2013-08-28 15:42:22,815 INFO org.apache.hadoop.yarn.server.resourcemanager.ResourceManager: STARTUP_MSG: 
/************************************************************
STARTUP_MSG: Starting ResourceManager
STARTUP_MSG:   host = hadoop-16-1/192.168.100.5
STARTUP_MSG:   args = []
STARTUP_MSG:   version = 3.0.0-SNAPSHOT
STARTUP_MSG:   build = https://github.com/lalithsuresh/hadoop-common -r 0cb423bd4868928bb06cd93f882bb0913172fd17; compiled by 'lsuresh' on 2013-04-08T15:47Z
STARTUP_MSG:   java = 1.7.0_17
************************************************************/
2013-08-28 15:42:22,830 INFO org.apache.hadoop.yarn.server.resourcemanager.ResourceManager: registered UNIX signal handlers for [TERM, HUP, INT]
2013-08-28 15:42:23,574 INFO org.apache.hadoop.yarn.server.resourcemanager.security.ApplicationTokenSecretManager: Rolling master-key for application-tokens
2013-08-28 15:42:23,641 INFO org.apache.hadoop.yarn.server.resourcemanager.security.RMContainerTokenSecretManager: ContainerTokenKeyRollingInterval: 86400000ms and ContainerTokenKeyActivationDelay: 900000ms
2013-08-28 15:42:23,644 INFO org.apache.hadoop.yarn.service.AbstractService: Service:Dispatcher is inited.
2013-08-28 15:42:23,645 INFO org.apache.hadoop.yarn.event.AsyncDispatcher: Registering class org.apache.hadoop.yarn.server.resourcemanager.recovery.RMStateStoreEventType for class org.apache.hadoop.yarn.server.resourcemanager.recovery.RMStateStore$ForwardingEventHandler
2013-08-28 15:42:23,645 INFO org.apache.hadoop.yarn.service.AbstractService: Service:Dispatcher is started.
2013-08-28 15:42:23,654 INFO org.apache.hadoop.yarn.event.AsyncDispatcher: Registering class org.apache.hadoop.yarn.server.resourcemanager.NodesListManagerEventType for class org.apache.hadoop.yarn.server.resourcemanager.NodesListManager
2013-08-28 15:42:23,655 INFO org.apache.hadoop.yarn.server.resourcemanager.ResourceManager: Using Scheduler: org.apache.hadoop.yarn.server.resourcemanager.scheduler.capacity.CapacityScheduler
2013-08-28 15:42:23,808 INFO org.apache.hadoop.yarn.event.AsyncDispatcher: Registering class org.apache.hadoop.yarn.server.resourcemanager.scheduler.event.SchedulerEventType for class org.apache.hadoop.yarn.server.resourcemanager.ResourceManager$SchedulerEventDispatcher
2013-08-28 15:42:23,809 INFO org.apache.hadoop.yarn.event.AsyncDispatcher: Registering class org.apache.hadoop.yarn.server.resourcemanager.rmapp.RMAppEventType for class org.apache.hadoop.yarn.server.resourcemanager.ResourceManager$ApplicationEventDispatcher
2013-08-28 15:42:23,811 INFO org.apache.hadoop.yarn.event.AsyncDispatcher: Registering class org.apache.hadoop.yarn.server.resourcemanager.rmapp.attempt.RMAppAttemptEventType for class org.apache.hadoop.yarn.server.resourcemanager.ResourceManager$ApplicationAttemptEventDispatcher
2013-08-28 15:42:23,812 INFO org.apache.hadoop.yarn.event.AsyncDispatcher: Registering class org.apache.hadoop.yarn.server.resourcemanager.rmnode.RMNodeEventType for class org.apache.hadoop.yarn.server.resourcemanager.ResourceManager$NodeEventDispatcher
2013-08-28 15:42:24,340 WARN org.apache.hadoop.util.NativeCodeLoader: Unable to load native-hadoop library for your platform... using builtin-java classes where applicable
2013-08-28 15:42:24,365 INFO org.apache.hadoop.yarn.server.resourcemanager.scheduler.capacity.ParentQueue: root, capacity=1.0, asboluteCapacity=1.0, maxCapacity=1.0, asboluteMaxCapacity=1.0, state=RUNNING, acls=SUBMIT_APPLICATIONS:*ADMINISTER_QUEUE:*
2013-08-28 15:42:24,365 INFO org.apache.hadoop.yarn.server.resourcemanager.scheduler.capacity.ParentQueue: Initialized parent-queue root name=root, fullname=root
2013-08-28 15:42:24,382 INFO org.apache.hadoop.yarn.server.resourcemanager.scheduler.capacity.LeafQueue: Initializing default
capacity = 1.0 [= (float) configuredCapacity / 100 ]
asboluteCapacity = 1.0 [= parentAbsoluteCapacity * capacity ]
maxCapacity = 1.0 [= configuredMaxCapacity ]
absoluteMaxCapacity = 1.0 [= 1.0 maximumCapacity undefined, (parentAbsoluteMaxCapacity * maximumCapacity) / 100 otherwise ]
userLimit = 100 [= configuredUserLimit ]
userLimitFactor = 1.0 [= configuredUserLimitFactor ]
maxApplications = 10000 [= configuredMaximumSystemApplicationsPerQueue or (int)(configuredMaximumSystemApplications * absoluteCapacity)]
maxApplicationsPerUser = 10000 [= (int)(maxApplications * (userLimit / 100.0f) * userLimitFactor) ]
maxActiveApplications = 1 [= max((int)ceil((clusterResourceMemory / minimumAllocation) * maxAMResourcePerQueuePercent * absoluteMaxCapacity),1) ]
maxActiveAppsUsingAbsCap = 1 [= max((int)ceil((clusterResourceMemory / minimumAllocation) *maxAMResourcePercent * absoluteCapacity),1) ]
maxActiveApplicationsPerUser = 1 [= max((int)(maxActiveApplications * (userLimit / 100.0f) * userLimitFactor),1) ]
usedCapacity = 0.0 [= usedResourcesMemory / (clusterResourceMemory * absoluteCapacity)]
absoluteUsedCapacity = 0.0 [= usedResourcesMemory / clusterResourceMemory]
maxAMResourcePerQueuePercent = 0.1 [= configuredMaximumAMResourcePercent ]
minimumAllocationFactor = 0.875 [= (float)(maximumAllocationMemory - minimumAllocationMemory) / maximumAllocationMemory ]
numContainers = 0 [= currentNumContainers ]
state = RUNNING [= configuredState ]
acls = SUBMIT_APPLICATIONS:*ADMINISTER_QUEUE:* [= configuredAcls ]

2013-08-28 15:42:24,382 INFO org.apache.hadoop.yarn.server.resourcemanager.scheduler.capacity.CapacityScheduler: Initialized queue: default: capacity=1.0, absoluteCapacity=1.0, usedResources=<memory:0, vCores:0>usedCapacity=0.0, absoluteUsedCapacity=0.0, numApps=0, numContainers=0
2013-08-28 15:42:24,383 INFO org.apache.hadoop.yarn.server.resourcemanager.scheduler.capacity.CapacityScheduler: Initialized queue: root: numChildQueue= 1, capacity=1.0, absoluteCapacity=1.0, usedResources=<memory:0, vCores:0>usedCapacity=0.0, numApps=0, numContainers=0
2013-08-28 15:42:24,383 INFO org.apache.hadoop.yarn.server.resourcemanager.scheduler.capacity.CapacityScheduler: Initialized root queue root: numChildQueue= 1, capacity=1.0, absoluteCapacity=1.0, usedResources=<memory:0, vCores:0>usedCapacity=0.0, numApps=0, numContainers=0
2013-08-28 15:42:24,383 INFO org.apache.hadoop.yarn.server.resourcemanager.scheduler.capacity.CapacityScheduler: Initialized CapacityScheduler with calculator=class org.apache.hadoop.yarn.server.resourcemanager.resource.DefaultResourceCalculator, minimumAllocation=<<memory:1024, vCores:1>>, maximumAllocation=<<memory:8192, vCores:32>>
2013-08-28 15:42:24,765 INFO org.apache.hadoop.yarn.event.AsyncDispatcher: Registering class org.apache.hadoop.yarn.server.resourcemanager.RMAppManagerEventType for class org.apache.hadoop.yarn.server.resourcemanager.RMAppManager
2013-08-28 15:42:24,777 INFO org.apache.hadoop.yarn.event.AsyncDispatcher: Registering class org.apache.hadoop.yarn.server.resourcemanager.amlauncher.AMLauncherEventType for class org.apache.hadoop.yarn.server.resourcemanager.amlauncher.ApplicationMasterLauncher
2013-08-28 15:42:24,831 INFO org.apache.hadoop.yarn.server.resourcemanager.RMNMInfo: Registered RMNMInfo MBean
2013-08-28 15:42:24,831 INFO org.apache.hadoop.yarn.service.AbstractService: Service:Dispatcher is inited.
2013-08-28 15:42:24,831 INFO org.apache.hadoop.yarn.service.AbstractService: Service:org.apache.hadoop.yarn.server.resourcemanager.rmcontainer.ContainerAllocationExpirer is inited.
2013-08-28 15:42:24,831 INFO org.apache.hadoop.yarn.service.AbstractService: Service:AMLivelinessMonitor is inited.
2013-08-28 15:42:24,831 INFO org.apache.hadoop.yarn.service.AbstractService: Service:AMLivelinessMonitor is inited.
2013-08-28 15:42:24,832 INFO org.apache.hadoop.yarn.service.AbstractService: Service:org.apache.hadoop.yarn.server.resourcemanager.security.DelegationTokenRenewer is inited.
2013-08-28 15:42:24,833 INFO org.apache.hadoop.util.HostsFileReader: Refreshing hosts (include/exclude) list
2013-08-28 15:42:24,833 INFO org.apache.hadoop.yarn.service.AbstractService: Service:org.apache.hadoop.yarn.server.resourcemanager.NodesListManager is inited.
2013-08-28 15:42:24,833 INFO org.apache.hadoop.yarn.service.AbstractService: Service:org.apache.hadoop.yarn.server.resourcemanager.ResourceManager$SchedulerEventDispatcher is inited.
2013-08-28 15:42:24,833 INFO org.apache.hadoop.yarn.service.AbstractService: Service:NMLivelinessMonitor is inited.
2013-08-28 15:42:24,837 INFO org.apache.hadoop.yarn.service.AbstractService: Service:org.apache.hadoop.yarn.server.resourcemanager.ResourceTrackerService is inited.
2013-08-28 15:42:24,837 INFO org.apache.hadoop.yarn.service.AbstractService: Service:org.apache.hadoop.yarn.server.resourcemanager.ApplicationMasterService is inited.
2013-08-28 15:42:24,837 INFO org.apache.hadoop.yarn.service.AbstractService: Service:org.apache.hadoop.yarn.server.resourcemanager.ClientRMService is inited.
2013-08-28 15:42:24,837 INFO org.apache.hadoop.yarn.service.AbstractService: Service:org.apache.hadoop.yarn.server.resourcemanager.AdminService is inited.
2013-08-28 15:42:24,838 INFO org.apache.hadoop.yarn.service.AbstractService: Service:org.apache.hadoop.yarn.server.resourcemanager.amlauncher.ApplicationMasterLauncher is inited.
2013-08-28 15:42:24,838 INFO org.apache.hadoop.yarn.service.AbstractService: Service:ResourceManager is inited.
2013-08-28 15:42:24,838 INFO org.apache.hadoop.yarn.server.resourcemanager.security.RMContainerTokenSecretManager: Rolling master-key for container-tokens
2013-08-28 15:42:24,838 INFO org.apache.hadoop.yarn.server.resourcemanager.security.ApplicationTokenSecretManager: Rolling master-key for application-tokens
2013-08-28 15:42:24,927 INFO org.mortbay.log: Logging to org.slf4j.impl.Log4jLoggerAdapter(org.mortbay.log) via org.mortbay.log.Slf4jLog
2013-08-28 15:42:24,981 INFO org.apache.hadoop.http.HttpServer: Added global filter 'safety' (class=org.apache.hadoop.http.HttpServer$QuotingInputFilter)
2013-08-28 15:42:24,984 INFO org.apache.hadoop.http.HttpServer: Added filter static_user_filter (class=org.apache.hadoop.http.lib.StaticUserWebFilter$StaticUserFilter) to context cluster
2013-08-28 15:42:24,984 INFO org.apache.hadoop.http.HttpServer: Added filter static_user_filter (class=org.apache.hadoop.http.lib.StaticUserWebFilter$StaticUserFilter) to context static
2013-08-28 15:42:24,984 INFO org.apache.hadoop.http.HttpServer: Added filter static_user_filter (class=org.apache.hadoop.http.lib.StaticUserWebFilter$StaticUserFilter) to context logs
2013-08-28 15:42:24,988 INFO org.apache.hadoop.http.HttpServer: adding path spec: /cluster
2013-08-28 15:42:24,988 INFO org.apache.hadoop.http.HttpServer: adding path spec: /cluster/*
2013-08-28 15:42:24,988 INFO org.apache.hadoop.http.HttpServer: adding path spec: /ws
2013-08-28 15:42:24,988 INFO org.apache.hadoop.http.HttpServer: adding path spec: /ws/*
2013-08-28 15:42:24,990 INFO org.apache.hadoop.http.HttpServer: Added global filter 'guice' (class=com.google.inject.servlet.GuiceFilter)
2013-08-28 15:42:24,995 INFO org.apache.hadoop.http.HttpServer: Jetty bound to port 8088
2013-08-28 15:42:24,995 INFO org.mortbay.log: jetty-6.1.26
2013-08-28 15:42:25,024 INFO org.mortbay.log: Extract jar:file:/home/ubuntu/hadoop-3.0.0-SNAPSHOT/share/hadoop/yarn/hadoop-yarn-common-3.0.0-SNAPSHOT.jar!/webapps/cluster to /tmp/Jetty_0_0_0_0_8088_cluster____u0rgz3/webapp
2013-08-28 15:42:25,279 INFO org.mortbay.log: Started SelectChannelConnector@0.0.0.0:8088
2013-08-28 15:42:25,279 INFO org.apache.hadoop.yarn.webapp.WebApps: Web app /cluster started at 8088
2013-08-28 15:42:25,939 INFO org.apache.hadoop.yarn.webapp.WebApps: Registered webapp guice modules
2013-08-28 15:42:26,059 INFO org.apache.hadoop.metrics2.impl.MetricsConfig: loaded properties from hadoop-metrics2.properties
2013-08-28 15:42:26,084 INFO org.apache.hadoop.metrics2.impl.MetricsSystemImpl: Scheduled snapshot period at 10 second(s).
2013-08-28 15:42:26,084 INFO org.apache.hadoop.metrics2.impl.MetricsSystemImpl: ResourceManager metrics system started
2013-08-28 15:42:26,092 INFO org.apache.hadoop.security.token.delegation.AbstractDelegationTokenSecretManager: Updating the current master key for generating delegation tokens
2013-08-28 15:42:26,094 INFO org.apache.hadoop.yarn.service.AbstractService: Service:Dispatcher is started.
2013-08-28 15:42:26,095 INFO org.apache.hadoop.security.token.delegation.AbstractDelegationTokenSecretManager: Starting expired delegation token remover thread, tokenRemoverScanInterval=60 min(s)
2013-08-28 15:42:26,096 INFO org.apache.hadoop.security.token.delegation.AbstractDelegationTokenSecretManager: Updating the current master key for generating delegation tokens
2013-08-28 15:42:26,096 INFO org.apache.hadoop.yarn.service.AbstractService: Service:org.apache.hadoop.yarn.server.resourcemanager.rmcontainer.ContainerAllocationExpirer is started.
2013-08-28 15:42:26,096 INFO org.apache.hadoop.yarn.service.AbstractService: Service:AMLivelinessMonitor is started.
2013-08-28 15:42:26,097 INFO org.apache.hadoop.yarn.service.AbstractService: Service:AMLivelinessMonitor is started.
2013-08-28 15:42:26,097 INFO org.apache.hadoop.yarn.service.AbstractService: Service:org.apache.hadoop.yarn.server.resourcemanager.security.DelegationTokenRenewer is started.
2013-08-28 15:42:26,098 INFO org.apache.hadoop.yarn.service.AbstractService: Service:org.apache.hadoop.yarn.server.resourcemanager.NodesListManager is started.
2013-08-28 15:42:26,098 INFO org.apache.hadoop.yarn.service.AbstractService: Service:org.apache.hadoop.yarn.server.resourcemanager.ResourceManager$SchedulerEventDispatcher is started.
2013-08-28 15:42:26,099 INFO org.apache.hadoop.yarn.service.AbstractService: Service:NMLivelinessMonitor is started.
2013-08-28 15:42:26,099 INFO org.apache.hadoop.yarn.service.AbstractService: Service:org.apache.hadoop.yarn.server.resourcemanager.ResourceTrackerService is started.
2013-08-28 15:42:26,140 INFO org.apache.hadoop.ipc.Server: Starting Socket Reader #1 for port 54110
2013-08-28 15:42:26,163 INFO org.apache.hadoop.yarn.factories.impl.pb.RpcServerFactoryPBImpl: Adding protocol org.apache.hadoop.yarn.server.api.ResourceTrackerPB to the server
2013-08-28 15:42:26,164 INFO org.apache.hadoop.ipc.Server: IPC Server Responder: starting
2013-08-28 15:42:26,164 INFO org.apache.hadoop.ipc.Server: IPC Server listener on 54110: starting
2013-08-28 15:42:26,230 INFO org.apache.hadoop.ipc.Server: Starting Socket Reader #1 for port 54112
2013-08-28 15:42:26,238 INFO org.apache.hadoop.yarn.factories.impl.pb.RpcServerFactoryPBImpl: Adding protocol org.apache.hadoop.yarn.api.AMRMProtocolPB to the server
2013-08-28 15:42:26,239 INFO org.apache.hadoop.ipc.Server: IPC Server Responder: starting
2013-08-28 15:42:26,239 INFO org.apache.hadoop.ipc.Server: IPC Server listener on 54112: starting
2013-08-28 15:42:26,281 INFO org.apache.hadoop.yarn.service.AbstractService: Service:org.apache.hadoop.yarn.server.resourcemanager.ApplicationMasterService is started.
2013-08-28 15:42:26,318 INFO org.apache.hadoop.ipc.Server: Starting Socket Reader #1 for port 54111
2013-08-28 15:42:26,321 INFO org.apache.hadoop.yarn.factories.impl.pb.RpcServerFactoryPBImpl: Adding protocol org.apache.hadoop.yarn.api.ClientRMProtocolPB to the server
2013-08-28 15:42:26,322 INFO org.apache.hadoop.ipc.Server: IPC Server Responder: starting
2013-08-28 15:42:26,331 INFO org.apache.hadoop.ipc.Server: IPC Server listener on 54111: starting
2013-08-28 15:42:26,383 INFO org.apache.hadoop.yarn.service.AbstractService: Service:org.apache.hadoop.yarn.server.resourcemanager.ClientRMService is started.
2013-08-28 15:42:26,409 INFO org.apache.hadoop.ipc.Server: Starting Socket Reader #1 for port 8033
2013-08-28 15:42:26,425 INFO org.apache.hadoop.yarn.factories.impl.pb.RpcServerFactoryPBImpl: Adding protocol org.apache.hadoop.yarn.api.RMAdminProtocolPB to the server
2013-08-28 15:42:26,426 INFO org.apache.hadoop.ipc.Server: IPC Server Responder: starting
2013-08-28 15:42:26,428 INFO org.apache.hadoop.yarn.service.AbstractService: Service:org.apache.hadoop.yarn.server.resourcemanager.AdminService is started.
2013-08-28 15:42:26,429 INFO org.apache.hadoop.yarn.service.AbstractService: Service:org.apache.hadoop.yarn.server.resourcemanager.amlauncher.ApplicationMasterLauncher is started.
2013-08-28 15:42:26,429 INFO org.apache.hadoop.ipc.Server: IPC Server listener on 8033: starting
2013-08-28 15:42:26,429 INFO org.apache.hadoop.yarn.service.AbstractService: Service:ResourceManager is started.
2013-08-28 15:42:37,373 INFO org.apache.hadoop.yarn.util.RackResolver: Resolved hadoop-16-3 to /default-rack
2013-08-28 15:42:37,379 INFO org.apache.hadoop.yarn.util.RackResolver: Resolved hadoop-16-2 to /default-rack
2013-08-28 15:42:37,380 INFO org.apache.hadoop.yarn.server.resourcemanager.ResourceTrackerService: NodeManager from node hadoop-16-3(cmPort: 41896 httpPort: 8042) registered with capability: <memory:8192, vCores:16>, assigned nodeId hadoop-16-3:41896
2013-08-28 15:42:37,387 INFO org.apache.hadoop.yarn.server.resourcemanager.ResourceTrackerService: NodeManager from node hadoop-16-2(cmPort: 39317 httpPort: 8042) registered with capability: <memory:8192, vCores:16>, assigned nodeId hadoop-16-2:39317
2013-08-28 15:42:37,391 INFO org.apache.hadoop.yarn.util.RackResolver: Resolved hadoop-16-6 to /default-rack
2013-08-28 15:42:37,391 INFO org.apache.hadoop.yarn.util.RackResolver: Resolved hadoop-16-5 to /default-rack
2013-08-28 15:42:37,391 INFO org.apache.hadoop.yarn.util.RackResolver: Resolved hadoop-16-4 to /default-rack
2013-08-28 15:42:37,392 INFO org.apache.hadoop.yarn.server.resourcemanager.ResourceTrackerService: NodeManager from node hadoop-16-5(cmPort: 57886 httpPort: 8042) registered with capability: <memory:8192, vCores:16>, assigned nodeId hadoop-16-5:57886
2013-08-28 15:42:37,392 INFO org.apache.hadoop.yarn.server.resourcemanager.ResourceTrackerService: NodeManager from node hadoop-16-6(cmPort: 36337 httpPort: 8042) registered with capability: <memory:8192, vCores:16>, assigned nodeId hadoop-16-6:36337
2013-08-28 15:42:37,392 INFO org.apache.hadoop.yarn.server.resourcemanager.ResourceTrackerService: NodeManager from node hadoop-16-4(cmPort: 52495 httpPort: 8042) registered with capability: <memory:8192, vCores:16>, assigned nodeId hadoop-16-4:52495
2013-08-28 15:42:37,409 INFO org.apache.hadoop.yarn.server.resourcemanager.rmnode.RMNodeImpl: hadoop-16-3:41896 Node Transitioned from NEW to RUNNING
2013-08-28 15:42:37,411 INFO org.apache.hadoop.yarn.server.resourcemanager.rmnode.RMNodeImpl: hadoop-16-2:39317 Node Transitioned from NEW to RUNNING
2013-08-28 15:42:37,412 INFO org.apache.hadoop.yarn.server.resourcemanager.rmnode.RMNodeImpl: hadoop-16-6:36337 Node Transitioned from NEW to RUNNING
2013-08-28 15:42:37,412 INFO org.apache.hadoop.yarn.util.RackResolver: Resolved hadoop-16-7 to /default-rack
2013-08-28 15:42:37,412 INFO org.apache.hadoop.yarn.server.resourcemanager.ResourceTrackerService: NodeManager from node hadoop-16-7(cmPort: 53595 httpPort: 8042) registered with capability: <memory:8192, vCores:16>, assigned nodeId hadoop-16-7:53595
2013-08-28 15:42:37,413 INFO org.apache.hadoop.yarn.server.resourcemanager.rmnode.RMNodeImpl: hadoop-16-5:57886 Node Transitioned from NEW to RUNNING
2013-08-28 15:42:37,413 INFO org.apache.hadoop.yarn.server.resourcemanager.rmnode.RMNodeImpl: hadoop-16-4:52495 Node Transitioned from NEW to RUNNING
2013-08-28 15:42:37,417 INFO org.apache.hadoop.yarn.server.resourcemanager.scheduler.capacity.CapacityScheduler: Added node hadoop-16-3:41896 clusterResource: <memory:8192, vCores:16>
2013-08-28 15:42:37,417 INFO org.apache.hadoop.yarn.server.resourcemanager.scheduler.capacity.CapacityScheduler: Added node hadoop-16-2:39317 clusterResource: <memory:16384, vCores:32>
2013-08-28 15:42:37,417 INFO org.apache.hadoop.yarn.server.resourcemanager.scheduler.capacity.CapacityScheduler: Added node hadoop-16-6:36337 clusterResource: <memory:24576, vCores:48>
2013-08-28 15:42:37,418 INFO org.apache.hadoop.yarn.server.resourcemanager.rmnode.RMNodeImpl: hadoop-16-7:53595 Node Transitioned from NEW to RUNNING
2013-08-28 15:42:37,418 INFO org.apache.hadoop.yarn.server.resourcemanager.scheduler.capacity.CapacityScheduler: Added node hadoop-16-5:57886 clusterResource: <memory:32768, vCores:64>
2013-08-28 15:42:37,418 INFO org.apache.hadoop.yarn.server.resourcemanager.scheduler.capacity.CapacityScheduler: Added node hadoop-16-4:52495 clusterResource: <memory:40960, vCores:80>
2013-08-28 15:42:37,419 INFO org.apache.hadoop.yarn.server.resourcemanager.scheduler.capacity.CapacityScheduler: Added node hadoop-16-7:53595 clusterResource: <memory:49152, vCores:96>
2013-08-28 15:43:04,233 INFO org.apache.hadoop.yarn.server.resourcemanager.ClientRMService: Allocated new applicationId: 1
2013-08-28 15:43:07,863 INFO org.apache.hadoop.yarn.server.resourcemanager.ClientRMService: Storing Application with id application_1377704542759_0001
2013-08-28 15:43:07,866 INFO org.apache.hadoop.yarn.server.resourcemanager.recovery.RMStateStore: Storing info for app: application_1377704542759_0001
2013-08-28 15:43:07,866 INFO org.apache.hadoop.yarn.server.resourcemanager.ClientRMService: Application with id 1 submitted by user ubuntu
2013-08-28 15:43:07,870 INFO org.apache.hadoop.yarn.server.resourcemanager.RMAuditLogger: USER=ubuntu	IP=192.168.100.5	OPERATION=Submit Application Request	TARGET=ClientRMService	RESULT=SUCCESS	APPID=application_1377704542759_0001
2013-08-28 15:43:07,916 INFO org.apache.hadoop.yarn.server.resourcemanager.rmapp.RMAppImpl: application_1377704542759_0001 State change from NEW to SUBMITTED
2013-08-28 15:43:07,917 INFO org.apache.hadoop.yarn.server.resourcemanager.ApplicationMasterService: Registering appattempt_1377704542759_0001_000001
2013-08-28 15:43:07,918 INFO org.apache.hadoop.yarn.server.resourcemanager.rmapp.attempt.RMAppAttemptImpl: appattempt_1377704542759_0001_000001 State change from NEW to SUBMITTED
2013-08-28 15:43:07,952 INFO org.apache.hadoop.yarn.server.resourcemanager.scheduler.capacity.LeafQueue: Application application_1377704542759_0001 from user: ubuntu activated in queue: default
2013-08-28 15:43:07,952 INFO org.apache.hadoop.yarn.server.resourcemanager.scheduler.capacity.LeafQueue: Application added - appId: application_1377704542759_0001 user: org.apache.hadoop.yarn.server.resourcemanager.scheduler.capacity.LeafQueue$User@30d46770, leaf-queue: default #user-pending-applications: 0 #user-active-applications: 1 #queue-pending-applications: 0 #queue-active-applications: 1
2013-08-28 15:43:07,952 INFO org.apache.hadoop.yarn.server.resourcemanager.scheduler.capacity.ParentQueue: Application added - appId: application_1377704542759_0001 user: ubuntu leaf-queue of parent: root #applications: 1
2013-08-28 15:43:07,953 INFO org.apache.hadoop.yarn.server.resourcemanager.scheduler.capacity.CapacityScheduler: Application Submission: appattempt_1377704542759_0001_000001, user: ubuntu queue: default: capacity=1.0, absoluteCapacity=1.0, usedResources=<memory:0, vCores:0>usedCapacity=0.0, absoluteUsedCapacity=0.0, numApps=1, numContainers=0, currently active: 1
2013-08-28 15:43:07,960 INFO org.apache.hadoop.yarn.server.resourcemanager.rmapp.attempt.RMAppAttemptImpl: appattempt_1377704542759_0001_000001 State change from SUBMITTED to SCHEDULED
2013-08-28 15:43:07,960 INFO org.apache.hadoop.yarn.server.resourcemanager.rmapp.RMAppImpl: application_1377704542759_0001 State change from SUBMITTED to ACCEPTED
2013-08-28 15:43:08,670 INFO org.apache.hadoop.yarn.server.resourcemanager.rmcontainer.RMContainerImpl: container_1377704542759_0001_01_000001 Container Transitioned from NEW to ALLOCATED
2013-08-28 15:43:08,671 INFO org.apache.hadoop.yarn.server.resourcemanager.RMAuditLogger: USER=ubuntu	OPERATION=AM Allocated Container	TARGET=SchedulerApp	RESULT=SUCCESS	APPID=application_1377704542759_0001	CONTAINERID=container_1377704542759_0001_01_000001
2013-08-28 15:43:08,672 INFO org.apache.hadoop.yarn.server.resourcemanager.scheduler.common.fica.FiCaSchedulerNode: Assigned container container_1377704542759_0001_01_000001 of capacity <memory:2048, vCores:1> on host hadoop-16-3:41896, which currently has 1 containers, <memory:2048, vCores:1> used and <memory:6144, vCores:15> available
2013-08-28 15:43:08,682 INFO org.apache.hadoop.yarn.server.resourcemanager.scheduler.capacity.LeafQueue: assignedContainer application=application_1377704542759_0001 container=Container: [ContainerId: container_1377704542759_0001_01_000001, NodeId: hadoop-16-3:41896, NodeHttpAddress: hadoop-16-3:8042, Resource: <memory:2048, vCores:1>, Priority: 0, State: NEW, Token: null, Status: container_id {, app_attempt_id {, application_id {, id: 1, cluster_timestamp: 1377704542759, }, attemptId: 1, }, id: 1, }, state: C_NEW, ] containerId=container_1377704542759_0001_01_000001 queue=default: capacity=1.0, absoluteCapacity=1.0, usedResources=<memory:0, vCores:0>usedCapacity=0.0, absoluteUsedCapacity=0.0, numApps=1, numContainers=0 usedCapacity=0.0 absoluteUsedCapacity=0.0 used=<memory:0, vCores:0> cluster=<memory:49152, vCores:96>
2013-08-28 15:43:08,682 INFO org.apache.hadoop.yarn.server.resourcemanager.scheduler.capacity.ParentQueue: Re-sorting queues since queue: root.default stats: default: capacity=1.0, absoluteCapacity=1.0, usedResources=<memory:2048, vCores:1>usedCapacity=0.041666668, absoluteUsedCapacity=0.041666668, numApps=1, numContainers=1
2013-08-28 15:43:08,683 INFO org.apache.hadoop.yarn.server.resourcemanager.scheduler.capacity.ParentQueue: assignedContainer queue=root usedCapacity=0.041666668 absoluteUsedCapacity=0.041666668 used=<memory:2048, vCores:1> cluster=<memory:49152, vCores:96>
2013-08-28 15:43:08,686 INFO org.apache.hadoop.yarn.server.resourcemanager.rmcontainer.RMContainerImpl: container_1377704542759_0001_01_000001 Container Transitioned from ALLOCATED to ACQUIRED
2013-08-28 15:43:08,689 INFO org.apache.hadoop.yarn.server.resourcemanager.rmapp.attempt.RMAppAttemptImpl: Storing attempt: AppId: application_1377704542759_0001 AttemptId: appattempt_1377704542759_0001_000001 MasterContainer: Container: [ContainerId: container_1377704542759_0001_01_000001, NodeId: hadoop-16-3:41896, NodeHttpAddress: hadoop-16-3:8042, Resource: <memory:2048, vCores:1>, Priority: 0, State: NEW, Token: null, Status: container_id {, app_attempt_id {, application_id {, id: 1, cluster_timestamp: 1377704542759, }, attemptId: 1, }, id: 1, }, state: C_NEW, ]
2013-08-28 15:43:08,692 INFO org.apache.hadoop.yarn.server.resourcemanager.rmapp.attempt.RMAppAttemptImpl: appattempt_1377704542759_0001_000001 State change from SCHEDULED to ALLOCATED_SAVING
2013-08-28 15:43:08,696 INFO org.apache.hadoop.yarn.server.resourcemanager.recovery.RMStateStore: Storing info for attempt: appattempt_1377704542759_0001_000001
2013-08-28 15:43:08,699 INFO org.apache.hadoop.yarn.server.resourcemanager.rmapp.attempt.RMAppAttemptImpl: appattempt_1377704542759_0001_000001 State change from ALLOCATED_SAVING to ALLOCATED
2013-08-28 15:43:08,706 INFO org.apache.hadoop.yarn.server.resourcemanager.amlauncher.AMLauncher: Launching masterappattempt_1377704542759_0001_000001
2013-08-28 15:43:08,752 INFO org.apache.hadoop.yarn.server.resourcemanager.amlauncher.AMLauncher: Setting up container Container: [ContainerId: container_1377704542759_0001_01_000001, NodeId: hadoop-16-3:41896, NodeHttpAddress: hadoop-16-3:8042, Resource: <memory:2048, vCores:1>, Priority: 0, State: NEW, Token: null, Status: container_id {, app_attempt_id {, application_id {, id: 1, cluster_timestamp: 1377704542759, }, attemptId: 1, }, id: 1, }, state: C_NEW, ] for AM appattempt_1377704542759_0001_000001
2013-08-28 15:43:08,752 INFO org.apache.hadoop.yarn.server.resourcemanager.amlauncher.AMLauncher: Command to launch container container_1377704542759_0001_01_000001 : $JAVA_HOME/bin/java -Dlog4j.configuration=container-log4j.properties -Dyarn.app.mapreduce.container.log.dir=<LOG_DIR> -Dyarn.app.mapreduce.container.log.filesize=0 -Dhadoop.root.logger=INFO,CLA  -Xmx1024m org.apache.hadoop.mapreduce.v2.app.MRAppMaster 1><LOG_DIR>/stdout 2><LOG_DIR>/stderr 
2013-08-28 15:43:09,652 INFO org.apache.hadoop.yarn.server.resourcemanager.amlauncher.AMLauncher: Done launching container Container: [ContainerId: container_1377704542759_0001_01_000001, NodeId: hadoop-16-3:41896, NodeHttpAddress: hadoop-16-3:8042, Resource: <memory:2048, vCores:1>, Priority: 0, State: NEW, Token: null, Status: container_id {, app_attempt_id {, application_id {, id: 1, cluster_timestamp: 1377704542759, }, attemptId: 1, }, id: 1, }, state: C_NEW, ] for AM appattempt_1377704542759_0001_000001
2013-08-28 15:43:09,652 INFO org.apache.hadoop.yarn.server.resourcemanager.rmapp.attempt.RMAppAttemptImpl: appattempt_1377704542759_0001_000001 State change from ALLOCATED to LAUNCHED
2013-08-28 15:43:09,674 INFO org.apache.hadoop.yarn.server.resourcemanager.rmcontainer.RMContainerImpl: container_1377704542759_0001_01_000001 Container Transitioned from ACQUIRED to RUNNING
2013-08-28 15:43:18,285 INFO org.apache.hadoop.yarn.server.resourcemanager.ApplicationMasterService: AM registration appattempt_1377704542759_0001_000001
2013-08-28 15:43:18,287 INFO org.apache.hadoop.yarn.server.resourcemanager.RMAuditLogger: USER=ubuntu	IP=192.168.100.17	OPERATION=Register App Master	TARGET=ApplicationMasterService	RESULT=SUCCESS	APPID=application_1377704542759_0001	APPATTEMPTID=appattempt_1377704542759_0001_000001
2013-08-28 15:43:18,289 INFO org.apache.hadoop.yarn.server.resourcemanager.rmapp.attempt.RMAppAttemptImpl: appattempt_1377704542759_0001_000001 State change from LAUNCHED to RUNNING
2013-08-28 15:43:18,290 INFO org.apache.hadoop.yarn.server.resourcemanager.rmapp.RMAppImpl: application_1377704542759_0001 State change from ACCEPTED to RUNNING
2013-08-28 15:43:19,687 INFO org.apache.hadoop.yarn.server.resourcemanager.rmcontainer.RMContainerImpl: container_1377704542759_0001_01_000002 Container Transitioned from NEW to ALLOCATED
2013-08-28 15:43:19,687 INFO org.apache.hadoop.yarn.server.resourcemanager.RMAuditLogger: USER=ubuntu	OPERATION=AM Allocated Container	TARGET=SchedulerApp	RESULT=SUCCESS	APPID=application_1377704542759_0001	CONTAINERID=container_1377704542759_0001_01_000002
2013-08-28 15:43:19,687 INFO org.apache.hadoop.yarn.server.resourcemanager.scheduler.common.fica.FiCaSchedulerNode: Assigned container container_1377704542759_0001_01_000002 of capacity <memory:1024, vCores:1> on host hadoop-16-2:39317, which currently has 1 containers, <memory:1024, vCores:1> used and <memory:7168, vCores:15> available
2013-08-28 15:43:19,689 INFO org.apache.hadoop.yarn.server.resourcemanager.scheduler.capacity.LeafQueue: assignedContainer application=application_1377704542759_0001 container=Container: [ContainerId: container_1377704542759_0001_01_000002, NodeId: hadoop-16-2:39317, NodeHttpAddress: hadoop-16-2:8042, Resource: <memory:1024, vCores:1>, Priority: 20, State: NEW, Token: null, Status: container_id {, app_attempt_id {, application_id {, id: 1, cluster_timestamp: 1377704542759, }, attemptId: 1, }, id: 2, }, state: C_NEW, ] containerId=container_1377704542759_0001_01_000002 queue=default: capacity=1.0, absoluteCapacity=1.0, usedResources=<memory:2048, vCores:1>usedCapacity=0.041666668, absoluteUsedCapacity=0.041666668, numApps=1, numContainers=1 usedCapacity=0.041666668 absoluteUsedCapacity=0.041666668 used=<memory:2048, vCores:1> cluster=<memory:49152, vCores:96>
2013-08-28 15:43:19,690 INFO org.apache.hadoop.yarn.server.resourcemanager.scheduler.capacity.ParentQueue: Re-sorting queues since queue: root.default stats: default: capacity=1.0, absoluteCapacity=1.0, usedResources=<memory:3072, vCores:2>usedCapacity=0.0625, absoluteUsedCapacity=0.0625, numApps=1, numContainers=2
2013-08-28 15:43:19,690 INFO org.apache.hadoop.yarn.server.resourcemanager.scheduler.capacity.ParentQueue: assignedContainer queue=root usedCapacity=0.0625 absoluteUsedCapacity=0.0625 used=<memory:3072, vCores:2> cluster=<memory:49152, vCores:96>
2013-08-28 15:43:19,691 INFO org.apache.hadoop.yarn.server.resourcemanager.rmcontainer.RMContainerImpl: container_1377704542759_0001_01_000003 Container Transitioned from NEW to ALLOCATED
2013-08-28 15:43:19,691 INFO org.apache.hadoop.yarn.server.resourcemanager.RMAuditLogger: USER=ubuntu	OPERATION=AM Allocated Container	TARGET=SchedulerApp	RESULT=SUCCESS	APPID=application_1377704542759_0001	CONTAINERID=container_1377704542759_0001_01_000003
2013-08-28 15:43:19,691 INFO org.apache.hadoop.yarn.server.resourcemanager.scheduler.common.fica.FiCaSchedulerNode: Assigned container container_1377704542759_0001_01_000003 of capacity <memory:1024, vCores:1> on host hadoop-16-7:53595, which currently has 1 containers, <memory:1024, vCores:1> used and <memory:7168, vCores:15> available
2013-08-28 15:43:19,693 INFO org.apache.hadoop.yarn.server.resourcemanager.scheduler.capacity.LeafQueue: assignedContainer application=application_1377704542759_0001 container=Container: [ContainerId: container_1377704542759_0001_01_000003, NodeId: hadoop-16-7:53595, NodeHttpAddress: hadoop-16-7:8042, Resource: <memory:1024, vCores:1>, Priority: 20, State: NEW, Token: null, Status: container_id {, app_attempt_id {, application_id {, id: 1, cluster_timestamp: 1377704542759, }, attemptId: 1, }, id: 3, }, state: C_NEW, ] containerId=container_1377704542759_0001_01_000003 queue=default: capacity=1.0, absoluteCapacity=1.0, usedResources=<memory:3072, vCores:2>usedCapacity=0.0625, absoluteUsedCapacity=0.0625, numApps=1, numContainers=2 usedCapacity=0.0625 absoluteUsedCapacity=0.0625 used=<memory:3072, vCores:2> cluster=<memory:49152, vCores:96>
2013-08-28 15:43:19,693 INFO org.apache.hadoop.yarn.server.resourcemanager.scheduler.capacity.ParentQueue: Re-sorting queues since queue: root.default stats: default: capacity=1.0, absoluteCapacity=1.0, usedResources=<memory:4096, vCores:3>usedCapacity=0.083333336, absoluteUsedCapacity=0.083333336, numApps=1, numContainers=3
2013-08-28 15:43:19,693 INFO org.apache.hadoop.yarn.server.resourcemanager.scheduler.capacity.ParentQueue: assignedContainer queue=root usedCapacity=0.083333336 absoluteUsedCapacity=0.083333336 used=<memory:4096, vCores:3> cluster=<memory:49152, vCores:96>
2013-08-28 15:43:20,367 INFO org.apache.hadoop.yarn.server.resourcemanager.rmcontainer.RMContainerImpl: container_1377704542759_0001_01_000002 Container Transitioned from ALLOCATED to ACQUIRED
2013-08-28 15:43:20,369 INFO org.apache.hadoop.yarn.server.resourcemanager.rmcontainer.RMContainerImpl: container_1377704542759_0001_01_000003 Container Transitioned from ALLOCATED to ACQUIRED
2013-08-28 15:43:21,404 INFO org.apache.hadoop.yarn.server.resourcemanager.scheduler.AppSchedulingInfo: checking for deactivate... 
2013-08-28 15:43:21,839 INFO org.apache.hadoop.yarn.server.resourcemanager.rmcontainer.RMContainerImpl: container_1377704542759_0001_01_000002 Container Transitioned from ACQUIRED to RUNNING
2013-08-28 15:43:21,842 INFO org.apache.hadoop.yarn.server.resourcemanager.rmcontainer.RMContainerImpl: container_1377704542759_0001_01_000003 Container Transitioned from ACQUIRED to RUNNING
2013-08-28 15:46:08,923 INFO org.apache.hadoop.yarn.server.resourcemanager.rmcontainer.RMContainerImpl: container_1377704542759_0001_01_000003 Container Transitioned from RUNNING to COMPLETED
2013-08-28 15:46:08,923 INFO org.apache.hadoop.yarn.server.resourcemanager.scheduler.common.fica.FiCaSchedulerApp: Completed container: container_1377704542759_0001_01_000003 in state: COMPLETED event:FINISHED
2013-08-28 15:46:08,923 INFO org.apache.hadoop.yarn.server.resourcemanager.RMAuditLogger: USER=ubuntu	OPERATION=AM Released Container	TARGET=SchedulerApp	RESULT=SUCCESS	APPID=application_1377704542759_0001	CONTAINERID=container_1377704542759_0001_01_000003
2013-08-28 15:46:08,924 INFO org.apache.hadoop.yarn.server.resourcemanager.scheduler.common.fica.FiCaSchedulerNode: Released container container_1377704542759_0001_01_000003 of capacity <memory:1024, vCores:1> on host hadoop-16-7:53595, which currently has 0 containers, <memory:0, vCores:0> used and <memory:8192, vCores:16> available, release resources=true
2013-08-28 15:46:08,924 INFO org.apache.hadoop.yarn.server.resourcemanager.scheduler.capacity.LeafQueue: default used=<memory:3072, vCores:2> numContainers=2 user=ubuntu user-resources=<memory:3072, vCores:2>
2013-08-28 15:46:08,926 INFO org.apache.hadoop.yarn.server.resourcemanager.scheduler.capacity.LeafQueue: completedContainer container=Container: [ContainerId: container_1377704542759_0001_01_000003, NodeId: hadoop-16-7:53595, NodeHttpAddress: hadoop-16-7:8042, Resource: <memory:1024, vCores:1>, Priority: 20, State: NEW, Token: null, Status: container_id {, app_attempt_id {, application_id {, id: 1, cluster_timestamp: 1377704542759, }, attemptId: 1, }, id: 3, }, state: C_COMPLETE, diagnostics: "Container killed by the ApplicationMaster.\n\n", exit_status: 143, ] resource=<memory:1024, vCores:1> queue=default: capacity=1.0, absoluteCapacity=1.0, usedResources=<memory:3072, vCores:2>usedCapacity=0.0625, absoluteUsedCapacity=0.0625, numApps=1, numContainers=2 usedCapacity=0.0625 absoluteUsedCapacity=0.0625 used=<memory:3072, vCores:2> cluster=<memory:49152, vCores:96>
2013-08-28 15:46:08,927 INFO org.apache.hadoop.yarn.server.resourcemanager.scheduler.capacity.ParentQueue: completedContainer queue=root usedCapacity=0.0625 absoluteUsedCapacity=0.0625 used=<memory:3072, vCores:2> cluster=<memory:49152, vCores:96>
2013-08-28 15:46:08,927 INFO org.apache.hadoop.yarn.server.resourcemanager.scheduler.capacity.CapacityScheduler: Application appattempt_1377704542759_0001_000001 released container container_1377704542759_0001_01_000003 on node: host: hadoop-16-7:53595 #containers=0 available=8192 used=0 with event: FINISHED
2013-08-28 15:46:15,549 INFO org.apache.hadoop.yarn.server.resourcemanager.rmcontainer.RMContainerImpl: container_1377704542759_0001_01_000002 Container Transitioned from RUNNING to COMPLETED
2013-08-28 15:46:15,549 INFO org.apache.hadoop.yarn.server.resourcemanager.scheduler.common.fica.FiCaSchedulerApp: Completed container: container_1377704542759_0001_01_000002 in state: COMPLETED event:FINISHED
2013-08-28 15:46:15,549 INFO org.apache.hadoop.yarn.server.resourcemanager.RMAuditLogger: USER=ubuntu	OPERATION=AM Released Container	TARGET=SchedulerApp	RESULT=SUCCESS	APPID=application_1377704542759_0001	CONTAINERID=container_1377704542759_0001_01_000002
2013-08-28 15:46:15,550 INFO org.apache.hadoop.yarn.server.resourcemanager.scheduler.common.fica.FiCaSchedulerNode: Released container container_1377704542759_0001_01_000002 of capacity <memory:1024, vCores:1> on host hadoop-16-2:39317, which currently has 0 containers, <memory:0, vCores:0> used and <memory:8192, vCores:16> available, release resources=true
2013-08-28 15:46:15,550 INFO org.apache.hadoop.yarn.server.resourcemanager.scheduler.capacity.LeafQueue: default used=<memory:2048, vCores:1> numContainers=1 user=ubuntu user-resources=<memory:2048, vCores:1>
2013-08-28 15:46:15,552 INFO org.apache.hadoop.yarn.server.resourcemanager.scheduler.capacity.LeafQueue: completedContainer container=Container: [ContainerId: container_1377704542759_0001_01_000002, NodeId: hadoop-16-2:39317, NodeHttpAddress: hadoop-16-2:8042, Resource: <memory:1024, vCores:1>, Priority: 20, State: NEW, Token: null, Status: container_id {, app_attempt_id {, application_id {, id: 1, cluster_timestamp: 1377704542759, }, attemptId: 1, }, id: 2, }, state: C_COMPLETE, diagnostics: "Container killed by the ApplicationMaster.\n\n", exit_status: 143, ] resource=<memory:1024, vCores:1> queue=default: capacity=1.0, absoluteCapacity=1.0, usedResources=<memory:2048, vCores:1>usedCapacity=0.041666668, absoluteUsedCapacity=0.041666668, numApps=1, numContainers=1 usedCapacity=0.041666668 absoluteUsedCapacity=0.041666668 used=<memory:2048, vCores:1> cluster=<memory:49152, vCores:96>
2013-08-28 15:46:15,552 INFO org.apache.hadoop.yarn.server.resourcemanager.scheduler.capacity.ParentQueue: completedContainer queue=root usedCapacity=0.041666668 absoluteUsedCapacity=0.041666668 used=<memory:2048, vCores:1> cluster=<memory:49152, vCores:96>
2013-08-28 15:46:15,552 INFO org.apache.hadoop.yarn.server.resourcemanager.scheduler.capacity.CapacityScheduler: Application appattempt_1377704542759_0001_000001 released container container_1377704542759_0001_01_000002 on node: host: hadoop-16-2:39317 #containers=0 available=8192 used=0 with event: FINISHED
2013-08-28 15:46:19,707 INFO org.apache.hadoop.yarn.server.resourcemanager.rmapp.attempt.RMAppAttemptImpl: appattempt_1377704542759_0001_000001 State change from RUNNING to FINISHING
2013-08-28 15:46:19,708 INFO org.apache.hadoop.yarn.server.resourcemanager.rmapp.RMAppImpl: application_1377704542759_0001 State change from RUNNING to FINISHING
2013-08-28 15:46:19,964 INFO org.apache.hadoop.yarn.server.resourcemanager.rmcontainer.RMContainerImpl: container_1377704542759_0001_01_000001 Container Transitioned from RUNNING to COMPLETED
2013-08-28 15:46:19,964 INFO org.apache.hadoop.yarn.server.resourcemanager.scheduler.common.fica.FiCaSchedulerApp: Completed container: container_1377704542759_0001_01_000001 in state: COMPLETED event:FINISHED
2013-08-28 15:46:19,964 INFO org.apache.hadoop.yarn.server.resourcemanager.RMAuditLogger: USER=ubuntu	OPERATION=AM Released Container	TARGET=SchedulerApp	RESULT=SUCCESS	APPID=application_1377704542759_0001	CONTAINERID=container_1377704542759_0001_01_000001
2013-08-28 15:46:19,964 INFO org.apache.hadoop.yarn.server.resourcemanager.scheduler.common.fica.FiCaSchedulerNode: Released container container_1377704542759_0001_01_000001 of capacity <memory:2048, vCores:1> on host hadoop-16-3:41896, which currently has 0 containers, <memory:0, vCores:0> used and <memory:8192, vCores:16> available, release resources=true
2013-08-28 15:46:19,964 INFO org.apache.hadoop.yarn.server.resourcemanager.scheduler.capacity.LeafQueue: default used=<memory:0, vCores:0> numContainers=0 user=ubuntu user-resources=<memory:0, vCores:0>
2013-08-28 15:46:19,965 INFO org.apache.hadoop.yarn.server.resourcemanager.scheduler.capacity.LeafQueue: completedContainer container=Container: [ContainerId: container_1377704542759_0001_01_000001, NodeId: hadoop-16-3:41896, NodeHttpAddress: hadoop-16-3:8042, Resource: <memory:2048, vCores:1>, Priority: 0, State: NEW, Token: null, Status: container_id {, app_attempt_id {, application_id {, id: 1, cluster_timestamp: 1377704542759, }, attemptId: 1, }, id: 1, }, state: C_COMPLETE, diagnostics: "", exit_status: 0, ] resource=<memory:2048, vCores:1> queue=default: capacity=1.0, absoluteCapacity=1.0, usedResources=<memory:0, vCores:0>usedCapacity=0.0, absoluteUsedCapacity=0.0, numApps=1, numContainers=0 usedCapacity=0.0 absoluteUsedCapacity=0.0 used=<memory:0, vCores:0> cluster=<memory:49152, vCores:96>
2013-08-28 15:46:19,965 INFO org.apache.hadoop.yarn.server.resourcemanager.scheduler.capacity.ParentQueue: completedContainer queue=root usedCapacity=0.0 absoluteUsedCapacity=0.0 used=<memory:0, vCores:0> cluster=<memory:49152, vCores:96>
2013-08-28 15:46:19,965 INFO org.apache.hadoop.yarn.server.resourcemanager.scheduler.capacity.CapacityScheduler: Application appattempt_1377704542759_0001_000001 released container container_1377704542759_0001_01_000001 on node: host: hadoop-16-3:41896 #containers=0 available=8192 used=0 with event: FINISHED
2013-08-28 15:46:19,967 INFO org.apache.hadoop.yarn.server.resourcemanager.rmapp.attempt.RMAppAttemptImpl: appattempt_1377704542759_0001_000001 State change from FINISHING to FINISHED
2013-08-28 15:46:19,969 INFO org.apache.hadoop.yarn.server.resourcemanager.rmapp.RMAppImpl: application_1377704542759_0001 State change from FINISHING to FINISHED
2013-08-28 15:46:19,970 INFO org.apache.hadoop.yarn.server.resourcemanager.scheduler.capacity.CapacityScheduler: Application appattempt_1377704542759_0001_000001 is done. finalState=FINISHED
2013-08-28 15:46:19,970 INFO org.apache.hadoop.yarn.server.resourcemanager.RMAuditLogger: USER=ubuntu	OPERATION=Application Finished - Succeeded	TARGET=RMAppManager	RESULT=SUCCESS	APPID=application_1377704542759_0001
2013-08-28 15:46:19,971 INFO org.apache.hadoop.yarn.server.resourcemanager.scheduler.AppSchedulingInfo: Application application_1377704542759_0001 requests cleared
2013-08-28 15:46:19,983 INFO org.apache.hadoop.yarn.server.resourcemanager.amlauncher.AMLauncher: Cleaning master appattempt_1377704542759_0001_000001
2013-08-28 15:46:19,983 INFO org.apache.hadoop.yarn.server.resourcemanager.scheduler.capacity.LeafQueue: Application removed - appId: application_1377704542759_0001 user: ubuntu queue: default #user-pending-applications: 0 #user-active-applications: 0 #queue-pending-applications: 0 #queue-active-applications: 0
2013-08-28 15:46:19,983 INFO org.apache.hadoop.yarn.server.resourcemanager.scheduler.capacity.ParentQueue: Application removed - appId: application_1377704542759_0001 user: ubuntu leaf-queue of parent: root #applications: 0
2013-08-28 15:46:19,984 INFO org.apache.hadoop.yarn.server.resourcemanager.recovery.RMStateStore: Removing info for app: application_1377704542759_0001
2013-08-28 15:46:19,987 INFO org.apache.hadoop.yarn.server.resourcemanager.RMAppManager$ApplicationSummary: appId=application_1377704542759_0001,name=TeraGen,user=ubuntu,queue=default,state=FINISHED,trackingUrl=hadoop-16-1.novalocal:8088/proxy/application_1377704542759_0001/jobhistory/job/job_1377704542759_0001,appMasterHost=hadoop-16-3,startTime=1377704587850,finishTime=1377704779708
2013-08-28 15:46:20,883 INFO org.apache.hadoop.yarn.server.resourcemanager.ClientRMService: Allocated new applicationId: 2
2013-08-28 15:46:22,841 INFO org.apache.hadoop.yarn.server.resourcemanager.ClientRMService: Storing Application with id application_1377704542759_0002
2013-08-28 15:46:22,841 INFO org.apache.hadoop.yarn.server.resourcemanager.recovery.RMStateStore: Storing info for app: application_1377704542759_0002
2013-08-28 15:46:22,841 INFO org.apache.hadoop.yarn.server.resourcemanager.ClientRMService: Application with id 2 submitted by user ubuntu
2013-08-28 15:46:22,841 INFO org.apache.hadoop.yarn.server.resourcemanager.RMAuditLogger: USER=ubuntu	IP=192.168.100.5	OPERATION=Submit Application Request	TARGET=ClientRMService	RESULT=SUCCESS	APPID=application_1377704542759_0002
2013-08-28 15:46:22,846 INFO org.apache.hadoop.yarn.server.resourcemanager.rmapp.RMAppImpl: application_1377704542759_0002 State change from NEW to SUBMITTED
2013-08-28 15:46:22,846 INFO org.apache.hadoop.yarn.server.resourcemanager.ApplicationMasterService: Registering appattempt_1377704542759_0002_000001
2013-08-28 15:46:22,846 INFO org.apache.hadoop.yarn.server.resourcemanager.rmapp.attempt.RMAppAttemptImpl: appattempt_1377704542759_0002_000001 State change from NEW to SUBMITTED
2013-08-28 15:46:22,847 INFO org.apache.hadoop.yarn.server.resourcemanager.scheduler.capacity.LeafQueue: Application application_1377704542759_0002 from user: ubuntu activated in queue: default
2013-08-28 15:46:22,847 INFO org.apache.hadoop.yarn.server.resourcemanager.scheduler.capacity.LeafQueue: Application added - appId: application_1377704542759_0002 user: org.apache.hadoop.yarn.server.resourcemanager.scheduler.capacity.LeafQueue$User@759b9645, leaf-queue: default #user-pending-applications: 0 #user-active-applications: 1 #queue-pending-applications: 0 #queue-active-applications: 1
2013-08-28 15:46:22,847 INFO org.apache.hadoop.yarn.server.resourcemanager.scheduler.capacity.ParentQueue: Application added - appId: application_1377704542759_0002 user: ubuntu leaf-queue of parent: root #applications: 1
2013-08-28 15:46:22,847 INFO org.apache.hadoop.yarn.server.resourcemanager.scheduler.capacity.CapacityScheduler: Application Submission: appattempt_1377704542759_0002_000001, user: ubuntu queue: default: capacity=1.0, absoluteCapacity=1.0, usedResources=<memory:0, vCores:0>usedCapacity=0.0, absoluteUsedCapacity=0.0, numApps=1, numContainers=0, currently active: 1
2013-08-28 15:46:22,848 INFO org.apache.hadoop.yarn.server.resourcemanager.rmapp.attempt.RMAppAttemptImpl: appattempt_1377704542759_0002_000001 State change from SUBMITTED to SCHEDULED
2013-08-28 15:46:22,848 INFO org.apache.hadoop.yarn.server.resourcemanager.rmapp.RMAppImpl: application_1377704542759_0002 State change from SUBMITTED to ACCEPTED
2013-08-28 15:46:22,970 INFO org.apache.hadoop.yarn.server.resourcemanager.rmcontainer.RMContainerImpl: container_1377704542759_0002_01_000001 Container Transitioned from NEW to ALLOCATED
2013-08-28 15:46:22,970 INFO org.apache.hadoop.yarn.server.resourcemanager.RMAuditLogger: USER=ubuntu	OPERATION=AM Allocated Container	TARGET=SchedulerApp	RESULT=SUCCESS	APPID=application_1377704542759_0002	CONTAINERID=container_1377704542759_0002_01_000001
2013-08-28 15:46:22,970 INFO org.apache.hadoop.yarn.server.resourcemanager.scheduler.common.fica.FiCaSchedulerNode: Assigned container container_1377704542759_0002_01_000001 of capacity <memory:2048, vCores:1> on host hadoop-16-3:41896, which currently has 1 containers, <memory:2048, vCores:1> used and <memory:6144, vCores:15> available
2013-08-28 15:46:22,972 INFO org.apache.hadoop.yarn.server.resourcemanager.scheduler.capacity.LeafQueue: assignedContainer application=application_1377704542759_0002 container=Container: [ContainerId: container_1377704542759_0002_01_000001, NodeId: hadoop-16-3:41896, NodeHttpAddress: hadoop-16-3:8042, Resource: <memory:2048, vCores:1>, Priority: 0, State: NEW, Token: null, Status: container_id {, app_attempt_id {, application_id {, id: 2, cluster_timestamp: 1377704542759, }, attemptId: 1, }, id: 1, }, state: C_NEW, ] containerId=container_1377704542759_0002_01_000001 queue=default: capacity=1.0, absoluteCapacity=1.0, usedResources=<memory:0, vCores:0>usedCapacity=0.0, absoluteUsedCapacity=0.0, numApps=1, numContainers=0 usedCapacity=0.0 absoluteUsedCapacity=0.0 used=<memory:0, vCores:0> cluster=<memory:49152, vCores:96>
2013-08-28 15:46:22,972 INFO org.apache.hadoop.yarn.server.resourcemanager.scheduler.capacity.ParentQueue: Re-sorting queues since queue: root.default stats: default: capacity=1.0, absoluteCapacity=1.0, usedResources=<memory:2048, vCores:1>usedCapacity=0.041666668, absoluteUsedCapacity=0.041666668, numApps=1, numContainers=1
2013-08-28 15:46:22,973 INFO org.apache.hadoop.yarn.server.resourcemanager.scheduler.capacity.ParentQueue: assignedContainer queue=root usedCapacity=0.041666668 absoluteUsedCapacity=0.041666668 used=<memory:2048, vCores:1> cluster=<memory:49152, vCores:96>
2013-08-28 15:46:22,979 INFO org.apache.hadoop.yarn.server.resourcemanager.rmcontainer.RMContainerImpl: container_1377704542759_0002_01_000001 Container Transitioned from ALLOCATED to ACQUIRED
2013-08-28 15:46:22,981 INFO org.apache.hadoop.yarn.server.resourcemanager.rmapp.attempt.RMAppAttemptImpl: Storing attempt: AppId: application_1377704542759_0002 AttemptId: appattempt_1377704542759_0002_000001 MasterContainer: Container: [ContainerId: container_1377704542759_0002_01_000001, NodeId: hadoop-16-3:41896, NodeHttpAddress: hadoop-16-3:8042, Resource: <memory:2048, vCores:1>, Priority: 0, State: NEW, Token: null, Status: container_id {, app_attempt_id {, application_id {, id: 2, cluster_timestamp: 1377704542759, }, attemptId: 1, }, id: 1, }, state: C_NEW, ]
2013-08-28 15:46:22,982 INFO org.apache.hadoop.yarn.server.resourcemanager.rmapp.attempt.RMAppAttemptImpl: appattempt_1377704542759_0002_000001 State change from SCHEDULED to ALLOCATED_SAVING
2013-08-28 15:46:22,982 INFO org.apache.hadoop.yarn.server.resourcemanager.recovery.RMStateStore: Storing info for attempt: appattempt_1377704542759_0002_000001
2013-08-28 15:46:22,984 INFO org.apache.hadoop.yarn.server.resourcemanager.rmapp.attempt.RMAppAttemptImpl: appattempt_1377704542759_0002_000001 State change from ALLOCATED_SAVING to ALLOCATED
2013-08-28 15:46:22,986 INFO org.apache.hadoop.yarn.server.resourcemanager.amlauncher.AMLauncher: Launching masterappattempt_1377704542759_0002_000001
2013-08-28 15:46:22,989 INFO org.apache.hadoop.yarn.server.resourcemanager.amlauncher.AMLauncher: Setting up container Container: [ContainerId: container_1377704542759_0002_01_000001, NodeId: hadoop-16-3:41896, NodeHttpAddress: hadoop-16-3:8042, Resource: <memory:2048, vCores:1>, Priority: 0, State: NEW, Token: null, Status: container_id {, app_attempt_id {, application_id {, id: 2, cluster_timestamp: 1377704542759, }, attemptId: 1, }, id: 1, }, state: C_NEW, ] for AM appattempt_1377704542759_0002_000001
2013-08-28 15:46:22,989 INFO org.apache.hadoop.yarn.server.resourcemanager.amlauncher.AMLauncher: Command to launch container container_1377704542759_0002_01_000001 : $JAVA_HOME/bin/java -Dlog4j.configuration=container-log4j.properties -Dyarn.app.mapreduce.container.log.dir=<LOG_DIR> -Dyarn.app.mapreduce.container.log.filesize=0 -Dhadoop.root.logger=INFO,CLA  -Xmx1024m org.apache.hadoop.mapreduce.v2.app.MRAppMaster 1><LOG_DIR>/stdout 2><LOG_DIR>/stderr 
2013-08-28 15:46:23,013 INFO org.apache.hadoop.yarn.server.resourcemanager.amlauncher.AMLauncher: Done launching container Container: [ContainerId: container_1377704542759_0002_01_000001, NodeId: hadoop-16-3:41896, NodeHttpAddress: hadoop-16-3:8042, Resource: <memory:2048, vCores:1>, Priority: 0, State: NEW, Token: null, Status: container_id {, app_attempt_id {, application_id {, id: 2, cluster_timestamp: 1377704542759, }, attemptId: 1, }, id: 1, }, state: C_NEW, ] for AM appattempt_1377704542759_0002_000001
2013-08-28 15:46:23,014 INFO org.apache.hadoop.yarn.server.resourcemanager.rmapp.attempt.RMAppAttemptImpl: appattempt_1377704542759_0002_000001 State change from ALLOCATED to LAUNCHED
2013-08-28 15:46:23,975 INFO org.apache.hadoop.yarn.server.resourcemanager.rmcontainer.RMContainerImpl: container_1377704542759_0002_01_000001 Container Transitioned from ACQUIRED to RUNNING
2013-08-28 15:46:29,401 INFO org.apache.hadoop.yarn.server.resourcemanager.ApplicationMasterService: AM registration appattempt_1377704542759_0002_000001
2013-08-28 15:46:29,402 INFO org.apache.hadoop.yarn.server.resourcemanager.RMAuditLogger: USER=ubuntu	IP=192.168.100.17	OPERATION=Register App Master	TARGET=ApplicationMasterService	RESULT=SUCCESS	APPID=application_1377704542759_0002	APPATTEMPTID=appattempt_1377704542759_0002_000001
2013-08-28 15:46:29,408 INFO org.apache.hadoop.yarn.server.resourcemanager.rmapp.attempt.RMAppAttemptImpl: appattempt_1377704542759_0002_000001 State change from LAUNCHED to RUNNING
2013-08-28 15:46:29,409 INFO org.apache.hadoop.yarn.server.resourcemanager.rmapp.RMAppImpl: application_1377704542759_0002 State change from ACCEPTED to RUNNING
2013-08-28 15:46:30,611 INFO org.apache.hadoop.yarn.server.resourcemanager.rmcontainer.RMContainerImpl: container_1377704542759_0002_01_000002 Container Transitioned from NEW to ALLOCATED
2013-08-28 15:46:30,611 INFO org.apache.hadoop.yarn.server.resourcemanager.RMAuditLogger: USER=ubuntu	OPERATION=AM Allocated Container	TARGET=SchedulerApp	RESULT=SUCCESS	APPID=application_1377704542759_0002	CONTAINERID=container_1377704542759_0002_01_000002
2013-08-28 15:46:30,611 INFO org.apache.hadoop.yarn.server.resourcemanager.scheduler.common.fica.FiCaSchedulerNode: Assigned container container_1377704542759_0002_01_000002 of capacity <memory:1024, vCores:1> on host hadoop-16-2:39317, which currently has 1 containers, <memory:1024, vCores:1> used and <memory:7168, vCores:15> available
2013-08-28 15:46:30,613 INFO org.apache.hadoop.yarn.server.resourcemanager.scheduler.capacity.LeafQueue: assignedContainer application=application_1377704542759_0002 container=Container: [ContainerId: container_1377704542759_0002_01_000002, NodeId: hadoop-16-2:39317, NodeHttpAddress: hadoop-16-2:8042, Resource: <memory:1024, vCores:1>, Priority: 20, State: NEW, Token: null, Status: container_id {, app_attempt_id {, application_id {, id: 2, cluster_timestamp: 1377704542759, }, attemptId: 1, }, id: 2, }, state: C_NEW, ] containerId=container_1377704542759_0002_01_000002 queue=default: capacity=1.0, absoluteCapacity=1.0, usedResources=<memory:2048, vCores:1>usedCapacity=0.041666668, absoluteUsedCapacity=0.041666668, numApps=1, numContainers=1 usedCapacity=0.041666668 absoluteUsedCapacity=0.041666668 used=<memory:2048, vCores:1> cluster=<memory:49152, vCores:96>
2013-08-28 15:46:30,613 INFO org.apache.hadoop.yarn.server.resourcemanager.scheduler.capacity.ParentQueue: Re-sorting queues since queue: root.default stats: default: capacity=1.0, absoluteCapacity=1.0, usedResources=<memory:3072, vCores:2>usedCapacity=0.0625, absoluteUsedCapacity=0.0625, numApps=1, numContainers=2
2013-08-28 15:46:30,614 INFO org.apache.hadoop.yarn.server.resourcemanager.scheduler.capacity.ParentQueue: assignedContainer queue=root usedCapacity=0.0625 absoluteUsedCapacity=0.0625 used=<memory:3072, vCores:2> cluster=<memory:49152, vCores:96>
2013-08-28 15:46:30,689 INFO org.apache.hadoop.yarn.server.resourcemanager.rmcontainer.RMContainerImpl: container_1377704542759_0002_01_000003 Container Transitioned from NEW to ALLOCATED
2013-08-28 15:46:30,689 INFO org.apache.hadoop.yarn.server.resourcemanager.RMAuditLogger: USER=ubuntu	OPERATION=AM Allocated Container	TARGET=SchedulerApp	RESULT=SUCCESS	APPID=application_1377704542759_0002	CONTAINERID=container_1377704542759_0002_01_000003
2013-08-28 15:46:30,690 INFO org.apache.hadoop.yarn.server.resourcemanager.scheduler.common.fica.FiCaSchedulerNode: Assigned container container_1377704542759_0002_01_000003 of capacity <memory:1024, vCores:1> on host hadoop-16-5:57886, which currently has 1 containers, <memory:1024, vCores:1> used and <memory:7168, vCores:15> available
2013-08-28 15:46:30,691 INFO org.apache.hadoop.yarn.server.resourcemanager.scheduler.capacity.LeafQueue: assignedContainer application=application_1377704542759_0002 container=Container: [ContainerId: container_1377704542759_0002_01_000003, NodeId: hadoop-16-5:57886, NodeHttpAddress: hadoop-16-5:8042, Resource: <memory:1024, vCores:1>, Priority: 20, State: NEW, Token: null, Status: container_id {, app_attempt_id {, application_id {, id: 2, cluster_timestamp: 1377704542759, }, attemptId: 1, }, id: 3, }, state: C_NEW, ] containerId=container_1377704542759_0002_01_000003 queue=default: capacity=1.0, absoluteCapacity=1.0, usedResources=<memory:3072, vCores:2>usedCapacity=0.0625, absoluteUsedCapacity=0.0625, numApps=1, numContainers=2 usedCapacity=0.0625 absoluteUsedCapacity=0.0625 used=<memory:3072, vCores:2> cluster=<memory:49152, vCores:96>
2013-08-28 15:46:30,692 INFO org.apache.hadoop.yarn.server.resourcemanager.scheduler.capacity.ParentQueue: Re-sorting queues since queue: root.default stats: default: capacity=1.0, absoluteCapacity=1.0, usedResources=<memory:4096, vCores:3>usedCapacity=0.083333336, absoluteUsedCapacity=0.083333336, numApps=1, numContainers=3
2013-08-28 15:46:30,692 INFO org.apache.hadoop.yarn.server.resourcemanager.scheduler.capacity.ParentQueue: assignedContainer queue=root usedCapacity=0.083333336 absoluteUsedCapacity=0.083333336 used=<memory:4096, vCores:3> cluster=<memory:49152, vCores:96>
2013-08-28 15:46:31,451 INFO org.apache.hadoop.yarn.server.resourcemanager.rmcontainer.RMContainerImpl: container_1377704542759_0002_01_000002 Container Transitioned from ALLOCATED to ACQUIRED
2013-08-28 15:46:31,452 INFO org.apache.hadoop.yarn.server.resourcemanager.rmcontainer.RMContainerImpl: container_1377704542759_0002_01_000003 Container Transitioned from ALLOCATED to ACQUIRED
2013-08-28 15:46:32,481 INFO org.apache.hadoop.yarn.server.resourcemanager.scheduler.AppSchedulingInfo: checking for deactivate... 
2013-08-28 15:46:32,620 INFO org.apache.hadoop.yarn.server.resourcemanager.rmcontainer.RMContainerImpl: container_1377704542759_0002_01_000002 Container Transitioned from ACQUIRED to RUNNING
2013-08-28 15:46:34,306 INFO org.apache.hadoop.yarn.server.resourcemanager.rmcontainer.RMContainerImpl: container_1377704542759_0002_01_000003 Container Transitioned from ACQUIRED to RUNNING
2013-08-28 15:49:28,845 INFO org.apache.hadoop.yarn.server.resourcemanager.rmcontainer.RMContainerImpl: container_1377704542759_0002_01_000002 Container Transitioned from RUNNING to COMPLETED
2013-08-28 15:49:28,846 INFO org.apache.hadoop.yarn.server.resourcemanager.scheduler.common.fica.FiCaSchedulerApp: Completed container: container_1377704542759_0002_01_000002 in state: COMPLETED event:FINISHED
2013-08-28 15:49:28,846 INFO org.apache.hadoop.yarn.server.resourcemanager.RMAuditLogger: USER=ubuntu	OPERATION=AM Released Container	TARGET=SchedulerApp	RESULT=SUCCESS	APPID=application_1377704542759_0002	CONTAINERID=container_1377704542759_0002_01_000002
2013-08-28 15:49:28,846 INFO org.apache.hadoop.yarn.server.resourcemanager.scheduler.common.fica.FiCaSchedulerNode: Released container container_1377704542759_0002_01_000002 of capacity <memory:1024, vCores:1> on host hadoop-16-2:39317, which currently has 0 containers, <memory:0, vCores:0> used and <memory:8192, vCores:16> available, release resources=true
2013-08-28 15:49:28,846 INFO org.apache.hadoop.yarn.server.resourcemanager.scheduler.capacity.LeafQueue: default used=<memory:3072, vCores:2> numContainers=2 user=ubuntu user-resources=<memory:3072, vCores:2>
2013-08-28 15:49:28,860 INFO org.apache.hadoop.yarn.server.resourcemanager.scheduler.capacity.LeafQueue: completedContainer container=Container: [ContainerId: container_1377704542759_0002_01_000002, NodeId: hadoop-16-2:39317, NodeHttpAddress: hadoop-16-2:8042, Resource: <memory:1024, vCores:1>, Priority: 20, State: NEW, Token: null, Status: container_id {, app_attempt_id {, application_id {, id: 2, cluster_timestamp: 1377704542759, }, attemptId: 1, }, id: 2, }, state: C_COMPLETE, diagnostics: "Container killed by the ApplicationMaster.\n\n", exit_status: 143, ] resource=<memory:1024, vCores:1> queue=default: capacity=1.0, absoluteCapacity=1.0, usedResources=<memory:3072, vCores:2>usedCapacity=0.0625, absoluteUsedCapacity=0.0625, numApps=1, numContainers=2 usedCapacity=0.0625 absoluteUsedCapacity=0.0625 used=<memory:3072, vCores:2> cluster=<memory:49152, vCores:96>
2013-08-28 15:49:28,860 INFO org.apache.hadoop.yarn.server.resourcemanager.scheduler.capacity.ParentQueue: completedContainer queue=root usedCapacity=0.0625 absoluteUsedCapacity=0.0625 used=<memory:3072, vCores:2> cluster=<memory:49152, vCores:96>
2013-08-28 15:49:28,860 INFO org.apache.hadoop.yarn.server.resourcemanager.scheduler.capacity.CapacityScheduler: Application appattempt_1377704542759_0002_000001 released container container_1377704542759_0002_01_000002 on node: host: hadoop-16-2:39317 #containers=0 available=8192 used=0 with event: FINISHED
2013-08-28 15:49:31,975 INFO org.apache.hadoop.yarn.server.resourcemanager.rmcontainer.RMContainerImpl: container_1377704542759_0002_01_000003 Container Transitioned from RUNNING to COMPLETED
2013-08-28 15:49:31,976 INFO org.apache.hadoop.yarn.server.resourcemanager.scheduler.common.fica.FiCaSchedulerApp: Completed container: container_1377704542759_0002_01_000003 in state: COMPLETED event:FINISHED
2013-08-28 15:49:31,976 INFO org.apache.hadoop.yarn.server.resourcemanager.RMAuditLogger: USER=ubuntu	OPERATION=AM Released Container	TARGET=SchedulerApp	RESULT=SUCCESS	APPID=application_1377704542759_0002	CONTAINERID=container_1377704542759_0002_01_000003
2013-08-28 15:49:31,976 INFO org.apache.hadoop.yarn.server.resourcemanager.scheduler.common.fica.FiCaSchedulerNode: Released container container_1377704542759_0002_01_000003 of capacity <memory:1024, vCores:1> on host hadoop-16-5:57886, which currently has 0 containers, <memory:0, vCores:0> used and <memory:8192, vCores:16> available, release resources=true
2013-08-28 15:49:31,976 INFO org.apache.hadoop.yarn.server.resourcemanager.scheduler.capacity.LeafQueue: default used=<memory:2048, vCores:1> numContainers=1 user=ubuntu user-resources=<memory:2048, vCores:1>
2013-08-28 15:49:31,978 INFO org.apache.hadoop.yarn.server.resourcemanager.scheduler.capacity.LeafQueue: completedContainer container=Container: [ContainerId: container_1377704542759_0002_01_000003, NodeId: hadoop-16-5:57886, NodeHttpAddress: hadoop-16-5:8042, Resource: <memory:1024, vCores:1>, Priority: 20, State: NEW, Token: null, Status: container_id {, app_attempt_id {, application_id {, id: 2, cluster_timestamp: 1377704542759, }, attemptId: 1, }, id: 3, }, state: C_COMPLETE, diagnostics: "Container killed by the ApplicationMaster.\n\n", exit_status: 143, ] resource=<memory:1024, vCores:1> queue=default: capacity=1.0, absoluteCapacity=1.0, usedResources=<memory:2048, vCores:1>usedCapacity=0.041666668, absoluteUsedCapacity=0.041666668, numApps=1, numContainers=1 usedCapacity=0.041666668 absoluteUsedCapacity=0.041666668 used=<memory:2048, vCores:1> cluster=<memory:49152, vCores:96>
2013-08-28 15:49:31,979 INFO org.apache.hadoop.yarn.server.resourcemanager.scheduler.capacity.ParentQueue: completedContainer queue=root usedCapacity=0.041666668 absoluteUsedCapacity=0.041666668 used=<memory:2048, vCores:1> cluster=<memory:49152, vCores:96>
2013-08-28 15:49:31,979 INFO org.apache.hadoop.yarn.server.resourcemanager.scheduler.capacity.CapacityScheduler: Application appattempt_1377704542759_0002_000001 released container container_1377704542759_0002_01_000003 on node: host: hadoop-16-5:57886 #containers=0 available=8192 used=0 with event: FINISHED
2013-08-28 15:49:36,128 INFO org.apache.hadoop.yarn.server.resourcemanager.rmapp.attempt.RMAppAttemptImpl: appattempt_1377704542759_0002_000001 State change from RUNNING to FINISHING
2013-08-28 15:49:36,129 INFO org.apache.hadoop.yarn.server.resourcemanager.rmapp.RMAppImpl: application_1377704542759_0002 State change from RUNNING to FINISHING
2013-08-28 15:49:37,288 INFO org.apache.hadoop.yarn.server.resourcemanager.rmcontainer.RMContainerImpl: container_1377704542759_0002_01_000001 Container Transitioned from RUNNING to COMPLETED
2013-08-28 15:49:37,289 INFO org.apache.hadoop.yarn.server.resourcemanager.scheduler.common.fica.FiCaSchedulerApp: Completed container: container_1377704542759_0002_01_000001 in state: COMPLETED event:FINISHED
2013-08-28 15:49:37,289 INFO org.apache.hadoop.yarn.server.resourcemanager.RMAuditLogger: USER=ubuntu	OPERATION=AM Released Container	TARGET=SchedulerApp	RESULT=SUCCESS	APPID=application_1377704542759_0002	CONTAINERID=container_1377704542759_0002_01_000001
2013-08-28 15:49:37,289 INFO org.apache.hadoop.yarn.server.resourcemanager.scheduler.common.fica.FiCaSchedulerNode: Released container container_1377704542759_0002_01_000001 of capacity <memory:2048, vCores:1> on host hadoop-16-3:41896, which currently has 0 containers, <memory:0, vCores:0> used and <memory:8192, vCores:16> available, release resources=true
2013-08-28 15:49:37,289 INFO org.apache.hadoop.yarn.server.resourcemanager.scheduler.capacity.LeafQueue: default used=<memory:0, vCores:0> numContainers=0 user=ubuntu user-resources=<memory:0, vCores:0>
2013-08-28 15:49:37,291 INFO org.apache.hadoop.yarn.server.resourcemanager.scheduler.capacity.LeafQueue: completedContainer container=Container: [ContainerId: container_1377704542759_0002_01_000001, NodeId: hadoop-16-3:41896, NodeHttpAddress: hadoop-16-3:8042, Resource: <memory:2048, vCores:1>, Priority: 0, State: NEW, Token: null, Status: container_id {, app_attempt_id {, application_id {, id: 2, cluster_timestamp: 1377704542759, }, attemptId: 1, }, id: 1, }, state: C_COMPLETE, diagnostics: "", exit_status: 0, ] resource=<memory:2048, vCores:1> queue=default: capacity=1.0, absoluteCapacity=1.0, usedResources=<memory:0, vCores:0>usedCapacity=0.0, absoluteUsedCapacity=0.0, numApps=1, numContainers=0 usedCapacity=0.0 absoluteUsedCapacity=0.0 used=<memory:0, vCores:0> cluster=<memory:49152, vCores:96>
2013-08-28 15:49:37,291 INFO org.apache.hadoop.yarn.server.resourcemanager.scheduler.capacity.ParentQueue: completedContainer queue=root usedCapacity=0.0 absoluteUsedCapacity=0.0 used=<memory:0, vCores:0> cluster=<memory:49152, vCores:96>
2013-08-28 15:49:37,291 INFO org.apache.hadoop.yarn.server.resourcemanager.scheduler.capacity.CapacityScheduler: Application appattempt_1377704542759_0002_000001 released container container_1377704542759_0002_01_000001 on node: host: hadoop-16-3:41896 #containers=0 available=8192 used=0 with event: FINISHED
2013-08-28 15:49:37,291 INFO org.apache.hadoop.yarn.server.resourcemanager.rmapp.attempt.RMAppAttemptImpl: appattempt_1377704542759_0002_000001 State change from FINISHING to FINISHED
2013-08-28 15:49:37,292 INFO org.apache.hadoop.yarn.server.resourcemanager.rmapp.RMAppImpl: application_1377704542759_0002 State change from FINISHING to FINISHED
2013-08-28 15:49:37,292 INFO org.apache.hadoop.yarn.server.resourcemanager.scheduler.capacity.CapacityScheduler: Application appattempt_1377704542759_0002_000001 is done. finalState=FINISHED
2013-08-28 15:49:37,292 INFO org.apache.hadoop.yarn.server.resourcemanager.scheduler.AppSchedulingInfo: Application application_1377704542759_0002 requests cleared
2013-08-28 15:49:37,293 INFO org.apache.hadoop.yarn.server.resourcemanager.scheduler.capacity.LeafQueue: Application removed - appId: application_1377704542759_0002 user: ubuntu queue: default #user-pending-applications: 0 #user-active-applications: 0 #queue-pending-applications: 0 #queue-active-applications: 0
2013-08-28 15:49:37,293 INFO org.apache.hadoop.yarn.server.resourcemanager.scheduler.capacity.ParentQueue: Application removed - appId: application_1377704542759_0002 user: ubuntu leaf-queue of parent: root #applications: 0
2013-08-28 15:49:37,293 INFO org.apache.hadoop.yarn.server.resourcemanager.RMAuditLogger: USER=ubuntu	OPERATION=Application Finished - Succeeded	TARGET=RMAppManager	RESULT=SUCCESS	APPID=application_1377704542759_0002
2013-08-28 15:49:37,293 INFO org.apache.hadoop.yarn.server.resourcemanager.recovery.RMStateStore: Removing info for app: application_1377704542759_0002
2013-08-28 15:49:37,294 INFO org.apache.hadoop.yarn.server.resourcemanager.RMAppManager$ApplicationSummary: appId=application_1377704542759_0002,name=TeraGen,user=ubuntu,queue=default,state=FINISHED,trackingUrl=hadoop-16-1.novalocal:8088/proxy/application_1377704542759_0002/jobhistory/job/job_1377704542759_0002,appMasterHost=hadoop-16-3,startTime=1377704782840,finishTime=1377704976129
2013-08-28 15:49:37,294 INFO org.apache.hadoop.yarn.server.resourcemanager.amlauncher.AMLauncher: Cleaning master appattempt_1377704542759_0002_000001
2013-08-28 15:49:37,777 INFO org.apache.hadoop.yarn.server.resourcemanager.ClientRMService: Allocated new applicationId: 3
2013-08-28 15:49:39,559 INFO org.apache.hadoop.yarn.server.resourcemanager.ClientRMService: Storing Application with id application_1377704542759_0003
2013-08-28 15:49:39,559 INFO org.apache.hadoop.yarn.server.resourcemanager.recovery.RMStateStore: Storing info for app: application_1377704542759_0003
2013-08-28 15:49:39,559 INFO org.apache.hadoop.yarn.server.resourcemanager.ClientRMService: Application with id 3 submitted by user ubuntu
2013-08-28 15:49:39,560 INFO org.apache.hadoop.yarn.server.resourcemanager.RMAuditLogger: USER=ubuntu	IP=192.168.100.5	OPERATION=Submit Application Request	TARGET=ClientRMService	RESULT=SUCCESS	APPID=application_1377704542759_0003
2013-08-28 15:49:39,560 INFO org.apache.hadoop.yarn.server.resourcemanager.rmapp.RMAppImpl: application_1377704542759_0003 State change from NEW to SUBMITTED
2013-08-28 15:49:39,560 INFO org.apache.hadoop.yarn.server.resourcemanager.ApplicationMasterService: Registering appattempt_1377704542759_0003_000001
2013-08-28 15:49:39,560 INFO org.apache.hadoop.yarn.server.resourcemanager.rmapp.attempt.RMAppAttemptImpl: appattempt_1377704542759_0003_000001 State change from NEW to SUBMITTED
2013-08-28 15:49:39,561 INFO org.apache.hadoop.yarn.server.resourcemanager.scheduler.capacity.LeafQueue: Application application_1377704542759_0003 from user: ubuntu activated in queue: default
2013-08-28 15:49:39,561 INFO org.apache.hadoop.yarn.server.resourcemanager.scheduler.capacity.LeafQueue: Application added - appId: application_1377704542759_0003 user: org.apache.hadoop.yarn.server.resourcemanager.scheduler.capacity.LeafQueue$User@c27326e, leaf-queue: default #user-pending-applications: 0 #user-active-applications: 1 #queue-pending-applications: 0 #queue-active-applications: 1
2013-08-28 15:49:39,561 INFO org.apache.hadoop.yarn.server.resourcemanager.scheduler.capacity.ParentQueue: Application added - appId: application_1377704542759_0003 user: ubuntu leaf-queue of parent: root #applications: 1
2013-08-28 15:49:39,561 INFO org.apache.hadoop.yarn.server.resourcemanager.scheduler.capacity.CapacityScheduler: Application Submission: appattempt_1377704542759_0003_000001, user: ubuntu queue: default: capacity=1.0, absoluteCapacity=1.0, usedResources=<memory:0, vCores:0>usedCapacity=0.0, absoluteUsedCapacity=0.0, numApps=1, numContainers=0, currently active: 1
2013-08-28 15:49:39,562 INFO org.apache.hadoop.yarn.server.resourcemanager.rmapp.attempt.RMAppAttemptImpl: appattempt_1377704542759_0003_000001 State change from SUBMITTED to SCHEDULED
2013-08-28 15:49:39,562 INFO org.apache.hadoop.yarn.server.resourcemanager.rmapp.RMAppImpl: application_1377704542759_0003 State change from SUBMITTED to ACCEPTED
2013-08-28 15:49:39,600 INFO org.apache.hadoop.yarn.server.resourcemanager.rmcontainer.RMContainerImpl: container_1377704542759_0003_01_000001 Container Transitioned from NEW to ALLOCATED
2013-08-28 15:49:39,600 INFO org.apache.hadoop.yarn.server.resourcemanager.RMAuditLogger: USER=ubuntu	OPERATION=AM Allocated Container	TARGET=SchedulerApp	RESULT=SUCCESS	APPID=application_1377704542759_0003	CONTAINERID=container_1377704542759_0003_01_000001
2013-08-28 15:49:39,600 INFO org.apache.hadoop.yarn.server.resourcemanager.scheduler.common.fica.FiCaSchedulerNode: Assigned container container_1377704542759_0003_01_000001 of capacity <memory:2048, vCores:1> on host hadoop-16-4:52495, which currently has 1 containers, <memory:2048, vCores:1> used and <memory:6144, vCores:15> available
2013-08-28 15:49:39,602 INFO org.apache.hadoop.yarn.server.resourcemanager.scheduler.capacity.LeafQueue: assignedContainer application=application_1377704542759_0003 container=Container: [ContainerId: container_1377704542759_0003_01_000001, NodeId: hadoop-16-4:52495, NodeHttpAddress: hadoop-16-4:8042, Resource: <memory:2048, vCores:1>, Priority: 0, State: NEW, Token: null, Status: container_id {, app_attempt_id {, application_id {, id: 3, cluster_timestamp: 1377704542759, }, attemptId: 1, }, id: 1, }, state: C_NEW, ] containerId=container_1377704542759_0003_01_000001 queue=default: capacity=1.0, absoluteCapacity=1.0, usedResources=<memory:0, vCores:0>usedCapacity=0.0, absoluteUsedCapacity=0.0, numApps=1, numContainers=0 usedCapacity=0.0 absoluteUsedCapacity=0.0 used=<memory:0, vCores:0> cluster=<memory:49152, vCores:96>
2013-08-28 15:49:39,602 INFO org.apache.hadoop.yarn.server.resourcemanager.scheduler.capacity.ParentQueue: Re-sorting queues since queue: root.default stats: default: capacity=1.0, absoluteCapacity=1.0, usedResources=<memory:2048, vCores:1>usedCapacity=0.041666668, absoluteUsedCapacity=0.041666668, numApps=1, numContainers=1
2013-08-28 15:49:39,602 INFO org.apache.hadoop.yarn.server.resourcemanager.scheduler.capacity.ParentQueue: assignedContainer queue=root usedCapacity=0.041666668 absoluteUsedCapacity=0.041666668 used=<memory:2048, vCores:1> cluster=<memory:49152, vCores:96>
2013-08-28 15:49:39,603 INFO org.apache.hadoop.yarn.server.resourcemanager.rmcontainer.RMContainerImpl: container_1377704542759_0003_01_000001 Container Transitioned from ALLOCATED to ACQUIRED
2013-08-28 15:49:39,604 INFO org.apache.hadoop.yarn.server.resourcemanager.rmapp.attempt.RMAppAttemptImpl: Storing attempt: AppId: application_1377704542759_0003 AttemptId: appattempt_1377704542759_0003_000001 MasterContainer: Container: [ContainerId: container_1377704542759_0003_01_000001, NodeId: hadoop-16-4:52495, NodeHttpAddress: hadoop-16-4:8042, Resource: <memory:2048, vCores:1>, Priority: 0, State: NEW, Token: null, Status: container_id {, app_attempt_id {, application_id {, id: 3, cluster_timestamp: 1377704542759, }, attemptId: 1, }, id: 1, }, state: C_NEW, ]
2013-08-28 15:49:39,605 INFO org.apache.hadoop.yarn.server.resourcemanager.recovery.RMStateStore: Storing info for attempt: appattempt_1377704542759_0003_000001
2013-08-28 15:49:39,605 INFO org.apache.hadoop.yarn.server.resourcemanager.rmapp.attempt.RMAppAttemptImpl: appattempt_1377704542759_0003_000001 State change from SCHEDULED to ALLOCATED_SAVING
2013-08-28 15:49:39,605 INFO org.apache.hadoop.yarn.server.resourcemanager.rmapp.attempt.RMAppAttemptImpl: appattempt_1377704542759_0003_000001 State change from ALLOCATED_SAVING to ALLOCATED
2013-08-28 15:49:39,607 INFO org.apache.hadoop.yarn.server.resourcemanager.amlauncher.AMLauncher: Launching masterappattempt_1377704542759_0003_000001
2013-08-28 15:49:39,609 INFO org.apache.hadoop.yarn.server.resourcemanager.amlauncher.AMLauncher: Setting up container Container: [ContainerId: container_1377704542759_0003_01_000001, NodeId: hadoop-16-4:52495, NodeHttpAddress: hadoop-16-4:8042, Resource: <memory:2048, vCores:1>, Priority: 0, State: NEW, Token: null, Status: container_id {, app_attempt_id {, application_id {, id: 3, cluster_timestamp: 1377704542759, }, attemptId: 1, }, id: 1, }, state: C_NEW, ] for AM appattempt_1377704542759_0003_000001
2013-08-28 15:49:39,609 INFO org.apache.hadoop.yarn.server.resourcemanager.amlauncher.AMLauncher: Command to launch container container_1377704542759_0003_01_000001 : $JAVA_HOME/bin/java -Dlog4j.configuration=container-log4j.properties -Dyarn.app.mapreduce.container.log.dir=<LOG_DIR> -Dyarn.app.mapreduce.container.log.filesize=0 -Dhadoop.root.logger=INFO,CLA  -Xmx1024m org.apache.hadoop.mapreduce.v2.app.MRAppMaster 1><LOG_DIR>/stdout 2><LOG_DIR>/stderr 
2013-08-28 15:49:40,419 INFO org.apache.hadoop.yarn.server.resourcemanager.amlauncher.AMLauncher: Done launching container Container: [ContainerId: container_1377704542759_0003_01_000001, NodeId: hadoop-16-4:52495, NodeHttpAddress: hadoop-16-4:8042, Resource: <memory:2048, vCores:1>, Priority: 0, State: NEW, Token: null, Status: container_id {, app_attempt_id {, application_id {, id: 3, cluster_timestamp: 1377704542759, }, attemptId: 1, }, id: 1, }, state: C_NEW, ] for AM appattempt_1377704542759_0003_000001
2013-08-28 15:49:40,420 INFO org.apache.hadoop.yarn.server.resourcemanager.rmapp.attempt.RMAppAttemptImpl: appattempt_1377704542759_0003_000001 State change from ALLOCATED to LAUNCHED
2013-08-28 15:49:40,687 INFO org.apache.hadoop.yarn.server.resourcemanager.rmcontainer.RMContainerImpl: container_1377704542759_0003_01_000001 Container Transitioned from ACQUIRED to RUNNING
2013-08-28 15:49:49,888 INFO org.apache.hadoop.yarn.server.resourcemanager.ApplicationMasterService: AM registration appattempt_1377704542759_0003_000001
2013-08-28 15:49:49,889 INFO org.apache.hadoop.yarn.server.resourcemanager.RMAuditLogger: USER=ubuntu	IP=192.168.100.18	OPERATION=Register App Master	TARGET=ApplicationMasterService	RESULT=SUCCESS	APPID=application_1377704542759_0003	APPATTEMPTID=appattempt_1377704542759_0003_000001
2013-08-28 15:49:49,890 INFO org.apache.hadoop.yarn.server.resourcemanager.rmapp.attempt.RMAppAttemptImpl: appattempt_1377704542759_0003_000001 State change from LAUNCHED to RUNNING
2013-08-28 15:49:49,890 INFO org.apache.hadoop.yarn.server.resourcemanager.rmapp.RMAppImpl: application_1377704542759_0003 State change from ACCEPTED to RUNNING
2013-08-28 15:49:51,049 INFO org.apache.hadoop.yarn.server.resourcemanager.rmcontainer.RMContainerImpl: container_1377704542759_0003_01_000002 Container Transitioned from NEW to ALLOCATED
2013-08-28 15:49:51,049 INFO org.apache.hadoop.yarn.server.resourcemanager.RMAuditLogger: USER=ubuntu	OPERATION=AM Allocated Container	TARGET=SchedulerApp	RESULT=SUCCESS	APPID=application_1377704542759_0003	CONTAINERID=container_1377704542759_0003_01_000002
2013-08-28 15:49:51,050 INFO org.apache.hadoop.yarn.server.resourcemanager.scheduler.common.fica.FiCaSchedulerNode: Assigned container container_1377704542759_0003_01_000002 of capacity <memory:1024, vCores:1> on host hadoop-16-5:57886, which currently has 1 containers, <memory:1024, vCores:1> used and <memory:7168, vCores:15> available
2013-08-28 15:49:51,051 INFO org.apache.hadoop.yarn.server.resourcemanager.scheduler.capacity.LeafQueue: assignedContainer application=application_1377704542759_0003 container=Container: [ContainerId: container_1377704542759_0003_01_000002, NodeId: hadoop-16-5:57886, NodeHttpAddress: hadoop-16-5:8042, Resource: <memory:1024, vCores:1>, Priority: 20, State: NEW, Token: null, Status: container_id {, app_attempt_id {, application_id {, id: 3, cluster_timestamp: 1377704542759, }, attemptId: 1, }, id: 2, }, state: C_NEW, ] containerId=container_1377704542759_0003_01_000002 queue=default: capacity=1.0, absoluteCapacity=1.0, usedResources=<memory:2048, vCores:1>usedCapacity=0.041666668, absoluteUsedCapacity=0.041666668, numApps=1, numContainers=1 usedCapacity=0.041666668 absoluteUsedCapacity=0.041666668 used=<memory:2048, vCores:1> cluster=<memory:49152, vCores:96>
2013-08-28 15:49:51,052 INFO org.apache.hadoop.yarn.server.resourcemanager.scheduler.capacity.ParentQueue: Re-sorting queues since queue: root.default stats: default: capacity=1.0, absoluteCapacity=1.0, usedResources=<memory:3072, vCores:2>usedCapacity=0.0625, absoluteUsedCapacity=0.0625, numApps=1, numContainers=2
2013-08-28 15:49:51,052 INFO org.apache.hadoop.yarn.server.resourcemanager.scheduler.capacity.ParentQueue: assignedContainer queue=root usedCapacity=0.0625 absoluteUsedCapacity=0.0625 used=<memory:3072, vCores:2> cluster=<memory:49152, vCores:96>
2013-08-28 15:49:51,337 INFO org.apache.hadoop.yarn.server.resourcemanager.rmcontainer.RMContainerImpl: container_1377704542759_0003_01_000003 Container Transitioned from NEW to ALLOCATED
2013-08-28 15:49:51,338 INFO org.apache.hadoop.yarn.server.resourcemanager.RMAuditLogger: USER=ubuntu	OPERATION=AM Allocated Container	TARGET=SchedulerApp	RESULT=SUCCESS	APPID=application_1377704542759_0003	CONTAINERID=container_1377704542759_0003_01_000003
2013-08-28 15:49:51,338 INFO org.apache.hadoop.yarn.server.resourcemanager.scheduler.common.fica.FiCaSchedulerNode: Assigned container container_1377704542759_0003_01_000003 of capacity <memory:1024, vCores:1> on host hadoop-16-3:41896, which currently has 1 containers, <memory:1024, vCores:1> used and <memory:7168, vCores:15> available
2013-08-28 15:49:51,340 INFO org.apache.hadoop.yarn.server.resourcemanager.scheduler.capacity.LeafQueue: assignedContainer application=application_1377704542759_0003 container=Container: [ContainerId: container_1377704542759_0003_01_000003, NodeId: hadoop-16-3:41896, NodeHttpAddress: hadoop-16-3:8042, Resource: <memory:1024, vCores:1>, Priority: 20, State: NEW, Token: null, Status: container_id {, app_attempt_id {, application_id {, id: 3, cluster_timestamp: 1377704542759, }, attemptId: 1, }, id: 3, }, state: C_NEW, ] containerId=container_1377704542759_0003_01_000003 queue=default: capacity=1.0, absoluteCapacity=1.0, usedResources=<memory:3072, vCores:2>usedCapacity=0.0625, absoluteUsedCapacity=0.0625, numApps=1, numContainers=2 usedCapacity=0.0625 absoluteUsedCapacity=0.0625 used=<memory:3072, vCores:2> cluster=<memory:49152, vCores:96>
2013-08-28 15:49:51,340 INFO org.apache.hadoop.yarn.server.resourcemanager.scheduler.capacity.ParentQueue: Re-sorting queues since queue: root.default stats: default: capacity=1.0, absoluteCapacity=1.0, usedResources=<memory:4096, vCores:3>usedCapacity=0.083333336, absoluteUsedCapacity=0.083333336, numApps=1, numContainers=3
2013-08-28 15:49:51,340 INFO org.apache.hadoop.yarn.server.resourcemanager.scheduler.capacity.ParentQueue: assignedContainer queue=root usedCapacity=0.083333336 absoluteUsedCapacity=0.083333336 used=<memory:4096, vCores:3> cluster=<memory:49152, vCores:96>
2013-08-28 15:49:51,961 INFO org.apache.hadoop.yarn.server.resourcemanager.rmcontainer.RMContainerImpl: container_1377704542759_0003_01_000002 Container Transitioned from ALLOCATED to ACQUIRED
2013-08-28 15:49:51,963 INFO org.apache.hadoop.yarn.server.resourcemanager.rmcontainer.RMContainerImpl: container_1377704542759_0003_01_000003 Container Transitioned from ALLOCATED to ACQUIRED
2013-08-28 15:49:52,343 INFO org.apache.hadoop.yarn.server.resourcemanager.rmcontainer.RMContainerImpl: container_1377704542759_0003_01_000003 Container Transitioned from ACQUIRED to RUNNING
2013-08-28 15:49:52,991 INFO org.apache.hadoop.yarn.server.resourcemanager.scheduler.AppSchedulingInfo: checking for deactivate... 
2013-08-28 15:49:53,059 INFO org.apache.hadoop.yarn.server.resourcemanager.rmcontainer.RMContainerImpl: container_1377704542759_0003_01_000002 Container Transitioned from ACQUIRED to RUNNING
2013-08-28 15:52:42,640 INFO org.apache.hadoop.yarn.server.resourcemanager.rmcontainer.RMContainerImpl: container_1377704542759_0003_01_000002 Container Transitioned from RUNNING to COMPLETED
2013-08-28 15:52:42,641 INFO org.apache.hadoop.yarn.server.resourcemanager.scheduler.common.fica.FiCaSchedulerApp: Completed container: container_1377704542759_0003_01_000002 in state: COMPLETED event:FINISHED
2013-08-28 15:52:42,641 INFO org.apache.hadoop.yarn.server.resourcemanager.RMAuditLogger: USER=ubuntu	OPERATION=AM Released Container	TARGET=SchedulerApp	RESULT=SUCCESS	APPID=application_1377704542759_0003	CONTAINERID=container_1377704542759_0003_01_000002
2013-08-28 15:52:42,641 INFO org.apache.hadoop.yarn.server.resourcemanager.scheduler.common.fica.FiCaSchedulerNode: Released container container_1377704542759_0003_01_000002 of capacity <memory:1024, vCores:1> on host hadoop-16-5:57886, which currently has 0 containers, <memory:0, vCores:0> used and <memory:8192, vCores:16> available, release resources=true
2013-08-28 15:52:42,641 INFO org.apache.hadoop.yarn.server.resourcemanager.scheduler.capacity.LeafQueue: default used=<memory:3072, vCores:2> numContainers=2 user=ubuntu user-resources=<memory:3072, vCores:2>
2013-08-28 15:52:42,643 INFO org.apache.hadoop.yarn.server.resourcemanager.scheduler.capacity.LeafQueue: completedContainer container=Container: [ContainerId: container_1377704542759_0003_01_000002, NodeId: hadoop-16-5:57886, NodeHttpAddress: hadoop-16-5:8042, Resource: <memory:1024, vCores:1>, Priority: 20, State: NEW, Token: null, Status: container_id {, app_attempt_id {, application_id {, id: 3, cluster_timestamp: 1377704542759, }, attemptId: 1, }, id: 2, }, state: C_COMPLETE, diagnostics: "Container killed by the ApplicationMaster.\n\n", exit_status: 143, ] resource=<memory:1024, vCores:1> queue=default: capacity=1.0, absoluteCapacity=1.0, usedResources=<memory:3072, vCores:2>usedCapacity=0.0625, absoluteUsedCapacity=0.0625, numApps=1, numContainers=2 usedCapacity=0.0625 absoluteUsedCapacity=0.0625 used=<memory:3072, vCores:2> cluster=<memory:49152, vCores:96>
2013-08-28 15:52:42,643 INFO org.apache.hadoop.yarn.server.resourcemanager.scheduler.capacity.ParentQueue: completedContainer queue=root usedCapacity=0.0625 absoluteUsedCapacity=0.0625 used=<memory:3072, vCores:2> cluster=<memory:49152, vCores:96>
2013-08-28 15:52:42,643 INFO org.apache.hadoop.yarn.server.resourcemanager.scheduler.capacity.CapacityScheduler: Application appattempt_1377704542759_0003_000001 released container container_1377704542759_0003_01_000002 on node: host: hadoop-16-5:57886 #containers=0 available=8192 used=0 with event: FINISHED
2013-08-28 15:52:53,063 INFO org.apache.hadoop.yarn.server.resourcemanager.rmcontainer.RMContainerImpl: container_1377704542759_0003_01_000003 Container Transitioned from RUNNING to COMPLETED
2013-08-28 15:52:53,063 INFO org.apache.hadoop.yarn.server.resourcemanager.scheduler.common.fica.FiCaSchedulerApp: Completed container: container_1377704542759_0003_01_000003 in state: COMPLETED event:FINISHED
2013-08-28 15:52:53,063 INFO org.apache.hadoop.yarn.server.resourcemanager.RMAuditLogger: USER=ubuntu	OPERATION=AM Released Container	TARGET=SchedulerApp	RESULT=SUCCESS	APPID=application_1377704542759_0003	CONTAINERID=container_1377704542759_0003_01_000003
2013-08-28 15:52:53,063 INFO org.apache.hadoop.yarn.server.resourcemanager.scheduler.common.fica.FiCaSchedulerNode: Released container container_1377704542759_0003_01_000003 of capacity <memory:1024, vCores:1> on host hadoop-16-3:41896, which currently has 0 containers, <memory:0, vCores:0> used and <memory:8192, vCores:16> available, release resources=true
2013-08-28 15:52:53,063 INFO org.apache.hadoop.yarn.server.resourcemanager.scheduler.capacity.LeafQueue: default used=<memory:2048, vCores:1> numContainers=1 user=ubuntu user-resources=<memory:2048, vCores:1>
2013-08-28 15:52:53,065 INFO org.apache.hadoop.yarn.server.resourcemanager.scheduler.capacity.LeafQueue: completedContainer container=Container: [ContainerId: container_1377704542759_0003_01_000003, NodeId: hadoop-16-3:41896, NodeHttpAddress: hadoop-16-3:8042, Resource: <memory:1024, vCores:1>, Priority: 20, State: NEW, Token: null, Status: container_id {, app_attempt_id {, application_id {, id: 3, cluster_timestamp: 1377704542759, }, attemptId: 1, }, id: 3, }, state: C_COMPLETE, diagnostics: "Container killed by the ApplicationMaster.\n\n", exit_status: 143, ] resource=<memory:1024, vCores:1> queue=default: capacity=1.0, absoluteCapacity=1.0, usedResources=<memory:2048, vCores:1>usedCapacity=0.041666668, absoluteUsedCapacity=0.041666668, numApps=1, numContainers=1 usedCapacity=0.041666668 absoluteUsedCapacity=0.041666668 used=<memory:2048, vCores:1> cluster=<memory:49152, vCores:96>
2013-08-28 15:52:53,065 INFO org.apache.hadoop.yarn.server.resourcemanager.scheduler.capacity.ParentQueue: completedContainer queue=root usedCapacity=0.041666668 absoluteUsedCapacity=0.041666668 used=<memory:2048, vCores:1> cluster=<memory:49152, vCores:96>
2013-08-28 15:52:53,065 INFO org.apache.hadoop.yarn.server.resourcemanager.scheduler.capacity.CapacityScheduler: Application appattempt_1377704542759_0003_000001 released container container_1377704542759_0003_01_000003 on node: host: hadoop-16-3:41896 #containers=0 available=8192 used=0 with event: FINISHED
2013-08-28 15:52:57,233 INFO org.apache.hadoop.yarn.server.resourcemanager.rmapp.attempt.RMAppAttemptImpl: appattempt_1377704542759_0003_000001 State change from RUNNING to FINISHING
2013-08-28 15:52:57,234 INFO org.apache.hadoop.yarn.server.resourcemanager.rmapp.RMAppImpl: application_1377704542759_0003 State change from RUNNING to FINISHING
2013-08-28 15:52:57,985 INFO org.apache.hadoop.yarn.server.resourcemanager.rmcontainer.RMContainerImpl: container_1377704542759_0003_01_000001 Container Transitioned from RUNNING to COMPLETED
2013-08-28 15:52:57,985 INFO org.apache.hadoop.yarn.server.resourcemanager.scheduler.common.fica.FiCaSchedulerApp: Completed container: container_1377704542759_0003_01_000001 in state: COMPLETED event:FINISHED
2013-08-28 15:52:57,985 INFO org.apache.hadoop.yarn.server.resourcemanager.rmapp.attempt.RMAppAttemptImpl: appattempt_1377704542759_0003_000001 State change from FINISHING to FINISHED
2013-08-28 15:52:57,985 INFO org.apache.hadoop.yarn.server.resourcemanager.RMAuditLogger: USER=ubuntu	OPERATION=AM Released Container	TARGET=SchedulerApp	RESULT=SUCCESS	APPID=application_1377704542759_0003	CONTAINERID=container_1377704542759_0003_01_000001
2013-08-28 15:52:57,985 INFO org.apache.hadoop.yarn.server.resourcemanager.rmapp.RMAppImpl: application_1377704542759_0003 State change from FINISHING to FINISHED
2013-08-28 15:52:57,985 INFO org.apache.hadoop.yarn.server.resourcemanager.scheduler.common.fica.FiCaSchedulerNode: Released container container_1377704542759_0003_01_000001 of capacity <memory:2048, vCores:1> on host hadoop-16-4:52495, which currently has 0 containers, <memory:0, vCores:0> used and <memory:8192, vCores:16> available, release resources=true
2013-08-28 15:52:57,985 INFO org.apache.hadoop.yarn.server.resourcemanager.scheduler.capacity.LeafQueue: default used=<memory:0, vCores:0> numContainers=0 user=ubuntu user-resources=<memory:0, vCores:0>
2013-08-28 15:52:57,985 INFO org.apache.hadoop.yarn.server.resourcemanager.RMAuditLogger: USER=ubuntu	OPERATION=Application Finished - Succeeded	TARGET=RMAppManager	RESULT=SUCCESS	APPID=application_1377704542759_0003
2013-08-28 15:52:57,985 INFO org.apache.hadoop.yarn.server.resourcemanager.RMAppManager$ApplicationSummary: appId=application_1377704542759_0003,name=TeraGen,user=ubuntu,queue=default,state=FINISHED,trackingUrl=hadoop-16-1.novalocal:8088/proxy/application_1377704542759_0003/jobhistory/job/job_1377704542759_0003,appMasterHost=hadoop-16-4,startTime=1377704979559,finishTime=1377705177234
2013-08-28 15:52:57,985 INFO org.apache.hadoop.yarn.server.resourcemanager.recovery.RMStateStore: Removing info for app: application_1377704542759_0003
2013-08-28 15:52:57,986 INFO org.apache.hadoop.yarn.server.resourcemanager.scheduler.capacity.LeafQueue: completedContainer container=Container: [ContainerId: container_1377704542759_0003_01_000001, NodeId: hadoop-16-4:52495, NodeHttpAddress: hadoop-16-4:8042, Resource: <memory:2048, vCores:1>, Priority: 0, State: NEW, Token: null, Status: container_id {, app_attempt_id {, application_id {, id: 3, cluster_timestamp: 1377704542759, }, attemptId: 1, }, id: 1, }, state: C_COMPLETE, diagnostics: "", exit_status: 0, ] resource=<memory:2048, vCores:1> queue=default: capacity=1.0, absoluteCapacity=1.0, usedResources=<memory:0, vCores:0>usedCapacity=0.0, absoluteUsedCapacity=0.0, numApps=1, numContainers=0 usedCapacity=0.0 absoluteUsedCapacity=0.0 used=<memory:0, vCores:0> cluster=<memory:49152, vCores:96>
2013-08-28 15:52:57,986 INFO org.apache.hadoop.yarn.server.resourcemanager.scheduler.capacity.ParentQueue: completedContainer queue=root usedCapacity=0.0 absoluteUsedCapacity=0.0 used=<memory:0, vCores:0> cluster=<memory:49152, vCores:96>
2013-08-28 15:52:57,986 INFO org.apache.hadoop.yarn.server.resourcemanager.scheduler.capacity.CapacityScheduler: Application appattempt_1377704542759_0003_000001 released container container_1377704542759_0003_01_000001 on node: host: hadoop-16-4:52495 #containers=0 available=8192 used=0 with event: FINISHED
2013-08-28 15:52:57,986 INFO org.apache.hadoop.yarn.server.resourcemanager.scheduler.capacity.CapacityScheduler: Application appattempt_1377704542759_0003_000001 is done. finalState=FINISHED
2013-08-28 15:52:57,986 INFO org.apache.hadoop.yarn.server.resourcemanager.scheduler.AppSchedulingInfo: Application application_1377704542759_0003 requests cleared
2013-08-28 15:52:57,986 INFO org.apache.hadoop.yarn.server.resourcemanager.scheduler.capacity.LeafQueue: Application removed - appId: application_1377704542759_0003 user: ubuntu queue: default #user-pending-applications: 0 #user-active-applications: 0 #queue-pending-applications: 0 #queue-active-applications: 0
2013-08-28 15:52:57,986 INFO org.apache.hadoop.yarn.server.resourcemanager.scheduler.capacity.ParentQueue: Application removed - appId: application_1377704542759_0003 user: ubuntu leaf-queue of parent: root #applications: 0
2013-08-28 15:52:57,987 INFO org.apache.hadoop.yarn.server.resourcemanager.amlauncher.AMLauncher: Cleaning master appattempt_1377704542759_0003_000001
2013-08-28 15:52:58,452 INFO org.apache.hadoop.yarn.server.resourcemanager.ClientRMService: Allocated new applicationId: 4
2013-08-28 15:53:00,407 INFO org.apache.hadoop.yarn.server.resourcemanager.ClientRMService: Storing Application with id application_1377704542759_0004
2013-08-28 15:53:00,407 INFO org.apache.hadoop.yarn.server.resourcemanager.recovery.RMStateStore: Storing info for app: application_1377704542759_0004
2013-08-28 15:53:00,408 INFO org.apache.hadoop.yarn.server.resourcemanager.ClientRMService: Application with id 4 submitted by user ubuntu
2013-08-28 15:53:00,408 INFO org.apache.hadoop.yarn.server.resourcemanager.RMAuditLogger: USER=ubuntu	IP=192.168.100.5	OPERATION=Submit Application Request	TARGET=ClientRMService	RESULT=SUCCESS	APPID=application_1377704542759_0004
2013-08-28 15:53:00,408 INFO org.apache.hadoop.yarn.server.resourcemanager.rmapp.RMAppImpl: application_1377704542759_0004 State change from NEW to SUBMITTED
2013-08-28 15:53:00,408 INFO org.apache.hadoop.yarn.server.resourcemanager.ApplicationMasterService: Registering appattempt_1377704542759_0004_000001
2013-08-28 15:53:00,408 INFO org.apache.hadoop.yarn.server.resourcemanager.rmapp.attempt.RMAppAttemptImpl: appattempt_1377704542759_0004_000001 State change from NEW to SUBMITTED
2013-08-28 15:53:00,410 INFO org.apache.hadoop.yarn.server.resourcemanager.scheduler.capacity.LeafQueue: Application application_1377704542759_0004 from user: ubuntu activated in queue: default
2013-08-28 15:53:00,410 INFO org.apache.hadoop.yarn.server.resourcemanager.scheduler.capacity.LeafQueue: Application added - appId: application_1377704542759_0004 user: org.apache.hadoop.yarn.server.resourcemanager.scheduler.capacity.LeafQueue$User@3adf0ddc, leaf-queue: default #user-pending-applications: 0 #user-active-applications: 1 #queue-pending-applications: 0 #queue-active-applications: 1
2013-08-28 15:53:00,410 INFO org.apache.hadoop.yarn.server.resourcemanager.scheduler.capacity.ParentQueue: Application added - appId: application_1377704542759_0004 user: ubuntu leaf-queue of parent: root #applications: 1
2013-08-28 15:53:00,410 INFO org.apache.hadoop.yarn.server.resourcemanager.scheduler.capacity.CapacityScheduler: Application Submission: appattempt_1377704542759_0004_000001, user: ubuntu queue: default: capacity=1.0, absoluteCapacity=1.0, usedResources=<memory:0, vCores:0>usedCapacity=0.0, absoluteUsedCapacity=0.0, numApps=1, numContainers=0, currently active: 1
2013-08-28 15:53:00,411 INFO org.apache.hadoop.yarn.server.resourcemanager.rmapp.attempt.RMAppAttemptImpl: appattempt_1377704542759_0004_000001 State change from SUBMITTED to SCHEDULED
2013-08-28 15:53:00,411 INFO org.apache.hadoop.yarn.server.resourcemanager.rmapp.RMAppImpl: application_1377704542759_0004 State change from SUBMITTED to ACCEPTED
2013-08-28 15:53:00,593 INFO org.apache.hadoop.yarn.server.resourcemanager.rmcontainer.RMContainerImpl: container_1377704542759_0004_01_000001 Container Transitioned from NEW to ALLOCATED
2013-08-28 15:53:00,593 INFO org.apache.hadoop.yarn.server.resourcemanager.RMAuditLogger: USER=ubuntu	OPERATION=AM Allocated Container	TARGET=SchedulerApp	RESULT=SUCCESS	APPID=application_1377704542759_0004	CONTAINERID=container_1377704542759_0004_01_000001
2013-08-28 15:53:00,594 INFO org.apache.hadoop.yarn.server.resourcemanager.scheduler.common.fica.FiCaSchedulerNode: Assigned container container_1377704542759_0004_01_000001 of capacity <memory:2048, vCores:1> on host hadoop-16-2:39317, which currently has 1 containers, <memory:2048, vCores:1> used and <memory:6144, vCores:15> available
2013-08-28 15:53:00,596 INFO org.apache.hadoop.yarn.server.resourcemanager.scheduler.capacity.LeafQueue: assignedContainer application=application_1377704542759_0004 container=Container: [ContainerId: container_1377704542759_0004_01_000001, NodeId: hadoop-16-2:39317, NodeHttpAddress: hadoop-16-2:8042, Resource: <memory:2048, vCores:1>, Priority: 0, State: NEW, Token: null, Status: container_id {, app_attempt_id {, application_id {, id: 4, cluster_timestamp: 1377704542759, }, attemptId: 1, }, id: 1, }, state: C_NEW, ] containerId=container_1377704542759_0004_01_000001 queue=default: capacity=1.0, absoluteCapacity=1.0, usedResources=<memory:0, vCores:0>usedCapacity=0.0, absoluteUsedCapacity=0.0, numApps=1, numContainers=0 usedCapacity=0.0 absoluteUsedCapacity=0.0 used=<memory:0, vCores:0> cluster=<memory:49152, vCores:96>
2013-08-28 15:53:00,596 INFO org.apache.hadoop.yarn.server.resourcemanager.scheduler.capacity.ParentQueue: Re-sorting queues since queue: root.default stats: default: capacity=1.0, absoluteCapacity=1.0, usedResources=<memory:2048, vCores:1>usedCapacity=0.041666668, absoluteUsedCapacity=0.041666668, numApps=1, numContainers=1
2013-08-28 15:53:00,598 INFO org.apache.hadoop.yarn.server.resourcemanager.rmcontainer.RMContainerImpl: container_1377704542759_0004_01_000001 Container Transitioned from ALLOCATED to ACQUIRED
2013-08-28 15:53:00,599 INFO org.apache.hadoop.yarn.server.resourcemanager.scheduler.capacity.ParentQueue: assignedContainer queue=root usedCapacity=0.041666668 absoluteUsedCapacity=0.041666668 used=<memory:2048, vCores:1> cluster=<memory:49152, vCores:96>
2013-08-28 15:53:00,599 INFO org.apache.hadoop.yarn.server.resourcemanager.rmapp.attempt.RMAppAttemptImpl: Storing attempt: AppId: application_1377704542759_0004 AttemptId: appattempt_1377704542759_0004_000001 MasterContainer: Container: [ContainerId: container_1377704542759_0004_01_000001, NodeId: hadoop-16-2:39317, NodeHttpAddress: hadoop-16-2:8042, Resource: <memory:2048, vCores:1>, Priority: 0, State: NEW, Token: null, Status: container_id {, app_attempt_id {, application_id {, id: 4, cluster_timestamp: 1377704542759, }, attemptId: 1, }, id: 1, }, state: C_NEW, ]
2013-08-28 15:53:00,600 INFO org.apache.hadoop.yarn.server.resourcemanager.rmapp.attempt.RMAppAttemptImpl: appattempt_1377704542759_0004_000001 State change from SCHEDULED to ALLOCATED_SAVING
2013-08-28 15:53:00,600 INFO org.apache.hadoop.yarn.server.resourcemanager.recovery.RMStateStore: Storing info for attempt: appattempt_1377704542759_0004_000001
2013-08-28 15:53:00,601 INFO org.apache.hadoop.yarn.server.resourcemanager.rmapp.attempt.RMAppAttemptImpl: appattempt_1377704542759_0004_000001 State change from ALLOCATED_SAVING to ALLOCATED
2013-08-28 15:53:00,602 INFO org.apache.hadoop.yarn.server.resourcemanager.amlauncher.AMLauncher: Launching masterappattempt_1377704542759_0004_000001
2013-08-28 15:53:00,604 INFO org.apache.hadoop.yarn.server.resourcemanager.amlauncher.AMLauncher: Setting up container Container: [ContainerId: container_1377704542759_0004_01_000001, NodeId: hadoop-16-2:39317, NodeHttpAddress: hadoop-16-2:8042, Resource: <memory:2048, vCores:1>, Priority: 0, State: NEW, Token: null, Status: container_id {, app_attempt_id {, application_id {, id: 4, cluster_timestamp: 1377704542759, }, attemptId: 1, }, id: 1, }, state: C_NEW, ] for AM appattempt_1377704542759_0004_000001
2013-08-28 15:53:00,604 INFO org.apache.hadoop.yarn.server.resourcemanager.amlauncher.AMLauncher: Command to launch container container_1377704542759_0004_01_000001 : $JAVA_HOME/bin/java -Dlog4j.configuration=container-log4j.properties -Dyarn.app.mapreduce.container.log.dir=<LOG_DIR> -Dyarn.app.mapreduce.container.log.filesize=0 -Dhadoop.root.logger=INFO,CLA  -Xmx1024m org.apache.hadoop.mapreduce.v2.app.MRAppMaster 1><LOG_DIR>/stdout 2><LOG_DIR>/stderr 
2013-08-28 15:53:00,620 INFO org.apache.hadoop.yarn.server.resourcemanager.amlauncher.AMLauncher: Done launching container Container: [ContainerId: container_1377704542759_0004_01_000001, NodeId: hadoop-16-2:39317, NodeHttpAddress: hadoop-16-2:8042, Resource: <memory:2048, vCores:1>, Priority: 0, State: NEW, Token: null, Status: container_id {, app_attempt_id {, application_id {, id: 4, cluster_timestamp: 1377704542759, }, attemptId: 1, }, id: 1, }, state: C_NEW, ] for AM appattempt_1377704542759_0004_000001
2013-08-28 15:53:00,621 INFO org.apache.hadoop.yarn.server.resourcemanager.rmapp.attempt.RMAppAttemptImpl: appattempt_1377704542759_0004_000001 State change from ALLOCATED to LAUNCHED
2013-08-28 15:53:01,598 INFO org.apache.hadoop.yarn.server.resourcemanager.rmcontainer.RMContainerImpl: container_1377704542759_0004_01_000001 Container Transitioned from ACQUIRED to RUNNING
2013-08-28 15:53:08,832 INFO org.apache.hadoop.yarn.server.resourcemanager.ApplicationMasterService: AM registration appattempt_1377704542759_0004_000001
2013-08-28 15:53:08,833 INFO org.apache.hadoop.yarn.server.resourcemanager.RMAuditLogger: USER=ubuntu	IP=192.168.100.15	OPERATION=Register App Master	TARGET=ApplicationMasterService	RESULT=SUCCESS	APPID=application_1377704542759_0004	APPATTEMPTID=appattempt_1377704542759_0004_000001
2013-08-28 15:53:08,833 INFO org.apache.hadoop.yarn.server.resourcemanager.rmapp.attempt.RMAppAttemptImpl: appattempt_1377704542759_0004_000001 State change from LAUNCHED to RUNNING
2013-08-28 15:53:08,834 INFO org.apache.hadoop.yarn.server.resourcemanager.rmapp.RMAppImpl: application_1377704542759_0004 State change from ACCEPTED to RUNNING
2013-08-28 15:53:09,888 INFO org.apache.hadoop.yarn.server.resourcemanager.rmcontainer.RMContainerImpl: container_1377704542759_0004_01_000002 Container Transitioned from NEW to ALLOCATED
2013-08-28 15:53:09,888 INFO org.apache.hadoop.yarn.server.resourcemanager.RMAuditLogger: USER=ubuntu	OPERATION=AM Allocated Container	TARGET=SchedulerApp	RESULT=SUCCESS	APPID=application_1377704542759_0004	CONTAINERID=container_1377704542759_0004_01_000002
2013-08-28 15:53:09,888 INFO org.apache.hadoop.yarn.server.resourcemanager.scheduler.common.fica.FiCaSchedulerNode: Assigned container container_1377704542759_0004_01_000002 of capacity <memory:1024, vCores:1> on host hadoop-16-7:53595, which currently has 1 containers, <memory:1024, vCores:1> used and <memory:7168, vCores:15> available
2013-08-28 15:53:09,889 INFO org.apache.hadoop.yarn.server.resourcemanager.scheduler.capacity.LeafQueue: assignedContainer application=application_1377704542759_0004 container=Container: [ContainerId: container_1377704542759_0004_01_000002, NodeId: hadoop-16-7:53595, NodeHttpAddress: hadoop-16-7:8042, Resource: <memory:1024, vCores:1>, Priority: 20, State: NEW, Token: null, Status: container_id {, app_attempt_id {, application_id {, id: 4, cluster_timestamp: 1377704542759, }, attemptId: 1, }, id: 2, }, state: C_NEW, ] containerId=container_1377704542759_0004_01_000002 queue=default: capacity=1.0, absoluteCapacity=1.0, usedResources=<memory:2048, vCores:1>usedCapacity=0.041666668, absoluteUsedCapacity=0.041666668, numApps=1, numContainers=1 usedCapacity=0.041666668 absoluteUsedCapacity=0.041666668 used=<memory:2048, vCores:1> cluster=<memory:49152, vCores:96>
2013-08-28 15:53:09,890 INFO org.apache.hadoop.yarn.server.resourcemanager.scheduler.capacity.ParentQueue: Re-sorting queues since queue: root.default stats: default: capacity=1.0, absoluteCapacity=1.0, usedResources=<memory:3072, vCores:2>usedCapacity=0.0625, absoluteUsedCapacity=0.0625, numApps=1, numContainers=2
2013-08-28 15:53:09,890 INFO org.apache.hadoop.yarn.server.resourcemanager.scheduler.capacity.ParentQueue: assignedContainer queue=root usedCapacity=0.0625 absoluteUsedCapacity=0.0625 used=<memory:3072, vCores:2> cluster=<memory:49152, vCores:96>
2013-08-28 15:53:10,027 INFO org.apache.hadoop.yarn.server.resourcemanager.rmcontainer.RMContainerImpl: container_1377704542759_0004_01_000003 Container Transitioned from NEW to ALLOCATED
2013-08-28 15:53:10,028 INFO org.apache.hadoop.yarn.server.resourcemanager.RMAuditLogger: USER=ubuntu	OPERATION=AM Allocated Container	TARGET=SchedulerApp	RESULT=SUCCESS	APPID=application_1377704542759_0004	CONTAINERID=container_1377704542759_0004_01_000003
2013-08-28 15:53:10,028 INFO org.apache.hadoop.yarn.server.resourcemanager.scheduler.common.fica.FiCaSchedulerNode: Assigned container container_1377704542759_0004_01_000003 of capacity <memory:1024, vCores:1> on host hadoop-16-4:52495, which currently has 1 containers, <memory:1024, vCores:1> used and <memory:7168, vCores:15> available
2013-08-28 15:53:10,029 INFO org.apache.hadoop.yarn.server.resourcemanager.scheduler.capacity.LeafQueue: assignedContainer application=application_1377704542759_0004 container=Container: [ContainerId: container_1377704542759_0004_01_000003, NodeId: hadoop-16-4:52495, NodeHttpAddress: hadoop-16-4:8042, Resource: <memory:1024, vCores:1>, Priority: 20, State: NEW, Token: null, Status: container_id {, app_attempt_id {, application_id {, id: 4, cluster_timestamp: 1377704542759, }, attemptId: 1, }, id: 3, }, state: C_NEW, ] containerId=container_1377704542759_0004_01_000003 queue=default: capacity=1.0, absoluteCapacity=1.0, usedResources=<memory:3072, vCores:2>usedCapacity=0.0625, absoluteUsedCapacity=0.0625, numApps=1, numContainers=2 usedCapacity=0.0625 absoluteUsedCapacity=0.0625 used=<memory:3072, vCores:2> cluster=<memory:49152, vCores:96>
2013-08-28 15:53:10,029 INFO org.apache.hadoop.yarn.server.resourcemanager.scheduler.capacity.ParentQueue: Re-sorting queues since queue: root.default stats: default: capacity=1.0, absoluteCapacity=1.0, usedResources=<memory:4096, vCores:3>usedCapacity=0.083333336, absoluteUsedCapacity=0.083333336, numApps=1, numContainers=3
2013-08-28 15:53:10,029 INFO org.apache.hadoop.yarn.server.resourcemanager.scheduler.capacity.ParentQueue: assignedContainer queue=root usedCapacity=0.083333336 absoluteUsedCapacity=0.083333336 used=<memory:4096, vCores:3> cluster=<memory:49152, vCores:96>
2013-08-28 15:53:10,912 INFO org.apache.hadoop.yarn.server.resourcemanager.rmcontainer.RMContainerImpl: container_1377704542759_0004_01_000002 Container Transitioned from ALLOCATED to ACQUIRED
2013-08-28 15:53:10,914 INFO org.apache.hadoop.yarn.server.resourcemanager.rmcontainer.RMContainerImpl: container_1377704542759_0004_01_000003 Container Transitioned from ALLOCATED to ACQUIRED
2013-08-28 15:53:11,900 INFO org.apache.hadoop.yarn.server.resourcemanager.rmcontainer.RMContainerImpl: container_1377704542759_0004_01_000002 Container Transitioned from ACQUIRED to RUNNING
2013-08-28 15:53:11,943 INFO org.apache.hadoop.yarn.server.resourcemanager.scheduler.AppSchedulingInfo: checking for deactivate... 
2013-08-28 15:53:12,039 INFO org.apache.hadoop.yarn.server.resourcemanager.rmcontainer.RMContainerImpl: container_1377704542759_0004_01_000003 Container Transitioned from ACQUIRED to RUNNING
2013-08-28 15:55:51,545 INFO org.apache.hadoop.yarn.server.resourcemanager.rmcontainer.RMContainerImpl: container_1377704542759_0004_01_000002 Container Transitioned from RUNNING to COMPLETED
2013-08-28 15:55:51,545 INFO org.apache.hadoop.yarn.server.resourcemanager.scheduler.common.fica.FiCaSchedulerApp: Completed container: container_1377704542759_0004_01_000002 in state: COMPLETED event:FINISHED
2013-08-28 15:55:51,545 INFO org.apache.hadoop.yarn.server.resourcemanager.RMAuditLogger: USER=ubuntu	OPERATION=AM Released Container	TARGET=SchedulerApp	RESULT=SUCCESS	APPID=application_1377704542759_0004	CONTAINERID=container_1377704542759_0004_01_000002
2013-08-28 15:55:51,545 INFO org.apache.hadoop.yarn.server.resourcemanager.scheduler.common.fica.FiCaSchedulerNode: Released container container_1377704542759_0004_01_000002 of capacity <memory:1024, vCores:1> on host hadoop-16-7:53595, which currently has 0 containers, <memory:0, vCores:0> used and <memory:8192, vCores:16> available, release resources=true
2013-08-28 15:55:51,545 INFO org.apache.hadoop.yarn.server.resourcemanager.scheduler.capacity.LeafQueue: default used=<memory:3072, vCores:2> numContainers=2 user=ubuntu user-resources=<memory:3072, vCores:2>
2013-08-28 15:55:51,547 INFO org.apache.hadoop.yarn.server.resourcemanager.scheduler.capacity.LeafQueue: completedContainer container=Container: [ContainerId: container_1377704542759_0004_01_000002, NodeId: hadoop-16-7:53595, NodeHttpAddress: hadoop-16-7:8042, Resource: <memory:1024, vCores:1>, Priority: 20, State: NEW, Token: null, Status: container_id {, app_attempt_id {, application_id {, id: 4, cluster_timestamp: 1377704542759, }, attemptId: 1, }, id: 2, }, state: C_COMPLETE, diagnostics: "Container killed by the ApplicationMaster.\n", exit_status: 0, ] resource=<memory:1024, vCores:1> queue=default: capacity=1.0, absoluteCapacity=1.0, usedResources=<memory:3072, vCores:2>usedCapacity=0.0625, absoluteUsedCapacity=0.0625, numApps=1, numContainers=2 usedCapacity=0.0625 absoluteUsedCapacity=0.0625 used=<memory:3072, vCores:2> cluster=<memory:49152, vCores:96>
2013-08-28 15:55:51,547 INFO org.apache.hadoop.yarn.server.resourcemanager.scheduler.capacity.ParentQueue: completedContainer queue=root usedCapacity=0.0625 absoluteUsedCapacity=0.0625 used=<memory:3072, vCores:2> cluster=<memory:49152, vCores:96>
2013-08-28 15:55:51,547 INFO org.apache.hadoop.yarn.server.resourcemanager.scheduler.capacity.CapacityScheduler: Application appattempt_1377704542759_0004_000001 released container container_1377704542759_0004_01_000002 on node: host: hadoop-16-7:53595 #containers=0 available=8192 used=0 with event: FINISHED
2013-08-28 15:55:56,866 INFO org.apache.hadoop.yarn.server.resourcemanager.rmcontainer.RMContainerImpl: container_1377704542759_0004_01_000003 Container Transitioned from RUNNING to COMPLETED
2013-08-28 15:55:56,866 INFO org.apache.hadoop.yarn.server.resourcemanager.scheduler.common.fica.FiCaSchedulerApp: Completed container: container_1377704542759_0004_01_000003 in state: COMPLETED event:FINISHED
2013-08-28 15:55:56,866 INFO org.apache.hadoop.yarn.server.resourcemanager.RMAuditLogger: USER=ubuntu	OPERATION=AM Released Container	TARGET=SchedulerApp	RESULT=SUCCESS	APPID=application_1377704542759_0004	CONTAINERID=container_1377704542759_0004_01_000003
2013-08-28 15:55:56,867 INFO org.apache.hadoop.yarn.server.resourcemanager.scheduler.common.fica.FiCaSchedulerNode: Released container container_1377704542759_0004_01_000003 of capacity <memory:1024, vCores:1> on host hadoop-16-4:52495, which currently has 0 containers, <memory:0, vCores:0> used and <memory:8192, vCores:16> available, release resources=true
2013-08-28 15:55:56,867 INFO org.apache.hadoop.yarn.server.resourcemanager.scheduler.capacity.LeafQueue: default used=<memory:2048, vCores:1> numContainers=1 user=ubuntu user-resources=<memory:2048, vCores:1>
2013-08-28 15:55:56,869 INFO org.apache.hadoop.yarn.server.resourcemanager.scheduler.capacity.LeafQueue: completedContainer container=Container: [ContainerId: container_1377704542759_0004_01_000003, NodeId: hadoop-16-4:52495, NodeHttpAddress: hadoop-16-4:8042, Resource: <memory:1024, vCores:1>, Priority: 20, State: NEW, Token: null, Status: container_id {, app_attempt_id {, application_id {, id: 4, cluster_timestamp: 1377704542759, }, attemptId: 1, }, id: 3, }, state: C_COMPLETE, diagnostics: "Container killed by the ApplicationMaster.\n\n", exit_status: 143, ] resource=<memory:1024, vCores:1> queue=default: capacity=1.0, absoluteCapacity=1.0, usedResources=<memory:2048, vCores:1>usedCapacity=0.041666668, absoluteUsedCapacity=0.041666668, numApps=1, numContainers=1 usedCapacity=0.041666668 absoluteUsedCapacity=0.041666668 used=<memory:2048, vCores:1> cluster=<memory:49152, vCores:96>
2013-08-28 15:55:56,869 INFO org.apache.hadoop.yarn.server.resourcemanager.scheduler.capacity.ParentQueue: completedContainer queue=root usedCapacity=0.041666668 absoluteUsedCapacity=0.041666668 used=<memory:2048, vCores:1> cluster=<memory:49152, vCores:96>
2013-08-28 15:55:56,869 INFO org.apache.hadoop.yarn.server.resourcemanager.scheduler.capacity.CapacityScheduler: Application appattempt_1377704542759_0004_000001 released container container_1377704542759_0004_01_000003 on node: host: hadoop-16-4:52495 #containers=0 available=8192 used=0 with event: FINISHED
2013-08-28 15:56:01,224 INFO org.apache.hadoop.yarn.server.resourcemanager.rmapp.attempt.RMAppAttemptImpl: appattempt_1377704542759_0004_000001 State change from RUNNING to FINISHING
2013-08-28 15:56:01,225 INFO org.apache.hadoop.yarn.server.resourcemanager.rmapp.RMAppImpl: application_1377704542759_0004 State change from RUNNING to FINISHING
2013-08-28 15:56:01,965 INFO org.apache.hadoop.yarn.server.resourcemanager.rmcontainer.RMContainerImpl: container_1377704542759_0004_01_000001 Container Transitioned from RUNNING to COMPLETED
2013-08-28 15:56:01,966 INFO org.apache.hadoop.yarn.server.resourcemanager.scheduler.common.fica.FiCaSchedulerApp: Completed container: container_1377704542759_0004_01_000001 in state: COMPLETED event:FINISHED
2013-08-28 15:56:01,966 INFO org.apache.hadoop.yarn.server.resourcemanager.RMAuditLogger: USER=ubuntu	OPERATION=AM Released Container	TARGET=SchedulerApp	RESULT=SUCCESS	APPID=application_1377704542759_0004	CONTAINERID=container_1377704542759_0004_01_000001
2013-08-28 15:56:01,966 INFO org.apache.hadoop.yarn.server.resourcemanager.scheduler.common.fica.FiCaSchedulerNode: Released container container_1377704542759_0004_01_000001 of capacity <memory:2048, vCores:1> on host hadoop-16-2:39317, which currently has 0 containers, <memory:0, vCores:0> used and <memory:8192, vCores:16> available, release resources=true
2013-08-28 15:56:01,966 INFO org.apache.hadoop.yarn.server.resourcemanager.scheduler.capacity.LeafQueue: default used=<memory:0, vCores:0> numContainers=0 user=ubuntu user-resources=<memory:0, vCores:0>
2013-08-28 15:56:01,967 INFO org.apache.hadoop.yarn.server.resourcemanager.scheduler.capacity.LeafQueue: completedContainer container=Container: [ContainerId: container_1377704542759_0004_01_000001, NodeId: hadoop-16-2:39317, NodeHttpAddress: hadoop-16-2:8042, Resource: <memory:2048, vCores:1>, Priority: 0, State: NEW, Token: null, Status: container_id {, app_attempt_id {, application_id {, id: 4, cluster_timestamp: 1377704542759, }, attemptId: 1, }, id: 1, }, state: C_COMPLETE, diagnostics: "", exit_status: 0, ] resource=<memory:2048, vCores:1> queue=default: capacity=1.0, absoluteCapacity=1.0, usedResources=<memory:0, vCores:0>usedCapacity=0.0, absoluteUsedCapacity=0.0, numApps=1, numContainers=0 usedCapacity=0.0 absoluteUsedCapacity=0.0 used=<memory:0, vCores:0> cluster=<memory:49152, vCores:96>
2013-08-28 15:56:01,967 INFO org.apache.hadoop.yarn.server.resourcemanager.rmapp.attempt.RMAppAttemptImpl: appattempt_1377704542759_0004_000001 State change from FINISHING to FINISHED
2013-08-28 15:56:01,967 INFO org.apache.hadoop.yarn.server.resourcemanager.scheduler.capacity.ParentQueue: completedContainer queue=root usedCapacity=0.0 absoluteUsedCapacity=0.0 used=<memory:0, vCores:0> cluster=<memory:49152, vCores:96>
2013-08-28 15:56:01,969 INFO org.apache.hadoop.yarn.server.resourcemanager.scheduler.capacity.CapacityScheduler: Application appattempt_1377704542759_0004_000001 released container container_1377704542759_0004_01_000001 on node: host: hadoop-16-2:39317 #containers=0 available=8192 used=0 with event: FINISHED
2013-08-28 15:56:01,969 INFO org.apache.hadoop.yarn.server.resourcemanager.rmapp.RMAppImpl: application_1377704542759_0004 State change from FINISHING to FINISHED
2013-08-28 15:56:01,970 INFO org.apache.hadoop.yarn.server.resourcemanager.scheduler.capacity.CapacityScheduler: Application appattempt_1377704542759_0004_000001 is done. finalState=FINISHED
2013-08-28 15:56:01,970 INFO org.apache.hadoop.yarn.server.resourcemanager.scheduler.AppSchedulingInfo: Application application_1377704542759_0004 requests cleared
2013-08-28 15:56:01,970 INFO org.apache.hadoop.yarn.server.resourcemanager.scheduler.capacity.LeafQueue: Application removed - appId: application_1377704542759_0004 user: ubuntu queue: default #user-pending-applications: 0 #user-active-applications: 0 #queue-pending-applications: 0 #queue-active-applications: 0
2013-08-28 15:56:01,970 INFO org.apache.hadoop.yarn.server.resourcemanager.scheduler.capacity.ParentQueue: Application removed - appId: application_1377704542759_0004 user: ubuntu leaf-queue of parent: root #applications: 0
2013-08-28 15:56:01,970 INFO org.apache.hadoop.yarn.server.resourcemanager.RMAuditLogger: USER=ubuntu	OPERATION=Application Finished - Succeeded	TARGET=RMAppManager	RESULT=SUCCESS	APPID=application_1377704542759_0004
2013-08-28 15:56:01,971 INFO org.apache.hadoop.yarn.server.resourcemanager.recovery.RMStateStore: Removing info for app: application_1377704542759_0004
2013-08-28 15:56:01,971 INFO org.apache.hadoop.yarn.server.resourcemanager.RMAppManager$ApplicationSummary: appId=application_1377704542759_0004,name=TeraGen,user=ubuntu,queue=default,state=FINISHED,trackingUrl=hadoop-16-1.novalocal:8088/proxy/application_1377704542759_0004/jobhistory/job/job_1377704542759_0004,appMasterHost=hadoop-16-2,startTime=1377705180407,finishTime=1377705361225
2013-08-28 15:56:01,971 INFO org.apache.hadoop.yarn.server.resourcemanager.amlauncher.AMLauncher: Cleaning master appattempt_1377704542759_0004_000001
2013-08-28 15:56:02,556 INFO org.apache.hadoop.yarn.server.resourcemanager.ClientRMService: Allocated new applicationId: 5
2013-08-28 15:56:04,501 INFO org.apache.hadoop.yarn.server.resourcemanager.ClientRMService: Storing Application with id application_1377704542759_0005
2013-08-28 15:56:04,501 INFO org.apache.hadoop.yarn.server.resourcemanager.recovery.RMStateStore: Storing info for app: application_1377704542759_0005
2013-08-28 15:56:04,501 INFO org.apache.hadoop.yarn.server.resourcemanager.ClientRMService: Application with id 5 submitted by user ubuntu
2013-08-28 15:56:04,501 INFO org.apache.hadoop.yarn.server.resourcemanager.RMAuditLogger: USER=ubuntu	IP=192.168.100.5	OPERATION=Submit Application Request	TARGET=ClientRMService	RESULT=SUCCESS	APPID=application_1377704542759_0005
2013-08-28 15:56:04,504 INFO org.apache.hadoop.yarn.server.resourcemanager.rmapp.RMAppImpl: application_1377704542759_0005 State change from NEW to SUBMITTED
2013-08-28 15:56:04,504 INFO org.apache.hadoop.yarn.server.resourcemanager.ApplicationMasterService: Registering appattempt_1377704542759_0005_000001
2013-08-28 15:56:04,504 INFO org.apache.hadoop.yarn.server.resourcemanager.rmapp.attempt.RMAppAttemptImpl: appattempt_1377704542759_0005_000001 State change from NEW to SUBMITTED
2013-08-28 15:56:04,505 INFO org.apache.hadoop.yarn.server.resourcemanager.scheduler.capacity.LeafQueue: Application application_1377704542759_0005 from user: ubuntu activated in queue: default
2013-08-28 15:56:04,505 INFO org.apache.hadoop.yarn.server.resourcemanager.scheduler.capacity.LeafQueue: Application added - appId: application_1377704542759_0005 user: org.apache.hadoop.yarn.server.resourcemanager.scheduler.capacity.LeafQueue$User@506208e4, leaf-queue: default #user-pending-applications: 0 #user-active-applications: 1 #queue-pending-applications: 0 #queue-active-applications: 1
2013-08-28 15:56:04,505 INFO org.apache.hadoop.yarn.server.resourcemanager.scheduler.capacity.ParentQueue: Application added - appId: application_1377704542759_0005 user: ubuntu leaf-queue of parent: root #applications: 1
2013-08-28 15:56:04,505 INFO org.apache.hadoop.yarn.server.resourcemanager.scheduler.capacity.CapacityScheduler: Application Submission: appattempt_1377704542759_0005_000001, user: ubuntu queue: default: capacity=1.0, absoluteCapacity=1.0, usedResources=<memory:0, vCores:0>usedCapacity=0.0, absoluteUsedCapacity=0.0, numApps=1, numContainers=0, currently active: 1
2013-08-28 15:56:04,505 INFO org.apache.hadoop.yarn.server.resourcemanager.rmapp.attempt.RMAppAttemptImpl: appattempt_1377704542759_0005_000001 State change from SUBMITTED to SCHEDULED
2013-08-28 15:56:04,506 INFO org.apache.hadoop.yarn.server.resourcemanager.rmapp.RMAppImpl: application_1377704542759_0005 State change from SUBMITTED to ACCEPTED
2013-08-28 15:56:04,535 INFO org.apache.hadoop.yarn.server.resourcemanager.rmcontainer.RMContainerImpl: container_1377704542759_0005_01_000001 Container Transitioned from NEW to ALLOCATED
2013-08-28 15:56:04,535 INFO org.apache.hadoop.yarn.server.resourcemanager.RMAuditLogger: USER=ubuntu	OPERATION=AM Allocated Container	TARGET=SchedulerApp	RESULT=SUCCESS	APPID=application_1377704542759_0005	CONTAINERID=container_1377704542759_0005_01_000001
2013-08-28 15:56:04,535 INFO org.apache.hadoop.yarn.server.resourcemanager.scheduler.common.fica.FiCaSchedulerNode: Assigned container container_1377704542759_0005_01_000001 of capacity <memory:2048, vCores:1> on host hadoop-16-6:36337, which currently has 1 containers, <memory:2048, vCores:1> used and <memory:6144, vCores:15> available
2013-08-28 15:56:04,536 INFO org.apache.hadoop.yarn.server.resourcemanager.scheduler.capacity.LeafQueue: assignedContainer application=application_1377704542759_0005 container=Container: [ContainerId: container_1377704542759_0005_01_000001, NodeId: hadoop-16-6:36337, NodeHttpAddress: hadoop-16-6:8042, Resource: <memory:2048, vCores:1>, Priority: 0, State: NEW, Token: null, Status: container_id {, app_attempt_id {, application_id {, id: 5, cluster_timestamp: 1377704542759, }, attemptId: 1, }, id: 1, }, state: C_NEW, ] containerId=container_1377704542759_0005_01_000001 queue=default: capacity=1.0, absoluteCapacity=1.0, usedResources=<memory:0, vCores:0>usedCapacity=0.0, absoluteUsedCapacity=0.0, numApps=1, numContainers=0 usedCapacity=0.0 absoluteUsedCapacity=0.0 used=<memory:0, vCores:0> cluster=<memory:49152, vCores:96>
2013-08-28 15:56:04,537 INFO org.apache.hadoop.yarn.server.resourcemanager.scheduler.capacity.ParentQueue: Re-sorting queues since queue: root.default stats: default: capacity=1.0, absoluteCapacity=1.0, usedResources=<memory:2048, vCores:1>usedCapacity=0.041666668, absoluteUsedCapacity=0.041666668, numApps=1, numContainers=1
2013-08-28 15:56:04,542 INFO org.apache.hadoop.yarn.server.resourcemanager.scheduler.capacity.ParentQueue: assignedContainer queue=root usedCapacity=0.041666668 absoluteUsedCapacity=0.041666668 used=<memory:2048, vCores:1> cluster=<memory:49152, vCores:96>
2013-08-28 15:56:04,542 INFO org.apache.hadoop.yarn.server.resourcemanager.rmcontainer.RMContainerImpl: container_1377704542759_0005_01_000001 Container Transitioned from ALLOCATED to ACQUIRED
2013-08-28 15:56:04,544 INFO org.apache.hadoop.yarn.server.resourcemanager.rmapp.attempt.RMAppAttemptImpl: Storing attempt: AppId: application_1377704542759_0005 AttemptId: appattempt_1377704542759_0005_000001 MasterContainer: Container: [ContainerId: container_1377704542759_0005_01_000001, NodeId: hadoop-16-6:36337, NodeHttpAddress: hadoop-16-6:8042, Resource: <memory:2048, vCores:1>, Priority: 0, State: NEW, Token: null, Status: container_id {, app_attempt_id {, application_id {, id: 5, cluster_timestamp: 1377704542759, }, attemptId: 1, }, id: 1, }, state: C_NEW, ]
2013-08-28 15:56:04,544 INFO org.apache.hadoop.yarn.server.resourcemanager.rmapp.attempt.RMAppAttemptImpl: appattempt_1377704542759_0005_000001 State change from SCHEDULED to ALLOCATED_SAVING
2013-08-28 15:56:04,544 INFO org.apache.hadoop.yarn.server.resourcemanager.recovery.RMStateStore: Storing info for attempt: appattempt_1377704542759_0005_000001
2013-08-28 15:56:04,545 INFO org.apache.hadoop.yarn.server.resourcemanager.rmapp.attempt.RMAppAttemptImpl: appattempt_1377704542759_0005_000001 State change from ALLOCATED_SAVING to ALLOCATED
2013-08-28 15:56:04,546 INFO org.apache.hadoop.yarn.server.resourcemanager.amlauncher.AMLauncher: Launching masterappattempt_1377704542759_0005_000001
2013-08-28 15:56:04,549 INFO org.apache.hadoop.yarn.server.resourcemanager.amlauncher.AMLauncher: Setting up container Container: [ContainerId: container_1377704542759_0005_01_000001, NodeId: hadoop-16-6:36337, NodeHttpAddress: hadoop-16-6:8042, Resource: <memory:2048, vCores:1>, Priority: 0, State: NEW, Token: null, Status: container_id {, app_attempt_id {, application_id {, id: 5, cluster_timestamp: 1377704542759, }, attemptId: 1, }, id: 1, }, state: C_NEW, ] for AM appattempt_1377704542759_0005_000001
2013-08-28 15:56:04,549 INFO org.apache.hadoop.yarn.server.resourcemanager.amlauncher.AMLauncher: Command to launch container container_1377704542759_0005_01_000001 : $JAVA_HOME/bin/java -Dlog4j.configuration=container-log4j.properties -Dyarn.app.mapreduce.container.log.dir=<LOG_DIR> -Dyarn.app.mapreduce.container.log.filesize=0 -Dhadoop.root.logger=INFO,CLA  -Xmx1024m org.apache.hadoop.mapreduce.v2.app.MRAppMaster 1><LOG_DIR>/stdout 2><LOG_DIR>/stderr 
2013-08-28 15:56:05,475 INFO org.apache.hadoop.yarn.server.resourcemanager.amlauncher.AMLauncher: Done launching container Container: [ContainerId: container_1377704542759_0005_01_000001, NodeId: hadoop-16-6:36337, NodeHttpAddress: hadoop-16-6:8042, Resource: <memory:2048, vCores:1>, Priority: 0, State: NEW, Token: null, Status: container_id {, app_attempt_id {, application_id {, id: 5, cluster_timestamp: 1377704542759, }, attemptId: 1, }, id: 1, }, state: C_NEW, ] for AM appattempt_1377704542759_0005_000001
2013-08-28 15:56:05,476 INFO org.apache.hadoop.yarn.server.resourcemanager.rmapp.attempt.RMAppAttemptImpl: appattempt_1377704542759_0005_000001 State change from ALLOCATED to LAUNCHED
2013-08-28 15:56:05,558 INFO org.apache.hadoop.yarn.server.resourcemanager.rmcontainer.RMContainerImpl: container_1377704542759_0005_01_000001 Container Transitioned from ACQUIRED to RUNNING
2013-08-28 15:56:15,087 INFO org.apache.hadoop.yarn.server.resourcemanager.ApplicationMasterService: AM registration appattempt_1377704542759_0005_000001
2013-08-28 15:56:15,087 INFO org.apache.hadoop.yarn.server.resourcemanager.RMAuditLogger: USER=ubuntu	IP=192.168.100.21	OPERATION=Register App Master	TARGET=ApplicationMasterService	RESULT=SUCCESS	APPID=application_1377704542759_0005	APPATTEMPTID=appattempt_1377704542759_0005_000001
2013-08-28 15:56:15,088 INFO org.apache.hadoop.yarn.server.resourcemanager.rmapp.attempt.RMAppAttemptImpl: appattempt_1377704542759_0005_000001 State change from LAUNCHED to RUNNING
2013-08-28 15:56:15,088 INFO org.apache.hadoop.yarn.server.resourcemanager.rmapp.RMAppImpl: application_1377704542759_0005 State change from ACCEPTED to RUNNING
2013-08-28 15:56:16,617 INFO org.apache.hadoop.yarn.server.resourcemanager.rmcontainer.RMContainerImpl: container_1377704542759_0005_01_000002 Container Transitioned from NEW to ALLOCATED
2013-08-28 15:56:16,618 INFO org.apache.hadoop.yarn.server.resourcemanager.RMAuditLogger: USER=ubuntu	OPERATION=AM Allocated Container	TARGET=SchedulerApp	RESULT=SUCCESS	APPID=application_1377704542759_0005	CONTAINERID=container_1377704542759_0005_01_000002
2013-08-28 15:56:16,618 INFO org.apache.hadoop.yarn.server.resourcemanager.scheduler.common.fica.FiCaSchedulerNode: Assigned container container_1377704542759_0005_01_000002 of capacity <memory:1024, vCores:1> on host hadoop-16-6:36337, which currently has 2 containers, <memory:3072, vCores:2> used and <memory:5120, vCores:14> available
2013-08-28 15:56:16,619 INFO org.apache.hadoop.yarn.server.resourcemanager.scheduler.capacity.LeafQueue: assignedContainer application=application_1377704542759_0005 container=Container: [ContainerId: container_1377704542759_0005_01_000002, NodeId: hadoop-16-6:36337, NodeHttpAddress: hadoop-16-6:8042, Resource: <memory:1024, vCores:1>, Priority: 20, State: NEW, Token: null, Status: container_id {, app_attempt_id {, application_id {, id: 5, cluster_timestamp: 1377704542759, }, attemptId: 1, }, id: 2, }, state: C_NEW, ] containerId=container_1377704542759_0005_01_000002 queue=default: capacity=1.0, absoluteCapacity=1.0, usedResources=<memory:2048, vCores:1>usedCapacity=0.041666668, absoluteUsedCapacity=0.041666668, numApps=1, numContainers=1 usedCapacity=0.041666668 absoluteUsedCapacity=0.041666668 used=<memory:2048, vCores:1> cluster=<memory:49152, vCores:96>
2013-08-28 15:56:16,619 INFO org.apache.hadoop.yarn.server.resourcemanager.scheduler.capacity.ParentQueue: Re-sorting queues since queue: root.default stats: default: capacity=1.0, absoluteCapacity=1.0, usedResources=<memory:3072, vCores:2>usedCapacity=0.0625, absoluteUsedCapacity=0.0625, numApps=1, numContainers=2
2013-08-28 15:56:16,620 INFO org.apache.hadoop.yarn.server.resourcemanager.scheduler.capacity.ParentQueue: assignedContainer queue=root usedCapacity=0.0625 absoluteUsedCapacity=0.0625 used=<memory:3072, vCores:2> cluster=<memory:49152, vCores:96>
2013-08-28 15:56:16,624 INFO org.apache.hadoop.yarn.server.resourcemanager.rmcontainer.RMContainerImpl: container_1377704542759_0005_01_000003 Container Transitioned from NEW to ALLOCATED
2013-08-28 15:56:16,625 INFO org.apache.hadoop.yarn.server.resourcemanager.RMAuditLogger: USER=ubuntu	OPERATION=AM Allocated Container	TARGET=SchedulerApp	RESULT=SUCCESS	APPID=application_1377704542759_0005	CONTAINERID=container_1377704542759_0005_01_000003
2013-08-28 15:56:16,625 INFO org.apache.hadoop.yarn.server.resourcemanager.scheduler.common.fica.FiCaSchedulerNode: Assigned container container_1377704542759_0005_01_000003 of capacity <memory:1024, vCores:1> on host hadoop-16-7:53595, which currently has 1 containers, <memory:1024, vCores:1> used and <memory:7168, vCores:15> available
2013-08-28 15:56:16,626 INFO org.apache.hadoop.yarn.server.resourcemanager.scheduler.capacity.LeafQueue: assignedContainer application=application_1377704542759_0005 container=Container: [ContainerId: container_1377704542759_0005_01_000003, NodeId: hadoop-16-7:53595, NodeHttpAddress: hadoop-16-7:8042, Resource: <memory:1024, vCores:1>, Priority: 20, State: NEW, Token: null, Status: container_id {, app_attempt_id {, application_id {, id: 5, cluster_timestamp: 1377704542759, }, attemptId: 1, }, id: 3, }, state: C_NEW, ] containerId=container_1377704542759_0005_01_000003 queue=default: capacity=1.0, absoluteCapacity=1.0, usedResources=<memory:3072, vCores:2>usedCapacity=0.0625, absoluteUsedCapacity=0.0625, numApps=1, numContainers=2 usedCapacity=0.0625 absoluteUsedCapacity=0.0625 used=<memory:3072, vCores:2> cluster=<memory:49152, vCores:96>
2013-08-28 15:56:16,626 INFO org.apache.hadoop.yarn.server.resourcemanager.scheduler.capacity.ParentQueue: Re-sorting queues since queue: root.default stats: default: capacity=1.0, absoluteCapacity=1.0, usedResources=<memory:4096, vCores:3>usedCapacity=0.083333336, absoluteUsedCapacity=0.083333336, numApps=1, numContainers=3
2013-08-28 15:56:16,626 INFO org.apache.hadoop.yarn.server.resourcemanager.scheduler.capacity.ParentQueue: assignedContainer queue=root usedCapacity=0.083333336 absoluteUsedCapacity=0.083333336 used=<memory:4096, vCores:3> cluster=<memory:49152, vCores:96>
2013-08-28 15:56:17,148 INFO org.apache.hadoop.yarn.server.resourcemanager.rmcontainer.RMContainerImpl: container_1377704542759_0005_01_000002 Container Transitioned from ALLOCATED to ACQUIRED
2013-08-28 15:56:17,151 INFO org.apache.hadoop.yarn.server.resourcemanager.rmcontainer.RMContainerImpl: container_1377704542759_0005_01_000003 Container Transitioned from ALLOCATED to ACQUIRED
2013-08-28 15:56:17,625 INFO org.apache.hadoop.yarn.server.resourcemanager.rmcontainer.RMContainerImpl: container_1377704542759_0005_01_000002 Container Transitioned from ACQUIRED to RUNNING
2013-08-28 15:56:17,631 INFO org.apache.hadoop.yarn.server.resourcemanager.rmcontainer.RMContainerImpl: container_1377704542759_0005_01_000003 Container Transitioned from ACQUIRED to RUNNING
2013-08-28 15:56:18,176 INFO org.apache.hadoop.yarn.server.resourcemanager.scheduler.AppSchedulingInfo: checking for deactivate... 
2013-08-28 15:59:13,656 INFO org.apache.hadoop.yarn.server.resourcemanager.rmcontainer.RMContainerImpl: container_1377704542759_0005_01_000003 Container Transitioned from RUNNING to COMPLETED
2013-08-28 15:59:13,656 INFO org.apache.hadoop.yarn.server.resourcemanager.scheduler.common.fica.FiCaSchedulerApp: Completed container: container_1377704542759_0005_01_000003 in state: COMPLETED event:FINISHED
2013-08-28 15:59:13,657 INFO org.apache.hadoop.yarn.server.resourcemanager.RMAuditLogger: USER=ubuntu	OPERATION=AM Released Container	TARGET=SchedulerApp	RESULT=SUCCESS	APPID=application_1377704542759_0005	CONTAINERID=container_1377704542759_0005_01_000003
2013-08-28 15:59:13,657 INFO org.apache.hadoop.yarn.server.resourcemanager.scheduler.common.fica.FiCaSchedulerNode: Released container container_1377704542759_0005_01_000003 of capacity <memory:1024, vCores:1> on host hadoop-16-7:53595, which currently has 0 containers, <memory:0, vCores:0> used and <memory:8192, vCores:16> available, release resources=true
2013-08-28 15:59:13,657 INFO org.apache.hadoop.yarn.server.resourcemanager.scheduler.capacity.LeafQueue: default used=<memory:3072, vCores:2> numContainers=2 user=ubuntu user-resources=<memory:3072, vCores:2>
2013-08-28 15:59:13,659 INFO org.apache.hadoop.yarn.server.resourcemanager.scheduler.capacity.LeafQueue: completedContainer container=Container: [ContainerId: container_1377704542759_0005_01_000003, NodeId: hadoop-16-7:53595, NodeHttpAddress: hadoop-16-7:8042, Resource: <memory:1024, vCores:1>, Priority: 20, State: NEW, Token: null, Status: container_id {, app_attempt_id {, application_id {, id: 5, cluster_timestamp: 1377704542759, }, attemptId: 1, }, id: 3, }, state: C_COMPLETE, diagnostics: "Container killed by the ApplicationMaster.\n\n", exit_status: 143, ] resource=<memory:1024, vCores:1> queue=default: capacity=1.0, absoluteCapacity=1.0, usedResources=<memory:3072, vCores:2>usedCapacity=0.0625, absoluteUsedCapacity=0.0625, numApps=1, numContainers=2 usedCapacity=0.0625 absoluteUsedCapacity=0.0625 used=<memory:3072, vCores:2> cluster=<memory:49152, vCores:96>
2013-08-28 15:59:13,659 INFO org.apache.hadoop.yarn.server.resourcemanager.scheduler.capacity.ParentQueue: completedContainer queue=root usedCapacity=0.0625 absoluteUsedCapacity=0.0625 used=<memory:3072, vCores:2> cluster=<memory:49152, vCores:96>
2013-08-28 15:59:13,659 INFO org.apache.hadoop.yarn.server.resourcemanager.scheduler.capacity.CapacityScheduler: Application appattempt_1377704542759_0005_000001 released container container_1377704542759_0005_01_000003 on node: host: hadoop-16-7:53595 #containers=0 available=8192 used=0 with event: FINISHED
2013-08-28 15:59:17,006 INFO org.apache.hadoop.yarn.server.resourcemanager.rmcontainer.RMContainerImpl: container_1377704542759_0005_01_000002 Container Transitioned from RUNNING to COMPLETED
2013-08-28 15:59:17,007 INFO org.apache.hadoop.yarn.server.resourcemanager.scheduler.common.fica.FiCaSchedulerApp: Completed container: container_1377704542759_0005_01_000002 in state: COMPLETED event:FINISHED
2013-08-28 15:59:17,007 INFO org.apache.hadoop.yarn.server.resourcemanager.RMAuditLogger: USER=ubuntu	OPERATION=AM Released Container	TARGET=SchedulerApp	RESULT=SUCCESS	APPID=application_1377704542759_0005	CONTAINERID=container_1377704542759_0005_01_000002
2013-08-28 15:59:17,007 INFO org.apache.hadoop.yarn.server.resourcemanager.scheduler.common.fica.FiCaSchedulerNode: Released container container_1377704542759_0005_01_000002 of capacity <memory:1024, vCores:1> on host hadoop-16-6:36337, which currently has 1 containers, <memory:2048, vCores:1> used and <memory:6144, vCores:15> available, release resources=true
2013-08-28 15:59:17,008 INFO org.apache.hadoop.yarn.server.resourcemanager.scheduler.capacity.LeafQueue: default used=<memory:2048, vCores:1> numContainers=1 user=ubuntu user-resources=<memory:2048, vCores:1>
2013-08-28 15:59:17,009 INFO org.apache.hadoop.yarn.server.resourcemanager.scheduler.capacity.LeafQueue: completedContainer container=Container: [ContainerId: container_1377704542759_0005_01_000002, NodeId: hadoop-16-6:36337, NodeHttpAddress: hadoop-16-6:8042, Resource: <memory:1024, vCores:1>, Priority: 20, State: NEW, Token: null, Status: container_id {, app_attempt_id {, application_id {, id: 5, cluster_timestamp: 1377704542759, }, attemptId: 1, }, id: 2, }, state: C_COMPLETE, diagnostics: "Container killed by the ApplicationMaster.\n\n", exit_status: 143, ] resource=<memory:1024, vCores:1> queue=default: capacity=1.0, absoluteCapacity=1.0, usedResources=<memory:2048, vCores:1>usedCapacity=0.041666668, absoluteUsedCapacity=0.041666668, numApps=1, numContainers=1 usedCapacity=0.041666668 absoluteUsedCapacity=0.041666668 used=<memory:2048, vCores:1> cluster=<memory:49152, vCores:96>
2013-08-28 15:59:17,009 INFO org.apache.hadoop.yarn.server.resourcemanager.scheduler.capacity.ParentQueue: completedContainer queue=root usedCapacity=0.041666668 absoluteUsedCapacity=0.041666668 used=<memory:2048, vCores:1> cluster=<memory:49152, vCores:96>
2013-08-28 15:59:17,009 INFO org.apache.hadoop.yarn.server.resourcemanager.scheduler.capacity.CapacityScheduler: Application appattempt_1377704542759_0005_000001 released container container_1377704542759_0005_01_000002 on node: host: hadoop-16-6:36337 #containers=1 available=6144 used=2048 with event: FINISHED
2013-08-28 15:59:21,153 INFO org.apache.hadoop.yarn.server.resourcemanager.rmapp.attempt.RMAppAttemptImpl: appattempt_1377704542759_0005_000001 State change from RUNNING to FINISHING
2013-08-28 15:59:21,154 INFO org.apache.hadoop.yarn.server.resourcemanager.rmapp.RMAppImpl: application_1377704542759_0005 State change from RUNNING to FINISHING
2013-08-28 15:59:22,028 INFO org.apache.hadoop.yarn.server.resourcemanager.rmcontainer.RMContainerImpl: container_1377704542759_0005_01_000001 Container Transitioned from RUNNING to COMPLETED
2013-08-28 15:59:22,028 INFO org.apache.hadoop.yarn.server.resourcemanager.scheduler.common.fica.FiCaSchedulerApp: Completed container: container_1377704542759_0005_01_000001 in state: COMPLETED event:FINISHED
2013-08-28 15:59:22,028 INFO org.apache.hadoop.yarn.server.resourcemanager.rmapp.attempt.RMAppAttemptImpl: appattempt_1377704542759_0005_000001 State change from FINISHING to FINISHED
2013-08-28 15:59:22,029 INFO org.apache.hadoop.yarn.server.resourcemanager.RMAuditLogger: USER=ubuntu	OPERATION=AM Released Container	TARGET=SchedulerApp	RESULT=SUCCESS	APPID=application_1377704542759_0005	CONTAINERID=container_1377704542759_0005_01_000001
2013-08-28 15:59:22,029 INFO org.apache.hadoop.yarn.server.resourcemanager.rmapp.RMAppImpl: application_1377704542759_0005 State change from FINISHING to FINISHED
2013-08-28 15:59:22,029 INFO org.apache.hadoop.yarn.server.resourcemanager.scheduler.common.fica.FiCaSchedulerNode: Released container container_1377704542759_0005_01_000001 of capacity <memory:2048, vCores:1> on host hadoop-16-6:36337, which currently has 0 containers, <memory:0, vCores:0> used and <memory:8192, vCores:16> available, release resources=true
2013-08-28 15:59:22,029 INFO org.apache.hadoop.yarn.server.resourcemanager.RMAuditLogger: USER=ubuntu	OPERATION=Application Finished - Succeeded	TARGET=RMAppManager	RESULT=SUCCESS	APPID=application_1377704542759_0005
2013-08-28 15:59:22,030 INFO org.apache.hadoop.yarn.server.resourcemanager.scheduler.capacity.LeafQueue: default used=<memory:0, vCores:0> numContainers=0 user=ubuntu user-resources=<memory:0, vCores:0>
2013-08-28 15:59:22,030 INFO org.apache.hadoop.yarn.server.resourcemanager.amlauncher.AMLauncher: Cleaning master appattempt_1377704542759_0005_000001
2013-08-28 15:59:22,030 INFO org.apache.hadoop.yarn.server.resourcemanager.recovery.RMStateStore: Removing info for app: application_1377704542759_0005
2013-08-28 15:59:22,030 INFO org.apache.hadoop.yarn.server.resourcemanager.RMAppManager$ApplicationSummary: appId=application_1377704542759_0005,name=TeraGen,user=ubuntu,queue=default,state=FINISHED,trackingUrl=hadoop-16-1.novalocal:8088/proxy/application_1377704542759_0005/jobhistory/job/job_1377704542759_0005,appMasterHost=hadoop-16-6,startTime=1377705364500,finishTime=1377705561154
2013-08-28 15:59:22,031 INFO org.apache.hadoop.yarn.server.resourcemanager.scheduler.capacity.LeafQueue: completedContainer container=Container: [ContainerId: container_1377704542759_0005_01_000001, NodeId: hadoop-16-6:36337, NodeHttpAddress: hadoop-16-6:8042, Resource: <memory:2048, vCores:1>, Priority: 0, State: NEW, Token: null, Status: container_id {, app_attempt_id {, application_id {, id: 5, cluster_timestamp: 1377704542759, }, attemptId: 1, }, id: 1, }, state: C_COMPLETE, diagnostics: "", exit_status: 0, ] resource=<memory:2048, vCores:1> queue=default: capacity=1.0, absoluteCapacity=1.0, usedResources=<memory:0, vCores:0>usedCapacity=0.0, absoluteUsedCapacity=0.0, numApps=1, numContainers=0 usedCapacity=0.0 absoluteUsedCapacity=0.0 used=<memory:0, vCores:0> cluster=<memory:49152, vCores:96>
2013-08-28 15:59:22,031 INFO org.apache.hadoop.yarn.server.resourcemanager.scheduler.capacity.ParentQueue: completedContainer queue=root usedCapacity=0.0 absoluteUsedCapacity=0.0 used=<memory:0, vCores:0> cluster=<memory:49152, vCores:96>
2013-08-28 15:59:22,032 INFO org.apache.hadoop.yarn.server.resourcemanager.scheduler.capacity.CapacityScheduler: Application appattempt_1377704542759_0005_000001 released container container_1377704542759_0005_01_000001 on node: host: hadoop-16-6:36337 #containers=0 available=8192 used=0 with event: FINISHED
2013-08-28 15:59:22,032 INFO org.apache.hadoop.yarn.server.resourcemanager.scheduler.capacity.CapacityScheduler: Application appattempt_1377704542759_0005_000001 is done. finalState=FINISHED
2013-08-28 15:59:22,032 INFO org.apache.hadoop.yarn.server.resourcemanager.scheduler.AppSchedulingInfo: Application application_1377704542759_0005 requests cleared
2013-08-28 15:59:22,032 INFO org.apache.hadoop.yarn.server.resourcemanager.scheduler.capacity.LeafQueue: Application removed - appId: application_1377704542759_0005 user: ubuntu queue: default #user-pending-applications: 0 #user-active-applications: 0 #queue-pending-applications: 0 #queue-active-applications: 0
2013-08-28 15:59:22,032 INFO org.apache.hadoop.yarn.server.resourcemanager.scheduler.capacity.ParentQueue: Application removed - appId: application_1377704542759_0005 user: ubuntu leaf-queue of parent: root #applications: 0
2013-08-28 15:59:37,883 INFO org.apache.hadoop.yarn.server.resourcemanager.ClientRMService: Allocated new applicationId: 6
2013-08-28 15:59:37,977 INFO org.apache.hadoop.yarn.server.resourcemanager.ClientRMService: Allocated new applicationId: 7
2013-08-28 15:59:38,140 INFO org.apache.hadoop.yarn.server.resourcemanager.ClientRMService: Allocated new applicationId: 8
2013-08-28 15:59:38,151 INFO org.apache.hadoop.yarn.server.resourcemanager.ClientRMService: Allocated new applicationId: 9
2013-08-28 15:59:38,646 INFO org.apache.hadoop.yarn.server.resourcemanager.ClientRMService: Allocated new applicationId: 10
2013-08-28 15:59:39,684 INFO org.apache.hadoop.yarn.server.resourcemanager.ClientRMService: Storing Application with id application_1377704542759_0006
2013-08-28 15:59:39,684 INFO org.apache.hadoop.yarn.server.resourcemanager.recovery.RMStateStore: Storing info for app: application_1377704542759_0006
2013-08-28 15:59:39,684 INFO org.apache.hadoop.yarn.server.resourcemanager.ClientRMService: Application with id 6 submitted by user ubuntu
2013-08-28 15:59:39,684 INFO org.apache.hadoop.yarn.server.resourcemanager.RMAuditLogger: USER=ubuntu	IP=192.168.100.5	OPERATION=Submit Application Request	TARGET=ClientRMService	RESULT=SUCCESS	APPID=application_1377704542759_0006
2013-08-28 15:59:39,685 INFO org.apache.hadoop.yarn.server.resourcemanager.rmapp.RMAppImpl: application_1377704542759_0006 State change from NEW to SUBMITTED
2013-08-28 15:59:39,685 INFO org.apache.hadoop.yarn.server.resourcemanager.ApplicationMasterService: Registering appattempt_1377704542759_0006_000001
2013-08-28 15:59:39,685 INFO org.apache.hadoop.yarn.server.resourcemanager.rmapp.attempt.RMAppAttemptImpl: appattempt_1377704542759_0006_000001 State change from NEW to SUBMITTED
2013-08-28 15:59:39,685 INFO org.apache.hadoop.yarn.server.resourcemanager.scheduler.capacity.LeafQueue: Application application_1377704542759_0006 from user: ubuntu activated in queue: default
2013-08-28 15:59:39,685 INFO org.apache.hadoop.yarn.server.resourcemanager.scheduler.capacity.LeafQueue: Application added - appId: application_1377704542759_0006 user: org.apache.hadoop.yarn.server.resourcemanager.scheduler.capacity.LeafQueue$User@2b40b499, leaf-queue: default #user-pending-applications: 0 #user-active-applications: 1 #queue-pending-applications: 0 #queue-active-applications: 1
2013-08-28 15:59:39,685 INFO org.apache.hadoop.yarn.server.resourcemanager.scheduler.capacity.ParentQueue: Application added - appId: application_1377704542759_0006 user: ubuntu leaf-queue of parent: root #applications: 1
2013-08-28 15:59:39,685 INFO org.apache.hadoop.yarn.server.resourcemanager.scheduler.capacity.CapacityScheduler: Application Submission: appattempt_1377704542759_0006_000001, user: ubuntu queue: default: capacity=1.0, absoluteCapacity=1.0, usedResources=<memory:0, vCores:0>usedCapacity=0.0, absoluteUsedCapacity=0.0, numApps=1, numContainers=0, currently active: 1
2013-08-28 15:59:39,686 INFO org.apache.hadoop.yarn.server.resourcemanager.rmapp.attempt.RMAppAttemptImpl: appattempt_1377704542759_0006_000001 State change from SUBMITTED to SCHEDULED
2013-08-28 15:59:39,686 INFO org.apache.hadoop.yarn.server.resourcemanager.rmapp.RMAppImpl: application_1377704542759_0006 State change from SUBMITTED to ACCEPTED
2013-08-28 15:59:39,708 INFO org.apache.hadoop.yarn.server.resourcemanager.ClientRMService: Storing Application with id application_1377704542759_0007
2013-08-28 15:59:39,708 INFO org.apache.hadoop.yarn.server.resourcemanager.recovery.RMStateStore: Storing info for app: application_1377704542759_0007
2013-08-28 15:59:39,709 INFO org.apache.hadoop.yarn.server.resourcemanager.ClientRMService: Application with id 7 submitted by user ubuntu
2013-08-28 15:59:39,709 INFO org.apache.hadoop.yarn.server.resourcemanager.RMAuditLogger: USER=ubuntu	IP=192.168.100.5	OPERATION=Submit Application Request	TARGET=ClientRMService	RESULT=SUCCESS	APPID=application_1377704542759_0007
2013-08-28 15:59:39,709 INFO org.apache.hadoop.yarn.server.resourcemanager.rmapp.RMAppImpl: application_1377704542759_0007 State change from NEW to SUBMITTED
2013-08-28 15:59:39,709 INFO org.apache.hadoop.yarn.server.resourcemanager.ApplicationMasterService: Registering appattempt_1377704542759_0007_000001
2013-08-28 15:59:39,709 INFO org.apache.hadoop.yarn.server.resourcemanager.rmapp.attempt.RMAppAttemptImpl: appattempt_1377704542759_0007_000001 State change from NEW to SUBMITTED
2013-08-28 15:59:39,709 INFO org.apache.hadoop.yarn.server.resourcemanager.scheduler.capacity.LeafQueue: Application application_1377704542759_0007 from user: ubuntu activated in queue: default
2013-08-28 15:59:39,710 INFO org.apache.hadoop.yarn.server.resourcemanager.scheduler.capacity.LeafQueue: Application added - appId: application_1377704542759_0007 user: org.apache.hadoop.yarn.server.resourcemanager.scheduler.capacity.LeafQueue$User@2b40b499, leaf-queue: default #user-pending-applications: 0 #user-active-applications: 2 #queue-pending-applications: 0 #queue-active-applications: 2
2013-08-28 15:59:39,710 INFO org.apache.hadoop.yarn.server.resourcemanager.scheduler.capacity.ParentQueue: Application added - appId: application_1377704542759_0007 user: ubuntu leaf-queue of parent: root #applications: 2
2013-08-28 15:59:39,710 INFO org.apache.hadoop.yarn.server.resourcemanager.scheduler.capacity.CapacityScheduler: Application Submission: appattempt_1377704542759_0007_000001, user: ubuntu queue: default: capacity=1.0, absoluteCapacity=1.0, usedResources=<memory:0, vCores:0>usedCapacity=0.0, absoluteUsedCapacity=0.0, numApps=2, numContainers=0, currently active: 2
2013-08-28 15:59:39,710 INFO org.apache.hadoop.yarn.server.resourcemanager.rmapp.attempt.RMAppAttemptImpl: appattempt_1377704542759_0007_000001 State change from SUBMITTED to SCHEDULED
2013-08-28 15:59:39,710 INFO org.apache.hadoop.yarn.server.resourcemanager.rmapp.RMAppImpl: application_1377704542759_0007 State change from SUBMITTED to ACCEPTED
2013-08-28 15:59:39,784 INFO org.apache.hadoop.yarn.server.resourcemanager.ClientRMService: Storing Application with id application_1377704542759_0009
2013-08-28 15:59:39,784 INFO org.apache.hadoop.yarn.server.resourcemanager.recovery.RMStateStore: Storing info for app: application_1377704542759_0009
2013-08-28 15:59:39,784 INFO org.apache.hadoop.yarn.server.resourcemanager.ClientRMService: Application with id 9 submitted by user ubuntu
2013-08-28 15:59:39,784 INFO org.apache.hadoop.yarn.server.resourcemanager.RMAuditLogger: USER=ubuntu	IP=192.168.100.5	OPERATION=Submit Application Request	TARGET=ClientRMService	RESULT=SUCCESS	APPID=application_1377704542759_0009
2013-08-28 15:59:39,785 INFO org.apache.hadoop.yarn.server.resourcemanager.rmapp.RMAppImpl: application_1377704542759_0009 State change from NEW to SUBMITTED
2013-08-28 15:59:39,785 INFO org.apache.hadoop.yarn.server.resourcemanager.ApplicationMasterService: Registering appattempt_1377704542759_0009_000001
2013-08-28 15:59:39,785 INFO org.apache.hadoop.yarn.server.resourcemanager.rmapp.attempt.RMAppAttemptImpl: appattempt_1377704542759_0009_000001 State change from NEW to SUBMITTED
2013-08-28 15:59:39,785 INFO org.apache.hadoop.yarn.server.resourcemanager.scheduler.capacity.LeafQueue: Application application_1377704542759_0009 from user: ubuntu activated in queue: default
2013-08-28 15:59:39,785 INFO org.apache.hadoop.yarn.server.resourcemanager.scheduler.capacity.LeafQueue: Application added - appId: application_1377704542759_0009 user: org.apache.hadoop.yarn.server.resourcemanager.scheduler.capacity.LeafQueue$User@2b40b499, leaf-queue: default #user-pending-applications: 0 #user-active-applications: 3 #queue-pending-applications: 0 #queue-active-applications: 3
2013-08-28 15:59:39,786 INFO org.apache.hadoop.yarn.server.resourcemanager.scheduler.capacity.ParentQueue: Application added - appId: application_1377704542759_0009 user: ubuntu leaf-queue of parent: root #applications: 3
2013-08-28 15:59:39,786 INFO org.apache.hadoop.yarn.server.resourcemanager.scheduler.capacity.CapacityScheduler: Application Submission: appattempt_1377704542759_0009_000001, user: ubuntu queue: default: capacity=1.0, absoluteCapacity=1.0, usedResources=<memory:0, vCores:0>usedCapacity=0.0, absoluteUsedCapacity=0.0, numApps=3, numContainers=0, currently active: 3
2013-08-28 15:59:39,786 INFO org.apache.hadoop.yarn.server.resourcemanager.rmapp.attempt.RMAppAttemptImpl: appattempt_1377704542759_0009_000001 State change from SUBMITTED to SCHEDULED
2013-08-28 15:59:39,786 INFO org.apache.hadoop.yarn.server.resourcemanager.rmapp.RMAppImpl: application_1377704542759_0009 State change from SUBMITTED to ACCEPTED
2013-08-28 15:59:39,792 INFO org.apache.hadoop.yarn.server.resourcemanager.rmcontainer.RMContainerImpl: container_1377704542759_0006_01_000001 Container Transitioned from NEW to ALLOCATED
2013-08-28 15:59:39,792 INFO org.apache.hadoop.yarn.server.resourcemanager.RMAuditLogger: USER=ubuntu	OPERATION=AM Allocated Container	TARGET=SchedulerApp	RESULT=SUCCESS	APPID=application_1377704542759_0006	CONTAINERID=container_1377704542759_0006_01_000001
2013-08-28 15:59:39,792 INFO org.apache.hadoop.yarn.server.resourcemanager.scheduler.common.fica.FiCaSchedulerNode: Assigned container container_1377704542759_0006_01_000001 of capacity <memory:2048, vCores:1> on host hadoop-16-3:41896, which currently has 1 containers, <memory:2048, vCores:1> used and <memory:6144, vCores:15> available
2013-08-28 15:59:39,793 INFO org.apache.hadoop.yarn.server.resourcemanager.scheduler.capacity.LeafQueue: assignedContainer application=application_1377704542759_0006 container=Container: [ContainerId: container_1377704542759_0006_01_000001, NodeId: hadoop-16-3:41896, NodeHttpAddress: hadoop-16-3:8042, Resource: <memory:2048, vCores:1>, Priority: 0, State: NEW, Token: null, Status: container_id {, app_attempt_id {, application_id {, id: 6, cluster_timestamp: 1377704542759, }, attemptId: 1, }, id: 1, }, state: C_NEW, ] containerId=container_1377704542759_0006_01_000001 queue=default: capacity=1.0, absoluteCapacity=1.0, usedResources=<memory:0, vCores:0>usedCapacity=0.0, absoluteUsedCapacity=0.0, numApps=3, numContainers=0 usedCapacity=0.0 absoluteUsedCapacity=0.0 used=<memory:0, vCores:0> cluster=<memory:49152, vCores:96>
2013-08-28 15:59:39,793 INFO org.apache.hadoop.yarn.server.resourcemanager.scheduler.capacity.ParentQueue: Re-sorting queues since queue: root.default stats: default: capacity=1.0, absoluteCapacity=1.0, usedResources=<memory:2048, vCores:1>usedCapacity=0.041666668, absoluteUsedCapacity=0.041666668, numApps=3, numContainers=1
2013-08-28 15:59:39,793 INFO org.apache.hadoop.yarn.server.resourcemanager.scheduler.capacity.ParentQueue: assignedContainer queue=root usedCapacity=0.041666668 absoluteUsedCapacity=0.041666668 used=<memory:2048, vCores:1> cluster=<memory:49152, vCores:96>
2013-08-28 15:59:39,794 INFO org.apache.hadoop.yarn.server.resourcemanager.rmcontainer.RMContainerImpl: container_1377704542759_0006_01_000001 Container Transitioned from ALLOCATED to ACQUIRED
2013-08-28 15:59:39,794 INFO org.apache.hadoop.yarn.server.resourcemanager.rmapp.attempt.RMAppAttemptImpl: Storing attempt: AppId: application_1377704542759_0006 AttemptId: appattempt_1377704542759_0006_000001 MasterContainer: Container: [ContainerId: container_1377704542759_0006_01_000001, NodeId: hadoop-16-3:41896, NodeHttpAddress: hadoop-16-3:8042, Resource: <memory:2048, vCores:1>, Priority: 0, State: NEW, Token: null, Status: container_id {, app_attempt_id {, application_id {, id: 6, cluster_timestamp: 1377704542759, }, attemptId: 1, }, id: 1, }, state: C_NEW, ]
2013-08-28 15:59:39,795 INFO org.apache.hadoop.yarn.server.resourcemanager.recovery.RMStateStore: Storing info for attempt: appattempt_1377704542759_0006_000001
2013-08-28 15:59:39,795 INFO org.apache.hadoop.yarn.server.resourcemanager.rmapp.attempt.RMAppAttemptImpl: appattempt_1377704542759_0006_000001 State change from SCHEDULED to ALLOCATED_SAVING
2013-08-28 15:59:39,795 INFO org.apache.hadoop.yarn.server.resourcemanager.rmapp.attempt.RMAppAttemptImpl: appattempt_1377704542759_0006_000001 State change from ALLOCATED_SAVING to ALLOCATED
2013-08-28 15:59:39,795 INFO org.apache.hadoop.yarn.server.resourcemanager.amlauncher.AMLauncher: Launching masterappattempt_1377704542759_0006_000001
2013-08-28 15:59:39,796 INFO org.apache.hadoop.yarn.server.resourcemanager.amlauncher.AMLauncher: Setting up container Container: [ContainerId: container_1377704542759_0006_01_000001, NodeId: hadoop-16-3:41896, NodeHttpAddress: hadoop-16-3:8042, Resource: <memory:2048, vCores:1>, Priority: 0, State: NEW, Token: null, Status: container_id {, app_attempt_id {, application_id {, id: 6, cluster_timestamp: 1377704542759, }, attemptId: 1, }, id: 1, }, state: C_NEW, ] for AM appattempt_1377704542759_0006_000001
2013-08-28 15:59:39,797 INFO org.apache.hadoop.yarn.server.resourcemanager.amlauncher.AMLauncher: Command to launch container container_1377704542759_0006_01_000001 : $JAVA_HOME/bin/java -Dlog4j.configuration=container-log4j.properties -Dyarn.app.mapreduce.container.log.dir=<LOG_DIR> -Dyarn.app.mapreduce.container.log.filesize=0 -Dhadoop.root.logger=INFO,CLA  -Xmx1024m org.apache.hadoop.mapreduce.v2.app.MRAppMaster 1><LOG_DIR>/stdout 2><LOG_DIR>/stderr 
2013-08-28 15:59:39,821 INFO org.apache.hadoop.yarn.server.resourcemanager.amlauncher.AMLauncher: Done launching container Container: [ContainerId: container_1377704542759_0006_01_000001, NodeId: hadoop-16-3:41896, NodeHttpAddress: hadoop-16-3:8042, Resource: <memory:2048, vCores:1>, Priority: 0, State: NEW, Token: null, Status: container_id {, app_attempt_id {, application_id {, id: 6, cluster_timestamp: 1377704542759, }, attemptId: 1, }, id: 1, }, state: C_NEW, ] for AM appattempt_1377704542759_0006_000001
2013-08-28 15:59:39,821 INFO org.apache.hadoop.yarn.server.resourcemanager.rmapp.attempt.RMAppAttemptImpl: appattempt_1377704542759_0006_000001 State change from ALLOCATED to LAUNCHED
2013-08-28 15:59:39,845 INFO org.apache.hadoop.yarn.server.resourcemanager.ClientRMService: Storing Application with id application_1377704542759_0008
2013-08-28 15:59:39,845 INFO org.apache.hadoop.yarn.server.resourcemanager.recovery.RMStateStore: Storing info for app: application_1377704542759_0008
2013-08-28 15:59:39,845 INFO org.apache.hadoop.yarn.server.resourcemanager.ClientRMService: Application with id 8 submitted by user ubuntu
2013-08-28 15:59:39,845 INFO org.apache.hadoop.yarn.server.resourcemanager.RMAuditLogger: USER=ubuntu	IP=192.168.100.5	OPERATION=Submit Application Request	TARGET=ClientRMService	RESULT=SUCCESS	APPID=application_1377704542759_0008
2013-08-28 15:59:39,852 INFO org.apache.hadoop.yarn.server.resourcemanager.rmapp.RMAppImpl: application_1377704542759_0008 State change from NEW to SUBMITTED
2013-08-28 15:59:39,852 INFO org.apache.hadoop.yarn.server.resourcemanager.ApplicationMasterService: Registering appattempt_1377704542759_0008_000001
2013-08-28 15:59:39,852 INFO org.apache.hadoop.yarn.server.resourcemanager.rmapp.attempt.RMAppAttemptImpl: appattempt_1377704542759_0008_000001 State change from NEW to SUBMITTED
2013-08-28 15:59:39,853 INFO org.apache.hadoop.yarn.server.resourcemanager.scheduler.capacity.LeafQueue: Application application_1377704542759_0008 from user: ubuntu activated in queue: default
2013-08-28 15:59:39,853 INFO org.apache.hadoop.yarn.server.resourcemanager.scheduler.capacity.LeafQueue: Application added - appId: application_1377704542759_0008 user: org.apache.hadoop.yarn.server.resourcemanager.scheduler.capacity.LeafQueue$User@2b40b499, leaf-queue: default #user-pending-applications: 0 #user-active-applications: 4 #queue-pending-applications: 0 #queue-active-applications: 4
2013-08-28 15:59:39,853 INFO org.apache.hadoop.yarn.server.resourcemanager.scheduler.capacity.ParentQueue: Application added - appId: application_1377704542759_0008 user: ubuntu leaf-queue of parent: root #applications: 4
2013-08-28 15:59:39,853 INFO org.apache.hadoop.yarn.server.resourcemanager.scheduler.capacity.CapacityScheduler: Application Submission: appattempt_1377704542759_0008_000001, user: ubuntu queue: default: capacity=1.0, absoluteCapacity=1.0, usedResources=<memory:2048, vCores:1>usedCapacity=0.041666668, absoluteUsedCapacity=0.041666668, numApps=4, numContainers=1, currently active: 4
2013-08-28 15:59:39,853 INFO org.apache.hadoop.yarn.server.resourcemanager.rmapp.attempt.RMAppAttemptImpl: appattempt_1377704542759_0008_000001 State change from SUBMITTED to SCHEDULED
2013-08-28 15:59:39,853 INFO org.apache.hadoop.yarn.server.resourcemanager.rmapp.RMAppImpl: application_1377704542759_0008 State change from SUBMITTED to ACCEPTED
2013-08-28 15:59:39,859 INFO org.apache.hadoop.yarn.server.resourcemanager.rmcontainer.RMContainerImpl: container_1377704542759_0007_01_000001 Container Transitioned from NEW to ALLOCATED
2013-08-28 15:59:39,859 INFO org.apache.hadoop.yarn.server.resourcemanager.RMAuditLogger: USER=ubuntu	OPERATION=AM Allocated Container	TARGET=SchedulerApp	RESULT=SUCCESS	APPID=application_1377704542759_0007	CONTAINERID=container_1377704542759_0007_01_000001
2013-08-28 15:59:39,859 INFO org.apache.hadoop.yarn.server.resourcemanager.scheduler.common.fica.FiCaSchedulerNode: Assigned container container_1377704542759_0007_01_000001 of capacity <memory:2048, vCores:1> on host hadoop-16-4:52495, which currently has 1 containers, <memory:2048, vCores:1> used and <memory:6144, vCores:15> available
2013-08-28 15:59:39,859 INFO org.apache.hadoop.yarn.server.resourcemanager.scheduler.capacity.LeafQueue: assignedContainer application=application_1377704542759_0007 container=Container: [ContainerId: container_1377704542759_0007_01_000001, NodeId: hadoop-16-4:52495, NodeHttpAddress: hadoop-16-4:8042, Resource: <memory:2048, vCores:1>, Priority: 0, State: NEW, Token: null, Status: container_id {, app_attempt_id {, application_id {, id: 7, cluster_timestamp: 1377704542759, }, attemptId: 1, }, id: 1, }, state: C_NEW, ] containerId=container_1377704542759_0007_01_000001 queue=default: capacity=1.0, absoluteCapacity=1.0, usedResources=<memory:2048, vCores:1>usedCapacity=0.041666668, absoluteUsedCapacity=0.041666668, numApps=4, numContainers=1 usedCapacity=0.041666668 absoluteUsedCapacity=0.041666668 used=<memory:2048, vCores:1> cluster=<memory:49152, vCores:96>
2013-08-28 15:59:39,860 INFO org.apache.hadoop.yarn.server.resourcemanager.scheduler.capacity.ParentQueue: Re-sorting queues since queue: root.default stats: default: capacity=1.0, absoluteCapacity=1.0, usedResources=<memory:4096, vCores:2>usedCapacity=0.083333336, absoluteUsedCapacity=0.083333336, numApps=4, numContainers=2
2013-08-28 15:59:39,860 INFO org.apache.hadoop.yarn.server.resourcemanager.scheduler.capacity.ParentQueue: assignedContainer queue=root usedCapacity=0.083333336 absoluteUsedCapacity=0.083333336 used=<memory:4096, vCores:2> cluster=<memory:49152, vCores:96>
2013-08-28 15:59:39,860 INFO org.apache.hadoop.yarn.server.resourcemanager.rmcontainer.RMContainerImpl: container_1377704542759_0007_01_000001 Container Transitioned from ALLOCATED to ACQUIRED
2013-08-28 15:59:39,861 INFO org.apache.hadoop.yarn.server.resourcemanager.rmapp.attempt.RMAppAttemptImpl: Storing attempt: AppId: application_1377704542759_0007 AttemptId: appattempt_1377704542759_0007_000001 MasterContainer: Container: [ContainerId: container_1377704542759_0007_01_000001, NodeId: hadoop-16-4:52495, NodeHttpAddress: hadoop-16-4:8042, Resource: <memory:2048, vCores:1>, Priority: 0, State: NEW, Token: null, Status: container_id {, app_attempt_id {, application_id {, id: 7, cluster_timestamp: 1377704542759, }, attemptId: 1, }, id: 1, }, state: C_NEW, ]
2013-08-28 15:59:39,861 INFO org.apache.hadoop.yarn.server.resourcemanager.rmapp.attempt.RMAppAttemptImpl: appattempt_1377704542759_0007_000001 State change from SCHEDULED to ALLOCATED_SAVING
2013-08-28 15:59:39,861 INFO org.apache.hadoop.yarn.server.resourcemanager.recovery.RMStateStore: Storing info for attempt: appattempt_1377704542759_0007_000001
2013-08-28 15:59:39,862 INFO org.apache.hadoop.yarn.server.resourcemanager.rmapp.attempt.RMAppAttemptImpl: appattempt_1377704542759_0007_000001 State change from ALLOCATED_SAVING to ALLOCATED
2013-08-28 15:59:39,862 INFO org.apache.hadoop.yarn.server.resourcemanager.amlauncher.AMLauncher: Launching masterappattempt_1377704542759_0007_000001
2013-08-28 15:59:39,864 INFO org.apache.hadoop.yarn.server.resourcemanager.amlauncher.AMLauncher: Setting up container Container: [ContainerId: container_1377704542759_0007_01_000001, NodeId: hadoop-16-4:52495, NodeHttpAddress: hadoop-16-4:8042, Resource: <memory:2048, vCores:1>, Priority: 0, State: NEW, Token: null, Status: container_id {, app_attempt_id {, application_id {, id: 7, cluster_timestamp: 1377704542759, }, attemptId: 1, }, id: 1, }, state: C_NEW, ] for AM appattempt_1377704542759_0007_000001
2013-08-28 15:59:39,864 INFO org.apache.hadoop.yarn.server.resourcemanager.amlauncher.AMLauncher: Command to launch container container_1377704542759_0007_01_000001 : $JAVA_HOME/bin/java -Dlog4j.configuration=container-log4j.properties -Dyarn.app.mapreduce.container.log.dir=<LOG_DIR> -Dyarn.app.mapreduce.container.log.filesize=0 -Dhadoop.root.logger=INFO,CLA  -Xmx1024m org.apache.hadoop.mapreduce.v2.app.MRAppMaster 1><LOG_DIR>/stdout 2><LOG_DIR>/stderr 
2013-08-28 15:59:39,884 INFO org.apache.hadoop.yarn.server.resourcemanager.amlauncher.AMLauncher: Done launching container Container: [ContainerId: container_1377704542759_0007_01_000001, NodeId: hadoop-16-4:52495, NodeHttpAddress: hadoop-16-4:8042, Resource: <memory:2048, vCores:1>, Priority: 0, State: NEW, Token: null, Status: container_id {, app_attempt_id {, application_id {, id: 7, cluster_timestamp: 1377704542759, }, attemptId: 1, }, id: 1, }, state: C_NEW, ] for AM appattempt_1377704542759_0007_000001
2013-08-28 15:59:39,884 INFO org.apache.hadoop.yarn.server.resourcemanager.rmapp.attempt.RMAppAttemptImpl: appattempt_1377704542759_0007_000001 State change from ALLOCATED to LAUNCHED
2013-08-28 15:59:39,936 INFO org.apache.hadoop.yarn.server.resourcemanager.rmcontainer.RMContainerImpl: container_1377704542759_0008_01_000001 Container Transitioned from NEW to ALLOCATED
2013-08-28 15:59:39,936 INFO org.apache.hadoop.yarn.server.resourcemanager.RMAuditLogger: USER=ubuntu	OPERATION=AM Allocated Container	TARGET=SchedulerApp	RESULT=SUCCESS	APPID=application_1377704542759_0008	CONTAINERID=container_1377704542759_0008_01_000001
2013-08-28 15:59:39,936 INFO org.apache.hadoop.yarn.server.resourcemanager.scheduler.common.fica.FiCaSchedulerNode: Assigned container container_1377704542759_0008_01_000001 of capacity <memory:2048, vCores:1> on host hadoop-16-7:53595, which currently has 1 containers, <memory:2048, vCores:1> used and <memory:6144, vCores:15> available
2013-08-28 15:59:39,937 INFO org.apache.hadoop.yarn.server.resourcemanager.scheduler.capacity.LeafQueue: assignedContainer application=application_1377704542759_0008 container=Container: [ContainerId: container_1377704542759_0008_01_000001, NodeId: hadoop-16-7:53595, NodeHttpAddress: hadoop-16-7:8042, Resource: <memory:2048, vCores:1>, Priority: 0, State: NEW, Token: null, Status: container_id {, app_attempt_id {, application_id {, id: 8, cluster_timestamp: 1377704542759, }, attemptId: 1, }, id: 1, }, state: C_NEW, ] containerId=container_1377704542759_0008_01_000001 queue=default: capacity=1.0, absoluteCapacity=1.0, usedResources=<memory:4096, vCores:2>usedCapacity=0.083333336, absoluteUsedCapacity=0.083333336, numApps=4, numContainers=2 usedCapacity=0.083333336 absoluteUsedCapacity=0.083333336 used=<memory:4096, vCores:2> cluster=<memory:49152, vCores:96>
2013-08-28 15:59:39,937 INFO org.apache.hadoop.yarn.server.resourcemanager.scheduler.capacity.ParentQueue: Re-sorting queues since queue: root.default stats: default: capacity=1.0, absoluteCapacity=1.0, usedResources=<memory:6144, vCores:3>usedCapacity=0.125, absoluteUsedCapacity=0.125, numApps=4, numContainers=3
2013-08-28 15:59:39,937 INFO org.apache.hadoop.yarn.server.resourcemanager.scheduler.capacity.ParentQueue: assignedContainer queue=root usedCapacity=0.125 absoluteUsedCapacity=0.125 used=<memory:6144, vCores:3> cluster=<memory:49152, vCores:96>
2013-08-28 15:59:39,937 INFO org.apache.hadoop.yarn.server.resourcemanager.rmcontainer.RMContainerImpl: container_1377704542759_0008_01_000001 Container Transitioned from ALLOCATED to ACQUIRED
2013-08-28 15:59:39,938 INFO org.apache.hadoop.yarn.server.resourcemanager.rmapp.attempt.RMAppAttemptImpl: Storing attempt: AppId: application_1377704542759_0008 AttemptId: appattempt_1377704542759_0008_000001 MasterContainer: Container: [ContainerId: container_1377704542759_0008_01_000001, NodeId: hadoop-16-7:53595, NodeHttpAddress: hadoop-16-7:8042, Resource: <memory:2048, vCores:1>, Priority: 0, State: NEW, Token: null, Status: container_id {, app_attempt_id {, application_id {, id: 8, cluster_timestamp: 1377704542759, }, attemptId: 1, }, id: 1, }, state: C_NEW, ]
2013-08-28 15:59:39,938 INFO org.apache.hadoop.yarn.server.resourcemanager.rmapp.attempt.RMAppAttemptImpl: appattempt_1377704542759_0008_000001 State change from SCHEDULED to ALLOCATED_SAVING
2013-08-28 15:59:39,938 INFO org.apache.hadoop.yarn.server.resourcemanager.recovery.RMStateStore: Storing info for attempt: appattempt_1377704542759_0008_000001
2013-08-28 15:59:39,938 INFO org.apache.hadoop.yarn.server.resourcemanager.rmapp.attempt.RMAppAttemptImpl: appattempt_1377704542759_0008_000001 State change from ALLOCATED_SAVING to ALLOCATED
2013-08-28 15:59:39,939 INFO org.apache.hadoop.yarn.server.resourcemanager.amlauncher.AMLauncher: Launching masterappattempt_1377704542759_0008_000001
2013-08-28 15:59:39,940 INFO org.apache.hadoop.yarn.server.resourcemanager.amlauncher.AMLauncher: Setting up container Container: [ContainerId: container_1377704542759_0008_01_000001, NodeId: hadoop-16-7:53595, NodeHttpAddress: hadoop-16-7:8042, Resource: <memory:2048, vCores:1>, Priority: 0, State: NEW, Token: null, Status: container_id {, app_attempt_id {, application_id {, id: 8, cluster_timestamp: 1377704542759, }, attemptId: 1, }, id: 1, }, state: C_NEW, ] for AM appattempt_1377704542759_0008_000001
2013-08-28 15:59:39,940 INFO org.apache.hadoop.yarn.server.resourcemanager.amlauncher.AMLauncher: Command to launch container container_1377704542759_0008_01_000001 : $JAVA_HOME/bin/java -Dlog4j.configuration=container-log4j.properties -Dyarn.app.mapreduce.container.log.dir=<LOG_DIR> -Dyarn.app.mapreduce.container.log.filesize=0 -Dhadoop.root.logger=INFO,CLA  -Xmx1024m org.apache.hadoop.mapreduce.v2.app.MRAppMaster 1><LOG_DIR>/stdout 2><LOG_DIR>/stderr 
2013-08-28 15:59:39,952 INFO org.apache.hadoop.yarn.server.resourcemanager.amlauncher.AMLauncher: Done launching container Container: [ContainerId: container_1377704542759_0008_01_000001, NodeId: hadoop-16-7:53595, NodeHttpAddress: hadoop-16-7:8042, Resource: <memory:2048, vCores:1>, Priority: 0, State: NEW, Token: null, Status: container_id {, app_attempt_id {, application_id {, id: 8, cluster_timestamp: 1377704542759, }, attemptId: 1, }, id: 1, }, state: C_NEW, ] for AM appattempt_1377704542759_0008_000001
2013-08-28 15:59:39,952 INFO org.apache.hadoop.yarn.server.resourcemanager.rmapp.attempt.RMAppAttemptImpl: appattempt_1377704542759_0008_000001 State change from ALLOCATED to LAUNCHED
2013-08-28 15:59:40,090 INFO org.apache.hadoop.yarn.server.resourcemanager.ClientRMService: Storing Application with id application_1377704542759_0010
2013-08-28 15:59:40,090 INFO org.apache.hadoop.yarn.server.resourcemanager.recovery.RMStateStore: Storing info for app: application_1377704542759_0010
2013-08-28 15:59:40,090 INFO org.apache.hadoop.yarn.server.resourcemanager.ClientRMService: Application with id 10 submitted by user ubuntu
2013-08-28 15:59:40,090 INFO org.apache.hadoop.yarn.server.resourcemanager.RMAuditLogger: USER=ubuntu	IP=192.168.100.5	OPERATION=Submit Application Request	TARGET=ClientRMService	RESULT=SUCCESS	APPID=application_1377704542759_0010
2013-08-28 15:59:40,090 INFO org.apache.hadoop.yarn.server.resourcemanager.rmapp.RMAppImpl: application_1377704542759_0010 State change from NEW to SUBMITTED
2013-08-28 15:59:40,090 INFO org.apache.hadoop.yarn.server.resourcemanager.ApplicationMasterService: Registering appattempt_1377704542759_0010_000001
2013-08-28 15:59:40,090 INFO org.apache.hadoop.yarn.server.resourcemanager.rmapp.attempt.RMAppAttemptImpl: appattempt_1377704542759_0010_000001 State change from NEW to SUBMITTED
2013-08-28 15:59:40,091 INFO org.apache.hadoop.yarn.server.resourcemanager.scheduler.capacity.LeafQueue: Application application_1377704542759_0010 from user: ubuntu activated in queue: default
2013-08-28 15:59:40,091 INFO org.apache.hadoop.yarn.server.resourcemanager.scheduler.capacity.LeafQueue: Application added - appId: application_1377704542759_0010 user: org.apache.hadoop.yarn.server.resourcemanager.scheduler.capacity.LeafQueue$User@2b40b499, leaf-queue: default #user-pending-applications: 0 #user-active-applications: 5 #queue-pending-applications: 0 #queue-active-applications: 5
2013-08-28 15:59:40,091 INFO org.apache.hadoop.yarn.server.resourcemanager.scheduler.capacity.ParentQueue: Application added - appId: application_1377704542759_0010 user: ubuntu leaf-queue of parent: root #applications: 5
2013-08-28 15:59:40,091 INFO org.apache.hadoop.yarn.server.resourcemanager.scheduler.capacity.CapacityScheduler: Application Submission: appattempt_1377704542759_0010_000001, user: ubuntu queue: default: capacity=1.0, absoluteCapacity=1.0, usedResources=<memory:6144, vCores:3>usedCapacity=0.125, absoluteUsedCapacity=0.125, numApps=5, numContainers=3, currently active: 5
2013-08-28 15:59:40,092 INFO org.apache.hadoop.yarn.server.resourcemanager.rmapp.attempt.RMAppAttemptImpl: appattempt_1377704542759_0010_000001 State change from SUBMITTED to SCHEDULED
2013-08-28 15:59:40,092 INFO org.apache.hadoop.yarn.server.resourcemanager.rmapp.RMAppImpl: application_1377704542759_0010 State change from SUBMITTED to ACCEPTED
2013-08-28 15:59:40,102 INFO org.apache.hadoop.yarn.server.resourcemanager.rmcontainer.RMContainerImpl: container_1377704542759_0009_01_000001 Container Transitioned from NEW to ALLOCATED
2013-08-28 15:59:40,102 INFO org.apache.hadoop.yarn.server.resourcemanager.RMAuditLogger: USER=ubuntu	OPERATION=AM Allocated Container	TARGET=SchedulerApp	RESULT=SUCCESS	APPID=application_1377704542759_0009	CONTAINERID=container_1377704542759_0009_01_000001
2013-08-28 15:59:40,102 INFO org.apache.hadoop.yarn.server.resourcemanager.scheduler.common.fica.FiCaSchedulerNode: Assigned container container_1377704542759_0009_01_000001 of capacity <memory:2048, vCores:1> on host hadoop-16-6:36337, which currently has 1 containers, <memory:2048, vCores:1> used and <memory:6144, vCores:15> available
2013-08-28 15:59:40,103 INFO org.apache.hadoop.yarn.server.resourcemanager.scheduler.capacity.LeafQueue: assignedContainer application=application_1377704542759_0009 container=Container: [ContainerId: container_1377704542759_0009_01_000001, NodeId: hadoop-16-6:36337, NodeHttpAddress: hadoop-16-6:8042, Resource: <memory:2048, vCores:1>, Priority: 0, State: NEW, Token: null, Status: container_id {, app_attempt_id {, application_id {, id: 9, cluster_timestamp: 1377704542759, }, attemptId: 1, }, id: 1, }, state: C_NEW, ] containerId=container_1377704542759_0009_01_000001 queue=default: capacity=1.0, absoluteCapacity=1.0, usedResources=<memory:6144, vCores:3>usedCapacity=0.125, absoluteUsedCapacity=0.125, numApps=5, numContainers=3 usedCapacity=0.125 absoluteUsedCapacity=0.125 used=<memory:6144, vCores:3> cluster=<memory:49152, vCores:96>
2013-08-28 15:59:40,103 INFO org.apache.hadoop.yarn.server.resourcemanager.scheduler.capacity.ParentQueue: Re-sorting queues since queue: root.default stats: default: capacity=1.0, absoluteCapacity=1.0, usedResources=<memory:8192, vCores:4>usedCapacity=0.16666667, absoluteUsedCapacity=0.16666667, numApps=5, numContainers=4
2013-08-28 15:59:40,103 INFO org.apache.hadoop.yarn.server.resourcemanager.scheduler.capacity.ParentQueue: assignedContainer queue=root usedCapacity=0.16666667 absoluteUsedCapacity=0.16666667 used=<memory:8192, vCores:4> cluster=<memory:49152, vCores:96>
2013-08-28 15:59:40,103 INFO org.apache.hadoop.yarn.server.resourcemanager.rmcontainer.RMContainerImpl: container_1377704542759_0009_01_000001 Container Transitioned from ALLOCATED to ACQUIRED
2013-08-28 15:59:40,104 INFO org.apache.hadoop.yarn.server.resourcemanager.rmapp.attempt.RMAppAttemptImpl: Storing attempt: AppId: application_1377704542759_0009 AttemptId: appattempt_1377704542759_0009_000001 MasterContainer: Container: [ContainerId: container_1377704542759_0009_01_000001, NodeId: hadoop-16-6:36337, NodeHttpAddress: hadoop-16-6:8042, Resource: <memory:2048, vCores:1>, Priority: 0, State: NEW, Token: null, Status: container_id {, app_attempt_id {, application_id {, id: 9, cluster_timestamp: 1377704542759, }, attemptId: 1, }, id: 1, }, state: C_NEW, ]
2013-08-28 15:59:40,104 INFO org.apache.hadoop.yarn.server.resourcemanager.rmapp.attempt.RMAppAttemptImpl: appattempt_1377704542759_0009_000001 State change from SCHEDULED to ALLOCATED_SAVING
2013-08-28 15:59:40,104 INFO org.apache.hadoop.yarn.server.resourcemanager.recovery.RMStateStore: Storing info for attempt: appattempt_1377704542759_0009_000001
2013-08-28 15:59:40,105 INFO org.apache.hadoop.yarn.server.resourcemanager.rmapp.attempt.RMAppAttemptImpl: appattempt_1377704542759_0009_000001 State change from ALLOCATED_SAVING to ALLOCATED
2013-08-28 15:59:40,105 INFO org.apache.hadoop.yarn.server.resourcemanager.amlauncher.AMLauncher: Launching masterappattempt_1377704542759_0009_000001
2013-08-28 15:59:40,106 INFO org.apache.hadoop.yarn.server.resourcemanager.amlauncher.AMLauncher: Setting up container Container: [ContainerId: container_1377704542759_0009_01_000001, NodeId: hadoop-16-6:36337, NodeHttpAddress: hadoop-16-6:8042, Resource: <memory:2048, vCores:1>, Priority: 0, State: NEW, Token: null, Status: container_id {, app_attempt_id {, application_id {, id: 9, cluster_timestamp: 1377704542759, }, attemptId: 1, }, id: 1, }, state: C_NEW, ] for AM appattempt_1377704542759_0009_000001
2013-08-28 15:59:40,106 INFO org.apache.hadoop.yarn.server.resourcemanager.amlauncher.AMLauncher: Command to launch container container_1377704542759_0009_01_000001 : $JAVA_HOME/bin/java -Dlog4j.configuration=container-log4j.properties -Dyarn.app.mapreduce.container.log.dir=<LOG_DIR> -Dyarn.app.mapreduce.container.log.filesize=0 -Dhadoop.root.logger=INFO,CLA  -Xmx1024m org.apache.hadoop.mapreduce.v2.app.MRAppMaster 1><LOG_DIR>/stdout 2><LOG_DIR>/stderr 
2013-08-28 15:59:40,117 INFO org.apache.hadoop.yarn.server.resourcemanager.amlauncher.AMLauncher: Done launching container Container: [ContainerId: container_1377704542759_0009_01_000001, NodeId: hadoop-16-6:36337, NodeHttpAddress: hadoop-16-6:8042, Resource: <memory:2048, vCores:1>, Priority: 0, State: NEW, Token: null, Status: container_id {, app_attempt_id {, application_id {, id: 9, cluster_timestamp: 1377704542759, }, attemptId: 1, }, id: 1, }, state: C_NEW, ] for AM appattempt_1377704542759_0009_000001
2013-08-28 15:59:40,117 INFO org.apache.hadoop.yarn.server.resourcemanager.rmapp.attempt.RMAppAttemptImpl: appattempt_1377704542759_0009_000001 State change from ALLOCATED to LAUNCHED
2013-08-28 15:59:40,555 INFO org.apache.hadoop.yarn.server.resourcemanager.rmcontainer.RMContainerImpl: container_1377704542759_0010_01_000001 Container Transitioned from NEW to ALLOCATED
2013-08-28 15:59:40,556 INFO org.apache.hadoop.yarn.server.resourcemanager.RMAuditLogger: USER=ubuntu	OPERATION=AM Allocated Container	TARGET=SchedulerApp	RESULT=SUCCESS	APPID=application_1377704542759_0010	CONTAINERID=container_1377704542759_0010_01_000001
2013-08-28 15:59:40,556 INFO org.apache.hadoop.yarn.server.resourcemanager.scheduler.common.fica.FiCaSchedulerNode: Assigned container container_1377704542759_0010_01_000001 of capacity <memory:2048, vCores:1> on host hadoop-16-5:57886, which currently has 1 containers, <memory:2048, vCores:1> used and <memory:6144, vCores:15> available
2013-08-28 15:59:40,557 INFO org.apache.hadoop.yarn.server.resourcemanager.scheduler.capacity.LeafQueue: assignedContainer application=application_1377704542759_0010 container=Container: [ContainerId: container_1377704542759_0010_01_000001, NodeId: hadoop-16-5:57886, NodeHttpAddress: hadoop-16-5:8042, Resource: <memory:2048, vCores:1>, Priority: 0, State: NEW, Token: null, Status: container_id {, app_attempt_id {, application_id {, id: 10, cluster_timestamp: 1377704542759, }, attemptId: 1, }, id: 1, }, state: C_NEW, ] containerId=container_1377704542759_0010_01_000001 queue=default: capacity=1.0, absoluteCapacity=1.0, usedResources=<memory:8192, vCores:4>usedCapacity=0.16666667, absoluteUsedCapacity=0.16666667, numApps=5, numContainers=4 usedCapacity=0.16666667 absoluteUsedCapacity=0.16666667 used=<memory:8192, vCores:4> cluster=<memory:49152, vCores:96>
2013-08-28 15:59:40,558 INFO org.apache.hadoop.yarn.server.resourcemanager.scheduler.capacity.ParentQueue: Re-sorting queues since queue: root.default stats: default: capacity=1.0, absoluteCapacity=1.0, usedResources=<memory:10240, vCores:5>usedCapacity=0.20833333, absoluteUsedCapacity=0.20833333, numApps=5, numContainers=5
2013-08-28 15:59:40,559 INFO org.apache.hadoop.yarn.server.resourcemanager.rmcontainer.RMContainerImpl: container_1377704542759_0010_01_000001 Container Transitioned from ALLOCATED to ACQUIRED
2013-08-28 15:59:40,560 INFO org.apache.hadoop.yarn.server.resourcemanager.scheduler.capacity.ParentQueue: assignedContainer queue=root usedCapacity=0.20833333 absoluteUsedCapacity=0.20833333 used=<memory:10240, vCores:5> cluster=<memory:49152, vCores:96>
2013-08-28 15:59:40,561 INFO org.apache.hadoop.yarn.server.resourcemanager.rmapp.attempt.RMAppAttemptImpl: Storing attempt: AppId: application_1377704542759_0010 AttemptId: appattempt_1377704542759_0010_000001 MasterContainer: Container: [ContainerId: container_1377704542759_0010_01_000001, NodeId: hadoop-16-5:57886, NodeHttpAddress: hadoop-16-5:8042, Resource: <memory:2048, vCores:1>, Priority: 0, State: NEW, Token: null, Status: container_id {, app_attempt_id {, application_id {, id: 10, cluster_timestamp: 1377704542759, }, attemptId: 1, }, id: 1, }, state: C_NEW, ]
2013-08-28 15:59:40,561 INFO org.apache.hadoop.yarn.server.resourcemanager.rmapp.attempt.RMAppAttemptImpl: appattempt_1377704542759_0010_000001 State change from SCHEDULED to ALLOCATED_SAVING
2013-08-28 15:59:40,561 INFO org.apache.hadoop.yarn.server.resourcemanager.recovery.RMStateStore: Storing info for attempt: appattempt_1377704542759_0010_000001
2013-08-28 15:59:40,562 INFO org.apache.hadoop.yarn.server.resourcemanager.rmapp.attempt.RMAppAttemptImpl: appattempt_1377704542759_0010_000001 State change from ALLOCATED_SAVING to ALLOCATED
2013-08-28 15:59:40,562 INFO org.apache.hadoop.yarn.server.resourcemanager.amlauncher.AMLauncher: Launching masterappattempt_1377704542759_0010_000001
2013-08-28 15:59:40,565 INFO org.apache.hadoop.yarn.server.resourcemanager.amlauncher.AMLauncher: Setting up container Container: [ContainerId: container_1377704542759_0010_01_000001, NodeId: hadoop-16-5:57886, NodeHttpAddress: hadoop-16-5:8042, Resource: <memory:2048, vCores:1>, Priority: 0, State: NEW, Token: null, Status: container_id {, app_attempt_id {, application_id {, id: 10, cluster_timestamp: 1377704542759, }, attemptId: 1, }, id: 1, }, state: C_NEW, ] for AM appattempt_1377704542759_0010_000001
2013-08-28 15:59:40,565 INFO org.apache.hadoop.yarn.server.resourcemanager.amlauncher.AMLauncher: Command to launch container container_1377704542759_0010_01_000001 : $JAVA_HOME/bin/java -Dlog4j.configuration=container-log4j.properties -Dyarn.app.mapreduce.container.log.dir=<LOG_DIR> -Dyarn.app.mapreduce.container.log.filesize=0 -Dhadoop.root.logger=INFO,CLA  -Xmx1024m org.apache.hadoop.mapreduce.v2.app.MRAppMaster 1><LOG_DIR>/stdout 2><LOG_DIR>/stderr 
2013-08-28 15:59:40,579 INFO org.apache.hadoop.yarn.server.resourcemanager.amlauncher.AMLauncher: Done launching container Container: [ContainerId: container_1377704542759_0010_01_000001, NodeId: hadoop-16-5:57886, NodeHttpAddress: hadoop-16-5:8042, Resource: <memory:2048, vCores:1>, Priority: 0, State: NEW, Token: null, Status: container_id {, app_attempt_id {, application_id {, id: 10, cluster_timestamp: 1377704542759, }, attemptId: 1, }, id: 1, }, state: C_NEW, ] for AM appattempt_1377704542759_0010_000001
2013-08-28 15:59:40,580 INFO org.apache.hadoop.yarn.server.resourcemanager.rmapp.attempt.RMAppAttemptImpl: appattempt_1377704542759_0010_000001 State change from ALLOCATED to LAUNCHED
2013-08-28 15:59:40,796 INFO org.apache.hadoop.yarn.server.resourcemanager.rmcontainer.RMContainerImpl: container_1377704542759_0006_01_000001 Container Transitioned from ACQUIRED to RUNNING
2013-08-28 15:59:40,864 INFO org.apache.hadoop.yarn.server.resourcemanager.rmcontainer.RMContainerImpl: container_1377704542759_0007_01_000001 Container Transitioned from ACQUIRED to RUNNING
2013-08-28 15:59:40,941 INFO org.apache.hadoop.yarn.server.resourcemanager.rmcontainer.RMContainerImpl: container_1377704542759_0008_01_000001 Container Transitioned from ACQUIRED to RUNNING
2013-08-28 15:59:41,108 INFO org.apache.hadoop.yarn.server.resourcemanager.rmcontainer.RMContainerImpl: container_1377704542759_0009_01_000001 Container Transitioned from ACQUIRED to RUNNING
2013-08-28 15:59:41,561 INFO org.apache.hadoop.yarn.server.resourcemanager.rmcontainer.RMContainerImpl: container_1377704542759_0010_01_000001 Container Transitioned from ACQUIRED to RUNNING
2013-08-28 15:59:46,663 INFO org.apache.hadoop.yarn.server.resourcemanager.ApplicationMasterService: AM registration appattempt_1377704542759_0008_000001
2013-08-28 15:59:46,663 INFO org.apache.hadoop.yarn.server.resourcemanager.RMAuditLogger: USER=ubuntu	IP=192.168.100.22	OPERATION=Register App Master	TARGET=ApplicationMasterService	RESULT=SUCCESS	APPID=application_1377704542759_0008	APPATTEMPTID=appattempt_1377704542759_0008_000001
2013-08-28 15:59:46,664 INFO org.apache.hadoop.yarn.server.resourcemanager.rmapp.attempt.RMAppAttemptImpl: appattempt_1377704542759_0008_000001 State change from LAUNCHED to RUNNING
2013-08-28 15:59:46,664 INFO org.apache.hadoop.yarn.server.resourcemanager.rmapp.RMAppImpl: application_1377704542759_0008 State change from ACCEPTED to RUNNING
2013-08-28 15:59:47,034 INFO org.apache.hadoop.yarn.server.resourcemanager.ApplicationMasterService: AM registration appattempt_1377704542759_0006_000001
2013-08-28 15:59:47,034 INFO org.apache.hadoop.yarn.server.resourcemanager.RMAuditLogger: USER=ubuntu	IP=192.168.100.17	OPERATION=Register App Master	TARGET=ApplicationMasterService	RESULT=SUCCESS	APPID=application_1377704542759_0006	APPATTEMPTID=appattempt_1377704542759_0006_000001
2013-08-28 15:59:47,035 INFO org.apache.hadoop.yarn.server.resourcemanager.rmapp.attempt.RMAppAttemptImpl: appattempt_1377704542759_0006_000001 State change from LAUNCHED to RUNNING
2013-08-28 15:59:47,036 INFO org.apache.hadoop.yarn.server.resourcemanager.rmapp.RMAppImpl: application_1377704542759_0006 State change from ACCEPTED to RUNNING
2013-08-28 15:59:47,088 INFO org.apache.hadoop.yarn.server.resourcemanager.ApplicationMasterService: AM registration appattempt_1377704542759_0007_000001
2013-08-28 15:59:47,088 INFO org.apache.hadoop.yarn.server.resourcemanager.RMAuditLogger: USER=ubuntu	IP=192.168.100.18	OPERATION=Register App Master	TARGET=ApplicationMasterService	RESULT=SUCCESS	APPID=application_1377704542759_0007	APPATTEMPTID=appattempt_1377704542759_0007_000001
2013-08-28 15:59:47,089 INFO org.apache.hadoop.yarn.server.resourcemanager.rmapp.attempt.RMAppAttemptImpl: appattempt_1377704542759_0007_000001 State change from LAUNCHED to RUNNING
2013-08-28 15:59:47,089 INFO org.apache.hadoop.yarn.server.resourcemanager.rmapp.RMAppImpl: application_1377704542759_0007 State change from ACCEPTED to RUNNING
2013-08-28 15:59:47,649 INFO org.apache.hadoop.yarn.server.resourcemanager.ApplicationMasterService: AM registration appattempt_1377704542759_0009_000001
2013-08-28 15:59:47,650 INFO org.apache.hadoop.yarn.server.resourcemanager.RMAuditLogger: USER=ubuntu	IP=192.168.100.21	OPERATION=Register App Master	TARGET=ApplicationMasterService	RESULT=SUCCESS	APPID=application_1377704542759_0009	APPATTEMPTID=appattempt_1377704542759_0009_000001
2013-08-28 15:59:47,650 INFO org.apache.hadoop.yarn.server.resourcemanager.rmapp.attempt.RMAppAttemptImpl: appattempt_1377704542759_0009_000001 State change from LAUNCHED to RUNNING
2013-08-28 15:59:47,651 INFO org.apache.hadoop.yarn.server.resourcemanager.rmapp.RMAppImpl: application_1377704542759_0009 State change from ACCEPTED to RUNNING
2013-08-28 15:59:47,709 INFO org.apache.hadoop.yarn.server.resourcemanager.rmcontainer.RMContainerImpl: container_1377704542759_0008_01_000002 Container Transitioned from NEW to ALLOCATED
2013-08-28 15:59:47,709 INFO org.apache.hadoop.yarn.server.resourcemanager.RMAuditLogger: USER=ubuntu	OPERATION=AM Allocated Container	TARGET=SchedulerApp	RESULT=SUCCESS	APPID=application_1377704542759_0008	CONTAINERID=container_1377704542759_0008_01_000002
2013-08-28 15:59:47,709 INFO org.apache.hadoop.yarn.server.resourcemanager.scheduler.common.fica.FiCaSchedulerNode: Assigned container container_1377704542759_0008_01_000002 of capacity <memory:1024, vCores:1> on host hadoop-16-2:39317, which currently has 1 containers, <memory:1024, vCores:1> used and <memory:7168, vCores:15> available
2013-08-28 15:59:47,711 INFO org.apache.hadoop.yarn.server.resourcemanager.scheduler.capacity.LeafQueue: assignedContainer application=application_1377704542759_0008 container=Container: [ContainerId: container_1377704542759_0008_01_000002, NodeId: hadoop-16-2:39317, NodeHttpAddress: hadoop-16-2:8042, Resource: <memory:1024, vCores:1>, Priority: 20, State: NEW, Token: null, Status: container_id {, app_attempt_id {, application_id {, id: 8, cluster_timestamp: 1377704542759, }, attemptId: 1, }, id: 2, }, state: C_NEW, ] containerId=container_1377704542759_0008_01_000002 queue=default: capacity=1.0, absoluteCapacity=1.0, usedResources=<memory:10240, vCores:5>usedCapacity=0.20833333, absoluteUsedCapacity=0.20833333, numApps=5, numContainers=5 usedCapacity=0.20833333 absoluteUsedCapacity=0.20833333 used=<memory:10240, vCores:5> cluster=<memory:49152, vCores:96>
2013-08-28 15:59:47,711 INFO org.apache.hadoop.yarn.server.resourcemanager.scheduler.capacity.ParentQueue: Re-sorting queues since queue: root.default stats: default: capacity=1.0, absoluteCapacity=1.0, usedResources=<memory:11264, vCores:6>usedCapacity=0.22916667, absoluteUsedCapacity=0.22916667, numApps=5, numContainers=6
2013-08-28 15:59:47,711 INFO org.apache.hadoop.yarn.server.resourcemanager.scheduler.capacity.ParentQueue: assignedContainer queue=root usedCapacity=0.22916667 absoluteUsedCapacity=0.22916667 used=<memory:11264, vCores:6> cluster=<memory:49152, vCores:96>
2013-08-28 15:59:47,712 INFO org.apache.hadoop.yarn.server.resourcemanager.rmcontainer.RMContainerImpl: container_1377704542759_0008_01_000003 Container Transitioned from NEW to ALLOCATED
2013-08-28 15:59:47,712 INFO org.apache.hadoop.yarn.server.resourcemanager.RMAuditLogger: USER=ubuntu	OPERATION=AM Allocated Container	TARGET=SchedulerApp	RESULT=SUCCESS	APPID=application_1377704542759_0008	CONTAINERID=container_1377704542759_0008_01_000003
2013-08-28 15:59:47,712 INFO org.apache.hadoop.yarn.server.resourcemanager.scheduler.common.fica.FiCaSchedulerNode: Assigned container container_1377704542759_0008_01_000003 of capacity <memory:1024, vCores:1> on host hadoop-16-2:39317, which currently has 2 containers, <memory:2048, vCores:2> used and <memory:6144, vCores:14> available
2013-08-28 15:59:47,713 INFO org.apache.hadoop.yarn.server.resourcemanager.scheduler.capacity.LeafQueue: assignedContainer application=application_1377704542759_0008 container=Container: [ContainerId: container_1377704542759_0008_01_000003, NodeId: hadoop-16-2:39317, NodeHttpAddress: hadoop-16-2:8042, Resource: <memory:1024, vCores:1>, Priority: 20, State: NEW, Token: null, Status: container_id {, app_attempt_id {, application_id {, id: 8, cluster_timestamp: 1377704542759, }, attemptId: 1, }, id: 3, }, state: C_NEW, ] containerId=container_1377704542759_0008_01_000003 queue=default: capacity=1.0, absoluteCapacity=1.0, usedResources=<memory:11264, vCores:6>usedCapacity=0.22916667, absoluteUsedCapacity=0.22916667, numApps=5, numContainers=6 usedCapacity=0.22916667 absoluteUsedCapacity=0.22916667 used=<memory:11264, vCores:6> cluster=<memory:49152, vCores:96>
2013-08-28 15:59:47,713 INFO org.apache.hadoop.yarn.server.resourcemanager.scheduler.capacity.ParentQueue: Re-sorting queues since queue: root.default stats: default: capacity=1.0, absoluteCapacity=1.0, usedResources=<memory:12288, vCores:7>usedCapacity=0.25, absoluteUsedCapacity=0.25, numApps=5, numContainers=7
2013-08-28 15:59:47,713 INFO org.apache.hadoop.yarn.server.resourcemanager.scheduler.capacity.ParentQueue: assignedContainer queue=root usedCapacity=0.25 absoluteUsedCapacity=0.25 used=<memory:12288, vCores:7> cluster=<memory:49152, vCores:96>
2013-08-28 15:59:47,714 INFO org.apache.hadoop.yarn.server.resourcemanager.rmcontainer.RMContainerImpl: container_1377704542759_0008_01_000004 Container Transitioned from NEW to ALLOCATED
2013-08-28 15:59:47,714 INFO org.apache.hadoop.yarn.server.resourcemanager.RMAuditLogger: USER=ubuntu	OPERATION=AM Allocated Container	TARGET=SchedulerApp	RESULT=SUCCESS	APPID=application_1377704542759_0008	CONTAINERID=container_1377704542759_0008_01_000004
2013-08-28 15:59:47,714 INFO org.apache.hadoop.yarn.server.resourcemanager.scheduler.common.fica.FiCaSchedulerNode: Assigned container container_1377704542759_0008_01_000004 of capacity <memory:1024, vCores:1> on host hadoop-16-2:39317, which currently has 3 containers, <memory:3072, vCores:3> used and <memory:5120, vCores:13> available
2013-08-28 15:59:47,715 INFO org.apache.hadoop.yarn.server.resourcemanager.scheduler.capacity.LeafQueue: assignedContainer application=application_1377704542759_0008 container=Container: [ContainerId: container_1377704542759_0008_01_000004, NodeId: hadoop-16-2:39317, NodeHttpAddress: hadoop-16-2:8042, Resource: <memory:1024, vCores:1>, Priority: 20, State: NEW, Token: null, Status: container_id {, app_attempt_id {, application_id {, id: 8, cluster_timestamp: 1377704542759, }, attemptId: 1, }, id: 4, }, state: C_NEW, ] containerId=container_1377704542759_0008_01_000004 queue=default: capacity=1.0, absoluteCapacity=1.0, usedResources=<memory:12288, vCores:7>usedCapacity=0.25, absoluteUsedCapacity=0.25, numApps=5, numContainers=7 usedCapacity=0.25 absoluteUsedCapacity=0.25 used=<memory:12288, vCores:7> cluster=<memory:49152, vCores:96>
2013-08-28 15:59:47,716 INFO org.apache.hadoop.yarn.server.resourcemanager.scheduler.capacity.ParentQueue: Re-sorting queues since queue: root.default stats: default: capacity=1.0, absoluteCapacity=1.0, usedResources=<memory:13312, vCores:8>usedCapacity=0.27083334, absoluteUsedCapacity=0.27083334, numApps=5, numContainers=8
2013-08-28 15:59:47,716 INFO org.apache.hadoop.yarn.server.resourcemanager.scheduler.capacity.ParentQueue: assignedContainer queue=root usedCapacity=0.27083334 absoluteUsedCapacity=0.27083334 used=<memory:13312, vCores:8> cluster=<memory:49152, vCores:96>
2013-08-28 15:59:47,716 INFO org.apache.hadoop.yarn.server.resourcemanager.rmcontainer.RMContainerImpl: container_1377704542759_0008_01_000005 Container Transitioned from NEW to ALLOCATED
2013-08-28 15:59:47,717 INFO org.apache.hadoop.yarn.server.resourcemanager.RMAuditLogger: USER=ubuntu	OPERATION=AM Allocated Container	TARGET=SchedulerApp	RESULT=SUCCESS	APPID=application_1377704542759_0008	CONTAINERID=container_1377704542759_0008_01_000005
2013-08-28 15:59:47,717 INFO org.apache.hadoop.yarn.server.resourcemanager.scheduler.common.fica.FiCaSchedulerNode: Assigned container container_1377704542759_0008_01_000005 of capacity <memory:1024, vCores:1> on host hadoop-16-2:39317, which currently has 4 containers, <memory:4096, vCores:4> used and <memory:4096, vCores:12> available
2013-08-28 15:59:47,718 INFO org.apache.hadoop.yarn.server.resourcemanager.scheduler.capacity.LeafQueue: assignedContainer application=application_1377704542759_0008 container=Container: [ContainerId: container_1377704542759_0008_01_000005, NodeId: hadoop-16-2:39317, NodeHttpAddress: hadoop-16-2:8042, Resource: <memory:1024, vCores:1>, Priority: 20, State: NEW, Token: null, Status: container_id {, app_attempt_id {, application_id {, id: 8, cluster_timestamp: 1377704542759, }, attemptId: 1, }, id: 5, }, state: C_NEW, ] containerId=container_1377704542759_0008_01_000005 queue=default: capacity=1.0, absoluteCapacity=1.0, usedResources=<memory:13312, vCores:8>usedCapacity=0.27083334, absoluteUsedCapacity=0.27083334, numApps=5, numContainers=8 usedCapacity=0.27083334 absoluteUsedCapacity=0.27083334 used=<memory:13312, vCores:8> cluster=<memory:49152, vCores:96>
2013-08-28 15:59:47,718 INFO org.apache.hadoop.yarn.server.resourcemanager.scheduler.capacity.ParentQueue: Re-sorting queues since queue: root.default stats: default: capacity=1.0, absoluteCapacity=1.0, usedResources=<memory:14336, vCores:9>usedCapacity=0.29166666, absoluteUsedCapacity=0.29166666, numApps=5, numContainers=9
2013-08-28 15:59:47,718 INFO org.apache.hadoop.yarn.server.resourcemanager.scheduler.capacity.ParentQueue: assignedContainer queue=root usedCapacity=0.29166666 absoluteUsedCapacity=0.29166666 used=<memory:14336, vCores:9> cluster=<memory:49152, vCores:96>
2013-08-28 15:59:47,719 INFO org.apache.hadoop.yarn.server.resourcemanager.rmcontainer.RMContainerImpl: container_1377704542759_0008_01_000006 Container Transitioned from NEW to ALLOCATED
2013-08-28 15:59:47,719 INFO org.apache.hadoop.yarn.server.resourcemanager.RMAuditLogger: USER=ubuntu	OPERATION=AM Allocated Container	TARGET=SchedulerApp	RESULT=SUCCESS	APPID=application_1377704542759_0008	CONTAINERID=container_1377704542759_0008_01_000006
2013-08-28 15:59:47,719 INFO org.apache.hadoop.yarn.server.resourcemanager.scheduler.common.fica.FiCaSchedulerNode: Assigned container container_1377704542759_0008_01_000006 of capacity <memory:1024, vCores:1> on host hadoop-16-2:39317, which currently has 5 containers, <memory:5120, vCores:5> used and <memory:3072, vCores:11> available
2013-08-28 15:59:47,721 INFO org.apache.hadoop.yarn.server.resourcemanager.scheduler.capacity.LeafQueue: assignedContainer application=application_1377704542759_0008 container=Container: [ContainerId: container_1377704542759_0008_01_000006, NodeId: hadoop-16-2:39317, NodeHttpAddress: hadoop-16-2:8042, Resource: <memory:1024, vCores:1>, Priority: 20, State: NEW, Token: null, Status: container_id {, app_attempt_id {, application_id {, id: 8, cluster_timestamp: 1377704542759, }, attemptId: 1, }, id: 6, }, state: C_NEW, ] containerId=container_1377704542759_0008_01_000006 queue=default: capacity=1.0, absoluteCapacity=1.0, usedResources=<memory:14336, vCores:9>usedCapacity=0.29166666, absoluteUsedCapacity=0.29166666, numApps=5, numContainers=9 usedCapacity=0.29166666 absoluteUsedCapacity=0.29166666 used=<memory:14336, vCores:9> cluster=<memory:49152, vCores:96>
2013-08-28 15:59:47,721 INFO org.apache.hadoop.yarn.server.resourcemanager.scheduler.capacity.ParentQueue: Re-sorting queues since queue: root.default stats: default: capacity=1.0, absoluteCapacity=1.0, usedResources=<memory:15360, vCores:10>usedCapacity=0.3125, absoluteUsedCapacity=0.3125, numApps=5, numContainers=10
2013-08-28 15:59:47,721 INFO org.apache.hadoop.yarn.server.resourcemanager.scheduler.capacity.ParentQueue: assignedContainer queue=root usedCapacity=0.3125 absoluteUsedCapacity=0.3125 used=<memory:15360, vCores:10> cluster=<memory:49152, vCores:96>
2013-08-28 15:59:47,722 INFO org.apache.hadoop.yarn.server.resourcemanager.rmcontainer.RMContainerImpl: container_1377704542759_0008_01_000007 Container Transitioned from NEW to ALLOCATED
2013-08-28 15:59:47,722 INFO org.apache.hadoop.yarn.server.resourcemanager.RMAuditLogger: USER=ubuntu	OPERATION=AM Allocated Container	TARGET=SchedulerApp	RESULT=SUCCESS	APPID=application_1377704542759_0008	CONTAINERID=container_1377704542759_0008_01_000007
2013-08-28 15:59:47,722 INFO org.apache.hadoop.yarn.server.resourcemanager.scheduler.common.fica.FiCaSchedulerNode: Assigned container container_1377704542759_0008_01_000007 of capacity <memory:1024, vCores:1> on host hadoop-16-2:39317, which currently has 6 containers, <memory:6144, vCores:6> used and <memory:2048, vCores:10> available
2013-08-28 15:59:47,723 INFO org.apache.hadoop.yarn.server.resourcemanager.scheduler.capacity.LeafQueue: assignedContainer application=application_1377704542759_0008 container=Container: [ContainerId: container_1377704542759_0008_01_000007, NodeId: hadoop-16-2:39317, NodeHttpAddress: hadoop-16-2:8042, Resource: <memory:1024, vCores:1>, Priority: 20, State: NEW, Token: null, Status: container_id {, app_attempt_id {, application_id {, id: 8, cluster_timestamp: 1377704542759, }, attemptId: 1, }, id: 7, }, state: C_NEW, ] containerId=container_1377704542759_0008_01_000007 queue=default: capacity=1.0, absoluteCapacity=1.0, usedResources=<memory:15360, vCores:10>usedCapacity=0.3125, absoluteUsedCapacity=0.3125, numApps=5, numContainers=10 usedCapacity=0.3125 absoluteUsedCapacity=0.3125 used=<memory:15360, vCores:10> cluster=<memory:49152, vCores:96>
2013-08-28 15:59:47,723 INFO org.apache.hadoop.yarn.server.resourcemanager.scheduler.capacity.ParentQueue: Re-sorting queues since queue: root.default stats: default: capacity=1.0, absoluteCapacity=1.0, usedResources=<memory:16384, vCores:11>usedCapacity=0.33333334, absoluteUsedCapacity=0.33333334, numApps=5, numContainers=11
2013-08-28 15:59:47,724 INFO org.apache.hadoop.yarn.server.resourcemanager.scheduler.capacity.ParentQueue: assignedContainer queue=root usedCapacity=0.33333334 absoluteUsedCapacity=0.33333334 used=<memory:16384, vCores:11> cluster=<memory:49152, vCores:96>
2013-08-28 15:59:47,724 INFO org.apache.hadoop.yarn.server.resourcemanager.rmcontainer.RMContainerImpl: container_1377704542759_0008_01_000008 Container Transitioned from NEW to ALLOCATED
2013-08-28 15:59:47,724 INFO org.apache.hadoop.yarn.server.resourcemanager.RMAuditLogger: USER=ubuntu	OPERATION=AM Allocated Container	TARGET=SchedulerApp	RESULT=SUCCESS	APPID=application_1377704542759_0008	CONTAINERID=container_1377704542759_0008_01_000008
2013-08-28 15:59:47,724 INFO org.apache.hadoop.yarn.server.resourcemanager.scheduler.common.fica.FiCaSchedulerNode: Assigned container container_1377704542759_0008_01_000008 of capacity <memory:1024, vCores:1> on host hadoop-16-2:39317, which currently has 7 containers, <memory:7168, vCores:7> used and <memory:1024, vCores:9> available
2013-08-28 15:59:47,725 INFO org.apache.hadoop.yarn.server.resourcemanager.scheduler.capacity.LeafQueue: assignedContainer application=application_1377704542759_0008 container=Container: [ContainerId: container_1377704542759_0008_01_000008, NodeId: hadoop-16-2:39317, NodeHttpAddress: hadoop-16-2:8042, Resource: <memory:1024, vCores:1>, Priority: 20, State: NEW, Token: null, Status: container_id {, app_attempt_id {, application_id {, id: 8, cluster_timestamp: 1377704542759, }, attemptId: 1, }, id: 8, }, state: C_NEW, ] containerId=container_1377704542759_0008_01_000008 queue=default: capacity=1.0, absoluteCapacity=1.0, usedResources=<memory:16384, vCores:11>usedCapacity=0.33333334, absoluteUsedCapacity=0.33333334, numApps=5, numContainers=11 usedCapacity=0.33333334 absoluteUsedCapacity=0.33333334 used=<memory:16384, vCores:11> cluster=<memory:49152, vCores:96>
2013-08-28 15:59:47,726 INFO org.apache.hadoop.yarn.server.resourcemanager.scheduler.capacity.ParentQueue: Re-sorting queues since queue: root.default stats: default: capacity=1.0, absoluteCapacity=1.0, usedResources=<memory:17408, vCores:12>usedCapacity=0.35416666, absoluteUsedCapacity=0.35416666, numApps=5, numContainers=12
2013-08-28 15:59:47,726 INFO org.apache.hadoop.yarn.server.resourcemanager.scheduler.capacity.ParentQueue: assignedContainer queue=root usedCapacity=0.35416666 absoluteUsedCapacity=0.35416666 used=<memory:17408, vCores:12> cluster=<memory:49152, vCores:96>
2013-08-28 15:59:47,727 INFO org.apache.hadoop.yarn.server.resourcemanager.rmcontainer.RMContainerImpl: container_1377704542759_0008_01_000009 Container Transitioned from NEW to ALLOCATED
2013-08-28 15:59:47,727 INFO org.apache.hadoop.yarn.server.resourcemanager.RMAuditLogger: USER=ubuntu	OPERATION=AM Allocated Container	TARGET=SchedulerApp	RESULT=SUCCESS	APPID=application_1377704542759_0008	CONTAINERID=container_1377704542759_0008_01_000009
2013-08-28 15:59:47,727 INFO org.apache.hadoop.yarn.server.resourcemanager.scheduler.common.fica.FiCaSchedulerNode: Assigned container container_1377704542759_0008_01_000009 of capacity <memory:1024, vCores:1> on host hadoop-16-2:39317, which currently has 8 containers, <memory:8192, vCores:8> used and <memory:0, vCores:8> available
2013-08-28 15:59:47,728 INFO org.apache.hadoop.yarn.server.resourcemanager.scheduler.capacity.LeafQueue: assignedContainer application=application_1377704542759_0008 container=Container: [ContainerId: container_1377704542759_0008_01_000009, NodeId: hadoop-16-2:39317, NodeHttpAddress: hadoop-16-2:8042, Resource: <memory:1024, vCores:1>, Priority: 20, State: NEW, Token: null, Status: container_id {, app_attempt_id {, application_id {, id: 8, cluster_timestamp: 1377704542759, }, attemptId: 1, }, id: 9, }, state: C_NEW, ] containerId=container_1377704542759_0008_01_000009 queue=default: capacity=1.0, absoluteCapacity=1.0, usedResources=<memory:17408, vCores:12>usedCapacity=0.35416666, absoluteUsedCapacity=0.35416666, numApps=5, numContainers=12 usedCapacity=0.35416666 absoluteUsedCapacity=0.35416666 used=<memory:17408, vCores:12> cluster=<memory:49152, vCores:96>
2013-08-28 15:59:47,728 INFO org.apache.hadoop.yarn.server.resourcemanager.scheduler.capacity.ParentQueue: Re-sorting queues since queue: root.default stats: default: capacity=1.0, absoluteCapacity=1.0, usedResources=<memory:18432, vCores:13>usedCapacity=0.375, absoluteUsedCapacity=0.375, numApps=5, numContainers=13
2013-08-28 15:59:47,728 INFO org.apache.hadoop.yarn.server.resourcemanager.scheduler.capacity.ParentQueue: assignedContainer queue=root usedCapacity=0.375 absoluteUsedCapacity=0.375 used=<memory:18432, vCores:13> cluster=<memory:49152, vCores:96>
2013-08-28 15:59:47,834 INFO org.apache.hadoop.yarn.server.resourcemanager.rmcontainer.RMContainerImpl: container_1377704542759_0008_01_000010 Container Transitioned from NEW to ALLOCATED
2013-08-28 15:59:47,834 INFO org.apache.hadoop.yarn.server.resourcemanager.RMAuditLogger: USER=ubuntu	OPERATION=AM Allocated Container	TARGET=SchedulerApp	RESULT=SUCCESS	APPID=application_1377704542759_0008	CONTAINERID=container_1377704542759_0008_01_000010
2013-08-28 15:59:47,834 INFO org.apache.hadoop.yarn.server.resourcemanager.scheduler.common.fica.FiCaSchedulerNode: Assigned container container_1377704542759_0008_01_000010 of capacity <memory:1024, vCores:1> on host hadoop-16-3:41896, which currently has 2 containers, <memory:3072, vCores:2> used and <memory:5120, vCores:14> available
2013-08-28 15:59:47,835 INFO org.apache.hadoop.yarn.server.resourcemanager.scheduler.capacity.LeafQueue: assignedContainer application=application_1377704542759_0008 container=Container: [ContainerId: container_1377704542759_0008_01_000010, NodeId: hadoop-16-3:41896, NodeHttpAddress: hadoop-16-3:8042, Resource: <memory:1024, vCores:1>, Priority: 20, State: NEW, Token: null, Status: container_id {, app_attempt_id {, application_id {, id: 8, cluster_timestamp: 1377704542759, }, attemptId: 1, }, id: 10, }, state: C_NEW, ] containerId=container_1377704542759_0008_01_000010 queue=default: capacity=1.0, absoluteCapacity=1.0, usedResources=<memory:18432, vCores:13>usedCapacity=0.375, absoluteUsedCapacity=0.375, numApps=5, numContainers=13 usedCapacity=0.375 absoluteUsedCapacity=0.375 used=<memory:18432, vCores:13> cluster=<memory:49152, vCores:96>
2013-08-28 15:59:47,836 INFO org.apache.hadoop.yarn.server.resourcemanager.scheduler.capacity.ParentQueue: Re-sorting queues since queue: root.default stats: default: capacity=1.0, absoluteCapacity=1.0, usedResources=<memory:19456, vCores:14>usedCapacity=0.39583334, absoluteUsedCapacity=0.39583334, numApps=5, numContainers=14
2013-08-28 15:59:47,836 INFO org.apache.hadoop.yarn.server.resourcemanager.scheduler.capacity.ParentQueue: assignedContainer queue=root usedCapacity=0.39583334 absoluteUsedCapacity=0.39583334 used=<memory:19456, vCores:14> cluster=<memory:49152, vCores:96>
2013-08-28 15:59:47,836 INFO org.apache.hadoop.yarn.server.resourcemanager.rmcontainer.RMContainerImpl: container_1377704542759_0008_01_000011 Container Transitioned from NEW to ALLOCATED
2013-08-28 15:59:47,836 INFO org.apache.hadoop.yarn.server.resourcemanager.RMAuditLogger: USER=ubuntu	OPERATION=AM Allocated Container	TARGET=SchedulerApp	RESULT=SUCCESS	APPID=application_1377704542759_0008	CONTAINERID=container_1377704542759_0008_01_000011
2013-08-28 15:59:47,837 INFO org.apache.hadoop.yarn.server.resourcemanager.scheduler.common.fica.FiCaSchedulerNode: Assigned container container_1377704542759_0008_01_000011 of capacity <memory:1024, vCores:1> on host hadoop-16-3:41896, which currently has 3 containers, <memory:4096, vCores:3> used and <memory:4096, vCores:13> available
2013-08-28 15:59:47,838 INFO org.apache.hadoop.yarn.server.resourcemanager.scheduler.capacity.LeafQueue: assignedContainer application=application_1377704542759_0008 container=Container: [ContainerId: container_1377704542759_0008_01_000011, NodeId: hadoop-16-3:41896, NodeHttpAddress: hadoop-16-3:8042, Resource: <memory:1024, vCores:1>, Priority: 20, State: NEW, Token: null, Status: container_id {, app_attempt_id {, application_id {, id: 8, cluster_timestamp: 1377704542759, }, attemptId: 1, }, id: 11, }, state: C_NEW, ] containerId=container_1377704542759_0008_01_000011 queue=default: capacity=1.0, absoluteCapacity=1.0, usedResources=<memory:19456, vCores:14>usedCapacity=0.39583334, absoluteUsedCapacity=0.39583334, numApps=5, numContainers=14 usedCapacity=0.39583334 absoluteUsedCapacity=0.39583334 used=<memory:19456, vCores:14> cluster=<memory:49152, vCores:96>
2013-08-28 15:59:47,838 INFO org.apache.hadoop.yarn.server.resourcemanager.scheduler.capacity.ParentQueue: Re-sorting queues since queue: root.default stats: default: capacity=1.0, absoluteCapacity=1.0, usedResources=<memory:20480, vCores:15>usedCapacity=0.41666666, absoluteUsedCapacity=0.41666666, numApps=5, numContainers=15
2013-08-28 15:59:47,838 INFO org.apache.hadoop.yarn.server.resourcemanager.scheduler.capacity.ParentQueue: assignedContainer queue=root usedCapacity=0.41666666 absoluteUsedCapacity=0.41666666 used=<memory:20480, vCores:15> cluster=<memory:49152, vCores:96>
2013-08-28 15:59:47,839 INFO org.apache.hadoop.yarn.server.resourcemanager.rmcontainer.RMContainerImpl: container_1377704542759_0008_01_000012 Container Transitioned from NEW to ALLOCATED
2013-08-28 15:59:47,839 INFO org.apache.hadoop.yarn.server.resourcemanager.RMAuditLogger: USER=ubuntu	OPERATION=AM Allocated Container	TARGET=SchedulerApp	RESULT=SUCCESS	APPID=application_1377704542759_0008	CONTAINERID=container_1377704542759_0008_01_000012
2013-08-28 15:59:47,839 INFO org.apache.hadoop.yarn.server.resourcemanager.scheduler.common.fica.FiCaSchedulerNode: Assigned container container_1377704542759_0008_01_000012 of capacity <memory:1024, vCores:1> on host hadoop-16-3:41896, which currently has 4 containers, <memory:5120, vCores:4> used and <memory:3072, vCores:12> available
2013-08-28 15:59:47,840 INFO org.apache.hadoop.yarn.server.resourcemanager.scheduler.capacity.LeafQueue: assignedContainer application=application_1377704542759_0008 container=Container: [ContainerId: container_1377704542759_0008_01_000012, NodeId: hadoop-16-3:41896, NodeHttpAddress: hadoop-16-3:8042, Resource: <memory:1024, vCores:1>, Priority: 20, State: NEW, Token: null, Status: container_id {, app_attempt_id {, application_id {, id: 8, cluster_timestamp: 1377704542759, }, attemptId: 1, }, id: 12, }, state: C_NEW, ] containerId=container_1377704542759_0008_01_000012 queue=default: capacity=1.0, absoluteCapacity=1.0, usedResources=<memory:20480, vCores:15>usedCapacity=0.41666666, absoluteUsedCapacity=0.41666666, numApps=5, numContainers=15 usedCapacity=0.41666666 absoluteUsedCapacity=0.41666666 used=<memory:20480, vCores:15> cluster=<memory:49152, vCores:96>
2013-08-28 15:59:47,841 INFO org.apache.hadoop.yarn.server.resourcemanager.scheduler.capacity.ParentQueue: Re-sorting queues since queue: root.default stats: default: capacity=1.0, absoluteCapacity=1.0, usedResources=<memory:21504, vCores:16>usedCapacity=0.4375, absoluteUsedCapacity=0.4375, numApps=5, numContainers=16
2013-08-28 15:59:47,841 INFO org.apache.hadoop.yarn.server.resourcemanager.scheduler.capacity.ParentQueue: assignedContainer queue=root usedCapacity=0.4375 absoluteUsedCapacity=0.4375 used=<memory:21504, vCores:16> cluster=<memory:49152, vCores:96>
2013-08-28 15:59:47,841 INFO org.apache.hadoop.yarn.server.resourcemanager.rmcontainer.RMContainerImpl: container_1377704542759_0008_01_000013 Container Transitioned from NEW to ALLOCATED
2013-08-28 15:59:47,841 INFO org.apache.hadoop.yarn.server.resourcemanager.RMAuditLogger: USER=ubuntu	OPERATION=AM Allocated Container	TARGET=SchedulerApp	RESULT=SUCCESS	APPID=application_1377704542759_0008	CONTAINERID=container_1377704542759_0008_01_000013
2013-08-28 15:59:47,841 INFO org.apache.hadoop.yarn.server.resourcemanager.scheduler.common.fica.FiCaSchedulerNode: Assigned container container_1377704542759_0008_01_000013 of capacity <memory:1024, vCores:1> on host hadoop-16-3:41896, which currently has 5 containers, <memory:6144, vCores:5> used and <memory:2048, vCores:11> available
2013-08-28 15:59:47,843 INFO org.apache.hadoop.yarn.server.resourcemanager.scheduler.capacity.LeafQueue: assignedContainer application=application_1377704542759_0008 container=Container: [ContainerId: container_1377704542759_0008_01_000013, NodeId: hadoop-16-3:41896, NodeHttpAddress: hadoop-16-3:8042, Resource: <memory:1024, vCores:1>, Priority: 20, State: NEW, Token: null, Status: container_id {, app_attempt_id {, application_id {, id: 8, cluster_timestamp: 1377704542759, }, attemptId: 1, }, id: 13, }, state: C_NEW, ] containerId=container_1377704542759_0008_01_000013 queue=default: capacity=1.0, absoluteCapacity=1.0, usedResources=<memory:21504, vCores:16>usedCapacity=0.4375, absoluteUsedCapacity=0.4375, numApps=5, numContainers=16 usedCapacity=0.4375 absoluteUsedCapacity=0.4375 used=<memory:21504, vCores:16> cluster=<memory:49152, vCores:96>
2013-08-28 15:59:47,843 INFO org.apache.hadoop.yarn.server.resourcemanager.scheduler.capacity.ParentQueue: Re-sorting queues since queue: root.default stats: default: capacity=1.0, absoluteCapacity=1.0, usedResources=<memory:22528, vCores:17>usedCapacity=0.45833334, absoluteUsedCapacity=0.45833334, numApps=5, numContainers=17
2013-08-28 15:59:47,843 INFO org.apache.hadoop.yarn.server.resourcemanager.scheduler.capacity.ParentQueue: assignedContainer queue=root usedCapacity=0.45833334 absoluteUsedCapacity=0.45833334 used=<memory:22528, vCores:17> cluster=<memory:49152, vCores:96>
2013-08-28 15:59:47,844 INFO org.apache.hadoop.yarn.server.resourcemanager.rmcontainer.RMContainerImpl: container_1377704542759_0008_01_000014 Container Transitioned from NEW to ALLOCATED
2013-08-28 15:59:47,844 INFO org.apache.hadoop.yarn.server.resourcemanager.RMAuditLogger: USER=ubuntu	OPERATION=AM Allocated Container	TARGET=SchedulerApp	RESULT=SUCCESS	APPID=application_1377704542759_0008	CONTAINERID=container_1377704542759_0008_01_000014
2013-08-28 15:59:47,844 INFO org.apache.hadoop.yarn.server.resourcemanager.scheduler.common.fica.FiCaSchedulerNode: Assigned container container_1377704542759_0008_01_000014 of capacity <memory:1024, vCores:1> on host hadoop-16-3:41896, which currently has 6 containers, <memory:7168, vCores:6> used and <memory:1024, vCores:10> available
2013-08-28 15:59:47,845 INFO org.apache.hadoop.yarn.server.resourcemanager.scheduler.capacity.LeafQueue: assignedContainer application=application_1377704542759_0008 container=Container: [ContainerId: container_1377704542759_0008_01_000014, NodeId: hadoop-16-3:41896, NodeHttpAddress: hadoop-16-3:8042, Resource: <memory:1024, vCores:1>, Priority: 20, State: NEW, Token: null, Status: container_id {, app_attempt_id {, application_id {, id: 8, cluster_timestamp: 1377704542759, }, attemptId: 1, }, id: 14, }, state: C_NEW, ] containerId=container_1377704542759_0008_01_000014 queue=default: capacity=1.0, absoluteCapacity=1.0, usedResources=<memory:22528, vCores:17>usedCapacity=0.45833334, absoluteUsedCapacity=0.45833334, numApps=5, numContainers=17 usedCapacity=0.45833334 absoluteUsedCapacity=0.45833334 used=<memory:22528, vCores:17> cluster=<memory:49152, vCores:96>
2013-08-28 15:59:47,845 INFO org.apache.hadoop.yarn.server.resourcemanager.scheduler.capacity.ParentQueue: Re-sorting queues since queue: root.default stats: default: capacity=1.0, absoluteCapacity=1.0, usedResources=<memory:23552, vCores:18>usedCapacity=0.47916666, absoluteUsedCapacity=0.47916666, numApps=5, numContainers=18
2013-08-28 15:59:47,846 INFO org.apache.hadoop.yarn.server.resourcemanager.scheduler.capacity.ParentQueue: assignedContainer queue=root usedCapacity=0.47916666 absoluteUsedCapacity=0.47916666 used=<memory:23552, vCores:18> cluster=<memory:49152, vCores:96>
2013-08-28 15:59:47,846 INFO org.apache.hadoop.yarn.server.resourcemanager.rmcontainer.RMContainerImpl: container_1377704542759_0008_01_000015 Container Transitioned from NEW to ALLOCATED
2013-08-28 15:59:47,846 INFO org.apache.hadoop.yarn.server.resourcemanager.RMAuditLogger: USER=ubuntu	OPERATION=AM Allocated Container	TARGET=SchedulerApp	RESULT=SUCCESS	APPID=application_1377704542759_0008	CONTAINERID=container_1377704542759_0008_01_000015
2013-08-28 15:59:47,846 INFO org.apache.hadoop.yarn.server.resourcemanager.scheduler.common.fica.FiCaSchedulerNode: Assigned container container_1377704542759_0008_01_000015 of capacity <memory:1024, vCores:1> on host hadoop-16-3:41896, which currently has 7 containers, <memory:8192, vCores:7> used and <memory:0, vCores:9> available
2013-08-28 15:59:47,847 INFO org.apache.hadoop.yarn.server.resourcemanager.scheduler.capacity.LeafQueue: assignedContainer application=application_1377704542759_0008 container=Container: [ContainerId: container_1377704542759_0008_01_000015, NodeId: hadoop-16-3:41896, NodeHttpAddress: hadoop-16-3:8042, Resource: <memory:1024, vCores:1>, Priority: 20, State: NEW, Token: null, Status: container_id {, app_attempt_id {, application_id {, id: 8, cluster_timestamp: 1377704542759, }, attemptId: 1, }, id: 15, }, state: C_NEW, ] containerId=container_1377704542759_0008_01_000015 queue=default: capacity=1.0, absoluteCapacity=1.0, usedResources=<memory:23552, vCores:18>usedCapacity=0.47916666, absoluteUsedCapacity=0.47916666, numApps=5, numContainers=18 usedCapacity=0.47916666 absoluteUsedCapacity=0.47916666 used=<memory:23552, vCores:18> cluster=<memory:49152, vCores:96>
2013-08-28 15:59:47,848 INFO org.apache.hadoop.yarn.server.resourcemanager.scheduler.capacity.ParentQueue: Re-sorting queues since queue: root.default stats: default: capacity=1.0, absoluteCapacity=1.0, usedResources=<memory:24576, vCores:19>usedCapacity=0.5, absoluteUsedCapacity=0.5, numApps=5, numContainers=19
2013-08-28 15:59:47,848 INFO org.apache.hadoop.yarn.server.resourcemanager.scheduler.capacity.ParentQueue: assignedContainer queue=root usedCapacity=0.5 absoluteUsedCapacity=0.5 used=<memory:24576, vCores:19> cluster=<memory:49152, vCores:96>
2013-08-28 15:59:47,900 INFO org.apache.hadoop.yarn.server.resourcemanager.rmcontainer.RMContainerImpl: container_1377704542759_0008_01_000016 Container Transitioned from NEW to ALLOCATED
2013-08-28 15:59:47,900 INFO org.apache.hadoop.yarn.server.resourcemanager.RMAuditLogger: USER=ubuntu	OPERATION=AM Allocated Container	TARGET=SchedulerApp	RESULT=SUCCESS	APPID=application_1377704542759_0008	CONTAINERID=container_1377704542759_0008_01_000016
2013-08-28 15:59:47,900 INFO org.apache.hadoop.yarn.server.resourcemanager.scheduler.common.fica.FiCaSchedulerNode: Assigned container container_1377704542759_0008_01_000016 of capacity <memory:1024, vCores:1> on host hadoop-16-4:52495, which currently has 2 containers, <memory:3072, vCores:2> used and <memory:5120, vCores:14> available
2013-08-28 15:59:47,901 INFO org.apache.hadoop.yarn.server.resourcemanager.scheduler.capacity.LeafQueue: assignedContainer application=application_1377704542759_0008 container=Container: [ContainerId: container_1377704542759_0008_01_000016, NodeId: hadoop-16-4:52495, NodeHttpAddress: hadoop-16-4:8042, Resource: <memory:1024, vCores:1>, Priority: 20, State: NEW, Token: null, Status: container_id {, app_attempt_id {, application_id {, id: 8, cluster_timestamp: 1377704542759, }, attemptId: 1, }, id: 16, }, state: C_NEW, ] containerId=container_1377704542759_0008_01_000016 queue=default: capacity=1.0, absoluteCapacity=1.0, usedResources=<memory:24576, vCores:19>usedCapacity=0.5, absoluteUsedCapacity=0.5, numApps=5, numContainers=19 usedCapacity=0.5 absoluteUsedCapacity=0.5 used=<memory:24576, vCores:19> cluster=<memory:49152, vCores:96>
2013-08-28 15:59:47,901 INFO org.apache.hadoop.yarn.server.resourcemanager.scheduler.capacity.ParentQueue: Re-sorting queues since queue: root.default stats: default: capacity=1.0, absoluteCapacity=1.0, usedResources=<memory:25600, vCores:20>usedCapacity=0.5208333, absoluteUsedCapacity=0.5208333, numApps=5, numContainers=20
2013-08-28 15:59:47,901 INFO org.apache.hadoop.yarn.server.resourcemanager.scheduler.capacity.ParentQueue: assignedContainer queue=root usedCapacity=0.5208333 absoluteUsedCapacity=0.5208333 used=<memory:25600, vCores:20> cluster=<memory:49152, vCores:96>
2013-08-28 15:59:47,902 INFO org.apache.hadoop.yarn.server.resourcemanager.rmcontainer.RMContainerImpl: container_1377704542759_0008_01_000017 Container Transitioned from NEW to ALLOCATED
2013-08-28 15:59:47,902 INFO org.apache.hadoop.yarn.server.resourcemanager.RMAuditLogger: USER=ubuntu	OPERATION=AM Allocated Container	TARGET=SchedulerApp	RESULT=SUCCESS	APPID=application_1377704542759_0008	CONTAINERID=container_1377704542759_0008_01_000017
2013-08-28 15:59:47,902 INFO org.apache.hadoop.yarn.server.resourcemanager.scheduler.common.fica.FiCaSchedulerNode: Assigned container container_1377704542759_0008_01_000017 of capacity <memory:1024, vCores:1> on host hadoop-16-4:52495, which currently has 3 containers, <memory:4096, vCores:3> used and <memory:4096, vCores:13> available
2013-08-28 15:59:47,903 INFO org.apache.hadoop.yarn.server.resourcemanager.scheduler.capacity.LeafQueue: assignedContainer application=application_1377704542759_0008 container=Container: [ContainerId: container_1377704542759_0008_01_000017, NodeId: hadoop-16-4:52495, NodeHttpAddress: hadoop-16-4:8042, Resource: <memory:1024, vCores:1>, Priority: 20, State: NEW, Token: null, Status: container_id {, app_attempt_id {, application_id {, id: 8, cluster_timestamp: 1377704542759, }, attemptId: 1, }, id: 17, }, state: C_NEW, ] containerId=container_1377704542759_0008_01_000017 queue=default: capacity=1.0, absoluteCapacity=1.0, usedResources=<memory:25600, vCores:20>usedCapacity=0.5208333, absoluteUsedCapacity=0.5208333, numApps=5, numContainers=20 usedCapacity=0.5208333 absoluteUsedCapacity=0.5208333 used=<memory:25600, vCores:20> cluster=<memory:49152, vCores:96>
2013-08-28 15:59:47,904 INFO org.apache.hadoop.yarn.server.resourcemanager.scheduler.capacity.ParentQueue: Re-sorting queues since queue: root.default stats: default: capacity=1.0, absoluteCapacity=1.0, usedResources=<memory:26624, vCores:21>usedCapacity=0.5416667, absoluteUsedCapacity=0.5416667, numApps=5, numContainers=21
2013-08-28 15:59:47,904 INFO org.apache.hadoop.yarn.server.resourcemanager.scheduler.capacity.ParentQueue: assignedContainer queue=root usedCapacity=0.5416667 absoluteUsedCapacity=0.5416667 used=<memory:26624, vCores:21> cluster=<memory:49152, vCores:96>
2013-08-28 15:59:47,904 INFO org.apache.hadoop.yarn.server.resourcemanager.rmcontainer.RMContainerImpl: container_1377704542759_0008_01_000018 Container Transitioned from NEW to ALLOCATED
2013-08-28 15:59:47,904 INFO org.apache.hadoop.yarn.server.resourcemanager.RMAuditLogger: USER=ubuntu	OPERATION=AM Allocated Container	TARGET=SchedulerApp	RESULT=SUCCESS	APPID=application_1377704542759_0008	CONTAINERID=container_1377704542759_0008_01_000018
2013-08-28 15:59:47,905 INFO org.apache.hadoop.yarn.server.resourcemanager.scheduler.common.fica.FiCaSchedulerNode: Assigned container container_1377704542759_0008_01_000018 of capacity <memory:1024, vCores:1> on host hadoop-16-4:52495, which currently has 4 containers, <memory:5120, vCores:4> used and <memory:3072, vCores:12> available
2013-08-28 15:59:47,905 INFO org.apache.hadoop.yarn.server.resourcemanager.scheduler.capacity.LeafQueue: assignedContainer application=application_1377704542759_0008 container=Container: [ContainerId: container_1377704542759_0008_01_000018, NodeId: hadoop-16-4:52495, NodeHttpAddress: hadoop-16-4:8042, Resource: <memory:1024, vCores:1>, Priority: 20, State: NEW, Token: null, Status: container_id {, app_attempt_id {, application_id {, id: 8, cluster_timestamp: 1377704542759, }, attemptId: 1, }, id: 18, }, state: C_NEW, ] containerId=container_1377704542759_0008_01_000018 queue=default: capacity=1.0, absoluteCapacity=1.0, usedResources=<memory:26624, vCores:21>usedCapacity=0.5416667, absoluteUsedCapacity=0.5416667, numApps=5, numContainers=21 usedCapacity=0.5416667 absoluteUsedCapacity=0.5416667 used=<memory:26624, vCores:21> cluster=<memory:49152, vCores:96>
2013-08-28 15:59:47,906 INFO org.apache.hadoop.yarn.server.resourcemanager.scheduler.capacity.ParentQueue: Re-sorting queues since queue: root.default stats: default: capacity=1.0, absoluteCapacity=1.0, usedResources=<memory:27648, vCores:22>usedCapacity=0.5625, absoluteUsedCapacity=0.5625, numApps=5, numContainers=22
2013-08-28 15:59:47,906 INFO org.apache.hadoop.yarn.server.resourcemanager.scheduler.capacity.ParentQueue: assignedContainer queue=root usedCapacity=0.5625 absoluteUsedCapacity=0.5625 used=<memory:27648, vCores:22> cluster=<memory:49152, vCores:96>
2013-08-28 15:59:47,906 INFO org.apache.hadoop.yarn.server.resourcemanager.rmcontainer.RMContainerImpl: container_1377704542759_0008_01_000019 Container Transitioned from NEW to ALLOCATED
2013-08-28 15:59:47,906 INFO org.apache.hadoop.yarn.server.resourcemanager.RMAuditLogger: USER=ubuntu	OPERATION=AM Allocated Container	TARGET=SchedulerApp	RESULT=SUCCESS	APPID=application_1377704542759_0008	CONTAINERID=container_1377704542759_0008_01_000019
2013-08-28 15:59:47,907 INFO org.apache.hadoop.yarn.server.resourcemanager.scheduler.common.fica.FiCaSchedulerNode: Assigned container container_1377704542759_0008_01_000019 of capacity <memory:1024, vCores:1> on host hadoop-16-4:52495, which currently has 5 containers, <memory:6144, vCores:5> used and <memory:2048, vCores:11> available
2013-08-28 15:59:47,908 INFO org.apache.hadoop.yarn.server.resourcemanager.scheduler.capacity.LeafQueue: assignedContainer application=application_1377704542759_0008 container=Container: [ContainerId: container_1377704542759_0008_01_000019, NodeId: hadoop-16-4:52495, NodeHttpAddress: hadoop-16-4:8042, Resource: <memory:1024, vCores:1>, Priority: 20, State: NEW, Token: null, Status: container_id {, app_attempt_id {, application_id {, id: 8, cluster_timestamp: 1377704542759, }, attemptId: 1, }, id: 19, }, state: C_NEW, ] containerId=container_1377704542759_0008_01_000019 queue=default: capacity=1.0, absoluteCapacity=1.0, usedResources=<memory:27648, vCores:22>usedCapacity=0.5625, absoluteUsedCapacity=0.5625, numApps=5, numContainers=22 usedCapacity=0.5625 absoluteUsedCapacity=0.5625 used=<memory:27648, vCores:22> cluster=<memory:49152, vCores:96>
2013-08-28 15:59:47,908 INFO org.apache.hadoop.yarn.server.resourcemanager.scheduler.capacity.ParentQueue: Re-sorting queues since queue: root.default stats: default: capacity=1.0, absoluteCapacity=1.0, usedResources=<memory:28672, vCores:23>usedCapacity=0.5833333, absoluteUsedCapacity=0.5833333, numApps=5, numContainers=23
2013-08-28 15:59:47,908 INFO org.apache.hadoop.yarn.server.resourcemanager.scheduler.capacity.ParentQueue: assignedContainer queue=root usedCapacity=0.5833333 absoluteUsedCapacity=0.5833333 used=<memory:28672, vCores:23> cluster=<memory:49152, vCores:96>
2013-08-28 15:59:47,908 INFO org.apache.hadoop.yarn.server.resourcemanager.rmcontainer.RMContainerImpl: container_1377704542759_0008_01_000020 Container Transitioned from NEW to ALLOCATED
2013-08-28 15:59:47,909 INFO org.apache.hadoop.yarn.server.resourcemanager.RMAuditLogger: USER=ubuntu	OPERATION=AM Allocated Container	TARGET=SchedulerApp	RESULT=SUCCESS	APPID=application_1377704542759_0008	CONTAINERID=container_1377704542759_0008_01_000020
2013-08-28 15:59:47,909 INFO org.apache.hadoop.yarn.server.resourcemanager.scheduler.common.fica.FiCaSchedulerNode: Assigned container container_1377704542759_0008_01_000020 of capacity <memory:1024, vCores:1> on host hadoop-16-4:52495, which currently has 6 containers, <memory:7168, vCores:6> used and <memory:1024, vCores:10> available
2013-08-28 15:59:47,910 INFO org.apache.hadoop.yarn.server.resourcemanager.scheduler.capacity.LeafQueue: assignedContainer application=application_1377704542759_0008 container=Container: [ContainerId: container_1377704542759_0008_01_000020, NodeId: hadoop-16-4:52495, NodeHttpAddress: hadoop-16-4:8042, Resource: <memory:1024, vCores:1>, Priority: 20, State: NEW, Token: null, Status: container_id {, app_attempt_id {, application_id {, id: 8, cluster_timestamp: 1377704542759, }, attemptId: 1, }, id: 20, }, state: C_NEW, ] containerId=container_1377704542759_0008_01_000020 queue=default: capacity=1.0, absoluteCapacity=1.0, usedResources=<memory:28672, vCores:23>usedCapacity=0.5833333, absoluteUsedCapacity=0.5833333, numApps=5, numContainers=23 usedCapacity=0.5833333 absoluteUsedCapacity=0.5833333 used=<memory:28672, vCores:23> cluster=<memory:49152, vCores:96>
2013-08-28 15:59:47,910 INFO org.apache.hadoop.yarn.server.resourcemanager.scheduler.capacity.ParentQueue: Re-sorting queues since queue: root.default stats: default: capacity=1.0, absoluteCapacity=1.0, usedResources=<memory:29696, vCores:24>usedCapacity=0.6041667, absoluteUsedCapacity=0.6041667, numApps=5, numContainers=24
2013-08-28 15:59:47,910 INFO org.apache.hadoop.yarn.server.resourcemanager.scheduler.capacity.ParentQueue: assignedContainer queue=root usedCapacity=0.6041667 absoluteUsedCapacity=0.6041667 used=<memory:29696, vCores:24> cluster=<memory:49152, vCores:96>
2013-08-28 15:59:47,911 INFO org.apache.hadoop.yarn.server.resourcemanager.rmcontainer.RMContainerImpl: container_1377704542759_0008_01_000021 Container Transitioned from NEW to ALLOCATED
2013-08-28 15:59:47,911 INFO org.apache.hadoop.yarn.server.resourcemanager.RMAuditLogger: USER=ubuntu	OPERATION=AM Allocated Container	TARGET=SchedulerApp	RESULT=SUCCESS	APPID=application_1377704542759_0008	CONTAINERID=container_1377704542759_0008_01_000021
2013-08-28 15:59:47,911 INFO org.apache.hadoop.yarn.server.resourcemanager.scheduler.common.fica.FiCaSchedulerNode: Assigned container container_1377704542759_0008_01_000021 of capacity <memory:1024, vCores:1> on host hadoop-16-4:52495, which currently has 7 containers, <memory:8192, vCores:7> used and <memory:0, vCores:9> available
2013-08-28 15:59:47,912 INFO org.apache.hadoop.yarn.server.resourcemanager.scheduler.capacity.LeafQueue: assignedContainer application=application_1377704542759_0008 container=Container: [ContainerId: container_1377704542759_0008_01_000021, NodeId: hadoop-16-4:52495, NodeHttpAddress: hadoop-16-4:8042, Resource: <memory:1024, vCores:1>, Priority: 20, State: NEW, Token: null, Status: container_id {, app_attempt_id {, application_id {, id: 8, cluster_timestamp: 1377704542759, }, attemptId: 1, }, id: 21, }, state: C_NEW, ] containerId=container_1377704542759_0008_01_000021 queue=default: capacity=1.0, absoluteCapacity=1.0, usedResources=<memory:29696, vCores:24>usedCapacity=0.6041667, absoluteUsedCapacity=0.6041667, numApps=5, numContainers=24 usedCapacity=0.6041667 absoluteUsedCapacity=0.6041667 used=<memory:29696, vCores:24> cluster=<memory:49152, vCores:96>
2013-08-28 15:59:47,912 INFO org.apache.hadoop.yarn.server.resourcemanager.scheduler.capacity.ParentQueue: Re-sorting queues since queue: root.default stats: default: capacity=1.0, absoluteCapacity=1.0, usedResources=<memory:30720, vCores:25>usedCapacity=0.625, absoluteUsedCapacity=0.625, numApps=5, numContainers=25
2013-08-28 15:59:47,912 INFO org.apache.hadoop.yarn.server.resourcemanager.scheduler.capacity.ParentQueue: assignedContainer queue=root usedCapacity=0.625 absoluteUsedCapacity=0.625 used=<memory:30720, vCores:25> cluster=<memory:49152, vCores:96>
2013-08-28 15:59:47,929 INFO org.apache.hadoop.yarn.server.resourcemanager.ApplicationMasterService: AM registration appattempt_1377704542759_0010_000001
2013-08-28 15:59:47,930 INFO org.apache.hadoop.yarn.server.resourcemanager.RMAuditLogger: USER=ubuntu	IP=192.168.100.19	OPERATION=Register App Master	TARGET=ApplicationMasterService	RESULT=SUCCESS	APPID=application_1377704542759_0010	APPATTEMPTID=appattempt_1377704542759_0010_000001
2013-08-28 15:59:47,932 INFO org.apache.hadoop.yarn.server.resourcemanager.rmapp.attempt.RMAppAttemptImpl: appattempt_1377704542759_0010_000001 State change from LAUNCHED to RUNNING
2013-08-28 15:59:47,932 INFO org.apache.hadoop.yarn.server.resourcemanager.rmapp.RMAppImpl: application_1377704542759_0010 State change from ACCEPTED to RUNNING
2013-08-28 15:59:47,978 INFO org.apache.hadoop.yarn.server.resourcemanager.rmcontainer.RMContainerImpl: container_1377704542759_0008_01_000022 Container Transitioned from NEW to ALLOCATED
2013-08-28 15:59:47,978 INFO org.apache.hadoop.yarn.server.resourcemanager.RMAuditLogger: USER=ubuntu	OPERATION=AM Allocated Container	TARGET=SchedulerApp	RESULT=SUCCESS	APPID=application_1377704542759_0008	CONTAINERID=container_1377704542759_0008_01_000022
2013-08-28 15:59:47,978 INFO org.apache.hadoop.yarn.server.resourcemanager.scheduler.common.fica.FiCaSchedulerNode: Assigned container container_1377704542759_0008_01_000022 of capacity <memory:1024, vCores:1> on host hadoop-16-7:53595, which currently has 2 containers, <memory:3072, vCores:2> used and <memory:5120, vCores:14> available
2013-08-28 15:59:47,979 INFO org.apache.hadoop.yarn.server.resourcemanager.scheduler.capacity.LeafQueue: assignedContainer application=application_1377704542759_0008 container=Container: [ContainerId: container_1377704542759_0008_01_000022, NodeId: hadoop-16-7:53595, NodeHttpAddress: hadoop-16-7:8042, Resource: <memory:1024, vCores:1>, Priority: 20, State: NEW, Token: null, Status: container_id {, app_attempt_id {, application_id {, id: 8, cluster_timestamp: 1377704542759, }, attemptId: 1, }, id: 22, }, state: C_NEW, ] containerId=container_1377704542759_0008_01_000022 queue=default: capacity=1.0, absoluteCapacity=1.0, usedResources=<memory:30720, vCores:25>usedCapacity=0.625, absoluteUsedCapacity=0.625, numApps=5, numContainers=25 usedCapacity=0.625 absoluteUsedCapacity=0.625 used=<memory:30720, vCores:25> cluster=<memory:49152, vCores:96>
2013-08-28 15:59:47,979 INFO org.apache.hadoop.yarn.server.resourcemanager.scheduler.capacity.ParentQueue: Re-sorting queues since queue: root.default stats: default: capacity=1.0, absoluteCapacity=1.0, usedResources=<memory:31744, vCores:26>usedCapacity=0.6458333, absoluteUsedCapacity=0.6458333, numApps=5, numContainers=26
2013-08-28 15:59:47,980 INFO org.apache.hadoop.yarn.server.resourcemanager.scheduler.capacity.ParentQueue: assignedContainer queue=root usedCapacity=0.6458333 absoluteUsedCapacity=0.6458333 used=<memory:31744, vCores:26> cluster=<memory:49152, vCores:96>
2013-08-28 15:59:47,980 INFO org.apache.hadoop.yarn.server.resourcemanager.rmcontainer.RMContainerImpl: container_1377704542759_0008_01_000023 Container Transitioned from NEW to ALLOCATED
2013-08-28 15:59:47,980 INFO org.apache.hadoop.yarn.server.resourcemanager.RMAuditLogger: USER=ubuntu	OPERATION=AM Allocated Container	TARGET=SchedulerApp	RESULT=SUCCESS	APPID=application_1377704542759_0008	CONTAINERID=container_1377704542759_0008_01_000023
2013-08-28 15:59:47,981 INFO org.apache.hadoop.yarn.server.resourcemanager.scheduler.common.fica.FiCaSchedulerNode: Assigned container container_1377704542759_0008_01_000023 of capacity <memory:1024, vCores:1> on host hadoop-16-7:53595, which currently has 3 containers, <memory:4096, vCores:3> used and <memory:4096, vCores:13> available
2013-08-28 15:59:47,981 INFO org.apache.hadoop.yarn.server.resourcemanager.scheduler.capacity.LeafQueue: assignedContainer application=application_1377704542759_0008 container=Container: [ContainerId: container_1377704542759_0008_01_000023, NodeId: hadoop-16-7:53595, NodeHttpAddress: hadoop-16-7:8042, Resource: <memory:1024, vCores:1>, Priority: 20, State: NEW, Token: null, Status: container_id {, app_attempt_id {, application_id {, id: 8, cluster_timestamp: 1377704542759, }, attemptId: 1, }, id: 23, }, state: C_NEW, ] containerId=container_1377704542759_0008_01_000023 queue=default: capacity=1.0, absoluteCapacity=1.0, usedResources=<memory:31744, vCores:26>usedCapacity=0.6458333, absoluteUsedCapacity=0.6458333, numApps=5, numContainers=26 usedCapacity=0.6458333 absoluteUsedCapacity=0.6458333 used=<memory:31744, vCores:26> cluster=<memory:49152, vCores:96>
2013-08-28 15:59:47,982 INFO org.apache.hadoop.yarn.server.resourcemanager.scheduler.capacity.ParentQueue: Re-sorting queues since queue: root.default stats: default: capacity=1.0, absoluteCapacity=1.0, usedResources=<memory:32768, vCores:27>usedCapacity=0.6666667, absoluteUsedCapacity=0.6666667, numApps=5, numContainers=27
2013-08-28 15:59:47,982 INFO org.apache.hadoop.yarn.server.resourcemanager.scheduler.capacity.ParentQueue: assignedContainer queue=root usedCapacity=0.6666667 absoluteUsedCapacity=0.6666667 used=<memory:32768, vCores:27> cluster=<memory:49152, vCores:96>
2013-08-28 15:59:47,982 INFO org.apache.hadoop.yarn.server.resourcemanager.rmcontainer.RMContainerImpl: container_1377704542759_0008_01_000024 Container Transitioned from NEW to ALLOCATED
2013-08-28 15:59:47,982 INFO org.apache.hadoop.yarn.server.resourcemanager.RMAuditLogger: USER=ubuntu	OPERATION=AM Allocated Container	TARGET=SchedulerApp	RESULT=SUCCESS	APPID=application_1377704542759_0008	CONTAINERID=container_1377704542759_0008_01_000024
2013-08-28 15:59:47,983 INFO org.apache.hadoop.yarn.server.resourcemanager.scheduler.common.fica.FiCaSchedulerNode: Assigned container container_1377704542759_0008_01_000024 of capacity <memory:1024, vCores:1> on host hadoop-16-7:53595, which currently has 4 containers, <memory:5120, vCores:4> used and <memory:3072, vCores:12> available
2013-08-28 15:59:47,984 INFO org.apache.hadoop.yarn.server.resourcemanager.scheduler.capacity.LeafQueue: assignedContainer application=application_1377704542759_0008 container=Container: [ContainerId: container_1377704542759_0008_01_000024, NodeId: hadoop-16-7:53595, NodeHttpAddress: hadoop-16-7:8042, Resource: <memory:1024, vCores:1>, Priority: 20, State: NEW, Token: null, Status: container_id {, app_attempt_id {, application_id {, id: 8, cluster_timestamp: 1377704542759, }, attemptId: 1, }, id: 24, }, state: C_NEW, ] containerId=container_1377704542759_0008_01_000024 queue=default: capacity=1.0, absoluteCapacity=1.0, usedResources=<memory:32768, vCores:27>usedCapacity=0.6666667, absoluteUsedCapacity=0.6666667, numApps=5, numContainers=27 usedCapacity=0.6666667 absoluteUsedCapacity=0.6666667 used=<memory:32768, vCores:27> cluster=<memory:49152, vCores:96>
2013-08-28 15:59:47,984 INFO org.apache.hadoop.yarn.server.resourcemanager.scheduler.capacity.ParentQueue: Re-sorting queues since queue: root.default stats: default: capacity=1.0, absoluteCapacity=1.0, usedResources=<memory:33792, vCores:28>usedCapacity=0.6875, absoluteUsedCapacity=0.6875, numApps=5, numContainers=28
2013-08-28 15:59:47,984 INFO org.apache.hadoop.yarn.server.resourcemanager.scheduler.capacity.ParentQueue: assignedContainer queue=root usedCapacity=0.6875 absoluteUsedCapacity=0.6875 used=<memory:33792, vCores:28> cluster=<memory:49152, vCores:96>
2013-08-28 15:59:47,985 INFO org.apache.hadoop.yarn.server.resourcemanager.rmcontainer.RMContainerImpl: container_1377704542759_0008_01_000025 Container Transitioned from NEW to ALLOCATED
2013-08-28 15:59:47,985 INFO org.apache.hadoop.yarn.server.resourcemanager.RMAuditLogger: USER=ubuntu	OPERATION=AM Allocated Container	TARGET=SchedulerApp	RESULT=SUCCESS	APPID=application_1377704542759_0008	CONTAINERID=container_1377704542759_0008_01_000025
2013-08-28 15:59:47,985 INFO org.apache.hadoop.yarn.server.resourcemanager.scheduler.common.fica.FiCaSchedulerNode: Assigned container container_1377704542759_0008_01_000025 of capacity <memory:1024, vCores:1> on host hadoop-16-7:53595, which currently has 5 containers, <memory:6144, vCores:5> used and <memory:2048, vCores:11> available
2013-08-28 15:59:47,986 INFO org.apache.hadoop.yarn.server.resourcemanager.scheduler.capacity.LeafQueue: assignedContainer application=application_1377704542759_0008 container=Container: [ContainerId: container_1377704542759_0008_01_000025, NodeId: hadoop-16-7:53595, NodeHttpAddress: hadoop-16-7:8042, Resource: <memory:1024, vCores:1>, Priority: 20, State: NEW, Token: null, Status: container_id {, app_attempt_id {, application_id {, id: 8, cluster_timestamp: 1377704542759, }, attemptId: 1, }, id: 25, }, state: C_NEW, ] containerId=container_1377704542759_0008_01_000025 queue=default: capacity=1.0, absoluteCapacity=1.0, usedResources=<memory:33792, vCores:28>usedCapacity=0.6875, absoluteUsedCapacity=0.6875, numApps=5, numContainers=28 usedCapacity=0.6875 absoluteUsedCapacity=0.6875 used=<memory:33792, vCores:28> cluster=<memory:49152, vCores:96>
2013-08-28 15:59:47,986 INFO org.apache.hadoop.yarn.server.resourcemanager.scheduler.capacity.ParentQueue: Re-sorting queues since queue: root.default stats: default: capacity=1.0, absoluteCapacity=1.0, usedResources=<memory:34816, vCores:29>usedCapacity=0.7083333, absoluteUsedCapacity=0.7083333, numApps=5, numContainers=29
2013-08-28 15:59:47,986 INFO org.apache.hadoop.yarn.server.resourcemanager.scheduler.capacity.ParentQueue: assignedContainer queue=root usedCapacity=0.7083333 absoluteUsedCapacity=0.7083333 used=<memory:34816, vCores:29> cluster=<memory:49152, vCores:96>
2013-08-28 15:59:47,987 INFO org.apache.hadoop.yarn.server.resourcemanager.rmcontainer.RMContainerImpl: container_1377704542759_0008_01_000026 Container Transitioned from NEW to ALLOCATED
2013-08-28 15:59:47,987 INFO org.apache.hadoop.yarn.server.resourcemanager.RMAuditLogger: USER=ubuntu	OPERATION=AM Allocated Container	TARGET=SchedulerApp	RESULT=SUCCESS	APPID=application_1377704542759_0008	CONTAINERID=container_1377704542759_0008_01_000026
2013-08-28 15:59:47,987 INFO org.apache.hadoop.yarn.server.resourcemanager.scheduler.common.fica.FiCaSchedulerNode: Assigned container container_1377704542759_0008_01_000026 of capacity <memory:1024, vCores:1> on host hadoop-16-7:53595, which currently has 6 containers, <memory:7168, vCores:6> used and <memory:1024, vCores:10> available
2013-08-28 15:59:47,988 INFO org.apache.hadoop.yarn.server.resourcemanager.scheduler.capacity.LeafQueue: assignedContainer application=application_1377704542759_0008 container=Container: [ContainerId: container_1377704542759_0008_01_000026, NodeId: hadoop-16-7:53595, NodeHttpAddress: hadoop-16-7:8042, Resource: <memory:1024, vCores:1>, Priority: 20, State: NEW, Token: null, Status: container_id {, app_attempt_id {, application_id {, id: 8, cluster_timestamp: 1377704542759, }, attemptId: 1, }, id: 26, }, state: C_NEW, ] containerId=container_1377704542759_0008_01_000026 queue=default: capacity=1.0, absoluteCapacity=1.0, usedResources=<memory:34816, vCores:29>usedCapacity=0.7083333, absoluteUsedCapacity=0.7083333, numApps=5, numContainers=29 usedCapacity=0.7083333 absoluteUsedCapacity=0.7083333 used=<memory:34816, vCores:29> cluster=<memory:49152, vCores:96>
2013-08-28 15:59:47,988 INFO org.apache.hadoop.yarn.server.resourcemanager.scheduler.capacity.ParentQueue: Re-sorting queues since queue: root.default stats: default: capacity=1.0, absoluteCapacity=1.0, usedResources=<memory:35840, vCores:30>usedCapacity=0.7291667, absoluteUsedCapacity=0.7291667, numApps=5, numContainers=30
2013-08-28 15:59:47,988 INFO org.apache.hadoop.yarn.server.resourcemanager.scheduler.capacity.ParentQueue: assignedContainer queue=root usedCapacity=0.7291667 absoluteUsedCapacity=0.7291667 used=<memory:35840, vCores:30> cluster=<memory:49152, vCores:96>
2013-08-28 15:59:47,989 INFO org.apache.hadoop.yarn.server.resourcemanager.rmcontainer.RMContainerImpl: container_1377704542759_0008_01_000027 Container Transitioned from NEW to ALLOCATED
2013-08-28 15:59:47,989 INFO org.apache.hadoop.yarn.server.resourcemanager.RMAuditLogger: USER=ubuntu	OPERATION=AM Allocated Container	TARGET=SchedulerApp	RESULT=SUCCESS	APPID=application_1377704542759_0008	CONTAINERID=container_1377704542759_0008_01_000027
2013-08-28 15:59:47,989 INFO org.apache.hadoop.yarn.server.resourcemanager.scheduler.common.fica.FiCaSchedulerNode: Assigned container container_1377704542759_0008_01_000027 of capacity <memory:1024, vCores:1> on host hadoop-16-7:53595, which currently has 7 containers, <memory:8192, vCores:7> used and <memory:0, vCores:9> available
2013-08-28 15:59:47,990 INFO org.apache.hadoop.yarn.server.resourcemanager.scheduler.capacity.LeafQueue: assignedContainer application=application_1377704542759_0008 container=Container: [ContainerId: container_1377704542759_0008_01_000027, NodeId: hadoop-16-7:53595, NodeHttpAddress: hadoop-16-7:8042, Resource: <memory:1024, vCores:1>, Priority: 20, State: NEW, Token: null, Status: container_id {, app_attempt_id {, application_id {, id: 8, cluster_timestamp: 1377704542759, }, attemptId: 1, }, id: 27, }, state: C_NEW, ] containerId=container_1377704542759_0008_01_000027 queue=default: capacity=1.0, absoluteCapacity=1.0, usedResources=<memory:35840, vCores:30>usedCapacity=0.7291667, absoluteUsedCapacity=0.7291667, numApps=5, numContainers=30 usedCapacity=0.7291667 absoluteUsedCapacity=0.7291667 used=<memory:35840, vCores:30> cluster=<memory:49152, vCores:96>
2013-08-28 15:59:47,990 INFO org.apache.hadoop.yarn.server.resourcemanager.scheduler.capacity.ParentQueue: Re-sorting queues since queue: root.default stats: default: capacity=1.0, absoluteCapacity=1.0, usedResources=<memory:36864, vCores:31>usedCapacity=0.75, absoluteUsedCapacity=0.75, numApps=5, numContainers=31
2013-08-28 15:59:47,991 INFO org.apache.hadoop.yarn.server.resourcemanager.scheduler.capacity.ParentQueue: assignedContainer queue=root usedCapacity=0.75 absoluteUsedCapacity=0.75 used=<memory:36864, vCores:31> cluster=<memory:49152, vCores:96>
2013-08-28 15:59:48,142 INFO org.apache.hadoop.yarn.server.resourcemanager.rmcontainer.RMContainerImpl: container_1377704542759_0006_01_000002 Container Transitioned from NEW to ALLOCATED
2013-08-28 15:59:48,143 INFO org.apache.hadoop.yarn.server.resourcemanager.RMAuditLogger: USER=ubuntu	OPERATION=AM Allocated Container	TARGET=SchedulerApp	RESULT=SUCCESS	APPID=application_1377704542759_0006	CONTAINERID=container_1377704542759_0006_01_000002
2013-08-28 15:59:48,143 INFO org.apache.hadoop.yarn.server.resourcemanager.scheduler.common.fica.FiCaSchedulerNode: Assigned container container_1377704542759_0006_01_000002 of capacity <memory:1024, vCores:1> on host hadoop-16-6:36337, which currently has 2 containers, <memory:3072, vCores:2> used and <memory:5120, vCores:14> available
2013-08-28 15:59:48,144 INFO org.apache.hadoop.yarn.server.resourcemanager.scheduler.capacity.LeafQueue: assignedContainer application=application_1377704542759_0006 container=Container: [ContainerId: container_1377704542759_0006_01_000002, NodeId: hadoop-16-6:36337, NodeHttpAddress: hadoop-16-6:8042, Resource: <memory:1024, vCores:1>, Priority: 20, State: NEW, Token: null, Status: container_id {, app_attempt_id {, application_id {, id: 6, cluster_timestamp: 1377704542759, }, attemptId: 1, }, id: 2, }, state: C_NEW, ] containerId=container_1377704542759_0006_01_000002 queue=default: capacity=1.0, absoluteCapacity=1.0, usedResources=<memory:36864, vCores:31>usedCapacity=0.75, absoluteUsedCapacity=0.75, numApps=5, numContainers=31 usedCapacity=0.75 absoluteUsedCapacity=0.75 used=<memory:36864, vCores:31> cluster=<memory:49152, vCores:96>
2013-08-28 15:59:48,144 INFO org.apache.hadoop.yarn.server.resourcemanager.scheduler.capacity.ParentQueue: Re-sorting queues since queue: root.default stats: default: capacity=1.0, absoluteCapacity=1.0, usedResources=<memory:37888, vCores:32>usedCapacity=0.7708333, absoluteUsedCapacity=0.7708333, numApps=5, numContainers=32
2013-08-28 15:59:48,144 INFO org.apache.hadoop.yarn.server.resourcemanager.scheduler.capacity.ParentQueue: assignedContainer queue=root usedCapacity=0.7708333 absoluteUsedCapacity=0.7708333 used=<memory:37888, vCores:32> cluster=<memory:49152, vCores:96>
2013-08-28 15:59:48,145 INFO org.apache.hadoop.yarn.server.resourcemanager.rmcontainer.RMContainerImpl: container_1377704542759_0006_01_000003 Container Transitioned from NEW to ALLOCATED
2013-08-28 15:59:48,145 INFO org.apache.hadoop.yarn.server.resourcemanager.RMAuditLogger: USER=ubuntu	OPERATION=AM Allocated Container	TARGET=SchedulerApp	RESULT=SUCCESS	APPID=application_1377704542759_0006	CONTAINERID=container_1377704542759_0006_01_000003
2013-08-28 15:59:48,145 INFO org.apache.hadoop.yarn.server.resourcemanager.scheduler.common.fica.FiCaSchedulerNode: Assigned container container_1377704542759_0006_01_000003 of capacity <memory:1024, vCores:1> on host hadoop-16-6:36337, which currently has 3 containers, <memory:4096, vCores:3> used and <memory:4096, vCores:13> available
2013-08-28 15:59:48,146 INFO org.apache.hadoop.yarn.server.resourcemanager.scheduler.capacity.LeafQueue: assignedContainer application=application_1377704542759_0006 container=Container: [ContainerId: container_1377704542759_0006_01_000003, NodeId: hadoop-16-6:36337, NodeHttpAddress: hadoop-16-6:8042, Resource: <memory:1024, vCores:1>, Priority: 20, State: NEW, Token: null, Status: container_id {, app_attempt_id {, application_id {, id: 6, cluster_timestamp: 1377704542759, }, attemptId: 1, }, id: 3, }, state: C_NEW, ] containerId=container_1377704542759_0006_01_000003 queue=default: capacity=1.0, absoluteCapacity=1.0, usedResources=<memory:37888, vCores:32>usedCapacity=0.7708333, absoluteUsedCapacity=0.7708333, numApps=5, numContainers=32 usedCapacity=0.7708333 absoluteUsedCapacity=0.7708333 used=<memory:37888, vCores:32> cluster=<memory:49152, vCores:96>
2013-08-28 15:59:48,146 INFO org.apache.hadoop.yarn.server.resourcemanager.scheduler.capacity.ParentQueue: Re-sorting queues since queue: root.default stats: default: capacity=1.0, absoluteCapacity=1.0, usedResources=<memory:38912, vCores:33>usedCapacity=0.7916667, absoluteUsedCapacity=0.7916667, numApps=5, numContainers=33
2013-08-28 15:59:48,146 INFO org.apache.hadoop.yarn.server.resourcemanager.scheduler.capacity.ParentQueue: assignedContainer queue=root usedCapacity=0.7916667 absoluteUsedCapacity=0.7916667 used=<memory:38912, vCores:33> cluster=<memory:49152, vCores:96>
2013-08-28 15:59:48,147 INFO org.apache.hadoop.yarn.server.resourcemanager.rmcontainer.RMContainerImpl: container_1377704542759_0006_01_000004 Container Transitioned from NEW to ALLOCATED
2013-08-28 15:59:48,147 INFO org.apache.hadoop.yarn.server.resourcemanager.RMAuditLogger: USER=ubuntu	OPERATION=AM Allocated Container	TARGET=SchedulerApp	RESULT=SUCCESS	APPID=application_1377704542759_0006	CONTAINERID=container_1377704542759_0006_01_000004
2013-08-28 15:59:48,147 INFO org.apache.hadoop.yarn.server.resourcemanager.scheduler.common.fica.FiCaSchedulerNode: Assigned container container_1377704542759_0006_01_000004 of capacity <memory:1024, vCores:1> on host hadoop-16-6:36337, which currently has 4 containers, <memory:5120, vCores:4> used and <memory:3072, vCores:12> available
2013-08-28 15:59:48,148 INFO org.apache.hadoop.yarn.server.resourcemanager.scheduler.capacity.LeafQueue: assignedContainer application=application_1377704542759_0006 container=Container: [ContainerId: container_1377704542759_0006_01_000004, NodeId: hadoop-16-6:36337, NodeHttpAddress: hadoop-16-6:8042, Resource: <memory:1024, vCores:1>, Priority: 20, State: NEW, Token: null, Status: container_id {, app_attempt_id {, application_id {, id: 6, cluster_timestamp: 1377704542759, }, attemptId: 1, }, id: 4, }, state: C_NEW, ] containerId=container_1377704542759_0006_01_000004 queue=default: capacity=1.0, absoluteCapacity=1.0, usedResources=<memory:38912, vCores:33>usedCapacity=0.7916667, absoluteUsedCapacity=0.7916667, numApps=5, numContainers=33 usedCapacity=0.7916667 absoluteUsedCapacity=0.7916667 used=<memory:38912, vCores:33> cluster=<memory:49152, vCores:96>
2013-08-28 15:59:48,148 INFO org.apache.hadoop.yarn.server.resourcemanager.scheduler.capacity.ParentQueue: Re-sorting queues since queue: root.default stats: default: capacity=1.0, absoluteCapacity=1.0, usedResources=<memory:39936, vCores:34>usedCapacity=0.8125, absoluteUsedCapacity=0.8125, numApps=5, numContainers=34
2013-08-28 15:59:48,149 INFO org.apache.hadoop.yarn.server.resourcemanager.scheduler.capacity.ParentQueue: assignedContainer queue=root usedCapacity=0.8125 absoluteUsedCapacity=0.8125 used=<memory:39936, vCores:34> cluster=<memory:49152, vCores:96>
2013-08-28 15:59:48,149 INFO org.apache.hadoop.yarn.server.resourcemanager.rmcontainer.RMContainerImpl: container_1377704542759_0006_01_000005 Container Transitioned from NEW to ALLOCATED
2013-08-28 15:59:48,149 INFO org.apache.hadoop.yarn.server.resourcemanager.RMAuditLogger: USER=ubuntu	OPERATION=AM Allocated Container	TARGET=SchedulerApp	RESULT=SUCCESS	APPID=application_1377704542759_0006	CONTAINERID=container_1377704542759_0006_01_000005
2013-08-28 15:59:48,149 INFO org.apache.hadoop.yarn.server.resourcemanager.scheduler.common.fica.FiCaSchedulerNode: Assigned container container_1377704542759_0006_01_000005 of capacity <memory:1024, vCores:1> on host hadoop-16-6:36337, which currently has 5 containers, <memory:6144, vCores:5> used and <memory:2048, vCores:11> available
2013-08-28 15:59:48,150 INFO org.apache.hadoop.yarn.server.resourcemanager.scheduler.capacity.LeafQueue: assignedContainer application=application_1377704542759_0006 container=Container: [ContainerId: container_1377704542759_0006_01_000005, NodeId: hadoop-16-6:36337, NodeHttpAddress: hadoop-16-6:8042, Resource: <memory:1024, vCores:1>, Priority: 20, State: NEW, Token: null, Status: container_id {, app_attempt_id {, application_id {, id: 6, cluster_timestamp: 1377704542759, }, attemptId: 1, }, id: 5, }, state: C_NEW, ] containerId=container_1377704542759_0006_01_000005 queue=default: capacity=1.0, absoluteCapacity=1.0, usedResources=<memory:39936, vCores:34>usedCapacity=0.8125, absoluteUsedCapacity=0.8125, numApps=5, numContainers=34 usedCapacity=0.8125 absoluteUsedCapacity=0.8125 used=<memory:39936, vCores:34> cluster=<memory:49152, vCores:96>
2013-08-28 15:59:48,151 INFO org.apache.hadoop.yarn.server.resourcemanager.scheduler.capacity.ParentQueue: Re-sorting queues since queue: root.default stats: default: capacity=1.0, absoluteCapacity=1.0, usedResources=<memory:40960, vCores:35>usedCapacity=0.8333333, absoluteUsedCapacity=0.8333333, numApps=5, numContainers=35
2013-08-28 15:59:48,151 INFO org.apache.hadoop.yarn.server.resourcemanager.scheduler.capacity.ParentQueue: assignedContainer queue=root usedCapacity=0.8333333 absoluteUsedCapacity=0.8333333 used=<memory:40960, vCores:35> cluster=<memory:49152, vCores:96>
2013-08-28 15:59:48,151 INFO org.apache.hadoop.yarn.server.resourcemanager.rmcontainer.RMContainerImpl: container_1377704542759_0006_01_000006 Container Transitioned from NEW to ALLOCATED
2013-08-28 15:59:48,151 INFO org.apache.hadoop.yarn.server.resourcemanager.RMAuditLogger: USER=ubuntu	OPERATION=AM Allocated Container	TARGET=SchedulerApp	RESULT=SUCCESS	APPID=application_1377704542759_0006	CONTAINERID=container_1377704542759_0006_01_000006
2013-08-28 15:59:48,152 INFO org.apache.hadoop.yarn.server.resourcemanager.scheduler.common.fica.FiCaSchedulerNode: Assigned container container_1377704542759_0006_01_000006 of capacity <memory:1024, vCores:1> on host hadoop-16-6:36337, which currently has 6 containers, <memory:7168, vCores:6> used and <memory:1024, vCores:10> available
2013-08-28 15:59:48,152 INFO org.apache.hadoop.yarn.server.resourcemanager.scheduler.capacity.LeafQueue: assignedContainer application=application_1377704542759_0006 container=Container: [ContainerId: container_1377704542759_0006_01_000006, NodeId: hadoop-16-6:36337, NodeHttpAddress: hadoop-16-6:8042, Resource: <memory:1024, vCores:1>, Priority: 20, State: NEW, Token: null, Status: container_id {, app_attempt_id {, application_id {, id: 6, cluster_timestamp: 1377704542759, }, attemptId: 1, }, id: 6, }, state: C_NEW, ] containerId=container_1377704542759_0006_01_000006 queue=default: capacity=1.0, absoluteCapacity=1.0, usedResources=<memory:40960, vCores:35>usedCapacity=0.8333333, absoluteUsedCapacity=0.8333333, numApps=5, numContainers=35 usedCapacity=0.8333333 absoluteUsedCapacity=0.8333333 used=<memory:40960, vCores:35> cluster=<memory:49152, vCores:96>
2013-08-28 15:59:48,153 INFO org.apache.hadoop.yarn.server.resourcemanager.scheduler.capacity.ParentQueue: Re-sorting queues since queue: root.default stats: default: capacity=1.0, absoluteCapacity=1.0, usedResources=<memory:41984, vCores:36>usedCapacity=0.8541667, absoluteUsedCapacity=0.8541667, numApps=5, numContainers=36
2013-08-28 15:59:48,153 INFO org.apache.hadoop.yarn.server.resourcemanager.scheduler.capacity.ParentQueue: assignedContainer queue=root usedCapacity=0.8541667 absoluteUsedCapacity=0.8541667 used=<memory:41984, vCores:36> cluster=<memory:49152, vCores:96>
2013-08-28 15:59:48,153 INFO org.apache.hadoop.yarn.server.resourcemanager.rmcontainer.RMContainerImpl: container_1377704542759_0006_01_000007 Container Transitioned from NEW to ALLOCATED
2013-08-28 15:59:48,153 INFO org.apache.hadoop.yarn.server.resourcemanager.RMAuditLogger: USER=ubuntu	OPERATION=AM Allocated Container	TARGET=SchedulerApp	RESULT=SUCCESS	APPID=application_1377704542759_0006	CONTAINERID=container_1377704542759_0006_01_000007
2013-08-28 15:59:48,154 INFO org.apache.hadoop.yarn.server.resourcemanager.scheduler.common.fica.FiCaSchedulerNode: Assigned container container_1377704542759_0006_01_000007 of capacity <memory:1024, vCores:1> on host hadoop-16-6:36337, which currently has 7 containers, <memory:8192, vCores:7> used and <memory:0, vCores:9> available
2013-08-28 15:59:48,155 INFO org.apache.hadoop.yarn.server.resourcemanager.scheduler.capacity.LeafQueue: assignedContainer application=application_1377704542759_0006 container=Container: [ContainerId: container_1377704542759_0006_01_000007, NodeId: hadoop-16-6:36337, NodeHttpAddress: hadoop-16-6:8042, Resource: <memory:1024, vCores:1>, Priority: 20, State: NEW, Token: null, Status: container_id {, app_attempt_id {, application_id {, id: 6, cluster_timestamp: 1377704542759, }, attemptId: 1, }, id: 7, }, state: C_NEW, ] containerId=container_1377704542759_0006_01_000007 queue=default: capacity=1.0, absoluteCapacity=1.0, usedResources=<memory:41984, vCores:36>usedCapacity=0.8541667, absoluteUsedCapacity=0.8541667, numApps=5, numContainers=36 usedCapacity=0.8541667 absoluteUsedCapacity=0.8541667 used=<memory:41984, vCores:36> cluster=<memory:49152, vCores:96>
2013-08-28 15:59:48,155 INFO org.apache.hadoop.yarn.server.resourcemanager.scheduler.capacity.ParentQueue: Re-sorting queues since queue: root.default stats: default: capacity=1.0, absoluteCapacity=1.0, usedResources=<memory:43008, vCores:37>usedCapacity=0.875, absoluteUsedCapacity=0.875, numApps=5, numContainers=37
2013-08-28 15:59:48,155 INFO org.apache.hadoop.yarn.server.resourcemanager.scheduler.capacity.ParentQueue: assignedContainer queue=root usedCapacity=0.875 absoluteUsedCapacity=0.875 used=<memory:43008, vCores:37> cluster=<memory:49152, vCores:96>
2013-08-28 15:59:48,596 INFO org.apache.hadoop.yarn.server.resourcemanager.rmcontainer.RMContainerImpl: container_1377704542759_0006_01_000008 Container Transitioned from NEW to ALLOCATED
2013-08-28 15:59:48,596 INFO org.apache.hadoop.yarn.server.resourcemanager.RMAuditLogger: USER=ubuntu	OPERATION=AM Allocated Container	TARGET=SchedulerApp	RESULT=SUCCESS	APPID=application_1377704542759_0006	CONTAINERID=container_1377704542759_0006_01_000008
2013-08-28 15:59:48,596 INFO org.apache.hadoop.yarn.server.resourcemanager.scheduler.common.fica.FiCaSchedulerNode: Assigned container container_1377704542759_0006_01_000008 of capacity <memory:1024, vCores:1> on host hadoop-16-5:57886, which currently has 2 containers, <memory:3072, vCores:2> used and <memory:5120, vCores:14> available
2013-08-28 15:59:48,597 INFO org.apache.hadoop.yarn.server.resourcemanager.scheduler.capacity.LeafQueue: assignedContainer application=application_1377704542759_0006 container=Container: [ContainerId: container_1377704542759_0006_01_000008, NodeId: hadoop-16-5:57886, NodeHttpAddress: hadoop-16-5:8042, Resource: <memory:1024, vCores:1>, Priority: 20, State: NEW, Token: null, Status: container_id {, app_attempt_id {, application_id {, id: 6, cluster_timestamp: 1377704542759, }, attemptId: 1, }, id: 8, }, state: C_NEW, ] containerId=container_1377704542759_0006_01_000008 queue=default: capacity=1.0, absoluteCapacity=1.0, usedResources=<memory:43008, vCores:37>usedCapacity=0.875, absoluteUsedCapacity=0.875, numApps=5, numContainers=37 usedCapacity=0.875 absoluteUsedCapacity=0.875 used=<memory:43008, vCores:37> cluster=<memory:49152, vCores:96>
2013-08-28 15:59:48,598 INFO org.apache.hadoop.yarn.server.resourcemanager.scheduler.capacity.ParentQueue: Re-sorting queues since queue: root.default stats: default: capacity=1.0, absoluteCapacity=1.0, usedResources=<memory:44032, vCores:38>usedCapacity=0.8958333, absoluteUsedCapacity=0.8958333, numApps=5, numContainers=38
2013-08-28 15:59:48,598 INFO org.apache.hadoop.yarn.server.resourcemanager.scheduler.capacity.ParentQueue: assignedContainer queue=root usedCapacity=0.8958333 absoluteUsedCapacity=0.8958333 used=<memory:44032, vCores:38> cluster=<memory:49152, vCores:96>
2013-08-28 15:59:48,598 INFO org.apache.hadoop.yarn.server.resourcemanager.rmcontainer.RMContainerImpl: container_1377704542759_0006_01_000009 Container Transitioned from NEW to ALLOCATED
2013-08-28 15:59:48,599 INFO org.apache.hadoop.yarn.server.resourcemanager.RMAuditLogger: USER=ubuntu	OPERATION=AM Allocated Container	TARGET=SchedulerApp	RESULT=SUCCESS	APPID=application_1377704542759_0006	CONTAINERID=container_1377704542759_0006_01_000009
2013-08-28 15:59:48,599 INFO org.apache.hadoop.yarn.server.resourcemanager.scheduler.common.fica.FiCaSchedulerNode: Assigned container container_1377704542759_0006_01_000009 of capacity <memory:1024, vCores:1> on host hadoop-16-5:57886, which currently has 3 containers, <memory:4096, vCores:3> used and <memory:4096, vCores:13> available
2013-08-28 15:59:48,600 INFO org.apache.hadoop.yarn.server.resourcemanager.scheduler.capacity.LeafQueue: assignedContainer application=application_1377704542759_0006 container=Container: [ContainerId: container_1377704542759_0006_01_000009, NodeId: hadoop-16-5:57886, NodeHttpAddress: hadoop-16-5:8042, Resource: <memory:1024, vCores:1>, Priority: 20, State: NEW, Token: null, Status: container_id {, app_attempt_id {, application_id {, id: 6, cluster_timestamp: 1377704542759, }, attemptId: 1, }, id: 9, }, state: C_NEW, ] containerId=container_1377704542759_0006_01_000009 queue=default: capacity=1.0, absoluteCapacity=1.0, usedResources=<memory:44032, vCores:38>usedCapacity=0.8958333, absoluteUsedCapacity=0.8958333, numApps=5, numContainers=38 usedCapacity=0.8958333 absoluteUsedCapacity=0.8958333 used=<memory:44032, vCores:38> cluster=<memory:49152, vCores:96>
2013-08-28 15:59:48,600 INFO org.apache.hadoop.yarn.server.resourcemanager.scheduler.capacity.ParentQueue: Re-sorting queues since queue: root.default stats: default: capacity=1.0, absoluteCapacity=1.0, usedResources=<memory:45056, vCores:39>usedCapacity=0.9166667, absoluteUsedCapacity=0.9166667, numApps=5, numContainers=39
2013-08-28 15:59:48,600 INFO org.apache.hadoop.yarn.server.resourcemanager.scheduler.capacity.ParentQueue: assignedContainer queue=root usedCapacity=0.9166667 absoluteUsedCapacity=0.9166667 used=<memory:45056, vCores:39> cluster=<memory:49152, vCores:96>
2013-08-28 15:59:48,601 INFO org.apache.hadoop.yarn.server.resourcemanager.rmcontainer.RMContainerImpl: container_1377704542759_0006_01_000010 Container Transitioned from NEW to ALLOCATED
2013-08-28 15:59:48,601 INFO org.apache.hadoop.yarn.server.resourcemanager.RMAuditLogger: USER=ubuntu	OPERATION=AM Allocated Container	TARGET=SchedulerApp	RESULT=SUCCESS	APPID=application_1377704542759_0006	CONTAINERID=container_1377704542759_0006_01_000010
2013-08-28 15:59:48,601 INFO org.apache.hadoop.yarn.server.resourcemanager.scheduler.common.fica.FiCaSchedulerNode: Assigned container container_1377704542759_0006_01_000010 of capacity <memory:1024, vCores:1> on host hadoop-16-5:57886, which currently has 4 containers, <memory:5120, vCores:4> used and <memory:3072, vCores:12> available
2013-08-28 15:59:48,602 INFO org.apache.hadoop.yarn.server.resourcemanager.scheduler.capacity.LeafQueue: assignedContainer application=application_1377704542759_0006 container=Container: [ContainerId: container_1377704542759_0006_01_000010, NodeId: hadoop-16-5:57886, NodeHttpAddress: hadoop-16-5:8042, Resource: <memory:1024, vCores:1>, Priority: 20, State: NEW, Token: null, Status: container_id {, app_attempt_id {, application_id {, id: 6, cluster_timestamp: 1377704542759, }, attemptId: 1, }, id: 10, }, state: C_NEW, ] containerId=container_1377704542759_0006_01_000010 queue=default: capacity=1.0, absoluteCapacity=1.0, usedResources=<memory:45056, vCores:39>usedCapacity=0.9166667, absoluteUsedCapacity=0.9166667, numApps=5, numContainers=39 usedCapacity=0.9166667 absoluteUsedCapacity=0.9166667 used=<memory:45056, vCores:39> cluster=<memory:49152, vCores:96>
2013-08-28 15:59:48,602 INFO org.apache.hadoop.yarn.server.resourcemanager.scheduler.capacity.ParentQueue: Re-sorting queues since queue: root.default stats: default: capacity=1.0, absoluteCapacity=1.0, usedResources=<memory:46080, vCores:40>usedCapacity=0.9375, absoluteUsedCapacity=0.9375, numApps=5, numContainers=40
2013-08-28 15:59:48,602 INFO org.apache.hadoop.yarn.server.resourcemanager.scheduler.capacity.ParentQueue: assignedContainer queue=root usedCapacity=0.9375 absoluteUsedCapacity=0.9375 used=<memory:46080, vCores:40> cluster=<memory:49152, vCores:96>
2013-08-28 15:59:48,603 INFO org.apache.hadoop.yarn.server.resourcemanager.rmcontainer.RMContainerImpl: container_1377704542759_0006_01_000011 Container Transitioned from NEW to ALLOCATED
2013-08-28 15:59:48,603 INFO org.apache.hadoop.yarn.server.resourcemanager.RMAuditLogger: USER=ubuntu	OPERATION=AM Allocated Container	TARGET=SchedulerApp	RESULT=SUCCESS	APPID=application_1377704542759_0006	CONTAINERID=container_1377704542759_0006_01_000011
2013-08-28 15:59:48,603 INFO org.apache.hadoop.yarn.server.resourcemanager.scheduler.common.fica.FiCaSchedulerNode: Assigned container container_1377704542759_0006_01_000011 of capacity <memory:1024, vCores:1> on host hadoop-16-5:57886, which currently has 5 containers, <memory:6144, vCores:5> used and <memory:2048, vCores:11> available
2013-08-28 15:59:48,604 INFO org.apache.hadoop.yarn.server.resourcemanager.scheduler.capacity.LeafQueue: assignedContainer application=application_1377704542759_0006 container=Container: [ContainerId: container_1377704542759_0006_01_000011, NodeId: hadoop-16-5:57886, NodeHttpAddress: hadoop-16-5:8042, Resource: <memory:1024, vCores:1>, Priority: 20, State: NEW, Token: null, Status: container_id {, app_attempt_id {, application_id {, id: 6, cluster_timestamp: 1377704542759, }, attemptId: 1, }, id: 11, }, state: C_NEW, ] containerId=container_1377704542759_0006_01_000011 queue=default: capacity=1.0, absoluteCapacity=1.0, usedResources=<memory:46080, vCores:40>usedCapacity=0.9375, absoluteUsedCapacity=0.9375, numApps=5, numContainers=40 usedCapacity=0.9375 absoluteUsedCapacity=0.9375 used=<memory:46080, vCores:40> cluster=<memory:49152, vCores:96>
2013-08-28 15:59:48,604 INFO org.apache.hadoop.yarn.server.resourcemanager.scheduler.capacity.ParentQueue: Re-sorting queues since queue: root.default stats: default: capacity=1.0, absoluteCapacity=1.0, usedResources=<memory:47104, vCores:41>usedCapacity=0.9583333, absoluteUsedCapacity=0.9583333, numApps=5, numContainers=41
2013-08-28 15:59:48,605 INFO org.apache.hadoop.yarn.server.resourcemanager.scheduler.capacity.ParentQueue: assignedContainer queue=root usedCapacity=0.9583333 absoluteUsedCapacity=0.9583333 used=<memory:47104, vCores:41> cluster=<memory:49152, vCores:96>
2013-08-28 15:59:48,605 INFO org.apache.hadoop.yarn.server.resourcemanager.rmcontainer.RMContainerImpl: container_1377704542759_0006_01_000012 Container Transitioned from NEW to ALLOCATED
2013-08-28 15:59:48,605 INFO org.apache.hadoop.yarn.server.resourcemanager.RMAuditLogger: USER=ubuntu	OPERATION=AM Allocated Container	TARGET=SchedulerApp	RESULT=SUCCESS	APPID=application_1377704542759_0006	CONTAINERID=container_1377704542759_0006_01_000012
2013-08-28 15:59:48,605 INFO org.apache.hadoop.yarn.server.resourcemanager.scheduler.common.fica.FiCaSchedulerNode: Assigned container container_1377704542759_0006_01_000012 of capacity <memory:1024, vCores:1> on host hadoop-16-5:57886, which currently has 6 containers, <memory:7168, vCores:6> used and <memory:1024, vCores:10> available
2013-08-28 15:59:48,606 INFO org.apache.hadoop.yarn.server.resourcemanager.scheduler.capacity.LeafQueue: assignedContainer application=application_1377704542759_0006 container=Container: [ContainerId: container_1377704542759_0006_01_000012, NodeId: hadoop-16-5:57886, NodeHttpAddress: hadoop-16-5:8042, Resource: <memory:1024, vCores:1>, Priority: 20, State: NEW, Token: null, Status: container_id {, app_attempt_id {, application_id {, id: 6, cluster_timestamp: 1377704542759, }, attemptId: 1, }, id: 12, }, state: C_NEW, ] containerId=container_1377704542759_0006_01_000012 queue=default: capacity=1.0, absoluteCapacity=1.0, usedResources=<memory:47104, vCores:41>usedCapacity=0.9583333, absoluteUsedCapacity=0.9583333, numApps=5, numContainers=41 usedCapacity=0.9583333 absoluteUsedCapacity=0.9583333 used=<memory:47104, vCores:41> cluster=<memory:49152, vCores:96>
2013-08-28 15:59:48,606 INFO org.apache.hadoop.yarn.server.resourcemanager.scheduler.capacity.ParentQueue: Re-sorting queues since queue: root.default stats: default: capacity=1.0, absoluteCapacity=1.0, usedResources=<memory:48128, vCores:42>usedCapacity=0.9791667, absoluteUsedCapacity=0.9791667, numApps=5, numContainers=42
2013-08-28 15:59:48,607 INFO org.apache.hadoop.yarn.server.resourcemanager.scheduler.capacity.ParentQueue: assignedContainer queue=root usedCapacity=0.9791667 absoluteUsedCapacity=0.9791667 used=<memory:48128, vCores:42> cluster=<memory:49152, vCores:96>
2013-08-28 15:59:48,607 INFO org.apache.hadoop.yarn.server.resourcemanager.rmcontainer.RMContainerImpl: container_1377704542759_0006_01_000013 Container Transitioned from NEW to ALLOCATED
2013-08-28 15:59:48,607 INFO org.apache.hadoop.yarn.server.resourcemanager.RMAuditLogger: USER=ubuntu	OPERATION=AM Allocated Container	TARGET=SchedulerApp	RESULT=SUCCESS	APPID=application_1377704542759_0006	CONTAINERID=container_1377704542759_0006_01_000013
2013-08-28 15:59:48,607 INFO org.apache.hadoop.yarn.server.resourcemanager.scheduler.common.fica.FiCaSchedulerNode: Assigned container container_1377704542759_0006_01_000013 of capacity <memory:1024, vCores:1> on host hadoop-16-5:57886, which currently has 7 containers, <memory:8192, vCores:7> used and <memory:0, vCores:9> available
2013-08-28 15:59:48,608 INFO org.apache.hadoop.yarn.server.resourcemanager.scheduler.capacity.LeafQueue: assignedContainer application=application_1377704542759_0006 container=Container: [ContainerId: container_1377704542759_0006_01_000013, NodeId: hadoop-16-5:57886, NodeHttpAddress: hadoop-16-5:8042, Resource: <memory:1024, vCores:1>, Priority: 20, State: NEW, Token: null, Status: container_id {, app_attempt_id {, application_id {, id: 6, cluster_timestamp: 1377704542759, }, attemptId: 1, }, id: 13, }, state: C_NEW, ] containerId=container_1377704542759_0006_01_000013 queue=default: capacity=1.0, absoluteCapacity=1.0, usedResources=<memory:48128, vCores:42>usedCapacity=0.9791667, absoluteUsedCapacity=0.9791667, numApps=5, numContainers=42 usedCapacity=0.9791667 absoluteUsedCapacity=0.9791667 used=<memory:48128, vCores:42> cluster=<memory:49152, vCores:96>
2013-08-28 15:59:48,609 INFO org.apache.hadoop.yarn.server.resourcemanager.scheduler.capacity.ParentQueue: Re-sorting queues since queue: root.default stats: default: capacity=1.0, absoluteCapacity=1.0, usedResources=<memory:49152, vCores:43>usedCapacity=1.0, absoluteUsedCapacity=1.0, numApps=5, numContainers=43
2013-08-28 15:59:48,609 INFO org.apache.hadoop.yarn.server.resourcemanager.scheduler.capacity.ParentQueue: assignedContainer queue=root usedCapacity=1.0 absoluteUsedCapacity=1.0 used=<memory:49152, vCores:43> cluster=<memory:49152, vCores:96>
2013-08-28 15:59:48,731 INFO org.apache.hadoop.yarn.server.resourcemanager.rmcontainer.RMContainerImpl: container_1377704542759_0008_01_000002 Container Transitioned from ALLOCATED to ACQUIRED
2013-08-28 15:59:48,733 INFO org.apache.hadoop.yarn.server.resourcemanager.rmcontainer.RMContainerImpl: container_1377704542759_0008_01_000003 Container Transitioned from ALLOCATED to ACQUIRED
2013-08-28 15:59:48,734 INFO org.apache.hadoop.yarn.server.resourcemanager.rmcontainer.RMContainerImpl: container_1377704542759_0008_01_000004 Container Transitioned from ALLOCATED to ACQUIRED
2013-08-28 15:59:48,735 INFO org.apache.hadoop.yarn.server.resourcemanager.rmcontainer.RMContainerImpl: container_1377704542759_0008_01_000005 Container Transitioned from ALLOCATED to ACQUIRED
2013-08-28 15:59:48,736 INFO org.apache.hadoop.yarn.server.resourcemanager.rmcontainer.RMContainerImpl: container_1377704542759_0008_01_000006 Container Transitioned from ALLOCATED to ACQUIRED
2013-08-28 15:59:48,737 INFO org.apache.hadoop.yarn.server.resourcemanager.rmcontainer.RMContainerImpl: container_1377704542759_0008_01_000007 Container Transitioned from ALLOCATED to ACQUIRED
2013-08-28 15:59:48,738 INFO org.apache.hadoop.yarn.server.resourcemanager.rmcontainer.RMContainerImpl: container_1377704542759_0008_01_000008 Container Transitioned from ALLOCATED to ACQUIRED
2013-08-28 15:59:48,739 INFO org.apache.hadoop.yarn.server.resourcemanager.rmcontainer.RMContainerImpl: container_1377704542759_0008_01_000009 Container Transitioned from ALLOCATED to ACQUIRED
2013-08-28 15:59:48,740 INFO org.apache.hadoop.yarn.server.resourcemanager.rmcontainer.RMContainerImpl: container_1377704542759_0008_01_000010 Container Transitioned from ALLOCATED to ACQUIRED
2013-08-28 15:59:48,742 INFO org.apache.hadoop.yarn.server.resourcemanager.rmcontainer.RMContainerImpl: container_1377704542759_0008_01_000011 Container Transitioned from ALLOCATED to ACQUIRED
2013-08-28 15:59:48,742 INFO org.apache.hadoop.yarn.server.resourcemanager.rmcontainer.RMContainerImpl: container_1377704542759_0008_01_000012 Container Transitioned from ALLOCATED to ACQUIRED
2013-08-28 15:59:48,743 INFO org.apache.hadoop.yarn.server.resourcemanager.rmcontainer.RMContainerImpl: container_1377704542759_0008_01_000013 Container Transitioned from ALLOCATED to ACQUIRED
2013-08-28 15:59:48,744 INFO org.apache.hadoop.yarn.server.resourcemanager.rmcontainer.RMContainerImpl: container_1377704542759_0008_01_000014 Container Transitioned from ALLOCATED to ACQUIRED
2013-08-28 15:59:48,744 INFO org.apache.hadoop.yarn.server.resourcemanager.rmcontainer.RMContainerImpl: container_1377704542759_0008_01_000015 Container Transitioned from ALLOCATED to ACQUIRED
2013-08-28 15:59:48,745 INFO org.apache.hadoop.yarn.server.resourcemanager.rmcontainer.RMContainerImpl: container_1377704542759_0008_01_000016 Container Transitioned from ALLOCATED to ACQUIRED
2013-08-28 15:59:48,745 INFO org.apache.hadoop.yarn.server.resourcemanager.rmcontainer.RMContainerImpl: container_1377704542759_0008_01_000017 Container Transitioned from ALLOCATED to ACQUIRED
2013-08-28 15:59:48,746 INFO org.apache.hadoop.yarn.server.resourcemanager.rmcontainer.RMContainerImpl: container_1377704542759_0008_01_000018 Container Transitioned from ALLOCATED to ACQUIRED
2013-08-28 15:59:48,746 INFO org.apache.hadoop.yarn.server.resourcemanager.rmcontainer.RMContainerImpl: container_1377704542759_0008_01_000019 Container Transitioned from ALLOCATED to ACQUIRED
2013-08-28 15:59:48,747 INFO org.apache.hadoop.yarn.server.resourcemanager.rmcontainer.RMContainerImpl: container_1377704542759_0008_01_000020 Container Transitioned from ALLOCATED to ACQUIRED
2013-08-28 15:59:48,748 INFO org.apache.hadoop.yarn.server.resourcemanager.rmcontainer.RMContainerImpl: container_1377704542759_0008_01_000021 Container Transitioned from ALLOCATED to ACQUIRED
2013-08-28 15:59:48,748 INFO org.apache.hadoop.yarn.server.resourcemanager.rmcontainer.RMContainerImpl: container_1377704542759_0008_01_000022 Container Transitioned from ALLOCATED to ACQUIRED
2013-08-28 15:59:48,748 INFO org.apache.hadoop.yarn.server.resourcemanager.rmcontainer.RMContainerImpl: container_1377704542759_0008_01_000023 Container Transitioned from ALLOCATED to ACQUIRED
2013-08-28 15:59:48,749 INFO org.apache.hadoop.yarn.server.resourcemanager.rmcontainer.RMContainerImpl: container_1377704542759_0008_01_000024 Container Transitioned from ALLOCATED to ACQUIRED
2013-08-28 15:59:48,749 INFO org.apache.hadoop.yarn.server.resourcemanager.rmcontainer.RMContainerImpl: container_1377704542759_0008_01_000025 Container Transitioned from ALLOCATED to ACQUIRED
2013-08-28 15:59:48,749 INFO org.apache.hadoop.yarn.server.resourcemanager.rmcontainer.RMContainerImpl: container_1377704542759_0008_01_000026 Container Transitioned from ALLOCATED to ACQUIRED
2013-08-28 15:59:48,749 INFO org.apache.hadoop.yarn.server.resourcemanager.rmcontainer.RMContainerImpl: container_1377704542759_0008_01_000027 Container Transitioned from ALLOCATED to ACQUIRED
2013-08-28 15:59:49,118 INFO org.apache.hadoop.yarn.server.resourcemanager.rmcontainer.RMContainerImpl: container_1377704542759_0006_01_000002 Container Transitioned from ALLOCATED to ACQUIRED
2013-08-28 15:59:49,118 INFO org.apache.hadoop.yarn.server.resourcemanager.rmcontainer.RMContainerImpl: container_1377704542759_0006_01_000003 Container Transitioned from ALLOCATED to ACQUIRED
2013-08-28 15:59:49,118 INFO org.apache.hadoop.yarn.server.resourcemanager.rmcontainer.RMContainerImpl: container_1377704542759_0006_01_000004 Container Transitioned from ALLOCATED to ACQUIRED
2013-08-28 15:59:49,118 INFO org.apache.hadoop.yarn.server.resourcemanager.rmcontainer.RMContainerImpl: container_1377704542759_0006_01_000005 Container Transitioned from ALLOCATED to ACQUIRED
2013-08-28 15:59:49,118 INFO org.apache.hadoop.yarn.server.resourcemanager.rmcontainer.RMContainerImpl: container_1377704542759_0006_01_000006 Container Transitioned from ALLOCATED to ACQUIRED
2013-08-28 15:59:49,119 INFO org.apache.hadoop.yarn.server.resourcemanager.rmcontainer.RMContainerImpl: container_1377704542759_0006_01_000007 Container Transitioned from ALLOCATED to ACQUIRED
2013-08-28 15:59:49,119 INFO org.apache.hadoop.yarn.server.resourcemanager.rmcontainer.RMContainerImpl: container_1377704542759_0006_01_000008 Container Transitioned from ALLOCATED to ACQUIRED
2013-08-28 15:59:49,119 INFO org.apache.hadoop.yarn.server.resourcemanager.rmcontainer.RMContainerImpl: container_1377704542759_0006_01_000009 Container Transitioned from ALLOCATED to ACQUIRED
2013-08-28 15:59:49,119 INFO org.apache.hadoop.yarn.server.resourcemanager.rmcontainer.RMContainerImpl: container_1377704542759_0006_01_000010 Container Transitioned from ALLOCATED to ACQUIRED
2013-08-28 15:59:49,119 INFO org.apache.hadoop.yarn.server.resourcemanager.rmcontainer.RMContainerImpl: container_1377704542759_0006_01_000011 Container Transitioned from ALLOCATED to ACQUIRED
2013-08-28 15:59:49,119 INFO org.apache.hadoop.yarn.server.resourcemanager.rmcontainer.RMContainerImpl: container_1377704542759_0006_01_000012 Container Transitioned from ALLOCATED to ACQUIRED
2013-08-28 15:59:49,120 INFO org.apache.hadoop.yarn.server.resourcemanager.rmcontainer.RMContainerImpl: container_1377704542759_0006_01_000013 Container Transitioned from ALLOCATED to ACQUIRED
2013-08-28 15:59:49,609 INFO org.apache.hadoop.yarn.server.resourcemanager.rmcontainer.RMContainerImpl: container_1377704542759_0006_01_000008 Container Transitioned from ACQUIRED to RUNNING
2013-08-28 15:59:49,610 INFO org.apache.hadoop.yarn.server.resourcemanager.rmcontainer.RMContainerImpl: container_1377704542759_0006_01_000009 Container Transitioned from ACQUIRED to RUNNING
2013-08-28 15:59:49,611 INFO org.apache.hadoop.yarn.server.resourcemanager.rmcontainer.RMContainerImpl: container_1377704542759_0006_01_000010 Container Transitioned from ACQUIRED to RUNNING
2013-08-28 15:59:49,612 INFO org.apache.hadoop.yarn.server.resourcemanager.rmcontainer.RMContainerImpl: container_1377704542759_0006_01_000011 Container Transitioned from ACQUIRED to RUNNING
2013-08-28 15:59:49,613 INFO org.apache.hadoop.yarn.server.resourcemanager.rmcontainer.RMContainerImpl: container_1377704542759_0006_01_000012 Container Transitioned from ACQUIRED to RUNNING
2013-08-28 15:59:49,613 INFO org.apache.hadoop.yarn.server.resourcemanager.rmcontainer.RMContainerImpl: container_1377704542759_0006_01_000013 Container Transitioned from ACQUIRED to RUNNING
2013-08-28 15:59:49,734 INFO org.apache.hadoop.yarn.server.resourcemanager.rmcontainer.RMContainerImpl: container_1377704542759_0008_01_000002 Container Transitioned from ACQUIRED to RUNNING
2013-08-28 15:59:49,734 INFO org.apache.hadoop.yarn.server.resourcemanager.rmcontainer.RMContainerImpl: container_1377704542759_0008_01_000003 Container Transitioned from ACQUIRED to RUNNING
2013-08-28 15:59:49,735 INFO org.apache.hadoop.yarn.server.resourcemanager.rmcontainer.RMContainerImpl: container_1377704542759_0008_01_000004 Container Transitioned from ACQUIRED to RUNNING
2013-08-28 15:59:49,735 INFO org.apache.hadoop.yarn.server.resourcemanager.rmcontainer.RMContainerImpl: container_1377704542759_0008_01_000005 Container Transitioned from ACQUIRED to RUNNING
2013-08-28 15:59:49,736 INFO org.apache.hadoop.yarn.server.resourcemanager.rmcontainer.RMContainerImpl: container_1377704542759_0008_01_000006 Container Transitioned from ACQUIRED to RUNNING
2013-08-28 15:59:49,736 INFO org.apache.hadoop.yarn.server.resourcemanager.rmcontainer.RMContainerImpl: container_1377704542759_0008_01_000007 Container Transitioned from ACQUIRED to RUNNING
2013-08-28 15:59:49,736 INFO org.apache.hadoop.yarn.server.resourcemanager.rmcontainer.RMContainerImpl: container_1377704542759_0008_01_000008 Container Transitioned from ACQUIRED to RUNNING
2013-08-28 15:59:49,738 INFO org.apache.hadoop.yarn.server.resourcemanager.rmcontainer.RMContainerImpl: container_1377704542759_0008_01_000009 Container Transitioned from ACQUIRED to RUNNING
2013-08-28 15:59:49,853 INFO org.apache.hadoop.yarn.server.resourcemanager.rmcontainer.RMContainerImpl: container_1377704542759_0008_01_000010 Container Transitioned from ACQUIRED to RUNNING
2013-08-28 15:59:49,854 INFO org.apache.hadoop.yarn.server.resourcemanager.rmcontainer.RMContainerImpl: container_1377704542759_0008_01_000011 Container Transitioned from ACQUIRED to RUNNING
2013-08-28 15:59:49,854 INFO org.apache.hadoop.yarn.server.resourcemanager.rmcontainer.RMContainerImpl: container_1377704542759_0008_01_000012 Container Transitioned from ACQUIRED to RUNNING
2013-08-28 15:59:49,855 INFO org.apache.hadoop.yarn.server.resourcemanager.rmcontainer.RMContainerImpl: container_1377704542759_0008_01_000013 Container Transitioned from ACQUIRED to RUNNING
2013-08-28 15:59:49,855 INFO org.apache.hadoop.yarn.server.resourcemanager.rmcontainer.RMContainerImpl: container_1377704542759_0008_01_000014 Container Transitioned from ACQUIRED to RUNNING
2013-08-28 15:59:49,856 INFO org.apache.hadoop.yarn.server.resourcemanager.rmcontainer.RMContainerImpl: container_1377704542759_0008_01_000015 Container Transitioned from ACQUIRED to RUNNING
2013-08-28 15:59:49,921 INFO org.apache.hadoop.yarn.server.resourcemanager.rmcontainer.RMContainerImpl: container_1377704542759_0008_01_000016 Container Transitioned from ACQUIRED to RUNNING
2013-08-28 15:59:49,922 INFO org.apache.hadoop.yarn.server.resourcemanager.rmcontainer.RMContainerImpl: container_1377704542759_0008_01_000017 Container Transitioned from ACQUIRED to RUNNING
2013-08-28 15:59:49,922 INFO org.apache.hadoop.yarn.server.resourcemanager.rmcontainer.RMContainerImpl: container_1377704542759_0008_01_000018 Container Transitioned from ACQUIRED to RUNNING
2013-08-28 15:59:49,923 INFO org.apache.hadoop.yarn.server.resourcemanager.rmcontainer.RMContainerImpl: container_1377704542759_0008_01_000019 Container Transitioned from ACQUIRED to RUNNING
2013-08-28 15:59:49,924 INFO org.apache.hadoop.yarn.server.resourcemanager.rmcontainer.RMContainerImpl: container_1377704542759_0008_01_000020 Container Transitioned from ACQUIRED to RUNNING
2013-08-28 15:59:49,924 INFO org.apache.hadoop.yarn.server.resourcemanager.rmcontainer.RMContainerImpl: container_1377704542759_0008_01_000021 Container Transitioned from ACQUIRED to RUNNING
2013-08-28 15:59:50,001 INFO org.apache.hadoop.yarn.server.resourcemanager.rmcontainer.RMContainerImpl: container_1377704542759_0008_01_000022 Container Transitioned from ACQUIRED to RUNNING
2013-08-28 15:59:50,002 INFO org.apache.hadoop.yarn.server.resourcemanager.rmcontainer.RMContainerImpl: container_1377704542759_0008_01_000023 Container Transitioned from ACQUIRED to RUNNING
2013-08-28 15:59:50,003 INFO org.apache.hadoop.yarn.server.resourcemanager.rmcontainer.RMContainerImpl: container_1377704542759_0008_01_000024 Container Transitioned from ACQUIRED to RUNNING
2013-08-28 15:59:50,004 INFO org.apache.hadoop.yarn.server.resourcemanager.rmcontainer.RMContainerImpl: container_1377704542759_0008_01_000025 Container Transitioned from ACQUIRED to RUNNING
2013-08-28 15:59:50,004 INFO org.apache.hadoop.yarn.server.resourcemanager.rmcontainer.RMContainerImpl: container_1377704542759_0008_01_000026 Container Transitioned from ACQUIRED to RUNNING
2013-08-28 15:59:50,004 INFO org.apache.hadoop.yarn.server.resourcemanager.rmcontainer.RMContainerImpl: container_1377704542759_0008_01_000027 Container Transitioned from ACQUIRED to RUNNING
2013-08-28 15:59:50,155 INFO org.apache.hadoop.yarn.server.resourcemanager.rmcontainer.RMContainerImpl: container_1377704542759_0006_01_000002 Container Transitioned from ACQUIRED to RUNNING
2013-08-28 15:59:50,156 INFO org.apache.hadoop.yarn.server.resourcemanager.rmcontainer.RMContainerImpl: container_1377704542759_0006_01_000003 Container Transitioned from ACQUIRED to RUNNING
2013-08-28 15:59:50,156 INFO org.apache.hadoop.yarn.server.resourcemanager.rmcontainer.RMContainerImpl: container_1377704542759_0006_01_000004 Container Transitioned from ACQUIRED to RUNNING
2013-08-28 15:59:50,156 INFO org.apache.hadoop.yarn.server.resourcemanager.rmcontainer.RMContainerImpl: container_1377704542759_0006_01_000005 Container Transitioned from ACQUIRED to RUNNING
2013-08-28 15:59:50,156 INFO org.apache.hadoop.yarn.server.resourcemanager.rmcontainer.RMContainerImpl: container_1377704542759_0006_01_000006 Container Transitioned from ACQUIRED to RUNNING
2013-08-28 15:59:50,156 INFO org.apache.hadoop.yarn.server.resourcemanager.rmcontainer.RMContainerImpl: container_1377704542759_0006_01_000007 Container Transitioned from ACQUIRED to RUNNING
2013-08-28 16:00:10,853 INFO org.apache.hadoop.yarn.server.resourcemanager.rmcontainer.RMContainerImpl: container_1377704542759_0008_01_000017 Container Transitioned from RUNNING to COMPLETED
2013-08-28 16:00:10,853 INFO org.apache.hadoop.yarn.server.resourcemanager.scheduler.common.fica.FiCaSchedulerApp: Completed container: container_1377704542759_0008_01_000017 in state: COMPLETED event:FINISHED
2013-08-28 16:00:10,853 INFO org.apache.hadoop.yarn.server.resourcemanager.RMAuditLogger: USER=ubuntu	OPERATION=AM Released Container	TARGET=SchedulerApp	RESULT=SUCCESS	APPID=application_1377704542759_0008	CONTAINERID=container_1377704542759_0008_01_000017
2013-08-28 16:00:10,854 INFO org.apache.hadoop.yarn.server.resourcemanager.scheduler.common.fica.FiCaSchedulerNode: Released container container_1377704542759_0008_01_000017 of capacity <memory:1024, vCores:1> on host hadoop-16-4:52495, which currently has 6 containers, <memory:7168, vCores:6> used and <memory:1024, vCores:10> available, release resources=true
2013-08-28 16:00:10,854 INFO org.apache.hadoop.yarn.server.resourcemanager.scheduler.capacity.LeafQueue: default used=<memory:48128, vCores:42> numContainers=42 user=ubuntu user-resources=<memory:48128, vCores:42>
2013-08-28 16:00:10,856 INFO org.apache.hadoop.yarn.server.resourcemanager.scheduler.capacity.LeafQueue: completedContainer container=Container: [ContainerId: container_1377704542759_0008_01_000017, NodeId: hadoop-16-4:52495, NodeHttpAddress: hadoop-16-4:8042, Resource: <memory:1024, vCores:1>, Priority: 20, State: NEW, Token: null, Status: container_id {, app_attempt_id {, application_id {, id: 8, cluster_timestamp: 1377704542759, }, attemptId: 1, }, id: 17, }, state: C_COMPLETE, diagnostics: "", exit_status: 0, ] resource=<memory:1024, vCores:1> queue=default: capacity=1.0, absoluteCapacity=1.0, usedResources=<memory:48128, vCores:42>usedCapacity=0.9791667, absoluteUsedCapacity=0.9791667, numApps=5, numContainers=42 usedCapacity=0.9791667 absoluteUsedCapacity=0.9791667 used=<memory:48128, vCores:42> cluster=<memory:49152, vCores:96>
2013-08-28 16:00:10,857 INFO org.apache.hadoop.yarn.server.resourcemanager.scheduler.capacity.ParentQueue: completedContainer queue=root usedCapacity=0.9791667 absoluteUsedCapacity=0.9791667 used=<memory:48128, vCores:42> cluster=<memory:49152, vCores:96>
2013-08-28 16:00:10,857 INFO org.apache.hadoop.yarn.server.resourcemanager.scheduler.capacity.CapacityScheduler: Application appattempt_1377704542759_0008_000001 released container container_1377704542759_0008_01_000017 on node: host: hadoop-16-4:52495 #containers=6 available=1024 used=7168 with event: FINISHED
2013-08-28 16:00:10,857 INFO org.apache.hadoop.yarn.server.resourcemanager.rmcontainer.RMContainerImpl: container_1377704542759_0006_01_000014 Container Transitioned from NEW to ALLOCATED
2013-08-28 16:00:10,857 INFO org.apache.hadoop.yarn.server.resourcemanager.RMAuditLogger: USER=ubuntu	OPERATION=AM Allocated Container	TARGET=SchedulerApp	RESULT=SUCCESS	APPID=application_1377704542759_0006	CONTAINERID=container_1377704542759_0006_01_000014
2013-08-28 16:00:10,857 INFO org.apache.hadoop.yarn.server.resourcemanager.scheduler.common.fica.FiCaSchedulerNode: Assigned container container_1377704542759_0006_01_000014 of capacity <memory:1024, vCores:1> on host hadoop-16-4:52495, which currently has 7 containers, <memory:8192, vCores:7> used and <memory:0, vCores:9> available
2013-08-28 16:00:10,858 INFO org.apache.hadoop.yarn.server.resourcemanager.scheduler.capacity.LeafQueue: assignedContainer application=application_1377704542759_0006 container=Container: [ContainerId: container_1377704542759_0006_01_000014, NodeId: hadoop-16-4:52495, NodeHttpAddress: hadoop-16-4:8042, Resource: <memory:1024, vCores:1>, Priority: 20, State: NEW, Token: null, Status: container_id {, app_attempt_id {, application_id {, id: 6, cluster_timestamp: 1377704542759, }, attemptId: 1, }, id: 14, }, state: C_NEW, ] containerId=container_1377704542759_0006_01_000014 queue=default: capacity=1.0, absoluteCapacity=1.0, usedResources=<memory:48128, vCores:42>usedCapacity=0.9791667, absoluteUsedCapacity=0.9791667, numApps=5, numContainers=42 usedCapacity=0.9791667 absoluteUsedCapacity=0.9791667 used=<memory:48128, vCores:42> cluster=<memory:49152, vCores:96>
2013-08-28 16:00:10,858 INFO org.apache.hadoop.yarn.server.resourcemanager.scheduler.capacity.ParentQueue: Re-sorting queues since queue: root.default stats: default: capacity=1.0, absoluteCapacity=1.0, usedResources=<memory:49152, vCores:43>usedCapacity=1.0, absoluteUsedCapacity=1.0, numApps=5, numContainers=43
2013-08-28 16:00:10,859 INFO org.apache.hadoop.yarn.server.resourcemanager.scheduler.capacity.ParentQueue: assignedContainer queue=root usedCapacity=1.0 absoluteUsedCapacity=1.0 used=<memory:49152, vCores:43> cluster=<memory:49152, vCores:96>
2013-08-28 16:00:10,940 INFO org.apache.hadoop.yarn.server.resourcemanager.rmcontainer.RMContainerImpl: container_1377704542759_0006_01_000014 Container Transitioned from ALLOCATED to ACQUIRED
2013-08-28 16:00:12,140 INFO org.apache.hadoop.yarn.server.resourcemanager.rmcontainer.RMContainerImpl: container_1377704542759_0006_01_000014 Container Transitioned from ACQUIRED to RUNNING
2013-08-28 16:00:12,259 INFO org.apache.hadoop.yarn.server.resourcemanager.rmcontainer.RMContainerImpl: container_1377704542759_0006_01_000006 Container Transitioned from RUNNING to COMPLETED
2013-08-28 16:00:12,259 INFO org.apache.hadoop.yarn.server.resourcemanager.scheduler.common.fica.FiCaSchedulerApp: Completed container: container_1377704542759_0006_01_000006 in state: COMPLETED event:FINISHED
2013-08-28 16:00:12,260 INFO org.apache.hadoop.yarn.server.resourcemanager.RMAuditLogger: USER=ubuntu	OPERATION=AM Released Container	TARGET=SchedulerApp	RESULT=SUCCESS	APPID=application_1377704542759_0006	CONTAINERID=container_1377704542759_0006_01_000006
2013-08-28 16:00:12,260 INFO org.apache.hadoop.yarn.server.resourcemanager.scheduler.common.fica.FiCaSchedulerNode: Released container container_1377704542759_0006_01_000006 of capacity <memory:1024, vCores:1> on host hadoop-16-6:36337, which currently has 6 containers, <memory:7168, vCores:6> used and <memory:1024, vCores:10> available, release resources=true
2013-08-28 16:00:12,260 INFO org.apache.hadoop.yarn.server.resourcemanager.scheduler.capacity.LeafQueue: default used=<memory:48128, vCores:42> numContainers=42 user=ubuntu user-resources=<memory:48128, vCores:42>
2013-08-28 16:00:12,261 INFO org.apache.hadoop.yarn.server.resourcemanager.scheduler.capacity.LeafQueue: completedContainer container=Container: [ContainerId: container_1377704542759_0006_01_000006, NodeId: hadoop-16-6:36337, NodeHttpAddress: hadoop-16-6:8042, Resource: <memory:1024, vCores:1>, Priority: 20, State: NEW, Token: null, Status: container_id {, app_attempt_id {, application_id {, id: 6, cluster_timestamp: 1377704542759, }, attemptId: 1, }, id: 6, }, state: C_COMPLETE, diagnostics: "", exit_status: 0, ] resource=<memory:1024, vCores:1> queue=default: capacity=1.0, absoluteCapacity=1.0, usedResources=<memory:48128, vCores:42>usedCapacity=0.9791667, absoluteUsedCapacity=0.9791667, numApps=5, numContainers=42 usedCapacity=0.9791667 absoluteUsedCapacity=0.9791667 used=<memory:48128, vCores:42> cluster=<memory:49152, vCores:96>
2013-08-28 16:00:12,261 INFO org.apache.hadoop.yarn.server.resourcemanager.scheduler.capacity.ParentQueue: completedContainer queue=root usedCapacity=0.9791667 absoluteUsedCapacity=0.9791667 used=<memory:48128, vCores:42> cluster=<memory:49152, vCores:96>
2013-08-28 16:00:12,261 INFO org.apache.hadoop.yarn.server.resourcemanager.scheduler.capacity.CapacityScheduler: Application appattempt_1377704542759_0006_000001 released container container_1377704542759_0006_01_000006 on node: host: hadoop-16-6:36337 #containers=6 available=1024 used=7168 with event: FINISHED
2013-08-28 16:00:12,262 INFO org.apache.hadoop.yarn.server.resourcemanager.rmcontainer.RMContainerImpl: container_1377704542759_0006_01_000015 Container Transitioned from NEW to ALLOCATED
2013-08-28 16:00:12,262 INFO org.apache.hadoop.yarn.server.resourcemanager.RMAuditLogger: USER=ubuntu	OPERATION=AM Allocated Container	TARGET=SchedulerApp	RESULT=SUCCESS	APPID=application_1377704542759_0006	CONTAINERID=container_1377704542759_0006_01_000015
2013-08-28 16:00:12,262 INFO org.apache.hadoop.yarn.server.resourcemanager.scheduler.common.fica.FiCaSchedulerNode: Assigned container container_1377704542759_0006_01_000015 of capacity <memory:1024, vCores:1> on host hadoop-16-6:36337, which currently has 7 containers, <memory:8192, vCores:7> used and <memory:0, vCores:9> available
2013-08-28 16:00:12,263 INFO org.apache.hadoop.yarn.server.resourcemanager.scheduler.capacity.LeafQueue: assignedContainer application=application_1377704542759_0006 container=Container: [ContainerId: container_1377704542759_0006_01_000015, NodeId: hadoop-16-6:36337, NodeHttpAddress: hadoop-16-6:8042, Resource: <memory:1024, vCores:1>, Priority: 20, State: NEW, Token: null, Status: container_id {, app_attempt_id {, application_id {, id: 6, cluster_timestamp: 1377704542759, }, attemptId: 1, }, id: 15, }, state: C_NEW, ] containerId=container_1377704542759_0006_01_000015 queue=default: capacity=1.0, absoluteCapacity=1.0, usedResources=<memory:48128, vCores:42>usedCapacity=0.9791667, absoluteUsedCapacity=0.9791667, numApps=5, numContainers=42 usedCapacity=0.9791667 absoluteUsedCapacity=0.9791667 used=<memory:48128, vCores:42> cluster=<memory:49152, vCores:96>
2013-08-28 16:00:12,264 INFO org.apache.hadoop.yarn.server.resourcemanager.scheduler.capacity.ParentQueue: Re-sorting queues since queue: root.default stats: default: capacity=1.0, absoluteCapacity=1.0, usedResources=<memory:49152, vCores:43>usedCapacity=1.0, absoluteUsedCapacity=1.0, numApps=5, numContainers=43
2013-08-28 16:00:12,264 INFO org.apache.hadoop.yarn.server.resourcemanager.scheduler.capacity.ParentQueue: assignedContainer queue=root usedCapacity=1.0 absoluteUsedCapacity=1.0 used=<memory:49152, vCores:43> cluster=<memory:49152, vCores:96>
2013-08-28 16:00:12,969 INFO org.apache.hadoop.yarn.server.resourcemanager.rmcontainer.RMContainerImpl: container_1377704542759_0006_01_000015 Container Transitioned from ALLOCATED to ACQUIRED
2013-08-28 16:00:13,181 INFO org.apache.hadoop.yarn.server.resourcemanager.rmcontainer.RMContainerImpl: container_1377704542759_0006_01_000015 Container Transitioned from ACQUIRED to RUNNING
2013-08-28 16:00:13,365 INFO org.apache.hadoop.yarn.server.resourcemanager.rmcontainer.RMContainerImpl: container_1377704542759_0008_01_000010 Container Transitioned from RUNNING to COMPLETED
2013-08-28 16:00:13,365 INFO org.apache.hadoop.yarn.server.resourcemanager.scheduler.common.fica.FiCaSchedulerApp: Completed container: container_1377704542759_0008_01_000010 in state: COMPLETED event:FINISHED
2013-08-28 16:00:13,365 INFO org.apache.hadoop.yarn.server.resourcemanager.RMAuditLogger: USER=ubuntu	OPERATION=AM Released Container	TARGET=SchedulerApp	RESULT=SUCCESS	APPID=application_1377704542759_0008	CONTAINERID=container_1377704542759_0008_01_000010
2013-08-28 16:00:13,365 INFO org.apache.hadoop.yarn.server.resourcemanager.scheduler.common.fica.FiCaSchedulerNode: Released container container_1377704542759_0008_01_000010 of capacity <memory:1024, vCores:1> on host hadoop-16-3:41896, which currently has 6 containers, <memory:7168, vCores:6> used and <memory:1024, vCores:10> available, release resources=true
2013-08-28 16:00:13,365 INFO org.apache.hadoop.yarn.server.resourcemanager.scheduler.capacity.LeafQueue: default used=<memory:48128, vCores:42> numContainers=42 user=ubuntu user-resources=<memory:48128, vCores:42>
2013-08-28 16:00:13,367 INFO org.apache.hadoop.yarn.server.resourcemanager.scheduler.capacity.LeafQueue: completedContainer container=Container: [ContainerId: container_1377704542759_0008_01_000010, NodeId: hadoop-16-3:41896, NodeHttpAddress: hadoop-16-3:8042, Resource: <memory:1024, vCores:1>, Priority: 20, State: NEW, Token: null, Status: container_id {, app_attempt_id {, application_id {, id: 8, cluster_timestamp: 1377704542759, }, attemptId: 1, }, id: 10, }, state: C_COMPLETE, diagnostics: "Container killed by the ApplicationMaster.\n", exit_status: 0, ] resource=<memory:1024, vCores:1> queue=default: capacity=1.0, absoluteCapacity=1.0, usedResources=<memory:48128, vCores:42>usedCapacity=0.9791667, absoluteUsedCapacity=0.9791667, numApps=5, numContainers=42 usedCapacity=0.9791667 absoluteUsedCapacity=0.9791667 used=<memory:48128, vCores:42> cluster=<memory:49152, vCores:96>
2013-08-28 16:00:13,367 INFO org.apache.hadoop.yarn.server.resourcemanager.scheduler.capacity.ParentQueue: completedContainer queue=root usedCapacity=0.9791667 absoluteUsedCapacity=0.9791667 used=<memory:48128, vCores:42> cluster=<memory:49152, vCores:96>
2013-08-28 16:00:13,367 INFO org.apache.hadoop.yarn.server.resourcemanager.scheduler.capacity.CapacityScheduler: Application appattempt_1377704542759_0008_000001 released container container_1377704542759_0008_01_000010 on node: host: hadoop-16-3:41896 #containers=6 available=1024 used=7168 with event: FINISHED
2013-08-28 16:00:13,368 INFO org.apache.hadoop.yarn.server.resourcemanager.rmcontainer.RMContainerImpl: container_1377704542759_0006_01_000016 Container Transitioned from NEW to ALLOCATED
2013-08-28 16:00:13,368 INFO org.apache.hadoop.yarn.server.resourcemanager.RMAuditLogger: USER=ubuntu	OPERATION=AM Allocated Container	TARGET=SchedulerApp	RESULT=SUCCESS	APPID=application_1377704542759_0006	CONTAINERID=container_1377704542759_0006_01_000016
2013-08-28 16:00:13,368 INFO org.apache.hadoop.yarn.server.resourcemanager.scheduler.common.fica.FiCaSchedulerNode: Assigned container container_1377704542759_0006_01_000016 of capacity <memory:1024, vCores:1> on host hadoop-16-3:41896, which currently has 7 containers, <memory:8192, vCores:7> used and <memory:0, vCores:9> available
2013-08-28 16:00:13,369 INFO org.apache.hadoop.yarn.server.resourcemanager.scheduler.capacity.LeafQueue: assignedContainer application=application_1377704542759_0006 container=Container: [ContainerId: container_1377704542759_0006_01_000016, NodeId: hadoop-16-3:41896, NodeHttpAddress: hadoop-16-3:8042, Resource: <memory:1024, vCores:1>, Priority: 20, State: NEW, Token: null, Status: container_id {, app_attempt_id {, application_id {, id: 6, cluster_timestamp: 1377704542759, }, attemptId: 1, }, id: 16, }, state: C_NEW, ] containerId=container_1377704542759_0006_01_000016 queue=default: capacity=1.0, absoluteCapacity=1.0, usedResources=<memory:48128, vCores:42>usedCapacity=0.9791667, absoluteUsedCapacity=0.9791667, numApps=5, numContainers=42 usedCapacity=0.9791667 absoluteUsedCapacity=0.9791667 used=<memory:48128, vCores:42> cluster=<memory:49152, vCores:96>
2013-08-28 16:00:13,369 INFO org.apache.hadoop.yarn.server.resourcemanager.scheduler.capacity.ParentQueue: Re-sorting queues since queue: root.default stats: default: capacity=1.0, absoluteCapacity=1.0, usedResources=<memory:49152, vCores:43>usedCapacity=1.0, absoluteUsedCapacity=1.0, numApps=5, numContainers=43
2013-08-28 16:00:13,370 INFO org.apache.hadoop.yarn.server.resourcemanager.scheduler.capacity.ParentQueue: assignedContainer queue=root usedCapacity=1.0 absoluteUsedCapacity=1.0 used=<memory:49152, vCores:43> cluster=<memory:49152, vCores:96>
2013-08-28 16:00:14,042 INFO org.apache.hadoop.yarn.server.resourcemanager.rmcontainer.RMContainerImpl: container_1377704542759_0006_01_000016 Container Transitioned from ALLOCATED to ACQUIRED
2013-08-28 16:00:14,099 INFO org.apache.hadoop.yarn.server.resourcemanager.rmcontainer.RMContainerImpl: container_1377704542759_0006_01_000016 Container Transitioned from ACQUIRED to RUNNING
2013-08-28 16:00:14,276 INFO org.apache.hadoop.yarn.server.resourcemanager.rmcontainer.RMContainerImpl: container_1377704542759_0006_01_000007 Container Transitioned from RUNNING to COMPLETED
2013-08-28 16:00:14,276 INFO org.apache.hadoop.yarn.server.resourcemanager.scheduler.common.fica.FiCaSchedulerApp: Completed container: container_1377704542759_0006_01_000007 in state: COMPLETED event:FINISHED
2013-08-28 16:00:14,277 INFO org.apache.hadoop.yarn.server.resourcemanager.RMAuditLogger: USER=ubuntu	OPERATION=AM Released Container	TARGET=SchedulerApp	RESULT=SUCCESS	APPID=application_1377704542759_0006	CONTAINERID=container_1377704542759_0006_01_000007
2013-08-28 16:00:14,277 INFO org.apache.hadoop.yarn.server.resourcemanager.scheduler.common.fica.FiCaSchedulerNode: Released container container_1377704542759_0006_01_000007 of capacity <memory:1024, vCores:1> on host hadoop-16-6:36337, which currently has 6 containers, <memory:7168, vCores:6> used and <memory:1024, vCores:10> available, release resources=true
2013-08-28 16:00:14,277 INFO org.apache.hadoop.yarn.server.resourcemanager.scheduler.capacity.LeafQueue: default used=<memory:48128, vCores:42> numContainers=42 user=ubuntu user-resources=<memory:48128, vCores:42>
2013-08-28 16:00:14,278 INFO org.apache.hadoop.yarn.server.resourcemanager.scheduler.capacity.LeafQueue: completedContainer container=Container: [ContainerId: container_1377704542759_0006_01_000007, NodeId: hadoop-16-6:36337, NodeHttpAddress: hadoop-16-6:8042, Resource: <memory:1024, vCores:1>, Priority: 20, State: NEW, Token: null, Status: container_id {, app_attempt_id {, application_id {, id: 6, cluster_timestamp: 1377704542759, }, attemptId: 1, }, id: 7, }, state: C_COMPLETE, diagnostics: "Container killed by the ApplicationMaster.\n\n", exit_status: 143, ] resource=<memory:1024, vCores:1> queue=default: capacity=1.0, absoluteCapacity=1.0, usedResources=<memory:48128, vCores:42>usedCapacity=0.9791667, absoluteUsedCapacity=0.9791667, numApps=5, numContainers=42 usedCapacity=0.9791667 absoluteUsedCapacity=0.9791667 used=<memory:48128, vCores:42> cluster=<memory:49152, vCores:96>
2013-08-28 16:00:14,278 INFO org.apache.hadoop.yarn.server.resourcemanager.scheduler.capacity.ParentQueue: completedContainer queue=root usedCapacity=0.9791667 absoluteUsedCapacity=0.9791667 used=<memory:48128, vCores:42> cluster=<memory:49152, vCores:96>
2013-08-28 16:00:14,279 INFO org.apache.hadoop.yarn.server.resourcemanager.scheduler.capacity.CapacityScheduler: Application appattempt_1377704542759_0006_000001 released container container_1377704542759_0006_01_000007 on node: host: hadoop-16-6:36337 #containers=6 available=1024 used=7168 with event: FINISHED
2013-08-28 16:00:14,279 INFO org.apache.hadoop.yarn.server.resourcemanager.rmcontainer.RMContainerImpl: container_1377704542759_0006_01_000017 Container Transitioned from NEW to ALLOCATED
2013-08-28 16:00:14,279 INFO org.apache.hadoop.yarn.server.resourcemanager.RMAuditLogger: USER=ubuntu	OPERATION=AM Allocated Container	TARGET=SchedulerApp	RESULT=SUCCESS	APPID=application_1377704542759_0006	CONTAINERID=container_1377704542759_0006_01_000017
2013-08-28 16:00:14,279 INFO org.apache.hadoop.yarn.server.resourcemanager.scheduler.common.fica.FiCaSchedulerNode: Assigned container container_1377704542759_0006_01_000017 of capacity <memory:1024, vCores:1> on host hadoop-16-6:36337, which currently has 7 containers, <memory:8192, vCores:7> used and <memory:0, vCores:9> available
2013-08-28 16:00:14,280 INFO org.apache.hadoop.yarn.server.resourcemanager.scheduler.capacity.LeafQueue: assignedContainer application=application_1377704542759_0006 container=Container: [ContainerId: container_1377704542759_0006_01_000017, NodeId: hadoop-16-6:36337, NodeHttpAddress: hadoop-16-6:8042, Resource: <memory:1024, vCores:1>, Priority: 20, State: NEW, Token: null, Status: container_id {, app_attempt_id {, application_id {, id: 6, cluster_timestamp: 1377704542759, }, attemptId: 1, }, id: 17, }, state: C_NEW, ] containerId=container_1377704542759_0006_01_000017 queue=default: capacity=1.0, absoluteCapacity=1.0, usedResources=<memory:48128, vCores:42>usedCapacity=0.9791667, absoluteUsedCapacity=0.9791667, numApps=5, numContainers=42 usedCapacity=0.9791667 absoluteUsedCapacity=0.9791667 used=<memory:48128, vCores:42> cluster=<memory:49152, vCores:96>
2013-08-28 16:00:14,281 INFO org.apache.hadoop.yarn.server.resourcemanager.scheduler.capacity.ParentQueue: Re-sorting queues since queue: root.default stats: default: capacity=1.0, absoluteCapacity=1.0, usedResources=<memory:49152, vCores:43>usedCapacity=1.0, absoluteUsedCapacity=1.0, numApps=5, numContainers=43
2013-08-28 16:00:14,281 INFO org.apache.hadoop.yarn.server.resourcemanager.scheduler.capacity.ParentQueue: assignedContainer queue=root usedCapacity=1.0 absoluteUsedCapacity=1.0 used=<memory:49152, vCores:43> cluster=<memory:49152, vCores:96>
2013-08-28 16:00:14,803 INFO org.apache.hadoop.yarn.server.resourcemanager.rmcontainer.RMContainerImpl: container_1377704542759_0006_01_000013 Container Transitioned from RUNNING to COMPLETED
2013-08-28 16:00:14,803 INFO org.apache.hadoop.yarn.server.resourcemanager.scheduler.common.fica.FiCaSchedulerApp: Completed container: container_1377704542759_0006_01_000013 in state: COMPLETED event:FINISHED
2013-08-28 16:00:14,804 INFO org.apache.hadoop.yarn.server.resourcemanager.RMAuditLogger: USER=ubuntu	OPERATION=AM Released Container	TARGET=SchedulerApp	RESULT=SUCCESS	APPID=application_1377704542759_0006	CONTAINERID=container_1377704542759_0006_01_000013
2013-08-28 16:00:14,804 INFO org.apache.hadoop.yarn.server.resourcemanager.scheduler.common.fica.FiCaSchedulerNode: Released container container_1377704542759_0006_01_000013 of capacity <memory:1024, vCores:1> on host hadoop-16-5:57886, which currently has 6 containers, <memory:7168, vCores:6> used and <memory:1024, vCores:10> available, release resources=true
2013-08-28 16:00:14,804 INFO org.apache.hadoop.yarn.server.resourcemanager.scheduler.capacity.LeafQueue: default used=<memory:48128, vCores:42> numContainers=42 user=ubuntu user-resources=<memory:48128, vCores:42>
2013-08-28 16:00:14,805 INFO org.apache.hadoop.yarn.server.resourcemanager.scheduler.capacity.LeafQueue: completedContainer container=Container: [ContainerId: container_1377704542759_0006_01_000013, NodeId: hadoop-16-5:57886, NodeHttpAddress: hadoop-16-5:8042, Resource: <memory:1024, vCores:1>, Priority: 20, State: NEW, Token: null, Status: container_id {, app_attempt_id {, application_id {, id: 6, cluster_timestamp: 1377704542759, }, attemptId: 1, }, id: 13, }, state: C_COMPLETE, diagnostics: "Container killed by the ApplicationMaster.\n", exit_status: 0, ] resource=<memory:1024, vCores:1> queue=default: capacity=1.0, absoluteCapacity=1.0, usedResources=<memory:48128, vCores:42>usedCapacity=0.9791667, absoluteUsedCapacity=0.9791667, numApps=5, numContainers=42 usedCapacity=0.9791667 absoluteUsedCapacity=0.9791667 used=<memory:48128, vCores:42> cluster=<memory:49152, vCores:96>
2013-08-28 16:00:14,805 INFO org.apache.hadoop.yarn.server.resourcemanager.scheduler.capacity.ParentQueue: completedContainer queue=root usedCapacity=0.9791667 absoluteUsedCapacity=0.9791667 used=<memory:48128, vCores:42> cluster=<memory:49152, vCores:96>
2013-08-28 16:00:14,806 INFO org.apache.hadoop.yarn.server.resourcemanager.scheduler.capacity.CapacityScheduler: Application appattempt_1377704542759_0006_000001 released container container_1377704542759_0006_01_000013 on node: host: hadoop-16-5:57886 #containers=6 available=1024 used=7168 with event: FINISHED
2013-08-28 16:00:14,806 INFO org.apache.hadoop.yarn.server.resourcemanager.rmcontainer.RMContainerImpl: container_1377704542759_0006_01_000018 Container Transitioned from NEW to ALLOCATED
2013-08-28 16:00:14,806 INFO org.apache.hadoop.yarn.server.resourcemanager.RMAuditLogger: USER=ubuntu	OPERATION=AM Allocated Container	TARGET=SchedulerApp	RESULT=SUCCESS	APPID=application_1377704542759_0006	CONTAINERID=container_1377704542759_0006_01_000018
2013-08-28 16:00:14,806 INFO org.apache.hadoop.yarn.server.resourcemanager.scheduler.common.fica.FiCaSchedulerNode: Assigned container container_1377704542759_0006_01_000018 of capacity <memory:1024, vCores:1> on host hadoop-16-5:57886, which currently has 7 containers, <memory:8192, vCores:7> used and <memory:0, vCores:9> available
2013-08-28 16:00:14,808 INFO org.apache.hadoop.yarn.server.resourcemanager.scheduler.capacity.LeafQueue: assignedContainer application=application_1377704542759_0006 container=Container: [ContainerId: container_1377704542759_0006_01_000018, NodeId: hadoop-16-5:57886, NodeHttpAddress: hadoop-16-5:8042, Resource: <memory:1024, vCores:1>, Priority: 20, State: NEW, Token: null, Status: container_id {, app_attempt_id {, application_id {, id: 6, cluster_timestamp: 1377704542759, }, attemptId: 1, }, id: 18, }, state: C_NEW, ] containerId=container_1377704542759_0006_01_000018 queue=default: capacity=1.0, absoluteCapacity=1.0, usedResources=<memory:48128, vCores:42>usedCapacity=0.9791667, absoluteUsedCapacity=0.9791667, numApps=5, numContainers=42 usedCapacity=0.9791667 absoluteUsedCapacity=0.9791667 used=<memory:48128, vCores:42> cluster=<memory:49152, vCores:96>
2013-08-28 16:00:14,808 INFO org.apache.hadoop.yarn.server.resourcemanager.scheduler.capacity.ParentQueue: Re-sorting queues since queue: root.default stats: default: capacity=1.0, absoluteCapacity=1.0, usedResources=<memory:49152, vCores:43>usedCapacity=1.0, absoluteUsedCapacity=1.0, numApps=5, numContainers=43
2013-08-28 16:00:14,808 INFO org.apache.hadoop.yarn.server.resourcemanager.scheduler.capacity.ParentQueue: assignedContainer queue=root usedCapacity=1.0 absoluteUsedCapacity=1.0 used=<memory:49152, vCores:43> cluster=<memory:49152, vCores:96>
2013-08-28 16:00:15,053 INFO org.apache.hadoop.yarn.server.resourcemanager.rmcontainer.RMContainerImpl: container_1377704542759_0006_01_000017 Container Transitioned from ALLOCATED to ACQUIRED
2013-08-28 16:00:15,054 INFO org.apache.hadoop.yarn.server.resourcemanager.rmcontainer.RMContainerImpl: container_1377704542759_0006_01_000018 Container Transitioned from ALLOCATED to ACQUIRED
2013-08-28 16:00:15,513 INFO org.apache.hadoop.yarn.server.resourcemanager.rmcontainer.RMContainerImpl: container_1377704542759_0008_01_000011 Container Transitioned from RUNNING to COMPLETED
2013-08-28 16:00:15,513 INFO org.apache.hadoop.yarn.server.resourcemanager.scheduler.common.fica.FiCaSchedulerApp: Completed container: container_1377704542759_0008_01_000011 in state: COMPLETED event:FINISHED
2013-08-28 16:00:15,513 INFO org.apache.hadoop.yarn.server.resourcemanager.RMAuditLogger: USER=ubuntu	OPERATION=AM Released Container	TARGET=SchedulerApp	RESULT=SUCCESS	APPID=application_1377704542759_0008	CONTAINERID=container_1377704542759_0008_01_000011
2013-08-28 16:00:15,514 INFO org.apache.hadoop.yarn.server.resourcemanager.scheduler.common.fica.FiCaSchedulerNode: Released container container_1377704542759_0008_01_000011 of capacity <memory:1024, vCores:1> on host hadoop-16-3:41896, which currently has 6 containers, <memory:7168, vCores:6> used and <memory:1024, vCores:10> available, release resources=true
2013-08-28 16:00:15,514 INFO org.apache.hadoop.yarn.server.resourcemanager.scheduler.capacity.LeafQueue: default used=<memory:48128, vCores:42> numContainers=42 user=ubuntu user-resources=<memory:48128, vCores:42>
2013-08-28 16:00:15,515 INFO org.apache.hadoop.yarn.server.resourcemanager.scheduler.capacity.LeafQueue: completedContainer container=Container: [ContainerId: container_1377704542759_0008_01_000011, NodeId: hadoop-16-3:41896, NodeHttpAddress: hadoop-16-3:8042, Resource: <memory:1024, vCores:1>, Priority: 20, State: NEW, Token: null, Status: container_id {, app_attempt_id {, application_id {, id: 8, cluster_timestamp: 1377704542759, }, attemptId: 1, }, id: 11, }, state: C_COMPLETE, diagnostics: "Container killed by the ApplicationMaster.\n\n", exit_status: 143, ] resource=<memory:1024, vCores:1> queue=default: capacity=1.0, absoluteCapacity=1.0, usedResources=<memory:48128, vCores:42>usedCapacity=0.9791667, absoluteUsedCapacity=0.9791667, numApps=5, numContainers=42 usedCapacity=0.9791667 absoluteUsedCapacity=0.9791667 used=<memory:48128, vCores:42> cluster=<memory:49152, vCores:96>
2013-08-28 16:00:15,516 INFO org.apache.hadoop.yarn.server.resourcemanager.scheduler.capacity.ParentQueue: completedContainer queue=root usedCapacity=0.9791667 absoluteUsedCapacity=0.9791667 used=<memory:48128, vCores:42> cluster=<memory:49152, vCores:96>
2013-08-28 16:00:15,516 INFO org.apache.hadoop.yarn.server.resourcemanager.scheduler.capacity.CapacityScheduler: Application appattempt_1377704542759_0008_000001 released container container_1377704542759_0008_01_000011 on node: host: hadoop-16-3:41896 #containers=6 available=1024 used=7168 with event: FINISHED
2013-08-28 16:00:15,516 INFO org.apache.hadoop.yarn.server.resourcemanager.rmcontainer.RMContainerImpl: container_1377704542759_0006_01_000019 Container Transitioned from NEW to ALLOCATED
2013-08-28 16:00:15,516 INFO org.apache.hadoop.yarn.server.resourcemanager.RMAuditLogger: USER=ubuntu	OPERATION=AM Allocated Container	TARGET=SchedulerApp	RESULT=SUCCESS	APPID=application_1377704542759_0006	CONTAINERID=container_1377704542759_0006_01_000019
2013-08-28 16:00:15,517 INFO org.apache.hadoop.yarn.server.resourcemanager.scheduler.common.fica.FiCaSchedulerNode: Assigned container container_1377704542759_0006_01_000019 of capacity <memory:1024, vCores:1> on host hadoop-16-3:41896, which currently has 7 containers, <memory:8192, vCores:7> used and <memory:0, vCores:9> available
2013-08-28 16:00:15,518 INFO org.apache.hadoop.yarn.server.resourcemanager.scheduler.capacity.LeafQueue: assignedContainer application=application_1377704542759_0006 container=Container: [ContainerId: container_1377704542759_0006_01_000019, NodeId: hadoop-16-3:41896, NodeHttpAddress: hadoop-16-3:8042, Resource: <memory:1024, vCores:1>, Priority: 10, State: NEW, Token: null, Status: container_id {, app_attempt_id {, application_id {, id: 6, cluster_timestamp: 1377704542759, }, attemptId: 1, }, id: 19, }, state: C_NEW, ] containerId=container_1377704542759_0006_01_000019 queue=default: capacity=1.0, absoluteCapacity=1.0, usedResources=<memory:48128, vCores:42>usedCapacity=0.9791667, absoluteUsedCapacity=0.9791667, numApps=5, numContainers=42 usedCapacity=0.9791667 absoluteUsedCapacity=0.9791667 used=<memory:48128, vCores:42> cluster=<memory:49152, vCores:96>
2013-08-28 16:00:15,518 INFO org.apache.hadoop.yarn.server.resourcemanager.scheduler.capacity.ParentQueue: Re-sorting queues since queue: root.default stats: default: capacity=1.0, absoluteCapacity=1.0, usedResources=<memory:49152, vCores:43>usedCapacity=1.0, absoluteUsedCapacity=1.0, numApps=5, numContainers=43
2013-08-28 16:00:15,518 INFO org.apache.hadoop.yarn.server.resourcemanager.scheduler.capacity.ParentQueue: assignedContainer queue=root usedCapacity=1.0 absoluteUsedCapacity=1.0 used=<memory:49152, vCores:43> cluster=<memory:49152, vCores:96>
2013-08-28 16:00:16,392 INFO org.apache.hadoop.yarn.server.resourcemanager.rmcontainer.RMContainerImpl: container_1377704542759_0006_01_000017 Container Transitioned from ACQUIRED to RUNNING
2013-08-28 16:00:16,634 INFO org.apache.hadoop.yarn.server.resourcemanager.rmcontainer.RMContainerImpl: container_1377704542759_0006_01_000018 Container Transitioned from ACQUIRED to RUNNING
2013-08-28 16:00:16,634 INFO org.apache.hadoop.yarn.server.resourcemanager.rmcontainer.RMContainerImpl: container_1377704542759_0006_01_000011 Container Transitioned from RUNNING to COMPLETED
2013-08-28 16:00:16,635 INFO org.apache.hadoop.yarn.server.resourcemanager.scheduler.common.fica.FiCaSchedulerApp: Completed container: container_1377704542759_0006_01_000011 in state: COMPLETED event:FINISHED
2013-08-28 16:00:16,635 INFO org.apache.hadoop.yarn.server.resourcemanager.RMAuditLogger: USER=ubuntu	OPERATION=AM Released Container	TARGET=SchedulerApp	RESULT=SUCCESS	APPID=application_1377704542759_0006	CONTAINERID=container_1377704542759_0006_01_000011
2013-08-28 16:00:16,635 INFO org.apache.hadoop.yarn.server.resourcemanager.scheduler.common.fica.FiCaSchedulerNode: Released container container_1377704542759_0006_01_000011 of capacity <memory:1024, vCores:1> on host hadoop-16-5:57886, which currently has 6 containers, <memory:7168, vCores:6> used and <memory:1024, vCores:10> available, release resources=true
2013-08-28 16:00:16,635 INFO org.apache.hadoop.yarn.server.resourcemanager.scheduler.capacity.LeafQueue: default used=<memory:48128, vCores:42> numContainers=42 user=ubuntu user-resources=<memory:48128, vCores:42>
2013-08-28 16:00:16,636 INFO org.apache.hadoop.yarn.server.resourcemanager.scheduler.capacity.LeafQueue: completedContainer container=Container: [ContainerId: container_1377704542759_0006_01_000011, NodeId: hadoop-16-5:57886, NodeHttpAddress: hadoop-16-5:8042, Resource: <memory:1024, vCores:1>, Priority: 20, State: NEW, Token: null, Status: container_id {, app_attempt_id {, application_id {, id: 6, cluster_timestamp: 1377704542759, }, attemptId: 1, }, id: 11, }, state: C_COMPLETE, diagnostics: "Container killed by the ApplicationMaster.\n\n", exit_status: 143, ] resource=<memory:1024, vCores:1> queue=default: capacity=1.0, absoluteCapacity=1.0, usedResources=<memory:48128, vCores:42>usedCapacity=0.9791667, absoluteUsedCapacity=0.9791667, numApps=5, numContainers=42 usedCapacity=0.9791667 absoluteUsedCapacity=0.9791667 used=<memory:48128, vCores:42> cluster=<memory:49152, vCores:96>
2013-08-28 16:00:16,636 INFO org.apache.hadoop.yarn.server.resourcemanager.scheduler.capacity.ParentQueue: completedContainer queue=root usedCapacity=0.9791667 absoluteUsedCapacity=0.9791667 used=<memory:48128, vCores:42> cluster=<memory:49152, vCores:96>
2013-08-28 16:00:16,637 INFO org.apache.hadoop.yarn.server.resourcemanager.scheduler.capacity.CapacityScheduler: Application appattempt_1377704542759_0006_000001 released container container_1377704542759_0006_01_000011 on node: host: hadoop-16-5:57886 #containers=6 available=1024 used=7168 with event: FINISHED
2013-08-28 16:00:16,637 INFO org.apache.hadoop.yarn.server.resourcemanager.rmcontainer.RMContainerImpl: container_1377704542759_0006_01_000020 Container Transitioned from NEW to ALLOCATED
2013-08-28 16:00:16,637 INFO org.apache.hadoop.yarn.server.resourcemanager.RMAuditLogger: USER=ubuntu	OPERATION=AM Allocated Container	TARGET=SchedulerApp	RESULT=SUCCESS	APPID=application_1377704542759_0006	CONTAINERID=container_1377704542759_0006_01_000020
2013-08-28 16:00:16,637 INFO org.apache.hadoop.yarn.server.resourcemanager.scheduler.common.fica.FiCaSchedulerNode: Assigned container container_1377704542759_0006_01_000020 of capacity <memory:1024, vCores:1> on host hadoop-16-5:57886, which currently has 7 containers, <memory:8192, vCores:7> used and <memory:0, vCores:9> available
2013-08-28 16:00:16,638 INFO org.apache.hadoop.yarn.server.resourcemanager.scheduler.capacity.LeafQueue: assignedContainer application=application_1377704542759_0006 container=Container: [ContainerId: container_1377704542759_0006_01_000020, NodeId: hadoop-16-5:57886, NodeHttpAddress: hadoop-16-5:8042, Resource: <memory:1024, vCores:1>, Priority: 20, State: NEW, Token: null, Status: container_id {, app_attempt_id {, application_id {, id: 6, cluster_timestamp: 1377704542759, }, attemptId: 1, }, id: 20, }, state: C_NEW, ] containerId=container_1377704542759_0006_01_000020 queue=default: capacity=1.0, absoluteCapacity=1.0, usedResources=<memory:48128, vCores:42>usedCapacity=0.9791667, absoluteUsedCapacity=0.9791667, numApps=5, numContainers=42 usedCapacity=0.9791667 absoluteUsedCapacity=0.9791667 used=<memory:48128, vCores:42> cluster=<memory:49152, vCores:96>
2013-08-28 16:00:16,638 INFO org.apache.hadoop.yarn.server.resourcemanager.scheduler.capacity.ParentQueue: Re-sorting queues since queue: root.default stats: default: capacity=1.0, absoluteCapacity=1.0, usedResources=<memory:49152, vCores:43>usedCapacity=1.0, absoluteUsedCapacity=1.0, numApps=5, numContainers=43
2013-08-28 16:00:16,639 INFO org.apache.hadoop.yarn.server.resourcemanager.scheduler.capacity.ParentQueue: assignedContainer queue=root usedCapacity=1.0 absoluteUsedCapacity=1.0 used=<memory:49152, vCores:43> cluster=<memory:49152, vCores:96>
2013-08-28 16:00:16,911 INFO org.apache.hadoop.yarn.server.resourcemanager.rmcontainer.RMContainerImpl: container_1377704542759_0008_01_000023 Container Transitioned from RUNNING to COMPLETED
2013-08-28 16:00:16,911 INFO org.apache.hadoop.yarn.server.resourcemanager.scheduler.common.fica.FiCaSchedulerApp: Completed container: container_1377704542759_0008_01_000023 in state: COMPLETED event:FINISHED
2013-08-28 16:00:16,911 INFO org.apache.hadoop.yarn.server.resourcemanager.RMAuditLogger: USER=ubuntu	OPERATION=AM Released Container	TARGET=SchedulerApp	RESULT=SUCCESS	APPID=application_1377704542759_0008	CONTAINERID=container_1377704542759_0008_01_000023
2013-08-28 16:00:16,911 INFO org.apache.hadoop.yarn.server.resourcemanager.scheduler.common.fica.FiCaSchedulerNode: Released container container_1377704542759_0008_01_000023 of capacity <memory:1024, vCores:1> on host hadoop-16-7:53595, which currently has 6 containers, <memory:7168, vCores:6> used and <memory:1024, vCores:10> available, release resources=true
2013-08-28 16:00:16,911 INFO org.apache.hadoop.yarn.server.resourcemanager.scheduler.capacity.LeafQueue: default used=<memory:48128, vCores:42> numContainers=42 user=ubuntu user-resources=<memory:48128, vCores:42>
2013-08-28 16:00:16,913 INFO org.apache.hadoop.yarn.server.resourcemanager.scheduler.capacity.LeafQueue: completedContainer container=Container: [ContainerId: container_1377704542759_0008_01_000023, NodeId: hadoop-16-7:53595, NodeHttpAddress: hadoop-16-7:8042, Resource: <memory:1024, vCores:1>, Priority: 20, State: NEW, Token: null, Status: container_id {, app_attempt_id {, application_id {, id: 8, cluster_timestamp: 1377704542759, }, attemptId: 1, }, id: 23, }, state: C_COMPLETE, diagnostics: "Container killed by the ApplicationMaster.\n", exit_status: 0, ] resource=<memory:1024, vCores:1> queue=default: capacity=1.0, absoluteCapacity=1.0, usedResources=<memory:48128, vCores:42>usedCapacity=0.9791667, absoluteUsedCapacity=0.9791667, numApps=5, numContainers=42 usedCapacity=0.9791667 absoluteUsedCapacity=0.9791667 used=<memory:48128, vCores:42> cluster=<memory:49152, vCores:96>
2013-08-28 16:00:16,913 INFO org.apache.hadoop.yarn.server.resourcemanager.scheduler.capacity.ParentQueue: completedContainer queue=root usedCapacity=0.9791667 absoluteUsedCapacity=0.9791667 used=<memory:48128, vCores:42> cluster=<memory:49152, vCores:96>
2013-08-28 16:00:16,913 INFO org.apache.hadoop.yarn.server.resourcemanager.scheduler.capacity.CapacityScheduler: Application appattempt_1377704542759_0008_000001 released container container_1377704542759_0008_01_000023 on node: host: hadoop-16-7:53595 #containers=6 available=1024 used=7168 with event: FINISHED
2013-08-28 16:00:16,913 INFO org.apache.hadoop.yarn.server.resourcemanager.rmcontainer.RMContainerImpl: container_1377704542759_0006_01_000021 Container Transitioned from NEW to ALLOCATED
2013-08-28 16:00:16,914 INFO org.apache.hadoop.yarn.server.resourcemanager.RMAuditLogger: USER=ubuntu	OPERATION=AM Allocated Container	TARGET=SchedulerApp	RESULT=SUCCESS	APPID=application_1377704542759_0006	CONTAINERID=container_1377704542759_0006_01_000021
2013-08-28 16:00:16,914 INFO org.apache.hadoop.yarn.server.resourcemanager.scheduler.common.fica.FiCaSchedulerNode: Assigned container container_1377704542759_0006_01_000021 of capacity <memory:1024, vCores:1> on host hadoop-16-7:53595, which currently has 7 containers, <memory:8192, vCores:7> used and <memory:0, vCores:9> available
2013-08-28 16:00:16,915 INFO org.apache.hadoop.yarn.server.resourcemanager.scheduler.capacity.LeafQueue: assignedContainer application=application_1377704542759_0006 container=Container: [ContainerId: container_1377704542759_0006_01_000021, NodeId: hadoop-16-7:53595, NodeHttpAddress: hadoop-16-7:8042, Resource: <memory:1024, vCores:1>, Priority: 20, State: NEW, Token: null, Status: container_id {, app_attempt_id {, application_id {, id: 6, cluster_timestamp: 1377704542759, }, attemptId: 1, }, id: 21, }, state: C_NEW, ] containerId=container_1377704542759_0006_01_000021 queue=default: capacity=1.0, absoluteCapacity=1.0, usedResources=<memory:48128, vCores:42>usedCapacity=0.9791667, absoluteUsedCapacity=0.9791667, numApps=5, numContainers=42 usedCapacity=0.9791667 absoluteUsedCapacity=0.9791667 used=<memory:48128, vCores:42> cluster=<memory:49152, vCores:96>
2013-08-28 16:00:16,915 INFO org.apache.hadoop.yarn.server.resourcemanager.scheduler.capacity.ParentQueue: Re-sorting queues since queue: root.default stats: default: capacity=1.0, absoluteCapacity=1.0, usedResources=<memory:49152, vCores:43>usedCapacity=1.0, absoluteUsedCapacity=1.0, numApps=5, numContainers=43
2013-08-28 16:00:16,915 INFO org.apache.hadoop.yarn.server.resourcemanager.scheduler.capacity.ParentQueue: assignedContainer queue=root usedCapacity=1.0 absoluteUsedCapacity=1.0 used=<memory:49152, vCores:43> cluster=<memory:49152, vCores:96>
2013-08-28 16:00:17,546 INFO org.apache.hadoop.yarn.server.resourcemanager.rmcontainer.RMContainerImpl: container_1377704542759_0006_01_000019 Container Transitioned from ALLOCATED to ACQUIRED
2013-08-28 16:00:17,548 INFO org.apache.hadoop.yarn.server.resourcemanager.rmcontainer.RMContainerImpl: container_1377704542759_0006_01_000020 Container Transitioned from ALLOCATED to ACQUIRED
2013-08-28 16:00:17,548 INFO org.apache.hadoop.yarn.server.resourcemanager.rmcontainer.RMContainerImpl: container_1377704542759_0006_01_000021 Container Transitioned from ALLOCATED to ACQUIRED
2013-08-28 16:00:17,672 INFO org.apache.hadoop.yarn.server.resourcemanager.rmcontainer.RMContainerImpl: container_1377704542759_0006_01_000020 Container Transitioned from ACQUIRED to RUNNING
2013-08-28 16:00:17,923 INFO org.apache.hadoop.yarn.server.resourcemanager.rmcontainer.RMContainerImpl: container_1377704542759_0006_01_000021 Container Transitioned from ACQUIRED to RUNNING
2013-08-28 16:00:17,923 INFO org.apache.hadoop.yarn.server.resourcemanager.rmcontainer.RMContainerImpl: container_1377704542759_0008_01_000027 Container Transitioned from RUNNING to COMPLETED
2013-08-28 16:00:17,923 INFO org.apache.hadoop.yarn.server.resourcemanager.scheduler.common.fica.FiCaSchedulerApp: Completed container: container_1377704542759_0008_01_000027 in state: COMPLETED event:FINISHED
2013-08-28 16:00:17,924 INFO org.apache.hadoop.yarn.server.resourcemanager.RMAuditLogger: USER=ubuntu	OPERATION=AM Released Container	TARGET=SchedulerApp	RESULT=SUCCESS	APPID=application_1377704542759_0008	CONTAINERID=container_1377704542759_0008_01_000027
2013-08-28 16:00:17,924 INFO org.apache.hadoop.yarn.server.resourcemanager.scheduler.common.fica.FiCaSchedulerNode: Released container container_1377704542759_0008_01_000027 of capacity <memory:1024, vCores:1> on host hadoop-16-7:53595, which currently has 6 containers, <memory:7168, vCores:6> used and <memory:1024, vCores:10> available, release resources=true
2013-08-28 16:00:17,924 INFO org.apache.hadoop.yarn.server.resourcemanager.scheduler.capacity.LeafQueue: default used=<memory:48128, vCores:42> numContainers=42 user=ubuntu user-resources=<memory:48128, vCores:42>
2013-08-28 16:00:17,925 INFO org.apache.hadoop.yarn.server.resourcemanager.scheduler.capacity.LeafQueue: completedContainer container=Container: [ContainerId: container_1377704542759_0008_01_000027, NodeId: hadoop-16-7:53595, NodeHttpAddress: hadoop-16-7:8042, Resource: <memory:1024, vCores:1>, Priority: 20, State: NEW, Token: null, Status: container_id {, app_attempt_id {, application_id {, id: 8, cluster_timestamp: 1377704542759, }, attemptId: 1, }, id: 27, }, state: C_COMPLETE, diagnostics: "Container killed by the ApplicationMaster.\n\n", exit_status: 143, ] resource=<memory:1024, vCores:1> queue=default: capacity=1.0, absoluteCapacity=1.0, usedResources=<memory:48128, vCores:42>usedCapacity=0.9791667, absoluteUsedCapacity=0.9791667, numApps=5, numContainers=42 usedCapacity=0.9791667 absoluteUsedCapacity=0.9791667 used=<memory:48128, vCores:42> cluster=<memory:49152, vCores:96>
2013-08-28 16:00:17,925 INFO org.apache.hadoop.yarn.server.resourcemanager.scheduler.capacity.ParentQueue: completedContainer queue=root usedCapacity=0.9791667 absoluteUsedCapacity=0.9791667 used=<memory:48128, vCores:42> cluster=<memory:49152, vCores:96>
2013-08-28 16:00:17,926 INFO org.apache.hadoop.yarn.server.resourcemanager.scheduler.capacity.CapacityScheduler: Application appattempt_1377704542759_0008_000001 released container container_1377704542759_0008_01_000027 on node: host: hadoop-16-7:53595 #containers=6 available=1024 used=7168 with event: FINISHED
2013-08-28 16:00:17,926 INFO org.apache.hadoop.yarn.server.resourcemanager.rmcontainer.RMContainerImpl: container_1377704542759_0006_01_000022 Container Transitioned from NEW to ALLOCATED
2013-08-28 16:00:17,926 INFO org.apache.hadoop.yarn.server.resourcemanager.RMAuditLogger: USER=ubuntu	OPERATION=AM Allocated Container	TARGET=SchedulerApp	RESULT=SUCCESS	APPID=application_1377704542759_0006	CONTAINERID=container_1377704542759_0006_01_000022
2013-08-28 16:00:17,926 INFO org.apache.hadoop.yarn.server.resourcemanager.scheduler.common.fica.FiCaSchedulerNode: Assigned container container_1377704542759_0006_01_000022 of capacity <memory:1024, vCores:1> on host hadoop-16-7:53595, which currently has 7 containers, <memory:8192, vCores:7> used and <memory:0, vCores:9> available
2013-08-28 16:00:17,927 INFO org.apache.hadoop.yarn.server.resourcemanager.scheduler.capacity.LeafQueue: assignedContainer application=application_1377704542759_0006 container=Container: [ContainerId: container_1377704542759_0006_01_000022, NodeId: hadoop-16-7:53595, NodeHttpAddress: hadoop-16-7:8042, Resource: <memory:1024, vCores:1>, Priority: 20, State: NEW, Token: null, Status: container_id {, app_attempt_id {, application_id {, id: 6, cluster_timestamp: 1377704542759, }, attemptId: 1, }, id: 22, }, state: C_NEW, ] containerId=container_1377704542759_0006_01_000022 queue=default: capacity=1.0, absoluteCapacity=1.0, usedResources=<memory:48128, vCores:42>usedCapacity=0.9791667, absoluteUsedCapacity=0.9791667, numApps=5, numContainers=42 usedCapacity=0.9791667 absoluteUsedCapacity=0.9791667 used=<memory:48128, vCores:42> cluster=<memory:49152, vCores:96>
2013-08-28 16:00:17,928 INFO org.apache.hadoop.yarn.server.resourcemanager.scheduler.capacity.ParentQueue: Re-sorting queues since queue: root.default stats: default: capacity=1.0, absoluteCapacity=1.0, usedResources=<memory:49152, vCores:43>usedCapacity=1.0, absoluteUsedCapacity=1.0, numApps=5, numContainers=43
2013-08-28 16:00:17,928 INFO org.apache.hadoop.yarn.server.resourcemanager.scheduler.capacity.ParentQueue: assignedContainer queue=root usedCapacity=1.0 absoluteUsedCapacity=1.0 used=<memory:49152, vCores:43> cluster=<memory:49152, vCores:96>
2013-08-28 16:00:18,520 INFO org.apache.hadoop.yarn.server.resourcemanager.rmcontainer.RMContainerImpl: container_1377704542759_0006_01_000019 Container Transitioned from ACQUIRED to RUNNING
2013-08-28 16:00:18,570 INFO org.apache.hadoop.yarn.server.resourcemanager.scheduler.AppSchedulingInfo: checking for deactivate... 
2013-08-28 16:00:18,572 INFO org.apache.hadoop.yarn.server.resourcemanager.rmcontainer.RMContainerImpl: container_1377704542759_0006_01_000022 Container Transitioned from ALLOCATED to ACQUIRED
2013-08-28 16:00:18,721 INFO org.apache.hadoop.yarn.server.resourcemanager.rmcontainer.RMContainerImpl: container_1377704542759_0006_01_000012 Container Transitioned from RUNNING to COMPLETED
2013-08-28 16:00:18,721 INFO org.apache.hadoop.yarn.server.resourcemanager.scheduler.common.fica.FiCaSchedulerApp: Completed container: container_1377704542759_0006_01_000012 in state: COMPLETED event:FINISHED
2013-08-28 16:00:18,722 INFO org.apache.hadoop.yarn.server.resourcemanager.RMAuditLogger: USER=ubuntu	OPERATION=AM Released Container	TARGET=SchedulerApp	RESULT=SUCCESS	APPID=application_1377704542759_0006	CONTAINERID=container_1377704542759_0006_01_000012
2013-08-28 16:00:18,722 INFO org.apache.hadoop.yarn.server.resourcemanager.scheduler.common.fica.FiCaSchedulerNode: Released container container_1377704542759_0006_01_000012 of capacity <memory:1024, vCores:1> on host hadoop-16-5:57886, which currently has 6 containers, <memory:7168, vCores:6> used and <memory:1024, vCores:10> available, release resources=true
2013-08-28 16:00:18,722 INFO org.apache.hadoop.yarn.server.resourcemanager.scheduler.capacity.LeafQueue: default used=<memory:48128, vCores:42> numContainers=42 user=ubuntu user-resources=<memory:48128, vCores:42>
2013-08-28 16:00:18,723 INFO org.apache.hadoop.yarn.server.resourcemanager.scheduler.capacity.LeafQueue: completedContainer container=Container: [ContainerId: container_1377704542759_0006_01_000012, NodeId: hadoop-16-5:57886, NodeHttpAddress: hadoop-16-5:8042, Resource: <memory:1024, vCores:1>, Priority: 20, State: NEW, Token: null, Status: container_id {, app_attempt_id {, application_id {, id: 6, cluster_timestamp: 1377704542759, }, attemptId: 1, }, id: 12, }, state: C_COMPLETE, diagnostics: "Container killed by the ApplicationMaster.\n\n", exit_status: 143, ] resource=<memory:1024, vCores:1> queue=default: capacity=1.0, absoluteCapacity=1.0, usedResources=<memory:48128, vCores:42>usedCapacity=0.9791667, absoluteUsedCapacity=0.9791667, numApps=5, numContainers=42 usedCapacity=0.9791667 absoluteUsedCapacity=0.9791667 used=<memory:48128, vCores:42> cluster=<memory:49152, vCores:96>
2013-08-28 16:00:18,723 INFO org.apache.hadoop.yarn.server.resourcemanager.scheduler.capacity.ParentQueue: completedContainer queue=root usedCapacity=0.9791667 absoluteUsedCapacity=0.9791667 used=<memory:48128, vCores:42> cluster=<memory:49152, vCores:96>
2013-08-28 16:00:18,724 INFO org.apache.hadoop.yarn.server.resourcemanager.scheduler.capacity.CapacityScheduler: Application appattempt_1377704542759_0006_000001 released container container_1377704542759_0006_01_000012 on node: host: hadoop-16-5:57886 #containers=6 available=1024 used=7168 with event: FINISHED
2013-08-28 16:00:18,724 INFO org.apache.hadoop.yarn.server.resourcemanager.rmcontainer.RMContainerImpl: container_1377704542759_0006_01_000023 Container Transitioned from NEW to ALLOCATED
2013-08-28 16:00:18,724 INFO org.apache.hadoop.yarn.server.resourcemanager.RMAuditLogger: USER=ubuntu	OPERATION=AM Allocated Container	TARGET=SchedulerApp	RESULT=SUCCESS	APPID=application_1377704542759_0006	CONTAINERID=container_1377704542759_0006_01_000023
2013-08-28 16:00:18,724 INFO org.apache.hadoop.yarn.server.resourcemanager.scheduler.common.fica.FiCaSchedulerNode: Assigned container container_1377704542759_0006_01_000023 of capacity <memory:1024, vCores:1> on host hadoop-16-5:57886, which currently has 7 containers, <memory:8192, vCores:7> used and <memory:0, vCores:9> available
2013-08-28 16:00:18,725 INFO org.apache.hadoop.yarn.server.resourcemanager.scheduler.capacity.LeafQueue: assignedContainer application=application_1377704542759_0006 container=Container: [ContainerId: container_1377704542759_0006_01_000023, NodeId: hadoop-16-5:57886, NodeHttpAddress: hadoop-16-5:8042, Resource: <memory:1024, vCores:1>, Priority: 20, State: NEW, Token: null, Status: container_id {, app_attempt_id {, application_id {, id: 6, cluster_timestamp: 1377704542759, }, attemptId: 1, }, id: 23, }, state: C_NEW, ] containerId=container_1377704542759_0006_01_000023 queue=default: capacity=1.0, absoluteCapacity=1.0, usedResources=<memory:48128, vCores:42>usedCapacity=0.9791667, absoluteUsedCapacity=0.9791667, numApps=5, numContainers=42 usedCapacity=0.9791667 absoluteUsedCapacity=0.9791667 used=<memory:48128, vCores:42> cluster=<memory:49152, vCores:96>
2013-08-28 16:00:18,725 INFO org.apache.hadoop.yarn.server.resourcemanager.scheduler.capacity.ParentQueue: Re-sorting queues since queue: root.default stats: default: capacity=1.0, absoluteCapacity=1.0, usedResources=<memory:49152, vCores:43>usedCapacity=1.0, absoluteUsedCapacity=1.0, numApps=5, numContainers=43
2013-08-28 16:00:18,726 INFO org.apache.hadoop.yarn.server.resourcemanager.scheduler.capacity.ParentQueue: assignedContainer queue=root usedCapacity=1.0 absoluteUsedCapacity=1.0 used=<memory:49152, vCores:43> cluster=<memory:49152, vCores:96>
2013-08-28 16:00:18,939 INFO org.apache.hadoop.yarn.server.resourcemanager.rmcontainer.RMContainerImpl: container_1377704542759_0006_01_000022 Container Transitioned from ACQUIRED to RUNNING
2013-08-28 16:00:19,664 INFO org.apache.hadoop.yarn.server.resourcemanager.rmcontainer.RMContainerImpl: container_1377704542759_0006_01_000023 Container Transitioned from ALLOCATED to ACQUIRED
2013-08-28 16:00:21,047 INFO org.apache.hadoop.yarn.server.resourcemanager.rmcontainer.RMContainerImpl: container_1377704542759_0006_01_000023 Container Transitioned from ACQUIRED to RUNNING
2013-08-28 16:00:22,254 INFO org.apache.hadoop.yarn.server.resourcemanager.rmcontainer.RMContainerImpl: container_1377704542759_0008_01_000026 Container Transitioned from RUNNING to COMPLETED
2013-08-28 16:00:22,254 INFO org.apache.hadoop.yarn.server.resourcemanager.scheduler.common.fica.FiCaSchedulerApp: Completed container: container_1377704542759_0008_01_000026 in state: COMPLETED event:FINISHED
2013-08-28 16:00:22,254 INFO org.apache.hadoop.yarn.server.resourcemanager.RMAuditLogger: USER=ubuntu	OPERATION=AM Released Container	TARGET=SchedulerApp	RESULT=SUCCESS	APPID=application_1377704542759_0008	CONTAINERID=container_1377704542759_0008_01_000026
2013-08-28 16:00:22,254 INFO org.apache.hadoop.yarn.server.resourcemanager.scheduler.common.fica.FiCaSchedulerNode: Released container container_1377704542759_0008_01_000026 of capacity <memory:1024, vCores:1> on host hadoop-16-7:53595, which currently has 6 containers, <memory:7168, vCores:6> used and <memory:1024, vCores:10> available, release resources=true
2013-08-28 16:00:22,255 INFO org.apache.hadoop.yarn.server.resourcemanager.scheduler.capacity.LeafQueue: default used=<memory:48128, vCores:42> numContainers=42 user=ubuntu user-resources=<memory:48128, vCores:42>
2013-08-28 16:00:22,256 INFO org.apache.hadoop.yarn.server.resourcemanager.scheduler.capacity.LeafQueue: completedContainer container=Container: [ContainerId: container_1377704542759_0008_01_000026, NodeId: hadoop-16-7:53595, NodeHttpAddress: hadoop-16-7:8042, Resource: <memory:1024, vCores:1>, Priority: 20, State: NEW, Token: null, Status: container_id {, app_attempt_id {, application_id {, id: 8, cluster_timestamp: 1377704542759, }, attemptId: 1, }, id: 26, }, state: C_COMPLETE, diagnostics: "Container killed by the ApplicationMaster.\n\n", exit_status: 143, ] resource=<memory:1024, vCores:1> queue=default: capacity=1.0, absoluteCapacity=1.0, usedResources=<memory:48128, vCores:42>usedCapacity=0.9791667, absoluteUsedCapacity=0.9791667, numApps=5, numContainers=42 usedCapacity=0.9791667 absoluteUsedCapacity=0.9791667 used=<memory:48128, vCores:42> cluster=<memory:49152, vCores:96>
2013-08-28 16:00:22,256 INFO org.apache.hadoop.yarn.server.resourcemanager.scheduler.capacity.ParentQueue: completedContainer queue=root usedCapacity=0.9791667 absoluteUsedCapacity=0.9791667 used=<memory:48128, vCores:42> cluster=<memory:49152, vCores:96>
2013-08-28 16:00:22,256 INFO org.apache.hadoop.yarn.server.resourcemanager.scheduler.capacity.CapacityScheduler: Application appattempt_1377704542759_0008_000001 released container container_1377704542759_0008_01_000026 on node: host: hadoop-16-7:53595 #containers=6 available=1024 used=7168 with event: FINISHED
2013-08-28 16:00:22,257 INFO org.apache.hadoop.yarn.server.resourcemanager.rmcontainer.RMContainerImpl: container_1377704542759_0006_01_000024 Container Transitioned from NEW to ALLOCATED
2013-08-28 16:00:22,257 INFO org.apache.hadoop.yarn.server.resourcemanager.RMAuditLogger: USER=ubuntu	OPERATION=AM Allocated Container	TARGET=SchedulerApp	RESULT=SUCCESS	APPID=application_1377704542759_0006	CONTAINERID=container_1377704542759_0006_01_000024
2013-08-28 16:00:22,257 INFO org.apache.hadoop.yarn.server.resourcemanager.scheduler.common.fica.FiCaSchedulerNode: Assigned container container_1377704542759_0006_01_000024 of capacity <memory:1024, vCores:1> on host hadoop-16-7:53595, which currently has 7 containers, <memory:8192, vCores:7> used and <memory:0, vCores:9> available
2013-08-28 16:00:22,258 INFO org.apache.hadoop.yarn.server.resourcemanager.scheduler.capacity.LeafQueue: assignedContainer application=application_1377704542759_0006 container=Container: [ContainerId: container_1377704542759_0006_01_000024, NodeId: hadoop-16-7:53595, NodeHttpAddress: hadoop-16-7:8042, Resource: <memory:1024, vCores:1>, Priority: 20, State: NEW, Token: null, Status: container_id {, app_attempt_id {, application_id {, id: 6, cluster_timestamp: 1377704542759, }, attemptId: 1, }, id: 24, }, state: C_NEW, ] containerId=container_1377704542759_0006_01_000024 queue=default: capacity=1.0, absoluteCapacity=1.0, usedResources=<memory:48128, vCores:42>usedCapacity=0.9791667, absoluteUsedCapacity=0.9791667, numApps=5, numContainers=42 usedCapacity=0.9791667 absoluteUsedCapacity=0.9791667 used=<memory:48128, vCores:42> cluster=<memory:49152, vCores:96>
2013-08-28 16:00:22,258 INFO org.apache.hadoop.yarn.server.resourcemanager.scheduler.capacity.ParentQueue: Re-sorting queues since queue: root.default stats: default: capacity=1.0, absoluteCapacity=1.0, usedResources=<memory:49152, vCores:43>usedCapacity=1.0, absoluteUsedCapacity=1.0, numApps=5, numContainers=43
2013-08-28 16:00:22,259 INFO org.apache.hadoop.yarn.server.resourcemanager.scheduler.capacity.ParentQueue: assignedContainer queue=root usedCapacity=1.0 absoluteUsedCapacity=1.0 used=<memory:49152, vCores:43> cluster=<memory:49152, vCores:96>
2013-08-28 16:00:22,374 INFO org.apache.hadoop.yarn.server.resourcemanager.rmcontainer.RMContainerImpl: container_1377704542759_0006_01_000024 Container Transitioned from ALLOCATED to ACQUIRED
2013-08-28 16:00:23,280 INFO org.apache.hadoop.yarn.server.resourcemanager.rmcontainer.RMContainerImpl: container_1377704542759_0006_01_000024 Container Transitioned from ACQUIRED to RUNNING
2013-08-28 16:00:23,446 INFO org.apache.hadoop.yarn.server.resourcemanager.rmcontainer.RMContainerImpl: container_1377704542759_0008_01_000003 Container Transitioned from RUNNING to COMPLETED
2013-08-28 16:00:23,446 INFO org.apache.hadoop.yarn.server.resourcemanager.scheduler.common.fica.FiCaSchedulerApp: Completed container: container_1377704542759_0008_01_000003 in state: COMPLETED event:FINISHED
2013-08-28 16:00:23,446 INFO org.apache.hadoop.yarn.server.resourcemanager.RMAuditLogger: USER=ubuntu	OPERATION=AM Released Container	TARGET=SchedulerApp	RESULT=SUCCESS	APPID=application_1377704542759_0008	CONTAINERID=container_1377704542759_0008_01_000003
2013-08-28 16:00:23,446 INFO org.apache.hadoop.yarn.server.resourcemanager.scheduler.common.fica.FiCaSchedulerNode: Released container container_1377704542759_0008_01_000003 of capacity <memory:1024, vCores:1> on host hadoop-16-2:39317, which currently has 7 containers, <memory:7168, vCores:7> used and <memory:1024, vCores:9> available, release resources=true
2013-08-28 16:00:23,446 INFO org.apache.hadoop.yarn.server.resourcemanager.scheduler.capacity.LeafQueue: default used=<memory:48128, vCores:42> numContainers=42 user=ubuntu user-resources=<memory:48128, vCores:42>
2013-08-28 16:00:23,448 INFO org.apache.hadoop.yarn.server.resourcemanager.scheduler.capacity.LeafQueue: completedContainer container=Container: [ContainerId: container_1377704542759_0008_01_000003, NodeId: hadoop-16-2:39317, NodeHttpAddress: hadoop-16-2:8042, Resource: <memory:1024, vCores:1>, Priority: 20, State: NEW, Token: null, Status: container_id {, app_attempt_id {, application_id {, id: 8, cluster_timestamp: 1377704542759, }, attemptId: 1, }, id: 3, }, state: C_COMPLETE, diagnostics: "Container killed by the ApplicationMaster.\n", exit_status: 0, ] resource=<memory:1024, vCores:1> queue=default: capacity=1.0, absoluteCapacity=1.0, usedResources=<memory:48128, vCores:42>usedCapacity=0.9791667, absoluteUsedCapacity=0.9791667, numApps=5, numContainers=42 usedCapacity=0.9791667 absoluteUsedCapacity=0.9791667 used=<memory:48128, vCores:42> cluster=<memory:49152, vCores:96>
2013-08-28 16:00:23,448 INFO org.apache.hadoop.yarn.server.resourcemanager.scheduler.capacity.ParentQueue: completedContainer queue=root usedCapacity=0.9791667 absoluteUsedCapacity=0.9791667 used=<memory:48128, vCores:42> cluster=<memory:49152, vCores:96>
2013-08-28 16:00:23,448 INFO org.apache.hadoop.yarn.server.resourcemanager.scheduler.capacity.CapacityScheduler: Application appattempt_1377704542759_0008_000001 released container container_1377704542759_0008_01_000003 on node: host: hadoop-16-2:39317 #containers=7 available=1024 used=7168 with event: FINISHED
2013-08-28 16:00:23,449 INFO org.apache.hadoop.yarn.server.resourcemanager.rmcontainer.RMContainerImpl: container_1377704542759_0006_01_000025 Container Transitioned from NEW to ALLOCATED
2013-08-28 16:00:23,449 INFO org.apache.hadoop.yarn.server.resourcemanager.RMAuditLogger: USER=ubuntu	OPERATION=AM Allocated Container	TARGET=SchedulerApp	RESULT=SUCCESS	APPID=application_1377704542759_0006	CONTAINERID=container_1377704542759_0006_01_000025
2013-08-28 16:00:23,449 INFO org.apache.hadoop.yarn.server.resourcemanager.scheduler.common.fica.FiCaSchedulerNode: Assigned container container_1377704542759_0006_01_000025 of capacity <memory:1024, vCores:1> on host hadoop-16-2:39317, which currently has 8 containers, <memory:8192, vCores:8> used and <memory:0, vCores:8> available
2013-08-28 16:00:23,450 INFO org.apache.hadoop.yarn.server.resourcemanager.scheduler.capacity.LeafQueue: assignedContainer application=application_1377704542759_0006 container=Container: [ContainerId: container_1377704542759_0006_01_000025, NodeId: hadoop-16-2:39317, NodeHttpAddress: hadoop-16-2:8042, Resource: <memory:1024, vCores:1>, Priority: 20, State: NEW, Token: null, Status: container_id {, app_attempt_id {, application_id {, id: 6, cluster_timestamp: 1377704542759, }, attemptId: 1, }, id: 25, }, state: C_NEW, ] containerId=container_1377704542759_0006_01_000025 queue=default: capacity=1.0, absoluteCapacity=1.0, usedResources=<memory:48128, vCores:42>usedCapacity=0.9791667, absoluteUsedCapacity=0.9791667, numApps=5, numContainers=42 usedCapacity=0.9791667 absoluteUsedCapacity=0.9791667 used=<memory:48128, vCores:42> cluster=<memory:49152, vCores:96>
2013-08-28 16:00:23,450 INFO org.apache.hadoop.yarn.server.resourcemanager.scheduler.capacity.ParentQueue: Re-sorting queues since queue: root.default stats: default: capacity=1.0, absoluteCapacity=1.0, usedResources=<memory:49152, vCores:43>usedCapacity=1.0, absoluteUsedCapacity=1.0, numApps=5, numContainers=43
2013-08-28 16:00:23,450 INFO org.apache.hadoop.yarn.server.resourcemanager.scheduler.capacity.ParentQueue: assignedContainer queue=root usedCapacity=1.0 absoluteUsedCapacity=1.0 used=<memory:49152, vCores:43> cluster=<memory:49152, vCores:96>
2013-08-28 16:00:24,394 INFO org.apache.hadoop.yarn.server.resourcemanager.rmcontainer.RMContainerImpl: container_1377704542759_0006_01_000025 Container Transitioned from ALLOCATED to ACQUIRED
2013-08-28 16:00:24,457 INFO org.apache.hadoop.yarn.server.resourcemanager.rmcontainer.RMContainerImpl: container_1377704542759_0006_01_000025 Container Transitioned from ACQUIRED to RUNNING
2013-08-28 16:00:25,986 INFO org.apache.hadoop.yarn.server.resourcemanager.rmcontainer.RMContainerImpl: container_1377704542759_0008_01_000004 Container Transitioned from RUNNING to COMPLETED
2013-08-28 16:00:25,986 INFO org.apache.hadoop.yarn.server.resourcemanager.scheduler.common.fica.FiCaSchedulerApp: Completed container: container_1377704542759_0008_01_000004 in state: COMPLETED event:FINISHED
2013-08-28 16:00:25,986 INFO org.apache.hadoop.yarn.server.resourcemanager.RMAuditLogger: USER=ubuntu	OPERATION=AM Released Container	TARGET=SchedulerApp	RESULT=SUCCESS	APPID=application_1377704542759_0008	CONTAINERID=container_1377704542759_0008_01_000004
2013-08-28 16:00:25,986 INFO org.apache.hadoop.yarn.server.resourcemanager.scheduler.common.fica.FiCaSchedulerNode: Released container container_1377704542759_0008_01_000004 of capacity <memory:1024, vCores:1> on host hadoop-16-2:39317, which currently has 7 containers, <memory:7168, vCores:7> used and <memory:1024, vCores:9> available, release resources=true
2013-08-28 16:00:25,987 INFO org.apache.hadoop.yarn.server.resourcemanager.scheduler.capacity.LeafQueue: default used=<memory:48128, vCores:42> numContainers=42 user=ubuntu user-resources=<memory:48128, vCores:42>
2013-08-28 16:00:25,988 INFO org.apache.hadoop.yarn.server.resourcemanager.scheduler.capacity.LeafQueue: completedContainer container=Container: [ContainerId: container_1377704542759_0008_01_000004, NodeId: hadoop-16-2:39317, NodeHttpAddress: hadoop-16-2:8042, Resource: <memory:1024, vCores:1>, Priority: 20, State: NEW, Token: null, Status: container_id {, app_attempt_id {, application_id {, id: 8, cluster_timestamp: 1377704542759, }, attemptId: 1, }, id: 4, }, state: C_COMPLETE, diagnostics: "Container killed by the ApplicationMaster.\n\n", exit_status: 143, ] resource=<memory:1024, vCores:1> queue=default: capacity=1.0, absoluteCapacity=1.0, usedResources=<memory:48128, vCores:42>usedCapacity=0.9791667, absoluteUsedCapacity=0.9791667, numApps=5, numContainers=42 usedCapacity=0.9791667 absoluteUsedCapacity=0.9791667 used=<memory:48128, vCores:42> cluster=<memory:49152, vCores:96>
2013-08-28 16:00:25,988 INFO org.apache.hadoop.yarn.server.resourcemanager.scheduler.capacity.ParentQueue: completedContainer queue=root usedCapacity=0.9791667 absoluteUsedCapacity=0.9791667 used=<memory:48128, vCores:42> cluster=<memory:49152, vCores:96>
2013-08-28 16:00:25,988 INFO org.apache.hadoop.yarn.server.resourcemanager.scheduler.capacity.CapacityScheduler: Application appattempt_1377704542759_0008_000001 released container container_1377704542759_0008_01_000004 on node: host: hadoop-16-2:39317 #containers=7 available=1024 used=7168 with event: FINISHED
2013-08-28 16:00:25,989 INFO org.apache.hadoop.yarn.server.resourcemanager.rmcontainer.RMContainerImpl: container_1377704542759_0006_01_000026 Container Transitioned from NEW to ALLOCATED
2013-08-28 16:00:25,989 INFO org.apache.hadoop.yarn.server.resourcemanager.RMAuditLogger: USER=ubuntu	OPERATION=AM Allocated Container	TARGET=SchedulerApp	RESULT=SUCCESS	APPID=application_1377704542759_0006	CONTAINERID=container_1377704542759_0006_01_000026
2013-08-28 16:00:25,989 INFO org.apache.hadoop.yarn.server.resourcemanager.scheduler.common.fica.FiCaSchedulerNode: Assigned container container_1377704542759_0006_01_000026 of capacity <memory:1024, vCores:1> on host hadoop-16-2:39317, which currently has 8 containers, <memory:8192, vCores:8> used and <memory:0, vCores:8> available
2013-08-28 16:00:25,990 INFO org.apache.hadoop.yarn.server.resourcemanager.scheduler.capacity.LeafQueue: assignedContainer application=application_1377704542759_0006 container=Container: [ContainerId: container_1377704542759_0006_01_000026, NodeId: hadoop-16-2:39317, NodeHttpAddress: hadoop-16-2:8042, Resource: <memory:1024, vCores:1>, Priority: 20, State: NEW, Token: null, Status: container_id {, app_attempt_id {, application_id {, id: 6, cluster_timestamp: 1377704542759, }, attemptId: 1, }, id: 26, }, state: C_NEW, ] containerId=container_1377704542759_0006_01_000026 queue=default: capacity=1.0, absoluteCapacity=1.0, usedResources=<memory:48128, vCores:42>usedCapacity=0.9791667, absoluteUsedCapacity=0.9791667, numApps=5, numContainers=42 usedCapacity=0.9791667 absoluteUsedCapacity=0.9791667 used=<memory:48128, vCores:42> cluster=<memory:49152, vCores:96>
2013-08-28 16:00:25,990 INFO org.apache.hadoop.yarn.server.resourcemanager.scheduler.capacity.ParentQueue: Re-sorting queues since queue: root.default stats: default: capacity=1.0, absoluteCapacity=1.0, usedResources=<memory:49152, vCores:43>usedCapacity=1.0, absoluteUsedCapacity=1.0, numApps=5, numContainers=43
2013-08-28 16:00:25,991 INFO org.apache.hadoop.yarn.server.resourcemanager.scheduler.capacity.ParentQueue: assignedContainer queue=root usedCapacity=1.0 absoluteUsedCapacity=1.0 used=<memory:49152, vCores:43> cluster=<memory:49152, vCores:96>
2013-08-28 16:00:26,423 INFO org.apache.hadoop.yarn.server.resourcemanager.rmcontainer.RMContainerImpl: container_1377704542759_0006_01_000026 Container Transitioned from ALLOCATED to ACQUIRED
2013-08-28 16:00:28,312 INFO org.apache.hadoop.yarn.server.resourcemanager.rmcontainer.RMContainerImpl: container_1377704542759_0008_01_000018 Container Transitioned from RUNNING to COMPLETED
2013-08-28 16:00:28,312 INFO org.apache.hadoop.yarn.server.resourcemanager.scheduler.common.fica.FiCaSchedulerApp: Completed container: container_1377704542759_0008_01_000018 in state: COMPLETED event:FINISHED
2013-08-28 16:00:28,312 INFO org.apache.hadoop.yarn.server.resourcemanager.RMAuditLogger: USER=ubuntu	OPERATION=AM Released Container	TARGET=SchedulerApp	RESULT=SUCCESS	APPID=application_1377704542759_0008	CONTAINERID=container_1377704542759_0008_01_000018
2013-08-28 16:00:28,313 INFO org.apache.hadoop.yarn.server.resourcemanager.scheduler.common.fica.FiCaSchedulerNode: Released container container_1377704542759_0008_01_000018 of capacity <memory:1024, vCores:1> on host hadoop-16-4:52495, which currently has 6 containers, <memory:7168, vCores:6> used and <memory:1024, vCores:10> available, release resources=true
2013-08-28 16:00:28,313 INFO org.apache.hadoop.yarn.server.resourcemanager.scheduler.capacity.LeafQueue: default used=<memory:48128, vCores:42> numContainers=42 user=ubuntu user-resources=<memory:48128, vCores:42>
2013-08-28 16:00:28,314 INFO org.apache.hadoop.yarn.server.resourcemanager.scheduler.capacity.LeafQueue: completedContainer container=Container: [ContainerId: container_1377704542759_0008_01_000018, NodeId: hadoop-16-4:52495, NodeHttpAddress: hadoop-16-4:8042, Resource: <memory:1024, vCores:1>, Priority: 20, State: NEW, Token: null, Status: container_id {, app_attempt_id {, application_id {, id: 8, cluster_timestamp: 1377704542759, }, attemptId: 1, }, id: 18, }, state: C_COMPLETE, diagnostics: "", exit_status: 0, ] resource=<memory:1024, vCores:1> queue=default: capacity=1.0, absoluteCapacity=1.0, usedResources=<memory:48128, vCores:42>usedCapacity=0.9791667, absoluteUsedCapacity=0.9791667, numApps=5, numContainers=42 usedCapacity=0.9791667 absoluteUsedCapacity=0.9791667 used=<memory:48128, vCores:42> cluster=<memory:49152, vCores:96>
2013-08-28 16:00:28,314 INFO org.apache.hadoop.yarn.server.resourcemanager.scheduler.capacity.ParentQueue: completedContainer queue=root usedCapacity=0.9791667 absoluteUsedCapacity=0.9791667 used=<memory:48128, vCores:42> cluster=<memory:49152, vCores:96>
2013-08-28 16:00:28,314 INFO org.apache.hadoop.yarn.server.resourcemanager.scheduler.capacity.CapacityScheduler: Application appattempt_1377704542759_0008_000001 released container container_1377704542759_0008_01_000018 on node: host: hadoop-16-4:52495 #containers=6 available=1024 used=7168 with event: FINISHED
2013-08-28 16:00:28,315 INFO org.apache.hadoop.yarn.server.resourcemanager.rmcontainer.RMContainerImpl: container_1377704542759_0006_01_000027 Container Transitioned from NEW to ALLOCATED
2013-08-28 16:00:28,315 INFO org.apache.hadoop.yarn.server.resourcemanager.RMAuditLogger: USER=ubuntu	OPERATION=AM Allocated Container	TARGET=SchedulerApp	RESULT=SUCCESS	APPID=application_1377704542759_0006	CONTAINERID=container_1377704542759_0006_01_000027
2013-08-28 16:00:28,315 INFO org.apache.hadoop.yarn.server.resourcemanager.scheduler.common.fica.FiCaSchedulerNode: Assigned container container_1377704542759_0006_01_000027 of capacity <memory:1024, vCores:1> on host hadoop-16-4:52495, which currently has 7 containers, <memory:8192, vCores:7> used and <memory:0, vCores:9> available
2013-08-28 16:00:28,317 INFO org.apache.hadoop.yarn.server.resourcemanager.scheduler.capacity.LeafQueue: assignedContainer application=application_1377704542759_0006 container=Container: [ContainerId: container_1377704542759_0006_01_000027, NodeId: hadoop-16-4:52495, NodeHttpAddress: hadoop-16-4:8042, Resource: <memory:1024, vCores:1>, Priority: 20, State: NEW, Token: null, Status: container_id {, app_attempt_id {, application_id {, id: 6, cluster_timestamp: 1377704542759, }, attemptId: 1, }, id: 27, }, state: C_NEW, ] containerId=container_1377704542759_0006_01_000027 queue=default: capacity=1.0, absoluteCapacity=1.0, usedResources=<memory:48128, vCores:42>usedCapacity=0.9791667, absoluteUsedCapacity=0.9791667, numApps=5, numContainers=42 usedCapacity=0.9791667 absoluteUsedCapacity=0.9791667 used=<memory:48128, vCores:42> cluster=<memory:49152, vCores:96>
2013-08-28 16:00:28,317 INFO org.apache.hadoop.yarn.server.resourcemanager.scheduler.capacity.ParentQueue: Re-sorting queues since queue: root.default stats: default: capacity=1.0, absoluteCapacity=1.0, usedResources=<memory:49152, vCores:43>usedCapacity=1.0, absoluteUsedCapacity=1.0, numApps=5, numContainers=43
2013-08-28 16:00:28,317 INFO org.apache.hadoop.yarn.server.resourcemanager.scheduler.capacity.ParentQueue: assignedContainer queue=root usedCapacity=1.0 absoluteUsedCapacity=1.0 used=<memory:49152, vCores:43> cluster=<memory:49152, vCores:96>
2013-08-28 16:00:28,578 INFO org.apache.hadoop.yarn.server.resourcemanager.rmcontainer.RMContainerImpl: container_1377704542759_0006_01_000027 Container Transitioned from ALLOCATED to ACQUIRED
2013-08-28 16:00:29,307 INFO org.apache.hadoop.yarn.server.resourcemanager.rmcontainer.RMContainerImpl: container_1377704542759_0008_01_000008 Container Transitioned from RUNNING to COMPLETED
2013-08-28 16:00:29,308 INFO org.apache.hadoop.yarn.server.resourcemanager.scheduler.common.fica.FiCaSchedulerApp: Completed container: container_1377704542759_0008_01_000008 in state: COMPLETED event:FINISHED
2013-08-28 16:00:29,308 INFO org.apache.hadoop.yarn.server.resourcemanager.RMAuditLogger: USER=ubuntu	OPERATION=AM Released Container	TARGET=SchedulerApp	RESULT=SUCCESS	APPID=application_1377704542759_0008	CONTAINERID=container_1377704542759_0008_01_000008
2013-08-28 16:00:29,308 INFO org.apache.hadoop.yarn.server.resourcemanager.scheduler.common.fica.FiCaSchedulerNode: Released container container_1377704542759_0008_01_000008 of capacity <memory:1024, vCores:1> on host hadoop-16-2:39317, which currently has 7 containers, <memory:7168, vCores:7> used and <memory:1024, vCores:9> available, release resources=true
2013-08-28 16:00:29,308 INFO org.apache.hadoop.yarn.server.resourcemanager.scheduler.capacity.LeafQueue: default used=<memory:48128, vCores:42> numContainers=42 user=ubuntu user-resources=<memory:48128, vCores:42>
2013-08-28 16:00:29,310 INFO org.apache.hadoop.yarn.server.resourcemanager.scheduler.capacity.LeafQueue: completedContainer container=Container: [ContainerId: container_1377704542759_0008_01_000008, NodeId: hadoop-16-2:39317, NodeHttpAddress: hadoop-16-2:8042, Resource: <memory:1024, vCores:1>, Priority: 20, State: NEW, Token: null, Status: container_id {, app_attempt_id {, application_id {, id: 8, cluster_timestamp: 1377704542759, }, attemptId: 1, }, id: 8, }, state: C_COMPLETE, diagnostics: "Container killed by the ApplicationMaster.\n\n", exit_status: 143, ] resource=<memory:1024, vCores:1> queue=default: capacity=1.0, absoluteCapacity=1.0, usedResources=<memory:48128, vCores:42>usedCapacity=0.9791667, absoluteUsedCapacity=0.9791667, numApps=5, numContainers=42 usedCapacity=0.9791667 absoluteUsedCapacity=0.9791667 used=<memory:48128, vCores:42> cluster=<memory:49152, vCores:96>
2013-08-28 16:00:29,310 INFO org.apache.hadoop.yarn.server.resourcemanager.scheduler.capacity.ParentQueue: completedContainer queue=root usedCapacity=0.9791667 absoluteUsedCapacity=0.9791667 used=<memory:48128, vCores:42> cluster=<memory:49152, vCores:96>
2013-08-28 16:00:29,310 INFO org.apache.hadoop.yarn.server.resourcemanager.scheduler.capacity.CapacityScheduler: Application appattempt_1377704542759_0008_000001 released container container_1377704542759_0008_01_000008 on node: host: hadoop-16-2:39317 #containers=7 available=1024 used=7168 with event: FINISHED
2013-08-28 16:00:29,311 INFO org.apache.hadoop.yarn.server.resourcemanager.rmcontainer.RMContainerImpl: container_1377704542759_0006_01_000028 Container Transitioned from NEW to ALLOCATED
2013-08-28 16:00:29,311 INFO org.apache.hadoop.yarn.server.resourcemanager.RMAuditLogger: USER=ubuntu	OPERATION=AM Allocated Container	TARGET=SchedulerApp	RESULT=SUCCESS	APPID=application_1377704542759_0006	CONTAINERID=container_1377704542759_0006_01_000028
2013-08-28 16:00:29,311 INFO org.apache.hadoop.yarn.server.resourcemanager.scheduler.common.fica.FiCaSchedulerNode: Assigned container container_1377704542759_0006_01_000028 of capacity <memory:1024, vCores:1> on host hadoop-16-2:39317, which currently has 8 containers, <memory:8192, vCores:8> used and <memory:0, vCores:8> available
2013-08-28 16:00:29,312 INFO org.apache.hadoop.yarn.server.resourcemanager.scheduler.capacity.LeafQueue: assignedContainer application=application_1377704542759_0006 container=Container: [ContainerId: container_1377704542759_0006_01_000028, NodeId: hadoop-16-2:39317, NodeHttpAddress: hadoop-16-2:8042, Resource: <memory:1024, vCores:1>, Priority: 20, State: NEW, Token: null, Status: container_id {, app_attempt_id {, application_id {, id: 6, cluster_timestamp: 1377704542759, }, attemptId: 1, }, id: 28, }, state: C_NEW, ] containerId=container_1377704542759_0006_01_000028 queue=default: capacity=1.0, absoluteCapacity=1.0, usedResources=<memory:48128, vCores:42>usedCapacity=0.9791667, absoluteUsedCapacity=0.9791667, numApps=5, numContainers=42 usedCapacity=0.9791667 absoluteUsedCapacity=0.9791667 used=<memory:48128, vCores:42> cluster=<memory:49152, vCores:96>
2013-08-28 16:00:29,312 INFO org.apache.hadoop.yarn.server.resourcemanager.scheduler.capacity.ParentQueue: Re-sorting queues since queue: root.default stats: default: capacity=1.0, absoluteCapacity=1.0, usedResources=<memory:49152, vCores:43>usedCapacity=1.0, absoluteUsedCapacity=1.0, numApps=5, numContainers=43
2013-08-28 16:00:29,312 INFO org.apache.hadoop.yarn.server.resourcemanager.scheduler.capacity.ParentQueue: assignedContainer queue=root usedCapacity=1.0 absoluteUsedCapacity=1.0 used=<memory:49152, vCores:43> cluster=<memory:49152, vCores:96>
2013-08-28 16:00:29,330 INFO org.apache.hadoop.yarn.server.resourcemanager.rmcontainer.RMContainerImpl: container_1377704542759_0006_01_000027 Container Transitioned from ACQUIRED to RUNNING
2013-08-28 16:00:29,593 INFO org.apache.hadoop.yarn.server.resourcemanager.rmcontainer.RMContainerImpl: container_1377704542759_0006_01_000028 Container Transitioned from ALLOCATED to ACQUIRED
2013-08-28 16:00:30,319 INFO org.apache.hadoop.yarn.server.resourcemanager.rmcontainer.RMContainerImpl: container_1377704542759_0006_01_000026 Container Transitioned from ACQUIRED to RUNNING
2013-08-28 16:00:30,320 INFO org.apache.hadoop.yarn.server.resourcemanager.rmcontainer.RMContainerImpl: container_1377704542759_0006_01_000028 Container Transitioned from ACQUIRED to RUNNING
2013-08-28 16:00:30,338 INFO org.apache.hadoop.yarn.server.resourcemanager.rmcontainer.RMContainerImpl: container_1377704542759_0008_01_000016 Container Transitioned from RUNNING to COMPLETED
2013-08-28 16:00:30,338 INFO org.apache.hadoop.yarn.server.resourcemanager.scheduler.common.fica.FiCaSchedulerApp: Completed container: container_1377704542759_0008_01_000016 in state: COMPLETED event:FINISHED
2013-08-28 16:00:30,338 INFO org.apache.hadoop.yarn.server.resourcemanager.RMAuditLogger: USER=ubuntu	OPERATION=AM Released Container	TARGET=SchedulerApp	RESULT=SUCCESS	APPID=application_1377704542759_0008	CONTAINERID=container_1377704542759_0008_01_000016
2013-08-28 16:00:30,338 INFO org.apache.hadoop.yarn.server.resourcemanager.scheduler.common.fica.FiCaSchedulerNode: Released container container_1377704542759_0008_01_000016 of capacity <memory:1024, vCores:1> on host hadoop-16-4:52495, which currently has 6 containers, <memory:7168, vCores:6> used and <memory:1024, vCores:10> available, release resources=true
2013-08-28 16:00:30,338 INFO org.apache.hadoop.yarn.server.resourcemanager.scheduler.capacity.LeafQueue: default used=<memory:48128, vCores:42> numContainers=42 user=ubuntu user-resources=<memory:48128, vCores:42>
2013-08-28 16:00:30,340 INFO org.apache.hadoop.yarn.server.resourcemanager.scheduler.capacity.LeafQueue: completedContainer container=Container: [ContainerId: container_1377704542759_0008_01_000016, NodeId: hadoop-16-4:52495, NodeHttpAddress: hadoop-16-4:8042, Resource: <memory:1024, vCores:1>, Priority: 20, State: NEW, Token: null, Status: container_id {, app_attempt_id {, application_id {, id: 8, cluster_timestamp: 1377704542759, }, attemptId: 1, }, id: 16, }, state: C_COMPLETE, diagnostics: "Container killed by the ApplicationMaster.\n", exit_status: 0, ] resource=<memory:1024, vCores:1> queue=default: capacity=1.0, absoluteCapacity=1.0, usedResources=<memory:48128, vCores:42>usedCapacity=0.9791667, absoluteUsedCapacity=0.9791667, numApps=5, numContainers=42 usedCapacity=0.9791667 absoluteUsedCapacity=0.9791667 used=<memory:48128, vCores:42> cluster=<memory:49152, vCores:96>
2013-08-28 16:00:30,340 INFO org.apache.hadoop.yarn.server.resourcemanager.scheduler.capacity.ParentQueue: completedContainer queue=root usedCapacity=0.9791667 absoluteUsedCapacity=0.9791667 used=<memory:48128, vCores:42> cluster=<memory:49152, vCores:96>
2013-08-28 16:00:30,340 INFO org.apache.hadoop.yarn.server.resourcemanager.scheduler.capacity.CapacityScheduler: Application appattempt_1377704542759_0008_000001 released container container_1377704542759_0008_01_000016 on node: host: hadoop-16-4:52495 #containers=6 available=1024 used=7168 with event: FINISHED
2013-08-28 16:00:30,341 INFO org.apache.hadoop.yarn.server.resourcemanager.rmcontainer.RMContainerImpl: container_1377704542759_0006_01_000029 Container Transitioned from NEW to ALLOCATED
2013-08-28 16:00:30,341 INFO org.apache.hadoop.yarn.server.resourcemanager.RMAuditLogger: USER=ubuntu	OPERATION=AM Allocated Container	TARGET=SchedulerApp	RESULT=SUCCESS	APPID=application_1377704542759_0006	CONTAINERID=container_1377704542759_0006_01_000029
2013-08-28 16:00:30,341 INFO org.apache.hadoop.yarn.server.resourcemanager.scheduler.common.fica.FiCaSchedulerNode: Assigned container container_1377704542759_0006_01_000029 of capacity <memory:1024, vCores:1> on host hadoop-16-4:52495, which currently has 7 containers, <memory:8192, vCores:7> used and <memory:0, vCores:9> available
2013-08-28 16:00:30,342 INFO org.apache.hadoop.yarn.server.resourcemanager.scheduler.capacity.LeafQueue: assignedContainer application=application_1377704542759_0006 container=Container: [ContainerId: container_1377704542759_0006_01_000029, NodeId: hadoop-16-4:52495, NodeHttpAddress: hadoop-16-4:8042, Resource: <memory:1024, vCores:1>, Priority: 20, State: NEW, Token: null, Status: container_id {, app_attempt_id {, application_id {, id: 6, cluster_timestamp: 1377704542759, }, attemptId: 1, }, id: 29, }, state: C_NEW, ] containerId=container_1377704542759_0006_01_000029 queue=default: capacity=1.0, absoluteCapacity=1.0, usedResources=<memory:48128, vCores:42>usedCapacity=0.9791667, absoluteUsedCapacity=0.9791667, numApps=5, numContainers=42 usedCapacity=0.9791667 absoluteUsedCapacity=0.9791667 used=<memory:48128, vCores:42> cluster=<memory:49152, vCores:96>
2013-08-28 16:00:30,342 INFO org.apache.hadoop.yarn.server.resourcemanager.scheduler.capacity.ParentQueue: Re-sorting queues since queue: root.default stats: default: capacity=1.0, absoluteCapacity=1.0, usedResources=<memory:49152, vCores:43>usedCapacity=1.0, absoluteUsedCapacity=1.0, numApps=5, numContainers=43
2013-08-28 16:00:30,342 INFO org.apache.hadoop.yarn.server.resourcemanager.scheduler.capacity.ParentQueue: assignedContainer queue=root usedCapacity=1.0 absoluteUsedCapacity=1.0 used=<memory:49152, vCores:43> cluster=<memory:49152, vCores:96>
2013-08-28 16:00:30,611 INFO org.apache.hadoop.yarn.server.resourcemanager.rmcontainer.RMContainerImpl: container_1377704542759_0008_01_000025 Container Transitioned from RUNNING to COMPLETED
2013-08-28 16:00:30,612 INFO org.apache.hadoop.yarn.server.resourcemanager.scheduler.common.fica.FiCaSchedulerApp: Completed container: container_1377704542759_0008_01_000025 in state: COMPLETED event:FINISHED
2013-08-28 16:00:30,612 INFO org.apache.hadoop.yarn.server.resourcemanager.RMAuditLogger: USER=ubuntu	OPERATION=AM Released Container	TARGET=SchedulerApp	RESULT=SUCCESS	APPID=application_1377704542759_0008	CONTAINERID=container_1377704542759_0008_01_000025
2013-08-28 16:00:30,612 INFO org.apache.hadoop.yarn.server.resourcemanager.scheduler.common.fica.FiCaSchedulerNode: Released container container_1377704542759_0008_01_000025 of capacity <memory:1024, vCores:1> on host hadoop-16-7:53595, which currently has 6 containers, <memory:7168, vCores:6> used and <memory:1024, vCores:10> available, release resources=true
2013-08-28 16:00:30,612 INFO org.apache.hadoop.yarn.server.resourcemanager.scheduler.capacity.LeafQueue: default used=<memory:48128, vCores:42> numContainers=42 user=ubuntu user-resources=<memory:48128, vCores:42>
2013-08-28 16:00:30,613 INFO org.apache.hadoop.yarn.server.resourcemanager.rmcontainer.RMContainerImpl: container_1377704542759_0006_01_000029 Container Transitioned from ALLOCATED to ACQUIRED
2013-08-28 16:00:30,614 INFO org.apache.hadoop.yarn.server.resourcemanager.scheduler.capacity.LeafQueue: completedContainer container=Container: [ContainerId: container_1377704542759_0008_01_000025, NodeId: hadoop-16-7:53595, NodeHttpAddress: hadoop-16-7:8042, Resource: <memory:1024, vCores:1>, Priority: 20, State: NEW, Token: null, Status: container_id {, app_attempt_id {, application_id {, id: 8, cluster_timestamp: 1377704542759, }, attemptId: 1, }, id: 25, }, state: C_COMPLETE, diagnostics: "Container killed by the ApplicationMaster.\n\n", exit_status: 143, ] resource=<memory:1024, vCores:1> queue=default: capacity=1.0, absoluteCapacity=1.0, usedResources=<memory:48128, vCores:42>usedCapacity=0.9791667, absoluteUsedCapacity=0.9791667, numApps=5, numContainers=42 usedCapacity=0.9791667 absoluteUsedCapacity=0.9791667 used=<memory:48128, vCores:42> cluster=<memory:49152, vCores:96>
2013-08-28 16:00:30,615 INFO org.apache.hadoop.yarn.server.resourcemanager.scheduler.capacity.ParentQueue: completedContainer queue=root usedCapacity=0.9791667 absoluteUsedCapacity=0.9791667 used=<memory:48128, vCores:42> cluster=<memory:49152, vCores:96>
2013-08-28 16:00:30,615 INFO org.apache.hadoop.yarn.server.resourcemanager.scheduler.capacity.CapacityScheduler: Application appattempt_1377704542759_0008_000001 released container container_1377704542759_0008_01_000025 on node: host: hadoop-16-7:53595 #containers=6 available=1024 used=7168 with event: FINISHED
2013-08-28 16:00:30,615 INFO org.apache.hadoop.yarn.server.resourcemanager.rmcontainer.RMContainerImpl: container_1377704542759_0006_01_000030 Container Transitioned from NEW to ALLOCATED
2013-08-28 16:00:30,616 INFO org.apache.hadoop.yarn.server.resourcemanager.RMAuditLogger: USER=ubuntu	OPERATION=AM Allocated Container	TARGET=SchedulerApp	RESULT=SUCCESS	APPID=application_1377704542759_0006	CONTAINERID=container_1377704542759_0006_01_000030
2013-08-28 16:00:30,616 INFO org.apache.hadoop.yarn.server.resourcemanager.scheduler.common.fica.FiCaSchedulerNode: Assigned container container_1377704542759_0006_01_000030 of capacity <memory:1024, vCores:1> on host hadoop-16-7:53595, which currently has 7 containers, <memory:8192, vCores:7> used and <memory:0, vCores:9> available
2013-08-28 16:00:30,616 INFO org.apache.hadoop.yarn.server.resourcemanager.scheduler.capacity.LeafQueue: assignedContainer application=application_1377704542759_0006 container=Container: [ContainerId: container_1377704542759_0006_01_000030, NodeId: hadoop-16-7:53595, NodeHttpAddress: hadoop-16-7:8042, Resource: <memory:1024, vCores:1>, Priority: 20, State: NEW, Token: null, Status: container_id {, app_attempt_id {, application_id {, id: 6, cluster_timestamp: 1377704542759, }, attemptId: 1, }, id: 30, }, state: C_NEW, ] containerId=container_1377704542759_0006_01_000030 queue=default: capacity=1.0, absoluteCapacity=1.0, usedResources=<memory:48128, vCores:42>usedCapacity=0.9791667, absoluteUsedCapacity=0.9791667, numApps=5, numContainers=42 usedCapacity=0.9791667 absoluteUsedCapacity=0.9791667 used=<memory:48128, vCores:42> cluster=<memory:49152, vCores:96>
2013-08-28 16:00:30,617 INFO org.apache.hadoop.yarn.server.resourcemanager.scheduler.capacity.ParentQueue: Re-sorting queues since queue: root.default stats: default: capacity=1.0, absoluteCapacity=1.0, usedResources=<memory:49152, vCores:43>usedCapacity=1.0, absoluteUsedCapacity=1.0, numApps=5, numContainers=43
2013-08-28 16:00:30,617 INFO org.apache.hadoop.yarn.server.resourcemanager.scheduler.capacity.ParentQueue: assignedContainer queue=root usedCapacity=1.0 absoluteUsedCapacity=1.0 used=<memory:49152, vCores:43> cluster=<memory:49152, vCores:96>
2013-08-28 16:00:31,355 INFO org.apache.hadoop.yarn.server.resourcemanager.rmcontainer.RMContainerImpl: container_1377704542759_0006_01_000029 Container Transitioned from ACQUIRED to RUNNING
2013-08-28 16:00:31,626 INFO org.apache.hadoop.yarn.server.resourcemanager.rmcontainer.RMContainerImpl: container_1377704542759_0006_01_000030 Container Transitioned from ALLOCATED to ACQUIRED
2013-08-28 16:00:32,621 INFO org.apache.hadoop.yarn.server.resourcemanager.rmcontainer.RMContainerImpl: container_1377704542759_0006_01_000030 Container Transitioned from ACQUIRED to RUNNING
2013-08-28 16:00:33,003 INFO org.apache.hadoop.yarn.server.resourcemanager.rmcontainer.RMContainerImpl: container_1377704542759_0008_01_000005 Container Transitioned from RUNNING to COMPLETED
2013-08-28 16:00:33,004 INFO org.apache.hadoop.yarn.server.resourcemanager.scheduler.common.fica.FiCaSchedulerApp: Completed container: container_1377704542759_0008_01_000005 in state: COMPLETED event:FINISHED
2013-08-28 16:00:33,004 INFO org.apache.hadoop.yarn.server.resourcemanager.RMAuditLogger: USER=ubuntu	OPERATION=AM Released Container	TARGET=SchedulerApp	RESULT=SUCCESS	APPID=application_1377704542759_0008	CONTAINERID=container_1377704542759_0008_01_000005
2013-08-28 16:00:33,004 INFO org.apache.hadoop.yarn.server.resourcemanager.scheduler.common.fica.FiCaSchedulerNode: Released container container_1377704542759_0008_01_000005 of capacity <memory:1024, vCores:1> on host hadoop-16-2:39317, which currently has 7 containers, <memory:7168, vCores:7> used and <memory:1024, vCores:9> available, release resources=true
2013-08-28 16:00:33,004 INFO org.apache.hadoop.yarn.server.resourcemanager.scheduler.capacity.LeafQueue: default used=<memory:48128, vCores:42> numContainers=42 user=ubuntu user-resources=<memory:48128, vCores:42>
2013-08-28 16:00:33,005 INFO org.apache.hadoop.yarn.server.resourcemanager.scheduler.capacity.LeafQueue: completedContainer container=Container: [ContainerId: container_1377704542759_0008_01_000005, NodeId: hadoop-16-2:39317, NodeHttpAddress: hadoop-16-2:8042, Resource: <memory:1024, vCores:1>, Priority: 20, State: NEW, Token: null, Status: container_id {, app_attempt_id {, application_id {, id: 8, cluster_timestamp: 1377704542759, }, attemptId: 1, }, id: 5, }, state: C_COMPLETE, diagnostics: "Container killed by the ApplicationMaster.\n\n", exit_status: 143, ] resource=<memory:1024, vCores:1> queue=default: capacity=1.0, absoluteCapacity=1.0, usedResources=<memory:48128, vCores:42>usedCapacity=0.9791667, absoluteUsedCapacity=0.9791667, numApps=5, numContainers=42 usedCapacity=0.9791667 absoluteUsedCapacity=0.9791667 used=<memory:48128, vCores:42> cluster=<memory:49152, vCores:96>
2013-08-28 16:00:33,005 INFO org.apache.hadoop.yarn.server.resourcemanager.scheduler.capacity.ParentQueue: completedContainer queue=root usedCapacity=0.9791667 absoluteUsedCapacity=0.9791667 used=<memory:48128, vCores:42> cluster=<memory:49152, vCores:96>
2013-08-28 16:00:33,006 INFO org.apache.hadoop.yarn.server.resourcemanager.scheduler.capacity.CapacityScheduler: Application appattempt_1377704542759_0008_000001 released container container_1377704542759_0008_01_000005 on node: host: hadoop-16-2:39317 #containers=7 available=1024 used=7168 with event: FINISHED
2013-08-28 16:00:33,006 INFO org.apache.hadoop.yarn.server.resourcemanager.rmcontainer.RMContainerImpl: container_1377704542759_0006_01_000031 Container Transitioned from NEW to ALLOCATED
2013-08-28 16:00:33,006 INFO org.apache.hadoop.yarn.server.resourcemanager.RMAuditLogger: USER=ubuntu	OPERATION=AM Allocated Container	TARGET=SchedulerApp	RESULT=SUCCESS	APPID=application_1377704542759_0006	CONTAINERID=container_1377704542759_0006_01_000031
2013-08-28 16:00:33,006 INFO org.apache.hadoop.yarn.server.resourcemanager.scheduler.common.fica.FiCaSchedulerNode: Assigned container container_1377704542759_0006_01_000031 of capacity <memory:1024, vCores:1> on host hadoop-16-2:39317, which currently has 8 containers, <memory:8192, vCores:8> used and <memory:0, vCores:8> available
2013-08-28 16:00:33,007 INFO org.apache.hadoop.yarn.server.resourcemanager.scheduler.capacity.LeafQueue: assignedContainer application=application_1377704542759_0006 container=Container: [ContainerId: container_1377704542759_0006_01_000031, NodeId: hadoop-16-2:39317, NodeHttpAddress: hadoop-16-2:8042, Resource: <memory:1024, vCores:1>, Priority: 20, State: NEW, Token: null, Status: container_id {, app_attempt_id {, application_id {, id: 6, cluster_timestamp: 1377704542759, }, attemptId: 1, }, id: 31, }, state: C_NEW, ] containerId=container_1377704542759_0006_01_000031 queue=default: capacity=1.0, absoluteCapacity=1.0, usedResources=<memory:48128, vCores:42>usedCapacity=0.9791667, absoluteUsedCapacity=0.9791667, numApps=5, numContainers=42 usedCapacity=0.9791667 absoluteUsedCapacity=0.9791667 used=<memory:48128, vCores:42> cluster=<memory:49152, vCores:96>
2013-08-28 16:00:33,007 INFO org.apache.hadoop.yarn.server.resourcemanager.scheduler.capacity.ParentQueue: Re-sorting queues since queue: root.default stats: default: capacity=1.0, absoluteCapacity=1.0, usedResources=<memory:49152, vCores:43>usedCapacity=1.0, absoluteUsedCapacity=1.0, numApps=5, numContainers=43
2013-08-28 16:00:33,008 INFO org.apache.hadoop.yarn.server.resourcemanager.scheduler.capacity.ParentQueue: assignedContainer queue=root usedCapacity=1.0 absoluteUsedCapacity=1.0 used=<memory:49152, vCores:43> cluster=<memory:49152, vCores:96>
2013-08-28 16:00:33,638 INFO org.apache.hadoop.yarn.server.resourcemanager.rmcontainer.RMContainerImpl: container_1377704542759_0006_01_000031 Container Transitioned from ALLOCATED to ACQUIRED
2013-08-28 16:00:34,011 INFO org.apache.hadoop.yarn.server.resourcemanager.rmcontainer.RMContainerImpl: container_1377704542759_0006_01_000031 Container Transitioned from ACQUIRED to RUNNING
2013-08-28 16:00:34,989 INFO org.apache.hadoop.yarn.server.resourcemanager.rmcontainer.RMContainerImpl: container_1377704542759_0006_01_000003 Container Transitioned from RUNNING to COMPLETED
2013-08-28 16:00:34,989 INFO org.apache.hadoop.yarn.server.resourcemanager.scheduler.common.fica.FiCaSchedulerApp: Completed container: container_1377704542759_0006_01_000003 in state: COMPLETED event:FINISHED
2013-08-28 16:00:34,989 INFO org.apache.hadoop.yarn.server.resourcemanager.RMAuditLogger: USER=ubuntu	OPERATION=AM Released Container	TARGET=SchedulerApp	RESULT=SUCCESS	APPID=application_1377704542759_0006	CONTAINERID=container_1377704542759_0006_01_000003
2013-08-28 16:00:34,990 INFO org.apache.hadoop.yarn.server.resourcemanager.scheduler.common.fica.FiCaSchedulerNode: Released container container_1377704542759_0006_01_000003 of capacity <memory:1024, vCores:1> on host hadoop-16-6:36337, which currently has 6 containers, <memory:7168, vCores:6> used and <memory:1024, vCores:10> available, release resources=true
2013-08-28 16:00:34,990 INFO org.apache.hadoop.yarn.server.resourcemanager.scheduler.capacity.LeafQueue: default used=<memory:48128, vCores:42> numContainers=42 user=ubuntu user-resources=<memory:48128, vCores:42>
2013-08-28 16:00:34,991 INFO org.apache.hadoop.yarn.server.resourcemanager.scheduler.capacity.LeafQueue: completedContainer container=Container: [ContainerId: container_1377704542759_0006_01_000003, NodeId: hadoop-16-6:36337, NodeHttpAddress: hadoop-16-6:8042, Resource: <memory:1024, vCores:1>, Priority: 20, State: NEW, Token: null, Status: container_id {, app_attempt_id {, application_id {, id: 6, cluster_timestamp: 1377704542759, }, attemptId: 1, }, id: 3, }, state: C_COMPLETE, diagnostics: "", exit_status: 0, ] resource=<memory:1024, vCores:1> queue=default: capacity=1.0, absoluteCapacity=1.0, usedResources=<memory:48128, vCores:42>usedCapacity=0.9791667, absoluteUsedCapacity=0.9791667, numApps=5, numContainers=42 usedCapacity=0.9791667 absoluteUsedCapacity=0.9791667 used=<memory:48128, vCores:42> cluster=<memory:49152, vCores:96>
2013-08-28 16:00:34,991 INFO org.apache.hadoop.yarn.server.resourcemanager.scheduler.capacity.ParentQueue: completedContainer queue=root usedCapacity=0.9791667 absoluteUsedCapacity=0.9791667 used=<memory:48128, vCores:42> cluster=<memory:49152, vCores:96>
2013-08-28 16:00:34,991 INFO org.apache.hadoop.yarn.server.resourcemanager.scheduler.capacity.CapacityScheduler: Application appattempt_1377704542759_0006_000001 released container container_1377704542759_0006_01_000003 on node: host: hadoop-16-6:36337 #containers=6 available=1024 used=7168 with event: FINISHED
2013-08-28 16:00:34,992 INFO org.apache.hadoop.yarn.server.resourcemanager.rmcontainer.RMContainerImpl: container_1377704542759_0006_01_000032 Container Transitioned from NEW to ALLOCATED
2013-08-28 16:00:34,992 INFO org.apache.hadoop.yarn.server.resourcemanager.RMAuditLogger: USER=ubuntu	OPERATION=AM Allocated Container	TARGET=SchedulerApp	RESULT=SUCCESS	APPID=application_1377704542759_0006	CONTAINERID=container_1377704542759_0006_01_000032
2013-08-28 16:00:34,992 INFO org.apache.hadoop.yarn.server.resourcemanager.scheduler.common.fica.FiCaSchedulerNode: Assigned container container_1377704542759_0006_01_000032 of capacity <memory:1024, vCores:1> on host hadoop-16-6:36337, which currently has 7 containers, <memory:8192, vCores:7> used and <memory:0, vCores:9> available
2013-08-28 16:00:34,993 INFO org.apache.hadoop.yarn.server.resourcemanager.scheduler.capacity.LeafQueue: assignedContainer application=application_1377704542759_0006 container=Container: [ContainerId: container_1377704542759_0006_01_000032, NodeId: hadoop-16-6:36337, NodeHttpAddress: hadoop-16-6:8042, Resource: <memory:1024, vCores:1>, Priority: 20, State: NEW, Token: null, Status: container_id {, app_attempt_id {, application_id {, id: 6, cluster_timestamp: 1377704542759, }, attemptId: 1, }, id: 32, }, state: C_NEW, ] containerId=container_1377704542759_0006_01_000032 queue=default: capacity=1.0, absoluteCapacity=1.0, usedResources=<memory:48128, vCores:42>usedCapacity=0.9791667, absoluteUsedCapacity=0.9791667, numApps=5, numContainers=42 usedCapacity=0.9791667 absoluteUsedCapacity=0.9791667 used=<memory:48128, vCores:42> cluster=<memory:49152, vCores:96>
2013-08-28 16:00:34,993 INFO org.apache.hadoop.yarn.server.resourcemanager.scheduler.capacity.ParentQueue: Re-sorting queues since queue: root.default stats: default: capacity=1.0, absoluteCapacity=1.0, usedResources=<memory:49152, vCores:43>usedCapacity=1.0, absoluteUsedCapacity=1.0, numApps=5, numContainers=43
2013-08-28 16:00:34,994 INFO org.apache.hadoop.yarn.server.resourcemanager.scheduler.capacity.ParentQueue: assignedContainer queue=root usedCapacity=1.0 absoluteUsedCapacity=1.0 used=<memory:49152, vCores:43> cluster=<memory:49152, vCores:96>
2013-08-28 16:00:35,656 INFO org.apache.hadoop.yarn.server.resourcemanager.rmcontainer.RMContainerImpl: container_1377704542759_0006_01_000032 Container Transitioned from ALLOCATED to ACQUIRED
2013-08-28 16:00:35,998 INFO org.apache.hadoop.yarn.server.resourcemanager.rmcontainer.RMContainerImpl: container_1377704542759_0006_01_000032 Container Transitioned from ACQUIRED to RUNNING
2013-08-28 16:00:39,087 INFO org.apache.hadoop.yarn.server.resourcemanager.rmcontainer.RMContainerImpl: container_1377704542759_0006_01_000016 Container Transitioned from RUNNING to COMPLETED
2013-08-28 16:00:39,087 INFO org.apache.hadoop.yarn.server.resourcemanager.scheduler.common.fica.FiCaSchedulerApp: Completed container: container_1377704542759_0006_01_000016 in state: COMPLETED event:FINISHED
2013-08-28 16:00:39,088 INFO org.apache.hadoop.yarn.server.resourcemanager.RMAuditLogger: USER=ubuntu	OPERATION=AM Released Container	TARGET=SchedulerApp	RESULT=SUCCESS	APPID=application_1377704542759_0006	CONTAINERID=container_1377704542759_0006_01_000016
2013-08-28 16:00:39,088 INFO org.apache.hadoop.yarn.server.resourcemanager.scheduler.common.fica.FiCaSchedulerNode: Released container container_1377704542759_0006_01_000016 of capacity <memory:1024, vCores:1> on host hadoop-16-3:41896, which currently has 6 containers, <memory:7168, vCores:6> used and <memory:1024, vCores:10> available, release resources=true
2013-08-28 16:00:39,088 INFO org.apache.hadoop.yarn.server.resourcemanager.scheduler.capacity.LeafQueue: default used=<memory:48128, vCores:42> numContainers=42 user=ubuntu user-resources=<memory:48128, vCores:42>
2013-08-28 16:00:39,089 INFO org.apache.hadoop.yarn.server.resourcemanager.scheduler.capacity.LeafQueue: completedContainer container=Container: [ContainerId: container_1377704542759_0006_01_000016, NodeId: hadoop-16-3:41896, NodeHttpAddress: hadoop-16-3:8042, Resource: <memory:1024, vCores:1>, Priority: 20, State: NEW, Token: null, Status: container_id {, app_attempt_id {, application_id {, id: 6, cluster_timestamp: 1377704542759, }, attemptId: 1, }, id: 16, }, state: C_COMPLETE, diagnostics: "Container killed by the ApplicationMaster.\n\n", exit_status: 143, ] resource=<memory:1024, vCores:1> queue=default: capacity=1.0, absoluteCapacity=1.0, usedResources=<memory:48128, vCores:42>usedCapacity=0.9791667, absoluteUsedCapacity=0.9791667, numApps=5, numContainers=42 usedCapacity=0.9791667 absoluteUsedCapacity=0.9791667 used=<memory:48128, vCores:42> cluster=<memory:49152, vCores:96>
2013-08-28 16:00:39,089 INFO org.apache.hadoop.yarn.server.resourcemanager.scheduler.capacity.ParentQueue: completedContainer queue=root usedCapacity=0.9791667 absoluteUsedCapacity=0.9791667 used=<memory:48128, vCores:42> cluster=<memory:49152, vCores:96>
2013-08-28 16:00:39,090 INFO org.apache.hadoop.yarn.server.resourcemanager.scheduler.capacity.CapacityScheduler: Application appattempt_1377704542759_0006_000001 released container container_1377704542759_0006_01_000016 on node: host: hadoop-16-3:41896 #containers=6 available=1024 used=7168 with event: FINISHED
2013-08-28 16:00:39,090 INFO org.apache.hadoop.yarn.server.resourcemanager.rmcontainer.RMContainerImpl: container_1377704542759_0006_01_000033 Container Transitioned from NEW to ALLOCATED
2013-08-28 16:00:39,090 INFO org.apache.hadoop.yarn.server.resourcemanager.RMAuditLogger: USER=ubuntu	OPERATION=AM Allocated Container	TARGET=SchedulerApp	RESULT=SUCCESS	APPID=application_1377704542759_0006	CONTAINERID=container_1377704542759_0006_01_000033
2013-08-28 16:00:39,090 INFO org.apache.hadoop.yarn.server.resourcemanager.scheduler.common.fica.FiCaSchedulerNode: Assigned container container_1377704542759_0006_01_000033 of capacity <memory:1024, vCores:1> on host hadoop-16-3:41896, which currently has 7 containers, <memory:8192, vCores:7> used and <memory:0, vCores:9> available
2013-08-28 16:00:39,091 INFO org.apache.hadoop.yarn.server.resourcemanager.scheduler.capacity.LeafQueue: assignedContainer application=application_1377704542759_0006 container=Container: [ContainerId: container_1377704542759_0006_01_000033, NodeId: hadoop-16-3:41896, NodeHttpAddress: hadoop-16-3:8042, Resource: <memory:1024, vCores:1>, Priority: 20, State: NEW, Token: null, Status: container_id {, app_attempt_id {, application_id {, id: 6, cluster_timestamp: 1377704542759, }, attemptId: 1, }, id: 33, }, state: C_NEW, ] containerId=container_1377704542759_0006_01_000033 queue=default: capacity=1.0, absoluteCapacity=1.0, usedResources=<memory:48128, vCores:42>usedCapacity=0.9791667, absoluteUsedCapacity=0.9791667, numApps=5, numContainers=42 usedCapacity=0.9791667 absoluteUsedCapacity=0.9791667 used=<memory:48128, vCores:42> cluster=<memory:49152, vCores:96>
2013-08-28 16:00:39,091 INFO org.apache.hadoop.yarn.server.resourcemanager.scheduler.capacity.ParentQueue: Re-sorting queues since queue: root.default stats: default: capacity=1.0, absoluteCapacity=1.0, usedResources=<memory:49152, vCores:43>usedCapacity=1.0, absoluteUsedCapacity=1.0, numApps=5, numContainers=43
2013-08-28 16:00:39,092 INFO org.apache.hadoop.yarn.server.resourcemanager.scheduler.capacity.ParentQueue: assignedContainer queue=root usedCapacity=1.0 absoluteUsedCapacity=1.0 used=<memory:49152, vCores:43> cluster=<memory:49152, vCores:96>
2013-08-28 16:00:39,247 INFO org.apache.hadoop.yarn.server.resourcemanager.rmcontainer.RMContainerImpl: container_1377704542759_0008_01_000024 Container Transitioned from RUNNING to COMPLETED
2013-08-28 16:00:39,247 INFO org.apache.hadoop.yarn.server.resourcemanager.scheduler.common.fica.FiCaSchedulerApp: Completed container: container_1377704542759_0008_01_000024 in state: COMPLETED event:FINISHED
2013-08-28 16:00:39,247 INFO org.apache.hadoop.yarn.server.resourcemanager.RMAuditLogger: USER=ubuntu	OPERATION=AM Released Container	TARGET=SchedulerApp	RESULT=SUCCESS	APPID=application_1377704542759_0008	CONTAINERID=container_1377704542759_0008_01_000024
2013-08-28 16:00:39,247 INFO org.apache.hadoop.yarn.server.resourcemanager.scheduler.common.fica.FiCaSchedulerNode: Released container container_1377704542759_0008_01_000024 of capacity <memory:1024, vCores:1> on host hadoop-16-7:53595, which currently has 6 containers, <memory:7168, vCores:6> used and <memory:1024, vCores:10> available, release resources=true
2013-08-28 16:00:39,247 INFO org.apache.hadoop.yarn.server.resourcemanager.scheduler.capacity.LeafQueue: default used=<memory:48128, vCores:42> numContainers=42 user=ubuntu user-resources=<memory:48128, vCores:42>
2013-08-28 16:00:39,249 INFO org.apache.hadoop.yarn.server.resourcemanager.scheduler.capacity.LeafQueue: completedContainer container=Container: [ContainerId: container_1377704542759_0008_01_000024, NodeId: hadoop-16-7:53595, NodeHttpAddress: hadoop-16-7:8042, Resource: <memory:1024, vCores:1>, Priority: 20, State: NEW, Token: null, Status: container_id {, app_attempt_id {, application_id {, id: 8, cluster_timestamp: 1377704542759, }, attemptId: 1, }, id: 24, }, state: C_COMPLETE, diagnostics: "Container killed by the ApplicationMaster.\n\n", exit_status: 143, ] resource=<memory:1024, vCores:1> queue=default: capacity=1.0, absoluteCapacity=1.0, usedResources=<memory:48128, vCores:42>usedCapacity=0.9791667, absoluteUsedCapacity=0.9791667, numApps=5, numContainers=42 usedCapacity=0.9791667 absoluteUsedCapacity=0.9791667 used=<memory:48128, vCores:42> cluster=<memory:49152, vCores:96>
2013-08-28 16:00:39,249 INFO org.apache.hadoop.yarn.server.resourcemanager.scheduler.capacity.ParentQueue: completedContainer queue=root usedCapacity=0.9791667 absoluteUsedCapacity=0.9791667 used=<memory:48128, vCores:42> cluster=<memory:49152, vCores:96>
2013-08-28 16:00:39,249 INFO org.apache.hadoop.yarn.server.resourcemanager.scheduler.capacity.CapacityScheduler: Application appattempt_1377704542759_0008_000001 released container container_1377704542759_0008_01_000024 on node: host: hadoop-16-7:53595 #containers=6 available=1024 used=7168 with event: FINISHED
2013-08-28 16:00:39,249 INFO org.apache.hadoop.yarn.server.resourcemanager.rmcontainer.RMContainerImpl: container_1377704542759_0006_01_000034 Container Transitioned from NEW to ALLOCATED
2013-08-28 16:00:39,250 INFO org.apache.hadoop.yarn.server.resourcemanager.RMAuditLogger: USER=ubuntu	OPERATION=AM Allocated Container	TARGET=SchedulerApp	RESULT=SUCCESS	APPID=application_1377704542759_0006	CONTAINERID=container_1377704542759_0006_01_000034
2013-08-28 16:00:39,250 INFO org.apache.hadoop.yarn.server.resourcemanager.scheduler.common.fica.FiCaSchedulerNode: Assigned container container_1377704542759_0006_01_000034 of capacity <memory:1024, vCores:1> on host hadoop-16-7:53595, which currently has 7 containers, <memory:8192, vCores:7> used and <memory:0, vCores:9> available
2013-08-28 16:00:39,251 INFO org.apache.hadoop.yarn.server.resourcemanager.scheduler.capacity.LeafQueue: assignedContainer application=application_1377704542759_0006 container=Container: [ContainerId: container_1377704542759_0006_01_000034, NodeId: hadoop-16-7:53595, NodeHttpAddress: hadoop-16-7:8042, Resource: <memory:1024, vCores:1>, Priority: 20, State: NEW, Token: null, Status: container_id {, app_attempt_id {, application_id {, id: 6, cluster_timestamp: 1377704542759, }, attemptId: 1, }, id: 34, }, state: C_NEW, ] containerId=container_1377704542759_0006_01_000034 queue=default: capacity=1.0, absoluteCapacity=1.0, usedResources=<memory:48128, vCores:42>usedCapacity=0.9791667, absoluteUsedCapacity=0.9791667, numApps=5, numContainers=42 usedCapacity=0.9791667 absoluteUsedCapacity=0.9791667 used=<memory:48128, vCores:42> cluster=<memory:49152, vCores:96>
2013-08-28 16:00:39,251 INFO org.apache.hadoop.yarn.server.resourcemanager.scheduler.capacity.ParentQueue: Re-sorting queues since queue: root.default stats: default: capacity=1.0, absoluteCapacity=1.0, usedResources=<memory:49152, vCores:43>usedCapacity=1.0, absoluteUsedCapacity=1.0, numApps=5, numContainers=43
