2013-08-07 07:05:05,360 INFO org.apache.hadoop.yarn.server.resourcemanager.ResourceManager: STARTUP_MSG: 
/************************************************************
STARTUP_MSG: Starting ResourceManager
STARTUP_MSG:   host = hadoop-200-1/192.168.100.2
STARTUP_MSG:   args = []
STARTUP_MSG:   version = 3.0.0-SNAPSHOT
STARTUP_MSG:   build = https://github.com/lalithsuresh/hadoop-common -r 0cb423bd4868928bb06cd93f882bb0913172fd17; compiled by 'lsuresh' on 2013-04-08T15:47Z
STARTUP_MSG:   java = 1.7.0_17
************************************************************/
2013-08-07 07:05:05,375 INFO org.apache.hadoop.yarn.server.resourcemanager.ResourceManager: registered UNIX signal handlers for [TERM, HUP, INT]
2013-08-07 07:05:06,097 INFO org.apache.hadoop.yarn.server.resourcemanager.security.ApplicationTokenSecretManager: Rolling master-key for application-tokens
2013-08-07 07:05:06,145 INFO org.apache.hadoop.yarn.server.resourcemanager.security.RMContainerTokenSecretManager: ContainerTokenKeyRollingInterval: 86400000ms and ContainerTokenKeyActivationDelay: 900000ms
2013-08-07 07:05:06,147 INFO org.apache.hadoop.yarn.service.AbstractService: Service:Dispatcher is inited.
2013-08-07 07:05:06,148 INFO org.apache.hadoop.yarn.event.AsyncDispatcher: Registering class org.apache.hadoop.yarn.server.resourcemanager.recovery.RMStateStoreEventType for class org.apache.hadoop.yarn.server.resourcemanager.recovery.RMStateStore$ForwardingEventHandler
2013-08-07 07:05:06,149 INFO org.apache.hadoop.yarn.service.AbstractService: Service:Dispatcher is started.
2013-08-07 07:05:06,158 INFO org.apache.hadoop.yarn.event.AsyncDispatcher: Registering class org.apache.hadoop.yarn.server.resourcemanager.NodesListManagerEventType for class org.apache.hadoop.yarn.server.resourcemanager.NodesListManager
2013-08-07 07:05:06,158 INFO org.apache.hadoop.yarn.server.resourcemanager.ResourceManager: Using Scheduler: org.apache.hadoop.yarn.server.resourcemanager.scheduler.capacity.CapacityScheduler
2013-08-07 07:05:06,366 INFO org.apache.hadoop.yarn.event.AsyncDispatcher: Registering class org.apache.hadoop.yarn.server.resourcemanager.scheduler.event.SchedulerEventType for class org.apache.hadoop.yarn.server.resourcemanager.ResourceManager$SchedulerEventDispatcher
2013-08-07 07:05:06,368 INFO org.apache.hadoop.yarn.event.AsyncDispatcher: Registering class org.apache.hadoop.yarn.server.resourcemanager.rmapp.RMAppEventType for class org.apache.hadoop.yarn.server.resourcemanager.ResourceManager$ApplicationEventDispatcher
2013-08-07 07:05:06,370 INFO org.apache.hadoop.yarn.event.AsyncDispatcher: Registering class org.apache.hadoop.yarn.server.resourcemanager.rmapp.attempt.RMAppAttemptEventType for class org.apache.hadoop.yarn.server.resourcemanager.ResourceManager$ApplicationAttemptEventDispatcher
2013-08-07 07:05:06,371 INFO org.apache.hadoop.yarn.event.AsyncDispatcher: Registering class org.apache.hadoop.yarn.server.resourcemanager.rmnode.RMNodeEventType for class org.apache.hadoop.yarn.server.resourcemanager.ResourceManager$NodeEventDispatcher
2013-08-07 07:05:07,082 WARN org.apache.hadoop.util.NativeCodeLoader: Unable to load native-hadoop library for your platform... using builtin-java classes where applicable
2013-08-07 07:05:07,147 INFO org.apache.hadoop.yarn.server.resourcemanager.scheduler.capacity.ParentQueue: root, capacity=1.0, asboluteCapacity=1.0, maxCapacity=1.0, asboluteMaxCapacity=1.0, state=RUNNING, acls=SUBMIT_APPLICATIONS:*ADMINISTER_QUEUE:*
2013-08-07 07:05:07,147 INFO org.apache.hadoop.yarn.server.resourcemanager.scheduler.capacity.ParentQueue: Initialized parent-queue root name=root, fullname=root
2013-08-07 07:05:07,169 INFO org.apache.hadoop.yarn.server.resourcemanager.scheduler.capacity.LeafQueue: Initializing default
capacity = 1.0 [= (float) configuredCapacity / 100 ]
asboluteCapacity = 1.0 [= parentAbsoluteCapacity * capacity ]
maxCapacity = 1.0 [= configuredMaxCapacity ]
absoluteMaxCapacity = 1.0 [= 1.0 maximumCapacity undefined, (parentAbsoluteMaxCapacity * maximumCapacity) / 100 otherwise ]
userLimit = 100 [= configuredUserLimit ]
userLimitFactor = 1.0 [= configuredUserLimitFactor ]
maxApplications = 10000 [= configuredMaximumSystemApplicationsPerQueue or (int)(configuredMaximumSystemApplications * absoluteCapacity)]
maxApplicationsPerUser = 10000 [= (int)(maxApplications * (userLimit / 100.0f) * userLimitFactor) ]
maxActiveApplications = 1 [= max((int)ceil((clusterResourceMemory / minimumAllocation) * maxAMResourcePerQueuePercent * absoluteMaxCapacity),1) ]
maxActiveAppsUsingAbsCap = 1 [= max((int)ceil((clusterResourceMemory / minimumAllocation) *maxAMResourcePercent * absoluteCapacity),1) ]
maxActiveApplicationsPerUser = 1 [= max((int)(maxActiveApplications * (userLimit / 100.0f) * userLimitFactor),1) ]
usedCapacity = 0.0 [= usedResourcesMemory / (clusterResourceMemory * absoluteCapacity)]
absoluteUsedCapacity = 0.0 [= usedResourcesMemory / clusterResourceMemory]
maxAMResourcePerQueuePercent = 0.1 [= configuredMaximumAMResourcePercent ]
minimumAllocationFactor = 0.875 [= (float)(maximumAllocationMemory - minimumAllocationMemory) / maximumAllocationMemory ]
numContainers = 0 [= currentNumContainers ]
state = RUNNING [= configuredState ]
acls = SUBMIT_APPLICATIONS:*ADMINISTER_QUEUE:* [= configuredAcls ]

2013-08-07 07:05:07,169 INFO org.apache.hadoop.yarn.server.resourcemanager.scheduler.capacity.CapacityScheduler: Initialized queue: default: capacity=1.0, absoluteCapacity=1.0, usedResources=<memory:0, vCores:0>usedCapacity=0.0, absoluteUsedCapacity=0.0, numApps=0, numContainers=0
2013-08-07 07:05:07,170 INFO org.apache.hadoop.yarn.server.resourcemanager.scheduler.capacity.CapacityScheduler: Initialized queue: root: numChildQueue= 1, capacity=1.0, absoluteCapacity=1.0, usedResources=<memory:0, vCores:0>usedCapacity=0.0, numApps=0, numContainers=0
2013-08-07 07:05:07,170 INFO org.apache.hadoop.yarn.server.resourcemanager.scheduler.capacity.CapacityScheduler: Initialized root queue root: numChildQueue= 1, capacity=1.0, absoluteCapacity=1.0, usedResources=<memory:0, vCores:0>usedCapacity=0.0, numApps=0, numContainers=0
2013-08-07 07:05:07,170 INFO org.apache.hadoop.yarn.server.resourcemanager.scheduler.capacity.CapacityScheduler: Initialized CapacityScheduler with calculator=class org.apache.hadoop.yarn.server.resourcemanager.resource.DefaultResourceCalculator, minimumAllocation=<<memory:1024, vCores:1>>, maximumAllocation=<<memory:8192, vCores:32>>
2013-08-07 07:05:07,652 INFO org.apache.hadoop.yarn.event.AsyncDispatcher: Registering class org.apache.hadoop.yarn.server.resourcemanager.RMAppManagerEventType for class org.apache.hadoop.yarn.server.resourcemanager.RMAppManager
2013-08-07 07:05:07,675 INFO org.apache.hadoop.yarn.event.AsyncDispatcher: Registering class org.apache.hadoop.yarn.server.resourcemanager.amlauncher.AMLauncherEventType for class org.apache.hadoop.yarn.server.resourcemanager.amlauncher.ApplicationMasterLauncher
2013-08-07 07:05:07,779 INFO org.apache.hadoop.yarn.server.resourcemanager.RMNMInfo: Registered RMNMInfo MBean
2013-08-07 07:05:07,779 INFO org.apache.hadoop.yarn.service.AbstractService: Service:Dispatcher is inited.
2013-08-07 07:05:07,779 INFO org.apache.hadoop.yarn.service.AbstractService: Service:org.apache.hadoop.yarn.server.resourcemanager.rmcontainer.ContainerAllocationExpirer is inited.
2013-08-07 07:05:07,779 INFO org.apache.hadoop.yarn.service.AbstractService: Service:AMLivelinessMonitor is inited.
2013-08-07 07:05:07,780 INFO org.apache.hadoop.yarn.service.AbstractService: Service:AMLivelinessMonitor is inited.
2013-08-07 07:05:07,780 INFO org.apache.hadoop.yarn.service.AbstractService: Service:org.apache.hadoop.yarn.server.resourcemanager.security.DelegationTokenRenewer is inited.
2013-08-07 07:05:07,782 INFO org.apache.hadoop.util.HostsFileReader: Refreshing hosts (include/exclude) list
2013-08-07 07:05:07,782 INFO org.apache.hadoop.yarn.service.AbstractService: Service:org.apache.hadoop.yarn.server.resourcemanager.NodesListManager is inited.
2013-08-07 07:05:07,782 INFO org.apache.hadoop.yarn.service.AbstractService: Service:org.apache.hadoop.yarn.server.resourcemanager.ResourceManager$SchedulerEventDispatcher is inited.
2013-08-07 07:05:07,782 INFO org.apache.hadoop.yarn.service.AbstractService: Service:NMLivelinessMonitor is inited.
2013-08-07 07:05:07,790 INFO org.apache.hadoop.yarn.service.AbstractService: Service:org.apache.hadoop.yarn.server.resourcemanager.ResourceTrackerService is inited.
2013-08-07 07:05:07,790 INFO org.apache.hadoop.yarn.service.AbstractService: Service:org.apache.hadoop.yarn.server.resourcemanager.ApplicationMasterService is inited.
2013-08-07 07:05:07,791 INFO org.apache.hadoop.yarn.service.AbstractService: Service:org.apache.hadoop.yarn.server.resourcemanager.ClientRMService is inited.
2013-08-07 07:05:07,791 INFO org.apache.hadoop.yarn.service.AbstractService: Service:org.apache.hadoop.yarn.server.resourcemanager.AdminService is inited.
2013-08-07 07:05:07,791 INFO org.apache.hadoop.yarn.service.AbstractService: Service:org.apache.hadoop.yarn.server.resourcemanager.amlauncher.ApplicationMasterLauncher is inited.
2013-08-07 07:05:07,791 INFO org.apache.hadoop.yarn.service.AbstractService: Service:ResourceManager is inited.
2013-08-07 07:05:07,792 INFO org.apache.hadoop.yarn.server.resourcemanager.security.RMContainerTokenSecretManager: Rolling master-key for container-tokens
2013-08-07 07:05:07,792 INFO org.apache.hadoop.yarn.server.resourcemanager.security.ApplicationTokenSecretManager: Rolling master-key for application-tokens
2013-08-07 07:05:07,960 INFO org.mortbay.log: Logging to org.slf4j.impl.Log4jLoggerAdapter(org.mortbay.log) via org.mortbay.log.Slf4jLog
2013-08-07 07:05:08,067 INFO org.apache.hadoop.http.HttpServer: Added global filter 'safety' (class=org.apache.hadoop.http.HttpServer$QuotingInputFilter)
2013-08-07 07:05:08,071 INFO org.apache.hadoop.http.HttpServer: Added filter static_user_filter (class=org.apache.hadoop.http.lib.StaticUserWebFilter$StaticUserFilter) to context cluster
2013-08-07 07:05:08,072 INFO org.apache.hadoop.http.HttpServer: Added filter static_user_filter (class=org.apache.hadoop.http.lib.StaticUserWebFilter$StaticUserFilter) to context static
2013-08-07 07:05:08,072 INFO org.apache.hadoop.http.HttpServer: Added filter static_user_filter (class=org.apache.hadoop.http.lib.StaticUserWebFilter$StaticUserFilter) to context logs
2013-08-07 07:05:08,079 INFO org.apache.hadoop.http.HttpServer: adding path spec: /cluster
2013-08-07 07:05:08,080 INFO org.apache.hadoop.http.HttpServer: adding path spec: /cluster/*
2013-08-07 07:05:08,080 INFO org.apache.hadoop.http.HttpServer: adding path spec: /ws
2013-08-07 07:05:08,080 INFO org.apache.hadoop.http.HttpServer: adding path spec: /ws/*
2013-08-07 07:05:08,083 INFO org.apache.hadoop.http.HttpServer: Added global filter 'guice' (class=com.google.inject.servlet.GuiceFilter)
2013-08-07 07:05:08,093 INFO org.apache.hadoop.http.HttpServer: Jetty bound to port 8088
2013-08-07 07:05:08,093 INFO org.mortbay.log: jetty-6.1.26
2013-08-07 07:05:08,148 INFO org.mortbay.log: Extract jar:file:/home/ubuntu/hadoop-3.0.0-SNAPSHOT/share/hadoop/yarn/hadoop-yarn-common-3.0.0-SNAPSHOT.jar!/webapps/cluster to /tmp/Jetty_0_0_0_0_8088_cluster____u0rgz3/webapp
2013-08-07 07:05:08,626 INFO org.mortbay.log: Started SelectChannelConnector@0.0.0.0:8088
2013-08-07 07:05:08,626 INFO org.apache.hadoop.yarn.webapp.WebApps: Web app /cluster started at 8088
2013-08-07 07:05:09,276 INFO org.apache.hadoop.yarn.webapp.WebApps: Registered webapp guice modules
2013-08-07 07:05:09,345 INFO org.apache.hadoop.metrics2.impl.MetricsConfig: loaded properties from hadoop-metrics2.properties
2013-08-07 07:05:09,368 INFO org.apache.hadoop.metrics2.impl.MetricsSystemImpl: Scheduled snapshot period at 10 second(s).
2013-08-07 07:05:09,368 INFO org.apache.hadoop.metrics2.impl.MetricsSystemImpl: ResourceManager metrics system started
2013-08-07 07:05:09,378 INFO org.apache.hadoop.security.token.delegation.AbstractDelegationTokenSecretManager: Updating the current master key for generating delegation tokens
2013-08-07 07:05:09,380 INFO org.apache.hadoop.yarn.service.AbstractService: Service:Dispatcher is started.
2013-08-07 07:05:09,380 INFO org.apache.hadoop.security.token.delegation.AbstractDelegationTokenSecretManager: Starting expired delegation token remover thread, tokenRemoverScanInterval=60 min(s)
2013-08-07 07:05:09,381 INFO org.apache.hadoop.security.token.delegation.AbstractDelegationTokenSecretManager: Updating the current master key for generating delegation tokens
2013-08-07 07:05:09,382 INFO org.apache.hadoop.yarn.service.AbstractService: Service:org.apache.hadoop.yarn.server.resourcemanager.rmcontainer.ContainerAllocationExpirer is started.
2013-08-07 07:05:09,382 INFO org.apache.hadoop.yarn.service.AbstractService: Service:AMLivelinessMonitor is started.
2013-08-07 07:05:09,383 INFO org.apache.hadoop.yarn.service.AbstractService: Service:AMLivelinessMonitor is started.
2013-08-07 07:05:09,383 INFO org.apache.hadoop.yarn.service.AbstractService: Service:org.apache.hadoop.yarn.server.resourcemanager.security.DelegationTokenRenewer is started.
2013-08-07 07:05:09,383 INFO org.apache.hadoop.yarn.service.AbstractService: Service:org.apache.hadoop.yarn.server.resourcemanager.NodesListManager is started.
2013-08-07 07:05:09,384 INFO org.apache.hadoop.yarn.service.AbstractService: Service:org.apache.hadoop.yarn.server.resourcemanager.ResourceManager$SchedulerEventDispatcher is started.
2013-08-07 07:05:09,385 INFO org.apache.hadoop.yarn.service.AbstractService: Service:NMLivelinessMonitor is started.
2013-08-07 07:05:09,385 INFO org.apache.hadoop.yarn.service.AbstractService: Service:org.apache.hadoop.yarn.server.resourcemanager.ResourceTrackerService is started.
2013-08-07 07:05:09,431 INFO org.apache.hadoop.ipc.Server: Starting Socket Reader #1 for port 54110
2013-08-07 07:05:09,457 INFO org.apache.hadoop.yarn.factories.impl.pb.RpcServerFactoryPBImpl: Adding protocol org.apache.hadoop.yarn.server.api.ResourceTrackerPB to the server
2013-08-07 07:05:09,458 INFO org.apache.hadoop.ipc.Server: IPC Server Responder: starting
2013-08-07 07:05:09,464 INFO org.apache.hadoop.ipc.Server: IPC Server listener on 54110: starting
2013-08-07 07:05:09,607 INFO org.apache.hadoop.ipc.Server: Starting Socket Reader #1 for port 54112
2013-08-07 07:05:09,619 INFO org.apache.hadoop.yarn.factories.impl.pb.RpcServerFactoryPBImpl: Adding protocol org.apache.hadoop.yarn.api.AMRMProtocolPB to the server
2013-08-07 07:05:09,621 INFO org.apache.hadoop.ipc.Server: IPC Server Responder: starting
2013-08-07 07:05:09,622 INFO org.apache.hadoop.ipc.Server: IPC Server listener on 54112: starting
2013-08-07 07:05:09,662 INFO org.apache.hadoop.yarn.service.AbstractService: Service:org.apache.hadoop.yarn.server.resourcemanager.ApplicationMasterService is started.
2013-08-07 07:05:09,710 INFO org.apache.hadoop.ipc.Server: Starting Socket Reader #1 for port 54111
2013-08-07 07:05:09,715 INFO org.apache.hadoop.yarn.factories.impl.pb.RpcServerFactoryPBImpl: Adding protocol org.apache.hadoop.yarn.api.ClientRMProtocolPB to the server
2013-08-07 07:05:09,717 INFO org.apache.hadoop.ipc.Server: IPC Server Responder: starting
2013-08-07 07:05:09,719 INFO org.apache.hadoop.ipc.Server: IPC Server listener on 54111: starting
2013-08-07 07:05:09,761 INFO org.apache.hadoop.yarn.service.AbstractService: Service:org.apache.hadoop.yarn.server.resourcemanager.ClientRMService is started.
2013-08-07 07:05:09,798 INFO org.apache.hadoop.ipc.Server: Starting Socket Reader #1 for port 8033
2013-08-07 07:05:09,814 INFO org.apache.hadoop.yarn.factories.impl.pb.RpcServerFactoryPBImpl: Adding protocol org.apache.hadoop.yarn.api.RMAdminProtocolPB to the server
2013-08-07 07:05:09,815 INFO org.apache.hadoop.ipc.Server: IPC Server Responder: starting
2013-08-07 07:05:09,815 INFO org.apache.hadoop.ipc.Server: IPC Server listener on 8033: starting
2013-08-07 07:05:09,829 INFO org.apache.hadoop.yarn.service.AbstractService: Service:org.apache.hadoop.yarn.server.resourcemanager.AdminService is started.
2013-08-07 07:05:09,829 INFO org.apache.hadoop.yarn.service.AbstractService: Service:org.apache.hadoop.yarn.server.resourcemanager.amlauncher.ApplicationMasterLauncher is started.
2013-08-07 07:05:09,829 INFO org.apache.hadoop.yarn.service.AbstractService: Service:ResourceManager is started.
2013-08-07 07:05:18,631 INFO org.apache.hadoop.yarn.util.RackResolver: Resolved hadoop-200-7 to /default-rack
2013-08-07 07:05:18,639 INFO org.apache.hadoop.yarn.server.resourcemanager.ResourceTrackerService: NodeManager from node hadoop-200-7(cmPort: 58499 httpPort: 8042) registered with capability: <memory:8192, vCores:16>, assigned nodeId hadoop-200-7:58499
2013-08-07 07:05:18,661 INFO org.apache.hadoop.yarn.server.resourcemanager.rmnode.RMNodeImpl: hadoop-200-7:58499 Node Transitioned from NEW to RUNNING
2013-08-07 07:05:18,665 INFO org.apache.hadoop.yarn.server.resourcemanager.scheduler.capacity.CapacityScheduler: Added node hadoop-200-7:58499 clusterResource: <memory:8192, vCores:16>
2013-08-07 07:05:19,246 INFO org.apache.hadoop.yarn.util.RackResolver: Resolved hadoop-200-3 to /default-rack
2013-08-07 07:05:19,247 INFO org.apache.hadoop.yarn.server.resourcemanager.ResourceTrackerService: NodeManager from node hadoop-200-3(cmPort: 55493 httpPort: 8042) registered with capability: <memory:8192, vCores:16>, assigned nodeId hadoop-200-3:55493
2013-08-07 07:05:19,248 INFO org.apache.hadoop.yarn.server.resourcemanager.rmnode.RMNodeImpl: hadoop-200-3:55493 Node Transitioned from NEW to RUNNING
2013-08-07 07:05:19,249 INFO org.apache.hadoop.yarn.server.resourcemanager.scheduler.capacity.CapacityScheduler: Added node hadoop-200-3:55493 clusterResource: <memory:16384, vCores:32>
2013-08-07 07:05:19,439 INFO org.apache.hadoop.yarn.util.RackResolver: Resolved hadoop-200-4 to /default-rack
2013-08-07 07:05:19,440 INFO org.apache.hadoop.yarn.server.resourcemanager.ResourceTrackerService: NodeManager from node hadoop-200-4(cmPort: 41828 httpPort: 8042) registered with capability: <memory:8192, vCores:16>, assigned nodeId hadoop-200-4:41828
2013-08-07 07:05:19,440 INFO org.apache.hadoop.yarn.server.resourcemanager.rmnode.RMNodeImpl: hadoop-200-4:41828 Node Transitioned from NEW to RUNNING
2013-08-07 07:05:19,441 INFO org.apache.hadoop.yarn.server.resourcemanager.scheduler.capacity.CapacityScheduler: Added node hadoop-200-4:41828 clusterResource: <memory:24576, vCores:48>
2013-08-07 07:05:19,534 INFO org.apache.hadoop.yarn.util.RackResolver: Resolved hadoop-200-5 to /default-rack
2013-08-07 07:05:19,534 INFO org.apache.hadoop.yarn.server.resourcemanager.ResourceTrackerService: NodeManager from node hadoop-200-5(cmPort: 52184 httpPort: 8042) registered with capability: <memory:8192, vCores:16>, assigned nodeId hadoop-200-5:52184
2013-08-07 07:05:19,535 INFO org.apache.hadoop.yarn.server.resourcemanager.rmnode.RMNodeImpl: hadoop-200-5:52184 Node Transitioned from NEW to RUNNING
2013-08-07 07:05:19,536 INFO org.apache.hadoop.yarn.server.resourcemanager.scheduler.capacity.CapacityScheduler: Added node hadoop-200-5:52184 clusterResource: <memory:32768, vCores:64>
2013-08-07 07:05:19,614 INFO org.apache.hadoop.yarn.util.RackResolver: Resolved hadoop-200-2 to /default-rack
2013-08-07 07:05:19,614 INFO org.apache.hadoop.yarn.server.resourcemanager.ResourceTrackerService: NodeManager from node hadoop-200-2(cmPort: 35087 httpPort: 8042) registered with capability: <memory:8192, vCores:16>, assigned nodeId hadoop-200-2:35087
2013-08-07 07:05:19,615 INFO org.apache.hadoop.yarn.server.resourcemanager.rmnode.RMNodeImpl: hadoop-200-2:35087 Node Transitioned from NEW to RUNNING
2013-08-07 07:05:19,616 INFO org.apache.hadoop.yarn.server.resourcemanager.scheduler.capacity.CapacityScheduler: Added node hadoop-200-2:35087 clusterResource: <memory:40960, vCores:80>
2013-08-07 07:05:19,949 INFO org.apache.hadoop.yarn.util.RackResolver: Resolved hadoop-200-6 to /default-rack
2013-08-07 07:05:19,950 INFO org.apache.hadoop.yarn.server.resourcemanager.ResourceTrackerService: NodeManager from node hadoop-200-6(cmPort: 34031 httpPort: 8042) registered with capability: <memory:8192, vCores:16>, assigned nodeId hadoop-200-6:34031
2013-08-07 07:05:19,950 INFO org.apache.hadoop.yarn.server.resourcemanager.rmnode.RMNodeImpl: hadoop-200-6:34031 Node Transitioned from NEW to RUNNING
2013-08-07 07:05:19,951 INFO org.apache.hadoop.yarn.server.resourcemanager.scheduler.capacity.CapacityScheduler: Added node hadoop-200-6:34031 clusterResource: <memory:49152, vCores:96>
2013-08-07 07:05:25,473 INFO org.apache.hadoop.yarn.server.resourcemanager.ClientRMService: Allocated new applicationId: 1
2013-08-07 07:05:28,915 INFO org.apache.hadoop.yarn.server.resourcemanager.ClientRMService: Storing Application with id application_1375859105306_0001
2013-08-07 07:05:28,918 INFO org.apache.hadoop.yarn.server.resourcemanager.recovery.RMStateStore: Storing info for app: application_1375859105306_0001
2013-08-07 07:05:28,923 INFO org.apache.hadoop.yarn.server.resourcemanager.ClientRMService: Application with id 1 submitted by user ubuntu
2013-08-07 07:05:28,927 INFO org.apache.hadoop.yarn.server.resourcemanager.RMAuditLogger: USER=ubuntu	IP=192.168.100.2	OPERATION=Submit Application Request	TARGET=ClientRMService	RESULT=SUCCESS	APPID=application_1375859105306_0001
2013-08-07 07:05:28,966 INFO org.apache.hadoop.yarn.server.resourcemanager.rmapp.RMAppImpl: application_1375859105306_0001 State change from NEW to SUBMITTED
2013-08-07 07:05:28,967 INFO org.apache.hadoop.yarn.server.resourcemanager.ApplicationMasterService: Registering appattempt_1375859105306_0001_000001
2013-08-07 07:05:28,968 INFO org.apache.hadoop.yarn.server.resourcemanager.rmapp.attempt.RMAppAttemptImpl: appattempt_1375859105306_0001_000001 State change from NEW to SUBMITTED
2013-08-07 07:05:29,005 INFO org.apache.hadoop.yarn.server.resourcemanager.scheduler.capacity.LeafQueue: Application application_1375859105306_0001 from user: ubuntu activated in queue: default
2013-08-07 07:05:29,005 INFO org.apache.hadoop.yarn.server.resourcemanager.scheduler.capacity.LeafQueue: Application added - appId: application_1375859105306_0001 user: org.apache.hadoop.yarn.server.resourcemanager.scheduler.capacity.LeafQueue$User@29a7584e, leaf-queue: default #user-pending-applications: 0 #user-active-applications: 1 #queue-pending-applications: 0 #queue-active-applications: 1
2013-08-07 07:05:29,005 INFO org.apache.hadoop.yarn.server.resourcemanager.scheduler.capacity.ParentQueue: Application added - appId: application_1375859105306_0001 user: ubuntu leaf-queue of parent: root #applications: 1
2013-08-07 07:05:29,006 INFO org.apache.hadoop.yarn.server.resourcemanager.scheduler.capacity.CapacityScheduler: Application Submission: appattempt_1375859105306_0001_000001, user: ubuntu queue: default: capacity=1.0, absoluteCapacity=1.0, usedResources=<memory:0, vCores:0>usedCapacity=0.0, absoluteUsedCapacity=0.0, numApps=1, numContainers=0, currently active: 1
2013-08-07 07:05:29,011 INFO org.apache.hadoop.yarn.server.resourcemanager.rmapp.attempt.RMAppAttemptImpl: appattempt_1375859105306_0001_000001 State change from SUBMITTED to SCHEDULED
2013-08-07 07:05:29,012 INFO org.apache.hadoop.yarn.server.resourcemanager.rmapp.RMAppImpl: application_1375859105306_0001 State change from SUBMITTED to ACCEPTED
2013-08-07 07:05:29,098 INFO org.apache.hadoop.yarn.server.resourcemanager.rmcontainer.RMContainerImpl: container_1375859105306_0001_01_000001 Container Transitioned from NEW to ALLOCATED
2013-08-07 07:05:29,098 INFO org.apache.hadoop.yarn.server.resourcemanager.RMAuditLogger: USER=ubuntu	OPERATION=AM Allocated Container	TARGET=SchedulerApp	RESULT=SUCCESS	APPID=application_1375859105306_0001	CONTAINERID=container_1375859105306_0001_01_000001
2013-08-07 07:05:29,102 INFO org.apache.hadoop.yarn.server.resourcemanager.scheduler.common.fica.FiCaSchedulerNode: Assigned container container_1375859105306_0001_01_000001 of capacity <memory:2048, vCores:1> on host hadoop-200-6:34031, which currently has 1 containers, <memory:2048, vCores:1> used and <memory:6144, vCores:15> available
2013-08-07 07:05:29,109 INFO org.apache.hadoop.yarn.server.resourcemanager.scheduler.capacity.LeafQueue: assignedContainer application=application_1375859105306_0001 container=Container: [ContainerId: container_1375859105306_0001_01_000001, NodeId: hadoop-200-6:34031, NodeHttpAddress: hadoop-200-6:8042, Resource: <memory:2048, vCores:1>, Priority: 0, State: NEW, Token: null, Status: container_id {, app_attempt_id {, application_id {, id: 1, cluster_timestamp: 1375859105306, }, attemptId: 1, }, id: 1, }, state: C_NEW, ] containerId=container_1375859105306_0001_01_000001 queue=default: capacity=1.0, absoluteCapacity=1.0, usedResources=<memory:0, vCores:0>usedCapacity=0.0, absoluteUsedCapacity=0.0, numApps=1, numContainers=0 usedCapacity=0.0 absoluteUsedCapacity=0.0 used=<memory:0, vCores:0> cluster=<memory:49152, vCores:96>
2013-08-07 07:05:29,110 INFO org.apache.hadoop.yarn.server.resourcemanager.scheduler.capacity.ParentQueue: Re-sorting queues since queue: root.default stats: default: capacity=1.0, absoluteCapacity=1.0, usedResources=<memory:2048, vCores:1>usedCapacity=0.041666668, absoluteUsedCapacity=0.041666668, numApps=1, numContainers=1
2013-08-07 07:05:29,111 INFO org.apache.hadoop.yarn.server.resourcemanager.scheduler.capacity.ParentQueue: assignedContainer queue=root usedCapacity=0.041666668 absoluteUsedCapacity=0.041666668 used=<memory:2048, vCores:1> cluster=<memory:49152, vCores:96>
2013-08-07 07:05:29,111 INFO org.apache.hadoop.yarn.server.resourcemanager.rmcontainer.RMContainerImpl: container_1375859105306_0001_01_000001 Container Transitioned from ALLOCATED to ACQUIRED
2013-08-07 07:05:29,114 INFO org.apache.hadoop.yarn.server.resourcemanager.rmapp.attempt.RMAppAttemptImpl: Storing attempt: AppId: application_1375859105306_0001 AttemptId: appattempt_1375859105306_0001_000001 MasterContainer: Container: [ContainerId: container_1375859105306_0001_01_000001, NodeId: hadoop-200-6:34031, NodeHttpAddress: hadoop-200-6:8042, Resource: <memory:2048, vCores:1>, Priority: 0, State: NEW, Token: null, Status: container_id {, app_attempt_id {, application_id {, id: 1, cluster_timestamp: 1375859105306, }, attemptId: 1, }, id: 1, }, state: C_NEW, ]
2013-08-07 07:05:29,118 INFO org.apache.hadoop.yarn.server.resourcemanager.rmapp.attempt.RMAppAttemptImpl: appattempt_1375859105306_0001_000001 State change from SCHEDULED to ALLOCATED_SAVING
2013-08-07 07:05:29,122 INFO org.apache.hadoop.yarn.server.resourcemanager.recovery.RMStateStore: Storing info for attempt: appattempt_1375859105306_0001_000001
2013-08-07 07:05:29,125 INFO org.apache.hadoop.yarn.server.resourcemanager.rmapp.attempt.RMAppAttemptImpl: appattempt_1375859105306_0001_000001 State change from ALLOCATED_SAVING to ALLOCATED
2013-08-07 07:05:29,131 INFO org.apache.hadoop.yarn.server.resourcemanager.amlauncher.AMLauncher: Launching masterappattempt_1375859105306_0001_000001
2013-08-07 07:05:29,177 INFO org.apache.hadoop.yarn.server.resourcemanager.amlauncher.AMLauncher: Setting up container Container: [ContainerId: container_1375859105306_0001_01_000001, NodeId: hadoop-200-6:34031, NodeHttpAddress: hadoop-200-6:8042, Resource: <memory:2048, vCores:1>, Priority: 0, State: NEW, Token: null, Status: container_id {, app_attempt_id {, application_id {, id: 1, cluster_timestamp: 1375859105306, }, attemptId: 1, }, id: 1, }, state: C_NEW, ] for AM appattempt_1375859105306_0001_000001
2013-08-07 07:05:29,178 INFO org.apache.hadoop.yarn.server.resourcemanager.amlauncher.AMLauncher: Command to launch container container_1375859105306_0001_01_000001 : $JAVA_HOME/bin/java -Dlog4j.configuration=container-log4j.properties -Dyarn.app.mapreduce.container.log.dir=<LOG_DIR> -Dyarn.app.mapreduce.container.log.filesize=0 -Dhadoop.root.logger=INFO,CLA  -Xmx1024m org.apache.hadoop.mapreduce.v2.app.MRAppMaster 1><LOG_DIR>/stdout 2><LOG_DIR>/stderr 
2013-08-07 07:05:30,086 INFO org.apache.hadoop.yarn.server.resourcemanager.amlauncher.AMLauncher: Done launching container Container: [ContainerId: container_1375859105306_0001_01_000001, NodeId: hadoop-200-6:34031, NodeHttpAddress: hadoop-200-6:8042, Resource: <memory:2048, vCores:1>, Priority: 0, State: NEW, Token: null, Status: container_id {, app_attempt_id {, application_id {, id: 1, cluster_timestamp: 1375859105306, }, attemptId: 1, }, id: 1, }, state: C_NEW, ] for AM appattempt_1375859105306_0001_000001
2013-08-07 07:05:30,087 INFO org.apache.hadoop.yarn.server.resourcemanager.rmapp.attempt.RMAppAttemptImpl: appattempt_1375859105306_0001_000001 State change from ALLOCATED to LAUNCHED
2013-08-07 07:05:30,104 INFO org.apache.hadoop.yarn.server.resourcemanager.rmcontainer.RMContainerImpl: container_1375859105306_0001_01_000001 Container Transitioned from ACQUIRED to RUNNING
2013-08-07 07:05:39,123 INFO org.apache.hadoop.yarn.server.resourcemanager.ApplicationMasterService: AM registration appattempt_1375859105306_0001_000001
2013-08-07 07:05:39,125 INFO org.apache.hadoop.yarn.server.resourcemanager.RMAuditLogger: USER=ubuntu	IP=192.168.100.10	OPERATION=Register App Master	TARGET=ApplicationMasterService	RESULT=SUCCESS	APPID=application_1375859105306_0001	APPATTEMPTID=appattempt_1375859105306_0001_000001
2013-08-07 07:05:39,134 INFO org.apache.hadoop.yarn.server.resourcemanager.rmapp.attempt.RMAppAttemptImpl: appattempt_1375859105306_0001_000001 State change from LAUNCHED to RUNNING
2013-08-07 07:05:39,134 INFO org.apache.hadoop.yarn.server.resourcemanager.rmapp.RMAppImpl: application_1375859105306_0001 State change from ACCEPTED to RUNNING
2013-08-07 07:05:40,412 INFO org.apache.hadoop.yarn.server.resourcemanager.rmcontainer.RMContainerImpl: container_1375859105306_0001_01_000002 Container Transitioned from NEW to ALLOCATED
2013-08-07 07:05:40,412 INFO org.apache.hadoop.yarn.server.resourcemanager.RMAuditLogger: USER=ubuntu	OPERATION=AM Allocated Container	TARGET=SchedulerApp	RESULT=SUCCESS	APPID=application_1375859105306_0001	CONTAINERID=container_1375859105306_0001_01_000002
2013-08-07 07:05:40,413 INFO org.apache.hadoop.yarn.server.resourcemanager.scheduler.common.fica.FiCaSchedulerNode: Assigned container container_1375859105306_0001_01_000002 of capacity <memory:1024, vCores:1> on host hadoop-200-3:55493, which currently has 1 containers, <memory:1024, vCores:1> used and <memory:7168, vCores:15> available
2013-08-07 07:05:40,414 INFO org.apache.hadoop.yarn.server.resourcemanager.scheduler.capacity.LeafQueue: assignedContainer application=application_1375859105306_0001 container=Container: [ContainerId: container_1375859105306_0001_01_000002, NodeId: hadoop-200-3:55493, NodeHttpAddress: hadoop-200-3:8042, Resource: <memory:1024, vCores:1>, Priority: 20, State: NEW, Token: null, Status: container_id {, app_attempt_id {, application_id {, id: 1, cluster_timestamp: 1375859105306, }, attemptId: 1, }, id: 2, }, state: C_NEW, ] containerId=container_1375859105306_0001_01_000002 queue=default: capacity=1.0, absoluteCapacity=1.0, usedResources=<memory:2048, vCores:1>usedCapacity=0.041666668, absoluteUsedCapacity=0.041666668, numApps=1, numContainers=1 usedCapacity=0.041666668 absoluteUsedCapacity=0.041666668 used=<memory:2048, vCores:1> cluster=<memory:49152, vCores:96>
2013-08-07 07:05:40,415 INFO org.apache.hadoop.yarn.server.resourcemanager.scheduler.capacity.ParentQueue: Re-sorting queues since queue: root.default stats: default: capacity=1.0, absoluteCapacity=1.0, usedResources=<memory:3072, vCores:2>usedCapacity=0.0625, absoluteUsedCapacity=0.0625, numApps=1, numContainers=2
2013-08-07 07:05:40,415 INFO org.apache.hadoop.yarn.server.resourcemanager.scheduler.capacity.ParentQueue: assignedContainer queue=root usedCapacity=0.0625 absoluteUsedCapacity=0.0625 used=<memory:3072, vCores:2> cluster=<memory:49152, vCores:96>
2013-08-07 07:05:40,596 INFO org.apache.hadoop.yarn.server.resourcemanager.rmcontainer.RMContainerImpl: container_1375859105306_0001_01_000003 Container Transitioned from NEW to ALLOCATED
2013-08-07 07:05:40,596 INFO org.apache.hadoop.yarn.server.resourcemanager.RMAuditLogger: USER=ubuntu	OPERATION=AM Allocated Container	TARGET=SchedulerApp	RESULT=SUCCESS	APPID=application_1375859105306_0001	CONTAINERID=container_1375859105306_0001_01_000003
2013-08-07 07:05:40,596 INFO org.apache.hadoop.yarn.server.resourcemanager.scheduler.common.fica.FiCaSchedulerNode: Assigned container container_1375859105306_0001_01_000003 of capacity <memory:1024, vCores:1> on host hadoop-200-4:41828, which currently has 1 containers, <memory:1024, vCores:1> used and <memory:7168, vCores:15> available
2013-08-07 07:05:40,598 INFO org.apache.hadoop.yarn.server.resourcemanager.scheduler.capacity.LeafQueue: assignedContainer application=application_1375859105306_0001 container=Container: [ContainerId: container_1375859105306_0001_01_000003, NodeId: hadoop-200-4:41828, NodeHttpAddress: hadoop-200-4:8042, Resource: <memory:1024, vCores:1>, Priority: 20, State: NEW, Token: null, Status: container_id {, app_attempt_id {, application_id {, id: 1, cluster_timestamp: 1375859105306, }, attemptId: 1, }, id: 3, }, state: C_NEW, ] containerId=container_1375859105306_0001_01_000003 queue=default: capacity=1.0, absoluteCapacity=1.0, usedResources=<memory:3072, vCores:2>usedCapacity=0.0625, absoluteUsedCapacity=0.0625, numApps=1, numContainers=2 usedCapacity=0.0625 absoluteUsedCapacity=0.0625 used=<memory:3072, vCores:2> cluster=<memory:49152, vCores:96>
2013-08-07 07:05:40,599 INFO org.apache.hadoop.yarn.server.resourcemanager.scheduler.capacity.ParentQueue: Re-sorting queues since queue: root.default stats: default: capacity=1.0, absoluteCapacity=1.0, usedResources=<memory:4096, vCores:3>usedCapacity=0.083333336, absoluteUsedCapacity=0.083333336, numApps=1, numContainers=3
2013-08-07 07:05:40,599 INFO org.apache.hadoop.yarn.server.resourcemanager.scheduler.capacity.ParentQueue: assignedContainer queue=root usedCapacity=0.083333336 absoluteUsedCapacity=0.083333336 used=<memory:4096, vCores:3> cluster=<memory:49152, vCores:96>
2013-08-07 07:05:41,195 INFO org.apache.hadoop.yarn.server.resourcemanager.rmcontainer.RMContainerImpl: container_1375859105306_0001_01_000002 Container Transitioned from ALLOCATED to ACQUIRED
2013-08-07 07:05:41,196 INFO org.apache.hadoop.yarn.server.resourcemanager.rmcontainer.RMContainerImpl: container_1375859105306_0001_01_000003 Container Transitioned from ALLOCATED to ACQUIRED
2013-08-07 07:05:42,231 INFO org.apache.hadoop.yarn.server.resourcemanager.scheduler.AppSchedulingInfo: checking for deactivate... 
2013-08-07 07:05:42,585 INFO org.apache.hadoop.yarn.server.resourcemanager.rmcontainer.RMContainerImpl: container_1375859105306_0001_01_000002 Container Transitioned from ACQUIRED to RUNNING
2013-08-07 07:05:42,694 INFO org.apache.hadoop.yarn.server.resourcemanager.rmcontainer.RMContainerImpl: container_1375859105306_0001_01_000003 Container Transitioned from ACQUIRED to RUNNING
2013-08-07 07:07:27,078 INFO org.apache.hadoop.yarn.server.resourcemanager.rmcontainer.RMContainerImpl: container_1375859105306_0001_01_000002 Container Transitioned from RUNNING to COMPLETED
2013-08-07 07:07:27,079 INFO org.apache.hadoop.yarn.server.resourcemanager.scheduler.common.fica.FiCaSchedulerApp: Completed container: container_1375859105306_0001_01_000002 in state: COMPLETED event:FINISHED
2013-08-07 07:07:27,079 INFO org.apache.hadoop.yarn.server.resourcemanager.RMAuditLogger: USER=ubuntu	OPERATION=AM Released Container	TARGET=SchedulerApp	RESULT=SUCCESS	APPID=application_1375859105306_0001	CONTAINERID=container_1375859105306_0001_01_000002
2013-08-07 07:07:27,079 INFO org.apache.hadoop.yarn.server.resourcemanager.scheduler.common.fica.FiCaSchedulerNode: Released container container_1375859105306_0001_01_000002 of capacity <memory:1024, vCores:1> on host hadoop-200-3:55493, which currently has 0 containers, <memory:0, vCores:0> used and <memory:8192, vCores:16> available, release resources=true
2013-08-07 07:07:27,079 INFO org.apache.hadoop.yarn.server.resourcemanager.scheduler.capacity.LeafQueue: default used=<memory:3072, vCores:2> numContainers=2 user=ubuntu user-resources=<memory:3072, vCores:2>
2013-08-07 07:07:27,082 INFO org.apache.hadoop.yarn.server.resourcemanager.scheduler.capacity.LeafQueue: completedContainer container=Container: [ContainerId: container_1375859105306_0001_01_000002, NodeId: hadoop-200-3:55493, NodeHttpAddress: hadoop-200-3:8042, Resource: <memory:1024, vCores:1>, Priority: 20, State: NEW, Token: null, Status: container_id {, app_attempt_id {, application_id {, id: 1, cluster_timestamp: 1375859105306, }, attemptId: 1, }, id: 2, }, state: C_COMPLETE, diagnostics: "Container killed by the ApplicationMaster.\n\n", exit_status: 143, ] resource=<memory:1024, vCores:1> queue=default: capacity=1.0, absoluteCapacity=1.0, usedResources=<memory:3072, vCores:2>usedCapacity=0.0625, absoluteUsedCapacity=0.0625, numApps=1, numContainers=2 usedCapacity=0.0625 absoluteUsedCapacity=0.0625 used=<memory:3072, vCores:2> cluster=<memory:49152, vCores:96>
2013-08-07 07:07:27,082 INFO org.apache.hadoop.yarn.server.resourcemanager.scheduler.capacity.ParentQueue: completedContainer queue=root usedCapacity=0.0625 absoluteUsedCapacity=0.0625 used=<memory:3072, vCores:2> cluster=<memory:49152, vCores:96>
2013-08-07 07:07:27,082 INFO org.apache.hadoop.yarn.server.resourcemanager.scheduler.capacity.CapacityScheduler: Application appattempt_1375859105306_0001_000001 released container container_1375859105306_0001_01_000002 on node: host: hadoop-200-3:55493 #containers=0 available=8192 used=0 with event: FINISHED
2013-08-07 07:07:29,726 INFO org.apache.hadoop.yarn.server.resourcemanager.rmcontainer.RMContainerImpl: container_1375859105306_0001_01_000003 Container Transitioned from RUNNING to COMPLETED
2013-08-07 07:07:29,726 INFO org.apache.hadoop.yarn.server.resourcemanager.scheduler.common.fica.FiCaSchedulerApp: Completed container: container_1375859105306_0001_01_000003 in state: COMPLETED event:FINISHED
2013-08-07 07:07:29,726 INFO org.apache.hadoop.yarn.server.resourcemanager.RMAuditLogger: USER=ubuntu	OPERATION=AM Released Container	TARGET=SchedulerApp	RESULT=SUCCESS	APPID=application_1375859105306_0001	CONTAINERID=container_1375859105306_0001_01_000003
2013-08-07 07:07:29,726 INFO org.apache.hadoop.yarn.server.resourcemanager.scheduler.common.fica.FiCaSchedulerNode: Released container container_1375859105306_0001_01_000003 of capacity <memory:1024, vCores:1> on host hadoop-200-4:41828, which currently has 0 containers, <memory:0, vCores:0> used and <memory:8192, vCores:16> available, release resources=true
2013-08-07 07:07:29,726 INFO org.apache.hadoop.yarn.server.resourcemanager.scheduler.capacity.LeafQueue: default used=<memory:2048, vCores:1> numContainers=1 user=ubuntu user-resources=<memory:2048, vCores:1>
2013-08-07 07:07:29,728 INFO org.apache.hadoop.yarn.server.resourcemanager.scheduler.capacity.LeafQueue: completedContainer container=Container: [ContainerId: container_1375859105306_0001_01_000003, NodeId: hadoop-200-4:41828, NodeHttpAddress: hadoop-200-4:8042, Resource: <memory:1024, vCores:1>, Priority: 20, State: NEW, Token: null, Status: container_id {, app_attempt_id {, application_id {, id: 1, cluster_timestamp: 1375859105306, }, attemptId: 1, }, id: 3, }, state: C_COMPLETE, diagnostics: "Container killed by the ApplicationMaster.\n\n", exit_status: 143, ] resource=<memory:1024, vCores:1> queue=default: capacity=1.0, absoluteCapacity=1.0, usedResources=<memory:2048, vCores:1>usedCapacity=0.041666668, absoluteUsedCapacity=0.041666668, numApps=1, numContainers=1 usedCapacity=0.041666668 absoluteUsedCapacity=0.041666668 used=<memory:2048, vCores:1> cluster=<memory:49152, vCores:96>
2013-08-07 07:07:29,729 INFO org.apache.hadoop.yarn.server.resourcemanager.scheduler.capacity.ParentQueue: completedContainer queue=root usedCapacity=0.041666668 absoluteUsedCapacity=0.041666668 used=<memory:2048, vCores:1> cluster=<memory:49152, vCores:96>
2013-08-07 07:07:29,729 INFO org.apache.hadoop.yarn.server.resourcemanager.scheduler.capacity.CapacityScheduler: Application appattempt_1375859105306_0001_000001 released container container_1375859105306_0001_01_000003 on node: host: hadoop-200-4:41828 #containers=0 available=8192 used=0 with event: FINISHED
2013-08-07 07:07:33,887 INFO org.apache.hadoop.yarn.server.resourcemanager.rmapp.attempt.RMAppAttemptImpl: appattempt_1375859105306_0001_000001 State change from RUNNING to FINISHING
2013-08-07 07:07:33,888 INFO org.apache.hadoop.yarn.server.resourcemanager.rmapp.RMAppImpl: application_1375859105306_0001 State change from RUNNING to FINISHING
2013-08-07 07:07:34,846 INFO org.apache.hadoop.yarn.server.resourcemanager.rmcontainer.RMContainerImpl: container_1375859105306_0001_01_000001 Container Transitioned from RUNNING to COMPLETED
2013-08-07 07:07:34,847 INFO org.apache.hadoop.yarn.server.resourcemanager.scheduler.common.fica.FiCaSchedulerApp: Completed container: container_1375859105306_0001_01_000001 in state: COMPLETED event:FINISHED
2013-08-07 07:07:34,847 INFO org.apache.hadoop.yarn.server.resourcemanager.RMAuditLogger: USER=ubuntu	OPERATION=AM Released Container	TARGET=SchedulerApp	RESULT=SUCCESS	APPID=application_1375859105306_0001	CONTAINERID=container_1375859105306_0001_01_000001
2013-08-07 07:07:34,847 INFO org.apache.hadoop.yarn.server.resourcemanager.scheduler.common.fica.FiCaSchedulerNode: Released container container_1375859105306_0001_01_000001 of capacity <memory:2048, vCores:1> on host hadoop-200-6:34031, which currently has 0 containers, <memory:0, vCores:0> used and <memory:8192, vCores:16> available, release resources=true
2013-08-07 07:07:34,847 INFO org.apache.hadoop.yarn.server.resourcemanager.scheduler.capacity.LeafQueue: default used=<memory:0, vCores:0> numContainers=0 user=ubuntu user-resources=<memory:0, vCores:0>
2013-08-07 07:07:34,849 INFO org.apache.hadoop.yarn.server.resourcemanager.scheduler.capacity.LeafQueue: completedContainer container=Container: [ContainerId: container_1375859105306_0001_01_000001, NodeId: hadoop-200-6:34031, NodeHttpAddress: hadoop-200-6:8042, Resource: <memory:2048, vCores:1>, Priority: 0, State: NEW, Token: null, Status: container_id {, app_attempt_id {, application_id {, id: 1, cluster_timestamp: 1375859105306, }, attemptId: 1, }, id: 1, }, state: C_COMPLETE, diagnostics: "", exit_status: 0, ] resource=<memory:2048, vCores:1> queue=default: capacity=1.0, absoluteCapacity=1.0, usedResources=<memory:0, vCores:0>usedCapacity=0.0, absoluteUsedCapacity=0.0, numApps=1, numContainers=0 usedCapacity=0.0 absoluteUsedCapacity=0.0 used=<memory:0, vCores:0> cluster=<memory:49152, vCores:96>
2013-08-07 07:07:34,849 INFO org.apache.hadoop.yarn.server.resourcemanager.scheduler.capacity.ParentQueue: completedContainer queue=root usedCapacity=0.0 absoluteUsedCapacity=0.0 used=<memory:0, vCores:0> cluster=<memory:49152, vCores:96>
2013-08-07 07:07:34,849 INFO org.apache.hadoop.yarn.server.resourcemanager.scheduler.capacity.CapacityScheduler: Application appattempt_1375859105306_0001_000001 released container container_1375859105306_0001_01_000001 on node: host: hadoop-200-6:34031 #containers=0 available=8192 used=0 with event: FINISHED
2013-08-07 07:07:34,850 INFO org.apache.hadoop.yarn.server.resourcemanager.rmapp.attempt.RMAppAttemptImpl: appattempt_1375859105306_0001_000001 State change from FINISHING to FINISHED
2013-08-07 07:07:34,852 INFO org.apache.hadoop.yarn.server.resourcemanager.rmapp.RMAppImpl: application_1375859105306_0001 State change from FINISHING to FINISHED
2013-08-07 07:07:34,852 INFO org.apache.hadoop.yarn.server.resourcemanager.scheduler.capacity.CapacityScheduler: Application appattempt_1375859105306_0001_000001 is done. finalState=FINISHED
2013-08-07 07:07:34,853 INFO org.apache.hadoop.yarn.server.resourcemanager.RMAuditLogger: USER=ubuntu	OPERATION=Application Finished - Succeeded	TARGET=RMAppManager	RESULT=SUCCESS	APPID=application_1375859105306_0001
2013-08-07 07:07:34,853 INFO org.apache.hadoop.yarn.server.resourcemanager.amlauncher.AMLauncher: Cleaning master appattempt_1375859105306_0001_000001
2013-08-07 07:07:34,865 INFO org.apache.hadoop.yarn.server.resourcemanager.scheduler.AppSchedulingInfo: Application application_1375859105306_0001 requests cleared
2013-08-07 07:07:34,867 INFO org.apache.hadoop.yarn.server.resourcemanager.scheduler.capacity.LeafQueue: Application removed - appId: application_1375859105306_0001 user: ubuntu queue: default #user-pending-applications: 0 #user-active-applications: 0 #queue-pending-applications: 0 #queue-active-applications: 0
2013-08-07 07:07:34,867 INFO org.apache.hadoop.yarn.server.resourcemanager.scheduler.capacity.ParentQueue: Application removed - appId: application_1375859105306_0001 user: ubuntu leaf-queue of parent: root #applications: 0
2013-08-07 07:07:34,869 INFO org.apache.hadoop.yarn.server.resourcemanager.recovery.RMStateStore: Removing info for app: application_1375859105306_0001
2013-08-07 07:07:34,873 INFO org.apache.hadoop.yarn.server.resourcemanager.RMAppManager$ApplicationSummary: appId=application_1375859105306_0001,name=TeraGen,user=ubuntu,queue=default,state=FINISHED,trackingUrl=hadoop-200-1.novalocal:8088/proxy/application_1375859105306_0001/jobhistory/job/job_1375859105306_0001,appMasterHost=hadoop-200-6,startTime=1375859128903,finishTime=1375859253888
2013-08-07 07:07:35,073 INFO org.apache.hadoop.yarn.server.resourcemanager.ClientRMService: Allocated new applicationId: 2
2013-08-07 07:07:37,002 INFO org.apache.hadoop.yarn.server.resourcemanager.ClientRMService: Storing Application with id application_1375859105306_0002
2013-08-07 07:07:37,002 INFO org.apache.hadoop.yarn.server.resourcemanager.recovery.RMStateStore: Storing info for app: application_1375859105306_0002
2013-08-07 07:07:37,002 INFO org.apache.hadoop.yarn.server.resourcemanager.ClientRMService: Application with id 2 submitted by user ubuntu
2013-08-07 07:07:37,002 INFO org.apache.hadoop.yarn.server.resourcemanager.RMAuditLogger: USER=ubuntu	IP=192.168.100.2	OPERATION=Submit Application Request	TARGET=ClientRMService	RESULT=SUCCESS	APPID=application_1375859105306_0002
2013-08-07 07:07:37,006 INFO org.apache.hadoop.yarn.server.resourcemanager.rmapp.RMAppImpl: application_1375859105306_0002 State change from NEW to SUBMITTED
2013-08-07 07:07:37,006 INFO org.apache.hadoop.yarn.server.resourcemanager.ApplicationMasterService: Registering appattempt_1375859105306_0002_000001
2013-08-07 07:07:37,006 INFO org.apache.hadoop.yarn.server.resourcemanager.rmapp.attempt.RMAppAttemptImpl: appattempt_1375859105306_0002_000001 State change from NEW to SUBMITTED
2013-08-07 07:07:37,007 INFO org.apache.hadoop.yarn.server.resourcemanager.scheduler.capacity.LeafQueue: Application application_1375859105306_0002 from user: ubuntu activated in queue: default
2013-08-07 07:07:37,007 INFO org.apache.hadoop.yarn.server.resourcemanager.scheduler.capacity.LeafQueue: Application added - appId: application_1375859105306_0002 user: org.apache.hadoop.yarn.server.resourcemanager.scheduler.capacity.LeafQueue$User@2f148f39, leaf-queue: default #user-pending-applications: 0 #user-active-applications: 1 #queue-pending-applications: 0 #queue-active-applications: 1
2013-08-07 07:07:37,007 INFO org.apache.hadoop.yarn.server.resourcemanager.scheduler.capacity.ParentQueue: Application added - appId: application_1375859105306_0002 user: ubuntu leaf-queue of parent: root #applications: 1
2013-08-07 07:07:37,007 INFO org.apache.hadoop.yarn.server.resourcemanager.scheduler.capacity.CapacityScheduler: Application Submission: appattempt_1375859105306_0002_000001, user: ubuntu queue: default: capacity=1.0, absoluteCapacity=1.0, usedResources=<memory:0, vCores:0>usedCapacity=0.0, absoluteUsedCapacity=0.0, numApps=1, numContainers=0, currently active: 1
2013-08-07 07:07:37,008 INFO org.apache.hadoop.yarn.server.resourcemanager.rmapp.attempt.RMAppAttemptImpl: appattempt_1375859105306_0002_000001 State change from SUBMITTED to SCHEDULED
2013-08-07 07:07:37,008 INFO org.apache.hadoop.yarn.server.resourcemanager.rmapp.RMAppImpl: application_1375859105306_0002 State change from SUBMITTED to ACCEPTED
2013-08-07 07:07:37,119 INFO org.apache.hadoop.yarn.server.resourcemanager.rmcontainer.RMContainerImpl: container_1375859105306_0002_01_000001 Container Transitioned from NEW to ALLOCATED
2013-08-07 07:07:37,119 INFO org.apache.hadoop.yarn.server.resourcemanager.RMAuditLogger: USER=ubuntu	OPERATION=AM Allocated Container	TARGET=SchedulerApp	RESULT=SUCCESS	APPID=application_1375859105306_0002	CONTAINERID=container_1375859105306_0002_01_000001
2013-08-07 07:07:37,119 INFO org.apache.hadoop.yarn.server.resourcemanager.scheduler.common.fica.FiCaSchedulerNode: Assigned container container_1375859105306_0002_01_000001 of capacity <memory:2048, vCores:1> on host hadoop-200-3:55493, which currently has 1 containers, <memory:2048, vCores:1> used and <memory:6144, vCores:15> available
2013-08-07 07:07:37,121 INFO org.apache.hadoop.yarn.server.resourcemanager.scheduler.capacity.LeafQueue: assignedContainer application=application_1375859105306_0002 container=Container: [ContainerId: container_1375859105306_0002_01_000001, NodeId: hadoop-200-3:55493, NodeHttpAddress: hadoop-200-3:8042, Resource: <memory:2048, vCores:1>, Priority: 0, State: NEW, Token: null, Status: container_id {, app_attempt_id {, application_id {, id: 2, cluster_timestamp: 1375859105306, }, attemptId: 1, }, id: 1, }, state: C_NEW, ] containerId=container_1375859105306_0002_01_000001 queue=default: capacity=1.0, absoluteCapacity=1.0, usedResources=<memory:0, vCores:0>usedCapacity=0.0, absoluteUsedCapacity=0.0, numApps=1, numContainers=0 usedCapacity=0.0 absoluteUsedCapacity=0.0 used=<memory:0, vCores:0> cluster=<memory:49152, vCores:96>
2013-08-07 07:07:37,121 INFO org.apache.hadoop.yarn.server.resourcemanager.scheduler.capacity.ParentQueue: Re-sorting queues since queue: root.default stats: default: capacity=1.0, absoluteCapacity=1.0, usedResources=<memory:2048, vCores:1>usedCapacity=0.041666668, absoluteUsedCapacity=0.041666668, numApps=1, numContainers=1
2013-08-07 07:07:37,122 INFO org.apache.hadoop.yarn.server.resourcemanager.scheduler.capacity.ParentQueue: assignedContainer queue=root usedCapacity=0.041666668 absoluteUsedCapacity=0.041666668 used=<memory:2048, vCores:1> cluster=<memory:49152, vCores:96>
2013-08-07 07:07:37,122 INFO org.apache.hadoop.yarn.server.resourcemanager.rmcontainer.RMContainerImpl: container_1375859105306_0002_01_000001 Container Transitioned from ALLOCATED to ACQUIRED
2013-08-07 07:07:37,125 INFO org.apache.hadoop.yarn.server.resourcemanager.rmapp.attempt.RMAppAttemptImpl: Storing attempt: AppId: application_1375859105306_0002 AttemptId: appattempt_1375859105306_0002_000001 MasterContainer: Container: [ContainerId: container_1375859105306_0002_01_000001, NodeId: hadoop-200-3:55493, NodeHttpAddress: hadoop-200-3:8042, Resource: <memory:2048, vCores:1>, Priority: 0, State: NEW, Token: null, Status: container_id {, app_attempt_id {, application_id {, id: 2, cluster_timestamp: 1375859105306, }, attemptId: 1, }, id: 1, }, state: C_NEW, ]
2013-08-07 07:07:37,125 INFO org.apache.hadoop.yarn.server.resourcemanager.rmapp.attempt.RMAppAttemptImpl: appattempt_1375859105306_0002_000001 State change from SCHEDULED to ALLOCATED_SAVING
2013-08-07 07:07:37,125 INFO org.apache.hadoop.yarn.server.resourcemanager.recovery.RMStateStore: Storing info for attempt: appattempt_1375859105306_0002_000001
2013-08-07 07:07:37,127 INFO org.apache.hadoop.yarn.server.resourcemanager.rmapp.attempt.RMAppAttemptImpl: appattempt_1375859105306_0002_000001 State change from ALLOCATED_SAVING to ALLOCATED
2013-08-07 07:07:37,131 INFO org.apache.hadoop.yarn.server.resourcemanager.amlauncher.AMLauncher: Launching masterappattempt_1375859105306_0002_000001
2013-08-07 07:07:37,137 INFO org.apache.hadoop.yarn.server.resourcemanager.amlauncher.AMLauncher: Setting up container Container: [ContainerId: container_1375859105306_0002_01_000001, NodeId: hadoop-200-3:55493, NodeHttpAddress: hadoop-200-3:8042, Resource: <memory:2048, vCores:1>, Priority: 0, State: NEW, Token: null, Status: container_id {, app_attempt_id {, application_id {, id: 2, cluster_timestamp: 1375859105306, }, attemptId: 1, }, id: 1, }, state: C_NEW, ] for AM appattempt_1375859105306_0002_000001
2013-08-07 07:07:37,137 INFO org.apache.hadoop.yarn.server.resourcemanager.amlauncher.AMLauncher: Command to launch container container_1375859105306_0002_01_000001 : $JAVA_HOME/bin/java -Dlog4j.configuration=container-log4j.properties -Dyarn.app.mapreduce.container.log.dir=<LOG_DIR> -Dyarn.app.mapreduce.container.log.filesize=0 -Dhadoop.root.logger=INFO,CLA  -Xmx1024m org.apache.hadoop.mapreduce.v2.app.MRAppMaster 1><LOG_DIR>/stdout 2><LOG_DIR>/stderr 
2013-08-07 07:07:37,156 INFO org.apache.hadoop.yarn.server.resourcemanager.amlauncher.AMLauncher: Done launching container Container: [ContainerId: container_1375859105306_0002_01_000001, NodeId: hadoop-200-3:55493, NodeHttpAddress: hadoop-200-3:8042, Resource: <memory:2048, vCores:1>, Priority: 0, State: NEW, Token: null, Status: container_id {, app_attempt_id {, application_id {, id: 2, cluster_timestamp: 1375859105306, }, attemptId: 1, }, id: 1, }, state: C_NEW, ] for AM appattempt_1375859105306_0002_000001
2013-08-07 07:07:37,156 INFO org.apache.hadoop.yarn.server.resourcemanager.rmapp.attempt.RMAppAttemptImpl: appattempt_1375859105306_0002_000001 State change from ALLOCATED to LAUNCHED
2013-08-07 07:07:38,125 INFO org.apache.hadoop.yarn.server.resourcemanager.rmcontainer.RMContainerImpl: container_1375859105306_0002_01_000001 Container Transitioned from ACQUIRED to RUNNING
2013-08-07 07:07:43,133 INFO org.apache.hadoop.yarn.server.resourcemanager.ApplicationMasterService: AM registration appattempt_1375859105306_0002_000001
2013-08-07 07:07:43,133 INFO org.apache.hadoop.yarn.server.resourcemanager.RMAuditLogger: USER=ubuntu	IP=192.168.100.3	OPERATION=Register App Master	TARGET=ApplicationMasterService	RESULT=SUCCESS	APPID=application_1375859105306_0002	APPATTEMPTID=appattempt_1375859105306_0002_000001
2013-08-07 07:07:43,135 INFO org.apache.hadoop.yarn.server.resourcemanager.rmapp.attempt.RMAppAttemptImpl: appattempt_1375859105306_0002_000001 State change from LAUNCHED to RUNNING
2013-08-07 07:07:43,136 INFO org.apache.hadoop.yarn.server.resourcemanager.rmapp.RMAppImpl: application_1375859105306_0002 State change from ACCEPTED to RUNNING
2013-08-07 07:07:44,230 INFO org.apache.hadoop.yarn.server.resourcemanager.rmcontainer.RMContainerImpl: container_1375859105306_0002_01_000002 Container Transitioned from NEW to ALLOCATED
2013-08-07 07:07:44,231 INFO org.apache.hadoop.yarn.server.resourcemanager.RMAuditLogger: USER=ubuntu	OPERATION=AM Allocated Container	TARGET=SchedulerApp	RESULT=SUCCESS	APPID=application_1375859105306_0002	CONTAINERID=container_1375859105306_0002_01_000002
2013-08-07 07:07:44,231 INFO org.apache.hadoop.yarn.server.resourcemanager.scheduler.common.fica.FiCaSchedulerNode: Assigned container container_1375859105306_0002_01_000002 of capacity <memory:1024, vCores:1> on host hadoop-200-2:35087, which currently has 1 containers, <memory:1024, vCores:1> used and <memory:7168, vCores:15> available
2013-08-07 07:07:44,233 INFO org.apache.hadoop.yarn.server.resourcemanager.scheduler.capacity.LeafQueue: assignedContainer application=application_1375859105306_0002 container=Container: [ContainerId: container_1375859105306_0002_01_000002, NodeId: hadoop-200-2:35087, NodeHttpAddress: hadoop-200-2:8042, Resource: <memory:1024, vCores:1>, Priority: 20, State: NEW, Token: null, Status: container_id {, app_attempt_id {, application_id {, id: 2, cluster_timestamp: 1375859105306, }, attemptId: 1, }, id: 2, }, state: C_NEW, ] containerId=container_1375859105306_0002_01_000002 queue=default: capacity=1.0, absoluteCapacity=1.0, usedResources=<memory:2048, vCores:1>usedCapacity=0.041666668, absoluteUsedCapacity=0.041666668, numApps=1, numContainers=1 usedCapacity=0.041666668 absoluteUsedCapacity=0.041666668 used=<memory:2048, vCores:1> cluster=<memory:49152, vCores:96>
2013-08-07 07:07:44,233 INFO org.apache.hadoop.yarn.server.resourcemanager.scheduler.capacity.ParentQueue: Re-sorting queues since queue: root.default stats: default: capacity=1.0, absoluteCapacity=1.0, usedResources=<memory:3072, vCores:2>usedCapacity=0.0625, absoluteUsedCapacity=0.0625, numApps=1, numContainers=2
2013-08-07 07:07:44,233 INFO org.apache.hadoop.yarn.server.resourcemanager.scheduler.capacity.ParentQueue: assignedContainer queue=root usedCapacity=0.0625 absoluteUsedCapacity=0.0625 used=<memory:3072, vCores:2> cluster=<memory:49152, vCores:96>
2013-08-07 07:07:44,240 INFO org.apache.hadoop.yarn.server.resourcemanager.rmcontainer.RMContainerImpl: container_1375859105306_0002_01_000003 Container Transitioned from NEW to ALLOCATED
2013-08-07 07:07:44,240 INFO org.apache.hadoop.yarn.server.resourcemanager.RMAuditLogger: USER=ubuntu	OPERATION=AM Allocated Container	TARGET=SchedulerApp	RESULT=SUCCESS	APPID=application_1375859105306_0002	CONTAINERID=container_1375859105306_0002_01_000003
2013-08-07 07:07:44,241 INFO org.apache.hadoop.yarn.server.resourcemanager.scheduler.common.fica.FiCaSchedulerNode: Assigned container container_1375859105306_0002_01_000003 of capacity <memory:1024, vCores:1> on host hadoop-200-5:52184, which currently has 1 containers, <memory:1024, vCores:1> used and <memory:7168, vCores:15> available
2013-08-07 07:07:44,242 INFO org.apache.hadoop.yarn.server.resourcemanager.scheduler.capacity.LeafQueue: assignedContainer application=application_1375859105306_0002 container=Container: [ContainerId: container_1375859105306_0002_01_000003, NodeId: hadoop-200-5:52184, NodeHttpAddress: hadoop-200-5:8042, Resource: <memory:1024, vCores:1>, Priority: 20, State: NEW, Token: null, Status: container_id {, app_attempt_id {, application_id {, id: 2, cluster_timestamp: 1375859105306, }, attemptId: 1, }, id: 3, }, state: C_NEW, ] containerId=container_1375859105306_0002_01_000003 queue=default: capacity=1.0, absoluteCapacity=1.0, usedResources=<memory:3072, vCores:2>usedCapacity=0.0625, absoluteUsedCapacity=0.0625, numApps=1, numContainers=2 usedCapacity=0.0625 absoluteUsedCapacity=0.0625 used=<memory:3072, vCores:2> cluster=<memory:49152, vCores:96>
2013-08-07 07:07:44,242 INFO org.apache.hadoop.yarn.server.resourcemanager.scheduler.capacity.ParentQueue: Re-sorting queues since queue: root.default stats: default: capacity=1.0, absoluteCapacity=1.0, usedResources=<memory:4096, vCores:3>usedCapacity=0.083333336, absoluteUsedCapacity=0.083333336, numApps=1, numContainers=3
2013-08-07 07:07:44,243 INFO org.apache.hadoop.yarn.server.resourcemanager.scheduler.capacity.ParentQueue: assignedContainer queue=root usedCapacity=0.083333336 absoluteUsedCapacity=0.083333336 used=<memory:4096, vCores:3> cluster=<memory:49152, vCores:96>
2013-08-07 07:07:45,191 INFO org.apache.hadoop.yarn.server.resourcemanager.rmcontainer.RMContainerImpl: container_1375859105306_0002_01_000002 Container Transitioned from ALLOCATED to ACQUIRED
2013-08-07 07:07:45,194 INFO org.apache.hadoop.yarn.server.resourcemanager.rmcontainer.RMContainerImpl: container_1375859105306_0002_01_000003 Container Transitioned from ALLOCATED to ACQUIRED
2013-08-07 07:07:46,225 INFO org.apache.hadoop.yarn.server.resourcemanager.scheduler.AppSchedulingInfo: checking for deactivate... 
2013-08-07 07:07:46,268 INFO org.apache.hadoop.yarn.server.resourcemanager.rmcontainer.RMContainerImpl: container_1375859105306_0002_01_000003 Container Transitioned from ACQUIRED to RUNNING
2013-08-07 07:07:47,266 INFO org.apache.hadoop.yarn.server.resourcemanager.rmcontainer.RMContainerImpl: container_1375859105306_0002_01_000002 Container Transitioned from ACQUIRED to RUNNING
2013-08-07 07:09:29,043 INFO org.apache.hadoop.yarn.server.resourcemanager.rmcontainer.RMContainerImpl: container_1375859105306_0002_01_000002 Container Transitioned from RUNNING to COMPLETED
2013-08-07 07:09:29,043 INFO org.apache.hadoop.yarn.server.resourcemanager.scheduler.common.fica.FiCaSchedulerApp: Completed container: container_1375859105306_0002_01_000002 in state: COMPLETED event:FINISHED
2013-08-07 07:09:29,043 INFO org.apache.hadoop.yarn.server.resourcemanager.RMAuditLogger: USER=ubuntu	OPERATION=AM Released Container	TARGET=SchedulerApp	RESULT=SUCCESS	APPID=application_1375859105306_0002	CONTAINERID=container_1375859105306_0002_01_000002
2013-08-07 07:09:29,044 INFO org.apache.hadoop.yarn.server.resourcemanager.scheduler.common.fica.FiCaSchedulerNode: Released container container_1375859105306_0002_01_000002 of capacity <memory:1024, vCores:1> on host hadoop-200-2:35087, which currently has 0 containers, <memory:0, vCores:0> used and <memory:8192, vCores:16> available, release resources=true
2013-08-07 07:09:29,044 INFO org.apache.hadoop.yarn.server.resourcemanager.scheduler.capacity.LeafQueue: default used=<memory:3072, vCores:2> numContainers=2 user=ubuntu user-resources=<memory:3072, vCores:2>
2013-08-07 07:09:29,057 INFO org.apache.hadoop.yarn.server.resourcemanager.scheduler.capacity.LeafQueue: completedContainer container=Container: [ContainerId: container_1375859105306_0002_01_000002, NodeId: hadoop-200-2:35087, NodeHttpAddress: hadoop-200-2:8042, Resource: <memory:1024, vCores:1>, Priority: 20, State: NEW, Token: null, Status: container_id {, app_attempt_id {, application_id {, id: 2, cluster_timestamp: 1375859105306, }, attemptId: 1, }, id: 2, }, state: C_COMPLETE, diagnostics: "Container killed by the ApplicationMaster.\n\n", exit_status: 143, ] resource=<memory:1024, vCores:1> queue=default: capacity=1.0, absoluteCapacity=1.0, usedResources=<memory:3072, vCores:2>usedCapacity=0.0625, absoluteUsedCapacity=0.0625, numApps=1, numContainers=2 usedCapacity=0.0625 absoluteUsedCapacity=0.0625 used=<memory:3072, vCores:2> cluster=<memory:49152, vCores:96>
2013-08-07 07:09:29,057 INFO org.apache.hadoop.yarn.server.resourcemanager.scheduler.capacity.ParentQueue: completedContainer queue=root usedCapacity=0.0625 absoluteUsedCapacity=0.0625 used=<memory:3072, vCores:2> cluster=<memory:49152, vCores:96>
2013-08-07 07:09:29,057 INFO org.apache.hadoop.yarn.server.resourcemanager.scheduler.capacity.CapacityScheduler: Application appattempt_1375859105306_0002_000001 released container container_1375859105306_0002_01_000002 on node: host: hadoop-200-2:35087 #containers=0 available=8192 used=0 with event: FINISHED
2013-08-07 07:09:32,400 INFO org.apache.hadoop.yarn.server.resourcemanager.rmcontainer.RMContainerImpl: container_1375859105306_0002_01_000003 Container Transitioned from RUNNING to COMPLETED
2013-08-07 07:09:32,400 INFO org.apache.hadoop.yarn.server.resourcemanager.scheduler.common.fica.FiCaSchedulerApp: Completed container: container_1375859105306_0002_01_000003 in state: COMPLETED event:FINISHED
2013-08-07 07:09:32,400 INFO org.apache.hadoop.yarn.server.resourcemanager.RMAuditLogger: USER=ubuntu	OPERATION=AM Released Container	TARGET=SchedulerApp	RESULT=SUCCESS	APPID=application_1375859105306_0002	CONTAINERID=container_1375859105306_0002_01_000003
2013-08-07 07:09:32,401 INFO org.apache.hadoop.yarn.server.resourcemanager.scheduler.common.fica.FiCaSchedulerNode: Released container container_1375859105306_0002_01_000003 of capacity <memory:1024, vCores:1> on host hadoop-200-5:52184, which currently has 0 containers, <memory:0, vCores:0> used and <memory:8192, vCores:16> available, release resources=true
2013-08-07 07:09:32,401 INFO org.apache.hadoop.yarn.server.resourcemanager.scheduler.capacity.LeafQueue: default used=<memory:2048, vCores:1> numContainers=1 user=ubuntu user-resources=<memory:2048, vCores:1>
2013-08-07 07:09:32,403 INFO org.apache.hadoop.yarn.server.resourcemanager.scheduler.capacity.LeafQueue: completedContainer container=Container: [ContainerId: container_1375859105306_0002_01_000003, NodeId: hadoop-200-5:52184, NodeHttpAddress: hadoop-200-5:8042, Resource: <memory:1024, vCores:1>, Priority: 20, State: NEW, Token: null, Status: container_id {, app_attempt_id {, application_id {, id: 2, cluster_timestamp: 1375859105306, }, attemptId: 1, }, id: 3, }, state: C_COMPLETE, diagnostics: "Container killed by the ApplicationMaster.\n\n", exit_status: 143, ] resource=<memory:1024, vCores:1> queue=default: capacity=1.0, absoluteCapacity=1.0, usedResources=<memory:2048, vCores:1>usedCapacity=0.041666668, absoluteUsedCapacity=0.041666668, numApps=1, numContainers=1 usedCapacity=0.041666668 absoluteUsedCapacity=0.041666668 used=<memory:2048, vCores:1> cluster=<memory:49152, vCores:96>
2013-08-07 07:09:32,403 INFO org.apache.hadoop.yarn.server.resourcemanager.scheduler.capacity.ParentQueue: completedContainer queue=root usedCapacity=0.041666668 absoluteUsedCapacity=0.041666668 used=<memory:2048, vCores:1> cluster=<memory:49152, vCores:96>
2013-08-07 07:09:32,403 INFO org.apache.hadoop.yarn.server.resourcemanager.scheduler.capacity.CapacityScheduler: Application appattempt_1375859105306_0002_000001 released container container_1375859105306_0002_01_000003 on node: host: hadoop-200-5:52184 #containers=0 available=8192 used=0 with event: FINISHED
2013-08-07 07:09:36,561 INFO org.apache.hadoop.yarn.server.resourcemanager.rmapp.attempt.RMAppAttemptImpl: appattempt_1375859105306_0002_000001 State change from RUNNING to FINISHING
2013-08-07 07:09:36,565 INFO org.apache.hadoop.yarn.server.resourcemanager.rmapp.RMAppImpl: application_1375859105306_0002 State change from RUNNING to FINISHING
2013-08-07 07:09:36,768 INFO org.apache.hadoop.yarn.server.resourcemanager.rmcontainer.RMContainerImpl: container_1375859105306_0002_01_000001 Container Transitioned from RUNNING to COMPLETED
2013-08-07 07:09:36,768 INFO org.apache.hadoop.yarn.server.resourcemanager.scheduler.common.fica.FiCaSchedulerApp: Completed container: container_1375859105306_0002_01_000001 in state: COMPLETED event:FINISHED
2013-08-07 07:09:36,768 INFO org.apache.hadoop.yarn.server.resourcemanager.RMAuditLogger: USER=ubuntu	OPERATION=AM Released Container	TARGET=SchedulerApp	RESULT=SUCCESS	APPID=application_1375859105306_0002	CONTAINERID=container_1375859105306_0002_01_000001
2013-08-07 07:09:36,768 INFO org.apache.hadoop.yarn.server.resourcemanager.rmapp.attempt.RMAppAttemptImpl: appattempt_1375859105306_0002_000001 State change from FINISHING to FINISHED
2013-08-07 07:09:36,768 INFO org.apache.hadoop.yarn.server.resourcemanager.scheduler.common.fica.FiCaSchedulerNode: Released container container_1375859105306_0002_01_000001 of capacity <memory:2048, vCores:1> on host hadoop-200-3:55493, which currently has 0 containers, <memory:0, vCores:0> used and <memory:8192, vCores:16> available, release resources=true
2013-08-07 07:09:36,769 INFO org.apache.hadoop.yarn.server.resourcemanager.scheduler.capacity.LeafQueue: default used=<memory:0, vCores:0> numContainers=0 user=ubuntu user-resources=<memory:0, vCores:0>
2013-08-07 07:09:36,769 INFO org.apache.hadoop.yarn.server.resourcemanager.rmapp.RMAppImpl: application_1375859105306_0002 State change from FINISHING to FINISHED
2013-08-07 07:09:36,769 INFO org.apache.hadoop.yarn.server.resourcemanager.RMAuditLogger: USER=ubuntu	OPERATION=Application Finished - Succeeded	TARGET=RMAppManager	RESULT=SUCCESS	APPID=application_1375859105306_0002
2013-08-07 07:09:36,770 INFO org.apache.hadoop.yarn.server.resourcemanager.recovery.RMStateStore: Removing info for app: application_1375859105306_0002
2013-08-07 07:09:36,770 INFO org.apache.hadoop.yarn.server.resourcemanager.RMAppManager$ApplicationSummary: appId=application_1375859105306_0002,name=TeraGen,user=ubuntu,queue=default,state=FINISHED,trackingUrl=hadoop-200-1.novalocal:8088/proxy/application_1375859105306_0002/jobhistory/job/job_1375859105306_0002,appMasterHost=hadoop-200-3,startTime=1375859257001,finishTime=1375859376564
2013-08-07 07:09:36,770 INFO org.apache.hadoop.yarn.server.resourcemanager.scheduler.capacity.LeafQueue: completedContainer container=Container: [ContainerId: container_1375859105306_0002_01_000001, NodeId: hadoop-200-3:55493, NodeHttpAddress: hadoop-200-3:8042, Resource: <memory:2048, vCores:1>, Priority: 0, State: NEW, Token: null, Status: container_id {, app_attempt_id {, application_id {, id: 2, cluster_timestamp: 1375859105306, }, attemptId: 1, }, id: 1, }, state: C_COMPLETE, diagnostics: "", exit_status: 0, ] resource=<memory:2048, vCores:1> queue=default: capacity=1.0, absoluteCapacity=1.0, usedResources=<memory:0, vCores:0>usedCapacity=0.0, absoluteUsedCapacity=0.0, numApps=1, numContainers=0 usedCapacity=0.0 absoluteUsedCapacity=0.0 used=<memory:0, vCores:0> cluster=<memory:49152, vCores:96>
2013-08-07 07:09:36,772 INFO org.apache.hadoop.yarn.server.resourcemanager.scheduler.capacity.ParentQueue: completedContainer queue=root usedCapacity=0.0 absoluteUsedCapacity=0.0 used=<memory:0, vCores:0> cluster=<memory:49152, vCores:96>
2013-08-07 07:09:36,772 INFO org.apache.hadoop.yarn.server.resourcemanager.scheduler.capacity.CapacityScheduler: Application appattempt_1375859105306_0002_000001 released container container_1375859105306_0002_01_000001 on node: host: hadoop-200-3:55493 #containers=0 available=8192 used=0 with event: FINISHED
2013-08-07 07:09:36,772 INFO org.apache.hadoop.yarn.server.resourcemanager.scheduler.capacity.CapacityScheduler: Application appattempt_1375859105306_0002_000001 is done. finalState=FINISHED
2013-08-07 07:09:36,773 INFO org.apache.hadoop.yarn.server.resourcemanager.scheduler.AppSchedulingInfo: Application application_1375859105306_0002 requests cleared
2013-08-07 07:09:36,773 INFO org.apache.hadoop.yarn.server.resourcemanager.scheduler.capacity.LeafQueue: Application removed - appId: application_1375859105306_0002 user: ubuntu queue: default #user-pending-applications: 0 #user-active-applications: 0 #queue-pending-applications: 0 #queue-active-applications: 0
2013-08-07 07:09:36,773 INFO org.apache.hadoop.yarn.server.resourcemanager.scheduler.capacity.ParentQueue: Application removed - appId: application_1375859105306_0002 user: ubuntu leaf-queue of parent: root #applications: 0
2013-08-07 07:09:36,774 INFO org.apache.hadoop.yarn.server.resourcemanager.amlauncher.AMLauncher: Cleaning master appattempt_1375859105306_0002_000001
2013-08-07 07:09:38,193 INFO org.apache.hadoop.yarn.server.resourcemanager.ClientRMService: Allocated new applicationId: 3
2013-08-07 07:09:40,083 INFO org.apache.hadoop.yarn.server.resourcemanager.ClientRMService: Storing Application with id application_1375859105306_0003
2013-08-07 07:09:40,083 INFO org.apache.hadoop.yarn.server.resourcemanager.recovery.RMStateStore: Storing info for app: application_1375859105306_0003
2013-08-07 07:09:40,084 INFO org.apache.hadoop.yarn.server.resourcemanager.ClientRMService: Application with id 3 submitted by user ubuntu
2013-08-07 07:09:40,084 INFO org.apache.hadoop.yarn.server.resourcemanager.RMAuditLogger: USER=ubuntu	IP=192.168.100.2	OPERATION=Submit Application Request	TARGET=ClientRMService	RESULT=SUCCESS	APPID=application_1375859105306_0003
2013-08-07 07:09:40,086 INFO org.apache.hadoop.yarn.server.resourcemanager.rmapp.RMAppImpl: application_1375859105306_0003 State change from NEW to SUBMITTED
2013-08-07 07:09:40,086 INFO org.apache.hadoop.yarn.server.resourcemanager.ApplicationMasterService: Registering appattempt_1375859105306_0003_000001
2013-08-07 07:09:40,086 INFO org.apache.hadoop.yarn.server.resourcemanager.rmapp.attempt.RMAppAttemptImpl: appattempt_1375859105306_0003_000001 State change from NEW to SUBMITTED
2013-08-07 07:09:40,087 INFO org.apache.hadoop.yarn.server.resourcemanager.scheduler.capacity.LeafQueue: Application application_1375859105306_0003 from user: ubuntu activated in queue: default
2013-08-07 07:09:40,087 INFO org.apache.hadoop.yarn.server.resourcemanager.scheduler.capacity.LeafQueue: Application added - appId: application_1375859105306_0003 user: org.apache.hadoop.yarn.server.resourcemanager.scheduler.capacity.LeafQueue$User@785e7845, leaf-queue: default #user-pending-applications: 0 #user-active-applications: 1 #queue-pending-applications: 0 #queue-active-applications: 1
2013-08-07 07:09:40,087 INFO org.apache.hadoop.yarn.server.resourcemanager.scheduler.capacity.ParentQueue: Application added - appId: application_1375859105306_0003 user: ubuntu leaf-queue of parent: root #applications: 1
2013-08-07 07:09:40,087 INFO org.apache.hadoop.yarn.server.resourcemanager.scheduler.capacity.CapacityScheduler: Application Submission: appattempt_1375859105306_0003_000001, user: ubuntu queue: default: capacity=1.0, absoluteCapacity=1.0, usedResources=<memory:0, vCores:0>usedCapacity=0.0, absoluteUsedCapacity=0.0, numApps=1, numContainers=0, currently active: 1
2013-08-07 07:09:40,088 INFO org.apache.hadoop.yarn.server.resourcemanager.rmapp.attempt.RMAppAttemptImpl: appattempt_1375859105306_0003_000001 State change from SUBMITTED to SCHEDULED
2013-08-07 07:09:40,090 INFO org.apache.hadoop.yarn.server.resourcemanager.rmcontainer.RMContainerImpl: container_1375859105306_0003_01_000001 Container Transitioned from NEW to ALLOCATED
2013-08-07 07:09:40,090 INFO org.apache.hadoop.yarn.server.resourcemanager.RMAuditLogger: USER=ubuntu	OPERATION=AM Allocated Container	TARGET=SchedulerApp	RESULT=SUCCESS	APPID=application_1375859105306_0003	CONTAINERID=container_1375859105306_0003_01_000001
2013-08-07 07:09:40,090 INFO org.apache.hadoop.yarn.server.resourcemanager.scheduler.common.fica.FiCaSchedulerNode: Assigned container container_1375859105306_0003_01_000001 of capacity <memory:2048, vCores:1> on host hadoop-200-2:35087, which currently has 1 containers, <memory:2048, vCores:1> used and <memory:6144, vCores:15> available
2013-08-07 07:09:40,091 INFO org.apache.hadoop.yarn.server.resourcemanager.scheduler.capacity.LeafQueue: assignedContainer application=application_1375859105306_0003 container=Container: [ContainerId: container_1375859105306_0003_01_000001, NodeId: hadoop-200-2:35087, NodeHttpAddress: hadoop-200-2:8042, Resource: <memory:2048, vCores:1>, Priority: 0, State: NEW, Token: null, Status: container_id {, app_attempt_id {, application_id {, id: 3, cluster_timestamp: 1375859105306, }, attemptId: 1, }, id: 1, }, state: C_NEW, ] containerId=container_1375859105306_0003_01_000001 queue=default: capacity=1.0, absoluteCapacity=1.0, usedResources=<memory:0, vCores:0>usedCapacity=0.0, absoluteUsedCapacity=0.0, numApps=1, numContainers=0 usedCapacity=0.0 absoluteUsedCapacity=0.0 used=<memory:0, vCores:0> cluster=<memory:49152, vCores:96>
2013-08-07 07:09:40,091 INFO org.apache.hadoop.yarn.server.resourcemanager.scheduler.capacity.ParentQueue: Re-sorting queues since queue: root.default stats: default: capacity=1.0, absoluteCapacity=1.0, usedResources=<memory:2048, vCores:1>usedCapacity=0.041666668, absoluteUsedCapacity=0.041666668, numApps=1, numContainers=1
2013-08-07 07:09:40,092 INFO org.apache.hadoop.yarn.server.resourcemanager.scheduler.capacity.ParentQueue: assignedContainer queue=root usedCapacity=0.041666668 absoluteUsedCapacity=0.041666668 used=<memory:2048, vCores:1> cluster=<memory:49152, vCores:96>
2013-08-07 07:09:40,089 INFO org.apache.hadoop.yarn.server.resourcemanager.rmapp.RMAppImpl: application_1375859105306_0003 State change from SUBMITTED to ACCEPTED
2013-08-07 07:09:40,094 INFO org.apache.hadoop.yarn.server.resourcemanager.rmcontainer.RMContainerImpl: container_1375859105306_0003_01_000001 Container Transitioned from ALLOCATED to ACQUIRED
2013-08-07 07:09:40,095 INFO org.apache.hadoop.yarn.server.resourcemanager.rmapp.attempt.RMAppAttemptImpl: Storing attempt: AppId: application_1375859105306_0003 AttemptId: appattempt_1375859105306_0003_000001 MasterContainer: Container: [ContainerId: container_1375859105306_0003_01_000001, NodeId: hadoop-200-2:35087, NodeHttpAddress: hadoop-200-2:8042, Resource: <memory:2048, vCores:1>, Priority: 0, State: NEW, Token: null, Status: container_id {, app_attempt_id {, application_id {, id: 3, cluster_timestamp: 1375859105306, }, attemptId: 1, }, id: 1, }, state: C_NEW, ]
2013-08-07 07:09:40,095 INFO org.apache.hadoop.yarn.server.resourcemanager.recovery.RMStateStore: Storing info for attempt: appattempt_1375859105306_0003_000001
2013-08-07 07:09:40,096 INFO org.apache.hadoop.yarn.server.resourcemanager.rmapp.attempt.RMAppAttemptImpl: appattempt_1375859105306_0003_000001 State change from SCHEDULED to ALLOCATED_SAVING
2013-08-07 07:09:40,097 INFO org.apache.hadoop.yarn.server.resourcemanager.rmapp.attempt.RMAppAttemptImpl: appattempt_1375859105306_0003_000001 State change from ALLOCATED_SAVING to ALLOCATED
2013-08-07 07:09:40,098 INFO org.apache.hadoop.yarn.server.resourcemanager.amlauncher.AMLauncher: Launching masterappattempt_1375859105306_0003_000001
2013-08-07 07:09:40,101 INFO org.apache.hadoop.yarn.server.resourcemanager.amlauncher.AMLauncher: Setting up container Container: [ContainerId: container_1375859105306_0003_01_000001, NodeId: hadoop-200-2:35087, NodeHttpAddress: hadoop-200-2:8042, Resource: <memory:2048, vCores:1>, Priority: 0, State: NEW, Token: null, Status: container_id {, app_attempt_id {, application_id {, id: 3, cluster_timestamp: 1375859105306, }, attemptId: 1, }, id: 1, }, state: C_NEW, ] for AM appattempt_1375859105306_0003_000001
2013-08-07 07:09:40,101 INFO org.apache.hadoop.yarn.server.resourcemanager.amlauncher.AMLauncher: Command to launch container container_1375859105306_0003_01_000001 : $JAVA_HOME/bin/java -Dlog4j.configuration=container-log4j.properties -Dyarn.app.mapreduce.container.log.dir=<LOG_DIR> -Dyarn.app.mapreduce.container.log.filesize=0 -Dhadoop.root.logger=INFO,CLA  -Xmx1024m org.apache.hadoop.mapreduce.v2.app.MRAppMaster 1><LOG_DIR>/stdout 2><LOG_DIR>/stderr 
2013-08-07 07:09:40,118 INFO org.apache.hadoop.yarn.server.resourcemanager.amlauncher.AMLauncher: Done launching container Container: [ContainerId: container_1375859105306_0003_01_000001, NodeId: hadoop-200-2:35087, NodeHttpAddress: hadoop-200-2:8042, Resource: <memory:2048, vCores:1>, Priority: 0, State: NEW, Token: null, Status: container_id {, app_attempt_id {, application_id {, id: 3, cluster_timestamp: 1375859105306, }, attemptId: 1, }, id: 1, }, state: C_NEW, ] for AM appattempt_1375859105306_0003_000001
2013-08-07 07:09:40,118 INFO org.apache.hadoop.yarn.server.resourcemanager.rmapp.attempt.RMAppAttemptImpl: appattempt_1375859105306_0003_000001 State change from ALLOCATED to LAUNCHED
2013-08-07 07:09:41,096 INFO org.apache.hadoop.yarn.server.resourcemanager.rmcontainer.RMContainerImpl: container_1375859105306_0003_01_000001 Container Transitioned from ACQUIRED to RUNNING
2013-08-07 07:09:47,060 INFO org.apache.hadoop.yarn.server.resourcemanager.ApplicationMasterService: AM registration appattempt_1375859105306_0003_000001
2013-08-07 07:09:47,061 INFO org.apache.hadoop.yarn.server.resourcemanager.RMAuditLogger: USER=ubuntu	IP=192.168.100.4	OPERATION=Register App Master	TARGET=ApplicationMasterService	RESULT=SUCCESS	APPID=application_1375859105306_0003	APPATTEMPTID=appattempt_1375859105306_0003_000001
2013-08-07 07:09:47,062 INFO org.apache.hadoop.yarn.server.resourcemanager.rmapp.attempt.RMAppAttemptImpl: appattempt_1375859105306_0003_000001 State change from LAUNCHED to RUNNING
2013-08-07 07:09:47,062 INFO org.apache.hadoop.yarn.server.resourcemanager.rmapp.RMAppImpl: application_1375859105306_0003 State change from ACCEPTED to RUNNING
2013-08-07 07:09:48,140 INFO org.apache.hadoop.yarn.server.resourcemanager.rmcontainer.RMContainerImpl: container_1375859105306_0003_01_000002 Container Transitioned from NEW to ALLOCATED
2013-08-07 07:09:48,140 INFO org.apache.hadoop.yarn.server.resourcemanager.RMAuditLogger: USER=ubuntu	OPERATION=AM Allocated Container	TARGET=SchedulerApp	RESULT=SUCCESS	APPID=application_1375859105306_0003	CONTAINERID=container_1375859105306_0003_01_000002
2013-08-07 07:09:48,142 INFO org.apache.hadoop.yarn.server.resourcemanager.scheduler.common.fica.FiCaSchedulerNode: Assigned container container_1375859105306_0003_01_000002 of capacity <memory:1024, vCores:1> on host hadoop-200-2:35087, which currently has 2 containers, <memory:3072, vCores:2> used and <memory:5120, vCores:14> available
2013-08-07 07:09:48,144 INFO org.apache.hadoop.yarn.server.resourcemanager.scheduler.capacity.LeafQueue: assignedContainer application=application_1375859105306_0003 container=Container: [ContainerId: container_1375859105306_0003_01_000002, NodeId: hadoop-200-2:35087, NodeHttpAddress: hadoop-200-2:8042, Resource: <memory:1024, vCores:1>, Priority: 20, State: NEW, Token: null, Status: container_id {, app_attempt_id {, application_id {, id: 3, cluster_timestamp: 1375859105306, }, attemptId: 1, }, id: 2, }, state: C_NEW, ] containerId=container_1375859105306_0003_01_000002 queue=default: capacity=1.0, absoluteCapacity=1.0, usedResources=<memory:2048, vCores:1>usedCapacity=0.041666668, absoluteUsedCapacity=0.041666668, numApps=1, numContainers=1 usedCapacity=0.041666668 absoluteUsedCapacity=0.041666668 used=<memory:2048, vCores:1> cluster=<memory:49152, vCores:96>
2013-08-07 07:09:48,144 INFO org.apache.hadoop.yarn.server.resourcemanager.scheduler.capacity.ParentQueue: Re-sorting queues since queue: root.default stats: default: capacity=1.0, absoluteCapacity=1.0, usedResources=<memory:3072, vCores:2>usedCapacity=0.0625, absoluteUsedCapacity=0.0625, numApps=1, numContainers=2
2013-08-07 07:09:48,144 INFO org.apache.hadoop.yarn.server.resourcemanager.scheduler.capacity.ParentQueue: assignedContainer queue=root usedCapacity=0.0625 absoluteUsedCapacity=0.0625 used=<memory:3072, vCores:2> cluster=<memory:49152, vCores:96>
2013-08-07 07:09:48,268 INFO org.apache.hadoop.yarn.server.resourcemanager.rmcontainer.RMContainerImpl: container_1375859105306_0003_01_000003 Container Transitioned from NEW to ALLOCATED
2013-08-07 07:09:48,268 INFO org.apache.hadoop.yarn.server.resourcemanager.RMAuditLogger: USER=ubuntu	OPERATION=AM Allocated Container	TARGET=SchedulerApp	RESULT=SUCCESS	APPID=application_1375859105306_0003	CONTAINERID=container_1375859105306_0003_01_000003
2013-08-07 07:09:48,268 INFO org.apache.hadoop.yarn.server.resourcemanager.scheduler.common.fica.FiCaSchedulerNode: Assigned container container_1375859105306_0003_01_000003 of capacity <memory:1024, vCores:1> on host hadoop-200-4:41828, which currently has 1 containers, <memory:1024, vCores:1> used and <memory:7168, vCores:15> available
2013-08-07 07:09:48,270 INFO org.apache.hadoop.yarn.server.resourcemanager.scheduler.capacity.LeafQueue: assignedContainer application=application_1375859105306_0003 container=Container: [ContainerId: container_1375859105306_0003_01_000003, NodeId: hadoop-200-4:41828, NodeHttpAddress: hadoop-200-4:8042, Resource: <memory:1024, vCores:1>, Priority: 20, State: NEW, Token: null, Status: container_id {, app_attempt_id {, application_id {, id: 3, cluster_timestamp: 1375859105306, }, attemptId: 1, }, id: 3, }, state: C_NEW, ] containerId=container_1375859105306_0003_01_000003 queue=default: capacity=1.0, absoluteCapacity=1.0, usedResources=<memory:3072, vCores:2>usedCapacity=0.0625, absoluteUsedCapacity=0.0625, numApps=1, numContainers=2 usedCapacity=0.0625 absoluteUsedCapacity=0.0625 used=<memory:3072, vCores:2> cluster=<memory:49152, vCores:96>
2013-08-07 07:09:48,270 INFO org.apache.hadoop.yarn.server.resourcemanager.scheduler.capacity.ParentQueue: Re-sorting queues since queue: root.default stats: default: capacity=1.0, absoluteCapacity=1.0, usedResources=<memory:4096, vCores:3>usedCapacity=0.083333336, absoluteUsedCapacity=0.083333336, numApps=1, numContainers=3
2013-08-07 07:09:48,270 INFO org.apache.hadoop.yarn.server.resourcemanager.scheduler.capacity.ParentQueue: assignedContainer queue=root usedCapacity=0.083333336 absoluteUsedCapacity=0.083333336 used=<memory:4096, vCores:3> cluster=<memory:49152, vCores:96>
2013-08-07 07:09:49,121 INFO org.apache.hadoop.yarn.server.resourcemanager.rmcontainer.RMContainerImpl: container_1375859105306_0003_01_000002 Container Transitioned from ALLOCATED to ACQUIRED
2013-08-07 07:09:49,123 INFO org.apache.hadoop.yarn.server.resourcemanager.rmcontainer.RMContainerImpl: container_1375859105306_0003_01_000003 Container Transitioned from ALLOCATED to ACQUIRED
2013-08-07 07:09:50,151 INFO org.apache.hadoop.yarn.server.resourcemanager.rmcontainer.RMContainerImpl: container_1375859105306_0003_01_000002 Container Transitioned from ACQUIRED to RUNNING
2013-08-07 07:09:50,153 INFO org.apache.hadoop.yarn.server.resourcemanager.scheduler.AppSchedulingInfo: checking for deactivate... 
2013-08-07 07:09:50,277 INFO org.apache.hadoop.yarn.server.resourcemanager.rmcontainer.RMContainerImpl: container_1375859105306_0003_01_000003 Container Transitioned from ACQUIRED to RUNNING
2013-08-07 07:11:41,786 INFO org.apache.hadoop.yarn.server.resourcemanager.rmcontainer.RMContainerImpl: container_1375859105306_0003_01_000002 Container Transitioned from RUNNING to COMPLETED
2013-08-07 07:11:41,786 INFO org.apache.hadoop.yarn.server.resourcemanager.scheduler.common.fica.FiCaSchedulerApp: Completed container: container_1375859105306_0003_01_000002 in state: COMPLETED event:FINISHED
2013-08-07 07:11:41,786 INFO org.apache.hadoop.yarn.server.resourcemanager.RMAuditLogger: USER=ubuntu	OPERATION=AM Released Container	TARGET=SchedulerApp	RESULT=SUCCESS	APPID=application_1375859105306_0003	CONTAINERID=container_1375859105306_0003_01_000002
2013-08-07 07:11:41,787 INFO org.apache.hadoop.yarn.server.resourcemanager.scheduler.common.fica.FiCaSchedulerNode: Released container container_1375859105306_0003_01_000002 of capacity <memory:1024, vCores:1> on host hadoop-200-2:35087, which currently has 1 containers, <memory:2048, vCores:1> used and <memory:6144, vCores:15> available, release resources=true
2013-08-07 07:11:41,787 INFO org.apache.hadoop.yarn.server.resourcemanager.scheduler.capacity.LeafQueue: default used=<memory:3072, vCores:2> numContainers=2 user=ubuntu user-resources=<memory:3072, vCores:2>
2013-08-07 07:11:41,789 INFO org.apache.hadoop.yarn.server.resourcemanager.scheduler.capacity.LeafQueue: completedContainer container=Container: [ContainerId: container_1375859105306_0003_01_000002, NodeId: hadoop-200-2:35087, NodeHttpAddress: hadoop-200-2:8042, Resource: <memory:1024, vCores:1>, Priority: 20, State: NEW, Token: null, Status: container_id {, app_attempt_id {, application_id {, id: 3, cluster_timestamp: 1375859105306, }, attemptId: 1, }, id: 2, }, state: C_COMPLETE, diagnostics: "Container killed by the ApplicationMaster.\n\n", exit_status: 143, ] resource=<memory:1024, vCores:1> queue=default: capacity=1.0, absoluteCapacity=1.0, usedResources=<memory:3072, vCores:2>usedCapacity=0.0625, absoluteUsedCapacity=0.0625, numApps=1, numContainers=2 usedCapacity=0.0625 absoluteUsedCapacity=0.0625 used=<memory:3072, vCores:2> cluster=<memory:49152, vCores:96>
2013-08-07 07:11:41,789 INFO org.apache.hadoop.yarn.server.resourcemanager.scheduler.capacity.ParentQueue: completedContainer queue=root usedCapacity=0.0625 absoluteUsedCapacity=0.0625 used=<memory:3072, vCores:2> cluster=<memory:49152, vCores:96>
2013-08-07 07:11:41,789 INFO org.apache.hadoop.yarn.server.resourcemanager.scheduler.capacity.CapacityScheduler: Application appattempt_1375859105306_0003_000001 released container container_1375859105306_0003_01_000002 on node: host: hadoop-200-2:35087 #containers=1 available=6144 used=2048 with event: FINISHED
2013-08-07 07:11:44,361 INFO org.apache.hadoop.yarn.server.resourcemanager.rmcontainer.RMContainerImpl: container_1375859105306_0003_01_000003 Container Transitioned from RUNNING to COMPLETED
2013-08-07 07:11:44,361 INFO org.apache.hadoop.yarn.server.resourcemanager.scheduler.common.fica.FiCaSchedulerApp: Completed container: container_1375859105306_0003_01_000003 in state: COMPLETED event:FINISHED
2013-08-07 07:11:44,361 INFO org.apache.hadoop.yarn.server.resourcemanager.RMAuditLogger: USER=ubuntu	OPERATION=AM Released Container	TARGET=SchedulerApp	RESULT=SUCCESS	APPID=application_1375859105306_0003	CONTAINERID=container_1375859105306_0003_01_000003
2013-08-07 07:11:44,362 INFO org.apache.hadoop.yarn.server.resourcemanager.scheduler.common.fica.FiCaSchedulerNode: Released container container_1375859105306_0003_01_000003 of capacity <memory:1024, vCores:1> on host hadoop-200-4:41828, which currently has 0 containers, <memory:0, vCores:0> used and <memory:8192, vCores:16> available, release resources=true
2013-08-07 07:11:44,362 INFO org.apache.hadoop.yarn.server.resourcemanager.scheduler.capacity.LeafQueue: default used=<memory:2048, vCores:1> numContainers=1 user=ubuntu user-resources=<memory:2048, vCores:1>
2013-08-07 07:11:44,364 INFO org.apache.hadoop.yarn.server.resourcemanager.scheduler.capacity.LeafQueue: completedContainer container=Container: [ContainerId: container_1375859105306_0003_01_000003, NodeId: hadoop-200-4:41828, NodeHttpAddress: hadoop-200-4:8042, Resource: <memory:1024, vCores:1>, Priority: 20, State: NEW, Token: null, Status: container_id {, app_attempt_id {, application_id {, id: 3, cluster_timestamp: 1375859105306, }, attemptId: 1, }, id: 3, }, state: C_COMPLETE, diagnostics: "Container killed by the ApplicationMaster.\n", exit_status: 0, ] resource=<memory:1024, vCores:1> queue=default: capacity=1.0, absoluteCapacity=1.0, usedResources=<memory:2048, vCores:1>usedCapacity=0.041666668, absoluteUsedCapacity=0.041666668, numApps=1, numContainers=1 usedCapacity=0.041666668 absoluteUsedCapacity=0.041666668 used=<memory:2048, vCores:1> cluster=<memory:49152, vCores:96>
2013-08-07 07:11:44,364 INFO org.apache.hadoop.yarn.server.resourcemanager.scheduler.capacity.ParentQueue: completedContainer queue=root usedCapacity=0.041666668 absoluteUsedCapacity=0.041666668 used=<memory:2048, vCores:1> cluster=<memory:49152, vCores:96>
2013-08-07 07:11:44,364 INFO org.apache.hadoop.yarn.server.resourcemanager.scheduler.capacity.CapacityScheduler: Application appattempt_1375859105306_0003_000001 released container container_1375859105306_0003_01_000003 on node: host: hadoop-200-4:41828 #containers=0 available=8192 used=0 with event: FINISHED
2013-08-07 07:11:47,481 INFO org.apache.hadoop.yarn.server.resourcemanager.rmapp.attempt.RMAppAttemptImpl: appattempt_1375859105306_0003_000001 State change from RUNNING to FINISHING
2013-08-07 07:11:47,482 INFO org.apache.hadoop.yarn.server.resourcemanager.rmapp.RMAppImpl: application_1375859105306_0003 State change from RUNNING to FINISHING
2013-08-07 07:11:47,817 INFO org.apache.hadoop.yarn.server.resourcemanager.rmcontainer.RMContainerImpl: container_1375859105306_0003_01_000001 Container Transitioned from RUNNING to COMPLETED
2013-08-07 07:11:47,817 INFO org.apache.hadoop.yarn.server.resourcemanager.scheduler.common.fica.FiCaSchedulerApp: Completed container: container_1375859105306_0003_01_000001 in state: COMPLETED event:FINISHED
2013-08-07 07:11:47,817 INFO org.apache.hadoop.yarn.server.resourcemanager.rmapp.attempt.RMAppAttemptImpl: appattempt_1375859105306_0003_000001 State change from FINISHING to FINISHED
2013-08-07 07:11:47,817 INFO org.apache.hadoop.yarn.server.resourcemanager.rmapp.RMAppImpl: application_1375859105306_0003 State change from FINISHING to FINISHED
2013-08-07 07:11:47,818 INFO org.apache.hadoop.yarn.server.resourcemanager.RMAuditLogger: USER=ubuntu	OPERATION=Application Finished - Succeeded	TARGET=RMAppManager	RESULT=SUCCESS	APPID=application_1375859105306_0003
2013-08-07 07:11:47,818 INFO org.apache.hadoop.yarn.server.resourcemanager.recovery.RMStateStore: Removing info for app: application_1375859105306_0003
2013-08-07 07:11:47,818 INFO org.apache.hadoop.yarn.server.resourcemanager.amlauncher.AMLauncher: Cleaning master appattempt_1375859105306_0003_000001
2013-08-07 07:11:47,819 INFO org.apache.hadoop.yarn.server.resourcemanager.RMAppManager$ApplicationSummary: appId=application_1375859105306_0003,name=TeraGen,user=ubuntu,queue=default,state=FINISHED,trackingUrl=hadoop-200-1.novalocal:8088/proxy/application_1375859105306_0003/jobhistory/job/job_1375859105306_0003,appMasterHost=hadoop-200-2,startTime=1375859380083,finishTime=1375859507482
2013-08-07 07:11:47,820 INFO org.apache.hadoop.yarn.server.resourcemanager.RMAuditLogger: USER=ubuntu	OPERATION=AM Released Container	TARGET=SchedulerApp	RESULT=SUCCESS	APPID=application_1375859105306_0003	CONTAINERID=container_1375859105306_0003_01_000001
2013-08-07 07:11:47,821 INFO org.apache.hadoop.yarn.server.resourcemanager.scheduler.common.fica.FiCaSchedulerNode: Released container container_1375859105306_0003_01_000001 of capacity <memory:2048, vCores:1> on host hadoop-200-2:35087, which currently has 0 containers, <memory:0, vCores:0> used and <memory:8192, vCores:16> available, release resources=true
2013-08-07 07:11:47,821 INFO org.apache.hadoop.yarn.server.resourcemanager.scheduler.capacity.LeafQueue: default used=<memory:0, vCores:0> numContainers=0 user=ubuntu user-resources=<memory:0, vCores:0>
2013-08-07 07:11:47,822 INFO org.apache.hadoop.yarn.server.resourcemanager.scheduler.capacity.LeafQueue: completedContainer container=Container: [ContainerId: container_1375859105306_0003_01_000001, NodeId: hadoop-200-2:35087, NodeHttpAddress: hadoop-200-2:8042, Resource: <memory:2048, vCores:1>, Priority: 0, State: NEW, Token: null, Status: container_id {, app_attempt_id {, application_id {, id: 3, cluster_timestamp: 1375859105306, }, attemptId: 1, }, id: 1, }, state: C_COMPLETE, diagnostics: "", exit_status: 0, ] resource=<memory:2048, vCores:1> queue=default: capacity=1.0, absoluteCapacity=1.0, usedResources=<memory:0, vCores:0>usedCapacity=0.0, absoluteUsedCapacity=0.0, numApps=1, numContainers=0 usedCapacity=0.0 absoluteUsedCapacity=0.0 used=<memory:0, vCores:0> cluster=<memory:49152, vCores:96>
2013-08-07 07:11:47,822 INFO org.apache.hadoop.yarn.server.resourcemanager.scheduler.capacity.ParentQueue: completedContainer queue=root usedCapacity=0.0 absoluteUsedCapacity=0.0 used=<memory:0, vCores:0> cluster=<memory:49152, vCores:96>
2013-08-07 07:11:47,824 INFO org.apache.hadoop.yarn.server.resourcemanager.scheduler.capacity.CapacityScheduler: Application appattempt_1375859105306_0003_000001 released container container_1375859105306_0003_01_000001 on node: host: hadoop-200-2:35087 #containers=0 available=8192 used=0 with event: FINISHED
2013-08-07 07:11:47,834 INFO org.apache.hadoop.yarn.server.resourcemanager.scheduler.capacity.CapacityScheduler: Application appattempt_1375859105306_0003_000001 is done. finalState=FINISHED
2013-08-07 07:11:47,835 INFO org.apache.hadoop.yarn.server.resourcemanager.scheduler.AppSchedulingInfo: Application application_1375859105306_0003 requests cleared
2013-08-07 07:11:47,835 INFO org.apache.hadoop.yarn.server.resourcemanager.scheduler.capacity.LeafQueue: Application removed - appId: application_1375859105306_0003 user: ubuntu queue: default #user-pending-applications: 0 #user-active-applications: 0 #queue-pending-applications: 0 #queue-active-applications: 0
2013-08-07 07:11:47,835 INFO org.apache.hadoop.yarn.server.resourcemanager.scheduler.capacity.ParentQueue: Application removed - appId: application_1375859105306_0003 user: ubuntu leaf-queue of parent: root #applications: 0
2013-08-07 07:11:48,792 INFO org.apache.hadoop.yarn.server.resourcemanager.ClientRMService: Allocated new applicationId: 4
2013-08-07 07:11:50,591 INFO org.apache.hadoop.yarn.server.resourcemanager.ClientRMService: Storing Application with id application_1375859105306_0004
2013-08-07 07:11:50,591 INFO org.apache.hadoop.yarn.server.resourcemanager.recovery.RMStateStore: Storing info for app: application_1375859105306_0004
2013-08-07 07:11:50,591 INFO org.apache.hadoop.yarn.server.resourcemanager.ClientRMService: Application with id 4 submitted by user ubuntu
2013-08-07 07:11:50,591 INFO org.apache.hadoop.yarn.server.resourcemanager.RMAuditLogger: USER=ubuntu	IP=192.168.100.2	OPERATION=Submit Application Request	TARGET=ClientRMService	RESULT=SUCCESS	APPID=application_1375859105306_0004
2013-08-07 07:11:50,593 INFO org.apache.hadoop.yarn.server.resourcemanager.rmapp.RMAppImpl: application_1375859105306_0004 State change from NEW to SUBMITTED
2013-08-07 07:11:50,593 INFO org.apache.hadoop.yarn.server.resourcemanager.ApplicationMasterService: Registering appattempt_1375859105306_0004_000001
2013-08-07 07:11:50,594 INFO org.apache.hadoop.yarn.server.resourcemanager.rmapp.attempt.RMAppAttemptImpl: appattempt_1375859105306_0004_000001 State change from NEW to SUBMITTED
2013-08-07 07:11:50,594 INFO org.apache.hadoop.yarn.server.resourcemanager.scheduler.capacity.LeafQueue: Application application_1375859105306_0004 from user: ubuntu activated in queue: default
2013-08-07 07:11:50,594 INFO org.apache.hadoop.yarn.server.resourcemanager.scheduler.capacity.LeafQueue: Application added - appId: application_1375859105306_0004 user: org.apache.hadoop.yarn.server.resourcemanager.scheduler.capacity.LeafQueue$User@3246fc1d, leaf-queue: default #user-pending-applications: 0 #user-active-applications: 1 #queue-pending-applications: 0 #queue-active-applications: 1
2013-08-07 07:11:50,594 INFO org.apache.hadoop.yarn.server.resourcemanager.scheduler.capacity.ParentQueue: Application added - appId: application_1375859105306_0004 user: ubuntu leaf-queue of parent: root #applications: 1
2013-08-07 07:11:50,595 INFO org.apache.hadoop.yarn.server.resourcemanager.scheduler.capacity.CapacityScheduler: Application Submission: appattempt_1375859105306_0004_000001, user: ubuntu queue: default: capacity=1.0, absoluteCapacity=1.0, usedResources=<memory:0, vCores:0>usedCapacity=0.0, absoluteUsedCapacity=0.0, numApps=1, numContainers=0, currently active: 1
2013-08-07 07:11:50,595 INFO org.apache.hadoop.yarn.server.resourcemanager.rmapp.attempt.RMAppAttemptImpl: appattempt_1375859105306_0004_000001 State change from SUBMITTED to SCHEDULED
2013-08-07 07:11:50,595 INFO org.apache.hadoop.yarn.server.resourcemanager.rmapp.RMAppImpl: application_1375859105306_0004 State change from SUBMITTED to ACCEPTED
2013-08-07 07:11:50,823 INFO org.apache.hadoop.yarn.server.resourcemanager.rmcontainer.RMContainerImpl: container_1375859105306_0004_01_000001 Container Transitioned from NEW to ALLOCATED
2013-08-07 07:11:50,823 INFO org.apache.hadoop.yarn.server.resourcemanager.RMAuditLogger: USER=ubuntu	OPERATION=AM Allocated Container	TARGET=SchedulerApp	RESULT=SUCCESS	APPID=application_1375859105306_0004	CONTAINERID=container_1375859105306_0004_01_000001
2013-08-07 07:11:50,823 INFO org.apache.hadoop.yarn.server.resourcemanager.scheduler.common.fica.FiCaSchedulerNode: Assigned container container_1375859105306_0004_01_000001 of capacity <memory:2048, vCores:1> on host hadoop-200-6:34031, which currently has 1 containers, <memory:2048, vCores:1> used and <memory:6144, vCores:15> available
2013-08-07 07:11:50,824 INFO org.apache.hadoop.yarn.server.resourcemanager.scheduler.capacity.LeafQueue: assignedContainer application=application_1375859105306_0004 container=Container: [ContainerId: container_1375859105306_0004_01_000001, NodeId: hadoop-200-6:34031, NodeHttpAddress: hadoop-200-6:8042, Resource: <memory:2048, vCores:1>, Priority: 0, State: NEW, Token: null, Status: container_id {, app_attempt_id {, application_id {, id: 4, cluster_timestamp: 1375859105306, }, attemptId: 1, }, id: 1, }, state: C_NEW, ] containerId=container_1375859105306_0004_01_000001 queue=default: capacity=1.0, absoluteCapacity=1.0, usedResources=<memory:0, vCores:0>usedCapacity=0.0, absoluteUsedCapacity=0.0, numApps=1, numContainers=0 usedCapacity=0.0 absoluteUsedCapacity=0.0 used=<memory:0, vCores:0> cluster=<memory:49152, vCores:96>
2013-08-07 07:11:50,825 INFO org.apache.hadoop.yarn.server.resourcemanager.scheduler.capacity.ParentQueue: Re-sorting queues since queue: root.default stats: default: capacity=1.0, absoluteCapacity=1.0, usedResources=<memory:2048, vCores:1>usedCapacity=0.041666668, absoluteUsedCapacity=0.041666668, numApps=1, numContainers=1
2013-08-07 07:11:50,825 INFO org.apache.hadoop.yarn.server.resourcemanager.scheduler.capacity.ParentQueue: assignedContainer queue=root usedCapacity=0.041666668 absoluteUsedCapacity=0.041666668 used=<memory:2048, vCores:1> cluster=<memory:49152, vCores:96>
2013-08-07 07:11:50,827 INFO org.apache.hadoop.yarn.server.resourcemanager.rmcontainer.RMContainerImpl: container_1375859105306_0004_01_000001 Container Transitioned from ALLOCATED to ACQUIRED
2013-08-07 07:11:50,829 INFO org.apache.hadoop.yarn.server.resourcemanager.rmapp.attempt.RMAppAttemptImpl: Storing attempt: AppId: application_1375859105306_0004 AttemptId: appattempt_1375859105306_0004_000001 MasterContainer: Container: [ContainerId: container_1375859105306_0004_01_000001, NodeId: hadoop-200-6:34031, NodeHttpAddress: hadoop-200-6:8042, Resource: <memory:2048, vCores:1>, Priority: 0, State: NEW, Token: null, Status: container_id {, app_attempt_id {, application_id {, id: 4, cluster_timestamp: 1375859105306, }, attemptId: 1, }, id: 1, }, state: C_NEW, ]
2013-08-07 07:11:50,830 INFO org.apache.hadoop.yarn.server.resourcemanager.recovery.RMStateStore: Storing info for attempt: appattempt_1375859105306_0004_000001
2013-08-07 07:11:50,830 INFO org.apache.hadoop.yarn.server.resourcemanager.rmapp.attempt.RMAppAttemptImpl: appattempt_1375859105306_0004_000001 State change from SCHEDULED to ALLOCATED_SAVING
2013-08-07 07:11:50,832 INFO org.apache.hadoop.yarn.server.resourcemanager.rmapp.attempt.RMAppAttemptImpl: appattempt_1375859105306_0004_000001 State change from ALLOCATED_SAVING to ALLOCATED
2013-08-07 07:11:50,834 INFO org.apache.hadoop.yarn.server.resourcemanager.amlauncher.AMLauncher: Launching masterappattempt_1375859105306_0004_000001
2013-08-07 07:11:50,837 INFO org.apache.hadoop.yarn.server.resourcemanager.amlauncher.AMLauncher: Setting up container Container: [ContainerId: container_1375859105306_0004_01_000001, NodeId: hadoop-200-6:34031, NodeHttpAddress: hadoop-200-6:8042, Resource: <memory:2048, vCores:1>, Priority: 0, State: NEW, Token: null, Status: container_id {, app_attempt_id {, application_id {, id: 4, cluster_timestamp: 1375859105306, }, attemptId: 1, }, id: 1, }, state: C_NEW, ] for AM appattempt_1375859105306_0004_000001
2013-08-07 07:11:50,837 INFO org.apache.hadoop.yarn.server.resourcemanager.amlauncher.AMLauncher: Command to launch container container_1375859105306_0004_01_000001 : $JAVA_HOME/bin/java -Dlog4j.configuration=container-log4j.properties -Dyarn.app.mapreduce.container.log.dir=<LOG_DIR> -Dyarn.app.mapreduce.container.log.filesize=0 -Dhadoop.root.logger=INFO,CLA  -Xmx1024m org.apache.hadoop.mapreduce.v2.app.MRAppMaster 1><LOG_DIR>/stdout 2><LOG_DIR>/stderr 
2013-08-07 07:11:50,853 INFO org.apache.hadoop.yarn.server.resourcemanager.amlauncher.AMLauncher: Done launching container Container: [ContainerId: container_1375859105306_0004_01_000001, NodeId: hadoop-200-6:34031, NodeHttpAddress: hadoop-200-6:8042, Resource: <memory:2048, vCores:1>, Priority: 0, State: NEW, Token: null, Status: container_id {, app_attempt_id {, application_id {, id: 4, cluster_timestamp: 1375859105306, }, attemptId: 1, }, id: 1, }, state: C_NEW, ] for AM appattempt_1375859105306_0004_000001
2013-08-07 07:11:50,854 INFO org.apache.hadoop.yarn.server.resourcemanager.rmapp.attempt.RMAppAttemptImpl: appattempt_1375859105306_0004_000001 State change from ALLOCATED to LAUNCHED
2013-08-07 07:11:51,831 INFO org.apache.hadoop.yarn.server.resourcemanager.rmcontainer.RMContainerImpl: container_1375859105306_0004_01_000001 Container Transitioned from ACQUIRED to RUNNING
2013-08-07 07:11:59,678 INFO org.apache.hadoop.yarn.server.resourcemanager.ApplicationMasterService: AM registration appattempt_1375859105306_0004_000001
2013-08-07 07:11:59,678 INFO org.apache.hadoop.yarn.server.resourcemanager.RMAuditLogger: USER=ubuntu	IP=192.168.100.10	OPERATION=Register App Master	TARGET=ApplicationMasterService	RESULT=SUCCESS	APPID=application_1375859105306_0004	APPATTEMPTID=appattempt_1375859105306_0004_000001
2013-08-07 07:11:59,680 INFO org.apache.hadoop.yarn.server.resourcemanager.rmapp.attempt.RMAppAttemptImpl: appattempt_1375859105306_0004_000001 State change from LAUNCHED to RUNNING
2013-08-07 07:11:59,680 INFO org.apache.hadoop.yarn.server.resourcemanager.rmapp.RMAppImpl: application_1375859105306_0004 State change from ACCEPTED to RUNNING
2013-08-07 07:12:00,868 INFO org.apache.hadoop.yarn.server.resourcemanager.rmcontainer.RMContainerImpl: container_1375859105306_0004_01_000002 Container Transitioned from NEW to ALLOCATED
2013-08-07 07:12:00,868 INFO org.apache.hadoop.yarn.server.resourcemanager.RMAuditLogger: USER=ubuntu	OPERATION=AM Allocated Container	TARGET=SchedulerApp	RESULT=SUCCESS	APPID=application_1375859105306_0004	CONTAINERID=container_1375859105306_0004_01_000002
2013-08-07 07:12:00,868 INFO org.apache.hadoop.yarn.server.resourcemanager.scheduler.common.fica.FiCaSchedulerNode: Assigned container container_1375859105306_0004_01_000002 of capacity <memory:1024, vCores:1> on host hadoop-200-2:35087, which currently has 1 containers, <memory:1024, vCores:1> used and <memory:7168, vCores:15> available
2013-08-07 07:12:00,870 INFO org.apache.hadoop.yarn.server.resourcemanager.scheduler.capacity.LeafQueue: assignedContainer application=application_1375859105306_0004 container=Container: [ContainerId: container_1375859105306_0004_01_000002, NodeId: hadoop-200-2:35087, NodeHttpAddress: hadoop-200-2:8042, Resource: <memory:1024, vCores:1>, Priority: 20, State: NEW, Token: null, Status: container_id {, app_attempt_id {, application_id {, id: 4, cluster_timestamp: 1375859105306, }, attemptId: 1, }, id: 2, }, state: C_NEW, ] containerId=container_1375859105306_0004_01_000002 queue=default: capacity=1.0, absoluteCapacity=1.0, usedResources=<memory:2048, vCores:1>usedCapacity=0.041666668, absoluteUsedCapacity=0.041666668, numApps=1, numContainers=1 usedCapacity=0.041666668 absoluteUsedCapacity=0.041666668 used=<memory:2048, vCores:1> cluster=<memory:49152, vCores:96>
2013-08-07 07:12:00,870 INFO org.apache.hadoop.yarn.server.resourcemanager.scheduler.capacity.ParentQueue: Re-sorting queues since queue: root.default stats: default: capacity=1.0, absoluteCapacity=1.0, usedResources=<memory:3072, vCores:2>usedCapacity=0.0625, absoluteUsedCapacity=0.0625, numApps=1, numContainers=2
2013-08-07 07:12:00,870 INFO org.apache.hadoop.yarn.server.resourcemanager.scheduler.capacity.ParentQueue: assignedContainer queue=root usedCapacity=0.0625 absoluteUsedCapacity=0.0625 used=<memory:3072, vCores:2> cluster=<memory:49152, vCores:96>
2013-08-07 07:12:00,975 INFO org.apache.hadoop.yarn.server.resourcemanager.rmcontainer.RMContainerImpl: container_1375859105306_0004_01_000003 Container Transitioned from NEW to ALLOCATED
2013-08-07 07:12:00,975 INFO org.apache.hadoop.yarn.server.resourcemanager.RMAuditLogger: USER=ubuntu	OPERATION=AM Allocated Container	TARGET=SchedulerApp	RESULT=SUCCESS	APPID=application_1375859105306_0004	CONTAINERID=container_1375859105306_0004_01_000003
2013-08-07 07:12:00,976 INFO org.apache.hadoop.yarn.server.resourcemanager.scheduler.common.fica.FiCaSchedulerNode: Assigned container container_1375859105306_0004_01_000003 of capacity <memory:1024, vCores:1> on host hadoop-200-5:52184, which currently has 1 containers, <memory:1024, vCores:1> used and <memory:7168, vCores:15> available
2013-08-07 07:12:00,977 INFO org.apache.hadoop.yarn.server.resourcemanager.scheduler.capacity.LeafQueue: assignedContainer application=application_1375859105306_0004 container=Container: [ContainerId: container_1375859105306_0004_01_000003, NodeId: hadoop-200-5:52184, NodeHttpAddress: hadoop-200-5:8042, Resource: <memory:1024, vCores:1>, Priority: 20, State: NEW, Token: null, Status: container_id {, app_attempt_id {, application_id {, id: 4, cluster_timestamp: 1375859105306, }, attemptId: 1, }, id: 3, }, state: C_NEW, ] containerId=container_1375859105306_0004_01_000003 queue=default: capacity=1.0, absoluteCapacity=1.0, usedResources=<memory:3072, vCores:2>usedCapacity=0.0625, absoluteUsedCapacity=0.0625, numApps=1, numContainers=2 usedCapacity=0.0625 absoluteUsedCapacity=0.0625 used=<memory:3072, vCores:2> cluster=<memory:49152, vCores:96>
2013-08-07 07:12:00,977 INFO org.apache.hadoop.yarn.server.resourcemanager.scheduler.capacity.ParentQueue: Re-sorting queues since queue: root.default stats: default: capacity=1.0, absoluteCapacity=1.0, usedResources=<memory:4096, vCores:3>usedCapacity=0.083333336, absoluteUsedCapacity=0.083333336, numApps=1, numContainers=3
2013-08-07 07:12:00,977 INFO org.apache.hadoop.yarn.server.resourcemanager.scheduler.capacity.ParentQueue: assignedContainer queue=root usedCapacity=0.083333336 absoluteUsedCapacity=0.083333336 used=<memory:4096, vCores:3> cluster=<memory:49152, vCores:96>
2013-08-07 07:12:01,761 INFO org.apache.hadoop.yarn.server.resourcemanager.rmcontainer.RMContainerImpl: container_1375859105306_0004_01_000002 Container Transitioned from ALLOCATED to ACQUIRED
2013-08-07 07:12:01,763 INFO org.apache.hadoop.yarn.server.resourcemanager.rmcontainer.RMContainerImpl: container_1375859105306_0004_01_000003 Container Transitioned from ALLOCATED to ACQUIRED
2013-08-07 07:12:02,795 INFO org.apache.hadoop.yarn.server.resourcemanager.scheduler.AppSchedulingInfo: checking for deactivate... 
2013-08-07 07:12:02,878 INFO org.apache.hadoop.yarn.server.resourcemanager.rmcontainer.RMContainerImpl: container_1375859105306_0004_01_000002 Container Transitioned from ACQUIRED to RUNNING
2013-08-07 07:12:02,985 INFO org.apache.hadoop.yarn.server.resourcemanager.rmcontainer.RMContainerImpl: container_1375859105306_0004_01_000003 Container Transitioned from ACQUIRED to RUNNING
2013-08-07 07:13:43,180 INFO org.apache.hadoop.yarn.server.resourcemanager.rmcontainer.RMContainerImpl: container_1375859105306_0004_01_000003 Container Transitioned from RUNNING to COMPLETED
2013-08-07 07:13:43,180 INFO org.apache.hadoop.yarn.server.resourcemanager.scheduler.common.fica.FiCaSchedulerApp: Completed container: container_1375859105306_0004_01_000003 in state: COMPLETED event:FINISHED
2013-08-07 07:13:43,180 INFO org.apache.hadoop.yarn.server.resourcemanager.RMAuditLogger: USER=ubuntu	OPERATION=AM Released Container	TARGET=SchedulerApp	RESULT=SUCCESS	APPID=application_1375859105306_0004	CONTAINERID=container_1375859105306_0004_01_000003
2013-08-07 07:13:43,180 INFO org.apache.hadoop.yarn.server.resourcemanager.scheduler.common.fica.FiCaSchedulerNode: Released container container_1375859105306_0004_01_000003 of capacity <memory:1024, vCores:1> on host hadoop-200-5:52184, which currently has 0 containers, <memory:0, vCores:0> used and <memory:8192, vCores:16> available, release resources=true
2013-08-07 07:13:43,181 INFO org.apache.hadoop.yarn.server.resourcemanager.scheduler.capacity.LeafQueue: default used=<memory:3072, vCores:2> numContainers=2 user=ubuntu user-resources=<memory:3072, vCores:2>
2013-08-07 07:13:43,182 INFO org.apache.hadoop.yarn.server.resourcemanager.scheduler.capacity.LeafQueue: completedContainer container=Container: [ContainerId: container_1375859105306_0004_01_000003, NodeId: hadoop-200-5:52184, NodeHttpAddress: hadoop-200-5:8042, Resource: <memory:1024, vCores:1>, Priority: 20, State: NEW, Token: null, Status: container_id {, app_attempt_id {, application_id {, id: 4, cluster_timestamp: 1375859105306, }, attemptId: 1, }, id: 3, }, state: C_COMPLETE, diagnostics: "Container killed by the ApplicationMaster.\n\n", exit_status: 143, ] resource=<memory:1024, vCores:1> queue=default: capacity=1.0, absoluteCapacity=1.0, usedResources=<memory:3072, vCores:2>usedCapacity=0.0625, absoluteUsedCapacity=0.0625, numApps=1, numContainers=2 usedCapacity=0.0625 absoluteUsedCapacity=0.0625 used=<memory:3072, vCores:2> cluster=<memory:49152, vCores:96>
2013-08-07 07:13:43,182 INFO org.apache.hadoop.yarn.server.resourcemanager.scheduler.capacity.ParentQueue: completedContainer queue=root usedCapacity=0.0625 absoluteUsedCapacity=0.0625 used=<memory:3072, vCores:2> cluster=<memory:49152, vCores:96>
2013-08-07 07:13:43,183 INFO org.apache.hadoop.yarn.server.resourcemanager.scheduler.capacity.CapacityScheduler: Application appattempt_1375859105306_0004_000001 released container container_1375859105306_0004_01_000003 on node: host: hadoop-200-5:52184 #containers=0 available=8192 used=0 with event: FINISHED
2013-08-07 07:13:46,162 INFO org.apache.hadoop.yarn.server.resourcemanager.rmcontainer.RMContainerImpl: container_1375859105306_0004_01_000002 Container Transitioned from RUNNING to COMPLETED
2013-08-07 07:13:46,162 INFO org.apache.hadoop.yarn.server.resourcemanager.scheduler.common.fica.FiCaSchedulerApp: Completed container: container_1375859105306_0004_01_000002 in state: COMPLETED event:FINISHED
2013-08-07 07:13:46,162 INFO org.apache.hadoop.yarn.server.resourcemanager.RMAuditLogger: USER=ubuntu	OPERATION=AM Released Container	TARGET=SchedulerApp	RESULT=SUCCESS	APPID=application_1375859105306_0004	CONTAINERID=container_1375859105306_0004_01_000002
2013-08-07 07:13:46,162 INFO org.apache.hadoop.yarn.server.resourcemanager.scheduler.common.fica.FiCaSchedulerNode: Released container container_1375859105306_0004_01_000002 of capacity <memory:1024, vCores:1> on host hadoop-200-2:35087, which currently has 0 containers, <memory:0, vCores:0> used and <memory:8192, vCores:16> available, release resources=true
2013-08-07 07:13:46,162 INFO org.apache.hadoop.yarn.server.resourcemanager.scheduler.capacity.LeafQueue: default used=<memory:2048, vCores:1> numContainers=1 user=ubuntu user-resources=<memory:2048, vCores:1>
2013-08-07 07:13:46,164 INFO org.apache.hadoop.yarn.server.resourcemanager.scheduler.capacity.LeafQueue: completedContainer container=Container: [ContainerId: container_1375859105306_0004_01_000002, NodeId: hadoop-200-2:35087, NodeHttpAddress: hadoop-200-2:8042, Resource: <memory:1024, vCores:1>, Priority: 20, State: NEW, Token: null, Status: container_id {, app_attempt_id {, application_id {, id: 4, cluster_timestamp: 1375859105306, }, attemptId: 1, }, id: 2, }, state: C_COMPLETE, diagnostics: "Container killed by the ApplicationMaster.\n\n", exit_status: 143, ] resource=<memory:1024, vCores:1> queue=default: capacity=1.0, absoluteCapacity=1.0, usedResources=<memory:2048, vCores:1>usedCapacity=0.041666668, absoluteUsedCapacity=0.041666668, numApps=1, numContainers=1 usedCapacity=0.041666668 absoluteUsedCapacity=0.041666668 used=<memory:2048, vCores:1> cluster=<memory:49152, vCores:96>
2013-08-07 07:13:46,164 INFO org.apache.hadoop.yarn.server.resourcemanager.scheduler.capacity.ParentQueue: completedContainer queue=root usedCapacity=0.041666668 absoluteUsedCapacity=0.041666668 used=<memory:2048, vCores:1> cluster=<memory:49152, vCores:96>
2013-08-07 07:13:46,164 INFO org.apache.hadoop.yarn.server.resourcemanager.scheduler.capacity.CapacityScheduler: Application appattempt_1375859105306_0004_000001 released container container_1375859105306_0004_01_000002 on node: host: hadoop-200-2:35087 #containers=0 available=8192 used=0 with event: FINISHED
2013-08-07 07:13:50,392 INFO org.apache.hadoop.yarn.server.resourcemanager.rmapp.attempt.RMAppAttemptImpl: appattempt_1375859105306_0004_000001 State change from RUNNING to FINISHING
2013-08-07 07:13:50,396 INFO org.apache.hadoop.yarn.server.resourcemanager.rmapp.RMAppImpl: application_1375859105306_0004 State change from RUNNING to FINISHING
2013-08-07 07:13:50,877 INFO org.apache.hadoop.yarn.server.resourcemanager.rmcontainer.RMContainerImpl: container_1375859105306_0004_01_000001 Container Transitioned from RUNNING to COMPLETED
2013-08-07 07:13:50,877 INFO org.apache.hadoop.yarn.server.resourcemanager.scheduler.common.fica.FiCaSchedulerApp: Completed container: container_1375859105306_0004_01_000001 in state: COMPLETED event:FINISHED
2013-08-07 07:13:50,878 INFO org.apache.hadoop.yarn.server.resourcemanager.RMAuditLogger: USER=ubuntu	OPERATION=AM Released Container	TARGET=SchedulerApp	RESULT=SUCCESS	APPID=application_1375859105306_0004	CONTAINERID=container_1375859105306_0004_01_000001
2013-08-07 07:13:50,878 INFO org.apache.hadoop.yarn.server.resourcemanager.scheduler.common.fica.FiCaSchedulerNode: Released container container_1375859105306_0004_01_000001 of capacity <memory:2048, vCores:1> on host hadoop-200-6:34031, which currently has 0 containers, <memory:0, vCores:0> used and <memory:8192, vCores:16> available, release resources=true
2013-08-07 07:13:50,878 INFO org.apache.hadoop.yarn.server.resourcemanager.scheduler.capacity.LeafQueue: default used=<memory:0, vCores:0> numContainers=0 user=ubuntu user-resources=<memory:0, vCores:0>
2013-08-07 07:13:50,879 INFO org.apache.hadoop.yarn.server.resourcemanager.scheduler.capacity.LeafQueue: completedContainer container=Container: [ContainerId: container_1375859105306_0004_01_000001, NodeId: hadoop-200-6:34031, NodeHttpAddress: hadoop-200-6:8042, Resource: <memory:2048, vCores:1>, Priority: 0, State: NEW, Token: null, Status: container_id {, app_attempt_id {, application_id {, id: 4, cluster_timestamp: 1375859105306, }, attemptId: 1, }, id: 1, }, state: C_COMPLETE, diagnostics: "", exit_status: 0, ] resource=<memory:2048, vCores:1> queue=default: capacity=1.0, absoluteCapacity=1.0, usedResources=<memory:0, vCores:0>usedCapacity=0.0, absoluteUsedCapacity=0.0, numApps=1, numContainers=0 usedCapacity=0.0 absoluteUsedCapacity=0.0 used=<memory:0, vCores:0> cluster=<memory:49152, vCores:96>
2013-08-07 07:13:50,880 INFO org.apache.hadoop.yarn.server.resourcemanager.scheduler.capacity.ParentQueue: completedContainer queue=root usedCapacity=0.0 absoluteUsedCapacity=0.0 used=<memory:0, vCores:0> cluster=<memory:49152, vCores:96>
2013-08-07 07:13:50,880 INFO org.apache.hadoop.yarn.server.resourcemanager.scheduler.capacity.CapacityScheduler: Application appattempt_1375859105306_0004_000001 released container container_1375859105306_0004_01_000001 on node: host: hadoop-200-6:34031 #containers=0 available=8192 used=0 with event: FINISHED
2013-08-07 07:13:50,880 INFO org.apache.hadoop.yarn.server.resourcemanager.rmapp.attempt.RMAppAttemptImpl: appattempt_1375859105306_0004_000001 State change from FINISHING to FINISHED
2013-08-07 07:13:50,881 INFO org.apache.hadoop.yarn.server.resourcemanager.rmapp.RMAppImpl: application_1375859105306_0004 State change from FINISHING to FINISHED
2013-08-07 07:13:50,881 INFO org.apache.hadoop.yarn.server.resourcemanager.scheduler.capacity.CapacityScheduler: Application appattempt_1375859105306_0004_000001 is done. finalState=FINISHED
2013-08-07 07:13:50,881 INFO org.apache.hadoop.yarn.server.resourcemanager.scheduler.AppSchedulingInfo: Application application_1375859105306_0004 requests cleared
2013-08-07 07:13:50,881 INFO org.apache.hadoop.yarn.server.resourcemanager.scheduler.capacity.LeafQueue: Application removed - appId: application_1375859105306_0004 user: ubuntu queue: default #user-pending-applications: 0 #user-active-applications: 0 #queue-pending-applications: 0 #queue-active-applications: 0
2013-08-07 07:13:50,881 INFO org.apache.hadoop.yarn.server.resourcemanager.scheduler.capacity.ParentQueue: Application removed - appId: application_1375859105306_0004 user: ubuntu leaf-queue of parent: root #applications: 0
2013-08-07 07:13:50,882 INFO org.apache.hadoop.yarn.server.resourcemanager.RMAuditLogger: USER=ubuntu	OPERATION=Application Finished - Succeeded	TARGET=RMAppManager	RESULT=SUCCESS	APPID=application_1375859105306_0004
2013-08-07 07:13:50,882 INFO org.apache.hadoop.yarn.server.resourcemanager.recovery.RMStateStore: Removing info for app: application_1375859105306_0004
2013-08-07 07:13:50,882 INFO org.apache.hadoop.yarn.server.resourcemanager.RMAppManager$ApplicationSummary: appId=application_1375859105306_0004,name=TeraGen,user=ubuntu,queue=default,state=FINISHED,trackingUrl=hadoop-200-1.novalocal:8088/proxy/application_1375859105306_0004/jobhistory/job/job_1375859105306_0004,appMasterHost=hadoop-200-6,startTime=1375859510590,finishTime=1375859630396
2013-08-07 07:13:50,883 INFO org.apache.hadoop.yarn.server.resourcemanager.amlauncher.AMLauncher: Cleaning master appattempt_1375859105306_0004_000001
2013-08-07 07:13:51,255 INFO org.apache.hadoop.yarn.server.resourcemanager.ClientRMService: Allocated new applicationId: 5
2013-08-07 07:13:53,060 INFO org.apache.hadoop.yarn.server.resourcemanager.ClientRMService: Storing Application with id application_1375859105306_0005
2013-08-07 07:13:53,060 INFO org.apache.hadoop.yarn.server.resourcemanager.recovery.RMStateStore: Storing info for app: application_1375859105306_0005
2013-08-07 07:13:53,060 INFO org.apache.hadoop.yarn.server.resourcemanager.ClientRMService: Application with id 5 submitted by user ubuntu
2013-08-07 07:13:53,061 INFO org.apache.hadoop.yarn.server.resourcemanager.RMAuditLogger: USER=ubuntu	IP=192.168.100.2	OPERATION=Submit Application Request	TARGET=ClientRMService	RESULT=SUCCESS	APPID=application_1375859105306_0005
2013-08-07 07:13:53,062 INFO org.apache.hadoop.yarn.server.resourcemanager.rmapp.RMAppImpl: application_1375859105306_0005 State change from NEW to SUBMITTED
2013-08-07 07:13:53,062 INFO org.apache.hadoop.yarn.server.resourcemanager.ApplicationMasterService: Registering appattempt_1375859105306_0005_000001
2013-08-07 07:13:53,063 INFO org.apache.hadoop.yarn.server.resourcemanager.rmapp.attempt.RMAppAttemptImpl: appattempt_1375859105306_0005_000001 State change from NEW to SUBMITTED
2013-08-07 07:13:53,063 INFO org.apache.hadoop.yarn.server.resourcemanager.scheduler.capacity.LeafQueue: Application application_1375859105306_0005 from user: ubuntu activated in queue: default
2013-08-07 07:13:53,063 INFO org.apache.hadoop.yarn.server.resourcemanager.scheduler.capacity.LeafQueue: Application added - appId: application_1375859105306_0005 user: org.apache.hadoop.yarn.server.resourcemanager.scheduler.capacity.LeafQueue$User@4ac1e4e8, leaf-queue: default #user-pending-applications: 0 #user-active-applications: 1 #queue-pending-applications: 0 #queue-active-applications: 1
2013-08-07 07:13:53,063 INFO org.apache.hadoop.yarn.server.resourcemanager.scheduler.capacity.ParentQueue: Application added - appId: application_1375859105306_0005 user: ubuntu leaf-queue of parent: root #applications: 1
2013-08-07 07:13:53,064 INFO org.apache.hadoop.yarn.server.resourcemanager.scheduler.capacity.CapacityScheduler: Application Submission: appattempt_1375859105306_0005_000001, user: ubuntu queue: default: capacity=1.0, absoluteCapacity=1.0, usedResources=<memory:0, vCores:0>usedCapacity=0.0, absoluteUsedCapacity=0.0, numApps=1, numContainers=0, currently active: 1
2013-08-07 07:13:53,064 INFO org.apache.hadoop.yarn.server.resourcemanager.rmapp.attempt.RMAppAttemptImpl: appattempt_1375859105306_0005_000001 State change from SUBMITTED to SCHEDULED
2013-08-07 07:13:53,064 INFO org.apache.hadoop.yarn.server.resourcemanager.rmapp.RMAppImpl: application_1375859105306_0005 State change from SUBMITTED to ACCEPTED
2013-08-07 07:13:53,185 INFO org.apache.hadoop.yarn.server.resourcemanager.rmcontainer.RMContainerImpl: container_1375859105306_0005_01_000001 Container Transitioned from NEW to ALLOCATED
2013-08-07 07:13:53,185 INFO org.apache.hadoop.yarn.server.resourcemanager.RMAuditLogger: USER=ubuntu	OPERATION=AM Allocated Container	TARGET=SchedulerApp	RESULT=SUCCESS	APPID=application_1375859105306_0005	CONTAINERID=container_1375859105306_0005_01_000001
2013-08-07 07:13:53,186 INFO org.apache.hadoop.yarn.server.resourcemanager.scheduler.common.fica.FiCaSchedulerNode: Assigned container container_1375859105306_0005_01_000001 of capacity <memory:2048, vCores:1> on host hadoop-200-2:35087, which currently has 1 containers, <memory:2048, vCores:1> used and <memory:6144, vCores:15> available
2013-08-07 07:13:53,187 INFO org.apache.hadoop.yarn.server.resourcemanager.scheduler.capacity.LeafQueue: assignedContainer application=application_1375859105306_0005 container=Container: [ContainerId: container_1375859105306_0005_01_000001, NodeId: hadoop-200-2:35087, NodeHttpAddress: hadoop-200-2:8042, Resource: <memory:2048, vCores:1>, Priority: 0, State: NEW, Token: null, Status: container_id {, app_attempt_id {, application_id {, id: 5, cluster_timestamp: 1375859105306, }, attemptId: 1, }, id: 1, }, state: C_NEW, ] containerId=container_1375859105306_0005_01_000001 queue=default: capacity=1.0, absoluteCapacity=1.0, usedResources=<memory:0, vCores:0>usedCapacity=0.0, absoluteUsedCapacity=0.0, numApps=1, numContainers=0 usedCapacity=0.0 absoluteUsedCapacity=0.0 used=<memory:0, vCores:0> cluster=<memory:49152, vCores:96>
2013-08-07 07:13:53,187 INFO org.apache.hadoop.yarn.server.resourcemanager.scheduler.capacity.ParentQueue: Re-sorting queues since queue: root.default stats: default: capacity=1.0, absoluteCapacity=1.0, usedResources=<memory:2048, vCores:1>usedCapacity=0.041666668, absoluteUsedCapacity=0.041666668, numApps=1, numContainers=1
2013-08-07 07:13:53,187 INFO org.apache.hadoop.yarn.server.resourcemanager.scheduler.capacity.ParentQueue: assignedContainer queue=root usedCapacity=0.041666668 absoluteUsedCapacity=0.041666668 used=<memory:2048, vCores:1> cluster=<memory:49152, vCores:96>
2013-08-07 07:13:53,189 INFO org.apache.hadoop.yarn.server.resourcemanager.rmcontainer.RMContainerImpl: container_1375859105306_0005_01_000001 Container Transitioned from ALLOCATED to ACQUIRED
2013-08-07 07:13:53,191 INFO org.apache.hadoop.yarn.server.resourcemanager.rmapp.attempt.RMAppAttemptImpl: Storing attempt: AppId: application_1375859105306_0005 AttemptId: appattempt_1375859105306_0005_000001 MasterContainer: Container: [ContainerId: container_1375859105306_0005_01_000001, NodeId: hadoop-200-2:35087, NodeHttpAddress: hadoop-200-2:8042, Resource: <memory:2048, vCores:1>, Priority: 0, State: NEW, Token: null, Status: container_id {, app_attempt_id {, application_id {, id: 5, cluster_timestamp: 1375859105306, }, attemptId: 1, }, id: 1, }, state: C_NEW, ]
2013-08-07 07:13:53,191 INFO org.apache.hadoop.yarn.server.resourcemanager.rmapp.attempt.RMAppAttemptImpl: appattempt_1375859105306_0005_000001 State change from SCHEDULED to ALLOCATED_SAVING
2013-08-07 07:13:53,191 INFO org.apache.hadoop.yarn.server.resourcemanager.recovery.RMStateStore: Storing info for attempt: appattempt_1375859105306_0005_000001
2013-08-07 07:13:53,193 INFO org.apache.hadoop.yarn.server.resourcemanager.rmapp.attempt.RMAppAttemptImpl: appattempt_1375859105306_0005_000001 State change from ALLOCATED_SAVING to ALLOCATED
2013-08-07 07:13:53,194 INFO org.apache.hadoop.yarn.server.resourcemanager.amlauncher.AMLauncher: Launching masterappattempt_1375859105306_0005_000001
2013-08-07 07:13:53,197 INFO org.apache.hadoop.yarn.server.resourcemanager.amlauncher.AMLauncher: Setting up container Container: [ContainerId: container_1375859105306_0005_01_000001, NodeId: hadoop-200-2:35087, NodeHttpAddress: hadoop-200-2:8042, Resource: <memory:2048, vCores:1>, Priority: 0, State: NEW, Token: null, Status: container_id {, app_attempt_id {, application_id {, id: 5, cluster_timestamp: 1375859105306, }, attemptId: 1, }, id: 1, }, state: C_NEW, ] for AM appattempt_1375859105306_0005_000001
2013-08-07 07:13:53,197 INFO org.apache.hadoop.yarn.server.resourcemanager.amlauncher.AMLauncher: Command to launch container container_1375859105306_0005_01_000001 : $JAVA_HOME/bin/java -Dlog4j.configuration=container-log4j.properties -Dyarn.app.mapreduce.container.log.dir=<LOG_DIR> -Dyarn.app.mapreduce.container.log.filesize=0 -Dhadoop.root.logger=INFO,CLA  -Xmx1024m org.apache.hadoop.mapreduce.v2.app.MRAppMaster 1><LOG_DIR>/stdout 2><LOG_DIR>/stderr 
2013-08-07 07:13:53,213 INFO org.apache.hadoop.yarn.server.resourcemanager.amlauncher.AMLauncher: Done launching container Container: [ContainerId: container_1375859105306_0005_01_000001, NodeId: hadoop-200-2:35087, NodeHttpAddress: hadoop-200-2:8042, Resource: <memory:2048, vCores:1>, Priority: 0, State: NEW, Token: null, Status: container_id {, app_attempt_id {, application_id {, id: 5, cluster_timestamp: 1375859105306, }, attemptId: 1, }, id: 1, }, state: C_NEW, ] for AM appattempt_1375859105306_0005_000001
2013-08-07 07:13:53,214 INFO org.apache.hadoop.yarn.server.resourcemanager.rmapp.attempt.RMAppAttemptImpl: appattempt_1375859105306_0005_000001 State change from ALLOCATED to LAUNCHED
2013-08-07 07:13:54,193 INFO org.apache.hadoop.yarn.server.resourcemanager.rmcontainer.RMContainerImpl: container_1375859105306_0005_01_000001 Container Transitioned from ACQUIRED to RUNNING
2013-08-07 07:14:00,187 INFO org.apache.hadoop.yarn.server.resourcemanager.ApplicationMasterService: AM registration appattempt_1375859105306_0005_000001
2013-08-07 07:14:00,187 INFO org.apache.hadoop.yarn.server.resourcemanager.RMAuditLogger: USER=ubuntu	IP=192.168.100.4	OPERATION=Register App Master	TARGET=ApplicationMasterService	RESULT=SUCCESS	APPID=application_1375859105306_0005	APPATTEMPTID=appattempt_1375859105306_0005_000001
2013-08-07 07:14:00,188 INFO org.apache.hadoop.yarn.server.resourcemanager.rmapp.attempt.RMAppAttemptImpl: appattempt_1375859105306_0005_000001 State change from LAUNCHED to RUNNING
2013-08-07 07:14:00,192 INFO org.apache.hadoop.yarn.server.resourcemanager.rmapp.RMAppImpl: application_1375859105306_0005 State change from ACCEPTED to RUNNING
2013-08-07 07:14:01,241 INFO org.apache.hadoop.yarn.server.resourcemanager.rmcontainer.RMContainerImpl: container_1375859105306_0005_01_000002 Container Transitioned from NEW to ALLOCATED
2013-08-07 07:14:01,241 INFO org.apache.hadoop.yarn.server.resourcemanager.RMAuditLogger: USER=ubuntu	OPERATION=AM Allocated Container	TARGET=SchedulerApp	RESULT=SUCCESS	APPID=application_1375859105306_0005	CONTAINERID=container_1375859105306_0005_01_000002
2013-08-07 07:14:01,241 INFO org.apache.hadoop.yarn.server.resourcemanager.scheduler.common.fica.FiCaSchedulerNode: Assigned container container_1375859105306_0005_01_000002 of capacity <memory:1024, vCores:1> on host hadoop-200-5:52184, which currently has 1 containers, <memory:1024, vCores:1> used and <memory:7168, vCores:15> available
2013-08-07 07:14:01,243 INFO org.apache.hadoop.yarn.server.resourcemanager.scheduler.capacity.LeafQueue: assignedContainer application=application_1375859105306_0005 container=Container: [ContainerId: container_1375859105306_0005_01_000002, NodeId: hadoop-200-5:52184, NodeHttpAddress: hadoop-200-5:8042, Resource: <memory:1024, vCores:1>, Priority: 20, State: NEW, Token: null, Status: container_id {, app_attempt_id {, application_id {, id: 5, cluster_timestamp: 1375859105306, }, attemptId: 1, }, id: 2, }, state: C_NEW, ] containerId=container_1375859105306_0005_01_000002 queue=default: capacity=1.0, absoluteCapacity=1.0, usedResources=<memory:2048, vCores:1>usedCapacity=0.041666668, absoluteUsedCapacity=0.041666668, numApps=1, numContainers=1 usedCapacity=0.041666668 absoluteUsedCapacity=0.041666668 used=<memory:2048, vCores:1> cluster=<memory:49152, vCores:96>
2013-08-07 07:14:01,243 INFO org.apache.hadoop.yarn.server.resourcemanager.scheduler.capacity.ParentQueue: Re-sorting queues since queue: root.default stats: default: capacity=1.0, absoluteCapacity=1.0, usedResources=<memory:3072, vCores:2>usedCapacity=0.0625, absoluteUsedCapacity=0.0625, numApps=1, numContainers=2
2013-08-07 07:14:01,243 INFO org.apache.hadoop.yarn.server.resourcemanager.scheduler.capacity.ParentQueue: assignedContainer queue=root usedCapacity=0.0625 absoluteUsedCapacity=0.0625 used=<memory:3072, vCores:2> cluster=<memory:49152, vCores:96>
2013-08-07 07:14:01,709 INFO org.apache.hadoop.yarn.server.resourcemanager.rmcontainer.RMContainerImpl: container_1375859105306_0005_01_000003 Container Transitioned from NEW to ALLOCATED
2013-08-07 07:14:01,709 INFO org.apache.hadoop.yarn.server.resourcemanager.RMAuditLogger: USER=ubuntu	OPERATION=AM Allocated Container	TARGET=SchedulerApp	RESULT=SUCCESS	APPID=application_1375859105306_0005	CONTAINERID=container_1375859105306_0005_01_000003
2013-08-07 07:14:01,709 INFO org.apache.hadoop.yarn.server.resourcemanager.scheduler.common.fica.FiCaSchedulerNode: Assigned container container_1375859105306_0005_01_000003 of capacity <memory:1024, vCores:1> on host hadoop-200-3:55493, which currently has 1 containers, <memory:1024, vCores:1> used and <memory:7168, vCores:15> available
2013-08-07 07:14:01,710 INFO org.apache.hadoop.yarn.server.resourcemanager.scheduler.capacity.LeafQueue: assignedContainer application=application_1375859105306_0005 container=Container: [ContainerId: container_1375859105306_0005_01_000003, NodeId: hadoop-200-3:55493, NodeHttpAddress: hadoop-200-3:8042, Resource: <memory:1024, vCores:1>, Priority: 20, State: NEW, Token: null, Status: container_id {, app_attempt_id {, application_id {, id: 5, cluster_timestamp: 1375859105306, }, attemptId: 1, }, id: 3, }, state: C_NEW, ] containerId=container_1375859105306_0005_01_000003 queue=default: capacity=1.0, absoluteCapacity=1.0, usedResources=<memory:3072, vCores:2>usedCapacity=0.0625, absoluteUsedCapacity=0.0625, numApps=1, numContainers=2 usedCapacity=0.0625 absoluteUsedCapacity=0.0625 used=<memory:3072, vCores:2> cluster=<memory:49152, vCores:96>
2013-08-07 07:14:01,710 INFO org.apache.hadoop.yarn.server.resourcemanager.scheduler.capacity.ParentQueue: Re-sorting queues since queue: root.default stats: default: capacity=1.0, absoluteCapacity=1.0, usedResources=<memory:4096, vCores:3>usedCapacity=0.083333336, absoluteUsedCapacity=0.083333336, numApps=1, numContainers=3
2013-08-07 07:14:01,711 INFO org.apache.hadoop.yarn.server.resourcemanager.scheduler.capacity.ParentQueue: assignedContainer queue=root usedCapacity=0.083333336 absoluteUsedCapacity=0.083333336 used=<memory:4096, vCores:3> cluster=<memory:49152, vCores:96>
2013-08-07 07:14:02,254 INFO org.apache.hadoop.yarn.server.resourcemanager.rmcontainer.RMContainerImpl: container_1375859105306_0005_01_000002 Container Transitioned from ALLOCATED to ACQUIRED
2013-08-07 07:14:02,257 INFO org.apache.hadoop.yarn.server.resourcemanager.rmcontainer.RMContainerImpl: container_1375859105306_0005_01_000003 Container Transitioned from ALLOCATED to ACQUIRED
2013-08-07 07:14:02,715 INFO org.apache.hadoop.yarn.server.resourcemanager.rmcontainer.RMContainerImpl: container_1375859105306_0005_01_000003 Container Transitioned from ACQUIRED to RUNNING
2013-08-07 07:14:03,249 INFO org.apache.hadoop.yarn.server.resourcemanager.rmcontainer.RMContainerImpl: container_1375859105306_0005_01_000002 Container Transitioned from ACQUIRED to RUNNING
2013-08-07 07:14:03,295 INFO org.apache.hadoop.yarn.server.resourcemanager.scheduler.AppSchedulingInfo: checking for deactivate... 
2013-08-07 07:15:49,068 INFO org.apache.hadoop.yarn.server.resourcemanager.rmcontainer.RMContainerImpl: container_1375859105306_0005_01_000003 Container Transitioned from RUNNING to COMPLETED
2013-08-07 07:15:49,068 INFO org.apache.hadoop.yarn.server.resourcemanager.scheduler.common.fica.FiCaSchedulerApp: Completed container: container_1375859105306_0005_01_000003 in state: COMPLETED event:FINISHED
2013-08-07 07:15:49,068 INFO org.apache.hadoop.yarn.server.resourcemanager.RMAuditLogger: USER=ubuntu	OPERATION=AM Released Container	TARGET=SchedulerApp	RESULT=SUCCESS	APPID=application_1375859105306_0005	CONTAINERID=container_1375859105306_0005_01_000003
2013-08-07 07:15:49,068 INFO org.apache.hadoop.yarn.server.resourcemanager.scheduler.common.fica.FiCaSchedulerNode: Released container container_1375859105306_0005_01_000003 of capacity <memory:1024, vCores:1> on host hadoop-200-3:55493, which currently has 0 containers, <memory:0, vCores:0> used and <memory:8192, vCores:16> available, release resources=true
2013-08-07 07:15:49,068 INFO org.apache.hadoop.yarn.server.resourcemanager.scheduler.capacity.LeafQueue: default used=<memory:3072, vCores:2> numContainers=2 user=ubuntu user-resources=<memory:3072, vCores:2>
2013-08-07 07:15:49,070 INFO org.apache.hadoop.yarn.server.resourcemanager.scheduler.capacity.LeafQueue: completedContainer container=Container: [ContainerId: container_1375859105306_0005_01_000003, NodeId: hadoop-200-3:55493, NodeHttpAddress: hadoop-200-3:8042, Resource: <memory:1024, vCores:1>, Priority: 20, State: NEW, Token: null, Status: container_id {, app_attempt_id {, application_id {, id: 5, cluster_timestamp: 1375859105306, }, attemptId: 1, }, id: 3, }, state: C_COMPLETE, diagnostics: "Container killed by the ApplicationMaster.\n\n", exit_status: 143, ] resource=<memory:1024, vCores:1> queue=default: capacity=1.0, absoluteCapacity=1.0, usedResources=<memory:3072, vCores:2>usedCapacity=0.0625, absoluteUsedCapacity=0.0625, numApps=1, numContainers=2 usedCapacity=0.0625 absoluteUsedCapacity=0.0625 used=<memory:3072, vCores:2> cluster=<memory:49152, vCores:96>
2013-08-07 07:15:49,070 INFO org.apache.hadoop.yarn.server.resourcemanager.scheduler.capacity.ParentQueue: completedContainer queue=root usedCapacity=0.0625 absoluteUsedCapacity=0.0625 used=<memory:3072, vCores:2> cluster=<memory:49152, vCores:96>
2013-08-07 07:15:49,070 INFO org.apache.hadoop.yarn.server.resourcemanager.scheduler.capacity.CapacityScheduler: Application appattempt_1375859105306_0005_000001 released container container_1375859105306_0005_01_000003 on node: host: hadoop-200-3:55493 #containers=0 available=8192 used=0 with event: FINISHED
2013-08-07 07:15:49,342 INFO org.apache.hadoop.yarn.server.resourcemanager.rmcontainer.RMContainerImpl: container_1375859105306_0005_01_000002 Container Transitioned from RUNNING to COMPLETED
2013-08-07 07:15:49,343 INFO org.apache.hadoop.yarn.server.resourcemanager.scheduler.common.fica.FiCaSchedulerApp: Completed container: container_1375859105306_0005_01_000002 in state: COMPLETED event:FINISHED
2013-08-07 07:15:49,343 INFO org.apache.hadoop.yarn.server.resourcemanager.RMAuditLogger: USER=ubuntu	OPERATION=AM Released Container	TARGET=SchedulerApp	RESULT=SUCCESS	APPID=application_1375859105306_0005	CONTAINERID=container_1375859105306_0005_01_000002
2013-08-07 07:15:49,343 INFO org.apache.hadoop.yarn.server.resourcemanager.scheduler.common.fica.FiCaSchedulerNode: Released container container_1375859105306_0005_01_000002 of capacity <memory:1024, vCores:1> on host hadoop-200-5:52184, which currently has 0 containers, <memory:0, vCores:0> used and <memory:8192, vCores:16> available, release resources=true
2013-08-07 07:15:49,343 INFO org.apache.hadoop.yarn.server.resourcemanager.scheduler.capacity.LeafQueue: default used=<memory:2048, vCores:1> numContainers=1 user=ubuntu user-resources=<memory:2048, vCores:1>
2013-08-07 07:15:49,345 INFO org.apache.hadoop.yarn.server.resourcemanager.scheduler.capacity.LeafQueue: completedContainer container=Container: [ContainerId: container_1375859105306_0005_01_000002, NodeId: hadoop-200-5:52184, NodeHttpAddress: hadoop-200-5:8042, Resource: <memory:1024, vCores:1>, Priority: 20, State: NEW, Token: null, Status: container_id {, app_attempt_id {, application_id {, id: 5, cluster_timestamp: 1375859105306, }, attemptId: 1, }, id: 2, }, state: C_COMPLETE, diagnostics: "Container killed by the ApplicationMaster.\n\n", exit_status: 143, ] resource=<memory:1024, vCores:1> queue=default: capacity=1.0, absoluteCapacity=1.0, usedResources=<memory:2048, vCores:1>usedCapacity=0.041666668, absoluteUsedCapacity=0.041666668, numApps=1, numContainers=1 usedCapacity=0.041666668 absoluteUsedCapacity=0.041666668 used=<memory:2048, vCores:1> cluster=<memory:49152, vCores:96>
2013-08-07 07:15:49,345 INFO org.apache.hadoop.yarn.server.resourcemanager.scheduler.capacity.ParentQueue: completedContainer queue=root usedCapacity=0.041666668 absoluteUsedCapacity=0.041666668 used=<memory:2048, vCores:1> cluster=<memory:49152, vCores:96>
2013-08-07 07:15:49,345 INFO org.apache.hadoop.yarn.server.resourcemanager.scheduler.capacity.CapacityScheduler: Application appattempt_1375859105306_0005_000001 released container container_1375859105306_0005_01_000002 on node: host: hadoop-200-5:52184 #containers=0 available=8192 used=0 with event: FINISHED
2013-08-07 07:15:54,122 INFO org.apache.hadoop.yarn.server.resourcemanager.rmapp.attempt.RMAppAttemptImpl: appattempt_1375859105306_0005_000001 State change from RUNNING to FINISHING
2013-08-07 07:15:54,123 INFO org.apache.hadoop.yarn.server.resourcemanager.rmapp.RMAppImpl: application_1375859105306_0005 State change from RUNNING to FINISHING
2013-08-07 07:15:54,764 INFO org.apache.hadoop.yarn.server.resourcemanager.rmcontainer.RMContainerImpl: container_1375859105306_0005_01_000001 Container Transitioned from RUNNING to COMPLETED
2013-08-07 07:15:54,764 INFO org.apache.hadoop.yarn.server.resourcemanager.scheduler.common.fica.FiCaSchedulerApp: Completed container: container_1375859105306_0005_01_000001 in state: COMPLETED event:FINISHED
2013-08-07 07:15:54,764 INFO org.apache.hadoop.yarn.server.resourcemanager.RMAuditLogger: USER=ubuntu	OPERATION=AM Released Container	TARGET=SchedulerApp	RESULT=SUCCESS	APPID=application_1375859105306_0005	CONTAINERID=container_1375859105306_0005_01_000001
2013-08-07 07:15:54,764 INFO org.apache.hadoop.yarn.server.resourcemanager.scheduler.common.fica.FiCaSchedulerNode: Released container container_1375859105306_0005_01_000001 of capacity <memory:2048, vCores:1> on host hadoop-200-2:35087, which currently has 0 containers, <memory:0, vCores:0> used and <memory:8192, vCores:16> available, release resources=true
2013-08-07 07:15:54,764 INFO org.apache.hadoop.yarn.server.resourcemanager.scheduler.capacity.LeafQueue: default used=<memory:0, vCores:0> numContainers=0 user=ubuntu user-resources=<memory:0, vCores:0>
2013-08-07 07:15:54,765 INFO org.apache.hadoop.yarn.server.resourcemanager.scheduler.capacity.LeafQueue: completedContainer container=Container: [ContainerId: container_1375859105306_0005_01_000001, NodeId: hadoop-200-2:35087, NodeHttpAddress: hadoop-200-2:8042, Resource: <memory:2048, vCores:1>, Priority: 0, State: NEW, Token: null, Status: container_id {, app_attempt_id {, application_id {, id: 5, cluster_timestamp: 1375859105306, }, attemptId: 1, }, id: 1, }, state: C_COMPLETE, diagnostics: "", exit_status: 0, ] resource=<memory:2048, vCores:1> queue=default: capacity=1.0, absoluteCapacity=1.0, usedResources=<memory:0, vCores:0>usedCapacity=0.0, absoluteUsedCapacity=0.0, numApps=1, numContainers=0 usedCapacity=0.0 absoluteUsedCapacity=0.0 used=<memory:0, vCores:0> cluster=<memory:49152, vCores:96>
2013-08-07 07:15:54,765 INFO org.apache.hadoop.yarn.server.resourcemanager.scheduler.capacity.ParentQueue: completedContainer queue=root usedCapacity=0.0 absoluteUsedCapacity=0.0 used=<memory:0, vCores:0> cluster=<memory:49152, vCores:96>
2013-08-07 07:15:54,765 INFO org.apache.hadoop.yarn.server.resourcemanager.scheduler.capacity.CapacityScheduler: Application appattempt_1375859105306_0005_000001 released container container_1375859105306_0005_01_000001 on node: host: hadoop-200-2:35087 #containers=0 available=8192 used=0 with event: FINISHED
2013-08-07 07:15:54,765 INFO org.apache.hadoop.yarn.server.resourcemanager.rmapp.attempt.RMAppAttemptImpl: appattempt_1375859105306_0005_000001 State change from FINISHING to FINISHED
2013-08-07 07:15:54,765 INFO org.apache.hadoop.yarn.server.resourcemanager.rmapp.RMAppImpl: application_1375859105306_0005 State change from FINISHING to FINISHED
2013-08-07 07:15:54,766 INFO org.apache.hadoop.yarn.server.resourcemanager.RMAuditLogger: USER=ubuntu	OPERATION=Application Finished - Succeeded	TARGET=RMAppManager	RESULT=SUCCESS	APPID=application_1375859105306_0005
2013-08-07 07:15:54,766 INFO org.apache.hadoop.yarn.server.resourcemanager.RMAppManager$ApplicationSummary: appId=application_1375859105306_0005,name=TeraGen,user=ubuntu,queue=default,state=FINISHED,trackingUrl=hadoop-200-1.novalocal:8088/proxy/application_1375859105306_0005/jobhistory/job/job_1375859105306_0005,appMasterHost=hadoop-200-2,startTime=1375859633059,finishTime=1375859754123
2013-08-07 07:15:54,766 INFO org.apache.hadoop.yarn.server.resourcemanager.amlauncher.AMLauncher: Cleaning master appattempt_1375859105306_0005_000001
2013-08-07 07:15:54,766 INFO org.apache.hadoop.yarn.server.resourcemanager.scheduler.capacity.CapacityScheduler: Application appattempt_1375859105306_0005_000001 is done. finalState=FINISHED
2013-08-07 07:15:54,766 INFO org.apache.hadoop.yarn.server.resourcemanager.scheduler.AppSchedulingInfo: Application application_1375859105306_0005 requests cleared
2013-08-07 07:15:54,766 INFO org.apache.hadoop.yarn.server.resourcemanager.scheduler.capacity.LeafQueue: Application removed - appId: application_1375859105306_0005 user: ubuntu queue: default #user-pending-applications: 0 #user-active-applications: 0 #queue-pending-applications: 0 #queue-active-applications: 0
2013-08-07 07:15:54,766 INFO org.apache.hadoop.yarn.server.resourcemanager.scheduler.capacity.ParentQueue: Application removed - appId: application_1375859105306_0005 user: ubuntu leaf-queue of parent: root #applications: 0
2013-08-07 07:15:54,770 INFO org.apache.hadoop.yarn.server.resourcemanager.recovery.RMStateStore: Removing info for app: application_1375859105306_0005
2013-08-07 07:15:59,014 INFO org.apache.hadoop.yarn.server.resourcemanager.ClientRMService: Allocated new applicationId: 6
2013-08-07 07:15:59,196 INFO org.apache.hadoop.yarn.server.resourcemanager.ClientRMService: Allocated new applicationId: 7
2013-08-07 07:15:59,837 INFO org.apache.hadoop.yarn.server.resourcemanager.ClientRMService: Allocated new applicationId: 8
2013-08-07 07:16:00,287 INFO org.apache.hadoop.yarn.server.resourcemanager.ClientRMService: Allocated new applicationId: 9
2013-08-07 07:16:00,380 INFO org.apache.hadoop.yarn.server.resourcemanager.ClientRMService: Storing Application with id application_1375859105306_0006
2013-08-07 07:16:00,380 INFO org.apache.hadoop.yarn.server.resourcemanager.recovery.RMStateStore: Storing info for app: application_1375859105306_0006
2013-08-07 07:16:00,380 INFO org.apache.hadoop.yarn.server.resourcemanager.ClientRMService: Application with id 6 submitted by user ubuntu
2013-08-07 07:16:00,380 INFO org.apache.hadoop.yarn.server.resourcemanager.RMAuditLogger: USER=ubuntu	IP=192.168.100.2	OPERATION=Submit Application Request	TARGET=ClientRMService	RESULT=SUCCESS	APPID=application_1375859105306_0006
2013-08-07 07:16:00,381 INFO org.apache.hadoop.yarn.server.resourcemanager.rmapp.RMAppImpl: application_1375859105306_0006 State change from NEW to SUBMITTED
2013-08-07 07:16:00,382 INFO org.apache.hadoop.yarn.server.resourcemanager.ApplicationMasterService: Registering appattempt_1375859105306_0006_000001
2013-08-07 07:16:00,382 INFO org.apache.hadoop.yarn.server.resourcemanager.rmapp.attempt.RMAppAttemptImpl: appattempt_1375859105306_0006_000001 State change from NEW to SUBMITTED
2013-08-07 07:16:00,382 INFO org.apache.hadoop.yarn.server.resourcemanager.scheduler.capacity.LeafQueue: Application application_1375859105306_0006 from user: ubuntu activated in queue: default
2013-08-07 07:16:00,382 INFO org.apache.hadoop.yarn.server.resourcemanager.scheduler.capacity.LeafQueue: Application added - appId: application_1375859105306_0006 user: org.apache.hadoop.yarn.server.resourcemanager.scheduler.capacity.LeafQueue$User@50f66944, leaf-queue: default #user-pending-applications: 0 #user-active-applications: 1 #queue-pending-applications: 0 #queue-active-applications: 1
2013-08-07 07:16:00,382 INFO org.apache.hadoop.yarn.server.resourcemanager.scheduler.capacity.ParentQueue: Application added - appId: application_1375859105306_0006 user: ubuntu leaf-queue of parent: root #applications: 1
2013-08-07 07:16:00,382 INFO org.apache.hadoop.yarn.server.resourcemanager.scheduler.capacity.CapacityScheduler: Application Submission: appattempt_1375859105306_0006_000001, user: ubuntu queue: default: capacity=1.0, absoluteCapacity=1.0, usedResources=<memory:0, vCores:0>usedCapacity=0.0, absoluteUsedCapacity=0.0, numApps=1, numContainers=0, currently active: 1
2013-08-07 07:16:00,382 INFO org.apache.hadoop.yarn.server.resourcemanager.rmapp.attempt.RMAppAttemptImpl: appattempt_1375859105306_0006_000001 State change from SUBMITTED to SCHEDULED
2013-08-07 07:16:00,382 INFO org.apache.hadoop.yarn.server.resourcemanager.rmapp.RMAppImpl: application_1375859105306_0006 State change from SUBMITTED to ACCEPTED
2013-08-07 07:16:00,384 INFO org.apache.hadoop.yarn.server.resourcemanager.ClientRMService: Allocated new applicationId: 10
2013-08-07 07:16:00,694 INFO org.apache.hadoop.yarn.server.resourcemanager.ClientRMService: Storing Application with id application_1375859105306_0007
2013-08-07 07:16:00,694 INFO org.apache.hadoop.yarn.server.resourcemanager.recovery.RMStateStore: Storing info for app: application_1375859105306_0007
2013-08-07 07:16:00,694 INFO org.apache.hadoop.yarn.server.resourcemanager.ClientRMService: Application with id 7 submitted by user ubuntu
2013-08-07 07:16:00,695 INFO org.apache.hadoop.yarn.server.resourcemanager.RMAuditLogger: USER=ubuntu	IP=192.168.100.2	OPERATION=Submit Application Request	TARGET=ClientRMService	RESULT=SUCCESS	APPID=application_1375859105306_0007
2013-08-07 07:16:00,695 INFO org.apache.hadoop.yarn.server.resourcemanager.rmapp.RMAppImpl: application_1375859105306_0007 State change from NEW to SUBMITTED
2013-08-07 07:16:00,695 INFO org.apache.hadoop.yarn.server.resourcemanager.ApplicationMasterService: Registering appattempt_1375859105306_0007_000001
2013-08-07 07:16:00,695 INFO org.apache.hadoop.yarn.server.resourcemanager.rmapp.attempt.RMAppAttemptImpl: appattempt_1375859105306_0007_000001 State change from NEW to SUBMITTED
2013-08-07 07:16:00,696 INFO org.apache.hadoop.yarn.server.resourcemanager.scheduler.capacity.LeafQueue: Application application_1375859105306_0007 from user: ubuntu activated in queue: default
2013-08-07 07:16:00,696 INFO org.apache.hadoop.yarn.server.resourcemanager.scheduler.capacity.LeafQueue: Application added - appId: application_1375859105306_0007 user: org.apache.hadoop.yarn.server.resourcemanager.scheduler.capacity.LeafQueue$User@50f66944, leaf-queue: default #user-pending-applications: 0 #user-active-applications: 2 #queue-pending-applications: 0 #queue-active-applications: 2
2013-08-07 07:16:00,696 INFO org.apache.hadoop.yarn.server.resourcemanager.scheduler.capacity.ParentQueue: Application added - appId: application_1375859105306_0007 user: ubuntu leaf-queue of parent: root #applications: 2
2013-08-07 07:16:00,696 INFO org.apache.hadoop.yarn.server.resourcemanager.scheduler.capacity.CapacityScheduler: Application Submission: appattempt_1375859105306_0007_000001, user: ubuntu queue: default: capacity=1.0, absoluteCapacity=1.0, usedResources=<memory:0, vCores:0>usedCapacity=0.0, absoluteUsedCapacity=0.0, numApps=2, numContainers=0, currently active: 2
2013-08-07 07:16:00,696 INFO org.apache.hadoop.yarn.server.resourcemanager.rmapp.attempt.RMAppAttemptImpl: appattempt_1375859105306_0007_000001 State change from SUBMITTED to SCHEDULED
2013-08-07 07:16:00,696 INFO org.apache.hadoop.yarn.server.resourcemanager.rmapp.RMAppImpl: application_1375859105306_0007 State change from SUBMITTED to ACCEPTED
2013-08-07 07:16:00,784 INFO org.apache.hadoop.yarn.server.resourcemanager.rmcontainer.RMContainerImpl: container_1375859105306_0006_01_000001 Container Transitioned from NEW to ALLOCATED
2013-08-07 07:16:00,784 INFO org.apache.hadoop.yarn.server.resourcemanager.RMAuditLogger: USER=ubuntu	OPERATION=AM Allocated Container	TARGET=SchedulerApp	RESULT=SUCCESS	APPID=application_1375859105306_0006	CONTAINERID=container_1375859105306_0006_01_000001
2013-08-07 07:16:00,784 INFO org.apache.hadoop.yarn.server.resourcemanager.scheduler.common.fica.FiCaSchedulerNode: Assigned container container_1375859105306_0006_01_000001 of capacity <memory:2048, vCores:1> on host hadoop-200-2:35087, which currently has 1 containers, <memory:2048, vCores:1> used and <memory:6144, vCores:15> available
2013-08-07 07:16:00,785 INFO org.apache.hadoop.yarn.server.resourcemanager.scheduler.capacity.LeafQueue: assignedContainer application=application_1375859105306_0006 container=Container: [ContainerId: container_1375859105306_0006_01_000001, NodeId: hadoop-200-2:35087, NodeHttpAddress: hadoop-200-2:8042, Resource: <memory:2048, vCores:1>, Priority: 0, State: NEW, Token: null, Status: container_id {, app_attempt_id {, application_id {, id: 6, cluster_timestamp: 1375859105306, }, attemptId: 1, }, id: 1, }, state: C_NEW, ] containerId=container_1375859105306_0006_01_000001 queue=default: capacity=1.0, absoluteCapacity=1.0, usedResources=<memory:0, vCores:0>usedCapacity=0.0, absoluteUsedCapacity=0.0, numApps=2, numContainers=0 usedCapacity=0.0 absoluteUsedCapacity=0.0 used=<memory:0, vCores:0> cluster=<memory:49152, vCores:96>
2013-08-07 07:16:00,785 INFO org.apache.hadoop.yarn.server.resourcemanager.scheduler.capacity.ParentQueue: Re-sorting queues since queue: root.default stats: default: capacity=1.0, absoluteCapacity=1.0, usedResources=<memory:2048, vCores:1>usedCapacity=0.041666668, absoluteUsedCapacity=0.041666668, numApps=2, numContainers=1
2013-08-07 07:16:00,786 INFO org.apache.hadoop.yarn.server.resourcemanager.scheduler.capacity.ParentQueue: assignedContainer queue=root usedCapacity=0.041666668 absoluteUsedCapacity=0.041666668 used=<memory:2048, vCores:1> cluster=<memory:49152, vCores:96>
2013-08-07 07:16:00,791 INFO org.apache.hadoop.yarn.server.resourcemanager.rmcontainer.RMContainerImpl: container_1375859105306_0006_01_000001 Container Transitioned from ALLOCATED to ACQUIRED
2013-08-07 07:16:00,792 INFO org.apache.hadoop.yarn.server.resourcemanager.rmapp.attempt.RMAppAttemptImpl: Storing attempt: AppId: application_1375859105306_0006 AttemptId: appattempt_1375859105306_0006_000001 MasterContainer: Container: [ContainerId: container_1375859105306_0006_01_000001, NodeId: hadoop-200-2:35087, NodeHttpAddress: hadoop-200-2:8042, Resource: <memory:2048, vCores:1>, Priority: 0, State: NEW, Token: null, Status: container_id {, app_attempt_id {, application_id {, id: 6, cluster_timestamp: 1375859105306, }, attemptId: 1, }, id: 1, }, state: C_NEW, ]
2013-08-07 07:16:00,792 INFO org.apache.hadoop.yarn.server.resourcemanager.recovery.RMStateStore: Storing info for attempt: appattempt_1375859105306_0006_000001
2013-08-07 07:16:00,792 INFO org.apache.hadoop.yarn.server.resourcemanager.rmapp.attempt.RMAppAttemptImpl: appattempt_1375859105306_0006_000001 State change from SCHEDULED to ALLOCATED_SAVING
2013-08-07 07:16:00,792 INFO org.apache.hadoop.yarn.server.resourcemanager.rmapp.attempt.RMAppAttemptImpl: appattempt_1375859105306_0006_000001 State change from ALLOCATED_SAVING to ALLOCATED
2013-08-07 07:16:00,793 INFO org.apache.hadoop.yarn.server.resourcemanager.amlauncher.AMLauncher: Launching masterappattempt_1375859105306_0006_000001
2013-08-07 07:16:00,794 INFO org.apache.hadoop.yarn.server.resourcemanager.amlauncher.AMLauncher: Setting up container Container: [ContainerId: container_1375859105306_0006_01_000001, NodeId: hadoop-200-2:35087, NodeHttpAddress: hadoop-200-2:8042, Resource: <memory:2048, vCores:1>, Priority: 0, State: NEW, Token: null, Status: container_id {, app_attempt_id {, application_id {, id: 6, cluster_timestamp: 1375859105306, }, attemptId: 1, }, id: 1, }, state: C_NEW, ] for AM appattempt_1375859105306_0006_000001
2013-08-07 07:16:00,794 INFO org.apache.hadoop.yarn.server.resourcemanager.amlauncher.AMLauncher: Command to launch container container_1375859105306_0006_01_000001 : $JAVA_HOME/bin/java -Dlog4j.configuration=container-log4j.properties -Dyarn.app.mapreduce.container.log.dir=<LOG_DIR> -Dyarn.app.mapreduce.container.log.filesize=0 -Dhadoop.root.logger=INFO,CLA  -Xmx1024m org.apache.hadoop.mapreduce.v2.app.MRAppMaster 1><LOG_DIR>/stdout 2><LOG_DIR>/stderr 
2013-08-07 07:16:00,805 INFO org.apache.hadoop.yarn.server.resourcemanager.amlauncher.AMLauncher: Done launching container Container: [ContainerId: container_1375859105306_0006_01_000001, NodeId: hadoop-200-2:35087, NodeHttpAddress: hadoop-200-2:8042, Resource: <memory:2048, vCores:1>, Priority: 0, State: NEW, Token: null, Status: container_id {, app_attempt_id {, application_id {, id: 6, cluster_timestamp: 1375859105306, }, attemptId: 1, }, id: 1, }, state: C_NEW, ] for AM appattempt_1375859105306_0006_000001
2013-08-07 07:16:00,805 INFO org.apache.hadoop.yarn.server.resourcemanager.rmapp.attempt.RMAppAttemptImpl: appattempt_1375859105306_0006_000001 State change from ALLOCATED to LAUNCHED
2013-08-07 07:16:01,112 INFO org.apache.hadoop.yarn.server.resourcemanager.rmcontainer.RMContainerImpl: container_1375859105306_0007_01_000001 Container Transitioned from NEW to ALLOCATED
2013-08-07 07:16:01,112 INFO org.apache.hadoop.yarn.server.resourcemanager.RMAuditLogger: USER=ubuntu	OPERATION=AM Allocated Container	TARGET=SchedulerApp	RESULT=SUCCESS	APPID=application_1375859105306_0007	CONTAINERID=container_1375859105306_0007_01_000001
2013-08-07 07:16:01,112 INFO org.apache.hadoop.yarn.server.resourcemanager.scheduler.common.fica.FiCaSchedulerNode: Assigned container container_1375859105306_0007_01_000001 of capacity <memory:2048, vCores:1> on host hadoop-200-3:55493, which currently has 1 containers, <memory:2048, vCores:1> used and <memory:6144, vCores:15> available
2013-08-07 07:16:01,113 INFO org.apache.hadoop.yarn.server.resourcemanager.scheduler.capacity.LeafQueue: assignedContainer application=application_1375859105306_0007 container=Container: [ContainerId: container_1375859105306_0007_01_000001, NodeId: hadoop-200-3:55493, NodeHttpAddress: hadoop-200-3:8042, Resource: <memory:2048, vCores:1>, Priority: 0, State: NEW, Token: null, Status: container_id {, app_attempt_id {, application_id {, id: 7, cluster_timestamp: 1375859105306, }, attemptId: 1, }, id: 1, }, state: C_NEW, ] containerId=container_1375859105306_0007_01_000001 queue=default: capacity=1.0, absoluteCapacity=1.0, usedResources=<memory:2048, vCores:1>usedCapacity=0.041666668, absoluteUsedCapacity=0.041666668, numApps=2, numContainers=1 usedCapacity=0.041666668 absoluteUsedCapacity=0.041666668 used=<memory:2048, vCores:1> cluster=<memory:49152, vCores:96>
2013-08-07 07:16:01,113 INFO org.apache.hadoop.yarn.server.resourcemanager.scheduler.capacity.ParentQueue: Re-sorting queues since queue: root.default stats: default: capacity=1.0, absoluteCapacity=1.0, usedResources=<memory:4096, vCores:2>usedCapacity=0.083333336, absoluteUsedCapacity=0.083333336, numApps=2, numContainers=2
2013-08-07 07:16:01,113 INFO org.apache.hadoop.yarn.server.resourcemanager.scheduler.capacity.ParentQueue: assignedContainer queue=root usedCapacity=0.083333336 absoluteUsedCapacity=0.083333336 used=<memory:4096, vCores:2> cluster=<memory:49152, vCores:96>
2013-08-07 07:16:01,117 INFO org.apache.hadoop.yarn.server.resourcemanager.rmcontainer.RMContainerImpl: container_1375859105306_0007_01_000001 Container Transitioned from ALLOCATED to ACQUIRED
2013-08-07 07:16:01,117 INFO org.apache.hadoop.yarn.server.resourcemanager.rmapp.attempt.RMAppAttemptImpl: Storing attempt: AppId: application_1375859105306_0007 AttemptId: appattempt_1375859105306_0007_000001 MasterContainer: Container: [ContainerId: container_1375859105306_0007_01_000001, NodeId: hadoop-200-3:55493, NodeHttpAddress: hadoop-200-3:8042, Resource: <memory:2048, vCores:1>, Priority: 0, State: NEW, Token: null, Status: container_id {, app_attempt_id {, application_id {, id: 7, cluster_timestamp: 1375859105306, }, attemptId: 1, }, id: 1, }, state: C_NEW, ]
2013-08-07 07:16:01,118 INFO org.apache.hadoop.yarn.server.resourcemanager.rmapp.attempt.RMAppAttemptImpl: appattempt_1375859105306_0007_000001 State change from SCHEDULED to ALLOCATED_SAVING
2013-08-07 07:16:01,118 INFO org.apache.hadoop.yarn.server.resourcemanager.recovery.RMStateStore: Storing info for attempt: appattempt_1375859105306_0007_000001
2013-08-07 07:16:01,119 INFO org.apache.hadoop.yarn.server.resourcemanager.rmapp.attempt.RMAppAttemptImpl: appattempt_1375859105306_0007_000001 State change from ALLOCATED_SAVING to ALLOCATED
2013-08-07 07:16:01,119 INFO org.apache.hadoop.yarn.server.resourcemanager.amlauncher.AMLauncher: Launching masterappattempt_1375859105306_0007_000001
2013-08-07 07:16:01,121 INFO org.apache.hadoop.yarn.server.resourcemanager.amlauncher.AMLauncher: Setting up container Container: [ContainerId: container_1375859105306_0007_01_000001, NodeId: hadoop-200-3:55493, NodeHttpAddress: hadoop-200-3:8042, Resource: <memory:2048, vCores:1>, Priority: 0, State: NEW, Token: null, Status: container_id {, app_attempt_id {, application_id {, id: 7, cluster_timestamp: 1375859105306, }, attemptId: 1, }, id: 1, }, state: C_NEW, ] for AM appattempt_1375859105306_0007_000001
2013-08-07 07:16:01,121 INFO org.apache.hadoop.yarn.server.resourcemanager.amlauncher.AMLauncher: Command to launch container container_1375859105306_0007_01_000001 : $JAVA_HOME/bin/java -Dlog4j.configuration=container-log4j.properties -Dyarn.app.mapreduce.container.log.dir=<LOG_DIR> -Dyarn.app.mapreduce.container.log.filesize=0 -Dhadoop.root.logger=INFO,CLA  -Xmx1024m org.apache.hadoop.mapreduce.v2.app.MRAppMaster 1><LOG_DIR>/stdout 2><LOG_DIR>/stderr 
2013-08-07 07:16:01,132 INFO org.apache.hadoop.yarn.server.resourcemanager.ClientRMService: Storing Application with id application_1375859105306_0008
2013-08-07 07:16:01,133 INFO org.apache.hadoop.yarn.server.resourcemanager.recovery.RMStateStore: Storing info for app: application_1375859105306_0008
2013-08-07 07:16:01,133 INFO org.apache.hadoop.yarn.server.resourcemanager.ClientRMService: Application with id 8 submitted by user ubuntu
2013-08-07 07:16:01,133 INFO org.apache.hadoop.yarn.server.resourcemanager.RMAuditLogger: USER=ubuntu	IP=192.168.100.2	OPERATION=Submit Application Request	TARGET=ClientRMService	RESULT=SUCCESS	APPID=application_1375859105306_0008
2013-08-07 07:16:01,133 INFO org.apache.hadoop.yarn.server.resourcemanager.rmapp.RMAppImpl: application_1375859105306_0008 State change from NEW to SUBMITTED
2013-08-07 07:16:01,133 INFO org.apache.hadoop.yarn.server.resourcemanager.ApplicationMasterService: Registering appattempt_1375859105306_0008_000001
2013-08-07 07:16:01,133 INFO org.apache.hadoop.yarn.server.resourcemanager.rmapp.attempt.RMAppAttemptImpl: appattempt_1375859105306_0008_000001 State change from NEW to SUBMITTED
2013-08-07 07:16:01,134 INFO org.apache.hadoop.yarn.server.resourcemanager.scheduler.capacity.LeafQueue: Application application_1375859105306_0008 from user: ubuntu activated in queue: default
2013-08-07 07:16:01,134 INFO org.apache.hadoop.yarn.server.resourcemanager.scheduler.capacity.LeafQueue: Application added - appId: application_1375859105306_0008 user: org.apache.hadoop.yarn.server.resourcemanager.scheduler.capacity.LeafQueue$User@50f66944, leaf-queue: default #user-pending-applications: 0 #user-active-applications: 3 #queue-pending-applications: 0 #queue-active-applications: 3
2013-08-07 07:16:01,134 INFO org.apache.hadoop.yarn.server.resourcemanager.scheduler.capacity.ParentQueue: Application added - appId: application_1375859105306_0008 user: ubuntu leaf-queue of parent: root #applications: 3
2013-08-07 07:16:01,134 INFO org.apache.hadoop.yarn.server.resourcemanager.scheduler.capacity.CapacityScheduler: Application Submission: appattempt_1375859105306_0008_000001, user: ubuntu queue: default: capacity=1.0, absoluteCapacity=1.0, usedResources=<memory:4096, vCores:2>usedCapacity=0.083333336, absoluteUsedCapacity=0.083333336, numApps=3, numContainers=2, currently active: 3
2013-08-07 07:16:01,134 INFO org.apache.hadoop.yarn.server.resourcemanager.rmapp.attempt.RMAppAttemptImpl: appattempt_1375859105306_0008_000001 State change from SUBMITTED to SCHEDULED
2013-08-07 07:16:01,134 INFO org.apache.hadoop.yarn.server.resourcemanager.rmapp.RMAppImpl: application_1375859105306_0008 State change from SUBMITTED to ACCEPTED
2013-08-07 07:16:01,139 INFO org.apache.hadoop.yarn.server.resourcemanager.amlauncher.AMLauncher: Done launching container Container: [ContainerId: container_1375859105306_0007_01_000001, NodeId: hadoop-200-3:55493, NodeHttpAddress: hadoop-200-3:8042, Resource: <memory:2048, vCores:1>, Priority: 0, State: NEW, Token: null, Status: container_id {, app_attempt_id {, application_id {, id: 7, cluster_timestamp: 1375859105306, }, attemptId: 1, }, id: 1, }, state: C_NEW, ] for AM appattempt_1375859105306_0007_000001
2013-08-07 07:16:01,140 INFO org.apache.hadoop.yarn.server.resourcemanager.rmapp.attempt.RMAppAttemptImpl: appattempt_1375859105306_0007_000001 State change from ALLOCATED to LAUNCHED
2013-08-07 07:16:01,314 INFO org.apache.hadoop.yarn.server.resourcemanager.rmcontainer.RMContainerImpl: container_1375859105306_0008_01_000001 Container Transitioned from NEW to ALLOCATED
2013-08-07 07:16:01,315 INFO org.apache.hadoop.yarn.server.resourcemanager.RMAuditLogger: USER=ubuntu	OPERATION=AM Allocated Container	TARGET=SchedulerApp	RESULT=SUCCESS	APPID=application_1375859105306_0008	CONTAINERID=container_1375859105306_0008_01_000001
2013-08-07 07:16:01,315 INFO org.apache.hadoop.yarn.server.resourcemanager.scheduler.common.fica.FiCaSchedulerNode: Assigned container container_1375859105306_0008_01_000001 of capacity <memory:2048, vCores:1> on host hadoop-200-4:41828, which currently has 1 containers, <memory:2048, vCores:1> used and <memory:6144, vCores:15> available
2013-08-07 07:16:01,316 INFO org.apache.hadoop.yarn.server.resourcemanager.scheduler.capacity.LeafQueue: assignedContainer application=application_1375859105306_0008 container=Container: [ContainerId: container_1375859105306_0008_01_000001, NodeId: hadoop-200-4:41828, NodeHttpAddress: hadoop-200-4:8042, Resource: <memory:2048, vCores:1>, Priority: 0, State: NEW, Token: null, Status: container_id {, app_attempt_id {, application_id {, id: 8, cluster_timestamp: 1375859105306, }, attemptId: 1, }, id: 1, }, state: C_NEW, ] containerId=container_1375859105306_0008_01_000001 queue=default: capacity=1.0, absoluteCapacity=1.0, usedResources=<memory:4096, vCores:2>usedCapacity=0.083333336, absoluteUsedCapacity=0.083333336, numApps=3, numContainers=2 usedCapacity=0.083333336 absoluteUsedCapacity=0.083333336 used=<memory:4096, vCores:2> cluster=<memory:49152, vCores:96>
2013-08-07 07:16:01,316 INFO org.apache.hadoop.yarn.server.resourcemanager.scheduler.capacity.ParentQueue: Re-sorting queues since queue: root.default stats: default: capacity=1.0, absoluteCapacity=1.0, usedResources=<memory:6144, vCores:3>usedCapacity=0.125, absoluteUsedCapacity=0.125, numApps=3, numContainers=3
2013-08-07 07:16:01,316 INFO org.apache.hadoop.yarn.server.resourcemanager.scheduler.capacity.ParentQueue: assignedContainer queue=root usedCapacity=0.125 absoluteUsedCapacity=0.125 used=<memory:6144, vCores:3> cluster=<memory:49152, vCores:96>
2013-08-07 07:16:01,316 INFO org.apache.hadoop.yarn.server.resourcemanager.rmcontainer.RMContainerImpl: container_1375859105306_0008_01_000001 Container Transitioned from ALLOCATED to ACQUIRED
2013-08-07 07:16:01,317 INFO org.apache.hadoop.yarn.server.resourcemanager.rmapp.attempt.RMAppAttemptImpl: Storing attempt: AppId: application_1375859105306_0008 AttemptId: appattempt_1375859105306_0008_000001 MasterContainer: Container: [ContainerId: container_1375859105306_0008_01_000001, NodeId: hadoop-200-4:41828, NodeHttpAddress: hadoop-200-4:8042, Resource: <memory:2048, vCores:1>, Priority: 0, State: NEW, Token: null, Status: container_id {, app_attempt_id {, application_id {, id: 8, cluster_timestamp: 1375859105306, }, attemptId: 1, }, id: 1, }, state: C_NEW, ]
2013-08-07 07:16:01,317 INFO org.apache.hadoop.yarn.server.resourcemanager.rmapp.attempt.RMAppAttemptImpl: appattempt_1375859105306_0008_000001 State change from SCHEDULED to ALLOCATED_SAVING
2013-08-07 07:16:01,317 INFO org.apache.hadoop.yarn.server.resourcemanager.recovery.RMStateStore: Storing info for attempt: appattempt_1375859105306_0008_000001
2013-08-07 07:16:01,318 INFO org.apache.hadoop.yarn.server.resourcemanager.rmapp.attempt.RMAppAttemptImpl: appattempt_1375859105306_0008_000001 State change from ALLOCATED_SAVING to ALLOCATED
2013-08-07 07:16:01,319 INFO org.apache.hadoop.yarn.server.resourcemanager.amlauncher.AMLauncher: Launching masterappattempt_1375859105306_0008_000001
2013-08-07 07:16:01,320 INFO org.apache.hadoop.yarn.server.resourcemanager.amlauncher.AMLauncher: Setting up container Container: [ContainerId: container_1375859105306_0008_01_000001, NodeId: hadoop-200-4:41828, NodeHttpAddress: hadoop-200-4:8042, Resource: <memory:2048, vCores:1>, Priority: 0, State: NEW, Token: null, Status: container_id {, app_attempt_id {, application_id {, id: 8, cluster_timestamp: 1375859105306, }, attemptId: 1, }, id: 1, }, state: C_NEW, ] for AM appattempt_1375859105306_0008_000001
2013-08-07 07:16:01,320 INFO org.apache.hadoop.yarn.server.resourcemanager.amlauncher.AMLauncher: Command to launch container container_1375859105306_0008_01_000001 : $JAVA_HOME/bin/java -Dlog4j.configuration=container-log4j.properties -Dyarn.app.mapreduce.container.log.dir=<LOG_DIR> -Dyarn.app.mapreduce.container.log.filesize=0 -Dhadoop.root.logger=INFO,CLA  -Xmx1024m org.apache.hadoop.mapreduce.v2.app.MRAppMaster 1><LOG_DIR>/stdout 2><LOG_DIR>/stderr 
2013-08-07 07:16:01,348 INFO org.apache.hadoop.yarn.server.resourcemanager.amlauncher.AMLauncher: Done launching container Container: [ContainerId: container_1375859105306_0008_01_000001, NodeId: hadoop-200-4:41828, NodeHttpAddress: hadoop-200-4:8042, Resource: <memory:2048, vCores:1>, Priority: 0, State: NEW, Token: null, Status: container_id {, app_attempt_id {, application_id {, id: 8, cluster_timestamp: 1375859105306, }, attemptId: 1, }, id: 1, }, state: C_NEW, ] for AM appattempt_1375859105306_0008_000001
2013-08-07 07:16:01,348 INFO org.apache.hadoop.yarn.server.resourcemanager.rmapp.attempt.RMAppAttemptImpl: appattempt_1375859105306_0008_000001 State change from ALLOCATED to LAUNCHED
2013-08-07 07:16:01,474 INFO org.apache.hadoop.yarn.server.resourcemanager.ClientRMService: Storing Application with id application_1375859105306_0009
2013-08-07 07:16:01,475 INFO org.apache.hadoop.yarn.server.resourcemanager.recovery.RMStateStore: Storing info for app: application_1375859105306_0009
2013-08-07 07:16:01,475 INFO org.apache.hadoop.yarn.server.resourcemanager.ClientRMService: Application with id 9 submitted by user ubuntu
2013-08-07 07:16:01,475 INFO org.apache.hadoop.yarn.server.resourcemanager.RMAuditLogger: USER=ubuntu	IP=192.168.100.2	OPERATION=Submit Application Request	TARGET=ClientRMService	RESULT=SUCCESS	APPID=application_1375859105306_0009
2013-08-07 07:16:01,477 INFO org.apache.hadoop.yarn.server.resourcemanager.rmapp.RMAppImpl: application_1375859105306_0009 State change from NEW to SUBMITTED
2013-08-07 07:16:01,477 INFO org.apache.hadoop.yarn.server.resourcemanager.ApplicationMasterService: Registering appattempt_1375859105306_0009_000001
2013-08-07 07:16:01,477 INFO org.apache.hadoop.yarn.server.resourcemanager.rmapp.attempt.RMAppAttemptImpl: appattempt_1375859105306_0009_000001 State change from NEW to SUBMITTED
2013-08-07 07:16:01,478 INFO org.apache.hadoop.yarn.server.resourcemanager.scheduler.capacity.LeafQueue: Application application_1375859105306_0009 from user: ubuntu activated in queue: default
2013-08-07 07:16:01,478 INFO org.apache.hadoop.yarn.server.resourcemanager.scheduler.capacity.LeafQueue: Application added - appId: application_1375859105306_0009 user: org.apache.hadoop.yarn.server.resourcemanager.scheduler.capacity.LeafQueue$User@50f66944, leaf-queue: default #user-pending-applications: 0 #user-active-applications: 4 #queue-pending-applications: 0 #queue-active-applications: 4
2013-08-07 07:16:01,478 INFO org.apache.hadoop.yarn.server.resourcemanager.scheduler.capacity.ParentQueue: Application added - appId: application_1375859105306_0009 user: ubuntu leaf-queue of parent: root #applications: 4
2013-08-07 07:16:01,478 INFO org.apache.hadoop.yarn.server.resourcemanager.scheduler.capacity.CapacityScheduler: Application Submission: appattempt_1375859105306_0009_000001, user: ubuntu queue: default: capacity=1.0, absoluteCapacity=1.0, usedResources=<memory:6144, vCores:3>usedCapacity=0.125, absoluteUsedCapacity=0.125, numApps=4, numContainers=3, currently active: 4
2013-08-07 07:16:01,478 INFO org.apache.hadoop.yarn.server.resourcemanager.rmapp.attempt.RMAppAttemptImpl: appattempt_1375859105306_0009_000001 State change from SUBMITTED to SCHEDULED
2013-08-07 07:16:01,479 INFO org.apache.hadoop.yarn.server.resourcemanager.rmapp.RMAppImpl: application_1375859105306_0009 State change from SUBMITTED to ACCEPTED
2013-08-07 07:16:01,563 INFO org.apache.hadoop.yarn.server.resourcemanager.ClientRMService: Storing Application with id application_1375859105306_0010
2013-08-07 07:16:01,563 INFO org.apache.hadoop.yarn.server.resourcemanager.recovery.RMStateStore: Storing info for app: application_1375859105306_0010
2013-08-07 07:16:01,563 INFO org.apache.hadoop.yarn.server.resourcemanager.ClientRMService: Application with id 10 submitted by user ubuntu
2013-08-07 07:16:01,563 INFO org.apache.hadoop.yarn.server.resourcemanager.RMAuditLogger: USER=ubuntu	IP=192.168.100.2	OPERATION=Submit Application Request	TARGET=ClientRMService	RESULT=SUCCESS	APPID=application_1375859105306_0010
2013-08-07 07:16:01,565 INFO org.apache.hadoop.yarn.server.resourcemanager.rmapp.RMAppImpl: application_1375859105306_0010 State change from NEW to SUBMITTED
2013-08-07 07:16:01,565 INFO org.apache.hadoop.yarn.server.resourcemanager.ApplicationMasterService: Registering appattempt_1375859105306_0010_000001
2013-08-07 07:16:01,565 INFO org.apache.hadoop.yarn.server.resourcemanager.rmapp.attempt.RMAppAttemptImpl: appattempt_1375859105306_0010_000001 State change from NEW to SUBMITTED
2013-08-07 07:16:01,566 INFO org.apache.hadoop.yarn.server.resourcemanager.scheduler.capacity.LeafQueue: Application application_1375859105306_0010 from user: ubuntu activated in queue: default
2013-08-07 07:16:01,566 INFO org.apache.hadoop.yarn.server.resourcemanager.scheduler.capacity.LeafQueue: Application added - appId: application_1375859105306_0010 user: org.apache.hadoop.yarn.server.resourcemanager.scheduler.capacity.LeafQueue$User@50f66944, leaf-queue: default #user-pending-applications: 0 #user-active-applications: 5 #queue-pending-applications: 0 #queue-active-applications: 5
2013-08-07 07:16:01,566 INFO org.apache.hadoop.yarn.server.resourcemanager.scheduler.capacity.ParentQueue: Application added - appId: application_1375859105306_0010 user: ubuntu leaf-queue of parent: root #applications: 5
2013-08-07 07:16:01,566 INFO org.apache.hadoop.yarn.server.resourcemanager.scheduler.capacity.CapacityScheduler: Application Submission: appattempt_1375859105306_0010_000001, user: ubuntu queue: default: capacity=1.0, absoluteCapacity=1.0, usedResources=<memory:6144, vCores:3>usedCapacity=0.125, absoluteUsedCapacity=0.125, numApps=5, numContainers=3, currently active: 5
2013-08-07 07:16:01,567 INFO org.apache.hadoop.yarn.server.resourcemanager.rmapp.attempt.RMAppAttemptImpl: appattempt_1375859105306_0010_000001 State change from SUBMITTED to SCHEDULED
2013-08-07 07:16:01,567 INFO org.apache.hadoop.yarn.server.resourcemanager.rmapp.RMAppImpl: application_1375859105306_0010 State change from SUBMITTED to ACCEPTED
2013-08-07 07:16:01,788 INFO org.apache.hadoop.yarn.server.resourcemanager.rmcontainer.RMContainerImpl: container_1375859105306_0006_01_000001 Container Transitioned from ACQUIRED to RUNNING
2013-08-07 07:16:01,789 INFO org.apache.hadoop.yarn.server.resourcemanager.rmcontainer.RMContainerImpl: container_1375859105306_0009_01_000001 Container Transitioned from NEW to ALLOCATED
2013-08-07 07:16:01,789 INFO org.apache.hadoop.yarn.server.resourcemanager.RMAuditLogger: USER=ubuntu	OPERATION=AM Allocated Container	TARGET=SchedulerApp	RESULT=SUCCESS	APPID=application_1375859105306_0009	CONTAINERID=container_1375859105306_0009_01_000001
2013-08-07 07:16:01,789 INFO org.apache.hadoop.yarn.server.resourcemanager.scheduler.common.fica.FiCaSchedulerNode: Assigned container container_1375859105306_0009_01_000001 of capacity <memory:2048, vCores:1> on host hadoop-200-2:35087, which currently has 2 containers, <memory:4096, vCores:2> used and <memory:4096, vCores:14> available
2013-08-07 07:16:01,791 INFO org.apache.hadoop.yarn.server.resourcemanager.scheduler.capacity.LeafQueue: assignedContainer application=application_1375859105306_0009 container=Container: [ContainerId: container_1375859105306_0009_01_000001, NodeId: hadoop-200-2:35087, NodeHttpAddress: hadoop-200-2:8042, Resource: <memory:2048, vCores:1>, Priority: 0, State: NEW, Token: null, Status: container_id {, app_attempt_id {, application_id {, id: 9, cluster_timestamp: 1375859105306, }, attemptId: 1, }, id: 1, }, state: C_NEW, ] containerId=container_1375859105306_0009_01_000001 queue=default: capacity=1.0, absoluteCapacity=1.0, usedResources=<memory:6144, vCores:3>usedCapacity=0.125, absoluteUsedCapacity=0.125, numApps=5, numContainers=3 usedCapacity=0.125 absoluteUsedCapacity=0.125 used=<memory:6144, vCores:3> cluster=<memory:49152, vCores:96>
2013-08-07 07:16:01,791 INFO org.apache.hadoop.yarn.server.resourcemanager.scheduler.capacity.ParentQueue: Re-sorting queues since queue: root.default stats: default: capacity=1.0, absoluteCapacity=1.0, usedResources=<memory:8192, vCores:4>usedCapacity=0.16666667, absoluteUsedCapacity=0.16666667, numApps=5, numContainers=4
2013-08-07 07:16:01,791 INFO org.apache.hadoop.yarn.server.resourcemanager.scheduler.capacity.ParentQueue: assignedContainer queue=root usedCapacity=0.16666667 absoluteUsedCapacity=0.16666667 used=<memory:8192, vCores:4> cluster=<memory:49152, vCores:96>
2013-08-07 07:16:01,792 INFO org.apache.hadoop.yarn.server.resourcemanager.rmcontainer.RMContainerImpl: container_1375859105306_0009_01_000001 Container Transitioned from ALLOCATED to ACQUIRED
2013-08-07 07:16:01,794 INFO org.apache.hadoop.yarn.server.resourcemanager.rmapp.attempt.RMAppAttemptImpl: Storing attempt: AppId: application_1375859105306_0009 AttemptId: appattempt_1375859105306_0009_000001 MasterContainer: Container: [ContainerId: container_1375859105306_0009_01_000001, NodeId: hadoop-200-2:35087, NodeHttpAddress: hadoop-200-2:8042, Resource: <memory:2048, vCores:1>, Priority: 0, State: NEW, Token: null, Status: container_id {, app_attempt_id {, application_id {, id: 9, cluster_timestamp: 1375859105306, }, attemptId: 1, }, id: 1, }, state: C_NEW, ]
2013-08-07 07:16:01,794 INFO org.apache.hadoop.yarn.server.resourcemanager.rmapp.attempt.RMAppAttemptImpl: appattempt_1375859105306_0009_000001 State change from SCHEDULED to ALLOCATED_SAVING
2013-08-07 07:16:01,794 INFO org.apache.hadoop.yarn.server.resourcemanager.recovery.RMStateStore: Storing info for attempt: appattempt_1375859105306_0009_000001
2013-08-07 07:16:01,795 INFO org.apache.hadoop.yarn.server.resourcemanager.rmapp.attempt.RMAppAttemptImpl: appattempt_1375859105306_0009_000001 State change from ALLOCATED_SAVING to ALLOCATED
2013-08-07 07:16:01,796 INFO org.apache.hadoop.yarn.server.resourcemanager.amlauncher.AMLauncher: Launching masterappattempt_1375859105306_0009_000001
2013-08-07 07:16:01,798 INFO org.apache.hadoop.yarn.server.resourcemanager.amlauncher.AMLauncher: Setting up container Container: [ContainerId: container_1375859105306_0009_01_000001, NodeId: hadoop-200-2:35087, NodeHttpAddress: hadoop-200-2:8042, Resource: <memory:2048, vCores:1>, Priority: 0, State: NEW, Token: null, Status: container_id {, app_attempt_id {, application_id {, id: 9, cluster_timestamp: 1375859105306, }, attemptId: 1, }, id: 1, }, state: C_NEW, ] for AM appattempt_1375859105306_0009_000001
2013-08-07 07:16:01,798 INFO org.apache.hadoop.yarn.server.resourcemanager.amlauncher.AMLauncher: Command to launch container container_1375859105306_0009_01_000001 : $JAVA_HOME/bin/java -Dlog4j.configuration=container-log4j.properties -Dyarn.app.mapreduce.container.log.dir=<LOG_DIR> -Dyarn.app.mapreduce.container.log.filesize=0 -Dhadoop.root.logger=INFO,CLA  -Xmx1024m org.apache.hadoop.mapreduce.v2.app.MRAppMaster 1><LOG_DIR>/stdout 2><LOG_DIR>/stderr 
2013-08-07 07:16:01,807 INFO org.apache.hadoop.yarn.server.resourcemanager.amlauncher.AMLauncher: Done launching container Container: [ContainerId: container_1375859105306_0009_01_000001, NodeId: hadoop-200-2:35087, NodeHttpAddress: hadoop-200-2:8042, Resource: <memory:2048, vCores:1>, Priority: 0, State: NEW, Token: null, Status: container_id {, app_attempt_id {, application_id {, id: 9, cluster_timestamp: 1375859105306, }, attemptId: 1, }, id: 1, }, state: C_NEW, ] for AM appattempt_1375859105306_0009_000001
2013-08-07 07:16:01,807 INFO org.apache.hadoop.yarn.server.resourcemanager.rmapp.attempt.RMAppAttemptImpl: appattempt_1375859105306_0009_000001 State change from ALLOCATED to LAUNCHED
2013-08-07 07:16:02,117 INFO org.apache.hadoop.yarn.server.resourcemanager.rmcontainer.RMContainerImpl: container_1375859105306_0007_01_000001 Container Transitioned from ACQUIRED to RUNNING
2013-08-07 07:16:02,120 INFO org.apache.hadoop.yarn.server.resourcemanager.rmcontainer.RMContainerImpl: container_1375859105306_0010_01_000001 Container Transitioned from NEW to ALLOCATED
2013-08-07 07:16:02,120 INFO org.apache.hadoop.yarn.server.resourcemanager.RMAuditLogger: USER=ubuntu	OPERATION=AM Allocated Container	TARGET=SchedulerApp	RESULT=SUCCESS	APPID=application_1375859105306_0010	CONTAINERID=container_1375859105306_0010_01_000001
2013-08-07 07:16:02,120 INFO org.apache.hadoop.yarn.server.resourcemanager.scheduler.common.fica.FiCaSchedulerNode: Assigned container container_1375859105306_0010_01_000001 of capacity <memory:2048, vCores:1> on host hadoop-200-3:55493, which currently has 2 containers, <memory:4096, vCores:2> used and <memory:4096, vCores:14> available
2013-08-07 07:16:02,122 INFO org.apache.hadoop.yarn.server.resourcemanager.scheduler.capacity.LeafQueue: assignedContainer application=application_1375859105306_0010 container=Container: [ContainerId: container_1375859105306_0010_01_000001, NodeId: hadoop-200-3:55493, NodeHttpAddress: hadoop-200-3:8042, Resource: <memory:2048, vCores:1>, Priority: 0, State: NEW, Token: null, Status: container_id {, app_attempt_id {, application_id {, id: 10, cluster_timestamp: 1375859105306, }, attemptId: 1, }, id: 1, }, state: C_NEW, ] containerId=container_1375859105306_0010_01_000001 queue=default: capacity=1.0, absoluteCapacity=1.0, usedResources=<memory:8192, vCores:4>usedCapacity=0.16666667, absoluteUsedCapacity=0.16666667, numApps=5, numContainers=4 usedCapacity=0.16666667 absoluteUsedCapacity=0.16666667 used=<memory:8192, vCores:4> cluster=<memory:49152, vCores:96>
2013-08-07 07:16:02,122 INFO org.apache.hadoop.yarn.server.resourcemanager.scheduler.capacity.ParentQueue: Re-sorting queues since queue: root.default stats: default: capacity=1.0, absoluteCapacity=1.0, usedResources=<memory:10240, vCores:5>usedCapacity=0.20833333, absoluteUsedCapacity=0.20833333, numApps=5, numContainers=5
2013-08-07 07:16:02,123 INFO org.apache.hadoop.yarn.server.resourcemanager.scheduler.capacity.ParentQueue: assignedContainer queue=root usedCapacity=0.20833333 absoluteUsedCapacity=0.20833333 used=<memory:10240, vCores:5> cluster=<memory:49152, vCores:96>
2013-08-07 07:16:02,124 INFO org.apache.hadoop.yarn.server.resourcemanager.rmcontainer.RMContainerImpl: container_1375859105306_0010_01_000001 Container Transitioned from ALLOCATED to ACQUIRED
2013-08-07 07:16:02,126 INFO org.apache.hadoop.yarn.server.resourcemanager.rmapp.attempt.RMAppAttemptImpl: Storing attempt: AppId: application_1375859105306_0010 AttemptId: appattempt_1375859105306_0010_000001 MasterContainer: Container: [ContainerId: container_1375859105306_0010_01_000001, NodeId: hadoop-200-3:55493, NodeHttpAddress: hadoop-200-3:8042, Resource: <memory:2048, vCores:1>, Priority: 0, State: NEW, Token: null, Status: container_id {, app_attempt_id {, application_id {, id: 10, cluster_timestamp: 1375859105306, }, attemptId: 1, }, id: 1, }, state: C_NEW, ]
2013-08-07 07:16:02,126 INFO org.apache.hadoop.yarn.server.resourcemanager.rmapp.attempt.RMAppAttemptImpl: appattempt_1375859105306_0010_000001 State change from SCHEDULED to ALLOCATED_SAVING
2013-08-07 07:16:02,126 INFO org.apache.hadoop.yarn.server.resourcemanager.recovery.RMStateStore: Storing info for attempt: appattempt_1375859105306_0010_000001
2013-08-07 07:16:02,127 INFO org.apache.hadoop.yarn.server.resourcemanager.rmapp.attempt.RMAppAttemptImpl: appattempt_1375859105306_0010_000001 State change from ALLOCATED_SAVING to ALLOCATED
2013-08-07 07:16:02,127 INFO org.apache.hadoop.yarn.server.resourcemanager.amlauncher.AMLauncher: Launching masterappattempt_1375859105306_0010_000001
2013-08-07 07:16:02,129 INFO org.apache.hadoop.yarn.server.resourcemanager.amlauncher.AMLauncher: Setting up container Container: [ContainerId: container_1375859105306_0010_01_000001, NodeId: hadoop-200-3:55493, NodeHttpAddress: hadoop-200-3:8042, Resource: <memory:2048, vCores:1>, Priority: 0, State: NEW, Token: null, Status: container_id {, app_attempt_id {, application_id {, id: 10, cluster_timestamp: 1375859105306, }, attemptId: 1, }, id: 1, }, state: C_NEW, ] for AM appattempt_1375859105306_0010_000001
2013-08-07 07:16:02,130 INFO org.apache.hadoop.yarn.server.resourcemanager.amlauncher.AMLauncher: Command to launch container container_1375859105306_0010_01_000001 : $JAVA_HOME/bin/java -Dlog4j.configuration=container-log4j.properties -Dyarn.app.mapreduce.container.log.dir=<LOG_DIR> -Dyarn.app.mapreduce.container.log.filesize=0 -Dhadoop.root.logger=INFO,CLA  -Xmx1024m org.apache.hadoop.mapreduce.v2.app.MRAppMaster 1><LOG_DIR>/stdout 2><LOG_DIR>/stderr 
2013-08-07 07:16:02,141 INFO org.apache.hadoop.yarn.server.resourcemanager.amlauncher.AMLauncher: Done launching container Container: [ContainerId: container_1375859105306_0010_01_000001, NodeId: hadoop-200-3:55493, NodeHttpAddress: hadoop-200-3:8042, Resource: <memory:2048, vCores:1>, Priority: 0, State: NEW, Token: null, Status: container_id {, app_attempt_id {, application_id {, id: 10, cluster_timestamp: 1375859105306, }, attemptId: 1, }, id: 1, }, state: C_NEW, ] for AM appattempt_1375859105306_0010_000001
2013-08-07 07:16:02,141 INFO org.apache.hadoop.yarn.server.resourcemanager.rmapp.attempt.RMAppAttemptImpl: appattempt_1375859105306_0010_000001 State change from ALLOCATED to LAUNCHED
2013-08-07 07:16:02,320 INFO org.apache.hadoop.yarn.server.resourcemanager.rmcontainer.RMContainerImpl: container_1375859105306_0008_01_000001 Container Transitioned from ACQUIRED to RUNNING
2013-08-07 07:16:02,794 INFO org.apache.hadoop.yarn.server.resourcemanager.rmcontainer.RMContainerImpl: container_1375859105306_0009_01_000001 Container Transitioned from ACQUIRED to RUNNING
2013-08-07 07:16:03,124 INFO org.apache.hadoop.yarn.server.resourcemanager.rmcontainer.RMContainerImpl: container_1375859105306_0010_01_000001 Container Transitioned from ACQUIRED to RUNNING
2013-08-07 07:16:06,681 INFO org.apache.hadoop.yarn.server.resourcemanager.ApplicationMasterService: AM registration appattempt_1375859105306_0006_000001
2013-08-07 07:16:06,681 INFO org.apache.hadoop.yarn.server.resourcemanager.RMAuditLogger: USER=ubuntu	IP=192.168.100.4	OPERATION=Register App Master	TARGET=ApplicationMasterService	RESULT=SUCCESS	APPID=application_1375859105306_0006	APPATTEMPTID=appattempt_1375859105306_0006_000001
2013-08-07 07:16:06,683 INFO org.apache.hadoop.yarn.server.resourcemanager.rmapp.attempt.RMAppAttemptImpl: appattempt_1375859105306_0006_000001 State change from LAUNCHED to RUNNING
2013-08-07 07:16:06,683 INFO org.apache.hadoop.yarn.server.resourcemanager.rmapp.RMAppImpl: application_1375859105306_0006 State change from ACCEPTED to RUNNING
2013-08-07 07:16:07,046 INFO org.apache.hadoop.yarn.server.resourcemanager.ApplicationMasterService: AM registration appattempt_1375859105306_0007_000001
2013-08-07 07:16:07,047 INFO org.apache.hadoop.yarn.server.resourcemanager.RMAuditLogger: USER=ubuntu	IP=192.168.100.3	OPERATION=Register App Master	TARGET=ApplicationMasterService	RESULT=SUCCESS	APPID=application_1375859105306_0007	APPATTEMPTID=appattempt_1375859105306_0007_000001
2013-08-07 07:16:07,047 INFO org.apache.hadoop.yarn.server.resourcemanager.rmapp.attempt.RMAppAttemptImpl: appattempt_1375859105306_0007_000001 State change from LAUNCHED to RUNNING
2013-08-07 07:16:07,048 INFO org.apache.hadoop.yarn.server.resourcemanager.rmapp.RMAppImpl: application_1375859105306_0007 State change from ACCEPTED to RUNNING
2013-08-07 07:16:07,541 INFO org.apache.hadoop.yarn.server.resourcemanager.ApplicationMasterService: AM registration appattempt_1375859105306_0010_000001
2013-08-07 07:16:07,541 INFO org.apache.hadoop.yarn.server.resourcemanager.RMAuditLogger: USER=ubuntu	IP=192.168.100.3	OPERATION=Register App Master	TARGET=ApplicationMasterService	RESULT=SUCCESS	APPID=application_1375859105306_0010	APPATTEMPTID=appattempt_1375859105306_0010_000001
2013-08-07 07:16:07,543 INFO org.apache.hadoop.yarn.server.resourcemanager.rmapp.attempt.RMAppAttemptImpl: appattempt_1375859105306_0010_000001 State change from LAUNCHED to RUNNING
2013-08-07 07:16:07,543 INFO org.apache.hadoop.yarn.server.resourcemanager.rmapp.RMAppImpl: application_1375859105306_0010 State change from ACCEPTED to RUNNING
2013-08-07 07:16:07,823 INFO org.apache.hadoop.yarn.server.resourcemanager.rmcontainer.RMContainerImpl: container_1375859105306_0006_01_000002 Container Transitioned from NEW to ALLOCATED
2013-08-07 07:16:07,823 INFO org.apache.hadoop.yarn.server.resourcemanager.RMAuditLogger: USER=ubuntu	OPERATION=AM Allocated Container	TARGET=SchedulerApp	RESULT=SUCCESS	APPID=application_1375859105306_0006	CONTAINERID=container_1375859105306_0006_01_000002
2013-08-07 07:16:07,823 INFO org.apache.hadoop.yarn.server.resourcemanager.scheduler.common.fica.FiCaSchedulerNode: Assigned container container_1375859105306_0006_01_000002 of capacity <memory:1024, vCores:1> on host hadoop-200-2:35087, which currently has 3 containers, <memory:5120, vCores:3> used and <memory:3072, vCores:13> available
2013-08-07 07:16:07,825 INFO org.apache.hadoop.yarn.server.resourcemanager.scheduler.capacity.LeafQueue: assignedContainer application=application_1375859105306_0006 container=Container: [ContainerId: container_1375859105306_0006_01_000002, NodeId: hadoop-200-2:35087, NodeHttpAddress: hadoop-200-2:8042, Resource: <memory:1024, vCores:1>, Priority: 20, State: NEW, Token: null, Status: container_id {, app_attempt_id {, application_id {, id: 6, cluster_timestamp: 1375859105306, }, attemptId: 1, }, id: 2, }, state: C_NEW, ] containerId=container_1375859105306_0006_01_000002 queue=default: capacity=1.0, absoluteCapacity=1.0, usedResources=<memory:10240, vCores:5>usedCapacity=0.20833333, absoluteUsedCapacity=0.20833333, numApps=5, numContainers=5 usedCapacity=0.20833333 absoluteUsedCapacity=0.20833333 used=<memory:10240, vCores:5> cluster=<memory:49152, vCores:96>
2013-08-07 07:16:07,825 INFO org.apache.hadoop.yarn.server.resourcemanager.scheduler.capacity.ParentQueue: Re-sorting queues since queue: root.default stats: default: capacity=1.0, absoluteCapacity=1.0, usedResources=<memory:11264, vCores:6>usedCapacity=0.22916667, absoluteUsedCapacity=0.22916667, numApps=5, numContainers=6
2013-08-07 07:16:07,825 INFO org.apache.hadoop.yarn.server.resourcemanager.scheduler.capacity.ParentQueue: assignedContainer queue=root usedCapacity=0.22916667 absoluteUsedCapacity=0.22916667 used=<memory:11264, vCores:6> cluster=<memory:49152, vCores:96>
2013-08-07 07:16:07,826 INFO org.apache.hadoop.yarn.server.resourcemanager.rmcontainer.RMContainerImpl: container_1375859105306_0006_01_000003 Container Transitioned from NEW to ALLOCATED
2013-08-07 07:16:07,826 INFO org.apache.hadoop.yarn.server.resourcemanager.RMAuditLogger: USER=ubuntu	OPERATION=AM Allocated Container	TARGET=SchedulerApp	RESULT=SUCCESS	APPID=application_1375859105306_0006	CONTAINERID=container_1375859105306_0006_01_000003
2013-08-07 07:16:07,826 INFO org.apache.hadoop.yarn.server.resourcemanager.scheduler.common.fica.FiCaSchedulerNode: Assigned container container_1375859105306_0006_01_000003 of capacity <memory:1024, vCores:1> on host hadoop-200-2:35087, which currently has 4 containers, <memory:6144, vCores:4> used and <memory:2048, vCores:12> available
2013-08-07 07:16:07,827 INFO org.apache.hadoop.yarn.server.resourcemanager.scheduler.capacity.LeafQueue: assignedContainer application=application_1375859105306_0006 container=Container: [ContainerId: container_1375859105306_0006_01_000003, NodeId: hadoop-200-2:35087, NodeHttpAddress: hadoop-200-2:8042, Resource: <memory:1024, vCores:1>, Priority: 20, State: NEW, Token: null, Status: container_id {, app_attempt_id {, application_id {, id: 6, cluster_timestamp: 1375859105306, }, attemptId: 1, }, id: 3, }, state: C_NEW, ] containerId=container_1375859105306_0006_01_000003 queue=default: capacity=1.0, absoluteCapacity=1.0, usedResources=<memory:11264, vCores:6>usedCapacity=0.22916667, absoluteUsedCapacity=0.22916667, numApps=5, numContainers=6 usedCapacity=0.22916667 absoluteUsedCapacity=0.22916667 used=<memory:11264, vCores:6> cluster=<memory:49152, vCores:96>
2013-08-07 07:16:07,827 INFO org.apache.hadoop.yarn.server.resourcemanager.scheduler.capacity.ParentQueue: Re-sorting queues since queue: root.default stats: default: capacity=1.0, absoluteCapacity=1.0, usedResources=<memory:12288, vCores:7>usedCapacity=0.25, absoluteUsedCapacity=0.25, numApps=5, numContainers=7
2013-08-07 07:16:07,828 INFO org.apache.hadoop.yarn.server.resourcemanager.scheduler.capacity.ParentQueue: assignedContainer queue=root usedCapacity=0.25 absoluteUsedCapacity=0.25 used=<memory:12288, vCores:7> cluster=<memory:49152, vCores:96>
2013-08-07 07:16:07,828 INFO org.apache.hadoop.yarn.server.resourcemanager.rmcontainer.RMContainerImpl: container_1375859105306_0006_01_000004 Container Transitioned from NEW to ALLOCATED
2013-08-07 07:16:07,829 INFO org.apache.hadoop.yarn.server.resourcemanager.RMAuditLogger: USER=ubuntu	OPERATION=AM Allocated Container	TARGET=SchedulerApp	RESULT=SUCCESS	APPID=application_1375859105306_0006	CONTAINERID=container_1375859105306_0006_01_000004
2013-08-07 07:16:07,829 INFO org.apache.hadoop.yarn.server.resourcemanager.scheduler.common.fica.FiCaSchedulerNode: Assigned container container_1375859105306_0006_01_000004 of capacity <memory:1024, vCores:1> on host hadoop-200-2:35087, which currently has 5 containers, <memory:7168, vCores:5> used and <memory:1024, vCores:11> available
2013-08-07 07:16:07,830 INFO org.apache.hadoop.yarn.server.resourcemanager.scheduler.capacity.LeafQueue: assignedContainer application=application_1375859105306_0006 container=Container: [ContainerId: container_1375859105306_0006_01_000004, NodeId: hadoop-200-2:35087, NodeHttpAddress: hadoop-200-2:8042, Resource: <memory:1024, vCores:1>, Priority: 20, State: NEW, Token: null, Status: container_id {, app_attempt_id {, application_id {, id: 6, cluster_timestamp: 1375859105306, }, attemptId: 1, }, id: 4, }, state: C_NEW, ] containerId=container_1375859105306_0006_01_000004 queue=default: capacity=1.0, absoluteCapacity=1.0, usedResources=<memory:12288, vCores:7>usedCapacity=0.25, absoluteUsedCapacity=0.25, numApps=5, numContainers=7 usedCapacity=0.25 absoluteUsedCapacity=0.25 used=<memory:12288, vCores:7> cluster=<memory:49152, vCores:96>
2013-08-07 07:16:07,830 INFO org.apache.hadoop.yarn.server.resourcemanager.scheduler.capacity.ParentQueue: Re-sorting queues since queue: root.default stats: default: capacity=1.0, absoluteCapacity=1.0, usedResources=<memory:13312, vCores:8>usedCapacity=0.27083334, absoluteUsedCapacity=0.27083334, numApps=5, numContainers=8
2013-08-07 07:16:07,830 INFO org.apache.hadoop.yarn.server.resourcemanager.scheduler.capacity.ParentQueue: assignedContainer queue=root usedCapacity=0.27083334 absoluteUsedCapacity=0.27083334 used=<memory:13312, vCores:8> cluster=<memory:49152, vCores:96>
2013-08-07 07:16:07,831 INFO org.apache.hadoop.yarn.server.resourcemanager.rmcontainer.RMContainerImpl: container_1375859105306_0006_01_000005 Container Transitioned from NEW to ALLOCATED
2013-08-07 07:16:07,831 INFO org.apache.hadoop.yarn.server.resourcemanager.RMAuditLogger: USER=ubuntu	OPERATION=AM Allocated Container	TARGET=SchedulerApp	RESULT=SUCCESS	APPID=application_1375859105306_0006	CONTAINERID=container_1375859105306_0006_01_000005
2013-08-07 07:16:07,831 INFO org.apache.hadoop.yarn.server.resourcemanager.scheduler.common.fica.FiCaSchedulerNode: Assigned container container_1375859105306_0006_01_000005 of capacity <memory:1024, vCores:1> on host hadoop-200-2:35087, which currently has 6 containers, <memory:8192, vCores:6> used and <memory:0, vCores:10> available
2013-08-07 07:16:07,833 INFO org.apache.hadoop.yarn.server.resourcemanager.scheduler.capacity.LeafQueue: assignedContainer application=application_1375859105306_0006 container=Container: [ContainerId: container_1375859105306_0006_01_000005, NodeId: hadoop-200-2:35087, NodeHttpAddress: hadoop-200-2:8042, Resource: <memory:1024, vCores:1>, Priority: 20, State: NEW, Token: null, Status: container_id {, app_attempt_id {, application_id {, id: 6, cluster_timestamp: 1375859105306, }, attemptId: 1, }, id: 5, }, state: C_NEW, ] containerId=container_1375859105306_0006_01_000005 queue=default: capacity=1.0, absoluteCapacity=1.0, usedResources=<memory:13312, vCores:8>usedCapacity=0.27083334, absoluteUsedCapacity=0.27083334, numApps=5, numContainers=8 usedCapacity=0.27083334 absoluteUsedCapacity=0.27083334 used=<memory:13312, vCores:8> cluster=<memory:49152, vCores:96>
2013-08-07 07:16:07,833 INFO org.apache.hadoop.yarn.server.resourcemanager.scheduler.capacity.ParentQueue: Re-sorting queues since queue: root.default stats: default: capacity=1.0, absoluteCapacity=1.0, usedResources=<memory:14336, vCores:9>usedCapacity=0.29166666, absoluteUsedCapacity=0.29166666, numApps=5, numContainers=9
2013-08-07 07:16:07,833 INFO org.apache.hadoop.yarn.server.resourcemanager.scheduler.capacity.ParentQueue: assignedContainer queue=root usedCapacity=0.29166666 absoluteUsedCapacity=0.29166666 used=<memory:14336, vCores:9> cluster=<memory:49152, vCores:96>
2013-08-07 07:16:08,147 INFO org.apache.hadoop.yarn.server.resourcemanager.rmcontainer.RMContainerImpl: container_1375859105306_0006_01_000006 Container Transitioned from NEW to ALLOCATED
2013-08-07 07:16:08,147 INFO org.apache.hadoop.yarn.server.resourcemanager.RMAuditLogger: USER=ubuntu	OPERATION=AM Allocated Container	TARGET=SchedulerApp	RESULT=SUCCESS	APPID=application_1375859105306_0006	CONTAINERID=container_1375859105306_0006_01_000006
2013-08-07 07:16:08,148 INFO org.apache.hadoop.yarn.server.resourcemanager.scheduler.common.fica.FiCaSchedulerNode: Assigned container container_1375859105306_0006_01_000006 of capacity <memory:1024, vCores:1> on host hadoop-200-3:55493, which currently has 3 containers, <memory:5120, vCores:3> used and <memory:3072, vCores:13> available
2013-08-07 07:16:08,149 INFO org.apache.hadoop.yarn.server.resourcemanager.scheduler.capacity.LeafQueue: assignedContainer application=application_1375859105306_0006 container=Container: [ContainerId: container_1375859105306_0006_01_000006, NodeId: hadoop-200-3:55493, NodeHttpAddress: hadoop-200-3:8042, Resource: <memory:1024, vCores:1>, Priority: 20, State: NEW, Token: null, Status: container_id {, app_attempt_id {, application_id {, id: 6, cluster_timestamp: 1375859105306, }, attemptId: 1, }, id: 6, }, state: C_NEW, ] containerId=container_1375859105306_0006_01_000006 queue=default: capacity=1.0, absoluteCapacity=1.0, usedResources=<memory:14336, vCores:9>usedCapacity=0.29166666, absoluteUsedCapacity=0.29166666, numApps=5, numContainers=9 usedCapacity=0.29166666 absoluteUsedCapacity=0.29166666 used=<memory:14336, vCores:9> cluster=<memory:49152, vCores:96>
2013-08-07 07:16:08,149 INFO org.apache.hadoop.yarn.server.resourcemanager.scheduler.capacity.ParentQueue: Re-sorting queues since queue: root.default stats: default: capacity=1.0, absoluteCapacity=1.0, usedResources=<memory:15360, vCores:10>usedCapacity=0.3125, absoluteUsedCapacity=0.3125, numApps=5, numContainers=10
2013-08-07 07:16:08,149 INFO org.apache.hadoop.yarn.server.resourcemanager.scheduler.capacity.ParentQueue: assignedContainer queue=root usedCapacity=0.3125 absoluteUsedCapacity=0.3125 used=<memory:15360, vCores:10> cluster=<memory:49152, vCores:96>
2013-08-07 07:16:08,150 INFO org.apache.hadoop.yarn.server.resourcemanager.rmcontainer.RMContainerImpl: container_1375859105306_0006_01_000007 Container Transitioned from NEW to ALLOCATED
2013-08-07 07:16:08,150 INFO org.apache.hadoop.yarn.server.resourcemanager.RMAuditLogger: USER=ubuntu	OPERATION=AM Allocated Container	TARGET=SchedulerApp	RESULT=SUCCESS	APPID=application_1375859105306_0006	CONTAINERID=container_1375859105306_0006_01_000007
2013-08-07 07:16:08,150 INFO org.apache.hadoop.yarn.server.resourcemanager.scheduler.common.fica.FiCaSchedulerNode: Assigned container container_1375859105306_0006_01_000007 of capacity <memory:1024, vCores:1> on host hadoop-200-3:55493, which currently has 4 containers, <memory:6144, vCores:4> used and <memory:2048, vCores:12> available
2013-08-07 07:16:08,152 INFO org.apache.hadoop.yarn.server.resourcemanager.scheduler.capacity.LeafQueue: assignedContainer application=application_1375859105306_0006 container=Container: [ContainerId: container_1375859105306_0006_01_000007, NodeId: hadoop-200-3:55493, NodeHttpAddress: hadoop-200-3:8042, Resource: <memory:1024, vCores:1>, Priority: 20, State: NEW, Token: null, Status: container_id {, app_attempt_id {, application_id {, id: 6, cluster_timestamp: 1375859105306, }, attemptId: 1, }, id: 7, }, state: C_NEW, ] containerId=container_1375859105306_0006_01_000007 queue=default: capacity=1.0, absoluteCapacity=1.0, usedResources=<memory:15360, vCores:10>usedCapacity=0.3125, absoluteUsedCapacity=0.3125, numApps=5, numContainers=10 usedCapacity=0.3125 absoluteUsedCapacity=0.3125 used=<memory:15360, vCores:10> cluster=<memory:49152, vCores:96>
2013-08-07 07:16:08,152 INFO org.apache.hadoop.yarn.server.resourcemanager.scheduler.capacity.ParentQueue: Re-sorting queues since queue: root.default stats: default: capacity=1.0, absoluteCapacity=1.0, usedResources=<memory:16384, vCores:11>usedCapacity=0.33333334, absoluteUsedCapacity=0.33333334, numApps=5, numContainers=11
2013-08-07 07:16:08,152 INFO org.apache.hadoop.yarn.server.resourcemanager.scheduler.capacity.ParentQueue: assignedContainer queue=root usedCapacity=0.33333334 absoluteUsedCapacity=0.33333334 used=<memory:16384, vCores:11> cluster=<memory:49152, vCores:96>
2013-08-07 07:16:08,153 INFO org.apache.hadoop.yarn.server.resourcemanager.rmcontainer.RMContainerImpl: container_1375859105306_0006_01_000008 Container Transitioned from NEW to ALLOCATED
2013-08-07 07:16:08,153 INFO org.apache.hadoop.yarn.server.resourcemanager.RMAuditLogger: USER=ubuntu	OPERATION=AM Allocated Container	TARGET=SchedulerApp	RESULT=SUCCESS	APPID=application_1375859105306_0006	CONTAINERID=container_1375859105306_0006_01_000008
2013-08-07 07:16:08,153 INFO org.apache.hadoop.yarn.server.resourcemanager.scheduler.common.fica.FiCaSchedulerNode: Assigned container container_1375859105306_0006_01_000008 of capacity <memory:1024, vCores:1> on host hadoop-200-3:55493, which currently has 5 containers, <memory:7168, vCores:5> used and <memory:1024, vCores:11> available
2013-08-07 07:16:08,154 INFO org.apache.hadoop.yarn.server.resourcemanager.scheduler.capacity.LeafQueue: assignedContainer application=application_1375859105306_0006 container=Container: [ContainerId: container_1375859105306_0006_01_000008, NodeId: hadoop-200-3:55493, NodeHttpAddress: hadoop-200-3:8042, Resource: <memory:1024, vCores:1>, Priority: 20, State: NEW, Token: null, Status: container_id {, app_attempt_id {, application_id {, id: 6, cluster_timestamp: 1375859105306, }, attemptId: 1, }, id: 8, }, state: C_NEW, ] containerId=container_1375859105306_0006_01_000008 queue=default: capacity=1.0, absoluteCapacity=1.0, usedResources=<memory:16384, vCores:11>usedCapacity=0.33333334, absoluteUsedCapacity=0.33333334, numApps=5, numContainers=11 usedCapacity=0.33333334 absoluteUsedCapacity=0.33333334 used=<memory:16384, vCores:11> cluster=<memory:49152, vCores:96>
2013-08-07 07:16:08,154 INFO org.apache.hadoop.yarn.server.resourcemanager.scheduler.capacity.ParentQueue: Re-sorting queues since queue: root.default stats: default: capacity=1.0, absoluteCapacity=1.0, usedResources=<memory:17408, vCores:12>usedCapacity=0.35416666, absoluteUsedCapacity=0.35416666, numApps=5, numContainers=12
2013-08-07 07:16:08,155 INFO org.apache.hadoop.yarn.server.resourcemanager.scheduler.capacity.ParentQueue: assignedContainer queue=root usedCapacity=0.35416666 absoluteUsedCapacity=0.35416666 used=<memory:17408, vCores:12> cluster=<memory:49152, vCores:96>
2013-08-07 07:16:08,155 INFO org.apache.hadoop.yarn.server.resourcemanager.rmcontainer.RMContainerImpl: container_1375859105306_0006_01_000009 Container Transitioned from NEW to ALLOCATED
2013-08-07 07:16:08,155 INFO org.apache.hadoop.yarn.server.resourcemanager.RMAuditLogger: USER=ubuntu	OPERATION=AM Allocated Container	TARGET=SchedulerApp	RESULT=SUCCESS	APPID=application_1375859105306_0006	CONTAINERID=container_1375859105306_0006_01_000009
2013-08-07 07:16:08,155 INFO org.apache.hadoop.yarn.server.resourcemanager.scheduler.common.fica.FiCaSchedulerNode: Assigned container container_1375859105306_0006_01_000009 of capacity <memory:1024, vCores:1> on host hadoop-200-3:55493, which currently has 6 containers, <memory:8192, vCores:6> used and <memory:0, vCores:10> available
2013-08-07 07:16:08,156 INFO org.apache.hadoop.yarn.server.resourcemanager.scheduler.capacity.LeafQueue: assignedContainer application=application_1375859105306_0006 container=Container: [ContainerId: container_1375859105306_0006_01_000009, NodeId: hadoop-200-3:55493, NodeHttpAddress: hadoop-200-3:8042, Resource: <memory:1024, vCores:1>, Priority: 20, State: NEW, Token: null, Status: container_id {, app_attempt_id {, application_id {, id: 6, cluster_timestamp: 1375859105306, }, attemptId: 1, }, id: 9, }, state: C_NEW, ] containerId=container_1375859105306_0006_01_000009 queue=default: capacity=1.0, absoluteCapacity=1.0, usedResources=<memory:17408, vCores:12>usedCapacity=0.35416666, absoluteUsedCapacity=0.35416666, numApps=5, numContainers=12 usedCapacity=0.35416666 absoluteUsedCapacity=0.35416666 used=<memory:17408, vCores:12> cluster=<memory:49152, vCores:96>
2013-08-07 07:16:08,157 INFO org.apache.hadoop.yarn.server.resourcemanager.scheduler.capacity.ParentQueue: Re-sorting queues since queue: root.default stats: default: capacity=1.0, absoluteCapacity=1.0, usedResources=<memory:18432, vCores:13>usedCapacity=0.375, absoluteUsedCapacity=0.375, numApps=5, numContainers=13
2013-08-07 07:16:08,157 INFO org.apache.hadoop.yarn.server.resourcemanager.scheduler.capacity.ParentQueue: assignedContainer queue=root usedCapacity=0.375 absoluteUsedCapacity=0.375 used=<memory:18432, vCores:13> cluster=<memory:49152, vCores:96>
2013-08-07 07:16:08,347 INFO org.apache.hadoop.yarn.server.resourcemanager.rmcontainer.RMContainerImpl: container_1375859105306_0006_01_000010 Container Transitioned from NEW to ALLOCATED
2013-08-07 07:16:08,348 INFO org.apache.hadoop.yarn.server.resourcemanager.RMAuditLogger: USER=ubuntu	OPERATION=AM Allocated Container	TARGET=SchedulerApp	RESULT=SUCCESS	APPID=application_1375859105306_0006	CONTAINERID=container_1375859105306_0006_01_000010
2013-08-07 07:16:08,348 INFO org.apache.hadoop.yarn.server.resourcemanager.scheduler.common.fica.FiCaSchedulerNode: Assigned container container_1375859105306_0006_01_000010 of capacity <memory:1024, vCores:1> on host hadoop-200-4:41828, which currently has 2 containers, <memory:3072, vCores:2> used and <memory:5120, vCores:14> available
2013-08-07 07:16:08,349 INFO org.apache.hadoop.yarn.server.resourcemanager.scheduler.capacity.LeafQueue: assignedContainer application=application_1375859105306_0006 container=Container: [ContainerId: container_1375859105306_0006_01_000010, NodeId: hadoop-200-4:41828, NodeHttpAddress: hadoop-200-4:8042, Resource: <memory:1024, vCores:1>, Priority: 20, State: NEW, Token: null, Status: container_id {, app_attempt_id {, application_id {, id: 6, cluster_timestamp: 1375859105306, }, attemptId: 1, }, id: 10, }, state: C_NEW, ] containerId=container_1375859105306_0006_01_000010 queue=default: capacity=1.0, absoluteCapacity=1.0, usedResources=<memory:18432, vCores:13>usedCapacity=0.375, absoluteUsedCapacity=0.375, numApps=5, numContainers=13 usedCapacity=0.375 absoluteUsedCapacity=0.375 used=<memory:18432, vCores:13> cluster=<memory:49152, vCores:96>
2013-08-07 07:16:08,349 INFO org.apache.hadoop.yarn.server.resourcemanager.scheduler.capacity.ParentQueue: Re-sorting queues since queue: root.default stats: default: capacity=1.0, absoluteCapacity=1.0, usedResources=<memory:19456, vCores:14>usedCapacity=0.39583334, absoluteUsedCapacity=0.39583334, numApps=5, numContainers=14
2013-08-07 07:16:08,350 INFO org.apache.hadoop.yarn.server.resourcemanager.scheduler.capacity.ParentQueue: assignedContainer queue=root usedCapacity=0.39583334 absoluteUsedCapacity=0.39583334 used=<memory:19456, vCores:14> cluster=<memory:49152, vCores:96>
2013-08-07 07:16:08,350 INFO org.apache.hadoop.yarn.server.resourcemanager.rmcontainer.RMContainerImpl: container_1375859105306_0006_01_000011 Container Transitioned from NEW to ALLOCATED
2013-08-07 07:16:08,350 INFO org.apache.hadoop.yarn.server.resourcemanager.RMAuditLogger: USER=ubuntu	OPERATION=AM Allocated Container	TARGET=SchedulerApp	RESULT=SUCCESS	APPID=application_1375859105306_0006	CONTAINERID=container_1375859105306_0006_01_000011
2013-08-07 07:16:08,350 INFO org.apache.hadoop.yarn.server.resourcemanager.scheduler.common.fica.FiCaSchedulerNode: Assigned container container_1375859105306_0006_01_000011 of capacity <memory:1024, vCores:1> on host hadoop-200-4:41828, which currently has 3 containers, <memory:4096, vCores:3> used and <memory:4096, vCores:13> available
2013-08-07 07:16:08,351 INFO org.apache.hadoop.yarn.server.resourcemanager.scheduler.capacity.LeafQueue: assignedContainer application=application_1375859105306_0006 container=Container: [ContainerId: container_1375859105306_0006_01_000011, NodeId: hadoop-200-4:41828, NodeHttpAddress: hadoop-200-4:8042, Resource: <memory:1024, vCores:1>, Priority: 20, State: NEW, Token: null, Status: container_id {, app_attempt_id {, application_id {, id: 6, cluster_timestamp: 1375859105306, }, attemptId: 1, }, id: 11, }, state: C_NEW, ] containerId=container_1375859105306_0006_01_000011 queue=default: capacity=1.0, absoluteCapacity=1.0, usedResources=<memory:19456, vCores:14>usedCapacity=0.39583334, absoluteUsedCapacity=0.39583334, numApps=5, numContainers=14 usedCapacity=0.39583334 absoluteUsedCapacity=0.39583334 used=<memory:19456, vCores:14> cluster=<memory:49152, vCores:96>
2013-08-07 07:16:08,351 INFO org.apache.hadoop.yarn.server.resourcemanager.scheduler.capacity.ParentQueue: Re-sorting queues since queue: root.default stats: default: capacity=1.0, absoluteCapacity=1.0, usedResources=<memory:20480, vCores:15>usedCapacity=0.41666666, absoluteUsedCapacity=0.41666666, numApps=5, numContainers=15
2013-08-07 07:16:08,352 INFO org.apache.hadoop.yarn.server.resourcemanager.scheduler.capacity.ParentQueue: assignedContainer queue=root usedCapacity=0.41666666 absoluteUsedCapacity=0.41666666 used=<memory:20480, vCores:15> cluster=<memory:49152, vCores:96>
2013-08-07 07:16:08,352 INFO org.apache.hadoop.yarn.server.resourcemanager.rmcontainer.RMContainerImpl: container_1375859105306_0006_01_000012 Container Transitioned from NEW to ALLOCATED
2013-08-07 07:16:08,352 INFO org.apache.hadoop.yarn.server.resourcemanager.RMAuditLogger: USER=ubuntu	OPERATION=AM Allocated Container	TARGET=SchedulerApp	RESULT=SUCCESS	APPID=application_1375859105306_0006	CONTAINERID=container_1375859105306_0006_01_000012
2013-08-07 07:16:08,352 INFO org.apache.hadoop.yarn.server.resourcemanager.scheduler.common.fica.FiCaSchedulerNode: Assigned container container_1375859105306_0006_01_000012 of capacity <memory:1024, vCores:1> on host hadoop-200-4:41828, which currently has 4 containers, <memory:5120, vCores:4> used and <memory:3072, vCores:12> available
2013-08-07 07:16:08,353 INFO org.apache.hadoop.yarn.server.resourcemanager.scheduler.capacity.LeafQueue: assignedContainer application=application_1375859105306_0006 container=Container: [ContainerId: container_1375859105306_0006_01_000012, NodeId: hadoop-200-4:41828, NodeHttpAddress: hadoop-200-4:8042, Resource: <memory:1024, vCores:1>, Priority: 20, State: NEW, Token: null, Status: container_id {, app_attempt_id {, application_id {, id: 6, cluster_timestamp: 1375859105306, }, attemptId: 1, }, id: 12, }, state: C_NEW, ] containerId=container_1375859105306_0006_01_000012 queue=default: capacity=1.0, absoluteCapacity=1.0, usedResources=<memory:20480, vCores:15>usedCapacity=0.41666666, absoluteUsedCapacity=0.41666666, numApps=5, numContainers=15 usedCapacity=0.41666666 absoluteUsedCapacity=0.41666666 used=<memory:20480, vCores:15> cluster=<memory:49152, vCores:96>
2013-08-07 07:16:08,354 INFO org.apache.hadoop.yarn.server.resourcemanager.scheduler.capacity.ParentQueue: Re-sorting queues since queue: root.default stats: default: capacity=1.0, absoluteCapacity=1.0, usedResources=<memory:21504, vCores:16>usedCapacity=0.4375, absoluteUsedCapacity=0.4375, numApps=5, numContainers=16
2013-08-07 07:16:08,354 INFO org.apache.hadoop.yarn.server.resourcemanager.scheduler.capacity.ParentQueue: assignedContainer queue=root usedCapacity=0.4375 absoluteUsedCapacity=0.4375 used=<memory:21504, vCores:16> cluster=<memory:49152, vCores:96>
2013-08-07 07:16:08,354 INFO org.apache.hadoop.yarn.server.resourcemanager.rmcontainer.RMContainerImpl: container_1375859105306_0006_01_000013 Container Transitioned from NEW to ALLOCATED
2013-08-07 07:16:08,354 INFO org.apache.hadoop.yarn.server.resourcemanager.RMAuditLogger: USER=ubuntu	OPERATION=AM Allocated Container	TARGET=SchedulerApp	RESULT=SUCCESS	APPID=application_1375859105306_0006	CONTAINERID=container_1375859105306_0006_01_000013
2013-08-07 07:16:08,355 INFO org.apache.hadoop.yarn.server.resourcemanager.scheduler.common.fica.FiCaSchedulerNode: Assigned container container_1375859105306_0006_01_000013 of capacity <memory:1024, vCores:1> on host hadoop-200-4:41828, which currently has 5 containers, <memory:6144, vCores:5> used and <memory:2048, vCores:11> available
2013-08-07 07:16:08,355 INFO org.apache.hadoop.yarn.server.resourcemanager.scheduler.capacity.LeafQueue: assignedContainer application=application_1375859105306_0006 container=Container: [ContainerId: container_1375859105306_0006_01_000013, NodeId: hadoop-200-4:41828, NodeHttpAddress: hadoop-200-4:8042, Resource: <memory:1024, vCores:1>, Priority: 20, State: NEW, Token: null, Status: container_id {, app_attempt_id {, application_id {, id: 6, cluster_timestamp: 1375859105306, }, attemptId: 1, }, id: 13, }, state: C_NEW, ] containerId=container_1375859105306_0006_01_000013 queue=default: capacity=1.0, absoluteCapacity=1.0, usedResources=<memory:21504, vCores:16>usedCapacity=0.4375, absoluteUsedCapacity=0.4375, numApps=5, numContainers=16 usedCapacity=0.4375 absoluteUsedCapacity=0.4375 used=<memory:21504, vCores:16> cluster=<memory:49152, vCores:96>
2013-08-07 07:16:08,356 INFO org.apache.hadoop.yarn.server.resourcemanager.scheduler.capacity.ParentQueue: Re-sorting queues since queue: root.default stats: default: capacity=1.0, absoluteCapacity=1.0, usedResources=<memory:22528, vCores:17>usedCapacity=0.45833334, absoluteUsedCapacity=0.45833334, numApps=5, numContainers=17
2013-08-07 07:16:08,356 INFO org.apache.hadoop.yarn.server.resourcemanager.scheduler.capacity.ParentQueue: assignedContainer queue=root usedCapacity=0.45833334 absoluteUsedCapacity=0.45833334 used=<memory:22528, vCores:17> cluster=<memory:49152, vCores:96>
2013-08-07 07:16:08,356 INFO org.apache.hadoop.yarn.server.resourcemanager.rmcontainer.RMContainerImpl: container_1375859105306_0006_01_000014 Container Transitioned from NEW to ALLOCATED
2013-08-07 07:16:08,357 INFO org.apache.hadoop.yarn.server.resourcemanager.RMAuditLogger: USER=ubuntu	OPERATION=AM Allocated Container	TARGET=SchedulerApp	RESULT=SUCCESS	APPID=application_1375859105306_0006	CONTAINERID=container_1375859105306_0006_01_000014
2013-08-07 07:16:08,357 INFO org.apache.hadoop.yarn.server.resourcemanager.scheduler.common.fica.FiCaSchedulerNode: Assigned container container_1375859105306_0006_01_000014 of capacity <memory:1024, vCores:1> on host hadoop-200-4:41828, which currently has 6 containers, <memory:7168, vCores:6> used and <memory:1024, vCores:10> available
2013-08-07 07:16:08,358 INFO org.apache.hadoop.yarn.server.resourcemanager.scheduler.capacity.LeafQueue: assignedContainer application=application_1375859105306_0006 container=Container: [ContainerId: container_1375859105306_0006_01_000014, NodeId: hadoop-200-4:41828, NodeHttpAddress: hadoop-200-4:8042, Resource: <memory:1024, vCores:1>, Priority: 20, State: NEW, Token: null, Status: container_id {, app_attempt_id {, application_id {, id: 6, cluster_timestamp: 1375859105306, }, attemptId: 1, }, id: 14, }, state: C_NEW, ] containerId=container_1375859105306_0006_01_000014 queue=default: capacity=1.0, absoluteCapacity=1.0, usedResources=<memory:22528, vCores:17>usedCapacity=0.45833334, absoluteUsedCapacity=0.45833334, numApps=5, numContainers=17 usedCapacity=0.45833334 absoluteUsedCapacity=0.45833334 used=<memory:22528, vCores:17> cluster=<memory:49152, vCores:96>
2013-08-07 07:16:08,358 INFO org.apache.hadoop.yarn.server.resourcemanager.scheduler.capacity.ParentQueue: Re-sorting queues since queue: root.default stats: default: capacity=1.0, absoluteCapacity=1.0, usedResources=<memory:23552, vCores:18>usedCapacity=0.47916666, absoluteUsedCapacity=0.47916666, numApps=5, numContainers=18
2013-08-07 07:16:08,358 INFO org.apache.hadoop.yarn.server.resourcemanager.scheduler.capacity.ParentQueue: assignedContainer queue=root usedCapacity=0.47916666 absoluteUsedCapacity=0.47916666 used=<memory:23552, vCores:18> cluster=<memory:49152, vCores:96>
2013-08-07 07:16:08,359 INFO org.apache.hadoop.yarn.server.resourcemanager.rmcontainer.RMContainerImpl: container_1375859105306_0006_01_000015 Container Transitioned from NEW to ALLOCATED
2013-08-07 07:16:08,359 INFO org.apache.hadoop.yarn.server.resourcemanager.RMAuditLogger: USER=ubuntu	OPERATION=AM Allocated Container	TARGET=SchedulerApp	RESULT=SUCCESS	APPID=application_1375859105306_0006	CONTAINERID=container_1375859105306_0006_01_000015
2013-08-07 07:16:08,359 INFO org.apache.hadoop.yarn.server.resourcemanager.scheduler.common.fica.FiCaSchedulerNode: Assigned container container_1375859105306_0006_01_000015 of capacity <memory:1024, vCores:1> on host hadoop-200-4:41828, which currently has 7 containers, <memory:8192, vCores:7> used and <memory:0, vCores:9> available
2013-08-07 07:16:08,360 INFO org.apache.hadoop.yarn.server.resourcemanager.scheduler.capacity.LeafQueue: assignedContainer application=application_1375859105306_0006 container=Container: [ContainerId: container_1375859105306_0006_01_000015, NodeId: hadoop-200-4:41828, NodeHttpAddress: hadoop-200-4:8042, Resource: <memory:1024, vCores:1>, Priority: 20, State: NEW, Token: null, Status: container_id {, app_attempt_id {, application_id {, id: 6, cluster_timestamp: 1375859105306, }, attemptId: 1, }, id: 15, }, state: C_NEW, ] containerId=container_1375859105306_0006_01_000015 queue=default: capacity=1.0, absoluteCapacity=1.0, usedResources=<memory:23552, vCores:18>usedCapacity=0.47916666, absoluteUsedCapacity=0.47916666, numApps=5, numContainers=18 usedCapacity=0.47916666 absoluteUsedCapacity=0.47916666 used=<memory:23552, vCores:18> cluster=<memory:49152, vCores:96>
2013-08-07 07:16:08,360 INFO org.apache.hadoop.yarn.server.resourcemanager.scheduler.capacity.ParentQueue: Re-sorting queues since queue: root.default stats: default: capacity=1.0, absoluteCapacity=1.0, usedResources=<memory:24576, vCores:19>usedCapacity=0.5, absoluteUsedCapacity=0.5, numApps=5, numContainers=19
2013-08-07 07:16:08,360 INFO org.apache.hadoop.yarn.server.resourcemanager.scheduler.capacity.ParentQueue: assignedContainer queue=root usedCapacity=0.5 absoluteUsedCapacity=0.5 used=<memory:24576, vCores:19> cluster=<memory:49152, vCores:96>
2013-08-07 07:16:08,361 INFO org.apache.hadoop.yarn.server.resourcemanager.rmcontainer.RMContainerImpl: container_1375859105306_0006_01_000016 Container Transitioned from NEW to ALLOCATED
2013-08-07 07:16:08,361 INFO org.apache.hadoop.yarn.server.resourcemanager.RMAuditLogger: USER=ubuntu	OPERATION=AM Allocated Container	TARGET=SchedulerApp	RESULT=SUCCESS	APPID=application_1375859105306_0006	CONTAINERID=container_1375859105306_0006_01_000016
2013-08-07 07:16:08,361 INFO org.apache.hadoop.yarn.server.resourcemanager.scheduler.common.fica.FiCaSchedulerNode: Assigned container container_1375859105306_0006_01_000016 of capacity <memory:1024, vCores:1> on host hadoop-200-6:34031, which currently has 1 containers, <memory:1024, vCores:1> used and <memory:7168, vCores:15> available
2013-08-07 07:16:08,362 INFO org.apache.hadoop.yarn.server.resourcemanager.scheduler.capacity.LeafQueue: assignedContainer application=application_1375859105306_0006 container=Container: [ContainerId: container_1375859105306_0006_01_000016, NodeId: hadoop-200-6:34031, NodeHttpAddress: hadoop-200-6:8042, Resource: <memory:1024, vCores:1>, Priority: 20, State: NEW, Token: null, Status: container_id {, app_attempt_id {, application_id {, id: 6, cluster_timestamp: 1375859105306, }, attemptId: 1, }, id: 16, }, state: C_NEW, ] containerId=container_1375859105306_0006_01_000016 queue=default: capacity=1.0, absoluteCapacity=1.0, usedResources=<memory:24576, vCores:19>usedCapacity=0.5, absoluteUsedCapacity=0.5, numApps=5, numContainers=19 usedCapacity=0.5 absoluteUsedCapacity=0.5 used=<memory:24576, vCores:19> cluster=<memory:49152, vCores:96>
2013-08-07 07:16:08,362 INFO org.apache.hadoop.yarn.server.resourcemanager.scheduler.capacity.ParentQueue: Re-sorting queues since queue: root.default stats: default: capacity=1.0, absoluteCapacity=1.0, usedResources=<memory:25600, vCores:20>usedCapacity=0.5208333, absoluteUsedCapacity=0.5208333, numApps=5, numContainers=20
2013-08-07 07:16:08,362 INFO org.apache.hadoop.yarn.server.resourcemanager.scheduler.capacity.ParentQueue: assignedContainer queue=root usedCapacity=0.5208333 absoluteUsedCapacity=0.5208333 used=<memory:25600, vCores:20> cluster=<memory:49152, vCores:96>
2013-08-07 07:16:08,363 INFO org.apache.hadoop.yarn.server.resourcemanager.rmcontainer.RMContainerImpl: container_1375859105306_0006_01_000017 Container Transitioned from NEW to ALLOCATED
2013-08-07 07:16:08,363 INFO org.apache.hadoop.yarn.server.resourcemanager.RMAuditLogger: USER=ubuntu	OPERATION=AM Allocated Container	TARGET=SchedulerApp	RESULT=SUCCESS	APPID=application_1375859105306_0006	CONTAINERID=container_1375859105306_0006_01_000017
2013-08-07 07:16:08,363 INFO org.apache.hadoop.yarn.server.resourcemanager.scheduler.common.fica.FiCaSchedulerNode: Assigned container container_1375859105306_0006_01_000017 of capacity <memory:1024, vCores:1> on host hadoop-200-6:34031, which currently has 2 containers, <memory:2048, vCores:2> used and <memory:6144, vCores:14> available
2013-08-07 07:16:08,364 INFO org.apache.hadoop.yarn.server.resourcemanager.scheduler.capacity.LeafQueue: assignedContainer application=application_1375859105306_0006 container=Container: [ContainerId: container_1375859105306_0006_01_000017, NodeId: hadoop-200-6:34031, NodeHttpAddress: hadoop-200-6:8042, Resource: <memory:1024, vCores:1>, Priority: 20, State: NEW, Token: null, Status: container_id {, app_attempt_id {, application_id {, id: 6, cluster_timestamp: 1375859105306, }, attemptId: 1, }, id: 17, }, state: C_NEW, ] containerId=container_1375859105306_0006_01_000017 queue=default: capacity=1.0, absoluteCapacity=1.0, usedResources=<memory:25600, vCores:20>usedCapacity=0.5208333, absoluteUsedCapacity=0.5208333, numApps=5, numContainers=20 usedCapacity=0.5208333 absoluteUsedCapacity=0.5208333 used=<memory:25600, vCores:20> cluster=<memory:49152, vCores:96>
2013-08-07 07:16:08,364 INFO org.apache.hadoop.yarn.server.resourcemanager.scheduler.capacity.ParentQueue: Re-sorting queues since queue: root.default stats: default: capacity=1.0, absoluteCapacity=1.0, usedResources=<memory:26624, vCores:21>usedCapacity=0.5416667, absoluteUsedCapacity=0.5416667, numApps=5, numContainers=21
2013-08-07 07:16:08,364 INFO org.apache.hadoop.yarn.server.resourcemanager.scheduler.capacity.ParentQueue: assignedContainer queue=root usedCapacity=0.5416667 absoluteUsedCapacity=0.5416667 used=<memory:26624, vCores:21> cluster=<memory:49152, vCores:96>
2013-08-07 07:16:08,365 INFO org.apache.hadoop.yarn.server.resourcemanager.rmcontainer.RMContainerImpl: container_1375859105306_0006_01_000018 Container Transitioned from NEW to ALLOCATED
2013-08-07 07:16:08,365 INFO org.apache.hadoop.yarn.server.resourcemanager.RMAuditLogger: USER=ubuntu	OPERATION=AM Allocated Container	TARGET=SchedulerApp	RESULT=SUCCESS	APPID=application_1375859105306_0006	CONTAINERID=container_1375859105306_0006_01_000018
2013-08-07 07:16:08,365 INFO org.apache.hadoop.yarn.server.resourcemanager.scheduler.common.fica.FiCaSchedulerNode: Assigned container container_1375859105306_0006_01_000018 of capacity <memory:1024, vCores:1> on host hadoop-200-6:34031, which currently has 3 containers, <memory:3072, vCores:3> used and <memory:5120, vCores:13> available
2013-08-07 07:16:08,366 INFO org.apache.hadoop.yarn.server.resourcemanager.scheduler.capacity.LeafQueue: assignedContainer application=application_1375859105306_0006 container=Container: [ContainerId: container_1375859105306_0006_01_000018, NodeId: hadoop-200-6:34031, NodeHttpAddress: hadoop-200-6:8042, Resource: <memory:1024, vCores:1>, Priority: 20, State: NEW, Token: null, Status: container_id {, app_attempt_id {, application_id {, id: 6, cluster_timestamp: 1375859105306, }, attemptId: 1, }, id: 18, }, state: C_NEW, ] containerId=container_1375859105306_0006_01_000018 queue=default: capacity=1.0, absoluteCapacity=1.0, usedResources=<memory:26624, vCores:21>usedCapacity=0.5416667, absoluteUsedCapacity=0.5416667, numApps=5, numContainers=21 usedCapacity=0.5416667 absoluteUsedCapacity=0.5416667 used=<memory:26624, vCores:21> cluster=<memory:49152, vCores:96>
2013-08-07 07:16:08,366 INFO org.apache.hadoop.yarn.server.resourcemanager.scheduler.capacity.ParentQueue: Re-sorting queues since queue: root.default stats: default: capacity=1.0, absoluteCapacity=1.0, usedResources=<memory:27648, vCores:22>usedCapacity=0.5625, absoluteUsedCapacity=0.5625, numApps=5, numContainers=22
2013-08-07 07:16:08,367 INFO org.apache.hadoop.yarn.server.resourcemanager.scheduler.capacity.ParentQueue: assignedContainer queue=root usedCapacity=0.5625 absoluteUsedCapacity=0.5625 used=<memory:27648, vCores:22> cluster=<memory:49152, vCores:96>
2013-08-07 07:16:08,367 INFO org.apache.hadoop.yarn.server.resourcemanager.rmcontainer.RMContainerImpl: container_1375859105306_0006_01_000019 Container Transitioned from NEW to ALLOCATED
2013-08-07 07:16:08,367 INFO org.apache.hadoop.yarn.server.resourcemanager.RMAuditLogger: USER=ubuntu	OPERATION=AM Allocated Container	TARGET=SchedulerApp	RESULT=SUCCESS	APPID=application_1375859105306_0006	CONTAINERID=container_1375859105306_0006_01_000019
2013-08-07 07:16:08,367 INFO org.apache.hadoop.yarn.server.resourcemanager.scheduler.common.fica.FiCaSchedulerNode: Assigned container container_1375859105306_0006_01_000019 of capacity <memory:1024, vCores:1> on host hadoop-200-6:34031, which currently has 4 containers, <memory:4096, vCores:4> used and <memory:4096, vCores:12> available
2013-08-07 07:16:08,368 INFO org.apache.hadoop.yarn.server.resourcemanager.scheduler.capacity.LeafQueue: assignedContainer application=application_1375859105306_0006 container=Container: [ContainerId: container_1375859105306_0006_01_000019, NodeId: hadoop-200-6:34031, NodeHttpAddress: hadoop-200-6:8042, Resource: <memory:1024, vCores:1>, Priority: 20, State: NEW, Token: null, Status: container_id {, app_attempt_id {, application_id {, id: 6, cluster_timestamp: 1375859105306, }, attemptId: 1, }, id: 19, }, state: C_NEW, ] containerId=container_1375859105306_0006_01_000019 queue=default: capacity=1.0, absoluteCapacity=1.0, usedResources=<memory:27648, vCores:22>usedCapacity=0.5625, absoluteUsedCapacity=0.5625, numApps=5, numContainers=22 usedCapacity=0.5625 absoluteUsedCapacity=0.5625 used=<memory:27648, vCores:22> cluster=<memory:49152, vCores:96>
2013-08-07 07:16:08,369 INFO org.apache.hadoop.yarn.server.resourcemanager.scheduler.capacity.ParentQueue: Re-sorting queues since queue: root.default stats: default: capacity=1.0, absoluteCapacity=1.0, usedResources=<memory:28672, vCores:23>usedCapacity=0.5833333, absoluteUsedCapacity=0.5833333, numApps=5, numContainers=23
2013-08-07 07:16:08,369 INFO org.apache.hadoop.yarn.server.resourcemanager.scheduler.capacity.ParentQueue: assignedContainer queue=root usedCapacity=0.5833333 absoluteUsedCapacity=0.5833333 used=<memory:28672, vCores:23> cluster=<memory:49152, vCores:96>
2013-08-07 07:16:08,369 INFO org.apache.hadoop.yarn.server.resourcemanager.rmcontainer.RMContainerImpl: container_1375859105306_0006_01_000020 Container Transitioned from NEW to ALLOCATED
2013-08-07 07:16:08,369 INFO org.apache.hadoop.yarn.server.resourcemanager.RMAuditLogger: USER=ubuntu	OPERATION=AM Allocated Container	TARGET=SchedulerApp	RESULT=SUCCESS	APPID=application_1375859105306_0006	CONTAINERID=container_1375859105306_0006_01_000020
2013-08-07 07:16:08,370 INFO org.apache.hadoop.yarn.server.resourcemanager.scheduler.common.fica.FiCaSchedulerNode: Assigned container container_1375859105306_0006_01_000020 of capacity <memory:1024, vCores:1> on host hadoop-200-6:34031, which currently has 5 containers, <memory:5120, vCores:5> used and <memory:3072, vCores:11> available
2013-08-07 07:16:08,370 INFO org.apache.hadoop.yarn.server.resourcemanager.scheduler.capacity.LeafQueue: assignedContainer application=application_1375859105306_0006 container=Container: [ContainerId: container_1375859105306_0006_01_000020, NodeId: hadoop-200-6:34031, NodeHttpAddress: hadoop-200-6:8042, Resource: <memory:1024, vCores:1>, Priority: 20, State: NEW, Token: null, Status: container_id {, app_attempt_id {, application_id {, id: 6, cluster_timestamp: 1375859105306, }, attemptId: 1, }, id: 20, }, state: C_NEW, ] containerId=container_1375859105306_0006_01_000020 queue=default: capacity=1.0, absoluteCapacity=1.0, usedResources=<memory:28672, vCores:23>usedCapacity=0.5833333, absoluteUsedCapacity=0.5833333, numApps=5, numContainers=23 usedCapacity=0.5833333 absoluteUsedCapacity=0.5833333 used=<memory:28672, vCores:23> cluster=<memory:49152, vCores:96>
2013-08-07 07:16:08,371 INFO org.apache.hadoop.yarn.server.resourcemanager.scheduler.capacity.ParentQueue: Re-sorting queues since queue: root.default stats: default: capacity=1.0, absoluteCapacity=1.0, usedResources=<memory:29696, vCores:24>usedCapacity=0.6041667, absoluteUsedCapacity=0.6041667, numApps=5, numContainers=24
2013-08-07 07:16:08,371 INFO org.apache.hadoop.yarn.server.resourcemanager.scheduler.capacity.ParentQueue: assignedContainer queue=root usedCapacity=0.6041667 absoluteUsedCapacity=0.6041667 used=<memory:29696, vCores:24> cluster=<memory:49152, vCores:96>
2013-08-07 07:16:08,371 INFO org.apache.hadoop.yarn.server.resourcemanager.rmcontainer.RMContainerImpl: container_1375859105306_0006_01_000021 Container Transitioned from NEW to ALLOCATED
2013-08-07 07:16:08,372 INFO org.apache.hadoop.yarn.server.resourcemanager.RMAuditLogger: USER=ubuntu	OPERATION=AM Allocated Container	TARGET=SchedulerApp	RESULT=SUCCESS	APPID=application_1375859105306_0006	CONTAINERID=container_1375859105306_0006_01_000021
2013-08-07 07:16:08,372 INFO org.apache.hadoop.yarn.server.resourcemanager.scheduler.common.fica.FiCaSchedulerNode: Assigned container container_1375859105306_0006_01_000021 of capacity <memory:1024, vCores:1> on host hadoop-200-6:34031, which currently has 6 containers, <memory:6144, vCores:6> used and <memory:2048, vCores:10> available
2013-08-07 07:16:08,373 INFO org.apache.hadoop.yarn.server.resourcemanager.scheduler.capacity.LeafQueue: assignedContainer application=application_1375859105306_0006 container=Container: [ContainerId: container_1375859105306_0006_01_000021, NodeId: hadoop-200-6:34031, NodeHttpAddress: hadoop-200-6:8042, Resource: <memory:1024, vCores:1>, Priority: 20, State: NEW, Token: null, Status: container_id {, app_attempt_id {, application_id {, id: 6, cluster_timestamp: 1375859105306, }, attemptId: 1, }, id: 21, }, state: C_NEW, ] containerId=container_1375859105306_0006_01_000021 queue=default: capacity=1.0, absoluteCapacity=1.0, usedResources=<memory:29696, vCores:24>usedCapacity=0.6041667, absoluteUsedCapacity=0.6041667, numApps=5, numContainers=24 usedCapacity=0.6041667 absoluteUsedCapacity=0.6041667 used=<memory:29696, vCores:24> cluster=<memory:49152, vCores:96>
2013-08-07 07:16:08,373 INFO org.apache.hadoop.yarn.server.resourcemanager.scheduler.capacity.ParentQueue: Re-sorting queues since queue: root.default stats: default: capacity=1.0, absoluteCapacity=1.0, usedResources=<memory:30720, vCores:25>usedCapacity=0.625, absoluteUsedCapacity=0.625, numApps=5, numContainers=25
2013-08-07 07:16:08,373 INFO org.apache.hadoop.yarn.server.resourcemanager.scheduler.capacity.ParentQueue: assignedContainer queue=root usedCapacity=0.625 absoluteUsedCapacity=0.625 used=<memory:30720, vCores:25> cluster=<memory:49152, vCores:96>
2013-08-07 07:16:08,374 INFO org.apache.hadoop.yarn.server.resourcemanager.rmcontainer.RMContainerImpl: container_1375859105306_0006_01_000022 Container Transitioned from NEW to ALLOCATED
2013-08-07 07:16:08,374 INFO org.apache.hadoop.yarn.server.resourcemanager.RMAuditLogger: USER=ubuntu	OPERATION=AM Allocated Container	TARGET=SchedulerApp	RESULT=SUCCESS	APPID=application_1375859105306_0006	CONTAINERID=container_1375859105306_0006_01_000022
2013-08-07 07:16:08,374 INFO org.apache.hadoop.yarn.server.resourcemanager.scheduler.common.fica.FiCaSchedulerNode: Assigned container container_1375859105306_0006_01_000022 of capacity <memory:1024, vCores:1> on host hadoop-200-6:34031, which currently has 7 containers, <memory:7168, vCores:7> used and <memory:1024, vCores:9> available
2013-08-07 07:16:08,375 INFO org.apache.hadoop.yarn.server.resourcemanager.scheduler.capacity.LeafQueue: assignedContainer application=application_1375859105306_0006 container=Container: [ContainerId: container_1375859105306_0006_01_000022, NodeId: hadoop-200-6:34031, NodeHttpAddress: hadoop-200-6:8042, Resource: <memory:1024, vCores:1>, Priority: 20, State: NEW, Token: null, Status: container_id {, app_attempt_id {, application_id {, id: 6, cluster_timestamp: 1375859105306, }, attemptId: 1, }, id: 22, }, state: C_NEW, ] containerId=container_1375859105306_0006_01_000022 queue=default: capacity=1.0, absoluteCapacity=1.0, usedResources=<memory:30720, vCores:25>usedCapacity=0.625, absoluteUsedCapacity=0.625, numApps=5, numContainers=25 usedCapacity=0.625 absoluteUsedCapacity=0.625 used=<memory:30720, vCores:25> cluster=<memory:49152, vCores:96>
2013-08-07 07:16:08,375 INFO org.apache.hadoop.yarn.server.resourcemanager.scheduler.capacity.ParentQueue: Re-sorting queues since queue: root.default stats: default: capacity=1.0, absoluteCapacity=1.0, usedResources=<memory:31744, vCores:26>usedCapacity=0.6458333, absoluteUsedCapacity=0.6458333, numApps=5, numContainers=26
2013-08-07 07:16:08,375 INFO org.apache.hadoop.yarn.server.resourcemanager.scheduler.capacity.ParentQueue: assignedContainer queue=root usedCapacity=0.6458333 absoluteUsedCapacity=0.6458333 used=<memory:31744, vCores:26> cluster=<memory:49152, vCores:96>
2013-08-07 07:16:08,376 INFO org.apache.hadoop.yarn.server.resourcemanager.rmcontainer.RMContainerImpl: container_1375859105306_0006_01_000023 Container Transitioned from NEW to ALLOCATED
2013-08-07 07:16:08,376 INFO org.apache.hadoop.yarn.server.resourcemanager.RMAuditLogger: USER=ubuntu	OPERATION=AM Allocated Container	TARGET=SchedulerApp	RESULT=SUCCESS	APPID=application_1375859105306_0006	CONTAINERID=container_1375859105306_0006_01_000023
2013-08-07 07:16:08,376 INFO org.apache.hadoop.yarn.server.resourcemanager.scheduler.common.fica.FiCaSchedulerNode: Assigned container container_1375859105306_0006_01_000023 of capacity <memory:1024, vCores:1> on host hadoop-200-6:34031, which currently has 8 containers, <memory:8192, vCores:8> used and <memory:0, vCores:8> available
2013-08-07 07:16:08,377 INFO org.apache.hadoop.yarn.server.resourcemanager.scheduler.capacity.LeafQueue: assignedContainer application=application_1375859105306_0006 container=Container: [ContainerId: container_1375859105306_0006_01_000023, NodeId: hadoop-200-6:34031, NodeHttpAddress: hadoop-200-6:8042, Resource: <memory:1024, vCores:1>, Priority: 20, State: NEW, Token: null, Status: container_id {, app_attempt_id {, application_id {, id: 6, cluster_timestamp: 1375859105306, }, attemptId: 1, }, id: 23, }, state: C_NEW, ] containerId=container_1375859105306_0006_01_000023 queue=default: capacity=1.0, absoluteCapacity=1.0, usedResources=<memory:31744, vCores:26>usedCapacity=0.6458333, absoluteUsedCapacity=0.6458333, numApps=5, numContainers=26 usedCapacity=0.6458333 absoluteUsedCapacity=0.6458333 used=<memory:31744, vCores:26> cluster=<memory:49152, vCores:96>
2013-08-07 07:16:08,377 INFO org.apache.hadoop.yarn.server.resourcemanager.scheduler.capacity.ParentQueue: Re-sorting queues since queue: root.default stats: default: capacity=1.0, absoluteCapacity=1.0, usedResources=<memory:32768, vCores:27>usedCapacity=0.6666667, absoluteUsedCapacity=0.6666667, numApps=5, numContainers=27
2013-08-07 07:16:08,377 INFO org.apache.hadoop.yarn.server.resourcemanager.scheduler.capacity.ParentQueue: assignedContainer queue=root usedCapacity=0.6666667 absoluteUsedCapacity=0.6666667 used=<memory:32768, vCores:27> cluster=<memory:49152, vCores:96>
2013-08-07 07:16:08,397 INFO org.apache.hadoop.yarn.server.resourcemanager.rmcontainer.RMContainerImpl: container_1375859105306_0006_01_000024 Container Transitioned from NEW to ALLOCATED
2013-08-07 07:16:08,398 INFO org.apache.hadoop.yarn.server.resourcemanager.RMAuditLogger: USER=ubuntu	OPERATION=AM Allocated Container	TARGET=SchedulerApp	RESULT=SUCCESS	APPID=application_1375859105306_0006	CONTAINERID=container_1375859105306_0006_01_000024
2013-08-07 07:16:08,398 INFO org.apache.hadoop.yarn.server.resourcemanager.scheduler.common.fica.FiCaSchedulerNode: Assigned container container_1375859105306_0006_01_000024 of capacity <memory:1024, vCores:1> on host hadoop-200-7:58499, which currently has 1 containers, <memory:1024, vCores:1> used and <memory:7168, vCores:15> available
2013-08-07 07:16:08,399 INFO org.apache.hadoop.yarn.server.resourcemanager.scheduler.capacity.LeafQueue: assignedContainer application=application_1375859105306_0006 container=Container: [ContainerId: container_1375859105306_0006_01_000024, NodeId: hadoop-200-7:58499, NodeHttpAddress: hadoop-200-7:8042, Resource: <memory:1024, vCores:1>, Priority: 20, State: NEW, Token: null, Status: container_id {, app_attempt_id {, application_id {, id: 6, cluster_timestamp: 1375859105306, }, attemptId: 1, }, id: 24, }, state: C_NEW, ] containerId=container_1375859105306_0006_01_000024 queue=default: capacity=1.0, absoluteCapacity=1.0, usedResources=<memory:32768, vCores:27>usedCapacity=0.6666667, absoluteUsedCapacity=0.6666667, numApps=5, numContainers=27 usedCapacity=0.6666667 absoluteUsedCapacity=0.6666667 used=<memory:32768, vCores:27> cluster=<memory:49152, vCores:96>
2013-08-07 07:16:08,399 INFO org.apache.hadoop.yarn.server.resourcemanager.scheduler.capacity.ParentQueue: Re-sorting queues since queue: root.default stats: default: capacity=1.0, absoluteCapacity=1.0, usedResources=<memory:33792, vCores:28>usedCapacity=0.6875, absoluteUsedCapacity=0.6875, numApps=5, numContainers=28
2013-08-07 07:16:08,399 INFO org.apache.hadoop.yarn.server.resourcemanager.scheduler.capacity.ParentQueue: assignedContainer queue=root usedCapacity=0.6875 absoluteUsedCapacity=0.6875 used=<memory:33792, vCores:28> cluster=<memory:49152, vCores:96>
2013-08-07 07:16:08,400 INFO org.apache.hadoop.yarn.server.resourcemanager.rmcontainer.RMContainerImpl: container_1375859105306_0006_01_000025 Container Transitioned from NEW to ALLOCATED
2013-08-07 07:16:08,400 INFO org.apache.hadoop.yarn.server.resourcemanager.RMAuditLogger: USER=ubuntu	OPERATION=AM Allocated Container	TARGET=SchedulerApp	RESULT=SUCCESS	APPID=application_1375859105306_0006	CONTAINERID=container_1375859105306_0006_01_000025
2013-08-07 07:16:08,400 INFO org.apache.hadoop.yarn.server.resourcemanager.scheduler.common.fica.FiCaSchedulerNode: Assigned container container_1375859105306_0006_01_000025 of capacity <memory:1024, vCores:1> on host hadoop-200-7:58499, which currently has 2 containers, <memory:2048, vCores:2> used and <memory:6144, vCores:14> available
2013-08-07 07:16:08,401 INFO org.apache.hadoop.yarn.server.resourcemanager.scheduler.capacity.LeafQueue: assignedContainer application=application_1375859105306_0006 container=Container: [ContainerId: container_1375859105306_0006_01_000025, NodeId: hadoop-200-7:58499, NodeHttpAddress: hadoop-200-7:8042, Resource: <memory:1024, vCores:1>, Priority: 20, State: NEW, Token: null, Status: container_id {, app_attempt_id {, application_id {, id: 6, cluster_timestamp: 1375859105306, }, attemptId: 1, }, id: 25, }, state: C_NEW, ] containerId=container_1375859105306_0006_01_000025 queue=default: capacity=1.0, absoluteCapacity=1.0, usedResources=<memory:33792, vCores:28>usedCapacity=0.6875, absoluteUsedCapacity=0.6875, numApps=5, numContainers=28 usedCapacity=0.6875 absoluteUsedCapacity=0.6875 used=<memory:33792, vCores:28> cluster=<memory:49152, vCores:96>
2013-08-07 07:16:08,401 INFO org.apache.hadoop.yarn.server.resourcemanager.scheduler.capacity.ParentQueue: Re-sorting queues since queue: root.default stats: default: capacity=1.0, absoluteCapacity=1.0, usedResources=<memory:34816, vCores:29>usedCapacity=0.7083333, absoluteUsedCapacity=0.7083333, numApps=5, numContainers=29
2013-08-07 07:16:08,401 INFO org.apache.hadoop.yarn.server.resourcemanager.scheduler.capacity.ParentQueue: assignedContainer queue=root usedCapacity=0.7083333 absoluteUsedCapacity=0.7083333 used=<memory:34816, vCores:29> cluster=<memory:49152, vCores:96>
2013-08-07 07:16:08,402 INFO org.apache.hadoop.yarn.server.resourcemanager.rmcontainer.RMContainerImpl: container_1375859105306_0006_01_000026 Container Transitioned from NEW to ALLOCATED
2013-08-07 07:16:08,402 INFO org.apache.hadoop.yarn.server.resourcemanager.RMAuditLogger: USER=ubuntu	OPERATION=AM Allocated Container	TARGET=SchedulerApp	RESULT=SUCCESS	APPID=application_1375859105306_0006	CONTAINERID=container_1375859105306_0006_01_000026
2013-08-07 07:16:08,402 INFO org.apache.hadoop.yarn.server.resourcemanager.scheduler.common.fica.FiCaSchedulerNode: Assigned container container_1375859105306_0006_01_000026 of capacity <memory:1024, vCores:1> on host hadoop-200-7:58499, which currently has 3 containers, <memory:3072, vCores:3> used and <memory:5120, vCores:13> available
2013-08-07 07:16:08,403 INFO org.apache.hadoop.yarn.server.resourcemanager.scheduler.capacity.LeafQueue: assignedContainer application=application_1375859105306_0006 container=Container: [ContainerId: container_1375859105306_0006_01_000026, NodeId: hadoop-200-7:58499, NodeHttpAddress: hadoop-200-7:8042, Resource: <memory:1024, vCores:1>, Priority: 20, State: NEW, Token: null, Status: container_id {, app_attempt_id {, application_id {, id: 6, cluster_timestamp: 1375859105306, }, attemptId: 1, }, id: 26, }, state: C_NEW, ] containerId=container_1375859105306_0006_01_000026 queue=default: capacity=1.0, absoluteCapacity=1.0, usedResources=<memory:34816, vCores:29>usedCapacity=0.7083333, absoluteUsedCapacity=0.7083333, numApps=5, numContainers=29 usedCapacity=0.7083333 absoluteUsedCapacity=0.7083333 used=<memory:34816, vCores:29> cluster=<memory:49152, vCores:96>
2013-08-07 07:16:08,403 INFO org.apache.hadoop.yarn.server.resourcemanager.scheduler.capacity.ParentQueue: Re-sorting queues since queue: root.default stats: default: capacity=1.0, absoluteCapacity=1.0, usedResources=<memory:35840, vCores:30>usedCapacity=0.7291667, absoluteUsedCapacity=0.7291667, numApps=5, numContainers=30
2013-08-07 07:16:08,404 INFO org.apache.hadoop.yarn.server.resourcemanager.scheduler.capacity.ParentQueue: assignedContainer queue=root usedCapacity=0.7291667 absoluteUsedCapacity=0.7291667 used=<memory:35840, vCores:30> cluster=<memory:49152, vCores:96>
2013-08-07 07:16:08,404 INFO org.apache.hadoop.yarn.server.resourcemanager.rmcontainer.RMContainerImpl: container_1375859105306_0006_01_000027 Container Transitioned from NEW to ALLOCATED
2013-08-07 07:16:08,404 INFO org.apache.hadoop.yarn.server.resourcemanager.RMAuditLogger: USER=ubuntu	OPERATION=AM Allocated Container	TARGET=SchedulerApp	RESULT=SUCCESS	APPID=application_1375859105306_0006	CONTAINERID=container_1375859105306_0006_01_000027
2013-08-07 07:16:08,404 INFO org.apache.hadoop.yarn.server.resourcemanager.scheduler.common.fica.FiCaSchedulerNode: Assigned container container_1375859105306_0006_01_000027 of capacity <memory:1024, vCores:1> on host hadoop-200-7:58499, which currently has 4 containers, <memory:4096, vCores:4> used and <memory:4096, vCores:12> available
2013-08-07 07:16:08,405 INFO org.apache.hadoop.yarn.server.resourcemanager.scheduler.capacity.LeafQueue: assignedContainer application=application_1375859105306_0006 container=Container: [ContainerId: container_1375859105306_0006_01_000027, NodeId: hadoop-200-7:58499, NodeHttpAddress: hadoop-200-7:8042, Resource: <memory:1024, vCores:1>, Priority: 20, State: NEW, Token: null, Status: container_id {, app_attempt_id {, application_id {, id: 6, cluster_timestamp: 1375859105306, }, attemptId: 1, }, id: 27, }, state: C_NEW, ] containerId=container_1375859105306_0006_01_000027 queue=default: capacity=1.0, absoluteCapacity=1.0, usedResources=<memory:35840, vCores:30>usedCapacity=0.7291667, absoluteUsedCapacity=0.7291667, numApps=5, numContainers=30 usedCapacity=0.7291667 absoluteUsedCapacity=0.7291667 used=<memory:35840, vCores:30> cluster=<memory:49152, vCores:96>
2013-08-07 07:16:08,406 INFO org.apache.hadoop.yarn.server.resourcemanager.scheduler.capacity.ParentQueue: Re-sorting queues since queue: root.default stats: default: capacity=1.0, absoluteCapacity=1.0, usedResources=<memory:36864, vCores:31>usedCapacity=0.75, absoluteUsedCapacity=0.75, numApps=5, numContainers=31
2013-08-07 07:16:08,406 INFO org.apache.hadoop.yarn.server.resourcemanager.scheduler.capacity.ParentQueue: assignedContainer queue=root usedCapacity=0.75 absoluteUsedCapacity=0.75 used=<memory:36864, vCores:31> cluster=<memory:49152, vCores:96>
2013-08-07 07:16:08,406 INFO org.apache.hadoop.yarn.server.resourcemanager.rmcontainer.RMContainerImpl: container_1375859105306_0006_01_000028 Container Transitioned from NEW to ALLOCATED
2013-08-07 07:16:08,406 INFO org.apache.hadoop.yarn.server.resourcemanager.RMAuditLogger: USER=ubuntu	OPERATION=AM Allocated Container	TARGET=SchedulerApp	RESULT=SUCCESS	APPID=application_1375859105306_0006	CONTAINERID=container_1375859105306_0006_01_000028
2013-08-07 07:16:08,407 INFO org.apache.hadoop.yarn.server.resourcemanager.scheduler.common.fica.FiCaSchedulerNode: Assigned container container_1375859105306_0006_01_000028 of capacity <memory:1024, vCores:1> on host hadoop-200-7:58499, which currently has 5 containers, <memory:5120, vCores:5> used and <memory:3072, vCores:11> available
2013-08-07 07:16:08,407 INFO org.apache.hadoop.yarn.server.resourcemanager.scheduler.capacity.LeafQueue: assignedContainer application=application_1375859105306_0006 container=Container: [ContainerId: container_1375859105306_0006_01_000028, NodeId: hadoop-200-7:58499, NodeHttpAddress: hadoop-200-7:8042, Resource: <memory:1024, vCores:1>, Priority: 20, State: NEW, Token: null, Status: container_id {, app_attempt_id {, application_id {, id: 6, cluster_timestamp: 1375859105306, }, attemptId: 1, }, id: 28, }, state: C_NEW, ] containerId=container_1375859105306_0006_01_000028 queue=default: capacity=1.0, absoluteCapacity=1.0, usedResources=<memory:36864, vCores:31>usedCapacity=0.75, absoluteUsedCapacity=0.75, numApps=5, numContainers=31 usedCapacity=0.75 absoluteUsedCapacity=0.75 used=<memory:36864, vCores:31> cluster=<memory:49152, vCores:96>
2013-08-07 07:16:08,408 INFO org.apache.hadoop.yarn.server.resourcemanager.scheduler.capacity.ParentQueue: Re-sorting queues since queue: root.default stats: default: capacity=1.0, absoluteCapacity=1.0, usedResources=<memory:37888, vCores:32>usedCapacity=0.7708333, absoluteUsedCapacity=0.7708333, numApps=5, numContainers=32
2013-08-07 07:16:08,408 INFO org.apache.hadoop.yarn.server.resourcemanager.scheduler.capacity.ParentQueue: assignedContainer queue=root usedCapacity=0.7708333 absoluteUsedCapacity=0.7708333 used=<memory:37888, vCores:32> cluster=<memory:49152, vCores:96>
2013-08-07 07:16:08,408 INFO org.apache.hadoop.yarn.server.resourcemanager.rmcontainer.RMContainerImpl: container_1375859105306_0006_01_000029 Container Transitioned from NEW to ALLOCATED
2013-08-07 07:16:08,409 INFO org.apache.hadoop.yarn.server.resourcemanager.RMAuditLogger: USER=ubuntu	OPERATION=AM Allocated Container	TARGET=SchedulerApp	RESULT=SUCCESS	APPID=application_1375859105306_0006	CONTAINERID=container_1375859105306_0006_01_000029
2013-08-07 07:16:08,409 INFO org.apache.hadoop.yarn.server.resourcemanager.scheduler.common.fica.FiCaSchedulerNode: Assigned container container_1375859105306_0006_01_000029 of capacity <memory:1024, vCores:1> on host hadoop-200-7:58499, which currently has 6 containers, <memory:6144, vCores:6> used and <memory:2048, vCores:10> available
2013-08-07 07:16:08,410 INFO org.apache.hadoop.yarn.server.resourcemanager.scheduler.capacity.LeafQueue: assignedContainer application=application_1375859105306_0006 container=Container: [ContainerId: container_1375859105306_0006_01_000029, NodeId: hadoop-200-7:58499, NodeHttpAddress: hadoop-200-7:8042, Resource: <memory:1024, vCores:1>, Priority: 20, State: NEW, Token: null, Status: container_id {, app_attempt_id {, application_id {, id: 6, cluster_timestamp: 1375859105306, }, attemptId: 1, }, id: 29, }, state: C_NEW, ] containerId=container_1375859105306_0006_01_000029 queue=default: capacity=1.0, absoluteCapacity=1.0, usedResources=<memory:37888, vCores:32>usedCapacity=0.7708333, absoluteUsedCapacity=0.7708333, numApps=5, numContainers=32 usedCapacity=0.7708333 absoluteUsedCapacity=0.7708333 used=<memory:37888, vCores:32> cluster=<memory:49152, vCores:96>
2013-08-07 07:16:08,410 INFO org.apache.hadoop.yarn.server.resourcemanager.scheduler.capacity.ParentQueue: Re-sorting queues since queue: root.default stats: default: capacity=1.0, absoluteCapacity=1.0, usedResources=<memory:38912, vCores:33>usedCapacity=0.7916667, absoluteUsedCapacity=0.7916667, numApps=5, numContainers=33
2013-08-07 07:16:08,410 INFO org.apache.hadoop.yarn.server.resourcemanager.scheduler.capacity.ParentQueue: assignedContainer queue=root usedCapacity=0.7916667 absoluteUsedCapacity=0.7916667 used=<memory:38912, vCores:33> cluster=<memory:49152, vCores:96>
2013-08-07 07:16:08,411 INFO org.apache.hadoop.yarn.server.resourcemanager.rmcontainer.RMContainerImpl: container_1375859105306_0006_01_000030 Container Transitioned from NEW to ALLOCATED
2013-08-07 07:16:08,411 INFO org.apache.hadoop.yarn.server.resourcemanager.RMAuditLogger: USER=ubuntu	OPERATION=AM Allocated Container	TARGET=SchedulerApp	RESULT=SUCCESS	APPID=application_1375859105306_0006	CONTAINERID=container_1375859105306_0006_01_000030
2013-08-07 07:16:08,411 INFO org.apache.hadoop.yarn.server.resourcemanager.scheduler.common.fica.FiCaSchedulerNode: Assigned container container_1375859105306_0006_01_000030 of capacity <memory:1024, vCores:1> on host hadoop-200-7:58499, which currently has 7 containers, <memory:7168, vCores:7> used and <memory:1024, vCores:9> available
2013-08-07 07:16:08,412 INFO org.apache.hadoop.yarn.server.resourcemanager.scheduler.capacity.LeafQueue: assignedContainer application=application_1375859105306_0006 container=Container: [ContainerId: container_1375859105306_0006_01_000030, NodeId: hadoop-200-7:58499, NodeHttpAddress: hadoop-200-7:8042, Resource: <memory:1024, vCores:1>, Priority: 20, State: NEW, Token: null, Status: container_id {, app_attempt_id {, application_id {, id: 6, cluster_timestamp: 1375859105306, }, attemptId: 1, }, id: 30, }, state: C_NEW, ] containerId=container_1375859105306_0006_01_000030 queue=default: capacity=1.0, absoluteCapacity=1.0, usedResources=<memory:38912, vCores:33>usedCapacity=0.7916667, absoluteUsedCapacity=0.7916667, numApps=5, numContainers=33 usedCapacity=0.7916667 absoluteUsedCapacity=0.7916667 used=<memory:38912, vCores:33> cluster=<memory:49152, vCores:96>
2013-08-07 07:16:08,412 INFO org.apache.hadoop.yarn.server.resourcemanager.scheduler.capacity.ParentQueue: Re-sorting queues since queue: root.default stats: default: capacity=1.0, absoluteCapacity=1.0, usedResources=<memory:39936, vCores:34>usedCapacity=0.8125, absoluteUsedCapacity=0.8125, numApps=5, numContainers=34
2013-08-07 07:16:08,412 INFO org.apache.hadoop.yarn.server.resourcemanager.scheduler.capacity.ParentQueue: assignedContainer queue=root usedCapacity=0.8125 absoluteUsedCapacity=0.8125 used=<memory:39936, vCores:34> cluster=<memory:49152, vCores:96>
2013-08-07 07:16:08,413 INFO org.apache.hadoop.yarn.server.resourcemanager.rmcontainer.RMContainerImpl: container_1375859105306_0006_01_000031 Container Transitioned from NEW to ALLOCATED
2013-08-07 07:16:08,413 INFO org.apache.hadoop.yarn.server.resourcemanager.RMAuditLogger: USER=ubuntu	OPERATION=AM Allocated Container	TARGET=SchedulerApp	RESULT=SUCCESS	APPID=application_1375859105306_0006	CONTAINERID=container_1375859105306_0006_01_000031
2013-08-07 07:16:08,413 INFO org.apache.hadoop.yarn.server.resourcemanager.scheduler.common.fica.FiCaSchedulerNode: Assigned container container_1375859105306_0006_01_000031 of capacity <memory:1024, vCores:1> on host hadoop-200-7:58499, which currently has 8 containers, <memory:8192, vCores:8> used and <memory:0, vCores:8> available
2013-08-07 07:16:08,414 INFO org.apache.hadoop.yarn.server.resourcemanager.scheduler.capacity.LeafQueue: assignedContainer application=application_1375859105306_0006 container=Container: [ContainerId: container_1375859105306_0006_01_000031, NodeId: hadoop-200-7:58499, NodeHttpAddress: hadoop-200-7:8042, Resource: <memory:1024, vCores:1>, Priority: 20, State: NEW, Token: null, Status: container_id {, app_attempt_id {, application_id {, id: 6, cluster_timestamp: 1375859105306, }, attemptId: 1, }, id: 31, }, state: C_NEW, ] containerId=container_1375859105306_0006_01_000031 queue=default: capacity=1.0, absoluteCapacity=1.0, usedResources=<memory:39936, vCores:34>usedCapacity=0.8125, absoluteUsedCapacity=0.8125, numApps=5, numContainers=34 usedCapacity=0.8125 absoluteUsedCapacity=0.8125 used=<memory:39936, vCores:34> cluster=<memory:49152, vCores:96>
2013-08-07 07:16:08,414 INFO org.apache.hadoop.yarn.server.resourcemanager.scheduler.capacity.ParentQueue: Re-sorting queues since queue: root.default stats: default: capacity=1.0, absoluteCapacity=1.0, usedResources=<memory:40960, vCores:35>usedCapacity=0.8333333, absoluteUsedCapacity=0.8333333, numApps=5, numContainers=35
2013-08-07 07:16:08,414 INFO org.apache.hadoop.yarn.server.resourcemanager.scheduler.capacity.ParentQueue: assignedContainer queue=root usedCapacity=0.8333333 absoluteUsedCapacity=0.8333333 used=<memory:40960, vCores:35> cluster=<memory:49152, vCores:96>
2013-08-07 07:16:08,415 INFO org.apache.hadoop.yarn.server.resourcemanager.rmcontainer.RMContainerImpl: container_1375859105306_0006_01_000032 Container Transitioned from NEW to ALLOCATED
2013-08-07 07:16:08,415 INFO org.apache.hadoop.yarn.server.resourcemanager.RMAuditLogger: USER=ubuntu	OPERATION=AM Allocated Container	TARGET=SchedulerApp	RESULT=SUCCESS	APPID=application_1375859105306_0006	CONTAINERID=container_1375859105306_0006_01_000032
2013-08-07 07:16:08,415 INFO org.apache.hadoop.yarn.server.resourcemanager.scheduler.common.fica.FiCaSchedulerNode: Assigned container container_1375859105306_0006_01_000032 of capacity <memory:1024, vCores:1> on host hadoop-200-5:52184, which currently has 1 containers, <memory:1024, vCores:1> used and <memory:7168, vCores:15> available
2013-08-07 07:16:08,416 INFO org.apache.hadoop.yarn.server.resourcemanager.scheduler.capacity.LeafQueue: assignedContainer application=application_1375859105306_0006 container=Container: [ContainerId: container_1375859105306_0006_01_000032, NodeId: hadoop-200-5:52184, NodeHttpAddress: hadoop-200-5:8042, Resource: <memory:1024, vCores:1>, Priority: 20, State: NEW, Token: null, Status: container_id {, app_attempt_id {, application_id {, id: 6, cluster_timestamp: 1375859105306, }, attemptId: 1, }, id: 32, }, state: C_NEW, ] containerId=container_1375859105306_0006_01_000032 queue=default: capacity=1.0, absoluteCapacity=1.0, usedResources=<memory:40960, vCores:35>usedCapacity=0.8333333, absoluteUsedCapacity=0.8333333, numApps=5, numContainers=35 usedCapacity=0.8333333 absoluteUsedCapacity=0.8333333 used=<memory:40960, vCores:35> cluster=<memory:49152, vCores:96>
2013-08-07 07:16:08,416 INFO org.apache.hadoop.yarn.server.resourcemanager.scheduler.capacity.ParentQueue: Re-sorting queues since queue: root.default stats: default: capacity=1.0, absoluteCapacity=1.0, usedResources=<memory:41984, vCores:36>usedCapacity=0.8541667, absoluteUsedCapacity=0.8541667, numApps=5, numContainers=36
2013-08-07 07:16:08,416 INFO org.apache.hadoop.yarn.server.resourcemanager.scheduler.capacity.ParentQueue: assignedContainer queue=root usedCapacity=0.8541667 absoluteUsedCapacity=0.8541667 used=<memory:41984, vCores:36> cluster=<memory:49152, vCores:96>
2013-08-07 07:16:08,417 INFO org.apache.hadoop.yarn.server.resourcemanager.rmcontainer.RMContainerImpl: container_1375859105306_0006_01_000033 Container Transitioned from NEW to ALLOCATED
2013-08-07 07:16:08,417 INFO org.apache.hadoop.yarn.server.resourcemanager.RMAuditLogger: USER=ubuntu	OPERATION=AM Allocated Container	TARGET=SchedulerApp	RESULT=SUCCESS	APPID=application_1375859105306_0006	CONTAINERID=container_1375859105306_0006_01_000033
2013-08-07 07:16:08,417 INFO org.apache.hadoop.yarn.server.resourcemanager.scheduler.common.fica.FiCaSchedulerNode: Assigned container container_1375859105306_0006_01_000033 of capacity <memory:1024, vCores:1> on host hadoop-200-5:52184, which currently has 2 containers, <memory:2048, vCores:2> used and <memory:6144, vCores:14> available
2013-08-07 07:16:08,418 INFO org.apache.hadoop.yarn.server.resourcemanager.scheduler.capacity.LeafQueue: assignedContainer application=application_1375859105306_0006 container=Container: [ContainerId: container_1375859105306_0006_01_000033, NodeId: hadoop-200-5:52184, NodeHttpAddress: hadoop-200-5:8042, Resource: <memory:1024, vCores:1>, Priority: 20, State: NEW, Token: null, Status: container_id {, app_attempt_id {, application_id {, id: 6, cluster_timestamp: 1375859105306, }, attemptId: 1, }, id: 33, }, state: C_NEW, ] containerId=container_1375859105306_0006_01_000033 queue=default: capacity=1.0, absoluteCapacity=1.0, usedResources=<memory:41984, vCores:36>usedCapacity=0.8541667, absoluteUsedCapacity=0.8541667, numApps=5, numContainers=36 usedCapacity=0.8541667 absoluteUsedCapacity=0.8541667 used=<memory:41984, vCores:36> cluster=<memory:49152, vCores:96>
2013-08-07 07:16:08,418 INFO org.apache.hadoop.yarn.server.resourcemanager.scheduler.capacity.ParentQueue: Re-sorting queues since queue: root.default stats: default: capacity=1.0, absoluteCapacity=1.0, usedResources=<memory:43008, vCores:37>usedCapacity=0.875, absoluteUsedCapacity=0.875, numApps=5, numContainers=37
2013-08-07 07:16:08,419 INFO org.apache.hadoop.yarn.server.resourcemanager.scheduler.capacity.ParentQueue: assignedContainer queue=root usedCapacity=0.875 absoluteUsedCapacity=0.875 used=<memory:43008, vCores:37> cluster=<memory:49152, vCores:96>
2013-08-07 07:16:08,419 INFO org.apache.hadoop.yarn.server.resourcemanager.rmcontainer.RMContainerImpl: container_1375859105306_0006_01_000034 Container Transitioned from NEW to ALLOCATED
2013-08-07 07:16:08,419 INFO org.apache.hadoop.yarn.server.resourcemanager.RMAuditLogger: USER=ubuntu	OPERATION=AM Allocated Container	TARGET=SchedulerApp	RESULT=SUCCESS	APPID=application_1375859105306_0006	CONTAINERID=container_1375859105306_0006_01_000034
2013-08-07 07:16:08,420 INFO org.apache.hadoop.yarn.server.resourcemanager.scheduler.common.fica.FiCaSchedulerNode: Assigned container container_1375859105306_0006_01_000034 of capacity <memory:1024, vCores:1> on host hadoop-200-5:52184, which currently has 3 containers, <memory:3072, vCores:3> used and <memory:5120, vCores:13> available
2013-08-07 07:16:08,421 INFO org.apache.hadoop.yarn.server.resourcemanager.scheduler.capacity.LeafQueue: assignedContainer application=application_1375859105306_0006 container=Container: [ContainerId: container_1375859105306_0006_01_000034, NodeId: hadoop-200-5:52184, NodeHttpAddress: hadoop-200-5:8042, Resource: <memory:1024, vCores:1>, Priority: 20, State: NEW, Token: null, Status: container_id {, app_attempt_id {, application_id {, id: 6, cluster_timestamp: 1375859105306, }, attemptId: 1, }, id: 34, }, state: C_NEW, ] containerId=container_1375859105306_0006_01_000034 queue=default: capacity=1.0, absoluteCapacity=1.0, usedResources=<memory:43008, vCores:37>usedCapacity=0.875, absoluteUsedCapacity=0.875, numApps=5, numContainers=37 usedCapacity=0.875 absoluteUsedCapacity=0.875 used=<memory:43008, vCores:37> cluster=<memory:49152, vCores:96>
2013-08-07 07:16:08,421 INFO org.apache.hadoop.yarn.server.resourcemanager.scheduler.capacity.ParentQueue: Re-sorting queues since queue: root.default stats: default: capacity=1.0, absoluteCapacity=1.0, usedResources=<memory:44032, vCores:38>usedCapacity=0.8958333, absoluteUsedCapacity=0.8958333, numApps=5, numContainers=38
2013-08-07 07:16:08,421 INFO org.apache.hadoop.yarn.server.resourcemanager.scheduler.capacity.ParentQueue: assignedContainer queue=root usedCapacity=0.8958333 absoluteUsedCapacity=0.8958333 used=<memory:44032, vCores:38> cluster=<memory:49152, vCores:96>
2013-08-07 07:16:08,421 INFO org.apache.hadoop.yarn.server.resourcemanager.rmcontainer.RMContainerImpl: container_1375859105306_0006_01_000035 Container Transitioned from NEW to ALLOCATED
2013-08-07 07:16:08,422 INFO org.apache.hadoop.yarn.server.resourcemanager.RMAuditLogger: USER=ubuntu	OPERATION=AM Allocated Container	TARGET=SchedulerApp	RESULT=SUCCESS	APPID=application_1375859105306_0006	CONTAINERID=container_1375859105306_0006_01_000035
2013-08-07 07:16:08,422 INFO org.apache.hadoop.yarn.server.resourcemanager.scheduler.common.fica.FiCaSchedulerNode: Assigned container container_1375859105306_0006_01_000035 of capacity <memory:1024, vCores:1> on host hadoop-200-5:52184, which currently has 4 containers, <memory:4096, vCores:4> used and <memory:4096, vCores:12> available
2013-08-07 07:16:08,423 INFO org.apache.hadoop.yarn.server.resourcemanager.scheduler.capacity.LeafQueue: assignedContainer application=application_1375859105306_0006 container=Container: [ContainerId: container_1375859105306_0006_01_000035, NodeId: hadoop-200-5:52184, NodeHttpAddress: hadoop-200-5:8042, Resource: <memory:1024, vCores:1>, Priority: 20, State: NEW, Token: null, Status: container_id {, app_attempt_id {, application_id {, id: 6, cluster_timestamp: 1375859105306, }, attemptId: 1, }, id: 35, }, state: C_NEW, ] containerId=container_1375859105306_0006_01_000035 queue=default: capacity=1.0, absoluteCapacity=1.0, usedResources=<memory:44032, vCores:38>usedCapacity=0.8958333, absoluteUsedCapacity=0.8958333, numApps=5, numContainers=38 usedCapacity=0.8958333 absoluteUsedCapacity=0.8958333 used=<memory:44032, vCores:38> cluster=<memory:49152, vCores:96>
2013-08-07 07:16:08,423 INFO org.apache.hadoop.yarn.server.resourcemanager.scheduler.capacity.ParentQueue: Re-sorting queues since queue: root.default stats: default: capacity=1.0, absoluteCapacity=1.0, usedResources=<memory:45056, vCores:39>usedCapacity=0.9166667, absoluteUsedCapacity=0.9166667, numApps=5, numContainers=39
2013-08-07 07:16:08,423 INFO org.apache.hadoop.yarn.server.resourcemanager.scheduler.capacity.ParentQueue: assignedContainer queue=root usedCapacity=0.9166667 absoluteUsedCapacity=0.9166667 used=<memory:45056, vCores:39> cluster=<memory:49152, vCores:96>
2013-08-07 07:16:08,424 INFO org.apache.hadoop.yarn.server.resourcemanager.rmcontainer.RMContainerImpl: container_1375859105306_0006_01_000036 Container Transitioned from NEW to ALLOCATED
2013-08-07 07:16:08,424 INFO org.apache.hadoop.yarn.server.resourcemanager.RMAuditLogger: USER=ubuntu	OPERATION=AM Allocated Container	TARGET=SchedulerApp	RESULT=SUCCESS	APPID=application_1375859105306_0006	CONTAINERID=container_1375859105306_0006_01_000036
2013-08-07 07:16:08,424 INFO org.apache.hadoop.yarn.server.resourcemanager.scheduler.common.fica.FiCaSchedulerNode: Assigned container container_1375859105306_0006_01_000036 of capacity <memory:1024, vCores:1> on host hadoop-200-5:52184, which currently has 5 containers, <memory:5120, vCores:5> used and <memory:3072, vCores:11> available
2013-08-07 07:16:08,425 INFO org.apache.hadoop.yarn.server.resourcemanager.scheduler.capacity.LeafQueue: assignedContainer application=application_1375859105306_0006 container=Container: [ContainerId: container_1375859105306_0006_01_000036, NodeId: hadoop-200-5:52184, NodeHttpAddress: hadoop-200-5:8042, Resource: <memory:1024, vCores:1>, Priority: 20, State: NEW, Token: null, Status: container_id {, app_attempt_id {, application_id {, id: 6, cluster_timestamp: 1375859105306, }, attemptId: 1, }, id: 36, }, state: C_NEW, ] containerId=container_1375859105306_0006_01_000036 queue=default: capacity=1.0, absoluteCapacity=1.0, usedResources=<memory:45056, vCores:39>usedCapacity=0.9166667, absoluteUsedCapacity=0.9166667, numApps=5, numContainers=39 usedCapacity=0.9166667 absoluteUsedCapacity=0.9166667 used=<memory:45056, vCores:39> cluster=<memory:49152, vCores:96>
2013-08-07 07:16:08,425 INFO org.apache.hadoop.yarn.server.resourcemanager.scheduler.capacity.ParentQueue: Re-sorting queues since queue: root.default stats: default: capacity=1.0, absoluteCapacity=1.0, usedResources=<memory:46080, vCores:40>usedCapacity=0.9375, absoluteUsedCapacity=0.9375, numApps=5, numContainers=40
2013-08-07 07:16:08,425 INFO org.apache.hadoop.yarn.server.resourcemanager.scheduler.capacity.ParentQueue: assignedContainer queue=root usedCapacity=0.9375 absoluteUsedCapacity=0.9375 used=<memory:46080, vCores:40> cluster=<memory:49152, vCores:96>
2013-08-07 07:16:08,426 INFO org.apache.hadoop.yarn.server.resourcemanager.rmcontainer.RMContainerImpl: container_1375859105306_0006_01_000037 Container Transitioned from NEW to ALLOCATED
2013-08-07 07:16:08,426 INFO org.apache.hadoop.yarn.server.resourcemanager.RMAuditLogger: USER=ubuntu	OPERATION=AM Allocated Container	TARGET=SchedulerApp	RESULT=SUCCESS	APPID=application_1375859105306_0006	CONTAINERID=container_1375859105306_0006_01_000037
2013-08-07 07:16:08,426 INFO org.apache.hadoop.yarn.server.resourcemanager.scheduler.common.fica.FiCaSchedulerNode: Assigned container container_1375859105306_0006_01_000037 of capacity <memory:1024, vCores:1> on host hadoop-200-5:52184, which currently has 6 containers, <memory:6144, vCores:6> used and <memory:2048, vCores:10> available
2013-08-07 07:16:08,427 INFO org.apache.hadoop.yarn.server.resourcemanager.scheduler.capacity.LeafQueue: assignedContainer application=application_1375859105306_0006 container=Container: [ContainerId: container_1375859105306_0006_01_000037, NodeId: hadoop-200-5:52184, NodeHttpAddress: hadoop-200-5:8042, Resource: <memory:1024, vCores:1>, Priority: 20, State: NEW, Token: null, Status: container_id {, app_attempt_id {, application_id {, id: 6, cluster_timestamp: 1375859105306, }, attemptId: 1, }, id: 37, }, state: C_NEW, ] containerId=container_1375859105306_0006_01_000037 queue=default: capacity=1.0, absoluteCapacity=1.0, usedResources=<memory:46080, vCores:40>usedCapacity=0.9375, absoluteUsedCapacity=0.9375, numApps=5, numContainers=40 usedCapacity=0.9375 absoluteUsedCapacity=0.9375 used=<memory:46080, vCores:40> cluster=<memory:49152, vCores:96>
2013-08-07 07:16:08,427 INFO org.apache.hadoop.yarn.server.resourcemanager.scheduler.capacity.ParentQueue: Re-sorting queues since queue: root.default stats: default: capacity=1.0, absoluteCapacity=1.0, usedResources=<memory:47104, vCores:41>usedCapacity=0.9583333, absoluteUsedCapacity=0.9583333, numApps=5, numContainers=41
2013-08-07 07:16:08,427 INFO org.apache.hadoop.yarn.server.resourcemanager.scheduler.capacity.ParentQueue: assignedContainer queue=root usedCapacity=0.9583333 absoluteUsedCapacity=0.9583333 used=<memory:47104, vCores:41> cluster=<memory:49152, vCores:96>
2013-08-07 07:16:08,428 INFO org.apache.hadoop.yarn.server.resourcemanager.rmcontainer.RMContainerImpl: container_1375859105306_0006_01_000038 Container Transitioned from NEW to ALLOCATED
2013-08-07 07:16:08,428 INFO org.apache.hadoop.yarn.server.resourcemanager.RMAuditLogger: USER=ubuntu	OPERATION=AM Allocated Container	TARGET=SchedulerApp	RESULT=SUCCESS	APPID=application_1375859105306_0006	CONTAINERID=container_1375859105306_0006_01_000038
2013-08-07 07:16:08,428 INFO org.apache.hadoop.yarn.server.resourcemanager.scheduler.common.fica.FiCaSchedulerNode: Assigned container container_1375859105306_0006_01_000038 of capacity <memory:1024, vCores:1> on host hadoop-200-5:52184, which currently has 7 containers, <memory:7168, vCores:7> used and <memory:1024, vCores:9> available
2013-08-07 07:16:08,429 INFO org.apache.hadoop.yarn.server.resourcemanager.scheduler.capacity.LeafQueue: assignedContainer application=application_1375859105306_0006 container=Container: [ContainerId: container_1375859105306_0006_01_000038, NodeId: hadoop-200-5:52184, NodeHttpAddress: hadoop-200-5:8042, Resource: <memory:1024, vCores:1>, Priority: 20, State: NEW, Token: null, Status: container_id {, app_attempt_id {, application_id {, id: 6, cluster_timestamp: 1375859105306, }, attemptId: 1, }, id: 38, }, state: C_NEW, ] containerId=container_1375859105306_0006_01_000038 queue=default: capacity=1.0, absoluteCapacity=1.0, usedResources=<memory:47104, vCores:41>usedCapacity=0.9583333, absoluteUsedCapacity=0.9583333, numApps=5, numContainers=41 usedCapacity=0.9583333 absoluteUsedCapacity=0.9583333 used=<memory:47104, vCores:41> cluster=<memory:49152, vCores:96>
2013-08-07 07:16:08,430 INFO org.apache.hadoop.yarn.server.resourcemanager.scheduler.capacity.ParentQueue: Re-sorting queues since queue: root.default stats: default: capacity=1.0, absoluteCapacity=1.0, usedResources=<memory:48128, vCores:42>usedCapacity=0.9791667, absoluteUsedCapacity=0.9791667, numApps=5, numContainers=42
2013-08-07 07:16:08,430 INFO org.apache.hadoop.yarn.server.resourcemanager.scheduler.capacity.ParentQueue: assignedContainer queue=root usedCapacity=0.9791667 absoluteUsedCapacity=0.9791667 used=<memory:48128, vCores:42> cluster=<memory:49152, vCores:96>
2013-08-07 07:16:08,430 INFO org.apache.hadoop.yarn.server.resourcemanager.rmcontainer.RMContainerImpl: container_1375859105306_0006_01_000039 Container Transitioned from NEW to ALLOCATED
2013-08-07 07:16:08,430 INFO org.apache.hadoop.yarn.server.resourcemanager.RMAuditLogger: USER=ubuntu	OPERATION=AM Allocated Container	TARGET=SchedulerApp	RESULT=SUCCESS	APPID=application_1375859105306_0006	CONTAINERID=container_1375859105306_0006_01_000039
2013-08-07 07:16:08,430 INFO org.apache.hadoop.yarn.server.resourcemanager.scheduler.common.fica.FiCaSchedulerNode: Assigned container container_1375859105306_0006_01_000039 of capacity <memory:1024, vCores:1> on host hadoop-200-5:52184, which currently has 8 containers, <memory:8192, vCores:8> used and <memory:0, vCores:8> available
2013-08-07 07:16:08,431 INFO org.apache.hadoop.yarn.server.resourcemanager.scheduler.capacity.LeafQueue: assignedContainer application=application_1375859105306_0006 container=Container: [ContainerId: container_1375859105306_0006_01_000039, NodeId: hadoop-200-5:52184, NodeHttpAddress: hadoop-200-5:8042, Resource: <memory:1024, vCores:1>, Priority: 20, State: NEW, Token: null, Status: container_id {, app_attempt_id {, application_id {, id: 6, cluster_timestamp: 1375859105306, }, attemptId: 1, }, id: 39, }, state: C_NEW, ] containerId=container_1375859105306_0006_01_000039 queue=default: capacity=1.0, absoluteCapacity=1.0, usedResources=<memory:48128, vCores:42>usedCapacity=0.9791667, absoluteUsedCapacity=0.9791667, numApps=5, numContainers=42 usedCapacity=0.9791667 absoluteUsedCapacity=0.9791667 used=<memory:48128, vCores:42> cluster=<memory:49152, vCores:96>
2013-08-07 07:16:08,432 INFO org.apache.hadoop.yarn.server.resourcemanager.scheduler.capacity.ParentQueue: Re-sorting queues since queue: root.default stats: default: capacity=1.0, absoluteCapacity=1.0, usedResources=<memory:49152, vCores:43>usedCapacity=1.0, absoluteUsedCapacity=1.0, numApps=5, numContainers=43
2013-08-07 07:16:08,432 INFO org.apache.hadoop.yarn.server.resourcemanager.scheduler.capacity.ParentQueue: assignedContainer queue=root usedCapacity=1.0 absoluteUsedCapacity=1.0 used=<memory:49152, vCores:43> cluster=<memory:49152, vCores:96>
2013-08-07 07:16:08,658 INFO org.apache.hadoop.yarn.server.resourcemanager.ApplicationMasterService: AM registration appattempt_1375859105306_0009_000001
2013-08-07 07:16:08,659 INFO org.apache.hadoop.yarn.server.resourcemanager.RMAuditLogger: USER=ubuntu	IP=192.168.100.4	OPERATION=Register App Master	TARGET=ApplicationMasterService	RESULT=SUCCESS	APPID=application_1375859105306_0009	APPATTEMPTID=appattempt_1375859105306_0009_000001
2013-08-07 07:16:08,660 INFO org.apache.hadoop.yarn.server.resourcemanager.rmapp.attempt.RMAppAttemptImpl: appattempt_1375859105306_0009_000001 State change from LAUNCHED to RUNNING
2013-08-07 07:16:08,660 INFO org.apache.hadoop.yarn.server.resourcemanager.rmapp.RMAppImpl: application_1375859105306_0009 State change from ACCEPTED to RUNNING
2013-08-07 07:16:08,752 INFO org.apache.hadoop.yarn.server.resourcemanager.rmcontainer.RMContainerImpl: container_1375859105306_0006_01_000002 Container Transitioned from ALLOCATED to ACQUIRED
2013-08-07 07:16:08,752 INFO org.apache.hadoop.yarn.server.resourcemanager.rmcontainer.RMContainerImpl: container_1375859105306_0006_01_000003 Container Transitioned from ALLOCATED to ACQUIRED
2013-08-07 07:16:08,753 INFO org.apache.hadoop.yarn.server.resourcemanager.rmcontainer.RMContainerImpl: container_1375859105306_0006_01_000004 Container Transitioned from ALLOCATED to ACQUIRED
2013-08-07 07:16:08,754 INFO org.apache.hadoop.yarn.server.resourcemanager.rmcontainer.RMContainerImpl: container_1375859105306_0006_01_000005 Container Transitioned from ALLOCATED to ACQUIRED
2013-08-07 07:16:08,755 INFO org.apache.hadoop.yarn.server.resourcemanager.rmcontainer.RMContainerImpl: container_1375859105306_0006_01_000006 Container Transitioned from ALLOCATED to ACQUIRED
2013-08-07 07:16:08,755 INFO org.apache.hadoop.yarn.server.resourcemanager.rmcontainer.RMContainerImpl: container_1375859105306_0006_01_000007 Container Transitioned from ALLOCATED to ACQUIRED
2013-08-07 07:16:08,756 INFO org.apache.hadoop.yarn.server.resourcemanager.rmcontainer.RMContainerImpl: container_1375859105306_0006_01_000008 Container Transitioned from ALLOCATED to ACQUIRED
2013-08-07 07:16:08,758 INFO org.apache.hadoop.yarn.server.resourcemanager.rmcontainer.RMContainerImpl: container_1375859105306_0006_01_000009 Container Transitioned from ALLOCATED to ACQUIRED
2013-08-07 07:16:08,758 INFO org.apache.hadoop.yarn.server.resourcemanager.rmcontainer.RMContainerImpl: container_1375859105306_0006_01_000010 Container Transitioned from ALLOCATED to ACQUIRED
2013-08-07 07:16:08,759 INFO org.apache.hadoop.yarn.server.resourcemanager.rmcontainer.RMContainerImpl: container_1375859105306_0006_01_000011 Container Transitioned from ALLOCATED to ACQUIRED
2013-08-07 07:16:08,759 INFO org.apache.hadoop.yarn.server.resourcemanager.rmcontainer.RMContainerImpl: container_1375859105306_0006_01_000012 Container Transitioned from ALLOCATED to ACQUIRED
2013-08-07 07:16:08,760 INFO org.apache.hadoop.yarn.server.resourcemanager.rmcontainer.RMContainerImpl: container_1375859105306_0006_01_000013 Container Transitioned from ALLOCATED to ACQUIRED
2013-08-07 07:16:08,760 INFO org.apache.hadoop.yarn.server.resourcemanager.rmcontainer.RMContainerImpl: container_1375859105306_0006_01_000014 Container Transitioned from ALLOCATED to ACQUIRED
2013-08-07 07:16:08,760 INFO org.apache.hadoop.yarn.server.resourcemanager.rmcontainer.RMContainerImpl: container_1375859105306_0006_01_000015 Container Transitioned from ALLOCATED to ACQUIRED
2013-08-07 07:16:08,760 INFO org.apache.hadoop.yarn.server.resourcemanager.rmcontainer.RMContainerImpl: container_1375859105306_0006_01_000016 Container Transitioned from ALLOCATED to ACQUIRED
2013-08-07 07:16:08,761 INFO org.apache.hadoop.yarn.server.resourcemanager.rmcontainer.RMContainerImpl: container_1375859105306_0006_01_000017 Container Transitioned from ALLOCATED to ACQUIRED
2013-08-07 07:16:08,761 INFO org.apache.hadoop.yarn.server.resourcemanager.rmcontainer.RMContainerImpl: container_1375859105306_0006_01_000018 Container Transitioned from ALLOCATED to ACQUIRED
2013-08-07 07:16:08,761 INFO org.apache.hadoop.yarn.server.resourcemanager.rmcontainer.RMContainerImpl: container_1375859105306_0006_01_000019 Container Transitioned from ALLOCATED to ACQUIRED
2013-08-07 07:16:08,761 INFO org.apache.hadoop.yarn.server.resourcemanager.rmcontainer.RMContainerImpl: container_1375859105306_0006_01_000020 Container Transitioned from ALLOCATED to ACQUIRED
2013-08-07 07:16:08,761 INFO org.apache.hadoop.yarn.server.resourcemanager.rmcontainer.RMContainerImpl: container_1375859105306_0006_01_000021 Container Transitioned from ALLOCATED to ACQUIRED
2013-08-07 07:16:08,762 INFO org.apache.hadoop.yarn.server.resourcemanager.rmcontainer.RMContainerImpl: container_1375859105306_0006_01_000022 Container Transitioned from ALLOCATED to ACQUIRED
2013-08-07 07:16:08,762 INFO org.apache.hadoop.yarn.server.resourcemanager.rmcontainer.RMContainerImpl: container_1375859105306_0006_01_000023 Container Transitioned from ALLOCATED to ACQUIRED
2013-08-07 07:16:08,762 INFO org.apache.hadoop.yarn.server.resourcemanager.rmcontainer.RMContainerImpl: container_1375859105306_0006_01_000024 Container Transitioned from ALLOCATED to ACQUIRED
2013-08-07 07:16:08,762 INFO org.apache.hadoop.yarn.server.resourcemanager.rmcontainer.RMContainerImpl: container_1375859105306_0006_01_000025 Container Transitioned from ALLOCATED to ACQUIRED
2013-08-07 07:16:08,762 INFO org.apache.hadoop.yarn.server.resourcemanager.rmcontainer.RMContainerImpl: container_1375859105306_0006_01_000026 Container Transitioned from ALLOCATED to ACQUIRED
2013-08-07 07:16:08,762 INFO org.apache.hadoop.yarn.server.resourcemanager.rmcontainer.RMContainerImpl: container_1375859105306_0006_01_000027 Container Transitioned from ALLOCATED to ACQUIRED
2013-08-07 07:16:08,763 INFO org.apache.hadoop.yarn.server.resourcemanager.rmcontainer.RMContainerImpl: container_1375859105306_0006_01_000028 Container Transitioned from ALLOCATED to ACQUIRED
2013-08-07 07:16:08,763 INFO org.apache.hadoop.yarn.server.resourcemanager.rmcontainer.RMContainerImpl: container_1375859105306_0006_01_000029 Container Transitioned from ALLOCATED to ACQUIRED
2013-08-07 07:16:08,763 INFO org.apache.hadoop.yarn.server.resourcemanager.rmcontainer.RMContainerImpl: container_1375859105306_0006_01_000030 Container Transitioned from ALLOCATED to ACQUIRED
2013-08-07 07:16:08,763 INFO org.apache.hadoop.yarn.server.resourcemanager.rmcontainer.RMContainerImpl: container_1375859105306_0006_01_000031 Container Transitioned from ALLOCATED to ACQUIRED
2013-08-07 07:16:08,763 INFO org.apache.hadoop.yarn.server.resourcemanager.rmcontainer.RMContainerImpl: container_1375859105306_0006_01_000032 Container Transitioned from ALLOCATED to ACQUIRED
2013-08-07 07:16:08,764 INFO org.apache.hadoop.yarn.server.resourcemanager.rmcontainer.RMContainerImpl: container_1375859105306_0006_01_000033 Container Transitioned from ALLOCATED to ACQUIRED
2013-08-07 07:16:08,764 INFO org.apache.hadoop.yarn.server.resourcemanager.rmcontainer.RMContainerImpl: container_1375859105306_0006_01_000034 Container Transitioned from ALLOCATED to ACQUIRED
2013-08-07 07:16:08,764 INFO org.apache.hadoop.yarn.server.resourcemanager.rmcontainer.RMContainerImpl: container_1375859105306_0006_01_000035 Container Transitioned from ALLOCATED to ACQUIRED
2013-08-07 07:16:08,764 INFO org.apache.hadoop.yarn.server.resourcemanager.rmcontainer.RMContainerImpl: container_1375859105306_0006_01_000036 Container Transitioned from ALLOCATED to ACQUIRED
2013-08-07 07:16:08,765 INFO org.apache.hadoop.yarn.server.resourcemanager.rmcontainer.RMContainerImpl: container_1375859105306_0006_01_000037 Container Transitioned from ALLOCATED to ACQUIRED
2013-08-07 07:16:08,765 INFO org.apache.hadoop.yarn.server.resourcemanager.rmcontainer.RMContainerImpl: container_1375859105306_0006_01_000038 Container Transitioned from ALLOCATED to ACQUIRED
2013-08-07 07:16:08,765 INFO org.apache.hadoop.yarn.server.resourcemanager.rmcontainer.RMContainerImpl: container_1375859105306_0006_01_000039 Container Transitioned from ALLOCATED to ACQUIRED
2013-08-07 07:16:09,389 INFO org.apache.hadoop.yarn.server.resourcemanager.rmcontainer.RMContainerImpl: container_1375859105306_0006_01_000016 Container Transitioned from ACQUIRED to RUNNING
2013-08-07 07:16:09,390 INFO org.apache.hadoop.yarn.server.resourcemanager.rmcontainer.RMContainerImpl: container_1375859105306_0006_01_000017 Container Transitioned from ACQUIRED to RUNNING
2013-08-07 07:16:09,390 INFO org.apache.hadoop.yarn.server.resourcemanager.rmcontainer.RMContainerImpl: container_1375859105306_0006_01_000018 Container Transitioned from ACQUIRED to RUNNING
2013-08-07 07:16:09,391 INFO org.apache.hadoop.yarn.server.resourcemanager.rmcontainer.RMContainerImpl: container_1375859105306_0006_01_000019 Container Transitioned from ACQUIRED to RUNNING
2013-08-07 07:16:09,392 INFO org.apache.hadoop.yarn.server.resourcemanager.rmcontainer.RMContainerImpl: container_1375859105306_0006_01_000020 Container Transitioned from ACQUIRED to RUNNING
2013-08-07 07:16:09,397 INFO org.apache.hadoop.yarn.server.resourcemanager.rmcontainer.RMContainerImpl: container_1375859105306_0006_01_000021 Container Transitioned from ACQUIRED to RUNNING
2013-08-07 07:16:09,397 INFO org.apache.hadoop.yarn.server.resourcemanager.rmcontainer.RMContainerImpl: container_1375859105306_0006_01_000022 Container Transitioned from ACQUIRED to RUNNING
2013-08-07 07:16:09,398 INFO org.apache.hadoop.yarn.server.resourcemanager.rmcontainer.RMContainerImpl: container_1375859105306_0006_01_000023 Container Transitioned from ACQUIRED to RUNNING
2013-08-07 07:16:09,409 INFO org.apache.hadoop.yarn.server.resourcemanager.rmcontainer.RMContainerImpl: container_1375859105306_0006_01_000010 Container Transitioned from ACQUIRED to RUNNING
2013-08-07 07:16:09,410 INFO org.apache.hadoop.yarn.server.resourcemanager.rmcontainer.RMContainerImpl: container_1375859105306_0006_01_000011 Container Transitioned from ACQUIRED to RUNNING
2013-08-07 07:16:09,410 INFO org.apache.hadoop.yarn.server.resourcemanager.rmcontainer.RMContainerImpl: container_1375859105306_0006_01_000012 Container Transitioned from ACQUIRED to RUNNING
2013-08-07 07:16:09,410 INFO org.apache.hadoop.yarn.server.resourcemanager.rmcontainer.RMContainerImpl: container_1375859105306_0006_01_000013 Container Transitioned from ACQUIRED to RUNNING
2013-08-07 07:16:09,411 INFO org.apache.hadoop.yarn.server.resourcemanager.rmcontainer.RMContainerImpl: container_1375859105306_0006_01_000014 Container Transitioned from ACQUIRED to RUNNING
2013-08-07 07:16:09,411 INFO org.apache.hadoop.yarn.server.resourcemanager.rmcontainer.RMContainerImpl: container_1375859105306_0006_01_000015 Container Transitioned from ACQUIRED to RUNNING
2013-08-07 07:16:09,835 INFO org.apache.hadoop.yarn.server.resourcemanager.rmcontainer.RMContainerImpl: container_1375859105306_0006_01_000002 Container Transitioned from ACQUIRED to RUNNING
2013-08-07 07:16:09,835 INFO org.apache.hadoop.yarn.server.resourcemanager.rmcontainer.RMContainerImpl: container_1375859105306_0006_01_000003 Container Transitioned from ACQUIRED to RUNNING
2013-08-07 07:16:09,835 INFO org.apache.hadoop.yarn.server.resourcemanager.rmcontainer.RMContainerImpl: container_1375859105306_0006_01_000004 Container Transitioned from ACQUIRED to RUNNING
2013-08-07 07:16:09,835 INFO org.apache.hadoop.yarn.server.resourcemanager.rmcontainer.RMContainerImpl: container_1375859105306_0006_01_000005 Container Transitioned from ACQUIRED to RUNNING
2013-08-07 07:16:10,159 INFO org.apache.hadoop.yarn.server.resourcemanager.rmcontainer.RMContainerImpl: container_1375859105306_0006_01_000006 Container Transitioned from ACQUIRED to RUNNING
2013-08-07 07:16:10,159 INFO org.apache.hadoop.yarn.server.resourcemanager.rmcontainer.RMContainerImpl: container_1375859105306_0006_01_000007 Container Transitioned from ACQUIRED to RUNNING
2013-08-07 07:16:10,159 INFO org.apache.hadoop.yarn.server.resourcemanager.rmcontainer.RMContainerImpl: container_1375859105306_0006_01_000008 Container Transitioned from ACQUIRED to RUNNING
2013-08-07 07:16:10,159 INFO org.apache.hadoop.yarn.server.resourcemanager.rmcontainer.RMContainerImpl: container_1375859105306_0006_01_000009 Container Transitioned from ACQUIRED to RUNNING
2013-08-07 07:16:10,426 INFO org.apache.hadoop.yarn.server.resourcemanager.rmcontainer.RMContainerImpl: container_1375859105306_0006_01_000032 Container Transitioned from ACQUIRED to RUNNING
2013-08-07 07:16:10,427 INFO org.apache.hadoop.yarn.server.resourcemanager.rmcontainer.RMContainerImpl: container_1375859105306_0006_01_000033 Container Transitioned from ACQUIRED to RUNNING
2013-08-07 07:16:10,427 INFO org.apache.hadoop.yarn.server.resourcemanager.rmcontainer.RMContainerImpl: container_1375859105306_0006_01_000034 Container Transitioned from ACQUIRED to RUNNING
2013-08-07 07:16:10,428 INFO org.apache.hadoop.yarn.server.resourcemanager.rmcontainer.RMContainerImpl: container_1375859105306_0006_01_000035 Container Transitioned from ACQUIRED to RUNNING
2013-08-07 07:16:10,428 INFO org.apache.hadoop.yarn.server.resourcemanager.rmcontainer.RMContainerImpl: container_1375859105306_0006_01_000036 Container Transitioned from ACQUIRED to RUNNING
2013-08-07 07:16:10,428 INFO org.apache.hadoop.yarn.server.resourcemanager.rmcontainer.RMContainerImpl: container_1375859105306_0006_01_000037 Container Transitioned from ACQUIRED to RUNNING
2013-08-07 07:16:10,430 INFO org.apache.hadoop.yarn.server.resourcemanager.rmcontainer.RMContainerImpl: container_1375859105306_0006_01_000038 Container Transitioned from ACQUIRED to RUNNING
2013-08-07 07:16:10,430 INFO org.apache.hadoop.yarn.server.resourcemanager.rmcontainer.RMContainerImpl: container_1375859105306_0006_01_000039 Container Transitioned from ACQUIRED to RUNNING
2013-08-07 07:16:10,448 INFO org.apache.hadoop.yarn.server.resourcemanager.rmcontainer.RMContainerImpl: container_1375859105306_0006_01_000024 Container Transitioned from ACQUIRED to RUNNING
2013-08-07 07:16:10,448 INFO org.apache.hadoop.yarn.server.resourcemanager.rmcontainer.RMContainerImpl: container_1375859105306_0006_01_000025 Container Transitioned from ACQUIRED to RUNNING
2013-08-07 07:16:10,448 INFO org.apache.hadoop.yarn.server.resourcemanager.rmcontainer.RMContainerImpl: container_1375859105306_0006_01_000026 Container Transitioned from ACQUIRED to RUNNING
2013-08-07 07:16:10,448 INFO org.apache.hadoop.yarn.server.resourcemanager.rmcontainer.RMContainerImpl: container_1375859105306_0006_01_000027 Container Transitioned from ACQUIRED to RUNNING
2013-08-07 07:16:10,448 INFO org.apache.hadoop.yarn.server.resourcemanager.rmcontainer.RMContainerImpl: container_1375859105306_0006_01_000028 Container Transitioned from ACQUIRED to RUNNING
2013-08-07 07:16:10,449 INFO org.apache.hadoop.yarn.server.resourcemanager.rmcontainer.RMContainerImpl: container_1375859105306_0006_01_000029 Container Transitioned from ACQUIRED to RUNNING
2013-08-07 07:16:10,449 INFO org.apache.hadoop.yarn.server.resourcemanager.rmcontainer.RMContainerImpl: container_1375859105306_0006_01_000030 Container Transitioned from ACQUIRED to RUNNING
2013-08-07 07:16:10,449 INFO org.apache.hadoop.yarn.server.resourcemanager.rmcontainer.RMContainerImpl: container_1375859105306_0006_01_000031 Container Transitioned from ACQUIRED to RUNNING
2013-08-07 07:16:10,526 INFO org.apache.hadoop.yarn.server.resourcemanager.ApplicationMasterService: AM registration appattempt_1375859105306_0008_000001
2013-08-07 07:16:10,526 INFO org.apache.hadoop.yarn.server.resourcemanager.RMAuditLogger: USER=ubuntu	IP=192.168.100.5	OPERATION=Register App Master	TARGET=ApplicationMasterService	RESULT=SUCCESS	APPID=application_1375859105306_0008	APPATTEMPTID=appattempt_1375859105306_0008_000001
2013-08-07 07:16:10,527 INFO org.apache.hadoop.yarn.server.resourcemanager.rmapp.attempt.RMAppAttemptImpl: appattempt_1375859105306_0008_000001 State change from LAUNCHED to RUNNING
2013-08-07 07:16:10,527 INFO org.apache.hadoop.yarn.server.resourcemanager.rmapp.RMAppImpl: application_1375859105306_0008 State change from ACCEPTED to RUNNING
2013-08-07 07:16:27,879 INFO org.apache.hadoop.yarn.server.resourcemanager.rmcontainer.RMContainerImpl: container_1375859105306_0006_01_000007 Container Transitioned from RUNNING to COMPLETED
2013-08-07 07:16:27,879 INFO org.apache.hadoop.yarn.server.resourcemanager.scheduler.common.fica.FiCaSchedulerApp: Completed container: container_1375859105306_0006_01_000007 in state: COMPLETED event:FINISHED
2013-08-07 07:16:27,879 INFO org.apache.hadoop.yarn.server.resourcemanager.RMAuditLogger: USER=ubuntu	OPERATION=AM Released Container	TARGET=SchedulerApp	RESULT=SUCCESS	APPID=application_1375859105306_0006	CONTAINERID=container_1375859105306_0006_01_000007
2013-08-07 07:16:27,879 INFO org.apache.hadoop.yarn.server.resourcemanager.scheduler.common.fica.FiCaSchedulerNode: Released container container_1375859105306_0006_01_000007 of capacity <memory:1024, vCores:1> on host hadoop-200-3:55493, which currently has 5 containers, <memory:7168, vCores:5> used and <memory:1024, vCores:11> available, release resources=true
2013-08-07 07:16:27,879 INFO org.apache.hadoop.yarn.server.resourcemanager.scheduler.capacity.LeafQueue: default used=<memory:48128, vCores:42> numContainers=42 user=ubuntu user-resources=<memory:48128, vCores:42>
2013-08-07 07:16:27,882 INFO org.apache.hadoop.yarn.server.resourcemanager.scheduler.capacity.LeafQueue: completedContainer container=Container: [ContainerId: container_1375859105306_0006_01_000007, NodeId: hadoop-200-3:55493, NodeHttpAddress: hadoop-200-3:8042, Resource: <memory:1024, vCores:1>, Priority: 20, State: NEW, Token: null, Status: container_id {, app_attempt_id {, application_id {, id: 6, cluster_timestamp: 1375859105306, }, attemptId: 1, }, id: 7, }, state: C_COMPLETE, diagnostics: "Container killed by the ApplicationMaster.\n\n", exit_status: 143, ] resource=<memory:1024, vCores:1> queue=default: capacity=1.0, absoluteCapacity=1.0, usedResources=<memory:48128, vCores:42>usedCapacity=0.9791667, absoluteUsedCapacity=0.9791667, numApps=5, numContainers=42 usedCapacity=0.9791667 absoluteUsedCapacity=0.9791667 used=<memory:48128, vCores:42> cluster=<memory:49152, vCores:96>
2013-08-07 07:16:27,882 INFO org.apache.hadoop.yarn.server.resourcemanager.scheduler.capacity.ParentQueue: completedContainer queue=root usedCapacity=0.9791667 absoluteUsedCapacity=0.9791667 used=<memory:48128, vCores:42> cluster=<memory:49152, vCores:96>
2013-08-07 07:16:27,883 INFO org.apache.hadoop.yarn.server.resourcemanager.scheduler.capacity.CapacityScheduler: Application appattempt_1375859105306_0006_000001 released container container_1375859105306_0006_01_000007 on node: host: hadoop-200-3:55493 #containers=5 available=1024 used=7168 with event: FINISHED
2013-08-07 07:16:27,883 INFO org.apache.hadoop.yarn.server.resourcemanager.rmcontainer.RMContainerImpl: container_1375859105306_0006_01_000040 Container Transitioned from NEW to ALLOCATED
2013-08-07 07:16:27,884 INFO org.apache.hadoop.yarn.server.resourcemanager.RMAuditLogger: USER=ubuntu	OPERATION=AM Allocated Container	TARGET=SchedulerApp	RESULT=SUCCESS	APPID=application_1375859105306_0006	CONTAINERID=container_1375859105306_0006_01_000040
2013-08-07 07:16:27,884 INFO org.apache.hadoop.yarn.server.resourcemanager.scheduler.common.fica.FiCaSchedulerNode: Assigned container container_1375859105306_0006_01_000040 of capacity <memory:1024, vCores:1> on host hadoop-200-3:55493, which currently has 6 containers, <memory:8192, vCores:6> used and <memory:0, vCores:10> available
2013-08-07 07:16:27,885 INFO org.apache.hadoop.yarn.server.resourcemanager.scheduler.capacity.LeafQueue: assignedContainer application=application_1375859105306_0006 container=Container: [ContainerId: container_1375859105306_0006_01_000040, NodeId: hadoop-200-3:55493, NodeHttpAddress: hadoop-200-3:8042, Resource: <memory:1024, vCores:1>, Priority: 20, State: NEW, Token: null, Status: container_id {, app_attempt_id {, application_id {, id: 6, cluster_timestamp: 1375859105306, }, attemptId: 1, }, id: 40, }, state: C_NEW, ] containerId=container_1375859105306_0006_01_000040 queue=default: capacity=1.0, absoluteCapacity=1.0, usedResources=<memory:48128, vCores:42>usedCapacity=0.9791667, absoluteUsedCapacity=0.9791667, numApps=5, numContainers=42 usedCapacity=0.9791667 absoluteUsedCapacity=0.9791667 used=<memory:48128, vCores:42> cluster=<memory:49152, vCores:96>
2013-08-07 07:16:27,885 INFO org.apache.hadoop.yarn.server.resourcemanager.scheduler.capacity.ParentQueue: Re-sorting queues since queue: root.default stats: default: capacity=1.0, absoluteCapacity=1.0, usedResources=<memory:49152, vCores:43>usedCapacity=1.0, absoluteUsedCapacity=1.0, numApps=5, numContainers=43
2013-08-07 07:16:27,885 INFO org.apache.hadoop.yarn.server.resourcemanager.scheduler.capacity.ParentQueue: assignedContainer queue=root usedCapacity=1.0 absoluteUsedCapacity=1.0 used=<memory:49152, vCores:43> cluster=<memory:49152, vCores:96>
2013-08-07 07:16:27,961 INFO org.apache.hadoop.yarn.server.resourcemanager.rmcontainer.RMContainerImpl: container_1375859105306_0006_01_000040 Container Transitioned from ALLOCATED to ACQUIRED
2013-08-07 07:16:28,812 INFO org.apache.hadoop.yarn.server.resourcemanager.rmcontainer.RMContainerImpl: container_1375859105306_0006_01_000040 Container Transitioned from ACQUIRED to RUNNING
2013-08-07 07:16:28,814 INFO org.apache.hadoop.yarn.server.resourcemanager.rmcontainer.RMContainerImpl: container_1375859105306_0006_01_000009 Container Transitioned from RUNNING to COMPLETED
2013-08-07 07:16:28,814 INFO org.apache.hadoop.yarn.server.resourcemanager.scheduler.common.fica.FiCaSchedulerApp: Completed container: container_1375859105306_0006_01_000009 in state: COMPLETED event:FINISHED
2013-08-07 07:16:28,815 INFO org.apache.hadoop.yarn.server.resourcemanager.RMAuditLogger: USER=ubuntu	OPERATION=AM Released Container	TARGET=SchedulerApp	RESULT=SUCCESS	APPID=application_1375859105306_0006	CONTAINERID=container_1375859105306_0006_01_000009
2013-08-07 07:16:28,815 INFO org.apache.hadoop.yarn.server.resourcemanager.scheduler.common.fica.FiCaSchedulerNode: Released container container_1375859105306_0006_01_000009 of capacity <memory:1024, vCores:1> on host hadoop-200-3:55493, which currently has 5 containers, <memory:7168, vCores:5> used and <memory:1024, vCores:11> available, release resources=true
2013-08-07 07:16:28,815 INFO org.apache.hadoop.yarn.server.resourcemanager.scheduler.capacity.LeafQueue: default used=<memory:48128, vCores:42> numContainers=42 user=ubuntu user-resources=<memory:48128, vCores:42>
2013-08-07 07:16:28,816 INFO org.apache.hadoop.yarn.server.resourcemanager.scheduler.capacity.LeafQueue: completedContainer container=Container: [ContainerId: container_1375859105306_0006_01_000009, NodeId: hadoop-200-3:55493, NodeHttpAddress: hadoop-200-3:8042, Resource: <memory:1024, vCores:1>, Priority: 20, State: NEW, Token: null, Status: container_id {, app_attempt_id {, application_id {, id: 6, cluster_timestamp: 1375859105306, }, attemptId: 1, }, id: 9, }, state: C_COMPLETE, diagnostics: "Container killed by the ApplicationMaster.\n\n", exit_status: 143, ] resource=<memory:1024, vCores:1> queue=default: capacity=1.0, absoluteCapacity=1.0, usedResources=<memory:48128, vCores:42>usedCapacity=0.9791667, absoluteUsedCapacity=0.9791667, numApps=5, numContainers=42 usedCapacity=0.9791667 absoluteUsedCapacity=0.9791667 used=<memory:48128, vCores:42> cluster=<memory:49152, vCores:96>
2013-08-07 07:16:28,817 INFO org.apache.hadoop.yarn.server.resourcemanager.scheduler.capacity.ParentQueue: completedContainer queue=root usedCapacity=0.9791667 absoluteUsedCapacity=0.9791667 used=<memory:48128, vCores:42> cluster=<memory:49152, vCores:96>
2013-08-07 07:16:28,817 INFO org.apache.hadoop.yarn.server.resourcemanager.scheduler.capacity.CapacityScheduler: Application appattempt_1375859105306_0006_000001 released container container_1375859105306_0006_01_000009 on node: host: hadoop-200-3:55493 #containers=5 available=1024 used=7168 with event: FINISHED
2013-08-07 07:16:28,818 INFO org.apache.hadoop.yarn.server.resourcemanager.rmcontainer.RMContainerImpl: container_1375859105306_0006_01_000041 Container Transitioned from NEW to ALLOCATED
2013-08-07 07:16:28,818 INFO org.apache.hadoop.yarn.server.resourcemanager.RMAuditLogger: USER=ubuntu	OPERATION=AM Allocated Container	TARGET=SchedulerApp	RESULT=SUCCESS	APPID=application_1375859105306_0006	CONTAINERID=container_1375859105306_0006_01_000041
2013-08-07 07:16:28,818 INFO org.apache.hadoop.yarn.server.resourcemanager.scheduler.common.fica.FiCaSchedulerNode: Assigned container container_1375859105306_0006_01_000041 of capacity <memory:1024, vCores:1> on host hadoop-200-3:55493, which currently has 6 containers, <memory:8192, vCores:6> used and <memory:0, vCores:10> available
2013-08-07 07:16:28,819 INFO org.apache.hadoop.yarn.server.resourcemanager.scheduler.capacity.LeafQueue: assignedContainer application=application_1375859105306_0006 container=Container: [ContainerId: container_1375859105306_0006_01_000041, NodeId: hadoop-200-3:55493, NodeHttpAddress: hadoop-200-3:8042, Resource: <memory:1024, vCores:1>, Priority: 20, State: NEW, Token: null, Status: container_id {, app_attempt_id {, application_id {, id: 6, cluster_timestamp: 1375859105306, }, attemptId: 1, }, id: 41, }, state: C_NEW, ] containerId=container_1375859105306_0006_01_000041 queue=default: capacity=1.0, absoluteCapacity=1.0, usedResources=<memory:48128, vCores:42>usedCapacity=0.9791667, absoluteUsedCapacity=0.9791667, numApps=5, numContainers=42 usedCapacity=0.9791667 absoluteUsedCapacity=0.9791667 used=<memory:48128, vCores:42> cluster=<memory:49152, vCores:96>
2013-08-07 07:16:28,819 INFO org.apache.hadoop.yarn.server.resourcemanager.scheduler.capacity.ParentQueue: Re-sorting queues since queue: root.default stats: default: capacity=1.0, absoluteCapacity=1.0, usedResources=<memory:49152, vCores:43>usedCapacity=1.0, absoluteUsedCapacity=1.0, numApps=5, numContainers=43
2013-08-07 07:16:28,819 INFO org.apache.hadoop.yarn.server.resourcemanager.scheduler.capacity.ParentQueue: assignedContainer queue=root usedCapacity=1.0 absoluteUsedCapacity=1.0 used=<memory:49152, vCores:43> cluster=<memory:49152, vCores:96>
2013-08-07 07:16:28,973 INFO org.apache.hadoop.yarn.server.resourcemanager.rmcontainer.RMContainerImpl: container_1375859105306_0006_01_000041 Container Transitioned from ALLOCATED to ACQUIRED
2013-08-07 07:16:29,832 INFO org.apache.hadoop.yarn.server.resourcemanager.rmcontainer.RMContainerImpl: container_1375859105306_0006_01_000041 Container Transitioned from ACQUIRED to RUNNING
2013-08-07 07:16:29,832 INFO org.apache.hadoop.yarn.server.resourcemanager.rmcontainer.RMContainerImpl: container_1375859105306_0006_01_000006 Container Transitioned from RUNNING to COMPLETED
2013-08-07 07:16:29,832 INFO org.apache.hadoop.yarn.server.resourcemanager.scheduler.common.fica.FiCaSchedulerApp: Completed container: container_1375859105306_0006_01_000006 in state: COMPLETED event:FINISHED
2013-08-07 07:16:29,833 INFO org.apache.hadoop.yarn.server.resourcemanager.RMAuditLogger: USER=ubuntu	OPERATION=AM Released Container	TARGET=SchedulerApp	RESULT=SUCCESS	APPID=application_1375859105306_0006	CONTAINERID=container_1375859105306_0006_01_000006
2013-08-07 07:16:29,833 INFO org.apache.hadoop.yarn.server.resourcemanager.scheduler.common.fica.FiCaSchedulerNode: Released container container_1375859105306_0006_01_000006 of capacity <memory:1024, vCores:1> on host hadoop-200-3:55493, which currently has 5 containers, <memory:7168, vCores:5> used and <memory:1024, vCores:11> available, release resources=true
2013-08-07 07:16:29,833 INFO org.apache.hadoop.yarn.server.resourcemanager.scheduler.capacity.LeafQueue: default used=<memory:48128, vCores:42> numContainers=42 user=ubuntu user-resources=<memory:48128, vCores:42>
2013-08-07 07:16:29,834 INFO org.apache.hadoop.yarn.server.resourcemanager.scheduler.capacity.LeafQueue: completedContainer container=Container: [ContainerId: container_1375859105306_0006_01_000006, NodeId: hadoop-200-3:55493, NodeHttpAddress: hadoop-200-3:8042, Resource: <memory:1024, vCores:1>, Priority: 20, State: NEW, Token: null, Status: container_id {, app_attempt_id {, application_id {, id: 6, cluster_timestamp: 1375859105306, }, attemptId: 1, }, id: 6, }, state: C_COMPLETE, diagnostics: "Container killed by the ApplicationMaster.\n\n", exit_status: 143, ] resource=<memory:1024, vCores:1> queue=default: capacity=1.0, absoluteCapacity=1.0, usedResources=<memory:48128, vCores:42>usedCapacity=0.9791667, absoluteUsedCapacity=0.9791667, numApps=5, numContainers=42 usedCapacity=0.9791667 absoluteUsedCapacity=0.9791667 used=<memory:48128, vCores:42> cluster=<memory:49152, vCores:96>
2013-08-07 07:16:29,834 INFO org.apache.hadoop.yarn.server.resourcemanager.scheduler.capacity.ParentQueue: completedContainer queue=root usedCapacity=0.9791667 absoluteUsedCapacity=0.9791667 used=<memory:48128, vCores:42> cluster=<memory:49152, vCores:96>
2013-08-07 07:16:29,834 INFO org.apache.hadoop.yarn.server.resourcemanager.scheduler.capacity.CapacityScheduler: Application appattempt_1375859105306_0006_000001 released container container_1375859105306_0006_01_000006 on node: host: hadoop-200-3:55493 #containers=5 available=1024 used=7168 with event: FINISHED
2013-08-07 07:16:29,835 INFO org.apache.hadoop.yarn.server.resourcemanager.rmcontainer.RMContainerImpl: container_1375859105306_0006_01_000042 Container Transitioned from NEW to ALLOCATED
2013-08-07 07:16:29,835 INFO org.apache.hadoop.yarn.server.resourcemanager.RMAuditLogger: USER=ubuntu	OPERATION=AM Allocated Container	TARGET=SchedulerApp	RESULT=SUCCESS	APPID=application_1375859105306_0006	CONTAINERID=container_1375859105306_0006_01_000042
2013-08-07 07:16:29,835 INFO org.apache.hadoop.yarn.server.resourcemanager.scheduler.common.fica.FiCaSchedulerNode: Assigned container container_1375859105306_0006_01_000042 of capacity <memory:1024, vCores:1> on host hadoop-200-3:55493, which currently has 6 containers, <memory:8192, vCores:6> used and <memory:0, vCores:10> available
2013-08-07 07:16:29,836 INFO org.apache.hadoop.yarn.server.resourcemanager.scheduler.capacity.LeafQueue: assignedContainer application=application_1375859105306_0006 container=Container: [ContainerId: container_1375859105306_0006_01_000042, NodeId: hadoop-200-3:55493, NodeHttpAddress: hadoop-200-3:8042, Resource: <memory:1024, vCores:1>, Priority: 10, State: NEW, Token: null, Status: container_id {, app_attempt_id {, application_id {, id: 6, cluster_timestamp: 1375859105306, }, attemptId: 1, }, id: 42, }, state: C_NEW, ] containerId=container_1375859105306_0006_01_000042 queue=default: capacity=1.0, absoluteCapacity=1.0, usedResources=<memory:48128, vCores:42>usedCapacity=0.9791667, absoluteUsedCapacity=0.9791667, numApps=5, numContainers=42 usedCapacity=0.9791667 absoluteUsedCapacity=0.9791667 used=<memory:48128, vCores:42> cluster=<memory:49152, vCores:96>
2013-08-07 07:16:29,837 INFO org.apache.hadoop.yarn.server.resourcemanager.scheduler.capacity.ParentQueue: Re-sorting queues since queue: root.default stats: default: capacity=1.0, absoluteCapacity=1.0, usedResources=<memory:49152, vCores:43>usedCapacity=1.0, absoluteUsedCapacity=1.0, numApps=5, numContainers=43
2013-08-07 07:16:29,837 INFO org.apache.hadoop.yarn.server.resourcemanager.scheduler.capacity.ParentQueue: assignedContainer queue=root usedCapacity=1.0 absoluteUsedCapacity=1.0 used=<memory:49152, vCores:43> cluster=<memory:49152, vCores:96>
2013-08-07 07:16:29,980 INFO org.apache.hadoop.yarn.server.resourcemanager.rmcontainer.RMContainerImpl: container_1375859105306_0006_01_000042 Container Transitioned from ALLOCATED to ACQUIRED
2013-08-07 07:16:30,844 INFO org.apache.hadoop.yarn.server.resourcemanager.rmcontainer.RMContainerImpl: container_1375859105306_0006_01_000042 Container Transitioned from ACQUIRED to RUNNING
2013-08-07 07:16:33,287 INFO org.apache.hadoop.yarn.server.resourcemanager.rmcontainer.RMContainerImpl: container_1375859105306_0006_01_000002 Container Transitioned from RUNNING to COMPLETED
2013-08-07 07:16:33,287 INFO org.apache.hadoop.yarn.server.resourcemanager.scheduler.common.fica.FiCaSchedulerApp: Completed container: container_1375859105306_0006_01_000002 in state: COMPLETED event:FINISHED
2013-08-07 07:16:33,288 INFO org.apache.hadoop.yarn.server.resourcemanager.RMAuditLogger: USER=ubuntu	OPERATION=AM Released Container	TARGET=SchedulerApp	RESULT=SUCCESS	APPID=application_1375859105306_0006	CONTAINERID=container_1375859105306_0006_01_000002
2013-08-07 07:16:33,288 INFO org.apache.hadoop.yarn.server.resourcemanager.scheduler.common.fica.FiCaSchedulerNode: Released container container_1375859105306_0006_01_000002 of capacity <memory:1024, vCores:1> on host hadoop-200-2:35087, which currently has 5 containers, <memory:7168, vCores:5> used and <memory:1024, vCores:11> available, release resources=true
2013-08-07 07:16:33,288 INFO org.apache.hadoop.yarn.server.resourcemanager.scheduler.capacity.LeafQueue: default used=<memory:48128, vCores:42> numContainers=42 user=ubuntu user-resources=<memory:48128, vCores:42>
2013-08-07 07:16:33,289 INFO org.apache.hadoop.yarn.server.resourcemanager.scheduler.capacity.LeafQueue: completedContainer container=Container: [ContainerId: container_1375859105306_0006_01_000002, NodeId: hadoop-200-2:35087, NodeHttpAddress: hadoop-200-2:8042, Resource: <memory:1024, vCores:1>, Priority: 20, State: NEW, Token: null, Status: container_id {, app_attempt_id {, application_id {, id: 6, cluster_timestamp: 1375859105306, }, attemptId: 1, }, id: 2, }, state: C_COMPLETE, diagnostics: "Container killed by the ApplicationMaster.\n", exit_status: 0, ] resource=<memory:1024, vCores:1> queue=default: capacity=1.0, absoluteCapacity=1.0, usedResources=<memory:48128, vCores:42>usedCapacity=0.9791667, absoluteUsedCapacity=0.9791667, numApps=5, numContainers=42 usedCapacity=0.9791667 absoluteUsedCapacity=0.9791667 used=<memory:48128, vCores:42> cluster=<memory:49152, vCores:96>
2013-08-07 07:16:33,289 INFO org.apache.hadoop.yarn.server.resourcemanager.scheduler.capacity.ParentQueue: completedContainer queue=root usedCapacity=0.9791667 absoluteUsedCapacity=0.9791667 used=<memory:48128, vCores:42> cluster=<memory:49152, vCores:96>
2013-08-07 07:16:33,290 INFO org.apache.hadoop.yarn.server.resourcemanager.scheduler.capacity.CapacityScheduler: Application appattempt_1375859105306_0006_000001 released container container_1375859105306_0006_01_000002 on node: host: hadoop-200-2:35087 #containers=5 available=1024 used=7168 with event: FINISHED
2013-08-07 07:16:33,290 INFO org.apache.hadoop.yarn.server.resourcemanager.rmcontainer.RMContainerImpl: container_1375859105306_0006_01_000003 Container Transitioned from RUNNING to COMPLETED
2013-08-07 07:16:33,290 INFO org.apache.hadoop.yarn.server.resourcemanager.scheduler.common.fica.FiCaSchedulerApp: Completed container: container_1375859105306_0006_01_000003 in state: COMPLETED event:FINISHED
2013-08-07 07:16:33,290 INFO org.apache.hadoop.yarn.server.resourcemanager.RMAuditLogger: USER=ubuntu	OPERATION=AM Released Container	TARGET=SchedulerApp	RESULT=SUCCESS	APPID=application_1375859105306_0006	CONTAINERID=container_1375859105306_0006_01_000003
2013-08-07 07:16:33,290 INFO org.apache.hadoop.yarn.server.resourcemanager.scheduler.common.fica.FiCaSchedulerNode: Released container container_1375859105306_0006_01_000003 of capacity <memory:1024, vCores:1> on host hadoop-200-2:35087, which currently has 4 containers, <memory:6144, vCores:4> used and <memory:2048, vCores:12> available, release resources=true
2013-08-07 07:16:33,290 INFO org.apache.hadoop.yarn.server.resourcemanager.scheduler.capacity.LeafQueue: default used=<memory:47104, vCores:41> numContainers=41 user=ubuntu user-resources=<memory:47104, vCores:41>
2013-08-07 07:16:33,291 INFO org.apache.hadoop.yarn.server.resourcemanager.scheduler.capacity.LeafQueue: completedContainer container=Container: [ContainerId: container_1375859105306_0006_01_000003, NodeId: hadoop-200-2:35087, NodeHttpAddress: hadoop-200-2:8042, Resource: <memory:1024, vCores:1>, Priority: 20, State: NEW, Token: null, Status: container_id {, app_attempt_id {, application_id {, id: 6, cluster_timestamp: 1375859105306, }, attemptId: 1, }, id: 3, }, state: C_COMPLETE, diagnostics: "Container killed by the ApplicationMaster.\n\n", exit_status: 143, ] resource=<memory:1024, vCores:1> queue=default: capacity=1.0, absoluteCapacity=1.0, usedResources=<memory:47104, vCores:41>usedCapacity=0.9583333, absoluteUsedCapacity=0.9583333, numApps=5, numContainers=41 usedCapacity=0.9583333 absoluteUsedCapacity=0.9583333 used=<memory:47104, vCores:41> cluster=<memory:49152, vCores:96>
2013-08-07 07:16:33,292 INFO org.apache.hadoop.yarn.server.resourcemanager.scheduler.capacity.ParentQueue: completedContainer queue=root usedCapacity=0.9583333 absoluteUsedCapacity=0.9583333 used=<memory:47104, vCores:41> cluster=<memory:49152, vCores:96>
2013-08-07 07:16:33,292 INFO org.apache.hadoop.yarn.server.resourcemanager.scheduler.capacity.CapacityScheduler: Application appattempt_1375859105306_0006_000001 released container container_1375859105306_0006_01_000003 on node: host: hadoop-200-2:35087 #containers=4 available=2048 used=6144 with event: FINISHED
2013-08-07 07:16:33,292 INFO org.apache.hadoop.yarn.server.resourcemanager.rmcontainer.RMContainerImpl: container_1375859105306_0006_01_000043 Container Transitioned from NEW to ALLOCATED
2013-08-07 07:16:33,292 INFO org.apache.hadoop.yarn.server.resourcemanager.RMAuditLogger: USER=ubuntu	OPERATION=AM Allocated Container	TARGET=SchedulerApp	RESULT=SUCCESS	APPID=application_1375859105306_0006	CONTAINERID=container_1375859105306_0006_01_000043
2013-08-07 07:16:33,293 INFO org.apache.hadoop.yarn.server.resourcemanager.scheduler.common.fica.FiCaSchedulerNode: Assigned container container_1375859105306_0006_01_000043 of capacity <memory:1024, vCores:1> on host hadoop-200-2:35087, which currently has 5 containers, <memory:7168, vCores:5> used and <memory:1024, vCores:11> available
2013-08-07 07:16:33,294 INFO org.apache.hadoop.yarn.server.resourcemanager.scheduler.capacity.LeafQueue: assignedContainer application=application_1375859105306_0006 container=Container: [ContainerId: container_1375859105306_0006_01_000043, NodeId: hadoop-200-2:35087, NodeHttpAddress: hadoop-200-2:8042, Resource: <memory:1024, vCores:1>, Priority: 10, State: NEW, Token: null, Status: container_id {, app_attempt_id {, application_id {, id: 6, cluster_timestamp: 1375859105306, }, attemptId: 1, }, id: 43, }, state: C_NEW, ] containerId=container_1375859105306_0006_01_000043 queue=default: capacity=1.0, absoluteCapacity=1.0, usedResources=<memory:47104, vCores:41>usedCapacity=0.9583333, absoluteUsedCapacity=0.9583333, numApps=5, numContainers=41 usedCapacity=0.9583333 absoluteUsedCapacity=0.9583333 used=<memory:47104, vCores:41> cluster=<memory:49152, vCores:96>
2013-08-07 07:16:33,294 INFO org.apache.hadoop.yarn.server.resourcemanager.scheduler.capacity.ParentQueue: Re-sorting queues since queue: root.default stats: default: capacity=1.0, absoluteCapacity=1.0, usedResources=<memory:48128, vCores:42>usedCapacity=0.9791667, absoluteUsedCapacity=0.9791667, numApps=5, numContainers=42
2013-08-07 07:16:33,294 INFO org.apache.hadoop.yarn.server.resourcemanager.scheduler.capacity.ParentQueue: assignedContainer queue=root usedCapacity=0.9791667 absoluteUsedCapacity=0.9791667 used=<memory:48128, vCores:42> cluster=<memory:49152, vCores:96>
2013-08-07 07:16:33,313 INFO org.apache.hadoop.yarn.server.resourcemanager.rmcontainer.RMContainerImpl: container_1375859105306_0006_01_000044 Container Transitioned from NEW to ALLOCATED
2013-08-07 07:16:33,313 INFO org.apache.hadoop.yarn.server.resourcemanager.RMAuditLogger: USER=ubuntu	OPERATION=AM Allocated Container	TARGET=SchedulerApp	RESULT=SUCCESS	APPID=application_1375859105306_0006	CONTAINERID=container_1375859105306_0006_01_000044
2013-08-07 07:16:33,313 INFO org.apache.hadoop.yarn.server.resourcemanager.scheduler.common.fica.FiCaSchedulerNode: Assigned container container_1375859105306_0006_01_000044 of capacity <memory:1024, vCores:1> on host hadoop-200-2:35087, which currently has 6 containers, <memory:8192, vCores:6> used and <memory:0, vCores:10> available
2013-08-07 07:16:33,314 INFO org.apache.hadoop.yarn.server.resourcemanager.scheduler.capacity.LeafQueue: assignedContainer application=application_1375859105306_0006 container=Container: [ContainerId: container_1375859105306_0006_01_000044, NodeId: hadoop-200-2:35087, NodeHttpAddress: hadoop-200-2:8042, Resource: <memory:1024, vCores:1>, Priority: 10, State: NEW, Token: null, Status: container_id {, app_attempt_id {, application_id {, id: 6, cluster_timestamp: 1375859105306, }, attemptId: 1, }, id: 44, }, state: C_NEW, ] containerId=container_1375859105306_0006_01_000044 queue=default: capacity=1.0, absoluteCapacity=1.0, usedResources=<memory:48128, vCores:42>usedCapacity=0.9791667, absoluteUsedCapacity=0.9791667, numApps=5, numContainers=42 usedCapacity=0.9791667 absoluteUsedCapacity=0.9791667 used=<memory:48128, vCores:42> cluster=<memory:49152, vCores:96>
2013-08-07 07:16:33,314 INFO org.apache.hadoop.yarn.server.resourcemanager.scheduler.capacity.ParentQueue: Re-sorting queues since queue: root.default stats: default: capacity=1.0, absoluteCapacity=1.0, usedResources=<memory:49152, vCores:43>usedCapacity=1.0, absoluteUsedCapacity=1.0, numApps=5, numContainers=43
2013-08-07 07:16:33,314 INFO org.apache.hadoop.yarn.server.resourcemanager.scheduler.capacity.ParentQueue: assignedContainer queue=root usedCapacity=1.0 absoluteUsedCapacity=1.0 used=<memory:49152, vCores:43> cluster=<memory:49152, vCores:96>
2013-08-07 07:16:33,348 INFO org.apache.hadoop.yarn.server.resourcemanager.rmcontainer.RMContainerImpl: container_1375859105306_0006_01_000008 Container Transitioned from RUNNING to COMPLETED
2013-08-07 07:16:33,349 INFO org.apache.hadoop.yarn.server.resourcemanager.scheduler.common.fica.FiCaSchedulerApp: Completed container: container_1375859105306_0006_01_000008 in state: COMPLETED event:FINISHED
2013-08-07 07:16:33,349 INFO org.apache.hadoop.yarn.server.resourcemanager.RMAuditLogger: USER=ubuntu	OPERATION=AM Released Container	TARGET=SchedulerApp	RESULT=SUCCESS	APPID=application_1375859105306_0006	CONTAINERID=container_1375859105306_0006_01_000008
2013-08-07 07:16:33,349 INFO org.apache.hadoop.yarn.server.resourcemanager.scheduler.common.fica.FiCaSchedulerNode: Released container container_1375859105306_0006_01_000008 of capacity <memory:1024, vCores:1> on host hadoop-200-3:55493, which currently has 5 containers, <memory:7168, vCores:5> used and <memory:1024, vCores:11> available, release resources=true
2013-08-07 07:16:33,349 INFO org.apache.hadoop.yarn.server.resourcemanager.scheduler.capacity.LeafQueue: default used=<memory:48128, vCores:42> numContainers=42 user=ubuntu user-resources=<memory:48128, vCores:42>
2013-08-07 07:16:33,350 INFO org.apache.hadoop.yarn.server.resourcemanager.scheduler.capacity.LeafQueue: completedContainer container=Container: [ContainerId: container_1375859105306_0006_01_000008, NodeId: hadoop-200-3:55493, NodeHttpAddress: hadoop-200-3:8042, Resource: <memory:1024, vCores:1>, Priority: 20, State: NEW, Token: null, Status: container_id {, app_attempt_id {, application_id {, id: 6, cluster_timestamp: 1375859105306, }, attemptId: 1, }, id: 8, }, state: C_COMPLETE, diagnostics: "Container killed by the ApplicationMaster.\n\n", exit_status: 143, ] resource=<memory:1024, vCores:1> queue=default: capacity=1.0, absoluteCapacity=1.0, usedResources=<memory:48128, vCores:42>usedCapacity=0.9791667, absoluteUsedCapacity=0.9791667, numApps=5, numContainers=42 usedCapacity=0.9791667 absoluteUsedCapacity=0.9791667 used=<memory:48128, vCores:42> cluster=<memory:49152, vCores:96>
2013-08-07 07:16:33,350 INFO org.apache.hadoop.yarn.server.resourcemanager.scheduler.capacity.ParentQueue: completedContainer queue=root usedCapacity=0.9791667 absoluteUsedCapacity=0.9791667 used=<memory:48128, vCores:42> cluster=<memory:49152, vCores:96>
2013-08-07 07:16:33,350 INFO org.apache.hadoop.yarn.server.resourcemanager.scheduler.capacity.CapacityScheduler: Application appattempt_1375859105306_0006_000001 released container container_1375859105306_0006_01_000008 on node: host: hadoop-200-3:55493 #containers=5 available=1024 used=7168 with event: FINISHED
2013-08-07 07:16:33,351 INFO org.apache.hadoop.yarn.server.resourcemanager.rmcontainer.RMContainerImpl: container_1375859105306_0006_01_000045 Container Transitioned from NEW to ALLOCATED
2013-08-07 07:16:33,351 INFO org.apache.hadoop.yarn.server.resourcemanager.RMAuditLogger: USER=ubuntu	OPERATION=AM Allocated Container	TARGET=SchedulerApp	RESULT=SUCCESS	APPID=application_1375859105306_0006	CONTAINERID=container_1375859105306_0006_01_000045
2013-08-07 07:16:33,351 INFO org.apache.hadoop.yarn.server.resourcemanager.scheduler.common.fica.FiCaSchedulerNode: Assigned container container_1375859105306_0006_01_000045 of capacity <memory:1024, vCores:1> on host hadoop-200-3:55493, which currently has 6 containers, <memory:8192, vCores:6> used and <memory:0, vCores:10> available
2013-08-07 07:16:33,355 INFO org.apache.hadoop.yarn.server.resourcemanager.scheduler.capacity.LeafQueue: assignedContainer application=application_1375859105306_0006 container=Container: [ContainerId: container_1375859105306_0006_01_000045, NodeId: hadoop-200-3:55493, NodeHttpAddress: hadoop-200-3:8042, Resource: <memory:1024, vCores:1>, Priority: 10, State: NEW, Token: null, Status: container_id {, app_attempt_id {, application_id {, id: 6, cluster_timestamp: 1375859105306, }, attemptId: 1, }, id: 45, }, state: C_NEW, ] containerId=container_1375859105306_0006_01_000045 queue=default: capacity=1.0, absoluteCapacity=1.0, usedResources=<memory:48128, vCores:42>usedCapacity=0.9791667, absoluteUsedCapacity=0.9791667, numApps=5, numContainers=42 usedCapacity=0.9791667 absoluteUsedCapacity=0.9791667 used=<memory:48128, vCores:42> cluster=<memory:49152, vCores:96>
2013-08-07 07:16:33,355 INFO org.apache.hadoop.yarn.server.resourcemanager.scheduler.capacity.ParentQueue: Re-sorting queues since queue: root.default stats: default: capacity=1.0, absoluteCapacity=1.0, usedResources=<memory:49152, vCores:43>usedCapacity=1.0, absoluteUsedCapacity=1.0, numApps=5, numContainers=43
2013-08-07 07:16:33,356 INFO org.apache.hadoop.yarn.server.resourcemanager.scheduler.capacity.ParentQueue: assignedContainer queue=root usedCapacity=1.0 absoluteUsedCapacity=1.0 used=<memory:49152, vCores:43> cluster=<memory:49152, vCores:96>
2013-08-07 07:16:33,996 INFO org.apache.hadoop.yarn.server.resourcemanager.rmcontainer.RMContainerImpl: container_1375859105306_0006_01_000043 Container Transitioned from ALLOCATED to ACQUIRED
2013-08-07 07:16:33,997 INFO org.apache.hadoop.yarn.server.resourcemanager.rmcontainer.RMContainerImpl: container_1375859105306_0006_01_000044 Container Transitioned from ALLOCATED to ACQUIRED
2013-08-07 07:16:33,997 INFO org.apache.hadoop.yarn.server.resourcemanager.rmcontainer.RMContainerImpl: container_1375859105306_0006_01_000045 Container Transitioned from ALLOCATED to ACQUIRED
2013-08-07 07:16:34,332 INFO org.apache.hadoop.yarn.server.resourcemanager.rmcontainer.RMContainerImpl: container_1375859105306_0006_01_000043 Container Transitioned from ACQUIRED to RUNNING
2013-08-07 07:16:34,333 INFO org.apache.hadoop.yarn.server.resourcemanager.rmcontainer.RMContainerImpl: container_1375859105306_0006_01_000044 Container Transitioned from ACQUIRED to RUNNING
2013-08-07 07:16:34,333 INFO org.apache.hadoop.yarn.server.resourcemanager.rmcontainer.RMContainerImpl: container_1375859105306_0006_01_000004 Container Transitioned from RUNNING to COMPLETED
2013-08-07 07:16:34,333 INFO org.apache.hadoop.yarn.server.resourcemanager.scheduler.common.fica.FiCaSchedulerApp: Completed container: container_1375859105306_0006_01_000004 in state: COMPLETED event:FINISHED
2013-08-07 07:16:34,333 INFO org.apache.hadoop.yarn.server.resourcemanager.RMAuditLogger: USER=ubuntu	OPERATION=AM Released Container	TARGET=SchedulerApp	RESULT=SUCCESS	APPID=application_1375859105306_0006	CONTAINERID=container_1375859105306_0006_01_000004
2013-08-07 07:16:34,334 INFO org.apache.hadoop.yarn.server.resourcemanager.scheduler.common.fica.FiCaSchedulerNode: Released container container_1375859105306_0006_01_000004 of capacity <memory:1024, vCores:1> on host hadoop-200-2:35087, which currently has 5 containers, <memory:7168, vCores:5> used and <memory:1024, vCores:11> available, release resources=true
2013-08-07 07:16:34,334 INFO org.apache.hadoop.yarn.server.resourcemanager.scheduler.capacity.LeafQueue: default used=<memory:48128, vCores:42> numContainers=42 user=ubuntu user-resources=<memory:48128, vCores:42>
2013-08-07 07:16:34,335 INFO org.apache.hadoop.yarn.server.resourcemanager.scheduler.capacity.LeafQueue: completedContainer container=Container: [ContainerId: container_1375859105306_0006_01_000004, NodeId: hadoop-200-2:35087, NodeHttpAddress: hadoop-200-2:8042, Resource: <memory:1024, vCores:1>, Priority: 20, State: NEW, Token: null, Status: container_id {, app_attempt_id {, application_id {, id: 6, cluster_timestamp: 1375859105306, }, attemptId: 1, }, id: 4, }, state: C_COMPLETE, diagnostics: "Container killed by the ApplicationMaster.\n\n", exit_status: 143, ] resource=<memory:1024, vCores:1> queue=default: capacity=1.0, absoluteCapacity=1.0, usedResources=<memory:48128, vCores:42>usedCapacity=0.9791667, absoluteUsedCapacity=0.9791667, numApps=5, numContainers=42 usedCapacity=0.9791667 absoluteUsedCapacity=0.9791667 used=<memory:48128, vCores:42> cluster=<memory:49152, vCores:96>
2013-08-07 07:16:34,335 INFO org.apache.hadoop.yarn.server.resourcemanager.scheduler.capacity.ParentQueue: completedContainer queue=root usedCapacity=0.9791667 absoluteUsedCapacity=0.9791667 used=<memory:48128, vCores:42> cluster=<memory:49152, vCores:96>
2013-08-07 07:16:34,335 INFO org.apache.hadoop.yarn.server.resourcemanager.scheduler.capacity.CapacityScheduler: Application appattempt_1375859105306_0006_000001 released container container_1375859105306_0006_01_000004 on node: host: hadoop-200-2:35087 #containers=5 available=1024 used=7168 with event: FINISHED
2013-08-07 07:16:34,336 INFO org.apache.hadoop.yarn.server.resourcemanager.rmcontainer.RMContainerImpl: container_1375859105306_0006_01_000005 Container Transitioned from RUNNING to COMPLETED
2013-08-07 07:16:34,336 INFO org.apache.hadoop.yarn.server.resourcemanager.scheduler.common.fica.FiCaSchedulerApp: Completed container: container_1375859105306_0006_01_000005 in state: COMPLETED event:FINISHED
2013-08-07 07:16:34,336 INFO org.apache.hadoop.yarn.server.resourcemanager.RMAuditLogger: USER=ubuntu	OPERATION=AM Released Container	TARGET=SchedulerApp	RESULT=SUCCESS	APPID=application_1375859105306_0006	CONTAINERID=container_1375859105306_0006_01_000005
2013-08-07 07:16:34,336 INFO org.apache.hadoop.yarn.server.resourcemanager.scheduler.common.fica.FiCaSchedulerNode: Released container container_1375859105306_0006_01_000005 of capacity <memory:1024, vCores:1> on host hadoop-200-2:35087, which currently has 4 containers, <memory:6144, vCores:4> used and <memory:2048, vCores:12> available, release resources=true
2013-08-07 07:16:34,336 INFO org.apache.hadoop.yarn.server.resourcemanager.scheduler.capacity.LeafQueue: default used=<memory:47104, vCores:41> numContainers=41 user=ubuntu user-resources=<memory:47104, vCores:41>
2013-08-07 07:16:34,337 INFO org.apache.hadoop.yarn.server.resourcemanager.scheduler.capacity.LeafQueue: completedContainer container=Container: [ContainerId: container_1375859105306_0006_01_000005, NodeId: hadoop-200-2:35087, NodeHttpAddress: hadoop-200-2:8042, Resource: <memory:1024, vCores:1>, Priority: 20, State: NEW, Token: null, Status: container_id {, app_attempt_id {, application_id {, id: 6, cluster_timestamp: 1375859105306, }, attemptId: 1, }, id: 5, }, state: C_COMPLETE, diagnostics: "Container killed by the ApplicationMaster.\n\n", exit_status: 143, ] resource=<memory:1024, vCores:1> queue=default: capacity=1.0, absoluteCapacity=1.0, usedResources=<memory:47104, vCores:41>usedCapacity=0.9583333, absoluteUsedCapacity=0.9583333, numApps=5, numContainers=41 usedCapacity=0.9583333 absoluteUsedCapacity=0.9583333 used=<memory:47104, vCores:41> cluster=<memory:49152, vCores:96>
2013-08-07 07:16:34,337 INFO org.apache.hadoop.yarn.server.resourcemanager.scheduler.capacity.ParentQueue: completedContainer queue=root usedCapacity=0.9583333 absoluteUsedCapacity=0.9583333 used=<memory:47104, vCores:41> cluster=<memory:49152, vCores:96>
2013-08-07 07:16:34,338 INFO org.apache.hadoop.yarn.server.resourcemanager.scheduler.capacity.CapacityScheduler: Application appattempt_1375859105306_0006_000001 released container container_1375859105306_0006_01_000005 on node: host: hadoop-200-2:35087 #containers=4 available=2048 used=6144 with event: FINISHED
2013-08-07 07:16:34,338 INFO org.apache.hadoop.yarn.server.resourcemanager.rmcontainer.RMContainerImpl: container_1375859105306_0006_01_000046 Container Transitioned from NEW to ALLOCATED
2013-08-07 07:16:34,338 INFO org.apache.hadoop.yarn.server.resourcemanager.RMAuditLogger: USER=ubuntu	OPERATION=AM Allocated Container	TARGET=SchedulerApp	RESULT=SUCCESS	APPID=application_1375859105306_0006	CONTAINERID=container_1375859105306_0006_01_000046
2013-08-07 07:16:34,339 INFO org.apache.hadoop.yarn.server.resourcemanager.scheduler.common.fica.FiCaSchedulerNode: Assigned container container_1375859105306_0006_01_000046 of capacity <memory:1024, vCores:1> on host hadoop-200-2:35087, which currently has 5 containers, <memory:7168, vCores:5> used and <memory:1024, vCores:11> available
2013-08-07 07:16:34,339 INFO org.apache.hadoop.yarn.server.resourcemanager.scheduler.capacity.LeafQueue: assignedContainer application=application_1375859105306_0006 container=Container: [ContainerId: container_1375859105306_0006_01_000046, NodeId: hadoop-200-2:35087, NodeHttpAddress: hadoop-200-2:8042, Resource: <memory:1024, vCores:1>, Priority: 10, State: NEW, Token: null, Status: container_id {, app_attempt_id {, application_id {, id: 6, cluster_timestamp: 1375859105306, }, attemptId: 1, }, id: 46, }, state: C_NEW, ] containerId=container_1375859105306_0006_01_000046 queue=default: capacity=1.0, absoluteCapacity=1.0, usedResources=<memory:47104, vCores:41>usedCapacity=0.9583333, absoluteUsedCapacity=0.9583333, numApps=5, numContainers=41 usedCapacity=0.9583333 absoluteUsedCapacity=0.9583333 used=<memory:47104, vCores:41> cluster=<memory:49152, vCores:96>
2013-08-07 07:16:34,340 INFO org.apache.hadoop.yarn.server.resourcemanager.scheduler.capacity.ParentQueue: Re-sorting queues since queue: root.default stats: default: capacity=1.0, absoluteCapacity=1.0, usedResources=<memory:48128, vCores:42>usedCapacity=0.9791667, absoluteUsedCapacity=0.9791667, numApps=5, numContainers=42
2013-08-07 07:16:34,340 INFO org.apache.hadoop.yarn.server.resourcemanager.scheduler.capacity.ParentQueue: assignedContainer queue=root usedCapacity=0.9791667 absoluteUsedCapacity=0.9791667 used=<memory:48128, vCores:42> cluster=<memory:49152, vCores:96>
2013-08-07 07:16:34,356 INFO org.apache.hadoop.yarn.server.resourcemanager.rmcontainer.RMContainerImpl: container_1375859105306_0006_01_000045 Container Transitioned from ACQUIRED to RUNNING
2013-08-07 07:16:35,007 INFO org.apache.hadoop.yarn.server.resourcemanager.rmcontainer.RMContainerImpl: container_1375859105306_0006_01_000046 Container Transitioned from ALLOCATED to ACQUIRED
2013-08-07 07:16:35,338 INFO org.apache.hadoop.yarn.server.resourcemanager.rmcontainer.RMContainerImpl: container_1375859105306_0006_01_000046 Container Transitioned from ACQUIRED to RUNNING
2013-08-07 07:16:35,339 INFO org.apache.hadoop.yarn.server.resourcemanager.rmcontainer.RMContainerImpl: container_1375859105306_0006_01_000047 Container Transitioned from NEW to ALLOCATED
2013-08-07 07:16:35,339 INFO org.apache.hadoop.yarn.server.resourcemanager.RMAuditLogger: USER=ubuntu	OPERATION=AM Allocated Container	TARGET=SchedulerApp	RESULT=SUCCESS	APPID=application_1375859105306_0006	CONTAINERID=container_1375859105306_0006_01_000047
2013-08-07 07:16:35,339 INFO org.apache.hadoop.yarn.server.resourcemanager.scheduler.common.fica.FiCaSchedulerNode: Assigned container container_1375859105306_0006_01_000047 of capacity <memory:1024, vCores:1> on host hadoop-200-2:35087, which currently has 6 containers, <memory:8192, vCores:6> used and <memory:0, vCores:10> available
2013-08-07 07:16:35,340 INFO org.apache.hadoop.yarn.server.resourcemanager.scheduler.capacity.LeafQueue: assignedContainer application=application_1375859105306_0006 container=Container: [ContainerId: container_1375859105306_0006_01_000047, NodeId: hadoop-200-2:35087, NodeHttpAddress: hadoop-200-2:8042, Resource: <memory:1024, vCores:1>, Priority: 10, State: NEW, Token: null, Status: container_id {, app_attempt_id {, application_id {, id: 6, cluster_timestamp: 1375859105306, }, attemptId: 1, }, id: 47, }, state: C_NEW, ] containerId=container_1375859105306_0006_01_000047 queue=default: capacity=1.0, absoluteCapacity=1.0, usedResources=<memory:48128, vCores:42>usedCapacity=0.9791667, absoluteUsedCapacity=0.9791667, numApps=5, numContainers=42 usedCapacity=0.9791667 absoluteUsedCapacity=0.9791667 used=<memory:48128, vCores:42> cluster=<memory:49152, vCores:96>
2013-08-07 07:16:35,341 INFO org.apache.hadoop.yarn.server.resourcemanager.scheduler.capacity.ParentQueue: Re-sorting queues since queue: root.default stats: default: capacity=1.0, absoluteCapacity=1.0, usedResources=<memory:49152, vCores:43>usedCapacity=1.0, absoluteUsedCapacity=1.0, numApps=5, numContainers=43
2013-08-07 07:16:35,341 INFO org.apache.hadoop.yarn.server.resourcemanager.scheduler.capacity.ParentQueue: assignedContainer queue=root usedCapacity=1.0 absoluteUsedCapacity=1.0 used=<memory:49152, vCores:43> cluster=<memory:49152, vCores:96>
2013-08-07 07:16:36,016 INFO org.apache.hadoop.yarn.server.resourcemanager.scheduler.AppSchedulingInfo: checking for deactivate... 
2013-08-07 07:16:36,017 INFO org.apache.hadoop.yarn.server.resourcemanager.rmcontainer.RMContainerImpl: container_1375859105306_0006_01_000047 Container Transitioned from ALLOCATED to ACQUIRED
2013-08-07 07:16:37,425 INFO org.apache.hadoop.yarn.server.resourcemanager.rmcontainer.RMContainerImpl: container_1375859105306_0006_01_000047 Container Transitioned from ACQUIRED to RELEASED
2013-08-07 07:16:37,425 INFO org.apache.hadoop.yarn.server.resourcemanager.scheduler.common.fica.FiCaSchedulerApp: Completed container: container_1375859105306_0006_01_000047 in state: RELEASED event:RELEASED
2013-08-07 07:16:37,426 INFO org.apache.hadoop.yarn.server.resourcemanager.RMAuditLogger: USER=ubuntu	IP=192.168.100.4	OPERATION=AM Released Container	TARGET=SchedulerApp	RESULT=SUCCESS	APPID=application_1375859105306_0006	CONTAINERID=container_1375859105306_0006_01_000047
2013-08-07 07:16:37,427 INFO org.apache.hadoop.yarn.server.resourcemanager.scheduler.common.fica.FiCaSchedulerNode: Released container container_1375859105306_0006_01_000047 of capacity <memory:1024, vCores:1> on host hadoop-200-2:35087, which currently has 5 containers, <memory:7168, vCores:5> used and <memory:1024, vCores:11> available, release resources=true
2013-08-07 07:16:37,427 INFO org.apache.hadoop.yarn.server.resourcemanager.scheduler.capacity.LeafQueue: default used=<memory:48128, vCores:42> numContainers=42 user=ubuntu user-resources=<memory:48128, vCores:42>
2013-08-07 07:16:37,429 INFO org.apache.hadoop.yarn.server.resourcemanager.scheduler.capacity.LeafQueue: completedContainer container=Container: [ContainerId: container_1375859105306_0006_01_000047, NodeId: hadoop-200-2:35087, NodeHttpAddress: hadoop-200-2:8042, Resource: <memory:1024, vCores:1>, Priority: 10, State: NEW, Token: null, Status: container_id {, app_attempt_id {, application_id {, id: 6, cluster_timestamp: 1375859105306, }, attemptId: 1, }, id: 47, }, state: C_COMPLETE, diagnostics: "Container released by application", exit_status: -100, ] resource=<memory:1024, vCores:1> queue=default: capacity=1.0, absoluteCapacity=1.0, usedResources=<memory:48128, vCores:42>usedCapacity=0.9791667, absoluteUsedCapacity=0.9791667, numApps=5, numContainers=42 usedCapacity=0.9791667 absoluteUsedCapacity=0.9791667 used=<memory:48128, vCores:42> cluster=<memory:49152, vCores:96>
2013-08-07 07:16:37,429 INFO org.apache.hadoop.yarn.server.resourcemanager.scheduler.capacity.ParentQueue: completedContainer queue=root usedCapacity=0.9791667 absoluteUsedCapacity=0.9791667 used=<memory:48128, vCores:42> cluster=<memory:49152, vCores:96>
2013-08-07 07:16:37,429 INFO org.apache.hadoop.yarn.server.resourcemanager.scheduler.capacity.CapacityScheduler: Application appattempt_1375859105306_0006_000001 released container container_1375859105306_0006_01_000047 on node: host: hadoop-200-2:35087 #containers=5 available=1024 used=7168 with event: RELEASED
2013-08-07 07:16:37,808 INFO org.apache.hadoop.yarn.server.resourcemanager.rmcontainer.RMContainerImpl: container_1375859105306_0006_01_000033 Container Transitioned from RUNNING to COMPLETED
2013-08-07 07:16:37,809 INFO org.apache.hadoop.yarn.server.resourcemanager.scheduler.common.fica.FiCaSchedulerApp: Completed container: container_1375859105306_0006_01_000033 in state: COMPLETED event:FINISHED
2013-08-07 07:16:37,809 INFO org.apache.hadoop.yarn.server.resourcemanager.RMAuditLogger: USER=ubuntu	OPERATION=AM Released Container	TARGET=SchedulerApp	RESULT=SUCCESS	APPID=application_1375859105306_0006	CONTAINERID=container_1375859105306_0006_01_000033
2013-08-07 07:16:37,809 INFO org.apache.hadoop.yarn.server.resourcemanager.scheduler.common.fica.FiCaSchedulerNode: Released container container_1375859105306_0006_01_000033 of capacity <memory:1024, vCores:1> on host hadoop-200-5:52184, which currently has 7 containers, <memory:7168, vCores:7> used and <memory:1024, vCores:9> available, release resources=true
2013-08-07 07:16:37,809 INFO org.apache.hadoop.yarn.server.resourcemanager.scheduler.capacity.LeafQueue: default used=<memory:47104, vCores:41> numContainers=41 user=ubuntu user-resources=<memory:47104, vCores:41>
2013-08-07 07:16:37,810 INFO org.apache.hadoop.yarn.server.resourcemanager.scheduler.capacity.LeafQueue: completedContainer container=Container: [ContainerId: container_1375859105306_0006_01_000033, NodeId: hadoop-200-5:52184, NodeHttpAddress: hadoop-200-5:8042, Resource: <memory:1024, vCores:1>, Priority: 20, State: NEW, Token: null, Status: container_id {, app_attempt_id {, application_id {, id: 6, cluster_timestamp: 1375859105306, }, attemptId: 1, }, id: 33, }, state: C_COMPLETE, diagnostics: "Container killed by the ApplicationMaster.\n\n", exit_status: 143, ] resource=<memory:1024, vCores:1> queue=default: capacity=1.0, absoluteCapacity=1.0, usedResources=<memory:47104, vCores:41>usedCapacity=0.9583333, absoluteUsedCapacity=0.9583333, numApps=5, numContainers=41 usedCapacity=0.9583333 absoluteUsedCapacity=0.9583333 used=<memory:47104, vCores:41> cluster=<memory:49152, vCores:96>
2013-08-07 07:16:37,811 INFO org.apache.hadoop.yarn.server.resourcemanager.scheduler.capacity.ParentQueue: completedContainer queue=root usedCapacity=0.9583333 absoluteUsedCapacity=0.9583333 used=<memory:47104, vCores:41> cluster=<memory:49152, vCores:96>
2013-08-07 07:16:37,811 INFO org.apache.hadoop.yarn.server.resourcemanager.scheduler.capacity.CapacityScheduler: Application appattempt_1375859105306_0006_000001 released container container_1375859105306_0006_01_000033 on node: host: hadoop-200-5:52184 #containers=7 available=1024 used=7168 with event: FINISHED
2013-08-07 07:16:37,811 INFO org.apache.hadoop.yarn.server.resourcemanager.rmcontainer.RMContainerImpl: container_1375859105306_0006_01_000048 Container Transitioned from NEW to ALLOCATED
2013-08-07 07:16:37,812 INFO org.apache.hadoop.yarn.server.resourcemanager.RMAuditLogger: USER=ubuntu	OPERATION=AM Allocated Container	TARGET=SchedulerApp	RESULT=SUCCESS	APPID=application_1375859105306_0006	CONTAINERID=container_1375859105306_0006_01_000048
2013-08-07 07:16:37,812 INFO org.apache.hadoop.yarn.server.resourcemanager.scheduler.common.fica.FiCaSchedulerNode: Assigned container container_1375859105306_0006_01_000048 of capacity <memory:1024, vCores:1> on host hadoop-200-5:52184, which currently has 8 containers, <memory:8192, vCores:8> used and <memory:0, vCores:8> available
2013-08-07 07:16:37,817 INFO org.apache.hadoop.yarn.server.resourcemanager.scheduler.capacity.LeafQueue: assignedContainer application=application_1375859105306_0006 container=Container: [ContainerId: container_1375859105306_0006_01_000048, NodeId: hadoop-200-5:52184, NodeHttpAddress: hadoop-200-5:8042, Resource: <memory:1024, vCores:1>, Priority: 20, State: NEW, Token: null, Status: container_id {, app_attempt_id {, application_id {, id: 6, cluster_timestamp: 1375859105306, }, attemptId: 1, }, id: 48, }, state: C_NEW, ] containerId=container_1375859105306_0006_01_000048 queue=default: capacity=1.0, absoluteCapacity=1.0, usedResources=<memory:47104, vCores:41>usedCapacity=0.9583333, absoluteUsedCapacity=0.9583333, numApps=5, numContainers=41 usedCapacity=0.9583333 absoluteUsedCapacity=0.9583333 used=<memory:47104, vCores:41> cluster=<memory:49152, vCores:96>
2013-08-07 07:16:37,817 INFO org.apache.hadoop.yarn.server.resourcemanager.scheduler.capacity.ParentQueue: Re-sorting queues since queue: root.default stats: default: capacity=1.0, absoluteCapacity=1.0, usedResources=<memory:48128, vCores:42>usedCapacity=0.9791667, absoluteUsedCapacity=0.9791667, numApps=5, numContainers=42
2013-08-07 07:16:37,817 INFO org.apache.hadoop.yarn.server.resourcemanager.scheduler.capacity.ParentQueue: assignedContainer queue=root usedCapacity=0.9791667 absoluteUsedCapacity=0.9791667 used=<memory:48128, vCores:42> cluster=<memory:49152, vCores:96>
2013-08-07 07:16:38,359 INFO org.apache.hadoop.yarn.server.resourcemanager.rmcontainer.RMContainerImpl: container_1375859105306_0007_01_000002 Container Transitioned from NEW to ALLOCATED
2013-08-07 07:16:38,359 INFO org.apache.hadoop.yarn.server.resourcemanager.RMAuditLogger: USER=ubuntu	OPERATION=AM Allocated Container	TARGET=SchedulerApp	RESULT=SUCCESS	APPID=application_1375859105306_0007	CONTAINERID=container_1375859105306_0007_01_000002
2013-08-07 07:16:38,359 INFO org.apache.hadoop.yarn.server.resourcemanager.scheduler.common.fica.FiCaSchedulerNode: Assigned container container_1375859105306_0007_01_000002 of capacity <memory:1024, vCores:1> on host hadoop-200-2:35087, which currently has 6 containers, <memory:8192, vCores:6> used and <memory:0, vCores:10> available
2013-08-07 07:16:38,361 INFO org.apache.hadoop.yarn.server.resourcemanager.scheduler.capacity.LeafQueue: assignedContainer application=application_1375859105306_0007 container=Container: [ContainerId: container_1375859105306_0007_01_000002, NodeId: hadoop-200-2:35087, NodeHttpAddress: hadoop-200-2:8042, Resource: <memory:1024, vCores:1>, Priority: 20, State: NEW, Token: null, Status: container_id {, app_attempt_id {, application_id {, id: 7, cluster_timestamp: 1375859105306, }, attemptId: 1, }, id: 2, }, state: C_NEW, ] containerId=container_1375859105306_0007_01_000002 queue=default: capacity=1.0, absoluteCapacity=1.0, usedResources=<memory:48128, vCores:42>usedCapacity=0.9791667, absoluteUsedCapacity=0.9791667, numApps=5, numContainers=42 usedCapacity=0.9791667 absoluteUsedCapacity=0.9791667 used=<memory:48128, vCores:42> cluster=<memory:49152, vCores:96>
2013-08-07 07:16:38,361 INFO org.apache.hadoop.yarn.server.resourcemanager.scheduler.capacity.ParentQueue: Re-sorting queues since queue: root.default stats: default: capacity=1.0, absoluteCapacity=1.0, usedResources=<memory:49152, vCores:43>usedCapacity=1.0, absoluteUsedCapacity=1.0, numApps=5, numContainers=43
2013-08-07 07:16:38,361 INFO org.apache.hadoop.yarn.server.resourcemanager.scheduler.capacity.ParentQueue: assignedContainer queue=root usedCapacity=1.0 absoluteUsedCapacity=1.0 used=<memory:49152, vCores:43> cluster=<memory:49152, vCores:96>
2013-08-07 07:16:38,436 INFO org.apache.hadoop.yarn.server.resourcemanager.rmcontainer.RMContainerImpl: container_1375859105306_0006_01_000048 Container Transitioned from ALLOCATED to ACQUIRED
2013-08-07 07:16:38,835 INFO org.apache.hadoop.yarn.server.resourcemanager.rmcontainer.RMContainerImpl: container_1375859105306_0006_01_000048 Container Transitioned from ACQUIRED to RUNNING
2013-08-07 07:16:38,951 INFO org.apache.hadoop.yarn.server.resourcemanager.rmcontainer.RMContainerImpl: container_1375859105306_0006_01_000020 Container Transitioned from RUNNING to COMPLETED
2013-08-07 07:16:38,951 INFO org.apache.hadoop.yarn.server.resourcemanager.scheduler.common.fica.FiCaSchedulerApp: Completed container: container_1375859105306_0006_01_000020 in state: COMPLETED event:FINISHED
2013-08-07 07:16:38,951 INFO org.apache.hadoop.yarn.server.resourcemanager.RMAuditLogger: USER=ubuntu	OPERATION=AM Released Container	TARGET=SchedulerApp	RESULT=SUCCESS	APPID=application_1375859105306_0006	CONTAINERID=container_1375859105306_0006_01_000020
2013-08-07 07:16:38,951 INFO org.apache.hadoop.yarn.server.resourcemanager.scheduler.common.fica.FiCaSchedulerNode: Released container container_1375859105306_0006_01_000020 of capacity <memory:1024, vCores:1> on host hadoop-200-6:34031, which currently has 7 containers, <memory:7168, vCores:7> used and <memory:1024, vCores:9> available, release resources=true
2013-08-07 07:16:38,951 INFO org.apache.hadoop.yarn.server.resourcemanager.scheduler.capacity.LeafQueue: default used=<memory:48128, vCores:42> numContainers=42 user=ubuntu user-resources=<memory:48128, vCores:42>
2013-08-07 07:16:38,953 INFO org.apache.hadoop.yarn.server.resourcemanager.scheduler.capacity.LeafQueue: completedContainer container=Container: [ContainerId: container_1375859105306_0006_01_000020, NodeId: hadoop-200-6:34031, NodeHttpAddress: hadoop-200-6:8042, Resource: <memory:1024, vCores:1>, Priority: 20, State: NEW, Token: null, Status: container_id {, app_attempt_id {, application_id {, id: 6, cluster_timestamp: 1375859105306, }, attemptId: 1, }, id: 20, }, state: C_COMPLETE, diagnostics: "Container killed by the ApplicationMaster.\n", exit_status: 0, ] resource=<memory:1024, vCores:1> queue=default: capacity=1.0, absoluteCapacity=1.0, usedResources=<memory:48128, vCores:42>usedCapacity=0.9791667, absoluteUsedCapacity=0.9791667, numApps=5, numContainers=42 usedCapacity=0.9791667 absoluteUsedCapacity=0.9791667 used=<memory:48128, vCores:42> cluster=<memory:49152, vCores:96>
2013-08-07 07:16:38,953 INFO org.apache.hadoop.yarn.server.resourcemanager.scheduler.capacity.ParentQueue: completedContainer queue=root usedCapacity=0.9791667 absoluteUsedCapacity=0.9791667 used=<memory:48128, vCores:42> cluster=<memory:49152, vCores:96>
2013-08-07 07:16:38,953 INFO org.apache.hadoop.yarn.server.resourcemanager.scheduler.capacity.CapacityScheduler: Application appattempt_1375859105306_0006_000001 released container container_1375859105306_0006_01_000020 on node: host: hadoop-200-6:34031 #containers=7 available=1024 used=7168 with event: FINISHED
2013-08-07 07:16:38,954 INFO org.apache.hadoop.yarn.server.resourcemanager.rmcontainer.RMContainerImpl: container_1375859105306_0007_01_000003 Container Transitioned from NEW to ALLOCATED
2013-08-07 07:16:38,954 INFO org.apache.hadoop.yarn.server.resourcemanager.RMAuditLogger: USER=ubuntu	OPERATION=AM Allocated Container	TARGET=SchedulerApp	RESULT=SUCCESS	APPID=application_1375859105306_0007	CONTAINERID=container_1375859105306_0007_01_000003
2013-08-07 07:16:38,954 INFO org.apache.hadoop.yarn.server.resourcemanager.scheduler.common.fica.FiCaSchedulerNode: Assigned container container_1375859105306_0007_01_000003 of capacity <memory:1024, vCores:1> on host hadoop-200-6:34031, which currently has 8 containers, <memory:8192, vCores:8> used and <memory:0, vCores:8> available
2013-08-07 07:16:38,955 INFO org.apache.hadoop.yarn.server.resourcemanager.scheduler.capacity.LeafQueue: assignedContainer application=application_1375859105306_0007 container=Container: [ContainerId: container_1375859105306_0007_01_000003, NodeId: hadoop-200-6:34031, NodeHttpAddress: hadoop-200-6:8042, Resource: <memory:1024, vCores:1>, Priority: 20, State: NEW, Token: null, Status: container_id {, app_attempt_id {, application_id {, id: 7, cluster_timestamp: 1375859105306, }, attemptId: 1, }, id: 3, }, state: C_NEW, ] containerId=container_1375859105306_0007_01_000003 queue=default: capacity=1.0, absoluteCapacity=1.0, usedResources=<memory:48128, vCores:42>usedCapacity=0.9791667, absoluteUsedCapacity=0.9791667, numApps=5, numContainers=42 usedCapacity=0.9791667 absoluteUsedCapacity=0.9791667 used=<memory:48128, vCores:42> cluster=<memory:49152, vCores:96>
2013-08-07 07:16:38,955 INFO org.apache.hadoop.yarn.server.resourcemanager.scheduler.capacity.ParentQueue: Re-sorting queues since queue: root.default stats: default: capacity=1.0, absoluteCapacity=1.0, usedResources=<memory:49152, vCores:43>usedCapacity=1.0, absoluteUsedCapacity=1.0, numApps=5, numContainers=43
2013-08-07 07:16:38,956 INFO org.apache.hadoop.yarn.server.resourcemanager.scheduler.capacity.ParentQueue: assignedContainer queue=root usedCapacity=1.0 absoluteUsedCapacity=1.0 used=<memory:49152, vCores:43> cluster=<memory:49152, vCores:96>
2013-08-07 07:16:39,306 INFO org.apache.hadoop.yarn.server.resourcemanager.rmcontainer.RMContainerImpl: container_1375859105306_0007_01_000002 Container Transitioned from ALLOCATED to ACQUIRED
2013-08-07 07:16:39,313 INFO org.apache.hadoop.yarn.server.resourcemanager.rmcontainer.RMContainerImpl: container_1375859105306_0007_01_000003 Container Transitioned from ALLOCATED to ACQUIRED
2013-08-07 07:16:39,451 INFO org.apache.hadoop.yarn.server.resourcemanager.scheduler.AppSchedulingInfo: checking for deactivate... 
2013-08-07 07:16:39,669 INFO org.apache.hadoop.yarn.server.resourcemanager.rmcontainer.RMContainerImpl: container_1375859105306_0006_01_000016 Container Transitioned from RUNNING to COMPLETED
2013-08-07 07:16:39,669 INFO org.apache.hadoop.yarn.server.resourcemanager.scheduler.common.fica.FiCaSchedulerApp: Completed container: container_1375859105306_0006_01_000016 in state: COMPLETED event:FINISHED
2013-08-07 07:16:39,669 INFO org.apache.hadoop.yarn.server.resourcemanager.RMAuditLogger: USER=ubuntu	OPERATION=AM Released Container	TARGET=SchedulerApp	RESULT=SUCCESS	APPID=application_1375859105306_0006	CONTAINERID=container_1375859105306_0006_01_000016
2013-08-07 07:16:39,670 INFO org.apache.hadoop.yarn.server.resourcemanager.scheduler.common.fica.FiCaSchedulerNode: Released container container_1375859105306_0006_01_000016 of capacity <memory:1024, vCores:1> on host hadoop-200-6:34031, which currently has 7 containers, <memory:7168, vCores:7> used and <memory:1024, vCores:9> available, release resources=true
2013-08-07 07:16:39,670 INFO org.apache.hadoop.yarn.server.resourcemanager.scheduler.capacity.LeafQueue: default used=<memory:48128, vCores:42> numContainers=42 user=ubuntu user-resources=<memory:48128, vCores:42>
2013-08-07 07:16:39,671 INFO org.apache.hadoop.yarn.server.resourcemanager.scheduler.capacity.LeafQueue: completedContainer container=Container: [ContainerId: container_1375859105306_0006_01_000016, NodeId: hadoop-200-6:34031, NodeHttpAddress: hadoop-200-6:8042, Resource: <memory:1024, vCores:1>, Priority: 20, State: NEW, Token: null, Status: container_id {, app_attempt_id {, application_id {, id: 6, cluster_timestamp: 1375859105306, }, attemptId: 1, }, id: 16, }, state: C_COMPLETE, diagnostics: "Container killed by the ApplicationMaster.\n", exit_status: 0, ] resource=<memory:1024, vCores:1> queue=default: capacity=1.0, absoluteCapacity=1.0, usedResources=<memory:48128, vCores:42>usedCapacity=0.9791667, absoluteUsedCapacity=0.9791667, numApps=5, numContainers=42 usedCapacity=0.9791667 absoluteUsedCapacity=0.9791667 used=<memory:48128, vCores:42> cluster=<memory:49152, vCores:96>
2013-08-07 07:16:39,671 INFO org.apache.hadoop.yarn.server.resourcemanager.scheduler.capacity.ParentQueue: completedContainer queue=root usedCapacity=0.9791667 absoluteUsedCapacity=0.9791667 used=<memory:48128, vCores:42> cluster=<memory:49152, vCores:96>
2013-08-07 07:16:39,671 INFO org.apache.hadoop.yarn.server.resourcemanager.scheduler.capacity.CapacityScheduler: Application appattempt_1375859105306_0006_000001 released container container_1375859105306_0006_01_000016 on node: host: hadoop-200-6:34031 #containers=7 available=1024 used=7168 with event: FINISHED
2013-08-07 07:16:39,672 INFO org.apache.hadoop.yarn.server.resourcemanager.rmcontainer.RMContainerImpl: container_1375859105306_0007_01_000004 Container Transitioned from NEW to ALLOCATED
2013-08-07 07:16:39,672 INFO org.apache.hadoop.yarn.server.resourcemanager.RMAuditLogger: USER=ubuntu	OPERATION=AM Allocated Container	TARGET=SchedulerApp	RESULT=SUCCESS	APPID=application_1375859105306_0007	CONTAINERID=container_1375859105306_0007_01_000004
2013-08-07 07:16:39,672 INFO org.apache.hadoop.yarn.server.resourcemanager.scheduler.common.fica.FiCaSchedulerNode: Assigned container container_1375859105306_0007_01_000004 of capacity <memory:1024, vCores:1> on host hadoop-200-6:34031, which currently has 8 containers, <memory:8192, vCores:8> used and <memory:0, vCores:8> available
2013-08-07 07:16:39,673 INFO org.apache.hadoop.yarn.server.resourcemanager.scheduler.capacity.LeafQueue: assignedContainer application=application_1375859105306_0007 container=Container: [ContainerId: container_1375859105306_0007_01_000004, NodeId: hadoop-200-6:34031, NodeHttpAddress: hadoop-200-6:8042, Resource: <memory:1024, vCores:1>, Priority: 20, State: NEW, Token: null, Status: container_id {, app_attempt_id {, application_id {, id: 7, cluster_timestamp: 1375859105306, }, attemptId: 1, }, id: 4, }, state: C_NEW, ] containerId=container_1375859105306_0007_01_000004 queue=default: capacity=1.0, absoluteCapacity=1.0, usedResources=<memory:48128, vCores:42>usedCapacity=0.9791667, absoluteUsedCapacity=0.9791667, numApps=5, numContainers=42 usedCapacity=0.9791667 absoluteUsedCapacity=0.9791667 used=<memory:48128, vCores:42> cluster=<memory:49152, vCores:96>
2013-08-07 07:16:39,674 INFO org.apache.hadoop.yarn.server.resourcemanager.scheduler.capacity.ParentQueue: Re-sorting queues since queue: root.default stats: default: capacity=1.0, absoluteCapacity=1.0, usedResources=<memory:49152, vCores:43>usedCapacity=1.0, absoluteUsedCapacity=1.0, numApps=5, numContainers=43
2013-08-07 07:16:39,674 INFO org.apache.hadoop.yarn.server.resourcemanager.scheduler.capacity.ParentQueue: assignedContainer queue=root usedCapacity=1.0 absoluteUsedCapacity=1.0 used=<memory:49152, vCores:43> cluster=<memory:49152, vCores:96>
2013-08-07 07:16:39,963 INFO org.apache.hadoop.yarn.server.resourcemanager.rmcontainer.RMContainerImpl: container_1375859105306_0006_01_000037 Container Transitioned from RUNNING to COMPLETED
2013-08-07 07:16:39,963 INFO org.apache.hadoop.yarn.server.resourcemanager.scheduler.common.fica.FiCaSchedulerApp: Completed container: container_1375859105306_0006_01_000037 in state: COMPLETED event:FINISHED
2013-08-07 07:16:39,964 INFO org.apache.hadoop.yarn.server.resourcemanager.RMAuditLogger: USER=ubuntu	OPERATION=AM Released Container	TARGET=SchedulerApp	RESULT=SUCCESS	APPID=application_1375859105306_0006	CONTAINERID=container_1375859105306_0006_01_000037
2013-08-07 07:16:39,964 INFO org.apache.hadoop.yarn.server.resourcemanager.scheduler.common.fica.FiCaSchedulerNode: Released container container_1375859105306_0006_01_000037 of capacity <memory:1024, vCores:1> on host hadoop-200-5:52184, which currently has 7 containers, <memory:7168, vCores:7> used and <memory:1024, vCores:9> available, release resources=true
2013-08-07 07:16:39,964 INFO org.apache.hadoop.yarn.server.resourcemanager.scheduler.capacity.LeafQueue: default used=<memory:48128, vCores:42> numContainers=42 user=ubuntu user-resources=<memory:48128, vCores:42>
2013-08-07 07:16:39,965 INFO org.apache.hadoop.yarn.server.resourcemanager.scheduler.capacity.LeafQueue: completedContainer container=Container: [ContainerId: container_1375859105306_0006_01_000037, NodeId: hadoop-200-5:52184, NodeHttpAddress: hadoop-200-5:8042, Resource: <memory:1024, vCores:1>, Priority: 20, State: NEW, Token: null, Status: container_id {, app_attempt_id {, application_id {, id: 6, cluster_timestamp: 1375859105306, }, attemptId: 1, }, id: 37, }, state: C_COMPLETE, diagnostics: "Container killed by the ApplicationMaster.\n\n", exit_status: 143, ] resource=<memory:1024, vCores:1> queue=default: capacity=1.0, absoluteCapacity=1.0, usedResources=<memory:48128, vCores:42>usedCapacity=0.9791667, absoluteUsedCapacity=0.9791667, numApps=5, numContainers=42 usedCapacity=0.9791667 absoluteUsedCapacity=0.9791667 used=<memory:48128, vCores:42> cluster=<memory:49152, vCores:96>
2013-08-07 07:16:39,965 INFO org.apache.hadoop.yarn.server.resourcemanager.scheduler.capacity.ParentQueue: completedContainer queue=root usedCapacity=0.9791667 absoluteUsedCapacity=0.9791667 used=<memory:48128, vCores:42> cluster=<memory:49152, vCores:96>
2013-08-07 07:16:39,966 INFO org.apache.hadoop.yarn.server.resourcemanager.scheduler.capacity.CapacityScheduler: Application appattempt_1375859105306_0006_000001 released container container_1375859105306_0006_01_000037 on node: host: hadoop-200-5:52184 #containers=7 available=1024 used=7168 with event: FINISHED
2013-08-07 07:16:39,966 INFO org.apache.hadoop.yarn.server.resourcemanager.rmcontainer.RMContainerImpl: container_1375859105306_0007_01_000005 Container Transitioned from NEW to ALLOCATED
2013-08-07 07:16:39,966 INFO org.apache.hadoop.yarn.server.resourcemanager.RMAuditLogger: USER=ubuntu	OPERATION=AM Allocated Container	TARGET=SchedulerApp	RESULT=SUCCESS	APPID=application_1375859105306_0007	CONTAINERID=container_1375859105306_0007_01_000005
2013-08-07 07:16:39,967 INFO org.apache.hadoop.yarn.server.resourcemanager.scheduler.common.fica.FiCaSchedulerNode: Assigned container container_1375859105306_0007_01_000005 of capacity <memory:1024, vCores:1> on host hadoop-200-5:52184, which currently has 8 containers, <memory:8192, vCores:8> used and <memory:0, vCores:8> available
2013-08-07 07:16:39,968 INFO org.apache.hadoop.yarn.server.resourcemanager.scheduler.capacity.LeafQueue: assignedContainer application=application_1375859105306_0007 container=Container: [ContainerId: container_1375859105306_0007_01_000005, NodeId: hadoop-200-5:52184, NodeHttpAddress: hadoop-200-5:8042, Resource: <memory:1024, vCores:1>, Priority: 20, State: NEW, Token: null, Status: container_id {, app_attempt_id {, application_id {, id: 7, cluster_timestamp: 1375859105306, }, attemptId: 1, }, id: 5, }, state: C_NEW, ] containerId=container_1375859105306_0007_01_000005 queue=default: capacity=1.0, absoluteCapacity=1.0, usedResources=<memory:48128, vCores:42>usedCapacity=0.9791667, absoluteUsedCapacity=0.9791667, numApps=5, numContainers=42 usedCapacity=0.9791667 absoluteUsedCapacity=0.9791667 used=<memory:48128, vCores:42> cluster=<memory:49152, vCores:96>
2013-08-07 07:16:39,968 INFO org.apache.hadoop.yarn.server.resourcemanager.scheduler.capacity.ParentQueue: Re-sorting queues since queue: root.default stats: default: capacity=1.0, absoluteCapacity=1.0, usedResources=<memory:49152, vCores:43>usedCapacity=1.0, absoluteUsedCapacity=1.0, numApps=5, numContainers=43
2013-08-07 07:16:39,968 INFO org.apache.hadoop.yarn.server.resourcemanager.scheduler.capacity.ParentQueue: assignedContainer queue=root usedCapacity=1.0 absoluteUsedCapacity=1.0 used=<memory:49152, vCores:43> cluster=<memory:49152, vCores:96>
2013-08-07 07:16:40,377 INFO org.apache.hadoop.yarn.server.resourcemanager.rmcontainer.RMContainerImpl: container_1375859105306_0007_01_000002 Container Transitioned from ACQUIRED to RUNNING
2013-08-07 07:16:40,407 INFO org.apache.hadoop.yarn.server.resourcemanager.rmcontainer.RMContainerImpl: container_1375859105306_0007_01_000004 Container Transitioned from ALLOCATED to ACQUIRED
2013-08-07 07:16:40,408 INFO org.apache.hadoop.yarn.server.resourcemanager.rmcontainer.RMContainerImpl: container_1375859105306_0007_01_000005 Container Transitioned from ALLOCATED to ACQUIRED
2013-08-07 07:16:40,747 INFO org.apache.hadoop.yarn.server.resourcemanager.rmcontainer.RMContainerImpl: container_1375859105306_0007_01_000003 Container Transitioned from ACQUIRED to RUNNING
2013-08-07 07:16:40,747 INFO org.apache.hadoop.yarn.server.resourcemanager.rmcontainer.RMContainerImpl: container_1375859105306_0007_01_000004 Container Transitioned from ACQUIRED to RUNNING
2013-08-07 07:16:40,747 INFO org.apache.hadoop.yarn.server.resourcemanager.rmcontainer.RMContainerImpl: container_1375859105306_0006_01_000023 Container Transitioned from RUNNING to COMPLETED
2013-08-07 07:16:40,748 INFO org.apache.hadoop.yarn.server.resourcemanager.scheduler.common.fica.FiCaSchedulerApp: Completed container: container_1375859105306_0006_01_000023 in state: COMPLETED event:FINISHED
2013-08-07 07:16:40,748 INFO org.apache.hadoop.yarn.server.resourcemanager.RMAuditLogger: USER=ubuntu	OPERATION=AM Released Container	TARGET=SchedulerApp	RESULT=SUCCESS	APPID=application_1375859105306_0006	CONTAINERID=container_1375859105306_0006_01_000023
2013-08-07 07:16:40,748 INFO org.apache.hadoop.yarn.server.resourcemanager.scheduler.common.fica.FiCaSchedulerNode: Released container container_1375859105306_0006_01_000023 of capacity <memory:1024, vCores:1> on host hadoop-200-6:34031, which currently has 7 containers, <memory:7168, vCores:7> used and <memory:1024, vCores:9> available, release resources=true
2013-08-07 07:16:40,748 INFO org.apache.hadoop.yarn.server.resourcemanager.scheduler.capacity.LeafQueue: default used=<memory:48128, vCores:42> numContainers=42 user=ubuntu user-resources=<memory:48128, vCores:42>
2013-08-07 07:16:40,750 INFO org.apache.hadoop.yarn.server.resourcemanager.scheduler.capacity.LeafQueue: completedContainer container=Container: [ContainerId: container_1375859105306_0006_01_000023, NodeId: hadoop-200-6:34031, NodeHttpAddress: hadoop-200-6:8042, Resource: <memory:1024, vCores:1>, Priority: 20, State: NEW, Token: null, Status: container_id {, app_attempt_id {, application_id {, id: 6, cluster_timestamp: 1375859105306, }, attemptId: 1, }, id: 23, }, state: C_COMPLETE, diagnostics: "Container killed by the ApplicationMaster.\n\n", exit_status: 143, ] resource=<memory:1024, vCores:1> queue=default: capacity=1.0, absoluteCapacity=1.0, usedResources=<memory:48128, vCores:42>usedCapacity=0.9791667, absoluteUsedCapacity=0.9791667, numApps=5, numContainers=42 usedCapacity=0.9791667 absoluteUsedCapacity=0.9791667 used=<memory:48128, vCores:42> cluster=<memory:49152, vCores:96>
2013-08-07 07:16:40,750 INFO org.apache.hadoop.yarn.server.resourcemanager.scheduler.capacity.ParentQueue: completedContainer queue=root usedCapacity=0.9791667 absoluteUsedCapacity=0.9791667 used=<memory:48128, vCores:42> cluster=<memory:49152, vCores:96>
2013-08-07 07:16:40,750 INFO org.apache.hadoop.yarn.server.resourcemanager.scheduler.capacity.CapacityScheduler: Application appattempt_1375859105306_0006_000001 released container container_1375859105306_0006_01_000023 on node: host: hadoop-200-6:34031 #containers=7 available=1024 used=7168 with event: FINISHED
2013-08-07 07:16:40,751 INFO org.apache.hadoop.yarn.server.resourcemanager.rmcontainer.RMContainerImpl: container_1375859105306_0007_01_000006 Container Transitioned from NEW to ALLOCATED
2013-08-07 07:16:40,751 INFO org.apache.hadoop.yarn.server.resourcemanager.RMAuditLogger: USER=ubuntu	OPERATION=AM Allocated Container	TARGET=SchedulerApp	RESULT=SUCCESS	APPID=application_1375859105306_0007	CONTAINERID=container_1375859105306_0007_01_000006
2013-08-07 07:16:40,751 INFO org.apache.hadoop.yarn.server.resourcemanager.scheduler.common.fica.FiCaSchedulerNode: Assigned container container_1375859105306_0007_01_000006 of capacity <memory:1024, vCores:1> on host hadoop-200-6:34031, which currently has 8 containers, <memory:8192, vCores:8> used and <memory:0, vCores:8> available
2013-08-07 07:16:40,752 INFO org.apache.hadoop.yarn.server.resourcemanager.scheduler.capacity.LeafQueue: assignedContainer application=application_1375859105306_0007 container=Container: [ContainerId: container_1375859105306_0007_01_000006, NodeId: hadoop-200-6:34031, NodeHttpAddress: hadoop-200-6:8042, Resource: <memory:1024, vCores:1>, Priority: 20, State: NEW, Token: null, Status: container_id {, app_attempt_id {, application_id {, id: 7, cluster_timestamp: 1375859105306, }, attemptId: 1, }, id: 6, }, state: C_NEW, ] containerId=container_1375859105306_0007_01_000006 queue=default: capacity=1.0, absoluteCapacity=1.0, usedResources=<memory:48128, vCores:42>usedCapacity=0.9791667, absoluteUsedCapacity=0.9791667, numApps=5, numContainers=42 usedCapacity=0.9791667 absoluteUsedCapacity=0.9791667 used=<memory:48128, vCores:42> cluster=<memory:49152, vCores:96>
2013-08-07 07:16:40,752 INFO org.apache.hadoop.yarn.server.resourcemanager.scheduler.capacity.ParentQueue: Re-sorting queues since queue: root.default stats: default: capacity=1.0, absoluteCapacity=1.0, usedResources=<memory:49152, vCores:43>usedCapacity=1.0, absoluteUsedCapacity=1.0, numApps=5, numContainers=43
2013-08-07 07:16:40,752 INFO org.apache.hadoop.yarn.server.resourcemanager.scheduler.capacity.ParentQueue: assignedContainer queue=root usedCapacity=1.0 absoluteUsedCapacity=1.0 used=<memory:49152, vCores:43> cluster=<memory:49152, vCores:96>
2013-08-07 07:16:40,977 INFO org.apache.hadoop.yarn.server.resourcemanager.rmcontainer.RMContainerImpl: container_1375859105306_0006_01_000014 Container Transitioned from RUNNING to COMPLETED
2013-08-07 07:16:40,977 INFO org.apache.hadoop.yarn.server.resourcemanager.scheduler.common.fica.FiCaSchedulerApp: Completed container: container_1375859105306_0006_01_000014 in state: COMPLETED event:FINISHED
2013-08-07 07:16:40,977 INFO org.apache.hadoop.yarn.server.resourcemanager.RMAuditLogger: USER=ubuntu	OPERATION=AM Released Container	TARGET=SchedulerApp	RESULT=SUCCESS	APPID=application_1375859105306_0006	CONTAINERID=container_1375859105306_0006_01_000014
2013-08-07 07:16:40,977 INFO org.apache.hadoop.yarn.server.resourcemanager.scheduler.common.fica.FiCaSchedulerNode: Released container container_1375859105306_0006_01_000014 of capacity <memory:1024, vCores:1> on host hadoop-200-4:41828, which currently has 6 containers, <memory:7168, vCores:6> used and <memory:1024, vCores:10> available, release resources=true
2013-08-07 07:16:40,977 INFO org.apache.hadoop.yarn.server.resourcemanager.scheduler.capacity.LeafQueue: default used=<memory:48128, vCores:42> numContainers=42 user=ubuntu user-resources=<memory:48128, vCores:42>
2013-08-07 07:16:40,979 INFO org.apache.hadoop.yarn.server.resourcemanager.scheduler.capacity.LeafQueue: completedContainer container=Container: [ContainerId: container_1375859105306_0006_01_000014, NodeId: hadoop-200-4:41828, NodeHttpAddress: hadoop-200-4:8042, Resource: <memory:1024, vCores:1>, Priority: 20, State: NEW, Token: null, Status: container_id {, app_attempt_id {, application_id {, id: 6, cluster_timestamp: 1375859105306, }, attemptId: 1, }, id: 14, }, state: C_COMPLETE, diagnostics: "Container killed by the ApplicationMaster.\n", exit_status: 0, ] resource=<memory:1024, vCores:1> queue=default: capacity=1.0, absoluteCapacity=1.0, usedResources=<memory:48128, vCores:42>usedCapacity=0.9791667, absoluteUsedCapacity=0.9791667, numApps=5, numContainers=42 usedCapacity=0.9791667 absoluteUsedCapacity=0.9791667 used=<memory:48128, vCores:42> cluster=<memory:49152, vCores:96>
2013-08-07 07:16:40,979 INFO org.apache.hadoop.yarn.server.resourcemanager.scheduler.capacity.ParentQueue: completedContainer queue=root usedCapacity=0.9791667 absoluteUsedCapacity=0.9791667 used=<memory:48128, vCores:42> cluster=<memory:49152, vCores:96>
2013-08-07 07:16:40,979 INFO org.apache.hadoop.yarn.server.resourcemanager.scheduler.capacity.CapacityScheduler: Application appattempt_1375859105306_0006_000001 released container container_1375859105306_0006_01_000014 on node: host: hadoop-200-4:41828 #containers=6 available=1024 used=7168 with event: FINISHED
2013-08-07 07:16:40,980 INFO org.apache.hadoop.yarn.server.resourcemanager.rmcontainer.RMContainerImpl: container_1375859105306_0007_01_000007 Container Transitioned from NEW to ALLOCATED
2013-08-07 07:16:40,980 INFO org.apache.hadoop.yarn.server.resourcemanager.RMAuditLogger: USER=ubuntu	OPERATION=AM Allocated Container	TARGET=SchedulerApp	RESULT=SUCCESS	APPID=application_1375859105306_0007	CONTAINERID=container_1375859105306_0007_01_000007
2013-08-07 07:16:40,980 INFO org.apache.hadoop.yarn.server.resourcemanager.scheduler.common.fica.FiCaSchedulerNode: Assigned container container_1375859105306_0007_01_000007 of capacity <memory:1024, vCores:1> on host hadoop-200-4:41828, which currently has 7 containers, <memory:8192, vCores:7> used and <memory:0, vCores:9> available
2013-08-07 07:16:40,981 INFO org.apache.hadoop.yarn.server.resourcemanager.scheduler.capacity.LeafQueue: assignedContainer application=application_1375859105306_0007 container=Container: [ContainerId: container_1375859105306_0007_01_000007, NodeId: hadoop-200-4:41828, NodeHttpAddress: hadoop-200-4:8042, Resource: <memory:1024, vCores:1>, Priority: 20, State: NEW, Token: null, Status: container_id {, app_attempt_id {, application_id {, id: 7, cluster_timestamp: 1375859105306, }, attemptId: 1, }, id: 7, }, state: C_NEW, ] containerId=container_1375859105306_0007_01_000007 queue=default: capacity=1.0, absoluteCapacity=1.0, usedResources=<memory:48128, vCores:42>usedCapacity=0.9791667, absoluteUsedCapacity=0.9791667, numApps=5, numContainers=42 usedCapacity=0.9791667 absoluteUsedCapacity=0.9791667 used=<memory:48128, vCores:42> cluster=<memory:49152, vCores:96>
2013-08-07 07:16:40,981 INFO org.apache.hadoop.yarn.server.resourcemanager.scheduler.capacity.ParentQueue: Re-sorting queues since queue: root.default stats: default: capacity=1.0, absoluteCapacity=1.0, usedResources=<memory:49152, vCores:43>usedCapacity=1.0, absoluteUsedCapacity=1.0, numApps=5, numContainers=43
2013-08-07 07:16:40,981 INFO org.apache.hadoop.yarn.server.resourcemanager.scheduler.capacity.ParentQueue: assignedContainer queue=root usedCapacity=1.0 absoluteUsedCapacity=1.0 used=<memory:49152, vCores:43> cluster=<memory:49152, vCores:96>
2013-08-07 07:16:41,027 INFO org.apache.hadoop.yarn.server.resourcemanager.rmcontainer.RMContainerImpl: container_1375859105306_0007_01_000005 Container Transitioned from ACQUIRED to RUNNING
2013-08-07 07:16:41,231 INFO org.apache.hadoop.yarn.server.resourcemanager.rmcontainer.RMContainerImpl: container_1375859105306_0006_01_000027 Container Transitioned from RUNNING to COMPLETED
2013-08-07 07:16:41,231 INFO org.apache.hadoop.yarn.server.resourcemanager.scheduler.common.fica.FiCaSchedulerApp: Completed container: container_1375859105306_0006_01_000027 in state: COMPLETED event:FINISHED
2013-08-07 07:16:41,231 INFO org.apache.hadoop.yarn.server.resourcemanager.RMAuditLogger: USER=ubuntu	OPERATION=AM Released Container	TARGET=SchedulerApp	RESULT=SUCCESS	APPID=application_1375859105306_0006	CONTAINERID=container_1375859105306_0006_01_000027
2013-08-07 07:16:41,231 INFO org.apache.hadoop.yarn.server.resourcemanager.scheduler.common.fica.FiCaSchedulerNode: Released container container_1375859105306_0006_01_000027 of capacity <memory:1024, vCores:1> on host hadoop-200-7:58499, which currently has 7 containers, <memory:7168, vCores:7> used and <memory:1024, vCores:9> available, release resources=true
2013-08-07 07:16:41,232 INFO org.apache.hadoop.yarn.server.resourcemanager.scheduler.capacity.LeafQueue: default used=<memory:48128, vCores:42> numContainers=42 user=ubuntu user-resources=<memory:48128, vCores:42>
2013-08-07 07:16:41,233 INFO org.apache.hadoop.yarn.server.resourcemanager.scheduler.capacity.LeafQueue: completedContainer container=Container: [ContainerId: container_1375859105306_0006_01_000027, NodeId: hadoop-200-7:58499, NodeHttpAddress: hadoop-200-7:8042, Resource: <memory:1024, vCores:1>, Priority: 20, State: NEW, Token: null, Status: container_id {, app_attempt_id {, application_id {, id: 6, cluster_timestamp: 1375859105306, }, attemptId: 1, }, id: 27, }, state: C_COMPLETE, diagnostics: "Container killed by the ApplicationMaster.\n", exit_status: 0, ] resource=<memory:1024, vCores:1> queue=default: capacity=1.0, absoluteCapacity=1.0, usedResources=<memory:48128, vCores:42>usedCapacity=0.9791667, absoluteUsedCapacity=0.9791667, numApps=5, numContainers=42 usedCapacity=0.9791667 absoluteUsedCapacity=0.9791667 used=<memory:48128, vCores:42> cluster=<memory:49152, vCores:96>
2013-08-07 07:16:41,233 INFO org.apache.hadoop.yarn.server.resourcemanager.scheduler.capacity.ParentQueue: completedContainer queue=root usedCapacity=0.9791667 absoluteUsedCapacity=0.9791667 used=<memory:48128, vCores:42> cluster=<memory:49152, vCores:96>
2013-08-07 07:16:41,233 INFO org.apache.hadoop.yarn.server.resourcemanager.scheduler.capacity.CapacityScheduler: Application appattempt_1375859105306_0006_000001 released container container_1375859105306_0006_01_000027 on node: host: hadoop-200-7:58499 #containers=7 available=1024 used=7168 with event: FINISHED
2013-08-07 07:16:41,233 INFO org.apache.hadoop.yarn.server.resourcemanager.rmcontainer.RMContainerImpl: container_1375859105306_0006_01_000028 Container Transitioned from RUNNING to COMPLETED
2013-08-07 07:16:41,233 INFO org.apache.hadoop.yarn.server.resourcemanager.scheduler.common.fica.FiCaSchedulerApp: Completed container: container_1375859105306_0006_01_000028 in state: COMPLETED event:FINISHED
2013-08-07 07:16:41,234 INFO org.apache.hadoop.yarn.server.resourcemanager.RMAuditLogger: USER=ubuntu	OPERATION=AM Released Container	TARGET=SchedulerApp	RESULT=SUCCESS	APPID=application_1375859105306_0006	CONTAINERID=container_1375859105306_0006_01_000028
2013-08-07 07:16:41,234 INFO org.apache.hadoop.yarn.server.resourcemanager.scheduler.common.fica.FiCaSchedulerNode: Released container container_1375859105306_0006_01_000028 of capacity <memory:1024, vCores:1> on host hadoop-200-7:58499, which currently has 6 containers, <memory:6144, vCores:6> used and <memory:2048, vCores:10> available, release resources=true
2013-08-07 07:16:41,234 INFO org.apache.hadoop.yarn.server.resourcemanager.scheduler.capacity.LeafQueue: default used=<memory:47104, vCores:41> numContainers=41 user=ubuntu user-resources=<memory:47104, vCores:41>
2013-08-07 07:16:41,235 INFO org.apache.hadoop.yarn.server.resourcemanager.scheduler.capacity.LeafQueue: completedContainer container=Container: [ContainerId: container_1375859105306_0006_01_000028, NodeId: hadoop-200-7:58499, NodeHttpAddress: hadoop-200-7:8042, Resource: <memory:1024, vCores:1>, Priority: 20, State: NEW, Token: null, Status: container_id {, app_attempt_id {, application_id {, id: 6, cluster_timestamp: 1375859105306, }, attemptId: 1, }, id: 28, }, state: C_COMPLETE, diagnostics: "Container killed by the ApplicationMaster.\n", exit_status: 0, ] resource=<memory:1024, vCores:1> queue=default: capacity=1.0, absoluteCapacity=1.0, usedResources=<memory:47104, vCores:41>usedCapacity=0.9583333, absoluteUsedCapacity=0.9583333, numApps=5, numContainers=41 usedCapacity=0.9583333 absoluteUsedCapacity=0.9583333 used=<memory:47104, vCores:41> cluster=<memory:49152, vCores:96>
2013-08-07 07:16:41,235 INFO org.apache.hadoop.yarn.server.resourcemanager.scheduler.capacity.ParentQueue: completedContainer queue=root usedCapacity=0.9583333 absoluteUsedCapacity=0.9583333 used=<memory:47104, vCores:41> cluster=<memory:49152, vCores:96>
2013-08-07 07:16:41,235 INFO org.apache.hadoop.yarn.server.resourcemanager.scheduler.capacity.CapacityScheduler: Application appattempt_1375859105306_0006_000001 released container container_1375859105306_0006_01_000028 on node: host: hadoop-200-7:58499 #containers=6 available=2048 used=6144 with event: FINISHED
2013-08-07 07:16:41,236 INFO org.apache.hadoop.yarn.server.resourcemanager.rmcontainer.RMContainerImpl: container_1375859105306_0006_01_000031 Container Transitioned from RUNNING to COMPLETED
2013-08-07 07:16:41,236 INFO org.apache.hadoop.yarn.server.resourcemanager.scheduler.common.fica.FiCaSchedulerApp: Completed container: container_1375859105306_0006_01_000031 in state: COMPLETED event:FINISHED
2013-08-07 07:16:41,236 INFO org.apache.hadoop.yarn.server.resourcemanager.RMAuditLogger: USER=ubuntu	OPERATION=AM Released Container	TARGET=SchedulerApp	RESULT=SUCCESS	APPID=application_1375859105306_0006	CONTAINERID=container_1375859105306_0006_01_000031
2013-08-07 07:16:41,236 INFO org.apache.hadoop.yarn.server.resourcemanager.scheduler.common.fica.FiCaSchedulerNode: Released container container_1375859105306_0006_01_000031 of capacity <memory:1024, vCores:1> on host hadoop-200-7:58499, which currently has 5 containers, <memory:5120, vCores:5> used and <memory:3072, vCores:11> available, release resources=true
2013-08-07 07:16:41,236 INFO org.apache.hadoop.yarn.server.resourcemanager.scheduler.capacity.LeafQueue: default used=<memory:46080, vCores:40> numContainers=40 user=ubuntu user-resources=<memory:46080, vCores:40>
2013-08-07 07:16:41,237 INFO org.apache.hadoop.yarn.server.resourcemanager.scheduler.capacity.LeafQueue: completedContainer container=Container: [ContainerId: container_1375859105306_0006_01_000031, NodeId: hadoop-200-7:58499, NodeHttpAddress: hadoop-200-7:8042, Resource: <memory:1024, vCores:1>, Priority: 20, State: NEW, Token: null, Status: container_id {, app_attempt_id {, application_id {, id: 6, cluster_timestamp: 1375859105306, }, attemptId: 1, }, id: 31, }, state: C_COMPLETE, diagnostics: "Container killed by the ApplicationMaster.\n", exit_status: 0, ] resource=<memory:1024, vCores:1> queue=default: capacity=1.0, absoluteCapacity=1.0, usedResources=<memory:46080, vCores:40>usedCapacity=0.9375, absoluteUsedCapacity=0.9375, numApps=5, numContainers=40 usedCapacity=0.9375 absoluteUsedCapacity=0.9375 used=<memory:46080, vCores:40> cluster=<memory:49152, vCores:96>
2013-08-07 07:16:41,237 INFO org.apache.hadoop.yarn.server.resourcemanager.scheduler.capacity.ParentQueue: completedContainer queue=root usedCapacity=0.9375 absoluteUsedCapacity=0.9375 used=<memory:46080, vCores:40> cluster=<memory:49152, vCores:96>
2013-08-07 07:16:41,238 INFO org.apache.hadoop.yarn.server.resourcemanager.scheduler.capacity.CapacityScheduler: Application appattempt_1375859105306_0006_000001 released container container_1375859105306_0006_01_000031 on node: host: hadoop-200-7:58499 #containers=5 available=3072 used=5120 with event: FINISHED
2013-08-07 07:16:41,238 INFO org.apache.hadoop.yarn.server.resourcemanager.rmcontainer.RMContainerImpl: container_1375859105306_0007_01_000008 Container Transitioned from NEW to ALLOCATED
2013-08-07 07:16:41,238 INFO org.apache.hadoop.yarn.server.resourcemanager.RMAuditLogger: USER=ubuntu	OPERATION=AM Allocated Container	TARGET=SchedulerApp	RESULT=SUCCESS	APPID=application_1375859105306_0007	CONTAINERID=container_1375859105306_0007_01_000008
2013-08-07 07:16:41,239 INFO org.apache.hadoop.yarn.server.resourcemanager.scheduler.common.fica.FiCaSchedulerNode: Assigned container container_1375859105306_0007_01_000008 of capacity <memory:1024, vCores:1> on host hadoop-200-7:58499, which currently has 6 containers, <memory:6144, vCores:6> used and <memory:2048, vCores:10> available
2013-08-07 07:16:41,240 INFO org.apache.hadoop.yarn.server.resourcemanager.scheduler.capacity.LeafQueue: assignedContainer application=application_1375859105306_0007 container=Container: [ContainerId: container_1375859105306_0007_01_000008, NodeId: hadoop-200-7:58499, NodeHttpAddress: hadoop-200-7:8042, Resource: <memory:1024, vCores:1>, Priority: 20, State: NEW, Token: null, Status: container_id {, app_attempt_id {, application_id {, id: 7, cluster_timestamp: 1375859105306, }, attemptId: 1, }, id: 8, }, state: C_NEW, ] containerId=container_1375859105306_0007_01_000008 queue=default: capacity=1.0, absoluteCapacity=1.0, usedResources=<memory:46080, vCores:40>usedCapacity=0.9375, absoluteUsedCapacity=0.9375, numApps=5, numContainers=40 usedCapacity=0.9375 absoluteUsedCapacity=0.9375 used=<memory:46080, vCores:40> cluster=<memory:49152, vCores:96>
2013-08-07 07:16:41,240 INFO org.apache.hadoop.yarn.server.resourcemanager.scheduler.capacity.ParentQueue: Re-sorting queues since queue: root.default stats: default: capacity=1.0, absoluteCapacity=1.0, usedResources=<memory:47104, vCores:41>usedCapacity=0.9583333, absoluteUsedCapacity=0.9583333, numApps=5, numContainers=41
2013-08-07 07:16:41,240 INFO org.apache.hadoop.yarn.server.resourcemanager.scheduler.capacity.ParentQueue: assignedContainer queue=root usedCapacity=0.9583333 absoluteUsedCapacity=0.9583333 used=<memory:47104, vCores:41> cluster=<memory:49152, vCores:96>
2013-08-07 07:16:41,241 INFO org.apache.hadoop.yarn.server.resourcemanager.rmcontainer.RMContainerImpl: container_1375859105306_0007_01_000009 Container Transitioned from NEW to ALLOCATED
2013-08-07 07:16:41,241 INFO org.apache.hadoop.yarn.server.resourcemanager.RMAuditLogger: USER=ubuntu	OPERATION=AM Allocated Container	TARGET=SchedulerApp	RESULT=SUCCESS	APPID=application_1375859105306_0007	CONTAINERID=container_1375859105306_0007_01_000009
2013-08-07 07:16:41,241 INFO org.apache.hadoop.yarn.server.resourcemanager.scheduler.common.fica.FiCaSchedulerNode: Assigned container container_1375859105306_0007_01_000009 of capacity <memory:1024, vCores:1> on host hadoop-200-7:58499, which currently has 7 containers, <memory:7168, vCores:7> used and <memory:1024, vCores:9> available
2013-08-07 07:16:41,242 INFO org.apache.hadoop.yarn.server.resourcemanager.scheduler.capacity.LeafQueue: assignedContainer application=application_1375859105306_0007 container=Container: [ContainerId: container_1375859105306_0007_01_000009, NodeId: hadoop-200-7:58499, NodeHttpAddress: hadoop-200-7:8042, Resource: <memory:1024, vCores:1>, Priority: 20, State: NEW, Token: null, Status: container_id {, app_attempt_id {, application_id {, id: 7, cluster_timestamp: 1375859105306, }, attemptId: 1, }, id: 9, }, state: C_NEW, ] containerId=container_1375859105306_0007_01_000009 queue=default: capacity=1.0, absoluteCapacity=1.0, usedResources=<memory:47104, vCores:41>usedCapacity=0.9583333, absoluteUsedCapacity=0.9583333, numApps=5, numContainers=41 usedCapacity=0.9583333 absoluteUsedCapacity=0.9583333 used=<memory:47104, vCores:41> cluster=<memory:49152, vCores:96>
2013-08-07 07:16:41,242 INFO org.apache.hadoop.yarn.server.resourcemanager.scheduler.capacity.ParentQueue: Re-sorting queues since queue: root.default stats: default: capacity=1.0, absoluteCapacity=1.0, usedResources=<memory:48128, vCores:42>usedCapacity=0.9791667, absoluteUsedCapacity=0.9791667, numApps=5, numContainers=42
2013-08-07 07:16:41,242 INFO org.apache.hadoop.yarn.server.resourcemanager.scheduler.capacity.ParentQueue: assignedContainer queue=root usedCapacity=0.9791667 absoluteUsedCapacity=0.9791667 used=<memory:48128, vCores:42> cluster=<memory:49152, vCores:96>
2013-08-07 07:16:41,243 INFO org.apache.hadoop.yarn.server.resourcemanager.rmcontainer.RMContainerImpl: container_1375859105306_0007_01_000010 Container Transitioned from NEW to ALLOCATED
2013-08-07 07:16:41,243 INFO org.apache.hadoop.yarn.server.resourcemanager.RMAuditLogger: USER=ubuntu	OPERATION=AM Allocated Container	TARGET=SchedulerApp	RESULT=SUCCESS	APPID=application_1375859105306_0007	CONTAINERID=container_1375859105306_0007_01_000010
2013-08-07 07:16:41,243 INFO org.apache.hadoop.yarn.server.resourcemanager.scheduler.common.fica.FiCaSchedulerNode: Assigned container container_1375859105306_0007_01_000010 of capacity <memory:1024, vCores:1> on host hadoop-200-7:58499, which currently has 8 containers, <memory:8192, vCores:8> used and <memory:0, vCores:8> available
2013-08-07 07:16:41,244 INFO org.apache.hadoop.yarn.server.resourcemanager.scheduler.capacity.LeafQueue: assignedContainer application=application_1375859105306_0007 container=Container: [ContainerId: container_1375859105306_0007_01_000010, NodeId: hadoop-200-7:58499, NodeHttpAddress: hadoop-200-7:8042, Resource: <memory:1024, vCores:1>, Priority: 20, State: NEW, Token: null, Status: container_id {, app_attempt_id {, application_id {, id: 7, cluster_timestamp: 1375859105306, }, attemptId: 1, }, id: 10, }, state: C_NEW, ] containerId=container_1375859105306_0007_01_000010 queue=default: capacity=1.0, absoluteCapacity=1.0, usedResources=<memory:48128, vCores:42>usedCapacity=0.9791667, absoluteUsedCapacity=0.9791667, numApps=5, numContainers=42 usedCapacity=0.9791667 absoluteUsedCapacity=0.9791667 used=<memory:48128, vCores:42> cluster=<memory:49152, vCores:96>
2013-08-07 07:16:41,245 INFO org.apache.hadoop.yarn.server.resourcemanager.scheduler.capacity.ParentQueue: Re-sorting queues since queue: root.default stats: default: capacity=1.0, absoluteCapacity=1.0, usedResources=<memory:49152, vCores:43>usedCapacity=1.0, absoluteUsedCapacity=1.0, numApps=5, numContainers=43
2013-08-07 07:16:41,245 INFO org.apache.hadoop.yarn.server.resourcemanager.scheduler.capacity.ParentQueue: assignedContainer queue=root usedCapacity=1.0 absoluteUsedCapacity=1.0 used=<memory:49152, vCores:43> cluster=<memory:49152, vCores:96>
2013-08-07 07:16:41,282 INFO org.apache.hadoop.yarn.server.resourcemanager.rmcontainer.RMContainerImpl: container_1375859105306_0006_01_000017 Container Transitioned from RUNNING to COMPLETED
2013-08-07 07:16:41,283 INFO org.apache.hadoop.yarn.server.resourcemanager.scheduler.common.fica.FiCaSchedulerApp: Completed container: container_1375859105306_0006_01_000017 in state: COMPLETED event:FINISHED
2013-08-07 07:16:41,283 INFO org.apache.hadoop.yarn.server.resourcemanager.RMAuditLogger: USER=ubuntu	OPERATION=AM Released Container	TARGET=SchedulerApp	RESULT=SUCCESS	APPID=application_1375859105306_0006	CONTAINERID=container_1375859105306_0006_01_000017
2013-08-07 07:16:41,283 INFO org.apache.hadoop.yarn.server.resourcemanager.scheduler.common.fica.FiCaSchedulerNode: Released container container_1375859105306_0006_01_000017 of capacity <memory:1024, vCores:1> on host hadoop-200-6:34031, which currently has 7 containers, <memory:7168, vCores:7> used and <memory:1024, vCores:9> available, release resources=true
2013-08-07 07:16:41,283 INFO org.apache.hadoop.yarn.server.resourcemanager.scheduler.capacity.LeafQueue: default used=<memory:48128, vCores:42> numContainers=42 user=ubuntu user-resources=<memory:48128, vCores:42>
2013-08-07 07:16:41,284 INFO org.apache.hadoop.yarn.server.resourcemanager.scheduler.capacity.LeafQueue: completedContainer container=Container: [ContainerId: container_1375859105306_0006_01_000017, NodeId: hadoop-200-6:34031, NodeHttpAddress: hadoop-200-6:8042, Resource: <memory:1024, vCores:1>, Priority: 20, State: NEW, Token: null, Status: container_id {, app_attempt_id {, application_id {, id: 6, cluster_timestamp: 1375859105306, }, attemptId: 1, }, id: 17, }, state: C_COMPLETE, diagnostics: "", exit_status: 0, ] resource=<memory:1024, vCores:1> queue=default: capacity=1.0, absoluteCapacity=1.0, usedResources=<memory:48128, vCores:42>usedCapacity=0.9791667, absoluteUsedCapacity=0.9791667, numApps=5, numContainers=42 usedCapacity=0.9791667 absoluteUsedCapacity=0.9791667 used=<memory:48128, vCores:42> cluster=<memory:49152, vCores:96>
2013-08-07 07:16:41,284 INFO org.apache.hadoop.yarn.server.resourcemanager.scheduler.capacity.ParentQueue: completedContainer queue=root usedCapacity=0.9791667 absoluteUsedCapacity=0.9791667 used=<memory:48128, vCores:42> cluster=<memory:49152, vCores:96>
2013-08-07 07:16:41,285 INFO org.apache.hadoop.yarn.server.resourcemanager.scheduler.capacity.CapacityScheduler: Application appattempt_1375859105306_0006_000001 released container container_1375859105306_0006_01_000017 on node: host: hadoop-200-6:34031 #containers=7 available=1024 used=7168 with event: FINISHED
2013-08-07 07:16:41,285 INFO org.apache.hadoop.yarn.server.resourcemanager.rmcontainer.RMContainerImpl: container_1375859105306_0007_01_000011 Container Transitioned from NEW to ALLOCATED
2013-08-07 07:16:41,285 INFO org.apache.hadoop.yarn.server.resourcemanager.RMAuditLogger: USER=ubuntu	OPERATION=AM Allocated Container	TARGET=SchedulerApp	RESULT=SUCCESS	APPID=application_1375859105306_0007	CONTAINERID=container_1375859105306_0007_01_000011
2013-08-07 07:16:41,286 INFO org.apache.hadoop.yarn.server.resourcemanager.scheduler.common.fica.FiCaSchedulerNode: Assigned container container_1375859105306_0007_01_000011 of capacity <memory:1024, vCores:1> on host hadoop-200-6:34031, which currently has 8 containers, <memory:8192, vCores:8> used and <memory:0, vCores:8> available
2013-08-07 07:16:41,286 INFO org.apache.hadoop.yarn.server.resourcemanager.scheduler.capacity.LeafQueue: assignedContainer application=application_1375859105306_0007 container=Container: [ContainerId: container_1375859105306_0007_01_000011, NodeId: hadoop-200-6:34031, NodeHttpAddress: hadoop-200-6:8042, Resource: <memory:1024, vCores:1>, Priority: 20, State: NEW, Token: null, Status: container_id {, app_attempt_id {, application_id {, id: 7, cluster_timestamp: 1375859105306, }, attemptId: 1, }, id: 11, }, state: C_NEW, ] containerId=container_1375859105306_0007_01_000011 queue=default: capacity=1.0, absoluteCapacity=1.0, usedResources=<memory:48128, vCores:42>usedCapacity=0.9791667, absoluteUsedCapacity=0.9791667, numApps=5, numContainers=42 usedCapacity=0.9791667 absoluteUsedCapacity=0.9791667 used=<memory:48128, vCores:42> cluster=<memory:49152, vCores:96>
2013-08-07 07:16:41,287 INFO org.apache.hadoop.yarn.server.resourcemanager.scheduler.capacity.ParentQueue: Re-sorting queues since queue: root.default stats: default: capacity=1.0, absoluteCapacity=1.0, usedResources=<memory:49152, vCores:43>usedCapacity=1.0, absoluteUsedCapacity=1.0, numApps=5, numContainers=43
2013-08-07 07:16:41,287 INFO org.apache.hadoop.yarn.server.resourcemanager.scheduler.capacity.ParentQueue: assignedContainer queue=root usedCapacity=1.0 absoluteUsedCapacity=1.0 used=<memory:49152, vCores:43> cluster=<memory:49152, vCores:96>
2013-08-07 07:16:41,636 INFO org.apache.hadoop.yarn.server.resourcemanager.rmcontainer.RMContainerImpl: container_1375859105306_0007_01_000006 Container Transitioned from ALLOCATED to ACQUIRED
2013-08-07 07:16:41,637 INFO org.apache.hadoop.yarn.server.resourcemanager.rmcontainer.RMContainerImpl: container_1375859105306_0007_01_000007 Container Transitioned from ALLOCATED to ACQUIRED
2013-08-07 07:16:41,637 INFO org.apache.hadoop.yarn.server.resourcemanager.rmcontainer.RMContainerImpl: container_1375859105306_0007_01_000008 Container Transitioned from ALLOCATED to ACQUIRED
2013-08-07 07:16:41,637 INFO org.apache.hadoop.yarn.server.resourcemanager.rmcontainer.RMContainerImpl: container_1375859105306_0007_01_000009 Container Transitioned from ALLOCATED to ACQUIRED
2013-08-07 07:16:41,637 INFO org.apache.hadoop.yarn.server.resourcemanager.rmcontainer.RMContainerImpl: container_1375859105306_0007_01_000010 Container Transitioned from ALLOCATED to ACQUIRED
2013-08-07 07:16:41,638 INFO org.apache.hadoop.yarn.server.resourcemanager.rmcontainer.RMContainerImpl: container_1375859105306_0007_01_000011 Container Transitioned from ALLOCATED to ACQUIRED
2013-08-07 07:16:41,791 INFO org.apache.hadoop.yarn.server.resourcemanager.rmcontainer.RMContainerImpl: container_1375859105306_0006_01_000019 Container Transitioned from RUNNING to COMPLETED
2013-08-07 07:16:41,791 INFO org.apache.hadoop.yarn.server.resourcemanager.scheduler.common.fica.FiCaSchedulerApp: Completed container: container_1375859105306_0006_01_000019 in state: COMPLETED event:FINISHED
2013-08-07 07:16:41,792 INFO org.apache.hadoop.yarn.server.resourcemanager.RMAuditLogger: USER=ubuntu	OPERATION=AM Released Container	TARGET=SchedulerApp	RESULT=SUCCESS	APPID=application_1375859105306_0006	CONTAINERID=container_1375859105306_0006_01_000019
2013-08-07 07:16:41,792 INFO org.apache.hadoop.yarn.server.resourcemanager.scheduler.common.fica.FiCaSchedulerNode: Released container container_1375859105306_0006_01_000019 of capacity <memory:1024, vCores:1> on host hadoop-200-6:34031, which currently has 7 containers, <memory:7168, vCores:7> used and <memory:1024, vCores:9> available, release resources=true
2013-08-07 07:16:41,792 INFO org.apache.hadoop.yarn.server.resourcemanager.scheduler.capacity.LeafQueue: default used=<memory:48128, vCores:42> numContainers=42 user=ubuntu user-resources=<memory:48128, vCores:42>
2013-08-07 07:16:41,793 INFO org.apache.hadoop.yarn.server.resourcemanager.scheduler.capacity.LeafQueue: completedContainer container=Container: [ContainerId: container_1375859105306_0006_01_000019, NodeId: hadoop-200-6:34031, NodeHttpAddress: hadoop-200-6:8042, Resource: <memory:1024, vCores:1>, Priority: 20, State: NEW, Token: null, Status: container_id {, app_attempt_id {, application_id {, id: 6, cluster_timestamp: 1375859105306, }, attemptId: 1, }, id: 19, }, state: C_COMPLETE, diagnostics: "", exit_status: 0, ] resource=<memory:1024, vCores:1> queue=default: capacity=1.0, absoluteCapacity=1.0, usedResources=<memory:48128, vCores:42>usedCapacity=0.9791667, absoluteUsedCapacity=0.9791667, numApps=5, numContainers=42 usedCapacity=0.9791667 absoluteUsedCapacity=0.9791667 used=<memory:48128, vCores:42> cluster=<memory:49152, vCores:96>
2013-08-07 07:16:41,793 INFO org.apache.hadoop.yarn.server.resourcemanager.scheduler.capacity.ParentQueue: completedContainer queue=root usedCapacity=0.9791667 absoluteUsedCapacity=0.9791667 used=<memory:48128, vCores:42> cluster=<memory:49152, vCores:96>
2013-08-07 07:16:41,794 INFO org.apache.hadoop.yarn.server.resourcemanager.scheduler.capacity.CapacityScheduler: Application appattempt_1375859105306_0006_000001 released container container_1375859105306_0006_01_000019 on node: host: hadoop-200-6:34031 #containers=7 available=1024 used=7168 with event: FINISHED
2013-08-07 07:16:41,794 INFO org.apache.hadoop.yarn.server.resourcemanager.rmcontainer.RMContainerImpl: container_1375859105306_0007_01_000012 Container Transitioned from NEW to ALLOCATED
2013-08-07 07:16:41,794 INFO org.apache.hadoop.yarn.server.resourcemanager.RMAuditLogger: USER=ubuntu	OPERATION=AM Allocated Container	TARGET=SchedulerApp	RESULT=SUCCESS	APPID=application_1375859105306_0007	CONTAINERID=container_1375859105306_0007_01_000012
2013-08-07 07:16:41,795 INFO org.apache.hadoop.yarn.server.resourcemanager.scheduler.common.fica.FiCaSchedulerNode: Assigned container container_1375859105306_0007_01_000012 of capacity <memory:1024, vCores:1> on host hadoop-200-6:34031, which currently has 8 containers, <memory:8192, vCores:8> used and <memory:0, vCores:8> available
2013-08-07 07:16:41,795 INFO org.apache.hadoop.yarn.server.resourcemanager.scheduler.capacity.LeafQueue: assignedContainer application=application_1375859105306_0007 container=Container: [ContainerId: container_1375859105306_0007_01_000012, NodeId: hadoop-200-6:34031, NodeHttpAddress: hadoop-200-6:8042, Resource: <memory:1024, vCores:1>, Priority: 20, State: NEW, Token: null, Status: container_id {, app_attempt_id {, application_id {, id: 7, cluster_timestamp: 1375859105306, }, attemptId: 1, }, id: 12, }, state: C_NEW, ] containerId=container_1375859105306_0007_01_000012 queue=default: capacity=1.0, absoluteCapacity=1.0, usedResources=<memory:48128, vCores:42>usedCapacity=0.9791667, absoluteUsedCapacity=0.9791667, numApps=5, numContainers=42 usedCapacity=0.9791667 absoluteUsedCapacity=0.9791667 used=<memory:48128, vCores:42> cluster=<memory:49152, vCores:96>
2013-08-07 07:16:41,796 INFO org.apache.hadoop.yarn.server.resourcemanager.scheduler.capacity.ParentQueue: Re-sorting queues since queue: root.default stats: default: capacity=1.0, absoluteCapacity=1.0, usedResources=<memory:49152, vCores:43>usedCapacity=1.0, absoluteUsedCapacity=1.0, numApps=5, numContainers=43
2013-08-07 07:16:41,796 INFO org.apache.hadoop.yarn.server.resourcemanager.scheduler.capacity.ParentQueue: assignedContainer queue=root usedCapacity=1.0 absoluteUsedCapacity=1.0 used=<memory:49152, vCores:43> cluster=<memory:49152, vCores:96>
2013-08-07 07:16:42,238 INFO org.apache.hadoop.yarn.server.resourcemanager.rmcontainer.RMContainerImpl: container_1375859105306_0006_01_000025 Container Transitioned from RUNNING to COMPLETED
2013-08-07 07:16:42,238 INFO org.apache.hadoop.yarn.server.resourcemanager.scheduler.common.fica.FiCaSchedulerApp: Completed container: container_1375859105306_0006_01_000025 in state: COMPLETED event:FINISHED
2013-08-07 07:16:42,239 INFO org.apache.hadoop.yarn.server.resourcemanager.RMAuditLogger: USER=ubuntu	OPERATION=AM Released Container	TARGET=SchedulerApp	RESULT=SUCCESS	APPID=application_1375859105306_0006	CONTAINERID=container_1375859105306_0006_01_000025
2013-08-07 07:16:42,239 INFO org.apache.hadoop.yarn.server.resourcemanager.scheduler.common.fica.FiCaSchedulerNode: Released container container_1375859105306_0006_01_000025 of capacity <memory:1024, vCores:1> on host hadoop-200-7:58499, which currently has 7 containers, <memory:7168, vCores:7> used and <memory:1024, vCores:9> available, release resources=true
2013-08-07 07:16:42,239 INFO org.apache.hadoop.yarn.server.resourcemanager.scheduler.capacity.LeafQueue: default used=<memory:48128, vCores:42> numContainers=42 user=ubuntu user-resources=<memory:48128, vCores:42>
2013-08-07 07:16:42,240 INFO org.apache.hadoop.yarn.server.resourcemanager.scheduler.capacity.LeafQueue: completedContainer container=Container: [ContainerId: container_1375859105306_0006_01_000025, NodeId: hadoop-200-7:58499, NodeHttpAddress: hadoop-200-7:8042, Resource: <memory:1024, vCores:1>, Priority: 20, State: NEW, Token: null, Status: container_id {, app_attempt_id {, application_id {, id: 6, cluster_timestamp: 1375859105306, }, attemptId: 1, }, id: 25, }, state: C_COMPLETE, diagnostics: "Container killed by the ApplicationMaster.\n\n", exit_status: 143, ] resource=<memory:1024, vCores:1> queue=default: capacity=1.0, absoluteCapacity=1.0, usedResources=<memory:48128, vCores:42>usedCapacity=0.9791667, absoluteUsedCapacity=0.9791667, numApps=5, numContainers=42 usedCapacity=0.9791667 absoluteUsedCapacity=0.9791667 used=<memory:48128, vCores:42> cluster=<memory:49152, vCores:96>
2013-08-07 07:16:42,241 INFO org.apache.hadoop.yarn.server.resourcemanager.scheduler.capacity.ParentQueue: completedContainer queue=root usedCapacity=0.9791667 absoluteUsedCapacity=0.9791667 used=<memory:48128, vCores:42> cluster=<memory:49152, vCores:96>
2013-08-07 07:16:42,241 INFO org.apache.hadoop.yarn.server.resourcemanager.scheduler.capacity.CapacityScheduler: Application appattempt_1375859105306_0006_000001 released container container_1375859105306_0006_01_000025 on node: host: hadoop-200-7:58499 #containers=7 available=1024 used=7168 with event: FINISHED
2013-08-07 07:16:42,241 INFO org.apache.hadoop.yarn.server.resourcemanager.rmcontainer.RMContainerImpl: container_1375859105306_0007_01_000013 Container Transitioned from NEW to ALLOCATED
2013-08-07 07:16:42,242 INFO org.apache.hadoop.yarn.server.resourcemanager.RMAuditLogger: USER=ubuntu	OPERATION=AM Allocated Container	TARGET=SchedulerApp	RESULT=SUCCESS	APPID=application_1375859105306_0007	CONTAINERID=container_1375859105306_0007_01_000013
2013-08-07 07:16:42,242 INFO org.apache.hadoop.yarn.server.resourcemanager.scheduler.common.fica.FiCaSchedulerNode: Assigned container container_1375859105306_0007_01_000013 of capacity <memory:1024, vCores:1> on host hadoop-200-7:58499, which currently has 8 containers, <memory:8192, vCores:8> used and <memory:0, vCores:8> available
2013-08-07 07:16:42,243 INFO org.apache.hadoop.yarn.server.resourcemanager.scheduler.capacity.LeafQueue: assignedContainer application=application_1375859105306_0007 container=Container: [ContainerId: container_1375859105306_0007_01_000013, NodeId: hadoop-200-7:58499, NodeHttpAddress: hadoop-200-7:8042, Resource: <memory:1024, vCores:1>, Priority: 20, State: NEW, Token: null, Status: container_id {, app_attempt_id {, application_id {, id: 7, cluster_timestamp: 1375859105306, }, attemptId: 1, }, id: 13, }, state: C_NEW, ] containerId=container_1375859105306_0007_01_000013 queue=default: capacity=1.0, absoluteCapacity=1.0, usedResources=<memory:48128, vCores:42>usedCapacity=0.9791667, absoluteUsedCapacity=0.9791667, numApps=5, numContainers=42 usedCapacity=0.9791667 absoluteUsedCapacity=0.9791667 used=<memory:48128, vCores:42> cluster=<memory:49152, vCores:96>
2013-08-07 07:16:42,243 INFO org.apache.hadoop.yarn.server.resourcemanager.scheduler.capacity.ParentQueue: Re-sorting queues since queue: root.default stats: default: capacity=1.0, absoluteCapacity=1.0, usedResources=<memory:49152, vCores:43>usedCapacity=1.0, absoluteUsedCapacity=1.0, numApps=5, numContainers=43
2013-08-07 07:16:42,243 INFO org.apache.hadoop.yarn.server.resourcemanager.scheduler.capacity.ParentQueue: assignedContainer queue=root usedCapacity=1.0 absoluteUsedCapacity=1.0 used=<memory:49152, vCores:43> cluster=<memory:49152, vCores:96>
2013-08-07 07:16:42,724 INFO org.apache.hadoop.yarn.server.resourcemanager.rmcontainer.RMContainerImpl: container_1375859105306_0007_01_000007 Container Transitioned from ACQUIRED to RUNNING
2013-08-07 07:16:42,725 INFO org.apache.hadoop.yarn.server.resourcemanager.rmcontainer.RMContainerImpl: container_1375859105306_0006_01_000013 Container Transitioned from RUNNING to COMPLETED
