2013-08-31 00:09:24,791 INFO org.apache.hadoop.yarn.server.resourcemanager.ResourceManager: STARTUP_MSG: 
/************************************************************
STARTUP_MSG: Starting ResourceManager
STARTUP_MSG:   host = hadoop-32-1/192.168.100.5
STARTUP_MSG:   args = []
STARTUP_MSG:   version = 3.0.0-SNAPSHOT
STARTUP_MSG:   build = https://github.com/lalithsuresh/hadoop-common -r 0cb423bd4868928bb06cd93f882bb0913172fd17; compiled by 'lsuresh' on 2013-04-08T15:47Z
STARTUP_MSG:   java = 1.7.0_17
************************************************************/
2013-08-31 00:09:24,803 INFO org.apache.hadoop.yarn.server.resourcemanager.ResourceManager: registered UNIX signal handlers for [TERM, HUP, INT]
2013-08-31 00:09:25,481 INFO org.apache.hadoop.yarn.server.resourcemanager.security.ApplicationTokenSecretManager: Rolling master-key for application-tokens
2013-08-31 00:09:25,532 INFO org.apache.hadoop.yarn.server.resourcemanager.security.RMContainerTokenSecretManager: ContainerTokenKeyRollingInterval: 86400000ms and ContainerTokenKeyActivationDelay: 900000ms
2013-08-31 00:09:25,536 INFO org.apache.hadoop.yarn.service.AbstractService: Service:Dispatcher is inited.
2013-08-31 00:09:25,539 INFO org.apache.hadoop.yarn.event.AsyncDispatcher: Registering class org.apache.hadoop.yarn.server.resourcemanager.recovery.RMStateStoreEventType for class org.apache.hadoop.yarn.server.resourcemanager.recovery.RMStateStore$ForwardingEventHandler
2013-08-31 00:09:25,540 INFO org.apache.hadoop.yarn.service.AbstractService: Service:Dispatcher is started.
2013-08-31 00:09:25,549 INFO org.apache.hadoop.yarn.event.AsyncDispatcher: Registering class org.apache.hadoop.yarn.server.resourcemanager.NodesListManagerEventType for class org.apache.hadoop.yarn.server.resourcemanager.NodesListManager
2013-08-31 00:09:25,550 INFO org.apache.hadoop.yarn.server.resourcemanager.ResourceManager: Using Scheduler: org.apache.hadoop.yarn.server.resourcemanager.scheduler.capacity.CapacityScheduler
2013-08-31 00:09:25,847 INFO org.apache.hadoop.yarn.event.AsyncDispatcher: Registering class org.apache.hadoop.yarn.server.resourcemanager.scheduler.event.SchedulerEventType for class org.apache.hadoop.yarn.server.resourcemanager.ResourceManager$SchedulerEventDispatcher
2013-08-31 00:09:25,858 INFO org.apache.hadoop.yarn.event.AsyncDispatcher: Registering class org.apache.hadoop.yarn.server.resourcemanager.rmapp.RMAppEventType for class org.apache.hadoop.yarn.server.resourcemanager.ResourceManager$ApplicationEventDispatcher
2013-08-31 00:09:25,861 INFO org.apache.hadoop.yarn.event.AsyncDispatcher: Registering class org.apache.hadoop.yarn.server.resourcemanager.rmapp.attempt.RMAppAttemptEventType for class org.apache.hadoop.yarn.server.resourcemanager.ResourceManager$ApplicationAttemptEventDispatcher
2013-08-31 00:09:25,871 INFO org.apache.hadoop.yarn.event.AsyncDispatcher: Registering class org.apache.hadoop.yarn.server.resourcemanager.rmnode.RMNodeEventType for class org.apache.hadoop.yarn.server.resourcemanager.ResourceManager$NodeEventDispatcher
2013-08-31 00:09:26,425 WARN org.apache.hadoop.util.NativeCodeLoader: Unable to load native-hadoop library for your platform... using builtin-java classes where applicable
2013-08-31 00:09:26,443 INFO org.apache.hadoop.yarn.server.resourcemanager.scheduler.capacity.ParentQueue: root, capacity=1.0, asboluteCapacity=1.0, maxCapacity=1.0, asboluteMaxCapacity=1.0, state=RUNNING, acls=ADMINISTER_QUEUE:*SUBMIT_APPLICATIONS:*
2013-08-31 00:09:26,443 INFO org.apache.hadoop.yarn.server.resourcemanager.scheduler.capacity.ParentQueue: Initialized parent-queue root name=root, fullname=root
2013-08-31 00:09:26,454 INFO org.apache.hadoop.yarn.server.resourcemanager.scheduler.capacity.LeafQueue: Initializing default
capacity = 1.0 [= (float) configuredCapacity / 100 ]
asboluteCapacity = 1.0 [= parentAbsoluteCapacity * capacity ]
maxCapacity = 1.0 [= configuredMaxCapacity ]
absoluteMaxCapacity = 1.0 [= 1.0 maximumCapacity undefined, (parentAbsoluteMaxCapacity * maximumCapacity) / 100 otherwise ]
userLimit = 100 [= configuredUserLimit ]
userLimitFactor = 1.0 [= configuredUserLimitFactor ]
maxApplications = 10000 [= configuredMaximumSystemApplicationsPerQueue or (int)(configuredMaximumSystemApplications * absoluteCapacity)]
maxApplicationsPerUser = 10000 [= (int)(maxApplications * (userLimit / 100.0f) * userLimitFactor) ]
maxActiveApplications = 1 [= max((int)ceil((clusterResourceMemory / minimumAllocation) * maxAMResourcePerQueuePercent * absoluteMaxCapacity),1) ]
maxActiveAppsUsingAbsCap = 1 [= max((int)ceil((clusterResourceMemory / minimumAllocation) *maxAMResourcePercent * absoluteCapacity),1) ]
maxActiveApplicationsPerUser = 1 [= max((int)(maxActiveApplications * (userLimit / 100.0f) * userLimitFactor),1) ]
usedCapacity = 0.0 [= usedResourcesMemory / (clusterResourceMemory * absoluteCapacity)]
absoluteUsedCapacity = 0.0 [= usedResourcesMemory / clusterResourceMemory]
maxAMResourcePerQueuePercent = 0.1 [= configuredMaximumAMResourcePercent ]
minimumAllocationFactor = 0.875 [= (float)(maximumAllocationMemory - minimumAllocationMemory) / maximumAllocationMemory ]
numContainers = 0 [= currentNumContainers ]
state = RUNNING [= configuredState ]
acls = ADMINISTER_QUEUE:*SUBMIT_APPLICATIONS:* [= configuredAcls ]

2013-08-31 00:09:26,454 INFO org.apache.hadoop.yarn.server.resourcemanager.scheduler.capacity.CapacityScheduler: Initialized queue: default: capacity=1.0, absoluteCapacity=1.0, usedResources=<memory:0, vCores:0>usedCapacity=0.0, absoluteUsedCapacity=0.0, numApps=0, numContainers=0
2013-08-31 00:09:26,454 INFO org.apache.hadoop.yarn.server.resourcemanager.scheduler.capacity.CapacityScheduler: Initialized queue: root: numChildQueue= 1, capacity=1.0, absoluteCapacity=1.0, usedResources=<memory:0, vCores:0>usedCapacity=0.0, numApps=0, numContainers=0
2013-08-31 00:09:26,454 INFO org.apache.hadoop.yarn.server.resourcemanager.scheduler.capacity.CapacityScheduler: Initialized root queue root: numChildQueue= 1, capacity=1.0, absoluteCapacity=1.0, usedResources=<memory:0, vCores:0>usedCapacity=0.0, numApps=0, numContainers=0
2013-08-31 00:09:26,454 INFO org.apache.hadoop.yarn.server.resourcemanager.scheduler.capacity.CapacityScheduler: Initialized CapacityScheduler with calculator=class org.apache.hadoop.yarn.server.resourcemanager.resource.DefaultResourceCalculator, minimumAllocation=<<memory:1024, vCores:1>>, maximumAllocation=<<memory:8192, vCores:32>>
2013-08-31 00:09:26,792 INFO org.apache.hadoop.yarn.event.AsyncDispatcher: Registering class org.apache.hadoop.yarn.server.resourcemanager.RMAppManagerEventType for class org.apache.hadoop.yarn.server.resourcemanager.RMAppManager
2013-08-31 00:09:26,807 INFO org.apache.hadoop.yarn.event.AsyncDispatcher: Registering class org.apache.hadoop.yarn.server.resourcemanager.amlauncher.AMLauncherEventType for class org.apache.hadoop.yarn.server.resourcemanager.amlauncher.ApplicationMasterLauncher
2013-08-31 00:09:26,872 INFO org.apache.hadoop.yarn.server.resourcemanager.RMNMInfo: Registered RMNMInfo MBean
2013-08-31 00:09:26,872 INFO org.apache.hadoop.yarn.service.AbstractService: Service:Dispatcher is inited.
2013-08-31 00:09:26,872 INFO org.apache.hadoop.yarn.service.AbstractService: Service:org.apache.hadoop.yarn.server.resourcemanager.rmcontainer.ContainerAllocationExpirer is inited.
2013-08-31 00:09:26,872 INFO org.apache.hadoop.yarn.service.AbstractService: Service:AMLivelinessMonitor is inited.
2013-08-31 00:09:26,872 INFO org.apache.hadoop.yarn.service.AbstractService: Service:AMLivelinessMonitor is inited.
2013-08-31 00:09:26,872 INFO org.apache.hadoop.yarn.service.AbstractService: Service:org.apache.hadoop.yarn.server.resourcemanager.security.DelegationTokenRenewer is inited.
2013-08-31 00:09:26,874 INFO org.apache.hadoop.util.HostsFileReader: Refreshing hosts (include/exclude) list
2013-08-31 00:09:26,874 INFO org.apache.hadoop.yarn.service.AbstractService: Service:org.apache.hadoop.yarn.server.resourcemanager.NodesListManager is inited.
2013-08-31 00:09:26,874 INFO org.apache.hadoop.yarn.service.AbstractService: Service:org.apache.hadoop.yarn.server.resourcemanager.ResourceManager$SchedulerEventDispatcher is inited.
2013-08-31 00:09:26,874 INFO org.apache.hadoop.yarn.service.AbstractService: Service:NMLivelinessMonitor is inited.
2013-08-31 00:09:26,879 INFO org.apache.hadoop.yarn.service.AbstractService: Service:org.apache.hadoop.yarn.server.resourcemanager.ResourceTrackerService is inited.
2013-08-31 00:09:26,879 INFO org.apache.hadoop.yarn.service.AbstractService: Service:org.apache.hadoop.yarn.server.resourcemanager.ApplicationMasterService is inited.
2013-08-31 00:09:26,879 INFO org.apache.hadoop.yarn.service.AbstractService: Service:org.apache.hadoop.yarn.server.resourcemanager.ClientRMService is inited.
2013-08-31 00:09:26,879 INFO org.apache.hadoop.yarn.service.AbstractService: Service:org.apache.hadoop.yarn.server.resourcemanager.AdminService is inited.
2013-08-31 00:09:26,880 INFO org.apache.hadoop.yarn.service.AbstractService: Service:org.apache.hadoop.yarn.server.resourcemanager.amlauncher.ApplicationMasterLauncher is inited.
2013-08-31 00:09:26,880 INFO org.apache.hadoop.yarn.service.AbstractService: Service:ResourceManager is inited.
2013-08-31 00:09:26,880 INFO org.apache.hadoop.yarn.server.resourcemanager.security.RMContainerTokenSecretManager: Rolling master-key for container-tokens
2013-08-31 00:09:26,880 INFO org.apache.hadoop.yarn.server.resourcemanager.security.ApplicationTokenSecretManager: Rolling master-key for application-tokens
2013-08-31 00:09:26,984 INFO org.mortbay.log: Logging to org.slf4j.impl.Log4jLoggerAdapter(org.mortbay.log) via org.mortbay.log.Slf4jLog
2013-08-31 00:09:27,050 INFO org.apache.hadoop.http.HttpServer: Added global filter 'safety' (class=org.apache.hadoop.http.HttpServer$QuotingInputFilter)
2013-08-31 00:09:27,053 INFO org.apache.hadoop.http.HttpServer: Added filter static_user_filter (class=org.apache.hadoop.http.lib.StaticUserWebFilter$StaticUserFilter) to context cluster
2013-08-31 00:09:27,053 INFO org.apache.hadoop.http.HttpServer: Added filter static_user_filter (class=org.apache.hadoop.http.lib.StaticUserWebFilter$StaticUserFilter) to context static
2013-08-31 00:09:27,054 INFO org.apache.hadoop.http.HttpServer: Added filter static_user_filter (class=org.apache.hadoop.http.lib.StaticUserWebFilter$StaticUserFilter) to context logs
2013-08-31 00:09:27,058 INFO org.apache.hadoop.http.HttpServer: adding path spec: /cluster
2013-08-31 00:09:27,059 INFO org.apache.hadoop.http.HttpServer: adding path spec: /cluster/*
2013-08-31 00:09:27,059 INFO org.apache.hadoop.http.HttpServer: adding path spec: /ws
2013-08-31 00:09:27,059 INFO org.apache.hadoop.http.HttpServer: adding path spec: /ws/*
2013-08-31 00:09:27,061 INFO org.apache.hadoop.http.HttpServer: Added global filter 'guice' (class=com.google.inject.servlet.GuiceFilter)
2013-08-31 00:09:27,068 INFO org.apache.hadoop.http.HttpServer: Jetty bound to port 8088
2013-08-31 00:09:27,068 INFO org.mortbay.log: jetty-6.1.26
2013-08-31 00:09:27,103 INFO org.mortbay.log: Extract jar:file:/home/ubuntu/hadoop-3.0.0-SNAPSHOT/share/hadoop/yarn/hadoop-yarn-common-3.0.0-SNAPSHOT.jar!/webapps/cluster to /tmp/Jetty_0_0_0_0_8088_cluster____u0rgz3/webapp
2013-08-31 00:09:27,507 INFO org.mortbay.log: Started SelectChannelConnector@0.0.0.0:8088
2013-08-31 00:09:27,507 INFO org.apache.hadoop.yarn.webapp.WebApps: Web app /cluster started at 8088
2013-08-31 00:09:28,277 INFO org.apache.hadoop.yarn.webapp.WebApps: Registered webapp guice modules
2013-08-31 00:09:28,399 INFO org.apache.hadoop.metrics2.impl.MetricsConfig: loaded properties from hadoop-metrics2.properties
2013-08-31 00:09:28,436 INFO org.apache.hadoop.metrics2.impl.MetricsSystemImpl: Scheduled snapshot period at 10 second(s).
2013-08-31 00:09:28,436 INFO org.apache.hadoop.metrics2.impl.MetricsSystemImpl: ResourceManager metrics system started
2013-08-31 00:09:28,452 INFO org.apache.hadoop.security.token.delegation.AbstractDelegationTokenSecretManager: Updating the current master key for generating delegation tokens
2013-08-31 00:09:28,456 INFO org.apache.hadoop.yarn.service.AbstractService: Service:Dispatcher is started.
2013-08-31 00:09:28,457 INFO org.apache.hadoop.security.token.delegation.AbstractDelegationTokenSecretManager: Starting expired delegation token remover thread, tokenRemoverScanInterval=60 min(s)
2013-08-31 00:09:28,457 INFO org.apache.hadoop.security.token.delegation.AbstractDelegationTokenSecretManager: Updating the current master key for generating delegation tokens
2013-08-31 00:09:28,459 INFO org.apache.hadoop.yarn.service.AbstractService: Service:org.apache.hadoop.yarn.server.resourcemanager.rmcontainer.ContainerAllocationExpirer is started.
2013-08-31 00:09:28,459 INFO org.apache.hadoop.yarn.service.AbstractService: Service:AMLivelinessMonitor is started.
2013-08-31 00:09:28,460 INFO org.apache.hadoop.yarn.service.AbstractService: Service:AMLivelinessMonitor is started.
2013-08-31 00:09:28,460 INFO org.apache.hadoop.yarn.service.AbstractService: Service:org.apache.hadoop.yarn.server.resourcemanager.security.DelegationTokenRenewer is started.
2013-08-31 00:09:28,461 INFO org.apache.hadoop.yarn.service.AbstractService: Service:org.apache.hadoop.yarn.server.resourcemanager.NodesListManager is started.
2013-08-31 00:09:28,462 INFO org.apache.hadoop.yarn.service.AbstractService: Service:org.apache.hadoop.yarn.server.resourcemanager.ResourceManager$SchedulerEventDispatcher is started.
2013-08-31 00:09:28,462 INFO org.apache.hadoop.yarn.service.AbstractService: Service:NMLivelinessMonitor is started.
2013-08-31 00:09:28,462 INFO org.apache.hadoop.yarn.service.AbstractService: Service:org.apache.hadoop.yarn.server.resourcemanager.ResourceTrackerService is started.
2013-08-31 00:09:28,543 INFO org.apache.hadoop.ipc.Server: Starting Socket Reader #1 for port 54110
2013-08-31 00:09:28,588 INFO org.apache.hadoop.yarn.factories.impl.pb.RpcServerFactoryPBImpl: Adding protocol org.apache.hadoop.yarn.server.api.ResourceTrackerPB to the server
2013-08-31 00:09:28,589 INFO org.apache.hadoop.ipc.Server: IPC Server Responder: starting
2013-08-31 00:09:28,589 INFO org.apache.hadoop.ipc.Server: IPC Server listener on 54110: starting
2013-08-31 00:09:28,704 INFO org.apache.hadoop.ipc.Server: Starting Socket Reader #1 for port 54112
2013-08-31 00:09:28,712 INFO org.apache.hadoop.yarn.factories.impl.pb.RpcServerFactoryPBImpl: Adding protocol org.apache.hadoop.yarn.api.AMRMProtocolPB to the server
2013-08-31 00:09:28,714 INFO org.apache.hadoop.ipc.Server: IPC Server listener on 54112: starting
2013-08-31 00:09:28,714 INFO org.apache.hadoop.ipc.Server: IPC Server Responder: starting
2013-08-31 00:09:28,747 INFO org.apache.hadoop.yarn.service.AbstractService: Service:org.apache.hadoop.yarn.server.resourcemanager.ApplicationMasterService is started.
2013-08-31 00:09:28,794 INFO org.apache.hadoop.ipc.Server: Starting Socket Reader #1 for port 54111
2013-08-31 00:09:28,799 INFO org.apache.hadoop.yarn.factories.impl.pb.RpcServerFactoryPBImpl: Adding protocol org.apache.hadoop.yarn.api.ClientRMProtocolPB to the server
2013-08-31 00:09:28,800 INFO org.apache.hadoop.ipc.Server: IPC Server Responder: starting
2013-08-31 00:09:28,801 INFO org.apache.hadoop.ipc.Server: IPC Server listener on 54111: starting
2013-08-31 00:09:28,847 INFO org.apache.hadoop.yarn.service.AbstractService: Service:org.apache.hadoop.yarn.server.resourcemanager.ClientRMService is started.
2013-08-31 00:09:28,889 INFO org.apache.hadoop.ipc.Server: Starting Socket Reader #1 for port 8033
2013-08-31 00:09:28,895 INFO org.apache.hadoop.yarn.factories.impl.pb.RpcServerFactoryPBImpl: Adding protocol org.apache.hadoop.yarn.api.RMAdminProtocolPB to the server
2013-08-31 00:09:28,896 INFO org.apache.hadoop.ipc.Server: IPC Server Responder: starting
2013-08-31 00:09:28,897 INFO org.apache.hadoop.ipc.Server: IPC Server listener on 8033: starting
2013-08-31 00:09:28,898 INFO org.apache.hadoop.yarn.service.AbstractService: Service:org.apache.hadoop.yarn.server.resourcemanager.AdminService is started.
2013-08-31 00:09:28,908 INFO org.apache.hadoop.yarn.service.AbstractService: Service:org.apache.hadoop.yarn.server.resourcemanager.amlauncher.ApplicationMasterLauncher is started.
2013-08-31 00:09:28,908 INFO org.apache.hadoop.yarn.service.AbstractService: Service:ResourceManager is started.
2013-08-31 00:09:39,081 INFO org.apache.hadoop.yarn.util.RackResolver: Resolved hadoop-32-2 to /default-rack
2013-08-31 00:09:39,086 INFO org.apache.hadoop.yarn.server.resourcemanager.ResourceTrackerService: NodeManager from node hadoop-32-2(cmPort: 38703 httpPort: 8042) registered with capability: <memory:8192, vCores:16>, assigned nodeId hadoop-32-2:38703
2013-08-31 00:09:39,097 INFO org.apache.hadoop.yarn.server.resourcemanager.rmnode.RMNodeImpl: hadoop-32-2:38703 Node Transitioned from NEW to RUNNING
2013-08-31 00:09:39,100 INFO org.apache.hadoop.yarn.server.resourcemanager.scheduler.capacity.CapacityScheduler: Added node hadoop-32-2:38703 clusterResource: <memory:8192, vCores:16>
2013-08-31 00:09:39,166 INFO org.apache.hadoop.yarn.util.RackResolver: Resolved hadoop-32-4 to /default-rack
2013-08-31 00:09:39,167 INFO org.apache.hadoop.yarn.server.resourcemanager.ResourceTrackerService: NodeManager from node hadoop-32-4(cmPort: 58137 httpPort: 8042) registered with capability: <memory:8192, vCores:16>, assigned nodeId hadoop-32-4:58137
2013-08-31 00:09:39,169 INFO org.apache.hadoop.yarn.server.resourcemanager.rmnode.RMNodeImpl: hadoop-32-4:58137 Node Transitioned from NEW to RUNNING
2013-08-31 00:09:39,170 INFO org.apache.hadoop.yarn.server.resourcemanager.scheduler.capacity.CapacityScheduler: Added node hadoop-32-4:58137 clusterResource: <memory:16384, vCores:32>
2013-08-31 00:09:39,448 INFO org.apache.hadoop.yarn.util.RackResolver: Resolved hadoop-32-5 to /default-rack
2013-08-31 00:09:39,448 INFO org.apache.hadoop.yarn.server.resourcemanager.ResourceTrackerService: NodeManager from node hadoop-32-5(cmPort: 54799 httpPort: 8042) registered with capability: <memory:8192, vCores:16>, assigned nodeId hadoop-32-5:54799
2013-08-31 00:09:39,449 INFO org.apache.hadoop.yarn.server.resourcemanager.rmnode.RMNodeImpl: hadoop-32-5:54799 Node Transitioned from NEW to RUNNING
2013-08-31 00:09:39,450 INFO org.apache.hadoop.yarn.server.resourcemanager.scheduler.capacity.CapacityScheduler: Added node hadoop-32-5:54799 clusterResource: <memory:24576, vCores:48>
2013-08-31 00:09:39,524 INFO org.apache.hadoop.yarn.util.RackResolver: Resolved hadoop-32-3 to /default-rack
2013-08-31 00:09:39,524 INFO org.apache.hadoop.yarn.server.resourcemanager.ResourceTrackerService: NodeManager from node hadoop-32-3(cmPort: 33603 httpPort: 8042) registered with capability: <memory:8192, vCores:16>, assigned nodeId hadoop-32-3:33603
2013-08-31 00:09:39,525 INFO org.apache.hadoop.yarn.server.resourcemanager.rmnode.RMNodeImpl: hadoop-32-3:33603 Node Transitioned from NEW to RUNNING
2013-08-31 00:09:39,525 INFO org.apache.hadoop.yarn.server.resourcemanager.scheduler.capacity.CapacityScheduler: Added node hadoop-32-3:33603 clusterResource: <memory:32768, vCores:64>
2013-08-31 00:09:39,525 INFO org.apache.hadoop.yarn.util.RackResolver: Resolved hadoop-32-6 to /default-rack
2013-08-31 00:09:39,526 INFO org.apache.hadoop.yarn.server.resourcemanager.ResourceTrackerService: NodeManager from node hadoop-32-6(cmPort: 48039 httpPort: 8042) registered with capability: <memory:8192, vCores:16>, assigned nodeId hadoop-32-6:48039
2013-08-31 00:09:39,526 INFO org.apache.hadoop.yarn.server.resourcemanager.rmnode.RMNodeImpl: hadoop-32-6:48039 Node Transitioned from NEW to RUNNING
2013-08-31 00:09:39,526 INFO org.apache.hadoop.yarn.server.resourcemanager.scheduler.capacity.CapacityScheduler: Added node hadoop-32-6:48039 clusterResource: <memory:40960, vCores:80>
2013-08-31 00:09:39,703 INFO org.apache.hadoop.yarn.util.RackResolver: Resolved hadoop-32-7 to /default-rack
2013-08-31 00:09:39,703 INFO org.apache.hadoop.yarn.server.resourcemanager.ResourceTrackerService: NodeManager from node hadoop-32-7(cmPort: 54070 httpPort: 8042) registered with capability: <memory:8192, vCores:16>, assigned nodeId hadoop-32-7:54070
2013-08-31 00:09:39,704 INFO org.apache.hadoop.yarn.server.resourcemanager.rmnode.RMNodeImpl: hadoop-32-7:54070 Node Transitioned from NEW to RUNNING
2013-08-31 00:09:39,704 INFO org.apache.hadoop.yarn.server.resourcemanager.scheduler.capacity.CapacityScheduler: Added node hadoop-32-7:54070 clusterResource: <memory:49152, vCores:96>
2013-08-31 00:10:06,667 INFO org.apache.hadoop.yarn.server.resourcemanager.ClientRMService: Allocated new applicationId: 1
2013-08-31 00:10:10,013 INFO org.apache.hadoop.yarn.server.resourcemanager.ClientRMService: Storing Application with id application_1377907764744_0001
2013-08-31 00:10:10,017 INFO org.apache.hadoop.yarn.server.resourcemanager.recovery.RMStateStore: Storing info for app: application_1377907764744_0001
2013-08-31 00:10:10,017 INFO org.apache.hadoop.yarn.server.resourcemanager.ClientRMService: Application with id 1 submitted by user ubuntu
2013-08-31 00:10:10,020 INFO org.apache.hadoop.yarn.server.resourcemanager.RMAuditLogger: USER=ubuntu	IP=192.168.100.5	OPERATION=Submit Application Request	TARGET=ClientRMService	RESULT=SUCCESS	APPID=application_1377907764744_0001
2013-08-31 00:10:10,065 INFO org.apache.hadoop.yarn.server.resourcemanager.rmapp.RMAppImpl: application_1377907764744_0001 State change from NEW to SUBMITTED
2013-08-31 00:10:10,066 INFO org.apache.hadoop.yarn.server.resourcemanager.ApplicationMasterService: Registering appattempt_1377907764744_0001_000001
2013-08-31 00:10:10,067 INFO org.apache.hadoop.yarn.server.resourcemanager.rmapp.attempt.RMAppAttemptImpl: appattempt_1377907764744_0001_000001 State change from NEW to SUBMITTED
2013-08-31 00:10:10,100 INFO org.apache.hadoop.yarn.server.resourcemanager.scheduler.capacity.LeafQueue: Application application_1377907764744_0001 from user: ubuntu activated in queue: default
2013-08-31 00:10:10,100 INFO org.apache.hadoop.yarn.server.resourcemanager.scheduler.capacity.LeafQueue: Application added - appId: application_1377907764744_0001 user: org.apache.hadoop.yarn.server.resourcemanager.scheduler.capacity.LeafQueue$User@267b0b0b, leaf-queue: default #user-pending-applications: 0 #user-active-applications: 1 #queue-pending-applications: 0 #queue-active-applications: 1
2013-08-31 00:10:10,101 INFO org.apache.hadoop.yarn.server.resourcemanager.scheduler.capacity.ParentQueue: Application added - appId: application_1377907764744_0001 user: ubuntu leaf-queue of parent: root #applications: 1
2013-08-31 00:10:10,101 INFO org.apache.hadoop.yarn.server.resourcemanager.scheduler.capacity.CapacityScheduler: Application Submission: appattempt_1377907764744_0001_000001, user: ubuntu queue: default: capacity=1.0, absoluteCapacity=1.0, usedResources=<memory:0, vCores:0>usedCapacity=0.0, absoluteUsedCapacity=0.0, numApps=1, numContainers=0, currently active: 1
2013-08-31 00:10:10,107 INFO org.apache.hadoop.yarn.server.resourcemanager.rmapp.attempt.RMAppAttemptImpl: appattempt_1377907764744_0001_000001 State change from SUBMITTED to SCHEDULED
2013-08-31 00:10:10,107 INFO org.apache.hadoop.yarn.server.resourcemanager.rmapp.RMAppImpl: application_1377907764744_0001 State change from SUBMITTED to ACCEPTED
2013-08-31 00:10:10,333 INFO org.apache.hadoop.yarn.server.resourcemanager.rmcontainer.RMContainerImpl: container_1377907764744_0001_01_000001 Container Transitioned from NEW to ALLOCATED
2013-08-31 00:10:10,333 INFO org.apache.hadoop.yarn.server.resourcemanager.RMAuditLogger: USER=ubuntu	OPERATION=AM Allocated Container	TARGET=SchedulerApp	RESULT=SUCCESS	APPID=application_1377907764744_0001	CONTAINERID=container_1377907764744_0001_01_000001
2013-08-31 00:10:10,334 INFO org.apache.hadoop.yarn.server.resourcemanager.scheduler.common.fica.FiCaSchedulerNode: Assigned container container_1377907764744_0001_01_000001 of capacity <memory:2048, vCores:1> on host hadoop-32-2:38703, which currently has 1 containers, <memory:2048, vCores:1> used and <memory:6144, vCores:15> available
2013-08-31 00:10:10,340 INFO org.apache.hadoop.yarn.server.resourcemanager.scheduler.capacity.LeafQueue: assignedContainer application=application_1377907764744_0001 container=Container: [ContainerId: container_1377907764744_0001_01_000001, NodeId: hadoop-32-2:38703, NodeHttpAddress: hadoop-32-2:8042, Resource: <memory:2048, vCores:1>, Priority: 0, State: NEW, Token: null, Status: container_id {, app_attempt_id {, application_id {, id: 1, cluster_timestamp: 1377907764744, }, attemptId: 1, }, id: 1, }, state: C_NEW, ] containerId=container_1377907764744_0001_01_000001 queue=default: capacity=1.0, absoluteCapacity=1.0, usedResources=<memory:0, vCores:0>usedCapacity=0.0, absoluteUsedCapacity=0.0, numApps=1, numContainers=0 usedCapacity=0.0 absoluteUsedCapacity=0.0 used=<memory:0, vCores:0> cluster=<memory:49152, vCores:96>
2013-08-31 00:10:10,341 INFO org.apache.hadoop.yarn.server.resourcemanager.scheduler.capacity.ParentQueue: Re-sorting queues since queue: root.default stats: default: capacity=1.0, absoluteCapacity=1.0, usedResources=<memory:2048, vCores:1>usedCapacity=0.041666668, absoluteUsedCapacity=0.041666668, numApps=1, numContainers=1
2013-08-31 00:10:10,341 INFO org.apache.hadoop.yarn.server.resourcemanager.scheduler.capacity.ParentQueue: assignedContainer queue=root usedCapacity=0.041666668 absoluteUsedCapacity=0.041666668 used=<memory:2048, vCores:1> cluster=<memory:49152, vCores:96>
2013-08-31 00:10:10,343 INFO org.apache.hadoop.yarn.server.resourcemanager.rmcontainer.RMContainerImpl: container_1377907764744_0001_01_000001 Container Transitioned from ALLOCATED to ACQUIRED
2013-08-31 00:10:10,347 INFO org.apache.hadoop.yarn.server.resourcemanager.rmapp.attempt.RMAppAttemptImpl: Storing attempt: AppId: application_1377907764744_0001 AttemptId: appattempt_1377907764744_0001_000001 MasterContainer: Container: [ContainerId: container_1377907764744_0001_01_000001, NodeId: hadoop-32-2:38703, NodeHttpAddress: hadoop-32-2:8042, Resource: <memory:2048, vCores:1>, Priority: 0, State: NEW, Token: null, Status: container_id {, app_attempt_id {, application_id {, id: 1, cluster_timestamp: 1377907764744, }, attemptId: 1, }, id: 1, }, state: C_NEW, ]
2013-08-31 00:10:10,352 INFO org.apache.hadoop.yarn.server.resourcemanager.rmapp.attempt.RMAppAttemptImpl: appattempt_1377907764744_0001_000001 State change from SCHEDULED to ALLOCATED_SAVING
2013-08-31 00:10:10,354 INFO org.apache.hadoop.yarn.server.resourcemanager.recovery.RMStateStore: Storing info for attempt: appattempt_1377907764744_0001_000001
2013-08-31 00:10:10,359 INFO org.apache.hadoop.yarn.server.resourcemanager.rmapp.attempt.RMAppAttemptImpl: appattempt_1377907764744_0001_000001 State change from ALLOCATED_SAVING to ALLOCATED
2013-08-31 00:10:10,366 INFO org.apache.hadoop.yarn.server.resourcemanager.amlauncher.AMLauncher: Launching masterappattempt_1377907764744_0001_000001
2013-08-31 00:10:10,408 INFO org.apache.hadoop.yarn.server.resourcemanager.amlauncher.AMLauncher: Setting up container Container: [ContainerId: container_1377907764744_0001_01_000001, NodeId: hadoop-32-2:38703, NodeHttpAddress: hadoop-32-2:8042, Resource: <memory:2048, vCores:1>, Priority: 0, State: NEW, Token: null, Status: container_id {, app_attempt_id {, application_id {, id: 1, cluster_timestamp: 1377907764744, }, attemptId: 1, }, id: 1, }, state: C_NEW, ] for AM appattempt_1377907764744_0001_000001
2013-08-31 00:10:10,408 INFO org.apache.hadoop.yarn.server.resourcemanager.amlauncher.AMLauncher: Command to launch container container_1377907764744_0001_01_000001 : $JAVA_HOME/bin/java -Dlog4j.configuration=container-log4j.properties -Dyarn.app.mapreduce.container.log.dir=<LOG_DIR> -Dyarn.app.mapreduce.container.log.filesize=0 -Dhadoop.root.logger=INFO,CLA  -Xmx1024m org.apache.hadoop.mapreduce.v2.app.MRAppMaster 1><LOG_DIR>/stdout 2><LOG_DIR>/stderr 
2013-08-31 00:10:11,293 INFO org.apache.hadoop.yarn.server.resourcemanager.amlauncher.AMLauncher: Done launching container Container: [ContainerId: container_1377907764744_0001_01_000001, NodeId: hadoop-32-2:38703, NodeHttpAddress: hadoop-32-2:8042, Resource: <memory:2048, vCores:1>, Priority: 0, State: NEW, Token: null, Status: container_id {, app_attempt_id {, application_id {, id: 1, cluster_timestamp: 1377907764744, }, attemptId: 1, }, id: 1, }, state: C_NEW, ] for AM appattempt_1377907764744_0001_000001
2013-08-31 00:10:11,293 INFO org.apache.hadoop.yarn.server.resourcemanager.rmapp.attempt.RMAppAttemptImpl: appattempt_1377907764744_0001_000001 State change from ALLOCATED to LAUNCHED
2013-08-31 00:10:11,333 INFO org.apache.hadoop.yarn.server.resourcemanager.rmcontainer.RMContainerImpl: container_1377907764744_0001_01_000001 Container Transitioned from ACQUIRED to RUNNING
2013-08-31 00:10:20,162 INFO org.apache.hadoop.yarn.server.resourcemanager.ApplicationMasterService: AM registration appattempt_1377907764744_0001_000001
2013-08-31 00:10:20,164 INFO org.apache.hadoop.yarn.server.resourcemanager.RMAuditLogger: USER=ubuntu	IP=192.168.100.22	OPERATION=Register App Master	TARGET=ApplicationMasterService	RESULT=SUCCESS	APPID=application_1377907764744_0001	APPATTEMPTID=appattempt_1377907764744_0001_000001
2013-08-31 00:10:20,167 INFO org.apache.hadoop.yarn.server.resourcemanager.rmapp.attempt.RMAppAttemptImpl: appattempt_1377907764744_0001_000001 State change from LAUNCHED to RUNNING
2013-08-31 00:10:20,167 INFO org.apache.hadoop.yarn.server.resourcemanager.rmapp.RMAppImpl: application_1377907764744_0001 State change from ACCEPTED to RUNNING
2013-08-31 00:10:21,388 INFO org.apache.hadoop.yarn.server.resourcemanager.rmcontainer.RMContainerImpl: container_1377907764744_0001_01_000002 Container Transitioned from NEW to ALLOCATED
2013-08-31 00:10:21,389 INFO org.apache.hadoop.yarn.server.resourcemanager.RMAuditLogger: USER=ubuntu	OPERATION=AM Allocated Container	TARGET=SchedulerApp	RESULT=SUCCESS	APPID=application_1377907764744_0001	CONTAINERID=container_1377907764744_0001_01_000002
2013-08-31 00:10:21,389 INFO org.apache.hadoop.yarn.server.resourcemanager.scheduler.common.fica.FiCaSchedulerNode: Assigned container container_1377907764744_0001_01_000002 of capacity <memory:1024, vCores:1> on host hadoop-32-4:58137, which currently has 1 containers, <memory:1024, vCores:1> used and <memory:7168, vCores:15> available
2013-08-31 00:10:21,391 INFO org.apache.hadoop.yarn.server.resourcemanager.scheduler.capacity.LeafQueue: assignedContainer application=application_1377907764744_0001 container=Container: [ContainerId: container_1377907764744_0001_01_000002, NodeId: hadoop-32-4:58137, NodeHttpAddress: hadoop-32-4:8042, Resource: <memory:1024, vCores:1>, Priority: 20, State: NEW, Token: null, Status: container_id {, app_attempt_id {, application_id {, id: 1, cluster_timestamp: 1377907764744, }, attemptId: 1, }, id: 2, }, state: C_NEW, ] containerId=container_1377907764744_0001_01_000002 queue=default: capacity=1.0, absoluteCapacity=1.0, usedResources=<memory:2048, vCores:1>usedCapacity=0.041666668, absoluteUsedCapacity=0.041666668, numApps=1, numContainers=1 usedCapacity=0.041666668 absoluteUsedCapacity=0.041666668 used=<memory:2048, vCores:1> cluster=<memory:49152, vCores:96>
2013-08-31 00:10:21,391 INFO org.apache.hadoop.yarn.server.resourcemanager.scheduler.capacity.ParentQueue: Re-sorting queues since queue: root.default stats: default: capacity=1.0, absoluteCapacity=1.0, usedResources=<memory:3072, vCores:2>usedCapacity=0.0625, absoluteUsedCapacity=0.0625, numApps=1, numContainers=2
2013-08-31 00:10:21,391 INFO org.apache.hadoop.yarn.server.resourcemanager.scheduler.capacity.ParentQueue: assignedContainer queue=root usedCapacity=0.0625 absoluteUsedCapacity=0.0625 used=<memory:3072, vCores:2> cluster=<memory:49152, vCores:96>
2013-08-31 00:10:21,392 INFO org.apache.hadoop.yarn.server.resourcemanager.rmcontainer.RMContainerImpl: container_1377907764744_0001_01_000003 Container Transitioned from NEW to ALLOCATED
2013-08-31 00:10:21,392 INFO org.apache.hadoop.yarn.server.resourcemanager.RMAuditLogger: USER=ubuntu	OPERATION=AM Allocated Container	TARGET=SchedulerApp	RESULT=SUCCESS	APPID=application_1377907764744_0001	CONTAINERID=container_1377907764744_0001_01_000003
2013-08-31 00:10:21,393 INFO org.apache.hadoop.yarn.server.resourcemanager.scheduler.common.fica.FiCaSchedulerNode: Assigned container container_1377907764744_0001_01_000003 of capacity <memory:1024, vCores:1> on host hadoop-32-2:38703, which currently has 2 containers, <memory:3072, vCores:2> used and <memory:5120, vCores:14> available
2013-08-31 00:10:21,394 INFO org.apache.hadoop.yarn.server.resourcemanager.scheduler.capacity.LeafQueue: assignedContainer application=application_1377907764744_0001 container=Container: [ContainerId: container_1377907764744_0001_01_000003, NodeId: hadoop-32-2:38703, NodeHttpAddress: hadoop-32-2:8042, Resource: <memory:1024, vCores:1>, Priority: 20, State: NEW, Token: null, Status: container_id {, app_attempt_id {, application_id {, id: 1, cluster_timestamp: 1377907764744, }, attemptId: 1, }, id: 3, }, state: C_NEW, ] containerId=container_1377907764744_0001_01_000003 queue=default: capacity=1.0, absoluteCapacity=1.0, usedResources=<memory:3072, vCores:2>usedCapacity=0.0625, absoluteUsedCapacity=0.0625, numApps=1, numContainers=2 usedCapacity=0.0625 absoluteUsedCapacity=0.0625 used=<memory:3072, vCores:2> cluster=<memory:49152, vCores:96>
2013-08-31 00:10:21,395 INFO org.apache.hadoop.yarn.server.resourcemanager.scheduler.capacity.ParentQueue: Re-sorting queues since queue: root.default stats: default: capacity=1.0, absoluteCapacity=1.0, usedResources=<memory:4096, vCores:3>usedCapacity=0.083333336, absoluteUsedCapacity=0.083333336, numApps=1, numContainers=3
2013-08-31 00:10:21,395 INFO org.apache.hadoop.yarn.server.resourcemanager.scheduler.capacity.ParentQueue: assignedContainer queue=root usedCapacity=0.083333336 absoluteUsedCapacity=0.083333336 used=<memory:4096, vCores:3> cluster=<memory:49152, vCores:96>
2013-08-31 00:10:22,240 INFO org.apache.hadoop.yarn.server.resourcemanager.rmcontainer.RMContainerImpl: container_1377907764744_0001_01_000002 Container Transitioned from ALLOCATED to ACQUIRED
2013-08-31 00:10:22,241 INFO org.apache.hadoop.yarn.server.resourcemanager.rmcontainer.RMContainerImpl: container_1377907764744_0001_01_000003 Container Transitioned from ALLOCATED to ACQUIRED
2013-08-31 00:10:23,274 INFO org.apache.hadoop.yarn.server.resourcemanager.scheduler.AppSchedulingInfo: checking for deactivate... 
2013-08-31 00:10:23,405 INFO org.apache.hadoop.yarn.server.resourcemanager.rmcontainer.RMContainerImpl: container_1377907764744_0001_01_000003 Container Transitioned from ACQUIRED to RUNNING
2013-08-31 00:10:23,413 INFO org.apache.hadoop.yarn.server.resourcemanager.rmcontainer.RMContainerImpl: container_1377907764744_0001_01_000002 Container Transitioned from ACQUIRED to RUNNING
2013-08-31 00:13:08,564 INFO org.apache.hadoop.yarn.server.resourcemanager.rmcontainer.RMContainerImpl: container_1377907764744_0001_01_000003 Container Transitioned from RUNNING to COMPLETED
2013-08-31 00:13:08,564 INFO org.apache.hadoop.yarn.server.resourcemanager.scheduler.common.fica.FiCaSchedulerApp: Completed container: container_1377907764744_0001_01_000003 in state: COMPLETED event:FINISHED
2013-08-31 00:13:08,564 INFO org.apache.hadoop.yarn.server.resourcemanager.RMAuditLogger: USER=ubuntu	OPERATION=AM Released Container	TARGET=SchedulerApp	RESULT=SUCCESS	APPID=application_1377907764744_0001	CONTAINERID=container_1377907764744_0001_01_000003
2013-08-31 00:13:08,565 INFO org.apache.hadoop.yarn.server.resourcemanager.scheduler.common.fica.FiCaSchedulerNode: Released container container_1377907764744_0001_01_000003 of capacity <memory:1024, vCores:1> on host hadoop-32-2:38703, which currently has 1 containers, <memory:2048, vCores:1> used and <memory:6144, vCores:15> available, release resources=true
2013-08-31 00:13:08,565 INFO org.apache.hadoop.yarn.server.resourcemanager.scheduler.capacity.LeafQueue: default used=<memory:3072, vCores:2> numContainers=2 user=ubuntu user-resources=<memory:3072, vCores:2>
2013-08-31 00:13:08,567 INFO org.apache.hadoop.yarn.server.resourcemanager.scheduler.capacity.LeafQueue: completedContainer container=Container: [ContainerId: container_1377907764744_0001_01_000003, NodeId: hadoop-32-2:38703, NodeHttpAddress: hadoop-32-2:8042, Resource: <memory:1024, vCores:1>, Priority: 20, State: NEW, Token: null, Status: container_id {, app_attempt_id {, application_id {, id: 1, cluster_timestamp: 1377907764744, }, attemptId: 1, }, id: 3, }, state: C_COMPLETE, diagnostics: "Container killed by the ApplicationMaster.\n\n", exit_status: 143, ] resource=<memory:1024, vCores:1> queue=default: capacity=1.0, absoluteCapacity=1.0, usedResources=<memory:3072, vCores:2>usedCapacity=0.0625, absoluteUsedCapacity=0.0625, numApps=1, numContainers=2 usedCapacity=0.0625 absoluteUsedCapacity=0.0625 used=<memory:3072, vCores:2> cluster=<memory:49152, vCores:96>
2013-08-31 00:13:08,567 INFO org.apache.hadoop.yarn.server.resourcemanager.scheduler.capacity.ParentQueue: completedContainer queue=root usedCapacity=0.0625 absoluteUsedCapacity=0.0625 used=<memory:3072, vCores:2> cluster=<memory:49152, vCores:96>
2013-08-31 00:13:08,568 INFO org.apache.hadoop.yarn.server.resourcemanager.scheduler.capacity.CapacityScheduler: Application appattempt_1377907764744_0001_000001 released container container_1377907764744_0001_01_000003 on node: host: hadoop-32-2:38703 #containers=1 available=6144 used=2048 with event: FINISHED
2013-08-31 00:13:14,359 INFO org.apache.hadoop.yarn.server.resourcemanager.rmcontainer.RMContainerImpl: container_1377907764744_0001_01_000002 Container Transitioned from RUNNING to COMPLETED
2013-08-31 00:13:14,359 INFO org.apache.hadoop.yarn.server.resourcemanager.scheduler.common.fica.FiCaSchedulerApp: Completed container: container_1377907764744_0001_01_000002 in state: COMPLETED event:FINISHED
2013-08-31 00:13:14,359 INFO org.apache.hadoop.yarn.server.resourcemanager.RMAuditLogger: USER=ubuntu	OPERATION=AM Released Container	TARGET=SchedulerApp	RESULT=SUCCESS	APPID=application_1377907764744_0001	CONTAINERID=container_1377907764744_0001_01_000002
2013-08-31 00:13:14,360 INFO org.apache.hadoop.yarn.server.resourcemanager.scheduler.common.fica.FiCaSchedulerNode: Released container container_1377907764744_0001_01_000002 of capacity <memory:1024, vCores:1> on host hadoop-32-4:58137, which currently has 0 containers, <memory:0, vCores:0> used and <memory:8192, vCores:16> available, release resources=true
2013-08-31 00:13:14,360 INFO org.apache.hadoop.yarn.server.resourcemanager.scheduler.capacity.LeafQueue: default used=<memory:2048, vCores:1> numContainers=1 user=ubuntu user-resources=<memory:2048, vCores:1>
2013-08-31 00:13:14,362 INFO org.apache.hadoop.yarn.server.resourcemanager.scheduler.capacity.LeafQueue: completedContainer container=Container: [ContainerId: container_1377907764744_0001_01_000002, NodeId: hadoop-32-4:58137, NodeHttpAddress: hadoop-32-4:8042, Resource: <memory:1024, vCores:1>, Priority: 20, State: NEW, Token: null, Status: container_id {, app_attempt_id {, application_id {, id: 1, cluster_timestamp: 1377907764744, }, attemptId: 1, }, id: 2, }, state: C_COMPLETE, diagnostics: "Container killed by the ApplicationMaster.\n\n", exit_status: 143, ] resource=<memory:1024, vCores:1> queue=default: capacity=1.0, absoluteCapacity=1.0, usedResources=<memory:2048, vCores:1>usedCapacity=0.041666668, absoluteUsedCapacity=0.041666668, numApps=1, numContainers=1 usedCapacity=0.041666668 absoluteUsedCapacity=0.041666668 used=<memory:2048, vCores:1> cluster=<memory:49152, vCores:96>
2013-08-31 00:13:14,362 INFO org.apache.hadoop.yarn.server.resourcemanager.scheduler.capacity.ParentQueue: completedContainer queue=root usedCapacity=0.041666668 absoluteUsedCapacity=0.041666668 used=<memory:2048, vCores:1> cluster=<memory:49152, vCores:96>
2013-08-31 00:13:14,362 INFO org.apache.hadoop.yarn.server.resourcemanager.scheduler.capacity.CapacityScheduler: Application appattempt_1377907764744_0001_000001 released container container_1377907764744_0001_01_000002 on node: host: hadoop-32-4:58137 #containers=0 available=8192 used=0 with event: FINISHED
2013-08-31 00:13:18,550 INFO org.apache.hadoop.yarn.server.resourcemanager.rmapp.attempt.RMAppAttemptImpl: appattempt_1377907764744_0001_000001 State change from RUNNING to FINISHING
2013-08-31 00:13:18,551 INFO org.apache.hadoop.yarn.server.resourcemanager.rmapp.RMAppImpl: application_1377907764744_0001 State change from RUNNING to FINISHING
2013-08-31 00:13:19,625 INFO org.apache.hadoop.yarn.server.resourcemanager.rmcontainer.RMContainerImpl: container_1377907764744_0001_01_000001 Container Transitioned from RUNNING to COMPLETED
2013-08-31 00:13:19,625 INFO org.apache.hadoop.yarn.server.resourcemanager.scheduler.common.fica.FiCaSchedulerApp: Completed container: container_1377907764744_0001_01_000001 in state: COMPLETED event:FINISHED
2013-08-31 00:13:19,626 INFO org.apache.hadoop.yarn.server.resourcemanager.RMAuditLogger: USER=ubuntu	OPERATION=AM Released Container	TARGET=SchedulerApp	RESULT=SUCCESS	APPID=application_1377907764744_0001	CONTAINERID=container_1377907764744_0001_01_000001
2013-08-31 00:13:19,626 INFO org.apache.hadoop.yarn.server.resourcemanager.scheduler.common.fica.FiCaSchedulerNode: Released container container_1377907764744_0001_01_000001 of capacity <memory:2048, vCores:1> on host hadoop-32-2:38703, which currently has 0 containers, <memory:0, vCores:0> used and <memory:8192, vCores:16> available, release resources=true
2013-08-31 00:13:19,626 INFO org.apache.hadoop.yarn.server.resourcemanager.scheduler.capacity.LeafQueue: default used=<memory:0, vCores:0> numContainers=0 user=ubuntu user-resources=<memory:0, vCores:0>
2013-08-31 00:13:19,627 INFO org.apache.hadoop.yarn.server.resourcemanager.scheduler.capacity.LeafQueue: completedContainer container=Container: [ContainerId: container_1377907764744_0001_01_000001, NodeId: hadoop-32-2:38703, NodeHttpAddress: hadoop-32-2:8042, Resource: <memory:2048, vCores:1>, Priority: 0, State: NEW, Token: null, Status: container_id {, app_attempt_id {, application_id {, id: 1, cluster_timestamp: 1377907764744, }, attemptId: 1, }, id: 1, }, state: C_COMPLETE, diagnostics: "", exit_status: 0, ] resource=<memory:2048, vCores:1> queue=default: capacity=1.0, absoluteCapacity=1.0, usedResources=<memory:0, vCores:0>usedCapacity=0.0, absoluteUsedCapacity=0.0, numApps=1, numContainers=0 usedCapacity=0.0 absoluteUsedCapacity=0.0 used=<memory:0, vCores:0> cluster=<memory:49152, vCores:96>
2013-08-31 00:13:19,627 INFO org.apache.hadoop.yarn.server.resourcemanager.scheduler.capacity.ParentQueue: completedContainer queue=root usedCapacity=0.0 absoluteUsedCapacity=0.0 used=<memory:0, vCores:0> cluster=<memory:49152, vCores:96>
2013-08-31 00:13:19,627 INFO org.apache.hadoop.yarn.server.resourcemanager.scheduler.capacity.CapacityScheduler: Application appattempt_1377907764744_0001_000001 released container container_1377907764744_0001_01_000001 on node: host: hadoop-32-2:38703 #containers=0 available=8192 used=0 with event: FINISHED
2013-08-31 00:13:19,627 INFO org.apache.hadoop.yarn.server.resourcemanager.rmapp.attempt.RMAppAttemptImpl: appattempt_1377907764744_0001_000001 State change from FINISHING to FINISHED
2013-08-31 00:13:19,633 INFO org.apache.hadoop.yarn.server.resourcemanager.rmapp.RMAppImpl: application_1377907764744_0001 State change from FINISHING to FINISHED
2013-08-31 00:13:19,634 INFO org.apache.hadoop.yarn.server.resourcemanager.scheduler.capacity.CapacityScheduler: Application appattempt_1377907764744_0001_000001 is done. finalState=FINISHED
2013-08-31 00:13:19,634 INFO org.apache.hadoop.yarn.server.resourcemanager.RMAuditLogger: USER=ubuntu	OPERATION=Application Finished - Succeeded	TARGET=RMAppManager	RESULT=SUCCESS	APPID=application_1377907764744_0001
2013-08-31 00:13:19,639 INFO org.apache.hadoop.yarn.server.resourcemanager.RMAppManager$ApplicationSummary: appId=application_1377907764744_0001,name=TeraGen,user=ubuntu,queue=default,state=FINISHED,trackingUrl=hadoop-32-1.novalocal:8088/proxy/application_1377907764744_0001/jobhistory/job/job_1377907764744_0001,appMasterHost=hadoop-32-2,startTime=1377907810006,finishTime=1377907998551
2013-08-31 00:13:19,635 INFO org.apache.hadoop.yarn.server.resourcemanager.scheduler.AppSchedulingInfo: Application application_1377907764744_0001 requests cleared
2013-08-31 00:13:19,640 INFO org.apache.hadoop.yarn.server.resourcemanager.scheduler.capacity.LeafQueue: Application removed - appId: application_1377907764744_0001 user: ubuntu queue: default #user-pending-applications: 0 #user-active-applications: 0 #queue-pending-applications: 0 #queue-active-applications: 0
2013-08-31 00:13:19,640 INFO org.apache.hadoop.yarn.server.resourcemanager.recovery.RMStateStore: Removing info for app: application_1377907764744_0001
2013-08-31 00:13:19,640 INFO org.apache.hadoop.yarn.server.resourcemanager.scheduler.capacity.ParentQueue: Application removed - appId: application_1377907764744_0001 user: ubuntu leaf-queue of parent: root #applications: 0
2013-08-31 00:13:19,641 INFO org.apache.hadoop.yarn.server.resourcemanager.amlauncher.AMLauncher: Cleaning master appattempt_1377907764744_0001_000001
2013-08-31 00:13:19,960 INFO org.apache.hadoop.yarn.server.resourcemanager.ClientRMService: Allocated new applicationId: 2
2013-08-31 00:13:22,149 INFO org.apache.hadoop.yarn.server.resourcemanager.ClientRMService: Storing Application with id application_1377907764744_0002
2013-08-31 00:13:22,149 INFO org.apache.hadoop.yarn.server.resourcemanager.recovery.RMStateStore: Storing info for app: application_1377907764744_0002
2013-08-31 00:13:22,149 INFO org.apache.hadoop.yarn.server.resourcemanager.ClientRMService: Application with id 2 submitted by user ubuntu
2013-08-31 00:13:22,150 INFO org.apache.hadoop.yarn.server.resourcemanager.RMAuditLogger: USER=ubuntu	IP=192.168.100.5	OPERATION=Submit Application Request	TARGET=ClientRMService	RESULT=SUCCESS	APPID=application_1377907764744_0002
2013-08-31 00:13:22,152 INFO org.apache.hadoop.yarn.server.resourcemanager.rmapp.RMAppImpl: application_1377907764744_0002 State change from NEW to SUBMITTED
2013-08-31 00:13:22,153 INFO org.apache.hadoop.yarn.server.resourcemanager.ApplicationMasterService: Registering appattempt_1377907764744_0002_000001
2013-08-31 00:13:22,153 INFO org.apache.hadoop.yarn.server.resourcemanager.rmapp.attempt.RMAppAttemptImpl: appattempt_1377907764744_0002_000001 State change from NEW to SUBMITTED
2013-08-31 00:13:22,153 INFO org.apache.hadoop.yarn.server.resourcemanager.scheduler.capacity.LeafQueue: Application application_1377907764744_0002 from user: ubuntu activated in queue: default
2013-08-31 00:13:22,154 INFO org.apache.hadoop.yarn.server.resourcemanager.scheduler.capacity.LeafQueue: Application added - appId: application_1377907764744_0002 user: org.apache.hadoop.yarn.server.resourcemanager.scheduler.capacity.LeafQueue$User@25a09508, leaf-queue: default #user-pending-applications: 0 #user-active-applications: 1 #queue-pending-applications: 0 #queue-active-applications: 1
2013-08-31 00:13:22,154 INFO org.apache.hadoop.yarn.server.resourcemanager.scheduler.capacity.ParentQueue: Application added - appId: application_1377907764744_0002 user: ubuntu leaf-queue of parent: root #applications: 1
2013-08-31 00:13:22,154 INFO org.apache.hadoop.yarn.server.resourcemanager.scheduler.capacity.CapacityScheduler: Application Submission: appattempt_1377907764744_0002_000001, user: ubuntu queue: default: capacity=1.0, absoluteCapacity=1.0, usedResources=<memory:0, vCores:0>usedCapacity=0.0, absoluteUsedCapacity=0.0, numApps=1, numContainers=0, currently active: 1
2013-08-31 00:13:22,155 INFO org.apache.hadoop.yarn.server.resourcemanager.rmapp.attempt.RMAppAttemptImpl: appattempt_1377907764744_0002_000001 State change from SUBMITTED to SCHEDULED
2013-08-31 00:13:22,155 INFO org.apache.hadoop.yarn.server.resourcemanager.rmapp.RMAppImpl: application_1377907764744_0002 State change from SUBMITTED to ACCEPTED
2013-08-31 00:13:22,392 INFO org.apache.hadoop.yarn.server.resourcemanager.rmcontainer.RMContainerImpl: container_1377907764744_0002_01_000001 Container Transitioned from NEW to ALLOCATED
2013-08-31 00:13:22,392 INFO org.apache.hadoop.yarn.server.resourcemanager.RMAuditLogger: USER=ubuntu	OPERATION=AM Allocated Container	TARGET=SchedulerApp	RESULT=SUCCESS	APPID=application_1377907764744_0002	CONTAINERID=container_1377907764744_0002_01_000001
2013-08-31 00:13:22,393 INFO org.apache.hadoop.yarn.server.resourcemanager.scheduler.common.fica.FiCaSchedulerNode: Assigned container container_1377907764744_0002_01_000001 of capacity <memory:2048, vCores:1> on host hadoop-32-4:58137, which currently has 1 containers, <memory:2048, vCores:1> used and <memory:6144, vCores:15> available
2013-08-31 00:13:22,394 INFO org.apache.hadoop.yarn.server.resourcemanager.scheduler.capacity.LeafQueue: assignedContainer application=application_1377907764744_0002 container=Container: [ContainerId: container_1377907764744_0002_01_000001, NodeId: hadoop-32-4:58137, NodeHttpAddress: hadoop-32-4:8042, Resource: <memory:2048, vCores:1>, Priority: 0, State: NEW, Token: null, Status: container_id {, app_attempt_id {, application_id {, id: 2, cluster_timestamp: 1377907764744, }, attemptId: 1, }, id: 1, }, state: C_NEW, ] containerId=container_1377907764744_0002_01_000001 queue=default: capacity=1.0, absoluteCapacity=1.0, usedResources=<memory:0, vCores:0>usedCapacity=0.0, absoluteUsedCapacity=0.0, numApps=1, numContainers=0 usedCapacity=0.0 absoluteUsedCapacity=0.0 used=<memory:0, vCores:0> cluster=<memory:49152, vCores:96>
2013-08-31 00:13:22,395 INFO org.apache.hadoop.yarn.server.resourcemanager.scheduler.capacity.ParentQueue: Re-sorting queues since queue: root.default stats: default: capacity=1.0, absoluteCapacity=1.0, usedResources=<memory:2048, vCores:1>usedCapacity=0.041666668, absoluteUsedCapacity=0.041666668, numApps=1, numContainers=1
2013-08-31 00:13:22,395 INFO org.apache.hadoop.yarn.server.resourcemanager.scheduler.capacity.ParentQueue: assignedContainer queue=root usedCapacity=0.041666668 absoluteUsedCapacity=0.041666668 used=<memory:2048, vCores:1> cluster=<memory:49152, vCores:96>
2013-08-31 00:13:22,396 INFO org.apache.hadoop.yarn.server.resourcemanager.rmcontainer.RMContainerImpl: container_1377907764744_0002_01_000001 Container Transitioned from ALLOCATED to ACQUIRED
2013-08-31 00:13:22,398 INFO org.apache.hadoop.yarn.server.resourcemanager.rmapp.attempt.RMAppAttemptImpl: Storing attempt: AppId: application_1377907764744_0002 AttemptId: appattempt_1377907764744_0002_000001 MasterContainer: Container: [ContainerId: container_1377907764744_0002_01_000001, NodeId: hadoop-32-4:58137, NodeHttpAddress: hadoop-32-4:8042, Resource: <memory:2048, vCores:1>, Priority: 0, State: NEW, Token: null, Status: container_id {, app_attempt_id {, application_id {, id: 2, cluster_timestamp: 1377907764744, }, attemptId: 1, }, id: 1, }, state: C_NEW, ]
2013-08-31 00:13:22,399 INFO org.apache.hadoop.yarn.server.resourcemanager.recovery.RMStateStore: Storing info for attempt: appattempt_1377907764744_0002_000001
2013-08-31 00:13:22,399 INFO org.apache.hadoop.yarn.server.resourcemanager.rmapp.attempt.RMAppAttemptImpl: appattempt_1377907764744_0002_000001 State change from SCHEDULED to ALLOCATED_SAVING
2013-08-31 00:13:22,400 INFO org.apache.hadoop.yarn.server.resourcemanager.rmapp.attempt.RMAppAttemptImpl: appattempt_1377907764744_0002_000001 State change from ALLOCATED_SAVING to ALLOCATED
2013-08-31 00:13:22,401 INFO org.apache.hadoop.yarn.server.resourcemanager.amlauncher.AMLauncher: Launching masterappattempt_1377907764744_0002_000001
2013-08-31 00:13:22,404 INFO org.apache.hadoop.yarn.server.resourcemanager.amlauncher.AMLauncher: Setting up container Container: [ContainerId: container_1377907764744_0002_01_000001, NodeId: hadoop-32-4:58137, NodeHttpAddress: hadoop-32-4:8042, Resource: <memory:2048, vCores:1>, Priority: 0, State: NEW, Token: null, Status: container_id {, app_attempt_id {, application_id {, id: 2, cluster_timestamp: 1377907764744, }, attemptId: 1, }, id: 1, }, state: C_NEW, ] for AM appattempt_1377907764744_0002_000001
2013-08-31 00:13:22,404 INFO org.apache.hadoop.yarn.server.resourcemanager.amlauncher.AMLauncher: Command to launch container container_1377907764744_0002_01_000001 : $JAVA_HOME/bin/java -Dlog4j.configuration=container-log4j.properties -Dyarn.app.mapreduce.container.log.dir=<LOG_DIR> -Dyarn.app.mapreduce.container.log.filesize=0 -Dhadoop.root.logger=INFO,CLA  -Xmx1024m org.apache.hadoop.mapreduce.v2.app.MRAppMaster 1><LOG_DIR>/stdout 2><LOG_DIR>/stderr 
2013-08-31 00:13:22,419 INFO org.apache.hadoop.yarn.server.resourcemanager.amlauncher.AMLauncher: Done launching container Container: [ContainerId: container_1377907764744_0002_01_000001, NodeId: hadoop-32-4:58137, NodeHttpAddress: hadoop-32-4:8042, Resource: <memory:2048, vCores:1>, Priority: 0, State: NEW, Token: null, Status: container_id {, app_attempt_id {, application_id {, id: 2, cluster_timestamp: 1377907764744, }, attemptId: 1, }, id: 1, }, state: C_NEW, ] for AM appattempt_1377907764744_0002_000001
2013-08-31 00:13:22,419 INFO org.apache.hadoop.yarn.server.resourcemanager.rmapp.attempt.RMAppAttemptImpl: appattempt_1377907764744_0002_000001 State change from ALLOCATED to LAUNCHED
2013-08-31 00:13:23,398 INFO org.apache.hadoop.yarn.server.resourcemanager.rmcontainer.RMContainerImpl: container_1377907764744_0002_01_000001 Container Transitioned from ACQUIRED to RUNNING
2013-08-31 00:13:29,110 INFO org.apache.hadoop.yarn.server.resourcemanager.ApplicationMasterService: AM registration appattempt_1377907764744_0002_000001
2013-08-31 00:13:29,111 INFO org.apache.hadoop.yarn.server.resourcemanager.RMAuditLogger: USER=ubuntu	IP=192.168.100.21	OPERATION=Register App Master	TARGET=ApplicationMasterService	RESULT=SUCCESS	APPID=application_1377907764744_0002	APPATTEMPTID=appattempt_1377907764744_0002_000001
2013-08-31 00:13:29,113 INFO org.apache.hadoop.yarn.server.resourcemanager.rmapp.attempt.RMAppAttemptImpl: appattempt_1377907764744_0002_000001 State change from LAUNCHED to RUNNING
2013-08-31 00:13:29,114 INFO org.apache.hadoop.yarn.server.resourcemanager.rmapp.RMAppImpl: application_1377907764744_0002 State change from ACCEPTED to RUNNING
2013-08-31 00:13:30,432 INFO org.apache.hadoop.yarn.server.resourcemanager.rmcontainer.RMContainerImpl: container_1377907764744_0002_01_000002 Container Transitioned from NEW to ALLOCATED
2013-08-31 00:13:30,433 INFO org.apache.hadoop.yarn.server.resourcemanager.RMAuditLogger: USER=ubuntu	OPERATION=AM Allocated Container	TARGET=SchedulerApp	RESULT=SUCCESS	APPID=application_1377907764744_0002	CONTAINERID=container_1377907764744_0002_01_000002
2013-08-31 00:13:30,433 INFO org.apache.hadoop.yarn.server.resourcemanager.scheduler.common.fica.FiCaSchedulerNode: Assigned container container_1377907764744_0002_01_000002 of capacity <memory:1024, vCores:1> on host hadoop-32-4:58137, which currently has 2 containers, <memory:3072, vCores:2> used and <memory:5120, vCores:14> available
2013-08-31 00:13:30,435 INFO org.apache.hadoop.yarn.server.resourcemanager.scheduler.capacity.LeafQueue: assignedContainer application=application_1377907764744_0002 container=Container: [ContainerId: container_1377907764744_0002_01_000002, NodeId: hadoop-32-4:58137, NodeHttpAddress: hadoop-32-4:8042, Resource: <memory:1024, vCores:1>, Priority: 20, State: NEW, Token: null, Status: container_id {, app_attempt_id {, application_id {, id: 2, cluster_timestamp: 1377907764744, }, attemptId: 1, }, id: 2, }, state: C_NEW, ] containerId=container_1377907764744_0002_01_000002 queue=default: capacity=1.0, absoluteCapacity=1.0, usedResources=<memory:2048, vCores:1>usedCapacity=0.041666668, absoluteUsedCapacity=0.041666668, numApps=1, numContainers=1 usedCapacity=0.041666668 absoluteUsedCapacity=0.041666668 used=<memory:2048, vCores:1> cluster=<memory:49152, vCores:96>
2013-08-31 00:13:30,435 INFO org.apache.hadoop.yarn.server.resourcemanager.scheduler.capacity.ParentQueue: Re-sorting queues since queue: root.default stats: default: capacity=1.0, absoluteCapacity=1.0, usedResources=<memory:3072, vCores:2>usedCapacity=0.0625, absoluteUsedCapacity=0.0625, numApps=1, numContainers=2
2013-08-31 00:13:30,436 INFO org.apache.hadoop.yarn.server.resourcemanager.scheduler.capacity.ParentQueue: assignedContainer queue=root usedCapacity=0.0625 absoluteUsedCapacity=0.0625 used=<memory:3072, vCores:2> cluster=<memory:49152, vCores:96>
2013-08-31 00:13:30,595 INFO org.apache.hadoop.yarn.server.resourcemanager.rmcontainer.RMContainerImpl: container_1377907764744_0002_01_000003 Container Transitioned from NEW to ALLOCATED
2013-08-31 00:13:30,595 INFO org.apache.hadoop.yarn.server.resourcemanager.RMAuditLogger: USER=ubuntu	OPERATION=AM Allocated Container	TARGET=SchedulerApp	RESULT=SUCCESS	APPID=application_1377907764744_0002	CONTAINERID=container_1377907764744_0002_01_000003
2013-08-31 00:13:30,595 INFO org.apache.hadoop.yarn.server.resourcemanager.scheduler.common.fica.FiCaSchedulerNode: Assigned container container_1377907764744_0002_01_000003 of capacity <memory:1024, vCores:1> on host hadoop-32-5:54799, which currently has 1 containers, <memory:1024, vCores:1> used and <memory:7168, vCores:15> available
2013-08-31 00:13:30,597 INFO org.apache.hadoop.yarn.server.resourcemanager.scheduler.capacity.LeafQueue: assignedContainer application=application_1377907764744_0002 container=Container: [ContainerId: container_1377907764744_0002_01_000003, NodeId: hadoop-32-5:54799, NodeHttpAddress: hadoop-32-5:8042, Resource: <memory:1024, vCores:1>, Priority: 20, State: NEW, Token: null, Status: container_id {, app_attempt_id {, application_id {, id: 2, cluster_timestamp: 1377907764744, }, attemptId: 1, }, id: 3, }, state: C_NEW, ] containerId=container_1377907764744_0002_01_000003 queue=default: capacity=1.0, absoluteCapacity=1.0, usedResources=<memory:3072, vCores:2>usedCapacity=0.0625, absoluteUsedCapacity=0.0625, numApps=1, numContainers=2 usedCapacity=0.0625 absoluteUsedCapacity=0.0625 used=<memory:3072, vCores:2> cluster=<memory:49152, vCores:96>
2013-08-31 00:13:30,597 INFO org.apache.hadoop.yarn.server.resourcemanager.scheduler.capacity.ParentQueue: Re-sorting queues since queue: root.default stats: default: capacity=1.0, absoluteCapacity=1.0, usedResources=<memory:4096, vCores:3>usedCapacity=0.083333336, absoluteUsedCapacity=0.083333336, numApps=1, numContainers=3
2013-08-31 00:13:30,597 INFO org.apache.hadoop.yarn.server.resourcemanager.scheduler.capacity.ParentQueue: assignedContainer queue=root usedCapacity=0.083333336 absoluteUsedCapacity=0.083333336 used=<memory:4096, vCores:3> cluster=<memory:49152, vCores:96>
2013-08-31 00:13:31,163 INFO org.apache.hadoop.yarn.server.resourcemanager.rmcontainer.RMContainerImpl: container_1377907764744_0002_01_000002 Container Transitioned from ALLOCATED to ACQUIRED
2013-08-31 00:13:31,165 INFO org.apache.hadoop.yarn.server.resourcemanager.rmcontainer.RMContainerImpl: container_1377907764744_0002_01_000003 Container Transitioned from ALLOCATED to ACQUIRED
2013-08-31 00:13:32,195 INFO org.apache.hadoop.yarn.server.resourcemanager.scheduler.AppSchedulingInfo: checking for deactivate... 
2013-08-31 00:13:32,451 INFO org.apache.hadoop.yarn.server.resourcemanager.rmcontainer.RMContainerImpl: container_1377907764744_0002_01_000002 Container Transitioned from ACQUIRED to RUNNING
2013-08-31 00:13:32,688 INFO org.apache.hadoop.yarn.server.resourcemanager.rmcontainer.RMContainerImpl: container_1377907764744_0002_01_000003 Container Transitioned from ACQUIRED to RUNNING
2013-08-31 00:16:09,151 INFO org.apache.hadoop.yarn.server.resourcemanager.rmcontainer.RMContainerImpl: container_1377907764744_0002_01_000003 Container Transitioned from RUNNING to COMPLETED
2013-08-31 00:16:09,151 INFO org.apache.hadoop.yarn.server.resourcemanager.scheduler.common.fica.FiCaSchedulerApp: Completed container: container_1377907764744_0002_01_000003 in state: COMPLETED event:FINISHED
2013-08-31 00:16:09,152 INFO org.apache.hadoop.yarn.server.resourcemanager.RMAuditLogger: USER=ubuntu	OPERATION=AM Released Container	TARGET=SchedulerApp	RESULT=SUCCESS	APPID=application_1377907764744_0002	CONTAINERID=container_1377907764744_0002_01_000003
2013-08-31 00:16:09,152 INFO org.apache.hadoop.yarn.server.resourcemanager.scheduler.common.fica.FiCaSchedulerNode: Released container container_1377907764744_0002_01_000003 of capacity <memory:1024, vCores:1> on host hadoop-32-5:54799, which currently has 0 containers, <memory:0, vCores:0> used and <memory:8192, vCores:16> available, release resources=true
2013-08-31 00:16:09,152 INFO org.apache.hadoop.yarn.server.resourcemanager.scheduler.capacity.LeafQueue: default used=<memory:3072, vCores:2> numContainers=2 user=ubuntu user-resources=<memory:3072, vCores:2>
2013-08-31 00:16:09,166 INFO org.apache.hadoop.yarn.server.resourcemanager.scheduler.capacity.LeafQueue: completedContainer container=Container: [ContainerId: container_1377907764744_0002_01_000003, NodeId: hadoop-32-5:54799, NodeHttpAddress: hadoop-32-5:8042, Resource: <memory:1024, vCores:1>, Priority: 20, State: NEW, Token: null, Status: container_id {, app_attempt_id {, application_id {, id: 2, cluster_timestamp: 1377907764744, }, attemptId: 1, }, id: 3, }, state: C_COMPLETE, diagnostics: "Container killed by the ApplicationMaster.\n\n", exit_status: 143, ] resource=<memory:1024, vCores:1> queue=default: capacity=1.0, absoluteCapacity=1.0, usedResources=<memory:3072, vCores:2>usedCapacity=0.0625, absoluteUsedCapacity=0.0625, numApps=1, numContainers=2 usedCapacity=0.0625 absoluteUsedCapacity=0.0625 used=<memory:3072, vCores:2> cluster=<memory:49152, vCores:96>
2013-08-31 00:16:09,166 INFO org.apache.hadoop.yarn.server.resourcemanager.scheduler.capacity.ParentQueue: completedContainer queue=root usedCapacity=0.0625 absoluteUsedCapacity=0.0625 used=<memory:3072, vCores:2> cluster=<memory:49152, vCores:96>
2013-08-31 00:16:09,166 INFO org.apache.hadoop.yarn.server.resourcemanager.scheduler.capacity.CapacityScheduler: Application appattempt_1377907764744_0002_000001 released container container_1377907764744_0002_01_000003 on node: host: hadoop-32-5:54799 #containers=0 available=8192 used=0 with event: FINISHED
2013-08-31 00:16:23,341 INFO org.apache.hadoop.yarn.server.resourcemanager.rmcontainer.RMContainerImpl: container_1377907764744_0002_01_000002 Container Transitioned from RUNNING to COMPLETED
2013-08-31 00:16:23,341 INFO org.apache.hadoop.yarn.server.resourcemanager.scheduler.common.fica.FiCaSchedulerApp: Completed container: container_1377907764744_0002_01_000002 in state: COMPLETED event:FINISHED
2013-08-31 00:16:23,341 INFO org.apache.hadoop.yarn.server.resourcemanager.RMAuditLogger: USER=ubuntu	OPERATION=AM Released Container	TARGET=SchedulerApp	RESULT=SUCCESS	APPID=application_1377907764744_0002	CONTAINERID=container_1377907764744_0002_01_000002
2013-08-31 00:16:23,342 INFO org.apache.hadoop.yarn.server.resourcemanager.scheduler.common.fica.FiCaSchedulerNode: Released container container_1377907764744_0002_01_000002 of capacity <memory:1024, vCores:1> on host hadoop-32-4:58137, which currently has 1 containers, <memory:2048, vCores:1> used and <memory:6144, vCores:15> available, release resources=true
2013-08-31 00:16:23,342 INFO org.apache.hadoop.yarn.server.resourcemanager.scheduler.capacity.LeafQueue: default used=<memory:2048, vCores:1> numContainers=1 user=ubuntu user-resources=<memory:2048, vCores:1>
2013-08-31 00:16:23,344 INFO org.apache.hadoop.yarn.server.resourcemanager.scheduler.capacity.LeafQueue: completedContainer container=Container: [ContainerId: container_1377907764744_0002_01_000002, NodeId: hadoop-32-4:58137, NodeHttpAddress: hadoop-32-4:8042, Resource: <memory:1024, vCores:1>, Priority: 20, State: NEW, Token: null, Status: container_id {, app_attempt_id {, application_id {, id: 2, cluster_timestamp: 1377907764744, }, attemptId: 1, }, id: 2, }, state: C_COMPLETE, diagnostics: "Container killed by the ApplicationMaster.\n\n", exit_status: 143, ] resource=<memory:1024, vCores:1> queue=default: capacity=1.0, absoluteCapacity=1.0, usedResources=<memory:2048, vCores:1>usedCapacity=0.041666668, absoluteUsedCapacity=0.041666668, numApps=1, numContainers=1 usedCapacity=0.041666668 absoluteUsedCapacity=0.041666668 used=<memory:2048, vCores:1> cluster=<memory:49152, vCores:96>
2013-08-31 00:16:23,344 INFO org.apache.hadoop.yarn.server.resourcemanager.scheduler.capacity.ParentQueue: completedContainer queue=root usedCapacity=0.041666668 absoluteUsedCapacity=0.041666668 used=<memory:2048, vCores:1> cluster=<memory:49152, vCores:96>
2013-08-31 00:16:23,345 INFO org.apache.hadoop.yarn.server.resourcemanager.scheduler.capacity.CapacityScheduler: Application appattempt_1377907764744_0002_000001 released container container_1377907764744_0002_01_000002 on node: host: hadoop-32-4:58137 #containers=1 available=6144 used=2048 with event: FINISHED
2013-08-31 00:16:27,534 INFO org.apache.hadoop.yarn.server.resourcemanager.rmapp.attempt.RMAppAttemptImpl: appattempt_1377907764744_0002_000001 State change from RUNNING to FINISHING
2013-08-31 00:16:27,534 INFO org.apache.hadoop.yarn.server.resourcemanager.rmapp.RMAppImpl: application_1377907764744_0002 State change from RUNNING to FINISHING
2013-08-31 00:16:28,362 INFO org.apache.hadoop.yarn.server.resourcemanager.rmcontainer.RMContainerImpl: container_1377907764744_0002_01_000001 Container Transitioned from RUNNING to COMPLETED
2013-08-31 00:16:28,363 INFO org.apache.hadoop.yarn.server.resourcemanager.scheduler.common.fica.FiCaSchedulerApp: Completed container: container_1377907764744_0002_01_000001 in state: COMPLETED event:FINISHED
2013-08-31 00:16:28,363 INFO org.apache.hadoop.yarn.server.resourcemanager.rmapp.attempt.RMAppAttemptImpl: appattempt_1377907764744_0002_000001 State change from FINISHING to FINISHED
2013-08-31 00:16:28,364 INFO org.apache.hadoop.yarn.server.resourcemanager.RMAuditLogger: USER=ubuntu	OPERATION=AM Released Container	TARGET=SchedulerApp	RESULT=SUCCESS	APPID=application_1377907764744_0002	CONTAINERID=container_1377907764744_0002_01_000001
2013-08-31 00:16:28,364 INFO org.apache.hadoop.yarn.server.resourcemanager.scheduler.common.fica.FiCaSchedulerNode: Released container container_1377907764744_0002_01_000001 of capacity <memory:2048, vCores:1> on host hadoop-32-4:58137, which currently has 0 containers, <memory:0, vCores:0> used and <memory:8192, vCores:16> available, release resources=true
2013-08-31 00:16:28,364 INFO org.apache.hadoop.yarn.server.resourcemanager.rmapp.RMAppImpl: application_1377907764744_0002 State change from FINISHING to FINISHED
2013-08-31 00:16:28,364 INFO org.apache.hadoop.yarn.server.resourcemanager.scheduler.capacity.LeafQueue: default used=<memory:0, vCores:0> numContainers=0 user=ubuntu user-resources=<memory:0, vCores:0>
2013-08-31 00:16:28,365 INFO org.apache.hadoop.yarn.server.resourcemanager.RMAuditLogger: USER=ubuntu	OPERATION=Application Finished - Succeeded	TARGET=RMAppManager	RESULT=SUCCESS	APPID=application_1377907764744_0002
2013-08-31 00:16:28,365 INFO org.apache.hadoop.yarn.server.resourcemanager.recovery.RMStateStore: Removing info for app: application_1377907764744_0002
2013-08-31 00:16:28,365 INFO org.apache.hadoop.yarn.server.resourcemanager.amlauncher.AMLauncher: Cleaning master appattempt_1377907764744_0002_000001
2013-08-31 00:16:28,366 INFO org.apache.hadoop.yarn.server.resourcemanager.scheduler.capacity.LeafQueue: completedContainer container=Container: [ContainerId: container_1377907764744_0002_01_000001, NodeId: hadoop-32-4:58137, NodeHttpAddress: hadoop-32-4:8042, Resource: <memory:2048, vCores:1>, Priority: 0, State: NEW, Token: null, Status: container_id {, app_attempt_id {, application_id {, id: 2, cluster_timestamp: 1377907764744, }, attemptId: 1, }, id: 1, }, state: C_COMPLETE, diagnostics: "", exit_status: 0, ] resource=<memory:2048, vCores:1> queue=default: capacity=1.0, absoluteCapacity=1.0, usedResources=<memory:0, vCores:0>usedCapacity=0.0, absoluteUsedCapacity=0.0, numApps=1, numContainers=0 usedCapacity=0.0 absoluteUsedCapacity=0.0 used=<memory:0, vCores:0> cluster=<memory:49152, vCores:96>
2013-08-31 00:16:28,366 INFO org.apache.hadoop.yarn.server.resourcemanager.scheduler.capacity.ParentQueue: completedContainer queue=root usedCapacity=0.0 absoluteUsedCapacity=0.0 used=<memory:0, vCores:0> cluster=<memory:49152, vCores:96>
2013-08-31 00:16:28,366 INFO org.apache.hadoop.yarn.server.resourcemanager.scheduler.capacity.CapacityScheduler: Application appattempt_1377907764744_0002_000001 released container container_1377907764744_0002_01_000001 on node: host: hadoop-32-4:58137 #containers=0 available=8192 used=0 with event: FINISHED
2013-08-31 00:16:28,366 INFO org.apache.hadoop.yarn.server.resourcemanager.scheduler.capacity.CapacityScheduler: Application appattempt_1377907764744_0002_000001 is done. finalState=FINISHED
2013-08-31 00:16:28,367 INFO org.apache.hadoop.yarn.server.resourcemanager.scheduler.AppSchedulingInfo: Application application_1377907764744_0002 requests cleared
2013-08-31 00:16:28,367 INFO org.apache.hadoop.yarn.server.resourcemanager.scheduler.capacity.LeafQueue: Application removed - appId: application_1377907764744_0002 user: ubuntu queue: default #user-pending-applications: 0 #user-active-applications: 0 #queue-pending-applications: 0 #queue-active-applications: 0
2013-08-31 00:16:28,367 INFO org.apache.hadoop.yarn.server.resourcemanager.scheduler.capacity.ParentQueue: Application removed - appId: application_1377907764744_0002 user: ubuntu leaf-queue of parent: root #applications: 0
2013-08-31 00:16:28,365 INFO org.apache.hadoop.yarn.server.resourcemanager.RMAppManager$ApplicationSummary: appId=application_1377907764744_0002,name=TeraGen,user=ubuntu,queue=default,state=FINISHED,trackingUrl=hadoop-32-1.novalocal:8088/proxy/application_1377907764744_0002/jobhistory/job/job_1377907764744_0002,appMasterHost=hadoop-32-4,startTime=1377908002148,finishTime=1377908187534
2013-08-31 00:16:29,114 INFO org.apache.hadoop.yarn.server.resourcemanager.ClientRMService: Allocated new applicationId: 3
2013-08-31 00:16:31,106 INFO org.apache.hadoop.yarn.server.resourcemanager.ClientRMService: Storing Application with id application_1377907764744_0003
2013-08-31 00:16:31,106 INFO org.apache.hadoop.yarn.server.resourcemanager.recovery.RMStateStore: Storing info for app: application_1377907764744_0003
2013-08-31 00:16:31,106 INFO org.apache.hadoop.yarn.server.resourcemanager.ClientRMService: Application with id 3 submitted by user ubuntu
2013-08-31 00:16:31,106 INFO org.apache.hadoop.yarn.server.resourcemanager.RMAuditLogger: USER=ubuntu	IP=192.168.100.5	OPERATION=Submit Application Request	TARGET=ClientRMService	RESULT=SUCCESS	APPID=application_1377907764744_0003
2013-08-31 00:16:31,109 INFO org.apache.hadoop.yarn.server.resourcemanager.rmapp.RMAppImpl: application_1377907764744_0003 State change from NEW to SUBMITTED
2013-08-31 00:16:31,109 INFO org.apache.hadoop.yarn.server.resourcemanager.ApplicationMasterService: Registering appattempt_1377907764744_0003_000001
2013-08-31 00:16:31,109 INFO org.apache.hadoop.yarn.server.resourcemanager.rmapp.attempt.RMAppAttemptImpl: appattempt_1377907764744_0003_000001 State change from NEW to SUBMITTED
2013-08-31 00:16:31,110 INFO org.apache.hadoop.yarn.server.resourcemanager.scheduler.capacity.LeafQueue: Application application_1377907764744_0003 from user: ubuntu activated in queue: default
2013-08-31 00:16:31,110 INFO org.apache.hadoop.yarn.server.resourcemanager.scheduler.capacity.LeafQueue: Application added - appId: application_1377907764744_0003 user: org.apache.hadoop.yarn.server.resourcemanager.scheduler.capacity.LeafQueue$User@655467d7, leaf-queue: default #user-pending-applications: 0 #user-active-applications: 1 #queue-pending-applications: 0 #queue-active-applications: 1
2013-08-31 00:16:31,110 INFO org.apache.hadoop.yarn.server.resourcemanager.scheduler.capacity.ParentQueue: Application added - appId: application_1377907764744_0003 user: ubuntu leaf-queue of parent: root #applications: 1
2013-08-31 00:16:31,111 INFO org.apache.hadoop.yarn.server.resourcemanager.scheduler.capacity.CapacityScheduler: Application Submission: appattempt_1377907764744_0003_000001, user: ubuntu queue: default: capacity=1.0, absoluteCapacity=1.0, usedResources=<memory:0, vCores:0>usedCapacity=0.0, absoluteUsedCapacity=0.0, numApps=1, numContainers=0, currently active: 1
2013-08-31 00:16:31,111 INFO org.apache.hadoop.yarn.server.resourcemanager.rmapp.attempt.RMAppAttemptImpl: appattempt_1377907764744_0003_000001 State change from SUBMITTED to SCHEDULED
2013-08-31 00:16:31,111 INFO org.apache.hadoop.yarn.server.resourcemanager.rmapp.RMAppImpl: application_1377907764744_0003 State change from SUBMITTED to ACCEPTED
2013-08-31 00:16:31,141 INFO org.apache.hadoop.yarn.server.resourcemanager.rmcontainer.RMContainerImpl: container_1377907764744_0003_01_000001 Container Transitioned from NEW to ALLOCATED
2013-08-31 00:16:31,142 INFO org.apache.hadoop.yarn.server.resourcemanager.RMAuditLogger: USER=ubuntu	OPERATION=AM Allocated Container	TARGET=SchedulerApp	RESULT=SUCCESS	APPID=application_1377907764744_0003	CONTAINERID=container_1377907764744_0003_01_000001
2013-08-31 00:16:31,142 INFO org.apache.hadoop.yarn.server.resourcemanager.scheduler.common.fica.FiCaSchedulerNode: Assigned container container_1377907764744_0003_01_000001 of capacity <memory:2048, vCores:1> on host hadoop-32-7:54070, which currently has 1 containers, <memory:2048, vCores:1> used and <memory:6144, vCores:15> available
2013-08-31 00:16:31,143 INFO org.apache.hadoop.yarn.server.resourcemanager.scheduler.capacity.LeafQueue: assignedContainer application=application_1377907764744_0003 container=Container: [ContainerId: container_1377907764744_0003_01_000001, NodeId: hadoop-32-7:54070, NodeHttpAddress: hadoop-32-7:8042, Resource: <memory:2048, vCores:1>, Priority: 0, State: NEW, Token: null, Status: container_id {, app_attempt_id {, application_id {, id: 3, cluster_timestamp: 1377907764744, }, attemptId: 1, }, id: 1, }, state: C_NEW, ] containerId=container_1377907764744_0003_01_000001 queue=default: capacity=1.0, absoluteCapacity=1.0, usedResources=<memory:0, vCores:0>usedCapacity=0.0, absoluteUsedCapacity=0.0, numApps=1, numContainers=0 usedCapacity=0.0 absoluteUsedCapacity=0.0 used=<memory:0, vCores:0> cluster=<memory:49152, vCores:96>
2013-08-31 00:16:31,144 INFO org.apache.hadoop.yarn.server.resourcemanager.scheduler.capacity.ParentQueue: Re-sorting queues since queue: root.default stats: default: capacity=1.0, absoluteCapacity=1.0, usedResources=<memory:2048, vCores:1>usedCapacity=0.041666668, absoluteUsedCapacity=0.041666668, numApps=1, numContainers=1
2013-08-31 00:16:31,144 INFO org.apache.hadoop.yarn.server.resourcemanager.scheduler.capacity.ParentQueue: assignedContainer queue=root usedCapacity=0.041666668 absoluteUsedCapacity=0.041666668 used=<memory:2048, vCores:1> cluster=<memory:49152, vCores:96>
2013-08-31 00:16:31,145 INFO org.apache.hadoop.yarn.server.resourcemanager.rmcontainer.RMContainerImpl: container_1377907764744_0003_01_000001 Container Transitioned from ALLOCATED to ACQUIRED
2013-08-31 00:16:31,149 INFO org.apache.hadoop.yarn.server.resourcemanager.rmapp.attempt.RMAppAttemptImpl: Storing attempt: AppId: application_1377907764744_0003 AttemptId: appattempt_1377907764744_0003_000001 MasterContainer: Container: [ContainerId: container_1377907764744_0003_01_000001, NodeId: hadoop-32-7:54070, NodeHttpAddress: hadoop-32-7:8042, Resource: <memory:2048, vCores:1>, Priority: 0, State: NEW, Token: null, Status: container_id {, app_attempt_id {, application_id {, id: 3, cluster_timestamp: 1377907764744, }, attemptId: 1, }, id: 1, }, state: C_NEW, ]
2013-08-31 00:16:31,149 INFO org.apache.hadoop.yarn.server.resourcemanager.rmapp.attempt.RMAppAttemptImpl: appattempt_1377907764744_0003_000001 State change from SCHEDULED to ALLOCATED_SAVING
2013-08-31 00:16:31,149 INFO org.apache.hadoop.yarn.server.resourcemanager.recovery.RMStateStore: Storing info for attempt: appattempt_1377907764744_0003_000001
2013-08-31 00:16:31,153 INFO org.apache.hadoop.yarn.server.resourcemanager.rmapp.attempt.RMAppAttemptImpl: appattempt_1377907764744_0003_000001 State change from ALLOCATED_SAVING to ALLOCATED
2013-08-31 00:16:31,154 INFO org.apache.hadoop.yarn.server.resourcemanager.amlauncher.AMLauncher: Launching masterappattempt_1377907764744_0003_000001
2013-08-31 00:16:31,157 INFO org.apache.hadoop.yarn.server.resourcemanager.amlauncher.AMLauncher: Setting up container Container: [ContainerId: container_1377907764744_0003_01_000001, NodeId: hadoop-32-7:54070, NodeHttpAddress: hadoop-32-7:8042, Resource: <memory:2048, vCores:1>, Priority: 0, State: NEW, Token: null, Status: container_id {, app_attempt_id {, application_id {, id: 3, cluster_timestamp: 1377907764744, }, attemptId: 1, }, id: 1, }, state: C_NEW, ] for AM appattempt_1377907764744_0003_000001
2013-08-31 00:16:31,157 INFO org.apache.hadoop.yarn.server.resourcemanager.amlauncher.AMLauncher: Command to launch container container_1377907764744_0003_01_000001 : $JAVA_HOME/bin/java -Dlog4j.configuration=container-log4j.properties -Dyarn.app.mapreduce.container.log.dir=<LOG_DIR> -Dyarn.app.mapreduce.container.log.filesize=0 -Dhadoop.root.logger=INFO,CLA  -Xmx1024m org.apache.hadoop.mapreduce.v2.app.MRAppMaster 1><LOG_DIR>/stdout 2><LOG_DIR>/stderr 
2013-08-31 00:16:31,997 INFO org.apache.hadoop.yarn.server.resourcemanager.amlauncher.AMLauncher: Done launching container Container: [ContainerId: container_1377907764744_0003_01_000001, NodeId: hadoop-32-7:54070, NodeHttpAddress: hadoop-32-7:8042, Resource: <memory:2048, vCores:1>, Priority: 0, State: NEW, Token: null, Status: container_id {, app_attempt_id {, application_id {, id: 3, cluster_timestamp: 1377907764744, }, attemptId: 1, }, id: 1, }, state: C_NEW, ] for AM appattempt_1377907764744_0003_000001
2013-08-31 00:16:31,997 INFO org.apache.hadoop.yarn.server.resourcemanager.rmapp.attempt.RMAppAttemptImpl: appattempt_1377907764744_0003_000001 State change from ALLOCATED to LAUNCHED
2013-08-31 00:16:32,237 INFO org.apache.hadoop.yarn.server.resourcemanager.rmcontainer.RMContainerImpl: container_1377907764744_0003_01_000001 Container Transitioned from ACQUIRED to RUNNING
2013-08-31 00:16:40,799 INFO org.apache.hadoop.yarn.server.resourcemanager.ApplicationMasterService: AM registration appattempt_1377907764744_0003_000001
2013-08-31 00:16:40,799 INFO org.apache.hadoop.yarn.server.resourcemanager.RMAuditLogger: USER=ubuntu	IP=192.168.100.38	OPERATION=Register App Master	TARGET=ApplicationMasterService	RESULT=SUCCESS	APPID=application_1377907764744_0003	APPATTEMPTID=appattempt_1377907764744_0003_000001
2013-08-31 00:16:40,800 INFO org.apache.hadoop.yarn.server.resourcemanager.rmapp.attempt.RMAppAttemptImpl: appattempt_1377907764744_0003_000001 State change from LAUNCHED to RUNNING
2013-08-31 00:16:40,800 INFO org.apache.hadoop.yarn.server.resourcemanager.rmapp.RMAppImpl: application_1377907764744_0003 State change from ACCEPTED to RUNNING
2013-08-31 00:16:43,284 INFO org.apache.hadoop.yarn.server.resourcemanager.rmcontainer.RMContainerImpl: container_1377907764744_0003_01_000002 Container Transitioned from NEW to ALLOCATED
2013-08-31 00:16:43,294 INFO org.apache.hadoop.yarn.server.resourcemanager.RMAuditLogger: USER=ubuntu	OPERATION=AM Allocated Container	TARGET=SchedulerApp	RESULT=SUCCESS	APPID=application_1377907764744_0003	CONTAINERID=container_1377907764744_0003_01_000002
2013-08-31 00:16:43,294 INFO org.apache.hadoop.yarn.server.resourcemanager.scheduler.common.fica.FiCaSchedulerNode: Assigned container container_1377907764744_0003_01_000002 of capacity <memory:1024, vCores:1> on host hadoop-32-5:54799, which currently has 1 containers, <memory:1024, vCores:1> used and <memory:7168, vCores:15> available
2013-08-31 00:16:43,296 INFO org.apache.hadoop.yarn.server.resourcemanager.scheduler.capacity.LeafQueue: assignedContainer application=application_1377907764744_0003 container=Container: [ContainerId: container_1377907764744_0003_01_000002, NodeId: hadoop-32-5:54799, NodeHttpAddress: hadoop-32-5:8042, Resource: <memory:1024, vCores:1>, Priority: 20, State: NEW, Token: null, Status: container_id {, app_attempt_id {, application_id {, id: 3, cluster_timestamp: 1377907764744, }, attemptId: 1, }, id: 2, }, state: C_NEW, ] containerId=container_1377907764744_0003_01_000002 queue=default: capacity=1.0, absoluteCapacity=1.0, usedResources=<memory:2048, vCores:1>usedCapacity=0.041666668, absoluteUsedCapacity=0.041666668, numApps=1, numContainers=1 usedCapacity=0.041666668 absoluteUsedCapacity=0.041666668 used=<memory:2048, vCores:1> cluster=<memory:49152, vCores:96>
2013-08-31 00:16:43,296 INFO org.apache.hadoop.yarn.server.resourcemanager.scheduler.capacity.ParentQueue: Re-sorting queues since queue: root.default stats: default: capacity=1.0, absoluteCapacity=1.0, usedResources=<memory:3072, vCores:2>usedCapacity=0.0625, absoluteUsedCapacity=0.0625, numApps=1, numContainers=2
2013-08-31 00:16:43,296 INFO org.apache.hadoop.yarn.server.resourcemanager.scheduler.capacity.ParentQueue: assignedContainer queue=root usedCapacity=0.0625 absoluteUsedCapacity=0.0625 used=<memory:3072, vCores:2> cluster=<memory:49152, vCores:96>
2013-08-31 00:16:43,306 INFO org.apache.hadoop.yarn.server.resourcemanager.rmcontainer.RMContainerImpl: container_1377907764744_0003_01_000003 Container Transitioned from NEW to ALLOCATED
2013-08-31 00:16:43,307 INFO org.apache.hadoop.yarn.server.resourcemanager.RMAuditLogger: USER=ubuntu	OPERATION=AM Allocated Container	TARGET=SchedulerApp	RESULT=SUCCESS	APPID=application_1377907764744_0003	CONTAINERID=container_1377907764744_0003_01_000003
2013-08-31 00:16:43,307 INFO org.apache.hadoop.yarn.server.resourcemanager.scheduler.common.fica.FiCaSchedulerNode: Assigned container container_1377907764744_0003_01_000003 of capacity <memory:1024, vCores:1> on host hadoop-32-7:54070, which currently has 2 containers, <memory:3072, vCores:2> used and <memory:5120, vCores:14> available
2013-08-31 00:16:43,308 INFO org.apache.hadoop.yarn.server.resourcemanager.scheduler.capacity.LeafQueue: assignedContainer application=application_1377907764744_0003 container=Container: [ContainerId: container_1377907764744_0003_01_000003, NodeId: hadoop-32-7:54070, NodeHttpAddress: hadoop-32-7:8042, Resource: <memory:1024, vCores:1>, Priority: 20, State: NEW, Token: null, Status: container_id {, app_attempt_id {, application_id {, id: 3, cluster_timestamp: 1377907764744, }, attemptId: 1, }, id: 3, }, state: C_NEW, ] containerId=container_1377907764744_0003_01_000003 queue=default: capacity=1.0, absoluteCapacity=1.0, usedResources=<memory:3072, vCores:2>usedCapacity=0.0625, absoluteUsedCapacity=0.0625, numApps=1, numContainers=2 usedCapacity=0.0625 absoluteUsedCapacity=0.0625 used=<memory:3072, vCores:2> cluster=<memory:49152, vCores:96>
2013-08-31 00:16:43,309 INFO org.apache.hadoop.yarn.server.resourcemanager.scheduler.capacity.ParentQueue: Re-sorting queues since queue: root.default stats: default: capacity=1.0, absoluteCapacity=1.0, usedResources=<memory:4096, vCores:3>usedCapacity=0.083333336, absoluteUsedCapacity=0.083333336, numApps=1, numContainers=3
2013-08-31 00:16:43,309 INFO org.apache.hadoop.yarn.server.resourcemanager.scheduler.capacity.ParentQueue: assignedContainer queue=root usedCapacity=0.083333336 absoluteUsedCapacity=0.083333336 used=<memory:4096, vCores:3> cluster=<memory:49152, vCores:96>
2013-08-31 00:16:43,973 INFO org.apache.hadoop.yarn.server.resourcemanager.rmcontainer.RMContainerImpl: container_1377907764744_0003_01_000002 Container Transitioned from ALLOCATED to ACQUIRED
2013-08-31 00:16:43,975 INFO org.apache.hadoop.yarn.server.resourcemanager.rmcontainer.RMContainerImpl: container_1377907764744_0003_01_000003 Container Transitioned from ALLOCATED to ACQUIRED
2013-08-31 00:16:44,318 INFO org.apache.hadoop.yarn.server.resourcemanager.rmcontainer.RMContainerImpl: container_1377907764744_0003_01_000003 Container Transitioned from ACQUIRED to RUNNING
2013-08-31 00:16:45,002 INFO org.apache.hadoop.yarn.server.resourcemanager.scheduler.AppSchedulingInfo: checking for deactivate... 
2013-08-31 00:16:45,294 INFO org.apache.hadoop.yarn.server.resourcemanager.rmcontainer.RMContainerImpl: container_1377907764744_0003_01_000002 Container Transitioned from ACQUIRED to RUNNING
2013-08-31 00:19:27,308 INFO org.apache.hadoop.yarn.server.resourcemanager.rmcontainer.RMContainerImpl: container_1377907764744_0003_01_000003 Container Transitioned from RUNNING to COMPLETED
2013-08-31 00:19:27,308 INFO org.apache.hadoop.yarn.server.resourcemanager.scheduler.common.fica.FiCaSchedulerApp: Completed container: container_1377907764744_0003_01_000003 in state: COMPLETED event:FINISHED
2013-08-31 00:19:27,309 INFO org.apache.hadoop.yarn.server.resourcemanager.RMAuditLogger: USER=ubuntu	OPERATION=AM Released Container	TARGET=SchedulerApp	RESULT=SUCCESS	APPID=application_1377907764744_0003	CONTAINERID=container_1377907764744_0003_01_000003
2013-08-31 00:19:27,309 INFO org.apache.hadoop.yarn.server.resourcemanager.scheduler.common.fica.FiCaSchedulerNode: Released container container_1377907764744_0003_01_000003 of capacity <memory:1024, vCores:1> on host hadoop-32-7:54070, which currently has 1 containers, <memory:2048, vCores:1> used and <memory:6144, vCores:15> available, release resources=true
2013-08-31 00:19:27,309 INFO org.apache.hadoop.yarn.server.resourcemanager.scheduler.capacity.LeafQueue: default used=<memory:3072, vCores:2> numContainers=2 user=ubuntu user-resources=<memory:3072, vCores:2>
2013-08-31 00:19:27,311 INFO org.apache.hadoop.yarn.server.resourcemanager.scheduler.capacity.LeafQueue: completedContainer container=Container: [ContainerId: container_1377907764744_0003_01_000003, NodeId: hadoop-32-7:54070, NodeHttpAddress: hadoop-32-7:8042, Resource: <memory:1024, vCores:1>, Priority: 20, State: NEW, Token: null, Status: container_id {, app_attempt_id {, application_id {, id: 3, cluster_timestamp: 1377907764744, }, attemptId: 1, }, id: 3, }, state: C_COMPLETE, diagnostics: "Container killed by the ApplicationMaster.\n\n", exit_status: 143, ] resource=<memory:1024, vCores:1> queue=default: capacity=1.0, absoluteCapacity=1.0, usedResources=<memory:3072, vCores:2>usedCapacity=0.0625, absoluteUsedCapacity=0.0625, numApps=1, numContainers=2 usedCapacity=0.0625 absoluteUsedCapacity=0.0625 used=<memory:3072, vCores:2> cluster=<memory:49152, vCores:96>
2013-08-31 00:19:27,311 INFO org.apache.hadoop.yarn.server.resourcemanager.scheduler.capacity.ParentQueue: completedContainer queue=root usedCapacity=0.0625 absoluteUsedCapacity=0.0625 used=<memory:3072, vCores:2> cluster=<memory:49152, vCores:96>
2013-08-31 00:19:27,311 INFO org.apache.hadoop.yarn.server.resourcemanager.scheduler.capacity.CapacityScheduler: Application appattempt_1377907764744_0003_000001 released container container_1377907764744_0003_01_000003 on node: host: hadoop-32-7:54070 #containers=1 available=6144 used=2048 with event: FINISHED
2013-08-31 00:19:34,725 INFO org.apache.hadoop.yarn.server.resourcemanager.rmcontainer.RMContainerImpl: container_1377907764744_0003_01_000002 Container Transitioned from RUNNING to COMPLETED
2013-08-31 00:19:34,726 INFO org.apache.hadoop.yarn.server.resourcemanager.scheduler.common.fica.FiCaSchedulerApp: Completed container: container_1377907764744_0003_01_000002 in state: COMPLETED event:FINISHED
2013-08-31 00:19:34,726 INFO org.apache.hadoop.yarn.server.resourcemanager.RMAuditLogger: USER=ubuntu	OPERATION=AM Released Container	TARGET=SchedulerApp	RESULT=SUCCESS	APPID=application_1377907764744_0003	CONTAINERID=container_1377907764744_0003_01_000002
2013-08-31 00:19:34,726 INFO org.apache.hadoop.yarn.server.resourcemanager.scheduler.common.fica.FiCaSchedulerNode: Released container container_1377907764744_0003_01_000002 of capacity <memory:1024, vCores:1> on host hadoop-32-5:54799, which currently has 0 containers, <memory:0, vCores:0> used and <memory:8192, vCores:16> available, release resources=true
2013-08-31 00:19:34,726 INFO org.apache.hadoop.yarn.server.resourcemanager.scheduler.capacity.LeafQueue: default used=<memory:2048, vCores:1> numContainers=1 user=ubuntu user-resources=<memory:2048, vCores:1>
2013-08-31 00:19:34,728 INFO org.apache.hadoop.yarn.server.resourcemanager.scheduler.capacity.LeafQueue: completedContainer container=Container: [ContainerId: container_1377907764744_0003_01_000002, NodeId: hadoop-32-5:54799, NodeHttpAddress: hadoop-32-5:8042, Resource: <memory:1024, vCores:1>, Priority: 20, State: NEW, Token: null, Status: container_id {, app_attempt_id {, application_id {, id: 3, cluster_timestamp: 1377907764744, }, attemptId: 1, }, id: 2, }, state: C_COMPLETE, diagnostics: "Container killed by the ApplicationMaster.\n\n", exit_status: 143, ] resource=<memory:1024, vCores:1> queue=default: capacity=1.0, absoluteCapacity=1.0, usedResources=<memory:2048, vCores:1>usedCapacity=0.041666668, absoluteUsedCapacity=0.041666668, numApps=1, numContainers=1 usedCapacity=0.041666668 absoluteUsedCapacity=0.041666668 used=<memory:2048, vCores:1> cluster=<memory:49152, vCores:96>
2013-08-31 00:19:34,728 INFO org.apache.hadoop.yarn.server.resourcemanager.scheduler.capacity.ParentQueue: completedContainer queue=root usedCapacity=0.041666668 absoluteUsedCapacity=0.041666668 used=<memory:2048, vCores:1> cluster=<memory:49152, vCores:96>
2013-08-31 00:19:34,728 INFO org.apache.hadoop.yarn.server.resourcemanager.scheduler.capacity.CapacityScheduler: Application appattempt_1377907764744_0003_000001 released container container_1377907764744_0003_01_000002 on node: host: hadoop-32-5:54799 #containers=0 available=8192 used=0 with event: FINISHED
2013-08-31 00:19:38,901 INFO org.apache.hadoop.yarn.server.resourcemanager.rmapp.attempt.RMAppAttemptImpl: appattempt_1377907764744_0003_000001 State change from RUNNING to FINISHING
2013-08-31 00:19:38,902 INFO org.apache.hadoop.yarn.server.resourcemanager.rmapp.RMAppImpl: application_1377907764744_0003 State change from RUNNING to FINISHING
2013-08-31 00:19:39,366 INFO org.apache.hadoop.yarn.server.resourcemanager.rmcontainer.RMContainerImpl: container_1377907764744_0003_01_000001 Container Transitioned from RUNNING to COMPLETED
2013-08-31 00:19:39,367 INFO org.apache.hadoop.yarn.server.resourcemanager.scheduler.common.fica.FiCaSchedulerApp: Completed container: container_1377907764744_0003_01_000001 in state: COMPLETED event:FINISHED
2013-08-31 00:19:39,367 INFO org.apache.hadoop.yarn.server.resourcemanager.RMAuditLogger: USER=ubuntu	OPERATION=AM Released Container	TARGET=SchedulerApp	RESULT=SUCCESS	APPID=application_1377907764744_0003	CONTAINERID=container_1377907764744_0003_01_000001
2013-08-31 00:19:39,367 INFO org.apache.hadoop.yarn.server.resourcemanager.scheduler.common.fica.FiCaSchedulerNode: Released container container_1377907764744_0003_01_000001 of capacity <memory:2048, vCores:1> on host hadoop-32-7:54070, which currently has 0 containers, <memory:0, vCores:0> used and <memory:8192, vCores:16> available, release resources=true
2013-08-31 00:19:39,367 INFO org.apache.hadoop.yarn.server.resourcemanager.scheduler.capacity.LeafQueue: default used=<memory:0, vCores:0> numContainers=0 user=ubuntu user-resources=<memory:0, vCores:0>
2013-08-31 00:19:39,369 INFO org.apache.hadoop.yarn.server.resourcemanager.scheduler.capacity.LeafQueue: completedContainer container=Container: [ContainerId: container_1377907764744_0003_01_000001, NodeId: hadoop-32-7:54070, NodeHttpAddress: hadoop-32-7:8042, Resource: <memory:2048, vCores:1>, Priority: 0, State: NEW, Token: null, Status: container_id {, app_attempt_id {, application_id {, id: 3, cluster_timestamp: 1377907764744, }, attemptId: 1, }, id: 1, }, state: C_COMPLETE, diagnostics: "", exit_status: 0, ] resource=<memory:2048, vCores:1> queue=default: capacity=1.0, absoluteCapacity=1.0, usedResources=<memory:0, vCores:0>usedCapacity=0.0, absoluteUsedCapacity=0.0, numApps=1, numContainers=0 usedCapacity=0.0 absoluteUsedCapacity=0.0 used=<memory:0, vCores:0> cluster=<memory:49152, vCores:96>
2013-08-31 00:19:39,369 INFO org.apache.hadoop.yarn.server.resourcemanager.scheduler.capacity.ParentQueue: completedContainer queue=root usedCapacity=0.0 absoluteUsedCapacity=0.0 used=<memory:0, vCores:0> cluster=<memory:49152, vCores:96>
2013-08-31 00:19:39,369 INFO org.apache.hadoop.yarn.server.resourcemanager.scheduler.capacity.CapacityScheduler: Application appattempt_1377907764744_0003_000001 released container container_1377907764744_0003_01_000001 on node: host: hadoop-32-7:54070 #containers=0 available=8192 used=0 with event: FINISHED
2013-08-31 00:19:39,369 INFO org.apache.hadoop.yarn.server.resourcemanager.rmapp.attempt.RMAppAttemptImpl: appattempt_1377907764744_0003_000001 State change from FINISHING to FINISHED
2013-08-31 00:19:39,370 INFO org.apache.hadoop.yarn.server.resourcemanager.rmapp.RMAppImpl: application_1377907764744_0003 State change from FINISHING to FINISHED
2013-08-31 00:19:39,370 INFO org.apache.hadoop.yarn.server.resourcemanager.RMAuditLogger: USER=ubuntu	OPERATION=Application Finished - Succeeded	TARGET=RMAppManager	RESULT=SUCCESS	APPID=application_1377907764744_0003
2013-08-31 00:19:39,370 INFO org.apache.hadoop.yarn.server.resourcemanager.scheduler.capacity.CapacityScheduler: Application appattempt_1377907764744_0003_000001 is done. finalState=FINISHED
2013-08-31 00:19:39,370 INFO org.apache.hadoop.yarn.server.resourcemanager.recovery.RMStateStore: Removing info for app: application_1377907764744_0003
2013-08-31 00:19:39,371 INFO org.apache.hadoop.yarn.server.resourcemanager.scheduler.AppSchedulingInfo: Application application_1377907764744_0003 requests cleared
2013-08-31 00:19:39,370 INFO org.apache.hadoop.yarn.server.resourcemanager.RMAppManager$ApplicationSummary: appId=application_1377907764744_0003,name=TeraGen,user=ubuntu,queue=default,state=FINISHED,trackingUrl=hadoop-32-1.novalocal:8088/proxy/application_1377907764744_0003/jobhistory/job/job_1377907764744_0003,appMasterHost=hadoop-32-7,startTime=1377908191105,finishTime=1377908378902
2013-08-31 00:19:39,371 INFO org.apache.hadoop.yarn.server.resourcemanager.scheduler.capacity.LeafQueue: Application removed - appId: application_1377907764744_0003 user: ubuntu queue: default #user-pending-applications: 0 #user-active-applications: 0 #queue-pending-applications: 0 #queue-active-applications: 0
2013-08-31 00:19:39,371 INFO org.apache.hadoop.yarn.server.resourcemanager.amlauncher.AMLauncher: Cleaning master appattempt_1377907764744_0003_000001
2013-08-31 00:19:39,371 INFO org.apache.hadoop.yarn.server.resourcemanager.scheduler.capacity.ParentQueue: Application removed - appId: application_1377907764744_0003 user: ubuntu leaf-queue of parent: root #applications: 0
2013-08-31 00:19:40,186 INFO org.apache.hadoop.yarn.server.resourcemanager.ClientRMService: Allocated new applicationId: 4
2013-08-31 00:19:42,110 INFO org.apache.hadoop.yarn.server.resourcemanager.ClientRMService: Storing Application with id application_1377907764744_0004
2013-08-31 00:19:42,110 INFO org.apache.hadoop.yarn.server.resourcemanager.recovery.RMStateStore: Storing info for app: application_1377907764744_0004
2013-08-31 00:19:42,110 INFO org.apache.hadoop.yarn.server.resourcemanager.ClientRMService: Application with id 4 submitted by user ubuntu
2013-08-31 00:19:42,110 INFO org.apache.hadoop.yarn.server.resourcemanager.RMAuditLogger: USER=ubuntu	IP=192.168.100.5	OPERATION=Submit Application Request	TARGET=ClientRMService	RESULT=SUCCESS	APPID=application_1377907764744_0004
2013-08-31 00:19:42,113 INFO org.apache.hadoop.yarn.server.resourcemanager.rmapp.RMAppImpl: application_1377907764744_0004 State change from NEW to SUBMITTED
2013-08-31 00:19:42,113 INFO org.apache.hadoop.yarn.server.resourcemanager.ApplicationMasterService: Registering appattempt_1377907764744_0004_000001
2013-08-31 00:19:42,113 INFO org.apache.hadoop.yarn.server.resourcemanager.rmapp.attempt.RMAppAttemptImpl: appattempt_1377907764744_0004_000001 State change from NEW to SUBMITTED
2013-08-31 00:19:42,114 INFO org.apache.hadoop.yarn.server.resourcemanager.scheduler.capacity.LeafQueue: Application application_1377907764744_0004 from user: ubuntu activated in queue: default
2013-08-31 00:19:42,114 INFO org.apache.hadoop.yarn.server.resourcemanager.scheduler.capacity.LeafQueue: Application added - appId: application_1377907764744_0004 user: org.apache.hadoop.yarn.server.resourcemanager.scheduler.capacity.LeafQueue$User@7431d461, leaf-queue: default #user-pending-applications: 0 #user-active-applications: 1 #queue-pending-applications: 0 #queue-active-applications: 1
2013-08-31 00:19:42,114 INFO org.apache.hadoop.yarn.server.resourcemanager.scheduler.capacity.ParentQueue: Application added - appId: application_1377907764744_0004 user: ubuntu leaf-queue of parent: root #applications: 1
2013-08-31 00:19:42,115 INFO org.apache.hadoop.yarn.server.resourcemanager.scheduler.capacity.CapacityScheduler: Application Submission: appattempt_1377907764744_0004_000001, user: ubuntu queue: default: capacity=1.0, absoluteCapacity=1.0, usedResources=<memory:0, vCores:0>usedCapacity=0.0, absoluteUsedCapacity=0.0, numApps=1, numContainers=0, currently active: 1
2013-08-31 00:19:42,115 INFO org.apache.hadoop.yarn.server.resourcemanager.rmapp.attempt.RMAppAttemptImpl: appattempt_1377907764744_0004_000001 State change from SUBMITTED to SCHEDULED
2013-08-31 00:19:42,115 INFO org.apache.hadoop.yarn.server.resourcemanager.rmapp.RMAppImpl: application_1377907764744_0004 State change from SUBMITTED to ACCEPTED
2013-08-31 00:19:42,257 INFO org.apache.hadoop.yarn.server.resourcemanager.rmcontainer.RMContainerImpl: container_1377907764744_0004_01_000001 Container Transitioned from NEW to ALLOCATED
2013-08-31 00:19:42,257 INFO org.apache.hadoop.yarn.server.resourcemanager.RMAuditLogger: USER=ubuntu	OPERATION=AM Allocated Container	TARGET=SchedulerApp	RESULT=SUCCESS	APPID=application_1377907764744_0004	CONTAINERID=container_1377907764744_0004_01_000001
2013-08-31 00:19:42,258 INFO org.apache.hadoop.yarn.server.resourcemanager.scheduler.common.fica.FiCaSchedulerNode: Assigned container container_1377907764744_0004_01_000001 of capacity <memory:2048, vCores:1> on host hadoop-32-3:33603, which currently has 1 containers, <memory:2048, vCores:1> used and <memory:6144, vCores:15> available
2013-08-31 00:19:42,259 INFO org.apache.hadoop.yarn.server.resourcemanager.scheduler.capacity.LeafQueue: assignedContainer application=application_1377907764744_0004 container=Container: [ContainerId: container_1377907764744_0004_01_000001, NodeId: hadoop-32-3:33603, NodeHttpAddress: hadoop-32-3:8042, Resource: <memory:2048, vCores:1>, Priority: 0, State: NEW, Token: null, Status: container_id {, app_attempt_id {, application_id {, id: 4, cluster_timestamp: 1377907764744, }, attemptId: 1, }, id: 1, }, state: C_NEW, ] containerId=container_1377907764744_0004_01_000001 queue=default: capacity=1.0, absoluteCapacity=1.0, usedResources=<memory:0, vCores:0>usedCapacity=0.0, absoluteUsedCapacity=0.0, numApps=1, numContainers=0 usedCapacity=0.0 absoluteUsedCapacity=0.0 used=<memory:0, vCores:0> cluster=<memory:49152, vCores:96>
2013-08-31 00:19:42,259 INFO org.apache.hadoop.yarn.server.resourcemanager.scheduler.capacity.ParentQueue: Re-sorting queues since queue: root.default stats: default: capacity=1.0, absoluteCapacity=1.0, usedResources=<memory:2048, vCores:1>usedCapacity=0.041666668, absoluteUsedCapacity=0.041666668, numApps=1, numContainers=1
2013-08-31 00:19:42,260 INFO org.apache.hadoop.yarn.server.resourcemanager.scheduler.capacity.ParentQueue: assignedContainer queue=root usedCapacity=0.041666668 absoluteUsedCapacity=0.041666668 used=<memory:2048, vCores:1> cluster=<memory:49152, vCores:96>
2013-08-31 00:19:42,262 INFO org.apache.hadoop.yarn.server.resourcemanager.rmcontainer.RMContainerImpl: container_1377907764744_0004_01_000001 Container Transitioned from ALLOCATED to ACQUIRED
2013-08-31 00:19:42,264 INFO org.apache.hadoop.yarn.server.resourcemanager.rmapp.attempt.RMAppAttemptImpl: Storing attempt: AppId: application_1377907764744_0004 AttemptId: appattempt_1377907764744_0004_000001 MasterContainer: Container: [ContainerId: container_1377907764744_0004_01_000001, NodeId: hadoop-32-3:33603, NodeHttpAddress: hadoop-32-3:8042, Resource: <memory:2048, vCores:1>, Priority: 0, State: NEW, Token: null, Status: container_id {, app_attempt_id {, application_id {, id: 4, cluster_timestamp: 1377907764744, }, attemptId: 1, }, id: 1, }, state: C_NEW, ]
2013-08-31 00:19:42,264 INFO org.apache.hadoop.yarn.server.resourcemanager.rmapp.attempt.RMAppAttemptImpl: appattempt_1377907764744_0004_000001 State change from SCHEDULED to ALLOCATED_SAVING
2013-08-31 00:19:42,264 INFO org.apache.hadoop.yarn.server.resourcemanager.recovery.RMStateStore: Storing info for attempt: appattempt_1377907764744_0004_000001
2013-08-31 00:19:42,265 INFO org.apache.hadoop.yarn.server.resourcemanager.rmapp.attempt.RMAppAttemptImpl: appattempt_1377907764744_0004_000001 State change from ALLOCATED_SAVING to ALLOCATED
2013-08-31 00:19:42,267 INFO org.apache.hadoop.yarn.server.resourcemanager.amlauncher.AMLauncher: Launching masterappattempt_1377907764744_0004_000001
2013-08-31 00:19:42,269 INFO org.apache.hadoop.yarn.server.resourcemanager.amlauncher.AMLauncher: Setting up container Container: [ContainerId: container_1377907764744_0004_01_000001, NodeId: hadoop-32-3:33603, NodeHttpAddress: hadoop-32-3:8042, Resource: <memory:2048, vCores:1>, Priority: 0, State: NEW, Token: null, Status: container_id {, app_attempt_id {, application_id {, id: 4, cluster_timestamp: 1377907764744, }, attemptId: 1, }, id: 1, }, state: C_NEW, ] for AM appattempt_1377907764744_0004_000001
2013-08-31 00:19:42,269 INFO org.apache.hadoop.yarn.server.resourcemanager.amlauncher.AMLauncher: Command to launch container container_1377907764744_0004_01_000001 : $JAVA_HOME/bin/java -Dlog4j.configuration=container-log4j.properties -Dyarn.app.mapreduce.container.log.dir=<LOG_DIR> -Dyarn.app.mapreduce.container.log.filesize=0 -Dhadoop.root.logger=INFO,CLA  -Xmx1024m org.apache.hadoop.mapreduce.v2.app.MRAppMaster 1><LOG_DIR>/stdout 2><LOG_DIR>/stderr 
2013-08-31 00:19:44,355 INFO org.apache.hadoop.yarn.server.resourcemanager.amlauncher.AMLauncher: Done launching container Container: [ContainerId: container_1377907764744_0004_01_000001, NodeId: hadoop-32-3:33603, NodeHttpAddress: hadoop-32-3:8042, Resource: <memory:2048, vCores:1>, Priority: 0, State: NEW, Token: null, Status: container_id {, app_attempt_id {, application_id {, id: 4, cluster_timestamp: 1377907764744, }, attemptId: 1, }, id: 1, }, state: C_NEW, ] for AM appattempt_1377907764744_0004_000001
2013-08-31 00:19:44,355 INFO org.apache.hadoop.yarn.server.resourcemanager.rmapp.attempt.RMAppAttemptImpl: appattempt_1377907764744_0004_000001 State change from ALLOCATED to LAUNCHED
2013-08-31 00:19:45,291 INFO org.apache.hadoop.yarn.server.resourcemanager.rmcontainer.RMContainerImpl: container_1377907764744_0004_01_000001 Container Transitioned from ACQUIRED to RUNNING
2013-08-31 00:19:52,075 INFO org.apache.hadoop.yarn.server.resourcemanager.ApplicationMasterService: AM registration appattempt_1377907764744_0004_000001
2013-08-31 00:19:52,075 INFO org.apache.hadoop.yarn.server.resourcemanager.RMAuditLogger: USER=ubuntu	IP=192.168.100.34	OPERATION=Register App Master	TARGET=ApplicationMasterService	RESULT=SUCCESS	APPID=application_1377907764744_0004	APPATTEMPTID=appattempt_1377907764744_0004_000001
2013-08-31 00:19:52,076 INFO org.apache.hadoop.yarn.server.resourcemanager.rmapp.attempt.RMAppAttemptImpl: appattempt_1377907764744_0004_000001 State change from LAUNCHED to RUNNING
2013-08-31 00:19:52,076 INFO org.apache.hadoop.yarn.server.resourcemanager.rmapp.RMAppImpl: application_1377907764744_0004 State change from ACCEPTED to RUNNING
2013-08-31 00:19:53,326 INFO org.apache.hadoop.yarn.server.resourcemanager.rmcontainer.RMContainerImpl: container_1377907764744_0004_01_000002 Container Transitioned from NEW to ALLOCATED
2013-08-31 00:19:53,326 INFO org.apache.hadoop.yarn.server.resourcemanager.RMAuditLogger: USER=ubuntu	OPERATION=AM Allocated Container	TARGET=SchedulerApp	RESULT=SUCCESS	APPID=application_1377907764744_0004	CONTAINERID=container_1377907764744_0004_01_000002
2013-08-31 00:19:53,327 INFO org.apache.hadoop.yarn.server.resourcemanager.scheduler.common.fica.FiCaSchedulerNode: Assigned container container_1377907764744_0004_01_000002 of capacity <memory:1024, vCores:1> on host hadoop-32-4:58137, which currently has 1 containers, <memory:1024, vCores:1> used and <memory:7168, vCores:15> available
2013-08-31 00:19:53,328 INFO org.apache.hadoop.yarn.server.resourcemanager.scheduler.capacity.LeafQueue: assignedContainer application=application_1377907764744_0004 container=Container: [ContainerId: container_1377907764744_0004_01_000002, NodeId: hadoop-32-4:58137, NodeHttpAddress: hadoop-32-4:8042, Resource: <memory:1024, vCores:1>, Priority: 20, State: NEW, Token: null, Status: container_id {, app_attempt_id {, application_id {, id: 4, cluster_timestamp: 1377907764744, }, attemptId: 1, }, id: 2, }, state: C_NEW, ] containerId=container_1377907764744_0004_01_000002 queue=default: capacity=1.0, absoluteCapacity=1.0, usedResources=<memory:2048, vCores:1>usedCapacity=0.041666668, absoluteUsedCapacity=0.041666668, numApps=1, numContainers=1 usedCapacity=0.041666668 absoluteUsedCapacity=0.041666668 used=<memory:2048, vCores:1> cluster=<memory:49152, vCores:96>
2013-08-31 00:19:53,328 INFO org.apache.hadoop.yarn.server.resourcemanager.scheduler.capacity.ParentQueue: Re-sorting queues since queue: root.default stats: default: capacity=1.0, absoluteCapacity=1.0, usedResources=<memory:3072, vCores:2>usedCapacity=0.0625, absoluteUsedCapacity=0.0625, numApps=1, numContainers=2
2013-08-31 00:19:53,329 INFO org.apache.hadoop.yarn.server.resourcemanager.scheduler.capacity.ParentQueue: assignedContainer queue=root usedCapacity=0.0625 absoluteUsedCapacity=0.0625 used=<memory:3072, vCores:2> cluster=<memory:49152, vCores:96>
2013-08-31 00:19:53,338 INFO org.apache.hadoop.yarn.server.resourcemanager.rmcontainer.RMContainerImpl: container_1377907764744_0004_01_000003 Container Transitioned from NEW to ALLOCATED
2013-08-31 00:19:53,338 INFO org.apache.hadoop.yarn.server.resourcemanager.RMAuditLogger: USER=ubuntu	OPERATION=AM Allocated Container	TARGET=SchedulerApp	RESULT=SUCCESS	APPID=application_1377907764744_0004	CONTAINERID=container_1377907764744_0004_01_000003
2013-08-31 00:19:53,338 INFO org.apache.hadoop.yarn.server.resourcemanager.scheduler.common.fica.FiCaSchedulerNode: Assigned container container_1377907764744_0004_01_000003 of capacity <memory:1024, vCores:1> on host hadoop-32-3:33603, which currently has 2 containers, <memory:3072, vCores:2> used and <memory:5120, vCores:14> available
2013-08-31 00:19:53,340 INFO org.apache.hadoop.yarn.server.resourcemanager.scheduler.capacity.LeafQueue: assignedContainer application=application_1377907764744_0004 container=Container: [ContainerId: container_1377907764744_0004_01_000003, NodeId: hadoop-32-3:33603, NodeHttpAddress: hadoop-32-3:8042, Resource: <memory:1024, vCores:1>, Priority: 20, State: NEW, Token: null, Status: container_id {, app_attempt_id {, application_id {, id: 4, cluster_timestamp: 1377907764744, }, attemptId: 1, }, id: 3, }, state: C_NEW, ] containerId=container_1377907764744_0004_01_000003 queue=default: capacity=1.0, absoluteCapacity=1.0, usedResources=<memory:3072, vCores:2>usedCapacity=0.0625, absoluteUsedCapacity=0.0625, numApps=1, numContainers=2 usedCapacity=0.0625 absoluteUsedCapacity=0.0625 used=<memory:3072, vCores:2> cluster=<memory:49152, vCores:96>
2013-08-31 00:19:53,340 INFO org.apache.hadoop.yarn.server.resourcemanager.scheduler.capacity.ParentQueue: Re-sorting queues since queue: root.default stats: default: capacity=1.0, absoluteCapacity=1.0, usedResources=<memory:4096, vCores:3>usedCapacity=0.083333336, absoluteUsedCapacity=0.083333336, numApps=1, numContainers=3
2013-08-31 00:19:53,340 INFO org.apache.hadoop.yarn.server.resourcemanager.scheduler.capacity.ParentQueue: assignedContainer queue=root usedCapacity=0.083333336 absoluteUsedCapacity=0.083333336 used=<memory:4096, vCores:3> cluster=<memory:49152, vCores:96>
2013-08-31 00:19:54,137 INFO org.apache.hadoop.yarn.server.resourcemanager.rmcontainer.RMContainerImpl: container_1377907764744_0004_01_000002 Container Transitioned from ALLOCATED to ACQUIRED
2013-08-31 00:19:54,139 INFO org.apache.hadoop.yarn.server.resourcemanager.rmcontainer.RMContainerImpl: container_1377907764744_0004_01_000003 Container Transitioned from ALLOCATED to ACQUIRED
2013-08-31 00:19:55,167 INFO org.apache.hadoop.yarn.server.resourcemanager.scheduler.AppSchedulingInfo: checking for deactivate... 
2013-08-31 00:19:55,337 INFO org.apache.hadoop.yarn.server.resourcemanager.rmcontainer.RMContainerImpl: container_1377907764744_0004_01_000002 Container Transitioned from ACQUIRED to RUNNING
2013-08-31 00:19:55,353 INFO org.apache.hadoop.yarn.server.resourcemanager.rmcontainer.RMContainerImpl: container_1377907764744_0004_01_000003 Container Transitioned from ACQUIRED to RUNNING
2013-08-31 00:22:35,630 INFO org.apache.hadoop.yarn.server.resourcemanager.rmcontainer.RMContainerImpl: container_1377907764744_0004_01_000003 Container Transitioned from RUNNING to COMPLETED
2013-08-31 00:22:35,630 INFO org.apache.hadoop.yarn.server.resourcemanager.scheduler.common.fica.FiCaSchedulerApp: Completed container: container_1377907764744_0004_01_000003 in state: COMPLETED event:FINISHED
2013-08-31 00:22:35,630 INFO org.apache.hadoop.yarn.server.resourcemanager.RMAuditLogger: USER=ubuntu	OPERATION=AM Released Container	TARGET=SchedulerApp	RESULT=SUCCESS	APPID=application_1377907764744_0004	CONTAINERID=container_1377907764744_0004_01_000003
2013-08-31 00:22:35,630 INFO org.apache.hadoop.yarn.server.resourcemanager.scheduler.common.fica.FiCaSchedulerNode: Released container container_1377907764744_0004_01_000003 of capacity <memory:1024, vCores:1> on host hadoop-32-3:33603, which currently has 1 containers, <memory:2048, vCores:1> used and <memory:6144, vCores:15> available, release resources=true
2013-08-31 00:22:35,631 INFO org.apache.hadoop.yarn.server.resourcemanager.scheduler.capacity.LeafQueue: default used=<memory:3072, vCores:2> numContainers=2 user=ubuntu user-resources=<memory:3072, vCores:2>
2013-08-31 00:22:35,632 INFO org.apache.hadoop.yarn.server.resourcemanager.scheduler.capacity.LeafQueue: completedContainer container=Container: [ContainerId: container_1377907764744_0004_01_000003, NodeId: hadoop-32-3:33603, NodeHttpAddress: hadoop-32-3:8042, Resource: <memory:1024, vCores:1>, Priority: 20, State: NEW, Token: null, Status: container_id {, app_attempt_id {, application_id {, id: 4, cluster_timestamp: 1377907764744, }, attemptId: 1, }, id: 3, }, state: C_COMPLETE, diagnostics: "Container killed by the ApplicationMaster.\n\n", exit_status: 143, ] resource=<memory:1024, vCores:1> queue=default: capacity=1.0, absoluteCapacity=1.0, usedResources=<memory:3072, vCores:2>usedCapacity=0.0625, absoluteUsedCapacity=0.0625, numApps=1, numContainers=2 usedCapacity=0.0625 absoluteUsedCapacity=0.0625 used=<memory:3072, vCores:2> cluster=<memory:49152, vCores:96>
2013-08-31 00:22:35,633 INFO org.apache.hadoop.yarn.server.resourcemanager.scheduler.capacity.ParentQueue: completedContainer queue=root usedCapacity=0.0625 absoluteUsedCapacity=0.0625 used=<memory:3072, vCores:2> cluster=<memory:49152, vCores:96>
2013-08-31 00:22:35,633 INFO org.apache.hadoop.yarn.server.resourcemanager.scheduler.capacity.CapacityScheduler: Application appattempt_1377907764744_0004_000001 released container container_1377907764744_0004_01_000003 on node: host: hadoop-32-3:33603 #containers=1 available=6144 used=2048 with event: FINISHED
2013-08-31 00:22:39,690 INFO org.apache.hadoop.yarn.server.resourcemanager.rmcontainer.RMContainerImpl: container_1377907764744_0004_01_000002 Container Transitioned from RUNNING to COMPLETED
2013-08-31 00:22:39,690 INFO org.apache.hadoop.yarn.server.resourcemanager.scheduler.common.fica.FiCaSchedulerApp: Completed container: container_1377907764744_0004_01_000002 in state: COMPLETED event:FINISHED
2013-08-31 00:22:39,691 INFO org.apache.hadoop.yarn.server.resourcemanager.RMAuditLogger: USER=ubuntu	OPERATION=AM Released Container	TARGET=SchedulerApp	RESULT=SUCCESS	APPID=application_1377907764744_0004	CONTAINERID=container_1377907764744_0004_01_000002
2013-08-31 00:22:39,691 INFO org.apache.hadoop.yarn.server.resourcemanager.scheduler.common.fica.FiCaSchedulerNode: Released container container_1377907764744_0004_01_000002 of capacity <memory:1024, vCores:1> on host hadoop-32-4:58137, which currently has 0 containers, <memory:0, vCores:0> used and <memory:8192, vCores:16> available, release resources=true
2013-08-31 00:22:39,691 INFO org.apache.hadoop.yarn.server.resourcemanager.scheduler.capacity.LeafQueue: default used=<memory:2048, vCores:1> numContainers=1 user=ubuntu user-resources=<memory:2048, vCores:1>
2013-08-31 00:22:39,693 INFO org.apache.hadoop.yarn.server.resourcemanager.scheduler.capacity.LeafQueue: completedContainer container=Container: [ContainerId: container_1377907764744_0004_01_000002, NodeId: hadoop-32-4:58137, NodeHttpAddress: hadoop-32-4:8042, Resource: <memory:1024, vCores:1>, Priority: 20, State: NEW, Token: null, Status: container_id {, app_attempt_id {, application_id {, id: 4, cluster_timestamp: 1377907764744, }, attemptId: 1, }, id: 2, }, state: C_COMPLETE, diagnostics: "Container killed by the ApplicationMaster.\n\n", exit_status: 143, ] resource=<memory:1024, vCores:1> queue=default: capacity=1.0, absoluteCapacity=1.0, usedResources=<memory:2048, vCores:1>usedCapacity=0.041666668, absoluteUsedCapacity=0.041666668, numApps=1, numContainers=1 usedCapacity=0.041666668 absoluteUsedCapacity=0.041666668 used=<memory:2048, vCores:1> cluster=<memory:49152, vCores:96>
2013-08-31 00:22:39,693 INFO org.apache.hadoop.yarn.server.resourcemanager.scheduler.capacity.ParentQueue: completedContainer queue=root usedCapacity=0.041666668 absoluteUsedCapacity=0.041666668 used=<memory:2048, vCores:1> cluster=<memory:49152, vCores:96>
2013-08-31 00:22:39,693 INFO org.apache.hadoop.yarn.server.resourcemanager.scheduler.capacity.CapacityScheduler: Application appattempt_1377907764744_0004_000001 released container container_1377907764744_0004_01_000002 on node: host: hadoop-32-4:58137 #containers=0 available=8192 used=0 with event: FINISHED
2013-08-31 00:22:44,569 INFO org.apache.hadoop.yarn.server.resourcemanager.rmapp.attempt.RMAppAttemptImpl: appattempt_1377907764744_0004_000001 State change from RUNNING to FINISHING
2013-08-31 00:22:44,569 INFO org.apache.hadoop.yarn.server.resourcemanager.rmapp.RMAppImpl: application_1377907764744_0004 State change from RUNNING to FINISHING
2013-08-31 00:22:45,021 INFO org.apache.hadoop.yarn.server.resourcemanager.ClientRMService: Allocated new applicationId: 5
2013-08-31 00:22:45,675 INFO org.apache.hadoop.yarn.server.resourcemanager.rmcontainer.RMContainerImpl: container_1377907764744_0004_01_000001 Container Transitioned from RUNNING to COMPLETED
2013-08-31 00:22:45,675 INFO org.apache.hadoop.yarn.server.resourcemanager.scheduler.common.fica.FiCaSchedulerApp: Completed container: container_1377907764744_0004_01_000001 in state: COMPLETED event:FINISHED
2013-08-31 00:22:45,675 INFO org.apache.hadoop.yarn.server.resourcemanager.RMAuditLogger: USER=ubuntu	OPERATION=AM Released Container	TARGET=SchedulerApp	RESULT=SUCCESS	APPID=application_1377907764744_0004	CONTAINERID=container_1377907764744_0004_01_000001
2013-08-31 00:22:45,675 INFO org.apache.hadoop.yarn.server.resourcemanager.scheduler.common.fica.FiCaSchedulerNode: Released container container_1377907764744_0004_01_000001 of capacity <memory:2048, vCores:1> on host hadoop-32-3:33603, which currently has 0 containers, <memory:0, vCores:0> used and <memory:8192, vCores:16> available, release resources=true
2013-08-31 00:22:45,675 INFO org.apache.hadoop.yarn.server.resourcemanager.scheduler.capacity.LeafQueue: default used=<memory:0, vCores:0> numContainers=0 user=ubuntu user-resources=<memory:0, vCores:0>
2013-08-31 00:22:45,677 INFO org.apache.hadoop.yarn.server.resourcemanager.scheduler.capacity.LeafQueue: completedContainer container=Container: [ContainerId: container_1377907764744_0004_01_000001, NodeId: hadoop-32-3:33603, NodeHttpAddress: hadoop-32-3:8042, Resource: <memory:2048, vCores:1>, Priority: 0, State: NEW, Token: null, Status: container_id {, app_attempt_id {, application_id {, id: 4, cluster_timestamp: 1377907764744, }, attemptId: 1, }, id: 1, }, state: C_COMPLETE, diagnostics: "", exit_status: 0, ] resource=<memory:2048, vCores:1> queue=default: capacity=1.0, absoluteCapacity=1.0, usedResources=<memory:0, vCores:0>usedCapacity=0.0, absoluteUsedCapacity=0.0, numApps=1, numContainers=0 usedCapacity=0.0 absoluteUsedCapacity=0.0 used=<memory:0, vCores:0> cluster=<memory:49152, vCores:96>
2013-08-31 00:22:45,677 INFO org.apache.hadoop.yarn.server.resourcemanager.scheduler.capacity.ParentQueue: completedContainer queue=root usedCapacity=0.0 absoluteUsedCapacity=0.0 used=<memory:0, vCores:0> cluster=<memory:49152, vCores:96>
2013-08-31 00:22:45,677 INFO org.apache.hadoop.yarn.server.resourcemanager.scheduler.capacity.CapacityScheduler: Application appattempt_1377907764744_0004_000001 released container container_1377907764744_0004_01_000001 on node: host: hadoop-32-3:33603 #containers=0 available=8192 used=0 with event: FINISHED
2013-08-31 00:22:45,678 INFO org.apache.hadoop.yarn.server.resourcemanager.rmapp.attempt.RMAppAttemptImpl: appattempt_1377907764744_0004_000001 State change from FINISHING to FINISHED
2013-08-31 00:22:45,680 INFO org.apache.hadoop.yarn.server.resourcemanager.rmapp.RMAppImpl: application_1377907764744_0004 State change from FINISHING to FINISHED
2013-08-31 00:22:45,680 INFO org.apache.hadoop.yarn.server.resourcemanager.scheduler.capacity.CapacityScheduler: Application appattempt_1377907764744_0004_000001 is done. finalState=FINISHED
2013-08-31 00:22:45,681 INFO org.apache.hadoop.yarn.server.resourcemanager.scheduler.AppSchedulingInfo: Application application_1377907764744_0004 requests cleared
2013-08-31 00:22:45,681 INFO org.apache.hadoop.yarn.server.resourcemanager.scheduler.capacity.LeafQueue: Application removed - appId: application_1377907764744_0004 user: ubuntu queue: default #user-pending-applications: 0 #user-active-applications: 0 #queue-pending-applications: 0 #queue-active-applications: 0
2013-08-31 00:22:45,681 INFO org.apache.hadoop.yarn.server.resourcemanager.scheduler.capacity.ParentQueue: Application removed - appId: application_1377907764744_0004 user: ubuntu leaf-queue of parent: root #applications: 0
2013-08-31 00:22:45,681 INFO org.apache.hadoop.yarn.server.resourcemanager.RMAuditLogger: USER=ubuntu	OPERATION=Application Finished - Succeeded	TARGET=RMAppManager	RESULT=SUCCESS	APPID=application_1377907764744_0004
2013-08-31 00:22:45,682 INFO org.apache.hadoop.yarn.server.resourcemanager.recovery.RMStateStore: Removing info for app: application_1377907764744_0004
2013-08-31 00:22:45,682 INFO org.apache.hadoop.yarn.server.resourcemanager.RMAppManager$ApplicationSummary: appId=application_1377907764744_0004,name=TeraGen,user=ubuntu,queue=default,state=FINISHED,trackingUrl=hadoop-32-1.novalocal:8088/proxy/application_1377907764744_0004/jobhistory/job/job_1377907764744_0004,appMasterHost=hadoop-32-3,startTime=1377908382109,finishTime=1377908564569
2013-08-31 00:22:45,682 INFO org.apache.hadoop.yarn.server.resourcemanager.amlauncher.AMLauncher: Cleaning master appattempt_1377907764744_0004_000001
2013-08-31 00:22:46,885 INFO org.apache.hadoop.yarn.server.resourcemanager.ClientRMService: Storing Application with id application_1377907764744_0005
2013-08-31 00:22:46,885 INFO org.apache.hadoop.yarn.server.resourcemanager.recovery.RMStateStore: Storing info for app: application_1377907764744_0005
2013-08-31 00:22:46,885 INFO org.apache.hadoop.yarn.server.resourcemanager.ClientRMService: Application with id 5 submitted by user ubuntu
2013-08-31 00:22:46,886 INFO org.apache.hadoop.yarn.server.resourcemanager.RMAuditLogger: USER=ubuntu	IP=192.168.100.5	OPERATION=Submit Application Request	TARGET=ClientRMService	RESULT=SUCCESS	APPID=application_1377907764744_0005
2013-08-31 00:22:46,887 INFO org.apache.hadoop.yarn.server.resourcemanager.rmapp.RMAppImpl: application_1377907764744_0005 State change from NEW to SUBMITTED
2013-08-31 00:22:46,887 INFO org.apache.hadoop.yarn.server.resourcemanager.ApplicationMasterService: Registering appattempt_1377907764744_0005_000001
2013-08-31 00:22:46,888 INFO org.apache.hadoop.yarn.server.resourcemanager.rmapp.attempt.RMAppAttemptImpl: appattempt_1377907764744_0005_000001 State change from NEW to SUBMITTED
2013-08-31 00:22:46,888 INFO org.apache.hadoop.yarn.server.resourcemanager.scheduler.capacity.LeafQueue: Application application_1377907764744_0005 from user: ubuntu activated in queue: default
2013-08-31 00:22:46,888 INFO org.apache.hadoop.yarn.server.resourcemanager.scheduler.capacity.LeafQueue: Application added - appId: application_1377907764744_0005 user: org.apache.hadoop.yarn.server.resourcemanager.scheduler.capacity.LeafQueue$User@3b37d2b6, leaf-queue: default #user-pending-applications: 0 #user-active-applications: 1 #queue-pending-applications: 0 #queue-active-applications: 1
2013-08-31 00:22:46,888 INFO org.apache.hadoop.yarn.server.resourcemanager.scheduler.capacity.ParentQueue: Application added - appId: application_1377907764744_0005 user: ubuntu leaf-queue of parent: root #applications: 1
2013-08-31 00:22:46,889 INFO org.apache.hadoop.yarn.server.resourcemanager.scheduler.capacity.CapacityScheduler: Application Submission: appattempt_1377907764744_0005_000001, user: ubuntu queue: default: capacity=1.0, absoluteCapacity=1.0, usedResources=<memory:0, vCores:0>usedCapacity=0.0, absoluteUsedCapacity=0.0, numApps=1, numContainers=0, currently active: 1
2013-08-31 00:22:46,889 INFO org.apache.hadoop.yarn.server.resourcemanager.rmapp.attempt.RMAppAttemptImpl: appattempt_1377907764744_0005_000001 State change from SUBMITTED to SCHEDULED
2013-08-31 00:22:46,889 INFO org.apache.hadoop.yarn.server.resourcemanager.rmapp.RMAppImpl: application_1377907764744_0005 State change from SUBMITTED to ACCEPTED
2013-08-31 00:22:47,210 INFO org.apache.hadoop.yarn.server.resourcemanager.rmcontainer.RMContainerImpl: container_1377907764744_0005_01_000001 Container Transitioned from NEW to ALLOCATED
2013-08-31 00:22:47,210 INFO org.apache.hadoop.yarn.server.resourcemanager.RMAuditLogger: USER=ubuntu	OPERATION=AM Allocated Container	TARGET=SchedulerApp	RESULT=SUCCESS	APPID=application_1377907764744_0005	CONTAINERID=container_1377907764744_0005_01_000001
2013-08-31 00:22:47,211 INFO org.apache.hadoop.yarn.server.resourcemanager.scheduler.common.fica.FiCaSchedulerNode: Assigned container container_1377907764744_0005_01_000001 of capacity <memory:2048, vCores:1> on host hadoop-32-7:54070, which currently has 1 containers, <memory:2048, vCores:1> used and <memory:6144, vCores:15> available
2013-08-31 00:22:47,212 INFO org.apache.hadoop.yarn.server.resourcemanager.scheduler.capacity.LeafQueue: assignedContainer application=application_1377907764744_0005 container=Container: [ContainerId: container_1377907764744_0005_01_000001, NodeId: hadoop-32-7:54070, NodeHttpAddress: hadoop-32-7:8042, Resource: <memory:2048, vCores:1>, Priority: 0, State: NEW, Token: null, Status: container_id {, app_attempt_id {, application_id {, id: 5, cluster_timestamp: 1377907764744, }, attemptId: 1, }, id: 1, }, state: C_NEW, ] containerId=container_1377907764744_0005_01_000001 queue=default: capacity=1.0, absoluteCapacity=1.0, usedResources=<memory:0, vCores:0>usedCapacity=0.0, absoluteUsedCapacity=0.0, numApps=1, numContainers=0 usedCapacity=0.0 absoluteUsedCapacity=0.0 used=<memory:0, vCores:0> cluster=<memory:49152, vCores:96>
2013-08-31 00:22:47,212 INFO org.apache.hadoop.yarn.server.resourcemanager.scheduler.capacity.ParentQueue: Re-sorting queues since queue: root.default stats: default: capacity=1.0, absoluteCapacity=1.0, usedResources=<memory:2048, vCores:1>usedCapacity=0.041666668, absoluteUsedCapacity=0.041666668, numApps=1, numContainers=1
2013-08-31 00:22:47,212 INFO org.apache.hadoop.yarn.server.resourcemanager.scheduler.capacity.ParentQueue: assignedContainer queue=root usedCapacity=0.041666668 absoluteUsedCapacity=0.041666668 used=<memory:2048, vCores:1> cluster=<memory:49152, vCores:96>
2013-08-31 00:22:47,214 INFO org.apache.hadoop.yarn.server.resourcemanager.rmcontainer.RMContainerImpl: container_1377907764744_0005_01_000001 Container Transitioned from ALLOCATED to ACQUIRED
2013-08-31 00:22:47,216 INFO org.apache.hadoop.yarn.server.resourcemanager.rmapp.attempt.RMAppAttemptImpl: Storing attempt: AppId: application_1377907764744_0005 AttemptId: appattempt_1377907764744_0005_000001 MasterContainer: Container: [ContainerId: container_1377907764744_0005_01_000001, NodeId: hadoop-32-7:54070, NodeHttpAddress: hadoop-32-7:8042, Resource: <memory:2048, vCores:1>, Priority: 0, State: NEW, Token: null, Status: container_id {, app_attempt_id {, application_id {, id: 5, cluster_timestamp: 1377907764744, }, attemptId: 1, }, id: 1, }, state: C_NEW, ]
2013-08-31 00:22:47,216 INFO org.apache.hadoop.yarn.server.resourcemanager.rmapp.attempt.RMAppAttemptImpl: appattempt_1377907764744_0005_000001 State change from SCHEDULED to ALLOCATED_SAVING
2013-08-31 00:22:47,217 INFO org.apache.hadoop.yarn.server.resourcemanager.recovery.RMStateStore: Storing info for attempt: appattempt_1377907764744_0005_000001
2013-08-31 00:22:47,217 INFO org.apache.hadoop.yarn.server.resourcemanager.rmapp.attempt.RMAppAttemptImpl: appattempt_1377907764744_0005_000001 State change from ALLOCATED_SAVING to ALLOCATED
2013-08-31 00:22:47,219 INFO org.apache.hadoop.yarn.server.resourcemanager.amlauncher.AMLauncher: Launching masterappattempt_1377907764744_0005_000001
2013-08-31 00:22:47,222 INFO org.apache.hadoop.yarn.server.resourcemanager.amlauncher.AMLauncher: Setting up container Container: [ContainerId: container_1377907764744_0005_01_000001, NodeId: hadoop-32-7:54070, NodeHttpAddress: hadoop-32-7:8042, Resource: <memory:2048, vCores:1>, Priority: 0, State: NEW, Token: null, Status: container_id {, app_attempt_id {, application_id {, id: 5, cluster_timestamp: 1377907764744, }, attemptId: 1, }, id: 1, }, state: C_NEW, ] for AM appattempt_1377907764744_0005_000001
2013-08-31 00:22:47,222 INFO org.apache.hadoop.yarn.server.resourcemanager.amlauncher.AMLauncher: Command to launch container container_1377907764744_0005_01_000001 : $JAVA_HOME/bin/java -Dlog4j.configuration=container-log4j.properties -Dyarn.app.mapreduce.container.log.dir=<LOG_DIR> -Dyarn.app.mapreduce.container.log.filesize=0 -Dhadoop.root.logger=INFO,CLA  -Xmx1024m org.apache.hadoop.mapreduce.v2.app.MRAppMaster 1><LOG_DIR>/stdout 2><LOG_DIR>/stderr 
2013-08-31 00:22:47,239 INFO org.apache.hadoop.yarn.server.resourcemanager.amlauncher.AMLauncher: Done launching container Container: [ContainerId: container_1377907764744_0005_01_000001, NodeId: hadoop-32-7:54070, NodeHttpAddress: hadoop-32-7:8042, Resource: <memory:2048, vCores:1>, Priority: 0, State: NEW, Token: null, Status: container_id {, app_attempt_id {, application_id {, id: 5, cluster_timestamp: 1377907764744, }, attemptId: 1, }, id: 1, }, state: C_NEW, ] for AM appattempt_1377907764744_0005_000001
2013-08-31 00:22:47,239 INFO org.apache.hadoop.yarn.server.resourcemanager.rmapp.attempt.RMAppAttemptImpl: appattempt_1377907764744_0005_000001 State change from ALLOCATED to LAUNCHED
2013-08-31 00:22:48,216 INFO org.apache.hadoop.yarn.server.resourcemanager.rmcontainer.RMContainerImpl: container_1377907764744_0005_01_000001 Container Transitioned from ACQUIRED to RUNNING
2013-08-31 00:22:53,900 INFO org.apache.hadoop.yarn.server.resourcemanager.ApplicationMasterService: AM registration appattempt_1377907764744_0005_000001
2013-08-31 00:22:53,901 INFO org.apache.hadoop.yarn.server.resourcemanager.RMAuditLogger: USER=ubuntu	IP=192.168.100.38	OPERATION=Register App Master	TARGET=ApplicationMasterService	RESULT=SUCCESS	APPID=application_1377907764744_0005	APPATTEMPTID=appattempt_1377907764744_0005_000001
2013-08-31 00:22:53,901 INFO org.apache.hadoop.yarn.server.resourcemanager.rmapp.attempt.RMAppAttemptImpl: appattempt_1377907764744_0005_000001 State change from LAUNCHED to RUNNING
2013-08-31 00:22:53,902 INFO org.apache.hadoop.yarn.server.resourcemanager.rmapp.RMAppImpl: application_1377907764744_0005 State change from ACCEPTED to RUNNING
2013-08-31 00:22:55,258 INFO org.apache.hadoop.yarn.server.resourcemanager.rmcontainer.RMContainerImpl: container_1377907764744_0005_01_000002 Container Transitioned from NEW to ALLOCATED
2013-08-31 00:22:55,258 INFO org.apache.hadoop.yarn.server.resourcemanager.RMAuditLogger: USER=ubuntu	OPERATION=AM Allocated Container	TARGET=SchedulerApp	RESULT=SUCCESS	APPID=application_1377907764744_0005	CONTAINERID=container_1377907764744_0005_01_000002
2013-08-31 00:22:55,259 INFO org.apache.hadoop.yarn.server.resourcemanager.scheduler.common.fica.FiCaSchedulerNode: Assigned container container_1377907764744_0005_01_000002 of capacity <memory:1024, vCores:1> on host hadoop-32-7:54070, which currently has 2 containers, <memory:3072, vCores:2> used and <memory:5120, vCores:14> available
2013-08-31 00:22:55,261 INFO org.apache.hadoop.yarn.server.resourcemanager.scheduler.capacity.LeafQueue: assignedContainer application=application_1377907764744_0005 container=Container: [ContainerId: container_1377907764744_0005_01_000002, NodeId: hadoop-32-7:54070, NodeHttpAddress: hadoop-32-7:8042, Resource: <memory:1024, vCores:1>, Priority: 20, State: NEW, Token: null, Status: container_id {, app_attempt_id {, application_id {, id: 5, cluster_timestamp: 1377907764744, }, attemptId: 1, }, id: 2, }, state: C_NEW, ] containerId=container_1377907764744_0005_01_000002 queue=default: capacity=1.0, absoluteCapacity=1.0, usedResources=<memory:2048, vCores:1>usedCapacity=0.041666668, absoluteUsedCapacity=0.041666668, numApps=1, numContainers=1 usedCapacity=0.041666668 absoluteUsedCapacity=0.041666668 used=<memory:2048, vCores:1> cluster=<memory:49152, vCores:96>
2013-08-31 00:22:55,261 INFO org.apache.hadoop.yarn.server.resourcemanager.scheduler.capacity.ParentQueue: Re-sorting queues since queue: root.default stats: default: capacity=1.0, absoluteCapacity=1.0, usedResources=<memory:3072, vCores:2>usedCapacity=0.0625, absoluteUsedCapacity=0.0625, numApps=1, numContainers=2
2013-08-31 00:22:55,261 INFO org.apache.hadoop.yarn.server.resourcemanager.scheduler.capacity.ParentQueue: assignedContainer queue=root usedCapacity=0.0625 absoluteUsedCapacity=0.0625 used=<memory:3072, vCores:2> cluster=<memory:49152, vCores:96>
2013-08-31 00:22:55,644 INFO org.apache.hadoop.yarn.server.resourcemanager.rmcontainer.RMContainerImpl: container_1377907764744_0005_01_000003 Container Transitioned from NEW to ALLOCATED
2013-08-31 00:22:55,645 INFO org.apache.hadoop.yarn.server.resourcemanager.RMAuditLogger: USER=ubuntu	OPERATION=AM Allocated Container	TARGET=SchedulerApp	RESULT=SUCCESS	APPID=application_1377907764744_0005	CONTAINERID=container_1377907764744_0005_01_000003
2013-08-31 00:22:55,645 INFO org.apache.hadoop.yarn.server.resourcemanager.scheduler.common.fica.FiCaSchedulerNode: Assigned container container_1377907764744_0005_01_000003 of capacity <memory:1024, vCores:1> on host hadoop-32-6:48039, which currently has 1 containers, <memory:1024, vCores:1> used and <memory:7168, vCores:15> available
2013-08-31 00:22:55,646 INFO org.apache.hadoop.yarn.server.resourcemanager.scheduler.capacity.LeafQueue: assignedContainer application=application_1377907764744_0005 container=Container: [ContainerId: container_1377907764744_0005_01_000003, NodeId: hadoop-32-6:48039, NodeHttpAddress: hadoop-32-6:8042, Resource: <memory:1024, vCores:1>, Priority: 20, State: NEW, Token: null, Status: container_id {, app_attempt_id {, application_id {, id: 5, cluster_timestamp: 1377907764744, }, attemptId: 1, }, id: 3, }, state: C_NEW, ] containerId=container_1377907764744_0005_01_000003 queue=default: capacity=1.0, absoluteCapacity=1.0, usedResources=<memory:3072, vCores:2>usedCapacity=0.0625, absoluteUsedCapacity=0.0625, numApps=1, numContainers=2 usedCapacity=0.0625 absoluteUsedCapacity=0.0625 used=<memory:3072, vCores:2> cluster=<memory:49152, vCores:96>
2013-08-31 00:22:55,646 INFO org.apache.hadoop.yarn.server.resourcemanager.scheduler.capacity.ParentQueue: Re-sorting queues since queue: root.default stats: default: capacity=1.0, absoluteCapacity=1.0, usedResources=<memory:4096, vCores:3>usedCapacity=0.083333336, absoluteUsedCapacity=0.083333336, numApps=1, numContainers=3
2013-08-31 00:22:55,646 INFO org.apache.hadoop.yarn.server.resourcemanager.scheduler.capacity.ParentQueue: assignedContainer queue=root usedCapacity=0.083333336 absoluteUsedCapacity=0.083333336 used=<memory:4096, vCores:3> cluster=<memory:49152, vCores:96>
2013-08-31 00:22:55,956 INFO org.apache.hadoop.yarn.server.resourcemanager.rmcontainer.RMContainerImpl: container_1377907764744_0005_01_000002 Container Transitioned from ALLOCATED to ACQUIRED
2013-08-31 00:22:55,959 INFO org.apache.hadoop.yarn.server.resourcemanager.rmcontainer.RMContainerImpl: container_1377907764744_0005_01_000003 Container Transitioned from ALLOCATED to ACQUIRED
2013-08-31 00:22:56,267 INFO org.apache.hadoop.yarn.server.resourcemanager.rmcontainer.RMContainerImpl: container_1377907764744_0005_01_000002 Container Transitioned from ACQUIRED to RUNNING
2013-08-31 00:22:56,993 INFO org.apache.hadoop.yarn.server.resourcemanager.scheduler.AppSchedulingInfo: checking for deactivate... 
2013-08-31 00:22:57,754 INFO org.apache.hadoop.yarn.server.resourcemanager.rmcontainer.RMContainerImpl: container_1377907764744_0005_01_000003 Container Transitioned from ACQUIRED to RUNNING
2013-08-31 00:25:47,226 INFO org.apache.hadoop.yarn.server.resourcemanager.rmcontainer.RMContainerImpl: container_1377907764744_0005_01_000003 Container Transitioned from RUNNING to COMPLETED
2013-08-31 00:25:47,226 INFO org.apache.hadoop.yarn.server.resourcemanager.scheduler.common.fica.FiCaSchedulerApp: Completed container: container_1377907764744_0005_01_000003 in state: COMPLETED event:FINISHED
2013-08-31 00:25:47,226 INFO org.apache.hadoop.yarn.server.resourcemanager.RMAuditLogger: USER=ubuntu	OPERATION=AM Released Container	TARGET=SchedulerApp	RESULT=SUCCESS	APPID=application_1377907764744_0005	CONTAINERID=container_1377907764744_0005_01_000003
2013-08-31 00:25:47,227 INFO org.apache.hadoop.yarn.server.resourcemanager.scheduler.common.fica.FiCaSchedulerNode: Released container container_1377907764744_0005_01_000003 of capacity <memory:1024, vCores:1> on host hadoop-32-6:48039, which currently has 0 containers, <memory:0, vCores:0> used and <memory:8192, vCores:16> available, release resources=true
2013-08-31 00:25:47,227 INFO org.apache.hadoop.yarn.server.resourcemanager.scheduler.capacity.LeafQueue: default used=<memory:3072, vCores:2> numContainers=2 user=ubuntu user-resources=<memory:3072, vCores:2>
2013-08-31 00:25:47,228 INFO org.apache.hadoop.yarn.server.resourcemanager.scheduler.capacity.LeafQueue: completedContainer container=Container: [ContainerId: container_1377907764744_0005_01_000003, NodeId: hadoop-32-6:48039, NodeHttpAddress: hadoop-32-6:8042, Resource: <memory:1024, vCores:1>, Priority: 20, State: NEW, Token: null, Status: container_id {, app_attempt_id {, application_id {, id: 5, cluster_timestamp: 1377907764744, }, attemptId: 1, }, id: 3, }, state: C_COMPLETE, diagnostics: "Container killed by the ApplicationMaster.\n\n", exit_status: 143, ] resource=<memory:1024, vCores:1> queue=default: capacity=1.0, absoluteCapacity=1.0, usedResources=<memory:3072, vCores:2>usedCapacity=0.0625, absoluteUsedCapacity=0.0625, numApps=1, numContainers=2 usedCapacity=0.0625 absoluteUsedCapacity=0.0625 used=<memory:3072, vCores:2> cluster=<memory:49152, vCores:96>
2013-08-31 00:25:47,229 INFO org.apache.hadoop.yarn.server.resourcemanager.scheduler.capacity.ParentQueue: completedContainer queue=root usedCapacity=0.0625 absoluteUsedCapacity=0.0625 used=<memory:3072, vCores:2> cluster=<memory:49152, vCores:96>
2013-08-31 00:25:47,229 INFO org.apache.hadoop.yarn.server.resourcemanager.scheduler.capacity.CapacityScheduler: Application appattempt_1377907764744_0005_000001 released container container_1377907764744_0005_01_000003 on node: host: hadoop-32-6:48039 #containers=0 available=8192 used=0 with event: FINISHED
2013-08-31 00:25:48,171 INFO org.apache.hadoop.yarn.server.resourcemanager.rmcontainer.RMContainerImpl: container_1377907764744_0005_01_000002 Container Transitioned from RUNNING to COMPLETED
2013-08-31 00:25:48,171 INFO org.apache.hadoop.yarn.server.resourcemanager.scheduler.common.fica.FiCaSchedulerApp: Completed container: container_1377907764744_0005_01_000002 in state: COMPLETED event:FINISHED
2013-08-31 00:25:48,171 INFO org.apache.hadoop.yarn.server.resourcemanager.RMAuditLogger: USER=ubuntu	OPERATION=AM Released Container	TARGET=SchedulerApp	RESULT=SUCCESS	APPID=application_1377907764744_0005	CONTAINERID=container_1377907764744_0005_01_000002
2013-08-31 00:25:48,171 INFO org.apache.hadoop.yarn.server.resourcemanager.scheduler.common.fica.FiCaSchedulerNode: Released container container_1377907764744_0005_01_000002 of capacity <memory:1024, vCores:1> on host hadoop-32-7:54070, which currently has 1 containers, <memory:2048, vCores:1> used and <memory:6144, vCores:15> available, release resources=true
2013-08-31 00:25:48,172 INFO org.apache.hadoop.yarn.server.resourcemanager.scheduler.capacity.LeafQueue: default used=<memory:2048, vCores:1> numContainers=1 user=ubuntu user-resources=<memory:2048, vCores:1>
2013-08-31 00:25:48,173 INFO org.apache.hadoop.yarn.server.resourcemanager.scheduler.capacity.LeafQueue: completedContainer container=Container: [ContainerId: container_1377907764744_0005_01_000002, NodeId: hadoop-32-7:54070, NodeHttpAddress: hadoop-32-7:8042, Resource: <memory:1024, vCores:1>, Priority: 20, State: NEW, Token: null, Status: container_id {, app_attempt_id {, application_id {, id: 5, cluster_timestamp: 1377907764744, }, attemptId: 1, }, id: 2, }, state: C_COMPLETE, diagnostics: "Container killed by the ApplicationMaster.\n\n", exit_status: 143, ] resource=<memory:1024, vCores:1> queue=default: capacity=1.0, absoluteCapacity=1.0, usedResources=<memory:2048, vCores:1>usedCapacity=0.041666668, absoluteUsedCapacity=0.041666668, numApps=1, numContainers=1 usedCapacity=0.041666668 absoluteUsedCapacity=0.041666668 used=<memory:2048, vCores:1> cluster=<memory:49152, vCores:96>
2013-08-31 00:25:48,173 INFO org.apache.hadoop.yarn.server.resourcemanager.scheduler.capacity.ParentQueue: completedContainer queue=root usedCapacity=0.041666668 absoluteUsedCapacity=0.041666668 used=<memory:2048, vCores:1> cluster=<memory:49152, vCores:96>
2013-08-31 00:25:48,174 INFO org.apache.hadoop.yarn.server.resourcemanager.scheduler.capacity.CapacityScheduler: Application appattempt_1377907764744_0005_000001 released container container_1377907764744_0005_01_000002 on node: host: hadoop-32-7:54070 #containers=1 available=6144 used=2048 with event: FINISHED
2013-08-31 00:25:52,526 INFO org.apache.hadoop.yarn.server.resourcemanager.rmapp.attempt.RMAppAttemptImpl: appattempt_1377907764744_0005_000001 State change from RUNNING to FINISHING
2013-08-31 00:25:52,527 INFO org.apache.hadoop.yarn.server.resourcemanager.rmapp.RMAppImpl: application_1377907764744_0005 State change from RUNNING to FINISHING
2013-08-31 00:25:53,189 INFO org.apache.hadoop.yarn.server.resourcemanager.rmcontainer.RMContainerImpl: container_1377907764744_0005_01_000001 Container Transitioned from RUNNING to COMPLETED
2013-08-31 00:25:53,189 INFO org.apache.hadoop.yarn.server.resourcemanager.scheduler.common.fica.FiCaSchedulerApp: Completed container: container_1377907764744_0005_01_000001 in state: COMPLETED event:FINISHED
2013-08-31 00:25:53,190 INFO org.apache.hadoop.yarn.server.resourcemanager.rmapp.attempt.RMAppAttemptImpl: appattempt_1377907764744_0005_000001 State change from FINISHING to FINISHED
2013-08-31 00:25:53,190 INFO org.apache.hadoop.yarn.server.resourcemanager.RMAuditLogger: USER=ubuntu	OPERATION=AM Released Container	TARGET=SchedulerApp	RESULT=SUCCESS	APPID=application_1377907764744_0005	CONTAINERID=container_1377907764744_0005_01_000001
2013-08-31 00:25:53,190 INFO org.apache.hadoop.yarn.server.resourcemanager.rmapp.RMAppImpl: application_1377907764744_0005 State change from FINISHING to FINISHED
2013-08-31 00:25:53,190 INFO org.apache.hadoop.yarn.server.resourcemanager.scheduler.common.fica.FiCaSchedulerNode: Released container container_1377907764744_0005_01_000001 of capacity <memory:2048, vCores:1> on host hadoop-32-7:54070, which currently has 0 containers, <memory:0, vCores:0> used and <memory:8192, vCores:16> available, release resources=true
2013-08-31 00:25:53,190 INFO org.apache.hadoop.yarn.server.resourcemanager.scheduler.capacity.LeafQueue: default used=<memory:0, vCores:0> numContainers=0 user=ubuntu user-resources=<memory:0, vCores:0>
2013-08-31 00:25:53,190 INFO org.apache.hadoop.yarn.server.resourcemanager.RMAuditLogger: USER=ubuntu	OPERATION=Application Finished - Succeeded	TARGET=RMAppManager	RESULT=SUCCESS	APPID=application_1377907764744_0005
2013-08-31 00:25:53,191 INFO org.apache.hadoop.yarn.server.resourcemanager.recovery.RMStateStore: Removing info for app: application_1377907764744_0005
2013-08-31 00:25:53,191 INFO org.apache.hadoop.yarn.server.resourcemanager.RMAppManager$ApplicationSummary: appId=application_1377907764744_0005,name=TeraGen,user=ubuntu,queue=default,state=FINISHED,trackingUrl=hadoop-32-1.novalocal:8088/proxy/application_1377907764744_0005/jobhistory/job/job_1377907764744_0005,appMasterHost=hadoop-32-7,startTime=1377908566885,finishTime=1377908752527
2013-08-31 00:25:53,192 INFO org.apache.hadoop.yarn.server.resourcemanager.amlauncher.AMLauncher: Cleaning master appattempt_1377907764744_0005_000001
2013-08-31 00:25:53,192 INFO org.apache.hadoop.yarn.server.resourcemanager.scheduler.capacity.LeafQueue: completedContainer container=Container: [ContainerId: container_1377907764744_0005_01_000001, NodeId: hadoop-32-7:54070, NodeHttpAddress: hadoop-32-7:8042, Resource: <memory:2048, vCores:1>, Priority: 0, State: NEW, Token: null, Status: container_id {, app_attempt_id {, application_id {, id: 5, cluster_timestamp: 1377907764744, }, attemptId: 1, }, id: 1, }, state: C_COMPLETE, diagnostics: "", exit_status: 0, ] resource=<memory:2048, vCores:1> queue=default: capacity=1.0, absoluteCapacity=1.0, usedResources=<memory:0, vCores:0>usedCapacity=0.0, absoluteUsedCapacity=0.0, numApps=1, numContainers=0 usedCapacity=0.0 absoluteUsedCapacity=0.0 used=<memory:0, vCores:0> cluster=<memory:49152, vCores:96>
2013-08-31 00:25:53,192 INFO org.apache.hadoop.yarn.server.resourcemanager.scheduler.capacity.ParentQueue: completedContainer queue=root usedCapacity=0.0 absoluteUsedCapacity=0.0 used=<memory:0, vCores:0> cluster=<memory:49152, vCores:96>
2013-08-31 00:25:53,193 INFO org.apache.hadoop.yarn.server.resourcemanager.scheduler.capacity.CapacityScheduler: Application appattempt_1377907764744_0005_000001 released container container_1377907764744_0005_01_000001 on node: host: hadoop-32-7:54070 #containers=0 available=8192 used=0 with event: FINISHED
2013-08-31 00:25:53,193 INFO org.apache.hadoop.yarn.server.resourcemanager.scheduler.capacity.CapacityScheduler: Application appattempt_1377907764744_0005_000001 is done. finalState=FINISHED
2013-08-31 00:25:53,193 INFO org.apache.hadoop.yarn.server.resourcemanager.scheduler.AppSchedulingInfo: Application application_1377907764744_0005 requests cleared
2013-08-31 00:25:53,193 INFO org.apache.hadoop.yarn.server.resourcemanager.scheduler.capacity.LeafQueue: Application removed - appId: application_1377907764744_0005 user: ubuntu queue: default #user-pending-applications: 0 #user-active-applications: 0 #queue-pending-applications: 0 #queue-active-applications: 0
2013-08-31 00:25:53,193 INFO org.apache.hadoop.yarn.server.resourcemanager.scheduler.capacity.ParentQueue: Application removed - appId: application_1377907764744_0005 user: ubuntu leaf-queue of parent: root #applications: 0
2013-08-31 00:26:07,756 INFO org.apache.hadoop.yarn.server.resourcemanager.ClientRMService: Allocated new applicationId: 6
2013-08-31 00:26:08,167 INFO org.apache.hadoop.yarn.server.resourcemanager.ClientRMService: Allocated new applicationId: 7
2013-08-31 00:26:08,215 INFO org.apache.hadoop.yarn.server.resourcemanager.ClientRMService: Allocated new applicationId: 8
2013-08-31 00:26:09,017 INFO org.apache.hadoop.yarn.server.resourcemanager.ClientRMService: Storing Application with id application_1377907764744_0006
2013-08-31 00:26:09,017 INFO org.apache.hadoop.yarn.server.resourcemanager.recovery.RMStateStore: Storing info for app: application_1377907764744_0006
2013-08-31 00:26:09,018 INFO org.apache.hadoop.yarn.server.resourcemanager.ClientRMService: Application with id 6 submitted by user ubuntu
2013-08-31 00:26:09,018 INFO org.apache.hadoop.yarn.server.resourcemanager.RMAuditLogger: USER=ubuntu	IP=192.168.100.5	OPERATION=Submit Application Request	TARGET=ClientRMService	RESULT=SUCCESS	APPID=application_1377907764744_0006
2013-08-31 00:26:09,024 INFO org.apache.hadoop.yarn.server.resourcemanager.rmapp.RMAppImpl: application_1377907764744_0006 State change from NEW to SUBMITTED
2013-08-31 00:26:09,025 INFO org.apache.hadoop.yarn.server.resourcemanager.ApplicationMasterService: Registering appattempt_1377907764744_0006_000001
2013-08-31 00:26:09,025 INFO org.apache.hadoop.yarn.server.resourcemanager.rmapp.attempt.RMAppAttemptImpl: appattempt_1377907764744_0006_000001 State change from NEW to SUBMITTED
2013-08-31 00:26:09,025 INFO org.apache.hadoop.yarn.server.resourcemanager.scheduler.capacity.LeafQueue: Application application_1377907764744_0006 from user: ubuntu activated in queue: default
2013-08-31 00:26:09,025 INFO org.apache.hadoop.yarn.server.resourcemanager.scheduler.capacity.LeafQueue: Application added - appId: application_1377907764744_0006 user: org.apache.hadoop.yarn.server.resourcemanager.scheduler.capacity.LeafQueue$User@277b3c9b, leaf-queue: default #user-pending-applications: 0 #user-active-applications: 1 #queue-pending-applications: 0 #queue-active-applications: 1
2013-08-31 00:26:09,025 INFO org.apache.hadoop.yarn.server.resourcemanager.scheduler.capacity.ParentQueue: Application added - appId: application_1377907764744_0006 user: ubuntu leaf-queue of parent: root #applications: 1
2013-08-31 00:26:09,025 INFO org.apache.hadoop.yarn.server.resourcemanager.scheduler.capacity.CapacityScheduler: Application Submission: appattempt_1377907764744_0006_000001, user: ubuntu queue: default: capacity=1.0, absoluteCapacity=1.0, usedResources=<memory:0, vCores:0>usedCapacity=0.0, absoluteUsedCapacity=0.0, numApps=1, numContainers=0, currently active: 1
2013-08-31 00:26:09,026 INFO org.apache.hadoop.yarn.server.resourcemanager.rmapp.attempt.RMAppAttemptImpl: appattempt_1377907764744_0006_000001 State change from SUBMITTED to SCHEDULED
2013-08-31 00:26:09,026 INFO org.apache.hadoop.yarn.server.resourcemanager.rmapp.RMAppImpl: application_1377907764744_0006 State change from SUBMITTED to ACCEPTED
2013-08-31 00:26:09,241 INFO org.apache.hadoop.yarn.server.resourcemanager.rmcontainer.RMContainerImpl: container_1377907764744_0006_01_000001 Container Transitioned from NEW to ALLOCATED
2013-08-31 00:26:09,242 INFO org.apache.hadoop.yarn.server.resourcemanager.RMAuditLogger: USER=ubuntu	OPERATION=AM Allocated Container	TARGET=SchedulerApp	RESULT=SUCCESS	APPID=application_1377907764744_0006	CONTAINERID=container_1377907764744_0006_01_000001
2013-08-31 00:26:09,242 INFO org.apache.hadoop.yarn.server.resourcemanager.scheduler.common.fica.FiCaSchedulerNode: Assigned container container_1377907764744_0006_01_000001 of capacity <memory:2048, vCores:1> on host hadoop-32-7:54070, which currently has 1 containers, <memory:2048, vCores:1> used and <memory:6144, vCores:15> available
2013-08-31 00:26:09,242 INFO org.apache.hadoop.yarn.server.resourcemanager.scheduler.capacity.LeafQueue: assignedContainer application=application_1377907764744_0006 container=Container: [ContainerId: container_1377907764744_0006_01_000001, NodeId: hadoop-32-7:54070, NodeHttpAddress: hadoop-32-7:8042, Resource: <memory:2048, vCores:1>, Priority: 0, State: NEW, Token: null, Status: container_id {, app_attempt_id {, application_id {, id: 6, cluster_timestamp: 1377907764744, }, attemptId: 1, }, id: 1, }, state: C_NEW, ] containerId=container_1377907764744_0006_01_000001 queue=default: capacity=1.0, absoluteCapacity=1.0, usedResources=<memory:0, vCores:0>usedCapacity=0.0, absoluteUsedCapacity=0.0, numApps=1, numContainers=0 usedCapacity=0.0 absoluteUsedCapacity=0.0 used=<memory:0, vCores:0> cluster=<memory:49152, vCores:96>
2013-08-31 00:26:09,243 INFO org.apache.hadoop.yarn.server.resourcemanager.scheduler.capacity.ParentQueue: Re-sorting queues since queue: root.default stats: default: capacity=1.0, absoluteCapacity=1.0, usedResources=<memory:2048, vCores:1>usedCapacity=0.041666668, absoluteUsedCapacity=0.041666668, numApps=1, numContainers=1
2013-08-31 00:26:09,244 INFO org.apache.hadoop.yarn.server.resourcemanager.scheduler.capacity.ParentQueue: assignedContainer queue=root usedCapacity=0.041666668 absoluteUsedCapacity=0.041666668 used=<memory:2048, vCores:1> cluster=<memory:49152, vCores:96>
2013-08-31 00:26:09,243 INFO org.apache.hadoop.yarn.server.resourcemanager.rmcontainer.RMContainerImpl: container_1377907764744_0006_01_000001 Container Transitioned from ALLOCATED to ACQUIRED
2013-08-31 00:26:09,245 INFO org.apache.hadoop.yarn.server.resourcemanager.rmapp.attempt.RMAppAttemptImpl: Storing attempt: AppId: application_1377907764744_0006 AttemptId: appattempt_1377907764744_0006_000001 MasterContainer: Container: [ContainerId: container_1377907764744_0006_01_000001, NodeId: hadoop-32-7:54070, NodeHttpAddress: hadoop-32-7:8042, Resource: <memory:2048, vCores:1>, Priority: 0, State: NEW, Token: null, Status: container_id {, app_attempt_id {, application_id {, id: 6, cluster_timestamp: 1377907764744, }, attemptId: 1, }, id: 1, }, state: C_NEW, ]
2013-08-31 00:26:09,245 INFO org.apache.hadoop.yarn.server.resourcemanager.rmapp.attempt.RMAppAttemptImpl: appattempt_1377907764744_0006_000001 State change from SCHEDULED to ALLOCATED_SAVING
2013-08-31 00:26:09,245 INFO org.apache.hadoop.yarn.server.resourcemanager.recovery.RMStateStore: Storing info for attempt: appattempt_1377907764744_0006_000001
2013-08-31 00:26:09,249 INFO org.apache.hadoop.yarn.server.resourcemanager.rmapp.attempt.RMAppAttemptImpl: appattempt_1377907764744_0006_000001 State change from ALLOCATED_SAVING to ALLOCATED
2013-08-31 00:26:09,249 INFO org.apache.hadoop.yarn.server.resourcemanager.amlauncher.AMLauncher: Launching masterappattempt_1377907764744_0006_000001
2013-08-31 00:26:09,250 INFO org.apache.hadoop.yarn.server.resourcemanager.amlauncher.AMLauncher: Setting up container Container: [ContainerId: container_1377907764744_0006_01_000001, NodeId: hadoop-32-7:54070, NodeHttpAddress: hadoop-32-7:8042, Resource: <memory:2048, vCores:1>, Priority: 0, State: NEW, Token: null, Status: container_id {, app_attempt_id {, application_id {, id: 6, cluster_timestamp: 1377907764744, }, attemptId: 1, }, id: 1, }, state: C_NEW, ] for AM appattempt_1377907764744_0006_000001
2013-08-31 00:26:09,250 INFO org.apache.hadoop.yarn.server.resourcemanager.amlauncher.AMLauncher: Command to launch container container_1377907764744_0006_01_000001 : $JAVA_HOME/bin/java -Dlog4j.configuration=container-log4j.properties -Dyarn.app.mapreduce.container.log.dir=<LOG_DIR> -Dyarn.app.mapreduce.container.log.filesize=0 -Dhadoop.root.logger=INFO,CLA  -Xmx1024m org.apache.hadoop.mapreduce.v2.app.MRAppMaster 1><LOG_DIR>/stdout 2><LOG_DIR>/stderr 
2013-08-31 00:26:09,261 INFO org.apache.hadoop.yarn.server.resourcemanager.amlauncher.AMLauncher: Done launching container Container: [ContainerId: container_1377907764744_0006_01_000001, NodeId: hadoop-32-7:54070, NodeHttpAddress: hadoop-32-7:8042, Resource: <memory:2048, vCores:1>, Priority: 0, State: NEW, Token: null, Status: container_id {, app_attempt_id {, application_id {, id: 6, cluster_timestamp: 1377907764744, }, attemptId: 1, }, id: 1, }, state: C_NEW, ] for AM appattempt_1377907764744_0006_000001
2013-08-31 00:26:09,262 INFO org.apache.hadoop.yarn.server.resourcemanager.rmapp.attempt.RMAppAttemptImpl: appattempt_1377907764744_0006_000001 State change from ALLOCATED to LAUNCHED
2013-08-31 00:26:09,366 INFO org.apache.hadoop.yarn.server.resourcemanager.ClientRMService: Storing Application with id application_1377907764744_0007
2013-08-31 00:26:09,366 INFO org.apache.hadoop.yarn.server.resourcemanager.recovery.RMStateStore: Storing info for app: application_1377907764744_0007
2013-08-31 00:26:09,366 INFO org.apache.hadoop.yarn.server.resourcemanager.ClientRMService: Application with id 7 submitted by user ubuntu
2013-08-31 00:26:09,366 INFO org.apache.hadoop.yarn.server.resourcemanager.RMAuditLogger: USER=ubuntu	IP=192.168.100.5	OPERATION=Submit Application Request	TARGET=ClientRMService	RESULT=SUCCESS	APPID=application_1377907764744_0007
2013-08-31 00:26:09,367 INFO org.apache.hadoop.yarn.server.resourcemanager.rmapp.RMAppImpl: application_1377907764744_0007 State change from NEW to SUBMITTED
2013-08-31 00:26:09,367 INFO org.apache.hadoop.yarn.server.resourcemanager.ApplicationMasterService: Registering appattempt_1377907764744_0007_000001
2013-08-31 00:26:09,367 INFO org.apache.hadoop.yarn.server.resourcemanager.rmapp.attempt.RMAppAttemptImpl: appattempt_1377907764744_0007_000001 State change from NEW to SUBMITTED
2013-08-31 00:26:09,368 INFO org.apache.hadoop.yarn.server.resourcemanager.scheduler.capacity.LeafQueue: Application application_1377907764744_0007 from user: ubuntu activated in queue: default
2013-08-31 00:26:09,368 INFO org.apache.hadoop.yarn.server.resourcemanager.scheduler.capacity.LeafQueue: Application added - appId: application_1377907764744_0007 user: org.apache.hadoop.yarn.server.resourcemanager.scheduler.capacity.LeafQueue$User@277b3c9b, leaf-queue: default #user-pending-applications: 0 #user-active-applications: 2 #queue-pending-applications: 0 #queue-active-applications: 2
2013-08-31 00:26:09,368 INFO org.apache.hadoop.yarn.server.resourcemanager.scheduler.capacity.ParentQueue: Application added - appId: application_1377907764744_0007 user: ubuntu leaf-queue of parent: root #applications: 2
2013-08-31 00:26:09,368 INFO org.apache.hadoop.yarn.server.resourcemanager.scheduler.capacity.CapacityScheduler: Application Submission: appattempt_1377907764744_0007_000001, user: ubuntu queue: default: capacity=1.0, absoluteCapacity=1.0, usedResources=<memory:2048, vCores:1>usedCapacity=0.041666668, absoluteUsedCapacity=0.041666668, numApps=2, numContainers=1, currently active: 2
2013-08-31 00:26:09,368 INFO org.apache.hadoop.yarn.server.resourcemanager.rmapp.attempt.RMAppAttemptImpl: appattempt_1377907764744_0007_000001 State change from SUBMITTED to SCHEDULED
2013-08-31 00:26:09,369 INFO org.apache.hadoop.yarn.server.resourcemanager.rmapp.RMAppImpl: application_1377907764744_0007 State change from SUBMITTED to ACCEPTED
2013-08-31 00:26:09,385 INFO org.apache.hadoop.yarn.server.resourcemanager.ClientRMService: Storing Application with id application_1377907764744_0008
2013-08-31 00:26:09,385 INFO org.apache.hadoop.yarn.server.resourcemanager.recovery.RMStateStore: Storing info for app: application_1377907764744_0008
2013-08-31 00:26:09,385 INFO org.apache.hadoop.yarn.server.resourcemanager.ClientRMService: Application with id 8 submitted by user ubuntu
2013-08-31 00:26:09,385 INFO org.apache.hadoop.yarn.server.resourcemanager.RMAuditLogger: USER=ubuntu	IP=192.168.100.5	OPERATION=Submit Application Request	TARGET=ClientRMService	RESULT=SUCCESS	APPID=application_1377907764744_0008
2013-08-31 00:26:09,385 INFO org.apache.hadoop.yarn.server.resourcemanager.rmapp.RMAppImpl: application_1377907764744_0008 State change from NEW to SUBMITTED
2013-08-31 00:26:09,385 INFO org.apache.hadoop.yarn.server.resourcemanager.ApplicationMasterService: Registering appattempt_1377907764744_0008_000001
2013-08-31 00:26:09,386 INFO org.apache.hadoop.yarn.server.resourcemanager.rmapp.attempt.RMAppAttemptImpl: appattempt_1377907764744_0008_000001 State change from NEW to SUBMITTED
2013-08-31 00:26:09,386 INFO org.apache.hadoop.yarn.server.resourcemanager.scheduler.capacity.LeafQueue: Application application_1377907764744_0008 from user: ubuntu activated in queue: default
2013-08-31 00:26:09,386 INFO org.apache.hadoop.yarn.server.resourcemanager.scheduler.capacity.LeafQueue: Application added - appId: application_1377907764744_0008 user: org.apache.hadoop.yarn.server.resourcemanager.scheduler.capacity.LeafQueue$User@277b3c9b, leaf-queue: default #user-pending-applications: 0 #user-active-applications: 3 #queue-pending-applications: 0 #queue-active-applications: 3
2013-08-31 00:26:09,386 INFO org.apache.hadoop.yarn.server.resourcemanager.scheduler.capacity.ParentQueue: Application added - appId: application_1377907764744_0008 user: ubuntu leaf-queue of parent: root #applications: 3
2013-08-31 00:26:09,386 INFO org.apache.hadoop.yarn.server.resourcemanager.scheduler.capacity.CapacityScheduler: Application Submission: appattempt_1377907764744_0008_000001, user: ubuntu queue: default: capacity=1.0, absoluteCapacity=1.0, usedResources=<memory:2048, vCores:1>usedCapacity=0.041666668, absoluteUsedCapacity=0.041666668, numApps=3, numContainers=1, currently active: 3
2013-08-31 00:26:09,388 INFO org.apache.hadoop.yarn.server.resourcemanager.rmapp.attempt.RMAppAttemptImpl: appattempt_1377907764744_0008_000001 State change from SUBMITTED to SCHEDULED
2013-08-31 00:26:09,388 INFO org.apache.hadoop.yarn.server.resourcemanager.rmapp.RMAppImpl: application_1377907764744_0008 State change from SUBMITTED to ACCEPTED
2013-08-31 00:26:09,442 INFO org.apache.hadoop.yarn.server.resourcemanager.rmcontainer.RMContainerImpl: container_1377907764744_0007_01_000001 Container Transitioned from NEW to ALLOCATED
2013-08-31 00:26:09,442 INFO org.apache.hadoop.yarn.server.resourcemanager.RMAuditLogger: USER=ubuntu	OPERATION=AM Allocated Container	TARGET=SchedulerApp	RESULT=SUCCESS	APPID=application_1377907764744_0007	CONTAINERID=container_1377907764744_0007_01_000001
2013-08-31 00:26:09,442 INFO org.apache.hadoop.yarn.server.resourcemanager.scheduler.common.fica.FiCaSchedulerNode: Assigned container container_1377907764744_0007_01_000001 of capacity <memory:2048, vCores:1> on host hadoop-32-2:38703, which currently has 1 containers, <memory:2048, vCores:1> used and <memory:6144, vCores:15> available
2013-08-31 00:26:09,443 INFO org.apache.hadoop.yarn.server.resourcemanager.scheduler.capacity.LeafQueue: assignedContainer application=application_1377907764744_0007 container=Container: [ContainerId: container_1377907764744_0007_01_000001, NodeId: hadoop-32-2:38703, NodeHttpAddress: hadoop-32-2:8042, Resource: <memory:2048, vCores:1>, Priority: 0, State: NEW, Token: null, Status: container_id {, app_attempt_id {, application_id {, id: 7, cluster_timestamp: 1377907764744, }, attemptId: 1, }, id: 1, }, state: C_NEW, ] containerId=container_1377907764744_0007_01_000001 queue=default: capacity=1.0, absoluteCapacity=1.0, usedResources=<memory:2048, vCores:1>usedCapacity=0.041666668, absoluteUsedCapacity=0.041666668, numApps=3, numContainers=1 usedCapacity=0.041666668 absoluteUsedCapacity=0.041666668 used=<memory:2048, vCores:1> cluster=<memory:49152, vCores:96>
2013-08-31 00:26:09,443 INFO org.apache.hadoop.yarn.server.resourcemanager.scheduler.capacity.ParentQueue: Re-sorting queues since queue: root.default stats: default: capacity=1.0, absoluteCapacity=1.0, usedResources=<memory:4096, vCores:2>usedCapacity=0.083333336, absoluteUsedCapacity=0.083333336, numApps=3, numContainers=2
2013-08-31 00:26:09,444 INFO org.apache.hadoop.yarn.server.resourcemanager.scheduler.capacity.ParentQueue: assignedContainer queue=root usedCapacity=0.083333336 absoluteUsedCapacity=0.083333336 used=<memory:4096, vCores:2> cluster=<memory:49152, vCores:96>
2013-08-31 00:26:09,444 INFO org.apache.hadoop.yarn.server.resourcemanager.rmcontainer.RMContainerImpl: container_1377907764744_0007_01_000001 Container Transitioned from ALLOCATED to ACQUIRED
2013-08-31 00:26:09,444 INFO org.apache.hadoop.yarn.server.resourcemanager.rmapp.attempt.RMAppAttemptImpl: Storing attempt: AppId: application_1377907764744_0007 AttemptId: appattempt_1377907764744_0007_000001 MasterContainer: Container: [ContainerId: container_1377907764744_0007_01_000001, NodeId: hadoop-32-2:38703, NodeHttpAddress: hadoop-32-2:8042, Resource: <memory:2048, vCores:1>, Priority: 0, State: NEW, Token: null, Status: container_id {, app_attempt_id {, application_id {, id: 7, cluster_timestamp: 1377907764744, }, attemptId: 1, }, id: 1, }, state: C_NEW, ]
2013-08-31 00:26:09,445 INFO org.apache.hadoop.yarn.server.resourcemanager.recovery.RMStateStore: Storing info for attempt: appattempt_1377907764744_0007_000001
2013-08-31 00:26:09,445 INFO org.apache.hadoop.yarn.server.resourcemanager.rmapp.attempt.RMAppAttemptImpl: appattempt_1377907764744_0007_000001 State change from SCHEDULED to ALLOCATED_SAVING
2013-08-31 00:26:09,445 INFO org.apache.hadoop.yarn.server.resourcemanager.rmapp.attempt.RMAppAttemptImpl: appattempt_1377907764744_0007_000001 State change from ALLOCATED_SAVING to ALLOCATED
2013-08-31 00:26:09,445 INFO org.apache.hadoop.yarn.server.resourcemanager.amlauncher.AMLauncher: Launching masterappattempt_1377907764744_0007_000001
2013-08-31 00:26:09,447 INFO org.apache.hadoop.yarn.server.resourcemanager.amlauncher.AMLauncher: Setting up container Container: [ContainerId: container_1377907764744_0007_01_000001, NodeId: hadoop-32-2:38703, NodeHttpAddress: hadoop-32-2:8042, Resource: <memory:2048, vCores:1>, Priority: 0, State: NEW, Token: null, Status: container_id {, app_attempt_id {, application_id {, id: 7, cluster_timestamp: 1377907764744, }, attemptId: 1, }, id: 1, }, state: C_NEW, ] for AM appattempt_1377907764744_0007_000001
2013-08-31 00:26:09,447 INFO org.apache.hadoop.yarn.server.resourcemanager.amlauncher.AMLauncher: Command to launch container container_1377907764744_0007_01_000001 : $JAVA_HOME/bin/java -Dlog4j.configuration=container-log4j.properties -Dyarn.app.mapreduce.container.log.dir=<LOG_DIR> -Dyarn.app.mapreduce.container.log.filesize=0 -Dhadoop.root.logger=INFO,CLA  -Xmx1024m org.apache.hadoop.mapreduce.v2.app.MRAppMaster 1><LOG_DIR>/stdout 2><LOG_DIR>/stderr 
2013-08-31 00:26:09,461 INFO org.apache.hadoop.yarn.server.resourcemanager.amlauncher.AMLauncher: Done launching container Container: [ContainerId: container_1377907764744_0007_01_000001, NodeId: hadoop-32-2:38703, NodeHttpAddress: hadoop-32-2:8042, Resource: <memory:2048, vCores:1>, Priority: 0, State: NEW, Token: null, Status: container_id {, app_attempt_id {, application_id {, id: 7, cluster_timestamp: 1377907764744, }, attemptId: 1, }, id: 1, }, state: C_NEW, ] for AM appattempt_1377907764744_0007_000001
2013-08-31 00:26:09,461 INFO org.apache.hadoop.yarn.server.resourcemanager.rmapp.attempt.RMAppAttemptImpl: appattempt_1377907764744_0007_000001 State change from ALLOCATED to LAUNCHED
2013-08-31 00:26:09,537 INFO org.apache.hadoop.yarn.server.resourcemanager.rmcontainer.RMContainerImpl: container_1377907764744_0008_01_000001 Container Transitioned from NEW to ALLOCATED
2013-08-31 00:26:09,537 INFO org.apache.hadoop.yarn.server.resourcemanager.RMAuditLogger: USER=ubuntu	OPERATION=AM Allocated Container	TARGET=SchedulerApp	RESULT=SUCCESS	APPID=application_1377907764744_0008	CONTAINERID=container_1377907764744_0008_01_000001
2013-08-31 00:26:09,537 INFO org.apache.hadoop.yarn.server.resourcemanager.scheduler.common.fica.FiCaSchedulerNode: Assigned container container_1377907764744_0008_01_000001 of capacity <memory:2048, vCores:1> on host hadoop-32-5:54799, which currently has 1 containers, <memory:2048, vCores:1> used and <memory:6144, vCores:15> available
2013-08-31 00:26:09,538 INFO org.apache.hadoop.yarn.server.resourcemanager.scheduler.capacity.LeafQueue: assignedContainer application=application_1377907764744_0008 container=Container: [ContainerId: container_1377907764744_0008_01_000001, NodeId: hadoop-32-5:54799, NodeHttpAddress: hadoop-32-5:8042, Resource: <memory:2048, vCores:1>, Priority: 0, State: NEW, Token: null, Status: container_id {, app_attempt_id {, application_id {, id: 8, cluster_timestamp: 1377907764744, }, attemptId: 1, }, id: 1, }, state: C_NEW, ] containerId=container_1377907764744_0008_01_000001 queue=default: capacity=1.0, absoluteCapacity=1.0, usedResources=<memory:4096, vCores:2>usedCapacity=0.083333336, absoluteUsedCapacity=0.083333336, numApps=3, numContainers=2 usedCapacity=0.083333336 absoluteUsedCapacity=0.083333336 used=<memory:4096, vCores:2> cluster=<memory:49152, vCores:96>
2013-08-31 00:26:09,538 INFO org.apache.hadoop.yarn.server.resourcemanager.scheduler.capacity.ParentQueue: Re-sorting queues since queue: root.default stats: default: capacity=1.0, absoluteCapacity=1.0, usedResources=<memory:6144, vCores:3>usedCapacity=0.125, absoluteUsedCapacity=0.125, numApps=3, numContainers=3
2013-08-31 00:26:09,538 INFO org.apache.hadoop.yarn.server.resourcemanager.scheduler.capacity.ParentQueue: assignedContainer queue=root usedCapacity=0.125 absoluteUsedCapacity=0.125 used=<memory:6144, vCores:3> cluster=<memory:49152, vCores:96>
2013-08-31 00:26:09,540 INFO org.apache.hadoop.yarn.server.resourcemanager.rmcontainer.RMContainerImpl: container_1377907764744_0008_01_000001 Container Transitioned from ALLOCATED to ACQUIRED
2013-08-31 00:26:09,541 INFO org.apache.hadoop.yarn.server.resourcemanager.rmapp.attempt.RMAppAttemptImpl: Storing attempt: AppId: application_1377907764744_0008 AttemptId: appattempt_1377907764744_0008_000001 MasterContainer: Container: [ContainerId: container_1377907764744_0008_01_000001, NodeId: hadoop-32-5:54799, NodeHttpAddress: hadoop-32-5:8042, Resource: <memory:2048, vCores:1>, Priority: 0, State: NEW, Token: null, Status: container_id {, app_attempt_id {, application_id {, id: 8, cluster_timestamp: 1377907764744, }, attemptId: 1, }, id: 1, }, state: C_NEW, ]
2013-08-31 00:26:09,542 INFO org.apache.hadoop.yarn.server.resourcemanager.recovery.RMStateStore: Storing info for attempt: appattempt_1377907764744_0008_000001
2013-08-31 00:26:09,542 INFO org.apache.hadoop.yarn.server.resourcemanager.rmapp.attempt.RMAppAttemptImpl: appattempt_1377907764744_0008_000001 State change from SCHEDULED to ALLOCATED_SAVING
2013-08-31 00:26:09,542 INFO org.apache.hadoop.yarn.server.resourcemanager.rmapp.attempt.RMAppAttemptImpl: appattempt_1377907764744_0008_000001 State change from ALLOCATED_SAVING to ALLOCATED
2013-08-31 00:26:09,542 INFO org.apache.hadoop.yarn.server.resourcemanager.amlauncher.AMLauncher: Launching masterappattempt_1377907764744_0008_000001
2013-08-31 00:26:09,543 INFO org.apache.hadoop.yarn.server.resourcemanager.amlauncher.AMLauncher: Setting up container Container: [ContainerId: container_1377907764744_0008_01_000001, NodeId: hadoop-32-5:54799, NodeHttpAddress: hadoop-32-5:8042, Resource: <memory:2048, vCores:1>, Priority: 0, State: NEW, Token: null, Status: container_id {, app_attempt_id {, application_id {, id: 8, cluster_timestamp: 1377907764744, }, attemptId: 1, }, id: 1, }, state: C_NEW, ] for AM appattempt_1377907764744_0008_000001
2013-08-31 00:26:09,543 INFO org.apache.hadoop.yarn.server.resourcemanager.amlauncher.AMLauncher: Command to launch container container_1377907764744_0008_01_000001 : $JAVA_HOME/bin/java -Dlog4j.configuration=container-log4j.properties -Dyarn.app.mapreduce.container.log.dir=<LOG_DIR> -Dyarn.app.mapreduce.container.log.filesize=0 -Dhadoop.root.logger=INFO,CLA  -Xmx1024m org.apache.hadoop.mapreduce.v2.app.MRAppMaster 1><LOG_DIR>/stdout 2><LOG_DIR>/stderr 
2013-08-31 00:26:09,558 INFO org.apache.hadoop.yarn.server.resourcemanager.amlauncher.AMLauncher: Done launching container Container: [ContainerId: container_1377907764744_0008_01_000001, NodeId: hadoop-32-5:54799, NodeHttpAddress: hadoop-32-5:8042, Resource: <memory:2048, vCores:1>, Priority: 0, State: NEW, Token: null, Status: container_id {, app_attempt_id {, application_id {, id: 8, cluster_timestamp: 1377907764744, }, attemptId: 1, }, id: 1, }, state: C_NEW, ] for AM appattempt_1377907764744_0008_000001
2013-08-31 00:26:09,558 INFO org.apache.hadoop.yarn.server.resourcemanager.rmapp.attempt.RMAppAttemptImpl: appattempt_1377907764744_0008_000001 State change from ALLOCATED to LAUNCHED
2013-08-31 00:26:10,246 INFO org.apache.hadoop.yarn.server.resourcemanager.rmcontainer.RMContainerImpl: container_1377907764744_0006_01_000001 Container Transitioned from ACQUIRED to RUNNING
2013-08-31 00:26:10,447 INFO org.apache.hadoop.yarn.server.resourcemanager.rmcontainer.RMContainerImpl: container_1377907764744_0007_01_000001 Container Transitioned from ACQUIRED to RUNNING
2013-08-31 00:26:10,542 INFO org.apache.hadoop.yarn.server.resourcemanager.rmcontainer.RMContainerImpl: container_1377907764744_0008_01_000001 Container Transitioned from ACQUIRED to RUNNING
2013-08-31 00:26:20,998 INFO org.apache.hadoop.yarn.server.resourcemanager.ClientRMService: Allocated new applicationId: 9
2013-08-31 00:26:21,274 INFO org.apache.hadoop.yarn.server.resourcemanager.ClientRMService: Allocated new applicationId: 10
2013-08-31 00:26:21,430 INFO org.apache.hadoop.yarn.server.resourcemanager.ApplicationMasterService: AM registration appattempt_1377907764744_0007_000001
2013-08-31 00:26:21,430 INFO org.apache.hadoop.yarn.server.resourcemanager.RMAuditLogger: USER=ubuntu	IP=192.168.100.22	OPERATION=Register App Master	TARGET=ApplicationMasterService	RESULT=SUCCESS	APPID=application_1377907764744_0007	APPATTEMPTID=appattempt_1377907764744_0007_000001
2013-08-31 00:26:21,431 INFO org.apache.hadoop.yarn.server.resourcemanager.rmapp.attempt.RMAppAttemptImpl: appattempt_1377907764744_0007_000001 State change from LAUNCHED to RUNNING
2013-08-31 00:26:21,431 INFO org.apache.hadoop.yarn.server.resourcemanager.rmapp.RMAppImpl: application_1377907764744_0007 State change from ACCEPTED to RUNNING
2013-08-31 00:26:22,132 INFO org.apache.hadoop.yarn.server.resourcemanager.ApplicationMasterService: AM registration appattempt_1377907764744_0006_000001
2013-08-31 00:26:22,132 INFO org.apache.hadoop.yarn.server.resourcemanager.RMAuditLogger: USER=ubuntu	IP=192.168.100.38	OPERATION=Register App Master	TARGET=ApplicationMasterService	RESULT=SUCCESS	APPID=application_1377907764744_0006	APPATTEMPTID=appattempt_1377907764744_0006_000001
2013-08-31 00:26:22,133 INFO org.apache.hadoop.yarn.server.resourcemanager.rmapp.attempt.RMAppAttemptImpl: appattempt_1377907764744_0006_000001 State change from LAUNCHED to RUNNING
2013-08-31 00:26:22,133 INFO org.apache.hadoop.yarn.server.resourcemanager.rmapp.RMAppImpl: application_1377907764744_0006 State change from ACCEPTED to RUNNING
2013-08-31 00:26:22,489 INFO org.apache.hadoop.yarn.server.resourcemanager.ClientRMService: Storing Application with id application_1377907764744_0009
2013-08-31 00:26:22,489 INFO org.apache.hadoop.yarn.server.resourcemanager.recovery.RMStateStore: Storing info for app: application_1377907764744_0009
2013-08-31 00:26:22,489 INFO org.apache.hadoop.yarn.server.resourcemanager.ClientRMService: Application with id 9 submitted by user ubuntu
2013-08-31 00:26:22,489 INFO org.apache.hadoop.yarn.server.resourcemanager.RMAuditLogger: USER=ubuntu	IP=192.168.100.5	OPERATION=Submit Application Request	TARGET=ClientRMService	RESULT=SUCCESS	APPID=application_1377907764744_0009
2013-08-31 00:26:22,491 INFO org.apache.hadoop.yarn.server.resourcemanager.rmapp.RMAppImpl: application_1377907764744_0009 State change from NEW to SUBMITTED
2013-08-31 00:26:22,491 INFO org.apache.hadoop.yarn.server.resourcemanager.ApplicationMasterService: Registering appattempt_1377907764744_0009_000001
2013-08-31 00:26:22,491 INFO org.apache.hadoop.yarn.server.resourcemanager.rmapp.attempt.RMAppAttemptImpl: appattempt_1377907764744_0009_000001 State change from NEW to SUBMITTED
2013-08-31 00:26:22,491 INFO org.apache.hadoop.yarn.server.resourcemanager.scheduler.capacity.LeafQueue: Application application_1377907764744_0009 from user: ubuntu activated in queue: default
2013-08-31 00:26:22,492 INFO org.apache.hadoop.yarn.server.resourcemanager.scheduler.capacity.LeafQueue: Application added - appId: application_1377907764744_0009 user: org.apache.hadoop.yarn.server.resourcemanager.scheduler.capacity.LeafQueue$User@277b3c9b, leaf-queue: default #user-pending-applications: 0 #user-active-applications: 4 #queue-pending-applications: 0 #queue-active-applications: 4
2013-08-31 00:26:22,492 INFO org.apache.hadoop.yarn.server.resourcemanager.scheduler.capacity.ParentQueue: Application added - appId: application_1377907764744_0009 user: ubuntu leaf-queue of parent: root #applications: 4
2013-08-31 00:26:22,492 INFO org.apache.hadoop.yarn.server.resourcemanager.scheduler.capacity.CapacityScheduler: Application Submission: appattempt_1377907764744_0009_000001, user: ubuntu queue: default: capacity=1.0, absoluteCapacity=1.0, usedResources=<memory:6144, vCores:3>usedCapacity=0.125, absoluteUsedCapacity=0.125, numApps=4, numContainers=3, currently active: 4
2013-08-31 00:26:22,493 INFO org.apache.hadoop.yarn.server.resourcemanager.rmapp.attempt.RMAppAttemptImpl: appattempt_1377907764744_0009_000001 State change from SUBMITTED to SCHEDULED
2013-08-31 00:26:22,493 INFO org.apache.hadoop.yarn.server.resourcemanager.rmapp.RMAppImpl: application_1377907764744_0009 State change from SUBMITTED to ACCEPTED
2013-08-31 00:26:22,509 INFO org.apache.hadoop.yarn.server.resourcemanager.rmcontainer.RMContainerImpl: container_1377907764744_0007_01_000002 Container Transitioned from NEW to ALLOCATED
2013-08-31 00:26:22,509 INFO org.apache.hadoop.yarn.server.resourcemanager.RMAuditLogger: USER=ubuntu	OPERATION=AM Allocated Container	TARGET=SchedulerApp	RESULT=SUCCESS	APPID=application_1377907764744_0007	CONTAINERID=container_1377907764744_0007_01_000002
2013-08-31 00:26:22,509 INFO org.apache.hadoop.yarn.server.resourcemanager.scheduler.common.fica.FiCaSchedulerNode: Assigned container container_1377907764744_0007_01_000002 of capacity <memory:1024, vCores:1> on host hadoop-32-2:38703, which currently has 2 containers, <memory:3072, vCores:2> used and <memory:5120, vCores:14> available
2013-08-31 00:26:22,510 INFO org.apache.hadoop.yarn.server.resourcemanager.scheduler.capacity.LeafQueue: assignedContainer application=application_1377907764744_0007 container=Container: [ContainerId: container_1377907764744_0007_01_000002, NodeId: hadoop-32-2:38703, NodeHttpAddress: hadoop-32-2:8042, Resource: <memory:1024, vCores:1>, Priority: 20, State: NEW, Token: null, Status: container_id {, app_attempt_id {, application_id {, id: 7, cluster_timestamp: 1377907764744, }, attemptId: 1, }, id: 2, }, state: C_NEW, ] containerId=container_1377907764744_0007_01_000002 queue=default: capacity=1.0, absoluteCapacity=1.0, usedResources=<memory:6144, vCores:3>usedCapacity=0.125, absoluteUsedCapacity=0.125, numApps=4, numContainers=3 usedCapacity=0.125 absoluteUsedCapacity=0.125 used=<memory:6144, vCores:3> cluster=<memory:49152, vCores:96>
2013-08-31 00:26:22,511 INFO org.apache.hadoop.yarn.server.resourcemanager.scheduler.capacity.ParentQueue: Re-sorting queues since queue: root.default stats: default: capacity=1.0, absoluteCapacity=1.0, usedResources=<memory:7168, vCores:4>usedCapacity=0.14583333, absoluteUsedCapacity=0.14583333, numApps=4, numContainers=4
2013-08-31 00:26:22,511 INFO org.apache.hadoop.yarn.server.resourcemanager.scheduler.capacity.ParentQueue: assignedContainer queue=root usedCapacity=0.14583333 absoluteUsedCapacity=0.14583333 used=<memory:7168, vCores:4> cluster=<memory:49152, vCores:96>
2013-08-31 00:26:22,511 INFO org.apache.hadoop.yarn.server.resourcemanager.rmcontainer.RMContainerImpl: container_1377907764744_0007_01_000003 Container Transitioned from NEW to ALLOCATED
2013-08-31 00:26:22,512 INFO org.apache.hadoop.yarn.server.resourcemanager.RMAuditLogger: USER=ubuntu	OPERATION=AM Allocated Container	TARGET=SchedulerApp	RESULT=SUCCESS	APPID=application_1377907764744_0007	CONTAINERID=container_1377907764744_0007_01_000003
2013-08-31 00:26:22,512 INFO org.apache.hadoop.yarn.server.resourcemanager.scheduler.common.fica.FiCaSchedulerNode: Assigned container container_1377907764744_0007_01_000003 of capacity <memory:1024, vCores:1> on host hadoop-32-2:38703, which currently has 3 containers, <memory:4096, vCores:3> used and <memory:4096, vCores:13> available
2013-08-31 00:26:22,513 INFO org.apache.hadoop.yarn.server.resourcemanager.scheduler.capacity.LeafQueue: assignedContainer application=application_1377907764744_0007 container=Container: [ContainerId: container_1377907764744_0007_01_000003, NodeId: hadoop-32-2:38703, NodeHttpAddress: hadoop-32-2:8042, Resource: <memory:1024, vCores:1>, Priority: 20, State: NEW, Token: null, Status: container_id {, app_attempt_id {, application_id {, id: 7, cluster_timestamp: 1377907764744, }, attemptId: 1, }, id: 3, }, state: C_NEW, ] containerId=container_1377907764744_0007_01_000003 queue=default: capacity=1.0, absoluteCapacity=1.0, usedResources=<memory:7168, vCores:4>usedCapacity=0.14583333, absoluteUsedCapacity=0.14583333, numApps=4, numContainers=4 usedCapacity=0.14583333 absoluteUsedCapacity=0.14583333 used=<memory:7168, vCores:4> cluster=<memory:49152, vCores:96>
2013-08-31 00:26:22,513 INFO org.apache.hadoop.yarn.server.resourcemanager.scheduler.capacity.ParentQueue: Re-sorting queues since queue: root.default stats: default: capacity=1.0, absoluteCapacity=1.0, usedResources=<memory:8192, vCores:5>usedCapacity=0.16666667, absoluteUsedCapacity=0.16666667, numApps=4, numContainers=5
2013-08-31 00:26:22,513 INFO org.apache.hadoop.yarn.server.resourcemanager.scheduler.capacity.ParentQueue: assignedContainer queue=root usedCapacity=0.16666667 absoluteUsedCapacity=0.16666667 used=<memory:8192, vCores:5> cluster=<memory:49152, vCores:96>
2013-08-31 00:26:22,514 INFO org.apache.hadoop.yarn.server.resourcemanager.rmcontainer.RMContainerImpl: container_1377907764744_0007_01_000004 Container Transitioned from NEW to ALLOCATED
2013-08-31 00:26:22,514 INFO org.apache.hadoop.yarn.server.resourcemanager.RMAuditLogger: USER=ubuntu	OPERATION=AM Allocated Container	TARGET=SchedulerApp	RESULT=SUCCESS	APPID=application_1377907764744_0007	CONTAINERID=container_1377907764744_0007_01_000004
2013-08-31 00:26:22,514 INFO org.apache.hadoop.yarn.server.resourcemanager.scheduler.common.fica.FiCaSchedulerNode: Assigned container container_1377907764744_0007_01_000004 of capacity <memory:1024, vCores:1> on host hadoop-32-2:38703, which currently has 4 containers, <memory:5120, vCores:4> used and <memory:3072, vCores:12> available
2013-08-31 00:26:22,516 INFO org.apache.hadoop.yarn.server.resourcemanager.scheduler.capacity.LeafQueue: assignedContainer application=application_1377907764744_0007 container=Container: [ContainerId: container_1377907764744_0007_01_000004, NodeId: hadoop-32-2:38703, NodeHttpAddress: hadoop-32-2:8042, Resource: <memory:1024, vCores:1>, Priority: 20, State: NEW, Token: null, Status: container_id {, app_attempt_id {, application_id {, id: 7, cluster_timestamp: 1377907764744, }, attemptId: 1, }, id: 4, }, state: C_NEW, ] containerId=container_1377907764744_0007_01_000004 queue=default: capacity=1.0, absoluteCapacity=1.0, usedResources=<memory:8192, vCores:5>usedCapacity=0.16666667, absoluteUsedCapacity=0.16666667, numApps=4, numContainers=5 usedCapacity=0.16666667 absoluteUsedCapacity=0.16666667 used=<memory:8192, vCores:5> cluster=<memory:49152, vCores:96>
2013-08-31 00:26:22,516 INFO org.apache.hadoop.yarn.server.resourcemanager.scheduler.capacity.ParentQueue: Re-sorting queues since queue: root.default stats: default: capacity=1.0, absoluteCapacity=1.0, usedResources=<memory:9216, vCores:6>usedCapacity=0.1875, absoluteUsedCapacity=0.1875, numApps=4, numContainers=6
2013-08-31 00:26:22,517 INFO org.apache.hadoop.yarn.server.resourcemanager.scheduler.capacity.ParentQueue: assignedContainer queue=root usedCapacity=0.1875 absoluteUsedCapacity=0.1875 used=<memory:9216, vCores:6> cluster=<memory:49152, vCores:96>
2013-08-31 00:26:22,517 INFO org.apache.hadoop.yarn.server.resourcemanager.rmcontainer.RMContainerImpl: container_1377907764744_0007_01_000005 Container Transitioned from NEW to ALLOCATED
2013-08-31 00:26:22,517 INFO org.apache.hadoop.yarn.server.resourcemanager.RMAuditLogger: USER=ubuntu	OPERATION=AM Allocated Container	TARGET=SchedulerApp	RESULT=SUCCESS	APPID=application_1377907764744_0007	CONTAINERID=container_1377907764744_0007_01_000005
2013-08-31 00:26:22,517 INFO org.apache.hadoop.yarn.server.resourcemanager.scheduler.common.fica.FiCaSchedulerNode: Assigned container container_1377907764744_0007_01_000005 of capacity <memory:1024, vCores:1> on host hadoop-32-2:38703, which currently has 5 containers, <memory:6144, vCores:5> used and <memory:2048, vCores:11> available
2013-08-31 00:26:22,518 INFO org.apache.hadoop.yarn.server.resourcemanager.scheduler.capacity.LeafQueue: assignedContainer application=application_1377907764744_0007 container=Container: [ContainerId: container_1377907764744_0007_01_000005, NodeId: hadoop-32-2:38703, NodeHttpAddress: hadoop-32-2:8042, Resource: <memory:1024, vCores:1>, Priority: 20, State: NEW, Token: null, Status: container_id {, app_attempt_id {, application_id {, id: 7, cluster_timestamp: 1377907764744, }, attemptId: 1, }, id: 5, }, state: C_NEW, ] containerId=container_1377907764744_0007_01_000005 queue=default: capacity=1.0, absoluteCapacity=1.0, usedResources=<memory:9216, vCores:6>usedCapacity=0.1875, absoluteUsedCapacity=0.1875, numApps=4, numContainers=6 usedCapacity=0.1875 absoluteUsedCapacity=0.1875 used=<memory:9216, vCores:6> cluster=<memory:49152, vCores:96>
2013-08-31 00:26:22,519 INFO org.apache.hadoop.yarn.server.resourcemanager.scheduler.capacity.ParentQueue: Re-sorting queues since queue: root.default stats: default: capacity=1.0, absoluteCapacity=1.0, usedResources=<memory:10240, vCores:7>usedCapacity=0.20833333, absoluteUsedCapacity=0.20833333, numApps=4, numContainers=7
2013-08-31 00:26:22,519 INFO org.apache.hadoop.yarn.server.resourcemanager.scheduler.capacity.ParentQueue: assignedContainer queue=root usedCapacity=0.20833333 absoluteUsedCapacity=0.20833333 used=<memory:10240, vCores:7> cluster=<memory:49152, vCores:96>
2013-08-31 00:26:22,519 INFO org.apache.hadoop.yarn.server.resourcemanager.rmcontainer.RMContainerImpl: container_1377907764744_0007_01_000006 Container Transitioned from NEW to ALLOCATED
2013-08-31 00:26:22,520 INFO org.apache.hadoop.yarn.server.resourcemanager.RMAuditLogger: USER=ubuntu	OPERATION=AM Allocated Container	TARGET=SchedulerApp	RESULT=SUCCESS	APPID=application_1377907764744_0007	CONTAINERID=container_1377907764744_0007_01_000006
2013-08-31 00:26:22,520 INFO org.apache.hadoop.yarn.server.resourcemanager.scheduler.common.fica.FiCaSchedulerNode: Assigned container container_1377907764744_0007_01_000006 of capacity <memory:1024, vCores:1> on host hadoop-32-2:38703, which currently has 6 containers, <memory:7168, vCores:6> used and <memory:1024, vCores:10> available
2013-08-31 00:26:22,521 INFO org.apache.hadoop.yarn.server.resourcemanager.scheduler.capacity.LeafQueue: assignedContainer application=application_1377907764744_0007 container=Container: [ContainerId: container_1377907764744_0007_01_000006, NodeId: hadoop-32-2:38703, NodeHttpAddress: hadoop-32-2:8042, Resource: <memory:1024, vCores:1>, Priority: 20, State: NEW, Token: null, Status: container_id {, app_attempt_id {, application_id {, id: 7, cluster_timestamp: 1377907764744, }, attemptId: 1, }, id: 6, }, state: C_NEW, ] containerId=container_1377907764744_0007_01_000006 queue=default: capacity=1.0, absoluteCapacity=1.0, usedResources=<memory:10240, vCores:7>usedCapacity=0.20833333, absoluteUsedCapacity=0.20833333, numApps=4, numContainers=7 usedCapacity=0.20833333 absoluteUsedCapacity=0.20833333 used=<memory:10240, vCores:7> cluster=<memory:49152, vCores:96>
2013-08-31 00:26:22,521 INFO org.apache.hadoop.yarn.server.resourcemanager.scheduler.capacity.ParentQueue: Re-sorting queues since queue: root.default stats: default: capacity=1.0, absoluteCapacity=1.0, usedResources=<memory:11264, vCores:8>usedCapacity=0.22916667, absoluteUsedCapacity=0.22916667, numApps=4, numContainers=8
2013-08-31 00:26:22,521 INFO org.apache.hadoop.yarn.server.resourcemanager.scheduler.capacity.ParentQueue: assignedContainer queue=root usedCapacity=0.22916667 absoluteUsedCapacity=0.22916667 used=<memory:11264, vCores:8> cluster=<memory:49152, vCores:96>
2013-08-31 00:26:22,522 INFO org.apache.hadoop.yarn.server.resourcemanager.rmcontainer.RMContainerImpl: container_1377907764744_0007_01_000007 Container Transitioned from NEW to ALLOCATED
2013-08-31 00:26:22,522 INFO org.apache.hadoop.yarn.server.resourcemanager.RMAuditLogger: USER=ubuntu	OPERATION=AM Allocated Container	TARGET=SchedulerApp	RESULT=SUCCESS	APPID=application_1377907764744_0007	CONTAINERID=container_1377907764744_0007_01_000007
2013-08-31 00:26:22,522 INFO org.apache.hadoop.yarn.server.resourcemanager.scheduler.common.fica.FiCaSchedulerNode: Assigned container container_1377907764744_0007_01_000007 of capacity <memory:1024, vCores:1> on host hadoop-32-2:38703, which currently has 7 containers, <memory:8192, vCores:7> used and <memory:0, vCores:9> available
2013-08-31 00:26:22,524 INFO org.apache.hadoop.yarn.server.resourcemanager.scheduler.capacity.LeafQueue: assignedContainer application=application_1377907764744_0007 container=Container: [ContainerId: container_1377907764744_0007_01_000007, NodeId: hadoop-32-2:38703, NodeHttpAddress: hadoop-32-2:8042, Resource: <memory:1024, vCores:1>, Priority: 20, State: NEW, Token: null, Status: container_id {, app_attempt_id {, application_id {, id: 7, cluster_timestamp: 1377907764744, }, attemptId: 1, }, id: 7, }, state: C_NEW, ] containerId=container_1377907764744_0007_01_000007 queue=default: capacity=1.0, absoluteCapacity=1.0, usedResources=<memory:11264, vCores:8>usedCapacity=0.22916667, absoluteUsedCapacity=0.22916667, numApps=4, numContainers=8 usedCapacity=0.22916667 absoluteUsedCapacity=0.22916667 used=<memory:11264, vCores:8> cluster=<memory:49152, vCores:96>
2013-08-31 00:26:22,524 INFO org.apache.hadoop.yarn.server.resourcemanager.scheduler.capacity.ParentQueue: Re-sorting queues since queue: root.default stats: default: capacity=1.0, absoluteCapacity=1.0, usedResources=<memory:12288, vCores:9>usedCapacity=0.25, absoluteUsedCapacity=0.25, numApps=4, numContainers=9
2013-08-31 00:26:22,524 INFO org.apache.hadoop.yarn.server.resourcemanager.scheduler.capacity.ParentQueue: assignedContainer queue=root usedCapacity=0.25 absoluteUsedCapacity=0.25 used=<memory:12288, vCores:9> cluster=<memory:49152, vCores:96>
2013-08-31 00:26:22,595 INFO org.apache.hadoop.yarn.server.resourcemanager.rmcontainer.RMContainerImpl: container_1377907764744_0007_01_000008 Container Transitioned from NEW to ALLOCATED
2013-08-31 00:26:22,596 INFO org.apache.hadoop.yarn.server.resourcemanager.RMAuditLogger: USER=ubuntu	OPERATION=AM Allocated Container	TARGET=SchedulerApp	RESULT=SUCCESS	APPID=application_1377907764744_0007	CONTAINERID=container_1377907764744_0007_01_000008
2013-08-31 00:26:22,596 INFO org.apache.hadoop.yarn.server.resourcemanager.scheduler.common.fica.FiCaSchedulerNode: Assigned container container_1377907764744_0007_01_000008 of capacity <memory:1024, vCores:1> on host hadoop-32-4:58137, which currently has 1 containers, <memory:1024, vCores:1> used and <memory:7168, vCores:15> available
2013-08-31 00:26:22,597 INFO org.apache.hadoop.yarn.server.resourcemanager.scheduler.capacity.LeafQueue: assignedContainer application=application_1377907764744_0007 container=Container: [ContainerId: container_1377907764744_0007_01_000008, NodeId: hadoop-32-4:58137, NodeHttpAddress: hadoop-32-4:8042, Resource: <memory:1024, vCores:1>, Priority: 20, State: NEW, Token: null, Status: container_id {, app_attempt_id {, application_id {, id: 7, cluster_timestamp: 1377907764744, }, attemptId: 1, }, id: 8, }, state: C_NEW, ] containerId=container_1377907764744_0007_01_000008 queue=default: capacity=1.0, absoluteCapacity=1.0, usedResources=<memory:12288, vCores:9>usedCapacity=0.25, absoluteUsedCapacity=0.25, numApps=4, numContainers=9 usedCapacity=0.25 absoluteUsedCapacity=0.25 used=<memory:12288, vCores:9> cluster=<memory:49152, vCores:96>
2013-08-31 00:26:22,598 INFO org.apache.hadoop.yarn.server.resourcemanager.scheduler.capacity.ParentQueue: Re-sorting queues since queue: root.default stats: default: capacity=1.0, absoluteCapacity=1.0, usedResources=<memory:13312, vCores:10>usedCapacity=0.27083334, absoluteUsedCapacity=0.27083334, numApps=4, numContainers=10
2013-08-31 00:26:22,598 INFO org.apache.hadoop.yarn.server.resourcemanager.scheduler.capacity.ParentQueue: assignedContainer queue=root usedCapacity=0.27083334 absoluteUsedCapacity=0.27083334 used=<memory:13312, vCores:10> cluster=<memory:49152, vCores:96>
2013-08-31 00:26:22,598 INFO org.apache.hadoop.yarn.server.resourcemanager.rmcontainer.RMContainerImpl: container_1377907764744_0007_01_000009 Container Transitioned from NEW to ALLOCATED
2013-08-31 00:26:22,598 INFO org.apache.hadoop.yarn.server.resourcemanager.RMAuditLogger: USER=ubuntu	OPERATION=AM Allocated Container	TARGET=SchedulerApp	RESULT=SUCCESS	APPID=application_1377907764744_0007	CONTAINERID=container_1377907764744_0007_01_000009
2013-08-31 00:26:22,599 INFO org.apache.hadoop.yarn.server.resourcemanager.scheduler.common.fica.FiCaSchedulerNode: Assigned container container_1377907764744_0007_01_000009 of capacity <memory:1024, vCores:1> on host hadoop-32-4:58137, which currently has 2 containers, <memory:2048, vCores:2> used and <memory:6144, vCores:14> available
2013-08-31 00:26:22,600 INFO org.apache.hadoop.yarn.server.resourcemanager.scheduler.capacity.LeafQueue: assignedContainer application=application_1377907764744_0007 container=Container: [ContainerId: container_1377907764744_0007_01_000009, NodeId: hadoop-32-4:58137, NodeHttpAddress: hadoop-32-4:8042, Resource: <memory:1024, vCores:1>, Priority: 20, State: NEW, Token: null, Status: container_id {, app_attempt_id {, application_id {, id: 7, cluster_timestamp: 1377907764744, }, attemptId: 1, }, id: 9, }, state: C_NEW, ] containerId=container_1377907764744_0007_01_000009 queue=default: capacity=1.0, absoluteCapacity=1.0, usedResources=<memory:13312, vCores:10>usedCapacity=0.27083334, absoluteUsedCapacity=0.27083334, numApps=4, numContainers=10 usedCapacity=0.27083334 absoluteUsedCapacity=0.27083334 used=<memory:13312, vCores:10> cluster=<memory:49152, vCores:96>
2013-08-31 00:26:22,600 INFO org.apache.hadoop.yarn.server.resourcemanager.scheduler.capacity.ParentQueue: Re-sorting queues since queue: root.default stats: default: capacity=1.0, absoluteCapacity=1.0, usedResources=<memory:14336, vCores:11>usedCapacity=0.29166666, absoluteUsedCapacity=0.29166666, numApps=4, numContainers=11
2013-08-31 00:26:22,600 INFO org.apache.hadoop.yarn.server.resourcemanager.scheduler.capacity.ParentQueue: assignedContainer queue=root usedCapacity=0.29166666 absoluteUsedCapacity=0.29166666 used=<memory:14336, vCores:11> cluster=<memory:49152, vCores:96>
2013-08-31 00:26:22,601 INFO org.apache.hadoop.yarn.server.resourcemanager.rmcontainer.RMContainerImpl: container_1377907764744_0007_01_000010 Container Transitioned from NEW to ALLOCATED
2013-08-31 00:26:22,601 INFO org.apache.hadoop.yarn.server.resourcemanager.RMAuditLogger: USER=ubuntu	OPERATION=AM Allocated Container	TARGET=SchedulerApp	RESULT=SUCCESS	APPID=application_1377907764744_0007	CONTAINERID=container_1377907764744_0007_01_000010
2013-08-31 00:26:22,601 INFO org.apache.hadoop.yarn.server.resourcemanager.scheduler.common.fica.FiCaSchedulerNode: Assigned container container_1377907764744_0007_01_000010 of capacity <memory:1024, vCores:1> on host hadoop-32-4:58137, which currently has 3 containers, <memory:3072, vCores:3> used and <memory:5120, vCores:13> available
2013-08-31 00:26:22,602 INFO org.apache.hadoop.yarn.server.resourcemanager.scheduler.capacity.LeafQueue: assignedContainer application=application_1377907764744_0007 container=Container: [ContainerId: container_1377907764744_0007_01_000010, NodeId: hadoop-32-4:58137, NodeHttpAddress: hadoop-32-4:8042, Resource: <memory:1024, vCores:1>, Priority: 20, State: NEW, Token: null, Status: container_id {, app_attempt_id {, application_id {, id: 7, cluster_timestamp: 1377907764744, }, attemptId: 1, }, id: 10, }, state: C_NEW, ] containerId=container_1377907764744_0007_01_000010 queue=default: capacity=1.0, absoluteCapacity=1.0, usedResources=<memory:14336, vCores:11>usedCapacity=0.29166666, absoluteUsedCapacity=0.29166666, numApps=4, numContainers=11 usedCapacity=0.29166666 absoluteUsedCapacity=0.29166666 used=<memory:14336, vCores:11> cluster=<memory:49152, vCores:96>
2013-08-31 00:26:22,602 INFO org.apache.hadoop.yarn.server.resourcemanager.scheduler.capacity.ParentQueue: Re-sorting queues since queue: root.default stats: default: capacity=1.0, absoluteCapacity=1.0, usedResources=<memory:15360, vCores:12>usedCapacity=0.3125, absoluteUsedCapacity=0.3125, numApps=4, numContainers=12
2013-08-31 00:26:22,603 INFO org.apache.hadoop.yarn.server.resourcemanager.scheduler.capacity.ParentQueue: assignedContainer queue=root usedCapacity=0.3125 absoluteUsedCapacity=0.3125 used=<memory:15360, vCores:12> cluster=<memory:49152, vCores:96>
2013-08-31 00:26:22,603 INFO org.apache.hadoop.yarn.server.resourcemanager.rmcontainer.RMContainerImpl: container_1377907764744_0007_01_000011 Container Transitioned from NEW to ALLOCATED
2013-08-31 00:26:22,603 INFO org.apache.hadoop.yarn.server.resourcemanager.RMAuditLogger: USER=ubuntu	OPERATION=AM Allocated Container	TARGET=SchedulerApp	RESULT=SUCCESS	APPID=application_1377907764744_0007	CONTAINERID=container_1377907764744_0007_01_000011
2013-08-31 00:26:22,603 INFO org.apache.hadoop.yarn.server.resourcemanager.scheduler.common.fica.FiCaSchedulerNode: Assigned container container_1377907764744_0007_01_000011 of capacity <memory:1024, vCores:1> on host hadoop-32-4:58137, which currently has 4 containers, <memory:4096, vCores:4> used and <memory:4096, vCores:12> available
2013-08-31 00:26:22,605 INFO org.apache.hadoop.yarn.server.resourcemanager.scheduler.capacity.LeafQueue: assignedContainer application=application_1377907764744_0007 container=Container: [ContainerId: container_1377907764744_0007_01_000011, NodeId: hadoop-32-4:58137, NodeHttpAddress: hadoop-32-4:8042, Resource: <memory:1024, vCores:1>, Priority: 20, State: NEW, Token: null, Status: container_id {, app_attempt_id {, application_id {, id: 7, cluster_timestamp: 1377907764744, }, attemptId: 1, }, id: 11, }, state: C_NEW, ] containerId=container_1377907764744_0007_01_000011 queue=default: capacity=1.0, absoluteCapacity=1.0, usedResources=<memory:15360, vCores:12>usedCapacity=0.3125, absoluteUsedCapacity=0.3125, numApps=4, numContainers=12 usedCapacity=0.3125 absoluteUsedCapacity=0.3125 used=<memory:15360, vCores:12> cluster=<memory:49152, vCores:96>
2013-08-31 00:26:22,605 INFO org.apache.hadoop.yarn.server.resourcemanager.scheduler.capacity.ParentQueue: Re-sorting queues since queue: root.default stats: default: capacity=1.0, absoluteCapacity=1.0, usedResources=<memory:16384, vCores:13>usedCapacity=0.33333334, absoluteUsedCapacity=0.33333334, numApps=4, numContainers=13
2013-08-31 00:26:22,605 INFO org.apache.hadoop.yarn.server.resourcemanager.scheduler.capacity.ParentQueue: assignedContainer queue=root usedCapacity=0.33333334 absoluteUsedCapacity=0.33333334 used=<memory:16384, vCores:13> cluster=<memory:49152, vCores:96>
2013-08-31 00:26:22,606 INFO org.apache.hadoop.yarn.server.resourcemanager.rmcontainer.RMContainerImpl: container_1377907764744_0007_01_000012 Container Transitioned from NEW to ALLOCATED
2013-08-31 00:26:22,606 INFO org.apache.hadoop.yarn.server.resourcemanager.RMAuditLogger: USER=ubuntu	OPERATION=AM Allocated Container	TARGET=SchedulerApp	RESULT=SUCCESS	APPID=application_1377907764744_0007	CONTAINERID=container_1377907764744_0007_01_000012
2013-08-31 00:26:22,606 INFO org.apache.hadoop.yarn.server.resourcemanager.scheduler.common.fica.FiCaSchedulerNode: Assigned container container_1377907764744_0007_01_000012 of capacity <memory:1024, vCores:1> on host hadoop-32-4:58137, which currently has 5 containers, <memory:5120, vCores:5> used and <memory:3072, vCores:11> available
2013-08-31 00:26:22,607 INFO org.apache.hadoop.yarn.server.resourcemanager.scheduler.capacity.LeafQueue: assignedContainer application=application_1377907764744_0007 container=Container: [ContainerId: container_1377907764744_0007_01_000012, NodeId: hadoop-32-4:58137, NodeHttpAddress: hadoop-32-4:8042, Resource: <memory:1024, vCores:1>, Priority: 20, State: NEW, Token: null, Status: container_id {, app_attempt_id {, application_id {, id: 7, cluster_timestamp: 1377907764744, }, attemptId: 1, }, id: 12, }, state: C_NEW, ] containerId=container_1377907764744_0007_01_000012 queue=default: capacity=1.0, absoluteCapacity=1.0, usedResources=<memory:16384, vCores:13>usedCapacity=0.33333334, absoluteUsedCapacity=0.33333334, numApps=4, numContainers=13 usedCapacity=0.33333334 absoluteUsedCapacity=0.33333334 used=<memory:16384, vCores:13> cluster=<memory:49152, vCores:96>
2013-08-31 00:26:22,607 INFO org.apache.hadoop.yarn.server.resourcemanager.scheduler.capacity.ParentQueue: Re-sorting queues since queue: root.default stats: default: capacity=1.0, absoluteCapacity=1.0, usedResources=<memory:17408, vCores:14>usedCapacity=0.35416666, absoluteUsedCapacity=0.35416666, numApps=4, numContainers=14
2013-08-31 00:26:22,607 INFO org.apache.hadoop.yarn.server.resourcemanager.scheduler.capacity.ParentQueue: assignedContainer queue=root usedCapacity=0.35416666 absoluteUsedCapacity=0.35416666 used=<memory:17408, vCores:14> cluster=<memory:49152, vCores:96>
2013-08-31 00:26:22,608 INFO org.apache.hadoop.yarn.server.resourcemanager.rmcontainer.RMContainerImpl: container_1377907764744_0007_01_000013 Container Transitioned from NEW to ALLOCATED
2013-08-31 00:26:22,608 INFO org.apache.hadoop.yarn.server.resourcemanager.RMAuditLogger: USER=ubuntu	OPERATION=AM Allocated Container	TARGET=SchedulerApp	RESULT=SUCCESS	APPID=application_1377907764744_0007	CONTAINERID=container_1377907764744_0007_01_000013
2013-08-31 00:26:22,608 INFO org.apache.hadoop.yarn.server.resourcemanager.scheduler.common.fica.FiCaSchedulerNode: Assigned container container_1377907764744_0007_01_000013 of capacity <memory:1024, vCores:1> on host hadoop-32-4:58137, which currently has 6 containers, <memory:6144, vCores:6> used and <memory:2048, vCores:10> available
2013-08-31 00:26:22,609 INFO org.apache.hadoop.yarn.server.resourcemanager.scheduler.capacity.LeafQueue: assignedContainer application=application_1377907764744_0007 container=Container: [ContainerId: container_1377907764744_0007_01_000013, NodeId: hadoop-32-4:58137, NodeHttpAddress: hadoop-32-4:8042, Resource: <memory:1024, vCores:1>, Priority: 20, State: NEW, Token: null, Status: container_id {, app_attempt_id {, application_id {, id: 7, cluster_timestamp: 1377907764744, }, attemptId: 1, }, id: 13, }, state: C_NEW, ] containerId=container_1377907764744_0007_01_000013 queue=default: capacity=1.0, absoluteCapacity=1.0, usedResources=<memory:17408, vCores:14>usedCapacity=0.35416666, absoluteUsedCapacity=0.35416666, numApps=4, numContainers=14 usedCapacity=0.35416666 absoluteUsedCapacity=0.35416666 used=<memory:17408, vCores:14> cluster=<memory:49152, vCores:96>
2013-08-31 00:26:22,610 INFO org.apache.hadoop.yarn.server.resourcemanager.scheduler.capacity.ParentQueue: Re-sorting queues since queue: root.default stats: default: capacity=1.0, absoluteCapacity=1.0, usedResources=<memory:18432, vCores:15>usedCapacity=0.375, absoluteUsedCapacity=0.375, numApps=4, numContainers=15
2013-08-31 00:26:22,610 INFO org.apache.hadoop.yarn.server.resourcemanager.scheduler.capacity.ParentQueue: assignedContainer queue=root usedCapacity=0.375 absoluteUsedCapacity=0.375 used=<memory:18432, vCores:15> cluster=<memory:49152, vCores:96>
2013-08-31 00:26:22,610 INFO org.apache.hadoop.yarn.server.resourcemanager.rmcontainer.RMContainerImpl: container_1377907764744_0007_01_000014 Container Transitioned from NEW to ALLOCATED
2013-08-31 00:26:22,610 INFO org.apache.hadoop.yarn.server.resourcemanager.RMAuditLogger: USER=ubuntu	OPERATION=AM Allocated Container	TARGET=SchedulerApp	RESULT=SUCCESS	APPID=application_1377907764744_0007	CONTAINERID=container_1377907764744_0007_01_000014
2013-08-31 00:26:22,611 INFO org.apache.hadoop.yarn.server.resourcemanager.scheduler.common.fica.FiCaSchedulerNode: Assigned container container_1377907764744_0007_01_000014 of capacity <memory:1024, vCores:1> on host hadoop-32-4:58137, which currently has 7 containers, <memory:7168, vCores:7> used and <memory:1024, vCores:9> available
2013-08-31 00:26:22,611 INFO org.apache.hadoop.yarn.server.resourcemanager.scheduler.capacity.LeafQueue: assignedContainer application=application_1377907764744_0007 container=Container: [ContainerId: container_1377907764744_0007_01_000014, NodeId: hadoop-32-4:58137, NodeHttpAddress: hadoop-32-4:8042, Resource: <memory:1024, vCores:1>, Priority: 20, State: NEW, Token: null, Status: container_id {, app_attempt_id {, application_id {, id: 7, cluster_timestamp: 1377907764744, }, attemptId: 1, }, id: 14, }, state: C_NEW, ] containerId=container_1377907764744_0007_01_000014 queue=default: capacity=1.0, absoluteCapacity=1.0, usedResources=<memory:18432, vCores:15>usedCapacity=0.375, absoluteUsedCapacity=0.375, numApps=4, numContainers=15 usedCapacity=0.375 absoluteUsedCapacity=0.375 used=<memory:18432, vCores:15> cluster=<memory:49152, vCores:96>
2013-08-31 00:26:22,612 INFO org.apache.hadoop.yarn.server.resourcemanager.scheduler.capacity.ParentQueue: Re-sorting queues since queue: root.default stats: default: capacity=1.0, absoluteCapacity=1.0, usedResources=<memory:19456, vCores:16>usedCapacity=0.39583334, absoluteUsedCapacity=0.39583334, numApps=4, numContainers=16
2013-08-31 00:26:22,612 INFO org.apache.hadoop.yarn.server.resourcemanager.scheduler.capacity.ParentQueue: assignedContainer queue=root usedCapacity=0.39583334 absoluteUsedCapacity=0.39583334 used=<memory:19456, vCores:16> cluster=<memory:49152, vCores:96>
2013-08-31 00:26:22,613 INFO org.apache.hadoop.yarn.server.resourcemanager.rmcontainer.RMContainerImpl: container_1377907764744_0007_01_000015 Container Transitioned from NEW to ALLOCATED
2013-08-31 00:26:22,613 INFO org.apache.hadoop.yarn.server.resourcemanager.RMAuditLogger: USER=ubuntu	OPERATION=AM Allocated Container	TARGET=SchedulerApp	RESULT=SUCCESS	APPID=application_1377907764744_0007	CONTAINERID=container_1377907764744_0007_01_000015
2013-08-31 00:26:22,613 INFO org.apache.hadoop.yarn.server.resourcemanager.scheduler.common.fica.FiCaSchedulerNode: Assigned container container_1377907764744_0007_01_000015 of capacity <memory:1024, vCores:1> on host hadoop-32-4:58137, which currently has 8 containers, <memory:8192, vCores:8> used and <memory:0, vCores:8> available
2013-08-31 00:26:22,614 INFO org.apache.hadoop.yarn.server.resourcemanager.scheduler.capacity.LeafQueue: assignedContainer application=application_1377907764744_0007 container=Container: [ContainerId: container_1377907764744_0007_01_000015, NodeId: hadoop-32-4:58137, NodeHttpAddress: hadoop-32-4:8042, Resource: <memory:1024, vCores:1>, Priority: 20, State: NEW, Token: null, Status: container_id {, app_attempt_id {, application_id {, id: 7, cluster_timestamp: 1377907764744, }, attemptId: 1, }, id: 15, }, state: C_NEW, ] containerId=container_1377907764744_0007_01_000015 queue=default: capacity=1.0, absoluteCapacity=1.0, usedResources=<memory:19456, vCores:16>usedCapacity=0.39583334, absoluteUsedCapacity=0.39583334, numApps=4, numContainers=16 usedCapacity=0.39583334 absoluteUsedCapacity=0.39583334 used=<memory:19456, vCores:16> cluster=<memory:49152, vCores:96>
2013-08-31 00:26:22,614 INFO org.apache.hadoop.yarn.server.resourcemanager.scheduler.capacity.ParentQueue: Re-sorting queues since queue: root.default stats: default: capacity=1.0, absoluteCapacity=1.0, usedResources=<memory:20480, vCores:17>usedCapacity=0.41666666, absoluteUsedCapacity=0.41666666, numApps=4, numContainers=17
2013-08-31 00:26:22,614 INFO org.apache.hadoop.yarn.server.resourcemanager.scheduler.capacity.ParentQueue: assignedContainer queue=root usedCapacity=0.41666666 absoluteUsedCapacity=0.41666666 used=<memory:20480, vCores:17> cluster=<memory:49152, vCores:96>
2013-08-31 00:26:22,615 INFO org.apache.hadoop.yarn.server.resourcemanager.rmcontainer.RMContainerImpl: container_1377907764744_0007_01_000016 Container Transitioned from NEW to ALLOCATED
2013-08-31 00:26:22,615 INFO org.apache.hadoop.yarn.server.resourcemanager.RMAuditLogger: USER=ubuntu	OPERATION=AM Allocated Container	TARGET=SchedulerApp	RESULT=SUCCESS	APPID=application_1377907764744_0007	CONTAINERID=container_1377907764744_0007_01_000016
2013-08-31 00:26:22,615 INFO org.apache.hadoop.yarn.server.resourcemanager.scheduler.common.fica.FiCaSchedulerNode: Assigned container container_1377907764744_0007_01_000016 of capacity <memory:1024, vCores:1> on host hadoop-32-5:54799, which currently has 2 containers, <memory:3072, vCores:2> used and <memory:5120, vCores:14> available
2013-08-31 00:26:22,616 INFO org.apache.hadoop.yarn.server.resourcemanager.scheduler.capacity.LeafQueue: assignedContainer application=application_1377907764744_0007 container=Container: [ContainerId: container_1377907764744_0007_01_000016, NodeId: hadoop-32-5:54799, NodeHttpAddress: hadoop-32-5:8042, Resource: <memory:1024, vCores:1>, Priority: 20, State: NEW, Token: null, Status: container_id {, app_attempt_id {, application_id {, id: 7, cluster_timestamp: 1377907764744, }, attemptId: 1, }, id: 16, }, state: C_NEW, ] containerId=container_1377907764744_0007_01_000016 queue=default: capacity=1.0, absoluteCapacity=1.0, usedResources=<memory:20480, vCores:17>usedCapacity=0.41666666, absoluteUsedCapacity=0.41666666, numApps=4, numContainers=17 usedCapacity=0.41666666 absoluteUsedCapacity=0.41666666 used=<memory:20480, vCores:17> cluster=<memory:49152, vCores:96>
2013-08-31 00:26:22,616 INFO org.apache.hadoop.yarn.server.resourcemanager.scheduler.capacity.ParentQueue: Re-sorting queues since queue: root.default stats: default: capacity=1.0, absoluteCapacity=1.0, usedResources=<memory:21504, vCores:18>usedCapacity=0.4375, absoluteUsedCapacity=0.4375, numApps=4, numContainers=18
2013-08-31 00:26:22,616 INFO org.apache.hadoop.yarn.server.resourcemanager.scheduler.capacity.ParentQueue: assignedContainer queue=root usedCapacity=0.4375 absoluteUsedCapacity=0.4375 used=<memory:21504, vCores:18> cluster=<memory:49152, vCores:96>
2013-08-31 00:26:22,617 INFO org.apache.hadoop.yarn.server.resourcemanager.rmcontainer.RMContainerImpl: container_1377907764744_0007_01_000017 Container Transitioned from NEW to ALLOCATED
2013-08-31 00:26:22,617 INFO org.apache.hadoop.yarn.server.resourcemanager.RMAuditLogger: USER=ubuntu	OPERATION=AM Allocated Container	TARGET=SchedulerApp	RESULT=SUCCESS	APPID=application_1377907764744_0007	CONTAINERID=container_1377907764744_0007_01_000017
2013-08-31 00:26:22,617 INFO org.apache.hadoop.yarn.server.resourcemanager.scheduler.common.fica.FiCaSchedulerNode: Assigned container container_1377907764744_0007_01_000017 of capacity <memory:1024, vCores:1> on host hadoop-32-5:54799, which currently has 3 containers, <memory:4096, vCores:3> used and <memory:4096, vCores:13> available
2013-08-31 00:26:22,618 INFO org.apache.hadoop.yarn.server.resourcemanager.scheduler.capacity.LeafQueue: assignedContainer application=application_1377907764744_0007 container=Container: [ContainerId: container_1377907764744_0007_01_000017, NodeId: hadoop-32-5:54799, NodeHttpAddress: hadoop-32-5:8042, Resource: <memory:1024, vCores:1>, Priority: 20, State: NEW, Token: null, Status: container_id {, app_attempt_id {, application_id {, id: 7, cluster_timestamp: 1377907764744, }, attemptId: 1, }, id: 17, }, state: C_NEW, ] containerId=container_1377907764744_0007_01_000017 queue=default: capacity=1.0, absoluteCapacity=1.0, usedResources=<memory:21504, vCores:18>usedCapacity=0.4375, absoluteUsedCapacity=0.4375, numApps=4, numContainers=18 usedCapacity=0.4375 absoluteUsedCapacity=0.4375 used=<memory:21504, vCores:18> cluster=<memory:49152, vCores:96>
2013-08-31 00:26:22,618 INFO org.apache.hadoop.yarn.server.resourcemanager.scheduler.capacity.ParentQueue: Re-sorting queues since queue: root.default stats: default: capacity=1.0, absoluteCapacity=1.0, usedResources=<memory:22528, vCores:19>usedCapacity=0.45833334, absoluteUsedCapacity=0.45833334, numApps=4, numContainers=19
2013-08-31 00:26:22,619 INFO org.apache.hadoop.yarn.server.resourcemanager.scheduler.capacity.ParentQueue: assignedContainer queue=root usedCapacity=0.45833334 absoluteUsedCapacity=0.45833334 used=<memory:22528, vCores:19> cluster=<memory:49152, vCores:96>
2013-08-31 00:26:22,619 INFO org.apache.hadoop.yarn.server.resourcemanager.rmcontainer.RMContainerImpl: container_1377907764744_0007_01_000018 Container Transitioned from NEW to ALLOCATED
2013-08-31 00:26:22,619 INFO org.apache.hadoop.yarn.server.resourcemanager.RMAuditLogger: USER=ubuntu	OPERATION=AM Allocated Container	TARGET=SchedulerApp	RESULT=SUCCESS	APPID=application_1377907764744_0007	CONTAINERID=container_1377907764744_0007_01_000018
2013-08-31 00:26:22,619 INFO org.apache.hadoop.yarn.server.resourcemanager.scheduler.common.fica.FiCaSchedulerNode: Assigned container container_1377907764744_0007_01_000018 of capacity <memory:1024, vCores:1> on host hadoop-32-5:54799, which currently has 4 containers, <memory:5120, vCores:4> used and <memory:3072, vCores:12> available
2013-08-31 00:26:22,620 INFO org.apache.hadoop.yarn.server.resourcemanager.scheduler.capacity.LeafQueue: assignedContainer application=application_1377907764744_0007 container=Container: [ContainerId: container_1377907764744_0007_01_000018, NodeId: hadoop-32-5:54799, NodeHttpAddress: hadoop-32-5:8042, Resource: <memory:1024, vCores:1>, Priority: 20, State: NEW, Token: null, Status: container_id {, app_attempt_id {, application_id {, id: 7, cluster_timestamp: 1377907764744, }, attemptId: 1, }, id: 18, }, state: C_NEW, ] containerId=container_1377907764744_0007_01_000018 queue=default: capacity=1.0, absoluteCapacity=1.0, usedResources=<memory:22528, vCores:19>usedCapacity=0.45833334, absoluteUsedCapacity=0.45833334, numApps=4, numContainers=19 usedCapacity=0.45833334 absoluteUsedCapacity=0.45833334 used=<memory:22528, vCores:19> cluster=<memory:49152, vCores:96>
2013-08-31 00:26:22,621 INFO org.apache.hadoop.yarn.server.resourcemanager.scheduler.capacity.ParentQueue: Re-sorting queues since queue: root.default stats: default: capacity=1.0, absoluteCapacity=1.0, usedResources=<memory:23552, vCores:20>usedCapacity=0.47916666, absoluteUsedCapacity=0.47916666, numApps=4, numContainers=20
2013-08-31 00:26:22,621 INFO org.apache.hadoop.yarn.server.resourcemanager.scheduler.capacity.ParentQueue: assignedContainer queue=root usedCapacity=0.47916666 absoluteUsedCapacity=0.47916666 used=<memory:23552, vCores:20> cluster=<memory:49152, vCores:96>
2013-08-31 00:26:22,621 INFO org.apache.hadoop.yarn.server.resourcemanager.rmcontainer.RMContainerImpl: container_1377907764744_0007_01_000019 Container Transitioned from NEW to ALLOCATED
2013-08-31 00:26:22,621 INFO org.apache.hadoop.yarn.server.resourcemanager.RMAuditLogger: USER=ubuntu	OPERATION=AM Allocated Container	TARGET=SchedulerApp	RESULT=SUCCESS	APPID=application_1377907764744_0007	CONTAINERID=container_1377907764744_0007_01_000019
2013-08-31 00:26:22,622 INFO org.apache.hadoop.yarn.server.resourcemanager.scheduler.common.fica.FiCaSchedulerNode: Assigned container container_1377907764744_0007_01_000019 of capacity <memory:1024, vCores:1> on host hadoop-32-5:54799, which currently has 5 containers, <memory:6144, vCores:5> used and <memory:2048, vCores:11> available
2013-08-31 00:26:22,623 INFO org.apache.hadoop.yarn.server.resourcemanager.scheduler.capacity.LeafQueue: assignedContainer application=application_1377907764744_0007 container=Container: [ContainerId: container_1377907764744_0007_01_000019, NodeId: hadoop-32-5:54799, NodeHttpAddress: hadoop-32-5:8042, Resource: <memory:1024, vCores:1>, Priority: 20, State: NEW, Token: null, Status: container_id {, app_attempt_id {, application_id {, id: 7, cluster_timestamp: 1377907764744, }, attemptId: 1, }, id: 19, }, state: C_NEW, ] containerId=container_1377907764744_0007_01_000019 queue=default: capacity=1.0, absoluteCapacity=1.0, usedResources=<memory:23552, vCores:20>usedCapacity=0.47916666, absoluteUsedCapacity=0.47916666, numApps=4, numContainers=20 usedCapacity=0.47916666 absoluteUsedCapacity=0.47916666 used=<memory:23552, vCores:20> cluster=<memory:49152, vCores:96>
2013-08-31 00:26:22,623 INFO org.apache.hadoop.yarn.server.resourcemanager.scheduler.capacity.ParentQueue: Re-sorting queues since queue: root.default stats: default: capacity=1.0, absoluteCapacity=1.0, usedResources=<memory:24576, vCores:21>usedCapacity=0.5, absoluteUsedCapacity=0.5, numApps=4, numContainers=21
2013-08-31 00:26:22,623 INFO org.apache.hadoop.yarn.server.resourcemanager.scheduler.capacity.ParentQueue: assignedContainer queue=root usedCapacity=0.5 absoluteUsedCapacity=0.5 used=<memory:24576, vCores:21> cluster=<memory:49152, vCores:96>
2013-08-31 00:26:22,624 INFO org.apache.hadoop.yarn.server.resourcemanager.rmcontainer.RMContainerImpl: container_1377907764744_0007_01_000020 Container Transitioned from NEW to ALLOCATED
2013-08-31 00:26:22,624 INFO org.apache.hadoop.yarn.server.resourcemanager.RMAuditLogger: USER=ubuntu	OPERATION=AM Allocated Container	TARGET=SchedulerApp	RESULT=SUCCESS	APPID=application_1377907764744_0007	CONTAINERID=container_1377907764744_0007_01_000020
2013-08-31 00:26:22,624 INFO org.apache.hadoop.yarn.server.resourcemanager.scheduler.common.fica.FiCaSchedulerNode: Assigned container container_1377907764744_0007_01_000020 of capacity <memory:1024, vCores:1> on host hadoop-32-5:54799, which currently has 6 containers, <memory:7168, vCores:6> used and <memory:1024, vCores:10> available
2013-08-31 00:26:22,625 INFO org.apache.hadoop.yarn.server.resourcemanager.scheduler.capacity.LeafQueue: assignedContainer application=application_1377907764744_0007 container=Container: [ContainerId: container_1377907764744_0007_01_000020, NodeId: hadoop-32-5:54799, NodeHttpAddress: hadoop-32-5:8042, Resource: <memory:1024, vCores:1>, Priority: 20, State: NEW, Token: null, Status: container_id {, app_attempt_id {, application_id {, id: 7, cluster_timestamp: 1377907764744, }, attemptId: 1, }, id: 20, }, state: C_NEW, ] containerId=container_1377907764744_0007_01_000020 queue=default: capacity=1.0, absoluteCapacity=1.0, usedResources=<memory:24576, vCores:21>usedCapacity=0.5, absoluteUsedCapacity=0.5, numApps=4, numContainers=21 usedCapacity=0.5 absoluteUsedCapacity=0.5 used=<memory:24576, vCores:21> cluster=<memory:49152, vCores:96>
2013-08-31 00:26:22,625 INFO org.apache.hadoop.yarn.server.resourcemanager.scheduler.capacity.ParentQueue: Re-sorting queues since queue: root.default stats: default: capacity=1.0, absoluteCapacity=1.0, usedResources=<memory:25600, vCores:22>usedCapacity=0.5208333, absoluteUsedCapacity=0.5208333, numApps=4, numContainers=22
2013-08-31 00:26:22,625 INFO org.apache.hadoop.yarn.server.resourcemanager.scheduler.capacity.ParentQueue: assignedContainer queue=root usedCapacity=0.5208333 absoluteUsedCapacity=0.5208333 used=<memory:25600, vCores:22> cluster=<memory:49152, vCores:96>
2013-08-31 00:26:22,626 INFO org.apache.hadoop.yarn.server.resourcemanager.rmcontainer.RMContainerImpl: container_1377907764744_0007_01_000021 Container Transitioned from NEW to ALLOCATED
2013-08-31 00:26:22,626 INFO org.apache.hadoop.yarn.server.resourcemanager.RMAuditLogger: USER=ubuntu	OPERATION=AM Allocated Container	TARGET=SchedulerApp	RESULT=SUCCESS	APPID=application_1377907764744_0007	CONTAINERID=container_1377907764744_0007_01_000021
2013-08-31 00:26:22,626 INFO org.apache.hadoop.yarn.server.resourcemanager.scheduler.common.fica.FiCaSchedulerNode: Assigned container container_1377907764744_0007_01_000021 of capacity <memory:1024, vCores:1> on host hadoop-32-5:54799, which currently has 7 containers, <memory:8192, vCores:7> used and <memory:0, vCores:9> available
2013-08-31 00:26:22,627 INFO org.apache.hadoop.yarn.server.resourcemanager.scheduler.capacity.LeafQueue: assignedContainer application=application_1377907764744_0007 container=Container: [ContainerId: container_1377907764744_0007_01_000021, NodeId: hadoop-32-5:54799, NodeHttpAddress: hadoop-32-5:8042, Resource: <memory:1024, vCores:1>, Priority: 20, State: NEW, Token: null, Status: container_id {, app_attempt_id {, application_id {, id: 7, cluster_timestamp: 1377907764744, }, attemptId: 1, }, id: 21, }, state: C_NEW, ] containerId=container_1377907764744_0007_01_000021 queue=default: capacity=1.0, absoluteCapacity=1.0, usedResources=<memory:25600, vCores:22>usedCapacity=0.5208333, absoluteUsedCapacity=0.5208333, numApps=4, numContainers=22 usedCapacity=0.5208333 absoluteUsedCapacity=0.5208333 used=<memory:25600, vCores:22> cluster=<memory:49152, vCores:96>
2013-08-31 00:26:22,627 INFO org.apache.hadoop.yarn.server.resourcemanager.scheduler.capacity.ParentQueue: Re-sorting queues since queue: root.default stats: default: capacity=1.0, absoluteCapacity=1.0, usedResources=<memory:26624, vCores:23>usedCapacity=0.5416667, absoluteUsedCapacity=0.5416667, numApps=4, numContainers=23
2013-08-31 00:26:22,627 INFO org.apache.hadoop.yarn.server.resourcemanager.scheduler.capacity.ParentQueue: assignedContainer queue=root usedCapacity=0.5416667 absoluteUsedCapacity=0.5416667 used=<memory:26624, vCores:23> cluster=<memory:49152, vCores:96>
2013-08-31 00:26:22,628 INFO org.apache.hadoop.yarn.server.resourcemanager.rmcontainer.RMContainerImpl: container_1377907764744_0007_01_000022 Container Transitioned from NEW to ALLOCATED
2013-08-31 00:26:22,628 INFO org.apache.hadoop.yarn.server.resourcemanager.RMAuditLogger: USER=ubuntu	OPERATION=AM Allocated Container	TARGET=SchedulerApp	RESULT=SUCCESS	APPID=application_1377907764744_0007	CONTAINERID=container_1377907764744_0007_01_000022
2013-08-31 00:26:22,628 INFO org.apache.hadoop.yarn.server.resourcemanager.scheduler.common.fica.FiCaSchedulerNode: Assigned container container_1377907764744_0007_01_000022 of capacity <memory:1024, vCores:1> on host hadoop-32-3:33603, which currently has 1 containers, <memory:1024, vCores:1> used and <memory:7168, vCores:15> available
2013-08-31 00:26:22,629 INFO org.apache.hadoop.yarn.server.resourcemanager.scheduler.capacity.LeafQueue: assignedContainer application=application_1377907764744_0007 container=Container: [ContainerId: container_1377907764744_0007_01_000022, NodeId: hadoop-32-3:33603, NodeHttpAddress: hadoop-32-3:8042, Resource: <memory:1024, vCores:1>, Priority: 20, State: NEW, Token: null, Status: container_id {, app_attempt_id {, application_id {, id: 7, cluster_timestamp: 1377907764744, }, attemptId: 1, }, id: 22, }, state: C_NEW, ] containerId=container_1377907764744_0007_01_000022 queue=default: capacity=1.0, absoluteCapacity=1.0, usedResources=<memory:26624, vCores:23>usedCapacity=0.5416667, absoluteUsedCapacity=0.5416667, numApps=4, numContainers=23 usedCapacity=0.5416667 absoluteUsedCapacity=0.5416667 used=<memory:26624, vCores:23> cluster=<memory:49152, vCores:96>
2013-08-31 00:26:22,630 INFO org.apache.hadoop.yarn.server.resourcemanager.scheduler.capacity.ParentQueue: Re-sorting queues since queue: root.default stats: default: capacity=1.0, absoluteCapacity=1.0, usedResources=<memory:27648, vCores:24>usedCapacity=0.5625, absoluteUsedCapacity=0.5625, numApps=4, numContainers=24
2013-08-31 00:26:22,630 INFO org.apache.hadoop.yarn.server.resourcemanager.scheduler.capacity.ParentQueue: assignedContainer queue=root usedCapacity=0.5625 absoluteUsedCapacity=0.5625 used=<memory:27648, vCores:24> cluster=<memory:49152, vCores:96>
2013-08-31 00:26:22,630 INFO org.apache.hadoop.yarn.server.resourcemanager.rmcontainer.RMContainerImpl: container_1377907764744_0007_01_000023 Container Transitioned from NEW to ALLOCATED
2013-08-31 00:26:22,630 INFO org.apache.hadoop.yarn.server.resourcemanager.RMAuditLogger: USER=ubuntu	OPERATION=AM Allocated Container	TARGET=SchedulerApp	RESULT=SUCCESS	APPID=application_1377907764744_0007	CONTAINERID=container_1377907764744_0007_01_000023
2013-08-31 00:26:22,630 INFO org.apache.hadoop.yarn.server.resourcemanager.scheduler.common.fica.FiCaSchedulerNode: Assigned container container_1377907764744_0007_01_000023 of capacity <memory:1024, vCores:1> on host hadoop-32-3:33603, which currently has 2 containers, <memory:2048, vCores:2> used and <memory:6144, vCores:14> available
2013-08-31 00:26:22,631 INFO org.apache.hadoop.yarn.server.resourcemanager.scheduler.capacity.LeafQueue: assignedContainer application=application_1377907764744_0007 container=Container: [ContainerId: container_1377907764744_0007_01_000023, NodeId: hadoop-32-3:33603, NodeHttpAddress: hadoop-32-3:8042, Resource: <memory:1024, vCores:1>, Priority: 20, State: NEW, Token: null, Status: container_id {, app_attempt_id {, application_id {, id: 7, cluster_timestamp: 1377907764744, }, attemptId: 1, }, id: 23, }, state: C_NEW, ] containerId=container_1377907764744_0007_01_000023 queue=default: capacity=1.0, absoluteCapacity=1.0, usedResources=<memory:27648, vCores:24>usedCapacity=0.5625, absoluteUsedCapacity=0.5625, numApps=4, numContainers=24 usedCapacity=0.5625 absoluteUsedCapacity=0.5625 used=<memory:27648, vCores:24> cluster=<memory:49152, vCores:96>
2013-08-31 00:26:22,632 INFO org.apache.hadoop.yarn.server.resourcemanager.scheduler.capacity.ParentQueue: Re-sorting queues since queue: root.default stats: default: capacity=1.0, absoluteCapacity=1.0, usedResources=<memory:28672, vCores:25>usedCapacity=0.5833333, absoluteUsedCapacity=0.5833333, numApps=4, numContainers=25
2013-08-31 00:26:22,632 INFO org.apache.hadoop.yarn.server.resourcemanager.scheduler.capacity.ParentQueue: assignedContainer queue=root usedCapacity=0.5833333 absoluteUsedCapacity=0.5833333 used=<memory:28672, vCores:25> cluster=<memory:49152, vCores:96>
2013-08-31 00:26:22,632 INFO org.apache.hadoop.yarn.server.resourcemanager.rmcontainer.RMContainerImpl: container_1377907764744_0007_01_000024 Container Transitioned from NEW to ALLOCATED
2013-08-31 00:26:22,633 INFO org.apache.hadoop.yarn.server.resourcemanager.RMAuditLogger: USER=ubuntu	OPERATION=AM Allocated Container	TARGET=SchedulerApp	RESULT=SUCCESS	APPID=application_1377907764744_0007	CONTAINERID=container_1377907764744_0007_01_000024
2013-08-31 00:26:22,633 INFO org.apache.hadoop.yarn.server.resourcemanager.scheduler.common.fica.FiCaSchedulerNode: Assigned container container_1377907764744_0007_01_000024 of capacity <memory:1024, vCores:1> on host hadoop-32-3:33603, which currently has 3 containers, <memory:3072, vCores:3> used and <memory:5120, vCores:13> available
2013-08-31 00:26:22,634 INFO org.apache.hadoop.yarn.server.resourcemanager.scheduler.capacity.LeafQueue: assignedContainer application=application_1377907764744_0007 container=Container: [ContainerId: container_1377907764744_0007_01_000024, NodeId: hadoop-32-3:33603, NodeHttpAddress: hadoop-32-3:8042, Resource: <memory:1024, vCores:1>, Priority: 20, State: NEW, Token: null, Status: container_id {, app_attempt_id {, application_id {, id: 7, cluster_timestamp: 1377907764744, }, attemptId: 1, }, id: 24, }, state: C_NEW, ] containerId=container_1377907764744_0007_01_000024 queue=default: capacity=1.0, absoluteCapacity=1.0, usedResources=<memory:28672, vCores:25>usedCapacity=0.5833333, absoluteUsedCapacity=0.5833333, numApps=4, numContainers=25 usedCapacity=0.5833333 absoluteUsedCapacity=0.5833333 used=<memory:28672, vCores:25> cluster=<memory:49152, vCores:96>
2013-08-31 00:26:22,634 INFO org.apache.hadoop.yarn.server.resourcemanager.scheduler.capacity.ParentQueue: Re-sorting queues since queue: root.default stats: default: capacity=1.0, absoluteCapacity=1.0, usedResources=<memory:29696, vCores:26>usedCapacity=0.6041667, absoluteUsedCapacity=0.6041667, numApps=4, numContainers=26
2013-08-31 00:26:22,634 INFO org.apache.hadoop.yarn.server.resourcemanager.scheduler.capacity.ParentQueue: assignedContainer queue=root usedCapacity=0.6041667 absoluteUsedCapacity=0.6041667 used=<memory:29696, vCores:26> cluster=<memory:49152, vCores:96>
2013-08-31 00:26:22,635 INFO org.apache.hadoop.yarn.server.resourcemanager.rmcontainer.RMContainerImpl: container_1377907764744_0007_01_000025 Container Transitioned from NEW to ALLOCATED
2013-08-31 00:26:22,635 INFO org.apache.hadoop.yarn.server.resourcemanager.RMAuditLogger: USER=ubuntu	OPERATION=AM Allocated Container	TARGET=SchedulerApp	RESULT=SUCCESS	APPID=application_1377907764744_0007	CONTAINERID=container_1377907764744_0007_01_000025
2013-08-31 00:26:22,635 INFO org.apache.hadoop.yarn.server.resourcemanager.scheduler.common.fica.FiCaSchedulerNode: Assigned container container_1377907764744_0007_01_000025 of capacity <memory:1024, vCores:1> on host hadoop-32-3:33603, which currently has 4 containers, <memory:4096, vCores:4> used and <memory:4096, vCores:12> available
2013-08-31 00:26:22,636 INFO org.apache.hadoop.yarn.server.resourcemanager.scheduler.capacity.LeafQueue: assignedContainer application=application_1377907764744_0007 container=Container: [ContainerId: container_1377907764744_0007_01_000025, NodeId: hadoop-32-3:33603, NodeHttpAddress: hadoop-32-3:8042, Resource: <memory:1024, vCores:1>, Priority: 20, State: NEW, Token: null, Status: container_id {, app_attempt_id {, application_id {, id: 7, cluster_timestamp: 1377907764744, }, attemptId: 1, }, id: 25, }, state: C_NEW, ] containerId=container_1377907764744_0007_01_000025 queue=default: capacity=1.0, absoluteCapacity=1.0, usedResources=<memory:29696, vCores:26>usedCapacity=0.6041667, absoluteUsedCapacity=0.6041667, numApps=4, numContainers=26 usedCapacity=0.6041667 absoluteUsedCapacity=0.6041667 used=<memory:29696, vCores:26> cluster=<memory:49152, vCores:96>
2013-08-31 00:26:22,636 INFO org.apache.hadoop.yarn.server.resourcemanager.scheduler.capacity.ParentQueue: Re-sorting queues since queue: root.default stats: default: capacity=1.0, absoluteCapacity=1.0, usedResources=<memory:30720, vCores:27>usedCapacity=0.625, absoluteUsedCapacity=0.625, numApps=4, numContainers=27
2013-08-31 00:26:22,636 INFO org.apache.hadoop.yarn.server.resourcemanager.scheduler.capacity.ParentQueue: assignedContainer queue=root usedCapacity=0.625 absoluteUsedCapacity=0.625 used=<memory:30720, vCores:27> cluster=<memory:49152, vCores:96>
2013-08-31 00:26:22,637 INFO org.apache.hadoop.yarn.server.resourcemanager.rmcontainer.RMContainerImpl: container_1377907764744_0007_01_000026 Container Transitioned from NEW to ALLOCATED
2013-08-31 00:26:22,637 INFO org.apache.hadoop.yarn.server.resourcemanager.RMAuditLogger: USER=ubuntu	OPERATION=AM Allocated Container	TARGET=SchedulerApp	RESULT=SUCCESS	APPID=application_1377907764744_0007	CONTAINERID=container_1377907764744_0007_01_000026
2013-08-31 00:26:22,637 INFO org.apache.hadoop.yarn.server.resourcemanager.scheduler.common.fica.FiCaSchedulerNode: Assigned container container_1377907764744_0007_01_000026 of capacity <memory:1024, vCores:1> on host hadoop-32-3:33603, which currently has 5 containers, <memory:5120, vCores:5> used and <memory:3072, vCores:11> available
2013-08-31 00:26:22,638 INFO org.apache.hadoop.yarn.server.resourcemanager.scheduler.capacity.LeafQueue: assignedContainer application=application_1377907764744_0007 container=Container: [ContainerId: container_1377907764744_0007_01_000026, NodeId: hadoop-32-3:33603, NodeHttpAddress: hadoop-32-3:8042, Resource: <memory:1024, vCores:1>, Priority: 20, State: NEW, Token: null, Status: container_id {, app_attempt_id {, application_id {, id: 7, cluster_timestamp: 1377907764744, }, attemptId: 1, }, id: 26, }, state: C_NEW, ] containerId=container_1377907764744_0007_01_000026 queue=default: capacity=1.0, absoluteCapacity=1.0, usedResources=<memory:30720, vCores:27>usedCapacity=0.625, absoluteUsedCapacity=0.625, numApps=4, numContainers=27 usedCapacity=0.625 absoluteUsedCapacity=0.625 used=<memory:30720, vCores:27> cluster=<memory:49152, vCores:96>
2013-08-31 00:26:22,638 INFO org.apache.hadoop.yarn.server.resourcemanager.scheduler.capacity.ParentQueue: Re-sorting queues since queue: root.default stats: default: capacity=1.0, absoluteCapacity=1.0, usedResources=<memory:31744, vCores:28>usedCapacity=0.6458333, absoluteUsedCapacity=0.6458333, numApps=4, numContainers=28
2013-08-31 00:26:22,638 INFO org.apache.hadoop.yarn.server.resourcemanager.scheduler.capacity.ParentQueue: assignedContainer queue=root usedCapacity=0.6458333 absoluteUsedCapacity=0.6458333 used=<memory:31744, vCores:28> cluster=<memory:49152, vCores:96>
2013-08-31 00:26:22,639 INFO org.apache.hadoop.yarn.server.resourcemanager.rmcontainer.RMContainerImpl: container_1377907764744_0007_01_000027 Container Transitioned from NEW to ALLOCATED
2013-08-31 00:26:22,639 INFO org.apache.hadoop.yarn.server.resourcemanager.RMAuditLogger: USER=ubuntu	OPERATION=AM Allocated Container	TARGET=SchedulerApp	RESULT=SUCCESS	APPID=application_1377907764744_0007	CONTAINERID=container_1377907764744_0007_01_000027
2013-08-31 00:26:22,639 INFO org.apache.hadoop.yarn.server.resourcemanager.scheduler.common.fica.FiCaSchedulerNode: Assigned container container_1377907764744_0007_01_000027 of capacity <memory:1024, vCores:1> on host hadoop-32-3:33603, which currently has 6 containers, <memory:6144, vCores:6> used and <memory:2048, vCores:10> available
2013-08-31 00:26:22,640 INFO org.apache.hadoop.yarn.server.resourcemanager.scheduler.capacity.LeafQueue: assignedContainer application=application_1377907764744_0007 container=Container: [ContainerId: container_1377907764744_0007_01_000027, NodeId: hadoop-32-3:33603, NodeHttpAddress: hadoop-32-3:8042, Resource: <memory:1024, vCores:1>, Priority: 20, State: NEW, Token: null, Status: container_id {, app_attempt_id {, application_id {, id: 7, cluster_timestamp: 1377907764744, }, attemptId: 1, }, id: 27, }, state: C_NEW, ] containerId=container_1377907764744_0007_01_000027 queue=default: capacity=1.0, absoluteCapacity=1.0, usedResources=<memory:31744, vCores:28>usedCapacity=0.6458333, absoluteUsedCapacity=0.6458333, numApps=4, numContainers=28 usedCapacity=0.6458333 absoluteUsedCapacity=0.6458333 used=<memory:31744, vCores:28> cluster=<memory:49152, vCores:96>
2013-08-31 00:26:22,641 INFO org.apache.hadoop.yarn.server.resourcemanager.scheduler.capacity.ParentQueue: Re-sorting queues since queue: root.default stats: default: capacity=1.0, absoluteCapacity=1.0, usedResources=<memory:32768, vCores:29>usedCapacity=0.6666667, absoluteUsedCapacity=0.6666667, numApps=4, numContainers=29
2013-08-31 00:26:22,641 INFO org.apache.hadoop.yarn.server.resourcemanager.scheduler.capacity.ParentQueue: assignedContainer queue=root usedCapacity=0.6666667 absoluteUsedCapacity=0.6666667 used=<memory:32768, vCores:29> cluster=<memory:49152, vCores:96>
2013-08-31 00:26:22,641 INFO org.apache.hadoop.yarn.server.resourcemanager.rmcontainer.RMContainerImpl: container_1377907764744_0007_01_000028 Container Transitioned from NEW to ALLOCATED
2013-08-31 00:26:22,641 INFO org.apache.hadoop.yarn.server.resourcemanager.RMAuditLogger: USER=ubuntu	OPERATION=AM Allocated Container	TARGET=SchedulerApp	RESULT=SUCCESS	APPID=application_1377907764744_0007	CONTAINERID=container_1377907764744_0007_01_000028
2013-08-31 00:26:22,641 INFO org.apache.hadoop.yarn.server.resourcemanager.scheduler.common.fica.FiCaSchedulerNode: Assigned container container_1377907764744_0007_01_000028 of capacity <memory:1024, vCores:1> on host hadoop-32-3:33603, which currently has 7 containers, <memory:7168, vCores:7> used and <memory:1024, vCores:9> available
2013-08-31 00:26:22,642 INFO org.apache.hadoop.yarn.server.resourcemanager.scheduler.capacity.LeafQueue: assignedContainer application=application_1377907764744_0007 container=Container: [ContainerId: container_1377907764744_0007_01_000028, NodeId: hadoop-32-3:33603, NodeHttpAddress: hadoop-32-3:8042, Resource: <memory:1024, vCores:1>, Priority: 20, State: NEW, Token: null, Status: container_id {, app_attempt_id {, application_id {, id: 7, cluster_timestamp: 1377907764744, }, attemptId: 1, }, id: 28, }, state: C_NEW, ] containerId=container_1377907764744_0007_01_000028 queue=default: capacity=1.0, absoluteCapacity=1.0, usedResources=<memory:32768, vCores:29>usedCapacity=0.6666667, absoluteUsedCapacity=0.6666667, numApps=4, numContainers=29 usedCapacity=0.6666667 absoluteUsedCapacity=0.6666667 used=<memory:32768, vCores:29> cluster=<memory:49152, vCores:96>
2013-08-31 00:26:22,643 INFO org.apache.hadoop.yarn.server.resourcemanager.scheduler.capacity.ParentQueue: Re-sorting queues since queue: root.default stats: default: capacity=1.0, absoluteCapacity=1.0, usedResources=<memory:33792, vCores:30>usedCapacity=0.6875, absoluteUsedCapacity=0.6875, numApps=4, numContainers=30
2013-08-31 00:26:22,643 INFO org.apache.hadoop.yarn.server.resourcemanager.scheduler.capacity.ParentQueue: assignedContainer queue=root usedCapacity=0.6875 absoluteUsedCapacity=0.6875 used=<memory:33792, vCores:30> cluster=<memory:49152, vCores:96>
2013-08-31 00:26:22,643 INFO org.apache.hadoop.yarn.server.resourcemanager.rmcontainer.RMContainerImpl: container_1377907764744_0007_01_000029 Container Transitioned from NEW to ALLOCATED
2013-08-31 00:26:22,644 INFO org.apache.hadoop.yarn.server.resourcemanager.RMAuditLogger: USER=ubuntu	OPERATION=AM Allocated Container	TARGET=SchedulerApp	RESULT=SUCCESS	APPID=application_1377907764744_0007	CONTAINERID=container_1377907764744_0007_01_000029
2013-08-31 00:26:22,644 INFO org.apache.hadoop.yarn.server.resourcemanager.scheduler.common.fica.FiCaSchedulerNode: Assigned container container_1377907764744_0007_01_000029 of capacity <memory:1024, vCores:1> on host hadoop-32-3:33603, which currently has 8 containers, <memory:8192, vCores:8> used and <memory:0, vCores:8> available
2013-08-31 00:26:22,645 INFO org.apache.hadoop.yarn.server.resourcemanager.scheduler.capacity.LeafQueue: assignedContainer application=application_1377907764744_0007 container=Container: [ContainerId: container_1377907764744_0007_01_000029, NodeId: hadoop-32-3:33603, NodeHttpAddress: hadoop-32-3:8042, Resource: <memory:1024, vCores:1>, Priority: 20, State: NEW, Token: null, Status: container_id {, app_attempt_id {, application_id {, id: 7, cluster_timestamp: 1377907764744, }, attemptId: 1, }, id: 29, }, state: C_NEW, ] containerId=container_1377907764744_0007_01_000029 queue=default: capacity=1.0, absoluteCapacity=1.0, usedResources=<memory:33792, vCores:30>usedCapacity=0.6875, absoluteUsedCapacity=0.6875, numApps=4, numContainers=30 usedCapacity=0.6875 absoluteUsedCapacity=0.6875 used=<memory:33792, vCores:30> cluster=<memory:49152, vCores:96>
2013-08-31 00:26:22,645 INFO org.apache.hadoop.yarn.server.resourcemanager.scheduler.capacity.ParentQueue: Re-sorting queues since queue: root.default stats: default: capacity=1.0, absoluteCapacity=1.0, usedResources=<memory:34816, vCores:31>usedCapacity=0.7083333, absoluteUsedCapacity=0.7083333, numApps=4, numContainers=31
2013-08-31 00:26:22,645 INFO org.apache.hadoop.yarn.server.resourcemanager.scheduler.capacity.ParentQueue: assignedContainer queue=root usedCapacity=0.7083333 absoluteUsedCapacity=0.7083333 used=<memory:34816, vCores:31> cluster=<memory:49152, vCores:96>
2013-08-31 00:26:22,652 INFO org.apache.hadoop.yarn.server.resourcemanager.ApplicationMasterService: AM registration appattempt_1377907764744_0008_000001
2013-08-31 00:26:22,654 INFO org.apache.hadoop.yarn.server.resourcemanager.RMAuditLogger: USER=ubuntu	IP=192.168.100.11	OPERATION=Register App Master	TARGET=ApplicationMasterService	RESULT=SUCCESS	APPID=application_1377907764744_0008	APPATTEMPTID=appattempt_1377907764744_0008_000001
2013-08-31 00:26:22,657 INFO org.apache.hadoop.yarn.server.resourcemanager.rmapp.attempt.RMAppAttemptImpl: appattempt_1377907764744_0008_000001 State change from LAUNCHED to RUNNING
2013-08-31 00:26:22,657 INFO org.apache.hadoop.yarn.server.resourcemanager.rmapp.RMAppImpl: application_1377907764744_0008 State change from ACCEPTED to RUNNING
2013-08-31 00:26:22,916 INFO org.apache.hadoop.yarn.server.resourcemanager.ClientRMService: Storing Application with id application_1377907764744_0010
2013-08-31 00:26:22,917 INFO org.apache.hadoop.yarn.server.resourcemanager.recovery.RMStateStore: Storing info for app: application_1377907764744_0010
2013-08-31 00:26:22,917 INFO org.apache.hadoop.yarn.server.resourcemanager.ClientRMService: Application with id 10 submitted by user ubuntu
2013-08-31 00:26:22,917 INFO org.apache.hadoop.yarn.server.resourcemanager.RMAuditLogger: USER=ubuntu	IP=192.168.100.5	OPERATION=Submit Application Request	TARGET=ClientRMService	RESULT=SUCCESS	APPID=application_1377907764744_0010
2013-08-31 00:26:22,918 INFO org.apache.hadoop.yarn.server.resourcemanager.rmapp.RMAppImpl: application_1377907764744_0010 State change from NEW to SUBMITTED
2013-08-31 00:26:22,918 INFO org.apache.hadoop.yarn.server.resourcemanager.ApplicationMasterService: Registering appattempt_1377907764744_0010_000001
2013-08-31 00:26:22,918 INFO org.apache.hadoop.yarn.server.resourcemanager.rmapp.attempt.RMAppAttemptImpl: appattempt_1377907764744_0010_000001 State change from NEW to SUBMITTED
2013-08-31 00:26:22,919 INFO org.apache.hadoop.yarn.server.resourcemanager.scheduler.capacity.LeafQueue: Application application_1377907764744_0010 from user: ubuntu activated in queue: default
2013-08-31 00:26:22,919 INFO org.apache.hadoop.yarn.server.resourcemanager.scheduler.capacity.LeafQueue: Application added - appId: application_1377907764744_0010 user: org.apache.hadoop.yarn.server.resourcemanager.scheduler.capacity.LeafQueue$User@277b3c9b, leaf-queue: default #user-pending-applications: 0 #user-active-applications: 5 #queue-pending-applications: 0 #queue-active-applications: 5
2013-08-31 00:26:22,919 INFO org.apache.hadoop.yarn.server.resourcemanager.scheduler.capacity.ParentQueue: Application added - appId: application_1377907764744_0010 user: ubuntu leaf-queue of parent: root #applications: 5
2013-08-31 00:26:22,919 INFO org.apache.hadoop.yarn.server.resourcemanager.scheduler.capacity.CapacityScheduler: Application Submission: appattempt_1377907764744_0010_000001, user: ubuntu queue: default: capacity=1.0, absoluteCapacity=1.0, usedResources=<memory:34816, vCores:31>usedCapacity=0.7083333, absoluteUsedCapacity=0.7083333, numApps=5, numContainers=31, currently active: 5
2013-08-31 00:26:22,920 INFO org.apache.hadoop.yarn.server.resourcemanager.rmapp.attempt.RMAppAttemptImpl: appattempt_1377907764744_0010_000001 State change from SUBMITTED to SCHEDULED
2013-08-31 00:26:22,920 INFO org.apache.hadoop.yarn.server.resourcemanager.rmapp.RMAppImpl: application_1377907764744_0010 State change from SUBMITTED to ACCEPTED
2013-08-31 00:26:23,311 INFO org.apache.hadoop.yarn.server.resourcemanager.rmcontainer.RMContainerImpl: container_1377907764744_0006_01_000002 Container Transitioned from NEW to ALLOCATED
2013-08-31 00:26:23,311 INFO org.apache.hadoop.yarn.server.resourcemanager.RMAuditLogger: USER=ubuntu	OPERATION=AM Allocated Container	TARGET=SchedulerApp	RESULT=SUCCESS	APPID=application_1377907764744_0006	CONTAINERID=container_1377907764744_0006_01_000002
2013-08-31 00:26:23,311 INFO org.apache.hadoop.yarn.server.resourcemanager.scheduler.common.fica.FiCaSchedulerNode: Assigned container container_1377907764744_0006_01_000002 of capacity <memory:1024, vCores:1> on host hadoop-32-7:54070, which currently has 2 containers, <memory:3072, vCores:2> used and <memory:5120, vCores:14> available
2013-08-31 00:26:23,312 INFO org.apache.hadoop.yarn.server.resourcemanager.scheduler.capacity.LeafQueue: assignedContainer application=application_1377907764744_0006 container=Container: [ContainerId: container_1377907764744_0006_01_000002, NodeId: hadoop-32-7:54070, NodeHttpAddress: hadoop-32-7:8042, Resource: <memory:1024, vCores:1>, Priority: 20, State: NEW, Token: null, Status: container_id {, app_attempt_id {, application_id {, id: 6, cluster_timestamp: 1377907764744, }, attemptId: 1, }, id: 2, }, state: C_NEW, ] containerId=container_1377907764744_0006_01_000002 queue=default: capacity=1.0, absoluteCapacity=1.0, usedResources=<memory:34816, vCores:31>usedCapacity=0.7083333, absoluteUsedCapacity=0.7083333, numApps=5, numContainers=31 usedCapacity=0.7083333 absoluteUsedCapacity=0.7083333 used=<memory:34816, vCores:31> cluster=<memory:49152, vCores:96>
2013-08-31 00:26:23,312 INFO org.apache.hadoop.yarn.server.resourcemanager.scheduler.capacity.ParentQueue: Re-sorting queues since queue: root.default stats: default: capacity=1.0, absoluteCapacity=1.0, usedResources=<memory:35840, vCores:32>usedCapacity=0.7291667, absoluteUsedCapacity=0.7291667, numApps=5, numContainers=32
2013-08-31 00:26:23,313 INFO org.apache.hadoop.yarn.server.resourcemanager.scheduler.capacity.ParentQueue: assignedContainer queue=root usedCapacity=0.7291667 absoluteUsedCapacity=0.7291667 used=<memory:35840, vCores:32> cluster=<memory:49152, vCores:96>
2013-08-31 00:26:23,313 INFO org.apache.hadoop.yarn.server.resourcemanager.rmcontainer.RMContainerImpl: container_1377907764744_0006_01_000003 Container Transitioned from NEW to ALLOCATED
2013-08-31 00:26:23,313 INFO org.apache.hadoop.yarn.server.resourcemanager.RMAuditLogger: USER=ubuntu	OPERATION=AM Allocated Container	TARGET=SchedulerApp	RESULT=SUCCESS	APPID=application_1377907764744_0006	CONTAINERID=container_1377907764744_0006_01_000003
2013-08-31 00:26:23,313 INFO org.apache.hadoop.yarn.server.resourcemanager.scheduler.common.fica.FiCaSchedulerNode: Assigned container container_1377907764744_0006_01_000003 of capacity <memory:1024, vCores:1> on host hadoop-32-7:54070, which currently has 3 containers, <memory:4096, vCores:3> used and <memory:4096, vCores:13> available
2013-08-31 00:26:23,314 INFO org.apache.hadoop.yarn.server.resourcemanager.scheduler.capacity.LeafQueue: assignedContainer application=application_1377907764744_0006 container=Container: [ContainerId: container_1377907764744_0006_01_000003, NodeId: hadoop-32-7:54070, NodeHttpAddress: hadoop-32-7:8042, Resource: <memory:1024, vCores:1>, Priority: 20, State: NEW, Token: null, Status: container_id {, app_attempt_id {, application_id {, id: 6, cluster_timestamp: 1377907764744, }, attemptId: 1, }, id: 3, }, state: C_NEW, ] containerId=container_1377907764744_0006_01_000003 queue=default: capacity=1.0, absoluteCapacity=1.0, usedResources=<memory:35840, vCores:32>usedCapacity=0.7291667, absoluteUsedCapacity=0.7291667, numApps=5, numContainers=32 usedCapacity=0.7291667 absoluteUsedCapacity=0.7291667 used=<memory:35840, vCores:32> cluster=<memory:49152, vCores:96>
2013-08-31 00:26:23,315 INFO org.apache.hadoop.yarn.server.resourcemanager.scheduler.capacity.ParentQueue: Re-sorting queues since queue: root.default stats: default: capacity=1.0, absoluteCapacity=1.0, usedResources=<memory:36864, vCores:33>usedCapacity=0.75, absoluteUsedCapacity=0.75, numApps=5, numContainers=33
2013-08-31 00:26:23,315 INFO org.apache.hadoop.yarn.server.resourcemanager.scheduler.capacity.ParentQueue: assignedContainer queue=root usedCapacity=0.75 absoluteUsedCapacity=0.75 used=<memory:36864, vCores:33> cluster=<memory:49152, vCores:96>
2013-08-31 00:26:23,315 INFO org.apache.hadoop.yarn.server.resourcemanager.rmcontainer.RMContainerImpl: container_1377907764744_0006_01_000004 Container Transitioned from NEW to ALLOCATED
2013-08-31 00:26:23,315 INFO org.apache.hadoop.yarn.server.resourcemanager.RMAuditLogger: USER=ubuntu	OPERATION=AM Allocated Container	TARGET=SchedulerApp	RESULT=SUCCESS	APPID=application_1377907764744_0006	CONTAINERID=container_1377907764744_0006_01_000004
2013-08-31 00:26:23,316 INFO org.apache.hadoop.yarn.server.resourcemanager.scheduler.common.fica.FiCaSchedulerNode: Assigned container container_1377907764744_0006_01_000004 of capacity <memory:1024, vCores:1> on host hadoop-32-7:54070, which currently has 4 containers, <memory:5120, vCores:4> used and <memory:3072, vCores:12> available
2013-08-31 00:26:23,316 INFO org.apache.hadoop.yarn.server.resourcemanager.scheduler.capacity.LeafQueue: assignedContainer application=application_1377907764744_0006 container=Container: [ContainerId: container_1377907764744_0006_01_000004, NodeId: hadoop-32-7:54070, NodeHttpAddress: hadoop-32-7:8042, Resource: <memory:1024, vCores:1>, Priority: 20, State: NEW, Token: null, Status: container_id {, app_attempt_id {, application_id {, id: 6, cluster_timestamp: 1377907764744, }, attemptId: 1, }, id: 4, }, state: C_NEW, ] containerId=container_1377907764744_0006_01_000004 queue=default: capacity=1.0, absoluteCapacity=1.0, usedResources=<memory:36864, vCores:33>usedCapacity=0.75, absoluteUsedCapacity=0.75, numApps=5, numContainers=33 usedCapacity=0.75 absoluteUsedCapacity=0.75 used=<memory:36864, vCores:33> cluster=<memory:49152, vCores:96>
2013-08-31 00:26:23,317 INFO org.apache.hadoop.yarn.server.resourcemanager.scheduler.capacity.ParentQueue: Re-sorting queues since queue: root.default stats: default: capacity=1.0, absoluteCapacity=1.0, usedResources=<memory:37888, vCores:34>usedCapacity=0.7708333, absoluteUsedCapacity=0.7708333, numApps=5, numContainers=34
2013-08-31 00:26:23,317 INFO org.apache.hadoop.yarn.server.resourcemanager.scheduler.capacity.ParentQueue: assignedContainer queue=root usedCapacity=0.7708333 absoluteUsedCapacity=0.7708333 used=<memory:37888, vCores:34> cluster=<memory:49152, vCores:96>
2013-08-31 00:26:23,317 INFO org.apache.hadoop.yarn.server.resourcemanager.rmcontainer.RMContainerImpl: container_1377907764744_0006_01_000005 Container Transitioned from NEW to ALLOCATED
2013-08-31 00:26:23,318 INFO org.apache.hadoop.yarn.server.resourcemanager.RMAuditLogger: USER=ubuntu	OPERATION=AM Allocated Container	TARGET=SchedulerApp	RESULT=SUCCESS	APPID=application_1377907764744_0006	CONTAINERID=container_1377907764744_0006_01_000005
2013-08-31 00:26:23,318 INFO org.apache.hadoop.yarn.server.resourcemanager.scheduler.common.fica.FiCaSchedulerNode: Assigned container container_1377907764744_0006_01_000005 of capacity <memory:1024, vCores:1> on host hadoop-32-7:54070, which currently has 5 containers, <memory:6144, vCores:5> used and <memory:2048, vCores:11> available
2013-08-31 00:26:23,319 INFO org.apache.hadoop.yarn.server.resourcemanager.scheduler.capacity.LeafQueue: assignedContainer application=application_1377907764744_0006 container=Container: [ContainerId: container_1377907764744_0006_01_000005, NodeId: hadoop-32-7:54070, NodeHttpAddress: hadoop-32-7:8042, Resource: <memory:1024, vCores:1>, Priority: 20, State: NEW, Token: null, Status: container_id {, app_attempt_id {, application_id {, id: 6, cluster_timestamp: 1377907764744, }, attemptId: 1, }, id: 5, }, state: C_NEW, ] containerId=container_1377907764744_0006_01_000005 queue=default: capacity=1.0, absoluteCapacity=1.0, usedResources=<memory:37888, vCores:34>usedCapacity=0.7708333, absoluteUsedCapacity=0.7708333, numApps=5, numContainers=34 usedCapacity=0.7708333 absoluteUsedCapacity=0.7708333 used=<memory:37888, vCores:34> cluster=<memory:49152, vCores:96>
2013-08-31 00:26:23,319 INFO org.apache.hadoop.yarn.server.resourcemanager.scheduler.capacity.ParentQueue: Re-sorting queues since queue: root.default stats: default: capacity=1.0, absoluteCapacity=1.0, usedResources=<memory:38912, vCores:35>usedCapacity=0.7916667, absoluteUsedCapacity=0.7916667, numApps=5, numContainers=35
2013-08-31 00:26:23,319 INFO org.apache.hadoop.yarn.server.resourcemanager.scheduler.capacity.ParentQueue: assignedContainer queue=root usedCapacity=0.7916667 absoluteUsedCapacity=0.7916667 used=<memory:38912, vCores:35> cluster=<memory:49152, vCores:96>
2013-08-31 00:26:23,320 INFO org.apache.hadoop.yarn.server.resourcemanager.rmcontainer.RMContainerImpl: container_1377907764744_0006_01_000006 Container Transitioned from NEW to ALLOCATED
2013-08-31 00:26:23,320 INFO org.apache.hadoop.yarn.server.resourcemanager.RMAuditLogger: USER=ubuntu	OPERATION=AM Allocated Container	TARGET=SchedulerApp	RESULT=SUCCESS	APPID=application_1377907764744_0006	CONTAINERID=container_1377907764744_0006_01_000006
2013-08-31 00:26:23,320 INFO org.apache.hadoop.yarn.server.resourcemanager.scheduler.common.fica.FiCaSchedulerNode: Assigned container container_1377907764744_0006_01_000006 of capacity <memory:1024, vCores:1> on host hadoop-32-7:54070, which currently has 6 containers, <memory:7168, vCores:6> used and <memory:1024, vCores:10> available
2013-08-31 00:26:23,321 INFO org.apache.hadoop.yarn.server.resourcemanager.scheduler.capacity.LeafQueue: assignedContainer application=application_1377907764744_0006 container=Container: [ContainerId: container_1377907764744_0006_01_000006, NodeId: hadoop-32-7:54070, NodeHttpAddress: hadoop-32-7:8042, Resource: <memory:1024, vCores:1>, Priority: 20, State: NEW, Token: null, Status: container_id {, app_attempt_id {, application_id {, id: 6, cluster_timestamp: 1377907764744, }, attemptId: 1, }, id: 6, }, state: C_NEW, ] containerId=container_1377907764744_0006_01_000006 queue=default: capacity=1.0, absoluteCapacity=1.0, usedResources=<memory:38912, vCores:35>usedCapacity=0.7916667, absoluteUsedCapacity=0.7916667, numApps=5, numContainers=35 usedCapacity=0.7916667 absoluteUsedCapacity=0.7916667 used=<memory:38912, vCores:35> cluster=<memory:49152, vCores:96>
2013-08-31 00:26:23,321 INFO org.apache.hadoop.yarn.server.resourcemanager.scheduler.capacity.ParentQueue: Re-sorting queues since queue: root.default stats: default: capacity=1.0, absoluteCapacity=1.0, usedResources=<memory:39936, vCores:36>usedCapacity=0.8125, absoluteUsedCapacity=0.8125, numApps=5, numContainers=36
2013-08-31 00:26:23,321 INFO org.apache.hadoop.yarn.server.resourcemanager.scheduler.capacity.ParentQueue: assignedContainer queue=root usedCapacity=0.8125 absoluteUsedCapacity=0.8125 used=<memory:39936, vCores:36> cluster=<memory:49152, vCores:96>
2013-08-31 00:26:23,322 INFO org.apache.hadoop.yarn.server.resourcemanager.rmcontainer.RMContainerImpl: container_1377907764744_0006_01_000007 Container Transitioned from NEW to ALLOCATED
2013-08-31 00:26:23,322 INFO org.apache.hadoop.yarn.server.resourcemanager.RMAuditLogger: USER=ubuntu	OPERATION=AM Allocated Container	TARGET=SchedulerApp	RESULT=SUCCESS	APPID=application_1377907764744_0006	CONTAINERID=container_1377907764744_0006_01_000007
2013-08-31 00:26:23,322 INFO org.apache.hadoop.yarn.server.resourcemanager.scheduler.common.fica.FiCaSchedulerNode: Assigned container container_1377907764744_0006_01_000007 of capacity <memory:1024, vCores:1> on host hadoop-32-7:54070, which currently has 7 containers, <memory:8192, vCores:7> used and <memory:0, vCores:9> available
2013-08-31 00:26:23,323 INFO org.apache.hadoop.yarn.server.resourcemanager.scheduler.capacity.LeafQueue: assignedContainer application=application_1377907764744_0006 container=Container: [ContainerId: container_1377907764744_0006_01_000007, NodeId: hadoop-32-7:54070, NodeHttpAddress: hadoop-32-7:8042, Resource: <memory:1024, vCores:1>, Priority: 20, State: NEW, Token: null, Status: container_id {, app_attempt_id {, application_id {, id: 6, cluster_timestamp: 1377907764744, }, attemptId: 1, }, id: 7, }, state: C_NEW, ] containerId=container_1377907764744_0006_01_000007 queue=default: capacity=1.0, absoluteCapacity=1.0, usedResources=<memory:39936, vCores:36>usedCapacity=0.8125, absoluteUsedCapacity=0.8125, numApps=5, numContainers=36 usedCapacity=0.8125 absoluteUsedCapacity=0.8125 used=<memory:39936, vCores:36> cluster=<memory:49152, vCores:96>
2013-08-31 00:26:23,323 INFO org.apache.hadoop.yarn.server.resourcemanager.scheduler.capacity.ParentQueue: Re-sorting queues since queue: root.default stats: default: capacity=1.0, absoluteCapacity=1.0, usedResources=<memory:40960, vCores:37>usedCapacity=0.8333333, absoluteUsedCapacity=0.8333333, numApps=5, numContainers=37
2013-08-31 00:26:23,323 INFO org.apache.hadoop.yarn.server.resourcemanager.scheduler.capacity.ParentQueue: assignedContainer queue=root usedCapacity=0.8333333 absoluteUsedCapacity=0.8333333 used=<memory:40960, vCores:37> cluster=<memory:49152, vCores:96>
2013-08-31 00:26:23,340 INFO org.apache.hadoop.yarn.server.resourcemanager.rmcontainer.RMContainerImpl: container_1377907764744_0006_01_000008 Container Transitioned from NEW to ALLOCATED
2013-08-31 00:26:23,340 INFO org.apache.hadoop.yarn.server.resourcemanager.RMAuditLogger: USER=ubuntu	OPERATION=AM Allocated Container	TARGET=SchedulerApp	RESULT=SUCCESS	APPID=application_1377907764744_0006	CONTAINERID=container_1377907764744_0006_01_000008
2013-08-31 00:26:23,340 INFO org.apache.hadoop.yarn.server.resourcemanager.scheduler.common.fica.FiCaSchedulerNode: Assigned container container_1377907764744_0006_01_000008 of capacity <memory:1024, vCores:1> on host hadoop-32-6:48039, which currently has 1 containers, <memory:1024, vCores:1> used and <memory:7168, vCores:15> available
2013-08-31 00:26:23,341 INFO org.apache.hadoop.yarn.server.resourcemanager.scheduler.capacity.LeafQueue: assignedContainer application=application_1377907764744_0006 container=Container: [ContainerId: container_1377907764744_0006_01_000008, NodeId: hadoop-32-6:48039, NodeHttpAddress: hadoop-32-6:8042, Resource: <memory:1024, vCores:1>, Priority: 20, State: NEW, Token: null, Status: container_id {, app_attempt_id {, application_id {, id: 6, cluster_timestamp: 1377907764744, }, attemptId: 1, }, id: 8, }, state: C_NEW, ] containerId=container_1377907764744_0006_01_000008 queue=default: capacity=1.0, absoluteCapacity=1.0, usedResources=<memory:40960, vCores:37>usedCapacity=0.8333333, absoluteUsedCapacity=0.8333333, numApps=5, numContainers=37 usedCapacity=0.8333333 absoluteUsedCapacity=0.8333333 used=<memory:40960, vCores:37> cluster=<memory:49152, vCores:96>
2013-08-31 00:26:23,341 INFO org.apache.hadoop.yarn.server.resourcemanager.scheduler.capacity.ParentQueue: Re-sorting queues since queue: root.default stats: default: capacity=1.0, absoluteCapacity=1.0, usedResources=<memory:41984, vCores:38>usedCapacity=0.8541667, absoluteUsedCapacity=0.8541667, numApps=5, numContainers=38
2013-08-31 00:26:23,342 INFO org.apache.hadoop.yarn.server.resourcemanager.scheduler.capacity.ParentQueue: assignedContainer queue=root usedCapacity=0.8541667 absoluteUsedCapacity=0.8541667 used=<memory:41984, vCores:38> cluster=<memory:49152, vCores:96>
2013-08-31 00:26:23,342 INFO org.apache.hadoop.yarn.server.resourcemanager.rmcontainer.RMContainerImpl: container_1377907764744_0006_01_000009 Container Transitioned from NEW to ALLOCATED
2013-08-31 00:26:23,342 INFO org.apache.hadoop.yarn.server.resourcemanager.RMAuditLogger: USER=ubuntu	OPERATION=AM Allocated Container	TARGET=SchedulerApp	RESULT=SUCCESS	APPID=application_1377907764744_0006	CONTAINERID=container_1377907764744_0006_01_000009
2013-08-31 00:26:23,343 INFO org.apache.hadoop.yarn.server.resourcemanager.scheduler.common.fica.FiCaSchedulerNode: Assigned container container_1377907764744_0006_01_000009 of capacity <memory:1024, vCores:1> on host hadoop-32-6:48039, which currently has 2 containers, <memory:2048, vCores:2> used and <memory:6144, vCores:14> available
2013-08-31 00:26:23,343 INFO org.apache.hadoop.yarn.server.resourcemanager.scheduler.capacity.LeafQueue: assignedContainer application=application_1377907764744_0006 container=Container: [ContainerId: container_1377907764744_0006_01_000009, NodeId: hadoop-32-6:48039, NodeHttpAddress: hadoop-32-6:8042, Resource: <memory:1024, vCores:1>, Priority: 20, State: NEW, Token: null, Status: container_id {, app_attempt_id {, application_id {, id: 6, cluster_timestamp: 1377907764744, }, attemptId: 1, }, id: 9, }, state: C_NEW, ] containerId=container_1377907764744_0006_01_000009 queue=default: capacity=1.0, absoluteCapacity=1.0, usedResources=<memory:41984, vCores:38>usedCapacity=0.8541667, absoluteUsedCapacity=0.8541667, numApps=5, numContainers=38 usedCapacity=0.8541667 absoluteUsedCapacity=0.8541667 used=<memory:41984, vCores:38> cluster=<memory:49152, vCores:96>
2013-08-31 00:26:23,344 INFO org.apache.hadoop.yarn.server.resourcemanager.scheduler.capacity.ParentQueue: Re-sorting queues since queue: root.default stats: default: capacity=1.0, absoluteCapacity=1.0, usedResources=<memory:43008, vCores:39>usedCapacity=0.875, absoluteUsedCapacity=0.875, numApps=5, numContainers=39
2013-08-31 00:26:23,344 INFO org.apache.hadoop.yarn.server.resourcemanager.scheduler.capacity.ParentQueue: assignedContainer queue=root usedCapacity=0.875 absoluteUsedCapacity=0.875 used=<memory:43008, vCores:39> cluster=<memory:49152, vCores:96>
2013-08-31 00:26:23,344 INFO org.apache.hadoop.yarn.server.resourcemanager.rmcontainer.RMContainerImpl: container_1377907764744_0006_01_000010 Container Transitioned from NEW to ALLOCATED
2013-08-31 00:26:23,345 INFO org.apache.hadoop.yarn.server.resourcemanager.RMAuditLogger: USER=ubuntu	OPERATION=AM Allocated Container	TARGET=SchedulerApp	RESULT=SUCCESS	APPID=application_1377907764744_0006	CONTAINERID=container_1377907764744_0006_01_000010
2013-08-31 00:26:23,345 INFO org.apache.hadoop.yarn.server.resourcemanager.scheduler.common.fica.FiCaSchedulerNode: Assigned container container_1377907764744_0006_01_000010 of capacity <memory:1024, vCores:1> on host hadoop-32-6:48039, which currently has 3 containers, <memory:3072, vCores:3> used and <memory:5120, vCores:13> available
2013-08-31 00:26:23,346 INFO org.apache.hadoop.yarn.server.resourcemanager.scheduler.capacity.LeafQueue: assignedContainer application=application_1377907764744_0006 container=Container: [ContainerId: container_1377907764744_0006_01_000010, NodeId: hadoop-32-6:48039, NodeHttpAddress: hadoop-32-6:8042, Resource: <memory:1024, vCores:1>, Priority: 20, State: NEW, Token: null, Status: container_id {, app_attempt_id {, application_id {, id: 6, cluster_timestamp: 1377907764744, }, attemptId: 1, }, id: 10, }, state: C_NEW, ] containerId=container_1377907764744_0006_01_000010 queue=default: capacity=1.0, absoluteCapacity=1.0, usedResources=<memory:43008, vCores:39>usedCapacity=0.875, absoluteUsedCapacity=0.875, numApps=5, numContainers=39 usedCapacity=0.875 absoluteUsedCapacity=0.875 used=<memory:43008, vCores:39> cluster=<memory:49152, vCores:96>
2013-08-31 00:26:23,346 INFO org.apache.hadoop.yarn.server.resourcemanager.scheduler.capacity.ParentQueue: Re-sorting queues since queue: root.default stats: default: capacity=1.0, absoluteCapacity=1.0, usedResources=<memory:44032, vCores:40>usedCapacity=0.8958333, absoluteUsedCapacity=0.8958333, numApps=5, numContainers=40
2013-08-31 00:26:23,346 INFO org.apache.hadoop.yarn.server.resourcemanager.scheduler.capacity.ParentQueue: assignedContainer queue=root usedCapacity=0.8958333 absoluteUsedCapacity=0.8958333 used=<memory:44032, vCores:40> cluster=<memory:49152, vCores:96>
2013-08-31 00:26:23,347 INFO org.apache.hadoop.yarn.server.resourcemanager.rmcontainer.RMContainerImpl: container_1377907764744_0006_01_000011 Container Transitioned from NEW to ALLOCATED
2013-08-31 00:26:23,347 INFO org.apache.hadoop.yarn.server.resourcemanager.RMAuditLogger: USER=ubuntu	OPERATION=AM Allocated Container	TARGET=SchedulerApp	RESULT=SUCCESS	APPID=application_1377907764744_0006	CONTAINERID=container_1377907764744_0006_01_000011
2013-08-31 00:26:23,347 INFO org.apache.hadoop.yarn.server.resourcemanager.scheduler.common.fica.FiCaSchedulerNode: Assigned container container_1377907764744_0006_01_000011 of capacity <memory:1024, vCores:1> on host hadoop-32-6:48039, which currently has 4 containers, <memory:4096, vCores:4> used and <memory:4096, vCores:12> available
2013-08-31 00:26:23,348 INFO org.apache.hadoop.yarn.server.resourcemanager.scheduler.capacity.LeafQueue: assignedContainer application=application_1377907764744_0006 container=Container: [ContainerId: container_1377907764744_0006_01_000011, NodeId: hadoop-32-6:48039, NodeHttpAddress: hadoop-32-6:8042, Resource: <memory:1024, vCores:1>, Priority: 20, State: NEW, Token: null, Status: container_id {, app_attempt_id {, application_id {, id: 6, cluster_timestamp: 1377907764744, }, attemptId: 1, }, id: 11, }, state: C_NEW, ] containerId=container_1377907764744_0006_01_000011 queue=default: capacity=1.0, absoluteCapacity=1.0, usedResources=<memory:44032, vCores:40>usedCapacity=0.8958333, absoluteUsedCapacity=0.8958333, numApps=5, numContainers=40 usedCapacity=0.8958333 absoluteUsedCapacity=0.8958333 used=<memory:44032, vCores:40> cluster=<memory:49152, vCores:96>
2013-08-31 00:26:23,348 INFO org.apache.hadoop.yarn.server.resourcemanager.scheduler.capacity.ParentQueue: Re-sorting queues since queue: root.default stats: default: capacity=1.0, absoluteCapacity=1.0, usedResources=<memory:45056, vCores:41>usedCapacity=0.9166667, absoluteUsedCapacity=0.9166667, numApps=5, numContainers=41
2013-08-31 00:26:23,348 INFO org.apache.hadoop.yarn.server.resourcemanager.scheduler.capacity.ParentQueue: assignedContainer queue=root usedCapacity=0.9166667 absoluteUsedCapacity=0.9166667 used=<memory:45056, vCores:41> cluster=<memory:49152, vCores:96>
2013-08-31 00:26:23,349 INFO org.apache.hadoop.yarn.server.resourcemanager.rmcontainer.RMContainerImpl: container_1377907764744_0006_01_000012 Container Transitioned from NEW to ALLOCATED
2013-08-31 00:26:23,349 INFO org.apache.hadoop.yarn.server.resourcemanager.RMAuditLogger: USER=ubuntu	OPERATION=AM Allocated Container	TARGET=SchedulerApp	RESULT=SUCCESS	APPID=application_1377907764744_0006	CONTAINERID=container_1377907764744_0006_01_000012
2013-08-31 00:26:23,349 INFO org.apache.hadoop.yarn.server.resourcemanager.scheduler.common.fica.FiCaSchedulerNode: Assigned container container_1377907764744_0006_01_000012 of capacity <memory:1024, vCores:1> on host hadoop-32-6:48039, which currently has 5 containers, <memory:5120, vCores:5> used and <memory:3072, vCores:11> available
2013-08-31 00:26:23,350 INFO org.apache.hadoop.yarn.server.resourcemanager.scheduler.capacity.LeafQueue: assignedContainer application=application_1377907764744_0006 container=Container: [ContainerId: container_1377907764744_0006_01_000012, NodeId: hadoop-32-6:48039, NodeHttpAddress: hadoop-32-6:8042, Resource: <memory:1024, vCores:1>, Priority: 20, State: NEW, Token: null, Status: container_id {, app_attempt_id {, application_id {, id: 6, cluster_timestamp: 1377907764744, }, attemptId: 1, }, id: 12, }, state: C_NEW, ] containerId=container_1377907764744_0006_01_000012 queue=default: capacity=1.0, absoluteCapacity=1.0, usedResources=<memory:45056, vCores:41>usedCapacity=0.9166667, absoluteUsedCapacity=0.9166667, numApps=5, numContainers=41 usedCapacity=0.9166667 absoluteUsedCapacity=0.9166667 used=<memory:45056, vCores:41> cluster=<memory:49152, vCores:96>
2013-08-31 00:26:23,350 INFO org.apache.hadoop.yarn.server.resourcemanager.scheduler.capacity.ParentQueue: Re-sorting queues since queue: root.default stats: default: capacity=1.0, absoluteCapacity=1.0, usedResources=<memory:46080, vCores:42>usedCapacity=0.9375, absoluteUsedCapacity=0.9375, numApps=5, numContainers=42
2013-08-31 00:26:23,351 INFO org.apache.hadoop.yarn.server.resourcemanager.scheduler.capacity.ParentQueue: assignedContainer queue=root usedCapacity=0.9375 absoluteUsedCapacity=0.9375 used=<memory:46080, vCores:42> cluster=<memory:49152, vCores:96>
2013-08-31 00:26:23,351 INFO org.apache.hadoop.yarn.server.resourcemanager.rmcontainer.RMContainerImpl: container_1377907764744_0006_01_000013 Container Transitioned from NEW to ALLOCATED
2013-08-31 00:26:23,351 INFO org.apache.hadoop.yarn.server.resourcemanager.RMAuditLogger: USER=ubuntu	OPERATION=AM Allocated Container	TARGET=SchedulerApp	RESULT=SUCCESS	APPID=application_1377907764744_0006	CONTAINERID=container_1377907764744_0006_01_000013
2013-08-31 00:26:23,351 INFO org.apache.hadoop.yarn.server.resourcemanager.scheduler.common.fica.FiCaSchedulerNode: Assigned container container_1377907764744_0006_01_000013 of capacity <memory:1024, vCores:1> on host hadoop-32-6:48039, which currently has 6 containers, <memory:6144, vCores:6> used and <memory:2048, vCores:10> available
2013-08-31 00:26:23,352 INFO org.apache.hadoop.yarn.server.resourcemanager.scheduler.capacity.LeafQueue: assignedContainer application=application_1377907764744_0006 container=Container: [ContainerId: container_1377907764744_0006_01_000013, NodeId: hadoop-32-6:48039, NodeHttpAddress: hadoop-32-6:8042, Resource: <memory:1024, vCores:1>, Priority: 20, State: NEW, Token: null, Status: container_id {, app_attempt_id {, application_id {, id: 6, cluster_timestamp: 1377907764744, }, attemptId: 1, }, id: 13, }, state: C_NEW, ] containerId=container_1377907764744_0006_01_000013 queue=default: capacity=1.0, absoluteCapacity=1.0, usedResources=<memory:46080, vCores:42>usedCapacity=0.9375, absoluteUsedCapacity=0.9375, numApps=5, numContainers=42 usedCapacity=0.9375 absoluteUsedCapacity=0.9375 used=<memory:46080, vCores:42> cluster=<memory:49152, vCores:96>
2013-08-31 00:26:23,353 INFO org.apache.hadoop.yarn.server.resourcemanager.scheduler.capacity.ParentQueue: Re-sorting queues since queue: root.default stats: default: capacity=1.0, absoluteCapacity=1.0, usedResources=<memory:47104, vCores:43>usedCapacity=0.9583333, absoluteUsedCapacity=0.9583333, numApps=5, numContainers=43
2013-08-31 00:26:23,353 INFO org.apache.hadoop.yarn.server.resourcemanager.scheduler.capacity.ParentQueue: assignedContainer queue=root usedCapacity=0.9583333 absoluteUsedCapacity=0.9583333 used=<memory:47104, vCores:43> cluster=<memory:49152, vCores:96>
2013-08-31 00:26:23,353 INFO org.apache.hadoop.yarn.server.resourcemanager.rmcontainer.RMContainerImpl: container_1377907764744_0006_01_000014 Container Transitioned from NEW to ALLOCATED
2013-08-31 00:26:23,353 INFO org.apache.hadoop.yarn.server.resourcemanager.RMAuditLogger: USER=ubuntu	OPERATION=AM Allocated Container	TARGET=SchedulerApp	RESULT=SUCCESS	APPID=application_1377907764744_0006	CONTAINERID=container_1377907764744_0006_01_000014
2013-08-31 00:26:23,354 INFO org.apache.hadoop.yarn.server.resourcemanager.scheduler.common.fica.FiCaSchedulerNode: Assigned container container_1377907764744_0006_01_000014 of capacity <memory:1024, vCores:1> on host hadoop-32-6:48039, which currently has 7 containers, <memory:7168, vCores:7> used and <memory:1024, vCores:9> available
2013-08-31 00:26:23,355 INFO org.apache.hadoop.yarn.server.resourcemanager.scheduler.capacity.LeafQueue: assignedContainer application=application_1377907764744_0006 container=Container: [ContainerId: container_1377907764744_0006_01_000014, NodeId: hadoop-32-6:48039, NodeHttpAddress: hadoop-32-6:8042, Resource: <memory:1024, vCores:1>, Priority: 20, State: NEW, Token: null, Status: container_id {, app_attempt_id {, application_id {, id: 6, cluster_timestamp: 1377907764744, }, attemptId: 1, }, id: 14, }, state: C_NEW, ] containerId=container_1377907764744_0006_01_000014 queue=default: capacity=1.0, absoluteCapacity=1.0, usedResources=<memory:47104, vCores:43>usedCapacity=0.9583333, absoluteUsedCapacity=0.9583333, numApps=5, numContainers=43 usedCapacity=0.9583333 absoluteUsedCapacity=0.9583333 used=<memory:47104, vCores:43> cluster=<memory:49152, vCores:96>
2013-08-31 00:26:23,355 INFO org.apache.hadoop.yarn.server.resourcemanager.scheduler.capacity.ParentQueue: Re-sorting queues since queue: root.default stats: default: capacity=1.0, absoluteCapacity=1.0, usedResources=<memory:48128, vCores:44>usedCapacity=0.9791667, absoluteUsedCapacity=0.9791667, numApps=5, numContainers=44
2013-08-31 00:26:23,355 INFO org.apache.hadoop.yarn.server.resourcemanager.scheduler.capacity.ParentQueue: assignedContainer queue=root usedCapacity=0.9791667 absoluteUsedCapacity=0.9791667 used=<memory:48128, vCores:44> cluster=<memory:49152, vCores:96>
2013-08-31 00:26:23,356 INFO org.apache.hadoop.yarn.server.resourcemanager.rmcontainer.RMContainerImpl: container_1377907764744_0006_01_000015 Container Transitioned from NEW to ALLOCATED
2013-08-31 00:26:23,356 INFO org.apache.hadoop.yarn.server.resourcemanager.RMAuditLogger: USER=ubuntu	OPERATION=AM Allocated Container	TARGET=SchedulerApp	RESULT=SUCCESS	APPID=application_1377907764744_0006	CONTAINERID=container_1377907764744_0006_01_000015
2013-08-31 00:26:23,356 INFO org.apache.hadoop.yarn.server.resourcemanager.scheduler.common.fica.FiCaSchedulerNode: Assigned container container_1377907764744_0006_01_000015 of capacity <memory:1024, vCores:1> on host hadoop-32-6:48039, which currently has 8 containers, <memory:8192, vCores:8> used and <memory:0, vCores:8> available
2013-08-31 00:26:23,357 INFO org.apache.hadoop.yarn.server.resourcemanager.scheduler.capacity.LeafQueue: assignedContainer application=application_1377907764744_0006 container=Container: [ContainerId: container_1377907764744_0006_01_000015, NodeId: hadoop-32-6:48039, NodeHttpAddress: hadoop-32-6:8042, Resource: <memory:1024, vCores:1>, Priority: 20, State: NEW, Token: null, Status: container_id {, app_attempt_id {, application_id {, id: 6, cluster_timestamp: 1377907764744, }, attemptId: 1, }, id: 15, }, state: C_NEW, ] containerId=container_1377907764744_0006_01_000015 queue=default: capacity=1.0, absoluteCapacity=1.0, usedResources=<memory:48128, vCores:44>usedCapacity=0.9791667, absoluteUsedCapacity=0.9791667, numApps=5, numContainers=44 usedCapacity=0.9791667 absoluteUsedCapacity=0.9791667 used=<memory:48128, vCores:44> cluster=<memory:49152, vCores:96>
2013-08-31 00:26:23,357 INFO org.apache.hadoop.yarn.server.resourcemanager.scheduler.capacity.ParentQueue: Re-sorting queues since queue: root.default stats: default: capacity=1.0, absoluteCapacity=1.0, usedResources=<memory:49152, vCores:45>usedCapacity=1.0, absoluteUsedCapacity=1.0, numApps=5, numContainers=45
2013-08-31 00:26:23,357 INFO org.apache.hadoop.yarn.server.resourcemanager.scheduler.capacity.ParentQueue: assignedContainer queue=root usedCapacity=1.0 absoluteUsedCapacity=1.0 used=<memory:49152, vCores:45> cluster=<memory:49152, vCores:96>
2013-08-31 00:26:23,506 INFO org.apache.hadoop.yarn.server.resourcemanager.rmcontainer.RMContainerImpl: container_1377907764744_0007_01_000002 Container Transitioned from ALLOCATED to ACQUIRED
2013-08-31 00:26:23,508 INFO org.apache.hadoop.yarn.server.resourcemanager.rmcontainer.RMContainerImpl: container_1377907764744_0007_01_000003 Container Transitioned from ALLOCATED to ACQUIRED
2013-08-31 00:26:23,509 INFO org.apache.hadoop.yarn.server.resourcemanager.rmcontainer.RMContainerImpl: container_1377907764744_0007_01_000004 Container Transitioned from ALLOCATED to ACQUIRED
2013-08-31 00:26:23,510 INFO org.apache.hadoop.yarn.server.resourcemanager.rmcontainer.RMContainerImpl: container_1377907764744_0007_01_000005 Container Transitioned from ALLOCATED to ACQUIRED
2013-08-31 00:26:23,511 INFO org.apache.hadoop.yarn.server.resourcemanager.rmcontainer.RMContainerImpl: container_1377907764744_0007_01_000006 Container Transitioned from ALLOCATED to ACQUIRED
2013-08-31 00:26:23,511 INFO org.apache.hadoop.yarn.server.resourcemanager.rmcontainer.RMContainerImpl: container_1377907764744_0007_01_000007 Container Transitioned from ALLOCATED to ACQUIRED
2013-08-31 00:26:23,512 INFO org.apache.hadoop.yarn.server.resourcemanager.rmcontainer.RMContainerImpl: container_1377907764744_0007_01_000008 Container Transitioned from ALLOCATED to ACQUIRED
2013-08-31 00:26:23,514 INFO org.apache.hadoop.yarn.server.resourcemanager.rmcontainer.RMContainerImpl: container_1377907764744_0007_01_000009 Container Transitioned from ALLOCATED to ACQUIRED
2013-08-31 00:26:23,515 INFO org.apache.hadoop.yarn.server.resourcemanager.rmcontainer.RMContainerImpl: container_1377907764744_0007_01_000010 Container Transitioned from ALLOCATED to ACQUIRED
2013-08-31 00:26:23,516 INFO org.apache.hadoop.yarn.server.resourcemanager.rmcontainer.RMContainerImpl: container_1377907764744_0007_01_000011 Container Transitioned from ALLOCATED to ACQUIRED
2013-08-31 00:26:23,517 INFO org.apache.hadoop.yarn.server.resourcemanager.rmcontainer.RMContainerImpl: container_1377907764744_0007_01_000012 Container Transitioned from ALLOCATED to ACQUIRED
2013-08-31 00:26:23,519 INFO org.apache.hadoop.yarn.server.resourcemanager.rmcontainer.RMContainerImpl: container_1377907764744_0007_01_000013 Container Transitioned from ALLOCATED to ACQUIRED
2013-08-31 00:26:23,520 INFO org.apache.hadoop.yarn.server.resourcemanager.rmcontainer.RMContainerImpl: container_1377907764744_0007_01_000014 Container Transitioned from ALLOCATED to ACQUIRED
2013-08-31 00:26:23,520 INFO org.apache.hadoop.yarn.server.resourcemanager.rmcontainer.RMContainerImpl: container_1377907764744_0007_01_000015 Container Transitioned from ALLOCATED to ACQUIRED
2013-08-31 00:26:23,521 INFO org.apache.hadoop.yarn.server.resourcemanager.rmcontainer.RMContainerImpl: container_1377907764744_0007_01_000016 Container Transitioned from ALLOCATED to ACQUIRED
2013-08-31 00:26:23,521 INFO org.apache.hadoop.yarn.server.resourcemanager.rmcontainer.RMContainerImpl: container_1377907764744_0007_01_000017 Container Transitioned from ALLOCATED to ACQUIRED
2013-08-31 00:26:23,522 INFO org.apache.hadoop.yarn.server.resourcemanager.rmcontainer.RMContainerImpl: container_1377907764744_0007_01_000018 Container Transitioned from ALLOCATED to ACQUIRED
2013-08-31 00:26:23,523 INFO org.apache.hadoop.yarn.server.resourcemanager.rmcontainer.RMContainerImpl: container_1377907764744_0007_01_000019 Container Transitioned from ALLOCATED to ACQUIRED
2013-08-31 00:26:23,523 INFO org.apache.hadoop.yarn.server.resourcemanager.rmcontainer.RMContainerImpl: container_1377907764744_0007_01_000020 Container Transitioned from ALLOCATED to ACQUIRED
2013-08-31 00:26:23,525 INFO org.apache.hadoop.yarn.server.resourcemanager.rmcontainer.RMContainerImpl: container_1377907764744_0007_01_000021 Container Transitioned from ALLOCATED to ACQUIRED
2013-08-31 00:26:23,525 INFO org.apache.hadoop.yarn.server.resourcemanager.rmcontainer.RMContainerImpl: container_1377907764744_0007_01_000022 Container Transitioned from ALLOCATED to ACQUIRED
2013-08-31 00:26:23,525 INFO org.apache.hadoop.yarn.server.resourcemanager.rmcontainer.RMContainerImpl: container_1377907764744_0007_01_000023 Container Transitioned from ALLOCATED to ACQUIRED
2013-08-31 00:26:23,525 INFO org.apache.hadoop.yarn.server.resourcemanager.rmcontainer.RMContainerImpl: container_1377907764744_0007_01_000024 Container Transitioned from ALLOCATED to ACQUIRED
2013-08-31 00:26:23,526 INFO org.apache.hadoop.yarn.server.resourcemanager.rmcontainer.RMContainerImpl: container_1377907764744_0007_01_000025 Container Transitioned from ALLOCATED to ACQUIRED
2013-08-31 00:26:23,526 INFO org.apache.hadoop.yarn.server.resourcemanager.rmcontainer.RMContainerImpl: container_1377907764744_0007_01_000026 Container Transitioned from ALLOCATED to ACQUIRED
2013-08-31 00:26:23,526 INFO org.apache.hadoop.yarn.server.resourcemanager.rmcontainer.RMContainerImpl: container_1377907764744_0007_01_000027 Container Transitioned from ALLOCATED to ACQUIRED
2013-08-31 00:26:23,526 INFO org.apache.hadoop.yarn.server.resourcemanager.rmcontainer.RMContainerImpl: container_1377907764744_0007_01_000028 Container Transitioned from ALLOCATED to ACQUIRED
2013-08-31 00:26:23,527 INFO org.apache.hadoop.yarn.server.resourcemanager.rmcontainer.RMContainerImpl: container_1377907764744_0007_01_000029 Container Transitioned from ALLOCATED to ACQUIRED
2013-08-31 00:26:24,197 INFO org.apache.hadoop.yarn.server.resourcemanager.rmcontainer.RMContainerImpl: container_1377907764744_0006_01_000002 Container Transitioned from ALLOCATED to ACQUIRED
2013-08-31 00:26:24,197 INFO org.apache.hadoop.yarn.server.resourcemanager.rmcontainer.RMContainerImpl: container_1377907764744_0006_01_000003 Container Transitioned from ALLOCATED to ACQUIRED
2013-08-31 00:26:24,197 INFO org.apache.hadoop.yarn.server.resourcemanager.rmcontainer.RMContainerImpl: container_1377907764744_0006_01_000004 Container Transitioned from ALLOCATED to ACQUIRED
2013-08-31 00:26:24,198 INFO org.apache.hadoop.yarn.server.resourcemanager.rmcontainer.RMContainerImpl: container_1377907764744_0006_01_000005 Container Transitioned from ALLOCATED to ACQUIRED
2013-08-31 00:26:24,198 INFO org.apache.hadoop.yarn.server.resourcemanager.rmcontainer.RMContainerImpl: container_1377907764744_0006_01_000006 Container Transitioned from ALLOCATED to ACQUIRED
2013-08-31 00:26:24,198 INFO org.apache.hadoop.yarn.server.resourcemanager.rmcontainer.RMContainerImpl: container_1377907764744_0006_01_000007 Container Transitioned from ALLOCATED to ACQUIRED
2013-08-31 00:26:24,198 INFO org.apache.hadoop.yarn.server.resourcemanager.rmcontainer.RMContainerImpl: container_1377907764744_0006_01_000008 Container Transitioned from ALLOCATED to ACQUIRED
2013-08-31 00:26:24,198 INFO org.apache.hadoop.yarn.server.resourcemanager.rmcontainer.RMContainerImpl: container_1377907764744_0006_01_000009 Container Transitioned from ALLOCATED to ACQUIRED
2013-08-31 00:26:24,199 INFO org.apache.hadoop.yarn.server.resourcemanager.rmcontainer.RMContainerImpl: container_1377907764744_0006_01_000010 Container Transitioned from ALLOCATED to ACQUIRED
2013-08-31 00:26:24,199 INFO org.apache.hadoop.yarn.server.resourcemanager.rmcontainer.RMContainerImpl: container_1377907764744_0006_01_000011 Container Transitioned from ALLOCATED to ACQUIRED
2013-08-31 00:26:24,199 INFO org.apache.hadoop.yarn.server.resourcemanager.rmcontainer.RMContainerImpl: container_1377907764744_0006_01_000012 Container Transitioned from ALLOCATED to ACQUIRED
2013-08-31 00:26:24,199 INFO org.apache.hadoop.yarn.server.resourcemanager.rmcontainer.RMContainerImpl: container_1377907764744_0006_01_000013 Container Transitioned from ALLOCATED to ACQUIRED
2013-08-31 00:26:24,199 INFO org.apache.hadoop.yarn.server.resourcemanager.rmcontainer.RMContainerImpl: container_1377907764744_0006_01_000014 Container Transitioned from ALLOCATED to ACQUIRED
2013-08-31 00:26:24,200 INFO org.apache.hadoop.yarn.server.resourcemanager.rmcontainer.RMContainerImpl: container_1377907764744_0006_01_000015 Container Transitioned from ALLOCATED to ACQUIRED
2013-08-31 00:26:24,552 INFO org.apache.hadoop.yarn.server.resourcemanager.rmcontainer.RMContainerImpl: container_1377907764744_0007_01_000002 Container Transitioned from ACQUIRED to RUNNING
2013-08-31 00:26:24,553 INFO org.apache.hadoop.yarn.server.resourcemanager.rmcontainer.RMContainerImpl: container_1377907764744_0007_01_000003 Container Transitioned from ACQUIRED to RUNNING
2013-08-31 00:26:24,554 INFO org.apache.hadoop.yarn.server.resourcemanager.rmcontainer.RMContainerImpl: container_1377907764744_0007_01_000004 Container Transitioned from ACQUIRED to RUNNING
2013-08-31 00:26:24,555 INFO org.apache.hadoop.yarn.server.resourcemanager.rmcontainer.RMContainerImpl: container_1377907764744_0007_01_000005 Container Transitioned from ACQUIRED to RUNNING
2013-08-31 00:26:24,556 INFO org.apache.hadoop.yarn.server.resourcemanager.rmcontainer.RMContainerImpl: container_1377907764744_0007_01_000006 Container Transitioned from ACQUIRED to RUNNING
2013-08-31 00:26:24,556 INFO org.apache.hadoop.yarn.server.resourcemanager.rmcontainer.RMContainerImpl: container_1377907764744_0007_01_000007 Container Transitioned from ACQUIRED to RUNNING
2013-08-31 00:26:24,617 INFO org.apache.hadoop.yarn.server.resourcemanager.rmcontainer.RMContainerImpl: container_1377907764744_0007_01_000008 Container Transitioned from ACQUIRED to RUNNING
2013-08-31 00:26:24,618 INFO org.apache.hadoop.yarn.server.resourcemanager.rmcontainer.RMContainerImpl: container_1377907764744_0007_01_000009 Container Transitioned from ACQUIRED to RUNNING
2013-08-31 00:26:24,619 INFO org.apache.hadoop.yarn.server.resourcemanager.rmcontainer.RMContainerImpl: container_1377907764744_0007_01_000010 Container Transitioned from ACQUIRED to RUNNING
2013-08-31 00:26:24,619 INFO org.apache.hadoop.yarn.server.resourcemanager.rmcontainer.RMContainerImpl: container_1377907764744_0007_01_000011 Container Transitioned from ACQUIRED to RUNNING
2013-08-31 00:26:24,620 INFO org.apache.hadoop.yarn.server.resourcemanager.rmcontainer.RMContainerImpl: container_1377907764744_0007_01_000012 Container Transitioned from ACQUIRED to RUNNING
2013-08-31 00:26:24,621 INFO org.apache.hadoop.yarn.server.resourcemanager.rmcontainer.RMContainerImpl: container_1377907764744_0007_01_000013 Container Transitioned from ACQUIRED to RUNNING
2013-08-31 00:26:24,621 INFO org.apache.hadoop.yarn.server.resourcemanager.rmcontainer.RMContainerImpl: container_1377907764744_0007_01_000014 Container Transitioned from ACQUIRED to RUNNING
2013-08-31 00:26:24,622 INFO org.apache.hadoop.yarn.server.resourcemanager.rmcontainer.RMContainerImpl: container_1377907764744_0007_01_000015 Container Transitioned from ACQUIRED to RUNNING
2013-08-31 00:26:24,650 INFO org.apache.hadoop.yarn.server.resourcemanager.rmcontainer.RMContainerImpl: container_1377907764744_0007_01_000016 Container Transitioned from ACQUIRED to RUNNING
2013-08-31 00:26:24,651 INFO org.apache.hadoop.yarn.server.resourcemanager.rmcontainer.RMContainerImpl: container_1377907764744_0007_01_000017 Container Transitioned from ACQUIRED to RUNNING
2013-08-31 00:26:24,651 INFO org.apache.hadoop.yarn.server.resourcemanager.rmcontainer.RMContainerImpl: container_1377907764744_0007_01_000018 Container Transitioned from ACQUIRED to RUNNING
2013-08-31 00:26:24,652 INFO org.apache.hadoop.yarn.server.resourcemanager.rmcontainer.RMContainerImpl: container_1377907764744_0007_01_000019 Container Transitioned from ACQUIRED to RUNNING
2013-08-31 00:26:24,652 INFO org.apache.hadoop.yarn.server.resourcemanager.rmcontainer.RMContainerImpl: container_1377907764744_0007_01_000020 Container Transitioned from ACQUIRED to RUNNING
2013-08-31 00:26:24,654 INFO org.apache.hadoop.yarn.server.resourcemanager.rmcontainer.RMContainerImpl: container_1377907764744_0007_01_000021 Container Transitioned from ACQUIRED to RUNNING
2013-08-31 00:26:24,676 INFO org.apache.hadoop.yarn.server.resourcemanager.rmcontainer.RMContainerImpl: container_1377907764744_0007_01_000022 Container Transitioned from ACQUIRED to RUNNING
2013-08-31 00:26:24,676 INFO org.apache.hadoop.yarn.server.resourcemanager.rmcontainer.RMContainerImpl: container_1377907764744_0007_01_000023 Container Transitioned from ACQUIRED to RUNNING
2013-08-31 00:26:24,677 INFO org.apache.hadoop.yarn.server.resourcemanager.rmcontainer.RMContainerImpl: container_1377907764744_0007_01_000024 Container Transitioned from ACQUIRED to RUNNING
2013-08-31 00:26:24,677 INFO org.apache.hadoop.yarn.server.resourcemanager.rmcontainer.RMContainerImpl: container_1377907764744_0007_01_000025 Container Transitioned from ACQUIRED to RUNNING
2013-08-31 00:26:24,677 INFO org.apache.hadoop.yarn.server.resourcemanager.rmcontainer.RMContainerImpl: container_1377907764744_0007_01_000026 Container Transitioned from ACQUIRED to RUNNING
2013-08-31 00:26:24,678 INFO org.apache.hadoop.yarn.server.resourcemanager.rmcontainer.RMContainerImpl: container_1377907764744_0007_01_000027 Container Transitioned from ACQUIRED to RUNNING
2013-08-31 00:26:24,678 INFO org.apache.hadoop.yarn.server.resourcemanager.rmcontainer.RMContainerImpl: container_1377907764744_0007_01_000028 Container Transitioned from ACQUIRED to RUNNING
2013-08-31 00:26:24,679 INFO org.apache.hadoop.yarn.server.resourcemanager.rmcontainer.RMContainerImpl: container_1377907764744_0007_01_000029 Container Transitioned from ACQUIRED to RUNNING
2013-08-31 00:26:25,324 INFO org.apache.hadoop.yarn.server.resourcemanager.rmcontainer.RMContainerImpl: container_1377907764744_0006_01_000002 Container Transitioned from ACQUIRED to RUNNING
2013-08-31 00:26:25,324 INFO org.apache.hadoop.yarn.server.resourcemanager.rmcontainer.RMContainerImpl: container_1377907764744_0006_01_000003 Container Transitioned from ACQUIRED to RUNNING
2013-08-31 00:26:25,326 INFO org.apache.hadoop.yarn.server.resourcemanager.rmcontainer.RMContainerImpl: container_1377907764744_0006_01_000004 Container Transitioned from ACQUIRED to RUNNING
2013-08-31 00:26:25,326 INFO org.apache.hadoop.yarn.server.resourcemanager.rmcontainer.RMContainerImpl: container_1377907764744_0006_01_000005 Container Transitioned from ACQUIRED to RUNNING
2013-08-31 00:26:25,326 INFO org.apache.hadoop.yarn.server.resourcemanager.rmcontainer.RMContainerImpl: container_1377907764744_0006_01_000006 Container Transitioned from ACQUIRED to RUNNING
2013-08-31 00:26:25,326 INFO org.apache.hadoop.yarn.server.resourcemanager.rmcontainer.RMContainerImpl: container_1377907764744_0006_01_000007 Container Transitioned from ACQUIRED to RUNNING
2013-08-31 00:26:25,390 INFO org.apache.hadoop.yarn.server.resourcemanager.rmcontainer.RMContainerImpl: container_1377907764744_0006_01_000008 Container Transitioned from ACQUIRED to RUNNING
2013-08-31 00:26:25,390 INFO org.apache.hadoop.yarn.server.resourcemanager.rmcontainer.RMContainerImpl: container_1377907764744_0006_01_000009 Container Transitioned from ACQUIRED to RUNNING
2013-08-31 00:26:25,391 INFO org.apache.hadoop.yarn.server.resourcemanager.rmcontainer.RMContainerImpl: container_1377907764744_0006_01_000010 Container Transitioned from ACQUIRED to RUNNING
2013-08-31 00:26:25,391 INFO org.apache.hadoop.yarn.server.resourcemanager.rmcontainer.RMContainerImpl: container_1377907764744_0006_01_000011 Container Transitioned from ACQUIRED to RUNNING
2013-08-31 00:26:25,391 INFO org.apache.hadoop.yarn.server.resourcemanager.rmcontainer.RMContainerImpl: container_1377907764744_0006_01_000012 Container Transitioned from ACQUIRED to RUNNING
2013-08-31 00:26:25,391 INFO org.apache.hadoop.yarn.server.resourcemanager.rmcontainer.RMContainerImpl: container_1377907764744_0006_01_000013 Container Transitioned from ACQUIRED to RUNNING
2013-08-31 00:26:25,391 INFO org.apache.hadoop.yarn.server.resourcemanager.rmcontainer.RMContainerImpl: container_1377907764744_0006_01_000014 Container Transitioned from ACQUIRED to RUNNING
2013-08-31 00:26:25,391 INFO org.apache.hadoop.yarn.server.resourcemanager.rmcontainer.RMContainerImpl: container_1377907764744_0006_01_000015 Container Transitioned from ACQUIRED to RUNNING
2013-08-31 00:26:50,206 INFO org.apache.hadoop.yarn.server.resourcemanager.rmcontainer.RMContainerImpl: container_1377907764744_0006_01_000007 Container Transitioned from RUNNING to COMPLETED
2013-08-31 00:26:50,206 INFO org.apache.hadoop.yarn.server.resourcemanager.scheduler.common.fica.FiCaSchedulerApp: Completed container: container_1377907764744_0006_01_000007 in state: COMPLETED event:FINISHED
2013-08-31 00:26:50,206 INFO org.apache.hadoop.yarn.server.resourcemanager.RMAuditLogger: USER=ubuntu	OPERATION=AM Released Container	TARGET=SchedulerApp	RESULT=SUCCESS	APPID=application_1377907764744_0006	CONTAINERID=container_1377907764744_0006_01_000007
2013-08-31 00:26:50,206 INFO org.apache.hadoop.yarn.server.resourcemanager.scheduler.common.fica.FiCaSchedulerNode: Released container container_1377907764744_0006_01_000007 of capacity <memory:1024, vCores:1> on host hadoop-32-7:54070, which currently has 6 containers, <memory:7168, vCores:6> used and <memory:1024, vCores:10> available, release resources=true
2013-08-31 00:26:50,206 INFO org.apache.hadoop.yarn.server.resourcemanager.scheduler.capacity.LeafQueue: default used=<memory:48128, vCores:44> numContainers=44 user=ubuntu user-resources=<memory:48128, vCores:44>
2013-08-31 00:26:50,209 INFO org.apache.hadoop.yarn.server.resourcemanager.scheduler.capacity.LeafQueue: completedContainer container=Container: [ContainerId: container_1377907764744_0006_01_000007, NodeId: hadoop-32-7:54070, NodeHttpAddress: hadoop-32-7:8042, Resource: <memory:1024, vCores:1>, Priority: 20, State: NEW, Token: null, Status: container_id {, app_attempt_id {, application_id {, id: 6, cluster_timestamp: 1377907764744, }, attemptId: 1, }, id: 7, }, state: C_COMPLETE, diagnostics: "", exit_status: 0, ] resource=<memory:1024, vCores:1> queue=default: capacity=1.0, absoluteCapacity=1.0, usedResources=<memory:48128, vCores:44>usedCapacity=0.9791667, absoluteUsedCapacity=0.9791667, numApps=5, numContainers=44 usedCapacity=0.9791667 absoluteUsedCapacity=0.9791667 used=<memory:48128, vCores:44> cluster=<memory:49152, vCores:96>
2013-08-31 00:26:50,209 INFO org.apache.hadoop.yarn.server.resourcemanager.scheduler.capacity.ParentQueue: completedContainer queue=root usedCapacity=0.9791667 absoluteUsedCapacity=0.9791667 used=<memory:48128, vCores:44> cluster=<memory:49152, vCores:96>
2013-08-31 00:26:50,209 INFO org.apache.hadoop.yarn.server.resourcemanager.scheduler.capacity.CapacityScheduler: Application appattempt_1377907764744_0006_000001 released container container_1377907764744_0006_01_000007 on node: host: hadoop-32-7:54070 #containers=6 available=1024 used=7168 with event: FINISHED
2013-08-31 00:26:50,210 INFO org.apache.hadoop.yarn.server.resourcemanager.rmcontainer.RMContainerImpl: container_1377907764744_0006_01_000016 Container Transitioned from NEW to ALLOCATED
2013-08-31 00:26:50,210 INFO org.apache.hadoop.yarn.server.resourcemanager.RMAuditLogger: USER=ubuntu	OPERATION=AM Allocated Container	TARGET=SchedulerApp	RESULT=SUCCESS	APPID=application_1377907764744_0006	CONTAINERID=container_1377907764744_0006_01_000016
2013-08-31 00:26:50,210 INFO org.apache.hadoop.yarn.server.resourcemanager.scheduler.common.fica.FiCaSchedulerNode: Assigned container container_1377907764744_0006_01_000016 of capacity <memory:1024, vCores:1> on host hadoop-32-7:54070, which currently has 7 containers, <memory:8192, vCores:7> used and <memory:0, vCores:9> available
2013-08-31 00:26:50,211 INFO org.apache.hadoop.yarn.server.resourcemanager.scheduler.capacity.LeafQueue: assignedContainer application=application_1377907764744_0006 container=Container: [ContainerId: container_1377907764744_0006_01_000016, NodeId: hadoop-32-7:54070, NodeHttpAddress: hadoop-32-7:8042, Resource: <memory:1024, vCores:1>, Priority: 20, State: NEW, Token: null, Status: container_id {, app_attempt_id {, application_id {, id: 6, cluster_timestamp: 1377907764744, }, attemptId: 1, }, id: 16, }, state: C_NEW, ] containerId=container_1377907764744_0006_01_000016 queue=default: capacity=1.0, absoluteCapacity=1.0, usedResources=<memory:48128, vCores:44>usedCapacity=0.9791667, absoluteUsedCapacity=0.9791667, numApps=5, numContainers=44 usedCapacity=0.9791667 absoluteUsedCapacity=0.9791667 used=<memory:48128, vCores:44> cluster=<memory:49152, vCores:96>
2013-08-31 00:26:50,211 INFO org.apache.hadoop.yarn.server.resourcemanager.scheduler.capacity.ParentQueue: Re-sorting queues since queue: root.default stats: default: capacity=1.0, absoluteCapacity=1.0, usedResources=<memory:49152, vCores:45>usedCapacity=1.0, absoluteUsedCapacity=1.0, numApps=5, numContainers=45
2013-08-31 00:26:50,211 INFO org.apache.hadoop.yarn.server.resourcemanager.scheduler.capacity.ParentQueue: assignedContainer queue=root usedCapacity=1.0 absoluteUsedCapacity=1.0 used=<memory:49152, vCores:45> cluster=<memory:49152, vCores:96>
2013-08-31 00:26:50,691 INFO org.apache.hadoop.yarn.server.resourcemanager.rmcontainer.RMContainerImpl: container_1377907764744_0006_01_000016 Container Transitioned from ALLOCATED to ACQUIRED
2013-08-31 00:26:51,216 INFO org.apache.hadoop.yarn.server.resourcemanager.rmcontainer.RMContainerImpl: container_1377907764744_0006_01_000016 Container Transitioned from ACQUIRED to RUNNING
2013-08-31 00:26:54,003 INFO org.apache.hadoop.yarn.server.resourcemanager.rmcontainer.RMContainerImpl: container_1377907764744_0007_01_000002 Container Transitioned from RUNNING to COMPLETED
2013-08-31 00:26:54,003 INFO org.apache.hadoop.yarn.server.resourcemanager.scheduler.common.fica.FiCaSchedulerApp: Completed container: container_1377907764744_0007_01_000002 in state: COMPLETED event:FINISHED
2013-08-31 00:26:54,004 INFO org.apache.hadoop.yarn.server.resourcemanager.RMAuditLogger: USER=ubuntu	OPERATION=AM Released Container	TARGET=SchedulerApp	RESULT=SUCCESS	APPID=application_1377907764744_0007	CONTAINERID=container_1377907764744_0007_01_000002
2013-08-31 00:26:54,004 INFO org.apache.hadoop.yarn.server.resourcemanager.scheduler.common.fica.FiCaSchedulerNode: Released container container_1377907764744_0007_01_000002 of capacity <memory:1024, vCores:1> on host hadoop-32-2:38703, which currently has 6 containers, <memory:7168, vCores:6> used and <memory:1024, vCores:10> available, release resources=true
2013-08-31 00:26:54,004 INFO org.apache.hadoop.yarn.server.resourcemanager.scheduler.capacity.LeafQueue: default used=<memory:48128, vCores:44> numContainers=44 user=ubuntu user-resources=<memory:48128, vCores:44>
2013-08-31 00:26:54,005 INFO org.apache.hadoop.yarn.server.resourcemanager.scheduler.capacity.LeafQueue: completedContainer container=Container: [ContainerId: container_1377907764744_0007_01_000002, NodeId: hadoop-32-2:38703, NodeHttpAddress: hadoop-32-2:8042, Resource: <memory:1024, vCores:1>, Priority: 20, State: NEW, Token: null, Status: container_id {, app_attempt_id {, application_id {, id: 7, cluster_timestamp: 1377907764744, }, attemptId: 1, }, id: 2, }, state: C_COMPLETE, diagnostics: "Container killed by the ApplicationMaster.\n", exit_status: 0, ] resource=<memory:1024, vCores:1> queue=default: capacity=1.0, absoluteCapacity=1.0, usedResources=<memory:48128, vCores:44>usedCapacity=0.9791667, absoluteUsedCapacity=0.9791667, numApps=5, numContainers=44 usedCapacity=0.9791667 absoluteUsedCapacity=0.9791667 used=<memory:48128, vCores:44> cluster=<memory:49152, vCores:96>
2013-08-31 00:26:54,005 INFO org.apache.hadoop.yarn.server.resourcemanager.scheduler.capacity.ParentQueue: completedContainer queue=root usedCapacity=0.9791667 absoluteUsedCapacity=0.9791667 used=<memory:48128, vCores:44> cluster=<memory:49152, vCores:96>
2013-08-31 00:26:54,005 INFO org.apache.hadoop.yarn.server.resourcemanager.scheduler.capacity.CapacityScheduler: Application appattempt_1377907764744_0007_000001 released container container_1377907764744_0007_01_000002 on node: host: hadoop-32-2:38703 #containers=6 available=1024 used=7168 with event: FINISHED
2013-08-31 00:26:54,006 INFO org.apache.hadoop.yarn.server.resourcemanager.rmcontainer.RMContainerImpl: container_1377907764744_0007_01_000005 Container Transitioned from RUNNING to COMPLETED
2013-08-31 00:26:54,006 INFO org.apache.hadoop.yarn.server.resourcemanager.scheduler.common.fica.FiCaSchedulerApp: Completed container: container_1377907764744_0007_01_000005 in state: COMPLETED event:FINISHED
2013-08-31 00:26:54,006 INFO org.apache.hadoop.yarn.server.resourcemanager.RMAuditLogger: USER=ubuntu	OPERATION=AM Released Container	TARGET=SchedulerApp	RESULT=SUCCESS	APPID=application_1377907764744_0007	CONTAINERID=container_1377907764744_0007_01_000005
2013-08-31 00:26:54,006 INFO org.apache.hadoop.yarn.server.resourcemanager.scheduler.common.fica.FiCaSchedulerNode: Released container container_1377907764744_0007_01_000005 of capacity <memory:1024, vCores:1> on host hadoop-32-2:38703, which currently has 5 containers, <memory:6144, vCores:5> used and <memory:2048, vCores:11> available, release resources=true
2013-08-31 00:26:54,006 INFO org.apache.hadoop.yarn.server.resourcemanager.scheduler.capacity.LeafQueue: default used=<memory:47104, vCores:43> numContainers=43 user=ubuntu user-resources=<memory:47104, vCores:43>
2013-08-31 00:26:54,007 INFO org.apache.hadoop.yarn.server.resourcemanager.scheduler.capacity.LeafQueue: completedContainer container=Container: [ContainerId: container_1377907764744_0007_01_000005, NodeId: hadoop-32-2:38703, NodeHttpAddress: hadoop-32-2:8042, Resource: <memory:1024, vCores:1>, Priority: 20, State: NEW, Token: null, Status: container_id {, app_attempt_id {, application_id {, id: 7, cluster_timestamp: 1377907764744, }, attemptId: 1, }, id: 5, }, state: C_COMPLETE, diagnostics: "Container killed by the ApplicationMaster.\n", exit_status: 0, ] resource=<memory:1024, vCores:1> queue=default: capacity=1.0, absoluteCapacity=1.0, usedResources=<memory:47104, vCores:43>usedCapacity=0.9583333, absoluteUsedCapacity=0.9583333, numApps=5, numContainers=43 usedCapacity=0.9583333 absoluteUsedCapacity=0.9583333 used=<memory:47104, vCores:43> cluster=<memory:49152, vCores:96>
2013-08-31 00:26:54,007 INFO org.apache.hadoop.yarn.server.resourcemanager.scheduler.capacity.ParentQueue: completedContainer queue=root usedCapacity=0.9583333 absoluteUsedCapacity=0.9583333 used=<memory:47104, vCores:43> cluster=<memory:49152, vCores:96>
2013-08-31 00:26:54,007 INFO org.apache.hadoop.yarn.server.resourcemanager.scheduler.capacity.CapacityScheduler: Application appattempt_1377907764744_0007_000001 released container container_1377907764744_0007_01_000005 on node: host: hadoop-32-2:38703 #containers=5 available=2048 used=6144 with event: FINISHED
2013-08-31 00:26:54,008 INFO org.apache.hadoop.yarn.server.resourcemanager.rmcontainer.RMContainerImpl: container_1377907764744_0007_01_000007 Container Transitioned from RUNNING to COMPLETED
2013-08-31 00:26:54,008 INFO org.apache.hadoop.yarn.server.resourcemanager.scheduler.common.fica.FiCaSchedulerApp: Completed container: container_1377907764744_0007_01_000007 in state: COMPLETED event:FINISHED
2013-08-31 00:26:54,008 INFO org.apache.hadoop.yarn.server.resourcemanager.RMAuditLogger: USER=ubuntu	OPERATION=AM Released Container	TARGET=SchedulerApp	RESULT=SUCCESS	APPID=application_1377907764744_0007	CONTAINERID=container_1377907764744_0007_01_000007
2013-08-31 00:26:54,008 INFO org.apache.hadoop.yarn.server.resourcemanager.scheduler.common.fica.FiCaSchedulerNode: Released container container_1377907764744_0007_01_000007 of capacity <memory:1024, vCores:1> on host hadoop-32-2:38703, which currently has 4 containers, <memory:5120, vCores:4> used and <memory:3072, vCores:12> available, release resources=true
2013-08-31 00:26:54,008 INFO org.apache.hadoop.yarn.server.resourcemanager.scheduler.capacity.LeafQueue: default used=<memory:46080, vCores:42> numContainers=42 user=ubuntu user-resources=<memory:46080, vCores:42>
2013-08-31 00:26:54,009 INFO org.apache.hadoop.yarn.server.resourcemanager.scheduler.capacity.LeafQueue: completedContainer container=Container: [ContainerId: container_1377907764744_0007_01_000007, NodeId: hadoop-32-2:38703, NodeHttpAddress: hadoop-32-2:8042, Resource: <memory:1024, vCores:1>, Priority: 20, State: NEW, Token: null, Status: container_id {, app_attempt_id {, application_id {, id: 7, cluster_timestamp: 1377907764744, }, attemptId: 1, }, id: 7, }, state: C_COMPLETE, diagnostics: "Container killed by the ApplicationMaster.\n", exit_status: 0, ] resource=<memory:1024, vCores:1> queue=default: capacity=1.0, absoluteCapacity=1.0, usedResources=<memory:46080, vCores:42>usedCapacity=0.9375, absoluteUsedCapacity=0.9375, numApps=5, numContainers=42 usedCapacity=0.9375 absoluteUsedCapacity=0.9375 used=<memory:46080, vCores:42> cluster=<memory:49152, vCores:96>
2013-08-31 00:26:54,009 INFO org.apache.hadoop.yarn.server.resourcemanager.scheduler.capacity.ParentQueue: completedContainer queue=root usedCapacity=0.9375 absoluteUsedCapacity=0.9375 used=<memory:46080, vCores:42> cluster=<memory:49152, vCores:96>
2013-08-31 00:26:54,009 INFO org.apache.hadoop.yarn.server.resourcemanager.scheduler.capacity.CapacityScheduler: Application appattempt_1377907764744_0007_000001 released container container_1377907764744_0007_01_000007 on node: host: hadoop-32-2:38703 #containers=4 available=3072 used=5120 with event: FINISHED
2013-08-31 00:26:54,010 INFO org.apache.hadoop.yarn.server.resourcemanager.rmcontainer.RMContainerImpl: container_1377907764744_0006_01_000017 Container Transitioned from NEW to ALLOCATED
2013-08-31 00:26:54,010 INFO org.apache.hadoop.yarn.server.resourcemanager.RMAuditLogger: USER=ubuntu	OPERATION=AM Allocated Container	TARGET=SchedulerApp	RESULT=SUCCESS	APPID=application_1377907764744_0006	CONTAINERID=container_1377907764744_0006_01_000017
2013-08-31 00:26:54,010 INFO org.apache.hadoop.yarn.server.resourcemanager.scheduler.common.fica.FiCaSchedulerNode: Assigned container container_1377907764744_0006_01_000017 of capacity <memory:1024, vCores:1> on host hadoop-32-2:38703, which currently has 5 containers, <memory:6144, vCores:5> used and <memory:2048, vCores:11> available
2013-08-31 00:26:54,011 INFO org.apache.hadoop.yarn.server.resourcemanager.scheduler.capacity.LeafQueue: assignedContainer application=application_1377907764744_0006 container=Container: [ContainerId: container_1377907764744_0006_01_000017, NodeId: hadoop-32-2:38703, NodeHttpAddress: hadoop-32-2:8042, Resource: <memory:1024, vCores:1>, Priority: 20, State: NEW, Token: null, Status: container_id {, app_attempt_id {, application_id {, id: 6, cluster_timestamp: 1377907764744, }, attemptId: 1, }, id: 17, }, state: C_NEW, ] containerId=container_1377907764744_0006_01_000017 queue=default: capacity=1.0, absoluteCapacity=1.0, usedResources=<memory:46080, vCores:42>usedCapacity=0.9375, absoluteUsedCapacity=0.9375, numApps=5, numContainers=42 usedCapacity=0.9375 absoluteUsedCapacity=0.9375 used=<memory:46080, vCores:42> cluster=<memory:49152, vCores:96>
2013-08-31 00:26:54,011 INFO org.apache.hadoop.yarn.server.resourcemanager.scheduler.capacity.ParentQueue: Re-sorting queues since queue: root.default stats: default: capacity=1.0, absoluteCapacity=1.0, usedResources=<memory:47104, vCores:43>usedCapacity=0.9583333, absoluteUsedCapacity=0.9583333, numApps=5, numContainers=43
2013-08-31 00:26:54,011 INFO org.apache.hadoop.yarn.server.resourcemanager.scheduler.capacity.ParentQueue: assignedContainer queue=root usedCapacity=0.9583333 absoluteUsedCapacity=0.9583333 used=<memory:47104, vCores:43> cluster=<memory:49152, vCores:96>
2013-08-31 00:26:54,012 INFO org.apache.hadoop.yarn.server.resourcemanager.rmcontainer.RMContainerImpl: container_1377907764744_0006_01_000018 Container Transitioned from NEW to ALLOCATED
2013-08-31 00:26:54,012 INFO org.apache.hadoop.yarn.server.resourcemanager.RMAuditLogger: USER=ubuntu	OPERATION=AM Allocated Container	TARGET=SchedulerApp	RESULT=SUCCESS	APPID=application_1377907764744_0006	CONTAINERID=container_1377907764744_0006_01_000018
2013-08-31 00:26:54,012 INFO org.apache.hadoop.yarn.server.resourcemanager.scheduler.common.fica.FiCaSchedulerNode: Assigned container container_1377907764744_0006_01_000018 of capacity <memory:1024, vCores:1> on host hadoop-32-2:38703, which currently has 6 containers, <memory:7168, vCores:6> used and <memory:1024, vCores:10> available
2013-08-31 00:26:54,013 INFO org.apache.hadoop.yarn.server.resourcemanager.scheduler.capacity.LeafQueue: assignedContainer application=application_1377907764744_0006 container=Container: [ContainerId: container_1377907764744_0006_01_000018, NodeId: hadoop-32-2:38703, NodeHttpAddress: hadoop-32-2:8042, Resource: <memory:1024, vCores:1>, Priority: 20, State: NEW, Token: null, Status: container_id {, app_attempt_id {, application_id {, id: 6, cluster_timestamp: 1377907764744, }, attemptId: 1, }, id: 18, }, state: C_NEW, ] containerId=container_1377907764744_0006_01_000018 queue=default: capacity=1.0, absoluteCapacity=1.0, usedResources=<memory:47104, vCores:43>usedCapacity=0.9583333, absoluteUsedCapacity=0.9583333, numApps=5, numContainers=43 usedCapacity=0.9583333 absoluteUsedCapacity=0.9583333 used=<memory:47104, vCores:43> cluster=<memory:49152, vCores:96>
2013-08-31 00:26:54,013 INFO org.apache.hadoop.yarn.server.resourcemanager.scheduler.capacity.ParentQueue: Re-sorting queues since queue: root.default stats: default: capacity=1.0, absoluteCapacity=1.0, usedResources=<memory:48128, vCores:44>usedCapacity=0.9791667, absoluteUsedCapacity=0.9791667, numApps=5, numContainers=44
2013-08-31 00:26:54,013 INFO org.apache.hadoop.yarn.server.resourcemanager.scheduler.capacity.ParentQueue: assignedContainer queue=root usedCapacity=0.9791667 absoluteUsedCapacity=0.9791667 used=<memory:48128, vCores:44> cluster=<memory:49152, vCores:96>
2013-08-31 00:26:54,014 INFO org.apache.hadoop.yarn.server.resourcemanager.rmcontainer.RMContainerImpl: container_1377907764744_0006_01_000019 Container Transitioned from NEW to ALLOCATED
2013-08-31 00:26:54,014 INFO org.apache.hadoop.yarn.server.resourcemanager.RMAuditLogger: USER=ubuntu	OPERATION=AM Allocated Container	TARGET=SchedulerApp	RESULT=SUCCESS	APPID=application_1377907764744_0006	CONTAINERID=container_1377907764744_0006_01_000019
2013-08-31 00:26:54,014 INFO org.apache.hadoop.yarn.server.resourcemanager.scheduler.common.fica.FiCaSchedulerNode: Assigned container container_1377907764744_0006_01_000019 of capacity <memory:1024, vCores:1> on host hadoop-32-2:38703, which currently has 7 containers, <memory:8192, vCores:7> used and <memory:0, vCores:9> available
2013-08-31 00:26:54,015 INFO org.apache.hadoop.yarn.server.resourcemanager.scheduler.capacity.LeafQueue: assignedContainer application=application_1377907764744_0006 container=Container: [ContainerId: container_1377907764744_0006_01_000019, NodeId: hadoop-32-2:38703, NodeHttpAddress: hadoop-32-2:8042, Resource: <memory:1024, vCores:1>, Priority: 20, State: NEW, Token: null, Status: container_id {, app_attempt_id {, application_id {, id: 6, cluster_timestamp: 1377907764744, }, attemptId: 1, }, id: 19, }, state: C_NEW, ] containerId=container_1377907764744_0006_01_000019 queue=default: capacity=1.0, absoluteCapacity=1.0, usedResources=<memory:48128, vCores:44>usedCapacity=0.9791667, absoluteUsedCapacity=0.9791667, numApps=5, numContainers=44 usedCapacity=0.9791667 absoluteUsedCapacity=0.9791667 used=<memory:48128, vCores:44> cluster=<memory:49152, vCores:96>
2013-08-31 00:26:54,015 INFO org.apache.hadoop.yarn.server.resourcemanager.scheduler.capacity.ParentQueue: Re-sorting queues since queue: root.default stats: default: capacity=1.0, absoluteCapacity=1.0, usedResources=<memory:49152, vCores:45>usedCapacity=1.0, absoluteUsedCapacity=1.0, numApps=5, numContainers=45
2013-08-31 00:26:54,015 INFO org.apache.hadoop.yarn.server.resourcemanager.scheduler.capacity.ParentQueue: assignedContainer queue=root usedCapacity=1.0 absoluteUsedCapacity=1.0 used=<memory:49152, vCores:45> cluster=<memory:49152, vCores:96>
2013-08-31 00:26:54,828 INFO org.apache.hadoop.yarn.server.resourcemanager.rmcontainer.RMContainerImpl: container_1377907764744_0006_01_000017 Container Transitioned from ALLOCATED to ACQUIRED
2013-08-31 00:26:54,833 INFO org.apache.hadoop.yarn.server.resourcemanager.rmcontainer.RMContainerImpl: container_1377907764744_0006_01_000018 Container Transitioned from ALLOCATED to ACQUIRED
2013-08-31 00:26:54,833 INFO org.apache.hadoop.yarn.server.resourcemanager.rmcontainer.RMContainerImpl: container_1377907764744_0006_01_000019 Container Transitioned from ALLOCATED to ACQUIRED
2013-08-31 00:26:55,932 INFO org.apache.hadoop.yarn.server.resourcemanager.rmcontainer.RMContainerImpl: container_1377907764744_0006_01_000002 Container Transitioned from RUNNING to COMPLETED
2013-08-31 00:26:55,932 INFO org.apache.hadoop.yarn.server.resourcemanager.scheduler.common.fica.FiCaSchedulerApp: Completed container: container_1377907764744_0006_01_000002 in state: COMPLETED event:FINISHED
2013-08-31 00:26:55,932 INFO org.apache.hadoop.yarn.server.resourcemanager.RMAuditLogger: USER=ubuntu	OPERATION=AM Released Container	TARGET=SchedulerApp	RESULT=SUCCESS	APPID=application_1377907764744_0006	CONTAINERID=container_1377907764744_0006_01_000002
2013-08-31 00:26:55,933 INFO org.apache.hadoop.yarn.server.resourcemanager.scheduler.common.fica.FiCaSchedulerNode: Released container container_1377907764744_0006_01_000002 of capacity <memory:1024, vCores:1> on host hadoop-32-7:54070, which currently has 6 containers, <memory:7168, vCores:6> used and <memory:1024, vCores:10> available, release resources=true
2013-08-31 00:26:55,933 INFO org.apache.hadoop.yarn.server.resourcemanager.scheduler.capacity.LeafQueue: default used=<memory:48128, vCores:44> numContainers=44 user=ubuntu user-resources=<memory:48128, vCores:44>
2013-08-31 00:26:55,934 INFO org.apache.hadoop.yarn.server.resourcemanager.scheduler.capacity.LeafQueue: completedContainer container=Container: [ContainerId: container_1377907764744_0006_01_000002, NodeId: hadoop-32-7:54070, NodeHttpAddress: hadoop-32-7:8042, Resource: <memory:1024, vCores:1>, Priority: 20, State: NEW, Token: null, Status: container_id {, app_attempt_id {, application_id {, id: 6, cluster_timestamp: 1377907764744, }, attemptId: 1, }, id: 2, }, state: C_COMPLETE, diagnostics: "Container killed by the ApplicationMaster.\n\n", exit_status: 143, ] resource=<memory:1024, vCores:1> queue=default: capacity=1.0, absoluteCapacity=1.0, usedResources=<memory:48128, vCores:44>usedCapacity=0.9791667, absoluteUsedCapacity=0.9791667, numApps=5, numContainers=44 usedCapacity=0.9791667 absoluteUsedCapacity=0.9791667 used=<memory:48128, vCores:44> cluster=<memory:49152, vCores:96>
2013-08-31 00:26:55,934 INFO org.apache.hadoop.yarn.server.resourcemanager.scheduler.capacity.ParentQueue: completedContainer queue=root usedCapacity=0.9791667 absoluteUsedCapacity=0.9791667 used=<memory:48128, vCores:44> cluster=<memory:49152, vCores:96>
2013-08-31 00:26:55,934 INFO org.apache.hadoop.yarn.server.resourcemanager.scheduler.capacity.CapacityScheduler: Application appattempt_1377907764744_0006_000001 released container container_1377907764744_0006_01_000002 on node: host: hadoop-32-7:54070 #containers=6 available=1024 used=7168 with event: FINISHED
2013-08-31 00:26:55,935 INFO org.apache.hadoop.yarn.server.resourcemanager.rmcontainer.RMContainerImpl: container_1377907764744_0006_01_000020 Container Transitioned from NEW to ALLOCATED
2013-08-31 00:26:55,935 INFO org.apache.hadoop.yarn.server.resourcemanager.RMAuditLogger: USER=ubuntu	OPERATION=AM Allocated Container	TARGET=SchedulerApp	RESULT=SUCCESS	APPID=application_1377907764744_0006	CONTAINERID=container_1377907764744_0006_01_000020
2013-08-31 00:26:55,935 INFO org.apache.hadoop.yarn.server.resourcemanager.scheduler.common.fica.FiCaSchedulerNode: Assigned container container_1377907764744_0006_01_000020 of capacity <memory:1024, vCores:1> on host hadoop-32-7:54070, which currently has 7 containers, <memory:8192, vCores:7> used and <memory:0, vCores:9> available
2013-08-31 00:26:55,936 INFO org.apache.hadoop.yarn.server.resourcemanager.scheduler.capacity.LeafQueue: assignedContainer application=application_1377907764744_0006 container=Container: [ContainerId: container_1377907764744_0006_01_000020, NodeId: hadoop-32-7:54070, NodeHttpAddress: hadoop-32-7:8042, Resource: <memory:1024, vCores:1>, Priority: 20, State: NEW, Token: null, Status: container_id {, app_attempt_id {, application_id {, id: 6, cluster_timestamp: 1377907764744, }, attemptId: 1, }, id: 20, }, state: C_NEW, ] containerId=container_1377907764744_0006_01_000020 queue=default: capacity=1.0, absoluteCapacity=1.0, usedResources=<memory:48128, vCores:44>usedCapacity=0.9791667, absoluteUsedCapacity=0.9791667, numApps=5, numContainers=44 usedCapacity=0.9791667 absoluteUsedCapacity=0.9791667 used=<memory:48128, vCores:44> cluster=<memory:49152, vCores:96>
2013-08-31 00:26:55,936 INFO org.apache.hadoop.yarn.server.resourcemanager.scheduler.capacity.ParentQueue: Re-sorting queues since queue: root.default stats: default: capacity=1.0, absoluteCapacity=1.0, usedResources=<memory:49152, vCores:45>usedCapacity=1.0, absoluteUsedCapacity=1.0, numApps=5, numContainers=45
2013-08-31 00:26:55,936 INFO org.apache.hadoop.yarn.server.resourcemanager.scheduler.capacity.ParentQueue: assignedContainer queue=root usedCapacity=1.0 absoluteUsedCapacity=1.0 used=<memory:49152, vCores:45> cluster=<memory:49152, vCores:96>
2013-08-31 00:26:56,291 INFO org.apache.hadoop.yarn.server.resourcemanager.rmcontainer.RMContainerImpl: container_1377907764744_0006_01_000017 Container Transitioned from ACQUIRED to RUNNING
2013-08-31 00:26:56,291 INFO org.apache.hadoop.yarn.server.resourcemanager.rmcontainer.RMContainerImpl: container_1377907764744_0006_01_000018 Container Transitioned from ACQUIRED to RUNNING
2013-08-31 00:26:56,291 INFO org.apache.hadoop.yarn.server.resourcemanager.rmcontainer.RMContainerImpl: container_1377907764744_0006_01_000019 Container Transitioned from ACQUIRED to RUNNING
2013-08-31 00:26:56,849 INFO org.apache.hadoop.yarn.server.resourcemanager.rmcontainer.RMContainerImpl: container_1377907764744_0006_01_000020 Container Transitioned from ALLOCATED to ACQUIRED
2013-08-31 00:26:56,938 INFO org.apache.hadoop.yarn.server.resourcemanager.rmcontainer.RMContainerImpl: container_1377907764744_0006_01_000020 Container Transitioned from ACQUIRED to RUNNING
2013-08-31 00:26:57,218 INFO org.apache.hadoop.yarn.server.resourcemanager.rmcontainer.RMContainerImpl: container_1377907764744_0007_01_000012 Container Transitioned from RUNNING to COMPLETED
2013-08-31 00:26:57,218 INFO org.apache.hadoop.yarn.server.resourcemanager.scheduler.common.fica.FiCaSchedulerApp: Completed container: container_1377907764744_0007_01_000012 in state: COMPLETED event:FINISHED
2013-08-31 00:26:57,219 INFO org.apache.hadoop.yarn.server.resourcemanager.RMAuditLogger: USER=ubuntu	OPERATION=AM Released Container	TARGET=SchedulerApp	RESULT=SUCCESS	APPID=application_1377907764744_0007	CONTAINERID=container_1377907764744_0007_01_000012
2013-08-31 00:26:57,219 INFO org.apache.hadoop.yarn.server.resourcemanager.scheduler.common.fica.FiCaSchedulerNode: Released container container_1377907764744_0007_01_000012 of capacity <memory:1024, vCores:1> on host hadoop-32-4:58137, which currently has 7 containers, <memory:7168, vCores:7> used and <memory:1024, vCores:9> available, release resources=true
2013-08-31 00:26:57,219 INFO org.apache.hadoop.yarn.server.resourcemanager.scheduler.capacity.LeafQueue: default used=<memory:48128, vCores:44> numContainers=44 user=ubuntu user-resources=<memory:48128, vCores:44>
2013-08-31 00:26:57,220 INFO org.apache.hadoop.yarn.server.resourcemanager.scheduler.capacity.LeafQueue: completedContainer container=Container: [ContainerId: container_1377907764744_0007_01_000012, NodeId: hadoop-32-4:58137, NodeHttpAddress: hadoop-32-4:8042, Resource: <memory:1024, vCores:1>, Priority: 20, State: NEW, Token: null, Status: container_id {, app_attempt_id {, application_id {, id: 7, cluster_timestamp: 1377907764744, }, attemptId: 1, }, id: 12, }, state: C_COMPLETE, diagnostics: "Container killed by the ApplicationMaster.\n\n", exit_status: 143, ] resource=<memory:1024, vCores:1> queue=default: capacity=1.0, absoluteCapacity=1.0, usedResources=<memory:48128, vCores:44>usedCapacity=0.9791667, absoluteUsedCapacity=0.9791667, numApps=5, numContainers=44 usedCapacity=0.9791667 absoluteUsedCapacity=0.9791667 used=<memory:48128, vCores:44> cluster=<memory:49152, vCores:96>
2013-08-31 00:26:57,220 INFO org.apache.hadoop.yarn.server.resourcemanager.scheduler.capacity.ParentQueue: completedContainer queue=root usedCapacity=0.9791667 absoluteUsedCapacity=0.9791667 used=<memory:48128, vCores:44> cluster=<memory:49152, vCores:96>
2013-08-31 00:26:57,220 INFO org.apache.hadoop.yarn.server.resourcemanager.scheduler.capacity.CapacityScheduler: Application appattempt_1377907764744_0007_000001 released container container_1377907764744_0007_01_000012 on node: host: hadoop-32-4:58137 #containers=7 available=1024 used=7168 with event: FINISHED
2013-08-31 00:26:57,221 INFO org.apache.hadoop.yarn.server.resourcemanager.rmcontainer.RMContainerImpl: container_1377907764744_0006_01_000021 Container Transitioned from NEW to ALLOCATED
2013-08-31 00:26:57,221 INFO org.apache.hadoop.yarn.server.resourcemanager.RMAuditLogger: USER=ubuntu	OPERATION=AM Allocated Container	TARGET=SchedulerApp	RESULT=SUCCESS	APPID=application_1377907764744_0006	CONTAINERID=container_1377907764744_0006_01_000021
2013-08-31 00:26:57,221 INFO org.apache.hadoop.yarn.server.resourcemanager.scheduler.common.fica.FiCaSchedulerNode: Assigned container container_1377907764744_0006_01_000021 of capacity <memory:1024, vCores:1> on host hadoop-32-4:58137, which currently has 8 containers, <memory:8192, vCores:8> used and <memory:0, vCores:8> available
2013-08-31 00:26:57,222 INFO org.apache.hadoop.yarn.server.resourcemanager.scheduler.capacity.LeafQueue: assignedContainer application=application_1377907764744_0006 container=Container: [ContainerId: container_1377907764744_0006_01_000021, NodeId: hadoop-32-4:58137, NodeHttpAddress: hadoop-32-4:8042, Resource: <memory:1024, vCores:1>, Priority: 20, State: NEW, Token: null, Status: container_id {, app_attempt_id {, application_id {, id: 6, cluster_timestamp: 1377907764744, }, attemptId: 1, }, id: 21, }, state: C_NEW, ] containerId=container_1377907764744_0006_01_000021 queue=default: capacity=1.0, absoluteCapacity=1.0, usedResources=<memory:48128, vCores:44>usedCapacity=0.9791667, absoluteUsedCapacity=0.9791667, numApps=5, numContainers=44 usedCapacity=0.9791667 absoluteUsedCapacity=0.9791667 used=<memory:48128, vCores:44> cluster=<memory:49152, vCores:96>
2013-08-31 00:26:57,222 INFO org.apache.hadoop.yarn.server.resourcemanager.scheduler.capacity.ParentQueue: Re-sorting queues since queue: root.default stats: default: capacity=1.0, absoluteCapacity=1.0, usedResources=<memory:49152, vCores:45>usedCapacity=1.0, absoluteUsedCapacity=1.0, numApps=5, numContainers=45
2013-08-31 00:26:57,222 INFO org.apache.hadoop.yarn.server.resourcemanager.scheduler.capacity.ParentQueue: assignedContainer queue=root usedCapacity=1.0 absoluteUsedCapacity=1.0 used=<memory:49152, vCores:45> cluster=<memory:49152, vCores:96>
2013-08-31 00:26:57,917 INFO org.apache.hadoop.yarn.server.resourcemanager.rmcontainer.RMContainerImpl: container_1377907764744_0006_01_000021 Container Transitioned from ALLOCATED to ACQUIRED
2013-08-31 00:26:58,046 INFO org.apache.hadoop.yarn.server.resourcemanager.rmcontainer.RMContainerImpl: container_1377907764744_0006_01_000005 Container Transitioned from RUNNING to COMPLETED
2013-08-31 00:26:58,047 INFO org.apache.hadoop.yarn.server.resourcemanager.scheduler.common.fica.FiCaSchedulerApp: Completed container: container_1377907764744_0006_01_000005 in state: COMPLETED event:FINISHED
2013-08-31 00:26:58,047 INFO org.apache.hadoop.yarn.server.resourcemanager.RMAuditLogger: USER=ubuntu	OPERATION=AM Released Container	TARGET=SchedulerApp	RESULT=SUCCESS	APPID=application_1377907764744_0006	CONTAINERID=container_1377907764744_0006_01_000005
2013-08-31 00:26:58,047 INFO org.apache.hadoop.yarn.server.resourcemanager.scheduler.common.fica.FiCaSchedulerNode: Released container container_1377907764744_0006_01_000005 of capacity <memory:1024, vCores:1> on host hadoop-32-7:54070, which currently has 6 containers, <memory:7168, vCores:6> used and <memory:1024, vCores:10> available, release resources=true
2013-08-31 00:26:58,047 INFO org.apache.hadoop.yarn.server.resourcemanager.scheduler.capacity.LeafQueue: default used=<memory:48128, vCores:44> numContainers=44 user=ubuntu user-resources=<memory:48128, vCores:44>
2013-08-31 00:26:58,052 INFO org.apache.hadoop.yarn.server.resourcemanager.scheduler.capacity.LeafQueue: completedContainer container=Container: [ContainerId: container_1377907764744_0006_01_000005, NodeId: hadoop-32-7:54070, NodeHttpAddress: hadoop-32-7:8042, Resource: <memory:1024, vCores:1>, Priority: 20, State: NEW, Token: null, Status: container_id {, app_attempt_id {, application_id {, id: 6, cluster_timestamp: 1377907764744, }, attemptId: 1, }, id: 5, }, state: C_COMPLETE, diagnostics: "Container killed by the ApplicationMaster.\n\n", exit_status: 143, ] resource=<memory:1024, vCores:1> queue=default: capacity=1.0, absoluteCapacity=1.0, usedResources=<memory:48128, vCores:44>usedCapacity=0.9791667, absoluteUsedCapacity=0.9791667, numApps=5, numContainers=44 usedCapacity=0.9791667 absoluteUsedCapacity=0.9791667 used=<memory:48128, vCores:44> cluster=<memory:49152, vCores:96>
2013-08-31 00:26:58,052 INFO org.apache.hadoop.yarn.server.resourcemanager.scheduler.capacity.ParentQueue: completedContainer queue=root usedCapacity=0.9791667 absoluteUsedCapacity=0.9791667 used=<memory:48128, vCores:44> cluster=<memory:49152, vCores:96>
2013-08-31 00:26:58,052 INFO org.apache.hadoop.yarn.server.resourcemanager.scheduler.capacity.CapacityScheduler: Application appattempt_1377907764744_0006_000001 released container container_1377907764744_0006_01_000005 on node: host: hadoop-32-7:54070 #containers=6 available=1024 used=7168 with event: FINISHED
2013-08-31 00:26:58,053 INFO org.apache.hadoop.yarn.server.resourcemanager.rmcontainer.RMContainerImpl: container_1377907764744_0006_01_000022 Container Transitioned from NEW to ALLOCATED
2013-08-31 00:26:58,053 INFO org.apache.hadoop.yarn.server.resourcemanager.RMAuditLogger: USER=ubuntu	OPERATION=AM Allocated Container	TARGET=SchedulerApp	RESULT=SUCCESS	APPID=application_1377907764744_0006	CONTAINERID=container_1377907764744_0006_01_000022
2013-08-31 00:26:58,053 INFO org.apache.hadoop.yarn.server.resourcemanager.scheduler.common.fica.FiCaSchedulerNode: Assigned container container_1377907764744_0006_01_000022 of capacity <memory:1024, vCores:1> on host hadoop-32-7:54070, which currently has 7 containers, <memory:8192, vCores:7> used and <memory:0, vCores:9> available
2013-08-31 00:26:58,054 INFO org.apache.hadoop.yarn.server.resourcemanager.scheduler.capacity.LeafQueue: assignedContainer application=application_1377907764744_0006 container=Container: [ContainerId: container_1377907764744_0006_01_000022, NodeId: hadoop-32-7:54070, NodeHttpAddress: hadoop-32-7:8042, Resource: <memory:1024, vCores:1>, Priority: 20, State: NEW, Token: null, Status: container_id {, app_attempt_id {, application_id {, id: 6, cluster_timestamp: 1377907764744, }, attemptId: 1, }, id: 22, }, state: C_NEW, ] containerId=container_1377907764744_0006_01_000022 queue=default: capacity=1.0, absoluteCapacity=1.0, usedResources=<memory:48128, vCores:44>usedCapacity=0.9791667, absoluteUsedCapacity=0.9791667, numApps=5, numContainers=44 usedCapacity=0.9791667 absoluteUsedCapacity=0.9791667 used=<memory:48128, vCores:44> cluster=<memory:49152, vCores:96>
2013-08-31 00:26:58,054 INFO org.apache.hadoop.yarn.server.resourcemanager.scheduler.capacity.ParentQueue: Re-sorting queues since queue: root.default stats: default: capacity=1.0, absoluteCapacity=1.0, usedResources=<memory:49152, vCores:45>usedCapacity=1.0, absoluteUsedCapacity=1.0, numApps=5, numContainers=45
2013-08-31 00:26:58,054 INFO org.apache.hadoop.yarn.server.resourcemanager.scheduler.capacity.ParentQueue: assignedContainer queue=root usedCapacity=1.0 absoluteUsedCapacity=1.0 used=<memory:49152, vCores:45> cluster=<memory:49152, vCores:96>
2013-08-31 00:26:58,229 INFO org.apache.hadoop.yarn.server.resourcemanager.rmcontainer.RMContainerImpl: container_1377907764744_0006_01_000021 Container Transitioned from ACQUIRED to RUNNING
2013-08-31 00:26:58,229 INFO org.apache.hadoop.yarn.server.resourcemanager.rmcontainer.RMContainerImpl: container_1377907764744_0007_01_000014 Container Transitioned from RUNNING to COMPLETED
2013-08-31 00:26:58,229 INFO org.apache.hadoop.yarn.server.resourcemanager.scheduler.common.fica.FiCaSchedulerApp: Completed container: container_1377907764744_0007_01_000014 in state: COMPLETED event:FINISHED
2013-08-31 00:26:58,229 INFO org.apache.hadoop.yarn.server.resourcemanager.RMAuditLogger: USER=ubuntu	OPERATION=AM Released Container	TARGET=SchedulerApp	RESULT=SUCCESS	APPID=application_1377907764744_0007	CONTAINERID=container_1377907764744_0007_01_000014
2013-08-31 00:26:58,229 INFO org.apache.hadoop.yarn.server.resourcemanager.scheduler.common.fica.FiCaSchedulerNode: Released container container_1377907764744_0007_01_000014 of capacity <memory:1024, vCores:1> on host hadoop-32-4:58137, which currently has 7 containers, <memory:7168, vCores:7> used and <memory:1024, vCores:9> available, release resources=true
2013-08-31 00:26:58,230 INFO org.apache.hadoop.yarn.server.resourcemanager.scheduler.capacity.LeafQueue: default used=<memory:48128, vCores:44> numContainers=44 user=ubuntu user-resources=<memory:48128, vCores:44>
2013-08-31 00:26:58,231 INFO org.apache.hadoop.yarn.server.resourcemanager.scheduler.capacity.LeafQueue: completedContainer container=Container: [ContainerId: container_1377907764744_0007_01_000014, NodeId: hadoop-32-4:58137, NodeHttpAddress: hadoop-32-4:8042, Resource: <memory:1024, vCores:1>, Priority: 20, State: NEW, Token: null, Status: container_id {, app_attempt_id {, application_id {, id: 7, cluster_timestamp: 1377907764744, }, attemptId: 1, }, id: 14, }, state: C_COMPLETE, diagnostics: "Container killed by the ApplicationMaster.\n\n", exit_status: 143, ] resource=<memory:1024, vCores:1> queue=default: capacity=1.0, absoluteCapacity=1.0, usedResources=<memory:48128, vCores:44>usedCapacity=0.9791667, absoluteUsedCapacity=0.9791667, numApps=5, numContainers=44 usedCapacity=0.9791667 absoluteUsedCapacity=0.9791667 used=<memory:48128, vCores:44> cluster=<memory:49152, vCores:96>
2013-08-31 00:26:58,231 INFO org.apache.hadoop.yarn.server.resourcemanager.scheduler.capacity.ParentQueue: completedContainer queue=root usedCapacity=0.9791667 absoluteUsedCapacity=0.9791667 used=<memory:48128, vCores:44> cluster=<memory:49152, vCores:96>
2013-08-31 00:26:58,231 INFO org.apache.hadoop.yarn.server.resourcemanager.scheduler.capacity.CapacityScheduler: Application appattempt_1377907764744_0007_000001 released container container_1377907764744_0007_01_000014 on node: host: hadoop-32-4:58137 #containers=7 available=1024 used=7168 with event: FINISHED
2013-08-31 00:26:58,231 INFO org.apache.hadoop.yarn.server.resourcemanager.rmcontainer.RMContainerImpl: container_1377907764744_0006_01_000023 Container Transitioned from NEW to ALLOCATED
2013-08-31 00:26:58,231 INFO org.apache.hadoop.yarn.server.resourcemanager.RMAuditLogger: USER=ubuntu	OPERATION=AM Allocated Container	TARGET=SchedulerApp	RESULT=SUCCESS	APPID=application_1377907764744_0006	CONTAINERID=container_1377907764744_0006_01_000023
2013-08-31 00:26:58,232 INFO org.apache.hadoop.yarn.server.resourcemanager.scheduler.common.fica.FiCaSchedulerNode: Assigned container container_1377907764744_0006_01_000023 of capacity <memory:1024, vCores:1> on host hadoop-32-4:58137, which currently has 8 containers, <memory:8192, vCores:8> used and <memory:0, vCores:8> available
2013-08-31 00:26:58,232 INFO org.apache.hadoop.yarn.server.resourcemanager.scheduler.capacity.LeafQueue: assignedContainer application=application_1377907764744_0006 container=Container: [ContainerId: container_1377907764744_0006_01_000023, NodeId: hadoop-32-4:58137, NodeHttpAddress: hadoop-32-4:8042, Resource: <memory:1024, vCores:1>, Priority: 20, State: NEW, Token: null, Status: container_id {, app_attempt_id {, application_id {, id: 6, cluster_timestamp: 1377907764744, }, attemptId: 1, }, id: 23, }, state: C_NEW, ] containerId=container_1377907764744_0006_01_000023 queue=default: capacity=1.0, absoluteCapacity=1.0, usedResources=<memory:48128, vCores:44>usedCapacity=0.9791667, absoluteUsedCapacity=0.9791667, numApps=5, numContainers=44 usedCapacity=0.9791667 absoluteUsedCapacity=0.9791667 used=<memory:48128, vCores:44> cluster=<memory:49152, vCores:96>
2013-08-31 00:26:58,233 INFO org.apache.hadoop.yarn.server.resourcemanager.scheduler.capacity.ParentQueue: Re-sorting queues since queue: root.default stats: default: capacity=1.0, absoluteCapacity=1.0, usedResources=<memory:49152, vCores:45>usedCapacity=1.0, absoluteUsedCapacity=1.0, numApps=5, numContainers=45
2013-08-31 00:26:58,233 INFO org.apache.hadoop.yarn.server.resourcemanager.scheduler.capacity.ParentQueue: assignedContainer queue=root usedCapacity=1.0 absoluteUsedCapacity=1.0 used=<memory:49152, vCores:45> cluster=<memory:49152, vCores:96>
2013-08-31 00:26:58,293 INFO org.apache.hadoop.yarn.server.resourcemanager.rmcontainer.RMContainerImpl: container_1377907764744_0007_01_000025 Container Transitioned from RUNNING to COMPLETED
2013-08-31 00:26:58,293 INFO org.apache.hadoop.yarn.server.resourcemanager.scheduler.common.fica.FiCaSchedulerApp: Completed container: container_1377907764744_0007_01_000025 in state: COMPLETED event:FINISHED
2013-08-31 00:26:58,293 INFO org.apache.hadoop.yarn.server.resourcemanager.RMAuditLogger: USER=ubuntu	OPERATION=AM Released Container	TARGET=SchedulerApp	RESULT=SUCCESS	APPID=application_1377907764744_0007	CONTAINERID=container_1377907764744_0007_01_000025
2013-08-31 00:26:58,293 INFO org.apache.hadoop.yarn.server.resourcemanager.scheduler.common.fica.FiCaSchedulerNode: Released container container_1377907764744_0007_01_000025 of capacity <memory:1024, vCores:1> on host hadoop-32-3:33603, which currently has 7 containers, <memory:7168, vCores:7> used and <memory:1024, vCores:9> available, release resources=true
2013-08-31 00:26:58,294 INFO org.apache.hadoop.yarn.server.resourcemanager.scheduler.capacity.LeafQueue: default used=<memory:48128, vCores:44> numContainers=44 user=ubuntu user-resources=<memory:48128, vCores:44>
2013-08-31 00:26:58,295 INFO org.apache.hadoop.yarn.server.resourcemanager.scheduler.capacity.LeafQueue: completedContainer container=Container: [ContainerId: container_1377907764744_0007_01_000025, NodeId: hadoop-32-3:33603, NodeHttpAddress: hadoop-32-3:8042, Resource: <memory:1024, vCores:1>, Priority: 20, State: NEW, Token: null, Status: container_id {, app_attempt_id {, application_id {, id: 7, cluster_timestamp: 1377907764744, }, attemptId: 1, }, id: 25, }, state: C_COMPLETE, diagnostics: "Container killed by the ApplicationMaster.\n\n", exit_status: 143, ] resource=<memory:1024, vCores:1> queue=default: capacity=1.0, absoluteCapacity=1.0, usedResources=<memory:48128, vCores:44>usedCapacity=0.9791667, absoluteUsedCapacity=0.9791667, numApps=5, numContainers=44 usedCapacity=0.9791667 absoluteUsedCapacity=0.9791667 used=<memory:48128, vCores:44> cluster=<memory:49152, vCores:96>
2013-08-31 00:26:58,295 INFO org.apache.hadoop.yarn.server.resourcemanager.scheduler.capacity.ParentQueue: completedContainer queue=root usedCapacity=0.9791667 absoluteUsedCapacity=0.9791667 used=<memory:48128, vCores:44> cluster=<memory:49152, vCores:96>
2013-08-31 00:26:58,295 INFO org.apache.hadoop.yarn.server.resourcemanager.scheduler.capacity.CapacityScheduler: Application appattempt_1377907764744_0007_000001 released container container_1377907764744_0007_01_000025 on node: host: hadoop-32-3:33603 #containers=7 available=1024 used=7168 with event: FINISHED
2013-08-31 00:26:58,295 INFO org.apache.hadoop.yarn.server.resourcemanager.rmcontainer.RMContainerImpl: container_1377907764744_0006_01_000024 Container Transitioned from NEW to ALLOCATED
2013-08-31 00:26:58,296 INFO org.apache.hadoop.yarn.server.resourcemanager.RMAuditLogger: USER=ubuntu	OPERATION=AM Allocated Container	TARGET=SchedulerApp	RESULT=SUCCESS	APPID=application_1377907764744_0006	CONTAINERID=container_1377907764744_0006_01_000024
2013-08-31 00:26:58,296 INFO org.apache.hadoop.yarn.server.resourcemanager.scheduler.common.fica.FiCaSchedulerNode: Assigned container container_1377907764744_0006_01_000024 of capacity <memory:1024, vCores:1> on host hadoop-32-3:33603, which currently has 8 containers, <memory:8192, vCores:8> used and <memory:0, vCores:8> available
2013-08-31 00:26:58,296 INFO org.apache.hadoop.yarn.server.resourcemanager.scheduler.capacity.LeafQueue: assignedContainer application=application_1377907764744_0006 container=Container: [ContainerId: container_1377907764744_0006_01_000024, NodeId: hadoop-32-3:33603, NodeHttpAddress: hadoop-32-3:8042, Resource: <memory:1024, vCores:1>, Priority: 20, State: NEW, Token: null, Status: container_id {, app_attempt_id {, application_id {, id: 6, cluster_timestamp: 1377907764744, }, attemptId: 1, }, id: 24, }, state: C_NEW, ] containerId=container_1377907764744_0006_01_000024 queue=default: capacity=1.0, absoluteCapacity=1.0, usedResources=<memory:48128, vCores:44>usedCapacity=0.9791667, absoluteUsedCapacity=0.9791667, numApps=5, numContainers=44 usedCapacity=0.9791667 absoluteUsedCapacity=0.9791667 used=<memory:48128, vCores:44> cluster=<memory:49152, vCores:96>
2013-08-31 00:26:58,297 INFO org.apache.hadoop.yarn.server.resourcemanager.scheduler.capacity.ParentQueue: Re-sorting queues since queue: root.default stats: default: capacity=1.0, absoluteCapacity=1.0, usedResources=<memory:49152, vCores:45>usedCapacity=1.0, absoluteUsedCapacity=1.0, numApps=5, numContainers=45
2013-08-31 00:26:58,297 INFO org.apache.hadoop.yarn.server.resourcemanager.scheduler.capacity.ParentQueue: assignedContainer queue=root usedCapacity=1.0 absoluteUsedCapacity=1.0 used=<memory:49152, vCores:45> cluster=<memory:49152, vCores:96>
2013-08-31 00:26:58,590 INFO org.apache.hadoop.yarn.server.resourcemanager.rmcontainer.RMContainerImpl: container_1377907764744_0007_01_000019 Container Transitioned from RUNNING to COMPLETED
2013-08-31 00:26:58,591 INFO org.apache.hadoop.yarn.server.resourcemanager.scheduler.common.fica.FiCaSchedulerApp: Completed container: container_1377907764744_0007_01_000019 in state: COMPLETED event:FINISHED
2013-08-31 00:26:58,591 INFO org.apache.hadoop.yarn.server.resourcemanager.RMAuditLogger: USER=ubuntu	OPERATION=AM Released Container	TARGET=SchedulerApp	RESULT=SUCCESS	APPID=application_1377907764744_0007	CONTAINERID=container_1377907764744_0007_01_000019
2013-08-31 00:26:58,591 INFO org.apache.hadoop.yarn.server.resourcemanager.scheduler.common.fica.FiCaSchedulerNode: Released container container_1377907764744_0007_01_000019 of capacity <memory:1024, vCores:1> on host hadoop-32-5:54799, which currently has 6 containers, <memory:7168, vCores:6> used and <memory:1024, vCores:10> available, release resources=true
2013-08-31 00:26:58,591 INFO org.apache.hadoop.yarn.server.resourcemanager.scheduler.capacity.LeafQueue: default used=<memory:48128, vCores:44> numContainers=44 user=ubuntu user-resources=<memory:48128, vCores:44>
2013-08-31 00:26:58,592 INFO org.apache.hadoop.yarn.server.resourcemanager.scheduler.capacity.LeafQueue: completedContainer container=Container: [ContainerId: container_1377907764744_0007_01_000019, NodeId: hadoop-32-5:54799, NodeHttpAddress: hadoop-32-5:8042, Resource: <memory:1024, vCores:1>, Priority: 20, State: NEW, Token: null, Status: container_id {, app_attempt_id {, application_id {, id: 7, cluster_timestamp: 1377907764744, }, attemptId: 1, }, id: 19, }, state: C_COMPLETE, diagnostics: "Container killed by the ApplicationMaster.\n", exit_status: 0, ] resource=<memory:1024, vCores:1> queue=default: capacity=1.0, absoluteCapacity=1.0, usedResources=<memory:48128, vCores:44>usedCapacity=0.9791667, absoluteUsedCapacity=0.9791667, numApps=5, numContainers=44 usedCapacity=0.9791667 absoluteUsedCapacity=0.9791667 used=<memory:48128, vCores:44> cluster=<memory:49152, vCores:96>
2013-08-31 00:26:58,592 INFO org.apache.hadoop.yarn.server.resourcemanager.scheduler.capacity.ParentQueue: completedContainer queue=root usedCapacity=0.9791667 absoluteUsedCapacity=0.9791667 used=<memory:48128, vCores:44> cluster=<memory:49152, vCores:96>
2013-08-31 00:26:58,593 INFO org.apache.hadoop.yarn.server.resourcemanager.scheduler.capacity.CapacityScheduler: Application appattempt_1377907764744_0007_000001 released container container_1377907764744_0007_01_000019 on node: host: hadoop-32-5:54799 #containers=6 available=1024 used=7168 with event: FINISHED
2013-08-31 00:26:58,593 INFO org.apache.hadoop.yarn.server.resourcemanager.rmcontainer.RMContainerImpl: container_1377907764744_0006_01_000025 Container Transitioned from NEW to ALLOCATED
2013-08-31 00:26:58,593 INFO org.apache.hadoop.yarn.server.resourcemanager.RMAuditLogger: USER=ubuntu	OPERATION=AM Allocated Container	TARGET=SchedulerApp	RESULT=SUCCESS	APPID=application_1377907764744_0006	CONTAINERID=container_1377907764744_0006_01_000025
2013-08-31 00:26:58,593 INFO org.apache.hadoop.yarn.server.resourcemanager.scheduler.common.fica.FiCaSchedulerNode: Assigned container container_1377907764744_0006_01_000025 of capacity <memory:1024, vCores:1> on host hadoop-32-5:54799, which currently has 7 containers, <memory:8192, vCores:7> used and <memory:0, vCores:9> available
2013-08-31 00:26:58,594 INFO org.apache.hadoop.yarn.server.resourcemanager.scheduler.capacity.LeafQueue: assignedContainer application=application_1377907764744_0006 container=Container: [ContainerId: container_1377907764744_0006_01_000025, NodeId: hadoop-32-5:54799, NodeHttpAddress: hadoop-32-5:8042, Resource: <memory:1024, vCores:1>, Priority: 20, State: NEW, Token: null, Status: container_id {, app_attempt_id {, application_id {, id: 6, cluster_timestamp: 1377907764744, }, attemptId: 1, }, id: 25, }, state: C_NEW, ] containerId=container_1377907764744_0006_01_000025 queue=default: capacity=1.0, absoluteCapacity=1.0, usedResources=<memory:48128, vCores:44>usedCapacity=0.9791667, absoluteUsedCapacity=0.9791667, numApps=5, numContainers=44 usedCapacity=0.9791667 absoluteUsedCapacity=0.9791667 used=<memory:48128, vCores:44> cluster=<memory:49152, vCores:96>
2013-08-31 00:26:58,594 INFO org.apache.hadoop.yarn.server.resourcemanager.scheduler.capacity.ParentQueue: Re-sorting queues since queue: root.default stats: default: capacity=1.0, absoluteCapacity=1.0, usedResources=<memory:49152, vCores:45>usedCapacity=1.0, absoluteUsedCapacity=1.0, numApps=5, numContainers=45
2013-08-31 00:26:58,595 INFO org.apache.hadoop.yarn.server.resourcemanager.scheduler.capacity.ParentQueue: assignedContainer queue=root usedCapacity=1.0 absoluteUsedCapacity=1.0 used=<memory:49152, vCores:45> cluster=<memory:49152, vCores:96>
2013-08-31 00:26:58,924 INFO org.apache.hadoop.yarn.server.resourcemanager.rmcontainer.RMContainerImpl: container_1377907764744_0006_01_000009 Container Transitioned from RUNNING to COMPLETED
2013-08-31 00:26:58,924 INFO org.apache.hadoop.yarn.server.resourcemanager.scheduler.common.fica.FiCaSchedulerApp: Completed container: container_1377907764744_0006_01_000009 in state: COMPLETED event:FINISHED
2013-08-31 00:26:58,924 INFO org.apache.hadoop.yarn.server.resourcemanager.RMAuditLogger: USER=ubuntu	OPERATION=AM Released Container	TARGET=SchedulerApp	RESULT=SUCCESS	APPID=application_1377907764744_0006	CONTAINERID=container_1377907764744_0006_01_000009
2013-08-31 00:26:58,924 INFO org.apache.hadoop.yarn.server.resourcemanager.scheduler.common.fica.FiCaSchedulerNode: Released container container_1377907764744_0006_01_000009 of capacity <memory:1024, vCores:1> on host hadoop-32-6:48039, which currently has 7 containers, <memory:7168, vCores:7> used and <memory:1024, vCores:9> available, release resources=true
2013-08-31 00:26:58,924 INFO org.apache.hadoop.yarn.server.resourcemanager.scheduler.capacity.LeafQueue: default used=<memory:48128, vCores:44> numContainers=44 user=ubuntu user-resources=<memory:48128, vCores:44>
2013-08-31 00:26:58,925 INFO org.apache.hadoop.yarn.server.resourcemanager.scheduler.capacity.LeafQueue: completedContainer container=Container: [ContainerId: container_1377907764744_0006_01_000009, NodeId: hadoop-32-6:48039, NodeHttpAddress: hadoop-32-6:8042, Resource: <memory:1024, vCores:1>, Priority: 20, State: NEW, Token: null, Status: container_id {, app_attempt_id {, application_id {, id: 6, cluster_timestamp: 1377907764744, }, attemptId: 1, }, id: 9, }, state: C_COMPLETE, diagnostics: "", exit_status: 0, ] resource=<memory:1024, vCores:1> queue=default: capacity=1.0, absoluteCapacity=1.0, usedResources=<memory:48128, vCores:44>usedCapacity=0.9791667, absoluteUsedCapacity=0.9791667, numApps=5, numContainers=44 usedCapacity=0.9791667 absoluteUsedCapacity=0.9791667 used=<memory:48128, vCores:44> cluster=<memory:49152, vCores:96>
2013-08-31 00:26:58,926 INFO org.apache.hadoop.yarn.server.resourcemanager.scheduler.capacity.ParentQueue: completedContainer queue=root usedCapacity=0.9791667 absoluteUsedCapacity=0.9791667 used=<memory:48128, vCores:44> cluster=<memory:49152, vCores:96>
2013-08-31 00:26:58,926 INFO org.apache.hadoop.yarn.server.resourcemanager.scheduler.capacity.CapacityScheduler: Application appattempt_1377907764744_0006_000001 released container container_1377907764744_0006_01_000009 on node: host: hadoop-32-6:48039 #containers=7 available=1024 used=7168 with event: FINISHED
2013-08-31 00:26:58,926 INFO org.apache.hadoop.yarn.server.resourcemanager.rmcontainer.RMContainerImpl: container_1377907764744_0006_01_000026 Container Transitioned from NEW to ALLOCATED
2013-08-31 00:26:58,926 INFO org.apache.hadoop.yarn.server.resourcemanager.RMAuditLogger: USER=ubuntu	OPERATION=AM Allocated Container	TARGET=SchedulerApp	RESULT=SUCCESS	APPID=application_1377907764744_0006	CONTAINERID=container_1377907764744_0006_01_000026
2013-08-31 00:26:58,926 INFO org.apache.hadoop.yarn.server.resourcemanager.scheduler.common.fica.FiCaSchedulerNode: Assigned container container_1377907764744_0006_01_000026 of capacity <memory:1024, vCores:1> on host hadoop-32-6:48039, which currently has 8 containers, <memory:8192, vCores:8> used and <memory:0, vCores:8> available
2013-08-31 00:26:58,927 INFO org.apache.hadoop.yarn.server.resourcemanager.scheduler.capacity.LeafQueue: assignedContainer application=application_1377907764744_0006 container=Container: [ContainerId: container_1377907764744_0006_01_000026, NodeId: hadoop-32-6:48039, NodeHttpAddress: hadoop-32-6:8042, Resource: <memory:1024, vCores:1>, Priority: 20, State: NEW, Token: null, Status: container_id {, app_attempt_id {, application_id {, id: 6, cluster_timestamp: 1377907764744, }, attemptId: 1, }, id: 26, }, state: C_NEW, ] containerId=container_1377907764744_0006_01_000026 queue=default: capacity=1.0, absoluteCapacity=1.0, usedResources=<memory:48128, vCores:44>usedCapacity=0.9791667, absoluteUsedCapacity=0.9791667, numApps=5, numContainers=44 usedCapacity=0.9791667 absoluteUsedCapacity=0.9791667 used=<memory:48128, vCores:44> cluster=<memory:49152, vCores:96>
2013-08-31 00:26:58,928 INFO org.apache.hadoop.yarn.server.resourcemanager.scheduler.capacity.ParentQueue: Re-sorting queues since queue: root.default stats: default: capacity=1.0, absoluteCapacity=1.0, usedResources=<memory:49152, vCores:45>usedCapacity=1.0, absoluteUsedCapacity=1.0, numApps=5, numContainers=45
2013-08-31 00:26:58,928 INFO org.apache.hadoop.yarn.server.resourcemanager.scheduler.capacity.ParentQueue: assignedContainer queue=root usedCapacity=1.0 absoluteUsedCapacity=1.0 used=<memory:49152, vCores:45> cluster=<memory:49152, vCores:96>
2013-08-31 00:26:58,939 INFO org.apache.hadoop.yarn.server.resourcemanager.rmcontainer.RMContainerImpl: container_1377907764744_0006_01_000022 Container Transitioned from ALLOCATED to ACQUIRED
2013-08-31 00:26:58,940 INFO org.apache.hadoop.yarn.server.resourcemanager.rmcontainer.RMContainerImpl: container_1377907764744_0006_01_000023 Container Transitioned from ALLOCATED to ACQUIRED
2013-08-31 00:26:58,940 INFO org.apache.hadoop.yarn.server.resourcemanager.rmcontainer.RMContainerImpl: container_1377907764744_0006_01_000024 Container Transitioned from ALLOCATED to ACQUIRED
2013-08-31 00:26:58,941 INFO org.apache.hadoop.yarn.server.resourcemanager.rmcontainer.RMContainerImpl: container_1377907764744_0006_01_000025 Container Transitioned from ALLOCATED to ACQUIRED
2013-08-31 00:26:58,941 INFO org.apache.hadoop.yarn.server.resourcemanager.rmcontainer.RMContainerImpl: container_1377907764744_0006_01_000026 Container Transitioned from ALLOCATED to ACQUIRED
2013-08-31 00:26:59,066 INFO org.apache.hadoop.yarn.server.resourcemanager.rmcontainer.RMContainerImpl: container_1377907764744_0006_01_000022 Container Transitioned from ACQUIRED to RUNNING
2013-08-31 00:26:59,236 INFO org.apache.hadoop.yarn.server.resourcemanager.rmcontainer.RMContainerImpl: container_1377907764744_0006_01_000023 Container Transitioned from ACQUIRED to RUNNING
2013-08-31 00:26:59,306 INFO org.apache.hadoop.yarn.server.resourcemanager.rmcontainer.RMContainerImpl: container_1377907764744_0006_01_000024 Container Transitioned from ACQUIRED to RUNNING
2013-08-31 00:26:59,663 INFO org.apache.hadoop.yarn.server.resourcemanager.rmcontainer.RMContainerImpl: container_1377907764744_0006_01_000025 Container Transitioned from ACQUIRED to RUNNING
2013-08-31 00:26:59,984 INFO org.apache.hadoop.yarn.server.resourcemanager.rmcontainer.RMContainerImpl: container_1377907764744_0006_01_000026 Container Transitioned from ACQUIRED to RUNNING
2013-08-31 00:26:59,985 INFO org.apache.hadoop.yarn.server.resourcemanager.rmcontainer.RMContainerImpl: container_1377907764744_0006_01_000008 Container Transitioned from RUNNING to COMPLETED
2013-08-31 00:26:59,985 INFO org.apache.hadoop.yarn.server.resourcemanager.scheduler.common.fica.FiCaSchedulerApp: Completed container: container_1377907764744_0006_01_000008 in state: COMPLETED event:FINISHED
2013-08-31 00:26:59,985 INFO org.apache.hadoop.yarn.server.resourcemanager.RMAuditLogger: USER=ubuntu	OPERATION=AM Released Container	TARGET=SchedulerApp	RESULT=SUCCESS	APPID=application_1377907764744_0006	CONTAINERID=container_1377907764744_0006_01_000008
2013-08-31 00:26:59,985 INFO org.apache.hadoop.yarn.server.resourcemanager.scheduler.common.fica.FiCaSchedulerNode: Released container container_1377907764744_0006_01_000008 of capacity <memory:1024, vCores:1> on host hadoop-32-6:48039, which currently has 7 containers, <memory:7168, vCores:7> used and <memory:1024, vCores:9> available, release resources=true
2013-08-31 00:26:59,985 INFO org.apache.hadoop.yarn.server.resourcemanager.scheduler.capacity.LeafQueue: default used=<memory:48128, vCores:44> numContainers=44 user=ubuntu user-resources=<memory:48128, vCores:44>
2013-08-31 00:26:59,986 INFO org.apache.hadoop.yarn.server.resourcemanager.scheduler.capacity.LeafQueue: completedContainer container=Container: [ContainerId: container_1377907764744_0006_01_000008, NodeId: hadoop-32-6:48039, NodeHttpAddress: hadoop-32-6:8042, Resource: <memory:1024, vCores:1>, Priority: 20, State: NEW, Token: null, Status: container_id {, app_attempt_id {, application_id {, id: 6, cluster_timestamp: 1377907764744, }, attemptId: 1, }, id: 8, }, state: C_COMPLETE, diagnostics: "Container killed by the ApplicationMaster.\n\n", exit_status: 143, ] resource=<memory:1024, vCores:1> queue=default: capacity=1.0, absoluteCapacity=1.0, usedResources=<memory:48128, vCores:44>usedCapacity=0.9791667, absoluteUsedCapacity=0.9791667, numApps=5, numContainers=44 usedCapacity=0.9791667 absoluteUsedCapacity=0.9791667 used=<memory:48128, vCores:44> cluster=<memory:49152, vCores:96>
2013-08-31 00:26:59,987 INFO org.apache.hadoop.yarn.server.resourcemanager.scheduler.capacity.ParentQueue: completedContainer queue=root usedCapacity=0.9791667 absoluteUsedCapacity=0.9791667 used=<memory:48128, vCores:44> cluster=<memory:49152, vCores:96>
2013-08-31 00:26:59,987 INFO org.apache.hadoop.yarn.server.resourcemanager.scheduler.capacity.CapacityScheduler: Application appattempt_1377907764744_0006_000001 released container container_1377907764744_0006_01_000008 on node: host: hadoop-32-6:48039 #containers=7 available=1024 used=7168 with event: FINISHED
2013-08-31 00:26:59,987 INFO org.apache.hadoop.yarn.server.resourcemanager.rmcontainer.RMContainerImpl: container_1377907764744_0006_01_000027 Container Transitioned from NEW to ALLOCATED
2013-08-31 00:26:59,987 INFO org.apache.hadoop.yarn.server.resourcemanager.RMAuditLogger: USER=ubuntu	OPERATION=AM Allocated Container	TARGET=SchedulerApp	RESULT=SUCCESS	APPID=application_1377907764744_0006	CONTAINERID=container_1377907764744_0006_01_000027
2013-08-31 00:26:59,987 INFO org.apache.hadoop.yarn.server.resourcemanager.scheduler.common.fica.FiCaSchedulerNode: Assigned container container_1377907764744_0006_01_000027 of capacity <memory:1024, vCores:1> on host hadoop-32-6:48039, which currently has 8 containers, <memory:8192, vCores:8> used and <memory:0, vCores:8> available
2013-08-31 00:26:59,988 INFO org.apache.hadoop.yarn.server.resourcemanager.scheduler.capacity.LeafQueue: assignedContainer application=application_1377907764744_0006 container=Container: [ContainerId: container_1377907764744_0006_01_000027, NodeId: hadoop-32-6:48039, NodeHttpAddress: hadoop-32-6:8042, Resource: <memory:1024, vCores:1>, Priority: 10, State: NEW, Token: null, Status: container_id {, app_attempt_id {, application_id {, id: 6, cluster_timestamp: 1377907764744, }, attemptId: 1, }, id: 27, }, state: C_NEW, ] containerId=container_1377907764744_0006_01_000027 queue=default: capacity=1.0, absoluteCapacity=1.0, usedResources=<memory:48128, vCores:44>usedCapacity=0.9791667, absoluteUsedCapacity=0.9791667, numApps=5, numContainers=44 usedCapacity=0.9791667 absoluteUsedCapacity=0.9791667 used=<memory:48128, vCores:44> cluster=<memory:49152, vCores:96>
2013-08-31 00:26:59,988 INFO org.apache.hadoop.yarn.server.resourcemanager.scheduler.capacity.ParentQueue: Re-sorting queues since queue: root.default stats: default: capacity=1.0, absoluteCapacity=1.0, usedResources=<memory:49152, vCores:45>usedCapacity=1.0, absoluteUsedCapacity=1.0, numApps=5, numContainers=45
2013-08-31 00:26:59,989 INFO org.apache.hadoop.yarn.server.resourcemanager.scheduler.capacity.ParentQueue: assignedContainer queue=root usedCapacity=1.0 absoluteUsedCapacity=1.0 used=<memory:49152, vCores:45> cluster=<memory:49152, vCores:96>
2013-08-31 00:27:00,006 INFO org.apache.hadoop.yarn.server.resourcemanager.rmcontainer.RMContainerImpl: container_1377907764744_0006_01_000027 Container Transitioned from ALLOCATED to ACQUIRED
2013-08-31 00:27:00,157 INFO org.apache.hadoop.yarn.server.resourcemanager.rmcontainer.RMContainerImpl: container_1377907764744_0007_01_000029 Container Transitioned from RUNNING to COMPLETED
2013-08-31 00:27:00,157 INFO org.apache.hadoop.yarn.server.resourcemanager.scheduler.common.fica.FiCaSchedulerApp: Completed container: container_1377907764744_0007_01_000029 in state: COMPLETED event:FINISHED
2013-08-31 00:27:00,158 INFO org.apache.hadoop.yarn.server.resourcemanager.RMAuditLogger: USER=ubuntu	OPERATION=AM Released Container	TARGET=SchedulerApp	RESULT=SUCCESS	APPID=application_1377907764744_0007	CONTAINERID=container_1377907764744_0007_01_000029
2013-08-31 00:27:00,158 INFO org.apache.hadoop.yarn.server.resourcemanager.scheduler.common.fica.FiCaSchedulerNode: Released container container_1377907764744_0007_01_000029 of capacity <memory:1024, vCores:1> on host hadoop-32-3:33603, which currently has 7 containers, <memory:7168, vCores:7> used and <memory:1024, vCores:9> available, release resources=true
2013-08-31 00:27:00,158 INFO org.apache.hadoop.yarn.server.resourcemanager.scheduler.capacity.LeafQueue: default used=<memory:48128, vCores:44> numContainers=44 user=ubuntu user-resources=<memory:48128, vCores:44>
2013-08-31 00:27:00,159 INFO org.apache.hadoop.yarn.server.resourcemanager.scheduler.capacity.LeafQueue: completedContainer container=Container: [ContainerId: container_1377907764744_0007_01_000029, NodeId: hadoop-32-3:33603, NodeHttpAddress: hadoop-32-3:8042, Resource: <memory:1024, vCores:1>, Priority: 20, State: NEW, Token: null, Status: container_id {, app_attempt_id {, application_id {, id: 7, cluster_timestamp: 1377907764744, }, attemptId: 1, }, id: 29, }, state: C_COMPLETE, diagnostics: "Container killed by the ApplicationMaster.\n\n", exit_status: 143, ] resource=<memory:1024, vCores:1> queue=default: capacity=1.0, absoluteCapacity=1.0, usedResources=<memory:48128, vCores:44>usedCapacity=0.9791667, absoluteUsedCapacity=0.9791667, numApps=5, numContainers=44 usedCapacity=0.9791667 absoluteUsedCapacity=0.9791667 used=<memory:48128, vCores:44> cluster=<memory:49152, vCores:96>
2013-08-31 00:27:00,159 INFO org.apache.hadoop.yarn.server.resourcemanager.scheduler.capacity.ParentQueue: completedContainer queue=root usedCapacity=0.9791667 absoluteUsedCapacity=0.9791667 used=<memory:48128, vCores:44> cluster=<memory:49152, vCores:96>
2013-08-31 00:27:00,159 INFO org.apache.hadoop.yarn.server.resourcemanager.scheduler.capacity.CapacityScheduler: Application appattempt_1377907764744_0007_000001 released container container_1377907764744_0007_01_000029 on node: host: hadoop-32-3:33603 #containers=7 available=1024 used=7168 with event: FINISHED
2013-08-31 00:27:00,160 INFO org.apache.hadoop.yarn.server.resourcemanager.rmcontainer.RMContainerImpl: container_1377907764744_0006_01_000028 Container Transitioned from NEW to ALLOCATED
2013-08-31 00:27:00,160 INFO org.apache.hadoop.yarn.server.resourcemanager.RMAuditLogger: USER=ubuntu	OPERATION=AM Allocated Container	TARGET=SchedulerApp	RESULT=SUCCESS	APPID=application_1377907764744_0006	CONTAINERID=container_1377907764744_0006_01_000028
2013-08-31 00:27:00,160 INFO org.apache.hadoop.yarn.server.resourcemanager.scheduler.common.fica.FiCaSchedulerNode: Assigned container container_1377907764744_0006_01_000028 of capacity <memory:1024, vCores:1> on host hadoop-32-3:33603, which currently has 8 containers, <memory:8192, vCores:8> used and <memory:0, vCores:8> available
2013-08-31 00:27:00,161 INFO org.apache.hadoop.yarn.server.resourcemanager.scheduler.capacity.LeafQueue: assignedContainer application=application_1377907764744_0006 container=Container: [ContainerId: container_1377907764744_0006_01_000028, NodeId: hadoop-32-3:33603, NodeHttpAddress: hadoop-32-3:8042, Resource: <memory:1024, vCores:1>, Priority: 20, State: NEW, Token: null, Status: container_id {, app_attempt_id {, application_id {, id: 6, cluster_timestamp: 1377907764744, }, attemptId: 1, }, id: 28, }, state: C_NEW, ] containerId=container_1377907764744_0006_01_000028 queue=default: capacity=1.0, absoluteCapacity=1.0, usedResources=<memory:48128, vCores:44>usedCapacity=0.9791667, absoluteUsedCapacity=0.9791667, numApps=5, numContainers=44 usedCapacity=0.9791667 absoluteUsedCapacity=0.9791667 used=<memory:48128, vCores:44> cluster=<memory:49152, vCores:96>
2013-08-31 00:27:00,161 INFO org.apache.hadoop.yarn.server.resourcemanager.scheduler.capacity.ParentQueue: Re-sorting queues since queue: root.default stats: default: capacity=1.0, absoluteCapacity=1.0, usedResources=<memory:49152, vCores:45>usedCapacity=1.0, absoluteUsedCapacity=1.0, numApps=5, numContainers=45
2013-08-31 00:27:00,161 INFO org.apache.hadoop.yarn.server.resourcemanager.scheduler.capacity.ParentQueue: assignedContainer queue=root usedCapacity=1.0 absoluteUsedCapacity=1.0 used=<memory:49152, vCores:45> cluster=<memory:49152, vCores:96>
2013-08-31 00:27:01,017 INFO org.apache.hadoop.yarn.server.resourcemanager.scheduler.AppSchedulingInfo: checking for deactivate... 
2013-08-31 00:27:01,019 INFO org.apache.hadoop.yarn.server.resourcemanager.rmcontainer.RMContainerImpl: container_1377907764744_0006_01_000028 Container Transitioned from ALLOCATED to ACQUIRED
2013-08-31 00:27:01,065 INFO org.apache.hadoop.yarn.server.resourcemanager.rmcontainer.RMContainerImpl: container_1377907764744_0006_01_000027 Container Transitioned from ACQUIRED to RUNNING
2013-08-31 00:27:01,066 INFO org.apache.hadoop.yarn.server.resourcemanager.rmcontainer.RMContainerImpl: container_1377907764744_0006_01_000011 Container Transitioned from RUNNING to COMPLETED
2013-08-31 00:27:01,066 INFO org.apache.hadoop.yarn.server.resourcemanager.scheduler.common.fica.FiCaSchedulerApp: Completed container: container_1377907764744_0006_01_000011 in state: COMPLETED event:FINISHED
2013-08-31 00:27:01,066 INFO org.apache.hadoop.yarn.server.resourcemanager.RMAuditLogger: USER=ubuntu	OPERATION=AM Released Container	TARGET=SchedulerApp	RESULT=SUCCESS	APPID=application_1377907764744_0006	CONTAINERID=container_1377907764744_0006_01_000011
2013-08-31 00:27:01,066 INFO org.apache.hadoop.yarn.server.resourcemanager.scheduler.common.fica.FiCaSchedulerNode: Released container container_1377907764744_0006_01_000011 of capacity <memory:1024, vCores:1> on host hadoop-32-6:48039, which currently has 7 containers, <memory:7168, vCores:7> used and <memory:1024, vCores:9> available, release resources=true
2013-08-31 00:27:01,066 INFO org.apache.hadoop.yarn.server.resourcemanager.scheduler.capacity.LeafQueue: default used=<memory:48128, vCores:44> numContainers=44 user=ubuntu user-resources=<memory:48128, vCores:44>
2013-08-31 00:27:01,067 INFO org.apache.hadoop.yarn.server.resourcemanager.scheduler.capacity.LeafQueue: completedContainer container=Container: [ContainerId: container_1377907764744_0006_01_000011, NodeId: hadoop-32-6:48039, NodeHttpAddress: hadoop-32-6:8042, Resource: <memory:1024, vCores:1>, Priority: 20, State: NEW, Token: null, Status: container_id {, app_attempt_id {, application_id {, id: 6, cluster_timestamp: 1377907764744, }, attemptId: 1, }, id: 11, }, state: C_COMPLETE, diagnostics: "", exit_status: 0, ] resource=<memory:1024, vCores:1> queue=default: capacity=1.0, absoluteCapacity=1.0, usedResources=<memory:48128, vCores:44>usedCapacity=0.9791667, absoluteUsedCapacity=0.9791667, numApps=5, numContainers=44 usedCapacity=0.9791667 absoluteUsedCapacity=0.9791667 used=<memory:48128, vCores:44> cluster=<memory:49152, vCores:96>
2013-08-31 00:27:01,067 INFO org.apache.hadoop.yarn.server.resourcemanager.scheduler.capacity.ParentQueue: completedContainer queue=root usedCapacity=0.9791667 absoluteUsedCapacity=0.9791667 used=<memory:48128, vCores:44> cluster=<memory:49152, vCores:96>
2013-08-31 00:27:01,068 INFO org.apache.hadoop.yarn.server.resourcemanager.scheduler.capacity.CapacityScheduler: Application appattempt_1377907764744_0006_000001 released container container_1377907764744_0006_01_000011 on node: host: hadoop-32-6:48039 #containers=7 available=1024 used=7168 with event: FINISHED
2013-08-31 00:27:01,068 INFO org.apache.hadoop.yarn.server.resourcemanager.rmcontainer.RMContainerImpl: container_1377907764744_0006_01_000029 Container Transitioned from NEW to ALLOCATED
2013-08-31 00:27:01,068 INFO org.apache.hadoop.yarn.server.resourcemanager.RMAuditLogger: USER=ubuntu	OPERATION=AM Allocated Container	TARGET=SchedulerApp	RESULT=SUCCESS	APPID=application_1377907764744_0006	CONTAINERID=container_1377907764744_0006_01_000029
2013-08-31 00:27:01,068 INFO org.apache.hadoop.yarn.server.resourcemanager.scheduler.common.fica.FiCaSchedulerNode: Assigned container container_1377907764744_0006_01_000029 of capacity <memory:1024, vCores:1> on host hadoop-32-6:48039, which currently has 8 containers, <memory:8192, vCores:8> used and <memory:0, vCores:8> available
2013-08-31 00:27:01,069 INFO org.apache.hadoop.yarn.server.resourcemanager.scheduler.capacity.LeafQueue: assignedContainer application=application_1377907764744_0006 container=Container: [ContainerId: container_1377907764744_0006_01_000029, NodeId: hadoop-32-6:48039, NodeHttpAddress: hadoop-32-6:8042, Resource: <memory:1024, vCores:1>, Priority: 20, State: NEW, Token: null, Status: container_id {, app_attempt_id {, application_id {, id: 6, cluster_timestamp: 1377907764744, }, attemptId: 1, }, id: 29, }, state: C_NEW, ] containerId=container_1377907764744_0006_01_000029 queue=default: capacity=1.0, absoluteCapacity=1.0, usedResources=<memory:48128, vCores:44>usedCapacity=0.9791667, absoluteUsedCapacity=0.9791667, numApps=5, numContainers=44 usedCapacity=0.9791667 absoluteUsedCapacity=0.9791667 used=<memory:48128, vCores:44> cluster=<memory:49152, vCores:96>
2013-08-31 00:27:01,069 INFO org.apache.hadoop.yarn.server.resourcemanager.scheduler.capacity.ParentQueue: Re-sorting queues since queue: root.default stats: default: capacity=1.0, absoluteCapacity=1.0, usedResources=<memory:49152, vCores:45>usedCapacity=1.0, absoluteUsedCapacity=1.0, numApps=5, numContainers=45
2013-08-31 00:27:01,069 INFO org.apache.hadoop.yarn.server.resourcemanager.scheduler.capacity.ParentQueue: assignedContainer queue=root usedCapacity=1.0 absoluteUsedCapacity=1.0 used=<memory:49152, vCores:45> cluster=<memory:49152, vCores:96>
2013-08-31 00:27:01,164 INFO org.apache.hadoop.yarn.server.resourcemanager.rmcontainer.RMContainerImpl: container_1377907764744_0007_01_000023 Container Transitioned from RUNNING to COMPLETED
2013-08-31 00:27:01,164 INFO org.apache.hadoop.yarn.server.resourcemanager.scheduler.common.fica.FiCaSchedulerApp: Completed container: container_1377907764744_0007_01_000023 in state: COMPLETED event:FINISHED
2013-08-31 00:27:01,164 INFO org.apache.hadoop.yarn.server.resourcemanager.RMAuditLogger: USER=ubuntu	OPERATION=AM Released Container	TARGET=SchedulerApp	RESULT=SUCCESS	APPID=application_1377907764744_0007	CONTAINERID=container_1377907764744_0007_01_000023
2013-08-31 00:27:01,164 INFO org.apache.hadoop.yarn.server.resourcemanager.scheduler.common.fica.FiCaSchedulerNode: Released container container_1377907764744_0007_01_000023 of capacity <memory:1024, vCores:1> on host hadoop-32-3:33603, which currently has 7 containers, <memory:7168, vCores:7> used and <memory:1024, vCores:9> available, release resources=true
2013-08-31 00:27:01,165 INFO org.apache.hadoop.yarn.server.resourcemanager.scheduler.capacity.LeafQueue: default used=<memory:48128, vCores:44> numContainers=44 user=ubuntu user-resources=<memory:48128, vCores:44>
2013-08-31 00:27:01,165 INFO org.apache.hadoop.yarn.server.resourcemanager.scheduler.capacity.LeafQueue: completedContainer container=Container: [ContainerId: container_1377907764744_0007_01_000023, NodeId: hadoop-32-3:33603, NodeHttpAddress: hadoop-32-3:8042, Resource: <memory:1024, vCores:1>, Priority: 20, State: NEW, Token: null, Status: container_id {, app_attempt_id {, application_id {, id: 7, cluster_timestamp: 1377907764744, }, attemptId: 1, }, id: 23, }, state: C_COMPLETE, diagnostics: "Container killed by the ApplicationMaster.\n\n", exit_status: 143, ] resource=<memory:1024, vCores:1> queue=default: capacity=1.0, absoluteCapacity=1.0, usedResources=<memory:48128, vCores:44>usedCapacity=0.9791667, absoluteUsedCapacity=0.9791667, numApps=5, numContainers=44 usedCapacity=0.9791667 absoluteUsedCapacity=0.9791667 used=<memory:48128, vCores:44> cluster=<memory:49152, vCores:96>
2013-08-31 00:27:01,166 INFO org.apache.hadoop.yarn.server.resourcemanager.scheduler.capacity.ParentQueue: completedContainer queue=root usedCapacity=0.9791667 absoluteUsedCapacity=0.9791667 used=<memory:48128, vCores:44> cluster=<memory:49152, vCores:96>
2013-08-31 00:27:01,166 INFO org.apache.hadoop.yarn.server.resourcemanager.scheduler.capacity.CapacityScheduler: Application appattempt_1377907764744_0007_000001 released container container_1377907764744_0007_01_000023 on node: host: hadoop-32-3:33603 #containers=7 available=1024 used=7168 with event: FINISHED
2013-08-31 00:27:01,166 INFO org.apache.hadoop.yarn.server.resourcemanager.rmcontainer.RMContainerImpl: container_1377907764744_0006_01_000030 Container Transitioned from NEW to ALLOCATED
2013-08-31 00:27:01,166 INFO org.apache.hadoop.yarn.server.resourcemanager.RMAuditLogger: USER=ubuntu	OPERATION=AM Allocated Container	TARGET=SchedulerApp	RESULT=SUCCESS	APPID=application_1377907764744_0006	CONTAINERID=container_1377907764744_0006_01_000030
2013-08-31 00:27:01,166 INFO org.apache.hadoop.yarn.server.resourcemanager.scheduler.common.fica.FiCaSchedulerNode: Assigned container container_1377907764744_0006_01_000030 of capacity <memory:1024, vCores:1> on host hadoop-32-3:33603, which currently has 8 containers, <memory:8192, vCores:8> used and <memory:0, vCores:8> available
2013-08-31 00:27:01,167 INFO org.apache.hadoop.yarn.server.resourcemanager.scheduler.capacity.LeafQueue: assignedContainer application=application_1377907764744_0006 container=Container: [ContainerId: container_1377907764744_0006_01_000030, NodeId: hadoop-32-3:33603, NodeHttpAddress: hadoop-32-3:8042, Resource: <memory:1024, vCores:1>, Priority: 20, State: NEW, Token: null, Status: container_id {, app_attempt_id {, application_id {, id: 6, cluster_timestamp: 1377907764744, }, attemptId: 1, }, id: 30, }, state: C_NEW, ] containerId=container_1377907764744_0006_01_000030 queue=default: capacity=1.0, absoluteCapacity=1.0, usedResources=<memory:48128, vCores:44>usedCapacity=0.9791667, absoluteUsedCapacity=0.9791667, numApps=5, numContainers=44 usedCapacity=0.9791667 absoluteUsedCapacity=0.9791667 used=<memory:48128, vCores:44> cluster=<memory:49152, vCores:96>
2013-08-31 00:27:01,167 INFO org.apache.hadoop.yarn.server.resourcemanager.scheduler.capacity.ParentQueue: Re-sorting queues since queue: root.default stats: default: capacity=1.0, absoluteCapacity=1.0, usedResources=<memory:49152, vCores:45>usedCapacity=1.0, absoluteUsedCapacity=1.0, numApps=5, numContainers=45
2013-08-31 00:27:01,168 INFO org.apache.hadoop.yarn.server.resourcemanager.scheduler.capacity.ParentQueue: assignedContainer queue=root usedCapacity=1.0 absoluteUsedCapacity=1.0 used=<memory:49152, vCores:45> cluster=<memory:49152, vCores:96>
2013-08-31 00:27:01,275 INFO org.apache.hadoop.yarn.server.resourcemanager.rmcontainer.RMContainerImpl: container_1377907764744_0007_01_000020 Container Transitioned from RUNNING to COMPLETED
2013-08-31 00:27:01,275 INFO org.apache.hadoop.yarn.server.resourcemanager.scheduler.common.fica.FiCaSchedulerApp: Completed container: container_1377907764744_0007_01_000020 in state: COMPLETED event:FINISHED
2013-08-31 00:27:01,275 INFO org.apache.hadoop.yarn.server.resourcemanager.RMAuditLogger: USER=ubuntu	OPERATION=AM Released Container	TARGET=SchedulerApp	RESULT=SUCCESS	APPID=application_1377907764744_0007	CONTAINERID=container_1377907764744_0007_01_000020
2013-08-31 00:27:01,275 INFO org.apache.hadoop.yarn.server.resourcemanager.scheduler.common.fica.FiCaSchedulerNode: Released container container_1377907764744_0007_01_000020 of capacity <memory:1024, vCores:1> on host hadoop-32-5:54799, which currently has 6 containers, <memory:7168, vCores:6> used and <memory:1024, vCores:10> available, release resources=true
2013-08-31 00:27:01,276 INFO org.apache.hadoop.yarn.server.resourcemanager.scheduler.capacity.LeafQueue: default used=<memory:48128, vCores:44> numContainers=44 user=ubuntu user-resources=<memory:48128, vCores:44>
2013-08-31 00:27:01,277 INFO org.apache.hadoop.yarn.server.resourcemanager.scheduler.capacity.LeafQueue: completedContainer container=Container: [ContainerId: container_1377907764744_0007_01_000020, NodeId: hadoop-32-5:54799, NodeHttpAddress: hadoop-32-5:8042, Resource: <memory:1024, vCores:1>, Priority: 20, State: NEW, Token: null, Status: container_id {, app_attempt_id {, application_id {, id: 7, cluster_timestamp: 1377907764744, }, attemptId: 1, }, id: 20, }, state: C_COMPLETE, diagnostics: "Container killed by the ApplicationMaster.\n\n", exit_status: 143, ] resource=<memory:1024, vCores:1> queue=default: capacity=1.0, absoluteCapacity=1.0, usedResources=<memory:48128, vCores:44>usedCapacity=0.9791667, absoluteUsedCapacity=0.9791667, numApps=5, numContainers=44 usedCapacity=0.9791667 absoluteUsedCapacity=0.9791667 used=<memory:48128, vCores:44> cluster=<memory:49152, vCores:96>
2013-08-31 00:27:01,277 INFO org.apache.hadoop.yarn.server.resourcemanager.scheduler.capacity.ParentQueue: completedContainer queue=root usedCapacity=0.9791667 absoluteUsedCapacity=0.9791667 used=<memory:48128, vCores:44> cluster=<memory:49152, vCores:96>
2013-08-31 00:27:01,277 INFO org.apache.hadoop.yarn.server.resourcemanager.scheduler.capacity.CapacityScheduler: Application appattempt_1377907764744_0007_000001 released container container_1377907764744_0007_01_000020 on node: host: hadoop-32-5:54799 #containers=6 available=1024 used=7168 with event: FINISHED
2013-08-31 00:27:01,277 INFO org.apache.hadoop.yarn.server.resourcemanager.rmcontainer.RMContainerImpl: container_1377907764744_0006_01_000031 Container Transitioned from NEW to ALLOCATED
2013-08-31 00:27:01,277 INFO org.apache.hadoop.yarn.server.resourcemanager.RMAuditLogger: USER=ubuntu	OPERATION=AM Allocated Container	TARGET=SchedulerApp	RESULT=SUCCESS	APPID=application_1377907764744_0006	CONTAINERID=container_1377907764744_0006_01_000031
2013-08-31 00:27:01,278 INFO org.apache.hadoop.yarn.server.resourcemanager.scheduler.common.fica.FiCaSchedulerNode: Assigned container container_1377907764744_0006_01_000031 of capacity <memory:1024, vCores:1> on host hadoop-32-5:54799, which currently has 7 containers, <memory:8192, vCores:7> used and <memory:0, vCores:9> available
2013-08-31 00:27:01,278 INFO org.apache.hadoop.yarn.server.resourcemanager.scheduler.capacity.LeafQueue: assignedContainer application=application_1377907764744_0006 container=Container: [ContainerId: container_1377907764744_0006_01_000031, NodeId: hadoop-32-5:54799, NodeHttpAddress: hadoop-32-5:8042, Resource: <memory:1024, vCores:1>, Priority: 20, State: NEW, Token: null, Status: container_id {, app_attempt_id {, application_id {, id: 6, cluster_timestamp: 1377907764744, }, attemptId: 1, }, id: 31, }, state: C_NEW, ] containerId=container_1377907764744_0006_01_000031 queue=default: capacity=1.0, absoluteCapacity=1.0, usedResources=<memory:48128, vCores:44>usedCapacity=0.9791667, absoluteUsedCapacity=0.9791667, numApps=5, numContainers=44 usedCapacity=0.9791667 absoluteUsedCapacity=0.9791667 used=<memory:48128, vCores:44> cluster=<memory:49152, vCores:96>
2013-08-31 00:27:01,279 INFO org.apache.hadoop.yarn.server.resourcemanager.scheduler.capacity.ParentQueue: Re-sorting queues since queue: root.default stats: default: capacity=1.0, absoluteCapacity=1.0, usedResources=<memory:49152, vCores:45>usedCapacity=1.0, absoluteUsedCapacity=1.0, numApps=5, numContainers=45
2013-08-31 00:27:01,279 INFO org.apache.hadoop.yarn.server.resourcemanager.scheduler.capacity.ParentQueue: assignedContainer queue=root usedCapacity=1.0 absoluteUsedCapacity=1.0 used=<memory:49152, vCores:45> cluster=<memory:49152, vCores:96>
2013-08-31 00:27:02,649 INFO org.apache.hadoop.yarn.server.resourcemanager.rmcontainer.RMContainerImpl: container_1377907764744_0006_01_000028 Container Transitioned from ACQUIRED to RUNNING
2013-08-31 00:27:02,679 INFO org.apache.hadoop.yarn.server.resourcemanager.rmcontainer.RMContainerImpl: container_1377907764744_0007_01_000021 Container Transitioned from RUNNING to COMPLETED
2013-08-31 00:27:02,679 INFO org.apache.hadoop.yarn.server.resourcemanager.scheduler.common.fica.FiCaSchedulerApp: Completed container: container_1377907764744_0007_01_000021 in state: COMPLETED event:FINISHED
2013-08-31 00:27:02,679 INFO org.apache.hadoop.yarn.server.resourcemanager.RMAuditLogger: USER=ubuntu	OPERATION=AM Released Container	TARGET=SchedulerApp	RESULT=SUCCESS	APPID=application_1377907764744_0007	CONTAINERID=container_1377907764744_0007_01_000021
2013-08-31 00:27:02,679 INFO org.apache.hadoop.yarn.server.resourcemanager.scheduler.common.fica.FiCaSchedulerNode: Released container container_1377907764744_0007_01_000021 of capacity <memory:1024, vCores:1> on host hadoop-32-5:54799, which currently has 6 containers, <memory:7168, vCores:6> used and <memory:1024, vCores:10> available, release resources=true
2013-08-31 00:27:02,679 INFO org.apache.hadoop.yarn.server.resourcemanager.scheduler.capacity.LeafQueue: default used=<memory:48128, vCores:44> numContainers=44 user=ubuntu user-resources=<memory:48128, vCores:44>
2013-08-31 00:27:02,681 INFO org.apache.hadoop.yarn.server.resourcemanager.scheduler.capacity.LeafQueue: completedContainer container=Container: [ContainerId: container_1377907764744_0007_01_000021, NodeId: hadoop-32-5:54799, NodeHttpAddress: hadoop-32-5:8042, Resource: <memory:1024, vCores:1>, Priority: 20, State: NEW, Token: null, Status: container_id {, app_attempt_id {, application_id {, id: 7, cluster_timestamp: 1377907764744, }, attemptId: 1, }, id: 21, }, state: C_COMPLETE, diagnostics: "Container killed by the ApplicationMaster.\n\n", exit_status: 143, ] resource=<memory:1024, vCores:1> queue=default: capacity=1.0, absoluteCapacity=1.0, usedResources=<memory:48128, vCores:44>usedCapacity=0.9791667, absoluteUsedCapacity=0.9791667, numApps=5, numContainers=44 usedCapacity=0.9791667 absoluteUsedCapacity=0.9791667 used=<memory:48128, vCores:44> cluster=<memory:49152, vCores:96>
2013-08-31 00:27:02,681 INFO org.apache.hadoop.yarn.server.resourcemanager.scheduler.capacity.ParentQueue: completedContainer queue=root usedCapacity=0.9791667 absoluteUsedCapacity=0.9791667 used=<memory:48128, vCores:44> cluster=<memory:49152, vCores:96>
2013-08-31 00:27:02,681 INFO org.apache.hadoop.yarn.server.resourcemanager.scheduler.capacity.CapacityScheduler: Application appattempt_1377907764744_0007_000001 released container container_1377907764744_0007_01_000021 on node: host: hadoop-32-5:54799 #containers=6 available=1024 used=7168 with event: FINISHED
2013-08-31 00:27:02,681 INFO org.apache.hadoop.yarn.server.resourcemanager.rmcontainer.RMContainerImpl: container_1377907764744_0006_01_000032 Container Transitioned from NEW to ALLOCATED
2013-08-31 00:27:02,682 INFO org.apache.hadoop.yarn.server.resourcemanager.RMAuditLogger: USER=ubuntu	OPERATION=AM Allocated Container	TARGET=SchedulerApp	RESULT=SUCCESS	APPID=application_1377907764744_0006	CONTAINERID=container_1377907764744_0006_01_000032
2013-08-31 00:27:02,682 INFO org.apache.hadoop.yarn.server.resourcemanager.scheduler.common.fica.FiCaSchedulerNode: Assigned container container_1377907764744_0006_01_000032 of capacity <memory:1024, vCores:1> on host hadoop-32-5:54799, which currently has 7 containers, <memory:8192, vCores:7> used and <memory:0, vCores:9> available
2013-08-31 00:27:02,682 INFO org.apache.hadoop.yarn.server.resourcemanager.scheduler.capacity.LeafQueue: assignedContainer application=application_1377907764744_0006 container=Container: [ContainerId: container_1377907764744_0006_01_000032, NodeId: hadoop-32-5:54799, NodeHttpAddress: hadoop-32-5:8042, Resource: <memory:1024, vCores:1>, Priority: 20, State: NEW, Token: null, Status: container_id {, app_attempt_id {, application_id {, id: 6, cluster_timestamp: 1377907764744, }, attemptId: 1, }, id: 32, }, state: C_NEW, ] containerId=container_1377907764744_0006_01_000032 queue=default: capacity=1.0, absoluteCapacity=1.0, usedResources=<memory:48128, vCores:44>usedCapacity=0.9791667, absoluteUsedCapacity=0.9791667, numApps=5, numContainers=44 usedCapacity=0.9791667 absoluteUsedCapacity=0.9791667 used=<memory:48128, vCores:44> cluster=<memory:49152, vCores:96>
2013-08-31 00:27:02,683 INFO org.apache.hadoop.yarn.server.resourcemanager.scheduler.capacity.ParentQueue: Re-sorting queues since queue: root.default stats: default: capacity=1.0, absoluteCapacity=1.0, usedResources=<memory:49152, vCores:45>usedCapacity=1.0, absoluteUsedCapacity=1.0, numApps=5, numContainers=45
2013-08-31 00:27:02,683 INFO org.apache.hadoop.yarn.server.resourcemanager.scheduler.capacity.ParentQueue: assignedContainer queue=root usedCapacity=1.0 absoluteUsedCapacity=1.0 used=<memory:49152, vCores:45> cluster=<memory:49152, vCores:96>
2013-08-31 00:27:02,721 INFO org.apache.hadoop.yarn.server.resourcemanager.rmcontainer.RMContainerImpl: container_1377907764744_0007_01_000022 Container Transitioned from RUNNING to COMPLETED
2013-08-31 00:27:02,721 INFO org.apache.hadoop.yarn.server.resourcemanager.scheduler.common.fica.FiCaSchedulerApp: Completed container: container_1377907764744_0007_01_000022 in state: COMPLETED event:FINISHED
2013-08-31 00:27:02,721 INFO org.apache.hadoop.yarn.server.resourcemanager.RMAuditLogger: USER=ubuntu	OPERATION=AM Released Container	TARGET=SchedulerApp	RESULT=SUCCESS	APPID=application_1377907764744_0007	CONTAINERID=container_1377907764744_0007_01_000022
2013-08-31 00:27:02,721 INFO org.apache.hadoop.yarn.server.resourcemanager.scheduler.common.fica.FiCaSchedulerNode: Released container container_1377907764744_0007_01_000022 of capacity <memory:1024, vCores:1> on host hadoop-32-3:33603, which currently has 7 containers, <memory:7168, vCores:7> used and <memory:1024, vCores:9> available, release resources=true
2013-08-31 00:27:02,721 INFO org.apache.hadoop.yarn.server.resourcemanager.scheduler.capacity.LeafQueue: default used=<memory:48128, vCores:44> numContainers=44 user=ubuntu user-resources=<memory:48128, vCores:44>
2013-08-31 00:27:02,722 INFO org.apache.hadoop.yarn.server.resourcemanager.scheduler.capacity.LeafQueue: completedContainer container=Container: [ContainerId: container_1377907764744_0007_01_000022, NodeId: hadoop-32-3:33603, NodeHttpAddress: hadoop-32-3:8042, Resource: <memory:1024, vCores:1>, Priority: 20, State: NEW, Token: null, Status: container_id {, app_attempt_id {, application_id {, id: 7, cluster_timestamp: 1377907764744, }, attemptId: 1, }, id: 22, }, state: C_COMPLETE, diagnostics: "Container killed by the ApplicationMaster.\n\n", exit_status: 143, ] resource=<memory:1024, vCores:1> queue=default: capacity=1.0, absoluteCapacity=1.0, usedResources=<memory:48128, vCores:44>usedCapacity=0.9791667, absoluteUsedCapacity=0.9791667, numApps=5, numContainers=44 usedCapacity=0.9791667 absoluteUsedCapacity=0.9791667 used=<memory:48128, vCores:44> cluster=<memory:49152, vCores:96>
2013-08-31 00:27:02,723 INFO org.apache.hadoop.yarn.server.resourcemanager.scheduler.capacity.ParentQueue: completedContainer queue=root usedCapacity=0.9791667 absoluteUsedCapacity=0.9791667 used=<memory:48128, vCores:44> cluster=<memory:49152, vCores:96>
2013-08-31 00:27:02,723 INFO org.apache.hadoop.yarn.server.resourcemanager.scheduler.capacity.CapacityScheduler: Application appattempt_1377907764744_0007_000001 released container container_1377907764744_0007_01_000022 on node: host: hadoop-32-3:33603 #containers=7 available=1024 used=7168 with event: FINISHED
2013-08-31 00:27:02,723 INFO org.apache.hadoop.yarn.server.resourcemanager.rmcontainer.RMContainerImpl: container_1377907764744_0006_01_000033 Container Transitioned from NEW to ALLOCATED
2013-08-31 00:27:02,723 INFO org.apache.hadoop.yarn.server.resourcemanager.RMAuditLogger: USER=ubuntu	OPERATION=AM Allocated Container	TARGET=SchedulerApp	RESULT=SUCCESS	APPID=application_1377907764744_0006	CONTAINERID=container_1377907764744_0006_01_000033
2013-08-31 00:27:02,723 INFO org.apache.hadoop.yarn.server.resourcemanager.scheduler.common.fica.FiCaSchedulerNode: Assigned container container_1377907764744_0006_01_000033 of capacity <memory:1024, vCores:1> on host hadoop-32-3:33603, which currently has 8 containers, <memory:8192, vCores:8> used and <memory:0, vCores:8> available
2013-08-31 00:27:02,725 INFO org.apache.hadoop.yarn.server.resourcemanager.scheduler.capacity.LeafQueue: assignedContainer application=application_1377907764744_0006 container=Container: [ContainerId: container_1377907764744_0006_01_000033, NodeId: hadoop-32-3:33603, NodeHttpAddress: hadoop-32-3:8042, Resource: <memory:1024, vCores:1>, Priority: 20, State: NEW, Token: null, Status: container_id {, app_attempt_id {, application_id {, id: 6, cluster_timestamp: 1377907764744, }, attemptId: 1, }, id: 33, }, state: C_NEW, ] containerId=container_1377907764744_0006_01_000033 queue=default: capacity=1.0, absoluteCapacity=1.0, usedResources=<memory:48128, vCores:44>usedCapacity=0.9791667, absoluteUsedCapacity=0.9791667, numApps=5, numContainers=44 usedCapacity=0.9791667 absoluteUsedCapacity=0.9791667 used=<memory:48128, vCores:44> cluster=<memory:49152, vCores:96>
2013-08-31 00:27:02,725 INFO org.apache.hadoop.yarn.server.resourcemanager.scheduler.capacity.ParentQueue: Re-sorting queues since queue: root.default stats: default: capacity=1.0, absoluteCapacity=1.0, usedResources=<memory:49152, vCores:45>usedCapacity=1.0, absoluteUsedCapacity=1.0, numApps=5, numContainers=45
2013-08-31 00:27:02,725 INFO org.apache.hadoop.yarn.server.resourcemanager.scheduler.capacity.ParentQueue: assignedContainer queue=root usedCapacity=1.0 absoluteUsedCapacity=1.0 used=<memory:49152, vCores:45> cluster=<memory:49152, vCores:96>
2013-08-31 00:27:03,614 INFO org.apache.hadoop.yarn.server.resourcemanager.rmcontainer.RMContainerImpl: container_1377907764744_0006_01_000029 Container Transitioned from ALLOCATED to ACQUIRED
2013-08-31 00:27:03,615 INFO org.apache.hadoop.yarn.server.resourcemanager.rmcontainer.RMContainerImpl: container_1377907764744_0006_01_000030 Container Transitioned from ALLOCATED to ACQUIRED
2013-08-31 00:27:03,615 INFO org.apache.hadoop.yarn.server.resourcemanager.rmcontainer.RMContainerImpl: container_1377907764744_0006_01_000031 Container Transitioned from ALLOCATED to ACQUIRED
2013-08-31 00:27:03,615 INFO org.apache.hadoop.yarn.server.resourcemanager.rmcontainer.RMContainerImpl: container_1377907764744_0006_01_000032 Container Transitioned from ALLOCATED to ACQUIRED
2013-08-31 00:27:03,615 INFO org.apache.hadoop.yarn.server.resourcemanager.rmcontainer.RMContainerImpl: container_1377907764744_0006_01_000033 Container Transitioned from ALLOCATED to ACQUIRED
2013-08-31 00:27:03,735 INFO org.apache.hadoop.yarn.server.resourcemanager.rmcontainer.RMContainerImpl: container_1377907764744_0007_01_000027 Container Transitioned from RUNNING to COMPLETED
2013-08-31 00:27:03,735 INFO org.apache.hadoop.yarn.server.resourcemanager.scheduler.common.fica.FiCaSchedulerApp: Completed container: container_1377907764744_0007_01_000027 in state: COMPLETED event:FINISHED
2013-08-31 00:27:03,736 INFO org.apache.hadoop.yarn.server.resourcemanager.RMAuditLogger: USER=ubuntu	OPERATION=AM Released Container	TARGET=SchedulerApp	RESULT=SUCCESS	APPID=application_1377907764744_0007	CONTAINERID=container_1377907764744_0007_01_000027
2013-08-31 00:27:03,736 INFO org.apache.hadoop.yarn.server.resourcemanager.scheduler.common.fica.FiCaSchedulerNode: Released container container_1377907764744_0007_01_000027 of capacity <memory:1024, vCores:1> on host hadoop-32-3:33603, which currently has 7 containers, <memory:7168, vCores:7> used and <memory:1024, vCores:9> available, release resources=true
2013-08-31 00:27:03,736 INFO org.apache.hadoop.yarn.server.resourcemanager.scheduler.capacity.LeafQueue: default used=<memory:48128, vCores:44> numContainers=44 user=ubuntu user-resources=<memory:48128, vCores:44>
2013-08-31 00:27:03,737 INFO org.apache.hadoop.yarn.server.resourcemanager.scheduler.capacity.LeafQueue: completedContainer container=Container: [ContainerId: container_1377907764744_0007_01_000027, NodeId: hadoop-32-3:33603, NodeHttpAddress: hadoop-32-3:8042, Resource: <memory:1024, vCores:1>, Priority: 20, State: NEW, Token: null, Status: container_id {, app_attempt_id {, application_id {, id: 7, cluster_timestamp: 1377907764744, }, attemptId: 1, }, id: 27, }, state: C_COMPLETE, diagnostics: "Container killed by the ApplicationMaster.\n\n", exit_status: 143, ] resource=<memory:1024, vCores:1> queue=default: capacity=1.0, absoluteCapacity=1.0, usedResources=<memory:48128, vCores:44>usedCapacity=0.9791667, absoluteUsedCapacity=0.9791667, numApps=5, numContainers=44 usedCapacity=0.9791667 absoluteUsedCapacity=0.9791667 used=<memory:48128, vCores:44> cluster=<memory:49152, vCores:96>
2013-08-31 00:27:03,737 INFO org.apache.hadoop.yarn.server.resourcemanager.scheduler.capacity.ParentQueue: completedContainer queue=root usedCapacity=0.9791667 absoluteUsedCapacity=0.9791667 used=<memory:48128, vCores:44> cluster=<memory:49152, vCores:96>
2013-08-31 00:27:03,737 INFO org.apache.hadoop.yarn.server.resourcemanager.scheduler.capacity.CapacityScheduler: Application appattempt_1377907764744_0007_000001 released container container_1377907764744_0007_01_000027 on node: host: hadoop-32-3:33603 #containers=7 available=1024 used=7168 with event: FINISHED
2013-08-31 00:27:03,738 INFO org.apache.hadoop.yarn.server.resourcemanager.rmcontainer.RMContainerImpl: container_1377907764744_0006_01_000034 Container Transitioned from NEW to ALLOCATED
2013-08-31 00:27:03,738 INFO org.apache.hadoop.yarn.server.resourcemanager.RMAuditLogger: USER=ubuntu	OPERATION=AM Allocated Container	TARGET=SchedulerApp	RESULT=SUCCESS	APPID=application_1377907764744_0006	CONTAINERID=container_1377907764744_0006_01_000034
2013-08-31 00:27:03,738 INFO org.apache.hadoop.yarn.server.resourcemanager.scheduler.common.fica.FiCaSchedulerNode: Assigned container container_1377907764744_0006_01_000034 of capacity <memory:1024, vCores:1> on host hadoop-32-3:33603, which currently has 8 containers, <memory:8192, vCores:8> used and <memory:0, vCores:8> available
2013-08-31 00:27:03,739 INFO org.apache.hadoop.yarn.server.resourcemanager.scheduler.capacity.LeafQueue: assignedContainer application=application_1377907764744_0006 container=Container: [ContainerId: container_1377907764744_0006_01_000034, NodeId: hadoop-32-3:33603, NodeHttpAddress: hadoop-32-3:8042, Resource: <memory:1024, vCores:1>, Priority: 20, State: NEW, Token: null, Status: container_id {, app_attempt_id {, application_id {, id: 6, cluster_timestamp: 1377907764744, }, attemptId: 1, }, id: 34, }, state: C_NEW, ] containerId=container_1377907764744_0006_01_000034 queue=default: capacity=1.0, absoluteCapacity=1.0, usedResources=<memory:48128, vCores:44>usedCapacity=0.9791667, absoluteUsedCapacity=0.9791667, numApps=5, numContainers=44 usedCapacity=0.9791667 absoluteUsedCapacity=0.9791667 used=<memory:48128, vCores:44> cluster=<memory:49152, vCores:96>
2013-08-31 00:27:03,739 INFO org.apache.hadoop.yarn.server.resourcemanager.scheduler.capacity.ParentQueue: Re-sorting queues since queue: root.default stats: default: capacity=1.0, absoluteCapacity=1.0, usedResources=<memory:49152, vCores:45>usedCapacity=1.0, absoluteUsedCapacity=1.0, numApps=5, numContainers=45
2013-08-31 00:27:03,739 INFO org.apache.hadoop.yarn.server.resourcemanager.scheduler.capacity.ParentQueue: assignedContainer queue=root usedCapacity=1.0 absoluteUsedCapacity=1.0 used=<memory:49152, vCores:45> cluster=<memory:49152, vCores:96>
2013-08-31 00:27:04,181 INFO org.apache.hadoop.yarn.server.resourcemanager.rmcontainer.RMContainerImpl: container_1377907764744_0006_01_000029 Container Transitioned from ACQUIRED to RUNNING
2013-08-31 00:27:04,686 INFO org.apache.hadoop.yarn.server.resourcemanager.rmcontainer.RMContainerImpl: container_1377907764744_0006_01_000034 Container Transitioned from ALLOCATED to ACQUIRED
2013-08-31 00:27:04,704 INFO org.apache.hadoop.yarn.server.resourcemanager.rmcontainer.RMContainerImpl: container_1377907764744_0006_01_000031 Container Transitioned from ACQUIRED to RUNNING
2013-08-31 00:27:04,704 INFO org.apache.hadoop.yarn.server.resourcemanager.rmcontainer.RMContainerImpl: container_1377907764744_0006_01_000032 Container Transitioned from ACQUIRED to RUNNING
2013-08-31 00:27:04,763 INFO org.apache.hadoop.yarn.server.resourcemanager.rmcontainer.RMContainerImpl: container_1377907764744_0006_01_000030 Container Transitioned from ACQUIRED to RUNNING
2013-08-31 00:27:04,764 INFO org.apache.hadoop.yarn.server.resourcemanager.rmcontainer.RMContainerImpl: container_1377907764744_0006_01_000033 Container Transitioned from ACQUIRED to RUNNING
2013-08-31 00:27:04,764 INFO org.apache.hadoop.yarn.server.resourcemanager.rmcontainer.RMContainerImpl: container_1377907764744_0006_01_000034 Container Transitioned from ACQUIRED to RUNNING
2013-08-31 00:27:05,482 INFO org.apache.hadoop.yarn.server.resourcemanager.rmcontainer.RMContainerImpl: container_1377907764744_0006_01_000013 Container Transitioned from RUNNING to COMPLETED
2013-08-31 00:27:05,483 INFO org.apache.hadoop.yarn.server.resourcemanager.scheduler.common.fica.FiCaSchedulerApp: Completed container: container_1377907764744_0006_01_000013 in state: COMPLETED event:FINISHED
2013-08-31 00:27:05,483 INFO org.apache.hadoop.yarn.server.resourcemanager.RMAuditLogger: USER=ubuntu	OPERATION=AM Released Container	TARGET=SchedulerApp	RESULT=SUCCESS	APPID=application_1377907764744_0006	CONTAINERID=container_1377907764744_0006_01_000013
2013-08-31 00:27:05,483 INFO org.apache.hadoop.yarn.server.resourcemanager.scheduler.common.fica.FiCaSchedulerNode: Released container container_1377907764744_0006_01_000013 of capacity <memory:1024, vCores:1> on host hadoop-32-6:48039, which currently has 7 containers, <memory:7168, vCores:7> used and <memory:1024, vCores:9> available, release resources=true
2013-08-31 00:27:05,483 INFO org.apache.hadoop.yarn.server.resourcemanager.scheduler.capacity.LeafQueue: default used=<memory:48128, vCores:44> numContainers=44 user=ubuntu user-resources=<memory:48128, vCores:44>
2013-08-31 00:27:05,484 INFO org.apache.hadoop.yarn.server.resourcemanager.scheduler.capacity.LeafQueue: completedContainer container=Container: [ContainerId: container_1377907764744_0006_01_000013, NodeId: hadoop-32-6:48039, NodeHttpAddress: hadoop-32-6:8042, Resource: <memory:1024, vCores:1>, Priority: 20, State: NEW, Token: null, Status: container_id {, app_attempt_id {, application_id {, id: 6, cluster_timestamp: 1377907764744, }, attemptId: 1, }, id: 13, }, state: C_COMPLETE, diagnostics: "Container killed by the ApplicationMaster.\n\n", exit_status: 143, ] resource=<memory:1024, vCores:1> queue=default: capacity=1.0, absoluteCapacity=1.0, usedResources=<memory:48128, vCores:44>usedCapacity=0.9791667, absoluteUsedCapacity=0.9791667, numApps=5, numContainers=44 usedCapacity=0.9791667 absoluteUsedCapacity=0.9791667 used=<memory:48128, vCores:44> cluster=<memory:49152, vCores:96>
2013-08-31 00:27:05,484 INFO org.apache.hadoop.yarn.server.resourcemanager.scheduler.capacity.ParentQueue: completedContainer queue=root usedCapacity=0.9791667 absoluteUsedCapacity=0.9791667 used=<memory:48128, vCores:44> cluster=<memory:49152, vCores:96>
2013-08-31 00:27:05,484 INFO org.apache.hadoop.yarn.server.resourcemanager.scheduler.capacity.CapacityScheduler: Application appattempt_1377907764744_0006_000001 released container container_1377907764744_0006_01_000013 on node: host: hadoop-32-6:48039 #containers=7 available=1024 used=7168 with event: FINISHED
2013-08-31 00:27:05,485 INFO org.apache.hadoop.yarn.server.resourcemanager.rmcontainer.RMContainerImpl: container_1377907764744_0006_01_000035 Container Transitioned from NEW to ALLOCATED
2013-08-31 00:27:05,485 INFO org.apache.hadoop.yarn.server.resourcemanager.RMAuditLogger: USER=ubuntu	OPERATION=AM Allocated Container	TARGET=SchedulerApp	RESULT=SUCCESS	APPID=application_1377907764744_0006	CONTAINERID=container_1377907764744_0006_01_000035
2013-08-31 00:27:05,485 INFO org.apache.hadoop.yarn.server.resourcemanager.scheduler.common.fica.FiCaSchedulerNode: Assigned container container_1377907764744_0006_01_000035 of capacity <memory:1024, vCores:1> on host hadoop-32-6:48039, which currently has 8 containers, <memory:8192, vCores:8> used and <memory:0, vCores:8> available
2013-08-31 00:27:05,486 INFO org.apache.hadoop.yarn.server.resourcemanager.scheduler.capacity.LeafQueue: assignedContainer application=application_1377907764744_0006 container=Container: [ContainerId: container_1377907764744_0006_01_000035, NodeId: hadoop-32-6:48039, NodeHttpAddress: hadoop-32-6:8042, Resource: <memory:1024, vCores:1>, Priority: 20, State: NEW, Token: null, Status: container_id {, app_attempt_id {, application_id {, id: 6, cluster_timestamp: 1377907764744, }, attemptId: 1, }, id: 35, }, state: C_NEW, ] containerId=container_1377907764744_0006_01_000035 queue=default: capacity=1.0, absoluteCapacity=1.0, usedResources=<memory:48128, vCores:44>usedCapacity=0.9791667, absoluteUsedCapacity=0.9791667, numApps=5, numContainers=44 usedCapacity=0.9791667 absoluteUsedCapacity=0.9791667 used=<memory:48128, vCores:44> cluster=<memory:49152, vCores:96>
2013-08-31 00:27:05,486 INFO org.apache.hadoop.yarn.server.resourcemanager.scheduler.capacity.ParentQueue: Re-sorting queues since queue: root.default stats: default: capacity=1.0, absoluteCapacity=1.0, usedResources=<memory:49152, vCores:45>usedCapacity=1.0, absoluteUsedCapacity=1.0, numApps=5, numContainers=45
2013-08-31 00:27:05,486 INFO org.apache.hadoop.yarn.server.resourcemanager.scheduler.capacity.ParentQueue: assignedContainer queue=root usedCapacity=1.0 absoluteUsedCapacity=1.0 used=<memory:49152, vCores:45> cluster=<memory:49152, vCores:96>
2013-08-31 00:27:05,737 INFO org.apache.hadoop.yarn.server.resourcemanager.rmcontainer.RMContainerImpl: container_1377907764744_0006_01_000035 Container Transitioned from ALLOCATED to ACQUIRED
2013-08-31 00:27:06,557 INFO org.apache.hadoop.yarn.server.resourcemanager.rmcontainer.RMContainerImpl: container_1377907764744_0006_01_000035 Container Transitioned from ACQUIRED to RUNNING
2013-08-31 00:27:07,842 INFO org.apache.hadoop.yarn.server.resourcemanager.rmcontainer.RMContainerImpl: container_1377907764744_0006_01_000015 Container Transitioned from RUNNING to COMPLETED
2013-08-31 00:27:07,842 INFO org.apache.hadoop.yarn.server.resourcemanager.scheduler.common.fica.FiCaSchedulerApp: Completed container: container_1377907764744_0006_01_000015 in state: COMPLETED event:FINISHED
2013-08-31 00:27:07,842 INFO org.apache.hadoop.yarn.server.resourcemanager.RMAuditLogger: USER=ubuntu	OPERATION=AM Released Container	TARGET=SchedulerApp	RESULT=SUCCESS	APPID=application_1377907764744_0006	CONTAINERID=container_1377907764744_0006_01_000015
2013-08-31 00:27:07,843 INFO org.apache.hadoop.yarn.server.resourcemanager.scheduler.common.fica.FiCaSchedulerNode: Released container container_1377907764744_0006_01_000015 of capacity <memory:1024, vCores:1> on host hadoop-32-6:48039, which currently has 7 containers, <memory:7168, vCores:7> used and <memory:1024, vCores:9> available, release resources=true
2013-08-31 00:27:07,843 INFO org.apache.hadoop.yarn.server.resourcemanager.scheduler.capacity.LeafQueue: default used=<memory:48128, vCores:44> numContainers=44 user=ubuntu user-resources=<memory:48128, vCores:44>
2013-08-31 00:27:07,844 INFO org.apache.hadoop.yarn.server.resourcemanager.scheduler.capacity.LeafQueue: completedContainer container=Container: [ContainerId: container_1377907764744_0006_01_000015, NodeId: hadoop-32-6:48039, NodeHttpAddress: hadoop-32-6:8042, Resource: <memory:1024, vCores:1>, Priority: 20, State: NEW, Token: null, Status: container_id {, app_attempt_id {, application_id {, id: 6, cluster_timestamp: 1377907764744, }, attemptId: 1, }, id: 15, }, state: C_COMPLETE, diagnostics: "", exit_status: 0, ] resource=<memory:1024, vCores:1> queue=default: capacity=1.0, absoluteCapacity=1.0, usedResources=<memory:48128, vCores:44>usedCapacity=0.9791667, absoluteUsedCapacity=0.9791667, numApps=5, numContainers=44 usedCapacity=0.9791667 absoluteUsedCapacity=0.9791667 used=<memory:48128, vCores:44> cluster=<memory:49152, vCores:96>
2013-08-31 00:27:07,844 INFO org.apache.hadoop.yarn.server.resourcemanager.scheduler.capacity.ParentQueue: completedContainer queue=root usedCapacity=0.9791667 absoluteUsedCapacity=0.9791667 used=<memory:48128, vCores:44> cluster=<memory:49152, vCores:96>
2013-08-31 00:27:07,844 INFO org.apache.hadoop.yarn.server.resourcemanager.scheduler.capacity.CapacityScheduler: Application appattempt_1377907764744_0006_000001 released container container_1377907764744_0006_01_000015 on node: host: hadoop-32-6:48039 #containers=7 available=1024 used=7168 with event: FINISHED
2013-08-31 00:27:07,845 INFO org.apache.hadoop.yarn.server.resourcemanager.rmcontainer.RMContainerImpl: container_1377907764744_0006_01_000036 Container Transitioned from NEW to ALLOCATED
2013-08-31 00:27:07,845 INFO org.apache.hadoop.yarn.server.resourcemanager.RMAuditLogger: USER=ubuntu	OPERATION=AM Allocated Container	TARGET=SchedulerApp	RESULT=SUCCESS	APPID=application_1377907764744_0006	CONTAINERID=container_1377907764744_0006_01_000036
2013-08-31 00:27:07,845 INFO org.apache.hadoop.yarn.server.resourcemanager.scheduler.common.fica.FiCaSchedulerNode: Assigned container container_1377907764744_0006_01_000036 of capacity <memory:1024, vCores:1> on host hadoop-32-6:48039, which currently has 8 containers, <memory:8192, vCores:8> used and <memory:0, vCores:8> available
2013-08-31 00:27:07,848 INFO org.apache.hadoop.yarn.server.resourcemanager.scheduler.capacity.LeafQueue: assignedContainer application=application_1377907764744_0006 container=Container: [ContainerId: container_1377907764744_0006_01_000036, NodeId: hadoop-32-6:48039, NodeHttpAddress: hadoop-32-6:8042, Resource: <memory:1024, vCores:1>, Priority: 20, State: NEW, Token: null, Status: container_id {, app_attempt_id {, application_id {, id: 6, cluster_timestamp: 1377907764744, }, attemptId: 1, }, id: 36, }, state: C_NEW, ] containerId=container_1377907764744_0006_01_000036 queue=default: capacity=1.0, absoluteCapacity=1.0, usedResources=<memory:48128, vCores:44>usedCapacity=0.9791667, absoluteUsedCapacity=0.9791667, numApps=5, numContainers=44 usedCapacity=0.9791667 absoluteUsedCapacity=0.9791667 used=<memory:48128, vCores:44> cluster=<memory:49152, vCores:96>
2013-08-31 00:27:07,849 INFO org.apache.hadoop.yarn.server.resourcemanager.scheduler.capacity.ParentQueue: Re-sorting queues since queue: root.default stats: default: capacity=1.0, absoluteCapacity=1.0, usedResources=<memory:49152, vCores:45>usedCapacity=1.0, absoluteUsedCapacity=1.0, numApps=5, numContainers=45
2013-08-31 00:27:07,849 INFO org.apache.hadoop.yarn.server.resourcemanager.scheduler.capacity.ParentQueue: assignedContainer queue=root usedCapacity=1.0 absoluteUsedCapacity=1.0 used=<memory:49152, vCores:45> cluster=<memory:49152, vCores:96>
2013-08-31 00:27:08,832 INFO org.apache.hadoop.yarn.server.resourcemanager.rmcontainer.RMContainerImpl: container_1377907764744_0006_01_000036 Container Transitioned from ALLOCATED to ACQUIRED
2013-08-31 00:27:10,819 INFO org.apache.hadoop.yarn.server.resourcemanager.rmcontainer.RMContainerImpl: container_1377907764744_0006_01_000036 Container Transitioned from ACQUIRED to RUNNING
2013-08-31 00:27:15,075 INFO org.apache.hadoop.yarn.server.resourcemanager.rmcontainer.RMContainerImpl: container_1377907764744_0006_01_000018 Container Transitioned from RUNNING to COMPLETED
2013-08-31 00:27:15,076 INFO org.apache.hadoop.yarn.server.resourcemanager.scheduler.common.fica.FiCaSchedulerApp: Completed container: container_1377907764744_0006_01_000018 in state: COMPLETED event:FINISHED
2013-08-31 00:27:15,076 INFO org.apache.hadoop.yarn.server.resourcemanager.RMAuditLogger: USER=ubuntu	OPERATION=AM Released Container	TARGET=SchedulerApp	RESULT=SUCCESS	APPID=application_1377907764744_0006	CONTAINERID=container_1377907764744_0006_01_000018
2013-08-31 00:27:15,076 INFO org.apache.hadoop.yarn.server.resourcemanager.scheduler.common.fica.FiCaSchedulerNode: Released container container_1377907764744_0006_01_000018 of capacity <memory:1024, vCores:1> on host hadoop-32-2:38703, which currently has 6 containers, <memory:7168, vCores:6> used and <memory:1024, vCores:10> available, release resources=true
2013-08-31 00:27:15,076 INFO org.apache.hadoop.yarn.server.resourcemanager.scheduler.capacity.LeafQueue: default used=<memory:48128, vCores:44> numContainers=44 user=ubuntu user-resources=<memory:48128, vCores:44>
