2013-08-06 12:42:51,691 INFO org.apache.hadoop.yarn.server.resourcemanager.ResourceManager: STARTUP_MSG: 
/************************************************************
STARTUP_MSG: Starting ResourceManager
STARTUP_MSG:   host = hadoop-110-1/192.168.100.2
STARTUP_MSG:   args = []
STARTUP_MSG:   version = 3.0.0-SNAPSHOT
STARTUP_MSG:   build = https://github.com/lalithsuresh/hadoop-common -r 0cb423bd4868928bb06cd93f882bb0913172fd17; compiled by 'lsuresh' on 2013-04-08T15:47Z
STARTUP_MSG:   java = 1.7.0_17
************************************************************/
2013-08-06 12:42:51,705 INFO org.apache.hadoop.yarn.server.resourcemanager.ResourceManager: registered UNIX signal handlers for [TERM, HUP, INT]
2013-08-06 12:42:52,385 INFO org.apache.hadoop.yarn.server.resourcemanager.security.ApplicationTokenSecretManager: Rolling master-key for application-tokens
2013-08-06 12:42:52,448 INFO org.apache.hadoop.yarn.server.resourcemanager.security.RMContainerTokenSecretManager: ContainerTokenKeyRollingInterval: 86400000ms and ContainerTokenKeyActivationDelay: 900000ms
2013-08-06 12:42:52,452 INFO org.apache.hadoop.yarn.service.AbstractService: Service:Dispatcher is inited.
2013-08-06 12:42:52,456 INFO org.apache.hadoop.yarn.event.AsyncDispatcher: Registering class org.apache.hadoop.yarn.server.resourcemanager.recovery.RMStateStoreEventType for class org.apache.hadoop.yarn.server.resourcemanager.recovery.RMStateStore$ForwardingEventHandler
2013-08-06 12:42:52,456 INFO org.apache.hadoop.yarn.service.AbstractService: Service:Dispatcher is started.
2013-08-06 12:42:52,470 INFO org.apache.hadoop.yarn.event.AsyncDispatcher: Registering class org.apache.hadoop.yarn.server.resourcemanager.NodesListManagerEventType for class org.apache.hadoop.yarn.server.resourcemanager.NodesListManager
2013-08-06 12:42:52,470 INFO org.apache.hadoop.yarn.server.resourcemanager.ResourceManager: Using Scheduler: org.apache.hadoop.yarn.server.resourcemanager.scheduler.capacity.CapacityScheduler
2013-08-06 12:42:52,749 INFO org.apache.hadoop.yarn.event.AsyncDispatcher: Registering class org.apache.hadoop.yarn.server.resourcemanager.scheduler.event.SchedulerEventType for class org.apache.hadoop.yarn.server.resourcemanager.ResourceManager$SchedulerEventDispatcher
2013-08-06 12:42:52,752 INFO org.apache.hadoop.yarn.event.AsyncDispatcher: Registering class org.apache.hadoop.yarn.server.resourcemanager.rmapp.RMAppEventType for class org.apache.hadoop.yarn.server.resourcemanager.ResourceManager$ApplicationEventDispatcher
2013-08-06 12:42:52,759 INFO org.apache.hadoop.yarn.event.AsyncDispatcher: Registering class org.apache.hadoop.yarn.server.resourcemanager.rmapp.attempt.RMAppAttemptEventType for class org.apache.hadoop.yarn.server.resourcemanager.ResourceManager$ApplicationAttemptEventDispatcher
2013-08-06 12:42:52,762 INFO org.apache.hadoop.yarn.event.AsyncDispatcher: Registering class org.apache.hadoop.yarn.server.resourcemanager.rmnode.RMNodeEventType for class org.apache.hadoop.yarn.server.resourcemanager.ResourceManager$NodeEventDispatcher
2013-08-06 12:42:53,457 WARN org.apache.hadoop.util.NativeCodeLoader: Unable to load native-hadoop library for your platform... using builtin-java classes where applicable
2013-08-06 12:42:53,541 INFO org.apache.hadoop.yarn.server.resourcemanager.scheduler.capacity.ParentQueue: root, capacity=1.0, asboluteCapacity=1.0, maxCapacity=1.0, asboluteMaxCapacity=1.0, state=RUNNING, acls=SUBMIT_APPLICATIONS:*ADMINISTER_QUEUE:*
2013-08-06 12:42:53,541 INFO org.apache.hadoop.yarn.server.resourcemanager.scheduler.capacity.ParentQueue: Initialized parent-queue root name=root, fullname=root
2013-08-06 12:42:53,558 INFO org.apache.hadoop.yarn.server.resourcemanager.scheduler.capacity.LeafQueue: Initializing default
capacity = 1.0 [= (float) configuredCapacity / 100 ]
asboluteCapacity = 1.0 [= parentAbsoluteCapacity * capacity ]
maxCapacity = 1.0 [= configuredMaxCapacity ]
absoluteMaxCapacity = 1.0 [= 1.0 maximumCapacity undefined, (parentAbsoluteMaxCapacity * maximumCapacity) / 100 otherwise ]
userLimit = 100 [= configuredUserLimit ]
userLimitFactor = 1.0 [= configuredUserLimitFactor ]
maxApplications = 10000 [= configuredMaximumSystemApplicationsPerQueue or (int)(configuredMaximumSystemApplications * absoluteCapacity)]
maxApplicationsPerUser = 10000 [= (int)(maxApplications * (userLimit / 100.0f) * userLimitFactor) ]
maxActiveApplications = 1 [= max((int)ceil((clusterResourceMemory / minimumAllocation) * maxAMResourcePerQueuePercent * absoluteMaxCapacity),1) ]
maxActiveAppsUsingAbsCap = 1 [= max((int)ceil((clusterResourceMemory / minimumAllocation) *maxAMResourcePercent * absoluteCapacity),1) ]
maxActiveApplicationsPerUser = 1 [= max((int)(maxActiveApplications * (userLimit / 100.0f) * userLimitFactor),1) ]
usedCapacity = 0.0 [= usedResourcesMemory / (clusterResourceMemory * absoluteCapacity)]
absoluteUsedCapacity = 0.0 [= usedResourcesMemory / clusterResourceMemory]
maxAMResourcePerQueuePercent = 0.1 [= configuredMaximumAMResourcePercent ]
minimumAllocationFactor = 0.875 [= (float)(maximumAllocationMemory - minimumAllocationMemory) / maximumAllocationMemory ]
numContainers = 0 [= currentNumContainers ]
state = RUNNING [= configuredState ]
acls = SUBMIT_APPLICATIONS:*ADMINISTER_QUEUE:* [= configuredAcls ]

2013-08-06 12:42:53,559 INFO org.apache.hadoop.yarn.server.resourcemanager.scheduler.capacity.CapacityScheduler: Initialized queue: default: capacity=1.0, absoluteCapacity=1.0, usedResources=<memory:0, vCores:0>usedCapacity=0.0, absoluteUsedCapacity=0.0, numApps=0, numContainers=0
2013-08-06 12:42:53,559 INFO org.apache.hadoop.yarn.server.resourcemanager.scheduler.capacity.CapacityScheduler: Initialized queue: root: numChildQueue= 1, capacity=1.0, absoluteCapacity=1.0, usedResources=<memory:0, vCores:0>usedCapacity=0.0, numApps=0, numContainers=0
2013-08-06 12:42:53,559 INFO org.apache.hadoop.yarn.server.resourcemanager.scheduler.capacity.CapacityScheduler: Initialized root queue root: numChildQueue= 1, capacity=1.0, absoluteCapacity=1.0, usedResources=<memory:0, vCores:0>usedCapacity=0.0, numApps=0, numContainers=0
2013-08-06 12:42:53,559 INFO org.apache.hadoop.yarn.server.resourcemanager.scheduler.capacity.CapacityScheduler: Initialized CapacityScheduler with calculator=class org.apache.hadoop.yarn.server.resourcemanager.resource.DefaultResourceCalculator, minimumAllocation=<<memory:1024, vCores:1>>, maximumAllocation=<<memory:8192, vCores:32>>
2013-08-06 12:42:53,898 INFO org.apache.hadoop.yarn.event.AsyncDispatcher: Registering class org.apache.hadoop.yarn.server.resourcemanager.RMAppManagerEventType for class org.apache.hadoop.yarn.server.resourcemanager.RMAppManager
2013-08-06 12:42:53,921 INFO org.apache.hadoop.yarn.event.AsyncDispatcher: Registering class org.apache.hadoop.yarn.server.resourcemanager.amlauncher.AMLauncherEventType for class org.apache.hadoop.yarn.server.resourcemanager.amlauncher.ApplicationMasterLauncher
2013-08-06 12:42:54,015 INFO org.apache.hadoop.yarn.server.resourcemanager.RMNMInfo: Registered RMNMInfo MBean
2013-08-06 12:42:54,015 INFO org.apache.hadoop.yarn.service.AbstractService: Service:Dispatcher is inited.
2013-08-06 12:42:54,015 INFO org.apache.hadoop.yarn.service.AbstractService: Service:org.apache.hadoop.yarn.server.resourcemanager.rmcontainer.ContainerAllocationExpirer is inited.
2013-08-06 12:42:54,015 INFO org.apache.hadoop.yarn.service.AbstractService: Service:AMLivelinessMonitor is inited.
2013-08-06 12:42:54,015 INFO org.apache.hadoop.yarn.service.AbstractService: Service:AMLivelinessMonitor is inited.
2013-08-06 12:42:54,015 INFO org.apache.hadoop.yarn.service.AbstractService: Service:org.apache.hadoop.yarn.server.resourcemanager.security.DelegationTokenRenewer is inited.
2013-08-06 12:42:54,017 INFO org.apache.hadoop.util.HostsFileReader: Refreshing hosts (include/exclude) list
2013-08-06 12:42:54,017 INFO org.apache.hadoop.yarn.service.AbstractService: Service:org.apache.hadoop.yarn.server.resourcemanager.NodesListManager is inited.
2013-08-06 12:42:54,017 INFO org.apache.hadoop.yarn.service.AbstractService: Service:org.apache.hadoop.yarn.server.resourcemanager.ResourceManager$SchedulerEventDispatcher is inited.
2013-08-06 12:42:54,017 INFO org.apache.hadoop.yarn.service.AbstractService: Service:NMLivelinessMonitor is inited.
2013-08-06 12:42:54,025 INFO org.apache.hadoop.yarn.service.AbstractService: Service:org.apache.hadoop.yarn.server.resourcemanager.ResourceTrackerService is inited.
2013-08-06 12:42:54,025 INFO org.apache.hadoop.yarn.service.AbstractService: Service:org.apache.hadoop.yarn.server.resourcemanager.ApplicationMasterService is inited.
2013-08-06 12:42:54,025 INFO org.apache.hadoop.yarn.service.AbstractService: Service:org.apache.hadoop.yarn.server.resourcemanager.ClientRMService is inited.
2013-08-06 12:42:54,025 INFO org.apache.hadoop.yarn.service.AbstractService: Service:org.apache.hadoop.yarn.server.resourcemanager.AdminService is inited.
2013-08-06 12:42:54,025 INFO org.apache.hadoop.yarn.service.AbstractService: Service:org.apache.hadoop.yarn.server.resourcemanager.amlauncher.ApplicationMasterLauncher is inited.
2013-08-06 12:42:54,026 INFO org.apache.hadoop.yarn.service.AbstractService: Service:ResourceManager is inited.
2013-08-06 12:42:54,026 INFO org.apache.hadoop.yarn.server.resourcemanager.security.ApplicationTokenSecretManager: Rolling master-key for application-tokens
2013-08-06 12:42:54,026 INFO org.apache.hadoop.yarn.server.resourcemanager.security.RMContainerTokenSecretManager: Rolling master-key for container-tokens
2013-08-06 12:42:54,170 INFO org.mortbay.log: Logging to org.slf4j.impl.Log4jLoggerAdapter(org.mortbay.log) via org.mortbay.log.Slf4jLog
2013-08-06 12:42:54,260 INFO org.apache.hadoop.http.HttpServer: Added global filter 'safety' (class=org.apache.hadoop.http.HttpServer$QuotingInputFilter)
2013-08-06 12:42:54,264 INFO org.apache.hadoop.http.HttpServer: Added filter static_user_filter (class=org.apache.hadoop.http.lib.StaticUserWebFilter$StaticUserFilter) to context cluster
2013-08-06 12:42:54,265 INFO org.apache.hadoop.http.HttpServer: Added filter static_user_filter (class=org.apache.hadoop.http.lib.StaticUserWebFilter$StaticUserFilter) to context logs
2013-08-06 12:42:54,265 INFO org.apache.hadoop.http.HttpServer: Added filter static_user_filter (class=org.apache.hadoop.http.lib.StaticUserWebFilter$StaticUserFilter) to context static
2013-08-06 12:42:54,271 INFO org.apache.hadoop.http.HttpServer: adding path spec: /cluster
2013-08-06 12:42:54,271 INFO org.apache.hadoop.http.HttpServer: adding path spec: /cluster/*
2013-08-06 12:42:54,272 INFO org.apache.hadoop.http.HttpServer: adding path spec: /ws
2013-08-06 12:42:54,272 INFO org.apache.hadoop.http.HttpServer: adding path spec: /ws/*
2013-08-06 12:42:54,274 INFO org.apache.hadoop.http.HttpServer: Added global filter 'guice' (class=com.google.inject.servlet.GuiceFilter)
2013-08-06 12:42:54,283 INFO org.apache.hadoop.http.HttpServer: Jetty bound to port 8088
2013-08-06 12:42:54,283 INFO org.mortbay.log: jetty-6.1.26
2013-08-06 12:42:54,330 INFO org.mortbay.log: Extract jar:file:/home/ubuntu/hadoop-3.0.0-SNAPSHOT/share/hadoop/yarn/hadoop-yarn-common-3.0.0-SNAPSHOT.jar!/webapps/cluster to /tmp/Jetty_0_0_0_0_8088_cluster____u0rgz3/webapp
2013-08-06 12:42:54,722 INFO org.mortbay.log: Started SelectChannelConnector@0.0.0.0:8088
2013-08-06 12:42:54,722 INFO org.apache.hadoop.yarn.webapp.WebApps: Web app /cluster started at 8088
2013-08-06 12:42:55,538 INFO org.apache.hadoop.yarn.webapp.WebApps: Registered webapp guice modules
2013-08-06 12:42:55,658 INFO org.apache.hadoop.metrics2.impl.MetricsConfig: loaded properties from hadoop-metrics2.properties
2013-08-06 12:42:55,696 INFO org.apache.hadoop.metrics2.impl.MetricsSystemImpl: Scheduled snapshot period at 10 second(s).
2013-08-06 12:42:55,696 INFO org.apache.hadoop.metrics2.impl.MetricsSystemImpl: ResourceManager metrics system started
2013-08-06 12:42:55,712 INFO org.apache.hadoop.security.token.delegation.AbstractDelegationTokenSecretManager: Updating the current master key for generating delegation tokens
2013-08-06 12:42:55,716 INFO org.apache.hadoop.yarn.service.AbstractService: Service:Dispatcher is started.
2013-08-06 12:42:55,716 INFO org.apache.hadoop.security.token.delegation.AbstractDelegationTokenSecretManager: Starting expired delegation token remover thread, tokenRemoverScanInterval=60 min(s)
2013-08-06 12:42:55,717 INFO org.apache.hadoop.security.token.delegation.AbstractDelegationTokenSecretManager: Updating the current master key for generating delegation tokens
2013-08-06 12:42:55,719 INFO org.apache.hadoop.yarn.service.AbstractService: Service:org.apache.hadoop.yarn.server.resourcemanager.rmcontainer.ContainerAllocationExpirer is started.
2013-08-06 12:42:55,719 INFO org.apache.hadoop.yarn.service.AbstractService: Service:AMLivelinessMonitor is started.
2013-08-06 12:42:55,720 INFO org.apache.hadoop.yarn.service.AbstractService: Service:AMLivelinessMonitor is started.
2013-08-06 12:42:55,720 INFO org.apache.hadoop.yarn.service.AbstractService: Service:org.apache.hadoop.yarn.server.resourcemanager.security.DelegationTokenRenewer is started.
2013-08-06 12:42:55,721 INFO org.apache.hadoop.yarn.service.AbstractService: Service:org.apache.hadoop.yarn.server.resourcemanager.NodesListManager is started.
2013-08-06 12:42:55,721 INFO org.apache.hadoop.yarn.service.AbstractService: Service:org.apache.hadoop.yarn.server.resourcemanager.ResourceManager$SchedulerEventDispatcher is started.
2013-08-06 12:42:55,722 INFO org.apache.hadoop.yarn.service.AbstractService: Service:NMLivelinessMonitor is started.
2013-08-06 12:42:55,722 INFO org.apache.hadoop.yarn.service.AbstractService: Service:org.apache.hadoop.yarn.server.resourcemanager.ResourceTrackerService is started.
2013-08-06 12:42:55,802 INFO org.apache.hadoop.ipc.Server: Starting Socket Reader #1 for port 54110
2013-08-06 12:42:55,847 INFO org.apache.hadoop.yarn.factories.impl.pb.RpcServerFactoryPBImpl: Adding protocol org.apache.hadoop.yarn.server.api.ResourceTrackerPB to the server
2013-08-06 12:42:55,848 INFO org.apache.hadoop.ipc.Server: IPC Server Responder: starting
2013-08-06 12:42:55,849 INFO org.apache.hadoop.ipc.Server: IPC Server listener on 54110: starting
2013-08-06 12:42:55,991 INFO org.apache.hadoop.ipc.Server: Starting Socket Reader #1 for port 54112
2013-08-06 12:42:56,010 INFO org.apache.hadoop.yarn.factories.impl.pb.RpcServerFactoryPBImpl: Adding protocol org.apache.hadoop.yarn.api.AMRMProtocolPB to the server
2013-08-06 12:42:56,012 INFO org.apache.hadoop.ipc.Server: IPC Server Responder: starting
2013-08-06 12:42:56,013 INFO org.apache.hadoop.ipc.Server: IPC Server listener on 54112: starting
2013-08-06 12:42:56,056 INFO org.apache.hadoop.yarn.service.AbstractService: Service:org.apache.hadoop.yarn.server.resourcemanager.ApplicationMasterService is started.
2013-08-06 12:42:56,111 INFO org.apache.hadoop.ipc.Server: Starting Socket Reader #1 for port 54111
2013-08-06 12:42:56,121 INFO org.apache.hadoop.yarn.factories.impl.pb.RpcServerFactoryPBImpl: Adding protocol org.apache.hadoop.yarn.api.ClientRMProtocolPB to the server
2013-08-06 12:42:56,122 INFO org.apache.hadoop.ipc.Server: IPC Server Responder: starting
2013-08-06 12:42:56,123 INFO org.apache.hadoop.ipc.Server: IPC Server listener on 54111: starting
2013-08-06 12:42:56,157 INFO org.apache.hadoop.yarn.service.AbstractService: Service:org.apache.hadoop.yarn.server.resourcemanager.ClientRMService is started.
2013-08-06 12:42:56,191 INFO org.apache.hadoop.ipc.Server: Starting Socket Reader #1 for port 8033
2013-08-06 12:42:56,199 INFO org.apache.hadoop.yarn.factories.impl.pb.RpcServerFactoryPBImpl: Adding protocol org.apache.hadoop.yarn.api.RMAdminProtocolPB to the server
2013-08-06 12:42:56,200 INFO org.apache.hadoop.ipc.Server: IPC Server Responder: starting
2013-08-06 12:42:56,201 INFO org.apache.hadoop.ipc.Server: IPC Server listener on 8033: starting
2013-08-06 12:42:56,203 INFO org.apache.hadoop.yarn.service.AbstractService: Service:org.apache.hadoop.yarn.server.resourcemanager.AdminService is started.
2013-08-06 12:42:56,203 INFO org.apache.hadoop.yarn.service.AbstractService: Service:org.apache.hadoop.yarn.server.resourcemanager.amlauncher.ApplicationMasterLauncher is started.
2013-08-06 12:42:56,205 INFO org.apache.hadoop.yarn.service.AbstractService: Service:ResourceManager is started.
2013-08-06 12:43:06,110 INFO org.apache.hadoop.yarn.util.RackResolver: Resolved hadoop-110-3 to /default-rack
2013-08-06 12:43:06,110 INFO org.apache.hadoop.yarn.util.RackResolver: Resolved hadoop-110-2 to /default-rack
2013-08-06 12:43:06,118 INFO org.apache.hadoop.yarn.util.RackResolver: Resolved hadoop-110-5 to /default-rack
2013-08-06 12:43:06,120 INFO org.apache.hadoop.yarn.server.resourcemanager.ResourceTrackerService: NodeManager from node hadoop-110-5(cmPort: 54830 httpPort: 8042) registered with capability: <memory:8192, vCores:16>, assigned nodeId hadoop-110-5:54830
2013-08-06 12:43:06,121 INFO org.apache.hadoop.yarn.util.RackResolver: Resolved hadoop-110-4 to /default-rack
2013-08-06 12:43:06,121 INFO org.apache.hadoop.yarn.server.resourcemanager.ResourceTrackerService: NodeManager from node hadoop-110-4(cmPort: 59955 httpPort: 8042) registered with capability: <memory:8192, vCores:16>, assigned nodeId hadoop-110-4:59955
2013-08-06 12:43:06,122 INFO org.apache.hadoop.yarn.server.resourcemanager.ResourceTrackerService: NodeManager from node hadoop-110-3(cmPort: 34727 httpPort: 8042) registered with capability: <memory:8192, vCores:16>, assigned nodeId hadoop-110-3:34727
2013-08-06 12:43:06,123 INFO org.apache.hadoop.yarn.server.resourcemanager.ResourceTrackerService: NodeManager from node hadoop-110-2(cmPort: 50749 httpPort: 8042) registered with capability: <memory:8192, vCores:16>, assigned nodeId hadoop-110-2:50749
2013-08-06 12:43:06,146 INFO org.apache.hadoop.yarn.server.resourcemanager.rmnode.RMNodeImpl: hadoop-110-2:50749 Node Transitioned from NEW to RUNNING
2013-08-06 12:43:06,147 INFO org.apache.hadoop.yarn.server.resourcemanager.rmnode.RMNodeImpl: hadoop-110-3:34727 Node Transitioned from NEW to RUNNING
2013-08-06 12:43:06,147 INFO org.apache.hadoop.yarn.server.resourcemanager.rmnode.RMNodeImpl: hadoop-110-5:54830 Node Transitioned from NEW to RUNNING
2013-08-06 12:43:06,147 INFO org.apache.hadoop.yarn.server.resourcemanager.rmnode.RMNodeImpl: hadoop-110-4:59955 Node Transitioned from NEW to RUNNING
2013-08-06 12:43:06,150 INFO org.apache.hadoop.yarn.server.resourcemanager.scheduler.capacity.CapacityScheduler: Added node hadoop-110-2:50749 clusterResource: <memory:8192, vCores:16>
2013-08-06 12:43:06,150 INFO org.apache.hadoop.yarn.server.resourcemanager.scheduler.capacity.CapacityScheduler: Added node hadoop-110-3:34727 clusterResource: <memory:16384, vCores:32>
2013-08-06 12:43:06,151 INFO org.apache.hadoop.yarn.server.resourcemanager.scheduler.capacity.CapacityScheduler: Added node hadoop-110-5:54830 clusterResource: <memory:24576, vCores:48>
2013-08-06 12:43:06,151 INFO org.apache.hadoop.yarn.server.resourcemanager.scheduler.capacity.CapacityScheduler: Added node hadoop-110-4:59955 clusterResource: <memory:32768, vCores:64>
2013-08-06 12:43:06,300 INFO org.apache.hadoop.yarn.util.RackResolver: Resolved hadoop-110-7 to /default-rack
2013-08-06 12:43:06,300 INFO org.apache.hadoop.yarn.server.resourcemanager.ResourceTrackerService: NodeManager from node hadoop-110-7(cmPort: 55372 httpPort: 8042) registered with capability: <memory:8192, vCores:16>, assigned nodeId hadoop-110-7:55372
2013-08-06 12:43:06,306 INFO org.apache.hadoop.yarn.server.resourcemanager.rmnode.RMNodeImpl: hadoop-110-7:55372 Node Transitioned from NEW to RUNNING
2013-08-06 12:43:06,306 INFO org.apache.hadoop.yarn.server.resourcemanager.scheduler.capacity.CapacityScheduler: Added node hadoop-110-7:55372 clusterResource: <memory:40960, vCores:80>
2013-08-06 12:43:10,676 INFO org.apache.hadoop.yarn.util.RackResolver: Resolved hadoop-110-6 to /default-rack
2013-08-06 12:43:10,677 INFO org.apache.hadoop.yarn.server.resourcemanager.ResourceTrackerService: NodeManager from node hadoop-110-6(cmPort: 50003 httpPort: 8042) registered with capability: <memory:8192, vCores:16>, assigned nodeId hadoop-110-6:50003
2013-08-06 12:43:10,678 INFO org.apache.hadoop.yarn.server.resourcemanager.rmnode.RMNodeImpl: hadoop-110-6:50003 Node Transitioned from NEW to RUNNING
2013-08-06 12:43:10,678 INFO org.apache.hadoop.yarn.server.resourcemanager.scheduler.capacity.CapacityScheduler: Added node hadoop-110-6:50003 clusterResource: <memory:49152, vCores:96>
2013-08-06 12:45:11,731 INFO org.apache.hadoop.yarn.server.resourcemanager.ClientRMService: Allocated new applicationId: 1
2013-08-06 12:45:14,947 INFO org.apache.hadoop.yarn.server.resourcemanager.ClientRMService: Storing Application with id application_1375792971633_0001
2013-08-06 12:45:14,950 INFO org.apache.hadoop.yarn.server.resourcemanager.recovery.RMStateStore: Storing info for app: application_1375792971633_0001
2013-08-06 12:45:14,951 INFO org.apache.hadoop.yarn.server.resourcemanager.ClientRMService: Application with id 1 submitted by user ubuntu
2013-08-06 12:45:14,954 INFO org.apache.hadoop.yarn.server.resourcemanager.RMAuditLogger: USER=ubuntu	IP=192.168.100.2	OPERATION=Submit Application Request	TARGET=ClientRMService	RESULT=SUCCESS	APPID=application_1375792971633_0001
2013-08-06 12:45:15,000 INFO org.apache.hadoop.yarn.server.resourcemanager.rmapp.RMAppImpl: application_1375792971633_0001 State change from NEW to SUBMITTED
2013-08-06 12:45:15,001 INFO org.apache.hadoop.yarn.server.resourcemanager.ApplicationMasterService: Registering appattempt_1375792971633_0001_000001
2013-08-06 12:45:15,003 INFO org.apache.hadoop.yarn.server.resourcemanager.rmapp.attempt.RMAppAttemptImpl: appattempt_1375792971633_0001_000001 State change from NEW to SUBMITTED
2013-08-06 12:45:15,035 INFO org.apache.hadoop.yarn.server.resourcemanager.scheduler.capacity.LeafQueue: Application application_1375792971633_0001 from user: ubuntu activated in queue: default
2013-08-06 12:45:15,036 INFO org.apache.hadoop.yarn.server.resourcemanager.scheduler.capacity.LeafQueue: Application added - appId: application_1375792971633_0001 user: org.apache.hadoop.yarn.server.resourcemanager.scheduler.capacity.LeafQueue$User@7606a33b, leaf-queue: default #user-pending-applications: 0 #user-active-applications: 1 #queue-pending-applications: 0 #queue-active-applications: 1
2013-08-06 12:45:15,036 INFO org.apache.hadoop.yarn.server.resourcemanager.scheduler.capacity.ParentQueue: Application added - appId: application_1375792971633_0001 user: ubuntu leaf-queue of parent: root #applications: 1
2013-08-06 12:45:15,036 INFO org.apache.hadoop.yarn.server.resourcemanager.scheduler.capacity.CapacityScheduler: Application Submission: appattempt_1375792971633_0001_000001, user: ubuntu queue: default: capacity=1.0, absoluteCapacity=1.0, usedResources=<memory:0, vCores:0>usedCapacity=0.0, absoluteUsedCapacity=0.0, numApps=1, numContainers=0, currently active: 1
2013-08-06 12:45:15,042 INFO org.apache.hadoop.yarn.server.resourcemanager.rmapp.attempt.RMAppAttemptImpl: appattempt_1375792971633_0001_000001 State change from SUBMITTED to SCHEDULED
2013-08-06 12:45:15,042 INFO org.apache.hadoop.yarn.server.resourcemanager.rmapp.RMAppImpl: application_1375792971633_0001 State change from SUBMITTED to ACCEPTED
2013-08-06 12:45:15,258 INFO org.apache.hadoop.yarn.server.resourcemanager.rmcontainer.RMContainerImpl: container_1375792971633_0001_01_000001 Container Transitioned from NEW to ALLOCATED
2013-08-06 12:45:15,258 INFO org.apache.hadoop.yarn.server.resourcemanager.RMAuditLogger: USER=ubuntu	OPERATION=AM Allocated Container	TARGET=SchedulerApp	RESULT=SUCCESS	APPID=application_1375792971633_0001	CONTAINERID=container_1375792971633_0001_01_000001
2013-08-06 12:45:15,259 INFO org.apache.hadoop.yarn.server.resourcemanager.scheduler.common.fica.FiCaSchedulerNode: Assigned container container_1375792971633_0001_01_000001 of capacity <memory:2048, vCores:1> on host hadoop-110-6:50003, which currently has 1 containers, <memory:2048, vCores:1> used and <memory:6144, vCores:15> available
2013-08-06 12:45:15,265 INFO org.apache.hadoop.yarn.server.resourcemanager.scheduler.capacity.LeafQueue: assignedContainer application=application_1375792971633_0001 container=Container: [ContainerId: container_1375792971633_0001_01_000001, NodeId: hadoop-110-6:50003, NodeHttpAddress: hadoop-110-6:8042, Resource: <memory:2048, vCores:1>, Priority: 0, State: NEW, Token: null, Status: container_id {, app_attempt_id {, application_id {, id: 1, cluster_timestamp: 1375792971633, }, attemptId: 1, }, id: 1, }, state: C_NEW, ] containerId=container_1375792971633_0001_01_000001 queue=default: capacity=1.0, absoluteCapacity=1.0, usedResources=<memory:0, vCores:0>usedCapacity=0.0, absoluteUsedCapacity=0.0, numApps=1, numContainers=0 usedCapacity=0.0 absoluteUsedCapacity=0.0 used=<memory:0, vCores:0> cluster=<memory:49152, vCores:96>
2013-08-06 12:45:15,265 INFO org.apache.hadoop.yarn.server.resourcemanager.scheduler.capacity.ParentQueue: Re-sorting queues since queue: root.default stats: default: capacity=1.0, absoluteCapacity=1.0, usedResources=<memory:2048, vCores:1>usedCapacity=0.041666668, absoluteUsedCapacity=0.041666668, numApps=1, numContainers=1
2013-08-06 12:45:15,266 INFO org.apache.hadoop.yarn.server.resourcemanager.scheduler.capacity.ParentQueue: assignedContainer queue=root usedCapacity=0.041666668 absoluteUsedCapacity=0.041666668 used=<memory:2048, vCores:1> cluster=<memory:49152, vCores:96>
2013-08-06 12:45:15,269 INFO org.apache.hadoop.yarn.server.resourcemanager.rmcontainer.RMContainerImpl: container_1375792971633_0001_01_000001 Container Transitioned from ALLOCATED to ACQUIRED
2013-08-06 12:45:15,272 INFO org.apache.hadoop.yarn.server.resourcemanager.rmapp.attempt.RMAppAttemptImpl: Storing attempt: AppId: application_1375792971633_0001 AttemptId: appattempt_1375792971633_0001_000001 MasterContainer: Container: [ContainerId: container_1375792971633_0001_01_000001, NodeId: hadoop-110-6:50003, NodeHttpAddress: hadoop-110-6:8042, Resource: <memory:2048, vCores:1>, Priority: 0, State: NEW, Token: null, Status: container_id {, app_attempt_id {, application_id {, id: 1, cluster_timestamp: 1375792971633, }, attemptId: 1, }, id: 1, }, state: C_NEW, ]
2013-08-06 12:45:15,277 INFO org.apache.hadoop.yarn.server.resourcemanager.rmapp.attempt.RMAppAttemptImpl: appattempt_1375792971633_0001_000001 State change from SCHEDULED to ALLOCATED_SAVING
2013-08-06 12:45:15,281 INFO org.apache.hadoop.yarn.server.resourcemanager.recovery.RMStateStore: Storing info for attempt: appattempt_1375792971633_0001_000001
2013-08-06 12:45:15,284 INFO org.apache.hadoop.yarn.server.resourcemanager.rmapp.attempt.RMAppAttemptImpl: appattempt_1375792971633_0001_000001 State change from ALLOCATED_SAVING to ALLOCATED
2013-08-06 12:45:15,291 INFO org.apache.hadoop.yarn.server.resourcemanager.amlauncher.AMLauncher: Launching masterappattempt_1375792971633_0001_000001
2013-08-06 12:45:15,331 INFO org.apache.hadoop.yarn.server.resourcemanager.amlauncher.AMLauncher: Setting up container Container: [ContainerId: container_1375792971633_0001_01_000001, NodeId: hadoop-110-6:50003, NodeHttpAddress: hadoop-110-6:8042, Resource: <memory:2048, vCores:1>, Priority: 0, State: NEW, Token: null, Status: container_id {, app_attempt_id {, application_id {, id: 1, cluster_timestamp: 1375792971633, }, attemptId: 1, }, id: 1, }, state: C_NEW, ] for AM appattempt_1375792971633_0001_000001
2013-08-06 12:45:15,332 INFO org.apache.hadoop.yarn.server.resourcemanager.amlauncher.AMLauncher: Command to launch container container_1375792971633_0001_01_000001 : $JAVA_HOME/bin/java -Dlog4j.configuration=container-log4j.properties -Dyarn.app.mapreduce.container.log.dir=<LOG_DIR> -Dyarn.app.mapreduce.container.log.filesize=0 -Dhadoop.root.logger=INFO,CLA  -Xmx1024m org.apache.hadoop.mapreduce.v2.app.MRAppMaster 1><LOG_DIR>/stdout 2><LOG_DIR>/stderr 
2013-08-06 12:45:16,268 INFO org.apache.hadoop.yarn.server.resourcemanager.rmcontainer.RMContainerImpl: container_1375792971633_0001_01_000001 Container Transitioned from ACQUIRED to RUNNING
2013-08-06 12:45:16,278 INFO org.apache.hadoop.yarn.server.resourcemanager.amlauncher.AMLauncher: Done launching container Container: [ContainerId: container_1375792971633_0001_01_000001, NodeId: hadoop-110-6:50003, NodeHttpAddress: hadoop-110-6:8042, Resource: <memory:2048, vCores:1>, Priority: 0, State: NEW, Token: null, Status: container_id {, app_attempt_id {, application_id {, id: 1, cluster_timestamp: 1375792971633, }, attemptId: 1, }, id: 1, }, state: C_NEW, ] for AM appattempt_1375792971633_0001_000001
2013-08-06 12:45:16,279 INFO org.apache.hadoop.yarn.server.resourcemanager.rmapp.attempt.RMAppAttemptImpl: appattempt_1375792971633_0001_000001 State change from ALLOCATED to LAUNCHED
2013-08-06 12:45:24,778 INFO org.apache.hadoop.yarn.server.resourcemanager.ApplicationMasterService: AM registration appattempt_1375792971633_0001_000001
2013-08-06 12:45:24,780 INFO org.apache.hadoop.yarn.server.resourcemanager.RMAuditLogger: USER=ubuntu	IP=192.168.100.11	OPERATION=Register App Master	TARGET=ApplicationMasterService	RESULT=SUCCESS	APPID=application_1375792971633_0001	APPATTEMPTID=appattempt_1375792971633_0001_000001
2013-08-06 12:45:24,783 INFO org.apache.hadoop.yarn.server.resourcemanager.rmapp.attempt.RMAppAttemptImpl: appattempt_1375792971633_0001_000001 State change from LAUNCHED to RUNNING
2013-08-06 12:45:24,783 INFO org.apache.hadoop.yarn.server.resourcemanager.rmapp.RMAppImpl: application_1375792971633_0001 State change from ACCEPTED to RUNNING
2013-08-06 12:45:25,909 INFO org.apache.hadoop.yarn.server.resourcemanager.rmcontainer.RMContainerImpl: container_1375792971633_0001_01_000002 Container Transitioned from NEW to ALLOCATED
2013-08-06 12:45:25,909 INFO org.apache.hadoop.yarn.server.resourcemanager.RMAuditLogger: USER=ubuntu	OPERATION=AM Allocated Container	TARGET=SchedulerApp	RESULT=SUCCESS	APPID=application_1375792971633_0001	CONTAINERID=container_1375792971633_0001_01_000002
2013-08-06 12:45:25,909 INFO org.apache.hadoop.yarn.server.resourcemanager.scheduler.common.fica.FiCaSchedulerNode: Assigned container container_1375792971633_0001_01_000002 of capacity <memory:1024, vCores:1> on host hadoop-110-7:55372, which currently has 1 containers, <memory:1024, vCores:1> used and <memory:7168, vCores:15> available
2013-08-06 12:45:25,911 INFO org.apache.hadoop.yarn.server.resourcemanager.scheduler.capacity.LeafQueue: assignedContainer application=application_1375792971633_0001 container=Container: [ContainerId: container_1375792971633_0001_01_000002, NodeId: hadoop-110-7:55372, NodeHttpAddress: hadoop-110-7:8042, Resource: <memory:1024, vCores:1>, Priority: 20, State: NEW, Token: null, Status: container_id {, app_attempt_id {, application_id {, id: 1, cluster_timestamp: 1375792971633, }, attemptId: 1, }, id: 2, }, state: C_NEW, ] containerId=container_1375792971633_0001_01_000002 queue=default: capacity=1.0, absoluteCapacity=1.0, usedResources=<memory:2048, vCores:1>usedCapacity=0.041666668, absoluteUsedCapacity=0.041666668, numApps=1, numContainers=1 usedCapacity=0.041666668 absoluteUsedCapacity=0.041666668 used=<memory:2048, vCores:1> cluster=<memory:49152, vCores:96>
2013-08-06 12:45:25,911 INFO org.apache.hadoop.yarn.server.resourcemanager.scheduler.capacity.ParentQueue: Re-sorting queues since queue: root.default stats: default: capacity=1.0, absoluteCapacity=1.0, usedResources=<memory:3072, vCores:2>usedCapacity=0.0625, absoluteUsedCapacity=0.0625, numApps=1, numContainers=2
2013-08-06 12:45:25,911 INFO org.apache.hadoop.yarn.server.resourcemanager.scheduler.capacity.ParentQueue: assignedContainer queue=root usedCapacity=0.0625 absoluteUsedCapacity=0.0625 used=<memory:3072, vCores:2> cluster=<memory:49152, vCores:96>
2013-08-06 12:45:26,323 INFO org.apache.hadoop.yarn.server.resourcemanager.rmcontainer.RMContainerImpl: container_1375792971633_0001_01_000003 Container Transitioned from NEW to ALLOCATED
2013-08-06 12:45:26,323 INFO org.apache.hadoop.yarn.server.resourcemanager.RMAuditLogger: USER=ubuntu	OPERATION=AM Allocated Container	TARGET=SchedulerApp	RESULT=SUCCESS	APPID=application_1375792971633_0001	CONTAINERID=container_1375792971633_0001_01_000003
2013-08-06 12:45:26,323 INFO org.apache.hadoop.yarn.server.resourcemanager.scheduler.common.fica.FiCaSchedulerNode: Assigned container container_1375792971633_0001_01_000003 of capacity <memory:1024, vCores:1> on host hadoop-110-6:50003, which currently has 2 containers, <memory:3072, vCores:2> used and <memory:5120, vCores:14> available
2013-08-06 12:45:26,325 INFO org.apache.hadoop.yarn.server.resourcemanager.scheduler.capacity.LeafQueue: assignedContainer application=application_1375792971633_0001 container=Container: [ContainerId: container_1375792971633_0001_01_000003, NodeId: hadoop-110-6:50003, NodeHttpAddress: hadoop-110-6:8042, Resource: <memory:1024, vCores:1>, Priority: 20, State: NEW, Token: null, Status: container_id {, app_attempt_id {, application_id {, id: 1, cluster_timestamp: 1375792971633, }, attemptId: 1, }, id: 3, }, state: C_NEW, ] containerId=container_1375792971633_0001_01_000003 queue=default: capacity=1.0, absoluteCapacity=1.0, usedResources=<memory:3072, vCores:2>usedCapacity=0.0625, absoluteUsedCapacity=0.0625, numApps=1, numContainers=2 usedCapacity=0.0625 absoluteUsedCapacity=0.0625 used=<memory:3072, vCores:2> cluster=<memory:49152, vCores:96>
2013-08-06 12:45:26,325 INFO org.apache.hadoop.yarn.server.resourcemanager.scheduler.capacity.ParentQueue: Re-sorting queues since queue: root.default stats: default: capacity=1.0, absoluteCapacity=1.0, usedResources=<memory:4096, vCores:3>usedCapacity=0.083333336, absoluteUsedCapacity=0.083333336, numApps=1, numContainers=3
2013-08-06 12:45:26,326 INFO org.apache.hadoop.yarn.server.resourcemanager.scheduler.capacity.ParentQueue: assignedContainer queue=root usedCapacity=0.083333336 absoluteUsedCapacity=0.083333336 used=<memory:4096, vCores:3> cluster=<memory:49152, vCores:96>
2013-08-06 12:45:26,886 INFO org.apache.hadoop.yarn.server.resourcemanager.rmcontainer.RMContainerImpl: container_1375792971633_0001_01_000002 Container Transitioned from ALLOCATED to ACQUIRED
2013-08-06 12:45:26,888 INFO org.apache.hadoop.yarn.server.resourcemanager.rmcontainer.RMContainerImpl: container_1375792971633_0001_01_000003 Container Transitioned from ALLOCATED to ACQUIRED
2013-08-06 12:45:27,332 INFO org.apache.hadoop.yarn.server.resourcemanager.rmcontainer.RMContainerImpl: container_1375792971633_0001_01_000003 Container Transitioned from ACQUIRED to RUNNING
2013-08-06 12:45:27,921 INFO org.apache.hadoop.yarn.server.resourcemanager.scheduler.AppSchedulingInfo: checking for deactivate... 
2013-08-06 12:45:28,988 INFO org.apache.hadoop.yarn.server.resourcemanager.rmcontainer.RMContainerImpl: container_1375792971633_0001_01_000002 Container Transitioned from ACQUIRED to RUNNING
2013-08-06 12:47:27,850 INFO org.apache.hadoop.yarn.server.resourcemanager.rmcontainer.RMContainerImpl: container_1375792971633_0001_01_000002 Container Transitioned from RUNNING to COMPLETED
2013-08-06 12:47:27,851 INFO org.apache.hadoop.yarn.server.resourcemanager.scheduler.common.fica.FiCaSchedulerApp: Completed container: container_1375792971633_0001_01_000002 in state: COMPLETED event:FINISHED
2013-08-06 12:47:27,858 INFO org.apache.hadoop.yarn.server.resourcemanager.RMAuditLogger: USER=ubuntu	OPERATION=AM Released Container	TARGET=SchedulerApp	RESULT=SUCCESS	APPID=application_1375792971633_0001	CONTAINERID=container_1375792971633_0001_01_000002
2013-08-06 12:47:27,858 INFO org.apache.hadoop.yarn.server.resourcemanager.scheduler.common.fica.FiCaSchedulerNode: Released container container_1375792971633_0001_01_000002 of capacity <memory:1024, vCores:1> on host hadoop-110-7:55372, which currently has 0 containers, <memory:0, vCores:0> used and <memory:8192, vCores:16> available, release resources=true
2013-08-06 12:47:27,859 INFO org.apache.hadoop.yarn.server.resourcemanager.scheduler.capacity.LeafQueue: default used=<memory:3072, vCores:2> numContainers=2 user=ubuntu user-resources=<memory:3072, vCores:2>
2013-08-06 12:47:27,861 INFO org.apache.hadoop.yarn.server.resourcemanager.scheduler.capacity.LeafQueue: completedContainer container=Container: [ContainerId: container_1375792971633_0001_01_000002, NodeId: hadoop-110-7:55372, NodeHttpAddress: hadoop-110-7:8042, Resource: <memory:1024, vCores:1>, Priority: 20, State: NEW, Token: null, Status: container_id {, app_attempt_id {, application_id {, id: 1, cluster_timestamp: 1375792971633, }, attemptId: 1, }, id: 2, }, state: C_COMPLETE, diagnostics: "Container killed by the ApplicationMaster.\n\n", exit_status: 143, ] resource=<memory:1024, vCores:1> queue=default: capacity=1.0, absoluteCapacity=1.0, usedResources=<memory:3072, vCores:2>usedCapacity=0.0625, absoluteUsedCapacity=0.0625, numApps=1, numContainers=2 usedCapacity=0.0625 absoluteUsedCapacity=0.0625 used=<memory:3072, vCores:2> cluster=<memory:49152, vCores:96>
2013-08-06 12:47:27,861 INFO org.apache.hadoop.yarn.server.resourcemanager.scheduler.capacity.ParentQueue: completedContainer queue=root usedCapacity=0.0625 absoluteUsedCapacity=0.0625 used=<memory:3072, vCores:2> cluster=<memory:49152, vCores:96>
2013-08-06 12:47:27,862 INFO org.apache.hadoop.yarn.server.resourcemanager.scheduler.capacity.CapacityScheduler: Application appattempt_1375792971633_0001_000001 released container container_1375792971633_0001_01_000002 on node: host: hadoop-110-7:55372 #containers=0 available=8192 used=0 with event: FINISHED
2013-08-06 12:47:31,742 INFO org.apache.hadoop.yarn.server.resourcemanager.rmcontainer.RMContainerImpl: container_1375792971633_0001_01_000003 Container Transitioned from RUNNING to COMPLETED
2013-08-06 12:47:31,742 INFO org.apache.hadoop.yarn.server.resourcemanager.scheduler.common.fica.FiCaSchedulerApp: Completed container: container_1375792971633_0001_01_000003 in state: COMPLETED event:FINISHED
2013-08-06 12:47:31,742 INFO org.apache.hadoop.yarn.server.resourcemanager.RMAuditLogger: USER=ubuntu	OPERATION=AM Released Container	TARGET=SchedulerApp	RESULT=SUCCESS	APPID=application_1375792971633_0001	CONTAINERID=container_1375792971633_0001_01_000003
2013-08-06 12:47:31,742 INFO org.apache.hadoop.yarn.server.resourcemanager.scheduler.common.fica.FiCaSchedulerNode: Released container container_1375792971633_0001_01_000003 of capacity <memory:1024, vCores:1> on host hadoop-110-6:50003, which currently has 1 containers, <memory:2048, vCores:1> used and <memory:6144, vCores:15> available, release resources=true
2013-08-06 12:47:31,743 INFO org.apache.hadoop.yarn.server.resourcemanager.scheduler.capacity.LeafQueue: default used=<memory:2048, vCores:1> numContainers=1 user=ubuntu user-resources=<memory:2048, vCores:1>
2013-08-06 12:47:31,745 INFO org.apache.hadoop.yarn.server.resourcemanager.scheduler.capacity.LeafQueue: completedContainer container=Container: [ContainerId: container_1375792971633_0001_01_000003, NodeId: hadoop-110-6:50003, NodeHttpAddress: hadoop-110-6:8042, Resource: <memory:1024, vCores:1>, Priority: 20, State: NEW, Token: null, Status: container_id {, app_attempt_id {, application_id {, id: 1, cluster_timestamp: 1375792971633, }, attemptId: 1, }, id: 3, }, state: C_COMPLETE, diagnostics: "Container killed by the ApplicationMaster.\n\n", exit_status: 143, ] resource=<memory:1024, vCores:1> queue=default: capacity=1.0, absoluteCapacity=1.0, usedResources=<memory:2048, vCores:1>usedCapacity=0.041666668, absoluteUsedCapacity=0.041666668, numApps=1, numContainers=1 usedCapacity=0.041666668 absoluteUsedCapacity=0.041666668 used=<memory:2048, vCores:1> cluster=<memory:49152, vCores:96>
2013-08-06 12:47:31,745 INFO org.apache.hadoop.yarn.server.resourcemanager.scheduler.capacity.ParentQueue: completedContainer queue=root usedCapacity=0.041666668 absoluteUsedCapacity=0.041666668 used=<memory:2048, vCores:1> cluster=<memory:49152, vCores:96>
2013-08-06 12:47:31,745 INFO org.apache.hadoop.yarn.server.resourcemanager.scheduler.capacity.CapacityScheduler: Application appattempt_1375792971633_0001_000001 released container container_1375792971633_0001_01_000003 on node: host: hadoop-110-6:50003 #containers=1 available=6144 used=2048 with event: FINISHED
2013-08-06 12:47:35,909 INFO org.apache.hadoop.yarn.server.resourcemanager.rmapp.attempt.RMAppAttemptImpl: appattempt_1375792971633_0001_000001 State change from RUNNING to FINISHING
2013-08-06 12:47:35,910 INFO org.apache.hadoop.yarn.server.resourcemanager.rmapp.RMAppImpl: application_1375792971633_0001 State change from RUNNING to FINISHING
2013-08-06 12:47:36,751 INFO org.apache.hadoop.yarn.server.resourcemanager.ClientRMService: Allocated new applicationId: 2
2013-08-06 12:47:36,780 INFO org.apache.hadoop.yarn.server.resourcemanager.rmcontainer.RMContainerImpl: container_1375792971633_0001_01_000001 Container Transitioned from RUNNING to COMPLETED
2013-08-06 12:47:36,780 INFO org.apache.hadoop.yarn.server.resourcemanager.scheduler.common.fica.FiCaSchedulerApp: Completed container: container_1375792971633_0001_01_000001 in state: COMPLETED event:FINISHED
2013-08-06 12:47:36,780 INFO org.apache.hadoop.yarn.server.resourcemanager.RMAuditLogger: USER=ubuntu	OPERATION=AM Released Container	TARGET=SchedulerApp	RESULT=SUCCESS	APPID=application_1375792971633_0001	CONTAINERID=container_1375792971633_0001_01_000001
2013-08-06 12:47:36,781 INFO org.apache.hadoop.yarn.server.resourcemanager.scheduler.common.fica.FiCaSchedulerNode: Released container container_1375792971633_0001_01_000001 of capacity <memory:2048, vCores:1> on host hadoop-110-6:50003, which currently has 0 containers, <memory:0, vCores:0> used and <memory:8192, vCores:16> available, release resources=true
2013-08-06 12:47:36,781 INFO org.apache.hadoop.yarn.server.resourcemanager.scheduler.capacity.LeafQueue: default used=<memory:0, vCores:0> numContainers=0 user=ubuntu user-resources=<memory:0, vCores:0>
2013-08-06 12:47:36,783 INFO org.apache.hadoop.yarn.server.resourcemanager.scheduler.capacity.LeafQueue: completedContainer container=Container: [ContainerId: container_1375792971633_0001_01_000001, NodeId: hadoop-110-6:50003, NodeHttpAddress: hadoop-110-6:8042, Resource: <memory:2048, vCores:1>, Priority: 0, State: NEW, Token: null, Status: container_id {, app_attempt_id {, application_id {, id: 1, cluster_timestamp: 1375792971633, }, attemptId: 1, }, id: 1, }, state: C_COMPLETE, diagnostics: "", exit_status: 0, ] resource=<memory:2048, vCores:1> queue=default: capacity=1.0, absoluteCapacity=1.0, usedResources=<memory:0, vCores:0>usedCapacity=0.0, absoluteUsedCapacity=0.0, numApps=1, numContainers=0 usedCapacity=0.0 absoluteUsedCapacity=0.0 used=<memory:0, vCores:0> cluster=<memory:49152, vCores:96>
2013-08-06 12:47:36,783 INFO org.apache.hadoop.yarn.server.resourcemanager.scheduler.capacity.ParentQueue: completedContainer queue=root usedCapacity=0.0 absoluteUsedCapacity=0.0 used=<memory:0, vCores:0> cluster=<memory:49152, vCores:96>
2013-08-06 12:47:36,783 INFO org.apache.hadoop.yarn.server.resourcemanager.rmapp.attempt.RMAppAttemptImpl: appattempt_1375792971633_0001_000001 State change from FINISHING to FINISHED
2013-08-06 12:47:36,783 INFO org.apache.hadoop.yarn.server.resourcemanager.scheduler.capacity.CapacityScheduler: Application appattempt_1375792971633_0001_000001 released container container_1375792971633_0001_01_000001 on node: host: hadoop-110-6:50003 #containers=0 available=8192 used=0 with event: FINISHED
2013-08-06 12:47:36,786 INFO org.apache.hadoop.yarn.server.resourcemanager.rmapp.RMAppImpl: application_1375792971633_0001 State change from FINISHING to FINISHED
2013-08-06 12:47:36,786 INFO org.apache.hadoop.yarn.server.resourcemanager.scheduler.capacity.CapacityScheduler: Application appattempt_1375792971633_0001_000001 is done. finalState=FINISHED
2013-08-06 12:47:36,786 INFO org.apache.hadoop.yarn.server.resourcemanager.RMAuditLogger: USER=ubuntu	OPERATION=Application Finished - Succeeded	TARGET=RMAppManager	RESULT=SUCCESS	APPID=application_1375792971633_0001
2013-08-06 12:47:36,787 INFO org.apache.hadoop.yarn.server.resourcemanager.amlauncher.AMLauncher: Cleaning master appattempt_1375792971633_0001_000001
2013-08-06 12:47:36,800 INFO org.apache.hadoop.yarn.server.resourcemanager.recovery.RMStateStore: Removing info for app: application_1375792971633_0001
2013-08-06 12:47:36,788 INFO org.apache.hadoop.yarn.server.resourcemanager.scheduler.AppSchedulingInfo: Application application_1375792971633_0001 requests cleared
2013-08-06 12:47:36,800 INFO org.apache.hadoop.yarn.server.resourcemanager.scheduler.capacity.LeafQueue: Application removed - appId: application_1375792971633_0001 user: ubuntu queue: default #user-pending-applications: 0 #user-active-applications: 0 #queue-pending-applications: 0 #queue-active-applications: 0
2013-08-06 12:47:36,800 INFO org.apache.hadoop.yarn.server.resourcemanager.scheduler.capacity.ParentQueue: Application removed - appId: application_1375792971633_0001 user: ubuntu leaf-queue of parent: root #applications: 0
2013-08-06 12:47:36,808 INFO org.apache.hadoop.yarn.server.resourcemanager.RMAppManager$ApplicationSummary: appId=application_1375792971633_0001,name=TeraGen,user=ubuntu,queue=default,state=FINISHED,trackingUrl=hadoop-110-1.novalocal:8088/proxy/application_1375792971633_0001/jobhistory/job/job_1375792971633_0001,appMasterHost=hadoop-110-6,startTime=1375793114940,finishTime=1375793255910
2013-08-06 12:47:38,702 INFO org.apache.hadoop.yarn.server.resourcemanager.ClientRMService: Storing Application with id application_1375792971633_0002
2013-08-06 12:47:38,702 INFO org.apache.hadoop.yarn.server.resourcemanager.recovery.RMStateStore: Storing info for app: application_1375792971633_0002
2013-08-06 12:47:38,703 INFO org.apache.hadoop.yarn.server.resourcemanager.ClientRMService: Application with id 2 submitted by user ubuntu
2013-08-06 12:47:38,703 INFO org.apache.hadoop.yarn.server.resourcemanager.rmapp.RMAppImpl: application_1375792971633_0002 State change from NEW to SUBMITTED
2013-08-06 12:47:38,703 INFO org.apache.hadoop.yarn.server.resourcemanager.RMAuditLogger: USER=ubuntu	IP=192.168.100.2	OPERATION=Submit Application Request	TARGET=ClientRMService	RESULT=SUCCESS	APPID=application_1375792971633_0002
2013-08-06 12:47:38,703 INFO org.apache.hadoop.yarn.server.resourcemanager.ApplicationMasterService: Registering appattempt_1375792971633_0002_000001
2013-08-06 12:47:38,704 INFO org.apache.hadoop.yarn.server.resourcemanager.rmapp.attempt.RMAppAttemptImpl: appattempt_1375792971633_0002_000001 State change from NEW to SUBMITTED
2013-08-06 12:47:38,707 INFO org.apache.hadoop.yarn.server.resourcemanager.scheduler.capacity.LeafQueue: Application application_1375792971633_0002 from user: ubuntu activated in queue: default
2013-08-06 12:47:38,707 INFO org.apache.hadoop.yarn.server.resourcemanager.scheduler.capacity.LeafQueue: Application added - appId: application_1375792971633_0002 user: org.apache.hadoop.yarn.server.resourcemanager.scheduler.capacity.LeafQueue$User@2ca258c2, leaf-queue: default #user-pending-applications: 0 #user-active-applications: 1 #queue-pending-applications: 0 #queue-active-applications: 1
2013-08-06 12:47:38,707 INFO org.apache.hadoop.yarn.server.resourcemanager.scheduler.capacity.ParentQueue: Application added - appId: application_1375792971633_0002 user: ubuntu leaf-queue of parent: root #applications: 1
2013-08-06 12:47:38,708 INFO org.apache.hadoop.yarn.server.resourcemanager.scheduler.capacity.CapacityScheduler: Application Submission: appattempt_1375792971633_0002_000001, user: ubuntu queue: default: capacity=1.0, absoluteCapacity=1.0, usedResources=<memory:0, vCores:0>usedCapacity=0.0, absoluteUsedCapacity=0.0, numApps=1, numContainers=0, currently active: 1
2013-08-06 12:47:38,708 INFO org.apache.hadoop.yarn.server.resourcemanager.rmapp.attempt.RMAppAttemptImpl: appattempt_1375792971633_0002_000001 State change from SUBMITTED to SCHEDULED
2013-08-06 12:47:38,708 INFO org.apache.hadoop.yarn.server.resourcemanager.rmapp.RMAppImpl: application_1375792971633_0002 State change from SUBMITTED to ACCEPTED
2013-08-06 12:47:38,791 INFO org.apache.hadoop.yarn.server.resourcemanager.rmcontainer.RMContainerImpl: container_1375792971633_0002_01_000001 Container Transitioned from NEW to ALLOCATED
2013-08-06 12:47:38,791 INFO org.apache.hadoop.yarn.server.resourcemanager.RMAuditLogger: USER=ubuntu	OPERATION=AM Allocated Container	TARGET=SchedulerApp	RESULT=SUCCESS	APPID=application_1375792971633_0002	CONTAINERID=container_1375792971633_0002_01_000001
2013-08-06 12:47:38,791 INFO org.apache.hadoop.yarn.server.resourcemanager.scheduler.common.fica.FiCaSchedulerNode: Assigned container container_1375792971633_0002_01_000001 of capacity <memory:2048, vCores:1> on host hadoop-110-6:50003, which currently has 1 containers, <memory:2048, vCores:1> used and <memory:6144, vCores:15> available
2013-08-06 12:47:38,793 INFO org.apache.hadoop.yarn.server.resourcemanager.scheduler.capacity.LeafQueue: assignedContainer application=application_1375792971633_0002 container=Container: [ContainerId: container_1375792971633_0002_01_000001, NodeId: hadoop-110-6:50003, NodeHttpAddress: hadoop-110-6:8042, Resource: <memory:2048, vCores:1>, Priority: 0, State: NEW, Token: null, Status: container_id {, app_attempt_id {, application_id {, id: 2, cluster_timestamp: 1375792971633, }, attemptId: 1, }, id: 1, }, state: C_NEW, ] containerId=container_1375792971633_0002_01_000001 queue=default: capacity=1.0, absoluteCapacity=1.0, usedResources=<memory:0, vCores:0>usedCapacity=0.0, absoluteUsedCapacity=0.0, numApps=1, numContainers=0 usedCapacity=0.0 absoluteUsedCapacity=0.0 used=<memory:0, vCores:0> cluster=<memory:49152, vCores:96>
2013-08-06 12:47:38,793 INFO org.apache.hadoop.yarn.server.resourcemanager.scheduler.capacity.ParentQueue: Re-sorting queues since queue: root.default stats: default: capacity=1.0, absoluteCapacity=1.0, usedResources=<memory:2048, vCores:1>usedCapacity=0.041666668, absoluteUsedCapacity=0.041666668, numApps=1, numContainers=1
2013-08-06 12:47:38,793 INFO org.apache.hadoop.yarn.server.resourcemanager.scheduler.capacity.ParentQueue: assignedContainer queue=root usedCapacity=0.041666668 absoluteUsedCapacity=0.041666668 used=<memory:2048, vCores:1> cluster=<memory:49152, vCores:96>
2013-08-06 12:47:38,795 INFO org.apache.hadoop.yarn.server.resourcemanager.rmcontainer.RMContainerImpl: container_1375792971633_0002_01_000001 Container Transitioned from ALLOCATED to ACQUIRED
2013-08-06 12:47:38,798 INFO org.apache.hadoop.yarn.server.resourcemanager.rmapp.attempt.RMAppAttemptImpl: Storing attempt: AppId: application_1375792971633_0002 AttemptId: appattempt_1375792971633_0002_000001 MasterContainer: Container: [ContainerId: container_1375792971633_0002_01_000001, NodeId: hadoop-110-6:50003, NodeHttpAddress: hadoop-110-6:8042, Resource: <memory:2048, vCores:1>, Priority: 0, State: NEW, Token: null, Status: container_id {, app_attempt_id {, application_id {, id: 2, cluster_timestamp: 1375792971633, }, attemptId: 1, }, id: 1, }, state: C_NEW, ]
2013-08-06 12:47:38,798 INFO org.apache.hadoop.yarn.server.resourcemanager.rmapp.attempt.RMAppAttemptImpl: appattempt_1375792971633_0002_000001 State change from SCHEDULED to ALLOCATED_SAVING
2013-08-06 12:47:38,798 INFO org.apache.hadoop.yarn.server.resourcemanager.recovery.RMStateStore: Storing info for attempt: appattempt_1375792971633_0002_000001
2013-08-06 12:47:38,799 INFO org.apache.hadoop.yarn.server.resourcemanager.rmapp.attempt.RMAppAttemptImpl: appattempt_1375792971633_0002_000001 State change from ALLOCATED_SAVING to ALLOCATED
2013-08-06 12:47:38,801 INFO org.apache.hadoop.yarn.server.resourcemanager.amlauncher.AMLauncher: Launching masterappattempt_1375792971633_0002_000001
2013-08-06 12:47:38,809 INFO org.apache.hadoop.yarn.server.resourcemanager.amlauncher.AMLauncher: Setting up container Container: [ContainerId: container_1375792971633_0002_01_000001, NodeId: hadoop-110-6:50003, NodeHttpAddress: hadoop-110-6:8042, Resource: <memory:2048, vCores:1>, Priority: 0, State: NEW, Token: null, Status: container_id {, app_attempt_id {, application_id {, id: 2, cluster_timestamp: 1375792971633, }, attemptId: 1, }, id: 1, }, state: C_NEW, ] for AM appattempt_1375792971633_0002_000001
2013-08-06 12:47:38,809 INFO org.apache.hadoop.yarn.server.resourcemanager.amlauncher.AMLauncher: Command to launch container container_1375792971633_0002_01_000001 : $JAVA_HOME/bin/java -Dlog4j.configuration=container-log4j.properties -Dyarn.app.mapreduce.container.log.dir=<LOG_DIR> -Dyarn.app.mapreduce.container.log.filesize=0 -Dhadoop.root.logger=INFO,CLA  -Xmx1024m org.apache.hadoop.mapreduce.v2.app.MRAppMaster 1><LOG_DIR>/stdout 2><LOG_DIR>/stderr 
2013-08-06 12:47:38,829 INFO org.apache.hadoop.yarn.server.resourcemanager.amlauncher.AMLauncher: Done launching container Container: [ContainerId: container_1375792971633_0002_01_000001, NodeId: hadoop-110-6:50003, NodeHttpAddress: hadoop-110-6:8042, Resource: <memory:2048, vCores:1>, Priority: 0, State: NEW, Token: null, Status: container_id {, app_attempt_id {, application_id {, id: 2, cluster_timestamp: 1375792971633, }, attemptId: 1, }, id: 1, }, state: C_NEW, ] for AM appattempt_1375792971633_0002_000001
2013-08-06 12:47:38,829 INFO org.apache.hadoop.yarn.server.resourcemanager.rmapp.attempt.RMAppAttemptImpl: appattempt_1375792971633_0002_000001 State change from ALLOCATED to LAUNCHED
2013-08-06 12:47:39,797 INFO org.apache.hadoop.yarn.server.resourcemanager.rmcontainer.RMContainerImpl: container_1375792971633_0002_01_000001 Container Transitioned from ACQUIRED to RUNNING
2013-08-06 12:47:46,190 INFO org.apache.hadoop.yarn.server.resourcemanager.ApplicationMasterService: AM registration appattempt_1375792971633_0002_000001
2013-08-06 12:47:46,190 INFO org.apache.hadoop.yarn.server.resourcemanager.RMAuditLogger: USER=ubuntu	IP=192.168.100.11	OPERATION=Register App Master	TARGET=ApplicationMasterService	RESULT=SUCCESS	APPID=application_1375792971633_0002	APPATTEMPTID=appattempt_1375792971633_0002_000001
2013-08-06 12:47:46,193 INFO org.apache.hadoop.yarn.server.resourcemanager.rmapp.attempt.RMAppAttemptImpl: appattempt_1375792971633_0002_000001 State change from LAUNCHED to RUNNING
2013-08-06 12:47:46,193 INFO org.apache.hadoop.yarn.server.resourcemanager.rmapp.RMAppImpl: application_1375792971633_0002 State change from ACCEPTED to RUNNING
2013-08-06 12:47:47,340 INFO org.apache.hadoop.yarn.server.resourcemanager.rmcontainer.RMContainerImpl: container_1375792971633_0002_01_000002 Container Transitioned from NEW to ALLOCATED
2013-08-06 12:47:47,340 INFO org.apache.hadoop.yarn.server.resourcemanager.RMAuditLogger: USER=ubuntu	OPERATION=AM Allocated Container	TARGET=SchedulerApp	RESULT=SUCCESS	APPID=application_1375792971633_0002	CONTAINERID=container_1375792971633_0002_01_000002
2013-08-06 12:47:47,340 INFO org.apache.hadoop.yarn.server.resourcemanager.scheduler.common.fica.FiCaSchedulerNode: Assigned container container_1375792971633_0002_01_000002 of capacity <memory:1024, vCores:1> on host hadoop-110-3:34727, which currently has 1 containers, <memory:1024, vCores:1> used and <memory:7168, vCores:15> available
2013-08-06 12:47:47,342 INFO org.apache.hadoop.yarn.server.resourcemanager.scheduler.capacity.LeafQueue: assignedContainer application=application_1375792971633_0002 container=Container: [ContainerId: container_1375792971633_0002_01_000002, NodeId: hadoop-110-3:34727, NodeHttpAddress: hadoop-110-3:8042, Resource: <memory:1024, vCores:1>, Priority: 20, State: NEW, Token: null, Status: container_id {, app_attempt_id {, application_id {, id: 2, cluster_timestamp: 1375792971633, }, attemptId: 1, }, id: 2, }, state: C_NEW, ] containerId=container_1375792971633_0002_01_000002 queue=default: capacity=1.0, absoluteCapacity=1.0, usedResources=<memory:2048, vCores:1>usedCapacity=0.041666668, absoluteUsedCapacity=0.041666668, numApps=1, numContainers=1 usedCapacity=0.041666668 absoluteUsedCapacity=0.041666668 used=<memory:2048, vCores:1> cluster=<memory:49152, vCores:96>
2013-08-06 12:47:47,342 INFO org.apache.hadoop.yarn.server.resourcemanager.scheduler.capacity.ParentQueue: Re-sorting queues since queue: root.default stats: default: capacity=1.0, absoluteCapacity=1.0, usedResources=<memory:3072, vCores:2>usedCapacity=0.0625, absoluteUsedCapacity=0.0625, numApps=1, numContainers=2
2013-08-06 12:47:47,343 INFO org.apache.hadoop.yarn.server.resourcemanager.scheduler.capacity.ParentQueue: assignedContainer queue=root usedCapacity=0.0625 absoluteUsedCapacity=0.0625 used=<memory:3072, vCores:2> cluster=<memory:49152, vCores:96>
2013-08-06 12:47:47,343 INFO org.apache.hadoop.yarn.server.resourcemanager.rmcontainer.RMContainerImpl: container_1375792971633_0002_01_000003 Container Transitioned from NEW to ALLOCATED
2013-08-06 12:47:47,344 INFO org.apache.hadoop.yarn.server.resourcemanager.RMAuditLogger: USER=ubuntu	OPERATION=AM Allocated Container	TARGET=SchedulerApp	RESULT=SUCCESS	APPID=application_1375792971633_0002	CONTAINERID=container_1375792971633_0002_01_000003
2013-08-06 12:47:47,344 INFO org.apache.hadoop.yarn.server.resourcemanager.scheduler.common.fica.FiCaSchedulerNode: Assigned container container_1375792971633_0002_01_000003 of capacity <memory:1024, vCores:1> on host hadoop-110-2:50749, which currently has 1 containers, <memory:1024, vCores:1> used and <memory:7168, vCores:15> available
2013-08-06 12:47:47,345 INFO org.apache.hadoop.yarn.server.resourcemanager.scheduler.capacity.LeafQueue: assignedContainer application=application_1375792971633_0002 container=Container: [ContainerId: container_1375792971633_0002_01_000003, NodeId: hadoop-110-2:50749, NodeHttpAddress: hadoop-110-2:8042, Resource: <memory:1024, vCores:1>, Priority: 20, State: NEW, Token: null, Status: container_id {, app_attempt_id {, application_id {, id: 2, cluster_timestamp: 1375792971633, }, attemptId: 1, }, id: 3, }, state: C_NEW, ] containerId=container_1375792971633_0002_01_000003 queue=default: capacity=1.0, absoluteCapacity=1.0, usedResources=<memory:3072, vCores:2>usedCapacity=0.0625, absoluteUsedCapacity=0.0625, numApps=1, numContainers=2 usedCapacity=0.0625 absoluteUsedCapacity=0.0625 used=<memory:3072, vCores:2> cluster=<memory:49152, vCores:96>
2013-08-06 12:47:47,346 INFO org.apache.hadoop.yarn.server.resourcemanager.scheduler.capacity.ParentQueue: Re-sorting queues since queue: root.default stats: default: capacity=1.0, absoluteCapacity=1.0, usedResources=<memory:4096, vCores:3>usedCapacity=0.083333336, absoluteUsedCapacity=0.083333336, numApps=1, numContainers=3
2013-08-06 12:47:47,346 INFO org.apache.hadoop.yarn.server.resourcemanager.scheduler.capacity.ParentQueue: assignedContainer queue=root usedCapacity=0.083333336 absoluteUsedCapacity=0.083333336 used=<memory:4096, vCores:3> cluster=<memory:49152, vCores:96>
2013-08-06 12:47:48,262 INFO org.apache.hadoop.yarn.server.resourcemanager.rmcontainer.RMContainerImpl: container_1375792971633_0002_01_000002 Container Transitioned from ALLOCATED to ACQUIRED
2013-08-06 12:47:48,265 INFO org.apache.hadoop.yarn.server.resourcemanager.rmcontainer.RMContainerImpl: container_1375792971633_0002_01_000003 Container Transitioned from ALLOCATED to ACQUIRED
2013-08-06 12:47:49,295 INFO org.apache.hadoop.yarn.server.resourcemanager.scheduler.AppSchedulingInfo: checking for deactivate... 
2013-08-06 12:47:50,384 INFO org.apache.hadoop.yarn.server.resourcemanager.rmcontainer.RMContainerImpl: container_1375792971633_0002_01_000003 Container Transitioned from ACQUIRED to RUNNING
2013-08-06 12:47:50,388 INFO org.apache.hadoop.yarn.server.resourcemanager.rmcontainer.RMContainerImpl: container_1375792971633_0002_01_000002 Container Transitioned from ACQUIRED to RUNNING
2013-08-06 12:49:40,922 INFO org.apache.hadoop.yarn.server.resourcemanager.rmcontainer.RMContainerImpl: container_1375792971633_0002_01_000002 Container Transitioned from RUNNING to COMPLETED
2013-08-06 12:49:40,922 INFO org.apache.hadoop.yarn.server.resourcemanager.scheduler.common.fica.FiCaSchedulerApp: Completed container: container_1375792971633_0002_01_000002 in state: COMPLETED event:FINISHED
2013-08-06 12:49:40,922 INFO org.apache.hadoop.yarn.server.resourcemanager.RMAuditLogger: USER=ubuntu	OPERATION=AM Released Container	TARGET=SchedulerApp	RESULT=SUCCESS	APPID=application_1375792971633_0002	CONTAINERID=container_1375792971633_0002_01_000002
2013-08-06 12:49:40,923 INFO org.apache.hadoop.yarn.server.resourcemanager.scheduler.common.fica.FiCaSchedulerNode: Released container container_1375792971633_0002_01_000002 of capacity <memory:1024, vCores:1> on host hadoop-110-3:34727, which currently has 0 containers, <memory:0, vCores:0> used and <memory:8192, vCores:16> available, release resources=true
2013-08-06 12:49:40,923 INFO org.apache.hadoop.yarn.server.resourcemanager.scheduler.capacity.LeafQueue: default used=<memory:3072, vCores:2> numContainers=2 user=ubuntu user-resources=<memory:3072, vCores:2>
2013-08-06 12:49:40,937 INFO org.apache.hadoop.yarn.server.resourcemanager.scheduler.capacity.LeafQueue: completedContainer container=Container: [ContainerId: container_1375792971633_0002_01_000002, NodeId: hadoop-110-3:34727, NodeHttpAddress: hadoop-110-3:8042, Resource: <memory:1024, vCores:1>, Priority: 20, State: NEW, Token: null, Status: container_id {, app_attempt_id {, application_id {, id: 2, cluster_timestamp: 1375792971633, }, attemptId: 1, }, id: 2, }, state: C_COMPLETE, diagnostics: "Container killed by the ApplicationMaster.\n\n", exit_status: 143, ] resource=<memory:1024, vCores:1> queue=default: capacity=1.0, absoluteCapacity=1.0, usedResources=<memory:3072, vCores:2>usedCapacity=0.0625, absoluteUsedCapacity=0.0625, numApps=1, numContainers=2 usedCapacity=0.0625 absoluteUsedCapacity=0.0625 used=<memory:3072, vCores:2> cluster=<memory:49152, vCores:96>
2013-08-06 12:49:40,937 INFO org.apache.hadoop.yarn.server.resourcemanager.scheduler.capacity.ParentQueue: completedContainer queue=root usedCapacity=0.0625 absoluteUsedCapacity=0.0625 used=<memory:3072, vCores:2> cluster=<memory:49152, vCores:96>
2013-08-06 12:49:40,937 INFO org.apache.hadoop.yarn.server.resourcemanager.scheduler.capacity.CapacityScheduler: Application appattempt_1375792971633_0002_000001 released container container_1375792971633_0002_01_000002 on node: host: hadoop-110-3:34727 #containers=0 available=8192 used=0 with event: FINISHED
2013-08-06 12:49:41,485 INFO org.apache.hadoop.yarn.server.resourcemanager.rmcontainer.RMContainerImpl: container_1375792971633_0002_01_000003 Container Transitioned from RUNNING to COMPLETED
2013-08-06 12:49:41,485 INFO org.apache.hadoop.yarn.server.resourcemanager.scheduler.common.fica.FiCaSchedulerApp: Completed container: container_1375792971633_0002_01_000003 in state: COMPLETED event:FINISHED
2013-08-06 12:49:41,485 INFO org.apache.hadoop.yarn.server.resourcemanager.RMAuditLogger: USER=ubuntu	OPERATION=AM Released Container	TARGET=SchedulerApp	RESULT=SUCCESS	APPID=application_1375792971633_0002	CONTAINERID=container_1375792971633_0002_01_000003
2013-08-06 12:49:41,485 INFO org.apache.hadoop.yarn.server.resourcemanager.scheduler.common.fica.FiCaSchedulerNode: Released container container_1375792971633_0002_01_000003 of capacity <memory:1024, vCores:1> on host hadoop-110-2:50749, which currently has 0 containers, <memory:0, vCores:0> used and <memory:8192, vCores:16> available, release resources=true
2013-08-06 12:49:41,486 INFO org.apache.hadoop.yarn.server.resourcemanager.scheduler.capacity.LeafQueue: default used=<memory:2048, vCores:1> numContainers=1 user=ubuntu user-resources=<memory:2048, vCores:1>
2013-08-06 12:49:41,488 INFO org.apache.hadoop.yarn.server.resourcemanager.scheduler.capacity.LeafQueue: completedContainer container=Container: [ContainerId: container_1375792971633_0002_01_000003, NodeId: hadoop-110-2:50749, NodeHttpAddress: hadoop-110-2:8042, Resource: <memory:1024, vCores:1>, Priority: 20, State: NEW, Token: null, Status: container_id {, app_attempt_id {, application_id {, id: 2, cluster_timestamp: 1375792971633, }, attemptId: 1, }, id: 3, }, state: C_COMPLETE, diagnostics: "Container killed by the ApplicationMaster.\n\n", exit_status: 143, ] resource=<memory:1024, vCores:1> queue=default: capacity=1.0, absoluteCapacity=1.0, usedResources=<memory:2048, vCores:1>usedCapacity=0.041666668, absoluteUsedCapacity=0.041666668, numApps=1, numContainers=1 usedCapacity=0.041666668 absoluteUsedCapacity=0.041666668 used=<memory:2048, vCores:1> cluster=<memory:49152, vCores:96>
2013-08-06 12:49:41,488 INFO org.apache.hadoop.yarn.server.resourcemanager.scheduler.capacity.ParentQueue: completedContainer queue=root usedCapacity=0.041666668 absoluteUsedCapacity=0.041666668 used=<memory:2048, vCores:1> cluster=<memory:49152, vCores:96>
2013-08-06 12:49:41,488 INFO org.apache.hadoop.yarn.server.resourcemanager.scheduler.capacity.CapacityScheduler: Application appattempt_1375792971633_0002_000001 released container container_1375792971633_0002_01_000003 on node: host: hadoop-110-2:50749 #containers=0 available=8192 used=0 with event: FINISHED
2013-08-06 12:49:45,631 INFO org.apache.hadoop.yarn.server.resourcemanager.rmapp.attempt.RMAppAttemptImpl: appattempt_1375792971633_0002_000001 State change from RUNNING to FINISHING
2013-08-06 12:49:45,631 INFO org.apache.hadoop.yarn.server.resourcemanager.rmapp.RMAppImpl: application_1375792971633_0002 State change from RUNNING to FINISHING
2013-08-06 12:49:46,460 INFO org.apache.hadoop.yarn.server.resourcemanager.rmcontainer.RMContainerImpl: container_1375792971633_0002_01_000001 Container Transitioned from RUNNING to COMPLETED
2013-08-06 12:49:46,461 INFO org.apache.hadoop.yarn.server.resourcemanager.scheduler.common.fica.FiCaSchedulerApp: Completed container: container_1375792971633_0002_01_000001 in state: COMPLETED event:FINISHED
2013-08-06 12:49:46,461 INFO org.apache.hadoop.yarn.server.resourcemanager.rmapp.attempt.RMAppAttemptImpl: appattempt_1375792971633_0002_000001 State change from FINISHING to FINISHED
2013-08-06 12:49:46,461 INFO org.apache.hadoop.yarn.server.resourcemanager.RMAuditLogger: USER=ubuntu	OPERATION=AM Released Container	TARGET=SchedulerApp	RESULT=SUCCESS	APPID=application_1375792971633_0002	CONTAINERID=container_1375792971633_0002_01_000001
2013-08-06 12:49:46,461 INFO org.apache.hadoop.yarn.server.resourcemanager.scheduler.common.fica.FiCaSchedulerNode: Released container container_1375792971633_0002_01_000001 of capacity <memory:2048, vCores:1> on host hadoop-110-6:50003, which currently has 0 containers, <memory:0, vCores:0> used and <memory:8192, vCores:16> available, release resources=true
2013-08-06 12:49:46,461 INFO org.apache.hadoop.yarn.server.resourcemanager.rmapp.RMAppImpl: application_1375792971633_0002 State change from FINISHING to FINISHED
2013-08-06 12:49:46,461 INFO org.apache.hadoop.yarn.server.resourcemanager.scheduler.capacity.LeafQueue: default used=<memory:0, vCores:0> numContainers=0 user=ubuntu user-resources=<memory:0, vCores:0>
2013-08-06 12:49:46,462 INFO org.apache.hadoop.yarn.server.resourcemanager.RMAuditLogger: USER=ubuntu	OPERATION=Application Finished - Succeeded	TARGET=RMAppManager	RESULT=SUCCESS	APPID=application_1375792971633_0002
2013-08-06 12:49:46,462 INFO org.apache.hadoop.yarn.server.resourcemanager.amlauncher.AMLauncher: Cleaning master appattempt_1375792971633_0002_000001
2013-08-06 12:49:46,462 INFO org.apache.hadoop.yarn.server.resourcemanager.recovery.RMStateStore: Removing info for app: application_1375792971633_0002
2013-08-06 12:49:46,463 INFO org.apache.hadoop.yarn.server.resourcemanager.RMAppManager$ApplicationSummary: appId=application_1375792971633_0002,name=TeraGen,user=ubuntu,queue=default,state=FINISHED,trackingUrl=hadoop-110-1.novalocal:8088/proxy/application_1375792971633_0002/jobhistory/job/job_1375792971633_0002,appMasterHost=hadoop-110-6,startTime=1375793258701,finishTime=1375793385631
2013-08-06 12:49:46,463 INFO org.apache.hadoop.yarn.server.resourcemanager.scheduler.capacity.LeafQueue: completedContainer container=Container: [ContainerId: container_1375792971633_0002_01_000001, NodeId: hadoop-110-6:50003, NodeHttpAddress: hadoop-110-6:8042, Resource: <memory:2048, vCores:1>, Priority: 0, State: NEW, Token: null, Status: container_id {, app_attempt_id {, application_id {, id: 2, cluster_timestamp: 1375792971633, }, attemptId: 1, }, id: 1, }, state: C_COMPLETE, diagnostics: "", exit_status: 0, ] resource=<memory:2048, vCores:1> queue=default: capacity=1.0, absoluteCapacity=1.0, usedResources=<memory:0, vCores:0>usedCapacity=0.0, absoluteUsedCapacity=0.0, numApps=1, numContainers=0 usedCapacity=0.0 absoluteUsedCapacity=0.0 used=<memory:0, vCores:0> cluster=<memory:49152, vCores:96>
2013-08-06 12:49:46,463 INFO org.apache.hadoop.yarn.server.resourcemanager.scheduler.capacity.ParentQueue: completedContainer queue=root usedCapacity=0.0 absoluteUsedCapacity=0.0 used=<memory:0, vCores:0> cluster=<memory:49152, vCores:96>
2013-08-06 12:49:46,463 INFO org.apache.hadoop.yarn.server.resourcemanager.scheduler.capacity.CapacityScheduler: Application appattempt_1375792971633_0002_000001 released container container_1375792971633_0002_01_000001 on node: host: hadoop-110-6:50003 #containers=0 available=8192 used=0 with event: FINISHED
2013-08-06 12:49:46,464 INFO org.apache.hadoop.yarn.server.resourcemanager.scheduler.capacity.CapacityScheduler: Application appattempt_1375792971633_0002_000001 is done. finalState=FINISHED
2013-08-06 12:49:46,464 INFO org.apache.hadoop.yarn.server.resourcemanager.scheduler.AppSchedulingInfo: Application application_1375792971633_0002 requests cleared
2013-08-06 12:49:46,464 INFO org.apache.hadoop.yarn.server.resourcemanager.scheduler.capacity.LeafQueue: Application removed - appId: application_1375792971633_0002 user: ubuntu queue: default #user-pending-applications: 0 #user-active-applications: 0 #queue-pending-applications: 0 #queue-active-applications: 0
2013-08-06 12:49:46,464 INFO org.apache.hadoop.yarn.server.resourcemanager.scheduler.capacity.ParentQueue: Application removed - appId: application_1375792971633_0002 user: ubuntu leaf-queue of parent: root #applications: 0
2013-08-06 12:49:46,598 INFO org.apache.hadoop.yarn.server.resourcemanager.ClientRMService: Allocated new applicationId: 3
2013-08-06 12:49:48,480 INFO org.apache.hadoop.yarn.server.resourcemanager.ClientRMService: Storing Application with id application_1375792971633_0003
2013-08-06 12:49:48,480 INFO org.apache.hadoop.yarn.server.resourcemanager.recovery.RMStateStore: Storing info for app: application_1375792971633_0003
2013-08-06 12:49:48,480 INFO org.apache.hadoop.yarn.server.resourcemanager.ClientRMService: Application with id 3 submitted by user ubuntu
2013-08-06 12:49:48,480 INFO org.apache.hadoop.yarn.server.resourcemanager.RMAuditLogger: USER=ubuntu	IP=192.168.100.2	OPERATION=Submit Application Request	TARGET=ClientRMService	RESULT=SUCCESS	APPID=application_1375792971633_0003
2013-08-06 12:49:48,482 INFO org.apache.hadoop.yarn.server.resourcemanager.rmapp.RMAppImpl: application_1375792971633_0003 State change from NEW to SUBMITTED
2013-08-06 12:49:48,483 INFO org.apache.hadoop.yarn.server.resourcemanager.ApplicationMasterService: Registering appattempt_1375792971633_0003_000001
2013-08-06 12:49:48,483 INFO org.apache.hadoop.yarn.server.resourcemanager.rmapp.attempt.RMAppAttemptImpl: appattempt_1375792971633_0003_000001 State change from NEW to SUBMITTED
2013-08-06 12:49:48,483 INFO org.apache.hadoop.yarn.server.resourcemanager.scheduler.capacity.LeafQueue: Application application_1375792971633_0003 from user: ubuntu activated in queue: default
2013-08-06 12:49:48,484 INFO org.apache.hadoop.yarn.server.resourcemanager.scheduler.capacity.LeafQueue: Application added - appId: application_1375792971633_0003 user: org.apache.hadoop.yarn.server.resourcemanager.scheduler.capacity.LeafQueue$User@8667df7, leaf-queue: default #user-pending-applications: 0 #user-active-applications: 1 #queue-pending-applications: 0 #queue-active-applications: 1
2013-08-06 12:49:48,484 INFO org.apache.hadoop.yarn.server.resourcemanager.scheduler.capacity.ParentQueue: Application added - appId: application_1375792971633_0003 user: ubuntu leaf-queue of parent: root #applications: 1
2013-08-06 12:49:48,484 INFO org.apache.hadoop.yarn.server.resourcemanager.scheduler.capacity.CapacityScheduler: Application Submission: appattempt_1375792971633_0003_000001, user: ubuntu queue: default: capacity=1.0, absoluteCapacity=1.0, usedResources=<memory:0, vCores:0>usedCapacity=0.0, absoluteUsedCapacity=0.0, numApps=1, numContainers=0, currently active: 1
2013-08-06 12:49:48,484 INFO org.apache.hadoop.yarn.server.resourcemanager.rmapp.attempt.RMAppAttemptImpl: appattempt_1375792971633_0003_000001 State change from SUBMITTED to SCHEDULED
2013-08-06 12:49:48,485 INFO org.apache.hadoop.yarn.server.resourcemanager.rmapp.RMAppImpl: application_1375792971633_0003 State change from SUBMITTED to ACCEPTED
2013-08-06 12:49:48,511 INFO org.apache.hadoop.yarn.server.resourcemanager.rmcontainer.RMContainerImpl: container_1375792971633_0003_01_000001 Container Transitioned from NEW to ALLOCATED
2013-08-06 12:49:48,511 INFO org.apache.hadoop.yarn.server.resourcemanager.RMAuditLogger: USER=ubuntu	OPERATION=AM Allocated Container	TARGET=SchedulerApp	RESULT=SUCCESS	APPID=application_1375792971633_0003	CONTAINERID=container_1375792971633_0003_01_000001
2013-08-06 12:49:48,511 INFO org.apache.hadoop.yarn.server.resourcemanager.scheduler.common.fica.FiCaSchedulerNode: Assigned container container_1375792971633_0003_01_000001 of capacity <memory:2048, vCores:1> on host hadoop-110-2:50749, which currently has 1 containers, <memory:2048, vCores:1> used and <memory:6144, vCores:15> available
2013-08-06 12:49:48,513 INFO org.apache.hadoop.yarn.server.resourcemanager.scheduler.capacity.LeafQueue: assignedContainer application=application_1375792971633_0003 container=Container: [ContainerId: container_1375792971633_0003_01_000001, NodeId: hadoop-110-2:50749, NodeHttpAddress: hadoop-110-2:8042, Resource: <memory:2048, vCores:1>, Priority: 0, State: NEW, Token: null, Status: container_id {, app_attempt_id {, application_id {, id: 3, cluster_timestamp: 1375792971633, }, attemptId: 1, }, id: 1, }, state: C_NEW, ] containerId=container_1375792971633_0003_01_000001 queue=default: capacity=1.0, absoluteCapacity=1.0, usedResources=<memory:0, vCores:0>usedCapacity=0.0, absoluteUsedCapacity=0.0, numApps=1, numContainers=0 usedCapacity=0.0 absoluteUsedCapacity=0.0 used=<memory:0, vCores:0> cluster=<memory:49152, vCores:96>
2013-08-06 12:49:48,513 INFO org.apache.hadoop.yarn.server.resourcemanager.scheduler.capacity.ParentQueue: Re-sorting queues since queue: root.default stats: default: capacity=1.0, absoluteCapacity=1.0, usedResources=<memory:2048, vCores:1>usedCapacity=0.041666668, absoluteUsedCapacity=0.041666668, numApps=1, numContainers=1
2013-08-06 12:49:48,513 INFO org.apache.hadoop.yarn.server.resourcemanager.scheduler.capacity.ParentQueue: assignedContainer queue=root usedCapacity=0.041666668 absoluteUsedCapacity=0.041666668 used=<memory:2048, vCores:1> cluster=<memory:49152, vCores:96>
2013-08-06 12:49:48,515 INFO org.apache.hadoop.yarn.server.resourcemanager.rmcontainer.RMContainerImpl: container_1375792971633_0003_01_000001 Container Transitioned from ALLOCATED to ACQUIRED
2013-08-06 12:49:48,517 INFO org.apache.hadoop.yarn.server.resourcemanager.rmapp.attempt.RMAppAttemptImpl: Storing attempt: AppId: application_1375792971633_0003 AttemptId: appattempt_1375792971633_0003_000001 MasterContainer: Container: [ContainerId: container_1375792971633_0003_01_000001, NodeId: hadoop-110-2:50749, NodeHttpAddress: hadoop-110-2:8042, Resource: <memory:2048, vCores:1>, Priority: 0, State: NEW, Token: null, Status: container_id {, app_attempt_id {, application_id {, id: 3, cluster_timestamp: 1375792971633, }, attemptId: 1, }, id: 1, }, state: C_NEW, ]
2013-08-06 12:49:48,517 INFO org.apache.hadoop.yarn.server.resourcemanager.recovery.RMStateStore: Storing info for attempt: appattempt_1375792971633_0003_000001
2013-08-06 12:49:48,517 INFO org.apache.hadoop.yarn.server.resourcemanager.rmapp.attempt.RMAppAttemptImpl: appattempt_1375792971633_0003_000001 State change from SCHEDULED to ALLOCATED_SAVING
2013-08-06 12:49:48,518 INFO org.apache.hadoop.yarn.server.resourcemanager.rmapp.attempt.RMAppAttemptImpl: appattempt_1375792971633_0003_000001 State change from ALLOCATED_SAVING to ALLOCATED
2013-08-06 12:49:48,520 INFO org.apache.hadoop.yarn.server.resourcemanager.amlauncher.AMLauncher: Launching masterappattempt_1375792971633_0003_000001
2013-08-06 12:49:48,523 INFO org.apache.hadoop.yarn.server.resourcemanager.amlauncher.AMLauncher: Setting up container Container: [ContainerId: container_1375792971633_0003_01_000001, NodeId: hadoop-110-2:50749, NodeHttpAddress: hadoop-110-2:8042, Resource: <memory:2048, vCores:1>, Priority: 0, State: NEW, Token: null, Status: container_id {, app_attempt_id {, application_id {, id: 3, cluster_timestamp: 1375792971633, }, attemptId: 1, }, id: 1, }, state: C_NEW, ] for AM appattempt_1375792971633_0003_000001
2013-08-06 12:49:48,523 INFO org.apache.hadoop.yarn.server.resourcemanager.amlauncher.AMLauncher: Command to launch container container_1375792971633_0003_01_000001 : $JAVA_HOME/bin/java -Dlog4j.configuration=container-log4j.properties -Dyarn.app.mapreduce.container.log.dir=<LOG_DIR> -Dyarn.app.mapreduce.container.log.filesize=0 -Dhadoop.root.logger=INFO,CLA  -Xmx1024m org.apache.hadoop.mapreduce.v2.app.MRAppMaster 1><LOG_DIR>/stdout 2><LOG_DIR>/stderr 
2013-08-06 12:49:48,538 INFO org.apache.hadoop.yarn.server.resourcemanager.amlauncher.AMLauncher: Done launching container Container: [ContainerId: container_1375792971633_0003_01_000001, NodeId: hadoop-110-2:50749, NodeHttpAddress: hadoop-110-2:8042, Resource: <memory:2048, vCores:1>, Priority: 0, State: NEW, Token: null, Status: container_id {, app_attempt_id {, application_id {, id: 3, cluster_timestamp: 1375792971633, }, attemptId: 1, }, id: 1, }, state: C_NEW, ] for AM appattempt_1375792971633_0003_000001
2013-08-06 12:49:48,538 INFO org.apache.hadoop.yarn.server.resourcemanager.rmapp.attempt.RMAppAttemptImpl: appattempt_1375792971633_0003_000001 State change from ALLOCATED to LAUNCHED
2013-08-06 12:49:49,518 INFO org.apache.hadoop.yarn.server.resourcemanager.rmcontainer.RMContainerImpl: container_1375792971633_0003_01_000001 Container Transitioned from ACQUIRED to RUNNING
2013-08-06 12:49:55,966 INFO org.apache.hadoop.yarn.server.resourcemanager.ApplicationMasterService: AM registration appattempt_1375792971633_0003_000001
2013-08-06 12:49:55,966 INFO org.apache.hadoop.yarn.server.resourcemanager.RMAuditLogger: USER=ubuntu	IP=192.168.100.3	OPERATION=Register App Master	TARGET=ApplicationMasterService	RESULT=SUCCESS	APPID=application_1375792971633_0003	APPATTEMPTID=appattempt_1375792971633_0003_000001
2013-08-06 12:49:55,967 INFO org.apache.hadoop.yarn.server.resourcemanager.rmapp.attempt.RMAppAttemptImpl: appattempt_1375792971633_0003_000001 State change from LAUNCHED to RUNNING
2013-08-06 12:49:55,968 INFO org.apache.hadoop.yarn.server.resourcemanager.rmapp.RMAppImpl: application_1375792971633_0003 State change from ACCEPTED to RUNNING
2013-08-06 12:49:57,411 INFO org.apache.hadoop.yarn.server.resourcemanager.rmcontainer.RMContainerImpl: container_1375792971633_0003_01_000002 Container Transitioned from NEW to ALLOCATED
2013-08-06 12:49:57,411 INFO org.apache.hadoop.yarn.server.resourcemanager.RMAuditLogger: USER=ubuntu	OPERATION=AM Allocated Container	TARGET=SchedulerApp	RESULT=SUCCESS	APPID=application_1375792971633_0003	CONTAINERID=container_1375792971633_0003_01_000002
2013-08-06 12:49:57,411 INFO org.apache.hadoop.yarn.server.resourcemanager.scheduler.common.fica.FiCaSchedulerNode: Assigned container container_1375792971633_0003_01_000002 of capacity <memory:1024, vCores:1> on host hadoop-110-7:55372, which currently has 1 containers, <memory:1024, vCores:1> used and <memory:7168, vCores:15> available
2013-08-06 12:49:57,413 INFO org.apache.hadoop.yarn.server.resourcemanager.scheduler.capacity.LeafQueue: assignedContainer application=application_1375792971633_0003 container=Container: [ContainerId: container_1375792971633_0003_01_000002, NodeId: hadoop-110-7:55372, NodeHttpAddress: hadoop-110-7:8042, Resource: <memory:1024, vCores:1>, Priority: 20, State: NEW, Token: null, Status: container_id {, app_attempt_id {, application_id {, id: 3, cluster_timestamp: 1375792971633, }, attemptId: 1, }, id: 2, }, state: C_NEW, ] containerId=container_1375792971633_0003_01_000002 queue=default: capacity=1.0, absoluteCapacity=1.0, usedResources=<memory:2048, vCores:1>usedCapacity=0.041666668, absoluteUsedCapacity=0.041666668, numApps=1, numContainers=1 usedCapacity=0.041666668 absoluteUsedCapacity=0.041666668 used=<memory:2048, vCores:1> cluster=<memory:49152, vCores:96>
2013-08-06 12:49:57,413 INFO org.apache.hadoop.yarn.server.resourcemanager.scheduler.capacity.ParentQueue: Re-sorting queues since queue: root.default stats: default: capacity=1.0, absoluteCapacity=1.0, usedResources=<memory:3072, vCores:2>usedCapacity=0.0625, absoluteUsedCapacity=0.0625, numApps=1, numContainers=2
2013-08-06 12:49:57,413 INFO org.apache.hadoop.yarn.server.resourcemanager.scheduler.capacity.ParentQueue: assignedContainer queue=root usedCapacity=0.0625 absoluteUsedCapacity=0.0625 used=<memory:3072, vCores:2> cluster=<memory:49152, vCores:96>
2013-08-06 12:49:57,495 INFO org.apache.hadoop.yarn.server.resourcemanager.rmcontainer.RMContainerImpl: container_1375792971633_0003_01_000003 Container Transitioned from NEW to ALLOCATED
2013-08-06 12:49:57,496 INFO org.apache.hadoop.yarn.server.resourcemanager.RMAuditLogger: USER=ubuntu	OPERATION=AM Allocated Container	TARGET=SchedulerApp	RESULT=SUCCESS	APPID=application_1375792971633_0003	CONTAINERID=container_1375792971633_0003_01_000003
2013-08-06 12:49:57,496 INFO org.apache.hadoop.yarn.server.resourcemanager.scheduler.common.fica.FiCaSchedulerNode: Assigned container container_1375792971633_0003_01_000003 of capacity <memory:1024, vCores:1> on host hadoop-110-6:50003, which currently has 1 containers, <memory:1024, vCores:1> used and <memory:7168, vCores:15> available
2013-08-06 12:49:57,498 INFO org.apache.hadoop.yarn.server.resourcemanager.scheduler.capacity.LeafQueue: assignedContainer application=application_1375792971633_0003 container=Container: [ContainerId: container_1375792971633_0003_01_000003, NodeId: hadoop-110-6:50003, NodeHttpAddress: hadoop-110-6:8042, Resource: <memory:1024, vCores:1>, Priority: 20, State: NEW, Token: null, Status: container_id {, app_attempt_id {, application_id {, id: 3, cluster_timestamp: 1375792971633, }, attemptId: 1, }, id: 3, }, state: C_NEW, ] containerId=container_1375792971633_0003_01_000003 queue=default: capacity=1.0, absoluteCapacity=1.0, usedResources=<memory:3072, vCores:2>usedCapacity=0.0625, absoluteUsedCapacity=0.0625, numApps=1, numContainers=2 usedCapacity=0.0625 absoluteUsedCapacity=0.0625 used=<memory:3072, vCores:2> cluster=<memory:49152, vCores:96>
2013-08-06 12:49:57,498 INFO org.apache.hadoop.yarn.server.resourcemanager.scheduler.capacity.ParentQueue: Re-sorting queues since queue: root.default stats: default: capacity=1.0, absoluteCapacity=1.0, usedResources=<memory:4096, vCores:3>usedCapacity=0.083333336, absoluteUsedCapacity=0.083333336, numApps=1, numContainers=3
2013-08-06 12:49:57,498 INFO org.apache.hadoop.yarn.server.resourcemanager.scheduler.capacity.ParentQueue: assignedContainer queue=root usedCapacity=0.083333336 absoluteUsedCapacity=0.083333336 used=<memory:4096, vCores:3> cluster=<memory:49152, vCores:96>
2013-08-06 12:49:58,051 INFO org.apache.hadoop.yarn.server.resourcemanager.rmcontainer.RMContainerImpl: container_1375792971633_0003_01_000002 Container Transitioned from ALLOCATED to ACQUIRED
2013-08-06 12:49:58,053 INFO org.apache.hadoop.yarn.server.resourcemanager.rmcontainer.RMContainerImpl: container_1375792971633_0003_01_000003 Container Transitioned from ALLOCATED to ACQUIRED
2013-08-06 12:49:58,417 INFO org.apache.hadoop.yarn.server.resourcemanager.rmcontainer.RMContainerImpl: container_1375792971633_0003_01_000002 Container Transitioned from ACQUIRED to RUNNING
2013-08-06 12:49:58,501 INFO org.apache.hadoop.yarn.server.resourcemanager.rmcontainer.RMContainerImpl: container_1375792971633_0003_01_000003 Container Transitioned from ACQUIRED to RUNNING
2013-08-06 12:49:59,084 INFO org.apache.hadoop.yarn.server.resourcemanager.scheduler.AppSchedulingInfo: checking for deactivate... 
2013-08-06 12:52:02,117 INFO org.apache.hadoop.yarn.server.resourcemanager.rmcontainer.RMContainerImpl: container_1375792971633_0003_01_000002 Container Transitioned from RUNNING to COMPLETED
2013-08-06 12:52:02,117 INFO org.apache.hadoop.yarn.server.resourcemanager.scheduler.common.fica.FiCaSchedulerApp: Completed container: container_1375792971633_0003_01_000002 in state: COMPLETED event:FINISHED
2013-08-06 12:52:02,117 INFO org.apache.hadoop.yarn.server.resourcemanager.RMAuditLogger: USER=ubuntu	OPERATION=AM Released Container	TARGET=SchedulerApp	RESULT=SUCCESS	APPID=application_1375792971633_0003	CONTAINERID=container_1375792971633_0003_01_000002
2013-08-06 12:52:02,117 INFO org.apache.hadoop.yarn.server.resourcemanager.scheduler.common.fica.FiCaSchedulerNode: Released container container_1375792971633_0003_01_000002 of capacity <memory:1024, vCores:1> on host hadoop-110-7:55372, which currently has 0 containers, <memory:0, vCores:0> used and <memory:8192, vCores:16> available, release resources=true
2013-08-06 12:52:02,118 INFO org.apache.hadoop.yarn.server.resourcemanager.scheduler.capacity.LeafQueue: default used=<memory:3072, vCores:2> numContainers=2 user=ubuntu user-resources=<memory:3072, vCores:2>
2013-08-06 12:52:02,123 INFO org.apache.hadoop.yarn.server.resourcemanager.scheduler.capacity.LeafQueue: completedContainer container=Container: [ContainerId: container_1375792971633_0003_01_000002, NodeId: hadoop-110-7:55372, NodeHttpAddress: hadoop-110-7:8042, Resource: <memory:1024, vCores:1>, Priority: 20, State: NEW, Token: null, Status: container_id {, app_attempt_id {, application_id {, id: 3, cluster_timestamp: 1375792971633, }, attemptId: 1, }, id: 2, }, state: C_COMPLETE, diagnostics: "Container killed by the ApplicationMaster.\n", exit_status: 0, ] resource=<memory:1024, vCores:1> queue=default: capacity=1.0, absoluteCapacity=1.0, usedResources=<memory:3072, vCores:2>usedCapacity=0.0625, absoluteUsedCapacity=0.0625, numApps=1, numContainers=2 usedCapacity=0.0625 absoluteUsedCapacity=0.0625 used=<memory:3072, vCores:2> cluster=<memory:49152, vCores:96>
2013-08-06 12:52:02,124 INFO org.apache.hadoop.yarn.server.resourcemanager.scheduler.capacity.ParentQueue: completedContainer queue=root usedCapacity=0.0625 absoluteUsedCapacity=0.0625 used=<memory:3072, vCores:2> cluster=<memory:49152, vCores:96>
2013-08-06 12:52:02,124 INFO org.apache.hadoop.yarn.server.resourcemanager.scheduler.capacity.CapacityScheduler: Application appattempt_1375792971633_0003_000001 released container container_1375792971633_0003_01_000002 on node: host: hadoop-110-7:55372 #containers=0 available=8192 used=0 with event: FINISHED
2013-08-06 12:52:02,776 INFO org.apache.hadoop.yarn.server.resourcemanager.rmcontainer.RMContainerImpl: container_1375792971633_0003_01_000003 Container Transitioned from RUNNING to COMPLETED
2013-08-06 12:52:02,776 INFO org.apache.hadoop.yarn.server.resourcemanager.scheduler.common.fica.FiCaSchedulerApp: Completed container: container_1375792971633_0003_01_000003 in state: COMPLETED event:FINISHED
2013-08-06 12:52:02,776 INFO org.apache.hadoop.yarn.server.resourcemanager.RMAuditLogger: USER=ubuntu	OPERATION=AM Released Container	TARGET=SchedulerApp	RESULT=SUCCESS	APPID=application_1375792971633_0003	CONTAINERID=container_1375792971633_0003_01_000003
2013-08-06 12:52:02,777 INFO org.apache.hadoop.yarn.server.resourcemanager.scheduler.common.fica.FiCaSchedulerNode: Released container container_1375792971633_0003_01_000003 of capacity <memory:1024, vCores:1> on host hadoop-110-6:50003, which currently has 0 containers, <memory:0, vCores:0> used and <memory:8192, vCores:16> available, release resources=true
2013-08-06 12:52:02,777 INFO org.apache.hadoop.yarn.server.resourcemanager.scheduler.capacity.LeafQueue: default used=<memory:2048, vCores:1> numContainers=1 user=ubuntu user-resources=<memory:2048, vCores:1>
2013-08-06 12:52:02,779 INFO org.apache.hadoop.yarn.server.resourcemanager.scheduler.capacity.LeafQueue: completedContainer container=Container: [ContainerId: container_1375792971633_0003_01_000003, NodeId: hadoop-110-6:50003, NodeHttpAddress: hadoop-110-6:8042, Resource: <memory:1024, vCores:1>, Priority: 20, State: NEW, Token: null, Status: container_id {, app_attempt_id {, application_id {, id: 3, cluster_timestamp: 1375792971633, }, attemptId: 1, }, id: 3, }, state: C_COMPLETE, diagnostics: "Container killed by the ApplicationMaster.\n\n", exit_status: 143, ] resource=<memory:1024, vCores:1> queue=default: capacity=1.0, absoluteCapacity=1.0, usedResources=<memory:2048, vCores:1>usedCapacity=0.041666668, absoluteUsedCapacity=0.041666668, numApps=1, numContainers=1 usedCapacity=0.041666668 absoluteUsedCapacity=0.041666668 used=<memory:2048, vCores:1> cluster=<memory:49152, vCores:96>
2013-08-06 12:52:02,779 INFO org.apache.hadoop.yarn.server.resourcemanager.scheduler.capacity.ParentQueue: completedContainer queue=root usedCapacity=0.041666668 absoluteUsedCapacity=0.041666668 used=<memory:2048, vCores:1> cluster=<memory:49152, vCores:96>
2013-08-06 12:52:02,779 INFO org.apache.hadoop.yarn.server.resourcemanager.scheduler.capacity.CapacityScheduler: Application appattempt_1375792971633_0003_000001 released container container_1375792971633_0003_01_000003 on node: host: hadoop-110-6:50003 #containers=0 available=8192 used=0 with event: FINISHED
2013-08-06 12:52:06,925 INFO org.apache.hadoop.yarn.server.resourcemanager.rmapp.attempt.RMAppAttemptImpl: appattempt_1375792971633_0003_000001 State change from RUNNING to FINISHING
2013-08-06 12:52:06,926 INFO org.apache.hadoop.yarn.server.resourcemanager.rmapp.RMAppImpl: application_1375792971633_0003 State change from RUNNING to FINISHING
2013-08-06 12:52:07,825 INFO org.apache.hadoop.yarn.server.resourcemanager.rmcontainer.RMContainerImpl: container_1375792971633_0003_01_000001 Container Transitioned from RUNNING to COMPLETED
2013-08-06 12:52:07,826 INFO org.apache.hadoop.yarn.server.resourcemanager.scheduler.common.fica.FiCaSchedulerApp: Completed container: container_1375792971633_0003_01_000001 in state: COMPLETED event:FINISHED
2013-08-06 12:52:07,826 INFO org.apache.hadoop.yarn.server.resourcemanager.rmapp.attempt.RMAppAttemptImpl: appattempt_1375792971633_0003_000001 State change from FINISHING to FINISHED
2013-08-06 12:52:07,826 INFO org.apache.hadoop.yarn.server.resourcemanager.RMAuditLogger: USER=ubuntu	OPERATION=AM Released Container	TARGET=SchedulerApp	RESULT=SUCCESS	APPID=application_1375792971633_0003	CONTAINERID=container_1375792971633_0003_01_000001
2013-08-06 12:52:07,826 INFO org.apache.hadoop.yarn.server.resourcemanager.scheduler.common.fica.FiCaSchedulerNode: Released container container_1375792971633_0003_01_000001 of capacity <memory:2048, vCores:1> on host hadoop-110-2:50749, which currently has 0 containers, <memory:0, vCores:0> used and <memory:8192, vCores:16> available, release resources=true
2013-08-06 12:52:07,826 INFO org.apache.hadoop.yarn.server.resourcemanager.scheduler.capacity.LeafQueue: default used=<memory:0, vCores:0> numContainers=0 user=ubuntu user-resources=<memory:0, vCores:0>
2013-08-06 12:52:07,826 INFO org.apache.hadoop.yarn.server.resourcemanager.rmapp.RMAppImpl: application_1375792971633_0003 State change from FINISHING to FINISHED
2013-08-06 12:52:07,828 INFO org.apache.hadoop.yarn.server.resourcemanager.RMAuditLogger: USER=ubuntu	OPERATION=Application Finished - Succeeded	TARGET=RMAppManager	RESULT=SUCCESS	APPID=application_1375792971633_0003
2013-08-06 12:52:07,828 INFO org.apache.hadoop.yarn.server.resourcemanager.scheduler.capacity.LeafQueue: completedContainer container=Container: [ContainerId: container_1375792971633_0003_01_000001, NodeId: hadoop-110-2:50749, NodeHttpAddress: hadoop-110-2:8042, Resource: <memory:2048, vCores:1>, Priority: 0, State: NEW, Token: null, Status: container_id {, app_attempt_id {, application_id {, id: 3, cluster_timestamp: 1375792971633, }, attemptId: 1, }, id: 1, }, state: C_COMPLETE, diagnostics: "", exit_status: 0, ] resource=<memory:2048, vCores:1> queue=default: capacity=1.0, absoluteCapacity=1.0, usedResources=<memory:0, vCores:0>usedCapacity=0.0, absoluteUsedCapacity=0.0, numApps=1, numContainers=0 usedCapacity=0.0 absoluteUsedCapacity=0.0 used=<memory:0, vCores:0> cluster=<memory:49152, vCores:96>
2013-08-06 12:52:07,828 INFO org.apache.hadoop.yarn.server.resourcemanager.recovery.RMStateStore: Removing info for app: application_1375792971633_0003
2013-08-06 12:52:07,828 INFO org.apache.hadoop.yarn.server.resourcemanager.scheduler.capacity.ParentQueue: completedContainer queue=root usedCapacity=0.0 absoluteUsedCapacity=0.0 used=<memory:0, vCores:0> cluster=<memory:49152, vCores:96>
2013-08-06 12:52:07,830 INFO org.apache.hadoop.yarn.server.resourcemanager.scheduler.capacity.CapacityScheduler: Application appattempt_1375792971633_0003_000001 released container container_1375792971633_0003_01_000001 on node: host: hadoop-110-2:50749 #containers=0 available=8192 used=0 with event: FINISHED
2013-08-06 12:52:07,831 INFO org.apache.hadoop.yarn.server.resourcemanager.scheduler.capacity.CapacityScheduler: Application appattempt_1375792971633_0003_000001 is done. finalState=FINISHED
2013-08-06 12:52:07,831 INFO org.apache.hadoop.yarn.server.resourcemanager.scheduler.AppSchedulingInfo: Application application_1375792971633_0003 requests cleared
2013-08-06 12:52:07,831 INFO org.apache.hadoop.yarn.server.resourcemanager.scheduler.capacity.LeafQueue: Application removed - appId: application_1375792971633_0003 user: ubuntu queue: default #user-pending-applications: 0 #user-active-applications: 0 #queue-pending-applications: 0 #queue-active-applications: 0
2013-08-06 12:52:07,831 INFO org.apache.hadoop.yarn.server.resourcemanager.scheduler.capacity.ParentQueue: Application removed - appId: application_1375792971633_0003 user: ubuntu leaf-queue of parent: root #applications: 0
2013-08-06 12:52:07,830 INFO org.apache.hadoop.yarn.server.resourcemanager.RMAppManager$ApplicationSummary: appId=application_1375792971633_0003,name=TeraGen,user=ubuntu,queue=default,state=FINISHED,trackingUrl=hadoop-110-1.novalocal:8088/proxy/application_1375792971633_0003/jobhistory/job/job_1375792971633_0003,appMasterHost=hadoop-110-2,startTime=1375793388479,finishTime=1375793526926
2013-08-06 12:52:07,830 INFO org.apache.hadoop.yarn.server.resourcemanager.amlauncher.AMLauncher: Cleaning master appattempt_1375792971633_0003_000001
2013-08-06 12:52:08,001 INFO org.apache.hadoop.yarn.server.resourcemanager.ClientRMService: Allocated new applicationId: 4
2013-08-06 12:52:09,906 INFO org.apache.hadoop.yarn.server.resourcemanager.ClientRMService: Storing Application with id application_1375792971633_0004
2013-08-06 12:52:09,906 INFO org.apache.hadoop.yarn.server.resourcemanager.recovery.RMStateStore: Storing info for app: application_1375792971633_0004
2013-08-06 12:52:09,906 INFO org.apache.hadoop.yarn.server.resourcemanager.ClientRMService: Application with id 4 submitted by user ubuntu
2013-08-06 12:52:09,906 INFO org.apache.hadoop.yarn.server.resourcemanager.RMAuditLogger: USER=ubuntu	IP=192.168.100.2	OPERATION=Submit Application Request	TARGET=ClientRMService	RESULT=SUCCESS	APPID=application_1375792971633_0004
2013-08-06 12:52:09,908 INFO org.apache.hadoop.yarn.server.resourcemanager.rmapp.RMAppImpl: application_1375792971633_0004 State change from NEW to SUBMITTED
2013-08-06 12:52:09,908 INFO org.apache.hadoop.yarn.server.resourcemanager.ApplicationMasterService: Registering appattempt_1375792971633_0004_000001
2013-08-06 12:52:09,908 INFO org.apache.hadoop.yarn.server.resourcemanager.rmapp.attempt.RMAppAttemptImpl: appattempt_1375792971633_0004_000001 State change from NEW to SUBMITTED
2013-08-06 12:52:09,909 INFO org.apache.hadoop.yarn.server.resourcemanager.scheduler.capacity.LeafQueue: Application application_1375792971633_0004 from user: ubuntu activated in queue: default
2013-08-06 12:52:09,909 INFO org.apache.hadoop.yarn.server.resourcemanager.scheduler.capacity.LeafQueue: Application added - appId: application_1375792971633_0004 user: org.apache.hadoop.yarn.server.resourcemanager.scheduler.capacity.LeafQueue$User@4ba9b15, leaf-queue: default #user-pending-applications: 0 #user-active-applications: 1 #queue-pending-applications: 0 #queue-active-applications: 1
2013-08-06 12:52:09,909 INFO org.apache.hadoop.yarn.server.resourcemanager.scheduler.capacity.ParentQueue: Application added - appId: application_1375792971633_0004 user: ubuntu leaf-queue of parent: root #applications: 1
2013-08-06 12:52:09,910 INFO org.apache.hadoop.yarn.server.resourcemanager.scheduler.capacity.CapacityScheduler: Application Submission: appattempt_1375792971633_0004_000001, user: ubuntu queue: default: capacity=1.0, absoluteCapacity=1.0, usedResources=<memory:0, vCores:0>usedCapacity=0.0, absoluteUsedCapacity=0.0, numApps=1, numContainers=0, currently active: 1
2013-08-06 12:52:09,910 INFO org.apache.hadoop.yarn.server.resourcemanager.rmapp.attempt.RMAppAttemptImpl: appattempt_1375792971633_0004_000001 State change from SUBMITTED to SCHEDULED
2013-08-06 12:52:09,910 INFO org.apache.hadoop.yarn.server.resourcemanager.rmapp.RMAppImpl: application_1375792971633_0004 State change from SUBMITTED to ACCEPTED
2013-08-06 12:52:10,146 INFO org.apache.hadoop.yarn.server.resourcemanager.rmcontainer.RMContainerImpl: container_1375792971633_0004_01_000001 Container Transitioned from NEW to ALLOCATED
2013-08-06 12:52:10,146 INFO org.apache.hadoop.yarn.server.resourcemanager.RMAuditLogger: USER=ubuntu	OPERATION=AM Allocated Container	TARGET=SchedulerApp	RESULT=SUCCESS	APPID=application_1375792971633_0004	CONTAINERID=container_1375792971633_0004_01_000001
2013-08-06 12:52:10,146 INFO org.apache.hadoop.yarn.server.resourcemanager.scheduler.common.fica.FiCaSchedulerNode: Assigned container container_1375792971633_0004_01_000001 of capacity <memory:2048, vCores:1> on host hadoop-110-7:55372, which currently has 1 containers, <memory:2048, vCores:1> used and <memory:6144, vCores:15> available
2013-08-06 12:52:10,148 INFO org.apache.hadoop.yarn.server.resourcemanager.scheduler.capacity.LeafQueue: assignedContainer application=application_1375792971633_0004 container=Container: [ContainerId: container_1375792971633_0004_01_000001, NodeId: hadoop-110-7:55372, NodeHttpAddress: hadoop-110-7:8042, Resource: <memory:2048, vCores:1>, Priority: 0, State: NEW, Token: null, Status: container_id {, app_attempt_id {, application_id {, id: 4, cluster_timestamp: 1375792971633, }, attemptId: 1, }, id: 1, }, state: C_NEW, ] containerId=container_1375792971633_0004_01_000001 queue=default: capacity=1.0, absoluteCapacity=1.0, usedResources=<memory:0, vCores:0>usedCapacity=0.0, absoluteUsedCapacity=0.0, numApps=1, numContainers=0 usedCapacity=0.0 absoluteUsedCapacity=0.0 used=<memory:0, vCores:0> cluster=<memory:49152, vCores:96>
2013-08-06 12:52:10,148 INFO org.apache.hadoop.yarn.server.resourcemanager.scheduler.capacity.ParentQueue: Re-sorting queues since queue: root.default stats: default: capacity=1.0, absoluteCapacity=1.0, usedResources=<memory:2048, vCores:1>usedCapacity=0.041666668, absoluteUsedCapacity=0.041666668, numApps=1, numContainers=1
2013-08-06 12:52:10,148 INFO org.apache.hadoop.yarn.server.resourcemanager.scheduler.capacity.ParentQueue: assignedContainer queue=root usedCapacity=0.041666668 absoluteUsedCapacity=0.041666668 used=<memory:2048, vCores:1> cluster=<memory:49152, vCores:96>
2013-08-06 12:52:10,150 INFO org.apache.hadoop.yarn.server.resourcemanager.rmcontainer.RMContainerImpl: container_1375792971633_0004_01_000001 Container Transitioned from ALLOCATED to ACQUIRED
2013-08-06 12:52:10,152 INFO org.apache.hadoop.yarn.server.resourcemanager.rmapp.attempt.RMAppAttemptImpl: Storing attempt: AppId: application_1375792971633_0004 AttemptId: appattempt_1375792971633_0004_000001 MasterContainer: Container: [ContainerId: container_1375792971633_0004_01_000001, NodeId: hadoop-110-7:55372, NodeHttpAddress: hadoop-110-7:8042, Resource: <memory:2048, vCores:1>, Priority: 0, State: NEW, Token: null, Status: container_id {, app_attempt_id {, application_id {, id: 4, cluster_timestamp: 1375792971633, }, attemptId: 1, }, id: 1, }, state: C_NEW, ]
2013-08-06 12:52:10,152 INFO org.apache.hadoop.yarn.server.resourcemanager.rmapp.attempt.RMAppAttemptImpl: appattempt_1375792971633_0004_000001 State change from SCHEDULED to ALLOCATED_SAVING
2013-08-06 12:52:10,153 INFO org.apache.hadoop.yarn.server.resourcemanager.recovery.RMStateStore: Storing info for attempt: appattempt_1375792971633_0004_000001
2013-08-06 12:52:10,155 INFO org.apache.hadoop.yarn.server.resourcemanager.rmapp.attempt.RMAppAttemptImpl: appattempt_1375792971633_0004_000001 State change from ALLOCATED_SAVING to ALLOCATED
2013-08-06 12:52:10,157 INFO org.apache.hadoop.yarn.server.resourcemanager.amlauncher.AMLauncher: Launching masterappattempt_1375792971633_0004_000001
2013-08-06 12:52:10,160 INFO org.apache.hadoop.yarn.server.resourcemanager.amlauncher.AMLauncher: Setting up container Container: [ContainerId: container_1375792971633_0004_01_000001, NodeId: hadoop-110-7:55372, NodeHttpAddress: hadoop-110-7:8042, Resource: <memory:2048, vCores:1>, Priority: 0, State: NEW, Token: null, Status: container_id {, app_attempt_id {, application_id {, id: 4, cluster_timestamp: 1375792971633, }, attemptId: 1, }, id: 1, }, state: C_NEW, ] for AM appattempt_1375792971633_0004_000001
2013-08-06 12:52:10,160 INFO org.apache.hadoop.yarn.server.resourcemanager.amlauncher.AMLauncher: Command to launch container container_1375792971633_0004_01_000001 : $JAVA_HOME/bin/java -Dlog4j.configuration=container-log4j.properties -Dyarn.app.mapreduce.container.log.dir=<LOG_DIR> -Dyarn.app.mapreduce.container.log.filesize=0 -Dhadoop.root.logger=INFO,CLA  -Xmx1024m org.apache.hadoop.mapreduce.v2.app.MRAppMaster 1><LOG_DIR>/stdout 2><LOG_DIR>/stderr 
2013-08-06 12:52:10,176 INFO org.apache.hadoop.yarn.server.resourcemanager.amlauncher.AMLauncher: Done launching container Container: [ContainerId: container_1375792971633_0004_01_000001, NodeId: hadoop-110-7:55372, NodeHttpAddress: hadoop-110-7:8042, Resource: <memory:2048, vCores:1>, Priority: 0, State: NEW, Token: null, Status: container_id {, app_attempt_id {, application_id {, id: 4, cluster_timestamp: 1375792971633, }, attemptId: 1, }, id: 1, }, state: C_NEW, ] for AM appattempt_1375792971633_0004_000001
2013-08-06 12:52:10,176 INFO org.apache.hadoop.yarn.server.resourcemanager.rmapp.attempt.RMAppAttemptImpl: appattempt_1375792971633_0004_000001 State change from ALLOCATED to LAUNCHED
2013-08-06 12:52:11,152 INFO org.apache.hadoop.yarn.server.resourcemanager.rmcontainer.RMContainerImpl: container_1375792971633_0004_01_000001 Container Transitioned from ACQUIRED to RUNNING
2013-08-06 12:52:17,583 INFO org.apache.hadoop.yarn.server.resourcemanager.ApplicationMasterService: AM registration appattempt_1375792971633_0004_000001
2013-08-06 12:52:17,583 INFO org.apache.hadoop.yarn.server.resourcemanager.RMAuditLogger: USER=ubuntu	IP=192.168.100.13	OPERATION=Register App Master	TARGET=ApplicationMasterService	RESULT=SUCCESS	APPID=application_1375792971633_0004	APPATTEMPTID=appattempt_1375792971633_0004_000001
2013-08-06 12:52:17,585 INFO org.apache.hadoop.yarn.server.resourcemanager.rmapp.attempt.RMAppAttemptImpl: appattempt_1375792971633_0004_000001 State change from LAUNCHED to RUNNING
2013-08-06 12:52:17,585 INFO org.apache.hadoop.yarn.server.resourcemanager.rmapp.RMAppImpl: application_1375792971633_0004 State change from ACCEPTED to RUNNING
2013-08-06 12:52:18,646 INFO org.apache.hadoop.yarn.server.resourcemanager.rmcontainer.RMContainerImpl: container_1375792971633_0004_01_000002 Container Transitioned from NEW to ALLOCATED
2013-08-06 12:52:18,647 INFO org.apache.hadoop.yarn.server.resourcemanager.RMAuditLogger: USER=ubuntu	OPERATION=AM Allocated Container	TARGET=SchedulerApp	RESULT=SUCCESS	APPID=application_1375792971633_0004	CONTAINERID=container_1375792971633_0004_01_000002
2013-08-06 12:52:18,647 INFO org.apache.hadoop.yarn.server.resourcemanager.scheduler.common.fica.FiCaSchedulerNode: Assigned container container_1375792971633_0004_01_000002 of capacity <memory:1024, vCores:1> on host hadoop-110-4:59955, which currently has 1 containers, <memory:1024, vCores:1> used and <memory:7168, vCores:15> available
2013-08-06 12:52:18,649 INFO org.apache.hadoop.yarn.server.resourcemanager.scheduler.capacity.LeafQueue: assignedContainer application=application_1375792971633_0004 container=Container: [ContainerId: container_1375792971633_0004_01_000002, NodeId: hadoop-110-4:59955, NodeHttpAddress: hadoop-110-4:8042, Resource: <memory:1024, vCores:1>, Priority: 20, State: NEW, Token: null, Status: container_id {, app_attempt_id {, application_id {, id: 4, cluster_timestamp: 1375792971633, }, attemptId: 1, }, id: 2, }, state: C_NEW, ] containerId=container_1375792971633_0004_01_000002 queue=default: capacity=1.0, absoluteCapacity=1.0, usedResources=<memory:2048, vCores:1>usedCapacity=0.041666668, absoluteUsedCapacity=0.041666668, numApps=1, numContainers=1 usedCapacity=0.041666668 absoluteUsedCapacity=0.041666668 used=<memory:2048, vCores:1> cluster=<memory:49152, vCores:96>
2013-08-06 12:52:18,649 INFO org.apache.hadoop.yarn.server.resourcemanager.scheduler.capacity.ParentQueue: Re-sorting queues since queue: root.default stats: default: capacity=1.0, absoluteCapacity=1.0, usedResources=<memory:3072, vCores:2>usedCapacity=0.0625, absoluteUsedCapacity=0.0625, numApps=1, numContainers=2
2013-08-06 12:52:18,649 INFO org.apache.hadoop.yarn.server.resourcemanager.scheduler.capacity.ParentQueue: assignedContainer queue=root usedCapacity=0.0625 absoluteUsedCapacity=0.0625 used=<memory:3072, vCores:2> cluster=<memory:49152, vCores:96>
2013-08-06 12:52:18,836 INFO org.apache.hadoop.yarn.server.resourcemanager.rmcontainer.RMContainerImpl: container_1375792971633_0004_01_000003 Container Transitioned from NEW to ALLOCATED
2013-08-06 12:52:18,836 INFO org.apache.hadoop.yarn.server.resourcemanager.RMAuditLogger: USER=ubuntu	OPERATION=AM Allocated Container	TARGET=SchedulerApp	RESULT=SUCCESS	APPID=application_1375792971633_0004	CONTAINERID=container_1375792971633_0004_01_000003
2013-08-06 12:52:18,836 INFO org.apache.hadoop.yarn.server.resourcemanager.scheduler.common.fica.FiCaSchedulerNode: Assigned container container_1375792971633_0004_01_000003 of capacity <memory:1024, vCores:1> on host hadoop-110-6:50003, which currently has 1 containers, <memory:1024, vCores:1> used and <memory:7168, vCores:15> available
2013-08-06 12:52:18,838 INFO org.apache.hadoop.yarn.server.resourcemanager.scheduler.capacity.LeafQueue: assignedContainer application=application_1375792971633_0004 container=Container: [ContainerId: container_1375792971633_0004_01_000003, NodeId: hadoop-110-6:50003, NodeHttpAddress: hadoop-110-6:8042, Resource: <memory:1024, vCores:1>, Priority: 20, State: NEW, Token: null, Status: container_id {, app_attempt_id {, application_id {, id: 4, cluster_timestamp: 1375792971633, }, attemptId: 1, }, id: 3, }, state: C_NEW, ] containerId=container_1375792971633_0004_01_000003 queue=default: capacity=1.0, absoluteCapacity=1.0, usedResources=<memory:3072, vCores:2>usedCapacity=0.0625, absoluteUsedCapacity=0.0625, numApps=1, numContainers=2 usedCapacity=0.0625 absoluteUsedCapacity=0.0625 used=<memory:3072, vCores:2> cluster=<memory:49152, vCores:96>
2013-08-06 12:52:18,838 INFO org.apache.hadoop.yarn.server.resourcemanager.scheduler.capacity.ParentQueue: Re-sorting queues since queue: root.default stats: default: capacity=1.0, absoluteCapacity=1.0, usedResources=<memory:4096, vCores:3>usedCapacity=0.083333336, absoluteUsedCapacity=0.083333336, numApps=1, numContainers=3
2013-08-06 12:52:18,838 INFO org.apache.hadoop.yarn.server.resourcemanager.scheduler.capacity.ParentQueue: assignedContainer queue=root usedCapacity=0.083333336 absoluteUsedCapacity=0.083333336 used=<memory:4096, vCores:3> cluster=<memory:49152, vCores:96>
2013-08-06 12:52:19,660 INFO org.apache.hadoop.yarn.server.resourcemanager.rmcontainer.RMContainerImpl: container_1375792971633_0004_01_000002 Container Transitioned from ALLOCATED to ACQUIRED
2013-08-06 12:52:19,662 INFO org.apache.hadoop.yarn.server.resourcemanager.rmcontainer.RMContainerImpl: container_1375792971633_0004_01_000003 Container Transitioned from ALLOCATED to ACQUIRED
2013-08-06 12:52:20,688 INFO org.apache.hadoop.yarn.server.resourcemanager.scheduler.AppSchedulingInfo: checking for deactivate... 
2013-08-06 12:52:20,844 INFO org.apache.hadoop.yarn.server.resourcemanager.rmcontainer.RMContainerImpl: container_1375792971633_0004_01_000003 Container Transitioned from ACQUIRED to RUNNING
2013-08-06 12:52:21,686 INFO org.apache.hadoop.yarn.server.resourcemanager.rmcontainer.RMContainerImpl: container_1375792971633_0004_01_000002 Container Transitioned from ACQUIRED to RUNNING
2013-08-06 12:54:19,519 INFO org.apache.hadoop.yarn.server.resourcemanager.rmcontainer.RMContainerImpl: container_1375792971633_0004_01_000003 Container Transitioned from RUNNING to COMPLETED
2013-08-06 12:54:19,519 INFO org.apache.hadoop.yarn.server.resourcemanager.scheduler.common.fica.FiCaSchedulerApp: Completed container: container_1375792971633_0004_01_000003 in state: COMPLETED event:FINISHED
2013-08-06 12:54:19,520 INFO org.apache.hadoop.yarn.server.resourcemanager.RMAuditLogger: USER=ubuntu	OPERATION=AM Released Container	TARGET=SchedulerApp	RESULT=SUCCESS	APPID=application_1375792971633_0004	CONTAINERID=container_1375792971633_0004_01_000003
2013-08-06 12:54:19,520 INFO org.apache.hadoop.yarn.server.resourcemanager.scheduler.common.fica.FiCaSchedulerNode: Released container container_1375792971633_0004_01_000003 of capacity <memory:1024, vCores:1> on host hadoop-110-6:50003, which currently has 0 containers, <memory:0, vCores:0> used and <memory:8192, vCores:16> available, release resources=true
2013-08-06 12:54:19,520 INFO org.apache.hadoop.yarn.server.resourcemanager.scheduler.capacity.LeafQueue: default used=<memory:3072, vCores:2> numContainers=2 user=ubuntu user-resources=<memory:3072, vCores:2>
2013-08-06 12:54:19,522 INFO org.apache.hadoop.yarn.server.resourcemanager.scheduler.capacity.LeafQueue: completedContainer container=Container: [ContainerId: container_1375792971633_0004_01_000003, NodeId: hadoop-110-6:50003, NodeHttpAddress: hadoop-110-6:8042, Resource: <memory:1024, vCores:1>, Priority: 20, State: NEW, Token: null, Status: container_id {, app_attempt_id {, application_id {, id: 4, cluster_timestamp: 1375792971633, }, attemptId: 1, }, id: 3, }, state: C_COMPLETE, diagnostics: "Container killed by the ApplicationMaster.\n\n", exit_status: 143, ] resource=<memory:1024, vCores:1> queue=default: capacity=1.0, absoluteCapacity=1.0, usedResources=<memory:3072, vCores:2>usedCapacity=0.0625, absoluteUsedCapacity=0.0625, numApps=1, numContainers=2 usedCapacity=0.0625 absoluteUsedCapacity=0.0625 used=<memory:3072, vCores:2> cluster=<memory:49152, vCores:96>
2013-08-06 12:54:19,522 INFO org.apache.hadoop.yarn.server.resourcemanager.scheduler.capacity.ParentQueue: completedContainer queue=root usedCapacity=0.0625 absoluteUsedCapacity=0.0625 used=<memory:3072, vCores:2> cluster=<memory:49152, vCores:96>
2013-08-06 12:54:19,522 INFO org.apache.hadoop.yarn.server.resourcemanager.scheduler.capacity.CapacityScheduler: Application appattempt_1375792971633_0004_000001 released container container_1375792971633_0004_01_000003 on node: host: hadoop-110-6:50003 #containers=0 available=8192 used=0 with event: FINISHED
2013-08-06 12:54:19,808 INFO org.apache.hadoop.yarn.server.resourcemanager.rmcontainer.RMContainerImpl: container_1375792971633_0004_01_000002 Container Transitioned from RUNNING to COMPLETED
2013-08-06 12:54:19,808 INFO org.apache.hadoop.yarn.server.resourcemanager.scheduler.common.fica.FiCaSchedulerApp: Completed container: container_1375792971633_0004_01_000002 in state: COMPLETED event:FINISHED
2013-08-06 12:54:19,808 INFO org.apache.hadoop.yarn.server.resourcemanager.RMAuditLogger: USER=ubuntu	OPERATION=AM Released Container	TARGET=SchedulerApp	RESULT=SUCCESS	APPID=application_1375792971633_0004	CONTAINERID=container_1375792971633_0004_01_000002
2013-08-06 12:54:19,808 INFO org.apache.hadoop.yarn.server.resourcemanager.scheduler.common.fica.FiCaSchedulerNode: Released container container_1375792971633_0004_01_000002 of capacity <memory:1024, vCores:1> on host hadoop-110-4:59955, which currently has 0 containers, <memory:0, vCores:0> used and <memory:8192, vCores:16> available, release resources=true
2013-08-06 12:54:19,808 INFO org.apache.hadoop.yarn.server.resourcemanager.scheduler.capacity.LeafQueue: default used=<memory:2048, vCores:1> numContainers=1 user=ubuntu user-resources=<memory:2048, vCores:1>
2013-08-06 12:54:19,810 INFO org.apache.hadoop.yarn.server.resourcemanager.scheduler.capacity.LeafQueue: completedContainer container=Container: [ContainerId: container_1375792971633_0004_01_000002, NodeId: hadoop-110-4:59955, NodeHttpAddress: hadoop-110-4:8042, Resource: <memory:1024, vCores:1>, Priority: 20, State: NEW, Token: null, Status: container_id {, app_attempt_id {, application_id {, id: 4, cluster_timestamp: 1375792971633, }, attemptId: 1, }, id: 2, }, state: C_COMPLETE, diagnostics: "Container killed by the ApplicationMaster.\n\n", exit_status: 143, ] resource=<memory:1024, vCores:1> queue=default: capacity=1.0, absoluteCapacity=1.0, usedResources=<memory:2048, vCores:1>usedCapacity=0.041666668, absoluteUsedCapacity=0.041666668, numApps=1, numContainers=1 usedCapacity=0.041666668 absoluteUsedCapacity=0.041666668 used=<memory:2048, vCores:1> cluster=<memory:49152, vCores:96>
2013-08-06 12:54:19,810 INFO org.apache.hadoop.yarn.server.resourcemanager.scheduler.capacity.ParentQueue: completedContainer queue=root usedCapacity=0.041666668 absoluteUsedCapacity=0.041666668 used=<memory:2048, vCores:1> cluster=<memory:49152, vCores:96>
2013-08-06 12:54:19,810 INFO org.apache.hadoop.yarn.server.resourcemanager.scheduler.capacity.CapacityScheduler: Application appattempt_1375792971633_0004_000001 released container container_1375792971633_0004_01_000002 on node: host: hadoop-110-4:59955 #containers=0 available=8192 used=0 with event: FINISHED
2013-08-06 12:54:24,159 INFO org.apache.hadoop.yarn.server.resourcemanager.rmapp.attempt.RMAppAttemptImpl: appattempt_1375792971633_0004_000001 State change from RUNNING to FINISHING
2013-08-06 12:54:24,160 INFO org.apache.hadoop.yarn.server.resourcemanager.rmapp.RMAppImpl: application_1375792971633_0004 State change from RUNNING to FINISHING
2013-08-06 12:54:25,180 INFO org.apache.hadoop.yarn.server.resourcemanager.ClientRMService: Allocated new applicationId: 5
2013-08-06 12:54:25,358 INFO org.apache.hadoop.yarn.server.resourcemanager.rmcontainer.RMContainerImpl: container_1375792971633_0004_01_000001 Container Transitioned from RUNNING to COMPLETED
2013-08-06 12:54:25,358 INFO org.apache.hadoop.yarn.server.resourcemanager.rmapp.attempt.RMAppAttemptImpl: appattempt_1375792971633_0004_000001 State change from FINISHING to FINISHED
2013-08-06 12:54:25,358 INFO org.apache.hadoop.yarn.server.resourcemanager.scheduler.common.fica.FiCaSchedulerApp: Completed container: container_1375792971633_0004_01_000001 in state: COMPLETED event:FINISHED
2013-08-06 12:54:25,358 INFO org.apache.hadoop.yarn.server.resourcemanager.RMAuditLogger: USER=ubuntu	OPERATION=AM Released Container	TARGET=SchedulerApp	RESULT=SUCCESS	APPID=application_1375792971633_0004	CONTAINERID=container_1375792971633_0004_01_000001
2013-08-06 12:54:25,358 INFO org.apache.hadoop.yarn.server.resourcemanager.rmapp.RMAppImpl: application_1375792971633_0004 State change from FINISHING to FINISHED
2013-08-06 12:54:25,358 INFO org.apache.hadoop.yarn.server.resourcemanager.scheduler.common.fica.FiCaSchedulerNode: Released container container_1375792971633_0004_01_000001 of capacity <memory:2048, vCores:1> on host hadoop-110-7:55372, which currently has 0 containers, <memory:0, vCores:0> used and <memory:8192, vCores:16> available, release resources=true
2013-08-06 12:54:25,359 INFO org.apache.hadoop.yarn.server.resourcemanager.RMAuditLogger: USER=ubuntu	OPERATION=Application Finished - Succeeded	TARGET=RMAppManager	RESULT=SUCCESS	APPID=application_1375792971633_0004
2013-08-06 12:54:25,359 INFO org.apache.hadoop.yarn.server.resourcemanager.scheduler.capacity.LeafQueue: default used=<memory:0, vCores:0> numContainers=0 user=ubuntu user-resources=<memory:0, vCores:0>
2013-08-06 12:54:25,359 INFO org.apache.hadoop.yarn.server.resourcemanager.recovery.RMStateStore: Removing info for app: application_1375792971633_0004
2013-08-06 12:54:25,399 INFO org.apache.hadoop.yarn.server.resourcemanager.amlauncher.AMLauncher: Cleaning master appattempt_1375792971633_0004_000001
2013-08-06 12:54:25,400 INFO org.apache.hadoop.yarn.server.resourcemanager.RMAppManager$ApplicationSummary: appId=application_1375792971633_0004,name=TeraGen,user=ubuntu,queue=default,state=FINISHED,trackingUrl=hadoop-110-1.novalocal:8088/proxy/application_1375792971633_0004/jobhistory/job/job_1375792971633_0004,appMasterHost=hadoop-110-7,startTime=1375793529905,finishTime=1375793664160
2013-08-06 12:54:25,401 INFO org.apache.hadoop.yarn.server.resourcemanager.scheduler.capacity.LeafQueue: completedContainer container=Container: [ContainerId: container_1375792971633_0004_01_000001, NodeId: hadoop-110-7:55372, NodeHttpAddress: hadoop-110-7:8042, Resource: <memory:2048, vCores:1>, Priority: 0, State: NEW, Token: null, Status: container_id {, app_attempt_id {, application_id {, id: 4, cluster_timestamp: 1375792971633, }, attemptId: 1, }, id: 1, }, state: C_COMPLETE, diagnostics: "", exit_status: 0, ] resource=<memory:2048, vCores:1> queue=default: capacity=1.0, absoluteCapacity=1.0, usedResources=<memory:0, vCores:0>usedCapacity=0.0, absoluteUsedCapacity=0.0, numApps=1, numContainers=0 usedCapacity=0.0 absoluteUsedCapacity=0.0 used=<memory:0, vCores:0> cluster=<memory:49152, vCores:96>
2013-08-06 12:54:25,402 INFO org.apache.hadoop.yarn.server.resourcemanager.scheduler.capacity.ParentQueue: completedContainer queue=root usedCapacity=0.0 absoluteUsedCapacity=0.0 used=<memory:0, vCores:0> cluster=<memory:49152, vCores:96>
2013-08-06 12:54:25,402 INFO org.apache.hadoop.yarn.server.resourcemanager.scheduler.capacity.CapacityScheduler: Application appattempt_1375792971633_0004_000001 released container container_1375792971633_0004_01_000001 on node: host: hadoop-110-7:55372 #containers=0 available=8192 used=0 with event: FINISHED
2013-08-06 12:54:25,402 INFO org.apache.hadoop.yarn.server.resourcemanager.scheduler.capacity.CapacityScheduler: Application appattempt_1375792971633_0004_000001 is done. finalState=FINISHED
2013-08-06 12:54:25,402 INFO org.apache.hadoop.yarn.server.resourcemanager.scheduler.AppSchedulingInfo: Application application_1375792971633_0004 requests cleared
2013-08-06 12:54:25,402 INFO org.apache.hadoop.yarn.server.resourcemanager.scheduler.capacity.LeafQueue: Application removed - appId: application_1375792971633_0004 user: ubuntu queue: default #user-pending-applications: 0 #user-active-applications: 0 #queue-pending-applications: 0 #queue-active-applications: 0
2013-08-06 12:54:25,402 INFO org.apache.hadoop.yarn.server.resourcemanager.scheduler.capacity.ParentQueue: Application removed - appId: application_1375792971633_0004 user: ubuntu leaf-queue of parent: root #applications: 0
2013-08-06 12:54:27,079 INFO org.apache.hadoop.yarn.server.resourcemanager.ClientRMService: Storing Application with id application_1375792971633_0005
2013-08-06 12:54:27,081 INFO org.apache.hadoop.yarn.server.resourcemanager.recovery.RMStateStore: Storing info for app: application_1375792971633_0005
2013-08-06 12:54:27,081 INFO org.apache.hadoop.yarn.server.resourcemanager.ClientRMService: Application with id 5 submitted by user ubuntu
2013-08-06 12:54:27,081 INFO org.apache.hadoop.yarn.server.resourcemanager.RMAuditLogger: USER=ubuntu	IP=192.168.100.2	OPERATION=Submit Application Request	TARGET=ClientRMService	RESULT=SUCCESS	APPID=application_1375792971633_0005
2013-08-06 12:54:27,080 INFO org.apache.hadoop.yarn.server.resourcemanager.rmapp.RMAppImpl: application_1375792971633_0005 State change from NEW to SUBMITTED
2013-08-06 12:54:27,083 INFO org.apache.hadoop.yarn.server.resourcemanager.ApplicationMasterService: Registering appattempt_1375792971633_0005_000001
2013-08-06 12:54:27,083 INFO org.apache.hadoop.yarn.server.resourcemanager.rmapp.attempt.RMAppAttemptImpl: appattempt_1375792971633_0005_000001 State change from NEW to SUBMITTED
2013-08-06 12:54:27,084 INFO org.apache.hadoop.yarn.server.resourcemanager.scheduler.capacity.LeafQueue: Application application_1375792971633_0005 from user: ubuntu activated in queue: default
2013-08-06 12:54:27,084 INFO org.apache.hadoop.yarn.server.resourcemanager.scheduler.capacity.LeafQueue: Application added - appId: application_1375792971633_0005 user: org.apache.hadoop.yarn.server.resourcemanager.scheduler.capacity.LeafQueue$User@4c16cfa, leaf-queue: default #user-pending-applications: 0 #user-active-applications: 1 #queue-pending-applications: 0 #queue-active-applications: 1
2013-08-06 12:54:27,084 INFO org.apache.hadoop.yarn.server.resourcemanager.scheduler.capacity.ParentQueue: Application added - appId: application_1375792971633_0005 user: ubuntu leaf-queue of parent: root #applications: 1
2013-08-06 12:54:27,084 INFO org.apache.hadoop.yarn.server.resourcemanager.scheduler.capacity.CapacityScheduler: Application Submission: appattempt_1375792971633_0005_000001, user: ubuntu queue: default: capacity=1.0, absoluteCapacity=1.0, usedResources=<memory:0, vCores:0>usedCapacity=0.0, absoluteUsedCapacity=0.0, numApps=1, numContainers=0, currently active: 1
2013-08-06 12:54:27,085 INFO org.apache.hadoop.yarn.server.resourcemanager.rmapp.attempt.RMAppAttemptImpl: appattempt_1375792971633_0005_000001 State change from SUBMITTED to SCHEDULED
2013-08-06 12:54:27,085 INFO org.apache.hadoop.yarn.server.resourcemanager.rmapp.RMAppImpl: application_1375792971633_0005 State change from SUBMITTED to ACCEPTED
2013-08-06 12:54:27,328 INFO org.apache.hadoop.yarn.server.resourcemanager.rmcontainer.RMContainerImpl: container_1375792971633_0005_01_000001 Container Transitioned from NEW to ALLOCATED
2013-08-06 12:54:27,328 INFO org.apache.hadoop.yarn.server.resourcemanager.RMAuditLogger: USER=ubuntu	OPERATION=AM Allocated Container	TARGET=SchedulerApp	RESULT=SUCCESS	APPID=application_1375792971633_0005	CONTAINERID=container_1375792971633_0005_01_000001
2013-08-06 12:54:27,329 INFO org.apache.hadoop.yarn.server.resourcemanager.scheduler.common.fica.FiCaSchedulerNode: Assigned container container_1375792971633_0005_01_000001 of capacity <memory:2048, vCores:1> on host hadoop-110-2:50749, which currently has 1 containers, <memory:2048, vCores:1> used and <memory:6144, vCores:15> available
2013-08-06 12:54:27,330 INFO org.apache.hadoop.yarn.server.resourcemanager.scheduler.capacity.LeafQueue: assignedContainer application=application_1375792971633_0005 container=Container: [ContainerId: container_1375792971633_0005_01_000001, NodeId: hadoop-110-2:50749, NodeHttpAddress: hadoop-110-2:8042, Resource: <memory:2048, vCores:1>, Priority: 0, State: NEW, Token: null, Status: container_id {, app_attempt_id {, application_id {, id: 5, cluster_timestamp: 1375792971633, }, attemptId: 1, }, id: 1, }, state: C_NEW, ] containerId=container_1375792971633_0005_01_000001 queue=default: capacity=1.0, absoluteCapacity=1.0, usedResources=<memory:0, vCores:0>usedCapacity=0.0, absoluteUsedCapacity=0.0, numApps=1, numContainers=0 usedCapacity=0.0 absoluteUsedCapacity=0.0 used=<memory:0, vCores:0> cluster=<memory:49152, vCores:96>
2013-08-06 12:54:27,330 INFO org.apache.hadoop.yarn.server.resourcemanager.scheduler.capacity.ParentQueue: Re-sorting queues since queue: root.default stats: default: capacity=1.0, absoluteCapacity=1.0, usedResources=<memory:2048, vCores:1>usedCapacity=0.041666668, absoluteUsedCapacity=0.041666668, numApps=1, numContainers=1
2013-08-06 12:54:27,330 INFO org.apache.hadoop.yarn.server.resourcemanager.scheduler.capacity.ParentQueue: assignedContainer queue=root usedCapacity=0.041666668 absoluteUsedCapacity=0.041666668 used=<memory:2048, vCores:1> cluster=<memory:49152, vCores:96>
2013-08-06 12:54:27,332 INFO org.apache.hadoop.yarn.server.resourcemanager.rmcontainer.RMContainerImpl: container_1375792971633_0005_01_000001 Container Transitioned from ALLOCATED to ACQUIRED
2013-08-06 12:54:27,334 INFO org.apache.hadoop.yarn.server.resourcemanager.rmapp.attempt.RMAppAttemptImpl: Storing attempt: AppId: application_1375792971633_0005 AttemptId: appattempt_1375792971633_0005_000001 MasterContainer: Container: [ContainerId: container_1375792971633_0005_01_000001, NodeId: hadoop-110-2:50749, NodeHttpAddress: hadoop-110-2:8042, Resource: <memory:2048, vCores:1>, Priority: 0, State: NEW, Token: null, Status: container_id {, app_attempt_id {, application_id {, id: 5, cluster_timestamp: 1375792971633, }, attemptId: 1, }, id: 1, }, state: C_NEW, ]
2013-08-06 12:54:27,335 INFO org.apache.hadoop.yarn.server.resourcemanager.recovery.RMStateStore: Storing info for attempt: appattempt_1375792971633_0005_000001
2013-08-06 12:54:27,335 INFO org.apache.hadoop.yarn.server.resourcemanager.rmapp.attempt.RMAppAttemptImpl: appattempt_1375792971633_0005_000001 State change from SCHEDULED to ALLOCATED_SAVING
2013-08-06 12:54:27,336 INFO org.apache.hadoop.yarn.server.resourcemanager.rmapp.attempt.RMAppAttemptImpl: appattempt_1375792971633_0005_000001 State change from ALLOCATED_SAVING to ALLOCATED
2013-08-06 12:54:27,337 INFO org.apache.hadoop.yarn.server.resourcemanager.amlauncher.AMLauncher: Launching masterappattempt_1375792971633_0005_000001
2013-08-06 12:54:27,340 INFO org.apache.hadoop.yarn.server.resourcemanager.amlauncher.AMLauncher: Setting up container Container: [ContainerId: container_1375792971633_0005_01_000001, NodeId: hadoop-110-2:50749, NodeHttpAddress: hadoop-110-2:8042, Resource: <memory:2048, vCores:1>, Priority: 0, State: NEW, Token: null, Status: container_id {, app_attempt_id {, application_id {, id: 5, cluster_timestamp: 1375792971633, }, attemptId: 1, }, id: 1, }, state: C_NEW, ] for AM appattempt_1375792971633_0005_000001
2013-08-06 12:54:27,340 INFO org.apache.hadoop.yarn.server.resourcemanager.amlauncher.AMLauncher: Command to launch container container_1375792971633_0005_01_000001 : $JAVA_HOME/bin/java -Dlog4j.configuration=container-log4j.properties -Dyarn.app.mapreduce.container.log.dir=<LOG_DIR> -Dyarn.app.mapreduce.container.log.filesize=0 -Dhadoop.root.logger=INFO,CLA  -Xmx1024m org.apache.hadoop.mapreduce.v2.app.MRAppMaster 1><LOG_DIR>/stdout 2><LOG_DIR>/stderr 
2013-08-06 12:54:27,354 INFO org.apache.hadoop.yarn.server.resourcemanager.amlauncher.AMLauncher: Done launching container Container: [ContainerId: container_1375792971633_0005_01_000001, NodeId: hadoop-110-2:50749, NodeHttpAddress: hadoop-110-2:8042, Resource: <memory:2048, vCores:1>, Priority: 0, State: NEW, Token: null, Status: container_id {, app_attempt_id {, application_id {, id: 5, cluster_timestamp: 1375792971633, }, attemptId: 1, }, id: 1, }, state: C_NEW, ] for AM appattempt_1375792971633_0005_000001
2013-08-06 12:54:27,355 INFO org.apache.hadoop.yarn.server.resourcemanager.rmapp.attempt.RMAppAttemptImpl: appattempt_1375792971633_0005_000001 State change from ALLOCATED to LAUNCHED
2013-08-06 12:54:28,333 INFO org.apache.hadoop.yarn.server.resourcemanager.rmcontainer.RMContainerImpl: container_1375792971633_0005_01_000001 Container Transitioned from ACQUIRED to RUNNING
2013-08-06 12:54:33,552 INFO org.apache.hadoop.yarn.server.resourcemanager.ApplicationMasterService: AM registration appattempt_1375792971633_0005_000001
2013-08-06 12:54:33,552 INFO org.apache.hadoop.yarn.server.resourcemanager.RMAuditLogger: USER=ubuntu	IP=192.168.100.3	OPERATION=Register App Master	TARGET=ApplicationMasterService	RESULT=SUCCESS	APPID=application_1375792971633_0005	APPATTEMPTID=appattempt_1375792971633_0005_000001
2013-08-06 12:54:33,553 INFO org.apache.hadoop.yarn.server.resourcemanager.rmapp.attempt.RMAppAttemptImpl: appattempt_1375792971633_0005_000001 State change from LAUNCHED to RUNNING
2013-08-06 12:54:33,553 INFO org.apache.hadoop.yarn.server.resourcemanager.rmapp.RMAppImpl: application_1375792971633_0005 State change from ACCEPTED to RUNNING
2013-08-06 12:54:34,864 INFO org.apache.hadoop.yarn.server.resourcemanager.rmcontainer.RMContainerImpl: container_1375792971633_0005_01_000002 Container Transitioned from NEW to ALLOCATED
2013-08-06 12:54:34,864 INFO org.apache.hadoop.yarn.server.resourcemanager.RMAuditLogger: USER=ubuntu	OPERATION=AM Allocated Container	TARGET=SchedulerApp	RESULT=SUCCESS	APPID=application_1375792971633_0005	CONTAINERID=container_1375792971633_0005_01_000002
2013-08-06 12:54:34,864 INFO org.apache.hadoop.yarn.server.resourcemanager.scheduler.common.fica.FiCaSchedulerNode: Assigned container container_1375792971633_0005_01_000002 of capacity <memory:1024, vCores:1> on host hadoop-110-4:59955, which currently has 1 containers, <memory:1024, vCores:1> used and <memory:7168, vCores:15> available
2013-08-06 12:54:34,865 INFO org.apache.hadoop.yarn.server.resourcemanager.scheduler.capacity.LeafQueue: assignedContainer application=application_1375792971633_0005 container=Container: [ContainerId: container_1375792971633_0005_01_000002, NodeId: hadoop-110-4:59955, NodeHttpAddress: hadoop-110-4:8042, Resource: <memory:1024, vCores:1>, Priority: 20, State: NEW, Token: null, Status: container_id {, app_attempt_id {, application_id {, id: 5, cluster_timestamp: 1375792971633, }, attemptId: 1, }, id: 2, }, state: C_NEW, ] containerId=container_1375792971633_0005_01_000002 queue=default: capacity=1.0, absoluteCapacity=1.0, usedResources=<memory:2048, vCores:1>usedCapacity=0.041666668, absoluteUsedCapacity=0.041666668, numApps=1, numContainers=1 usedCapacity=0.041666668 absoluteUsedCapacity=0.041666668 used=<memory:2048, vCores:1> cluster=<memory:49152, vCores:96>
2013-08-06 12:54:34,866 INFO org.apache.hadoop.yarn.server.resourcemanager.scheduler.capacity.ParentQueue: Re-sorting queues since queue: root.default stats: default: capacity=1.0, absoluteCapacity=1.0, usedResources=<memory:3072, vCores:2>usedCapacity=0.0625, absoluteUsedCapacity=0.0625, numApps=1, numContainers=2
2013-08-06 12:54:34,866 INFO org.apache.hadoop.yarn.server.resourcemanager.scheduler.capacity.ParentQueue: assignedContainer queue=root usedCapacity=0.0625 absoluteUsedCapacity=0.0625 used=<memory:3072, vCores:2> cluster=<memory:49152, vCores:96>
2013-08-06 12:54:34,942 INFO org.apache.hadoop.yarn.server.resourcemanager.rmcontainer.RMContainerImpl: container_1375792971633_0005_01_000003 Container Transitioned from NEW to ALLOCATED
2013-08-06 12:54:34,942 INFO org.apache.hadoop.yarn.server.resourcemanager.RMAuditLogger: USER=ubuntu	OPERATION=AM Allocated Container	TARGET=SchedulerApp	RESULT=SUCCESS	APPID=application_1375792971633_0005	CONTAINERID=container_1375792971633_0005_01_000003
2013-08-06 12:54:34,942 INFO org.apache.hadoop.yarn.server.resourcemanager.scheduler.common.fica.FiCaSchedulerNode: Assigned container container_1375792971633_0005_01_000003 of capacity <memory:1024, vCores:1> on host hadoop-110-5:54830, which currently has 1 containers, <memory:1024, vCores:1> used and <memory:7168, vCores:15> available
2013-08-06 12:54:34,943 INFO org.apache.hadoop.yarn.server.resourcemanager.scheduler.capacity.LeafQueue: assignedContainer application=application_1375792971633_0005 container=Container: [ContainerId: container_1375792971633_0005_01_000003, NodeId: hadoop-110-5:54830, NodeHttpAddress: hadoop-110-5:8042, Resource: <memory:1024, vCores:1>, Priority: 20, State: NEW, Token: null, Status: container_id {, app_attempt_id {, application_id {, id: 5, cluster_timestamp: 1375792971633, }, attemptId: 1, }, id: 3, }, state: C_NEW, ] containerId=container_1375792971633_0005_01_000003 queue=default: capacity=1.0, absoluteCapacity=1.0, usedResources=<memory:3072, vCores:2>usedCapacity=0.0625, absoluteUsedCapacity=0.0625, numApps=1, numContainers=2 usedCapacity=0.0625 absoluteUsedCapacity=0.0625 used=<memory:3072, vCores:2> cluster=<memory:49152, vCores:96>
2013-08-06 12:54:34,943 INFO org.apache.hadoop.yarn.server.resourcemanager.scheduler.capacity.ParentQueue: Re-sorting queues since queue: root.default stats: default: capacity=1.0, absoluteCapacity=1.0, usedResources=<memory:4096, vCores:3>usedCapacity=0.083333336, absoluteUsedCapacity=0.083333336, numApps=1, numContainers=3
2013-08-06 12:54:34,944 INFO org.apache.hadoop.yarn.server.resourcemanager.scheduler.capacity.ParentQueue: assignedContainer queue=root usedCapacity=0.083333336 absoluteUsedCapacity=0.083333336 used=<memory:4096, vCores:3> cluster=<memory:49152, vCores:96>
2013-08-06 12:54:35,614 INFO org.apache.hadoop.yarn.server.resourcemanager.rmcontainer.RMContainerImpl: container_1375792971633_0005_01_000002 Container Transitioned from ALLOCATED to ACQUIRED
2013-08-06 12:54:35,618 INFO org.apache.hadoop.yarn.server.resourcemanager.rmcontainer.RMContainerImpl: container_1375792971633_0005_01_000003 Container Transitioned from ALLOCATED to ACQUIRED
2013-08-06 12:54:36,646 INFO org.apache.hadoop.yarn.server.resourcemanager.scheduler.AppSchedulingInfo: checking for deactivate... 
2013-08-06 12:54:36,878 INFO org.apache.hadoop.yarn.server.resourcemanager.rmcontainer.RMContainerImpl: container_1375792971633_0005_01_000002 Container Transitioned from ACQUIRED to RUNNING
2013-08-06 12:54:37,018 INFO org.apache.hadoop.yarn.server.resourcemanager.rmcontainer.RMContainerImpl: container_1375792971633_0005_01_000003 Container Transitioned from ACQUIRED to RUNNING
2013-08-06 12:56:25,282 INFO org.apache.hadoop.yarn.server.resourcemanager.rmcontainer.RMContainerImpl: container_1375792971633_0005_01_000002 Container Transitioned from RUNNING to COMPLETED
2013-08-06 12:56:25,282 INFO org.apache.hadoop.yarn.server.resourcemanager.scheduler.common.fica.FiCaSchedulerApp: Completed container: container_1375792971633_0005_01_000002 in state: COMPLETED event:FINISHED
2013-08-06 12:56:25,282 INFO org.apache.hadoop.yarn.server.resourcemanager.RMAuditLogger: USER=ubuntu	OPERATION=AM Released Container	TARGET=SchedulerApp	RESULT=SUCCESS	APPID=application_1375792971633_0005	CONTAINERID=container_1375792971633_0005_01_000002
2013-08-06 12:56:25,283 INFO org.apache.hadoop.yarn.server.resourcemanager.scheduler.common.fica.FiCaSchedulerNode: Released container container_1375792971633_0005_01_000002 of capacity <memory:1024, vCores:1> on host hadoop-110-4:59955, which currently has 0 containers, <memory:0, vCores:0> used and <memory:8192, vCores:16> available, release resources=true
2013-08-06 12:56:25,283 INFO org.apache.hadoop.yarn.server.resourcemanager.scheduler.capacity.LeafQueue: default used=<memory:3072, vCores:2> numContainers=2 user=ubuntu user-resources=<memory:3072, vCores:2>
2013-08-06 12:56:25,284 INFO org.apache.hadoop.yarn.server.resourcemanager.scheduler.capacity.LeafQueue: completedContainer container=Container: [ContainerId: container_1375792971633_0005_01_000002, NodeId: hadoop-110-4:59955, NodeHttpAddress: hadoop-110-4:8042, Resource: <memory:1024, vCores:1>, Priority: 20, State: NEW, Token: null, Status: container_id {, app_attempt_id {, application_id {, id: 5, cluster_timestamp: 1375792971633, }, attemptId: 1, }, id: 2, }, state: C_COMPLETE, diagnostics: "Container killed by the ApplicationMaster.\n\n", exit_status: 143, ] resource=<memory:1024, vCores:1> queue=default: capacity=1.0, absoluteCapacity=1.0, usedResources=<memory:3072, vCores:2>usedCapacity=0.0625, absoluteUsedCapacity=0.0625, numApps=1, numContainers=2 usedCapacity=0.0625 absoluteUsedCapacity=0.0625 used=<memory:3072, vCores:2> cluster=<memory:49152, vCores:96>
2013-08-06 12:56:25,284 INFO org.apache.hadoop.yarn.server.resourcemanager.scheduler.capacity.ParentQueue: completedContainer queue=root usedCapacity=0.0625 absoluteUsedCapacity=0.0625 used=<memory:3072, vCores:2> cluster=<memory:49152, vCores:96>
2013-08-06 12:56:25,285 INFO org.apache.hadoop.yarn.server.resourcemanager.scheduler.capacity.CapacityScheduler: Application appattempt_1375792971633_0005_000001 released container container_1375792971633_0005_01_000002 on node: host: hadoop-110-4:59955 #containers=0 available=8192 used=0 with event: FINISHED
2013-08-06 12:56:30,898 INFO org.apache.hadoop.yarn.server.resourcemanager.rmcontainer.RMContainerImpl: container_1375792971633_0005_01_000003 Container Transitioned from RUNNING to COMPLETED
2013-08-06 12:56:30,898 INFO org.apache.hadoop.yarn.server.resourcemanager.scheduler.common.fica.FiCaSchedulerApp: Completed container: container_1375792971633_0005_01_000003 in state: COMPLETED event:FINISHED
2013-08-06 12:56:30,899 INFO org.apache.hadoop.yarn.server.resourcemanager.RMAuditLogger: USER=ubuntu	OPERATION=AM Released Container	TARGET=SchedulerApp	RESULT=SUCCESS	APPID=application_1375792971633_0005	CONTAINERID=container_1375792971633_0005_01_000003
2013-08-06 12:56:30,899 INFO org.apache.hadoop.yarn.server.resourcemanager.scheduler.common.fica.FiCaSchedulerNode: Released container container_1375792971633_0005_01_000003 of capacity <memory:1024, vCores:1> on host hadoop-110-5:54830, which currently has 0 containers, <memory:0, vCores:0> used and <memory:8192, vCores:16> available, release resources=true
2013-08-06 12:56:30,899 INFO org.apache.hadoop.yarn.server.resourcemanager.scheduler.capacity.LeafQueue: default used=<memory:2048, vCores:1> numContainers=1 user=ubuntu user-resources=<memory:2048, vCores:1>
2013-08-06 12:56:30,901 INFO org.apache.hadoop.yarn.server.resourcemanager.scheduler.capacity.LeafQueue: completedContainer container=Container: [ContainerId: container_1375792971633_0005_01_000003, NodeId: hadoop-110-5:54830, NodeHttpAddress: hadoop-110-5:8042, Resource: <memory:1024, vCores:1>, Priority: 20, State: NEW, Token: null, Status: container_id {, app_attempt_id {, application_id {, id: 5, cluster_timestamp: 1375792971633, }, attemptId: 1, }, id: 3, }, state: C_COMPLETE, diagnostics: "Container killed by the ApplicationMaster.\n\n", exit_status: 143, ] resource=<memory:1024, vCores:1> queue=default: capacity=1.0, absoluteCapacity=1.0, usedResources=<memory:2048, vCores:1>usedCapacity=0.041666668, absoluteUsedCapacity=0.041666668, numApps=1, numContainers=1 usedCapacity=0.041666668 absoluteUsedCapacity=0.041666668 used=<memory:2048, vCores:1> cluster=<memory:49152, vCores:96>
2013-08-06 12:56:30,901 INFO org.apache.hadoop.yarn.server.resourcemanager.scheduler.capacity.ParentQueue: completedContainer queue=root usedCapacity=0.041666668 absoluteUsedCapacity=0.041666668 used=<memory:2048, vCores:1> cluster=<memory:49152, vCores:96>
2013-08-06 12:56:30,901 INFO org.apache.hadoop.yarn.server.resourcemanager.scheduler.capacity.CapacityScheduler: Application appattempt_1375792971633_0005_000001 released container container_1375792971633_0005_01_000003 on node: host: hadoop-110-5:54830 #containers=0 available=8192 used=0 with event: FINISHED
2013-08-06 12:56:36,809 INFO org.apache.hadoop.yarn.server.resourcemanager.rmapp.attempt.RMAppAttemptImpl: appattempt_1375792971633_0005_000001 State change from RUNNING to FINISHING
2013-08-06 12:56:36,810 INFO org.apache.hadoop.yarn.server.resourcemanager.rmapp.RMAppImpl: application_1375792971633_0005 State change from RUNNING to FINISHING
2013-08-06 12:56:38,063 INFO org.apache.hadoop.yarn.server.resourcemanager.rmcontainer.RMContainerImpl: container_1375792971633_0005_01_000001 Container Transitioned from RUNNING to COMPLETED
2013-08-06 12:56:38,063 INFO org.apache.hadoop.yarn.server.resourcemanager.rmapp.attempt.RMAppAttemptImpl: appattempt_1375792971633_0005_000001 State change from FINISHING to FINISHED
2013-08-06 12:56:38,063 INFO org.apache.hadoop.yarn.server.resourcemanager.scheduler.common.fica.FiCaSchedulerApp: Completed container: container_1375792971633_0005_01_000001 in state: COMPLETED event:FINISHED
2013-08-06 12:56:38,063 INFO org.apache.hadoop.yarn.server.resourcemanager.rmapp.RMAppImpl: application_1375792971633_0005 State change from FINISHING to FINISHED
2013-08-06 12:56:38,063 INFO org.apache.hadoop.yarn.server.resourcemanager.RMAuditLogger: USER=ubuntu	OPERATION=AM Released Container	TARGET=SchedulerApp	RESULT=SUCCESS	APPID=application_1375792971633_0005	CONTAINERID=container_1375792971633_0005_01_000001
2013-08-06 12:56:38,064 INFO org.apache.hadoop.yarn.server.resourcemanager.scheduler.common.fica.FiCaSchedulerNode: Released container container_1375792971633_0005_01_000001 of capacity <memory:2048, vCores:1> on host hadoop-110-2:50749, which currently has 0 containers, <memory:0, vCores:0> used and <memory:8192, vCores:16> available, release resources=true
2013-08-06 12:56:38,064 INFO org.apache.hadoop.yarn.server.resourcemanager.RMAuditLogger: USER=ubuntu	OPERATION=Application Finished - Succeeded	TARGET=RMAppManager	RESULT=SUCCESS	APPID=application_1375792971633_0005
2013-08-06 12:56:38,064 INFO org.apache.hadoop.yarn.server.resourcemanager.scheduler.capacity.LeafQueue: default used=<memory:0, vCores:0> numContainers=0 user=ubuntu user-resources=<memory:0, vCores:0>
2013-08-06 12:56:38,064 INFO org.apache.hadoop.yarn.server.resourcemanager.RMAppManager$ApplicationSummary: appId=application_1375792971633_0005,name=TeraGen,user=ubuntu,queue=default,state=FINISHED,trackingUrl=hadoop-110-1.novalocal:8088/proxy/application_1375792971633_0005/jobhistory/job/job_1375792971633_0005,appMasterHost=hadoop-110-2,startTime=1375793667078,finishTime=1375793796810
2013-08-06 12:56:38,064 INFO org.apache.hadoop.yarn.server.resourcemanager.recovery.RMStateStore: Removing info for app: application_1375792971633_0005
2013-08-06 12:56:38,065 INFO org.apache.hadoop.yarn.server.resourcemanager.amlauncher.AMLauncher: Cleaning master appattempt_1375792971633_0005_000001
2013-08-06 12:56:38,067 INFO org.apache.hadoop.yarn.server.resourcemanager.scheduler.capacity.LeafQueue: completedContainer container=Container: [ContainerId: container_1375792971633_0005_01_000001, NodeId: hadoop-110-2:50749, NodeHttpAddress: hadoop-110-2:8042, Resource: <memory:2048, vCores:1>, Priority: 0, State: NEW, Token: null, Status: container_id {, app_attempt_id {, application_id {, id: 5, cluster_timestamp: 1375792971633, }, attemptId: 1, }, id: 1, }, state: C_COMPLETE, diagnostics: "", exit_status: 0, ] resource=<memory:2048, vCores:1> queue=default: capacity=1.0, absoluteCapacity=1.0, usedResources=<memory:0, vCores:0>usedCapacity=0.0, absoluteUsedCapacity=0.0, numApps=1, numContainers=0 usedCapacity=0.0 absoluteUsedCapacity=0.0 used=<memory:0, vCores:0> cluster=<memory:49152, vCores:96>
2013-08-06 12:56:38,067 INFO org.apache.hadoop.yarn.server.resourcemanager.scheduler.capacity.ParentQueue: completedContainer queue=root usedCapacity=0.0 absoluteUsedCapacity=0.0 used=<memory:0, vCores:0> cluster=<memory:49152, vCores:96>
2013-08-06 12:56:38,067 INFO org.apache.hadoop.yarn.server.resourcemanager.scheduler.capacity.CapacityScheduler: Application appattempt_1375792971633_0005_000001 released container container_1375792971633_0005_01_000001 on node: host: hadoop-110-2:50749 #containers=0 available=8192 used=0 with event: FINISHED
2013-08-06 12:56:38,067 INFO org.apache.hadoop.yarn.server.resourcemanager.scheduler.capacity.CapacityScheduler: Application appattempt_1375792971633_0005_000001 is done. finalState=FINISHED
2013-08-06 12:56:38,067 INFO org.apache.hadoop.yarn.server.resourcemanager.scheduler.AppSchedulingInfo: Application application_1375792971633_0005 requests cleared
2013-08-06 12:56:38,067 INFO org.apache.hadoop.yarn.server.resourcemanager.scheduler.capacity.LeafQueue: Application removed - appId: application_1375792971633_0005 user: ubuntu queue: default #user-pending-applications: 0 #user-active-applications: 0 #queue-pending-applications: 0 #queue-active-applications: 0
2013-08-06 12:56:38,067 INFO org.apache.hadoop.yarn.server.resourcemanager.scheduler.capacity.ParentQueue: Application removed - appId: application_1375792971633_0005 user: ubuntu leaf-queue of parent: root #applications: 0
2013-08-06 12:57:51,685 INFO org.apache.hadoop.yarn.server.resourcemanager.ClientRMService: Allocated new applicationId: 6
2013-08-06 12:57:51,979 INFO org.apache.hadoop.yarn.server.resourcemanager.ClientRMService: Allocated new applicationId: 7
2013-08-06 12:57:52,659 INFO org.apache.hadoop.yarn.server.resourcemanager.ClientRMService: Allocated new applicationId: 8
2013-08-06 12:57:52,803 INFO org.apache.hadoop.yarn.server.resourcemanager.ClientRMService: Allocated new applicationId: 9
2013-08-06 12:57:53,358 INFO org.apache.hadoop.yarn.server.resourcemanager.ClientRMService: Storing Application with id application_1375792971633_0006
2013-08-06 12:57:53,358 INFO org.apache.hadoop.yarn.server.resourcemanager.recovery.RMStateStore: Storing info for app: application_1375792971633_0006
2013-08-06 12:57:53,358 INFO org.apache.hadoop.yarn.server.resourcemanager.ClientRMService: Application with id 6 submitted by user ubuntu
2013-08-06 12:57:53,358 INFO org.apache.hadoop.yarn.server.resourcemanager.RMAuditLogger: USER=ubuntu	IP=192.168.100.2	OPERATION=Submit Application Request	TARGET=ClientRMService	RESULT=SUCCESS	APPID=application_1375792971633_0006
2013-08-06 12:57:53,359 INFO org.apache.hadoop.yarn.server.resourcemanager.rmapp.RMAppImpl: application_1375792971633_0006 State change from NEW to SUBMITTED
2013-08-06 12:57:53,360 INFO org.apache.hadoop.yarn.server.resourcemanager.ApplicationMasterService: Registering appattempt_1375792971633_0006_000001
2013-08-06 12:57:53,360 INFO org.apache.hadoop.yarn.server.resourcemanager.rmapp.attempt.RMAppAttemptImpl: appattempt_1375792971633_0006_000001 State change from NEW to SUBMITTED
2013-08-06 12:57:53,360 INFO org.apache.hadoop.yarn.server.resourcemanager.scheduler.capacity.LeafQueue: Application application_1375792971633_0006 from user: ubuntu activated in queue: default
2013-08-06 12:57:53,360 INFO org.apache.hadoop.yarn.server.resourcemanager.scheduler.capacity.LeafQueue: Application added - appId: application_1375792971633_0006 user: org.apache.hadoop.yarn.server.resourcemanager.scheduler.capacity.LeafQueue$User@2c61e736, leaf-queue: default #user-pending-applications: 0 #user-active-applications: 1 #queue-pending-applications: 0 #queue-active-applications: 1
2013-08-06 12:57:53,360 INFO org.apache.hadoop.yarn.server.resourcemanager.scheduler.capacity.ParentQueue: Application added - appId: application_1375792971633_0006 user: ubuntu leaf-queue of parent: root #applications: 1
2013-08-06 12:57:53,360 INFO org.apache.hadoop.yarn.server.resourcemanager.scheduler.capacity.CapacityScheduler: Application Submission: appattempt_1375792971633_0006_000001, user: ubuntu queue: default: capacity=1.0, absoluteCapacity=1.0, usedResources=<memory:0, vCores:0>usedCapacity=0.0, absoluteUsedCapacity=0.0, numApps=1, numContainers=0, currently active: 1
2013-08-06 12:57:53,364 INFO org.apache.hadoop.yarn.server.resourcemanager.rmapp.attempt.RMAppAttemptImpl: appattempt_1375792971633_0006_000001 State change from SUBMITTED to SCHEDULED
2013-08-06 12:57:53,364 INFO org.apache.hadoop.yarn.server.resourcemanager.rmapp.RMAppImpl: application_1375792971633_0006 State change from SUBMITTED to ACCEPTED
2013-08-06 12:57:53,537 INFO org.apache.hadoop.yarn.server.resourcemanager.ClientRMService: Allocated new applicationId: 10
2013-08-06 12:57:53,563 INFO org.apache.hadoop.yarn.server.resourcemanager.rmcontainer.RMContainerImpl: container_1375792971633_0006_01_000001 Container Transitioned from NEW to ALLOCATED
2013-08-06 12:57:53,563 INFO org.apache.hadoop.yarn.server.resourcemanager.RMAuditLogger: USER=ubuntu	OPERATION=AM Allocated Container	TARGET=SchedulerApp	RESULT=SUCCESS	APPID=application_1375792971633_0006	CONTAINERID=container_1375792971633_0006_01_000001
2013-08-06 12:57:53,563 INFO org.apache.hadoop.yarn.server.resourcemanager.scheduler.common.fica.FiCaSchedulerNode: Assigned container container_1375792971633_0006_01_000001 of capacity <memory:2048, vCores:1> on host hadoop-110-4:59955, which currently has 1 containers, <memory:2048, vCores:1> used and <memory:6144, vCores:15> available
2013-08-06 12:57:53,564 INFO org.apache.hadoop.yarn.server.resourcemanager.scheduler.capacity.LeafQueue: assignedContainer application=application_1375792971633_0006 container=Container: [ContainerId: container_1375792971633_0006_01_000001, NodeId: hadoop-110-4:59955, NodeHttpAddress: hadoop-110-4:8042, Resource: <memory:2048, vCores:1>, Priority: 0, State: NEW, Token: null, Status: container_id {, app_attempt_id {, application_id {, id: 6, cluster_timestamp: 1375792971633, }, attemptId: 1, }, id: 1, }, state: C_NEW, ] containerId=container_1375792971633_0006_01_000001 queue=default: capacity=1.0, absoluteCapacity=1.0, usedResources=<memory:0, vCores:0>usedCapacity=0.0, absoluteUsedCapacity=0.0, numApps=1, numContainers=0 usedCapacity=0.0 absoluteUsedCapacity=0.0 used=<memory:0, vCores:0> cluster=<memory:49152, vCores:96>
2013-08-06 12:57:53,564 INFO org.apache.hadoop.yarn.server.resourcemanager.scheduler.capacity.ParentQueue: Re-sorting queues since queue: root.default stats: default: capacity=1.0, absoluteCapacity=1.0, usedResources=<memory:2048, vCores:1>usedCapacity=0.041666668, absoluteUsedCapacity=0.041666668, numApps=1, numContainers=1
2013-08-06 12:57:53,565 INFO org.apache.hadoop.yarn.server.resourcemanager.scheduler.capacity.ParentQueue: assignedContainer queue=root usedCapacity=0.041666668 absoluteUsedCapacity=0.041666668 used=<memory:2048, vCores:1> cluster=<memory:49152, vCores:96>
2013-08-06 12:57:53,564 INFO org.apache.hadoop.yarn.server.resourcemanager.rmcontainer.RMContainerImpl: container_1375792971633_0006_01_000001 Container Transitioned from ALLOCATED to ACQUIRED
2013-08-06 12:57:53,566 INFO org.apache.hadoop.yarn.server.resourcemanager.rmapp.attempt.RMAppAttemptImpl: Storing attempt: AppId: application_1375792971633_0006 AttemptId: appattempt_1375792971633_0006_000001 MasterContainer: Container: [ContainerId: container_1375792971633_0006_01_000001, NodeId: hadoop-110-4:59955, NodeHttpAddress: hadoop-110-4:8042, Resource: <memory:2048, vCores:1>, Priority: 0, State: NEW, Token: null, Status: container_id {, app_attempt_id {, application_id {, id: 6, cluster_timestamp: 1375792971633, }, attemptId: 1, }, id: 1, }, state: C_NEW, ]
2013-08-06 12:57:53,566 INFO org.apache.hadoop.yarn.server.resourcemanager.recovery.RMStateStore: Storing info for attempt: appattempt_1375792971633_0006_000001
2013-08-06 12:57:53,566 INFO org.apache.hadoop.yarn.server.resourcemanager.rmapp.attempt.RMAppAttemptImpl: appattempt_1375792971633_0006_000001 State change from SCHEDULED to ALLOCATED_SAVING
2013-08-06 12:57:53,567 INFO org.apache.hadoop.yarn.server.resourcemanager.rmapp.attempt.RMAppAttemptImpl: appattempt_1375792971633_0006_000001 State change from ALLOCATED_SAVING to ALLOCATED
2013-08-06 12:57:53,567 INFO org.apache.hadoop.yarn.server.resourcemanager.amlauncher.AMLauncher: Launching masterappattempt_1375792971633_0006_000001
2013-08-06 12:57:53,568 INFO org.apache.hadoop.yarn.server.resourcemanager.amlauncher.AMLauncher: Setting up container Container: [ContainerId: container_1375792971633_0006_01_000001, NodeId: hadoop-110-4:59955, NodeHttpAddress: hadoop-110-4:8042, Resource: <memory:2048, vCores:1>, Priority: 0, State: NEW, Token: null, Status: container_id {, app_attempt_id {, application_id {, id: 6, cluster_timestamp: 1375792971633, }, attemptId: 1, }, id: 1, }, state: C_NEW, ] for AM appattempt_1375792971633_0006_000001
2013-08-06 12:57:53,568 INFO org.apache.hadoop.yarn.server.resourcemanager.amlauncher.AMLauncher: Command to launch container container_1375792971633_0006_01_000001 : $JAVA_HOME/bin/java -Dlog4j.configuration=container-log4j.properties -Dyarn.app.mapreduce.container.log.dir=<LOG_DIR> -Dyarn.app.mapreduce.container.log.filesize=0 -Dhadoop.root.logger=INFO,CLA  -Xmx1024m org.apache.hadoop.mapreduce.v2.app.MRAppMaster 1><LOG_DIR>/stdout 2><LOG_DIR>/stderr 
2013-08-06 12:57:53,598 INFO org.apache.hadoop.yarn.server.resourcemanager.amlauncher.AMLauncher: Done launching container Container: [ContainerId: container_1375792971633_0006_01_000001, NodeId: hadoop-110-4:59955, NodeHttpAddress: hadoop-110-4:8042, Resource: <memory:2048, vCores:1>, Priority: 0, State: NEW, Token: null, Status: container_id {, app_attempt_id {, application_id {, id: 6, cluster_timestamp: 1375792971633, }, attemptId: 1, }, id: 1, }, state: C_NEW, ] for AM appattempt_1375792971633_0006_000001
2013-08-06 12:57:53,599 INFO org.apache.hadoop.yarn.server.resourcemanager.rmapp.attempt.RMAppAttemptImpl: appattempt_1375792971633_0006_000001 State change from ALLOCATED to LAUNCHED
2013-08-06 12:57:53,657 INFO org.apache.hadoop.yarn.server.resourcemanager.ClientRMService: Storing Application with id application_1375792971633_0007
2013-08-06 12:57:53,657 INFO org.apache.hadoop.yarn.server.resourcemanager.recovery.RMStateStore: Storing info for app: application_1375792971633_0007
2013-08-06 12:57:53,657 INFO org.apache.hadoop.yarn.server.resourcemanager.ClientRMService: Application with id 7 submitted by user ubuntu
2013-08-06 12:57:53,657 INFO org.apache.hadoop.yarn.server.resourcemanager.RMAuditLogger: USER=ubuntu	IP=192.168.100.2	OPERATION=Submit Application Request	TARGET=ClientRMService	RESULT=SUCCESS	APPID=application_1375792971633_0007
2013-08-06 12:57:53,658 INFO org.apache.hadoop.yarn.server.resourcemanager.rmapp.RMAppImpl: application_1375792971633_0007 State change from NEW to SUBMITTED
2013-08-06 12:57:53,658 INFO org.apache.hadoop.yarn.server.resourcemanager.ApplicationMasterService: Registering appattempt_1375792971633_0007_000001
2013-08-06 12:57:53,658 INFO org.apache.hadoop.yarn.server.resourcemanager.rmapp.attempt.RMAppAttemptImpl: appattempt_1375792971633_0007_000001 State change from NEW to SUBMITTED
2013-08-06 12:57:53,662 INFO org.apache.hadoop.yarn.server.resourcemanager.scheduler.capacity.LeafQueue: Application application_1375792971633_0007 from user: ubuntu activated in queue: default
2013-08-06 12:57:53,662 INFO org.apache.hadoop.yarn.server.resourcemanager.scheduler.capacity.LeafQueue: Application added - appId: application_1375792971633_0007 user: org.apache.hadoop.yarn.server.resourcemanager.scheduler.capacity.LeafQueue$User@2c61e736, leaf-queue: default #user-pending-applications: 0 #user-active-applications: 2 #queue-pending-applications: 0 #queue-active-applications: 2
2013-08-06 12:57:53,662 INFO org.apache.hadoop.yarn.server.resourcemanager.scheduler.capacity.ParentQueue: Application added - appId: application_1375792971633_0007 user: ubuntu leaf-queue of parent: root #applications: 2
2013-08-06 12:57:53,662 INFO org.apache.hadoop.yarn.server.resourcemanager.scheduler.capacity.CapacityScheduler: Application Submission: appattempt_1375792971633_0007_000001, user: ubuntu queue: default: capacity=1.0, absoluteCapacity=1.0, usedResources=<memory:2048, vCores:1>usedCapacity=0.041666668, absoluteUsedCapacity=0.041666668, numApps=2, numContainers=1, currently active: 2
2013-08-06 12:57:53,662 INFO org.apache.hadoop.yarn.server.resourcemanager.rmapp.attempt.RMAppAttemptImpl: appattempt_1375792971633_0007_000001 State change from SUBMITTED to SCHEDULED
2013-08-06 12:57:53,662 INFO org.apache.hadoop.yarn.server.resourcemanager.rmapp.RMAppImpl: application_1375792971633_0007 State change from SUBMITTED to ACCEPTED
2013-08-06 12:57:53,665 INFO org.apache.hadoop.yarn.server.resourcemanager.rmcontainer.RMContainerImpl: container_1375792971633_0007_01_000001 Container Transitioned from NEW to ALLOCATED
2013-08-06 12:57:53,665 INFO org.apache.hadoop.yarn.server.resourcemanager.RMAuditLogger: USER=ubuntu	OPERATION=AM Allocated Container	TARGET=SchedulerApp	RESULT=SUCCESS	APPID=application_1375792971633_0007	CONTAINERID=container_1375792971633_0007_01_000001
2013-08-06 12:57:53,665 INFO org.apache.hadoop.yarn.server.resourcemanager.scheduler.common.fica.FiCaSchedulerNode: Assigned container container_1375792971633_0007_01_000001 of capacity <memory:2048, vCores:1> on host hadoop-110-3:34727, which currently has 1 containers, <memory:2048, vCores:1> used and <memory:6144, vCores:15> available
2013-08-06 12:57:53,666 INFO org.apache.hadoop.yarn.server.resourcemanager.scheduler.capacity.LeafQueue: assignedContainer application=application_1375792971633_0007 container=Container: [ContainerId: container_1375792971633_0007_01_000001, NodeId: hadoop-110-3:34727, NodeHttpAddress: hadoop-110-3:8042, Resource: <memory:2048, vCores:1>, Priority: 0, State: NEW, Token: null, Status: container_id {, app_attempt_id {, application_id {, id: 7, cluster_timestamp: 1375792971633, }, attemptId: 1, }, id: 1, }, state: C_NEW, ] containerId=container_1375792971633_0007_01_000001 queue=default: capacity=1.0, absoluteCapacity=1.0, usedResources=<memory:2048, vCores:1>usedCapacity=0.041666668, absoluteUsedCapacity=0.041666668, numApps=2, numContainers=1 usedCapacity=0.041666668 absoluteUsedCapacity=0.041666668 used=<memory:2048, vCores:1> cluster=<memory:49152, vCores:96>
2013-08-06 12:57:53,666 INFO org.apache.hadoop.yarn.server.resourcemanager.scheduler.capacity.ParentQueue: Re-sorting queues since queue: root.default stats: default: capacity=1.0, absoluteCapacity=1.0, usedResources=<memory:4096, vCores:2>usedCapacity=0.083333336, absoluteUsedCapacity=0.083333336, numApps=2, numContainers=2
2013-08-06 12:57:53,666 INFO org.apache.hadoop.yarn.server.resourcemanager.rmcontainer.RMContainerImpl: container_1375792971633_0007_01_000001 Container Transitioned from ALLOCATED to ACQUIRED
2013-08-06 12:57:53,667 INFO org.apache.hadoop.yarn.server.resourcemanager.rmapp.attempt.RMAppAttemptImpl: Storing attempt: AppId: application_1375792971633_0007 AttemptId: appattempt_1375792971633_0007_000001 MasterContainer: Container: [ContainerId: container_1375792971633_0007_01_000001, NodeId: hadoop-110-3:34727, NodeHttpAddress: hadoop-110-3:8042, Resource: <memory:2048, vCores:1>, Priority: 0, State: NEW, Token: null, Status: container_id {, app_attempt_id {, application_id {, id: 7, cluster_timestamp: 1375792971633, }, attemptId: 1, }, id: 1, }, state: C_NEW, ]
2013-08-06 12:57:53,667 INFO org.apache.hadoop.yarn.server.resourcemanager.rmapp.attempt.RMAppAttemptImpl: appattempt_1375792971633_0007_000001 State change from SCHEDULED to ALLOCATED_SAVING
2013-08-06 12:57:53,667 INFO org.apache.hadoop.yarn.server.resourcemanager.recovery.RMStateStore: Storing info for attempt: appattempt_1375792971633_0007_000001
2013-08-06 12:57:53,676 INFO org.apache.hadoop.yarn.server.resourcemanager.scheduler.capacity.ParentQueue: assignedContainer queue=root usedCapacity=0.083333336 absoluteUsedCapacity=0.083333336 used=<memory:4096, vCores:2> cluster=<memory:49152, vCores:96>
2013-08-06 12:57:53,676 INFO org.apache.hadoop.yarn.server.resourcemanager.rmapp.attempt.RMAppAttemptImpl: appattempt_1375792971633_0007_000001 State change from ALLOCATED_SAVING to ALLOCATED
2013-08-06 12:57:53,676 INFO org.apache.hadoop.yarn.server.resourcemanager.amlauncher.AMLauncher: Launching masterappattempt_1375792971633_0007_000001
2013-08-06 12:57:53,678 INFO org.apache.hadoop.yarn.server.resourcemanager.amlauncher.AMLauncher: Setting up container Container: [ContainerId: container_1375792971633_0007_01_000001, NodeId: hadoop-110-3:34727, NodeHttpAddress: hadoop-110-3:8042, Resource: <memory:2048, vCores:1>, Priority: 0, State: NEW, Token: null, Status: container_id {, app_attempt_id {, application_id {, id: 7, cluster_timestamp: 1375792971633, }, attemptId: 1, }, id: 1, }, state: C_NEW, ] for AM appattempt_1375792971633_0007_000001
2013-08-06 12:57:53,678 INFO org.apache.hadoop.yarn.server.resourcemanager.amlauncher.AMLauncher: Command to launch container container_1375792971633_0007_01_000001 : $JAVA_HOME/bin/java -Dlog4j.configuration=container-log4j.properties -Dyarn.app.mapreduce.container.log.dir=<LOG_DIR> -Dyarn.app.mapreduce.container.log.filesize=0 -Dhadoop.root.logger=INFO,CLA  -Xmx1024m org.apache.hadoop.mapreduce.v2.app.MRAppMaster 1><LOG_DIR>/stdout 2><LOG_DIR>/stderr 
2013-08-06 12:57:53,707 INFO org.apache.hadoop.yarn.server.resourcemanager.amlauncher.AMLauncher: Done launching container Container: [ContainerId: container_1375792971633_0007_01_000001, NodeId: hadoop-110-3:34727, NodeHttpAddress: hadoop-110-3:8042, Resource: <memory:2048, vCores:1>, Priority: 0, State: NEW, Token: null, Status: container_id {, app_attempt_id {, application_id {, id: 7, cluster_timestamp: 1375792971633, }, attemptId: 1, }, id: 1, }, state: C_NEW, ] for AM appattempt_1375792971633_0007_000001
2013-08-06 12:57:53,707 INFO org.apache.hadoop.yarn.server.resourcemanager.rmapp.attempt.RMAppAttemptImpl: appattempt_1375792971633_0007_000001 State change from ALLOCATED to LAUNCHED
2013-08-06 12:57:54,197 INFO org.apache.hadoop.yarn.server.resourcemanager.ClientRMService: Storing Application with id application_1375792971633_0008
2013-08-06 12:57:54,198 INFO org.apache.hadoop.yarn.server.resourcemanager.rmapp.RMAppImpl: application_1375792971633_0008 State change from NEW to SUBMITTED
2013-08-06 12:57:54,198 INFO org.apache.hadoop.yarn.server.resourcemanager.recovery.RMStateStore: Storing info for app: application_1375792971633_0008
2013-08-06 12:57:54,199 INFO org.apache.hadoop.yarn.server.resourcemanager.ApplicationMasterService: Registering appattempt_1375792971633_0008_000001
2013-08-06 12:57:54,199 INFO org.apache.hadoop.yarn.server.resourcemanager.ClientRMService: Application with id 8 submitted by user ubuntu
2013-08-06 12:57:54,199 INFO org.apache.hadoop.yarn.server.resourcemanager.rmapp.attempt.RMAppAttemptImpl: appattempt_1375792971633_0008_000001 State change from NEW to SUBMITTED
2013-08-06 12:57:54,199 INFO org.apache.hadoop.yarn.server.resourcemanager.RMAuditLogger: USER=ubuntu	IP=192.168.100.2	OPERATION=Submit Application Request	TARGET=ClientRMService	RESULT=SUCCESS	APPID=application_1375792971633_0008
2013-08-06 12:57:54,199 INFO org.apache.hadoop.yarn.server.resourcemanager.scheduler.capacity.LeafQueue: Application application_1375792971633_0008 from user: ubuntu activated in queue: default
2013-08-06 12:57:54,199 INFO org.apache.hadoop.yarn.server.resourcemanager.scheduler.capacity.LeafQueue: Application added - appId: application_1375792971633_0008 user: org.apache.hadoop.yarn.server.resourcemanager.scheduler.capacity.LeafQueue$User@2c61e736, leaf-queue: default #user-pending-applications: 0 #user-active-applications: 3 #queue-pending-applications: 0 #queue-active-applications: 3
2013-08-06 12:57:54,200 INFO org.apache.hadoop.yarn.server.resourcemanager.scheduler.capacity.ParentQueue: Application added - appId: application_1375792971633_0008 user: ubuntu leaf-queue of parent: root #applications: 3
2013-08-06 12:57:54,200 INFO org.apache.hadoop.yarn.server.resourcemanager.scheduler.capacity.CapacityScheduler: Application Submission: appattempt_1375792971633_0008_000001, user: ubuntu queue: default: capacity=1.0, absoluteCapacity=1.0, usedResources=<memory:4096, vCores:2>usedCapacity=0.083333336, absoluteUsedCapacity=0.083333336, numApps=3, numContainers=2, currently active: 3
2013-08-06 12:57:54,200 INFO org.apache.hadoop.yarn.server.resourcemanager.rmapp.attempt.RMAppAttemptImpl: appattempt_1375792971633_0008_000001 State change from SUBMITTED to SCHEDULED
2013-08-06 12:57:54,200 INFO org.apache.hadoop.yarn.server.resourcemanager.rmapp.RMAppImpl: application_1375792971633_0008 State change from SUBMITTED to ACCEPTED
2013-08-06 12:57:54,224 INFO org.apache.hadoop.yarn.server.resourcemanager.rmcontainer.RMContainerImpl: container_1375792971633_0008_01_000001 Container Transitioned from NEW to ALLOCATED
2013-08-06 12:57:54,224 INFO org.apache.hadoop.yarn.server.resourcemanager.RMAuditLogger: USER=ubuntu	OPERATION=AM Allocated Container	TARGET=SchedulerApp	RESULT=SUCCESS	APPID=application_1375792971633_0008	CONTAINERID=container_1375792971633_0008_01_000001
2013-08-06 12:57:54,224 INFO org.apache.hadoop.yarn.server.resourcemanager.scheduler.common.fica.FiCaSchedulerNode: Assigned container container_1375792971633_0008_01_000001 of capacity <memory:2048, vCores:1> on host hadoop-110-6:50003, which currently has 1 containers, <memory:2048, vCores:1> used and <memory:6144, vCores:15> available
2013-08-06 12:57:54,226 INFO org.apache.hadoop.yarn.server.resourcemanager.scheduler.capacity.LeafQueue: assignedContainer application=application_1375792971633_0008 container=Container: [ContainerId: container_1375792971633_0008_01_000001, NodeId: hadoop-110-6:50003, NodeHttpAddress: hadoop-110-6:8042, Resource: <memory:2048, vCores:1>, Priority: 0, State: NEW, Token: null, Status: container_id {, app_attempt_id {, application_id {, id: 8, cluster_timestamp: 1375792971633, }, attemptId: 1, }, id: 1, }, state: C_NEW, ] containerId=container_1375792971633_0008_01_000001 queue=default: capacity=1.0, absoluteCapacity=1.0, usedResources=<memory:4096, vCores:2>usedCapacity=0.083333336, absoluteUsedCapacity=0.083333336, numApps=3, numContainers=2 usedCapacity=0.083333336 absoluteUsedCapacity=0.083333336 used=<memory:4096, vCores:2> cluster=<memory:49152, vCores:96>
2013-08-06 12:57:54,226 INFO org.apache.hadoop.yarn.server.resourcemanager.scheduler.capacity.ParentQueue: Re-sorting queues since queue: root.default stats: default: capacity=1.0, absoluteCapacity=1.0, usedResources=<memory:6144, vCores:3>usedCapacity=0.125, absoluteUsedCapacity=0.125, numApps=3, numContainers=3
2013-08-06 12:57:54,226 INFO org.apache.hadoop.yarn.server.resourcemanager.scheduler.capacity.ParentQueue: assignedContainer queue=root usedCapacity=0.125 absoluteUsedCapacity=0.125 used=<memory:6144, vCores:3> cluster=<memory:49152, vCores:96>
2013-08-06 12:57:54,227 INFO org.apache.hadoop.yarn.server.resourcemanager.rmcontainer.RMContainerImpl: container_1375792971633_0008_01_000001 Container Transitioned from ALLOCATED to ACQUIRED
2013-08-06 12:57:54,228 INFO org.apache.hadoop.yarn.server.resourcemanager.rmapp.attempt.RMAppAttemptImpl: Storing attempt: AppId: application_1375792971633_0008 AttemptId: appattempt_1375792971633_0008_000001 MasterContainer: Container: [ContainerId: container_1375792971633_0008_01_000001, NodeId: hadoop-110-6:50003, NodeHttpAddress: hadoop-110-6:8042, Resource: <memory:2048, vCores:1>, Priority: 0, State: NEW, Token: null, Status: container_id {, app_attempt_id {, application_id {, id: 8, cluster_timestamp: 1375792971633, }, attemptId: 1, }, id: 1, }, state: C_NEW, ]
2013-08-06 12:57:54,228 INFO org.apache.hadoop.yarn.server.resourcemanager.rmapp.attempt.RMAppAttemptImpl: appattempt_1375792971633_0008_000001 State change from SCHEDULED to ALLOCATED_SAVING
2013-08-06 12:57:54,228 INFO org.apache.hadoop.yarn.server.resourcemanager.recovery.RMStateStore: Storing info for attempt: appattempt_1375792971633_0008_000001
2013-08-06 12:57:54,234 INFO org.apache.hadoop.yarn.server.resourcemanager.rmapp.attempt.RMAppAttemptImpl: appattempt_1375792971633_0008_000001 State change from ALLOCATED_SAVING to ALLOCATED
2013-08-06 12:57:54,234 INFO org.apache.hadoop.yarn.server.resourcemanager.amlauncher.AMLauncher: Launching masterappattempt_1375792971633_0008_000001
2013-08-06 12:57:54,235 INFO org.apache.hadoop.yarn.server.resourcemanager.amlauncher.AMLauncher: Setting up container Container: [ContainerId: container_1375792971633_0008_01_000001, NodeId: hadoop-110-6:50003, NodeHttpAddress: hadoop-110-6:8042, Resource: <memory:2048, vCores:1>, Priority: 0, State: NEW, Token: null, Status: container_id {, app_attempt_id {, application_id {, id: 8, cluster_timestamp: 1375792971633, }, attemptId: 1, }, id: 1, }, state: C_NEW, ] for AM appattempt_1375792971633_0008_000001
2013-08-06 12:57:54,235 INFO org.apache.hadoop.yarn.server.resourcemanager.amlauncher.AMLauncher: Command to launch container container_1375792971633_0008_01_000001 : $JAVA_HOME/bin/java -Dlog4j.configuration=container-log4j.properties -Dyarn.app.mapreduce.container.log.dir=<LOG_DIR> -Dyarn.app.mapreduce.container.log.filesize=0 -Dhadoop.root.logger=INFO,CLA  -Xmx1024m org.apache.hadoop.mapreduce.v2.app.MRAppMaster 1><LOG_DIR>/stdout 2><LOG_DIR>/stderr 
2013-08-06 12:57:54,254 INFO org.apache.hadoop.yarn.server.resourcemanager.amlauncher.AMLauncher: Done launching container Container: [ContainerId: container_1375792971633_0008_01_000001, NodeId: hadoop-110-6:50003, NodeHttpAddress: hadoop-110-6:8042, Resource: <memory:2048, vCores:1>, Priority: 0, State: NEW, Token: null, Status: container_id {, app_attempt_id {, application_id {, id: 8, cluster_timestamp: 1375792971633, }, attemptId: 1, }, id: 1, }, state: C_NEW, ] for AM appattempt_1375792971633_0008_000001
2013-08-06 12:57:54,254 INFO org.apache.hadoop.yarn.server.resourcemanager.rmapp.attempt.RMAppAttemptImpl: appattempt_1375792971633_0008_000001 State change from ALLOCATED to LAUNCHED
2013-08-06 12:57:54,366 INFO org.apache.hadoop.yarn.server.resourcemanager.ClientRMService: Storing Application with id application_1375792971633_0009
2013-08-06 12:57:54,368 INFO org.apache.hadoop.yarn.server.resourcemanager.recovery.RMStateStore: Storing info for app: application_1375792971633_0009
2013-08-06 12:57:54,368 INFO org.apache.hadoop.yarn.server.resourcemanager.ClientRMService: Application with id 9 submitted by user ubuntu
2013-08-06 12:57:54,368 INFO org.apache.hadoop.yarn.server.resourcemanager.RMAuditLogger: USER=ubuntu	IP=192.168.100.2	OPERATION=Submit Application Request	TARGET=ClientRMService	RESULT=SUCCESS	APPID=application_1375792971633_0009
2013-08-06 12:57:54,369 INFO org.apache.hadoop.yarn.server.resourcemanager.rmapp.RMAppImpl: application_1375792971633_0009 State change from NEW to SUBMITTED
2013-08-06 12:57:54,369 INFO org.apache.hadoop.yarn.server.resourcemanager.ApplicationMasterService: Registering appattempt_1375792971633_0009_000001
2013-08-06 12:57:54,369 INFO org.apache.hadoop.yarn.server.resourcemanager.rmapp.attempt.RMAppAttemptImpl: appattempt_1375792971633_0009_000001 State change from NEW to SUBMITTED
2013-08-06 12:57:54,369 INFO org.apache.hadoop.yarn.server.resourcemanager.scheduler.capacity.LeafQueue: Application application_1375792971633_0009 from user: ubuntu activated in queue: default
2013-08-06 12:57:54,370 INFO org.apache.hadoop.yarn.server.resourcemanager.scheduler.capacity.LeafQueue: Application added - appId: application_1375792971633_0009 user: org.apache.hadoop.yarn.server.resourcemanager.scheduler.capacity.LeafQueue$User@2c61e736, leaf-queue: default #user-pending-applications: 0 #user-active-applications: 4 #queue-pending-applications: 0 #queue-active-applications: 4
2013-08-06 12:57:54,370 INFO org.apache.hadoop.yarn.server.resourcemanager.scheduler.capacity.ParentQueue: Application added - appId: application_1375792971633_0009 user: ubuntu leaf-queue of parent: root #applications: 4
2013-08-06 12:57:54,370 INFO org.apache.hadoop.yarn.server.resourcemanager.scheduler.capacity.CapacityScheduler: Application Submission: appattempt_1375792971633_0009_000001, user: ubuntu queue: default: capacity=1.0, absoluteCapacity=1.0, usedResources=<memory:6144, vCores:3>usedCapacity=0.125, absoluteUsedCapacity=0.125, numApps=4, numContainers=3, currently active: 4
2013-08-06 12:57:54,373 INFO org.apache.hadoop.yarn.server.resourcemanager.rmapp.attempt.RMAppAttemptImpl: appattempt_1375792971633_0009_000001 State change from SUBMITTED to SCHEDULED
2013-08-06 12:57:54,373 INFO org.apache.hadoop.yarn.server.resourcemanager.rmapp.RMAppImpl: application_1375792971633_0009 State change from SUBMITTED to ACCEPTED
2013-08-06 12:57:54,566 INFO org.apache.hadoop.yarn.server.resourcemanager.rmcontainer.RMContainerImpl: container_1375792971633_0006_01_000001 Container Transitioned from ACQUIRED to RUNNING
2013-08-06 12:57:54,567 INFO org.apache.hadoop.yarn.server.resourcemanager.rmcontainer.RMContainerImpl: container_1375792971633_0009_01_000001 Container Transitioned from NEW to ALLOCATED
2013-08-06 12:57:54,567 INFO org.apache.hadoop.yarn.server.resourcemanager.RMAuditLogger: USER=ubuntu	OPERATION=AM Allocated Container	TARGET=SchedulerApp	RESULT=SUCCESS	APPID=application_1375792971633_0009	CONTAINERID=container_1375792971633_0009_01_000001
2013-08-06 12:57:54,567 INFO org.apache.hadoop.yarn.server.resourcemanager.scheduler.common.fica.FiCaSchedulerNode: Assigned container container_1375792971633_0009_01_000001 of capacity <memory:2048, vCores:1> on host hadoop-110-4:59955, which currently has 2 containers, <memory:4096, vCores:2> used and <memory:4096, vCores:14> available
2013-08-06 12:57:54,568 INFO org.apache.hadoop.yarn.server.resourcemanager.scheduler.capacity.LeafQueue: assignedContainer application=application_1375792971633_0009 container=Container: [ContainerId: container_1375792971633_0009_01_000001, NodeId: hadoop-110-4:59955, NodeHttpAddress: hadoop-110-4:8042, Resource: <memory:2048, vCores:1>, Priority: 0, State: NEW, Token: null, Status: container_id {, app_attempt_id {, application_id {, id: 9, cluster_timestamp: 1375792971633, }, attemptId: 1, }, id: 1, }, state: C_NEW, ] containerId=container_1375792971633_0009_01_000001 queue=default: capacity=1.0, absoluteCapacity=1.0, usedResources=<memory:6144, vCores:3>usedCapacity=0.125, absoluteUsedCapacity=0.125, numApps=4, numContainers=3 usedCapacity=0.125 absoluteUsedCapacity=0.125 used=<memory:6144, vCores:3> cluster=<memory:49152, vCores:96>
2013-08-06 12:57:54,569 INFO org.apache.hadoop.yarn.server.resourcemanager.scheduler.capacity.ParentQueue: Re-sorting queues since queue: root.default stats: default: capacity=1.0, absoluteCapacity=1.0, usedResources=<memory:8192, vCores:4>usedCapacity=0.16666667, absoluteUsedCapacity=0.16666667, numApps=4, numContainers=4
2013-08-06 12:57:54,570 INFO org.apache.hadoop.yarn.server.resourcemanager.scheduler.capacity.ParentQueue: assignedContainer queue=root usedCapacity=0.16666667 absoluteUsedCapacity=0.16666667 used=<memory:8192, vCores:4> cluster=<memory:49152, vCores:96>
2013-08-06 12:57:54,570 INFO org.apache.hadoop.yarn.server.resourcemanager.rmcontainer.RMContainerImpl: container_1375792971633_0009_01_000001 Container Transitioned from ALLOCATED to ACQUIRED
2013-08-06 12:57:54,572 INFO org.apache.hadoop.yarn.server.resourcemanager.rmapp.attempt.RMAppAttemptImpl: Storing attempt: AppId: application_1375792971633_0009 AttemptId: appattempt_1375792971633_0009_000001 MasterContainer: Container: [ContainerId: container_1375792971633_0009_01_000001, NodeId: hadoop-110-4:59955, NodeHttpAddress: hadoop-110-4:8042, Resource: <memory:2048, vCores:1>, Priority: 0, State: NEW, Token: null, Status: container_id {, app_attempt_id {, application_id {, id: 9, cluster_timestamp: 1375792971633, }, attemptId: 1, }, id: 1, }, state: C_NEW, ]
2013-08-06 12:57:54,572 INFO org.apache.hadoop.yarn.server.resourcemanager.rmapp.attempt.RMAppAttemptImpl: appattempt_1375792971633_0009_000001 State change from SCHEDULED to ALLOCATED_SAVING
2013-08-06 12:57:54,572 INFO org.apache.hadoop.yarn.server.resourcemanager.recovery.RMStateStore: Storing info for attempt: appattempt_1375792971633_0009_000001
2013-08-06 12:57:54,574 INFO org.apache.hadoop.yarn.server.resourcemanager.rmapp.attempt.RMAppAttemptImpl: appattempt_1375792971633_0009_000001 State change from ALLOCATED_SAVING to ALLOCATED
2013-08-06 12:57:54,574 INFO org.apache.hadoop.yarn.server.resourcemanager.amlauncher.AMLauncher: Launching masterappattempt_1375792971633_0009_000001
2013-08-06 12:57:54,576 INFO org.apache.hadoop.yarn.server.resourcemanager.amlauncher.AMLauncher: Setting up container Container: [ContainerId: container_1375792971633_0009_01_000001, NodeId: hadoop-110-4:59955, NodeHttpAddress: hadoop-110-4:8042, Resource: <memory:2048, vCores:1>, Priority: 0, State: NEW, Token: null, Status: container_id {, app_attempt_id {, application_id {, id: 9, cluster_timestamp: 1375792971633, }, attemptId: 1, }, id: 1, }, state: C_NEW, ] for AM appattempt_1375792971633_0009_000001
2013-08-06 12:57:54,576 INFO org.apache.hadoop.yarn.server.resourcemanager.amlauncher.AMLauncher: Command to launch container container_1375792971633_0009_01_000001 : $JAVA_HOME/bin/java -Dlog4j.configuration=container-log4j.properties -Dyarn.app.mapreduce.container.log.dir=<LOG_DIR> -Dyarn.app.mapreduce.container.log.filesize=0 -Dhadoop.root.logger=INFO,CLA  -Xmx1024m org.apache.hadoop.mapreduce.v2.app.MRAppMaster 1><LOG_DIR>/stdout 2><LOG_DIR>/stderr 
2013-08-06 12:57:54,589 INFO org.apache.hadoop.yarn.server.resourcemanager.amlauncher.AMLauncher: Done launching container Container: [ContainerId: container_1375792971633_0009_01_000001, NodeId: hadoop-110-4:59955, NodeHttpAddress: hadoop-110-4:8042, Resource: <memory:2048, vCores:1>, Priority: 0, State: NEW, Token: null, Status: container_id {, app_attempt_id {, application_id {, id: 9, cluster_timestamp: 1375792971633, }, attemptId: 1, }, id: 1, }, state: C_NEW, ] for AM appattempt_1375792971633_0009_000001
2013-08-06 12:57:54,590 INFO org.apache.hadoop.yarn.server.resourcemanager.rmapp.attempt.RMAppAttemptImpl: appattempt_1375792971633_0009_000001 State change from ALLOCATED to LAUNCHED
2013-08-06 12:57:54,670 INFO org.apache.hadoop.yarn.server.resourcemanager.rmcontainer.RMContainerImpl: container_1375792971633_0007_01_000001 Container Transitioned from ACQUIRED to RUNNING
2013-08-06 12:57:54,959 INFO org.apache.hadoop.yarn.server.resourcemanager.ClientRMService: Storing Application with id application_1375792971633_0010
2013-08-06 12:57:54,960 INFO org.apache.hadoop.yarn.server.resourcemanager.recovery.RMStateStore: Storing info for app: application_1375792971633_0010
2013-08-06 12:57:54,960 INFO org.apache.hadoop.yarn.server.resourcemanager.ClientRMService: Application with id 10 submitted by user ubuntu
2013-08-06 12:57:54,960 INFO org.apache.hadoop.yarn.server.resourcemanager.RMAuditLogger: USER=ubuntu	IP=192.168.100.2	OPERATION=Submit Application Request	TARGET=ClientRMService	RESULT=SUCCESS	APPID=application_1375792971633_0010
2013-08-06 12:57:54,961 INFO org.apache.hadoop.yarn.server.resourcemanager.rmapp.RMAppImpl: application_1375792971633_0010 State change from NEW to SUBMITTED
2013-08-06 12:57:54,962 INFO org.apache.hadoop.yarn.server.resourcemanager.ApplicationMasterService: Registering appattempt_1375792971633_0010_000001
2013-08-06 12:57:54,962 INFO org.apache.hadoop.yarn.server.resourcemanager.rmapp.attempt.RMAppAttemptImpl: appattempt_1375792971633_0010_000001 State change from NEW to SUBMITTED
2013-08-06 12:57:54,963 INFO org.apache.hadoop.yarn.server.resourcemanager.scheduler.capacity.LeafQueue: Application application_1375792971633_0010 from user: ubuntu activated in queue: default
2013-08-06 12:57:54,963 INFO org.apache.hadoop.yarn.server.resourcemanager.scheduler.capacity.LeafQueue: Application added - appId: application_1375792971633_0010 user: org.apache.hadoop.yarn.server.resourcemanager.scheduler.capacity.LeafQueue$User@2c61e736, leaf-queue: default #user-pending-applications: 0 #user-active-applications: 5 #queue-pending-applications: 0 #queue-active-applications: 5
2013-08-06 12:57:54,963 INFO org.apache.hadoop.yarn.server.resourcemanager.scheduler.capacity.ParentQueue: Application added - appId: application_1375792971633_0010 user: ubuntu leaf-queue of parent: root #applications: 5
2013-08-06 12:57:54,963 INFO org.apache.hadoop.yarn.server.resourcemanager.scheduler.capacity.CapacityScheduler: Application Submission: appattempt_1375792971633_0010_000001, user: ubuntu queue: default: capacity=1.0, absoluteCapacity=1.0, usedResources=<memory:8192, vCores:4>usedCapacity=0.16666667, absoluteUsedCapacity=0.16666667, numApps=5, numContainers=4, currently active: 5
2013-08-06 12:57:54,963 INFO org.apache.hadoop.yarn.server.resourcemanager.rmapp.attempt.RMAppAttemptImpl: appattempt_1375792971633_0010_000001 State change from SUBMITTED to SCHEDULED
2013-08-06 12:57:54,964 INFO org.apache.hadoop.yarn.server.resourcemanager.rmapp.RMAppImpl: application_1375792971633_0010 State change from SUBMITTED to ACCEPTED
2013-08-06 12:57:55,047 INFO org.apache.hadoop.yarn.server.resourcemanager.rmcontainer.RMContainerImpl: container_1375792971633_0010_01_000001 Container Transitioned from NEW to ALLOCATED
2013-08-06 12:57:55,048 INFO org.apache.hadoop.yarn.server.resourcemanager.RMAuditLogger: USER=ubuntu	OPERATION=AM Allocated Container	TARGET=SchedulerApp	RESULT=SUCCESS	APPID=application_1375792971633_0010	CONTAINERID=container_1375792971633_0010_01_000001
2013-08-06 12:57:55,048 INFO org.apache.hadoop.yarn.server.resourcemanager.scheduler.common.fica.FiCaSchedulerNode: Assigned container container_1375792971633_0010_01_000001 of capacity <memory:2048, vCores:1> on host hadoop-110-7:55372, which currently has 1 containers, <memory:2048, vCores:1> used and <memory:6144, vCores:15> available
2013-08-06 12:57:55,049 INFO org.apache.hadoop.yarn.server.resourcemanager.scheduler.capacity.LeafQueue: assignedContainer application=application_1375792971633_0010 container=Container: [ContainerId: container_1375792971633_0010_01_000001, NodeId: hadoop-110-7:55372, NodeHttpAddress: hadoop-110-7:8042, Resource: <memory:2048, vCores:1>, Priority: 0, State: NEW, Token: null, Status: container_id {, app_attempt_id {, application_id {, id: 10, cluster_timestamp: 1375792971633, }, attemptId: 1, }, id: 1, }, state: C_NEW, ] containerId=container_1375792971633_0010_01_000001 queue=default: capacity=1.0, absoluteCapacity=1.0, usedResources=<memory:8192, vCores:4>usedCapacity=0.16666667, absoluteUsedCapacity=0.16666667, numApps=5, numContainers=4 usedCapacity=0.16666667 absoluteUsedCapacity=0.16666667 used=<memory:8192, vCores:4> cluster=<memory:49152, vCores:96>
2013-08-06 12:57:55,050 INFO org.apache.hadoop.yarn.server.resourcemanager.scheduler.capacity.ParentQueue: Re-sorting queues since queue: root.default stats: default: capacity=1.0, absoluteCapacity=1.0, usedResources=<memory:10240, vCores:5>usedCapacity=0.20833333, absoluteUsedCapacity=0.20833333, numApps=5, numContainers=5
2013-08-06 12:57:55,051 INFO org.apache.hadoop.yarn.server.resourcemanager.rmcontainer.RMContainerImpl: container_1375792971633_0010_01_000001 Container Transitioned from ALLOCATED to ACQUIRED
2013-08-06 12:57:55,052 INFO org.apache.hadoop.yarn.server.resourcemanager.scheduler.capacity.ParentQueue: assignedContainer queue=root usedCapacity=0.20833333 absoluteUsedCapacity=0.20833333 used=<memory:10240, vCores:5> cluster=<memory:49152, vCores:96>
2013-08-06 12:57:55,054 INFO org.apache.hadoop.yarn.server.resourcemanager.rmapp.attempt.RMAppAttemptImpl: Storing attempt: AppId: application_1375792971633_0010 AttemptId: appattempt_1375792971633_0010_000001 MasterContainer: Container: [ContainerId: container_1375792971633_0010_01_000001, NodeId: hadoop-110-7:55372, NodeHttpAddress: hadoop-110-7:8042, Resource: <memory:2048, vCores:1>, Priority: 0, State: NEW, Token: null, Status: container_id {, app_attempt_id {, application_id {, id: 10, cluster_timestamp: 1375792971633, }, attemptId: 1, }, id: 1, }, state: C_NEW, ]
2013-08-06 12:57:55,054 INFO org.apache.hadoop.yarn.server.resourcemanager.rmapp.attempt.RMAppAttemptImpl: appattempt_1375792971633_0010_000001 State change from SCHEDULED to ALLOCATED_SAVING
2013-08-06 12:57:55,054 INFO org.apache.hadoop.yarn.server.resourcemanager.recovery.RMStateStore: Storing info for attempt: appattempt_1375792971633_0010_000001
2013-08-06 12:57:55,055 INFO org.apache.hadoop.yarn.server.resourcemanager.rmapp.attempt.RMAppAttemptImpl: appattempt_1375792971633_0010_000001 State change from ALLOCATED_SAVING to ALLOCATED
2013-08-06 12:57:55,056 INFO org.apache.hadoop.yarn.server.resourcemanager.amlauncher.AMLauncher: Launching masterappattempt_1375792971633_0010_000001
2013-08-06 12:57:55,058 INFO org.apache.hadoop.yarn.server.resourcemanager.amlauncher.AMLauncher: Setting up container Container: [ContainerId: container_1375792971633_0010_01_000001, NodeId: hadoop-110-7:55372, NodeHttpAddress: hadoop-110-7:8042, Resource: <memory:2048, vCores:1>, Priority: 0, State: NEW, Token: null, Status: container_id {, app_attempt_id {, application_id {, id: 10, cluster_timestamp: 1375792971633, }, attemptId: 1, }, id: 1, }, state: C_NEW, ] for AM appattempt_1375792971633_0010_000001
2013-08-06 12:57:55,058 INFO org.apache.hadoop.yarn.server.resourcemanager.amlauncher.AMLauncher: Command to launch container container_1375792971633_0010_01_000001 : $JAVA_HOME/bin/java -Dlog4j.configuration=container-log4j.properties -Dyarn.app.mapreduce.container.log.dir=<LOG_DIR> -Dyarn.app.mapreduce.container.log.filesize=0 -Dhadoop.root.logger=INFO,CLA  -Xmx1024m org.apache.hadoop.mapreduce.v2.app.MRAppMaster 1><LOG_DIR>/stdout 2><LOG_DIR>/stderr 
2013-08-06 12:57:55,075 INFO org.apache.hadoop.yarn.server.resourcemanager.amlauncher.AMLauncher: Done launching container Container: [ContainerId: container_1375792971633_0010_01_000001, NodeId: hadoop-110-7:55372, NodeHttpAddress: hadoop-110-7:8042, Resource: <memory:2048, vCores:1>, Priority: 0, State: NEW, Token: null, Status: container_id {, app_attempt_id {, application_id {, id: 10, cluster_timestamp: 1375792971633, }, attemptId: 1, }, id: 1, }, state: C_NEW, ] for AM appattempt_1375792971633_0010_000001
2013-08-06 12:57:55,075 INFO org.apache.hadoop.yarn.server.resourcemanager.rmapp.attempt.RMAppAttemptImpl: appattempt_1375792971633_0010_000001 State change from ALLOCATED to LAUNCHED
2013-08-06 12:57:55,231 INFO org.apache.hadoop.yarn.server.resourcemanager.rmcontainer.RMContainerImpl: container_1375792971633_0008_01_000001 Container Transitioned from ACQUIRED to RUNNING
2013-08-06 12:57:55,595 INFO org.apache.hadoop.yarn.server.resourcemanager.rmcontainer.RMContainerImpl: container_1375792971633_0009_01_000001 Container Transitioned from ACQUIRED to RUNNING
2013-08-06 12:57:56,053 INFO org.apache.hadoop.yarn.server.resourcemanager.rmcontainer.RMContainerImpl: container_1375792971633_0010_01_000001 Container Transitioned from ACQUIRED to RUNNING
2013-08-06 12:57:59,499 INFO org.apache.hadoop.yarn.server.resourcemanager.ApplicationMasterService: AM registration appattempt_1375792971633_0008_000001
2013-08-06 12:57:59,500 INFO org.apache.hadoop.yarn.server.resourcemanager.RMAuditLogger: USER=ubuntu	IP=192.168.100.11	OPERATION=Register App Master	TARGET=ApplicationMasterService	RESULT=SUCCESS	APPID=application_1375792971633_0008	APPATTEMPTID=appattempt_1375792971633_0008_000001
2013-08-06 12:57:59,501 INFO org.apache.hadoop.yarn.server.resourcemanager.rmapp.attempt.RMAppAttemptImpl: appattempt_1375792971633_0008_000001 State change from LAUNCHED to RUNNING
2013-08-06 12:57:59,501 INFO org.apache.hadoop.yarn.server.resourcemanager.rmapp.RMAppImpl: application_1375792971633_0008 State change from ACCEPTED to RUNNING
2013-08-06 12:58:00,098 INFO org.apache.hadoop.yarn.server.resourcemanager.ApplicationMasterService: AM registration appattempt_1375792971633_0006_000001
2013-08-06 12:58:00,098 INFO org.apache.hadoop.yarn.server.resourcemanager.RMAuditLogger: USER=ubuntu	IP=192.168.100.9	OPERATION=Register App Master	TARGET=ApplicationMasterService	RESULT=SUCCESS	APPID=application_1375792971633_0006	APPATTEMPTID=appattempt_1375792971633_0006_000001
2013-08-06 12:58:00,099 INFO org.apache.hadoop.yarn.server.resourcemanager.rmapp.attempt.RMAppAttemptImpl: appattempt_1375792971633_0006_000001 State change from LAUNCHED to RUNNING
2013-08-06 12:58:00,099 INFO org.apache.hadoop.yarn.server.resourcemanager.rmapp.RMAppImpl: application_1375792971633_0006 State change from ACCEPTED to RUNNING
2013-08-06 12:58:00,616 INFO org.apache.hadoop.yarn.server.resourcemanager.rmcontainer.RMContainerImpl: container_1375792971633_0008_01_000002 Container Transitioned from NEW to ALLOCATED
2013-08-06 12:58:00,617 INFO org.apache.hadoop.yarn.server.resourcemanager.RMAuditLogger: USER=ubuntu	OPERATION=AM Allocated Container	TARGET=SchedulerApp	RESULT=SUCCESS	APPID=application_1375792971633_0008	CONTAINERID=container_1375792971633_0008_01_000002
2013-08-06 12:58:00,617 INFO org.apache.hadoop.yarn.server.resourcemanager.scheduler.common.fica.FiCaSchedulerNode: Assigned container container_1375792971633_0008_01_000002 of capacity <memory:1024, vCores:1> on host hadoop-110-4:59955, which currently has 3 containers, <memory:5120, vCores:3> used and <memory:3072, vCores:13> available
2013-08-06 12:58:00,618 INFO org.apache.hadoop.yarn.server.resourcemanager.scheduler.capacity.LeafQueue: assignedContainer application=application_1375792971633_0008 container=Container: [ContainerId: container_1375792971633_0008_01_000002, NodeId: hadoop-110-4:59955, NodeHttpAddress: hadoop-110-4:8042, Resource: <memory:1024, vCores:1>, Priority: 20, State: NEW, Token: null, Status: container_id {, app_attempt_id {, application_id {, id: 8, cluster_timestamp: 1375792971633, }, attemptId: 1, }, id: 2, }, state: C_NEW, ] containerId=container_1375792971633_0008_01_000002 queue=default: capacity=1.0, absoluteCapacity=1.0, usedResources=<memory:10240, vCores:5>usedCapacity=0.20833333, absoluteUsedCapacity=0.20833333, numApps=5, numContainers=5 usedCapacity=0.20833333 absoluteUsedCapacity=0.20833333 used=<memory:10240, vCores:5> cluster=<memory:49152, vCores:96>
2013-08-06 12:58:00,618 INFO org.apache.hadoop.yarn.server.resourcemanager.scheduler.capacity.ParentQueue: Re-sorting queues since queue: root.default stats: default: capacity=1.0, absoluteCapacity=1.0, usedResources=<memory:11264, vCores:6>usedCapacity=0.22916667, absoluteUsedCapacity=0.22916667, numApps=5, numContainers=6
2013-08-06 12:58:00,618 INFO org.apache.hadoop.yarn.server.resourcemanager.scheduler.capacity.ParentQueue: assignedContainer queue=root usedCapacity=0.22916667 absoluteUsedCapacity=0.22916667 used=<memory:11264, vCores:6> cluster=<memory:49152, vCores:96>
2013-08-06 12:58:00,619 INFO org.apache.hadoop.yarn.server.resourcemanager.rmcontainer.RMContainerImpl: container_1375792971633_0008_01_000003 Container Transitioned from NEW to ALLOCATED
2013-08-06 12:58:00,619 INFO org.apache.hadoop.yarn.server.resourcemanager.RMAuditLogger: USER=ubuntu	OPERATION=AM Allocated Container	TARGET=SchedulerApp	RESULT=SUCCESS	APPID=application_1375792971633_0008	CONTAINERID=container_1375792971633_0008_01_000003
2013-08-06 12:58:00,619 INFO org.apache.hadoop.yarn.server.resourcemanager.scheduler.common.fica.FiCaSchedulerNode: Assigned container container_1375792971633_0008_01_000003 of capacity <memory:1024, vCores:1> on host hadoop-110-4:59955, which currently has 4 containers, <memory:6144, vCores:4> used and <memory:2048, vCores:12> available
2013-08-06 12:58:00,620 INFO org.apache.hadoop.yarn.server.resourcemanager.scheduler.capacity.LeafQueue: assignedContainer application=application_1375792971633_0008 container=Container: [ContainerId: container_1375792971633_0008_01_000003, NodeId: hadoop-110-4:59955, NodeHttpAddress: hadoop-110-4:8042, Resource: <memory:1024, vCores:1>, Priority: 20, State: NEW, Token: null, Status: container_id {, app_attempt_id {, application_id {, id: 8, cluster_timestamp: 1375792971633, }, attemptId: 1, }, id: 3, }, state: C_NEW, ] containerId=container_1375792971633_0008_01_000003 queue=default: capacity=1.0, absoluteCapacity=1.0, usedResources=<memory:11264, vCores:6>usedCapacity=0.22916667, absoluteUsedCapacity=0.22916667, numApps=5, numContainers=6 usedCapacity=0.22916667 absoluteUsedCapacity=0.22916667 used=<memory:11264, vCores:6> cluster=<memory:49152, vCores:96>
2013-08-06 12:58:00,620 INFO org.apache.hadoop.yarn.server.resourcemanager.scheduler.capacity.ParentQueue: Re-sorting queues since queue: root.default stats: default: capacity=1.0, absoluteCapacity=1.0, usedResources=<memory:12288, vCores:7>usedCapacity=0.25, absoluteUsedCapacity=0.25, numApps=5, numContainers=7
2013-08-06 12:58:00,621 INFO org.apache.hadoop.yarn.server.resourcemanager.scheduler.capacity.ParentQueue: assignedContainer queue=root usedCapacity=0.25 absoluteUsedCapacity=0.25 used=<memory:12288, vCores:7> cluster=<memory:49152, vCores:96>
2013-08-06 12:58:00,621 INFO org.apache.hadoop.yarn.server.resourcemanager.rmcontainer.RMContainerImpl: container_1375792971633_0008_01_000004 Container Transitioned from NEW to ALLOCATED
2013-08-06 12:58:00,621 INFO org.apache.hadoop.yarn.server.resourcemanager.RMAuditLogger: USER=ubuntu	OPERATION=AM Allocated Container	TARGET=SchedulerApp	RESULT=SUCCESS	APPID=application_1375792971633_0008	CONTAINERID=container_1375792971633_0008_01_000004
2013-08-06 12:58:00,621 INFO org.apache.hadoop.yarn.server.resourcemanager.scheduler.common.fica.FiCaSchedulerNode: Assigned container container_1375792971633_0008_01_000004 of capacity <memory:1024, vCores:1> on host hadoop-110-4:59955, which currently has 5 containers, <memory:7168, vCores:5> used and <memory:1024, vCores:11> available
2013-08-06 12:58:00,622 INFO org.apache.hadoop.yarn.server.resourcemanager.scheduler.capacity.LeafQueue: assignedContainer application=application_1375792971633_0008 container=Container: [ContainerId: container_1375792971633_0008_01_000004, NodeId: hadoop-110-4:59955, NodeHttpAddress: hadoop-110-4:8042, Resource: <memory:1024, vCores:1>, Priority: 20, State: NEW, Token: null, Status: container_id {, app_attempt_id {, application_id {, id: 8, cluster_timestamp: 1375792971633, }, attemptId: 1, }, id: 4, }, state: C_NEW, ] containerId=container_1375792971633_0008_01_000004 queue=default: capacity=1.0, absoluteCapacity=1.0, usedResources=<memory:12288, vCores:7>usedCapacity=0.25, absoluteUsedCapacity=0.25, numApps=5, numContainers=7 usedCapacity=0.25 absoluteUsedCapacity=0.25 used=<memory:12288, vCores:7> cluster=<memory:49152, vCores:96>
2013-08-06 12:58:00,623 INFO org.apache.hadoop.yarn.server.resourcemanager.scheduler.capacity.ParentQueue: Re-sorting queues since queue: root.default stats: default: capacity=1.0, absoluteCapacity=1.0, usedResources=<memory:13312, vCores:8>usedCapacity=0.27083334, absoluteUsedCapacity=0.27083334, numApps=5, numContainers=8
2013-08-06 12:58:00,623 INFO org.apache.hadoop.yarn.server.resourcemanager.scheduler.capacity.ParentQueue: assignedContainer queue=root usedCapacity=0.27083334 absoluteUsedCapacity=0.27083334 used=<memory:13312, vCores:8> cluster=<memory:49152, vCores:96>
2013-08-06 12:58:00,623 INFO org.apache.hadoop.yarn.server.resourcemanager.rmcontainer.RMContainerImpl: container_1375792971633_0008_01_000005 Container Transitioned from NEW to ALLOCATED
2013-08-06 12:58:00,623 INFO org.apache.hadoop.yarn.server.resourcemanager.RMAuditLogger: USER=ubuntu	OPERATION=AM Allocated Container	TARGET=SchedulerApp	RESULT=SUCCESS	APPID=application_1375792971633_0008	CONTAINERID=container_1375792971633_0008_01_000005
2013-08-06 12:58:00,624 INFO org.apache.hadoop.yarn.server.resourcemanager.scheduler.common.fica.FiCaSchedulerNode: Assigned container container_1375792971633_0008_01_000005 of capacity <memory:1024, vCores:1> on host hadoop-110-4:59955, which currently has 6 containers, <memory:8192, vCores:6> used and <memory:0, vCores:10> available
2013-08-06 12:58:00,625 INFO org.apache.hadoop.yarn.server.resourcemanager.scheduler.capacity.LeafQueue: assignedContainer application=application_1375792971633_0008 container=Container: [ContainerId: container_1375792971633_0008_01_000005, NodeId: hadoop-110-4:59955, NodeHttpAddress: hadoop-110-4:8042, Resource: <memory:1024, vCores:1>, Priority: 20, State: NEW, Token: null, Status: container_id {, app_attempt_id {, application_id {, id: 8, cluster_timestamp: 1375792971633, }, attemptId: 1, }, id: 5, }, state: C_NEW, ] containerId=container_1375792971633_0008_01_000005 queue=default: capacity=1.0, absoluteCapacity=1.0, usedResources=<memory:13312, vCores:8>usedCapacity=0.27083334, absoluteUsedCapacity=0.27083334, numApps=5, numContainers=8 usedCapacity=0.27083334 absoluteUsedCapacity=0.27083334 used=<memory:13312, vCores:8> cluster=<memory:49152, vCores:96>
2013-08-06 12:58:00,625 INFO org.apache.hadoop.yarn.server.resourcemanager.scheduler.capacity.ParentQueue: Re-sorting queues since queue: root.default stats: default: capacity=1.0, absoluteCapacity=1.0, usedResources=<memory:14336, vCores:9>usedCapacity=0.29166666, absoluteUsedCapacity=0.29166666, numApps=5, numContainers=9
2013-08-06 12:58:00,625 INFO org.apache.hadoop.yarn.server.resourcemanager.scheduler.capacity.ParentQueue: assignedContainer queue=root usedCapacity=0.29166666 absoluteUsedCapacity=0.29166666 used=<memory:14336, vCores:9> cluster=<memory:49152, vCores:96>
2013-08-06 12:58:00,696 INFO org.apache.hadoop.yarn.server.resourcemanager.rmcontainer.RMContainerImpl: container_1375792971633_0008_01_000006 Container Transitioned from NEW to ALLOCATED
2013-08-06 12:58:00,696 INFO org.apache.hadoop.yarn.server.resourcemanager.RMAuditLogger: USER=ubuntu	OPERATION=AM Allocated Container	TARGET=SchedulerApp	RESULT=SUCCESS	APPID=application_1375792971633_0008	CONTAINERID=container_1375792971633_0008_01_000006
2013-08-06 12:58:00,696 INFO org.apache.hadoop.yarn.server.resourcemanager.scheduler.common.fica.FiCaSchedulerNode: Assigned container container_1375792971633_0008_01_000006 of capacity <memory:1024, vCores:1> on host hadoop-110-3:34727, which currently has 2 containers, <memory:3072, vCores:2> used and <memory:5120, vCores:14> available
2013-08-06 12:58:00,698 INFO org.apache.hadoop.yarn.server.resourcemanager.scheduler.capacity.LeafQueue: assignedContainer application=application_1375792971633_0008 container=Container: [ContainerId: container_1375792971633_0008_01_000006, NodeId: hadoop-110-3:34727, NodeHttpAddress: hadoop-110-3:8042, Resource: <memory:1024, vCores:1>, Priority: 20, State: NEW, Token: null, Status: container_id {, app_attempt_id {, application_id {, id: 8, cluster_timestamp: 1375792971633, }, attemptId: 1, }, id: 6, }, state: C_NEW, ] containerId=container_1375792971633_0008_01_000006 queue=default: capacity=1.0, absoluteCapacity=1.0, usedResources=<memory:14336, vCores:9>usedCapacity=0.29166666, absoluteUsedCapacity=0.29166666, numApps=5, numContainers=9 usedCapacity=0.29166666 absoluteUsedCapacity=0.29166666 used=<memory:14336, vCores:9> cluster=<memory:49152, vCores:96>
2013-08-06 12:58:00,698 INFO org.apache.hadoop.yarn.server.resourcemanager.scheduler.capacity.ParentQueue: Re-sorting queues since queue: root.default stats: default: capacity=1.0, absoluteCapacity=1.0, usedResources=<memory:15360, vCores:10>usedCapacity=0.3125, absoluteUsedCapacity=0.3125, numApps=5, numContainers=10
2013-08-06 12:58:00,698 INFO org.apache.hadoop.yarn.server.resourcemanager.scheduler.capacity.ParentQueue: assignedContainer queue=root usedCapacity=0.3125 absoluteUsedCapacity=0.3125 used=<memory:15360, vCores:10> cluster=<memory:49152, vCores:96>
2013-08-06 12:58:00,699 INFO org.apache.hadoop.yarn.server.resourcemanager.rmcontainer.RMContainerImpl: container_1375792971633_0008_01_000007 Container Transitioned from NEW to ALLOCATED
2013-08-06 12:58:00,699 INFO org.apache.hadoop.yarn.server.resourcemanager.RMAuditLogger: USER=ubuntu	OPERATION=AM Allocated Container	TARGET=SchedulerApp	RESULT=SUCCESS	APPID=application_1375792971633_0008	CONTAINERID=container_1375792971633_0008_01_000007
2013-08-06 12:58:00,699 INFO org.apache.hadoop.yarn.server.resourcemanager.scheduler.common.fica.FiCaSchedulerNode: Assigned container container_1375792971633_0008_01_000007 of capacity <memory:1024, vCores:1> on host hadoop-110-3:34727, which currently has 3 containers, <memory:4096, vCores:3> used and <memory:4096, vCores:13> available
2013-08-06 12:58:00,700 INFO org.apache.hadoop.yarn.server.resourcemanager.scheduler.capacity.LeafQueue: assignedContainer application=application_1375792971633_0008 container=Container: [ContainerId: container_1375792971633_0008_01_000007, NodeId: hadoop-110-3:34727, NodeHttpAddress: hadoop-110-3:8042, Resource: <memory:1024, vCores:1>, Priority: 20, State: NEW, Token: null, Status: container_id {, app_attempt_id {, application_id {, id: 8, cluster_timestamp: 1375792971633, }, attemptId: 1, }, id: 7, }, state: C_NEW, ] containerId=container_1375792971633_0008_01_000007 queue=default: capacity=1.0, absoluteCapacity=1.0, usedResources=<memory:15360, vCores:10>usedCapacity=0.3125, absoluteUsedCapacity=0.3125, numApps=5, numContainers=10 usedCapacity=0.3125 absoluteUsedCapacity=0.3125 used=<memory:15360, vCores:10> cluster=<memory:49152, vCores:96>
2013-08-06 12:58:00,700 INFO org.apache.hadoop.yarn.server.resourcemanager.scheduler.capacity.ParentQueue: Re-sorting queues since queue: root.default stats: default: capacity=1.0, absoluteCapacity=1.0, usedResources=<memory:16384, vCores:11>usedCapacity=0.33333334, absoluteUsedCapacity=0.33333334, numApps=5, numContainers=11
2013-08-06 12:58:00,700 INFO org.apache.hadoop.yarn.server.resourcemanager.scheduler.capacity.ParentQueue: assignedContainer queue=root usedCapacity=0.33333334 absoluteUsedCapacity=0.33333334 used=<memory:16384, vCores:11> cluster=<memory:49152, vCores:96>
2013-08-06 12:58:00,701 INFO org.apache.hadoop.yarn.server.resourcemanager.rmcontainer.RMContainerImpl: container_1375792971633_0008_01_000008 Container Transitioned from NEW to ALLOCATED
2013-08-06 12:58:00,701 INFO org.apache.hadoop.yarn.server.resourcemanager.RMAuditLogger: USER=ubuntu	OPERATION=AM Allocated Container	TARGET=SchedulerApp	RESULT=SUCCESS	APPID=application_1375792971633_0008	CONTAINERID=container_1375792971633_0008_01_000008
2013-08-06 12:58:00,701 INFO org.apache.hadoop.yarn.server.resourcemanager.scheduler.common.fica.FiCaSchedulerNode: Assigned container container_1375792971633_0008_01_000008 of capacity <memory:1024, vCores:1> on host hadoop-110-3:34727, which currently has 4 containers, <memory:5120, vCores:4> used and <memory:3072, vCores:12> available
2013-08-06 12:58:00,702 INFO org.apache.hadoop.yarn.server.resourcemanager.scheduler.capacity.LeafQueue: assignedContainer application=application_1375792971633_0008 container=Container: [ContainerId: container_1375792971633_0008_01_000008, NodeId: hadoop-110-3:34727, NodeHttpAddress: hadoop-110-3:8042, Resource: <memory:1024, vCores:1>, Priority: 20, State: NEW, Token: null, Status: container_id {, app_attempt_id {, application_id {, id: 8, cluster_timestamp: 1375792971633, }, attemptId: 1, }, id: 8, }, state: C_NEW, ] containerId=container_1375792971633_0008_01_000008 queue=default: capacity=1.0, absoluteCapacity=1.0, usedResources=<memory:16384, vCores:11>usedCapacity=0.33333334, absoluteUsedCapacity=0.33333334, numApps=5, numContainers=11 usedCapacity=0.33333334 absoluteUsedCapacity=0.33333334 used=<memory:16384, vCores:11> cluster=<memory:49152, vCores:96>
2013-08-06 12:58:00,702 INFO org.apache.hadoop.yarn.server.resourcemanager.scheduler.capacity.ParentQueue: Re-sorting queues since queue: root.default stats: default: capacity=1.0, absoluteCapacity=1.0, usedResources=<memory:17408, vCores:12>usedCapacity=0.35416666, absoluteUsedCapacity=0.35416666, numApps=5, numContainers=12
2013-08-06 12:58:00,702 INFO org.apache.hadoop.yarn.server.resourcemanager.scheduler.capacity.ParentQueue: assignedContainer queue=root usedCapacity=0.35416666 absoluteUsedCapacity=0.35416666 used=<memory:17408, vCores:12> cluster=<memory:49152, vCores:96>
2013-08-06 12:58:00,703 INFO org.apache.hadoop.yarn.server.resourcemanager.rmcontainer.RMContainerImpl: container_1375792971633_0008_01_000009 Container Transitioned from NEW to ALLOCATED
2013-08-06 12:58:00,703 INFO org.apache.hadoop.yarn.server.resourcemanager.RMAuditLogger: USER=ubuntu	OPERATION=AM Allocated Container	TARGET=SchedulerApp	RESULT=SUCCESS	APPID=application_1375792971633_0008	CONTAINERID=container_1375792971633_0008_01_000009
2013-08-06 12:58:00,703 INFO org.apache.hadoop.yarn.server.resourcemanager.scheduler.common.fica.FiCaSchedulerNode: Assigned container container_1375792971633_0008_01_000009 of capacity <memory:1024, vCores:1> on host hadoop-110-3:34727, which currently has 5 containers, <memory:6144, vCores:5> used and <memory:2048, vCores:11> available
2013-08-06 12:58:00,704 INFO org.apache.hadoop.yarn.server.resourcemanager.scheduler.capacity.LeafQueue: assignedContainer application=application_1375792971633_0008 container=Container: [ContainerId: container_1375792971633_0008_01_000009, NodeId: hadoop-110-3:34727, NodeHttpAddress: hadoop-110-3:8042, Resource: <memory:1024, vCores:1>, Priority: 20, State: NEW, Token: null, Status: container_id {, app_attempt_id {, application_id {, id: 8, cluster_timestamp: 1375792971633, }, attemptId: 1, }, id: 9, }, state: C_NEW, ] containerId=container_1375792971633_0008_01_000009 queue=default: capacity=1.0, absoluteCapacity=1.0, usedResources=<memory:17408, vCores:12>usedCapacity=0.35416666, absoluteUsedCapacity=0.35416666, numApps=5, numContainers=12 usedCapacity=0.35416666 absoluteUsedCapacity=0.35416666 used=<memory:17408, vCores:12> cluster=<memory:49152, vCores:96>
2013-08-06 12:58:00,704 INFO org.apache.hadoop.yarn.server.resourcemanager.scheduler.capacity.ParentQueue: Re-sorting queues since queue: root.default stats: default: capacity=1.0, absoluteCapacity=1.0, usedResources=<memory:18432, vCores:13>usedCapacity=0.375, absoluteUsedCapacity=0.375, numApps=5, numContainers=13
2013-08-06 12:58:00,705 INFO org.apache.hadoop.yarn.server.resourcemanager.scheduler.capacity.ParentQueue: assignedContainer queue=root usedCapacity=0.375 absoluteUsedCapacity=0.375 used=<memory:18432, vCores:13> cluster=<memory:49152, vCores:96>
2013-08-06 12:58:00,705 INFO org.apache.hadoop.yarn.server.resourcemanager.rmcontainer.RMContainerImpl: container_1375792971633_0008_01_000010 Container Transitioned from NEW to ALLOCATED
2013-08-06 12:58:00,705 INFO org.apache.hadoop.yarn.server.resourcemanager.RMAuditLogger: USER=ubuntu	OPERATION=AM Allocated Container	TARGET=SchedulerApp	RESULT=SUCCESS	APPID=application_1375792971633_0008	CONTAINERID=container_1375792971633_0008_01_000010
2013-08-06 12:58:00,705 INFO org.apache.hadoop.yarn.server.resourcemanager.scheduler.common.fica.FiCaSchedulerNode: Assigned container container_1375792971633_0008_01_000010 of capacity <memory:1024, vCores:1> on host hadoop-110-3:34727, which currently has 6 containers, <memory:7168, vCores:6> used and <memory:1024, vCores:10> available
2013-08-06 12:58:00,706 INFO org.apache.hadoop.yarn.server.resourcemanager.scheduler.capacity.LeafQueue: assignedContainer application=application_1375792971633_0008 container=Container: [ContainerId: container_1375792971633_0008_01_000010, NodeId: hadoop-110-3:34727, NodeHttpAddress: hadoop-110-3:8042, Resource: <memory:1024, vCores:1>, Priority: 20, State: NEW, Token: null, Status: container_id {, app_attempt_id {, application_id {, id: 8, cluster_timestamp: 1375792971633, }, attemptId: 1, }, id: 10, }, state: C_NEW, ] containerId=container_1375792971633_0008_01_000010 queue=default: capacity=1.0, absoluteCapacity=1.0, usedResources=<memory:18432, vCores:13>usedCapacity=0.375, absoluteUsedCapacity=0.375, numApps=5, numContainers=13 usedCapacity=0.375 absoluteUsedCapacity=0.375 used=<memory:18432, vCores:13> cluster=<memory:49152, vCores:96>
2013-08-06 12:58:00,706 INFO org.apache.hadoop.yarn.server.resourcemanager.scheduler.capacity.ParentQueue: Re-sorting queues since queue: root.default stats: default: capacity=1.0, absoluteCapacity=1.0, usedResources=<memory:19456, vCores:14>usedCapacity=0.39583334, absoluteUsedCapacity=0.39583334, numApps=5, numContainers=14
2013-08-06 12:58:00,707 INFO org.apache.hadoop.yarn.server.resourcemanager.scheduler.capacity.ParentQueue: assignedContainer queue=root usedCapacity=0.39583334 absoluteUsedCapacity=0.39583334 used=<memory:19456, vCores:14> cluster=<memory:49152, vCores:96>
2013-08-06 12:58:00,707 INFO org.apache.hadoop.yarn.server.resourcemanager.rmcontainer.RMContainerImpl: container_1375792971633_0008_01_000011 Container Transitioned from NEW to ALLOCATED
2013-08-06 12:58:00,707 INFO org.apache.hadoop.yarn.server.resourcemanager.RMAuditLogger: USER=ubuntu	OPERATION=AM Allocated Container	TARGET=SchedulerApp	RESULT=SUCCESS	APPID=application_1375792971633_0008	CONTAINERID=container_1375792971633_0008_01_000011
2013-08-06 12:58:00,707 INFO org.apache.hadoop.yarn.server.resourcemanager.scheduler.common.fica.FiCaSchedulerNode: Assigned container container_1375792971633_0008_01_000011 of capacity <memory:1024, vCores:1> on host hadoop-110-3:34727, which currently has 7 containers, <memory:8192, vCores:7> used and <memory:0, vCores:9> available
2013-08-06 12:58:00,708 INFO org.apache.hadoop.yarn.server.resourcemanager.scheduler.capacity.LeafQueue: assignedContainer application=application_1375792971633_0008 container=Container: [ContainerId: container_1375792971633_0008_01_000011, NodeId: hadoop-110-3:34727, NodeHttpAddress: hadoop-110-3:8042, Resource: <memory:1024, vCores:1>, Priority: 20, State: NEW, Token: null, Status: container_id {, app_attempt_id {, application_id {, id: 8, cluster_timestamp: 1375792971633, }, attemptId: 1, }, id: 11, }, state: C_NEW, ] containerId=container_1375792971633_0008_01_000011 queue=default: capacity=1.0, absoluteCapacity=1.0, usedResources=<memory:19456, vCores:14>usedCapacity=0.39583334, absoluteUsedCapacity=0.39583334, numApps=5, numContainers=14 usedCapacity=0.39583334 absoluteUsedCapacity=0.39583334 used=<memory:19456, vCores:14> cluster=<memory:49152, vCores:96>
2013-08-06 12:58:00,709 INFO org.apache.hadoop.yarn.server.resourcemanager.scheduler.capacity.ParentQueue: Re-sorting queues since queue: root.default stats: default: capacity=1.0, absoluteCapacity=1.0, usedResources=<memory:20480, vCores:15>usedCapacity=0.41666666, absoluteUsedCapacity=0.41666666, numApps=5, numContainers=15
2013-08-06 12:58:00,709 INFO org.apache.hadoop.yarn.server.resourcemanager.scheduler.capacity.ParentQueue: assignedContainer queue=root usedCapacity=0.41666666 absoluteUsedCapacity=0.41666666 used=<memory:20480, vCores:15> cluster=<memory:49152, vCores:96>
2013-08-06 12:58:01,019 INFO org.apache.hadoop.yarn.server.resourcemanager.ApplicationMasterService: AM registration appattempt_1375792971633_0009_000001
2013-08-06 12:58:01,020 INFO org.apache.hadoop.yarn.server.resourcemanager.RMAuditLogger: USER=ubuntu	IP=192.168.100.9	OPERATION=Register App Master	TARGET=ApplicationMasterService	RESULT=SUCCESS	APPID=application_1375792971633_0009	APPATTEMPTID=appattempt_1375792971633_0009_000001
2013-08-06 12:58:01,020 INFO org.apache.hadoop.yarn.server.resourcemanager.rmapp.attempt.RMAppAttemptImpl: appattempt_1375792971633_0009_000001 State change from LAUNCHED to RUNNING
2013-08-06 12:58:01,021 INFO org.apache.hadoop.yarn.server.resourcemanager.rmapp.RMAppImpl: application_1375792971633_0009 State change from ACCEPTED to RUNNING
2013-08-06 12:58:01,074 INFO org.apache.hadoop.yarn.server.resourcemanager.rmcontainer.RMContainerImpl: container_1375792971633_0008_01_000012 Container Transitioned from NEW to ALLOCATED
2013-08-06 12:58:01,074 INFO org.apache.hadoop.yarn.server.resourcemanager.RMAuditLogger: USER=ubuntu	OPERATION=AM Allocated Container	TARGET=SchedulerApp	RESULT=SUCCESS	APPID=application_1375792971633_0008	CONTAINERID=container_1375792971633_0008_01_000012
2013-08-06 12:58:01,074 INFO org.apache.hadoop.yarn.server.resourcemanager.scheduler.common.fica.FiCaSchedulerNode: Assigned container container_1375792971633_0008_01_000012 of capacity <memory:1024, vCores:1> on host hadoop-110-7:55372, which currently has 2 containers, <memory:3072, vCores:2> used and <memory:5120, vCores:14> available
2013-08-06 12:58:01,075 INFO org.apache.hadoop.yarn.server.resourcemanager.scheduler.capacity.LeafQueue: assignedContainer application=application_1375792971633_0008 container=Container: [ContainerId: container_1375792971633_0008_01_000012, NodeId: hadoop-110-7:55372, NodeHttpAddress: hadoop-110-7:8042, Resource: <memory:1024, vCores:1>, Priority: 20, State: NEW, Token: null, Status: container_id {, app_attempt_id {, application_id {, id: 8, cluster_timestamp: 1375792971633, }, attemptId: 1, }, id: 12, }, state: C_NEW, ] containerId=container_1375792971633_0008_01_000012 queue=default: capacity=1.0, absoluteCapacity=1.0, usedResources=<memory:20480, vCores:15>usedCapacity=0.41666666, absoluteUsedCapacity=0.41666666, numApps=5, numContainers=15 usedCapacity=0.41666666 absoluteUsedCapacity=0.41666666 used=<memory:20480, vCores:15> cluster=<memory:49152, vCores:96>
2013-08-06 12:58:01,075 INFO org.apache.hadoop.yarn.server.resourcemanager.scheduler.capacity.ParentQueue: Re-sorting queues since queue: root.default stats: default: capacity=1.0, absoluteCapacity=1.0, usedResources=<memory:21504, vCores:16>usedCapacity=0.4375, absoluteUsedCapacity=0.4375, numApps=5, numContainers=16
2013-08-06 12:58:01,076 INFO org.apache.hadoop.yarn.server.resourcemanager.scheduler.capacity.ParentQueue: assignedContainer queue=root usedCapacity=0.4375 absoluteUsedCapacity=0.4375 used=<memory:21504, vCores:16> cluster=<memory:49152, vCores:96>
2013-08-06 12:58:01,076 INFO org.apache.hadoop.yarn.server.resourcemanager.rmcontainer.RMContainerImpl: container_1375792971633_0008_01_000013 Container Transitioned from NEW to ALLOCATED
2013-08-06 12:58:01,076 INFO org.apache.hadoop.yarn.server.resourcemanager.RMAuditLogger: USER=ubuntu	OPERATION=AM Allocated Container	TARGET=SchedulerApp	RESULT=SUCCESS	APPID=application_1375792971633_0008	CONTAINERID=container_1375792971633_0008_01_000013
2013-08-06 12:58:01,076 INFO org.apache.hadoop.yarn.server.resourcemanager.scheduler.common.fica.FiCaSchedulerNode: Assigned container container_1375792971633_0008_01_000013 of capacity <memory:1024, vCores:1> on host hadoop-110-7:55372, which currently has 3 containers, <memory:4096, vCores:3> used and <memory:4096, vCores:13> available
2013-08-06 12:58:01,077 INFO org.apache.hadoop.yarn.server.resourcemanager.scheduler.capacity.LeafQueue: assignedContainer application=application_1375792971633_0008 container=Container: [ContainerId: container_1375792971633_0008_01_000013, NodeId: hadoop-110-7:55372, NodeHttpAddress: hadoop-110-7:8042, Resource: <memory:1024, vCores:1>, Priority: 20, State: NEW, Token: null, Status: container_id {, app_attempt_id {, application_id {, id: 8, cluster_timestamp: 1375792971633, }, attemptId: 1, }, id: 13, }, state: C_NEW, ] containerId=container_1375792971633_0008_01_000013 queue=default: capacity=1.0, absoluteCapacity=1.0, usedResources=<memory:21504, vCores:16>usedCapacity=0.4375, absoluteUsedCapacity=0.4375, numApps=5, numContainers=16 usedCapacity=0.4375 absoluteUsedCapacity=0.4375 used=<memory:21504, vCores:16> cluster=<memory:49152, vCores:96>
2013-08-06 12:58:01,078 INFO org.apache.hadoop.yarn.server.resourcemanager.scheduler.capacity.ParentQueue: Re-sorting queues since queue: root.default stats: default: capacity=1.0, absoluteCapacity=1.0, usedResources=<memory:22528, vCores:17>usedCapacity=0.45833334, absoluteUsedCapacity=0.45833334, numApps=5, numContainers=17
2013-08-06 12:58:01,078 INFO org.apache.hadoop.yarn.server.resourcemanager.scheduler.capacity.ParentQueue: assignedContainer queue=root usedCapacity=0.45833334 absoluteUsedCapacity=0.45833334 used=<memory:22528, vCores:17> cluster=<memory:49152, vCores:96>
2013-08-06 12:58:01,078 INFO org.apache.hadoop.yarn.server.resourcemanager.rmcontainer.RMContainerImpl: container_1375792971633_0008_01_000014 Container Transitioned from NEW to ALLOCATED
2013-08-06 12:58:01,078 INFO org.apache.hadoop.yarn.server.resourcemanager.RMAuditLogger: USER=ubuntu	OPERATION=AM Allocated Container	TARGET=SchedulerApp	RESULT=SUCCESS	APPID=application_1375792971633_0008	CONTAINERID=container_1375792971633_0008_01_000014
2013-08-06 12:58:01,079 INFO org.apache.hadoop.yarn.server.resourcemanager.scheduler.common.fica.FiCaSchedulerNode: Assigned container container_1375792971633_0008_01_000014 of capacity <memory:1024, vCores:1> on host hadoop-110-7:55372, which currently has 4 containers, <memory:5120, vCores:4> used and <memory:3072, vCores:12> available
2013-08-06 12:58:01,080 INFO org.apache.hadoop.yarn.server.resourcemanager.scheduler.capacity.LeafQueue: assignedContainer application=application_1375792971633_0008 container=Container: [ContainerId: container_1375792971633_0008_01_000014, NodeId: hadoop-110-7:55372, NodeHttpAddress: hadoop-110-7:8042, Resource: <memory:1024, vCores:1>, Priority: 20, State: NEW, Token: null, Status: container_id {, app_attempt_id {, application_id {, id: 8, cluster_timestamp: 1375792971633, }, attemptId: 1, }, id: 14, }, state: C_NEW, ] containerId=container_1375792971633_0008_01_000014 queue=default: capacity=1.0, absoluteCapacity=1.0, usedResources=<memory:22528, vCores:17>usedCapacity=0.45833334, absoluteUsedCapacity=0.45833334, numApps=5, numContainers=17 usedCapacity=0.45833334 absoluteUsedCapacity=0.45833334 used=<memory:22528, vCores:17> cluster=<memory:49152, vCores:96>
2013-08-06 12:58:01,080 INFO org.apache.hadoop.yarn.server.resourcemanager.scheduler.capacity.ParentQueue: Re-sorting queues since queue: root.default stats: default: capacity=1.0, absoluteCapacity=1.0, usedResources=<memory:23552, vCores:18>usedCapacity=0.47916666, absoluteUsedCapacity=0.47916666, numApps=5, numContainers=18
2013-08-06 12:58:01,080 INFO org.apache.hadoop.yarn.server.resourcemanager.scheduler.capacity.ParentQueue: assignedContainer queue=root usedCapacity=0.47916666 absoluteUsedCapacity=0.47916666 used=<memory:23552, vCores:18> cluster=<memory:49152, vCores:96>
2013-08-06 12:58:01,080 INFO org.apache.hadoop.yarn.server.resourcemanager.rmcontainer.RMContainerImpl: container_1375792971633_0008_01_000015 Container Transitioned from NEW to ALLOCATED
2013-08-06 12:58:01,081 INFO org.apache.hadoop.yarn.server.resourcemanager.RMAuditLogger: USER=ubuntu	OPERATION=AM Allocated Container	TARGET=SchedulerApp	RESULT=SUCCESS	APPID=application_1375792971633_0008	CONTAINERID=container_1375792971633_0008_01_000015
2013-08-06 12:58:01,081 INFO org.apache.hadoop.yarn.server.resourcemanager.scheduler.common.fica.FiCaSchedulerNode: Assigned container container_1375792971633_0008_01_000015 of capacity <memory:1024, vCores:1> on host hadoop-110-7:55372, which currently has 5 containers, <memory:6144, vCores:5> used and <memory:2048, vCores:11> available
2013-08-06 12:58:01,082 INFO org.apache.hadoop.yarn.server.resourcemanager.scheduler.capacity.LeafQueue: assignedContainer application=application_1375792971633_0008 container=Container: [ContainerId: container_1375792971633_0008_01_000015, NodeId: hadoop-110-7:55372, NodeHttpAddress: hadoop-110-7:8042, Resource: <memory:1024, vCores:1>, Priority: 20, State: NEW, Token: null, Status: container_id {, app_attempt_id {, application_id {, id: 8, cluster_timestamp: 1375792971633, }, attemptId: 1, }, id: 15, }, state: C_NEW, ] containerId=container_1375792971633_0008_01_000015 queue=default: capacity=1.0, absoluteCapacity=1.0, usedResources=<memory:23552, vCores:18>usedCapacity=0.47916666, absoluteUsedCapacity=0.47916666, numApps=5, numContainers=18 usedCapacity=0.47916666 absoluteUsedCapacity=0.47916666 used=<memory:23552, vCores:18> cluster=<memory:49152, vCores:96>
2013-08-06 12:58:01,082 INFO org.apache.hadoop.yarn.server.resourcemanager.scheduler.capacity.ParentQueue: Re-sorting queues since queue: root.default stats: default: capacity=1.0, absoluteCapacity=1.0, usedResources=<memory:24576, vCores:19>usedCapacity=0.5, absoluteUsedCapacity=0.5, numApps=5, numContainers=19
2013-08-06 12:58:01,082 INFO org.apache.hadoop.yarn.server.resourcemanager.scheduler.capacity.ParentQueue: assignedContainer queue=root usedCapacity=0.5 absoluteUsedCapacity=0.5 used=<memory:24576, vCores:19> cluster=<memory:49152, vCores:96>
2013-08-06 12:58:01,083 INFO org.apache.hadoop.yarn.server.resourcemanager.rmcontainer.RMContainerImpl: container_1375792971633_0008_01_000016 Container Transitioned from NEW to ALLOCATED
2013-08-06 12:58:01,083 INFO org.apache.hadoop.yarn.server.resourcemanager.RMAuditLogger: USER=ubuntu	OPERATION=AM Allocated Container	TARGET=SchedulerApp	RESULT=SUCCESS	APPID=application_1375792971633_0008	CONTAINERID=container_1375792971633_0008_01_000016
2013-08-06 12:58:01,083 INFO org.apache.hadoop.yarn.server.resourcemanager.scheduler.common.fica.FiCaSchedulerNode: Assigned container container_1375792971633_0008_01_000016 of capacity <memory:1024, vCores:1> on host hadoop-110-7:55372, which currently has 6 containers, <memory:7168, vCores:6> used and <memory:1024, vCores:10> available
2013-08-06 12:58:01,084 INFO org.apache.hadoop.yarn.server.resourcemanager.scheduler.capacity.LeafQueue: assignedContainer application=application_1375792971633_0008 container=Container: [ContainerId: container_1375792971633_0008_01_000016, NodeId: hadoop-110-7:55372, NodeHttpAddress: hadoop-110-7:8042, Resource: <memory:1024, vCores:1>, Priority: 20, State: NEW, Token: null, Status: container_id {, app_attempt_id {, application_id {, id: 8, cluster_timestamp: 1375792971633, }, attemptId: 1, }, id: 16, }, state: C_NEW, ] containerId=container_1375792971633_0008_01_000016 queue=default: capacity=1.0, absoluteCapacity=1.0, usedResources=<memory:24576, vCores:19>usedCapacity=0.5, absoluteUsedCapacity=0.5, numApps=5, numContainers=19 usedCapacity=0.5 absoluteUsedCapacity=0.5 used=<memory:24576, vCores:19> cluster=<memory:49152, vCores:96>
2013-08-06 12:58:01,084 INFO org.apache.hadoop.yarn.server.resourcemanager.scheduler.capacity.ParentQueue: Re-sorting queues since queue: root.default stats: default: capacity=1.0, absoluteCapacity=1.0, usedResources=<memory:25600, vCores:20>usedCapacity=0.5208333, absoluteUsedCapacity=0.5208333, numApps=5, numContainers=20
2013-08-06 12:58:01,084 INFO org.apache.hadoop.yarn.server.resourcemanager.scheduler.capacity.ParentQueue: assignedContainer queue=root usedCapacity=0.5208333 absoluteUsedCapacity=0.5208333 used=<memory:25600, vCores:20> cluster=<memory:49152, vCores:96>
2013-08-06 12:58:01,085 INFO org.apache.hadoop.yarn.server.resourcemanager.rmcontainer.RMContainerImpl: container_1375792971633_0008_01_000017 Container Transitioned from NEW to ALLOCATED
2013-08-06 12:58:01,085 INFO org.apache.hadoop.yarn.server.resourcemanager.RMAuditLogger: USER=ubuntu	OPERATION=AM Allocated Container	TARGET=SchedulerApp	RESULT=SUCCESS	APPID=application_1375792971633_0008	CONTAINERID=container_1375792971633_0008_01_000017
2013-08-06 12:58:01,085 INFO org.apache.hadoop.yarn.server.resourcemanager.scheduler.common.fica.FiCaSchedulerNode: Assigned container container_1375792971633_0008_01_000017 of capacity <memory:1024, vCores:1> on host hadoop-110-7:55372, which currently has 7 containers, <memory:8192, vCores:7> used and <memory:0, vCores:9> available
2013-08-06 12:58:01,086 INFO org.apache.hadoop.yarn.server.resourcemanager.scheduler.capacity.LeafQueue: assignedContainer application=application_1375792971633_0008 container=Container: [ContainerId: container_1375792971633_0008_01_000017, NodeId: hadoop-110-7:55372, NodeHttpAddress: hadoop-110-7:8042, Resource: <memory:1024, vCores:1>, Priority: 20, State: NEW, Token: null, Status: container_id {, app_attempt_id {, application_id {, id: 8, cluster_timestamp: 1375792971633, }, attemptId: 1, }, id: 17, }, state: C_NEW, ] containerId=container_1375792971633_0008_01_000017 queue=default: capacity=1.0, absoluteCapacity=1.0, usedResources=<memory:25600, vCores:20>usedCapacity=0.5208333, absoluteUsedCapacity=0.5208333, numApps=5, numContainers=20 usedCapacity=0.5208333 absoluteUsedCapacity=0.5208333 used=<memory:25600, vCores:20> cluster=<memory:49152, vCores:96>
2013-08-06 12:58:01,086 INFO org.apache.hadoop.yarn.server.resourcemanager.scheduler.capacity.ParentQueue: Re-sorting queues since queue: root.default stats: default: capacity=1.0, absoluteCapacity=1.0, usedResources=<memory:26624, vCores:21>usedCapacity=0.5416667, absoluteUsedCapacity=0.5416667, numApps=5, numContainers=21
2013-08-06 12:58:01,087 INFO org.apache.hadoop.yarn.server.resourcemanager.scheduler.capacity.ParentQueue: assignedContainer queue=root usedCapacity=0.5416667 absoluteUsedCapacity=0.5416667 used=<memory:26624, vCores:21> cluster=<memory:49152, vCores:96>
2013-08-06 12:58:01,132 INFO org.apache.hadoop.yarn.server.resourcemanager.ApplicationMasterService: AM registration appattempt_1375792971633_0007_000001
2013-08-06 12:58:01,133 INFO org.apache.hadoop.yarn.server.resourcemanager.RMAuditLogger: USER=ubuntu	IP=192.168.100.6	OPERATION=Register App Master	TARGET=ApplicationMasterService	RESULT=SUCCESS	APPID=application_1375792971633_0007	APPATTEMPTID=appattempt_1375792971633_0007_000001
2013-08-06 12:58:01,134 INFO org.apache.hadoop.yarn.server.resourcemanager.rmapp.attempt.RMAppAttemptImpl: appattempt_1375792971633_0007_000001 State change from LAUNCHED to RUNNING
2013-08-06 12:58:01,134 INFO org.apache.hadoop.yarn.server.resourcemanager.rmapp.RMAppImpl: application_1375792971633_0007 State change from ACCEPTED to RUNNING
2013-08-06 12:58:01,192 INFO org.apache.hadoop.yarn.server.resourcemanager.rmcontainer.RMContainerImpl: container_1375792971633_0006_01_000002 Container Transitioned from NEW to ALLOCATED
2013-08-06 12:58:01,192 INFO org.apache.hadoop.yarn.server.resourcemanager.RMAuditLogger: USER=ubuntu	OPERATION=AM Allocated Container	TARGET=SchedulerApp	RESULT=SUCCESS	APPID=application_1375792971633_0006	CONTAINERID=container_1375792971633_0006_01_000002
2013-08-06 12:58:01,192 INFO org.apache.hadoop.yarn.server.resourcemanager.scheduler.common.fica.FiCaSchedulerNode: Assigned container container_1375792971633_0006_01_000002 of capacity <memory:1024, vCores:1> on host hadoop-110-5:54830, which currently has 1 containers, <memory:1024, vCores:1> used and <memory:7168, vCores:15> available
2013-08-06 12:58:01,193 INFO org.apache.hadoop.yarn.server.resourcemanager.scheduler.capacity.LeafQueue: assignedContainer application=application_1375792971633_0006 container=Container: [ContainerId: container_1375792971633_0006_01_000002, NodeId: hadoop-110-5:54830, NodeHttpAddress: hadoop-110-5:8042, Resource: <memory:1024, vCores:1>, Priority: 20, State: NEW, Token: null, Status: container_id {, app_attempt_id {, application_id {, id: 6, cluster_timestamp: 1375792971633, }, attemptId: 1, }, id: 2, }, state: C_NEW, ] containerId=container_1375792971633_0006_01_000002 queue=default: capacity=1.0, absoluteCapacity=1.0, usedResources=<memory:26624, vCores:21>usedCapacity=0.5416667, absoluteUsedCapacity=0.5416667, numApps=5, numContainers=21 usedCapacity=0.5416667 absoluteUsedCapacity=0.5416667 used=<memory:26624, vCores:21> cluster=<memory:49152, vCores:96>
2013-08-06 12:58:01,194 INFO org.apache.hadoop.yarn.server.resourcemanager.scheduler.capacity.ParentQueue: Re-sorting queues since queue: root.default stats: default: capacity=1.0, absoluteCapacity=1.0, usedResources=<memory:27648, vCores:22>usedCapacity=0.5625, absoluteUsedCapacity=0.5625, numApps=5, numContainers=22
2013-08-06 12:58:01,194 INFO org.apache.hadoop.yarn.server.resourcemanager.scheduler.capacity.ParentQueue: assignedContainer queue=root usedCapacity=0.5625 absoluteUsedCapacity=0.5625 used=<memory:27648, vCores:22> cluster=<memory:49152, vCores:96>
2013-08-06 12:58:01,194 INFO org.apache.hadoop.yarn.server.resourcemanager.rmcontainer.RMContainerImpl: container_1375792971633_0006_01_000003 Container Transitioned from NEW to ALLOCATED
2013-08-06 12:58:01,194 INFO org.apache.hadoop.yarn.server.resourcemanager.RMAuditLogger: USER=ubuntu	OPERATION=AM Allocated Container	TARGET=SchedulerApp	RESULT=SUCCESS	APPID=application_1375792971633_0006	CONTAINERID=container_1375792971633_0006_01_000003
2013-08-06 12:58:01,195 INFO org.apache.hadoop.yarn.server.resourcemanager.scheduler.common.fica.FiCaSchedulerNode: Assigned container container_1375792971633_0006_01_000003 of capacity <memory:1024, vCores:1> on host hadoop-110-5:54830, which currently has 2 containers, <memory:2048, vCores:2> used and <memory:6144, vCores:14> available
2013-08-06 12:58:01,196 INFO org.apache.hadoop.yarn.server.resourcemanager.scheduler.capacity.LeafQueue: assignedContainer application=application_1375792971633_0006 container=Container: [ContainerId: container_1375792971633_0006_01_000003, NodeId: hadoop-110-5:54830, NodeHttpAddress: hadoop-110-5:8042, Resource: <memory:1024, vCores:1>, Priority: 20, State: NEW, Token: null, Status: container_id {, app_attempt_id {, application_id {, id: 6, cluster_timestamp: 1375792971633, }, attemptId: 1, }, id: 3, }, state: C_NEW, ] containerId=container_1375792971633_0006_01_000003 queue=default: capacity=1.0, absoluteCapacity=1.0, usedResources=<memory:27648, vCores:22>usedCapacity=0.5625, absoluteUsedCapacity=0.5625, numApps=5, numContainers=22 usedCapacity=0.5625 absoluteUsedCapacity=0.5625 used=<memory:27648, vCores:22> cluster=<memory:49152, vCores:96>
2013-08-06 12:58:01,196 INFO org.apache.hadoop.yarn.server.resourcemanager.scheduler.capacity.ParentQueue: Re-sorting queues since queue: root.default stats: default: capacity=1.0, absoluteCapacity=1.0, usedResources=<memory:28672, vCores:23>usedCapacity=0.5833333, absoluteUsedCapacity=0.5833333, numApps=5, numContainers=23
2013-08-06 12:58:01,196 INFO org.apache.hadoop.yarn.server.resourcemanager.scheduler.capacity.ParentQueue: assignedContainer queue=root usedCapacity=0.5833333 absoluteUsedCapacity=0.5833333 used=<memory:28672, vCores:23> cluster=<memory:49152, vCores:96>
2013-08-06 12:58:01,197 INFO org.apache.hadoop.yarn.server.resourcemanager.rmcontainer.RMContainerImpl: container_1375792971633_0006_01_000004 Container Transitioned from NEW to ALLOCATED
2013-08-06 12:58:01,197 INFO org.apache.hadoop.yarn.server.resourcemanager.RMAuditLogger: USER=ubuntu	OPERATION=AM Allocated Container	TARGET=SchedulerApp	RESULT=SUCCESS	APPID=application_1375792971633_0006	CONTAINERID=container_1375792971633_0006_01_000004
2013-08-06 12:58:01,197 INFO org.apache.hadoop.yarn.server.resourcemanager.scheduler.common.fica.FiCaSchedulerNode: Assigned container container_1375792971633_0006_01_000004 of capacity <memory:1024, vCores:1> on host hadoop-110-5:54830, which currently has 3 containers, <memory:3072, vCores:3> used and <memory:5120, vCores:13> available
2013-08-06 12:58:01,198 INFO org.apache.hadoop.yarn.server.resourcemanager.scheduler.capacity.LeafQueue: assignedContainer application=application_1375792971633_0006 container=Container: [ContainerId: container_1375792971633_0006_01_000004, NodeId: hadoop-110-5:54830, NodeHttpAddress: hadoop-110-5:8042, Resource: <memory:1024, vCores:1>, Priority: 20, State: NEW, Token: null, Status: container_id {, app_attempt_id {, application_id {, id: 6, cluster_timestamp: 1375792971633, }, attemptId: 1, }, id: 4, }, state: C_NEW, ] containerId=container_1375792971633_0006_01_000004 queue=default: capacity=1.0, absoluteCapacity=1.0, usedResources=<memory:28672, vCores:23>usedCapacity=0.5833333, absoluteUsedCapacity=0.5833333, numApps=5, numContainers=23 usedCapacity=0.5833333 absoluteUsedCapacity=0.5833333 used=<memory:28672, vCores:23> cluster=<memory:49152, vCores:96>
2013-08-06 12:58:01,198 INFO org.apache.hadoop.yarn.server.resourcemanager.scheduler.capacity.ParentQueue: Re-sorting queues since queue: root.default stats: default: capacity=1.0, absoluteCapacity=1.0, usedResources=<memory:29696, vCores:24>usedCapacity=0.6041667, absoluteUsedCapacity=0.6041667, numApps=5, numContainers=24
2013-08-06 12:58:01,198 INFO org.apache.hadoop.yarn.server.resourcemanager.scheduler.capacity.ParentQueue: assignedContainer queue=root usedCapacity=0.6041667 absoluteUsedCapacity=0.6041667 used=<memory:29696, vCores:24> cluster=<memory:49152, vCores:96>
2013-08-06 12:58:01,199 INFO org.apache.hadoop.yarn.server.resourcemanager.rmcontainer.RMContainerImpl: container_1375792971633_0006_01_000005 Container Transitioned from NEW to ALLOCATED
2013-08-06 12:58:01,199 INFO org.apache.hadoop.yarn.server.resourcemanager.RMAuditLogger: USER=ubuntu	OPERATION=AM Allocated Container	TARGET=SchedulerApp	RESULT=SUCCESS	APPID=application_1375792971633_0006	CONTAINERID=container_1375792971633_0006_01_000005
2013-08-06 12:58:01,199 INFO org.apache.hadoop.yarn.server.resourcemanager.scheduler.common.fica.FiCaSchedulerNode: Assigned container container_1375792971633_0006_01_000005 of capacity <memory:1024, vCores:1> on host hadoop-110-5:54830, which currently has 4 containers, <memory:4096, vCores:4> used and <memory:4096, vCores:12> available
2013-08-06 12:58:01,200 INFO org.apache.hadoop.yarn.server.resourcemanager.scheduler.capacity.LeafQueue: assignedContainer application=application_1375792971633_0006 container=Container: [ContainerId: container_1375792971633_0006_01_000005, NodeId: hadoop-110-5:54830, NodeHttpAddress: hadoop-110-5:8042, Resource: <memory:1024, vCores:1>, Priority: 20, State: NEW, Token: null, Status: container_id {, app_attempt_id {, application_id {, id: 6, cluster_timestamp: 1375792971633, }, attemptId: 1, }, id: 5, }, state: C_NEW, ] containerId=container_1375792971633_0006_01_000005 queue=default: capacity=1.0, absoluteCapacity=1.0, usedResources=<memory:29696, vCores:24>usedCapacity=0.6041667, absoluteUsedCapacity=0.6041667, numApps=5, numContainers=24 usedCapacity=0.6041667 absoluteUsedCapacity=0.6041667 used=<memory:29696, vCores:24> cluster=<memory:49152, vCores:96>
2013-08-06 12:58:01,200 INFO org.apache.hadoop.yarn.server.resourcemanager.scheduler.capacity.ParentQueue: Re-sorting queues since queue: root.default stats: default: capacity=1.0, absoluteCapacity=1.0, usedResources=<memory:30720, vCores:25>usedCapacity=0.625, absoluteUsedCapacity=0.625, numApps=5, numContainers=25
2013-08-06 12:58:01,200 INFO org.apache.hadoop.yarn.server.resourcemanager.scheduler.capacity.ParentQueue: assignedContainer queue=root usedCapacity=0.625 absoluteUsedCapacity=0.625 used=<memory:30720, vCores:25> cluster=<memory:49152, vCores:96>
2013-08-06 12:58:01,201 INFO org.apache.hadoop.yarn.server.resourcemanager.rmcontainer.RMContainerImpl: container_1375792971633_0006_01_000006 Container Transitioned from NEW to ALLOCATED
2013-08-06 12:58:01,201 INFO org.apache.hadoop.yarn.server.resourcemanager.RMAuditLogger: USER=ubuntu	OPERATION=AM Allocated Container	TARGET=SchedulerApp	RESULT=SUCCESS	APPID=application_1375792971633_0006	CONTAINERID=container_1375792971633_0006_01_000006
2013-08-06 12:58:01,201 INFO org.apache.hadoop.yarn.server.resourcemanager.scheduler.common.fica.FiCaSchedulerNode: Assigned container container_1375792971633_0006_01_000006 of capacity <memory:1024, vCores:1> on host hadoop-110-5:54830, which currently has 5 containers, <memory:5120, vCores:5> used and <memory:3072, vCores:11> available
2013-08-06 12:58:01,202 INFO org.apache.hadoop.yarn.server.resourcemanager.scheduler.capacity.LeafQueue: assignedContainer application=application_1375792971633_0006 container=Container: [ContainerId: container_1375792971633_0006_01_000006, NodeId: hadoop-110-5:54830, NodeHttpAddress: hadoop-110-5:8042, Resource: <memory:1024, vCores:1>, Priority: 20, State: NEW, Token: null, Status: container_id {, app_attempt_id {, application_id {, id: 6, cluster_timestamp: 1375792971633, }, attemptId: 1, }, id: 6, }, state: C_NEW, ] containerId=container_1375792971633_0006_01_000006 queue=default: capacity=1.0, absoluteCapacity=1.0, usedResources=<memory:30720, vCores:25>usedCapacity=0.625, absoluteUsedCapacity=0.625, numApps=5, numContainers=25 usedCapacity=0.625 absoluteUsedCapacity=0.625 used=<memory:30720, vCores:25> cluster=<memory:49152, vCores:96>
2013-08-06 12:58:01,203 INFO org.apache.hadoop.yarn.server.resourcemanager.scheduler.capacity.ParentQueue: Re-sorting queues since queue: root.default stats: default: capacity=1.0, absoluteCapacity=1.0, usedResources=<memory:31744, vCores:26>usedCapacity=0.6458333, absoluteUsedCapacity=0.6458333, numApps=5, numContainers=26
2013-08-06 12:58:01,203 INFO org.apache.hadoop.yarn.server.resourcemanager.scheduler.capacity.ParentQueue: assignedContainer queue=root usedCapacity=0.6458333 absoluteUsedCapacity=0.6458333 used=<memory:31744, vCores:26> cluster=<memory:49152, vCores:96>
2013-08-06 12:58:01,203 INFO org.apache.hadoop.yarn.server.resourcemanager.rmcontainer.RMContainerImpl: container_1375792971633_0006_01_000007 Container Transitioned from NEW to ALLOCATED
2013-08-06 12:58:01,203 INFO org.apache.hadoop.yarn.server.resourcemanager.RMAuditLogger: USER=ubuntu	OPERATION=AM Allocated Container	TARGET=SchedulerApp	RESULT=SUCCESS	APPID=application_1375792971633_0006	CONTAINERID=container_1375792971633_0006_01_000007
2013-08-06 12:58:01,204 INFO org.apache.hadoop.yarn.server.resourcemanager.scheduler.common.fica.FiCaSchedulerNode: Assigned container container_1375792971633_0006_01_000007 of capacity <memory:1024, vCores:1> on host hadoop-110-5:54830, which currently has 6 containers, <memory:6144, vCores:6> used and <memory:2048, vCores:10> available
2013-08-06 12:58:01,204 INFO org.apache.hadoop.yarn.server.resourcemanager.scheduler.capacity.LeafQueue: assignedContainer application=application_1375792971633_0006 container=Container: [ContainerId: container_1375792971633_0006_01_000007, NodeId: hadoop-110-5:54830, NodeHttpAddress: hadoop-110-5:8042, Resource: <memory:1024, vCores:1>, Priority: 20, State: NEW, Token: null, Status: container_id {, app_attempt_id {, application_id {, id: 6, cluster_timestamp: 1375792971633, }, attemptId: 1, }, id: 7, }, state: C_NEW, ] containerId=container_1375792971633_0006_01_000007 queue=default: capacity=1.0, absoluteCapacity=1.0, usedResources=<memory:31744, vCores:26>usedCapacity=0.6458333, absoluteUsedCapacity=0.6458333, numApps=5, numContainers=26 usedCapacity=0.6458333 absoluteUsedCapacity=0.6458333 used=<memory:31744, vCores:26> cluster=<memory:49152, vCores:96>
2013-08-06 12:58:01,205 INFO org.apache.hadoop.yarn.server.resourcemanager.scheduler.capacity.ParentQueue: Re-sorting queues since queue: root.default stats: default: capacity=1.0, absoluteCapacity=1.0, usedResources=<memory:32768, vCores:27>usedCapacity=0.6666667, absoluteUsedCapacity=0.6666667, numApps=5, numContainers=27
2013-08-06 12:58:01,205 INFO org.apache.hadoop.yarn.server.resourcemanager.scheduler.capacity.ParentQueue: assignedContainer queue=root usedCapacity=0.6666667 absoluteUsedCapacity=0.6666667 used=<memory:32768, vCores:27> cluster=<memory:49152, vCores:96>
2013-08-06 12:58:01,206 INFO org.apache.hadoop.yarn.server.resourcemanager.rmcontainer.RMContainerImpl: container_1375792971633_0006_01_000008 Container Transitioned from NEW to ALLOCATED
2013-08-06 12:58:01,206 INFO org.apache.hadoop.yarn.server.resourcemanager.RMAuditLogger: USER=ubuntu	OPERATION=AM Allocated Container	TARGET=SchedulerApp	RESULT=SUCCESS	APPID=application_1375792971633_0006	CONTAINERID=container_1375792971633_0006_01_000008
2013-08-06 12:58:01,206 INFO org.apache.hadoop.yarn.server.resourcemanager.scheduler.common.fica.FiCaSchedulerNode: Assigned container container_1375792971633_0006_01_000008 of capacity <memory:1024, vCores:1> on host hadoop-110-5:54830, which currently has 7 containers, <memory:7168, vCores:7> used and <memory:1024, vCores:9> available
2013-08-06 12:58:01,207 INFO org.apache.hadoop.yarn.server.resourcemanager.scheduler.capacity.LeafQueue: assignedContainer application=application_1375792971633_0006 container=Container: [ContainerId: container_1375792971633_0006_01_000008, NodeId: hadoop-110-5:54830, NodeHttpAddress: hadoop-110-5:8042, Resource: <memory:1024, vCores:1>, Priority: 20, State: NEW, Token: null, Status: container_id {, app_attempt_id {, application_id {, id: 6, cluster_timestamp: 1375792971633, }, attemptId: 1, }, id: 8, }, state: C_NEW, ] containerId=container_1375792971633_0006_01_000008 queue=default: capacity=1.0, absoluteCapacity=1.0, usedResources=<memory:32768, vCores:27>usedCapacity=0.6666667, absoluteUsedCapacity=0.6666667, numApps=5, numContainers=27 usedCapacity=0.6666667 absoluteUsedCapacity=0.6666667 used=<memory:32768, vCores:27> cluster=<memory:49152, vCores:96>
2013-08-06 12:58:01,207 INFO org.apache.hadoop.yarn.server.resourcemanager.scheduler.capacity.ParentQueue: Re-sorting queues since queue: root.default stats: default: capacity=1.0, absoluteCapacity=1.0, usedResources=<memory:33792, vCores:28>usedCapacity=0.6875, absoluteUsedCapacity=0.6875, numApps=5, numContainers=28
2013-08-06 12:58:01,207 INFO org.apache.hadoop.yarn.server.resourcemanager.scheduler.capacity.ParentQueue: assignedContainer queue=root usedCapacity=0.6875 absoluteUsedCapacity=0.6875 used=<memory:33792, vCores:28> cluster=<memory:49152, vCores:96>
2013-08-06 12:58:01,208 INFO org.apache.hadoop.yarn.server.resourcemanager.rmcontainer.RMContainerImpl: container_1375792971633_0006_01_000009 Container Transitioned from NEW to ALLOCATED
2013-08-06 12:58:01,208 INFO org.apache.hadoop.yarn.server.resourcemanager.RMAuditLogger: USER=ubuntu	OPERATION=AM Allocated Container	TARGET=SchedulerApp	RESULT=SUCCESS	APPID=application_1375792971633_0006	CONTAINERID=container_1375792971633_0006_01_000009
2013-08-06 12:58:01,208 INFO org.apache.hadoop.yarn.server.resourcemanager.scheduler.common.fica.FiCaSchedulerNode: Assigned container container_1375792971633_0006_01_000009 of capacity <memory:1024, vCores:1> on host hadoop-110-5:54830, which currently has 8 containers, <memory:8192, vCores:8> used and <memory:0, vCores:8> available
2013-08-06 12:58:01,209 INFO org.apache.hadoop.yarn.server.resourcemanager.scheduler.capacity.LeafQueue: assignedContainer application=application_1375792971633_0006 container=Container: [ContainerId: container_1375792971633_0006_01_000009, NodeId: hadoop-110-5:54830, NodeHttpAddress: hadoop-110-5:8042, Resource: <memory:1024, vCores:1>, Priority: 20, State: NEW, Token: null, Status: container_id {, app_attempt_id {, application_id {, id: 6, cluster_timestamp: 1375792971633, }, attemptId: 1, }, id: 9, }, state: C_NEW, ] containerId=container_1375792971633_0006_01_000009 queue=default: capacity=1.0, absoluteCapacity=1.0, usedResources=<memory:33792, vCores:28>usedCapacity=0.6875, absoluteUsedCapacity=0.6875, numApps=5, numContainers=28 usedCapacity=0.6875 absoluteUsedCapacity=0.6875 used=<memory:33792, vCores:28> cluster=<memory:49152, vCores:96>
2013-08-06 12:58:01,209 INFO org.apache.hadoop.yarn.server.resourcemanager.scheduler.capacity.ParentQueue: Re-sorting queues since queue: root.default stats: default: capacity=1.0, absoluteCapacity=1.0, usedResources=<memory:34816, vCores:29>usedCapacity=0.7083333, absoluteUsedCapacity=0.7083333, numApps=5, numContainers=29
2013-08-06 12:58:01,209 INFO org.apache.hadoop.yarn.server.resourcemanager.scheduler.capacity.ParentQueue: assignedContainer queue=root usedCapacity=0.7083333 absoluteUsedCapacity=0.7083333 used=<memory:34816, vCores:29> cluster=<memory:49152, vCores:96>
2013-08-06 12:58:01,259 INFO org.apache.hadoop.yarn.server.resourcemanager.rmcontainer.RMContainerImpl: container_1375792971633_0006_01_000010 Container Transitioned from NEW to ALLOCATED
2013-08-06 12:58:01,259 INFO org.apache.hadoop.yarn.server.resourcemanager.RMAuditLogger: USER=ubuntu	OPERATION=AM Allocated Container	TARGET=SchedulerApp	RESULT=SUCCESS	APPID=application_1375792971633_0006	CONTAINERID=container_1375792971633_0006_01_000010
2013-08-06 12:58:01,259 INFO org.apache.hadoop.yarn.server.resourcemanager.scheduler.common.fica.FiCaSchedulerNode: Assigned container container_1375792971633_0006_01_000010 of capacity <memory:1024, vCores:1> on host hadoop-110-6:50003, which currently has 2 containers, <memory:3072, vCores:2> used and <memory:5120, vCores:14> available
2013-08-06 12:58:01,260 INFO org.apache.hadoop.yarn.server.resourcemanager.scheduler.capacity.LeafQueue: assignedContainer application=application_1375792971633_0006 container=Container: [ContainerId: container_1375792971633_0006_01_000010, NodeId: hadoop-110-6:50003, NodeHttpAddress: hadoop-110-6:8042, Resource: <memory:1024, vCores:1>, Priority: 20, State: NEW, Token: null, Status: container_id {, app_attempt_id {, application_id {, id: 6, cluster_timestamp: 1375792971633, }, attemptId: 1, }, id: 10, }, state: C_NEW, ] containerId=container_1375792971633_0006_01_000010 queue=default: capacity=1.0, absoluteCapacity=1.0, usedResources=<memory:34816, vCores:29>usedCapacity=0.7083333, absoluteUsedCapacity=0.7083333, numApps=5, numContainers=29 usedCapacity=0.7083333 absoluteUsedCapacity=0.7083333 used=<memory:34816, vCores:29> cluster=<memory:49152, vCores:96>
2013-08-06 12:58:01,260 INFO org.apache.hadoop.yarn.server.resourcemanager.scheduler.capacity.ParentQueue: Re-sorting queues since queue: root.default stats: default: capacity=1.0, absoluteCapacity=1.0, usedResources=<memory:35840, vCores:30>usedCapacity=0.7291667, absoluteUsedCapacity=0.7291667, numApps=5, numContainers=30
2013-08-06 12:58:01,261 INFO org.apache.hadoop.yarn.server.resourcemanager.scheduler.capacity.ParentQueue: assignedContainer queue=root usedCapacity=0.7291667 absoluteUsedCapacity=0.7291667 used=<memory:35840, vCores:30> cluster=<memory:49152, vCores:96>
2013-08-06 12:58:01,261 INFO org.apache.hadoop.yarn.server.resourcemanager.rmcontainer.RMContainerImpl: container_1375792971633_0006_01_000011 Container Transitioned from NEW to ALLOCATED
2013-08-06 12:58:01,261 INFO org.apache.hadoop.yarn.server.resourcemanager.RMAuditLogger: USER=ubuntu	OPERATION=AM Allocated Container	TARGET=SchedulerApp	RESULT=SUCCESS	APPID=application_1375792971633_0006	CONTAINERID=container_1375792971633_0006_01_000011
2013-08-06 12:58:01,261 INFO org.apache.hadoop.yarn.server.resourcemanager.scheduler.common.fica.FiCaSchedulerNode: Assigned container container_1375792971633_0006_01_000011 of capacity <memory:1024, vCores:1> on host hadoop-110-6:50003, which currently has 3 containers, <memory:4096, vCores:3> used and <memory:4096, vCores:13> available
2013-08-06 12:58:01,262 INFO org.apache.hadoop.yarn.server.resourcemanager.scheduler.capacity.LeafQueue: assignedContainer application=application_1375792971633_0006 container=Container: [ContainerId: container_1375792971633_0006_01_000011, NodeId: hadoop-110-6:50003, NodeHttpAddress: hadoop-110-6:8042, Resource: <memory:1024, vCores:1>, Priority: 20, State: NEW, Token: null, Status: container_id {, app_attempt_id {, application_id {, id: 6, cluster_timestamp: 1375792971633, }, attemptId: 1, }, id: 11, }, state: C_NEW, ] containerId=container_1375792971633_0006_01_000011 queue=default: capacity=1.0, absoluteCapacity=1.0, usedResources=<memory:35840, vCores:30>usedCapacity=0.7291667, absoluteUsedCapacity=0.7291667, numApps=5, numContainers=30 usedCapacity=0.7291667 absoluteUsedCapacity=0.7291667 used=<memory:35840, vCores:30> cluster=<memory:49152, vCores:96>
2013-08-06 12:58:01,262 INFO org.apache.hadoop.yarn.server.resourcemanager.scheduler.capacity.ParentQueue: Re-sorting queues since queue: root.default stats: default: capacity=1.0, absoluteCapacity=1.0, usedResources=<memory:36864, vCores:31>usedCapacity=0.75, absoluteUsedCapacity=0.75, numApps=5, numContainers=31
2013-08-06 12:58:01,263 INFO org.apache.hadoop.yarn.server.resourcemanager.scheduler.capacity.ParentQueue: assignedContainer queue=root usedCapacity=0.75 absoluteUsedCapacity=0.75 used=<memory:36864, vCores:31> cluster=<memory:49152, vCores:96>
2013-08-06 12:58:01,263 INFO org.apache.hadoop.yarn.server.resourcemanager.rmcontainer.RMContainerImpl: container_1375792971633_0006_01_000012 Container Transitioned from NEW to ALLOCATED
2013-08-06 12:58:01,263 INFO org.apache.hadoop.yarn.server.resourcemanager.RMAuditLogger: USER=ubuntu	OPERATION=AM Allocated Container	TARGET=SchedulerApp	RESULT=SUCCESS	APPID=application_1375792971633_0006	CONTAINERID=container_1375792971633_0006_01_000012
2013-08-06 12:58:01,263 INFO org.apache.hadoop.yarn.server.resourcemanager.scheduler.common.fica.FiCaSchedulerNode: Assigned container container_1375792971633_0006_01_000012 of capacity <memory:1024, vCores:1> on host hadoop-110-6:50003, which currently has 4 containers, <memory:5120, vCores:4> used and <memory:3072, vCores:12> available
2013-08-06 12:58:01,264 INFO org.apache.hadoop.yarn.server.resourcemanager.scheduler.capacity.LeafQueue: assignedContainer application=application_1375792971633_0006 container=Container: [ContainerId: container_1375792971633_0006_01_000012, NodeId: hadoop-110-6:50003, NodeHttpAddress: hadoop-110-6:8042, Resource: <memory:1024, vCores:1>, Priority: 20, State: NEW, Token: null, Status: container_id {, app_attempt_id {, application_id {, id: 6, cluster_timestamp: 1375792971633, }, attemptId: 1, }, id: 12, }, state: C_NEW, ] containerId=container_1375792971633_0006_01_000012 queue=default: capacity=1.0, absoluteCapacity=1.0, usedResources=<memory:36864, vCores:31>usedCapacity=0.75, absoluteUsedCapacity=0.75, numApps=5, numContainers=31 usedCapacity=0.75 absoluteUsedCapacity=0.75 used=<memory:36864, vCores:31> cluster=<memory:49152, vCores:96>
2013-08-06 12:58:01,265 INFO org.apache.hadoop.yarn.server.resourcemanager.scheduler.capacity.ParentQueue: Re-sorting queues since queue: root.default stats: default: capacity=1.0, absoluteCapacity=1.0, usedResources=<memory:37888, vCores:32>usedCapacity=0.7708333, absoluteUsedCapacity=0.7708333, numApps=5, numContainers=32
2013-08-06 12:58:01,265 INFO org.apache.hadoop.yarn.server.resourcemanager.scheduler.capacity.ParentQueue: assignedContainer queue=root usedCapacity=0.7708333 absoluteUsedCapacity=0.7708333 used=<memory:37888, vCores:32> cluster=<memory:49152, vCores:96>
2013-08-06 12:58:01,265 INFO org.apache.hadoop.yarn.server.resourcemanager.rmcontainer.RMContainerImpl: container_1375792971633_0006_01_000013 Container Transitioned from NEW to ALLOCATED
2013-08-06 12:58:01,266 INFO org.apache.hadoop.yarn.server.resourcemanager.RMAuditLogger: USER=ubuntu	OPERATION=AM Allocated Container	TARGET=SchedulerApp	RESULT=SUCCESS	APPID=application_1375792971633_0006	CONTAINERID=container_1375792971633_0006_01_000013
2013-08-06 12:58:01,266 INFO org.apache.hadoop.yarn.server.resourcemanager.scheduler.common.fica.FiCaSchedulerNode: Assigned container container_1375792971633_0006_01_000013 of capacity <memory:1024, vCores:1> on host hadoop-110-6:50003, which currently has 5 containers, <memory:6144, vCores:5> used and <memory:2048, vCores:11> available
2013-08-06 12:58:01,267 INFO org.apache.hadoop.yarn.server.resourcemanager.scheduler.capacity.LeafQueue: assignedContainer application=application_1375792971633_0006 container=Container: [ContainerId: container_1375792971633_0006_01_000013, NodeId: hadoop-110-6:50003, NodeHttpAddress: hadoop-110-6:8042, Resource: <memory:1024, vCores:1>, Priority: 20, State: NEW, Token: null, Status: container_id {, app_attempt_id {, application_id {, id: 6, cluster_timestamp: 1375792971633, }, attemptId: 1, }, id: 13, }, state: C_NEW, ] containerId=container_1375792971633_0006_01_000013 queue=default: capacity=1.0, absoluteCapacity=1.0, usedResources=<memory:37888, vCores:32>usedCapacity=0.7708333, absoluteUsedCapacity=0.7708333, numApps=5, numContainers=32 usedCapacity=0.7708333 absoluteUsedCapacity=0.7708333 used=<memory:37888, vCores:32> cluster=<memory:49152, vCores:96>
2013-08-06 12:58:01,267 INFO org.apache.hadoop.yarn.server.resourcemanager.scheduler.capacity.ParentQueue: Re-sorting queues since queue: root.default stats: default: capacity=1.0, absoluteCapacity=1.0, usedResources=<memory:38912, vCores:33>usedCapacity=0.7916667, absoluteUsedCapacity=0.7916667, numApps=5, numContainers=33
2013-08-06 12:58:01,267 INFO org.apache.hadoop.yarn.server.resourcemanager.scheduler.capacity.ParentQueue: assignedContainer queue=root usedCapacity=0.7916667 absoluteUsedCapacity=0.7916667 used=<memory:38912, vCores:33> cluster=<memory:49152, vCores:96>
2013-08-06 12:58:01,268 INFO org.apache.hadoop.yarn.server.resourcemanager.rmcontainer.RMContainerImpl: container_1375792971633_0006_01_000014 Container Transitioned from NEW to ALLOCATED
2013-08-06 12:58:01,268 INFO org.apache.hadoop.yarn.server.resourcemanager.RMAuditLogger: USER=ubuntu	OPERATION=AM Allocated Container	TARGET=SchedulerApp	RESULT=SUCCESS	APPID=application_1375792971633_0006	CONTAINERID=container_1375792971633_0006_01_000014
2013-08-06 12:58:01,268 INFO org.apache.hadoop.yarn.server.resourcemanager.scheduler.common.fica.FiCaSchedulerNode: Assigned container container_1375792971633_0006_01_000014 of capacity <memory:1024, vCores:1> on host hadoop-110-6:50003, which currently has 6 containers, <memory:7168, vCores:6> used and <memory:1024, vCores:10> available
2013-08-06 12:58:01,269 INFO org.apache.hadoop.yarn.server.resourcemanager.scheduler.capacity.LeafQueue: assignedContainer application=application_1375792971633_0006 container=Container: [ContainerId: container_1375792971633_0006_01_000014, NodeId: hadoop-110-6:50003, NodeHttpAddress: hadoop-110-6:8042, Resource: <memory:1024, vCores:1>, Priority: 20, State: NEW, Token: null, Status: container_id {, app_attempt_id {, application_id {, id: 6, cluster_timestamp: 1375792971633, }, attemptId: 1, }, id: 14, }, state: C_NEW, ] containerId=container_1375792971633_0006_01_000014 queue=default: capacity=1.0, absoluteCapacity=1.0, usedResources=<memory:38912, vCores:33>usedCapacity=0.7916667, absoluteUsedCapacity=0.7916667, numApps=5, numContainers=33 usedCapacity=0.7916667 absoluteUsedCapacity=0.7916667 used=<memory:38912, vCores:33> cluster=<memory:49152, vCores:96>
2013-08-06 12:58:01,269 INFO org.apache.hadoop.yarn.server.resourcemanager.scheduler.capacity.ParentQueue: Re-sorting queues since queue: root.default stats: default: capacity=1.0, absoluteCapacity=1.0, usedResources=<memory:39936, vCores:34>usedCapacity=0.8125, absoluteUsedCapacity=0.8125, numApps=5, numContainers=34
2013-08-06 12:58:01,269 INFO org.apache.hadoop.yarn.server.resourcemanager.scheduler.capacity.ParentQueue: assignedContainer queue=root usedCapacity=0.8125 absoluteUsedCapacity=0.8125 used=<memory:39936, vCores:34> cluster=<memory:49152, vCores:96>
2013-08-06 12:58:01,270 INFO org.apache.hadoop.yarn.server.resourcemanager.rmcontainer.RMContainerImpl: container_1375792971633_0006_01_000015 Container Transitioned from NEW to ALLOCATED
2013-08-06 12:58:01,270 INFO org.apache.hadoop.yarn.server.resourcemanager.RMAuditLogger: USER=ubuntu	OPERATION=AM Allocated Container	TARGET=SchedulerApp	RESULT=SUCCESS	APPID=application_1375792971633_0006	CONTAINERID=container_1375792971633_0006_01_000015
2013-08-06 12:58:01,270 INFO org.apache.hadoop.yarn.server.resourcemanager.scheduler.common.fica.FiCaSchedulerNode: Assigned container container_1375792971633_0006_01_000015 of capacity <memory:1024, vCores:1> on host hadoop-110-6:50003, which currently has 7 containers, <memory:8192, vCores:7> used and <memory:0, vCores:9> available
2013-08-06 12:58:01,271 INFO org.apache.hadoop.yarn.server.resourcemanager.scheduler.capacity.LeafQueue: assignedContainer application=application_1375792971633_0006 container=Container: [ContainerId: container_1375792971633_0006_01_000015, NodeId: hadoop-110-6:50003, NodeHttpAddress: hadoop-110-6:8042, Resource: <memory:1024, vCores:1>, Priority: 20, State: NEW, Token: null, Status: container_id {, app_attempt_id {, application_id {, id: 6, cluster_timestamp: 1375792971633, }, attemptId: 1, }, id: 15, }, state: C_NEW, ] containerId=container_1375792971633_0006_01_000015 queue=default: capacity=1.0, absoluteCapacity=1.0, usedResources=<memory:39936, vCores:34>usedCapacity=0.8125, absoluteUsedCapacity=0.8125, numApps=5, numContainers=34 usedCapacity=0.8125 absoluteUsedCapacity=0.8125 used=<memory:39936, vCores:34> cluster=<memory:49152, vCores:96>
2013-08-06 12:58:01,271 INFO org.apache.hadoop.yarn.server.resourcemanager.scheduler.capacity.ParentQueue: Re-sorting queues since queue: root.default stats: default: capacity=1.0, absoluteCapacity=1.0, usedResources=<memory:40960, vCores:35>usedCapacity=0.8333333, absoluteUsedCapacity=0.8333333, numApps=5, numContainers=35
2013-08-06 12:58:01,272 INFO org.apache.hadoop.yarn.server.resourcemanager.scheduler.capacity.ParentQueue: assignedContainer queue=root usedCapacity=0.8333333 absoluteUsedCapacity=0.8333333 used=<memory:40960, vCores:35> cluster=<memory:49152, vCores:96>
2013-08-06 12:58:01,320 INFO org.apache.hadoop.yarn.server.resourcemanager.rmcontainer.RMContainerImpl: container_1375792971633_0006_01_000016 Container Transitioned from NEW to ALLOCATED
2013-08-06 12:58:01,320 INFO org.apache.hadoop.yarn.server.resourcemanager.RMAuditLogger: USER=ubuntu	OPERATION=AM Allocated Container	TARGET=SchedulerApp	RESULT=SUCCESS	APPID=application_1375792971633_0006	CONTAINERID=container_1375792971633_0006_01_000016
2013-08-06 12:58:01,320 INFO org.apache.hadoop.yarn.server.resourcemanager.scheduler.common.fica.FiCaSchedulerNode: Assigned container container_1375792971633_0006_01_000016 of capacity <memory:1024, vCores:1> on host hadoop-110-2:50749, which currently has 1 containers, <memory:1024, vCores:1> used and <memory:7168, vCores:15> available
2013-08-06 12:58:01,322 INFO org.apache.hadoop.yarn.server.resourcemanager.scheduler.capacity.LeafQueue: assignedContainer application=application_1375792971633_0006 container=Container: [ContainerId: container_1375792971633_0006_01_000016, NodeId: hadoop-110-2:50749, NodeHttpAddress: hadoop-110-2:8042, Resource: <memory:1024, vCores:1>, Priority: 20, State: NEW, Token: null, Status: container_id {, app_attempt_id {, application_id {, id: 6, cluster_timestamp: 1375792971633, }, attemptId: 1, }, id: 16, }, state: C_NEW, ] containerId=container_1375792971633_0006_01_000016 queue=default: capacity=1.0, absoluteCapacity=1.0, usedResources=<memory:40960, vCores:35>usedCapacity=0.8333333, absoluteUsedCapacity=0.8333333, numApps=5, numContainers=35 usedCapacity=0.8333333 absoluteUsedCapacity=0.8333333 used=<memory:40960, vCores:35> cluster=<memory:49152, vCores:96>
2013-08-06 12:58:01,322 INFO org.apache.hadoop.yarn.server.resourcemanager.scheduler.capacity.ParentQueue: Re-sorting queues since queue: root.default stats: default: capacity=1.0, absoluteCapacity=1.0, usedResources=<memory:41984, vCores:36>usedCapacity=0.8541667, absoluteUsedCapacity=0.8541667, numApps=5, numContainers=36
2013-08-06 12:58:01,322 INFO org.apache.hadoop.yarn.server.resourcemanager.scheduler.capacity.ParentQueue: assignedContainer queue=root usedCapacity=0.8541667 absoluteUsedCapacity=0.8541667 used=<memory:41984, vCores:36> cluster=<memory:49152, vCores:96>
2013-08-06 12:58:01,322 INFO org.apache.hadoop.yarn.server.resourcemanager.rmcontainer.RMContainerImpl: container_1375792971633_0006_01_000017 Container Transitioned from NEW to ALLOCATED
2013-08-06 12:58:01,323 INFO org.apache.hadoop.yarn.server.resourcemanager.RMAuditLogger: USER=ubuntu	OPERATION=AM Allocated Container	TARGET=SchedulerApp	RESULT=SUCCESS	APPID=application_1375792971633_0006	CONTAINERID=container_1375792971633_0006_01_000017
2013-08-06 12:58:01,323 INFO org.apache.hadoop.yarn.server.resourcemanager.scheduler.common.fica.FiCaSchedulerNode: Assigned container container_1375792971633_0006_01_000017 of capacity <memory:1024, vCores:1> on host hadoop-110-2:50749, which currently has 2 containers, <memory:2048, vCores:2> used and <memory:6144, vCores:14> available
2013-08-06 12:58:01,324 INFO org.apache.hadoop.yarn.server.resourcemanager.scheduler.capacity.LeafQueue: assignedContainer application=application_1375792971633_0006 container=Container: [ContainerId: container_1375792971633_0006_01_000017, NodeId: hadoop-110-2:50749, NodeHttpAddress: hadoop-110-2:8042, Resource: <memory:1024, vCores:1>, Priority: 20, State: NEW, Token: null, Status: container_id {, app_attempt_id {, application_id {, id: 6, cluster_timestamp: 1375792971633, }, attemptId: 1, }, id: 17, }, state: C_NEW, ] containerId=container_1375792971633_0006_01_000017 queue=default: capacity=1.0, absoluteCapacity=1.0, usedResources=<memory:41984, vCores:36>usedCapacity=0.8541667, absoluteUsedCapacity=0.8541667, numApps=5, numContainers=36 usedCapacity=0.8541667 absoluteUsedCapacity=0.8541667 used=<memory:41984, vCores:36> cluster=<memory:49152, vCores:96>
2013-08-06 12:58:01,324 INFO org.apache.hadoop.yarn.server.resourcemanager.scheduler.capacity.ParentQueue: Re-sorting queues since queue: root.default stats: default: capacity=1.0, absoluteCapacity=1.0, usedResources=<memory:43008, vCores:37>usedCapacity=0.875, absoluteUsedCapacity=0.875, numApps=5, numContainers=37
2013-08-06 12:58:01,324 INFO org.apache.hadoop.yarn.server.resourcemanager.scheduler.capacity.ParentQueue: assignedContainer queue=root usedCapacity=0.875 absoluteUsedCapacity=0.875 used=<memory:43008, vCores:37> cluster=<memory:49152, vCores:96>
2013-08-06 12:58:01,325 INFO org.apache.hadoop.yarn.server.resourcemanager.rmcontainer.RMContainerImpl: container_1375792971633_0006_01_000018 Container Transitioned from NEW to ALLOCATED
2013-08-06 12:58:01,325 INFO org.apache.hadoop.yarn.server.resourcemanager.RMAuditLogger: USER=ubuntu	OPERATION=AM Allocated Container	TARGET=SchedulerApp	RESULT=SUCCESS	APPID=application_1375792971633_0006	CONTAINERID=container_1375792971633_0006_01_000018
2013-08-06 12:58:01,325 INFO org.apache.hadoop.yarn.server.resourcemanager.scheduler.common.fica.FiCaSchedulerNode: Assigned container container_1375792971633_0006_01_000018 of capacity <memory:1024, vCores:1> on host hadoop-110-2:50749, which currently has 3 containers, <memory:3072, vCores:3> used and <memory:5120, vCores:13> available
2013-08-06 12:58:01,326 INFO org.apache.hadoop.yarn.server.resourcemanager.scheduler.capacity.LeafQueue: assignedContainer application=application_1375792971633_0006 container=Container: [ContainerId: container_1375792971633_0006_01_000018, NodeId: hadoop-110-2:50749, NodeHttpAddress: hadoop-110-2:8042, Resource: <memory:1024, vCores:1>, Priority: 20, State: NEW, Token: null, Status: container_id {, app_attempt_id {, application_id {, id: 6, cluster_timestamp: 1375792971633, }, attemptId: 1, }, id: 18, }, state: C_NEW, ] containerId=container_1375792971633_0006_01_000018 queue=default: capacity=1.0, absoluteCapacity=1.0, usedResources=<memory:43008, vCores:37>usedCapacity=0.875, absoluteUsedCapacity=0.875, numApps=5, numContainers=37 usedCapacity=0.875 absoluteUsedCapacity=0.875 used=<memory:43008, vCores:37> cluster=<memory:49152, vCores:96>
2013-08-06 12:58:01,326 INFO org.apache.hadoop.yarn.server.resourcemanager.scheduler.capacity.ParentQueue: Re-sorting queues since queue: root.default stats: default: capacity=1.0, absoluteCapacity=1.0, usedResources=<memory:44032, vCores:38>usedCapacity=0.8958333, absoluteUsedCapacity=0.8958333, numApps=5, numContainers=38
2013-08-06 12:58:01,326 INFO org.apache.hadoop.yarn.server.resourcemanager.scheduler.capacity.ParentQueue: assignedContainer queue=root usedCapacity=0.8958333 absoluteUsedCapacity=0.8958333 used=<memory:44032, vCores:38> cluster=<memory:49152, vCores:96>
2013-08-06 12:58:01,327 INFO org.apache.hadoop.yarn.server.resourcemanager.rmcontainer.RMContainerImpl: container_1375792971633_0006_01_000019 Container Transitioned from NEW to ALLOCATED
2013-08-06 12:58:01,327 INFO org.apache.hadoop.yarn.server.resourcemanager.RMAuditLogger: USER=ubuntu	OPERATION=AM Allocated Container	TARGET=SchedulerApp	RESULT=SUCCESS	APPID=application_1375792971633_0006	CONTAINERID=container_1375792971633_0006_01_000019
2013-08-06 12:58:01,327 INFO org.apache.hadoop.yarn.server.resourcemanager.scheduler.common.fica.FiCaSchedulerNode: Assigned container container_1375792971633_0006_01_000019 of capacity <memory:1024, vCores:1> on host hadoop-110-2:50749, which currently has 4 containers, <memory:4096, vCores:4> used and <memory:4096, vCores:12> available
2013-08-06 12:58:01,328 INFO org.apache.hadoop.yarn.server.resourcemanager.scheduler.capacity.LeafQueue: assignedContainer application=application_1375792971633_0006 container=Container: [ContainerId: container_1375792971633_0006_01_000019, NodeId: hadoop-110-2:50749, NodeHttpAddress: hadoop-110-2:8042, Resource: <memory:1024, vCores:1>, Priority: 20, State: NEW, Token: null, Status: container_id {, app_attempt_id {, application_id {, id: 6, cluster_timestamp: 1375792971633, }, attemptId: 1, }, id: 19, }, state: C_NEW, ] containerId=container_1375792971633_0006_01_000019 queue=default: capacity=1.0, absoluteCapacity=1.0, usedResources=<memory:44032, vCores:38>usedCapacity=0.8958333, absoluteUsedCapacity=0.8958333, numApps=5, numContainers=38 usedCapacity=0.8958333 absoluteUsedCapacity=0.8958333 used=<memory:44032, vCores:38> cluster=<memory:49152, vCores:96>
2013-08-06 12:58:01,328 INFO org.apache.hadoop.yarn.server.resourcemanager.scheduler.capacity.ParentQueue: Re-sorting queues since queue: root.default stats: default: capacity=1.0, absoluteCapacity=1.0, usedResources=<memory:45056, vCores:39>usedCapacity=0.9166667, absoluteUsedCapacity=0.9166667, numApps=5, numContainers=39
2013-08-06 12:58:01,329 INFO org.apache.hadoop.yarn.server.resourcemanager.scheduler.capacity.ParentQueue: assignedContainer queue=root usedCapacity=0.9166667 absoluteUsedCapacity=0.9166667 used=<memory:45056, vCores:39> cluster=<memory:49152, vCores:96>
2013-08-06 12:58:01,329 INFO org.apache.hadoop.yarn.server.resourcemanager.rmcontainer.RMContainerImpl: container_1375792971633_0006_01_000020 Container Transitioned from NEW to ALLOCATED
2013-08-06 12:58:01,329 INFO org.apache.hadoop.yarn.server.resourcemanager.RMAuditLogger: USER=ubuntu	OPERATION=AM Allocated Container	TARGET=SchedulerApp	RESULT=SUCCESS	APPID=application_1375792971633_0006	CONTAINERID=container_1375792971633_0006_01_000020
2013-08-06 12:58:01,330 INFO org.apache.hadoop.yarn.server.resourcemanager.scheduler.common.fica.FiCaSchedulerNode: Assigned container container_1375792971633_0006_01_000020 of capacity <memory:1024, vCores:1> on host hadoop-110-2:50749, which currently has 5 containers, <memory:5120, vCores:5> used and <memory:3072, vCores:11> available
2013-08-06 12:58:01,330 INFO org.apache.hadoop.yarn.server.resourcemanager.scheduler.capacity.LeafQueue: assignedContainer application=application_1375792971633_0006 container=Container: [ContainerId: container_1375792971633_0006_01_000020, NodeId: hadoop-110-2:50749, NodeHttpAddress: hadoop-110-2:8042, Resource: <memory:1024, vCores:1>, Priority: 20, State: NEW, Token: null, Status: container_id {, app_attempt_id {, application_id {, id: 6, cluster_timestamp: 1375792971633, }, attemptId: 1, }, id: 20, }, state: C_NEW, ] containerId=container_1375792971633_0006_01_000020 queue=default: capacity=1.0, absoluteCapacity=1.0, usedResources=<memory:45056, vCores:39>usedCapacity=0.9166667, absoluteUsedCapacity=0.9166667, numApps=5, numContainers=39 usedCapacity=0.9166667 absoluteUsedCapacity=0.9166667 used=<memory:45056, vCores:39> cluster=<memory:49152, vCores:96>
2013-08-06 12:58:01,331 INFO org.apache.hadoop.yarn.server.resourcemanager.scheduler.capacity.ParentQueue: Re-sorting queues since queue: root.default stats: default: capacity=1.0, absoluteCapacity=1.0, usedResources=<memory:46080, vCores:40>usedCapacity=0.9375, absoluteUsedCapacity=0.9375, numApps=5, numContainers=40
2013-08-06 12:58:01,331 INFO org.apache.hadoop.yarn.server.resourcemanager.scheduler.capacity.ParentQueue: assignedContainer queue=root usedCapacity=0.9375 absoluteUsedCapacity=0.9375 used=<memory:46080, vCores:40> cluster=<memory:49152, vCores:96>
2013-08-06 12:58:01,331 INFO org.apache.hadoop.yarn.server.resourcemanager.rmcontainer.RMContainerImpl: container_1375792971633_0006_01_000021 Container Transitioned from NEW to ALLOCATED
2013-08-06 12:58:01,331 INFO org.apache.hadoop.yarn.server.resourcemanager.RMAuditLogger: USER=ubuntu	OPERATION=AM Allocated Container	TARGET=SchedulerApp	RESULT=SUCCESS	APPID=application_1375792971633_0006	CONTAINERID=container_1375792971633_0006_01_000021
2013-08-06 12:58:01,332 INFO org.apache.hadoop.yarn.server.resourcemanager.scheduler.common.fica.FiCaSchedulerNode: Assigned container container_1375792971633_0006_01_000021 of capacity <memory:1024, vCores:1> on host hadoop-110-2:50749, which currently has 6 containers, <memory:6144, vCores:6> used and <memory:2048, vCores:10> available
2013-08-06 12:58:01,333 INFO org.apache.hadoop.yarn.server.resourcemanager.scheduler.capacity.LeafQueue: assignedContainer application=application_1375792971633_0006 container=Container: [ContainerId: container_1375792971633_0006_01_000021, NodeId: hadoop-110-2:50749, NodeHttpAddress: hadoop-110-2:8042, Resource: <memory:1024, vCores:1>, Priority: 20, State: NEW, Token: null, Status: container_id {, app_attempt_id {, application_id {, id: 6, cluster_timestamp: 1375792971633, }, attemptId: 1, }, id: 21, }, state: C_NEW, ] containerId=container_1375792971633_0006_01_000021 queue=default: capacity=1.0, absoluteCapacity=1.0, usedResources=<memory:46080, vCores:40>usedCapacity=0.9375, absoluteUsedCapacity=0.9375, numApps=5, numContainers=40 usedCapacity=0.9375 absoluteUsedCapacity=0.9375 used=<memory:46080, vCores:40> cluster=<memory:49152, vCores:96>
2013-08-06 12:58:01,333 INFO org.apache.hadoop.yarn.server.resourcemanager.scheduler.capacity.ParentQueue: Re-sorting queues since queue: root.default stats: default: capacity=1.0, absoluteCapacity=1.0, usedResources=<memory:47104, vCores:41>usedCapacity=0.9583333, absoluteUsedCapacity=0.9583333, numApps=5, numContainers=41
2013-08-06 12:58:01,333 INFO org.apache.hadoop.yarn.server.resourcemanager.scheduler.capacity.ParentQueue: assignedContainer queue=root usedCapacity=0.9583333 absoluteUsedCapacity=0.9583333 used=<memory:47104, vCores:41> cluster=<memory:49152, vCores:96>
2013-08-06 12:58:01,333 INFO org.apache.hadoop.yarn.server.resourcemanager.rmcontainer.RMContainerImpl: container_1375792971633_0006_01_000022 Container Transitioned from NEW to ALLOCATED
2013-08-06 12:58:01,334 INFO org.apache.hadoop.yarn.server.resourcemanager.RMAuditLogger: USER=ubuntu	OPERATION=AM Allocated Container	TARGET=SchedulerApp	RESULT=SUCCESS	APPID=application_1375792971633_0006	CONTAINERID=container_1375792971633_0006_01_000022
2013-08-06 12:58:01,334 INFO org.apache.hadoop.yarn.server.resourcemanager.scheduler.common.fica.FiCaSchedulerNode: Assigned container container_1375792971633_0006_01_000022 of capacity <memory:1024, vCores:1> on host hadoop-110-2:50749, which currently has 7 containers, <memory:7168, vCores:7> used and <memory:1024, vCores:9> available
2013-08-06 12:58:01,335 INFO org.apache.hadoop.yarn.server.resourcemanager.scheduler.capacity.LeafQueue: assignedContainer application=application_1375792971633_0006 container=Container: [ContainerId: container_1375792971633_0006_01_000022, NodeId: hadoop-110-2:50749, NodeHttpAddress: hadoop-110-2:8042, Resource: <memory:1024, vCores:1>, Priority: 20, State: NEW, Token: null, Status: container_id {, app_attempt_id {, application_id {, id: 6, cluster_timestamp: 1375792971633, }, attemptId: 1, }, id: 22, }, state: C_NEW, ] containerId=container_1375792971633_0006_01_000022 queue=default: capacity=1.0, absoluteCapacity=1.0, usedResources=<memory:47104, vCores:41>usedCapacity=0.9583333, absoluteUsedCapacity=0.9583333, numApps=5, numContainers=41 usedCapacity=0.9583333 absoluteUsedCapacity=0.9583333 used=<memory:47104, vCores:41> cluster=<memory:49152, vCores:96>
2013-08-06 12:58:01,335 INFO org.apache.hadoop.yarn.server.resourcemanager.scheduler.capacity.ParentQueue: Re-sorting queues since queue: root.default stats: default: capacity=1.0, absoluteCapacity=1.0, usedResources=<memory:48128, vCores:42>usedCapacity=0.9791667, absoluteUsedCapacity=0.9791667, numApps=5, numContainers=42
2013-08-06 12:58:01,335 INFO org.apache.hadoop.yarn.server.resourcemanager.scheduler.capacity.ParentQueue: assignedContainer queue=root usedCapacity=0.9791667 absoluteUsedCapacity=0.9791667 used=<memory:48128, vCores:42> cluster=<memory:49152, vCores:96>
2013-08-06 12:58:01,336 INFO org.apache.hadoop.yarn.server.resourcemanager.rmcontainer.RMContainerImpl: container_1375792971633_0006_01_000023 Container Transitioned from NEW to ALLOCATED
2013-08-06 12:58:01,336 INFO org.apache.hadoop.yarn.server.resourcemanager.RMAuditLogger: USER=ubuntu	OPERATION=AM Allocated Container	TARGET=SchedulerApp	RESULT=SUCCESS	APPID=application_1375792971633_0006	CONTAINERID=container_1375792971633_0006_01_000023
2013-08-06 12:58:01,336 INFO org.apache.hadoop.yarn.server.resourcemanager.scheduler.common.fica.FiCaSchedulerNode: Assigned container container_1375792971633_0006_01_000023 of capacity <memory:1024, vCores:1> on host hadoop-110-2:50749, which currently has 8 containers, <memory:8192, vCores:8> used and <memory:0, vCores:8> available
2013-08-06 12:58:01,337 INFO org.apache.hadoop.yarn.server.resourcemanager.scheduler.capacity.LeafQueue: assignedContainer application=application_1375792971633_0006 container=Container: [ContainerId: container_1375792971633_0006_01_000023, NodeId: hadoop-110-2:50749, NodeHttpAddress: hadoop-110-2:8042, Resource: <memory:1024, vCores:1>, Priority: 20, State: NEW, Token: null, Status: container_id {, app_attempt_id {, application_id {, id: 6, cluster_timestamp: 1375792971633, }, attemptId: 1, }, id: 23, }, state: C_NEW, ] containerId=container_1375792971633_0006_01_000023 queue=default: capacity=1.0, absoluteCapacity=1.0, usedResources=<memory:48128, vCores:42>usedCapacity=0.9791667, absoluteUsedCapacity=0.9791667, numApps=5, numContainers=42 usedCapacity=0.9791667 absoluteUsedCapacity=0.9791667 used=<memory:48128, vCores:42> cluster=<memory:49152, vCores:96>
2013-08-06 12:58:01,337 INFO org.apache.hadoop.yarn.server.resourcemanager.scheduler.capacity.ParentQueue: Re-sorting queues since queue: root.default stats: default: capacity=1.0, absoluteCapacity=1.0, usedResources=<memory:49152, vCores:43>usedCapacity=1.0, absoluteUsedCapacity=1.0, numApps=5, numContainers=43
2013-08-06 12:58:01,337 INFO org.apache.hadoop.yarn.server.resourcemanager.scheduler.capacity.ParentQueue: assignedContainer queue=root usedCapacity=1.0 absoluteUsedCapacity=1.0 used=<memory:49152, vCores:43> cluster=<memory:49152, vCores:96>
2013-08-06 12:58:01,406 INFO org.apache.hadoop.yarn.server.resourcemanager.ApplicationMasterService: AM registration appattempt_1375792971633_0010_000001
2013-08-06 12:58:01,407 INFO org.apache.hadoop.yarn.server.resourcemanager.RMAuditLogger: USER=ubuntu	IP=192.168.100.13	OPERATION=Register App Master	TARGET=ApplicationMasterService	RESULT=SUCCESS	APPID=application_1375792971633_0010	APPATTEMPTID=appattempt_1375792971633_0010_000001
2013-08-06 12:58:01,408 INFO org.apache.hadoop.yarn.server.resourcemanager.rmapp.attempt.RMAppAttemptImpl: appattempt_1375792971633_0010_000001 State change from LAUNCHED to RUNNING
2013-08-06 12:58:01,408 INFO org.apache.hadoop.yarn.server.resourcemanager.rmapp.RMAppImpl: application_1375792971633_0010 State change from ACCEPTED to RUNNING
2013-08-06 12:58:01,564 INFO org.apache.hadoop.yarn.server.resourcemanager.rmcontainer.RMContainerImpl: container_1375792971633_0008_01_000002 Container Transitioned from ALLOCATED to ACQUIRED
2013-08-06 12:58:01,565 INFO org.apache.hadoop.yarn.server.resourcemanager.rmcontainer.RMContainerImpl: container_1375792971633_0008_01_000003 Container Transitioned from ALLOCATED to ACQUIRED
2013-08-06 12:58:01,566 INFO org.apache.hadoop.yarn.server.resourcemanager.rmcontainer.RMContainerImpl: container_1375792971633_0008_01_000004 Container Transitioned from ALLOCATED to ACQUIRED
2013-08-06 12:58:01,566 INFO org.apache.hadoop.yarn.server.resourcemanager.rmcontainer.RMContainerImpl: container_1375792971633_0008_01_000005 Container Transitioned from ALLOCATED to ACQUIRED
2013-08-06 12:58:01,567 INFO org.apache.hadoop.yarn.server.resourcemanager.rmcontainer.RMContainerImpl: container_1375792971633_0008_01_000006 Container Transitioned from ALLOCATED to ACQUIRED
2013-08-06 12:58:01,568 INFO org.apache.hadoop.yarn.server.resourcemanager.rmcontainer.RMContainerImpl: container_1375792971633_0008_01_000007 Container Transitioned from ALLOCATED to ACQUIRED
2013-08-06 12:58:01,568 INFO org.apache.hadoop.yarn.server.resourcemanager.rmcontainer.RMContainerImpl: container_1375792971633_0008_01_000008 Container Transitioned from ALLOCATED to ACQUIRED
2013-08-06 12:58:01,569 INFO org.apache.hadoop.yarn.server.resourcemanager.rmcontainer.RMContainerImpl: container_1375792971633_0008_01_000009 Container Transitioned from ALLOCATED to ACQUIRED
2013-08-06 12:58:01,570 INFO org.apache.hadoop.yarn.server.resourcemanager.rmcontainer.RMContainerImpl: container_1375792971633_0008_01_000010 Container Transitioned from ALLOCATED to ACQUIRED
2013-08-06 12:58:01,572 INFO org.apache.hadoop.yarn.server.resourcemanager.rmcontainer.RMContainerImpl: container_1375792971633_0008_01_000011 Container Transitioned from ALLOCATED to ACQUIRED
2013-08-06 12:58:01,573 INFO org.apache.hadoop.yarn.server.resourcemanager.rmcontainer.RMContainerImpl: container_1375792971633_0008_01_000012 Container Transitioned from ALLOCATED to ACQUIRED
2013-08-06 12:58:01,573 INFO org.apache.hadoop.yarn.server.resourcemanager.rmcontainer.RMContainerImpl: container_1375792971633_0008_01_000013 Container Transitioned from ALLOCATED to ACQUIRED
2013-08-06 12:58:01,573 INFO org.apache.hadoop.yarn.server.resourcemanager.rmcontainer.RMContainerImpl: container_1375792971633_0008_01_000014 Container Transitioned from ALLOCATED to ACQUIRED
2013-08-06 12:58:01,573 INFO org.apache.hadoop.yarn.server.resourcemanager.rmcontainer.RMContainerImpl: container_1375792971633_0008_01_000015 Container Transitioned from ALLOCATED to ACQUIRED
2013-08-06 12:58:01,574 INFO org.apache.hadoop.yarn.server.resourcemanager.rmcontainer.RMContainerImpl: container_1375792971633_0008_01_000016 Container Transitioned from ALLOCATED to ACQUIRED
2013-08-06 12:58:01,574 INFO org.apache.hadoop.yarn.server.resourcemanager.rmcontainer.RMContainerImpl: container_1375792971633_0008_01_000017 Container Transitioned from ALLOCATED to ACQUIRED
2013-08-06 12:58:02,127 INFO org.apache.hadoop.yarn.server.resourcemanager.rmcontainer.RMContainerImpl: container_1375792971633_0008_01_000012 Container Transitioned from ACQUIRED to RUNNING
2013-08-06 12:58:02,129 INFO org.apache.hadoop.yarn.server.resourcemanager.rmcontainer.RMContainerImpl: container_1375792971633_0008_01_000013 Container Transitioned from ACQUIRED to RUNNING
2013-08-06 12:58:02,130 INFO org.apache.hadoop.yarn.server.resourcemanager.rmcontainer.RMContainerImpl: container_1375792971633_0008_01_000014 Container Transitioned from ACQUIRED to RUNNING
2013-08-06 12:58:02,132 INFO org.apache.hadoop.yarn.server.resourcemanager.rmcontainer.RMContainerImpl: container_1375792971633_0008_01_000015 Container Transitioned from ACQUIRED to RUNNING
2013-08-06 12:58:02,133 INFO org.apache.hadoop.yarn.server.resourcemanager.rmcontainer.RMContainerImpl: container_1375792971633_0008_01_000016 Container Transitioned from ACQUIRED to RUNNING
2013-08-06 12:58:02,134 INFO org.apache.hadoop.yarn.server.resourcemanager.rmcontainer.RMContainerImpl: container_1375792971633_0008_01_000017 Container Transitioned from ACQUIRED to RUNNING
2013-08-06 12:58:02,186 INFO org.apache.hadoop.yarn.server.resourcemanager.rmcontainer.RMContainerImpl: container_1375792971633_0006_01_000002 Container Transitioned from ALLOCATED to ACQUIRED
2013-08-06 12:58:02,187 INFO org.apache.hadoop.yarn.server.resourcemanager.rmcontainer.RMContainerImpl: container_1375792971633_0006_01_000003 Container Transitioned from ALLOCATED to ACQUIRED
2013-08-06 12:58:02,187 INFO org.apache.hadoop.yarn.server.resourcemanager.rmcontainer.RMContainerImpl: container_1375792971633_0006_01_000004 Container Transitioned from ALLOCATED to ACQUIRED
2013-08-06 12:58:02,187 INFO org.apache.hadoop.yarn.server.resourcemanager.rmcontainer.RMContainerImpl: container_1375792971633_0006_01_000005 Container Transitioned from ALLOCATED to ACQUIRED
2013-08-06 12:58:02,187 INFO org.apache.hadoop.yarn.server.resourcemanager.rmcontainer.RMContainerImpl: container_1375792971633_0006_01_000006 Container Transitioned from ALLOCATED to ACQUIRED
2013-08-06 12:58:02,187 INFO org.apache.hadoop.yarn.server.resourcemanager.rmcontainer.RMContainerImpl: container_1375792971633_0006_01_000007 Container Transitioned from ALLOCATED to ACQUIRED
2013-08-06 12:58:02,188 INFO org.apache.hadoop.yarn.server.resourcemanager.rmcontainer.RMContainerImpl: container_1375792971633_0006_01_000008 Container Transitioned from ALLOCATED to ACQUIRED
2013-08-06 12:58:02,188 INFO org.apache.hadoop.yarn.server.resourcemanager.rmcontainer.RMContainerImpl: container_1375792971633_0006_01_000009 Container Transitioned from ALLOCATED to ACQUIRED
2013-08-06 12:58:02,188 INFO org.apache.hadoop.yarn.server.resourcemanager.rmcontainer.RMContainerImpl: container_1375792971633_0006_01_000010 Container Transitioned from ALLOCATED to ACQUIRED
2013-08-06 12:58:02,188 INFO org.apache.hadoop.yarn.server.resourcemanager.rmcontainer.RMContainerImpl: container_1375792971633_0006_01_000011 Container Transitioned from ALLOCATED to ACQUIRED
2013-08-06 12:58:02,188 INFO org.apache.hadoop.yarn.server.resourcemanager.rmcontainer.RMContainerImpl: container_1375792971633_0006_01_000012 Container Transitioned from ALLOCATED to ACQUIRED
2013-08-06 12:58:02,189 INFO org.apache.hadoop.yarn.server.resourcemanager.rmcontainer.RMContainerImpl: container_1375792971633_0006_01_000013 Container Transitioned from ALLOCATED to ACQUIRED
2013-08-06 12:58:02,189 INFO org.apache.hadoop.yarn.server.resourcemanager.rmcontainer.RMContainerImpl: container_1375792971633_0006_01_000014 Container Transitioned from ALLOCATED to ACQUIRED
2013-08-06 12:58:02,189 INFO org.apache.hadoop.yarn.server.resourcemanager.rmcontainer.RMContainerImpl: container_1375792971633_0006_01_000015 Container Transitioned from ALLOCATED to ACQUIRED
2013-08-06 12:58:02,189 INFO org.apache.hadoop.yarn.server.resourcemanager.rmcontainer.RMContainerImpl: container_1375792971633_0006_01_000016 Container Transitioned from ALLOCATED to ACQUIRED
2013-08-06 12:58:02,190 INFO org.apache.hadoop.yarn.server.resourcemanager.rmcontainer.RMContainerImpl: container_1375792971633_0006_01_000017 Container Transitioned from ALLOCATED to ACQUIRED
2013-08-06 12:58:02,190 INFO org.apache.hadoop.yarn.server.resourcemanager.rmcontainer.RMContainerImpl: container_1375792971633_0006_01_000018 Container Transitioned from ALLOCATED to ACQUIRED
2013-08-06 12:58:02,190 INFO org.apache.hadoop.yarn.server.resourcemanager.rmcontainer.RMContainerImpl: container_1375792971633_0006_01_000019 Container Transitioned from ALLOCATED to ACQUIRED
2013-08-06 12:58:02,190 INFO org.apache.hadoop.yarn.server.resourcemanager.rmcontainer.RMContainerImpl: container_1375792971633_0006_01_000020 Container Transitioned from ALLOCATED to ACQUIRED
2013-08-06 12:58:02,190 INFO org.apache.hadoop.yarn.server.resourcemanager.rmcontainer.RMContainerImpl: container_1375792971633_0006_01_000021 Container Transitioned from ALLOCATED to ACQUIRED
2013-08-06 12:58:02,191 INFO org.apache.hadoop.yarn.server.resourcemanager.rmcontainer.RMContainerImpl: container_1375792971633_0006_01_000022 Container Transitioned from ALLOCATED to ACQUIRED
2013-08-06 12:58:02,191 INFO org.apache.hadoop.yarn.server.resourcemanager.rmcontainer.RMContainerImpl: container_1375792971633_0006_01_000023 Container Transitioned from ALLOCATED to ACQUIRED
2013-08-06 12:58:02,631 INFO org.apache.hadoop.yarn.server.resourcemanager.rmcontainer.RMContainerImpl: container_1375792971633_0008_01_000002 Container Transitioned from ACQUIRED to RUNNING
2013-08-06 12:58:02,631 INFO org.apache.hadoop.yarn.server.resourcemanager.rmcontainer.RMContainerImpl: container_1375792971633_0008_01_000003 Container Transitioned from ACQUIRED to RUNNING
2013-08-06 12:58:02,632 INFO org.apache.hadoop.yarn.server.resourcemanager.rmcontainer.RMContainerImpl: container_1375792971633_0008_01_000004 Container Transitioned from ACQUIRED to RUNNING
2013-08-06 12:58:02,632 INFO org.apache.hadoop.yarn.server.resourcemanager.rmcontainer.RMContainerImpl: container_1375792971633_0008_01_000005 Container Transitioned from ACQUIRED to RUNNING
2013-08-06 12:58:02,716 INFO org.apache.hadoop.yarn.server.resourcemanager.rmcontainer.RMContainerImpl: container_1375792971633_0008_01_000006 Container Transitioned from ACQUIRED to RUNNING
2013-08-06 12:58:02,716 INFO org.apache.hadoop.yarn.server.resourcemanager.rmcontainer.RMContainerImpl: container_1375792971633_0008_01_000007 Container Transitioned from ACQUIRED to RUNNING
2013-08-06 12:58:02,717 INFO org.apache.hadoop.yarn.server.resourcemanager.rmcontainer.RMContainerImpl: container_1375792971633_0008_01_000008 Container Transitioned from ACQUIRED to RUNNING
2013-08-06 12:58:02,718 INFO org.apache.hadoop.yarn.server.resourcemanager.rmcontainer.RMContainerImpl: container_1375792971633_0008_01_000009 Container Transitioned from ACQUIRED to RUNNING
2013-08-06 12:58:02,719 INFO org.apache.hadoop.yarn.server.resourcemanager.rmcontainer.RMContainerImpl: container_1375792971633_0008_01_000010 Container Transitioned from ACQUIRED to RUNNING
2013-08-06 12:58:02,719 INFO org.apache.hadoop.yarn.server.resourcemanager.rmcontainer.RMContainerImpl: container_1375792971633_0008_01_000011 Container Transitioned from ACQUIRED to RUNNING
2013-08-06 12:58:03,259 INFO org.apache.hadoop.yarn.server.resourcemanager.rmcontainer.RMContainerImpl: container_1375792971633_0006_01_000002 Container Transitioned from ACQUIRED to RUNNING
2013-08-06 12:58:03,260 INFO org.apache.hadoop.yarn.server.resourcemanager.rmcontainer.RMContainerImpl: container_1375792971633_0006_01_000003 Container Transitioned from ACQUIRED to RUNNING
2013-08-06 12:58:03,260 INFO org.apache.hadoop.yarn.server.resourcemanager.rmcontainer.RMContainerImpl: container_1375792971633_0006_01_000004 Container Transitioned from ACQUIRED to RUNNING
2013-08-06 12:58:03,260 INFO org.apache.hadoop.yarn.server.resourcemanager.rmcontainer.RMContainerImpl: container_1375792971633_0006_01_000005 Container Transitioned from ACQUIRED to RUNNING
2013-08-06 12:58:03,261 INFO org.apache.hadoop.yarn.server.resourcemanager.rmcontainer.RMContainerImpl: container_1375792971633_0006_01_000006 Container Transitioned from ACQUIRED to RUNNING
2013-08-06 12:58:03,261 INFO org.apache.hadoop.yarn.server.resourcemanager.rmcontainer.RMContainerImpl: container_1375792971633_0006_01_000007 Container Transitioned from ACQUIRED to RUNNING
2013-08-06 12:58:03,262 INFO org.apache.hadoop.yarn.server.resourcemanager.rmcontainer.RMContainerImpl: container_1375792971633_0006_01_000008 Container Transitioned from ACQUIRED to RUNNING
2013-08-06 12:58:03,262 INFO org.apache.hadoop.yarn.server.resourcemanager.rmcontainer.RMContainerImpl: container_1375792971633_0006_01_000009 Container Transitioned from ACQUIRED to RUNNING
2013-08-06 12:58:03,275 INFO org.apache.hadoop.yarn.server.resourcemanager.rmcontainer.RMContainerImpl: container_1375792971633_0006_01_000010 Container Transitioned from ACQUIRED to RUNNING
2013-08-06 12:58:03,275 INFO org.apache.hadoop.yarn.server.resourcemanager.rmcontainer.RMContainerImpl: container_1375792971633_0006_01_000011 Container Transitioned from ACQUIRED to RUNNING
2013-08-06 12:58:03,275 INFO org.apache.hadoop.yarn.server.resourcemanager.rmcontainer.RMContainerImpl: container_1375792971633_0006_01_000012 Container Transitioned from ACQUIRED to RUNNING
2013-08-06 12:58:03,276 INFO org.apache.hadoop.yarn.server.resourcemanager.rmcontainer.RMContainerImpl: container_1375792971633_0006_01_000013 Container Transitioned from ACQUIRED to RUNNING
2013-08-06 12:58:03,277 INFO org.apache.hadoop.yarn.server.resourcemanager.rmcontainer.RMContainerImpl: container_1375792971633_0006_01_000014 Container Transitioned from ACQUIRED to RUNNING
2013-08-06 12:58:03,278 INFO org.apache.hadoop.yarn.server.resourcemanager.rmcontainer.RMContainerImpl: container_1375792971633_0006_01_000015 Container Transitioned from ACQUIRED to RUNNING
2013-08-06 12:58:03,350 INFO org.apache.hadoop.yarn.server.resourcemanager.rmcontainer.RMContainerImpl: container_1375792971633_0006_01_000016 Container Transitioned from ACQUIRED to RUNNING
2013-08-06 12:58:03,351 INFO org.apache.hadoop.yarn.server.resourcemanager.rmcontainer.RMContainerImpl: container_1375792971633_0006_01_000017 Container Transitioned from ACQUIRED to RUNNING
2013-08-06 12:58:03,351 INFO org.apache.hadoop.yarn.server.resourcemanager.rmcontainer.RMContainerImpl: container_1375792971633_0006_01_000018 Container Transitioned from ACQUIRED to RUNNING
2013-08-06 12:58:03,351 INFO org.apache.hadoop.yarn.server.resourcemanager.rmcontainer.RMContainerImpl: container_1375792971633_0006_01_000019 Container Transitioned from ACQUIRED to RUNNING
2013-08-06 12:58:03,351 INFO org.apache.hadoop.yarn.server.resourcemanager.rmcontainer.RMContainerImpl: container_1375792971633_0006_01_000020 Container Transitioned from ACQUIRED to RUNNING
2013-08-06 12:58:03,351 INFO org.apache.hadoop.yarn.server.resourcemanager.rmcontainer.RMContainerImpl: container_1375792971633_0006_01_000021 Container Transitioned from ACQUIRED to RUNNING
2013-08-06 12:58:03,352 INFO org.apache.hadoop.yarn.server.resourcemanager.rmcontainer.RMContainerImpl: container_1375792971633_0006_01_000022 Container Transitioned from ACQUIRED to RUNNING
2013-08-06 12:58:03,352 INFO org.apache.hadoop.yarn.server.resourcemanager.rmcontainer.RMContainerImpl: container_1375792971633_0006_01_000023 Container Transitioned from ACQUIRED to RUNNING
2013-08-06 12:58:21,403 INFO org.apache.hadoop.yarn.server.resourcemanager.rmcontainer.RMContainerImpl: container_1375792971633_0008_01_000004 Container Transitioned from RUNNING to COMPLETED
2013-08-06 12:58:21,404 INFO org.apache.hadoop.yarn.server.resourcemanager.scheduler.common.fica.FiCaSchedulerApp: Completed container: container_1375792971633_0008_01_000004 in state: COMPLETED event:FINISHED
2013-08-06 12:58:21,404 INFO org.apache.hadoop.yarn.server.resourcemanager.RMAuditLogger: USER=ubuntu	OPERATION=AM Released Container	TARGET=SchedulerApp	RESULT=SUCCESS	APPID=application_1375792971633_0008	CONTAINERID=container_1375792971633_0008_01_000004
2013-08-06 12:58:21,404 INFO org.apache.hadoop.yarn.server.resourcemanager.scheduler.common.fica.FiCaSchedulerNode: Released container container_1375792971633_0008_01_000004 of capacity <memory:1024, vCores:1> on host hadoop-110-4:59955, which currently has 5 containers, <memory:7168, vCores:5> used and <memory:1024, vCores:11> available, release resources=true
2013-08-06 12:58:21,404 INFO org.apache.hadoop.yarn.server.resourcemanager.scheduler.capacity.LeafQueue: default used=<memory:48128, vCores:42> numContainers=42 user=ubuntu user-resources=<memory:48128, vCores:42>
2013-08-06 12:58:21,407 INFO org.apache.hadoop.yarn.server.resourcemanager.scheduler.capacity.LeafQueue: completedContainer container=Container: [ContainerId: container_1375792971633_0008_01_000004, NodeId: hadoop-110-4:59955, NodeHttpAddress: hadoop-110-4:8042, Resource: <memory:1024, vCores:1>, Priority: 20, State: NEW, Token: null, Status: container_id {, app_attempt_id {, application_id {, id: 8, cluster_timestamp: 1375792971633, }, attemptId: 1, }, id: 4, }, state: C_COMPLETE, diagnostics: "Container killed by the ApplicationMaster.\n\n", exit_status: 143, ] resource=<memory:1024, vCores:1> queue=default: capacity=1.0, absoluteCapacity=1.0, usedResources=<memory:48128, vCores:42>usedCapacity=0.9791667, absoluteUsedCapacity=0.9791667, numApps=5, numContainers=42 usedCapacity=0.9791667 absoluteUsedCapacity=0.9791667 used=<memory:48128, vCores:42> cluster=<memory:49152, vCores:96>
2013-08-06 12:58:21,407 INFO org.apache.hadoop.yarn.server.resourcemanager.scheduler.capacity.ParentQueue: completedContainer queue=root usedCapacity=0.9791667 absoluteUsedCapacity=0.9791667 used=<memory:48128, vCores:42> cluster=<memory:49152, vCores:96>
2013-08-06 12:58:21,407 INFO org.apache.hadoop.yarn.server.resourcemanager.scheduler.capacity.CapacityScheduler: Application appattempt_1375792971633_0008_000001 released container container_1375792971633_0008_01_000004 on node: host: hadoop-110-4:59955 #containers=5 available=1024 used=7168 with event: FINISHED
2013-08-06 12:58:21,408 INFO org.apache.hadoop.yarn.server.resourcemanager.rmcontainer.RMContainerImpl: container_1375792971633_0006_01_000024 Container Transitioned from NEW to ALLOCATED
2013-08-06 12:58:21,408 INFO org.apache.hadoop.yarn.server.resourcemanager.RMAuditLogger: USER=ubuntu	OPERATION=AM Allocated Container	TARGET=SchedulerApp	RESULT=SUCCESS	APPID=application_1375792971633_0006	CONTAINERID=container_1375792971633_0006_01_000024
2013-08-06 12:58:21,408 INFO org.apache.hadoop.yarn.server.resourcemanager.scheduler.common.fica.FiCaSchedulerNode: Assigned container container_1375792971633_0006_01_000024 of capacity <memory:1024, vCores:1> on host hadoop-110-4:59955, which currently has 6 containers, <memory:8192, vCores:6> used and <memory:0, vCores:10> available
2013-08-06 12:58:21,409 INFO org.apache.hadoop.yarn.server.resourcemanager.scheduler.capacity.LeafQueue: assignedContainer application=application_1375792971633_0006 container=Container: [ContainerId: container_1375792971633_0006_01_000024, NodeId: hadoop-110-4:59955, NodeHttpAddress: hadoop-110-4:8042, Resource: <memory:1024, vCores:1>, Priority: 20, State: NEW, Token: null, Status: container_id {, app_attempt_id {, application_id {, id: 6, cluster_timestamp: 1375792971633, }, attemptId: 1, }, id: 24, }, state: C_NEW, ] containerId=container_1375792971633_0006_01_000024 queue=default: capacity=1.0, absoluteCapacity=1.0, usedResources=<memory:48128, vCores:42>usedCapacity=0.9791667, absoluteUsedCapacity=0.9791667, numApps=5, numContainers=42 usedCapacity=0.9791667 absoluteUsedCapacity=0.9791667 used=<memory:48128, vCores:42> cluster=<memory:49152, vCores:96>
2013-08-06 12:58:21,409 INFO org.apache.hadoop.yarn.server.resourcemanager.scheduler.capacity.ParentQueue: Re-sorting queues since queue: root.default stats: default: capacity=1.0, absoluteCapacity=1.0, usedResources=<memory:49152, vCores:43>usedCapacity=1.0, absoluteUsedCapacity=1.0, numApps=5, numContainers=43
2013-08-06 12:58:21,410 INFO org.apache.hadoop.yarn.server.resourcemanager.scheduler.capacity.ParentQueue: assignedContainer queue=root usedCapacity=1.0 absoluteUsedCapacity=1.0 used=<memory:49152, vCores:43> cluster=<memory:49152, vCores:96>
2013-08-06 12:58:21,563 INFO org.apache.hadoop.yarn.server.resourcemanager.rmcontainer.RMContainerImpl: container_1375792971633_0006_01_000024 Container Transitioned from ALLOCATED to ACQUIRED
2013-08-06 12:58:22,421 INFO org.apache.hadoop.yarn.server.resourcemanager.rmcontainer.RMContainerImpl: container_1375792971633_0006_01_000024 Container Transitioned from ACQUIRED to RUNNING
2013-08-06 12:58:26,365 INFO org.apache.hadoop.yarn.server.resourcemanager.rmcontainer.RMContainerImpl: container_1375792971633_0008_01_000003 Container Transitioned from RUNNING to COMPLETED
2013-08-06 12:58:26,365 INFO org.apache.hadoop.yarn.server.resourcemanager.scheduler.common.fica.FiCaSchedulerApp: Completed container: container_1375792971633_0008_01_000003 in state: COMPLETED event:FINISHED
2013-08-06 12:58:26,365 INFO org.apache.hadoop.yarn.server.resourcemanager.RMAuditLogger: USER=ubuntu	OPERATION=AM Released Container	TARGET=SchedulerApp	RESULT=SUCCESS	APPID=application_1375792971633_0008	CONTAINERID=container_1375792971633_0008_01_000003
2013-08-06 12:58:26,366 INFO org.apache.hadoop.yarn.server.resourcemanager.scheduler.common.fica.FiCaSchedulerNode: Released container container_1375792971633_0008_01_000003 of capacity <memory:1024, vCores:1> on host hadoop-110-4:59955, which currently has 5 containers, <memory:7168, vCores:5> used and <memory:1024, vCores:11> available, release resources=true
2013-08-06 12:58:26,366 INFO org.apache.hadoop.yarn.server.resourcemanager.scheduler.capacity.LeafQueue: default used=<memory:48128, vCores:42> numContainers=42 user=ubuntu user-resources=<memory:48128, vCores:42>
2013-08-06 12:58:26,367 INFO org.apache.hadoop.yarn.server.resourcemanager.scheduler.capacity.LeafQueue: completedContainer container=Container: [ContainerId: container_1375792971633_0008_01_000003, NodeId: hadoop-110-4:59955, NodeHttpAddress: hadoop-110-4:8042, Resource: <memory:1024, vCores:1>, Priority: 20, State: NEW, Token: null, Status: container_id {, app_attempt_id {, application_id {, id: 8, cluster_timestamp: 1375792971633, }, attemptId: 1, }, id: 3, }, state: C_COMPLETE, diagnostics: "Container killed by the ApplicationMaster.\n", exit_status: 0, ] resource=<memory:1024, vCores:1> queue=default: capacity=1.0, absoluteCapacity=1.0, usedResources=<memory:48128, vCores:42>usedCapacity=0.9791667, absoluteUsedCapacity=0.9791667, numApps=5, numContainers=42 usedCapacity=0.9791667 absoluteUsedCapacity=0.9791667 used=<memory:48128, vCores:42> cluster=<memory:49152, vCores:96>
2013-08-06 12:58:26,367 INFO org.apache.hadoop.yarn.server.resourcemanager.scheduler.capacity.ParentQueue: completedContainer queue=root usedCapacity=0.9791667 absoluteUsedCapacity=0.9791667 used=<memory:48128, vCores:42> cluster=<memory:49152, vCores:96>
2013-08-06 12:58:26,368 INFO org.apache.hadoop.yarn.server.resourcemanager.scheduler.capacity.CapacityScheduler: Application appattempt_1375792971633_0008_000001 released container container_1375792971633_0008_01_000003 on node: host: hadoop-110-4:59955 #containers=5 available=1024 used=7168 with event: FINISHED
2013-08-06 12:58:26,368 INFO org.apache.hadoop.yarn.server.resourcemanager.rmcontainer.RMContainerImpl: container_1375792971633_0006_01_000025 Container Transitioned from NEW to ALLOCATED
2013-08-06 12:58:26,368 INFO org.apache.hadoop.yarn.server.resourcemanager.RMAuditLogger: USER=ubuntu	OPERATION=AM Allocated Container	TARGET=SchedulerApp	RESULT=SUCCESS	APPID=application_1375792971633_0006	CONTAINERID=container_1375792971633_0006_01_000025
2013-08-06 12:58:26,369 INFO org.apache.hadoop.yarn.server.resourcemanager.scheduler.common.fica.FiCaSchedulerNode: Assigned container container_1375792971633_0006_01_000025 of capacity <memory:1024, vCores:1> on host hadoop-110-4:59955, which currently has 6 containers, <memory:8192, vCores:6> used and <memory:0, vCores:10> available
2013-08-06 12:58:26,370 INFO org.apache.hadoop.yarn.server.resourcemanager.scheduler.capacity.LeafQueue: assignedContainer application=application_1375792971633_0006 container=Container: [ContainerId: container_1375792971633_0006_01_000025, NodeId: hadoop-110-4:59955, NodeHttpAddress: hadoop-110-4:8042, Resource: <memory:1024, vCores:1>, Priority: 20, State: NEW, Token: null, Status: container_id {, app_attempt_id {, application_id {, id: 6, cluster_timestamp: 1375792971633, }, attemptId: 1, }, id: 25, }, state: C_NEW, ] containerId=container_1375792971633_0006_01_000025 queue=default: capacity=1.0, absoluteCapacity=1.0, usedResources=<memory:48128, vCores:42>usedCapacity=0.9791667, absoluteUsedCapacity=0.9791667, numApps=5, numContainers=42 usedCapacity=0.9791667 absoluteUsedCapacity=0.9791667 used=<memory:48128, vCores:42> cluster=<memory:49152, vCores:96>
2013-08-06 12:58:26,370 INFO org.apache.hadoop.yarn.server.resourcemanager.scheduler.capacity.ParentQueue: Re-sorting queues since queue: root.default stats: default: capacity=1.0, absoluteCapacity=1.0, usedResources=<memory:49152, vCores:43>usedCapacity=1.0, absoluteUsedCapacity=1.0, numApps=5, numContainers=43
2013-08-06 12:58:26,370 INFO org.apache.hadoop.yarn.server.resourcemanager.scheduler.capacity.ParentQueue: assignedContainer queue=root usedCapacity=1.0 absoluteUsedCapacity=1.0 used=<memory:49152, vCores:43> cluster=<memory:49152, vCores:96>
2013-08-06 12:58:26,594 INFO org.apache.hadoop.yarn.server.resourcemanager.rmcontainer.RMContainerImpl: container_1375792971633_0006_01_000025 Container Transitioned from ALLOCATED to ACQUIRED
2013-08-06 12:58:27,378 INFO org.apache.hadoop.yarn.server.resourcemanager.rmcontainer.RMContainerImpl: container_1375792971633_0006_01_000025 Container Transitioned from ACQUIRED to RUNNING
2013-08-06 12:58:27,378 INFO org.apache.hadoop.yarn.server.resourcemanager.rmcontainer.RMContainerImpl: container_1375792971633_0008_01_000002 Container Transitioned from RUNNING to COMPLETED
2013-08-06 12:58:27,378 INFO org.apache.hadoop.yarn.server.resourcemanager.scheduler.common.fica.FiCaSchedulerApp: Completed container: container_1375792971633_0008_01_000002 in state: COMPLETED event:FINISHED
2013-08-06 12:58:27,379 INFO org.apache.hadoop.yarn.server.resourcemanager.RMAuditLogger: USER=ubuntu	OPERATION=AM Released Container	TARGET=SchedulerApp	RESULT=SUCCESS	APPID=application_1375792971633_0008	CONTAINERID=container_1375792971633_0008_01_000002
2013-08-06 12:58:27,379 INFO org.apache.hadoop.yarn.server.resourcemanager.scheduler.common.fica.FiCaSchedulerNode: Released container container_1375792971633_0008_01_000002 of capacity <memory:1024, vCores:1> on host hadoop-110-4:59955, which currently has 5 containers, <memory:7168, vCores:5> used and <memory:1024, vCores:11> available, release resources=true
2013-08-06 12:58:27,379 INFO org.apache.hadoop.yarn.server.resourcemanager.scheduler.capacity.LeafQueue: default used=<memory:48128, vCores:42> numContainers=42 user=ubuntu user-resources=<memory:48128, vCores:42>
2013-08-06 12:58:27,380 INFO org.apache.hadoop.yarn.server.resourcemanager.scheduler.capacity.LeafQueue: completedContainer container=Container: [ContainerId: container_1375792971633_0008_01_000002, NodeId: hadoop-110-4:59955, NodeHttpAddress: hadoop-110-4:8042, Resource: <memory:1024, vCores:1>, Priority: 20, State: NEW, Token: null, Status: container_id {, app_attempt_id {, application_id {, id: 8, cluster_timestamp: 1375792971633, }, attemptId: 1, }, id: 2, }, state: C_COMPLETE, diagnostics: "Container killed by the ApplicationMaster.\n", exit_status: 0, ] resource=<memory:1024, vCores:1> queue=default: capacity=1.0, absoluteCapacity=1.0, usedResources=<memory:48128, vCores:42>usedCapacity=0.9791667, absoluteUsedCapacity=0.9791667, numApps=5, numContainers=42 usedCapacity=0.9791667 absoluteUsedCapacity=0.9791667 used=<memory:48128, vCores:42> cluster=<memory:49152, vCores:96>
2013-08-06 12:58:27,380 INFO org.apache.hadoop.yarn.server.resourcemanager.scheduler.capacity.ParentQueue: completedContainer queue=root usedCapacity=0.9791667 absoluteUsedCapacity=0.9791667 used=<memory:48128, vCores:42> cluster=<memory:49152, vCores:96>
2013-08-06 12:58:27,380 INFO org.apache.hadoop.yarn.server.resourcemanager.scheduler.capacity.CapacityScheduler: Application appattempt_1375792971633_0008_000001 released container container_1375792971633_0008_01_000002 on node: host: hadoop-110-4:59955 #containers=5 available=1024 used=7168 with event: FINISHED
2013-08-06 12:58:27,381 INFO org.apache.hadoop.yarn.server.resourcemanager.rmcontainer.RMContainerImpl: container_1375792971633_0006_01_000026 Container Transitioned from NEW to ALLOCATED
2013-08-06 12:58:27,381 INFO org.apache.hadoop.yarn.server.resourcemanager.RMAuditLogger: USER=ubuntu	OPERATION=AM Allocated Container	TARGET=SchedulerApp	RESULT=SUCCESS	APPID=application_1375792971633_0006	CONTAINERID=container_1375792971633_0006_01_000026
2013-08-06 12:58:27,381 INFO org.apache.hadoop.yarn.server.resourcemanager.scheduler.common.fica.FiCaSchedulerNode: Assigned container container_1375792971633_0006_01_000026 of capacity <memory:1024, vCores:1> on host hadoop-110-4:59955, which currently has 6 containers, <memory:8192, vCores:6> used and <memory:0, vCores:10> available
2013-08-06 12:58:27,382 INFO org.apache.hadoop.yarn.server.resourcemanager.scheduler.capacity.LeafQueue: assignedContainer application=application_1375792971633_0006 container=Container: [ContainerId: container_1375792971633_0006_01_000026, NodeId: hadoop-110-4:59955, NodeHttpAddress: hadoop-110-4:8042, Resource: <memory:1024, vCores:1>, Priority: 20, State: NEW, Token: null, Status: container_id {, app_attempt_id {, application_id {, id: 6, cluster_timestamp: 1375792971633, }, attemptId: 1, }, id: 26, }, state: C_NEW, ] containerId=container_1375792971633_0006_01_000026 queue=default: capacity=1.0, absoluteCapacity=1.0, usedResources=<memory:48128, vCores:42>usedCapacity=0.9791667, absoluteUsedCapacity=0.9791667, numApps=5, numContainers=42 usedCapacity=0.9791667 absoluteUsedCapacity=0.9791667 used=<memory:48128, vCores:42> cluster=<memory:49152, vCores:96>
2013-08-06 12:58:27,382 INFO org.apache.hadoop.yarn.server.resourcemanager.scheduler.capacity.ParentQueue: Re-sorting queues since queue: root.default stats: default: capacity=1.0, absoluteCapacity=1.0, usedResources=<memory:49152, vCores:43>usedCapacity=1.0, absoluteUsedCapacity=1.0, numApps=5, numContainers=43
2013-08-06 12:58:27,383 INFO org.apache.hadoop.yarn.server.resourcemanager.scheduler.capacity.ParentQueue: assignedContainer queue=root usedCapacity=1.0 absoluteUsedCapacity=1.0 used=<memory:49152, vCores:43> cluster=<memory:49152, vCores:96>
2013-08-06 12:58:27,607 INFO org.apache.hadoop.yarn.server.resourcemanager.rmcontainer.RMContainerImpl: container_1375792971633_0006_01_000026 Container Transitioned from ALLOCATED to ACQUIRED
2013-08-06 12:58:27,758 INFO org.apache.hadoop.yarn.server.resourcemanager.rmcontainer.RMContainerImpl: container_1375792971633_0008_01_000007 Container Transitioned from RUNNING to COMPLETED
2013-08-06 12:58:27,758 INFO org.apache.hadoop.yarn.server.resourcemanager.scheduler.common.fica.FiCaSchedulerApp: Completed container: container_1375792971633_0008_01_000007 in state: COMPLETED event:FINISHED
2013-08-06 12:58:27,758 INFO org.apache.hadoop.yarn.server.resourcemanager.RMAuditLogger: USER=ubuntu	OPERATION=AM Released Container	TARGET=SchedulerApp	RESULT=SUCCESS	APPID=application_1375792971633_0008	CONTAINERID=container_1375792971633_0008_01_000007
2013-08-06 12:58:27,759 INFO org.apache.hadoop.yarn.server.resourcemanager.scheduler.common.fica.FiCaSchedulerNode: Released container container_1375792971633_0008_01_000007 of capacity <memory:1024, vCores:1> on host hadoop-110-3:34727, which currently has 6 containers, <memory:7168, vCores:6> used and <memory:1024, vCores:10> available, release resources=true
2013-08-06 12:58:27,759 INFO org.apache.hadoop.yarn.server.resourcemanager.scheduler.capacity.LeafQueue: default used=<memory:48128, vCores:42> numContainers=42 user=ubuntu user-resources=<memory:48128, vCores:42>
2013-08-06 12:58:27,760 INFO org.apache.hadoop.yarn.server.resourcemanager.scheduler.capacity.LeafQueue: completedContainer container=Container: [ContainerId: container_1375792971633_0008_01_000007, NodeId: hadoop-110-3:34727, NodeHttpAddress: hadoop-110-3:8042, Resource: <memory:1024, vCores:1>, Priority: 20, State: NEW, Token: null, Status: container_id {, app_attempt_id {, application_id {, id: 8, cluster_timestamp: 1375792971633, }, attemptId: 1, }, id: 7, }, state: C_COMPLETE, diagnostics: "Container killed by the ApplicationMaster.\n", exit_status: 0, ] resource=<memory:1024, vCores:1> queue=default: capacity=1.0, absoluteCapacity=1.0, usedResources=<memory:48128, vCores:42>usedCapacity=0.9791667, absoluteUsedCapacity=0.9791667, numApps=5, numContainers=42 usedCapacity=0.9791667 absoluteUsedCapacity=0.9791667 used=<memory:48128, vCores:42> cluster=<memory:49152, vCores:96>
2013-08-06 12:58:27,760 INFO org.apache.hadoop.yarn.server.resourcemanager.scheduler.capacity.ParentQueue: completedContainer queue=root usedCapacity=0.9791667 absoluteUsedCapacity=0.9791667 used=<memory:48128, vCores:42> cluster=<memory:49152, vCores:96>
2013-08-06 12:58:27,760 INFO org.apache.hadoop.yarn.server.resourcemanager.scheduler.capacity.CapacityScheduler: Application appattempt_1375792971633_0008_000001 released container container_1375792971633_0008_01_000007 on node: host: hadoop-110-3:34727 #containers=6 available=1024 used=7168 with event: FINISHED
2013-08-06 12:58:27,761 INFO org.apache.hadoop.yarn.server.resourcemanager.rmcontainer.RMContainerImpl: container_1375792971633_0006_01_000027 Container Transitioned from NEW to ALLOCATED
2013-08-06 12:58:27,761 INFO org.apache.hadoop.yarn.server.resourcemanager.RMAuditLogger: USER=ubuntu	OPERATION=AM Allocated Container	TARGET=SchedulerApp	RESULT=SUCCESS	APPID=application_1375792971633_0006	CONTAINERID=container_1375792971633_0006_01_000027
2013-08-06 12:58:27,761 INFO org.apache.hadoop.yarn.server.resourcemanager.scheduler.common.fica.FiCaSchedulerNode: Assigned container container_1375792971633_0006_01_000027 of capacity <memory:1024, vCores:1> on host hadoop-110-3:34727, which currently has 7 containers, <memory:8192, vCores:7> used and <memory:0, vCores:9> available
2013-08-06 12:58:27,762 INFO org.apache.hadoop.yarn.server.resourcemanager.scheduler.capacity.LeafQueue: assignedContainer application=application_1375792971633_0006 container=Container: [ContainerId: container_1375792971633_0006_01_000027, NodeId: hadoop-110-3:34727, NodeHttpAddress: hadoop-110-3:8042, Resource: <memory:1024, vCores:1>, Priority: 20, State: NEW, Token: null, Status: container_id {, app_attempt_id {, application_id {, id: 6, cluster_timestamp: 1375792971633, }, attemptId: 1, }, id: 27, }, state: C_NEW, ] containerId=container_1375792971633_0006_01_000027 queue=default: capacity=1.0, absoluteCapacity=1.0, usedResources=<memory:48128, vCores:42>usedCapacity=0.9791667, absoluteUsedCapacity=0.9791667, numApps=5, numContainers=42 usedCapacity=0.9791667 absoluteUsedCapacity=0.9791667 used=<memory:48128, vCores:42> cluster=<memory:49152, vCores:96>
2013-08-06 12:58:27,762 INFO org.apache.hadoop.yarn.server.resourcemanager.scheduler.capacity.ParentQueue: Re-sorting queues since queue: root.default stats: default: capacity=1.0, absoluteCapacity=1.0, usedResources=<memory:49152, vCores:43>usedCapacity=1.0, absoluteUsedCapacity=1.0, numApps=5, numContainers=43
2013-08-06 12:58:27,762 INFO org.apache.hadoop.yarn.server.resourcemanager.scheduler.capacity.ParentQueue: assignedContainer queue=root usedCapacity=1.0 absoluteUsedCapacity=1.0 used=<memory:49152, vCores:43> cluster=<memory:49152, vCores:96>
2013-08-06 12:58:28,386 INFO org.apache.hadoop.yarn.server.resourcemanager.rmcontainer.RMContainerImpl: container_1375792971633_0006_01_000026 Container Transitioned from ACQUIRED to RUNNING
2013-08-06 12:58:28,632 INFO org.apache.hadoop.yarn.server.resourcemanager.rmcontainer.RMContainerImpl: container_1375792971633_0006_01_000027 Container Transitioned from ALLOCATED to ACQUIRED
2013-08-06 12:58:28,767 INFO org.apache.hadoop.yarn.server.resourcemanager.rmcontainer.RMContainerImpl: container_1375792971633_0006_01_000027 Container Transitioned from ACQUIRED to RUNNING
2013-08-06 12:58:29,751 INFO org.apache.hadoop.yarn.server.resourcemanager.rmcontainer.RMContainerImpl: container_1375792971633_0008_01_000005 Container Transitioned from RUNNING to COMPLETED
2013-08-06 12:58:29,751 INFO org.apache.hadoop.yarn.server.resourcemanager.scheduler.common.fica.FiCaSchedulerApp: Completed container: container_1375792971633_0008_01_000005 in state: COMPLETED event:FINISHED
2013-08-06 12:58:29,751 INFO org.apache.hadoop.yarn.server.resourcemanager.RMAuditLogger: USER=ubuntu	OPERATION=AM Released Container	TARGET=SchedulerApp	RESULT=SUCCESS	APPID=application_1375792971633_0008	CONTAINERID=container_1375792971633_0008_01_000005
2013-08-06 12:58:29,752 INFO org.apache.hadoop.yarn.server.resourcemanager.scheduler.common.fica.FiCaSchedulerNode: Released container container_1375792971633_0008_01_000005 of capacity <memory:1024, vCores:1> on host hadoop-110-4:59955, which currently has 5 containers, <memory:7168, vCores:5> used and <memory:1024, vCores:11> available, release resources=true
2013-08-06 12:58:29,752 INFO org.apache.hadoop.yarn.server.resourcemanager.scheduler.capacity.LeafQueue: default used=<memory:48128, vCores:42> numContainers=42 user=ubuntu user-resources=<memory:48128, vCores:42>
2013-08-06 12:58:29,753 INFO org.apache.hadoop.yarn.server.resourcemanager.scheduler.capacity.LeafQueue: completedContainer container=Container: [ContainerId: container_1375792971633_0008_01_000005, NodeId: hadoop-110-4:59955, NodeHttpAddress: hadoop-110-4:8042, Resource: <memory:1024, vCores:1>, Priority: 20, State: NEW, Token: null, Status: container_id {, app_attempt_id {, application_id {, id: 8, cluster_timestamp: 1375792971633, }, attemptId: 1, }, id: 5, }, state: C_COMPLETE, diagnostics: "Container killed by the ApplicationMaster.\n\n", exit_status: 143, ] resource=<memory:1024, vCores:1> queue=default: capacity=1.0, absoluteCapacity=1.0, usedResources=<memory:48128, vCores:42>usedCapacity=0.9791667, absoluteUsedCapacity=0.9791667, numApps=5, numContainers=42 usedCapacity=0.9791667 absoluteUsedCapacity=0.9791667 used=<memory:48128, vCores:42> cluster=<memory:49152, vCores:96>
2013-08-06 12:58:29,753 INFO org.apache.hadoop.yarn.server.resourcemanager.scheduler.capacity.ParentQueue: completedContainer queue=root usedCapacity=0.9791667 absoluteUsedCapacity=0.9791667 used=<memory:48128, vCores:42> cluster=<memory:49152, vCores:96>
2013-08-06 12:58:29,753 INFO org.apache.hadoop.yarn.server.resourcemanager.scheduler.capacity.CapacityScheduler: Application appattempt_1375792971633_0008_000001 released container container_1375792971633_0008_01_000005 on node: host: hadoop-110-4:59955 #containers=5 available=1024 used=7168 with event: FINISHED
2013-08-06 12:58:29,754 INFO org.apache.hadoop.yarn.server.resourcemanager.rmcontainer.RMContainerImpl: container_1375792971633_0006_01_000028 Container Transitioned from NEW to ALLOCATED
2013-08-06 12:58:29,754 INFO org.apache.hadoop.yarn.server.resourcemanager.RMAuditLogger: USER=ubuntu	OPERATION=AM Allocated Container	TARGET=SchedulerApp	RESULT=SUCCESS	APPID=application_1375792971633_0006	CONTAINERID=container_1375792971633_0006_01_000028
2013-08-06 12:58:29,754 INFO org.apache.hadoop.yarn.server.resourcemanager.scheduler.common.fica.FiCaSchedulerNode: Assigned container container_1375792971633_0006_01_000028 of capacity <memory:1024, vCores:1> on host hadoop-110-4:59955, which currently has 6 containers, <memory:8192, vCores:6> used and <memory:0, vCores:10> available
2013-08-06 12:58:29,755 INFO org.apache.hadoop.yarn.server.resourcemanager.scheduler.capacity.LeafQueue: assignedContainer application=application_1375792971633_0006 container=Container: [ContainerId: container_1375792971633_0006_01_000028, NodeId: hadoop-110-4:59955, NodeHttpAddress: hadoop-110-4:8042, Resource: <memory:1024, vCores:1>, Priority: 20, State: NEW, Token: null, Status: container_id {, app_attempt_id {, application_id {, id: 6, cluster_timestamp: 1375792971633, }, attemptId: 1, }, id: 28, }, state: C_NEW, ] containerId=container_1375792971633_0006_01_000028 queue=default: capacity=1.0, absoluteCapacity=1.0, usedResources=<memory:48128, vCores:42>usedCapacity=0.9791667, absoluteUsedCapacity=0.9791667, numApps=5, numContainers=42 usedCapacity=0.9791667 absoluteUsedCapacity=0.9791667 used=<memory:48128, vCores:42> cluster=<memory:49152, vCores:96>
2013-08-06 12:58:29,755 INFO org.apache.hadoop.yarn.server.resourcemanager.scheduler.capacity.ParentQueue: Re-sorting queues since queue: root.default stats: default: capacity=1.0, absoluteCapacity=1.0, usedResources=<memory:49152, vCores:43>usedCapacity=1.0, absoluteUsedCapacity=1.0, numApps=5, numContainers=43
2013-08-06 12:58:29,755 INFO org.apache.hadoop.yarn.server.resourcemanager.scheduler.capacity.ParentQueue: assignedContainer queue=root usedCapacity=1.0 absoluteUsedCapacity=1.0 used=<memory:49152, vCores:43> cluster=<memory:49152, vCores:96>
2013-08-06 12:58:30,615 INFO org.apache.hadoop.yarn.server.resourcemanager.rmcontainer.RMContainerImpl: container_1375792971633_0008_01_000010 Container Transitioned from RUNNING to COMPLETED
2013-08-06 12:58:30,615 INFO org.apache.hadoop.yarn.server.resourcemanager.scheduler.common.fica.FiCaSchedulerApp: Completed container: container_1375792971633_0008_01_000010 in state: COMPLETED event:FINISHED
2013-08-06 12:58:30,616 INFO org.apache.hadoop.yarn.server.resourcemanager.RMAuditLogger: USER=ubuntu	OPERATION=AM Released Container	TARGET=SchedulerApp	RESULT=SUCCESS	APPID=application_1375792971633_0008	CONTAINERID=container_1375792971633_0008_01_000010
2013-08-06 12:58:30,616 INFO org.apache.hadoop.yarn.server.resourcemanager.scheduler.common.fica.FiCaSchedulerNode: Released container container_1375792971633_0008_01_000010 of capacity <memory:1024, vCores:1> on host hadoop-110-3:34727, which currently has 6 containers, <memory:7168, vCores:6> used and <memory:1024, vCores:10> available, release resources=true
2013-08-06 12:58:30,616 INFO org.apache.hadoop.yarn.server.resourcemanager.scheduler.capacity.LeafQueue: default used=<memory:48128, vCores:42> numContainers=42 user=ubuntu user-resources=<memory:48128, vCores:42>
2013-08-06 12:58:30,617 INFO org.apache.hadoop.yarn.server.resourcemanager.scheduler.capacity.LeafQueue: completedContainer container=Container: [ContainerId: container_1375792971633_0008_01_000010, NodeId: hadoop-110-3:34727, NodeHttpAddress: hadoop-110-3:8042, Resource: <memory:1024, vCores:1>, Priority: 20, State: NEW, Token: null, Status: container_id {, app_attempt_id {, application_id {, id: 8, cluster_timestamp: 1375792971633, }, attemptId: 1, }, id: 10, }, state: C_COMPLETE, diagnostics: "Container killed by the ApplicationMaster.\n\n", exit_status: 143, ] resource=<memory:1024, vCores:1> queue=default: capacity=1.0, absoluteCapacity=1.0, usedResources=<memory:48128, vCores:42>usedCapacity=0.9791667, absoluteUsedCapacity=0.9791667, numApps=5, numContainers=42 usedCapacity=0.9791667 absoluteUsedCapacity=0.9791667 used=<memory:48128, vCores:42> cluster=<memory:49152, vCores:96>
2013-08-06 12:58:30,617 INFO org.apache.hadoop.yarn.server.resourcemanager.scheduler.capacity.ParentQueue: completedContainer queue=root usedCapacity=0.9791667 absoluteUsedCapacity=0.9791667 used=<memory:48128, vCores:42> cluster=<memory:49152, vCores:96>
2013-08-06 12:58:30,617 INFO org.apache.hadoop.yarn.server.resourcemanager.scheduler.capacity.CapacityScheduler: Application appattempt_1375792971633_0008_000001 released container container_1375792971633_0008_01_000010 on node: host: hadoop-110-3:34727 #containers=6 available=1024 used=7168 with event: FINISHED
2013-08-06 12:58:30,618 INFO org.apache.hadoop.yarn.server.resourcemanager.rmcontainer.RMContainerImpl: container_1375792971633_0006_01_000029 Container Transitioned from NEW to ALLOCATED
2013-08-06 12:58:30,618 INFO org.apache.hadoop.yarn.server.resourcemanager.RMAuditLogger: USER=ubuntu	OPERATION=AM Allocated Container	TARGET=SchedulerApp	RESULT=SUCCESS	APPID=application_1375792971633_0006	CONTAINERID=container_1375792971633_0006_01_000029
2013-08-06 12:58:30,618 INFO org.apache.hadoop.yarn.server.resourcemanager.scheduler.common.fica.FiCaSchedulerNode: Assigned container container_1375792971633_0006_01_000029 of capacity <memory:1024, vCores:1> on host hadoop-110-3:34727, which currently has 7 containers, <memory:8192, vCores:7> used and <memory:0, vCores:9> available
2013-08-06 12:58:30,619 INFO org.apache.hadoop.yarn.server.resourcemanager.scheduler.capacity.LeafQueue: assignedContainer application=application_1375792971633_0006 container=Container: [ContainerId: container_1375792971633_0006_01_000029, NodeId: hadoop-110-3:34727, NodeHttpAddress: hadoop-110-3:8042, Resource: <memory:1024, vCores:1>, Priority: 20, State: NEW, Token: null, Status: container_id {, app_attempt_id {, application_id {, id: 6, cluster_timestamp: 1375792971633, }, attemptId: 1, }, id: 29, }, state: C_NEW, ] containerId=container_1375792971633_0006_01_000029 queue=default: capacity=1.0, absoluteCapacity=1.0, usedResources=<memory:48128, vCores:42>usedCapacity=0.9791667, absoluteUsedCapacity=0.9791667, numApps=5, numContainers=42 usedCapacity=0.9791667 absoluteUsedCapacity=0.9791667 used=<memory:48128, vCores:42> cluster=<memory:49152, vCores:96>
2013-08-06 12:58:30,619 INFO org.apache.hadoop.yarn.server.resourcemanager.scheduler.capacity.ParentQueue: Re-sorting queues since queue: root.default stats: default: capacity=1.0, absoluteCapacity=1.0, usedResources=<memory:49152, vCores:43>usedCapacity=1.0, absoluteUsedCapacity=1.0, numApps=5, numContainers=43
2013-08-06 12:58:30,620 INFO org.apache.hadoop.yarn.server.resourcemanager.scheduler.capacity.ParentQueue: assignedContainer queue=root usedCapacity=1.0 absoluteUsedCapacity=1.0 used=<memory:49152, vCores:43> cluster=<memory:49152, vCores:96>
2013-08-06 12:58:30,724 INFO org.apache.hadoop.yarn.server.resourcemanager.rmcontainer.RMContainerImpl: container_1375792971633_0006_01_000028 Container Transitioned from ALLOCATED to ACQUIRED
2013-08-06 12:58:30,725 INFO org.apache.hadoop.yarn.server.resourcemanager.rmcontainer.RMContainerImpl: container_1375792971633_0006_01_000029 Container Transitioned from ALLOCATED to ACQUIRED
2013-08-06 12:58:31,512 INFO org.apache.hadoop.yarn.server.resourcemanager.rmcontainer.RMContainerImpl: container_1375792971633_0006_01_000029 Container Transitioned from ACQUIRED to RUNNING
2013-08-06 12:58:31,778 INFO org.apache.hadoop.yarn.server.resourcemanager.rmcontainer.RMContainerImpl: container_1375792971633_0006_01_000028 Container Transitioned from ACQUIRED to RUNNING
2013-08-06 12:58:32,519 INFO org.apache.hadoop.yarn.server.resourcemanager.rmcontainer.RMContainerImpl: container_1375792971633_0008_01_000006 Container Transitioned from RUNNING to COMPLETED
2013-08-06 12:58:32,519 INFO org.apache.hadoop.yarn.server.resourcemanager.scheduler.common.fica.FiCaSchedulerApp: Completed container: container_1375792971633_0008_01_000006 in state: COMPLETED event:FINISHED
2013-08-06 12:58:32,519 INFO org.apache.hadoop.yarn.server.resourcemanager.RMAuditLogger: USER=ubuntu	OPERATION=AM Released Container	TARGET=SchedulerApp	RESULT=SUCCESS	APPID=application_1375792971633_0008	CONTAINERID=container_1375792971633_0008_01_000006
2013-08-06 12:58:32,520 INFO org.apache.hadoop.yarn.server.resourcemanager.scheduler.common.fica.FiCaSchedulerNode: Released container container_1375792971633_0008_01_000006 of capacity <memory:1024, vCores:1> on host hadoop-110-3:34727, which currently has 6 containers, <memory:7168, vCores:6> used and <memory:1024, vCores:10> available, release resources=true
2013-08-06 12:58:32,520 INFO org.apache.hadoop.yarn.server.resourcemanager.scheduler.capacity.LeafQueue: default used=<memory:48128, vCores:42> numContainers=42 user=ubuntu user-resources=<memory:48128, vCores:42>
2013-08-06 12:58:32,521 INFO org.apache.hadoop.yarn.server.resourcemanager.scheduler.capacity.LeafQueue: completedContainer container=Container: [ContainerId: container_1375792971633_0008_01_000006, NodeId: hadoop-110-3:34727, NodeHttpAddress: hadoop-110-3:8042, Resource: <memory:1024, vCores:1>, Priority: 20, State: NEW, Token: null, Status: container_id {, app_attempt_id {, application_id {, id: 8, cluster_timestamp: 1375792971633, }, attemptId: 1, }, id: 6, }, state: C_COMPLETE, diagnostics: "Container killed by the ApplicationMaster.\n\n", exit_status: 143, ] resource=<memory:1024, vCores:1> queue=default: capacity=1.0, absoluteCapacity=1.0, usedResources=<memory:48128, vCores:42>usedCapacity=0.9791667, absoluteUsedCapacity=0.9791667, numApps=5, numContainers=42 usedCapacity=0.9791667 absoluteUsedCapacity=0.9791667 used=<memory:48128, vCores:42> cluster=<memory:49152, vCores:96>
2013-08-06 12:58:32,521 INFO org.apache.hadoop.yarn.server.resourcemanager.scheduler.capacity.ParentQueue: completedContainer queue=root usedCapacity=0.9791667 absoluteUsedCapacity=0.9791667 used=<memory:48128, vCores:42> cluster=<memory:49152, vCores:96>
2013-08-06 12:58:32,521 INFO org.apache.hadoop.yarn.server.resourcemanager.scheduler.capacity.CapacityScheduler: Application appattempt_1375792971633_0008_000001 released container container_1375792971633_0008_01_000006 on node: host: hadoop-110-3:34727 #containers=6 available=1024 used=7168 with event: FINISHED
2013-08-06 12:58:32,522 INFO org.apache.hadoop.yarn.server.resourcemanager.rmcontainer.RMContainerImpl: container_1375792971633_0006_01_000030 Container Transitioned from NEW to ALLOCATED
2013-08-06 12:58:32,522 INFO org.apache.hadoop.yarn.server.resourcemanager.RMAuditLogger: USER=ubuntu	OPERATION=AM Allocated Container	TARGET=SchedulerApp	RESULT=SUCCESS	APPID=application_1375792971633_0006	CONTAINERID=container_1375792971633_0006_01_000030
2013-08-06 12:58:32,522 INFO org.apache.hadoop.yarn.server.resourcemanager.scheduler.common.fica.FiCaSchedulerNode: Assigned container container_1375792971633_0006_01_000030 of capacity <memory:1024, vCores:1> on host hadoop-110-3:34727, which currently has 7 containers, <memory:8192, vCores:7> used and <memory:0, vCores:9> available
2013-08-06 12:58:32,523 INFO org.apache.hadoop.yarn.server.resourcemanager.scheduler.capacity.LeafQueue: assignedContainer application=application_1375792971633_0006 container=Container: [ContainerId: container_1375792971633_0006_01_000030, NodeId: hadoop-110-3:34727, NodeHttpAddress: hadoop-110-3:8042, Resource: <memory:1024, vCores:1>, Priority: 20, State: NEW, Token: null, Status: container_id {, app_attempt_id {, application_id {, id: 6, cluster_timestamp: 1375792971633, }, attemptId: 1, }, id: 30, }, state: C_NEW, ] containerId=container_1375792971633_0006_01_000030 queue=default: capacity=1.0, absoluteCapacity=1.0, usedResources=<memory:48128, vCores:42>usedCapacity=0.9791667, absoluteUsedCapacity=0.9791667, numApps=5, numContainers=42 usedCapacity=0.9791667 absoluteUsedCapacity=0.9791667 used=<memory:48128, vCores:42> cluster=<memory:49152, vCores:96>
2013-08-06 12:58:32,523 INFO org.apache.hadoop.yarn.server.resourcemanager.scheduler.capacity.ParentQueue: Re-sorting queues since queue: root.default stats: default: capacity=1.0, absoluteCapacity=1.0, usedResources=<memory:49152, vCores:43>usedCapacity=1.0, absoluteUsedCapacity=1.0, numApps=5, numContainers=43
2013-08-06 12:58:32,523 INFO org.apache.hadoop.yarn.server.resourcemanager.scheduler.capacity.ParentQueue: assignedContainer queue=root usedCapacity=1.0 absoluteUsedCapacity=1.0 used=<memory:49152, vCores:43> cluster=<memory:49152, vCores:96>
2013-08-06 12:58:32,628 INFO org.apache.hadoop.yarn.server.resourcemanager.rmcontainer.RMContainerImpl: container_1375792971633_0006_01_000010 Container Transitioned from RUNNING to COMPLETED
2013-08-06 12:58:32,628 INFO org.apache.hadoop.yarn.server.resourcemanager.scheduler.common.fica.FiCaSchedulerApp: Completed container: container_1375792971633_0006_01_000010 in state: COMPLETED event:FINISHED
2013-08-06 12:58:32,629 INFO org.apache.hadoop.yarn.server.resourcemanager.RMAuditLogger: USER=ubuntu	OPERATION=AM Released Container	TARGET=SchedulerApp	RESULT=SUCCESS	APPID=application_1375792971633_0006	CONTAINERID=container_1375792971633_0006_01_000010
2013-08-06 12:58:32,629 INFO org.apache.hadoop.yarn.server.resourcemanager.scheduler.common.fica.FiCaSchedulerNode: Released container container_1375792971633_0006_01_000010 of capacity <memory:1024, vCores:1> on host hadoop-110-6:50003, which currently has 6 containers, <memory:7168, vCores:6> used and <memory:1024, vCores:10> available, release resources=true
2013-08-06 12:58:32,629 INFO org.apache.hadoop.yarn.server.resourcemanager.scheduler.capacity.LeafQueue: default used=<memory:48128, vCores:42> numContainers=42 user=ubuntu user-resources=<memory:48128, vCores:42>
2013-08-06 12:58:32,630 INFO org.apache.hadoop.yarn.server.resourcemanager.scheduler.capacity.LeafQueue: completedContainer container=Container: [ContainerId: container_1375792971633_0006_01_000010, NodeId: hadoop-110-6:50003, NodeHttpAddress: hadoop-110-6:8042, Resource: <memory:1024, vCores:1>, Priority: 20, State: NEW, Token: null, Status: container_id {, app_attempt_id {, application_id {, id: 6, cluster_timestamp: 1375792971633, }, attemptId: 1, }, id: 10, }, state: C_COMPLETE, diagnostics: "Container killed by the ApplicationMaster.\n\n", exit_status: 143, ] resource=<memory:1024, vCores:1> queue=default: capacity=1.0, absoluteCapacity=1.0, usedResources=<memory:48128, vCores:42>usedCapacity=0.9791667, absoluteUsedCapacity=0.9791667, numApps=5, numContainers=42 usedCapacity=0.9791667 absoluteUsedCapacity=0.9791667 used=<memory:48128, vCores:42> cluster=<memory:49152, vCores:96>
2013-08-06 12:58:32,630 INFO org.apache.hadoop.yarn.server.resourcemanager.scheduler.capacity.ParentQueue: completedContainer queue=root usedCapacity=0.9791667 absoluteUsedCapacity=0.9791667 used=<memory:48128, vCores:42> cluster=<memory:49152, vCores:96>
2013-08-06 12:58:32,630 INFO org.apache.hadoop.yarn.server.resourcemanager.scheduler.capacity.CapacityScheduler: Application appattempt_1375792971633_0006_000001 released container container_1375792971633_0006_01_000010 on node: host: hadoop-110-6:50003 #containers=6 available=1024 used=7168 with event: FINISHED
2013-08-06 12:58:32,631 INFO org.apache.hadoop.yarn.server.resourcemanager.rmcontainer.RMContainerImpl: container_1375792971633_0006_01_000031 Container Transitioned from NEW to ALLOCATED
2013-08-06 12:58:32,631 INFO org.apache.hadoop.yarn.server.resourcemanager.RMAuditLogger: USER=ubuntu	OPERATION=AM Allocated Container	TARGET=SchedulerApp	RESULT=SUCCESS	APPID=application_1375792971633_0006	CONTAINERID=container_1375792971633_0006_01_000031
2013-08-06 12:58:32,631 INFO org.apache.hadoop.yarn.server.resourcemanager.scheduler.common.fica.FiCaSchedulerNode: Assigned container container_1375792971633_0006_01_000031 of capacity <memory:1024, vCores:1> on host hadoop-110-6:50003, which currently has 7 containers, <memory:8192, vCores:7> used and <memory:0, vCores:9> available
2013-08-06 12:58:32,632 INFO org.apache.hadoop.yarn.server.resourcemanager.scheduler.capacity.LeafQueue: assignedContainer application=application_1375792971633_0006 container=Container: [ContainerId: container_1375792971633_0006_01_000031, NodeId: hadoop-110-6:50003, NodeHttpAddress: hadoop-110-6:8042, Resource: <memory:1024, vCores:1>, Priority: 20, State: NEW, Token: null, Status: container_id {, app_attempt_id {, application_id {, id: 6, cluster_timestamp: 1375792971633, }, attemptId: 1, }, id: 31, }, state: C_NEW, ] containerId=container_1375792971633_0006_01_000031 queue=default: capacity=1.0, absoluteCapacity=1.0, usedResources=<memory:48128, vCores:42>usedCapacity=0.9791667, absoluteUsedCapacity=0.9791667, numApps=5, numContainers=42 usedCapacity=0.9791667 absoluteUsedCapacity=0.9791667 used=<memory:48128, vCores:42> cluster=<memory:49152, vCores:96>
2013-08-06 12:58:32,632 INFO org.apache.hadoop.yarn.server.resourcemanager.scheduler.capacity.ParentQueue: Re-sorting queues since queue: root.default stats: default: capacity=1.0, absoluteCapacity=1.0, usedResources=<memory:49152, vCores:43>usedCapacity=1.0, absoluteUsedCapacity=1.0, numApps=5, numContainers=43
2013-08-06 12:58:32,633 INFO org.apache.hadoop.yarn.server.resourcemanager.scheduler.capacity.ParentQueue: assignedContainer queue=root usedCapacity=1.0 absoluteUsedCapacity=1.0 used=<memory:49152, vCores:43> cluster=<memory:49152, vCores:96>
2013-08-06 12:58:32,740 INFO org.apache.hadoop.yarn.server.resourcemanager.rmcontainer.RMContainerImpl: container_1375792971633_0006_01_000030 Container Transitioned from ALLOCATED to ACQUIRED
2013-08-06 12:58:32,741 INFO org.apache.hadoop.yarn.server.resourcemanager.rmcontainer.RMContainerImpl: container_1375792971633_0006_01_000031 Container Transitioned from ALLOCATED to ACQUIRED
2013-08-06 12:58:33,527 INFO org.apache.hadoop.yarn.server.resourcemanager.rmcontainer.RMContainerImpl: container_1375792971633_0006_01_000030 Container Transitioned from ACQUIRED to RUNNING
2013-08-06 12:58:33,633 INFO org.apache.hadoop.yarn.server.resourcemanager.rmcontainer.RMContainerImpl: container_1375792971633_0006_01_000031 Container Transitioned from ACQUIRED to RUNNING
2013-08-06 12:58:34,407 INFO org.apache.hadoop.yarn.server.resourcemanager.rmcontainer.RMContainerImpl: container_1375792971633_0006_01_000009 Container Transitioned from RUNNING to COMPLETED
2013-08-06 12:58:34,407 INFO org.apache.hadoop.yarn.server.resourcemanager.scheduler.common.fica.FiCaSchedulerApp: Completed container: container_1375792971633_0006_01_000009 in state: COMPLETED event:FINISHED
2013-08-06 12:58:34,407 INFO org.apache.hadoop.yarn.server.resourcemanager.RMAuditLogger: USER=ubuntu	OPERATION=AM Released Container	TARGET=SchedulerApp	RESULT=SUCCESS	APPID=application_1375792971633_0006	CONTAINERID=container_1375792971633_0006_01_000009
2013-08-06 12:58:34,408 INFO org.apache.hadoop.yarn.server.resourcemanager.scheduler.common.fica.FiCaSchedulerNode: Released container container_1375792971633_0006_01_000009 of capacity <memory:1024, vCores:1> on host hadoop-110-5:54830, which currently has 7 containers, <memory:7168, vCores:7> used and <memory:1024, vCores:9> available, release resources=true
2013-08-06 12:58:34,408 INFO org.apache.hadoop.yarn.server.resourcemanager.scheduler.capacity.LeafQueue: default used=<memory:48128, vCores:42> numContainers=42 user=ubuntu user-resources=<memory:48128, vCores:42>
2013-08-06 12:58:34,409 INFO org.apache.hadoop.yarn.server.resourcemanager.scheduler.capacity.LeafQueue: completedContainer container=Container: [ContainerId: container_1375792971633_0006_01_000009, NodeId: hadoop-110-5:54830, NodeHttpAddress: hadoop-110-5:8042, Resource: <memory:1024, vCores:1>, Priority: 20, State: NEW, Token: null, Status: container_id {, app_attempt_id {, application_id {, id: 6, cluster_timestamp: 1375792971633, }, attemptId: 1, }, id: 9, }, state: C_COMPLETE, diagnostics: "Container killed by the ApplicationMaster.\n\n", exit_status: 143, ] resource=<memory:1024, vCores:1> queue=default: capacity=1.0, absoluteCapacity=1.0, usedResources=<memory:48128, vCores:42>usedCapacity=0.9791667, absoluteUsedCapacity=0.9791667, numApps=5, numContainers=42 usedCapacity=0.9791667 absoluteUsedCapacity=0.9791667 used=<memory:48128, vCores:42> cluster=<memory:49152, vCores:96>
2013-08-06 12:58:34,409 INFO org.apache.hadoop.yarn.server.resourcemanager.scheduler.capacity.ParentQueue: completedContainer queue=root usedCapacity=0.9791667 absoluteUsedCapacity=0.9791667 used=<memory:48128, vCores:42> cluster=<memory:49152, vCores:96>
2013-08-06 12:58:34,409 INFO org.apache.hadoop.yarn.server.resourcemanager.scheduler.capacity.CapacityScheduler: Application appattempt_1375792971633_0006_000001 released container container_1375792971633_0006_01_000009 on node: host: hadoop-110-5:54830 #containers=7 available=1024 used=7168 with event: FINISHED
2013-08-06 12:58:34,410 INFO org.apache.hadoop.yarn.server.resourcemanager.rmcontainer.RMContainerImpl: container_1375792971633_0006_01_000032 Container Transitioned from NEW to ALLOCATED
2013-08-06 12:58:34,410 INFO org.apache.hadoop.yarn.server.resourcemanager.RMAuditLogger: USER=ubuntu	OPERATION=AM Allocated Container	TARGET=SchedulerApp	RESULT=SUCCESS	APPID=application_1375792971633_0006	CONTAINERID=container_1375792971633_0006_01_000032
2013-08-06 12:58:34,410 INFO org.apache.hadoop.yarn.server.resourcemanager.scheduler.common.fica.FiCaSchedulerNode: Assigned container container_1375792971633_0006_01_000032 of capacity <memory:1024, vCores:1> on host hadoop-110-5:54830, which currently has 8 containers, <memory:8192, vCores:8> used and <memory:0, vCores:8> available
2013-08-06 12:58:34,411 INFO org.apache.hadoop.yarn.server.resourcemanager.scheduler.capacity.LeafQueue: assignedContainer application=application_1375792971633_0006 container=Container: [ContainerId: container_1375792971633_0006_01_000032, NodeId: hadoop-110-5:54830, NodeHttpAddress: hadoop-110-5:8042, Resource: <memory:1024, vCores:1>, Priority: 20, State: NEW, Token: null, Status: container_id {, app_attempt_id {, application_id {, id: 6, cluster_timestamp: 1375792971633, }, attemptId: 1, }, id: 32, }, state: C_NEW, ] containerId=container_1375792971633_0006_01_000032 queue=default: capacity=1.0, absoluteCapacity=1.0, usedResources=<memory:48128, vCores:42>usedCapacity=0.9791667, absoluteUsedCapacity=0.9791667, numApps=5, numContainers=42 usedCapacity=0.9791667 absoluteUsedCapacity=0.9791667 used=<memory:48128, vCores:42> cluster=<memory:49152, vCores:96>
2013-08-06 12:58:34,411 INFO org.apache.hadoop.yarn.server.resourcemanager.scheduler.capacity.ParentQueue: Re-sorting queues since queue: root.default stats: default: capacity=1.0, absoluteCapacity=1.0, usedResources=<memory:49152, vCores:43>usedCapacity=1.0, absoluteUsedCapacity=1.0, numApps=5, numContainers=43
2013-08-06 12:58:34,412 INFO org.apache.hadoop.yarn.server.resourcemanager.scheduler.capacity.ParentQueue: assignedContainer queue=root usedCapacity=1.0 absoluteUsedCapacity=1.0 used=<memory:49152, vCores:43> cluster=<memory:49152, vCores:96>
2013-08-06 12:58:34,775 INFO org.apache.hadoop.yarn.server.resourcemanager.rmcontainer.RMContainerImpl: container_1375792971633_0006_01_000032 Container Transitioned from ALLOCATED to ACQUIRED
2013-08-06 12:58:35,416 INFO org.apache.hadoop.yarn.server.resourcemanager.rmcontainer.RMContainerImpl: container_1375792971633_0006_01_000032 Container Transitioned from ACQUIRED to RUNNING
2013-08-06 12:58:35,416 INFO org.apache.hadoop.yarn.server.resourcemanager.rmcontainer.RMContainerImpl: container_1375792971633_0006_01_000002 Container Transitioned from RUNNING to COMPLETED
2013-08-06 12:58:35,416 INFO org.apache.hadoop.yarn.server.resourcemanager.scheduler.common.fica.FiCaSchedulerApp: Completed container: container_1375792971633_0006_01_000002 in state: COMPLETED event:FINISHED
2013-08-06 12:58:35,416 INFO org.apache.hadoop.yarn.server.resourcemanager.RMAuditLogger: USER=ubuntu	OPERATION=AM Released Container	TARGET=SchedulerApp	RESULT=SUCCESS	APPID=application_1375792971633_0006	CONTAINERID=container_1375792971633_0006_01_000002
2013-08-06 12:58:35,417 INFO org.apache.hadoop.yarn.server.resourcemanager.scheduler.common.fica.FiCaSchedulerNode: Released container container_1375792971633_0006_01_000002 of capacity <memory:1024, vCores:1> on host hadoop-110-5:54830, which currently has 7 containers, <memory:7168, vCores:7> used and <memory:1024, vCores:9> available, release resources=true
2013-08-06 12:58:35,417 INFO org.apache.hadoop.yarn.server.resourcemanager.scheduler.capacity.LeafQueue: default used=<memory:48128, vCores:42> numContainers=42 user=ubuntu user-resources=<memory:48128, vCores:42>
2013-08-06 12:58:35,418 INFO org.apache.hadoop.yarn.server.resourcemanager.scheduler.capacity.LeafQueue: completedContainer container=Container: [ContainerId: container_1375792971633_0006_01_000002, NodeId: hadoop-110-5:54830, NodeHttpAddress: hadoop-110-5:8042, Resource: <memory:1024, vCores:1>, Priority: 20, State: NEW, Token: null, Status: container_id {, app_attempt_id {, application_id {, id: 6, cluster_timestamp: 1375792971633, }, attemptId: 1, }, id: 2, }, state: C_COMPLETE, diagnostics: "Container killed by the ApplicationMaster.\n\n", exit_status: 143, ] resource=<memory:1024, vCores:1> queue=default: capacity=1.0, absoluteCapacity=1.0, usedResources=<memory:48128, vCores:42>usedCapacity=0.9791667, absoluteUsedCapacity=0.9791667, numApps=5, numContainers=42 usedCapacity=0.9791667 absoluteUsedCapacity=0.9791667 used=<memory:48128, vCores:42> cluster=<memory:49152, vCores:96>
2013-08-06 12:58:35,418 INFO org.apache.hadoop.yarn.server.resourcemanager.scheduler.capacity.ParentQueue: completedContainer queue=root usedCapacity=0.9791667 absoluteUsedCapacity=0.9791667 used=<memory:48128, vCores:42> cluster=<memory:49152, vCores:96>
2013-08-06 12:58:35,418 INFO org.apache.hadoop.yarn.server.resourcemanager.scheduler.capacity.CapacityScheduler: Application appattempt_1375792971633_0006_000001 released container container_1375792971633_0006_01_000002 on node: host: hadoop-110-5:54830 #containers=7 available=1024 used=7168 with event: FINISHED
2013-08-06 12:58:35,419 INFO org.apache.hadoop.yarn.server.resourcemanager.rmcontainer.RMContainerImpl: container_1375792971633_0006_01_000033 Container Transitioned from NEW to ALLOCATED
2013-08-06 12:58:35,419 INFO org.apache.hadoop.yarn.server.resourcemanager.RMAuditLogger: USER=ubuntu	OPERATION=AM Allocated Container	TARGET=SchedulerApp	RESULT=SUCCESS	APPID=application_1375792971633_0006	CONTAINERID=container_1375792971633_0006_01_000033
2013-08-06 12:58:35,419 INFO org.apache.hadoop.yarn.server.resourcemanager.scheduler.common.fica.FiCaSchedulerNode: Assigned container container_1375792971633_0006_01_000033 of capacity <memory:1024, vCores:1> on host hadoop-110-5:54830, which currently has 8 containers, <memory:8192, vCores:8> used and <memory:0, vCores:8> available
2013-08-06 12:58:35,420 INFO org.apache.hadoop.yarn.server.resourcemanager.scheduler.capacity.LeafQueue: assignedContainer application=application_1375792971633_0006 container=Container: [ContainerId: container_1375792971633_0006_01_000033, NodeId: hadoop-110-5:54830, NodeHttpAddress: hadoop-110-5:8042, Resource: <memory:1024, vCores:1>, Priority: 10, State: NEW, Token: null, Status: container_id {, app_attempt_id {, application_id {, id: 6, cluster_timestamp: 1375792971633, }, attemptId: 1, }, id: 33, }, state: C_NEW, ] containerId=container_1375792971633_0006_01_000033 queue=default: capacity=1.0, absoluteCapacity=1.0, usedResources=<memory:48128, vCores:42>usedCapacity=0.9791667, absoluteUsedCapacity=0.9791667, numApps=5, numContainers=42 usedCapacity=0.9791667 absoluteUsedCapacity=0.9791667 used=<memory:48128, vCores:42> cluster=<memory:49152, vCores:96>
2013-08-06 12:58:35,420 INFO org.apache.hadoop.yarn.server.resourcemanager.scheduler.capacity.ParentQueue: Re-sorting queues since queue: root.default stats: default: capacity=1.0, absoluteCapacity=1.0, usedResources=<memory:49152, vCores:43>usedCapacity=1.0, absoluteUsedCapacity=1.0, numApps=5, numContainers=43
2013-08-06 12:58:35,421 INFO org.apache.hadoop.yarn.server.resourcemanager.scheduler.capacity.ParentQueue: assignedContainer queue=root usedCapacity=1.0 absoluteUsedCapacity=1.0 used=<memory:49152, vCores:43> cluster=<memory:49152, vCores:96>
2013-08-06 12:58:35,782 INFO org.apache.hadoop.yarn.server.resourcemanager.rmcontainer.RMContainerImpl: container_1375792971633_0006_01_000033 Container Transitioned from ALLOCATED to ACQUIRED
2013-08-06 12:58:36,422 INFO org.apache.hadoop.yarn.server.resourcemanager.rmcontainer.RMContainerImpl: container_1375792971633_0006_01_000033 Container Transitioned from ACQUIRED to RUNNING
2013-08-06 12:58:36,788 INFO org.apache.hadoop.yarn.server.resourcemanager.scheduler.AppSchedulingInfo: checking for deactivate... 
2013-08-06 12:58:37,154 INFO org.apache.hadoop.yarn.server.resourcemanager.rmcontainer.RMContainerImpl: container_1375792971633_0006_01_000011 Container Transitioned from RUNNING to COMPLETED
2013-08-06 12:58:37,155 INFO org.apache.hadoop.yarn.server.resourcemanager.scheduler.common.fica.FiCaSchedulerApp: Completed container: container_1375792971633_0006_01_000011 in state: COMPLETED event:FINISHED
2013-08-06 12:58:37,155 INFO org.apache.hadoop.yarn.server.resourcemanager.RMAuditLogger: USER=ubuntu	OPERATION=AM Released Container	TARGET=SchedulerApp	RESULT=SUCCESS	APPID=application_1375792971633_0006	CONTAINERID=container_1375792971633_0006_01_000011
2013-08-06 12:58:37,155 INFO org.apache.hadoop.yarn.server.resourcemanager.scheduler.common.fica.FiCaSchedulerNode: Released container container_1375792971633_0006_01_000011 of capacity <memory:1024, vCores:1> on host hadoop-110-6:50003, which currently has 6 containers, <memory:7168, vCores:6> used and <memory:1024, vCores:10> available, release resources=true
2013-08-06 12:58:37,155 INFO org.apache.hadoop.yarn.server.resourcemanager.scheduler.capacity.LeafQueue: default used=<memory:48128, vCores:42> numContainers=42 user=ubuntu user-resources=<memory:48128, vCores:42>
2013-08-06 12:58:37,156 INFO org.apache.hadoop.yarn.server.resourcemanager.scheduler.capacity.LeafQueue: completedContainer container=Container: [ContainerId: container_1375792971633_0006_01_000011, NodeId: hadoop-110-6:50003, NodeHttpAddress: hadoop-110-6:8042, Resource: <memory:1024, vCores:1>, Priority: 20, State: NEW, Token: null, Status: container_id {, app_attempt_id {, application_id {, id: 6, cluster_timestamp: 1375792971633, }, attemptId: 1, }, id: 11, }, state: C_COMPLETE, diagnostics: "Container killed by the ApplicationMaster.\n\n", exit_status: 143, ] resource=<memory:1024, vCores:1> queue=default: capacity=1.0, absoluteCapacity=1.0, usedResources=<memory:48128, vCores:42>usedCapacity=0.9791667, absoluteUsedCapacity=0.9791667, numApps=5, numContainers=42 usedCapacity=0.9791667 absoluteUsedCapacity=0.9791667 used=<memory:48128, vCores:42> cluster=<memory:49152, vCores:96>
2013-08-06 12:58:37,156 INFO org.apache.hadoop.yarn.server.resourcemanager.scheduler.capacity.ParentQueue: completedContainer queue=root usedCapacity=0.9791667 absoluteUsedCapacity=0.9791667 used=<memory:48128, vCores:42> cluster=<memory:49152, vCores:96>
2013-08-06 12:58:37,156 INFO org.apache.hadoop.yarn.server.resourcemanager.scheduler.capacity.CapacityScheduler: Application appattempt_1375792971633_0006_000001 released container container_1375792971633_0006_01_000011 on node: host: hadoop-110-6:50003 #containers=6 available=1024 used=7168 with event: FINISHED
2013-08-06 12:58:37,157 INFO org.apache.hadoop.yarn.server.resourcemanager.rmcontainer.RMContainerImpl: container_1375792971633_0006_01_000034 Container Transitioned from NEW to ALLOCATED
2013-08-06 12:58:37,157 INFO org.apache.hadoop.yarn.server.resourcemanager.RMAuditLogger: USER=ubuntu	OPERATION=AM Allocated Container	TARGET=SchedulerApp	RESULT=SUCCESS	APPID=application_1375792971633_0006	CONTAINERID=container_1375792971633_0006_01_000034
2013-08-06 12:58:37,157 INFO org.apache.hadoop.yarn.server.resourcemanager.scheduler.common.fica.FiCaSchedulerNode: Assigned container container_1375792971633_0006_01_000034 of capacity <memory:1024, vCores:1> on host hadoop-110-6:50003, which currently has 7 containers, <memory:8192, vCores:7> used and <memory:0, vCores:9> available
2013-08-06 12:58:37,158 INFO org.apache.hadoop.yarn.server.resourcemanager.scheduler.capacity.LeafQueue: assignedContainer application=application_1375792971633_0006 container=Container: [ContainerId: container_1375792971633_0006_01_000034, NodeId: hadoop-110-6:50003, NodeHttpAddress: hadoop-110-6:8042, Resource: <memory:1024, vCores:1>, Priority: 20, State: NEW, Token: null, Status: container_id {, app_attempt_id {, application_id {, id: 6, cluster_timestamp: 1375792971633, }, attemptId: 1, }, id: 34, }, state: C_NEW, ] containerId=container_1375792971633_0006_01_000034 queue=default: capacity=1.0, absoluteCapacity=1.0, usedResources=<memory:48128, vCores:42>usedCapacity=0.9791667, absoluteUsedCapacity=0.9791667, numApps=5, numContainers=42 usedCapacity=0.9791667 absoluteUsedCapacity=0.9791667 used=<memory:48128, vCores:42> cluster=<memory:49152, vCores:96>
2013-08-06 12:58:37,158 INFO org.apache.hadoop.yarn.server.resourcemanager.scheduler.capacity.ParentQueue: Re-sorting queues since queue: root.default stats: default: capacity=1.0, absoluteCapacity=1.0, usedResources=<memory:49152, vCores:43>usedCapacity=1.0, absoluteUsedCapacity=1.0, numApps=5, numContainers=43
2013-08-06 12:58:37,159 INFO org.apache.hadoop.yarn.server.resourcemanager.scheduler.capacity.ParentQueue: assignedContainer queue=root usedCapacity=1.0 absoluteUsedCapacity=1.0 used=<memory:49152, vCores:43> cluster=<memory:49152, vCores:96>
2013-08-06 12:58:37,792 INFO org.apache.hadoop.yarn.server.resourcemanager.rmcontainer.RMContainerImpl: container_1375792971633_0006_01_000034 Container Transitioned from ALLOCATED to ACQUIRED
2013-08-06 12:58:38,187 INFO org.apache.hadoop.yarn.server.resourcemanager.rmcontainer.RMContainerImpl: container_1375792971633_0006_01_000034 Container Transitioned from ACQUIRED to RUNNING
2013-08-06 12:58:38,187 INFO org.apache.hadoop.yarn.server.resourcemanager.rmcontainer.RMContainerImpl: container_1375792971633_0006_01_000015 Container Transitioned from RUNNING to COMPLETED
2013-08-06 12:58:38,187 INFO org.apache.hadoop.yarn.server.resourcemanager.scheduler.common.fica.FiCaSchedulerApp: Completed container: container_1375792971633_0006_01_000015 in state: COMPLETED event:FINISHED
2013-08-06 12:58:38,188 INFO org.apache.hadoop.yarn.server.resourcemanager.RMAuditLogger: USER=ubuntu	OPERATION=AM Released Container	TARGET=SchedulerApp	RESULT=SUCCESS	APPID=application_1375792971633_0006	CONTAINERID=container_1375792971633_0006_01_000015
2013-08-06 12:58:38,188 INFO org.apache.hadoop.yarn.server.resourcemanager.scheduler.common.fica.FiCaSchedulerNode: Released container container_1375792971633_0006_01_000015 of capacity <memory:1024, vCores:1> on host hadoop-110-6:50003, which currently has 6 containers, <memory:7168, vCores:6> used and <memory:1024, vCores:10> available, release resources=true
2013-08-06 12:58:38,188 INFO org.apache.hadoop.yarn.server.resourcemanager.scheduler.capacity.LeafQueue: default used=<memory:48128, vCores:42> numContainers=42 user=ubuntu user-resources=<memory:48128, vCores:42>
2013-08-06 12:58:38,189 INFO org.apache.hadoop.yarn.server.resourcemanager.scheduler.capacity.LeafQueue: completedContainer container=Container: [ContainerId: container_1375792971633_0006_01_000015, NodeId: hadoop-110-6:50003, NodeHttpAddress: hadoop-110-6:8042, Resource: <memory:1024, vCores:1>, Priority: 20, State: NEW, Token: null, Status: container_id {, app_attempt_id {, application_id {, id: 6, cluster_timestamp: 1375792971633, }, attemptId: 1, }, id: 15, }, state: C_COMPLETE, diagnostics: "Container killed by the ApplicationMaster.\n\n", exit_status: 143, ] resource=<memory:1024, vCores:1> queue=default: capacity=1.0, absoluteCapacity=1.0, usedResources=<memory:48128, vCores:42>usedCapacity=0.9791667, absoluteUsedCapacity=0.9791667, numApps=5, numContainers=42 usedCapacity=0.9791667 absoluteUsedCapacity=0.9791667 used=<memory:48128, vCores:42> cluster=<memory:49152, vCores:96>
2013-08-06 12:58:38,189 INFO org.apache.hadoop.yarn.server.resourcemanager.scheduler.capacity.ParentQueue: completedContainer queue=root usedCapacity=0.9791667 absoluteUsedCapacity=0.9791667 used=<memory:48128, vCores:42> cluster=<memory:49152, vCores:96>
2013-08-06 12:58:38,190 INFO org.apache.hadoop.yarn.server.resourcemanager.scheduler.capacity.CapacityScheduler: Application appattempt_1375792971633_0006_000001 released container container_1375792971633_0006_01_000015 on node: host: hadoop-110-6:50003 #containers=6 available=1024 used=7168 with event: FINISHED
2013-08-06 12:58:38,190 INFO org.apache.hadoop.yarn.server.resourcemanager.rmcontainer.RMContainerImpl: container_1375792971633_0006_01_000035 Container Transitioned from NEW to ALLOCATED
2013-08-06 12:58:38,190 INFO org.apache.hadoop.yarn.server.resourcemanager.RMAuditLogger: USER=ubuntu	OPERATION=AM Allocated Container	TARGET=SchedulerApp	RESULT=SUCCESS	APPID=application_1375792971633_0006	CONTAINERID=container_1375792971633_0006_01_000035
2013-08-06 12:58:38,190 INFO org.apache.hadoop.yarn.server.resourcemanager.scheduler.common.fica.FiCaSchedulerNode: Assigned container container_1375792971633_0006_01_000035 of capacity <memory:1024, vCores:1> on host hadoop-110-6:50003, which currently has 7 containers, <memory:8192, vCores:7> used and <memory:0, vCores:9> available
2013-08-06 12:58:38,191 INFO org.apache.hadoop.yarn.server.resourcemanager.scheduler.capacity.LeafQueue: assignedContainer application=application_1375792971633_0006 container=Container: [ContainerId: container_1375792971633_0006_01_000035, NodeId: hadoop-110-6:50003, NodeHttpAddress: hadoop-110-6:8042, Resource: <memory:1024, vCores:1>, Priority: 20, State: NEW, Token: null, Status: container_id {, app_attempt_id {, application_id {, id: 6, cluster_timestamp: 1375792971633, }, attemptId: 1, }, id: 35, }, state: C_NEW, ] containerId=container_1375792971633_0006_01_000035 queue=default: capacity=1.0, absoluteCapacity=1.0, usedResources=<memory:48128, vCores:42>usedCapacity=0.9791667, absoluteUsedCapacity=0.9791667, numApps=5, numContainers=42 usedCapacity=0.9791667 absoluteUsedCapacity=0.9791667 used=<memory:48128, vCores:42> cluster=<memory:49152, vCores:96>
2013-08-06 12:58:38,191 INFO org.apache.hadoop.yarn.server.resourcemanager.scheduler.capacity.ParentQueue: Re-sorting queues since queue: root.default stats: default: capacity=1.0, absoluteCapacity=1.0, usedResources=<memory:49152, vCores:43>usedCapacity=1.0, absoluteUsedCapacity=1.0, numApps=5, numContainers=43
2013-08-06 12:58:38,192 INFO org.apache.hadoop.yarn.server.resourcemanager.scheduler.capacity.ParentQueue: assignedContainer queue=root usedCapacity=1.0 absoluteUsedCapacity=1.0 used=<memory:49152, vCores:43> cluster=<memory:49152, vCores:96>
2013-08-06 12:58:38,725 INFO org.apache.hadoop.yarn.server.resourcemanager.rmcontainer.RMContainerImpl: container_1375792971633_0008_01_000013 Container Transitioned from RUNNING to COMPLETED
2013-08-06 12:58:38,725 INFO org.apache.hadoop.yarn.server.resourcemanager.scheduler.common.fica.FiCaSchedulerApp: Completed container: container_1375792971633_0008_01_000013 in state: COMPLETED event:FINISHED
2013-08-06 12:58:38,725 INFO org.apache.hadoop.yarn.server.resourcemanager.RMAuditLogger: USER=ubuntu	OPERATION=AM Released Container	TARGET=SchedulerApp	RESULT=SUCCESS	APPID=application_1375792971633_0008	CONTAINERID=container_1375792971633_0008_01_000013
2013-08-06 12:58:38,725 INFO org.apache.hadoop.yarn.server.resourcemanager.scheduler.common.fica.FiCaSchedulerNode: Released container container_1375792971633_0008_01_000013 of capacity <memory:1024, vCores:1> on host hadoop-110-7:55372, which currently has 6 containers, <memory:7168, vCores:6> used and <memory:1024, vCores:10> available, release resources=true
2013-08-06 12:58:38,725 INFO org.apache.hadoop.yarn.server.resourcemanager.scheduler.capacity.LeafQueue: default used=<memory:48128, vCores:42> numContainers=42 user=ubuntu user-resources=<memory:48128, vCores:42>
2013-08-06 12:58:38,726 INFO org.apache.hadoop.yarn.server.resourcemanager.scheduler.capacity.LeafQueue: completedContainer container=Container: [ContainerId: container_1375792971633_0008_01_000013, NodeId: hadoop-110-7:55372, NodeHttpAddress: hadoop-110-7:8042, Resource: <memory:1024, vCores:1>, Priority: 20, State: NEW, Token: null, Status: container_id {, app_attempt_id {, application_id {, id: 8, cluster_timestamp: 1375792971633, }, attemptId: 1, }, id: 13, }, state: C_COMPLETE, diagnostics: "Container killed by the ApplicationMaster.\n", exit_status: 0, ] resource=<memory:1024, vCores:1> queue=default: capacity=1.0, absoluteCapacity=1.0, usedResources=<memory:48128, vCores:42>usedCapacity=0.9791667, absoluteUsedCapacity=0.9791667, numApps=5, numContainers=42 usedCapacity=0.9791667 absoluteUsedCapacity=0.9791667 used=<memory:48128, vCores:42> cluster=<memory:49152, vCores:96>
2013-08-06 12:58:38,727 INFO org.apache.hadoop.yarn.server.resourcemanager.scheduler.capacity.ParentQueue: completedContainer queue=root usedCapacity=0.9791667 absoluteUsedCapacity=0.9791667 used=<memory:48128, vCores:42> cluster=<memory:49152, vCores:96>
2013-08-06 12:58:38,727 INFO org.apache.hadoop.yarn.server.resourcemanager.scheduler.capacity.CapacityScheduler: Application appattempt_1375792971633_0008_000001 released container container_1375792971633_0008_01_000013 on node: host: hadoop-110-7:55372 #containers=6 available=1024 used=7168 with event: FINISHED
2013-08-06 12:58:38,727 INFO org.apache.hadoop.yarn.server.resourcemanager.rmcontainer.RMContainerImpl: container_1375792971633_0008_01_000016 Container Transitioned from RUNNING to COMPLETED
2013-08-06 12:58:38,727 INFO org.apache.hadoop.yarn.server.resourcemanager.scheduler.common.fica.FiCaSchedulerApp: Completed container: container_1375792971633_0008_01_000016 in state: COMPLETED event:FINISHED
2013-08-06 12:58:38,727 INFO org.apache.hadoop.yarn.server.resourcemanager.RMAuditLogger: USER=ubuntu	OPERATION=AM Released Container	TARGET=SchedulerApp	RESULT=SUCCESS	APPID=application_1375792971633_0008	CONTAINERID=container_1375792971633_0008_01_000016
2013-08-06 12:58:38,728 INFO org.apache.hadoop.yarn.server.resourcemanager.scheduler.common.fica.FiCaSchedulerNode: Released container container_1375792971633_0008_01_000016 of capacity <memory:1024, vCores:1> on host hadoop-110-7:55372, which currently has 5 containers, <memory:6144, vCores:5> used and <memory:2048, vCores:11> available, release resources=true
2013-08-06 12:58:38,728 INFO org.apache.hadoop.yarn.server.resourcemanager.scheduler.capacity.LeafQueue: default used=<memory:47104, vCores:41> numContainers=41 user=ubuntu user-resources=<memory:47104, vCores:41>
2013-08-06 12:58:38,729 INFO org.apache.hadoop.yarn.server.resourcemanager.scheduler.capacity.LeafQueue: completedContainer container=Container: [ContainerId: container_1375792971633_0008_01_000016, NodeId: hadoop-110-7:55372, NodeHttpAddress: hadoop-110-7:8042, Resource: <memory:1024, vCores:1>, Priority: 20, State: NEW, Token: null, Status: container_id {, app_attempt_id {, application_id {, id: 8, cluster_timestamp: 1375792971633, }, attemptId: 1, }, id: 16, }, state: C_COMPLETE, diagnostics: "Container killed by the ApplicationMaster.\n", exit_status: 0, ] resource=<memory:1024, vCores:1> queue=default: capacity=1.0, absoluteCapacity=1.0, usedResources=<memory:47104, vCores:41>usedCapacity=0.9583333, absoluteUsedCapacity=0.9583333, numApps=5, numContainers=41 usedCapacity=0.9583333 absoluteUsedCapacity=0.9583333 used=<memory:47104, vCores:41> cluster=<memory:49152, vCores:96>
2013-08-06 12:58:38,729 INFO org.apache.hadoop.yarn.server.resourcemanager.scheduler.capacity.ParentQueue: completedContainer queue=root usedCapacity=0.9583333 absoluteUsedCapacity=0.9583333 used=<memory:47104, vCores:41> cluster=<memory:49152, vCores:96>
2013-08-06 12:58:38,729 INFO org.apache.hadoop.yarn.server.resourcemanager.scheduler.capacity.CapacityScheduler: Application appattempt_1375792971633_0008_000001 released container container_1375792971633_0008_01_000016 on node: host: hadoop-110-7:55372 #containers=5 available=2048 used=6144 with event: FINISHED
2013-08-06 12:58:38,729 INFO org.apache.hadoop.yarn.server.resourcemanager.rmcontainer.RMContainerImpl: container_1375792971633_0006_01_000036 Container Transitioned from NEW to ALLOCATED
2013-08-06 12:58:38,730 INFO org.apache.hadoop.yarn.server.resourcemanager.RMAuditLogger: USER=ubuntu	OPERATION=AM Allocated Container	TARGET=SchedulerApp	RESULT=SUCCESS	APPID=application_1375792971633_0006	CONTAINERID=container_1375792971633_0006_01_000036
2013-08-06 12:58:38,730 INFO org.apache.hadoop.yarn.server.resourcemanager.scheduler.common.fica.FiCaSchedulerNode: Assigned container container_1375792971633_0006_01_000036 of capacity <memory:1024, vCores:1> on host hadoop-110-7:55372, which currently has 6 containers, <memory:7168, vCores:6> used and <memory:1024, vCores:10> available
2013-08-06 12:58:38,730 INFO org.apache.hadoop.yarn.server.resourcemanager.scheduler.capacity.LeafQueue: assignedContainer application=application_1375792971633_0006 container=Container: [ContainerId: container_1375792971633_0006_01_000036, NodeId: hadoop-110-7:55372, NodeHttpAddress: hadoop-110-7:8042, Resource: <memory:1024, vCores:1>, Priority: 20, State: NEW, Token: null, Status: container_id {, app_attempt_id {, application_id {, id: 6, cluster_timestamp: 1375792971633, }, attemptId: 1, }, id: 36, }, state: C_NEW, ] containerId=container_1375792971633_0006_01_000036 queue=default: capacity=1.0, absoluteCapacity=1.0, usedResources=<memory:47104, vCores:41>usedCapacity=0.9583333, absoluteUsedCapacity=0.9583333, numApps=5, numContainers=41 usedCapacity=0.9583333 absoluteUsedCapacity=0.9583333 used=<memory:47104, vCores:41> cluster=<memory:49152, vCores:96>
2013-08-06 12:58:38,731 INFO org.apache.hadoop.yarn.server.resourcemanager.scheduler.capacity.ParentQueue: Re-sorting queues since queue: root.default stats: default: capacity=1.0, absoluteCapacity=1.0, usedResources=<memory:48128, vCores:42>usedCapacity=0.9791667, absoluteUsedCapacity=0.9791667, numApps=5, numContainers=42
2013-08-06 12:58:38,731 INFO org.apache.hadoop.yarn.server.resourcemanager.scheduler.capacity.ParentQueue: assignedContainer queue=root usedCapacity=0.9791667 absoluteUsedCapacity=0.9791667 used=<memory:48128, vCores:42> cluster=<memory:49152, vCores:96>
2013-08-06 12:58:38,731 INFO org.apache.hadoop.yarn.server.resourcemanager.rmcontainer.RMContainerImpl: container_1375792971633_0006_01_000037 Container Transitioned from NEW to ALLOCATED
2013-08-06 12:58:38,731 INFO org.apache.hadoop.yarn.server.resourcemanager.RMAuditLogger: USER=ubuntu	OPERATION=AM Allocated Container	TARGET=SchedulerApp	RESULT=SUCCESS	APPID=application_1375792971633_0006	CONTAINERID=container_1375792971633_0006_01_000037
2013-08-06 12:58:38,732 INFO org.apache.hadoop.yarn.server.resourcemanager.scheduler.common.fica.FiCaSchedulerNode: Assigned container container_1375792971633_0006_01_000037 of capacity <memory:1024, vCores:1> on host hadoop-110-7:55372, which currently has 7 containers, <memory:8192, vCores:7> used and <memory:0, vCores:9> available
2013-08-06 12:58:38,732 INFO org.apache.hadoop.yarn.server.resourcemanager.scheduler.capacity.LeafQueue: assignedContainer application=application_1375792971633_0006 container=Container: [ContainerId: container_1375792971633_0006_01_000037, NodeId: hadoop-110-7:55372, NodeHttpAddress: hadoop-110-7:8042, Resource: <memory:1024, vCores:1>, Priority: 20, State: NEW, Token: null, Status: container_id {, app_attempt_id {, application_id {, id: 6, cluster_timestamp: 1375792971633, }, attemptId: 1, }, id: 37, }, state: C_NEW, ] containerId=container_1375792971633_0006_01_000037 queue=default: capacity=1.0, absoluteCapacity=1.0, usedResources=<memory:48128, vCores:42>usedCapacity=0.9791667, absoluteUsedCapacity=0.9791667, numApps=5, numContainers=42 usedCapacity=0.9791667 absoluteUsedCapacity=0.9791667 used=<memory:48128, vCores:42> cluster=<memory:49152, vCores:96>
2013-08-06 12:58:38,733 INFO org.apache.hadoop.yarn.server.resourcemanager.scheduler.capacity.ParentQueue: Re-sorting queues since queue: root.default stats: default: capacity=1.0, absoluteCapacity=1.0, usedResources=<memory:49152, vCores:43>usedCapacity=1.0, absoluteUsedCapacity=1.0, numApps=5, numContainers=43
2013-08-06 12:58:38,733 INFO org.apache.hadoop.yarn.server.resourcemanager.scheduler.capacity.ParentQueue: assignedContainer queue=root usedCapacity=1.0 absoluteUsedCapacity=1.0 used=<memory:49152, vCores:43> cluster=<memory:49152, vCores:96>
2013-08-06 12:58:38,806 INFO org.apache.hadoop.yarn.server.resourcemanager.rmcontainer.RMContainerImpl: container_1375792971633_0006_01_000035 Container Transitioned from ALLOCATED to ACQUIRED
2013-08-06 12:58:38,807 INFO org.apache.hadoop.yarn.server.resourcemanager.rmcontainer.RMContainerImpl: container_1375792971633_0006_01_000036 Container Transitioned from ALLOCATED to ACQUIRED
2013-08-06 12:58:38,807 INFO org.apache.hadoop.yarn.server.resourcemanager.rmcontainer.RMContainerImpl: container_1375792971633_0006_01_000037 Container Transitioned from ALLOCATED to ACQUIRED
2013-08-06 12:58:39,715 INFO org.apache.hadoop.yarn.server.resourcemanager.rmcontainer.RMContainerImpl: container_1375792971633_0006_01_000035 Container Transitioned from ACQUIRED to RUNNING
2013-08-06 12:58:39,715 INFO org.apache.hadoop.yarn.server.resourcemanager.rmcontainer.RMContainerImpl: container_1375792971633_0006_01_000013 Container Transitioned from RUNNING to COMPLETED
2013-08-06 12:58:39,716 INFO org.apache.hadoop.yarn.server.resourcemanager.scheduler.common.fica.FiCaSchedulerApp: Completed container: container_1375792971633_0006_01_000013 in state: COMPLETED event:FINISHED
2013-08-06 12:58:39,716 INFO org.apache.hadoop.yarn.server.resourcemanager.RMAuditLogger: USER=ubuntu	OPERATION=AM Released Container	TARGET=SchedulerApp	RESULT=SUCCESS	APPID=application_1375792971633_0006	CONTAINERID=container_1375792971633_0006_01_000013
2013-08-06 12:58:39,716 INFO org.apache.hadoop.yarn.server.resourcemanager.scheduler.common.fica.FiCaSchedulerNode: Released container container_1375792971633_0006_01_000013 of capacity <memory:1024, vCores:1> on host hadoop-110-6:50003, which currently has 6 containers, <memory:7168, vCores:6> used and <memory:1024, vCores:10> available, release resources=true
2013-08-06 12:58:39,716 INFO org.apache.hadoop.yarn.server.resourcemanager.scheduler.capacity.LeafQueue: default used=<memory:48128, vCores:42> numContainers=42 user=ubuntu user-resources=<memory:48128, vCores:42>
2013-08-06 12:58:39,717 INFO org.apache.hadoop.yarn.server.resourcemanager.scheduler.capacity.LeafQueue: completedContainer container=Container: [ContainerId: container_1375792971633_0006_01_000013, NodeId: hadoop-110-6:50003, NodeHttpAddress: hadoop-110-6:8042, Resource: <memory:1024, vCores:1>, Priority: 20, State: NEW, Token: null, Status: container_id {, app_attempt_id {, application_id {, id: 6, cluster_timestamp: 1375792971633, }, attemptId: 1, }, id: 13, }, state: C_COMPLETE, diagnostics: "Container killed by the ApplicationMaster.\n\n", exit_status: 143, ] resource=<memory:1024, vCores:1> queue=default: capacity=1.0, absoluteCapacity=1.0, usedResources=<memory:48128, vCores:42>usedCapacity=0.9791667, absoluteUsedCapacity=0.9791667, numApps=5, numContainers=42 usedCapacity=0.9791667 absoluteUsedCapacity=0.9791667 used=<memory:48128, vCores:42> cluster=<memory:49152, vCores:96>
2013-08-06 12:58:39,717 INFO org.apache.hadoop.yarn.server.resourcemanager.scheduler.capacity.ParentQueue: completedContainer queue=root usedCapacity=0.9791667 absoluteUsedCapacity=0.9791667 used=<memory:48128, vCores:42> cluster=<memory:49152, vCores:96>
2013-08-06 12:58:39,717 INFO org.apache.hadoop.yarn.server.resourcemanager.scheduler.capacity.CapacityScheduler: Application appattempt_1375792971633_0006_000001 released container container_1375792971633_0006_01_000013 on node: host: hadoop-110-6:50003 #containers=6 available=1024 used=7168 with event: FINISHED
2013-08-06 12:58:39,718 INFO org.apache.hadoop.yarn.server.resourcemanager.rmcontainer.RMContainerImpl: container_1375792971633_0006_01_000038 Container Transitioned from NEW to ALLOCATED
2013-08-06 12:58:39,718 INFO org.apache.hadoop.yarn.server.resourcemanager.RMAuditLogger: USER=ubuntu	OPERATION=AM Allocated Container	TARGET=SchedulerApp	RESULT=SUCCESS	APPID=application_1375792971633_0006	CONTAINERID=container_1375792971633_0006_01_000038
2013-08-06 12:58:39,718 INFO org.apache.hadoop.yarn.server.resourcemanager.scheduler.common.fica.FiCaSchedulerNode: Assigned container container_1375792971633_0006_01_000038 of capacity <memory:1024, vCores:1> on host hadoop-110-6:50003, which currently has 7 containers, <memory:8192, vCores:7> used and <memory:0, vCores:9> available
2013-08-06 12:58:39,719 INFO org.apache.hadoop.yarn.server.resourcemanager.scheduler.capacity.LeafQueue: assignedContainer application=application_1375792971633_0006 container=Container: [ContainerId: container_1375792971633_0006_01_000038, NodeId: hadoop-110-6:50003, NodeHttpAddress: hadoop-110-6:8042, Resource: <memory:1024, vCores:1>, Priority: 20, State: NEW, Token: null, Status: container_id {, app_attempt_id {, application_id {, id: 6, cluster_timestamp: 1375792971633, }, attemptId: 1, }, id: 38, }, state: C_NEW, ] containerId=container_1375792971633_0006_01_000038 queue=default: capacity=1.0, absoluteCapacity=1.0, usedResources=<memory:48128, vCores:42>usedCapacity=0.9791667, absoluteUsedCapacity=0.9791667, numApps=5, numContainers=42 usedCapacity=0.9791667 absoluteUsedCapacity=0.9791667 used=<memory:48128, vCores:42> cluster=<memory:49152, vCores:96>
2013-08-06 12:58:39,719 INFO org.apache.hadoop.yarn.server.resourcemanager.scheduler.capacity.ParentQueue: Re-sorting queues since queue: root.default stats: default: capacity=1.0, absoluteCapacity=1.0, usedResources=<memory:49152, vCores:43>usedCapacity=1.0, absoluteUsedCapacity=1.0, numApps=5, numContainers=43
2013-08-06 12:58:39,719 INFO org.apache.hadoop.yarn.server.resourcemanager.scheduler.capacity.ParentQueue: assignedContainer queue=root usedCapacity=1.0 absoluteUsedCapacity=1.0 used=<memory:49152, vCores:43> cluster=<memory:49152, vCores:96>
2013-08-06 12:58:39,733 INFO org.apache.hadoop.yarn.server.resourcemanager.rmcontainer.RMContainerImpl: container_1375792971633_0006_01_000036 Container Transitioned from ACQUIRED to RUNNING
2013-08-06 12:58:39,733 INFO org.apache.hadoop.yarn.server.resourcemanager.rmcontainer.RMContainerImpl: container_1375792971633_0006_01_000037 Container Transitioned from ACQUIRED to RUNNING
2013-08-06 12:58:39,832 INFO org.apache.hadoop.yarn.server.resourcemanager.rmcontainer.RMContainerImpl: container_1375792971633_0006_01_000038 Container Transitioned from ALLOCATED to ACQUIRED
2013-08-06 12:58:39,910 INFO org.apache.hadoop.yarn.server.resourcemanager.rmcontainer.RMContainerImpl: container_1375792971633_0006_01_000007 Container Transitioned from RUNNING to COMPLETED
2013-08-06 12:58:39,910 INFO org.apache.hadoop.yarn.server.resourcemanager.scheduler.common.fica.FiCaSchedulerApp: Completed container: container_1375792971633_0006_01_000007 in state: COMPLETED event:FINISHED
2013-08-06 12:58:39,910 INFO org.apache.hadoop.yarn.server.resourcemanager.RMAuditLogger: USER=ubuntu	OPERATION=AM Released Container	TARGET=SchedulerApp	RESULT=SUCCESS	APPID=application_1375792971633_0006	CONTAINERID=container_1375792971633_0006_01_000007
2013-08-06 12:58:39,910 INFO org.apache.hadoop.yarn.server.resourcemanager.scheduler.common.fica.FiCaSchedulerNode: Released container container_1375792971633_0006_01_000007 of capacity <memory:1024, vCores:1> on host hadoop-110-5:54830, which currently has 7 containers, <memory:7168, vCores:7> used and <memory:1024, vCores:9> available, release resources=true
2013-08-06 12:58:39,910 INFO org.apache.hadoop.yarn.server.resourcemanager.scheduler.capacity.LeafQueue: default used=<memory:48128, vCores:42> numContainers=42 user=ubuntu user-resources=<memory:48128, vCores:42>
2013-08-06 12:58:39,911 INFO org.apache.hadoop.yarn.server.resourcemanager.scheduler.capacity.LeafQueue: completedContainer container=Container: [ContainerId: container_1375792971633_0006_01_000007, NodeId: hadoop-110-5:54830, NodeHttpAddress: hadoop-110-5:8042, Resource: <memory:1024, vCores:1>, Priority: 20, State: NEW, Token: null, Status: container_id {, app_attempt_id {, application_id {, id: 6, cluster_timestamp: 1375792971633, }, attemptId: 1, }, id: 7, }, state: C_COMPLETE, diagnostics: "Container killed by the ApplicationMaster.\n\n", exit_status: 143, ] resource=<memory:1024, vCores:1> queue=default: capacity=1.0, absoluteCapacity=1.0, usedResources=<memory:48128, vCores:42>usedCapacity=0.9791667, absoluteUsedCapacity=0.9791667, numApps=5, numContainers=42 usedCapacity=0.9791667 absoluteUsedCapacity=0.9791667 used=<memory:48128, vCores:42> cluster=<memory:49152, vCores:96>
2013-08-06 12:58:39,911 INFO org.apache.hadoop.yarn.server.resourcemanager.scheduler.capacity.ParentQueue: completedContainer queue=root usedCapacity=0.9791667 absoluteUsedCapacity=0.9791667 used=<memory:48128, vCores:42> cluster=<memory:49152, vCores:96>
2013-08-06 12:58:39,912 INFO org.apache.hadoop.yarn.server.resourcemanager.scheduler.capacity.CapacityScheduler: Application appattempt_1375792971633_0006_000001 released container container_1375792971633_0006_01_000007 on node: host: hadoop-110-5:54830 #containers=7 available=1024 used=7168 with event: FINISHED
2013-08-06 12:58:39,912 INFO org.apache.hadoop.yarn.server.resourcemanager.rmcontainer.RMContainerImpl: container_1375792971633_0006_01_000039 Container Transitioned from NEW to ALLOCATED
2013-08-06 12:58:39,912 INFO org.apache.hadoop.yarn.server.resourcemanager.RMAuditLogger: USER=ubuntu	OPERATION=AM Allocated Container	TARGET=SchedulerApp	RESULT=SUCCESS	APPID=application_1375792971633_0006	CONTAINERID=container_1375792971633_0006_01_000039
2013-08-06 12:58:39,912 INFO org.apache.hadoop.yarn.server.resourcemanager.scheduler.common.fica.FiCaSchedulerNode: Assigned container container_1375792971633_0006_01_000039 of capacity <memory:1024, vCores:1> on host hadoop-110-5:54830, which currently has 8 containers, <memory:8192, vCores:8> used and <memory:0, vCores:8> available
2013-08-06 12:58:39,913 INFO org.apache.hadoop.yarn.server.resourcemanager.scheduler.capacity.LeafQueue: assignedContainer application=application_1375792971633_0006 container=Container: [ContainerId: container_1375792971633_0006_01_000039, NodeId: hadoop-110-5:54830, NodeHttpAddress: hadoop-110-5:8042, Resource: <memory:1024, vCores:1>, Priority: 20, State: NEW, Token: null, Status: container_id {, app_attempt_id {, application_id {, id: 6, cluster_timestamp: 1375792971633, }, attemptId: 1, }, id: 39, }, state: C_NEW, ] containerId=container_1375792971633_0006_01_000039 queue=default: capacity=1.0, absoluteCapacity=1.0, usedResources=<memory:48128, vCores:42>usedCapacity=0.9791667, absoluteUsedCapacity=0.9791667, numApps=5, numContainers=42 usedCapacity=0.9791667 absoluteUsedCapacity=0.9791667 used=<memory:48128, vCores:42> cluster=<memory:49152, vCores:96>
2013-08-06 12:58:39,913 INFO org.apache.hadoop.yarn.server.resourcemanager.scheduler.capacity.ParentQueue: Re-sorting queues since queue: root.default stats: default: capacity=1.0, absoluteCapacity=1.0, usedResources=<memory:49152, vCores:43>usedCapacity=1.0, absoluteUsedCapacity=1.0, numApps=5, numContainers=43
2013-08-06 12:58:39,914 INFO org.apache.hadoop.yarn.server.resourcemanager.scheduler.capacity.ParentQueue: assignedContainer queue=root usedCapacity=1.0 absoluteUsedCapacity=1.0 used=<memory:49152, vCores:43> cluster=<memory:49152, vCores:96>
2013-08-06 12:58:40,592 INFO org.apache.hadoop.yarn.server.resourcemanager.rmcontainer.RMContainerImpl: container_1375792971633_0006_01_000017 Container Transitioned from RUNNING to COMPLETED
2013-08-06 12:58:40,592 INFO org.apache.hadoop.yarn.server.resourcemanager.scheduler.common.fica.FiCaSchedulerApp: Completed container: container_1375792971633_0006_01_000017 in state: COMPLETED event:FINISHED
2013-08-06 12:58:40,592 INFO org.apache.hadoop.yarn.server.resourcemanager.RMAuditLogger: USER=ubuntu	OPERATION=AM Released Container	TARGET=SchedulerApp	RESULT=SUCCESS	APPID=application_1375792971633_0006	CONTAINERID=container_1375792971633_0006_01_000017
2013-08-06 12:58:40,593 INFO org.apache.hadoop.yarn.server.resourcemanager.scheduler.common.fica.FiCaSchedulerNode: Released container container_1375792971633_0006_01_000017 of capacity <memory:1024, vCores:1> on host hadoop-110-2:50749, which currently has 7 containers, <memory:7168, vCores:7> used and <memory:1024, vCores:9> available, release resources=true
2013-08-06 12:58:40,593 INFO org.apache.hadoop.yarn.server.resourcemanager.scheduler.capacity.LeafQueue: default used=<memory:48128, vCores:42> numContainers=42 user=ubuntu user-resources=<memory:48128, vCores:42>
2013-08-06 12:58:40,594 INFO org.apache.hadoop.yarn.server.resourcemanager.scheduler.capacity.LeafQueue: completedContainer container=Container: [ContainerId: container_1375792971633_0006_01_000017, NodeId: hadoop-110-2:50749, NodeHttpAddress: hadoop-110-2:8042, Resource: <memory:1024, vCores:1>, Priority: 20, State: NEW, Token: null, Status: container_id {, app_attempt_id {, application_id {, id: 6, cluster_timestamp: 1375792971633, }, attemptId: 1, }, id: 17, }, state: C_COMPLETE, diagnostics: "Container killed by the ApplicationMaster.\n\n", exit_status: 143, ] resource=<memory:1024, vCores:1> queue=default: capacity=1.0, absoluteCapacity=1.0, usedResources=<memory:48128, vCores:42>usedCapacity=0.9791667, absoluteUsedCapacity=0.9791667, numApps=5, numContainers=42 usedCapacity=0.9791667 absoluteUsedCapacity=0.9791667 used=<memory:48128, vCores:42> cluster=<memory:49152, vCores:96>
2013-08-06 12:58:40,594 INFO org.apache.hadoop.yarn.server.resourcemanager.scheduler.capacity.ParentQueue: completedContainer queue=root usedCapacity=0.9791667 absoluteUsedCapacity=0.9791667 used=<memory:48128, vCores:42> cluster=<memory:49152, vCores:96>
2013-08-06 12:58:40,594 INFO org.apache.hadoop.yarn.server.resourcemanager.scheduler.capacity.CapacityScheduler: Application appattempt_1375792971633_0006_000001 released container container_1375792971633_0006_01_000017 on node: host: hadoop-110-2:50749 #containers=7 available=1024 used=7168 with event: FINISHED
2013-08-06 12:58:40,595 INFO org.apache.hadoop.yarn.server.resourcemanager.rmcontainer.RMContainerImpl: container_1375792971633_0006_01_000040 Container Transitioned from NEW to ALLOCATED
2013-08-06 12:58:40,595 INFO org.apache.hadoop.yarn.server.resourcemanager.RMAuditLogger: USER=ubuntu	OPERATION=AM Allocated Container	TARGET=SchedulerApp	RESULT=SUCCESS	APPID=application_1375792971633_0006	CONTAINERID=container_1375792971633_0006_01_000040
2013-08-06 12:58:40,595 INFO org.apache.hadoop.yarn.server.resourcemanager.scheduler.common.fica.FiCaSchedulerNode: Assigned container container_1375792971633_0006_01_000040 of capacity <memory:1024, vCores:1> on host hadoop-110-2:50749, which currently has 8 containers, <memory:8192, vCores:8> used and <memory:0, vCores:8> available
2013-08-06 12:58:40,596 INFO org.apache.hadoop.yarn.server.resourcemanager.scheduler.capacity.LeafQueue: assignedContainer application=application_1375792971633_0006 container=Container: [ContainerId: container_1375792971633_0006_01_000040, NodeId: hadoop-110-2:50749, NodeHttpAddress: hadoop-110-2:8042, Resource: <memory:1024, vCores:1>, Priority: 20, State: NEW, Token: null, Status: container_id {, app_attempt_id {, application_id {, id: 6, cluster_timestamp: 1375792971633, }, attemptId: 1, }, id: 40, }, state: C_NEW, ] containerId=container_1375792971633_0006_01_000040 queue=default: capacity=1.0, absoluteCapacity=1.0, usedResources=<memory:48128, vCores:42>usedCapacity=0.9791667, absoluteUsedCapacity=0.9791667, numApps=5, numContainers=42 usedCapacity=0.9791667 absoluteUsedCapacity=0.9791667 used=<memory:48128, vCores:42> cluster=<memory:49152, vCores:96>
2013-08-06 12:58:40,596 INFO org.apache.hadoop.yarn.server.resourcemanager.scheduler.capacity.ParentQueue: Re-sorting queues since queue: root.default stats: default: capacity=1.0, absoluteCapacity=1.0, usedResources=<memory:49152, vCores:43>usedCapacity=1.0, absoluteUsedCapacity=1.0, numApps=5, numContainers=43
2013-08-06 12:58:40,596 INFO org.apache.hadoop.yarn.server.resourcemanager.scheduler.capacity.ParentQueue: assignedContainer queue=root usedCapacity=1.0 absoluteUsedCapacity=1.0 used=<memory:49152, vCores:43> cluster=<memory:49152, vCores:96>
2013-08-06 12:58:40,721 INFO org.apache.hadoop.yarn.server.resourcemanager.rmcontainer.RMContainerImpl: container_1375792971633_0006_01_000038 Container Transitioned from ACQUIRED to RUNNING
2013-08-06 12:58:40,840 INFO org.apache.hadoop.yarn.server.resourcemanager.rmcontainer.RMContainerImpl: container_1375792971633_0006_01_000039 Container Transitioned from ALLOCATED to ACQUIRED
2013-08-06 12:58:40,841 INFO org.apache.hadoop.yarn.server.resourcemanager.rmcontainer.RMContainerImpl: container_1375792971633_0006_01_000040 Container Transitioned from ALLOCATED to ACQUIRED
2013-08-06 12:58:40,967 INFO org.apache.hadoop.yarn.server.resourcemanager.rmcontainer.RMContainerImpl: container_1375792971633_0006_01_000039 Container Transitioned from ACQUIRED to RUNNING
2013-08-06 12:58:40,991 INFO org.apache.hadoop.yarn.server.resourcemanager.rmcontainer.RMContainerImpl: container_1375792971633_0006_01_000040 Container Transitioned from ACQUIRED to RUNNING
2013-08-06 12:58:40,991 INFO org.apache.hadoop.yarn.server.resourcemanager.rmcontainer.RMContainerImpl: container_1375792971633_0006_01_000022 Container Transitioned from RUNNING to COMPLETED
2013-08-06 12:58:40,991 INFO org.apache.hadoop.yarn.server.resourcemanager.scheduler.common.fica.FiCaSchedulerApp: Completed container: container_1375792971633_0006_01_000022 in state: COMPLETED event:FINISHED
2013-08-06 12:58:40,991 INFO org.apache.hadoop.yarn.server.resourcemanager.RMAuditLogger: USER=ubuntu	OPERATION=AM Released Container	TARGET=SchedulerApp	RESULT=SUCCESS	APPID=application_1375792971633_0006	CONTAINERID=container_1375792971633_0006_01_000022
2013-08-06 12:58:40,991 INFO org.apache.hadoop.yarn.server.resourcemanager.scheduler.common.fica.FiCaSchedulerNode: Released container container_1375792971633_0006_01_000022 of capacity <memory:1024, vCores:1> on host hadoop-110-2:50749, which currently has 7 containers, <memory:7168, vCores:7> used and <memory:1024, vCores:9> available, release resources=true
2013-08-06 12:58:40,991 INFO org.apache.hadoop.yarn.server.resourcemanager.scheduler.capacity.LeafQueue: default used=<memory:48128, vCores:42> numContainers=42 user=ubuntu user-resources=<memory:48128, vCores:42>
2013-08-06 12:58:40,992 INFO org.apache.hadoop.yarn.server.resourcemanager.scheduler.capacity.LeafQueue: completedContainer container=Container: [ContainerId: container_1375792971633_0006_01_000022, NodeId: hadoop-110-2:50749, NodeHttpAddress: hadoop-110-2:8042, Resource: <memory:1024, vCores:1>, Priority: 20, State: NEW, Token: null, Status: container_id {, app_attempt_id {, application_id {, id: 6, cluster_timestamp: 1375792971633, }, attemptId: 1, }, id: 22, }, state: C_COMPLETE, diagnostics: "", exit_status: 0, ] resource=<memory:1024, vCores:1> queue=default: capacity=1.0, absoluteCapacity=1.0, usedResources=<memory:48128, vCores:42>usedCapacity=0.9791667, absoluteUsedCapacity=0.9791667, numApps=5, numContainers=42 usedCapacity=0.9791667 absoluteUsedCapacity=0.9791667 used=<memory:48128, vCores:42> cluster=<memory:49152, vCores:96>
2013-08-06 12:58:40,993 INFO org.apache.hadoop.yarn.server.resourcemanager.scheduler.capacity.ParentQueue: completedContainer queue=root usedCapacity=0.9791667 absoluteUsedCapacity=0.9791667 used=<memory:48128, vCores:42> cluster=<memory:49152, vCores:96>
2013-08-06 12:58:40,993 INFO org.apache.hadoop.yarn.server.resourcemanager.scheduler.capacity.CapacityScheduler: Application appattempt_1375792971633_0006_000001 released container container_1375792971633_0006_01_000022 on node: host: hadoop-110-2:50749 #containers=7 available=1024 used=7168 with event: FINISHED
2013-08-06 12:58:40,993 INFO org.apache.hadoop.yarn.server.resourcemanager.rmcontainer.RMContainerImpl: container_1375792971633_0006_01_000041 Container Transitioned from NEW to ALLOCATED
2013-08-06 12:58:40,993 INFO org.apache.hadoop.yarn.server.resourcemanager.RMAuditLogger: USER=ubuntu	OPERATION=AM Allocated Container	TARGET=SchedulerApp	RESULT=SUCCESS	APPID=application_1375792971633_0006	CONTAINERID=container_1375792971633_0006_01_000041
2013-08-06 12:58:40,994 INFO org.apache.hadoop.yarn.server.resourcemanager.scheduler.common.fica.FiCaSchedulerNode: Assigned container container_1375792971633_0006_01_000041 of capacity <memory:1024, vCores:1> on host hadoop-110-2:50749, which currently has 8 containers, <memory:8192, vCores:8> used and <memory:0, vCores:8> available
2013-08-06 12:58:40,994 INFO org.apache.hadoop.yarn.server.resourcemanager.scheduler.capacity.LeafQueue: assignedContainer application=application_1375792971633_0006 container=Container: [ContainerId: container_1375792971633_0006_01_000041, NodeId: hadoop-110-2:50749, NodeHttpAddress: hadoop-110-2:8042, Resource: <memory:1024, vCores:1>, Priority: 20, State: NEW, Token: null, Status: container_id {, app_attempt_id {, application_id {, id: 6, cluster_timestamp: 1375792971633, }, attemptId: 1, }, id: 41, }, state: C_NEW, ] containerId=container_1375792971633_0006_01_000041 queue=default: capacity=1.0, absoluteCapacity=1.0, usedResources=<memory:48128, vCores:42>usedCapacity=0.9791667, absoluteUsedCapacity=0.9791667, numApps=5, numContainers=42 usedCapacity=0.9791667 absoluteUsedCapacity=0.9791667 used=<memory:48128, vCores:42> cluster=<memory:49152, vCores:96>
2013-08-06 12:58:40,995 INFO org.apache.hadoop.yarn.server.resourcemanager.scheduler.capacity.ParentQueue: Re-sorting queues since queue: root.default stats: default: capacity=1.0, absoluteCapacity=1.0, usedResources=<memory:49152, vCores:43>usedCapacity=1.0, absoluteUsedCapacity=1.0, numApps=5, numContainers=43
2013-08-06 12:58:40,995 INFO org.apache.hadoop.yarn.server.resourcemanager.scheduler.capacity.ParentQueue: assignedContainer queue=root usedCapacity=1.0 absoluteUsedCapacity=1.0 used=<memory:49152, vCores:43> cluster=<memory:49152, vCores:96>
2013-08-06 12:58:41,084 INFO org.apache.hadoop.yarn.server.resourcemanager.rmcontainer.RMContainerImpl: container_1375792971633_0008_01_000017 Container Transitioned from RUNNING to COMPLETED
2013-08-06 12:58:41,084 INFO org.apache.hadoop.yarn.server.resourcemanager.scheduler.common.fica.FiCaSchedulerApp: Completed container: container_1375792971633_0008_01_000017 in state: COMPLETED event:FINISHED
2013-08-06 12:58:41,084 INFO org.apache.hadoop.yarn.server.resourcemanager.RMAuditLogger: USER=ubuntu	OPERATION=AM Released Container	TARGET=SchedulerApp	RESULT=SUCCESS	APPID=application_1375792971633_0008	CONTAINERID=container_1375792971633_0008_01_000017
2013-08-06 12:58:41,084 INFO org.apache.hadoop.yarn.server.resourcemanager.scheduler.common.fica.FiCaSchedulerNode: Released container container_1375792971633_0008_01_000017 of capacity <memory:1024, vCores:1> on host hadoop-110-7:55372, which currently has 6 containers, <memory:7168, vCores:6> used and <memory:1024, vCores:10> available, release resources=true
2013-08-06 12:58:41,084 INFO org.apache.hadoop.yarn.server.resourcemanager.scheduler.capacity.LeafQueue: default used=<memory:48128, vCores:42> numContainers=42 user=ubuntu user-resources=<memory:48128, vCores:42>
2013-08-06 12:58:41,085 INFO org.apache.hadoop.yarn.server.resourcemanager.scheduler.capacity.LeafQueue: completedContainer container=Container: [ContainerId: container_1375792971633_0008_01_000017, NodeId: hadoop-110-7:55372, NodeHttpAddress: hadoop-110-7:8042, Resource: <memory:1024, vCores:1>, Priority: 20, State: NEW, Token: null, Status: container_id {, app_attempt_id {, application_id {, id: 8, cluster_timestamp: 1375792971633, }, attemptId: 1, }, id: 17, }, state: C_COMPLETE, diagnostics: "Container killed by the ApplicationMaster.\n\n", exit_status: 143, ] resource=<memory:1024, vCores:1> queue=default: capacity=1.0, absoluteCapacity=1.0, usedResources=<memory:48128, vCores:42>usedCapacity=0.9791667, absoluteUsedCapacity=0.9791667, numApps=5, numContainers=42 usedCapacity=0.9791667 absoluteUsedCapacity=0.9791667 used=<memory:48128, vCores:42> cluster=<memory:49152, vCores:96>
2013-08-06 12:58:41,086 INFO org.apache.hadoop.yarn.server.resourcemanager.scheduler.capacity.ParentQueue: completedContainer queue=root usedCapacity=0.9791667 absoluteUsedCapacity=0.9791667 used=<memory:48128, vCores:42> cluster=<memory:49152, vCores:96>
2013-08-06 12:58:41,086 INFO org.apache.hadoop.yarn.server.resourcemanager.scheduler.capacity.CapacityScheduler: Application appattempt_1375792971633_0008_000001 released container container_1375792971633_0008_01_000017 on node: host: hadoop-110-7:55372 #containers=6 available=1024 used=7168 with event: FINISHED
2013-08-06 12:58:41,086 INFO org.apache.hadoop.yarn.server.resourcemanager.rmcontainer.RMContainerImpl: container_1375792971633_0006_01_000042 Container Transitioned from NEW to ALLOCATED
2013-08-06 12:58:41,086 INFO org.apache.hadoop.yarn.server.resourcemanager.RMAuditLogger: USER=ubuntu	OPERATION=AM Allocated Container	TARGET=SchedulerApp	RESULT=SUCCESS	APPID=application_1375792971633_0006	CONTAINERID=container_1375792971633_0006_01_000042
2013-08-06 12:58:41,086 INFO org.apache.hadoop.yarn.server.resourcemanager.scheduler.common.fica.FiCaSchedulerNode: Assigned container container_1375792971633_0006_01_000042 of capacity <memory:1024, vCores:1> on host hadoop-110-7:55372, which currently has 7 containers, <memory:8192, vCores:7> used and <memory:0, vCores:9> available
2013-08-06 12:58:41,087 INFO org.apache.hadoop.yarn.server.resourcemanager.scheduler.capacity.LeafQueue: assignedContainer application=application_1375792971633_0006 container=Container: [ContainerId: container_1375792971633_0006_01_000042, NodeId: hadoop-110-7:55372, NodeHttpAddress: hadoop-110-7:8042, Resource: <memory:1024, vCores:1>, Priority: 20, State: NEW, Token: null, Status: container_id {, app_attempt_id {, application_id {, id: 6, cluster_timestamp: 1375792971633, }, attemptId: 1, }, id: 42, }, state: C_NEW, ] containerId=container_1375792971633_0006_01_000042 queue=default: capacity=1.0, absoluteCapacity=1.0, usedResources=<memory:48128, vCores:42>usedCapacity=0.9791667, absoluteUsedCapacity=0.9791667, numApps=5, numContainers=42 usedCapacity=0.9791667 absoluteUsedCapacity=0.9791667 used=<memory:48128, vCores:42> cluster=<memory:49152, vCores:96>
2013-08-06 12:58:41,088 INFO org.apache.hadoop.yarn.server.resourcemanager.scheduler.capacity.ParentQueue: Re-sorting queues since queue: root.default stats: default: capacity=1.0, absoluteCapacity=1.0, usedResources=<memory:49152, vCores:43>usedCapacity=1.0, absoluteUsedCapacity=1.0, numApps=5, numContainers=43
2013-08-06 12:58:41,088 INFO org.apache.hadoop.yarn.server.resourcemanager.scheduler.capacity.ParentQueue: assignedContainer queue=root usedCapacity=1.0 absoluteUsedCapacity=1.0 used=<memory:49152, vCores:43> cluster=<memory:49152, vCores:96>
2013-08-06 12:58:41,848 INFO org.apache.hadoop.yarn.server.resourcemanager.rmcontainer.RMContainerImpl: container_1375792971633_0006_01_000041 Container Transitioned from ALLOCATED to ACQUIRED
2013-08-06 12:58:41,849 INFO org.apache.hadoop.yarn.server.resourcemanager.rmcontainer.RMContainerImpl: container_1375792971633_0006_01_000042 Container Transitioned from ALLOCATED to ACQUIRED
2013-08-06 12:58:42,004 INFO org.apache.hadoop.yarn.server.resourcemanager.rmcontainer.RMContainerImpl: container_1375792971633_0006_01_000041 Container Transitioned from ACQUIRED to RUNNING
2013-08-06 12:58:42,005 INFO org.apache.hadoop.yarn.server.resourcemanager.rmcontainer.RMContainerImpl: container_1375792971633_0006_01_000021 Container Transitioned from RUNNING to COMPLETED
2013-08-06 12:58:42,005 INFO org.apache.hadoop.yarn.server.resourcemanager.scheduler.common.fica.FiCaSchedulerApp: Completed container: container_1375792971633_0006_01_000021 in state: COMPLETED event:FINISHED
2013-08-06 12:58:42,005 INFO org.apache.hadoop.yarn.server.resourcemanager.RMAuditLogger: USER=ubuntu	OPERATION=AM Released Container	TARGET=SchedulerApp	RESULT=SUCCESS	APPID=application_1375792971633_0006	CONTAINERID=container_1375792971633_0006_01_000021
2013-08-06 12:58:42,005 INFO org.apache.hadoop.yarn.server.resourcemanager.scheduler.common.fica.FiCaSchedulerNode: Released container container_1375792971633_0006_01_000021 of capacity <memory:1024, vCores:1> on host hadoop-110-2:50749, which currently has 7 containers, <memory:7168, vCores:7> used and <memory:1024, vCores:9> available, release resources=true
2013-08-06 12:58:42,005 INFO org.apache.hadoop.yarn.server.resourcemanager.scheduler.capacity.LeafQueue: default used=<memory:48128, vCores:42> numContainers=42 user=ubuntu user-resources=<memory:48128, vCores:42>
2013-08-06 12:58:42,006 INFO org.apache.hadoop.yarn.server.resourcemanager.scheduler.capacity.LeafQueue: completedContainer container=Container: [ContainerId: container_1375792971633_0006_01_000021, NodeId: hadoop-110-2:50749, NodeHttpAddress: hadoop-110-2:8042, Resource: <memory:1024, vCores:1>, Priority: 20, State: NEW, Token: null, Status: container_id {, app_attempt_id {, application_id {, id: 6, cluster_timestamp: 1375792971633, }, attemptId: 1, }, id: 21, }, state: C_COMPLETE, diagnostics: "Container killed by the ApplicationMaster.\n\n", exit_status: 143, ] resource=<memory:1024, vCores:1> queue=default: capacity=1.0, absoluteCapacity=1.0, usedResources=<memory:48128, vCores:42>usedCapacity=0.9791667, absoluteUsedCapacity=0.9791667, numApps=5, numContainers=42 usedCapacity=0.9791667 absoluteUsedCapacity=0.9791667 used=<memory:48128, vCores:42> cluster=<memory:49152, vCores:96>
2013-08-06 12:58:42,006 INFO org.apache.hadoop.yarn.server.resourcemanager.scheduler.capacity.ParentQueue: completedContainer queue=root usedCapacity=0.9791667 absoluteUsedCapacity=0.9791667 used=<memory:48128, vCores:42> cluster=<memory:49152, vCores:96>
2013-08-06 12:58:42,007 INFO org.apache.hadoop.yarn.server.resourcemanager.scheduler.capacity.CapacityScheduler: Application appattempt_1375792971633_0006_000001 released container container_1375792971633_0006_01_000021 on node: host: hadoop-110-2:50749 #containers=7 available=1024 used=7168 with event: FINISHED
2013-08-06 12:58:42,007 INFO org.apache.hadoop.yarn.server.resourcemanager.rmcontainer.RMContainerImpl: container_1375792971633_0006_01_000043 Container Transitioned from NEW to ALLOCATED
2013-08-06 12:58:42,007 INFO org.apache.hadoop.yarn.server.resourcemanager.RMAuditLogger: USER=ubuntu	OPERATION=AM Allocated Container	TARGET=SchedulerApp	RESULT=SUCCESS	APPID=application_1375792971633_0006	CONTAINERID=container_1375792971633_0006_01_000043
2013-08-06 12:58:42,007 INFO org.apache.hadoop.yarn.server.resourcemanager.scheduler.common.fica.FiCaSchedulerNode: Assigned container container_1375792971633_0006_01_000043 of capacity <memory:1024, vCores:1> on host hadoop-110-2:50749, which currently has 8 containers, <memory:8192, vCores:8> used and <memory:0, vCores:8> available
2013-08-06 12:58:42,008 INFO org.apache.hadoop.yarn.server.resourcemanager.scheduler.capacity.LeafQueue: assignedContainer application=application_1375792971633_0006 container=Container: [ContainerId: container_1375792971633_0006_01_000043, NodeId: hadoop-110-2:50749, NodeHttpAddress: hadoop-110-2:8042, Resource: <memory:1024, vCores:1>, Priority: 20, State: NEW, Token: null, Status: container_id {, app_attempt_id {, application_id {, id: 6, cluster_timestamp: 1375792971633, }, attemptId: 1, }, id: 43, }, state: C_NEW, ] containerId=container_1375792971633_0006_01_000043 queue=default: capacity=1.0, absoluteCapacity=1.0, usedResources=<memory:48128, vCores:42>usedCapacity=0.9791667, absoluteUsedCapacity=0.9791667, numApps=5, numContainers=42 usedCapacity=0.9791667 absoluteUsedCapacity=0.9791667 used=<memory:48128, vCores:42> cluster=<memory:49152, vCores:96>
2013-08-06 12:58:42,008 INFO org.apache.hadoop.yarn.server.resourcemanager.scheduler.capacity.ParentQueue: Re-sorting queues since queue: root.default stats: default: capacity=1.0, absoluteCapacity=1.0, usedResources=<memory:49152, vCores:43>usedCapacity=1.0, absoluteUsedCapacity=1.0, numApps=5, numContainers=43
2013-08-06 12:58:42,009 INFO org.apache.hadoop.yarn.server.resourcemanager.scheduler.capacity.ParentQueue: assignedContainer queue=root usedCapacity=1.0 absoluteUsedCapacity=1.0 used=<memory:49152, vCores:43> cluster=<memory:49152, vCores:96>
2013-08-06 12:58:42,092 INFO org.apache.hadoop.yarn.server.resourcemanager.rmcontainer.RMContainerImpl: container_1375792971633_0006_01_000042 Container Transitioned from ACQUIRED to RUNNING
2013-08-06 12:58:42,383 INFO org.apache.hadoop.yarn.server.resourcemanager.rmcontainer.RMContainerImpl: container_1375792971633_0006_01_000014 Container Transitioned from RUNNING to COMPLETED
2013-08-06 12:58:42,383 INFO org.apache.hadoop.yarn.server.resourcemanager.scheduler.common.fica.FiCaSchedulerApp: Completed container: container_1375792971633_0006_01_000014 in state: COMPLETED event:FINISHED
2013-08-06 12:58:42,383 INFO org.apache.hadoop.yarn.server.resourcemanager.RMAuditLogger: USER=ubuntu	OPERATION=AM Released Container	TARGET=SchedulerApp	RESULT=SUCCESS	APPID=application_1375792971633_0006	CONTAINERID=container_1375792971633_0006_01_000014
2013-08-06 12:58:42,383 INFO org.apache.hadoop.yarn.server.resourcemanager.scheduler.common.fica.FiCaSchedulerNode: Released container container_1375792971633_0006_01_000014 of capacity <memory:1024, vCores:1> on host hadoop-110-6:50003, which currently has 6 containers, <memory:7168, vCores:6> used and <memory:1024, vCores:10> available, release resources=true
2013-08-06 12:58:42,384 INFO org.apache.hadoop.yarn.server.resourcemanager.scheduler.capacity.LeafQueue: default used=<memory:48128, vCores:42> numContainers=42 user=ubuntu user-resources=<memory:48128, vCores:42>
2013-08-06 12:58:42,385 INFO org.apache.hadoop.yarn.server.resourcemanager.scheduler.capacity.LeafQueue: completedContainer container=Container: [ContainerId: container_1375792971633_0006_01_000014, NodeId: hadoop-110-6:50003, NodeHttpAddress: hadoop-110-6:8042, Resource: <memory:1024, vCores:1>, Priority: 20, State: NEW, Token: null, Status: container_id {, app_attempt_id {, application_id {, id: 6, cluster_timestamp: 1375792971633, }, attemptId: 1, }, id: 14, }, state: C_COMPLETE, diagnostics: "Container killed by the ApplicationMaster.\n\n", exit_status: 143, ] resource=<memory:1024, vCores:1> queue=default: capacity=1.0, absoluteCapacity=1.0, usedResources=<memory:48128, vCores:42>usedCapacity=0.9791667, absoluteUsedCapacity=0.9791667, numApps=5, numContainers=42 usedCapacity=0.9791667 absoluteUsedCapacity=0.9791667 used=<memory:48128, vCores:42> cluster=<memory:49152, vCores:96>
2013-08-06 12:58:42,385 INFO org.apache.hadoop.yarn.server.resourcemanager.scheduler.capacity.ParentQueue: completedContainer queue=root usedCapacity=0.9791667 absoluteUsedCapacity=0.9791667 used=<memory:48128, vCores:42> cluster=<memory:49152, vCores:96>
2013-08-06 12:58:42,385 INFO org.apache.hadoop.yarn.server.resourcemanager.scheduler.capacity.CapacityScheduler: Application appattempt_1375792971633_0006_000001 released container container_1375792971633_0006_01_000014 on node: host: hadoop-110-6:50003 #containers=6 available=1024 used=7168 with event: FINISHED
2013-08-06 12:58:42,386 INFO org.apache.hadoop.yarn.server.resourcemanager.rmcontainer.RMContainerImpl: container_1375792971633_0006_01_000044 Container Transitioned from NEW to ALLOCATED
2013-08-06 12:58:42,386 INFO org.apache.hadoop.yarn.server.resourcemanager.RMAuditLogger: USER=ubuntu	OPERATION=AM Allocated Container	TARGET=SchedulerApp	RESULT=SUCCESS	APPID=application_1375792971633_0006	CONTAINERID=container_1375792971633_0006_01_000044
2013-08-06 12:58:42,386 INFO org.apache.hadoop.yarn.server.resourcemanager.scheduler.common.fica.FiCaSchedulerNode: Assigned container container_1375792971633_0006_01_000044 of capacity <memory:1024, vCores:1> on host hadoop-110-6:50003, which currently has 7 containers, <memory:8192, vCores:7> used and <memory:0, vCores:9> available
