2013-08-17 06:29:57,918 INFO org.apache.hadoop.yarn.server.resourcemanager.ResourceManager: STARTUP_MSG: 
/************************************************************
STARTUP_MSG: Starting ResourceManager
STARTUP_MSG:   host = hadoop-512-1/192.168.100.5
STARTUP_MSG:   args = []
STARTUP_MSG:   version = 3.0.0-SNAPSHOT
STARTUP_MSG:   build = https://github.com/lalithsuresh/hadoop-common -r 0cb423bd4868928bb06cd93f882bb0913172fd17; compiled by 'lsuresh' on 2013-04-08T15:47Z
STARTUP_MSG:   java = 1.7.0_17
************************************************************/
2013-08-17 06:29:57,932 INFO org.apache.hadoop.yarn.server.resourcemanager.ResourceManager: registered UNIX signal handlers for [TERM, HUP, INT]
2013-08-17 06:29:58,672 INFO org.apache.hadoop.yarn.server.resourcemanager.security.ApplicationTokenSecretManager: Rolling master-key for application-tokens
2013-08-17 06:29:58,718 INFO org.apache.hadoop.yarn.server.resourcemanager.security.RMContainerTokenSecretManager: ContainerTokenKeyRollingInterval: 86400000ms and ContainerTokenKeyActivationDelay: 900000ms
2013-08-17 06:29:58,723 INFO org.apache.hadoop.yarn.service.AbstractService: Service:Dispatcher is inited.
2013-08-17 06:29:58,726 INFO org.apache.hadoop.yarn.event.AsyncDispatcher: Registering class org.apache.hadoop.yarn.server.resourcemanager.recovery.RMStateStoreEventType for class org.apache.hadoop.yarn.server.resourcemanager.recovery.RMStateStore$ForwardingEventHandler
2013-08-17 06:29:58,726 INFO org.apache.hadoop.yarn.service.AbstractService: Service:Dispatcher is started.
2013-08-17 06:29:58,737 INFO org.apache.hadoop.yarn.event.AsyncDispatcher: Registering class org.apache.hadoop.yarn.server.resourcemanager.NodesListManagerEventType for class org.apache.hadoop.yarn.server.resourcemanager.NodesListManager
2013-08-17 06:29:58,737 INFO org.apache.hadoop.yarn.server.resourcemanager.ResourceManager: Using Scheduler: org.apache.hadoop.yarn.server.resourcemanager.scheduler.capacity.CapacityScheduler
2013-08-17 06:29:59,027 INFO org.apache.hadoop.yarn.event.AsyncDispatcher: Registering class org.apache.hadoop.yarn.server.resourcemanager.scheduler.event.SchedulerEventType for class org.apache.hadoop.yarn.server.resourcemanager.ResourceManager$SchedulerEventDispatcher
2013-08-17 06:29:59,030 INFO org.apache.hadoop.yarn.event.AsyncDispatcher: Registering class org.apache.hadoop.yarn.server.resourcemanager.rmapp.RMAppEventType for class org.apache.hadoop.yarn.server.resourcemanager.ResourceManager$ApplicationEventDispatcher
2013-08-17 06:29:59,033 INFO org.apache.hadoop.yarn.event.AsyncDispatcher: Registering class org.apache.hadoop.yarn.server.resourcemanager.rmapp.attempt.RMAppAttemptEventType for class org.apache.hadoop.yarn.server.resourcemanager.ResourceManager$ApplicationAttemptEventDispatcher
2013-08-17 06:29:59,036 INFO org.apache.hadoop.yarn.event.AsyncDispatcher: Registering class org.apache.hadoop.yarn.server.resourcemanager.rmnode.RMNodeEventType for class org.apache.hadoop.yarn.server.resourcemanager.ResourceManager$NodeEventDispatcher
2013-08-17 06:29:59,788 WARN org.apache.hadoop.util.NativeCodeLoader: Unable to load native-hadoop library for your platform... using builtin-java classes where applicable
2013-08-17 06:29:59,825 INFO org.apache.hadoop.yarn.server.resourcemanager.scheduler.capacity.ParentQueue: root, capacity=1.0, asboluteCapacity=1.0, maxCapacity=1.0, asboluteMaxCapacity=1.0, state=RUNNING, acls=SUBMIT_APPLICATIONS:*ADMINISTER_QUEUE:*
2013-08-17 06:29:59,825 INFO org.apache.hadoop.yarn.server.resourcemanager.scheduler.capacity.ParentQueue: Initialized parent-queue root name=root, fullname=root
2013-08-17 06:29:59,843 INFO org.apache.hadoop.yarn.server.resourcemanager.scheduler.capacity.LeafQueue: Initializing default
capacity = 1.0 [= (float) configuredCapacity / 100 ]
asboluteCapacity = 1.0 [= parentAbsoluteCapacity * capacity ]
maxCapacity = 1.0 [= configuredMaxCapacity ]
absoluteMaxCapacity = 1.0 [= 1.0 maximumCapacity undefined, (parentAbsoluteMaxCapacity * maximumCapacity) / 100 otherwise ]
userLimit = 100 [= configuredUserLimit ]
userLimitFactor = 1.0 [= configuredUserLimitFactor ]
maxApplications = 10000 [= configuredMaximumSystemApplicationsPerQueue or (int)(configuredMaximumSystemApplications * absoluteCapacity)]
maxApplicationsPerUser = 10000 [= (int)(maxApplications * (userLimit / 100.0f) * userLimitFactor) ]
maxActiveApplications = 1 [= max((int)ceil((clusterResourceMemory / minimumAllocation) * maxAMResourcePerQueuePercent * absoluteMaxCapacity),1) ]
maxActiveAppsUsingAbsCap = 1 [= max((int)ceil((clusterResourceMemory / minimumAllocation) *maxAMResourcePercent * absoluteCapacity),1) ]
maxActiveApplicationsPerUser = 1 [= max((int)(maxActiveApplications * (userLimit / 100.0f) * userLimitFactor),1) ]
usedCapacity = 0.0 [= usedResourcesMemory / (clusterResourceMemory * absoluteCapacity)]
absoluteUsedCapacity = 0.0 [= usedResourcesMemory / clusterResourceMemory]
maxAMResourcePerQueuePercent = 0.1 [= configuredMaximumAMResourcePercent ]
minimumAllocationFactor = 0.875 [= (float)(maximumAllocationMemory - minimumAllocationMemory) / maximumAllocationMemory ]
numContainers = 0 [= currentNumContainers ]
state = RUNNING [= configuredState ]
acls = SUBMIT_APPLICATIONS:*ADMINISTER_QUEUE:* [= configuredAcls ]

2013-08-17 06:29:59,844 INFO org.apache.hadoop.yarn.server.resourcemanager.scheduler.capacity.CapacityScheduler: Initialized queue: default: capacity=1.0, absoluteCapacity=1.0, usedResources=<memory:0, vCores:0>usedCapacity=0.0, absoluteUsedCapacity=0.0, numApps=0, numContainers=0
2013-08-17 06:29:59,844 INFO org.apache.hadoop.yarn.server.resourcemanager.scheduler.capacity.CapacityScheduler: Initialized queue: root: numChildQueue= 1, capacity=1.0, absoluteCapacity=1.0, usedResources=<memory:0, vCores:0>usedCapacity=0.0, numApps=0, numContainers=0
2013-08-17 06:29:59,844 INFO org.apache.hadoop.yarn.server.resourcemanager.scheduler.capacity.CapacityScheduler: Initialized root queue root: numChildQueue= 1, capacity=1.0, absoluteCapacity=1.0, usedResources=<memory:0, vCores:0>usedCapacity=0.0, numApps=0, numContainers=0
2013-08-17 06:29:59,844 INFO org.apache.hadoop.yarn.server.resourcemanager.scheduler.capacity.CapacityScheduler: Initialized CapacityScheduler with calculator=class org.apache.hadoop.yarn.server.resourcemanager.resource.DefaultResourceCalculator, minimumAllocation=<<memory:1024, vCores:1>>, maximumAllocation=<<memory:8192, vCores:32>>
2013-08-17 06:30:00,225 INFO org.apache.hadoop.yarn.event.AsyncDispatcher: Registering class org.apache.hadoop.yarn.server.resourcemanager.RMAppManagerEventType for class org.apache.hadoop.yarn.server.resourcemanager.RMAppManager
2013-08-17 06:30:00,249 INFO org.apache.hadoop.yarn.event.AsyncDispatcher: Registering class org.apache.hadoop.yarn.server.resourcemanager.amlauncher.AMLauncherEventType for class org.apache.hadoop.yarn.server.resourcemanager.amlauncher.ApplicationMasterLauncher
2013-08-17 06:30:00,358 INFO org.apache.hadoop.yarn.server.resourcemanager.RMNMInfo: Registered RMNMInfo MBean
2013-08-17 06:30:00,358 INFO org.apache.hadoop.yarn.service.AbstractService: Service:Dispatcher is inited.
2013-08-17 06:30:00,358 INFO org.apache.hadoop.yarn.service.AbstractService: Service:org.apache.hadoop.yarn.server.resourcemanager.rmcontainer.ContainerAllocationExpirer is inited.
2013-08-17 06:30:00,359 INFO org.apache.hadoop.yarn.service.AbstractService: Service:AMLivelinessMonitor is inited.
2013-08-17 06:30:00,359 INFO org.apache.hadoop.yarn.service.AbstractService: Service:AMLivelinessMonitor is inited.
2013-08-17 06:30:00,359 INFO org.apache.hadoop.yarn.service.AbstractService: Service:org.apache.hadoop.yarn.server.resourcemanager.security.DelegationTokenRenewer is inited.
2013-08-17 06:30:00,361 INFO org.apache.hadoop.util.HostsFileReader: Refreshing hosts (include/exclude) list
2013-08-17 06:30:00,361 INFO org.apache.hadoop.yarn.service.AbstractService: Service:org.apache.hadoop.yarn.server.resourcemanager.NodesListManager is inited.
2013-08-17 06:30:00,361 INFO org.apache.hadoop.yarn.service.AbstractService: Service:org.apache.hadoop.yarn.server.resourcemanager.ResourceManager$SchedulerEventDispatcher is inited.
2013-08-17 06:30:00,361 INFO org.apache.hadoop.yarn.service.AbstractService: Service:NMLivelinessMonitor is inited.
2013-08-17 06:30:00,370 INFO org.apache.hadoop.yarn.service.AbstractService: Service:org.apache.hadoop.yarn.server.resourcemanager.ResourceTrackerService is inited.
2013-08-17 06:30:00,370 INFO org.apache.hadoop.yarn.service.AbstractService: Service:org.apache.hadoop.yarn.server.resourcemanager.ApplicationMasterService is inited.
2013-08-17 06:30:00,371 INFO org.apache.hadoop.yarn.service.AbstractService: Service:org.apache.hadoop.yarn.server.resourcemanager.ClientRMService is inited.
2013-08-17 06:30:00,371 INFO org.apache.hadoop.yarn.service.AbstractService: Service:org.apache.hadoop.yarn.server.resourcemanager.AdminService is inited.
2013-08-17 06:30:00,371 INFO org.apache.hadoop.yarn.service.AbstractService: Service:org.apache.hadoop.yarn.server.resourcemanager.amlauncher.ApplicationMasterLauncher is inited.
2013-08-17 06:30:00,371 INFO org.apache.hadoop.yarn.service.AbstractService: Service:ResourceManager is inited.
2013-08-17 06:30:00,372 INFO org.apache.hadoop.yarn.server.resourcemanager.security.ApplicationTokenSecretManager: Rolling master-key for application-tokens
2013-08-17 06:30:00,372 INFO org.apache.hadoop.yarn.server.resourcemanager.security.RMContainerTokenSecretManager: Rolling master-key for container-tokens
2013-08-17 06:30:00,540 INFO org.mortbay.log: Logging to org.slf4j.impl.Log4jLoggerAdapter(org.mortbay.log) via org.mortbay.log.Slf4jLog
2013-08-17 06:30:00,644 INFO org.apache.hadoop.http.HttpServer: Added global filter 'safety' (class=org.apache.hadoop.http.HttpServer$QuotingInputFilter)
2013-08-17 06:30:00,649 INFO org.apache.hadoop.http.HttpServer: Added filter static_user_filter (class=org.apache.hadoop.http.lib.StaticUserWebFilter$StaticUserFilter) to context cluster
2013-08-17 06:30:00,649 INFO org.apache.hadoop.http.HttpServer: Added filter static_user_filter (class=org.apache.hadoop.http.lib.StaticUserWebFilter$StaticUserFilter) to context static
2013-08-17 06:30:00,649 INFO org.apache.hadoop.http.HttpServer: Added filter static_user_filter (class=org.apache.hadoop.http.lib.StaticUserWebFilter$StaticUserFilter) to context logs
2013-08-17 06:30:00,657 INFO org.apache.hadoop.http.HttpServer: adding path spec: /cluster
2013-08-17 06:30:00,657 INFO org.apache.hadoop.http.HttpServer: adding path spec: /cluster/*
2013-08-17 06:30:00,657 INFO org.apache.hadoop.http.HttpServer: adding path spec: /ws
2013-08-17 06:30:00,657 INFO org.apache.hadoop.http.HttpServer: adding path spec: /ws/*
2013-08-17 06:30:00,660 INFO org.apache.hadoop.http.HttpServer: Added global filter 'guice' (class=com.google.inject.servlet.GuiceFilter)
2013-08-17 06:30:00,670 INFO org.apache.hadoop.http.HttpServer: Jetty bound to port 8088
2013-08-17 06:30:00,670 INFO org.mortbay.log: jetty-6.1.26
2013-08-17 06:30:00,725 INFO org.mortbay.log: Extract jar:file:/home/ubuntu/hadoop-3.0.0-SNAPSHOT/share/hadoop/yarn/hadoop-yarn-common-3.0.0-SNAPSHOT.jar!/webapps/cluster to /tmp/Jetty_0_0_0_0_8088_cluster____u0rgz3/webapp
2013-08-17 06:30:01,161 INFO org.mortbay.log: Started SelectChannelConnector@0.0.0.0:8088
2013-08-17 06:30:01,161 INFO org.apache.hadoop.yarn.webapp.WebApps: Web app /cluster started at 8088
2013-08-17 06:30:01,998 INFO org.apache.hadoop.yarn.webapp.WebApps: Registered webapp guice modules
2013-08-17 06:30:02,118 INFO org.apache.hadoop.metrics2.impl.MetricsConfig: loaded properties from hadoop-metrics2.properties
2013-08-17 06:30:02,155 INFO org.apache.hadoop.metrics2.impl.MetricsSystemImpl: Scheduled snapshot period at 10 second(s).
2013-08-17 06:30:02,155 INFO org.apache.hadoop.metrics2.impl.MetricsSystemImpl: ResourceManager metrics system started
2013-08-17 06:30:02,172 INFO org.apache.hadoop.security.token.delegation.AbstractDelegationTokenSecretManager: Updating the current master key for generating delegation tokens
2013-08-17 06:30:02,176 INFO org.apache.hadoop.yarn.service.AbstractService: Service:Dispatcher is started.
2013-08-17 06:30:02,176 INFO org.apache.hadoop.security.token.delegation.AbstractDelegationTokenSecretManager: Starting expired delegation token remover thread, tokenRemoverScanInterval=60 min(s)
2013-08-17 06:30:02,177 INFO org.apache.hadoop.security.token.delegation.AbstractDelegationTokenSecretManager: Updating the current master key for generating delegation tokens
2013-08-17 06:30:02,178 INFO org.apache.hadoop.yarn.service.AbstractService: Service:org.apache.hadoop.yarn.server.resourcemanager.rmcontainer.ContainerAllocationExpirer is started.
2013-08-17 06:30:02,179 INFO org.apache.hadoop.yarn.service.AbstractService: Service:AMLivelinessMonitor is started.
2013-08-17 06:30:02,180 INFO org.apache.hadoop.yarn.service.AbstractService: Service:AMLivelinessMonitor is started.
2013-08-17 06:30:02,180 INFO org.apache.hadoop.yarn.service.AbstractService: Service:org.apache.hadoop.yarn.server.resourcemanager.security.DelegationTokenRenewer is started.
2013-08-17 06:30:02,181 INFO org.apache.hadoop.yarn.service.AbstractService: Service:org.apache.hadoop.yarn.server.resourcemanager.NodesListManager is started.
2013-08-17 06:30:02,182 INFO org.apache.hadoop.yarn.service.AbstractService: Service:org.apache.hadoop.yarn.server.resourcemanager.ResourceManager$SchedulerEventDispatcher is started.
2013-08-17 06:30:02,182 INFO org.apache.hadoop.yarn.service.AbstractService: Service:NMLivelinessMonitor is started.
2013-08-17 06:30:02,182 INFO org.apache.hadoop.yarn.service.AbstractService: Service:org.apache.hadoop.yarn.server.resourcemanager.ResourceTrackerService is started.
2013-08-17 06:30:02,246 INFO org.apache.hadoop.ipc.Server: Starting Socket Reader #1 for port 54110
2013-08-17 06:30:02,270 INFO org.apache.hadoop.yarn.factories.impl.pb.RpcServerFactoryPBImpl: Adding protocol org.apache.hadoop.yarn.server.api.ResourceTrackerPB to the server
2013-08-17 06:30:02,271 INFO org.apache.hadoop.ipc.Server: IPC Server Responder: starting
2013-08-17 06:30:02,279 INFO org.apache.hadoop.ipc.Server: IPC Server listener on 54110: starting
2013-08-17 06:30:02,389 INFO org.apache.hadoop.ipc.Server: Starting Socket Reader #1 for port 54112
2013-08-17 06:30:02,396 INFO org.apache.hadoop.yarn.factories.impl.pb.RpcServerFactoryPBImpl: Adding protocol org.apache.hadoop.yarn.api.AMRMProtocolPB to the server
2013-08-17 06:30:02,397 INFO org.apache.hadoop.ipc.Server: IPC Server Responder: starting
2013-08-17 06:30:02,404 INFO org.apache.hadoop.ipc.Server: IPC Server listener on 54112: starting
2013-08-17 06:30:02,423 INFO org.apache.hadoop.yarn.service.AbstractService: Service:org.apache.hadoop.yarn.server.resourcemanager.ApplicationMasterService is started.
2013-08-17 06:30:02,452 INFO org.apache.hadoop.ipc.Server: Starting Socket Reader #1 for port 54111
2013-08-17 06:30:02,455 INFO org.apache.hadoop.yarn.factories.impl.pb.RpcServerFactoryPBImpl: Adding protocol org.apache.hadoop.yarn.api.ClientRMProtocolPB to the server
2013-08-17 06:30:02,456 INFO org.apache.hadoop.ipc.Server: IPC Server Responder: starting
2013-08-17 06:30:02,457 INFO org.apache.hadoop.ipc.Server: IPC Server listener on 54111: starting
2013-08-17 06:30:02,500 INFO org.apache.hadoop.yarn.service.AbstractService: Service:org.apache.hadoop.yarn.server.resourcemanager.ClientRMService is started.
2013-08-17 06:30:02,519 INFO org.apache.hadoop.ipc.Server: Starting Socket Reader #1 for port 8033
2013-08-17 06:30:02,525 INFO org.apache.hadoop.yarn.factories.impl.pb.RpcServerFactoryPBImpl: Adding protocol org.apache.hadoop.yarn.api.RMAdminProtocolPB to the server
2013-08-17 06:30:02,526 INFO org.apache.hadoop.ipc.Server: IPC Server Responder: starting
2013-08-17 06:30:02,527 INFO org.apache.hadoop.ipc.Server: IPC Server listener on 8033: starting
2013-08-17 06:30:02,528 INFO org.apache.hadoop.yarn.service.AbstractService: Service:org.apache.hadoop.yarn.server.resourcemanager.AdminService is started.
2013-08-17 06:30:02,531 INFO org.apache.hadoop.yarn.service.AbstractService: Service:org.apache.hadoop.yarn.server.resourcemanager.amlauncher.ApplicationMasterLauncher is started.
2013-08-17 06:30:02,531 INFO org.apache.hadoop.yarn.service.AbstractService: Service:ResourceManager is started.
2013-08-17 06:30:12,506 INFO org.apache.hadoop.yarn.util.RackResolver: Resolved hadoop-512-4 to /default-rack
2013-08-17 06:30:12,508 INFO org.apache.hadoop.yarn.util.RackResolver: Resolved hadoop-512-6 to /default-rack
2013-08-17 06:30:12,508 INFO org.apache.hadoop.yarn.util.RackResolver: Resolved hadoop-512-5 to /default-rack
2013-08-17 06:30:12,508 INFO org.apache.hadoop.yarn.util.RackResolver: Resolved hadoop-512-2 to /default-rack
2013-08-17 06:30:12,508 INFO org.apache.hadoop.yarn.util.RackResolver: Resolved hadoop-512-7 to /default-rack
2013-08-17 06:30:12,509 INFO org.apache.hadoop.yarn.util.RackResolver: Resolved hadoop-512-3 to /default-rack
2013-08-17 06:30:12,521 INFO org.apache.hadoop.yarn.server.resourcemanager.ResourceTrackerService: NodeManager from node hadoop-512-6(cmPort: 48301 httpPort: 8042) registered with capability: <memory:8192, vCores:16>, assigned nodeId hadoop-512-6:48301
2013-08-17 06:30:12,521 INFO org.apache.hadoop.yarn.server.resourcemanager.ResourceTrackerService: NodeManager from node hadoop-512-5(cmPort: 45082 httpPort: 8042) registered with capability: <memory:8192, vCores:16>, assigned nodeId hadoop-512-5:45082
2013-08-17 06:30:12,521 INFO org.apache.hadoop.yarn.server.resourcemanager.ResourceTrackerService: NodeManager from node hadoop-512-2(cmPort: 32923 httpPort: 8042) registered with capability: <memory:8192, vCores:16>, assigned nodeId hadoop-512-2:32923
2013-08-17 06:30:12,521 INFO org.apache.hadoop.yarn.server.resourcemanager.ResourceTrackerService: NodeManager from node hadoop-512-7(cmPort: 43914 httpPort: 8042) registered with capability: <memory:8192, vCores:16>, assigned nodeId hadoop-512-7:43914
2013-08-17 06:30:12,522 INFO org.apache.hadoop.yarn.server.resourcemanager.ResourceTrackerService: NodeManager from node hadoop-512-4(cmPort: 45085 httpPort: 8042) registered with capability: <memory:8192, vCores:16>, assigned nodeId hadoop-512-4:45085
2013-08-17 06:30:12,528 INFO org.apache.hadoop.yarn.server.resourcemanager.ResourceTrackerService: NodeManager from node hadoop-512-3(cmPort: 56071 httpPort: 8042) registered with capability: <memory:8192, vCores:16>, assigned nodeId hadoop-512-3:56071
2013-08-17 06:30:12,540 INFO org.apache.hadoop.yarn.server.resourcemanager.rmnode.RMNodeImpl: hadoop-512-6:48301 Node Transitioned from NEW to RUNNING
2013-08-17 06:30:12,540 INFO org.apache.hadoop.yarn.server.resourcemanager.rmnode.RMNodeImpl: hadoop-512-5:45082 Node Transitioned from NEW to RUNNING
2013-08-17 06:30:12,540 INFO org.apache.hadoop.yarn.server.resourcemanager.rmnode.RMNodeImpl: hadoop-512-2:32923 Node Transitioned from NEW to RUNNING
2013-08-17 06:30:12,541 INFO org.apache.hadoop.yarn.server.resourcemanager.rmnode.RMNodeImpl: hadoop-512-7:43914 Node Transitioned from NEW to RUNNING
2013-08-17 06:30:12,541 INFO org.apache.hadoop.yarn.server.resourcemanager.rmnode.RMNodeImpl: hadoop-512-4:45085 Node Transitioned from NEW to RUNNING
2013-08-17 06:30:12,541 INFO org.apache.hadoop.yarn.server.resourcemanager.rmnode.RMNodeImpl: hadoop-512-3:56071 Node Transitioned from NEW to RUNNING
2013-08-17 06:30:12,545 INFO org.apache.hadoop.yarn.server.resourcemanager.scheduler.capacity.CapacityScheduler: Added node hadoop-512-6:48301 clusterResource: <memory:8192, vCores:16>
2013-08-17 06:30:12,546 INFO org.apache.hadoop.yarn.server.resourcemanager.scheduler.capacity.CapacityScheduler: Added node hadoop-512-5:45082 clusterResource: <memory:16384, vCores:32>
2013-08-17 06:30:12,546 INFO org.apache.hadoop.yarn.server.resourcemanager.scheduler.capacity.CapacityScheduler: Added node hadoop-512-2:32923 clusterResource: <memory:24576, vCores:48>
2013-08-17 06:30:12,546 INFO org.apache.hadoop.yarn.server.resourcemanager.scheduler.capacity.CapacityScheduler: Added node hadoop-512-7:43914 clusterResource: <memory:32768, vCores:64>
2013-08-17 06:30:12,547 INFO org.apache.hadoop.yarn.server.resourcemanager.scheduler.capacity.CapacityScheduler: Added node hadoop-512-4:45085 clusterResource: <memory:40960, vCores:80>
2013-08-17 06:30:12,547 INFO org.apache.hadoop.yarn.server.resourcemanager.scheduler.capacity.CapacityScheduler: Added node hadoop-512-3:56071 clusterResource: <memory:49152, vCores:96>
2013-08-17 06:30:18,701 INFO org.apache.hadoop.yarn.server.resourcemanager.ClientRMService: Allocated new applicationId: 1
2013-08-17 06:30:22,117 INFO org.apache.hadoop.yarn.server.resourcemanager.ClientRMService: Storing Application with id application_1376720997863_0001
2013-08-17 06:30:22,120 INFO org.apache.hadoop.yarn.server.resourcemanager.recovery.RMStateStore: Storing info for app: application_1376720997863_0001
2013-08-17 06:30:22,120 INFO org.apache.hadoop.yarn.server.resourcemanager.ClientRMService: Application with id 1 submitted by user ubuntu
2013-08-17 06:30:22,124 INFO org.apache.hadoop.yarn.server.resourcemanager.RMAuditLogger: USER=ubuntu	IP=192.168.100.5	OPERATION=Submit Application Request	TARGET=ClientRMService	RESULT=SUCCESS	APPID=application_1376720997863_0001
2013-08-17 06:30:22,168 INFO org.apache.hadoop.yarn.server.resourcemanager.rmapp.RMAppImpl: application_1376720997863_0001 State change from NEW to SUBMITTED
2013-08-17 06:30:22,171 INFO org.apache.hadoop.yarn.server.resourcemanager.ApplicationMasterService: Registering appattempt_1376720997863_0001_000001
2013-08-17 06:30:22,173 INFO org.apache.hadoop.yarn.server.resourcemanager.rmapp.attempt.RMAppAttemptImpl: appattempt_1376720997863_0001_000001 State change from NEW to SUBMITTED
2013-08-17 06:30:22,212 INFO org.apache.hadoop.yarn.server.resourcemanager.scheduler.capacity.LeafQueue: Application application_1376720997863_0001 from user: ubuntu activated in queue: default
2013-08-17 06:30:22,212 INFO org.apache.hadoop.yarn.server.resourcemanager.scheduler.capacity.LeafQueue: Application added - appId: application_1376720997863_0001 user: org.apache.hadoop.yarn.server.resourcemanager.scheduler.capacity.LeafQueue$User@53d4287, leaf-queue: default #user-pending-applications: 0 #user-active-applications: 1 #queue-pending-applications: 0 #queue-active-applications: 1
2013-08-17 06:30:22,212 INFO org.apache.hadoop.yarn.server.resourcemanager.scheduler.capacity.ParentQueue: Application added - appId: application_1376720997863_0001 user: ubuntu leaf-queue of parent: root #applications: 1
2013-08-17 06:30:22,213 INFO org.apache.hadoop.yarn.server.resourcemanager.scheduler.capacity.CapacityScheduler: Application Submission: appattempt_1376720997863_0001_000001, user: ubuntu queue: default: capacity=1.0, absoluteCapacity=1.0, usedResources=<memory:0, vCores:0>usedCapacity=0.0, absoluteUsedCapacity=0.0, numApps=1, numContainers=0, currently active: 1
2013-08-17 06:30:22,219 INFO org.apache.hadoop.yarn.server.resourcemanager.rmapp.attempt.RMAppAttemptImpl: appattempt_1376720997863_0001_000001 State change from SUBMITTED to SCHEDULED
2013-08-17 06:30:22,219 INFO org.apache.hadoop.yarn.server.resourcemanager.rmapp.RMAppImpl: application_1376720997863_0001 State change from SUBMITTED to ACCEPTED
2013-08-17 06:30:22,726 INFO org.apache.hadoop.yarn.server.resourcemanager.rmcontainer.RMContainerImpl: container_1376720997863_0001_01_000001 Container Transitioned from NEW to ALLOCATED
2013-08-17 06:30:22,726 INFO org.apache.hadoop.yarn.server.resourcemanager.RMAuditLogger: USER=ubuntu	OPERATION=AM Allocated Container	TARGET=SchedulerApp	RESULT=SUCCESS	APPID=application_1376720997863_0001	CONTAINERID=container_1376720997863_0001_01_000001
2013-08-17 06:30:22,727 INFO org.apache.hadoop.yarn.server.resourcemanager.scheduler.common.fica.FiCaSchedulerNode: Assigned container container_1376720997863_0001_01_000001 of capacity <memory:2048, vCores:1> on host hadoop-512-6:48301, which currently has 1 containers, <memory:2048, vCores:1> used and <memory:6144, vCores:15> available
2013-08-17 06:30:22,733 INFO org.apache.hadoop.yarn.server.resourcemanager.scheduler.capacity.LeafQueue: assignedContainer application=application_1376720997863_0001 container=Container: [ContainerId: container_1376720997863_0001_01_000001, NodeId: hadoop-512-6:48301, NodeHttpAddress: hadoop-512-6:8042, Resource: <memory:2048, vCores:1>, Priority: 0, State: NEW, Token: null, Status: container_id {, app_attempt_id {, application_id {, id: 1, cluster_timestamp: 1376720997863, }, attemptId: 1, }, id: 1, }, state: C_NEW, ] containerId=container_1376720997863_0001_01_000001 queue=default: capacity=1.0, absoluteCapacity=1.0, usedResources=<memory:0, vCores:0>usedCapacity=0.0, absoluteUsedCapacity=0.0, numApps=1, numContainers=0 usedCapacity=0.0 absoluteUsedCapacity=0.0 used=<memory:0, vCores:0> cluster=<memory:49152, vCores:96>
2013-08-17 06:30:22,735 INFO org.apache.hadoop.yarn.server.resourcemanager.rmcontainer.RMContainerImpl: container_1376720997863_0001_01_000001 Container Transitioned from ALLOCATED to ACQUIRED
2013-08-17 06:30:22,738 INFO org.apache.hadoop.yarn.server.resourcemanager.rmapp.attempt.RMAppAttemptImpl: Storing attempt: AppId: application_1376720997863_0001 AttemptId: appattempt_1376720997863_0001_000001 MasterContainer: Container: [ContainerId: container_1376720997863_0001_01_000001, NodeId: hadoop-512-6:48301, NodeHttpAddress: hadoop-512-6:8042, Resource: <memory:2048, vCores:1>, Priority: 0, State: NEW, Token: null, Status: container_id {, app_attempt_id {, application_id {, id: 1, cluster_timestamp: 1376720997863, }, attemptId: 1, }, id: 1, }, state: C_NEW, ]
2013-08-17 06:30:22,738 INFO org.apache.hadoop.yarn.server.resourcemanager.scheduler.capacity.ParentQueue: Re-sorting queues since queue: root.default stats: default: capacity=1.0, absoluteCapacity=1.0, usedResources=<memory:2048, vCores:1>usedCapacity=0.041666668, absoluteUsedCapacity=0.041666668, numApps=1, numContainers=1
2013-08-17 06:30:22,739 INFO org.apache.hadoop.yarn.server.resourcemanager.scheduler.capacity.ParentQueue: assignedContainer queue=root usedCapacity=0.041666668 absoluteUsedCapacity=0.041666668 used=<memory:2048, vCores:1> cluster=<memory:49152, vCores:96>
2013-08-17 06:30:22,742 INFO org.apache.hadoop.yarn.server.resourcemanager.rmapp.attempt.RMAppAttemptImpl: appattempt_1376720997863_0001_000001 State change from SCHEDULED to ALLOCATED_SAVING
2013-08-17 06:30:22,745 INFO org.apache.hadoop.yarn.server.resourcemanager.recovery.RMStateStore: Storing info for attempt: appattempt_1376720997863_0001_000001
2013-08-17 06:30:22,748 INFO org.apache.hadoop.yarn.server.resourcemanager.rmapp.attempt.RMAppAttemptImpl: appattempt_1376720997863_0001_000001 State change from ALLOCATED_SAVING to ALLOCATED
2013-08-17 06:30:22,755 INFO org.apache.hadoop.yarn.server.resourcemanager.amlauncher.AMLauncher: Launching masterappattempt_1376720997863_0001_000001
2013-08-17 06:30:22,798 INFO org.apache.hadoop.yarn.server.resourcemanager.amlauncher.AMLauncher: Setting up container Container: [ContainerId: container_1376720997863_0001_01_000001, NodeId: hadoop-512-6:48301, NodeHttpAddress: hadoop-512-6:8042, Resource: <memory:2048, vCores:1>, Priority: 0, State: NEW, Token: null, Status: container_id {, app_attempt_id {, application_id {, id: 1, cluster_timestamp: 1376720997863, }, attemptId: 1, }, id: 1, }, state: C_NEW, ] for AM appattempt_1376720997863_0001_000001
2013-08-17 06:30:22,799 INFO org.apache.hadoop.yarn.server.resourcemanager.amlauncher.AMLauncher: Command to launch container container_1376720997863_0001_01_000001 : $JAVA_HOME/bin/java -Dlog4j.configuration=container-log4j.properties -Dyarn.app.mapreduce.container.log.dir=<LOG_DIR> -Dyarn.app.mapreduce.container.log.filesize=0 -Dhadoop.root.logger=INFO,CLA  -Xmx1024m org.apache.hadoop.mapreduce.v2.app.MRAppMaster 1><LOG_DIR>/stdout 2><LOG_DIR>/stderr 
2013-08-17 06:30:23,723 INFO org.apache.hadoop.yarn.server.resourcemanager.amlauncher.AMLauncher: Done launching container Container: [ContainerId: container_1376720997863_0001_01_000001, NodeId: hadoop-512-6:48301, NodeHttpAddress: hadoop-512-6:8042, Resource: <memory:2048, vCores:1>, Priority: 0, State: NEW, Token: null, Status: container_id {, app_attempt_id {, application_id {, id: 1, cluster_timestamp: 1376720997863, }, attemptId: 1, }, id: 1, }, state: C_NEW, ] for AM appattempt_1376720997863_0001_000001
2013-08-17 06:30:23,724 INFO org.apache.hadoop.yarn.server.resourcemanager.rmapp.attempt.RMAppAttemptImpl: appattempt_1376720997863_0001_000001 State change from ALLOCATED to LAUNCHED
2013-08-17 06:30:23,727 INFO org.apache.hadoop.yarn.server.resourcemanager.rmcontainer.RMContainerImpl: container_1376720997863_0001_01_000001 Container Transitioned from ACQUIRED to RUNNING
2013-08-17 06:30:32,653 INFO org.apache.hadoop.yarn.server.resourcemanager.ApplicationMasterService: AM registration appattempt_1376720997863_0001_000001
2013-08-17 06:30:32,659 INFO org.apache.hadoop.yarn.server.resourcemanager.RMAuditLogger: USER=ubuntu	IP=192.168.100.31	OPERATION=Register App Master	TARGET=ApplicationMasterService	RESULT=SUCCESS	APPID=application_1376720997863_0001	APPATTEMPTID=appattempt_1376720997863_0001_000001
2013-08-17 06:30:32,673 INFO org.apache.hadoop.yarn.server.resourcemanager.rmapp.attempt.RMAppAttemptImpl: appattempt_1376720997863_0001_000001 State change from LAUNCHED to RUNNING
2013-08-17 06:30:32,673 INFO org.apache.hadoop.yarn.server.resourcemanager.rmapp.RMAppImpl: application_1376720997863_0001 State change from ACCEPTED to RUNNING
2013-08-17 06:30:33,741 INFO org.apache.hadoop.yarn.server.resourcemanager.rmcontainer.RMContainerImpl: container_1376720997863_0001_01_000002 Container Transitioned from NEW to ALLOCATED
2013-08-17 06:30:33,741 INFO org.apache.hadoop.yarn.server.resourcemanager.RMAuditLogger: USER=ubuntu	OPERATION=AM Allocated Container	TARGET=SchedulerApp	RESULT=SUCCESS	APPID=application_1376720997863_0001	CONTAINERID=container_1376720997863_0001_01_000002
2013-08-17 06:30:33,741 INFO org.apache.hadoop.yarn.server.resourcemanager.scheduler.common.fica.FiCaSchedulerNode: Assigned container container_1376720997863_0001_01_000002 of capacity <memory:1024, vCores:1> on host hadoop-512-3:56071, which currently has 1 containers, <memory:1024, vCores:1> used and <memory:7168, vCores:15> available
2013-08-17 06:30:33,744 INFO org.apache.hadoop.yarn.server.resourcemanager.scheduler.capacity.LeafQueue: assignedContainer application=application_1376720997863_0001 container=Container: [ContainerId: container_1376720997863_0001_01_000002, NodeId: hadoop-512-3:56071, NodeHttpAddress: hadoop-512-3:8042, Resource: <memory:1024, vCores:1>, Priority: 20, State: NEW, Token: null, Status: container_id {, app_attempt_id {, application_id {, id: 1, cluster_timestamp: 1376720997863, }, attemptId: 1, }, id: 2, }, state: C_NEW, ] containerId=container_1376720997863_0001_01_000002 queue=default: capacity=1.0, absoluteCapacity=1.0, usedResources=<memory:2048, vCores:1>usedCapacity=0.041666668, absoluteUsedCapacity=0.041666668, numApps=1, numContainers=1 usedCapacity=0.041666668 absoluteUsedCapacity=0.041666668 used=<memory:2048, vCores:1> cluster=<memory:49152, vCores:96>
2013-08-17 06:30:33,744 INFO org.apache.hadoop.yarn.server.resourcemanager.scheduler.capacity.ParentQueue: Re-sorting queues since queue: root.default stats: default: capacity=1.0, absoluteCapacity=1.0, usedResources=<memory:3072, vCores:2>usedCapacity=0.0625, absoluteUsedCapacity=0.0625, numApps=1, numContainers=2
2013-08-17 06:30:33,744 INFO org.apache.hadoop.yarn.server.resourcemanager.scheduler.capacity.ParentQueue: assignedContainer queue=root usedCapacity=0.0625 absoluteUsedCapacity=0.0625 used=<memory:3072, vCores:2> cluster=<memory:49152, vCores:96>
2013-08-17 06:30:33,745 INFO org.apache.hadoop.yarn.server.resourcemanager.rmcontainer.RMContainerImpl: container_1376720997863_0001_01_000003 Container Transitioned from NEW to ALLOCATED
2013-08-17 06:30:33,746 INFO org.apache.hadoop.yarn.server.resourcemanager.RMAuditLogger: USER=ubuntu	OPERATION=AM Allocated Container	TARGET=SchedulerApp	RESULT=SUCCESS	APPID=application_1376720997863_0001	CONTAINERID=container_1376720997863_0001_01_000003
2013-08-17 06:30:33,746 INFO org.apache.hadoop.yarn.server.resourcemanager.scheduler.common.fica.FiCaSchedulerNode: Assigned container container_1376720997863_0001_01_000003 of capacity <memory:1024, vCores:1> on host hadoop-512-4:45085, which currently has 1 containers, <memory:1024, vCores:1> used and <memory:7168, vCores:15> available
2013-08-17 06:30:33,748 INFO org.apache.hadoop.yarn.server.resourcemanager.scheduler.capacity.LeafQueue: assignedContainer application=application_1376720997863_0001 container=Container: [ContainerId: container_1376720997863_0001_01_000003, NodeId: hadoop-512-4:45085, NodeHttpAddress: hadoop-512-4:8042, Resource: <memory:1024, vCores:1>, Priority: 20, State: NEW, Token: null, Status: container_id {, app_attempt_id {, application_id {, id: 1, cluster_timestamp: 1376720997863, }, attemptId: 1, }, id: 3, }, state: C_NEW, ] containerId=container_1376720997863_0001_01_000003 queue=default: capacity=1.0, absoluteCapacity=1.0, usedResources=<memory:3072, vCores:2>usedCapacity=0.0625, absoluteUsedCapacity=0.0625, numApps=1, numContainers=2 usedCapacity=0.0625 absoluteUsedCapacity=0.0625 used=<memory:3072, vCores:2> cluster=<memory:49152, vCores:96>
2013-08-17 06:30:33,749 INFO org.apache.hadoop.yarn.server.resourcemanager.scheduler.capacity.ParentQueue: Re-sorting queues since queue: root.default stats: default: capacity=1.0, absoluteCapacity=1.0, usedResources=<memory:4096, vCores:3>usedCapacity=0.083333336, absoluteUsedCapacity=0.083333336, numApps=1, numContainers=3
2013-08-17 06:30:33,749 INFO org.apache.hadoop.yarn.server.resourcemanager.scheduler.capacity.ParentQueue: assignedContainer queue=root usedCapacity=0.083333336 absoluteUsedCapacity=0.083333336 used=<memory:4096, vCores:3> cluster=<memory:49152, vCores:96>
2013-08-17 06:30:34,756 INFO org.apache.hadoop.yarn.server.resourcemanager.rmcontainer.RMContainerImpl: container_1376720997863_0001_01_000002 Container Transitioned from ALLOCATED to ACQUIRED
2013-08-17 06:30:34,758 INFO org.apache.hadoop.yarn.server.resourcemanager.rmcontainer.RMContainerImpl: container_1376720997863_0001_01_000003 Container Transitioned from ALLOCATED to ACQUIRED
2013-08-17 06:30:35,788 INFO org.apache.hadoop.yarn.server.resourcemanager.scheduler.AppSchedulingInfo: checking for deactivate... 
2013-08-17 06:30:36,770 INFO org.apache.hadoop.yarn.server.resourcemanager.rmcontainer.RMContainerImpl: container_1376720997863_0001_01_000002 Container Transitioned from ACQUIRED to RUNNING
2013-08-17 06:30:36,777 INFO org.apache.hadoop.yarn.server.resourcemanager.rmcontainer.RMContainerImpl: container_1376720997863_0001_01_000003 Container Transitioned from ACQUIRED to RUNNING
2013-08-17 06:32:18,338 INFO org.apache.hadoop.yarn.server.resourcemanager.rmcontainer.RMContainerImpl: container_1376720997863_0001_01_000003 Container Transitioned from RUNNING to COMPLETED
2013-08-17 06:32:18,338 INFO org.apache.hadoop.yarn.server.resourcemanager.scheduler.common.fica.FiCaSchedulerApp: Completed container: container_1376720997863_0001_01_000003 in state: COMPLETED event:FINISHED
2013-08-17 06:32:18,338 INFO org.apache.hadoop.yarn.server.resourcemanager.RMAuditLogger: USER=ubuntu	OPERATION=AM Released Container	TARGET=SchedulerApp	RESULT=SUCCESS	APPID=application_1376720997863_0001	CONTAINERID=container_1376720997863_0001_01_000003
2013-08-17 06:32:18,339 INFO org.apache.hadoop.yarn.server.resourcemanager.scheduler.common.fica.FiCaSchedulerNode: Released container container_1376720997863_0001_01_000003 of capacity <memory:1024, vCores:1> on host hadoop-512-4:45085, which currently has 0 containers, <memory:0, vCores:0> used and <memory:8192, vCores:16> available, release resources=true
2013-08-17 06:32:18,339 INFO org.apache.hadoop.yarn.server.resourcemanager.scheduler.capacity.LeafQueue: default used=<memory:3072, vCores:2> numContainers=2 user=ubuntu user-resources=<memory:3072, vCores:2>
2013-08-17 06:32:18,341 INFO org.apache.hadoop.yarn.server.resourcemanager.scheduler.capacity.LeafQueue: completedContainer container=Container: [ContainerId: container_1376720997863_0001_01_000003, NodeId: hadoop-512-4:45085, NodeHttpAddress: hadoop-512-4:8042, Resource: <memory:1024, vCores:1>, Priority: 20, State: NEW, Token: null, Status: container_id {, app_attempt_id {, application_id {, id: 1, cluster_timestamp: 1376720997863, }, attemptId: 1, }, id: 3, }, state: C_COMPLETE, diagnostics: "Container killed by the ApplicationMaster.\n\n", exit_status: 143, ] resource=<memory:1024, vCores:1> queue=default: capacity=1.0, absoluteCapacity=1.0, usedResources=<memory:3072, vCores:2>usedCapacity=0.0625, absoluteUsedCapacity=0.0625, numApps=1, numContainers=2 usedCapacity=0.0625 absoluteUsedCapacity=0.0625 used=<memory:3072, vCores:2> cluster=<memory:49152, vCores:96>
2013-08-17 06:32:18,341 INFO org.apache.hadoop.yarn.server.resourcemanager.scheduler.capacity.ParentQueue: completedContainer queue=root usedCapacity=0.0625 absoluteUsedCapacity=0.0625 used=<memory:3072, vCores:2> cluster=<memory:49152, vCores:96>
2013-08-17 06:32:18,342 INFO org.apache.hadoop.yarn.server.resourcemanager.scheduler.capacity.CapacityScheduler: Application appattempt_1376720997863_0001_000001 released container container_1376720997863_0001_01_000003 on node: host: hadoop-512-4:45085 #containers=0 available=8192 used=0 with event: FINISHED
2013-08-17 06:32:18,859 INFO org.apache.hadoop.yarn.server.resourcemanager.rmcontainer.RMContainerImpl: container_1376720997863_0001_01_000002 Container Transitioned from RUNNING to COMPLETED
2013-08-17 06:32:18,860 INFO org.apache.hadoop.yarn.server.resourcemanager.scheduler.common.fica.FiCaSchedulerApp: Completed container: container_1376720997863_0001_01_000002 in state: COMPLETED event:FINISHED
2013-08-17 06:32:18,860 INFO org.apache.hadoop.yarn.server.resourcemanager.RMAuditLogger: USER=ubuntu	OPERATION=AM Released Container	TARGET=SchedulerApp	RESULT=SUCCESS	APPID=application_1376720997863_0001	CONTAINERID=container_1376720997863_0001_01_000002
2013-08-17 06:32:18,860 INFO org.apache.hadoop.yarn.server.resourcemanager.scheduler.common.fica.FiCaSchedulerNode: Released container container_1376720997863_0001_01_000002 of capacity <memory:1024, vCores:1> on host hadoop-512-3:56071, which currently has 0 containers, <memory:0, vCores:0> used and <memory:8192, vCores:16> available, release resources=true
2013-08-17 06:32:18,860 INFO org.apache.hadoop.yarn.server.resourcemanager.scheduler.capacity.LeafQueue: default used=<memory:2048, vCores:1> numContainers=1 user=ubuntu user-resources=<memory:2048, vCores:1>
2013-08-17 06:32:18,862 INFO org.apache.hadoop.yarn.server.resourcemanager.scheduler.capacity.LeafQueue: completedContainer container=Container: [ContainerId: container_1376720997863_0001_01_000002, NodeId: hadoop-512-3:56071, NodeHttpAddress: hadoop-512-3:8042, Resource: <memory:1024, vCores:1>, Priority: 20, State: NEW, Token: null, Status: container_id {, app_attempt_id {, application_id {, id: 1, cluster_timestamp: 1376720997863, }, attemptId: 1, }, id: 2, }, state: C_COMPLETE, diagnostics: "Container killed by the ApplicationMaster.\n\n", exit_status: 143, ] resource=<memory:1024, vCores:1> queue=default: capacity=1.0, absoluteCapacity=1.0, usedResources=<memory:2048, vCores:1>usedCapacity=0.041666668, absoluteUsedCapacity=0.041666668, numApps=1, numContainers=1 usedCapacity=0.041666668 absoluteUsedCapacity=0.041666668 used=<memory:2048, vCores:1> cluster=<memory:49152, vCores:96>
2013-08-17 06:32:18,863 INFO org.apache.hadoop.yarn.server.resourcemanager.scheduler.capacity.ParentQueue: completedContainer queue=root usedCapacity=0.041666668 absoluteUsedCapacity=0.041666668 used=<memory:2048, vCores:1> cluster=<memory:49152, vCores:96>
2013-08-17 06:32:18,863 INFO org.apache.hadoop.yarn.server.resourcemanager.scheduler.capacity.CapacityScheduler: Application appattempt_1376720997863_0001_000001 released container container_1376720997863_0001_01_000002 on node: host: hadoop-512-3:56071 #containers=0 available=8192 used=0 with event: FINISHED
2013-08-17 06:32:23,013 INFO org.apache.hadoop.yarn.server.resourcemanager.rmapp.attempt.RMAppAttemptImpl: appattempt_1376720997863_0001_000001 State change from RUNNING to FINISHING
2013-08-17 06:32:23,014 INFO org.apache.hadoop.yarn.server.resourcemanager.rmapp.RMAppImpl: application_1376720997863_0001 State change from RUNNING to FINISHING
2013-08-17 06:32:23,526 INFO org.apache.hadoop.yarn.server.resourcemanager.rmcontainer.RMContainerImpl: container_1376720997863_0001_01_000001 Container Transitioned from RUNNING to COMPLETED
2013-08-17 06:32:23,526 INFO org.apache.hadoop.yarn.server.resourcemanager.scheduler.common.fica.FiCaSchedulerApp: Completed container: container_1376720997863_0001_01_000001 in state: COMPLETED event:FINISHED
2013-08-17 06:32:23,526 INFO org.apache.hadoop.yarn.server.resourcemanager.RMAuditLogger: USER=ubuntu	OPERATION=AM Released Container	TARGET=SchedulerApp	RESULT=SUCCESS	APPID=application_1376720997863_0001	CONTAINERID=container_1376720997863_0001_01_000001
2013-08-17 06:32:23,526 INFO org.apache.hadoop.yarn.server.resourcemanager.scheduler.common.fica.FiCaSchedulerNode: Released container container_1376720997863_0001_01_000001 of capacity <memory:2048, vCores:1> on host hadoop-512-6:48301, which currently has 0 containers, <memory:0, vCores:0> used and <memory:8192, vCores:16> available, release resources=true
2013-08-17 06:32:23,526 INFO org.apache.hadoop.yarn.server.resourcemanager.scheduler.capacity.LeafQueue: default used=<memory:0, vCores:0> numContainers=0 user=ubuntu user-resources=<memory:0, vCores:0>
2013-08-17 06:32:23,528 INFO org.apache.hadoop.yarn.server.resourcemanager.scheduler.capacity.LeafQueue: completedContainer container=Container: [ContainerId: container_1376720997863_0001_01_000001, NodeId: hadoop-512-6:48301, NodeHttpAddress: hadoop-512-6:8042, Resource: <memory:2048, vCores:1>, Priority: 0, State: NEW, Token: null, Status: container_id {, app_attempt_id {, application_id {, id: 1, cluster_timestamp: 1376720997863, }, attemptId: 1, }, id: 1, }, state: C_COMPLETE, diagnostics: "", exit_status: 0, ] resource=<memory:2048, vCores:1> queue=default: capacity=1.0, absoluteCapacity=1.0, usedResources=<memory:0, vCores:0>usedCapacity=0.0, absoluteUsedCapacity=0.0, numApps=1, numContainers=0 usedCapacity=0.0 absoluteUsedCapacity=0.0 used=<memory:0, vCores:0> cluster=<memory:49152, vCores:96>
2013-08-17 06:32:23,528 INFO org.apache.hadoop.yarn.server.resourcemanager.scheduler.capacity.ParentQueue: completedContainer queue=root usedCapacity=0.0 absoluteUsedCapacity=0.0 used=<memory:0, vCores:0> cluster=<memory:49152, vCores:96>
2013-08-17 06:32:23,528 INFO org.apache.hadoop.yarn.server.resourcemanager.scheduler.capacity.CapacityScheduler: Application appattempt_1376720997863_0001_000001 released container container_1376720997863_0001_01_000001 on node: host: hadoop-512-6:48301 #containers=0 available=8192 used=0 with event: FINISHED
2013-08-17 06:32:23,531 INFO org.apache.hadoop.yarn.server.resourcemanager.rmapp.attempt.RMAppAttemptImpl: appattempt_1376720997863_0001_000001 State change from FINISHING to FINISHED
2013-08-17 06:32:23,533 INFO org.apache.hadoop.yarn.server.resourcemanager.rmapp.RMAppImpl: application_1376720997863_0001 State change from FINISHING to FINISHED
2013-08-17 06:32:23,533 INFO org.apache.hadoop.yarn.server.resourcemanager.scheduler.capacity.CapacityScheduler: Application appattempt_1376720997863_0001_000001 is done. finalState=FINISHED
2013-08-17 06:32:23,534 INFO org.apache.hadoop.yarn.server.resourcemanager.scheduler.AppSchedulingInfo: Application application_1376720997863_0001 requests cleared
2013-08-17 06:32:23,534 INFO org.apache.hadoop.yarn.server.resourcemanager.scheduler.capacity.LeafQueue: Application removed - appId: application_1376720997863_0001 user: ubuntu queue: default #user-pending-applications: 0 #user-active-applications: 0 #queue-pending-applications: 0 #queue-active-applications: 0
2013-08-17 06:32:23,535 INFO org.apache.hadoop.yarn.server.resourcemanager.scheduler.capacity.ParentQueue: Application removed - appId: application_1376720997863_0001 user: ubuntu leaf-queue of parent: root #applications: 0
2013-08-17 06:32:23,535 INFO org.apache.hadoop.yarn.server.resourcemanager.RMAuditLogger: USER=ubuntu	OPERATION=Application Finished - Succeeded	TARGET=RMAppManager	RESULT=SUCCESS	APPID=application_1376720997863_0001
2013-08-17 06:32:23,538 INFO org.apache.hadoop.yarn.server.resourcemanager.recovery.RMStateStore: Removing info for app: application_1376720997863_0001
2013-08-17 06:32:23,540 INFO org.apache.hadoop.yarn.server.resourcemanager.RMAppManager$ApplicationSummary: appId=application_1376720997863_0001,name=TeraGen,user=ubuntu,queue=default,state=FINISHED,trackingUrl=hadoop-512-1.novalocal:8088/proxy/application_1376720997863_0001/jobhistory/job/job_1376720997863_0001,appMasterHost=hadoop-512-6,startTime=1376721022110,finishTime=1376721143014
2013-08-17 06:32:23,536 INFO org.apache.hadoop.yarn.server.resourcemanager.amlauncher.AMLauncher: Cleaning master appattempt_1376720997863_0001_000001
2013-08-17 06:32:24,401 INFO org.apache.hadoop.yarn.server.resourcemanager.ClientRMService: Allocated new applicationId: 2
2013-08-17 06:32:26,335 INFO org.apache.hadoop.yarn.server.resourcemanager.ClientRMService: Storing Application with id application_1376720997863_0002
2013-08-17 06:32:26,336 INFO org.apache.hadoop.yarn.server.resourcemanager.recovery.RMStateStore: Storing info for app: application_1376720997863_0002
2013-08-17 06:32:26,336 INFO org.apache.hadoop.yarn.server.resourcemanager.ClientRMService: Application with id 2 submitted by user ubuntu
2013-08-17 06:32:26,336 INFO org.apache.hadoop.yarn.server.resourcemanager.RMAuditLogger: USER=ubuntu	IP=192.168.100.5	OPERATION=Submit Application Request	TARGET=ClientRMService	RESULT=SUCCESS	APPID=application_1376720997863_0002
2013-08-17 06:32:26,339 INFO org.apache.hadoop.yarn.server.resourcemanager.rmapp.RMAppImpl: application_1376720997863_0002 State change from NEW to SUBMITTED
2013-08-17 06:32:26,339 INFO org.apache.hadoop.yarn.server.resourcemanager.ApplicationMasterService: Registering appattempt_1376720997863_0002_000001
2013-08-17 06:32:26,339 INFO org.apache.hadoop.yarn.server.resourcemanager.rmapp.attempt.RMAppAttemptImpl: appattempt_1376720997863_0002_000001 State change from NEW to SUBMITTED
2013-08-17 06:32:26,340 INFO org.apache.hadoop.yarn.server.resourcemanager.scheduler.capacity.LeafQueue: Application application_1376720997863_0002 from user: ubuntu activated in queue: default
2013-08-17 06:32:26,340 INFO org.apache.hadoop.yarn.server.resourcemanager.scheduler.capacity.LeafQueue: Application added - appId: application_1376720997863_0002 user: org.apache.hadoop.yarn.server.resourcemanager.scheduler.capacity.LeafQueue$User@4378dbdc, leaf-queue: default #user-pending-applications: 0 #user-active-applications: 1 #queue-pending-applications: 0 #queue-active-applications: 1
2013-08-17 06:32:26,340 INFO org.apache.hadoop.yarn.server.resourcemanager.scheduler.capacity.ParentQueue: Application added - appId: application_1376720997863_0002 user: ubuntu leaf-queue of parent: root #applications: 1
2013-08-17 06:32:26,340 INFO org.apache.hadoop.yarn.server.resourcemanager.scheduler.capacity.CapacityScheduler: Application Submission: appattempt_1376720997863_0002_000001, user: ubuntu queue: default: capacity=1.0, absoluteCapacity=1.0, usedResources=<memory:0, vCores:0>usedCapacity=0.0, absoluteUsedCapacity=0.0, numApps=1, numContainers=0, currently active: 1
2013-08-17 06:32:26,341 INFO org.apache.hadoop.yarn.server.resourcemanager.rmapp.attempt.RMAppAttemptImpl: appattempt_1376720997863_0002_000001 State change from SUBMITTED to SCHEDULED
2013-08-17 06:32:26,341 INFO org.apache.hadoop.yarn.server.resourcemanager.rmapp.RMAppImpl: application_1376720997863_0002 State change from SUBMITTED to ACCEPTED
2013-08-17 06:32:26,369 INFO org.apache.hadoop.yarn.server.resourcemanager.rmcontainer.RMContainerImpl: container_1376720997863_0002_01_000001 Container Transitioned from NEW to ALLOCATED
2013-08-17 06:32:26,369 INFO org.apache.hadoop.yarn.server.resourcemanager.RMAuditLogger: USER=ubuntu	OPERATION=AM Allocated Container	TARGET=SchedulerApp	RESULT=SUCCESS	APPID=application_1376720997863_0002	CONTAINERID=container_1376720997863_0002_01_000001
2013-08-17 06:32:26,369 INFO org.apache.hadoop.yarn.server.resourcemanager.scheduler.common.fica.FiCaSchedulerNode: Assigned container container_1376720997863_0002_01_000001 of capacity <memory:2048, vCores:1> on host hadoop-512-4:45085, which currently has 1 containers, <memory:2048, vCores:1> used and <memory:6144, vCores:15> available
2013-08-17 06:32:26,371 INFO org.apache.hadoop.yarn.server.resourcemanager.scheduler.capacity.LeafQueue: assignedContainer application=application_1376720997863_0002 container=Container: [ContainerId: container_1376720997863_0002_01_000001, NodeId: hadoop-512-4:45085, NodeHttpAddress: hadoop-512-4:8042, Resource: <memory:2048, vCores:1>, Priority: 0, State: NEW, Token: null, Status: container_id {, app_attempt_id {, application_id {, id: 2, cluster_timestamp: 1376720997863, }, attemptId: 1, }, id: 1, }, state: C_NEW, ] containerId=container_1376720997863_0002_01_000001 queue=default: capacity=1.0, absoluteCapacity=1.0, usedResources=<memory:0, vCores:0>usedCapacity=0.0, absoluteUsedCapacity=0.0, numApps=1, numContainers=0 usedCapacity=0.0 absoluteUsedCapacity=0.0 used=<memory:0, vCores:0> cluster=<memory:49152, vCores:96>
2013-08-17 06:32:26,371 INFO org.apache.hadoop.yarn.server.resourcemanager.scheduler.capacity.ParentQueue: Re-sorting queues since queue: root.default stats: default: capacity=1.0, absoluteCapacity=1.0, usedResources=<memory:2048, vCores:1>usedCapacity=0.041666668, absoluteUsedCapacity=0.041666668, numApps=1, numContainers=1
2013-08-17 06:32:26,372 INFO org.apache.hadoop.yarn.server.resourcemanager.rmcontainer.RMContainerImpl: container_1376720997863_0002_01_000001 Container Transitioned from ALLOCATED to ACQUIRED
2013-08-17 06:32:26,372 INFO org.apache.hadoop.yarn.server.resourcemanager.scheduler.capacity.ParentQueue: assignedContainer queue=root usedCapacity=0.041666668 absoluteUsedCapacity=0.041666668 used=<memory:2048, vCores:1> cluster=<memory:49152, vCores:96>
2013-08-17 06:32:26,374 INFO org.apache.hadoop.yarn.server.resourcemanager.rmapp.attempt.RMAppAttemptImpl: Storing attempt: AppId: application_1376720997863_0002 AttemptId: appattempt_1376720997863_0002_000001 MasterContainer: Container: [ContainerId: container_1376720997863_0002_01_000001, NodeId: hadoop-512-4:45085, NodeHttpAddress: hadoop-512-4:8042, Resource: <memory:2048, vCores:1>, Priority: 0, State: NEW, Token: null, Status: container_id {, app_attempt_id {, application_id {, id: 2, cluster_timestamp: 1376720997863, }, attemptId: 1, }, id: 1, }, state: C_NEW, ]
2013-08-17 06:32:26,374 INFO org.apache.hadoop.yarn.server.resourcemanager.rmapp.attempt.RMAppAttemptImpl: appattempt_1376720997863_0002_000001 State change from SCHEDULED to ALLOCATED_SAVING
2013-08-17 06:32:26,374 INFO org.apache.hadoop.yarn.server.resourcemanager.recovery.RMStateStore: Storing info for attempt: appattempt_1376720997863_0002_000001
2013-08-17 06:32:26,375 INFO org.apache.hadoop.yarn.server.resourcemanager.rmapp.attempt.RMAppAttemptImpl: appattempt_1376720997863_0002_000001 State change from ALLOCATED_SAVING to ALLOCATED
2013-08-17 06:32:26,377 INFO org.apache.hadoop.yarn.server.resourcemanager.amlauncher.AMLauncher: Launching masterappattempt_1376720997863_0002_000001
2013-08-17 06:32:26,380 INFO org.apache.hadoop.yarn.server.resourcemanager.amlauncher.AMLauncher: Setting up container Container: [ContainerId: container_1376720997863_0002_01_000001, NodeId: hadoop-512-4:45085, NodeHttpAddress: hadoop-512-4:8042, Resource: <memory:2048, vCores:1>, Priority: 0, State: NEW, Token: null, Status: container_id {, app_attempt_id {, application_id {, id: 2, cluster_timestamp: 1376720997863, }, attemptId: 1, }, id: 1, }, state: C_NEW, ] for AM appattempt_1376720997863_0002_000001
2013-08-17 06:32:26,380 INFO org.apache.hadoop.yarn.server.resourcemanager.amlauncher.AMLauncher: Command to launch container container_1376720997863_0002_01_000001 : $JAVA_HOME/bin/java -Dlog4j.configuration=container-log4j.properties -Dyarn.app.mapreduce.container.log.dir=<LOG_DIR> -Dyarn.app.mapreduce.container.log.filesize=0 -Dhadoop.root.logger=INFO,CLA  -Xmx1024m org.apache.hadoop.mapreduce.v2.app.MRAppMaster 1><LOG_DIR>/stdout 2><LOG_DIR>/stderr 
2013-08-17 06:32:26,396 INFO org.apache.hadoop.yarn.server.resourcemanager.amlauncher.AMLauncher: Done launching container Container: [ContainerId: container_1376720997863_0002_01_000001, NodeId: hadoop-512-4:45085, NodeHttpAddress: hadoop-512-4:8042, Resource: <memory:2048, vCores:1>, Priority: 0, State: NEW, Token: null, Status: container_id {, app_attempt_id {, application_id {, id: 2, cluster_timestamp: 1376720997863, }, attemptId: 1, }, id: 1, }, state: C_NEW, ] for AM appattempt_1376720997863_0002_000001
2013-08-17 06:32:26,396 INFO org.apache.hadoop.yarn.server.resourcemanager.rmapp.attempt.RMAppAttemptImpl: appattempt_1376720997863_0002_000001 State change from ALLOCATED to LAUNCHED
2013-08-17 06:32:27,646 INFO org.apache.hadoop.yarn.server.resourcemanager.rmcontainer.RMContainerImpl: container_1376720997863_0002_01_000001 Container Transitioned from ACQUIRED to RUNNING
2013-08-17 06:32:32,747 INFO org.apache.hadoop.yarn.server.resourcemanager.ApplicationMasterService: AM registration appattempt_1376720997863_0002_000001
2013-08-17 06:32:32,747 INFO org.apache.hadoop.yarn.server.resourcemanager.RMAuditLogger: USER=ubuntu	IP=192.168.100.14	OPERATION=Register App Master	TARGET=ApplicationMasterService	RESULT=SUCCESS	APPID=application_1376720997863_0002	APPATTEMPTID=appattempt_1376720997863_0002_000001
2013-08-17 06:32:32,751 INFO org.apache.hadoop.yarn.server.resourcemanager.rmapp.attempt.RMAppAttemptImpl: appattempt_1376720997863_0002_000001 State change from LAUNCHED to RUNNING
2013-08-17 06:32:32,751 INFO org.apache.hadoop.yarn.server.resourcemanager.rmapp.RMAppImpl: application_1376720997863_0002 State change from ACCEPTED to RUNNING
2013-08-17 06:32:33,920 INFO org.apache.hadoop.yarn.server.resourcemanager.rmcontainer.RMContainerImpl: container_1376720997863_0002_01_000002 Container Transitioned from NEW to ALLOCATED
2013-08-17 06:32:33,920 INFO org.apache.hadoop.yarn.server.resourcemanager.RMAuditLogger: USER=ubuntu	OPERATION=AM Allocated Container	TARGET=SchedulerApp	RESULT=SUCCESS	APPID=application_1376720997863_0002	CONTAINERID=container_1376720997863_0002_01_000002
2013-08-17 06:32:33,921 INFO org.apache.hadoop.yarn.server.resourcemanager.scheduler.common.fica.FiCaSchedulerNode: Assigned container container_1376720997863_0002_01_000002 of capacity <memory:1024, vCores:1> on host hadoop-512-3:56071, which currently has 1 containers, <memory:1024, vCores:1> used and <memory:7168, vCores:15> available
2013-08-17 06:32:33,922 INFO org.apache.hadoop.yarn.server.resourcemanager.scheduler.capacity.LeafQueue: assignedContainer application=application_1376720997863_0002 container=Container: [ContainerId: container_1376720997863_0002_01_000002, NodeId: hadoop-512-3:56071, NodeHttpAddress: hadoop-512-3:8042, Resource: <memory:1024, vCores:1>, Priority: 20, State: NEW, Token: null, Status: container_id {, app_attempt_id {, application_id {, id: 2, cluster_timestamp: 1376720997863, }, attemptId: 1, }, id: 2, }, state: C_NEW, ] containerId=container_1376720997863_0002_01_000002 queue=default: capacity=1.0, absoluteCapacity=1.0, usedResources=<memory:2048, vCores:1>usedCapacity=0.041666668, absoluteUsedCapacity=0.041666668, numApps=1, numContainers=1 usedCapacity=0.041666668 absoluteUsedCapacity=0.041666668 used=<memory:2048, vCores:1> cluster=<memory:49152, vCores:96>
2013-08-17 06:32:33,923 INFO org.apache.hadoop.yarn.server.resourcemanager.scheduler.capacity.ParentQueue: Re-sorting queues since queue: root.default stats: default: capacity=1.0, absoluteCapacity=1.0, usedResources=<memory:3072, vCores:2>usedCapacity=0.0625, absoluteUsedCapacity=0.0625, numApps=1, numContainers=2
2013-08-17 06:32:33,923 INFO org.apache.hadoop.yarn.server.resourcemanager.scheduler.capacity.ParentQueue: assignedContainer queue=root usedCapacity=0.0625 absoluteUsedCapacity=0.0625 used=<memory:3072, vCores:2> cluster=<memory:49152, vCores:96>
2013-08-17 06:32:34,253 INFO org.apache.hadoop.yarn.server.resourcemanager.rmcontainer.RMContainerImpl: container_1376720997863_0002_01_000003 Container Transitioned from NEW to ALLOCATED
2013-08-17 06:32:34,253 INFO org.apache.hadoop.yarn.server.resourcemanager.RMAuditLogger: USER=ubuntu	OPERATION=AM Allocated Container	TARGET=SchedulerApp	RESULT=SUCCESS	APPID=application_1376720997863_0002	CONTAINERID=container_1376720997863_0002_01_000003
2013-08-17 06:32:34,253 INFO org.apache.hadoop.yarn.server.resourcemanager.scheduler.common.fica.FiCaSchedulerNode: Assigned container container_1376720997863_0002_01_000003 of capacity <memory:1024, vCores:1> on host hadoop-512-5:45082, which currently has 1 containers, <memory:1024, vCores:1> used and <memory:7168, vCores:15> available
2013-08-17 06:32:34,255 INFO org.apache.hadoop.yarn.server.resourcemanager.scheduler.capacity.LeafQueue: assignedContainer application=application_1376720997863_0002 container=Container: [ContainerId: container_1376720997863_0002_01_000003, NodeId: hadoop-512-5:45082, NodeHttpAddress: hadoop-512-5:8042, Resource: <memory:1024, vCores:1>, Priority: 20, State: NEW, Token: null, Status: container_id {, app_attempt_id {, application_id {, id: 2, cluster_timestamp: 1376720997863, }, attemptId: 1, }, id: 3, }, state: C_NEW, ] containerId=container_1376720997863_0002_01_000003 queue=default: capacity=1.0, absoluteCapacity=1.0, usedResources=<memory:3072, vCores:2>usedCapacity=0.0625, absoluteUsedCapacity=0.0625, numApps=1, numContainers=2 usedCapacity=0.0625 absoluteUsedCapacity=0.0625 used=<memory:3072, vCores:2> cluster=<memory:49152, vCores:96>
2013-08-17 06:32:34,255 INFO org.apache.hadoop.yarn.server.resourcemanager.scheduler.capacity.ParentQueue: Re-sorting queues since queue: root.default stats: default: capacity=1.0, absoluteCapacity=1.0, usedResources=<memory:4096, vCores:3>usedCapacity=0.083333336, absoluteUsedCapacity=0.083333336, numApps=1, numContainers=3
2013-08-17 06:32:34,255 INFO org.apache.hadoop.yarn.server.resourcemanager.scheduler.capacity.ParentQueue: assignedContainer queue=root usedCapacity=0.083333336 absoluteUsedCapacity=0.083333336 used=<memory:4096, vCores:3> cluster=<memory:49152, vCores:96>
2013-08-17 06:32:34,804 INFO org.apache.hadoop.yarn.server.resourcemanager.rmcontainer.RMContainerImpl: container_1376720997863_0002_01_000002 Container Transitioned from ALLOCATED to ACQUIRED
2013-08-17 06:32:34,805 INFO org.apache.hadoop.yarn.server.resourcemanager.rmcontainer.RMContainerImpl: container_1376720997863_0002_01_000003 Container Transitioned from ALLOCATED to ACQUIRED
2013-08-17 06:32:35,833 INFO org.apache.hadoop.yarn.server.resourcemanager.scheduler.AppSchedulingInfo: checking for deactivate... 
2013-08-17 06:32:35,931 INFO org.apache.hadoop.yarn.server.resourcemanager.rmcontainer.RMContainerImpl: container_1376720997863_0002_01_000002 Container Transitioned from ACQUIRED to RUNNING
2013-08-17 06:32:36,387 INFO org.apache.hadoop.yarn.server.resourcemanager.rmcontainer.RMContainerImpl: container_1376720997863_0002_01_000003 Container Transitioned from ACQUIRED to RUNNING
2013-08-17 06:34:15,118 INFO org.apache.hadoop.yarn.server.resourcemanager.rmcontainer.RMContainerImpl: container_1376720997863_0002_01_000002 Container Transitioned from RUNNING to COMPLETED
2013-08-17 06:34:15,119 INFO org.apache.hadoop.yarn.server.resourcemanager.scheduler.common.fica.FiCaSchedulerApp: Completed container: container_1376720997863_0002_01_000002 in state: COMPLETED event:FINISHED
2013-08-17 06:34:15,119 INFO org.apache.hadoop.yarn.server.resourcemanager.RMAuditLogger: USER=ubuntu	OPERATION=AM Released Container	TARGET=SchedulerApp	RESULT=SUCCESS	APPID=application_1376720997863_0002	CONTAINERID=container_1376720997863_0002_01_000002
2013-08-17 06:34:15,119 INFO org.apache.hadoop.yarn.server.resourcemanager.scheduler.common.fica.FiCaSchedulerNode: Released container container_1376720997863_0002_01_000002 of capacity <memory:1024, vCores:1> on host hadoop-512-3:56071, which currently has 0 containers, <memory:0, vCores:0> used and <memory:8192, vCores:16> available, release resources=true
2013-08-17 06:34:15,119 INFO org.apache.hadoop.yarn.server.resourcemanager.scheduler.capacity.LeafQueue: default used=<memory:3072, vCores:2> numContainers=2 user=ubuntu user-resources=<memory:3072, vCores:2>
2013-08-17 06:34:15,133 INFO org.apache.hadoop.yarn.server.resourcemanager.scheduler.capacity.LeafQueue: completedContainer container=Container: [ContainerId: container_1376720997863_0002_01_000002, NodeId: hadoop-512-3:56071, NodeHttpAddress: hadoop-512-3:8042, Resource: <memory:1024, vCores:1>, Priority: 20, State: NEW, Token: null, Status: container_id {, app_attempt_id {, application_id {, id: 2, cluster_timestamp: 1376720997863, }, attemptId: 1, }, id: 2, }, state: C_COMPLETE, diagnostics: "Container killed by the ApplicationMaster.\n\n", exit_status: 143, ] resource=<memory:1024, vCores:1> queue=default: capacity=1.0, absoluteCapacity=1.0, usedResources=<memory:3072, vCores:2>usedCapacity=0.0625, absoluteUsedCapacity=0.0625, numApps=1, numContainers=2 usedCapacity=0.0625 absoluteUsedCapacity=0.0625 used=<memory:3072, vCores:2> cluster=<memory:49152, vCores:96>
2013-08-17 06:34:15,133 INFO org.apache.hadoop.yarn.server.resourcemanager.scheduler.capacity.ParentQueue: completedContainer queue=root usedCapacity=0.0625 absoluteUsedCapacity=0.0625 used=<memory:3072, vCores:2> cluster=<memory:49152, vCores:96>
2013-08-17 06:34:15,133 INFO org.apache.hadoop.yarn.server.resourcemanager.scheduler.capacity.CapacityScheduler: Application appattempt_1376720997863_0002_000001 released container container_1376720997863_0002_01_000002 on node: host: hadoop-512-3:56071 #containers=0 available=8192 used=0 with event: FINISHED
2013-08-17 06:34:22,246 INFO org.apache.hadoop.yarn.server.resourcemanager.rmcontainer.RMContainerImpl: container_1376720997863_0002_01_000003 Container Transitioned from RUNNING to COMPLETED
2013-08-17 06:34:22,247 INFO org.apache.hadoop.yarn.server.resourcemanager.scheduler.common.fica.FiCaSchedulerApp: Completed container: container_1376720997863_0002_01_000003 in state: COMPLETED event:FINISHED
2013-08-17 06:34:22,247 INFO org.apache.hadoop.yarn.server.resourcemanager.RMAuditLogger: USER=ubuntu	OPERATION=AM Released Container	TARGET=SchedulerApp	RESULT=SUCCESS	APPID=application_1376720997863_0002	CONTAINERID=container_1376720997863_0002_01_000003
2013-08-17 06:34:22,247 INFO org.apache.hadoop.yarn.server.resourcemanager.scheduler.common.fica.FiCaSchedulerNode: Released container container_1376720997863_0002_01_000003 of capacity <memory:1024, vCores:1> on host hadoop-512-5:45082, which currently has 0 containers, <memory:0, vCores:0> used and <memory:8192, vCores:16> available, release resources=true
2013-08-17 06:34:22,247 INFO org.apache.hadoop.yarn.server.resourcemanager.scheduler.capacity.LeafQueue: default used=<memory:2048, vCores:1> numContainers=1 user=ubuntu user-resources=<memory:2048, vCores:1>
2013-08-17 06:34:22,249 INFO org.apache.hadoop.yarn.server.resourcemanager.scheduler.capacity.LeafQueue: completedContainer container=Container: [ContainerId: container_1376720997863_0002_01_000003, NodeId: hadoop-512-5:45082, NodeHttpAddress: hadoop-512-5:8042, Resource: <memory:1024, vCores:1>, Priority: 20, State: NEW, Token: null, Status: container_id {, app_attempt_id {, application_id {, id: 2, cluster_timestamp: 1376720997863, }, attemptId: 1, }, id: 3, }, state: C_COMPLETE, diagnostics: "Container killed by the ApplicationMaster.\n\n", exit_status: 143, ] resource=<memory:1024, vCores:1> queue=default: capacity=1.0, absoluteCapacity=1.0, usedResources=<memory:2048, vCores:1>usedCapacity=0.041666668, absoluteUsedCapacity=0.041666668, numApps=1, numContainers=1 usedCapacity=0.041666668 absoluteUsedCapacity=0.041666668 used=<memory:2048, vCores:1> cluster=<memory:49152, vCores:96>
2013-08-17 06:34:22,250 INFO org.apache.hadoop.yarn.server.resourcemanager.scheduler.capacity.ParentQueue: completedContainer queue=root usedCapacity=0.041666668 absoluteUsedCapacity=0.041666668 used=<memory:2048, vCores:1> cluster=<memory:49152, vCores:96>
2013-08-17 06:34:22,250 INFO org.apache.hadoop.yarn.server.resourcemanager.scheduler.capacity.CapacityScheduler: Application appattempt_1376720997863_0002_000001 released container container_1376720997863_0002_01_000003 on node: host: hadoop-512-5:45082 #containers=0 available=8192 used=0 with event: FINISHED
2013-08-17 06:34:26,391 INFO org.apache.hadoop.yarn.server.resourcemanager.rmapp.attempt.RMAppAttemptImpl: appattempt_1376720997863_0002_000001 State change from RUNNING to FINISHING
2013-08-17 06:34:26,392 INFO org.apache.hadoop.yarn.server.resourcemanager.rmapp.RMAppImpl: application_1376720997863_0002 State change from RUNNING to FINISHING
2013-08-17 06:34:27,539 INFO org.apache.hadoop.yarn.server.resourcemanager.rmcontainer.RMContainerImpl: container_1376720997863_0002_01_000001 Container Transitioned from RUNNING to COMPLETED
2013-08-17 06:34:27,539 INFO org.apache.hadoop.yarn.server.resourcemanager.scheduler.common.fica.FiCaSchedulerApp: Completed container: container_1376720997863_0002_01_000001 in state: COMPLETED event:FINISHED
2013-08-17 06:34:27,539 INFO org.apache.hadoop.yarn.server.resourcemanager.RMAuditLogger: USER=ubuntu	OPERATION=AM Released Container	TARGET=SchedulerApp	RESULT=SUCCESS	APPID=application_1376720997863_0002	CONTAINERID=container_1376720997863_0002_01_000001
2013-08-17 06:34:27,539 INFO org.apache.hadoop.yarn.server.resourcemanager.scheduler.common.fica.FiCaSchedulerNode: Released container container_1376720997863_0002_01_000001 of capacity <memory:2048, vCores:1> on host hadoop-512-4:45085, which currently has 0 containers, <memory:0, vCores:0> used and <memory:8192, vCores:16> available, release resources=true
2013-08-17 06:34:27,540 INFO org.apache.hadoop.yarn.server.resourcemanager.scheduler.capacity.LeafQueue: default used=<memory:0, vCores:0> numContainers=0 user=ubuntu user-resources=<memory:0, vCores:0>
2013-08-17 06:34:27,541 INFO org.apache.hadoop.yarn.server.resourcemanager.scheduler.capacity.LeafQueue: completedContainer container=Container: [ContainerId: container_1376720997863_0002_01_000001, NodeId: hadoop-512-4:45085, NodeHttpAddress: hadoop-512-4:8042, Resource: <memory:2048, vCores:1>, Priority: 0, State: NEW, Token: null, Status: container_id {, app_attempt_id {, application_id {, id: 2, cluster_timestamp: 1376720997863, }, attemptId: 1, }, id: 1, }, state: C_COMPLETE, diagnostics: "", exit_status: 0, ] resource=<memory:2048, vCores:1> queue=default: capacity=1.0, absoluteCapacity=1.0, usedResources=<memory:0, vCores:0>usedCapacity=0.0, absoluteUsedCapacity=0.0, numApps=1, numContainers=0 usedCapacity=0.0 absoluteUsedCapacity=0.0 used=<memory:0, vCores:0> cluster=<memory:49152, vCores:96>
2013-08-17 06:34:27,541 INFO org.apache.hadoop.yarn.server.resourcemanager.scheduler.capacity.ParentQueue: completedContainer queue=root usedCapacity=0.0 absoluteUsedCapacity=0.0 used=<memory:0, vCores:0> cluster=<memory:49152, vCores:96>
2013-08-17 06:34:27,541 INFO org.apache.hadoop.yarn.server.resourcemanager.scheduler.capacity.CapacityScheduler: Application appattempt_1376720997863_0002_000001 released container container_1376720997863_0002_01_000001 on node: host: hadoop-512-4:45085 #containers=0 available=8192 used=0 with event: FINISHED
2013-08-17 06:34:27,541 INFO org.apache.hadoop.yarn.server.resourcemanager.rmapp.attempt.RMAppAttemptImpl: appattempt_1376720997863_0002_000001 State change from FINISHING to FINISHED
2013-08-17 06:34:27,542 INFO org.apache.hadoop.yarn.server.resourcemanager.rmapp.RMAppImpl: application_1376720997863_0002 State change from FINISHING to FINISHED
2013-08-17 06:34:27,542 INFO org.apache.hadoop.yarn.server.resourcemanager.RMAuditLogger: USER=ubuntu	OPERATION=Application Finished - Succeeded	TARGET=RMAppManager	RESULT=SUCCESS	APPID=application_1376720997863_0002
2013-08-17 06:34:27,542 INFO org.apache.hadoop.yarn.server.resourcemanager.scheduler.capacity.CapacityScheduler: Application appattempt_1376720997863_0002_000001 is done. finalState=FINISHED
2013-08-17 06:34:27,543 INFO org.apache.hadoop.yarn.server.resourcemanager.scheduler.AppSchedulingInfo: Application application_1376720997863_0002 requests cleared
2013-08-17 06:34:27,543 INFO org.apache.hadoop.yarn.server.resourcemanager.recovery.RMStateStore: Removing info for app: application_1376720997863_0002
2013-08-17 06:34:27,543 INFO org.apache.hadoop.yarn.server.resourcemanager.scheduler.capacity.LeafQueue: Application removed - appId: application_1376720997863_0002 user: ubuntu queue: default #user-pending-applications: 0 #user-active-applications: 0 #queue-pending-applications: 0 #queue-active-applications: 0
2013-08-17 06:34:27,543 INFO org.apache.hadoop.yarn.server.resourcemanager.scheduler.capacity.ParentQueue: Application removed - appId: application_1376720997863_0002 user: ubuntu leaf-queue of parent: root #applications: 0
2013-08-17 06:34:27,543 INFO org.apache.hadoop.yarn.server.resourcemanager.RMAppManager$ApplicationSummary: appId=application_1376720997863_0002,name=TeraGen,user=ubuntu,queue=default,state=FINISHED,trackingUrl=hadoop-512-1.novalocal:8088/proxy/application_1376720997863_0002/jobhistory/job/job_1376720997863_0002,appMasterHost=hadoop-512-4,startTime=1376721146335,finishTime=1376721266392
2013-08-17 06:34:27,546 INFO org.apache.hadoop.yarn.server.resourcemanager.amlauncher.AMLauncher: Cleaning master appattempt_1376720997863_0002_000001
2013-08-17 06:34:27,693 INFO org.apache.hadoop.yarn.server.resourcemanager.ClientRMService: Allocated new applicationId: 3
2013-08-17 06:34:29,646 INFO org.apache.hadoop.yarn.server.resourcemanager.ClientRMService: Storing Application with id application_1376720997863_0003
2013-08-17 06:34:29,646 INFO org.apache.hadoop.yarn.server.resourcemanager.recovery.RMStateStore: Storing info for app: application_1376720997863_0003
2013-08-17 06:34:29,646 INFO org.apache.hadoop.yarn.server.resourcemanager.ClientRMService: Application with id 3 submitted by user ubuntu
2013-08-17 06:34:29,647 INFO org.apache.hadoop.yarn.server.resourcemanager.RMAuditLogger: USER=ubuntu	IP=192.168.100.5	OPERATION=Submit Application Request	TARGET=ClientRMService	RESULT=SUCCESS	APPID=application_1376720997863_0003
2013-08-17 06:34:29,648 INFO org.apache.hadoop.yarn.server.resourcemanager.rmapp.RMAppImpl: application_1376720997863_0003 State change from NEW to SUBMITTED
2013-08-17 06:34:29,648 INFO org.apache.hadoop.yarn.server.resourcemanager.ApplicationMasterService: Registering appattempt_1376720997863_0003_000001
2013-08-17 06:34:29,648 INFO org.apache.hadoop.yarn.server.resourcemanager.rmapp.attempt.RMAppAttemptImpl: appattempt_1376720997863_0003_000001 State change from NEW to SUBMITTED
2013-08-17 06:34:29,649 INFO org.apache.hadoop.yarn.server.resourcemanager.scheduler.capacity.LeafQueue: Application application_1376720997863_0003 from user: ubuntu activated in queue: default
2013-08-17 06:34:29,649 INFO org.apache.hadoop.yarn.server.resourcemanager.scheduler.capacity.LeafQueue: Application added - appId: application_1376720997863_0003 user: org.apache.hadoop.yarn.server.resourcemanager.scheduler.capacity.LeafQueue$User@5be0a2fc, leaf-queue: default #user-pending-applications: 0 #user-active-applications: 1 #queue-pending-applications: 0 #queue-active-applications: 1
2013-08-17 06:34:29,649 INFO org.apache.hadoop.yarn.server.resourcemanager.scheduler.capacity.ParentQueue: Application added - appId: application_1376720997863_0003 user: ubuntu leaf-queue of parent: root #applications: 1
2013-08-17 06:34:29,649 INFO org.apache.hadoop.yarn.server.resourcemanager.scheduler.capacity.CapacityScheduler: Application Submission: appattempt_1376720997863_0003_000001, user: ubuntu queue: default: capacity=1.0, absoluteCapacity=1.0, usedResources=<memory:0, vCores:0>usedCapacity=0.0, absoluteUsedCapacity=0.0, numApps=1, numContainers=0, currently active: 1
2013-08-17 06:34:29,650 INFO org.apache.hadoop.yarn.server.resourcemanager.rmapp.attempt.RMAppAttemptImpl: appattempt_1376720997863_0003_000001 State change from SUBMITTED to SCHEDULED
2013-08-17 06:34:29,650 INFO org.apache.hadoop.yarn.server.resourcemanager.rmapp.RMAppImpl: application_1376720997863_0003 State change from SUBMITTED to ACCEPTED
2013-08-17 06:34:29,722 INFO org.apache.hadoop.yarn.server.resourcemanager.rmcontainer.RMContainerImpl: container_1376720997863_0003_01_000001 Container Transitioned from NEW to ALLOCATED
2013-08-17 06:34:29,722 INFO org.apache.hadoop.yarn.server.resourcemanager.RMAuditLogger: USER=ubuntu	OPERATION=AM Allocated Container	TARGET=SchedulerApp	RESULT=SUCCESS	APPID=application_1376720997863_0003	CONTAINERID=container_1376720997863_0003_01_000001
2013-08-17 06:34:29,722 INFO org.apache.hadoop.yarn.server.resourcemanager.scheduler.common.fica.FiCaSchedulerNode: Assigned container container_1376720997863_0003_01_000001 of capacity <memory:2048, vCores:1> on host hadoop-512-2:32923, which currently has 1 containers, <memory:2048, vCores:1> used and <memory:6144, vCores:15> available
2013-08-17 06:34:29,724 INFO org.apache.hadoop.yarn.server.resourcemanager.scheduler.capacity.LeafQueue: assignedContainer application=application_1376720997863_0003 container=Container: [ContainerId: container_1376720997863_0003_01_000001, NodeId: hadoop-512-2:32923, NodeHttpAddress: hadoop-512-2:8042, Resource: <memory:2048, vCores:1>, Priority: 0, State: NEW, Token: null, Status: container_id {, app_attempt_id {, application_id {, id: 3, cluster_timestamp: 1376720997863, }, attemptId: 1, }, id: 1, }, state: C_NEW, ] containerId=container_1376720997863_0003_01_000001 queue=default: capacity=1.0, absoluteCapacity=1.0, usedResources=<memory:0, vCores:0>usedCapacity=0.0, absoluteUsedCapacity=0.0, numApps=1, numContainers=0 usedCapacity=0.0 absoluteUsedCapacity=0.0 used=<memory:0, vCores:0> cluster=<memory:49152, vCores:96>
2013-08-17 06:34:29,724 INFO org.apache.hadoop.yarn.server.resourcemanager.scheduler.capacity.ParentQueue: Re-sorting queues since queue: root.default stats: default: capacity=1.0, absoluteCapacity=1.0, usedResources=<memory:2048, vCores:1>usedCapacity=0.041666668, absoluteUsedCapacity=0.041666668, numApps=1, numContainers=1
2013-08-17 06:34:29,725 INFO org.apache.hadoop.yarn.server.resourcemanager.scheduler.capacity.ParentQueue: assignedContainer queue=root usedCapacity=0.041666668 absoluteUsedCapacity=0.041666668 used=<memory:2048, vCores:1> cluster=<memory:49152, vCores:96>
2013-08-17 06:34:29,726 INFO org.apache.hadoop.yarn.server.resourcemanager.rmcontainer.RMContainerImpl: container_1376720997863_0003_01_000001 Container Transitioned from ALLOCATED to ACQUIRED
2013-08-17 06:34:29,728 INFO org.apache.hadoop.yarn.server.resourcemanager.rmapp.attempt.RMAppAttemptImpl: Storing attempt: AppId: application_1376720997863_0003 AttemptId: appattempt_1376720997863_0003_000001 MasterContainer: Container: [ContainerId: container_1376720997863_0003_01_000001, NodeId: hadoop-512-2:32923, NodeHttpAddress: hadoop-512-2:8042, Resource: <memory:2048, vCores:1>, Priority: 0, State: NEW, Token: null, Status: container_id {, app_attempt_id {, application_id {, id: 3, cluster_timestamp: 1376720997863, }, attemptId: 1, }, id: 1, }, state: C_NEW, ]
2013-08-17 06:34:29,728 INFO org.apache.hadoop.yarn.server.resourcemanager.rmapp.attempt.RMAppAttemptImpl: appattempt_1376720997863_0003_000001 State change from SCHEDULED to ALLOCATED_SAVING
2013-08-17 06:34:29,728 INFO org.apache.hadoop.yarn.server.resourcemanager.recovery.RMStateStore: Storing info for attempt: appattempt_1376720997863_0003_000001
2013-08-17 06:34:29,731 INFO org.apache.hadoop.yarn.server.resourcemanager.rmapp.attempt.RMAppAttemptImpl: appattempt_1376720997863_0003_000001 State change from ALLOCATED_SAVING to ALLOCATED
2013-08-17 06:34:29,733 INFO org.apache.hadoop.yarn.server.resourcemanager.amlauncher.AMLauncher: Launching masterappattempt_1376720997863_0003_000001
2013-08-17 06:34:29,736 INFO org.apache.hadoop.yarn.server.resourcemanager.amlauncher.AMLauncher: Setting up container Container: [ContainerId: container_1376720997863_0003_01_000001, NodeId: hadoop-512-2:32923, NodeHttpAddress: hadoop-512-2:8042, Resource: <memory:2048, vCores:1>, Priority: 0, State: NEW, Token: null, Status: container_id {, app_attempt_id {, application_id {, id: 3, cluster_timestamp: 1376720997863, }, attemptId: 1, }, id: 1, }, state: C_NEW, ] for AM appattempt_1376720997863_0003_000001
2013-08-17 06:34:29,736 INFO org.apache.hadoop.yarn.server.resourcemanager.amlauncher.AMLauncher: Command to launch container container_1376720997863_0003_01_000001 : $JAVA_HOME/bin/java -Dlog4j.configuration=container-log4j.properties -Dyarn.app.mapreduce.container.log.dir=<LOG_DIR> -Dyarn.app.mapreduce.container.log.filesize=0 -Dhadoop.root.logger=INFO,CLA  -Xmx1024m org.apache.hadoop.mapreduce.v2.app.MRAppMaster 1><LOG_DIR>/stdout 2><LOG_DIR>/stderr 
2013-08-17 06:34:30,577 INFO org.apache.hadoop.yarn.server.resourcemanager.amlauncher.AMLauncher: Done launching container Container: [ContainerId: container_1376720997863_0003_01_000001, NodeId: hadoop-512-2:32923, NodeHttpAddress: hadoop-512-2:8042, Resource: <memory:2048, vCores:1>, Priority: 0, State: NEW, Token: null, Status: container_id {, app_attempt_id {, application_id {, id: 3, cluster_timestamp: 1376720997863, }, attemptId: 1, }, id: 1, }, state: C_NEW, ] for AM appattempt_1376720997863_0003_000001
2013-08-17 06:34:30,578 INFO org.apache.hadoop.yarn.server.resourcemanager.rmapp.attempt.RMAppAttemptImpl: appattempt_1376720997863_0003_000001 State change from ALLOCATED to LAUNCHED
2013-08-17 06:34:30,808 INFO org.apache.hadoop.yarn.server.resourcemanager.rmcontainer.RMContainerImpl: container_1376720997863_0003_01_000001 Container Transitioned from ACQUIRED to RUNNING
2013-08-17 06:34:40,646 INFO org.apache.hadoop.yarn.server.resourcemanager.ApplicationMasterService: AM registration appattempt_1376720997863_0003_000001
2013-08-17 06:34:40,646 INFO org.apache.hadoop.yarn.server.resourcemanager.RMAuditLogger: USER=ubuntu	IP=192.168.100.26	OPERATION=Register App Master	TARGET=ApplicationMasterService	RESULT=SUCCESS	APPID=application_1376720997863_0003	APPATTEMPTID=appattempt_1376720997863_0003_000001
2013-08-17 06:34:40,647 INFO org.apache.hadoop.yarn.server.resourcemanager.rmapp.attempt.RMAppAttemptImpl: appattempt_1376720997863_0003_000001 State change from LAUNCHED to RUNNING
2013-08-17 06:34:40,648 INFO org.apache.hadoop.yarn.server.resourcemanager.rmapp.RMAppImpl: application_1376720997863_0003 State change from ACCEPTED to RUNNING
2013-08-17 06:34:41,779 INFO org.apache.hadoop.yarn.server.resourcemanager.rmcontainer.RMContainerImpl: container_1376720997863_0003_01_000002 Container Transitioned from NEW to ALLOCATED
2013-08-17 06:34:41,779 INFO org.apache.hadoop.yarn.server.resourcemanager.RMAuditLogger: USER=ubuntu	OPERATION=AM Allocated Container	TARGET=SchedulerApp	RESULT=SUCCESS	APPID=application_1376720997863_0003	CONTAINERID=container_1376720997863_0003_01_000002
2013-08-17 06:34:41,780 INFO org.apache.hadoop.yarn.server.resourcemanager.scheduler.common.fica.FiCaSchedulerNode: Assigned container container_1376720997863_0003_01_000002 of capacity <memory:1024, vCores:1> on host hadoop-512-7:43914, which currently has 1 containers, <memory:1024, vCores:1> used and <memory:7168, vCores:15> available
2013-08-17 06:34:41,781 INFO org.apache.hadoop.yarn.server.resourcemanager.scheduler.capacity.LeafQueue: assignedContainer application=application_1376720997863_0003 container=Container: [ContainerId: container_1376720997863_0003_01_000002, NodeId: hadoop-512-7:43914, NodeHttpAddress: hadoop-512-7:8042, Resource: <memory:1024, vCores:1>, Priority: 20, State: NEW, Token: null, Status: container_id {, app_attempt_id {, application_id {, id: 3, cluster_timestamp: 1376720997863, }, attemptId: 1, }, id: 2, }, state: C_NEW, ] containerId=container_1376720997863_0003_01_000002 queue=default: capacity=1.0, absoluteCapacity=1.0, usedResources=<memory:2048, vCores:1>usedCapacity=0.041666668, absoluteUsedCapacity=0.041666668, numApps=1, numContainers=1 usedCapacity=0.041666668 absoluteUsedCapacity=0.041666668 used=<memory:2048, vCores:1> cluster=<memory:49152, vCores:96>
2013-08-17 06:34:41,781 INFO org.apache.hadoop.yarn.server.resourcemanager.scheduler.capacity.ParentQueue: Re-sorting queues since queue: root.default stats: default: capacity=1.0, absoluteCapacity=1.0, usedResources=<memory:3072, vCores:2>usedCapacity=0.0625, absoluteUsedCapacity=0.0625, numApps=1, numContainers=2
2013-08-17 06:34:41,782 INFO org.apache.hadoop.yarn.server.resourcemanager.scheduler.capacity.ParentQueue: assignedContainer queue=root usedCapacity=0.0625 absoluteUsedCapacity=0.0625 used=<memory:3072, vCores:2> cluster=<memory:49152, vCores:96>
2013-08-17 06:34:41,872 INFO org.apache.hadoop.yarn.server.resourcemanager.rmcontainer.RMContainerImpl: container_1376720997863_0003_01_000003 Container Transitioned from NEW to ALLOCATED
2013-08-17 06:34:41,872 INFO org.apache.hadoop.yarn.server.resourcemanager.RMAuditLogger: USER=ubuntu	OPERATION=AM Allocated Container	TARGET=SchedulerApp	RESULT=SUCCESS	APPID=application_1376720997863_0003	CONTAINERID=container_1376720997863_0003_01_000003
2013-08-17 06:34:41,872 INFO org.apache.hadoop.yarn.server.resourcemanager.scheduler.common.fica.FiCaSchedulerNode: Assigned container container_1376720997863_0003_01_000003 of capacity <memory:1024, vCores:1> on host hadoop-512-2:32923, which currently has 2 containers, <memory:3072, vCores:2> used and <memory:5120, vCores:14> available
2013-08-17 06:34:41,874 INFO org.apache.hadoop.yarn.server.resourcemanager.scheduler.capacity.LeafQueue: assignedContainer application=application_1376720997863_0003 container=Container: [ContainerId: container_1376720997863_0003_01_000003, NodeId: hadoop-512-2:32923, NodeHttpAddress: hadoop-512-2:8042, Resource: <memory:1024, vCores:1>, Priority: 20, State: NEW, Token: null, Status: container_id {, app_attempt_id {, application_id {, id: 3, cluster_timestamp: 1376720997863, }, attemptId: 1, }, id: 3, }, state: C_NEW, ] containerId=container_1376720997863_0003_01_000003 queue=default: capacity=1.0, absoluteCapacity=1.0, usedResources=<memory:3072, vCores:2>usedCapacity=0.0625, absoluteUsedCapacity=0.0625, numApps=1, numContainers=2 usedCapacity=0.0625 absoluteUsedCapacity=0.0625 used=<memory:3072, vCores:2> cluster=<memory:49152, vCores:96>
2013-08-17 06:34:41,874 INFO org.apache.hadoop.yarn.server.resourcemanager.scheduler.capacity.ParentQueue: Re-sorting queues since queue: root.default stats: default: capacity=1.0, absoluteCapacity=1.0, usedResources=<memory:4096, vCores:3>usedCapacity=0.083333336, absoluteUsedCapacity=0.083333336, numApps=1, numContainers=3
2013-08-17 06:34:41,874 INFO org.apache.hadoop.yarn.server.resourcemanager.scheduler.capacity.ParentQueue: assignedContainer queue=root usedCapacity=0.083333336 absoluteUsedCapacity=0.083333336 used=<memory:4096, vCores:3> cluster=<memory:49152, vCores:96>
2013-08-17 06:34:42,708 INFO org.apache.hadoop.yarn.server.resourcemanager.rmcontainer.RMContainerImpl: container_1376720997863_0003_01_000002 Container Transitioned from ALLOCATED to ACQUIRED
2013-08-17 06:34:42,710 INFO org.apache.hadoop.yarn.server.resourcemanager.rmcontainer.RMContainerImpl: container_1376720997863_0003_01_000003 Container Transitioned from ALLOCATED to ACQUIRED
2013-08-17 06:34:43,740 INFO org.apache.hadoop.yarn.server.resourcemanager.scheduler.AppSchedulingInfo: checking for deactivate... 
2013-08-17 06:34:43,891 INFO org.apache.hadoop.yarn.server.resourcemanager.rmcontainer.RMContainerImpl: container_1376720997863_0003_01_000003 Container Transitioned from ACQUIRED to RUNNING
2013-08-17 06:34:45,011 INFO org.apache.hadoop.yarn.server.resourcemanager.rmcontainer.RMContainerImpl: container_1376720997863_0003_01_000002 Container Transitioned from ACQUIRED to RUNNING
2013-08-17 06:36:20,151 INFO org.apache.hadoop.yarn.server.resourcemanager.rmcontainer.RMContainerImpl: container_1376720997863_0003_01_000003 Container Transitioned from RUNNING to COMPLETED
2013-08-17 06:36:20,152 INFO org.apache.hadoop.yarn.server.resourcemanager.scheduler.common.fica.FiCaSchedulerApp: Completed container: container_1376720997863_0003_01_000003 in state: COMPLETED event:FINISHED
2013-08-17 06:36:20,152 INFO org.apache.hadoop.yarn.server.resourcemanager.RMAuditLogger: USER=ubuntu	OPERATION=AM Released Container	TARGET=SchedulerApp	RESULT=SUCCESS	APPID=application_1376720997863_0003	CONTAINERID=container_1376720997863_0003_01_000003
2013-08-17 06:36:20,152 INFO org.apache.hadoop.yarn.server.resourcemanager.scheduler.common.fica.FiCaSchedulerNode: Released container container_1376720997863_0003_01_000003 of capacity <memory:1024, vCores:1> on host hadoop-512-2:32923, which currently has 1 containers, <memory:2048, vCores:1> used and <memory:6144, vCores:15> available, release resources=true
2013-08-17 06:36:20,152 INFO org.apache.hadoop.yarn.server.resourcemanager.scheduler.capacity.LeafQueue: default used=<memory:3072, vCores:2> numContainers=2 user=ubuntu user-resources=<memory:3072, vCores:2>
2013-08-17 06:36:20,154 INFO org.apache.hadoop.yarn.server.resourcemanager.scheduler.capacity.LeafQueue: completedContainer container=Container: [ContainerId: container_1376720997863_0003_01_000003, NodeId: hadoop-512-2:32923, NodeHttpAddress: hadoop-512-2:8042, Resource: <memory:1024, vCores:1>, Priority: 20, State: NEW, Token: null, Status: container_id {, app_attempt_id {, application_id {, id: 3, cluster_timestamp: 1376720997863, }, attemptId: 1, }, id: 3, }, state: C_COMPLETE, diagnostics: "Container killed by the ApplicationMaster.\n\n", exit_status: 143, ] resource=<memory:1024, vCores:1> queue=default: capacity=1.0, absoluteCapacity=1.0, usedResources=<memory:3072, vCores:2>usedCapacity=0.0625, absoluteUsedCapacity=0.0625, numApps=1, numContainers=2 usedCapacity=0.0625 absoluteUsedCapacity=0.0625 used=<memory:3072, vCores:2> cluster=<memory:49152, vCores:96>
2013-08-17 06:36:20,154 INFO org.apache.hadoop.yarn.server.resourcemanager.scheduler.capacity.ParentQueue: completedContainer queue=root usedCapacity=0.0625 absoluteUsedCapacity=0.0625 used=<memory:3072, vCores:2> cluster=<memory:49152, vCores:96>
2013-08-17 06:36:20,155 INFO org.apache.hadoop.yarn.server.resourcemanager.scheduler.capacity.CapacityScheduler: Application appattempt_1376720997863_0003_000001 released container container_1376720997863_0003_01_000003 on node: host: hadoop-512-2:32923 #containers=1 available=6144 used=2048 with event: FINISHED
2013-08-17 06:36:28,692 INFO org.apache.hadoop.yarn.server.resourcemanager.rmcontainer.RMContainerImpl: container_1376720997863_0003_01_000002 Container Transitioned from RUNNING to COMPLETED
2013-08-17 06:36:28,693 INFO org.apache.hadoop.yarn.server.resourcemanager.scheduler.common.fica.FiCaSchedulerApp: Completed container: container_1376720997863_0003_01_000002 in state: COMPLETED event:FINISHED
2013-08-17 06:36:28,693 INFO org.apache.hadoop.yarn.server.resourcemanager.RMAuditLogger: USER=ubuntu	OPERATION=AM Released Container	TARGET=SchedulerApp	RESULT=SUCCESS	APPID=application_1376720997863_0003	CONTAINERID=container_1376720997863_0003_01_000002
2013-08-17 06:36:28,693 INFO org.apache.hadoop.yarn.server.resourcemanager.scheduler.common.fica.FiCaSchedulerNode: Released container container_1376720997863_0003_01_000002 of capacity <memory:1024, vCores:1> on host hadoop-512-7:43914, which currently has 0 containers, <memory:0, vCores:0> used and <memory:8192, vCores:16> available, release resources=true
2013-08-17 06:36:28,693 INFO org.apache.hadoop.yarn.server.resourcemanager.scheduler.capacity.LeafQueue: default used=<memory:2048, vCores:1> numContainers=1 user=ubuntu user-resources=<memory:2048, vCores:1>
2013-08-17 06:36:28,695 INFO org.apache.hadoop.yarn.server.resourcemanager.scheduler.capacity.LeafQueue: completedContainer container=Container: [ContainerId: container_1376720997863_0003_01_000002, NodeId: hadoop-512-7:43914, NodeHttpAddress: hadoop-512-7:8042, Resource: <memory:1024, vCores:1>, Priority: 20, State: NEW, Token: null, Status: container_id {, app_attempt_id {, application_id {, id: 3, cluster_timestamp: 1376720997863, }, attemptId: 1, }, id: 2, }, state: C_COMPLETE, diagnostics: "Container killed by the ApplicationMaster.\n\n", exit_status: 143, ] resource=<memory:1024, vCores:1> queue=default: capacity=1.0, absoluteCapacity=1.0, usedResources=<memory:2048, vCores:1>usedCapacity=0.041666668, absoluteUsedCapacity=0.041666668, numApps=1, numContainers=1 usedCapacity=0.041666668 absoluteUsedCapacity=0.041666668 used=<memory:2048, vCores:1> cluster=<memory:49152, vCores:96>
2013-08-17 06:36:28,695 INFO org.apache.hadoop.yarn.server.resourcemanager.scheduler.capacity.ParentQueue: completedContainer queue=root usedCapacity=0.041666668 absoluteUsedCapacity=0.041666668 used=<memory:2048, vCores:1> cluster=<memory:49152, vCores:96>
2013-08-17 06:36:28,696 INFO org.apache.hadoop.yarn.server.resourcemanager.scheduler.capacity.CapacityScheduler: Application appattempt_1376720997863_0003_000001 released container container_1376720997863_0003_01_000002 on node: host: hadoop-512-7:43914 #containers=0 available=8192 used=0 with event: FINISHED
2013-08-17 06:36:32,864 INFO org.apache.hadoop.yarn.server.resourcemanager.rmapp.attempt.RMAppAttemptImpl: appattempt_1376720997863_0003_000001 State change from RUNNING to FINISHING
2013-08-17 06:36:32,865 INFO org.apache.hadoop.yarn.server.resourcemanager.rmapp.RMAppImpl: application_1376720997863_0003 State change from RUNNING to FINISHING
2013-08-17 06:36:33,214 INFO org.apache.hadoop.yarn.server.resourcemanager.rmcontainer.RMContainerImpl: container_1376720997863_0003_01_000001 Container Transitioned from RUNNING to COMPLETED
2013-08-17 06:36:33,214 INFO org.apache.hadoop.yarn.server.resourcemanager.scheduler.common.fica.FiCaSchedulerApp: Completed container: container_1376720997863_0003_01_000001 in state: COMPLETED event:FINISHED
2013-08-17 06:36:33,214 INFO org.apache.hadoop.yarn.server.resourcemanager.RMAuditLogger: USER=ubuntu	OPERATION=AM Released Container	TARGET=SchedulerApp	RESULT=SUCCESS	APPID=application_1376720997863_0003	CONTAINERID=container_1376720997863_0003_01_000001
2013-08-17 06:36:33,215 INFO org.apache.hadoop.yarn.server.resourcemanager.scheduler.common.fica.FiCaSchedulerNode: Released container container_1376720997863_0003_01_000001 of capacity <memory:2048, vCores:1> on host hadoop-512-2:32923, which currently has 0 containers, <memory:0, vCores:0> used and <memory:8192, vCores:16> available, release resources=true
2013-08-17 06:36:33,215 INFO org.apache.hadoop.yarn.server.resourcemanager.rmapp.attempt.RMAppAttemptImpl: appattempt_1376720997863_0003_000001 State change from FINISHING to FINISHED
2013-08-17 06:36:33,215 INFO org.apache.hadoop.yarn.server.resourcemanager.scheduler.capacity.LeafQueue: default used=<memory:0, vCores:0> numContainers=0 user=ubuntu user-resources=<memory:0, vCores:0>
2013-08-17 06:36:33,215 INFO org.apache.hadoop.yarn.server.resourcemanager.rmapp.RMAppImpl: application_1376720997863_0003 State change from FINISHING to FINISHED
2013-08-17 06:36:33,216 INFO org.apache.hadoop.yarn.server.resourcemanager.RMAuditLogger: USER=ubuntu	OPERATION=Application Finished - Succeeded	TARGET=RMAppManager	RESULT=SUCCESS	APPID=application_1376720997863_0003
2013-08-17 06:36:33,216 INFO org.apache.hadoop.yarn.server.resourcemanager.recovery.RMStateStore: Removing info for app: application_1376720997863_0003
2013-08-17 06:36:33,216 INFO org.apache.hadoop.yarn.server.resourcemanager.amlauncher.AMLauncher: Cleaning master appattempt_1376720997863_0003_000001
2013-08-17 06:36:33,217 INFO org.apache.hadoop.yarn.server.resourcemanager.scheduler.capacity.LeafQueue: completedContainer container=Container: [ContainerId: container_1376720997863_0003_01_000001, NodeId: hadoop-512-2:32923, NodeHttpAddress: hadoop-512-2:8042, Resource: <memory:2048, vCores:1>, Priority: 0, State: NEW, Token: null, Status: container_id {, app_attempt_id {, application_id {, id: 3, cluster_timestamp: 1376720997863, }, attemptId: 1, }, id: 1, }, state: C_COMPLETE, diagnostics: "", exit_status: 0, ] resource=<memory:2048, vCores:1> queue=default: capacity=1.0, absoluteCapacity=1.0, usedResources=<memory:0, vCores:0>usedCapacity=0.0, absoluteUsedCapacity=0.0, numApps=1, numContainers=0 usedCapacity=0.0 absoluteUsedCapacity=0.0 used=<memory:0, vCores:0> cluster=<memory:49152, vCores:96>
2013-08-17 06:36:33,217 INFO org.apache.hadoop.yarn.server.resourcemanager.RMAppManager$ApplicationSummary: appId=application_1376720997863_0003,name=TeraGen,user=ubuntu,queue=default,state=FINISHED,trackingUrl=hadoop-512-1.novalocal:8088/proxy/application_1376720997863_0003/jobhistory/job/job_1376720997863_0003,appMasterHost=hadoop-512-2,startTime=1376721269645,finishTime=1376721392865
2013-08-17 06:36:33,217 INFO org.apache.hadoop.yarn.server.resourcemanager.scheduler.capacity.ParentQueue: completedContainer queue=root usedCapacity=0.0 absoluteUsedCapacity=0.0 used=<memory:0, vCores:0> cluster=<memory:49152, vCores:96>
2013-08-17 06:36:33,223 INFO org.apache.hadoop.yarn.server.resourcemanager.scheduler.capacity.CapacityScheduler: Application appattempt_1376720997863_0003_000001 released container container_1376720997863_0003_01_000001 on node: host: hadoop-512-2:32923 #containers=0 available=8192 used=0 with event: FINISHED
2013-08-17 06:36:33,223 INFO org.apache.hadoop.yarn.server.resourcemanager.scheduler.capacity.CapacityScheduler: Application appattempt_1376720997863_0003_000001 is done. finalState=FINISHED
2013-08-17 06:36:33,227 INFO org.apache.hadoop.yarn.server.resourcemanager.scheduler.AppSchedulingInfo: Application application_1376720997863_0003 requests cleared
2013-08-17 06:36:33,227 INFO org.apache.hadoop.yarn.server.resourcemanager.scheduler.capacity.LeafQueue: Application removed - appId: application_1376720997863_0003 user: ubuntu queue: default #user-pending-applications: 0 #user-active-applications: 0 #queue-pending-applications: 0 #queue-active-applications: 0
2013-08-17 06:36:33,227 INFO org.apache.hadoop.yarn.server.resourcemanager.scheduler.capacity.ParentQueue: Application removed - appId: application_1376720997863_0003 user: ubuntu leaf-queue of parent: root #applications: 0
2013-08-17 06:36:33,737 INFO org.apache.hadoop.yarn.server.resourcemanager.ClientRMService: Allocated new applicationId: 4
2013-08-17 06:36:35,468 INFO org.apache.hadoop.yarn.server.resourcemanager.ClientRMService: Storing Application with id application_1376720997863_0004
2013-08-17 06:36:35,469 INFO org.apache.hadoop.yarn.server.resourcemanager.recovery.RMStateStore: Storing info for app: application_1376720997863_0004
2013-08-17 06:36:35,469 INFO org.apache.hadoop.yarn.server.resourcemanager.ClientRMService: Application with id 4 submitted by user ubuntu
2013-08-17 06:36:35,469 INFO org.apache.hadoop.yarn.server.resourcemanager.RMAuditLogger: USER=ubuntu	IP=192.168.100.5	OPERATION=Submit Application Request	TARGET=ClientRMService	RESULT=SUCCESS	APPID=application_1376720997863_0004
2013-08-17 06:36:35,471 INFO org.apache.hadoop.yarn.server.resourcemanager.rmapp.RMAppImpl: application_1376720997863_0004 State change from NEW to SUBMITTED
2013-08-17 06:36:35,471 INFO org.apache.hadoop.yarn.server.resourcemanager.ApplicationMasterService: Registering appattempt_1376720997863_0004_000001
2013-08-17 06:36:35,471 INFO org.apache.hadoop.yarn.server.resourcemanager.rmapp.attempt.RMAppAttemptImpl: appattempt_1376720997863_0004_000001 State change from NEW to SUBMITTED
2013-08-17 06:36:35,472 INFO org.apache.hadoop.yarn.server.resourcemanager.scheduler.capacity.LeafQueue: Application application_1376720997863_0004 from user: ubuntu activated in queue: default
2013-08-17 06:36:35,472 INFO org.apache.hadoop.yarn.server.resourcemanager.scheduler.capacity.LeafQueue: Application added - appId: application_1376720997863_0004 user: org.apache.hadoop.yarn.server.resourcemanager.scheduler.capacity.LeafQueue$User@d7e770, leaf-queue: default #user-pending-applications: 0 #user-active-applications: 1 #queue-pending-applications: 0 #queue-active-applications: 1
2013-08-17 06:36:35,472 INFO org.apache.hadoop.yarn.server.resourcemanager.scheduler.capacity.ParentQueue: Application added - appId: application_1376720997863_0004 user: ubuntu leaf-queue of parent: root #applications: 1
2013-08-17 06:36:35,472 INFO org.apache.hadoop.yarn.server.resourcemanager.scheduler.capacity.CapacityScheduler: Application Submission: appattempt_1376720997863_0004_000001, user: ubuntu queue: default: capacity=1.0, absoluteCapacity=1.0, usedResources=<memory:0, vCores:0>usedCapacity=0.0, absoluteUsedCapacity=0.0, numApps=1, numContainers=0, currently active: 1
2013-08-17 06:36:35,473 INFO org.apache.hadoop.yarn.server.resourcemanager.rmapp.attempt.RMAppAttemptImpl: appattempt_1376720997863_0004_000001 State change from SUBMITTED to SCHEDULED
2013-08-17 06:36:35,473 INFO org.apache.hadoop.yarn.server.resourcemanager.rmapp.RMAppImpl: application_1376720997863_0004 State change from SUBMITTED to ACCEPTED
2013-08-17 06:36:35,544 INFO org.apache.hadoop.yarn.server.resourcemanager.rmcontainer.RMContainerImpl: container_1376720997863_0004_01_000001 Container Transitioned from NEW to ALLOCATED
2013-08-17 06:36:35,545 INFO org.apache.hadoop.yarn.server.resourcemanager.RMAuditLogger: USER=ubuntu	OPERATION=AM Allocated Container	TARGET=SchedulerApp	RESULT=SUCCESS	APPID=application_1376720997863_0004	CONTAINERID=container_1376720997863_0004_01_000001
2013-08-17 06:36:35,545 INFO org.apache.hadoop.yarn.server.resourcemanager.scheduler.common.fica.FiCaSchedulerNode: Assigned container container_1376720997863_0004_01_000001 of capacity <memory:2048, vCores:1> on host hadoop-512-6:48301, which currently has 1 containers, <memory:2048, vCores:1> used and <memory:6144, vCores:15> available
2013-08-17 06:36:35,547 INFO org.apache.hadoop.yarn.server.resourcemanager.scheduler.capacity.LeafQueue: assignedContainer application=application_1376720997863_0004 container=Container: [ContainerId: container_1376720997863_0004_01_000001, NodeId: hadoop-512-6:48301, NodeHttpAddress: hadoop-512-6:8042, Resource: <memory:2048, vCores:1>, Priority: 0, State: NEW, Token: null, Status: container_id {, app_attempt_id {, application_id {, id: 4, cluster_timestamp: 1376720997863, }, attemptId: 1, }, id: 1, }, state: C_NEW, ] containerId=container_1376720997863_0004_01_000001 queue=default: capacity=1.0, absoluteCapacity=1.0, usedResources=<memory:0, vCores:0>usedCapacity=0.0, absoluteUsedCapacity=0.0, numApps=1, numContainers=0 usedCapacity=0.0 absoluteUsedCapacity=0.0 used=<memory:0, vCores:0> cluster=<memory:49152, vCores:96>
2013-08-17 06:36:35,547 INFO org.apache.hadoop.yarn.server.resourcemanager.scheduler.capacity.ParentQueue: Re-sorting queues since queue: root.default stats: default: capacity=1.0, absoluteCapacity=1.0, usedResources=<memory:2048, vCores:1>usedCapacity=0.041666668, absoluteUsedCapacity=0.041666668, numApps=1, numContainers=1
2013-08-17 06:36:35,547 INFO org.apache.hadoop.yarn.server.resourcemanager.scheduler.capacity.ParentQueue: assignedContainer queue=root usedCapacity=0.041666668 absoluteUsedCapacity=0.041666668 used=<memory:2048, vCores:1> cluster=<memory:49152, vCores:96>
2013-08-17 06:36:35,549 INFO org.apache.hadoop.yarn.server.resourcemanager.rmcontainer.RMContainerImpl: container_1376720997863_0004_01_000001 Container Transitioned from ALLOCATED to ACQUIRED
2013-08-17 06:36:35,551 INFO org.apache.hadoop.yarn.server.resourcemanager.rmapp.attempt.RMAppAttemptImpl: Storing attempt: AppId: application_1376720997863_0004 AttemptId: appattempt_1376720997863_0004_000001 MasterContainer: Container: [ContainerId: container_1376720997863_0004_01_000001, NodeId: hadoop-512-6:48301, NodeHttpAddress: hadoop-512-6:8042, Resource: <memory:2048, vCores:1>, Priority: 0, State: NEW, Token: null, Status: container_id {, app_attempt_id {, application_id {, id: 4, cluster_timestamp: 1376720997863, }, attemptId: 1, }, id: 1, }, state: C_NEW, ]
2013-08-17 06:36:35,551 INFO org.apache.hadoop.yarn.server.resourcemanager.recovery.RMStateStore: Storing info for attempt: appattempt_1376720997863_0004_000001
2013-08-17 06:36:35,552 INFO org.apache.hadoop.yarn.server.resourcemanager.rmapp.attempt.RMAppAttemptImpl: appattempt_1376720997863_0004_000001 State change from SCHEDULED to ALLOCATED_SAVING
2013-08-17 06:36:35,554 INFO org.apache.hadoop.yarn.server.resourcemanager.rmapp.attempt.RMAppAttemptImpl: appattempt_1376720997863_0004_000001 State change from ALLOCATED_SAVING to ALLOCATED
2013-08-17 06:36:35,555 INFO org.apache.hadoop.yarn.server.resourcemanager.amlauncher.AMLauncher: Launching masterappattempt_1376720997863_0004_000001
2013-08-17 06:36:35,559 INFO org.apache.hadoop.yarn.server.resourcemanager.amlauncher.AMLauncher: Setting up container Container: [ContainerId: container_1376720997863_0004_01_000001, NodeId: hadoop-512-6:48301, NodeHttpAddress: hadoop-512-6:8042, Resource: <memory:2048, vCores:1>, Priority: 0, State: NEW, Token: null, Status: container_id {, app_attempt_id {, application_id {, id: 4, cluster_timestamp: 1376720997863, }, attemptId: 1, }, id: 1, }, state: C_NEW, ] for AM appattempt_1376720997863_0004_000001
2013-08-17 06:36:35,559 INFO org.apache.hadoop.yarn.server.resourcemanager.amlauncher.AMLauncher: Command to launch container container_1376720997863_0004_01_000001 : $JAVA_HOME/bin/java -Dlog4j.configuration=container-log4j.properties -Dyarn.app.mapreduce.container.log.dir=<LOG_DIR> -Dyarn.app.mapreduce.container.log.filesize=0 -Dhadoop.root.logger=INFO,CLA  -Xmx1024m org.apache.hadoop.mapreduce.v2.app.MRAppMaster 1><LOG_DIR>/stdout 2><LOG_DIR>/stderr 
2013-08-17 06:36:35,580 INFO org.apache.hadoop.yarn.server.resourcemanager.amlauncher.AMLauncher: Done launching container Container: [ContainerId: container_1376720997863_0004_01_000001, NodeId: hadoop-512-6:48301, NodeHttpAddress: hadoop-512-6:8042, Resource: <memory:2048, vCores:1>, Priority: 0, State: NEW, Token: null, Status: container_id {, app_attempt_id {, application_id {, id: 4, cluster_timestamp: 1376720997863, }, attemptId: 1, }, id: 1, }, state: C_NEW, ] for AM appattempt_1376720997863_0004_000001
2013-08-17 06:36:35,580 INFO org.apache.hadoop.yarn.server.resourcemanager.rmapp.attempt.RMAppAttemptImpl: appattempt_1376720997863_0004_000001 State change from ALLOCATED to LAUNCHED
2013-08-17 06:36:36,551 INFO org.apache.hadoop.yarn.server.resourcemanager.rmcontainer.RMContainerImpl: container_1376720997863_0004_01_000001 Container Transitioned from ACQUIRED to RUNNING
2013-08-17 06:36:41,156 INFO org.apache.hadoop.yarn.server.resourcemanager.ApplicationMasterService: AM registration appattempt_1376720997863_0004_000001
2013-08-17 06:36:41,157 INFO org.apache.hadoop.yarn.server.resourcemanager.RMAuditLogger: USER=ubuntu	IP=192.168.100.31	OPERATION=Register App Master	TARGET=ApplicationMasterService	RESULT=SUCCESS	APPID=application_1376720997863_0004	APPATTEMPTID=appattempt_1376720997863_0004_000001
2013-08-17 06:36:41,157 INFO org.apache.hadoop.yarn.server.resourcemanager.rmapp.attempt.RMAppAttemptImpl: appattempt_1376720997863_0004_000001 State change from LAUNCHED to RUNNING
2013-08-17 06:36:41,158 INFO org.apache.hadoop.yarn.server.resourcemanager.rmapp.RMAppImpl: application_1376720997863_0004 State change from ACCEPTED to RUNNING
2013-08-17 06:36:42,250 INFO org.apache.hadoop.yarn.server.resourcemanager.rmcontainer.RMContainerImpl: container_1376720997863_0004_01_000002 Container Transitioned from NEW to ALLOCATED
2013-08-17 06:36:42,250 INFO org.apache.hadoop.yarn.server.resourcemanager.RMAuditLogger: USER=ubuntu	OPERATION=AM Allocated Container	TARGET=SchedulerApp	RESULT=SUCCESS	APPID=application_1376720997863_0004	CONTAINERID=container_1376720997863_0004_01_000002
2013-08-17 06:36:42,250 INFO org.apache.hadoop.yarn.server.resourcemanager.scheduler.common.fica.FiCaSchedulerNode: Assigned container container_1376720997863_0004_01_000002 of capacity <memory:1024, vCores:1> on host hadoop-512-2:32923, which currently has 1 containers, <memory:1024, vCores:1> used and <memory:7168, vCores:15> available
2013-08-17 06:36:42,252 INFO org.apache.hadoop.yarn.server.resourcemanager.scheduler.capacity.LeafQueue: assignedContainer application=application_1376720997863_0004 container=Container: [ContainerId: container_1376720997863_0004_01_000002, NodeId: hadoop-512-2:32923, NodeHttpAddress: hadoop-512-2:8042, Resource: <memory:1024, vCores:1>, Priority: 20, State: NEW, Token: null, Status: container_id {, app_attempt_id {, application_id {, id: 4, cluster_timestamp: 1376720997863, }, attemptId: 1, }, id: 2, }, state: C_NEW, ] containerId=container_1376720997863_0004_01_000002 queue=default: capacity=1.0, absoluteCapacity=1.0, usedResources=<memory:2048, vCores:1>usedCapacity=0.041666668, absoluteUsedCapacity=0.041666668, numApps=1, numContainers=1 usedCapacity=0.041666668 absoluteUsedCapacity=0.041666668 used=<memory:2048, vCores:1> cluster=<memory:49152, vCores:96>
2013-08-17 06:36:42,252 INFO org.apache.hadoop.yarn.server.resourcemanager.scheduler.capacity.ParentQueue: Re-sorting queues since queue: root.default stats: default: capacity=1.0, absoluteCapacity=1.0, usedResources=<memory:3072, vCores:2>usedCapacity=0.0625, absoluteUsedCapacity=0.0625, numApps=1, numContainers=2
2013-08-17 06:36:42,252 INFO org.apache.hadoop.yarn.server.resourcemanager.scheduler.capacity.ParentQueue: assignedContainer queue=root usedCapacity=0.0625 absoluteUsedCapacity=0.0625 used=<memory:3072, vCores:2> cluster=<memory:49152, vCores:96>
2013-08-17 06:36:42,636 INFO org.apache.hadoop.yarn.server.resourcemanager.rmcontainer.RMContainerImpl: container_1376720997863_0004_01_000003 Container Transitioned from NEW to ALLOCATED
2013-08-17 06:36:42,636 INFO org.apache.hadoop.yarn.server.resourcemanager.RMAuditLogger: USER=ubuntu	OPERATION=AM Allocated Container	TARGET=SchedulerApp	RESULT=SUCCESS	APPID=application_1376720997863_0004	CONTAINERID=container_1376720997863_0004_01_000003
2013-08-17 06:36:42,636 INFO org.apache.hadoop.yarn.server.resourcemanager.scheduler.common.fica.FiCaSchedulerNode: Assigned container container_1376720997863_0004_01_000003 of capacity <memory:1024, vCores:1> on host hadoop-512-6:48301, which currently has 2 containers, <memory:3072, vCores:2> used and <memory:5120, vCores:14> available
2013-08-17 06:36:42,638 INFO org.apache.hadoop.yarn.server.resourcemanager.scheduler.capacity.LeafQueue: assignedContainer application=application_1376720997863_0004 container=Container: [ContainerId: container_1376720997863_0004_01_000003, NodeId: hadoop-512-6:48301, NodeHttpAddress: hadoop-512-6:8042, Resource: <memory:1024, vCores:1>, Priority: 20, State: NEW, Token: null, Status: container_id {, app_attempt_id {, application_id {, id: 4, cluster_timestamp: 1376720997863, }, attemptId: 1, }, id: 3, }, state: C_NEW, ] containerId=container_1376720997863_0004_01_000003 queue=default: capacity=1.0, absoluteCapacity=1.0, usedResources=<memory:3072, vCores:2>usedCapacity=0.0625, absoluteUsedCapacity=0.0625, numApps=1, numContainers=2 usedCapacity=0.0625 absoluteUsedCapacity=0.0625 used=<memory:3072, vCores:2> cluster=<memory:49152, vCores:96>
2013-08-17 06:36:42,638 INFO org.apache.hadoop.yarn.server.resourcemanager.scheduler.capacity.ParentQueue: Re-sorting queues since queue: root.default stats: default: capacity=1.0, absoluteCapacity=1.0, usedResources=<memory:4096, vCores:3>usedCapacity=0.083333336, absoluteUsedCapacity=0.083333336, numApps=1, numContainers=3
2013-08-17 06:36:42,638 INFO org.apache.hadoop.yarn.server.resourcemanager.scheduler.capacity.ParentQueue: assignedContainer queue=root usedCapacity=0.083333336 absoluteUsedCapacity=0.083333336 used=<memory:4096, vCores:3> cluster=<memory:49152, vCores:96>
2013-08-17 06:36:43,221 INFO org.apache.hadoop.yarn.server.resourcemanager.rmcontainer.RMContainerImpl: container_1376720997863_0004_01_000002 Container Transitioned from ALLOCATED to ACQUIRED
2013-08-17 06:36:43,222 INFO org.apache.hadoop.yarn.server.resourcemanager.rmcontainer.RMContainerImpl: container_1376720997863_0004_01_000003 Container Transitioned from ALLOCATED to ACQUIRED
2013-08-17 06:36:43,642 INFO org.apache.hadoop.yarn.server.resourcemanager.rmcontainer.RMContainerImpl: container_1376720997863_0004_01_000003 Container Transitioned from ACQUIRED to RUNNING
2013-08-17 06:36:44,248 INFO org.apache.hadoop.yarn.server.resourcemanager.scheduler.AppSchedulingInfo: checking for deactivate... 
2013-08-17 06:36:44,258 INFO org.apache.hadoop.yarn.server.resourcemanager.rmcontainer.RMContainerImpl: container_1376720997863_0004_01_000002 Container Transitioned from ACQUIRED to RUNNING
2013-08-17 06:38:30,538 INFO org.apache.hadoop.yarn.server.resourcemanager.rmcontainer.RMContainerImpl: container_1376720997863_0004_01_000003 Container Transitioned from RUNNING to COMPLETED
2013-08-17 06:38:30,539 INFO org.apache.hadoop.yarn.server.resourcemanager.scheduler.common.fica.FiCaSchedulerApp: Completed container: container_1376720997863_0004_01_000003 in state: COMPLETED event:FINISHED
2013-08-17 06:38:30,539 INFO org.apache.hadoop.yarn.server.resourcemanager.RMAuditLogger: USER=ubuntu	OPERATION=AM Released Container	TARGET=SchedulerApp	RESULT=SUCCESS	APPID=application_1376720997863_0004	CONTAINERID=container_1376720997863_0004_01_000003
2013-08-17 06:38:30,539 INFO org.apache.hadoop.yarn.server.resourcemanager.scheduler.common.fica.FiCaSchedulerNode: Released container container_1376720997863_0004_01_000003 of capacity <memory:1024, vCores:1> on host hadoop-512-6:48301, which currently has 1 containers, <memory:2048, vCores:1> used and <memory:6144, vCores:15> available, release resources=true
2013-08-17 06:38:30,539 INFO org.apache.hadoop.yarn.server.resourcemanager.scheduler.capacity.LeafQueue: default used=<memory:3072, vCores:2> numContainers=2 user=ubuntu user-resources=<memory:3072, vCores:2>
2013-08-17 06:38:30,541 INFO org.apache.hadoop.yarn.server.resourcemanager.scheduler.capacity.LeafQueue: completedContainer container=Container: [ContainerId: container_1376720997863_0004_01_000003, NodeId: hadoop-512-6:48301, NodeHttpAddress: hadoop-512-6:8042, Resource: <memory:1024, vCores:1>, Priority: 20, State: NEW, Token: null, Status: container_id {, app_attempt_id {, application_id {, id: 4, cluster_timestamp: 1376720997863, }, attemptId: 1, }, id: 3, }, state: C_COMPLETE, diagnostics: "Container killed by the ApplicationMaster.\n\n", exit_status: 143, ] resource=<memory:1024, vCores:1> queue=default: capacity=1.0, absoluteCapacity=1.0, usedResources=<memory:3072, vCores:2>usedCapacity=0.0625, absoluteUsedCapacity=0.0625, numApps=1, numContainers=2 usedCapacity=0.0625 absoluteUsedCapacity=0.0625 used=<memory:3072, vCores:2> cluster=<memory:49152, vCores:96>
2013-08-17 06:38:30,541 INFO org.apache.hadoop.yarn.server.resourcemanager.scheduler.capacity.ParentQueue: completedContainer queue=root usedCapacity=0.0625 absoluteUsedCapacity=0.0625 used=<memory:3072, vCores:2> cluster=<memory:49152, vCores:96>
2013-08-17 06:38:30,541 INFO org.apache.hadoop.yarn.server.resourcemanager.scheduler.capacity.CapacityScheduler: Application appattempt_1376720997863_0004_000001 released container container_1376720997863_0004_01_000003 on node: host: hadoop-512-6:48301 #containers=1 available=6144 used=2048 with event: FINISHED
2013-08-17 06:38:30,578 INFO org.apache.hadoop.yarn.server.resourcemanager.rmcontainer.RMContainerImpl: container_1376720997863_0004_01_000002 Container Transitioned from RUNNING to COMPLETED
2013-08-17 06:38:30,578 INFO org.apache.hadoop.yarn.server.resourcemanager.scheduler.common.fica.FiCaSchedulerApp: Completed container: container_1376720997863_0004_01_000002 in state: COMPLETED event:FINISHED
2013-08-17 06:38:30,579 INFO org.apache.hadoop.yarn.server.resourcemanager.RMAuditLogger: USER=ubuntu	OPERATION=AM Released Container	TARGET=SchedulerApp	RESULT=SUCCESS	APPID=application_1376720997863_0004	CONTAINERID=container_1376720997863_0004_01_000002
2013-08-17 06:38:30,579 INFO org.apache.hadoop.yarn.server.resourcemanager.scheduler.common.fica.FiCaSchedulerNode: Released container container_1376720997863_0004_01_000002 of capacity <memory:1024, vCores:1> on host hadoop-512-2:32923, which currently has 0 containers, <memory:0, vCores:0> used and <memory:8192, vCores:16> available, release resources=true
2013-08-17 06:38:30,579 INFO org.apache.hadoop.yarn.server.resourcemanager.scheduler.capacity.LeafQueue: default used=<memory:2048, vCores:1> numContainers=1 user=ubuntu user-resources=<memory:2048, vCores:1>
2013-08-17 06:38:30,581 INFO org.apache.hadoop.yarn.server.resourcemanager.scheduler.capacity.LeafQueue: completedContainer container=Container: [ContainerId: container_1376720997863_0004_01_000002, NodeId: hadoop-512-2:32923, NodeHttpAddress: hadoop-512-2:8042, Resource: <memory:1024, vCores:1>, Priority: 20, State: NEW, Token: null, Status: container_id {, app_attempt_id {, application_id {, id: 4, cluster_timestamp: 1376720997863, }, attemptId: 1, }, id: 2, }, state: C_COMPLETE, diagnostics: "Container killed by the ApplicationMaster.\n\n", exit_status: 143, ] resource=<memory:1024, vCores:1> queue=default: capacity=1.0, absoluteCapacity=1.0, usedResources=<memory:2048, vCores:1>usedCapacity=0.041666668, absoluteUsedCapacity=0.041666668, numApps=1, numContainers=1 usedCapacity=0.041666668 absoluteUsedCapacity=0.041666668 used=<memory:2048, vCores:1> cluster=<memory:49152, vCores:96>
2013-08-17 06:38:30,581 INFO org.apache.hadoop.yarn.server.resourcemanager.scheduler.capacity.ParentQueue: completedContainer queue=root usedCapacity=0.041666668 absoluteUsedCapacity=0.041666668 used=<memory:2048, vCores:1> cluster=<memory:49152, vCores:96>
2013-08-17 06:38:30,581 INFO org.apache.hadoop.yarn.server.resourcemanager.scheduler.capacity.CapacityScheduler: Application appattempt_1376720997863_0004_000001 released container container_1376720997863_0004_01_000002 on node: host: hadoop-512-2:32923 #containers=0 available=8192 used=0 with event: FINISHED
2013-08-17 06:38:34,759 INFO org.apache.hadoop.yarn.server.resourcemanager.rmapp.attempt.RMAppAttemptImpl: appattempt_1376720997863_0004_000001 State change from RUNNING to FINISHING
2013-08-17 06:38:34,759 INFO org.apache.hadoop.yarn.server.resourcemanager.rmapp.RMAppImpl: application_1376720997863_0004 State change from RUNNING to FINISHING
2013-08-17 06:38:35,563 INFO org.apache.hadoop.yarn.server.resourcemanager.rmcontainer.RMContainerImpl: container_1376720997863_0004_01_000001 Container Transitioned from RUNNING to COMPLETED
2013-08-17 06:38:35,564 INFO org.apache.hadoop.yarn.server.resourcemanager.scheduler.common.fica.FiCaSchedulerApp: Completed container: container_1376720997863_0004_01_000001 in state: COMPLETED event:FINISHED
2013-08-17 06:38:35,564 INFO org.apache.hadoop.yarn.server.resourcemanager.RMAuditLogger: USER=ubuntu	OPERATION=AM Released Container	TARGET=SchedulerApp	RESULT=SUCCESS	APPID=application_1376720997863_0004	CONTAINERID=container_1376720997863_0004_01_000001
2013-08-17 06:38:35,564 INFO org.apache.hadoop.yarn.server.resourcemanager.scheduler.common.fica.FiCaSchedulerNode: Released container container_1376720997863_0004_01_000001 of capacity <memory:2048, vCores:1> on host hadoop-512-6:48301, which currently has 0 containers, <memory:0, vCores:0> used and <memory:8192, vCores:16> available, release resources=true
2013-08-17 06:38:35,564 INFO org.apache.hadoop.yarn.server.resourcemanager.scheduler.capacity.LeafQueue: default used=<memory:0, vCores:0> numContainers=0 user=ubuntu user-resources=<memory:0, vCores:0>
2013-08-17 06:38:35,566 INFO org.apache.hadoop.yarn.server.resourcemanager.scheduler.capacity.LeafQueue: completedContainer container=Container: [ContainerId: container_1376720997863_0004_01_000001, NodeId: hadoop-512-6:48301, NodeHttpAddress: hadoop-512-6:8042, Resource: <memory:2048, vCores:1>, Priority: 0, State: NEW, Token: null, Status: container_id {, app_attempt_id {, application_id {, id: 4, cluster_timestamp: 1376720997863, }, attemptId: 1, }, id: 1, }, state: C_COMPLETE, diagnostics: "", exit_status: 0, ] resource=<memory:2048, vCores:1> queue=default: capacity=1.0, absoluteCapacity=1.0, usedResources=<memory:0, vCores:0>usedCapacity=0.0, absoluteUsedCapacity=0.0, numApps=1, numContainers=0 usedCapacity=0.0 absoluteUsedCapacity=0.0 used=<memory:0, vCores:0> cluster=<memory:49152, vCores:96>
2013-08-17 06:38:35,566 INFO org.apache.hadoop.yarn.server.resourcemanager.scheduler.capacity.ParentQueue: completedContainer queue=root usedCapacity=0.0 absoluteUsedCapacity=0.0 used=<memory:0, vCores:0> cluster=<memory:49152, vCores:96>
2013-08-17 06:38:35,566 INFO org.apache.hadoop.yarn.server.resourcemanager.scheduler.capacity.CapacityScheduler: Application appattempt_1376720997863_0004_000001 released container container_1376720997863_0004_01_000001 on node: host: hadoop-512-6:48301 #containers=0 available=8192 used=0 with event: FINISHED
2013-08-17 06:38:35,566 INFO org.apache.hadoop.yarn.server.resourcemanager.rmapp.attempt.RMAppAttemptImpl: appattempt_1376720997863_0004_000001 State change from FINISHING to FINISHED
2013-08-17 06:38:35,567 INFO org.apache.hadoop.yarn.server.resourcemanager.rmapp.RMAppImpl: application_1376720997863_0004 State change from FINISHING to FINISHED
2013-08-17 06:38:35,567 INFO org.apache.hadoop.yarn.server.resourcemanager.scheduler.capacity.CapacityScheduler: Application appattempt_1376720997863_0004_000001 is done. finalState=FINISHED
2013-08-17 06:38:35,567 INFO org.apache.hadoop.yarn.server.resourcemanager.scheduler.AppSchedulingInfo: Application application_1376720997863_0004 requests cleared
2013-08-17 06:38:35,568 INFO org.apache.hadoop.yarn.server.resourcemanager.scheduler.capacity.LeafQueue: Application removed - appId: application_1376720997863_0004 user: ubuntu queue: default #user-pending-applications: 0 #user-active-applications: 0 #queue-pending-applications: 0 #queue-active-applications: 0
2013-08-17 06:38:35,568 INFO org.apache.hadoop.yarn.server.resourcemanager.scheduler.capacity.ParentQueue: Application removed - appId: application_1376720997863_0004 user: ubuntu leaf-queue of parent: root #applications: 0
2013-08-17 06:38:35,568 INFO org.apache.hadoop.yarn.server.resourcemanager.RMAuditLogger: USER=ubuntu	OPERATION=Application Finished - Succeeded	TARGET=RMAppManager	RESULT=SUCCESS	APPID=application_1376720997863_0004
2013-08-17 06:38:35,569 INFO org.apache.hadoop.yarn.server.resourcemanager.recovery.RMStateStore: Removing info for app: application_1376720997863_0004
2013-08-17 06:38:35,569 INFO org.apache.hadoop.yarn.server.resourcemanager.RMAppManager$ApplicationSummary: appId=application_1376720997863_0004,name=TeraGen,user=ubuntu,queue=default,state=FINISHED,trackingUrl=hadoop-512-1.novalocal:8088/proxy/application_1376720997863_0004/jobhistory/job/job_1376720997863_0004,appMasterHost=hadoop-512-6,startTime=1376721395468,finishTime=1376721514759
2013-08-17 06:38:35,569 INFO org.apache.hadoop.yarn.server.resourcemanager.amlauncher.AMLauncher: Cleaning master appattempt_1376720997863_0004_000001
2013-08-17 06:38:36,651 INFO org.apache.hadoop.yarn.server.resourcemanager.ClientRMService: Allocated new applicationId: 5
2013-08-17 06:38:38,516 INFO org.apache.hadoop.yarn.server.resourcemanager.ClientRMService: Storing Application with id application_1376720997863_0005
2013-08-17 06:38:38,516 INFO org.apache.hadoop.yarn.server.resourcemanager.recovery.RMStateStore: Storing info for app: application_1376720997863_0005
2013-08-17 06:38:38,517 INFO org.apache.hadoop.yarn.server.resourcemanager.ClientRMService: Application with id 5 submitted by user ubuntu
2013-08-17 06:38:38,517 INFO org.apache.hadoop.yarn.server.resourcemanager.RMAuditLogger: USER=ubuntu	IP=192.168.100.5	OPERATION=Submit Application Request	TARGET=ClientRMService	RESULT=SUCCESS	APPID=application_1376720997863_0005
2013-08-17 06:38:38,519 INFO org.apache.hadoop.yarn.server.resourcemanager.rmapp.RMAppImpl: application_1376720997863_0005 State change from NEW to SUBMITTED
2013-08-17 06:38:38,519 INFO org.apache.hadoop.yarn.server.resourcemanager.ApplicationMasterService: Registering appattempt_1376720997863_0005_000001
2013-08-17 06:38:38,520 INFO org.apache.hadoop.yarn.server.resourcemanager.rmapp.attempt.RMAppAttemptImpl: appattempt_1376720997863_0005_000001 State change from NEW to SUBMITTED
2013-08-17 06:38:38,520 INFO org.apache.hadoop.yarn.server.resourcemanager.scheduler.capacity.LeafQueue: Application application_1376720997863_0005 from user: ubuntu activated in queue: default
2013-08-17 06:38:38,521 INFO org.apache.hadoop.yarn.server.resourcemanager.scheduler.capacity.LeafQueue: Application added - appId: application_1376720997863_0005 user: org.apache.hadoop.yarn.server.resourcemanager.scheduler.capacity.LeafQueue$User@1695bffd, leaf-queue: default #user-pending-applications: 0 #user-active-applications: 1 #queue-pending-applications: 0 #queue-active-applications: 1
2013-08-17 06:38:38,521 INFO org.apache.hadoop.yarn.server.resourcemanager.scheduler.capacity.ParentQueue: Application added - appId: application_1376720997863_0005 user: ubuntu leaf-queue of parent: root #applications: 1
2013-08-17 06:38:38,521 INFO org.apache.hadoop.yarn.server.resourcemanager.scheduler.capacity.CapacityScheduler: Application Submission: appattempt_1376720997863_0005_000001, user: ubuntu queue: default: capacity=1.0, absoluteCapacity=1.0, usedResources=<memory:0, vCores:0>usedCapacity=0.0, absoluteUsedCapacity=0.0, numApps=1, numContainers=0, currently active: 1
2013-08-17 06:38:38,521 INFO org.apache.hadoop.yarn.server.resourcemanager.rmapp.attempt.RMAppAttemptImpl: appattempt_1376720997863_0005_000001 State change from SUBMITTED to SCHEDULED
2013-08-17 06:38:38,522 INFO org.apache.hadoop.yarn.server.resourcemanager.rmapp.RMAppImpl: application_1376720997863_0005 State change from SUBMITTED to ACCEPTED
2013-08-17 06:38:38,574 INFO org.apache.hadoop.yarn.server.resourcemanager.rmcontainer.RMContainerImpl: container_1376720997863_0005_01_000001 Container Transitioned from NEW to ALLOCATED
2013-08-17 06:38:38,575 INFO org.apache.hadoop.yarn.server.resourcemanager.RMAuditLogger: USER=ubuntu	OPERATION=AM Allocated Container	TARGET=SchedulerApp	RESULT=SUCCESS	APPID=application_1376720997863_0005	CONTAINERID=container_1376720997863_0005_01_000001
2013-08-17 06:38:38,575 INFO org.apache.hadoop.yarn.server.resourcemanager.scheduler.common.fica.FiCaSchedulerNode: Assigned container container_1376720997863_0005_01_000001 of capacity <memory:2048, vCores:1> on host hadoop-512-6:48301, which currently has 1 containers, <memory:2048, vCores:1> used and <memory:6144, vCores:15> available
2013-08-17 06:38:38,576 INFO org.apache.hadoop.yarn.server.resourcemanager.scheduler.capacity.LeafQueue: assignedContainer application=application_1376720997863_0005 container=Container: [ContainerId: container_1376720997863_0005_01_000001, NodeId: hadoop-512-6:48301, NodeHttpAddress: hadoop-512-6:8042, Resource: <memory:2048, vCores:1>, Priority: 0, State: NEW, Token: null, Status: container_id {, app_attempt_id {, application_id {, id: 5, cluster_timestamp: 1376720997863, }, attemptId: 1, }, id: 1, }, state: C_NEW, ] containerId=container_1376720997863_0005_01_000001 queue=default: capacity=1.0, absoluteCapacity=1.0, usedResources=<memory:0, vCores:0>usedCapacity=0.0, absoluteUsedCapacity=0.0, numApps=1, numContainers=0 usedCapacity=0.0 absoluteUsedCapacity=0.0 used=<memory:0, vCores:0> cluster=<memory:49152, vCores:96>
2013-08-17 06:38:38,576 INFO org.apache.hadoop.yarn.server.resourcemanager.scheduler.capacity.ParentQueue: Re-sorting queues since queue: root.default stats: default: capacity=1.0, absoluteCapacity=1.0, usedResources=<memory:2048, vCores:1>usedCapacity=0.041666668, absoluteUsedCapacity=0.041666668, numApps=1, numContainers=1
2013-08-17 06:38:38,577 INFO org.apache.hadoop.yarn.server.resourcemanager.scheduler.capacity.ParentQueue: assignedContainer queue=root usedCapacity=0.041666668 absoluteUsedCapacity=0.041666668 used=<memory:2048, vCores:1> cluster=<memory:49152, vCores:96>
2013-08-17 06:38:38,578 INFO org.apache.hadoop.yarn.server.resourcemanager.rmcontainer.RMContainerImpl: container_1376720997863_0005_01_000001 Container Transitioned from ALLOCATED to ACQUIRED
2013-08-17 06:38:38,579 INFO org.apache.hadoop.yarn.server.resourcemanager.rmapp.attempt.RMAppAttemptImpl: Storing attempt: AppId: application_1376720997863_0005 AttemptId: appattempt_1376720997863_0005_000001 MasterContainer: Container: [ContainerId: container_1376720997863_0005_01_000001, NodeId: hadoop-512-6:48301, NodeHttpAddress: hadoop-512-6:8042, Resource: <memory:2048, vCores:1>, Priority: 0, State: NEW, Token: null, Status: container_id {, app_attempt_id {, application_id {, id: 5, cluster_timestamp: 1376720997863, }, attemptId: 1, }, id: 1, }, state: C_NEW, ]
2013-08-17 06:38:38,579 INFO org.apache.hadoop.yarn.server.resourcemanager.rmapp.attempt.RMAppAttemptImpl: appattempt_1376720997863_0005_000001 State change from SCHEDULED to ALLOCATED_SAVING
2013-08-17 06:38:38,579 INFO org.apache.hadoop.yarn.server.resourcemanager.recovery.RMStateStore: Storing info for attempt: appattempt_1376720997863_0005_000001
2013-08-17 06:38:38,581 INFO org.apache.hadoop.yarn.server.resourcemanager.rmapp.attempt.RMAppAttemptImpl: appattempt_1376720997863_0005_000001 State change from ALLOCATED_SAVING to ALLOCATED
2013-08-17 06:38:38,582 INFO org.apache.hadoop.yarn.server.resourcemanager.amlauncher.AMLauncher: Launching masterappattempt_1376720997863_0005_000001
2013-08-17 06:38:38,585 INFO org.apache.hadoop.yarn.server.resourcemanager.amlauncher.AMLauncher: Setting up container Container: [ContainerId: container_1376720997863_0005_01_000001, NodeId: hadoop-512-6:48301, NodeHttpAddress: hadoop-512-6:8042, Resource: <memory:2048, vCores:1>, Priority: 0, State: NEW, Token: null, Status: container_id {, app_attempt_id {, application_id {, id: 5, cluster_timestamp: 1376720997863, }, attemptId: 1, }, id: 1, }, state: C_NEW, ] for AM appattempt_1376720997863_0005_000001
2013-08-17 06:38:38,585 INFO org.apache.hadoop.yarn.server.resourcemanager.amlauncher.AMLauncher: Command to launch container container_1376720997863_0005_01_000001 : $JAVA_HOME/bin/java -Dlog4j.configuration=container-log4j.properties -Dyarn.app.mapreduce.container.log.dir=<LOG_DIR> -Dyarn.app.mapreduce.container.log.filesize=0 -Dhadoop.root.logger=INFO,CLA  -Xmx1024m org.apache.hadoop.mapreduce.v2.app.MRAppMaster 1><LOG_DIR>/stdout 2><LOG_DIR>/stderr 
2013-08-17 06:38:38,606 INFO org.apache.hadoop.yarn.server.resourcemanager.amlauncher.AMLauncher: Done launching container Container: [ContainerId: container_1376720997863_0005_01_000001, NodeId: hadoop-512-6:48301, NodeHttpAddress: hadoop-512-6:8042, Resource: <memory:2048, vCores:1>, Priority: 0, State: NEW, Token: null, Status: container_id {, app_attempt_id {, application_id {, id: 5, cluster_timestamp: 1376720997863, }, attemptId: 1, }, id: 1, }, state: C_NEW, ] for AM appattempt_1376720997863_0005_000001
2013-08-17 06:38:38,606 INFO org.apache.hadoop.yarn.server.resourcemanager.rmapp.attempt.RMAppAttemptImpl: appattempt_1376720997863_0005_000001 State change from ALLOCATED to LAUNCHED
2013-08-17 06:38:39,580 INFO org.apache.hadoop.yarn.server.resourcemanager.rmcontainer.RMContainerImpl: container_1376720997863_0005_01_000001 Container Transitioned from ACQUIRED to RUNNING
2013-08-17 06:38:44,671 INFO org.apache.hadoop.yarn.server.resourcemanager.ApplicationMasterService: AM registration appattempt_1376720997863_0005_000001
2013-08-17 06:38:44,671 INFO org.apache.hadoop.yarn.server.resourcemanager.RMAuditLogger: USER=ubuntu	IP=192.168.100.31	OPERATION=Register App Master	TARGET=ApplicationMasterService	RESULT=SUCCESS	APPID=application_1376720997863_0005	APPATTEMPTID=appattempt_1376720997863_0005_000001
2013-08-17 06:38:44,673 INFO org.apache.hadoop.yarn.server.resourcemanager.rmapp.attempt.RMAppAttemptImpl: appattempt_1376720997863_0005_000001 State change from LAUNCHED to RUNNING
2013-08-17 06:38:44,673 INFO org.apache.hadoop.yarn.server.resourcemanager.rmapp.RMAppImpl: application_1376720997863_0005 State change from ACCEPTED to RUNNING
2013-08-17 06:38:46,111 INFO org.apache.hadoop.yarn.server.resourcemanager.rmcontainer.RMContainerImpl: container_1376720997863_0005_01_000002 Container Transitioned from NEW to ALLOCATED
2013-08-17 06:38:46,112 INFO org.apache.hadoop.yarn.server.resourcemanager.RMAuditLogger: USER=ubuntu	OPERATION=AM Allocated Container	TARGET=SchedulerApp	RESULT=SUCCESS	APPID=application_1376720997863_0005	CONTAINERID=container_1376720997863_0005_01_000002
2013-08-17 06:38:46,112 INFO org.apache.hadoop.yarn.server.resourcemanager.scheduler.common.fica.FiCaSchedulerNode: Assigned container container_1376720997863_0005_01_000002 of capacity <memory:1024, vCores:1> on host hadoop-512-3:56071, which currently has 1 containers, <memory:1024, vCores:1> used and <memory:7168, vCores:15> available
2013-08-17 06:38:46,113 INFO org.apache.hadoop.yarn.server.resourcemanager.scheduler.capacity.LeafQueue: assignedContainer application=application_1376720997863_0005 container=Container: [ContainerId: container_1376720997863_0005_01_000002, NodeId: hadoop-512-3:56071, NodeHttpAddress: hadoop-512-3:8042, Resource: <memory:1024, vCores:1>, Priority: 20, State: NEW, Token: null, Status: container_id {, app_attempt_id {, application_id {, id: 5, cluster_timestamp: 1376720997863, }, attemptId: 1, }, id: 2, }, state: C_NEW, ] containerId=container_1376720997863_0005_01_000002 queue=default: capacity=1.0, absoluteCapacity=1.0, usedResources=<memory:2048, vCores:1>usedCapacity=0.041666668, absoluteUsedCapacity=0.041666668, numApps=1, numContainers=1 usedCapacity=0.041666668 absoluteUsedCapacity=0.041666668 used=<memory:2048, vCores:1> cluster=<memory:49152, vCores:96>
2013-08-17 06:38:46,114 INFO org.apache.hadoop.yarn.server.resourcemanager.scheduler.capacity.ParentQueue: Re-sorting queues since queue: root.default stats: default: capacity=1.0, absoluteCapacity=1.0, usedResources=<memory:3072, vCores:2>usedCapacity=0.0625, absoluteUsedCapacity=0.0625, numApps=1, numContainers=2
2013-08-17 06:38:46,114 INFO org.apache.hadoop.yarn.server.resourcemanager.scheduler.capacity.ParentQueue: assignedContainer queue=root usedCapacity=0.0625 absoluteUsedCapacity=0.0625 used=<memory:3072, vCores:2> cluster=<memory:49152, vCores:96>
2013-08-17 06:38:46,470 INFO org.apache.hadoop.yarn.server.resourcemanager.rmcontainer.RMContainerImpl: container_1376720997863_0005_01_000003 Container Transitioned from NEW to ALLOCATED
2013-08-17 06:38:46,471 INFO org.apache.hadoop.yarn.server.resourcemanager.RMAuditLogger: USER=ubuntu	OPERATION=AM Allocated Container	TARGET=SchedulerApp	RESULT=SUCCESS	APPID=application_1376720997863_0005	CONTAINERID=container_1376720997863_0005_01_000003
2013-08-17 06:38:46,471 INFO org.apache.hadoop.yarn.server.resourcemanager.scheduler.common.fica.FiCaSchedulerNode: Assigned container container_1376720997863_0005_01_000003 of capacity <memory:1024, vCores:1> on host hadoop-512-7:43914, which currently has 1 containers, <memory:1024, vCores:1> used and <memory:7168, vCores:15> available
2013-08-17 06:38:46,472 INFO org.apache.hadoop.yarn.server.resourcemanager.scheduler.capacity.LeafQueue: assignedContainer application=application_1376720997863_0005 container=Container: [ContainerId: container_1376720997863_0005_01_000003, NodeId: hadoop-512-7:43914, NodeHttpAddress: hadoop-512-7:8042, Resource: <memory:1024, vCores:1>, Priority: 20, State: NEW, Token: null, Status: container_id {, app_attempt_id {, application_id {, id: 5, cluster_timestamp: 1376720997863, }, attemptId: 1, }, id: 3, }, state: C_NEW, ] containerId=container_1376720997863_0005_01_000003 queue=default: capacity=1.0, absoluteCapacity=1.0, usedResources=<memory:3072, vCores:2>usedCapacity=0.0625, absoluteUsedCapacity=0.0625, numApps=1, numContainers=2 usedCapacity=0.0625 absoluteUsedCapacity=0.0625 used=<memory:3072, vCores:2> cluster=<memory:49152, vCores:96>
2013-08-17 06:38:46,472 INFO org.apache.hadoop.yarn.server.resourcemanager.scheduler.capacity.ParentQueue: Re-sorting queues since queue: root.default stats: default: capacity=1.0, absoluteCapacity=1.0, usedResources=<memory:4096, vCores:3>usedCapacity=0.083333336, absoluteUsedCapacity=0.083333336, numApps=1, numContainers=3
2013-08-17 06:38:46,473 INFO org.apache.hadoop.yarn.server.resourcemanager.scheduler.capacity.ParentQueue: assignedContainer queue=root usedCapacity=0.083333336 absoluteUsedCapacity=0.083333336 used=<memory:4096, vCores:3> cluster=<memory:49152, vCores:96>
2013-08-17 06:38:46,718 INFO org.apache.hadoop.yarn.server.resourcemanager.rmcontainer.RMContainerImpl: container_1376720997863_0005_01_000002 Container Transitioned from ALLOCATED to ACQUIRED
2013-08-17 06:38:46,721 INFO org.apache.hadoop.yarn.server.resourcemanager.rmcontainer.RMContainerImpl: container_1376720997863_0005_01_000003 Container Transitioned from ALLOCATED to ACQUIRED
2013-08-17 06:38:47,119 INFO org.apache.hadoop.yarn.server.resourcemanager.rmcontainer.RMContainerImpl: container_1376720997863_0005_01_000002 Container Transitioned from ACQUIRED to RUNNING
2013-08-17 06:38:47,477 INFO org.apache.hadoop.yarn.server.resourcemanager.rmcontainer.RMContainerImpl: container_1376720997863_0005_01_000003 Container Transitioned from ACQUIRED to RUNNING
2013-08-17 06:38:47,749 INFO org.apache.hadoop.yarn.server.resourcemanager.scheduler.AppSchedulingInfo: checking for deactivate... 
2013-08-17 06:40:32,321 INFO org.apache.hadoop.yarn.server.resourcemanager.rmcontainer.RMContainerImpl: container_1376720997863_0005_01_000002 Container Transitioned from RUNNING to COMPLETED
2013-08-17 06:40:32,322 INFO org.apache.hadoop.yarn.server.resourcemanager.scheduler.common.fica.FiCaSchedulerApp: Completed container: container_1376720997863_0005_01_000002 in state: COMPLETED event:FINISHED
2013-08-17 06:40:32,322 INFO org.apache.hadoop.yarn.server.resourcemanager.RMAuditLogger: USER=ubuntu	OPERATION=AM Released Container	TARGET=SchedulerApp	RESULT=SUCCESS	APPID=application_1376720997863_0005	CONTAINERID=container_1376720997863_0005_01_000002
2013-08-17 06:40:32,322 INFO org.apache.hadoop.yarn.server.resourcemanager.scheduler.common.fica.FiCaSchedulerNode: Released container container_1376720997863_0005_01_000002 of capacity <memory:1024, vCores:1> on host hadoop-512-3:56071, which currently has 0 containers, <memory:0, vCores:0> used and <memory:8192, vCores:16> available, release resources=true
2013-08-17 06:40:32,322 INFO org.apache.hadoop.yarn.server.resourcemanager.scheduler.capacity.LeafQueue: default used=<memory:3072, vCores:2> numContainers=2 user=ubuntu user-resources=<memory:3072, vCores:2>
2013-08-17 06:40:32,324 INFO org.apache.hadoop.yarn.server.resourcemanager.scheduler.capacity.LeafQueue: completedContainer container=Container: [ContainerId: container_1376720997863_0005_01_000002, NodeId: hadoop-512-3:56071, NodeHttpAddress: hadoop-512-3:8042, Resource: <memory:1024, vCores:1>, Priority: 20, State: NEW, Token: null, Status: container_id {, app_attempt_id {, application_id {, id: 5, cluster_timestamp: 1376720997863, }, attemptId: 1, }, id: 2, }, state: C_COMPLETE, diagnostics: "Container killed by the ApplicationMaster.\n\n", exit_status: 143, ] resource=<memory:1024, vCores:1> queue=default: capacity=1.0, absoluteCapacity=1.0, usedResources=<memory:3072, vCores:2>usedCapacity=0.0625, absoluteUsedCapacity=0.0625, numApps=1, numContainers=2 usedCapacity=0.0625 absoluteUsedCapacity=0.0625 used=<memory:3072, vCores:2> cluster=<memory:49152, vCores:96>
2013-08-17 06:40:32,324 INFO org.apache.hadoop.yarn.server.resourcemanager.scheduler.capacity.ParentQueue: completedContainer queue=root usedCapacity=0.0625 absoluteUsedCapacity=0.0625 used=<memory:3072, vCores:2> cluster=<memory:49152, vCores:96>
2013-08-17 06:40:32,325 INFO org.apache.hadoop.yarn.server.resourcemanager.scheduler.capacity.CapacityScheduler: Application appattempt_1376720997863_0005_000001 released container container_1376720997863_0005_01_000002 on node: host: hadoop-512-3:56071 #containers=0 available=8192 used=0 with event: FINISHED
2013-08-17 06:40:32,975 INFO org.apache.hadoop.yarn.server.resourcemanager.rmcontainer.RMContainerImpl: container_1376720997863_0005_01_000003 Container Transitioned from RUNNING to COMPLETED
2013-08-17 06:40:32,976 INFO org.apache.hadoop.yarn.server.resourcemanager.scheduler.common.fica.FiCaSchedulerApp: Completed container: container_1376720997863_0005_01_000003 in state: COMPLETED event:FINISHED
2013-08-17 06:40:32,976 INFO org.apache.hadoop.yarn.server.resourcemanager.RMAuditLogger: USER=ubuntu	OPERATION=AM Released Container	TARGET=SchedulerApp	RESULT=SUCCESS	APPID=application_1376720997863_0005	CONTAINERID=container_1376720997863_0005_01_000003
2013-08-17 06:40:32,977 INFO org.apache.hadoop.yarn.server.resourcemanager.scheduler.common.fica.FiCaSchedulerNode: Released container container_1376720997863_0005_01_000003 of capacity <memory:1024, vCores:1> on host hadoop-512-7:43914, which currently has 0 containers, <memory:0, vCores:0> used and <memory:8192, vCores:16> available, release resources=true
2013-08-17 06:40:32,977 INFO org.apache.hadoop.yarn.server.resourcemanager.scheduler.capacity.LeafQueue: default used=<memory:2048, vCores:1> numContainers=1 user=ubuntu user-resources=<memory:2048, vCores:1>
2013-08-17 06:40:32,979 INFO org.apache.hadoop.yarn.server.resourcemanager.scheduler.capacity.LeafQueue: completedContainer container=Container: [ContainerId: container_1376720997863_0005_01_000003, NodeId: hadoop-512-7:43914, NodeHttpAddress: hadoop-512-7:8042, Resource: <memory:1024, vCores:1>, Priority: 20, State: NEW, Token: null, Status: container_id {, app_attempt_id {, application_id {, id: 5, cluster_timestamp: 1376720997863, }, attemptId: 1, }, id: 3, }, state: C_COMPLETE, diagnostics: "Container killed by the ApplicationMaster.\n\n", exit_status: 143, ] resource=<memory:1024, vCores:1> queue=default: capacity=1.0, absoluteCapacity=1.0, usedResources=<memory:2048, vCores:1>usedCapacity=0.041666668, absoluteUsedCapacity=0.041666668, numApps=1, numContainers=1 usedCapacity=0.041666668 absoluteUsedCapacity=0.041666668 used=<memory:2048, vCores:1> cluster=<memory:49152, vCores:96>
2013-08-17 06:40:32,979 INFO org.apache.hadoop.yarn.server.resourcemanager.scheduler.capacity.ParentQueue: completedContainer queue=root usedCapacity=0.041666668 absoluteUsedCapacity=0.041666668 used=<memory:2048, vCores:1> cluster=<memory:49152, vCores:96>
2013-08-17 06:40:32,979 INFO org.apache.hadoop.yarn.server.resourcemanager.scheduler.capacity.CapacityScheduler: Application appattempt_1376720997863_0005_000001 released container container_1376720997863_0005_01_000003 on node: host: hadoop-512-7:43914 #containers=0 available=8192 used=0 with event: FINISHED
2013-08-17 06:40:37,113 INFO org.apache.hadoop.yarn.server.resourcemanager.rmapp.attempt.RMAppAttemptImpl: appattempt_1376720997863_0005_000001 State change from RUNNING to FINISHING
2013-08-17 06:40:37,115 INFO org.apache.hadoop.yarn.server.resourcemanager.rmapp.RMAppImpl: application_1376720997863_0005 State change from RUNNING to FINISHING
2013-08-17 06:40:37,331 INFO org.apache.hadoop.yarn.server.resourcemanager.rmcontainer.RMContainerImpl: container_1376720997863_0005_01_000001 Container Transitioned from RUNNING to COMPLETED
2013-08-17 06:40:37,331 INFO org.apache.hadoop.yarn.server.resourcemanager.scheduler.common.fica.FiCaSchedulerApp: Completed container: container_1376720997863_0005_01_000001 in state: COMPLETED event:FINISHED
2013-08-17 06:40:37,332 INFO org.apache.hadoop.yarn.server.resourcemanager.rmapp.attempt.RMAppAttemptImpl: appattempt_1376720997863_0005_000001 State change from FINISHING to FINISHED
2013-08-17 06:40:37,332 INFO org.apache.hadoop.yarn.server.resourcemanager.RMAuditLogger: USER=ubuntu	OPERATION=AM Released Container	TARGET=SchedulerApp	RESULT=SUCCESS	APPID=application_1376720997863_0005	CONTAINERID=container_1376720997863_0005_01_000001
2013-08-17 06:40:37,332 INFO org.apache.hadoop.yarn.server.resourcemanager.rmapp.RMAppImpl: application_1376720997863_0005 State change from FINISHING to FINISHED
2013-08-17 06:40:37,332 INFO org.apache.hadoop.yarn.server.resourcemanager.scheduler.common.fica.FiCaSchedulerNode: Released container container_1376720997863_0005_01_000001 of capacity <memory:2048, vCores:1> on host hadoop-512-6:48301, which currently has 0 containers, <memory:0, vCores:0> used and <memory:8192, vCores:16> available, release resources=true
2013-08-17 06:40:37,332 INFO org.apache.hadoop.yarn.server.resourcemanager.scheduler.capacity.LeafQueue: default used=<memory:0, vCores:0> numContainers=0 user=ubuntu user-resources=<memory:0, vCores:0>
2013-08-17 06:40:37,332 INFO org.apache.hadoop.yarn.server.resourcemanager.RMAuditLogger: USER=ubuntu	OPERATION=Application Finished - Succeeded	TARGET=RMAppManager	RESULT=SUCCESS	APPID=application_1376720997863_0005
2013-08-17 06:40:37,333 INFO org.apache.hadoop.yarn.server.resourcemanager.RMAppManager$ApplicationSummary: appId=application_1376720997863_0005,name=TeraGen,user=ubuntu,queue=default,state=FINISHED,trackingUrl=hadoop-512-1.novalocal:8088/proxy/application_1376720997863_0005/jobhistory/job/job_1376720997863_0005,appMasterHost=hadoop-512-6,startTime=1376721518516,finishTime=1376721637115
2013-08-17 06:40:37,334 INFO org.apache.hadoop.yarn.server.resourcemanager.scheduler.capacity.LeafQueue: completedContainer container=Container: [ContainerId: container_1376720997863_0005_01_000001, NodeId: hadoop-512-6:48301, NodeHttpAddress: hadoop-512-6:8042, Resource: <memory:2048, vCores:1>, Priority: 0, State: NEW, Token: null, Status: container_id {, app_attempt_id {, application_id {, id: 5, cluster_timestamp: 1376720997863, }, attemptId: 1, }, id: 1, }, state: C_COMPLETE, diagnostics: "", exit_status: 0, ] resource=<memory:2048, vCores:1> queue=default: capacity=1.0, absoluteCapacity=1.0, usedResources=<memory:0, vCores:0>usedCapacity=0.0, absoluteUsedCapacity=0.0, numApps=1, numContainers=0 usedCapacity=0.0 absoluteUsedCapacity=0.0 used=<memory:0, vCores:0> cluster=<memory:49152, vCores:96>
2013-08-17 06:40:37,334 INFO org.apache.hadoop.yarn.server.resourcemanager.scheduler.capacity.ParentQueue: completedContainer queue=root usedCapacity=0.0 absoluteUsedCapacity=0.0 used=<memory:0, vCores:0> cluster=<memory:49152, vCores:96>
2013-08-17 06:40:37,334 INFO org.apache.hadoop.yarn.server.resourcemanager.scheduler.capacity.CapacityScheduler: Application appattempt_1376720997863_0005_000001 released container container_1376720997863_0005_01_000001 on node: host: hadoop-512-6:48301 #containers=0 available=8192 used=0 with event: FINISHED
2013-08-17 06:40:37,334 INFO org.apache.hadoop.yarn.server.resourcemanager.scheduler.capacity.CapacityScheduler: Application appattempt_1376720997863_0005_000001 is done. finalState=FINISHED
2013-08-17 06:40:37,334 INFO org.apache.hadoop.yarn.server.resourcemanager.scheduler.AppSchedulingInfo: Application application_1376720997863_0005 requests cleared
2013-08-17 06:40:37,335 INFO org.apache.hadoop.yarn.server.resourcemanager.scheduler.capacity.LeafQueue: Application removed - appId: application_1376720997863_0005 user: ubuntu queue: default #user-pending-applications: 0 #user-active-applications: 0 #queue-pending-applications: 0 #queue-active-applications: 0
2013-08-17 06:40:37,335 INFO org.apache.hadoop.yarn.server.resourcemanager.scheduler.capacity.ParentQueue: Application removed - appId: application_1376720997863_0005 user: ubuntu leaf-queue of parent: root #applications: 0
2013-08-17 06:40:37,335 INFO org.apache.hadoop.yarn.server.resourcemanager.recovery.RMStateStore: Removing info for app: application_1376720997863_0005
2013-08-17 06:40:37,336 INFO org.apache.hadoop.yarn.server.resourcemanager.amlauncher.AMLauncher: Cleaning master appattempt_1376720997863_0005_000001
2013-08-17 06:41:23,150 INFO org.apache.hadoop.yarn.server.resourcemanager.ClientRMService: Allocated new applicationId: 6
2013-08-17 06:41:23,192 INFO org.apache.hadoop.yarn.server.resourcemanager.ClientRMService: Allocated new applicationId: 7
2013-08-17 06:41:23,211 INFO org.apache.hadoop.yarn.server.resourcemanager.ClientRMService: Allocated new applicationId: 8
2013-08-17 06:41:23,263 INFO org.apache.hadoop.yarn.server.resourcemanager.ClientRMService: Allocated new applicationId: 9
2013-08-17 06:41:23,381 INFO org.apache.hadoop.yarn.server.resourcemanager.ClientRMService: Allocated new applicationId: 10
2013-08-17 06:41:24,688 INFO org.apache.hadoop.yarn.server.resourcemanager.ClientRMService: Storing Application with id application_1376720997863_0006
2013-08-17 06:41:24,688 INFO org.apache.hadoop.yarn.server.resourcemanager.recovery.RMStateStore: Storing info for app: application_1376720997863_0006
2013-08-17 06:41:24,688 INFO org.apache.hadoop.yarn.server.resourcemanager.ClientRMService: Application with id 6 submitted by user ubuntu
2013-08-17 06:41:24,688 INFO org.apache.hadoop.yarn.server.resourcemanager.RMAuditLogger: USER=ubuntu	IP=192.168.100.5	OPERATION=Submit Application Request	TARGET=ClientRMService	RESULT=SUCCESS	APPID=application_1376720997863_0006
2013-08-17 06:41:24,691 INFO org.apache.hadoop.yarn.server.resourcemanager.rmapp.RMAppImpl: application_1376720997863_0006 State change from NEW to SUBMITTED
2013-08-17 06:41:24,691 INFO org.apache.hadoop.yarn.server.resourcemanager.ApplicationMasterService: Registering appattempt_1376720997863_0006_000001
2013-08-17 06:41:24,691 INFO org.apache.hadoop.yarn.server.resourcemanager.rmapp.attempt.RMAppAttemptImpl: appattempt_1376720997863_0006_000001 State change from NEW to SUBMITTED
2013-08-17 06:41:24,692 INFO org.apache.hadoop.yarn.server.resourcemanager.scheduler.capacity.LeafQueue: Application application_1376720997863_0006 from user: ubuntu activated in queue: default
2013-08-17 06:41:24,692 INFO org.apache.hadoop.yarn.server.resourcemanager.scheduler.capacity.LeafQueue: Application added - appId: application_1376720997863_0006 user: org.apache.hadoop.yarn.server.resourcemanager.scheduler.capacity.LeafQueue$User@a0704b6, leaf-queue: default #user-pending-applications: 0 #user-active-applications: 1 #queue-pending-applications: 0 #queue-active-applications: 1
2013-08-17 06:41:24,692 INFO org.apache.hadoop.yarn.server.resourcemanager.scheduler.capacity.ParentQueue: Application added - appId: application_1376720997863_0006 user: ubuntu leaf-queue of parent: root #applications: 1
2013-08-17 06:41:24,692 INFO org.apache.hadoop.yarn.server.resourcemanager.scheduler.capacity.CapacityScheduler: Application Submission: appattempt_1376720997863_0006_000001, user: ubuntu queue: default: capacity=1.0, absoluteCapacity=1.0, usedResources=<memory:0, vCores:0>usedCapacity=0.0, absoluteUsedCapacity=0.0, numApps=1, numContainers=0, currently active: 1
2013-08-17 06:41:24,692 INFO org.apache.hadoop.yarn.server.resourcemanager.rmapp.attempt.RMAppAttemptImpl: appattempt_1376720997863_0006_000001 State change from SUBMITTED to SCHEDULED
2013-08-17 06:41:24,692 INFO org.apache.hadoop.yarn.server.resourcemanager.rmapp.RMAppImpl: application_1376720997863_0006 State change from SUBMITTED to ACCEPTED
2013-08-17 06:41:24,727 INFO org.apache.hadoop.yarn.server.resourcemanager.ClientRMService: Storing Application with id application_1376720997863_0009
2013-08-17 06:41:24,727 INFO org.apache.hadoop.yarn.server.resourcemanager.recovery.RMStateStore: Storing info for app: application_1376720997863_0009
2013-08-17 06:41:24,727 INFO org.apache.hadoop.yarn.server.resourcemanager.ClientRMService: Application with id 9 submitted by user ubuntu
2013-08-17 06:41:24,728 INFO org.apache.hadoop.yarn.server.resourcemanager.RMAuditLogger: USER=ubuntu	IP=192.168.100.5	OPERATION=Submit Application Request	TARGET=ClientRMService	RESULT=SUCCESS	APPID=application_1376720997863_0009
2013-08-17 06:41:24,728 INFO org.apache.hadoop.yarn.server.resourcemanager.rmapp.RMAppImpl: application_1376720997863_0009 State change from NEW to SUBMITTED
2013-08-17 06:41:24,728 INFO org.apache.hadoop.yarn.server.resourcemanager.ApplicationMasterService: Registering appattempt_1376720997863_0009_000001
2013-08-17 06:41:24,729 INFO org.apache.hadoop.yarn.server.resourcemanager.rmapp.attempt.RMAppAttemptImpl: appattempt_1376720997863_0009_000001 State change from NEW to SUBMITTED
2013-08-17 06:41:24,729 INFO org.apache.hadoop.yarn.server.resourcemanager.scheduler.capacity.LeafQueue: Application application_1376720997863_0009 from user: ubuntu activated in queue: default
2013-08-17 06:41:24,729 INFO org.apache.hadoop.yarn.server.resourcemanager.scheduler.capacity.LeafQueue: Application added - appId: application_1376720997863_0009 user: org.apache.hadoop.yarn.server.resourcemanager.scheduler.capacity.LeafQueue$User@a0704b6, leaf-queue: default #user-pending-applications: 0 #user-active-applications: 2 #queue-pending-applications: 0 #queue-active-applications: 2
2013-08-17 06:41:24,729 INFO org.apache.hadoop.yarn.server.resourcemanager.scheduler.capacity.ParentQueue: Application added - appId: application_1376720997863_0009 user: ubuntu leaf-queue of parent: root #applications: 2
2013-08-17 06:41:24,729 INFO org.apache.hadoop.yarn.server.resourcemanager.scheduler.capacity.CapacityScheduler: Application Submission: appattempt_1376720997863_0009_000001, user: ubuntu queue: default: capacity=1.0, absoluteCapacity=1.0, usedResources=<memory:0, vCores:0>usedCapacity=0.0, absoluteUsedCapacity=0.0, numApps=2, numContainers=0, currently active: 2
2013-08-17 06:41:24,731 INFO org.apache.hadoop.yarn.server.resourcemanager.rmapp.attempt.RMAppAttemptImpl: appattempt_1376720997863_0009_000001 State change from SUBMITTED to SCHEDULED
2013-08-17 06:41:24,731 INFO org.apache.hadoop.yarn.server.resourcemanager.rmapp.RMAppImpl: application_1376720997863_0009 State change from SUBMITTED to ACCEPTED
2013-08-17 06:41:24,752 INFO org.apache.hadoop.yarn.server.resourcemanager.ClientRMService: Storing Application with id application_1376720997863_0008
2013-08-17 06:41:24,752 INFO org.apache.hadoop.yarn.server.resourcemanager.recovery.RMStateStore: Storing info for app: application_1376720997863_0008
2013-08-17 06:41:24,752 INFO org.apache.hadoop.yarn.server.resourcemanager.ClientRMService: Application with id 8 submitted by user ubuntu
2013-08-17 06:41:24,752 INFO org.apache.hadoop.yarn.server.resourcemanager.RMAuditLogger: USER=ubuntu	IP=192.168.100.5	OPERATION=Submit Application Request	TARGET=ClientRMService	RESULT=SUCCESS	APPID=application_1376720997863_0008
2013-08-17 06:41:24,753 INFO org.apache.hadoop.yarn.server.resourcemanager.rmapp.RMAppImpl: application_1376720997863_0008 State change from NEW to SUBMITTED
2013-08-17 06:41:24,753 INFO org.apache.hadoop.yarn.server.resourcemanager.ApplicationMasterService: Registering appattempt_1376720997863_0008_000001
2013-08-17 06:41:24,753 INFO org.apache.hadoop.yarn.server.resourcemanager.rmapp.attempt.RMAppAttemptImpl: appattempt_1376720997863_0008_000001 State change from NEW to SUBMITTED
2013-08-17 06:41:24,753 INFO org.apache.hadoop.yarn.server.resourcemanager.scheduler.capacity.LeafQueue: Application application_1376720997863_0008 from user: ubuntu activated in queue: default
2013-08-17 06:41:24,753 INFO org.apache.hadoop.yarn.server.resourcemanager.scheduler.capacity.LeafQueue: Application added - appId: application_1376720997863_0008 user: org.apache.hadoop.yarn.server.resourcemanager.scheduler.capacity.LeafQueue$User@a0704b6, leaf-queue: default #user-pending-applications: 0 #user-active-applications: 3 #queue-pending-applications: 0 #queue-active-applications: 3
2013-08-17 06:41:24,753 INFO org.apache.hadoop.yarn.server.resourcemanager.scheduler.capacity.ParentQueue: Application added - appId: application_1376720997863_0008 user: ubuntu leaf-queue of parent: root #applications: 3
2013-08-17 06:41:24,754 INFO org.apache.hadoop.yarn.server.resourcemanager.scheduler.capacity.CapacityScheduler: Application Submission: appattempt_1376720997863_0008_000001, user: ubuntu queue: default: capacity=1.0, absoluteCapacity=1.0, usedResources=<memory:0, vCores:0>usedCapacity=0.0, absoluteUsedCapacity=0.0, numApps=3, numContainers=0, currently active: 3
2013-08-17 06:41:24,754 INFO org.apache.hadoop.yarn.server.resourcemanager.rmapp.attempt.RMAppAttemptImpl: appattempt_1376720997863_0008_000001 State change from SUBMITTED to SCHEDULED
2013-08-17 06:41:24,754 INFO org.apache.hadoop.yarn.server.resourcemanager.rmapp.RMAppImpl: application_1376720997863_0008 State change from SUBMITTED to ACCEPTED
2013-08-17 06:41:24,793 INFO org.apache.hadoop.yarn.server.resourcemanager.ClientRMService: Storing Application with id application_1376720997863_0007
2013-08-17 06:41:24,793 INFO org.apache.hadoop.yarn.server.resourcemanager.recovery.RMStateStore: Storing info for app: application_1376720997863_0007
2013-08-17 06:41:24,793 INFO org.apache.hadoop.yarn.server.resourcemanager.ClientRMService: Application with id 7 submitted by user ubuntu
2013-08-17 06:41:24,793 INFO org.apache.hadoop.yarn.server.resourcemanager.RMAuditLogger: USER=ubuntu	IP=192.168.100.5	OPERATION=Submit Application Request	TARGET=ClientRMService	RESULT=SUCCESS	APPID=application_1376720997863_0007
2013-08-17 06:41:24,794 INFO org.apache.hadoop.yarn.server.resourcemanager.rmapp.RMAppImpl: application_1376720997863_0007 State change from NEW to SUBMITTED
2013-08-17 06:41:24,794 INFO org.apache.hadoop.yarn.server.resourcemanager.ApplicationMasterService: Registering appattempt_1376720997863_0007_000001
2013-08-17 06:41:24,794 INFO org.apache.hadoop.yarn.server.resourcemanager.rmapp.attempt.RMAppAttemptImpl: appattempt_1376720997863_0007_000001 State change from NEW to SUBMITTED
2013-08-17 06:41:24,794 INFO org.apache.hadoop.yarn.server.resourcemanager.scheduler.capacity.LeafQueue: Application application_1376720997863_0007 from user: ubuntu activated in queue: default
2013-08-17 06:41:24,794 INFO org.apache.hadoop.yarn.server.resourcemanager.scheduler.capacity.LeafQueue: Application added - appId: application_1376720997863_0007 user: org.apache.hadoop.yarn.server.resourcemanager.scheduler.capacity.LeafQueue$User@a0704b6, leaf-queue: default #user-pending-applications: 0 #user-active-applications: 4 #queue-pending-applications: 0 #queue-active-applications: 4
2013-08-17 06:41:24,794 INFO org.apache.hadoop.yarn.server.resourcemanager.scheduler.capacity.ParentQueue: Application added - appId: application_1376720997863_0007 user: ubuntu leaf-queue of parent: root #applications: 4
2013-08-17 06:41:24,795 INFO org.apache.hadoop.yarn.server.resourcemanager.scheduler.capacity.CapacityScheduler: Application Submission: appattempt_1376720997863_0007_000001, user: ubuntu queue: default: capacity=1.0, absoluteCapacity=1.0, usedResources=<memory:0, vCores:0>usedCapacity=0.0, absoluteUsedCapacity=0.0, numApps=4, numContainers=0, currently active: 4
2013-08-17 06:41:24,795 INFO org.apache.hadoop.yarn.server.resourcemanager.rmapp.attempt.RMAppAttemptImpl: appattempt_1376720997863_0007_000001 State change from SUBMITTED to SCHEDULED
2013-08-17 06:41:24,795 INFO org.apache.hadoop.yarn.server.resourcemanager.rmapp.RMAppImpl: application_1376720997863_0007 State change from SUBMITTED to ACCEPTED
2013-08-17 06:41:24,922 INFO org.apache.hadoop.yarn.server.resourcemanager.ClientRMService: Storing Application with id application_1376720997863_0010
2013-08-17 06:41:24,923 INFO org.apache.hadoop.yarn.server.resourcemanager.recovery.RMStateStore: Storing info for app: application_1376720997863_0010
2013-08-17 06:41:24,923 INFO org.apache.hadoop.yarn.server.resourcemanager.ClientRMService: Application with id 10 submitted by user ubuntu
2013-08-17 06:41:24,923 INFO org.apache.hadoop.yarn.server.resourcemanager.RMAuditLogger: USER=ubuntu	IP=192.168.100.5	OPERATION=Submit Application Request	TARGET=ClientRMService	RESULT=SUCCESS	APPID=application_1376720997863_0010
2013-08-17 06:41:24,924 INFO org.apache.hadoop.yarn.server.resourcemanager.rmapp.RMAppImpl: application_1376720997863_0010 State change from NEW to SUBMITTED
2013-08-17 06:41:24,924 INFO org.apache.hadoop.yarn.server.resourcemanager.ApplicationMasterService: Registering appattempt_1376720997863_0010_000001
2013-08-17 06:41:24,924 INFO org.apache.hadoop.yarn.server.resourcemanager.rmapp.attempt.RMAppAttemptImpl: appattempt_1376720997863_0010_000001 State change from NEW to SUBMITTED
2013-08-17 06:41:24,924 INFO org.apache.hadoop.yarn.server.resourcemanager.scheduler.capacity.LeafQueue: Application application_1376720997863_0010 from user: ubuntu activated in queue: default
2013-08-17 06:41:24,924 INFO org.apache.hadoop.yarn.server.resourcemanager.scheduler.capacity.LeafQueue: Application added - appId: application_1376720997863_0010 user: org.apache.hadoop.yarn.server.resourcemanager.scheduler.capacity.LeafQueue$User@a0704b6, leaf-queue: default #user-pending-applications: 0 #user-active-applications: 5 #queue-pending-applications: 0 #queue-active-applications: 5
2013-08-17 06:41:24,925 INFO org.apache.hadoop.yarn.server.resourcemanager.scheduler.capacity.ParentQueue: Application added - appId: application_1376720997863_0010 user: ubuntu leaf-queue of parent: root #applications: 5
2013-08-17 06:41:24,925 INFO org.apache.hadoop.yarn.server.resourcemanager.scheduler.capacity.CapacityScheduler: Application Submission: appattempt_1376720997863_0010_000001, user: ubuntu queue: default: capacity=1.0, absoluteCapacity=1.0, usedResources=<memory:0, vCores:0>usedCapacity=0.0, absoluteUsedCapacity=0.0, numApps=5, numContainers=0, currently active: 5
2013-08-17 06:41:24,925 INFO org.apache.hadoop.yarn.server.resourcemanager.rmapp.attempt.RMAppAttemptImpl: appattempt_1376720997863_0010_000001 State change from SUBMITTED to SCHEDULED
2013-08-17 06:41:24,925 INFO org.apache.hadoop.yarn.server.resourcemanager.rmapp.RMAppImpl: application_1376720997863_0010 State change from SUBMITTED to ACCEPTED
2013-08-17 06:41:25,061 INFO org.apache.hadoop.yarn.server.resourcemanager.rmcontainer.RMContainerImpl: container_1376720997863_0006_01_000001 Container Transitioned from NEW to ALLOCATED
2013-08-17 06:41:25,061 INFO org.apache.hadoop.yarn.server.resourcemanager.RMAuditLogger: USER=ubuntu	OPERATION=AM Allocated Container	TARGET=SchedulerApp	RESULT=SUCCESS	APPID=application_1376720997863_0006	CONTAINERID=container_1376720997863_0006_01_000001
2013-08-17 06:41:25,061 INFO org.apache.hadoop.yarn.server.resourcemanager.scheduler.common.fica.FiCaSchedulerNode: Assigned container container_1376720997863_0006_01_000001 of capacity <memory:2048, vCores:1> on host hadoop-512-5:45082, which currently has 1 containers, <memory:2048, vCores:1> used and <memory:6144, vCores:15> available
2013-08-17 06:41:25,062 INFO org.apache.hadoop.yarn.server.resourcemanager.scheduler.capacity.LeafQueue: assignedContainer application=application_1376720997863_0006 container=Container: [ContainerId: container_1376720997863_0006_01_000001, NodeId: hadoop-512-5:45082, NodeHttpAddress: hadoop-512-5:8042, Resource: <memory:2048, vCores:1>, Priority: 0, State: NEW, Token: null, Status: container_id {, app_attempt_id {, application_id {, id: 6, cluster_timestamp: 1376720997863, }, attemptId: 1, }, id: 1, }, state: C_NEW, ] containerId=container_1376720997863_0006_01_000001 queue=default: capacity=1.0, absoluteCapacity=1.0, usedResources=<memory:0, vCores:0>usedCapacity=0.0, absoluteUsedCapacity=0.0, numApps=5, numContainers=0 usedCapacity=0.0 absoluteUsedCapacity=0.0 used=<memory:0, vCores:0> cluster=<memory:49152, vCores:96>
2013-08-17 06:41:25,062 INFO org.apache.hadoop.yarn.server.resourcemanager.scheduler.capacity.ParentQueue: Re-sorting queues since queue: root.default stats: default: capacity=1.0, absoluteCapacity=1.0, usedResources=<memory:2048, vCores:1>usedCapacity=0.041666668, absoluteUsedCapacity=0.041666668, numApps=5, numContainers=1
2013-08-17 06:41:25,062 INFO org.apache.hadoop.yarn.server.resourcemanager.scheduler.capacity.ParentQueue: assignedContainer queue=root usedCapacity=0.041666668 absoluteUsedCapacity=0.041666668 used=<memory:2048, vCores:1> cluster=<memory:49152, vCores:96>
2013-08-17 06:41:25,064 INFO org.apache.hadoop.yarn.server.resourcemanager.rmcontainer.RMContainerImpl: container_1376720997863_0006_01_000001 Container Transitioned from ALLOCATED to ACQUIRED
2013-08-17 06:41:25,065 INFO org.apache.hadoop.yarn.server.resourcemanager.rmapp.attempt.RMAppAttemptImpl: Storing attempt: AppId: application_1376720997863_0006 AttemptId: appattempt_1376720997863_0006_000001 MasterContainer: Container: [ContainerId: container_1376720997863_0006_01_000001, NodeId: hadoop-512-5:45082, NodeHttpAddress: hadoop-512-5:8042, Resource: <memory:2048, vCores:1>, Priority: 0, State: NEW, Token: null, Status: container_id {, app_attempt_id {, application_id {, id: 6, cluster_timestamp: 1376720997863, }, attemptId: 1, }, id: 1, }, state: C_NEW, ]
2013-08-17 06:41:25,065 INFO org.apache.hadoop.yarn.server.resourcemanager.rmapp.attempt.RMAppAttemptImpl: appattempt_1376720997863_0006_000001 State change from SCHEDULED to ALLOCATED_SAVING
2013-08-17 06:41:25,065 INFO org.apache.hadoop.yarn.server.resourcemanager.recovery.RMStateStore: Storing info for attempt: appattempt_1376720997863_0006_000001
2013-08-17 06:41:25,065 INFO org.apache.hadoop.yarn.server.resourcemanager.rmcontainer.RMContainerImpl: container_1376720997863_0007_01_000001 Container Transitioned from NEW to ALLOCATED
2013-08-17 06:41:25,066 INFO org.apache.hadoop.yarn.server.resourcemanager.RMAuditLogger: USER=ubuntu	OPERATION=AM Allocated Container	TARGET=SchedulerApp	RESULT=SUCCESS	APPID=application_1376720997863_0007	CONTAINERID=container_1376720997863_0007_01_000001
2013-08-17 06:41:25,066 INFO org.apache.hadoop.yarn.server.resourcemanager.scheduler.common.fica.FiCaSchedulerNode: Assigned container container_1376720997863_0007_01_000001 of capacity <memory:2048, vCores:1> on host hadoop-512-4:45085, which currently has 1 containers, <memory:2048, vCores:1> used and <memory:6144, vCores:15> available
2013-08-17 06:41:25,066 INFO org.apache.hadoop.yarn.server.resourcemanager.rmapp.attempt.RMAppAttemptImpl: appattempt_1376720997863_0006_000001 State change from ALLOCATED_SAVING to ALLOCATED
2013-08-17 06:41:25,066 INFO org.apache.hadoop.yarn.server.resourcemanager.scheduler.capacity.LeafQueue: assignedContainer application=application_1376720997863_0007 container=Container: [ContainerId: container_1376720997863_0007_01_000001, NodeId: hadoop-512-4:45085, NodeHttpAddress: hadoop-512-4:8042, Resource: <memory:2048, vCores:1>, Priority: 0, State: NEW, Token: null, Status: container_id {, app_attempt_id {, application_id {, id: 7, cluster_timestamp: 1376720997863, }, attemptId: 1, }, id: 1, }, state: C_NEW, ] containerId=container_1376720997863_0007_01_000001 queue=default: capacity=1.0, absoluteCapacity=1.0, usedResources=<memory:2048, vCores:1>usedCapacity=0.041666668, absoluteUsedCapacity=0.041666668, numApps=5, numContainers=1 usedCapacity=0.041666668 absoluteUsedCapacity=0.041666668 used=<memory:2048, vCores:1> cluster=<memory:49152, vCores:96>
2013-08-17 06:41:25,066 INFO org.apache.hadoop.yarn.server.resourcemanager.scheduler.capacity.ParentQueue: Re-sorting queues since queue: root.default stats: default: capacity=1.0, absoluteCapacity=1.0, usedResources=<memory:4096, vCores:2>usedCapacity=0.083333336, absoluteUsedCapacity=0.083333336, numApps=5, numContainers=2
2013-08-17 06:41:25,067 INFO org.apache.hadoop.yarn.server.resourcemanager.rmcontainer.RMContainerImpl: container_1376720997863_0007_01_000001 Container Transitioned from ALLOCATED to ACQUIRED
2013-08-17 06:41:25,067 INFO org.apache.hadoop.yarn.server.resourcemanager.scheduler.capacity.ParentQueue: assignedContainer queue=root usedCapacity=0.083333336 absoluteUsedCapacity=0.083333336 used=<memory:4096, vCores:2> cluster=<memory:49152, vCores:96>
2013-08-17 06:41:25,068 INFO org.apache.hadoop.yarn.server.resourcemanager.rmapp.attempt.RMAppAttemptImpl: Storing attempt: AppId: application_1376720997863_0007 AttemptId: appattempt_1376720997863_0007_000001 MasterContainer: Container: [ContainerId: container_1376720997863_0007_01_000001, NodeId: hadoop-512-4:45085, NodeHttpAddress: hadoop-512-4:8042, Resource: <memory:2048, vCores:1>, Priority: 0, State: NEW, Token: null, Status: container_id {, app_attempt_id {, application_id {, id: 7, cluster_timestamp: 1376720997863, }, attemptId: 1, }, id: 1, }, state: C_NEW, ]
2013-08-17 06:41:25,068 INFO org.apache.hadoop.yarn.server.resourcemanager.rmapp.attempt.RMAppAttemptImpl: appattempt_1376720997863_0007_000001 State change from SCHEDULED to ALLOCATED_SAVING
2013-08-17 06:41:25,068 INFO org.apache.hadoop.yarn.server.resourcemanager.recovery.RMStateStore: Storing info for attempt: appattempt_1376720997863_0007_000001
2013-08-17 06:41:25,069 INFO org.apache.hadoop.yarn.server.resourcemanager.amlauncher.AMLauncher: Launching masterappattempt_1376720997863_0006_000001
2013-08-17 06:41:25,069 INFO org.apache.hadoop.yarn.server.resourcemanager.rmapp.attempt.RMAppAttemptImpl: appattempt_1376720997863_0007_000001 State change from ALLOCATED_SAVING to ALLOCATED
2013-08-17 06:41:25,070 INFO org.apache.hadoop.yarn.server.resourcemanager.amlauncher.AMLauncher: Setting up container Container: [ContainerId: container_1376720997863_0006_01_000001, NodeId: hadoop-512-5:45082, NodeHttpAddress: hadoop-512-5:8042, Resource: <memory:2048, vCores:1>, Priority: 0, State: NEW, Token: null, Status: container_id {, app_attempt_id {, application_id {, id: 6, cluster_timestamp: 1376720997863, }, attemptId: 1, }, id: 1, }, state: C_NEW, ] for AM appattempt_1376720997863_0006_000001
2013-08-17 06:41:25,070 INFO org.apache.hadoop.yarn.server.resourcemanager.amlauncher.AMLauncher: Command to launch container container_1376720997863_0006_01_000001 : $JAVA_HOME/bin/java -Dlog4j.configuration=container-log4j.properties -Dyarn.app.mapreduce.container.log.dir=<LOG_DIR> -Dyarn.app.mapreduce.container.log.filesize=0 -Dhadoop.root.logger=INFO,CLA  -Xmx1024m org.apache.hadoop.mapreduce.v2.app.MRAppMaster 1><LOG_DIR>/stdout 2><LOG_DIR>/stderr 
2013-08-17 06:41:25,071 INFO org.apache.hadoop.yarn.server.resourcemanager.amlauncher.AMLauncher: Launching masterappattempt_1376720997863_0007_000001
2013-08-17 06:41:25,073 INFO org.apache.hadoop.yarn.server.resourcemanager.amlauncher.AMLauncher: Setting up container Container: [ContainerId: container_1376720997863_0007_01_000001, NodeId: hadoop-512-4:45085, NodeHttpAddress: hadoop-512-4:8042, Resource: <memory:2048, vCores:1>, Priority: 0, State: NEW, Token: null, Status: container_id {, app_attempt_id {, application_id {, id: 7, cluster_timestamp: 1376720997863, }, attemptId: 1, }, id: 1, }, state: C_NEW, ] for AM appattempt_1376720997863_0007_000001
2013-08-17 06:41:25,078 INFO org.apache.hadoop.yarn.server.resourcemanager.amlauncher.AMLauncher: Command to launch container container_1376720997863_0007_01_000001 : $JAVA_HOME/bin/java -Dlog4j.configuration=container-log4j.properties -Dyarn.app.mapreduce.container.log.dir=<LOG_DIR> -Dyarn.app.mapreduce.container.log.filesize=0 -Dhadoop.root.logger=INFO,CLA  -Xmx1024m org.apache.hadoop.mapreduce.v2.app.MRAppMaster 1><LOG_DIR>/stdout 2><LOG_DIR>/stderr 
2013-08-17 06:41:25,087 INFO org.apache.hadoop.yarn.server.resourcemanager.amlauncher.AMLauncher: Done launching container Container: [ContainerId: container_1376720997863_0006_01_000001, NodeId: hadoop-512-5:45082, NodeHttpAddress: hadoop-512-5:8042, Resource: <memory:2048, vCores:1>, Priority: 0, State: NEW, Token: null, Status: container_id {, app_attempt_id {, application_id {, id: 6, cluster_timestamp: 1376720997863, }, attemptId: 1, }, id: 1, }, state: C_NEW, ] for AM appattempt_1376720997863_0006_000001
2013-08-17 06:41:25,087 INFO org.apache.hadoop.yarn.server.resourcemanager.rmapp.attempt.RMAppAttemptImpl: appattempt_1376720997863_0006_000001 State change from ALLOCATED to LAUNCHED
2013-08-17 06:41:25,098 INFO org.apache.hadoop.yarn.server.resourcemanager.amlauncher.AMLauncher: Done launching container Container: [ContainerId: container_1376720997863_0007_01_000001, NodeId: hadoop-512-4:45085, NodeHttpAddress: hadoop-512-4:8042, Resource: <memory:2048, vCores:1>, Priority: 0, State: NEW, Token: null, Status: container_id {, app_attempt_id {, application_id {, id: 7, cluster_timestamp: 1376720997863, }, attemptId: 1, }, id: 1, }, state: C_NEW, ] for AM appattempt_1376720997863_0007_000001
2013-08-17 06:41:25,098 INFO org.apache.hadoop.yarn.server.resourcemanager.rmapp.attempt.RMAppAttemptImpl: appattempt_1376720997863_0007_000001 State change from ALLOCATED to LAUNCHED
2013-08-17 06:41:25,166 INFO org.apache.hadoop.yarn.server.resourcemanager.rmcontainer.RMContainerImpl: container_1376720997863_0008_01_000001 Container Transitioned from NEW to ALLOCATED
2013-08-17 06:41:25,166 INFO org.apache.hadoop.yarn.server.resourcemanager.RMAuditLogger: USER=ubuntu	OPERATION=AM Allocated Container	TARGET=SchedulerApp	RESULT=SUCCESS	APPID=application_1376720997863_0008	CONTAINERID=container_1376720997863_0008_01_000001
2013-08-17 06:41:25,166 INFO org.apache.hadoop.yarn.server.resourcemanager.scheduler.common.fica.FiCaSchedulerNode: Assigned container container_1376720997863_0008_01_000001 of capacity <memory:2048, vCores:1> on host hadoop-512-7:43914, which currently has 1 containers, <memory:2048, vCores:1> used and <memory:6144, vCores:15> available
2013-08-17 06:41:25,167 INFO org.apache.hadoop.yarn.server.resourcemanager.scheduler.capacity.LeafQueue: assignedContainer application=application_1376720997863_0008 container=Container: [ContainerId: container_1376720997863_0008_01_000001, NodeId: hadoop-512-7:43914, NodeHttpAddress: hadoop-512-7:8042, Resource: <memory:2048, vCores:1>, Priority: 0, State: NEW, Token: null, Status: container_id {, app_attempt_id {, application_id {, id: 8, cluster_timestamp: 1376720997863, }, attemptId: 1, }, id: 1, }, state: C_NEW, ] containerId=container_1376720997863_0008_01_000001 queue=default: capacity=1.0, absoluteCapacity=1.0, usedResources=<memory:4096, vCores:2>usedCapacity=0.083333336, absoluteUsedCapacity=0.083333336, numApps=5, numContainers=2 usedCapacity=0.083333336 absoluteUsedCapacity=0.083333336 used=<memory:4096, vCores:2> cluster=<memory:49152, vCores:96>
2013-08-17 06:41:25,171 INFO org.apache.hadoop.yarn.server.resourcemanager.rmcontainer.RMContainerImpl: container_1376720997863_0008_01_000001 Container Transitioned from ALLOCATED to ACQUIRED
2013-08-17 06:41:25,171 INFO org.apache.hadoop.yarn.server.resourcemanager.scheduler.capacity.ParentQueue: Re-sorting queues since queue: root.default stats: default: capacity=1.0, absoluteCapacity=1.0, usedResources=<memory:6144, vCores:3>usedCapacity=0.125, absoluteUsedCapacity=0.125, numApps=5, numContainers=3
2013-08-17 06:41:25,171 INFO org.apache.hadoop.yarn.server.resourcemanager.rmapp.attempt.RMAppAttemptImpl: Storing attempt: AppId: application_1376720997863_0008 AttemptId: appattempt_1376720997863_0008_000001 MasterContainer: Container: [ContainerId: container_1376720997863_0008_01_000001, NodeId: hadoop-512-7:43914, NodeHttpAddress: hadoop-512-7:8042, Resource: <memory:2048, vCores:1>, Priority: 0, State: NEW, Token: null, Status: container_id {, app_attempt_id {, application_id {, id: 8, cluster_timestamp: 1376720997863, }, attemptId: 1, }, id: 1, }, state: C_NEW, ]
2013-08-17 06:41:25,172 INFO org.apache.hadoop.yarn.server.resourcemanager.rmapp.attempt.RMAppAttemptImpl: appattempt_1376720997863_0008_000001 State change from SCHEDULED to ALLOCATED_SAVING
2013-08-17 06:41:25,172 INFO org.apache.hadoop.yarn.server.resourcemanager.recovery.RMStateStore: Storing info for attempt: appattempt_1376720997863_0008_000001
2013-08-17 06:41:25,172 INFO org.apache.hadoop.yarn.server.resourcemanager.scheduler.capacity.ParentQueue: assignedContainer queue=root usedCapacity=0.125 absoluteUsedCapacity=0.125 used=<memory:6144, vCores:3> cluster=<memory:49152, vCores:96>
2013-08-17 06:41:25,173 INFO org.apache.hadoop.yarn.server.resourcemanager.rmapp.attempt.RMAppAttemptImpl: appattempt_1376720997863_0008_000001 State change from ALLOCATED_SAVING to ALLOCATED
2013-08-17 06:41:25,173 INFO org.apache.hadoop.yarn.server.resourcemanager.amlauncher.AMLauncher: Launching masterappattempt_1376720997863_0008_000001
2013-08-17 06:41:25,174 INFO org.apache.hadoop.yarn.server.resourcemanager.amlauncher.AMLauncher: Setting up container Container: [ContainerId: container_1376720997863_0008_01_000001, NodeId: hadoop-512-7:43914, NodeHttpAddress: hadoop-512-7:8042, Resource: <memory:2048, vCores:1>, Priority: 0, State: NEW, Token: null, Status: container_id {, app_attempt_id {, application_id {, id: 8, cluster_timestamp: 1376720997863, }, attemptId: 1, }, id: 1, }, state: C_NEW, ] for AM appattempt_1376720997863_0008_000001
2013-08-17 06:41:25,174 INFO org.apache.hadoop.yarn.server.resourcemanager.amlauncher.AMLauncher: Command to launch container container_1376720997863_0008_01_000001 : $JAVA_HOME/bin/java -Dlog4j.configuration=container-log4j.properties -Dyarn.app.mapreduce.container.log.dir=<LOG_DIR> -Dyarn.app.mapreduce.container.log.filesize=0 -Dhadoop.root.logger=INFO,CLA  -Xmx1024m org.apache.hadoop.mapreduce.v2.app.MRAppMaster 1><LOG_DIR>/stdout 2><LOG_DIR>/stderr 
2013-08-17 06:41:25,182 INFO org.apache.hadoop.yarn.server.resourcemanager.rmcontainer.RMContainerImpl: container_1376720997863_0009_01_000001 Container Transitioned from NEW to ALLOCATED
2013-08-17 06:41:25,183 INFO org.apache.hadoop.yarn.server.resourcemanager.RMAuditLogger: USER=ubuntu	OPERATION=AM Allocated Container	TARGET=SchedulerApp	RESULT=SUCCESS	APPID=application_1376720997863_0009	CONTAINERID=container_1376720997863_0009_01_000001
2013-08-17 06:41:25,183 INFO org.apache.hadoop.yarn.server.resourcemanager.scheduler.common.fica.FiCaSchedulerNode: Assigned container container_1376720997863_0009_01_000001 of capacity <memory:2048, vCores:1> on host hadoop-512-2:32923, which currently has 1 containers, <memory:2048, vCores:1> used and <memory:6144, vCores:15> available
2013-08-17 06:41:25,184 INFO org.apache.hadoop.yarn.server.resourcemanager.scheduler.capacity.LeafQueue: assignedContainer application=application_1376720997863_0009 container=Container: [ContainerId: container_1376720997863_0009_01_000001, NodeId: hadoop-512-2:32923, NodeHttpAddress: hadoop-512-2:8042, Resource: <memory:2048, vCores:1>, Priority: 0, State: NEW, Token: null, Status: container_id {, app_attempt_id {, application_id {, id: 9, cluster_timestamp: 1376720997863, }, attemptId: 1, }, id: 1, }, state: C_NEW, ] containerId=container_1376720997863_0009_01_000001 queue=default: capacity=1.0, absoluteCapacity=1.0, usedResources=<memory:6144, vCores:3>usedCapacity=0.125, absoluteUsedCapacity=0.125, numApps=5, numContainers=3 usedCapacity=0.125 absoluteUsedCapacity=0.125 used=<memory:6144, vCores:3> cluster=<memory:49152, vCores:96>
2013-08-17 06:41:25,184 INFO org.apache.hadoop.yarn.server.resourcemanager.scheduler.capacity.ParentQueue: Re-sorting queues since queue: root.default stats: default: capacity=1.0, absoluteCapacity=1.0, usedResources=<memory:8192, vCores:4>usedCapacity=0.16666667, absoluteUsedCapacity=0.16666667, numApps=5, numContainers=4
2013-08-17 06:41:25,185 INFO org.apache.hadoop.yarn.server.resourcemanager.rmcontainer.RMContainerImpl: container_1376720997863_0009_01_000001 Container Transitioned from ALLOCATED to ACQUIRED
2013-08-17 06:41:25,186 INFO org.apache.hadoop.yarn.server.resourcemanager.scheduler.capacity.ParentQueue: assignedContainer queue=root usedCapacity=0.16666667 absoluteUsedCapacity=0.16666667 used=<memory:8192, vCores:4> cluster=<memory:49152, vCores:96>
2013-08-17 06:41:25,186 INFO org.apache.hadoop.yarn.server.resourcemanager.amlauncher.AMLauncher: Done launching container Container: [ContainerId: container_1376720997863_0008_01_000001, NodeId: hadoop-512-7:43914, NodeHttpAddress: hadoop-512-7:8042, Resource: <memory:2048, vCores:1>, Priority: 0, State: NEW, Token: null, Status: container_id {, app_attempt_id {, application_id {, id: 8, cluster_timestamp: 1376720997863, }, attemptId: 1, }, id: 1, }, state: C_NEW, ] for AM appattempt_1376720997863_0008_000001
2013-08-17 06:41:25,186 INFO org.apache.hadoop.yarn.server.resourcemanager.rmapp.attempt.RMAppAttemptImpl: Storing attempt: AppId: application_1376720997863_0009 AttemptId: appattempt_1376720997863_0009_000001 MasterContainer: Container: [ContainerId: container_1376720997863_0009_01_000001, NodeId: hadoop-512-2:32923, NodeHttpAddress: hadoop-512-2:8042, Resource: <memory:2048, vCores:1>, Priority: 0, State: NEW, Token: null, Status: container_id {, app_attempt_id {, application_id {, id: 9, cluster_timestamp: 1376720997863, }, attemptId: 1, }, id: 1, }, state: C_NEW, ]
2013-08-17 06:41:25,186 INFO org.apache.hadoop.yarn.server.resourcemanager.rmapp.attempt.RMAppAttemptImpl: appattempt_1376720997863_0009_000001 State change from SCHEDULED to ALLOCATED_SAVING
2013-08-17 06:41:25,186 INFO org.apache.hadoop.yarn.server.resourcemanager.recovery.RMStateStore: Storing info for attempt: appattempt_1376720997863_0009_000001
2013-08-17 06:41:25,187 INFO org.apache.hadoop.yarn.server.resourcemanager.rmapp.attempt.RMAppAttemptImpl: appattempt_1376720997863_0008_000001 State change from ALLOCATED to LAUNCHED
2013-08-17 06:41:25,187 INFO org.apache.hadoop.yarn.server.resourcemanager.rmapp.attempt.RMAppAttemptImpl: appattempt_1376720997863_0009_000001 State change from ALLOCATED_SAVING to ALLOCATED
2013-08-17 06:41:25,187 INFO org.apache.hadoop.yarn.server.resourcemanager.amlauncher.AMLauncher: Launching masterappattempt_1376720997863_0009_000001
2013-08-17 06:41:25,188 INFO org.apache.hadoop.yarn.server.resourcemanager.amlauncher.AMLauncher: Setting up container Container: [ContainerId: container_1376720997863_0009_01_000001, NodeId: hadoop-512-2:32923, NodeHttpAddress: hadoop-512-2:8042, Resource: <memory:2048, vCores:1>, Priority: 0, State: NEW, Token: null, Status: container_id {, app_attempt_id {, application_id {, id: 9, cluster_timestamp: 1376720997863, }, attemptId: 1, }, id: 1, }, state: C_NEW, ] for AM appattempt_1376720997863_0009_000001
2013-08-17 06:41:25,188 INFO org.apache.hadoop.yarn.server.resourcemanager.amlauncher.AMLauncher: Command to launch container container_1376720997863_0009_01_000001 : $JAVA_HOME/bin/java -Dlog4j.configuration=container-log4j.properties -Dyarn.app.mapreduce.container.log.dir=<LOG_DIR> -Dyarn.app.mapreduce.container.log.filesize=0 -Dhadoop.root.logger=INFO,CLA  -Xmx1024m org.apache.hadoop.mapreduce.v2.app.MRAppMaster 1><LOG_DIR>/stdout 2><LOG_DIR>/stderr 
2013-08-17 06:41:25,201 INFO org.apache.hadoop.yarn.server.resourcemanager.amlauncher.AMLauncher: Done launching container Container: [ContainerId: container_1376720997863_0009_01_000001, NodeId: hadoop-512-2:32923, NodeHttpAddress: hadoop-512-2:8042, Resource: <memory:2048, vCores:1>, Priority: 0, State: NEW, Token: null, Status: container_id {, app_attempt_id {, application_id {, id: 9, cluster_timestamp: 1376720997863, }, attemptId: 1, }, id: 1, }, state: C_NEW, ] for AM appattempt_1376720997863_0009_000001
2013-08-17 06:41:25,201 INFO org.apache.hadoop.yarn.server.resourcemanager.rmapp.attempt.RMAppAttemptImpl: appattempt_1376720997863_0009_000001 State change from ALLOCATED to LAUNCHED
2013-08-17 06:41:25,495 INFO org.apache.hadoop.yarn.server.resourcemanager.rmcontainer.RMContainerImpl: container_1376720997863_0010_01_000001 Container Transitioned from NEW to ALLOCATED
2013-08-17 06:41:25,496 INFO org.apache.hadoop.yarn.server.resourcemanager.RMAuditLogger: USER=ubuntu	OPERATION=AM Allocated Container	TARGET=SchedulerApp	RESULT=SUCCESS	APPID=application_1376720997863_0010	CONTAINERID=container_1376720997863_0010_01_000001
2013-08-17 06:41:25,496 INFO org.apache.hadoop.yarn.server.resourcemanager.scheduler.common.fica.FiCaSchedulerNode: Assigned container container_1376720997863_0010_01_000001 of capacity <memory:2048, vCores:1> on host hadoop-512-3:56071, which currently has 1 containers, <memory:2048, vCores:1> used and <memory:6144, vCores:15> available
2013-08-17 06:41:25,497 INFO org.apache.hadoop.yarn.server.resourcemanager.scheduler.capacity.LeafQueue: assignedContainer application=application_1376720997863_0010 container=Container: [ContainerId: container_1376720997863_0010_01_000001, NodeId: hadoop-512-3:56071, NodeHttpAddress: hadoop-512-3:8042, Resource: <memory:2048, vCores:1>, Priority: 0, State: NEW, Token: null, Status: container_id {, app_attempt_id {, application_id {, id: 10, cluster_timestamp: 1376720997863, }, attemptId: 1, }, id: 1, }, state: C_NEW, ] containerId=container_1376720997863_0010_01_000001 queue=default: capacity=1.0, absoluteCapacity=1.0, usedResources=<memory:8192, vCores:4>usedCapacity=0.16666667, absoluteUsedCapacity=0.16666667, numApps=5, numContainers=4 usedCapacity=0.16666667 absoluteUsedCapacity=0.16666667 used=<memory:8192, vCores:4> cluster=<memory:49152, vCores:96>
2013-08-17 06:41:25,497 INFO org.apache.hadoop.yarn.server.resourcemanager.scheduler.capacity.ParentQueue: Re-sorting queues since queue: root.default stats: default: capacity=1.0, absoluteCapacity=1.0, usedResources=<memory:10240, vCores:5>usedCapacity=0.20833333, absoluteUsedCapacity=0.20833333, numApps=5, numContainers=5
2013-08-17 06:41:25,498 INFO org.apache.hadoop.yarn.server.resourcemanager.scheduler.capacity.ParentQueue: assignedContainer queue=root usedCapacity=0.20833333 absoluteUsedCapacity=0.20833333 used=<memory:10240, vCores:5> cluster=<memory:49152, vCores:96>
2013-08-17 06:41:25,499 INFO org.apache.hadoop.yarn.server.resourcemanager.rmcontainer.RMContainerImpl: container_1376720997863_0010_01_000001 Container Transitioned from ALLOCATED to ACQUIRED
2013-08-17 06:41:25,501 INFO org.apache.hadoop.yarn.server.resourcemanager.rmapp.attempt.RMAppAttemptImpl: Storing attempt: AppId: application_1376720997863_0010 AttemptId: appattempt_1376720997863_0010_000001 MasterContainer: Container: [ContainerId: container_1376720997863_0010_01_000001, NodeId: hadoop-512-3:56071, NodeHttpAddress: hadoop-512-3:8042, Resource: <memory:2048, vCores:1>, Priority: 0, State: NEW, Token: null, Status: container_id {, app_attempt_id {, application_id {, id: 10, cluster_timestamp: 1376720997863, }, attemptId: 1, }, id: 1, }, state: C_NEW, ]
2013-08-17 06:41:25,501 INFO org.apache.hadoop.yarn.server.resourcemanager.rmapp.attempt.RMAppAttemptImpl: appattempt_1376720997863_0010_000001 State change from SCHEDULED to ALLOCATED_SAVING
2013-08-17 06:41:25,501 INFO org.apache.hadoop.yarn.server.resourcemanager.recovery.RMStateStore: Storing info for attempt: appattempt_1376720997863_0010_000001
2013-08-17 06:41:25,502 INFO org.apache.hadoop.yarn.server.resourcemanager.rmapp.attempt.RMAppAttemptImpl: appattempt_1376720997863_0010_000001 State change from ALLOCATED_SAVING to ALLOCATED
2013-08-17 06:41:25,503 INFO org.apache.hadoop.yarn.server.resourcemanager.amlauncher.AMLauncher: Launching masterappattempt_1376720997863_0010_000001
2013-08-17 06:41:25,505 INFO org.apache.hadoop.yarn.server.resourcemanager.amlauncher.AMLauncher: Setting up container Container: [ContainerId: container_1376720997863_0010_01_000001, NodeId: hadoop-512-3:56071, NodeHttpAddress: hadoop-512-3:8042, Resource: <memory:2048, vCores:1>, Priority: 0, State: NEW, Token: null, Status: container_id {, app_attempt_id {, application_id {, id: 10, cluster_timestamp: 1376720997863, }, attemptId: 1, }, id: 1, }, state: C_NEW, ] for AM appattempt_1376720997863_0010_000001
2013-08-17 06:41:25,505 INFO org.apache.hadoop.yarn.server.resourcemanager.amlauncher.AMLauncher: Command to launch container container_1376720997863_0010_01_000001 : $JAVA_HOME/bin/java -Dlog4j.configuration=container-log4j.properties -Dyarn.app.mapreduce.container.log.dir=<LOG_DIR> -Dyarn.app.mapreduce.container.log.filesize=0 -Dhadoop.root.logger=INFO,CLA  -Xmx1024m org.apache.hadoop.mapreduce.v2.app.MRAppMaster 1><LOG_DIR>/stdout 2><LOG_DIR>/stderr 
2013-08-17 06:41:25,519 INFO org.apache.hadoop.yarn.server.resourcemanager.amlauncher.AMLauncher: Done launching container Container: [ContainerId: container_1376720997863_0010_01_000001, NodeId: hadoop-512-3:56071, NodeHttpAddress: hadoop-512-3:8042, Resource: <memory:2048, vCores:1>, Priority: 0, State: NEW, Token: null, Status: container_id {, app_attempt_id {, application_id {, id: 10, cluster_timestamp: 1376720997863, }, attemptId: 1, }, id: 1, }, state: C_NEW, ] for AM appattempt_1376720997863_0010_000001
2013-08-17 06:41:25,520 INFO org.apache.hadoop.yarn.server.resourcemanager.rmapp.attempt.RMAppAttemptImpl: appattempt_1376720997863_0010_000001 State change from ALLOCATED to LAUNCHED
2013-08-17 06:41:26,066 INFO org.apache.hadoop.yarn.server.resourcemanager.rmcontainer.RMContainerImpl: container_1376720997863_0006_01_000001 Container Transitioned from ACQUIRED to RUNNING
2013-08-17 06:41:26,069 INFO org.apache.hadoop.yarn.server.resourcemanager.rmcontainer.RMContainerImpl: container_1376720997863_0007_01_000001 Container Transitioned from ACQUIRED to RUNNING
2013-08-17 06:41:26,173 INFO org.apache.hadoop.yarn.server.resourcemanager.rmcontainer.RMContainerImpl: container_1376720997863_0008_01_000001 Container Transitioned from ACQUIRED to RUNNING
2013-08-17 06:41:26,188 INFO org.apache.hadoop.yarn.server.resourcemanager.rmcontainer.RMContainerImpl: container_1376720997863_0009_01_000001 Container Transitioned from ACQUIRED to RUNNING
2013-08-17 06:41:26,501 INFO org.apache.hadoop.yarn.server.resourcemanager.rmcontainer.RMContainerImpl: container_1376720997863_0010_01_000001 Container Transitioned from ACQUIRED to RUNNING
2013-08-17 06:41:32,011 INFO org.apache.hadoop.yarn.server.resourcemanager.ApplicationMasterService: AM registration appattempt_1376720997863_0007_000001
2013-08-17 06:41:32,011 INFO org.apache.hadoop.yarn.server.resourcemanager.RMAuditLogger: USER=ubuntu	IP=192.168.100.14	OPERATION=Register App Master	TARGET=ApplicationMasterService	RESULT=SUCCESS	APPID=application_1376720997863_0007	APPATTEMPTID=appattempt_1376720997863_0007_000001
2013-08-17 06:41:32,012 INFO org.apache.hadoop.yarn.server.resourcemanager.rmapp.attempt.RMAppAttemptImpl: appattempt_1376720997863_0007_000001 State change from LAUNCHED to RUNNING
2013-08-17 06:41:32,012 INFO org.apache.hadoop.yarn.server.resourcemanager.rmapp.RMAppImpl: application_1376720997863_0007 State change from ACCEPTED to RUNNING
2013-08-17 06:41:32,275 INFO org.apache.hadoop.yarn.server.resourcemanager.ApplicationMasterService: AM registration appattempt_1376720997863_0009_000001
2013-08-17 06:41:32,276 INFO org.apache.hadoop.yarn.server.resourcemanager.RMAuditLogger: USER=ubuntu	IP=192.168.100.26	OPERATION=Register App Master	TARGET=ApplicationMasterService	RESULT=SUCCESS	APPID=application_1376720997863_0009	APPATTEMPTID=appattempt_1376720997863_0009_000001
2013-08-17 06:41:32,276 INFO org.apache.hadoop.yarn.server.resourcemanager.rmapp.attempt.RMAppAttemptImpl: appattempt_1376720997863_0009_000001 State change from LAUNCHED to RUNNING
2013-08-17 06:41:32,277 INFO org.apache.hadoop.yarn.server.resourcemanager.rmapp.RMAppImpl: application_1376720997863_0009 State change from ACCEPTED to RUNNING
2013-08-17 06:41:32,736 INFO org.apache.hadoop.yarn.server.resourcemanager.ApplicationMasterService: AM registration appattempt_1376720997863_0008_000001
2013-08-17 06:41:32,736 INFO org.apache.hadoop.yarn.server.resourcemanager.ApplicationMasterService: AM registration appattempt_1376720997863_0006_000001
2013-08-17 06:41:32,736 INFO org.apache.hadoop.yarn.server.resourcemanager.RMAuditLogger: USER=ubuntu	IP=192.168.100.36	OPERATION=Register App Master	TARGET=ApplicationMasterService	RESULT=SUCCESS	APPID=application_1376720997863_0008	APPATTEMPTID=appattempt_1376720997863_0008_000001
2013-08-17 06:41:32,736 INFO org.apache.hadoop.yarn.server.resourcemanager.RMAuditLogger: USER=ubuntu	IP=192.168.100.15	OPERATION=Register App Master	TARGET=ApplicationMasterService	RESULT=SUCCESS	APPID=application_1376720997863_0006	APPATTEMPTID=appattempt_1376720997863_0006_000001
2013-08-17 06:41:32,737 INFO org.apache.hadoop.yarn.server.resourcemanager.rmapp.attempt.RMAppAttemptImpl: appattempt_1376720997863_0008_000001 State change from LAUNCHED to RUNNING
2013-08-17 06:41:32,738 INFO org.apache.hadoop.yarn.server.resourcemanager.rmapp.attempt.RMAppAttemptImpl: appattempt_1376720997863_0006_000001 State change from LAUNCHED to RUNNING
2013-08-17 06:41:32,738 INFO org.apache.hadoop.yarn.server.resourcemanager.rmapp.RMAppImpl: application_1376720997863_0008 State change from ACCEPTED to RUNNING
2013-08-17 06:41:32,738 INFO org.apache.hadoop.yarn.server.resourcemanager.rmapp.RMAppImpl: application_1376720997863_0006 State change from ACCEPTED to RUNNING
2013-08-17 06:41:33,098 INFO org.apache.hadoop.yarn.server.resourcemanager.rmcontainer.RMContainerImpl: container_1376720997863_0007_01_000002 Container Transitioned from NEW to ALLOCATED
2013-08-17 06:41:33,099 INFO org.apache.hadoop.yarn.server.resourcemanager.RMAuditLogger: USER=ubuntu	OPERATION=AM Allocated Container	TARGET=SchedulerApp	RESULT=SUCCESS	APPID=application_1376720997863_0007	CONTAINERID=container_1376720997863_0007_01_000002
2013-08-17 06:41:33,099 INFO org.apache.hadoop.yarn.server.resourcemanager.scheduler.common.fica.FiCaSchedulerNode: Assigned container container_1376720997863_0007_01_000002 of capacity <memory:1024, vCores:1> on host hadoop-512-5:45082, which currently has 2 containers, <memory:3072, vCores:2> used and <memory:5120, vCores:14> available
2013-08-17 06:41:33,100 INFO org.apache.hadoop.yarn.server.resourcemanager.scheduler.capacity.LeafQueue: assignedContainer application=application_1376720997863_0007 container=Container: [ContainerId: container_1376720997863_0007_01_000002, NodeId: hadoop-512-5:45082, NodeHttpAddress: hadoop-512-5:8042, Resource: <memory:1024, vCores:1>, Priority: 20, State: NEW, Token: null, Status: container_id {, app_attempt_id {, application_id {, id: 7, cluster_timestamp: 1376720997863, }, attemptId: 1, }, id: 2, }, state: C_NEW, ] containerId=container_1376720997863_0007_01_000002 queue=default: capacity=1.0, absoluteCapacity=1.0, usedResources=<memory:10240, vCores:5>usedCapacity=0.20833333, absoluteUsedCapacity=0.20833333, numApps=5, numContainers=5 usedCapacity=0.20833333 absoluteUsedCapacity=0.20833333 used=<memory:10240, vCores:5> cluster=<memory:49152, vCores:96>
2013-08-17 06:41:33,100 INFO org.apache.hadoop.yarn.server.resourcemanager.scheduler.capacity.ParentQueue: Re-sorting queues since queue: root.default stats: default: capacity=1.0, absoluteCapacity=1.0, usedResources=<memory:11264, vCores:6>usedCapacity=0.22916667, absoluteUsedCapacity=0.22916667, numApps=5, numContainers=6
2013-08-17 06:41:33,100 INFO org.apache.hadoop.yarn.server.resourcemanager.scheduler.capacity.ParentQueue: assignedContainer queue=root usedCapacity=0.22916667 absoluteUsedCapacity=0.22916667 used=<memory:11264, vCores:6> cluster=<memory:49152, vCores:96>
2013-08-17 06:41:33,101 INFO org.apache.hadoop.yarn.server.resourcemanager.rmcontainer.RMContainerImpl: container_1376720997863_0007_01_000003 Container Transitioned from NEW to ALLOCATED
2013-08-17 06:41:33,101 INFO org.apache.hadoop.yarn.server.resourcemanager.RMAuditLogger: USER=ubuntu	OPERATION=AM Allocated Container	TARGET=SchedulerApp	RESULT=SUCCESS	APPID=application_1376720997863_0007	CONTAINERID=container_1376720997863_0007_01_000003
2013-08-17 06:41:33,101 INFO org.apache.hadoop.yarn.server.resourcemanager.scheduler.common.fica.FiCaSchedulerNode: Assigned container container_1376720997863_0007_01_000003 of capacity <memory:1024, vCores:1> on host hadoop-512-5:45082, which currently has 3 containers, <memory:4096, vCores:3> used and <memory:4096, vCores:13> available
2013-08-17 06:41:33,102 INFO org.apache.hadoop.yarn.server.resourcemanager.scheduler.capacity.LeafQueue: assignedContainer application=application_1376720997863_0007 container=Container: [ContainerId: container_1376720997863_0007_01_000003, NodeId: hadoop-512-5:45082, NodeHttpAddress: hadoop-512-5:8042, Resource: <memory:1024, vCores:1>, Priority: 20, State: NEW, Token: null, Status: container_id {, app_attempt_id {, application_id {, id: 7, cluster_timestamp: 1376720997863, }, attemptId: 1, }, id: 3, }, state: C_NEW, ] containerId=container_1376720997863_0007_01_000003 queue=default: capacity=1.0, absoluteCapacity=1.0, usedResources=<memory:11264, vCores:6>usedCapacity=0.22916667, absoluteUsedCapacity=0.22916667, numApps=5, numContainers=6 usedCapacity=0.22916667 absoluteUsedCapacity=0.22916667 used=<memory:11264, vCores:6> cluster=<memory:49152, vCores:96>
2013-08-17 06:41:33,102 INFO org.apache.hadoop.yarn.server.resourcemanager.scheduler.capacity.ParentQueue: Re-sorting queues since queue: root.default stats: default: capacity=1.0, absoluteCapacity=1.0, usedResources=<memory:12288, vCores:7>usedCapacity=0.25, absoluteUsedCapacity=0.25, numApps=5, numContainers=7
2013-08-17 06:41:33,103 INFO org.apache.hadoop.yarn.server.resourcemanager.scheduler.capacity.ParentQueue: assignedContainer queue=root usedCapacity=0.25 absoluteUsedCapacity=0.25 used=<memory:12288, vCores:7> cluster=<memory:49152, vCores:96>
2013-08-17 06:41:33,103 INFO org.apache.hadoop.yarn.server.resourcemanager.rmcontainer.RMContainerImpl: container_1376720997863_0007_01_000004 Container Transitioned from NEW to ALLOCATED
2013-08-17 06:41:33,103 INFO org.apache.hadoop.yarn.server.resourcemanager.RMAuditLogger: USER=ubuntu	OPERATION=AM Allocated Container	TARGET=SchedulerApp	RESULT=SUCCESS	APPID=application_1376720997863_0007	CONTAINERID=container_1376720997863_0007_01_000004
2013-08-17 06:41:33,103 INFO org.apache.hadoop.yarn.server.resourcemanager.scheduler.common.fica.FiCaSchedulerNode: Assigned container container_1376720997863_0007_01_000004 of capacity <memory:1024, vCores:1> on host hadoop-512-5:45082, which currently has 4 containers, <memory:5120, vCores:4> used and <memory:3072, vCores:12> available
2013-08-17 06:41:33,104 INFO org.apache.hadoop.yarn.server.resourcemanager.scheduler.capacity.LeafQueue: assignedContainer application=application_1376720997863_0007 container=Container: [ContainerId: container_1376720997863_0007_01_000004, NodeId: hadoop-512-5:45082, NodeHttpAddress: hadoop-512-5:8042, Resource: <memory:1024, vCores:1>, Priority: 20, State: NEW, Token: null, Status: container_id {, app_attempt_id {, application_id {, id: 7, cluster_timestamp: 1376720997863, }, attemptId: 1, }, id: 4, }, state: C_NEW, ] containerId=container_1376720997863_0007_01_000004 queue=default: capacity=1.0, absoluteCapacity=1.0, usedResources=<memory:12288, vCores:7>usedCapacity=0.25, absoluteUsedCapacity=0.25, numApps=5, numContainers=7 usedCapacity=0.25 absoluteUsedCapacity=0.25 used=<memory:12288, vCores:7> cluster=<memory:49152, vCores:96>
2013-08-17 06:41:33,104 INFO org.apache.hadoop.yarn.server.resourcemanager.scheduler.capacity.ParentQueue: Re-sorting queues since queue: root.default stats: default: capacity=1.0, absoluteCapacity=1.0, usedResources=<memory:13312, vCores:8>usedCapacity=0.27083334, absoluteUsedCapacity=0.27083334, numApps=5, numContainers=8
2013-08-17 06:41:33,105 INFO org.apache.hadoop.yarn.server.resourcemanager.scheduler.capacity.ParentQueue: assignedContainer queue=root usedCapacity=0.27083334 absoluteUsedCapacity=0.27083334 used=<memory:13312, vCores:8> cluster=<memory:49152, vCores:96>
2013-08-17 06:41:33,105 INFO org.apache.hadoop.yarn.server.resourcemanager.rmcontainer.RMContainerImpl: container_1376720997863_0007_01_000005 Container Transitioned from NEW to ALLOCATED
2013-08-17 06:41:33,105 INFO org.apache.hadoop.yarn.server.resourcemanager.RMAuditLogger: USER=ubuntu	OPERATION=AM Allocated Container	TARGET=SchedulerApp	RESULT=SUCCESS	APPID=application_1376720997863_0007	CONTAINERID=container_1376720997863_0007_01_000005
2013-08-17 06:41:33,105 INFO org.apache.hadoop.yarn.server.resourcemanager.scheduler.common.fica.FiCaSchedulerNode: Assigned container container_1376720997863_0007_01_000005 of capacity <memory:1024, vCores:1> on host hadoop-512-5:45082, which currently has 5 containers, <memory:6144, vCores:5> used and <memory:2048, vCores:11> available
2013-08-17 06:41:33,106 INFO org.apache.hadoop.yarn.server.resourcemanager.scheduler.capacity.LeafQueue: assignedContainer application=application_1376720997863_0007 container=Container: [ContainerId: container_1376720997863_0007_01_000005, NodeId: hadoop-512-5:45082, NodeHttpAddress: hadoop-512-5:8042, Resource: <memory:1024, vCores:1>, Priority: 20, State: NEW, Token: null, Status: container_id {, app_attempt_id {, application_id {, id: 7, cluster_timestamp: 1376720997863, }, attemptId: 1, }, id: 5, }, state: C_NEW, ] containerId=container_1376720997863_0007_01_000005 queue=default: capacity=1.0, absoluteCapacity=1.0, usedResources=<memory:13312, vCores:8>usedCapacity=0.27083334, absoluteUsedCapacity=0.27083334, numApps=5, numContainers=8 usedCapacity=0.27083334 absoluteUsedCapacity=0.27083334 used=<memory:13312, vCores:8> cluster=<memory:49152, vCores:96>
2013-08-17 06:41:33,106 INFO org.apache.hadoop.yarn.server.resourcemanager.scheduler.capacity.ParentQueue: Re-sorting queues since queue: root.default stats: default: capacity=1.0, absoluteCapacity=1.0, usedResources=<memory:14336, vCores:9>usedCapacity=0.29166666, absoluteUsedCapacity=0.29166666, numApps=5, numContainers=9
2013-08-17 06:41:33,107 INFO org.apache.hadoop.yarn.server.resourcemanager.scheduler.capacity.ParentQueue: assignedContainer queue=root usedCapacity=0.29166666 absoluteUsedCapacity=0.29166666 used=<memory:14336, vCores:9> cluster=<memory:49152, vCores:96>
2013-08-17 06:41:33,107 INFO org.apache.hadoop.yarn.server.resourcemanager.rmcontainer.RMContainerImpl: container_1376720997863_0007_01_000006 Container Transitioned from NEW to ALLOCATED
2013-08-17 06:41:33,107 INFO org.apache.hadoop.yarn.server.resourcemanager.RMAuditLogger: USER=ubuntu	OPERATION=AM Allocated Container	TARGET=SchedulerApp	RESULT=SUCCESS	APPID=application_1376720997863_0007	CONTAINERID=container_1376720997863_0007_01_000006
2013-08-17 06:41:33,107 INFO org.apache.hadoop.yarn.server.resourcemanager.scheduler.common.fica.FiCaSchedulerNode: Assigned container container_1376720997863_0007_01_000006 of capacity <memory:1024, vCores:1> on host hadoop-512-5:45082, which currently has 6 containers, <memory:7168, vCores:6> used and <memory:1024, vCores:10> available
2013-08-17 06:41:33,108 INFO org.apache.hadoop.yarn.server.resourcemanager.scheduler.capacity.LeafQueue: assignedContainer application=application_1376720997863_0007 container=Container: [ContainerId: container_1376720997863_0007_01_000006, NodeId: hadoop-512-5:45082, NodeHttpAddress: hadoop-512-5:8042, Resource: <memory:1024, vCores:1>, Priority: 20, State: NEW, Token: null, Status: container_id {, app_attempt_id {, application_id {, id: 7, cluster_timestamp: 1376720997863, }, attemptId: 1, }, id: 6, }, state: C_NEW, ] containerId=container_1376720997863_0007_01_000006 queue=default: capacity=1.0, absoluteCapacity=1.0, usedResources=<memory:14336, vCores:9>usedCapacity=0.29166666, absoluteUsedCapacity=0.29166666, numApps=5, numContainers=9 usedCapacity=0.29166666 absoluteUsedCapacity=0.29166666 used=<memory:14336, vCores:9> cluster=<memory:49152, vCores:96>
2013-08-17 06:41:33,109 INFO org.apache.hadoop.yarn.server.resourcemanager.scheduler.capacity.ParentQueue: Re-sorting queues since queue: root.default stats: default: capacity=1.0, absoluteCapacity=1.0, usedResources=<memory:15360, vCores:10>usedCapacity=0.3125, absoluteUsedCapacity=0.3125, numApps=5, numContainers=10
2013-08-17 06:41:33,109 INFO org.apache.hadoop.yarn.server.resourcemanager.scheduler.capacity.ParentQueue: assignedContainer queue=root usedCapacity=0.3125 absoluteUsedCapacity=0.3125 used=<memory:15360, vCores:10> cluster=<memory:49152, vCores:96>
2013-08-17 06:41:33,109 INFO org.apache.hadoop.yarn.server.resourcemanager.rmcontainer.RMContainerImpl: container_1376720997863_0007_01_000007 Container Transitioned from NEW to ALLOCATED
2013-08-17 06:41:33,109 INFO org.apache.hadoop.yarn.server.resourcemanager.RMAuditLogger: USER=ubuntu	OPERATION=AM Allocated Container	TARGET=SchedulerApp	RESULT=SUCCESS	APPID=application_1376720997863_0007	CONTAINERID=container_1376720997863_0007_01_000007
2013-08-17 06:41:33,109 INFO org.apache.hadoop.yarn.server.resourcemanager.scheduler.common.fica.FiCaSchedulerNode: Assigned container container_1376720997863_0007_01_000007 of capacity <memory:1024, vCores:1> on host hadoop-512-5:45082, which currently has 7 containers, <memory:8192, vCores:7> used and <memory:0, vCores:9> available
2013-08-17 06:41:33,110 INFO org.apache.hadoop.yarn.server.resourcemanager.scheduler.capacity.LeafQueue: assignedContainer application=application_1376720997863_0007 container=Container: [ContainerId: container_1376720997863_0007_01_000007, NodeId: hadoop-512-5:45082, NodeHttpAddress: hadoop-512-5:8042, Resource: <memory:1024, vCores:1>, Priority: 20, State: NEW, Token: null, Status: container_id {, app_attempt_id {, application_id {, id: 7, cluster_timestamp: 1376720997863, }, attemptId: 1, }, id: 7, }, state: C_NEW, ] containerId=container_1376720997863_0007_01_000007 queue=default: capacity=1.0, absoluteCapacity=1.0, usedResources=<memory:15360, vCores:10>usedCapacity=0.3125, absoluteUsedCapacity=0.3125, numApps=5, numContainers=10 usedCapacity=0.3125 absoluteUsedCapacity=0.3125 used=<memory:15360, vCores:10> cluster=<memory:49152, vCores:96>
2013-08-17 06:41:33,111 INFO org.apache.hadoop.yarn.server.resourcemanager.scheduler.capacity.ParentQueue: Re-sorting queues since queue: root.default stats: default: capacity=1.0, absoluteCapacity=1.0, usedResources=<memory:16384, vCores:11>usedCapacity=0.33333334, absoluteUsedCapacity=0.33333334, numApps=5, numContainers=11
2013-08-17 06:41:33,111 INFO org.apache.hadoop.yarn.server.resourcemanager.scheduler.capacity.ParentQueue: assignedContainer queue=root usedCapacity=0.33333334 absoluteUsedCapacity=0.33333334 used=<memory:16384, vCores:11> cluster=<memory:49152, vCores:96>
2013-08-17 06:41:33,111 INFO org.apache.hadoop.yarn.server.resourcemanager.rmcontainer.RMContainerImpl: container_1376720997863_0007_01_000008 Container Transitioned from NEW to ALLOCATED
2013-08-17 06:41:33,111 INFO org.apache.hadoop.yarn.server.resourcemanager.RMAuditLogger: USER=ubuntu	OPERATION=AM Allocated Container	TARGET=SchedulerApp	RESULT=SUCCESS	APPID=application_1376720997863_0007	CONTAINERID=container_1376720997863_0007_01_000008
2013-08-17 06:41:33,111 INFO org.apache.hadoop.yarn.server.resourcemanager.scheduler.common.fica.FiCaSchedulerNode: Assigned container container_1376720997863_0007_01_000008 of capacity <memory:1024, vCores:1> on host hadoop-512-4:45085, which currently has 2 containers, <memory:3072, vCores:2> used and <memory:5120, vCores:14> available
2013-08-17 06:41:33,112 INFO org.apache.hadoop.yarn.server.resourcemanager.scheduler.capacity.LeafQueue: assignedContainer application=application_1376720997863_0007 container=Container: [ContainerId: container_1376720997863_0007_01_000008, NodeId: hadoop-512-4:45085, NodeHttpAddress: hadoop-512-4:8042, Resource: <memory:1024, vCores:1>, Priority: 20, State: NEW, Token: null, Status: container_id {, app_attempt_id {, application_id {, id: 7, cluster_timestamp: 1376720997863, }, attemptId: 1, }, id: 8, }, state: C_NEW, ] containerId=container_1376720997863_0007_01_000008 queue=default: capacity=1.0, absoluteCapacity=1.0, usedResources=<memory:16384, vCores:11>usedCapacity=0.33333334, absoluteUsedCapacity=0.33333334, numApps=5, numContainers=11 usedCapacity=0.33333334 absoluteUsedCapacity=0.33333334 used=<memory:16384, vCores:11> cluster=<memory:49152, vCores:96>
2013-08-17 06:41:33,113 INFO org.apache.hadoop.yarn.server.resourcemanager.scheduler.capacity.ParentQueue: Re-sorting queues since queue: root.default stats: default: capacity=1.0, absoluteCapacity=1.0, usedResources=<memory:17408, vCores:12>usedCapacity=0.35416666, absoluteUsedCapacity=0.35416666, numApps=5, numContainers=12
2013-08-17 06:41:33,113 INFO org.apache.hadoop.yarn.server.resourcemanager.scheduler.capacity.ParentQueue: assignedContainer queue=root usedCapacity=0.35416666 absoluteUsedCapacity=0.35416666 used=<memory:17408, vCores:12> cluster=<memory:49152, vCores:96>
2013-08-17 06:41:33,113 INFO org.apache.hadoop.yarn.server.resourcemanager.rmcontainer.RMContainerImpl: container_1376720997863_0007_01_000009 Container Transitioned from NEW to ALLOCATED
2013-08-17 06:41:33,113 INFO org.apache.hadoop.yarn.server.resourcemanager.RMAuditLogger: USER=ubuntu	OPERATION=AM Allocated Container	TARGET=SchedulerApp	RESULT=SUCCESS	APPID=application_1376720997863_0007	CONTAINERID=container_1376720997863_0007_01_000009
2013-08-17 06:41:33,114 INFO org.apache.hadoop.yarn.server.resourcemanager.scheduler.common.fica.FiCaSchedulerNode: Assigned container container_1376720997863_0007_01_000009 of capacity <memory:1024, vCores:1> on host hadoop-512-4:45085, which currently has 3 containers, <memory:4096, vCores:3> used and <memory:4096, vCores:13> available
2013-08-17 06:41:33,114 INFO org.apache.hadoop.yarn.server.resourcemanager.scheduler.capacity.LeafQueue: assignedContainer application=application_1376720997863_0007 container=Container: [ContainerId: container_1376720997863_0007_01_000009, NodeId: hadoop-512-4:45085, NodeHttpAddress: hadoop-512-4:8042, Resource: <memory:1024, vCores:1>, Priority: 20, State: NEW, Token: null, Status: container_id {, app_attempt_id {, application_id {, id: 7, cluster_timestamp: 1376720997863, }, attemptId: 1, }, id: 9, }, state: C_NEW, ] containerId=container_1376720997863_0007_01_000009 queue=default: capacity=1.0, absoluteCapacity=1.0, usedResources=<memory:17408, vCores:12>usedCapacity=0.35416666, absoluteUsedCapacity=0.35416666, numApps=5, numContainers=12 usedCapacity=0.35416666 absoluteUsedCapacity=0.35416666 used=<memory:17408, vCores:12> cluster=<memory:49152, vCores:96>
2013-08-17 06:41:33,115 INFO org.apache.hadoop.yarn.server.resourcemanager.scheduler.capacity.ParentQueue: Re-sorting queues since queue: root.default stats: default: capacity=1.0, absoluteCapacity=1.0, usedResources=<memory:18432, vCores:13>usedCapacity=0.375, absoluteUsedCapacity=0.375, numApps=5, numContainers=13
2013-08-17 06:41:33,115 INFO org.apache.hadoop.yarn.server.resourcemanager.scheduler.capacity.ParentQueue: assignedContainer queue=root usedCapacity=0.375 absoluteUsedCapacity=0.375 used=<memory:18432, vCores:13> cluster=<memory:49152, vCores:96>
2013-08-17 06:41:33,115 INFO org.apache.hadoop.yarn.server.resourcemanager.rmcontainer.RMContainerImpl: container_1376720997863_0007_01_000010 Container Transitioned from NEW to ALLOCATED
2013-08-17 06:41:33,115 INFO org.apache.hadoop.yarn.server.resourcemanager.RMAuditLogger: USER=ubuntu	OPERATION=AM Allocated Container	TARGET=SchedulerApp	RESULT=SUCCESS	APPID=application_1376720997863_0007	CONTAINERID=container_1376720997863_0007_01_000010
2013-08-17 06:41:33,116 INFO org.apache.hadoop.yarn.server.resourcemanager.scheduler.common.fica.FiCaSchedulerNode: Assigned container container_1376720997863_0007_01_000010 of capacity <memory:1024, vCores:1> on host hadoop-512-4:45085, which currently has 4 containers, <memory:5120, vCores:4> used and <memory:3072, vCores:12> available
2013-08-17 06:41:33,117 INFO org.apache.hadoop.yarn.server.resourcemanager.scheduler.capacity.LeafQueue: assignedContainer application=application_1376720997863_0007 container=Container: [ContainerId: container_1376720997863_0007_01_000010, NodeId: hadoop-512-4:45085, NodeHttpAddress: hadoop-512-4:8042, Resource: <memory:1024, vCores:1>, Priority: 20, State: NEW, Token: null, Status: container_id {, app_attempt_id {, application_id {, id: 7, cluster_timestamp: 1376720997863, }, attemptId: 1, }, id: 10, }, state: C_NEW, ] containerId=container_1376720997863_0007_01_000010 queue=default: capacity=1.0, absoluteCapacity=1.0, usedResources=<memory:18432, vCores:13>usedCapacity=0.375, absoluteUsedCapacity=0.375, numApps=5, numContainers=13 usedCapacity=0.375 absoluteUsedCapacity=0.375 used=<memory:18432, vCores:13> cluster=<memory:49152, vCores:96>
2013-08-17 06:41:33,117 INFO org.apache.hadoop.yarn.server.resourcemanager.scheduler.capacity.ParentQueue: Re-sorting queues since queue: root.default stats: default: capacity=1.0, absoluteCapacity=1.0, usedResources=<memory:19456, vCores:14>usedCapacity=0.39583334, absoluteUsedCapacity=0.39583334, numApps=5, numContainers=14
2013-08-17 06:41:33,117 INFO org.apache.hadoop.yarn.server.resourcemanager.scheduler.capacity.ParentQueue: assignedContainer queue=root usedCapacity=0.39583334 absoluteUsedCapacity=0.39583334 used=<memory:19456, vCores:14> cluster=<memory:49152, vCores:96>
2013-08-17 06:41:33,117 INFO org.apache.hadoop.yarn.server.resourcemanager.rmcontainer.RMContainerImpl: container_1376720997863_0007_01_000011 Container Transitioned from NEW to ALLOCATED
2013-08-17 06:41:33,118 INFO org.apache.hadoop.yarn.server.resourcemanager.RMAuditLogger: USER=ubuntu	OPERATION=AM Allocated Container	TARGET=SchedulerApp	RESULT=SUCCESS	APPID=application_1376720997863_0007	CONTAINERID=container_1376720997863_0007_01_000011
2013-08-17 06:41:33,118 INFO org.apache.hadoop.yarn.server.resourcemanager.scheduler.common.fica.FiCaSchedulerNode: Assigned container container_1376720997863_0007_01_000011 of capacity <memory:1024, vCores:1> on host hadoop-512-4:45085, which currently has 5 containers, <memory:6144, vCores:5> used and <memory:2048, vCores:11> available
2013-08-17 06:41:33,119 INFO org.apache.hadoop.yarn.server.resourcemanager.scheduler.capacity.LeafQueue: assignedContainer application=application_1376720997863_0007 container=Container: [ContainerId: container_1376720997863_0007_01_000011, NodeId: hadoop-512-4:45085, NodeHttpAddress: hadoop-512-4:8042, Resource: <memory:1024, vCores:1>, Priority: 20, State: NEW, Token: null, Status: container_id {, app_attempt_id {, application_id {, id: 7, cluster_timestamp: 1376720997863, }, attemptId: 1, }, id: 11, }, state: C_NEW, ] containerId=container_1376720997863_0007_01_000011 queue=default: capacity=1.0, absoluteCapacity=1.0, usedResources=<memory:19456, vCores:14>usedCapacity=0.39583334, absoluteUsedCapacity=0.39583334, numApps=5, numContainers=14 usedCapacity=0.39583334 absoluteUsedCapacity=0.39583334 used=<memory:19456, vCores:14> cluster=<memory:49152, vCores:96>
2013-08-17 06:41:33,119 INFO org.apache.hadoop.yarn.server.resourcemanager.scheduler.capacity.ParentQueue: Re-sorting queues since queue: root.default stats: default: capacity=1.0, absoluteCapacity=1.0, usedResources=<memory:20480, vCores:15>usedCapacity=0.41666666, absoluteUsedCapacity=0.41666666, numApps=5, numContainers=15
2013-08-17 06:41:33,119 INFO org.apache.hadoop.yarn.server.resourcemanager.scheduler.capacity.ParentQueue: assignedContainer queue=root usedCapacity=0.41666666 absoluteUsedCapacity=0.41666666 used=<memory:20480, vCores:15> cluster=<memory:49152, vCores:96>
2013-08-17 06:41:33,120 INFO org.apache.hadoop.yarn.server.resourcemanager.rmcontainer.RMContainerImpl: container_1376720997863_0007_01_000012 Container Transitioned from NEW to ALLOCATED
2013-08-17 06:41:33,120 INFO org.apache.hadoop.yarn.server.resourcemanager.RMAuditLogger: USER=ubuntu	OPERATION=AM Allocated Container	TARGET=SchedulerApp	RESULT=SUCCESS	APPID=application_1376720997863_0007	CONTAINERID=container_1376720997863_0007_01_000012
2013-08-17 06:41:33,120 INFO org.apache.hadoop.yarn.server.resourcemanager.scheduler.common.fica.FiCaSchedulerNode: Assigned container container_1376720997863_0007_01_000012 of capacity <memory:1024, vCores:1> on host hadoop-512-4:45085, which currently has 6 containers, <memory:7168, vCores:6> used and <memory:1024, vCores:10> available
2013-08-17 06:41:33,121 INFO org.apache.hadoop.yarn.server.resourcemanager.scheduler.capacity.LeafQueue: assignedContainer application=application_1376720997863_0007 container=Container: [ContainerId: container_1376720997863_0007_01_000012, NodeId: hadoop-512-4:45085, NodeHttpAddress: hadoop-512-4:8042, Resource: <memory:1024, vCores:1>, Priority: 20, State: NEW, Token: null, Status: container_id {, app_attempt_id {, application_id {, id: 7, cluster_timestamp: 1376720997863, }, attemptId: 1, }, id: 12, }, state: C_NEW, ] containerId=container_1376720997863_0007_01_000012 queue=default: capacity=1.0, absoluteCapacity=1.0, usedResources=<memory:20480, vCores:15>usedCapacity=0.41666666, absoluteUsedCapacity=0.41666666, numApps=5, numContainers=15 usedCapacity=0.41666666 absoluteUsedCapacity=0.41666666 used=<memory:20480, vCores:15> cluster=<memory:49152, vCores:96>
2013-08-17 06:41:33,121 INFO org.apache.hadoop.yarn.server.resourcemanager.scheduler.capacity.ParentQueue: Re-sorting queues since queue: root.default stats: default: capacity=1.0, absoluteCapacity=1.0, usedResources=<memory:21504, vCores:16>usedCapacity=0.4375, absoluteUsedCapacity=0.4375, numApps=5, numContainers=16
2013-08-17 06:41:33,121 INFO org.apache.hadoop.yarn.server.resourcemanager.scheduler.capacity.ParentQueue: assignedContainer queue=root usedCapacity=0.4375 absoluteUsedCapacity=0.4375 used=<memory:21504, vCores:16> cluster=<memory:49152, vCores:96>
2013-08-17 06:41:33,122 INFO org.apache.hadoop.yarn.server.resourcemanager.rmcontainer.RMContainerImpl: container_1376720997863_0007_01_000013 Container Transitioned from NEW to ALLOCATED
2013-08-17 06:41:33,122 INFO org.apache.hadoop.yarn.server.resourcemanager.RMAuditLogger: USER=ubuntu	OPERATION=AM Allocated Container	TARGET=SchedulerApp	RESULT=SUCCESS	APPID=application_1376720997863_0007	CONTAINERID=container_1376720997863_0007_01_000013
2013-08-17 06:41:33,122 INFO org.apache.hadoop.yarn.server.resourcemanager.scheduler.common.fica.FiCaSchedulerNode: Assigned container container_1376720997863_0007_01_000013 of capacity <memory:1024, vCores:1> on host hadoop-512-4:45085, which currently has 7 containers, <memory:8192, vCores:7> used and <memory:0, vCores:9> available
2013-08-17 06:41:33,123 INFO org.apache.hadoop.yarn.server.resourcemanager.scheduler.capacity.LeafQueue: assignedContainer application=application_1376720997863_0007 container=Container: [ContainerId: container_1376720997863_0007_01_000013, NodeId: hadoop-512-4:45085, NodeHttpAddress: hadoop-512-4:8042, Resource: <memory:1024, vCores:1>, Priority: 20, State: NEW, Token: null, Status: container_id {, app_attempt_id {, application_id {, id: 7, cluster_timestamp: 1376720997863, }, attemptId: 1, }, id: 13, }, state: C_NEW, ] containerId=container_1376720997863_0007_01_000013 queue=default: capacity=1.0, absoluteCapacity=1.0, usedResources=<memory:21504, vCores:16>usedCapacity=0.4375, absoluteUsedCapacity=0.4375, numApps=5, numContainers=16 usedCapacity=0.4375 absoluteUsedCapacity=0.4375 used=<memory:21504, vCores:16> cluster=<memory:49152, vCores:96>
2013-08-17 06:41:33,123 INFO org.apache.hadoop.yarn.server.resourcemanager.scheduler.capacity.ParentQueue: Re-sorting queues since queue: root.default stats: default: capacity=1.0, absoluteCapacity=1.0, usedResources=<memory:22528, vCores:17>usedCapacity=0.45833334, absoluteUsedCapacity=0.45833334, numApps=5, numContainers=17
2013-08-17 06:41:33,123 INFO org.apache.hadoop.yarn.server.resourcemanager.scheduler.capacity.ParentQueue: assignedContainer queue=root usedCapacity=0.45833334 absoluteUsedCapacity=0.45833334 used=<memory:22528, vCores:17> cluster=<memory:49152, vCores:96>
2013-08-17 06:41:33,211 INFO org.apache.hadoop.yarn.server.resourcemanager.rmcontainer.RMContainerImpl: container_1376720997863_0007_01_000014 Container Transitioned from NEW to ALLOCATED
2013-08-17 06:41:33,211 INFO org.apache.hadoop.yarn.server.resourcemanager.RMAuditLogger: USER=ubuntu	OPERATION=AM Allocated Container	TARGET=SchedulerApp	RESULT=SUCCESS	APPID=application_1376720997863_0007	CONTAINERID=container_1376720997863_0007_01_000014
2013-08-17 06:41:33,211 INFO org.apache.hadoop.yarn.server.resourcemanager.scheduler.common.fica.FiCaSchedulerNode: Assigned container container_1376720997863_0007_01_000014 of capacity <memory:1024, vCores:1> on host hadoop-512-7:43914, which currently has 2 containers, <memory:3072, vCores:2> used and <memory:5120, vCores:14> available
2013-08-17 06:41:33,212 INFO org.apache.hadoop.yarn.server.resourcemanager.scheduler.capacity.LeafQueue: assignedContainer application=application_1376720997863_0007 container=Container: [ContainerId: container_1376720997863_0007_01_000014, NodeId: hadoop-512-7:43914, NodeHttpAddress: hadoop-512-7:8042, Resource: <memory:1024, vCores:1>, Priority: 20, State: NEW, Token: null, Status: container_id {, app_attempt_id {, application_id {, id: 7, cluster_timestamp: 1376720997863, }, attemptId: 1, }, id: 14, }, state: C_NEW, ] containerId=container_1376720997863_0007_01_000014 queue=default: capacity=1.0, absoluteCapacity=1.0, usedResources=<memory:22528, vCores:17>usedCapacity=0.45833334, absoluteUsedCapacity=0.45833334, numApps=5, numContainers=17 usedCapacity=0.45833334 absoluteUsedCapacity=0.45833334 used=<memory:22528, vCores:17> cluster=<memory:49152, vCores:96>
2013-08-17 06:41:33,212 INFO org.apache.hadoop.yarn.server.resourcemanager.scheduler.capacity.ParentQueue: Re-sorting queues since queue: root.default stats: default: capacity=1.0, absoluteCapacity=1.0, usedResources=<memory:23552, vCores:18>usedCapacity=0.47916666, absoluteUsedCapacity=0.47916666, numApps=5, numContainers=18
2013-08-17 06:41:33,213 INFO org.apache.hadoop.yarn.server.resourcemanager.scheduler.capacity.ParentQueue: assignedContainer queue=root usedCapacity=0.47916666 absoluteUsedCapacity=0.47916666 used=<memory:23552, vCores:18> cluster=<memory:49152, vCores:96>
2013-08-17 06:41:33,213 INFO org.apache.hadoop.yarn.server.resourcemanager.rmcontainer.RMContainerImpl: container_1376720997863_0007_01_000015 Container Transitioned from NEW to ALLOCATED
2013-08-17 06:41:33,213 INFO org.apache.hadoop.yarn.server.resourcemanager.RMAuditLogger: USER=ubuntu	OPERATION=AM Allocated Container	TARGET=SchedulerApp	RESULT=SUCCESS	APPID=application_1376720997863_0007	CONTAINERID=container_1376720997863_0007_01_000015
2013-08-17 06:41:33,213 INFO org.apache.hadoop.yarn.server.resourcemanager.scheduler.common.fica.FiCaSchedulerNode: Assigned container container_1376720997863_0007_01_000015 of capacity <memory:1024, vCores:1> on host hadoop-512-7:43914, which currently has 3 containers, <memory:4096, vCores:3> used and <memory:4096, vCores:13> available
2013-08-17 06:41:33,214 INFO org.apache.hadoop.yarn.server.resourcemanager.scheduler.capacity.LeafQueue: assignedContainer application=application_1376720997863_0007 container=Container: [ContainerId: container_1376720997863_0007_01_000015, NodeId: hadoop-512-7:43914, NodeHttpAddress: hadoop-512-7:8042, Resource: <memory:1024, vCores:1>, Priority: 20, State: NEW, Token: null, Status: container_id {, app_attempt_id {, application_id {, id: 7, cluster_timestamp: 1376720997863, }, attemptId: 1, }, id: 15, }, state: C_NEW, ] containerId=container_1376720997863_0007_01_000015 queue=default: capacity=1.0, absoluteCapacity=1.0, usedResources=<memory:23552, vCores:18>usedCapacity=0.47916666, absoluteUsedCapacity=0.47916666, numApps=5, numContainers=18 usedCapacity=0.47916666 absoluteUsedCapacity=0.47916666 used=<memory:23552, vCores:18> cluster=<memory:49152, vCores:96>
2013-08-17 06:41:33,215 INFO org.apache.hadoop.yarn.server.resourcemanager.scheduler.capacity.ParentQueue: Re-sorting queues since queue: root.default stats: default: capacity=1.0, absoluteCapacity=1.0, usedResources=<memory:24576, vCores:19>usedCapacity=0.5, absoluteUsedCapacity=0.5, numApps=5, numContainers=19
2013-08-17 06:41:33,215 INFO org.apache.hadoop.yarn.server.resourcemanager.scheduler.capacity.ParentQueue: assignedContainer queue=root usedCapacity=0.5 absoluteUsedCapacity=0.5 used=<memory:24576, vCores:19> cluster=<memory:49152, vCores:96>
2013-08-17 06:41:33,215 INFO org.apache.hadoop.yarn.server.resourcemanager.rmcontainer.RMContainerImpl: container_1376720997863_0007_01_000016 Container Transitioned from NEW to ALLOCATED
2013-08-17 06:41:33,215 INFO org.apache.hadoop.yarn.server.resourcemanager.RMAuditLogger: USER=ubuntu	OPERATION=AM Allocated Container	TARGET=SchedulerApp	RESULT=SUCCESS	APPID=application_1376720997863_0007	CONTAINERID=container_1376720997863_0007_01_000016
2013-08-17 06:41:33,215 INFO org.apache.hadoop.yarn.server.resourcemanager.scheduler.common.fica.FiCaSchedulerNode: Assigned container container_1376720997863_0007_01_000016 of capacity <memory:1024, vCores:1> on host hadoop-512-7:43914, which currently has 4 containers, <memory:5120, vCores:4> used and <memory:3072, vCores:12> available
2013-08-17 06:41:33,216 INFO org.apache.hadoop.yarn.server.resourcemanager.scheduler.capacity.LeafQueue: assignedContainer application=application_1376720997863_0007 container=Container: [ContainerId: container_1376720997863_0007_01_000016, NodeId: hadoop-512-7:43914, NodeHttpAddress: hadoop-512-7:8042, Resource: <memory:1024, vCores:1>, Priority: 20, State: NEW, Token: null, Status: container_id {, app_attempt_id {, application_id {, id: 7, cluster_timestamp: 1376720997863, }, attemptId: 1, }, id: 16, }, state: C_NEW, ] containerId=container_1376720997863_0007_01_000016 queue=default: capacity=1.0, absoluteCapacity=1.0, usedResources=<memory:24576, vCores:19>usedCapacity=0.5, absoluteUsedCapacity=0.5, numApps=5, numContainers=19 usedCapacity=0.5 absoluteUsedCapacity=0.5 used=<memory:24576, vCores:19> cluster=<memory:49152, vCores:96>
2013-08-17 06:41:33,217 INFO org.apache.hadoop.yarn.server.resourcemanager.scheduler.capacity.ParentQueue: Re-sorting queues since queue: root.default stats: default: capacity=1.0, absoluteCapacity=1.0, usedResources=<memory:25600, vCores:20>usedCapacity=0.5208333, absoluteUsedCapacity=0.5208333, numApps=5, numContainers=20
2013-08-17 06:41:33,217 INFO org.apache.hadoop.yarn.server.resourcemanager.scheduler.capacity.ParentQueue: assignedContainer queue=root usedCapacity=0.5208333 absoluteUsedCapacity=0.5208333 used=<memory:25600, vCores:20> cluster=<memory:49152, vCores:96>
2013-08-17 06:41:33,217 INFO org.apache.hadoop.yarn.server.resourcemanager.rmcontainer.RMContainerImpl: container_1376720997863_0007_01_000017 Container Transitioned from NEW to ALLOCATED
2013-08-17 06:41:33,217 INFO org.apache.hadoop.yarn.server.resourcemanager.RMAuditLogger: USER=ubuntu	OPERATION=AM Allocated Container	TARGET=SchedulerApp	RESULT=SUCCESS	APPID=application_1376720997863_0007	CONTAINERID=container_1376720997863_0007_01_000017
2013-08-17 06:41:33,218 INFO org.apache.hadoop.yarn.server.resourcemanager.scheduler.common.fica.FiCaSchedulerNode: Assigned container container_1376720997863_0007_01_000017 of capacity <memory:1024, vCores:1> on host hadoop-512-7:43914, which currently has 5 containers, <memory:6144, vCores:5> used and <memory:2048, vCores:11> available
2013-08-17 06:41:33,219 INFO org.apache.hadoop.yarn.server.resourcemanager.scheduler.capacity.LeafQueue: assignedContainer application=application_1376720997863_0007 container=Container: [ContainerId: container_1376720997863_0007_01_000017, NodeId: hadoop-512-7:43914, NodeHttpAddress: hadoop-512-7:8042, Resource: <memory:1024, vCores:1>, Priority: 20, State: NEW, Token: null, Status: container_id {, app_attempt_id {, application_id {, id: 7, cluster_timestamp: 1376720997863, }, attemptId: 1, }, id: 17, }, state: C_NEW, ] containerId=container_1376720997863_0007_01_000017 queue=default: capacity=1.0, absoluteCapacity=1.0, usedResources=<memory:25600, vCores:20>usedCapacity=0.5208333, absoluteUsedCapacity=0.5208333, numApps=5, numContainers=20 usedCapacity=0.5208333 absoluteUsedCapacity=0.5208333 used=<memory:25600, vCores:20> cluster=<memory:49152, vCores:96>
2013-08-17 06:41:33,219 INFO org.apache.hadoop.yarn.server.resourcemanager.scheduler.capacity.ParentQueue: Re-sorting queues since queue: root.default stats: default: capacity=1.0, absoluteCapacity=1.0, usedResources=<memory:26624, vCores:21>usedCapacity=0.5416667, absoluteUsedCapacity=0.5416667, numApps=5, numContainers=21
2013-08-17 06:41:33,219 INFO org.apache.hadoop.yarn.server.resourcemanager.scheduler.capacity.ParentQueue: assignedContainer queue=root usedCapacity=0.5416667 absoluteUsedCapacity=0.5416667 used=<memory:26624, vCores:21> cluster=<memory:49152, vCores:96>
2013-08-17 06:41:33,219 INFO org.apache.hadoop.yarn.server.resourcemanager.rmcontainer.RMContainerImpl: container_1376720997863_0007_01_000018 Container Transitioned from NEW to ALLOCATED
2013-08-17 06:41:33,220 INFO org.apache.hadoop.yarn.server.resourcemanager.RMAuditLogger: USER=ubuntu	OPERATION=AM Allocated Container	TARGET=SchedulerApp	RESULT=SUCCESS	APPID=application_1376720997863_0007	CONTAINERID=container_1376720997863_0007_01_000018
2013-08-17 06:41:33,220 INFO org.apache.hadoop.yarn.server.resourcemanager.scheduler.common.fica.FiCaSchedulerNode: Assigned container container_1376720997863_0007_01_000018 of capacity <memory:1024, vCores:1> on host hadoop-512-7:43914, which currently has 6 containers, <memory:7168, vCores:6> used and <memory:1024, vCores:10> available
2013-08-17 06:41:33,221 INFO org.apache.hadoop.yarn.server.resourcemanager.scheduler.capacity.LeafQueue: assignedContainer application=application_1376720997863_0007 container=Container: [ContainerId: container_1376720997863_0007_01_000018, NodeId: hadoop-512-7:43914, NodeHttpAddress: hadoop-512-7:8042, Resource: <memory:1024, vCores:1>, Priority: 20, State: NEW, Token: null, Status: container_id {, app_attempt_id {, application_id {, id: 7, cluster_timestamp: 1376720997863, }, attemptId: 1, }, id: 18, }, state: C_NEW, ] containerId=container_1376720997863_0007_01_000018 queue=default: capacity=1.0, absoluteCapacity=1.0, usedResources=<memory:26624, vCores:21>usedCapacity=0.5416667, absoluteUsedCapacity=0.5416667, numApps=5, numContainers=21 usedCapacity=0.5416667 absoluteUsedCapacity=0.5416667 used=<memory:26624, vCores:21> cluster=<memory:49152, vCores:96>
2013-08-17 06:41:33,221 INFO org.apache.hadoop.yarn.server.resourcemanager.scheduler.capacity.ParentQueue: Re-sorting queues since queue: root.default stats: default: capacity=1.0, absoluteCapacity=1.0, usedResources=<memory:27648, vCores:22>usedCapacity=0.5625, absoluteUsedCapacity=0.5625, numApps=5, numContainers=22
2013-08-17 06:41:33,221 INFO org.apache.hadoop.yarn.server.resourcemanager.scheduler.capacity.ParentQueue: assignedContainer queue=root usedCapacity=0.5625 absoluteUsedCapacity=0.5625 used=<memory:27648, vCores:22> cluster=<memory:49152, vCores:96>
2013-08-17 06:41:33,221 INFO org.apache.hadoop.yarn.server.resourcemanager.rmcontainer.RMContainerImpl: container_1376720997863_0007_01_000019 Container Transitioned from NEW to ALLOCATED
2013-08-17 06:41:33,222 INFO org.apache.hadoop.yarn.server.resourcemanager.RMAuditLogger: USER=ubuntu	OPERATION=AM Allocated Container	TARGET=SchedulerApp	RESULT=SUCCESS	APPID=application_1376720997863_0007	CONTAINERID=container_1376720997863_0007_01_000019
2013-08-17 06:41:33,222 INFO org.apache.hadoop.yarn.server.resourcemanager.scheduler.common.fica.FiCaSchedulerNode: Assigned container container_1376720997863_0007_01_000019 of capacity <memory:1024, vCores:1> on host hadoop-512-7:43914, which currently has 7 containers, <memory:8192, vCores:7> used and <memory:0, vCores:9> available
2013-08-17 06:41:33,223 INFO org.apache.hadoop.yarn.server.resourcemanager.scheduler.capacity.LeafQueue: assignedContainer application=application_1376720997863_0007 container=Container: [ContainerId: container_1376720997863_0007_01_000019, NodeId: hadoop-512-7:43914, NodeHttpAddress: hadoop-512-7:8042, Resource: <memory:1024, vCores:1>, Priority: 20, State: NEW, Token: null, Status: container_id {, app_attempt_id {, application_id {, id: 7, cluster_timestamp: 1376720997863, }, attemptId: 1, }, id: 19, }, state: C_NEW, ] containerId=container_1376720997863_0007_01_000019 queue=default: capacity=1.0, absoluteCapacity=1.0, usedResources=<memory:27648, vCores:22>usedCapacity=0.5625, absoluteUsedCapacity=0.5625, numApps=5, numContainers=22 usedCapacity=0.5625 absoluteUsedCapacity=0.5625 used=<memory:27648, vCores:22> cluster=<memory:49152, vCores:96>
2013-08-17 06:41:33,223 INFO org.apache.hadoop.yarn.server.resourcemanager.scheduler.capacity.ParentQueue: Re-sorting queues since queue: root.default stats: default: capacity=1.0, absoluteCapacity=1.0, usedResources=<memory:28672, vCores:23>usedCapacity=0.5833333, absoluteUsedCapacity=0.5833333, numApps=5, numContainers=23
2013-08-17 06:41:33,223 INFO org.apache.hadoop.yarn.server.resourcemanager.scheduler.capacity.ParentQueue: assignedContainer queue=root usedCapacity=0.5833333 absoluteUsedCapacity=0.5833333 used=<memory:28672, vCores:23> cluster=<memory:49152, vCores:96>
2013-08-17 06:41:33,224 INFO org.apache.hadoop.yarn.server.resourcemanager.rmcontainer.RMContainerImpl: container_1376720997863_0007_01_000020 Container Transitioned from NEW to ALLOCATED
2013-08-17 06:41:33,224 INFO org.apache.hadoop.yarn.server.resourcemanager.RMAuditLogger: USER=ubuntu	OPERATION=AM Allocated Container	TARGET=SchedulerApp	RESULT=SUCCESS	APPID=application_1376720997863_0007	CONTAINERID=container_1376720997863_0007_01_000020
2013-08-17 06:41:33,224 INFO org.apache.hadoop.yarn.server.resourcemanager.scheduler.common.fica.FiCaSchedulerNode: Assigned container container_1376720997863_0007_01_000020 of capacity <memory:1024, vCores:1> on host hadoop-512-2:32923, which currently has 2 containers, <memory:3072, vCores:2> used and <memory:5120, vCores:14> available
2013-08-17 06:41:33,225 INFO org.apache.hadoop.yarn.server.resourcemanager.scheduler.capacity.LeafQueue: assignedContainer application=application_1376720997863_0007 container=Container: [ContainerId: container_1376720997863_0007_01_000020, NodeId: hadoop-512-2:32923, NodeHttpAddress: hadoop-512-2:8042, Resource: <memory:1024, vCores:1>, Priority: 20, State: NEW, Token: null, Status: container_id {, app_attempt_id {, application_id {, id: 7, cluster_timestamp: 1376720997863, }, attemptId: 1, }, id: 20, }, state: C_NEW, ] containerId=container_1376720997863_0007_01_000020 queue=default: capacity=1.0, absoluteCapacity=1.0, usedResources=<memory:28672, vCores:23>usedCapacity=0.5833333, absoluteUsedCapacity=0.5833333, numApps=5, numContainers=23 usedCapacity=0.5833333 absoluteUsedCapacity=0.5833333 used=<memory:28672, vCores:23> cluster=<memory:49152, vCores:96>
2013-08-17 06:41:33,225 INFO org.apache.hadoop.yarn.server.resourcemanager.scheduler.capacity.ParentQueue: Re-sorting queues since queue: root.default stats: default: capacity=1.0, absoluteCapacity=1.0, usedResources=<memory:29696, vCores:24>usedCapacity=0.6041667, absoluteUsedCapacity=0.6041667, numApps=5, numContainers=24
2013-08-17 06:41:33,225 INFO org.apache.hadoop.yarn.server.resourcemanager.scheduler.capacity.ParentQueue: assignedContainer queue=root usedCapacity=0.6041667 absoluteUsedCapacity=0.6041667 used=<memory:29696, vCores:24> cluster=<memory:49152, vCores:96>
2013-08-17 06:41:33,226 INFO org.apache.hadoop.yarn.server.resourcemanager.rmcontainer.RMContainerImpl: container_1376720997863_0007_01_000021 Container Transitioned from NEW to ALLOCATED
2013-08-17 06:41:33,226 INFO org.apache.hadoop.yarn.server.resourcemanager.RMAuditLogger: USER=ubuntu	OPERATION=AM Allocated Container	TARGET=SchedulerApp	RESULT=SUCCESS	APPID=application_1376720997863_0007	CONTAINERID=container_1376720997863_0007_01_000021
2013-08-17 06:41:33,226 INFO org.apache.hadoop.yarn.server.resourcemanager.scheduler.common.fica.FiCaSchedulerNode: Assigned container container_1376720997863_0007_01_000021 of capacity <memory:1024, vCores:1> on host hadoop-512-2:32923, which currently has 3 containers, <memory:4096, vCores:3> used and <memory:4096, vCores:13> available
2013-08-17 06:41:33,227 INFO org.apache.hadoop.yarn.server.resourcemanager.scheduler.capacity.LeafQueue: assignedContainer application=application_1376720997863_0007 container=Container: [ContainerId: container_1376720997863_0007_01_000021, NodeId: hadoop-512-2:32923, NodeHttpAddress: hadoop-512-2:8042, Resource: <memory:1024, vCores:1>, Priority: 20, State: NEW, Token: null, Status: container_id {, app_attempt_id {, application_id {, id: 7, cluster_timestamp: 1376720997863, }, attemptId: 1, }, id: 21, }, state: C_NEW, ] containerId=container_1376720997863_0007_01_000021 queue=default: capacity=1.0, absoluteCapacity=1.0, usedResources=<memory:29696, vCores:24>usedCapacity=0.6041667, absoluteUsedCapacity=0.6041667, numApps=5, numContainers=24 usedCapacity=0.6041667 absoluteUsedCapacity=0.6041667 used=<memory:29696, vCores:24> cluster=<memory:49152, vCores:96>
2013-08-17 06:41:33,227 INFO org.apache.hadoop.yarn.server.resourcemanager.scheduler.capacity.ParentQueue: Re-sorting queues since queue: root.default stats: default: capacity=1.0, absoluteCapacity=1.0, usedResources=<memory:30720, vCores:25>usedCapacity=0.625, absoluteUsedCapacity=0.625, numApps=5, numContainers=25
2013-08-17 06:41:33,227 INFO org.apache.hadoop.yarn.server.resourcemanager.scheduler.capacity.ParentQueue: assignedContainer queue=root usedCapacity=0.625 absoluteUsedCapacity=0.625 used=<memory:30720, vCores:25> cluster=<memory:49152, vCores:96>
2013-08-17 06:41:33,228 INFO org.apache.hadoop.yarn.server.resourcemanager.rmcontainer.RMContainerImpl: container_1376720997863_0007_01_000022 Container Transitioned from NEW to ALLOCATED
2013-08-17 06:41:33,228 INFO org.apache.hadoop.yarn.server.resourcemanager.RMAuditLogger: USER=ubuntu	OPERATION=AM Allocated Container	TARGET=SchedulerApp	RESULT=SUCCESS	APPID=application_1376720997863_0007	CONTAINERID=container_1376720997863_0007_01_000022
2013-08-17 06:41:33,228 INFO org.apache.hadoop.yarn.server.resourcemanager.scheduler.common.fica.FiCaSchedulerNode: Assigned container container_1376720997863_0007_01_000022 of capacity <memory:1024, vCores:1> on host hadoop-512-2:32923, which currently has 4 containers, <memory:5120, vCores:4> used and <memory:3072, vCores:12> available
2013-08-17 06:41:33,229 INFO org.apache.hadoop.yarn.server.resourcemanager.scheduler.capacity.LeafQueue: assignedContainer application=application_1376720997863_0007 container=Container: [ContainerId: container_1376720997863_0007_01_000022, NodeId: hadoop-512-2:32923, NodeHttpAddress: hadoop-512-2:8042, Resource: <memory:1024, vCores:1>, Priority: 20, State: NEW, Token: null, Status: container_id {, app_attempt_id {, application_id {, id: 7, cluster_timestamp: 1376720997863, }, attemptId: 1, }, id: 22, }, state: C_NEW, ] containerId=container_1376720997863_0007_01_000022 queue=default: capacity=1.0, absoluteCapacity=1.0, usedResources=<memory:30720, vCores:25>usedCapacity=0.625, absoluteUsedCapacity=0.625, numApps=5, numContainers=25 usedCapacity=0.625 absoluteUsedCapacity=0.625 used=<memory:30720, vCores:25> cluster=<memory:49152, vCores:96>
2013-08-17 06:41:33,229 INFO org.apache.hadoop.yarn.server.resourcemanager.scheduler.capacity.ParentQueue: Re-sorting queues since queue: root.default stats: default: capacity=1.0, absoluteCapacity=1.0, usedResources=<memory:31744, vCores:26>usedCapacity=0.6458333, absoluteUsedCapacity=0.6458333, numApps=5, numContainers=26
2013-08-17 06:41:33,229 INFO org.apache.hadoop.yarn.server.resourcemanager.scheduler.capacity.ParentQueue: assignedContainer queue=root usedCapacity=0.6458333 absoluteUsedCapacity=0.6458333 used=<memory:31744, vCores:26> cluster=<memory:49152, vCores:96>
2013-08-17 06:41:33,230 INFO org.apache.hadoop.yarn.server.resourcemanager.rmcontainer.RMContainerImpl: container_1376720997863_0007_01_000023 Container Transitioned from NEW to ALLOCATED
2013-08-17 06:41:33,230 INFO org.apache.hadoop.yarn.server.resourcemanager.RMAuditLogger: USER=ubuntu	OPERATION=AM Allocated Container	TARGET=SchedulerApp	RESULT=SUCCESS	APPID=application_1376720997863_0007	CONTAINERID=container_1376720997863_0007_01_000023
2013-08-17 06:41:33,230 INFO org.apache.hadoop.yarn.server.resourcemanager.scheduler.common.fica.FiCaSchedulerNode: Assigned container container_1376720997863_0007_01_000023 of capacity <memory:1024, vCores:1> on host hadoop-512-2:32923, which currently has 5 containers, <memory:6144, vCores:5> used and <memory:2048, vCores:11> available
2013-08-17 06:41:33,231 INFO org.apache.hadoop.yarn.server.resourcemanager.scheduler.capacity.LeafQueue: assignedContainer application=application_1376720997863_0007 container=Container: [ContainerId: container_1376720997863_0007_01_000023, NodeId: hadoop-512-2:32923, NodeHttpAddress: hadoop-512-2:8042, Resource: <memory:1024, vCores:1>, Priority: 20, State: NEW, Token: null, Status: container_id {, app_attempt_id {, application_id {, id: 7, cluster_timestamp: 1376720997863, }, attemptId: 1, }, id: 23, }, state: C_NEW, ] containerId=container_1376720997863_0007_01_000023 queue=default: capacity=1.0, absoluteCapacity=1.0, usedResources=<memory:31744, vCores:26>usedCapacity=0.6458333, absoluteUsedCapacity=0.6458333, numApps=5, numContainers=26 usedCapacity=0.6458333 absoluteUsedCapacity=0.6458333 used=<memory:31744, vCores:26> cluster=<memory:49152, vCores:96>
2013-08-17 06:41:33,231 INFO org.apache.hadoop.yarn.server.resourcemanager.scheduler.capacity.ParentQueue: Re-sorting queues since queue: root.default stats: default: capacity=1.0, absoluteCapacity=1.0, usedResources=<memory:32768, vCores:27>usedCapacity=0.6666667, absoluteUsedCapacity=0.6666667, numApps=5, numContainers=27
2013-08-17 06:41:33,231 INFO org.apache.hadoop.yarn.server.resourcemanager.scheduler.capacity.ParentQueue: assignedContainer queue=root usedCapacity=0.6666667 absoluteUsedCapacity=0.6666667 used=<memory:32768, vCores:27> cluster=<memory:49152, vCores:96>
2013-08-17 06:41:33,232 INFO org.apache.hadoop.yarn.server.resourcemanager.rmcontainer.RMContainerImpl: container_1376720997863_0007_01_000024 Container Transitioned from NEW to ALLOCATED
2013-08-17 06:41:33,232 INFO org.apache.hadoop.yarn.server.resourcemanager.RMAuditLogger: USER=ubuntu	OPERATION=AM Allocated Container	TARGET=SchedulerApp	RESULT=SUCCESS	APPID=application_1376720997863_0007	CONTAINERID=container_1376720997863_0007_01_000024
2013-08-17 06:41:33,232 INFO org.apache.hadoop.yarn.server.resourcemanager.scheduler.common.fica.FiCaSchedulerNode: Assigned container container_1376720997863_0007_01_000024 of capacity <memory:1024, vCores:1> on host hadoop-512-2:32923, which currently has 6 containers, <memory:7168, vCores:6> used and <memory:1024, vCores:10> available
2013-08-17 06:41:33,233 INFO org.apache.hadoop.yarn.server.resourcemanager.scheduler.capacity.LeafQueue: assignedContainer application=application_1376720997863_0007 container=Container: [ContainerId: container_1376720997863_0007_01_000024, NodeId: hadoop-512-2:32923, NodeHttpAddress: hadoop-512-2:8042, Resource: <memory:1024, vCores:1>, Priority: 20, State: NEW, Token: null, Status: container_id {, app_attempt_id {, application_id {, id: 7, cluster_timestamp: 1376720997863, }, attemptId: 1, }, id: 24, }, state: C_NEW, ] containerId=container_1376720997863_0007_01_000024 queue=default: capacity=1.0, absoluteCapacity=1.0, usedResources=<memory:32768, vCores:27>usedCapacity=0.6666667, absoluteUsedCapacity=0.6666667, numApps=5, numContainers=27 usedCapacity=0.6666667 absoluteUsedCapacity=0.6666667 used=<memory:32768, vCores:27> cluster=<memory:49152, vCores:96>
2013-08-17 06:41:33,233 INFO org.apache.hadoop.yarn.server.resourcemanager.scheduler.capacity.ParentQueue: Re-sorting queues since queue: root.default stats: default: capacity=1.0, absoluteCapacity=1.0, usedResources=<memory:33792, vCores:28>usedCapacity=0.6875, absoluteUsedCapacity=0.6875, numApps=5, numContainers=28
2013-08-17 06:41:33,234 INFO org.apache.hadoop.yarn.server.resourcemanager.scheduler.capacity.ParentQueue: assignedContainer queue=root usedCapacity=0.6875 absoluteUsedCapacity=0.6875 used=<memory:33792, vCores:28> cluster=<memory:49152, vCores:96>
2013-08-17 06:41:33,234 INFO org.apache.hadoop.yarn.server.resourcemanager.rmcontainer.RMContainerImpl: container_1376720997863_0007_01_000025 Container Transitioned from NEW to ALLOCATED
2013-08-17 06:41:33,234 INFO org.apache.hadoop.yarn.server.resourcemanager.RMAuditLogger: USER=ubuntu	OPERATION=AM Allocated Container	TARGET=SchedulerApp	RESULT=SUCCESS	APPID=application_1376720997863_0007	CONTAINERID=container_1376720997863_0007_01_000025
2013-08-17 06:41:33,234 INFO org.apache.hadoop.yarn.server.resourcemanager.scheduler.common.fica.FiCaSchedulerNode: Assigned container container_1376720997863_0007_01_000025 of capacity <memory:1024, vCores:1> on host hadoop-512-2:32923, which currently has 7 containers, <memory:8192, vCores:7> used and <memory:0, vCores:9> available
2013-08-17 06:41:33,235 INFO org.apache.hadoop.yarn.server.resourcemanager.scheduler.capacity.LeafQueue: assignedContainer application=application_1376720997863_0007 container=Container: [ContainerId: container_1376720997863_0007_01_000025, NodeId: hadoop-512-2:32923, NodeHttpAddress: hadoop-512-2:8042, Resource: <memory:1024, vCores:1>, Priority: 20, State: NEW, Token: null, Status: container_id {, app_attempt_id {, application_id {, id: 7, cluster_timestamp: 1376720997863, }, attemptId: 1, }, id: 25, }, state: C_NEW, ] containerId=container_1376720997863_0007_01_000025 queue=default: capacity=1.0, absoluteCapacity=1.0, usedResources=<memory:33792, vCores:28>usedCapacity=0.6875, absoluteUsedCapacity=0.6875, numApps=5, numContainers=28 usedCapacity=0.6875 absoluteUsedCapacity=0.6875 used=<memory:33792, vCores:28> cluster=<memory:49152, vCores:96>
2013-08-17 06:41:33,235 INFO org.apache.hadoop.yarn.server.resourcemanager.scheduler.capacity.ParentQueue: Re-sorting queues since queue: root.default stats: default: capacity=1.0, absoluteCapacity=1.0, usedResources=<memory:34816, vCores:29>usedCapacity=0.7083333, absoluteUsedCapacity=0.7083333, numApps=5, numContainers=29
2013-08-17 06:41:33,236 INFO org.apache.hadoop.yarn.server.resourcemanager.scheduler.capacity.ParentQueue: assignedContainer queue=root usedCapacity=0.7083333 absoluteUsedCapacity=0.7083333 used=<memory:34816, vCores:29> cluster=<memory:49152, vCores:96>
2013-08-17 06:41:33,452 INFO org.apache.hadoop.yarn.server.resourcemanager.ApplicationMasterService: AM registration appattempt_1376720997863_0010_000001
2013-08-17 06:41:33,453 INFO org.apache.hadoop.yarn.server.resourcemanager.RMAuditLogger: USER=ubuntu	IP=192.168.100.24	OPERATION=Register App Master	TARGET=ApplicationMasterService	RESULT=SUCCESS	APPID=application_1376720997863_0010	APPATTEMPTID=appattempt_1376720997863_0010_000001
2013-08-17 06:41:33,454 INFO org.apache.hadoop.yarn.server.resourcemanager.rmapp.attempt.RMAppAttemptImpl: appattempt_1376720997863_0010_000001 State change from LAUNCHED to RUNNING
2013-08-17 06:41:33,455 INFO org.apache.hadoop.yarn.server.resourcemanager.rmapp.RMAppImpl: application_1376720997863_0010 State change from ACCEPTED to RUNNING
2013-08-17 06:41:33,524 INFO org.apache.hadoop.yarn.server.resourcemanager.rmcontainer.RMContainerImpl: container_1376720997863_0007_01_000026 Container Transitioned from NEW to ALLOCATED
2013-08-17 06:41:33,524 INFO org.apache.hadoop.yarn.server.resourcemanager.RMAuditLogger: USER=ubuntu	OPERATION=AM Allocated Container	TARGET=SchedulerApp	RESULT=SUCCESS	APPID=application_1376720997863_0007	CONTAINERID=container_1376720997863_0007_01_000026
2013-08-17 06:41:33,524 INFO org.apache.hadoop.yarn.server.resourcemanager.scheduler.common.fica.FiCaSchedulerNode: Assigned container container_1376720997863_0007_01_000026 of capacity <memory:1024, vCores:1> on host hadoop-512-6:48301, which currently has 1 containers, <memory:1024, vCores:1> used and <memory:7168, vCores:15> available
2013-08-17 06:41:33,525 INFO org.apache.hadoop.yarn.server.resourcemanager.scheduler.capacity.LeafQueue: assignedContainer application=application_1376720997863_0007 container=Container: [ContainerId: container_1376720997863_0007_01_000026, NodeId: hadoop-512-6:48301, NodeHttpAddress: hadoop-512-6:8042, Resource: <memory:1024, vCores:1>, Priority: 20, State: NEW, Token: null, Status: container_id {, app_attempt_id {, application_id {, id: 7, cluster_timestamp: 1376720997863, }, attemptId: 1, }, id: 26, }, state: C_NEW, ] containerId=container_1376720997863_0007_01_000026 queue=default: capacity=1.0, absoluteCapacity=1.0, usedResources=<memory:34816, vCores:29>usedCapacity=0.7083333, absoluteUsedCapacity=0.7083333, numApps=5, numContainers=29 usedCapacity=0.7083333 absoluteUsedCapacity=0.7083333 used=<memory:34816, vCores:29> cluster=<memory:49152, vCores:96>
2013-08-17 06:41:33,525 INFO org.apache.hadoop.yarn.server.resourcemanager.scheduler.capacity.ParentQueue: Re-sorting queues since queue: root.default stats: default: capacity=1.0, absoluteCapacity=1.0, usedResources=<memory:35840, vCores:30>usedCapacity=0.7291667, absoluteUsedCapacity=0.7291667, numApps=5, numContainers=30
2013-08-17 06:41:33,525 INFO org.apache.hadoop.yarn.server.resourcemanager.scheduler.capacity.ParentQueue: assignedContainer queue=root usedCapacity=0.7291667 absoluteUsedCapacity=0.7291667 used=<memory:35840, vCores:30> cluster=<memory:49152, vCores:96>
2013-08-17 06:41:33,526 INFO org.apache.hadoop.yarn.server.resourcemanager.rmcontainer.RMContainerImpl: container_1376720997863_0007_01_000027 Container Transitioned from NEW to ALLOCATED
2013-08-17 06:41:33,526 INFO org.apache.hadoop.yarn.server.resourcemanager.RMAuditLogger: USER=ubuntu	OPERATION=AM Allocated Container	TARGET=SchedulerApp	RESULT=SUCCESS	APPID=application_1376720997863_0007	CONTAINERID=container_1376720997863_0007_01_000027
2013-08-17 06:41:33,526 INFO org.apache.hadoop.yarn.server.resourcemanager.scheduler.common.fica.FiCaSchedulerNode: Assigned container container_1376720997863_0007_01_000027 of capacity <memory:1024, vCores:1> on host hadoop-512-6:48301, which currently has 2 containers, <memory:2048, vCores:2> used and <memory:6144, vCores:14> available
2013-08-17 06:41:33,527 INFO org.apache.hadoop.yarn.server.resourcemanager.scheduler.capacity.LeafQueue: assignedContainer application=application_1376720997863_0007 container=Container: [ContainerId: container_1376720997863_0007_01_000027, NodeId: hadoop-512-6:48301, NodeHttpAddress: hadoop-512-6:8042, Resource: <memory:1024, vCores:1>, Priority: 20, State: NEW, Token: null, Status: container_id {, app_attempt_id {, application_id {, id: 7, cluster_timestamp: 1376720997863, }, attemptId: 1, }, id: 27, }, state: C_NEW, ] containerId=container_1376720997863_0007_01_000027 queue=default: capacity=1.0, absoluteCapacity=1.0, usedResources=<memory:35840, vCores:30>usedCapacity=0.7291667, absoluteUsedCapacity=0.7291667, numApps=5, numContainers=30 usedCapacity=0.7291667 absoluteUsedCapacity=0.7291667 used=<memory:35840, vCores:30> cluster=<memory:49152, vCores:96>
2013-08-17 06:41:33,527 INFO org.apache.hadoop.yarn.server.resourcemanager.scheduler.capacity.ParentQueue: Re-sorting queues since queue: root.default stats: default: capacity=1.0, absoluteCapacity=1.0, usedResources=<memory:36864, vCores:31>usedCapacity=0.75, absoluteUsedCapacity=0.75, numApps=5, numContainers=31
2013-08-17 06:41:33,528 INFO org.apache.hadoop.yarn.server.resourcemanager.scheduler.capacity.ParentQueue: assignedContainer queue=root usedCapacity=0.75 absoluteUsedCapacity=0.75 used=<memory:36864, vCores:31> cluster=<memory:49152, vCores:96>
2013-08-17 06:41:33,528 INFO org.apache.hadoop.yarn.server.resourcemanager.rmcontainer.RMContainerImpl: container_1376720997863_0007_01_000028 Container Transitioned from NEW to ALLOCATED
2013-08-17 06:41:33,528 INFO org.apache.hadoop.yarn.server.resourcemanager.RMAuditLogger: USER=ubuntu	OPERATION=AM Allocated Container	TARGET=SchedulerApp	RESULT=SUCCESS	APPID=application_1376720997863_0007	CONTAINERID=container_1376720997863_0007_01_000028
2013-08-17 06:41:33,528 INFO org.apache.hadoop.yarn.server.resourcemanager.scheduler.common.fica.FiCaSchedulerNode: Assigned container container_1376720997863_0007_01_000028 of capacity <memory:1024, vCores:1> on host hadoop-512-6:48301, which currently has 3 containers, <memory:3072, vCores:3> used and <memory:5120, vCores:13> available
2013-08-17 06:41:33,529 INFO org.apache.hadoop.yarn.server.resourcemanager.scheduler.capacity.LeafQueue: assignedContainer application=application_1376720997863_0007 container=Container: [ContainerId: container_1376720997863_0007_01_000028, NodeId: hadoop-512-6:48301, NodeHttpAddress: hadoop-512-6:8042, Resource: <memory:1024, vCores:1>, Priority: 20, State: NEW, Token: null, Status: container_id {, app_attempt_id {, application_id {, id: 7, cluster_timestamp: 1376720997863, }, attemptId: 1, }, id: 28, }, state: C_NEW, ] containerId=container_1376720997863_0007_01_000028 queue=default: capacity=1.0, absoluteCapacity=1.0, usedResources=<memory:36864, vCores:31>usedCapacity=0.75, absoluteUsedCapacity=0.75, numApps=5, numContainers=31 usedCapacity=0.75 absoluteUsedCapacity=0.75 used=<memory:36864, vCores:31> cluster=<memory:49152, vCores:96>
2013-08-17 06:41:33,529 INFO org.apache.hadoop.yarn.server.resourcemanager.scheduler.capacity.ParentQueue: Re-sorting queues since queue: root.default stats: default: capacity=1.0, absoluteCapacity=1.0, usedResources=<memory:37888, vCores:32>usedCapacity=0.7708333, absoluteUsedCapacity=0.7708333, numApps=5, numContainers=32
2013-08-17 06:41:33,530 INFO org.apache.hadoop.yarn.server.resourcemanager.scheduler.capacity.ParentQueue: assignedContainer queue=root usedCapacity=0.7708333 absoluteUsedCapacity=0.7708333 used=<memory:37888, vCores:32> cluster=<memory:49152, vCores:96>
2013-08-17 06:41:33,530 INFO org.apache.hadoop.yarn.server.resourcemanager.rmcontainer.RMContainerImpl: container_1376720997863_0007_01_000029 Container Transitioned from NEW to ALLOCATED
2013-08-17 06:41:33,530 INFO org.apache.hadoop.yarn.server.resourcemanager.RMAuditLogger: USER=ubuntu	OPERATION=AM Allocated Container	TARGET=SchedulerApp	RESULT=SUCCESS	APPID=application_1376720997863_0007	CONTAINERID=container_1376720997863_0007_01_000029
2013-08-17 06:41:33,530 INFO org.apache.hadoop.yarn.server.resourcemanager.scheduler.common.fica.FiCaSchedulerNode: Assigned container container_1376720997863_0007_01_000029 of capacity <memory:1024, vCores:1> on host hadoop-512-6:48301, which currently has 4 containers, <memory:4096, vCores:4> used and <memory:4096, vCores:12> available
2013-08-17 06:41:33,531 INFO org.apache.hadoop.yarn.server.resourcemanager.scheduler.capacity.LeafQueue: assignedContainer application=application_1376720997863_0007 container=Container: [ContainerId: container_1376720997863_0007_01_000029, NodeId: hadoop-512-6:48301, NodeHttpAddress: hadoop-512-6:8042, Resource: <memory:1024, vCores:1>, Priority: 20, State: NEW, Token: null, Status: container_id {, app_attempt_id {, application_id {, id: 7, cluster_timestamp: 1376720997863, }, attemptId: 1, }, id: 29, }, state: C_NEW, ] containerId=container_1376720997863_0007_01_000029 queue=default: capacity=1.0, absoluteCapacity=1.0, usedResources=<memory:37888, vCores:32>usedCapacity=0.7708333, absoluteUsedCapacity=0.7708333, numApps=5, numContainers=32 usedCapacity=0.7708333 absoluteUsedCapacity=0.7708333 used=<memory:37888, vCores:32> cluster=<memory:49152, vCores:96>
2013-08-17 06:41:33,532 INFO org.apache.hadoop.yarn.server.resourcemanager.scheduler.capacity.ParentQueue: Re-sorting queues since queue: root.default stats: default: capacity=1.0, absoluteCapacity=1.0, usedResources=<memory:38912, vCores:33>usedCapacity=0.7916667, absoluteUsedCapacity=0.7916667, numApps=5, numContainers=33
2013-08-17 06:41:33,532 INFO org.apache.hadoop.yarn.server.resourcemanager.scheduler.capacity.ParentQueue: assignedContainer queue=root usedCapacity=0.7916667 absoluteUsedCapacity=0.7916667 used=<memory:38912, vCores:33> cluster=<memory:49152, vCores:96>
2013-08-17 06:41:33,532 INFO org.apache.hadoop.yarn.server.resourcemanager.rmcontainer.RMContainerImpl: container_1376720997863_0007_01_000030 Container Transitioned from NEW to ALLOCATED
2013-08-17 06:41:33,532 INFO org.apache.hadoop.yarn.server.resourcemanager.RMAuditLogger: USER=ubuntu	OPERATION=AM Allocated Container	TARGET=SchedulerApp	RESULT=SUCCESS	APPID=application_1376720997863_0007	CONTAINERID=container_1376720997863_0007_01_000030
2013-08-17 06:41:33,533 INFO org.apache.hadoop.yarn.server.resourcemanager.scheduler.common.fica.FiCaSchedulerNode: Assigned container container_1376720997863_0007_01_000030 of capacity <memory:1024, vCores:1> on host hadoop-512-6:48301, which currently has 5 containers, <memory:5120, vCores:5> used and <memory:3072, vCores:11> available
2013-08-17 06:41:33,533 INFO org.apache.hadoop.yarn.server.resourcemanager.scheduler.capacity.LeafQueue: assignedContainer application=application_1376720997863_0007 container=Container: [ContainerId: container_1376720997863_0007_01_000030, NodeId: hadoop-512-6:48301, NodeHttpAddress: hadoop-512-6:8042, Resource: <memory:1024, vCores:1>, Priority: 20, State: NEW, Token: null, Status: container_id {, app_attempt_id {, application_id {, id: 7, cluster_timestamp: 1376720997863, }, attemptId: 1, }, id: 30, }, state: C_NEW, ] containerId=container_1376720997863_0007_01_000030 queue=default: capacity=1.0, absoluteCapacity=1.0, usedResources=<memory:38912, vCores:33>usedCapacity=0.7916667, absoluteUsedCapacity=0.7916667, numApps=5, numContainers=33 usedCapacity=0.7916667 absoluteUsedCapacity=0.7916667 used=<memory:38912, vCores:33> cluster=<memory:49152, vCores:96>
2013-08-17 06:41:33,534 INFO org.apache.hadoop.yarn.server.resourcemanager.scheduler.capacity.ParentQueue: Re-sorting queues since queue: root.default stats: default: capacity=1.0, absoluteCapacity=1.0, usedResources=<memory:39936, vCores:34>usedCapacity=0.8125, absoluteUsedCapacity=0.8125, numApps=5, numContainers=34
2013-08-17 06:41:33,534 INFO org.apache.hadoop.yarn.server.resourcemanager.scheduler.capacity.ParentQueue: assignedContainer queue=root usedCapacity=0.8125 absoluteUsedCapacity=0.8125 used=<memory:39936, vCores:34> cluster=<memory:49152, vCores:96>
2013-08-17 06:41:33,534 INFO org.apache.hadoop.yarn.server.resourcemanager.rmcontainer.RMContainerImpl: container_1376720997863_0007_01_000031 Container Transitioned from NEW to ALLOCATED
2013-08-17 06:41:33,535 INFO org.apache.hadoop.yarn.server.resourcemanager.RMAuditLogger: USER=ubuntu	OPERATION=AM Allocated Container	TARGET=SchedulerApp	RESULT=SUCCESS	APPID=application_1376720997863_0007	CONTAINERID=container_1376720997863_0007_01_000031
2013-08-17 06:41:33,535 INFO org.apache.hadoop.yarn.server.resourcemanager.scheduler.common.fica.FiCaSchedulerNode: Assigned container container_1376720997863_0007_01_000031 of capacity <memory:1024, vCores:1> on host hadoop-512-6:48301, which currently has 6 containers, <memory:6144, vCores:6> used and <memory:2048, vCores:10> available
2013-08-17 06:41:33,536 INFO org.apache.hadoop.yarn.server.resourcemanager.scheduler.capacity.LeafQueue: assignedContainer application=application_1376720997863_0007 container=Container: [ContainerId: container_1376720997863_0007_01_000031, NodeId: hadoop-512-6:48301, NodeHttpAddress: hadoop-512-6:8042, Resource: <memory:1024, vCores:1>, Priority: 20, State: NEW, Token: null, Status: container_id {, app_attempt_id {, application_id {, id: 7, cluster_timestamp: 1376720997863, }, attemptId: 1, }, id: 31, }, state: C_NEW, ] containerId=container_1376720997863_0007_01_000031 queue=default: capacity=1.0, absoluteCapacity=1.0, usedResources=<memory:39936, vCores:34>usedCapacity=0.8125, absoluteUsedCapacity=0.8125, numApps=5, numContainers=34 usedCapacity=0.8125 absoluteUsedCapacity=0.8125 used=<memory:39936, vCores:34> cluster=<memory:49152, vCores:96>
2013-08-17 06:41:33,536 INFO org.apache.hadoop.yarn.server.resourcemanager.scheduler.capacity.ParentQueue: Re-sorting queues since queue: root.default stats: default: capacity=1.0, absoluteCapacity=1.0, usedResources=<memory:40960, vCores:35>usedCapacity=0.8333333, absoluteUsedCapacity=0.8333333, numApps=5, numContainers=35
2013-08-17 06:41:33,536 INFO org.apache.hadoop.yarn.server.resourcemanager.scheduler.capacity.ParentQueue: assignedContainer queue=root usedCapacity=0.8333333 absoluteUsedCapacity=0.8333333 used=<memory:40960, vCores:35> cluster=<memory:49152, vCores:96>
2013-08-17 06:41:33,537 INFO org.apache.hadoop.yarn.server.resourcemanager.rmcontainer.RMContainerImpl: container_1376720997863_0007_01_000032 Container Transitioned from NEW to ALLOCATED
2013-08-17 06:41:33,537 INFO org.apache.hadoop.yarn.server.resourcemanager.RMAuditLogger: USER=ubuntu	OPERATION=AM Allocated Container	TARGET=SchedulerApp	RESULT=SUCCESS	APPID=application_1376720997863_0007	CONTAINERID=container_1376720997863_0007_01_000032
2013-08-17 06:41:33,537 INFO org.apache.hadoop.yarn.server.resourcemanager.scheduler.common.fica.FiCaSchedulerNode: Assigned container container_1376720997863_0007_01_000032 of capacity <memory:1024, vCores:1> on host hadoop-512-6:48301, which currently has 7 containers, <memory:7168, vCores:7> used and <memory:1024, vCores:9> available
2013-08-17 06:41:33,539 INFO org.apache.hadoop.yarn.server.resourcemanager.scheduler.capacity.LeafQueue: assignedContainer application=application_1376720997863_0007 container=Container: [ContainerId: container_1376720997863_0007_01_000032, NodeId: hadoop-512-6:48301, NodeHttpAddress: hadoop-512-6:8042, Resource: <memory:1024, vCores:1>, Priority: 20, State: NEW, Token: null, Status: container_id {, app_attempt_id {, application_id {, id: 7, cluster_timestamp: 1376720997863, }, attemptId: 1, }, id: 32, }, state: C_NEW, ] containerId=container_1376720997863_0007_01_000032 queue=default: capacity=1.0, absoluteCapacity=1.0, usedResources=<memory:40960, vCores:35>usedCapacity=0.8333333, absoluteUsedCapacity=0.8333333, numApps=5, numContainers=35 usedCapacity=0.8333333 absoluteUsedCapacity=0.8333333 used=<memory:40960, vCores:35> cluster=<memory:49152, vCores:96>
2013-08-17 06:41:33,539 INFO org.apache.hadoop.yarn.server.resourcemanager.scheduler.capacity.ParentQueue: Re-sorting queues since queue: root.default stats: default: capacity=1.0, absoluteCapacity=1.0, usedResources=<memory:41984, vCores:36>usedCapacity=0.8541667, absoluteUsedCapacity=0.8541667, numApps=5, numContainers=36
2013-08-17 06:41:33,539 INFO org.apache.hadoop.yarn.server.resourcemanager.scheduler.capacity.ParentQueue: assignedContainer queue=root usedCapacity=0.8541667 absoluteUsedCapacity=0.8541667 used=<memory:41984, vCores:36> cluster=<memory:49152, vCores:96>
2013-08-17 06:41:33,540 INFO org.apache.hadoop.yarn.server.resourcemanager.rmcontainer.RMContainerImpl: container_1376720997863_0007_01_000033 Container Transitioned from NEW to ALLOCATED
2013-08-17 06:41:33,540 INFO org.apache.hadoop.yarn.server.resourcemanager.RMAuditLogger: USER=ubuntu	OPERATION=AM Allocated Container	TARGET=SchedulerApp	RESULT=SUCCESS	APPID=application_1376720997863_0007	CONTAINERID=container_1376720997863_0007_01_000033
2013-08-17 06:41:33,540 INFO org.apache.hadoop.yarn.server.resourcemanager.scheduler.common.fica.FiCaSchedulerNode: Assigned container container_1376720997863_0007_01_000033 of capacity <memory:1024, vCores:1> on host hadoop-512-6:48301, which currently has 8 containers, <memory:8192, vCores:8> used and <memory:0, vCores:8> available
2013-08-17 06:41:33,541 INFO org.apache.hadoop.yarn.server.resourcemanager.scheduler.capacity.LeafQueue: assignedContainer application=application_1376720997863_0007 container=Container: [ContainerId: container_1376720997863_0007_01_000033, NodeId: hadoop-512-6:48301, NodeHttpAddress: hadoop-512-6:8042, Resource: <memory:1024, vCores:1>, Priority: 20, State: NEW, Token: null, Status: container_id {, app_attempt_id {, application_id {, id: 7, cluster_timestamp: 1376720997863, }, attemptId: 1, }, id: 33, }, state: C_NEW, ] containerId=container_1376720997863_0007_01_000033 queue=default: capacity=1.0, absoluteCapacity=1.0, usedResources=<memory:41984, vCores:36>usedCapacity=0.8541667, absoluteUsedCapacity=0.8541667, numApps=5, numContainers=36 usedCapacity=0.8541667 absoluteUsedCapacity=0.8541667 used=<memory:41984, vCores:36> cluster=<memory:49152, vCores:96>
2013-08-17 06:41:33,542 INFO org.apache.hadoop.yarn.server.resourcemanager.scheduler.capacity.ParentQueue: Re-sorting queues since queue: root.default stats: default: capacity=1.0, absoluteCapacity=1.0, usedResources=<memory:43008, vCores:37>usedCapacity=0.875, absoluteUsedCapacity=0.875, numApps=5, numContainers=37
2013-08-17 06:41:33,542 INFO org.apache.hadoop.yarn.server.resourcemanager.scheduler.capacity.ParentQueue: assignedContainer queue=root usedCapacity=0.875 absoluteUsedCapacity=0.875 used=<memory:43008, vCores:37> cluster=<memory:49152, vCores:96>
2013-08-17 06:41:33,542 INFO org.apache.hadoop.yarn.server.resourcemanager.rmcontainer.RMContainerImpl: container_1376720997863_0007_01_000034 Container Transitioned from NEW to ALLOCATED
2013-08-17 06:41:33,542 INFO org.apache.hadoop.yarn.server.resourcemanager.RMAuditLogger: USER=ubuntu	OPERATION=AM Allocated Container	TARGET=SchedulerApp	RESULT=SUCCESS	APPID=application_1376720997863_0007	CONTAINERID=container_1376720997863_0007_01_000034
2013-08-17 06:41:33,543 INFO org.apache.hadoop.yarn.server.resourcemanager.scheduler.common.fica.FiCaSchedulerNode: Assigned container container_1376720997863_0007_01_000034 of capacity <memory:1024, vCores:1> on host hadoop-512-3:56071, which currently has 2 containers, <memory:3072, vCores:2> used and <memory:5120, vCores:14> available
2013-08-17 06:41:33,543 INFO org.apache.hadoop.yarn.server.resourcemanager.scheduler.capacity.LeafQueue: assignedContainer application=application_1376720997863_0007 container=Container: [ContainerId: container_1376720997863_0007_01_000034, NodeId: hadoop-512-3:56071, NodeHttpAddress: hadoop-512-3:8042, Resource: <memory:1024, vCores:1>, Priority: 20, State: NEW, Token: null, Status: container_id {, app_attempt_id {, application_id {, id: 7, cluster_timestamp: 1376720997863, }, attemptId: 1, }, id: 34, }, state: C_NEW, ] containerId=container_1376720997863_0007_01_000034 queue=default: capacity=1.0, absoluteCapacity=1.0, usedResources=<memory:43008, vCores:37>usedCapacity=0.875, absoluteUsedCapacity=0.875, numApps=5, numContainers=37 usedCapacity=0.875 absoluteUsedCapacity=0.875 used=<memory:43008, vCores:37> cluster=<memory:49152, vCores:96>
2013-08-17 06:41:33,544 INFO org.apache.hadoop.yarn.server.resourcemanager.scheduler.capacity.ParentQueue: Re-sorting queues since queue: root.default stats: default: capacity=1.0, absoluteCapacity=1.0, usedResources=<memory:44032, vCores:38>usedCapacity=0.8958333, absoluteUsedCapacity=0.8958333, numApps=5, numContainers=38
2013-08-17 06:41:33,544 INFO org.apache.hadoop.yarn.server.resourcemanager.scheduler.capacity.ParentQueue: assignedContainer queue=root usedCapacity=0.8958333 absoluteUsedCapacity=0.8958333 used=<memory:44032, vCores:38> cluster=<memory:49152, vCores:96>
2013-08-17 06:41:33,544 INFO org.apache.hadoop.yarn.server.resourcemanager.rmcontainer.RMContainerImpl: container_1376720997863_0007_01_000035 Container Transitioned from NEW to ALLOCATED
2013-08-17 06:41:33,545 INFO org.apache.hadoop.yarn.server.resourcemanager.RMAuditLogger: USER=ubuntu	OPERATION=AM Allocated Container	TARGET=SchedulerApp	RESULT=SUCCESS	APPID=application_1376720997863_0007	CONTAINERID=container_1376720997863_0007_01_000035
2013-08-17 06:41:33,545 INFO org.apache.hadoop.yarn.server.resourcemanager.scheduler.common.fica.FiCaSchedulerNode: Assigned container container_1376720997863_0007_01_000035 of capacity <memory:1024, vCores:1> on host hadoop-512-3:56071, which currently has 3 containers, <memory:4096, vCores:3> used and <memory:4096, vCores:13> available
2013-08-17 06:41:33,546 INFO org.apache.hadoop.yarn.server.resourcemanager.scheduler.capacity.LeafQueue: assignedContainer application=application_1376720997863_0007 container=Container: [ContainerId: container_1376720997863_0007_01_000035, NodeId: hadoop-512-3:56071, NodeHttpAddress: hadoop-512-3:8042, Resource: <memory:1024, vCores:1>, Priority: 20, State: NEW, Token: null, Status: container_id {, app_attempt_id {, application_id {, id: 7, cluster_timestamp: 1376720997863, }, attemptId: 1, }, id: 35, }, state: C_NEW, ] containerId=container_1376720997863_0007_01_000035 queue=default: capacity=1.0, absoluteCapacity=1.0, usedResources=<memory:44032, vCores:38>usedCapacity=0.8958333, absoluteUsedCapacity=0.8958333, numApps=5, numContainers=38 usedCapacity=0.8958333 absoluteUsedCapacity=0.8958333 used=<memory:44032, vCores:38> cluster=<memory:49152, vCores:96>
2013-08-17 06:41:33,546 INFO org.apache.hadoop.yarn.server.resourcemanager.scheduler.capacity.ParentQueue: Re-sorting queues since queue: root.default stats: default: capacity=1.0, absoluteCapacity=1.0, usedResources=<memory:45056, vCores:39>usedCapacity=0.9166667, absoluteUsedCapacity=0.9166667, numApps=5, numContainers=39
2013-08-17 06:41:33,546 INFO org.apache.hadoop.yarn.server.resourcemanager.scheduler.capacity.ParentQueue: assignedContainer queue=root usedCapacity=0.9166667 absoluteUsedCapacity=0.9166667 used=<memory:45056, vCores:39> cluster=<memory:49152, vCores:96>
2013-08-17 06:41:33,547 INFO org.apache.hadoop.yarn.server.resourcemanager.rmcontainer.RMContainerImpl: container_1376720997863_0007_01_000036 Container Transitioned from NEW to ALLOCATED
2013-08-17 06:41:33,547 INFO org.apache.hadoop.yarn.server.resourcemanager.RMAuditLogger: USER=ubuntu	OPERATION=AM Allocated Container	TARGET=SchedulerApp	RESULT=SUCCESS	APPID=application_1376720997863_0007	CONTAINERID=container_1376720997863_0007_01_000036
2013-08-17 06:41:33,547 INFO org.apache.hadoop.yarn.server.resourcemanager.scheduler.common.fica.FiCaSchedulerNode: Assigned container container_1376720997863_0007_01_000036 of capacity <memory:1024, vCores:1> on host hadoop-512-3:56071, which currently has 4 containers, <memory:5120, vCores:4> used and <memory:3072, vCores:12> available
2013-08-17 06:41:33,548 INFO org.apache.hadoop.yarn.server.resourcemanager.scheduler.capacity.LeafQueue: assignedContainer application=application_1376720997863_0007 container=Container: [ContainerId: container_1376720997863_0007_01_000036, NodeId: hadoop-512-3:56071, NodeHttpAddress: hadoop-512-3:8042, Resource: <memory:1024, vCores:1>, Priority: 20, State: NEW, Token: null, Status: container_id {, app_attempt_id {, application_id {, id: 7, cluster_timestamp: 1376720997863, }, attemptId: 1, }, id: 36, }, state: C_NEW, ] containerId=container_1376720997863_0007_01_000036 queue=default: capacity=1.0, absoluteCapacity=1.0, usedResources=<memory:45056, vCores:39>usedCapacity=0.9166667, absoluteUsedCapacity=0.9166667, numApps=5, numContainers=39 usedCapacity=0.9166667 absoluteUsedCapacity=0.9166667 used=<memory:45056, vCores:39> cluster=<memory:49152, vCores:96>
2013-08-17 06:41:33,548 INFO org.apache.hadoop.yarn.server.resourcemanager.scheduler.capacity.ParentQueue: Re-sorting queues since queue: root.default stats: default: capacity=1.0, absoluteCapacity=1.0, usedResources=<memory:46080, vCores:40>usedCapacity=0.9375, absoluteUsedCapacity=0.9375, numApps=5, numContainers=40
2013-08-17 06:41:33,548 INFO org.apache.hadoop.yarn.server.resourcemanager.scheduler.capacity.ParentQueue: assignedContainer queue=root usedCapacity=0.9375 absoluteUsedCapacity=0.9375 used=<memory:46080, vCores:40> cluster=<memory:49152, vCores:96>
2013-08-17 06:41:33,549 INFO org.apache.hadoop.yarn.server.resourcemanager.rmcontainer.RMContainerImpl: container_1376720997863_0007_01_000037 Container Transitioned from NEW to ALLOCATED
2013-08-17 06:41:33,549 INFO org.apache.hadoop.yarn.server.resourcemanager.RMAuditLogger: USER=ubuntu	OPERATION=AM Allocated Container	TARGET=SchedulerApp	RESULT=SUCCESS	APPID=application_1376720997863_0007	CONTAINERID=container_1376720997863_0007_01_000037
2013-08-17 06:41:33,549 INFO org.apache.hadoop.yarn.server.resourcemanager.scheduler.common.fica.FiCaSchedulerNode: Assigned container container_1376720997863_0007_01_000037 of capacity <memory:1024, vCores:1> on host hadoop-512-3:56071, which currently has 5 containers, <memory:6144, vCores:5> used and <memory:2048, vCores:11> available
2013-08-17 06:41:33,550 INFO org.apache.hadoop.yarn.server.resourcemanager.scheduler.capacity.LeafQueue: assignedContainer application=application_1376720997863_0007 container=Container: [ContainerId: container_1376720997863_0007_01_000037, NodeId: hadoop-512-3:56071, NodeHttpAddress: hadoop-512-3:8042, Resource: <memory:1024, vCores:1>, Priority: 20, State: NEW, Token: null, Status: container_id {, app_attempt_id {, application_id {, id: 7, cluster_timestamp: 1376720997863, }, attemptId: 1, }, id: 37, }, state: C_NEW, ] containerId=container_1376720997863_0007_01_000037 queue=default: capacity=1.0, absoluteCapacity=1.0, usedResources=<memory:46080, vCores:40>usedCapacity=0.9375, absoluteUsedCapacity=0.9375, numApps=5, numContainers=40 usedCapacity=0.9375 absoluteUsedCapacity=0.9375 used=<memory:46080, vCores:40> cluster=<memory:49152, vCores:96>
2013-08-17 06:41:33,550 INFO org.apache.hadoop.yarn.server.resourcemanager.scheduler.capacity.ParentQueue: Re-sorting queues since queue: root.default stats: default: capacity=1.0, absoluteCapacity=1.0, usedResources=<memory:47104, vCores:41>usedCapacity=0.9583333, absoluteUsedCapacity=0.9583333, numApps=5, numContainers=41
2013-08-17 06:41:33,550 INFO org.apache.hadoop.yarn.server.resourcemanager.scheduler.capacity.ParentQueue: assignedContainer queue=root usedCapacity=0.9583333 absoluteUsedCapacity=0.9583333 used=<memory:47104, vCores:41> cluster=<memory:49152, vCores:96>
2013-08-17 06:41:33,551 INFO org.apache.hadoop.yarn.server.resourcemanager.rmcontainer.RMContainerImpl: container_1376720997863_0007_01_000038 Container Transitioned from NEW to ALLOCATED
2013-08-17 06:41:33,551 INFO org.apache.hadoop.yarn.server.resourcemanager.RMAuditLogger: USER=ubuntu	OPERATION=AM Allocated Container	TARGET=SchedulerApp	RESULT=SUCCESS	APPID=application_1376720997863_0007	CONTAINERID=container_1376720997863_0007_01_000038
2013-08-17 06:41:33,551 INFO org.apache.hadoop.yarn.server.resourcemanager.scheduler.common.fica.FiCaSchedulerNode: Assigned container container_1376720997863_0007_01_000038 of capacity <memory:1024, vCores:1> on host hadoop-512-3:56071, which currently has 6 containers, <memory:7168, vCores:6> used and <memory:1024, vCores:10> available
2013-08-17 06:41:33,552 INFO org.apache.hadoop.yarn.server.resourcemanager.scheduler.capacity.LeafQueue: assignedContainer application=application_1376720997863_0007 container=Container: [ContainerId: container_1376720997863_0007_01_000038, NodeId: hadoop-512-3:56071, NodeHttpAddress: hadoop-512-3:8042, Resource: <memory:1024, vCores:1>, Priority: 20, State: NEW, Token: null, Status: container_id {, app_attempt_id {, application_id {, id: 7, cluster_timestamp: 1376720997863, }, attemptId: 1, }, id: 38, }, state: C_NEW, ] containerId=container_1376720997863_0007_01_000038 queue=default: capacity=1.0, absoluteCapacity=1.0, usedResources=<memory:47104, vCores:41>usedCapacity=0.9583333, absoluteUsedCapacity=0.9583333, numApps=5, numContainers=41 usedCapacity=0.9583333 absoluteUsedCapacity=0.9583333 used=<memory:47104, vCores:41> cluster=<memory:49152, vCores:96>
2013-08-17 06:41:33,552 INFO org.apache.hadoop.yarn.server.resourcemanager.scheduler.capacity.ParentQueue: Re-sorting queues since queue: root.default stats: default: capacity=1.0, absoluteCapacity=1.0, usedResources=<memory:48128, vCores:42>usedCapacity=0.9791667, absoluteUsedCapacity=0.9791667, numApps=5, numContainers=42
2013-08-17 06:41:33,552 INFO org.apache.hadoop.yarn.server.resourcemanager.scheduler.capacity.ParentQueue: assignedContainer queue=root usedCapacity=0.9791667 absoluteUsedCapacity=0.9791667 used=<memory:48128, vCores:42> cluster=<memory:49152, vCores:96>
2013-08-17 06:41:33,553 INFO org.apache.hadoop.yarn.server.resourcemanager.rmcontainer.RMContainerImpl: container_1376720997863_0007_01_000039 Container Transitioned from NEW to ALLOCATED
2013-08-17 06:41:33,553 INFO org.apache.hadoop.yarn.server.resourcemanager.RMAuditLogger: USER=ubuntu	OPERATION=AM Allocated Container	TARGET=SchedulerApp	RESULT=SUCCESS	APPID=application_1376720997863_0007	CONTAINERID=container_1376720997863_0007_01_000039
2013-08-17 06:41:33,553 INFO org.apache.hadoop.yarn.server.resourcemanager.scheduler.common.fica.FiCaSchedulerNode: Assigned container container_1376720997863_0007_01_000039 of capacity <memory:1024, vCores:1> on host hadoop-512-3:56071, which currently has 7 containers, <memory:8192, vCores:7> used and <memory:0, vCores:9> available
2013-08-17 06:41:33,554 INFO org.apache.hadoop.yarn.server.resourcemanager.scheduler.capacity.LeafQueue: assignedContainer application=application_1376720997863_0007 container=Container: [ContainerId: container_1376720997863_0007_01_000039, NodeId: hadoop-512-3:56071, NodeHttpAddress: hadoop-512-3:8042, Resource: <memory:1024, vCores:1>, Priority: 20, State: NEW, Token: null, Status: container_id {, app_attempt_id {, application_id {, id: 7, cluster_timestamp: 1376720997863, }, attemptId: 1, }, id: 39, }, state: C_NEW, ] containerId=container_1376720997863_0007_01_000039 queue=default: capacity=1.0, absoluteCapacity=1.0, usedResources=<memory:48128, vCores:42>usedCapacity=0.9791667, absoluteUsedCapacity=0.9791667, numApps=5, numContainers=42 usedCapacity=0.9791667 absoluteUsedCapacity=0.9791667 used=<memory:48128, vCores:42> cluster=<memory:49152, vCores:96>
2013-08-17 06:41:33,554 INFO org.apache.hadoop.yarn.server.resourcemanager.scheduler.capacity.ParentQueue: Re-sorting queues since queue: root.default stats: default: capacity=1.0, absoluteCapacity=1.0, usedResources=<memory:49152, vCores:43>usedCapacity=1.0, absoluteUsedCapacity=1.0, numApps=5, numContainers=43
2013-08-17 06:41:33,554 INFO org.apache.hadoop.yarn.server.resourcemanager.scheduler.capacity.ParentQueue: assignedContainer queue=root usedCapacity=1.0 absoluteUsedCapacity=1.0 used=<memory:49152, vCores:43> cluster=<memory:49152, vCores:96>
2013-08-17 06:41:34,092 INFO org.apache.hadoop.yarn.server.resourcemanager.rmcontainer.RMContainerImpl: container_1376720997863_0007_01_000002 Container Transitioned from ALLOCATED to ACQUIRED
2013-08-17 06:41:34,093 INFO org.apache.hadoop.yarn.server.resourcemanager.rmcontainer.RMContainerImpl: container_1376720997863_0007_01_000003 Container Transitioned from ALLOCATED to ACQUIRED
2013-08-17 06:41:34,094 INFO org.apache.hadoop.yarn.server.resourcemanager.rmcontainer.RMContainerImpl: container_1376720997863_0007_01_000004 Container Transitioned from ALLOCATED to ACQUIRED
2013-08-17 06:41:34,095 INFO org.apache.hadoop.yarn.server.resourcemanager.rmcontainer.RMContainerImpl: container_1376720997863_0007_01_000005 Container Transitioned from ALLOCATED to ACQUIRED
2013-08-17 06:41:34,096 INFO org.apache.hadoop.yarn.server.resourcemanager.rmcontainer.RMContainerImpl: container_1376720997863_0007_01_000006 Container Transitioned from ALLOCATED to ACQUIRED
2013-08-17 06:41:34,096 INFO org.apache.hadoop.yarn.server.resourcemanager.rmcontainer.RMContainerImpl: container_1376720997863_0007_01_000007 Container Transitioned from ALLOCATED to ACQUIRED
2013-08-17 06:41:34,097 INFO org.apache.hadoop.yarn.server.resourcemanager.rmcontainer.RMContainerImpl: container_1376720997863_0007_01_000008 Container Transitioned from ALLOCATED to ACQUIRED
2013-08-17 06:41:34,098 INFO org.apache.hadoop.yarn.server.resourcemanager.rmcontainer.RMContainerImpl: container_1376720997863_0007_01_000009 Container Transitioned from ALLOCATED to ACQUIRED
2013-08-17 06:41:34,099 INFO org.apache.hadoop.yarn.server.resourcemanager.rmcontainer.RMContainerImpl: container_1376720997863_0007_01_000010 Container Transitioned from ALLOCATED to ACQUIRED
2013-08-17 06:41:34,101 INFO org.apache.hadoop.yarn.server.resourcemanager.rmcontainer.RMContainerImpl: container_1376720997863_0007_01_000011 Container Transitioned from ALLOCATED to ACQUIRED
2013-08-17 06:41:34,101 INFO org.apache.hadoop.yarn.server.resourcemanager.rmcontainer.RMContainerImpl: container_1376720997863_0007_01_000012 Container Transitioned from ALLOCATED to ACQUIRED
2013-08-17 06:41:34,102 INFO org.apache.hadoop.yarn.server.resourcemanager.rmcontainer.RMContainerImpl: container_1376720997863_0007_01_000013 Container Transitioned from ALLOCATED to ACQUIRED
2013-08-17 06:41:34,102 INFO org.apache.hadoop.yarn.server.resourcemanager.rmcontainer.RMContainerImpl: container_1376720997863_0007_01_000014 Container Transitioned from ALLOCATED to ACQUIRED
2013-08-17 06:41:34,102 INFO org.apache.hadoop.yarn.server.resourcemanager.rmcontainer.RMContainerImpl: container_1376720997863_0007_01_000015 Container Transitioned from ALLOCATED to ACQUIRED
2013-08-17 06:41:34,102 INFO org.apache.hadoop.yarn.server.resourcemanager.rmcontainer.RMContainerImpl: container_1376720997863_0007_01_000016 Container Transitioned from ALLOCATED to ACQUIRED
2013-08-17 06:41:34,102 INFO org.apache.hadoop.yarn.server.resourcemanager.rmcontainer.RMContainerImpl: container_1376720997863_0007_01_000017 Container Transitioned from ALLOCATED to ACQUIRED
2013-08-17 06:41:34,103 INFO org.apache.hadoop.yarn.server.resourcemanager.rmcontainer.RMContainerImpl: container_1376720997863_0007_01_000018 Container Transitioned from ALLOCATED to ACQUIRED
2013-08-17 06:41:34,103 INFO org.apache.hadoop.yarn.server.resourcemanager.rmcontainer.RMContainerImpl: container_1376720997863_0007_01_000019 Container Transitioned from ALLOCATED to ACQUIRED
2013-08-17 06:41:34,103 INFO org.apache.hadoop.yarn.server.resourcemanager.rmcontainer.RMContainerImpl: container_1376720997863_0007_01_000020 Container Transitioned from ALLOCATED to ACQUIRED
2013-08-17 06:41:34,103 INFO org.apache.hadoop.yarn.server.resourcemanager.rmcontainer.RMContainerImpl: container_1376720997863_0007_01_000021 Container Transitioned from ALLOCATED to ACQUIRED
2013-08-17 06:41:34,104 INFO org.apache.hadoop.yarn.server.resourcemanager.rmcontainer.RMContainerImpl: container_1376720997863_0007_01_000022 Container Transitioned from ALLOCATED to ACQUIRED
2013-08-17 06:41:34,104 INFO org.apache.hadoop.yarn.server.resourcemanager.rmcontainer.RMContainerImpl: container_1376720997863_0007_01_000023 Container Transitioned from ALLOCATED to ACQUIRED
2013-08-17 06:41:34,104 INFO org.apache.hadoop.yarn.server.resourcemanager.rmcontainer.RMContainerImpl: container_1376720997863_0007_01_000024 Container Transitioned from ALLOCATED to ACQUIRED
2013-08-17 06:41:34,104 INFO org.apache.hadoop.yarn.server.resourcemanager.rmcontainer.RMContainerImpl: container_1376720997863_0007_01_000025 Container Transitioned from ALLOCATED to ACQUIRED
2013-08-17 06:41:34,104 INFO org.apache.hadoop.yarn.server.resourcemanager.rmcontainer.RMContainerImpl: container_1376720997863_0007_01_000026 Container Transitioned from ALLOCATED to ACQUIRED
2013-08-17 06:41:34,105 INFO org.apache.hadoop.yarn.server.resourcemanager.rmcontainer.RMContainerImpl: container_1376720997863_0007_01_000027 Container Transitioned from ALLOCATED to ACQUIRED
2013-08-17 06:41:34,105 INFO org.apache.hadoop.yarn.server.resourcemanager.rmcontainer.RMContainerImpl: container_1376720997863_0007_01_000028 Container Transitioned from ALLOCATED to ACQUIRED
2013-08-17 06:41:34,105 INFO org.apache.hadoop.yarn.server.resourcemanager.rmcontainer.RMContainerImpl: container_1376720997863_0007_01_000029 Container Transitioned from ALLOCATED to ACQUIRED
2013-08-17 06:41:34,105 INFO org.apache.hadoop.yarn.server.resourcemanager.rmcontainer.RMContainerImpl: container_1376720997863_0007_01_000030 Container Transitioned from ALLOCATED to ACQUIRED
2013-08-17 06:41:34,105 INFO org.apache.hadoop.yarn.server.resourcemanager.rmcontainer.RMContainerImpl: container_1376720997863_0007_01_000031 Container Transitioned from ALLOCATED to ACQUIRED
2013-08-17 06:41:34,106 INFO org.apache.hadoop.yarn.server.resourcemanager.rmcontainer.RMContainerImpl: container_1376720997863_0007_01_000032 Container Transitioned from ALLOCATED to ACQUIRED
2013-08-17 06:41:34,106 INFO org.apache.hadoop.yarn.server.resourcemanager.rmcontainer.RMContainerImpl: container_1376720997863_0007_01_000033 Container Transitioned from ALLOCATED to ACQUIRED
2013-08-17 06:41:34,106 INFO org.apache.hadoop.yarn.server.resourcemanager.rmcontainer.RMContainerImpl: container_1376720997863_0007_01_000034 Container Transitioned from ALLOCATED to ACQUIRED
2013-08-17 06:41:34,106 INFO org.apache.hadoop.yarn.server.resourcemanager.rmcontainer.RMContainerImpl: container_1376720997863_0007_01_000035 Container Transitioned from ALLOCATED to ACQUIRED
2013-08-17 06:41:34,107 INFO org.apache.hadoop.yarn.server.resourcemanager.rmcontainer.RMContainerImpl: container_1376720997863_0007_01_000036 Container Transitioned from ALLOCATED to ACQUIRED
2013-08-17 06:41:34,107 INFO org.apache.hadoop.yarn.server.resourcemanager.rmcontainer.RMContainerImpl: container_1376720997863_0007_01_000037 Container Transitioned from ALLOCATED to ACQUIRED
2013-08-17 06:41:34,107 INFO org.apache.hadoop.yarn.server.resourcemanager.rmcontainer.RMContainerImpl: container_1376720997863_0007_01_000038 Container Transitioned from ALLOCATED to ACQUIRED
2013-08-17 06:41:34,107 INFO org.apache.hadoop.yarn.server.resourcemanager.rmcontainer.RMContainerImpl: container_1376720997863_0007_01_000039 Container Transitioned from ALLOCATED to ACQUIRED
2013-08-17 06:41:35,121 INFO org.apache.hadoop.yarn.server.resourcemanager.rmcontainer.RMContainerImpl: container_1376720997863_0007_01_000008 Container Transitioned from ACQUIRED to RUNNING
2013-08-17 06:41:35,122 INFO org.apache.hadoop.yarn.server.resourcemanager.rmcontainer.RMContainerImpl: container_1376720997863_0007_01_000009 Container Transitioned from ACQUIRED to RUNNING
2013-08-17 06:41:35,123 INFO org.apache.hadoop.yarn.server.resourcemanager.rmcontainer.RMContainerImpl: container_1376720997863_0007_01_000010 Container Transitioned from ACQUIRED to RUNNING
2013-08-17 06:41:35,125 INFO org.apache.hadoop.yarn.server.resourcemanager.rmcontainer.RMContainerImpl: container_1376720997863_0007_01_000011 Container Transitioned from ACQUIRED to RUNNING
2013-08-17 06:41:35,127 INFO org.apache.hadoop.yarn.server.resourcemanager.rmcontainer.RMContainerImpl: container_1376720997863_0007_01_000012 Container Transitioned from ACQUIRED to RUNNING
2013-08-17 06:41:35,128 INFO org.apache.hadoop.yarn.server.resourcemanager.rmcontainer.RMContainerImpl: container_1376720997863_0007_01_000013 Container Transitioned from ACQUIRED to RUNNING
2013-08-17 06:41:35,136 INFO org.apache.hadoop.yarn.server.resourcemanager.rmcontainer.RMContainerImpl: container_1376720997863_0007_01_000002 Container Transitioned from ACQUIRED to RUNNING
2013-08-17 06:41:35,137 INFO org.apache.hadoop.yarn.server.resourcemanager.rmcontainer.RMContainerImpl: container_1376720997863_0007_01_000003 Container Transitioned from ACQUIRED to RUNNING
2013-08-17 06:41:35,137 INFO org.apache.hadoop.yarn.server.resourcemanager.rmcontainer.RMContainerImpl: container_1376720997863_0007_01_000004 Container Transitioned from ACQUIRED to RUNNING
2013-08-17 06:41:35,138 INFO org.apache.hadoop.yarn.server.resourcemanager.rmcontainer.RMContainerImpl: container_1376720997863_0007_01_000005 Container Transitioned from ACQUIRED to RUNNING
2013-08-17 06:41:35,138 INFO org.apache.hadoop.yarn.server.resourcemanager.rmcontainer.RMContainerImpl: container_1376720997863_0007_01_000006 Container Transitioned from ACQUIRED to RUNNING
2013-08-17 06:41:35,139 INFO org.apache.hadoop.yarn.server.resourcemanager.rmcontainer.RMContainerImpl: container_1376720997863_0007_01_000007 Container Transitioned from ACQUIRED to RUNNING
2013-08-17 06:41:35,259 INFO org.apache.hadoop.yarn.server.resourcemanager.rmcontainer.RMContainerImpl: container_1376720997863_0007_01_000014 Container Transitioned from ACQUIRED to RUNNING
2013-08-17 06:41:35,261 INFO org.apache.hadoop.yarn.server.resourcemanager.rmcontainer.RMContainerImpl: container_1376720997863_0007_01_000015 Container Transitioned from ACQUIRED to RUNNING
2013-08-17 06:41:35,264 INFO org.apache.hadoop.yarn.server.resourcemanager.rmcontainer.RMContainerImpl: container_1376720997863_0007_01_000016 Container Transitioned from ACQUIRED to RUNNING
2013-08-17 06:41:35,264 INFO org.apache.hadoop.yarn.server.resourcemanager.rmcontainer.RMContainerImpl: container_1376720997863_0007_01_000017 Container Transitioned from ACQUIRED to RUNNING
2013-08-17 06:41:35,265 INFO org.apache.hadoop.yarn.server.resourcemanager.rmcontainer.RMContainerImpl: container_1376720997863_0007_01_000018 Container Transitioned from ACQUIRED to RUNNING
2013-08-17 06:41:35,266 INFO org.apache.hadoop.yarn.server.resourcemanager.rmcontainer.RMContainerImpl: container_1376720997863_0007_01_000019 Container Transitioned from ACQUIRED to RUNNING
2013-08-17 06:41:35,281 INFO org.apache.hadoop.yarn.server.resourcemanager.rmcontainer.RMContainerImpl: container_1376720997863_0007_01_000020 Container Transitioned from ACQUIRED to RUNNING
2013-08-17 06:41:35,282 INFO org.apache.hadoop.yarn.server.resourcemanager.rmcontainer.RMContainerImpl: container_1376720997863_0007_01_000021 Container Transitioned from ACQUIRED to RUNNING
2013-08-17 06:41:35,282 INFO org.apache.hadoop.yarn.server.resourcemanager.rmcontainer.RMContainerImpl: container_1376720997863_0007_01_000022 Container Transitioned from ACQUIRED to RUNNING
2013-08-17 06:41:35,283 INFO org.apache.hadoop.yarn.server.resourcemanager.rmcontainer.RMContainerImpl: container_1376720997863_0007_01_000023 Container Transitioned from ACQUIRED to RUNNING
2013-08-17 06:41:35,283 INFO org.apache.hadoop.yarn.server.resourcemanager.rmcontainer.RMContainerImpl: container_1376720997863_0007_01_000024 Container Transitioned from ACQUIRED to RUNNING
2013-08-17 06:41:35,284 INFO org.apache.hadoop.yarn.server.resourcemanager.rmcontainer.RMContainerImpl: container_1376720997863_0007_01_000025 Container Transitioned from ACQUIRED to RUNNING
2013-08-17 06:41:35,556 INFO org.apache.hadoop.yarn.server.resourcemanager.rmcontainer.RMContainerImpl: container_1376720997863_0007_01_000026 Container Transitioned from ACQUIRED to RUNNING
2013-08-17 06:41:35,557 INFO org.apache.hadoop.yarn.server.resourcemanager.rmcontainer.RMContainerImpl: container_1376720997863_0007_01_000027 Container Transitioned from ACQUIRED to RUNNING
2013-08-17 06:41:35,557 INFO org.apache.hadoop.yarn.server.resourcemanager.rmcontainer.RMContainerImpl: container_1376720997863_0007_01_000028 Container Transitioned from ACQUIRED to RUNNING
2013-08-17 06:41:35,558 INFO org.apache.hadoop.yarn.server.resourcemanager.rmcontainer.RMContainerImpl: container_1376720997863_0007_01_000029 Container Transitioned from ACQUIRED to RUNNING
2013-08-17 06:41:35,559 INFO org.apache.hadoop.yarn.server.resourcemanager.rmcontainer.RMContainerImpl: container_1376720997863_0007_01_000030 Container Transitioned from ACQUIRED to RUNNING
2013-08-17 06:41:35,559 INFO org.apache.hadoop.yarn.server.resourcemanager.rmcontainer.RMContainerImpl: container_1376720997863_0007_01_000031 Container Transitioned from ACQUIRED to RUNNING
2013-08-17 06:41:35,560 INFO org.apache.hadoop.yarn.server.resourcemanager.rmcontainer.RMContainerImpl: container_1376720997863_0007_01_000032 Container Transitioned from ACQUIRED to RUNNING
2013-08-17 06:41:35,560 INFO org.apache.hadoop.yarn.server.resourcemanager.rmcontainer.RMContainerImpl: container_1376720997863_0007_01_000033 Container Transitioned from ACQUIRED to RUNNING
2013-08-17 06:41:35,562 INFO org.apache.hadoop.yarn.server.resourcemanager.rmcontainer.RMContainerImpl: container_1376720997863_0007_01_000034 Container Transitioned from ACQUIRED to RUNNING
2013-08-17 06:41:35,562 INFO org.apache.hadoop.yarn.server.resourcemanager.rmcontainer.RMContainerImpl: container_1376720997863_0007_01_000035 Container Transitioned from ACQUIRED to RUNNING
2013-08-17 06:41:35,562 INFO org.apache.hadoop.yarn.server.resourcemanager.rmcontainer.RMContainerImpl: container_1376720997863_0007_01_000036 Container Transitioned from ACQUIRED to RUNNING
2013-08-17 06:41:35,562 INFO org.apache.hadoop.yarn.server.resourcemanager.rmcontainer.RMContainerImpl: container_1376720997863_0007_01_000037 Container Transitioned from ACQUIRED to RUNNING
2013-08-17 06:41:35,562 INFO org.apache.hadoop.yarn.server.resourcemanager.rmcontainer.RMContainerImpl: container_1376720997863_0007_01_000038 Container Transitioned from ACQUIRED to RUNNING
2013-08-17 06:41:35,563 INFO org.apache.hadoop.yarn.server.resourcemanager.rmcontainer.RMContainerImpl: container_1376720997863_0007_01_000039 Container Transitioned from ACQUIRED to RUNNING
2013-08-17 06:41:53,395 INFO org.apache.hadoop.yarn.server.resourcemanager.rmcontainer.RMContainerImpl: container_1376720997863_0007_01_000013 Container Transitioned from RUNNING to COMPLETED
2013-08-17 06:41:53,395 INFO org.apache.hadoop.yarn.server.resourcemanager.scheduler.common.fica.FiCaSchedulerApp: Completed container: container_1376720997863_0007_01_000013 in state: COMPLETED event:FINISHED
2013-08-17 06:41:53,395 INFO org.apache.hadoop.yarn.server.resourcemanager.RMAuditLogger: USER=ubuntu	OPERATION=AM Released Container	TARGET=SchedulerApp	RESULT=SUCCESS	APPID=application_1376720997863_0007	CONTAINERID=container_1376720997863_0007_01_000013
2013-08-17 06:41:53,396 INFO org.apache.hadoop.yarn.server.resourcemanager.scheduler.common.fica.FiCaSchedulerNode: Released container container_1376720997863_0007_01_000013 of capacity <memory:1024, vCores:1> on host hadoop-512-4:45085, which currently has 6 containers, <memory:7168, vCores:6> used and <memory:1024, vCores:10> available, release resources=true
2013-08-17 06:41:53,396 INFO org.apache.hadoop.yarn.server.resourcemanager.scheduler.capacity.LeafQueue: default used=<memory:48128, vCores:42> numContainers=42 user=ubuntu user-resources=<memory:48128, vCores:42>
2013-08-17 06:41:53,398 INFO org.apache.hadoop.yarn.server.resourcemanager.scheduler.capacity.LeafQueue: completedContainer container=Container: [ContainerId: container_1376720997863_0007_01_000013, NodeId: hadoop-512-4:45085, NodeHttpAddress: hadoop-512-4:8042, Resource: <memory:1024, vCores:1>, Priority: 20, State: NEW, Token: null, Status: container_id {, app_attempt_id {, application_id {, id: 7, cluster_timestamp: 1376720997863, }, attemptId: 1, }, id: 13, }, state: C_COMPLETE, diagnostics: "Container killed by the ApplicationMaster.\n\n", exit_status: 143, ] resource=<memory:1024, vCores:1> queue=default: capacity=1.0, absoluteCapacity=1.0, usedResources=<memory:48128, vCores:42>usedCapacity=0.9791667, absoluteUsedCapacity=0.9791667, numApps=5, numContainers=42 usedCapacity=0.9791667 absoluteUsedCapacity=0.9791667 used=<memory:48128, vCores:42> cluster=<memory:49152, vCores:96>
2013-08-17 06:41:53,399 INFO org.apache.hadoop.yarn.server.resourcemanager.scheduler.capacity.ParentQueue: completedContainer queue=root usedCapacity=0.9791667 absoluteUsedCapacity=0.9791667 used=<memory:48128, vCores:42> cluster=<memory:49152, vCores:96>
2013-08-17 06:41:53,399 INFO org.apache.hadoop.yarn.server.resourcemanager.scheduler.capacity.CapacityScheduler: Application appattempt_1376720997863_0007_000001 released container container_1376720997863_0007_01_000013 on node: host: hadoop-512-4:45085 #containers=6 available=1024 used=7168 with event: FINISHED
2013-08-17 06:41:53,399 INFO org.apache.hadoop.yarn.server.resourcemanager.rmcontainer.RMContainerImpl: container_1376720997863_0006_01_000002 Container Transitioned from NEW to ALLOCATED
2013-08-17 06:41:53,399 INFO org.apache.hadoop.yarn.server.resourcemanager.RMAuditLogger: USER=ubuntu	OPERATION=AM Allocated Container	TARGET=SchedulerApp	RESULT=SUCCESS	APPID=application_1376720997863_0006	CONTAINERID=container_1376720997863_0006_01_000002
2013-08-17 06:41:53,400 INFO org.apache.hadoop.yarn.server.resourcemanager.scheduler.common.fica.FiCaSchedulerNode: Assigned container container_1376720997863_0006_01_000002 of capacity <memory:1024, vCores:1> on host hadoop-512-4:45085, which currently has 7 containers, <memory:8192, vCores:7> used and <memory:0, vCores:9> available
2013-08-17 06:41:53,401 INFO org.apache.hadoop.yarn.server.resourcemanager.scheduler.capacity.LeafQueue: assignedContainer application=application_1376720997863_0006 container=Container: [ContainerId: container_1376720997863_0006_01_000002, NodeId: hadoop-512-4:45085, NodeHttpAddress: hadoop-512-4:8042, Resource: <memory:1024, vCores:1>, Priority: 20, State: NEW, Token: null, Status: container_id {, app_attempt_id {, application_id {, id: 6, cluster_timestamp: 1376720997863, }, attemptId: 1, }, id: 2, }, state: C_NEW, ] containerId=container_1376720997863_0006_01_000002 queue=default: capacity=1.0, absoluteCapacity=1.0, usedResources=<memory:48128, vCores:42>usedCapacity=0.9791667, absoluteUsedCapacity=0.9791667, numApps=5, numContainers=42 usedCapacity=0.9791667 absoluteUsedCapacity=0.9791667 used=<memory:48128, vCores:42> cluster=<memory:49152, vCores:96>
2013-08-17 06:41:53,401 INFO org.apache.hadoop.yarn.server.resourcemanager.scheduler.capacity.ParentQueue: Re-sorting queues since queue: root.default stats: default: capacity=1.0, absoluteCapacity=1.0, usedResources=<memory:49152, vCores:43>usedCapacity=1.0, absoluteUsedCapacity=1.0, numApps=5, numContainers=43
2013-08-17 06:41:53,401 INFO org.apache.hadoop.yarn.server.resourcemanager.scheduler.capacity.ParentQueue: assignedContainer queue=root usedCapacity=1.0 absoluteUsedCapacity=1.0 used=<memory:49152, vCores:43> cluster=<memory:49152, vCores:96>
2013-08-17 06:41:53,893 INFO org.apache.hadoop.yarn.server.resourcemanager.rmcontainer.RMContainerImpl: container_1376720997863_0006_01_000002 Container Transitioned from ALLOCATED to ACQUIRED
2013-08-17 06:41:54,407 INFO org.apache.hadoop.yarn.server.resourcemanager.rmcontainer.RMContainerImpl: container_1376720997863_0007_01_000009 Container Transitioned from RUNNING to COMPLETED
2013-08-17 06:41:54,408 INFO org.apache.hadoop.yarn.server.resourcemanager.scheduler.common.fica.FiCaSchedulerApp: Completed container: container_1376720997863_0007_01_000009 in state: COMPLETED event:FINISHED
2013-08-17 06:41:54,408 INFO org.apache.hadoop.yarn.server.resourcemanager.RMAuditLogger: USER=ubuntu	OPERATION=AM Released Container	TARGET=SchedulerApp	RESULT=SUCCESS	APPID=application_1376720997863_0007	CONTAINERID=container_1376720997863_0007_01_000009
2013-08-17 06:41:54,408 INFO org.apache.hadoop.yarn.server.resourcemanager.scheduler.common.fica.FiCaSchedulerNode: Released container container_1376720997863_0007_01_000009 of capacity <memory:1024, vCores:1> on host hadoop-512-4:45085, which currently has 6 containers, <memory:7168, vCores:6> used and <memory:1024, vCores:10> available, release resources=true
2013-08-17 06:41:54,408 INFO org.apache.hadoop.yarn.server.resourcemanager.scheduler.capacity.LeafQueue: default used=<memory:48128, vCores:42> numContainers=42 user=ubuntu user-resources=<memory:48128, vCores:42>
2013-08-17 06:41:54,409 INFO org.apache.hadoop.yarn.server.resourcemanager.scheduler.capacity.LeafQueue: completedContainer container=Container: [ContainerId: container_1376720997863_0007_01_000009, NodeId: hadoop-512-4:45085, NodeHttpAddress: hadoop-512-4:8042, Resource: <memory:1024, vCores:1>, Priority: 20, State: NEW, Token: null, Status: container_id {, app_attempt_id {, application_id {, id: 7, cluster_timestamp: 1376720997863, }, attemptId: 1, }, id: 9, }, state: C_COMPLETE, diagnostics: "Container killed by the ApplicationMaster.\n\n", exit_status: 143, ] resource=<memory:1024, vCores:1> queue=default: capacity=1.0, absoluteCapacity=1.0, usedResources=<memory:48128, vCores:42>usedCapacity=0.9791667, absoluteUsedCapacity=0.9791667, numApps=5, numContainers=42 usedCapacity=0.9791667 absoluteUsedCapacity=0.9791667 used=<memory:48128, vCores:42> cluster=<memory:49152, vCores:96>
2013-08-17 06:41:54,410 INFO org.apache.hadoop.yarn.server.resourcemanager.scheduler.capacity.ParentQueue: completedContainer queue=root usedCapacity=0.9791667 absoluteUsedCapacity=0.9791667 used=<memory:48128, vCores:42> cluster=<memory:49152, vCores:96>
2013-08-17 06:41:54,410 INFO org.apache.hadoop.yarn.server.resourcemanager.scheduler.capacity.CapacityScheduler: Application appattempt_1376720997863_0007_000001 released container container_1376720997863_0007_01_000009 on node: host: hadoop-512-4:45085 #containers=6 available=1024 used=7168 with event: FINISHED
2013-08-17 06:41:54,410 INFO org.apache.hadoop.yarn.server.resourcemanager.rmcontainer.RMContainerImpl: container_1376720997863_0006_01_000003 Container Transitioned from NEW to ALLOCATED
2013-08-17 06:41:54,410 INFO org.apache.hadoop.yarn.server.resourcemanager.RMAuditLogger: USER=ubuntu	OPERATION=AM Allocated Container	TARGET=SchedulerApp	RESULT=SUCCESS	APPID=application_1376720997863_0006	CONTAINERID=container_1376720997863_0006_01_000003
2013-08-17 06:41:54,411 INFO org.apache.hadoop.yarn.server.resourcemanager.scheduler.common.fica.FiCaSchedulerNode: Assigned container container_1376720997863_0006_01_000003 of capacity <memory:1024, vCores:1> on host hadoop-512-4:45085, which currently has 7 containers, <memory:8192, vCores:7> used and <memory:0, vCores:9> available
2013-08-17 06:41:54,411 INFO org.apache.hadoop.yarn.server.resourcemanager.scheduler.capacity.LeafQueue: assignedContainer application=application_1376720997863_0006 container=Container: [ContainerId: container_1376720997863_0006_01_000003, NodeId: hadoop-512-4:45085, NodeHttpAddress: hadoop-512-4:8042, Resource: <memory:1024, vCores:1>, Priority: 20, State: NEW, Token: null, Status: container_id {, app_attempt_id {, application_id {, id: 6, cluster_timestamp: 1376720997863, }, attemptId: 1, }, id: 3, }, state: C_NEW, ] containerId=container_1376720997863_0006_01_000003 queue=default: capacity=1.0, absoluteCapacity=1.0, usedResources=<memory:48128, vCores:42>usedCapacity=0.9791667, absoluteUsedCapacity=0.9791667, numApps=5, numContainers=42 usedCapacity=0.9791667 absoluteUsedCapacity=0.9791667 used=<memory:48128, vCores:42> cluster=<memory:49152, vCores:96>
2013-08-17 06:41:54,412 INFO org.apache.hadoop.yarn.server.resourcemanager.scheduler.capacity.ParentQueue: Re-sorting queues since queue: root.default stats: default: capacity=1.0, absoluteCapacity=1.0, usedResources=<memory:49152, vCores:43>usedCapacity=1.0, absoluteUsedCapacity=1.0, numApps=5, numContainers=43
2013-08-17 06:41:54,412 INFO org.apache.hadoop.yarn.server.resourcemanager.scheduler.capacity.ParentQueue: assignedContainer queue=root usedCapacity=1.0 absoluteUsedCapacity=1.0 used=<memory:49152, vCores:43> cluster=<memory:49152, vCores:96>
2013-08-17 06:41:54,965 INFO org.apache.hadoop.yarn.server.resourcemanager.rmcontainer.RMContainerImpl: container_1376720997863_0006_01_000003 Container Transitioned from ALLOCATED to ACQUIRED
2013-08-17 06:41:55,416 INFO org.apache.hadoop.yarn.server.resourcemanager.rmcontainer.RMContainerImpl: container_1376720997863_0006_01_000002 Container Transitioned from ACQUIRED to RUNNING
2013-08-17 06:41:55,416 INFO org.apache.hadoop.yarn.server.resourcemanager.rmcontainer.RMContainerImpl: container_1376720997863_0006_01_000003 Container Transitioned from ACQUIRED to RUNNING
2013-08-17 06:42:10,172 INFO org.apache.hadoop.yarn.server.resourcemanager.rmcontainer.RMContainerImpl: container_1376720997863_0007_01_000020 Container Transitioned from RUNNING to COMPLETED
2013-08-17 06:42:10,172 INFO org.apache.hadoop.yarn.server.resourcemanager.scheduler.common.fica.FiCaSchedulerApp: Completed container: container_1376720997863_0007_01_000020 in state: COMPLETED event:FINISHED
2013-08-17 06:42:10,172 INFO org.apache.hadoop.yarn.server.resourcemanager.RMAuditLogger: USER=ubuntu	OPERATION=AM Released Container	TARGET=SchedulerApp	RESULT=SUCCESS	APPID=application_1376720997863_0007	CONTAINERID=container_1376720997863_0007_01_000020
2013-08-17 06:42:10,172 INFO org.apache.hadoop.yarn.server.resourcemanager.scheduler.common.fica.FiCaSchedulerNode: Released container container_1376720997863_0007_01_000020 of capacity <memory:1024, vCores:1> on host hadoop-512-2:32923, which currently has 6 containers, <memory:7168, vCores:6> used and <memory:1024, vCores:10> available, release resources=true
2013-08-17 06:42:10,173 INFO org.apache.hadoop.yarn.server.resourcemanager.scheduler.capacity.LeafQueue: default used=<memory:48128, vCores:42> numContainers=42 user=ubuntu user-resources=<memory:48128, vCores:42>
2013-08-17 06:42:10,174 INFO org.apache.hadoop.yarn.server.resourcemanager.scheduler.capacity.LeafQueue: completedContainer container=Container: [ContainerId: container_1376720997863_0007_01_000020, NodeId: hadoop-512-2:32923, NodeHttpAddress: hadoop-512-2:8042, Resource: <memory:1024, vCores:1>, Priority: 20, State: NEW, Token: null, Status: container_id {, app_attempt_id {, application_id {, id: 7, cluster_timestamp: 1376720997863, }, attemptId: 1, }, id: 20, }, state: C_COMPLETE, diagnostics: "Container killed by the ApplicationMaster.\n", exit_status: 0, ] resource=<memory:1024, vCores:1> queue=default: capacity=1.0, absoluteCapacity=1.0, usedResources=<memory:48128, vCores:42>usedCapacity=0.9791667, absoluteUsedCapacity=0.9791667, numApps=5, numContainers=42 usedCapacity=0.9791667 absoluteUsedCapacity=0.9791667 used=<memory:48128, vCores:42> cluster=<memory:49152, vCores:96>
2013-08-17 06:42:10,174 INFO org.apache.hadoop.yarn.server.resourcemanager.scheduler.capacity.ParentQueue: completedContainer queue=root usedCapacity=0.9791667 absoluteUsedCapacity=0.9791667 used=<memory:48128, vCores:42> cluster=<memory:49152, vCores:96>
2013-08-17 06:42:10,174 INFO org.apache.hadoop.yarn.server.resourcemanager.scheduler.capacity.CapacityScheduler: Application appattempt_1376720997863_0007_000001 released container container_1376720997863_0007_01_000020 on node: host: hadoop-512-2:32923 #containers=6 available=1024 used=7168 with event: FINISHED
2013-08-17 06:42:10,175 INFO org.apache.hadoop.yarn.server.resourcemanager.rmcontainer.RMContainerImpl: container_1376720997863_0006_01_000004 Container Transitioned from NEW to ALLOCATED
2013-08-17 06:42:10,175 INFO org.apache.hadoop.yarn.server.resourcemanager.RMAuditLogger: USER=ubuntu	OPERATION=AM Allocated Container	TARGET=SchedulerApp	RESULT=SUCCESS	APPID=application_1376720997863_0006	CONTAINERID=container_1376720997863_0006_01_000004
2013-08-17 06:42:10,175 INFO org.apache.hadoop.yarn.server.resourcemanager.scheduler.common.fica.FiCaSchedulerNode: Assigned container container_1376720997863_0006_01_000004 of capacity <memory:1024, vCores:1> on host hadoop-512-2:32923, which currently has 7 containers, <memory:8192, vCores:7> used and <memory:0, vCores:9> available
2013-08-17 06:42:10,176 INFO org.apache.hadoop.yarn.server.resourcemanager.scheduler.capacity.LeafQueue: assignedContainer application=application_1376720997863_0006 container=Container: [ContainerId: container_1376720997863_0006_01_000004, NodeId: hadoop-512-2:32923, NodeHttpAddress: hadoop-512-2:8042, Resource: <memory:1024, vCores:1>, Priority: 20, State: NEW, Token: null, Status: container_id {, app_attempt_id {, application_id {, id: 6, cluster_timestamp: 1376720997863, }, attemptId: 1, }, id: 4, }, state: C_NEW, ] containerId=container_1376720997863_0006_01_000004 queue=default: capacity=1.0, absoluteCapacity=1.0, usedResources=<memory:48128, vCores:42>usedCapacity=0.9791667, absoluteUsedCapacity=0.9791667, numApps=5, numContainers=42 usedCapacity=0.9791667 absoluteUsedCapacity=0.9791667 used=<memory:48128, vCores:42> cluster=<memory:49152, vCores:96>
2013-08-17 06:42:10,176 INFO org.apache.hadoop.yarn.server.resourcemanager.scheduler.capacity.ParentQueue: Re-sorting queues since queue: root.default stats: default: capacity=1.0, absoluteCapacity=1.0, usedResources=<memory:49152, vCores:43>usedCapacity=1.0, absoluteUsedCapacity=1.0, numApps=5, numContainers=43
2013-08-17 06:42:10,176 INFO org.apache.hadoop.yarn.server.resourcemanager.scheduler.capacity.ParentQueue: assignedContainer queue=root usedCapacity=1.0 absoluteUsedCapacity=1.0 used=<memory:49152, vCores:43> cluster=<memory:49152, vCores:96>
2013-08-17 06:42:10,752 INFO org.apache.hadoop.yarn.server.resourcemanager.rmcontainer.RMContainerImpl: container_1376720997863_0007_01_000015 Container Transitioned from RUNNING to COMPLETED
2013-08-17 06:42:10,752 INFO org.apache.hadoop.yarn.server.resourcemanager.scheduler.common.fica.FiCaSchedulerApp: Completed container: container_1376720997863_0007_01_000015 in state: COMPLETED event:FINISHED
2013-08-17 06:42:10,752 INFO org.apache.hadoop.yarn.server.resourcemanager.RMAuditLogger: USER=ubuntu	OPERATION=AM Released Container	TARGET=SchedulerApp	RESULT=SUCCESS	APPID=application_1376720997863_0007	CONTAINERID=container_1376720997863_0007_01_000015
2013-08-17 06:42:10,753 INFO org.apache.hadoop.yarn.server.resourcemanager.scheduler.common.fica.FiCaSchedulerNode: Released container container_1376720997863_0007_01_000015 of capacity <memory:1024, vCores:1> on host hadoop-512-7:43914, which currently has 6 containers, <memory:7168, vCores:6> used and <memory:1024, vCores:10> available, release resources=true
2013-08-17 06:42:10,753 INFO org.apache.hadoop.yarn.server.resourcemanager.scheduler.capacity.LeafQueue: default used=<memory:48128, vCores:42> numContainers=42 user=ubuntu user-resources=<memory:48128, vCores:42>
2013-08-17 06:42:10,754 INFO org.apache.hadoop.yarn.server.resourcemanager.scheduler.capacity.LeafQueue: completedContainer container=Container: [ContainerId: container_1376720997863_0007_01_000015, NodeId: hadoop-512-7:43914, NodeHttpAddress: hadoop-512-7:8042, Resource: <memory:1024, vCores:1>, Priority: 20, State: NEW, Token: null, Status: container_id {, app_attempt_id {, application_id {, id: 7, cluster_timestamp: 1376720997863, }, attemptId: 1, }, id: 15, }, state: C_COMPLETE, diagnostics: "Container killed by the ApplicationMaster.\n\n", exit_status: 143, ] resource=<memory:1024, vCores:1> queue=default: capacity=1.0, absoluteCapacity=1.0, usedResources=<memory:48128, vCores:42>usedCapacity=0.9791667, absoluteUsedCapacity=0.9791667, numApps=5, numContainers=42 usedCapacity=0.9791667 absoluteUsedCapacity=0.9791667 used=<memory:48128, vCores:42> cluster=<memory:49152, vCores:96>
2013-08-17 06:42:10,754 INFO org.apache.hadoop.yarn.server.resourcemanager.scheduler.capacity.ParentQueue: completedContainer queue=root usedCapacity=0.9791667 absoluteUsedCapacity=0.9791667 used=<memory:48128, vCores:42> cluster=<memory:49152, vCores:96>
2013-08-17 06:42:10,754 INFO org.apache.hadoop.yarn.server.resourcemanager.scheduler.capacity.CapacityScheduler: Application appattempt_1376720997863_0007_000001 released container container_1376720997863_0007_01_000015 on node: host: hadoop-512-7:43914 #containers=6 available=1024 used=7168 with event: FINISHED
2013-08-17 06:42:10,755 INFO org.apache.hadoop.yarn.server.resourcemanager.rmcontainer.RMContainerImpl: container_1376720997863_0006_01_000005 Container Transitioned from NEW to ALLOCATED
2013-08-17 06:42:10,755 INFO org.apache.hadoop.yarn.server.resourcemanager.RMAuditLogger: USER=ubuntu	OPERATION=AM Allocated Container	TARGET=SchedulerApp	RESULT=SUCCESS	APPID=application_1376720997863_0006	CONTAINERID=container_1376720997863_0006_01_000005
2013-08-17 06:42:10,755 INFO org.apache.hadoop.yarn.server.resourcemanager.scheduler.common.fica.FiCaSchedulerNode: Assigned container container_1376720997863_0006_01_000005 of capacity <memory:1024, vCores:1> on host hadoop-512-7:43914, which currently has 7 containers, <memory:8192, vCores:7> used and <memory:0, vCores:9> available
2013-08-17 06:42:10,756 INFO org.apache.hadoop.yarn.server.resourcemanager.scheduler.capacity.LeafQueue: assignedContainer application=application_1376720997863_0006 container=Container: [ContainerId: container_1376720997863_0006_01_000005, NodeId: hadoop-512-7:43914, NodeHttpAddress: hadoop-512-7:8042, Resource: <memory:1024, vCores:1>, Priority: 20, State: NEW, Token: null, Status: container_id {, app_attempt_id {, application_id {, id: 6, cluster_timestamp: 1376720997863, }, attemptId: 1, }, id: 5, }, state: C_NEW, ] containerId=container_1376720997863_0006_01_000005 queue=default: capacity=1.0, absoluteCapacity=1.0, usedResources=<memory:48128, vCores:42>usedCapacity=0.9791667, absoluteUsedCapacity=0.9791667, numApps=5, numContainers=42 usedCapacity=0.9791667 absoluteUsedCapacity=0.9791667 used=<memory:48128, vCores:42> cluster=<memory:49152, vCores:96>
2013-08-17 06:42:10,756 INFO org.apache.hadoop.yarn.server.resourcemanager.scheduler.capacity.ParentQueue: Re-sorting queues since queue: root.default stats: default: capacity=1.0, absoluteCapacity=1.0, usedResources=<memory:49152, vCores:43>usedCapacity=1.0, absoluteUsedCapacity=1.0, numApps=5, numContainers=43
2013-08-17 06:42:10,756 INFO org.apache.hadoop.yarn.server.resourcemanager.scheduler.capacity.ParentQueue: assignedContainer queue=root usedCapacity=1.0 absoluteUsedCapacity=1.0 used=<memory:49152, vCores:43> cluster=<memory:49152, vCores:96>
2013-08-17 06:42:11,049 INFO org.apache.hadoop.yarn.server.resourcemanager.rmcontainer.RMContainerImpl: container_1376720997863_0006_01_000004 Container Transitioned from ALLOCATED to ACQUIRED
2013-08-17 06:42:11,050 INFO org.apache.hadoop.yarn.server.resourcemanager.rmcontainer.RMContainerImpl: container_1376720997863_0006_01_000005 Container Transitioned from ALLOCATED to ACQUIRED
2013-08-17 06:42:11,179 INFO org.apache.hadoop.yarn.server.resourcemanager.rmcontainer.RMContainerImpl: container_1376720997863_0006_01_000004 Container Transitioned from ACQUIRED to RUNNING
2013-08-17 06:42:11,910 INFO org.apache.hadoop.yarn.server.resourcemanager.rmcontainer.RMContainerImpl: container_1376720997863_0006_01_000005 Container Transitioned from ACQUIRED to RUNNING
2013-08-17 06:42:11,911 INFO org.apache.hadoop.yarn.server.resourcemanager.rmcontainer.RMContainerImpl: container_1376720997863_0007_01_000017 Container Transitioned from RUNNING to COMPLETED
2013-08-17 06:42:11,911 INFO org.apache.hadoop.yarn.server.resourcemanager.scheduler.common.fica.FiCaSchedulerApp: Completed container: container_1376720997863_0007_01_000017 in state: COMPLETED event:FINISHED
2013-08-17 06:42:11,911 INFO org.apache.hadoop.yarn.server.resourcemanager.RMAuditLogger: USER=ubuntu	OPERATION=AM Released Container	TARGET=SchedulerApp	RESULT=SUCCESS	APPID=application_1376720997863_0007	CONTAINERID=container_1376720997863_0007_01_000017
2013-08-17 06:42:11,911 INFO org.apache.hadoop.yarn.server.resourcemanager.scheduler.common.fica.FiCaSchedulerNode: Released container container_1376720997863_0007_01_000017 of capacity <memory:1024, vCores:1> on host hadoop-512-7:43914, which currently has 6 containers, <memory:7168, vCores:6> used and <memory:1024, vCores:10> available, release resources=true
2013-08-17 06:42:11,911 INFO org.apache.hadoop.yarn.server.resourcemanager.scheduler.capacity.LeafQueue: default used=<memory:48128, vCores:42> numContainers=42 user=ubuntu user-resources=<memory:48128, vCores:42>
2013-08-17 06:42:11,913 INFO org.apache.hadoop.yarn.server.resourcemanager.scheduler.capacity.LeafQueue: completedContainer container=Container: [ContainerId: container_1376720997863_0007_01_000017, NodeId: hadoop-512-7:43914, NodeHttpAddress: hadoop-512-7:8042, Resource: <memory:1024, vCores:1>, Priority: 20, State: NEW, Token: null, Status: container_id {, app_attempt_id {, application_id {, id: 7, cluster_timestamp: 1376720997863, }, attemptId: 1, }, id: 17, }, state: C_COMPLETE, diagnostics: "Container killed by the ApplicationMaster.\n", exit_status: 0, ] resource=<memory:1024, vCores:1> queue=default: capacity=1.0, absoluteCapacity=1.0, usedResources=<memory:48128, vCores:42>usedCapacity=0.9791667, absoluteUsedCapacity=0.9791667, numApps=5, numContainers=42 usedCapacity=0.9791667 absoluteUsedCapacity=0.9791667 used=<memory:48128, vCores:42> cluster=<memory:49152, vCores:96>
2013-08-17 06:42:11,913 INFO org.apache.hadoop.yarn.server.resourcemanager.scheduler.capacity.ParentQueue: completedContainer queue=root usedCapacity=0.9791667 absoluteUsedCapacity=0.9791667 used=<memory:48128, vCores:42> cluster=<memory:49152, vCores:96>
2013-08-17 06:42:11,913 INFO org.apache.hadoop.yarn.server.resourcemanager.scheduler.capacity.CapacityScheduler: Application appattempt_1376720997863_0007_000001 released container container_1376720997863_0007_01_000017 on node: host: hadoop-512-7:43914 #containers=6 available=1024 used=7168 with event: FINISHED
2013-08-17 06:42:11,913 INFO org.apache.hadoop.yarn.server.resourcemanager.rmcontainer.RMContainerImpl: container_1376720997863_0006_01_000006 Container Transitioned from NEW to ALLOCATED
2013-08-17 06:42:11,913 INFO org.apache.hadoop.yarn.server.resourcemanager.RMAuditLogger: USER=ubuntu	OPERATION=AM Allocated Container	TARGET=SchedulerApp	RESULT=SUCCESS	APPID=application_1376720997863_0006	CONTAINERID=container_1376720997863_0006_01_000006
2013-08-17 06:42:11,914 INFO org.apache.hadoop.yarn.server.resourcemanager.scheduler.common.fica.FiCaSchedulerNode: Assigned container container_1376720997863_0006_01_000006 of capacity <memory:1024, vCores:1> on host hadoop-512-7:43914, which currently has 7 containers, <memory:8192, vCores:7> used and <memory:0, vCores:9> available
2013-08-17 06:42:11,914 INFO org.apache.hadoop.yarn.server.resourcemanager.scheduler.capacity.LeafQueue: assignedContainer application=application_1376720997863_0006 container=Container: [ContainerId: container_1376720997863_0006_01_000006, NodeId: hadoop-512-7:43914, NodeHttpAddress: hadoop-512-7:8042, Resource: <memory:1024, vCores:1>, Priority: 20, State: NEW, Token: null, Status: container_id {, app_attempt_id {, application_id {, id: 6, cluster_timestamp: 1376720997863, }, attemptId: 1, }, id: 6, }, state: C_NEW, ] containerId=container_1376720997863_0006_01_000006 queue=default: capacity=1.0, absoluteCapacity=1.0, usedResources=<memory:48128, vCores:42>usedCapacity=0.9791667, absoluteUsedCapacity=0.9791667, numApps=5, numContainers=42 usedCapacity=0.9791667 absoluteUsedCapacity=0.9791667 used=<memory:48128, vCores:42> cluster=<memory:49152, vCores:96>
2013-08-17 06:42:11,915 INFO org.apache.hadoop.yarn.server.resourcemanager.scheduler.capacity.ParentQueue: Re-sorting queues since queue: root.default stats: default: capacity=1.0, absoluteCapacity=1.0, usedResources=<memory:49152, vCores:43>usedCapacity=1.0, absoluteUsedCapacity=1.0, numApps=5, numContainers=43
2013-08-17 06:42:11,915 INFO org.apache.hadoop.yarn.server.resourcemanager.scheduler.capacity.ParentQueue: assignedContainer queue=root usedCapacity=1.0 absoluteUsedCapacity=1.0 used=<memory:49152, vCores:43> cluster=<memory:49152, vCores:96>
2013-08-17 06:42:12,067 INFO org.apache.hadoop.yarn.server.resourcemanager.rmcontainer.RMContainerImpl: container_1376720997863_0006_01_000006 Container Transitioned from ALLOCATED to ACQUIRED
2013-08-17 06:42:13,756 INFO org.apache.hadoop.yarn.server.resourcemanager.rmcontainer.RMContainerImpl: container_1376720997863_0006_01_000006 Container Transitioned from ACQUIRED to RUNNING
2013-08-17 06:42:15,152 INFO org.apache.hadoop.yarn.server.resourcemanager.rmcontainer.RMContainerImpl: container_1376720997863_0007_01_000022 Container Transitioned from RUNNING to COMPLETED
2013-08-17 06:42:15,152 INFO org.apache.hadoop.yarn.server.resourcemanager.scheduler.common.fica.FiCaSchedulerApp: Completed container: container_1376720997863_0007_01_000022 in state: COMPLETED event:FINISHED
2013-08-17 06:42:15,152 INFO org.apache.hadoop.yarn.server.resourcemanager.RMAuditLogger: USER=ubuntu	OPERATION=AM Released Container	TARGET=SchedulerApp	RESULT=SUCCESS	APPID=application_1376720997863_0007	CONTAINERID=container_1376720997863_0007_01_000022
2013-08-17 06:42:15,152 INFO org.apache.hadoop.yarn.server.resourcemanager.scheduler.common.fica.FiCaSchedulerNode: Released container container_1376720997863_0007_01_000022 of capacity <memory:1024, vCores:1> on host hadoop-512-2:32923, which currently has 6 containers, <memory:7168, vCores:6> used and <memory:1024, vCores:10> available, release resources=true
2013-08-17 06:42:15,152 INFO org.apache.hadoop.yarn.server.resourcemanager.scheduler.capacity.LeafQueue: default used=<memory:48128, vCores:42> numContainers=42 user=ubuntu user-resources=<memory:48128, vCores:42>
2013-08-17 06:42:15,153 INFO org.apache.hadoop.yarn.server.resourcemanager.scheduler.capacity.LeafQueue: completedContainer container=Container: [ContainerId: container_1376720997863_0007_01_000022, NodeId: hadoop-512-2:32923, NodeHttpAddress: hadoop-512-2:8042, Resource: <memory:1024, vCores:1>, Priority: 20, State: NEW, Token: null, Status: container_id {, app_attempt_id {, application_id {, id: 7, cluster_timestamp: 1376720997863, }, attemptId: 1, }, id: 22, }, state: C_COMPLETE, diagnostics: "Container killed by the ApplicationMaster.\n\n", exit_status: 143, ] resource=<memory:1024, vCores:1> queue=default: capacity=1.0, absoluteCapacity=1.0, usedResources=<memory:48128, vCores:42>usedCapacity=0.9791667, absoluteUsedCapacity=0.9791667, numApps=5, numContainers=42 usedCapacity=0.9791667 absoluteUsedCapacity=0.9791667 used=<memory:48128, vCores:42> cluster=<memory:49152, vCores:96>
2013-08-17 06:42:15,154 INFO org.apache.hadoop.yarn.server.resourcemanager.scheduler.capacity.ParentQueue: completedContainer queue=root usedCapacity=0.9791667 absoluteUsedCapacity=0.9791667 used=<memory:48128, vCores:42> cluster=<memory:49152, vCores:96>
2013-08-17 06:42:15,154 INFO org.apache.hadoop.yarn.server.resourcemanager.scheduler.capacity.CapacityScheduler: Application appattempt_1376720997863_0007_000001 released container container_1376720997863_0007_01_000022 on node: host: hadoop-512-2:32923 #containers=6 available=1024 used=7168 with event: FINISHED
2013-08-17 06:42:15,154 INFO org.apache.hadoop.yarn.server.resourcemanager.rmcontainer.RMContainerImpl: container_1376720997863_0006_01_000007 Container Transitioned from NEW to ALLOCATED
2013-08-17 06:42:15,154 INFO org.apache.hadoop.yarn.server.resourcemanager.RMAuditLogger: USER=ubuntu	OPERATION=AM Allocated Container	TARGET=SchedulerApp	RESULT=SUCCESS	APPID=application_1376720997863_0006	CONTAINERID=container_1376720997863_0006_01_000007
2013-08-17 06:42:15,155 INFO org.apache.hadoop.yarn.server.resourcemanager.scheduler.common.fica.FiCaSchedulerNode: Assigned container container_1376720997863_0006_01_000007 of capacity <memory:1024, vCores:1> on host hadoop-512-2:32923, which currently has 7 containers, <memory:8192, vCores:7> used and <memory:0, vCores:9> available
2013-08-17 06:42:15,155 INFO org.apache.hadoop.yarn.server.resourcemanager.scheduler.capacity.LeafQueue: assignedContainer application=application_1376720997863_0006 container=Container: [ContainerId: container_1376720997863_0006_01_000007, NodeId: hadoop-512-2:32923, NodeHttpAddress: hadoop-512-2:8042, Resource: <memory:1024, vCores:1>, Priority: 20, State: NEW, Token: null, Status: container_id {, app_attempt_id {, application_id {, id: 6, cluster_timestamp: 1376720997863, }, attemptId: 1, }, id: 7, }, state: C_NEW, ] containerId=container_1376720997863_0006_01_000007 queue=default: capacity=1.0, absoluteCapacity=1.0, usedResources=<memory:48128, vCores:42>usedCapacity=0.9791667, absoluteUsedCapacity=0.9791667, numApps=5, numContainers=42 usedCapacity=0.9791667 absoluteUsedCapacity=0.9791667 used=<memory:48128, vCores:42> cluster=<memory:49152, vCores:96>
2013-08-17 06:42:15,156 INFO org.apache.hadoop.yarn.server.resourcemanager.scheduler.capacity.ParentQueue: Re-sorting queues since queue: root.default stats: default: capacity=1.0, absoluteCapacity=1.0, usedResources=<memory:49152, vCores:43>usedCapacity=1.0, absoluteUsedCapacity=1.0, numApps=5, numContainers=43
2013-08-17 06:42:15,156 INFO org.apache.hadoop.yarn.server.resourcemanager.scheduler.capacity.ParentQueue: assignedContainer queue=root usedCapacity=1.0 absoluteUsedCapacity=1.0 used=<memory:49152, vCores:43> cluster=<memory:49152, vCores:96>
2013-08-17 06:42:16,087 INFO org.apache.hadoop.yarn.server.resourcemanager.rmcontainer.RMContainerImpl: container_1376720997863_0006_01_000007 Container Transitioned from ALLOCATED to ACQUIRED
2013-08-17 06:42:16,171 INFO org.apache.hadoop.yarn.server.resourcemanager.rmcontainer.RMContainerImpl: container_1376720997863_0006_01_000007 Container Transitioned from ACQUIRED to RUNNING
2013-08-17 06:42:16,602 INFO org.apache.hadoop.yarn.server.resourcemanager.rmcontainer.RMContainerImpl: container_1376720997863_0007_01_000004 Container Transitioned from RUNNING to COMPLETED
2013-08-17 06:42:16,602 INFO org.apache.hadoop.yarn.server.resourcemanager.scheduler.common.fica.FiCaSchedulerApp: Completed container: container_1376720997863_0007_01_000004 in state: COMPLETED event:FINISHED
2013-08-17 06:42:16,602 INFO org.apache.hadoop.yarn.server.resourcemanager.RMAuditLogger: USER=ubuntu	OPERATION=AM Released Container	TARGET=SchedulerApp	RESULT=SUCCESS	APPID=application_1376720997863_0007	CONTAINERID=container_1376720997863_0007_01_000004
2013-08-17 06:42:16,602 INFO org.apache.hadoop.yarn.server.resourcemanager.scheduler.common.fica.FiCaSchedulerNode: Released container container_1376720997863_0007_01_000004 of capacity <memory:1024, vCores:1> on host hadoop-512-5:45082, which currently has 6 containers, <memory:7168, vCores:6> used and <memory:1024, vCores:10> available, release resources=true
2013-08-17 06:42:16,602 INFO org.apache.hadoop.yarn.server.resourcemanager.scheduler.capacity.LeafQueue: default used=<memory:48128, vCores:42> numContainers=42 user=ubuntu user-resources=<memory:48128, vCores:42>
2013-08-17 06:42:16,603 INFO org.apache.hadoop.yarn.server.resourcemanager.scheduler.capacity.LeafQueue: completedContainer container=Container: [ContainerId: container_1376720997863_0007_01_000004, NodeId: hadoop-512-5:45082, NodeHttpAddress: hadoop-512-5:8042, Resource: <memory:1024, vCores:1>, Priority: 20, State: NEW, Token: null, Status: container_id {, app_attempt_id {, application_id {, id: 7, cluster_timestamp: 1376720997863, }, attemptId: 1, }, id: 4, }, state: C_COMPLETE, diagnostics: "Container killed by the ApplicationMaster.\n\n", exit_status: 143, ] resource=<memory:1024, vCores:1> queue=default: capacity=1.0, absoluteCapacity=1.0, usedResources=<memory:48128, vCores:42>usedCapacity=0.9791667, absoluteUsedCapacity=0.9791667, numApps=5, numContainers=42 usedCapacity=0.9791667 absoluteUsedCapacity=0.9791667 used=<memory:48128, vCores:42> cluster=<memory:49152, vCores:96>
2013-08-17 06:42:16,604 INFO org.apache.hadoop.yarn.server.resourcemanager.scheduler.capacity.ParentQueue: completedContainer queue=root usedCapacity=0.9791667 absoluteUsedCapacity=0.9791667 used=<memory:48128, vCores:42> cluster=<memory:49152, vCores:96>
2013-08-17 06:42:16,604 INFO org.apache.hadoop.yarn.server.resourcemanager.scheduler.capacity.CapacityScheduler: Application appattempt_1376720997863_0007_000001 released container container_1376720997863_0007_01_000004 on node: host: hadoop-512-5:45082 #containers=6 available=1024 used=7168 with event: FINISHED
2013-08-17 06:42:16,604 INFO org.apache.hadoop.yarn.server.resourcemanager.rmcontainer.RMContainerImpl: container_1376720997863_0006_01_000008 Container Transitioned from NEW to ALLOCATED
2013-08-17 06:42:16,605 INFO org.apache.hadoop.yarn.server.resourcemanager.RMAuditLogger: USER=ubuntu	OPERATION=AM Allocated Container	TARGET=SchedulerApp	RESULT=SUCCESS	APPID=application_1376720997863_0006	CONTAINERID=container_1376720997863_0006_01_000008
2013-08-17 06:42:16,605 INFO org.apache.hadoop.yarn.server.resourcemanager.scheduler.common.fica.FiCaSchedulerNode: Assigned container container_1376720997863_0006_01_000008 of capacity <memory:1024, vCores:1> on host hadoop-512-5:45082, which currently has 7 containers, <memory:8192, vCores:7> used and <memory:0, vCores:9> available
2013-08-17 06:42:16,605 INFO org.apache.hadoop.yarn.server.resourcemanager.scheduler.capacity.LeafQueue: assignedContainer application=application_1376720997863_0006 container=Container: [ContainerId: container_1376720997863_0006_01_000008, NodeId: hadoop-512-5:45082, NodeHttpAddress: hadoop-512-5:8042, Resource: <memory:1024, vCores:1>, Priority: 20, State: NEW, Token: null, Status: container_id {, app_attempt_id {, application_id {, id: 6, cluster_timestamp: 1376720997863, }, attemptId: 1, }, id: 8, }, state: C_NEW, ] containerId=container_1376720997863_0006_01_000008 queue=default: capacity=1.0, absoluteCapacity=1.0, usedResources=<memory:48128, vCores:42>usedCapacity=0.9791667, absoluteUsedCapacity=0.9791667, numApps=5, numContainers=42 usedCapacity=0.9791667 absoluteUsedCapacity=0.9791667 used=<memory:48128, vCores:42> cluster=<memory:49152, vCores:96>
2013-08-17 06:42:16,606 INFO org.apache.hadoop.yarn.server.resourcemanager.scheduler.capacity.ParentQueue: Re-sorting queues since queue: root.default stats: default: capacity=1.0, absoluteCapacity=1.0, usedResources=<memory:49152, vCores:43>usedCapacity=1.0, absoluteUsedCapacity=1.0, numApps=5, numContainers=43
2013-08-17 06:42:16,606 INFO org.apache.hadoop.yarn.server.resourcemanager.scheduler.capacity.ParentQueue: assignedContainer queue=root usedCapacity=1.0 absoluteUsedCapacity=1.0 used=<memory:49152, vCores:43> cluster=<memory:49152, vCores:96>
2013-08-17 06:42:17,095 INFO org.apache.hadoop.yarn.server.resourcemanager.rmcontainer.RMContainerImpl: container_1376720997863_0006_01_000008 Container Transitioned from ALLOCATED to ACQUIRED
2013-08-17 06:42:17,605 INFO org.apache.hadoop.yarn.server.resourcemanager.rmcontainer.RMContainerImpl: container_1376720997863_0007_01_000014 Container Transitioned from RUNNING to COMPLETED
2013-08-17 06:42:17,605 INFO org.apache.hadoop.yarn.server.resourcemanager.scheduler.common.fica.FiCaSchedulerApp: Completed container: container_1376720997863_0007_01_000014 in state: COMPLETED event:FINISHED
2013-08-17 06:42:17,606 INFO org.apache.hadoop.yarn.server.resourcemanager.RMAuditLogger: USER=ubuntu	OPERATION=AM Released Container	TARGET=SchedulerApp	RESULT=SUCCESS	APPID=application_1376720997863_0007	CONTAINERID=container_1376720997863_0007_01_000014
2013-08-17 06:42:17,606 INFO org.apache.hadoop.yarn.server.resourcemanager.scheduler.common.fica.FiCaSchedulerNode: Released container container_1376720997863_0007_01_000014 of capacity <memory:1024, vCores:1> on host hadoop-512-7:43914, which currently has 6 containers, <memory:7168, vCores:6> used and <memory:1024, vCores:10> available, release resources=true
2013-08-17 06:42:17,606 INFO org.apache.hadoop.yarn.server.resourcemanager.scheduler.capacity.LeafQueue: default used=<memory:48128, vCores:42> numContainers=42 user=ubuntu user-resources=<memory:48128, vCores:42>
2013-08-17 06:42:17,607 INFO org.apache.hadoop.yarn.server.resourcemanager.scheduler.capacity.LeafQueue: completedContainer container=Container: [ContainerId: container_1376720997863_0007_01_000014, NodeId: hadoop-512-7:43914, NodeHttpAddress: hadoop-512-7:8042, Resource: <memory:1024, vCores:1>, Priority: 20, State: NEW, Token: null, Status: container_id {, app_attempt_id {, application_id {, id: 7, cluster_timestamp: 1376720997863, }, attemptId: 1, }, id: 14, }, state: C_COMPLETE, diagnostics: "Container killed by the ApplicationMaster.\n\n", exit_status: 143, ] resource=<memory:1024, vCores:1> queue=default: capacity=1.0, absoluteCapacity=1.0, usedResources=<memory:48128, vCores:42>usedCapacity=0.9791667, absoluteUsedCapacity=0.9791667, numApps=5, numContainers=42 usedCapacity=0.9791667 absoluteUsedCapacity=0.9791667 used=<memory:48128, vCores:42> cluster=<memory:49152, vCores:96>
2013-08-17 06:42:17,607 INFO org.apache.hadoop.yarn.server.resourcemanager.scheduler.capacity.ParentQueue: completedContainer queue=root usedCapacity=0.9791667 absoluteUsedCapacity=0.9791667 used=<memory:48128, vCores:42> cluster=<memory:49152, vCores:96>
2013-08-17 06:42:17,607 INFO org.apache.hadoop.yarn.server.resourcemanager.scheduler.capacity.CapacityScheduler: Application appattempt_1376720997863_0007_000001 released container container_1376720997863_0007_01_000014 on node: host: hadoop-512-7:43914 #containers=6 available=1024 used=7168 with event: FINISHED
2013-08-17 06:42:17,608 INFO org.apache.hadoop.yarn.server.resourcemanager.rmcontainer.RMContainerImpl: container_1376720997863_0006_01_000009 Container Transitioned from NEW to ALLOCATED
2013-08-17 06:42:17,608 INFO org.apache.hadoop.yarn.server.resourcemanager.RMAuditLogger: USER=ubuntu	OPERATION=AM Allocated Container	TARGET=SchedulerApp	RESULT=SUCCESS	APPID=application_1376720997863_0006	CONTAINERID=container_1376720997863_0006_01_000009
2013-08-17 06:42:17,608 INFO org.apache.hadoop.yarn.server.resourcemanager.scheduler.common.fica.FiCaSchedulerNode: Assigned container container_1376720997863_0006_01_000009 of capacity <memory:1024, vCores:1> on host hadoop-512-7:43914, which currently has 7 containers, <memory:8192, vCores:7> used and <memory:0, vCores:9> available
2013-08-17 06:42:17,609 INFO org.apache.hadoop.yarn.server.resourcemanager.scheduler.capacity.LeafQueue: assignedContainer application=application_1376720997863_0006 container=Container: [ContainerId: container_1376720997863_0006_01_000009, NodeId: hadoop-512-7:43914, NodeHttpAddress: hadoop-512-7:8042, Resource: <memory:1024, vCores:1>, Priority: 20, State: NEW, Token: null, Status: container_id {, app_attempt_id {, application_id {, id: 6, cluster_timestamp: 1376720997863, }, attemptId: 1, }, id: 9, }, state: C_NEW, ] containerId=container_1376720997863_0006_01_000009 queue=default: capacity=1.0, absoluteCapacity=1.0, usedResources=<memory:48128, vCores:42>usedCapacity=0.9791667, absoluteUsedCapacity=0.9791667, numApps=5, numContainers=42 usedCapacity=0.9791667 absoluteUsedCapacity=0.9791667 used=<memory:48128, vCores:42> cluster=<memory:49152, vCores:96>
2013-08-17 06:42:17,609 INFO org.apache.hadoop.yarn.server.resourcemanager.scheduler.capacity.ParentQueue: Re-sorting queues since queue: root.default stats: default: capacity=1.0, absoluteCapacity=1.0, usedResources=<memory:49152, vCores:43>usedCapacity=1.0, absoluteUsedCapacity=1.0, numApps=5, numContainers=43
2013-08-17 06:42:17,609 INFO org.apache.hadoop.yarn.server.resourcemanager.scheduler.capacity.ParentQueue: assignedContainer queue=root usedCapacity=1.0 absoluteUsedCapacity=1.0 used=<memory:49152, vCores:43> cluster=<memory:49152, vCores:96>
2013-08-17 06:42:17,612 INFO org.apache.hadoop.yarn.server.resourcemanager.rmcontainer.RMContainerImpl: container_1376720997863_0006_01_000008 Container Transitioned from ACQUIRED to RUNNING
2013-08-17 06:42:18,196 INFO org.apache.hadoop.yarn.server.resourcemanager.rmcontainer.RMContainerImpl: container_1376720997863_0006_01_000009 Container Transitioned from ALLOCATED to ACQUIRED
2013-08-17 06:42:18,612 INFO org.apache.hadoop.yarn.server.resourcemanager.rmcontainer.RMContainerImpl: container_1376720997863_0006_01_000009 Container Transitioned from ACQUIRED to RUNNING
2013-08-17 06:42:20,823 INFO org.apache.hadoop.yarn.server.resourcemanager.rmcontainer.RMContainerImpl: container_1376720997863_0007_01_000028 Container Transitioned from RUNNING to COMPLETED
2013-08-17 06:42:20,823 INFO org.apache.hadoop.yarn.server.resourcemanager.scheduler.common.fica.FiCaSchedulerApp: Completed container: container_1376720997863_0007_01_000028 in state: COMPLETED event:FINISHED
2013-08-17 06:42:20,824 INFO org.apache.hadoop.yarn.server.resourcemanager.RMAuditLogger: USER=ubuntu	OPERATION=AM Released Container	TARGET=SchedulerApp	RESULT=SUCCESS	APPID=application_1376720997863_0007	CONTAINERID=container_1376720997863_0007_01_000028
2013-08-17 06:42:20,824 INFO org.apache.hadoop.yarn.server.resourcemanager.scheduler.common.fica.FiCaSchedulerNode: Released container container_1376720997863_0007_01_000028 of capacity <memory:1024, vCores:1> on host hadoop-512-6:48301, which currently has 7 containers, <memory:7168, vCores:7> used and <memory:1024, vCores:9> available, release resources=true
2013-08-17 06:42:20,824 INFO org.apache.hadoop.yarn.server.resourcemanager.scheduler.capacity.LeafQueue: default used=<memory:48128, vCores:42> numContainers=42 user=ubuntu user-resources=<memory:48128, vCores:42>
2013-08-17 06:42:20,825 INFO org.apache.hadoop.yarn.server.resourcemanager.scheduler.capacity.LeafQueue: completedContainer container=Container: [ContainerId: container_1376720997863_0007_01_000028, NodeId: hadoop-512-6:48301, NodeHttpAddress: hadoop-512-6:8042, Resource: <memory:1024, vCores:1>, Priority: 20, State: NEW, Token: null, Status: container_id {, app_attempt_id {, application_id {, id: 7, cluster_timestamp: 1376720997863, }, attemptId: 1, }, id: 28, }, state: C_COMPLETE, diagnostics: "Container killed by the ApplicationMaster.\n\n", exit_status: 143, ] resource=<memory:1024, vCores:1> queue=default: capacity=1.0, absoluteCapacity=1.0, usedResources=<memory:48128, vCores:42>usedCapacity=0.9791667, absoluteUsedCapacity=0.9791667, numApps=5, numContainers=42 usedCapacity=0.9791667 absoluteUsedCapacity=0.9791667 used=<memory:48128, vCores:42> cluster=<memory:49152, vCores:96>
2013-08-17 06:42:20,825 INFO org.apache.hadoop.yarn.server.resourcemanager.scheduler.capacity.ParentQueue: completedContainer queue=root usedCapacity=0.9791667 absoluteUsedCapacity=0.9791667 used=<memory:48128, vCores:42> cluster=<memory:49152, vCores:96>
2013-08-17 06:42:20,825 INFO org.apache.hadoop.yarn.server.resourcemanager.scheduler.capacity.CapacityScheduler: Application appattempt_1376720997863_0007_000001 released container container_1376720997863_0007_01_000028 on node: host: hadoop-512-6:48301 #containers=7 available=1024 used=7168 with event: FINISHED
2013-08-17 06:42:20,826 INFO org.apache.hadoop.yarn.server.resourcemanager.rmcontainer.RMContainerImpl: container_1376720997863_0006_01_000010 Container Transitioned from NEW to ALLOCATED
2013-08-17 06:42:20,826 INFO org.apache.hadoop.yarn.server.resourcemanager.RMAuditLogger: USER=ubuntu	OPERATION=AM Allocated Container	TARGET=SchedulerApp	RESULT=SUCCESS	APPID=application_1376720997863_0006	CONTAINERID=container_1376720997863_0006_01_000010
2013-08-17 06:42:20,826 INFO org.apache.hadoop.yarn.server.resourcemanager.scheduler.common.fica.FiCaSchedulerNode: Assigned container container_1376720997863_0006_01_000010 of capacity <memory:1024, vCores:1> on host hadoop-512-6:48301, which currently has 8 containers, <memory:8192, vCores:8> used and <memory:0, vCores:8> available
2013-08-17 06:42:20,827 INFO org.apache.hadoop.yarn.server.resourcemanager.scheduler.capacity.LeafQueue: assignedContainer application=application_1376720997863_0006 container=Container: [ContainerId: container_1376720997863_0006_01_000010, NodeId: hadoop-512-6:48301, NodeHttpAddress: hadoop-512-6:8042, Resource: <memory:1024, vCores:1>, Priority: 20, State: NEW, Token: null, Status: container_id {, app_attempt_id {, application_id {, id: 6, cluster_timestamp: 1376720997863, }, attemptId: 1, }, id: 10, }, state: C_NEW, ] containerId=container_1376720997863_0006_01_000010 queue=default: capacity=1.0, absoluteCapacity=1.0, usedResources=<memory:48128, vCores:42>usedCapacity=0.9791667, absoluteUsedCapacity=0.9791667, numApps=5, numContainers=42 usedCapacity=0.9791667 absoluteUsedCapacity=0.9791667 used=<memory:48128, vCores:42> cluster=<memory:49152, vCores:96>
2013-08-17 06:42:20,827 INFO org.apache.hadoop.yarn.server.resourcemanager.scheduler.capacity.ParentQueue: Re-sorting queues since queue: root.default stats: default: capacity=1.0, absoluteCapacity=1.0, usedResources=<memory:49152, vCores:43>usedCapacity=1.0, absoluteUsedCapacity=1.0, numApps=5, numContainers=43
2013-08-17 06:42:20,827 INFO org.apache.hadoop.yarn.server.resourcemanager.scheduler.capacity.ParentQueue: assignedContainer queue=root usedCapacity=1.0 absoluteUsedCapacity=1.0 used=<memory:49152, vCores:43> cluster=<memory:49152, vCores:96>
2013-08-17 06:42:21,083 INFO org.apache.hadoop.yarn.server.resourcemanager.rmcontainer.RMContainerImpl: container_1376720997863_0007_01_000033 Container Transitioned from RUNNING to COMPLETED
2013-08-17 06:42:21,083 INFO org.apache.hadoop.yarn.server.resourcemanager.scheduler.common.fica.FiCaSchedulerApp: Completed container: container_1376720997863_0007_01_000033 in state: COMPLETED event:FINISHED
2013-08-17 06:42:21,083 INFO org.apache.hadoop.yarn.server.resourcemanager.RMAuditLogger: USER=ubuntu	OPERATION=AM Released Container	TARGET=SchedulerApp	RESULT=SUCCESS	APPID=application_1376720997863_0007	CONTAINERID=container_1376720997863_0007_01_000033
2013-08-17 06:42:21,083 INFO org.apache.hadoop.yarn.server.resourcemanager.scheduler.common.fica.FiCaSchedulerNode: Released container container_1376720997863_0007_01_000033 of capacity <memory:1024, vCores:1> on host hadoop-512-6:48301, which currently has 7 containers, <memory:7168, vCores:7> used and <memory:1024, vCores:9> available, release resources=true
2013-08-17 06:42:21,083 INFO org.apache.hadoop.yarn.server.resourcemanager.scheduler.capacity.LeafQueue: default used=<memory:48128, vCores:42> numContainers=42 user=ubuntu user-resources=<memory:48128, vCores:42>
2013-08-17 06:42:21,084 INFO org.apache.hadoop.yarn.server.resourcemanager.scheduler.capacity.LeafQueue: completedContainer container=Container: [ContainerId: container_1376720997863_0007_01_000033, NodeId: hadoop-512-6:48301, NodeHttpAddress: hadoop-512-6:8042, Resource: <memory:1024, vCores:1>, Priority: 20, State: NEW, Token: null, Status: container_id {, app_attempt_id {, application_id {, id: 7, cluster_timestamp: 1376720997863, }, attemptId: 1, }, id: 33, }, state: C_COMPLETE, diagnostics: "Container killed by the ApplicationMaster.\n\n", exit_status: 143, ] resource=<memory:1024, vCores:1> queue=default: capacity=1.0, absoluteCapacity=1.0, usedResources=<memory:48128, vCores:42>usedCapacity=0.9791667, absoluteUsedCapacity=0.9791667, numApps=5, numContainers=42 usedCapacity=0.9791667 absoluteUsedCapacity=0.9791667 used=<memory:48128, vCores:42> cluster=<memory:49152, vCores:96>
2013-08-17 06:42:21,084 INFO org.apache.hadoop.yarn.server.resourcemanager.scheduler.capacity.ParentQueue: completedContainer queue=root usedCapacity=0.9791667 absoluteUsedCapacity=0.9791667 used=<memory:48128, vCores:42> cluster=<memory:49152, vCores:96>
2013-08-17 06:42:21,084 INFO org.apache.hadoop.yarn.server.resourcemanager.scheduler.capacity.CapacityScheduler: Application appattempt_1376720997863_0007_000001 released container container_1376720997863_0007_01_000033 on node: host: hadoop-512-6:48301 #containers=7 available=1024 used=7168 with event: FINISHED
2013-08-17 06:42:21,085 INFO org.apache.hadoop.yarn.server.resourcemanager.rmcontainer.RMContainerImpl: container_1376720997863_0006_01_000011 Container Transitioned from NEW to ALLOCATED
2013-08-17 06:42:21,085 INFO org.apache.hadoop.yarn.server.resourcemanager.RMAuditLogger: USER=ubuntu	OPERATION=AM Allocated Container	TARGET=SchedulerApp	RESULT=SUCCESS	APPID=application_1376720997863_0006	CONTAINERID=container_1376720997863_0006_01_000011
2013-08-17 06:42:21,085 INFO org.apache.hadoop.yarn.server.resourcemanager.scheduler.common.fica.FiCaSchedulerNode: Assigned container container_1376720997863_0006_01_000011 of capacity <memory:1024, vCores:1> on host hadoop-512-6:48301, which currently has 8 containers, <memory:8192, vCores:8> used and <memory:0, vCores:8> available
2013-08-17 06:42:21,086 INFO org.apache.hadoop.yarn.server.resourcemanager.scheduler.capacity.LeafQueue: assignedContainer application=application_1376720997863_0006 container=Container: [ContainerId: container_1376720997863_0006_01_000011, NodeId: hadoop-512-6:48301, NodeHttpAddress: hadoop-512-6:8042, Resource: <memory:1024, vCores:1>, Priority: 20, State: NEW, Token: null, Status: container_id {, app_attempt_id {, application_id {, id: 6, cluster_timestamp: 1376720997863, }, attemptId: 1, }, id: 11, }, state: C_NEW, ] containerId=container_1376720997863_0006_01_000011 queue=default: capacity=1.0, absoluteCapacity=1.0, usedResources=<memory:48128, vCores:42>usedCapacity=0.9791667, absoluteUsedCapacity=0.9791667, numApps=5, numContainers=42 usedCapacity=0.9791667 absoluteUsedCapacity=0.9791667 used=<memory:48128, vCores:42> cluster=<memory:49152, vCores:96>
2013-08-17 06:42:21,086 INFO org.apache.hadoop.yarn.server.resourcemanager.scheduler.capacity.ParentQueue: Re-sorting queues since queue: root.default stats: default: capacity=1.0, absoluteCapacity=1.0, usedResources=<memory:49152, vCores:43>usedCapacity=1.0, absoluteUsedCapacity=1.0, numApps=5, numContainers=43
2013-08-17 06:42:21,087 INFO org.apache.hadoop.yarn.server.resourcemanager.scheduler.capacity.ParentQueue: assignedContainer queue=root usedCapacity=1.0 absoluteUsedCapacity=1.0 used=<memory:49152, vCores:43> cluster=<memory:49152, vCores:96>
2013-08-17 06:42:21,147 INFO org.apache.hadoop.yarn.server.resourcemanager.rmcontainer.RMContainerImpl: container_1376720997863_0007_01_000036 Container Transitioned from RUNNING to COMPLETED
2013-08-17 06:42:21,147 INFO org.apache.hadoop.yarn.server.resourcemanager.scheduler.common.fica.FiCaSchedulerApp: Completed container: container_1376720997863_0007_01_000036 in state: COMPLETED event:FINISHED
2013-08-17 06:42:21,147 INFO org.apache.hadoop.yarn.server.resourcemanager.RMAuditLogger: USER=ubuntu	OPERATION=AM Released Container	TARGET=SchedulerApp	RESULT=SUCCESS	APPID=application_1376720997863_0007	CONTAINERID=container_1376720997863_0007_01_000036
2013-08-17 06:42:21,147 INFO org.apache.hadoop.yarn.server.resourcemanager.scheduler.common.fica.FiCaSchedulerNode: Released container container_1376720997863_0007_01_000036 of capacity <memory:1024, vCores:1> on host hadoop-512-3:56071, which currently has 6 containers, <memory:7168, vCores:6> used and <memory:1024, vCores:10> available, release resources=true
2013-08-17 06:42:21,147 INFO org.apache.hadoop.yarn.server.resourcemanager.scheduler.capacity.LeafQueue: default used=<memory:48128, vCores:42> numContainers=42 user=ubuntu user-resources=<memory:48128, vCores:42>
2013-08-17 06:42:21,148 INFO org.apache.hadoop.yarn.server.resourcemanager.scheduler.capacity.LeafQueue: completedContainer container=Container: [ContainerId: container_1376720997863_0007_01_000036, NodeId: hadoop-512-3:56071, NodeHttpAddress: hadoop-512-3:8042, Resource: <memory:1024, vCores:1>, Priority: 20, State: NEW, Token: null, Status: container_id {, app_attempt_id {, application_id {, id: 7, cluster_timestamp: 1376720997863, }, attemptId: 1, }, id: 36, }, state: C_COMPLETE, diagnostics: "Container killed by the ApplicationMaster.\n", exit_status: 0, ] resource=<memory:1024, vCores:1> queue=default: capacity=1.0, absoluteCapacity=1.0, usedResources=<memory:48128, vCores:42>usedCapacity=0.9791667, absoluteUsedCapacity=0.9791667, numApps=5, numContainers=42 usedCapacity=0.9791667 absoluteUsedCapacity=0.9791667 used=<memory:48128, vCores:42> cluster=<memory:49152, vCores:96>
2013-08-17 06:42:21,148 INFO org.apache.hadoop.yarn.server.resourcemanager.scheduler.capacity.ParentQueue: completedContainer queue=root usedCapacity=0.9791667 absoluteUsedCapacity=0.9791667 used=<memory:48128, vCores:42> cluster=<memory:49152, vCores:96>
2013-08-17 06:42:21,149 INFO org.apache.hadoop.yarn.server.resourcemanager.scheduler.capacity.CapacityScheduler: Application appattempt_1376720997863_0007_000001 released container container_1376720997863_0007_01_000036 on node: host: hadoop-512-3:56071 #containers=6 available=1024 used=7168 with event: FINISHED
2013-08-17 06:42:21,149 INFO org.apache.hadoop.yarn.server.resourcemanager.rmcontainer.RMContainerImpl: container_1376720997863_0006_01_000012 Container Transitioned from NEW to ALLOCATED
2013-08-17 06:42:21,149 INFO org.apache.hadoop.yarn.server.resourcemanager.RMAuditLogger: USER=ubuntu	OPERATION=AM Allocated Container	TARGET=SchedulerApp	RESULT=SUCCESS	APPID=application_1376720997863_0006	CONTAINERID=container_1376720997863_0006_01_000012
2013-08-17 06:42:21,149 INFO org.apache.hadoop.yarn.server.resourcemanager.scheduler.common.fica.FiCaSchedulerNode: Assigned container container_1376720997863_0006_01_000012 of capacity <memory:1024, vCores:1> on host hadoop-512-3:56071, which currently has 7 containers, <memory:8192, vCores:7> used and <memory:0, vCores:9> available
2013-08-17 06:42:21,150 INFO org.apache.hadoop.yarn.server.resourcemanager.scheduler.capacity.LeafQueue: assignedContainer application=application_1376720997863_0006 container=Container: [ContainerId: container_1376720997863_0006_01_000012, NodeId: hadoop-512-3:56071, NodeHttpAddress: hadoop-512-3:8042, Resource: <memory:1024, vCores:1>, Priority: 20, State: NEW, Token: null, Status: container_id {, app_attempt_id {, application_id {, id: 6, cluster_timestamp: 1376720997863, }, attemptId: 1, }, id: 12, }, state: C_NEW, ] containerId=container_1376720997863_0006_01_000012 queue=default: capacity=1.0, absoluteCapacity=1.0, usedResources=<memory:48128, vCores:42>usedCapacity=0.9791667, absoluteUsedCapacity=0.9791667, numApps=5, numContainers=42 usedCapacity=0.9791667 absoluteUsedCapacity=0.9791667 used=<memory:48128, vCores:42> cluster=<memory:49152, vCores:96>
2013-08-17 06:42:21,150 INFO org.apache.hadoop.yarn.server.resourcemanager.scheduler.capacity.ParentQueue: Re-sorting queues since queue: root.default stats: default: capacity=1.0, absoluteCapacity=1.0, usedResources=<memory:49152, vCores:43>usedCapacity=1.0, absoluteUsedCapacity=1.0, numApps=5, numContainers=43
2013-08-17 06:42:21,151 INFO org.apache.hadoop.yarn.server.resourcemanager.scheduler.capacity.ParentQueue: assignedContainer queue=root usedCapacity=1.0 absoluteUsedCapacity=1.0 used=<memory:49152, vCores:43> cluster=<memory:49152, vCores:96>
2013-08-17 06:42:21,325 INFO org.apache.hadoop.yarn.server.resourcemanager.rmcontainer.RMContainerImpl: container_1376720997863_0007_01_000018 Container Transitioned from RUNNING to COMPLETED
2013-08-17 06:42:21,325 INFO org.apache.hadoop.yarn.server.resourcemanager.scheduler.common.fica.FiCaSchedulerApp: Completed container: container_1376720997863_0007_01_000018 in state: COMPLETED event:FINISHED
2013-08-17 06:42:21,325 INFO org.apache.hadoop.yarn.server.resourcemanager.RMAuditLogger: USER=ubuntu	OPERATION=AM Released Container	TARGET=SchedulerApp	RESULT=SUCCESS	APPID=application_1376720997863_0007	CONTAINERID=container_1376720997863_0007_01_000018
2013-08-17 06:42:21,325 INFO org.apache.hadoop.yarn.server.resourcemanager.scheduler.common.fica.FiCaSchedulerNode: Released container container_1376720997863_0007_01_000018 of capacity <memory:1024, vCores:1> on host hadoop-512-7:43914, which currently has 6 containers, <memory:7168, vCores:6> used and <memory:1024, vCores:10> available, release resources=true
2013-08-17 06:42:21,326 INFO org.apache.hadoop.yarn.server.resourcemanager.scheduler.capacity.LeafQueue: default used=<memory:48128, vCores:42> numContainers=42 user=ubuntu user-resources=<memory:48128, vCores:42>
2013-08-17 06:42:21,327 INFO org.apache.hadoop.yarn.server.resourcemanager.scheduler.capacity.LeafQueue: completedContainer container=Container: [ContainerId: container_1376720997863_0007_01_000018, NodeId: hadoop-512-7:43914, NodeHttpAddress: hadoop-512-7:8042, Resource: <memory:1024, vCores:1>, Priority: 20, State: NEW, Token: null, Status: container_id {, app_attempt_id {, application_id {, id: 7, cluster_timestamp: 1376720997863, }, attemptId: 1, }, id: 18, }, state: C_COMPLETE, diagnostics: "Container killed by the ApplicationMaster.\n\n", exit_status: 143, ] resource=<memory:1024, vCores:1> queue=default: capacity=1.0, absoluteCapacity=1.0, usedResources=<memory:48128, vCores:42>usedCapacity=0.9791667, absoluteUsedCapacity=0.9791667, numApps=5, numContainers=42 usedCapacity=0.9791667 absoluteUsedCapacity=0.9791667 used=<memory:48128, vCores:42> cluster=<memory:49152, vCores:96>
2013-08-17 06:42:21,327 INFO org.apache.hadoop.yarn.server.resourcemanager.scheduler.capacity.ParentQueue: completedContainer queue=root usedCapacity=0.9791667 absoluteUsedCapacity=0.9791667 used=<memory:48128, vCores:42> cluster=<memory:49152, vCores:96>
2013-08-17 06:42:21,327 INFO org.apache.hadoop.yarn.server.resourcemanager.scheduler.capacity.CapacityScheduler: Application appattempt_1376720997863_0007_000001 released container container_1376720997863_0007_01_000018 on node: host: hadoop-512-7:43914 #containers=6 available=1024 used=7168 with event: FINISHED
2013-08-17 06:42:21,327 INFO org.apache.hadoop.yarn.server.resourcemanager.rmcontainer.RMContainerImpl: container_1376720997863_0006_01_000013 Container Transitioned from NEW to ALLOCATED
2013-08-17 06:42:21,327 INFO org.apache.hadoop.yarn.server.resourcemanager.RMAuditLogger: USER=ubuntu	OPERATION=AM Allocated Container	TARGET=SchedulerApp	RESULT=SUCCESS	APPID=application_1376720997863_0006	CONTAINERID=container_1376720997863_0006_01_000013
2013-08-17 06:42:21,328 INFO org.apache.hadoop.yarn.server.resourcemanager.scheduler.common.fica.FiCaSchedulerNode: Assigned container container_1376720997863_0006_01_000013 of capacity <memory:1024, vCores:1> on host hadoop-512-7:43914, which currently has 7 containers, <memory:8192, vCores:7> used and <memory:0, vCores:9> available
2013-08-17 06:42:21,328 INFO org.apache.hadoop.yarn.server.resourcemanager.scheduler.capacity.LeafQueue: assignedContainer application=application_1376720997863_0006 container=Container: [ContainerId: container_1376720997863_0006_01_000013, NodeId: hadoop-512-7:43914, NodeHttpAddress: hadoop-512-7:8042, Resource: <memory:1024, vCores:1>, Priority: 20, State: NEW, Token: null, Status: container_id {, app_attempt_id {, application_id {, id: 6, cluster_timestamp: 1376720997863, }, attemptId: 1, }, id: 13, }, state: C_NEW, ] containerId=container_1376720997863_0006_01_000013 queue=default: capacity=1.0, absoluteCapacity=1.0, usedResources=<memory:48128, vCores:42>usedCapacity=0.9791667, absoluteUsedCapacity=0.9791667, numApps=5, numContainers=42 usedCapacity=0.9791667 absoluteUsedCapacity=0.9791667 used=<memory:48128, vCores:42> cluster=<memory:49152, vCores:96>
2013-08-17 06:42:21,329 INFO org.apache.hadoop.yarn.server.resourcemanager.scheduler.capacity.ParentQueue: Re-sorting queues since queue: root.default stats: default: capacity=1.0, absoluteCapacity=1.0, usedResources=<memory:49152, vCores:43>usedCapacity=1.0, absoluteUsedCapacity=1.0, numApps=5, numContainers=43
2013-08-17 06:42:21,329 INFO org.apache.hadoop.yarn.server.resourcemanager.scheduler.capacity.ParentQueue: assignedContainer queue=root usedCapacity=1.0 absoluteUsedCapacity=1.0 used=<memory:49152, vCores:43> cluster=<memory:49152, vCores:96>
2013-08-17 06:42:21,369 INFO org.apache.hadoop.yarn.server.resourcemanager.rmcontainer.RMContainerImpl: container_1376720997863_0006_01_000010 Container Transitioned from ALLOCATED to ACQUIRED
2013-08-17 06:42:21,371 INFO org.apache.hadoop.yarn.server.resourcemanager.rmcontainer.RMContainerImpl: container_1376720997863_0006_01_000011 Container Transitioned from ALLOCATED to ACQUIRED
2013-08-17 06:42:21,371 INFO org.apache.hadoop.yarn.server.resourcemanager.rmcontainer.RMContainerImpl: container_1376720997863_0006_01_000012 Container Transitioned from ALLOCATED to ACQUIRED
2013-08-17 06:42:21,371 INFO org.apache.hadoop.yarn.server.resourcemanager.rmcontainer.RMContainerImpl: container_1376720997863_0006_01_000013 Container Transitioned from ALLOCATED to ACQUIRED
2013-08-17 06:42:21,371 INFO org.apache.hadoop.yarn.server.resourcemanager.rmcontainer.RMContainerImpl: container_1376720997863_0007_01_000012 Container Transitioned from RUNNING to COMPLETED
2013-08-17 06:42:21,372 INFO org.apache.hadoop.yarn.server.resourcemanager.scheduler.common.fica.FiCaSchedulerApp: Completed container: container_1376720997863_0007_01_000012 in state: COMPLETED event:FINISHED
2013-08-17 06:42:21,372 INFO org.apache.hadoop.yarn.server.resourcemanager.RMAuditLogger: USER=ubuntu	OPERATION=AM Released Container	TARGET=SchedulerApp	RESULT=SUCCESS	APPID=application_1376720997863_0007	CONTAINERID=container_1376720997863_0007_01_000012
2013-08-17 06:42:21,372 INFO org.apache.hadoop.yarn.server.resourcemanager.scheduler.common.fica.FiCaSchedulerNode: Released container container_1376720997863_0007_01_000012 of capacity <memory:1024, vCores:1> on host hadoop-512-4:45085, which currently has 6 containers, <memory:7168, vCores:6> used and <memory:1024, vCores:10> available, release resources=true
2013-08-17 06:42:21,372 INFO org.apache.hadoop.yarn.server.resourcemanager.scheduler.capacity.LeafQueue: default used=<memory:48128, vCores:42> numContainers=42 user=ubuntu user-resources=<memory:48128, vCores:42>
2013-08-17 06:42:21,373 INFO org.apache.hadoop.yarn.server.resourcemanager.scheduler.capacity.LeafQueue: completedContainer container=Container: [ContainerId: container_1376720997863_0007_01_000012, NodeId: hadoop-512-4:45085, NodeHttpAddress: hadoop-512-4:8042, Resource: <memory:1024, vCores:1>, Priority: 20, State: NEW, Token: null, Status: container_id {, app_attempt_id {, application_id {, id: 7, cluster_timestamp: 1376720997863, }, attemptId: 1, }, id: 12, }, state: C_COMPLETE, diagnostics: "Container killed by the ApplicationMaster.\n\n", exit_status: 143, ] resource=<memory:1024, vCores:1> queue=default: capacity=1.0, absoluteCapacity=1.0, usedResources=<memory:48128, vCores:42>usedCapacity=0.9791667, absoluteUsedCapacity=0.9791667, numApps=5, numContainers=42 usedCapacity=0.9791667 absoluteUsedCapacity=0.9791667 used=<memory:48128, vCores:42> cluster=<memory:49152, vCores:96>
2013-08-17 06:42:21,373 INFO org.apache.hadoop.yarn.server.resourcemanager.scheduler.capacity.ParentQueue: completedContainer queue=root usedCapacity=0.9791667 absoluteUsedCapacity=0.9791667 used=<memory:48128, vCores:42> cluster=<memory:49152, vCores:96>
2013-08-17 06:42:21,373 INFO org.apache.hadoop.yarn.server.resourcemanager.scheduler.capacity.CapacityScheduler: Application appattempt_1376720997863_0007_000001 released container container_1376720997863_0007_01_000012 on node: host: hadoop-512-4:45085 #containers=6 available=1024 used=7168 with event: FINISHED
2013-08-17 06:42:21,374 INFO org.apache.hadoop.yarn.server.resourcemanager.rmcontainer.RMContainerImpl: container_1376720997863_0006_01_000014 Container Transitioned from NEW to ALLOCATED
2013-08-17 06:42:21,374 INFO org.apache.hadoop.yarn.server.resourcemanager.RMAuditLogger: USER=ubuntu	OPERATION=AM Allocated Container	TARGET=SchedulerApp	RESULT=SUCCESS	APPID=application_1376720997863_0006	CONTAINERID=container_1376720997863_0006_01_000014
2013-08-17 06:42:21,374 INFO org.apache.hadoop.yarn.server.resourcemanager.scheduler.common.fica.FiCaSchedulerNode: Assigned container container_1376720997863_0006_01_000014 of capacity <memory:1024, vCores:1> on host hadoop-512-4:45085, which currently has 7 containers, <memory:8192, vCores:7> used and <memory:0, vCores:9> available
2013-08-17 06:42:21,375 INFO org.apache.hadoop.yarn.server.resourcemanager.scheduler.capacity.LeafQueue: assignedContainer application=application_1376720997863_0006 container=Container: [ContainerId: container_1376720997863_0006_01_000014, NodeId: hadoop-512-4:45085, NodeHttpAddress: hadoop-512-4:8042, Resource: <memory:1024, vCores:1>, Priority: 20, State: NEW, Token: null, Status: container_id {, app_attempt_id {, application_id {, id: 6, cluster_timestamp: 1376720997863, }, attemptId: 1, }, id: 14, }, state: C_NEW, ] containerId=container_1376720997863_0006_01_000014 queue=default: capacity=1.0, absoluteCapacity=1.0, usedResources=<memory:48128, vCores:42>usedCapacity=0.9791667, absoluteUsedCapacity=0.9791667, numApps=5, numContainers=42 usedCapacity=0.9791667 absoluteUsedCapacity=0.9791667 used=<memory:48128, vCores:42> cluster=<memory:49152, vCores:96>
2013-08-17 06:42:21,375 INFO org.apache.hadoop.yarn.server.resourcemanager.scheduler.capacity.ParentQueue: Re-sorting queues since queue: root.default stats: default: capacity=1.0, absoluteCapacity=1.0, usedResources=<memory:49152, vCores:43>usedCapacity=1.0, absoluteUsedCapacity=1.0, numApps=5, numContainers=43
2013-08-17 06:42:21,375 INFO org.apache.hadoop.yarn.server.resourcemanager.scheduler.capacity.ParentQueue: assignedContainer queue=root usedCapacity=1.0 absoluteUsedCapacity=1.0 used=<memory:49152, vCores:43> cluster=<memory:49152, vCores:96>
2013-08-17 06:42:22,088 INFO org.apache.hadoop.yarn.server.resourcemanager.rmcontainer.RMContainerImpl: container_1376720997863_0006_01_000010 Container Transitioned from ACQUIRED to RUNNING
2013-08-17 06:42:22,088 INFO org.apache.hadoop.yarn.server.resourcemanager.rmcontainer.RMContainerImpl: container_1376720997863_0006_01_000011 Container Transitioned from ACQUIRED to RUNNING
2013-08-17 06:42:22,089 INFO org.apache.hadoop.yarn.server.resourcemanager.rmcontainer.RMContainerImpl: container_1376720997863_0007_01_000031 Container Transitioned from RUNNING to COMPLETED
2013-08-17 06:42:22,089 INFO org.apache.hadoop.yarn.server.resourcemanager.scheduler.common.fica.FiCaSchedulerApp: Completed container: container_1376720997863_0007_01_000031 in state: COMPLETED event:FINISHED
2013-08-17 06:42:22,089 INFO org.apache.hadoop.yarn.server.resourcemanager.RMAuditLogger: USER=ubuntu	OPERATION=AM Released Container	TARGET=SchedulerApp	RESULT=SUCCESS	APPID=application_1376720997863_0007	CONTAINERID=container_1376720997863_0007_01_000031
2013-08-17 06:42:22,089 INFO org.apache.hadoop.yarn.server.resourcemanager.scheduler.common.fica.FiCaSchedulerNode: Released container container_1376720997863_0007_01_000031 of capacity <memory:1024, vCores:1> on host hadoop-512-6:48301, which currently has 7 containers, <memory:7168, vCores:7> used and <memory:1024, vCores:9> available, release resources=true
2013-08-17 06:42:22,089 INFO org.apache.hadoop.yarn.server.resourcemanager.scheduler.capacity.LeafQueue: default used=<memory:48128, vCores:42> numContainers=42 user=ubuntu user-resources=<memory:48128, vCores:42>
2013-08-17 06:42:22,090 INFO org.apache.hadoop.yarn.server.resourcemanager.scheduler.capacity.LeafQueue: completedContainer container=Container: [ContainerId: container_1376720997863_0007_01_000031, NodeId: hadoop-512-6:48301, NodeHttpAddress: hadoop-512-6:8042, Resource: <memory:1024, vCores:1>, Priority: 20, State: NEW, Token: null, Status: container_id {, app_attempt_id {, application_id {, id: 7, cluster_timestamp: 1376720997863, }, attemptId: 1, }, id: 31, }, state: C_COMPLETE, diagnostics: "Container killed by the ApplicationMaster.\n\n", exit_status: 143, ] resource=<memory:1024, vCores:1> queue=default: capacity=1.0, absoluteCapacity=1.0, usedResources=<memory:48128, vCores:42>usedCapacity=0.9791667, absoluteUsedCapacity=0.9791667, numApps=5, numContainers=42 usedCapacity=0.9791667 absoluteUsedCapacity=0.9791667 used=<memory:48128, vCores:42> cluster=<memory:49152, vCores:96>
2013-08-17 06:42:22,091 INFO org.apache.hadoop.yarn.server.resourcemanager.scheduler.capacity.ParentQueue: completedContainer queue=root usedCapacity=0.9791667 absoluteUsedCapacity=0.9791667 used=<memory:48128, vCores:42> cluster=<memory:49152, vCores:96>
2013-08-17 06:42:22,091 INFO org.apache.hadoop.yarn.server.resourcemanager.scheduler.capacity.CapacityScheduler: Application appattempt_1376720997863_0007_000001 released container container_1376720997863_0007_01_000031 on node: host: hadoop-512-6:48301 #containers=7 available=1024 used=7168 with event: FINISHED
2013-08-17 06:42:22,091 INFO org.apache.hadoop.yarn.server.resourcemanager.rmcontainer.RMContainerImpl: container_1376720997863_0006_01_000015 Container Transitioned from NEW to ALLOCATED
2013-08-17 06:42:22,091 INFO org.apache.hadoop.yarn.server.resourcemanager.RMAuditLogger: USER=ubuntu	OPERATION=AM Allocated Container	TARGET=SchedulerApp	RESULT=SUCCESS	APPID=application_1376720997863_0006	CONTAINERID=container_1376720997863_0006_01_000015
2013-08-17 06:42:22,091 INFO org.apache.hadoop.yarn.server.resourcemanager.scheduler.common.fica.FiCaSchedulerNode: Assigned container container_1376720997863_0006_01_000015 of capacity <memory:1024, vCores:1> on host hadoop-512-6:48301, which currently has 8 containers, <memory:8192, vCores:8> used and <memory:0, vCores:8> available
2013-08-17 06:42:22,092 INFO org.apache.hadoop.yarn.server.resourcemanager.scheduler.capacity.LeafQueue: assignedContainer application=application_1376720997863_0006 container=Container: [ContainerId: container_1376720997863_0006_01_000015, NodeId: hadoop-512-6:48301, NodeHttpAddress: hadoop-512-6:8042, Resource: <memory:1024, vCores:1>, Priority: 20, State: NEW, Token: null, Status: container_id {, app_attempt_id {, application_id {, id: 6, cluster_timestamp: 1376720997863, }, attemptId: 1, }, id: 15, }, state: C_NEW, ] containerId=container_1376720997863_0006_01_000015 queue=default: capacity=1.0, absoluteCapacity=1.0, usedResources=<memory:48128, vCores:42>usedCapacity=0.9791667, absoluteUsedCapacity=0.9791667, numApps=5, numContainers=42 usedCapacity=0.9791667 absoluteUsedCapacity=0.9791667 used=<memory:48128, vCores:42> cluster=<memory:49152, vCores:96>
2013-08-17 06:42:22,092 INFO org.apache.hadoop.yarn.server.resourcemanager.scheduler.capacity.ParentQueue: Re-sorting queues since queue: root.default stats: default: capacity=1.0, absoluteCapacity=1.0, usedResources=<memory:49152, vCores:43>usedCapacity=1.0, absoluteUsedCapacity=1.0, numApps=5, numContainers=43
2013-08-17 06:42:22,093 INFO org.apache.hadoop.yarn.server.resourcemanager.scheduler.capacity.ParentQueue: assignedContainer queue=root usedCapacity=1.0 absoluteUsedCapacity=1.0 used=<memory:49152, vCores:43> cluster=<memory:49152, vCores:96>
2013-08-17 06:42:22,156 INFO org.apache.hadoop.yarn.server.resourcemanager.rmcontainer.RMContainerImpl: container_1376720997863_0006_01_000012 Container Transitioned from ACQUIRED to RUNNING
2013-08-17 06:42:22,337 INFO org.apache.hadoop.yarn.server.resourcemanager.rmcontainer.RMContainerImpl: container_1376720997863_0006_01_000013 Container Transitioned from ACQUIRED to RUNNING
2013-08-17 06:42:22,399 INFO org.apache.hadoop.yarn.server.resourcemanager.rmcontainer.RMContainerImpl: container_1376720997863_0006_01_000014 Container Transitioned from ALLOCATED to ACQUIRED
2013-08-17 06:42:22,400 INFO org.apache.hadoop.yarn.server.resourcemanager.rmcontainer.RMContainerImpl: container_1376720997863_0006_01_000015 Container Transitioned from ALLOCATED to ACQUIRED
2013-08-17 06:42:22,598 INFO org.apache.hadoop.yarn.server.resourcemanager.rmcontainer.RMContainerImpl: container_1376720997863_0006_01_000014 Container Transitioned from ACQUIRED to RUNNING
2013-08-17 06:42:23,607 INFO org.apache.hadoop.yarn.server.resourcemanager.rmcontainer.RMContainerImpl: container_1376720997863_0007_01_000010 Container Transitioned from RUNNING to COMPLETED
2013-08-17 06:42:23,607 INFO org.apache.hadoop.yarn.server.resourcemanager.scheduler.common.fica.FiCaSchedulerApp: Completed container: container_1376720997863_0007_01_000010 in state: COMPLETED event:FINISHED
2013-08-17 06:42:23,607 INFO org.apache.hadoop.yarn.server.resourcemanager.RMAuditLogger: USER=ubuntu	OPERATION=AM Released Container	TARGET=SchedulerApp	RESULT=SUCCESS	APPID=application_1376720997863_0007	CONTAINERID=container_1376720997863_0007_01_000010
2013-08-17 06:42:23,607 INFO org.apache.hadoop.yarn.server.resourcemanager.scheduler.common.fica.FiCaSchedulerNode: Released container container_1376720997863_0007_01_000010 of capacity <memory:1024, vCores:1> on host hadoop-512-4:45085, which currently has 6 containers, <memory:7168, vCores:6> used and <memory:1024, vCores:10> available, release resources=true
2013-08-17 06:42:23,607 INFO org.apache.hadoop.yarn.server.resourcemanager.scheduler.capacity.LeafQueue: default used=<memory:48128, vCores:42> numContainers=42 user=ubuntu user-resources=<memory:48128, vCores:42>
2013-08-17 06:42:23,609 INFO org.apache.hadoop.yarn.server.resourcemanager.scheduler.capacity.LeafQueue: completedContainer container=Container: [ContainerId: container_1376720997863_0007_01_000010, NodeId: hadoop-512-4:45085, NodeHttpAddress: hadoop-512-4:8042, Resource: <memory:1024, vCores:1>, Priority: 20, State: NEW, Token: null, Status: container_id {, app_attempt_id {, application_id {, id: 7, cluster_timestamp: 1376720997863, }, attemptId: 1, }, id: 10, }, state: C_COMPLETE, diagnostics: "Container killed by the ApplicationMaster.\n\n", exit_status: 143, ] resource=<memory:1024, vCores:1> queue=default: capacity=1.0, absoluteCapacity=1.0, usedResources=<memory:48128, vCores:42>usedCapacity=0.9791667, absoluteUsedCapacity=0.9791667, numApps=5, numContainers=42 usedCapacity=0.9791667 absoluteUsedCapacity=0.9791667 used=<memory:48128, vCores:42> cluster=<memory:49152, vCores:96>
2013-08-17 06:42:23,609 INFO org.apache.hadoop.yarn.server.resourcemanager.scheduler.capacity.ParentQueue: completedContainer queue=root usedCapacity=0.9791667 absoluteUsedCapacity=0.9791667 used=<memory:48128, vCores:42> cluster=<memory:49152, vCores:96>
2013-08-17 06:42:23,609 INFO org.apache.hadoop.yarn.server.resourcemanager.scheduler.capacity.CapacityScheduler: Application appattempt_1376720997863_0007_000001 released container container_1376720997863_0007_01_000010 on node: host: hadoop-512-4:45085 #containers=6 available=1024 used=7168 with event: FINISHED
2013-08-17 06:42:23,609 INFO org.apache.hadoop.yarn.server.resourcemanager.rmcontainer.RMContainerImpl: container_1376720997863_0006_01_000016 Container Transitioned from NEW to ALLOCATED
2013-08-17 06:42:23,609 INFO org.apache.hadoop.yarn.server.resourcemanager.RMAuditLogger: USER=ubuntu	OPERATION=AM Allocated Container	TARGET=SchedulerApp	RESULT=SUCCESS	APPID=application_1376720997863_0006	CONTAINERID=container_1376720997863_0006_01_000016
2013-08-17 06:42:23,610 INFO org.apache.hadoop.yarn.server.resourcemanager.scheduler.common.fica.FiCaSchedulerNode: Assigned container container_1376720997863_0006_01_000016 of capacity <memory:1024, vCores:1> on host hadoop-512-4:45085, which currently has 7 containers, <memory:8192, vCores:7> used and <memory:0, vCores:9> available
2013-08-17 06:42:23,611 INFO org.apache.hadoop.yarn.server.resourcemanager.scheduler.capacity.LeafQueue: assignedContainer application=application_1376720997863_0006 container=Container: [ContainerId: container_1376720997863_0006_01_000016, NodeId: hadoop-512-4:45085, NodeHttpAddress: hadoop-512-4:8042, Resource: <memory:1024, vCores:1>, Priority: 20, State: NEW, Token: null, Status: container_id {, app_attempt_id {, application_id {, id: 6, cluster_timestamp: 1376720997863, }, attemptId: 1, }, id: 16, }, state: C_NEW, ] containerId=container_1376720997863_0006_01_000016 queue=default: capacity=1.0, absoluteCapacity=1.0, usedResources=<memory:48128, vCores:42>usedCapacity=0.9791667, absoluteUsedCapacity=0.9791667, numApps=5, numContainers=42 usedCapacity=0.9791667 absoluteUsedCapacity=0.9791667 used=<memory:48128, vCores:42> cluster=<memory:49152, vCores:96>
2013-08-17 06:42:23,611 INFO org.apache.hadoop.yarn.server.resourcemanager.scheduler.capacity.ParentQueue: Re-sorting queues since queue: root.default stats: default: capacity=1.0, absoluteCapacity=1.0, usedResources=<memory:49152, vCores:43>usedCapacity=1.0, absoluteUsedCapacity=1.0, numApps=5, numContainers=43
2013-08-17 06:42:23,611 INFO org.apache.hadoop.yarn.server.resourcemanager.scheduler.capacity.ParentQueue: assignedContainer queue=root usedCapacity=1.0 absoluteUsedCapacity=1.0 used=<memory:49152, vCores:43> cluster=<memory:49152, vCores:96>
2013-08-17 06:42:24,310 INFO org.apache.hadoop.yarn.server.resourcemanager.rmcontainer.RMContainerImpl: container_1376720997863_0006_01_000015 Container Transitioned from ACQUIRED to RUNNING
2013-08-17 06:42:24,490 INFO org.apache.hadoop.yarn.server.resourcemanager.rmcontainer.RMContainerImpl: container_1376720997863_0006_01_000016 Container Transitioned from ALLOCATED to ACQUIRED
2013-08-17 06:42:24,617 INFO org.apache.hadoop.yarn.server.resourcemanager.rmcontainer.RMContainerImpl: container_1376720997863_0006_01_000016 Container Transitioned from ACQUIRED to RUNNING
2013-08-17 06:42:25,050 INFO org.apache.hadoop.yarn.server.resourcemanager.rmcontainer.RMContainerImpl: container_1376720997863_0007_01_000021 Container Transitioned from RUNNING to COMPLETED
2013-08-17 06:42:25,050 INFO org.apache.hadoop.yarn.server.resourcemanager.scheduler.common.fica.FiCaSchedulerApp: Completed container: container_1376720997863_0007_01_000021 in state: COMPLETED event:FINISHED
2013-08-17 06:42:25,050 INFO org.apache.hadoop.yarn.server.resourcemanager.RMAuditLogger: USER=ubuntu	OPERATION=AM Released Container	TARGET=SchedulerApp	RESULT=SUCCESS	APPID=application_1376720997863_0007	CONTAINERID=container_1376720997863_0007_01_000021
2013-08-17 06:42:25,050 INFO org.apache.hadoop.yarn.server.resourcemanager.scheduler.common.fica.FiCaSchedulerNode: Released container container_1376720997863_0007_01_000021 of capacity <memory:1024, vCores:1> on host hadoop-512-2:32923, which currently has 6 containers, <memory:7168, vCores:6> used and <memory:1024, vCores:10> available, release resources=true
2013-08-17 06:42:25,050 INFO org.apache.hadoop.yarn.server.resourcemanager.scheduler.capacity.LeafQueue: default used=<memory:48128, vCores:42> numContainers=42 user=ubuntu user-resources=<memory:48128, vCores:42>
2013-08-17 06:42:25,052 INFO org.apache.hadoop.yarn.server.resourcemanager.scheduler.capacity.LeafQueue: completedContainer container=Container: [ContainerId: container_1376720997863_0007_01_000021, NodeId: hadoop-512-2:32923, NodeHttpAddress: hadoop-512-2:8042, Resource: <memory:1024, vCores:1>, Priority: 20, State: NEW, Token: null, Status: container_id {, app_attempt_id {, application_id {, id: 7, cluster_timestamp: 1376720997863, }, attemptId: 1, }, id: 21, }, state: C_COMPLETE, diagnostics: "Container killed by the ApplicationMaster.\n\n", exit_status: 143, ] resource=<memory:1024, vCores:1> queue=default: capacity=1.0, absoluteCapacity=1.0, usedResources=<memory:48128, vCores:42>usedCapacity=0.9791667, absoluteUsedCapacity=0.9791667, numApps=5, numContainers=42 usedCapacity=0.9791667 absoluteUsedCapacity=0.9791667 used=<memory:48128, vCores:42> cluster=<memory:49152, vCores:96>
2013-08-17 06:42:25,052 INFO org.apache.hadoop.yarn.server.resourcemanager.scheduler.capacity.ParentQueue: completedContainer queue=root usedCapacity=0.9791667 absoluteUsedCapacity=0.9791667 used=<memory:48128, vCores:42> cluster=<memory:49152, vCores:96>
2013-08-17 06:42:25,052 INFO org.apache.hadoop.yarn.server.resourcemanager.scheduler.capacity.CapacityScheduler: Application appattempt_1376720997863_0007_000001 released container container_1376720997863_0007_01_000021 on node: host: hadoop-512-2:32923 #containers=6 available=1024 used=7168 with event: FINISHED
2013-08-17 06:42:25,053 INFO org.apache.hadoop.yarn.server.resourcemanager.rmcontainer.RMContainerImpl: container_1376720997863_0006_01_000017 Container Transitioned from NEW to ALLOCATED
2013-08-17 06:42:25,053 INFO org.apache.hadoop.yarn.server.resourcemanager.RMAuditLogger: USER=ubuntu	OPERATION=AM Allocated Container	TARGET=SchedulerApp	RESULT=SUCCESS	APPID=application_1376720997863_0006	CONTAINERID=container_1376720997863_0006_01_000017
2013-08-17 06:42:25,053 INFO org.apache.hadoop.yarn.server.resourcemanager.scheduler.common.fica.FiCaSchedulerNode: Assigned container container_1376720997863_0006_01_000017 of capacity <memory:1024, vCores:1> on host hadoop-512-2:32923, which currently has 7 containers, <memory:8192, vCores:7> used and <memory:0, vCores:9> available
2013-08-17 06:42:25,054 INFO org.apache.hadoop.yarn.server.resourcemanager.scheduler.capacity.LeafQueue: assignedContainer application=application_1376720997863_0006 container=Container: [ContainerId: container_1376720997863_0006_01_000017, NodeId: hadoop-512-2:32923, NodeHttpAddress: hadoop-512-2:8042, Resource: <memory:1024, vCores:1>, Priority: 20, State: NEW, Token: null, Status: container_id {, app_attempt_id {, application_id {, id: 6, cluster_timestamp: 1376720997863, }, attemptId: 1, }, id: 17, }, state: C_NEW, ] containerId=container_1376720997863_0006_01_000017 queue=default: capacity=1.0, absoluteCapacity=1.0, usedResources=<memory:48128, vCores:42>usedCapacity=0.9791667, absoluteUsedCapacity=0.9791667, numApps=5, numContainers=42 usedCapacity=0.9791667 absoluteUsedCapacity=0.9791667 used=<memory:48128, vCores:42> cluster=<memory:49152, vCores:96>
2013-08-17 06:42:25,054 INFO org.apache.hadoop.yarn.server.resourcemanager.scheduler.capacity.ParentQueue: Re-sorting queues since queue: root.default stats: default: capacity=1.0, absoluteCapacity=1.0, usedResources=<memory:49152, vCores:43>usedCapacity=1.0, absoluteUsedCapacity=1.0, numApps=5, numContainers=43
2013-08-17 06:42:25,054 INFO org.apache.hadoop.yarn.server.resourcemanager.scheduler.capacity.ParentQueue: assignedContainer queue=root usedCapacity=1.0 absoluteUsedCapacity=1.0 used=<memory:49152, vCores:43> cluster=<memory:49152, vCores:96>
2013-08-17 06:42:25,501 INFO org.apache.hadoop.yarn.server.resourcemanager.rmcontainer.RMContainerImpl: container_1376720997863_0006_01_000017 Container Transitioned from ALLOCATED to ACQUIRED
2013-08-17 06:42:26,066 INFO org.apache.hadoop.yarn.server.resourcemanager.rmcontainer.RMContainerImpl: container_1376720997863_0006_01_000017 Container Transitioned from ACQUIRED to RUNNING
2013-08-17 06:42:27,186 INFO org.apache.hadoop.yarn.server.resourcemanager.rmcontainer.RMContainerImpl: container_1376720997863_0007_01_000007 Container Transitioned from RUNNING to COMPLETED
2013-08-17 06:42:27,186 INFO org.apache.hadoop.yarn.server.resourcemanager.scheduler.common.fica.FiCaSchedulerApp: Completed container: container_1376720997863_0007_01_000007 in state: COMPLETED event:FINISHED
2013-08-17 06:42:27,186 INFO org.apache.hadoop.yarn.server.resourcemanager.RMAuditLogger: USER=ubuntu	OPERATION=AM Released Container	TARGET=SchedulerApp	RESULT=SUCCESS	APPID=application_1376720997863_0007	CONTAINERID=container_1376720997863_0007_01_000007
2013-08-17 06:42:27,187 INFO org.apache.hadoop.yarn.server.resourcemanager.scheduler.common.fica.FiCaSchedulerNode: Released container container_1376720997863_0007_01_000007 of capacity <memory:1024, vCores:1> on host hadoop-512-5:45082, which currently has 6 containers, <memory:7168, vCores:6> used and <memory:1024, vCores:10> available, release resources=true
2013-08-17 06:42:27,187 INFO org.apache.hadoop.yarn.server.resourcemanager.scheduler.capacity.LeafQueue: default used=<memory:48128, vCores:42> numContainers=42 user=ubuntu user-resources=<memory:48128, vCores:42>
2013-08-17 06:42:27,188 INFO org.apache.hadoop.yarn.server.resourcemanager.scheduler.capacity.LeafQueue: completedContainer container=Container: [ContainerId: container_1376720997863_0007_01_000007, NodeId: hadoop-512-5:45082, NodeHttpAddress: hadoop-512-5:8042, Resource: <memory:1024, vCores:1>, Priority: 20, State: NEW, Token: null, Status: container_id {, app_attempt_id {, application_id {, id: 7, cluster_timestamp: 1376720997863, }, attemptId: 1, }, id: 7, }, state: C_COMPLETE, diagnostics: "Container killed by the ApplicationMaster.\n\n", exit_status: 143, ] resource=<memory:1024, vCores:1> queue=default: capacity=1.0, absoluteCapacity=1.0, usedResources=<memory:48128, vCores:42>usedCapacity=0.9791667, absoluteUsedCapacity=0.9791667, numApps=5, numContainers=42 usedCapacity=0.9791667 absoluteUsedCapacity=0.9791667 used=<memory:48128, vCores:42> cluster=<memory:49152, vCores:96>
2013-08-17 06:42:27,188 INFO org.apache.hadoop.yarn.server.resourcemanager.scheduler.capacity.ParentQueue: completedContainer queue=root usedCapacity=0.9791667 absoluteUsedCapacity=0.9791667 used=<memory:48128, vCores:42> cluster=<memory:49152, vCores:96>
2013-08-17 06:42:27,188 INFO org.apache.hadoop.yarn.server.resourcemanager.scheduler.capacity.CapacityScheduler: Application appattempt_1376720997863_0007_000001 released container container_1376720997863_0007_01_000007 on node: host: hadoop-512-5:45082 #containers=6 available=1024 used=7168 with event: FINISHED
2013-08-17 06:42:27,189 INFO org.apache.hadoop.yarn.server.resourcemanager.rmcontainer.RMContainerImpl: container_1376720997863_0006_01_000018 Container Transitioned from NEW to ALLOCATED
2013-08-17 06:42:27,189 INFO org.apache.hadoop.yarn.server.resourcemanager.RMAuditLogger: USER=ubuntu	OPERATION=AM Allocated Container	TARGET=SchedulerApp	RESULT=SUCCESS	APPID=application_1376720997863_0006	CONTAINERID=container_1376720997863_0006_01_000018
2013-08-17 06:42:27,189 INFO org.apache.hadoop.yarn.server.resourcemanager.scheduler.common.fica.FiCaSchedulerNode: Assigned container container_1376720997863_0006_01_000018 of capacity <memory:1024, vCores:1> on host hadoop-512-5:45082, which currently has 7 containers, <memory:8192, vCores:7> used and <memory:0, vCores:9> available
2013-08-17 06:42:27,190 INFO org.apache.hadoop.yarn.server.resourcemanager.scheduler.capacity.LeafQueue: assignedContainer application=application_1376720997863_0006 container=Container: [ContainerId: container_1376720997863_0006_01_000018, NodeId: hadoop-512-5:45082, NodeHttpAddress: hadoop-512-5:8042, Resource: <memory:1024, vCores:1>, Priority: 20, State: NEW, Token: null, Status: container_id {, app_attempt_id {, application_id {, id: 6, cluster_timestamp: 1376720997863, }, attemptId: 1, }, id: 18, }, state: C_NEW, ] containerId=container_1376720997863_0006_01_000018 queue=default: capacity=1.0, absoluteCapacity=1.0, usedResources=<memory:48128, vCores:42>usedCapacity=0.9791667, absoluteUsedCapacity=0.9791667, numApps=5, numContainers=42 usedCapacity=0.9791667 absoluteUsedCapacity=0.9791667 used=<memory:48128, vCores:42> cluster=<memory:49152, vCores:96>
2013-08-17 06:42:27,190 INFO org.apache.hadoop.yarn.server.resourcemanager.scheduler.capacity.ParentQueue: Re-sorting queues since queue: root.default stats: default: capacity=1.0, absoluteCapacity=1.0, usedResources=<memory:49152, vCores:43>usedCapacity=1.0, absoluteUsedCapacity=1.0, numApps=5, numContainers=43
2013-08-17 06:42:27,190 INFO org.apache.hadoop.yarn.server.resourcemanager.scheduler.capacity.ParentQueue: assignedContainer queue=root usedCapacity=1.0 absoluteUsedCapacity=1.0 used=<memory:49152, vCores:43> cluster=<memory:49152, vCores:96>
2013-08-17 06:42:27,229 INFO org.apache.hadoop.yarn.server.resourcemanager.rmcontainer.RMContainerImpl: container_1376720997863_0007_01_000037 Container Transitioned from RUNNING to COMPLETED
2013-08-17 06:42:27,230 INFO org.apache.hadoop.yarn.server.resourcemanager.scheduler.common.fica.FiCaSchedulerApp: Completed container: container_1376720997863_0007_01_000037 in state: COMPLETED event:FINISHED
2013-08-17 06:42:27,230 INFO org.apache.hadoop.yarn.server.resourcemanager.RMAuditLogger: USER=ubuntu	OPERATION=AM Released Container	TARGET=SchedulerApp	RESULT=SUCCESS	APPID=application_1376720997863_0007	CONTAINERID=container_1376720997863_0007_01_000037
2013-08-17 06:42:27,230 INFO org.apache.hadoop.yarn.server.resourcemanager.scheduler.common.fica.FiCaSchedulerNode: Released container container_1376720997863_0007_01_000037 of capacity <memory:1024, vCores:1> on host hadoop-512-3:56071, which currently has 6 containers, <memory:7168, vCores:6> used and <memory:1024, vCores:10> available, release resources=true
2013-08-17 06:42:27,230 INFO org.apache.hadoop.yarn.server.resourcemanager.scheduler.capacity.LeafQueue: default used=<memory:48128, vCores:42> numContainers=42 user=ubuntu user-resources=<memory:48128, vCores:42>
2013-08-17 06:42:27,231 INFO org.apache.hadoop.yarn.server.resourcemanager.scheduler.capacity.LeafQueue: completedContainer container=Container: [ContainerId: container_1376720997863_0007_01_000037, NodeId: hadoop-512-3:56071, NodeHttpAddress: hadoop-512-3:8042, Resource: <memory:1024, vCores:1>, Priority: 20, State: NEW, Token: null, Status: container_id {, app_attempt_id {, application_id {, id: 7, cluster_timestamp: 1376720997863, }, attemptId: 1, }, id: 37, }, state: C_COMPLETE, diagnostics: "Container killed by the ApplicationMaster.\n\n", exit_status: 143, ] resource=<memory:1024, vCores:1> queue=default: capacity=1.0, absoluteCapacity=1.0, usedResources=<memory:48128, vCores:42>usedCapacity=0.9791667, absoluteUsedCapacity=0.9791667, numApps=5, numContainers=42 usedCapacity=0.9791667 absoluteUsedCapacity=0.9791667 used=<memory:48128, vCores:42> cluster=<memory:49152, vCores:96>
2013-08-17 06:42:27,231 INFO org.apache.hadoop.yarn.server.resourcemanager.scheduler.capacity.ParentQueue: completedContainer queue=root usedCapacity=0.9791667 absoluteUsedCapacity=0.9791667 used=<memory:48128, vCores:42> cluster=<memory:49152, vCores:96>
2013-08-17 06:42:27,231 INFO org.apache.hadoop.yarn.server.resourcemanager.scheduler.capacity.CapacityScheduler: Application appattempt_1376720997863_0007_000001 released container container_1376720997863_0007_01_000037 on node: host: hadoop-512-3:56071 #containers=6 available=1024 used=7168 with event: FINISHED
2013-08-17 06:42:27,232 INFO org.apache.hadoop.yarn.server.resourcemanager.rmcontainer.RMContainerImpl: container_1376720997863_0006_01_000019 Container Transitioned from NEW to ALLOCATED
2013-08-17 06:42:27,232 INFO org.apache.hadoop.yarn.server.resourcemanager.RMAuditLogger: USER=ubuntu	OPERATION=AM Allocated Container	TARGET=SchedulerApp	RESULT=SUCCESS	APPID=application_1376720997863_0006	CONTAINERID=container_1376720997863_0006_01_000019
2013-08-17 06:42:27,232 INFO org.apache.hadoop.yarn.server.resourcemanager.scheduler.common.fica.FiCaSchedulerNode: Assigned container container_1376720997863_0006_01_000019 of capacity <memory:1024, vCores:1> on host hadoop-512-3:56071, which currently has 7 containers, <memory:8192, vCores:7> used and <memory:0, vCores:9> available
2013-08-17 06:42:27,233 INFO org.apache.hadoop.yarn.server.resourcemanager.scheduler.capacity.LeafQueue: assignedContainer application=application_1376720997863_0006 container=Container: [ContainerId: container_1376720997863_0006_01_000019, NodeId: hadoop-512-3:56071, NodeHttpAddress: hadoop-512-3:8042, Resource: <memory:1024, vCores:1>, Priority: 20, State: NEW, Token: null, Status: container_id {, app_attempt_id {, application_id {, id: 6, cluster_timestamp: 1376720997863, }, attemptId: 1, }, id: 19, }, state: C_NEW, ] containerId=container_1376720997863_0006_01_000019 queue=default: capacity=1.0, absoluteCapacity=1.0, usedResources=<memory:48128, vCores:42>usedCapacity=0.9791667, absoluteUsedCapacity=0.9791667, numApps=5, numContainers=42 usedCapacity=0.9791667 absoluteUsedCapacity=0.9791667 used=<memory:48128, vCores:42> cluster=<memory:49152, vCores:96>
2013-08-17 06:42:27,233 INFO org.apache.hadoop.yarn.server.resourcemanager.scheduler.capacity.ParentQueue: Re-sorting queues since queue: root.default stats: default: capacity=1.0, absoluteCapacity=1.0, usedResources=<memory:49152, vCores:43>usedCapacity=1.0, absoluteUsedCapacity=1.0, numApps=5, numContainers=43
2013-08-17 06:42:27,233 INFO org.apache.hadoop.yarn.server.resourcemanager.scheduler.capacity.ParentQueue: assignedContainer queue=root usedCapacity=1.0 absoluteUsedCapacity=1.0 used=<memory:49152, vCores:43> cluster=<memory:49152, vCores:96>
2013-08-17 06:42:27,511 INFO org.apache.hadoop.yarn.server.resourcemanager.rmcontainer.RMContainerImpl: container_1376720997863_0006_01_000018 Container Transitioned from ALLOCATED to ACQUIRED
2013-08-17 06:42:27,512 INFO org.apache.hadoop.yarn.server.resourcemanager.rmcontainer.RMContainerImpl: container_1376720997863_0006_01_000019 Container Transitioned from ALLOCATED to ACQUIRED
2013-08-17 06:42:28,192 INFO org.apache.hadoop.yarn.server.resourcemanager.rmcontainer.RMContainerImpl: container_1376720997863_0006_01_000018 Container Transitioned from ACQUIRED to RUNNING
2013-08-17 06:42:28,193 INFO org.apache.hadoop.yarn.server.resourcemanager.rmcontainer.RMContainerImpl: container_1376720997863_0007_01_000003 Container Transitioned from RUNNING to COMPLETED
2013-08-17 06:42:28,193 INFO org.apache.hadoop.yarn.server.resourcemanager.scheduler.common.fica.FiCaSchedulerApp: Completed container: container_1376720997863_0007_01_000003 in state: COMPLETED event:FINISHED
2013-08-17 06:42:28,193 INFO org.apache.hadoop.yarn.server.resourcemanager.RMAuditLogger: USER=ubuntu	OPERATION=AM Released Container	TARGET=SchedulerApp	RESULT=SUCCESS	APPID=application_1376720997863_0007	CONTAINERID=container_1376720997863_0007_01_000003
2013-08-17 06:42:28,193 INFO org.apache.hadoop.yarn.server.resourcemanager.scheduler.common.fica.FiCaSchedulerNode: Released container container_1376720997863_0007_01_000003 of capacity <memory:1024, vCores:1> on host hadoop-512-5:45082, which currently has 6 containers, <memory:7168, vCores:6> used and <memory:1024, vCores:10> available, release resources=true
2013-08-17 06:42:28,193 INFO org.apache.hadoop.yarn.server.resourcemanager.scheduler.capacity.LeafQueue: default used=<memory:48128, vCores:42> numContainers=42 user=ubuntu user-resources=<memory:48128, vCores:42>
2013-08-17 06:42:28,194 INFO org.apache.hadoop.yarn.server.resourcemanager.scheduler.capacity.LeafQueue: completedContainer container=Container: [ContainerId: container_1376720997863_0007_01_000003, NodeId: hadoop-512-5:45082, NodeHttpAddress: hadoop-512-5:8042, Resource: <memory:1024, vCores:1>, Priority: 20, State: NEW, Token: null, Status: container_id {, app_attempt_id {, application_id {, id: 7, cluster_timestamp: 1376720997863, }, attemptId: 1, }, id: 3, }, state: C_COMPLETE, diagnostics: "Container killed by the ApplicationMaster.\n\n", exit_status: 143, ] resource=<memory:1024, vCores:1> queue=default: capacity=1.0, absoluteCapacity=1.0, usedResources=<memory:48128, vCores:42>usedCapacity=0.9791667, absoluteUsedCapacity=0.9791667, numApps=5, numContainers=42 usedCapacity=0.9791667 absoluteUsedCapacity=0.9791667 used=<memory:48128, vCores:42> cluster=<memory:49152, vCores:96>
2013-08-17 06:42:28,195 INFO org.apache.hadoop.yarn.server.resourcemanager.scheduler.capacity.ParentQueue: completedContainer queue=root usedCapacity=0.9791667 absoluteUsedCapacity=0.9791667 used=<memory:48128, vCores:42> cluster=<memory:49152, vCores:96>
2013-08-17 06:42:28,195 INFO org.apache.hadoop.yarn.server.resourcemanager.scheduler.capacity.CapacityScheduler: Application appattempt_1376720997863_0007_000001 released container container_1376720997863_0007_01_000003 on node: host: hadoop-512-5:45082 #containers=6 available=1024 used=7168 with event: FINISHED
2013-08-17 06:42:28,195 INFO org.apache.hadoop.yarn.server.resourcemanager.rmcontainer.RMContainerImpl: container_1376720997863_0006_01_000020 Container Transitioned from NEW to ALLOCATED
2013-08-17 06:42:28,195 INFO org.apache.hadoop.yarn.server.resourcemanager.RMAuditLogger: USER=ubuntu	OPERATION=AM Allocated Container	TARGET=SchedulerApp	RESULT=SUCCESS	APPID=application_1376720997863_0006	CONTAINERID=container_1376720997863_0006_01_000020
2013-08-17 06:42:28,196 INFO org.apache.hadoop.yarn.server.resourcemanager.scheduler.common.fica.FiCaSchedulerNode: Assigned container container_1376720997863_0006_01_000020 of capacity <memory:1024, vCores:1> on host hadoop-512-5:45082, which currently has 7 containers, <memory:8192, vCores:7> used and <memory:0, vCores:9> available
2013-08-17 06:42:28,196 INFO org.apache.hadoop.yarn.server.resourcemanager.scheduler.capacity.LeafQueue: assignedContainer application=application_1376720997863_0006 container=Container: [ContainerId: container_1376720997863_0006_01_000020, NodeId: hadoop-512-5:45082, NodeHttpAddress: hadoop-512-5:8042, Resource: <memory:1024, vCores:1>, Priority: 20, State: NEW, Token: null, Status: container_id {, app_attempt_id {, application_id {, id: 6, cluster_timestamp: 1376720997863, }, attemptId: 1, }, id: 20, }, state: C_NEW, ] containerId=container_1376720997863_0006_01_000020 queue=default: capacity=1.0, absoluteCapacity=1.0, usedResources=<memory:48128, vCores:42>usedCapacity=0.9791667, absoluteUsedCapacity=0.9791667, numApps=5, numContainers=42 usedCapacity=0.9791667 absoluteUsedCapacity=0.9791667 used=<memory:48128, vCores:42> cluster=<memory:49152, vCores:96>
2013-08-17 06:42:28,197 INFO org.apache.hadoop.yarn.server.resourcemanager.scheduler.capacity.ParentQueue: Re-sorting queues since queue: root.default stats: default: capacity=1.0, absoluteCapacity=1.0, usedResources=<memory:49152, vCores:43>usedCapacity=1.0, absoluteUsedCapacity=1.0, numApps=5, numContainers=43
2013-08-17 06:42:28,197 INFO org.apache.hadoop.yarn.server.resourcemanager.scheduler.capacity.ParentQueue: assignedContainer queue=root usedCapacity=1.0 absoluteUsedCapacity=1.0 used=<memory:49152, vCores:43> cluster=<memory:49152, vCores:96>
2013-08-17 06:42:28,235 INFO org.apache.hadoop.yarn.server.resourcemanager.rmcontainer.RMContainerImpl: container_1376720997863_0006_01_000019 Container Transitioned from ACQUIRED to RUNNING
2013-08-17 06:42:28,519 INFO org.apache.hadoop.yarn.server.resourcemanager.rmcontainer.RMContainerImpl: container_1376720997863_0006_01_000020 Container Transitioned from ALLOCATED to ACQUIRED
2013-08-17 06:42:29,198 INFO org.apache.hadoop.yarn.server.resourcemanager.rmcontainer.RMContainerImpl: container_1376720997863_0006_01_000020 Container Transitioned from ACQUIRED to RUNNING
2013-08-17 06:42:32,520 INFO org.apache.hadoop.yarn.server.resourcemanager.rmcontainer.RMContainerImpl: container_1376720997863_0007_01_000011 Container Transitioned from RUNNING to COMPLETED
2013-08-17 06:42:32,520 INFO org.apache.hadoop.yarn.server.resourcemanager.scheduler.common.fica.FiCaSchedulerApp: Completed container: container_1376720997863_0007_01_000011 in state: COMPLETED event:FINISHED
2013-08-17 06:42:32,521 INFO org.apache.hadoop.yarn.server.resourcemanager.RMAuditLogger: USER=ubuntu	OPERATION=AM Released Container	TARGET=SchedulerApp	RESULT=SUCCESS	APPID=application_1376720997863_0007	CONTAINERID=container_1376720997863_0007_01_000011
2013-08-17 06:42:32,521 INFO org.apache.hadoop.yarn.server.resourcemanager.scheduler.common.fica.FiCaSchedulerNode: Released container container_1376720997863_0007_01_000011 of capacity <memory:1024, vCores:1> on host hadoop-512-4:45085, which currently has 6 containers, <memory:7168, vCores:6> used and <memory:1024, vCores:10> available, release resources=true
2013-08-17 06:42:32,521 INFO org.apache.hadoop.yarn.server.resourcemanager.scheduler.capacity.LeafQueue: default used=<memory:48128, vCores:42> numContainers=42 user=ubuntu user-resources=<memory:48128, vCores:42>
2013-08-17 06:42:32,522 INFO org.apache.hadoop.yarn.server.resourcemanager.scheduler.capacity.LeafQueue: completedContainer container=Container: [ContainerId: container_1376720997863_0007_01_000011, NodeId: hadoop-512-4:45085, NodeHttpAddress: hadoop-512-4:8042, Resource: <memory:1024, vCores:1>, Priority: 20, State: NEW, Token: null, Status: container_id {, app_attempt_id {, application_id {, id: 7, cluster_timestamp: 1376720997863, }, attemptId: 1, }, id: 11, }, state: C_COMPLETE, diagnostics: "Container killed by the ApplicationMaster.\n\n", exit_status: 143, ] resource=<memory:1024, vCores:1> queue=default: capacity=1.0, absoluteCapacity=1.0, usedResources=<memory:48128, vCores:42>usedCapacity=0.9791667, absoluteUsedCapacity=0.9791667, numApps=5, numContainers=42 usedCapacity=0.9791667 absoluteUsedCapacity=0.9791667 used=<memory:48128, vCores:42> cluster=<memory:49152, vCores:96>
2013-08-17 06:42:32,522 INFO org.apache.hadoop.yarn.server.resourcemanager.scheduler.capacity.ParentQueue: completedContainer queue=root usedCapacity=0.9791667 absoluteUsedCapacity=0.9791667 used=<memory:48128, vCores:42> cluster=<memory:49152, vCores:96>
2013-08-17 06:42:32,522 INFO org.apache.hadoop.yarn.server.resourcemanager.scheduler.capacity.CapacityScheduler: Application appattempt_1376720997863_0007_000001 released container container_1376720997863_0007_01_000011 on node: host: hadoop-512-4:45085 #containers=6 available=1024 used=7168 with event: FINISHED
2013-08-17 06:42:32,523 INFO org.apache.hadoop.yarn.server.resourcemanager.rmcontainer.RMContainerImpl: container_1376720997863_0006_01_000021 Container Transitioned from NEW to ALLOCATED
2013-08-17 06:42:32,523 INFO org.apache.hadoop.yarn.server.resourcemanager.RMAuditLogger: USER=ubuntu	OPERATION=AM Allocated Container	TARGET=SchedulerApp	RESULT=SUCCESS	APPID=application_1376720997863_0006	CONTAINERID=container_1376720997863_0006_01_000021
2013-08-17 06:42:32,523 INFO org.apache.hadoop.yarn.server.resourcemanager.scheduler.common.fica.FiCaSchedulerNode: Assigned container container_1376720997863_0006_01_000021 of capacity <memory:1024, vCores:1> on host hadoop-512-4:45085, which currently has 7 containers, <memory:8192, vCores:7> used and <memory:0, vCores:9> available
2013-08-17 06:42:32,524 INFO org.apache.hadoop.yarn.server.resourcemanager.scheduler.capacity.LeafQueue: assignedContainer application=application_1376720997863_0006 container=Container: [ContainerId: container_1376720997863_0006_01_000021, NodeId: hadoop-512-4:45085, NodeHttpAddress: hadoop-512-4:8042, Resource: <memory:1024, vCores:1>, Priority: 20, State: NEW, Token: null, Status: container_id {, app_attempt_id {, application_id {, id: 6, cluster_timestamp: 1376720997863, }, attemptId: 1, }, id: 21, }, state: C_NEW, ] containerId=container_1376720997863_0006_01_000021 queue=default: capacity=1.0, absoluteCapacity=1.0, usedResources=<memory:48128, vCores:42>usedCapacity=0.9791667, absoluteUsedCapacity=0.9791667, numApps=5, numContainers=42 usedCapacity=0.9791667 absoluteUsedCapacity=0.9791667 used=<memory:48128, vCores:42> cluster=<memory:49152, vCores:96>
2013-08-17 06:42:32,524 INFO org.apache.hadoop.yarn.server.resourcemanager.scheduler.capacity.ParentQueue: Re-sorting queues since queue: root.default stats: default: capacity=1.0, absoluteCapacity=1.0, usedResources=<memory:49152, vCores:43>usedCapacity=1.0, absoluteUsedCapacity=1.0, numApps=5, numContainers=43
2013-08-17 06:42:32,524 INFO org.apache.hadoop.yarn.server.resourcemanager.scheduler.capacity.ParentQueue: assignedContainer queue=root usedCapacity=1.0 absoluteUsedCapacity=1.0 used=<memory:49152, vCores:43> cluster=<memory:49152, vCores:96>
2013-08-17 06:42:32,538 INFO org.apache.hadoop.yarn.server.resourcemanager.rmcontainer.RMContainerImpl: container_1376720997863_0006_01_000021 Container Transitioned from ALLOCATED to ACQUIRED
2013-08-17 06:42:33,540 INFO org.apache.hadoop.yarn.server.resourcemanager.rmcontainer.RMContainerImpl: container_1376720997863_0006_01_000021 Container Transitioned from ACQUIRED to RUNNING
2013-08-17 06:42:34,860 INFO org.apache.hadoop.yarn.server.resourcemanager.rmcontainer.RMContainerImpl: container_1376720997863_0007_01_000005 Container Transitioned from RUNNING to COMPLETED
2013-08-17 06:42:34,860 INFO org.apache.hadoop.yarn.server.resourcemanager.scheduler.common.fica.FiCaSchedulerApp: Completed container: container_1376720997863_0007_01_000005 in state: COMPLETED event:FINISHED
2013-08-17 06:42:34,860 INFO org.apache.hadoop.yarn.server.resourcemanager.RMAuditLogger: USER=ubuntu	OPERATION=AM Released Container	TARGET=SchedulerApp	RESULT=SUCCESS	APPID=application_1376720997863_0007	CONTAINERID=container_1376720997863_0007_01_000005
2013-08-17 06:42:34,860 INFO org.apache.hadoop.yarn.server.resourcemanager.scheduler.common.fica.FiCaSchedulerNode: Released container container_1376720997863_0007_01_000005 of capacity <memory:1024, vCores:1> on host hadoop-512-5:45082, which currently has 6 containers, <memory:7168, vCores:6> used and <memory:1024, vCores:10> available, release resources=true
2013-08-17 06:42:34,860 INFO org.apache.hadoop.yarn.server.resourcemanager.scheduler.capacity.LeafQueue: default used=<memory:48128, vCores:42> numContainers=42 user=ubuntu user-resources=<memory:48128, vCores:42>
2013-08-17 06:42:34,861 INFO org.apache.hadoop.yarn.server.resourcemanager.scheduler.capacity.LeafQueue: completedContainer container=Container: [ContainerId: container_1376720997863_0007_01_000005, NodeId: hadoop-512-5:45082, NodeHttpAddress: hadoop-512-5:8042, Resource: <memory:1024, vCores:1>, Priority: 20, State: NEW, Token: null, Status: container_id {, app_attempt_id {, application_id {, id: 7, cluster_timestamp: 1376720997863, }, attemptId: 1, }, id: 5, }, state: C_COMPLETE, diagnostics: "Container killed by the ApplicationMaster.\n\n", exit_status: 143, ] resource=<memory:1024, vCores:1> queue=default: capacity=1.0, absoluteCapacity=1.0, usedResources=<memory:48128, vCores:42>usedCapacity=0.9791667, absoluteUsedCapacity=0.9791667, numApps=5, numContainers=42 usedCapacity=0.9791667 absoluteUsedCapacity=0.9791667 used=<memory:48128, vCores:42> cluster=<memory:49152, vCores:96>
2013-08-17 06:42:34,862 INFO org.apache.hadoop.yarn.server.resourcemanager.scheduler.capacity.ParentQueue: completedContainer queue=root usedCapacity=0.9791667 absoluteUsedCapacity=0.9791667 used=<memory:48128, vCores:42> cluster=<memory:49152, vCores:96>
2013-08-17 06:42:34,862 INFO org.apache.hadoop.yarn.server.resourcemanager.scheduler.capacity.CapacityScheduler: Application appattempt_1376720997863_0007_000001 released container container_1376720997863_0007_01_000005 on node: host: hadoop-512-5:45082 #containers=6 available=1024 used=7168 with event: FINISHED
2013-08-17 06:42:34,862 INFO org.apache.hadoop.yarn.server.resourcemanager.rmcontainer.RMContainerImpl: container_1376720997863_0006_01_000022 Container Transitioned from NEW to ALLOCATED
2013-08-17 06:42:34,862 INFO org.apache.hadoop.yarn.server.resourcemanager.RMAuditLogger: USER=ubuntu	OPERATION=AM Allocated Container	TARGET=SchedulerApp	RESULT=SUCCESS	APPID=application_1376720997863_0006	CONTAINERID=container_1376720997863_0006_01_000022
2013-08-17 06:42:34,862 INFO org.apache.hadoop.yarn.server.resourcemanager.scheduler.common.fica.FiCaSchedulerNode: Assigned container container_1376720997863_0006_01_000022 of capacity <memory:1024, vCores:1> on host hadoop-512-5:45082, which currently has 7 containers, <memory:8192, vCores:7> used and <memory:0, vCores:9> available
