2013-08-11 06:09:43,541 INFO org.apache.hadoop.yarn.server.resourcemanager.ResourceManager: STARTUP_MSG: 
/************************************************************
STARTUP_MSG: Starting ResourceManager
STARTUP_MSG:   host = hadoop-320-1/192.168.100.4
STARTUP_MSG:   args = []
STARTUP_MSG:   version = 3.0.0-SNAPSHOT
STARTUP_MSG:   build = https://github.com/lalithsuresh/hadoop-common -r 0cb423bd4868928bb06cd93f882bb0913172fd17; compiled by 'lsuresh' on 2013-04-08T15:47Z
STARTUP_MSG:   java = 1.7.0_17
************************************************************/
2013-08-11 06:09:43,557 INFO org.apache.hadoop.yarn.server.resourcemanager.ResourceManager: registered UNIX signal handlers for [TERM, HUP, INT]
2013-08-11 06:09:44,223 INFO org.apache.hadoop.yarn.server.resourcemanager.security.ApplicationTokenSecretManager: Rolling master-key for application-tokens
2013-08-11 06:09:44,250 INFO org.apache.hadoop.yarn.server.resourcemanager.security.RMContainerTokenSecretManager: ContainerTokenKeyRollingInterval: 86400000ms and ContainerTokenKeyActivationDelay: 900000ms
2013-08-11 06:09:44,252 INFO org.apache.hadoop.yarn.service.AbstractService: Service:Dispatcher is inited.
2013-08-11 06:09:44,254 INFO org.apache.hadoop.yarn.event.AsyncDispatcher: Registering class org.apache.hadoop.yarn.server.resourcemanager.recovery.RMStateStoreEventType for class org.apache.hadoop.yarn.server.resourcemanager.recovery.RMStateStore$ForwardingEventHandler
2013-08-11 06:09:44,254 INFO org.apache.hadoop.yarn.service.AbstractService: Service:Dispatcher is started.
2013-08-11 06:09:44,265 INFO org.apache.hadoop.yarn.event.AsyncDispatcher: Registering class org.apache.hadoop.yarn.server.resourcemanager.NodesListManagerEventType for class org.apache.hadoop.yarn.server.resourcemanager.NodesListManager
2013-08-11 06:09:44,265 INFO org.apache.hadoop.yarn.server.resourcemanager.ResourceManager: Using Scheduler: org.apache.hadoop.yarn.server.resourcemanager.scheduler.capacity.CapacityScheduler
2013-08-11 06:09:44,434 INFO org.apache.hadoop.yarn.event.AsyncDispatcher: Registering class org.apache.hadoop.yarn.server.resourcemanager.scheduler.event.SchedulerEventType for class org.apache.hadoop.yarn.server.resourcemanager.ResourceManager$SchedulerEventDispatcher
2013-08-11 06:09:44,436 INFO org.apache.hadoop.yarn.event.AsyncDispatcher: Registering class org.apache.hadoop.yarn.server.resourcemanager.rmapp.RMAppEventType for class org.apache.hadoop.yarn.server.resourcemanager.ResourceManager$ApplicationEventDispatcher
2013-08-11 06:09:44,437 INFO org.apache.hadoop.yarn.event.AsyncDispatcher: Registering class org.apache.hadoop.yarn.server.resourcemanager.rmapp.attempt.RMAppAttemptEventType for class org.apache.hadoop.yarn.server.resourcemanager.ResourceManager$ApplicationAttemptEventDispatcher
2013-08-11 06:09:44,439 INFO org.apache.hadoop.yarn.event.AsyncDispatcher: Registering class org.apache.hadoop.yarn.server.resourcemanager.rmnode.RMNodeEventType for class org.apache.hadoop.yarn.server.resourcemanager.ResourceManager$NodeEventDispatcher
2013-08-11 06:09:45,055 WARN org.apache.hadoop.util.NativeCodeLoader: Unable to load native-hadoop library for your platform... using builtin-java classes where applicable
2013-08-11 06:09:45,106 INFO org.apache.hadoop.yarn.server.resourcemanager.scheduler.capacity.ParentQueue: root, capacity=1.0, asboluteCapacity=1.0, maxCapacity=1.0, asboluteMaxCapacity=1.0, state=RUNNING, acls=ADMINISTER_QUEUE:*SUBMIT_APPLICATIONS:*
2013-08-11 06:09:45,106 INFO org.apache.hadoop.yarn.server.resourcemanager.scheduler.capacity.ParentQueue: Initialized parent-queue root name=root, fullname=root
2013-08-11 06:09:45,127 INFO org.apache.hadoop.yarn.server.resourcemanager.scheduler.capacity.LeafQueue: Initializing default
capacity = 1.0 [= (float) configuredCapacity / 100 ]
asboluteCapacity = 1.0 [= parentAbsoluteCapacity * capacity ]
maxCapacity = 1.0 [= configuredMaxCapacity ]
absoluteMaxCapacity = 1.0 [= 1.0 maximumCapacity undefined, (parentAbsoluteMaxCapacity * maximumCapacity) / 100 otherwise ]
userLimit = 100 [= configuredUserLimit ]
userLimitFactor = 1.0 [= configuredUserLimitFactor ]
maxApplications = 10000 [= configuredMaximumSystemApplicationsPerQueue or (int)(configuredMaximumSystemApplications * absoluteCapacity)]
maxApplicationsPerUser = 10000 [= (int)(maxApplications * (userLimit / 100.0f) * userLimitFactor) ]
maxActiveApplications = 1 [= max((int)ceil((clusterResourceMemory / minimumAllocation) * maxAMResourcePerQueuePercent * absoluteMaxCapacity),1) ]
maxActiveAppsUsingAbsCap = 1 [= max((int)ceil((clusterResourceMemory / minimumAllocation) *maxAMResourcePercent * absoluteCapacity),1) ]
maxActiveApplicationsPerUser = 1 [= max((int)(maxActiveApplications * (userLimit / 100.0f) * userLimitFactor),1) ]
usedCapacity = 0.0 [= usedResourcesMemory / (clusterResourceMemory * absoluteCapacity)]
absoluteUsedCapacity = 0.0 [= usedResourcesMemory / clusterResourceMemory]
maxAMResourcePerQueuePercent = 0.1 [= configuredMaximumAMResourcePercent ]
minimumAllocationFactor = 0.875 [= (float)(maximumAllocationMemory - minimumAllocationMemory) / maximumAllocationMemory ]
numContainers = 0 [= currentNumContainers ]
state = RUNNING [= configuredState ]
acls = ADMINISTER_QUEUE:*SUBMIT_APPLICATIONS:* [= configuredAcls ]

2013-08-11 06:09:45,128 INFO org.apache.hadoop.yarn.server.resourcemanager.scheduler.capacity.CapacityScheduler: Initialized queue: default: capacity=1.0, absoluteCapacity=1.0, usedResources=<memory:0, vCores:0>usedCapacity=0.0, absoluteUsedCapacity=0.0, numApps=0, numContainers=0
2013-08-11 06:09:45,128 INFO org.apache.hadoop.yarn.server.resourcemanager.scheduler.capacity.CapacityScheduler: Initialized queue: root: numChildQueue= 1, capacity=1.0, absoluteCapacity=1.0, usedResources=<memory:0, vCores:0>usedCapacity=0.0, numApps=0, numContainers=0
2013-08-11 06:09:45,128 INFO org.apache.hadoop.yarn.server.resourcemanager.scheduler.capacity.CapacityScheduler: Initialized root queue root: numChildQueue= 1, capacity=1.0, absoluteCapacity=1.0, usedResources=<memory:0, vCores:0>usedCapacity=0.0, numApps=0, numContainers=0
2013-08-11 06:09:45,128 INFO org.apache.hadoop.yarn.server.resourcemanager.scheduler.capacity.CapacityScheduler: Initialized CapacityScheduler with calculator=class org.apache.hadoop.yarn.server.resourcemanager.resource.DefaultResourceCalculator, minimumAllocation=<<memory:1024, vCores:1>>, maximumAllocation=<<memory:8192, vCores:32>>
2013-08-11 06:09:45,549 INFO org.apache.hadoop.yarn.event.AsyncDispatcher: Registering class org.apache.hadoop.yarn.server.resourcemanager.RMAppManagerEventType for class org.apache.hadoop.yarn.server.resourcemanager.RMAppManager
2013-08-11 06:09:45,569 INFO org.apache.hadoop.yarn.event.AsyncDispatcher: Registering class org.apache.hadoop.yarn.server.resourcemanager.amlauncher.AMLauncherEventType for class org.apache.hadoop.yarn.server.resourcemanager.amlauncher.ApplicationMasterLauncher
2013-08-11 06:09:45,657 INFO org.apache.hadoop.yarn.server.resourcemanager.RMNMInfo: Registered RMNMInfo MBean
2013-08-11 06:09:45,657 INFO org.apache.hadoop.yarn.service.AbstractService: Service:Dispatcher is inited.
2013-08-11 06:09:45,657 INFO org.apache.hadoop.yarn.service.AbstractService: Service:org.apache.hadoop.yarn.server.resourcemanager.rmcontainer.ContainerAllocationExpirer is inited.
2013-08-11 06:09:45,658 INFO org.apache.hadoop.yarn.service.AbstractService: Service:AMLivelinessMonitor is inited.
2013-08-11 06:09:45,658 INFO org.apache.hadoop.yarn.service.AbstractService: Service:AMLivelinessMonitor is inited.
2013-08-11 06:09:45,658 INFO org.apache.hadoop.yarn.service.AbstractService: Service:org.apache.hadoop.yarn.server.resourcemanager.security.DelegationTokenRenewer is inited.
2013-08-11 06:09:45,659 INFO org.apache.hadoop.util.HostsFileReader: Refreshing hosts (include/exclude) list
2013-08-11 06:09:45,659 INFO org.apache.hadoop.yarn.service.AbstractService: Service:org.apache.hadoop.yarn.server.resourcemanager.NodesListManager is inited.
2013-08-11 06:09:45,659 INFO org.apache.hadoop.yarn.service.AbstractService: Service:org.apache.hadoop.yarn.server.resourcemanager.ResourceManager$SchedulerEventDispatcher is inited.
2013-08-11 06:09:45,659 INFO org.apache.hadoop.yarn.service.AbstractService: Service:NMLivelinessMonitor is inited.
2013-08-11 06:09:45,665 INFO org.apache.hadoop.yarn.service.AbstractService: Service:org.apache.hadoop.yarn.server.resourcemanager.ResourceTrackerService is inited.
2013-08-11 06:09:45,665 INFO org.apache.hadoop.yarn.service.AbstractService: Service:org.apache.hadoop.yarn.server.resourcemanager.ApplicationMasterService is inited.
2013-08-11 06:09:45,666 INFO org.apache.hadoop.yarn.service.AbstractService: Service:org.apache.hadoop.yarn.server.resourcemanager.ClientRMService is inited.
2013-08-11 06:09:45,666 INFO org.apache.hadoop.yarn.service.AbstractService: Service:org.apache.hadoop.yarn.server.resourcemanager.AdminService is inited.
2013-08-11 06:09:45,666 INFO org.apache.hadoop.yarn.service.AbstractService: Service:org.apache.hadoop.yarn.server.resourcemanager.amlauncher.ApplicationMasterLauncher is inited.
2013-08-11 06:09:45,666 INFO org.apache.hadoop.yarn.service.AbstractService: Service:ResourceManager is inited.
2013-08-11 06:09:45,666 INFO org.apache.hadoop.yarn.server.resourcemanager.security.RMContainerTokenSecretManager: Rolling master-key for container-tokens
2013-08-11 06:09:45,666 INFO org.apache.hadoop.yarn.server.resourcemanager.security.ApplicationTokenSecretManager: Rolling master-key for application-tokens
2013-08-11 06:09:45,787 INFO org.mortbay.log: Logging to org.slf4j.impl.Log4jLoggerAdapter(org.mortbay.log) via org.mortbay.log.Slf4jLog
2013-08-11 06:09:45,861 INFO org.apache.hadoop.http.HttpServer: Added global filter 'safety' (class=org.apache.hadoop.http.HttpServer$QuotingInputFilter)
2013-08-11 06:09:45,864 INFO org.apache.hadoop.http.HttpServer: Added filter static_user_filter (class=org.apache.hadoop.http.lib.StaticUserWebFilter$StaticUserFilter) to context cluster
2013-08-11 06:09:45,864 INFO org.apache.hadoop.http.HttpServer: Added filter static_user_filter (class=org.apache.hadoop.http.lib.StaticUserWebFilter$StaticUserFilter) to context static
2013-08-11 06:09:45,865 INFO org.apache.hadoop.http.HttpServer: Added filter static_user_filter (class=org.apache.hadoop.http.lib.StaticUserWebFilter$StaticUserFilter) to context logs
2013-08-11 06:09:45,870 INFO org.apache.hadoop.http.HttpServer: adding path spec: /cluster
2013-08-11 06:09:45,870 INFO org.apache.hadoop.http.HttpServer: adding path spec: /cluster/*
2013-08-11 06:09:45,870 INFO org.apache.hadoop.http.HttpServer: adding path spec: /ws
2013-08-11 06:09:45,871 INFO org.apache.hadoop.http.HttpServer: adding path spec: /ws/*
2013-08-11 06:09:45,873 INFO org.apache.hadoop.http.HttpServer: Added global filter 'guice' (class=com.google.inject.servlet.GuiceFilter)
2013-08-11 06:09:45,880 INFO org.apache.hadoop.http.HttpServer: Jetty bound to port 8088
2013-08-11 06:09:45,880 INFO org.mortbay.log: jetty-6.1.26
2013-08-11 06:09:45,919 INFO org.mortbay.log: Extract jar:file:/home/ubuntu/hadoop-3.0.0-SNAPSHOT/share/hadoop/yarn/hadoop-yarn-common-3.0.0-SNAPSHOT.jar!/webapps/cluster to /tmp/Jetty_0_0_0_0_8088_cluster____u0rgz3/webapp
2013-08-11 06:09:46,331 INFO org.mortbay.log: Started SelectChannelConnector@0.0.0.0:8088
2013-08-11 06:09:46,331 INFO org.apache.hadoop.yarn.webapp.WebApps: Web app /cluster started at 8088
2013-08-11 06:09:47,184 INFO org.apache.hadoop.yarn.webapp.WebApps: Registered webapp guice modules
2013-08-11 06:09:47,292 INFO org.apache.hadoop.metrics2.impl.MetricsConfig: loaded properties from hadoop-metrics2.properties
2013-08-11 06:09:47,326 INFO org.apache.hadoop.metrics2.impl.MetricsSystemImpl: Scheduled snapshot period at 10 second(s).
2013-08-11 06:09:47,326 INFO org.apache.hadoop.metrics2.impl.MetricsSystemImpl: ResourceManager metrics system started
2013-08-11 06:09:47,340 INFO org.apache.hadoop.security.token.delegation.AbstractDelegationTokenSecretManager: Updating the current master key for generating delegation tokens
2013-08-11 06:09:47,343 INFO org.apache.hadoop.yarn.service.AbstractService: Service:Dispatcher is started.
2013-08-11 06:09:47,344 INFO org.apache.hadoop.security.token.delegation.AbstractDelegationTokenSecretManager: Starting expired delegation token remover thread, tokenRemoverScanInterval=60 min(s)
2013-08-11 06:09:47,344 INFO org.apache.hadoop.security.token.delegation.AbstractDelegationTokenSecretManager: Updating the current master key for generating delegation tokens
2013-08-11 06:09:47,346 INFO org.apache.hadoop.yarn.service.AbstractService: Service:org.apache.hadoop.yarn.server.resourcemanager.rmcontainer.ContainerAllocationExpirer is started.
2013-08-11 06:09:47,346 INFO org.apache.hadoop.yarn.service.AbstractService: Service:AMLivelinessMonitor is started.
2013-08-11 06:09:47,347 INFO org.apache.hadoop.yarn.service.AbstractService: Service:AMLivelinessMonitor is started.
2013-08-11 06:09:47,347 INFO org.apache.hadoop.yarn.service.AbstractService: Service:org.apache.hadoop.yarn.server.resourcemanager.security.DelegationTokenRenewer is started.
2013-08-11 06:09:47,348 INFO org.apache.hadoop.yarn.service.AbstractService: Service:org.apache.hadoop.yarn.server.resourcemanager.NodesListManager is started.
2013-08-11 06:09:47,349 INFO org.apache.hadoop.yarn.service.AbstractService: Service:org.apache.hadoop.yarn.server.resourcemanager.ResourceManager$SchedulerEventDispatcher is started.
2013-08-11 06:09:47,349 INFO org.apache.hadoop.yarn.service.AbstractService: Service:NMLivelinessMonitor is started.
2013-08-11 06:09:47,349 INFO org.apache.hadoop.yarn.service.AbstractService: Service:org.apache.hadoop.yarn.server.resourcemanager.ResourceTrackerService is started.
2013-08-11 06:09:47,419 INFO org.apache.hadoop.ipc.Server: Starting Socket Reader #1 for port 54110
2013-08-11 06:09:47,459 INFO org.apache.hadoop.yarn.factories.impl.pb.RpcServerFactoryPBImpl: Adding protocol org.apache.hadoop.yarn.server.api.ResourceTrackerPB to the server
2013-08-11 06:09:47,460 INFO org.apache.hadoop.ipc.Server: IPC Server Responder: starting
2013-08-11 06:09:47,462 INFO org.apache.hadoop.ipc.Server: IPC Server listener on 54110: starting
2013-08-11 06:09:47,591 INFO org.apache.hadoop.ipc.Server: Starting Socket Reader #1 for port 54112
2013-08-11 06:09:47,608 INFO org.apache.hadoop.yarn.factories.impl.pb.RpcServerFactoryPBImpl: Adding protocol org.apache.hadoop.yarn.api.AMRMProtocolPB to the server
2013-08-11 06:09:47,611 INFO org.apache.hadoop.ipc.Server: IPC Server listener on 54112: starting
2013-08-11 06:09:47,611 INFO org.apache.hadoop.ipc.Server: IPC Server Responder: starting
2013-08-11 06:09:47,657 INFO org.apache.hadoop.yarn.service.AbstractService: Service:org.apache.hadoop.yarn.server.resourcemanager.ApplicationMasterService is started.
2013-08-11 06:09:47,709 INFO org.apache.hadoop.ipc.Server: Starting Socket Reader #1 for port 54111
2013-08-11 06:09:47,716 INFO org.apache.hadoop.yarn.factories.impl.pb.RpcServerFactoryPBImpl: Adding protocol org.apache.hadoop.yarn.api.ClientRMProtocolPB to the server
2013-08-11 06:09:47,717 INFO org.apache.hadoop.ipc.Server: IPC Server Responder: starting
2013-08-11 06:09:47,723 INFO org.apache.hadoop.ipc.Server: IPC Server listener on 54111: starting
2013-08-11 06:09:47,762 INFO org.apache.hadoop.yarn.service.AbstractService: Service:org.apache.hadoop.yarn.server.resourcemanager.ClientRMService is started.
2013-08-11 06:09:47,799 INFO org.apache.hadoop.ipc.Server: Starting Socket Reader #1 for port 8033
2013-08-11 06:09:47,805 INFO org.apache.hadoop.yarn.factories.impl.pb.RpcServerFactoryPBImpl: Adding protocol org.apache.hadoop.yarn.api.RMAdminProtocolPB to the server
2013-08-11 06:09:47,807 INFO org.apache.hadoop.ipc.Server: IPC Server Responder: starting
2013-08-11 06:09:47,807 INFO org.apache.hadoop.ipc.Server: IPC Server listener on 8033: starting
2013-08-11 06:09:47,808 INFO org.apache.hadoop.yarn.service.AbstractService: Service:org.apache.hadoop.yarn.server.resourcemanager.AdminService is started.
2013-08-11 06:09:47,809 INFO org.apache.hadoop.yarn.service.AbstractService: Service:org.apache.hadoop.yarn.server.resourcemanager.amlauncher.ApplicationMasterLauncher is started.
2013-08-11 06:09:47,819 INFO org.apache.hadoop.yarn.service.AbstractService: Service:ResourceManager is started.
2013-08-11 06:09:57,321 INFO org.apache.hadoop.yarn.util.RackResolver: Resolved hadoop-320-7 to /default-rack
2013-08-11 06:09:57,326 INFO org.apache.hadoop.yarn.server.resourcemanager.ResourceTrackerService: NodeManager from node hadoop-320-7(cmPort: 37753 httpPort: 8042) registered with capability: <memory:8192, vCores:16>, assigned nodeId hadoop-320-7:37753
2013-08-11 06:09:57,344 INFO org.apache.hadoop.yarn.server.resourcemanager.rmnode.RMNodeImpl: hadoop-320-7:37753 Node Transitioned from NEW to RUNNING
2013-08-11 06:09:57,346 INFO org.apache.hadoop.yarn.server.resourcemanager.scheduler.capacity.CapacityScheduler: Added node hadoop-320-7:37753 clusterResource: <memory:8192, vCores:16>
2013-08-11 06:09:57,391 INFO org.apache.hadoop.yarn.util.RackResolver: Resolved hadoop-320-5 to /default-rack
2013-08-11 06:09:57,391 INFO org.apache.hadoop.yarn.server.resourcemanager.ResourceTrackerService: NodeManager from node hadoop-320-5(cmPort: 32992 httpPort: 8042) registered with capability: <memory:8192, vCores:16>, assigned nodeId hadoop-320-5:32992
2013-08-11 06:09:57,392 INFO org.apache.hadoop.yarn.server.resourcemanager.rmnode.RMNodeImpl: hadoop-320-5:32992 Node Transitioned from NEW to RUNNING
2013-08-11 06:09:57,392 INFO org.apache.hadoop.yarn.server.resourcemanager.scheduler.capacity.CapacityScheduler: Added node hadoop-320-5:32992 clusterResource: <memory:16384, vCores:32>
2013-08-11 06:09:57,523 INFO org.apache.hadoop.yarn.util.RackResolver: Resolved hadoop-320-6 to /default-rack
2013-08-11 06:09:57,524 INFO org.apache.hadoop.yarn.server.resourcemanager.ResourceTrackerService: NodeManager from node hadoop-320-6(cmPort: 35360 httpPort: 8042) registered with capability: <memory:8192, vCores:16>, assigned nodeId hadoop-320-6:35360
2013-08-11 06:09:57,524 INFO org.apache.hadoop.yarn.server.resourcemanager.rmnode.RMNodeImpl: hadoop-320-6:35360 Node Transitioned from NEW to RUNNING
2013-08-11 06:09:57,524 INFO org.apache.hadoop.yarn.server.resourcemanager.scheduler.capacity.CapacityScheduler: Added node hadoop-320-6:35360 clusterResource: <memory:24576, vCores:48>
2013-08-11 06:09:57,742 INFO org.apache.hadoop.yarn.util.RackResolver: Resolved hadoop-320-2 to /default-rack
2013-08-11 06:09:57,743 INFO org.apache.hadoop.yarn.server.resourcemanager.ResourceTrackerService: NodeManager from node hadoop-320-2(cmPort: 40354 httpPort: 8042) registered with capability: <memory:8192, vCores:16>, assigned nodeId hadoop-320-2:40354
2013-08-11 06:09:57,743 INFO org.apache.hadoop.yarn.server.resourcemanager.rmnode.RMNodeImpl: hadoop-320-2:40354 Node Transitioned from NEW to RUNNING
2013-08-11 06:09:57,743 INFO org.apache.hadoop.yarn.server.resourcemanager.scheduler.capacity.CapacityScheduler: Added node hadoop-320-2:40354 clusterResource: <memory:32768, vCores:64>
2013-08-11 06:09:57,747 INFO org.apache.hadoop.yarn.util.RackResolver: Resolved hadoop-320-4 to /default-rack
2013-08-11 06:09:57,747 INFO org.apache.hadoop.yarn.server.resourcemanager.ResourceTrackerService: NodeManager from node hadoop-320-4(cmPort: 46709 httpPort: 8042) registered with capability: <memory:8192, vCores:16>, assigned nodeId hadoop-320-4:46709
2013-08-11 06:09:57,748 INFO org.apache.hadoop.yarn.server.resourcemanager.rmnode.RMNodeImpl: hadoop-320-4:46709 Node Transitioned from NEW to RUNNING
2013-08-11 06:09:57,748 INFO org.apache.hadoop.yarn.server.resourcemanager.scheduler.capacity.CapacityScheduler: Added node hadoop-320-4:46709 clusterResource: <memory:40960, vCores:80>
2013-08-11 06:09:57,784 INFO org.apache.hadoop.yarn.util.RackResolver: Resolved hadoop-320-3 to /default-rack
2013-08-11 06:09:57,785 INFO org.apache.hadoop.yarn.server.resourcemanager.ResourceTrackerService: NodeManager from node hadoop-320-3(cmPort: 36899 httpPort: 8042) registered with capability: <memory:8192, vCores:16>, assigned nodeId hadoop-320-3:36899
2013-08-11 06:09:57,785 INFO org.apache.hadoop.yarn.server.resourcemanager.rmnode.RMNodeImpl: hadoop-320-3:36899 Node Transitioned from NEW to RUNNING
2013-08-11 06:09:57,786 INFO org.apache.hadoop.yarn.server.resourcemanager.scheduler.capacity.CapacityScheduler: Added node hadoop-320-3:36899 clusterResource: <memory:49152, vCores:96>
2013-08-11 06:10:04,190 INFO org.apache.hadoop.yarn.server.resourcemanager.ClientRMService: Allocated new applicationId: 1
2013-08-11 06:10:07,674 INFO org.apache.hadoop.yarn.server.resourcemanager.ClientRMService: Storing Application with id application_1376201383303_0001
2013-08-11 06:10:07,677 INFO org.apache.hadoop.yarn.server.resourcemanager.recovery.RMStateStore: Storing info for app: application_1376201383303_0001
2013-08-11 06:10:07,677 INFO org.apache.hadoop.yarn.server.resourcemanager.ClientRMService: Application with id 1 submitted by user ubuntu
2013-08-11 06:10:07,680 INFO org.apache.hadoop.yarn.server.resourcemanager.RMAuditLogger: USER=ubuntu	IP=192.168.100.4	OPERATION=Submit Application Request	TARGET=ClientRMService	RESULT=SUCCESS	APPID=application_1376201383303_0001
2013-08-11 06:10:07,727 INFO org.apache.hadoop.yarn.server.resourcemanager.rmapp.RMAppImpl: application_1376201383303_0001 State change from NEW to SUBMITTED
2013-08-11 06:10:07,728 INFO org.apache.hadoop.yarn.server.resourcemanager.ApplicationMasterService: Registering appattempt_1376201383303_0001_000001
2013-08-11 06:10:07,730 INFO org.apache.hadoop.yarn.server.resourcemanager.rmapp.attempt.RMAppAttemptImpl: appattempt_1376201383303_0001_000001 State change from NEW to SUBMITTED
2013-08-11 06:10:07,763 INFO org.apache.hadoop.yarn.server.resourcemanager.scheduler.capacity.LeafQueue: Application application_1376201383303_0001 from user: ubuntu activated in queue: default
2013-08-11 06:10:07,763 INFO org.apache.hadoop.yarn.server.resourcemanager.scheduler.capacity.LeafQueue: Application added - appId: application_1376201383303_0001 user: org.apache.hadoop.yarn.server.resourcemanager.scheduler.capacity.LeafQueue$User@7606a33b, leaf-queue: default #user-pending-applications: 0 #user-active-applications: 1 #queue-pending-applications: 0 #queue-active-applications: 1
2013-08-11 06:10:07,763 INFO org.apache.hadoop.yarn.server.resourcemanager.scheduler.capacity.ParentQueue: Application added - appId: application_1376201383303_0001 user: ubuntu leaf-queue of parent: root #applications: 1
2013-08-11 06:10:07,764 INFO org.apache.hadoop.yarn.server.resourcemanager.scheduler.capacity.CapacityScheduler: Application Submission: appattempt_1376201383303_0001_000001, user: ubuntu queue: default: capacity=1.0, absoluteCapacity=1.0, usedResources=<memory:0, vCores:0>usedCapacity=0.0, absoluteUsedCapacity=0.0, numApps=1, numContainers=0, currently active: 1
2013-08-11 06:10:07,770 INFO org.apache.hadoop.yarn.server.resourcemanager.rmapp.attempt.RMAppAttemptImpl: appattempt_1376201383303_0001_000001 State change from SUBMITTED to SCHEDULED
2013-08-11 06:10:07,770 INFO org.apache.hadoop.yarn.server.resourcemanager.rmapp.RMAppImpl: application_1376201383303_0001 State change from SUBMITTED to ACCEPTED
2013-08-11 06:10:07,871 INFO org.apache.hadoop.yarn.server.resourcemanager.rmcontainer.RMContainerImpl: container_1376201383303_0001_01_000001 Container Transitioned from NEW to ALLOCATED
2013-08-11 06:10:07,872 INFO org.apache.hadoop.yarn.server.resourcemanager.RMAuditLogger: USER=ubuntu	OPERATION=AM Allocated Container	TARGET=SchedulerApp	RESULT=SUCCESS	APPID=application_1376201383303_0001	CONTAINERID=container_1376201383303_0001_01_000001
2013-08-11 06:10:07,873 INFO org.apache.hadoop.yarn.server.resourcemanager.scheduler.common.fica.FiCaSchedulerNode: Assigned container container_1376201383303_0001_01_000001 of capacity <memory:2048, vCores:1> on host hadoop-320-2:40354, which currently has 1 containers, <memory:2048, vCores:1> used and <memory:6144, vCores:15> available
2013-08-11 06:10:07,879 INFO org.apache.hadoop.yarn.server.resourcemanager.scheduler.capacity.LeafQueue: assignedContainer application=application_1376201383303_0001 container=Container: [ContainerId: container_1376201383303_0001_01_000001, NodeId: hadoop-320-2:40354, NodeHttpAddress: hadoop-320-2:8042, Resource: <memory:2048, vCores:1>, Priority: 0, State: NEW, Token: null, Status: container_id {, app_attempt_id {, application_id {, id: 1, cluster_timestamp: 1376201383303, }, attemptId: 1, }, id: 1, }, state: C_NEW, ] containerId=container_1376201383303_0001_01_000001 queue=default: capacity=1.0, absoluteCapacity=1.0, usedResources=<memory:0, vCores:0>usedCapacity=0.0, absoluteUsedCapacity=0.0, numApps=1, numContainers=0 usedCapacity=0.0 absoluteUsedCapacity=0.0 used=<memory:0, vCores:0> cluster=<memory:49152, vCores:96>
2013-08-11 06:10:07,880 INFO org.apache.hadoop.yarn.server.resourcemanager.scheduler.capacity.ParentQueue: Re-sorting queues since queue: root.default stats: default: capacity=1.0, absoluteCapacity=1.0, usedResources=<memory:2048, vCores:1>usedCapacity=0.041666668, absoluteUsedCapacity=0.041666668, numApps=1, numContainers=1
2013-08-11 06:10:07,881 INFO org.apache.hadoop.yarn.server.resourcemanager.scheduler.capacity.ParentQueue: assignedContainer queue=root usedCapacity=0.041666668 absoluteUsedCapacity=0.041666668 used=<memory:2048, vCores:1> cluster=<memory:49152, vCores:96>
2013-08-11 06:10:07,883 INFO org.apache.hadoop.yarn.server.resourcemanager.rmcontainer.RMContainerImpl: container_1376201383303_0001_01_000001 Container Transitioned from ALLOCATED to ACQUIRED
2013-08-11 06:10:07,885 INFO org.apache.hadoop.yarn.server.resourcemanager.rmapp.attempt.RMAppAttemptImpl: Storing attempt: AppId: application_1376201383303_0001 AttemptId: appattempt_1376201383303_0001_000001 MasterContainer: Container: [ContainerId: container_1376201383303_0001_01_000001, NodeId: hadoop-320-2:40354, NodeHttpAddress: hadoop-320-2:8042, Resource: <memory:2048, vCores:1>, Priority: 0, State: NEW, Token: null, Status: container_id {, app_attempt_id {, application_id {, id: 1, cluster_timestamp: 1376201383303, }, attemptId: 1, }, id: 1, }, state: C_NEW, ]
2013-08-11 06:10:07,892 INFO org.apache.hadoop.yarn.server.resourcemanager.rmapp.attempt.RMAppAttemptImpl: appattempt_1376201383303_0001_000001 State change from SCHEDULED to ALLOCATED_SAVING
2013-08-11 06:10:07,896 INFO org.apache.hadoop.yarn.server.resourcemanager.recovery.RMStateStore: Storing info for attempt: appattempt_1376201383303_0001_000001
2013-08-11 06:10:07,899 INFO org.apache.hadoop.yarn.server.resourcemanager.rmapp.attempt.RMAppAttemptImpl: appattempt_1376201383303_0001_000001 State change from ALLOCATED_SAVING to ALLOCATED
2013-08-11 06:10:07,908 INFO org.apache.hadoop.yarn.server.resourcemanager.amlauncher.AMLauncher: Launching masterappattempt_1376201383303_0001_000001
2013-08-11 06:10:07,951 INFO org.apache.hadoop.yarn.server.resourcemanager.amlauncher.AMLauncher: Setting up container Container: [ContainerId: container_1376201383303_0001_01_000001, NodeId: hadoop-320-2:40354, NodeHttpAddress: hadoop-320-2:8042, Resource: <memory:2048, vCores:1>, Priority: 0, State: NEW, Token: null, Status: container_id {, app_attempt_id {, application_id {, id: 1, cluster_timestamp: 1376201383303, }, attemptId: 1, }, id: 1, }, state: C_NEW, ] for AM appattempt_1376201383303_0001_000001
2013-08-11 06:10:07,951 INFO org.apache.hadoop.yarn.server.resourcemanager.amlauncher.AMLauncher: Command to launch container container_1376201383303_0001_01_000001 : $JAVA_HOME/bin/java -Dlog4j.configuration=container-log4j.properties -Dyarn.app.mapreduce.container.log.dir=<LOG_DIR> -Dyarn.app.mapreduce.container.log.filesize=0 -Dhadoop.root.logger=INFO,CLA  -Xmx1024m org.apache.hadoop.mapreduce.v2.app.MRAppMaster 1><LOG_DIR>/stdout 2><LOG_DIR>/stderr 
2013-08-11 06:10:08,845 INFO org.apache.hadoop.yarn.server.resourcemanager.amlauncher.AMLauncher: Done launching container Container: [ContainerId: container_1376201383303_0001_01_000001, NodeId: hadoop-320-2:40354, NodeHttpAddress: hadoop-320-2:8042, Resource: <memory:2048, vCores:1>, Priority: 0, State: NEW, Token: null, Status: container_id {, app_attempt_id {, application_id {, id: 1, cluster_timestamp: 1376201383303, }, attemptId: 1, }, id: 1, }, state: C_NEW, ] for AM appattempt_1376201383303_0001_000001
2013-08-11 06:10:08,846 INFO org.apache.hadoop.yarn.server.resourcemanager.rmapp.attempt.RMAppAttemptImpl: appattempt_1376201383303_0001_000001 State change from ALLOCATED to LAUNCHED
2013-08-11 06:10:08,871 INFO org.apache.hadoop.yarn.server.resourcemanager.rmcontainer.RMContainerImpl: container_1376201383303_0001_01_000001 Container Transitioned from ACQUIRED to RUNNING
2013-08-11 06:10:17,626 INFO org.apache.hadoop.yarn.server.resourcemanager.ApplicationMasterService: AM registration appattempt_1376201383303_0001_000001
2013-08-11 06:10:17,628 INFO org.apache.hadoop.yarn.server.resourcemanager.RMAuditLogger: USER=ubuntu	IP=192.168.100.9	OPERATION=Register App Master	TARGET=ApplicationMasterService	RESULT=SUCCESS	APPID=application_1376201383303_0001	APPATTEMPTID=appattempt_1376201383303_0001_000001
2013-08-11 06:10:17,633 INFO org.apache.hadoop.yarn.server.resourcemanager.rmapp.attempt.RMAppAttemptImpl: appattempt_1376201383303_0001_000001 State change from LAUNCHED to RUNNING
2013-08-11 06:10:17,634 INFO org.apache.hadoop.yarn.server.resourcemanager.rmapp.RMAppImpl: application_1376201383303_0001 State change from ACCEPTED to RUNNING
2013-08-11 06:10:18,686 INFO org.apache.hadoop.yarn.server.resourcemanager.rmcontainer.RMContainerImpl: container_1376201383303_0001_01_000002 Container Transitioned from NEW to ALLOCATED
2013-08-11 06:10:18,686 INFO org.apache.hadoop.yarn.server.resourcemanager.RMAuditLogger: USER=ubuntu	OPERATION=AM Allocated Container	TARGET=SchedulerApp	RESULT=SUCCESS	APPID=application_1376201383303_0001	CONTAINERID=container_1376201383303_0001_01_000002
2013-08-11 06:10:18,686 INFO org.apache.hadoop.yarn.server.resourcemanager.scheduler.common.fica.FiCaSchedulerNode: Assigned container container_1376201383303_0001_01_000002 of capacity <memory:1024, vCores:1> on host hadoop-320-6:35360, which currently has 1 containers, <memory:1024, vCores:1> used and <memory:7168, vCores:15> available
2013-08-11 06:10:18,688 INFO org.apache.hadoop.yarn.server.resourcemanager.scheduler.capacity.LeafQueue: assignedContainer application=application_1376201383303_0001 container=Container: [ContainerId: container_1376201383303_0001_01_000002, NodeId: hadoop-320-6:35360, NodeHttpAddress: hadoop-320-6:8042, Resource: <memory:1024, vCores:1>, Priority: 20, State: NEW, Token: null, Status: container_id {, app_attempt_id {, application_id {, id: 1, cluster_timestamp: 1376201383303, }, attemptId: 1, }, id: 2, }, state: C_NEW, ] containerId=container_1376201383303_0001_01_000002 queue=default: capacity=1.0, absoluteCapacity=1.0, usedResources=<memory:2048, vCores:1>usedCapacity=0.041666668, absoluteUsedCapacity=0.041666668, numApps=1, numContainers=1 usedCapacity=0.041666668 absoluteUsedCapacity=0.041666668 used=<memory:2048, vCores:1> cluster=<memory:49152, vCores:96>
2013-08-11 06:10:18,688 INFO org.apache.hadoop.yarn.server.resourcemanager.scheduler.capacity.ParentQueue: Re-sorting queues since queue: root.default stats: default: capacity=1.0, absoluteCapacity=1.0, usedResources=<memory:3072, vCores:2>usedCapacity=0.0625, absoluteUsedCapacity=0.0625, numApps=1, numContainers=2
2013-08-11 06:10:18,689 INFO org.apache.hadoop.yarn.server.resourcemanager.scheduler.capacity.ParentQueue: assignedContainer queue=root usedCapacity=0.0625 absoluteUsedCapacity=0.0625 used=<memory:3072, vCores:2> cluster=<memory:49152, vCores:96>
2013-08-11 06:10:18,907 INFO org.apache.hadoop.yarn.server.resourcemanager.rmcontainer.RMContainerImpl: container_1376201383303_0001_01_000003 Container Transitioned from NEW to ALLOCATED
2013-08-11 06:10:18,907 INFO org.apache.hadoop.yarn.server.resourcemanager.RMAuditLogger: USER=ubuntu	OPERATION=AM Allocated Container	TARGET=SchedulerApp	RESULT=SUCCESS	APPID=application_1376201383303_0001	CONTAINERID=container_1376201383303_0001_01_000003
2013-08-11 06:10:18,907 INFO org.apache.hadoop.yarn.server.resourcemanager.scheduler.common.fica.FiCaSchedulerNode: Assigned container container_1376201383303_0001_01_000003 of capacity <memory:1024, vCores:1> on host hadoop-320-4:46709, which currently has 1 containers, <memory:1024, vCores:1> used and <memory:7168, vCores:15> available
2013-08-11 06:10:18,909 INFO org.apache.hadoop.yarn.server.resourcemanager.scheduler.capacity.LeafQueue: assignedContainer application=application_1376201383303_0001 container=Container: [ContainerId: container_1376201383303_0001_01_000003, NodeId: hadoop-320-4:46709, NodeHttpAddress: hadoop-320-4:8042, Resource: <memory:1024, vCores:1>, Priority: 20, State: NEW, Token: null, Status: container_id {, app_attempt_id {, application_id {, id: 1, cluster_timestamp: 1376201383303, }, attemptId: 1, }, id: 3, }, state: C_NEW, ] containerId=container_1376201383303_0001_01_000003 queue=default: capacity=1.0, absoluteCapacity=1.0, usedResources=<memory:3072, vCores:2>usedCapacity=0.0625, absoluteUsedCapacity=0.0625, numApps=1, numContainers=2 usedCapacity=0.0625 absoluteUsedCapacity=0.0625 used=<memory:3072, vCores:2> cluster=<memory:49152, vCores:96>
2013-08-11 06:10:18,909 INFO org.apache.hadoop.yarn.server.resourcemanager.scheduler.capacity.ParentQueue: Re-sorting queues since queue: root.default stats: default: capacity=1.0, absoluteCapacity=1.0, usedResources=<memory:4096, vCores:3>usedCapacity=0.083333336, absoluteUsedCapacity=0.083333336, numApps=1, numContainers=3
2013-08-11 06:10:18,909 INFO org.apache.hadoop.yarn.server.resourcemanager.scheduler.capacity.ParentQueue: assignedContainer queue=root usedCapacity=0.083333336 absoluteUsedCapacity=0.083333336 used=<memory:4096, vCores:3> cluster=<memory:49152, vCores:96>
2013-08-11 06:10:19,697 INFO org.apache.hadoop.yarn.server.resourcemanager.rmcontainer.RMContainerImpl: container_1376201383303_0001_01_000002 Container Transitioned from ALLOCATED to ACQUIRED
2013-08-11 06:10:19,698 INFO org.apache.hadoop.yarn.server.resourcemanager.rmcontainer.RMContainerImpl: container_1376201383303_0001_01_000003 Container Transitioned from ALLOCATED to ACQUIRED
2013-08-11 06:10:20,733 INFO org.apache.hadoop.yarn.server.resourcemanager.scheduler.AppSchedulingInfo: checking for deactivate... 
2013-08-11 06:10:21,074 INFO org.apache.hadoop.yarn.server.resourcemanager.rmcontainer.RMContainerImpl: container_1376201383303_0001_01_000003 Container Transitioned from ACQUIRED to RUNNING
2013-08-11 06:10:21,725 INFO org.apache.hadoop.yarn.server.resourcemanager.rmcontainer.RMContainerImpl: container_1376201383303_0001_01_000002 Container Transitioned from ACQUIRED to RUNNING
2013-08-11 06:13:22,741 INFO org.apache.hadoop.yarn.server.resourcemanager.rmcontainer.RMContainerImpl: container_1376201383303_0001_01_000002 Container Transitioned from RUNNING to COMPLETED
2013-08-11 06:13:22,741 INFO org.apache.hadoop.yarn.server.resourcemanager.scheduler.common.fica.FiCaSchedulerApp: Completed container: container_1376201383303_0001_01_000002 in state: COMPLETED event:FINISHED
2013-08-11 06:13:22,741 INFO org.apache.hadoop.yarn.server.resourcemanager.RMAuditLogger: USER=ubuntu	OPERATION=AM Released Container	TARGET=SchedulerApp	RESULT=SUCCESS	APPID=application_1376201383303_0001	CONTAINERID=container_1376201383303_0001_01_000002
2013-08-11 06:13:22,742 INFO org.apache.hadoop.yarn.server.resourcemanager.scheduler.common.fica.FiCaSchedulerNode: Released container container_1376201383303_0001_01_000002 of capacity <memory:1024, vCores:1> on host hadoop-320-6:35360, which currently has 0 containers, <memory:0, vCores:0> used and <memory:8192, vCores:16> available, release resources=true
2013-08-11 06:13:22,742 INFO org.apache.hadoop.yarn.server.resourcemanager.scheduler.capacity.LeafQueue: default used=<memory:3072, vCores:2> numContainers=2 user=ubuntu user-resources=<memory:3072, vCores:2>
2013-08-11 06:13:22,745 INFO org.apache.hadoop.yarn.server.resourcemanager.scheduler.capacity.LeafQueue: completedContainer container=Container: [ContainerId: container_1376201383303_0001_01_000002, NodeId: hadoop-320-6:35360, NodeHttpAddress: hadoop-320-6:8042, Resource: <memory:1024, vCores:1>, Priority: 20, State: NEW, Token: null, Status: container_id {, app_attempt_id {, application_id {, id: 1, cluster_timestamp: 1376201383303, }, attemptId: 1, }, id: 2, }, state: C_COMPLETE, diagnostics: "Container killed by the ApplicationMaster.\n\n", exit_status: 143, ] resource=<memory:1024, vCores:1> queue=default: capacity=1.0, absoluteCapacity=1.0, usedResources=<memory:3072, vCores:2>usedCapacity=0.0625, absoluteUsedCapacity=0.0625, numApps=1, numContainers=2 usedCapacity=0.0625 absoluteUsedCapacity=0.0625 used=<memory:3072, vCores:2> cluster=<memory:49152, vCores:96>
2013-08-11 06:13:22,745 INFO org.apache.hadoop.yarn.server.resourcemanager.scheduler.capacity.ParentQueue: completedContainer queue=root usedCapacity=0.0625 absoluteUsedCapacity=0.0625 used=<memory:3072, vCores:2> cluster=<memory:49152, vCores:96>
2013-08-11 06:13:22,745 INFO org.apache.hadoop.yarn.server.resourcemanager.scheduler.capacity.CapacityScheduler: Application appattempt_1376201383303_0001_000001 released container container_1376201383303_0001_01_000002 on node: host: hadoop-320-6:35360 #containers=0 available=8192 used=0 with event: FINISHED
2013-08-11 06:13:23,566 INFO org.apache.hadoop.yarn.server.resourcemanager.rmcontainer.RMContainerImpl: container_1376201383303_0001_01_000003 Container Transitioned from RUNNING to COMPLETED
2013-08-11 06:13:23,567 INFO org.apache.hadoop.yarn.server.resourcemanager.scheduler.common.fica.FiCaSchedulerApp: Completed container: container_1376201383303_0001_01_000003 in state: COMPLETED event:FINISHED
2013-08-11 06:13:23,567 INFO org.apache.hadoop.yarn.server.resourcemanager.RMAuditLogger: USER=ubuntu	OPERATION=AM Released Container	TARGET=SchedulerApp	RESULT=SUCCESS	APPID=application_1376201383303_0001	CONTAINERID=container_1376201383303_0001_01_000003
2013-08-11 06:13:23,567 INFO org.apache.hadoop.yarn.server.resourcemanager.scheduler.common.fica.FiCaSchedulerNode: Released container container_1376201383303_0001_01_000003 of capacity <memory:1024, vCores:1> on host hadoop-320-4:46709, which currently has 0 containers, <memory:0, vCores:0> used and <memory:8192, vCores:16> available, release resources=true
2013-08-11 06:13:23,567 INFO org.apache.hadoop.yarn.server.resourcemanager.scheduler.capacity.LeafQueue: default used=<memory:2048, vCores:1> numContainers=1 user=ubuntu user-resources=<memory:2048, vCores:1>
2013-08-11 06:13:23,569 INFO org.apache.hadoop.yarn.server.resourcemanager.scheduler.capacity.LeafQueue: completedContainer container=Container: [ContainerId: container_1376201383303_0001_01_000003, NodeId: hadoop-320-4:46709, NodeHttpAddress: hadoop-320-4:8042, Resource: <memory:1024, vCores:1>, Priority: 20, State: NEW, Token: null, Status: container_id {, app_attempt_id {, application_id {, id: 1, cluster_timestamp: 1376201383303, }, attemptId: 1, }, id: 3, }, state: C_COMPLETE, diagnostics: "Container killed by the ApplicationMaster.\n\n", exit_status: 143, ] resource=<memory:1024, vCores:1> queue=default: capacity=1.0, absoluteCapacity=1.0, usedResources=<memory:2048, vCores:1>usedCapacity=0.041666668, absoluteUsedCapacity=0.041666668, numApps=1, numContainers=1 usedCapacity=0.041666668 absoluteUsedCapacity=0.041666668 used=<memory:2048, vCores:1> cluster=<memory:49152, vCores:96>
2013-08-11 06:13:23,569 INFO org.apache.hadoop.yarn.server.resourcemanager.scheduler.capacity.ParentQueue: completedContainer queue=root usedCapacity=0.041666668 absoluteUsedCapacity=0.041666668 used=<memory:2048, vCores:1> cluster=<memory:49152, vCores:96>
2013-08-11 06:13:23,570 INFO org.apache.hadoop.yarn.server.resourcemanager.scheduler.capacity.CapacityScheduler: Application appattempt_1376201383303_0001_000001 released container container_1376201383303_0001_01_000003 on node: host: hadoop-320-4:46709 #containers=0 available=8192 used=0 with event: FINISHED
2013-08-11 06:13:27,748 INFO org.apache.hadoop.yarn.server.resourcemanager.rmapp.attempt.RMAppAttemptImpl: appattempt_1376201383303_0001_000001 State change from RUNNING to FINISHING
2013-08-11 06:13:27,749 INFO org.apache.hadoop.yarn.server.resourcemanager.rmapp.RMAppImpl: application_1376201383303_0001 State change from RUNNING to FINISHING
2013-08-11 06:13:27,994 INFO org.apache.hadoop.yarn.server.resourcemanager.rmcontainer.RMContainerImpl: container_1376201383303_0001_01_000001 Container Transitioned from RUNNING to COMPLETED
2013-08-11 06:13:27,995 INFO org.apache.hadoop.yarn.server.resourcemanager.scheduler.common.fica.FiCaSchedulerApp: Completed container: container_1376201383303_0001_01_000001 in state: COMPLETED event:FINISHED
2013-08-11 06:13:27,995 INFO org.apache.hadoop.yarn.server.resourcemanager.RMAuditLogger: USER=ubuntu	OPERATION=AM Released Container	TARGET=SchedulerApp	RESULT=SUCCESS	APPID=application_1376201383303_0001	CONTAINERID=container_1376201383303_0001_01_000001
2013-08-11 06:13:27,995 INFO org.apache.hadoop.yarn.server.resourcemanager.scheduler.common.fica.FiCaSchedulerNode: Released container container_1376201383303_0001_01_000001 of capacity <memory:2048, vCores:1> on host hadoop-320-2:40354, which currently has 0 containers, <memory:0, vCores:0> used and <memory:8192, vCores:16> available, release resources=true
2013-08-11 06:13:27,995 INFO org.apache.hadoop.yarn.server.resourcemanager.scheduler.capacity.LeafQueue: default used=<memory:0, vCores:0> numContainers=0 user=ubuntu user-resources=<memory:0, vCores:0>
2013-08-11 06:13:27,997 INFO org.apache.hadoop.yarn.server.resourcemanager.scheduler.capacity.LeafQueue: completedContainer container=Container: [ContainerId: container_1376201383303_0001_01_000001, NodeId: hadoop-320-2:40354, NodeHttpAddress: hadoop-320-2:8042, Resource: <memory:2048, vCores:1>, Priority: 0, State: NEW, Token: null, Status: container_id {, app_attempt_id {, application_id {, id: 1, cluster_timestamp: 1376201383303, }, attemptId: 1, }, id: 1, }, state: C_COMPLETE, diagnostics: "", exit_status: 0, ] resource=<memory:2048, vCores:1> queue=default: capacity=1.0, absoluteCapacity=1.0, usedResources=<memory:0, vCores:0>usedCapacity=0.0, absoluteUsedCapacity=0.0, numApps=1, numContainers=0 usedCapacity=0.0 absoluteUsedCapacity=0.0 used=<memory:0, vCores:0> cluster=<memory:49152, vCores:96>
2013-08-11 06:13:27,997 INFO org.apache.hadoop.yarn.server.resourcemanager.rmapp.attempt.RMAppAttemptImpl: appattempt_1376201383303_0001_000001 State change from FINISHING to FINISHED
2013-08-11 06:13:27,997 INFO org.apache.hadoop.yarn.server.resourcemanager.scheduler.capacity.ParentQueue: completedContainer queue=root usedCapacity=0.0 absoluteUsedCapacity=0.0 used=<memory:0, vCores:0> cluster=<memory:49152, vCores:96>
2013-08-11 06:13:27,999 INFO org.apache.hadoop.yarn.server.resourcemanager.scheduler.capacity.CapacityScheduler: Application appattempt_1376201383303_0001_000001 released container container_1376201383303_0001_01_000001 on node: host: hadoop-320-2:40354 #containers=0 available=8192 used=0 with event: FINISHED
2013-08-11 06:13:28,001 INFO org.apache.hadoop.yarn.server.resourcemanager.rmapp.RMAppImpl: application_1376201383303_0001 State change from FINISHING to FINISHED
2013-08-11 06:13:28,001 INFO org.apache.hadoop.yarn.server.resourcemanager.scheduler.capacity.CapacityScheduler: Application appattempt_1376201383303_0001_000001 is done. finalState=FINISHED
2013-08-11 06:13:28,002 INFO org.apache.hadoop.yarn.server.resourcemanager.RMAuditLogger: USER=ubuntu	OPERATION=Application Finished - Succeeded	TARGET=RMAppManager	RESULT=SUCCESS	APPID=application_1376201383303_0001
2013-08-11 06:13:28,002 INFO org.apache.hadoop.yarn.server.resourcemanager.amlauncher.AMLauncher: Cleaning master appattempt_1376201383303_0001_000001
2013-08-11 06:13:28,005 INFO org.apache.hadoop.yarn.server.resourcemanager.scheduler.AppSchedulingInfo: Application application_1376201383303_0001 requests cleared
2013-08-11 06:13:28,007 INFO org.apache.hadoop.yarn.server.resourcemanager.scheduler.capacity.LeafQueue: Application removed - appId: application_1376201383303_0001 user: ubuntu queue: default #user-pending-applications: 0 #user-active-applications: 0 #queue-pending-applications: 0 #queue-active-applications: 0
2013-08-11 06:13:28,007 INFO org.apache.hadoop.yarn.server.resourcemanager.scheduler.capacity.ParentQueue: Application removed - appId: application_1376201383303_0001 user: ubuntu leaf-queue of parent: root #applications: 0
2013-08-11 06:13:28,011 INFO org.apache.hadoop.yarn.server.resourcemanager.recovery.RMStateStore: Removing info for app: application_1376201383303_0001
2013-08-11 06:13:28,014 INFO org.apache.hadoop.yarn.server.resourcemanager.RMAppManager$ApplicationSummary: appId=application_1376201383303_0001,name=TeraGen,user=ubuntu,queue=default,state=FINISHED,trackingUrl=hadoop-320-1.novalocal:8088/proxy/application_1376201383303_0001/jobhistory/job/job_1376201383303_0001,appMasterHost=hadoop-320-2,startTime=1376201407667,finishTime=1376201607749
2013-08-11 06:13:28,127 INFO org.apache.hadoop.yarn.server.resourcemanager.ClientRMService: Allocated new applicationId: 2
2013-08-11 06:13:30,102 INFO org.apache.hadoop.yarn.server.resourcemanager.ClientRMService: Storing Application with id application_1376201383303_0002
2013-08-11 06:13:30,103 INFO org.apache.hadoop.yarn.server.resourcemanager.recovery.RMStateStore: Storing info for app: application_1376201383303_0002
2013-08-11 06:13:30,103 INFO org.apache.hadoop.yarn.server.resourcemanager.ClientRMService: Application with id 2 submitted by user ubuntu
2013-08-11 06:13:30,103 INFO org.apache.hadoop.yarn.server.resourcemanager.RMAuditLogger: USER=ubuntu	IP=192.168.100.4	OPERATION=Submit Application Request	TARGET=ClientRMService	RESULT=SUCCESS	APPID=application_1376201383303_0002
2013-08-11 06:13:30,105 INFO org.apache.hadoop.yarn.server.resourcemanager.rmapp.RMAppImpl: application_1376201383303_0002 State change from NEW to SUBMITTED
2013-08-11 06:13:30,106 INFO org.apache.hadoop.yarn.server.resourcemanager.ApplicationMasterService: Registering appattempt_1376201383303_0002_000001
2013-08-11 06:13:30,106 INFO org.apache.hadoop.yarn.server.resourcemanager.rmapp.attempt.RMAppAttemptImpl: appattempt_1376201383303_0002_000001 State change from NEW to SUBMITTED
2013-08-11 06:13:30,106 INFO org.apache.hadoop.yarn.server.resourcemanager.scheduler.capacity.LeafQueue: Application application_1376201383303_0002 from user: ubuntu activated in queue: default
2013-08-11 06:13:30,106 INFO org.apache.hadoop.yarn.server.resourcemanager.scheduler.capacity.LeafQueue: Application added - appId: application_1376201383303_0002 user: org.apache.hadoop.yarn.server.resourcemanager.scheduler.capacity.LeafQueue$User@44a359b1, leaf-queue: default #user-pending-applications: 0 #user-active-applications: 1 #queue-pending-applications: 0 #queue-active-applications: 1
2013-08-11 06:13:30,107 INFO org.apache.hadoop.yarn.server.resourcemanager.scheduler.capacity.ParentQueue: Application added - appId: application_1376201383303_0002 user: ubuntu leaf-queue of parent: root #applications: 1
2013-08-11 06:13:30,107 INFO org.apache.hadoop.yarn.server.resourcemanager.scheduler.capacity.CapacityScheduler: Application Submission: appattempt_1376201383303_0002_000001, user: ubuntu queue: default: capacity=1.0, absoluteCapacity=1.0, usedResources=<memory:0, vCores:0>usedCapacity=0.0, absoluteUsedCapacity=0.0, numApps=1, numContainers=0, currently active: 1
2013-08-11 06:13:30,107 INFO org.apache.hadoop.yarn.server.resourcemanager.rmapp.attempt.RMAppAttemptImpl: appattempt_1376201383303_0002_000001 State change from SUBMITTED to SCHEDULED
2013-08-11 06:13:30,108 INFO org.apache.hadoop.yarn.server.resourcemanager.rmapp.RMAppImpl: application_1376201383303_0002 State change from SUBMITTED to ACCEPTED
2013-08-11 06:13:30,380 INFO org.apache.hadoop.yarn.server.resourcemanager.rmcontainer.RMContainerImpl: container_1376201383303_0002_01_000001 Container Transitioned from NEW to ALLOCATED
2013-08-11 06:13:30,381 INFO org.apache.hadoop.yarn.server.resourcemanager.RMAuditLogger: USER=ubuntu	OPERATION=AM Allocated Container	TARGET=SchedulerApp	RESULT=SUCCESS	APPID=application_1376201383303_0002	CONTAINERID=container_1376201383303_0002_01_000001
2013-08-11 06:13:30,381 INFO org.apache.hadoop.yarn.server.resourcemanager.scheduler.common.fica.FiCaSchedulerNode: Assigned container container_1376201383303_0002_01_000001 of capacity <memory:2048, vCores:1> on host hadoop-320-7:37753, which currently has 1 containers, <memory:2048, vCores:1> used and <memory:6144, vCores:15> available
2013-08-11 06:13:30,383 INFO org.apache.hadoop.yarn.server.resourcemanager.scheduler.capacity.LeafQueue: assignedContainer application=application_1376201383303_0002 container=Container: [ContainerId: container_1376201383303_0002_01_000001, NodeId: hadoop-320-7:37753, NodeHttpAddress: hadoop-320-7:8042, Resource: <memory:2048, vCores:1>, Priority: 0, State: NEW, Token: null, Status: container_id {, app_attempt_id {, application_id {, id: 2, cluster_timestamp: 1376201383303, }, attemptId: 1, }, id: 1, }, state: C_NEW, ] containerId=container_1376201383303_0002_01_000001 queue=default: capacity=1.0, absoluteCapacity=1.0, usedResources=<memory:0, vCores:0>usedCapacity=0.0, absoluteUsedCapacity=0.0, numApps=1, numContainers=0 usedCapacity=0.0 absoluteUsedCapacity=0.0 used=<memory:0, vCores:0> cluster=<memory:49152, vCores:96>
2013-08-11 06:13:30,383 INFO org.apache.hadoop.yarn.server.resourcemanager.scheduler.capacity.ParentQueue: Re-sorting queues since queue: root.default stats: default: capacity=1.0, absoluteCapacity=1.0, usedResources=<memory:2048, vCores:1>usedCapacity=0.041666668, absoluteUsedCapacity=0.041666668, numApps=1, numContainers=1
2013-08-11 06:13:30,384 INFO org.apache.hadoop.yarn.server.resourcemanager.scheduler.capacity.ParentQueue: assignedContainer queue=root usedCapacity=0.041666668 absoluteUsedCapacity=0.041666668 used=<memory:2048, vCores:1> cluster=<memory:49152, vCores:96>
2013-08-11 06:13:30,385 INFO org.apache.hadoop.yarn.server.resourcemanager.rmcontainer.RMContainerImpl: container_1376201383303_0002_01_000001 Container Transitioned from ALLOCATED to ACQUIRED
2013-08-11 06:13:30,387 INFO org.apache.hadoop.yarn.server.resourcemanager.rmapp.attempt.RMAppAttemptImpl: Storing attempt: AppId: application_1376201383303_0002 AttemptId: appattempt_1376201383303_0002_000001 MasterContainer: Container: [ContainerId: container_1376201383303_0002_01_000001, NodeId: hadoop-320-7:37753, NodeHttpAddress: hadoop-320-7:8042, Resource: <memory:2048, vCores:1>, Priority: 0, State: NEW, Token: null, Status: container_id {, app_attempt_id {, application_id {, id: 2, cluster_timestamp: 1376201383303, }, attemptId: 1, }, id: 1, }, state: C_NEW, ]
2013-08-11 06:13:30,387 INFO org.apache.hadoop.yarn.server.resourcemanager.rmapp.attempt.RMAppAttemptImpl: appattempt_1376201383303_0002_000001 State change from SCHEDULED to ALLOCATED_SAVING
2013-08-11 06:13:30,387 INFO org.apache.hadoop.yarn.server.resourcemanager.recovery.RMStateStore: Storing info for attempt: appattempt_1376201383303_0002_000001
2013-08-11 06:13:30,388 INFO org.apache.hadoop.yarn.server.resourcemanager.rmapp.attempt.RMAppAttemptImpl: appattempt_1376201383303_0002_000001 State change from ALLOCATED_SAVING to ALLOCATED
2013-08-11 06:13:30,424 INFO org.apache.hadoop.yarn.server.resourcemanager.amlauncher.AMLauncher: Launching masterappattempt_1376201383303_0002_000001
2013-08-11 06:13:30,427 INFO org.apache.hadoop.yarn.server.resourcemanager.amlauncher.AMLauncher: Setting up container Container: [ContainerId: container_1376201383303_0002_01_000001, NodeId: hadoop-320-7:37753, NodeHttpAddress: hadoop-320-7:8042, Resource: <memory:2048, vCores:1>, Priority: 0, State: NEW, Token: null, Status: container_id {, app_attempt_id {, application_id {, id: 2, cluster_timestamp: 1376201383303, }, attemptId: 1, }, id: 1, }, state: C_NEW, ] for AM appattempt_1376201383303_0002_000001
2013-08-11 06:13:30,428 INFO org.apache.hadoop.yarn.server.resourcemanager.amlauncher.AMLauncher: Command to launch container container_1376201383303_0002_01_000001 : $JAVA_HOME/bin/java -Dlog4j.configuration=container-log4j.properties -Dyarn.app.mapreduce.container.log.dir=<LOG_DIR> -Dyarn.app.mapreduce.container.log.filesize=0 -Dhadoop.root.logger=INFO,CLA  -Xmx1024m org.apache.hadoop.mapreduce.v2.app.MRAppMaster 1><LOG_DIR>/stdout 2><LOG_DIR>/stderr 
2013-08-11 06:13:31,271 INFO org.apache.hadoop.yarn.server.resourcemanager.amlauncher.AMLauncher: Done launching container Container: [ContainerId: container_1376201383303_0002_01_000001, NodeId: hadoop-320-7:37753, NodeHttpAddress: hadoop-320-7:8042, Resource: <memory:2048, vCores:1>, Priority: 0, State: NEW, Token: null, Status: container_id {, app_attempt_id {, application_id {, id: 2, cluster_timestamp: 1376201383303, }, attemptId: 1, }, id: 1, }, state: C_NEW, ] for AM appattempt_1376201383303_0002_000001
2013-08-11 06:13:31,271 INFO org.apache.hadoop.yarn.server.resourcemanager.rmapp.attempt.RMAppAttemptImpl: appattempt_1376201383303_0002_000001 State change from ALLOCATED to LAUNCHED
2013-08-11 06:13:31,570 INFO org.apache.hadoop.yarn.server.resourcemanager.rmcontainer.RMContainerImpl: container_1376201383303_0002_01_000001 Container Transitioned from ACQUIRED to RUNNING
2013-08-11 06:13:40,823 INFO org.apache.hadoop.yarn.server.resourcemanager.ApplicationMasterService: AM registration appattempt_1376201383303_0002_000001
2013-08-11 06:13:40,824 INFO org.apache.hadoop.yarn.server.resourcemanager.RMAuditLogger: USER=ubuntu	IP=192.168.100.34	OPERATION=Register App Master	TARGET=ApplicationMasterService	RESULT=SUCCESS	APPID=application_1376201383303_0002	APPATTEMPTID=appattempt_1376201383303_0002_000001
2013-08-11 06:13:40,826 INFO org.apache.hadoop.yarn.server.resourcemanager.rmapp.attempt.RMAppAttemptImpl: appattempt_1376201383303_0002_000001 State change from LAUNCHED to RUNNING
2013-08-11 06:13:40,826 INFO org.apache.hadoop.yarn.server.resourcemanager.rmapp.RMAppImpl: application_1376201383303_0002 State change from ACCEPTED to RUNNING
2013-08-11 06:13:42,033 INFO org.apache.hadoop.yarn.server.resourcemanager.rmcontainer.RMContainerImpl: container_1376201383303_0002_01_000002 Container Transitioned from NEW to ALLOCATED
2013-08-11 06:13:42,033 INFO org.apache.hadoop.yarn.server.resourcemanager.RMAuditLogger: USER=ubuntu	OPERATION=AM Allocated Container	TARGET=SchedulerApp	RESULT=SUCCESS	APPID=application_1376201383303_0002	CONTAINERID=container_1376201383303_0002_01_000002
2013-08-11 06:13:42,033 INFO org.apache.hadoop.yarn.server.resourcemanager.scheduler.common.fica.FiCaSchedulerNode: Assigned container container_1376201383303_0002_01_000002 of capacity <memory:1024, vCores:1> on host hadoop-320-3:36899, which currently has 1 containers, <memory:1024, vCores:1> used and <memory:7168, vCores:15> available
2013-08-11 06:13:42,035 INFO org.apache.hadoop.yarn.server.resourcemanager.scheduler.capacity.LeafQueue: assignedContainer application=application_1376201383303_0002 container=Container: [ContainerId: container_1376201383303_0002_01_000002, NodeId: hadoop-320-3:36899, NodeHttpAddress: hadoop-320-3:8042, Resource: <memory:1024, vCores:1>, Priority: 20, State: NEW, Token: null, Status: container_id {, app_attempt_id {, application_id {, id: 2, cluster_timestamp: 1376201383303, }, attemptId: 1, }, id: 2, }, state: C_NEW, ] containerId=container_1376201383303_0002_01_000002 queue=default: capacity=1.0, absoluteCapacity=1.0, usedResources=<memory:2048, vCores:1>usedCapacity=0.041666668, absoluteUsedCapacity=0.041666668, numApps=1, numContainers=1 usedCapacity=0.041666668 absoluteUsedCapacity=0.041666668 used=<memory:2048, vCores:1> cluster=<memory:49152, vCores:96>
2013-08-11 06:13:42,035 INFO org.apache.hadoop.yarn.server.resourcemanager.scheduler.capacity.ParentQueue: Re-sorting queues since queue: root.default stats: default: capacity=1.0, absoluteCapacity=1.0, usedResources=<memory:3072, vCores:2>usedCapacity=0.0625, absoluteUsedCapacity=0.0625, numApps=1, numContainers=2
2013-08-11 06:13:42,036 INFO org.apache.hadoop.yarn.server.resourcemanager.scheduler.capacity.ParentQueue: assignedContainer queue=root usedCapacity=0.0625 absoluteUsedCapacity=0.0625 used=<memory:3072, vCores:2> cluster=<memory:49152, vCores:96>
2013-08-11 06:13:42,048 INFO org.apache.hadoop.yarn.server.resourcemanager.rmcontainer.RMContainerImpl: container_1376201383303_0002_01_000003 Container Transitioned from NEW to ALLOCATED
2013-08-11 06:13:42,049 INFO org.apache.hadoop.yarn.server.resourcemanager.RMAuditLogger: USER=ubuntu	OPERATION=AM Allocated Container	TARGET=SchedulerApp	RESULT=SUCCESS	APPID=application_1376201383303_0002	CONTAINERID=container_1376201383303_0002_01_000003
2013-08-11 06:13:42,049 INFO org.apache.hadoop.yarn.server.resourcemanager.scheduler.common.fica.FiCaSchedulerNode: Assigned container container_1376201383303_0002_01_000003 of capacity <memory:1024, vCores:1> on host hadoop-320-2:40354, which currently has 1 containers, <memory:1024, vCores:1> used and <memory:7168, vCores:15> available
2013-08-11 06:13:42,050 INFO org.apache.hadoop.yarn.server.resourcemanager.scheduler.capacity.LeafQueue: assignedContainer application=application_1376201383303_0002 container=Container: [ContainerId: container_1376201383303_0002_01_000003, NodeId: hadoop-320-2:40354, NodeHttpAddress: hadoop-320-2:8042, Resource: <memory:1024, vCores:1>, Priority: 20, State: NEW, Token: null, Status: container_id {, app_attempt_id {, application_id {, id: 2, cluster_timestamp: 1376201383303, }, attemptId: 1, }, id: 3, }, state: C_NEW, ] containerId=container_1376201383303_0002_01_000003 queue=default: capacity=1.0, absoluteCapacity=1.0, usedResources=<memory:3072, vCores:2>usedCapacity=0.0625, absoluteUsedCapacity=0.0625, numApps=1, numContainers=2 usedCapacity=0.0625 absoluteUsedCapacity=0.0625 used=<memory:3072, vCores:2> cluster=<memory:49152, vCores:96>
2013-08-11 06:13:42,051 INFO org.apache.hadoop.yarn.server.resourcemanager.scheduler.capacity.ParentQueue: Re-sorting queues since queue: root.default stats: default: capacity=1.0, absoluteCapacity=1.0, usedResources=<memory:4096, vCores:3>usedCapacity=0.083333336, absoluteUsedCapacity=0.083333336, numApps=1, numContainers=3
2013-08-11 06:13:42,051 INFO org.apache.hadoop.yarn.server.resourcemanager.scheduler.capacity.ParentQueue: assignedContainer queue=root usedCapacity=0.083333336 absoluteUsedCapacity=0.083333336 used=<memory:4096, vCores:3> cluster=<memory:49152, vCores:96>
2013-08-11 06:13:42,880 INFO org.apache.hadoop.yarn.server.resourcemanager.rmcontainer.RMContainerImpl: container_1376201383303_0002_01_000002 Container Transitioned from ALLOCATED to ACQUIRED
2013-08-11 06:13:42,882 INFO org.apache.hadoop.yarn.server.resourcemanager.rmcontainer.RMContainerImpl: container_1376201383303_0002_01_000003 Container Transitioned from ALLOCATED to ACQUIRED
2013-08-11 06:13:43,911 INFO org.apache.hadoop.yarn.server.resourcemanager.scheduler.AppSchedulingInfo: checking for deactivate... 
2013-08-11 06:13:44,067 INFO org.apache.hadoop.yarn.server.resourcemanager.rmcontainer.RMContainerImpl: container_1376201383303_0002_01_000002 Container Transitioned from ACQUIRED to RUNNING
2013-08-11 06:13:44,112 INFO org.apache.hadoop.yarn.server.resourcemanager.rmcontainer.RMContainerImpl: container_1376201383303_0002_01_000003 Container Transitioned from ACQUIRED to RUNNING
2013-08-11 06:16:24,038 INFO org.apache.hadoop.yarn.server.resourcemanager.rmcontainer.RMContainerImpl: container_1376201383303_0002_01_000002 Container Transitioned from RUNNING to COMPLETED
2013-08-11 06:16:24,038 INFO org.apache.hadoop.yarn.server.resourcemanager.scheduler.common.fica.FiCaSchedulerApp: Completed container: container_1376201383303_0002_01_000002 in state: COMPLETED event:FINISHED
2013-08-11 06:16:24,038 INFO org.apache.hadoop.yarn.server.resourcemanager.RMAuditLogger: USER=ubuntu	OPERATION=AM Released Container	TARGET=SchedulerApp	RESULT=SUCCESS	APPID=application_1376201383303_0002	CONTAINERID=container_1376201383303_0002_01_000002
2013-08-11 06:16:24,039 INFO org.apache.hadoop.yarn.server.resourcemanager.scheduler.common.fica.FiCaSchedulerNode: Released container container_1376201383303_0002_01_000002 of capacity <memory:1024, vCores:1> on host hadoop-320-3:36899, which currently has 0 containers, <memory:0, vCores:0> used and <memory:8192, vCores:16> available, release resources=true
2013-08-11 06:16:24,039 INFO org.apache.hadoop.yarn.server.resourcemanager.scheduler.capacity.LeafQueue: default used=<memory:3072, vCores:2> numContainers=2 user=ubuntu user-resources=<memory:3072, vCores:2>
2013-08-11 06:16:24,052 INFO org.apache.hadoop.yarn.server.resourcemanager.scheduler.capacity.LeafQueue: completedContainer container=Container: [ContainerId: container_1376201383303_0002_01_000002, NodeId: hadoop-320-3:36899, NodeHttpAddress: hadoop-320-3:8042, Resource: <memory:1024, vCores:1>, Priority: 20, State: NEW, Token: null, Status: container_id {, app_attempt_id {, application_id {, id: 2, cluster_timestamp: 1376201383303, }, attemptId: 1, }, id: 2, }, state: C_COMPLETE, diagnostics: "Container killed by the ApplicationMaster.\n\n", exit_status: 143, ] resource=<memory:1024, vCores:1> queue=default: capacity=1.0, absoluteCapacity=1.0, usedResources=<memory:3072, vCores:2>usedCapacity=0.0625, absoluteUsedCapacity=0.0625, numApps=1, numContainers=2 usedCapacity=0.0625 absoluteUsedCapacity=0.0625 used=<memory:3072, vCores:2> cluster=<memory:49152, vCores:96>
2013-08-11 06:16:24,052 INFO org.apache.hadoop.yarn.server.resourcemanager.scheduler.capacity.ParentQueue: completedContainer queue=root usedCapacity=0.0625 absoluteUsedCapacity=0.0625 used=<memory:3072, vCores:2> cluster=<memory:49152, vCores:96>
2013-08-11 06:16:24,052 INFO org.apache.hadoop.yarn.server.resourcemanager.scheduler.capacity.CapacityScheduler: Application appattempt_1376201383303_0002_000001 released container container_1376201383303_0002_01_000002 on node: host: hadoop-320-3:36899 #containers=0 available=8192 used=0 with event: FINISHED
2013-08-11 06:16:36,175 INFO org.apache.hadoop.yarn.server.resourcemanager.rmcontainer.RMContainerImpl: container_1376201383303_0002_01_000003 Container Transitioned from RUNNING to COMPLETED
2013-08-11 06:16:36,175 INFO org.apache.hadoop.yarn.server.resourcemanager.scheduler.common.fica.FiCaSchedulerApp: Completed container: container_1376201383303_0002_01_000003 in state: COMPLETED event:FINISHED
2013-08-11 06:16:36,175 INFO org.apache.hadoop.yarn.server.resourcemanager.RMAuditLogger: USER=ubuntu	OPERATION=AM Released Container	TARGET=SchedulerApp	RESULT=SUCCESS	APPID=application_1376201383303_0002	CONTAINERID=container_1376201383303_0002_01_000003
2013-08-11 06:16:36,176 INFO org.apache.hadoop.yarn.server.resourcemanager.scheduler.common.fica.FiCaSchedulerNode: Released container container_1376201383303_0002_01_000003 of capacity <memory:1024, vCores:1> on host hadoop-320-2:40354, which currently has 0 containers, <memory:0, vCores:0> used and <memory:8192, vCores:16> available, release resources=true
2013-08-11 06:16:36,176 INFO org.apache.hadoop.yarn.server.resourcemanager.scheduler.capacity.LeafQueue: default used=<memory:2048, vCores:1> numContainers=1 user=ubuntu user-resources=<memory:2048, vCores:1>
2013-08-11 06:16:36,178 INFO org.apache.hadoop.yarn.server.resourcemanager.scheduler.capacity.LeafQueue: completedContainer container=Container: [ContainerId: container_1376201383303_0002_01_000003, NodeId: hadoop-320-2:40354, NodeHttpAddress: hadoop-320-2:8042, Resource: <memory:1024, vCores:1>, Priority: 20, State: NEW, Token: null, Status: container_id {, app_attempt_id {, application_id {, id: 2, cluster_timestamp: 1376201383303, }, attemptId: 1, }, id: 3, }, state: C_COMPLETE, diagnostics: "Container killed by the ApplicationMaster.\n\n", exit_status: 143, ] resource=<memory:1024, vCores:1> queue=default: capacity=1.0, absoluteCapacity=1.0, usedResources=<memory:2048, vCores:1>usedCapacity=0.041666668, absoluteUsedCapacity=0.041666668, numApps=1, numContainers=1 usedCapacity=0.041666668 absoluteUsedCapacity=0.041666668 used=<memory:2048, vCores:1> cluster=<memory:49152, vCores:96>
2013-08-11 06:16:36,178 INFO org.apache.hadoop.yarn.server.resourcemanager.scheduler.capacity.ParentQueue: completedContainer queue=root usedCapacity=0.041666668 absoluteUsedCapacity=0.041666668 used=<memory:2048, vCores:1> cluster=<memory:49152, vCores:96>
2013-08-11 06:16:36,178 INFO org.apache.hadoop.yarn.server.resourcemanager.scheduler.capacity.CapacityScheduler: Application appattempt_1376201383303_0002_000001 released container container_1376201383303_0002_01_000003 on node: host: hadoop-320-2:40354 #containers=0 available=8192 used=0 with event: FINISHED
2013-08-11 06:16:40,353 INFO org.apache.hadoop.yarn.server.resourcemanager.rmapp.attempt.RMAppAttemptImpl: appattempt_1376201383303_0002_000001 State change from RUNNING to FINISHING
2013-08-11 06:16:40,353 INFO org.apache.hadoop.yarn.server.resourcemanager.rmapp.RMAppImpl: application_1376201383303_0002 State change from RUNNING to FINISHING
2013-08-11 06:16:40,837 INFO org.apache.hadoop.yarn.server.resourcemanager.rmcontainer.RMContainerImpl: container_1376201383303_0002_01_000001 Container Transitioned from RUNNING to COMPLETED
2013-08-11 06:16:40,838 INFO org.apache.hadoop.yarn.server.resourcemanager.scheduler.common.fica.FiCaSchedulerApp: Completed container: container_1376201383303_0002_01_000001 in state: COMPLETED event:FINISHED
2013-08-11 06:16:40,838 INFO org.apache.hadoop.yarn.server.resourcemanager.RMAuditLogger: USER=ubuntu	OPERATION=AM Released Container	TARGET=SchedulerApp	RESULT=SUCCESS	APPID=application_1376201383303_0002	CONTAINERID=container_1376201383303_0002_01_000001
2013-08-11 06:16:40,838 INFO org.apache.hadoop.yarn.server.resourcemanager.scheduler.common.fica.FiCaSchedulerNode: Released container container_1376201383303_0002_01_000001 of capacity <memory:2048, vCores:1> on host hadoop-320-7:37753, which currently has 0 containers, <memory:0, vCores:0> used and <memory:8192, vCores:16> available, release resources=true
2013-08-11 06:16:40,838 INFO org.apache.hadoop.yarn.server.resourcemanager.scheduler.capacity.LeafQueue: default used=<memory:0, vCores:0> numContainers=0 user=ubuntu user-resources=<memory:0, vCores:0>
2013-08-11 06:16:40,839 INFO org.apache.hadoop.yarn.server.resourcemanager.rmapp.attempt.RMAppAttemptImpl: appattempt_1376201383303_0002_000001 State change from FINISHING to FINISHED
2013-08-11 06:16:40,839 INFO org.apache.hadoop.yarn.server.resourcemanager.rmapp.RMAppImpl: application_1376201383303_0002 State change from FINISHING to FINISHED
2013-08-11 06:16:40,840 INFO org.apache.hadoop.yarn.server.resourcemanager.scheduler.capacity.LeafQueue: completedContainer container=Container: [ContainerId: container_1376201383303_0002_01_000001, NodeId: hadoop-320-7:37753, NodeHttpAddress: hadoop-320-7:8042, Resource: <memory:2048, vCores:1>, Priority: 0, State: NEW, Token: null, Status: container_id {, app_attempt_id {, application_id {, id: 2, cluster_timestamp: 1376201383303, }, attemptId: 1, }, id: 1, }, state: C_COMPLETE, diagnostics: "", exit_status: 0, ] resource=<memory:2048, vCores:1> queue=default: capacity=1.0, absoluteCapacity=1.0, usedResources=<memory:0, vCores:0>usedCapacity=0.0, absoluteUsedCapacity=0.0, numApps=1, numContainers=0 usedCapacity=0.0 absoluteUsedCapacity=0.0 used=<memory:0, vCores:0> cluster=<memory:49152, vCores:96>
2013-08-11 06:16:40,840 INFO org.apache.hadoop.yarn.server.resourcemanager.RMAuditLogger: USER=ubuntu	OPERATION=Application Finished - Succeeded	TARGET=RMAppManager	RESULT=SUCCESS	APPID=application_1376201383303_0002
2013-08-11 06:16:40,840 INFO org.apache.hadoop.yarn.server.resourcemanager.scheduler.capacity.ParentQueue: completedContainer queue=root usedCapacity=0.0 absoluteUsedCapacity=0.0 used=<memory:0, vCores:0> cluster=<memory:49152, vCores:96>
2013-08-11 06:16:40,841 INFO org.apache.hadoop.yarn.server.resourcemanager.RMAppManager$ApplicationSummary: appId=application_1376201383303_0002,name=TeraGen,user=ubuntu,queue=default,state=FINISHED,trackingUrl=hadoop-320-1.novalocal:8088/proxy/application_1376201383303_0002/jobhistory/job/job_1376201383303_0002,appMasterHost=hadoop-320-7,startTime=1376201610102,finishTime=1376201800353
2013-08-11 06:16:40,841 INFO org.apache.hadoop.yarn.server.resourcemanager.recovery.RMStateStore: Removing info for app: application_1376201383303_0002
2013-08-11 06:16:40,840 INFO org.apache.hadoop.yarn.server.resourcemanager.amlauncher.AMLauncher: Cleaning master appattempt_1376201383303_0002_000001
2013-08-11 06:16:40,842 INFO org.apache.hadoop.yarn.server.resourcemanager.scheduler.capacity.CapacityScheduler: Application appattempt_1376201383303_0002_000001 released container container_1376201383303_0002_01_000001 on node: host: hadoop-320-7:37753 #containers=0 available=8192 used=0 with event: FINISHED
2013-08-11 06:16:40,843 INFO org.apache.hadoop.yarn.server.resourcemanager.scheduler.capacity.CapacityScheduler: Application appattempt_1376201383303_0002_000001 is done. finalState=FINISHED
2013-08-11 06:16:40,843 INFO org.apache.hadoop.yarn.server.resourcemanager.scheduler.AppSchedulingInfo: Application application_1376201383303_0002 requests cleared
2013-08-11 06:16:40,843 INFO org.apache.hadoop.yarn.server.resourcemanager.scheduler.capacity.LeafQueue: Application removed - appId: application_1376201383303_0002 user: ubuntu queue: default #user-pending-applications: 0 #user-active-applications: 0 #queue-pending-applications: 0 #queue-active-applications: 0
2013-08-11 06:16:40,843 INFO org.apache.hadoop.yarn.server.resourcemanager.scheduler.capacity.ParentQueue: Application removed - appId: application_1376201383303_0002 user: ubuntu leaf-queue of parent: root #applications: 0
2013-08-11 06:16:42,453 INFO org.apache.hadoop.yarn.server.resourcemanager.ClientRMService: Allocated new applicationId: 3
2013-08-11 06:16:44,364 INFO org.apache.hadoop.yarn.server.resourcemanager.ClientRMService: Storing Application with id application_1376201383303_0003
2013-08-11 06:16:44,364 INFO org.apache.hadoop.yarn.server.resourcemanager.recovery.RMStateStore: Storing info for app: application_1376201383303_0003
2013-08-11 06:16:44,365 INFO org.apache.hadoop.yarn.server.resourcemanager.ClientRMService: Application with id 3 submitted by user ubuntu
2013-08-11 06:16:44,365 INFO org.apache.hadoop.yarn.server.resourcemanager.RMAuditLogger: USER=ubuntu	IP=192.168.100.4	OPERATION=Submit Application Request	TARGET=ClientRMService	RESULT=SUCCESS	APPID=application_1376201383303_0003
2013-08-11 06:16:44,366 INFO org.apache.hadoop.yarn.server.resourcemanager.rmapp.RMAppImpl: application_1376201383303_0003 State change from NEW to SUBMITTED
2013-08-11 06:16:44,367 INFO org.apache.hadoop.yarn.server.resourcemanager.ApplicationMasterService: Registering appattempt_1376201383303_0003_000001
2013-08-11 06:16:44,367 INFO org.apache.hadoop.yarn.server.resourcemanager.rmapp.attempt.RMAppAttemptImpl: appattempt_1376201383303_0003_000001 State change from NEW to SUBMITTED
2013-08-11 06:16:44,367 INFO org.apache.hadoop.yarn.server.resourcemanager.scheduler.capacity.LeafQueue: Application application_1376201383303_0003 from user: ubuntu activated in queue: default
2013-08-11 06:16:44,367 INFO org.apache.hadoop.yarn.server.resourcemanager.scheduler.capacity.LeafQueue: Application added - appId: application_1376201383303_0003 user: org.apache.hadoop.yarn.server.resourcemanager.scheduler.capacity.LeafQueue$User@22a37c0, leaf-queue: default #user-pending-applications: 0 #user-active-applications: 1 #queue-pending-applications: 0 #queue-active-applications: 1
2013-08-11 06:16:44,368 INFO org.apache.hadoop.yarn.server.resourcemanager.scheduler.capacity.ParentQueue: Application added - appId: application_1376201383303_0003 user: ubuntu leaf-queue of parent: root #applications: 1
2013-08-11 06:16:44,368 INFO org.apache.hadoop.yarn.server.resourcemanager.scheduler.capacity.CapacityScheduler: Application Submission: appattempt_1376201383303_0003_000001, user: ubuntu queue: default: capacity=1.0, absoluteCapacity=1.0, usedResources=<memory:0, vCores:0>usedCapacity=0.0, absoluteUsedCapacity=0.0, numApps=1, numContainers=0, currently active: 1
2013-08-11 06:16:44,368 INFO org.apache.hadoop.yarn.server.resourcemanager.rmapp.attempt.RMAppAttemptImpl: appattempt_1376201383303_0003_000001 State change from SUBMITTED to SCHEDULED
2013-08-11 06:16:44,368 INFO org.apache.hadoop.yarn.server.resourcemanager.rmapp.RMAppImpl: application_1376201383303_0003 State change from SUBMITTED to ACCEPTED
2013-08-11 06:16:44,577 INFO org.apache.hadoop.yarn.server.resourcemanager.rmcontainer.RMContainerImpl: container_1376201383303_0003_01_000001 Container Transitioned from NEW to ALLOCATED
2013-08-11 06:16:44,577 INFO org.apache.hadoop.yarn.server.resourcemanager.RMAuditLogger: USER=ubuntu	OPERATION=AM Allocated Container	TARGET=SchedulerApp	RESULT=SUCCESS	APPID=application_1376201383303_0003	CONTAINERID=container_1376201383303_0003_01_000001
2013-08-11 06:16:44,577 INFO org.apache.hadoop.yarn.server.resourcemanager.scheduler.common.fica.FiCaSchedulerNode: Assigned container container_1376201383303_0003_01_000001 of capacity <memory:2048, vCores:1> on host hadoop-320-6:35360, which currently has 1 containers, <memory:2048, vCores:1> used and <memory:6144, vCores:15> available
2013-08-11 06:16:44,579 INFO org.apache.hadoop.yarn.server.resourcemanager.scheduler.capacity.LeafQueue: assignedContainer application=application_1376201383303_0003 container=Container: [ContainerId: container_1376201383303_0003_01_000001, NodeId: hadoop-320-6:35360, NodeHttpAddress: hadoop-320-6:8042, Resource: <memory:2048, vCores:1>, Priority: 0, State: NEW, Token: null, Status: container_id {, app_attempt_id {, application_id {, id: 3, cluster_timestamp: 1376201383303, }, attemptId: 1, }, id: 1, }, state: C_NEW, ] containerId=container_1376201383303_0003_01_000001 queue=default: capacity=1.0, absoluteCapacity=1.0, usedResources=<memory:0, vCores:0>usedCapacity=0.0, absoluteUsedCapacity=0.0, numApps=1, numContainers=0 usedCapacity=0.0 absoluteUsedCapacity=0.0 used=<memory:0, vCores:0> cluster=<memory:49152, vCores:96>
2013-08-11 06:16:44,579 INFO org.apache.hadoop.yarn.server.resourcemanager.scheduler.capacity.ParentQueue: Re-sorting queues since queue: root.default stats: default: capacity=1.0, absoluteCapacity=1.0, usedResources=<memory:2048, vCores:1>usedCapacity=0.041666668, absoluteUsedCapacity=0.041666668, numApps=1, numContainers=1
2013-08-11 06:16:44,579 INFO org.apache.hadoop.yarn.server.resourcemanager.scheduler.capacity.ParentQueue: assignedContainer queue=root usedCapacity=0.041666668 absoluteUsedCapacity=0.041666668 used=<memory:2048, vCores:1> cluster=<memory:49152, vCores:96>
2013-08-11 06:16:44,580 INFO org.apache.hadoop.yarn.server.resourcemanager.rmcontainer.RMContainerImpl: container_1376201383303_0003_01_000001 Container Transitioned from ALLOCATED to ACQUIRED
2013-08-11 06:16:44,582 INFO org.apache.hadoop.yarn.server.resourcemanager.rmapp.attempt.RMAppAttemptImpl: Storing attempt: AppId: application_1376201383303_0003 AttemptId: appattempt_1376201383303_0003_000001 MasterContainer: Container: [ContainerId: container_1376201383303_0003_01_000001, NodeId: hadoop-320-6:35360, NodeHttpAddress: hadoop-320-6:8042, Resource: <memory:2048, vCores:1>, Priority: 0, State: NEW, Token: null, Status: container_id {, app_attempt_id {, application_id {, id: 3, cluster_timestamp: 1376201383303, }, attemptId: 1, }, id: 1, }, state: C_NEW, ]
2013-08-11 06:16:44,582 INFO org.apache.hadoop.yarn.server.resourcemanager.recovery.RMStateStore: Storing info for attempt: appattempt_1376201383303_0003_000001
2013-08-11 06:16:44,582 INFO org.apache.hadoop.yarn.server.resourcemanager.rmapp.attempt.RMAppAttemptImpl: appattempt_1376201383303_0003_000001 State change from SCHEDULED to ALLOCATED_SAVING
2013-08-11 06:16:44,583 INFO org.apache.hadoop.yarn.server.resourcemanager.rmapp.attempt.RMAppAttemptImpl: appattempt_1376201383303_0003_000001 State change from ALLOCATED_SAVING to ALLOCATED
2013-08-11 06:16:44,584 INFO org.apache.hadoop.yarn.server.resourcemanager.amlauncher.AMLauncher: Launching masterappattempt_1376201383303_0003_000001
2013-08-11 06:16:44,587 INFO org.apache.hadoop.yarn.server.resourcemanager.amlauncher.AMLauncher: Setting up container Container: [ContainerId: container_1376201383303_0003_01_000001, NodeId: hadoop-320-6:35360, NodeHttpAddress: hadoop-320-6:8042, Resource: <memory:2048, vCores:1>, Priority: 0, State: NEW, Token: null, Status: container_id {, app_attempt_id {, application_id {, id: 3, cluster_timestamp: 1376201383303, }, attemptId: 1, }, id: 1, }, state: C_NEW, ] for AM appattempt_1376201383303_0003_000001
2013-08-11 06:16:44,588 INFO org.apache.hadoop.yarn.server.resourcemanager.amlauncher.AMLauncher: Command to launch container container_1376201383303_0003_01_000001 : $JAVA_HOME/bin/java -Dlog4j.configuration=container-log4j.properties -Dyarn.app.mapreduce.container.log.dir=<LOG_DIR> -Dyarn.app.mapreduce.container.log.filesize=0 -Dhadoop.root.logger=INFO,CLA  -Xmx1024m org.apache.hadoop.mapreduce.v2.app.MRAppMaster 1><LOG_DIR>/stdout 2><LOG_DIR>/stderr 
2013-08-11 06:16:44,605 INFO org.apache.hadoop.yarn.server.resourcemanager.amlauncher.AMLauncher: Done launching container Container: [ContainerId: container_1376201383303_0003_01_000001, NodeId: hadoop-320-6:35360, NodeHttpAddress: hadoop-320-6:8042, Resource: <memory:2048, vCores:1>, Priority: 0, State: NEW, Token: null, Status: container_id {, app_attempt_id {, application_id {, id: 3, cluster_timestamp: 1376201383303, }, attemptId: 1, }, id: 1, }, state: C_NEW, ] for AM appattempt_1376201383303_0003_000001
2013-08-11 06:16:44,605 INFO org.apache.hadoop.yarn.server.resourcemanager.rmapp.attempt.RMAppAttemptImpl: appattempt_1376201383303_0003_000001 State change from ALLOCATED to LAUNCHED
2013-08-11 06:16:45,583 INFO org.apache.hadoop.yarn.server.resourcemanager.rmcontainer.RMContainerImpl: container_1376201383303_0003_01_000001 Container Transitioned from ACQUIRED to RUNNING
2013-08-11 06:16:51,280 INFO org.apache.hadoop.yarn.server.resourcemanager.ApplicationMasterService: AM registration appattempt_1376201383303_0003_000001
2013-08-11 06:16:51,280 INFO org.apache.hadoop.yarn.server.resourcemanager.RMAuditLogger: USER=ubuntu	IP=192.168.100.31	OPERATION=Register App Master	TARGET=ApplicationMasterService	RESULT=SUCCESS	APPID=application_1376201383303_0003	APPATTEMPTID=appattempt_1376201383303_0003_000001
2013-08-11 06:16:51,281 INFO org.apache.hadoop.yarn.server.resourcemanager.rmapp.attempt.RMAppAttemptImpl: appattempt_1376201383303_0003_000001 State change from LAUNCHED to RUNNING
2013-08-11 06:16:51,281 INFO org.apache.hadoop.yarn.server.resourcemanager.rmapp.RMAppImpl: application_1376201383303_0003 State change from ACCEPTED to RUNNING
2013-08-11 06:16:52,621 INFO org.apache.hadoop.yarn.server.resourcemanager.rmcontainer.RMContainerImpl: container_1376201383303_0003_01_000002 Container Transitioned from NEW to ALLOCATED
2013-08-11 06:16:52,622 INFO org.apache.hadoop.yarn.server.resourcemanager.RMAuditLogger: USER=ubuntu	OPERATION=AM Allocated Container	TARGET=SchedulerApp	RESULT=SUCCESS	APPID=application_1376201383303_0003	CONTAINERID=container_1376201383303_0003_01_000002
2013-08-11 06:16:52,622 INFO org.apache.hadoop.yarn.server.resourcemanager.scheduler.common.fica.FiCaSchedulerNode: Assigned container container_1376201383303_0003_01_000002 of capacity <memory:1024, vCores:1> on host hadoop-320-6:35360, which currently has 2 containers, <memory:3072, vCores:2> used and <memory:5120, vCores:14> available
2013-08-11 06:16:52,623 INFO org.apache.hadoop.yarn.server.resourcemanager.scheduler.capacity.LeafQueue: assignedContainer application=application_1376201383303_0003 container=Container: [ContainerId: container_1376201383303_0003_01_000002, NodeId: hadoop-320-6:35360, NodeHttpAddress: hadoop-320-6:8042, Resource: <memory:1024, vCores:1>, Priority: 20, State: NEW, Token: null, Status: container_id {, app_attempt_id {, application_id {, id: 3, cluster_timestamp: 1376201383303, }, attemptId: 1, }, id: 2, }, state: C_NEW, ] containerId=container_1376201383303_0003_01_000002 queue=default: capacity=1.0, absoluteCapacity=1.0, usedResources=<memory:2048, vCores:1>usedCapacity=0.041666668, absoluteUsedCapacity=0.041666668, numApps=1, numContainers=1 usedCapacity=0.041666668 absoluteUsedCapacity=0.041666668 used=<memory:2048, vCores:1> cluster=<memory:49152, vCores:96>
2013-08-11 06:16:52,624 INFO org.apache.hadoop.yarn.server.resourcemanager.scheduler.capacity.ParentQueue: Re-sorting queues since queue: root.default stats: default: capacity=1.0, absoluteCapacity=1.0, usedResources=<memory:3072, vCores:2>usedCapacity=0.0625, absoluteUsedCapacity=0.0625, numApps=1, numContainers=2
2013-08-11 06:16:52,624 INFO org.apache.hadoop.yarn.server.resourcemanager.scheduler.capacity.ParentQueue: assignedContainer queue=root usedCapacity=0.0625 absoluteUsedCapacity=0.0625 used=<memory:3072, vCores:2> cluster=<memory:49152, vCores:96>
2013-08-11 06:16:52,694 INFO org.apache.hadoop.yarn.server.resourcemanager.rmcontainer.RMContainerImpl: container_1376201383303_0003_01_000003 Container Transitioned from NEW to ALLOCATED
2013-08-11 06:16:52,694 INFO org.apache.hadoop.yarn.server.resourcemanager.RMAuditLogger: USER=ubuntu	OPERATION=AM Allocated Container	TARGET=SchedulerApp	RESULT=SUCCESS	APPID=application_1376201383303_0003	CONTAINERID=container_1376201383303_0003_01_000003
2013-08-11 06:16:52,695 INFO org.apache.hadoop.yarn.server.resourcemanager.scheduler.common.fica.FiCaSchedulerNode: Assigned container container_1376201383303_0003_01_000003 of capacity <memory:1024, vCores:1> on host hadoop-320-4:46709, which currently has 1 containers, <memory:1024, vCores:1> used and <memory:7168, vCores:15> available
2013-08-11 06:16:52,696 INFO org.apache.hadoop.yarn.server.resourcemanager.scheduler.capacity.LeafQueue: assignedContainer application=application_1376201383303_0003 container=Container: [ContainerId: container_1376201383303_0003_01_000003, NodeId: hadoop-320-4:46709, NodeHttpAddress: hadoop-320-4:8042, Resource: <memory:1024, vCores:1>, Priority: 20, State: NEW, Token: null, Status: container_id {, app_attempt_id {, application_id {, id: 3, cluster_timestamp: 1376201383303, }, attemptId: 1, }, id: 3, }, state: C_NEW, ] containerId=container_1376201383303_0003_01_000003 queue=default: capacity=1.0, absoluteCapacity=1.0, usedResources=<memory:3072, vCores:2>usedCapacity=0.0625, absoluteUsedCapacity=0.0625, numApps=1, numContainers=2 usedCapacity=0.0625 absoluteUsedCapacity=0.0625 used=<memory:3072, vCores:2> cluster=<memory:49152, vCores:96>
2013-08-11 06:16:52,696 INFO org.apache.hadoop.yarn.server.resourcemanager.scheduler.capacity.ParentQueue: Re-sorting queues since queue: root.default stats: default: capacity=1.0, absoluteCapacity=1.0, usedResources=<memory:4096, vCores:3>usedCapacity=0.083333336, absoluteUsedCapacity=0.083333336, numApps=1, numContainers=3
2013-08-11 06:16:52,697 INFO org.apache.hadoop.yarn.server.resourcemanager.scheduler.capacity.ParentQueue: assignedContainer queue=root usedCapacity=0.083333336 absoluteUsedCapacity=0.083333336 used=<memory:4096, vCores:3> cluster=<memory:49152, vCores:96>
2013-08-11 06:16:53,335 INFO org.apache.hadoop.yarn.server.resourcemanager.rmcontainer.RMContainerImpl: container_1376201383303_0003_01_000002 Container Transitioned from ALLOCATED to ACQUIRED
2013-08-11 06:16:53,337 INFO org.apache.hadoop.yarn.server.resourcemanager.rmcontainer.RMContainerImpl: container_1376201383303_0003_01_000003 Container Transitioned from ALLOCATED to ACQUIRED
2013-08-11 06:16:53,630 INFO org.apache.hadoop.yarn.server.resourcemanager.rmcontainer.RMContainerImpl: container_1376201383303_0003_01_000002 Container Transitioned from ACQUIRED to RUNNING
2013-08-11 06:16:53,699 INFO org.apache.hadoop.yarn.server.resourcemanager.rmcontainer.RMContainerImpl: container_1376201383303_0003_01_000003 Container Transitioned from ACQUIRED to RUNNING
2013-08-11 06:16:54,377 INFO org.apache.hadoop.yarn.server.resourcemanager.scheduler.AppSchedulingInfo: checking for deactivate... 
2013-08-11 06:19:44,047 INFO org.apache.hadoop.yarn.server.resourcemanager.rmcontainer.RMContainerImpl: container_1376201383303_0003_01_000002 Container Transitioned from RUNNING to COMPLETED
2013-08-11 06:19:44,047 INFO org.apache.hadoop.yarn.server.resourcemanager.scheduler.common.fica.FiCaSchedulerApp: Completed container: container_1376201383303_0003_01_000002 in state: COMPLETED event:FINISHED
2013-08-11 06:19:44,047 INFO org.apache.hadoop.yarn.server.resourcemanager.RMAuditLogger: USER=ubuntu	OPERATION=AM Released Container	TARGET=SchedulerApp	RESULT=SUCCESS	APPID=application_1376201383303_0003	CONTAINERID=container_1376201383303_0003_01_000002
2013-08-11 06:19:44,047 INFO org.apache.hadoop.yarn.server.resourcemanager.scheduler.common.fica.FiCaSchedulerNode: Released container container_1376201383303_0003_01_000002 of capacity <memory:1024, vCores:1> on host hadoop-320-6:35360, which currently has 1 containers, <memory:2048, vCores:1> used and <memory:6144, vCores:15> available, release resources=true
2013-08-11 06:19:44,048 INFO org.apache.hadoop.yarn.server.resourcemanager.scheduler.capacity.LeafQueue: default used=<memory:3072, vCores:2> numContainers=2 user=ubuntu user-resources=<memory:3072, vCores:2>
2013-08-11 06:19:44,049 INFO org.apache.hadoop.yarn.server.resourcemanager.scheduler.capacity.LeafQueue: completedContainer container=Container: [ContainerId: container_1376201383303_0003_01_000002, NodeId: hadoop-320-6:35360, NodeHttpAddress: hadoop-320-6:8042, Resource: <memory:1024, vCores:1>, Priority: 20, State: NEW, Token: null, Status: container_id {, app_attempt_id {, application_id {, id: 3, cluster_timestamp: 1376201383303, }, attemptId: 1, }, id: 2, }, state: C_COMPLETE, diagnostics: "Container killed by the ApplicationMaster.\n", exit_status: 0, ] resource=<memory:1024, vCores:1> queue=default: capacity=1.0, absoluteCapacity=1.0, usedResources=<memory:3072, vCores:2>usedCapacity=0.0625, absoluteUsedCapacity=0.0625, numApps=1, numContainers=2 usedCapacity=0.0625 absoluteUsedCapacity=0.0625 used=<memory:3072, vCores:2> cluster=<memory:49152, vCores:96>
2013-08-11 06:19:44,049 INFO org.apache.hadoop.yarn.server.resourcemanager.scheduler.capacity.ParentQueue: completedContainer queue=root usedCapacity=0.0625 absoluteUsedCapacity=0.0625 used=<memory:3072, vCores:2> cluster=<memory:49152, vCores:96>
2013-08-11 06:19:44,050 INFO org.apache.hadoop.yarn.server.resourcemanager.scheduler.capacity.CapacityScheduler: Application appattempt_1376201383303_0003_000001 released container container_1376201383303_0003_01_000002 on node: host: hadoop-320-6:35360 #containers=1 available=6144 used=2048 with event: FINISHED
2013-08-11 06:19:49,109 INFO org.apache.hadoop.yarn.server.resourcemanager.rmcontainer.RMContainerImpl: container_1376201383303_0003_01_000003 Container Transitioned from RUNNING to COMPLETED
2013-08-11 06:19:49,109 INFO org.apache.hadoop.yarn.server.resourcemanager.scheduler.common.fica.FiCaSchedulerApp: Completed container: container_1376201383303_0003_01_000003 in state: COMPLETED event:FINISHED
2013-08-11 06:19:49,109 INFO org.apache.hadoop.yarn.server.resourcemanager.RMAuditLogger: USER=ubuntu	OPERATION=AM Released Container	TARGET=SchedulerApp	RESULT=SUCCESS	APPID=application_1376201383303_0003	CONTAINERID=container_1376201383303_0003_01_000003
2013-08-11 06:19:49,109 INFO org.apache.hadoop.yarn.server.resourcemanager.scheduler.common.fica.FiCaSchedulerNode: Released container container_1376201383303_0003_01_000003 of capacity <memory:1024, vCores:1> on host hadoop-320-4:46709, which currently has 0 containers, <memory:0, vCores:0> used and <memory:8192, vCores:16> available, release resources=true
2013-08-11 06:19:49,110 INFO org.apache.hadoop.yarn.server.resourcemanager.scheduler.capacity.LeafQueue: default used=<memory:2048, vCores:1> numContainers=1 user=ubuntu user-resources=<memory:2048, vCores:1>
2013-08-11 06:19:49,111 INFO org.apache.hadoop.yarn.server.resourcemanager.scheduler.capacity.LeafQueue: completedContainer container=Container: [ContainerId: container_1376201383303_0003_01_000003, NodeId: hadoop-320-4:46709, NodeHttpAddress: hadoop-320-4:8042, Resource: <memory:1024, vCores:1>, Priority: 20, State: NEW, Token: null, Status: container_id {, app_attempt_id {, application_id {, id: 3, cluster_timestamp: 1376201383303, }, attemptId: 1, }, id: 3, }, state: C_COMPLETE, diagnostics: "Container killed by the ApplicationMaster.\n", exit_status: 0, ] resource=<memory:1024, vCores:1> queue=default: capacity=1.0, absoluteCapacity=1.0, usedResources=<memory:2048, vCores:1>usedCapacity=0.041666668, absoluteUsedCapacity=0.041666668, numApps=1, numContainers=1 usedCapacity=0.041666668 absoluteUsedCapacity=0.041666668 used=<memory:2048, vCores:1> cluster=<memory:49152, vCores:96>
2013-08-11 06:19:49,111 INFO org.apache.hadoop.yarn.server.resourcemanager.scheduler.capacity.ParentQueue: completedContainer queue=root usedCapacity=0.041666668 absoluteUsedCapacity=0.041666668 used=<memory:2048, vCores:1> cluster=<memory:49152, vCores:96>
2013-08-11 06:19:49,112 INFO org.apache.hadoop.yarn.server.resourcemanager.scheduler.capacity.CapacityScheduler: Application appattempt_1376201383303_0003_000001 released container container_1376201383303_0003_01_000003 on node: host: hadoop-320-4:46709 #containers=0 available=8192 used=0 with event: FINISHED
2013-08-11 06:19:53,337 INFO org.apache.hadoop.yarn.server.resourcemanager.rmapp.attempt.RMAppAttemptImpl: appattempt_1376201383303_0003_000001 State change from RUNNING to FINISHING
2013-08-11 06:19:53,337 INFO org.apache.hadoop.yarn.server.resourcemanager.rmapp.RMAppImpl: application_1376201383303_0003 State change from RUNNING to FINISHING
2013-08-11 06:19:54,092 INFO org.apache.hadoop.yarn.server.resourcemanager.rmcontainer.RMContainerImpl: container_1376201383303_0003_01_000001 Container Transitioned from RUNNING to COMPLETED
2013-08-11 06:19:54,093 INFO org.apache.hadoop.yarn.server.resourcemanager.scheduler.common.fica.FiCaSchedulerApp: Completed container: container_1376201383303_0003_01_000001 in state: COMPLETED event:FINISHED
2013-08-11 06:19:54,093 INFO org.apache.hadoop.yarn.server.resourcemanager.RMAuditLogger: USER=ubuntu	OPERATION=AM Released Container	TARGET=SchedulerApp	RESULT=SUCCESS	APPID=application_1376201383303_0003	CONTAINERID=container_1376201383303_0003_01_000001
2013-08-11 06:19:54,093 INFO org.apache.hadoop.yarn.server.resourcemanager.scheduler.common.fica.FiCaSchedulerNode: Released container container_1376201383303_0003_01_000001 of capacity <memory:2048, vCores:1> on host hadoop-320-6:35360, which currently has 0 containers, <memory:0, vCores:0> used and <memory:8192, vCores:16> available, release resources=true
2013-08-11 06:19:54,093 INFO org.apache.hadoop.yarn.server.resourcemanager.scheduler.capacity.LeafQueue: default used=<memory:0, vCores:0> numContainers=0 user=ubuntu user-resources=<memory:0, vCores:0>
2013-08-11 06:19:54,095 INFO org.apache.hadoop.yarn.server.resourcemanager.rmapp.attempt.RMAppAttemptImpl: appattempt_1376201383303_0003_000001 State change from FINISHING to FINISHED
2013-08-11 06:19:54,095 INFO org.apache.hadoop.yarn.server.resourcemanager.rmapp.RMAppImpl: application_1376201383303_0003 State change from FINISHING to FINISHED
2013-08-11 06:19:54,095 INFO org.apache.hadoop.yarn.server.resourcemanager.RMAuditLogger: USER=ubuntu	OPERATION=Application Finished - Succeeded	TARGET=RMAppManager	RESULT=SUCCESS	APPID=application_1376201383303_0003
2013-08-11 06:19:54,095 INFO org.apache.hadoop.yarn.server.resourcemanager.recovery.RMStateStore: Removing info for app: application_1376201383303_0003
2013-08-11 06:19:54,095 INFO org.apache.hadoop.yarn.server.resourcemanager.RMAppManager$ApplicationSummary: appId=application_1376201383303_0003,name=TeraGen,user=ubuntu,queue=default,state=FINISHED,trackingUrl=hadoop-320-1.novalocal:8088/proxy/application_1376201383303_0003/jobhistory/job/job_1376201383303_0003,appMasterHost=hadoop-320-6,startTime=1376201804364,finishTime=1376201993337
2013-08-11 06:19:54,096 INFO org.apache.hadoop.yarn.server.resourcemanager.scheduler.capacity.LeafQueue: completedContainer container=Container: [ContainerId: container_1376201383303_0003_01_000001, NodeId: hadoop-320-6:35360, NodeHttpAddress: hadoop-320-6:8042, Resource: <memory:2048, vCores:1>, Priority: 0, State: NEW, Token: null, Status: container_id {, app_attempt_id {, application_id {, id: 3, cluster_timestamp: 1376201383303, }, attemptId: 1, }, id: 1, }, state: C_COMPLETE, diagnostics: "", exit_status: 0, ] resource=<memory:2048, vCores:1> queue=default: capacity=1.0, absoluteCapacity=1.0, usedResources=<memory:0, vCores:0>usedCapacity=0.0, absoluteUsedCapacity=0.0, numApps=1, numContainers=0 usedCapacity=0.0 absoluteUsedCapacity=0.0 used=<memory:0, vCores:0> cluster=<memory:49152, vCores:96>
2013-08-11 06:19:54,096 INFO org.apache.hadoop.yarn.server.resourcemanager.amlauncher.AMLauncher: Cleaning master appattempt_1376201383303_0003_000001
2013-08-11 06:19:54,096 INFO org.apache.hadoop.yarn.server.resourcemanager.scheduler.capacity.ParentQueue: completedContainer queue=root usedCapacity=0.0 absoluteUsedCapacity=0.0 used=<memory:0, vCores:0> cluster=<memory:49152, vCores:96>
2013-08-11 06:19:54,097 INFO org.apache.hadoop.yarn.server.resourcemanager.scheduler.capacity.CapacityScheduler: Application appattempt_1376201383303_0003_000001 released container container_1376201383303_0003_01_000001 on node: host: hadoop-320-6:35360 #containers=0 available=8192 used=0 with event: FINISHED
2013-08-11 06:19:54,097 INFO org.apache.hadoop.yarn.server.resourcemanager.scheduler.capacity.CapacityScheduler: Application appattempt_1376201383303_0003_000001 is done. finalState=FINISHED
2013-08-11 06:19:54,098 INFO org.apache.hadoop.yarn.server.resourcemanager.scheduler.AppSchedulingInfo: Application application_1376201383303_0003 requests cleared
2013-08-11 06:19:54,098 INFO org.apache.hadoop.yarn.server.resourcemanager.scheduler.capacity.LeafQueue: Application removed - appId: application_1376201383303_0003 user: ubuntu queue: default #user-pending-applications: 0 #user-active-applications: 0 #queue-pending-applications: 0 #queue-active-applications: 0
2013-08-11 06:19:54,098 INFO org.apache.hadoop.yarn.server.resourcemanager.scheduler.capacity.ParentQueue: Application removed - appId: application_1376201383303_0003 user: ubuntu leaf-queue of parent: root #applications: 0
2013-08-11 06:19:54,838 INFO org.apache.hadoop.yarn.server.resourcemanager.ClientRMService: Allocated new applicationId: 4
2013-08-11 06:19:57,007 INFO org.apache.hadoop.yarn.server.resourcemanager.ClientRMService: Storing Application with id application_1376201383303_0004
2013-08-11 06:19:57,007 INFO org.apache.hadoop.yarn.server.resourcemanager.recovery.RMStateStore: Storing info for app: application_1376201383303_0004
2013-08-11 06:19:57,007 INFO org.apache.hadoop.yarn.server.resourcemanager.ClientRMService: Application with id 4 submitted by user ubuntu
2013-08-11 06:19:57,007 INFO org.apache.hadoop.yarn.server.resourcemanager.RMAuditLogger: USER=ubuntu	IP=192.168.100.4	OPERATION=Submit Application Request	TARGET=ClientRMService	RESULT=SUCCESS	APPID=application_1376201383303_0004
2013-08-11 06:19:57,008 INFO org.apache.hadoop.yarn.server.resourcemanager.rmapp.RMAppImpl: application_1376201383303_0004 State change from NEW to SUBMITTED
2013-08-11 06:19:57,008 INFO org.apache.hadoop.yarn.server.resourcemanager.ApplicationMasterService: Registering appattempt_1376201383303_0004_000001
2013-08-11 06:19:57,008 INFO org.apache.hadoop.yarn.server.resourcemanager.rmapp.attempt.RMAppAttemptImpl: appattempt_1376201383303_0004_000001 State change from NEW to SUBMITTED
2013-08-11 06:19:57,009 INFO org.apache.hadoop.yarn.server.resourcemanager.scheduler.capacity.LeafQueue: Application application_1376201383303_0004 from user: ubuntu activated in queue: default
2013-08-11 06:19:57,009 INFO org.apache.hadoop.yarn.server.resourcemanager.scheduler.capacity.LeafQueue: Application added - appId: application_1376201383303_0004 user: org.apache.hadoop.yarn.server.resourcemanager.scheduler.capacity.LeafQueue$User@716acb4e, leaf-queue: default #user-pending-applications: 0 #user-active-applications: 1 #queue-pending-applications: 0 #queue-active-applications: 1
2013-08-11 06:19:57,010 INFO org.apache.hadoop.yarn.server.resourcemanager.scheduler.capacity.ParentQueue: Application added - appId: application_1376201383303_0004 user: ubuntu leaf-queue of parent: root #applications: 1
2013-08-11 06:19:57,011 INFO org.apache.hadoop.yarn.server.resourcemanager.scheduler.capacity.CapacityScheduler: Application Submission: appattempt_1376201383303_0004_000001, user: ubuntu queue: default: capacity=1.0, absoluteCapacity=1.0, usedResources=<memory:0, vCores:0>usedCapacity=0.0, absoluteUsedCapacity=0.0, numApps=1, numContainers=0, currently active: 1
2013-08-11 06:19:57,012 INFO org.apache.hadoop.yarn.server.resourcemanager.rmapp.attempt.RMAppAttemptImpl: appattempt_1376201383303_0004_000001 State change from SUBMITTED to SCHEDULED
2013-08-11 06:19:57,012 INFO org.apache.hadoop.yarn.server.resourcemanager.rmapp.RMAppImpl: application_1376201383303_0004 State change from SUBMITTED to ACCEPTED
2013-08-11 06:19:57,103 INFO org.apache.hadoop.yarn.server.resourcemanager.rmcontainer.RMContainerImpl: container_1376201383303_0004_01_000001 Container Transitioned from NEW to ALLOCATED
2013-08-11 06:19:57,103 INFO org.apache.hadoop.yarn.server.resourcemanager.RMAuditLogger: USER=ubuntu	OPERATION=AM Allocated Container	TARGET=SchedulerApp	RESULT=SUCCESS	APPID=application_1376201383303_0004	CONTAINERID=container_1376201383303_0004_01_000001
2013-08-11 06:19:57,103 INFO org.apache.hadoop.yarn.server.resourcemanager.scheduler.common.fica.FiCaSchedulerNode: Assigned container container_1376201383303_0004_01_000001 of capacity <memory:2048, vCores:1> on host hadoop-320-6:35360, which currently has 1 containers, <memory:2048, vCores:1> used and <memory:6144, vCores:15> available
2013-08-11 06:19:57,104 INFO org.apache.hadoop.yarn.server.resourcemanager.scheduler.capacity.LeafQueue: assignedContainer application=application_1376201383303_0004 container=Container: [ContainerId: container_1376201383303_0004_01_000001, NodeId: hadoop-320-6:35360, NodeHttpAddress: hadoop-320-6:8042, Resource: <memory:2048, vCores:1>, Priority: 0, State: NEW, Token: null, Status: container_id {, app_attempt_id {, application_id {, id: 4, cluster_timestamp: 1376201383303, }, attemptId: 1, }, id: 1, }, state: C_NEW, ] containerId=container_1376201383303_0004_01_000001 queue=default: capacity=1.0, absoluteCapacity=1.0, usedResources=<memory:0, vCores:0>usedCapacity=0.0, absoluteUsedCapacity=0.0, numApps=1, numContainers=0 usedCapacity=0.0 absoluteUsedCapacity=0.0 used=<memory:0, vCores:0> cluster=<memory:49152, vCores:96>
2013-08-11 06:19:57,105 INFO org.apache.hadoop.yarn.server.resourcemanager.scheduler.capacity.ParentQueue: Re-sorting queues since queue: root.default stats: default: capacity=1.0, absoluteCapacity=1.0, usedResources=<memory:2048, vCores:1>usedCapacity=0.041666668, absoluteUsedCapacity=0.041666668, numApps=1, numContainers=1
2013-08-11 06:19:57,105 INFO org.apache.hadoop.yarn.server.resourcemanager.scheduler.capacity.ParentQueue: assignedContainer queue=root usedCapacity=0.041666668 absoluteUsedCapacity=0.041666668 used=<memory:2048, vCores:1> cluster=<memory:49152, vCores:96>
2013-08-11 06:19:57,106 INFO org.apache.hadoop.yarn.server.resourcemanager.rmcontainer.RMContainerImpl: container_1376201383303_0004_01_000001 Container Transitioned from ALLOCATED to ACQUIRED
2013-08-11 06:19:57,108 INFO org.apache.hadoop.yarn.server.resourcemanager.rmapp.attempt.RMAppAttemptImpl: Storing attempt: AppId: application_1376201383303_0004 AttemptId: appattempt_1376201383303_0004_000001 MasterContainer: Container: [ContainerId: container_1376201383303_0004_01_000001, NodeId: hadoop-320-6:35360, NodeHttpAddress: hadoop-320-6:8042, Resource: <memory:2048, vCores:1>, Priority: 0, State: NEW, Token: null, Status: container_id {, app_attempt_id {, application_id {, id: 4, cluster_timestamp: 1376201383303, }, attemptId: 1, }, id: 1, }, state: C_NEW, ]
2013-08-11 06:19:57,108 INFO org.apache.hadoop.yarn.server.resourcemanager.rmapp.attempt.RMAppAttemptImpl: appattempt_1376201383303_0004_000001 State change from SCHEDULED to ALLOCATED_SAVING
2013-08-11 06:19:57,109 INFO org.apache.hadoop.yarn.server.resourcemanager.recovery.RMStateStore: Storing info for attempt: appattempt_1376201383303_0004_000001
2013-08-11 06:19:57,110 INFO org.apache.hadoop.yarn.server.resourcemanager.rmapp.attempt.RMAppAttemptImpl: appattempt_1376201383303_0004_000001 State change from ALLOCATED_SAVING to ALLOCATED
2013-08-11 06:19:57,115 INFO org.apache.hadoop.yarn.server.resourcemanager.amlauncher.AMLauncher: Launching masterappattempt_1376201383303_0004_000001
2013-08-11 06:19:57,118 INFO org.apache.hadoop.yarn.server.resourcemanager.amlauncher.AMLauncher: Setting up container Container: [ContainerId: container_1376201383303_0004_01_000001, NodeId: hadoop-320-6:35360, NodeHttpAddress: hadoop-320-6:8042, Resource: <memory:2048, vCores:1>, Priority: 0, State: NEW, Token: null, Status: container_id {, app_attempt_id {, application_id {, id: 4, cluster_timestamp: 1376201383303, }, attemptId: 1, }, id: 1, }, state: C_NEW, ] for AM appattempt_1376201383303_0004_000001
2013-08-11 06:19:57,118 INFO org.apache.hadoop.yarn.server.resourcemanager.amlauncher.AMLauncher: Command to launch container container_1376201383303_0004_01_000001 : $JAVA_HOME/bin/java -Dlog4j.configuration=container-log4j.properties -Dyarn.app.mapreduce.container.log.dir=<LOG_DIR> -Dyarn.app.mapreduce.container.log.filesize=0 -Dhadoop.root.logger=INFO,CLA  -Xmx1024m org.apache.hadoop.mapreduce.v2.app.MRAppMaster 1><LOG_DIR>/stdout 2><LOG_DIR>/stderr 
2013-08-11 06:19:57,132 INFO org.apache.hadoop.yarn.server.resourcemanager.amlauncher.AMLauncher: Done launching container Container: [ContainerId: container_1376201383303_0004_01_000001, NodeId: hadoop-320-6:35360, NodeHttpAddress: hadoop-320-6:8042, Resource: <memory:2048, vCores:1>, Priority: 0, State: NEW, Token: null, Status: container_id {, app_attempt_id {, application_id {, id: 4, cluster_timestamp: 1376201383303, }, attemptId: 1, }, id: 1, }, state: C_NEW, ] for AM appattempt_1376201383303_0004_000001
2013-08-11 06:19:57,133 INFO org.apache.hadoop.yarn.server.resourcemanager.rmapp.attempt.RMAppAttemptImpl: appattempt_1376201383303_0004_000001 State change from ALLOCATED to LAUNCHED
2013-08-11 06:19:58,108 INFO org.apache.hadoop.yarn.server.resourcemanager.rmcontainer.RMContainerImpl: container_1376201383303_0004_01_000001 Container Transitioned from ACQUIRED to RUNNING
2013-08-11 06:20:03,276 INFO org.apache.hadoop.yarn.server.resourcemanager.ApplicationMasterService: AM registration appattempt_1376201383303_0004_000001
2013-08-11 06:20:03,277 INFO org.apache.hadoop.yarn.server.resourcemanager.RMAuditLogger: USER=ubuntu	IP=192.168.100.31	OPERATION=Register App Master	TARGET=ApplicationMasterService	RESULT=SUCCESS	APPID=application_1376201383303_0004	APPATTEMPTID=appattempt_1376201383303_0004_000001
2013-08-11 06:20:03,278 INFO org.apache.hadoop.yarn.server.resourcemanager.rmapp.attempt.RMAppAttemptImpl: appattempt_1376201383303_0004_000001 State change from LAUNCHED to RUNNING
2013-08-11 06:20:03,278 INFO org.apache.hadoop.yarn.server.resourcemanager.rmapp.RMAppImpl: application_1376201383303_0004 State change from ACCEPTED to RUNNING
2013-08-11 06:20:04,772 INFO org.apache.hadoop.yarn.server.resourcemanager.rmcontainer.RMContainerImpl: container_1376201383303_0004_01_000002 Container Transitioned from NEW to ALLOCATED
2013-08-11 06:20:04,772 INFO org.apache.hadoop.yarn.server.resourcemanager.RMAuditLogger: USER=ubuntu	OPERATION=AM Allocated Container	TARGET=SchedulerApp	RESULT=SUCCESS	APPID=application_1376201383303_0004	CONTAINERID=container_1376201383303_0004_01_000002
2013-08-11 06:20:04,772 INFO org.apache.hadoop.yarn.server.resourcemanager.scheduler.common.fica.FiCaSchedulerNode: Assigned container container_1376201383303_0004_01_000002 of capacity <memory:1024, vCores:1> on host hadoop-320-5:32992, which currently has 1 containers, <memory:1024, vCores:1> used and <memory:7168, vCores:15> available
2013-08-11 06:20:04,773 INFO org.apache.hadoop.yarn.server.resourcemanager.scheduler.capacity.LeafQueue: assignedContainer application=application_1376201383303_0004 container=Container: [ContainerId: container_1376201383303_0004_01_000002, NodeId: hadoop-320-5:32992, NodeHttpAddress: hadoop-320-5:8042, Resource: <memory:1024, vCores:1>, Priority: 20, State: NEW, Token: null, Status: container_id {, app_attempt_id {, application_id {, id: 4, cluster_timestamp: 1376201383303, }, attemptId: 1, }, id: 2, }, state: C_NEW, ] containerId=container_1376201383303_0004_01_000002 queue=default: capacity=1.0, absoluteCapacity=1.0, usedResources=<memory:2048, vCores:1>usedCapacity=0.041666668, absoluteUsedCapacity=0.041666668, numApps=1, numContainers=1 usedCapacity=0.041666668 absoluteUsedCapacity=0.041666668 used=<memory:2048, vCores:1> cluster=<memory:49152, vCores:96>
2013-08-11 06:20:04,774 INFO org.apache.hadoop.yarn.server.resourcemanager.scheduler.capacity.ParentQueue: Re-sorting queues since queue: root.default stats: default: capacity=1.0, absoluteCapacity=1.0, usedResources=<memory:3072, vCores:2>usedCapacity=0.0625, absoluteUsedCapacity=0.0625, numApps=1, numContainers=2
2013-08-11 06:20:04,774 INFO org.apache.hadoop.yarn.server.resourcemanager.scheduler.capacity.ParentQueue: assignedContainer queue=root usedCapacity=0.0625 absoluteUsedCapacity=0.0625 used=<memory:3072, vCores:2> cluster=<memory:49152, vCores:96>
2013-08-11 06:20:04,870 INFO org.apache.hadoop.yarn.server.resourcemanager.rmcontainer.RMContainerImpl: container_1376201383303_0004_01_000003 Container Transitioned from NEW to ALLOCATED
2013-08-11 06:20:04,870 INFO org.apache.hadoop.yarn.server.resourcemanager.RMAuditLogger: USER=ubuntu	OPERATION=AM Allocated Container	TARGET=SchedulerApp	RESULT=SUCCESS	APPID=application_1376201383303_0004	CONTAINERID=container_1376201383303_0004_01_000003
2013-08-11 06:20:04,870 INFO org.apache.hadoop.yarn.server.resourcemanager.scheduler.common.fica.FiCaSchedulerNode: Assigned container container_1376201383303_0004_01_000003 of capacity <memory:1024, vCores:1> on host hadoop-320-2:40354, which currently has 1 containers, <memory:1024, vCores:1> used and <memory:7168, vCores:15> available
2013-08-11 06:20:04,871 INFO org.apache.hadoop.yarn.server.resourcemanager.scheduler.capacity.LeafQueue: assignedContainer application=application_1376201383303_0004 container=Container: [ContainerId: container_1376201383303_0004_01_000003, NodeId: hadoop-320-2:40354, NodeHttpAddress: hadoop-320-2:8042, Resource: <memory:1024, vCores:1>, Priority: 20, State: NEW, Token: null, Status: container_id {, app_attempt_id {, application_id {, id: 4, cluster_timestamp: 1376201383303, }, attemptId: 1, }, id: 3, }, state: C_NEW, ] containerId=container_1376201383303_0004_01_000003 queue=default: capacity=1.0, absoluteCapacity=1.0, usedResources=<memory:3072, vCores:2>usedCapacity=0.0625, absoluteUsedCapacity=0.0625, numApps=1, numContainers=2 usedCapacity=0.0625 absoluteUsedCapacity=0.0625 used=<memory:3072, vCores:2> cluster=<memory:49152, vCores:96>
2013-08-11 06:20:04,872 INFO org.apache.hadoop.yarn.server.resourcemanager.scheduler.capacity.ParentQueue: Re-sorting queues since queue: root.default stats: default: capacity=1.0, absoluteCapacity=1.0, usedResources=<memory:4096, vCores:3>usedCapacity=0.083333336, absoluteUsedCapacity=0.083333336, numApps=1, numContainers=3
2013-08-11 06:20:04,872 INFO org.apache.hadoop.yarn.server.resourcemanager.scheduler.capacity.ParentQueue: assignedContainer queue=root usedCapacity=0.083333336 absoluteUsedCapacity=0.083333336 used=<memory:4096, vCores:3> cluster=<memory:49152, vCores:96>
2013-08-11 06:20:05,340 INFO org.apache.hadoop.yarn.server.resourcemanager.rmcontainer.RMContainerImpl: container_1376201383303_0004_01_000002 Container Transitioned from ALLOCATED to ACQUIRED
2013-08-11 06:20:05,342 INFO org.apache.hadoop.yarn.server.resourcemanager.rmcontainer.RMContainerImpl: container_1376201383303_0004_01_000003 Container Transitioned from ALLOCATED to ACQUIRED
2013-08-11 06:20:05,876 INFO org.apache.hadoop.yarn.server.resourcemanager.rmcontainer.RMContainerImpl: container_1376201383303_0004_01_000003 Container Transitioned from ACQUIRED to RUNNING
2013-08-11 06:20:06,372 INFO org.apache.hadoop.yarn.server.resourcemanager.scheduler.AppSchedulingInfo: checking for deactivate... 
2013-08-11 06:20:06,860 INFO org.apache.hadoop.yarn.server.resourcemanager.rmcontainer.RMContainerImpl: container_1376201383303_0004_01_000002 Container Transitioned from ACQUIRED to RUNNING
2013-08-11 06:22:55,323 INFO org.apache.hadoop.yarn.server.resourcemanager.rmcontainer.RMContainerImpl: container_1376201383303_0004_01_000002 Container Transitioned from RUNNING to COMPLETED
2013-08-11 06:22:55,323 INFO org.apache.hadoop.yarn.server.resourcemanager.scheduler.common.fica.FiCaSchedulerApp: Completed container: container_1376201383303_0004_01_000002 in state: COMPLETED event:FINISHED
2013-08-11 06:22:55,323 INFO org.apache.hadoop.yarn.server.resourcemanager.RMAuditLogger: USER=ubuntu	OPERATION=AM Released Container	TARGET=SchedulerApp	RESULT=SUCCESS	APPID=application_1376201383303_0004	CONTAINERID=container_1376201383303_0004_01_000002
2013-08-11 06:22:55,324 INFO org.apache.hadoop.yarn.server.resourcemanager.scheduler.common.fica.FiCaSchedulerNode: Released container container_1376201383303_0004_01_000002 of capacity <memory:1024, vCores:1> on host hadoop-320-5:32992, which currently has 0 containers, <memory:0, vCores:0> used and <memory:8192, vCores:16> available, release resources=true
2013-08-11 06:22:55,324 INFO org.apache.hadoop.yarn.server.resourcemanager.scheduler.capacity.LeafQueue: default used=<memory:3072, vCores:2> numContainers=2 user=ubuntu user-resources=<memory:3072, vCores:2>
2013-08-11 06:22:55,325 INFO org.apache.hadoop.yarn.server.resourcemanager.scheduler.capacity.LeafQueue: completedContainer container=Container: [ContainerId: container_1376201383303_0004_01_000002, NodeId: hadoop-320-5:32992, NodeHttpAddress: hadoop-320-5:8042, Resource: <memory:1024, vCores:1>, Priority: 20, State: NEW, Token: null, Status: container_id {, app_attempt_id {, application_id {, id: 4, cluster_timestamp: 1376201383303, }, attemptId: 1, }, id: 2, }, state: C_COMPLETE, diagnostics: "Container killed by the ApplicationMaster.\n\n", exit_status: 143, ] resource=<memory:1024, vCores:1> queue=default: capacity=1.0, absoluteCapacity=1.0, usedResources=<memory:3072, vCores:2>usedCapacity=0.0625, absoluteUsedCapacity=0.0625, numApps=1, numContainers=2 usedCapacity=0.0625 absoluteUsedCapacity=0.0625 used=<memory:3072, vCores:2> cluster=<memory:49152, vCores:96>
2013-08-11 06:22:55,325 INFO org.apache.hadoop.yarn.server.resourcemanager.scheduler.capacity.ParentQueue: completedContainer queue=root usedCapacity=0.0625 absoluteUsedCapacity=0.0625 used=<memory:3072, vCores:2> cluster=<memory:49152, vCores:96>
2013-08-11 06:22:55,325 INFO org.apache.hadoop.yarn.server.resourcemanager.scheduler.capacity.CapacityScheduler: Application appattempt_1376201383303_0004_000001 released container container_1376201383303_0004_01_000002 on node: host: hadoop-320-5:32992 #containers=0 available=8192 used=0 with event: FINISHED
2013-08-11 06:22:56,292 INFO org.apache.hadoop.yarn.server.resourcemanager.rmcontainer.RMContainerImpl: container_1376201383303_0004_01_000003 Container Transitioned from RUNNING to COMPLETED
2013-08-11 06:22:56,292 INFO org.apache.hadoop.yarn.server.resourcemanager.scheduler.common.fica.FiCaSchedulerApp: Completed container: container_1376201383303_0004_01_000003 in state: COMPLETED event:FINISHED
2013-08-11 06:22:56,292 INFO org.apache.hadoop.yarn.server.resourcemanager.RMAuditLogger: USER=ubuntu	OPERATION=AM Released Container	TARGET=SchedulerApp	RESULT=SUCCESS	APPID=application_1376201383303_0004	CONTAINERID=container_1376201383303_0004_01_000003
2013-08-11 06:22:56,292 INFO org.apache.hadoop.yarn.server.resourcemanager.scheduler.common.fica.FiCaSchedulerNode: Released container container_1376201383303_0004_01_000003 of capacity <memory:1024, vCores:1> on host hadoop-320-2:40354, which currently has 0 containers, <memory:0, vCores:0> used and <memory:8192, vCores:16> available, release resources=true
2013-08-11 06:22:56,292 INFO org.apache.hadoop.yarn.server.resourcemanager.scheduler.capacity.LeafQueue: default used=<memory:2048, vCores:1> numContainers=1 user=ubuntu user-resources=<memory:2048, vCores:1>
2013-08-11 06:22:56,294 INFO org.apache.hadoop.yarn.server.resourcemanager.scheduler.capacity.LeafQueue: completedContainer container=Container: [ContainerId: container_1376201383303_0004_01_000003, NodeId: hadoop-320-2:40354, NodeHttpAddress: hadoop-320-2:8042, Resource: <memory:1024, vCores:1>, Priority: 20, State: NEW, Token: null, Status: container_id {, app_attempt_id {, application_id {, id: 4, cluster_timestamp: 1376201383303, }, attemptId: 1, }, id: 3, }, state: C_COMPLETE, diagnostics: "Container killed by the ApplicationMaster.\n\n", exit_status: 143, ] resource=<memory:1024, vCores:1> queue=default: capacity=1.0, absoluteCapacity=1.0, usedResources=<memory:2048, vCores:1>usedCapacity=0.041666668, absoluteUsedCapacity=0.041666668, numApps=1, numContainers=1 usedCapacity=0.041666668 absoluteUsedCapacity=0.041666668 used=<memory:2048, vCores:1> cluster=<memory:49152, vCores:96>
2013-08-11 06:22:56,294 INFO org.apache.hadoop.yarn.server.resourcemanager.scheduler.capacity.ParentQueue: completedContainer queue=root usedCapacity=0.041666668 absoluteUsedCapacity=0.041666668 used=<memory:2048, vCores:1> cluster=<memory:49152, vCores:96>
2013-08-11 06:22:56,295 INFO org.apache.hadoop.yarn.server.resourcemanager.scheduler.capacity.CapacityScheduler: Application appattempt_1376201383303_0004_000001 released container container_1376201383303_0004_01_000003 on node: host: hadoop-320-2:40354 #containers=0 available=8192 used=0 with event: FINISHED
2013-08-11 06:23:00,422 INFO org.apache.hadoop.yarn.server.resourcemanager.rmapp.attempt.RMAppAttemptImpl: appattempt_1376201383303_0004_000001 State change from RUNNING to FINISHING
2013-08-11 06:23:00,423 INFO org.apache.hadoop.yarn.server.resourcemanager.rmapp.RMAppImpl: application_1376201383303_0004 State change from RUNNING to FINISHING
2013-08-11 06:23:01,122 INFO org.apache.hadoop.yarn.server.resourcemanager.rmcontainer.RMContainerImpl: container_1376201383303_0004_01_000001 Container Transitioned from RUNNING to COMPLETED
2013-08-11 06:23:01,122 INFO org.apache.hadoop.yarn.server.resourcemanager.rmapp.attempt.RMAppAttemptImpl: appattempt_1376201383303_0004_000001 State change from FINISHING to FINISHED
2013-08-11 06:23:01,122 INFO org.apache.hadoop.yarn.server.resourcemanager.scheduler.common.fica.FiCaSchedulerApp: Completed container: container_1376201383303_0004_01_000001 in state: COMPLETED event:FINISHED
2013-08-11 06:23:01,123 INFO org.apache.hadoop.yarn.server.resourcemanager.rmapp.RMAppImpl: application_1376201383303_0004 State change from FINISHING to FINISHED
2013-08-11 06:23:01,123 INFO org.apache.hadoop.yarn.server.resourcemanager.RMAuditLogger: USER=ubuntu	OPERATION=AM Released Container	TARGET=SchedulerApp	RESULT=SUCCESS	APPID=application_1376201383303_0004	CONTAINERID=container_1376201383303_0004_01_000001
2013-08-11 06:23:01,123 INFO org.apache.hadoop.yarn.server.resourcemanager.RMAuditLogger: USER=ubuntu	OPERATION=Application Finished - Succeeded	TARGET=RMAppManager	RESULT=SUCCESS	APPID=application_1376201383303_0004
2013-08-11 06:23:01,123 INFO org.apache.hadoop.yarn.server.resourcemanager.scheduler.common.fica.FiCaSchedulerNode: Released container container_1376201383303_0004_01_000001 of capacity <memory:2048, vCores:1> on host hadoop-320-6:35360, which currently has 0 containers, <memory:0, vCores:0> used and <memory:8192, vCores:16> available, release resources=true
2013-08-11 06:23:01,123 INFO org.apache.hadoop.yarn.server.resourcemanager.RMAppManager$ApplicationSummary: appId=application_1376201383303_0004,name=TeraGen,user=ubuntu,queue=default,state=FINISHED,trackingUrl=hadoop-320-1.novalocal:8088/proxy/application_1376201383303_0004/jobhistory/job/job_1376201383303_0004,appMasterHost=hadoop-320-6,startTime=1376201997006,finishTime=1376202180423
2013-08-11 06:23:01,123 INFO org.apache.hadoop.yarn.server.resourcemanager.scheduler.capacity.LeafQueue: default used=<memory:0, vCores:0> numContainers=0 user=ubuntu user-resources=<memory:0, vCores:0>
2013-08-11 06:23:01,123 INFO org.apache.hadoop.yarn.server.resourcemanager.recovery.RMStateStore: Removing info for app: application_1376201383303_0004
2013-08-11 06:23:01,125 INFO org.apache.hadoop.yarn.server.resourcemanager.scheduler.capacity.LeafQueue: completedContainer container=Container: [ContainerId: container_1376201383303_0004_01_000001, NodeId: hadoop-320-6:35360, NodeHttpAddress: hadoop-320-6:8042, Resource: <memory:2048, vCores:1>, Priority: 0, State: NEW, Token: null, Status: container_id {, app_attempt_id {, application_id {, id: 4, cluster_timestamp: 1376201383303, }, attemptId: 1, }, id: 1, }, state: C_COMPLETE, diagnostics: "", exit_status: 0, ] resource=<memory:2048, vCores:1> queue=default: capacity=1.0, absoluteCapacity=1.0, usedResources=<memory:0, vCores:0>usedCapacity=0.0, absoluteUsedCapacity=0.0, numApps=1, numContainers=0 usedCapacity=0.0 absoluteUsedCapacity=0.0 used=<memory:0, vCores:0> cluster=<memory:49152, vCores:96>
2013-08-11 06:23:01,125 INFO org.apache.hadoop.yarn.server.resourcemanager.scheduler.capacity.ParentQueue: completedContainer queue=root usedCapacity=0.0 absoluteUsedCapacity=0.0 used=<memory:0, vCores:0> cluster=<memory:49152, vCores:96>
2013-08-11 06:23:01,125 INFO org.apache.hadoop.yarn.server.resourcemanager.scheduler.capacity.CapacityScheduler: Application appattempt_1376201383303_0004_000001 released container container_1376201383303_0004_01_000001 on node: host: hadoop-320-6:35360 #containers=0 available=8192 used=0 with event: FINISHED
2013-08-11 06:23:01,125 INFO org.apache.hadoop.yarn.server.resourcemanager.scheduler.capacity.CapacityScheduler: Application appattempt_1376201383303_0004_000001 is done. finalState=FINISHED
2013-08-11 06:23:01,125 INFO org.apache.hadoop.yarn.server.resourcemanager.scheduler.AppSchedulingInfo: Application application_1376201383303_0004 requests cleared
2013-08-11 06:23:01,126 INFO org.apache.hadoop.yarn.server.resourcemanager.scheduler.capacity.LeafQueue: Application removed - appId: application_1376201383303_0004 user: ubuntu queue: default #user-pending-applications: 0 #user-active-applications: 0 #queue-pending-applications: 0 #queue-active-applications: 0
2013-08-11 06:23:01,126 INFO org.apache.hadoop.yarn.server.resourcemanager.scheduler.capacity.ParentQueue: Application removed - appId: application_1376201383303_0004 user: ubuntu leaf-queue of parent: root #applications: 0
2013-08-11 06:23:01,126 INFO org.apache.hadoop.yarn.server.resourcemanager.amlauncher.AMLauncher: Cleaning master appattempt_1376201383303_0004_000001
2013-08-11 06:23:01,733 INFO org.apache.hadoop.yarn.server.resourcemanager.ClientRMService: Allocated new applicationId: 5
2013-08-11 06:23:03,633 INFO org.apache.hadoop.yarn.server.resourcemanager.ClientRMService: Storing Application with id application_1376201383303_0005
2013-08-11 06:23:03,633 INFO org.apache.hadoop.yarn.server.resourcemanager.recovery.RMStateStore: Storing info for app: application_1376201383303_0005
2013-08-11 06:23:03,633 INFO org.apache.hadoop.yarn.server.resourcemanager.ClientRMService: Application with id 5 submitted by user ubuntu
2013-08-11 06:23:03,633 INFO org.apache.hadoop.yarn.server.resourcemanager.RMAuditLogger: USER=ubuntu	IP=192.168.100.4	OPERATION=Submit Application Request	TARGET=ClientRMService	RESULT=SUCCESS	APPID=application_1376201383303_0005
2013-08-11 06:23:03,636 INFO org.apache.hadoop.yarn.server.resourcemanager.rmapp.RMAppImpl: application_1376201383303_0005 State change from NEW to SUBMITTED
2013-08-11 06:23:03,636 INFO org.apache.hadoop.yarn.server.resourcemanager.ApplicationMasterService: Registering appattempt_1376201383303_0005_000001
2013-08-11 06:23:03,636 INFO org.apache.hadoop.yarn.server.resourcemanager.rmapp.attempt.RMAppAttemptImpl: appattempt_1376201383303_0005_000001 State change from NEW to SUBMITTED
2013-08-11 06:23:03,637 INFO org.apache.hadoop.yarn.server.resourcemanager.scheduler.capacity.LeafQueue: Application application_1376201383303_0005 from user: ubuntu activated in queue: default
2013-08-11 06:23:03,637 INFO org.apache.hadoop.yarn.server.resourcemanager.scheduler.capacity.LeafQueue: Application added - appId: application_1376201383303_0005 user: org.apache.hadoop.yarn.server.resourcemanager.scheduler.capacity.LeafQueue$User@5fa2004b, leaf-queue: default #user-pending-applications: 0 #user-active-applications: 1 #queue-pending-applications: 0 #queue-active-applications: 1
2013-08-11 06:23:03,638 INFO org.apache.hadoop.yarn.server.resourcemanager.scheduler.capacity.ParentQueue: Application added - appId: application_1376201383303_0005 user: ubuntu leaf-queue of parent: root #applications: 1
2013-08-11 06:23:03,638 INFO org.apache.hadoop.yarn.server.resourcemanager.scheduler.capacity.CapacityScheduler: Application Submission: appattempt_1376201383303_0005_000001, user: ubuntu queue: default: capacity=1.0, absoluteCapacity=1.0, usedResources=<memory:0, vCores:0>usedCapacity=0.0, absoluteUsedCapacity=0.0, numApps=1, numContainers=0, currently active: 1
2013-08-11 06:23:03,638 INFO org.apache.hadoop.yarn.server.resourcemanager.rmapp.attempt.RMAppAttemptImpl: appattempt_1376201383303_0005_000001 State change from SUBMITTED to SCHEDULED
2013-08-11 06:23:03,639 INFO org.apache.hadoop.yarn.server.resourcemanager.rmapp.RMAppImpl: application_1376201383303_0005 State change from SUBMITTED to ACCEPTED
2013-08-11 06:23:03,906 INFO org.apache.hadoop.yarn.server.resourcemanager.rmcontainer.RMContainerImpl: container_1376201383303_0005_01_000001 Container Transitioned from NEW to ALLOCATED
2013-08-11 06:23:03,906 INFO org.apache.hadoop.yarn.server.resourcemanager.RMAuditLogger: USER=ubuntu	OPERATION=AM Allocated Container	TARGET=SchedulerApp	RESULT=SUCCESS	APPID=application_1376201383303_0005	CONTAINERID=container_1376201383303_0005_01_000001
2013-08-11 06:23:03,906 INFO org.apache.hadoop.yarn.server.resourcemanager.scheduler.common.fica.FiCaSchedulerNode: Assigned container container_1376201383303_0005_01_000001 of capacity <memory:2048, vCores:1> on host hadoop-320-3:36899, which currently has 1 containers, <memory:2048, vCores:1> used and <memory:6144, vCores:15> available
2013-08-11 06:23:03,908 INFO org.apache.hadoop.yarn.server.resourcemanager.scheduler.capacity.LeafQueue: assignedContainer application=application_1376201383303_0005 container=Container: [ContainerId: container_1376201383303_0005_01_000001, NodeId: hadoop-320-3:36899, NodeHttpAddress: hadoop-320-3:8042, Resource: <memory:2048, vCores:1>, Priority: 0, State: NEW, Token: null, Status: container_id {, app_attempt_id {, application_id {, id: 5, cluster_timestamp: 1376201383303, }, attemptId: 1, }, id: 1, }, state: C_NEW, ] containerId=container_1376201383303_0005_01_000001 queue=default: capacity=1.0, absoluteCapacity=1.0, usedResources=<memory:0, vCores:0>usedCapacity=0.0, absoluteUsedCapacity=0.0, numApps=1, numContainers=0 usedCapacity=0.0 absoluteUsedCapacity=0.0 used=<memory:0, vCores:0> cluster=<memory:49152, vCores:96>
2013-08-11 06:23:03,908 INFO org.apache.hadoop.yarn.server.resourcemanager.scheduler.capacity.ParentQueue: Re-sorting queues since queue: root.default stats: default: capacity=1.0, absoluteCapacity=1.0, usedResources=<memory:2048, vCores:1>usedCapacity=0.041666668, absoluteUsedCapacity=0.041666668, numApps=1, numContainers=1
2013-08-11 06:23:03,908 INFO org.apache.hadoop.yarn.server.resourcemanager.scheduler.capacity.ParentQueue: assignedContainer queue=root usedCapacity=0.041666668 absoluteUsedCapacity=0.041666668 used=<memory:2048, vCores:1> cluster=<memory:49152, vCores:96>
2013-08-11 06:23:03,910 INFO org.apache.hadoop.yarn.server.resourcemanager.rmcontainer.RMContainerImpl: container_1376201383303_0005_01_000001 Container Transitioned from ALLOCATED to ACQUIRED
2013-08-11 06:23:03,911 INFO org.apache.hadoop.yarn.server.resourcemanager.rmapp.attempt.RMAppAttemptImpl: Storing attempt: AppId: application_1376201383303_0005 AttemptId: appattempt_1376201383303_0005_000001 MasterContainer: Container: [ContainerId: container_1376201383303_0005_01_000001, NodeId: hadoop-320-3:36899, NodeHttpAddress: hadoop-320-3:8042, Resource: <memory:2048, vCores:1>, Priority: 0, State: NEW, Token: null, Status: container_id {, app_attempt_id {, application_id {, id: 5, cluster_timestamp: 1376201383303, }, attemptId: 1, }, id: 1, }, state: C_NEW, ]
2013-08-11 06:23:03,911 INFO org.apache.hadoop.yarn.server.resourcemanager.rmapp.attempt.RMAppAttemptImpl: appattempt_1376201383303_0005_000001 State change from SCHEDULED to ALLOCATED_SAVING
2013-08-11 06:23:03,912 INFO org.apache.hadoop.yarn.server.resourcemanager.recovery.RMStateStore: Storing info for attempt: appattempt_1376201383303_0005_000001
2013-08-11 06:23:03,912 INFO org.apache.hadoop.yarn.server.resourcemanager.rmapp.attempt.RMAppAttemptImpl: appattempt_1376201383303_0005_000001 State change from ALLOCATED_SAVING to ALLOCATED
2013-08-11 06:23:03,914 INFO org.apache.hadoop.yarn.server.resourcemanager.amlauncher.AMLauncher: Launching masterappattempt_1376201383303_0005_000001
2013-08-11 06:23:03,916 INFO org.apache.hadoop.yarn.server.resourcemanager.amlauncher.AMLauncher: Setting up container Container: [ContainerId: container_1376201383303_0005_01_000001, NodeId: hadoop-320-3:36899, NodeHttpAddress: hadoop-320-3:8042, Resource: <memory:2048, vCores:1>, Priority: 0, State: NEW, Token: null, Status: container_id {, app_attempt_id {, application_id {, id: 5, cluster_timestamp: 1376201383303, }, attemptId: 1, }, id: 1, }, state: C_NEW, ] for AM appattempt_1376201383303_0005_000001
2013-08-11 06:23:03,916 INFO org.apache.hadoop.yarn.server.resourcemanager.amlauncher.AMLauncher: Command to launch container container_1376201383303_0005_01_000001 : $JAVA_HOME/bin/java -Dlog4j.configuration=container-log4j.properties -Dyarn.app.mapreduce.container.log.dir=<LOG_DIR> -Dyarn.app.mapreduce.container.log.filesize=0 -Dhadoop.root.logger=INFO,CLA  -Xmx1024m org.apache.hadoop.mapreduce.v2.app.MRAppMaster 1><LOG_DIR>/stdout 2><LOG_DIR>/stderr 
2013-08-11 06:23:03,932 INFO org.apache.hadoop.yarn.server.resourcemanager.amlauncher.AMLauncher: Done launching container Container: [ContainerId: container_1376201383303_0005_01_000001, NodeId: hadoop-320-3:36899, NodeHttpAddress: hadoop-320-3:8042, Resource: <memory:2048, vCores:1>, Priority: 0, State: NEW, Token: null, Status: container_id {, app_attempt_id {, application_id {, id: 5, cluster_timestamp: 1376201383303, }, attemptId: 1, }, id: 1, }, state: C_NEW, ] for AM appattempt_1376201383303_0005_000001
2013-08-11 06:23:03,932 INFO org.apache.hadoop.yarn.server.resourcemanager.rmapp.attempt.RMAppAttemptImpl: appattempt_1376201383303_0005_000001 State change from ALLOCATED to LAUNCHED
2013-08-11 06:23:04,911 INFO org.apache.hadoop.yarn.server.resourcemanager.rmcontainer.RMContainerImpl: container_1376201383303_0005_01_000001 Container Transitioned from ACQUIRED to RUNNING
2013-08-11 06:23:11,832 INFO org.apache.hadoop.yarn.server.resourcemanager.ApplicationMasterService: AM registration appattempt_1376201383303_0005_000001
2013-08-11 06:23:11,832 INFO org.apache.hadoop.yarn.server.resourcemanager.RMAuditLogger: USER=ubuntu	IP=192.168.100.14	OPERATION=Register App Master	TARGET=ApplicationMasterService	RESULT=SUCCESS	APPID=application_1376201383303_0005	APPATTEMPTID=appattempt_1376201383303_0005_000001
2013-08-11 06:23:11,833 INFO org.apache.hadoop.yarn.server.resourcemanager.rmapp.attempt.RMAppAttemptImpl: appattempt_1376201383303_0005_000001 State change from LAUNCHED to RUNNING
2013-08-11 06:23:11,833 INFO org.apache.hadoop.yarn.server.resourcemanager.rmapp.RMAppImpl: application_1376201383303_0005 State change from ACCEPTED to RUNNING
2013-08-11 06:23:12,953 INFO org.apache.hadoop.yarn.server.resourcemanager.rmcontainer.RMContainerImpl: container_1376201383303_0005_01_000002 Container Transitioned from NEW to ALLOCATED
2013-08-11 06:23:12,953 INFO org.apache.hadoop.yarn.server.resourcemanager.RMAuditLogger: USER=ubuntu	OPERATION=AM Allocated Container	TARGET=SchedulerApp	RESULT=SUCCESS	APPID=application_1376201383303_0005	CONTAINERID=container_1376201383303_0005_01_000002
2013-08-11 06:23:12,954 INFO org.apache.hadoop.yarn.server.resourcemanager.scheduler.common.fica.FiCaSchedulerNode: Assigned container container_1376201383303_0005_01_000002 of capacity <memory:1024, vCores:1> on host hadoop-320-3:36899, which currently has 2 containers, <memory:3072, vCores:2> used and <memory:5120, vCores:14> available
2013-08-11 06:23:12,955 INFO org.apache.hadoop.yarn.server.resourcemanager.scheduler.capacity.LeafQueue: assignedContainer application=application_1376201383303_0005 container=Container: [ContainerId: container_1376201383303_0005_01_000002, NodeId: hadoop-320-3:36899, NodeHttpAddress: hadoop-320-3:8042, Resource: <memory:1024, vCores:1>, Priority: 20, State: NEW, Token: null, Status: container_id {, app_attempt_id {, application_id {, id: 5, cluster_timestamp: 1376201383303, }, attemptId: 1, }, id: 2, }, state: C_NEW, ] containerId=container_1376201383303_0005_01_000002 queue=default: capacity=1.0, absoluteCapacity=1.0, usedResources=<memory:2048, vCores:1>usedCapacity=0.041666668, absoluteUsedCapacity=0.041666668, numApps=1, numContainers=1 usedCapacity=0.041666668 absoluteUsedCapacity=0.041666668 used=<memory:2048, vCores:1> cluster=<memory:49152, vCores:96>
2013-08-11 06:23:12,955 INFO org.apache.hadoop.yarn.server.resourcemanager.scheduler.capacity.ParentQueue: Re-sorting queues since queue: root.default stats: default: capacity=1.0, absoluteCapacity=1.0, usedResources=<memory:3072, vCores:2>usedCapacity=0.0625, absoluteUsedCapacity=0.0625, numApps=1, numContainers=2
2013-08-11 06:23:12,955 INFO org.apache.hadoop.yarn.server.resourcemanager.scheduler.capacity.ParentQueue: assignedContainer queue=root usedCapacity=0.0625 absoluteUsedCapacity=0.0625 used=<memory:3072, vCores:2> cluster=<memory:49152, vCores:96>
2013-08-11 06:23:13,001 INFO org.apache.hadoop.yarn.server.resourcemanager.rmcontainer.RMContainerImpl: container_1376201383303_0005_01_000003 Container Transitioned from NEW to ALLOCATED
2013-08-11 06:23:13,001 INFO org.apache.hadoop.yarn.server.resourcemanager.RMAuditLogger: USER=ubuntu	OPERATION=AM Allocated Container	TARGET=SchedulerApp	RESULT=SUCCESS	APPID=application_1376201383303_0005	CONTAINERID=container_1376201383303_0005_01_000003
2013-08-11 06:23:13,001 INFO org.apache.hadoop.yarn.server.resourcemanager.scheduler.common.fica.FiCaSchedulerNode: Assigned container container_1376201383303_0005_01_000003 of capacity <memory:1024, vCores:1> on host hadoop-320-4:46709, which currently has 1 containers, <memory:1024, vCores:1> used and <memory:7168, vCores:15> available
2013-08-11 06:23:13,003 INFO org.apache.hadoop.yarn.server.resourcemanager.scheduler.capacity.LeafQueue: assignedContainer application=application_1376201383303_0005 container=Container: [ContainerId: container_1376201383303_0005_01_000003, NodeId: hadoop-320-4:46709, NodeHttpAddress: hadoop-320-4:8042, Resource: <memory:1024, vCores:1>, Priority: 20, State: NEW, Token: null, Status: container_id {, app_attempt_id {, application_id {, id: 5, cluster_timestamp: 1376201383303, }, attemptId: 1, }, id: 3, }, state: C_NEW, ] containerId=container_1376201383303_0005_01_000003 queue=default: capacity=1.0, absoluteCapacity=1.0, usedResources=<memory:3072, vCores:2>usedCapacity=0.0625, absoluteUsedCapacity=0.0625, numApps=1, numContainers=2 usedCapacity=0.0625 absoluteUsedCapacity=0.0625 used=<memory:3072, vCores:2> cluster=<memory:49152, vCores:96>
2013-08-11 06:23:13,003 INFO org.apache.hadoop.yarn.server.resourcemanager.scheduler.capacity.ParentQueue: Re-sorting queues since queue: root.default stats: default: capacity=1.0, absoluteCapacity=1.0, usedResources=<memory:4096, vCores:3>usedCapacity=0.083333336, absoluteUsedCapacity=0.083333336, numApps=1, numContainers=3
2013-08-11 06:23:13,003 INFO org.apache.hadoop.yarn.server.resourcemanager.scheduler.capacity.ParentQueue: assignedContainer queue=root usedCapacity=0.083333336 absoluteUsedCapacity=0.083333336 used=<memory:4096, vCores:3> cluster=<memory:49152, vCores:96>
2013-08-11 06:23:13,899 INFO org.apache.hadoop.yarn.server.resourcemanager.rmcontainer.RMContainerImpl: container_1376201383303_0005_01_000002 Container Transitioned from ALLOCATED to ACQUIRED
2013-08-11 06:23:13,902 INFO org.apache.hadoop.yarn.server.resourcemanager.rmcontainer.RMContainerImpl: container_1376201383303_0005_01_000003 Container Transitioned from ALLOCATED to ACQUIRED
2013-08-11 06:23:14,932 INFO org.apache.hadoop.yarn.server.resourcemanager.scheduler.AppSchedulingInfo: checking for deactivate... 
2013-08-11 06:23:14,964 INFO org.apache.hadoop.yarn.server.resourcemanager.rmcontainer.RMContainerImpl: container_1376201383303_0005_01_000002 Container Transitioned from ACQUIRED to RUNNING
2013-08-11 06:23:15,009 INFO org.apache.hadoop.yarn.server.resourcemanager.rmcontainer.RMContainerImpl: container_1376201383303_0005_01_000003 Container Transitioned from ACQUIRED to RUNNING
2013-08-11 06:26:07,607 INFO org.apache.hadoop.yarn.server.resourcemanager.rmcontainer.RMContainerImpl: container_1376201383303_0005_01_000002 Container Transitioned from RUNNING to COMPLETED
2013-08-11 06:26:07,607 INFO org.apache.hadoop.yarn.server.resourcemanager.scheduler.common.fica.FiCaSchedulerApp: Completed container: container_1376201383303_0005_01_000002 in state: COMPLETED event:FINISHED
2013-08-11 06:26:07,607 INFO org.apache.hadoop.yarn.server.resourcemanager.RMAuditLogger: USER=ubuntu	OPERATION=AM Released Container	TARGET=SchedulerApp	RESULT=SUCCESS	APPID=application_1376201383303_0005	CONTAINERID=container_1376201383303_0005_01_000002
2013-08-11 06:26:07,607 INFO org.apache.hadoop.yarn.server.resourcemanager.scheduler.common.fica.FiCaSchedulerNode: Released container container_1376201383303_0005_01_000002 of capacity <memory:1024, vCores:1> on host hadoop-320-3:36899, which currently has 1 containers, <memory:2048, vCores:1> used and <memory:6144, vCores:15> available, release resources=true
2013-08-11 06:26:07,607 INFO org.apache.hadoop.yarn.server.resourcemanager.scheduler.capacity.LeafQueue: default used=<memory:3072, vCores:2> numContainers=2 user=ubuntu user-resources=<memory:3072, vCores:2>
2013-08-11 06:26:07,609 INFO org.apache.hadoop.yarn.server.resourcemanager.scheduler.capacity.LeafQueue: completedContainer container=Container: [ContainerId: container_1376201383303_0005_01_000002, NodeId: hadoop-320-3:36899, NodeHttpAddress: hadoop-320-3:8042, Resource: <memory:1024, vCores:1>, Priority: 20, State: NEW, Token: null, Status: container_id {, app_attempt_id {, application_id {, id: 5, cluster_timestamp: 1376201383303, }, attemptId: 1, }, id: 2, }, state: C_COMPLETE, diagnostics: "Container killed by the ApplicationMaster.\n\n", exit_status: 143, ] resource=<memory:1024, vCores:1> queue=default: capacity=1.0, absoluteCapacity=1.0, usedResources=<memory:3072, vCores:2>usedCapacity=0.0625, absoluteUsedCapacity=0.0625, numApps=1, numContainers=2 usedCapacity=0.0625 absoluteUsedCapacity=0.0625 used=<memory:3072, vCores:2> cluster=<memory:49152, vCores:96>
2013-08-11 06:26:07,609 INFO org.apache.hadoop.yarn.server.resourcemanager.scheduler.capacity.ParentQueue: completedContainer queue=root usedCapacity=0.0625 absoluteUsedCapacity=0.0625 used=<memory:3072, vCores:2> cluster=<memory:49152, vCores:96>
2013-08-11 06:26:07,609 INFO org.apache.hadoop.yarn.server.resourcemanager.scheduler.capacity.CapacityScheduler: Application appattempt_1376201383303_0005_000001 released container container_1376201383303_0005_01_000002 on node: host: hadoop-320-3:36899 #containers=1 available=6144 used=2048 with event: FINISHED
2013-08-11 06:26:09,661 INFO org.apache.hadoop.yarn.server.resourcemanager.rmcontainer.RMContainerImpl: container_1376201383303_0005_01_000003 Container Transitioned from RUNNING to COMPLETED
2013-08-11 06:26:09,663 INFO org.apache.hadoop.yarn.server.resourcemanager.scheduler.common.fica.FiCaSchedulerApp: Completed container: container_1376201383303_0005_01_000003 in state: COMPLETED event:FINISHED
2013-08-11 06:26:09,663 INFO org.apache.hadoop.yarn.server.resourcemanager.RMAuditLogger: USER=ubuntu	OPERATION=AM Released Container	TARGET=SchedulerApp	RESULT=SUCCESS	APPID=application_1376201383303_0005	CONTAINERID=container_1376201383303_0005_01_000003
2013-08-11 06:26:09,663 INFO org.apache.hadoop.yarn.server.resourcemanager.scheduler.common.fica.FiCaSchedulerNode: Released container container_1376201383303_0005_01_000003 of capacity <memory:1024, vCores:1> on host hadoop-320-4:46709, which currently has 0 containers, <memory:0, vCores:0> used and <memory:8192, vCores:16> available, release resources=true
2013-08-11 06:26:09,664 INFO org.apache.hadoop.yarn.server.resourcemanager.scheduler.capacity.LeafQueue: default used=<memory:2048, vCores:1> numContainers=1 user=ubuntu user-resources=<memory:2048, vCores:1>
2013-08-11 06:26:09,665 INFO org.apache.hadoop.yarn.server.resourcemanager.scheduler.capacity.LeafQueue: completedContainer container=Container: [ContainerId: container_1376201383303_0005_01_000003, NodeId: hadoop-320-4:46709, NodeHttpAddress: hadoop-320-4:8042, Resource: <memory:1024, vCores:1>, Priority: 20, State: NEW, Token: null, Status: container_id {, app_attempt_id {, application_id {, id: 5, cluster_timestamp: 1376201383303, }, attemptId: 1, }, id: 3, }, state: C_COMPLETE, diagnostics: "Container killed by the ApplicationMaster.\n\n", exit_status: 143, ] resource=<memory:1024, vCores:1> queue=default: capacity=1.0, absoluteCapacity=1.0, usedResources=<memory:2048, vCores:1>usedCapacity=0.041666668, absoluteUsedCapacity=0.041666668, numApps=1, numContainers=1 usedCapacity=0.041666668 absoluteUsedCapacity=0.041666668 used=<memory:2048, vCores:1> cluster=<memory:49152, vCores:96>
2013-08-11 06:26:09,665 INFO org.apache.hadoop.yarn.server.resourcemanager.scheduler.capacity.ParentQueue: completedContainer queue=root usedCapacity=0.041666668 absoluteUsedCapacity=0.041666668 used=<memory:2048, vCores:1> cluster=<memory:49152, vCores:96>
2013-08-11 06:26:09,666 INFO org.apache.hadoop.yarn.server.resourcemanager.scheduler.capacity.CapacityScheduler: Application appattempt_1376201383303_0005_000001 released container container_1376201383303_0005_01_000003 on node: host: hadoop-320-4:46709 #containers=0 available=8192 used=0 with event: FINISHED
2013-08-11 06:26:13,850 INFO org.apache.hadoop.yarn.server.resourcemanager.rmapp.attempt.RMAppAttemptImpl: appattempt_1376201383303_0005_000001 State change from RUNNING to FINISHING
2013-08-11 06:26:13,851 INFO org.apache.hadoop.yarn.server.resourcemanager.rmapp.RMAppImpl: application_1376201383303_0005 State change from RUNNING to FINISHING
2013-08-11 06:26:14,643 INFO org.apache.hadoop.yarn.server.resourcemanager.rmcontainer.RMContainerImpl: container_1376201383303_0005_01_000001 Container Transitioned from RUNNING to COMPLETED
2013-08-11 06:26:14,643 INFO org.apache.hadoop.yarn.server.resourcemanager.scheduler.common.fica.FiCaSchedulerApp: Completed container: container_1376201383303_0005_01_000001 in state: COMPLETED event:FINISHED
2013-08-11 06:26:14,643 INFO org.apache.hadoop.yarn.server.resourcemanager.RMAuditLogger: USER=ubuntu	OPERATION=AM Released Container	TARGET=SchedulerApp	RESULT=SUCCESS	APPID=application_1376201383303_0005	CONTAINERID=container_1376201383303_0005_01_000001
2013-08-11 06:26:14,643 INFO org.apache.hadoop.yarn.server.resourcemanager.scheduler.common.fica.FiCaSchedulerNode: Released container container_1376201383303_0005_01_000001 of capacity <memory:2048, vCores:1> on host hadoop-320-3:36899, which currently has 0 containers, <memory:0, vCores:0> used and <memory:8192, vCores:16> available, release resources=true
2013-08-11 06:26:14,643 INFO org.apache.hadoop.yarn.server.resourcemanager.scheduler.capacity.LeafQueue: default used=<memory:0, vCores:0> numContainers=0 user=ubuntu user-resources=<memory:0, vCores:0>
2013-08-11 06:26:14,644 INFO org.apache.hadoop.yarn.server.resourcemanager.scheduler.capacity.LeafQueue: completedContainer container=Container: [ContainerId: container_1376201383303_0005_01_000001, NodeId: hadoop-320-3:36899, NodeHttpAddress: hadoop-320-3:8042, Resource: <memory:2048, vCores:1>, Priority: 0, State: NEW, Token: null, Status: container_id {, app_attempt_id {, application_id {, id: 5, cluster_timestamp: 1376201383303, }, attemptId: 1, }, id: 1, }, state: C_COMPLETE, diagnostics: "", exit_status: 0, ] resource=<memory:2048, vCores:1> queue=default: capacity=1.0, absoluteCapacity=1.0, usedResources=<memory:0, vCores:0>usedCapacity=0.0, absoluteUsedCapacity=0.0, numApps=1, numContainers=0 usedCapacity=0.0 absoluteUsedCapacity=0.0 used=<memory:0, vCores:0> cluster=<memory:49152, vCores:96>
2013-08-11 06:26:14,644 INFO org.apache.hadoop.yarn.server.resourcemanager.scheduler.capacity.ParentQueue: completedContainer queue=root usedCapacity=0.0 absoluteUsedCapacity=0.0 used=<memory:0, vCores:0> cluster=<memory:49152, vCores:96>
2013-08-11 06:26:14,644 INFO org.apache.hadoop.yarn.server.resourcemanager.scheduler.capacity.CapacityScheduler: Application appattempt_1376201383303_0005_000001 released container container_1376201383303_0005_01_000001 on node: host: hadoop-320-3:36899 #containers=0 available=8192 used=0 with event: FINISHED
2013-08-11 06:26:14,645 INFO org.apache.hadoop.yarn.server.resourcemanager.rmapp.attempt.RMAppAttemptImpl: appattempt_1376201383303_0005_000001 State change from FINISHING to FINISHED
2013-08-11 06:26:14,655 INFO org.apache.hadoop.yarn.server.resourcemanager.rmapp.RMAppImpl: application_1376201383303_0005 State change from FINISHING to FINISHED
2013-08-11 06:26:14,655 INFO org.apache.hadoop.yarn.server.resourcemanager.RMAuditLogger: USER=ubuntu	OPERATION=Application Finished - Succeeded	TARGET=RMAppManager	RESULT=SUCCESS	APPID=application_1376201383303_0005
2013-08-11 06:26:14,655 INFO org.apache.hadoop.yarn.server.resourcemanager.RMAppManager$ApplicationSummary: appId=application_1376201383303_0005,name=TeraGen,user=ubuntu,queue=default,state=FINISHED,trackingUrl=hadoop-320-1.novalocal:8088/proxy/application_1376201383303_0005/jobhistory/job/job_1376201383303_0005,appMasterHost=hadoop-320-3,startTime=1376202183632,finishTime=1376202373851
2013-08-11 06:26:14,655 INFO org.apache.hadoop.yarn.server.resourcemanager.scheduler.capacity.CapacityScheduler: Application appattempt_1376201383303_0005_000001 is done. finalState=FINISHED
2013-08-11 06:26:14,655 INFO org.apache.hadoop.yarn.server.resourcemanager.amlauncher.AMLauncher: Cleaning master appattempt_1376201383303_0005_000001
2013-08-11 06:26:14,656 INFO org.apache.hadoop.yarn.server.resourcemanager.scheduler.AppSchedulingInfo: Application application_1376201383303_0005 requests cleared
2013-08-11 06:26:14,656 INFO org.apache.hadoop.yarn.server.resourcemanager.scheduler.capacity.LeafQueue: Application removed - appId: application_1376201383303_0005 user: ubuntu queue: default #user-pending-applications: 0 #user-active-applications: 0 #queue-pending-applications: 0 #queue-active-applications: 0
2013-08-11 06:26:14,656 INFO org.apache.hadoop.yarn.server.resourcemanager.scheduler.capacity.ParentQueue: Application removed - appId: application_1376201383303_0005 user: ubuntu leaf-queue of parent: root #applications: 0
2013-08-11 06:26:14,662 INFO org.apache.hadoop.yarn.server.resourcemanager.recovery.RMStateStore: Removing info for app: application_1376201383303_0005
2013-08-11 06:26:19,803 INFO org.apache.hadoop.yarn.server.resourcemanager.ClientRMService: Allocated new applicationId: 6
2013-08-11 06:26:20,195 INFO org.apache.hadoop.yarn.server.resourcemanager.ClientRMService: Allocated new applicationId: 7
2013-08-11 06:26:20,428 INFO org.apache.hadoop.yarn.server.resourcemanager.ClientRMService: Allocated new applicationId: 8
2013-08-11 06:26:20,527 INFO org.apache.hadoop.yarn.server.resourcemanager.ClientRMService: Allocated new applicationId: 9
2013-08-11 06:26:20,624 INFO org.apache.hadoop.yarn.server.resourcemanager.ClientRMService: Allocated new applicationId: 10
2013-08-11 06:26:21,466 INFO org.apache.hadoop.yarn.server.resourcemanager.ClientRMService: Storing Application with id application_1376201383303_0006
2013-08-11 06:26:21,466 INFO org.apache.hadoop.yarn.server.resourcemanager.recovery.RMStateStore: Storing info for app: application_1376201383303_0006
2013-08-11 06:26:21,466 INFO org.apache.hadoop.yarn.server.resourcemanager.ClientRMService: Application with id 6 submitted by user ubuntu
2013-08-11 06:26:21,466 INFO org.apache.hadoop.yarn.server.resourcemanager.RMAuditLogger: USER=ubuntu	IP=192.168.100.4	OPERATION=Submit Application Request	TARGET=ClientRMService	RESULT=SUCCESS	APPID=application_1376201383303_0006
2013-08-11 06:26:21,473 INFO org.apache.hadoop.yarn.server.resourcemanager.rmapp.RMAppImpl: application_1376201383303_0006 State change from NEW to SUBMITTED
2013-08-11 06:26:21,473 INFO org.apache.hadoop.yarn.server.resourcemanager.ApplicationMasterService: Registering appattempt_1376201383303_0006_000001
2013-08-11 06:26:21,474 INFO org.apache.hadoop.yarn.server.resourcemanager.rmapp.attempt.RMAppAttemptImpl: appattempt_1376201383303_0006_000001 State change from NEW to SUBMITTED
2013-08-11 06:26:21,474 INFO org.apache.hadoop.yarn.server.resourcemanager.scheduler.capacity.LeafQueue: Application application_1376201383303_0006 from user: ubuntu activated in queue: default
2013-08-11 06:26:21,474 INFO org.apache.hadoop.yarn.server.resourcemanager.scheduler.capacity.LeafQueue: Application added - appId: application_1376201383303_0006 user: org.apache.hadoop.yarn.server.resourcemanager.scheduler.capacity.LeafQueue$User@667b9d6b, leaf-queue: default #user-pending-applications: 0 #user-active-applications: 1 #queue-pending-applications: 0 #queue-active-applications: 1
2013-08-11 06:26:21,474 INFO org.apache.hadoop.yarn.server.resourcemanager.scheduler.capacity.ParentQueue: Application added - appId: application_1376201383303_0006 user: ubuntu leaf-queue of parent: root #applications: 1
2013-08-11 06:26:21,474 INFO org.apache.hadoop.yarn.server.resourcemanager.scheduler.capacity.CapacityScheduler: Application Submission: appattempt_1376201383303_0006_000001, user: ubuntu queue: default: capacity=1.0, absoluteCapacity=1.0, usedResources=<memory:0, vCores:0>usedCapacity=0.0, absoluteUsedCapacity=0.0, numApps=1, numContainers=0, currently active: 1
2013-08-11 06:26:21,474 INFO org.apache.hadoop.yarn.server.resourcemanager.rmapp.attempt.RMAppAttemptImpl: appattempt_1376201383303_0006_000001 State change from SUBMITTED to SCHEDULED
2013-08-11 06:26:21,475 INFO org.apache.hadoop.yarn.server.resourcemanager.rmapp.RMAppImpl: application_1376201383303_0006 State change from SUBMITTED to ACCEPTED
2013-08-11 06:26:21,656 INFO org.apache.hadoop.yarn.server.resourcemanager.ClientRMService: Storing Application with id application_1376201383303_0007
2013-08-11 06:26:21,656 INFO org.apache.hadoop.yarn.server.resourcemanager.recovery.RMStateStore: Storing info for app: application_1376201383303_0007
2013-08-11 06:26:21,656 INFO org.apache.hadoop.yarn.server.resourcemanager.ClientRMService: Application with id 7 submitted by user ubuntu
2013-08-11 06:26:21,656 INFO org.apache.hadoop.yarn.server.resourcemanager.RMAuditLogger: USER=ubuntu	IP=192.168.100.4	OPERATION=Submit Application Request	TARGET=ClientRMService	RESULT=SUCCESS	APPID=application_1376201383303_0007
2013-08-11 06:26:21,657 INFO org.apache.hadoop.yarn.server.resourcemanager.rmapp.RMAppImpl: application_1376201383303_0007 State change from NEW to SUBMITTED
2013-08-11 06:26:21,657 INFO org.apache.hadoop.yarn.server.resourcemanager.ApplicationMasterService: Registering appattempt_1376201383303_0007_000001
2013-08-11 06:26:21,657 INFO org.apache.hadoop.yarn.server.resourcemanager.rmapp.attempt.RMAppAttemptImpl: appattempt_1376201383303_0007_000001 State change from NEW to SUBMITTED
2013-08-11 06:26:21,657 INFO org.apache.hadoop.yarn.server.resourcemanager.scheduler.capacity.LeafQueue: Application application_1376201383303_0007 from user: ubuntu activated in queue: default
2013-08-11 06:26:21,658 INFO org.apache.hadoop.yarn.server.resourcemanager.scheduler.capacity.LeafQueue: Application added - appId: application_1376201383303_0007 user: org.apache.hadoop.yarn.server.resourcemanager.scheduler.capacity.LeafQueue$User@667b9d6b, leaf-queue: default #user-pending-applications: 0 #user-active-applications: 2 #queue-pending-applications: 0 #queue-active-applications: 2
2013-08-11 06:26:21,658 INFO org.apache.hadoop.yarn.server.resourcemanager.scheduler.capacity.ParentQueue: Application added - appId: application_1376201383303_0007 user: ubuntu leaf-queue of parent: root #applications: 2
2013-08-11 06:26:21,658 INFO org.apache.hadoop.yarn.server.resourcemanager.scheduler.capacity.CapacityScheduler: Application Submission: appattempt_1376201383303_0007_000001, user: ubuntu queue: default: capacity=1.0, absoluteCapacity=1.0, usedResources=<memory:0, vCores:0>usedCapacity=0.0, absoluteUsedCapacity=0.0, numApps=2, numContainers=0, currently active: 2
2013-08-11 06:26:21,658 INFO org.apache.hadoop.yarn.server.resourcemanager.rmapp.attempt.RMAppAttemptImpl: appattempt_1376201383303_0007_000001 State change from SUBMITTED to SCHEDULED
2013-08-11 06:26:21,658 INFO org.apache.hadoop.yarn.server.resourcemanager.rmapp.RMAppImpl: application_1376201383303_0007 State change from SUBMITTED to ACCEPTED
2013-08-11 06:26:21,679 INFO org.apache.hadoop.yarn.server.resourcemanager.rmcontainer.RMContainerImpl: container_1376201383303_0006_01_000001 Container Transitioned from NEW to ALLOCATED
2013-08-11 06:26:21,679 INFO org.apache.hadoop.yarn.server.resourcemanager.RMAuditLogger: USER=ubuntu	OPERATION=AM Allocated Container	TARGET=SchedulerApp	RESULT=SUCCESS	APPID=application_1376201383303_0006	CONTAINERID=container_1376201383303_0006_01_000001
2013-08-11 06:26:21,680 INFO org.apache.hadoop.yarn.server.resourcemanager.scheduler.common.fica.FiCaSchedulerNode: Assigned container container_1376201383303_0006_01_000001 of capacity <memory:2048, vCores:1> on host hadoop-320-3:36899, which currently has 1 containers, <memory:2048, vCores:1> used and <memory:6144, vCores:15> available
2013-08-11 06:26:21,680 INFO org.apache.hadoop.yarn.server.resourcemanager.scheduler.capacity.LeafQueue: assignedContainer application=application_1376201383303_0006 container=Container: [ContainerId: container_1376201383303_0006_01_000001, NodeId: hadoop-320-3:36899, NodeHttpAddress: hadoop-320-3:8042, Resource: <memory:2048, vCores:1>, Priority: 0, State: NEW, Token: null, Status: container_id {, app_attempt_id {, application_id {, id: 6, cluster_timestamp: 1376201383303, }, attemptId: 1, }, id: 1, }, state: C_NEW, ] containerId=container_1376201383303_0006_01_000001 queue=default: capacity=1.0, absoluteCapacity=1.0, usedResources=<memory:0, vCores:0>usedCapacity=0.0, absoluteUsedCapacity=0.0, numApps=2, numContainers=0 usedCapacity=0.0 absoluteUsedCapacity=0.0 used=<memory:0, vCores:0> cluster=<memory:49152, vCores:96>
2013-08-11 06:26:21,681 INFO org.apache.hadoop.yarn.server.resourcemanager.scheduler.capacity.ParentQueue: Re-sorting queues since queue: root.default stats: default: capacity=1.0, absoluteCapacity=1.0, usedResources=<memory:2048, vCores:1>usedCapacity=0.041666668, absoluteUsedCapacity=0.041666668, numApps=2, numContainers=1
2013-08-11 06:26:21,681 INFO org.apache.hadoop.yarn.server.resourcemanager.scheduler.capacity.ParentQueue: assignedContainer queue=root usedCapacity=0.041666668 absoluteUsedCapacity=0.041666668 used=<memory:2048, vCores:1> cluster=<memory:49152, vCores:96>
2013-08-11 06:26:21,682 INFO org.apache.hadoop.yarn.server.resourcemanager.rmcontainer.RMContainerImpl: container_1376201383303_0006_01_000001 Container Transitioned from ALLOCATED to ACQUIRED
2013-08-11 06:26:21,683 INFO org.apache.hadoop.yarn.server.resourcemanager.rmapp.attempt.RMAppAttemptImpl: Storing attempt: AppId: application_1376201383303_0006 AttemptId: appattempt_1376201383303_0006_000001 MasterContainer: Container: [ContainerId: container_1376201383303_0006_01_000001, NodeId: hadoop-320-3:36899, NodeHttpAddress: hadoop-320-3:8042, Resource: <memory:2048, vCores:1>, Priority: 0, State: NEW, Token: null, Status: container_id {, app_attempt_id {, application_id {, id: 6, cluster_timestamp: 1376201383303, }, attemptId: 1, }, id: 1, }, state: C_NEW, ]
2013-08-11 06:26:21,683 INFO org.apache.hadoop.yarn.server.resourcemanager.rmapp.attempt.RMAppAttemptImpl: appattempt_1376201383303_0006_000001 State change from SCHEDULED to ALLOCATED_SAVING
2013-08-11 06:26:21,683 INFO org.apache.hadoop.yarn.server.resourcemanager.recovery.RMStateStore: Storing info for attempt: appattempt_1376201383303_0006_000001
2013-08-11 06:26:21,685 INFO org.apache.hadoop.yarn.server.resourcemanager.rmapp.attempt.RMAppAttemptImpl: appattempt_1376201383303_0006_000001 State change from ALLOCATED_SAVING to ALLOCATED
2013-08-11 06:26:21,686 INFO org.apache.hadoop.yarn.server.resourcemanager.amlauncher.AMLauncher: Launching masterappattempt_1376201383303_0006_000001
2013-08-11 06:26:21,687 INFO org.apache.hadoop.yarn.server.resourcemanager.amlauncher.AMLauncher: Setting up container Container: [ContainerId: container_1376201383303_0006_01_000001, NodeId: hadoop-320-3:36899, NodeHttpAddress: hadoop-320-3:8042, Resource: <memory:2048, vCores:1>, Priority: 0, State: NEW, Token: null, Status: container_id {, app_attempt_id {, application_id {, id: 6, cluster_timestamp: 1376201383303, }, attemptId: 1, }, id: 1, }, state: C_NEW, ] for AM appattempt_1376201383303_0006_000001
2013-08-11 06:26:21,687 INFO org.apache.hadoop.yarn.server.resourcemanager.amlauncher.AMLauncher: Command to launch container container_1376201383303_0006_01_000001 : $JAVA_HOME/bin/java -Dlog4j.configuration=container-log4j.properties -Dyarn.app.mapreduce.container.log.dir=<LOG_DIR> -Dyarn.app.mapreduce.container.log.filesize=0 -Dhadoop.root.logger=INFO,CLA  -Xmx1024m org.apache.hadoop.mapreduce.v2.app.MRAppMaster 1><LOG_DIR>/stdout 2><LOG_DIR>/stderr 
2013-08-11 06:26:21,700 INFO org.apache.hadoop.yarn.server.resourcemanager.amlauncher.AMLauncher: Done launching container Container: [ContainerId: container_1376201383303_0006_01_000001, NodeId: hadoop-320-3:36899, NodeHttpAddress: hadoop-320-3:8042, Resource: <memory:2048, vCores:1>, Priority: 0, State: NEW, Token: null, Status: container_id {, app_attempt_id {, application_id {, id: 6, cluster_timestamp: 1376201383303, }, attemptId: 1, }, id: 1, }, state: C_NEW, ] for AM appattempt_1376201383303_0006_000001
2013-08-11 06:26:21,700 INFO org.apache.hadoop.yarn.server.resourcemanager.rmapp.attempt.RMAppAttemptImpl: appattempt_1376201383303_0006_000001 State change from ALLOCATED to LAUNCHED
2013-08-11 06:26:21,711 INFO org.apache.hadoop.yarn.server.resourcemanager.rmcontainer.RMContainerImpl: container_1376201383303_0007_01_000001 Container Transitioned from NEW to ALLOCATED
2013-08-11 06:26:21,712 INFO org.apache.hadoop.yarn.server.resourcemanager.RMAuditLogger: USER=ubuntu	OPERATION=AM Allocated Container	TARGET=SchedulerApp	RESULT=SUCCESS	APPID=application_1376201383303_0007	CONTAINERID=container_1376201383303_0007_01_000001
2013-08-11 06:26:21,712 INFO org.apache.hadoop.yarn.server.resourcemanager.scheduler.common.fica.FiCaSchedulerNode: Assigned container container_1376201383303_0007_01_000001 of capacity <memory:2048, vCores:1> on host hadoop-320-4:46709, which currently has 1 containers, <memory:2048, vCores:1> used and <memory:6144, vCores:15> available
2013-08-11 06:26:21,713 INFO org.apache.hadoop.yarn.server.resourcemanager.scheduler.capacity.LeafQueue: assignedContainer application=application_1376201383303_0007 container=Container: [ContainerId: container_1376201383303_0007_01_000001, NodeId: hadoop-320-4:46709, NodeHttpAddress: hadoop-320-4:8042, Resource: <memory:2048, vCores:1>, Priority: 0, State: NEW, Token: null, Status: container_id {, app_attempt_id {, application_id {, id: 7, cluster_timestamp: 1376201383303, }, attemptId: 1, }, id: 1, }, state: C_NEW, ] containerId=container_1376201383303_0007_01_000001 queue=default: capacity=1.0, absoluteCapacity=1.0, usedResources=<memory:2048, vCores:1>usedCapacity=0.041666668, absoluteUsedCapacity=0.041666668, numApps=2, numContainers=1 usedCapacity=0.041666668 absoluteUsedCapacity=0.041666668 used=<memory:2048, vCores:1> cluster=<memory:49152, vCores:96>
2013-08-11 06:26:21,713 INFO org.apache.hadoop.yarn.server.resourcemanager.scheduler.capacity.ParentQueue: Re-sorting queues since queue: root.default stats: default: capacity=1.0, absoluteCapacity=1.0, usedResources=<memory:4096, vCores:2>usedCapacity=0.083333336, absoluteUsedCapacity=0.083333336, numApps=2, numContainers=2
2013-08-11 06:26:21,713 INFO org.apache.hadoop.yarn.server.resourcemanager.scheduler.capacity.ParentQueue: assignedContainer queue=root usedCapacity=0.083333336 absoluteUsedCapacity=0.083333336 used=<memory:4096, vCores:2> cluster=<memory:49152, vCores:96>
2013-08-11 06:26:21,714 INFO org.apache.hadoop.yarn.server.resourcemanager.rmcontainer.RMContainerImpl: container_1376201383303_0007_01_000001 Container Transitioned from ALLOCATED to ACQUIRED
2013-08-11 06:26:21,715 INFO org.apache.hadoop.yarn.server.resourcemanager.rmapp.attempt.RMAppAttemptImpl: Storing attempt: AppId: application_1376201383303_0007 AttemptId: appattempt_1376201383303_0007_000001 MasterContainer: Container: [ContainerId: container_1376201383303_0007_01_000001, NodeId: hadoop-320-4:46709, NodeHttpAddress: hadoop-320-4:8042, Resource: <memory:2048, vCores:1>, Priority: 0, State: NEW, Token: null, Status: container_id {, app_attempt_id {, application_id {, id: 7, cluster_timestamp: 1376201383303, }, attemptId: 1, }, id: 1, }, state: C_NEW, ]
2013-08-11 06:26:21,715 INFO org.apache.hadoop.yarn.server.resourcemanager.rmapp.attempt.RMAppAttemptImpl: appattempt_1376201383303_0007_000001 State change from SCHEDULED to ALLOCATED_SAVING
2013-08-11 06:26:21,715 INFO org.apache.hadoop.yarn.server.resourcemanager.recovery.RMStateStore: Storing info for attempt: appattempt_1376201383303_0007_000001
2013-08-11 06:26:21,715 INFO org.apache.hadoop.yarn.server.resourcemanager.rmapp.attempt.RMAppAttemptImpl: appattempt_1376201383303_0007_000001 State change from ALLOCATED_SAVING to ALLOCATED
2013-08-11 06:26:21,716 INFO org.apache.hadoop.yarn.server.resourcemanager.amlauncher.AMLauncher: Launching masterappattempt_1376201383303_0007_000001
2013-08-11 06:26:21,717 INFO org.apache.hadoop.yarn.server.resourcemanager.amlauncher.AMLauncher: Setting up container Container: [ContainerId: container_1376201383303_0007_01_000001, NodeId: hadoop-320-4:46709, NodeHttpAddress: hadoop-320-4:8042, Resource: <memory:2048, vCores:1>, Priority: 0, State: NEW, Token: null, Status: container_id {, app_attempt_id {, application_id {, id: 7, cluster_timestamp: 1376201383303, }, attemptId: 1, }, id: 1, }, state: C_NEW, ] for AM appattempt_1376201383303_0007_000001
2013-08-11 06:26:21,718 INFO org.apache.hadoop.yarn.server.resourcemanager.amlauncher.AMLauncher: Command to launch container container_1376201383303_0007_01_000001 : $JAVA_HOME/bin/java -Dlog4j.configuration=container-log4j.properties -Dyarn.app.mapreduce.container.log.dir=<LOG_DIR> -Dyarn.app.mapreduce.container.log.filesize=0 -Dhadoop.root.logger=INFO,CLA  -Xmx1024m org.apache.hadoop.mapreduce.v2.app.MRAppMaster 1><LOG_DIR>/stdout 2><LOG_DIR>/stderr 
2013-08-11 06:26:21,730 INFO org.apache.hadoop.yarn.server.resourcemanager.amlauncher.AMLauncher: Done launching container Container: [ContainerId: container_1376201383303_0007_01_000001, NodeId: hadoop-320-4:46709, NodeHttpAddress: hadoop-320-4:8042, Resource: <memory:2048, vCores:1>, Priority: 0, State: NEW, Token: null, Status: container_id {, app_attempt_id {, application_id {, id: 7, cluster_timestamp: 1376201383303, }, attemptId: 1, }, id: 1, }, state: C_NEW, ] for AM appattempt_1376201383303_0007_000001
2013-08-11 06:26:21,730 INFO org.apache.hadoop.yarn.server.resourcemanager.rmapp.attempt.RMAppAttemptImpl: appattempt_1376201383303_0007_000001 State change from ALLOCATED to LAUNCHED
2013-08-11 06:26:22,004 INFO org.apache.hadoop.yarn.server.resourcemanager.ClientRMService: Storing Application with id application_1376201383303_0008
2013-08-11 06:26:22,007 INFO org.apache.hadoop.yarn.server.resourcemanager.recovery.RMStateStore: Storing info for app: application_1376201383303_0008
2013-08-11 06:26:22,007 INFO org.apache.hadoop.yarn.server.resourcemanager.ClientRMService: Application with id 8 submitted by user ubuntu
2013-08-11 06:26:22,007 INFO org.apache.hadoop.yarn.server.resourcemanager.RMAuditLogger: USER=ubuntu	IP=192.168.100.4	OPERATION=Submit Application Request	TARGET=ClientRMService	RESULT=SUCCESS	APPID=application_1376201383303_0008
2013-08-11 06:26:22,005 INFO org.apache.hadoop.yarn.server.resourcemanager.rmapp.RMAppImpl: application_1376201383303_0008 State change from NEW to SUBMITTED
2013-08-11 06:26:22,007 INFO org.apache.hadoop.yarn.server.resourcemanager.ApplicationMasterService: Registering appattempt_1376201383303_0008_000001
2013-08-11 06:26:22,007 INFO org.apache.hadoop.yarn.server.resourcemanager.rmapp.attempt.RMAppAttemptImpl: appattempt_1376201383303_0008_000001 State change from NEW to SUBMITTED
2013-08-11 06:26:22,008 INFO org.apache.hadoop.yarn.server.resourcemanager.scheduler.capacity.LeafQueue: Application application_1376201383303_0008 from user: ubuntu activated in queue: default
2013-08-11 06:26:22,008 INFO org.apache.hadoop.yarn.server.resourcemanager.scheduler.capacity.LeafQueue: Application added - appId: application_1376201383303_0008 user: org.apache.hadoop.yarn.server.resourcemanager.scheduler.capacity.LeafQueue$User@667b9d6b, leaf-queue: default #user-pending-applications: 0 #user-active-applications: 3 #queue-pending-applications: 0 #queue-active-applications: 3
2013-08-11 06:26:22,008 INFO org.apache.hadoop.yarn.server.resourcemanager.scheduler.capacity.ParentQueue: Application added - appId: application_1376201383303_0008 user: ubuntu leaf-queue of parent: root #applications: 3
2013-08-11 06:26:22,009 INFO org.apache.hadoop.yarn.server.resourcemanager.scheduler.capacity.CapacityScheduler: Application Submission: appattempt_1376201383303_0008_000001, user: ubuntu queue: default: capacity=1.0, absoluteCapacity=1.0, usedResources=<memory:4096, vCores:2>usedCapacity=0.083333336, absoluteUsedCapacity=0.083333336, numApps=3, numContainers=2, currently active: 3
2013-08-11 06:26:22,011 INFO org.apache.hadoop.yarn.server.resourcemanager.rmapp.attempt.RMAppAttemptImpl: appattempt_1376201383303_0008_000001 State change from SUBMITTED to SCHEDULED
2013-08-11 06:26:22,011 INFO org.apache.hadoop.yarn.server.resourcemanager.rmapp.RMAppImpl: application_1376201383303_0008 State change from SUBMITTED to ACCEPTED
2013-08-11 06:26:22,012 INFO org.apache.hadoop.yarn.server.resourcemanager.ClientRMService: Storing Application with id application_1376201383303_0010
2013-08-11 06:26:22,013 INFO org.apache.hadoop.yarn.server.resourcemanager.recovery.RMStateStore: Storing info for app: application_1376201383303_0010
2013-08-11 06:26:22,013 INFO org.apache.hadoop.yarn.server.resourcemanager.ClientRMService: Application with id 10 submitted by user ubuntu
2013-08-11 06:26:22,013 INFO org.apache.hadoop.yarn.server.resourcemanager.RMAuditLogger: USER=ubuntu	IP=192.168.100.4	OPERATION=Submit Application Request	TARGET=ClientRMService	RESULT=SUCCESS	APPID=application_1376201383303_0010
2013-08-11 06:26:22,013 INFO org.apache.hadoop.yarn.server.resourcemanager.ClientRMService: Storing Application with id application_1376201383303_0009
2013-08-11 06:26:22,013 INFO org.apache.hadoop.yarn.server.resourcemanager.recovery.RMStateStore: Storing info for app: application_1376201383303_0009
2013-08-11 06:26:22,013 INFO org.apache.hadoop.yarn.server.resourcemanager.ClientRMService: Application with id 9 submitted by user ubuntu
2013-08-11 06:26:22,013 INFO org.apache.hadoop.yarn.server.resourcemanager.RMAuditLogger: USER=ubuntu	IP=192.168.100.4	OPERATION=Submit Application Request	TARGET=ClientRMService	RESULT=SUCCESS	APPID=application_1376201383303_0009
2013-08-11 06:26:22,013 INFO org.apache.hadoop.yarn.server.resourcemanager.rmapp.RMAppImpl: application_1376201383303_0010 State change from NEW to SUBMITTED
2013-08-11 06:26:22,014 INFO org.apache.hadoop.yarn.server.resourcemanager.rmapp.RMAppImpl: application_1376201383303_0009 State change from NEW to SUBMITTED
2013-08-11 06:26:22,014 INFO org.apache.hadoop.yarn.server.resourcemanager.ApplicationMasterService: Registering appattempt_1376201383303_0010_000001
2013-08-11 06:26:22,014 INFO org.apache.hadoop.yarn.server.resourcemanager.rmapp.attempt.RMAppAttemptImpl: appattempt_1376201383303_0010_000001 State change from NEW to SUBMITTED
2013-08-11 06:26:22,014 INFO org.apache.hadoop.yarn.server.resourcemanager.ApplicationMasterService: Registering appattempt_1376201383303_0009_000001
2013-08-11 06:26:22,014 INFO org.apache.hadoop.yarn.server.resourcemanager.rmapp.attempt.RMAppAttemptImpl: appattempt_1376201383303_0009_000001 State change from NEW to SUBMITTED
2013-08-11 06:26:22,014 INFO org.apache.hadoop.yarn.server.resourcemanager.scheduler.capacity.LeafQueue: Application application_1376201383303_0010 from user: ubuntu activated in queue: default
2013-08-11 06:26:22,015 INFO org.apache.hadoop.yarn.server.resourcemanager.scheduler.capacity.LeafQueue: Application added - appId: application_1376201383303_0010 user: org.apache.hadoop.yarn.server.resourcemanager.scheduler.capacity.LeafQueue$User@667b9d6b, leaf-queue: default #user-pending-applications: 0 #user-active-applications: 4 #queue-pending-applications: 0 #queue-active-applications: 4
2013-08-11 06:26:22,015 INFO org.apache.hadoop.yarn.server.resourcemanager.scheduler.capacity.ParentQueue: Application added - appId: application_1376201383303_0010 user: ubuntu leaf-queue of parent: root #applications: 4
2013-08-11 06:26:22,015 INFO org.apache.hadoop.yarn.server.resourcemanager.scheduler.capacity.CapacityScheduler: Application Submission: appattempt_1376201383303_0010_000001, user: ubuntu queue: default: capacity=1.0, absoluteCapacity=1.0, usedResources=<memory:4096, vCores:2>usedCapacity=0.083333336, absoluteUsedCapacity=0.083333336, numApps=4, numContainers=2, currently active: 4
2013-08-11 06:26:22,015 INFO org.apache.hadoop.yarn.server.resourcemanager.scheduler.capacity.LeafQueue: Application application_1376201383303_0009 from user: ubuntu activated in queue: default
2013-08-11 06:26:22,015 INFO org.apache.hadoop.yarn.server.resourcemanager.scheduler.capacity.LeafQueue: Application added - appId: application_1376201383303_0009 user: org.apache.hadoop.yarn.server.resourcemanager.scheduler.capacity.LeafQueue$User@667b9d6b, leaf-queue: default #user-pending-applications: 0 #user-active-applications: 5 #queue-pending-applications: 0 #queue-active-applications: 5
2013-08-11 06:26:22,015 INFO org.apache.hadoop.yarn.server.resourcemanager.scheduler.capacity.ParentQueue: Application added - appId: application_1376201383303_0009 user: ubuntu leaf-queue of parent: root #applications: 5
2013-08-11 06:26:22,015 INFO org.apache.hadoop.yarn.server.resourcemanager.scheduler.capacity.CapacityScheduler: Application Submission: appattempt_1376201383303_0009_000001, user: ubuntu queue: default: capacity=1.0, absoluteCapacity=1.0, usedResources=<memory:4096, vCores:2>usedCapacity=0.083333336, absoluteUsedCapacity=0.083333336, numApps=5, numContainers=2, currently active: 5
2013-08-11 06:26:22,015 INFO org.apache.hadoop.yarn.server.resourcemanager.rmapp.attempt.RMAppAttemptImpl: appattempt_1376201383303_0010_000001 State change from SUBMITTED to SCHEDULED
2013-08-11 06:26:22,016 INFO org.apache.hadoop.yarn.server.resourcemanager.rmapp.attempt.RMAppAttemptImpl: appattempt_1376201383303_0009_000001 State change from SUBMITTED to SCHEDULED
2013-08-11 06:26:22,016 INFO org.apache.hadoop.yarn.server.resourcemanager.rmapp.RMAppImpl: application_1376201383303_0010 State change from SUBMITTED to ACCEPTED
2013-08-11 06:26:22,016 INFO org.apache.hadoop.yarn.server.resourcemanager.rmapp.RMAppImpl: application_1376201383303_0009 State change from SUBMITTED to ACCEPTED
2013-08-11 06:26:22,154 INFO org.apache.hadoop.yarn.server.resourcemanager.rmcontainer.RMContainerImpl: container_1376201383303_0008_01_000001 Container Transitioned from NEW to ALLOCATED
2013-08-11 06:26:22,154 INFO org.apache.hadoop.yarn.server.resourcemanager.RMAuditLogger: USER=ubuntu	OPERATION=AM Allocated Container	TARGET=SchedulerApp	RESULT=SUCCESS	APPID=application_1376201383303_0008	CONTAINERID=container_1376201383303_0008_01_000001
2013-08-11 06:26:22,154 INFO org.apache.hadoop.yarn.server.resourcemanager.scheduler.common.fica.FiCaSchedulerNode: Assigned container container_1376201383303_0008_01_000001 of capacity <memory:2048, vCores:1> on host hadoop-320-7:37753, which currently has 1 containers, <memory:2048, vCores:1> used and <memory:6144, vCores:15> available
2013-08-11 06:26:22,155 INFO org.apache.hadoop.yarn.server.resourcemanager.scheduler.capacity.LeafQueue: assignedContainer application=application_1376201383303_0008 container=Container: [ContainerId: container_1376201383303_0008_01_000001, NodeId: hadoop-320-7:37753, NodeHttpAddress: hadoop-320-7:8042, Resource: <memory:2048, vCores:1>, Priority: 0, State: NEW, Token: null, Status: container_id {, app_attempt_id {, application_id {, id: 8, cluster_timestamp: 1376201383303, }, attemptId: 1, }, id: 1, }, state: C_NEW, ] containerId=container_1376201383303_0008_01_000001 queue=default: capacity=1.0, absoluteCapacity=1.0, usedResources=<memory:4096, vCores:2>usedCapacity=0.083333336, absoluteUsedCapacity=0.083333336, numApps=5, numContainers=2 usedCapacity=0.083333336 absoluteUsedCapacity=0.083333336 used=<memory:4096, vCores:2> cluster=<memory:49152, vCores:96>
2013-08-11 06:26:22,155 INFO org.apache.hadoop.yarn.server.resourcemanager.rmcontainer.RMContainerImpl: container_1376201383303_0008_01_000001 Container Transitioned from ALLOCATED to ACQUIRED
2013-08-11 06:26:22,155 INFO org.apache.hadoop.yarn.server.resourcemanager.scheduler.capacity.ParentQueue: Re-sorting queues since queue: root.default stats: default: capacity=1.0, absoluteCapacity=1.0, usedResources=<memory:6144, vCores:3>usedCapacity=0.125, absoluteUsedCapacity=0.125, numApps=5, numContainers=3
2013-08-11 06:26:22,156 INFO org.apache.hadoop.yarn.server.resourcemanager.rmapp.attempt.RMAppAttemptImpl: Storing attempt: AppId: application_1376201383303_0008 AttemptId: appattempt_1376201383303_0008_000001 MasterContainer: Container: [ContainerId: container_1376201383303_0008_01_000001, NodeId: hadoop-320-7:37753, NodeHttpAddress: hadoop-320-7:8042, Resource: <memory:2048, vCores:1>, Priority: 0, State: NEW, Token: null, Status: container_id {, app_attempt_id {, application_id {, id: 8, cluster_timestamp: 1376201383303, }, attemptId: 1, }, id: 1, }, state: C_NEW, ]
2013-08-11 06:26:22,157 INFO org.apache.hadoop.yarn.server.resourcemanager.scheduler.capacity.ParentQueue: assignedContainer queue=root usedCapacity=0.125 absoluteUsedCapacity=0.125 used=<memory:6144, vCores:3> cluster=<memory:49152, vCores:96>
2013-08-11 06:26:22,157 INFO org.apache.hadoop.yarn.server.resourcemanager.rmapp.attempt.RMAppAttemptImpl: appattempt_1376201383303_0008_000001 State change from SCHEDULED to ALLOCATED_SAVING
2013-08-11 06:26:22,157 INFO org.apache.hadoop.yarn.server.resourcemanager.recovery.RMStateStore: Storing info for attempt: appattempt_1376201383303_0008_000001
2013-08-11 06:26:22,157 INFO org.apache.hadoop.yarn.server.resourcemanager.rmapp.attempt.RMAppAttemptImpl: appattempt_1376201383303_0008_000001 State change from ALLOCATED_SAVING to ALLOCATED
2013-08-11 06:26:22,158 INFO org.apache.hadoop.yarn.server.resourcemanager.amlauncher.AMLauncher: Launching masterappattempt_1376201383303_0008_000001
2013-08-11 06:26:22,159 INFO org.apache.hadoop.yarn.server.resourcemanager.amlauncher.AMLauncher: Setting up container Container: [ContainerId: container_1376201383303_0008_01_000001, NodeId: hadoop-320-7:37753, NodeHttpAddress: hadoop-320-7:8042, Resource: <memory:2048, vCores:1>, Priority: 0, State: NEW, Token: null, Status: container_id {, app_attempt_id {, application_id {, id: 8, cluster_timestamp: 1376201383303, }, attemptId: 1, }, id: 1, }, state: C_NEW, ] for AM appattempt_1376201383303_0008_000001
2013-08-11 06:26:22,159 INFO org.apache.hadoop.yarn.server.resourcemanager.amlauncher.AMLauncher: Command to launch container container_1376201383303_0008_01_000001 : $JAVA_HOME/bin/java -Dlog4j.configuration=container-log4j.properties -Dyarn.app.mapreduce.container.log.dir=<LOG_DIR> -Dyarn.app.mapreduce.container.log.filesize=0 -Dhadoop.root.logger=INFO,CLA  -Xmx1024m org.apache.hadoop.mapreduce.v2.app.MRAppMaster 1><LOG_DIR>/stdout 2><LOG_DIR>/stderr 
2013-08-11 06:26:22,171 INFO org.apache.hadoop.yarn.server.resourcemanager.amlauncher.AMLauncher: Done launching container Container: [ContainerId: container_1376201383303_0008_01_000001, NodeId: hadoop-320-7:37753, NodeHttpAddress: hadoop-320-7:8042, Resource: <memory:2048, vCores:1>, Priority: 0, State: NEW, Token: null, Status: container_id {, app_attempt_id {, application_id {, id: 8, cluster_timestamp: 1376201383303, }, attemptId: 1, }, id: 1, }, state: C_NEW, ] for AM appattempt_1376201383303_0008_000001
2013-08-11 06:26:22,172 INFO org.apache.hadoop.yarn.server.resourcemanager.rmapp.attempt.RMAppAttemptImpl: appattempt_1376201383303_0008_000001 State change from ALLOCATED to LAUNCHED
2013-08-11 06:26:22,421 INFO org.apache.hadoop.yarn.server.resourcemanager.rmcontainer.RMContainerImpl: container_1376201383303_0009_01_000001 Container Transitioned from NEW to ALLOCATED
2013-08-11 06:26:22,421 INFO org.apache.hadoop.yarn.server.resourcemanager.RMAuditLogger: USER=ubuntu	OPERATION=AM Allocated Container	TARGET=SchedulerApp	RESULT=SUCCESS	APPID=application_1376201383303_0009	CONTAINERID=container_1376201383303_0009_01_000001
2013-08-11 06:26:22,421 INFO org.apache.hadoop.yarn.server.resourcemanager.scheduler.common.fica.FiCaSchedulerNode: Assigned container container_1376201383303_0009_01_000001 of capacity <memory:2048, vCores:1> on host hadoop-320-5:32992, which currently has 1 containers, <memory:2048, vCores:1> used and <memory:6144, vCores:15> available
2013-08-11 06:26:22,422 INFO org.apache.hadoop.yarn.server.resourcemanager.scheduler.capacity.LeafQueue: assignedContainer application=application_1376201383303_0009 container=Container: [ContainerId: container_1376201383303_0009_01_000001, NodeId: hadoop-320-5:32992, NodeHttpAddress: hadoop-320-5:8042, Resource: <memory:2048, vCores:1>, Priority: 0, State: NEW, Token: null, Status: container_id {, app_attempt_id {, application_id {, id: 9, cluster_timestamp: 1376201383303, }, attemptId: 1, }, id: 1, }, state: C_NEW, ] containerId=container_1376201383303_0009_01_000001 queue=default: capacity=1.0, absoluteCapacity=1.0, usedResources=<memory:6144, vCores:3>usedCapacity=0.125, absoluteUsedCapacity=0.125, numApps=5, numContainers=3 usedCapacity=0.125 absoluteUsedCapacity=0.125 used=<memory:6144, vCores:3> cluster=<memory:49152, vCores:96>
2013-08-11 06:26:22,422 INFO org.apache.hadoop.yarn.server.resourcemanager.scheduler.capacity.ParentQueue: Re-sorting queues since queue: root.default stats: default: capacity=1.0, absoluteCapacity=1.0, usedResources=<memory:8192, vCores:4>usedCapacity=0.16666667, absoluteUsedCapacity=0.16666667, numApps=5, numContainers=4
2013-08-11 06:26:22,422 INFO org.apache.hadoop.yarn.server.resourcemanager.scheduler.capacity.ParentQueue: assignedContainer queue=root usedCapacity=0.16666667 absoluteUsedCapacity=0.16666667 used=<memory:8192, vCores:4> cluster=<memory:49152, vCores:96>
2013-08-11 06:26:22,423 INFO org.apache.hadoop.yarn.server.resourcemanager.rmcontainer.RMContainerImpl: container_1376201383303_0009_01_000001 Container Transitioned from ALLOCATED to ACQUIRED
2013-08-11 06:26:22,424 INFO org.apache.hadoop.yarn.server.resourcemanager.rmapp.attempt.RMAppAttemptImpl: Storing attempt: AppId: application_1376201383303_0009 AttemptId: appattempt_1376201383303_0009_000001 MasterContainer: Container: [ContainerId: container_1376201383303_0009_01_000001, NodeId: hadoop-320-5:32992, NodeHttpAddress: hadoop-320-5:8042, Resource: <memory:2048, vCores:1>, Priority: 0, State: NEW, Token: null, Status: container_id {, app_attempt_id {, application_id {, id: 9, cluster_timestamp: 1376201383303, }, attemptId: 1, }, id: 1, }, state: C_NEW, ]
2013-08-11 06:26:22,424 INFO org.apache.hadoop.yarn.server.resourcemanager.rmapp.attempt.RMAppAttemptImpl: appattempt_1376201383303_0009_000001 State change from SCHEDULED to ALLOCATED_SAVING
2013-08-11 06:26:22,424 INFO org.apache.hadoop.yarn.server.resourcemanager.recovery.RMStateStore: Storing info for attempt: appattempt_1376201383303_0009_000001
2013-08-11 06:26:22,425 INFO org.apache.hadoop.yarn.server.resourcemanager.rmapp.attempt.RMAppAttemptImpl: appattempt_1376201383303_0009_000001 State change from ALLOCATED_SAVING to ALLOCATED
2013-08-11 06:26:22,425 INFO org.apache.hadoop.yarn.server.resourcemanager.amlauncher.AMLauncher: Launching masterappattempt_1376201383303_0009_000001
2013-08-11 06:26:22,427 INFO org.apache.hadoop.yarn.server.resourcemanager.amlauncher.AMLauncher: Setting up container Container: [ContainerId: container_1376201383303_0009_01_000001, NodeId: hadoop-320-5:32992, NodeHttpAddress: hadoop-320-5:8042, Resource: <memory:2048, vCores:1>, Priority: 0, State: NEW, Token: null, Status: container_id {, app_attempt_id {, application_id {, id: 9, cluster_timestamp: 1376201383303, }, attemptId: 1, }, id: 1, }, state: C_NEW, ] for AM appattempt_1376201383303_0009_000001
2013-08-11 06:26:22,427 INFO org.apache.hadoop.yarn.server.resourcemanager.amlauncher.AMLauncher: Command to launch container container_1376201383303_0009_01_000001 : $JAVA_HOME/bin/java -Dlog4j.configuration=container-log4j.properties -Dyarn.app.mapreduce.container.log.dir=<LOG_DIR> -Dyarn.app.mapreduce.container.log.filesize=0 -Dhadoop.root.logger=INFO,CLA  -Xmx1024m org.apache.hadoop.mapreduce.v2.app.MRAppMaster 1><LOG_DIR>/stdout 2><LOG_DIR>/stderr 
2013-08-11 06:26:22,439 INFO org.apache.hadoop.yarn.server.resourcemanager.amlauncher.AMLauncher: Done launching container Container: [ContainerId: container_1376201383303_0009_01_000001, NodeId: hadoop-320-5:32992, NodeHttpAddress: hadoop-320-5:8042, Resource: <memory:2048, vCores:1>, Priority: 0, State: NEW, Token: null, Status: container_id {, app_attempt_id {, application_id {, id: 9, cluster_timestamp: 1376201383303, }, attemptId: 1, }, id: 1, }, state: C_NEW, ] for AM appattempt_1376201383303_0009_000001
2013-08-11 06:26:22,439 INFO org.apache.hadoop.yarn.server.resourcemanager.rmapp.attempt.RMAppAttemptImpl: appattempt_1376201383303_0009_000001 State change from ALLOCATED to LAUNCHED
2013-08-11 06:26:22,684 INFO org.apache.hadoop.yarn.server.resourcemanager.rmcontainer.RMContainerImpl: container_1376201383303_0006_01_000001 Container Transitioned from ACQUIRED to RUNNING
2013-08-11 06:26:22,686 INFO org.apache.hadoop.yarn.server.resourcemanager.rmcontainer.RMContainerImpl: container_1376201383303_0010_01_000001 Container Transitioned from NEW to ALLOCATED
2013-08-11 06:26:22,686 INFO org.apache.hadoop.yarn.server.resourcemanager.RMAuditLogger: USER=ubuntu	OPERATION=AM Allocated Container	TARGET=SchedulerApp	RESULT=SUCCESS	APPID=application_1376201383303_0010	CONTAINERID=container_1376201383303_0010_01_000001
2013-08-11 06:26:22,687 INFO org.apache.hadoop.yarn.server.resourcemanager.scheduler.common.fica.FiCaSchedulerNode: Assigned container container_1376201383303_0010_01_000001 of capacity <memory:2048, vCores:1> on host hadoop-320-3:36899, which currently has 2 containers, <memory:4096, vCores:2> used and <memory:4096, vCores:14> available
2013-08-11 06:26:22,688 INFO org.apache.hadoop.yarn.server.resourcemanager.scheduler.capacity.LeafQueue: assignedContainer application=application_1376201383303_0010 container=Container: [ContainerId: container_1376201383303_0010_01_000001, NodeId: hadoop-320-3:36899, NodeHttpAddress: hadoop-320-3:8042, Resource: <memory:2048, vCores:1>, Priority: 0, State: NEW, Token: null, Status: container_id {, app_attempt_id {, application_id {, id: 10, cluster_timestamp: 1376201383303, }, attemptId: 1, }, id: 1, }, state: C_NEW, ] containerId=container_1376201383303_0010_01_000001 queue=default: capacity=1.0, absoluteCapacity=1.0, usedResources=<memory:8192, vCores:4>usedCapacity=0.16666667, absoluteUsedCapacity=0.16666667, numApps=5, numContainers=4 usedCapacity=0.16666667 absoluteUsedCapacity=0.16666667 used=<memory:8192, vCores:4> cluster=<memory:49152, vCores:96>
2013-08-11 06:26:22,688 INFO org.apache.hadoop.yarn.server.resourcemanager.scheduler.capacity.ParentQueue: Re-sorting queues since queue: root.default stats: default: capacity=1.0, absoluteCapacity=1.0, usedResources=<memory:10240, vCores:5>usedCapacity=0.20833333, absoluteUsedCapacity=0.20833333, numApps=5, numContainers=5
2013-08-11 06:26:22,689 INFO org.apache.hadoop.yarn.server.resourcemanager.scheduler.capacity.ParentQueue: assignedContainer queue=root usedCapacity=0.20833333 absoluteUsedCapacity=0.20833333 used=<memory:10240, vCores:5> cluster=<memory:49152, vCores:96>
2013-08-11 06:26:22,690 INFO org.apache.hadoop.yarn.server.resourcemanager.rmcontainer.RMContainerImpl: container_1376201383303_0010_01_000001 Container Transitioned from ALLOCATED to ACQUIRED
2013-08-11 06:26:22,695 INFO org.apache.hadoop.yarn.server.resourcemanager.rmapp.attempt.RMAppAttemptImpl: Storing attempt: AppId: application_1376201383303_0010 AttemptId: appattempt_1376201383303_0010_000001 MasterContainer: Container: [ContainerId: container_1376201383303_0010_01_000001, NodeId: hadoop-320-3:36899, NodeHttpAddress: hadoop-320-3:8042, Resource: <memory:2048, vCores:1>, Priority: 0, State: NEW, Token: null, Status: container_id {, app_attempt_id {, application_id {, id: 10, cluster_timestamp: 1376201383303, }, attemptId: 1, }, id: 1, }, state: C_NEW, ]
2013-08-11 06:26:22,696 INFO org.apache.hadoop.yarn.server.resourcemanager.recovery.RMStateStore: Storing info for attempt: appattempt_1376201383303_0010_000001
2013-08-11 06:26:22,696 INFO org.apache.hadoop.yarn.server.resourcemanager.rmapp.attempt.RMAppAttemptImpl: appattempt_1376201383303_0010_000001 State change from SCHEDULED to ALLOCATED_SAVING
2013-08-11 06:26:22,697 INFO org.apache.hadoop.yarn.server.resourcemanager.rmapp.attempt.RMAppAttemptImpl: appattempt_1376201383303_0010_000001 State change from ALLOCATED_SAVING to ALLOCATED
2013-08-11 06:26:22,697 INFO org.apache.hadoop.yarn.server.resourcemanager.amlauncher.AMLauncher: Launching masterappattempt_1376201383303_0010_000001
2013-08-11 06:26:22,700 INFO org.apache.hadoop.yarn.server.resourcemanager.amlauncher.AMLauncher: Setting up container Container: [ContainerId: container_1376201383303_0010_01_000001, NodeId: hadoop-320-3:36899, NodeHttpAddress: hadoop-320-3:8042, Resource: <memory:2048, vCores:1>, Priority: 0, State: NEW, Token: null, Status: container_id {, app_attempt_id {, application_id {, id: 10, cluster_timestamp: 1376201383303, }, attemptId: 1, }, id: 1, }, state: C_NEW, ] for AM appattempt_1376201383303_0010_000001
2013-08-11 06:26:22,700 INFO org.apache.hadoop.yarn.server.resourcemanager.amlauncher.AMLauncher: Command to launch container container_1376201383303_0010_01_000001 : $JAVA_HOME/bin/java -Dlog4j.configuration=container-log4j.properties -Dyarn.app.mapreduce.container.log.dir=<LOG_DIR> -Dyarn.app.mapreduce.container.log.filesize=0 -Dhadoop.root.logger=INFO,CLA  -Xmx1024m org.apache.hadoop.mapreduce.v2.app.MRAppMaster 1><LOG_DIR>/stdout 2><LOG_DIR>/stderr 
2013-08-11 06:26:22,723 INFO org.apache.hadoop.yarn.server.resourcemanager.rmcontainer.RMContainerImpl: container_1376201383303_0007_01_000001 Container Transitioned from ACQUIRED to RUNNING
2013-08-11 06:26:22,724 INFO org.apache.hadoop.yarn.server.resourcemanager.amlauncher.AMLauncher: Done launching container Container: [ContainerId: container_1376201383303_0010_01_000001, NodeId: hadoop-320-3:36899, NodeHttpAddress: hadoop-320-3:8042, Resource: <memory:2048, vCores:1>, Priority: 0, State: NEW, Token: null, Status: container_id {, app_attempt_id {, application_id {, id: 10, cluster_timestamp: 1376201383303, }, attemptId: 1, }, id: 1, }, state: C_NEW, ] for AM appattempt_1376201383303_0010_000001
2013-08-11 06:26:22,724 INFO org.apache.hadoop.yarn.server.resourcemanager.rmapp.attempt.RMAppAttemptImpl: appattempt_1376201383303_0010_000001 State change from ALLOCATED to LAUNCHED
2013-08-11 06:26:23,159 INFO org.apache.hadoop.yarn.server.resourcemanager.rmcontainer.RMContainerImpl: container_1376201383303_0008_01_000001 Container Transitioned from ACQUIRED to RUNNING
2013-08-11 06:26:23,426 INFO org.apache.hadoop.yarn.server.resourcemanager.rmcontainer.RMContainerImpl: container_1376201383303_0009_01_000001 Container Transitioned from ACQUIRED to RUNNING
2013-08-11 06:26:23,689 INFO org.apache.hadoop.yarn.server.resourcemanager.rmcontainer.RMContainerImpl: container_1376201383303_0010_01_000001 Container Transitioned from ACQUIRED to RUNNING
2013-08-11 06:26:27,582 INFO org.apache.hadoop.yarn.server.resourcemanager.ApplicationMasterService: AM registration appattempt_1376201383303_0006_000001
2013-08-11 06:26:27,583 INFO org.apache.hadoop.yarn.server.resourcemanager.RMAuditLogger: USER=ubuntu	IP=192.168.100.14	OPERATION=Register App Master	TARGET=ApplicationMasterService	RESULT=SUCCESS	APPID=application_1376201383303_0006	APPATTEMPTID=appattempt_1376201383303_0006_000001
2013-08-11 06:26:27,584 INFO org.apache.hadoop.yarn.server.resourcemanager.rmapp.attempt.RMAppAttemptImpl: appattempt_1376201383303_0006_000001 State change from LAUNCHED to RUNNING
2013-08-11 06:26:27,584 INFO org.apache.hadoop.yarn.server.resourcemanager.rmapp.RMAppImpl: application_1376201383303_0006 State change from ACCEPTED to RUNNING
2013-08-11 06:26:28,646 INFO org.apache.hadoop.yarn.server.resourcemanager.ApplicationMasterService: AM registration appattempt_1376201383303_0007_000001
2013-08-11 06:26:28,647 INFO org.apache.hadoop.yarn.server.resourcemanager.RMAuditLogger: USER=ubuntu	IP=192.168.100.15	OPERATION=Register App Master	TARGET=ApplicationMasterService	RESULT=SUCCESS	APPID=application_1376201383303_0007	APPATTEMPTID=appattempt_1376201383303_0007_000001
2013-08-11 06:26:28,648 INFO org.apache.hadoop.yarn.server.resourcemanager.rmapp.attempt.RMAppAttemptImpl: appattempt_1376201383303_0007_000001 State change from LAUNCHED to RUNNING
2013-08-11 06:26:28,648 INFO org.apache.hadoop.yarn.server.resourcemanager.rmapp.RMAppImpl: application_1376201383303_0007 State change from ACCEPTED to RUNNING
2013-08-11 06:26:28,710 INFO org.apache.hadoop.yarn.server.resourcemanager.rmcontainer.RMContainerImpl: container_1376201383303_0006_01_000002 Container Transitioned from NEW to ALLOCATED
2013-08-11 06:26:28,710 INFO org.apache.hadoop.yarn.server.resourcemanager.RMAuditLogger: USER=ubuntu	OPERATION=AM Allocated Container	TARGET=SchedulerApp	RESULT=SUCCESS	APPID=application_1376201383303_0006	CONTAINERID=container_1376201383303_0006_01_000002
2013-08-11 06:26:28,710 INFO org.apache.hadoop.yarn.server.resourcemanager.scheduler.common.fica.FiCaSchedulerNode: Assigned container container_1376201383303_0006_01_000002 of capacity <memory:1024, vCores:1> on host hadoop-320-3:36899, which currently has 3 containers, <memory:5120, vCores:3> used and <memory:3072, vCores:13> available
2013-08-11 06:26:28,711 INFO org.apache.hadoop.yarn.server.resourcemanager.scheduler.capacity.LeafQueue: assignedContainer application=application_1376201383303_0006 container=Container: [ContainerId: container_1376201383303_0006_01_000002, NodeId: hadoop-320-3:36899, NodeHttpAddress: hadoop-320-3:8042, Resource: <memory:1024, vCores:1>, Priority: 20, State: NEW, Token: null, Status: container_id {, app_attempt_id {, application_id {, id: 6, cluster_timestamp: 1376201383303, }, attemptId: 1, }, id: 2, }, state: C_NEW, ] containerId=container_1376201383303_0006_01_000002 queue=default: capacity=1.0, absoluteCapacity=1.0, usedResources=<memory:10240, vCores:5>usedCapacity=0.20833333, absoluteUsedCapacity=0.20833333, numApps=5, numContainers=5 usedCapacity=0.20833333 absoluteUsedCapacity=0.20833333 used=<memory:10240, vCores:5> cluster=<memory:49152, vCores:96>
2013-08-11 06:26:28,712 INFO org.apache.hadoop.yarn.server.resourcemanager.scheduler.capacity.ParentQueue: Re-sorting queues since queue: root.default stats: default: capacity=1.0, absoluteCapacity=1.0, usedResources=<memory:11264, vCores:6>usedCapacity=0.22916667, absoluteUsedCapacity=0.22916667, numApps=5, numContainers=6
2013-08-11 06:26:28,712 INFO org.apache.hadoop.yarn.server.resourcemanager.scheduler.capacity.ParentQueue: assignedContainer queue=root usedCapacity=0.22916667 absoluteUsedCapacity=0.22916667 used=<memory:11264, vCores:6> cluster=<memory:49152, vCores:96>
2013-08-11 06:26:28,712 INFO org.apache.hadoop.yarn.server.resourcemanager.rmcontainer.RMContainerImpl: container_1376201383303_0006_01_000003 Container Transitioned from NEW to ALLOCATED
2013-08-11 06:26:28,713 INFO org.apache.hadoop.yarn.server.resourcemanager.RMAuditLogger: USER=ubuntu	OPERATION=AM Allocated Container	TARGET=SchedulerApp	RESULT=SUCCESS	APPID=application_1376201383303_0006	CONTAINERID=container_1376201383303_0006_01_000003
2013-08-11 06:26:28,713 INFO org.apache.hadoop.yarn.server.resourcemanager.scheduler.common.fica.FiCaSchedulerNode: Assigned container container_1376201383303_0006_01_000003 of capacity <memory:1024, vCores:1> on host hadoop-320-3:36899, which currently has 4 containers, <memory:6144, vCores:4> used and <memory:2048, vCores:12> available
2013-08-11 06:26:28,714 INFO org.apache.hadoop.yarn.server.resourcemanager.scheduler.capacity.LeafQueue: assignedContainer application=application_1376201383303_0006 container=Container: [ContainerId: container_1376201383303_0006_01_000003, NodeId: hadoop-320-3:36899, NodeHttpAddress: hadoop-320-3:8042, Resource: <memory:1024, vCores:1>, Priority: 20, State: NEW, Token: null, Status: container_id {, app_attempt_id {, application_id {, id: 6, cluster_timestamp: 1376201383303, }, attemptId: 1, }, id: 3, }, state: C_NEW, ] containerId=container_1376201383303_0006_01_000003 queue=default: capacity=1.0, absoluteCapacity=1.0, usedResources=<memory:11264, vCores:6>usedCapacity=0.22916667, absoluteUsedCapacity=0.22916667, numApps=5, numContainers=6 usedCapacity=0.22916667 absoluteUsedCapacity=0.22916667 used=<memory:11264, vCores:6> cluster=<memory:49152, vCores:96>
2013-08-11 06:26:28,714 INFO org.apache.hadoop.yarn.server.resourcemanager.scheduler.capacity.ParentQueue: Re-sorting queues since queue: root.default stats: default: capacity=1.0, absoluteCapacity=1.0, usedResources=<memory:12288, vCores:7>usedCapacity=0.25, absoluteUsedCapacity=0.25, numApps=5, numContainers=7
2013-08-11 06:26:28,714 INFO org.apache.hadoop.yarn.server.resourcemanager.scheduler.capacity.ParentQueue: assignedContainer queue=root usedCapacity=0.25 absoluteUsedCapacity=0.25 used=<memory:12288, vCores:7> cluster=<memory:49152, vCores:96>
2013-08-11 06:26:28,715 INFO org.apache.hadoop.yarn.server.resourcemanager.rmcontainer.RMContainerImpl: container_1376201383303_0006_01_000004 Container Transitioned from NEW to ALLOCATED
2013-08-11 06:26:28,715 INFO org.apache.hadoop.yarn.server.resourcemanager.RMAuditLogger: USER=ubuntu	OPERATION=AM Allocated Container	TARGET=SchedulerApp	RESULT=SUCCESS	APPID=application_1376201383303_0006	CONTAINERID=container_1376201383303_0006_01_000004
2013-08-11 06:26:28,715 INFO org.apache.hadoop.yarn.server.resourcemanager.scheduler.common.fica.FiCaSchedulerNode: Assigned container container_1376201383303_0006_01_000004 of capacity <memory:1024, vCores:1> on host hadoop-320-3:36899, which currently has 5 containers, <memory:7168, vCores:5> used and <memory:1024, vCores:11> available
2013-08-11 06:26:28,716 INFO org.apache.hadoop.yarn.server.resourcemanager.scheduler.capacity.LeafQueue: assignedContainer application=application_1376201383303_0006 container=Container: [ContainerId: container_1376201383303_0006_01_000004, NodeId: hadoop-320-3:36899, NodeHttpAddress: hadoop-320-3:8042, Resource: <memory:1024, vCores:1>, Priority: 20, State: NEW, Token: null, Status: container_id {, app_attempt_id {, application_id {, id: 6, cluster_timestamp: 1376201383303, }, attemptId: 1, }, id: 4, }, state: C_NEW, ] containerId=container_1376201383303_0006_01_000004 queue=default: capacity=1.0, absoluteCapacity=1.0, usedResources=<memory:12288, vCores:7>usedCapacity=0.25, absoluteUsedCapacity=0.25, numApps=5, numContainers=7 usedCapacity=0.25 absoluteUsedCapacity=0.25 used=<memory:12288, vCores:7> cluster=<memory:49152, vCores:96>
2013-08-11 06:26:28,716 INFO org.apache.hadoop.yarn.server.resourcemanager.scheduler.capacity.ParentQueue: Re-sorting queues since queue: root.default stats: default: capacity=1.0, absoluteCapacity=1.0, usedResources=<memory:13312, vCores:8>usedCapacity=0.27083334, absoluteUsedCapacity=0.27083334, numApps=5, numContainers=8
2013-08-11 06:26:28,716 INFO org.apache.hadoop.yarn.server.resourcemanager.scheduler.capacity.ParentQueue: assignedContainer queue=root usedCapacity=0.27083334 absoluteUsedCapacity=0.27083334 used=<memory:13312, vCores:8> cluster=<memory:49152, vCores:96>
2013-08-11 06:26:28,717 INFO org.apache.hadoop.yarn.server.resourcemanager.rmcontainer.RMContainerImpl: container_1376201383303_0006_01_000005 Container Transitioned from NEW to ALLOCATED
2013-08-11 06:26:28,717 INFO org.apache.hadoop.yarn.server.resourcemanager.RMAuditLogger: USER=ubuntu	OPERATION=AM Allocated Container	TARGET=SchedulerApp	RESULT=SUCCESS	APPID=application_1376201383303_0006	CONTAINERID=container_1376201383303_0006_01_000005
2013-08-11 06:26:28,717 INFO org.apache.hadoop.yarn.server.resourcemanager.scheduler.common.fica.FiCaSchedulerNode: Assigned container container_1376201383303_0006_01_000005 of capacity <memory:1024, vCores:1> on host hadoop-320-3:36899, which currently has 6 containers, <memory:8192, vCores:6> used and <memory:0, vCores:10> available
2013-08-11 06:26:28,718 INFO org.apache.hadoop.yarn.server.resourcemanager.scheduler.capacity.LeafQueue: assignedContainer application=application_1376201383303_0006 container=Container: [ContainerId: container_1376201383303_0006_01_000005, NodeId: hadoop-320-3:36899, NodeHttpAddress: hadoop-320-3:8042, Resource: <memory:1024, vCores:1>, Priority: 20, State: NEW, Token: null, Status: container_id {, app_attempt_id {, application_id {, id: 6, cluster_timestamp: 1376201383303, }, attemptId: 1, }, id: 5, }, state: C_NEW, ] containerId=container_1376201383303_0006_01_000005 queue=default: capacity=1.0, absoluteCapacity=1.0, usedResources=<memory:13312, vCores:8>usedCapacity=0.27083334, absoluteUsedCapacity=0.27083334, numApps=5, numContainers=8 usedCapacity=0.27083334 absoluteUsedCapacity=0.27083334 used=<memory:13312, vCores:8> cluster=<memory:49152, vCores:96>
2013-08-11 06:26:28,719 INFO org.apache.hadoop.yarn.server.resourcemanager.scheduler.capacity.ParentQueue: Re-sorting queues since queue: root.default stats: default: capacity=1.0, absoluteCapacity=1.0, usedResources=<memory:14336, vCores:9>usedCapacity=0.29166666, absoluteUsedCapacity=0.29166666, numApps=5, numContainers=9
2013-08-11 06:26:28,719 INFO org.apache.hadoop.yarn.server.resourcemanager.scheduler.capacity.ParentQueue: assignedContainer queue=root usedCapacity=0.29166666 absoluteUsedCapacity=0.29166666 used=<memory:14336, vCores:9> cluster=<memory:49152, vCores:96>
2013-08-11 06:26:28,751 INFO org.apache.hadoop.yarn.server.resourcemanager.rmcontainer.RMContainerImpl: container_1376201383303_0006_01_000006 Container Transitioned from NEW to ALLOCATED
2013-08-11 06:26:28,751 INFO org.apache.hadoop.yarn.server.resourcemanager.RMAuditLogger: USER=ubuntu	OPERATION=AM Allocated Container	TARGET=SchedulerApp	RESULT=SUCCESS	APPID=application_1376201383303_0006	CONTAINERID=container_1376201383303_0006_01_000006
2013-08-11 06:26:28,752 INFO org.apache.hadoop.yarn.server.resourcemanager.scheduler.common.fica.FiCaSchedulerNode: Assigned container container_1376201383303_0006_01_000006 of capacity <memory:1024, vCores:1> on host hadoop-320-4:46709, which currently has 2 containers, <memory:3072, vCores:2> used and <memory:5120, vCores:14> available
2013-08-11 06:26:28,753 INFO org.apache.hadoop.yarn.server.resourcemanager.scheduler.capacity.LeafQueue: assignedContainer application=application_1376201383303_0006 container=Container: [ContainerId: container_1376201383303_0006_01_000006, NodeId: hadoop-320-4:46709, NodeHttpAddress: hadoop-320-4:8042, Resource: <memory:1024, vCores:1>, Priority: 20, State: NEW, Token: null, Status: container_id {, app_attempt_id {, application_id {, id: 6, cluster_timestamp: 1376201383303, }, attemptId: 1, }, id: 6, }, state: C_NEW, ] containerId=container_1376201383303_0006_01_000006 queue=default: capacity=1.0, absoluteCapacity=1.0, usedResources=<memory:14336, vCores:9>usedCapacity=0.29166666, absoluteUsedCapacity=0.29166666, numApps=5, numContainers=9 usedCapacity=0.29166666 absoluteUsedCapacity=0.29166666 used=<memory:14336, vCores:9> cluster=<memory:49152, vCores:96>
2013-08-11 06:26:28,753 INFO org.apache.hadoop.yarn.server.resourcemanager.scheduler.capacity.ParentQueue: Re-sorting queues since queue: root.default stats: default: capacity=1.0, absoluteCapacity=1.0, usedResources=<memory:15360, vCores:10>usedCapacity=0.3125, absoluteUsedCapacity=0.3125, numApps=5, numContainers=10
2013-08-11 06:26:28,753 INFO org.apache.hadoop.yarn.server.resourcemanager.scheduler.capacity.ParentQueue: assignedContainer queue=root usedCapacity=0.3125 absoluteUsedCapacity=0.3125 used=<memory:15360, vCores:10> cluster=<memory:49152, vCores:96>
2013-08-11 06:26:28,754 INFO org.apache.hadoop.yarn.server.resourcemanager.rmcontainer.RMContainerImpl: container_1376201383303_0006_01_000007 Container Transitioned from NEW to ALLOCATED
2013-08-11 06:26:28,754 INFO org.apache.hadoop.yarn.server.resourcemanager.RMAuditLogger: USER=ubuntu	OPERATION=AM Allocated Container	TARGET=SchedulerApp	RESULT=SUCCESS	APPID=application_1376201383303_0006	CONTAINERID=container_1376201383303_0006_01_000007
2013-08-11 06:26:28,754 INFO org.apache.hadoop.yarn.server.resourcemanager.scheduler.common.fica.FiCaSchedulerNode: Assigned container container_1376201383303_0006_01_000007 of capacity <memory:1024, vCores:1> on host hadoop-320-4:46709, which currently has 3 containers, <memory:4096, vCores:3> used and <memory:4096, vCores:13> available
2013-08-11 06:26:28,755 INFO org.apache.hadoop.yarn.server.resourcemanager.scheduler.capacity.LeafQueue: assignedContainer application=application_1376201383303_0006 container=Container: [ContainerId: container_1376201383303_0006_01_000007, NodeId: hadoop-320-4:46709, NodeHttpAddress: hadoop-320-4:8042, Resource: <memory:1024, vCores:1>, Priority: 20, State: NEW, Token: null, Status: container_id {, app_attempt_id {, application_id {, id: 6, cluster_timestamp: 1376201383303, }, attemptId: 1, }, id: 7, }, state: C_NEW, ] containerId=container_1376201383303_0006_01_000007 queue=default: capacity=1.0, absoluteCapacity=1.0, usedResources=<memory:15360, vCores:10>usedCapacity=0.3125, absoluteUsedCapacity=0.3125, numApps=5, numContainers=10 usedCapacity=0.3125 absoluteUsedCapacity=0.3125 used=<memory:15360, vCores:10> cluster=<memory:49152, vCores:96>
2013-08-11 06:26:28,755 INFO org.apache.hadoop.yarn.server.resourcemanager.scheduler.capacity.ParentQueue: Re-sorting queues since queue: root.default stats: default: capacity=1.0, absoluteCapacity=1.0, usedResources=<memory:16384, vCores:11>usedCapacity=0.33333334, absoluteUsedCapacity=0.33333334, numApps=5, numContainers=11
2013-08-11 06:26:28,756 INFO org.apache.hadoop.yarn.server.resourcemanager.scheduler.capacity.ParentQueue: assignedContainer queue=root usedCapacity=0.33333334 absoluteUsedCapacity=0.33333334 used=<memory:16384, vCores:11> cluster=<memory:49152, vCores:96>
2013-08-11 06:26:28,756 INFO org.apache.hadoop.yarn.server.resourcemanager.rmcontainer.RMContainerImpl: container_1376201383303_0006_01_000008 Container Transitioned from NEW to ALLOCATED
2013-08-11 06:26:28,756 INFO org.apache.hadoop.yarn.server.resourcemanager.RMAuditLogger: USER=ubuntu	OPERATION=AM Allocated Container	TARGET=SchedulerApp	RESULT=SUCCESS	APPID=application_1376201383303_0006	CONTAINERID=container_1376201383303_0006_01_000008
2013-08-11 06:26:28,756 INFO org.apache.hadoop.yarn.server.resourcemanager.scheduler.common.fica.FiCaSchedulerNode: Assigned container container_1376201383303_0006_01_000008 of capacity <memory:1024, vCores:1> on host hadoop-320-4:46709, which currently has 4 containers, <memory:5120, vCores:4> used and <memory:3072, vCores:12> available
2013-08-11 06:26:28,757 INFO org.apache.hadoop.yarn.server.resourcemanager.scheduler.capacity.LeafQueue: assignedContainer application=application_1376201383303_0006 container=Container: [ContainerId: container_1376201383303_0006_01_000008, NodeId: hadoop-320-4:46709, NodeHttpAddress: hadoop-320-4:8042, Resource: <memory:1024, vCores:1>, Priority: 20, State: NEW, Token: null, Status: container_id {, app_attempt_id {, application_id {, id: 6, cluster_timestamp: 1376201383303, }, attemptId: 1, }, id: 8, }, state: C_NEW, ] containerId=container_1376201383303_0006_01_000008 queue=default: capacity=1.0, absoluteCapacity=1.0, usedResources=<memory:16384, vCores:11>usedCapacity=0.33333334, absoluteUsedCapacity=0.33333334, numApps=5, numContainers=11 usedCapacity=0.33333334 absoluteUsedCapacity=0.33333334 used=<memory:16384, vCores:11> cluster=<memory:49152, vCores:96>
2013-08-11 06:26:28,758 INFO org.apache.hadoop.yarn.server.resourcemanager.scheduler.capacity.ParentQueue: Re-sorting queues since queue: root.default stats: default: capacity=1.0, absoluteCapacity=1.0, usedResources=<memory:17408, vCores:12>usedCapacity=0.35416666, absoluteUsedCapacity=0.35416666, numApps=5, numContainers=12
2013-08-11 06:26:28,758 INFO org.apache.hadoop.yarn.server.resourcemanager.scheduler.capacity.ParentQueue: assignedContainer queue=root usedCapacity=0.35416666 absoluteUsedCapacity=0.35416666 used=<memory:17408, vCores:12> cluster=<memory:49152, vCores:96>
2013-08-11 06:26:28,758 INFO org.apache.hadoop.yarn.server.resourcemanager.rmcontainer.RMContainerImpl: container_1376201383303_0006_01_000009 Container Transitioned from NEW to ALLOCATED
2013-08-11 06:26:28,758 INFO org.apache.hadoop.yarn.server.resourcemanager.RMAuditLogger: USER=ubuntu	OPERATION=AM Allocated Container	TARGET=SchedulerApp	RESULT=SUCCESS	APPID=application_1376201383303_0006	CONTAINERID=container_1376201383303_0006_01_000009
2013-08-11 06:26:28,759 INFO org.apache.hadoop.yarn.server.resourcemanager.scheduler.common.fica.FiCaSchedulerNode: Assigned container container_1376201383303_0006_01_000009 of capacity <memory:1024, vCores:1> on host hadoop-320-4:46709, which currently has 5 containers, <memory:6144, vCores:5> used and <memory:2048, vCores:11> available
2013-08-11 06:26:28,760 INFO org.apache.hadoop.yarn.server.resourcemanager.scheduler.capacity.LeafQueue: assignedContainer application=application_1376201383303_0006 container=Container: [ContainerId: container_1376201383303_0006_01_000009, NodeId: hadoop-320-4:46709, NodeHttpAddress: hadoop-320-4:8042, Resource: <memory:1024, vCores:1>, Priority: 20, State: NEW, Token: null, Status: container_id {, app_attempt_id {, application_id {, id: 6, cluster_timestamp: 1376201383303, }, attemptId: 1, }, id: 9, }, state: C_NEW, ] containerId=container_1376201383303_0006_01_000009 queue=default: capacity=1.0, absoluteCapacity=1.0, usedResources=<memory:17408, vCores:12>usedCapacity=0.35416666, absoluteUsedCapacity=0.35416666, numApps=5, numContainers=12 usedCapacity=0.35416666 absoluteUsedCapacity=0.35416666 used=<memory:17408, vCores:12> cluster=<memory:49152, vCores:96>
2013-08-11 06:26:28,760 INFO org.apache.hadoop.yarn.server.resourcemanager.scheduler.capacity.ParentQueue: Re-sorting queues since queue: root.default stats: default: capacity=1.0, absoluteCapacity=1.0, usedResources=<memory:18432, vCores:13>usedCapacity=0.375, absoluteUsedCapacity=0.375, numApps=5, numContainers=13
2013-08-11 06:26:28,760 INFO org.apache.hadoop.yarn.server.resourcemanager.scheduler.capacity.ParentQueue: assignedContainer queue=root usedCapacity=0.375 absoluteUsedCapacity=0.375 used=<memory:18432, vCores:13> cluster=<memory:49152, vCores:96>
2013-08-11 06:26:28,760 INFO org.apache.hadoop.yarn.server.resourcemanager.rmcontainer.RMContainerImpl: container_1376201383303_0006_01_000010 Container Transitioned from NEW to ALLOCATED
2013-08-11 06:26:28,761 INFO org.apache.hadoop.yarn.server.resourcemanager.RMAuditLogger: USER=ubuntu	OPERATION=AM Allocated Container	TARGET=SchedulerApp	RESULT=SUCCESS	APPID=application_1376201383303_0006	CONTAINERID=container_1376201383303_0006_01_000010
2013-08-11 06:26:28,761 INFO org.apache.hadoop.yarn.server.resourcemanager.scheduler.common.fica.FiCaSchedulerNode: Assigned container container_1376201383303_0006_01_000010 of capacity <memory:1024, vCores:1> on host hadoop-320-4:46709, which currently has 6 containers, <memory:7168, vCores:6> used and <memory:1024, vCores:10> available
2013-08-11 06:26:28,762 INFO org.apache.hadoop.yarn.server.resourcemanager.scheduler.capacity.LeafQueue: assignedContainer application=application_1376201383303_0006 container=Container: [ContainerId: container_1376201383303_0006_01_000010, NodeId: hadoop-320-4:46709, NodeHttpAddress: hadoop-320-4:8042, Resource: <memory:1024, vCores:1>, Priority: 20, State: NEW, Token: null, Status: container_id {, app_attempt_id {, application_id {, id: 6, cluster_timestamp: 1376201383303, }, attemptId: 1, }, id: 10, }, state: C_NEW, ] containerId=container_1376201383303_0006_01_000010 queue=default: capacity=1.0, absoluteCapacity=1.0, usedResources=<memory:18432, vCores:13>usedCapacity=0.375, absoluteUsedCapacity=0.375, numApps=5, numContainers=13 usedCapacity=0.375 absoluteUsedCapacity=0.375 used=<memory:18432, vCores:13> cluster=<memory:49152, vCores:96>
2013-08-11 06:26:28,762 INFO org.apache.hadoop.yarn.server.resourcemanager.scheduler.capacity.ParentQueue: Re-sorting queues since queue: root.default stats: default: capacity=1.0, absoluteCapacity=1.0, usedResources=<memory:19456, vCores:14>usedCapacity=0.39583334, absoluteUsedCapacity=0.39583334, numApps=5, numContainers=14
2013-08-11 06:26:28,762 INFO org.apache.hadoop.yarn.server.resourcemanager.scheduler.capacity.ParentQueue: assignedContainer queue=root usedCapacity=0.39583334 absoluteUsedCapacity=0.39583334 used=<memory:19456, vCores:14> cluster=<memory:49152, vCores:96>
2013-08-11 06:26:28,763 INFO org.apache.hadoop.yarn.server.resourcemanager.rmcontainer.RMContainerImpl: container_1376201383303_0006_01_000011 Container Transitioned from NEW to ALLOCATED
2013-08-11 06:26:28,763 INFO org.apache.hadoop.yarn.server.resourcemanager.RMAuditLogger: USER=ubuntu	OPERATION=AM Allocated Container	TARGET=SchedulerApp	RESULT=SUCCESS	APPID=application_1376201383303_0006	CONTAINERID=container_1376201383303_0006_01_000011
2013-08-11 06:26:28,763 INFO org.apache.hadoop.yarn.server.resourcemanager.scheduler.common.fica.FiCaSchedulerNode: Assigned container container_1376201383303_0006_01_000011 of capacity <memory:1024, vCores:1> on host hadoop-320-4:46709, which currently has 7 containers, <memory:8192, vCores:7> used and <memory:0, vCores:9> available
2013-08-11 06:26:28,764 INFO org.apache.hadoop.yarn.server.resourcemanager.scheduler.capacity.LeafQueue: assignedContainer application=application_1376201383303_0006 container=Container: [ContainerId: container_1376201383303_0006_01_000011, NodeId: hadoop-320-4:46709, NodeHttpAddress: hadoop-320-4:8042, Resource: <memory:1024, vCores:1>, Priority: 20, State: NEW, Token: null, Status: container_id {, app_attempt_id {, application_id {, id: 6, cluster_timestamp: 1376201383303, }, attemptId: 1, }, id: 11, }, state: C_NEW, ] containerId=container_1376201383303_0006_01_000011 queue=default: capacity=1.0, absoluteCapacity=1.0, usedResources=<memory:19456, vCores:14>usedCapacity=0.39583334, absoluteUsedCapacity=0.39583334, numApps=5, numContainers=14 usedCapacity=0.39583334 absoluteUsedCapacity=0.39583334 used=<memory:19456, vCores:14> cluster=<memory:49152, vCores:96>
2013-08-11 06:26:28,764 INFO org.apache.hadoop.yarn.server.resourcemanager.scheduler.capacity.ParentQueue: Re-sorting queues since queue: root.default stats: default: capacity=1.0, absoluteCapacity=1.0, usedResources=<memory:20480, vCores:15>usedCapacity=0.41666666, absoluteUsedCapacity=0.41666666, numApps=5, numContainers=15
2013-08-11 06:26:28,764 INFO org.apache.hadoop.yarn.server.resourcemanager.scheduler.capacity.ParentQueue: assignedContainer queue=root usedCapacity=0.41666666 absoluteUsedCapacity=0.41666666 used=<memory:20480, vCores:15> cluster=<memory:49152, vCores:96>
2013-08-11 06:26:28,848 INFO org.apache.hadoop.yarn.server.resourcemanager.ApplicationMasterService: AM registration appattempt_1376201383303_0010_000001
2013-08-11 06:26:28,850 INFO org.apache.hadoop.yarn.server.resourcemanager.RMAuditLogger: USER=ubuntu	IP=192.168.100.14	OPERATION=Register App Master	TARGET=ApplicationMasterService	RESULT=SUCCESS	APPID=application_1376201383303_0010	APPATTEMPTID=appattempt_1376201383303_0010_000001
2013-08-11 06:26:28,851 INFO org.apache.hadoop.yarn.server.resourcemanager.rmapp.attempt.RMAppAttemptImpl: appattempt_1376201383303_0010_000001 State change from LAUNCHED to RUNNING
2013-08-11 06:26:28,851 INFO org.apache.hadoop.yarn.server.resourcemanager.rmapp.RMAppImpl: application_1376201383303_0010 State change from ACCEPTED to RUNNING
2013-08-11 06:26:28,967 INFO org.apache.hadoop.yarn.server.resourcemanager.rmcontainer.RMContainerImpl: container_1376201383303_0006_01_000012 Container Transitioned from NEW to ALLOCATED
2013-08-11 06:26:28,967 INFO org.apache.hadoop.yarn.server.resourcemanager.RMAuditLogger: USER=ubuntu	OPERATION=AM Allocated Container	TARGET=SchedulerApp	RESULT=SUCCESS	APPID=application_1376201383303_0006	CONTAINERID=container_1376201383303_0006_01_000012
2013-08-11 06:26:28,968 INFO org.apache.hadoop.yarn.server.resourcemanager.scheduler.common.fica.FiCaSchedulerNode: Assigned container container_1376201383303_0006_01_000012 of capacity <memory:1024, vCores:1> on host hadoop-320-6:35360, which currently has 1 containers, <memory:1024, vCores:1> used and <memory:7168, vCores:15> available
2013-08-11 06:26:28,969 INFO org.apache.hadoop.yarn.server.resourcemanager.scheduler.capacity.LeafQueue: assignedContainer application=application_1376201383303_0006 container=Container: [ContainerId: container_1376201383303_0006_01_000012, NodeId: hadoop-320-6:35360, NodeHttpAddress: hadoop-320-6:8042, Resource: <memory:1024, vCores:1>, Priority: 20, State: NEW, Token: null, Status: container_id {, app_attempt_id {, application_id {, id: 6, cluster_timestamp: 1376201383303, }, attemptId: 1, }, id: 12, }, state: C_NEW, ] containerId=container_1376201383303_0006_01_000012 queue=default: capacity=1.0, absoluteCapacity=1.0, usedResources=<memory:20480, vCores:15>usedCapacity=0.41666666, absoluteUsedCapacity=0.41666666, numApps=5, numContainers=15 usedCapacity=0.41666666 absoluteUsedCapacity=0.41666666 used=<memory:20480, vCores:15> cluster=<memory:49152, vCores:96>
2013-08-11 06:26:28,969 INFO org.apache.hadoop.yarn.server.resourcemanager.scheduler.capacity.ParentQueue: Re-sorting queues since queue: root.default stats: default: capacity=1.0, absoluteCapacity=1.0, usedResources=<memory:21504, vCores:16>usedCapacity=0.4375, absoluteUsedCapacity=0.4375, numApps=5, numContainers=16
2013-08-11 06:26:28,969 INFO org.apache.hadoop.yarn.server.resourcemanager.scheduler.capacity.ParentQueue: assignedContainer queue=root usedCapacity=0.4375 absoluteUsedCapacity=0.4375 used=<memory:21504, vCores:16> cluster=<memory:49152, vCores:96>
2013-08-11 06:26:28,970 INFO org.apache.hadoop.yarn.server.resourcemanager.rmcontainer.RMContainerImpl: container_1376201383303_0006_01_000013 Container Transitioned from NEW to ALLOCATED
2013-08-11 06:26:28,970 INFO org.apache.hadoop.yarn.server.resourcemanager.RMAuditLogger: USER=ubuntu	OPERATION=AM Allocated Container	TARGET=SchedulerApp	RESULT=SUCCESS	APPID=application_1376201383303_0006	CONTAINERID=container_1376201383303_0006_01_000013
2013-08-11 06:26:28,970 INFO org.apache.hadoop.yarn.server.resourcemanager.scheduler.common.fica.FiCaSchedulerNode: Assigned container container_1376201383303_0006_01_000013 of capacity <memory:1024, vCores:1> on host hadoop-320-6:35360, which currently has 2 containers, <memory:2048, vCores:2> used and <memory:6144, vCores:14> available
2013-08-11 06:26:28,971 INFO org.apache.hadoop.yarn.server.resourcemanager.scheduler.capacity.LeafQueue: assignedContainer application=application_1376201383303_0006 container=Container: [ContainerId: container_1376201383303_0006_01_000013, NodeId: hadoop-320-6:35360, NodeHttpAddress: hadoop-320-6:8042, Resource: <memory:1024, vCores:1>, Priority: 20, State: NEW, Token: null, Status: container_id {, app_attempt_id {, application_id {, id: 6, cluster_timestamp: 1376201383303, }, attemptId: 1, }, id: 13, }, state: C_NEW, ] containerId=container_1376201383303_0006_01_000013 queue=default: capacity=1.0, absoluteCapacity=1.0, usedResources=<memory:21504, vCores:16>usedCapacity=0.4375, absoluteUsedCapacity=0.4375, numApps=5, numContainers=16 usedCapacity=0.4375 absoluteUsedCapacity=0.4375 used=<memory:21504, vCores:16> cluster=<memory:49152, vCores:96>
2013-08-11 06:26:28,971 INFO org.apache.hadoop.yarn.server.resourcemanager.scheduler.capacity.ParentQueue: Re-sorting queues since queue: root.default stats: default: capacity=1.0, absoluteCapacity=1.0, usedResources=<memory:22528, vCores:17>usedCapacity=0.45833334, absoluteUsedCapacity=0.45833334, numApps=5, numContainers=17
2013-08-11 06:26:28,971 INFO org.apache.hadoop.yarn.server.resourcemanager.scheduler.capacity.ParentQueue: assignedContainer queue=root usedCapacity=0.45833334 absoluteUsedCapacity=0.45833334 used=<memory:22528, vCores:17> cluster=<memory:49152, vCores:96>
2013-08-11 06:26:28,972 INFO org.apache.hadoop.yarn.server.resourcemanager.rmcontainer.RMContainerImpl: container_1376201383303_0006_01_000014 Container Transitioned from NEW to ALLOCATED
2013-08-11 06:26:28,972 INFO org.apache.hadoop.yarn.server.resourcemanager.RMAuditLogger: USER=ubuntu	OPERATION=AM Allocated Container	TARGET=SchedulerApp	RESULT=SUCCESS	APPID=application_1376201383303_0006	CONTAINERID=container_1376201383303_0006_01_000014
2013-08-11 06:26:28,972 INFO org.apache.hadoop.yarn.server.resourcemanager.scheduler.common.fica.FiCaSchedulerNode: Assigned container container_1376201383303_0006_01_000014 of capacity <memory:1024, vCores:1> on host hadoop-320-6:35360, which currently has 3 containers, <memory:3072, vCores:3> used and <memory:5120, vCores:13> available
2013-08-11 06:26:28,973 INFO org.apache.hadoop.yarn.server.resourcemanager.scheduler.capacity.LeafQueue: assignedContainer application=application_1376201383303_0006 container=Container: [ContainerId: container_1376201383303_0006_01_000014, NodeId: hadoop-320-6:35360, NodeHttpAddress: hadoop-320-6:8042, Resource: <memory:1024, vCores:1>, Priority: 20, State: NEW, Token: null, Status: container_id {, app_attempt_id {, application_id {, id: 6, cluster_timestamp: 1376201383303, }, attemptId: 1, }, id: 14, }, state: C_NEW, ] containerId=container_1376201383303_0006_01_000014 queue=default: capacity=1.0, absoluteCapacity=1.0, usedResources=<memory:22528, vCores:17>usedCapacity=0.45833334, absoluteUsedCapacity=0.45833334, numApps=5, numContainers=17 usedCapacity=0.45833334 absoluteUsedCapacity=0.45833334 used=<memory:22528, vCores:17> cluster=<memory:49152, vCores:96>
2013-08-11 06:26:28,973 INFO org.apache.hadoop.yarn.server.resourcemanager.scheduler.capacity.ParentQueue: Re-sorting queues since queue: root.default stats: default: capacity=1.0, absoluteCapacity=1.0, usedResources=<memory:23552, vCores:18>usedCapacity=0.47916666, absoluteUsedCapacity=0.47916666, numApps=5, numContainers=18
2013-08-11 06:26:28,974 INFO org.apache.hadoop.yarn.server.resourcemanager.scheduler.capacity.ParentQueue: assignedContainer queue=root usedCapacity=0.47916666 absoluteUsedCapacity=0.47916666 used=<memory:23552, vCores:18> cluster=<memory:49152, vCores:96>
2013-08-11 06:26:28,974 INFO org.apache.hadoop.yarn.server.resourcemanager.rmcontainer.RMContainerImpl: container_1376201383303_0006_01_000015 Container Transitioned from NEW to ALLOCATED
2013-08-11 06:26:28,974 INFO org.apache.hadoop.yarn.server.resourcemanager.RMAuditLogger: USER=ubuntu	OPERATION=AM Allocated Container	TARGET=SchedulerApp	RESULT=SUCCESS	APPID=application_1376201383303_0006	CONTAINERID=container_1376201383303_0006_01_000015
2013-08-11 06:26:28,974 INFO org.apache.hadoop.yarn.server.resourcemanager.scheduler.common.fica.FiCaSchedulerNode: Assigned container container_1376201383303_0006_01_000015 of capacity <memory:1024, vCores:1> on host hadoop-320-6:35360, which currently has 4 containers, <memory:4096, vCores:4> used and <memory:4096, vCores:12> available
2013-08-11 06:26:28,975 INFO org.apache.hadoop.yarn.server.resourcemanager.scheduler.capacity.LeafQueue: assignedContainer application=application_1376201383303_0006 container=Container: [ContainerId: container_1376201383303_0006_01_000015, NodeId: hadoop-320-6:35360, NodeHttpAddress: hadoop-320-6:8042, Resource: <memory:1024, vCores:1>, Priority: 20, State: NEW, Token: null, Status: container_id {, app_attempt_id {, application_id {, id: 6, cluster_timestamp: 1376201383303, }, attemptId: 1, }, id: 15, }, state: C_NEW, ] containerId=container_1376201383303_0006_01_000015 queue=default: capacity=1.0, absoluteCapacity=1.0, usedResources=<memory:23552, vCores:18>usedCapacity=0.47916666, absoluteUsedCapacity=0.47916666, numApps=5, numContainers=18 usedCapacity=0.47916666 absoluteUsedCapacity=0.47916666 used=<memory:23552, vCores:18> cluster=<memory:49152, vCores:96>
2013-08-11 06:26:28,975 INFO org.apache.hadoop.yarn.server.resourcemanager.scheduler.capacity.ParentQueue: Re-sorting queues since queue: root.default stats: default: capacity=1.0, absoluteCapacity=1.0, usedResources=<memory:24576, vCores:19>usedCapacity=0.5, absoluteUsedCapacity=0.5, numApps=5, numContainers=19
2013-08-11 06:26:28,976 INFO org.apache.hadoop.yarn.server.resourcemanager.scheduler.capacity.ParentQueue: assignedContainer queue=root usedCapacity=0.5 absoluteUsedCapacity=0.5 used=<memory:24576, vCores:19> cluster=<memory:49152, vCores:96>
2013-08-11 06:26:28,976 INFO org.apache.hadoop.yarn.server.resourcemanager.rmcontainer.RMContainerImpl: container_1376201383303_0006_01_000016 Container Transitioned from NEW to ALLOCATED
2013-08-11 06:26:28,976 INFO org.apache.hadoop.yarn.server.resourcemanager.RMAuditLogger: USER=ubuntu	OPERATION=AM Allocated Container	TARGET=SchedulerApp	RESULT=SUCCESS	APPID=application_1376201383303_0006	CONTAINERID=container_1376201383303_0006_01_000016
2013-08-11 06:26:28,976 INFO org.apache.hadoop.yarn.server.resourcemanager.scheduler.common.fica.FiCaSchedulerNode: Assigned container container_1376201383303_0006_01_000016 of capacity <memory:1024, vCores:1> on host hadoop-320-6:35360, which currently has 5 containers, <memory:5120, vCores:5> used and <memory:3072, vCores:11> available
2013-08-11 06:26:28,977 INFO org.apache.hadoop.yarn.server.resourcemanager.scheduler.capacity.LeafQueue: assignedContainer application=application_1376201383303_0006 container=Container: [ContainerId: container_1376201383303_0006_01_000016, NodeId: hadoop-320-6:35360, NodeHttpAddress: hadoop-320-6:8042, Resource: <memory:1024, vCores:1>, Priority: 20, State: NEW, Token: null, Status: container_id {, app_attempt_id {, application_id {, id: 6, cluster_timestamp: 1376201383303, }, attemptId: 1, }, id: 16, }, state: C_NEW, ] containerId=container_1376201383303_0006_01_000016 queue=default: capacity=1.0, absoluteCapacity=1.0, usedResources=<memory:24576, vCores:19>usedCapacity=0.5, absoluteUsedCapacity=0.5, numApps=5, numContainers=19 usedCapacity=0.5 absoluteUsedCapacity=0.5 used=<memory:24576, vCores:19> cluster=<memory:49152, vCores:96>
2013-08-11 06:26:28,978 INFO org.apache.hadoop.yarn.server.resourcemanager.scheduler.capacity.ParentQueue: Re-sorting queues since queue: root.default stats: default: capacity=1.0, absoluteCapacity=1.0, usedResources=<memory:25600, vCores:20>usedCapacity=0.5208333, absoluteUsedCapacity=0.5208333, numApps=5, numContainers=20
2013-08-11 06:26:28,978 INFO org.apache.hadoop.yarn.server.resourcemanager.scheduler.capacity.ParentQueue: assignedContainer queue=root usedCapacity=0.5208333 absoluteUsedCapacity=0.5208333 used=<memory:25600, vCores:20> cluster=<memory:49152, vCores:96>
2013-08-11 06:26:28,978 INFO org.apache.hadoop.yarn.server.resourcemanager.rmcontainer.RMContainerImpl: container_1376201383303_0006_01_000017 Container Transitioned from NEW to ALLOCATED
2013-08-11 06:26:28,978 INFO org.apache.hadoop.yarn.server.resourcemanager.RMAuditLogger: USER=ubuntu	OPERATION=AM Allocated Container	TARGET=SchedulerApp	RESULT=SUCCESS	APPID=application_1376201383303_0006	CONTAINERID=container_1376201383303_0006_01_000017
2013-08-11 06:26:28,979 INFO org.apache.hadoop.yarn.server.resourcemanager.scheduler.common.fica.FiCaSchedulerNode: Assigned container container_1376201383303_0006_01_000017 of capacity <memory:1024, vCores:1> on host hadoop-320-6:35360, which currently has 6 containers, <memory:6144, vCores:6> used and <memory:2048, vCores:10> available
2013-08-11 06:26:28,979 INFO org.apache.hadoop.yarn.server.resourcemanager.scheduler.capacity.LeafQueue: assignedContainer application=application_1376201383303_0006 container=Container: [ContainerId: container_1376201383303_0006_01_000017, NodeId: hadoop-320-6:35360, NodeHttpAddress: hadoop-320-6:8042, Resource: <memory:1024, vCores:1>, Priority: 20, State: NEW, Token: null, Status: container_id {, app_attempt_id {, application_id {, id: 6, cluster_timestamp: 1376201383303, }, attemptId: 1, }, id: 17, }, state: C_NEW, ] containerId=container_1376201383303_0006_01_000017 queue=default: capacity=1.0, absoluteCapacity=1.0, usedResources=<memory:25600, vCores:20>usedCapacity=0.5208333, absoluteUsedCapacity=0.5208333, numApps=5, numContainers=20 usedCapacity=0.5208333 absoluteUsedCapacity=0.5208333 used=<memory:25600, vCores:20> cluster=<memory:49152, vCores:96>
2013-08-11 06:26:28,980 INFO org.apache.hadoop.yarn.server.resourcemanager.scheduler.capacity.ParentQueue: Re-sorting queues since queue: root.default stats: default: capacity=1.0, absoluteCapacity=1.0, usedResources=<memory:26624, vCores:21>usedCapacity=0.5416667, absoluteUsedCapacity=0.5416667, numApps=5, numContainers=21
2013-08-11 06:26:28,980 INFO org.apache.hadoop.yarn.server.resourcemanager.scheduler.capacity.ParentQueue: assignedContainer queue=root usedCapacity=0.5416667 absoluteUsedCapacity=0.5416667 used=<memory:26624, vCores:21> cluster=<memory:49152, vCores:96>
2013-08-11 06:26:28,980 INFO org.apache.hadoop.yarn.server.resourcemanager.rmcontainer.RMContainerImpl: container_1376201383303_0006_01_000018 Container Transitioned from NEW to ALLOCATED
2013-08-11 06:26:28,981 INFO org.apache.hadoop.yarn.server.resourcemanager.RMAuditLogger: USER=ubuntu	OPERATION=AM Allocated Container	TARGET=SchedulerApp	RESULT=SUCCESS	APPID=application_1376201383303_0006	CONTAINERID=container_1376201383303_0006_01_000018
2013-08-11 06:26:28,981 INFO org.apache.hadoop.yarn.server.resourcemanager.scheduler.common.fica.FiCaSchedulerNode: Assigned container container_1376201383303_0006_01_000018 of capacity <memory:1024, vCores:1> on host hadoop-320-6:35360, which currently has 7 containers, <memory:7168, vCores:7> used and <memory:1024, vCores:9> available
2013-08-11 06:26:28,982 INFO org.apache.hadoop.yarn.server.resourcemanager.scheduler.capacity.LeafQueue: assignedContainer application=application_1376201383303_0006 container=Container: [ContainerId: container_1376201383303_0006_01_000018, NodeId: hadoop-320-6:35360, NodeHttpAddress: hadoop-320-6:8042, Resource: <memory:1024, vCores:1>, Priority: 20, State: NEW, Token: null, Status: container_id {, app_attempt_id {, application_id {, id: 6, cluster_timestamp: 1376201383303, }, attemptId: 1, }, id: 18, }, state: C_NEW, ] containerId=container_1376201383303_0006_01_000018 queue=default: capacity=1.0, absoluteCapacity=1.0, usedResources=<memory:26624, vCores:21>usedCapacity=0.5416667, absoluteUsedCapacity=0.5416667, numApps=5, numContainers=21 usedCapacity=0.5416667 absoluteUsedCapacity=0.5416667 used=<memory:26624, vCores:21> cluster=<memory:49152, vCores:96>
2013-08-11 06:26:28,982 INFO org.apache.hadoop.yarn.server.resourcemanager.scheduler.capacity.ParentQueue: Re-sorting queues since queue: root.default stats: default: capacity=1.0, absoluteCapacity=1.0, usedResources=<memory:27648, vCores:22>usedCapacity=0.5625, absoluteUsedCapacity=0.5625, numApps=5, numContainers=22
2013-08-11 06:26:28,982 INFO org.apache.hadoop.yarn.server.resourcemanager.scheduler.capacity.ParentQueue: assignedContainer queue=root usedCapacity=0.5625 absoluteUsedCapacity=0.5625 used=<memory:27648, vCores:22> cluster=<memory:49152, vCores:96>
2013-08-11 06:26:28,983 INFO org.apache.hadoop.yarn.server.resourcemanager.rmcontainer.RMContainerImpl: container_1376201383303_0006_01_000019 Container Transitioned from NEW to ALLOCATED
2013-08-11 06:26:28,983 INFO org.apache.hadoop.yarn.server.resourcemanager.RMAuditLogger: USER=ubuntu	OPERATION=AM Allocated Container	TARGET=SchedulerApp	RESULT=SUCCESS	APPID=application_1376201383303_0006	CONTAINERID=container_1376201383303_0006_01_000019
2013-08-11 06:26:28,983 INFO org.apache.hadoop.yarn.server.resourcemanager.scheduler.common.fica.FiCaSchedulerNode: Assigned container container_1376201383303_0006_01_000019 of capacity <memory:1024, vCores:1> on host hadoop-320-6:35360, which currently has 8 containers, <memory:8192, vCores:8> used and <memory:0, vCores:8> available
2013-08-11 06:26:28,984 INFO org.apache.hadoop.yarn.server.resourcemanager.scheduler.capacity.LeafQueue: assignedContainer application=application_1376201383303_0006 container=Container: [ContainerId: container_1376201383303_0006_01_000019, NodeId: hadoop-320-6:35360, NodeHttpAddress: hadoop-320-6:8042, Resource: <memory:1024, vCores:1>, Priority: 20, State: NEW, Token: null, Status: container_id {, app_attempt_id {, application_id {, id: 6, cluster_timestamp: 1376201383303, }, attemptId: 1, }, id: 19, }, state: C_NEW, ] containerId=container_1376201383303_0006_01_000019 queue=default: capacity=1.0, absoluteCapacity=1.0, usedResources=<memory:27648, vCores:22>usedCapacity=0.5625, absoluteUsedCapacity=0.5625, numApps=5, numContainers=22 usedCapacity=0.5625 absoluteUsedCapacity=0.5625 used=<memory:27648, vCores:22> cluster=<memory:49152, vCores:96>
2013-08-11 06:26:28,984 INFO org.apache.hadoop.yarn.server.resourcemanager.scheduler.capacity.ParentQueue: Re-sorting queues since queue: root.default stats: default: capacity=1.0, absoluteCapacity=1.0, usedResources=<memory:28672, vCores:23>usedCapacity=0.5833333, absoluteUsedCapacity=0.5833333, numApps=5, numContainers=23
2013-08-11 06:26:28,984 INFO org.apache.hadoop.yarn.server.resourcemanager.scheduler.capacity.ParentQueue: assignedContainer queue=root usedCapacity=0.5833333 absoluteUsedCapacity=0.5833333 used=<memory:28672, vCores:23> cluster=<memory:49152, vCores:96>
2013-08-11 06:26:29,031 INFO org.apache.hadoop.yarn.server.resourcemanager.rmcontainer.RMContainerImpl: container_1376201383303_0006_01_000020 Container Transitioned from NEW to ALLOCATED
2013-08-11 06:26:29,031 INFO org.apache.hadoop.yarn.server.resourcemanager.RMAuditLogger: USER=ubuntu	OPERATION=AM Allocated Container	TARGET=SchedulerApp	RESULT=SUCCESS	APPID=application_1376201383303_0006	CONTAINERID=container_1376201383303_0006_01_000020
2013-08-11 06:26:29,031 INFO org.apache.hadoop.yarn.server.resourcemanager.scheduler.common.fica.FiCaSchedulerNode: Assigned container container_1376201383303_0006_01_000020 of capacity <memory:1024, vCores:1> on host hadoop-320-2:40354, which currently has 1 containers, <memory:1024, vCores:1> used and <memory:7168, vCores:15> available
2013-08-11 06:26:29,033 INFO org.apache.hadoop.yarn.server.resourcemanager.scheduler.capacity.LeafQueue: assignedContainer application=application_1376201383303_0006 container=Container: [ContainerId: container_1376201383303_0006_01_000020, NodeId: hadoop-320-2:40354, NodeHttpAddress: hadoop-320-2:8042, Resource: <memory:1024, vCores:1>, Priority: 20, State: NEW, Token: null, Status: container_id {, app_attempt_id {, application_id {, id: 6, cluster_timestamp: 1376201383303, }, attemptId: 1, }, id: 20, }, state: C_NEW, ] containerId=container_1376201383303_0006_01_000020 queue=default: capacity=1.0, absoluteCapacity=1.0, usedResources=<memory:28672, vCores:23>usedCapacity=0.5833333, absoluteUsedCapacity=0.5833333, numApps=5, numContainers=23 usedCapacity=0.5833333 absoluteUsedCapacity=0.5833333 used=<memory:28672, vCores:23> cluster=<memory:49152, vCores:96>
2013-08-11 06:26:29,033 INFO org.apache.hadoop.yarn.server.resourcemanager.scheduler.capacity.ParentQueue: Re-sorting queues since queue: root.default stats: default: capacity=1.0, absoluteCapacity=1.0, usedResources=<memory:29696, vCores:24>usedCapacity=0.6041667, absoluteUsedCapacity=0.6041667, numApps=5, numContainers=24
2013-08-11 06:26:29,033 INFO org.apache.hadoop.yarn.server.resourcemanager.scheduler.capacity.ParentQueue: assignedContainer queue=root usedCapacity=0.6041667 absoluteUsedCapacity=0.6041667 used=<memory:29696, vCores:24> cluster=<memory:49152, vCores:96>
2013-08-11 06:26:29,033 INFO org.apache.hadoop.yarn.server.resourcemanager.rmcontainer.RMContainerImpl: container_1376201383303_0006_01_000021 Container Transitioned from NEW to ALLOCATED
2013-08-11 06:26:29,034 INFO org.apache.hadoop.yarn.server.resourcemanager.RMAuditLogger: USER=ubuntu	OPERATION=AM Allocated Container	TARGET=SchedulerApp	RESULT=SUCCESS	APPID=application_1376201383303_0006	CONTAINERID=container_1376201383303_0006_01_000021
2013-08-11 06:26:29,034 INFO org.apache.hadoop.yarn.server.resourcemanager.scheduler.common.fica.FiCaSchedulerNode: Assigned container container_1376201383303_0006_01_000021 of capacity <memory:1024, vCores:1> on host hadoop-320-2:40354, which currently has 2 containers, <memory:2048, vCores:2> used and <memory:6144, vCores:14> available
2013-08-11 06:26:29,035 INFO org.apache.hadoop.yarn.server.resourcemanager.scheduler.capacity.LeafQueue: assignedContainer application=application_1376201383303_0006 container=Container: [ContainerId: container_1376201383303_0006_01_000021, NodeId: hadoop-320-2:40354, NodeHttpAddress: hadoop-320-2:8042, Resource: <memory:1024, vCores:1>, Priority: 20, State: NEW, Token: null, Status: container_id {, app_attempt_id {, application_id {, id: 6, cluster_timestamp: 1376201383303, }, attemptId: 1, }, id: 21, }, state: C_NEW, ] containerId=container_1376201383303_0006_01_000021 queue=default: capacity=1.0, absoluteCapacity=1.0, usedResources=<memory:29696, vCores:24>usedCapacity=0.6041667, absoluteUsedCapacity=0.6041667, numApps=5, numContainers=24 usedCapacity=0.6041667 absoluteUsedCapacity=0.6041667 used=<memory:29696, vCores:24> cluster=<memory:49152, vCores:96>
2013-08-11 06:26:29,035 INFO org.apache.hadoop.yarn.server.resourcemanager.scheduler.capacity.ParentQueue: Re-sorting queues since queue: root.default stats: default: capacity=1.0, absoluteCapacity=1.0, usedResources=<memory:30720, vCores:25>usedCapacity=0.625, absoluteUsedCapacity=0.625, numApps=5, numContainers=25
2013-08-11 06:26:29,035 INFO org.apache.hadoop.yarn.server.resourcemanager.scheduler.capacity.ParentQueue: assignedContainer queue=root usedCapacity=0.625 absoluteUsedCapacity=0.625 used=<memory:30720, vCores:25> cluster=<memory:49152, vCores:96>
2013-08-11 06:26:29,036 INFO org.apache.hadoop.yarn.server.resourcemanager.rmcontainer.RMContainerImpl: container_1376201383303_0006_01_000022 Container Transitioned from NEW to ALLOCATED
2013-08-11 06:26:29,036 INFO org.apache.hadoop.yarn.server.resourcemanager.RMAuditLogger: USER=ubuntu	OPERATION=AM Allocated Container	TARGET=SchedulerApp	RESULT=SUCCESS	APPID=application_1376201383303_0006	CONTAINERID=container_1376201383303_0006_01_000022
2013-08-11 06:26:29,036 INFO org.apache.hadoop.yarn.server.resourcemanager.scheduler.common.fica.FiCaSchedulerNode: Assigned container container_1376201383303_0006_01_000022 of capacity <memory:1024, vCores:1> on host hadoop-320-2:40354, which currently has 3 containers, <memory:3072, vCores:3> used and <memory:5120, vCores:13> available
2013-08-11 06:26:29,037 INFO org.apache.hadoop.yarn.server.resourcemanager.scheduler.capacity.LeafQueue: assignedContainer application=application_1376201383303_0006 container=Container: [ContainerId: container_1376201383303_0006_01_000022, NodeId: hadoop-320-2:40354, NodeHttpAddress: hadoop-320-2:8042, Resource: <memory:1024, vCores:1>, Priority: 20, State: NEW, Token: null, Status: container_id {, app_attempt_id {, application_id {, id: 6, cluster_timestamp: 1376201383303, }, attemptId: 1, }, id: 22, }, state: C_NEW, ] containerId=container_1376201383303_0006_01_000022 queue=default: capacity=1.0, absoluteCapacity=1.0, usedResources=<memory:30720, vCores:25>usedCapacity=0.625, absoluteUsedCapacity=0.625, numApps=5, numContainers=25 usedCapacity=0.625 absoluteUsedCapacity=0.625 used=<memory:30720, vCores:25> cluster=<memory:49152, vCores:96>
2013-08-11 06:26:29,037 INFO org.apache.hadoop.yarn.server.resourcemanager.scheduler.capacity.ParentQueue: Re-sorting queues since queue: root.default stats: default: capacity=1.0, absoluteCapacity=1.0, usedResources=<memory:31744, vCores:26>usedCapacity=0.6458333, absoluteUsedCapacity=0.6458333, numApps=5, numContainers=26
2013-08-11 06:26:29,037 INFO org.apache.hadoop.yarn.server.resourcemanager.scheduler.capacity.ParentQueue: assignedContainer queue=root usedCapacity=0.6458333 absoluteUsedCapacity=0.6458333 used=<memory:31744, vCores:26> cluster=<memory:49152, vCores:96>
2013-08-11 06:26:29,038 INFO org.apache.hadoop.yarn.server.resourcemanager.rmcontainer.RMContainerImpl: container_1376201383303_0006_01_000023 Container Transitioned from NEW to ALLOCATED
2013-08-11 06:26:29,038 INFO org.apache.hadoop.yarn.server.resourcemanager.RMAuditLogger: USER=ubuntu	OPERATION=AM Allocated Container	TARGET=SchedulerApp	RESULT=SUCCESS	APPID=application_1376201383303_0006	CONTAINERID=container_1376201383303_0006_01_000023
2013-08-11 06:26:29,038 INFO org.apache.hadoop.yarn.server.resourcemanager.scheduler.common.fica.FiCaSchedulerNode: Assigned container container_1376201383303_0006_01_000023 of capacity <memory:1024, vCores:1> on host hadoop-320-2:40354, which currently has 4 containers, <memory:4096, vCores:4> used and <memory:4096, vCores:12> available
2013-08-11 06:26:29,039 INFO org.apache.hadoop.yarn.server.resourcemanager.scheduler.capacity.LeafQueue: assignedContainer application=application_1376201383303_0006 container=Container: [ContainerId: container_1376201383303_0006_01_000023, NodeId: hadoop-320-2:40354, NodeHttpAddress: hadoop-320-2:8042, Resource: <memory:1024, vCores:1>, Priority: 20, State: NEW, Token: null, Status: container_id {, app_attempt_id {, application_id {, id: 6, cluster_timestamp: 1376201383303, }, attemptId: 1, }, id: 23, }, state: C_NEW, ] containerId=container_1376201383303_0006_01_000023 queue=default: capacity=1.0, absoluteCapacity=1.0, usedResources=<memory:31744, vCores:26>usedCapacity=0.6458333, absoluteUsedCapacity=0.6458333, numApps=5, numContainers=26 usedCapacity=0.6458333 absoluteUsedCapacity=0.6458333 used=<memory:31744, vCores:26> cluster=<memory:49152, vCores:96>
2013-08-11 06:26:29,039 INFO org.apache.hadoop.yarn.server.resourcemanager.scheduler.capacity.ParentQueue: Re-sorting queues since queue: root.default stats: default: capacity=1.0, absoluteCapacity=1.0, usedResources=<memory:32768, vCores:27>usedCapacity=0.6666667, absoluteUsedCapacity=0.6666667, numApps=5, numContainers=27
2013-08-11 06:26:29,039 INFO org.apache.hadoop.yarn.server.resourcemanager.scheduler.capacity.ParentQueue: assignedContainer queue=root usedCapacity=0.6666667 absoluteUsedCapacity=0.6666667 used=<memory:32768, vCores:27> cluster=<memory:49152, vCores:96>
2013-08-11 06:26:29,040 INFO org.apache.hadoop.yarn.server.resourcemanager.rmcontainer.RMContainerImpl: container_1376201383303_0006_01_000024 Container Transitioned from NEW to ALLOCATED
2013-08-11 06:26:29,040 INFO org.apache.hadoop.yarn.server.resourcemanager.RMAuditLogger: USER=ubuntu	OPERATION=AM Allocated Container	TARGET=SchedulerApp	RESULT=SUCCESS	APPID=application_1376201383303_0006	CONTAINERID=container_1376201383303_0006_01_000024
2013-08-11 06:26:29,040 INFO org.apache.hadoop.yarn.server.resourcemanager.scheduler.common.fica.FiCaSchedulerNode: Assigned container container_1376201383303_0006_01_000024 of capacity <memory:1024, vCores:1> on host hadoop-320-2:40354, which currently has 5 containers, <memory:5120, vCores:5> used and <memory:3072, vCores:11> available
2013-08-11 06:26:29,041 INFO org.apache.hadoop.yarn.server.resourcemanager.scheduler.capacity.LeafQueue: assignedContainer application=application_1376201383303_0006 container=Container: [ContainerId: container_1376201383303_0006_01_000024, NodeId: hadoop-320-2:40354, NodeHttpAddress: hadoop-320-2:8042, Resource: <memory:1024, vCores:1>, Priority: 20, State: NEW, Token: null, Status: container_id {, app_attempt_id {, application_id {, id: 6, cluster_timestamp: 1376201383303, }, attemptId: 1, }, id: 24, }, state: C_NEW, ] containerId=container_1376201383303_0006_01_000024 queue=default: capacity=1.0, absoluteCapacity=1.0, usedResources=<memory:32768, vCores:27>usedCapacity=0.6666667, absoluteUsedCapacity=0.6666667, numApps=5, numContainers=27 usedCapacity=0.6666667 absoluteUsedCapacity=0.6666667 used=<memory:32768, vCores:27> cluster=<memory:49152, vCores:96>
2013-08-11 06:26:29,041 INFO org.apache.hadoop.yarn.server.resourcemanager.scheduler.capacity.ParentQueue: Re-sorting queues since queue: root.default stats: default: capacity=1.0, absoluteCapacity=1.0, usedResources=<memory:33792, vCores:28>usedCapacity=0.6875, absoluteUsedCapacity=0.6875, numApps=5, numContainers=28
2013-08-11 06:26:29,042 INFO org.apache.hadoop.yarn.server.resourcemanager.scheduler.capacity.ParentQueue: assignedContainer queue=root usedCapacity=0.6875 absoluteUsedCapacity=0.6875 used=<memory:33792, vCores:28> cluster=<memory:49152, vCores:96>
2013-08-11 06:26:29,042 INFO org.apache.hadoop.yarn.server.resourcemanager.rmcontainer.RMContainerImpl: container_1376201383303_0006_01_000025 Container Transitioned from NEW to ALLOCATED
2013-08-11 06:26:29,042 INFO org.apache.hadoop.yarn.server.resourcemanager.RMAuditLogger: USER=ubuntu	OPERATION=AM Allocated Container	TARGET=SchedulerApp	RESULT=SUCCESS	APPID=application_1376201383303_0006	CONTAINERID=container_1376201383303_0006_01_000025
2013-08-11 06:26:29,042 INFO org.apache.hadoop.yarn.server.resourcemanager.scheduler.common.fica.FiCaSchedulerNode: Assigned container container_1376201383303_0006_01_000025 of capacity <memory:1024, vCores:1> on host hadoop-320-2:40354, which currently has 6 containers, <memory:6144, vCores:6> used and <memory:2048, vCores:10> available
2013-08-11 06:26:29,043 INFO org.apache.hadoop.yarn.server.resourcemanager.scheduler.capacity.LeafQueue: assignedContainer application=application_1376201383303_0006 container=Container: [ContainerId: container_1376201383303_0006_01_000025, NodeId: hadoop-320-2:40354, NodeHttpAddress: hadoop-320-2:8042, Resource: <memory:1024, vCores:1>, Priority: 20, State: NEW, Token: null, Status: container_id {, app_attempt_id {, application_id {, id: 6, cluster_timestamp: 1376201383303, }, attemptId: 1, }, id: 25, }, state: C_NEW, ] containerId=container_1376201383303_0006_01_000025 queue=default: capacity=1.0, absoluteCapacity=1.0, usedResources=<memory:33792, vCores:28>usedCapacity=0.6875, absoluteUsedCapacity=0.6875, numApps=5, numContainers=28 usedCapacity=0.6875 absoluteUsedCapacity=0.6875 used=<memory:33792, vCores:28> cluster=<memory:49152, vCores:96>
2013-08-11 06:26:29,043 INFO org.apache.hadoop.yarn.server.resourcemanager.scheduler.capacity.ParentQueue: Re-sorting queues since queue: root.default stats: default: capacity=1.0, absoluteCapacity=1.0, usedResources=<memory:34816, vCores:29>usedCapacity=0.7083333, absoluteUsedCapacity=0.7083333, numApps=5, numContainers=29
2013-08-11 06:26:29,044 INFO org.apache.hadoop.yarn.server.resourcemanager.scheduler.capacity.ParentQueue: assignedContainer queue=root usedCapacity=0.7083333 absoluteUsedCapacity=0.7083333 used=<memory:34816, vCores:29> cluster=<memory:49152, vCores:96>
2013-08-11 06:26:29,044 INFO org.apache.hadoop.yarn.server.resourcemanager.rmcontainer.RMContainerImpl: container_1376201383303_0006_01_000026 Container Transitioned from NEW to ALLOCATED
2013-08-11 06:26:29,044 INFO org.apache.hadoop.yarn.server.resourcemanager.RMAuditLogger: USER=ubuntu	OPERATION=AM Allocated Container	TARGET=SchedulerApp	RESULT=SUCCESS	APPID=application_1376201383303_0006	CONTAINERID=container_1376201383303_0006_01_000026
2013-08-11 06:26:29,044 INFO org.apache.hadoop.yarn.server.resourcemanager.scheduler.common.fica.FiCaSchedulerNode: Assigned container container_1376201383303_0006_01_000026 of capacity <memory:1024, vCores:1> on host hadoop-320-2:40354, which currently has 7 containers, <memory:7168, vCores:7> used and <memory:1024, vCores:9> available
2013-08-11 06:26:29,045 INFO org.apache.hadoop.yarn.server.resourcemanager.scheduler.capacity.LeafQueue: assignedContainer application=application_1376201383303_0006 container=Container: [ContainerId: container_1376201383303_0006_01_000026, NodeId: hadoop-320-2:40354, NodeHttpAddress: hadoop-320-2:8042, Resource: <memory:1024, vCores:1>, Priority: 20, State: NEW, Token: null, Status: container_id {, app_attempt_id {, application_id {, id: 6, cluster_timestamp: 1376201383303, }, attemptId: 1, }, id: 26, }, state: C_NEW, ] containerId=container_1376201383303_0006_01_000026 queue=default: capacity=1.0, absoluteCapacity=1.0, usedResources=<memory:34816, vCores:29>usedCapacity=0.7083333, absoluteUsedCapacity=0.7083333, numApps=5, numContainers=29 usedCapacity=0.7083333 absoluteUsedCapacity=0.7083333 used=<memory:34816, vCores:29> cluster=<memory:49152, vCores:96>
2013-08-11 06:26:29,046 INFO org.apache.hadoop.yarn.server.resourcemanager.scheduler.capacity.ParentQueue: Re-sorting queues since queue: root.default stats: default: capacity=1.0, absoluteCapacity=1.0, usedResources=<memory:35840, vCores:30>usedCapacity=0.7291667, absoluteUsedCapacity=0.7291667, numApps=5, numContainers=30
2013-08-11 06:26:29,046 INFO org.apache.hadoop.yarn.server.resourcemanager.scheduler.capacity.ParentQueue: assignedContainer queue=root usedCapacity=0.7291667 absoluteUsedCapacity=0.7291667 used=<memory:35840, vCores:30> cluster=<memory:49152, vCores:96>
2013-08-11 06:26:29,046 INFO org.apache.hadoop.yarn.server.resourcemanager.rmcontainer.RMContainerImpl: container_1376201383303_0006_01_000027 Container Transitioned from NEW to ALLOCATED
2013-08-11 06:26:29,046 INFO org.apache.hadoop.yarn.server.resourcemanager.RMAuditLogger: USER=ubuntu	OPERATION=AM Allocated Container	TARGET=SchedulerApp	RESULT=SUCCESS	APPID=application_1376201383303_0006	CONTAINERID=container_1376201383303_0006_01_000027
2013-08-11 06:26:29,047 INFO org.apache.hadoop.yarn.server.resourcemanager.scheduler.common.fica.FiCaSchedulerNode: Assigned container container_1376201383303_0006_01_000027 of capacity <memory:1024, vCores:1> on host hadoop-320-2:40354, which currently has 8 containers, <memory:8192, vCores:8> used and <memory:0, vCores:8> available
2013-08-11 06:26:29,048 INFO org.apache.hadoop.yarn.server.resourcemanager.scheduler.capacity.LeafQueue: assignedContainer application=application_1376201383303_0006 container=Container: [ContainerId: container_1376201383303_0006_01_000027, NodeId: hadoop-320-2:40354, NodeHttpAddress: hadoop-320-2:8042, Resource: <memory:1024, vCores:1>, Priority: 20, State: NEW, Token: null, Status: container_id {, app_attempt_id {, application_id {, id: 6, cluster_timestamp: 1376201383303, }, attemptId: 1, }, id: 27, }, state: C_NEW, ] containerId=container_1376201383303_0006_01_000027 queue=default: capacity=1.0, absoluteCapacity=1.0, usedResources=<memory:35840, vCores:30>usedCapacity=0.7291667, absoluteUsedCapacity=0.7291667, numApps=5, numContainers=30 usedCapacity=0.7291667 absoluteUsedCapacity=0.7291667 used=<memory:35840, vCores:30> cluster=<memory:49152, vCores:96>
2013-08-11 06:26:29,048 INFO org.apache.hadoop.yarn.server.resourcemanager.scheduler.capacity.ParentQueue: Re-sorting queues since queue: root.default stats: default: capacity=1.0, absoluteCapacity=1.0, usedResources=<memory:36864, vCores:31>usedCapacity=0.75, absoluteUsedCapacity=0.75, numApps=5, numContainers=31
2013-08-11 06:26:29,048 INFO org.apache.hadoop.yarn.server.resourcemanager.scheduler.capacity.ParentQueue: assignedContainer queue=root usedCapacity=0.75 absoluteUsedCapacity=0.75 used=<memory:36864, vCores:31> cluster=<memory:49152, vCores:96>
2013-08-11 06:26:29,192 INFO org.apache.hadoop.yarn.server.resourcemanager.rmcontainer.RMContainerImpl: container_1376201383303_0006_01_000028 Container Transitioned from NEW to ALLOCATED
2013-08-11 06:26:29,192 INFO org.apache.hadoop.yarn.server.resourcemanager.RMAuditLogger: USER=ubuntu	OPERATION=AM Allocated Container	TARGET=SchedulerApp	RESULT=SUCCESS	APPID=application_1376201383303_0006	CONTAINERID=container_1376201383303_0006_01_000028
2013-08-11 06:26:29,192 INFO org.apache.hadoop.yarn.server.resourcemanager.scheduler.common.fica.FiCaSchedulerNode: Assigned container container_1376201383303_0006_01_000028 of capacity <memory:1024, vCores:1> on host hadoop-320-7:37753, which currently has 2 containers, <memory:3072, vCores:2> used and <memory:5120, vCores:14> available
2013-08-11 06:26:29,193 INFO org.apache.hadoop.yarn.server.resourcemanager.scheduler.capacity.LeafQueue: assignedContainer application=application_1376201383303_0006 container=Container: [ContainerId: container_1376201383303_0006_01_000028, NodeId: hadoop-320-7:37753, NodeHttpAddress: hadoop-320-7:8042, Resource: <memory:1024, vCores:1>, Priority: 20, State: NEW, Token: null, Status: container_id {, app_attempt_id {, application_id {, id: 6, cluster_timestamp: 1376201383303, }, attemptId: 1, }, id: 28, }, state: C_NEW, ] containerId=container_1376201383303_0006_01_000028 queue=default: capacity=1.0, absoluteCapacity=1.0, usedResources=<memory:36864, vCores:31>usedCapacity=0.75, absoluteUsedCapacity=0.75, numApps=5, numContainers=31 usedCapacity=0.75 absoluteUsedCapacity=0.75 used=<memory:36864, vCores:31> cluster=<memory:49152, vCores:96>
2013-08-11 06:26:29,194 INFO org.apache.hadoop.yarn.server.resourcemanager.scheduler.capacity.ParentQueue: Re-sorting queues since queue: root.default stats: default: capacity=1.0, absoluteCapacity=1.0, usedResources=<memory:37888, vCores:32>usedCapacity=0.7708333, absoluteUsedCapacity=0.7708333, numApps=5, numContainers=32
2013-08-11 06:26:29,194 INFO org.apache.hadoop.yarn.server.resourcemanager.scheduler.capacity.ParentQueue: assignedContainer queue=root usedCapacity=0.7708333 absoluteUsedCapacity=0.7708333 used=<memory:37888, vCores:32> cluster=<memory:49152, vCores:96>
2013-08-11 06:26:29,194 INFO org.apache.hadoop.yarn.server.resourcemanager.rmcontainer.RMContainerImpl: container_1376201383303_0006_01_000029 Container Transitioned from NEW to ALLOCATED
2013-08-11 06:26:29,194 INFO org.apache.hadoop.yarn.server.resourcemanager.RMAuditLogger: USER=ubuntu	OPERATION=AM Allocated Container	TARGET=SchedulerApp	RESULT=SUCCESS	APPID=application_1376201383303_0006	CONTAINERID=container_1376201383303_0006_01_000029
2013-08-11 06:26:29,195 INFO org.apache.hadoop.yarn.server.resourcemanager.scheduler.common.fica.FiCaSchedulerNode: Assigned container container_1376201383303_0006_01_000029 of capacity <memory:1024, vCores:1> on host hadoop-320-7:37753, which currently has 3 containers, <memory:4096, vCores:3> used and <memory:4096, vCores:13> available
2013-08-11 06:26:29,196 INFO org.apache.hadoop.yarn.server.resourcemanager.scheduler.capacity.LeafQueue: assignedContainer application=application_1376201383303_0006 container=Container: [ContainerId: container_1376201383303_0006_01_000029, NodeId: hadoop-320-7:37753, NodeHttpAddress: hadoop-320-7:8042, Resource: <memory:1024, vCores:1>, Priority: 20, State: NEW, Token: null, Status: container_id {, app_attempt_id {, application_id {, id: 6, cluster_timestamp: 1376201383303, }, attemptId: 1, }, id: 29, }, state: C_NEW, ] containerId=container_1376201383303_0006_01_000029 queue=default: capacity=1.0, absoluteCapacity=1.0, usedResources=<memory:37888, vCores:32>usedCapacity=0.7708333, absoluteUsedCapacity=0.7708333, numApps=5, numContainers=32 usedCapacity=0.7708333 absoluteUsedCapacity=0.7708333 used=<memory:37888, vCores:32> cluster=<memory:49152, vCores:96>
2013-08-11 06:26:29,196 INFO org.apache.hadoop.yarn.server.resourcemanager.scheduler.capacity.ParentQueue: Re-sorting queues since queue: root.default stats: default: capacity=1.0, absoluteCapacity=1.0, usedResources=<memory:38912, vCores:33>usedCapacity=0.7916667, absoluteUsedCapacity=0.7916667, numApps=5, numContainers=33
2013-08-11 06:26:29,196 INFO org.apache.hadoop.yarn.server.resourcemanager.scheduler.capacity.ParentQueue: assignedContainer queue=root usedCapacity=0.7916667 absoluteUsedCapacity=0.7916667 used=<memory:38912, vCores:33> cluster=<memory:49152, vCores:96>
2013-08-11 06:26:29,196 INFO org.apache.hadoop.yarn.server.resourcemanager.rmcontainer.RMContainerImpl: container_1376201383303_0006_01_000030 Container Transitioned from NEW to ALLOCATED
2013-08-11 06:26:29,197 INFO org.apache.hadoop.yarn.server.resourcemanager.RMAuditLogger: USER=ubuntu	OPERATION=AM Allocated Container	TARGET=SchedulerApp	RESULT=SUCCESS	APPID=application_1376201383303_0006	CONTAINERID=container_1376201383303_0006_01_000030
2013-08-11 06:26:29,197 INFO org.apache.hadoop.yarn.server.resourcemanager.scheduler.common.fica.FiCaSchedulerNode: Assigned container container_1376201383303_0006_01_000030 of capacity <memory:1024, vCores:1> on host hadoop-320-7:37753, which currently has 4 containers, <memory:5120, vCores:4> used and <memory:3072, vCores:12> available
2013-08-11 06:26:29,198 INFO org.apache.hadoop.yarn.server.resourcemanager.scheduler.capacity.LeafQueue: assignedContainer application=application_1376201383303_0006 container=Container: [ContainerId: container_1376201383303_0006_01_000030, NodeId: hadoop-320-7:37753, NodeHttpAddress: hadoop-320-7:8042, Resource: <memory:1024, vCores:1>, Priority: 20, State: NEW, Token: null, Status: container_id {, app_attempt_id {, application_id {, id: 6, cluster_timestamp: 1376201383303, }, attemptId: 1, }, id: 30, }, state: C_NEW, ] containerId=container_1376201383303_0006_01_000030 queue=default: capacity=1.0, absoluteCapacity=1.0, usedResources=<memory:38912, vCores:33>usedCapacity=0.7916667, absoluteUsedCapacity=0.7916667, numApps=5, numContainers=33 usedCapacity=0.7916667 absoluteUsedCapacity=0.7916667 used=<memory:38912, vCores:33> cluster=<memory:49152, vCores:96>
2013-08-11 06:26:29,198 INFO org.apache.hadoop.yarn.server.resourcemanager.scheduler.capacity.ParentQueue: Re-sorting queues since queue: root.default stats: default: capacity=1.0, absoluteCapacity=1.0, usedResources=<memory:39936, vCores:34>usedCapacity=0.8125, absoluteUsedCapacity=0.8125, numApps=5, numContainers=34
2013-08-11 06:26:29,198 INFO org.apache.hadoop.yarn.server.resourcemanager.scheduler.capacity.ParentQueue: assignedContainer queue=root usedCapacity=0.8125 absoluteUsedCapacity=0.8125 used=<memory:39936, vCores:34> cluster=<memory:49152, vCores:96>
2013-08-11 06:26:29,199 INFO org.apache.hadoop.yarn.server.resourcemanager.rmcontainer.RMContainerImpl: container_1376201383303_0006_01_000031 Container Transitioned from NEW to ALLOCATED
2013-08-11 06:26:29,199 INFO org.apache.hadoop.yarn.server.resourcemanager.RMAuditLogger: USER=ubuntu	OPERATION=AM Allocated Container	TARGET=SchedulerApp	RESULT=SUCCESS	APPID=application_1376201383303_0006	CONTAINERID=container_1376201383303_0006_01_000031
2013-08-11 06:26:29,199 INFO org.apache.hadoop.yarn.server.resourcemanager.scheduler.common.fica.FiCaSchedulerNode: Assigned container container_1376201383303_0006_01_000031 of capacity <memory:1024, vCores:1> on host hadoop-320-7:37753, which currently has 5 containers, <memory:6144, vCores:5> used and <memory:2048, vCores:11> available
2013-08-11 06:26:29,200 INFO org.apache.hadoop.yarn.server.resourcemanager.scheduler.capacity.LeafQueue: assignedContainer application=application_1376201383303_0006 container=Container: [ContainerId: container_1376201383303_0006_01_000031, NodeId: hadoop-320-7:37753, NodeHttpAddress: hadoop-320-7:8042, Resource: <memory:1024, vCores:1>, Priority: 20, State: NEW, Token: null, Status: container_id {, app_attempt_id {, application_id {, id: 6, cluster_timestamp: 1376201383303, }, attemptId: 1, }, id: 31, }, state: C_NEW, ] containerId=container_1376201383303_0006_01_000031 queue=default: capacity=1.0, absoluteCapacity=1.0, usedResources=<memory:39936, vCores:34>usedCapacity=0.8125, absoluteUsedCapacity=0.8125, numApps=5, numContainers=34 usedCapacity=0.8125 absoluteUsedCapacity=0.8125 used=<memory:39936, vCores:34> cluster=<memory:49152, vCores:96>
2013-08-11 06:26:29,200 INFO org.apache.hadoop.yarn.server.resourcemanager.scheduler.capacity.ParentQueue: Re-sorting queues since queue: root.default stats: default: capacity=1.0, absoluteCapacity=1.0, usedResources=<memory:40960, vCores:35>usedCapacity=0.8333333, absoluteUsedCapacity=0.8333333, numApps=5, numContainers=35
2013-08-11 06:26:29,200 INFO org.apache.hadoop.yarn.server.resourcemanager.scheduler.capacity.ParentQueue: assignedContainer queue=root usedCapacity=0.8333333 absoluteUsedCapacity=0.8333333 used=<memory:40960, vCores:35> cluster=<memory:49152, vCores:96>
2013-08-11 06:26:29,201 INFO org.apache.hadoop.yarn.server.resourcemanager.rmcontainer.RMContainerImpl: container_1376201383303_0006_01_000032 Container Transitioned from NEW to ALLOCATED
2013-08-11 06:26:29,201 INFO org.apache.hadoop.yarn.server.resourcemanager.RMAuditLogger: USER=ubuntu	OPERATION=AM Allocated Container	TARGET=SchedulerApp	RESULT=SUCCESS	APPID=application_1376201383303_0006	CONTAINERID=container_1376201383303_0006_01_000032
2013-08-11 06:26:29,201 INFO org.apache.hadoop.yarn.server.resourcemanager.scheduler.common.fica.FiCaSchedulerNode: Assigned container container_1376201383303_0006_01_000032 of capacity <memory:1024, vCores:1> on host hadoop-320-7:37753, which currently has 6 containers, <memory:7168, vCores:6> used and <memory:1024, vCores:10> available
2013-08-11 06:26:29,202 INFO org.apache.hadoop.yarn.server.resourcemanager.scheduler.capacity.LeafQueue: assignedContainer application=application_1376201383303_0006 container=Container: [ContainerId: container_1376201383303_0006_01_000032, NodeId: hadoop-320-7:37753, NodeHttpAddress: hadoop-320-7:8042, Resource: <memory:1024, vCores:1>, Priority: 20, State: NEW, Token: null, Status: container_id {, app_attempt_id {, application_id {, id: 6, cluster_timestamp: 1376201383303, }, attemptId: 1, }, id: 32, }, state: C_NEW, ] containerId=container_1376201383303_0006_01_000032 queue=default: capacity=1.0, absoluteCapacity=1.0, usedResources=<memory:40960, vCores:35>usedCapacity=0.8333333, absoluteUsedCapacity=0.8333333, numApps=5, numContainers=35 usedCapacity=0.8333333 absoluteUsedCapacity=0.8333333 used=<memory:40960, vCores:35> cluster=<memory:49152, vCores:96>
2013-08-11 06:26:29,202 INFO org.apache.hadoop.yarn.server.resourcemanager.scheduler.capacity.ParentQueue: Re-sorting queues since queue: root.default stats: default: capacity=1.0, absoluteCapacity=1.0, usedResources=<memory:41984, vCores:36>usedCapacity=0.8541667, absoluteUsedCapacity=0.8541667, numApps=5, numContainers=36
2013-08-11 06:26:29,202 INFO org.apache.hadoop.yarn.server.resourcemanager.scheduler.capacity.ParentQueue: assignedContainer queue=root usedCapacity=0.8541667 absoluteUsedCapacity=0.8541667 used=<memory:41984, vCores:36> cluster=<memory:49152, vCores:96>
2013-08-11 06:26:29,203 INFO org.apache.hadoop.yarn.server.resourcemanager.rmcontainer.RMContainerImpl: container_1376201383303_0006_01_000033 Container Transitioned from NEW to ALLOCATED
2013-08-11 06:26:29,203 INFO org.apache.hadoop.yarn.server.resourcemanager.RMAuditLogger: USER=ubuntu	OPERATION=AM Allocated Container	TARGET=SchedulerApp	RESULT=SUCCESS	APPID=application_1376201383303_0006	CONTAINERID=container_1376201383303_0006_01_000033
2013-08-11 06:26:29,203 INFO org.apache.hadoop.yarn.server.resourcemanager.scheduler.common.fica.FiCaSchedulerNode: Assigned container container_1376201383303_0006_01_000033 of capacity <memory:1024, vCores:1> on host hadoop-320-7:37753, which currently has 7 containers, <memory:8192, vCores:7> used and <memory:0, vCores:9> available
2013-08-11 06:26:29,204 INFO org.apache.hadoop.yarn.server.resourcemanager.scheduler.capacity.LeafQueue: assignedContainer application=application_1376201383303_0006 container=Container: [ContainerId: container_1376201383303_0006_01_000033, NodeId: hadoop-320-7:37753, NodeHttpAddress: hadoop-320-7:8042, Resource: <memory:1024, vCores:1>, Priority: 20, State: NEW, Token: null, Status: container_id {, app_attempt_id {, application_id {, id: 6, cluster_timestamp: 1376201383303, }, attemptId: 1, }, id: 33, }, state: C_NEW, ] containerId=container_1376201383303_0006_01_000033 queue=default: capacity=1.0, absoluteCapacity=1.0, usedResources=<memory:41984, vCores:36>usedCapacity=0.8541667, absoluteUsedCapacity=0.8541667, numApps=5, numContainers=36 usedCapacity=0.8541667 absoluteUsedCapacity=0.8541667 used=<memory:41984, vCores:36> cluster=<memory:49152, vCores:96>
2013-08-11 06:26:29,204 INFO org.apache.hadoop.yarn.server.resourcemanager.scheduler.capacity.ParentQueue: Re-sorting queues since queue: root.default stats: default: capacity=1.0, absoluteCapacity=1.0, usedResources=<memory:43008, vCores:37>usedCapacity=0.875, absoluteUsedCapacity=0.875, numApps=5, numContainers=37
2013-08-11 06:26:29,205 INFO org.apache.hadoop.yarn.server.resourcemanager.scheduler.capacity.ParentQueue: assignedContainer queue=root usedCapacity=0.875 absoluteUsedCapacity=0.875 used=<memory:43008, vCores:37> cluster=<memory:49152, vCores:96>
2013-08-11 06:26:29,461 INFO org.apache.hadoop.yarn.server.resourcemanager.rmcontainer.RMContainerImpl: container_1376201383303_0006_01_000034 Container Transitioned from NEW to ALLOCATED
2013-08-11 06:26:29,461 INFO org.apache.hadoop.yarn.server.resourcemanager.RMAuditLogger: USER=ubuntu	OPERATION=AM Allocated Container	TARGET=SchedulerApp	RESULT=SUCCESS	APPID=application_1376201383303_0006	CONTAINERID=container_1376201383303_0006_01_000034
2013-08-11 06:26:29,461 INFO org.apache.hadoop.yarn.server.resourcemanager.scheduler.common.fica.FiCaSchedulerNode: Assigned container container_1376201383303_0006_01_000034 of capacity <memory:1024, vCores:1> on host hadoop-320-5:32992, which currently has 2 containers, <memory:3072, vCores:2> used and <memory:5120, vCores:14> available
2013-08-11 06:26:29,462 INFO org.apache.hadoop.yarn.server.resourcemanager.scheduler.capacity.LeafQueue: assignedContainer application=application_1376201383303_0006 container=Container: [ContainerId: container_1376201383303_0006_01_000034, NodeId: hadoop-320-5:32992, NodeHttpAddress: hadoop-320-5:8042, Resource: <memory:1024, vCores:1>, Priority: 20, State: NEW, Token: null, Status: container_id {, app_attempt_id {, application_id {, id: 6, cluster_timestamp: 1376201383303, }, attemptId: 1, }, id: 34, }, state: C_NEW, ] containerId=container_1376201383303_0006_01_000034 queue=default: capacity=1.0, absoluteCapacity=1.0, usedResources=<memory:43008, vCores:37>usedCapacity=0.875, absoluteUsedCapacity=0.875, numApps=5, numContainers=37 usedCapacity=0.875 absoluteUsedCapacity=0.875 used=<memory:43008, vCores:37> cluster=<memory:49152, vCores:96>
2013-08-11 06:26:29,463 INFO org.apache.hadoop.yarn.server.resourcemanager.scheduler.capacity.ParentQueue: Re-sorting queues since queue: root.default stats: default: capacity=1.0, absoluteCapacity=1.0, usedResources=<memory:44032, vCores:38>usedCapacity=0.8958333, absoluteUsedCapacity=0.8958333, numApps=5, numContainers=38
2013-08-11 06:26:29,463 INFO org.apache.hadoop.yarn.server.resourcemanager.scheduler.capacity.ParentQueue: assignedContainer queue=root usedCapacity=0.8958333 absoluteUsedCapacity=0.8958333 used=<memory:44032, vCores:38> cluster=<memory:49152, vCores:96>
2013-08-11 06:26:29,463 INFO org.apache.hadoop.yarn.server.resourcemanager.rmcontainer.RMContainerImpl: container_1376201383303_0006_01_000035 Container Transitioned from NEW to ALLOCATED
2013-08-11 06:26:29,463 INFO org.apache.hadoop.yarn.server.resourcemanager.RMAuditLogger: USER=ubuntu	OPERATION=AM Allocated Container	TARGET=SchedulerApp	RESULT=SUCCESS	APPID=application_1376201383303_0006	CONTAINERID=container_1376201383303_0006_01_000035
2013-08-11 06:26:29,464 INFO org.apache.hadoop.yarn.server.resourcemanager.scheduler.common.fica.FiCaSchedulerNode: Assigned container container_1376201383303_0006_01_000035 of capacity <memory:1024, vCores:1> on host hadoop-320-5:32992, which currently has 3 containers, <memory:4096, vCores:3> used and <memory:4096, vCores:13> available
2013-08-11 06:26:29,465 INFO org.apache.hadoop.yarn.server.resourcemanager.scheduler.capacity.LeafQueue: assignedContainer application=application_1376201383303_0006 container=Container: [ContainerId: container_1376201383303_0006_01_000035, NodeId: hadoop-320-5:32992, NodeHttpAddress: hadoop-320-5:8042, Resource: <memory:1024, vCores:1>, Priority: 20, State: NEW, Token: null, Status: container_id {, app_attempt_id {, application_id {, id: 6, cluster_timestamp: 1376201383303, }, attemptId: 1, }, id: 35, }, state: C_NEW, ] containerId=container_1376201383303_0006_01_000035 queue=default: capacity=1.0, absoluteCapacity=1.0, usedResources=<memory:44032, vCores:38>usedCapacity=0.8958333, absoluteUsedCapacity=0.8958333, numApps=5, numContainers=38 usedCapacity=0.8958333 absoluteUsedCapacity=0.8958333 used=<memory:44032, vCores:38> cluster=<memory:49152, vCores:96>
2013-08-11 06:26:29,465 INFO org.apache.hadoop.yarn.server.resourcemanager.scheduler.capacity.ParentQueue: Re-sorting queues since queue: root.default stats: default: capacity=1.0, absoluteCapacity=1.0, usedResources=<memory:45056, vCores:39>usedCapacity=0.9166667, absoluteUsedCapacity=0.9166667, numApps=5, numContainers=39
2013-08-11 06:26:29,465 INFO org.apache.hadoop.yarn.server.resourcemanager.scheduler.capacity.ParentQueue: assignedContainer queue=root usedCapacity=0.9166667 absoluteUsedCapacity=0.9166667 used=<memory:45056, vCores:39> cluster=<memory:49152, vCores:96>
2013-08-11 06:26:29,466 INFO org.apache.hadoop.yarn.server.resourcemanager.rmcontainer.RMContainerImpl: container_1376201383303_0006_01_000036 Container Transitioned from NEW to ALLOCATED
2013-08-11 06:26:29,466 INFO org.apache.hadoop.yarn.server.resourcemanager.RMAuditLogger: USER=ubuntu	OPERATION=AM Allocated Container	TARGET=SchedulerApp	RESULT=SUCCESS	APPID=application_1376201383303_0006	CONTAINERID=container_1376201383303_0006_01_000036
2013-08-11 06:26:29,466 INFO org.apache.hadoop.yarn.server.resourcemanager.scheduler.common.fica.FiCaSchedulerNode: Assigned container container_1376201383303_0006_01_000036 of capacity <memory:1024, vCores:1> on host hadoop-320-5:32992, which currently has 4 containers, <memory:5120, vCores:4> used and <memory:3072, vCores:12> available
2013-08-11 06:26:29,467 INFO org.apache.hadoop.yarn.server.resourcemanager.scheduler.capacity.LeafQueue: assignedContainer application=application_1376201383303_0006 container=Container: [ContainerId: container_1376201383303_0006_01_000036, NodeId: hadoop-320-5:32992, NodeHttpAddress: hadoop-320-5:8042, Resource: <memory:1024, vCores:1>, Priority: 20, State: NEW, Token: null, Status: container_id {, app_attempt_id {, application_id {, id: 6, cluster_timestamp: 1376201383303, }, attemptId: 1, }, id: 36, }, state: C_NEW, ] containerId=container_1376201383303_0006_01_000036 queue=default: capacity=1.0, absoluteCapacity=1.0, usedResources=<memory:45056, vCores:39>usedCapacity=0.9166667, absoluteUsedCapacity=0.9166667, numApps=5, numContainers=39 usedCapacity=0.9166667 absoluteUsedCapacity=0.9166667 used=<memory:45056, vCores:39> cluster=<memory:49152, vCores:96>
2013-08-11 06:26:29,467 INFO org.apache.hadoop.yarn.server.resourcemanager.scheduler.capacity.ParentQueue: Re-sorting queues since queue: root.default stats: default: capacity=1.0, absoluteCapacity=1.0, usedResources=<memory:46080, vCores:40>usedCapacity=0.9375, absoluteUsedCapacity=0.9375, numApps=5, numContainers=40
2013-08-11 06:26:29,467 INFO org.apache.hadoop.yarn.server.resourcemanager.scheduler.capacity.ParentQueue: assignedContainer queue=root usedCapacity=0.9375 absoluteUsedCapacity=0.9375 used=<memory:46080, vCores:40> cluster=<memory:49152, vCores:96>
2013-08-11 06:26:29,468 INFO org.apache.hadoop.yarn.server.resourcemanager.rmcontainer.RMContainerImpl: container_1376201383303_0006_01_000037 Container Transitioned from NEW to ALLOCATED
2013-08-11 06:26:29,468 INFO org.apache.hadoop.yarn.server.resourcemanager.RMAuditLogger: USER=ubuntu	OPERATION=AM Allocated Container	TARGET=SchedulerApp	RESULT=SUCCESS	APPID=application_1376201383303_0006	CONTAINERID=container_1376201383303_0006_01_000037
2013-08-11 06:26:29,468 INFO org.apache.hadoop.yarn.server.resourcemanager.scheduler.common.fica.FiCaSchedulerNode: Assigned container container_1376201383303_0006_01_000037 of capacity <memory:1024, vCores:1> on host hadoop-320-5:32992, which currently has 5 containers, <memory:6144, vCores:5> used and <memory:2048, vCores:11> available
2013-08-11 06:26:29,469 INFO org.apache.hadoop.yarn.server.resourcemanager.scheduler.capacity.LeafQueue: assignedContainer application=application_1376201383303_0006 container=Container: [ContainerId: container_1376201383303_0006_01_000037, NodeId: hadoop-320-5:32992, NodeHttpAddress: hadoop-320-5:8042, Resource: <memory:1024, vCores:1>, Priority: 20, State: NEW, Token: null, Status: container_id {, app_attempt_id {, application_id {, id: 6, cluster_timestamp: 1376201383303, }, attemptId: 1, }, id: 37, }, state: C_NEW, ] containerId=container_1376201383303_0006_01_000037 queue=default: capacity=1.0, absoluteCapacity=1.0, usedResources=<memory:46080, vCores:40>usedCapacity=0.9375, absoluteUsedCapacity=0.9375, numApps=5, numContainers=40 usedCapacity=0.9375 absoluteUsedCapacity=0.9375 used=<memory:46080, vCores:40> cluster=<memory:49152, vCores:96>
2013-08-11 06:26:29,469 INFO org.apache.hadoop.yarn.server.resourcemanager.scheduler.capacity.ParentQueue: Re-sorting queues since queue: root.default stats: default: capacity=1.0, absoluteCapacity=1.0, usedResources=<memory:47104, vCores:41>usedCapacity=0.9583333, absoluteUsedCapacity=0.9583333, numApps=5, numContainers=41
2013-08-11 06:26:29,469 INFO org.apache.hadoop.yarn.server.resourcemanager.scheduler.capacity.ParentQueue: assignedContainer queue=root usedCapacity=0.9583333 absoluteUsedCapacity=0.9583333 used=<memory:47104, vCores:41> cluster=<memory:49152, vCores:96>
2013-08-11 06:26:29,470 INFO org.apache.hadoop.yarn.server.resourcemanager.rmcontainer.RMContainerImpl: container_1376201383303_0006_01_000038 Container Transitioned from NEW to ALLOCATED
2013-08-11 06:26:29,470 INFO org.apache.hadoop.yarn.server.resourcemanager.RMAuditLogger: USER=ubuntu	OPERATION=AM Allocated Container	TARGET=SchedulerApp	RESULT=SUCCESS	APPID=application_1376201383303_0006	CONTAINERID=container_1376201383303_0006_01_000038
2013-08-11 06:26:29,470 INFO org.apache.hadoop.yarn.server.resourcemanager.scheduler.common.fica.FiCaSchedulerNode: Assigned container container_1376201383303_0006_01_000038 of capacity <memory:1024, vCores:1> on host hadoop-320-5:32992, which currently has 6 containers, <memory:7168, vCores:6> used and <memory:1024, vCores:10> available
2013-08-11 06:26:29,471 INFO org.apache.hadoop.yarn.server.resourcemanager.scheduler.capacity.LeafQueue: assignedContainer application=application_1376201383303_0006 container=Container: [ContainerId: container_1376201383303_0006_01_000038, NodeId: hadoop-320-5:32992, NodeHttpAddress: hadoop-320-5:8042, Resource: <memory:1024, vCores:1>, Priority: 20, State: NEW, Token: null, Status: container_id {, app_attempt_id {, application_id {, id: 6, cluster_timestamp: 1376201383303, }, attemptId: 1, }, id: 38, }, state: C_NEW, ] containerId=container_1376201383303_0006_01_000038 queue=default: capacity=1.0, absoluteCapacity=1.0, usedResources=<memory:47104, vCores:41>usedCapacity=0.9583333, absoluteUsedCapacity=0.9583333, numApps=5, numContainers=41 usedCapacity=0.9583333 absoluteUsedCapacity=0.9583333 used=<memory:47104, vCores:41> cluster=<memory:49152, vCores:96>
2013-08-11 06:26:29,471 INFO org.apache.hadoop.yarn.server.resourcemanager.scheduler.capacity.ParentQueue: Re-sorting queues since queue: root.default stats: default: capacity=1.0, absoluteCapacity=1.0, usedResources=<memory:48128, vCores:42>usedCapacity=0.9791667, absoluteUsedCapacity=0.9791667, numApps=5, numContainers=42
2013-08-11 06:26:29,472 INFO org.apache.hadoop.yarn.server.resourcemanager.scheduler.capacity.ParentQueue: assignedContainer queue=root usedCapacity=0.9791667 absoluteUsedCapacity=0.9791667 used=<memory:48128, vCores:42> cluster=<memory:49152, vCores:96>
2013-08-11 06:26:29,472 INFO org.apache.hadoop.yarn.server.resourcemanager.rmcontainer.RMContainerImpl: container_1376201383303_0006_01_000039 Container Transitioned from NEW to ALLOCATED
2013-08-11 06:26:29,472 INFO org.apache.hadoop.yarn.server.resourcemanager.RMAuditLogger: USER=ubuntu	OPERATION=AM Allocated Container	TARGET=SchedulerApp	RESULT=SUCCESS	APPID=application_1376201383303_0006	CONTAINERID=container_1376201383303_0006_01_000039
2013-08-11 06:26:29,472 INFO org.apache.hadoop.yarn.server.resourcemanager.scheduler.common.fica.FiCaSchedulerNode: Assigned container container_1376201383303_0006_01_000039 of capacity <memory:1024, vCores:1> on host hadoop-320-5:32992, which currently has 7 containers, <memory:8192, vCores:7> used and <memory:0, vCores:9> available
2013-08-11 06:26:29,473 INFO org.apache.hadoop.yarn.server.resourcemanager.scheduler.capacity.LeafQueue: assignedContainer application=application_1376201383303_0006 container=Container: [ContainerId: container_1376201383303_0006_01_000039, NodeId: hadoop-320-5:32992, NodeHttpAddress: hadoop-320-5:8042, Resource: <memory:1024, vCores:1>, Priority: 20, State: NEW, Token: null, Status: container_id {, app_attempt_id {, application_id {, id: 6, cluster_timestamp: 1376201383303, }, attemptId: 1, }, id: 39, }, state: C_NEW, ] containerId=container_1376201383303_0006_01_000039 queue=default: capacity=1.0, absoluteCapacity=1.0, usedResources=<memory:48128, vCores:42>usedCapacity=0.9791667, absoluteUsedCapacity=0.9791667, numApps=5, numContainers=42 usedCapacity=0.9791667 absoluteUsedCapacity=0.9791667 used=<memory:48128, vCores:42> cluster=<memory:49152, vCores:96>
2013-08-11 06:26:29,474 INFO org.apache.hadoop.yarn.server.resourcemanager.scheduler.capacity.ParentQueue: Re-sorting queues since queue: root.default stats: default: capacity=1.0, absoluteCapacity=1.0, usedResources=<memory:49152, vCores:43>usedCapacity=1.0, absoluteUsedCapacity=1.0, numApps=5, numContainers=43
2013-08-11 06:26:29,474 INFO org.apache.hadoop.yarn.server.resourcemanager.scheduler.capacity.ParentQueue: assignedContainer queue=root usedCapacity=1.0 absoluteUsedCapacity=1.0 used=<memory:49152, vCores:43> cluster=<memory:49152, vCores:96>
2013-08-11 06:26:29,582 INFO org.apache.hadoop.yarn.server.resourcemanager.ApplicationMasterService: AM registration appattempt_1376201383303_0008_000001
2013-08-11 06:26:29,583 INFO org.apache.hadoop.yarn.server.resourcemanager.RMAuditLogger: USER=ubuntu	IP=192.168.100.34	OPERATION=Register App Master	TARGET=ApplicationMasterService	RESULT=SUCCESS	APPID=application_1376201383303_0008	APPATTEMPTID=appattempt_1376201383303_0008_000001
2013-08-11 06:26:29,584 INFO org.apache.hadoop.yarn.server.resourcemanager.rmapp.attempt.RMAppAttemptImpl: appattempt_1376201383303_0008_000001 State change from LAUNCHED to RUNNING
2013-08-11 06:26:29,584 INFO org.apache.hadoop.yarn.server.resourcemanager.rmapp.RMAppImpl: application_1376201383303_0008 State change from ACCEPTED to RUNNING
2013-08-11 06:26:29,625 INFO org.apache.hadoop.yarn.server.resourcemanager.rmcontainer.RMContainerImpl: container_1376201383303_0006_01_000002 Container Transitioned from ALLOCATED to ACQUIRED
2013-08-11 06:26:29,625 INFO org.apache.hadoop.yarn.server.resourcemanager.rmcontainer.RMContainerImpl: container_1376201383303_0006_01_000003 Container Transitioned from ALLOCATED to ACQUIRED
2013-08-11 06:26:29,626 INFO org.apache.hadoop.yarn.server.resourcemanager.rmcontainer.RMContainerImpl: container_1376201383303_0006_01_000004 Container Transitioned from ALLOCATED to ACQUIRED
2013-08-11 06:26:29,627 INFO org.apache.hadoop.yarn.server.resourcemanager.rmcontainer.RMContainerImpl: container_1376201383303_0006_01_000005 Container Transitioned from ALLOCATED to ACQUIRED
2013-08-11 06:26:29,628 INFO org.apache.hadoop.yarn.server.resourcemanager.rmcontainer.RMContainerImpl: container_1376201383303_0006_01_000006 Container Transitioned from ALLOCATED to ACQUIRED
2013-08-11 06:26:29,629 INFO org.apache.hadoop.yarn.server.resourcemanager.rmcontainer.RMContainerImpl: container_1376201383303_0006_01_000007 Container Transitioned from ALLOCATED to ACQUIRED
2013-08-11 06:26:29,629 INFO org.apache.hadoop.yarn.server.resourcemanager.rmcontainer.RMContainerImpl: container_1376201383303_0006_01_000008 Container Transitioned from ALLOCATED to ACQUIRED
2013-08-11 06:26:29,631 INFO org.apache.hadoop.yarn.server.resourcemanager.rmcontainer.RMContainerImpl: container_1376201383303_0006_01_000009 Container Transitioned from ALLOCATED to ACQUIRED
2013-08-11 06:26:29,632 INFO org.apache.hadoop.yarn.server.resourcemanager.rmcontainer.RMContainerImpl: container_1376201383303_0006_01_000010 Container Transitioned from ALLOCATED to ACQUIRED
2013-08-11 06:26:29,633 INFO org.apache.hadoop.yarn.server.resourcemanager.rmcontainer.RMContainerImpl: container_1376201383303_0006_01_000011 Container Transitioned from ALLOCATED to ACQUIRED
2013-08-11 06:26:29,633 INFO org.apache.hadoop.yarn.server.resourcemanager.rmcontainer.RMContainerImpl: container_1376201383303_0006_01_000012 Container Transitioned from ALLOCATED to ACQUIRED
2013-08-11 06:26:29,633 INFO org.apache.hadoop.yarn.server.resourcemanager.rmcontainer.RMContainerImpl: container_1376201383303_0006_01_000013 Container Transitioned from ALLOCATED to ACQUIRED
2013-08-11 06:26:29,633 INFO org.apache.hadoop.yarn.server.resourcemanager.rmcontainer.RMContainerImpl: container_1376201383303_0006_01_000014 Container Transitioned from ALLOCATED to ACQUIRED
2013-08-11 06:26:29,633 INFO org.apache.hadoop.yarn.server.resourcemanager.rmcontainer.RMContainerImpl: container_1376201383303_0006_01_000015 Container Transitioned from ALLOCATED to ACQUIRED
2013-08-11 06:26:29,634 INFO org.apache.hadoop.yarn.server.resourcemanager.rmcontainer.RMContainerImpl: container_1376201383303_0006_01_000016 Container Transitioned from ALLOCATED to ACQUIRED
2013-08-11 06:26:29,634 INFO org.apache.hadoop.yarn.server.resourcemanager.rmcontainer.RMContainerImpl: container_1376201383303_0006_01_000017 Container Transitioned from ALLOCATED to ACQUIRED
2013-08-11 06:26:29,634 INFO org.apache.hadoop.yarn.server.resourcemanager.rmcontainer.RMContainerImpl: container_1376201383303_0006_01_000018 Container Transitioned from ALLOCATED to ACQUIRED
2013-08-11 06:26:29,634 INFO org.apache.hadoop.yarn.server.resourcemanager.rmcontainer.RMContainerImpl: container_1376201383303_0006_01_000019 Container Transitioned from ALLOCATED to ACQUIRED
2013-08-11 06:26:29,634 INFO org.apache.hadoop.yarn.server.resourcemanager.rmcontainer.RMContainerImpl: container_1376201383303_0006_01_000020 Container Transitioned from ALLOCATED to ACQUIRED
2013-08-11 06:26:29,635 INFO org.apache.hadoop.yarn.server.resourcemanager.rmcontainer.RMContainerImpl: container_1376201383303_0006_01_000021 Container Transitioned from ALLOCATED to ACQUIRED
2013-08-11 06:26:29,635 INFO org.apache.hadoop.yarn.server.resourcemanager.rmcontainer.RMContainerImpl: container_1376201383303_0006_01_000022 Container Transitioned from ALLOCATED to ACQUIRED
2013-08-11 06:26:29,635 INFO org.apache.hadoop.yarn.server.resourcemanager.rmcontainer.RMContainerImpl: container_1376201383303_0006_01_000023 Container Transitioned from ALLOCATED to ACQUIRED
2013-08-11 06:26:29,635 INFO org.apache.hadoop.yarn.server.resourcemanager.rmcontainer.RMContainerImpl: container_1376201383303_0006_01_000024 Container Transitioned from ALLOCATED to ACQUIRED
2013-08-11 06:26:29,635 INFO org.apache.hadoop.yarn.server.resourcemanager.rmcontainer.RMContainerImpl: container_1376201383303_0006_01_000025 Container Transitioned from ALLOCATED to ACQUIRED
2013-08-11 06:26:29,636 INFO org.apache.hadoop.yarn.server.resourcemanager.rmcontainer.RMContainerImpl: container_1376201383303_0006_01_000026 Container Transitioned from ALLOCATED to ACQUIRED
2013-08-11 06:26:29,636 INFO org.apache.hadoop.yarn.server.resourcemanager.rmcontainer.RMContainerImpl: container_1376201383303_0006_01_000027 Container Transitioned from ALLOCATED to ACQUIRED
2013-08-11 06:26:29,636 INFO org.apache.hadoop.yarn.server.resourcemanager.rmcontainer.RMContainerImpl: container_1376201383303_0006_01_000028 Container Transitioned from ALLOCATED to ACQUIRED
2013-08-11 06:26:29,636 INFO org.apache.hadoop.yarn.server.resourcemanager.rmcontainer.RMContainerImpl: container_1376201383303_0006_01_000029 Container Transitioned from ALLOCATED to ACQUIRED
2013-08-11 06:26:29,636 INFO org.apache.hadoop.yarn.server.resourcemanager.rmcontainer.RMContainerImpl: container_1376201383303_0006_01_000030 Container Transitioned from ALLOCATED to ACQUIRED
2013-08-11 06:26:29,637 INFO org.apache.hadoop.yarn.server.resourcemanager.rmcontainer.RMContainerImpl: container_1376201383303_0006_01_000031 Container Transitioned from ALLOCATED to ACQUIRED
2013-08-11 06:26:29,637 INFO org.apache.hadoop.yarn.server.resourcemanager.rmcontainer.RMContainerImpl: container_1376201383303_0006_01_000032 Container Transitioned from ALLOCATED to ACQUIRED
2013-08-11 06:26:29,637 INFO org.apache.hadoop.yarn.server.resourcemanager.rmcontainer.RMContainerImpl: container_1376201383303_0006_01_000033 Container Transitioned from ALLOCATED to ACQUIRED
2013-08-11 06:26:29,637 INFO org.apache.hadoop.yarn.server.resourcemanager.rmcontainer.RMContainerImpl: container_1376201383303_0006_01_000034 Container Transitioned from ALLOCATED to ACQUIRED
2013-08-11 06:26:29,637 INFO org.apache.hadoop.yarn.server.resourcemanager.rmcontainer.RMContainerImpl: container_1376201383303_0006_01_000035 Container Transitioned from ALLOCATED to ACQUIRED
2013-08-11 06:26:29,638 INFO org.apache.hadoop.yarn.server.resourcemanager.rmcontainer.RMContainerImpl: container_1376201383303_0006_01_000036 Container Transitioned from ALLOCATED to ACQUIRED
2013-08-11 06:26:29,638 INFO org.apache.hadoop.yarn.server.resourcemanager.rmcontainer.RMContainerImpl: container_1376201383303_0006_01_000037 Container Transitioned from ALLOCATED to ACQUIRED
2013-08-11 06:26:29,638 INFO org.apache.hadoop.yarn.server.resourcemanager.rmcontainer.RMContainerImpl: container_1376201383303_0006_01_000038 Container Transitioned from ALLOCATED to ACQUIRED
2013-08-11 06:26:29,638 INFO org.apache.hadoop.yarn.server.resourcemanager.rmcontainer.RMContainerImpl: container_1376201383303_0006_01_000039 Container Transitioned from ALLOCATED to ACQUIRED
2013-08-11 06:26:29,676 INFO org.apache.hadoop.yarn.server.resourcemanager.ApplicationMasterService: AM registration appattempt_1376201383303_0009_000001
2013-08-11 06:26:29,676 INFO org.apache.hadoop.yarn.server.resourcemanager.RMAuditLogger: USER=ubuntu	IP=192.168.100.18	OPERATION=Register App Master	TARGET=ApplicationMasterService	RESULT=SUCCESS	APPID=application_1376201383303_0009	APPATTEMPTID=appattempt_1376201383303_0009_000001
2013-08-11 06:26:29,678 INFO org.apache.hadoop.yarn.server.resourcemanager.rmapp.attempt.RMAppAttemptImpl: appattempt_1376201383303_0009_000001 State change from LAUNCHED to RUNNING
2013-08-11 06:26:29,678 INFO org.apache.hadoop.yarn.server.resourcemanager.rmapp.RMAppImpl: application_1376201383303_0009 State change from ACCEPTED to RUNNING
2013-08-11 06:26:30,498 INFO org.apache.hadoop.yarn.server.resourcemanager.rmcontainer.RMContainerImpl: container_1376201383303_0006_01_000034 Container Transitioned from ACQUIRED to RUNNING
2013-08-11 06:26:30,499 INFO org.apache.hadoop.yarn.server.resourcemanager.rmcontainer.RMContainerImpl: container_1376201383303_0006_01_000035 Container Transitioned from ACQUIRED to RUNNING
2013-08-11 06:26:30,500 INFO org.apache.hadoop.yarn.server.resourcemanager.rmcontainer.RMContainerImpl: container_1376201383303_0006_01_000036 Container Transitioned from ACQUIRED to RUNNING
2013-08-11 06:26:30,501 INFO org.apache.hadoop.yarn.server.resourcemanager.rmcontainer.RMContainerImpl: container_1376201383303_0006_01_000037 Container Transitioned from ACQUIRED to RUNNING
2013-08-11 06:26:30,501 INFO org.apache.hadoop.yarn.server.resourcemanager.rmcontainer.RMContainerImpl: container_1376201383303_0006_01_000038 Container Transitioned from ACQUIRED to RUNNING
2013-08-11 06:26:30,502 INFO org.apache.hadoop.yarn.server.resourcemanager.rmcontainer.RMContainerImpl: container_1376201383303_0006_01_000039 Container Transitioned from ACQUIRED to RUNNING
2013-08-11 06:26:30,727 INFO org.apache.hadoop.yarn.server.resourcemanager.rmcontainer.RMContainerImpl: container_1376201383303_0006_01_000002 Container Transitioned from ACQUIRED to RUNNING
2013-08-11 06:26:30,727 INFO org.apache.hadoop.yarn.server.resourcemanager.rmcontainer.RMContainerImpl: container_1376201383303_0006_01_000003 Container Transitioned from ACQUIRED to RUNNING
2013-08-11 06:26:30,728 INFO org.apache.hadoop.yarn.server.resourcemanager.rmcontainer.RMContainerImpl: container_1376201383303_0006_01_000004 Container Transitioned from ACQUIRED to RUNNING
2013-08-11 06:26:30,728 INFO org.apache.hadoop.yarn.server.resourcemanager.rmcontainer.RMContainerImpl: container_1376201383303_0006_01_000005 Container Transitioned from ACQUIRED to RUNNING
2013-08-11 06:26:30,767 INFO org.apache.hadoop.yarn.server.resourcemanager.rmcontainer.RMContainerImpl: container_1376201383303_0006_01_000006 Container Transitioned from ACQUIRED to RUNNING
2013-08-11 06:26:30,767 INFO org.apache.hadoop.yarn.server.resourcemanager.rmcontainer.RMContainerImpl: container_1376201383303_0006_01_000007 Container Transitioned from ACQUIRED to RUNNING
2013-08-11 06:26:30,767 INFO org.apache.hadoop.yarn.server.resourcemanager.rmcontainer.RMContainerImpl: container_1376201383303_0006_01_000008 Container Transitioned from ACQUIRED to RUNNING
2013-08-11 06:26:30,767 INFO org.apache.hadoop.yarn.server.resourcemanager.rmcontainer.RMContainerImpl: container_1376201383303_0006_01_000009 Container Transitioned from ACQUIRED to RUNNING
2013-08-11 06:26:30,768 INFO org.apache.hadoop.yarn.server.resourcemanager.rmcontainer.RMContainerImpl: container_1376201383303_0006_01_000010 Container Transitioned from ACQUIRED to RUNNING
2013-08-11 06:26:30,768 INFO org.apache.hadoop.yarn.server.resourcemanager.rmcontainer.RMContainerImpl: container_1376201383303_0006_01_000011 Container Transitioned from ACQUIRED to RUNNING
2013-08-11 06:26:31,058 INFO org.apache.hadoop.yarn.server.resourcemanager.rmcontainer.RMContainerImpl: container_1376201383303_0006_01_000020 Container Transitioned from ACQUIRED to RUNNING
2013-08-11 06:26:31,059 INFO org.apache.hadoop.yarn.server.resourcemanager.rmcontainer.RMContainerImpl: container_1376201383303_0006_01_000021 Container Transitioned from ACQUIRED to RUNNING
2013-08-11 06:26:31,060 INFO org.apache.hadoop.yarn.server.resourcemanager.rmcontainer.RMContainerImpl: container_1376201383303_0006_01_000022 Container Transitioned from ACQUIRED to RUNNING
2013-08-11 06:26:31,061 INFO org.apache.hadoop.yarn.server.resourcemanager.rmcontainer.RMContainerImpl: container_1376201383303_0006_01_000023 Container Transitioned from ACQUIRED to RUNNING
2013-08-11 06:26:31,062 INFO org.apache.hadoop.yarn.server.resourcemanager.rmcontainer.RMContainerImpl: container_1376201383303_0006_01_000024 Container Transitioned from ACQUIRED to RUNNING
2013-08-11 06:26:31,062 INFO org.apache.hadoop.yarn.server.resourcemanager.rmcontainer.RMContainerImpl: container_1376201383303_0006_01_000025 Container Transitioned from ACQUIRED to RUNNING
2013-08-11 06:26:31,063 INFO org.apache.hadoop.yarn.server.resourcemanager.rmcontainer.RMContainerImpl: container_1376201383303_0006_01_000026 Container Transitioned from ACQUIRED to RUNNING
2013-08-11 06:26:31,064 INFO org.apache.hadoop.yarn.server.resourcemanager.rmcontainer.RMContainerImpl: container_1376201383303_0006_01_000027 Container Transitioned from ACQUIRED to RUNNING
2013-08-11 06:26:31,225 INFO org.apache.hadoop.yarn.server.resourcemanager.rmcontainer.RMContainerImpl: container_1376201383303_0006_01_000028 Container Transitioned from ACQUIRED to RUNNING
2013-08-11 06:26:31,226 INFO org.apache.hadoop.yarn.server.resourcemanager.rmcontainer.RMContainerImpl: container_1376201383303_0006_01_000029 Container Transitioned from ACQUIRED to RUNNING
2013-08-11 06:26:31,227 INFO org.apache.hadoop.yarn.server.resourcemanager.rmcontainer.RMContainerImpl: container_1376201383303_0006_01_000030 Container Transitioned from ACQUIRED to RUNNING
2013-08-11 06:26:31,227 INFO org.apache.hadoop.yarn.server.resourcemanager.rmcontainer.RMContainerImpl: container_1376201383303_0006_01_000031 Container Transitioned from ACQUIRED to RUNNING
2013-08-11 06:26:31,229 INFO org.apache.hadoop.yarn.server.resourcemanager.rmcontainer.RMContainerImpl: container_1376201383303_0006_01_000032 Container Transitioned from ACQUIRED to RUNNING
2013-08-11 06:26:31,229 INFO org.apache.hadoop.yarn.server.resourcemanager.rmcontainer.RMContainerImpl: container_1376201383303_0006_01_000033 Container Transitioned from ACQUIRED to RUNNING
2013-08-11 06:26:31,237 INFO org.apache.hadoop.yarn.server.resourcemanager.rmcontainer.RMContainerImpl: container_1376201383303_0006_01_000012 Container Transitioned from ACQUIRED to RUNNING
2013-08-11 06:26:31,237 INFO org.apache.hadoop.yarn.server.resourcemanager.rmcontainer.RMContainerImpl: container_1376201383303_0006_01_000013 Container Transitioned from ACQUIRED to RUNNING
2013-08-11 06:26:31,238 INFO org.apache.hadoop.yarn.server.resourcemanager.rmcontainer.RMContainerImpl: container_1376201383303_0006_01_000014 Container Transitioned from ACQUIRED to RUNNING
2013-08-11 06:26:31,238 INFO org.apache.hadoop.yarn.server.resourcemanager.rmcontainer.RMContainerImpl: container_1376201383303_0006_01_000015 Container Transitioned from ACQUIRED to RUNNING
2013-08-11 06:26:31,238 INFO org.apache.hadoop.yarn.server.resourcemanager.rmcontainer.RMContainerImpl: container_1376201383303_0006_01_000016 Container Transitioned from ACQUIRED to RUNNING
2013-08-11 06:26:31,238 INFO org.apache.hadoop.yarn.server.resourcemanager.rmcontainer.RMContainerImpl: container_1376201383303_0006_01_000017 Container Transitioned from ACQUIRED to RUNNING
2013-08-11 06:26:31,238 INFO org.apache.hadoop.yarn.server.resourcemanager.rmcontainer.RMContainerImpl: container_1376201383303_0006_01_000018 Container Transitioned from ACQUIRED to RUNNING
2013-08-11 06:26:31,238 INFO org.apache.hadoop.yarn.server.resourcemanager.rmcontainer.RMContainerImpl: container_1376201383303_0006_01_000019 Container Transitioned from ACQUIRED to RUNNING
2013-08-11 06:26:49,722 INFO org.apache.hadoop.yarn.server.resourcemanager.rmcontainer.RMContainerImpl: container_1376201383303_0006_01_000002 Container Transitioned from RUNNING to COMPLETED
2013-08-11 06:26:49,722 INFO org.apache.hadoop.yarn.server.resourcemanager.scheduler.common.fica.FiCaSchedulerApp: Completed container: container_1376201383303_0006_01_000002 in state: COMPLETED event:FINISHED
2013-08-11 06:26:49,723 INFO org.apache.hadoop.yarn.server.resourcemanager.RMAuditLogger: USER=ubuntu	OPERATION=AM Released Container	TARGET=SchedulerApp	RESULT=SUCCESS	APPID=application_1376201383303_0006	CONTAINERID=container_1376201383303_0006_01_000002
2013-08-11 06:26:49,723 INFO org.apache.hadoop.yarn.server.resourcemanager.scheduler.common.fica.FiCaSchedulerNode: Released container container_1376201383303_0006_01_000002 of capacity <memory:1024, vCores:1> on host hadoop-320-3:36899, which currently has 5 containers, <memory:7168, vCores:5> used and <memory:1024, vCores:11> available, release resources=true
2013-08-11 06:26:49,723 INFO org.apache.hadoop.yarn.server.resourcemanager.scheduler.capacity.LeafQueue: default used=<memory:48128, vCores:42> numContainers=42 user=ubuntu user-resources=<memory:48128, vCores:42>
2013-08-11 06:26:49,726 INFO org.apache.hadoop.yarn.server.resourcemanager.scheduler.capacity.LeafQueue: completedContainer container=Container: [ContainerId: container_1376201383303_0006_01_000002, NodeId: hadoop-320-3:36899, NodeHttpAddress: hadoop-320-3:8042, Resource: <memory:1024, vCores:1>, Priority: 20, State: NEW, Token: null, Status: container_id {, app_attempt_id {, application_id {, id: 6, cluster_timestamp: 1376201383303, }, attemptId: 1, }, id: 2, }, state: C_COMPLETE, diagnostics: "Container killed by the ApplicationMaster.\n\n", exit_status: 143, ] resource=<memory:1024, vCores:1> queue=default: capacity=1.0, absoluteCapacity=1.0, usedResources=<memory:48128, vCores:42>usedCapacity=0.9791667, absoluteUsedCapacity=0.9791667, numApps=5, numContainers=42 usedCapacity=0.9791667 absoluteUsedCapacity=0.9791667 used=<memory:48128, vCores:42> cluster=<memory:49152, vCores:96>
2013-08-11 06:26:49,726 INFO org.apache.hadoop.yarn.server.resourcemanager.scheduler.capacity.ParentQueue: completedContainer queue=root usedCapacity=0.9791667 absoluteUsedCapacity=0.9791667 used=<memory:48128, vCores:42> cluster=<memory:49152, vCores:96>
2013-08-11 06:26:49,726 INFO org.apache.hadoop.yarn.server.resourcemanager.scheduler.capacity.CapacityScheduler: Application appattempt_1376201383303_0006_000001 released container container_1376201383303_0006_01_000002 on node: host: hadoop-320-3:36899 #containers=5 available=1024 used=7168 with event: FINISHED
2013-08-11 06:26:49,727 INFO org.apache.hadoop.yarn.server.resourcemanager.rmcontainer.RMContainerImpl: container_1376201383303_0006_01_000040 Container Transitioned from NEW to ALLOCATED
2013-08-11 06:26:49,727 INFO org.apache.hadoop.yarn.server.resourcemanager.RMAuditLogger: USER=ubuntu	OPERATION=AM Allocated Container	TARGET=SchedulerApp	RESULT=SUCCESS	APPID=application_1376201383303_0006	CONTAINERID=container_1376201383303_0006_01_000040
2013-08-11 06:26:49,727 INFO org.apache.hadoop.yarn.server.resourcemanager.scheduler.common.fica.FiCaSchedulerNode: Assigned container container_1376201383303_0006_01_000040 of capacity <memory:1024, vCores:1> on host hadoop-320-3:36899, which currently has 6 containers, <memory:8192, vCores:6> used and <memory:0, vCores:10> available
2013-08-11 06:26:49,728 INFO org.apache.hadoop.yarn.server.resourcemanager.scheduler.capacity.LeafQueue: assignedContainer application=application_1376201383303_0006 container=Container: [ContainerId: container_1376201383303_0006_01_000040, NodeId: hadoop-320-3:36899, NodeHttpAddress: hadoop-320-3:8042, Resource: <memory:1024, vCores:1>, Priority: 20, State: NEW, Token: null, Status: container_id {, app_attempt_id {, application_id {, id: 6, cluster_timestamp: 1376201383303, }, attemptId: 1, }, id: 40, }, state: C_NEW, ] containerId=container_1376201383303_0006_01_000040 queue=default: capacity=1.0, absoluteCapacity=1.0, usedResources=<memory:48128, vCores:42>usedCapacity=0.9791667, absoluteUsedCapacity=0.9791667, numApps=5, numContainers=42 usedCapacity=0.9791667 absoluteUsedCapacity=0.9791667 used=<memory:48128, vCores:42> cluster=<memory:49152, vCores:96>
2013-08-11 06:26:49,728 INFO org.apache.hadoop.yarn.server.resourcemanager.scheduler.capacity.ParentQueue: Re-sorting queues since queue: root.default stats: default: capacity=1.0, absoluteCapacity=1.0, usedResources=<memory:49152, vCores:43>usedCapacity=1.0, absoluteUsedCapacity=1.0, numApps=5, numContainers=43
2013-08-11 06:26:49,728 INFO org.apache.hadoop.yarn.server.resourcemanager.scheduler.capacity.ParentQueue: assignedContainer queue=root usedCapacity=1.0 absoluteUsedCapacity=1.0 used=<memory:49152, vCores:43> cluster=<memory:49152, vCores:96>
2013-08-11 06:26:50,946 INFO org.apache.hadoop.yarn.server.resourcemanager.rmcontainer.RMContainerImpl: container_1376201383303_0006_01_000040 Container Transitioned from ALLOCATED to ACQUIRED
2013-08-11 06:26:51,009 INFO org.apache.hadoop.yarn.server.resourcemanager.rmcontainer.RMContainerImpl: container_1376201383303_0006_01_000003 Container Transitioned from RUNNING to COMPLETED
2013-08-11 06:26:51,010 INFO org.apache.hadoop.yarn.server.resourcemanager.scheduler.common.fica.FiCaSchedulerApp: Completed container: container_1376201383303_0006_01_000003 in state: COMPLETED event:FINISHED
2013-08-11 06:26:51,010 INFO org.apache.hadoop.yarn.server.resourcemanager.RMAuditLogger: USER=ubuntu	OPERATION=AM Released Container	TARGET=SchedulerApp	RESULT=SUCCESS	APPID=application_1376201383303_0006	CONTAINERID=container_1376201383303_0006_01_000003
2013-08-11 06:26:51,010 INFO org.apache.hadoop.yarn.server.resourcemanager.scheduler.common.fica.FiCaSchedulerNode: Released container container_1376201383303_0006_01_000003 of capacity <memory:1024, vCores:1> on host hadoop-320-3:36899, which currently has 5 containers, <memory:7168, vCores:5> used and <memory:1024, vCores:11> available, release resources=true
2013-08-11 06:26:51,010 INFO org.apache.hadoop.yarn.server.resourcemanager.scheduler.capacity.LeafQueue: default used=<memory:48128, vCores:42> numContainers=42 user=ubuntu user-resources=<memory:48128, vCores:42>
2013-08-11 06:26:51,011 INFO org.apache.hadoop.yarn.server.resourcemanager.scheduler.capacity.LeafQueue: completedContainer container=Container: [ContainerId: container_1376201383303_0006_01_000003, NodeId: hadoop-320-3:36899, NodeHttpAddress: hadoop-320-3:8042, Resource: <memory:1024, vCores:1>, Priority: 20, State: NEW, Token: null, Status: container_id {, app_attempt_id {, application_id {, id: 6, cluster_timestamp: 1376201383303, }, attemptId: 1, }, id: 3, }, state: C_COMPLETE, diagnostics: "Container killed by the ApplicationMaster.\n\n", exit_status: 143, ] resource=<memory:1024, vCores:1> queue=default: capacity=1.0, absoluteCapacity=1.0, usedResources=<memory:48128, vCores:42>usedCapacity=0.9791667, absoluteUsedCapacity=0.9791667, numApps=5, numContainers=42 usedCapacity=0.9791667 absoluteUsedCapacity=0.9791667 used=<memory:48128, vCores:42> cluster=<memory:49152, vCores:96>
2013-08-11 06:26:51,012 INFO org.apache.hadoop.yarn.server.resourcemanager.scheduler.capacity.ParentQueue: completedContainer queue=root usedCapacity=0.9791667 absoluteUsedCapacity=0.9791667 used=<memory:48128, vCores:42> cluster=<memory:49152, vCores:96>
2013-08-11 06:26:51,012 INFO org.apache.hadoop.yarn.server.resourcemanager.scheduler.capacity.CapacityScheduler: Application appattempt_1376201383303_0006_000001 released container container_1376201383303_0006_01_000003 on node: host: hadoop-320-3:36899 #containers=5 available=1024 used=7168 with event: FINISHED
2013-08-11 06:26:51,012 INFO org.apache.hadoop.yarn.server.resourcemanager.rmcontainer.RMContainerImpl: container_1376201383303_0006_01_000041 Container Transitioned from NEW to ALLOCATED
2013-08-11 06:26:51,012 INFO org.apache.hadoop.yarn.server.resourcemanager.RMAuditLogger: USER=ubuntu	OPERATION=AM Allocated Container	TARGET=SchedulerApp	RESULT=SUCCESS	APPID=application_1376201383303_0006	CONTAINERID=container_1376201383303_0006_01_000041
2013-08-11 06:26:51,012 INFO org.apache.hadoop.yarn.server.resourcemanager.scheduler.common.fica.FiCaSchedulerNode: Assigned container container_1376201383303_0006_01_000041 of capacity <memory:1024, vCores:1> on host hadoop-320-3:36899, which currently has 6 containers, <memory:8192, vCores:6> used and <memory:0, vCores:10> available
2013-08-11 06:26:51,014 INFO org.apache.hadoop.yarn.server.resourcemanager.scheduler.capacity.LeafQueue: assignedContainer application=application_1376201383303_0006 container=Container: [ContainerId: container_1376201383303_0006_01_000041, NodeId: hadoop-320-3:36899, NodeHttpAddress: hadoop-320-3:8042, Resource: <memory:1024, vCores:1>, Priority: 10, State: NEW, Token: null, Status: container_id {, app_attempt_id {, application_id {, id: 6, cluster_timestamp: 1376201383303, }, attemptId: 1, }, id: 41, }, state: C_NEW, ] containerId=container_1376201383303_0006_01_000041 queue=default: capacity=1.0, absoluteCapacity=1.0, usedResources=<memory:48128, vCores:42>usedCapacity=0.9791667, absoluteUsedCapacity=0.9791667, numApps=5, numContainers=42 usedCapacity=0.9791667 absoluteUsedCapacity=0.9791667 used=<memory:48128, vCores:42> cluster=<memory:49152, vCores:96>
2013-08-11 06:26:51,014 INFO org.apache.hadoop.yarn.server.resourcemanager.scheduler.capacity.ParentQueue: Re-sorting queues since queue: root.default stats: default: capacity=1.0, absoluteCapacity=1.0, usedResources=<memory:49152, vCores:43>usedCapacity=1.0, absoluteUsedCapacity=1.0, numApps=5, numContainers=43
2013-08-11 06:26:51,014 INFO org.apache.hadoop.yarn.server.resourcemanager.scheduler.capacity.ParentQueue: assignedContainer queue=root usedCapacity=1.0 absoluteUsedCapacity=1.0 used=<memory:49152, vCores:43> cluster=<memory:49152, vCores:96>
2013-08-11 06:26:52,310 INFO org.apache.hadoop.yarn.server.resourcemanager.rmcontainer.RMContainerImpl: container_1376201383303_0006_01_000041 Container Transitioned from ALLOCATED to ACQUIRED
2013-08-11 06:26:52,349 INFO org.apache.hadoop.yarn.server.resourcemanager.rmcontainer.RMContainerImpl: container_1376201383303_0006_01_000040 Container Transitioned from ACQUIRED to RUNNING
2013-08-11 06:26:53,634 INFO org.apache.hadoop.yarn.server.resourcemanager.rmcontainer.RMContainerImpl: container_1376201383303_0006_01_000041 Container Transitioned from ACQUIRED to RUNNING
2013-08-11 06:26:53,635 INFO org.apache.hadoop.yarn.server.resourcemanager.rmcontainer.RMContainerImpl: container_1376201383303_0006_01_000004 Container Transitioned from RUNNING to COMPLETED
2013-08-11 06:26:53,635 INFO org.apache.hadoop.yarn.server.resourcemanager.scheduler.common.fica.FiCaSchedulerApp: Completed container: container_1376201383303_0006_01_000004 in state: COMPLETED event:FINISHED
2013-08-11 06:26:53,635 INFO org.apache.hadoop.yarn.server.resourcemanager.RMAuditLogger: USER=ubuntu	OPERATION=AM Released Container	TARGET=SchedulerApp	RESULT=SUCCESS	APPID=application_1376201383303_0006	CONTAINERID=container_1376201383303_0006_01_000004
2013-08-11 06:26:53,635 INFO org.apache.hadoop.yarn.server.resourcemanager.scheduler.common.fica.FiCaSchedulerNode: Released container container_1376201383303_0006_01_000004 of capacity <memory:1024, vCores:1> on host hadoop-320-3:36899, which currently has 5 containers, <memory:7168, vCores:5> used and <memory:1024, vCores:11> available, release resources=true
2013-08-11 06:26:53,636 INFO org.apache.hadoop.yarn.server.resourcemanager.scheduler.capacity.LeafQueue: default used=<memory:48128, vCores:42> numContainers=42 user=ubuntu user-resources=<memory:48128, vCores:42>
2013-08-11 06:26:53,637 INFO org.apache.hadoop.yarn.server.resourcemanager.scheduler.capacity.LeafQueue: completedContainer container=Container: [ContainerId: container_1376201383303_0006_01_000004, NodeId: hadoop-320-3:36899, NodeHttpAddress: hadoop-320-3:8042, Resource: <memory:1024, vCores:1>, Priority: 20, State: NEW, Token: null, Status: container_id {, app_attempt_id {, application_id {, id: 6, cluster_timestamp: 1376201383303, }, attemptId: 1, }, id: 4, }, state: C_COMPLETE, diagnostics: "Container killed by the ApplicationMaster.\n\n", exit_status: 143, ] resource=<memory:1024, vCores:1> queue=default: capacity=1.0, absoluteCapacity=1.0, usedResources=<memory:48128, vCores:42>usedCapacity=0.9791667, absoluteUsedCapacity=0.9791667, numApps=5, numContainers=42 usedCapacity=0.9791667 absoluteUsedCapacity=0.9791667 used=<memory:48128, vCores:42> cluster=<memory:49152, vCores:96>
2013-08-11 06:26:53,637 INFO org.apache.hadoop.yarn.server.resourcemanager.scheduler.capacity.ParentQueue: completedContainer queue=root usedCapacity=0.9791667 absoluteUsedCapacity=0.9791667 used=<memory:48128, vCores:42> cluster=<memory:49152, vCores:96>
2013-08-11 06:26:53,637 INFO org.apache.hadoop.yarn.server.resourcemanager.scheduler.capacity.CapacityScheduler: Application appattempt_1376201383303_0006_000001 released container container_1376201383303_0006_01_000004 on node: host: hadoop-320-3:36899 #containers=5 available=1024 used=7168 with event: FINISHED
2013-08-11 06:26:53,638 INFO org.apache.hadoop.yarn.server.resourcemanager.rmcontainer.RMContainerImpl: container_1376201383303_0006_01_000042 Container Transitioned from NEW to ALLOCATED
2013-08-11 06:26:53,638 INFO org.apache.hadoop.yarn.server.resourcemanager.RMAuditLogger: USER=ubuntu	OPERATION=AM Allocated Container	TARGET=SchedulerApp	RESULT=SUCCESS	APPID=application_1376201383303_0006	CONTAINERID=container_1376201383303_0006_01_000042
2013-08-11 06:26:53,638 INFO org.apache.hadoop.yarn.server.resourcemanager.scheduler.common.fica.FiCaSchedulerNode: Assigned container container_1376201383303_0006_01_000042 of capacity <memory:1024, vCores:1> on host hadoop-320-3:36899, which currently has 6 containers, <memory:8192, vCores:6> used and <memory:0, vCores:10> available
2013-08-11 06:26:53,639 INFO org.apache.hadoop.yarn.server.resourcemanager.scheduler.capacity.LeafQueue: assignedContainer application=application_1376201383303_0006 container=Container: [ContainerId: container_1376201383303_0006_01_000042, NodeId: hadoop-320-3:36899, NodeHttpAddress: hadoop-320-3:8042, Resource: <memory:1024, vCores:1>, Priority: 20, State: NEW, Token: null, Status: container_id {, app_attempt_id {, application_id {, id: 6, cluster_timestamp: 1376201383303, }, attemptId: 1, }, id: 42, }, state: C_NEW, ] containerId=container_1376201383303_0006_01_000042 queue=default: capacity=1.0, absoluteCapacity=1.0, usedResources=<memory:48128, vCores:42>usedCapacity=0.9791667, absoluteUsedCapacity=0.9791667, numApps=5, numContainers=42 usedCapacity=0.9791667 absoluteUsedCapacity=0.9791667 used=<memory:48128, vCores:42> cluster=<memory:49152, vCores:96>
2013-08-11 06:26:53,640 INFO org.apache.hadoop.yarn.server.resourcemanager.scheduler.capacity.ParentQueue: Re-sorting queues since queue: root.default stats: default: capacity=1.0, absoluteCapacity=1.0, usedResources=<memory:49152, vCores:43>usedCapacity=1.0, absoluteUsedCapacity=1.0, numApps=5, numContainers=43
2013-08-11 06:26:53,640 INFO org.apache.hadoop.yarn.server.resourcemanager.scheduler.capacity.ParentQueue: assignedContainer queue=root usedCapacity=1.0 absoluteUsedCapacity=1.0 used=<memory:49152, vCores:43> cluster=<memory:49152, vCores:96>
2013-08-11 06:26:53,677 INFO org.apache.hadoop.yarn.server.resourcemanager.rmcontainer.RMContainerImpl: container_1376201383303_0006_01_000042 Container Transitioned from ALLOCATED to ACQUIRED
2013-08-11 06:26:54,910 INFO org.apache.hadoop.yarn.server.resourcemanager.rmcontainer.RMContainerImpl: container_1376201383303_0006_01_000042 Container Transitioned from ACQUIRED to RUNNING
2013-08-11 06:26:54,911 INFO org.apache.hadoop.yarn.server.resourcemanager.rmcontainer.RMContainerImpl: container_1376201383303_0006_01_000005 Container Transitioned from RUNNING to COMPLETED
2013-08-11 06:26:54,911 INFO org.apache.hadoop.yarn.server.resourcemanager.scheduler.common.fica.FiCaSchedulerApp: Completed container: container_1376201383303_0006_01_000005 in state: COMPLETED event:FINISHED
2013-08-11 06:26:54,911 INFO org.apache.hadoop.yarn.server.resourcemanager.RMAuditLogger: USER=ubuntu	OPERATION=AM Released Container	TARGET=SchedulerApp	RESULT=SUCCESS	APPID=application_1376201383303_0006	CONTAINERID=container_1376201383303_0006_01_000005
2013-08-11 06:26:54,911 INFO org.apache.hadoop.yarn.server.resourcemanager.scheduler.common.fica.FiCaSchedulerNode: Released container container_1376201383303_0006_01_000005 of capacity <memory:1024, vCores:1> on host hadoop-320-3:36899, which currently has 5 containers, <memory:7168, vCores:5> used and <memory:1024, vCores:11> available, release resources=true
2013-08-11 06:26:54,911 INFO org.apache.hadoop.yarn.server.resourcemanager.scheduler.capacity.LeafQueue: default used=<memory:48128, vCores:42> numContainers=42 user=ubuntu user-resources=<memory:48128, vCores:42>
2013-08-11 06:26:54,913 INFO org.apache.hadoop.yarn.server.resourcemanager.scheduler.capacity.LeafQueue: completedContainer container=Container: [ContainerId: container_1376201383303_0006_01_000005, NodeId: hadoop-320-3:36899, NodeHttpAddress: hadoop-320-3:8042, Resource: <memory:1024, vCores:1>, Priority: 20, State: NEW, Token: null, Status: container_id {, app_attempt_id {, application_id {, id: 6, cluster_timestamp: 1376201383303, }, attemptId: 1, }, id: 5, }, state: C_COMPLETE, diagnostics: "Container killed by the ApplicationMaster.\n\n", exit_status: 143, ] resource=<memory:1024, vCores:1> queue=default: capacity=1.0, absoluteCapacity=1.0, usedResources=<memory:48128, vCores:42>usedCapacity=0.9791667, absoluteUsedCapacity=0.9791667, numApps=5, numContainers=42 usedCapacity=0.9791667 absoluteUsedCapacity=0.9791667 used=<memory:48128, vCores:42> cluster=<memory:49152, vCores:96>
2013-08-11 06:26:54,913 INFO org.apache.hadoop.yarn.server.resourcemanager.scheduler.capacity.ParentQueue: completedContainer queue=root usedCapacity=0.9791667 absoluteUsedCapacity=0.9791667 used=<memory:48128, vCores:42> cluster=<memory:49152, vCores:96>
2013-08-11 06:26:54,913 INFO org.apache.hadoop.yarn.server.resourcemanager.scheduler.capacity.CapacityScheduler: Application appattempt_1376201383303_0006_000001 released container container_1376201383303_0006_01_000005 on node: host: hadoop-320-3:36899 #containers=5 available=1024 used=7168 with event: FINISHED
2013-08-11 06:26:54,914 INFO org.apache.hadoop.yarn.server.resourcemanager.rmcontainer.RMContainerImpl: container_1376201383303_0006_01_000043 Container Transitioned from NEW to ALLOCATED
2013-08-11 06:26:54,914 INFO org.apache.hadoop.yarn.server.resourcemanager.RMAuditLogger: USER=ubuntu	OPERATION=AM Allocated Container	TARGET=SchedulerApp	RESULT=SUCCESS	APPID=application_1376201383303_0006	CONTAINERID=container_1376201383303_0006_01_000043
2013-08-11 06:26:54,914 INFO org.apache.hadoop.yarn.server.resourcemanager.scheduler.common.fica.FiCaSchedulerNode: Assigned container container_1376201383303_0006_01_000043 of capacity <memory:1024, vCores:1> on host hadoop-320-3:36899, which currently has 6 containers, <memory:8192, vCores:6> used and <memory:0, vCores:10> available
2013-08-11 06:26:54,915 INFO org.apache.hadoop.yarn.server.resourcemanager.scheduler.capacity.LeafQueue: assignedContainer application=application_1376201383303_0006 container=Container: [ContainerId: container_1376201383303_0006_01_000043, NodeId: hadoop-320-3:36899, NodeHttpAddress: hadoop-320-3:8042, Resource: <memory:1024, vCores:1>, Priority: 10, State: NEW, Token: null, Status: container_id {, app_attempt_id {, application_id {, id: 6, cluster_timestamp: 1376201383303, }, attemptId: 1, }, id: 43, }, state: C_NEW, ] containerId=container_1376201383303_0006_01_000043 queue=default: capacity=1.0, absoluteCapacity=1.0, usedResources=<memory:48128, vCores:42>usedCapacity=0.9791667, absoluteUsedCapacity=0.9791667, numApps=5, numContainers=42 usedCapacity=0.9791667 absoluteUsedCapacity=0.9791667 used=<memory:48128, vCores:42> cluster=<memory:49152, vCores:96>
2013-08-11 06:26:54,915 INFO org.apache.hadoop.yarn.server.resourcemanager.scheduler.capacity.ParentQueue: Re-sorting queues since queue: root.default stats: default: capacity=1.0, absoluteCapacity=1.0, usedResources=<memory:49152, vCores:43>usedCapacity=1.0, absoluteUsedCapacity=1.0, numApps=5, numContainers=43
2013-08-11 06:26:54,916 INFO org.apache.hadoop.yarn.server.resourcemanager.scheduler.capacity.ParentQueue: assignedContainer queue=root usedCapacity=1.0 absoluteUsedCapacity=1.0 used=<memory:49152, vCores:43> cluster=<memory:49152, vCores:96>
2013-08-11 06:26:55,892 INFO org.apache.hadoop.yarn.server.resourcemanager.scheduler.AppSchedulingInfo: checking for deactivate... 
2013-08-11 06:26:55,894 INFO org.apache.hadoop.yarn.server.resourcemanager.rmcontainer.RMContainerImpl: container_1376201383303_0006_01_000043 Container Transitioned from ALLOCATED to ACQUIRED
2013-08-11 06:26:57,568 INFO org.apache.hadoop.yarn.server.resourcemanager.rmcontainer.RMContainerImpl: container_1376201383303_0006_01_000043 Container Transitioned from ACQUIRED to RUNNING
2013-08-11 06:26:59,686 INFO org.apache.hadoop.yarn.server.resourcemanager.rmcontainer.RMContainerImpl: container_1376201383303_0006_01_000007 Container Transitioned from RUNNING to COMPLETED
2013-08-11 06:26:59,686 INFO org.apache.hadoop.yarn.server.resourcemanager.scheduler.common.fica.FiCaSchedulerApp: Completed container: container_1376201383303_0006_01_000007 in state: COMPLETED event:FINISHED
2013-08-11 06:26:59,686 INFO org.apache.hadoop.yarn.server.resourcemanager.RMAuditLogger: USER=ubuntu	OPERATION=AM Released Container	TARGET=SchedulerApp	RESULT=SUCCESS	APPID=application_1376201383303_0006	CONTAINERID=container_1376201383303_0006_01_000007
2013-08-11 06:26:59,687 INFO org.apache.hadoop.yarn.server.resourcemanager.scheduler.common.fica.FiCaSchedulerNode: Released container container_1376201383303_0006_01_000007 of capacity <memory:1024, vCores:1> on host hadoop-320-4:46709, which currently has 6 containers, <memory:7168, vCores:6> used and <memory:1024, vCores:10> available, release resources=true
2013-08-11 06:26:59,687 INFO org.apache.hadoop.yarn.server.resourcemanager.scheduler.capacity.LeafQueue: default used=<memory:48128, vCores:42> numContainers=42 user=ubuntu user-resources=<memory:48128, vCores:42>
2013-08-11 06:26:59,688 INFO org.apache.hadoop.yarn.server.resourcemanager.scheduler.capacity.LeafQueue: completedContainer container=Container: [ContainerId: container_1376201383303_0006_01_000007, NodeId: hadoop-320-4:46709, NodeHttpAddress: hadoop-320-4:8042, Resource: <memory:1024, vCores:1>, Priority: 20, State: NEW, Token: null, Status: container_id {, app_attempt_id {, application_id {, id: 6, cluster_timestamp: 1376201383303, }, attemptId: 1, }, id: 7, }, state: C_COMPLETE, diagnostics: "Container killed by the ApplicationMaster.\n\n", exit_status: 143, ] resource=<memory:1024, vCores:1> queue=default: capacity=1.0, absoluteCapacity=1.0, usedResources=<memory:48128, vCores:42>usedCapacity=0.9791667, absoluteUsedCapacity=0.9791667, numApps=5, numContainers=42 usedCapacity=0.9791667 absoluteUsedCapacity=0.9791667 used=<memory:48128, vCores:42> cluster=<memory:49152, vCores:96>
2013-08-11 06:26:59,688 INFO org.apache.hadoop.yarn.server.resourcemanager.scheduler.capacity.ParentQueue: completedContainer queue=root usedCapacity=0.9791667 absoluteUsedCapacity=0.9791667 used=<memory:48128, vCores:42> cluster=<memory:49152, vCores:96>
2013-08-11 06:26:59,688 INFO org.apache.hadoop.yarn.server.resourcemanager.scheduler.capacity.CapacityScheduler: Application appattempt_1376201383303_0006_000001 released container container_1376201383303_0006_01_000007 on node: host: hadoop-320-4:46709 #containers=6 available=1024 used=7168 with event: FINISHED
2013-08-11 06:26:59,689 INFO org.apache.hadoop.yarn.server.resourcemanager.rmcontainer.RMContainerImpl: container_1376201383303_0006_01_000010 Container Transitioned from RUNNING to COMPLETED
2013-08-11 06:26:59,689 INFO org.apache.hadoop.yarn.server.resourcemanager.scheduler.common.fica.FiCaSchedulerApp: Completed container: container_1376201383303_0006_01_000010 in state: COMPLETED event:FINISHED
2013-08-11 06:26:59,689 INFO org.apache.hadoop.yarn.server.resourcemanager.RMAuditLogger: USER=ubuntu	OPERATION=AM Released Container	TARGET=SchedulerApp	RESULT=SUCCESS	APPID=application_1376201383303_0006	CONTAINERID=container_1376201383303_0006_01_000010
2013-08-11 06:26:59,689 INFO org.apache.hadoop.yarn.server.resourcemanager.scheduler.common.fica.FiCaSchedulerNode: Released container container_1376201383303_0006_01_000010 of capacity <memory:1024, vCores:1> on host hadoop-320-4:46709, which currently has 5 containers, <memory:6144, vCores:5> used and <memory:2048, vCores:11> available, release resources=true
2013-08-11 06:26:59,689 INFO org.apache.hadoop.yarn.server.resourcemanager.scheduler.capacity.LeafQueue: default used=<memory:47104, vCores:41> numContainers=41 user=ubuntu user-resources=<memory:47104, vCores:41>
2013-08-11 06:26:59,690 INFO org.apache.hadoop.yarn.server.resourcemanager.scheduler.capacity.LeafQueue: completedContainer container=Container: [ContainerId: container_1376201383303_0006_01_000010, NodeId: hadoop-320-4:46709, NodeHttpAddress: hadoop-320-4:8042, Resource: <memory:1024, vCores:1>, Priority: 20, State: NEW, Token: null, Status: container_id {, app_attempt_id {, application_id {, id: 6, cluster_timestamp: 1376201383303, }, attemptId: 1, }, id: 10, }, state: C_COMPLETE, diagnostics: "", exit_status: 0, ] resource=<memory:1024, vCores:1> queue=default: capacity=1.0, absoluteCapacity=1.0, usedResources=<memory:47104, vCores:41>usedCapacity=0.9583333, absoluteUsedCapacity=0.9583333, numApps=5, numContainers=41 usedCapacity=0.9583333 absoluteUsedCapacity=0.9583333 used=<memory:47104, vCores:41> cluster=<memory:49152, vCores:96>
2013-08-11 06:26:59,691 INFO org.apache.hadoop.yarn.server.resourcemanager.scheduler.capacity.ParentQueue: completedContainer queue=root usedCapacity=0.9583333 absoluteUsedCapacity=0.9583333 used=<memory:47104, vCores:41> cluster=<memory:49152, vCores:96>
2013-08-11 06:26:59,691 INFO org.apache.hadoop.yarn.server.resourcemanager.scheduler.capacity.CapacityScheduler: Application appattempt_1376201383303_0006_000001 released container container_1376201383303_0006_01_000010 on node: host: hadoop-320-4:46709 #containers=5 available=2048 used=6144 with event: FINISHED
2013-08-11 06:26:59,691 INFO org.apache.hadoop.yarn.server.resourcemanager.rmcontainer.RMContainerImpl: container_1376201383303_0006_01_000044 Container Transitioned from NEW to ALLOCATED
2013-08-11 06:26:59,692 INFO org.apache.hadoop.yarn.server.resourcemanager.RMAuditLogger: USER=ubuntu	OPERATION=AM Allocated Container	TARGET=SchedulerApp	RESULT=SUCCESS	APPID=application_1376201383303_0006	CONTAINERID=container_1376201383303_0006_01_000044
2013-08-11 06:26:59,692 INFO org.apache.hadoop.yarn.server.resourcemanager.scheduler.common.fica.FiCaSchedulerNode: Assigned container container_1376201383303_0006_01_000044 of capacity <memory:1024, vCores:1> on host hadoop-320-4:46709, which currently has 6 containers, <memory:7168, vCores:6> used and <memory:1024, vCores:10> available
2013-08-11 06:26:59,693 INFO org.apache.hadoop.yarn.server.resourcemanager.scheduler.capacity.LeafQueue: assignedContainer application=application_1376201383303_0006 container=Container: [ContainerId: container_1376201383303_0006_01_000044, NodeId: hadoop-320-4:46709, NodeHttpAddress: hadoop-320-4:8042, Resource: <memory:1024, vCores:1>, Priority: 10, State: NEW, Token: null, Status: container_id {, app_attempt_id {, application_id {, id: 6, cluster_timestamp: 1376201383303, }, attemptId: 1, }, id: 44, }, state: C_NEW, ] containerId=container_1376201383303_0006_01_000044 queue=default: capacity=1.0, absoluteCapacity=1.0, usedResources=<memory:47104, vCores:41>usedCapacity=0.9583333, absoluteUsedCapacity=0.9583333, numApps=5, numContainers=41 usedCapacity=0.9583333 absoluteUsedCapacity=0.9583333 used=<memory:47104, vCores:41> cluster=<memory:49152, vCores:96>
2013-08-11 06:26:59,693 INFO org.apache.hadoop.yarn.server.resourcemanager.scheduler.capacity.ParentQueue: Re-sorting queues since queue: root.default stats: default: capacity=1.0, absoluteCapacity=1.0, usedResources=<memory:48128, vCores:42>usedCapacity=0.9791667, absoluteUsedCapacity=0.9791667, numApps=5, numContainers=42
2013-08-11 06:26:59,693 INFO org.apache.hadoop.yarn.server.resourcemanager.scheduler.capacity.ParentQueue: assignedContainer queue=root usedCapacity=0.9791667 absoluteUsedCapacity=0.9791667 used=<memory:48128, vCores:42> cluster=<memory:49152, vCores:96>
2013-08-11 06:27:00,092 INFO org.apache.hadoop.yarn.server.resourcemanager.rmcontainer.RMContainerImpl: container_1376201383303_0006_01_000035 Container Transitioned from RUNNING to COMPLETED
2013-08-11 06:27:00,093 INFO org.apache.hadoop.yarn.server.resourcemanager.scheduler.common.fica.FiCaSchedulerApp: Completed container: container_1376201383303_0006_01_000035 in state: COMPLETED event:FINISHED
2013-08-11 06:27:00,093 INFO org.apache.hadoop.yarn.server.resourcemanager.RMAuditLogger: USER=ubuntu	OPERATION=AM Released Container	TARGET=SchedulerApp	RESULT=SUCCESS	APPID=application_1376201383303_0006	CONTAINERID=container_1376201383303_0006_01_000035
2013-08-11 06:27:00,093 INFO org.apache.hadoop.yarn.server.resourcemanager.scheduler.common.fica.FiCaSchedulerNode: Released container container_1376201383303_0006_01_000035 of capacity <memory:1024, vCores:1> on host hadoop-320-5:32992, which currently has 6 containers, <memory:7168, vCores:6> used and <memory:1024, vCores:10> available, release resources=true
2013-08-11 06:27:00,093 INFO org.apache.hadoop.yarn.server.resourcemanager.scheduler.capacity.LeafQueue: default used=<memory:47104, vCores:41> numContainers=41 user=ubuntu user-resources=<memory:47104, vCores:41>
2013-08-11 06:27:00,094 INFO org.apache.hadoop.yarn.server.resourcemanager.scheduler.capacity.LeafQueue: completedContainer container=Container: [ContainerId: container_1376201383303_0006_01_000035, NodeId: hadoop-320-5:32992, NodeHttpAddress: hadoop-320-5:8042, Resource: <memory:1024, vCores:1>, Priority: 20, State: NEW, Token: null, Status: container_id {, app_attempt_id {, application_id {, id: 6, cluster_timestamp: 1376201383303, }, attemptId: 1, }, id: 35, }, state: C_COMPLETE, diagnostics: "Container killed by the ApplicationMaster.\n\n", exit_status: 143, ] resource=<memory:1024, vCores:1> queue=default: capacity=1.0, absoluteCapacity=1.0, usedResources=<memory:47104, vCores:41>usedCapacity=0.9583333, absoluteUsedCapacity=0.9583333, numApps=5, numContainers=41 usedCapacity=0.9583333 absoluteUsedCapacity=0.9583333 used=<memory:47104, vCores:41> cluster=<memory:49152, vCores:96>
2013-08-11 06:27:00,095 INFO org.apache.hadoop.yarn.server.resourcemanager.scheduler.capacity.ParentQueue: completedContainer queue=root usedCapacity=0.9583333 absoluteUsedCapacity=0.9583333 used=<memory:47104, vCores:41> cluster=<memory:49152, vCores:96>
2013-08-11 06:27:00,095 INFO org.apache.hadoop.yarn.server.resourcemanager.scheduler.capacity.CapacityScheduler: Application appattempt_1376201383303_0006_000001 released container container_1376201383303_0006_01_000035 on node: host: hadoop-320-5:32992 #containers=6 available=1024 used=7168 with event: FINISHED
2013-08-11 06:27:00,095 INFO org.apache.hadoop.yarn.server.resourcemanager.rmcontainer.RMContainerImpl: container_1376201383303_0006_01_000036 Container Transitioned from RUNNING to COMPLETED
2013-08-11 06:27:00,095 INFO org.apache.hadoop.yarn.server.resourcemanager.scheduler.common.fica.FiCaSchedulerApp: Completed container: container_1376201383303_0006_01_000036 in state: COMPLETED event:FINISHED
2013-08-11 06:27:00,095 INFO org.apache.hadoop.yarn.server.resourcemanager.RMAuditLogger: USER=ubuntu	OPERATION=AM Released Container	TARGET=SchedulerApp	RESULT=SUCCESS	APPID=application_1376201383303_0006	CONTAINERID=container_1376201383303_0006_01_000036
2013-08-11 06:27:00,096 INFO org.apache.hadoop.yarn.server.resourcemanager.scheduler.common.fica.FiCaSchedulerNode: Released container container_1376201383303_0006_01_000036 of capacity <memory:1024, vCores:1> on host hadoop-320-5:32992, which currently has 5 containers, <memory:6144, vCores:5> used and <memory:2048, vCores:11> available, release resources=true
2013-08-11 06:27:00,096 INFO org.apache.hadoop.yarn.server.resourcemanager.scheduler.capacity.LeafQueue: default used=<memory:46080, vCores:40> numContainers=40 user=ubuntu user-resources=<memory:46080, vCores:40>
2013-08-11 06:27:00,097 INFO org.apache.hadoop.yarn.server.resourcemanager.scheduler.capacity.LeafQueue: completedContainer container=Container: [ContainerId: container_1376201383303_0006_01_000036, NodeId: hadoop-320-5:32992, NodeHttpAddress: hadoop-320-5:8042, Resource: <memory:1024, vCores:1>, Priority: 20, State: NEW, Token: null, Status: container_id {, app_attempt_id {, application_id {, id: 6, cluster_timestamp: 1376201383303, }, attemptId: 1, }, id: 36, }, state: C_COMPLETE, diagnostics: "Container killed by the ApplicationMaster.\n\n", exit_status: 143, ] resource=<memory:1024, vCores:1> queue=default: capacity=1.0, absoluteCapacity=1.0, usedResources=<memory:46080, vCores:40>usedCapacity=0.9375, absoluteUsedCapacity=0.9375, numApps=5, numContainers=40 usedCapacity=0.9375 absoluteUsedCapacity=0.9375 used=<memory:46080, vCores:40> cluster=<memory:49152, vCores:96>
2013-08-11 06:27:00,097 INFO org.apache.hadoop.yarn.server.resourcemanager.scheduler.capacity.ParentQueue: completedContainer queue=root usedCapacity=0.9375 absoluteUsedCapacity=0.9375 used=<memory:46080, vCores:40> cluster=<memory:49152, vCores:96>
2013-08-11 06:27:00,097 INFO org.apache.hadoop.yarn.server.resourcemanager.scheduler.capacity.CapacityScheduler: Application appattempt_1376201383303_0006_000001 released container container_1376201383303_0006_01_000036 on node: host: hadoop-320-5:32992 #containers=5 available=2048 used=6144 with event: FINISHED
2013-08-11 06:27:00,098 INFO org.apache.hadoop.yarn.server.resourcemanager.rmcontainer.RMContainerImpl: container_1376201383303_0006_01_000045 Container Transitioned from NEW to ALLOCATED
2013-08-11 06:27:00,098 INFO org.apache.hadoop.yarn.server.resourcemanager.RMAuditLogger: USER=ubuntu	OPERATION=AM Allocated Container	TARGET=SchedulerApp	RESULT=SUCCESS	APPID=application_1376201383303_0006	CONTAINERID=container_1376201383303_0006_01_000045
2013-08-11 06:27:00,098 INFO org.apache.hadoop.yarn.server.resourcemanager.scheduler.common.fica.FiCaSchedulerNode: Assigned container container_1376201383303_0006_01_000045 of capacity <memory:1024, vCores:1> on host hadoop-320-5:32992, which currently has 6 containers, <memory:7168, vCores:6> used and <memory:1024, vCores:10> available
2013-08-11 06:27:00,099 INFO org.apache.hadoop.yarn.server.resourcemanager.scheduler.capacity.LeafQueue: assignedContainer application=application_1376201383303_0006 container=Container: [ContainerId: container_1376201383303_0006_01_000045, NodeId: hadoop-320-5:32992, NodeHttpAddress: hadoop-320-5:8042, Resource: <memory:1024, vCores:1>, Priority: 10, State: NEW, Token: null, Status: container_id {, app_attempt_id {, application_id {, id: 6, cluster_timestamp: 1376201383303, }, attemptId: 1, }, id: 45, }, state: C_NEW, ] containerId=container_1376201383303_0006_01_000045 queue=default: capacity=1.0, absoluteCapacity=1.0, usedResources=<memory:46080, vCores:40>usedCapacity=0.9375, absoluteUsedCapacity=0.9375, numApps=5, numContainers=40 usedCapacity=0.9375 absoluteUsedCapacity=0.9375 used=<memory:46080, vCores:40> cluster=<memory:49152, vCores:96>
2013-08-11 06:27:00,099 INFO org.apache.hadoop.yarn.server.resourcemanager.scheduler.capacity.ParentQueue: Re-sorting queues since queue: root.default stats: default: capacity=1.0, absoluteCapacity=1.0, usedResources=<memory:47104, vCores:41>usedCapacity=0.9583333, absoluteUsedCapacity=0.9583333, numApps=5, numContainers=41
2013-08-11 06:27:00,100 INFO org.apache.hadoop.yarn.server.resourcemanager.scheduler.capacity.ParentQueue: assignedContainer queue=root usedCapacity=0.9583333 absoluteUsedCapacity=0.9583333 used=<memory:47104, vCores:41> cluster=<memory:49152, vCores:96>
2013-08-11 06:27:00,673 INFO org.apache.hadoop.yarn.server.resourcemanager.rmcontainer.RMContainerImpl: container_1376201383303_0006_01_000044 Container Transitioned from ALLOCATED to ACQUIRED
2013-08-11 06:27:00,674 INFO org.apache.hadoop.yarn.server.resourcemanager.rmcontainer.RMContainerImpl: container_1376201383303_0006_01_000045 Container Transitioned from ALLOCATED to ACQUIRED
2013-08-11 06:27:00,798 INFO org.apache.hadoop.yarn.server.resourcemanager.rmcontainer.RMContainerImpl: container_1376201383303_0006_01_000046 Container Transitioned from NEW to ALLOCATED
2013-08-11 06:27:00,799 INFO org.apache.hadoop.yarn.server.resourcemanager.RMAuditLogger: USER=ubuntu	OPERATION=AM Allocated Container	TARGET=SchedulerApp	RESULT=SUCCESS	APPID=application_1376201383303_0006	CONTAINERID=container_1376201383303_0006_01_000046
2013-08-11 06:27:00,799 INFO org.apache.hadoop.yarn.server.resourcemanager.scheduler.common.fica.FiCaSchedulerNode: Assigned container container_1376201383303_0006_01_000046 of capacity <memory:1024, vCores:1> on host hadoop-320-5:32992, which currently has 7 containers, <memory:8192, vCores:7> used and <memory:0, vCores:9> available
2013-08-11 06:27:00,800 INFO org.apache.hadoop.yarn.server.resourcemanager.scheduler.capacity.LeafQueue: assignedContainer application=application_1376201383303_0006 container=Container: [ContainerId: container_1376201383303_0006_01_000046, NodeId: hadoop-320-5:32992, NodeHttpAddress: hadoop-320-5:8042, Resource: <memory:1024, vCores:1>, Priority: 10, State: NEW, Token: null, Status: container_id {, app_attempt_id {, application_id {, id: 6, cluster_timestamp: 1376201383303, }, attemptId: 1, }, id: 46, }, state: C_NEW, ] containerId=container_1376201383303_0006_01_000046 queue=default: capacity=1.0, absoluteCapacity=1.0, usedResources=<memory:47104, vCores:41>usedCapacity=0.9583333, absoluteUsedCapacity=0.9583333, numApps=5, numContainers=41 usedCapacity=0.9583333 absoluteUsedCapacity=0.9583333 used=<memory:47104, vCores:41> cluster=<memory:49152, vCores:96>
2013-08-11 06:27:00,800 INFO org.apache.hadoop.yarn.server.resourcemanager.scheduler.capacity.ParentQueue: Re-sorting queues since queue: root.default stats: default: capacity=1.0, absoluteCapacity=1.0, usedResources=<memory:48128, vCores:42>usedCapacity=0.9791667, absoluteUsedCapacity=0.9791667, numApps=5, numContainers=42
2013-08-11 06:27:00,800 INFO org.apache.hadoop.yarn.server.resourcemanager.scheduler.capacity.ParentQueue: assignedContainer queue=root usedCapacity=0.9791667 absoluteUsedCapacity=0.9791667 used=<memory:48128, vCores:42> cluster=<memory:49152, vCores:96>
2013-08-11 06:27:00,876 INFO org.apache.hadoop.yarn.server.resourcemanager.rmcontainer.RMContainerImpl: container_1376201383303_0007_01_000002 Container Transitioned from NEW to ALLOCATED
2013-08-11 06:27:00,877 INFO org.apache.hadoop.yarn.server.resourcemanager.RMAuditLogger: USER=ubuntu	OPERATION=AM Allocated Container	TARGET=SchedulerApp	RESULT=SUCCESS	APPID=application_1376201383303_0007	CONTAINERID=container_1376201383303_0007_01_000002
2013-08-11 06:27:00,877 INFO org.apache.hadoop.yarn.server.resourcemanager.scheduler.common.fica.FiCaSchedulerNode: Assigned container container_1376201383303_0007_01_000002 of capacity <memory:1024, vCores:1> on host hadoop-320-4:46709, which currently has 7 containers, <memory:8192, vCores:7> used and <memory:0, vCores:9> available
2013-08-11 06:27:00,878 INFO org.apache.hadoop.yarn.server.resourcemanager.scheduler.capacity.LeafQueue: assignedContainer application=application_1376201383303_0007 container=Container: [ContainerId: container_1376201383303_0007_01_000002, NodeId: hadoop-320-4:46709, NodeHttpAddress: hadoop-320-4:8042, Resource: <memory:1024, vCores:1>, Priority: 20, State: NEW, Token: null, Status: container_id {, app_attempt_id {, application_id {, id: 7, cluster_timestamp: 1376201383303, }, attemptId: 1, }, id: 2, }, state: C_NEW, ] containerId=container_1376201383303_0007_01_000002 queue=default: capacity=1.0, absoluteCapacity=1.0, usedResources=<memory:48128, vCores:42>usedCapacity=0.9791667, absoluteUsedCapacity=0.9791667, numApps=5, numContainers=42 usedCapacity=0.9791667 absoluteUsedCapacity=0.9791667 used=<memory:48128, vCores:42> cluster=<memory:49152, vCores:96>
2013-08-11 06:27:00,878 INFO org.apache.hadoop.yarn.server.resourcemanager.scheduler.capacity.ParentQueue: Re-sorting queues since queue: root.default stats: default: capacity=1.0, absoluteCapacity=1.0, usedResources=<memory:49152, vCores:43>usedCapacity=1.0, absoluteUsedCapacity=1.0, numApps=5, numContainers=43
2013-08-11 06:27:00,878 INFO org.apache.hadoop.yarn.server.resourcemanager.scheduler.capacity.ParentQueue: assignedContainer queue=root usedCapacity=1.0 absoluteUsedCapacity=1.0 used=<memory:49152, vCores:43> cluster=<memory:49152, vCores:96>
2013-08-11 06:27:01,777 INFO org.apache.hadoop.yarn.server.resourcemanager.rmcontainer.RMContainerImpl: container_1376201383303_0007_01_000002 Container Transitioned from ALLOCATED to ACQUIRED
2013-08-11 06:27:01,815 INFO org.apache.hadoop.yarn.server.resourcemanager.rmcontainer.RMContainerImpl: container_1376201383303_0006_01_000046 Container Transitioned from ALLOCATED to ACQUIRED
2013-08-11 06:27:01,822 INFO org.apache.hadoop.yarn.server.resourcemanager.rmcontainer.RMContainerImpl: container_1376201383303_0006_01_000045 Container Transitioned from ACQUIRED to RUNNING
2013-08-11 06:27:01,822 INFO org.apache.hadoop.yarn.server.resourcemanager.rmcontainer.RMContainerImpl: container_1376201383303_0006_01_000037 Container Transitioned from RUNNING to COMPLETED
2013-08-11 06:27:01,823 INFO org.apache.hadoop.yarn.server.resourcemanager.scheduler.common.fica.FiCaSchedulerApp: Completed container: container_1376201383303_0006_01_000037 in state: COMPLETED event:FINISHED
2013-08-11 06:27:01,823 INFO org.apache.hadoop.yarn.server.resourcemanager.RMAuditLogger: USER=ubuntu	OPERATION=AM Released Container	TARGET=SchedulerApp	RESULT=SUCCESS	APPID=application_1376201383303_0006	CONTAINERID=container_1376201383303_0006_01_000037
2013-08-11 06:27:01,823 INFO org.apache.hadoop.yarn.server.resourcemanager.scheduler.common.fica.FiCaSchedulerNode: Released container container_1376201383303_0006_01_000037 of capacity <memory:1024, vCores:1> on host hadoop-320-5:32992, which currently has 6 containers, <memory:7168, vCores:6> used and <memory:1024, vCores:10> available, release resources=true
2013-08-11 06:27:01,823 INFO org.apache.hadoop.yarn.server.resourcemanager.scheduler.capacity.LeafQueue: default used=<memory:48128, vCores:42> numContainers=42 user=ubuntu user-resources=<memory:48128, vCores:42>
2013-08-11 06:27:01,824 INFO org.apache.hadoop.yarn.server.resourcemanager.scheduler.capacity.LeafQueue: completedContainer container=Container: [ContainerId: container_1376201383303_0006_01_000037, NodeId: hadoop-320-5:32992, NodeHttpAddress: hadoop-320-5:8042, Resource: <memory:1024, vCores:1>, Priority: 20, State: NEW, Token: null, Status: container_id {, app_attempt_id {, application_id {, id: 6, cluster_timestamp: 1376201383303, }, attemptId: 1, }, id: 37, }, state: C_COMPLETE, diagnostics: "", exit_status: 0, ] resource=<memory:1024, vCores:1> queue=default: capacity=1.0, absoluteCapacity=1.0, usedResources=<memory:48128, vCores:42>usedCapacity=0.9791667, absoluteUsedCapacity=0.9791667, numApps=5, numContainers=42 usedCapacity=0.9791667 absoluteUsedCapacity=0.9791667 used=<memory:48128, vCores:42> cluster=<memory:49152, vCores:96>
2013-08-11 06:27:01,825 INFO org.apache.hadoop.yarn.server.resourcemanager.scheduler.capacity.ParentQueue: completedContainer queue=root usedCapacity=0.9791667 absoluteUsedCapacity=0.9791667 used=<memory:48128, vCores:42> cluster=<memory:49152, vCores:96>
2013-08-11 06:27:01,825 INFO org.apache.hadoop.yarn.server.resourcemanager.scheduler.capacity.CapacityScheduler: Application appattempt_1376201383303_0006_000001 released container container_1376201383303_0006_01_000037 on node: host: hadoop-320-5:32992 #containers=6 available=1024 used=7168 with event: FINISHED
2013-08-11 06:27:01,825 INFO org.apache.hadoop.yarn.server.resourcemanager.rmcontainer.RMContainerImpl: container_1376201383303_0006_01_000047 Container Transitioned from NEW to ALLOCATED
2013-08-11 06:27:01,825 INFO org.apache.hadoop.yarn.server.resourcemanager.RMAuditLogger: USER=ubuntu	OPERATION=AM Allocated Container	TARGET=SchedulerApp	RESULT=SUCCESS	APPID=application_1376201383303_0006	CONTAINERID=container_1376201383303_0006_01_000047
2013-08-11 06:27:01,826 INFO org.apache.hadoop.yarn.server.resourcemanager.scheduler.common.fica.FiCaSchedulerNode: Assigned container container_1376201383303_0006_01_000047 of capacity <memory:1024, vCores:1> on host hadoop-320-5:32992, which currently has 7 containers, <memory:8192, vCores:7> used and <memory:0, vCores:9> available
2013-08-11 06:27:01,827 INFO org.apache.hadoop.yarn.server.resourcemanager.scheduler.capacity.LeafQueue: assignedContainer application=application_1376201383303_0006 container=Container: [ContainerId: container_1376201383303_0006_01_000047, NodeId: hadoop-320-5:32992, NodeHttpAddress: hadoop-320-5:8042, Resource: <memory:1024, vCores:1>, Priority: 10, State: NEW, Token: null, Status: container_id {, app_attempt_id {, application_id {, id: 6, cluster_timestamp: 1376201383303, }, attemptId: 1, }, id: 47, }, state: C_NEW, ] containerId=container_1376201383303_0006_01_000047 queue=default: capacity=1.0, absoluteCapacity=1.0, usedResources=<memory:48128, vCores:42>usedCapacity=0.9791667, absoluteUsedCapacity=0.9791667, numApps=5, numContainers=42 usedCapacity=0.9791667 absoluteUsedCapacity=0.9791667 used=<memory:48128, vCores:42> cluster=<memory:49152, vCores:96>
2013-08-11 06:27:01,827 INFO org.apache.hadoop.yarn.server.resourcemanager.scheduler.capacity.ParentQueue: Re-sorting queues since queue: root.default stats: default: capacity=1.0, absoluteCapacity=1.0, usedResources=<memory:49152, vCores:43>usedCapacity=1.0, absoluteUsedCapacity=1.0, numApps=5, numContainers=43
2013-08-11 06:27:01,827 INFO org.apache.hadoop.yarn.server.resourcemanager.scheduler.capacity.ParentQueue: assignedContainer queue=root usedCapacity=1.0 absoluteUsedCapacity=1.0 used=<memory:49152, vCores:43> cluster=<memory:49152, vCores:96>
2013-08-11 06:27:01,915 INFO org.apache.hadoop.yarn.server.resourcemanager.rmcontainer.RMContainerImpl: container_1376201383303_0006_01_000044 Container Transitioned from ACQUIRED to RUNNING
2013-08-11 06:27:01,915 INFO org.apache.hadoop.yarn.server.resourcemanager.rmcontainer.RMContainerImpl: container_1376201383303_0006_01_000006 Container Transitioned from RUNNING to COMPLETED
2013-08-11 06:27:01,915 INFO org.apache.hadoop.yarn.server.resourcemanager.scheduler.common.fica.FiCaSchedulerApp: Completed container: container_1376201383303_0006_01_000006 in state: COMPLETED event:FINISHED
2013-08-11 06:27:01,915 INFO org.apache.hadoop.yarn.server.resourcemanager.RMAuditLogger: USER=ubuntu	OPERATION=AM Released Container	TARGET=SchedulerApp	RESULT=SUCCESS	APPID=application_1376201383303_0006	CONTAINERID=container_1376201383303_0006_01_000006
2013-08-11 06:27:01,915 INFO org.apache.hadoop.yarn.server.resourcemanager.scheduler.common.fica.FiCaSchedulerNode: Released container container_1376201383303_0006_01_000006 of capacity <memory:1024, vCores:1> on host hadoop-320-4:46709, which currently has 6 containers, <memory:7168, vCores:6> used and <memory:1024, vCores:10> available, release resources=true
2013-08-11 06:27:01,916 INFO org.apache.hadoop.yarn.server.resourcemanager.scheduler.capacity.LeafQueue: default used=<memory:48128, vCores:42> numContainers=42 user=ubuntu user-resources=<memory:48128, vCores:42>
2013-08-11 06:27:01,917 INFO org.apache.hadoop.yarn.server.resourcemanager.scheduler.capacity.LeafQueue: completedContainer container=Container: [ContainerId: container_1376201383303_0006_01_000006, NodeId: hadoop-320-4:46709, NodeHttpAddress: hadoop-320-4:8042, Resource: <memory:1024, vCores:1>, Priority: 20, State: NEW, Token: null, Status: container_id {, app_attempt_id {, application_id {, id: 6, cluster_timestamp: 1376201383303, }, attemptId: 1, }, id: 6, }, state: C_COMPLETE, diagnostics: "", exit_status: 0, ] resource=<memory:1024, vCores:1> queue=default: capacity=1.0, absoluteCapacity=1.0, usedResources=<memory:48128, vCores:42>usedCapacity=0.9791667, absoluteUsedCapacity=0.9791667, numApps=5, numContainers=42 usedCapacity=0.9791667 absoluteUsedCapacity=0.9791667 used=<memory:48128, vCores:42> cluster=<memory:49152, vCores:96>
2013-08-11 06:27:01,917 INFO org.apache.hadoop.yarn.server.resourcemanager.scheduler.capacity.ParentQueue: completedContainer queue=root usedCapacity=0.9791667 absoluteUsedCapacity=0.9791667 used=<memory:48128, vCores:42> cluster=<memory:49152, vCores:96>
2013-08-11 06:27:01,917 INFO org.apache.hadoop.yarn.server.resourcemanager.scheduler.capacity.CapacityScheduler: Application appattempt_1376201383303_0006_000001 released container container_1376201383303_0006_01_000006 on node: host: hadoop-320-4:46709 #containers=6 available=1024 used=7168 with event: FINISHED
2013-08-11 06:27:01,918 INFO org.apache.hadoop.yarn.server.resourcemanager.rmcontainer.RMContainerImpl: container_1376201383303_0007_01_000003 Container Transitioned from NEW to ALLOCATED
2013-08-11 06:27:01,918 INFO org.apache.hadoop.yarn.server.resourcemanager.RMAuditLogger: USER=ubuntu	OPERATION=AM Allocated Container	TARGET=SchedulerApp	RESULT=SUCCESS	APPID=application_1376201383303_0007	CONTAINERID=container_1376201383303_0007_01_000003
2013-08-11 06:27:01,918 INFO org.apache.hadoop.yarn.server.resourcemanager.scheduler.common.fica.FiCaSchedulerNode: Assigned container container_1376201383303_0007_01_000003 of capacity <memory:1024, vCores:1> on host hadoop-320-4:46709, which currently has 7 containers, <memory:8192, vCores:7> used and <memory:0, vCores:9> available
2013-08-11 06:27:01,919 INFO org.apache.hadoop.yarn.server.resourcemanager.scheduler.capacity.LeafQueue: assignedContainer application=application_1376201383303_0007 container=Container: [ContainerId: container_1376201383303_0007_01_000003, NodeId: hadoop-320-4:46709, NodeHttpAddress: hadoop-320-4:8042, Resource: <memory:1024, vCores:1>, Priority: 20, State: NEW, Token: null, Status: container_id {, app_attempt_id {, application_id {, id: 7, cluster_timestamp: 1376201383303, }, attemptId: 1, }, id: 3, }, state: C_NEW, ] containerId=container_1376201383303_0007_01_000003 queue=default: capacity=1.0, absoluteCapacity=1.0, usedResources=<memory:48128, vCores:42>usedCapacity=0.9791667, absoluteUsedCapacity=0.9791667, numApps=5, numContainers=42 usedCapacity=0.9791667 absoluteUsedCapacity=0.9791667 used=<memory:48128, vCores:42> cluster=<memory:49152, vCores:96>
2013-08-11 06:27:01,919 INFO org.apache.hadoop.yarn.server.resourcemanager.scheduler.capacity.ParentQueue: Re-sorting queues since queue: root.default stats: default: capacity=1.0, absoluteCapacity=1.0, usedResources=<memory:49152, vCores:43>usedCapacity=1.0, absoluteUsedCapacity=1.0, numApps=5, numContainers=43
2013-08-11 06:27:01,919 INFO org.apache.hadoop.yarn.server.resourcemanager.scheduler.capacity.ParentQueue: assignedContainer queue=root usedCapacity=1.0 absoluteUsedCapacity=1.0 used=<memory:49152, vCores:43> cluster=<memory:49152, vCores:96>
2013-08-11 06:27:02,829 INFO org.apache.hadoop.yarn.server.resourcemanager.rmcontainer.RMContainerImpl: container_1376201383303_0006_01_000046 Container Transitioned from ACQUIRED to RUNNING
2013-08-11 06:27:02,953 INFO org.apache.hadoop.yarn.server.resourcemanager.scheduler.AppSchedulingInfo: checking for deactivate... 
2013-08-11 06:27:02,954 INFO org.apache.hadoop.yarn.server.resourcemanager.rmcontainer.RMContainerImpl: container_1376201383303_0006_01_000047 Container Transitioned from ALLOCATED to ACQUIRED
2013-08-11 06:27:03,094 INFO org.apache.hadoop.yarn.server.resourcemanager.rmcontainer.RMContainerImpl: container_1376201383303_0007_01_000002 Container Transitioned from ACQUIRED to RUNNING
2013-08-11 06:27:03,353 INFO org.apache.hadoop.yarn.server.resourcemanager.rmcontainer.RMContainerImpl: container_1376201383303_0006_01_000025 Container Transitioned from RUNNING to COMPLETED
2013-08-11 06:27:03,353 INFO org.apache.hadoop.yarn.server.resourcemanager.scheduler.common.fica.FiCaSchedulerApp: Completed container: container_1376201383303_0006_01_000025 in state: COMPLETED event:FINISHED
2013-08-11 06:27:03,353 INFO org.apache.hadoop.yarn.server.resourcemanager.RMAuditLogger: USER=ubuntu	OPERATION=AM Released Container	TARGET=SchedulerApp	RESULT=SUCCESS	APPID=application_1376201383303_0006	CONTAINERID=container_1376201383303_0006_01_000025
2013-08-11 06:27:03,353 INFO org.apache.hadoop.yarn.server.resourcemanager.scheduler.common.fica.FiCaSchedulerNode: Released container container_1376201383303_0006_01_000025 of capacity <memory:1024, vCores:1> on host hadoop-320-2:40354, which currently has 7 containers, <memory:7168, vCores:7> used and <memory:1024, vCores:9> available, release resources=true
2013-08-11 06:27:03,354 INFO org.apache.hadoop.yarn.server.resourcemanager.scheduler.capacity.LeafQueue: default used=<memory:48128, vCores:42> numContainers=42 user=ubuntu user-resources=<memory:48128, vCores:42>
2013-08-11 06:27:03,355 INFO org.apache.hadoop.yarn.server.resourcemanager.scheduler.capacity.LeafQueue: completedContainer container=Container: [ContainerId: container_1376201383303_0006_01_000025, NodeId: hadoop-320-2:40354, NodeHttpAddress: hadoop-320-2:8042, Resource: <memory:1024, vCores:1>, Priority: 20, State: NEW, Token: null, Status: container_id {, app_attempt_id {, application_id {, id: 6, cluster_timestamp: 1376201383303, }, attemptId: 1, }, id: 25, }, state: C_COMPLETE, diagnostics: "", exit_status: 0, ] resource=<memory:1024, vCores:1> queue=default: capacity=1.0, absoluteCapacity=1.0, usedResources=<memory:48128, vCores:42>usedCapacity=0.9791667, absoluteUsedCapacity=0.9791667, numApps=5, numContainers=42 usedCapacity=0.9791667 absoluteUsedCapacity=0.9791667 used=<memory:48128, vCores:42> cluster=<memory:49152, vCores:96>
2013-08-11 06:27:03,355 INFO org.apache.hadoop.yarn.server.resourcemanager.scheduler.capacity.ParentQueue: completedContainer queue=root usedCapacity=0.9791667 absoluteUsedCapacity=0.9791667 used=<memory:48128, vCores:42> cluster=<memory:49152, vCores:96>
2013-08-11 06:27:03,355 INFO org.apache.hadoop.yarn.server.resourcemanager.scheduler.capacity.CapacityScheduler: Application appattempt_1376201383303_0006_000001 released container container_1376201383303_0006_01_000025 on node: host: hadoop-320-2:40354 #containers=7 available=1024 used=7168 with event: FINISHED
2013-08-11 06:27:03,356 INFO org.apache.hadoop.yarn.server.resourcemanager.rmcontainer.RMContainerImpl: container_1376201383303_0007_01_000004 Container Transitioned from NEW to ALLOCATED
2013-08-11 06:27:03,356 INFO org.apache.hadoop.yarn.server.resourcemanager.RMAuditLogger: USER=ubuntu	OPERATION=AM Allocated Container	TARGET=SchedulerApp	RESULT=SUCCESS	APPID=application_1376201383303_0007	CONTAINERID=container_1376201383303_0007_01_000004
2013-08-11 06:27:03,356 INFO org.apache.hadoop.yarn.server.resourcemanager.scheduler.common.fica.FiCaSchedulerNode: Assigned container container_1376201383303_0007_01_000004 of capacity <memory:1024, vCores:1> on host hadoop-320-2:40354, which currently has 8 containers, <memory:8192, vCores:8> used and <memory:0, vCores:8> available
2013-08-11 06:27:03,357 INFO org.apache.hadoop.yarn.server.resourcemanager.scheduler.capacity.LeafQueue: assignedContainer application=application_1376201383303_0007 container=Container: [ContainerId: container_1376201383303_0007_01_000004, NodeId: hadoop-320-2:40354, NodeHttpAddress: hadoop-320-2:8042, Resource: <memory:1024, vCores:1>, Priority: 20, State: NEW, Token: null, Status: container_id {, app_attempt_id {, application_id {, id: 7, cluster_timestamp: 1376201383303, }, attemptId: 1, }, id: 4, }, state: C_NEW, ] containerId=container_1376201383303_0007_01_000004 queue=default: capacity=1.0, absoluteCapacity=1.0, usedResources=<memory:48128, vCores:42>usedCapacity=0.9791667, absoluteUsedCapacity=0.9791667, numApps=5, numContainers=42 usedCapacity=0.9791667 absoluteUsedCapacity=0.9791667 used=<memory:48128, vCores:42> cluster=<memory:49152, vCores:96>
2013-08-11 06:27:03,358 INFO org.apache.hadoop.yarn.server.resourcemanager.scheduler.capacity.ParentQueue: Re-sorting queues since queue: root.default stats: default: capacity=1.0, absoluteCapacity=1.0, usedResources=<memory:49152, vCores:43>usedCapacity=1.0, absoluteUsedCapacity=1.0, numApps=5, numContainers=43
2013-08-11 06:27:03,359 INFO org.apache.hadoop.yarn.server.resourcemanager.scheduler.capacity.ParentQueue: assignedContainer queue=root usedCapacity=1.0 absoluteUsedCapacity=1.0 used=<memory:49152, vCores:43> cluster=<memory:49152, vCores:96>
2013-08-11 06:27:03,506 INFO org.apache.hadoop.yarn.server.resourcemanager.rmcontainer.RMContainerImpl: container_1376201383303_0007_01_000003 Container Transitioned from ALLOCATED to ACQUIRED
2013-08-11 06:27:03,507 INFO org.apache.hadoop.yarn.server.resourcemanager.rmcontainer.RMContainerImpl: container_1376201383303_0007_01_000004 Container Transitioned from ALLOCATED to ACQUIRED
2013-08-11 06:27:04,067 INFO org.apache.hadoop.yarn.server.resourcemanager.rmcontainer.RMContainerImpl: container_1376201383303_0006_01_000047 Container Transitioned from ACQUIRED to RELEASED
2013-08-11 06:27:04,068 INFO org.apache.hadoop.yarn.server.resourcemanager.scheduler.common.fica.FiCaSchedulerApp: Completed container: container_1376201383303_0006_01_000047 in state: RELEASED event:RELEASED
2013-08-11 06:27:04,069 INFO org.apache.hadoop.yarn.server.resourcemanager.RMAuditLogger: USER=ubuntu	IP=192.168.100.14	OPERATION=AM Released Container	TARGET=SchedulerApp	RESULT=SUCCESS	APPID=application_1376201383303_0006	CONTAINERID=container_1376201383303_0006_01_000047
2013-08-11 06:27:04,069 INFO org.apache.hadoop.yarn.server.resourcemanager.scheduler.common.fica.FiCaSchedulerNode: Released container container_1376201383303_0006_01_000047 of capacity <memory:1024, vCores:1> on host hadoop-320-5:32992, which currently has 6 containers, <memory:7168, vCores:6> used and <memory:1024, vCores:10> available, release resources=true
2013-08-11 06:27:04,070 INFO org.apache.hadoop.yarn.server.resourcemanager.scheduler.capacity.LeafQueue: default used=<memory:48128, vCores:42> numContainers=42 user=ubuntu user-resources=<memory:48128, vCores:42>
2013-08-11 06:27:04,072 INFO org.apache.hadoop.yarn.server.resourcemanager.scheduler.capacity.LeafQueue: completedContainer container=Container: [ContainerId: container_1376201383303_0006_01_000047, NodeId: hadoop-320-5:32992, NodeHttpAddress: hadoop-320-5:8042, Resource: <memory:1024, vCores:1>, Priority: 10, State: NEW, Token: null, Status: container_id {, app_attempt_id {, application_id {, id: 6, cluster_timestamp: 1376201383303, }, attemptId: 1, }, id: 47, }, state: C_COMPLETE, diagnostics: "Container released by application", exit_status: -100, ] resource=<memory:1024, vCores:1> queue=default: capacity=1.0, absoluteCapacity=1.0, usedResources=<memory:48128, vCores:42>usedCapacity=0.9791667, absoluteUsedCapacity=0.9791667, numApps=5, numContainers=42 usedCapacity=0.9791667 absoluteUsedCapacity=0.9791667 used=<memory:48128, vCores:42> cluster=<memory:49152, vCores:96>
2013-08-11 06:27:04,072 INFO org.apache.hadoop.yarn.server.resourcemanager.scheduler.capacity.ParentQueue: completedContainer queue=root usedCapacity=0.9791667 absoluteUsedCapacity=0.9791667 used=<memory:48128, vCores:42> cluster=<memory:49152, vCores:96>
2013-08-11 06:27:04,072 INFO org.apache.hadoop.yarn.server.resourcemanager.scheduler.capacity.CapacityScheduler: Application appattempt_1376201383303_0006_000001 released container container_1376201383303_0006_01_000047 on node: host: hadoop-320-5:32992 #containers=6 available=1024 used=7168 with event: RELEASED
2013-08-11 06:27:04,263 INFO org.apache.hadoop.yarn.server.resourcemanager.rmcontainer.RMContainerImpl: container_1376201383303_0007_01_000003 Container Transitioned from ACQUIRED to RUNNING
2013-08-11 06:27:04,683 INFO org.apache.hadoop.yarn.server.resourcemanager.rmcontainer.RMContainerImpl: container_1376201383303_0007_01_000004 Container Transitioned from ACQUIRED to RUNNING
2013-08-11 06:27:04,784 INFO org.apache.hadoop.yarn.server.resourcemanager.rmcontainer.RMContainerImpl: container_1376201383303_0006_01_000012 Container Transitioned from RUNNING to COMPLETED
2013-08-11 06:27:04,784 INFO org.apache.hadoop.yarn.server.resourcemanager.scheduler.common.fica.FiCaSchedulerApp: Completed container: container_1376201383303_0006_01_000012 in state: COMPLETED event:FINISHED
2013-08-11 06:27:04,784 INFO org.apache.hadoop.yarn.server.resourcemanager.RMAuditLogger: USER=ubuntu	OPERATION=AM Released Container	TARGET=SchedulerApp	RESULT=SUCCESS	APPID=application_1376201383303_0006	CONTAINERID=container_1376201383303_0006_01_000012
2013-08-11 06:27:04,785 INFO org.apache.hadoop.yarn.server.resourcemanager.scheduler.common.fica.FiCaSchedulerNode: Released container container_1376201383303_0006_01_000012 of capacity <memory:1024, vCores:1> on host hadoop-320-6:35360, which currently has 7 containers, <memory:7168, vCores:7> used and <memory:1024, vCores:9> available, release resources=true
2013-08-11 06:27:04,785 INFO org.apache.hadoop.yarn.server.resourcemanager.scheduler.capacity.LeafQueue: default used=<memory:47104, vCores:41> numContainers=41 user=ubuntu user-resources=<memory:47104, vCores:41>
2013-08-11 06:27:04,786 INFO org.apache.hadoop.yarn.server.resourcemanager.scheduler.capacity.LeafQueue: completedContainer container=Container: [ContainerId: container_1376201383303_0006_01_000012, NodeId: hadoop-320-6:35360, NodeHttpAddress: hadoop-320-6:8042, Resource: <memory:1024, vCores:1>, Priority: 20, State: NEW, Token: null, Status: container_id {, app_attempt_id {, application_id {, id: 6, cluster_timestamp: 1376201383303, }, attemptId: 1, }, id: 12, }, state: C_COMPLETE, diagnostics: "", exit_status: 0, ] resource=<memory:1024, vCores:1> queue=default: capacity=1.0, absoluteCapacity=1.0, usedResources=<memory:47104, vCores:41>usedCapacity=0.9583333, absoluteUsedCapacity=0.9583333, numApps=5, numContainers=41 usedCapacity=0.9583333 absoluteUsedCapacity=0.9583333 used=<memory:47104, vCores:41> cluster=<memory:49152, vCores:96>
2013-08-11 06:27:04,786 INFO org.apache.hadoop.yarn.server.resourcemanager.scheduler.capacity.ParentQueue: completedContainer queue=root usedCapacity=0.9583333 absoluteUsedCapacity=0.9583333 used=<memory:47104, vCores:41> cluster=<memory:49152, vCores:96>
2013-08-11 06:27:04,786 INFO org.apache.hadoop.yarn.server.resourcemanager.scheduler.capacity.CapacityScheduler: Application appattempt_1376201383303_0006_000001 released container container_1376201383303_0006_01_000012 on node: host: hadoop-320-6:35360 #containers=7 available=1024 used=7168 with event: FINISHED
2013-08-11 06:27:04,787 INFO org.apache.hadoop.yarn.server.resourcemanager.rmcontainer.RMContainerImpl: container_1376201383303_0006_01_000018 Container Transitioned from RUNNING to COMPLETED
2013-08-11 06:27:04,787 INFO org.apache.hadoop.yarn.server.resourcemanager.scheduler.common.fica.FiCaSchedulerApp: Completed container: container_1376201383303_0006_01_000018 in state: COMPLETED event:FINISHED
2013-08-11 06:27:04,787 INFO org.apache.hadoop.yarn.server.resourcemanager.RMAuditLogger: USER=ubuntu	OPERATION=AM Released Container	TARGET=SchedulerApp	RESULT=SUCCESS	APPID=application_1376201383303_0006	CONTAINERID=container_1376201383303_0006_01_000018
2013-08-11 06:27:04,787 INFO org.apache.hadoop.yarn.server.resourcemanager.scheduler.common.fica.FiCaSchedulerNode: Released container container_1376201383303_0006_01_000018 of capacity <memory:1024, vCores:1> on host hadoop-320-6:35360, which currently has 6 containers, <memory:6144, vCores:6> used and <memory:2048, vCores:10> available, release resources=true
2013-08-11 06:27:04,787 INFO org.apache.hadoop.yarn.server.resourcemanager.scheduler.capacity.LeafQueue: default used=<memory:46080, vCores:40> numContainers=40 user=ubuntu user-resources=<memory:46080, vCores:40>
2013-08-11 06:27:04,788 INFO org.apache.hadoop.yarn.server.resourcemanager.scheduler.capacity.LeafQueue: completedContainer container=Container: [ContainerId: container_1376201383303_0006_01_000018, NodeId: hadoop-320-6:35360, NodeHttpAddress: hadoop-320-6:8042, Resource: <memory:1024, vCores:1>, Priority: 20, State: NEW, Token: null, Status: container_id {, app_attempt_id {, application_id {, id: 6, cluster_timestamp: 1376201383303, }, attemptId: 1, }, id: 18, }, state: C_COMPLETE, diagnostics: "", exit_status: 0, ] resource=<memory:1024, vCores:1> queue=default: capacity=1.0, absoluteCapacity=1.0, usedResources=<memory:46080, vCores:40>usedCapacity=0.9375, absoluteUsedCapacity=0.9375, numApps=5, numContainers=40 usedCapacity=0.9375 absoluteUsedCapacity=0.9375 used=<memory:46080, vCores:40> cluster=<memory:49152, vCores:96>
2013-08-11 06:27:04,789 INFO org.apache.hadoop.yarn.server.resourcemanager.scheduler.capacity.ParentQueue: completedContainer queue=root usedCapacity=0.9375 absoluteUsedCapacity=0.9375 used=<memory:46080, vCores:40> cluster=<memory:49152, vCores:96>
2013-08-11 06:27:04,789 INFO org.apache.hadoop.yarn.server.resourcemanager.scheduler.capacity.CapacityScheduler: Application appattempt_1376201383303_0006_000001 released container container_1376201383303_0006_01_000018 on node: host: hadoop-320-6:35360 #containers=6 available=2048 used=6144 with event: FINISHED
2013-08-11 06:27:04,789 INFO org.apache.hadoop.yarn.server.resourcemanager.rmcontainer.RMContainerImpl: container_1376201383303_0007_01_000005 Container Transitioned from NEW to ALLOCATED
2013-08-11 06:27:04,789 INFO org.apache.hadoop.yarn.server.resourcemanager.RMAuditLogger: USER=ubuntu	OPERATION=AM Allocated Container	TARGET=SchedulerApp	RESULT=SUCCESS	APPID=application_1376201383303_0007	CONTAINERID=container_1376201383303_0007_01_000005
2013-08-11 06:27:04,790 INFO org.apache.hadoop.yarn.server.resourcemanager.scheduler.common.fica.FiCaSchedulerNode: Assigned container container_1376201383303_0007_01_000005 of capacity <memory:1024, vCores:1> on host hadoop-320-6:35360, which currently has 7 containers, <memory:7168, vCores:7> used and <memory:1024, vCores:9> available
2013-08-11 06:27:04,791 INFO org.apache.hadoop.yarn.server.resourcemanager.scheduler.capacity.LeafQueue: assignedContainer application=application_1376201383303_0007 container=Container: [ContainerId: container_1376201383303_0007_01_000005, NodeId: hadoop-320-6:35360, NodeHttpAddress: hadoop-320-6:8042, Resource: <memory:1024, vCores:1>, Priority: 20, State: NEW, Token: null, Status: container_id {, app_attempt_id {, application_id {, id: 7, cluster_timestamp: 1376201383303, }, attemptId: 1, }, id: 5, }, state: C_NEW, ] containerId=container_1376201383303_0007_01_000005 queue=default: capacity=1.0, absoluteCapacity=1.0, usedResources=<memory:46080, vCores:40>usedCapacity=0.9375, absoluteUsedCapacity=0.9375, numApps=5, numContainers=40 usedCapacity=0.9375 absoluteUsedCapacity=0.9375 used=<memory:46080, vCores:40> cluster=<memory:49152, vCores:96>
2013-08-11 06:27:04,791 INFO org.apache.hadoop.yarn.server.resourcemanager.scheduler.capacity.ParentQueue: Re-sorting queues since queue: root.default stats: default: capacity=1.0, absoluteCapacity=1.0, usedResources=<memory:47104, vCores:41>usedCapacity=0.9583333, absoluteUsedCapacity=0.9583333, numApps=5, numContainers=41
2013-08-11 06:27:04,791 INFO org.apache.hadoop.yarn.server.resourcemanager.scheduler.capacity.ParentQueue: assignedContainer queue=root usedCapacity=0.9583333 absoluteUsedCapacity=0.9583333 used=<memory:47104, vCores:41> cluster=<memory:49152, vCores:96>
2013-08-11 06:27:04,792 INFO org.apache.hadoop.yarn.server.resourcemanager.rmcontainer.RMContainerImpl: container_1376201383303_0007_01_000006 Container Transitioned from NEW to ALLOCATED
2013-08-11 06:27:04,792 INFO org.apache.hadoop.yarn.server.resourcemanager.RMAuditLogger: USER=ubuntu	OPERATION=AM Allocated Container	TARGET=SchedulerApp	RESULT=SUCCESS	APPID=application_1376201383303_0007	CONTAINERID=container_1376201383303_0007_01_000006
2013-08-11 06:27:04,792 INFO org.apache.hadoop.yarn.server.resourcemanager.scheduler.common.fica.FiCaSchedulerNode: Assigned container container_1376201383303_0007_01_000006 of capacity <memory:1024, vCores:1> on host hadoop-320-6:35360, which currently has 8 containers, <memory:8192, vCores:8> used and <memory:0, vCores:8> available
2013-08-11 06:27:04,793 INFO org.apache.hadoop.yarn.server.resourcemanager.scheduler.capacity.LeafQueue: assignedContainer application=application_1376201383303_0007 container=Container: [ContainerId: container_1376201383303_0007_01_000006, NodeId: hadoop-320-6:35360, NodeHttpAddress: hadoop-320-6:8042, Resource: <memory:1024, vCores:1>, Priority: 20, State: NEW, Token: null, Status: container_id {, app_attempt_id {, application_id {, id: 7, cluster_timestamp: 1376201383303, }, attemptId: 1, }, id: 6, }, state: C_NEW, ] containerId=container_1376201383303_0007_01_000006 queue=default: capacity=1.0, absoluteCapacity=1.0, usedResources=<memory:47104, vCores:41>usedCapacity=0.9583333, absoluteUsedCapacity=0.9583333, numApps=5, numContainers=41 usedCapacity=0.9583333 absoluteUsedCapacity=0.9583333 used=<memory:47104, vCores:41> cluster=<memory:49152, vCores:96>
2013-08-11 06:27:04,793 INFO org.apache.hadoop.yarn.server.resourcemanager.scheduler.capacity.ParentQueue: Re-sorting queues since queue: root.default stats: default: capacity=1.0, absoluteCapacity=1.0, usedResources=<memory:48128, vCores:42>usedCapacity=0.9791667, absoluteUsedCapacity=0.9791667, numApps=5, numContainers=42
2013-08-11 06:27:04,793 INFO org.apache.hadoop.yarn.server.resourcemanager.scheduler.capacity.ParentQueue: assignedContainer queue=root usedCapacity=0.9791667 absoluteUsedCapacity=0.9791667 used=<memory:48128, vCores:42> cluster=<memory:49152, vCores:96>
2013-08-11 06:27:04,845 INFO org.apache.hadoop.yarn.server.resourcemanager.rmcontainer.RMContainerImpl: container_1376201383303_0007_01_000007 Container Transitioned from NEW to ALLOCATED
2013-08-11 06:27:04,845 INFO org.apache.hadoop.yarn.server.resourcemanager.RMAuditLogger: USER=ubuntu	OPERATION=AM Allocated Container	TARGET=SchedulerApp	RESULT=SUCCESS	APPID=application_1376201383303_0007	CONTAINERID=container_1376201383303_0007_01_000007
2013-08-11 06:27:04,845 INFO org.apache.hadoop.yarn.server.resourcemanager.scheduler.common.fica.FiCaSchedulerNode: Assigned container container_1376201383303_0007_01_000007 of capacity <memory:1024, vCores:1> on host hadoop-320-5:32992, which currently has 7 containers, <memory:8192, vCores:7> used and <memory:0, vCores:9> available
2013-08-11 06:27:04,847 INFO org.apache.hadoop.yarn.server.resourcemanager.scheduler.capacity.LeafQueue: assignedContainer application=application_1376201383303_0007 container=Container: [ContainerId: container_1376201383303_0007_01_000007, NodeId: hadoop-320-5:32992, NodeHttpAddress: hadoop-320-5:8042, Resource: <memory:1024, vCores:1>, Priority: 20, State: NEW, Token: null, Status: container_id {, app_attempt_id {, application_id {, id: 7, cluster_timestamp: 1376201383303, }, attemptId: 1, }, id: 7, }, state: C_NEW, ] containerId=container_1376201383303_0007_01_000007 queue=default: capacity=1.0, absoluteCapacity=1.0, usedResources=<memory:48128, vCores:42>usedCapacity=0.9791667, absoluteUsedCapacity=0.9791667, numApps=5, numContainers=42 usedCapacity=0.9791667 absoluteUsedCapacity=0.9791667 used=<memory:48128, vCores:42> cluster=<memory:49152, vCores:96>
2013-08-11 06:27:04,847 INFO org.apache.hadoop.yarn.server.resourcemanager.scheduler.capacity.ParentQueue: Re-sorting queues since queue: root.default stats: default: capacity=1.0, absoluteCapacity=1.0, usedResources=<memory:49152, vCores:43>usedCapacity=1.0, absoluteUsedCapacity=1.0, numApps=5, numContainers=43
2013-08-11 06:27:04,847 INFO org.apache.hadoop.yarn.server.resourcemanager.scheduler.capacity.ParentQueue: assignedContainer queue=root usedCapacity=1.0 absoluteUsedCapacity=1.0 used=<memory:49152, vCores:43> cluster=<memory:49152, vCores:96>
2013-08-11 06:27:05,125 INFO org.apache.hadoop.yarn.server.resourcemanager.rmcontainer.RMContainerImpl: container_1376201383303_0007_01_000005 Container Transitioned from ALLOCATED to ACQUIRED
2013-08-11 06:27:05,126 INFO org.apache.hadoop.yarn.server.resourcemanager.rmcontainer.RMContainerImpl: container_1376201383303_0007_01_000006 Container Transitioned from ALLOCATED to ACQUIRED
2013-08-11 06:27:05,126 INFO org.apache.hadoop.yarn.server.resourcemanager.rmcontainer.RMContainerImpl: container_1376201383303_0007_01_000007 Container Transitioned from ALLOCATED to ACQUIRED
2013-08-11 06:27:05,877 INFO org.apache.hadoop.yarn.server.resourcemanager.rmcontainer.RMContainerImpl: container_1376201383303_0006_01_000017 Container Transitioned from RUNNING to COMPLETED
2013-08-11 06:27:05,877 INFO org.apache.hadoop.yarn.server.resourcemanager.scheduler.common.fica.FiCaSchedulerApp: Completed container: container_1376201383303_0006_01_000017 in state: COMPLETED event:FINISHED
2013-08-11 06:27:05,877 INFO org.apache.hadoop.yarn.server.resourcemanager.RMAuditLogger: USER=ubuntu	OPERATION=AM Released Container	TARGET=SchedulerApp	RESULT=SUCCESS	APPID=application_1376201383303_0006	CONTAINERID=container_1376201383303_0006_01_000017
2013-08-11 06:27:05,877 INFO org.apache.hadoop.yarn.server.resourcemanager.scheduler.common.fica.FiCaSchedulerNode: Released container container_1376201383303_0006_01_000017 of capacity <memory:1024, vCores:1> on host hadoop-320-6:35360, which currently has 7 containers, <memory:7168, vCores:7> used and <memory:1024, vCores:9> available, release resources=true
2013-08-11 06:27:05,878 INFO org.apache.hadoop.yarn.server.resourcemanager.scheduler.capacity.LeafQueue: default used=<memory:48128, vCores:42> numContainers=42 user=ubuntu user-resources=<memory:48128, vCores:42>
2013-08-11 06:27:05,879 INFO org.apache.hadoop.yarn.server.resourcemanager.scheduler.capacity.LeafQueue: completedContainer container=Container: [ContainerId: container_1376201383303_0006_01_000017, NodeId: hadoop-320-6:35360, NodeHttpAddress: hadoop-320-6:8042, Resource: <memory:1024, vCores:1>, Priority: 20, State: NEW, Token: null, Status: container_id {, app_attempt_id {, application_id {, id: 6, cluster_timestamp: 1376201383303, }, attemptId: 1, }, id: 17, }, state: C_COMPLETE, diagnostics: "Container killed by the ApplicationMaster.\n\n", exit_status: 143, ] resource=<memory:1024, vCores:1> queue=default: capacity=1.0, absoluteCapacity=1.0, usedResources=<memory:48128, vCores:42>usedCapacity=0.9791667, absoluteUsedCapacity=0.9791667, numApps=5, numContainers=42 usedCapacity=0.9791667 absoluteUsedCapacity=0.9791667 used=<memory:48128, vCores:42> cluster=<memory:49152, vCores:96>
2013-08-11 06:27:05,879 INFO org.apache.hadoop.yarn.server.resourcemanager.scheduler.capacity.ParentQueue: completedContainer queue=root usedCapacity=0.9791667 absoluteUsedCapacity=0.9791667 used=<memory:48128, vCores:42> cluster=<memory:49152, vCores:96>
2013-08-11 06:27:05,879 INFO org.apache.hadoop.yarn.server.resourcemanager.scheduler.capacity.CapacityScheduler: Application appattempt_1376201383303_0006_000001 released container container_1376201383303_0006_01_000017 on node: host: hadoop-320-6:35360 #containers=7 available=1024 used=7168 with event: FINISHED
2013-08-11 06:27:05,880 INFO org.apache.hadoop.yarn.server.resourcemanager.rmcontainer.RMContainerImpl: container_1376201383303_0007_01_000008 Container Transitioned from NEW to ALLOCATED
2013-08-11 06:27:05,880 INFO org.apache.hadoop.yarn.server.resourcemanager.RMAuditLogger: USER=ubuntu	OPERATION=AM Allocated Container	TARGET=SchedulerApp	RESULT=SUCCESS	APPID=application_1376201383303_0007	CONTAINERID=container_1376201383303_0007_01_000008
2013-08-11 06:27:05,880 INFO org.apache.hadoop.yarn.server.resourcemanager.scheduler.common.fica.FiCaSchedulerNode: Assigned container container_1376201383303_0007_01_000008 of capacity <memory:1024, vCores:1> on host hadoop-320-6:35360, which currently has 8 containers, <memory:8192, vCores:8> used and <memory:0, vCores:8> available
2013-08-11 06:27:05,881 INFO org.apache.hadoop.yarn.server.resourcemanager.scheduler.capacity.LeafQueue: assignedContainer application=application_1376201383303_0007 container=Container: [ContainerId: container_1376201383303_0007_01_000008, NodeId: hadoop-320-6:35360, NodeHttpAddress: hadoop-320-6:8042, Resource: <memory:1024, vCores:1>, Priority: 20, State: NEW, Token: null, Status: container_id {, app_attempt_id {, application_id {, id: 7, cluster_timestamp: 1376201383303, }, attemptId: 1, }, id: 8, }, state: C_NEW, ] containerId=container_1376201383303_0007_01_000008 queue=default: capacity=1.0, absoluteCapacity=1.0, usedResources=<memory:48128, vCores:42>usedCapacity=0.9791667, absoluteUsedCapacity=0.9791667, numApps=5, numContainers=42 usedCapacity=0.9791667 absoluteUsedCapacity=0.9791667 used=<memory:48128, vCores:42> cluster=<memory:49152, vCores:96>
2013-08-11 06:27:05,881 INFO org.apache.hadoop.yarn.server.resourcemanager.scheduler.capacity.ParentQueue: Re-sorting queues since queue: root.default stats: default: capacity=1.0, absoluteCapacity=1.0, usedResources=<memory:49152, vCores:43>usedCapacity=1.0, absoluteUsedCapacity=1.0, numApps=5, numContainers=43
2013-08-11 06:27:05,882 INFO org.apache.hadoop.yarn.server.resourcemanager.scheduler.capacity.ParentQueue: assignedContainer queue=root usedCapacity=1.0 absoluteUsedCapacity=1.0 used=<memory:49152, vCores:43> cluster=<memory:49152, vCores:96>
2013-08-11 06:27:06,893 INFO org.apache.hadoop.yarn.server.resourcemanager.rmcontainer.RMContainerImpl: container_1376201383303_0007_01_000005 Container Transitioned from ACQUIRED to RUNNING
2013-08-11 06:27:06,893 INFO org.apache.hadoop.yarn.server.resourcemanager.rmcontainer.RMContainerImpl: container_1376201383303_0007_01_000006 Container Transitioned from ACQUIRED to RUNNING
2013-08-11 06:27:06,977 INFO org.apache.hadoop.yarn.server.resourcemanager.rmcontainer.RMContainerImpl: container_1376201383303_0006_01_000022 Container Transitioned from RUNNING to COMPLETED
2013-08-11 06:27:06,977 INFO org.apache.hadoop.yarn.server.resourcemanager.scheduler.common.fica.FiCaSchedulerApp: Completed container: container_1376201383303_0006_01_000022 in state: COMPLETED event:FINISHED
2013-08-11 06:27:06,977 INFO org.apache.hadoop.yarn.server.resourcemanager.RMAuditLogger: USER=ubuntu	OPERATION=AM Released Container	TARGET=SchedulerApp	RESULT=SUCCESS	APPID=application_1376201383303_0006	CONTAINERID=container_1376201383303_0006_01_000022
2013-08-11 06:27:06,978 INFO org.apache.hadoop.yarn.server.resourcemanager.scheduler.common.fica.FiCaSchedulerNode: Released container container_1376201383303_0006_01_000022 of capacity <memory:1024, vCores:1> on host hadoop-320-2:40354, which currently has 7 containers, <memory:7168, vCores:7> used and <memory:1024, vCores:9> available, release resources=true
2013-08-11 06:27:06,978 INFO org.apache.hadoop.yarn.server.resourcemanager.scheduler.capacity.LeafQueue: default used=<memory:48128, vCores:42> numContainers=42 user=ubuntu user-resources=<memory:48128, vCores:42>
2013-08-11 06:27:06,979 INFO org.apache.hadoop.yarn.server.resourcemanager.scheduler.capacity.LeafQueue: completedContainer container=Container: [ContainerId: container_1376201383303_0006_01_000022, NodeId: hadoop-320-2:40354, NodeHttpAddress: hadoop-320-2:8042, Resource: <memory:1024, vCores:1>, Priority: 20, State: NEW, Token: null, Status: container_id {, app_attempt_id {, application_id {, id: 6, cluster_timestamp: 1376201383303, }, attemptId: 1, }, id: 22, }, state: C_COMPLETE, diagnostics: "Container killed by the ApplicationMaster.\n", exit_status: 0, ] resource=<memory:1024, vCores:1> queue=default: capacity=1.0, absoluteCapacity=1.0, usedResources=<memory:48128, vCores:42>usedCapacity=0.9791667, absoluteUsedCapacity=0.9791667, numApps=5, numContainers=42 usedCapacity=0.9791667 absoluteUsedCapacity=0.9791667 used=<memory:48128, vCores:42> cluster=<memory:49152, vCores:96>
2013-08-11 06:27:06,979 INFO org.apache.hadoop.yarn.server.resourcemanager.scheduler.capacity.ParentQueue: completedContainer queue=root usedCapacity=0.9791667 absoluteUsedCapacity=0.9791667 used=<memory:48128, vCores:42> cluster=<memory:49152, vCores:96>
2013-08-11 06:27:06,980 INFO org.apache.hadoop.yarn.server.resourcemanager.scheduler.capacity.CapacityScheduler: Application appattempt_1376201383303_0006_000001 released container container_1376201383303_0006_01_000022 on node: host: hadoop-320-2:40354 #containers=7 available=1024 used=7168 with event: FINISHED
2013-08-11 06:27:06,980 INFO org.apache.hadoop.yarn.server.resourcemanager.rmcontainer.RMContainerImpl: container_1376201383303_0006_01_000024 Container Transitioned from RUNNING to COMPLETED
2013-08-11 06:27:06,980 INFO org.apache.hadoop.yarn.server.resourcemanager.scheduler.common.fica.FiCaSchedulerApp: Completed container: container_1376201383303_0006_01_000024 in state: COMPLETED event:FINISHED
2013-08-11 06:27:06,980 INFO org.apache.hadoop.yarn.server.resourcemanager.RMAuditLogger: USER=ubuntu	OPERATION=AM Released Container	TARGET=SchedulerApp	RESULT=SUCCESS	APPID=application_1376201383303_0006	CONTAINERID=container_1376201383303_0006_01_000024
2013-08-11 06:27:06,980 INFO org.apache.hadoop.yarn.server.resourcemanager.scheduler.common.fica.FiCaSchedulerNode: Released container container_1376201383303_0006_01_000024 of capacity <memory:1024, vCores:1> on host hadoop-320-2:40354, which currently has 6 containers, <memory:6144, vCores:6> used and <memory:2048, vCores:10> available, release resources=true
2013-08-11 06:27:06,980 INFO org.apache.hadoop.yarn.server.resourcemanager.scheduler.capacity.LeafQueue: default used=<memory:47104, vCores:41> numContainers=41 user=ubuntu user-resources=<memory:47104, vCores:41>
2013-08-11 06:27:06,981 INFO org.apache.hadoop.yarn.server.resourcemanager.scheduler.capacity.LeafQueue: completedContainer container=Container: [ContainerId: container_1376201383303_0006_01_000024, NodeId: hadoop-320-2:40354, NodeHttpAddress: hadoop-320-2:8042, Resource: <memory:1024, vCores:1>, Priority: 20, State: NEW, Token: null, Status: container_id {, app_attempt_id {, application_id {, id: 6, cluster_timestamp: 1376201383303, }, attemptId: 1, }, id: 24, }, state: C_COMPLETE, diagnostics: "", exit_status: 0, ] resource=<memory:1024, vCores:1> queue=default: capacity=1.0, absoluteCapacity=1.0, usedResources=<memory:47104, vCores:41>usedCapacity=0.9583333, absoluteUsedCapacity=0.9583333, numApps=5, numContainers=41 usedCapacity=0.9583333 absoluteUsedCapacity=0.9583333 used=<memory:47104, vCores:41> cluster=<memory:49152, vCores:96>
2013-08-11 06:27:06,982 INFO org.apache.hadoop.yarn.server.resourcemanager.scheduler.capacity.ParentQueue: completedContainer queue=root usedCapacity=0.9583333 absoluteUsedCapacity=0.9583333 used=<memory:47104, vCores:41> cluster=<memory:49152, vCores:96>
2013-08-11 06:27:06,982 INFO org.apache.hadoop.yarn.server.resourcemanager.scheduler.capacity.CapacityScheduler: Application appattempt_1376201383303_0006_000001 released container container_1376201383303_0006_01_000024 on node: host: hadoop-320-2:40354 #containers=6 available=2048 used=6144 with event: FINISHED
2013-08-11 06:27:06,982 INFO org.apache.hadoop.yarn.server.resourcemanager.rmcontainer.RMContainerImpl: container_1376201383303_0007_01_000009 Container Transitioned from NEW to ALLOCATED
2013-08-11 06:27:06,983 INFO org.apache.hadoop.yarn.server.resourcemanager.RMAuditLogger: USER=ubuntu	OPERATION=AM Allocated Container	TARGET=SchedulerApp	RESULT=SUCCESS	APPID=application_1376201383303_0007	CONTAINERID=container_1376201383303_0007_01_000009
2013-08-11 06:27:06,983 INFO org.apache.hadoop.yarn.server.resourcemanager.scheduler.common.fica.FiCaSchedulerNode: Assigned container container_1376201383303_0007_01_000009 of capacity <memory:1024, vCores:1> on host hadoop-320-2:40354, which currently has 7 containers, <memory:7168, vCores:7> used and <memory:1024, vCores:9> available
2013-08-11 06:27:06,984 INFO org.apache.hadoop.yarn.server.resourcemanager.scheduler.capacity.LeafQueue: assignedContainer application=application_1376201383303_0007 container=Container: [ContainerId: container_1376201383303_0007_01_000009, NodeId: hadoop-320-2:40354, NodeHttpAddress: hadoop-320-2:8042, Resource: <memory:1024, vCores:1>, Priority: 20, State: NEW, Token: null, Status: container_id {, app_attempt_id {, application_id {, id: 7, cluster_timestamp: 1376201383303, }, attemptId: 1, }, id: 9, }, state: C_NEW, ] containerId=container_1376201383303_0007_01_000009 queue=default: capacity=1.0, absoluteCapacity=1.0, usedResources=<memory:47104, vCores:41>usedCapacity=0.9583333, absoluteUsedCapacity=0.9583333, numApps=5, numContainers=41 usedCapacity=0.9583333 absoluteUsedCapacity=0.9583333 used=<memory:47104, vCores:41> cluster=<memory:49152, vCores:96>
2013-08-11 06:27:06,984 INFO org.apache.hadoop.yarn.server.resourcemanager.scheduler.capacity.ParentQueue: Re-sorting queues since queue: root.default stats: default: capacity=1.0, absoluteCapacity=1.0, usedResources=<memory:48128, vCores:42>usedCapacity=0.9791667, absoluteUsedCapacity=0.9791667, numApps=5, numContainers=42
2013-08-11 06:27:06,984 INFO org.apache.hadoop.yarn.server.resourcemanager.scheduler.capacity.ParentQueue: assignedContainer queue=root usedCapacity=0.9791667 absoluteUsedCapacity=0.9791667 used=<memory:48128, vCores:42> cluster=<memory:49152, vCores:96>
2013-08-11 06:27:06,985 INFO org.apache.hadoop.yarn.server.resourcemanager.rmcontainer.RMContainerImpl: container_1376201383303_0007_01_000010 Container Transitioned from NEW to ALLOCATED
2013-08-11 06:27:06,985 INFO org.apache.hadoop.yarn.server.resourcemanager.RMAuditLogger: USER=ubuntu	OPERATION=AM Allocated Container	TARGET=SchedulerApp	RESULT=SUCCESS	APPID=application_1376201383303_0007	CONTAINERID=container_1376201383303_0007_01_000010
2013-08-11 06:27:06,985 INFO org.apache.hadoop.yarn.server.resourcemanager.scheduler.common.fica.FiCaSchedulerNode: Assigned container container_1376201383303_0007_01_000010 of capacity <memory:1024, vCores:1> on host hadoop-320-2:40354, which currently has 8 containers, <memory:8192, vCores:8> used and <memory:0, vCores:8> available
2013-08-11 06:27:06,986 INFO org.apache.hadoop.yarn.server.resourcemanager.scheduler.capacity.LeafQueue: assignedContainer application=application_1376201383303_0007 container=Container: [ContainerId: container_1376201383303_0007_01_000010, NodeId: hadoop-320-2:40354, NodeHttpAddress: hadoop-320-2:8042, Resource: <memory:1024, vCores:1>, Priority: 20, State: NEW, Token: null, Status: container_id {, app_attempt_id {, application_id {, id: 7, cluster_timestamp: 1376201383303, }, attemptId: 1, }, id: 10, }, state: C_NEW, ] containerId=container_1376201383303_0007_01_000010 queue=default: capacity=1.0, absoluteCapacity=1.0, usedResources=<memory:48128, vCores:42>usedCapacity=0.9791667, absoluteUsedCapacity=0.9791667, numApps=5, numContainers=42 usedCapacity=0.9791667 absoluteUsedCapacity=0.9791667 used=<memory:48128, vCores:42> cluster=<memory:49152, vCores:96>
2013-08-11 06:27:06,986 INFO org.apache.hadoop.yarn.server.resourcemanager.scheduler.capacity.ParentQueue: Re-sorting queues since queue: root.default stats: default: capacity=1.0, absoluteCapacity=1.0, usedResources=<memory:49152, vCores:43>usedCapacity=1.0, absoluteUsedCapacity=1.0, numApps=5, numContainers=43
2013-08-11 06:27:06,986 INFO org.apache.hadoop.yarn.server.resourcemanager.scheduler.capacity.ParentQueue: assignedContainer queue=root usedCapacity=1.0 absoluteUsedCapacity=1.0 used=<memory:49152, vCores:43> cluster=<memory:49152, vCores:96>
2013-08-11 06:27:07,370 INFO org.apache.hadoop.yarn.server.resourcemanager.rmcontainer.RMContainerImpl: container_1376201383303_0007_01_000008 Container Transitioned from ALLOCATED to ACQUIRED
2013-08-11 06:27:07,371 INFO org.apache.hadoop.yarn.server.resourcemanager.rmcontainer.RMContainerImpl: container_1376201383303_0007_01_000009 Container Transitioned from ALLOCATED to ACQUIRED
2013-08-11 06:27:07,371 INFO org.apache.hadoop.yarn.server.resourcemanager.rmcontainer.RMContainerImpl: container_1376201383303_0007_01_000010 Container Transitioned from ALLOCATED to ACQUIRED
2013-08-11 06:27:07,456 INFO org.apache.hadoop.yarn.server.resourcemanager.rmcontainer.RMContainerImpl: container_1376201383303_0007_01_000007 Container Transitioned from ACQUIRED to RUNNING
2013-08-11 06:27:07,991 INFO org.apache.hadoop.yarn.server.resourcemanager.rmcontainer.RMContainerImpl: container_1376201383303_0007_01_000010 Container Transitioned from ACQUIRED to RUNNING
2013-08-11 06:27:09,004 INFO org.apache.hadoop.yarn.server.resourcemanager.rmcontainer.RMContainerImpl: container_1376201383303_0007_01_000009 Container Transitioned from ACQUIRED to RUNNING
2013-08-11 06:27:09,079 INFO org.apache.hadoop.yarn.server.resourcemanager.rmcontainer.RMContainerImpl: container_1376201383303_0007_01_000008 Container Transitioned from ACQUIRED to RUNNING
2013-08-11 06:27:09,080 INFO org.apache.hadoop.yarn.server.resourcemanager.rmcontainer.RMContainerImpl: container_1376201383303_0006_01_000014 Container Transitioned from RUNNING to COMPLETED
2013-08-11 06:27:09,080 INFO org.apache.hadoop.yarn.server.resourcemanager.scheduler.common.fica.FiCaSchedulerApp: Completed container: container_1376201383303_0006_01_000014 in state: COMPLETED event:FINISHED
2013-08-11 06:27:09,080 INFO org.apache.hadoop.yarn.server.resourcemanager.RMAuditLogger: USER=ubuntu	OPERATION=AM Released Container	TARGET=SchedulerApp	RESULT=SUCCESS	APPID=application_1376201383303_0006	CONTAINERID=container_1376201383303_0006_01_000014
2013-08-11 06:27:09,080 INFO org.apache.hadoop.yarn.server.resourcemanager.scheduler.common.fica.FiCaSchedulerNode: Released container container_1376201383303_0006_01_000014 of capacity <memory:1024, vCores:1> on host hadoop-320-6:35360, which currently has 7 containers, <memory:7168, vCores:7> used and <memory:1024, vCores:9> available, release resources=true
2013-08-11 06:27:09,080 INFO org.apache.hadoop.yarn.server.resourcemanager.scheduler.capacity.LeafQueue: default used=<memory:48128, vCores:42> numContainers=42 user=ubuntu user-resources=<memory:48128, vCores:42>
2013-08-11 06:27:09,082 INFO org.apache.hadoop.yarn.server.resourcemanager.scheduler.capacity.LeafQueue: completedContainer container=Container: [ContainerId: container_1376201383303_0006_01_000014, NodeId: hadoop-320-6:35360, NodeHttpAddress: hadoop-320-6:8042, Resource: <memory:1024, vCores:1>, Priority: 20, State: NEW, Token: null, Status: container_id {, app_attempt_id {, application_id {, id: 6, cluster_timestamp: 1376201383303, }, attemptId: 1, }, id: 14, }, state: C_COMPLETE, diagnostics: "Container killed by the ApplicationMaster.\n\n", exit_status: 143, ] resource=<memory:1024, vCores:1> queue=default: capacity=1.0, absoluteCapacity=1.0, usedResources=<memory:48128, vCores:42>usedCapacity=0.9791667, absoluteUsedCapacity=0.9791667, numApps=5, numContainers=42 usedCapacity=0.9791667 absoluteUsedCapacity=0.9791667 used=<memory:48128, vCores:42> cluster=<memory:49152, vCores:96>
2013-08-11 06:27:09,082 INFO org.apache.hadoop.yarn.server.resourcemanager.scheduler.capacity.ParentQueue: completedContainer queue=root usedCapacity=0.9791667 absoluteUsedCapacity=0.9791667 used=<memory:48128, vCores:42> cluster=<memory:49152, vCores:96>
2013-08-11 06:27:09,082 INFO org.apache.hadoop.yarn.server.resourcemanager.scheduler.capacity.CapacityScheduler: Application appattempt_1376201383303_0006_000001 released container container_1376201383303_0006_01_000014 on node: host: hadoop-320-6:35360 #containers=7 available=1024 used=7168 with event: FINISHED
2013-08-11 06:27:09,083 INFO org.apache.hadoop.yarn.server.resourcemanager.rmcontainer.RMContainerImpl: container_1376201383303_0007_01_000011 Container Transitioned from NEW to ALLOCATED
2013-08-11 06:27:09,083 INFO org.apache.hadoop.yarn.server.resourcemanager.RMAuditLogger: USER=ubuntu	OPERATION=AM Allocated Container	TARGET=SchedulerApp	RESULT=SUCCESS	APPID=application_1376201383303_0007	CONTAINERID=container_1376201383303_0007_01_000011
2013-08-11 06:27:09,083 INFO org.apache.hadoop.yarn.server.resourcemanager.scheduler.common.fica.FiCaSchedulerNode: Assigned container container_1376201383303_0007_01_000011 of capacity <memory:1024, vCores:1> on host hadoop-320-6:35360, which currently has 8 containers, <memory:8192, vCores:8> used and <memory:0, vCores:8> available
2013-08-11 06:27:09,084 INFO org.apache.hadoop.yarn.server.resourcemanager.scheduler.capacity.LeafQueue: assignedContainer application=application_1376201383303_0007 container=Container: [ContainerId: container_1376201383303_0007_01_000011, NodeId: hadoop-320-6:35360, NodeHttpAddress: hadoop-320-6:8042, Resource: <memory:1024, vCores:1>, Priority: 20, State: NEW, Token: null, Status: container_id {, app_attempt_id {, application_id {, id: 7, cluster_timestamp: 1376201383303, }, attemptId: 1, }, id: 11, }, state: C_NEW, ] containerId=container_1376201383303_0007_01_000011 queue=default: capacity=1.0, absoluteCapacity=1.0, usedResources=<memory:48128, vCores:42>usedCapacity=0.9791667, absoluteUsedCapacity=0.9791667, numApps=5, numContainers=42 usedCapacity=0.9791667 absoluteUsedCapacity=0.9791667 used=<memory:48128, vCores:42> cluster=<memory:49152, vCores:96>
2013-08-11 06:27:09,084 INFO org.apache.hadoop.yarn.server.resourcemanager.scheduler.capacity.ParentQueue: Re-sorting queues since queue: root.default stats: default: capacity=1.0, absoluteCapacity=1.0, usedResources=<memory:49152, vCores:43>usedCapacity=1.0, absoluteUsedCapacity=1.0, numApps=5, numContainers=43
2013-08-11 06:27:09,085 INFO org.apache.hadoop.yarn.server.resourcemanager.scheduler.capacity.ParentQueue: assignedContainer queue=root usedCapacity=1.0 absoluteUsedCapacity=1.0 used=<memory:49152, vCores:43> cluster=<memory:49152, vCores:96>
2013-08-11 06:27:09,814 INFO org.apache.hadoop.yarn.server.resourcemanager.rmcontainer.RMContainerImpl: container_1376201383303_0007_01_000011 Container Transitioned from ALLOCATED to ACQUIRED
2013-08-11 06:27:11,139 INFO org.apache.hadoop.yarn.server.resourcemanager.rmcontainer.RMContainerImpl: container_1376201383303_0007_01_000011 Container Transitioned from ACQUIRED to RUNNING
2013-08-11 06:27:13,311 INFO org.apache.hadoop.yarn.server.resourcemanager.rmcontainer.RMContainerImpl: container_1376201383303_0006_01_000034 Container Transitioned from RUNNING to COMPLETED
2013-08-11 06:27:13,311 INFO org.apache.hadoop.yarn.server.resourcemanager.scheduler.common.fica.FiCaSchedulerApp: Completed container: container_1376201383303_0006_01_000034 in state: COMPLETED event:FINISHED
2013-08-11 06:27:13,311 INFO org.apache.hadoop.yarn.server.resourcemanager.RMAuditLogger: USER=ubuntu	OPERATION=AM Released Container	TARGET=SchedulerApp	RESULT=SUCCESS	APPID=application_1376201383303_0006	CONTAINERID=container_1376201383303_0006_01_000034
2013-08-11 06:27:13,312 INFO org.apache.hadoop.yarn.server.resourcemanager.scheduler.common.fica.FiCaSchedulerNode: Released container container_1376201383303_0006_01_000034 of capacity <memory:1024, vCores:1> on host hadoop-320-5:32992, which currently has 6 containers, <memory:7168, vCores:6> used and <memory:1024, vCores:10> available, release resources=true
2013-08-11 06:27:13,312 INFO org.apache.hadoop.yarn.server.resourcemanager.scheduler.capacity.LeafQueue: default used=<memory:48128, vCores:42> numContainers=42 user=ubuntu user-resources=<memory:48128, vCores:42>
2013-08-11 06:27:13,313 INFO org.apache.hadoop.yarn.server.resourcemanager.scheduler.capacity.LeafQueue: completedContainer container=Container: [ContainerId: container_1376201383303_0006_01_000034, NodeId: hadoop-320-5:32992, NodeHttpAddress: hadoop-320-5:8042, Resource: <memory:1024, vCores:1>, Priority: 20, State: NEW, Token: null, Status: container_id {, app_attempt_id {, application_id {, id: 6, cluster_timestamp: 1376201383303, }, attemptId: 1, }, id: 34, }, state: C_COMPLETE, diagnostics: "Container killed by the ApplicationMaster.\n\n", exit_status: 143, ] resource=<memory:1024, vCores:1> queue=default: capacity=1.0, absoluteCapacity=1.0, usedResources=<memory:48128, vCores:42>usedCapacity=0.9791667, absoluteUsedCapacity=0.9791667, numApps=5, numContainers=42 usedCapacity=0.9791667 absoluteUsedCapacity=0.9791667 used=<memory:48128, vCores:42> cluster=<memory:49152, vCores:96>
2013-08-11 06:27:13,313 INFO org.apache.hadoop.yarn.server.resourcemanager.scheduler.capacity.ParentQueue: completedContainer queue=root usedCapacity=0.9791667 absoluteUsedCapacity=0.9791667 used=<memory:48128, vCores:42> cluster=<memory:49152, vCores:96>
2013-08-11 06:27:13,313 INFO org.apache.hadoop.yarn.server.resourcemanager.scheduler.capacity.CapacityScheduler: Application appattempt_1376201383303_0006_000001 released container container_1376201383303_0006_01_000034 on node: host: hadoop-320-5:32992 #containers=6 available=1024 used=7168 with event: FINISHED
2013-08-11 06:27:13,314 INFO org.apache.hadoop.yarn.server.resourcemanager.rmcontainer.RMContainerImpl: container_1376201383303_0006_01_000038 Container Transitioned from RUNNING to COMPLETED
2013-08-11 06:27:13,314 INFO org.apache.hadoop.yarn.server.resourcemanager.scheduler.common.fica.FiCaSchedulerApp: Completed container: container_1376201383303_0006_01_000038 in state: COMPLETED event:FINISHED
2013-08-11 06:27:13,314 INFO org.apache.hadoop.yarn.server.resourcemanager.RMAuditLogger: USER=ubuntu	OPERATION=AM Released Container	TARGET=SchedulerApp	RESULT=SUCCESS	APPID=application_1376201383303_0006	CONTAINERID=container_1376201383303_0006_01_000038
2013-08-11 06:27:13,314 INFO org.apache.hadoop.yarn.server.resourcemanager.scheduler.common.fica.FiCaSchedulerNode: Released container container_1376201383303_0006_01_000038 of capacity <memory:1024, vCores:1> on host hadoop-320-5:32992, which currently has 5 containers, <memory:6144, vCores:5> used and <memory:2048, vCores:11> available, release resources=true
2013-08-11 06:27:13,314 INFO org.apache.hadoop.yarn.server.resourcemanager.scheduler.capacity.LeafQueue: default used=<memory:47104, vCores:41> numContainers=41 user=ubuntu user-resources=<memory:47104, vCores:41>
2013-08-11 06:27:13,315 INFO org.apache.hadoop.yarn.server.resourcemanager.scheduler.capacity.LeafQueue: completedContainer container=Container: [ContainerId: container_1376201383303_0006_01_000038, NodeId: hadoop-320-5:32992, NodeHttpAddress: hadoop-320-5:8042, Resource: <memory:1024, vCores:1>, Priority: 20, State: NEW, Token: null, Status: container_id {, app_attempt_id {, application_id {, id: 6, cluster_timestamp: 1376201383303, }, attemptId: 1, }, id: 38, }, state: C_COMPLETE, diagnostics: "Container killed by the ApplicationMaster.\n\n", exit_status: 143, ] resource=<memory:1024, vCores:1> queue=default: capacity=1.0, absoluteCapacity=1.0, usedResources=<memory:47104, vCores:41>usedCapacity=0.9583333, absoluteUsedCapacity=0.9583333, numApps=5, numContainers=41 usedCapacity=0.9583333 absoluteUsedCapacity=0.9583333 used=<memory:47104, vCores:41> cluster=<memory:49152, vCores:96>
2013-08-11 06:27:13,316 INFO org.apache.hadoop.yarn.server.resourcemanager.scheduler.capacity.ParentQueue: completedContainer queue=root usedCapacity=0.9583333 absoluteUsedCapacity=0.9583333 used=<memory:47104, vCores:41> cluster=<memory:49152, vCores:96>
2013-08-11 06:27:13,316 INFO org.apache.hadoop.yarn.server.resourcemanager.scheduler.capacity.CapacityScheduler: Application appattempt_1376201383303_0006_000001 released container container_1376201383303_0006_01_000038 on node: host: hadoop-320-5:32992 #containers=5 available=2048 used=6144 with event: FINISHED
2013-08-11 06:27:13,316 INFO org.apache.hadoop.yarn.server.resourcemanager.rmcontainer.RMContainerImpl: container_1376201383303_0007_01_000012 Container Transitioned from NEW to ALLOCATED
2013-08-11 06:27:13,316 INFO org.apache.hadoop.yarn.server.resourcemanager.RMAuditLogger: USER=ubuntu	OPERATION=AM Allocated Container	TARGET=SchedulerApp	RESULT=SUCCESS	APPID=application_1376201383303_0007	CONTAINERID=container_1376201383303_0007_01_000012
2013-08-11 06:27:13,317 INFO org.apache.hadoop.yarn.server.resourcemanager.scheduler.common.fica.FiCaSchedulerNode: Assigned container container_1376201383303_0007_01_000012 of capacity <memory:1024, vCores:1> on host hadoop-320-5:32992, which currently has 6 containers, <memory:7168, vCores:6> used and <memory:1024, vCores:10> available
2013-08-11 06:27:13,318 INFO org.apache.hadoop.yarn.server.resourcemanager.scheduler.capacity.LeafQueue: assignedContainer application=application_1376201383303_0007 container=Container: [ContainerId: container_1376201383303_0007_01_000012, NodeId: hadoop-320-5:32992, NodeHttpAddress: hadoop-320-5:8042, Resource: <memory:1024, vCores:1>, Priority: 20, State: NEW, Token: null, Status: container_id {, app_attempt_id {, application_id {, id: 7, cluster_timestamp: 1376201383303, }, attemptId: 1, }, id: 12, }, state: C_NEW, ] containerId=container_1376201383303_0007_01_000012 queue=default: capacity=1.0, absoluteCapacity=1.0, usedResources=<memory:47104, vCores:41>usedCapacity=0.9583333, absoluteUsedCapacity=0.9583333, numApps=5, numContainers=41 usedCapacity=0.9583333 absoluteUsedCapacity=0.9583333 used=<memory:47104, vCores:41> cluster=<memory:49152, vCores:96>
2013-08-11 06:27:13,318 INFO org.apache.hadoop.yarn.server.resourcemanager.scheduler.capacity.ParentQueue: Re-sorting queues since queue: root.default stats: default: capacity=1.0, absoluteCapacity=1.0, usedResources=<memory:48128, vCores:42>usedCapacity=0.9791667, absoluteUsedCapacity=0.9791667, numApps=5, numContainers=42
2013-08-11 06:27:13,318 INFO org.apache.hadoop.yarn.server.resourcemanager.scheduler.capacity.ParentQueue: assignedContainer queue=root usedCapacity=0.9791667 absoluteUsedCapacity=0.9791667 used=<memory:48128, vCores:42> cluster=<memory:49152, vCores:96>
2013-08-11 06:27:13,319 INFO org.apache.hadoop.yarn.server.resourcemanager.rmcontainer.RMContainerImpl: container_1376201383303_0007_01_000013 Container Transitioned from NEW to ALLOCATED
2013-08-11 06:27:13,319 INFO org.apache.hadoop.yarn.server.resourcemanager.RMAuditLogger: USER=ubuntu	OPERATION=AM Allocated Container	TARGET=SchedulerApp	RESULT=SUCCESS	APPID=application_1376201383303_0007	CONTAINERID=container_1376201383303_0007_01_000013
2013-08-11 06:27:13,319 INFO org.apache.hadoop.yarn.server.resourcemanager.scheduler.common.fica.FiCaSchedulerNode: Assigned container container_1376201383303_0007_01_000013 of capacity <memory:1024, vCores:1> on host hadoop-320-5:32992, which currently has 7 containers, <memory:8192, vCores:7> used and <memory:0, vCores:9> available
2013-08-11 06:27:13,320 INFO org.apache.hadoop.yarn.server.resourcemanager.scheduler.capacity.LeafQueue: assignedContainer application=application_1376201383303_0007 container=Container: [ContainerId: container_1376201383303_0007_01_000013, NodeId: hadoop-320-5:32992, NodeHttpAddress: hadoop-320-5:8042, Resource: <memory:1024, vCores:1>, Priority: 20, State: NEW, Token: null, Status: container_id {, app_attempt_id {, application_id {, id: 7, cluster_timestamp: 1376201383303, }, attemptId: 1, }, id: 13, }, state: C_NEW, ] containerId=container_1376201383303_0007_01_000013 queue=default: capacity=1.0, absoluteCapacity=1.0, usedResources=<memory:48128, vCores:42>usedCapacity=0.9791667, absoluteUsedCapacity=0.9791667, numApps=5, numContainers=42 usedCapacity=0.9791667 absoluteUsedCapacity=0.9791667 used=<memory:48128, vCores:42> cluster=<memory:49152, vCores:96>
2013-08-11 06:27:13,320 INFO org.apache.hadoop.yarn.server.resourcemanager.scheduler.capacity.ParentQueue: Re-sorting queues since queue: root.default stats: default: capacity=1.0, absoluteCapacity=1.0, usedResources=<memory:49152, vCores:43>usedCapacity=1.0, absoluteUsedCapacity=1.0, numApps=5, numContainers=43
2013-08-11 06:27:13,320 INFO org.apache.hadoop.yarn.server.resourcemanager.scheduler.capacity.ParentQueue: assignedContainer queue=root usedCapacity=1.0 absoluteUsedCapacity=1.0 used=<memory:49152, vCores:43> cluster=<memory:49152, vCores:96>
2013-08-11 06:27:13,595 INFO org.apache.hadoop.yarn.server.resourcemanager.rmcontainer.RMContainerImpl: container_1376201383303_0007_01_000012 Container Transitioned from ALLOCATED to ACQUIRED
2013-08-11 06:27:13,596 INFO org.apache.hadoop.yarn.server.resourcemanager.rmcontainer.RMContainerImpl: container_1376201383303_0007_01_000013 Container Transitioned from ALLOCATED to ACQUIRED
2013-08-11 06:27:13,649 INFO org.apache.hadoop.yarn.server.resourcemanager.rmcontainer.RMContainerImpl: container_1376201383303_0006_01_000027 Container Transitioned from RUNNING to COMPLETED
2013-08-11 06:27:13,650 INFO org.apache.hadoop.yarn.server.resourcemanager.scheduler.common.fica.FiCaSchedulerApp: Completed container: container_1376201383303_0006_01_000027 in state: COMPLETED event:FINISHED
2013-08-11 06:27:13,650 INFO org.apache.hadoop.yarn.server.resourcemanager.RMAuditLogger: USER=ubuntu	OPERATION=AM Released Container	TARGET=SchedulerApp	RESULT=SUCCESS	APPID=application_1376201383303_0006	CONTAINERID=container_1376201383303_0006_01_000027
2013-08-11 06:27:13,650 INFO org.apache.hadoop.yarn.server.resourcemanager.scheduler.common.fica.FiCaSchedulerNode: Released container container_1376201383303_0006_01_000027 of capacity <memory:1024, vCores:1> on host hadoop-320-2:40354, which currently has 7 containers, <memory:7168, vCores:7> used and <memory:1024, vCores:9> available, release resources=true
2013-08-11 06:27:13,650 INFO org.apache.hadoop.yarn.server.resourcemanager.scheduler.capacity.LeafQueue: default used=<memory:48128, vCores:42> numContainers=42 user=ubuntu user-resources=<memory:48128, vCores:42>
2013-08-11 06:27:13,651 INFO org.apache.hadoop.yarn.server.resourcemanager.scheduler.capacity.LeafQueue: completedContainer container=Container: [ContainerId: container_1376201383303_0006_01_000027, NodeId: hadoop-320-2:40354, NodeHttpAddress: hadoop-320-2:8042, Resource: <memory:1024, vCores:1>, Priority: 20, State: NEW, Token: null, Status: container_id {, app_attempt_id {, application_id {, id: 6, cluster_timestamp: 1376201383303, }, attemptId: 1, }, id: 27, }, state: C_COMPLETE, diagnostics: "", exit_status: 0, ] resource=<memory:1024, vCores:1> queue=default: capacity=1.0, absoluteCapacity=1.0, usedResources=<memory:48128, vCores:42>usedCapacity=0.9791667, absoluteUsedCapacity=0.9791667, numApps=5, numContainers=42 usedCapacity=0.9791667 absoluteUsedCapacity=0.9791667 used=<memory:48128, vCores:42> cluster=<memory:49152, vCores:96>
2013-08-11 06:27:13,651 INFO org.apache.hadoop.yarn.server.resourcemanager.scheduler.capacity.ParentQueue: completedContainer queue=root usedCapacity=0.9791667 absoluteUsedCapacity=0.9791667 used=<memory:48128, vCores:42> cluster=<memory:49152, vCores:96>
2013-08-11 06:27:13,652 INFO org.apache.hadoop.yarn.server.resourcemanager.scheduler.capacity.CapacityScheduler: Application appattempt_1376201383303_0006_000001 released container container_1376201383303_0006_01_000027 on node: host: hadoop-320-2:40354 #containers=7 available=1024 used=7168 with event: FINISHED
2013-08-11 06:27:13,652 INFO org.apache.hadoop.yarn.server.resourcemanager.rmcontainer.RMContainerImpl: container_1376201383303_0007_01_000014 Container Transitioned from NEW to ALLOCATED
2013-08-11 06:27:13,652 INFO org.apache.hadoop.yarn.server.resourcemanager.RMAuditLogger: USER=ubuntu	OPERATION=AM Allocated Container	TARGET=SchedulerApp	RESULT=SUCCESS	APPID=application_1376201383303_0007	CONTAINERID=container_1376201383303_0007_01_000014
2013-08-11 06:27:13,653 INFO org.apache.hadoop.yarn.server.resourcemanager.scheduler.common.fica.FiCaSchedulerNode: Assigned container container_1376201383303_0007_01_000014 of capacity <memory:1024, vCores:1> on host hadoop-320-2:40354, which currently has 8 containers, <memory:8192, vCores:8> used and <memory:0, vCores:8> available
2013-08-11 06:27:13,653 INFO org.apache.hadoop.yarn.server.resourcemanager.scheduler.capacity.LeafQueue: assignedContainer application=application_1376201383303_0007 container=Container: [ContainerId: container_1376201383303_0007_01_000014, NodeId: hadoop-320-2:40354, NodeHttpAddress: hadoop-320-2:8042, Resource: <memory:1024, vCores:1>, Priority: 20, State: NEW, Token: null, Status: container_id {, app_attempt_id {, application_id {, id: 7, cluster_timestamp: 1376201383303, }, attemptId: 1, }, id: 14, }, state: C_NEW, ] containerId=container_1376201383303_0007_01_000014 queue=default: capacity=1.0, absoluteCapacity=1.0, usedResources=<memory:48128, vCores:42>usedCapacity=0.9791667, absoluteUsedCapacity=0.9791667, numApps=5, numContainers=42 usedCapacity=0.9791667 absoluteUsedCapacity=0.9791667 used=<memory:48128, vCores:42> cluster=<memory:49152, vCores:96>
