2013-08-27 15:47:13,157 INFO org.apache.hadoop.yarn.server.resourcemanager.ResourceManager: STARTUP_MSG: 
/************************************************************
STARTUP_MSG: Starting ResourceManager
STARTUP_MSG:   host = hadoop-8-1/192.168.100.15
STARTUP_MSG:   args = []
STARTUP_MSG:   version = 3.0.0-SNAPSHOT
STARTUP_MSG:   build = https://github.com/lalithsuresh/hadoop-common -r 0cb423bd4868928bb06cd93f882bb0913172fd17; compiled by 'lsuresh' on 2013-04-08T15:47Z
STARTUP_MSG:   java = 1.7.0_17
************************************************************/
2013-08-27 15:47:13,171 INFO org.apache.hadoop.yarn.server.resourcemanager.ResourceManager: registered UNIX signal handlers for [TERM, HUP, INT]
2013-08-27 15:47:13,758 INFO org.apache.hadoop.yarn.server.resourcemanager.security.ApplicationTokenSecretManager: Rolling master-key for application-tokens
2013-08-27 15:47:13,786 INFO org.apache.hadoop.yarn.server.resourcemanager.security.RMContainerTokenSecretManager: ContainerTokenKeyRollingInterval: 86400000ms and ContainerTokenKeyActivationDelay: 900000ms
2013-08-27 15:47:13,788 INFO org.apache.hadoop.yarn.service.AbstractService: Service:Dispatcher is inited.
2013-08-27 15:47:13,790 INFO org.apache.hadoop.yarn.event.AsyncDispatcher: Registering class org.apache.hadoop.yarn.server.resourcemanager.recovery.RMStateStoreEventType for class org.apache.hadoop.yarn.server.resourcemanager.recovery.RMStateStore$ForwardingEventHandler
2013-08-27 15:47:13,790 INFO org.apache.hadoop.yarn.service.AbstractService: Service:Dispatcher is started.
2013-08-27 15:47:13,796 INFO org.apache.hadoop.yarn.event.AsyncDispatcher: Registering class org.apache.hadoop.yarn.server.resourcemanager.NodesListManagerEventType for class org.apache.hadoop.yarn.server.resourcemanager.NodesListManager
2013-08-27 15:47:13,796 INFO org.apache.hadoop.yarn.server.resourcemanager.ResourceManager: Using Scheduler: org.apache.hadoop.yarn.server.resourcemanager.scheduler.capacity.CapacityScheduler
2013-08-27 15:47:13,955 INFO org.apache.hadoop.yarn.event.AsyncDispatcher: Registering class org.apache.hadoop.yarn.server.resourcemanager.scheduler.event.SchedulerEventType for class org.apache.hadoop.yarn.server.resourcemanager.ResourceManager$SchedulerEventDispatcher
2013-08-27 15:47:13,957 INFO org.apache.hadoop.yarn.event.AsyncDispatcher: Registering class org.apache.hadoop.yarn.server.resourcemanager.rmapp.RMAppEventType for class org.apache.hadoop.yarn.server.resourcemanager.ResourceManager$ApplicationEventDispatcher
2013-08-27 15:47:13,962 INFO org.apache.hadoop.yarn.event.AsyncDispatcher: Registering class org.apache.hadoop.yarn.server.resourcemanager.rmapp.attempt.RMAppAttemptEventType for class org.apache.hadoop.yarn.server.resourcemanager.ResourceManager$ApplicationAttemptEventDispatcher
2013-08-27 15:47:13,964 INFO org.apache.hadoop.yarn.event.AsyncDispatcher: Registering class org.apache.hadoop.yarn.server.resourcemanager.rmnode.RMNodeEventType for class org.apache.hadoop.yarn.server.resourcemanager.ResourceManager$NodeEventDispatcher
2013-08-27 15:47:14,511 WARN org.apache.hadoop.util.NativeCodeLoader: Unable to load native-hadoop library for your platform... using builtin-java classes where applicable
2013-08-27 15:47:14,575 INFO org.apache.hadoop.yarn.server.resourcemanager.scheduler.capacity.ParentQueue: root, capacity=1.0, asboluteCapacity=1.0, maxCapacity=1.0, asboluteMaxCapacity=1.0, state=RUNNING, acls=SUBMIT_APPLICATIONS:*ADMINISTER_QUEUE:*
2013-08-27 15:47:14,575 INFO org.apache.hadoop.yarn.server.resourcemanager.scheduler.capacity.ParentQueue: Initialized parent-queue root name=root, fullname=root
2013-08-27 15:47:14,592 INFO org.apache.hadoop.yarn.server.resourcemanager.scheduler.capacity.LeafQueue: Initializing default
capacity = 1.0 [= (float) configuredCapacity / 100 ]
asboluteCapacity = 1.0 [= parentAbsoluteCapacity * capacity ]
maxCapacity = 1.0 [= configuredMaxCapacity ]
absoluteMaxCapacity = 1.0 [= 1.0 maximumCapacity undefined, (parentAbsoluteMaxCapacity * maximumCapacity) / 100 otherwise ]
userLimit = 100 [= configuredUserLimit ]
userLimitFactor = 1.0 [= configuredUserLimitFactor ]
maxApplications = 10000 [= configuredMaximumSystemApplicationsPerQueue or (int)(configuredMaximumSystemApplications * absoluteCapacity)]
maxApplicationsPerUser = 10000 [= (int)(maxApplications * (userLimit / 100.0f) * userLimitFactor) ]
maxActiveApplications = 1 [= max((int)ceil((clusterResourceMemory / minimumAllocation) * maxAMResourcePerQueuePercent * absoluteMaxCapacity),1) ]
maxActiveAppsUsingAbsCap = 1 [= max((int)ceil((clusterResourceMemory / minimumAllocation) *maxAMResourcePercent * absoluteCapacity),1) ]
maxActiveApplicationsPerUser = 1 [= max((int)(maxActiveApplications * (userLimit / 100.0f) * userLimitFactor),1) ]
usedCapacity = 0.0 [= usedResourcesMemory / (clusterResourceMemory * absoluteCapacity)]
absoluteUsedCapacity = 0.0 [= usedResourcesMemory / clusterResourceMemory]
maxAMResourcePerQueuePercent = 0.1 [= configuredMaximumAMResourcePercent ]
minimumAllocationFactor = 0.875 [= (float)(maximumAllocationMemory - minimumAllocationMemory) / maximumAllocationMemory ]
numContainers = 0 [= currentNumContainers ]
state = RUNNING [= configuredState ]
acls = SUBMIT_APPLICATIONS:*ADMINISTER_QUEUE:* [= configuredAcls ]

2013-08-27 15:47:14,592 INFO org.apache.hadoop.yarn.server.resourcemanager.scheduler.capacity.CapacityScheduler: Initialized queue: default: capacity=1.0, absoluteCapacity=1.0, usedResources=<memory:0, vCores:0>usedCapacity=0.0, absoluteUsedCapacity=0.0, numApps=0, numContainers=0
2013-08-27 15:47:14,593 INFO org.apache.hadoop.yarn.server.resourcemanager.scheduler.capacity.CapacityScheduler: Initialized queue: root: numChildQueue= 1, capacity=1.0, absoluteCapacity=1.0, usedResources=<memory:0, vCores:0>usedCapacity=0.0, numApps=0, numContainers=0
2013-08-27 15:47:14,593 INFO org.apache.hadoop.yarn.server.resourcemanager.scheduler.capacity.CapacityScheduler: Initialized root queue root: numChildQueue= 1, capacity=1.0, absoluteCapacity=1.0, usedResources=<memory:0, vCores:0>usedCapacity=0.0, numApps=0, numContainers=0
2013-08-27 15:47:14,593 INFO org.apache.hadoop.yarn.server.resourcemanager.scheduler.capacity.CapacityScheduler: Initialized CapacityScheduler with calculator=class org.apache.hadoop.yarn.server.resourcemanager.resource.DefaultResourceCalculator, minimumAllocation=<<memory:1024, vCores:1>>, maximumAllocation=<<memory:8192, vCores:32>>
2013-08-27 15:47:15,071 INFO org.apache.hadoop.yarn.event.AsyncDispatcher: Registering class org.apache.hadoop.yarn.server.resourcemanager.RMAppManagerEventType for class org.apache.hadoop.yarn.server.resourcemanager.RMAppManager
2013-08-27 15:47:15,083 INFO org.apache.hadoop.yarn.event.AsyncDispatcher: Registering class org.apache.hadoop.yarn.server.resourcemanager.amlauncher.AMLauncherEventType for class org.apache.hadoop.yarn.server.resourcemanager.amlauncher.ApplicationMasterLauncher
2013-08-27 15:47:15,135 INFO org.apache.hadoop.yarn.server.resourcemanager.RMNMInfo: Registered RMNMInfo MBean
2013-08-27 15:47:15,135 INFO org.apache.hadoop.yarn.service.AbstractService: Service:Dispatcher is inited.
2013-08-27 15:47:15,136 INFO org.apache.hadoop.yarn.service.AbstractService: Service:org.apache.hadoop.yarn.server.resourcemanager.rmcontainer.ContainerAllocationExpirer is inited.
2013-08-27 15:47:15,136 INFO org.apache.hadoop.yarn.service.AbstractService: Service:AMLivelinessMonitor is inited.
2013-08-27 15:47:15,136 INFO org.apache.hadoop.yarn.service.AbstractService: Service:AMLivelinessMonitor is inited.
2013-08-27 15:47:15,136 INFO org.apache.hadoop.yarn.service.AbstractService: Service:org.apache.hadoop.yarn.server.resourcemanager.security.DelegationTokenRenewer is inited.
2013-08-27 15:47:15,137 INFO org.apache.hadoop.util.HostsFileReader: Refreshing hosts (include/exclude) list
2013-08-27 15:47:15,137 INFO org.apache.hadoop.yarn.service.AbstractService: Service:org.apache.hadoop.yarn.server.resourcemanager.NodesListManager is inited.
2013-08-27 15:47:15,137 INFO org.apache.hadoop.yarn.service.AbstractService: Service:org.apache.hadoop.yarn.server.resourcemanager.ResourceManager$SchedulerEventDispatcher is inited.
2013-08-27 15:47:15,137 INFO org.apache.hadoop.yarn.service.AbstractService: Service:NMLivelinessMonitor is inited.
2013-08-27 15:47:15,141 INFO org.apache.hadoop.yarn.service.AbstractService: Service:org.apache.hadoop.yarn.server.resourcemanager.ResourceTrackerService is inited.
2013-08-27 15:47:15,142 INFO org.apache.hadoop.yarn.service.AbstractService: Service:org.apache.hadoop.yarn.server.resourcemanager.ApplicationMasterService is inited.
2013-08-27 15:47:15,142 INFO org.apache.hadoop.yarn.service.AbstractService: Service:org.apache.hadoop.yarn.server.resourcemanager.ClientRMService is inited.
2013-08-27 15:47:15,142 INFO org.apache.hadoop.yarn.service.AbstractService: Service:org.apache.hadoop.yarn.server.resourcemanager.AdminService is inited.
2013-08-27 15:47:15,142 INFO org.apache.hadoop.yarn.service.AbstractService: Service:org.apache.hadoop.yarn.server.resourcemanager.amlauncher.ApplicationMasterLauncher is inited.
2013-08-27 15:47:15,142 INFO org.apache.hadoop.yarn.service.AbstractService: Service:ResourceManager is inited.
2013-08-27 15:47:15,142 INFO org.apache.hadoop.yarn.server.resourcemanager.security.RMContainerTokenSecretManager: Rolling master-key for container-tokens
2013-08-27 15:47:15,142 INFO org.apache.hadoop.yarn.server.resourcemanager.security.ApplicationTokenSecretManager: Rolling master-key for application-tokens
2013-08-27 15:47:15,228 INFO org.mortbay.log: Logging to org.slf4j.impl.Log4jLoggerAdapter(org.mortbay.log) via org.mortbay.log.Slf4jLog
2013-08-27 15:47:15,283 INFO org.apache.hadoop.http.HttpServer: Added global filter 'safety' (class=org.apache.hadoop.http.HttpServer$QuotingInputFilter)
2013-08-27 15:47:15,286 INFO org.apache.hadoop.http.HttpServer: Added filter static_user_filter (class=org.apache.hadoop.http.lib.StaticUserWebFilter$StaticUserFilter) to context cluster
2013-08-27 15:47:15,286 INFO org.apache.hadoop.http.HttpServer: Added filter static_user_filter (class=org.apache.hadoop.http.lib.StaticUserWebFilter$StaticUserFilter) to context logs
2013-08-27 15:47:15,286 INFO org.apache.hadoop.http.HttpServer: Added filter static_user_filter (class=org.apache.hadoop.http.lib.StaticUserWebFilter$StaticUserFilter) to context static
2013-08-27 15:47:15,290 INFO org.apache.hadoop.http.HttpServer: adding path spec: /cluster
2013-08-27 15:47:15,290 INFO org.apache.hadoop.http.HttpServer: adding path spec: /cluster/*
2013-08-27 15:47:15,291 INFO org.apache.hadoop.http.HttpServer: adding path spec: /ws
2013-08-27 15:47:15,291 INFO org.apache.hadoop.http.HttpServer: adding path spec: /ws/*
2013-08-27 15:47:15,293 INFO org.apache.hadoop.http.HttpServer: Added global filter 'guice' (class=com.google.inject.servlet.GuiceFilter)
2013-08-27 15:47:15,298 INFO org.apache.hadoop.http.HttpServer: Jetty bound to port 8088
2013-08-27 15:47:15,298 INFO org.mortbay.log: jetty-6.1.26
2013-08-27 15:47:15,328 INFO org.mortbay.log: Extract jar:file:/home/ubuntu/hadoop-3.0.0-SNAPSHOT/share/hadoop/yarn/hadoop-yarn-common-3.0.0-SNAPSHOT.jar!/webapps/cluster to /tmp/Jetty_0_0_0_0_8088_cluster____u0rgz3/webapp
2013-08-27 15:47:15,645 INFO org.mortbay.log: Started SelectChannelConnector@0.0.0.0:8088
2013-08-27 15:47:15,645 INFO org.apache.hadoop.yarn.webapp.WebApps: Web app /cluster started at 8088
2013-08-27 15:47:16,653 INFO org.apache.hadoop.yarn.webapp.WebApps: Registered webapp guice modules
2013-08-27 15:47:16,753 INFO org.apache.hadoop.metrics2.impl.MetricsConfig: loaded properties from hadoop-metrics2.properties
2013-08-27 15:47:16,785 INFO org.apache.hadoop.metrics2.impl.MetricsSystemImpl: Scheduled snapshot period at 10 second(s).
2013-08-27 15:47:16,785 INFO org.apache.hadoop.metrics2.impl.MetricsSystemImpl: ResourceManager metrics system started
2013-08-27 15:47:16,802 INFO org.apache.hadoop.security.token.delegation.AbstractDelegationTokenSecretManager: Updating the current master key for generating delegation tokens
2013-08-27 15:47:16,806 INFO org.apache.hadoop.yarn.service.AbstractService: Service:Dispatcher is started.
2013-08-27 15:47:16,807 INFO org.apache.hadoop.security.token.delegation.AbstractDelegationTokenSecretManager: Starting expired delegation token remover thread, tokenRemoverScanInterval=60 min(s)
2013-08-27 15:47:16,807 INFO org.apache.hadoop.security.token.delegation.AbstractDelegationTokenSecretManager: Updating the current master key for generating delegation tokens
2013-08-27 15:47:16,809 INFO org.apache.hadoop.yarn.service.AbstractService: Service:org.apache.hadoop.yarn.server.resourcemanager.rmcontainer.ContainerAllocationExpirer is started.
2013-08-27 15:47:16,810 INFO org.apache.hadoop.yarn.service.AbstractService: Service:AMLivelinessMonitor is started.
2013-08-27 15:47:16,810 INFO org.apache.hadoop.yarn.service.AbstractService: Service:AMLivelinessMonitor is started.
2013-08-27 15:47:16,810 INFO org.apache.hadoop.yarn.service.AbstractService: Service:org.apache.hadoop.yarn.server.resourcemanager.security.DelegationTokenRenewer is started.
2013-08-27 15:47:16,812 INFO org.apache.hadoop.yarn.service.AbstractService: Service:org.apache.hadoop.yarn.server.resourcemanager.NodesListManager is started.
2013-08-27 15:47:16,813 INFO org.apache.hadoop.yarn.service.AbstractService: Service:org.apache.hadoop.yarn.server.resourcemanager.ResourceManager$SchedulerEventDispatcher is started.
2013-08-27 15:47:16,813 INFO org.apache.hadoop.yarn.service.AbstractService: Service:NMLivelinessMonitor is started.
2013-08-27 15:47:16,813 INFO org.apache.hadoop.yarn.service.AbstractService: Service:org.apache.hadoop.yarn.server.resourcemanager.ResourceTrackerService is started.
2013-08-27 15:47:16,897 INFO org.apache.hadoop.ipc.Server: Starting Socket Reader #1 for port 54110
2013-08-27 15:47:16,950 INFO org.apache.hadoop.yarn.factories.impl.pb.RpcServerFactoryPBImpl: Adding protocol org.apache.hadoop.yarn.server.api.ResourceTrackerPB to the server
2013-08-27 15:47:16,951 INFO org.apache.hadoop.ipc.Server: IPC Server Responder: starting
2013-08-27 15:47:16,986 INFO org.apache.hadoop.ipc.Server: IPC Server listener on 54110: starting
2013-08-27 15:47:17,078 INFO org.apache.hadoop.ipc.Server: Starting Socket Reader #1 for port 54112
2013-08-27 15:47:17,090 INFO org.apache.hadoop.yarn.factories.impl.pb.RpcServerFactoryPBImpl: Adding protocol org.apache.hadoop.yarn.api.AMRMProtocolPB to the server
2013-08-27 15:47:17,091 INFO org.apache.hadoop.ipc.Server: IPC Server Responder: starting
2013-08-27 15:47:17,093 INFO org.apache.hadoop.ipc.Server: IPC Server listener on 54112: starting
2013-08-27 15:47:17,132 INFO org.apache.hadoop.yarn.service.AbstractService: Service:org.apache.hadoop.yarn.server.resourcemanager.ApplicationMasterService is started.
2013-08-27 15:47:17,189 INFO org.apache.hadoop.ipc.Server: Starting Socket Reader #1 for port 54111
2013-08-27 15:47:17,195 INFO org.apache.hadoop.yarn.factories.impl.pb.RpcServerFactoryPBImpl: Adding protocol org.apache.hadoop.yarn.api.ClientRMProtocolPB to the server
2013-08-27 15:47:17,196 INFO org.apache.hadoop.ipc.Server: IPC Server Responder: starting
2013-08-27 15:47:17,200 INFO org.apache.hadoop.ipc.Server: IPC Server listener on 54111: starting
2013-08-27 15:47:17,247 INFO org.apache.hadoop.yarn.service.AbstractService: Service:org.apache.hadoop.yarn.server.resourcemanager.ClientRMService is started.
2013-08-27 15:47:17,284 INFO org.apache.hadoop.ipc.Server: Starting Socket Reader #1 for port 8033
2013-08-27 15:47:17,291 INFO org.apache.hadoop.yarn.factories.impl.pb.RpcServerFactoryPBImpl: Adding protocol org.apache.hadoop.yarn.api.RMAdminProtocolPB to the server
2013-08-27 15:47:17,292 INFO org.apache.hadoop.ipc.Server: IPC Server Responder: starting
2013-08-27 15:47:17,293 INFO org.apache.hadoop.ipc.Server: IPC Server listener on 8033: starting
2013-08-27 15:47:17,296 INFO org.apache.hadoop.yarn.service.AbstractService: Service:org.apache.hadoop.yarn.server.resourcemanager.AdminService is started.
2013-08-27 15:47:17,297 INFO org.apache.hadoop.yarn.service.AbstractService: Service:org.apache.hadoop.yarn.server.resourcemanager.amlauncher.ApplicationMasterLauncher is started.
2013-08-27 15:47:17,297 INFO org.apache.hadoop.yarn.service.AbstractService: Service:ResourceManager is started.
2013-08-27 15:47:28,009 INFO org.apache.hadoop.yarn.util.RackResolver: Resolved hadoop-8-4 to /default-rack
2013-08-27 15:47:28,009 INFO org.apache.hadoop.yarn.util.RackResolver: Resolved hadoop-8-6 to /default-rack
2013-08-27 15:47:28,010 INFO org.apache.hadoop.yarn.util.RackResolver: Resolved hadoop-8-5 to /default-rack
2013-08-27 15:47:28,011 INFO org.apache.hadoop.yarn.util.RackResolver: Resolved hadoop-8-2 to /default-rack
2013-08-27 15:47:28,012 INFO org.apache.hadoop.yarn.util.RackResolver: Resolved hadoop-8-3 to /default-rack
2013-08-27 15:47:28,027 INFO org.apache.hadoop.yarn.server.resourcemanager.ResourceTrackerService: NodeManager from node hadoop-8-5(cmPort: 56487 httpPort: 8042) registered with capability: <memory:8192, vCores:16>, assigned nodeId hadoop-8-5:56487
2013-08-27 15:47:28,029 INFO org.apache.hadoop.yarn.server.resourcemanager.ResourceTrackerService: NodeManager from node hadoop-8-2(cmPort: 41932 httpPort: 8042) registered with capability: <memory:8192, vCores:16>, assigned nodeId hadoop-8-2:41932
2013-08-27 15:47:28,029 INFO org.apache.hadoop.yarn.server.resourcemanager.ResourceTrackerService: NodeManager from node hadoop-8-6(cmPort: 45732 httpPort: 8042) registered with capability: <memory:8192, vCores:16>, assigned nodeId hadoop-8-6:45732
2013-08-27 15:47:28,029 INFO org.apache.hadoop.yarn.server.resourcemanager.ResourceTrackerService: NodeManager from node hadoop-8-3(cmPort: 42074 httpPort: 8042) registered with capability: <memory:8192, vCores:16>, assigned nodeId hadoop-8-3:42074
2013-08-27 15:47:28,030 INFO org.apache.hadoop.yarn.server.resourcemanager.ResourceTrackerService: NodeManager from node hadoop-8-4(cmPort: 36803 httpPort: 8042) registered with capability: <memory:8192, vCores:16>, assigned nodeId hadoop-8-4:36803
2013-08-27 15:47:28,062 INFO org.apache.hadoop.yarn.server.resourcemanager.rmnode.RMNodeImpl: hadoop-8-5:56487 Node Transitioned from NEW to RUNNING
2013-08-27 15:47:28,066 INFO org.apache.hadoop.yarn.server.resourcemanager.rmnode.RMNodeImpl: hadoop-8-2:41932 Node Transitioned from NEW to RUNNING
2013-08-27 15:47:28,067 INFO org.apache.hadoop.yarn.server.resourcemanager.rmnode.RMNodeImpl: hadoop-8-6:45732 Node Transitioned from NEW to RUNNING
2013-08-27 15:47:28,067 INFO org.apache.hadoop.yarn.server.resourcemanager.rmnode.RMNodeImpl: hadoop-8-3:42074 Node Transitioned from NEW to RUNNING
2013-08-27 15:47:28,068 INFO org.apache.hadoop.yarn.server.resourcemanager.rmnode.RMNodeImpl: hadoop-8-4:36803 Node Transitioned from NEW to RUNNING
2013-08-27 15:47:28,072 INFO org.apache.hadoop.yarn.server.resourcemanager.scheduler.capacity.CapacityScheduler: Added node hadoop-8-5:56487 clusterResource: <memory:8192, vCores:16>
2013-08-27 15:47:28,073 INFO org.apache.hadoop.yarn.server.resourcemanager.scheduler.capacity.CapacityScheduler: Added node hadoop-8-2:41932 clusterResource: <memory:16384, vCores:32>
2013-08-27 15:47:28,073 INFO org.apache.hadoop.yarn.server.resourcemanager.scheduler.capacity.CapacityScheduler: Added node hadoop-8-6:45732 clusterResource: <memory:24576, vCores:48>
2013-08-27 15:47:28,073 INFO org.apache.hadoop.yarn.server.resourcemanager.scheduler.capacity.CapacityScheduler: Added node hadoop-8-3:42074 clusterResource: <memory:32768, vCores:64>
2013-08-27 15:47:28,074 INFO org.apache.hadoop.yarn.server.resourcemanager.scheduler.capacity.CapacityScheduler: Added node hadoop-8-4:36803 clusterResource: <memory:40960, vCores:80>
2013-08-27 15:47:28,108 INFO org.apache.hadoop.yarn.util.RackResolver: Resolved hadoop-8-7 to /default-rack
2013-08-27 15:47:28,108 INFO org.apache.hadoop.yarn.server.resourcemanager.ResourceTrackerService: NodeManager from node hadoop-8-7(cmPort: 53314 httpPort: 8042) registered with capability: <memory:8192, vCores:16>, assigned nodeId hadoop-8-7:53314
2013-08-27 15:47:28,109 INFO org.apache.hadoop.yarn.server.resourcemanager.rmnode.RMNodeImpl: hadoop-8-7:53314 Node Transitioned from NEW to RUNNING
2013-08-27 15:47:28,110 INFO org.apache.hadoop.yarn.server.resourcemanager.scheduler.capacity.CapacityScheduler: Added node hadoop-8-7:53314 clusterResource: <memory:49152, vCores:96>
2013-08-27 15:47:54,256 INFO org.apache.hadoop.yarn.server.resourcemanager.ClientRMService: Allocated new applicationId: 1
2013-08-27 15:47:57,569 INFO org.apache.hadoop.yarn.server.resourcemanager.ClientRMService: Storing Application with id application_1377618433102_0001
2013-08-27 15:47:57,574 INFO org.apache.hadoop.yarn.server.resourcemanager.recovery.RMStateStore: Storing info for app: application_1377618433102_0001
2013-08-27 15:47:57,575 INFO org.apache.hadoop.yarn.server.resourcemanager.ClientRMService: Application with id 1 submitted by user ubuntu
2013-08-27 15:47:57,578 INFO org.apache.hadoop.yarn.server.resourcemanager.RMAuditLogger: USER=ubuntu	IP=192.168.100.15	OPERATION=Submit Application Request	TARGET=ClientRMService	RESULT=SUCCESS	APPID=application_1377618433102_0001
2013-08-27 15:47:57,622 INFO org.apache.hadoop.yarn.server.resourcemanager.rmapp.RMAppImpl: application_1377618433102_0001 State change from NEW to SUBMITTED
2013-08-27 15:47:57,622 INFO org.apache.hadoop.yarn.server.resourcemanager.ApplicationMasterService: Registering appattempt_1377618433102_0001_000001
2013-08-27 15:47:57,624 INFO org.apache.hadoop.yarn.server.resourcemanager.rmapp.attempt.RMAppAttemptImpl: appattempt_1377618433102_0001_000001 State change from NEW to SUBMITTED
2013-08-27 15:47:57,657 INFO org.apache.hadoop.yarn.server.resourcemanager.scheduler.capacity.LeafQueue: Application application_1377618433102_0001 from user: ubuntu activated in queue: default
2013-08-27 15:47:57,657 INFO org.apache.hadoop.yarn.server.resourcemanager.scheduler.capacity.LeafQueue: Application added - appId: application_1377618433102_0001 user: org.apache.hadoop.yarn.server.resourcemanager.scheduler.capacity.LeafQueue$User@2ea2c1d0, leaf-queue: default #user-pending-applications: 0 #user-active-applications: 1 #queue-pending-applications: 0 #queue-active-applications: 1
2013-08-27 15:47:57,658 INFO org.apache.hadoop.yarn.server.resourcemanager.scheduler.capacity.ParentQueue: Application added - appId: application_1377618433102_0001 user: ubuntu leaf-queue of parent: root #applications: 1
2013-08-27 15:47:57,658 INFO org.apache.hadoop.yarn.server.resourcemanager.scheduler.capacity.CapacityScheduler: Application Submission: appattempt_1377618433102_0001_000001, user: ubuntu queue: default: capacity=1.0, absoluteCapacity=1.0, usedResources=<memory:0, vCores:0>usedCapacity=0.0, absoluteUsedCapacity=0.0, numApps=1, numContainers=0, currently active: 1
2013-08-27 15:47:57,664 INFO org.apache.hadoop.yarn.server.resourcemanager.rmapp.attempt.RMAppAttemptImpl: appattempt_1377618433102_0001_000001 State change from SUBMITTED to SCHEDULED
2013-08-27 15:47:57,664 INFO org.apache.hadoop.yarn.server.resourcemanager.rmapp.RMAppImpl: application_1377618433102_0001 State change from SUBMITTED to ACCEPTED
2013-08-27 15:47:58,343 INFO org.apache.hadoop.yarn.server.resourcemanager.rmcontainer.RMContainerImpl: container_1377618433102_0001_01_000001 Container Transitioned from NEW to ALLOCATED
2013-08-27 15:47:58,344 INFO org.apache.hadoop.yarn.server.resourcemanager.RMAuditLogger: USER=ubuntu	OPERATION=AM Allocated Container	TARGET=SchedulerApp	RESULT=SUCCESS	APPID=application_1377618433102_0001	CONTAINERID=container_1377618433102_0001_01_000001
2013-08-27 15:47:58,348 INFO org.apache.hadoop.yarn.server.resourcemanager.scheduler.common.fica.FiCaSchedulerNode: Assigned container container_1377618433102_0001_01_000001 of capacity <memory:2048, vCores:1> on host hadoop-8-4:36803, which currently has 1 containers, <memory:2048, vCores:1> used and <memory:6144, vCores:15> available
2013-08-27 15:47:58,355 INFO org.apache.hadoop.yarn.server.resourcemanager.scheduler.capacity.LeafQueue: assignedContainer application=application_1377618433102_0001 container=Container: [ContainerId: container_1377618433102_0001_01_000001, NodeId: hadoop-8-4:36803, NodeHttpAddress: hadoop-8-4:8042, Resource: <memory:2048, vCores:1>, Priority: 0, State: NEW, Token: null, Status: container_id {, app_attempt_id {, application_id {, id: 1, cluster_timestamp: 1377618433102, }, attemptId: 1, }, id: 1, }, state: C_NEW, ] containerId=container_1377618433102_0001_01_000001 queue=default: capacity=1.0, absoluteCapacity=1.0, usedResources=<memory:0, vCores:0>usedCapacity=0.0, absoluteUsedCapacity=0.0, numApps=1, numContainers=0 usedCapacity=0.0 absoluteUsedCapacity=0.0 used=<memory:0, vCores:0> cluster=<memory:49152, vCores:96>
2013-08-27 15:47:58,355 INFO org.apache.hadoop.yarn.server.resourcemanager.scheduler.capacity.ParentQueue: Re-sorting queues since queue: root.default stats: default: capacity=1.0, absoluteCapacity=1.0, usedResources=<memory:2048, vCores:1>usedCapacity=0.041666668, absoluteUsedCapacity=0.041666668, numApps=1, numContainers=1
2013-08-27 15:47:58,356 INFO org.apache.hadoop.yarn.server.resourcemanager.scheduler.capacity.ParentQueue: assignedContainer queue=root usedCapacity=0.041666668 absoluteUsedCapacity=0.041666668 used=<memory:2048, vCores:1> cluster=<memory:49152, vCores:96>
2013-08-27 15:47:58,358 INFO org.apache.hadoop.yarn.server.resourcemanager.rmcontainer.RMContainerImpl: container_1377618433102_0001_01_000001 Container Transitioned from ALLOCATED to ACQUIRED
2013-08-27 15:47:58,362 INFO org.apache.hadoop.yarn.server.resourcemanager.rmapp.attempt.RMAppAttemptImpl: Storing attempt: AppId: application_1377618433102_0001 AttemptId: appattempt_1377618433102_0001_000001 MasterContainer: Container: [ContainerId: container_1377618433102_0001_01_000001, NodeId: hadoop-8-4:36803, NodeHttpAddress: hadoop-8-4:8042, Resource: <memory:2048, vCores:1>, Priority: 0, State: NEW, Token: null, Status: container_id {, app_attempt_id {, application_id {, id: 1, cluster_timestamp: 1377618433102, }, attemptId: 1, }, id: 1, }, state: C_NEW, ]
2013-08-27 15:47:58,365 INFO org.apache.hadoop.yarn.server.resourcemanager.rmapp.attempt.RMAppAttemptImpl: appattempt_1377618433102_0001_000001 State change from SCHEDULED to ALLOCATED_SAVING
2013-08-27 15:47:58,369 INFO org.apache.hadoop.yarn.server.resourcemanager.recovery.RMStateStore: Storing info for attempt: appattempt_1377618433102_0001_000001
2013-08-27 15:47:58,372 INFO org.apache.hadoop.yarn.server.resourcemanager.rmapp.attempt.RMAppAttemptImpl: appattempt_1377618433102_0001_000001 State change from ALLOCATED_SAVING to ALLOCATED
2013-08-27 15:47:58,379 INFO org.apache.hadoop.yarn.server.resourcemanager.amlauncher.AMLauncher: Launching masterappattempt_1377618433102_0001_000001
2013-08-27 15:47:58,428 INFO org.apache.hadoop.yarn.server.resourcemanager.amlauncher.AMLauncher: Setting up container Container: [ContainerId: container_1377618433102_0001_01_000001, NodeId: hadoop-8-4:36803, NodeHttpAddress: hadoop-8-4:8042, Resource: <memory:2048, vCores:1>, Priority: 0, State: NEW, Token: null, Status: container_id {, app_attempt_id {, application_id {, id: 1, cluster_timestamp: 1377618433102, }, attemptId: 1, }, id: 1, }, state: C_NEW, ] for AM appattempt_1377618433102_0001_000001
2013-08-27 15:47:58,428 INFO org.apache.hadoop.yarn.server.resourcemanager.amlauncher.AMLauncher: Command to launch container container_1377618433102_0001_01_000001 : $JAVA_HOME/bin/java -Dlog4j.configuration=container-log4j.properties -Dyarn.app.mapreduce.container.log.dir=<LOG_DIR> -Dyarn.app.mapreduce.container.log.filesize=0 -Dhadoop.root.logger=INFO,CLA  -Xmx1024m org.apache.hadoop.mapreduce.v2.app.MRAppMaster 1><LOG_DIR>/stdout 2><LOG_DIR>/stderr 
2013-08-27 15:47:59,320 INFO org.apache.hadoop.yarn.server.resourcemanager.amlauncher.AMLauncher: Done launching container Container: [ContainerId: container_1377618433102_0001_01_000001, NodeId: hadoop-8-4:36803, NodeHttpAddress: hadoop-8-4:8042, Resource: <memory:2048, vCores:1>, Priority: 0, State: NEW, Token: null, Status: container_id {, app_attempt_id {, application_id {, id: 1, cluster_timestamp: 1377618433102, }, attemptId: 1, }, id: 1, }, state: C_NEW, ] for AM appattempt_1377618433102_0001_000001
2013-08-27 15:47:59,320 INFO org.apache.hadoop.yarn.server.resourcemanager.rmapp.attempt.RMAppAttemptImpl: appattempt_1377618433102_0001_000001 State change from ALLOCATED to LAUNCHED
2013-08-27 15:47:59,342 INFO org.apache.hadoop.yarn.server.resourcemanager.rmcontainer.RMContainerImpl: container_1377618433102_0001_01_000001 Container Transitioned from ACQUIRED to RUNNING
2013-08-27 15:48:07,706 INFO org.apache.hadoop.yarn.server.resourcemanager.ApplicationMasterService: AM registration appattempt_1377618433102_0001_000001
2013-08-27 15:48:07,715 INFO org.apache.hadoop.yarn.server.resourcemanager.RMAuditLogger: USER=ubuntu	IP=192.168.100.24	OPERATION=Register App Master	TARGET=ApplicationMasterService	RESULT=SUCCESS	APPID=application_1377618433102_0001	APPATTEMPTID=appattempt_1377618433102_0001_000001
2013-08-27 15:48:07,718 INFO org.apache.hadoop.yarn.server.resourcemanager.rmapp.attempt.RMAppAttemptImpl: appattempt_1377618433102_0001_000001 State change from LAUNCHED to RUNNING
2013-08-27 15:48:07,723 INFO org.apache.hadoop.yarn.server.resourcemanager.rmapp.RMAppImpl: application_1377618433102_0001 State change from ACCEPTED to RUNNING
2013-08-27 15:48:09,361 INFO org.apache.hadoop.yarn.server.resourcemanager.rmcontainer.RMContainerImpl: container_1377618433102_0001_01_000002 Container Transitioned from NEW to ALLOCATED
2013-08-27 15:48:09,361 INFO org.apache.hadoop.yarn.server.resourcemanager.RMAuditLogger: USER=ubuntu	OPERATION=AM Allocated Container	TARGET=SchedulerApp	RESULT=SUCCESS	APPID=application_1377618433102_0001	CONTAINERID=container_1377618433102_0001_01_000002
2013-08-27 15:48:09,362 INFO org.apache.hadoop.yarn.server.resourcemanager.scheduler.common.fica.FiCaSchedulerNode: Assigned container container_1377618433102_0001_01_000002 of capacity <memory:1024, vCores:1> on host hadoop-8-3:42074, which currently has 1 containers, <memory:1024, vCores:1> used and <memory:7168, vCores:15> available
2013-08-27 15:48:09,363 INFO org.apache.hadoop.yarn.server.resourcemanager.scheduler.capacity.LeafQueue: assignedContainer application=application_1377618433102_0001 container=Container: [ContainerId: container_1377618433102_0001_01_000002, NodeId: hadoop-8-3:42074, NodeHttpAddress: hadoop-8-3:8042, Resource: <memory:1024, vCores:1>, Priority: 20, State: NEW, Token: null, Status: container_id {, app_attempt_id {, application_id {, id: 1, cluster_timestamp: 1377618433102, }, attemptId: 1, }, id: 2, }, state: C_NEW, ] containerId=container_1377618433102_0001_01_000002 queue=default: capacity=1.0, absoluteCapacity=1.0, usedResources=<memory:2048, vCores:1>usedCapacity=0.041666668, absoluteUsedCapacity=0.041666668, numApps=1, numContainers=1 usedCapacity=0.041666668 absoluteUsedCapacity=0.041666668 used=<memory:2048, vCores:1> cluster=<memory:49152, vCores:96>
2013-08-27 15:48:09,364 INFO org.apache.hadoop.yarn.server.resourcemanager.scheduler.capacity.ParentQueue: Re-sorting queues since queue: root.default stats: default: capacity=1.0, absoluteCapacity=1.0, usedResources=<memory:3072, vCores:2>usedCapacity=0.0625, absoluteUsedCapacity=0.0625, numApps=1, numContainers=2
2013-08-27 15:48:09,364 INFO org.apache.hadoop.yarn.server.resourcemanager.scheduler.capacity.ParentQueue: assignedContainer queue=root usedCapacity=0.0625 absoluteUsedCapacity=0.0625 used=<memory:3072, vCores:2> cluster=<memory:49152, vCores:96>
2013-08-27 15:48:09,365 INFO org.apache.hadoop.yarn.server.resourcemanager.rmcontainer.RMContainerImpl: container_1377618433102_0001_01_000003 Container Transitioned from NEW to ALLOCATED
2013-08-27 15:48:09,365 INFO org.apache.hadoop.yarn.server.resourcemanager.RMAuditLogger: USER=ubuntu	OPERATION=AM Allocated Container	TARGET=SchedulerApp	RESULT=SUCCESS	APPID=application_1377618433102_0001	CONTAINERID=container_1377618433102_0001_01_000003
2013-08-27 15:48:09,365 INFO org.apache.hadoop.yarn.server.resourcemanager.scheduler.common.fica.FiCaSchedulerNode: Assigned container container_1377618433102_0001_01_000003 of capacity <memory:1024, vCores:1> on host hadoop-8-2:41932, which currently has 1 containers, <memory:1024, vCores:1> used and <memory:7168, vCores:15> available
2013-08-27 15:48:09,367 INFO org.apache.hadoop.yarn.server.resourcemanager.scheduler.capacity.LeafQueue: assignedContainer application=application_1377618433102_0001 container=Container: [ContainerId: container_1377618433102_0001_01_000003, NodeId: hadoop-8-2:41932, NodeHttpAddress: hadoop-8-2:8042, Resource: <memory:1024, vCores:1>, Priority: 20, State: NEW, Token: null, Status: container_id {, app_attempt_id {, application_id {, id: 1, cluster_timestamp: 1377618433102, }, attemptId: 1, }, id: 3, }, state: C_NEW, ] containerId=container_1377618433102_0001_01_000003 queue=default: capacity=1.0, absoluteCapacity=1.0, usedResources=<memory:3072, vCores:2>usedCapacity=0.0625, absoluteUsedCapacity=0.0625, numApps=1, numContainers=2 usedCapacity=0.0625 absoluteUsedCapacity=0.0625 used=<memory:3072, vCores:2> cluster=<memory:49152, vCores:96>
2013-08-27 15:48:09,367 INFO org.apache.hadoop.yarn.server.resourcemanager.scheduler.capacity.ParentQueue: Re-sorting queues since queue: root.default stats: default: capacity=1.0, absoluteCapacity=1.0, usedResources=<memory:4096, vCores:3>usedCapacity=0.083333336, absoluteUsedCapacity=0.083333336, numApps=1, numContainers=3
2013-08-27 15:48:09,368 INFO org.apache.hadoop.yarn.server.resourcemanager.scheduler.capacity.ParentQueue: assignedContainer queue=root usedCapacity=0.083333336 absoluteUsedCapacity=0.083333336 used=<memory:4096, vCores:3> cluster=<memory:49152, vCores:96>
2013-08-27 15:48:09,791 INFO org.apache.hadoop.yarn.server.resourcemanager.rmcontainer.RMContainerImpl: container_1377618433102_0001_01_000002 Container Transitioned from ALLOCATED to ACQUIRED
2013-08-27 15:48:09,793 INFO org.apache.hadoop.yarn.server.resourcemanager.rmcontainer.RMContainerImpl: container_1377618433102_0001_01_000003 Container Transitioned from ALLOCATED to ACQUIRED
2013-08-27 15:48:10,823 INFO org.apache.hadoop.yarn.server.resourcemanager.scheduler.AppSchedulingInfo: checking for deactivate... 
2013-08-27 15:48:11,446 INFO org.apache.hadoop.yarn.server.resourcemanager.rmcontainer.RMContainerImpl: container_1377618433102_0001_01_000002 Container Transitioned from ACQUIRED to RUNNING
2013-08-27 15:48:11,448 INFO org.apache.hadoop.yarn.server.resourcemanager.rmcontainer.RMContainerImpl: container_1377618433102_0001_01_000003 Container Transitioned from ACQUIRED to RUNNING
2013-08-27 15:50:59,655 INFO org.apache.hadoop.yarn.server.resourcemanager.rmcontainer.RMContainerImpl: container_1377618433102_0001_01_000002 Container Transitioned from RUNNING to COMPLETED
2013-08-27 15:50:59,655 INFO org.apache.hadoop.yarn.server.resourcemanager.scheduler.common.fica.FiCaSchedulerApp: Completed container: container_1377618433102_0001_01_000002 in state: COMPLETED event:FINISHED
2013-08-27 15:50:59,656 INFO org.apache.hadoop.yarn.server.resourcemanager.RMAuditLogger: USER=ubuntu	OPERATION=AM Released Container	TARGET=SchedulerApp	RESULT=SUCCESS	APPID=application_1377618433102_0001	CONTAINERID=container_1377618433102_0001_01_000002
2013-08-27 15:50:59,656 INFO org.apache.hadoop.yarn.server.resourcemanager.scheduler.common.fica.FiCaSchedulerNode: Released container container_1377618433102_0001_01_000002 of capacity <memory:1024, vCores:1> on host hadoop-8-3:42074, which currently has 0 containers, <memory:0, vCores:0> used and <memory:8192, vCores:16> available, release resources=true
2013-08-27 15:50:59,656 INFO org.apache.hadoop.yarn.server.resourcemanager.scheduler.capacity.LeafQueue: default used=<memory:3072, vCores:2> numContainers=2 user=ubuntu user-resources=<memory:3072, vCores:2>
2013-08-27 15:50:59,659 INFO org.apache.hadoop.yarn.server.resourcemanager.scheduler.capacity.LeafQueue: completedContainer container=Container: [ContainerId: container_1377618433102_0001_01_000002, NodeId: hadoop-8-3:42074, NodeHttpAddress: hadoop-8-3:8042, Resource: <memory:1024, vCores:1>, Priority: 20, State: NEW, Token: null, Status: container_id {, app_attempt_id {, application_id {, id: 1, cluster_timestamp: 1377618433102, }, attemptId: 1, }, id: 2, }, state: C_COMPLETE, diagnostics: "Container killed by the ApplicationMaster.\n\n", exit_status: 143, ] resource=<memory:1024, vCores:1> queue=default: capacity=1.0, absoluteCapacity=1.0, usedResources=<memory:3072, vCores:2>usedCapacity=0.0625, absoluteUsedCapacity=0.0625, numApps=1, numContainers=2 usedCapacity=0.0625 absoluteUsedCapacity=0.0625 used=<memory:3072, vCores:2> cluster=<memory:49152, vCores:96>
2013-08-27 15:50:59,659 INFO org.apache.hadoop.yarn.server.resourcemanager.scheduler.capacity.ParentQueue: completedContainer queue=root usedCapacity=0.0625 absoluteUsedCapacity=0.0625 used=<memory:3072, vCores:2> cluster=<memory:49152, vCores:96>
2013-08-27 15:50:59,659 INFO org.apache.hadoop.yarn.server.resourcemanager.scheduler.capacity.CapacityScheduler: Application appattempt_1377618433102_0001_000001 released container container_1377618433102_0001_01_000002 on node: host: hadoop-8-3:42074 #containers=0 available=8192 used=0 with event: FINISHED
2013-08-27 15:51:10,229 INFO org.apache.hadoop.yarn.server.resourcemanager.rmcontainer.RMContainerImpl: container_1377618433102_0001_01_000003 Container Transitioned from RUNNING to COMPLETED
2013-08-27 15:51:10,229 INFO org.apache.hadoop.yarn.server.resourcemanager.scheduler.common.fica.FiCaSchedulerApp: Completed container: container_1377618433102_0001_01_000003 in state: COMPLETED event:FINISHED
2013-08-27 15:51:10,230 INFO org.apache.hadoop.yarn.server.resourcemanager.RMAuditLogger: USER=ubuntu	OPERATION=AM Released Container	TARGET=SchedulerApp	RESULT=SUCCESS	APPID=application_1377618433102_0001	CONTAINERID=container_1377618433102_0001_01_000003
2013-08-27 15:51:10,230 INFO org.apache.hadoop.yarn.server.resourcemanager.scheduler.common.fica.FiCaSchedulerNode: Released container container_1377618433102_0001_01_000003 of capacity <memory:1024, vCores:1> on host hadoop-8-2:41932, which currently has 0 containers, <memory:0, vCores:0> used and <memory:8192, vCores:16> available, release resources=true
2013-08-27 15:51:10,230 INFO org.apache.hadoop.yarn.server.resourcemanager.scheduler.capacity.LeafQueue: default used=<memory:2048, vCores:1> numContainers=1 user=ubuntu user-resources=<memory:2048, vCores:1>
2013-08-27 15:51:10,232 INFO org.apache.hadoop.yarn.server.resourcemanager.scheduler.capacity.LeafQueue: completedContainer container=Container: [ContainerId: container_1377618433102_0001_01_000003, NodeId: hadoop-8-2:41932, NodeHttpAddress: hadoop-8-2:8042, Resource: <memory:1024, vCores:1>, Priority: 20, State: NEW, Token: null, Status: container_id {, app_attempt_id {, application_id {, id: 1, cluster_timestamp: 1377618433102, }, attemptId: 1, }, id: 3, }, state: C_COMPLETE, diagnostics: "Container killed by the ApplicationMaster.\n\n", exit_status: 143, ] resource=<memory:1024, vCores:1> queue=default: capacity=1.0, absoluteCapacity=1.0, usedResources=<memory:2048, vCores:1>usedCapacity=0.041666668, absoluteUsedCapacity=0.041666668, numApps=1, numContainers=1 usedCapacity=0.041666668 absoluteUsedCapacity=0.041666668 used=<memory:2048, vCores:1> cluster=<memory:49152, vCores:96>
2013-08-27 15:51:10,233 INFO org.apache.hadoop.yarn.server.resourcemanager.scheduler.capacity.ParentQueue: completedContainer queue=root usedCapacity=0.041666668 absoluteUsedCapacity=0.041666668 used=<memory:2048, vCores:1> cluster=<memory:49152, vCores:96>
2013-08-27 15:51:10,233 INFO org.apache.hadoop.yarn.server.resourcemanager.scheduler.capacity.CapacityScheduler: Application appattempt_1377618433102_0001_000001 released container container_1377618433102_0001_01_000003 on node: host: hadoop-8-2:41932 #containers=0 available=8192 used=0 with event: FINISHED
2013-08-27 15:51:14,417 INFO org.apache.hadoop.yarn.server.resourcemanager.rmapp.attempt.RMAppAttemptImpl: appattempt_1377618433102_0001_000001 State change from RUNNING to FINISHING
2013-08-27 15:51:14,418 INFO org.apache.hadoop.yarn.server.resourcemanager.rmapp.RMAppImpl: application_1377618433102_0001 State change from RUNNING to FINISHING
2013-08-27 15:51:15,641 INFO org.apache.hadoop.yarn.server.resourcemanager.rmcontainer.RMContainerImpl: container_1377618433102_0001_01_000001 Container Transitioned from RUNNING to COMPLETED
2013-08-27 15:51:15,641 INFO org.apache.hadoop.yarn.server.resourcemanager.scheduler.common.fica.FiCaSchedulerApp: Completed container: container_1377618433102_0001_01_000001 in state: COMPLETED event:FINISHED
2013-08-27 15:51:15,642 INFO org.apache.hadoop.yarn.server.resourcemanager.RMAuditLogger: USER=ubuntu	OPERATION=AM Released Container	TARGET=SchedulerApp	RESULT=SUCCESS	APPID=application_1377618433102_0001	CONTAINERID=container_1377618433102_0001_01_000001
2013-08-27 15:51:15,642 INFO org.apache.hadoop.yarn.server.resourcemanager.scheduler.common.fica.FiCaSchedulerNode: Released container container_1377618433102_0001_01_000001 of capacity <memory:2048, vCores:1> on host hadoop-8-4:36803, which currently has 0 containers, <memory:0, vCores:0> used and <memory:8192, vCores:16> available, release resources=true
2013-08-27 15:51:15,642 INFO org.apache.hadoop.yarn.server.resourcemanager.scheduler.capacity.LeafQueue: default used=<memory:0, vCores:0> numContainers=0 user=ubuntu user-resources=<memory:0, vCores:0>
2013-08-27 15:51:15,644 INFO org.apache.hadoop.yarn.server.resourcemanager.scheduler.capacity.LeafQueue: completedContainer container=Container: [ContainerId: container_1377618433102_0001_01_000001, NodeId: hadoop-8-4:36803, NodeHttpAddress: hadoop-8-4:8042, Resource: <memory:2048, vCores:1>, Priority: 0, State: NEW, Token: null, Status: container_id {, app_attempt_id {, application_id {, id: 1, cluster_timestamp: 1377618433102, }, attemptId: 1, }, id: 1, }, state: C_COMPLETE, diagnostics: "", exit_status: 0, ] resource=<memory:2048, vCores:1> queue=default: capacity=1.0, absoluteCapacity=1.0, usedResources=<memory:0, vCores:0>usedCapacity=0.0, absoluteUsedCapacity=0.0, numApps=1, numContainers=0 usedCapacity=0.0 absoluteUsedCapacity=0.0 used=<memory:0, vCores:0> cluster=<memory:49152, vCores:96>
2013-08-27 15:51:15,644 INFO org.apache.hadoop.yarn.server.resourcemanager.scheduler.capacity.ParentQueue: completedContainer queue=root usedCapacity=0.0 absoluteUsedCapacity=0.0 used=<memory:0, vCores:0> cluster=<memory:49152, vCores:96>
2013-08-27 15:51:15,644 INFO org.apache.hadoop.yarn.server.resourcemanager.scheduler.capacity.CapacityScheduler: Application appattempt_1377618433102_0001_000001 released container container_1377618433102_0001_01_000001 on node: host: hadoop-8-4:36803 #containers=0 available=8192 used=0 with event: FINISHED
2013-08-27 15:51:15,648 INFO org.apache.hadoop.yarn.server.resourcemanager.rmapp.attempt.RMAppAttemptImpl: appattempt_1377618433102_0001_000001 State change from FINISHING to FINISHED
2013-08-27 15:51:15,650 INFO org.apache.hadoop.yarn.server.resourcemanager.rmapp.RMAppImpl: application_1377618433102_0001 State change from FINISHING to FINISHED
2013-08-27 15:51:15,650 INFO org.apache.hadoop.yarn.server.resourcemanager.scheduler.capacity.CapacityScheduler: Application appattempt_1377618433102_0001_000001 is done. finalState=FINISHED
2013-08-27 15:51:15,651 INFO org.apache.hadoop.yarn.server.resourcemanager.scheduler.AppSchedulingInfo: Application application_1377618433102_0001 requests cleared
2013-08-27 15:51:15,652 INFO org.apache.hadoop.yarn.server.resourcemanager.scheduler.capacity.LeafQueue: Application removed - appId: application_1377618433102_0001 user: ubuntu queue: default #user-pending-applications: 0 #user-active-applications: 0 #queue-pending-applications: 0 #queue-active-applications: 0
2013-08-27 15:51:15,652 INFO org.apache.hadoop.yarn.server.resourcemanager.scheduler.capacity.ParentQueue: Application removed - appId: application_1377618433102_0001 user: ubuntu leaf-queue of parent: root #applications: 0
2013-08-27 15:51:15,653 INFO org.apache.hadoop.yarn.server.resourcemanager.RMAuditLogger: USER=ubuntu	OPERATION=Application Finished - Succeeded	TARGET=RMAppManager	RESULT=SUCCESS	APPID=application_1377618433102_0001
2013-08-27 15:51:15,671 INFO org.apache.hadoop.yarn.server.resourcemanager.recovery.RMStateStore: Removing info for app: application_1377618433102_0001
2013-08-27 15:51:15,674 INFO org.apache.hadoop.yarn.server.resourcemanager.RMAppManager$ApplicationSummary: appId=application_1377618433102_0001,name=TeraGen,user=ubuntu,queue=default,state=FINISHED,trackingUrl=hadoop-8-1.novalocal:8088/proxy/application_1377618433102_0001/jobhistory/job/job_1377618433102_0001,appMasterHost=hadoop-8-4,startTime=1377618477562,finishTime=1377618674418
2013-08-27 15:51:15,653 INFO org.apache.hadoop.yarn.server.resourcemanager.amlauncher.AMLauncher: Cleaning master appattempt_1377618433102_0001_000001
2013-08-27 15:51:15,956 INFO org.apache.hadoop.yarn.server.resourcemanager.ClientRMService: Allocated new applicationId: 2
2013-08-27 15:51:17,908 INFO org.apache.hadoop.yarn.server.resourcemanager.ClientRMService: Storing Application with id application_1377618433102_0002
2013-08-27 15:51:17,908 INFO org.apache.hadoop.yarn.server.resourcemanager.recovery.RMStateStore: Storing info for app: application_1377618433102_0002
2013-08-27 15:51:17,908 INFO org.apache.hadoop.yarn.server.resourcemanager.ClientRMService: Application with id 2 submitted by user ubuntu
2013-08-27 15:51:17,908 INFO org.apache.hadoop.yarn.server.resourcemanager.RMAuditLogger: USER=ubuntu	IP=192.168.100.15	OPERATION=Submit Application Request	TARGET=ClientRMService	RESULT=SUCCESS	APPID=application_1377618433102_0002
2013-08-27 15:51:17,910 INFO org.apache.hadoop.yarn.server.resourcemanager.rmapp.RMAppImpl: application_1377618433102_0002 State change from NEW to SUBMITTED
2013-08-27 15:51:17,911 INFO org.apache.hadoop.yarn.server.resourcemanager.ApplicationMasterService: Registering appattempt_1377618433102_0002_000001
2013-08-27 15:51:17,912 INFO org.apache.hadoop.yarn.server.resourcemanager.rmapp.attempt.RMAppAttemptImpl: appattempt_1377618433102_0002_000001 State change from NEW to SUBMITTED
2013-08-27 15:51:17,912 INFO org.apache.hadoop.yarn.server.resourcemanager.scheduler.capacity.LeafQueue: Application application_1377618433102_0002 from user: ubuntu activated in queue: default
2013-08-27 15:51:17,912 INFO org.apache.hadoop.yarn.server.resourcemanager.scheduler.capacity.LeafQueue: Application added - appId: application_1377618433102_0002 user: org.apache.hadoop.yarn.server.resourcemanager.scheduler.capacity.LeafQueue$User@f866d49, leaf-queue: default #user-pending-applications: 0 #user-active-applications: 1 #queue-pending-applications: 0 #queue-active-applications: 1
2013-08-27 15:51:17,913 INFO org.apache.hadoop.yarn.server.resourcemanager.scheduler.capacity.ParentQueue: Application added - appId: application_1377618433102_0002 user: ubuntu leaf-queue of parent: root #applications: 1
2013-08-27 15:51:17,913 INFO org.apache.hadoop.yarn.server.resourcemanager.scheduler.capacity.CapacityScheduler: Application Submission: appattempt_1377618433102_0002_000001, user: ubuntu queue: default: capacity=1.0, absoluteCapacity=1.0, usedResources=<memory:0, vCores:0>usedCapacity=0.0, absoluteUsedCapacity=0.0, numApps=1, numContainers=0, currently active: 1
2013-08-27 15:51:17,913 INFO org.apache.hadoop.yarn.server.resourcemanager.rmapp.attempt.RMAppAttemptImpl: appattempt_1377618433102_0002_000001 State change from SUBMITTED to SCHEDULED
2013-08-27 15:51:17,914 INFO org.apache.hadoop.yarn.server.resourcemanager.rmapp.RMAppImpl: application_1377618433102_0002 State change from SUBMITTED to ACCEPTED
2013-08-27 15:51:18,265 INFO org.apache.hadoop.yarn.server.resourcemanager.rmcontainer.RMContainerImpl: container_1377618433102_0002_01_000001 Container Transitioned from NEW to ALLOCATED
2013-08-27 15:51:18,265 INFO org.apache.hadoop.yarn.server.resourcemanager.RMAuditLogger: USER=ubuntu	OPERATION=AM Allocated Container	TARGET=SchedulerApp	RESULT=SUCCESS	APPID=application_1377618433102_0002	CONTAINERID=container_1377618433102_0002_01_000001
2013-08-27 15:51:18,265 INFO org.apache.hadoop.yarn.server.resourcemanager.scheduler.common.fica.FiCaSchedulerNode: Assigned container container_1377618433102_0002_01_000001 of capacity <memory:2048, vCores:1> on host hadoop-8-2:41932, which currently has 1 containers, <memory:2048, vCores:1> used and <memory:6144, vCores:15> available
2013-08-27 15:51:18,267 INFO org.apache.hadoop.yarn.server.resourcemanager.scheduler.capacity.LeafQueue: assignedContainer application=application_1377618433102_0002 container=Container: [ContainerId: container_1377618433102_0002_01_000001, NodeId: hadoop-8-2:41932, NodeHttpAddress: hadoop-8-2:8042, Resource: <memory:2048, vCores:1>, Priority: 0, State: NEW, Token: null, Status: container_id {, app_attempt_id {, application_id {, id: 2, cluster_timestamp: 1377618433102, }, attemptId: 1, }, id: 1, }, state: C_NEW, ] containerId=container_1377618433102_0002_01_000001 queue=default: capacity=1.0, absoluteCapacity=1.0, usedResources=<memory:0, vCores:0>usedCapacity=0.0, absoluteUsedCapacity=0.0, numApps=1, numContainers=0 usedCapacity=0.0 absoluteUsedCapacity=0.0 used=<memory:0, vCores:0> cluster=<memory:49152, vCores:96>
2013-08-27 15:51:18,268 INFO org.apache.hadoop.yarn.server.resourcemanager.scheduler.capacity.ParentQueue: Re-sorting queues since queue: root.default stats: default: capacity=1.0, absoluteCapacity=1.0, usedResources=<memory:2048, vCores:1>usedCapacity=0.041666668, absoluteUsedCapacity=0.041666668, numApps=1, numContainers=1
2013-08-27 15:51:18,269 INFO org.apache.hadoop.yarn.server.resourcemanager.scheduler.capacity.ParentQueue: assignedContainer queue=root usedCapacity=0.041666668 absoluteUsedCapacity=0.041666668 used=<memory:2048, vCores:1> cluster=<memory:49152, vCores:96>
2013-08-27 15:51:18,270 INFO org.apache.hadoop.yarn.server.resourcemanager.rmcontainer.RMContainerImpl: container_1377618433102_0002_01_000001 Container Transitioned from ALLOCATED to ACQUIRED
2013-08-27 15:51:18,272 INFO org.apache.hadoop.yarn.server.resourcemanager.rmapp.attempt.RMAppAttemptImpl: Storing attempt: AppId: application_1377618433102_0002 AttemptId: appattempt_1377618433102_0002_000001 MasterContainer: Container: [ContainerId: container_1377618433102_0002_01_000001, NodeId: hadoop-8-2:41932, NodeHttpAddress: hadoop-8-2:8042, Resource: <memory:2048, vCores:1>, Priority: 0, State: NEW, Token: null, Status: container_id {, app_attempt_id {, application_id {, id: 2, cluster_timestamp: 1377618433102, }, attemptId: 1, }, id: 1, }, state: C_NEW, ]
2013-08-27 15:51:18,272 INFO org.apache.hadoop.yarn.server.resourcemanager.rmapp.attempt.RMAppAttemptImpl: appattempt_1377618433102_0002_000001 State change from SCHEDULED to ALLOCATED_SAVING
2013-08-27 15:51:18,272 INFO org.apache.hadoop.yarn.server.resourcemanager.recovery.RMStateStore: Storing info for attempt: appattempt_1377618433102_0002_000001
2013-08-27 15:51:18,276 INFO org.apache.hadoop.yarn.server.resourcemanager.rmapp.attempt.RMAppAttemptImpl: appattempt_1377618433102_0002_000001 State change from ALLOCATED_SAVING to ALLOCATED
2013-08-27 15:51:18,278 INFO org.apache.hadoop.yarn.server.resourcemanager.amlauncher.AMLauncher: Launching masterappattempt_1377618433102_0002_000001
2013-08-27 15:51:18,281 INFO org.apache.hadoop.yarn.server.resourcemanager.amlauncher.AMLauncher: Setting up container Container: [ContainerId: container_1377618433102_0002_01_000001, NodeId: hadoop-8-2:41932, NodeHttpAddress: hadoop-8-2:8042, Resource: <memory:2048, vCores:1>, Priority: 0, State: NEW, Token: null, Status: container_id {, app_attempt_id {, application_id {, id: 2, cluster_timestamp: 1377618433102, }, attemptId: 1, }, id: 1, }, state: C_NEW, ] for AM appattempt_1377618433102_0002_000001
2013-08-27 15:51:18,281 INFO org.apache.hadoop.yarn.server.resourcemanager.amlauncher.AMLauncher: Command to launch container container_1377618433102_0002_01_000001 : $JAVA_HOME/bin/java -Dlog4j.configuration=container-log4j.properties -Dyarn.app.mapreduce.container.log.dir=<LOG_DIR> -Dyarn.app.mapreduce.container.log.filesize=0 -Dhadoop.root.logger=INFO,CLA  -Xmx1024m org.apache.hadoop.mapreduce.v2.app.MRAppMaster 1><LOG_DIR>/stdout 2><LOG_DIR>/stderr 
2013-08-27 15:51:18,295 INFO org.apache.hadoop.yarn.server.resourcemanager.amlauncher.AMLauncher: Done launching container Container: [ContainerId: container_1377618433102_0002_01_000001, NodeId: hadoop-8-2:41932, NodeHttpAddress: hadoop-8-2:8042, Resource: <memory:2048, vCores:1>, Priority: 0, State: NEW, Token: null, Status: container_id {, app_attempt_id {, application_id {, id: 2, cluster_timestamp: 1377618433102, }, attemptId: 1, }, id: 1, }, state: C_NEW, ] for AM appattempt_1377618433102_0002_000001
2013-08-27 15:51:18,296 INFO org.apache.hadoop.yarn.server.resourcemanager.rmapp.attempt.RMAppAttemptImpl: appattempt_1377618433102_0002_000001 State change from ALLOCATED to LAUNCHED
2013-08-27 15:51:19,271 INFO org.apache.hadoop.yarn.server.resourcemanager.rmcontainer.RMContainerImpl: container_1377618433102_0002_01_000001 Container Transitioned from ACQUIRED to RUNNING
2013-08-27 15:51:25,682 INFO org.apache.hadoop.yarn.server.resourcemanager.ApplicationMasterService: AM registration appattempt_1377618433102_0002_000001
2013-08-27 15:51:25,682 INFO org.apache.hadoop.yarn.server.resourcemanager.RMAuditLogger: USER=ubuntu	IP=192.168.100.17	OPERATION=Register App Master	TARGET=ApplicationMasterService	RESULT=SUCCESS	APPID=application_1377618433102_0002	APPATTEMPTID=appattempt_1377618433102_0002_000001
2013-08-27 15:51:25,685 INFO org.apache.hadoop.yarn.server.resourcemanager.rmapp.attempt.RMAppAttemptImpl: appattempt_1377618433102_0002_000001 State change from LAUNCHED to RUNNING
2013-08-27 15:51:25,685 INFO org.apache.hadoop.yarn.server.resourcemanager.rmapp.RMAppImpl: application_1377618433102_0002 State change from ACCEPTED to RUNNING
2013-08-27 15:51:27,320 INFO org.apache.hadoop.yarn.server.resourcemanager.rmcontainer.RMContainerImpl: container_1377618433102_0002_01_000002 Container Transitioned from NEW to ALLOCATED
2013-08-27 15:51:27,320 INFO org.apache.hadoop.yarn.server.resourcemanager.RMAuditLogger: USER=ubuntu	OPERATION=AM Allocated Container	TARGET=SchedulerApp	RESULT=SUCCESS	APPID=application_1377618433102_0002	CONTAINERID=container_1377618433102_0002_01_000002
2013-08-27 15:51:27,321 INFO org.apache.hadoop.yarn.server.resourcemanager.scheduler.common.fica.FiCaSchedulerNode: Assigned container container_1377618433102_0002_01_000002 of capacity <memory:1024, vCores:1> on host hadoop-8-2:41932, which currently has 2 containers, <memory:3072, vCores:2> used and <memory:5120, vCores:14> available
2013-08-27 15:51:27,322 INFO org.apache.hadoop.yarn.server.resourcemanager.scheduler.capacity.LeafQueue: assignedContainer application=application_1377618433102_0002 container=Container: [ContainerId: container_1377618433102_0002_01_000002, NodeId: hadoop-8-2:41932, NodeHttpAddress: hadoop-8-2:8042, Resource: <memory:1024, vCores:1>, Priority: 20, State: NEW, Token: null, Status: container_id {, app_attempt_id {, application_id {, id: 2, cluster_timestamp: 1377618433102, }, attemptId: 1, }, id: 2, }, state: C_NEW, ] containerId=container_1377618433102_0002_01_000002 queue=default: capacity=1.0, absoluteCapacity=1.0, usedResources=<memory:2048, vCores:1>usedCapacity=0.041666668, absoluteUsedCapacity=0.041666668, numApps=1, numContainers=1 usedCapacity=0.041666668 absoluteUsedCapacity=0.041666668 used=<memory:2048, vCores:1> cluster=<memory:49152, vCores:96>
2013-08-27 15:51:27,323 INFO org.apache.hadoop.yarn.server.resourcemanager.scheduler.capacity.ParentQueue: Re-sorting queues since queue: root.default stats: default: capacity=1.0, absoluteCapacity=1.0, usedResources=<memory:3072, vCores:2>usedCapacity=0.0625, absoluteUsedCapacity=0.0625, numApps=1, numContainers=2
2013-08-27 15:51:27,323 INFO org.apache.hadoop.yarn.server.resourcemanager.scheduler.capacity.ParentQueue: assignedContainer queue=root usedCapacity=0.0625 absoluteUsedCapacity=0.0625 used=<memory:3072, vCores:2> cluster=<memory:49152, vCores:96>
2013-08-27 15:51:27,351 INFO org.apache.hadoop.yarn.server.resourcemanager.rmcontainer.RMContainerImpl: container_1377618433102_0002_01_000003 Container Transitioned from NEW to ALLOCATED
2013-08-27 15:51:27,351 INFO org.apache.hadoop.yarn.server.resourcemanager.RMAuditLogger: USER=ubuntu	OPERATION=AM Allocated Container	TARGET=SchedulerApp	RESULT=SUCCESS	APPID=application_1377618433102_0002	CONTAINERID=container_1377618433102_0002_01_000003
2013-08-27 15:51:27,351 INFO org.apache.hadoop.yarn.server.resourcemanager.scheduler.common.fica.FiCaSchedulerNode: Assigned container container_1377618433102_0002_01_000003 of capacity <memory:1024, vCores:1> on host hadoop-8-5:56487, which currently has 1 containers, <memory:1024, vCores:1> used and <memory:7168, vCores:15> available
2013-08-27 15:51:27,353 INFO org.apache.hadoop.yarn.server.resourcemanager.scheduler.capacity.LeafQueue: assignedContainer application=application_1377618433102_0002 container=Container: [ContainerId: container_1377618433102_0002_01_000003, NodeId: hadoop-8-5:56487, NodeHttpAddress: hadoop-8-5:8042, Resource: <memory:1024, vCores:1>, Priority: 20, State: NEW, Token: null, Status: container_id {, app_attempt_id {, application_id {, id: 2, cluster_timestamp: 1377618433102, }, attemptId: 1, }, id: 3, }, state: C_NEW, ] containerId=container_1377618433102_0002_01_000003 queue=default: capacity=1.0, absoluteCapacity=1.0, usedResources=<memory:3072, vCores:2>usedCapacity=0.0625, absoluteUsedCapacity=0.0625, numApps=1, numContainers=2 usedCapacity=0.0625 absoluteUsedCapacity=0.0625 used=<memory:3072, vCores:2> cluster=<memory:49152, vCores:96>
2013-08-27 15:51:27,353 INFO org.apache.hadoop.yarn.server.resourcemanager.scheduler.capacity.ParentQueue: Re-sorting queues since queue: root.default stats: default: capacity=1.0, absoluteCapacity=1.0, usedResources=<memory:4096, vCores:3>usedCapacity=0.083333336, absoluteUsedCapacity=0.083333336, numApps=1, numContainers=3
2013-08-27 15:51:27,353 INFO org.apache.hadoop.yarn.server.resourcemanager.scheduler.capacity.ParentQueue: assignedContainer queue=root usedCapacity=0.083333336 absoluteUsedCapacity=0.083333336 used=<memory:4096, vCores:3> cluster=<memory:49152, vCores:96>
2013-08-27 15:51:27,822 INFO org.apache.hadoop.yarn.server.resourcemanager.rmcontainer.RMContainerImpl: container_1377618433102_0002_01_000002 Container Transitioned from ALLOCATED to ACQUIRED
2013-08-27 15:51:27,824 INFO org.apache.hadoop.yarn.server.resourcemanager.rmcontainer.RMContainerImpl: container_1377618433102_0002_01_000003 Container Transitioned from ALLOCATED to ACQUIRED
2013-08-27 15:51:28,326 INFO org.apache.hadoop.yarn.server.resourcemanager.rmcontainer.RMContainerImpl: container_1377618433102_0002_01_000002 Container Transitioned from ACQUIRED to RUNNING
2013-08-27 15:51:28,858 INFO org.apache.hadoop.yarn.server.resourcemanager.scheduler.AppSchedulingInfo: checking for deactivate... 
2013-08-27 15:51:29,489 INFO org.apache.hadoop.yarn.server.resourcemanager.rmcontainer.RMContainerImpl: container_1377618433102_0002_01_000003 Container Transitioned from ACQUIRED to RUNNING
2013-08-27 15:54:21,122 INFO org.apache.hadoop.yarn.server.resourcemanager.rmcontainer.RMContainerImpl: container_1377618433102_0002_01_000003 Container Transitioned from RUNNING to COMPLETED
2013-08-27 15:54:21,122 INFO org.apache.hadoop.yarn.server.resourcemanager.scheduler.common.fica.FiCaSchedulerApp: Completed container: container_1377618433102_0002_01_000003 in state: COMPLETED event:FINISHED
2013-08-27 15:54:21,122 INFO org.apache.hadoop.yarn.server.resourcemanager.RMAuditLogger: USER=ubuntu	OPERATION=AM Released Container	TARGET=SchedulerApp	RESULT=SUCCESS	APPID=application_1377618433102_0002	CONTAINERID=container_1377618433102_0002_01_000003
2013-08-27 15:54:21,122 INFO org.apache.hadoop.yarn.server.resourcemanager.scheduler.common.fica.FiCaSchedulerNode: Released container container_1377618433102_0002_01_000003 of capacity <memory:1024, vCores:1> on host hadoop-8-5:56487, which currently has 0 containers, <memory:0, vCores:0> used and <memory:8192, vCores:16> available, release resources=true
2013-08-27 15:54:21,122 INFO org.apache.hadoop.yarn.server.resourcemanager.scheduler.capacity.LeafQueue: default used=<memory:3072, vCores:2> numContainers=2 user=ubuntu user-resources=<memory:3072, vCores:2>
2013-08-27 15:54:21,136 INFO org.apache.hadoop.yarn.server.resourcemanager.scheduler.capacity.LeafQueue: completedContainer container=Container: [ContainerId: container_1377618433102_0002_01_000003, NodeId: hadoop-8-5:56487, NodeHttpAddress: hadoop-8-5:8042, Resource: <memory:1024, vCores:1>, Priority: 20, State: NEW, Token: null, Status: container_id {, app_attempt_id {, application_id {, id: 2, cluster_timestamp: 1377618433102, }, attemptId: 1, }, id: 3, }, state: C_COMPLETE, diagnostics: "Container killed by the ApplicationMaster.\n\n", exit_status: 143, ] resource=<memory:1024, vCores:1> queue=default: capacity=1.0, absoluteCapacity=1.0, usedResources=<memory:3072, vCores:2>usedCapacity=0.0625, absoluteUsedCapacity=0.0625, numApps=1, numContainers=2 usedCapacity=0.0625 absoluteUsedCapacity=0.0625 used=<memory:3072, vCores:2> cluster=<memory:49152, vCores:96>
2013-08-27 15:54:21,136 INFO org.apache.hadoop.yarn.server.resourcemanager.scheduler.capacity.ParentQueue: completedContainer queue=root usedCapacity=0.0625 absoluteUsedCapacity=0.0625 used=<memory:3072, vCores:2> cluster=<memory:49152, vCores:96>
2013-08-27 15:54:21,137 INFO org.apache.hadoop.yarn.server.resourcemanager.scheduler.capacity.CapacityScheduler: Application appattempt_1377618433102_0002_000001 released container container_1377618433102_0002_01_000003 on node: host: hadoop-8-5:56487 #containers=0 available=8192 used=0 with event: FINISHED
2013-08-27 15:54:26,325 INFO org.apache.hadoop.yarn.server.resourcemanager.rmcontainer.RMContainerImpl: container_1377618433102_0002_01_000002 Container Transitioned from RUNNING to COMPLETED
2013-08-27 15:54:26,325 INFO org.apache.hadoop.yarn.server.resourcemanager.scheduler.common.fica.FiCaSchedulerApp: Completed container: container_1377618433102_0002_01_000002 in state: COMPLETED event:FINISHED
2013-08-27 15:54:26,325 INFO org.apache.hadoop.yarn.server.resourcemanager.RMAuditLogger: USER=ubuntu	OPERATION=AM Released Container	TARGET=SchedulerApp	RESULT=SUCCESS	APPID=application_1377618433102_0002	CONTAINERID=container_1377618433102_0002_01_000002
2013-08-27 15:54:26,326 INFO org.apache.hadoop.yarn.server.resourcemanager.scheduler.common.fica.FiCaSchedulerNode: Released container container_1377618433102_0002_01_000002 of capacity <memory:1024, vCores:1> on host hadoop-8-2:41932, which currently has 1 containers, <memory:2048, vCores:1> used and <memory:6144, vCores:15> available, release resources=true
2013-08-27 15:54:26,326 INFO org.apache.hadoop.yarn.server.resourcemanager.scheduler.capacity.LeafQueue: default used=<memory:2048, vCores:1> numContainers=1 user=ubuntu user-resources=<memory:2048, vCores:1>
2013-08-27 15:54:26,328 INFO org.apache.hadoop.yarn.server.resourcemanager.scheduler.capacity.LeafQueue: completedContainer container=Container: [ContainerId: container_1377618433102_0002_01_000002, NodeId: hadoop-8-2:41932, NodeHttpAddress: hadoop-8-2:8042, Resource: <memory:1024, vCores:1>, Priority: 20, State: NEW, Token: null, Status: container_id {, app_attempt_id {, application_id {, id: 2, cluster_timestamp: 1377618433102, }, attemptId: 1, }, id: 2, }, state: C_COMPLETE, diagnostics: "Container killed by the ApplicationMaster.\n", exit_status: 0, ] resource=<memory:1024, vCores:1> queue=default: capacity=1.0, absoluteCapacity=1.0, usedResources=<memory:2048, vCores:1>usedCapacity=0.041666668, absoluteUsedCapacity=0.041666668, numApps=1, numContainers=1 usedCapacity=0.041666668 absoluteUsedCapacity=0.041666668 used=<memory:2048, vCores:1> cluster=<memory:49152, vCores:96>
2013-08-27 15:54:26,328 INFO org.apache.hadoop.yarn.server.resourcemanager.scheduler.capacity.ParentQueue: completedContainer queue=root usedCapacity=0.041666668 absoluteUsedCapacity=0.041666668 used=<memory:2048, vCores:1> cluster=<memory:49152, vCores:96>
2013-08-27 15:54:26,329 INFO org.apache.hadoop.yarn.server.resourcemanager.scheduler.capacity.CapacityScheduler: Application appattempt_1377618433102_0002_000001 released container container_1377618433102_0002_01_000002 on node: host: hadoop-8-2:41932 #containers=1 available=6144 used=2048 with event: FINISHED
2013-08-27 15:54:30,249 INFO org.apache.hadoop.yarn.server.resourcemanager.rmapp.attempt.RMAppAttemptImpl: appattempt_1377618433102_0002_000001 State change from RUNNING to FINISHING
2013-08-27 15:54:30,250 INFO org.apache.hadoop.yarn.server.resourcemanager.rmapp.RMAppImpl: application_1377618433102_0002 State change from RUNNING to FINISHING
2013-08-27 15:54:31,348 INFO org.apache.hadoop.yarn.server.resourcemanager.rmcontainer.RMContainerImpl: container_1377618433102_0002_01_000001 Container Transitioned from RUNNING to COMPLETED
2013-08-27 15:54:31,348 INFO org.apache.hadoop.yarn.server.resourcemanager.scheduler.common.fica.FiCaSchedulerApp: Completed container: container_1377618433102_0002_01_000001 in state: COMPLETED event:FINISHED
2013-08-27 15:54:31,349 INFO org.apache.hadoop.yarn.server.resourcemanager.RMAuditLogger: USER=ubuntu	OPERATION=AM Released Container	TARGET=SchedulerApp	RESULT=SUCCESS	APPID=application_1377618433102_0002	CONTAINERID=container_1377618433102_0002_01_000001
2013-08-27 15:54:31,349 INFO org.apache.hadoop.yarn.server.resourcemanager.scheduler.common.fica.FiCaSchedulerNode: Released container container_1377618433102_0002_01_000001 of capacity <memory:2048, vCores:1> on host hadoop-8-2:41932, which currently has 0 containers, <memory:0, vCores:0> used and <memory:8192, vCores:16> available, release resources=true
2013-08-27 15:54:31,349 INFO org.apache.hadoop.yarn.server.resourcemanager.scheduler.capacity.LeafQueue: default used=<memory:0, vCores:0> numContainers=0 user=ubuntu user-resources=<memory:0, vCores:0>
2013-08-27 15:54:31,351 INFO org.apache.hadoop.yarn.server.resourcemanager.scheduler.capacity.LeafQueue: completedContainer container=Container: [ContainerId: container_1377618433102_0002_01_000001, NodeId: hadoop-8-2:41932, NodeHttpAddress: hadoop-8-2:8042, Resource: <memory:2048, vCores:1>, Priority: 0, State: NEW, Token: null, Status: container_id {, app_attempt_id {, application_id {, id: 2, cluster_timestamp: 1377618433102, }, attemptId: 1, }, id: 1, }, state: C_COMPLETE, diagnostics: "", exit_status: 0, ] resource=<memory:2048, vCores:1> queue=default: capacity=1.0, absoluteCapacity=1.0, usedResources=<memory:0, vCores:0>usedCapacity=0.0, absoluteUsedCapacity=0.0, numApps=1, numContainers=0 usedCapacity=0.0 absoluteUsedCapacity=0.0 used=<memory:0, vCores:0> cluster=<memory:49152, vCores:96>
2013-08-27 15:54:31,351 INFO org.apache.hadoop.yarn.server.resourcemanager.scheduler.capacity.ParentQueue: completedContainer queue=root usedCapacity=0.0 absoluteUsedCapacity=0.0 used=<memory:0, vCores:0> cluster=<memory:49152, vCores:96>
2013-08-27 15:54:31,351 INFO org.apache.hadoop.yarn.server.resourcemanager.scheduler.capacity.CapacityScheduler: Application appattempt_1377618433102_0002_000001 released container container_1377618433102_0002_01_000001 on node: host: hadoop-8-2:41932 #containers=0 available=8192 used=0 with event: FINISHED
2013-08-27 15:54:31,351 INFO org.apache.hadoop.yarn.server.resourcemanager.rmapp.attempt.RMAppAttemptImpl: appattempt_1377618433102_0002_000001 State change from FINISHING to FINISHED
2013-08-27 15:54:31,355 INFO org.apache.hadoop.yarn.server.resourcemanager.rmapp.RMAppImpl: application_1377618433102_0002 State change from FINISHING to FINISHED
2013-08-27 15:54:31,355 INFO org.apache.hadoop.yarn.server.resourcemanager.scheduler.capacity.CapacityScheduler: Application appattempt_1377618433102_0002_000001 is done. finalState=FINISHED
2013-08-27 15:54:31,356 INFO org.apache.hadoop.yarn.server.resourcemanager.scheduler.AppSchedulingInfo: Application application_1377618433102_0002 requests cleared
2013-08-27 15:54:31,356 INFO org.apache.hadoop.yarn.server.resourcemanager.scheduler.capacity.LeafQueue: Application removed - appId: application_1377618433102_0002 user: ubuntu queue: default #user-pending-applications: 0 #user-active-applications: 0 #queue-pending-applications: 0 #queue-active-applications: 0
2013-08-27 15:54:31,356 INFO org.apache.hadoop.yarn.server.resourcemanager.scheduler.capacity.ParentQueue: Application removed - appId: application_1377618433102_0002 user: ubuntu leaf-queue of parent: root #applications: 0
2013-08-27 15:54:31,356 INFO org.apache.hadoop.yarn.server.resourcemanager.RMAuditLogger: USER=ubuntu	OPERATION=Application Finished - Succeeded	TARGET=RMAppManager	RESULT=SUCCESS	APPID=application_1377618433102_0002
2013-08-27 15:54:31,357 INFO org.apache.hadoop.yarn.server.resourcemanager.amlauncher.AMLauncher: Cleaning master appattempt_1377618433102_0002_000001
2013-08-27 15:54:31,357 INFO org.apache.hadoop.yarn.server.resourcemanager.recovery.RMStateStore: Removing info for app: application_1377618433102_0002
2013-08-27 15:54:31,357 INFO org.apache.hadoop.yarn.server.resourcemanager.RMAppManager$ApplicationSummary: appId=application_1377618433102_0002,name=TeraGen,user=ubuntu,queue=default,state=FINISHED,trackingUrl=hadoop-8-1.novalocal:8088/proxy/application_1377618433102_0002/jobhistory/job/job_1377618433102_0002,appMasterHost=hadoop-8-2,startTime=1377618677907,finishTime=1377618870250
2013-08-27 15:54:31,961 INFO org.apache.hadoop.yarn.server.resourcemanager.ClientRMService: Allocated new applicationId: 3
2013-08-27 15:54:33,768 INFO org.apache.hadoop.yarn.server.resourcemanager.ClientRMService: Storing Application with id application_1377618433102_0003
2013-08-27 15:54:33,768 INFO org.apache.hadoop.yarn.server.resourcemanager.recovery.RMStateStore: Storing info for app: application_1377618433102_0003
2013-08-27 15:54:33,769 INFO org.apache.hadoop.yarn.server.resourcemanager.ClientRMService: Application with id 3 submitted by user ubuntu
2013-08-27 15:54:33,769 INFO org.apache.hadoop.yarn.server.resourcemanager.RMAuditLogger: USER=ubuntu	IP=192.168.100.15	OPERATION=Submit Application Request	TARGET=ClientRMService	RESULT=SUCCESS	APPID=application_1377618433102_0003
2013-08-27 15:54:33,770 INFO org.apache.hadoop.yarn.server.resourcemanager.rmapp.RMAppImpl: application_1377618433102_0003 State change from NEW to SUBMITTED
2013-08-27 15:54:33,771 INFO org.apache.hadoop.yarn.server.resourcemanager.ApplicationMasterService: Registering appattempt_1377618433102_0003_000001
2013-08-27 15:54:33,771 INFO org.apache.hadoop.yarn.server.resourcemanager.rmapp.attempt.RMAppAttemptImpl: appattempt_1377618433102_0003_000001 State change from NEW to SUBMITTED
2013-08-27 15:54:33,771 INFO org.apache.hadoop.yarn.server.resourcemanager.scheduler.capacity.LeafQueue: Application application_1377618433102_0003 from user: ubuntu activated in queue: default
2013-08-27 15:54:33,772 INFO org.apache.hadoop.yarn.server.resourcemanager.scheduler.capacity.LeafQueue: Application added - appId: application_1377618433102_0003 user: org.apache.hadoop.yarn.server.resourcemanager.scheduler.capacity.LeafQueue$User@66629978, leaf-queue: default #user-pending-applications: 0 #user-active-applications: 1 #queue-pending-applications: 0 #queue-active-applications: 1
2013-08-27 15:54:33,772 INFO org.apache.hadoop.yarn.server.resourcemanager.scheduler.capacity.ParentQueue: Application added - appId: application_1377618433102_0003 user: ubuntu leaf-queue of parent: root #applications: 1
2013-08-27 15:54:33,772 INFO org.apache.hadoop.yarn.server.resourcemanager.scheduler.capacity.CapacityScheduler: Application Submission: appattempt_1377618433102_0003_000001, user: ubuntu queue: default: capacity=1.0, absoluteCapacity=1.0, usedResources=<memory:0, vCores:0>usedCapacity=0.0, absoluteUsedCapacity=0.0, numApps=1, numContainers=0, currently active: 1
2013-08-27 15:54:33,773 INFO org.apache.hadoop.yarn.server.resourcemanager.rmapp.attempt.RMAppAttemptImpl: appattempt_1377618433102_0003_000001 State change from SUBMITTED to SCHEDULED
2013-08-27 15:54:33,773 INFO org.apache.hadoop.yarn.server.resourcemanager.rmapp.RMAppImpl: application_1377618433102_0003 State change from SUBMITTED to ACCEPTED
2013-08-27 15:54:34,036 INFO org.apache.hadoop.yarn.server.resourcemanager.rmcontainer.RMContainerImpl: container_1377618433102_0003_01_000001 Container Transitioned from NEW to ALLOCATED
2013-08-27 15:54:34,036 INFO org.apache.hadoop.yarn.server.resourcemanager.RMAuditLogger: USER=ubuntu	OPERATION=AM Allocated Container	TARGET=SchedulerApp	RESULT=SUCCESS	APPID=application_1377618433102_0003	CONTAINERID=container_1377618433102_0003_01_000001
2013-08-27 15:54:34,036 INFO org.apache.hadoop.yarn.server.resourcemanager.scheduler.common.fica.FiCaSchedulerNode: Assigned container container_1377618433102_0003_01_000001 of capacity <memory:2048, vCores:1> on host hadoop-8-3:42074, which currently has 1 containers, <memory:2048, vCores:1> used and <memory:6144, vCores:15> available
2013-08-27 15:54:34,038 INFO org.apache.hadoop.yarn.server.resourcemanager.scheduler.capacity.LeafQueue: assignedContainer application=application_1377618433102_0003 container=Container: [ContainerId: container_1377618433102_0003_01_000001, NodeId: hadoop-8-3:42074, NodeHttpAddress: hadoop-8-3:8042, Resource: <memory:2048, vCores:1>, Priority: 0, State: NEW, Token: null, Status: container_id {, app_attempt_id {, application_id {, id: 3, cluster_timestamp: 1377618433102, }, attemptId: 1, }, id: 1, }, state: C_NEW, ] containerId=container_1377618433102_0003_01_000001 queue=default: capacity=1.0, absoluteCapacity=1.0, usedResources=<memory:0, vCores:0>usedCapacity=0.0, absoluteUsedCapacity=0.0, numApps=1, numContainers=0 usedCapacity=0.0 absoluteUsedCapacity=0.0 used=<memory:0, vCores:0> cluster=<memory:49152, vCores:96>
2013-08-27 15:54:34,038 INFO org.apache.hadoop.yarn.server.resourcemanager.scheduler.capacity.ParentQueue: Re-sorting queues since queue: root.default stats: default: capacity=1.0, absoluteCapacity=1.0, usedResources=<memory:2048, vCores:1>usedCapacity=0.041666668, absoluteUsedCapacity=0.041666668, numApps=1, numContainers=1
2013-08-27 15:54:34,038 INFO org.apache.hadoop.yarn.server.resourcemanager.scheduler.capacity.ParentQueue: assignedContainer queue=root usedCapacity=0.041666668 absoluteUsedCapacity=0.041666668 used=<memory:2048, vCores:1> cluster=<memory:49152, vCores:96>
2013-08-27 15:54:34,040 INFO org.apache.hadoop.yarn.server.resourcemanager.rmcontainer.RMContainerImpl: container_1377618433102_0003_01_000001 Container Transitioned from ALLOCATED to ACQUIRED
2013-08-27 15:54:34,042 INFO org.apache.hadoop.yarn.server.resourcemanager.rmapp.attempt.RMAppAttemptImpl: Storing attempt: AppId: application_1377618433102_0003 AttemptId: appattempt_1377618433102_0003_000001 MasterContainer: Container: [ContainerId: container_1377618433102_0003_01_000001, NodeId: hadoop-8-3:42074, NodeHttpAddress: hadoop-8-3:8042, Resource: <memory:2048, vCores:1>, Priority: 0, State: NEW, Token: null, Status: container_id {, app_attempt_id {, application_id {, id: 3, cluster_timestamp: 1377618433102, }, attemptId: 1, }, id: 1, }, state: C_NEW, ]
2013-08-27 15:54:34,042 INFO org.apache.hadoop.yarn.server.resourcemanager.rmapp.attempt.RMAppAttemptImpl: appattempt_1377618433102_0003_000001 State change from SCHEDULED to ALLOCATED_SAVING
2013-08-27 15:54:34,043 INFO org.apache.hadoop.yarn.server.resourcemanager.recovery.RMStateStore: Storing info for attempt: appattempt_1377618433102_0003_000001
2013-08-27 15:54:34,044 INFO org.apache.hadoop.yarn.server.resourcemanager.rmapp.attempt.RMAppAttemptImpl: appattempt_1377618433102_0003_000001 State change from ALLOCATED_SAVING to ALLOCATED
2013-08-27 15:54:34,045 INFO org.apache.hadoop.yarn.server.resourcemanager.amlauncher.AMLauncher: Launching masterappattempt_1377618433102_0003_000001
2013-08-27 15:54:34,048 INFO org.apache.hadoop.yarn.server.resourcemanager.amlauncher.AMLauncher: Setting up container Container: [ContainerId: container_1377618433102_0003_01_000001, NodeId: hadoop-8-3:42074, NodeHttpAddress: hadoop-8-3:8042, Resource: <memory:2048, vCores:1>, Priority: 0, State: NEW, Token: null, Status: container_id {, app_attempt_id {, application_id {, id: 3, cluster_timestamp: 1377618433102, }, attemptId: 1, }, id: 1, }, state: C_NEW, ] for AM appattempt_1377618433102_0003_000001
2013-08-27 15:54:34,049 INFO org.apache.hadoop.yarn.server.resourcemanager.amlauncher.AMLauncher: Command to launch container container_1377618433102_0003_01_000001 : $JAVA_HOME/bin/java -Dlog4j.configuration=container-log4j.properties -Dyarn.app.mapreduce.container.log.dir=<LOG_DIR> -Dyarn.app.mapreduce.container.log.filesize=0 -Dhadoop.root.logger=INFO,CLA  -Xmx1024m org.apache.hadoop.mapreduce.v2.app.MRAppMaster 1><LOG_DIR>/stdout 2><LOG_DIR>/stderr 
2013-08-27 15:54:34,066 INFO org.apache.hadoop.yarn.server.resourcemanager.amlauncher.AMLauncher: Done launching container Container: [ContainerId: container_1377618433102_0003_01_000001, NodeId: hadoop-8-3:42074, NodeHttpAddress: hadoop-8-3:8042, Resource: <memory:2048, vCores:1>, Priority: 0, State: NEW, Token: null, Status: container_id {, app_attempt_id {, application_id {, id: 3, cluster_timestamp: 1377618433102, }, attemptId: 1, }, id: 1, }, state: C_NEW, ] for AM appattempt_1377618433102_0003_000001
2013-08-27 15:54:34,067 INFO org.apache.hadoop.yarn.server.resourcemanager.rmapp.attempt.RMAppAttemptImpl: appattempt_1377618433102_0003_000001 State change from ALLOCATED to LAUNCHED
2013-08-27 15:54:35,042 INFO org.apache.hadoop.yarn.server.resourcemanager.rmcontainer.RMContainerImpl: container_1377618433102_0003_01_000001 Container Transitioned from ACQUIRED to RUNNING
2013-08-27 15:54:41,522 INFO org.apache.hadoop.yarn.server.resourcemanager.ApplicationMasterService: AM registration appattempt_1377618433102_0003_000001
2013-08-27 15:54:41,523 INFO org.apache.hadoop.yarn.server.resourcemanager.RMAuditLogger: USER=ubuntu	IP=192.168.100.19	OPERATION=Register App Master	TARGET=ApplicationMasterService	RESULT=SUCCESS	APPID=application_1377618433102_0003	APPATTEMPTID=appattempt_1377618433102_0003_000001
2013-08-27 15:54:41,524 INFO org.apache.hadoop.yarn.server.resourcemanager.rmapp.attempt.RMAppAttemptImpl: appattempt_1377618433102_0003_000001 State change from LAUNCHED to RUNNING
2013-08-27 15:54:41,524 INFO org.apache.hadoop.yarn.server.resourcemanager.rmapp.RMAppImpl: application_1377618433102_0003 State change from ACCEPTED to RUNNING
2013-08-27 15:54:42,636 INFO org.apache.hadoop.yarn.server.resourcemanager.rmcontainer.RMContainerImpl: container_1377618433102_0003_01_000002 Container Transitioned from NEW to ALLOCATED
2013-08-27 15:54:42,637 INFO org.apache.hadoop.yarn.server.resourcemanager.RMAuditLogger: USER=ubuntu	OPERATION=AM Allocated Container	TARGET=SchedulerApp	RESULT=SUCCESS	APPID=application_1377618433102_0003	CONTAINERID=container_1377618433102_0003_01_000002
2013-08-27 15:54:42,637 INFO org.apache.hadoop.yarn.server.resourcemanager.scheduler.common.fica.FiCaSchedulerNode: Assigned container container_1377618433102_0003_01_000002 of capacity <memory:1024, vCores:1> on host hadoop-8-4:36803, which currently has 1 containers, <memory:1024, vCores:1> used and <memory:7168, vCores:15> available
2013-08-27 15:54:42,639 INFO org.apache.hadoop.yarn.server.resourcemanager.scheduler.capacity.LeafQueue: assignedContainer application=application_1377618433102_0003 container=Container: [ContainerId: container_1377618433102_0003_01_000002, NodeId: hadoop-8-4:36803, NodeHttpAddress: hadoop-8-4:8042, Resource: <memory:1024, vCores:1>, Priority: 20, State: NEW, Token: null, Status: container_id {, app_attempt_id {, application_id {, id: 3, cluster_timestamp: 1377618433102, }, attemptId: 1, }, id: 2, }, state: C_NEW, ] containerId=container_1377618433102_0003_01_000002 queue=default: capacity=1.0, absoluteCapacity=1.0, usedResources=<memory:2048, vCores:1>usedCapacity=0.041666668, absoluteUsedCapacity=0.041666668, numApps=1, numContainers=1 usedCapacity=0.041666668 absoluteUsedCapacity=0.041666668 used=<memory:2048, vCores:1> cluster=<memory:49152, vCores:96>
2013-08-27 15:54:42,639 INFO org.apache.hadoop.yarn.server.resourcemanager.scheduler.capacity.ParentQueue: Re-sorting queues since queue: root.default stats: default: capacity=1.0, absoluteCapacity=1.0, usedResources=<memory:3072, vCores:2>usedCapacity=0.0625, absoluteUsedCapacity=0.0625, numApps=1, numContainers=2
2013-08-27 15:54:42,639 INFO org.apache.hadoop.yarn.server.resourcemanager.scheduler.capacity.ParentQueue: assignedContainer queue=root usedCapacity=0.0625 absoluteUsedCapacity=0.0625 used=<memory:3072, vCores:2> cluster=<memory:49152, vCores:96>
2013-08-27 15:54:42,642 INFO org.apache.hadoop.yarn.server.resourcemanager.rmcontainer.RMContainerImpl: container_1377618433102_0003_01_000003 Container Transitioned from NEW to ALLOCATED
2013-08-27 15:54:42,642 INFO org.apache.hadoop.yarn.server.resourcemanager.RMAuditLogger: USER=ubuntu	OPERATION=AM Allocated Container	TARGET=SchedulerApp	RESULT=SUCCESS	APPID=application_1377618433102_0003	CONTAINERID=container_1377618433102_0003_01_000003
2013-08-27 15:54:42,642 INFO org.apache.hadoop.yarn.server.resourcemanager.scheduler.common.fica.FiCaSchedulerNode: Assigned container container_1377618433102_0003_01_000003 of capacity <memory:1024, vCores:1> on host hadoop-8-7:53314, which currently has 1 containers, <memory:1024, vCores:1> used and <memory:7168, vCores:15> available
2013-08-27 15:54:42,644 INFO org.apache.hadoop.yarn.server.resourcemanager.scheduler.capacity.LeafQueue: assignedContainer application=application_1377618433102_0003 container=Container: [ContainerId: container_1377618433102_0003_01_000003, NodeId: hadoop-8-7:53314, NodeHttpAddress: hadoop-8-7:8042, Resource: <memory:1024, vCores:1>, Priority: 20, State: NEW, Token: null, Status: container_id {, app_attempt_id {, application_id {, id: 3, cluster_timestamp: 1377618433102, }, attemptId: 1, }, id: 3, }, state: C_NEW, ] containerId=container_1377618433102_0003_01_000003 queue=default: capacity=1.0, absoluteCapacity=1.0, usedResources=<memory:3072, vCores:2>usedCapacity=0.0625, absoluteUsedCapacity=0.0625, numApps=1, numContainers=2 usedCapacity=0.0625 absoluteUsedCapacity=0.0625 used=<memory:3072, vCores:2> cluster=<memory:49152, vCores:96>
2013-08-27 15:54:42,644 INFO org.apache.hadoop.yarn.server.resourcemanager.scheduler.capacity.ParentQueue: Re-sorting queues since queue: root.default stats: default: capacity=1.0, absoluteCapacity=1.0, usedResources=<memory:4096, vCores:3>usedCapacity=0.083333336, absoluteUsedCapacity=0.083333336, numApps=1, numContainers=3
2013-08-27 15:54:42,644 INFO org.apache.hadoop.yarn.server.resourcemanager.scheduler.capacity.ParentQueue: assignedContainer queue=root usedCapacity=0.083333336 absoluteUsedCapacity=0.083333336 used=<memory:4096, vCores:3> cluster=<memory:49152, vCores:96>
2013-08-27 15:54:43,587 INFO org.apache.hadoop.yarn.server.resourcemanager.rmcontainer.RMContainerImpl: container_1377618433102_0003_01_000002 Container Transitioned from ALLOCATED to ACQUIRED
2013-08-27 15:54:43,589 INFO org.apache.hadoop.yarn.server.resourcemanager.rmcontainer.RMContainerImpl: container_1377618433102_0003_01_000003 Container Transitioned from ALLOCATED to ACQUIRED
2013-08-27 15:54:44,619 INFO org.apache.hadoop.yarn.server.resourcemanager.scheduler.AppSchedulingInfo: checking for deactivate... 
2013-08-27 15:54:44,645 INFO org.apache.hadoop.yarn.server.resourcemanager.rmcontainer.RMContainerImpl: container_1377618433102_0003_01_000002 Container Transitioned from ACQUIRED to RUNNING
2013-08-27 15:54:45,670 INFO org.apache.hadoop.yarn.server.resourcemanager.rmcontainer.RMContainerImpl: container_1377618433102_0003_01_000003 Container Transitioned from ACQUIRED to RUNNING
2013-08-27 15:57:41,535 INFO org.apache.hadoop.yarn.server.resourcemanager.rmcontainer.RMContainerImpl: container_1377618433102_0003_01_000003 Container Transitioned from RUNNING to COMPLETED
2013-08-27 15:57:41,535 INFO org.apache.hadoop.yarn.server.resourcemanager.scheduler.common.fica.FiCaSchedulerApp: Completed container: container_1377618433102_0003_01_000003 in state: COMPLETED event:FINISHED
2013-08-27 15:57:41,535 INFO org.apache.hadoop.yarn.server.resourcemanager.RMAuditLogger: USER=ubuntu	OPERATION=AM Released Container	TARGET=SchedulerApp	RESULT=SUCCESS	APPID=application_1377618433102_0003	CONTAINERID=container_1377618433102_0003_01_000003
2013-08-27 15:57:41,536 INFO org.apache.hadoop.yarn.server.resourcemanager.scheduler.common.fica.FiCaSchedulerNode: Released container container_1377618433102_0003_01_000003 of capacity <memory:1024, vCores:1> on host hadoop-8-7:53314, which currently has 0 containers, <memory:0, vCores:0> used and <memory:8192, vCores:16> available, release resources=true
2013-08-27 15:57:41,536 INFO org.apache.hadoop.yarn.server.resourcemanager.scheduler.capacity.LeafQueue: default used=<memory:3072, vCores:2> numContainers=2 user=ubuntu user-resources=<memory:3072, vCores:2>
2013-08-27 15:57:41,538 INFO org.apache.hadoop.yarn.server.resourcemanager.scheduler.capacity.LeafQueue: completedContainer container=Container: [ContainerId: container_1377618433102_0003_01_000003, NodeId: hadoop-8-7:53314, NodeHttpAddress: hadoop-8-7:8042, Resource: <memory:1024, vCores:1>, Priority: 20, State: NEW, Token: null, Status: container_id {, app_attempt_id {, application_id {, id: 3, cluster_timestamp: 1377618433102, }, attemptId: 1, }, id: 3, }, state: C_COMPLETE, diagnostics: "Container killed by the ApplicationMaster.\n\n", exit_status: 143, ] resource=<memory:1024, vCores:1> queue=default: capacity=1.0, absoluteCapacity=1.0, usedResources=<memory:3072, vCores:2>usedCapacity=0.0625, absoluteUsedCapacity=0.0625, numApps=1, numContainers=2 usedCapacity=0.0625 absoluteUsedCapacity=0.0625 used=<memory:3072, vCores:2> cluster=<memory:49152, vCores:96>
2013-08-27 15:57:41,538 INFO org.apache.hadoop.yarn.server.resourcemanager.scheduler.capacity.ParentQueue: completedContainer queue=root usedCapacity=0.0625 absoluteUsedCapacity=0.0625 used=<memory:3072, vCores:2> cluster=<memory:49152, vCores:96>
2013-08-27 15:57:41,538 INFO org.apache.hadoop.yarn.server.resourcemanager.scheduler.capacity.CapacityScheduler: Application appattempt_1377618433102_0003_000001 released container container_1377618433102_0003_01_000003 on node: host: hadoop-8-7:53314 #containers=0 available=8192 used=0 with event: FINISHED
2013-08-27 15:57:42,557 INFO org.apache.hadoop.yarn.server.resourcemanager.rmcontainer.RMContainerImpl: container_1377618433102_0003_01_000002 Container Transitioned from RUNNING to COMPLETED
2013-08-27 15:57:42,557 INFO org.apache.hadoop.yarn.server.resourcemanager.scheduler.common.fica.FiCaSchedulerApp: Completed container: container_1377618433102_0003_01_000002 in state: COMPLETED event:FINISHED
2013-08-27 15:57:42,558 INFO org.apache.hadoop.yarn.server.resourcemanager.RMAuditLogger: USER=ubuntu	OPERATION=AM Released Container	TARGET=SchedulerApp	RESULT=SUCCESS	APPID=application_1377618433102_0003	CONTAINERID=container_1377618433102_0003_01_000002
2013-08-27 15:57:42,558 INFO org.apache.hadoop.yarn.server.resourcemanager.scheduler.common.fica.FiCaSchedulerNode: Released container container_1377618433102_0003_01_000002 of capacity <memory:1024, vCores:1> on host hadoop-8-4:36803, which currently has 0 containers, <memory:0, vCores:0> used and <memory:8192, vCores:16> available, release resources=true
2013-08-27 15:57:42,558 INFO org.apache.hadoop.yarn.server.resourcemanager.scheduler.capacity.LeafQueue: default used=<memory:2048, vCores:1> numContainers=1 user=ubuntu user-resources=<memory:2048, vCores:1>
2013-08-27 15:57:42,560 INFO org.apache.hadoop.yarn.server.resourcemanager.scheduler.capacity.LeafQueue: completedContainer container=Container: [ContainerId: container_1377618433102_0003_01_000002, NodeId: hadoop-8-4:36803, NodeHttpAddress: hadoop-8-4:8042, Resource: <memory:1024, vCores:1>, Priority: 20, State: NEW, Token: null, Status: container_id {, app_attempt_id {, application_id {, id: 3, cluster_timestamp: 1377618433102, }, attemptId: 1, }, id: 2, }, state: C_COMPLETE, diagnostics: "Container killed by the ApplicationMaster.\n\n", exit_status: 143, ] resource=<memory:1024, vCores:1> queue=default: capacity=1.0, absoluteCapacity=1.0, usedResources=<memory:2048, vCores:1>usedCapacity=0.041666668, absoluteUsedCapacity=0.041666668, numApps=1, numContainers=1 usedCapacity=0.041666668 absoluteUsedCapacity=0.041666668 used=<memory:2048, vCores:1> cluster=<memory:49152, vCores:96>
2013-08-27 15:57:42,560 INFO org.apache.hadoop.yarn.server.resourcemanager.scheduler.capacity.ParentQueue: completedContainer queue=root usedCapacity=0.041666668 absoluteUsedCapacity=0.041666668 used=<memory:2048, vCores:1> cluster=<memory:49152, vCores:96>
2013-08-27 15:57:42,560 INFO org.apache.hadoop.yarn.server.resourcemanager.scheduler.capacity.CapacityScheduler: Application appattempt_1377618433102_0003_000001 released container container_1377618433102_0003_01_000002 on node: host: hadoop-8-4:36803 #containers=0 available=8192 used=0 with event: FINISHED
2013-08-27 15:57:46,741 INFO org.apache.hadoop.yarn.server.resourcemanager.rmapp.attempt.RMAppAttemptImpl: appattempt_1377618433102_0003_000001 State change from RUNNING to FINISHING
2013-08-27 15:57:46,742 INFO org.apache.hadoop.yarn.server.resourcemanager.rmapp.RMAppImpl: application_1377618433102_0003 State change from RUNNING to FINISHING
2013-08-27 15:57:47,094 INFO org.apache.hadoop.yarn.server.resourcemanager.rmcontainer.RMContainerImpl: container_1377618433102_0003_01_000001 Container Transitioned from RUNNING to COMPLETED
2013-08-27 15:57:47,094 INFO org.apache.hadoop.yarn.server.resourcemanager.scheduler.common.fica.FiCaSchedulerApp: Completed container: container_1377618433102_0003_01_000001 in state: COMPLETED event:FINISHED
2013-08-27 15:57:47,094 INFO org.apache.hadoop.yarn.server.resourcemanager.RMAuditLogger: USER=ubuntu	OPERATION=AM Released Container	TARGET=SchedulerApp	RESULT=SUCCESS	APPID=application_1377618433102_0003	CONTAINERID=container_1377618433102_0003_01_000001
2013-08-27 15:57:47,094 INFO org.apache.hadoop.yarn.server.resourcemanager.scheduler.common.fica.FiCaSchedulerNode: Released container container_1377618433102_0003_01_000001 of capacity <memory:2048, vCores:1> on host hadoop-8-3:42074, which currently has 0 containers, <memory:0, vCores:0> used and <memory:8192, vCores:16> available, release resources=true
2013-08-27 15:57:47,095 INFO org.apache.hadoop.yarn.server.resourcemanager.scheduler.capacity.LeafQueue: default used=<memory:0, vCores:0> numContainers=0 user=ubuntu user-resources=<memory:0, vCores:0>
2013-08-27 15:57:47,095 INFO org.apache.hadoop.yarn.server.resourcemanager.scheduler.capacity.LeafQueue: completedContainer container=Container: [ContainerId: container_1377618433102_0003_01_000001, NodeId: hadoop-8-3:42074, NodeHttpAddress: hadoop-8-3:8042, Resource: <memory:2048, vCores:1>, Priority: 0, State: NEW, Token: null, Status: container_id {, app_attempt_id {, application_id {, id: 3, cluster_timestamp: 1377618433102, }, attemptId: 1, }, id: 1, }, state: C_COMPLETE, diagnostics: "", exit_status: 0, ] resource=<memory:2048, vCores:1> queue=default: capacity=1.0, absoluteCapacity=1.0, usedResources=<memory:0, vCores:0>usedCapacity=0.0, absoluteUsedCapacity=0.0, numApps=1, numContainers=0 usedCapacity=0.0 absoluteUsedCapacity=0.0 used=<memory:0, vCores:0> cluster=<memory:49152, vCores:96>
2013-08-27 15:57:47,095 INFO org.apache.hadoop.yarn.server.resourcemanager.scheduler.capacity.ParentQueue: completedContainer queue=root usedCapacity=0.0 absoluteUsedCapacity=0.0 used=<memory:0, vCores:0> cluster=<memory:49152, vCores:96>
2013-08-27 15:57:47,096 INFO org.apache.hadoop.yarn.server.resourcemanager.scheduler.capacity.CapacityScheduler: Application appattempt_1377618433102_0003_000001 released container container_1377618433102_0003_01_000001 on node: host: hadoop-8-3:42074 #containers=0 available=8192 used=0 with event: FINISHED
2013-08-27 15:57:47,096 INFO org.apache.hadoop.yarn.server.resourcemanager.rmapp.attempt.RMAppAttemptImpl: appattempt_1377618433102_0003_000001 State change from FINISHING to FINISHED
2013-08-27 15:57:47,096 INFO org.apache.hadoop.yarn.server.resourcemanager.rmapp.RMAppImpl: application_1377618433102_0003 State change from FINISHING to FINISHED
2013-08-27 15:57:47,096 INFO org.apache.hadoop.yarn.server.resourcemanager.RMAuditLogger: USER=ubuntu	OPERATION=Application Finished - Succeeded	TARGET=RMAppManager	RESULT=SUCCESS	APPID=application_1377618433102_0003
2013-08-27 15:57:47,096 INFO org.apache.hadoop.yarn.server.resourcemanager.scheduler.capacity.CapacityScheduler: Application appattempt_1377618433102_0003_000001 is done. finalState=FINISHED
2013-08-27 15:57:47,096 INFO org.apache.hadoop.yarn.server.resourcemanager.scheduler.AppSchedulingInfo: Application application_1377618433102_0003 requests cleared
2013-08-27 15:57:47,097 INFO org.apache.hadoop.yarn.server.resourcemanager.scheduler.capacity.LeafQueue: Application removed - appId: application_1377618433102_0003 user: ubuntu queue: default #user-pending-applications: 0 #user-active-applications: 0 #queue-pending-applications: 0 #queue-active-applications: 0
2013-08-27 15:57:47,097 INFO org.apache.hadoop.yarn.server.resourcemanager.scheduler.capacity.ParentQueue: Application removed - appId: application_1377618433102_0003 user: ubuntu leaf-queue of parent: root #applications: 0
2013-08-27 15:57:47,097 INFO org.apache.hadoop.yarn.server.resourcemanager.amlauncher.AMLauncher: Cleaning master appattempt_1377618433102_0003_000001
2013-08-27 15:57:47,097 INFO org.apache.hadoop.yarn.server.resourcemanager.recovery.RMStateStore: Removing info for app: application_1377618433102_0003
2013-08-27 15:57:47,097 INFO org.apache.hadoop.yarn.server.resourcemanager.RMAppManager$ApplicationSummary: appId=application_1377618433102_0003,name=TeraGen,user=ubuntu,queue=default,state=FINISHED,trackingUrl=hadoop-8-1.novalocal:8088/proxy/application_1377618433102_0003/jobhistory/job/job_1377618433102_0003,appMasterHost=hadoop-8-3,startTime=1377618873768,finishTime=1377619066742
2013-08-27 15:57:47,641 INFO org.apache.hadoop.yarn.server.resourcemanager.ClientRMService: Allocated new applicationId: 4
2013-08-27 15:57:49,540 INFO org.apache.hadoop.yarn.server.resourcemanager.ClientRMService: Storing Application with id application_1377618433102_0004
2013-08-27 15:57:49,540 INFO org.apache.hadoop.yarn.server.resourcemanager.recovery.RMStateStore: Storing info for app: application_1377618433102_0004
2013-08-27 15:57:49,540 INFO org.apache.hadoop.yarn.server.resourcemanager.ClientRMService: Application with id 4 submitted by user ubuntu
2013-08-27 15:57:49,540 INFO org.apache.hadoop.yarn.server.resourcemanager.RMAuditLogger: USER=ubuntu	IP=192.168.100.15	OPERATION=Submit Application Request	TARGET=ClientRMService	RESULT=SUCCESS	APPID=application_1377618433102_0004
2013-08-27 15:57:49,548 INFO org.apache.hadoop.yarn.server.resourcemanager.rmapp.RMAppImpl: application_1377618433102_0004 State change from NEW to SUBMITTED
2013-08-27 15:57:49,548 INFO org.apache.hadoop.yarn.server.resourcemanager.ApplicationMasterService: Registering appattempt_1377618433102_0004_000001
2013-08-27 15:57:49,548 INFO org.apache.hadoop.yarn.server.resourcemanager.rmapp.attempt.RMAppAttemptImpl: appattempt_1377618433102_0004_000001 State change from NEW to SUBMITTED
2013-08-27 15:57:49,549 INFO org.apache.hadoop.yarn.server.resourcemanager.scheduler.capacity.LeafQueue: Application application_1377618433102_0004 from user: ubuntu activated in queue: default
2013-08-27 15:57:49,549 INFO org.apache.hadoop.yarn.server.resourcemanager.scheduler.capacity.LeafQueue: Application added - appId: application_1377618433102_0004 user: org.apache.hadoop.yarn.server.resourcemanager.scheduler.capacity.LeafQueue$User@657fa52d, leaf-queue: default #user-pending-applications: 0 #user-active-applications: 1 #queue-pending-applications: 0 #queue-active-applications: 1
2013-08-27 15:57:49,549 INFO org.apache.hadoop.yarn.server.resourcemanager.scheduler.capacity.ParentQueue: Application added - appId: application_1377618433102_0004 user: ubuntu leaf-queue of parent: root #applications: 1
2013-08-27 15:57:49,549 INFO org.apache.hadoop.yarn.server.resourcemanager.scheduler.capacity.CapacityScheduler: Application Submission: appattempt_1377618433102_0004_000001, user: ubuntu queue: default: capacity=1.0, absoluteCapacity=1.0, usedResources=<memory:0, vCores:0>usedCapacity=0.0, absoluteUsedCapacity=0.0, numApps=1, numContainers=0, currently active: 1
2013-08-27 15:57:49,550 INFO org.apache.hadoop.yarn.server.resourcemanager.rmapp.attempt.RMAppAttemptImpl: appattempt_1377618433102_0004_000001 State change from SUBMITTED to SCHEDULED
2013-08-27 15:57:49,550 INFO org.apache.hadoop.yarn.server.resourcemanager.rmapp.RMAppImpl: application_1377618433102_0004 State change from SUBMITTED to ACCEPTED
2013-08-27 15:57:49,565 INFO org.apache.hadoop.yarn.server.resourcemanager.rmcontainer.RMContainerImpl: container_1377618433102_0004_01_000001 Container Transitioned from NEW to ALLOCATED
2013-08-27 15:57:49,566 INFO org.apache.hadoop.yarn.server.resourcemanager.RMAuditLogger: USER=ubuntu	OPERATION=AM Allocated Container	TARGET=SchedulerApp	RESULT=SUCCESS	APPID=application_1377618433102_0004	CONTAINERID=container_1377618433102_0004_01_000001
2013-08-27 15:57:49,566 INFO org.apache.hadoop.yarn.server.resourcemanager.scheduler.common.fica.FiCaSchedulerNode: Assigned container container_1377618433102_0004_01_000001 of capacity <memory:2048, vCores:1> on host hadoop-8-7:53314, which currently has 1 containers, <memory:2048, vCores:1> used and <memory:6144, vCores:15> available
2013-08-27 15:57:49,567 INFO org.apache.hadoop.yarn.server.resourcemanager.scheduler.capacity.LeafQueue: assignedContainer application=application_1377618433102_0004 container=Container: [ContainerId: container_1377618433102_0004_01_000001, NodeId: hadoop-8-7:53314, NodeHttpAddress: hadoop-8-7:8042, Resource: <memory:2048, vCores:1>, Priority: 0, State: NEW, Token: null, Status: container_id {, app_attempt_id {, application_id {, id: 4, cluster_timestamp: 1377618433102, }, attemptId: 1, }, id: 1, }, state: C_NEW, ] containerId=container_1377618433102_0004_01_000001 queue=default: capacity=1.0, absoluteCapacity=1.0, usedResources=<memory:0, vCores:0>usedCapacity=0.0, absoluteUsedCapacity=0.0, numApps=1, numContainers=0 usedCapacity=0.0 absoluteUsedCapacity=0.0 used=<memory:0, vCores:0> cluster=<memory:49152, vCores:96>
2013-08-27 15:57:49,567 INFO org.apache.hadoop.yarn.server.resourcemanager.scheduler.capacity.ParentQueue: Re-sorting queues since queue: root.default stats: default: capacity=1.0, absoluteCapacity=1.0, usedResources=<memory:2048, vCores:1>usedCapacity=0.041666668, absoluteUsedCapacity=0.041666668, numApps=1, numContainers=1
2013-08-27 15:57:49,568 INFO org.apache.hadoop.yarn.server.resourcemanager.scheduler.capacity.ParentQueue: assignedContainer queue=root usedCapacity=0.041666668 absoluteUsedCapacity=0.041666668 used=<memory:2048, vCores:1> cluster=<memory:49152, vCores:96>
2013-08-27 15:57:49,569 INFO org.apache.hadoop.yarn.server.resourcemanager.rmcontainer.RMContainerImpl: container_1377618433102_0004_01_000001 Container Transitioned from ALLOCATED to ACQUIRED
2013-08-27 15:57:49,570 INFO org.apache.hadoop.yarn.server.resourcemanager.rmapp.attempt.RMAppAttemptImpl: Storing attempt: AppId: application_1377618433102_0004 AttemptId: appattempt_1377618433102_0004_000001 MasterContainer: Container: [ContainerId: container_1377618433102_0004_01_000001, NodeId: hadoop-8-7:53314, NodeHttpAddress: hadoop-8-7:8042, Resource: <memory:2048, vCores:1>, Priority: 0, State: NEW, Token: null, Status: container_id {, app_attempt_id {, application_id {, id: 4, cluster_timestamp: 1377618433102, }, attemptId: 1, }, id: 1, }, state: C_NEW, ]
2013-08-27 15:57:49,571 INFO org.apache.hadoop.yarn.server.resourcemanager.rmapp.attempt.RMAppAttemptImpl: appattempt_1377618433102_0004_000001 State change from SCHEDULED to ALLOCATED_SAVING
2013-08-27 15:57:49,571 INFO org.apache.hadoop.yarn.server.resourcemanager.recovery.RMStateStore: Storing info for attempt: appattempt_1377618433102_0004_000001
2013-08-27 15:57:49,572 INFO org.apache.hadoop.yarn.server.resourcemanager.rmapp.attempt.RMAppAttemptImpl: appattempt_1377618433102_0004_000001 State change from ALLOCATED_SAVING to ALLOCATED
2013-08-27 15:57:49,573 INFO org.apache.hadoop.yarn.server.resourcemanager.amlauncher.AMLauncher: Launching masterappattempt_1377618433102_0004_000001
2013-08-27 15:57:49,576 INFO org.apache.hadoop.yarn.server.resourcemanager.amlauncher.AMLauncher: Setting up container Container: [ContainerId: container_1377618433102_0004_01_000001, NodeId: hadoop-8-7:53314, NodeHttpAddress: hadoop-8-7:8042, Resource: <memory:2048, vCores:1>, Priority: 0, State: NEW, Token: null, Status: container_id {, app_attempt_id {, application_id {, id: 4, cluster_timestamp: 1377618433102, }, attemptId: 1, }, id: 1, }, state: C_NEW, ] for AM appattempt_1377618433102_0004_000001
2013-08-27 15:57:49,576 INFO org.apache.hadoop.yarn.server.resourcemanager.amlauncher.AMLauncher: Command to launch container container_1377618433102_0004_01_000001 : $JAVA_HOME/bin/java -Dlog4j.configuration=container-log4j.properties -Dyarn.app.mapreduce.container.log.dir=<LOG_DIR> -Dyarn.app.mapreduce.container.log.filesize=0 -Dhadoop.root.logger=INFO,CLA  -Xmx1024m org.apache.hadoop.mapreduce.v2.app.MRAppMaster 1><LOG_DIR>/stdout 2><LOG_DIR>/stderr 
2013-08-27 15:57:49,590 INFO org.apache.hadoop.yarn.server.resourcemanager.amlauncher.AMLauncher: Done launching container Container: [ContainerId: container_1377618433102_0004_01_000001, NodeId: hadoop-8-7:53314, NodeHttpAddress: hadoop-8-7:8042, Resource: <memory:2048, vCores:1>, Priority: 0, State: NEW, Token: null, Status: container_id {, app_attempt_id {, application_id {, id: 4, cluster_timestamp: 1377618433102, }, attemptId: 1, }, id: 1, }, state: C_NEW, ] for AM appattempt_1377618433102_0004_000001
2013-08-27 15:57:49,590 INFO org.apache.hadoop.yarn.server.resourcemanager.rmapp.attempt.RMAppAttemptImpl: appattempt_1377618433102_0004_000001 State change from ALLOCATED to LAUNCHED
2013-08-27 15:57:50,571 INFO org.apache.hadoop.yarn.server.resourcemanager.rmcontainer.RMContainerImpl: container_1377618433102_0004_01_000001 Container Transitioned from ACQUIRED to RUNNING
2013-08-27 15:57:58,916 INFO org.apache.hadoop.yarn.server.resourcemanager.ApplicationMasterService: AM registration appattempt_1377618433102_0004_000001
2013-08-27 15:57:58,916 INFO org.apache.hadoop.yarn.server.resourcemanager.RMAuditLogger: USER=ubuntu	IP=192.168.100.31	OPERATION=Register App Master	TARGET=ApplicationMasterService	RESULT=SUCCESS	APPID=application_1377618433102_0004	APPATTEMPTID=appattempt_1377618433102_0004_000001
2013-08-27 15:57:58,917 INFO org.apache.hadoop.yarn.server.resourcemanager.rmapp.attempt.RMAppAttemptImpl: appattempt_1377618433102_0004_000001 State change from LAUNCHED to RUNNING
2013-08-27 15:57:58,917 INFO org.apache.hadoop.yarn.server.resourcemanager.rmapp.RMAppImpl: application_1377618433102_0004 State change from ACCEPTED to RUNNING
2013-08-27 15:58:00,038 INFO org.apache.hadoop.yarn.server.resourcemanager.rmcontainer.RMContainerImpl: container_1377618433102_0004_01_000002 Container Transitioned from NEW to ALLOCATED
2013-08-27 15:58:00,038 INFO org.apache.hadoop.yarn.server.resourcemanager.RMAuditLogger: USER=ubuntu	OPERATION=AM Allocated Container	TARGET=SchedulerApp	RESULT=SUCCESS	APPID=application_1377618433102_0004	CONTAINERID=container_1377618433102_0004_01_000002
2013-08-27 15:58:00,039 INFO org.apache.hadoop.yarn.server.resourcemanager.scheduler.common.fica.FiCaSchedulerNode: Assigned container container_1377618433102_0004_01_000002 of capacity <memory:1024, vCores:1> on host hadoop-8-5:56487, which currently has 1 containers, <memory:1024, vCores:1> used and <memory:7168, vCores:15> available
2013-08-27 15:58:00,040 INFO org.apache.hadoop.yarn.server.resourcemanager.scheduler.capacity.LeafQueue: assignedContainer application=application_1377618433102_0004 container=Container: [ContainerId: container_1377618433102_0004_01_000002, NodeId: hadoop-8-5:56487, NodeHttpAddress: hadoop-8-5:8042, Resource: <memory:1024, vCores:1>, Priority: 20, State: NEW, Token: null, Status: container_id {, app_attempt_id {, application_id {, id: 4, cluster_timestamp: 1377618433102, }, attemptId: 1, }, id: 2, }, state: C_NEW, ] containerId=container_1377618433102_0004_01_000002 queue=default: capacity=1.0, absoluteCapacity=1.0, usedResources=<memory:2048, vCores:1>usedCapacity=0.041666668, absoluteUsedCapacity=0.041666668, numApps=1, numContainers=1 usedCapacity=0.041666668 absoluteUsedCapacity=0.041666668 used=<memory:2048, vCores:1> cluster=<memory:49152, vCores:96>
2013-08-27 15:58:00,040 INFO org.apache.hadoop.yarn.server.resourcemanager.scheduler.capacity.ParentQueue: Re-sorting queues since queue: root.default stats: default: capacity=1.0, absoluteCapacity=1.0, usedResources=<memory:3072, vCores:2>usedCapacity=0.0625, absoluteUsedCapacity=0.0625, numApps=1, numContainers=2
2013-08-27 15:58:00,041 INFO org.apache.hadoop.yarn.server.resourcemanager.scheduler.capacity.ParentQueue: assignedContainer queue=root usedCapacity=0.0625 absoluteUsedCapacity=0.0625 used=<memory:3072, vCores:2> cluster=<memory:49152, vCores:96>
2013-08-27 15:58:00,051 INFO org.apache.hadoop.yarn.server.resourcemanager.rmcontainer.RMContainerImpl: container_1377618433102_0004_01_000003 Container Transitioned from NEW to ALLOCATED
2013-08-27 15:58:00,052 INFO org.apache.hadoop.yarn.server.resourcemanager.RMAuditLogger: USER=ubuntu	OPERATION=AM Allocated Container	TARGET=SchedulerApp	RESULT=SUCCESS	APPID=application_1377618433102_0004	CONTAINERID=container_1377618433102_0004_01_000003
2013-08-27 15:58:00,052 INFO org.apache.hadoop.yarn.server.resourcemanager.scheduler.common.fica.FiCaSchedulerNode: Assigned container container_1377618433102_0004_01_000003 of capacity <memory:1024, vCores:1> on host hadoop-8-2:41932, which currently has 1 containers, <memory:1024, vCores:1> used and <memory:7168, vCores:15> available
2013-08-27 15:58:00,053 INFO org.apache.hadoop.yarn.server.resourcemanager.scheduler.capacity.LeafQueue: assignedContainer application=application_1377618433102_0004 container=Container: [ContainerId: container_1377618433102_0004_01_000003, NodeId: hadoop-8-2:41932, NodeHttpAddress: hadoop-8-2:8042, Resource: <memory:1024, vCores:1>, Priority: 20, State: NEW, Token: null, Status: container_id {, app_attempt_id {, application_id {, id: 4, cluster_timestamp: 1377618433102, }, attemptId: 1, }, id: 3, }, state: C_NEW, ] containerId=container_1377618433102_0004_01_000003 queue=default: capacity=1.0, absoluteCapacity=1.0, usedResources=<memory:3072, vCores:2>usedCapacity=0.0625, absoluteUsedCapacity=0.0625, numApps=1, numContainers=2 usedCapacity=0.0625 absoluteUsedCapacity=0.0625 used=<memory:3072, vCores:2> cluster=<memory:49152, vCores:96>
2013-08-27 15:58:00,053 INFO org.apache.hadoop.yarn.server.resourcemanager.scheduler.capacity.ParentQueue: Re-sorting queues since queue: root.default stats: default: capacity=1.0, absoluteCapacity=1.0, usedResources=<memory:4096, vCores:3>usedCapacity=0.083333336, absoluteUsedCapacity=0.083333336, numApps=1, numContainers=3
2013-08-27 15:58:00,053 INFO org.apache.hadoop.yarn.server.resourcemanager.scheduler.capacity.ParentQueue: assignedContainer queue=root usedCapacity=0.083333336 absoluteUsedCapacity=0.083333336 used=<memory:4096, vCores:3> cluster=<memory:49152, vCores:96>
2013-08-27 15:58:00,989 INFO org.apache.hadoop.yarn.server.resourcemanager.rmcontainer.RMContainerImpl: container_1377618433102_0004_01_000002 Container Transitioned from ALLOCATED to ACQUIRED
2013-08-27 15:58:00,991 INFO org.apache.hadoop.yarn.server.resourcemanager.rmcontainer.RMContainerImpl: container_1377618433102_0004_01_000003 Container Transitioned from ALLOCATED to ACQUIRED
2013-08-27 15:58:02,020 INFO org.apache.hadoop.yarn.server.resourcemanager.scheduler.AppSchedulingInfo: checking for deactivate... 
2013-08-27 15:58:02,053 INFO org.apache.hadoop.yarn.server.resourcemanager.rmcontainer.RMContainerImpl: container_1377618433102_0004_01_000002 Container Transitioned from ACQUIRED to RUNNING
2013-08-27 15:58:02,059 INFO org.apache.hadoop.yarn.server.resourcemanager.rmcontainer.RMContainerImpl: container_1377618433102_0004_01_000003 Container Transitioned from ACQUIRED to RUNNING
2013-08-27 16:00:49,847 INFO org.apache.hadoop.yarn.server.resourcemanager.rmcontainer.RMContainerImpl: container_1377618433102_0004_01_000002 Container Transitioned from RUNNING to COMPLETED
2013-08-27 16:00:49,848 INFO org.apache.hadoop.yarn.server.resourcemanager.scheduler.common.fica.FiCaSchedulerApp: Completed container: container_1377618433102_0004_01_000002 in state: COMPLETED event:FINISHED
2013-08-27 16:00:49,848 INFO org.apache.hadoop.yarn.server.resourcemanager.RMAuditLogger: USER=ubuntu	OPERATION=AM Released Container	TARGET=SchedulerApp	RESULT=SUCCESS	APPID=application_1377618433102_0004	CONTAINERID=container_1377618433102_0004_01_000002
2013-08-27 16:00:49,848 INFO org.apache.hadoop.yarn.server.resourcemanager.scheduler.common.fica.FiCaSchedulerNode: Released container container_1377618433102_0004_01_000002 of capacity <memory:1024, vCores:1> on host hadoop-8-5:56487, which currently has 0 containers, <memory:0, vCores:0> used and <memory:8192, vCores:16> available, release resources=true
2013-08-27 16:00:49,848 INFO org.apache.hadoop.yarn.server.resourcemanager.scheduler.capacity.LeafQueue: default used=<memory:3072, vCores:2> numContainers=2 user=ubuntu user-resources=<memory:3072, vCores:2>
2013-08-27 16:00:49,850 INFO org.apache.hadoop.yarn.server.resourcemanager.scheduler.capacity.LeafQueue: completedContainer container=Container: [ContainerId: container_1377618433102_0004_01_000002, NodeId: hadoop-8-5:56487, NodeHttpAddress: hadoop-8-5:8042, Resource: <memory:1024, vCores:1>, Priority: 20, State: NEW, Token: null, Status: container_id {, app_attempt_id {, application_id {, id: 4, cluster_timestamp: 1377618433102, }, attemptId: 1, }, id: 2, }, state: C_COMPLETE, diagnostics: "Container killed by the ApplicationMaster.\n\n", exit_status: 143, ] resource=<memory:1024, vCores:1> queue=default: capacity=1.0, absoluteCapacity=1.0, usedResources=<memory:3072, vCores:2>usedCapacity=0.0625, absoluteUsedCapacity=0.0625, numApps=1, numContainers=2 usedCapacity=0.0625 absoluteUsedCapacity=0.0625 used=<memory:3072, vCores:2> cluster=<memory:49152, vCores:96>
2013-08-27 16:00:49,850 INFO org.apache.hadoop.yarn.server.resourcemanager.scheduler.capacity.ParentQueue: completedContainer queue=root usedCapacity=0.0625 absoluteUsedCapacity=0.0625 used=<memory:3072, vCores:2> cluster=<memory:49152, vCores:96>
2013-08-27 16:00:49,850 INFO org.apache.hadoop.yarn.server.resourcemanager.scheduler.capacity.CapacityScheduler: Application appattempt_1377618433102_0004_000001 released container container_1377618433102_0004_01_000002 on node: host: hadoop-8-5:56487 #containers=0 available=8192 used=0 with event: FINISHED
2013-08-27 16:00:50,220 INFO org.apache.hadoop.yarn.server.resourcemanager.rmcontainer.RMContainerImpl: container_1377618433102_0004_01_000003 Container Transitioned from RUNNING to COMPLETED
2013-08-27 16:00:50,221 INFO org.apache.hadoop.yarn.server.resourcemanager.scheduler.common.fica.FiCaSchedulerApp: Completed container: container_1377618433102_0004_01_000003 in state: COMPLETED event:FINISHED
2013-08-27 16:00:50,221 INFO org.apache.hadoop.yarn.server.resourcemanager.RMAuditLogger: USER=ubuntu	OPERATION=AM Released Container	TARGET=SchedulerApp	RESULT=SUCCESS	APPID=application_1377618433102_0004	CONTAINERID=container_1377618433102_0004_01_000003
2013-08-27 16:00:50,221 INFO org.apache.hadoop.yarn.server.resourcemanager.scheduler.common.fica.FiCaSchedulerNode: Released container container_1377618433102_0004_01_000003 of capacity <memory:1024, vCores:1> on host hadoop-8-2:41932, which currently has 0 containers, <memory:0, vCores:0> used and <memory:8192, vCores:16> available, release resources=true
2013-08-27 16:00:50,221 INFO org.apache.hadoop.yarn.server.resourcemanager.scheduler.capacity.LeafQueue: default used=<memory:2048, vCores:1> numContainers=1 user=ubuntu user-resources=<memory:2048, vCores:1>
2013-08-27 16:00:50,223 INFO org.apache.hadoop.yarn.server.resourcemanager.scheduler.capacity.LeafQueue: completedContainer container=Container: [ContainerId: container_1377618433102_0004_01_000003, NodeId: hadoop-8-2:41932, NodeHttpAddress: hadoop-8-2:8042, Resource: <memory:1024, vCores:1>, Priority: 20, State: NEW, Token: null, Status: container_id {, app_attempt_id {, application_id {, id: 4, cluster_timestamp: 1377618433102, }, attemptId: 1, }, id: 3, }, state: C_COMPLETE, diagnostics: "Container killed by the ApplicationMaster.\n\n", exit_status: 143, ] resource=<memory:1024, vCores:1> queue=default: capacity=1.0, absoluteCapacity=1.0, usedResources=<memory:2048, vCores:1>usedCapacity=0.041666668, absoluteUsedCapacity=0.041666668, numApps=1, numContainers=1 usedCapacity=0.041666668 absoluteUsedCapacity=0.041666668 used=<memory:2048, vCores:1> cluster=<memory:49152, vCores:96>
2013-08-27 16:00:50,223 INFO org.apache.hadoop.yarn.server.resourcemanager.scheduler.capacity.ParentQueue: completedContainer queue=root usedCapacity=0.041666668 absoluteUsedCapacity=0.041666668 used=<memory:2048, vCores:1> cluster=<memory:49152, vCores:96>
2013-08-27 16:00:50,223 INFO org.apache.hadoop.yarn.server.resourcemanager.scheduler.capacity.CapacityScheduler: Application appattempt_1377618433102_0004_000001 released container container_1377618433102_0004_01_000003 on node: host: hadoop-8-2:41932 #containers=0 available=8192 used=0 with event: FINISHED
2013-08-27 16:00:54,419 INFO org.apache.hadoop.yarn.server.resourcemanager.rmapp.attempt.RMAppAttemptImpl: appattempt_1377618433102_0004_000001 State change from RUNNING to FINISHING
2013-08-27 16:00:54,420 INFO org.apache.hadoop.yarn.server.resourcemanager.rmapp.RMAppImpl: application_1377618433102_0004 State change from RUNNING to FINISHING
2013-08-27 16:00:54,981 INFO org.apache.hadoop.yarn.server.resourcemanager.rmcontainer.RMContainerImpl: container_1377618433102_0004_01_000001 Container Transitioned from RUNNING to COMPLETED
2013-08-27 16:00:54,982 INFO org.apache.hadoop.yarn.server.resourcemanager.scheduler.common.fica.FiCaSchedulerApp: Completed container: container_1377618433102_0004_01_000001 in state: COMPLETED event:FINISHED
2013-08-27 16:00:54,982 INFO org.apache.hadoop.yarn.server.resourcemanager.rmapp.attempt.RMAppAttemptImpl: appattempt_1377618433102_0004_000001 State change from FINISHING to FINISHED
2013-08-27 16:00:54,982 INFO org.apache.hadoop.yarn.server.resourcemanager.RMAuditLogger: USER=ubuntu	OPERATION=AM Released Container	TARGET=SchedulerApp	RESULT=SUCCESS	APPID=application_1377618433102_0004	CONTAINERID=container_1377618433102_0004_01_000001
2013-08-27 16:00:54,982 INFO org.apache.hadoop.yarn.server.resourcemanager.rmapp.RMAppImpl: application_1377618433102_0004 State change from FINISHING to FINISHED
2013-08-27 16:00:54,982 INFO org.apache.hadoop.yarn.server.resourcemanager.RMAuditLogger: USER=ubuntu	OPERATION=Application Finished - Succeeded	TARGET=RMAppManager	RESULT=SUCCESS	APPID=application_1377618433102_0004
2013-08-27 16:00:54,982 INFO org.apache.hadoop.yarn.server.resourcemanager.scheduler.common.fica.FiCaSchedulerNode: Released container container_1377618433102_0004_01_000001 of capacity <memory:2048, vCores:1> on host hadoop-8-7:53314, which currently has 0 containers, <memory:0, vCores:0> used and <memory:8192, vCores:16> available, release resources=true
2013-08-27 16:00:54,983 INFO org.apache.hadoop.yarn.server.resourcemanager.recovery.RMStateStore: Removing info for app: application_1377618433102_0004
2013-08-27 16:00:54,983 INFO org.apache.hadoop.yarn.server.resourcemanager.scheduler.capacity.LeafQueue: default used=<memory:0, vCores:0> numContainers=0 user=ubuntu user-resources=<memory:0, vCores:0>
2013-08-27 16:00:54,983 INFO org.apache.hadoop.yarn.server.resourcemanager.RMAppManager$ApplicationSummary: appId=application_1377618433102_0004,name=TeraGen,user=ubuntu,queue=default,state=FINISHED,trackingUrl=hadoop-8-1.novalocal:8088/proxy/application_1377618433102_0004/jobhistory/job/job_1377618433102_0004,appMasterHost=hadoop-8-7,startTime=1377619069539,finishTime=1377619254420
2013-08-27 16:00:54,985 INFO org.apache.hadoop.yarn.server.resourcemanager.scheduler.capacity.LeafQueue: completedContainer container=Container: [ContainerId: container_1377618433102_0004_01_000001, NodeId: hadoop-8-7:53314, NodeHttpAddress: hadoop-8-7:8042, Resource: <memory:2048, vCores:1>, Priority: 0, State: NEW, Token: null, Status: container_id {, app_attempt_id {, application_id {, id: 4, cluster_timestamp: 1377618433102, }, attemptId: 1, }, id: 1, }, state: C_COMPLETE, diagnostics: "", exit_status: 0, ] resource=<memory:2048, vCores:1> queue=default: capacity=1.0, absoluteCapacity=1.0, usedResources=<memory:0, vCores:0>usedCapacity=0.0, absoluteUsedCapacity=0.0, numApps=1, numContainers=0 usedCapacity=0.0 absoluteUsedCapacity=0.0 used=<memory:0, vCores:0> cluster=<memory:49152, vCores:96>
2013-08-27 16:00:54,985 INFO org.apache.hadoop.yarn.server.resourcemanager.scheduler.capacity.ParentQueue: completedContainer queue=root usedCapacity=0.0 absoluteUsedCapacity=0.0 used=<memory:0, vCores:0> cluster=<memory:49152, vCores:96>
2013-08-27 16:00:54,985 INFO org.apache.hadoop.yarn.server.resourcemanager.scheduler.capacity.CapacityScheduler: Application appattempt_1377618433102_0004_000001 released container container_1377618433102_0004_01_000001 on node: host: hadoop-8-7:53314 #containers=0 available=8192 used=0 with event: FINISHED
2013-08-27 16:00:54,985 INFO org.apache.hadoop.yarn.server.resourcemanager.scheduler.capacity.CapacityScheduler: Application appattempt_1377618433102_0004_000001 is done. finalState=FINISHED
2013-08-27 16:00:54,985 INFO org.apache.hadoop.yarn.server.resourcemanager.scheduler.AppSchedulingInfo: Application application_1377618433102_0004 requests cleared
2013-08-27 16:00:54,986 INFO org.apache.hadoop.yarn.server.resourcemanager.scheduler.capacity.LeafQueue: Application removed - appId: application_1377618433102_0004 user: ubuntu queue: default #user-pending-applications: 0 #user-active-applications: 0 #queue-pending-applications: 0 #queue-active-applications: 0
2013-08-27 16:00:54,986 INFO org.apache.hadoop.yarn.server.resourcemanager.scheduler.capacity.ParentQueue: Application removed - appId: application_1377618433102_0004 user: ubuntu leaf-queue of parent: root #applications: 0
2013-08-27 16:00:54,991 INFO org.apache.hadoop.yarn.server.resourcemanager.amlauncher.AMLauncher: Cleaning master appattempt_1377618433102_0004_000001
2013-08-27 16:00:56,088 INFO org.apache.hadoop.yarn.server.resourcemanager.ClientRMService: Allocated new applicationId: 5
2013-08-27 16:00:59,019 INFO org.apache.hadoop.yarn.server.resourcemanager.ClientRMService: Storing Application with id application_1377618433102_0005
2013-08-27 16:00:59,019 INFO org.apache.hadoop.yarn.server.resourcemanager.recovery.RMStateStore: Storing info for app: application_1377618433102_0005
2013-08-27 16:00:59,019 INFO org.apache.hadoop.yarn.server.resourcemanager.ClientRMService: Application with id 5 submitted by user ubuntu
2013-08-27 16:00:59,019 INFO org.apache.hadoop.yarn.server.resourcemanager.RMAuditLogger: USER=ubuntu	IP=192.168.100.15	OPERATION=Submit Application Request	TARGET=ClientRMService	RESULT=SUCCESS	APPID=application_1377618433102_0005
2013-08-27 16:00:59,020 INFO org.apache.hadoop.yarn.server.resourcemanager.rmapp.RMAppImpl: application_1377618433102_0005 State change from NEW to SUBMITTED
2013-08-27 16:00:59,021 INFO org.apache.hadoop.yarn.server.resourcemanager.ApplicationMasterService: Registering appattempt_1377618433102_0005_000001
2013-08-27 16:00:59,021 INFO org.apache.hadoop.yarn.server.resourcemanager.rmapp.attempt.RMAppAttemptImpl: appattempt_1377618433102_0005_000001 State change from NEW to SUBMITTED
2013-08-27 16:00:59,021 INFO org.apache.hadoop.yarn.server.resourcemanager.scheduler.capacity.LeafQueue: Application application_1377618433102_0005 from user: ubuntu activated in queue: default
2013-08-27 16:00:59,021 INFO org.apache.hadoop.yarn.server.resourcemanager.scheduler.capacity.LeafQueue: Application added - appId: application_1377618433102_0005 user: org.apache.hadoop.yarn.server.resourcemanager.scheduler.capacity.LeafQueue$User@757ed18b, leaf-queue: default #user-pending-applications: 0 #user-active-applications: 1 #queue-pending-applications: 0 #queue-active-applications: 1
2013-08-27 16:00:59,021 INFO org.apache.hadoop.yarn.server.resourcemanager.scheduler.capacity.ParentQueue: Application added - appId: application_1377618433102_0005 user: ubuntu leaf-queue of parent: root #applications: 1
2013-08-27 16:00:59,022 INFO org.apache.hadoop.yarn.server.resourcemanager.scheduler.capacity.CapacityScheduler: Application Submission: appattempt_1377618433102_0005_000001, user: ubuntu queue: default: capacity=1.0, absoluteCapacity=1.0, usedResources=<memory:0, vCores:0>usedCapacity=0.0, absoluteUsedCapacity=0.0, numApps=1, numContainers=0, currently active: 1
2013-08-27 16:00:59,022 INFO org.apache.hadoop.yarn.server.resourcemanager.rmapp.attempt.RMAppAttemptImpl: appattempt_1377618433102_0005_000001 State change from SUBMITTED to SCHEDULED
2013-08-27 16:00:59,022 INFO org.apache.hadoop.yarn.server.resourcemanager.rmapp.RMAppImpl: application_1377618433102_0005 State change from SUBMITTED to ACCEPTED
2013-08-27 16:00:59,223 INFO org.apache.hadoop.yarn.server.resourcemanager.rmcontainer.RMContainerImpl: container_1377618433102_0005_01_000001 Container Transitioned from NEW to ALLOCATED
2013-08-27 16:00:59,223 INFO org.apache.hadoop.yarn.server.resourcemanager.RMAuditLogger: USER=ubuntu	OPERATION=AM Allocated Container	TARGET=SchedulerApp	RESULT=SUCCESS	APPID=application_1377618433102_0005	CONTAINERID=container_1377618433102_0005_01_000001
2013-08-27 16:00:59,224 INFO org.apache.hadoop.yarn.server.resourcemanager.scheduler.common.fica.FiCaSchedulerNode: Assigned container container_1377618433102_0005_01_000001 of capacity <memory:2048, vCores:1> on host hadoop-8-6:45732, which currently has 1 containers, <memory:2048, vCores:1> used and <memory:6144, vCores:15> available
2013-08-27 16:00:59,225 INFO org.apache.hadoop.yarn.server.resourcemanager.scheduler.capacity.LeafQueue: assignedContainer application=application_1377618433102_0005 container=Container: [ContainerId: container_1377618433102_0005_01_000001, NodeId: hadoop-8-6:45732, NodeHttpAddress: hadoop-8-6:8042, Resource: <memory:2048, vCores:1>, Priority: 0, State: NEW, Token: null, Status: container_id {, app_attempt_id {, application_id {, id: 5, cluster_timestamp: 1377618433102, }, attemptId: 1, }, id: 1, }, state: C_NEW, ] containerId=container_1377618433102_0005_01_000001 queue=default: capacity=1.0, absoluteCapacity=1.0, usedResources=<memory:0, vCores:0>usedCapacity=0.0, absoluteUsedCapacity=0.0, numApps=1, numContainers=0 usedCapacity=0.0 absoluteUsedCapacity=0.0 used=<memory:0, vCores:0> cluster=<memory:49152, vCores:96>
2013-08-27 16:00:59,225 INFO org.apache.hadoop.yarn.server.resourcemanager.scheduler.capacity.ParentQueue: Re-sorting queues since queue: root.default stats: default: capacity=1.0, absoluteCapacity=1.0, usedResources=<memory:2048, vCores:1>usedCapacity=0.041666668, absoluteUsedCapacity=0.041666668, numApps=1, numContainers=1
2013-08-27 16:00:59,225 INFO org.apache.hadoop.yarn.server.resourcemanager.scheduler.capacity.ParentQueue: assignedContainer queue=root usedCapacity=0.041666668 absoluteUsedCapacity=0.041666668 used=<memory:2048, vCores:1> cluster=<memory:49152, vCores:96>
2013-08-27 16:00:59,227 INFO org.apache.hadoop.yarn.server.resourcemanager.rmcontainer.RMContainerImpl: container_1377618433102_0005_01_000001 Container Transitioned from ALLOCATED to ACQUIRED
2013-08-27 16:00:59,228 INFO org.apache.hadoop.yarn.server.resourcemanager.rmapp.attempt.RMAppAttemptImpl: Storing attempt: AppId: application_1377618433102_0005 AttemptId: appattempt_1377618433102_0005_000001 MasterContainer: Container: [ContainerId: container_1377618433102_0005_01_000001, NodeId: hadoop-8-6:45732, NodeHttpAddress: hadoop-8-6:8042, Resource: <memory:2048, vCores:1>, Priority: 0, State: NEW, Token: null, Status: container_id {, app_attempt_id {, application_id {, id: 5, cluster_timestamp: 1377618433102, }, attemptId: 1, }, id: 1, }, state: C_NEW, ]
2013-08-27 16:00:59,229 INFO org.apache.hadoop.yarn.server.resourcemanager.rmapp.attempt.RMAppAttemptImpl: appattempt_1377618433102_0005_000001 State change from SCHEDULED to ALLOCATED_SAVING
2013-08-27 16:00:59,229 INFO org.apache.hadoop.yarn.server.resourcemanager.recovery.RMStateStore: Storing info for attempt: appattempt_1377618433102_0005_000001
2013-08-27 16:00:59,230 INFO org.apache.hadoop.yarn.server.resourcemanager.rmapp.attempt.RMAppAttemptImpl: appattempt_1377618433102_0005_000001 State change from ALLOCATED_SAVING to ALLOCATED
2013-08-27 16:00:59,231 INFO org.apache.hadoop.yarn.server.resourcemanager.amlauncher.AMLauncher: Launching masterappattempt_1377618433102_0005_000001
2013-08-27 16:00:59,233 INFO org.apache.hadoop.yarn.server.resourcemanager.amlauncher.AMLauncher: Setting up container Container: [ContainerId: container_1377618433102_0005_01_000001, NodeId: hadoop-8-6:45732, NodeHttpAddress: hadoop-8-6:8042, Resource: <memory:2048, vCores:1>, Priority: 0, State: NEW, Token: null, Status: container_id {, app_attempt_id {, application_id {, id: 5, cluster_timestamp: 1377618433102, }, attemptId: 1, }, id: 1, }, state: C_NEW, ] for AM appattempt_1377618433102_0005_000001
2013-08-27 16:00:59,234 INFO org.apache.hadoop.yarn.server.resourcemanager.amlauncher.AMLauncher: Command to launch container container_1377618433102_0005_01_000001 : $JAVA_HOME/bin/java -Dlog4j.configuration=container-log4j.properties -Dyarn.app.mapreduce.container.log.dir=<LOG_DIR> -Dyarn.app.mapreduce.container.log.filesize=0 -Dhadoop.root.logger=INFO,CLA  -Xmx1024m org.apache.hadoop.mapreduce.v2.app.MRAppMaster 1><LOG_DIR>/stdout 2><LOG_DIR>/stderr 
2013-08-27 16:01:00,016 INFO org.apache.hadoop.yarn.server.resourcemanager.amlauncher.AMLauncher: Done launching container Container: [ContainerId: container_1377618433102_0005_01_000001, NodeId: hadoop-8-6:45732, NodeHttpAddress: hadoop-8-6:8042, Resource: <memory:2048, vCores:1>, Priority: 0, State: NEW, Token: null, Status: container_id {, app_attempt_id {, application_id {, id: 5, cluster_timestamp: 1377618433102, }, attemptId: 1, }, id: 1, }, state: C_NEW, ] for AM appattempt_1377618433102_0005_000001
2013-08-27 16:01:00,017 INFO org.apache.hadoop.yarn.server.resourcemanager.rmapp.attempt.RMAppAttemptImpl: appattempt_1377618433102_0005_000001 State change from ALLOCATED to LAUNCHED
2013-08-27 16:01:00,308 INFO org.apache.hadoop.yarn.server.resourcemanager.rmcontainer.RMContainerImpl: container_1377618433102_0005_01_000001 Container Transitioned from ACQUIRED to RUNNING
2013-08-27 16:01:09,856 INFO org.apache.hadoop.yarn.server.resourcemanager.ApplicationMasterService: AM registration appattempt_1377618433102_0005_000001
2013-08-27 16:01:09,857 INFO org.apache.hadoop.yarn.server.resourcemanager.RMAuditLogger: USER=ubuntu	IP=192.168.100.26	OPERATION=Register App Master	TARGET=ApplicationMasterService	RESULT=SUCCESS	APPID=application_1377618433102_0005	APPATTEMPTID=appattempt_1377618433102_0005_000001
2013-08-27 16:01:09,857 INFO org.apache.hadoop.yarn.server.resourcemanager.rmapp.attempt.RMAppAttemptImpl: appattempt_1377618433102_0005_000001 State change from LAUNCHED to RUNNING
2013-08-27 16:01:09,858 INFO org.apache.hadoop.yarn.server.resourcemanager.rmapp.RMAppImpl: application_1377618433102_0005 State change from ACCEPTED to RUNNING
2013-08-27 16:01:10,955 INFO org.apache.hadoop.yarn.server.resourcemanager.rmcontainer.RMContainerImpl: container_1377618433102_0005_01_000002 Container Transitioned from NEW to ALLOCATED
2013-08-27 16:01:10,956 INFO org.apache.hadoop.yarn.server.resourcemanager.RMAuditLogger: USER=ubuntu	OPERATION=AM Allocated Container	TARGET=SchedulerApp	RESULT=SUCCESS	APPID=application_1377618433102_0005	CONTAINERID=container_1377618433102_0005_01_000002
2013-08-27 16:01:10,956 INFO org.apache.hadoop.yarn.server.resourcemanager.scheduler.common.fica.FiCaSchedulerNode: Assigned container container_1377618433102_0005_01_000002 of capacity <memory:1024, vCores:1> on host hadoop-8-3:42074, which currently has 1 containers, <memory:1024, vCores:1> used and <memory:7168, vCores:15> available
2013-08-27 16:01:10,957 INFO org.apache.hadoop.yarn.server.resourcemanager.scheduler.capacity.LeafQueue: assignedContainer application=application_1377618433102_0005 container=Container: [ContainerId: container_1377618433102_0005_01_000002, NodeId: hadoop-8-3:42074, NodeHttpAddress: hadoop-8-3:8042, Resource: <memory:1024, vCores:1>, Priority: 20, State: NEW, Token: null, Status: container_id {, app_attempt_id {, application_id {, id: 5, cluster_timestamp: 1377618433102, }, attemptId: 1, }, id: 2, }, state: C_NEW, ] containerId=container_1377618433102_0005_01_000002 queue=default: capacity=1.0, absoluteCapacity=1.0, usedResources=<memory:2048, vCores:1>usedCapacity=0.041666668, absoluteUsedCapacity=0.041666668, numApps=1, numContainers=1 usedCapacity=0.041666668 absoluteUsedCapacity=0.041666668 used=<memory:2048, vCores:1> cluster=<memory:49152, vCores:96>
2013-08-27 16:01:10,957 INFO org.apache.hadoop.yarn.server.resourcemanager.scheduler.capacity.ParentQueue: Re-sorting queues since queue: root.default stats: default: capacity=1.0, absoluteCapacity=1.0, usedResources=<memory:3072, vCores:2>usedCapacity=0.0625, absoluteUsedCapacity=0.0625, numApps=1, numContainers=2
2013-08-27 16:01:10,958 INFO org.apache.hadoop.yarn.server.resourcemanager.scheduler.capacity.ParentQueue: assignedContainer queue=root usedCapacity=0.0625 absoluteUsedCapacity=0.0625 used=<memory:3072, vCores:2> cluster=<memory:49152, vCores:96>
2013-08-27 16:01:11,038 INFO org.apache.hadoop.yarn.server.resourcemanager.rmcontainer.RMContainerImpl: container_1377618433102_0005_01_000003 Container Transitioned from NEW to ALLOCATED
2013-08-27 16:01:11,039 INFO org.apache.hadoop.yarn.server.resourcemanager.RMAuditLogger: USER=ubuntu	OPERATION=AM Allocated Container	TARGET=SchedulerApp	RESULT=SUCCESS	APPID=application_1377618433102_0005	CONTAINERID=container_1377618433102_0005_01_000003
2013-08-27 16:01:11,039 INFO org.apache.hadoop.yarn.server.resourcemanager.scheduler.common.fica.FiCaSchedulerNode: Assigned container container_1377618433102_0005_01_000003 of capacity <memory:1024, vCores:1> on host hadoop-8-7:53314, which currently has 1 containers, <memory:1024, vCores:1> used and <memory:7168, vCores:15> available
2013-08-27 16:01:11,040 INFO org.apache.hadoop.yarn.server.resourcemanager.scheduler.capacity.LeafQueue: assignedContainer application=application_1377618433102_0005 container=Container: [ContainerId: container_1377618433102_0005_01_000003, NodeId: hadoop-8-7:53314, NodeHttpAddress: hadoop-8-7:8042, Resource: <memory:1024, vCores:1>, Priority: 20, State: NEW, Token: null, Status: container_id {, app_attempt_id {, application_id {, id: 5, cluster_timestamp: 1377618433102, }, attemptId: 1, }, id: 3, }, state: C_NEW, ] containerId=container_1377618433102_0005_01_000003 queue=default: capacity=1.0, absoluteCapacity=1.0, usedResources=<memory:3072, vCores:2>usedCapacity=0.0625, absoluteUsedCapacity=0.0625, numApps=1, numContainers=2 usedCapacity=0.0625 absoluteUsedCapacity=0.0625 used=<memory:3072, vCores:2> cluster=<memory:49152, vCores:96>
2013-08-27 16:01:11,040 INFO org.apache.hadoop.yarn.server.resourcemanager.scheduler.capacity.ParentQueue: Re-sorting queues since queue: root.default stats: default: capacity=1.0, absoluteCapacity=1.0, usedResources=<memory:4096, vCores:3>usedCapacity=0.083333336, absoluteUsedCapacity=0.083333336, numApps=1, numContainers=3
2013-08-27 16:01:11,040 INFO org.apache.hadoop.yarn.server.resourcemanager.scheduler.capacity.ParentQueue: assignedContainer queue=root usedCapacity=0.083333336 absoluteUsedCapacity=0.083333336 used=<memory:4096, vCores:3> cluster=<memory:49152, vCores:96>
2013-08-27 16:01:11,967 INFO org.apache.hadoop.yarn.server.resourcemanager.rmcontainer.RMContainerImpl: container_1377618433102_0005_01_000002 Container Transitioned from ALLOCATED to ACQUIRED
2013-08-27 16:01:11,969 INFO org.apache.hadoop.yarn.server.resourcemanager.rmcontainer.RMContainerImpl: container_1377618433102_0005_01_000003 Container Transitioned from ALLOCATED to ACQUIRED
2013-08-27 16:01:12,966 INFO org.apache.hadoop.yarn.server.resourcemanager.rmcontainer.RMContainerImpl: container_1377618433102_0005_01_000002 Container Transitioned from ACQUIRED to RUNNING
2013-08-27 16:01:13,000 INFO org.apache.hadoop.yarn.server.resourcemanager.scheduler.AppSchedulingInfo: checking for deactivate... 
2013-08-27 16:01:13,048 INFO org.apache.hadoop.yarn.server.resourcemanager.rmcontainer.RMContainerImpl: container_1377618433102_0005_01_000003 Container Transitioned from ACQUIRED to RUNNING
2013-08-27 16:04:10,689 INFO org.apache.hadoop.yarn.server.resourcemanager.rmcontainer.RMContainerImpl: container_1377618433102_0005_01_000003 Container Transitioned from RUNNING to COMPLETED
2013-08-27 16:04:10,690 INFO org.apache.hadoop.yarn.server.resourcemanager.scheduler.common.fica.FiCaSchedulerApp: Completed container: container_1377618433102_0005_01_000003 in state: COMPLETED event:FINISHED
2013-08-27 16:04:10,690 INFO org.apache.hadoop.yarn.server.resourcemanager.RMAuditLogger: USER=ubuntu	OPERATION=AM Released Container	TARGET=SchedulerApp	RESULT=SUCCESS	APPID=application_1377618433102_0005	CONTAINERID=container_1377618433102_0005_01_000003
2013-08-27 16:04:10,690 INFO org.apache.hadoop.yarn.server.resourcemanager.scheduler.common.fica.FiCaSchedulerNode: Released container container_1377618433102_0005_01_000003 of capacity <memory:1024, vCores:1> on host hadoop-8-7:53314, which currently has 0 containers, <memory:0, vCores:0> used and <memory:8192, vCores:16> available, release resources=true
2013-08-27 16:04:10,690 INFO org.apache.hadoop.yarn.server.resourcemanager.scheduler.capacity.LeafQueue: default used=<memory:3072, vCores:2> numContainers=2 user=ubuntu user-resources=<memory:3072, vCores:2>
2013-08-27 16:04:10,692 INFO org.apache.hadoop.yarn.server.resourcemanager.scheduler.capacity.LeafQueue: completedContainer container=Container: [ContainerId: container_1377618433102_0005_01_000003, NodeId: hadoop-8-7:53314, NodeHttpAddress: hadoop-8-7:8042, Resource: <memory:1024, vCores:1>, Priority: 20, State: NEW, Token: null, Status: container_id {, app_attempt_id {, application_id {, id: 5, cluster_timestamp: 1377618433102, }, attemptId: 1, }, id: 3, }, state: C_COMPLETE, diagnostics: "Container killed by the ApplicationMaster.\n\n", exit_status: 143, ] resource=<memory:1024, vCores:1> queue=default: capacity=1.0, absoluteCapacity=1.0, usedResources=<memory:3072, vCores:2>usedCapacity=0.0625, absoluteUsedCapacity=0.0625, numApps=1, numContainers=2 usedCapacity=0.0625 absoluteUsedCapacity=0.0625 used=<memory:3072, vCores:2> cluster=<memory:49152, vCores:96>
2013-08-27 16:04:10,692 INFO org.apache.hadoop.yarn.server.resourcemanager.scheduler.capacity.ParentQueue: completedContainer queue=root usedCapacity=0.0625 absoluteUsedCapacity=0.0625 used=<memory:3072, vCores:2> cluster=<memory:49152, vCores:96>
2013-08-27 16:04:10,692 INFO org.apache.hadoop.yarn.server.resourcemanager.scheduler.capacity.CapacityScheduler: Application appattempt_1377618433102_0005_000001 released container container_1377618433102_0005_01_000003 on node: host: hadoop-8-7:53314 #containers=0 available=8192 used=0 with event: FINISHED
2013-08-27 16:04:14,216 INFO org.apache.hadoop.yarn.server.resourcemanager.rmcontainer.RMContainerImpl: container_1377618433102_0005_01_000002 Container Transitioned from RUNNING to COMPLETED
2013-08-27 16:04:14,217 INFO org.apache.hadoop.yarn.server.resourcemanager.scheduler.common.fica.FiCaSchedulerApp: Completed container: container_1377618433102_0005_01_000002 in state: COMPLETED event:FINISHED
2013-08-27 16:04:14,217 INFO org.apache.hadoop.yarn.server.resourcemanager.RMAuditLogger: USER=ubuntu	OPERATION=AM Released Container	TARGET=SchedulerApp	RESULT=SUCCESS	APPID=application_1377618433102_0005	CONTAINERID=container_1377618433102_0005_01_000002
2013-08-27 16:04:14,218 INFO org.apache.hadoop.yarn.server.resourcemanager.scheduler.common.fica.FiCaSchedulerNode: Released container container_1377618433102_0005_01_000002 of capacity <memory:1024, vCores:1> on host hadoop-8-3:42074, which currently has 0 containers, <memory:0, vCores:0> used and <memory:8192, vCores:16> available, release resources=true
2013-08-27 16:04:14,218 INFO org.apache.hadoop.yarn.server.resourcemanager.scheduler.capacity.LeafQueue: default used=<memory:2048, vCores:1> numContainers=1 user=ubuntu user-resources=<memory:2048, vCores:1>
2013-08-27 16:04:14,219 INFO org.apache.hadoop.yarn.server.resourcemanager.scheduler.capacity.LeafQueue: completedContainer container=Container: [ContainerId: container_1377618433102_0005_01_000002, NodeId: hadoop-8-3:42074, NodeHttpAddress: hadoop-8-3:8042, Resource: <memory:1024, vCores:1>, Priority: 20, State: NEW, Token: null, Status: container_id {, app_attempt_id {, application_id {, id: 5, cluster_timestamp: 1377618433102, }, attemptId: 1, }, id: 2, }, state: C_COMPLETE, diagnostics: "Container killed by the ApplicationMaster.\n\n", exit_status: 143, ] resource=<memory:1024, vCores:1> queue=default: capacity=1.0, absoluteCapacity=1.0, usedResources=<memory:2048, vCores:1>usedCapacity=0.041666668, absoluteUsedCapacity=0.041666668, numApps=1, numContainers=1 usedCapacity=0.041666668 absoluteUsedCapacity=0.041666668 used=<memory:2048, vCores:1> cluster=<memory:49152, vCores:96>
2013-08-27 16:04:14,220 INFO org.apache.hadoop.yarn.server.resourcemanager.scheduler.capacity.ParentQueue: completedContainer queue=root usedCapacity=0.041666668 absoluteUsedCapacity=0.041666668 used=<memory:2048, vCores:1> cluster=<memory:49152, vCores:96>
2013-08-27 16:04:14,220 INFO org.apache.hadoop.yarn.server.resourcemanager.scheduler.capacity.CapacityScheduler: Application appattempt_1377618433102_0005_000001 released container container_1377618433102_0005_01_000002 on node: host: hadoop-8-3:42074 #containers=0 available=8192 used=0 with event: FINISHED
2013-08-27 16:04:18,379 INFO org.apache.hadoop.yarn.server.resourcemanager.rmapp.attempt.RMAppAttemptImpl: appattempt_1377618433102_0005_000001 State change from RUNNING to FINISHING
2013-08-27 16:04:18,380 INFO org.apache.hadoop.yarn.server.resourcemanager.rmapp.RMAppImpl: application_1377618433102_0005 State change from RUNNING to FINISHING
2013-08-27 16:04:19,209 INFO org.apache.hadoop.yarn.server.resourcemanager.rmcontainer.RMContainerImpl: container_1377618433102_0005_01_000001 Container Transitioned from RUNNING to COMPLETED
2013-08-27 16:04:19,209 INFO org.apache.hadoop.yarn.server.resourcemanager.scheduler.common.fica.FiCaSchedulerApp: Completed container: container_1377618433102_0005_01_000001 in state: COMPLETED event:FINISHED
2013-08-27 16:04:19,209 INFO org.apache.hadoop.yarn.server.resourcemanager.rmapp.attempt.RMAppAttemptImpl: appattempt_1377618433102_0005_000001 State change from FINISHING to FINISHED
2013-08-27 16:04:19,209 INFO org.apache.hadoop.yarn.server.resourcemanager.RMAuditLogger: USER=ubuntu	OPERATION=AM Released Container	TARGET=SchedulerApp	RESULT=SUCCESS	APPID=application_1377618433102_0005	CONTAINERID=container_1377618433102_0005_01_000001
2013-08-27 16:04:19,210 INFO org.apache.hadoop.yarn.server.resourcemanager.rmapp.RMAppImpl: application_1377618433102_0005 State change from FINISHING to FINISHED
2013-08-27 16:04:19,210 INFO org.apache.hadoop.yarn.server.resourcemanager.scheduler.common.fica.FiCaSchedulerNode: Released container container_1377618433102_0005_01_000001 of capacity <memory:2048, vCores:1> on host hadoop-8-6:45732, which currently has 0 containers, <memory:0, vCores:0> used and <memory:8192, vCores:16> available, release resources=true
2013-08-27 16:04:19,210 INFO org.apache.hadoop.yarn.server.resourcemanager.RMAuditLogger: USER=ubuntu	OPERATION=Application Finished - Succeeded	TARGET=RMAppManager	RESULT=SUCCESS	APPID=application_1377618433102_0005
2013-08-27 16:04:19,210 INFO org.apache.hadoop.yarn.server.resourcemanager.scheduler.capacity.LeafQueue: default used=<memory:0, vCores:0> numContainers=0 user=ubuntu user-resources=<memory:0, vCores:0>
2013-08-27 16:04:19,210 INFO org.apache.hadoop.yarn.server.resourcemanager.recovery.RMStateStore: Removing info for app: application_1377618433102_0005
2013-08-27 16:04:19,211 INFO org.apache.hadoop.yarn.server.resourcemanager.amlauncher.AMLauncher: Cleaning master appattempt_1377618433102_0005_000001
2013-08-27 16:04:19,211 INFO org.apache.hadoop.yarn.server.resourcemanager.RMAppManager$ApplicationSummary: appId=application_1377618433102_0005,name=TeraGen,user=ubuntu,queue=default,state=FINISHED,trackingUrl=hadoop-8-1.novalocal:8088/proxy/application_1377618433102_0005/jobhistory/job/job_1377618433102_0005,appMasterHost=hadoop-8-6,startTime=1377619259018,finishTime=1377619458380
2013-08-27 16:04:19,212 INFO org.apache.hadoop.yarn.server.resourcemanager.scheduler.capacity.LeafQueue: completedContainer container=Container: [ContainerId: container_1377618433102_0005_01_000001, NodeId: hadoop-8-6:45732, NodeHttpAddress: hadoop-8-6:8042, Resource: <memory:2048, vCores:1>, Priority: 0, State: NEW, Token: null, Status: container_id {, app_attempt_id {, application_id {, id: 5, cluster_timestamp: 1377618433102, }, attemptId: 1, }, id: 1, }, state: C_COMPLETE, diagnostics: "", exit_status: 0, ] resource=<memory:2048, vCores:1> queue=default: capacity=1.0, absoluteCapacity=1.0, usedResources=<memory:0, vCores:0>usedCapacity=0.0, absoluteUsedCapacity=0.0, numApps=1, numContainers=0 usedCapacity=0.0 absoluteUsedCapacity=0.0 used=<memory:0, vCores:0> cluster=<memory:49152, vCores:96>
2013-08-27 16:04:19,212 INFO org.apache.hadoop.yarn.server.resourcemanager.scheduler.capacity.ParentQueue: completedContainer queue=root usedCapacity=0.0 absoluteUsedCapacity=0.0 used=<memory:0, vCores:0> cluster=<memory:49152, vCores:96>
2013-08-27 16:04:19,212 INFO org.apache.hadoop.yarn.server.resourcemanager.scheduler.capacity.CapacityScheduler: Application appattempt_1377618433102_0005_000001 released container container_1377618433102_0005_01_000001 on node: host: hadoop-8-6:45732 #containers=0 available=8192 used=0 with event: FINISHED
2013-08-27 16:04:19,212 INFO org.apache.hadoop.yarn.server.resourcemanager.scheduler.capacity.CapacityScheduler: Application appattempt_1377618433102_0005_000001 is done. finalState=FINISHED
2013-08-27 16:04:19,212 INFO org.apache.hadoop.yarn.server.resourcemanager.scheduler.AppSchedulingInfo: Application application_1377618433102_0005 requests cleared
2013-08-27 16:04:19,212 INFO org.apache.hadoop.yarn.server.resourcemanager.scheduler.capacity.LeafQueue: Application removed - appId: application_1377618433102_0005 user: ubuntu queue: default #user-pending-applications: 0 #user-active-applications: 0 #queue-pending-applications: 0 #queue-active-applications: 0
2013-08-27 16:04:19,212 INFO org.apache.hadoop.yarn.server.resourcemanager.scheduler.capacity.ParentQueue: Application removed - appId: application_1377618433102_0005 user: ubuntu leaf-queue of parent: root #applications: 0
2013-08-27 16:04:35,407 INFO org.apache.hadoop.yarn.server.resourcemanager.ClientRMService: Allocated new applicationId: 6
2013-08-27 16:04:35,567 INFO org.apache.hadoop.yarn.server.resourcemanager.ClientRMService: Allocated new applicationId: 7
2013-08-27 16:04:35,700 INFO org.apache.hadoop.yarn.server.resourcemanager.ClientRMService: Allocated new applicationId: 8
2013-08-27 16:04:36,048 INFO org.apache.hadoop.yarn.server.resourcemanager.ClientRMService: Allocated new applicationId: 9
2013-08-27 16:04:36,330 INFO org.apache.hadoop.yarn.server.resourcemanager.ClientRMService: Allocated new applicationId: 10
2013-08-27 16:04:37,137 INFO org.apache.hadoop.yarn.server.resourcemanager.ClientRMService: Storing Application with id application_1377618433102_0006
2013-08-27 16:04:37,138 INFO org.apache.hadoop.yarn.server.resourcemanager.recovery.RMStateStore: Storing info for app: application_1377618433102_0006
2013-08-27 16:04:37,138 INFO org.apache.hadoop.yarn.server.resourcemanager.ClientRMService: Application with id 6 submitted by user ubuntu
2013-08-27 16:04:37,138 INFO org.apache.hadoop.yarn.server.resourcemanager.RMAuditLogger: USER=ubuntu	IP=192.168.100.15	OPERATION=Submit Application Request	TARGET=ClientRMService	RESULT=SUCCESS	APPID=application_1377618433102_0006
2013-08-27 16:04:37,139 INFO org.apache.hadoop.yarn.server.resourcemanager.rmapp.RMAppImpl: application_1377618433102_0006 State change from NEW to SUBMITTED
2013-08-27 16:04:37,139 INFO org.apache.hadoop.yarn.server.resourcemanager.ApplicationMasterService: Registering appattempt_1377618433102_0006_000001
2013-08-27 16:04:37,139 INFO org.apache.hadoop.yarn.server.resourcemanager.rmapp.attempt.RMAppAttemptImpl: appattempt_1377618433102_0006_000001 State change from NEW to SUBMITTED
2013-08-27 16:04:37,139 INFO org.apache.hadoop.yarn.server.resourcemanager.scheduler.capacity.LeafQueue: Application application_1377618433102_0006 from user: ubuntu activated in queue: default
2013-08-27 16:04:37,139 INFO org.apache.hadoop.yarn.server.resourcemanager.scheduler.capacity.LeafQueue: Application added - appId: application_1377618433102_0006 user: org.apache.hadoop.yarn.server.resourcemanager.scheduler.capacity.LeafQueue$User@24eca8f6, leaf-queue: default #user-pending-applications: 0 #user-active-applications: 1 #queue-pending-applications: 0 #queue-active-applications: 1
2013-08-27 16:04:37,139 INFO org.apache.hadoop.yarn.server.resourcemanager.scheduler.capacity.ParentQueue: Application added - appId: application_1377618433102_0006 user: ubuntu leaf-queue of parent: root #applications: 1
2013-08-27 16:04:37,140 INFO org.apache.hadoop.yarn.server.resourcemanager.scheduler.capacity.CapacityScheduler: Application Submission: appattempt_1377618433102_0006_000001, user: ubuntu queue: default: capacity=1.0, absoluteCapacity=1.0, usedResources=<memory:0, vCores:0>usedCapacity=0.0, absoluteUsedCapacity=0.0, numApps=1, numContainers=0, currently active: 1
2013-08-27 16:04:37,141 INFO org.apache.hadoop.yarn.server.resourcemanager.rmapp.attempt.RMAppAttemptImpl: appattempt_1377618433102_0006_000001 State change from SUBMITTED to SCHEDULED
2013-08-27 16:04:37,141 INFO org.apache.hadoop.yarn.server.resourcemanager.rmapp.RMAppImpl: application_1377618433102_0006 State change from SUBMITTED to ACCEPTED
2013-08-27 16:04:37,212 INFO org.apache.hadoop.yarn.server.resourcemanager.ClientRMService: Storing Application with id application_1377618433102_0007
2013-08-27 16:04:37,212 INFO org.apache.hadoop.yarn.server.resourcemanager.recovery.RMStateStore: Storing info for app: application_1377618433102_0007
2013-08-27 16:04:37,212 INFO org.apache.hadoop.yarn.server.resourcemanager.ClientRMService: Application with id 7 submitted by user ubuntu
2013-08-27 16:04:37,212 INFO org.apache.hadoop.yarn.server.resourcemanager.RMAuditLogger: USER=ubuntu	IP=192.168.100.15	OPERATION=Submit Application Request	TARGET=ClientRMService	RESULT=SUCCESS	APPID=application_1377618433102_0007
2013-08-27 16:04:37,213 INFO org.apache.hadoop.yarn.server.resourcemanager.rmapp.RMAppImpl: application_1377618433102_0007 State change from NEW to SUBMITTED
2013-08-27 16:04:37,213 INFO org.apache.hadoop.yarn.server.resourcemanager.ApplicationMasterService: Registering appattempt_1377618433102_0007_000001
2013-08-27 16:04:37,213 INFO org.apache.hadoop.yarn.server.resourcemanager.rmapp.attempt.RMAppAttemptImpl: appattempt_1377618433102_0007_000001 State change from NEW to SUBMITTED
2013-08-27 16:04:37,213 INFO org.apache.hadoop.yarn.server.resourcemanager.scheduler.capacity.LeafQueue: Application application_1377618433102_0007 from user: ubuntu activated in queue: default
2013-08-27 16:04:37,214 INFO org.apache.hadoop.yarn.server.resourcemanager.scheduler.capacity.LeafQueue: Application added - appId: application_1377618433102_0007 user: org.apache.hadoop.yarn.server.resourcemanager.scheduler.capacity.LeafQueue$User@24eca8f6, leaf-queue: default #user-pending-applications: 0 #user-active-applications: 2 #queue-pending-applications: 0 #queue-active-applications: 2
2013-08-27 16:04:37,214 INFO org.apache.hadoop.yarn.server.resourcemanager.scheduler.capacity.ParentQueue: Application added - appId: application_1377618433102_0007 user: ubuntu leaf-queue of parent: root #applications: 2
2013-08-27 16:04:37,214 INFO org.apache.hadoop.yarn.server.resourcemanager.scheduler.capacity.CapacityScheduler: Application Submission: appattempt_1377618433102_0007_000001, user: ubuntu queue: default: capacity=1.0, absoluteCapacity=1.0, usedResources=<memory:0, vCores:0>usedCapacity=0.0, absoluteUsedCapacity=0.0, numApps=2, numContainers=0, currently active: 2
2013-08-27 16:04:37,214 INFO org.apache.hadoop.yarn.server.resourcemanager.rmapp.attempt.RMAppAttemptImpl: appattempt_1377618433102_0007_000001 State change from SUBMITTED to SCHEDULED
2013-08-27 16:04:37,214 INFO org.apache.hadoop.yarn.server.resourcemanager.rmapp.RMAppImpl: application_1377618433102_0007 State change from SUBMITTED to ACCEPTED
2013-08-27 16:04:37,233 INFO org.apache.hadoop.yarn.server.resourcemanager.rmcontainer.RMContainerImpl: container_1377618433102_0006_01_000001 Container Transitioned from NEW to ALLOCATED
2013-08-27 16:04:37,233 INFO org.apache.hadoop.yarn.server.resourcemanager.RMAuditLogger: USER=ubuntu	OPERATION=AM Allocated Container	TARGET=SchedulerApp	RESULT=SUCCESS	APPID=application_1377618433102_0006	CONTAINERID=container_1377618433102_0006_01_000001
2013-08-27 16:04:37,234 INFO org.apache.hadoop.yarn.server.resourcemanager.scheduler.common.fica.FiCaSchedulerNode: Assigned container container_1377618433102_0006_01_000001 of capacity <memory:2048, vCores:1> on host hadoop-8-4:36803, which currently has 1 containers, <memory:2048, vCores:1> used and <memory:6144, vCores:15> available
2013-08-27 16:04:37,234 INFO org.apache.hadoop.yarn.server.resourcemanager.scheduler.capacity.LeafQueue: assignedContainer application=application_1377618433102_0006 container=Container: [ContainerId: container_1377618433102_0006_01_000001, NodeId: hadoop-8-4:36803, NodeHttpAddress: hadoop-8-4:8042, Resource: <memory:2048, vCores:1>, Priority: 0, State: NEW, Token: null, Status: container_id {, app_attempt_id {, application_id {, id: 6, cluster_timestamp: 1377618433102, }, attemptId: 1, }, id: 1, }, state: C_NEW, ] containerId=container_1377618433102_0006_01_000001 queue=default: capacity=1.0, absoluteCapacity=1.0, usedResources=<memory:0, vCores:0>usedCapacity=0.0, absoluteUsedCapacity=0.0, numApps=2, numContainers=0 usedCapacity=0.0 absoluteUsedCapacity=0.0 used=<memory:0, vCores:0> cluster=<memory:49152, vCores:96>
2013-08-27 16:04:37,234 INFO org.apache.hadoop.yarn.server.resourcemanager.scheduler.capacity.ParentQueue: Re-sorting queues since queue: root.default stats: default: capacity=1.0, absoluteCapacity=1.0, usedResources=<memory:2048, vCores:1>usedCapacity=0.041666668, absoluteUsedCapacity=0.041666668, numApps=2, numContainers=1
2013-08-27 16:04:37,235 INFO org.apache.hadoop.yarn.server.resourcemanager.scheduler.capacity.ParentQueue: assignedContainer queue=root usedCapacity=0.041666668 absoluteUsedCapacity=0.041666668 used=<memory:2048, vCores:1> cluster=<memory:49152, vCores:96>
2013-08-27 16:04:37,236 INFO org.apache.hadoop.yarn.server.resourcemanager.rmcontainer.RMContainerImpl: container_1377618433102_0006_01_000001 Container Transitioned from ALLOCATED to ACQUIRED
2013-08-27 16:04:37,237 INFO org.apache.hadoop.yarn.server.resourcemanager.rmapp.attempt.RMAppAttemptImpl: Storing attempt: AppId: application_1377618433102_0006 AttemptId: appattempt_1377618433102_0006_000001 MasterContainer: Container: [ContainerId: container_1377618433102_0006_01_000001, NodeId: hadoop-8-4:36803, NodeHttpAddress: hadoop-8-4:8042, Resource: <memory:2048, vCores:1>, Priority: 0, State: NEW, Token: null, Status: container_id {, app_attempt_id {, application_id {, id: 6, cluster_timestamp: 1377618433102, }, attemptId: 1, }, id: 1, }, state: C_NEW, ]
2013-08-27 16:04:37,237 INFO org.apache.hadoop.yarn.server.resourcemanager.recovery.RMStateStore: Storing info for attempt: appattempt_1377618433102_0006_000001
2013-08-27 16:04:37,238 INFO org.apache.hadoop.yarn.server.resourcemanager.rmapp.attempt.RMAppAttemptImpl: appattempt_1377618433102_0006_000001 State change from SCHEDULED to ALLOCATED_SAVING
2013-08-27 16:04:37,238 INFO org.apache.hadoop.yarn.server.resourcemanager.rmapp.attempt.RMAppAttemptImpl: appattempt_1377618433102_0006_000001 State change from ALLOCATED_SAVING to ALLOCATED
2013-08-27 16:04:37,238 INFO org.apache.hadoop.yarn.server.resourcemanager.amlauncher.AMLauncher: Launching masterappattempt_1377618433102_0006_000001
2013-08-27 16:04:37,239 INFO org.apache.hadoop.yarn.server.resourcemanager.amlauncher.AMLauncher: Setting up container Container: [ContainerId: container_1377618433102_0006_01_000001, NodeId: hadoop-8-4:36803, NodeHttpAddress: hadoop-8-4:8042, Resource: <memory:2048, vCores:1>, Priority: 0, State: NEW, Token: null, Status: container_id {, app_attempt_id {, application_id {, id: 6, cluster_timestamp: 1377618433102, }, attemptId: 1, }, id: 1, }, state: C_NEW, ] for AM appattempt_1377618433102_0006_000001
2013-08-27 16:04:37,239 INFO org.apache.hadoop.yarn.server.resourcemanager.amlauncher.AMLauncher: Command to launch container container_1377618433102_0006_01_000001 : $JAVA_HOME/bin/java -Dlog4j.configuration=container-log4j.properties -Dyarn.app.mapreduce.container.log.dir=<LOG_DIR> -Dyarn.app.mapreduce.container.log.filesize=0 -Dhadoop.root.logger=INFO,CLA  -Xmx1024m org.apache.hadoop.mapreduce.v2.app.MRAppMaster 1><LOG_DIR>/stdout 2><LOG_DIR>/stderr 
2013-08-27 16:04:37,257 INFO org.apache.hadoop.yarn.server.resourcemanager.amlauncher.AMLauncher: Done launching container Container: [ContainerId: container_1377618433102_0006_01_000001, NodeId: hadoop-8-4:36803, NodeHttpAddress: hadoop-8-4:8042, Resource: <memory:2048, vCores:1>, Priority: 0, State: NEW, Token: null, Status: container_id {, app_attempt_id {, application_id {, id: 6, cluster_timestamp: 1377618433102, }, attemptId: 1, }, id: 1, }, state: C_NEW, ] for AM appattempt_1377618433102_0006_000001
2013-08-27 16:04:37,257 INFO org.apache.hadoop.yarn.server.resourcemanager.rmapp.attempt.RMAppAttemptImpl: appattempt_1377618433102_0006_000001 State change from ALLOCATED to LAUNCHED
2013-08-27 16:04:37,286 INFO org.apache.hadoop.yarn.server.resourcemanager.rmcontainer.RMContainerImpl: container_1377618433102_0007_01_000001 Container Transitioned from NEW to ALLOCATED
2013-08-27 16:04:37,286 INFO org.apache.hadoop.yarn.server.resourcemanager.RMAuditLogger: USER=ubuntu	OPERATION=AM Allocated Container	TARGET=SchedulerApp	RESULT=SUCCESS	APPID=application_1377618433102_0007	CONTAINERID=container_1377618433102_0007_01_000001
2013-08-27 16:04:37,286 INFO org.apache.hadoop.yarn.server.resourcemanager.scheduler.common.fica.FiCaSchedulerNode: Assigned container container_1377618433102_0007_01_000001 of capacity <memory:2048, vCores:1> on host hadoop-8-6:45732, which currently has 1 containers, <memory:2048, vCores:1> used and <memory:6144, vCores:15> available
2013-08-27 16:04:37,287 INFO org.apache.hadoop.yarn.server.resourcemanager.scheduler.capacity.LeafQueue: assignedContainer application=application_1377618433102_0007 container=Container: [ContainerId: container_1377618433102_0007_01_000001, NodeId: hadoop-8-6:45732, NodeHttpAddress: hadoop-8-6:8042, Resource: <memory:2048, vCores:1>, Priority: 0, State: NEW, Token: null, Status: container_id {, app_attempt_id {, application_id {, id: 7, cluster_timestamp: 1377618433102, }, attemptId: 1, }, id: 1, }, state: C_NEW, ] containerId=container_1377618433102_0007_01_000001 queue=default: capacity=1.0, absoluteCapacity=1.0, usedResources=<memory:2048, vCores:1>usedCapacity=0.041666668, absoluteUsedCapacity=0.041666668, numApps=2, numContainers=1 usedCapacity=0.041666668 absoluteUsedCapacity=0.041666668 used=<memory:2048, vCores:1> cluster=<memory:49152, vCores:96>
2013-08-27 16:04:37,287 INFO org.apache.hadoop.yarn.server.resourcemanager.scheduler.capacity.ParentQueue: Re-sorting queues since queue: root.default stats: default: capacity=1.0, absoluteCapacity=1.0, usedResources=<memory:4096, vCores:2>usedCapacity=0.083333336, absoluteUsedCapacity=0.083333336, numApps=2, numContainers=2
2013-08-27 16:04:37,287 INFO org.apache.hadoop.yarn.server.resourcemanager.scheduler.capacity.ParentQueue: assignedContainer queue=root usedCapacity=0.083333336 absoluteUsedCapacity=0.083333336 used=<memory:4096, vCores:2> cluster=<memory:49152, vCores:96>
2013-08-27 16:04:37,288 INFO org.apache.hadoop.yarn.server.resourcemanager.rmcontainer.RMContainerImpl: container_1377618433102_0007_01_000001 Container Transitioned from ALLOCATED to ACQUIRED
2013-08-27 16:04:37,288 INFO org.apache.hadoop.yarn.server.resourcemanager.rmapp.attempt.RMAppAttemptImpl: Storing attempt: AppId: application_1377618433102_0007 AttemptId: appattempt_1377618433102_0007_000001 MasterContainer: Container: [ContainerId: container_1377618433102_0007_01_000001, NodeId: hadoop-8-6:45732, NodeHttpAddress: hadoop-8-6:8042, Resource: <memory:2048, vCores:1>, Priority: 0, State: NEW, Token: null, Status: container_id {, app_attempt_id {, application_id {, id: 7, cluster_timestamp: 1377618433102, }, attemptId: 1, }, id: 1, }, state: C_NEW, ]
2013-08-27 16:04:37,289 INFO org.apache.hadoop.yarn.server.resourcemanager.recovery.RMStateStore: Storing info for attempt: appattempt_1377618433102_0007_000001
2013-08-27 16:04:37,289 INFO org.apache.hadoop.yarn.server.resourcemanager.rmapp.attempt.RMAppAttemptImpl: appattempt_1377618433102_0007_000001 State change from SCHEDULED to ALLOCATED_SAVING
2013-08-27 16:04:37,289 INFO org.apache.hadoop.yarn.server.resourcemanager.rmapp.attempt.RMAppAttemptImpl: appattempt_1377618433102_0007_000001 State change from ALLOCATED_SAVING to ALLOCATED
2013-08-27 16:04:37,289 INFO org.apache.hadoop.yarn.server.resourcemanager.amlauncher.AMLauncher: Launching masterappattempt_1377618433102_0007_000001
2013-08-27 16:04:37,291 INFO org.apache.hadoop.yarn.server.resourcemanager.amlauncher.AMLauncher: Setting up container Container: [ContainerId: container_1377618433102_0007_01_000001, NodeId: hadoop-8-6:45732, NodeHttpAddress: hadoop-8-6:8042, Resource: <memory:2048, vCores:1>, Priority: 0, State: NEW, Token: null, Status: container_id {, app_attempt_id {, application_id {, id: 7, cluster_timestamp: 1377618433102, }, attemptId: 1, }, id: 1, }, state: C_NEW, ] for AM appattempt_1377618433102_0007_000001
2013-08-27 16:04:37,291 INFO org.apache.hadoop.yarn.server.resourcemanager.amlauncher.AMLauncher: Command to launch container container_1377618433102_0007_01_000001 : $JAVA_HOME/bin/java -Dlog4j.configuration=container-log4j.properties -Dyarn.app.mapreduce.container.log.dir=<LOG_DIR> -Dyarn.app.mapreduce.container.log.filesize=0 -Dhadoop.root.logger=INFO,CLA  -Xmx1024m org.apache.hadoop.mapreduce.v2.app.MRAppMaster 1><LOG_DIR>/stdout 2><LOG_DIR>/stderr 
2013-08-27 16:04:37,305 INFO org.apache.hadoop.yarn.server.resourcemanager.amlauncher.AMLauncher: Done launching container Container: [ContainerId: container_1377618433102_0007_01_000001, NodeId: hadoop-8-6:45732, NodeHttpAddress: hadoop-8-6:8042, Resource: <memory:2048, vCores:1>, Priority: 0, State: NEW, Token: null, Status: container_id {, app_attempt_id {, application_id {, id: 7, cluster_timestamp: 1377618433102, }, attemptId: 1, }, id: 1, }, state: C_NEW, ] for AM appattempt_1377618433102_0007_000001
2013-08-27 16:04:37,305 INFO org.apache.hadoop.yarn.server.resourcemanager.rmapp.attempt.RMAppAttemptImpl: appattempt_1377618433102_0007_000001 State change from ALLOCATED to LAUNCHED
2013-08-27 16:04:37,336 INFO org.apache.hadoop.yarn.server.resourcemanager.ClientRMService: Storing Application with id application_1377618433102_0008
2013-08-27 16:04:37,336 INFO org.apache.hadoop.yarn.server.resourcemanager.recovery.RMStateStore: Storing info for app: application_1377618433102_0008
2013-08-27 16:04:37,336 INFO org.apache.hadoop.yarn.server.resourcemanager.ClientRMService: Application with id 8 submitted by user ubuntu
2013-08-27 16:04:37,336 INFO org.apache.hadoop.yarn.server.resourcemanager.RMAuditLogger: USER=ubuntu	IP=192.168.100.15	OPERATION=Submit Application Request	TARGET=ClientRMService	RESULT=SUCCESS	APPID=application_1377618433102_0008
2013-08-27 16:04:37,337 INFO org.apache.hadoop.yarn.server.resourcemanager.rmapp.RMAppImpl: application_1377618433102_0008 State change from NEW to SUBMITTED
2013-08-27 16:04:37,337 INFO org.apache.hadoop.yarn.server.resourcemanager.ApplicationMasterService: Registering appattempt_1377618433102_0008_000001
2013-08-27 16:04:37,337 INFO org.apache.hadoop.yarn.server.resourcemanager.rmapp.attempt.RMAppAttemptImpl: appattempt_1377618433102_0008_000001 State change from NEW to SUBMITTED
2013-08-27 16:04:37,337 INFO org.apache.hadoop.yarn.server.resourcemanager.scheduler.capacity.LeafQueue: Application application_1377618433102_0008 from user: ubuntu activated in queue: default
2013-08-27 16:04:37,337 INFO org.apache.hadoop.yarn.server.resourcemanager.scheduler.capacity.LeafQueue: Application added - appId: application_1377618433102_0008 user: org.apache.hadoop.yarn.server.resourcemanager.scheduler.capacity.LeafQueue$User@24eca8f6, leaf-queue: default #user-pending-applications: 0 #user-active-applications: 3 #queue-pending-applications: 0 #queue-active-applications: 3
2013-08-27 16:04:37,337 INFO org.apache.hadoop.yarn.server.resourcemanager.scheduler.capacity.ParentQueue: Application added - appId: application_1377618433102_0008 user: ubuntu leaf-queue of parent: root #applications: 3
2013-08-27 16:04:37,337 INFO org.apache.hadoop.yarn.server.resourcemanager.scheduler.capacity.CapacityScheduler: Application Submission: appattempt_1377618433102_0008_000001, user: ubuntu queue: default: capacity=1.0, absoluteCapacity=1.0, usedResources=<memory:4096, vCores:2>usedCapacity=0.083333336, absoluteUsedCapacity=0.083333336, numApps=3, numContainers=2, currently active: 3
2013-08-27 16:04:37,338 INFO org.apache.hadoop.yarn.server.resourcemanager.rmapp.attempt.RMAppAttemptImpl: appattempt_1377618433102_0008_000001 State change from SUBMITTED to SCHEDULED
2013-08-27 16:04:37,338 INFO org.apache.hadoop.yarn.server.resourcemanager.rmapp.RMAppImpl: application_1377618433102_0008 State change from SUBMITTED to ACCEPTED
2013-08-27 16:04:37,385 INFO org.apache.hadoop.yarn.server.resourcemanager.rmcontainer.RMContainerImpl: container_1377618433102_0008_01_000001 Container Transitioned from NEW to ALLOCATED
2013-08-27 16:04:37,385 INFO org.apache.hadoop.yarn.server.resourcemanager.RMAuditLogger: USER=ubuntu	OPERATION=AM Allocated Container	TARGET=SchedulerApp	RESULT=SUCCESS	APPID=application_1377618433102_0008	CONTAINERID=container_1377618433102_0008_01_000001
2013-08-27 16:04:37,385 INFO org.apache.hadoop.yarn.server.resourcemanager.scheduler.common.fica.FiCaSchedulerNode: Assigned container container_1377618433102_0008_01_000001 of capacity <memory:2048, vCores:1> on host hadoop-8-2:41932, which currently has 1 containers, <memory:2048, vCores:1> used and <memory:6144, vCores:15> available
2013-08-27 16:04:37,386 INFO org.apache.hadoop.yarn.server.resourcemanager.scheduler.capacity.LeafQueue: assignedContainer application=application_1377618433102_0008 container=Container: [ContainerId: container_1377618433102_0008_01_000001, NodeId: hadoop-8-2:41932, NodeHttpAddress: hadoop-8-2:8042, Resource: <memory:2048, vCores:1>, Priority: 0, State: NEW, Token: null, Status: container_id {, app_attempt_id {, application_id {, id: 8, cluster_timestamp: 1377618433102, }, attemptId: 1, }, id: 1, }, state: C_NEW, ] containerId=container_1377618433102_0008_01_000001 queue=default: capacity=1.0, absoluteCapacity=1.0, usedResources=<memory:4096, vCores:2>usedCapacity=0.083333336, absoluteUsedCapacity=0.083333336, numApps=3, numContainers=2 usedCapacity=0.083333336 absoluteUsedCapacity=0.083333336 used=<memory:4096, vCores:2> cluster=<memory:49152, vCores:96>
2013-08-27 16:04:37,386 INFO org.apache.hadoop.yarn.server.resourcemanager.scheduler.capacity.ParentQueue: Re-sorting queues since queue: root.default stats: default: capacity=1.0, absoluteCapacity=1.0, usedResources=<memory:6144, vCores:3>usedCapacity=0.125, absoluteUsedCapacity=0.125, numApps=3, numContainers=3
2013-08-27 16:04:37,386 INFO org.apache.hadoop.yarn.server.resourcemanager.scheduler.capacity.ParentQueue: assignedContainer queue=root usedCapacity=0.125 absoluteUsedCapacity=0.125 used=<memory:6144, vCores:3> cluster=<memory:49152, vCores:96>
2013-08-27 16:04:37,387 INFO org.apache.hadoop.yarn.server.resourcemanager.rmcontainer.RMContainerImpl: container_1377618433102_0008_01_000001 Container Transitioned from ALLOCATED to ACQUIRED
2013-08-27 16:04:37,387 INFO org.apache.hadoop.yarn.server.resourcemanager.rmapp.attempt.RMAppAttemptImpl: Storing attempt: AppId: application_1377618433102_0008 AttemptId: appattempt_1377618433102_0008_000001 MasterContainer: Container: [ContainerId: container_1377618433102_0008_01_000001, NodeId: hadoop-8-2:41932, NodeHttpAddress: hadoop-8-2:8042, Resource: <memory:2048, vCores:1>, Priority: 0, State: NEW, Token: null, Status: container_id {, app_attempt_id {, application_id {, id: 8, cluster_timestamp: 1377618433102, }, attemptId: 1, }, id: 1, }, state: C_NEW, ]
2013-08-27 16:04:37,388 INFO org.apache.hadoop.yarn.server.resourcemanager.recovery.RMStateStore: Storing info for attempt: appattempt_1377618433102_0008_000001
2013-08-27 16:04:37,388 INFO org.apache.hadoop.yarn.server.resourcemanager.rmapp.attempt.RMAppAttemptImpl: appattempt_1377618433102_0008_000001 State change from SCHEDULED to ALLOCATED_SAVING
2013-08-27 16:04:37,388 INFO org.apache.hadoop.yarn.server.resourcemanager.rmapp.attempt.RMAppAttemptImpl: appattempt_1377618433102_0008_000001 State change from ALLOCATED_SAVING to ALLOCATED
2013-08-27 16:04:37,388 INFO org.apache.hadoop.yarn.server.resourcemanager.amlauncher.AMLauncher: Launching masterappattempt_1377618433102_0008_000001
2013-08-27 16:04:37,389 INFO org.apache.hadoop.yarn.server.resourcemanager.amlauncher.AMLauncher: Setting up container Container: [ContainerId: container_1377618433102_0008_01_000001, NodeId: hadoop-8-2:41932, NodeHttpAddress: hadoop-8-2:8042, Resource: <memory:2048, vCores:1>, Priority: 0, State: NEW, Token: null, Status: container_id {, app_attempt_id {, application_id {, id: 8, cluster_timestamp: 1377618433102, }, attemptId: 1, }, id: 1, }, state: C_NEW, ] for AM appattempt_1377618433102_0008_000001
2013-08-27 16:04:37,390 INFO org.apache.hadoop.yarn.server.resourcemanager.amlauncher.AMLauncher: Command to launch container container_1377618433102_0008_01_000001 : $JAVA_HOME/bin/java -Dlog4j.configuration=container-log4j.properties -Dyarn.app.mapreduce.container.log.dir=<LOG_DIR> -Dyarn.app.mapreduce.container.log.filesize=0 -Dhadoop.root.logger=INFO,CLA  -Xmx1024m org.apache.hadoop.mapreduce.v2.app.MRAppMaster 1><LOG_DIR>/stdout 2><LOG_DIR>/stderr 
2013-08-27 16:04:37,399 INFO org.apache.hadoop.yarn.server.resourcemanager.amlauncher.AMLauncher: Done launching container Container: [ContainerId: container_1377618433102_0008_01_000001, NodeId: hadoop-8-2:41932, NodeHttpAddress: hadoop-8-2:8042, Resource: <memory:2048, vCores:1>, Priority: 0, State: NEW, Token: null, Status: container_id {, app_attempt_id {, application_id {, id: 8, cluster_timestamp: 1377618433102, }, attemptId: 1, }, id: 1, }, state: C_NEW, ] for AM appattempt_1377618433102_0008_000001
2013-08-27 16:04:37,400 INFO org.apache.hadoop.yarn.server.resourcemanager.rmapp.attempt.RMAppAttemptImpl: appattempt_1377618433102_0008_000001 State change from ALLOCATED to LAUNCHED
2013-08-27 16:04:37,517 INFO org.apache.hadoop.yarn.server.resourcemanager.ClientRMService: Storing Application with id application_1377618433102_0009
2013-08-27 16:04:37,517 INFO org.apache.hadoop.yarn.server.resourcemanager.recovery.RMStateStore: Storing info for app: application_1377618433102_0009
2013-08-27 16:04:37,517 INFO org.apache.hadoop.yarn.server.resourcemanager.ClientRMService: Application with id 9 submitted by user ubuntu
2013-08-27 16:04:37,517 INFO org.apache.hadoop.yarn.server.resourcemanager.RMAuditLogger: USER=ubuntu	IP=192.168.100.15	OPERATION=Submit Application Request	TARGET=ClientRMService	RESULT=SUCCESS	APPID=application_1377618433102_0009
2013-08-27 16:04:37,523 INFO org.apache.hadoop.yarn.server.resourcemanager.rmapp.RMAppImpl: application_1377618433102_0009 State change from NEW to SUBMITTED
2013-08-27 16:04:37,523 INFO org.apache.hadoop.yarn.server.resourcemanager.ApplicationMasterService: Registering appattempt_1377618433102_0009_000001
2013-08-27 16:04:37,524 INFO org.apache.hadoop.yarn.server.resourcemanager.rmapp.attempt.RMAppAttemptImpl: appattempt_1377618433102_0009_000001 State change from NEW to SUBMITTED
2013-08-27 16:04:37,524 INFO org.apache.hadoop.yarn.server.resourcemanager.scheduler.capacity.LeafQueue: Application application_1377618433102_0009 from user: ubuntu activated in queue: default
2013-08-27 16:04:37,524 INFO org.apache.hadoop.yarn.server.resourcemanager.scheduler.capacity.LeafQueue: Application added - appId: application_1377618433102_0009 user: org.apache.hadoop.yarn.server.resourcemanager.scheduler.capacity.LeafQueue$User@24eca8f6, leaf-queue: default #user-pending-applications: 0 #user-active-applications: 4 #queue-pending-applications: 0 #queue-active-applications: 4
2013-08-27 16:04:37,524 INFO org.apache.hadoop.yarn.server.resourcemanager.scheduler.capacity.ParentQueue: Application added - appId: application_1377618433102_0009 user: ubuntu leaf-queue of parent: root #applications: 4
2013-08-27 16:04:37,524 INFO org.apache.hadoop.yarn.server.resourcemanager.scheduler.capacity.CapacityScheduler: Application Submission: appattempt_1377618433102_0009_000001, user: ubuntu queue: default: capacity=1.0, absoluteCapacity=1.0, usedResources=<memory:6144, vCores:3>usedCapacity=0.125, absoluteUsedCapacity=0.125, numApps=4, numContainers=3, currently active: 4
2013-08-27 16:04:37,524 INFO org.apache.hadoop.yarn.server.resourcemanager.rmapp.attempt.RMAppAttemptImpl: appattempt_1377618433102_0009_000001 State change from SUBMITTED to SCHEDULED
2013-08-27 16:04:37,525 INFO org.apache.hadoop.yarn.server.resourcemanager.rmapp.RMAppImpl: application_1377618433102_0009 State change from SUBMITTED to ACCEPTED
2013-08-27 16:04:37,617 INFO org.apache.hadoop.yarn.server.resourcemanager.ClientRMService: Storing Application with id application_1377618433102_0010
2013-08-27 16:04:37,617 INFO org.apache.hadoop.yarn.server.resourcemanager.recovery.RMStateStore: Storing info for app: application_1377618433102_0010
2013-08-27 16:04:37,617 INFO org.apache.hadoop.yarn.server.resourcemanager.ClientRMService: Application with id 10 submitted by user ubuntu
2013-08-27 16:04:37,617 INFO org.apache.hadoop.yarn.server.resourcemanager.RMAuditLogger: USER=ubuntu	IP=192.168.100.15	OPERATION=Submit Application Request	TARGET=ClientRMService	RESULT=SUCCESS	APPID=application_1377618433102_0010
2013-08-27 16:04:37,618 INFO org.apache.hadoop.yarn.server.resourcemanager.rmapp.RMAppImpl: application_1377618433102_0010 State change from NEW to SUBMITTED
2013-08-27 16:04:37,618 INFO org.apache.hadoop.yarn.server.resourcemanager.ApplicationMasterService: Registering appattempt_1377618433102_0010_000001
2013-08-27 16:04:37,619 INFO org.apache.hadoop.yarn.server.resourcemanager.rmapp.attempt.RMAppAttemptImpl: appattempt_1377618433102_0010_000001 State change from NEW to SUBMITTED
2013-08-27 16:04:37,619 INFO org.apache.hadoop.yarn.server.resourcemanager.scheduler.capacity.LeafQueue: Application application_1377618433102_0010 from user: ubuntu activated in queue: default
2013-08-27 16:04:37,619 INFO org.apache.hadoop.yarn.server.resourcemanager.scheduler.capacity.LeafQueue: Application added - appId: application_1377618433102_0010 user: org.apache.hadoop.yarn.server.resourcemanager.scheduler.capacity.LeafQueue$User@24eca8f6, leaf-queue: default #user-pending-applications: 0 #user-active-applications: 5 #queue-pending-applications: 0 #queue-active-applications: 5
2013-08-27 16:04:37,619 INFO org.apache.hadoop.yarn.server.resourcemanager.scheduler.capacity.ParentQueue: Application added - appId: application_1377618433102_0010 user: ubuntu leaf-queue of parent: root #applications: 5
2013-08-27 16:04:37,619 INFO org.apache.hadoop.yarn.server.resourcemanager.scheduler.capacity.CapacityScheduler: Application Submission: appattempt_1377618433102_0010_000001, user: ubuntu queue: default: capacity=1.0, absoluteCapacity=1.0, usedResources=<memory:6144, vCores:3>usedCapacity=0.125, absoluteUsedCapacity=0.125, numApps=5, numContainers=3, currently active: 5
2013-08-27 16:04:37,619 INFO org.apache.hadoop.yarn.server.resourcemanager.rmapp.attempt.RMAppAttemptImpl: appattempt_1377618433102_0010_000001 State change from SUBMITTED to SCHEDULED
2013-08-27 16:04:37,619 INFO org.apache.hadoop.yarn.server.resourcemanager.rmapp.RMAppImpl: application_1377618433102_0010 State change from SUBMITTED to ACCEPTED
2013-08-27 16:04:37,789 INFO org.apache.hadoop.yarn.server.resourcemanager.rmcontainer.RMContainerImpl: container_1377618433102_0009_01_000001 Container Transitioned from NEW to ALLOCATED
2013-08-27 16:04:37,789 INFO org.apache.hadoop.yarn.server.resourcemanager.RMAuditLogger: USER=ubuntu	OPERATION=AM Allocated Container	TARGET=SchedulerApp	RESULT=SUCCESS	APPID=application_1377618433102_0009	CONTAINERID=container_1377618433102_0009_01_000001
2013-08-27 16:04:37,789 INFO org.apache.hadoop.yarn.server.resourcemanager.scheduler.common.fica.FiCaSchedulerNode: Assigned container container_1377618433102_0009_01_000001 of capacity <memory:2048, vCores:1> on host hadoop-8-7:53314, which currently has 1 containers, <memory:2048, vCores:1> used and <memory:6144, vCores:15> available
2013-08-27 16:04:37,790 INFO org.apache.hadoop.yarn.server.resourcemanager.scheduler.capacity.LeafQueue: assignedContainer application=application_1377618433102_0009 container=Container: [ContainerId: container_1377618433102_0009_01_000001, NodeId: hadoop-8-7:53314, NodeHttpAddress: hadoop-8-7:8042, Resource: <memory:2048, vCores:1>, Priority: 0, State: NEW, Token: null, Status: container_id {, app_attempt_id {, application_id {, id: 9, cluster_timestamp: 1377618433102, }, attemptId: 1, }, id: 1, }, state: C_NEW, ] containerId=container_1377618433102_0009_01_000001 queue=default: capacity=1.0, absoluteCapacity=1.0, usedResources=<memory:6144, vCores:3>usedCapacity=0.125, absoluteUsedCapacity=0.125, numApps=5, numContainers=3 usedCapacity=0.125 absoluteUsedCapacity=0.125 used=<memory:6144, vCores:3> cluster=<memory:49152, vCores:96>
2013-08-27 16:04:37,790 INFO org.apache.hadoop.yarn.server.resourcemanager.scheduler.capacity.ParentQueue: Re-sorting queues since queue: root.default stats: default: capacity=1.0, absoluteCapacity=1.0, usedResources=<memory:8192, vCores:4>usedCapacity=0.16666667, absoluteUsedCapacity=0.16666667, numApps=5, numContainers=4
2013-08-27 16:04:37,790 INFO org.apache.hadoop.yarn.server.resourcemanager.scheduler.capacity.ParentQueue: assignedContainer queue=root usedCapacity=0.16666667 absoluteUsedCapacity=0.16666667 used=<memory:8192, vCores:4> cluster=<memory:49152, vCores:96>
2013-08-27 16:04:37,792 INFO org.apache.hadoop.yarn.server.resourcemanager.rmcontainer.RMContainerImpl: container_1377618433102_0009_01_000001 Container Transitioned from ALLOCATED to ACQUIRED
2013-08-27 16:04:37,795 INFO org.apache.hadoop.yarn.server.resourcemanager.rmapp.attempt.RMAppAttemptImpl: Storing attempt: AppId: application_1377618433102_0009 AttemptId: appattempt_1377618433102_0009_000001 MasterContainer: Container: [ContainerId: container_1377618433102_0009_01_000001, NodeId: hadoop-8-7:53314, NodeHttpAddress: hadoop-8-7:8042, Resource: <memory:2048, vCores:1>, Priority: 0, State: NEW, Token: null, Status: container_id {, app_attempt_id {, application_id {, id: 9, cluster_timestamp: 1377618433102, }, attemptId: 1, }, id: 1, }, state: C_NEW, ]
2013-08-27 16:04:37,795 INFO org.apache.hadoop.yarn.server.resourcemanager.rmapp.attempt.RMAppAttemptImpl: appattempt_1377618433102_0009_000001 State change from SCHEDULED to ALLOCATED_SAVING
2013-08-27 16:04:37,795 INFO org.apache.hadoop.yarn.server.resourcemanager.recovery.RMStateStore: Storing info for attempt: appattempt_1377618433102_0009_000001
2013-08-27 16:04:37,796 INFO org.apache.hadoop.yarn.server.resourcemanager.rmapp.attempt.RMAppAttemptImpl: appattempt_1377618433102_0009_000001 State change from ALLOCATED_SAVING to ALLOCATED
2013-08-27 16:04:37,796 INFO org.apache.hadoop.yarn.server.resourcemanager.amlauncher.AMLauncher: Launching masterappattempt_1377618433102_0009_000001
2013-08-27 16:04:37,797 INFO org.apache.hadoop.yarn.server.resourcemanager.amlauncher.AMLauncher: Setting up container Container: [ContainerId: container_1377618433102_0009_01_000001, NodeId: hadoop-8-7:53314, NodeHttpAddress: hadoop-8-7:8042, Resource: <memory:2048, vCores:1>, Priority: 0, State: NEW, Token: null, Status: container_id {, app_attempt_id {, application_id {, id: 9, cluster_timestamp: 1377618433102, }, attemptId: 1, }, id: 1, }, state: C_NEW, ] for AM appattempt_1377618433102_0009_000001
2013-08-27 16:04:37,797 INFO org.apache.hadoop.yarn.server.resourcemanager.amlauncher.AMLauncher: Command to launch container container_1377618433102_0009_01_000001 : $JAVA_HOME/bin/java -Dlog4j.configuration=container-log4j.properties -Dyarn.app.mapreduce.container.log.dir=<LOG_DIR> -Dyarn.app.mapreduce.container.log.filesize=0 -Dhadoop.root.logger=INFO,CLA  -Xmx1024m org.apache.hadoop.mapreduce.v2.app.MRAppMaster 1><LOG_DIR>/stdout 2><LOG_DIR>/stderr 
2013-08-27 16:04:37,808 INFO org.apache.hadoop.yarn.server.resourcemanager.amlauncher.AMLauncher: Done launching container Container: [ContainerId: container_1377618433102_0009_01_000001, NodeId: hadoop-8-7:53314, NodeHttpAddress: hadoop-8-7:8042, Resource: <memory:2048, vCores:1>, Priority: 0, State: NEW, Token: null, Status: container_id {, app_attempt_id {, application_id {, id: 9, cluster_timestamp: 1377618433102, }, attemptId: 1, }, id: 1, }, state: C_NEW, ] for AM appattempt_1377618433102_0009_000001
2013-08-27 16:04:37,809 INFO org.apache.hadoop.yarn.server.resourcemanager.rmapp.attempt.RMAppAttemptImpl: appattempt_1377618433102_0009_000001 State change from ALLOCATED to LAUNCHED
2013-08-27 16:04:37,913 INFO org.apache.hadoop.yarn.server.resourcemanager.rmcontainer.RMContainerImpl: container_1377618433102_0010_01_000001 Container Transitioned from NEW to ALLOCATED
2013-08-27 16:04:37,913 INFO org.apache.hadoop.yarn.server.resourcemanager.RMAuditLogger: USER=ubuntu	OPERATION=AM Allocated Container	TARGET=SchedulerApp	RESULT=SUCCESS	APPID=application_1377618433102_0010	CONTAINERID=container_1377618433102_0010_01_000001
2013-08-27 16:04:37,913 INFO org.apache.hadoop.yarn.server.resourcemanager.scheduler.common.fica.FiCaSchedulerNode: Assigned container container_1377618433102_0010_01_000001 of capacity <memory:2048, vCores:1> on host hadoop-8-5:56487, which currently has 1 containers, <memory:2048, vCores:1> used and <memory:6144, vCores:15> available
2013-08-27 16:04:37,914 INFO org.apache.hadoop.yarn.server.resourcemanager.scheduler.capacity.LeafQueue: assignedContainer application=application_1377618433102_0010 container=Container: [ContainerId: container_1377618433102_0010_01_000001, NodeId: hadoop-8-5:56487, NodeHttpAddress: hadoop-8-5:8042, Resource: <memory:2048, vCores:1>, Priority: 0, State: NEW, Token: null, Status: container_id {, app_attempt_id {, application_id {, id: 10, cluster_timestamp: 1377618433102, }, attemptId: 1, }, id: 1, }, state: C_NEW, ] containerId=container_1377618433102_0010_01_000001 queue=default: capacity=1.0, absoluteCapacity=1.0, usedResources=<memory:8192, vCores:4>usedCapacity=0.16666667, absoluteUsedCapacity=0.16666667, numApps=5, numContainers=4 usedCapacity=0.16666667 absoluteUsedCapacity=0.16666667 used=<memory:8192, vCores:4> cluster=<memory:49152, vCores:96>
2013-08-27 16:04:37,914 INFO org.apache.hadoop.yarn.server.resourcemanager.scheduler.capacity.ParentQueue: Re-sorting queues since queue: root.default stats: default: capacity=1.0, absoluteCapacity=1.0, usedResources=<memory:10240, vCores:5>usedCapacity=0.20833333, absoluteUsedCapacity=0.20833333, numApps=5, numContainers=5
2013-08-27 16:04:37,915 INFO org.apache.hadoop.yarn.server.resourcemanager.scheduler.capacity.ParentQueue: assignedContainer queue=root usedCapacity=0.20833333 absoluteUsedCapacity=0.20833333 used=<memory:10240, vCores:5> cluster=<memory:49152, vCores:96>
2013-08-27 16:04:37,916 INFO org.apache.hadoop.yarn.server.resourcemanager.rmcontainer.RMContainerImpl: container_1377618433102_0010_01_000001 Container Transitioned from ALLOCATED to ACQUIRED
2013-08-27 16:04:37,917 INFO org.apache.hadoop.yarn.server.resourcemanager.rmapp.attempt.RMAppAttemptImpl: Storing attempt: AppId: application_1377618433102_0010 AttemptId: appattempt_1377618433102_0010_000001 MasterContainer: Container: [ContainerId: container_1377618433102_0010_01_000001, NodeId: hadoop-8-5:56487, NodeHttpAddress: hadoop-8-5:8042, Resource: <memory:2048, vCores:1>, Priority: 0, State: NEW, Token: null, Status: container_id {, app_attempt_id {, application_id {, id: 10, cluster_timestamp: 1377618433102, }, attemptId: 1, }, id: 1, }, state: C_NEW, ]
2013-08-27 16:04:37,917 INFO org.apache.hadoop.yarn.server.resourcemanager.rmapp.attempt.RMAppAttemptImpl: appattempt_1377618433102_0010_000001 State change from SCHEDULED to ALLOCATED_SAVING
2013-08-27 16:04:37,917 INFO org.apache.hadoop.yarn.server.resourcemanager.recovery.RMStateStore: Storing info for attempt: appattempt_1377618433102_0010_000001
2013-08-27 16:04:37,918 INFO org.apache.hadoop.yarn.server.resourcemanager.rmapp.attempt.RMAppAttemptImpl: appattempt_1377618433102_0010_000001 State change from ALLOCATED_SAVING to ALLOCATED
2013-08-27 16:04:37,918 INFO org.apache.hadoop.yarn.server.resourcemanager.amlauncher.AMLauncher: Launching masterappattempt_1377618433102_0010_000001
2013-08-27 16:04:37,919 INFO org.apache.hadoop.yarn.server.resourcemanager.amlauncher.AMLauncher: Setting up container Container: [ContainerId: container_1377618433102_0010_01_000001, NodeId: hadoop-8-5:56487, NodeHttpAddress: hadoop-8-5:8042, Resource: <memory:2048, vCores:1>, Priority: 0, State: NEW, Token: null, Status: container_id {, app_attempt_id {, application_id {, id: 10, cluster_timestamp: 1377618433102, }, attemptId: 1, }, id: 1, }, state: C_NEW, ] for AM appattempt_1377618433102_0010_000001
2013-08-27 16:04:37,919 INFO org.apache.hadoop.yarn.server.resourcemanager.amlauncher.AMLauncher: Command to launch container container_1377618433102_0010_01_000001 : $JAVA_HOME/bin/java -Dlog4j.configuration=container-log4j.properties -Dyarn.app.mapreduce.container.log.dir=<LOG_DIR> -Dyarn.app.mapreduce.container.log.filesize=0 -Dhadoop.root.logger=INFO,CLA  -Xmx1024m org.apache.hadoop.mapreduce.v2.app.MRAppMaster 1><LOG_DIR>/stdout 2><LOG_DIR>/stderr 
2013-08-27 16:04:37,930 INFO org.apache.hadoop.yarn.server.resourcemanager.amlauncher.AMLauncher: Done launching container Container: [ContainerId: container_1377618433102_0010_01_000001, NodeId: hadoop-8-5:56487, NodeHttpAddress: hadoop-8-5:8042, Resource: <memory:2048, vCores:1>, Priority: 0, State: NEW, Token: null, Status: container_id {, app_attempt_id {, application_id {, id: 10, cluster_timestamp: 1377618433102, }, attemptId: 1, }, id: 1, }, state: C_NEW, ] for AM appattempt_1377618433102_0010_000001
2013-08-27 16:04:37,930 INFO org.apache.hadoop.yarn.server.resourcemanager.rmapp.attempt.RMAppAttemptImpl: appattempt_1377618433102_0010_000001 State change from ALLOCATED to LAUNCHED
2013-08-27 16:04:38,238 INFO org.apache.hadoop.yarn.server.resourcemanager.rmcontainer.RMContainerImpl: container_1377618433102_0006_01_000001 Container Transitioned from ACQUIRED to RUNNING
2013-08-27 16:04:38,292 INFO org.apache.hadoop.yarn.server.resourcemanager.rmcontainer.RMContainerImpl: container_1377618433102_0007_01_000001 Container Transitioned from ACQUIRED to RUNNING
2013-08-27 16:04:38,390 INFO org.apache.hadoop.yarn.server.resourcemanager.rmcontainer.RMContainerImpl: container_1377618433102_0008_01_000001 Container Transitioned from ACQUIRED to RUNNING
2013-08-27 16:04:38,795 INFO org.apache.hadoop.yarn.server.resourcemanager.rmcontainer.RMContainerImpl: container_1377618433102_0009_01_000001 Container Transitioned from ACQUIRED to RUNNING
2013-08-27 16:04:38,919 INFO org.apache.hadoop.yarn.server.resourcemanager.rmcontainer.RMContainerImpl: container_1377618433102_0010_01_000001 Container Transitioned from ACQUIRED to RUNNING
2013-08-27 16:04:42,838 INFO org.apache.hadoop.yarn.server.resourcemanager.ApplicationMasterService: AM registration appattempt_1377618433102_0007_000001
2013-08-27 16:04:42,838 INFO org.apache.hadoop.yarn.server.resourcemanager.RMAuditLogger: USER=ubuntu	IP=192.168.100.26	OPERATION=Register App Master	TARGET=ApplicationMasterService	RESULT=SUCCESS	APPID=application_1377618433102_0007	APPATTEMPTID=appattempt_1377618433102_0007_000001
2013-08-27 16:04:42,839 INFO org.apache.hadoop.yarn.server.resourcemanager.rmapp.attempt.RMAppAttemptImpl: appattempt_1377618433102_0007_000001 State change from LAUNCHED to RUNNING
2013-08-27 16:04:42,839 INFO org.apache.hadoop.yarn.server.resourcemanager.rmapp.RMAppImpl: application_1377618433102_0007 State change from ACCEPTED to RUNNING
2013-08-27 16:04:42,886 INFO org.apache.hadoop.yarn.server.resourcemanager.ApplicationMasterService: AM registration appattempt_1377618433102_0009_000001
2013-08-27 16:04:42,886 INFO org.apache.hadoop.yarn.server.resourcemanager.RMAuditLogger: USER=ubuntu	IP=192.168.100.31	OPERATION=Register App Master	TARGET=ApplicationMasterService	RESULT=SUCCESS	APPID=application_1377618433102_0009	APPATTEMPTID=appattempt_1377618433102_0009_000001
2013-08-27 16:04:42,888 INFO org.apache.hadoop.yarn.server.resourcemanager.rmapp.attempt.RMAppAttemptImpl: appattempt_1377618433102_0009_000001 State change from LAUNCHED to RUNNING
2013-08-27 16:04:42,888 INFO org.apache.hadoop.yarn.server.resourcemanager.rmapp.RMAppImpl: application_1377618433102_0009 State change from ACCEPTED to RUNNING
2013-08-27 16:04:43,676 INFO org.apache.hadoop.yarn.server.resourcemanager.ApplicationMasterService: AM registration appattempt_1377618433102_0006_000001
2013-08-27 16:04:43,676 INFO org.apache.hadoop.yarn.server.resourcemanager.RMAuditLogger: USER=ubuntu	IP=192.168.100.24	OPERATION=Register App Master	TARGET=ApplicationMasterService	RESULT=SUCCESS	APPID=application_1377618433102_0006	APPATTEMPTID=appattempt_1377618433102_0006_000001
2013-08-27 16:04:43,677 INFO org.apache.hadoop.yarn.server.resourcemanager.rmapp.attempt.RMAppAttemptImpl: appattempt_1377618433102_0006_000001 State change from LAUNCHED to RUNNING
2013-08-27 16:04:43,677 INFO org.apache.hadoop.yarn.server.resourcemanager.rmapp.RMAppImpl: application_1377618433102_0006 State change from ACCEPTED to RUNNING
2013-08-27 16:04:43,944 INFO org.apache.hadoop.yarn.server.resourcemanager.rmcontainer.RMContainerImpl: container_1377618433102_0007_01_000002 Container Transitioned from NEW to ALLOCATED
2013-08-27 16:04:43,944 INFO org.apache.hadoop.yarn.server.resourcemanager.RMAuditLogger: USER=ubuntu	OPERATION=AM Allocated Container	TARGET=SchedulerApp	RESULT=SUCCESS	APPID=application_1377618433102_0007	CONTAINERID=container_1377618433102_0007_01_000002
2013-08-27 16:04:43,945 INFO org.apache.hadoop.yarn.server.resourcemanager.scheduler.common.fica.FiCaSchedulerNode: Assigned container container_1377618433102_0007_01_000002 of capacity <memory:1024, vCores:1> on host hadoop-8-5:56487, which currently has 2 containers, <memory:3072, vCores:2> used and <memory:5120, vCores:14> available
2013-08-27 16:04:43,946 INFO org.apache.hadoop.yarn.server.resourcemanager.scheduler.capacity.LeafQueue: assignedContainer application=application_1377618433102_0007 container=Container: [ContainerId: container_1377618433102_0007_01_000002, NodeId: hadoop-8-5:56487, NodeHttpAddress: hadoop-8-5:8042, Resource: <memory:1024, vCores:1>, Priority: 20, State: NEW, Token: null, Status: container_id {, app_attempt_id {, application_id {, id: 7, cluster_timestamp: 1377618433102, }, attemptId: 1, }, id: 2, }, state: C_NEW, ] containerId=container_1377618433102_0007_01_000002 queue=default: capacity=1.0, absoluteCapacity=1.0, usedResources=<memory:10240, vCores:5>usedCapacity=0.20833333, absoluteUsedCapacity=0.20833333, numApps=5, numContainers=5 usedCapacity=0.20833333 absoluteUsedCapacity=0.20833333 used=<memory:10240, vCores:5> cluster=<memory:49152, vCores:96>
2013-08-27 16:04:43,947 INFO org.apache.hadoop.yarn.server.resourcemanager.scheduler.capacity.ParentQueue: Re-sorting queues since queue: root.default stats: default: capacity=1.0, absoluteCapacity=1.0, usedResources=<memory:11264, vCores:6>usedCapacity=0.22916667, absoluteUsedCapacity=0.22916667, numApps=5, numContainers=6
2013-08-27 16:04:43,947 INFO org.apache.hadoop.yarn.server.resourcemanager.scheduler.capacity.ParentQueue: assignedContainer queue=root usedCapacity=0.22916667 absoluteUsedCapacity=0.22916667 used=<memory:11264, vCores:6> cluster=<memory:49152, vCores:96>
2013-08-27 16:04:43,948 INFO org.apache.hadoop.yarn.server.resourcemanager.rmcontainer.RMContainerImpl: container_1377618433102_0007_01_000003 Container Transitioned from NEW to ALLOCATED
2013-08-27 16:04:43,948 INFO org.apache.hadoop.yarn.server.resourcemanager.RMAuditLogger: USER=ubuntu	OPERATION=AM Allocated Container	TARGET=SchedulerApp	RESULT=SUCCESS	APPID=application_1377618433102_0007	CONTAINERID=container_1377618433102_0007_01_000003
2013-08-27 16:04:43,948 INFO org.apache.hadoop.yarn.server.resourcemanager.scheduler.common.fica.FiCaSchedulerNode: Assigned container container_1377618433102_0007_01_000003 of capacity <memory:1024, vCores:1> on host hadoop-8-5:56487, which currently has 3 containers, <memory:4096, vCores:3> used and <memory:4096, vCores:13> available
2013-08-27 16:04:43,949 INFO org.apache.hadoop.yarn.server.resourcemanager.scheduler.capacity.LeafQueue: assignedContainer application=application_1377618433102_0007 container=Container: [ContainerId: container_1377618433102_0007_01_000003, NodeId: hadoop-8-5:56487, NodeHttpAddress: hadoop-8-5:8042, Resource: <memory:1024, vCores:1>, Priority: 20, State: NEW, Token: null, Status: container_id {, app_attempt_id {, application_id {, id: 7, cluster_timestamp: 1377618433102, }, attemptId: 1, }, id: 3, }, state: C_NEW, ] containerId=container_1377618433102_0007_01_000003 queue=default: capacity=1.0, absoluteCapacity=1.0, usedResources=<memory:11264, vCores:6>usedCapacity=0.22916667, absoluteUsedCapacity=0.22916667, numApps=5, numContainers=6 usedCapacity=0.22916667 absoluteUsedCapacity=0.22916667 used=<memory:11264, vCores:6> cluster=<memory:49152, vCores:96>
2013-08-27 16:04:43,950 INFO org.apache.hadoop.yarn.server.resourcemanager.scheduler.capacity.ParentQueue: Re-sorting queues since queue: root.default stats: default: capacity=1.0, absoluteCapacity=1.0, usedResources=<memory:12288, vCores:7>usedCapacity=0.25, absoluteUsedCapacity=0.25, numApps=5, numContainers=7
2013-08-27 16:04:43,950 INFO org.apache.hadoop.yarn.server.resourcemanager.scheduler.capacity.ParentQueue: assignedContainer queue=root usedCapacity=0.25 absoluteUsedCapacity=0.25 used=<memory:12288, vCores:7> cluster=<memory:49152, vCores:96>
2013-08-27 16:04:43,950 INFO org.apache.hadoop.yarn.server.resourcemanager.rmcontainer.RMContainerImpl: container_1377618433102_0007_01_000004 Container Transitioned from NEW to ALLOCATED
2013-08-27 16:04:43,951 INFO org.apache.hadoop.yarn.server.resourcemanager.RMAuditLogger: USER=ubuntu	OPERATION=AM Allocated Container	TARGET=SchedulerApp	RESULT=SUCCESS	APPID=application_1377618433102_0007	CONTAINERID=container_1377618433102_0007_01_000004
2013-08-27 16:04:43,951 INFO org.apache.hadoop.yarn.server.resourcemanager.scheduler.common.fica.FiCaSchedulerNode: Assigned container container_1377618433102_0007_01_000004 of capacity <memory:1024, vCores:1> on host hadoop-8-5:56487, which currently has 4 containers, <memory:5120, vCores:4> used and <memory:3072, vCores:12> available
2013-08-27 16:04:43,952 INFO org.apache.hadoop.yarn.server.resourcemanager.scheduler.capacity.LeafQueue: assignedContainer application=application_1377618433102_0007 container=Container: [ContainerId: container_1377618433102_0007_01_000004, NodeId: hadoop-8-5:56487, NodeHttpAddress: hadoop-8-5:8042, Resource: <memory:1024, vCores:1>, Priority: 20, State: NEW, Token: null, Status: container_id {, app_attempt_id {, application_id {, id: 7, cluster_timestamp: 1377618433102, }, attemptId: 1, }, id: 4, }, state: C_NEW, ] containerId=container_1377618433102_0007_01_000004 queue=default: capacity=1.0, absoluteCapacity=1.0, usedResources=<memory:12288, vCores:7>usedCapacity=0.25, absoluteUsedCapacity=0.25, numApps=5, numContainers=7 usedCapacity=0.25 absoluteUsedCapacity=0.25 used=<memory:12288, vCores:7> cluster=<memory:49152, vCores:96>
2013-08-27 16:04:43,952 INFO org.apache.hadoop.yarn.server.resourcemanager.scheduler.capacity.ParentQueue: Re-sorting queues since queue: root.default stats: default: capacity=1.0, absoluteCapacity=1.0, usedResources=<memory:13312, vCores:8>usedCapacity=0.27083334, absoluteUsedCapacity=0.27083334, numApps=5, numContainers=8
2013-08-27 16:04:43,953 INFO org.apache.hadoop.yarn.server.resourcemanager.scheduler.capacity.ParentQueue: assignedContainer queue=root usedCapacity=0.27083334 absoluteUsedCapacity=0.27083334 used=<memory:13312, vCores:8> cluster=<memory:49152, vCores:96>
2013-08-27 16:04:43,953 INFO org.apache.hadoop.yarn.server.resourcemanager.rmcontainer.RMContainerImpl: container_1377618433102_0007_01_000005 Container Transitioned from NEW to ALLOCATED
2013-08-27 16:04:43,953 INFO org.apache.hadoop.yarn.server.resourcemanager.RMAuditLogger: USER=ubuntu	OPERATION=AM Allocated Container	TARGET=SchedulerApp	RESULT=SUCCESS	APPID=application_1377618433102_0007	CONTAINERID=container_1377618433102_0007_01_000005
2013-08-27 16:04:43,953 INFO org.apache.hadoop.yarn.server.resourcemanager.scheduler.common.fica.FiCaSchedulerNode: Assigned container container_1377618433102_0007_01_000005 of capacity <memory:1024, vCores:1> on host hadoop-8-5:56487, which currently has 5 containers, <memory:6144, vCores:5> used and <memory:2048, vCores:11> available
2013-08-27 16:04:43,954 INFO org.apache.hadoop.yarn.server.resourcemanager.scheduler.capacity.LeafQueue: assignedContainer application=application_1377618433102_0007 container=Container: [ContainerId: container_1377618433102_0007_01_000005, NodeId: hadoop-8-5:56487, NodeHttpAddress: hadoop-8-5:8042, Resource: <memory:1024, vCores:1>, Priority: 20, State: NEW, Token: null, Status: container_id {, app_attempt_id {, application_id {, id: 7, cluster_timestamp: 1377618433102, }, attemptId: 1, }, id: 5, }, state: C_NEW, ] containerId=container_1377618433102_0007_01_000005 queue=default: capacity=1.0, absoluteCapacity=1.0, usedResources=<memory:13312, vCores:8>usedCapacity=0.27083334, absoluteUsedCapacity=0.27083334, numApps=5, numContainers=8 usedCapacity=0.27083334 absoluteUsedCapacity=0.27083334 used=<memory:13312, vCores:8> cluster=<memory:49152, vCores:96>
2013-08-27 16:04:43,955 INFO org.apache.hadoop.yarn.server.resourcemanager.scheduler.capacity.ParentQueue: Re-sorting queues since queue: root.default stats: default: capacity=1.0, absoluteCapacity=1.0, usedResources=<memory:14336, vCores:9>usedCapacity=0.29166666, absoluteUsedCapacity=0.29166666, numApps=5, numContainers=9
2013-08-27 16:04:43,955 INFO org.apache.hadoop.yarn.server.resourcemanager.scheduler.capacity.ParentQueue: assignedContainer queue=root usedCapacity=0.29166666 absoluteUsedCapacity=0.29166666 used=<memory:14336, vCores:9> cluster=<memory:49152, vCores:96>
2013-08-27 16:04:43,955 INFO org.apache.hadoop.yarn.server.resourcemanager.rmcontainer.RMContainerImpl: container_1377618433102_0007_01_000006 Container Transitioned from NEW to ALLOCATED
2013-08-27 16:04:43,956 INFO org.apache.hadoop.yarn.server.resourcemanager.RMAuditLogger: USER=ubuntu	OPERATION=AM Allocated Container	TARGET=SchedulerApp	RESULT=SUCCESS	APPID=application_1377618433102_0007	CONTAINERID=container_1377618433102_0007_01_000006
2013-08-27 16:04:43,956 INFO org.apache.hadoop.yarn.server.resourcemanager.scheduler.common.fica.FiCaSchedulerNode: Assigned container container_1377618433102_0007_01_000006 of capacity <memory:1024, vCores:1> on host hadoop-8-5:56487, which currently has 6 containers, <memory:7168, vCores:6> used and <memory:1024, vCores:10> available
2013-08-27 16:04:43,957 INFO org.apache.hadoop.yarn.server.resourcemanager.scheduler.capacity.LeafQueue: assignedContainer application=application_1377618433102_0007 container=Container: [ContainerId: container_1377618433102_0007_01_000006, NodeId: hadoop-8-5:56487, NodeHttpAddress: hadoop-8-5:8042, Resource: <memory:1024, vCores:1>, Priority: 20, State: NEW, Token: null, Status: container_id {, app_attempt_id {, application_id {, id: 7, cluster_timestamp: 1377618433102, }, attemptId: 1, }, id: 6, }, state: C_NEW, ] containerId=container_1377618433102_0007_01_000006 queue=default: capacity=1.0, absoluteCapacity=1.0, usedResources=<memory:14336, vCores:9>usedCapacity=0.29166666, absoluteUsedCapacity=0.29166666, numApps=5, numContainers=9 usedCapacity=0.29166666 absoluteUsedCapacity=0.29166666 used=<memory:14336, vCores:9> cluster=<memory:49152, vCores:96>
2013-08-27 16:04:43,957 INFO org.apache.hadoop.yarn.server.resourcemanager.scheduler.capacity.ParentQueue: Re-sorting queues since queue: root.default stats: default: capacity=1.0, absoluteCapacity=1.0, usedResources=<memory:15360, vCores:10>usedCapacity=0.3125, absoluteUsedCapacity=0.3125, numApps=5, numContainers=10
2013-08-27 16:04:43,957 INFO org.apache.hadoop.yarn.server.resourcemanager.scheduler.capacity.ParentQueue: assignedContainer queue=root usedCapacity=0.3125 absoluteUsedCapacity=0.3125 used=<memory:15360, vCores:10> cluster=<memory:49152, vCores:96>
2013-08-27 16:04:43,958 INFO org.apache.hadoop.yarn.server.resourcemanager.rmcontainer.RMContainerImpl: container_1377618433102_0007_01_000007 Container Transitioned from NEW to ALLOCATED
2013-08-27 16:04:43,958 INFO org.apache.hadoop.yarn.server.resourcemanager.RMAuditLogger: USER=ubuntu	OPERATION=AM Allocated Container	TARGET=SchedulerApp	RESULT=SUCCESS	APPID=application_1377618433102_0007	CONTAINERID=container_1377618433102_0007_01_000007
2013-08-27 16:04:43,958 INFO org.apache.hadoop.yarn.server.resourcemanager.scheduler.common.fica.FiCaSchedulerNode: Assigned container container_1377618433102_0007_01_000007 of capacity <memory:1024, vCores:1> on host hadoop-8-5:56487, which currently has 7 containers, <memory:8192, vCores:7> used and <memory:0, vCores:9> available
2013-08-27 16:04:43,959 INFO org.apache.hadoop.yarn.server.resourcemanager.scheduler.capacity.LeafQueue: assignedContainer application=application_1377618433102_0007 container=Container: [ContainerId: container_1377618433102_0007_01_000007, NodeId: hadoop-8-5:56487, NodeHttpAddress: hadoop-8-5:8042, Resource: <memory:1024, vCores:1>, Priority: 20, State: NEW, Token: null, Status: container_id {, app_attempt_id {, application_id {, id: 7, cluster_timestamp: 1377618433102, }, attemptId: 1, }, id: 7, }, state: C_NEW, ] containerId=container_1377618433102_0007_01_000007 queue=default: capacity=1.0, absoluteCapacity=1.0, usedResources=<memory:15360, vCores:10>usedCapacity=0.3125, absoluteUsedCapacity=0.3125, numApps=5, numContainers=10 usedCapacity=0.3125 absoluteUsedCapacity=0.3125 used=<memory:15360, vCores:10> cluster=<memory:49152, vCores:96>
2013-08-27 16:04:43,959 INFO org.apache.hadoop.yarn.server.resourcemanager.scheduler.capacity.ParentQueue: Re-sorting queues since queue: root.default stats: default: capacity=1.0, absoluteCapacity=1.0, usedResources=<memory:16384, vCores:11>usedCapacity=0.33333334, absoluteUsedCapacity=0.33333334, numApps=5, numContainers=11
2013-08-27 16:04:43,959 INFO org.apache.hadoop.yarn.server.resourcemanager.scheduler.capacity.ParentQueue: assignedContainer queue=root usedCapacity=0.33333334 absoluteUsedCapacity=0.33333334 used=<memory:16384, vCores:11> cluster=<memory:49152, vCores:96>
2013-08-27 16:04:43,987 INFO org.apache.hadoop.yarn.server.resourcemanager.ApplicationMasterService: AM registration appattempt_1377618433102_0008_000001
2013-08-27 16:04:43,988 INFO org.apache.hadoop.yarn.server.resourcemanager.RMAuditLogger: USER=ubuntu	IP=192.168.100.17	OPERATION=Register App Master	TARGET=ApplicationMasterService	RESULT=SUCCESS	APPID=application_1377618433102_0008	APPATTEMPTID=appattempt_1377618433102_0008_000001
2013-08-27 16:04:43,989 INFO org.apache.hadoop.yarn.server.resourcemanager.rmapp.attempt.RMAppAttemptImpl: appattempt_1377618433102_0008_000001 State change from LAUNCHED to RUNNING
2013-08-27 16:04:43,989 INFO org.apache.hadoop.yarn.server.resourcemanager.rmapp.RMAppImpl: application_1377618433102_0008 State change from ACCEPTED to RUNNING
2013-08-27 16:04:44,269 INFO org.apache.hadoop.yarn.server.resourcemanager.rmcontainer.RMContainerImpl: container_1377618433102_0007_01_000008 Container Transitioned from NEW to ALLOCATED
2013-08-27 16:04:44,269 INFO org.apache.hadoop.yarn.server.resourcemanager.RMAuditLogger: USER=ubuntu	OPERATION=AM Allocated Container	TARGET=SchedulerApp	RESULT=SUCCESS	APPID=application_1377618433102_0007	CONTAINERID=container_1377618433102_0007_01_000008
2013-08-27 16:04:44,269 INFO org.apache.hadoop.yarn.server.resourcemanager.scheduler.common.fica.FiCaSchedulerNode: Assigned container container_1377618433102_0007_01_000008 of capacity <memory:1024, vCores:1> on host hadoop-8-4:36803, which currently has 2 containers, <memory:3072, vCores:2> used and <memory:5120, vCores:14> available
2013-08-27 16:04:44,270 INFO org.apache.hadoop.yarn.server.resourcemanager.scheduler.capacity.LeafQueue: assignedContainer application=application_1377618433102_0007 container=Container: [ContainerId: container_1377618433102_0007_01_000008, NodeId: hadoop-8-4:36803, NodeHttpAddress: hadoop-8-4:8042, Resource: <memory:1024, vCores:1>, Priority: 20, State: NEW, Token: null, Status: container_id {, app_attempt_id {, application_id {, id: 7, cluster_timestamp: 1377618433102, }, attemptId: 1, }, id: 8, }, state: C_NEW, ] containerId=container_1377618433102_0007_01_000008 queue=default: capacity=1.0, absoluteCapacity=1.0, usedResources=<memory:16384, vCores:11>usedCapacity=0.33333334, absoluteUsedCapacity=0.33333334, numApps=5, numContainers=11 usedCapacity=0.33333334 absoluteUsedCapacity=0.33333334 used=<memory:16384, vCores:11> cluster=<memory:49152, vCores:96>
2013-08-27 16:04:44,271 INFO org.apache.hadoop.yarn.server.resourcemanager.scheduler.capacity.ParentQueue: Re-sorting queues since queue: root.default stats: default: capacity=1.0, absoluteCapacity=1.0, usedResources=<memory:17408, vCores:12>usedCapacity=0.35416666, absoluteUsedCapacity=0.35416666, numApps=5, numContainers=12
2013-08-27 16:04:44,271 INFO org.apache.hadoop.yarn.server.resourcemanager.scheduler.capacity.ParentQueue: assignedContainer queue=root usedCapacity=0.35416666 absoluteUsedCapacity=0.35416666 used=<memory:17408, vCores:12> cluster=<memory:49152, vCores:96>
2013-08-27 16:04:44,271 INFO org.apache.hadoop.yarn.server.resourcemanager.rmcontainer.RMContainerImpl: container_1377618433102_0007_01_000009 Container Transitioned from NEW to ALLOCATED
2013-08-27 16:04:44,271 INFO org.apache.hadoop.yarn.server.resourcemanager.RMAuditLogger: USER=ubuntu	OPERATION=AM Allocated Container	TARGET=SchedulerApp	RESULT=SUCCESS	APPID=application_1377618433102_0007	CONTAINERID=container_1377618433102_0007_01_000009
2013-08-27 16:04:44,271 INFO org.apache.hadoop.yarn.server.resourcemanager.scheduler.common.fica.FiCaSchedulerNode: Assigned container container_1377618433102_0007_01_000009 of capacity <memory:1024, vCores:1> on host hadoop-8-4:36803, which currently has 3 containers, <memory:4096, vCores:3> used and <memory:4096, vCores:13> available
2013-08-27 16:04:44,272 INFO org.apache.hadoop.yarn.server.resourcemanager.scheduler.capacity.LeafQueue: assignedContainer application=application_1377618433102_0007 container=Container: [ContainerId: container_1377618433102_0007_01_000009, NodeId: hadoop-8-4:36803, NodeHttpAddress: hadoop-8-4:8042, Resource: <memory:1024, vCores:1>, Priority: 20, State: NEW, Token: null, Status: container_id {, app_attempt_id {, application_id {, id: 7, cluster_timestamp: 1377618433102, }, attemptId: 1, }, id: 9, }, state: C_NEW, ] containerId=container_1377618433102_0007_01_000009 queue=default: capacity=1.0, absoluteCapacity=1.0, usedResources=<memory:17408, vCores:12>usedCapacity=0.35416666, absoluteUsedCapacity=0.35416666, numApps=5, numContainers=12 usedCapacity=0.35416666 absoluteUsedCapacity=0.35416666 used=<memory:17408, vCores:12> cluster=<memory:49152, vCores:96>
2013-08-27 16:04:44,273 INFO org.apache.hadoop.yarn.server.resourcemanager.scheduler.capacity.ParentQueue: Re-sorting queues since queue: root.default stats: default: capacity=1.0, absoluteCapacity=1.0, usedResources=<memory:18432, vCores:13>usedCapacity=0.375, absoluteUsedCapacity=0.375, numApps=5, numContainers=13
2013-08-27 16:04:44,273 INFO org.apache.hadoop.yarn.server.resourcemanager.scheduler.capacity.ParentQueue: assignedContainer queue=root usedCapacity=0.375 absoluteUsedCapacity=0.375 used=<memory:18432, vCores:13> cluster=<memory:49152, vCores:96>
2013-08-27 16:04:44,273 INFO org.apache.hadoop.yarn.server.resourcemanager.rmcontainer.RMContainerImpl: container_1377618433102_0007_01_000010 Container Transitioned from NEW to ALLOCATED
2013-08-27 16:04:44,274 INFO org.apache.hadoop.yarn.server.resourcemanager.RMAuditLogger: USER=ubuntu	OPERATION=AM Allocated Container	TARGET=SchedulerApp	RESULT=SUCCESS	APPID=application_1377618433102_0007	CONTAINERID=container_1377618433102_0007_01_000010
2013-08-27 16:04:44,274 INFO org.apache.hadoop.yarn.server.resourcemanager.scheduler.common.fica.FiCaSchedulerNode: Assigned container container_1377618433102_0007_01_000010 of capacity <memory:1024, vCores:1> on host hadoop-8-4:36803, which currently has 4 containers, <memory:5120, vCores:4> used and <memory:3072, vCores:12> available
2013-08-27 16:04:44,275 INFO org.apache.hadoop.yarn.server.resourcemanager.scheduler.capacity.LeafQueue: assignedContainer application=application_1377618433102_0007 container=Container: [ContainerId: container_1377618433102_0007_01_000010, NodeId: hadoop-8-4:36803, NodeHttpAddress: hadoop-8-4:8042, Resource: <memory:1024, vCores:1>, Priority: 20, State: NEW, Token: null, Status: container_id {, app_attempt_id {, application_id {, id: 7, cluster_timestamp: 1377618433102, }, attemptId: 1, }, id: 10, }, state: C_NEW, ] containerId=container_1377618433102_0007_01_000010 queue=default: capacity=1.0, absoluteCapacity=1.0, usedResources=<memory:18432, vCores:13>usedCapacity=0.375, absoluteUsedCapacity=0.375, numApps=5, numContainers=13 usedCapacity=0.375 absoluteUsedCapacity=0.375 used=<memory:18432, vCores:13> cluster=<memory:49152, vCores:96>
2013-08-27 16:04:44,275 INFO org.apache.hadoop.yarn.server.resourcemanager.scheduler.capacity.ParentQueue: Re-sorting queues since queue: root.default stats: default: capacity=1.0, absoluteCapacity=1.0, usedResources=<memory:19456, vCores:14>usedCapacity=0.39583334, absoluteUsedCapacity=0.39583334, numApps=5, numContainers=14
2013-08-27 16:04:44,275 INFO org.apache.hadoop.yarn.server.resourcemanager.scheduler.capacity.ParentQueue: assignedContainer queue=root usedCapacity=0.39583334 absoluteUsedCapacity=0.39583334 used=<memory:19456, vCores:14> cluster=<memory:49152, vCores:96>
2013-08-27 16:04:44,276 INFO org.apache.hadoop.yarn.server.resourcemanager.rmcontainer.RMContainerImpl: container_1377618433102_0007_01_000011 Container Transitioned from NEW to ALLOCATED
2013-08-27 16:04:44,276 INFO org.apache.hadoop.yarn.server.resourcemanager.RMAuditLogger: USER=ubuntu	OPERATION=AM Allocated Container	TARGET=SchedulerApp	RESULT=SUCCESS	APPID=application_1377618433102_0007	CONTAINERID=container_1377618433102_0007_01_000011
2013-08-27 16:04:44,276 INFO org.apache.hadoop.yarn.server.resourcemanager.scheduler.common.fica.FiCaSchedulerNode: Assigned container container_1377618433102_0007_01_000011 of capacity <memory:1024, vCores:1> on host hadoop-8-4:36803, which currently has 5 containers, <memory:6144, vCores:5> used and <memory:2048, vCores:11> available
2013-08-27 16:04:44,277 INFO org.apache.hadoop.yarn.server.resourcemanager.scheduler.capacity.LeafQueue: assignedContainer application=application_1377618433102_0007 container=Container: [ContainerId: container_1377618433102_0007_01_000011, NodeId: hadoop-8-4:36803, NodeHttpAddress: hadoop-8-4:8042, Resource: <memory:1024, vCores:1>, Priority: 20, State: NEW, Token: null, Status: container_id {, app_attempt_id {, application_id {, id: 7, cluster_timestamp: 1377618433102, }, attemptId: 1, }, id: 11, }, state: C_NEW, ] containerId=container_1377618433102_0007_01_000011 queue=default: capacity=1.0, absoluteCapacity=1.0, usedResources=<memory:19456, vCores:14>usedCapacity=0.39583334, absoluteUsedCapacity=0.39583334, numApps=5, numContainers=14 usedCapacity=0.39583334 absoluteUsedCapacity=0.39583334 used=<memory:19456, vCores:14> cluster=<memory:49152, vCores:96>
2013-08-27 16:04:44,277 INFO org.apache.hadoop.yarn.server.resourcemanager.scheduler.capacity.ParentQueue: Re-sorting queues since queue: root.default stats: default: capacity=1.0, absoluteCapacity=1.0, usedResources=<memory:20480, vCores:15>usedCapacity=0.41666666, absoluteUsedCapacity=0.41666666, numApps=5, numContainers=15
2013-08-27 16:04:44,277 INFO org.apache.hadoop.yarn.server.resourcemanager.scheduler.capacity.ParentQueue: assignedContainer queue=root usedCapacity=0.41666666 absoluteUsedCapacity=0.41666666 used=<memory:20480, vCores:15> cluster=<memory:49152, vCores:96>
2013-08-27 16:04:44,278 INFO org.apache.hadoop.yarn.server.resourcemanager.rmcontainer.RMContainerImpl: container_1377618433102_0007_01_000012 Container Transitioned from NEW to ALLOCATED
2013-08-27 16:04:44,278 INFO org.apache.hadoop.yarn.server.resourcemanager.RMAuditLogger: USER=ubuntu	OPERATION=AM Allocated Container	TARGET=SchedulerApp	RESULT=SUCCESS	APPID=application_1377618433102_0007	CONTAINERID=container_1377618433102_0007_01_000012
2013-08-27 16:04:44,278 INFO org.apache.hadoop.yarn.server.resourcemanager.scheduler.common.fica.FiCaSchedulerNode: Assigned container container_1377618433102_0007_01_000012 of capacity <memory:1024, vCores:1> on host hadoop-8-4:36803, which currently has 6 containers, <memory:7168, vCores:6> used and <memory:1024, vCores:10> available
2013-08-27 16:04:44,279 INFO org.apache.hadoop.yarn.server.resourcemanager.scheduler.capacity.LeafQueue: assignedContainer application=application_1377618433102_0007 container=Container: [ContainerId: container_1377618433102_0007_01_000012, NodeId: hadoop-8-4:36803, NodeHttpAddress: hadoop-8-4:8042, Resource: <memory:1024, vCores:1>, Priority: 20, State: NEW, Token: null, Status: container_id {, app_attempt_id {, application_id {, id: 7, cluster_timestamp: 1377618433102, }, attemptId: 1, }, id: 12, }, state: C_NEW, ] containerId=container_1377618433102_0007_01_000012 queue=default: capacity=1.0, absoluteCapacity=1.0, usedResources=<memory:20480, vCores:15>usedCapacity=0.41666666, absoluteUsedCapacity=0.41666666, numApps=5, numContainers=15 usedCapacity=0.41666666 absoluteUsedCapacity=0.41666666 used=<memory:20480, vCores:15> cluster=<memory:49152, vCores:96>
2013-08-27 16:04:44,279 INFO org.apache.hadoop.yarn.server.resourcemanager.scheduler.capacity.ParentQueue: Re-sorting queues since queue: root.default stats: default: capacity=1.0, absoluteCapacity=1.0, usedResources=<memory:21504, vCores:16>usedCapacity=0.4375, absoluteUsedCapacity=0.4375, numApps=5, numContainers=16
2013-08-27 16:04:44,280 INFO org.apache.hadoop.yarn.server.resourcemanager.scheduler.capacity.ParentQueue: assignedContainer queue=root usedCapacity=0.4375 absoluteUsedCapacity=0.4375 used=<memory:21504, vCores:16> cluster=<memory:49152, vCores:96>
2013-08-27 16:04:44,280 INFO org.apache.hadoop.yarn.server.resourcemanager.rmcontainer.RMContainerImpl: container_1377618433102_0007_01_000013 Container Transitioned from NEW to ALLOCATED
2013-08-27 16:04:44,280 INFO org.apache.hadoop.yarn.server.resourcemanager.RMAuditLogger: USER=ubuntu	OPERATION=AM Allocated Container	TARGET=SchedulerApp	RESULT=SUCCESS	APPID=application_1377618433102_0007	CONTAINERID=container_1377618433102_0007_01_000013
2013-08-27 16:04:44,280 INFO org.apache.hadoop.yarn.server.resourcemanager.scheduler.common.fica.FiCaSchedulerNode: Assigned container container_1377618433102_0007_01_000013 of capacity <memory:1024, vCores:1> on host hadoop-8-4:36803, which currently has 7 containers, <memory:8192, vCores:7> used and <memory:0, vCores:9> available
2013-08-27 16:04:44,281 INFO org.apache.hadoop.yarn.server.resourcemanager.scheduler.capacity.LeafQueue: assignedContainer application=application_1377618433102_0007 container=Container: [ContainerId: container_1377618433102_0007_01_000013, NodeId: hadoop-8-4:36803, NodeHttpAddress: hadoop-8-4:8042, Resource: <memory:1024, vCores:1>, Priority: 20, State: NEW, Token: null, Status: container_id {, app_attempt_id {, application_id {, id: 7, cluster_timestamp: 1377618433102, }, attemptId: 1, }, id: 13, }, state: C_NEW, ] containerId=container_1377618433102_0007_01_000013 queue=default: capacity=1.0, absoluteCapacity=1.0, usedResources=<memory:21504, vCores:16>usedCapacity=0.4375, absoluteUsedCapacity=0.4375, numApps=5, numContainers=16 usedCapacity=0.4375 absoluteUsedCapacity=0.4375 used=<memory:21504, vCores:16> cluster=<memory:49152, vCores:96>
2013-08-27 16:04:44,282 INFO org.apache.hadoop.yarn.server.resourcemanager.scheduler.capacity.ParentQueue: Re-sorting queues since queue: root.default stats: default: capacity=1.0, absoluteCapacity=1.0, usedResources=<memory:22528, vCores:17>usedCapacity=0.45833334, absoluteUsedCapacity=0.45833334, numApps=5, numContainers=17
2013-08-27 16:04:44,282 INFO org.apache.hadoop.yarn.server.resourcemanager.scheduler.capacity.ParentQueue: assignedContainer queue=root usedCapacity=0.45833334 absoluteUsedCapacity=0.45833334 used=<memory:22528, vCores:17> cluster=<memory:49152, vCores:96>
2013-08-27 16:04:44,319 INFO org.apache.hadoop.yarn.server.resourcemanager.rmcontainer.RMContainerImpl: container_1377618433102_0007_01_000014 Container Transitioned from NEW to ALLOCATED
2013-08-27 16:04:44,319 INFO org.apache.hadoop.yarn.server.resourcemanager.RMAuditLogger: USER=ubuntu	OPERATION=AM Allocated Container	TARGET=SchedulerApp	RESULT=SUCCESS	APPID=application_1377618433102_0007	CONTAINERID=container_1377618433102_0007_01_000014
2013-08-27 16:04:44,319 INFO org.apache.hadoop.yarn.server.resourcemanager.scheduler.common.fica.FiCaSchedulerNode: Assigned container container_1377618433102_0007_01_000014 of capacity <memory:1024, vCores:1> on host hadoop-8-6:45732, which currently has 2 containers, <memory:3072, vCores:2> used and <memory:5120, vCores:14> available
2013-08-27 16:04:44,321 INFO org.apache.hadoop.yarn.server.resourcemanager.scheduler.capacity.LeafQueue: assignedContainer application=application_1377618433102_0007 container=Container: [ContainerId: container_1377618433102_0007_01_000014, NodeId: hadoop-8-6:45732, NodeHttpAddress: hadoop-8-6:8042, Resource: <memory:1024, vCores:1>, Priority: 20, State: NEW, Token: null, Status: container_id {, app_attempt_id {, application_id {, id: 7, cluster_timestamp: 1377618433102, }, attemptId: 1, }, id: 14, }, state: C_NEW, ] containerId=container_1377618433102_0007_01_000014 queue=default: capacity=1.0, absoluteCapacity=1.0, usedResources=<memory:22528, vCores:17>usedCapacity=0.45833334, absoluteUsedCapacity=0.45833334, numApps=5, numContainers=17 usedCapacity=0.45833334 absoluteUsedCapacity=0.45833334 used=<memory:22528, vCores:17> cluster=<memory:49152, vCores:96>
2013-08-27 16:04:44,321 INFO org.apache.hadoop.yarn.server.resourcemanager.scheduler.capacity.ParentQueue: Re-sorting queues since queue: root.default stats: default: capacity=1.0, absoluteCapacity=1.0, usedResources=<memory:23552, vCores:18>usedCapacity=0.47916666, absoluteUsedCapacity=0.47916666, numApps=5, numContainers=18
2013-08-27 16:04:44,321 INFO org.apache.hadoop.yarn.server.resourcemanager.scheduler.capacity.ParentQueue: assignedContainer queue=root usedCapacity=0.47916666 absoluteUsedCapacity=0.47916666 used=<memory:23552, vCores:18> cluster=<memory:49152, vCores:96>
2013-08-27 16:04:44,322 INFO org.apache.hadoop.yarn.server.resourcemanager.rmcontainer.RMContainerImpl: container_1377618433102_0007_01_000015 Container Transitioned from NEW to ALLOCATED
2013-08-27 16:04:44,322 INFO org.apache.hadoop.yarn.server.resourcemanager.RMAuditLogger: USER=ubuntu	OPERATION=AM Allocated Container	TARGET=SchedulerApp	RESULT=SUCCESS	APPID=application_1377618433102_0007	CONTAINERID=container_1377618433102_0007_01_000015
2013-08-27 16:04:44,322 INFO org.apache.hadoop.yarn.server.resourcemanager.scheduler.common.fica.FiCaSchedulerNode: Assigned container container_1377618433102_0007_01_000015 of capacity <memory:1024, vCores:1> on host hadoop-8-6:45732, which currently has 3 containers, <memory:4096, vCores:3> used and <memory:4096, vCores:13> available
2013-08-27 16:04:44,323 INFO org.apache.hadoop.yarn.server.resourcemanager.scheduler.capacity.LeafQueue: assignedContainer application=application_1377618433102_0007 container=Container: [ContainerId: container_1377618433102_0007_01_000015, NodeId: hadoop-8-6:45732, NodeHttpAddress: hadoop-8-6:8042, Resource: <memory:1024, vCores:1>, Priority: 20, State: NEW, Token: null, Status: container_id {, app_attempt_id {, application_id {, id: 7, cluster_timestamp: 1377618433102, }, attemptId: 1, }, id: 15, }, state: C_NEW, ] containerId=container_1377618433102_0007_01_000015 queue=default: capacity=1.0, absoluteCapacity=1.0, usedResources=<memory:23552, vCores:18>usedCapacity=0.47916666, absoluteUsedCapacity=0.47916666, numApps=5, numContainers=18 usedCapacity=0.47916666 absoluteUsedCapacity=0.47916666 used=<memory:23552, vCores:18> cluster=<memory:49152, vCores:96>
2013-08-27 16:04:44,323 INFO org.apache.hadoop.yarn.server.resourcemanager.scheduler.capacity.ParentQueue: Re-sorting queues since queue: root.default stats: default: capacity=1.0, absoluteCapacity=1.0, usedResources=<memory:24576, vCores:19>usedCapacity=0.5, absoluteUsedCapacity=0.5, numApps=5, numContainers=19
2013-08-27 16:04:44,323 INFO org.apache.hadoop.yarn.server.resourcemanager.scheduler.capacity.ParentQueue: assignedContainer queue=root usedCapacity=0.5 absoluteUsedCapacity=0.5 used=<memory:24576, vCores:19> cluster=<memory:49152, vCores:96>
2013-08-27 16:04:44,324 INFO org.apache.hadoop.yarn.server.resourcemanager.rmcontainer.RMContainerImpl: container_1377618433102_0007_01_000016 Container Transitioned from NEW to ALLOCATED
2013-08-27 16:04:44,324 INFO org.apache.hadoop.yarn.server.resourcemanager.RMAuditLogger: USER=ubuntu	OPERATION=AM Allocated Container	TARGET=SchedulerApp	RESULT=SUCCESS	APPID=application_1377618433102_0007	CONTAINERID=container_1377618433102_0007_01_000016
2013-08-27 16:04:44,324 INFO org.apache.hadoop.yarn.server.resourcemanager.scheduler.common.fica.FiCaSchedulerNode: Assigned container container_1377618433102_0007_01_000016 of capacity <memory:1024, vCores:1> on host hadoop-8-6:45732, which currently has 4 containers, <memory:5120, vCores:4> used and <memory:3072, vCores:12> available
2013-08-27 16:04:44,325 INFO org.apache.hadoop.yarn.server.resourcemanager.scheduler.capacity.LeafQueue: assignedContainer application=application_1377618433102_0007 container=Container: [ContainerId: container_1377618433102_0007_01_000016, NodeId: hadoop-8-6:45732, NodeHttpAddress: hadoop-8-6:8042, Resource: <memory:1024, vCores:1>, Priority: 20, State: NEW, Token: null, Status: container_id {, app_attempt_id {, application_id {, id: 7, cluster_timestamp: 1377618433102, }, attemptId: 1, }, id: 16, }, state: C_NEW, ] containerId=container_1377618433102_0007_01_000016 queue=default: capacity=1.0, absoluteCapacity=1.0, usedResources=<memory:24576, vCores:19>usedCapacity=0.5, absoluteUsedCapacity=0.5, numApps=5, numContainers=19 usedCapacity=0.5 absoluteUsedCapacity=0.5 used=<memory:24576, vCores:19> cluster=<memory:49152, vCores:96>
2013-08-27 16:04:44,325 INFO org.apache.hadoop.yarn.server.resourcemanager.scheduler.capacity.ParentQueue: Re-sorting queues since queue: root.default stats: default: capacity=1.0, absoluteCapacity=1.0, usedResources=<memory:25600, vCores:20>usedCapacity=0.5208333, absoluteUsedCapacity=0.5208333, numApps=5, numContainers=20
2013-08-27 16:04:44,325 INFO org.apache.hadoop.yarn.server.resourcemanager.scheduler.capacity.ParentQueue: assignedContainer queue=root usedCapacity=0.5208333 absoluteUsedCapacity=0.5208333 used=<memory:25600, vCores:20> cluster=<memory:49152, vCores:96>
2013-08-27 16:04:44,326 INFO org.apache.hadoop.yarn.server.resourcemanager.rmcontainer.RMContainerImpl: container_1377618433102_0007_01_000017 Container Transitioned from NEW to ALLOCATED
2013-08-27 16:04:44,326 INFO org.apache.hadoop.yarn.server.resourcemanager.RMAuditLogger: USER=ubuntu	OPERATION=AM Allocated Container	TARGET=SchedulerApp	RESULT=SUCCESS	APPID=application_1377618433102_0007	CONTAINERID=container_1377618433102_0007_01_000017
2013-08-27 16:04:44,326 INFO org.apache.hadoop.yarn.server.resourcemanager.scheduler.common.fica.FiCaSchedulerNode: Assigned container container_1377618433102_0007_01_000017 of capacity <memory:1024, vCores:1> on host hadoop-8-6:45732, which currently has 5 containers, <memory:6144, vCores:5> used and <memory:2048, vCores:11> available
2013-08-27 16:04:44,327 INFO org.apache.hadoop.yarn.server.resourcemanager.scheduler.capacity.LeafQueue: assignedContainer application=application_1377618433102_0007 container=Container: [ContainerId: container_1377618433102_0007_01_000017, NodeId: hadoop-8-6:45732, NodeHttpAddress: hadoop-8-6:8042, Resource: <memory:1024, vCores:1>, Priority: 20, State: NEW, Token: null, Status: container_id {, app_attempt_id {, application_id {, id: 7, cluster_timestamp: 1377618433102, }, attemptId: 1, }, id: 17, }, state: C_NEW, ] containerId=container_1377618433102_0007_01_000017 queue=default: capacity=1.0, absoluteCapacity=1.0, usedResources=<memory:25600, vCores:20>usedCapacity=0.5208333, absoluteUsedCapacity=0.5208333, numApps=5, numContainers=20 usedCapacity=0.5208333 absoluteUsedCapacity=0.5208333 used=<memory:25600, vCores:20> cluster=<memory:49152, vCores:96>
2013-08-27 16:04:44,328 INFO org.apache.hadoop.yarn.server.resourcemanager.scheduler.capacity.ParentQueue: Re-sorting queues since queue: root.default stats: default: capacity=1.0, absoluteCapacity=1.0, usedResources=<memory:26624, vCores:21>usedCapacity=0.5416667, absoluteUsedCapacity=0.5416667, numApps=5, numContainers=21
2013-08-27 16:04:44,328 INFO org.apache.hadoop.yarn.server.resourcemanager.scheduler.capacity.ParentQueue: assignedContainer queue=root usedCapacity=0.5416667 absoluteUsedCapacity=0.5416667 used=<memory:26624, vCores:21> cluster=<memory:49152, vCores:96>
2013-08-27 16:04:44,328 INFO org.apache.hadoop.yarn.server.resourcemanager.rmcontainer.RMContainerImpl: container_1377618433102_0007_01_000018 Container Transitioned from NEW to ALLOCATED
2013-08-27 16:04:44,328 INFO org.apache.hadoop.yarn.server.resourcemanager.RMAuditLogger: USER=ubuntu	OPERATION=AM Allocated Container	TARGET=SchedulerApp	RESULT=SUCCESS	APPID=application_1377618433102_0007	CONTAINERID=container_1377618433102_0007_01_000018
2013-08-27 16:04:44,328 INFO org.apache.hadoop.yarn.server.resourcemanager.scheduler.common.fica.FiCaSchedulerNode: Assigned container container_1377618433102_0007_01_000018 of capacity <memory:1024, vCores:1> on host hadoop-8-6:45732, which currently has 6 containers, <memory:7168, vCores:6> used and <memory:1024, vCores:10> available
2013-08-27 16:04:44,329 INFO org.apache.hadoop.yarn.server.resourcemanager.scheduler.capacity.LeafQueue: assignedContainer application=application_1377618433102_0007 container=Container: [ContainerId: container_1377618433102_0007_01_000018, NodeId: hadoop-8-6:45732, NodeHttpAddress: hadoop-8-6:8042, Resource: <memory:1024, vCores:1>, Priority: 20, State: NEW, Token: null, Status: container_id {, app_attempt_id {, application_id {, id: 7, cluster_timestamp: 1377618433102, }, attemptId: 1, }, id: 18, }, state: C_NEW, ] containerId=container_1377618433102_0007_01_000018 queue=default: capacity=1.0, absoluteCapacity=1.0, usedResources=<memory:26624, vCores:21>usedCapacity=0.5416667, absoluteUsedCapacity=0.5416667, numApps=5, numContainers=21 usedCapacity=0.5416667 absoluteUsedCapacity=0.5416667 used=<memory:26624, vCores:21> cluster=<memory:49152, vCores:96>
2013-08-27 16:04:44,330 INFO org.apache.hadoop.yarn.server.resourcemanager.scheduler.capacity.ParentQueue: Re-sorting queues since queue: root.default stats: default: capacity=1.0, absoluteCapacity=1.0, usedResources=<memory:27648, vCores:22>usedCapacity=0.5625, absoluteUsedCapacity=0.5625, numApps=5, numContainers=22
2013-08-27 16:04:44,330 INFO org.apache.hadoop.yarn.server.resourcemanager.scheduler.capacity.ParentQueue: assignedContainer queue=root usedCapacity=0.5625 absoluteUsedCapacity=0.5625 used=<memory:27648, vCores:22> cluster=<memory:49152, vCores:96>
2013-08-27 16:04:44,330 INFO org.apache.hadoop.yarn.server.resourcemanager.rmcontainer.RMContainerImpl: container_1377618433102_0007_01_000019 Container Transitioned from NEW to ALLOCATED
2013-08-27 16:04:44,330 INFO org.apache.hadoop.yarn.server.resourcemanager.RMAuditLogger: USER=ubuntu	OPERATION=AM Allocated Container	TARGET=SchedulerApp	RESULT=SUCCESS	APPID=application_1377618433102_0007	CONTAINERID=container_1377618433102_0007_01_000019
2013-08-27 16:04:44,331 INFO org.apache.hadoop.yarn.server.resourcemanager.scheduler.common.fica.FiCaSchedulerNode: Assigned container container_1377618433102_0007_01_000019 of capacity <memory:1024, vCores:1> on host hadoop-8-6:45732, which currently has 7 containers, <memory:8192, vCores:7> used and <memory:0, vCores:9> available
2013-08-27 16:04:44,332 INFO org.apache.hadoop.yarn.server.resourcemanager.scheduler.capacity.LeafQueue: assignedContainer application=application_1377618433102_0007 container=Container: [ContainerId: container_1377618433102_0007_01_000019, NodeId: hadoop-8-6:45732, NodeHttpAddress: hadoop-8-6:8042, Resource: <memory:1024, vCores:1>, Priority: 20, State: NEW, Token: null, Status: container_id {, app_attempt_id {, application_id {, id: 7, cluster_timestamp: 1377618433102, }, attemptId: 1, }, id: 19, }, state: C_NEW, ] containerId=container_1377618433102_0007_01_000019 queue=default: capacity=1.0, absoluteCapacity=1.0, usedResources=<memory:27648, vCores:22>usedCapacity=0.5625, absoluteUsedCapacity=0.5625, numApps=5, numContainers=22 usedCapacity=0.5625 absoluteUsedCapacity=0.5625 used=<memory:27648, vCores:22> cluster=<memory:49152, vCores:96>
2013-08-27 16:04:44,332 INFO org.apache.hadoop.yarn.server.resourcemanager.scheduler.capacity.ParentQueue: Re-sorting queues since queue: root.default stats: default: capacity=1.0, absoluteCapacity=1.0, usedResources=<memory:28672, vCores:23>usedCapacity=0.5833333, absoluteUsedCapacity=0.5833333, numApps=5, numContainers=23
2013-08-27 16:04:44,332 INFO org.apache.hadoop.yarn.server.resourcemanager.scheduler.capacity.ParentQueue: assignedContainer queue=root usedCapacity=0.5833333 absoluteUsedCapacity=0.5833333 used=<memory:28672, vCores:23> cluster=<memory:49152, vCores:96>
2013-08-27 16:04:44,350 INFO org.apache.hadoop.yarn.server.resourcemanager.rmcontainer.RMContainerImpl: container_1377618433102_0007_01_000020 Container Transitioned from NEW to ALLOCATED
2013-08-27 16:04:44,351 INFO org.apache.hadoop.yarn.server.resourcemanager.RMAuditLogger: USER=ubuntu	OPERATION=AM Allocated Container	TARGET=SchedulerApp	RESULT=SUCCESS	APPID=application_1377618433102_0007	CONTAINERID=container_1377618433102_0007_01_000020
2013-08-27 16:04:44,351 INFO org.apache.hadoop.yarn.server.resourcemanager.scheduler.common.fica.FiCaSchedulerNode: Assigned container container_1377618433102_0007_01_000020 of capacity <memory:1024, vCores:1> on host hadoop-8-3:42074, which currently has 1 containers, <memory:1024, vCores:1> used and <memory:7168, vCores:15> available
2013-08-27 16:04:44,352 INFO org.apache.hadoop.yarn.server.resourcemanager.scheduler.capacity.LeafQueue: assignedContainer application=application_1377618433102_0007 container=Container: [ContainerId: container_1377618433102_0007_01_000020, NodeId: hadoop-8-3:42074, NodeHttpAddress: hadoop-8-3:8042, Resource: <memory:1024, vCores:1>, Priority: 20, State: NEW, Token: null, Status: container_id {, app_attempt_id {, application_id {, id: 7, cluster_timestamp: 1377618433102, }, attemptId: 1, }, id: 20, }, state: C_NEW, ] containerId=container_1377618433102_0007_01_000020 queue=default: capacity=1.0, absoluteCapacity=1.0, usedResources=<memory:28672, vCores:23>usedCapacity=0.5833333, absoluteUsedCapacity=0.5833333, numApps=5, numContainers=23 usedCapacity=0.5833333 absoluteUsedCapacity=0.5833333 used=<memory:28672, vCores:23> cluster=<memory:49152, vCores:96>
2013-08-27 16:04:44,352 INFO org.apache.hadoop.yarn.server.resourcemanager.scheduler.capacity.ParentQueue: Re-sorting queues since queue: root.default stats: default: capacity=1.0, absoluteCapacity=1.0, usedResources=<memory:29696, vCores:24>usedCapacity=0.6041667, absoluteUsedCapacity=0.6041667, numApps=5, numContainers=24
2013-08-27 16:04:44,353 INFO org.apache.hadoop.yarn.server.resourcemanager.scheduler.capacity.ParentQueue: assignedContainer queue=root usedCapacity=0.6041667 absoluteUsedCapacity=0.6041667 used=<memory:29696, vCores:24> cluster=<memory:49152, vCores:96>
2013-08-27 16:04:44,353 INFO org.apache.hadoop.yarn.server.resourcemanager.rmcontainer.RMContainerImpl: container_1377618433102_0007_01_000021 Container Transitioned from NEW to ALLOCATED
2013-08-27 16:04:44,353 INFO org.apache.hadoop.yarn.server.resourcemanager.RMAuditLogger: USER=ubuntu	OPERATION=AM Allocated Container	TARGET=SchedulerApp	RESULT=SUCCESS	APPID=application_1377618433102_0007	CONTAINERID=container_1377618433102_0007_01_000021
2013-08-27 16:04:44,353 INFO org.apache.hadoop.yarn.server.resourcemanager.scheduler.common.fica.FiCaSchedulerNode: Assigned container container_1377618433102_0007_01_000021 of capacity <memory:1024, vCores:1> on host hadoop-8-3:42074, which currently has 2 containers, <memory:2048, vCores:2> used and <memory:6144, vCores:14> available
2013-08-27 16:04:44,354 INFO org.apache.hadoop.yarn.server.resourcemanager.scheduler.capacity.LeafQueue: assignedContainer application=application_1377618433102_0007 container=Container: [ContainerId: container_1377618433102_0007_01_000021, NodeId: hadoop-8-3:42074, NodeHttpAddress: hadoop-8-3:8042, Resource: <memory:1024, vCores:1>, Priority: 20, State: NEW, Token: null, Status: container_id {, app_attempt_id {, application_id {, id: 7, cluster_timestamp: 1377618433102, }, attemptId: 1, }, id: 21, }, state: C_NEW, ] containerId=container_1377618433102_0007_01_000021 queue=default: capacity=1.0, absoluteCapacity=1.0, usedResources=<memory:29696, vCores:24>usedCapacity=0.6041667, absoluteUsedCapacity=0.6041667, numApps=5, numContainers=24 usedCapacity=0.6041667 absoluteUsedCapacity=0.6041667 used=<memory:29696, vCores:24> cluster=<memory:49152, vCores:96>
2013-08-27 16:04:44,355 INFO org.apache.hadoop.yarn.server.resourcemanager.scheduler.capacity.ParentQueue: Re-sorting queues since queue: root.default stats: default: capacity=1.0, absoluteCapacity=1.0, usedResources=<memory:30720, vCores:25>usedCapacity=0.625, absoluteUsedCapacity=0.625, numApps=5, numContainers=25
2013-08-27 16:04:44,355 INFO org.apache.hadoop.yarn.server.resourcemanager.scheduler.capacity.ParentQueue: assignedContainer queue=root usedCapacity=0.625 absoluteUsedCapacity=0.625 used=<memory:30720, vCores:25> cluster=<memory:49152, vCores:96>
2013-08-27 16:04:44,355 INFO org.apache.hadoop.yarn.server.resourcemanager.rmcontainer.RMContainerImpl: container_1377618433102_0007_01_000022 Container Transitioned from NEW to ALLOCATED
2013-08-27 16:04:44,355 INFO org.apache.hadoop.yarn.server.resourcemanager.RMAuditLogger: USER=ubuntu	OPERATION=AM Allocated Container	TARGET=SchedulerApp	RESULT=SUCCESS	APPID=application_1377618433102_0007	CONTAINERID=container_1377618433102_0007_01_000022
2013-08-27 16:04:44,356 INFO org.apache.hadoop.yarn.server.resourcemanager.scheduler.common.fica.FiCaSchedulerNode: Assigned container container_1377618433102_0007_01_000022 of capacity <memory:1024, vCores:1> on host hadoop-8-3:42074, which currently has 3 containers, <memory:3072, vCores:3> used and <memory:5120, vCores:13> available
2013-08-27 16:04:44,357 INFO org.apache.hadoop.yarn.server.resourcemanager.scheduler.capacity.LeafQueue: assignedContainer application=application_1377618433102_0007 container=Container: [ContainerId: container_1377618433102_0007_01_000022, NodeId: hadoop-8-3:42074, NodeHttpAddress: hadoop-8-3:8042, Resource: <memory:1024, vCores:1>, Priority: 20, State: NEW, Token: null, Status: container_id {, app_attempt_id {, application_id {, id: 7, cluster_timestamp: 1377618433102, }, attemptId: 1, }, id: 22, }, state: C_NEW, ] containerId=container_1377618433102_0007_01_000022 queue=default: capacity=1.0, absoluteCapacity=1.0, usedResources=<memory:30720, vCores:25>usedCapacity=0.625, absoluteUsedCapacity=0.625, numApps=5, numContainers=25 usedCapacity=0.625 absoluteUsedCapacity=0.625 used=<memory:30720, vCores:25> cluster=<memory:49152, vCores:96>
2013-08-27 16:04:44,357 INFO org.apache.hadoop.yarn.server.resourcemanager.scheduler.capacity.ParentQueue: Re-sorting queues since queue: root.default stats: default: capacity=1.0, absoluteCapacity=1.0, usedResources=<memory:31744, vCores:26>usedCapacity=0.6458333, absoluteUsedCapacity=0.6458333, numApps=5, numContainers=26
2013-08-27 16:04:44,357 INFO org.apache.hadoop.yarn.server.resourcemanager.scheduler.capacity.ParentQueue: assignedContainer queue=root usedCapacity=0.6458333 absoluteUsedCapacity=0.6458333 used=<memory:31744, vCores:26> cluster=<memory:49152, vCores:96>
2013-08-27 16:04:44,358 INFO org.apache.hadoop.yarn.server.resourcemanager.rmcontainer.RMContainerImpl: container_1377618433102_0007_01_000023 Container Transitioned from NEW to ALLOCATED
2013-08-27 16:04:44,358 INFO org.apache.hadoop.yarn.server.resourcemanager.RMAuditLogger: USER=ubuntu	OPERATION=AM Allocated Container	TARGET=SchedulerApp	RESULT=SUCCESS	APPID=application_1377618433102_0007	CONTAINERID=container_1377618433102_0007_01_000023
2013-08-27 16:04:44,358 INFO org.apache.hadoop.yarn.server.resourcemanager.scheduler.common.fica.FiCaSchedulerNode: Assigned container container_1377618433102_0007_01_000023 of capacity <memory:1024, vCores:1> on host hadoop-8-3:42074, which currently has 4 containers, <memory:4096, vCores:4> used and <memory:4096, vCores:12> available
2013-08-27 16:04:44,359 INFO org.apache.hadoop.yarn.server.resourcemanager.scheduler.capacity.LeafQueue: assignedContainer application=application_1377618433102_0007 container=Container: [ContainerId: container_1377618433102_0007_01_000023, NodeId: hadoop-8-3:42074, NodeHttpAddress: hadoop-8-3:8042, Resource: <memory:1024, vCores:1>, Priority: 20, State: NEW, Token: null, Status: container_id {, app_attempt_id {, application_id {, id: 7, cluster_timestamp: 1377618433102, }, attemptId: 1, }, id: 23, }, state: C_NEW, ] containerId=container_1377618433102_0007_01_000023 queue=default: capacity=1.0, absoluteCapacity=1.0, usedResources=<memory:31744, vCores:26>usedCapacity=0.6458333, absoluteUsedCapacity=0.6458333, numApps=5, numContainers=26 usedCapacity=0.6458333 absoluteUsedCapacity=0.6458333 used=<memory:31744, vCores:26> cluster=<memory:49152, vCores:96>
2013-08-27 16:04:44,359 INFO org.apache.hadoop.yarn.server.resourcemanager.scheduler.capacity.ParentQueue: Re-sorting queues since queue: root.default stats: default: capacity=1.0, absoluteCapacity=1.0, usedResources=<memory:32768, vCores:27>usedCapacity=0.6666667, absoluteUsedCapacity=0.6666667, numApps=5, numContainers=27
2013-08-27 16:04:44,359 INFO org.apache.hadoop.yarn.server.resourcemanager.scheduler.capacity.ParentQueue: assignedContainer queue=root usedCapacity=0.6666667 absoluteUsedCapacity=0.6666667 used=<memory:32768, vCores:27> cluster=<memory:49152, vCores:96>
2013-08-27 16:04:44,360 INFO org.apache.hadoop.yarn.server.resourcemanager.rmcontainer.RMContainerImpl: container_1377618433102_0007_01_000024 Container Transitioned from NEW to ALLOCATED
2013-08-27 16:04:44,360 INFO org.apache.hadoop.yarn.server.resourcemanager.RMAuditLogger: USER=ubuntu	OPERATION=AM Allocated Container	TARGET=SchedulerApp	RESULT=SUCCESS	APPID=application_1377618433102_0007	CONTAINERID=container_1377618433102_0007_01_000024
2013-08-27 16:04:44,360 INFO org.apache.hadoop.yarn.server.resourcemanager.scheduler.common.fica.FiCaSchedulerNode: Assigned container container_1377618433102_0007_01_000024 of capacity <memory:1024, vCores:1> on host hadoop-8-3:42074, which currently has 5 containers, <memory:5120, vCores:5> used and <memory:3072, vCores:11> available
2013-08-27 16:04:44,361 INFO org.apache.hadoop.yarn.server.resourcemanager.scheduler.capacity.LeafQueue: assignedContainer application=application_1377618433102_0007 container=Container: [ContainerId: container_1377618433102_0007_01_000024, NodeId: hadoop-8-3:42074, NodeHttpAddress: hadoop-8-3:8042, Resource: <memory:1024, vCores:1>, Priority: 20, State: NEW, Token: null, Status: container_id {, app_attempt_id {, application_id {, id: 7, cluster_timestamp: 1377618433102, }, attemptId: 1, }, id: 24, }, state: C_NEW, ] containerId=container_1377618433102_0007_01_000024 queue=default: capacity=1.0, absoluteCapacity=1.0, usedResources=<memory:32768, vCores:27>usedCapacity=0.6666667, absoluteUsedCapacity=0.6666667, numApps=5, numContainers=27 usedCapacity=0.6666667 absoluteUsedCapacity=0.6666667 used=<memory:32768, vCores:27> cluster=<memory:49152, vCores:96>
2013-08-27 16:04:44,361 INFO org.apache.hadoop.yarn.server.resourcemanager.scheduler.capacity.ParentQueue: Re-sorting queues since queue: root.default stats: default: capacity=1.0, absoluteCapacity=1.0, usedResources=<memory:33792, vCores:28>usedCapacity=0.6875, absoluteUsedCapacity=0.6875, numApps=5, numContainers=28
2013-08-27 16:04:44,361 INFO org.apache.hadoop.yarn.server.resourcemanager.scheduler.capacity.ParentQueue: assignedContainer queue=root usedCapacity=0.6875 absoluteUsedCapacity=0.6875 used=<memory:33792, vCores:28> cluster=<memory:49152, vCores:96>
2013-08-27 16:04:44,362 INFO org.apache.hadoop.yarn.server.resourcemanager.rmcontainer.RMContainerImpl: container_1377618433102_0007_01_000025 Container Transitioned from NEW to ALLOCATED
2013-08-27 16:04:44,362 INFO org.apache.hadoop.yarn.server.resourcemanager.RMAuditLogger: USER=ubuntu	OPERATION=AM Allocated Container	TARGET=SchedulerApp	RESULT=SUCCESS	APPID=application_1377618433102_0007	CONTAINERID=container_1377618433102_0007_01_000025
2013-08-27 16:04:44,362 INFO org.apache.hadoop.yarn.server.resourcemanager.scheduler.common.fica.FiCaSchedulerNode: Assigned container container_1377618433102_0007_01_000025 of capacity <memory:1024, vCores:1> on host hadoop-8-3:42074, which currently has 6 containers, <memory:6144, vCores:6> used and <memory:2048, vCores:10> available
2013-08-27 16:04:44,363 INFO org.apache.hadoop.yarn.server.resourcemanager.scheduler.capacity.LeafQueue: assignedContainer application=application_1377618433102_0007 container=Container: [ContainerId: container_1377618433102_0007_01_000025, NodeId: hadoop-8-3:42074, NodeHttpAddress: hadoop-8-3:8042, Resource: <memory:1024, vCores:1>, Priority: 20, State: NEW, Token: null, Status: container_id {, app_attempt_id {, application_id {, id: 7, cluster_timestamp: 1377618433102, }, attemptId: 1, }, id: 25, }, state: C_NEW, ] containerId=container_1377618433102_0007_01_000025 queue=default: capacity=1.0, absoluteCapacity=1.0, usedResources=<memory:33792, vCores:28>usedCapacity=0.6875, absoluteUsedCapacity=0.6875, numApps=5, numContainers=28 usedCapacity=0.6875 absoluteUsedCapacity=0.6875 used=<memory:33792, vCores:28> cluster=<memory:49152, vCores:96>
2013-08-27 16:04:44,363 INFO org.apache.hadoop.yarn.server.resourcemanager.scheduler.capacity.ParentQueue: Re-sorting queues since queue: root.default stats: default: capacity=1.0, absoluteCapacity=1.0, usedResources=<memory:34816, vCores:29>usedCapacity=0.7083333, absoluteUsedCapacity=0.7083333, numApps=5, numContainers=29
2013-08-27 16:04:44,364 INFO org.apache.hadoop.yarn.server.resourcemanager.scheduler.capacity.ParentQueue: assignedContainer queue=root usedCapacity=0.7083333 absoluteUsedCapacity=0.7083333 used=<memory:34816, vCores:29> cluster=<memory:49152, vCores:96>
2013-08-27 16:04:44,364 INFO org.apache.hadoop.yarn.server.resourcemanager.rmcontainer.RMContainerImpl: container_1377618433102_0007_01_000026 Container Transitioned from NEW to ALLOCATED
2013-08-27 16:04:44,364 INFO org.apache.hadoop.yarn.server.resourcemanager.RMAuditLogger: USER=ubuntu	OPERATION=AM Allocated Container	TARGET=SchedulerApp	RESULT=SUCCESS	APPID=application_1377618433102_0007	CONTAINERID=container_1377618433102_0007_01_000026
2013-08-27 16:04:44,364 INFO org.apache.hadoop.yarn.server.resourcemanager.scheduler.common.fica.FiCaSchedulerNode: Assigned container container_1377618433102_0007_01_000026 of capacity <memory:1024, vCores:1> on host hadoop-8-3:42074, which currently has 7 containers, <memory:7168, vCores:7> used and <memory:1024, vCores:9> available
2013-08-27 16:04:44,365 INFO org.apache.hadoop.yarn.server.resourcemanager.scheduler.capacity.LeafQueue: assignedContainer application=application_1377618433102_0007 container=Container: [ContainerId: container_1377618433102_0007_01_000026, NodeId: hadoop-8-3:42074, NodeHttpAddress: hadoop-8-3:8042, Resource: <memory:1024, vCores:1>, Priority: 20, State: NEW, Token: null, Status: container_id {, app_attempt_id {, application_id {, id: 7, cluster_timestamp: 1377618433102, }, attemptId: 1, }, id: 26, }, state: C_NEW, ] containerId=container_1377618433102_0007_01_000026 queue=default: capacity=1.0, absoluteCapacity=1.0, usedResources=<memory:34816, vCores:29>usedCapacity=0.7083333, absoluteUsedCapacity=0.7083333, numApps=5, numContainers=29 usedCapacity=0.7083333 absoluteUsedCapacity=0.7083333 used=<memory:34816, vCores:29> cluster=<memory:49152, vCores:96>
2013-08-27 16:04:44,365 INFO org.apache.hadoop.yarn.server.resourcemanager.scheduler.capacity.ParentQueue: Re-sorting queues since queue: root.default stats: default: capacity=1.0, absoluteCapacity=1.0, usedResources=<memory:35840, vCores:30>usedCapacity=0.7291667, absoluteUsedCapacity=0.7291667, numApps=5, numContainers=30
2013-08-27 16:04:44,366 INFO org.apache.hadoop.yarn.server.resourcemanager.scheduler.capacity.ParentQueue: assignedContainer queue=root usedCapacity=0.7291667 absoluteUsedCapacity=0.7291667 used=<memory:35840, vCores:30> cluster=<memory:49152, vCores:96>
2013-08-27 16:04:44,366 INFO org.apache.hadoop.yarn.server.resourcemanager.rmcontainer.RMContainerImpl: container_1377618433102_0007_01_000027 Container Transitioned from NEW to ALLOCATED
2013-08-27 16:04:44,366 INFO org.apache.hadoop.yarn.server.resourcemanager.RMAuditLogger: USER=ubuntu	OPERATION=AM Allocated Container	TARGET=SchedulerApp	RESULT=SUCCESS	APPID=application_1377618433102_0007	CONTAINERID=container_1377618433102_0007_01_000027
2013-08-27 16:04:44,366 INFO org.apache.hadoop.yarn.server.resourcemanager.scheduler.common.fica.FiCaSchedulerNode: Assigned container container_1377618433102_0007_01_000027 of capacity <memory:1024, vCores:1> on host hadoop-8-3:42074, which currently has 8 containers, <memory:8192, vCores:8> used and <memory:0, vCores:8> available
2013-08-27 16:04:44,367 INFO org.apache.hadoop.yarn.server.resourcemanager.scheduler.capacity.LeafQueue: assignedContainer application=application_1377618433102_0007 container=Container: [ContainerId: container_1377618433102_0007_01_000027, NodeId: hadoop-8-3:42074, NodeHttpAddress: hadoop-8-3:8042, Resource: <memory:1024, vCores:1>, Priority: 20, State: NEW, Token: null, Status: container_id {, app_attempt_id {, application_id {, id: 7, cluster_timestamp: 1377618433102, }, attemptId: 1, }, id: 27, }, state: C_NEW, ] containerId=container_1377618433102_0007_01_000027 queue=default: capacity=1.0, absoluteCapacity=1.0, usedResources=<memory:35840, vCores:30>usedCapacity=0.7291667, absoluteUsedCapacity=0.7291667, numApps=5, numContainers=30 usedCapacity=0.7291667 absoluteUsedCapacity=0.7291667 used=<memory:35840, vCores:30> cluster=<memory:49152, vCores:96>
2013-08-27 16:04:44,368 INFO org.apache.hadoop.yarn.server.resourcemanager.scheduler.capacity.ParentQueue: Re-sorting queues since queue: root.default stats: default: capacity=1.0, absoluteCapacity=1.0, usedResources=<memory:36864, vCores:31>usedCapacity=0.75, absoluteUsedCapacity=0.75, numApps=5, numContainers=31
2013-08-27 16:04:44,368 INFO org.apache.hadoop.yarn.server.resourcemanager.scheduler.capacity.ParentQueue: assignedContainer queue=root usedCapacity=0.75 absoluteUsedCapacity=0.75 used=<memory:36864, vCores:31> cluster=<memory:49152, vCores:96>
2013-08-27 16:04:44,415 INFO org.apache.hadoop.yarn.server.resourcemanager.rmcontainer.RMContainerImpl: container_1377618433102_0007_01_000028 Container Transitioned from NEW to ALLOCATED
2013-08-27 16:04:44,415 INFO org.apache.hadoop.yarn.server.resourcemanager.RMAuditLogger: USER=ubuntu	OPERATION=AM Allocated Container	TARGET=SchedulerApp	RESULT=SUCCESS	APPID=application_1377618433102_0007	CONTAINERID=container_1377618433102_0007_01_000028
2013-08-27 16:04:44,415 INFO org.apache.hadoop.yarn.server.resourcemanager.scheduler.common.fica.FiCaSchedulerNode: Assigned container container_1377618433102_0007_01_000028 of capacity <memory:1024, vCores:1> on host hadoop-8-2:41932, which currently has 2 containers, <memory:3072, vCores:2> used and <memory:5120, vCores:14> available
2013-08-27 16:04:44,416 INFO org.apache.hadoop.yarn.server.resourcemanager.scheduler.capacity.LeafQueue: assignedContainer application=application_1377618433102_0007 container=Container: [ContainerId: container_1377618433102_0007_01_000028, NodeId: hadoop-8-2:41932, NodeHttpAddress: hadoop-8-2:8042, Resource: <memory:1024, vCores:1>, Priority: 20, State: NEW, Token: null, Status: container_id {, app_attempt_id {, application_id {, id: 7, cluster_timestamp: 1377618433102, }, attemptId: 1, }, id: 28, }, state: C_NEW, ] containerId=container_1377618433102_0007_01_000028 queue=default: capacity=1.0, absoluteCapacity=1.0, usedResources=<memory:36864, vCores:31>usedCapacity=0.75, absoluteUsedCapacity=0.75, numApps=5, numContainers=31 usedCapacity=0.75 absoluteUsedCapacity=0.75 used=<memory:36864, vCores:31> cluster=<memory:49152, vCores:96>
2013-08-27 16:04:44,416 INFO org.apache.hadoop.yarn.server.resourcemanager.scheduler.capacity.ParentQueue: Re-sorting queues since queue: root.default stats: default: capacity=1.0, absoluteCapacity=1.0, usedResources=<memory:37888, vCores:32>usedCapacity=0.7708333, absoluteUsedCapacity=0.7708333, numApps=5, numContainers=32
2013-08-27 16:04:44,417 INFO org.apache.hadoop.yarn.server.resourcemanager.scheduler.capacity.ParentQueue: assignedContainer queue=root usedCapacity=0.7708333 absoluteUsedCapacity=0.7708333 used=<memory:37888, vCores:32> cluster=<memory:49152, vCores:96>
2013-08-27 16:04:44,417 INFO org.apache.hadoop.yarn.server.resourcemanager.rmcontainer.RMContainerImpl: container_1377618433102_0007_01_000029 Container Transitioned from NEW to ALLOCATED
2013-08-27 16:04:44,417 INFO org.apache.hadoop.yarn.server.resourcemanager.RMAuditLogger: USER=ubuntu	OPERATION=AM Allocated Container	TARGET=SchedulerApp	RESULT=SUCCESS	APPID=application_1377618433102_0007	CONTAINERID=container_1377618433102_0007_01_000029
2013-08-27 16:04:44,417 INFO org.apache.hadoop.yarn.server.resourcemanager.scheduler.common.fica.FiCaSchedulerNode: Assigned container container_1377618433102_0007_01_000029 of capacity <memory:1024, vCores:1> on host hadoop-8-2:41932, which currently has 3 containers, <memory:4096, vCores:3> used and <memory:4096, vCores:13> available
2013-08-27 16:04:44,418 INFO org.apache.hadoop.yarn.server.resourcemanager.scheduler.capacity.LeafQueue: assignedContainer application=application_1377618433102_0007 container=Container: [ContainerId: container_1377618433102_0007_01_000029, NodeId: hadoop-8-2:41932, NodeHttpAddress: hadoop-8-2:8042, Resource: <memory:1024, vCores:1>, Priority: 20, State: NEW, Token: null, Status: container_id {, app_attempt_id {, application_id {, id: 7, cluster_timestamp: 1377618433102, }, attemptId: 1, }, id: 29, }, state: C_NEW, ] containerId=container_1377618433102_0007_01_000029 queue=default: capacity=1.0, absoluteCapacity=1.0, usedResources=<memory:37888, vCores:32>usedCapacity=0.7708333, absoluteUsedCapacity=0.7708333, numApps=5, numContainers=32 usedCapacity=0.7708333 absoluteUsedCapacity=0.7708333 used=<memory:37888, vCores:32> cluster=<memory:49152, vCores:96>
2013-08-27 16:04:44,419 INFO org.apache.hadoop.yarn.server.resourcemanager.scheduler.capacity.ParentQueue: Re-sorting queues since queue: root.default stats: default: capacity=1.0, absoluteCapacity=1.0, usedResources=<memory:38912, vCores:33>usedCapacity=0.7916667, absoluteUsedCapacity=0.7916667, numApps=5, numContainers=33
2013-08-27 16:04:44,419 INFO org.apache.hadoop.yarn.server.resourcemanager.scheduler.capacity.ParentQueue: assignedContainer queue=root usedCapacity=0.7916667 absoluteUsedCapacity=0.7916667 used=<memory:38912, vCores:33> cluster=<memory:49152, vCores:96>
2013-08-27 16:04:44,419 INFO org.apache.hadoop.yarn.server.resourcemanager.rmcontainer.RMContainerImpl: container_1377618433102_0007_01_000030 Container Transitioned from NEW to ALLOCATED
2013-08-27 16:04:44,419 INFO org.apache.hadoop.yarn.server.resourcemanager.RMAuditLogger: USER=ubuntu	OPERATION=AM Allocated Container	TARGET=SchedulerApp	RESULT=SUCCESS	APPID=application_1377618433102_0007	CONTAINERID=container_1377618433102_0007_01_000030
2013-08-27 16:04:44,420 INFO org.apache.hadoop.yarn.server.resourcemanager.scheduler.common.fica.FiCaSchedulerNode: Assigned container container_1377618433102_0007_01_000030 of capacity <memory:1024, vCores:1> on host hadoop-8-2:41932, which currently has 4 containers, <memory:5120, vCores:4> used and <memory:3072, vCores:12> available
2013-08-27 16:04:44,420 INFO org.apache.hadoop.yarn.server.resourcemanager.scheduler.capacity.LeafQueue: assignedContainer application=application_1377618433102_0007 container=Container: [ContainerId: container_1377618433102_0007_01_000030, NodeId: hadoop-8-2:41932, NodeHttpAddress: hadoop-8-2:8042, Resource: <memory:1024, vCores:1>, Priority: 20, State: NEW, Token: null, Status: container_id {, app_attempt_id {, application_id {, id: 7, cluster_timestamp: 1377618433102, }, attemptId: 1, }, id: 30, }, state: C_NEW, ] containerId=container_1377618433102_0007_01_000030 queue=default: capacity=1.0, absoluteCapacity=1.0, usedResources=<memory:38912, vCores:33>usedCapacity=0.7916667, absoluteUsedCapacity=0.7916667, numApps=5, numContainers=33 usedCapacity=0.7916667 absoluteUsedCapacity=0.7916667 used=<memory:38912, vCores:33> cluster=<memory:49152, vCores:96>
2013-08-27 16:04:44,421 INFO org.apache.hadoop.yarn.server.resourcemanager.scheduler.capacity.ParentQueue: Re-sorting queues since queue: root.default stats: default: capacity=1.0, absoluteCapacity=1.0, usedResources=<memory:39936, vCores:34>usedCapacity=0.8125, absoluteUsedCapacity=0.8125, numApps=5, numContainers=34
2013-08-27 16:04:44,421 INFO org.apache.hadoop.yarn.server.resourcemanager.scheduler.capacity.ParentQueue: assignedContainer queue=root usedCapacity=0.8125 absoluteUsedCapacity=0.8125 used=<memory:39936, vCores:34> cluster=<memory:49152, vCores:96>
2013-08-27 16:04:44,421 INFO org.apache.hadoop.yarn.server.resourcemanager.rmcontainer.RMContainerImpl: container_1377618433102_0007_01_000031 Container Transitioned from NEW to ALLOCATED
2013-08-27 16:04:44,421 INFO org.apache.hadoop.yarn.server.resourcemanager.RMAuditLogger: USER=ubuntu	OPERATION=AM Allocated Container	TARGET=SchedulerApp	RESULT=SUCCESS	APPID=application_1377618433102_0007	CONTAINERID=container_1377618433102_0007_01_000031
2013-08-27 16:04:44,422 INFO org.apache.hadoop.yarn.server.resourcemanager.scheduler.common.fica.FiCaSchedulerNode: Assigned container container_1377618433102_0007_01_000031 of capacity <memory:1024, vCores:1> on host hadoop-8-2:41932, which currently has 5 containers, <memory:6144, vCores:5> used and <memory:2048, vCores:11> available
2013-08-27 16:04:44,422 INFO org.apache.hadoop.yarn.server.resourcemanager.scheduler.capacity.LeafQueue: assignedContainer application=application_1377618433102_0007 container=Container: [ContainerId: container_1377618433102_0007_01_000031, NodeId: hadoop-8-2:41932, NodeHttpAddress: hadoop-8-2:8042, Resource: <memory:1024, vCores:1>, Priority: 20, State: NEW, Token: null, Status: container_id {, app_attempt_id {, application_id {, id: 7, cluster_timestamp: 1377618433102, }, attemptId: 1, }, id: 31, }, state: C_NEW, ] containerId=container_1377618433102_0007_01_000031 queue=default: capacity=1.0, absoluteCapacity=1.0, usedResources=<memory:39936, vCores:34>usedCapacity=0.8125, absoluteUsedCapacity=0.8125, numApps=5, numContainers=34 usedCapacity=0.8125 absoluteUsedCapacity=0.8125 used=<memory:39936, vCores:34> cluster=<memory:49152, vCores:96>
2013-08-27 16:04:44,423 INFO org.apache.hadoop.yarn.server.resourcemanager.scheduler.capacity.ParentQueue: Re-sorting queues since queue: root.default stats: default: capacity=1.0, absoluteCapacity=1.0, usedResources=<memory:40960, vCores:35>usedCapacity=0.8333333, absoluteUsedCapacity=0.8333333, numApps=5, numContainers=35
2013-08-27 16:04:44,423 INFO org.apache.hadoop.yarn.server.resourcemanager.scheduler.capacity.ParentQueue: assignedContainer queue=root usedCapacity=0.8333333 absoluteUsedCapacity=0.8333333 used=<memory:40960, vCores:35> cluster=<memory:49152, vCores:96>
2013-08-27 16:04:44,423 INFO org.apache.hadoop.yarn.server.resourcemanager.rmcontainer.RMContainerImpl: container_1377618433102_0007_01_000032 Container Transitioned from NEW to ALLOCATED
2013-08-27 16:04:44,424 INFO org.apache.hadoop.yarn.server.resourcemanager.RMAuditLogger: USER=ubuntu	OPERATION=AM Allocated Container	TARGET=SchedulerApp	RESULT=SUCCESS	APPID=application_1377618433102_0007	CONTAINERID=container_1377618433102_0007_01_000032
2013-08-27 16:04:44,424 INFO org.apache.hadoop.yarn.server.resourcemanager.scheduler.common.fica.FiCaSchedulerNode: Assigned container container_1377618433102_0007_01_000032 of capacity <memory:1024, vCores:1> on host hadoop-8-2:41932, which currently has 6 containers, <memory:7168, vCores:6> used and <memory:1024, vCores:10> available
2013-08-27 16:04:44,425 INFO org.apache.hadoop.yarn.server.resourcemanager.scheduler.capacity.LeafQueue: assignedContainer application=application_1377618433102_0007 container=Container: [ContainerId: container_1377618433102_0007_01_000032, NodeId: hadoop-8-2:41932, NodeHttpAddress: hadoop-8-2:8042, Resource: <memory:1024, vCores:1>, Priority: 20, State: NEW, Token: null, Status: container_id {, app_attempt_id {, application_id {, id: 7, cluster_timestamp: 1377618433102, }, attemptId: 1, }, id: 32, }, state: C_NEW, ] containerId=container_1377618433102_0007_01_000032 queue=default: capacity=1.0, absoluteCapacity=1.0, usedResources=<memory:40960, vCores:35>usedCapacity=0.8333333, absoluteUsedCapacity=0.8333333, numApps=5, numContainers=35 usedCapacity=0.8333333 absoluteUsedCapacity=0.8333333 used=<memory:40960, vCores:35> cluster=<memory:49152, vCores:96>
2013-08-27 16:04:44,425 INFO org.apache.hadoop.yarn.server.resourcemanager.scheduler.capacity.ParentQueue: Re-sorting queues since queue: root.default stats: default: capacity=1.0, absoluteCapacity=1.0, usedResources=<memory:41984, vCores:36>usedCapacity=0.8541667, absoluteUsedCapacity=0.8541667, numApps=5, numContainers=36
2013-08-27 16:04:44,425 INFO org.apache.hadoop.yarn.server.resourcemanager.scheduler.capacity.ParentQueue: assignedContainer queue=root usedCapacity=0.8541667 absoluteUsedCapacity=0.8541667 used=<memory:41984, vCores:36> cluster=<memory:49152, vCores:96>
2013-08-27 16:04:44,425 INFO org.apache.hadoop.yarn.server.resourcemanager.rmcontainer.RMContainerImpl: container_1377618433102_0007_01_000033 Container Transitioned from NEW to ALLOCATED
2013-08-27 16:04:44,426 INFO org.apache.hadoop.yarn.server.resourcemanager.RMAuditLogger: USER=ubuntu	OPERATION=AM Allocated Container	TARGET=SchedulerApp	RESULT=SUCCESS	APPID=application_1377618433102_0007	CONTAINERID=container_1377618433102_0007_01_000033
2013-08-27 16:04:44,426 INFO org.apache.hadoop.yarn.server.resourcemanager.scheduler.common.fica.FiCaSchedulerNode: Assigned container container_1377618433102_0007_01_000033 of capacity <memory:1024, vCores:1> on host hadoop-8-2:41932, which currently has 7 containers, <memory:8192, vCores:7> used and <memory:0, vCores:9> available
2013-08-27 16:04:44,427 INFO org.apache.hadoop.yarn.server.resourcemanager.scheduler.capacity.LeafQueue: assignedContainer application=application_1377618433102_0007 container=Container: [ContainerId: container_1377618433102_0007_01_000033, NodeId: hadoop-8-2:41932, NodeHttpAddress: hadoop-8-2:8042, Resource: <memory:1024, vCores:1>, Priority: 20, State: NEW, Token: null, Status: container_id {, app_attempt_id {, application_id {, id: 7, cluster_timestamp: 1377618433102, }, attemptId: 1, }, id: 33, }, state: C_NEW, ] containerId=container_1377618433102_0007_01_000033 queue=default: capacity=1.0, absoluteCapacity=1.0, usedResources=<memory:41984, vCores:36>usedCapacity=0.8541667, absoluteUsedCapacity=0.8541667, numApps=5, numContainers=36 usedCapacity=0.8541667 absoluteUsedCapacity=0.8541667 used=<memory:41984, vCores:36> cluster=<memory:49152, vCores:96>
2013-08-27 16:04:44,427 INFO org.apache.hadoop.yarn.server.resourcemanager.scheduler.capacity.ParentQueue: Re-sorting queues since queue: root.default stats: default: capacity=1.0, absoluteCapacity=1.0, usedResources=<memory:43008, vCores:37>usedCapacity=0.875, absoluteUsedCapacity=0.875, numApps=5, numContainers=37
2013-08-27 16:04:44,427 INFO org.apache.hadoop.yarn.server.resourcemanager.scheduler.capacity.ParentQueue: assignedContainer queue=root usedCapacity=0.875 absoluteUsedCapacity=0.875 used=<memory:43008, vCores:37> cluster=<memory:49152, vCores:96>
2013-08-27 16:04:44,817 INFO org.apache.hadoop.yarn.server.resourcemanager.rmcontainer.RMContainerImpl: container_1377618433102_0006_01_000002 Container Transitioned from NEW to ALLOCATED
2013-08-27 16:04:44,820 INFO org.apache.hadoop.yarn.server.resourcemanager.RMAuditLogger: USER=ubuntu	OPERATION=AM Allocated Container	TARGET=SchedulerApp	RESULT=SUCCESS	APPID=application_1377618433102_0006	CONTAINERID=container_1377618433102_0006_01_000002
2013-08-27 16:04:44,820 INFO org.apache.hadoop.yarn.server.resourcemanager.scheduler.common.fica.FiCaSchedulerNode: Assigned container container_1377618433102_0006_01_000002 of capacity <memory:1024, vCores:1> on host hadoop-8-7:53314, which currently has 2 containers, <memory:3072, vCores:2> used and <memory:5120, vCores:14> available
2013-08-27 16:04:44,821 INFO org.apache.hadoop.yarn.server.resourcemanager.scheduler.capacity.LeafQueue: assignedContainer application=application_1377618433102_0006 container=Container: [ContainerId: container_1377618433102_0006_01_000002, NodeId: hadoop-8-7:53314, NodeHttpAddress: hadoop-8-7:8042, Resource: <memory:1024, vCores:1>, Priority: 20, State: NEW, Token: null, Status: container_id {, app_attempt_id {, application_id {, id: 6, cluster_timestamp: 1377618433102, }, attemptId: 1, }, id: 2, }, state: C_NEW, ] containerId=container_1377618433102_0006_01_000002 queue=default: capacity=1.0, absoluteCapacity=1.0, usedResources=<memory:43008, vCores:37>usedCapacity=0.875, absoluteUsedCapacity=0.875, numApps=5, numContainers=37 usedCapacity=0.875 absoluteUsedCapacity=0.875 used=<memory:43008, vCores:37> cluster=<memory:49152, vCores:96>
2013-08-27 16:04:44,821 INFO org.apache.hadoop.yarn.server.resourcemanager.scheduler.capacity.ParentQueue: Re-sorting queues since queue: root.default stats: default: capacity=1.0, absoluteCapacity=1.0, usedResources=<memory:44032, vCores:38>usedCapacity=0.8958333, absoluteUsedCapacity=0.8958333, numApps=5, numContainers=38
2013-08-27 16:04:44,821 INFO org.apache.hadoop.yarn.server.resourcemanager.scheduler.capacity.ParentQueue: assignedContainer queue=root usedCapacity=0.8958333 absoluteUsedCapacity=0.8958333 used=<memory:44032, vCores:38> cluster=<memory:49152, vCores:96>
2013-08-27 16:04:44,822 INFO org.apache.hadoop.yarn.server.resourcemanager.rmcontainer.RMContainerImpl: container_1377618433102_0006_01_000003 Container Transitioned from NEW to ALLOCATED
2013-08-27 16:04:44,822 INFO org.apache.hadoop.yarn.server.resourcemanager.RMAuditLogger: USER=ubuntu	OPERATION=AM Allocated Container	TARGET=SchedulerApp	RESULT=SUCCESS	APPID=application_1377618433102_0006	CONTAINERID=container_1377618433102_0006_01_000003
2013-08-27 16:04:44,822 INFO org.apache.hadoop.yarn.server.resourcemanager.scheduler.common.fica.FiCaSchedulerNode: Assigned container container_1377618433102_0006_01_000003 of capacity <memory:1024, vCores:1> on host hadoop-8-7:53314, which currently has 3 containers, <memory:4096, vCores:3> used and <memory:4096, vCores:13> available
2013-08-27 16:04:44,823 INFO org.apache.hadoop.yarn.server.resourcemanager.scheduler.capacity.LeafQueue: assignedContainer application=application_1377618433102_0006 container=Container: [ContainerId: container_1377618433102_0006_01_000003, NodeId: hadoop-8-7:53314, NodeHttpAddress: hadoop-8-7:8042, Resource: <memory:1024, vCores:1>, Priority: 20, State: NEW, Token: null, Status: container_id {, app_attempt_id {, application_id {, id: 6, cluster_timestamp: 1377618433102, }, attemptId: 1, }, id: 3, }, state: C_NEW, ] containerId=container_1377618433102_0006_01_000003 queue=default: capacity=1.0, absoluteCapacity=1.0, usedResources=<memory:44032, vCores:38>usedCapacity=0.8958333, absoluteUsedCapacity=0.8958333, numApps=5, numContainers=38 usedCapacity=0.8958333 absoluteUsedCapacity=0.8958333 used=<memory:44032, vCores:38> cluster=<memory:49152, vCores:96>
2013-08-27 16:04:44,823 INFO org.apache.hadoop.yarn.server.resourcemanager.scheduler.capacity.ParentQueue: Re-sorting queues since queue: root.default stats: default: capacity=1.0, absoluteCapacity=1.0, usedResources=<memory:45056, vCores:39>usedCapacity=0.9166667, absoluteUsedCapacity=0.9166667, numApps=5, numContainers=39
2013-08-27 16:04:44,824 INFO org.apache.hadoop.yarn.server.resourcemanager.scheduler.capacity.ParentQueue: assignedContainer queue=root usedCapacity=0.9166667 absoluteUsedCapacity=0.9166667 used=<memory:45056, vCores:39> cluster=<memory:49152, vCores:96>
2013-08-27 16:04:44,824 INFO org.apache.hadoop.yarn.server.resourcemanager.rmcontainer.RMContainerImpl: container_1377618433102_0006_01_000004 Container Transitioned from NEW to ALLOCATED
2013-08-27 16:04:44,824 INFO org.apache.hadoop.yarn.server.resourcemanager.RMAuditLogger: USER=ubuntu	OPERATION=AM Allocated Container	TARGET=SchedulerApp	RESULT=SUCCESS	APPID=application_1377618433102_0006	CONTAINERID=container_1377618433102_0006_01_000004
2013-08-27 16:04:44,824 INFO org.apache.hadoop.yarn.server.resourcemanager.scheduler.common.fica.FiCaSchedulerNode: Assigned container container_1377618433102_0006_01_000004 of capacity <memory:1024, vCores:1> on host hadoop-8-7:53314, which currently has 4 containers, <memory:5120, vCores:4> used and <memory:3072, vCores:12> available
2013-08-27 16:04:44,825 INFO org.apache.hadoop.yarn.server.resourcemanager.scheduler.capacity.LeafQueue: assignedContainer application=application_1377618433102_0006 container=Container: [ContainerId: container_1377618433102_0006_01_000004, NodeId: hadoop-8-7:53314, NodeHttpAddress: hadoop-8-7:8042, Resource: <memory:1024, vCores:1>, Priority: 20, State: NEW, Token: null, Status: container_id {, app_attempt_id {, application_id {, id: 6, cluster_timestamp: 1377618433102, }, attemptId: 1, }, id: 4, }, state: C_NEW, ] containerId=container_1377618433102_0006_01_000004 queue=default: capacity=1.0, absoluteCapacity=1.0, usedResources=<memory:45056, vCores:39>usedCapacity=0.9166667, absoluteUsedCapacity=0.9166667, numApps=5, numContainers=39 usedCapacity=0.9166667 absoluteUsedCapacity=0.9166667 used=<memory:45056, vCores:39> cluster=<memory:49152, vCores:96>
2013-08-27 16:04:44,826 INFO org.apache.hadoop.yarn.server.resourcemanager.scheduler.capacity.ParentQueue: Re-sorting queues since queue: root.default stats: default: capacity=1.0, absoluteCapacity=1.0, usedResources=<memory:46080, vCores:40>usedCapacity=0.9375, absoluteUsedCapacity=0.9375, numApps=5, numContainers=40
2013-08-27 16:04:44,826 INFO org.apache.hadoop.yarn.server.resourcemanager.scheduler.capacity.ParentQueue: assignedContainer queue=root usedCapacity=0.9375 absoluteUsedCapacity=0.9375 used=<memory:46080, vCores:40> cluster=<memory:49152, vCores:96>
2013-08-27 16:04:44,826 INFO org.apache.hadoop.yarn.server.resourcemanager.rmcontainer.RMContainerImpl: container_1377618433102_0006_01_000005 Container Transitioned from NEW to ALLOCATED
2013-08-27 16:04:44,826 INFO org.apache.hadoop.yarn.server.resourcemanager.RMAuditLogger: USER=ubuntu	OPERATION=AM Allocated Container	TARGET=SchedulerApp	RESULT=SUCCESS	APPID=application_1377618433102_0006	CONTAINERID=container_1377618433102_0006_01_000005
2013-08-27 16:04:44,826 INFO org.apache.hadoop.yarn.server.resourcemanager.scheduler.common.fica.FiCaSchedulerNode: Assigned container container_1377618433102_0006_01_000005 of capacity <memory:1024, vCores:1> on host hadoop-8-7:53314, which currently has 5 containers, <memory:6144, vCores:5> used and <memory:2048, vCores:11> available
2013-08-27 16:04:44,827 INFO org.apache.hadoop.yarn.server.resourcemanager.scheduler.capacity.LeafQueue: assignedContainer application=application_1377618433102_0006 container=Container: [ContainerId: container_1377618433102_0006_01_000005, NodeId: hadoop-8-7:53314, NodeHttpAddress: hadoop-8-7:8042, Resource: <memory:1024, vCores:1>, Priority: 20, State: NEW, Token: null, Status: container_id {, app_attempt_id {, application_id {, id: 6, cluster_timestamp: 1377618433102, }, attemptId: 1, }, id: 5, }, state: C_NEW, ] containerId=container_1377618433102_0006_01_000005 queue=default: capacity=1.0, absoluteCapacity=1.0, usedResources=<memory:46080, vCores:40>usedCapacity=0.9375, absoluteUsedCapacity=0.9375, numApps=5, numContainers=40 usedCapacity=0.9375 absoluteUsedCapacity=0.9375 used=<memory:46080, vCores:40> cluster=<memory:49152, vCores:96>
2013-08-27 16:04:44,828 INFO org.apache.hadoop.yarn.server.resourcemanager.scheduler.capacity.ParentQueue: Re-sorting queues since queue: root.default stats: default: capacity=1.0, absoluteCapacity=1.0, usedResources=<memory:47104, vCores:41>usedCapacity=0.9583333, absoluteUsedCapacity=0.9583333, numApps=5, numContainers=41
2013-08-27 16:04:44,828 INFO org.apache.hadoop.yarn.server.resourcemanager.scheduler.capacity.ParentQueue: assignedContainer queue=root usedCapacity=0.9583333 absoluteUsedCapacity=0.9583333 used=<memory:47104, vCores:41> cluster=<memory:49152, vCores:96>
2013-08-27 16:04:44,828 INFO org.apache.hadoop.yarn.server.resourcemanager.rmcontainer.RMContainerImpl: container_1377618433102_0006_01_000006 Container Transitioned from NEW to ALLOCATED
2013-08-27 16:04:44,828 INFO org.apache.hadoop.yarn.server.resourcemanager.RMAuditLogger: USER=ubuntu	OPERATION=AM Allocated Container	TARGET=SchedulerApp	RESULT=SUCCESS	APPID=application_1377618433102_0006	CONTAINERID=container_1377618433102_0006_01_000006
2013-08-27 16:04:44,828 INFO org.apache.hadoop.yarn.server.resourcemanager.scheduler.common.fica.FiCaSchedulerNode: Assigned container container_1377618433102_0006_01_000006 of capacity <memory:1024, vCores:1> on host hadoop-8-7:53314, which currently has 6 containers, <memory:7168, vCores:6> used and <memory:1024, vCores:10> available
2013-08-27 16:04:44,829 INFO org.apache.hadoop.yarn.server.resourcemanager.scheduler.capacity.LeafQueue: assignedContainer application=application_1377618433102_0006 container=Container: [ContainerId: container_1377618433102_0006_01_000006, NodeId: hadoop-8-7:53314, NodeHttpAddress: hadoop-8-7:8042, Resource: <memory:1024, vCores:1>, Priority: 20, State: NEW, Token: null, Status: container_id {, app_attempt_id {, application_id {, id: 6, cluster_timestamp: 1377618433102, }, attemptId: 1, }, id: 6, }, state: C_NEW, ] containerId=container_1377618433102_0006_01_000006 queue=default: capacity=1.0, absoluteCapacity=1.0, usedResources=<memory:47104, vCores:41>usedCapacity=0.9583333, absoluteUsedCapacity=0.9583333, numApps=5, numContainers=41 usedCapacity=0.9583333 absoluteUsedCapacity=0.9583333 used=<memory:47104, vCores:41> cluster=<memory:49152, vCores:96>
2013-08-27 16:04:44,830 INFO org.apache.hadoop.yarn.server.resourcemanager.scheduler.capacity.ParentQueue: Re-sorting queues since queue: root.default stats: default: capacity=1.0, absoluteCapacity=1.0, usedResources=<memory:48128, vCores:42>usedCapacity=0.9791667, absoluteUsedCapacity=0.9791667, numApps=5, numContainers=42
2013-08-27 16:04:44,830 INFO org.apache.hadoop.yarn.server.resourcemanager.scheduler.capacity.ParentQueue: assignedContainer queue=root usedCapacity=0.9791667 absoluteUsedCapacity=0.9791667 used=<memory:48128, vCores:42> cluster=<memory:49152, vCores:96>
2013-08-27 16:04:44,830 INFO org.apache.hadoop.yarn.server.resourcemanager.rmcontainer.RMContainerImpl: container_1377618433102_0006_01_000007 Container Transitioned from NEW to ALLOCATED
2013-08-27 16:04:44,830 INFO org.apache.hadoop.yarn.server.resourcemanager.RMAuditLogger: USER=ubuntu	OPERATION=AM Allocated Container	TARGET=SchedulerApp	RESULT=SUCCESS	APPID=application_1377618433102_0006	CONTAINERID=container_1377618433102_0006_01_000007
2013-08-27 16:04:44,830 INFO org.apache.hadoop.yarn.server.resourcemanager.scheduler.common.fica.FiCaSchedulerNode: Assigned container container_1377618433102_0006_01_000007 of capacity <memory:1024, vCores:1> on host hadoop-8-7:53314, which currently has 7 containers, <memory:8192, vCores:7> used and <memory:0, vCores:9> available
2013-08-27 16:04:44,831 INFO org.apache.hadoop.yarn.server.resourcemanager.scheduler.capacity.LeafQueue: assignedContainer application=application_1377618433102_0006 container=Container: [ContainerId: container_1377618433102_0006_01_000007, NodeId: hadoop-8-7:53314, NodeHttpAddress: hadoop-8-7:8042, Resource: <memory:1024, vCores:1>, Priority: 20, State: NEW, Token: null, Status: container_id {, app_attempt_id {, application_id {, id: 6, cluster_timestamp: 1377618433102, }, attemptId: 1, }, id: 7, }, state: C_NEW, ] containerId=container_1377618433102_0006_01_000007 queue=default: capacity=1.0, absoluteCapacity=1.0, usedResources=<memory:48128, vCores:42>usedCapacity=0.9791667, absoluteUsedCapacity=0.9791667, numApps=5, numContainers=42 usedCapacity=0.9791667 absoluteUsedCapacity=0.9791667 used=<memory:48128, vCores:42> cluster=<memory:49152, vCores:96>
2013-08-27 16:04:44,832 INFO org.apache.hadoop.yarn.server.resourcemanager.scheduler.capacity.ParentQueue: Re-sorting queues since queue: root.default stats: default: capacity=1.0, absoluteCapacity=1.0, usedResources=<memory:49152, vCores:43>usedCapacity=1.0, absoluteUsedCapacity=1.0, numApps=5, numContainers=43
2013-08-27 16:04:44,832 INFO org.apache.hadoop.yarn.server.resourcemanager.scheduler.capacity.ParentQueue: assignedContainer queue=root usedCapacity=1.0 absoluteUsedCapacity=1.0 used=<memory:49152, vCores:43> cluster=<memory:49152, vCores:96>
2013-08-27 16:04:45,008 INFO org.apache.hadoop.yarn.server.resourcemanager.rmcontainer.RMContainerImpl: container_1377618433102_0007_01_000002 Container Transitioned from ALLOCATED to ACQUIRED
2013-08-27 16:04:45,009 INFO org.apache.hadoop.yarn.server.resourcemanager.rmcontainer.RMContainerImpl: container_1377618433102_0007_01_000003 Container Transitioned from ALLOCATED to ACQUIRED
2013-08-27 16:04:45,010 INFO org.apache.hadoop.yarn.server.resourcemanager.rmcontainer.RMContainerImpl: container_1377618433102_0007_01_000004 Container Transitioned from ALLOCATED to ACQUIRED
2013-08-27 16:04:45,011 INFO org.apache.hadoop.yarn.server.resourcemanager.rmcontainer.RMContainerImpl: container_1377618433102_0007_01_000005 Container Transitioned from ALLOCATED to ACQUIRED
2013-08-27 16:04:45,012 INFO org.apache.hadoop.yarn.server.resourcemanager.rmcontainer.RMContainerImpl: container_1377618433102_0007_01_000006 Container Transitioned from ALLOCATED to ACQUIRED
2013-08-27 16:04:45,012 INFO org.apache.hadoop.yarn.server.resourcemanager.rmcontainer.RMContainerImpl: container_1377618433102_0007_01_000007 Container Transitioned from ALLOCATED to ACQUIRED
2013-08-27 16:04:45,013 INFO org.apache.hadoop.yarn.server.resourcemanager.rmcontainer.RMContainerImpl: container_1377618433102_0007_01_000008 Container Transitioned from ALLOCATED to ACQUIRED
2013-08-27 16:04:45,013 INFO org.apache.hadoop.yarn.server.resourcemanager.rmcontainer.RMContainerImpl: container_1377618433102_0007_01_000009 Container Transitioned from ALLOCATED to ACQUIRED
2013-08-27 16:04:45,014 INFO org.apache.hadoop.yarn.server.resourcemanager.rmcontainer.RMContainerImpl: container_1377618433102_0007_01_000010 Container Transitioned from ALLOCATED to ACQUIRED
2013-08-27 16:04:45,016 INFO org.apache.hadoop.yarn.server.resourcemanager.rmcontainer.RMContainerImpl: container_1377618433102_0007_01_000011 Container Transitioned from ALLOCATED to ACQUIRED
2013-08-27 16:04:45,016 INFO org.apache.hadoop.yarn.server.resourcemanager.rmcontainer.RMContainerImpl: container_1377618433102_0007_01_000012 Container Transitioned from ALLOCATED to ACQUIRED
2013-08-27 16:04:45,017 INFO org.apache.hadoop.yarn.server.resourcemanager.rmcontainer.RMContainerImpl: container_1377618433102_0007_01_000013 Container Transitioned from ALLOCATED to ACQUIRED
2013-08-27 16:04:45,017 INFO org.apache.hadoop.yarn.server.resourcemanager.rmcontainer.RMContainerImpl: container_1377618433102_0007_01_000014 Container Transitioned from ALLOCATED to ACQUIRED
2013-08-27 16:04:45,018 INFO org.apache.hadoop.yarn.server.resourcemanager.rmcontainer.RMContainerImpl: container_1377618433102_0007_01_000015 Container Transitioned from ALLOCATED to ACQUIRED
2013-08-27 16:04:45,018 INFO org.apache.hadoop.yarn.server.resourcemanager.rmcontainer.RMContainerImpl: container_1377618433102_0007_01_000016 Container Transitioned from ALLOCATED to ACQUIRED
2013-08-27 16:04:45,019 INFO org.apache.hadoop.yarn.server.resourcemanager.rmcontainer.RMContainerImpl: container_1377618433102_0007_01_000017 Container Transitioned from ALLOCATED to ACQUIRED
2013-08-27 16:04:45,019 INFO org.apache.hadoop.yarn.server.resourcemanager.rmcontainer.RMContainerImpl: container_1377618433102_0007_01_000018 Container Transitioned from ALLOCATED to ACQUIRED
2013-08-27 16:04:45,020 INFO org.apache.hadoop.yarn.server.resourcemanager.rmcontainer.RMContainerImpl: container_1377618433102_0007_01_000019 Container Transitioned from ALLOCATED to ACQUIRED
2013-08-27 16:04:45,020 INFO org.apache.hadoop.yarn.server.resourcemanager.rmcontainer.RMContainerImpl: container_1377618433102_0007_01_000020 Container Transitioned from ALLOCATED to ACQUIRED
2013-08-27 16:04:45,021 INFO org.apache.hadoop.yarn.server.resourcemanager.rmcontainer.RMContainerImpl: container_1377618433102_0007_01_000021 Container Transitioned from ALLOCATED to ACQUIRED
2013-08-27 16:04:45,022 INFO org.apache.hadoop.yarn.server.resourcemanager.rmcontainer.RMContainerImpl: container_1377618433102_0007_01_000022 Container Transitioned from ALLOCATED to ACQUIRED
2013-08-27 16:04:45,022 INFO org.apache.hadoop.yarn.server.resourcemanager.rmcontainer.RMContainerImpl: container_1377618433102_0007_01_000023 Container Transitioned from ALLOCATED to ACQUIRED
2013-08-27 16:04:45,022 INFO org.apache.hadoop.yarn.server.resourcemanager.rmcontainer.RMContainerImpl: container_1377618433102_0007_01_000024 Container Transitioned from ALLOCATED to ACQUIRED
2013-08-27 16:04:45,022 INFO org.apache.hadoop.yarn.server.resourcemanager.rmcontainer.RMContainerImpl: container_1377618433102_0007_01_000025 Container Transitioned from ALLOCATED to ACQUIRED
2013-08-27 16:04:45,022 INFO org.apache.hadoop.yarn.server.resourcemanager.rmcontainer.RMContainerImpl: container_1377618433102_0007_01_000026 Container Transitioned from ALLOCATED to ACQUIRED
2013-08-27 16:04:45,023 INFO org.apache.hadoop.yarn.server.resourcemanager.rmcontainer.RMContainerImpl: container_1377618433102_0007_01_000027 Container Transitioned from ALLOCATED to ACQUIRED
2013-08-27 16:04:45,023 INFO org.apache.hadoop.yarn.server.resourcemanager.rmcontainer.RMContainerImpl: container_1377618433102_0007_01_000028 Container Transitioned from ALLOCATED to ACQUIRED
2013-08-27 16:04:45,023 INFO org.apache.hadoop.yarn.server.resourcemanager.rmcontainer.RMContainerImpl: container_1377618433102_0007_01_000029 Container Transitioned from ALLOCATED to ACQUIRED
2013-08-27 16:04:45,023 INFO org.apache.hadoop.yarn.server.resourcemanager.rmcontainer.RMContainerImpl: container_1377618433102_0007_01_000030 Container Transitioned from ALLOCATED to ACQUIRED
2013-08-27 16:04:45,023 INFO org.apache.hadoop.yarn.server.resourcemanager.rmcontainer.RMContainerImpl: container_1377618433102_0007_01_000031 Container Transitioned from ALLOCATED to ACQUIRED
2013-08-27 16:04:45,024 INFO org.apache.hadoop.yarn.server.resourcemanager.rmcontainer.RMContainerImpl: container_1377618433102_0007_01_000032 Container Transitioned from ALLOCATED to ACQUIRED
2013-08-27 16:04:45,024 INFO org.apache.hadoop.yarn.server.resourcemanager.rmcontainer.RMContainerImpl: container_1377618433102_0007_01_000033 Container Transitioned from ALLOCATED to ACQUIRED
2013-08-27 16:04:45,568 INFO org.apache.hadoop.yarn.server.resourcemanager.ApplicationMasterService: AM registration appattempt_1377618433102_0010_000001
2013-08-27 16:04:45,568 INFO org.apache.hadoop.yarn.server.resourcemanager.RMAuditLogger: USER=ubuntu	IP=192.168.100.25	OPERATION=Register App Master	TARGET=ApplicationMasterService	RESULT=SUCCESS	APPID=application_1377618433102_0010	APPATTEMPTID=appattempt_1377618433102_0010_000001
2013-08-27 16:04:45,569 INFO org.apache.hadoop.yarn.server.resourcemanager.rmapp.attempt.RMAppAttemptImpl: appattempt_1377618433102_0010_000001 State change from LAUNCHED to RUNNING
2013-08-27 16:04:45,569 INFO org.apache.hadoop.yarn.server.resourcemanager.rmapp.RMAppImpl: application_1377618433102_0010 State change from ACCEPTED to RUNNING
2013-08-27 16:04:45,749 INFO org.apache.hadoop.yarn.server.resourcemanager.rmcontainer.RMContainerImpl: container_1377618433102_0006_01_000002 Container Transitioned from ALLOCATED to ACQUIRED
2013-08-27 16:04:45,750 INFO org.apache.hadoop.yarn.server.resourcemanager.rmcontainer.RMContainerImpl: container_1377618433102_0006_01_000003 Container Transitioned from ALLOCATED to ACQUIRED
2013-08-27 16:04:45,750 INFO org.apache.hadoop.yarn.server.resourcemanager.rmcontainer.RMContainerImpl: container_1377618433102_0006_01_000004 Container Transitioned from ALLOCATED to ACQUIRED
2013-08-27 16:04:45,750 INFO org.apache.hadoop.yarn.server.resourcemanager.rmcontainer.RMContainerImpl: container_1377618433102_0006_01_000005 Container Transitioned from ALLOCATED to ACQUIRED
2013-08-27 16:04:45,750 INFO org.apache.hadoop.yarn.server.resourcemanager.rmcontainer.RMContainerImpl: container_1377618433102_0006_01_000006 Container Transitioned from ALLOCATED to ACQUIRED
2013-08-27 16:04:45,750 INFO org.apache.hadoop.yarn.server.resourcemanager.rmcontainer.RMContainerImpl: container_1377618433102_0006_01_000007 Container Transitioned from ALLOCATED to ACQUIRED
2013-08-27 16:04:46,065 INFO org.apache.hadoop.yarn.server.resourcemanager.rmcontainer.RMContainerImpl: container_1377618433102_0007_01_000002 Container Transitioned from ACQUIRED to RUNNING
2013-08-27 16:04:46,065 INFO org.apache.hadoop.yarn.server.resourcemanager.rmcontainer.RMContainerImpl: container_1377618433102_0007_01_000003 Container Transitioned from ACQUIRED to RUNNING
2013-08-27 16:04:46,066 INFO org.apache.hadoop.yarn.server.resourcemanager.rmcontainer.RMContainerImpl: container_1377618433102_0007_01_000004 Container Transitioned from ACQUIRED to RUNNING
2013-08-27 16:04:46,067 INFO org.apache.hadoop.yarn.server.resourcemanager.rmcontainer.RMContainerImpl: container_1377618433102_0007_01_000005 Container Transitioned from ACQUIRED to RUNNING
2013-08-27 16:04:46,067 INFO org.apache.hadoop.yarn.server.resourcemanager.rmcontainer.RMContainerImpl: container_1377618433102_0007_01_000006 Container Transitioned from ACQUIRED to RUNNING
2013-08-27 16:04:46,068 INFO org.apache.hadoop.yarn.server.resourcemanager.rmcontainer.RMContainerImpl: container_1377618433102_0007_01_000007 Container Transitioned from ACQUIRED to RUNNING
2013-08-27 16:04:46,285 INFO org.apache.hadoop.yarn.server.resourcemanager.rmcontainer.RMContainerImpl: container_1377618433102_0007_01_000008 Container Transitioned from ACQUIRED to RUNNING
2013-08-27 16:04:46,285 INFO org.apache.hadoop.yarn.server.resourcemanager.rmcontainer.RMContainerImpl: container_1377618433102_0007_01_000009 Container Transitioned from ACQUIRED to RUNNING
2013-08-27 16:04:46,286 INFO org.apache.hadoop.yarn.server.resourcemanager.rmcontainer.RMContainerImpl: container_1377618433102_0007_01_000010 Container Transitioned from ACQUIRED to RUNNING
2013-08-27 16:04:46,286 INFO org.apache.hadoop.yarn.server.resourcemanager.rmcontainer.RMContainerImpl: container_1377618433102_0007_01_000011 Container Transitioned from ACQUIRED to RUNNING
2013-08-27 16:04:46,287 INFO org.apache.hadoop.yarn.server.resourcemanager.rmcontainer.RMContainerImpl: container_1377618433102_0007_01_000012 Container Transitioned from ACQUIRED to RUNNING
2013-08-27 16:04:46,287 INFO org.apache.hadoop.yarn.server.resourcemanager.rmcontainer.RMContainerImpl: container_1377618433102_0007_01_000013 Container Transitioned from ACQUIRED to RUNNING
2013-08-27 16:04:46,335 INFO org.apache.hadoop.yarn.server.resourcemanager.rmcontainer.RMContainerImpl: container_1377618433102_0007_01_000014 Container Transitioned from ACQUIRED to RUNNING
2013-08-27 16:04:46,337 INFO org.apache.hadoop.yarn.server.resourcemanager.rmcontainer.RMContainerImpl: container_1377618433102_0007_01_000015 Container Transitioned from ACQUIRED to RUNNING
2013-08-27 16:04:46,338 INFO org.apache.hadoop.yarn.server.resourcemanager.rmcontainer.RMContainerImpl: container_1377618433102_0007_01_000016 Container Transitioned from ACQUIRED to RUNNING
2013-08-27 16:04:46,339 INFO org.apache.hadoop.yarn.server.resourcemanager.rmcontainer.RMContainerImpl: container_1377618433102_0007_01_000017 Container Transitioned from ACQUIRED to RUNNING
2013-08-27 16:04:46,340 INFO org.apache.hadoop.yarn.server.resourcemanager.rmcontainer.RMContainerImpl: container_1377618433102_0007_01_000018 Container Transitioned from ACQUIRED to RUNNING
2013-08-27 16:04:46,341 INFO org.apache.hadoop.yarn.server.resourcemanager.rmcontainer.RMContainerImpl: container_1377618433102_0007_01_000019 Container Transitioned from ACQUIRED to RUNNING
2013-08-27 16:04:46,387 INFO org.apache.hadoop.yarn.server.resourcemanager.rmcontainer.RMContainerImpl: container_1377618433102_0007_01_000020 Container Transitioned from ACQUIRED to RUNNING
2013-08-27 16:04:46,391 INFO org.apache.hadoop.yarn.server.resourcemanager.rmcontainer.RMContainerImpl: container_1377618433102_0007_01_000021 Container Transitioned from ACQUIRED to RUNNING
2013-08-27 16:04:46,392 INFO org.apache.hadoop.yarn.server.resourcemanager.rmcontainer.RMContainerImpl: container_1377618433102_0007_01_000022 Container Transitioned from ACQUIRED to RUNNING
2013-08-27 16:04:46,392 INFO org.apache.hadoop.yarn.server.resourcemanager.rmcontainer.RMContainerImpl: container_1377618433102_0007_01_000023 Container Transitioned from ACQUIRED to RUNNING
2013-08-27 16:04:46,393 INFO org.apache.hadoop.yarn.server.resourcemanager.rmcontainer.RMContainerImpl: container_1377618433102_0007_01_000024 Container Transitioned from ACQUIRED to RUNNING
2013-08-27 16:04:46,394 INFO org.apache.hadoop.yarn.server.resourcemanager.rmcontainer.RMContainerImpl: container_1377618433102_0007_01_000025 Container Transitioned from ACQUIRED to RUNNING
2013-08-27 16:04:46,394 INFO org.apache.hadoop.yarn.server.resourcemanager.rmcontainer.RMContainerImpl: container_1377618433102_0007_01_000026 Container Transitioned from ACQUIRED to RUNNING
2013-08-27 16:04:46,395 INFO org.apache.hadoop.yarn.server.resourcemanager.rmcontainer.RMContainerImpl: container_1377618433102_0007_01_000027 Container Transitioned from ACQUIRED to RUNNING
2013-08-27 16:04:46,431 INFO org.apache.hadoop.yarn.server.resourcemanager.rmcontainer.RMContainerImpl: container_1377618433102_0007_01_000028 Container Transitioned from ACQUIRED to RUNNING
2013-08-27 16:04:46,432 INFO org.apache.hadoop.yarn.server.resourcemanager.rmcontainer.RMContainerImpl: container_1377618433102_0007_01_000029 Container Transitioned from ACQUIRED to RUNNING
2013-08-27 16:04:46,434 INFO org.apache.hadoop.yarn.server.resourcemanager.rmcontainer.RMContainerImpl: container_1377618433102_0007_01_000030 Container Transitioned from ACQUIRED to RUNNING
2013-08-27 16:04:46,434 INFO org.apache.hadoop.yarn.server.resourcemanager.rmcontainer.RMContainerImpl: container_1377618433102_0007_01_000031 Container Transitioned from ACQUIRED to RUNNING
2013-08-27 16:04:46,434 INFO org.apache.hadoop.yarn.server.resourcemanager.rmcontainer.RMContainerImpl: container_1377618433102_0007_01_000032 Container Transitioned from ACQUIRED to RUNNING
2013-08-27 16:04:46,434 INFO org.apache.hadoop.yarn.server.resourcemanager.rmcontainer.RMContainerImpl: container_1377618433102_0007_01_000033 Container Transitioned from ACQUIRED to RUNNING
2013-08-27 16:04:46,854 INFO org.apache.hadoop.yarn.server.resourcemanager.rmcontainer.RMContainerImpl: container_1377618433102_0006_01_000002 Container Transitioned from ACQUIRED to RUNNING
2013-08-27 16:04:46,854 INFO org.apache.hadoop.yarn.server.resourcemanager.rmcontainer.RMContainerImpl: container_1377618433102_0006_01_000003 Container Transitioned from ACQUIRED to RUNNING
2013-08-27 16:04:46,855 INFO org.apache.hadoop.yarn.server.resourcemanager.rmcontainer.RMContainerImpl: container_1377618433102_0006_01_000004 Container Transitioned from ACQUIRED to RUNNING
2013-08-27 16:04:46,855 INFO org.apache.hadoop.yarn.server.resourcemanager.rmcontainer.RMContainerImpl: container_1377618433102_0006_01_000005 Container Transitioned from ACQUIRED to RUNNING
2013-08-27 16:04:46,855 INFO org.apache.hadoop.yarn.server.resourcemanager.rmcontainer.RMContainerImpl: container_1377618433102_0006_01_000006 Container Transitioned from ACQUIRED to RUNNING
2013-08-27 16:04:46,855 INFO org.apache.hadoop.yarn.server.resourcemanager.rmcontainer.RMContainerImpl: container_1377618433102_0006_01_000007 Container Transitioned from ACQUIRED to RUNNING
2013-08-27 16:05:07,527 INFO org.apache.hadoop.yarn.server.resourcemanager.rmcontainer.RMContainerImpl: container_1377618433102_0007_01_000002 Container Transitioned from RUNNING to COMPLETED
2013-08-27 16:05:07,528 INFO org.apache.hadoop.yarn.server.resourcemanager.scheduler.common.fica.FiCaSchedulerApp: Completed container: container_1377618433102_0007_01_000002 in state: COMPLETED event:FINISHED
2013-08-27 16:05:07,528 INFO org.apache.hadoop.yarn.server.resourcemanager.RMAuditLogger: USER=ubuntu	OPERATION=AM Released Container	TARGET=SchedulerApp	RESULT=SUCCESS	APPID=application_1377618433102_0007	CONTAINERID=container_1377618433102_0007_01_000002
2013-08-27 16:05:07,528 INFO org.apache.hadoop.yarn.server.resourcemanager.scheduler.common.fica.FiCaSchedulerNode: Released container container_1377618433102_0007_01_000002 of capacity <memory:1024, vCores:1> on host hadoop-8-5:56487, which currently has 6 containers, <memory:7168, vCores:6> used and <memory:1024, vCores:10> available, release resources=true
2013-08-27 16:05:07,528 INFO org.apache.hadoop.yarn.server.resourcemanager.scheduler.capacity.LeafQueue: default used=<memory:48128, vCores:42> numContainers=42 user=ubuntu user-resources=<memory:48128, vCores:42>
2013-08-27 16:05:07,531 INFO org.apache.hadoop.yarn.server.resourcemanager.scheduler.capacity.LeafQueue: completedContainer container=Container: [ContainerId: container_1377618433102_0007_01_000002, NodeId: hadoop-8-5:56487, NodeHttpAddress: hadoop-8-5:8042, Resource: <memory:1024, vCores:1>, Priority: 20, State: NEW, Token: null, Status: container_id {, app_attempt_id {, application_id {, id: 7, cluster_timestamp: 1377618433102, }, attemptId: 1, }, id: 2, }, state: C_COMPLETE, diagnostics: "Container killed by the ApplicationMaster.\n\n", exit_status: 143, ] resource=<memory:1024, vCores:1> queue=default: capacity=1.0, absoluteCapacity=1.0, usedResources=<memory:48128, vCores:42>usedCapacity=0.9791667, absoluteUsedCapacity=0.9791667, numApps=5, numContainers=42 usedCapacity=0.9791667 absoluteUsedCapacity=0.9791667 used=<memory:48128, vCores:42> cluster=<memory:49152, vCores:96>
2013-08-27 16:05:07,531 INFO org.apache.hadoop.yarn.server.resourcemanager.scheduler.capacity.ParentQueue: completedContainer queue=root usedCapacity=0.9791667 absoluteUsedCapacity=0.9791667 used=<memory:48128, vCores:42> cluster=<memory:49152, vCores:96>
2013-08-27 16:05:07,531 INFO org.apache.hadoop.yarn.server.resourcemanager.scheduler.capacity.CapacityScheduler: Application appattempt_1377618433102_0007_000001 released container container_1377618433102_0007_01_000002 on node: host: hadoop-8-5:56487 #containers=6 available=1024 used=7168 with event: FINISHED
2013-08-27 16:05:07,532 INFO org.apache.hadoop.yarn.server.resourcemanager.rmcontainer.RMContainerImpl: container_1377618433102_0006_01_000008 Container Transitioned from NEW to ALLOCATED
2013-08-27 16:05:07,532 INFO org.apache.hadoop.yarn.server.resourcemanager.RMAuditLogger: USER=ubuntu	OPERATION=AM Allocated Container	TARGET=SchedulerApp	RESULT=SUCCESS	APPID=application_1377618433102_0006	CONTAINERID=container_1377618433102_0006_01_000008
2013-08-27 16:05:07,532 INFO org.apache.hadoop.yarn.server.resourcemanager.scheduler.common.fica.FiCaSchedulerNode: Assigned container container_1377618433102_0006_01_000008 of capacity <memory:1024, vCores:1> on host hadoop-8-5:56487, which currently has 7 containers, <memory:8192, vCores:7> used and <memory:0, vCores:9> available
2013-08-27 16:05:07,533 INFO org.apache.hadoop.yarn.server.resourcemanager.scheduler.capacity.LeafQueue: assignedContainer application=application_1377618433102_0006 container=Container: [ContainerId: container_1377618433102_0006_01_000008, NodeId: hadoop-8-5:56487, NodeHttpAddress: hadoop-8-5:8042, Resource: <memory:1024, vCores:1>, Priority: 20, State: NEW, Token: null, Status: container_id {, app_attempt_id {, application_id {, id: 6, cluster_timestamp: 1377618433102, }, attemptId: 1, }, id: 8, }, state: C_NEW, ] containerId=container_1377618433102_0006_01_000008 queue=default: capacity=1.0, absoluteCapacity=1.0, usedResources=<memory:48128, vCores:42>usedCapacity=0.9791667, absoluteUsedCapacity=0.9791667, numApps=5, numContainers=42 usedCapacity=0.9791667 absoluteUsedCapacity=0.9791667 used=<memory:48128, vCores:42> cluster=<memory:49152, vCores:96>
2013-08-27 16:05:07,534 INFO org.apache.hadoop.yarn.server.resourcemanager.scheduler.capacity.ParentQueue: Re-sorting queues since queue: root.default stats: default: capacity=1.0, absoluteCapacity=1.0, usedResources=<memory:49152, vCores:43>usedCapacity=1.0, absoluteUsedCapacity=1.0, numApps=5, numContainers=43
2013-08-27 16:05:07,534 INFO org.apache.hadoop.yarn.server.resourcemanager.scheduler.capacity.ParentQueue: assignedContainer queue=root usedCapacity=1.0 absoluteUsedCapacity=1.0 used=<memory:49152, vCores:43> cluster=<memory:49152, vCores:96>
2013-08-27 16:05:08,101 INFO org.apache.hadoop.yarn.server.resourcemanager.rmcontainer.RMContainerImpl: container_1377618433102_0006_01_000008 Container Transitioned from ALLOCATED to ACQUIRED
2013-08-27 16:05:09,082 INFO org.apache.hadoop.yarn.server.resourcemanager.rmcontainer.RMContainerImpl: container_1377618433102_0006_01_000008 Container Transitioned from ACQUIRED to RUNNING
2013-08-27 16:05:09,083 INFO org.apache.hadoop.yarn.server.resourcemanager.rmcontainer.RMContainerImpl: container_1377618433102_0007_01_000004 Container Transitioned from RUNNING to COMPLETED
2013-08-27 16:05:09,083 INFO org.apache.hadoop.yarn.server.resourcemanager.scheduler.common.fica.FiCaSchedulerApp: Completed container: container_1377618433102_0007_01_000004 in state: COMPLETED event:FINISHED
2013-08-27 16:05:09,083 INFO org.apache.hadoop.yarn.server.resourcemanager.RMAuditLogger: USER=ubuntu	OPERATION=AM Released Container	TARGET=SchedulerApp	RESULT=SUCCESS	APPID=application_1377618433102_0007	CONTAINERID=container_1377618433102_0007_01_000004
2013-08-27 16:05:09,083 INFO org.apache.hadoop.yarn.server.resourcemanager.scheduler.common.fica.FiCaSchedulerNode: Released container container_1377618433102_0007_01_000004 of capacity <memory:1024, vCores:1> on host hadoop-8-5:56487, which currently has 6 containers, <memory:7168, vCores:6> used and <memory:1024, vCores:10> available, release resources=true
2013-08-27 16:05:09,083 INFO org.apache.hadoop.yarn.server.resourcemanager.scheduler.capacity.LeafQueue: default used=<memory:48128, vCores:42> numContainers=42 user=ubuntu user-resources=<memory:48128, vCores:42>
2013-08-27 16:05:09,085 INFO org.apache.hadoop.yarn.server.resourcemanager.scheduler.capacity.LeafQueue: completedContainer container=Container: [ContainerId: container_1377618433102_0007_01_000004, NodeId: hadoop-8-5:56487, NodeHttpAddress: hadoop-8-5:8042, Resource: <memory:1024, vCores:1>, Priority: 20, State: NEW, Token: null, Status: container_id {, app_attempt_id {, application_id {, id: 7, cluster_timestamp: 1377618433102, }, attemptId: 1, }, id: 4, }, state: C_COMPLETE, diagnostics: "Container killed by the ApplicationMaster.\n\n", exit_status: 143, ] resource=<memory:1024, vCores:1> queue=default: capacity=1.0, absoluteCapacity=1.0, usedResources=<memory:48128, vCores:42>usedCapacity=0.9791667, absoluteUsedCapacity=0.9791667, numApps=5, numContainers=42 usedCapacity=0.9791667 absoluteUsedCapacity=0.9791667 used=<memory:48128, vCores:42> cluster=<memory:49152, vCores:96>
2013-08-27 16:05:09,085 INFO org.apache.hadoop.yarn.server.resourcemanager.scheduler.capacity.ParentQueue: completedContainer queue=root usedCapacity=0.9791667 absoluteUsedCapacity=0.9791667 used=<memory:48128, vCores:42> cluster=<memory:49152, vCores:96>
2013-08-27 16:05:09,085 INFO org.apache.hadoop.yarn.server.resourcemanager.scheduler.capacity.CapacityScheduler: Application appattempt_1377618433102_0007_000001 released container container_1377618433102_0007_01_000004 on node: host: hadoop-8-5:56487 #containers=6 available=1024 used=7168 with event: FINISHED
2013-08-27 16:05:09,086 INFO org.apache.hadoop.yarn.server.resourcemanager.rmcontainer.RMContainerImpl: container_1377618433102_0006_01_000009 Container Transitioned from NEW to ALLOCATED
2013-08-27 16:05:09,086 INFO org.apache.hadoop.yarn.server.resourcemanager.RMAuditLogger: USER=ubuntu	OPERATION=AM Allocated Container	TARGET=SchedulerApp	RESULT=SUCCESS	APPID=application_1377618433102_0006	CONTAINERID=container_1377618433102_0006_01_000009
2013-08-27 16:05:09,086 INFO org.apache.hadoop.yarn.server.resourcemanager.scheduler.common.fica.FiCaSchedulerNode: Assigned container container_1377618433102_0006_01_000009 of capacity <memory:1024, vCores:1> on host hadoop-8-5:56487, which currently has 7 containers, <memory:8192, vCores:7> used and <memory:0, vCores:9> available
2013-08-27 16:05:09,087 INFO org.apache.hadoop.yarn.server.resourcemanager.scheduler.capacity.LeafQueue: assignedContainer application=application_1377618433102_0006 container=Container: [ContainerId: container_1377618433102_0006_01_000009, NodeId: hadoop-8-5:56487, NodeHttpAddress: hadoop-8-5:8042, Resource: <memory:1024, vCores:1>, Priority: 20, State: NEW, Token: null, Status: container_id {, app_attempt_id {, application_id {, id: 6, cluster_timestamp: 1377618433102, }, attemptId: 1, }, id: 9, }, state: C_NEW, ] containerId=container_1377618433102_0006_01_000009 queue=default: capacity=1.0, absoluteCapacity=1.0, usedResources=<memory:48128, vCores:42>usedCapacity=0.9791667, absoluteUsedCapacity=0.9791667, numApps=5, numContainers=42 usedCapacity=0.9791667 absoluteUsedCapacity=0.9791667 used=<memory:48128, vCores:42> cluster=<memory:49152, vCores:96>
2013-08-27 16:05:09,088 INFO org.apache.hadoop.yarn.server.resourcemanager.scheduler.capacity.ParentQueue: Re-sorting queues since queue: root.default stats: default: capacity=1.0, absoluteCapacity=1.0, usedResources=<memory:49152, vCores:43>usedCapacity=1.0, absoluteUsedCapacity=1.0, numApps=5, numContainers=43
2013-08-27 16:05:09,088 INFO org.apache.hadoop.yarn.server.resourcemanager.scheduler.capacity.ParentQueue: assignedContainer queue=root usedCapacity=1.0 absoluteUsedCapacity=1.0 used=<memory:49152, vCores:43> cluster=<memory:49152, vCores:96>
2013-08-27 16:05:09,206 INFO org.apache.hadoop.yarn.server.resourcemanager.rmcontainer.RMContainerImpl: container_1377618433102_0006_01_000009 Container Transitioned from ALLOCATED to ACQUIRED
2013-08-27 16:05:10,094 INFO org.apache.hadoop.yarn.server.resourcemanager.rmcontainer.RMContainerImpl: container_1377618433102_0006_01_000009 Container Transitioned from ACQUIRED to RUNNING
2013-08-27 16:05:16,586 INFO org.apache.hadoop.yarn.server.resourcemanager.rmcontainer.RMContainerImpl: container_1377618433102_0007_01_000027 Container Transitioned from RUNNING to COMPLETED
2013-08-27 16:05:16,586 INFO org.apache.hadoop.yarn.server.resourcemanager.scheduler.common.fica.FiCaSchedulerApp: Completed container: container_1377618433102_0007_01_000027 in state: COMPLETED event:FINISHED
2013-08-27 16:05:16,586 INFO org.apache.hadoop.yarn.server.resourcemanager.RMAuditLogger: USER=ubuntu	OPERATION=AM Released Container	TARGET=SchedulerApp	RESULT=SUCCESS	APPID=application_1377618433102_0007	CONTAINERID=container_1377618433102_0007_01_000027
2013-08-27 16:05:16,586 INFO org.apache.hadoop.yarn.server.resourcemanager.scheduler.common.fica.FiCaSchedulerNode: Released container container_1377618433102_0007_01_000027 of capacity <memory:1024, vCores:1> on host hadoop-8-3:42074, which currently has 7 containers, <memory:7168, vCores:7> used and <memory:1024, vCores:9> available, release resources=true
2013-08-27 16:05:16,586 INFO org.apache.hadoop.yarn.server.resourcemanager.scheduler.capacity.LeafQueue: default used=<memory:48128, vCores:42> numContainers=42 user=ubuntu user-resources=<memory:48128, vCores:42>
2013-08-27 16:05:16,588 INFO org.apache.hadoop.yarn.server.resourcemanager.scheduler.capacity.LeafQueue: completedContainer container=Container: [ContainerId: container_1377618433102_0007_01_000027, NodeId: hadoop-8-3:42074, NodeHttpAddress: hadoop-8-3:8042, Resource: <memory:1024, vCores:1>, Priority: 20, State: NEW, Token: null, Status: container_id {, app_attempt_id {, application_id {, id: 7, cluster_timestamp: 1377618433102, }, attemptId: 1, }, id: 27, }, state: C_COMPLETE, diagnostics: "Container killed by the ApplicationMaster.\n\n", exit_status: 143, ] resource=<memory:1024, vCores:1> queue=default: capacity=1.0, absoluteCapacity=1.0, usedResources=<memory:48128, vCores:42>usedCapacity=0.9791667, absoluteUsedCapacity=0.9791667, numApps=5, numContainers=42 usedCapacity=0.9791667 absoluteUsedCapacity=0.9791667 used=<memory:48128, vCores:42> cluster=<memory:49152, vCores:96>
2013-08-27 16:05:16,588 INFO org.apache.hadoop.yarn.server.resourcemanager.scheduler.capacity.ParentQueue: completedContainer queue=root usedCapacity=0.9791667 absoluteUsedCapacity=0.9791667 used=<memory:48128, vCores:42> cluster=<memory:49152, vCores:96>
2013-08-27 16:05:16,588 INFO org.apache.hadoop.yarn.server.resourcemanager.scheduler.capacity.CapacityScheduler: Application appattempt_1377618433102_0007_000001 released container container_1377618433102_0007_01_000027 on node: host: hadoop-8-3:42074 #containers=7 available=1024 used=7168 with event: FINISHED
2013-08-27 16:05:16,589 INFO org.apache.hadoop.yarn.server.resourcemanager.rmcontainer.RMContainerImpl: container_1377618433102_0006_01_000010 Container Transitioned from NEW to ALLOCATED
2013-08-27 16:05:16,589 INFO org.apache.hadoop.yarn.server.resourcemanager.RMAuditLogger: USER=ubuntu	OPERATION=AM Allocated Container	TARGET=SchedulerApp	RESULT=SUCCESS	APPID=application_1377618433102_0006	CONTAINERID=container_1377618433102_0006_01_000010
2013-08-27 16:05:16,589 INFO org.apache.hadoop.yarn.server.resourcemanager.scheduler.common.fica.FiCaSchedulerNode: Assigned container container_1377618433102_0006_01_000010 of capacity <memory:1024, vCores:1> on host hadoop-8-3:42074, which currently has 8 containers, <memory:8192, vCores:8> used and <memory:0, vCores:8> available
2013-08-27 16:05:16,590 INFO org.apache.hadoop.yarn.server.resourcemanager.scheduler.capacity.LeafQueue: assignedContainer application=application_1377618433102_0006 container=Container: [ContainerId: container_1377618433102_0006_01_000010, NodeId: hadoop-8-3:42074, NodeHttpAddress: hadoop-8-3:8042, Resource: <memory:1024, vCores:1>, Priority: 20, State: NEW, Token: null, Status: container_id {, app_attempt_id {, application_id {, id: 6, cluster_timestamp: 1377618433102, }, attemptId: 1, }, id: 10, }, state: C_NEW, ] containerId=container_1377618433102_0006_01_000010 queue=default: capacity=1.0, absoluteCapacity=1.0, usedResources=<memory:48128, vCores:42>usedCapacity=0.9791667, absoluteUsedCapacity=0.9791667, numApps=5, numContainers=42 usedCapacity=0.9791667 absoluteUsedCapacity=0.9791667 used=<memory:48128, vCores:42> cluster=<memory:49152, vCores:96>
2013-08-27 16:05:16,590 INFO org.apache.hadoop.yarn.server.resourcemanager.scheduler.capacity.ParentQueue: Re-sorting queues since queue: root.default stats: default: capacity=1.0, absoluteCapacity=1.0, usedResources=<memory:49152, vCores:43>usedCapacity=1.0, absoluteUsedCapacity=1.0, numApps=5, numContainers=43
2013-08-27 16:05:16,590 INFO org.apache.hadoop.yarn.server.resourcemanager.scheduler.capacity.ParentQueue: assignedContainer queue=root usedCapacity=1.0 absoluteUsedCapacity=1.0 used=<memory:49152, vCores:43> cluster=<memory:49152, vCores:96>
2013-08-27 16:05:16,591 INFO org.apache.hadoop.yarn.server.resourcemanager.rmcontainer.RMContainerImpl: container_1377618433102_0007_01_000018 Container Transitioned from RUNNING to COMPLETED
2013-08-27 16:05:16,591 INFO org.apache.hadoop.yarn.server.resourcemanager.scheduler.common.fica.FiCaSchedulerApp: Completed container: container_1377618433102_0007_01_000018 in state: COMPLETED event:FINISHED
2013-08-27 16:05:16,591 INFO org.apache.hadoop.yarn.server.resourcemanager.RMAuditLogger: USER=ubuntu	OPERATION=AM Released Container	TARGET=SchedulerApp	RESULT=SUCCESS	APPID=application_1377618433102_0007	CONTAINERID=container_1377618433102_0007_01_000018
2013-08-27 16:05:16,591 INFO org.apache.hadoop.yarn.server.resourcemanager.scheduler.common.fica.FiCaSchedulerNode: Released container container_1377618433102_0007_01_000018 of capacity <memory:1024, vCores:1> on host hadoop-8-6:45732, which currently has 6 containers, <memory:7168, vCores:6> used and <memory:1024, vCores:10> available, release resources=true
2013-08-27 16:05:16,592 INFO org.apache.hadoop.yarn.server.resourcemanager.scheduler.capacity.LeafQueue: default used=<memory:48128, vCores:42> numContainers=42 user=ubuntu user-resources=<memory:48128, vCores:42>
2013-08-27 16:05:16,593 INFO org.apache.hadoop.yarn.server.resourcemanager.scheduler.capacity.LeafQueue: completedContainer container=Container: [ContainerId: container_1377618433102_0007_01_000018, NodeId: hadoop-8-6:45732, NodeHttpAddress: hadoop-8-6:8042, Resource: <memory:1024, vCores:1>, Priority: 20, State: NEW, Token: null, Status: container_id {, app_attempt_id {, application_id {, id: 7, cluster_timestamp: 1377618433102, }, attemptId: 1, }, id: 18, }, state: C_COMPLETE, diagnostics: "Container killed by the ApplicationMaster.\n\n", exit_status: 143, ] resource=<memory:1024, vCores:1> queue=default: capacity=1.0, absoluteCapacity=1.0, usedResources=<memory:48128, vCores:42>usedCapacity=0.9791667, absoluteUsedCapacity=0.9791667, numApps=5, numContainers=42 usedCapacity=0.9791667 absoluteUsedCapacity=0.9791667 used=<memory:48128, vCores:42> cluster=<memory:49152, vCores:96>
2013-08-27 16:05:16,593 INFO org.apache.hadoop.yarn.server.resourcemanager.scheduler.capacity.ParentQueue: completedContainer queue=root usedCapacity=0.9791667 absoluteUsedCapacity=0.9791667 used=<memory:48128, vCores:42> cluster=<memory:49152, vCores:96>
2013-08-27 16:05:16,593 INFO org.apache.hadoop.yarn.server.resourcemanager.scheduler.capacity.CapacityScheduler: Application appattempt_1377618433102_0007_000001 released container container_1377618433102_0007_01_000018 on node: host: hadoop-8-6:45732 #containers=6 available=1024 used=7168 with event: FINISHED
2013-08-27 16:05:16,594 INFO org.apache.hadoop.yarn.server.resourcemanager.rmcontainer.RMContainerImpl: container_1377618433102_0006_01_000011 Container Transitioned from NEW to ALLOCATED
2013-08-27 16:05:16,594 INFO org.apache.hadoop.yarn.server.resourcemanager.RMAuditLogger: USER=ubuntu	OPERATION=AM Allocated Container	TARGET=SchedulerApp	RESULT=SUCCESS	APPID=application_1377618433102_0006	CONTAINERID=container_1377618433102_0006_01_000011
2013-08-27 16:05:16,594 INFO org.apache.hadoop.yarn.server.resourcemanager.scheduler.common.fica.FiCaSchedulerNode: Assigned container container_1377618433102_0006_01_000011 of capacity <memory:1024, vCores:1> on host hadoop-8-6:45732, which currently has 7 containers, <memory:8192, vCores:7> used and <memory:0, vCores:9> available
2013-08-27 16:05:16,595 INFO org.apache.hadoop.yarn.server.resourcemanager.scheduler.capacity.LeafQueue: assignedContainer application=application_1377618433102_0006 container=Container: [ContainerId: container_1377618433102_0006_01_000011, NodeId: hadoop-8-6:45732, NodeHttpAddress: hadoop-8-6:8042, Resource: <memory:1024, vCores:1>, Priority: 20, State: NEW, Token: null, Status: container_id {, app_attempt_id {, application_id {, id: 6, cluster_timestamp: 1377618433102, }, attemptId: 1, }, id: 11, }, state: C_NEW, ] containerId=container_1377618433102_0006_01_000011 queue=default: capacity=1.0, absoluteCapacity=1.0, usedResources=<memory:48128, vCores:42>usedCapacity=0.9791667, absoluteUsedCapacity=0.9791667, numApps=5, numContainers=42 usedCapacity=0.9791667 absoluteUsedCapacity=0.9791667 used=<memory:48128, vCores:42> cluster=<memory:49152, vCores:96>
2013-08-27 16:05:16,595 INFO org.apache.hadoop.yarn.server.resourcemanager.scheduler.capacity.ParentQueue: Re-sorting queues since queue: root.default stats: default: capacity=1.0, absoluteCapacity=1.0, usedResources=<memory:49152, vCores:43>usedCapacity=1.0, absoluteUsedCapacity=1.0, numApps=5, numContainers=43
2013-08-27 16:05:16,595 INFO org.apache.hadoop.yarn.server.resourcemanager.scheduler.capacity.ParentQueue: assignedContainer queue=root usedCapacity=1.0 absoluteUsedCapacity=1.0 used=<memory:49152, vCores:43> cluster=<memory:49152, vCores:96>
2013-08-27 16:05:16,928 INFO org.apache.hadoop.yarn.server.resourcemanager.rmcontainer.RMContainerImpl: container_1377618433102_0007_01_000017 Container Transitioned from RUNNING to COMPLETED
2013-08-27 16:05:16,928 INFO org.apache.hadoop.yarn.server.resourcemanager.scheduler.common.fica.FiCaSchedulerApp: Completed container: container_1377618433102_0007_01_000017 in state: COMPLETED event:FINISHED
2013-08-27 16:05:16,928 INFO org.apache.hadoop.yarn.server.resourcemanager.RMAuditLogger: USER=ubuntu	OPERATION=AM Released Container	TARGET=SchedulerApp	RESULT=SUCCESS	APPID=application_1377618433102_0007	CONTAINERID=container_1377618433102_0007_01_000017
2013-08-27 16:05:16,929 INFO org.apache.hadoop.yarn.server.resourcemanager.scheduler.common.fica.FiCaSchedulerNode: Released container container_1377618433102_0007_01_000017 of capacity <memory:1024, vCores:1> on host hadoop-8-6:45732, which currently has 6 containers, <memory:7168, vCores:6> used and <memory:1024, vCores:10> available, release resources=true
2013-08-27 16:05:16,929 INFO org.apache.hadoop.yarn.server.resourcemanager.scheduler.capacity.LeafQueue: default used=<memory:48128, vCores:42> numContainers=42 user=ubuntu user-resources=<memory:48128, vCores:42>
2013-08-27 16:05:16,930 INFO org.apache.hadoop.yarn.server.resourcemanager.scheduler.capacity.LeafQueue: completedContainer container=Container: [ContainerId: container_1377618433102_0007_01_000017, NodeId: hadoop-8-6:45732, NodeHttpAddress: hadoop-8-6:8042, Resource: <memory:1024, vCores:1>, Priority: 20, State: NEW, Token: null, Status: container_id {, app_attempt_id {, application_id {, id: 7, cluster_timestamp: 1377618433102, }, attemptId: 1, }, id: 17, }, state: C_COMPLETE, diagnostics: "Container killed by the ApplicationMaster.\n\n", exit_status: 143, ] resource=<memory:1024, vCores:1> queue=default: capacity=1.0, absoluteCapacity=1.0, usedResources=<memory:48128, vCores:42>usedCapacity=0.9791667, absoluteUsedCapacity=0.9791667, numApps=5, numContainers=42 usedCapacity=0.9791667 absoluteUsedCapacity=0.9791667 used=<memory:48128, vCores:42> cluster=<memory:49152, vCores:96>
2013-08-27 16:05:16,930 INFO org.apache.hadoop.yarn.server.resourcemanager.scheduler.capacity.ParentQueue: completedContainer queue=root usedCapacity=0.9791667 absoluteUsedCapacity=0.9791667 used=<memory:48128, vCores:42> cluster=<memory:49152, vCores:96>
2013-08-27 16:05:16,930 INFO org.apache.hadoop.yarn.server.resourcemanager.scheduler.capacity.CapacityScheduler: Application appattempt_1377618433102_0007_000001 released container container_1377618433102_0007_01_000017 on node: host: hadoop-8-6:45732 #containers=6 available=1024 used=7168 with event: FINISHED
2013-08-27 16:05:16,931 INFO org.apache.hadoop.yarn.server.resourcemanager.rmcontainer.RMContainerImpl: container_1377618433102_0006_01_000012 Container Transitioned from NEW to ALLOCATED
2013-08-27 16:05:16,931 INFO org.apache.hadoop.yarn.server.resourcemanager.RMAuditLogger: USER=ubuntu	OPERATION=AM Allocated Container	TARGET=SchedulerApp	RESULT=SUCCESS	APPID=application_1377618433102_0006	CONTAINERID=container_1377618433102_0006_01_000012
2013-08-27 16:05:16,931 INFO org.apache.hadoop.yarn.server.resourcemanager.scheduler.common.fica.FiCaSchedulerNode: Assigned container container_1377618433102_0006_01_000012 of capacity <memory:1024, vCores:1> on host hadoop-8-6:45732, which currently has 7 containers, <memory:8192, vCores:7> used and <memory:0, vCores:9> available
2013-08-27 16:05:16,932 INFO org.apache.hadoop.yarn.server.resourcemanager.scheduler.capacity.LeafQueue: assignedContainer application=application_1377618433102_0006 container=Container: [ContainerId: container_1377618433102_0006_01_000012, NodeId: hadoop-8-6:45732, NodeHttpAddress: hadoop-8-6:8042, Resource: <memory:1024, vCores:1>, Priority: 20, State: NEW, Token: null, Status: container_id {, app_attempt_id {, application_id {, id: 6, cluster_timestamp: 1377618433102, }, attemptId: 1, }, id: 12, }, state: C_NEW, ] containerId=container_1377618433102_0006_01_000012 queue=default: capacity=1.0, absoluteCapacity=1.0, usedResources=<memory:48128, vCores:42>usedCapacity=0.9791667, absoluteUsedCapacity=0.9791667, numApps=5, numContainers=42 usedCapacity=0.9791667 absoluteUsedCapacity=0.9791667 used=<memory:48128, vCores:42> cluster=<memory:49152, vCores:96>
2013-08-27 16:05:16,932 INFO org.apache.hadoop.yarn.server.resourcemanager.scheduler.capacity.ParentQueue: Re-sorting queues since queue: root.default stats: default: capacity=1.0, absoluteCapacity=1.0, usedResources=<memory:49152, vCores:43>usedCapacity=1.0, absoluteUsedCapacity=1.0, numApps=5, numContainers=43
2013-08-27 16:05:16,932 INFO org.apache.hadoop.yarn.server.resourcemanager.scheduler.capacity.ParentQueue: assignedContainer queue=root usedCapacity=1.0 absoluteUsedCapacity=1.0 used=<memory:49152, vCores:43> cluster=<memory:49152, vCores:96>
2013-08-27 16:05:17,368 INFO org.apache.hadoop.yarn.server.resourcemanager.rmcontainer.RMContainerImpl: container_1377618433102_0006_01_000010 Container Transitioned from ALLOCATED to ACQUIRED
2013-08-27 16:05:17,369 INFO org.apache.hadoop.yarn.server.resourcemanager.rmcontainer.RMContainerImpl: container_1377618433102_0006_01_000011 Container Transitioned from ALLOCATED to ACQUIRED
2013-08-27 16:05:17,369 INFO org.apache.hadoop.yarn.server.resourcemanager.rmcontainer.RMContainerImpl: container_1377618433102_0006_01_000012 Container Transitioned from ALLOCATED to ACQUIRED
2013-08-27 16:05:17,915 INFO org.apache.hadoop.yarn.server.resourcemanager.rmcontainer.RMContainerImpl: container_1377618433102_0007_01_000013 Container Transitioned from RUNNING to COMPLETED
2013-08-27 16:05:17,915 INFO org.apache.hadoop.yarn.server.resourcemanager.scheduler.common.fica.FiCaSchedulerApp: Completed container: container_1377618433102_0007_01_000013 in state: COMPLETED event:FINISHED
2013-08-27 16:05:17,915 INFO org.apache.hadoop.yarn.server.resourcemanager.RMAuditLogger: USER=ubuntu	OPERATION=AM Released Container	TARGET=SchedulerApp	RESULT=SUCCESS	APPID=application_1377618433102_0007	CONTAINERID=container_1377618433102_0007_01_000013
2013-08-27 16:05:17,915 INFO org.apache.hadoop.yarn.server.resourcemanager.scheduler.common.fica.FiCaSchedulerNode: Released container container_1377618433102_0007_01_000013 of capacity <memory:1024, vCores:1> on host hadoop-8-4:36803, which currently has 6 containers, <memory:7168, vCores:6> used and <memory:1024, vCores:10> available, release resources=true
2013-08-27 16:05:17,915 INFO org.apache.hadoop.yarn.server.resourcemanager.scheduler.capacity.LeafQueue: default used=<memory:48128, vCores:42> numContainers=42 user=ubuntu user-resources=<memory:48128, vCores:42>
2013-08-27 16:05:17,916 INFO org.apache.hadoop.yarn.server.resourcemanager.scheduler.capacity.LeafQueue: completedContainer container=Container: [ContainerId: container_1377618433102_0007_01_000013, NodeId: hadoop-8-4:36803, NodeHttpAddress: hadoop-8-4:8042, Resource: <memory:1024, vCores:1>, Priority: 20, State: NEW, Token: null, Status: container_id {, app_attempt_id {, application_id {, id: 7, cluster_timestamp: 1377618433102, }, attemptId: 1, }, id: 13, }, state: C_COMPLETE, diagnostics: "Container killed by the ApplicationMaster.\n\n", exit_status: 143, ] resource=<memory:1024, vCores:1> queue=default: capacity=1.0, absoluteCapacity=1.0, usedResources=<memory:48128, vCores:42>usedCapacity=0.9791667, absoluteUsedCapacity=0.9791667, numApps=5, numContainers=42 usedCapacity=0.9791667 absoluteUsedCapacity=0.9791667 used=<memory:48128, vCores:42> cluster=<memory:49152, vCores:96>
2013-08-27 16:05:17,916 INFO org.apache.hadoop.yarn.server.resourcemanager.scheduler.capacity.ParentQueue: completedContainer queue=root usedCapacity=0.9791667 absoluteUsedCapacity=0.9791667 used=<memory:48128, vCores:42> cluster=<memory:49152, vCores:96>
2013-08-27 16:05:17,917 INFO org.apache.hadoop.yarn.server.resourcemanager.scheduler.capacity.CapacityScheduler: Application appattempt_1377618433102_0007_000001 released container container_1377618433102_0007_01_000013 on node: host: hadoop-8-4:36803 #containers=6 available=1024 used=7168 with event: FINISHED
2013-08-27 16:05:17,917 INFO org.apache.hadoop.yarn.server.resourcemanager.rmcontainer.RMContainerImpl: container_1377618433102_0006_01_000013 Container Transitioned from NEW to ALLOCATED
2013-08-27 16:05:17,917 INFO org.apache.hadoop.yarn.server.resourcemanager.RMAuditLogger: USER=ubuntu	OPERATION=AM Allocated Container	TARGET=SchedulerApp	RESULT=SUCCESS	APPID=application_1377618433102_0006	CONTAINERID=container_1377618433102_0006_01_000013
2013-08-27 16:05:17,917 INFO org.apache.hadoop.yarn.server.resourcemanager.scheduler.common.fica.FiCaSchedulerNode: Assigned container container_1377618433102_0006_01_000013 of capacity <memory:1024, vCores:1> on host hadoop-8-4:36803, which currently has 7 containers, <memory:8192, vCores:7> used and <memory:0, vCores:9> available
2013-08-27 16:05:17,918 INFO org.apache.hadoop.yarn.server.resourcemanager.scheduler.capacity.LeafQueue: assignedContainer application=application_1377618433102_0006 container=Container: [ContainerId: container_1377618433102_0006_01_000013, NodeId: hadoop-8-4:36803, NodeHttpAddress: hadoop-8-4:8042, Resource: <memory:1024, vCores:1>, Priority: 20, State: NEW, Token: null, Status: container_id {, app_attempt_id {, application_id {, id: 6, cluster_timestamp: 1377618433102, }, attemptId: 1, }, id: 13, }, state: C_NEW, ] containerId=container_1377618433102_0006_01_000013 queue=default: capacity=1.0, absoluteCapacity=1.0, usedResources=<memory:48128, vCores:42>usedCapacity=0.9791667, absoluteUsedCapacity=0.9791667, numApps=5, numContainers=42 usedCapacity=0.9791667 absoluteUsedCapacity=0.9791667 used=<memory:48128, vCores:42> cluster=<memory:49152, vCores:96>
2013-08-27 16:05:17,918 INFO org.apache.hadoop.yarn.server.resourcemanager.scheduler.capacity.ParentQueue: Re-sorting queues since queue: root.default stats: default: capacity=1.0, absoluteCapacity=1.0, usedResources=<memory:49152, vCores:43>usedCapacity=1.0, absoluteUsedCapacity=1.0, numApps=5, numContainers=43
2013-08-27 16:05:17,919 INFO org.apache.hadoop.yarn.server.resourcemanager.scheduler.capacity.ParentQueue: assignedContainer queue=root usedCapacity=1.0 absoluteUsedCapacity=1.0 used=<memory:49152, vCores:43> cluster=<memory:49152, vCores:96>
2013-08-27 16:05:17,935 INFO org.apache.hadoop.yarn.server.resourcemanager.rmcontainer.RMContainerImpl: container_1377618433102_0006_01_000011 Container Transitioned from ACQUIRED to RUNNING
2013-08-27 16:05:17,936 INFO org.apache.hadoop.yarn.server.resourcemanager.rmcontainer.RMContainerImpl: container_1377618433102_0006_01_000012 Container Transitioned from ACQUIRED to RUNNING
2013-08-27 16:05:17,936 INFO org.apache.hadoop.yarn.server.resourcemanager.rmcontainer.RMContainerImpl: container_1377618433102_0007_01_000019 Container Transitioned from RUNNING to COMPLETED
2013-08-27 16:05:17,936 INFO org.apache.hadoop.yarn.server.resourcemanager.scheduler.common.fica.FiCaSchedulerApp: Completed container: container_1377618433102_0007_01_000019 in state: COMPLETED event:FINISHED
2013-08-27 16:05:17,936 INFO org.apache.hadoop.yarn.server.resourcemanager.RMAuditLogger: USER=ubuntu	OPERATION=AM Released Container	TARGET=SchedulerApp	RESULT=SUCCESS	APPID=application_1377618433102_0007	CONTAINERID=container_1377618433102_0007_01_000019
2013-08-27 16:05:17,936 INFO org.apache.hadoop.yarn.server.resourcemanager.scheduler.common.fica.FiCaSchedulerNode: Released container container_1377618433102_0007_01_000019 of capacity <memory:1024, vCores:1> on host hadoop-8-6:45732, which currently has 6 containers, <memory:7168, vCores:6> used and <memory:1024, vCores:10> available, release resources=true
2013-08-27 16:05:17,936 INFO org.apache.hadoop.yarn.server.resourcemanager.scheduler.capacity.LeafQueue: default used=<memory:48128, vCores:42> numContainers=42 user=ubuntu user-resources=<memory:48128, vCores:42>
2013-08-27 16:05:17,937 INFO org.apache.hadoop.yarn.server.resourcemanager.scheduler.capacity.LeafQueue: completedContainer container=Container: [ContainerId: container_1377618433102_0007_01_000019, NodeId: hadoop-8-6:45732, NodeHttpAddress: hadoop-8-6:8042, Resource: <memory:1024, vCores:1>, Priority: 20, State: NEW, Token: null, Status: container_id {, app_attempt_id {, application_id {, id: 7, cluster_timestamp: 1377618433102, }, attemptId: 1, }, id: 19, }, state: C_COMPLETE, diagnostics: "Container killed by the ApplicationMaster.\n\n", exit_status: 143, ] resource=<memory:1024, vCores:1> queue=default: capacity=1.0, absoluteCapacity=1.0, usedResources=<memory:48128, vCores:42>usedCapacity=0.9791667, absoluteUsedCapacity=0.9791667, numApps=5, numContainers=42 usedCapacity=0.9791667 absoluteUsedCapacity=0.9791667 used=<memory:48128, vCores:42> cluster=<memory:49152, vCores:96>
2013-08-27 16:05:17,937 INFO org.apache.hadoop.yarn.server.resourcemanager.scheduler.capacity.ParentQueue: completedContainer queue=root usedCapacity=0.9791667 absoluteUsedCapacity=0.9791667 used=<memory:48128, vCores:42> cluster=<memory:49152, vCores:96>
2013-08-27 16:05:17,938 INFO org.apache.hadoop.yarn.server.resourcemanager.scheduler.capacity.CapacityScheduler: Application appattempt_1377618433102_0007_000001 released container container_1377618433102_0007_01_000019 on node: host: hadoop-8-6:45732 #containers=6 available=1024 used=7168 with event: FINISHED
2013-08-27 16:05:17,938 INFO org.apache.hadoop.yarn.server.resourcemanager.rmcontainer.RMContainerImpl: container_1377618433102_0006_01_000014 Container Transitioned from NEW to ALLOCATED
2013-08-27 16:05:17,938 INFO org.apache.hadoop.yarn.server.resourcemanager.RMAuditLogger: USER=ubuntu	OPERATION=AM Allocated Container	TARGET=SchedulerApp	RESULT=SUCCESS	APPID=application_1377618433102_0006	CONTAINERID=container_1377618433102_0006_01_000014
2013-08-27 16:05:17,938 INFO org.apache.hadoop.yarn.server.resourcemanager.scheduler.common.fica.FiCaSchedulerNode: Assigned container container_1377618433102_0006_01_000014 of capacity <memory:1024, vCores:1> on host hadoop-8-6:45732, which currently has 7 containers, <memory:8192, vCores:7> used and <memory:0, vCores:9> available
2013-08-27 16:05:17,939 INFO org.apache.hadoop.yarn.server.resourcemanager.scheduler.capacity.LeafQueue: assignedContainer application=application_1377618433102_0006 container=Container: [ContainerId: container_1377618433102_0006_01_000014, NodeId: hadoop-8-6:45732, NodeHttpAddress: hadoop-8-6:8042, Resource: <memory:1024, vCores:1>, Priority: 20, State: NEW, Token: null, Status: container_id {, app_attempt_id {, application_id {, id: 6, cluster_timestamp: 1377618433102, }, attemptId: 1, }, id: 14, }, state: C_NEW, ] containerId=container_1377618433102_0006_01_000014 queue=default: capacity=1.0, absoluteCapacity=1.0, usedResources=<memory:48128, vCores:42>usedCapacity=0.9791667, absoluteUsedCapacity=0.9791667, numApps=5, numContainers=42 usedCapacity=0.9791667 absoluteUsedCapacity=0.9791667 used=<memory:48128, vCores:42> cluster=<memory:49152, vCores:96>
2013-08-27 16:05:17,939 INFO org.apache.hadoop.yarn.server.resourcemanager.scheduler.capacity.ParentQueue: Re-sorting queues since queue: root.default stats: default: capacity=1.0, absoluteCapacity=1.0, usedResources=<memory:49152, vCores:43>usedCapacity=1.0, absoluteUsedCapacity=1.0, numApps=5, numContainers=43
2013-08-27 16:05:17,939 INFO org.apache.hadoop.yarn.server.resourcemanager.scheduler.capacity.ParentQueue: assignedContainer queue=root usedCapacity=1.0 absoluteUsedCapacity=1.0 used=<memory:49152, vCores:43> cluster=<memory:49152, vCores:96>
2013-08-27 16:05:18,212 INFO org.apache.hadoop.yarn.server.resourcemanager.rmcontainer.RMContainerImpl: container_1377618433102_0006_01_000010 Container Transitioned from ACQUIRED to RUNNING
2013-08-27 16:05:18,213 INFO org.apache.hadoop.yarn.server.resourcemanager.rmcontainer.RMContainerImpl: container_1377618433102_0007_01_000020 Container Transitioned from RUNNING to COMPLETED
2013-08-27 16:05:18,213 INFO org.apache.hadoop.yarn.server.resourcemanager.scheduler.common.fica.FiCaSchedulerApp: Completed container: container_1377618433102_0007_01_000020 in state: COMPLETED event:FINISHED
2013-08-27 16:05:18,213 INFO org.apache.hadoop.yarn.server.resourcemanager.RMAuditLogger: USER=ubuntu	OPERATION=AM Released Container	TARGET=SchedulerApp	RESULT=SUCCESS	APPID=application_1377618433102_0007	CONTAINERID=container_1377618433102_0007_01_000020
2013-08-27 16:05:18,213 INFO org.apache.hadoop.yarn.server.resourcemanager.scheduler.common.fica.FiCaSchedulerNode: Released container container_1377618433102_0007_01_000020 of capacity <memory:1024, vCores:1> on host hadoop-8-3:42074, which currently has 7 containers, <memory:7168, vCores:7> used and <memory:1024, vCores:9> available, release resources=true
2013-08-27 16:05:18,213 INFO org.apache.hadoop.yarn.server.resourcemanager.scheduler.capacity.LeafQueue: default used=<memory:48128, vCores:42> numContainers=42 user=ubuntu user-resources=<memory:48128, vCores:42>
2013-08-27 16:05:18,214 INFO org.apache.hadoop.yarn.server.resourcemanager.scheduler.capacity.LeafQueue: completedContainer container=Container: [ContainerId: container_1377618433102_0007_01_000020, NodeId: hadoop-8-3:42074, NodeHttpAddress: hadoop-8-3:8042, Resource: <memory:1024, vCores:1>, Priority: 20, State: NEW, Token: null, Status: container_id {, app_attempt_id {, application_id {, id: 7, cluster_timestamp: 1377618433102, }, attemptId: 1, }, id: 20, }, state: C_COMPLETE, diagnostics: "Container killed by the ApplicationMaster.\n\n", exit_status: 143, ] resource=<memory:1024, vCores:1> queue=default: capacity=1.0, absoluteCapacity=1.0, usedResources=<memory:48128, vCores:42>usedCapacity=0.9791667, absoluteUsedCapacity=0.9791667, numApps=5, numContainers=42 usedCapacity=0.9791667 absoluteUsedCapacity=0.9791667 used=<memory:48128, vCores:42> cluster=<memory:49152, vCores:96>
2013-08-27 16:05:18,215 INFO org.apache.hadoop.yarn.server.resourcemanager.scheduler.capacity.ParentQueue: completedContainer queue=root usedCapacity=0.9791667 absoluteUsedCapacity=0.9791667 used=<memory:48128, vCores:42> cluster=<memory:49152, vCores:96>
2013-08-27 16:05:18,215 INFO org.apache.hadoop.yarn.server.resourcemanager.scheduler.capacity.CapacityScheduler: Application appattempt_1377618433102_0007_000001 released container container_1377618433102_0007_01_000020 on node: host: hadoop-8-3:42074 #containers=7 available=1024 used=7168 with event: FINISHED
2013-08-27 16:05:18,215 INFO org.apache.hadoop.yarn.server.resourcemanager.rmcontainer.RMContainerImpl: container_1377618433102_0006_01_000015 Container Transitioned from NEW to ALLOCATED
2013-08-27 16:05:18,215 INFO org.apache.hadoop.yarn.server.resourcemanager.RMAuditLogger: USER=ubuntu	OPERATION=AM Allocated Container	TARGET=SchedulerApp	RESULT=SUCCESS	APPID=application_1377618433102_0006	CONTAINERID=container_1377618433102_0006_01_000015
2013-08-27 16:05:18,215 INFO org.apache.hadoop.yarn.server.resourcemanager.scheduler.common.fica.FiCaSchedulerNode: Assigned container container_1377618433102_0006_01_000015 of capacity <memory:1024, vCores:1> on host hadoop-8-3:42074, which currently has 8 containers, <memory:8192, vCores:8> used and <memory:0, vCores:8> available
2013-08-27 16:05:18,216 INFO org.apache.hadoop.yarn.server.resourcemanager.scheduler.capacity.LeafQueue: assignedContainer application=application_1377618433102_0006 container=Container: [ContainerId: container_1377618433102_0006_01_000015, NodeId: hadoop-8-3:42074, NodeHttpAddress: hadoop-8-3:8042, Resource: <memory:1024, vCores:1>, Priority: 20, State: NEW, Token: null, Status: container_id {, app_attempt_id {, application_id {, id: 6, cluster_timestamp: 1377618433102, }, attemptId: 1, }, id: 15, }, state: C_NEW, ] containerId=container_1377618433102_0006_01_000015 queue=default: capacity=1.0, absoluteCapacity=1.0, usedResources=<memory:48128, vCores:42>usedCapacity=0.9791667, absoluteUsedCapacity=0.9791667, numApps=5, numContainers=42 usedCapacity=0.9791667 absoluteUsedCapacity=0.9791667 used=<memory:48128, vCores:42> cluster=<memory:49152, vCores:96>
2013-08-27 16:05:18,216 INFO org.apache.hadoop.yarn.server.resourcemanager.scheduler.capacity.ParentQueue: Re-sorting queues since queue: root.default stats: default: capacity=1.0, absoluteCapacity=1.0, usedResources=<memory:49152, vCores:43>usedCapacity=1.0, absoluteUsedCapacity=1.0, numApps=5, numContainers=43
2013-08-27 16:05:18,217 INFO org.apache.hadoop.yarn.server.resourcemanager.scheduler.capacity.ParentQueue: assignedContainer queue=root usedCapacity=1.0 absoluteUsedCapacity=1.0 used=<memory:49152, vCores:43> cluster=<memory:49152, vCores:96>
2013-08-27 16:05:18,405 INFO org.apache.hadoop.yarn.server.resourcemanager.rmcontainer.RMContainerImpl: container_1377618433102_0006_01_000013 Container Transitioned from ALLOCATED to ACQUIRED
2013-08-27 16:05:18,406 INFO org.apache.hadoop.yarn.server.resourcemanager.rmcontainer.RMContainerImpl: container_1377618433102_0006_01_000014 Container Transitioned from ALLOCATED to ACQUIRED
2013-08-27 16:05:18,406 INFO org.apache.hadoop.yarn.server.resourcemanager.rmcontainer.RMContainerImpl: container_1377618433102_0006_01_000015 Container Transitioned from ALLOCATED to ACQUIRED
2013-08-27 16:05:18,912 INFO org.apache.hadoop.yarn.server.resourcemanager.rmcontainer.RMContainerImpl: container_1377618433102_0007_01_000031 Container Transitioned from RUNNING to COMPLETED
2013-08-27 16:05:18,912 INFO org.apache.hadoop.yarn.server.resourcemanager.scheduler.common.fica.FiCaSchedulerApp: Completed container: container_1377618433102_0007_01_000031 in state: COMPLETED event:FINISHED
2013-08-27 16:05:18,913 INFO org.apache.hadoop.yarn.server.resourcemanager.RMAuditLogger: USER=ubuntu	OPERATION=AM Released Container	TARGET=SchedulerApp	RESULT=SUCCESS	APPID=application_1377618433102_0007	CONTAINERID=container_1377618433102_0007_01_000031
2013-08-27 16:05:18,913 INFO org.apache.hadoop.yarn.server.resourcemanager.scheduler.common.fica.FiCaSchedulerNode: Released container container_1377618433102_0007_01_000031 of capacity <memory:1024, vCores:1> on host hadoop-8-2:41932, which currently has 6 containers, <memory:7168, vCores:6> used and <memory:1024, vCores:10> available, release resources=true
2013-08-27 16:05:18,913 INFO org.apache.hadoop.yarn.server.resourcemanager.scheduler.capacity.LeafQueue: default used=<memory:48128, vCores:42> numContainers=42 user=ubuntu user-resources=<memory:48128, vCores:42>
2013-08-27 16:05:18,914 INFO org.apache.hadoop.yarn.server.resourcemanager.scheduler.capacity.LeafQueue: completedContainer container=Container: [ContainerId: container_1377618433102_0007_01_000031, NodeId: hadoop-8-2:41932, NodeHttpAddress: hadoop-8-2:8042, Resource: <memory:1024, vCores:1>, Priority: 20, State: NEW, Token: null, Status: container_id {, app_attempt_id {, application_id {, id: 7, cluster_timestamp: 1377618433102, }, attemptId: 1, }, id: 31, }, state: C_COMPLETE, diagnostics: "Container killed by the ApplicationMaster.\n\n", exit_status: 143, ] resource=<memory:1024, vCores:1> queue=default: capacity=1.0, absoluteCapacity=1.0, usedResources=<memory:48128, vCores:42>usedCapacity=0.9791667, absoluteUsedCapacity=0.9791667, numApps=5, numContainers=42 usedCapacity=0.9791667 absoluteUsedCapacity=0.9791667 used=<memory:48128, vCores:42> cluster=<memory:49152, vCores:96>
2013-08-27 16:05:18,914 INFO org.apache.hadoop.yarn.server.resourcemanager.scheduler.capacity.ParentQueue: completedContainer queue=root usedCapacity=0.9791667 absoluteUsedCapacity=0.9791667 used=<memory:48128, vCores:42> cluster=<memory:49152, vCores:96>
2013-08-27 16:05:18,914 INFO org.apache.hadoop.yarn.server.resourcemanager.scheduler.capacity.CapacityScheduler: Application appattempt_1377618433102_0007_000001 released container container_1377618433102_0007_01_000031 on node: host: hadoop-8-2:41932 #containers=6 available=1024 used=7168 with event: FINISHED
2013-08-27 16:05:18,915 INFO org.apache.hadoop.yarn.server.resourcemanager.rmcontainer.RMContainerImpl: container_1377618433102_0006_01_000016 Container Transitioned from NEW to ALLOCATED
2013-08-27 16:05:18,915 INFO org.apache.hadoop.yarn.server.resourcemanager.RMAuditLogger: USER=ubuntu	OPERATION=AM Allocated Container	TARGET=SchedulerApp	RESULT=SUCCESS	APPID=application_1377618433102_0006	CONTAINERID=container_1377618433102_0006_01_000016
2013-08-27 16:05:18,915 INFO org.apache.hadoop.yarn.server.resourcemanager.scheduler.common.fica.FiCaSchedulerNode: Assigned container container_1377618433102_0006_01_000016 of capacity <memory:1024, vCores:1> on host hadoop-8-2:41932, which currently has 7 containers, <memory:8192, vCores:7> used and <memory:0, vCores:9> available
2013-08-27 16:05:18,916 INFO org.apache.hadoop.yarn.server.resourcemanager.scheduler.capacity.LeafQueue: assignedContainer application=application_1377618433102_0006 container=Container: [ContainerId: container_1377618433102_0006_01_000016, NodeId: hadoop-8-2:41932, NodeHttpAddress: hadoop-8-2:8042, Resource: <memory:1024, vCores:1>, Priority: 20, State: NEW, Token: null, Status: container_id {, app_attempt_id {, application_id {, id: 6, cluster_timestamp: 1377618433102, }, attemptId: 1, }, id: 16, }, state: C_NEW, ] containerId=container_1377618433102_0006_01_000016 queue=default: capacity=1.0, absoluteCapacity=1.0, usedResources=<memory:48128, vCores:42>usedCapacity=0.9791667, absoluteUsedCapacity=0.9791667, numApps=5, numContainers=42 usedCapacity=0.9791667 absoluteUsedCapacity=0.9791667 used=<memory:48128, vCores:42> cluster=<memory:49152, vCores:96>
2013-08-27 16:05:18,916 INFO org.apache.hadoop.yarn.server.resourcemanager.scheduler.capacity.ParentQueue: Re-sorting queues since queue: root.default stats: default: capacity=1.0, absoluteCapacity=1.0, usedResources=<memory:49152, vCores:43>usedCapacity=1.0, absoluteUsedCapacity=1.0, numApps=5, numContainers=43
2013-08-27 16:05:18,916 INFO org.apache.hadoop.yarn.server.resourcemanager.scheduler.capacity.ParentQueue: assignedContainer queue=root usedCapacity=1.0 absoluteUsedCapacity=1.0 used=<memory:49152, vCores:43> cluster=<memory:49152, vCores:96>
2013-08-27 16:05:18,951 INFO org.apache.hadoop.yarn.server.resourcemanager.rmcontainer.RMContainerImpl: container_1377618433102_0006_01_000013 Container Transitioned from ACQUIRED to RUNNING
2013-08-27 16:05:19,233 INFO org.apache.hadoop.yarn.server.resourcemanager.rmcontainer.RMContainerImpl: container_1377618433102_0006_01_000014 Container Transitioned from ACQUIRED to RUNNING
2013-08-27 16:05:19,243 INFO org.apache.hadoop.yarn.server.resourcemanager.rmcontainer.RMContainerImpl: container_1377618433102_0006_01_000015 Container Transitioned from ACQUIRED to RUNNING
2013-08-27 16:05:19,464 INFO org.apache.hadoop.yarn.server.resourcemanager.rmcontainer.RMContainerImpl: container_1377618433102_0006_01_000016 Container Transitioned from ALLOCATED to ACQUIRED
2013-08-27 16:05:19,920 INFO org.apache.hadoop.yarn.server.resourcemanager.rmcontainer.RMContainerImpl: container_1377618433102_0006_01_000016 Container Transitioned from ACQUIRED to RUNNING
2013-08-27 16:05:22,734 INFO org.apache.hadoop.yarn.server.resourcemanager.rmcontainer.RMContainerImpl: container_1377618433102_0007_01_000032 Container Transitioned from RUNNING to COMPLETED
2013-08-27 16:05:22,734 INFO org.apache.hadoop.yarn.server.resourcemanager.scheduler.common.fica.FiCaSchedulerApp: Completed container: container_1377618433102_0007_01_000032 in state: COMPLETED event:FINISHED
2013-08-27 16:05:22,734 INFO org.apache.hadoop.yarn.server.resourcemanager.RMAuditLogger: USER=ubuntu	OPERATION=AM Released Container	TARGET=SchedulerApp	RESULT=SUCCESS	APPID=application_1377618433102_0007	CONTAINERID=container_1377618433102_0007_01_000032
2013-08-27 16:05:22,734 INFO org.apache.hadoop.yarn.server.resourcemanager.scheduler.common.fica.FiCaSchedulerNode: Released container container_1377618433102_0007_01_000032 of capacity <memory:1024, vCores:1> on host hadoop-8-2:41932, which currently has 6 containers, <memory:7168, vCores:6> used and <memory:1024, vCores:10> available, release resources=true
2013-08-27 16:05:22,735 INFO org.apache.hadoop.yarn.server.resourcemanager.scheduler.capacity.LeafQueue: default used=<memory:48128, vCores:42> numContainers=42 user=ubuntu user-resources=<memory:48128, vCores:42>
2013-08-27 16:05:22,736 INFO org.apache.hadoop.yarn.server.resourcemanager.scheduler.capacity.LeafQueue: completedContainer container=Container: [ContainerId: container_1377618433102_0007_01_000032, NodeId: hadoop-8-2:41932, NodeHttpAddress: hadoop-8-2:8042, Resource: <memory:1024, vCores:1>, Priority: 20, State: NEW, Token: null, Status: container_id {, app_attempt_id {, application_id {, id: 7, cluster_timestamp: 1377618433102, }, attemptId: 1, }, id: 32, }, state: C_COMPLETE, diagnostics: "Container killed by the ApplicationMaster.\n\n", exit_status: 143, ] resource=<memory:1024, vCores:1> queue=default: capacity=1.0, absoluteCapacity=1.0, usedResources=<memory:48128, vCores:42>usedCapacity=0.9791667, absoluteUsedCapacity=0.9791667, numApps=5, numContainers=42 usedCapacity=0.9791667 absoluteUsedCapacity=0.9791667 used=<memory:48128, vCores:42> cluster=<memory:49152, vCores:96>
2013-08-27 16:05:22,736 INFO org.apache.hadoop.yarn.server.resourcemanager.scheduler.capacity.ParentQueue: completedContainer queue=root usedCapacity=0.9791667 absoluteUsedCapacity=0.9791667 used=<memory:48128, vCores:42> cluster=<memory:49152, vCores:96>
2013-08-27 16:05:22,736 INFO org.apache.hadoop.yarn.server.resourcemanager.scheduler.capacity.CapacityScheduler: Application appattempt_1377618433102_0007_000001 released container container_1377618433102_0007_01_000032 on node: host: hadoop-8-2:41932 #containers=6 available=1024 used=7168 with event: FINISHED
2013-08-27 16:05:22,737 INFO org.apache.hadoop.yarn.server.resourcemanager.rmcontainer.RMContainerImpl: container_1377618433102_0006_01_000017 Container Transitioned from NEW to ALLOCATED
2013-08-27 16:05:22,737 INFO org.apache.hadoop.yarn.server.resourcemanager.RMAuditLogger: USER=ubuntu	OPERATION=AM Allocated Container	TARGET=SchedulerApp	RESULT=SUCCESS	APPID=application_1377618433102_0006	CONTAINERID=container_1377618433102_0006_01_000017
2013-08-27 16:05:22,737 INFO org.apache.hadoop.yarn.server.resourcemanager.scheduler.common.fica.FiCaSchedulerNode: Assigned container container_1377618433102_0006_01_000017 of capacity <memory:1024, vCores:1> on host hadoop-8-2:41932, which currently has 7 containers, <memory:8192, vCores:7> used and <memory:0, vCores:9> available
2013-08-27 16:05:22,738 INFO org.apache.hadoop.yarn.server.resourcemanager.scheduler.capacity.LeafQueue: assignedContainer application=application_1377618433102_0006 container=Container: [ContainerId: container_1377618433102_0006_01_000017, NodeId: hadoop-8-2:41932, NodeHttpAddress: hadoop-8-2:8042, Resource: <memory:1024, vCores:1>, Priority: 20, State: NEW, Token: null, Status: container_id {, app_attempt_id {, application_id {, id: 6, cluster_timestamp: 1377618433102, }, attemptId: 1, }, id: 17, }, state: C_NEW, ] containerId=container_1377618433102_0006_01_000017 queue=default: capacity=1.0, absoluteCapacity=1.0, usedResources=<memory:48128, vCores:42>usedCapacity=0.9791667, absoluteUsedCapacity=0.9791667, numApps=5, numContainers=42 usedCapacity=0.9791667 absoluteUsedCapacity=0.9791667 used=<memory:48128, vCores:42> cluster=<memory:49152, vCores:96>
2013-08-27 16:05:22,738 INFO org.apache.hadoop.yarn.server.resourcemanager.scheduler.capacity.ParentQueue: Re-sorting queues since queue: root.default stats: default: capacity=1.0, absoluteCapacity=1.0, usedResources=<memory:49152, vCores:43>usedCapacity=1.0, absoluteUsedCapacity=1.0, numApps=5, numContainers=43
2013-08-27 16:05:22,739 INFO org.apache.hadoop.yarn.server.resourcemanager.scheduler.capacity.ParentQueue: assignedContainer queue=root usedCapacity=1.0 absoluteUsedCapacity=1.0 used=<memory:49152, vCores:43> cluster=<memory:49152, vCores:96>
2013-08-27 16:05:23,541 INFO org.apache.hadoop.yarn.server.resourcemanager.rmcontainer.RMContainerImpl: container_1377618433102_0006_01_000017 Container Transitioned from ALLOCATED to ACQUIRED
2013-08-27 16:05:23,746 INFO org.apache.hadoop.yarn.server.resourcemanager.rmcontainer.RMContainerImpl: container_1377618433102_0006_01_000017 Container Transitioned from ACQUIRED to RUNNING
2013-08-27 16:05:26,315 INFO org.apache.hadoop.yarn.server.resourcemanager.rmcontainer.RMContainerImpl: container_1377618433102_0007_01_000014 Container Transitioned from RUNNING to COMPLETED
2013-08-27 16:05:26,315 INFO org.apache.hadoop.yarn.server.resourcemanager.scheduler.common.fica.FiCaSchedulerApp: Completed container: container_1377618433102_0007_01_000014 in state: COMPLETED event:FINISHED
2013-08-27 16:05:26,315 INFO org.apache.hadoop.yarn.server.resourcemanager.RMAuditLogger: USER=ubuntu	OPERATION=AM Released Container	TARGET=SchedulerApp	RESULT=SUCCESS	APPID=application_1377618433102_0007	CONTAINERID=container_1377618433102_0007_01_000014
2013-08-27 16:05:26,316 INFO org.apache.hadoop.yarn.server.resourcemanager.scheduler.common.fica.FiCaSchedulerNode: Released container container_1377618433102_0007_01_000014 of capacity <memory:1024, vCores:1> on host hadoop-8-6:45732, which currently has 6 containers, <memory:7168, vCores:6> used and <memory:1024, vCores:10> available, release resources=true
2013-08-27 16:05:26,316 INFO org.apache.hadoop.yarn.server.resourcemanager.scheduler.capacity.LeafQueue: default used=<memory:48128, vCores:42> numContainers=42 user=ubuntu user-resources=<memory:48128, vCores:42>
2013-08-27 16:05:26,317 INFO org.apache.hadoop.yarn.server.resourcemanager.scheduler.capacity.LeafQueue: completedContainer container=Container: [ContainerId: container_1377618433102_0007_01_000014, NodeId: hadoop-8-6:45732, NodeHttpAddress: hadoop-8-6:8042, Resource: <memory:1024, vCores:1>, Priority: 20, State: NEW, Token: null, Status: container_id {, app_attempt_id {, application_id {, id: 7, cluster_timestamp: 1377618433102, }, attemptId: 1, }, id: 14, }, state: C_COMPLETE, diagnostics: "Container killed by the ApplicationMaster.\n\n", exit_status: 143, ] resource=<memory:1024, vCores:1> queue=default: capacity=1.0, absoluteCapacity=1.0, usedResources=<memory:48128, vCores:42>usedCapacity=0.9791667, absoluteUsedCapacity=0.9791667, numApps=5, numContainers=42 usedCapacity=0.9791667 absoluteUsedCapacity=0.9791667 used=<memory:48128, vCores:42> cluster=<memory:49152, vCores:96>
2013-08-27 16:05:26,317 INFO org.apache.hadoop.yarn.server.resourcemanager.scheduler.capacity.ParentQueue: completedContainer queue=root usedCapacity=0.9791667 absoluteUsedCapacity=0.9791667 used=<memory:48128, vCores:42> cluster=<memory:49152, vCores:96>
2013-08-27 16:05:26,317 INFO org.apache.hadoop.yarn.server.resourcemanager.scheduler.capacity.CapacityScheduler: Application appattempt_1377618433102_0007_000001 released container container_1377618433102_0007_01_000014 on node: host: hadoop-8-6:45732 #containers=6 available=1024 used=7168 with event: FINISHED
2013-08-27 16:05:26,318 INFO org.apache.hadoop.yarn.server.resourcemanager.rmcontainer.RMContainerImpl: container_1377618433102_0006_01_000018 Container Transitioned from NEW to ALLOCATED
2013-08-27 16:05:26,318 INFO org.apache.hadoop.yarn.server.resourcemanager.RMAuditLogger: USER=ubuntu	OPERATION=AM Allocated Container	TARGET=SchedulerApp	RESULT=SUCCESS	APPID=application_1377618433102_0006	CONTAINERID=container_1377618433102_0006_01_000018
2013-08-27 16:05:26,318 INFO org.apache.hadoop.yarn.server.resourcemanager.scheduler.common.fica.FiCaSchedulerNode: Assigned container container_1377618433102_0006_01_000018 of capacity <memory:1024, vCores:1> on host hadoop-8-6:45732, which currently has 7 containers, <memory:8192, vCores:7> used and <memory:0, vCores:9> available
2013-08-27 16:05:26,319 INFO org.apache.hadoop.yarn.server.resourcemanager.scheduler.capacity.LeafQueue: assignedContainer application=application_1377618433102_0006 container=Container: [ContainerId: container_1377618433102_0006_01_000018, NodeId: hadoop-8-6:45732, NodeHttpAddress: hadoop-8-6:8042, Resource: <memory:1024, vCores:1>, Priority: 20, State: NEW, Token: null, Status: container_id {, app_attempt_id {, application_id {, id: 6, cluster_timestamp: 1377618433102, }, attemptId: 1, }, id: 18, }, state: C_NEW, ] containerId=container_1377618433102_0006_01_000018 queue=default: capacity=1.0, absoluteCapacity=1.0, usedResources=<memory:48128, vCores:42>usedCapacity=0.9791667, absoluteUsedCapacity=0.9791667, numApps=5, numContainers=42 usedCapacity=0.9791667 absoluteUsedCapacity=0.9791667 used=<memory:48128, vCores:42> cluster=<memory:49152, vCores:96>
2013-08-27 16:05:26,319 INFO org.apache.hadoop.yarn.server.resourcemanager.scheduler.capacity.ParentQueue: Re-sorting queues since queue: root.default stats: default: capacity=1.0, absoluteCapacity=1.0, usedResources=<memory:49152, vCores:43>usedCapacity=1.0, absoluteUsedCapacity=1.0, numApps=5, numContainers=43
2013-08-27 16:05:26,320 INFO org.apache.hadoop.yarn.server.resourcemanager.scheduler.capacity.ParentQueue: assignedContainer queue=root usedCapacity=1.0 absoluteUsedCapacity=1.0 used=<memory:49152, vCores:43> cluster=<memory:49152, vCores:96>
2013-08-27 16:05:26,561 INFO org.apache.hadoop.yarn.server.resourcemanager.rmcontainer.RMContainerImpl: container_1377618433102_0006_01_000018 Container Transitioned from ALLOCATED to ACQUIRED
2013-08-27 16:05:27,200 INFO org.apache.hadoop.yarn.server.resourcemanager.rmcontainer.RMContainerImpl: container_1377618433102_0006_01_000002 Container Transitioned from RUNNING to COMPLETED
2013-08-27 16:05:27,201 INFO org.apache.hadoop.yarn.server.resourcemanager.scheduler.common.fica.FiCaSchedulerApp: Completed container: container_1377618433102_0006_01_000002 in state: COMPLETED event:FINISHED
2013-08-27 16:05:27,201 INFO org.apache.hadoop.yarn.server.resourcemanager.RMAuditLogger: USER=ubuntu	OPERATION=AM Released Container	TARGET=SchedulerApp	RESULT=SUCCESS	APPID=application_1377618433102_0006	CONTAINERID=container_1377618433102_0006_01_000002
2013-08-27 16:05:27,201 INFO org.apache.hadoop.yarn.server.resourcemanager.scheduler.common.fica.FiCaSchedulerNode: Released container container_1377618433102_0006_01_000002 of capacity <memory:1024, vCores:1> on host hadoop-8-7:53314, which currently has 6 containers, <memory:7168, vCores:6> used and <memory:1024, vCores:10> available, release resources=true
2013-08-27 16:05:27,201 INFO org.apache.hadoop.yarn.server.resourcemanager.scheduler.capacity.LeafQueue: default used=<memory:48128, vCores:42> numContainers=42 user=ubuntu user-resources=<memory:48128, vCores:42>
2013-08-27 16:05:27,202 INFO org.apache.hadoop.yarn.server.resourcemanager.scheduler.capacity.LeafQueue: completedContainer container=Container: [ContainerId: container_1377618433102_0006_01_000002, NodeId: hadoop-8-7:53314, NodeHttpAddress: hadoop-8-7:8042, Resource: <memory:1024, vCores:1>, Priority: 20, State: NEW, Token: null, Status: container_id {, app_attempt_id {, application_id {, id: 6, cluster_timestamp: 1377618433102, }, attemptId: 1, }, id: 2, }, state: C_COMPLETE, diagnostics: "Container killed by the ApplicationMaster.\n\n", exit_status: 143, ] resource=<memory:1024, vCores:1> queue=default: capacity=1.0, absoluteCapacity=1.0, usedResources=<memory:48128, vCores:42>usedCapacity=0.9791667, absoluteUsedCapacity=0.9791667, numApps=5, numContainers=42 usedCapacity=0.9791667 absoluteUsedCapacity=0.9791667 used=<memory:48128, vCores:42> cluster=<memory:49152, vCores:96>
2013-08-27 16:05:27,203 INFO org.apache.hadoop.yarn.server.resourcemanager.scheduler.capacity.ParentQueue: completedContainer queue=root usedCapacity=0.9791667 absoluteUsedCapacity=0.9791667 used=<memory:48128, vCores:42> cluster=<memory:49152, vCores:96>
2013-08-27 16:05:27,203 INFO org.apache.hadoop.yarn.server.resourcemanager.scheduler.capacity.CapacityScheduler: Application appattempt_1377618433102_0006_000001 released container container_1377618433102_0006_01_000002 on node: host: hadoop-8-7:53314 #containers=6 available=1024 used=7168 with event: FINISHED
2013-08-27 16:05:27,203 INFO org.apache.hadoop.yarn.server.resourcemanager.rmcontainer.RMContainerImpl: container_1377618433102_0006_01_000019 Container Transitioned from NEW to ALLOCATED
2013-08-27 16:05:27,203 INFO org.apache.hadoop.yarn.server.resourcemanager.RMAuditLogger: USER=ubuntu	OPERATION=AM Allocated Container	TARGET=SchedulerApp	RESULT=SUCCESS	APPID=application_1377618433102_0006	CONTAINERID=container_1377618433102_0006_01_000019
2013-08-27 16:05:27,204 INFO org.apache.hadoop.yarn.server.resourcemanager.scheduler.common.fica.FiCaSchedulerNode: Assigned container container_1377618433102_0006_01_000019 of capacity <memory:1024, vCores:1> on host hadoop-8-7:53314, which currently has 7 containers, <memory:8192, vCores:7> used and <memory:0, vCores:9> available
2013-08-27 16:05:27,204 INFO org.apache.hadoop.yarn.server.resourcemanager.scheduler.capacity.LeafQueue: assignedContainer application=application_1377618433102_0006 container=Container: [ContainerId: container_1377618433102_0006_01_000019, NodeId: hadoop-8-7:53314, NodeHttpAddress: hadoop-8-7:8042, Resource: <memory:1024, vCores:1>, Priority: 20, State: NEW, Token: null, Status: container_id {, app_attempt_id {, application_id {, id: 6, cluster_timestamp: 1377618433102, }, attemptId: 1, }, id: 19, }, state: C_NEW, ] containerId=container_1377618433102_0006_01_000019 queue=default: capacity=1.0, absoluteCapacity=1.0, usedResources=<memory:48128, vCores:42>usedCapacity=0.9791667, absoluteUsedCapacity=0.9791667, numApps=5, numContainers=42 usedCapacity=0.9791667 absoluteUsedCapacity=0.9791667 used=<memory:48128, vCores:42> cluster=<memory:49152, vCores:96>
2013-08-27 16:05:27,205 INFO org.apache.hadoop.yarn.server.resourcemanager.scheduler.capacity.ParentQueue: Re-sorting queues since queue: root.default stats: default: capacity=1.0, absoluteCapacity=1.0, usedResources=<memory:49152, vCores:43>usedCapacity=1.0, absoluteUsedCapacity=1.0, numApps=5, numContainers=43
2013-08-27 16:05:27,205 INFO org.apache.hadoop.yarn.server.resourcemanager.scheduler.capacity.ParentQueue: assignedContainer queue=root usedCapacity=1.0 absoluteUsedCapacity=1.0 used=<memory:49152, vCores:43> cluster=<memory:49152, vCores:96>
2013-08-27 16:05:27,325 INFO org.apache.hadoop.yarn.server.resourcemanager.rmcontainer.RMContainerImpl: container_1377618433102_0006_01_000018 Container Transitioned from ACQUIRED to RUNNING
2013-08-27 16:05:27,326 INFO org.apache.hadoop.yarn.server.resourcemanager.rmcontainer.RMContainerImpl: container_1377618433102_0007_01_000015 Container Transitioned from RUNNING to COMPLETED
2013-08-27 16:05:27,326 INFO org.apache.hadoop.yarn.server.resourcemanager.scheduler.common.fica.FiCaSchedulerApp: Completed container: container_1377618433102_0007_01_000015 in state: COMPLETED event:FINISHED
2013-08-27 16:05:27,326 INFO org.apache.hadoop.yarn.server.resourcemanager.RMAuditLogger: USER=ubuntu	OPERATION=AM Released Container	TARGET=SchedulerApp	RESULT=SUCCESS	APPID=application_1377618433102_0007	CONTAINERID=container_1377618433102_0007_01_000015
2013-08-27 16:05:27,326 INFO org.apache.hadoop.yarn.server.resourcemanager.scheduler.common.fica.FiCaSchedulerNode: Released container container_1377618433102_0007_01_000015 of capacity <memory:1024, vCores:1> on host hadoop-8-6:45732, which currently has 6 containers, <memory:7168, vCores:6> used and <memory:1024, vCores:10> available, release resources=true
2013-08-27 16:05:27,326 INFO org.apache.hadoop.yarn.server.resourcemanager.scheduler.capacity.LeafQueue: default used=<memory:48128, vCores:42> numContainers=42 user=ubuntu user-resources=<memory:48128, vCores:42>
2013-08-27 16:05:27,331 INFO org.apache.hadoop.yarn.server.resourcemanager.scheduler.capacity.LeafQueue: completedContainer container=Container: [ContainerId: container_1377618433102_0007_01_000015, NodeId: hadoop-8-6:45732, NodeHttpAddress: hadoop-8-6:8042, Resource: <memory:1024, vCores:1>, Priority: 20, State: NEW, Token: null, Status: container_id {, app_attempt_id {, application_id {, id: 7, cluster_timestamp: 1377618433102, }, attemptId: 1, }, id: 15, }, state: C_COMPLETE, diagnostics: "Container killed by the ApplicationMaster.\n\n", exit_status: 143, ] resource=<memory:1024, vCores:1> queue=default: capacity=1.0, absoluteCapacity=1.0, usedResources=<memory:48128, vCores:42>usedCapacity=0.9791667, absoluteUsedCapacity=0.9791667, numApps=5, numContainers=42 usedCapacity=0.9791667 absoluteUsedCapacity=0.9791667 used=<memory:48128, vCores:42> cluster=<memory:49152, vCores:96>
2013-08-27 16:05:27,331 INFO org.apache.hadoop.yarn.server.resourcemanager.scheduler.capacity.ParentQueue: completedContainer queue=root usedCapacity=0.9791667 absoluteUsedCapacity=0.9791667 used=<memory:48128, vCores:42> cluster=<memory:49152, vCores:96>
2013-08-27 16:05:27,331 INFO org.apache.hadoop.yarn.server.resourcemanager.scheduler.capacity.CapacityScheduler: Application appattempt_1377618433102_0007_000001 released container container_1377618433102_0007_01_000015 on node: host: hadoop-8-6:45732 #containers=6 available=1024 used=7168 with event: FINISHED
2013-08-27 16:05:27,332 INFO org.apache.hadoop.yarn.server.resourcemanager.rmcontainer.RMContainerImpl: container_1377618433102_0006_01_000020 Container Transitioned from NEW to ALLOCATED
2013-08-27 16:05:27,332 INFO org.apache.hadoop.yarn.server.resourcemanager.RMAuditLogger: USER=ubuntu	OPERATION=AM Allocated Container	TARGET=SchedulerApp	RESULT=SUCCESS	APPID=application_1377618433102_0006	CONTAINERID=container_1377618433102_0006_01_000020
2013-08-27 16:05:27,332 INFO org.apache.hadoop.yarn.server.resourcemanager.scheduler.common.fica.FiCaSchedulerNode: Assigned container container_1377618433102_0006_01_000020 of capacity <memory:1024, vCores:1> on host hadoop-8-6:45732, which currently has 7 containers, <memory:8192, vCores:7> used and <memory:0, vCores:9> available
2013-08-27 16:05:27,334 INFO org.apache.hadoop.yarn.server.resourcemanager.scheduler.capacity.LeafQueue: assignedContainer application=application_1377618433102_0006 container=Container: [ContainerId: container_1377618433102_0006_01_000020, NodeId: hadoop-8-6:45732, NodeHttpAddress: hadoop-8-6:8042, Resource: <memory:1024, vCores:1>, Priority: 20, State: NEW, Token: null, Status: container_id {, app_attempt_id {, application_id {, id: 6, cluster_timestamp: 1377618433102, }, attemptId: 1, }, id: 20, }, state: C_NEW, ] containerId=container_1377618433102_0006_01_000020 queue=default: capacity=1.0, absoluteCapacity=1.0, usedResources=<memory:48128, vCores:42>usedCapacity=0.9791667, absoluteUsedCapacity=0.9791667, numApps=5, numContainers=42 usedCapacity=0.9791667 absoluteUsedCapacity=0.9791667 used=<memory:48128, vCores:42> cluster=<memory:49152, vCores:96>
2013-08-27 16:05:27,334 INFO org.apache.hadoop.yarn.server.resourcemanager.scheduler.capacity.ParentQueue: Re-sorting queues since queue: root.default stats: default: capacity=1.0, absoluteCapacity=1.0, usedResources=<memory:49152, vCores:43>usedCapacity=1.0, absoluteUsedCapacity=1.0, numApps=5, numContainers=43
2013-08-27 16:05:27,334 INFO org.apache.hadoop.yarn.server.resourcemanager.scheduler.capacity.ParentQueue: assignedContainer queue=root usedCapacity=1.0 absoluteUsedCapacity=1.0 used=<memory:49152, vCores:43> cluster=<memory:49152, vCores:96>
2013-08-27 16:05:27,576 INFO org.apache.hadoop.yarn.server.resourcemanager.rmcontainer.RMContainerImpl: container_1377618433102_0006_01_000019 Container Transitioned from ALLOCATED to ACQUIRED
2013-08-27 16:05:27,578 INFO org.apache.hadoop.yarn.server.resourcemanager.rmcontainer.RMContainerImpl: container_1377618433102_0006_01_000020 Container Transitioned from ALLOCATED to ACQUIRED
2013-08-27 16:05:28,213 INFO org.apache.hadoop.yarn.server.resourcemanager.rmcontainer.RMContainerImpl: container_1377618433102_0006_01_000019 Container Transitioned from ACQUIRED to RUNNING
2013-08-27 16:05:28,337 INFO org.apache.hadoop.yarn.server.resourcemanager.rmcontainer.RMContainerImpl: container_1377618433102_0006_01_000020 Container Transitioned from ACQUIRED to RUNNING
2013-08-27 16:05:30,374 INFO org.apache.hadoop.yarn.server.resourcemanager.rmcontainer.RMContainerImpl: container_1377618433102_0007_01_000028 Container Transitioned from RUNNING to COMPLETED
2013-08-27 16:05:30,374 INFO org.apache.hadoop.yarn.server.resourcemanager.scheduler.common.fica.FiCaSchedulerApp: Completed container: container_1377618433102_0007_01_000028 in state: COMPLETED event:FINISHED
2013-08-27 16:05:30,374 INFO org.apache.hadoop.yarn.server.resourcemanager.RMAuditLogger: USER=ubuntu	OPERATION=AM Released Container	TARGET=SchedulerApp	RESULT=SUCCESS	APPID=application_1377618433102_0007	CONTAINERID=container_1377618433102_0007_01_000028
2013-08-27 16:05:30,374 INFO org.apache.hadoop.yarn.server.resourcemanager.scheduler.common.fica.FiCaSchedulerNode: Released container container_1377618433102_0007_01_000028 of capacity <memory:1024, vCores:1> on host hadoop-8-2:41932, which currently has 6 containers, <memory:7168, vCores:6> used and <memory:1024, vCores:10> available, release resources=true
2013-08-27 16:05:30,375 INFO org.apache.hadoop.yarn.server.resourcemanager.scheduler.capacity.LeafQueue: default used=<memory:48128, vCores:42> numContainers=42 user=ubuntu user-resources=<memory:48128, vCores:42>
2013-08-27 16:05:30,376 INFO org.apache.hadoop.yarn.server.resourcemanager.scheduler.capacity.LeafQueue: completedContainer container=Container: [ContainerId: container_1377618433102_0007_01_000028, NodeId: hadoop-8-2:41932, NodeHttpAddress: hadoop-8-2:8042, Resource: <memory:1024, vCores:1>, Priority: 20, State: NEW, Token: null, Status: container_id {, app_attempt_id {, application_id {, id: 7, cluster_timestamp: 1377618433102, }, attemptId: 1, }, id: 28, }, state: C_COMPLETE, diagnostics: "Container killed by the ApplicationMaster.\n", exit_status: 0, ] resource=<memory:1024, vCores:1> queue=default: capacity=1.0, absoluteCapacity=1.0, usedResources=<memory:48128, vCores:42>usedCapacity=0.9791667, absoluteUsedCapacity=0.9791667, numApps=5, numContainers=42 usedCapacity=0.9791667 absoluteUsedCapacity=0.9791667 used=<memory:48128, vCores:42> cluster=<memory:49152, vCores:96>
2013-08-27 16:05:30,376 INFO org.apache.hadoop.yarn.server.resourcemanager.scheduler.capacity.ParentQueue: completedContainer queue=root usedCapacity=0.9791667 absoluteUsedCapacity=0.9791667 used=<memory:48128, vCores:42> cluster=<memory:49152, vCores:96>
2013-08-27 16:05:30,376 INFO org.apache.hadoop.yarn.server.resourcemanager.scheduler.capacity.CapacityScheduler: Application appattempt_1377618433102_0007_000001 released container container_1377618433102_0007_01_000028 on node: host: hadoop-8-2:41932 #containers=6 available=1024 used=7168 with event: FINISHED
2013-08-27 16:05:30,377 INFO org.apache.hadoop.yarn.server.resourcemanager.rmcontainer.RMContainerImpl: container_1377618433102_0006_01_000021 Container Transitioned from NEW to ALLOCATED
2013-08-27 16:05:30,377 INFO org.apache.hadoop.yarn.server.resourcemanager.RMAuditLogger: USER=ubuntu	OPERATION=AM Allocated Container	TARGET=SchedulerApp	RESULT=SUCCESS	APPID=application_1377618433102_0006	CONTAINERID=container_1377618433102_0006_01_000021
2013-08-27 16:05:30,377 INFO org.apache.hadoop.yarn.server.resourcemanager.scheduler.common.fica.FiCaSchedulerNode: Assigned container container_1377618433102_0006_01_000021 of capacity <memory:1024, vCores:1> on host hadoop-8-2:41932, which currently has 7 containers, <memory:8192, vCores:7> used and <memory:0, vCores:9> available
2013-08-27 16:05:30,378 INFO org.apache.hadoop.yarn.server.resourcemanager.scheduler.capacity.LeafQueue: assignedContainer application=application_1377618433102_0006 container=Container: [ContainerId: container_1377618433102_0006_01_000021, NodeId: hadoop-8-2:41932, NodeHttpAddress: hadoop-8-2:8042, Resource: <memory:1024, vCores:1>, Priority: 20, State: NEW, Token: null, Status: container_id {, app_attempt_id {, application_id {, id: 6, cluster_timestamp: 1377618433102, }, attemptId: 1, }, id: 21, }, state: C_NEW, ] containerId=container_1377618433102_0006_01_000021 queue=default: capacity=1.0, absoluteCapacity=1.0, usedResources=<memory:48128, vCores:42>usedCapacity=0.9791667, absoluteUsedCapacity=0.9791667, numApps=5, numContainers=42 usedCapacity=0.9791667 absoluteUsedCapacity=0.9791667 used=<memory:48128, vCores:42> cluster=<memory:49152, vCores:96>
2013-08-27 16:05:30,379 INFO org.apache.hadoop.yarn.server.resourcemanager.scheduler.capacity.ParentQueue: Re-sorting queues since queue: root.default stats: default: capacity=1.0, absoluteCapacity=1.0, usedResources=<memory:49152, vCores:43>usedCapacity=1.0, absoluteUsedCapacity=1.0, numApps=5, numContainers=43
2013-08-27 16:05:30,379 INFO org.apache.hadoop.yarn.server.resourcemanager.scheduler.capacity.ParentQueue: assignedContainer queue=root usedCapacity=1.0 absoluteUsedCapacity=1.0 used=<memory:49152, vCores:43> cluster=<memory:49152, vCores:96>
2013-08-27 16:05:30,628 INFO org.apache.hadoop.yarn.server.resourcemanager.rmcontainer.RMContainerImpl: container_1377618433102_0006_01_000021 Container Transitioned from ALLOCATED to ACQUIRED
2013-08-27 16:05:30,904 INFO org.apache.hadoop.yarn.server.resourcemanager.rmcontainer.RMContainerImpl: container_1377618433102_0007_01_000016 Container Transitioned from RUNNING to COMPLETED
2013-08-27 16:05:30,904 INFO org.apache.hadoop.yarn.server.resourcemanager.scheduler.common.fica.FiCaSchedulerApp: Completed container: container_1377618433102_0007_01_000016 in state: COMPLETED event:FINISHED
2013-08-27 16:05:30,904 INFO org.apache.hadoop.yarn.server.resourcemanager.RMAuditLogger: USER=ubuntu	OPERATION=AM Released Container	TARGET=SchedulerApp	RESULT=SUCCESS	APPID=application_1377618433102_0007	CONTAINERID=container_1377618433102_0007_01_000016
2013-08-27 16:05:30,904 INFO org.apache.hadoop.yarn.server.resourcemanager.scheduler.common.fica.FiCaSchedulerNode: Released container container_1377618433102_0007_01_000016 of capacity <memory:1024, vCores:1> on host hadoop-8-6:45732, which currently has 6 containers, <memory:7168, vCores:6> used and <memory:1024, vCores:10> available, release resources=true
2013-08-27 16:05:30,904 INFO org.apache.hadoop.yarn.server.resourcemanager.scheduler.capacity.LeafQueue: default used=<memory:48128, vCores:42> numContainers=42 user=ubuntu user-resources=<memory:48128, vCores:42>
2013-08-27 16:05:30,906 INFO org.apache.hadoop.yarn.server.resourcemanager.scheduler.capacity.LeafQueue: completedContainer container=Container: [ContainerId: container_1377618433102_0007_01_000016, NodeId: hadoop-8-6:45732, NodeHttpAddress: hadoop-8-6:8042, Resource: <memory:1024, vCores:1>, Priority: 20, State: NEW, Token: null, Status: container_id {, app_attempt_id {, application_id {, id: 7, cluster_timestamp: 1377618433102, }, attemptId: 1, }, id: 16, }, state: C_COMPLETE, diagnostics: "Container killed by the ApplicationMaster.\n\n", exit_status: 143, ] resource=<memory:1024, vCores:1> queue=default: capacity=1.0, absoluteCapacity=1.0, usedResources=<memory:48128, vCores:42>usedCapacity=0.9791667, absoluteUsedCapacity=0.9791667, numApps=5, numContainers=42 usedCapacity=0.9791667 absoluteUsedCapacity=0.9791667 used=<memory:48128, vCores:42> cluster=<memory:49152, vCores:96>
2013-08-27 16:05:30,906 INFO org.apache.hadoop.yarn.server.resourcemanager.scheduler.capacity.ParentQueue: completedContainer queue=root usedCapacity=0.9791667 absoluteUsedCapacity=0.9791667 used=<memory:48128, vCores:42> cluster=<memory:49152, vCores:96>
2013-08-27 16:05:30,906 INFO org.apache.hadoop.yarn.server.resourcemanager.scheduler.capacity.CapacityScheduler: Application appattempt_1377618433102_0007_000001 released container container_1377618433102_0007_01_000016 on node: host: hadoop-8-6:45732 #containers=6 available=1024 used=7168 with event: FINISHED
2013-08-27 16:05:30,906 INFO org.apache.hadoop.yarn.server.resourcemanager.rmcontainer.RMContainerImpl: container_1377618433102_0006_01_000022 Container Transitioned from NEW to ALLOCATED
2013-08-27 16:05:30,907 INFO org.apache.hadoop.yarn.server.resourcemanager.RMAuditLogger: USER=ubuntu	OPERATION=AM Allocated Container	TARGET=SchedulerApp	RESULT=SUCCESS	APPID=application_1377618433102_0006	CONTAINERID=container_1377618433102_0006_01_000022
2013-08-27 16:05:30,907 INFO org.apache.hadoop.yarn.server.resourcemanager.scheduler.common.fica.FiCaSchedulerNode: Assigned container container_1377618433102_0006_01_000022 of capacity <memory:1024, vCores:1> on host hadoop-8-6:45732, which currently has 7 containers, <memory:8192, vCores:7> used and <memory:0, vCores:9> available
2013-08-27 16:05:30,909 INFO org.apache.hadoop.yarn.server.resourcemanager.scheduler.capacity.LeafQueue: assignedContainer application=application_1377618433102_0006 container=Container: [ContainerId: container_1377618433102_0006_01_000022, NodeId: hadoop-8-6:45732, NodeHttpAddress: hadoop-8-6:8042, Resource: <memory:1024, vCores:1>, Priority: 20, State: NEW, Token: null, Status: container_id {, app_attempt_id {, application_id {, id: 6, cluster_timestamp: 1377618433102, }, attemptId: 1, }, id: 22, }, state: C_NEW, ] containerId=container_1377618433102_0006_01_000022 queue=default: capacity=1.0, absoluteCapacity=1.0, usedResources=<memory:48128, vCores:42>usedCapacity=0.9791667, absoluteUsedCapacity=0.9791667, numApps=5, numContainers=42 usedCapacity=0.9791667 absoluteUsedCapacity=0.9791667 used=<memory:48128, vCores:42> cluster=<memory:49152, vCores:96>
2013-08-27 16:05:30,909 INFO org.apache.hadoop.yarn.server.resourcemanager.scheduler.capacity.ParentQueue: Re-sorting queues since queue: root.default stats: default: capacity=1.0, absoluteCapacity=1.0, usedResources=<memory:49152, vCores:43>usedCapacity=1.0, absoluteUsedCapacity=1.0, numApps=5, numContainers=43
2013-08-27 16:05:30,909 INFO org.apache.hadoop.yarn.server.resourcemanager.scheduler.capacity.ParentQueue: assignedContainer queue=root usedCapacity=1.0 absoluteUsedCapacity=1.0 used=<memory:49152, vCores:43> cluster=<memory:49152, vCores:96>
2013-08-27 16:05:30,909 INFO org.apache.hadoop.yarn.server.resourcemanager.rmcontainer.RMContainerImpl: container_1377618433102_0006_01_000004 Container Transitioned from RUNNING to COMPLETED
2013-08-27 16:05:30,910 INFO org.apache.hadoop.yarn.server.resourcemanager.scheduler.common.fica.FiCaSchedulerApp: Completed container: container_1377618433102_0006_01_000004 in state: COMPLETED event:FINISHED
2013-08-27 16:05:30,910 INFO org.apache.hadoop.yarn.server.resourcemanager.RMAuditLogger: USER=ubuntu	OPERATION=AM Released Container	TARGET=SchedulerApp	RESULT=SUCCESS	APPID=application_1377618433102_0006	CONTAINERID=container_1377618433102_0006_01_000004
2013-08-27 16:05:30,910 INFO org.apache.hadoop.yarn.server.resourcemanager.scheduler.common.fica.FiCaSchedulerNode: Released container container_1377618433102_0006_01_000004 of capacity <memory:1024, vCores:1> on host hadoop-8-7:53314, which currently has 6 containers, <memory:7168, vCores:6> used and <memory:1024, vCores:10> available, release resources=true
2013-08-27 16:05:30,910 INFO org.apache.hadoop.yarn.server.resourcemanager.scheduler.capacity.LeafQueue: default used=<memory:48128, vCores:42> numContainers=42 user=ubuntu user-resources=<memory:48128, vCores:42>
2013-08-27 16:05:30,911 INFO org.apache.hadoop.yarn.server.resourcemanager.scheduler.capacity.LeafQueue: completedContainer container=Container: [ContainerId: container_1377618433102_0006_01_000004, NodeId: hadoop-8-7:53314, NodeHttpAddress: hadoop-8-7:8042, Resource: <memory:1024, vCores:1>, Priority: 20, State: NEW, Token: null, Status: container_id {, app_attempt_id {, application_id {, id: 6, cluster_timestamp: 1377618433102, }, attemptId: 1, }, id: 4, }, state: C_COMPLETE, diagnostics: "Container killed by the ApplicationMaster.\n\n", exit_status: 143, ] resource=<memory:1024, vCores:1> queue=default: capacity=1.0, absoluteCapacity=1.0, usedResources=<memory:48128, vCores:42>usedCapacity=0.9791667, absoluteUsedCapacity=0.9791667, numApps=5, numContainers=42 usedCapacity=0.9791667 absoluteUsedCapacity=0.9791667 used=<memory:48128, vCores:42> cluster=<memory:49152, vCores:96>
2013-08-27 16:05:30,911 INFO org.apache.hadoop.yarn.server.resourcemanager.scheduler.capacity.ParentQueue: completedContainer queue=root usedCapacity=0.9791667 absoluteUsedCapacity=0.9791667 used=<memory:48128, vCores:42> cluster=<memory:49152, vCores:96>
2013-08-27 16:05:30,912 INFO org.apache.hadoop.yarn.server.resourcemanager.scheduler.capacity.CapacityScheduler: Application appattempt_1377618433102_0006_000001 released container container_1377618433102_0006_01_000004 on node: host: hadoop-8-7:53314 #containers=6 available=1024 used=7168 with event: FINISHED
2013-08-27 16:05:30,912 INFO org.apache.hadoop.yarn.server.resourcemanager.rmcontainer.RMContainerImpl: container_1377618433102_0006_01_000023 Container Transitioned from NEW to ALLOCATED
2013-08-27 16:05:30,912 INFO org.apache.hadoop.yarn.server.resourcemanager.RMAuditLogger: USER=ubuntu	OPERATION=AM Allocated Container	TARGET=SchedulerApp	RESULT=SUCCESS	APPID=application_1377618433102_0006	CONTAINERID=container_1377618433102_0006_01_000023
2013-08-27 16:05:30,912 INFO org.apache.hadoop.yarn.server.resourcemanager.scheduler.common.fica.FiCaSchedulerNode: Assigned container container_1377618433102_0006_01_000023 of capacity <memory:1024, vCores:1> on host hadoop-8-7:53314, which currently has 7 containers, <memory:8192, vCores:7> used and <memory:0, vCores:9> available
2013-08-27 16:05:30,913 INFO org.apache.hadoop.yarn.server.resourcemanager.scheduler.capacity.LeafQueue: assignedContainer application=application_1377618433102_0006 container=Container: [ContainerId: container_1377618433102_0006_01_000023, NodeId: hadoop-8-7:53314, NodeHttpAddress: hadoop-8-7:8042, Resource: <memory:1024, vCores:1>, Priority: 20, State: NEW, Token: null, Status: container_id {, app_attempt_id {, application_id {, id: 6, cluster_timestamp: 1377618433102, }, attemptId: 1, }, id: 23, }, state: C_NEW, ] containerId=container_1377618433102_0006_01_000023 queue=default: capacity=1.0, absoluteCapacity=1.0, usedResources=<memory:48128, vCores:42>usedCapacity=0.9791667, absoluteUsedCapacity=0.9791667, numApps=5, numContainers=42 usedCapacity=0.9791667 absoluteUsedCapacity=0.9791667 used=<memory:48128, vCores:42> cluster=<memory:49152, vCores:96>
2013-08-27 16:05:30,914 INFO org.apache.hadoop.yarn.server.resourcemanager.scheduler.capacity.ParentQueue: Re-sorting queues since queue: root.default stats: default: capacity=1.0, absoluteCapacity=1.0, usedResources=<memory:49152, vCores:43>usedCapacity=1.0, absoluteUsedCapacity=1.0, numApps=5, numContainers=43
2013-08-27 16:05:30,914 INFO org.apache.hadoop.yarn.server.resourcemanager.scheduler.capacity.ParentQueue: assignedContainer queue=root usedCapacity=1.0 absoluteUsedCapacity=1.0 used=<memory:49152, vCores:43> cluster=<memory:49152, vCores:96>
2013-08-27 16:05:31,343 INFO org.apache.hadoop.yarn.server.resourcemanager.rmcontainer.RMContainerImpl: container_1377618433102_0006_01_000009 Container Transitioned from RUNNING to COMPLETED
2013-08-27 16:05:31,343 INFO org.apache.hadoop.yarn.server.resourcemanager.scheduler.common.fica.FiCaSchedulerApp: Completed container: container_1377618433102_0006_01_000009 in state: COMPLETED event:FINISHED
2013-08-27 16:05:31,343 INFO org.apache.hadoop.yarn.server.resourcemanager.RMAuditLogger: USER=ubuntu	OPERATION=AM Released Container	TARGET=SchedulerApp	RESULT=SUCCESS	APPID=application_1377618433102_0006	CONTAINERID=container_1377618433102_0006_01_000009
2013-08-27 16:05:31,343 INFO org.apache.hadoop.yarn.server.resourcemanager.scheduler.common.fica.FiCaSchedulerNode: Released container container_1377618433102_0006_01_000009 of capacity <memory:1024, vCores:1> on host hadoop-8-5:56487, which currently has 6 containers, <memory:7168, vCores:6> used and <memory:1024, vCores:10> available, release resources=true
2013-08-27 16:05:31,343 INFO org.apache.hadoop.yarn.server.resourcemanager.scheduler.capacity.LeafQueue: default used=<memory:48128, vCores:42> numContainers=42 user=ubuntu user-resources=<memory:48128, vCores:42>
2013-08-27 16:05:31,345 INFO org.apache.hadoop.yarn.server.resourcemanager.scheduler.capacity.LeafQueue: completedContainer container=Container: [ContainerId: container_1377618433102_0006_01_000009, NodeId: hadoop-8-5:56487, NodeHttpAddress: hadoop-8-5:8042, Resource: <memory:1024, vCores:1>, Priority: 20, State: NEW, Token: null, Status: container_id {, app_attempt_id {, application_id {, id: 6, cluster_timestamp: 1377618433102, }, attemptId: 1, }, id: 9, }, state: C_COMPLETE, diagnostics: "Container killed by the ApplicationMaster.\n", exit_status: 0, ] resource=<memory:1024, vCores:1> queue=default: capacity=1.0, absoluteCapacity=1.0, usedResources=<memory:48128, vCores:42>usedCapacity=0.9791667, absoluteUsedCapacity=0.9791667, numApps=5, numContainers=42 usedCapacity=0.9791667 absoluteUsedCapacity=0.9791667 used=<memory:48128, vCores:42> cluster=<memory:49152, vCores:96>
2013-08-27 16:05:31,345 INFO org.apache.hadoop.yarn.server.resourcemanager.scheduler.capacity.ParentQueue: completedContainer queue=root usedCapacity=0.9791667 absoluteUsedCapacity=0.9791667 used=<memory:48128, vCores:42> cluster=<memory:49152, vCores:96>
2013-08-27 16:05:31,345 INFO org.apache.hadoop.yarn.server.resourcemanager.scheduler.capacity.CapacityScheduler: Application appattempt_1377618433102_0006_000001 released container container_1377618433102_0006_01_000009 on node: host: hadoop-8-5:56487 #containers=6 available=1024 used=7168 with event: FINISHED
2013-08-27 16:05:31,345 INFO org.apache.hadoop.yarn.server.resourcemanager.rmcontainer.RMContainerImpl: container_1377618433102_0006_01_000024 Container Transitioned from NEW to ALLOCATED
2013-08-27 16:05:31,345 INFO org.apache.hadoop.yarn.server.resourcemanager.RMAuditLogger: USER=ubuntu	OPERATION=AM Allocated Container	TARGET=SchedulerApp	RESULT=SUCCESS	APPID=application_1377618433102_0006	CONTAINERID=container_1377618433102_0006_01_000024
2013-08-27 16:05:31,346 INFO org.apache.hadoop.yarn.server.resourcemanager.scheduler.common.fica.FiCaSchedulerNode: Assigned container container_1377618433102_0006_01_000024 of capacity <memory:1024, vCores:1> on host hadoop-8-5:56487, which currently has 7 containers, <memory:8192, vCores:7> used and <memory:0, vCores:9> available
2013-08-27 16:05:31,347 INFO org.apache.hadoop.yarn.server.resourcemanager.scheduler.capacity.LeafQueue: assignedContainer application=application_1377618433102_0006 container=Container: [ContainerId: container_1377618433102_0006_01_000024, NodeId: hadoop-8-5:56487, NodeHttpAddress: hadoop-8-5:8042, Resource: <memory:1024, vCores:1>, Priority: 20, State: NEW, Token: null, Status: container_id {, app_attempt_id {, application_id {, id: 6, cluster_timestamp: 1377618433102, }, attemptId: 1, }, id: 24, }, state: C_NEW, ] containerId=container_1377618433102_0006_01_000024 queue=default: capacity=1.0, absoluteCapacity=1.0, usedResources=<memory:48128, vCores:42>usedCapacity=0.9791667, absoluteUsedCapacity=0.9791667, numApps=5, numContainers=42 usedCapacity=0.9791667 absoluteUsedCapacity=0.9791667 used=<memory:48128, vCores:42> cluster=<memory:49152, vCores:96>
2013-08-27 16:05:31,347 INFO org.apache.hadoop.yarn.server.resourcemanager.scheduler.capacity.ParentQueue: Re-sorting queues since queue: root.default stats: default: capacity=1.0, absoluteCapacity=1.0, usedResources=<memory:49152, vCores:43>usedCapacity=1.0, absoluteUsedCapacity=1.0, numApps=5, numContainers=43
2013-08-27 16:05:31,347 INFO org.apache.hadoop.yarn.server.resourcemanager.scheduler.capacity.ParentQueue: assignedContainer queue=root usedCapacity=1.0 absoluteUsedCapacity=1.0 used=<memory:49152, vCores:43> cluster=<memory:49152, vCores:96>
2013-08-27 16:05:31,380 INFO org.apache.hadoop.yarn.server.resourcemanager.rmcontainer.RMContainerImpl: container_1377618433102_0006_01_000021 Container Transitioned from ACQUIRED to RUNNING
2013-08-27 16:05:31,650 INFO org.apache.hadoop.yarn.server.resourcemanager.rmcontainer.RMContainerImpl: container_1377618433102_0006_01_000022 Container Transitioned from ALLOCATED to ACQUIRED
2013-08-27 16:05:31,652 INFO org.apache.hadoop.yarn.server.resourcemanager.rmcontainer.RMContainerImpl: container_1377618433102_0006_01_000023 Container Transitioned from ALLOCATED to ACQUIRED
2013-08-27 16:05:31,652 INFO org.apache.hadoop.yarn.server.resourcemanager.rmcontainer.RMContainerImpl: container_1377618433102_0006_01_000024 Container Transitioned from ALLOCATED to ACQUIRED
2013-08-27 16:05:31,914 INFO org.apache.hadoop.yarn.server.resourcemanager.rmcontainer.RMContainerImpl: container_1377618433102_0006_01_000022 Container Transitioned from ACQUIRED to RUNNING
2013-08-27 16:05:31,918 INFO org.apache.hadoop.yarn.server.resourcemanager.rmcontainer.RMContainerImpl: container_1377618433102_0006_01_000023 Container Transitioned from ACQUIRED to RUNNING
2013-08-27 16:05:32,349 INFO org.apache.hadoop.yarn.server.resourcemanager.rmcontainer.RMContainerImpl: container_1377618433102_0006_01_000024 Container Transitioned from ACQUIRED to RUNNING
2013-08-27 16:05:33,520 INFO org.apache.hadoop.yarn.server.resourcemanager.rmcontainer.RMContainerImpl: container_1377618433102_0006_01_000006 Container Transitioned from RUNNING to COMPLETED
2013-08-27 16:05:33,520 INFO org.apache.hadoop.yarn.server.resourcemanager.scheduler.common.fica.FiCaSchedulerApp: Completed container: container_1377618433102_0006_01_000006 in state: COMPLETED event:FINISHED
2013-08-27 16:05:33,520 INFO org.apache.hadoop.yarn.server.resourcemanager.RMAuditLogger: USER=ubuntu	OPERATION=AM Released Container	TARGET=SchedulerApp	RESULT=SUCCESS	APPID=application_1377618433102_0006	CONTAINERID=container_1377618433102_0006_01_000006
2013-08-27 16:05:33,521 INFO org.apache.hadoop.yarn.server.resourcemanager.scheduler.common.fica.FiCaSchedulerNode: Released container container_1377618433102_0006_01_000006 of capacity <memory:1024, vCores:1> on host hadoop-8-7:53314, which currently has 6 containers, <memory:7168, vCores:6> used and <memory:1024, vCores:10> available, release resources=true
2013-08-27 16:05:33,521 INFO org.apache.hadoop.yarn.server.resourcemanager.scheduler.capacity.LeafQueue: default used=<memory:48128, vCores:42> numContainers=42 user=ubuntu user-resources=<memory:48128, vCores:42>
2013-08-27 16:05:33,522 INFO org.apache.hadoop.yarn.server.resourcemanager.scheduler.capacity.LeafQueue: completedContainer container=Container: [ContainerId: container_1377618433102_0006_01_000006, NodeId: hadoop-8-7:53314, NodeHttpAddress: hadoop-8-7:8042, Resource: <memory:1024, vCores:1>, Priority: 20, State: NEW, Token: null, Status: container_id {, app_attempt_id {, application_id {, id: 6, cluster_timestamp: 1377618433102, }, attemptId: 1, }, id: 6, }, state: C_COMPLETE, diagnostics: "Container killed by the ApplicationMaster.\n\n", exit_status: 143, ] resource=<memory:1024, vCores:1> queue=default: capacity=1.0, absoluteCapacity=1.0, usedResources=<memory:48128, vCores:42>usedCapacity=0.9791667, absoluteUsedCapacity=0.9791667, numApps=5, numContainers=42 usedCapacity=0.9791667 absoluteUsedCapacity=0.9791667 used=<memory:48128, vCores:42> cluster=<memory:49152, vCores:96>
2013-08-27 16:05:33,522 INFO org.apache.hadoop.yarn.server.resourcemanager.scheduler.capacity.ParentQueue: completedContainer queue=root usedCapacity=0.9791667 absoluteUsedCapacity=0.9791667 used=<memory:48128, vCores:42> cluster=<memory:49152, vCores:96>
2013-08-27 16:05:33,522 INFO org.apache.hadoop.yarn.server.resourcemanager.scheduler.capacity.CapacityScheduler: Application appattempt_1377618433102_0006_000001 released container container_1377618433102_0006_01_000006 on node: host: hadoop-8-7:53314 #containers=6 available=1024 used=7168 with event: FINISHED
2013-08-27 16:05:33,523 INFO org.apache.hadoop.yarn.server.resourcemanager.rmcontainer.RMContainerImpl: container_1377618433102_0006_01_000025 Container Transitioned from NEW to ALLOCATED
2013-08-27 16:05:33,523 INFO org.apache.hadoop.yarn.server.resourcemanager.RMAuditLogger: USER=ubuntu	OPERATION=AM Allocated Container	TARGET=SchedulerApp	RESULT=SUCCESS	APPID=application_1377618433102_0006	CONTAINERID=container_1377618433102_0006_01_000025
2013-08-27 16:05:33,523 INFO org.apache.hadoop.yarn.server.resourcemanager.scheduler.common.fica.FiCaSchedulerNode: Assigned container container_1377618433102_0006_01_000025 of capacity <memory:1024, vCores:1> on host hadoop-8-7:53314, which currently has 7 containers, <memory:8192, vCores:7> used and <memory:0, vCores:9> available
2013-08-27 16:05:33,524 INFO org.apache.hadoop.yarn.server.resourcemanager.scheduler.capacity.LeafQueue: assignedContainer application=application_1377618433102_0006 container=Container: [ContainerId: container_1377618433102_0006_01_000025, NodeId: hadoop-8-7:53314, NodeHttpAddress: hadoop-8-7:8042, Resource: <memory:1024, vCores:1>, Priority: 10, State: NEW, Token: null, Status: container_id {, app_attempt_id {, application_id {, id: 6, cluster_timestamp: 1377618433102, }, attemptId: 1, }, id: 25, }, state: C_NEW, ] containerId=container_1377618433102_0006_01_000025 queue=default: capacity=1.0, absoluteCapacity=1.0, usedResources=<memory:48128, vCores:42>usedCapacity=0.9791667, absoluteUsedCapacity=0.9791667, numApps=5, numContainers=42 usedCapacity=0.9791667 absoluteUsedCapacity=0.9791667 used=<memory:48128, vCores:42> cluster=<memory:49152, vCores:96>
2013-08-27 16:05:33,525 INFO org.apache.hadoop.yarn.server.resourcemanager.scheduler.capacity.ParentQueue: Re-sorting queues since queue: root.default stats: default: capacity=1.0, absoluteCapacity=1.0, usedResources=<memory:49152, vCores:43>usedCapacity=1.0, absoluteUsedCapacity=1.0, numApps=5, numContainers=43
2013-08-27 16:05:33,525 INFO org.apache.hadoop.yarn.server.resourcemanager.scheduler.capacity.ParentQueue: assignedContainer queue=root usedCapacity=1.0 absoluteUsedCapacity=1.0 used=<memory:49152, vCores:43> cluster=<memory:49152, vCores:96>
2013-08-27 16:05:33,666 INFO org.apache.hadoop.yarn.server.resourcemanager.rmcontainer.RMContainerImpl: container_1377618433102_0006_01_000025 Container Transitioned from ALLOCATED to ACQUIRED
2013-08-27 16:05:34,526 INFO org.apache.hadoop.yarn.server.resourcemanager.rmcontainer.RMContainerImpl: container_1377618433102_0006_01_000025 Container Transitioned from ACQUIRED to RUNNING
2013-08-27 16:05:39,639 INFO org.apache.hadoop.yarn.server.resourcemanager.rmcontainer.RMContainerImpl: container_1377618433102_0006_01_000003 Container Transitioned from RUNNING to COMPLETED
2013-08-27 16:05:39,639 INFO org.apache.hadoop.yarn.server.resourcemanager.scheduler.common.fica.FiCaSchedulerApp: Completed container: container_1377618433102_0006_01_000003 in state: COMPLETED event:FINISHED
2013-08-27 16:05:39,639 INFO org.apache.hadoop.yarn.server.resourcemanager.RMAuditLogger: USER=ubuntu	OPERATION=AM Released Container	TARGET=SchedulerApp	RESULT=SUCCESS	APPID=application_1377618433102_0006	CONTAINERID=container_1377618433102_0006_01_000003
2013-08-27 16:05:39,640 INFO org.apache.hadoop.yarn.server.resourcemanager.scheduler.common.fica.FiCaSchedulerNode: Released container container_1377618433102_0006_01_000003 of capacity <memory:1024, vCores:1> on host hadoop-8-7:53314, which currently has 6 containers, <memory:7168, vCores:6> used and <memory:1024, vCores:10> available, release resources=true
2013-08-27 16:05:39,640 INFO org.apache.hadoop.yarn.server.resourcemanager.scheduler.capacity.LeafQueue: default used=<memory:48128, vCores:42> numContainers=42 user=ubuntu user-resources=<memory:48128, vCores:42>
2013-08-27 16:05:39,641 INFO org.apache.hadoop.yarn.server.resourcemanager.scheduler.capacity.LeafQueue: completedContainer container=Container: [ContainerId: container_1377618433102_0006_01_000003, NodeId: hadoop-8-7:53314, NodeHttpAddress: hadoop-8-7:8042, Resource: <memory:1024, vCores:1>, Priority: 20, State: NEW, Token: null, Status: container_id {, app_attempt_id {, application_id {, id: 6, cluster_timestamp: 1377618433102, }, attemptId: 1, }, id: 3, }, state: C_COMPLETE, diagnostics: "Container killed by the ApplicationMaster.\n\n", exit_status: 143, ] resource=<memory:1024, vCores:1> queue=default: capacity=1.0, absoluteCapacity=1.0, usedResources=<memory:48128, vCores:42>usedCapacity=0.9791667, absoluteUsedCapacity=0.9791667, numApps=5, numContainers=42 usedCapacity=0.9791667 absoluteUsedCapacity=0.9791667 used=<memory:48128, vCores:42> cluster=<memory:49152, vCores:96>
2013-08-27 16:05:39,641 INFO org.apache.hadoop.yarn.server.resourcemanager.scheduler.capacity.ParentQueue: completedContainer queue=root usedCapacity=0.9791667 absoluteUsedCapacity=0.9791667 used=<memory:48128, vCores:42> cluster=<memory:49152, vCores:96>
2013-08-27 16:05:39,641 INFO org.apache.hadoop.yarn.server.resourcemanager.scheduler.capacity.CapacityScheduler: Application appattempt_1377618433102_0006_000001 released container container_1377618433102_0006_01_000003 on node: host: hadoop-8-7:53314 #containers=6 available=1024 used=7168 with event: FINISHED
2013-08-27 16:05:39,642 INFO org.apache.hadoop.yarn.server.resourcemanager.rmcontainer.RMContainerImpl: container_1377618433102_0006_01_000026 Container Transitioned from NEW to ALLOCATED
2013-08-27 16:05:39,642 INFO org.apache.hadoop.yarn.server.resourcemanager.RMAuditLogger: USER=ubuntu	OPERATION=AM Allocated Container	TARGET=SchedulerApp	RESULT=SUCCESS	APPID=application_1377618433102_0006	CONTAINERID=container_1377618433102_0006_01_000026
2013-08-27 16:05:39,642 INFO org.apache.hadoop.yarn.server.resourcemanager.scheduler.common.fica.FiCaSchedulerNode: Assigned container container_1377618433102_0006_01_000026 of capacity <memory:1024, vCores:1> on host hadoop-8-7:53314, which currently has 7 containers, <memory:8192, vCores:7> used and <memory:0, vCores:9> available
2013-08-27 16:05:39,643 INFO org.apache.hadoop.yarn.server.resourcemanager.scheduler.capacity.LeafQueue: assignedContainer application=application_1377618433102_0006 container=Container: [ContainerId: container_1377618433102_0006_01_000026, NodeId: hadoop-8-7:53314, NodeHttpAddress: hadoop-8-7:8042, Resource: <memory:1024, vCores:1>, Priority: 10, State: NEW, Token: null, Status: container_id {, app_attempt_id {, application_id {, id: 6, cluster_timestamp: 1377618433102, }, attemptId: 1, }, id: 26, }, state: C_NEW, ] containerId=container_1377618433102_0006_01_000026 queue=default: capacity=1.0, absoluteCapacity=1.0, usedResources=<memory:48128, vCores:42>usedCapacity=0.9791667, absoluteUsedCapacity=0.9791667, numApps=5, numContainers=42 usedCapacity=0.9791667 absoluteUsedCapacity=0.9791667 used=<memory:48128, vCores:42> cluster=<memory:49152, vCores:96>
2013-08-27 16:05:39,643 INFO org.apache.hadoop.yarn.server.resourcemanager.scheduler.capacity.ParentQueue: Re-sorting queues since queue: root.default stats: default: capacity=1.0, absoluteCapacity=1.0, usedResources=<memory:49152, vCores:43>usedCapacity=1.0, absoluteUsedCapacity=1.0, numApps=5, numContainers=43
2013-08-27 16:05:39,643 INFO org.apache.hadoop.yarn.server.resourcemanager.scheduler.capacity.ParentQueue: assignedContainer queue=root usedCapacity=1.0 absoluteUsedCapacity=1.0 used=<memory:49152, vCores:43> cluster=<memory:49152, vCores:96>
2013-08-27 16:05:39,701 INFO org.apache.hadoop.yarn.server.resourcemanager.rmcontainer.RMContainerImpl: container_1377618433102_0006_01_000026 Container Transitioned from ALLOCATED to ACQUIRED
2013-08-27 16:05:40,650 INFO org.apache.hadoop.yarn.server.resourcemanager.rmcontainer.RMContainerImpl: container_1377618433102_0006_01_000026 Container Transitioned from ACQUIRED to RUNNING
2013-08-27 16:05:40,651 INFO org.apache.hadoop.yarn.server.resourcemanager.rmcontainer.RMContainerImpl: container_1377618433102_0006_01_000007 Container Transitioned from RUNNING to COMPLETED
2013-08-27 16:05:40,651 INFO org.apache.hadoop.yarn.server.resourcemanager.scheduler.common.fica.FiCaSchedulerApp: Completed container: container_1377618433102_0006_01_000007 in state: COMPLETED event:FINISHED
2013-08-27 16:05:40,651 INFO org.apache.hadoop.yarn.server.resourcemanager.RMAuditLogger: USER=ubuntu	OPERATION=AM Released Container	TARGET=SchedulerApp	RESULT=SUCCESS	APPID=application_1377618433102_0006	CONTAINERID=container_1377618433102_0006_01_000007
2013-08-27 16:05:40,651 INFO org.apache.hadoop.yarn.server.resourcemanager.scheduler.common.fica.FiCaSchedulerNode: Released container container_1377618433102_0006_01_000007 of capacity <memory:1024, vCores:1> on host hadoop-8-7:53314, which currently has 6 containers, <memory:7168, vCores:6> used and <memory:1024, vCores:10> available, release resources=true
2013-08-27 16:05:40,651 INFO org.apache.hadoop.yarn.server.resourcemanager.scheduler.capacity.LeafQueue: default used=<memory:48128, vCores:42> numContainers=42 user=ubuntu user-resources=<memory:48128, vCores:42>
2013-08-27 16:05:40,652 INFO org.apache.hadoop.yarn.server.resourcemanager.scheduler.capacity.LeafQueue: completedContainer container=Container: [ContainerId: container_1377618433102_0006_01_000007, NodeId: hadoop-8-7:53314, NodeHttpAddress: hadoop-8-7:8042, Resource: <memory:1024, vCores:1>, Priority: 20, State: NEW, Token: null, Status: container_id {, app_attempt_id {, application_id {, id: 6, cluster_timestamp: 1377618433102, }, attemptId: 1, }, id: 7, }, state: C_COMPLETE, diagnostics: "Container killed by the ApplicationMaster.\n\n", exit_status: 143, ] resource=<memory:1024, vCores:1> queue=default: capacity=1.0, absoluteCapacity=1.0, usedResources=<memory:48128, vCores:42>usedCapacity=0.9791667, absoluteUsedCapacity=0.9791667, numApps=5, numContainers=42 usedCapacity=0.9791667 absoluteUsedCapacity=0.9791667 used=<memory:48128, vCores:42> cluster=<memory:49152, vCores:96>
2013-08-27 16:05:40,652 INFO org.apache.hadoop.yarn.server.resourcemanager.scheduler.capacity.ParentQueue: completedContainer queue=root usedCapacity=0.9791667 absoluteUsedCapacity=0.9791667 used=<memory:48128, vCores:42> cluster=<memory:49152, vCores:96>
2013-08-27 16:05:40,653 INFO org.apache.hadoop.yarn.server.resourcemanager.scheduler.capacity.CapacityScheduler: Application appattempt_1377618433102_0006_000001 released container container_1377618433102_0006_01_000007 on node: host: hadoop-8-7:53314 #containers=6 available=1024 used=7168 with event: FINISHED
2013-08-27 16:05:40,653 INFO org.apache.hadoop.yarn.server.resourcemanager.rmcontainer.RMContainerImpl: container_1377618433102_0006_01_000027 Container Transitioned from NEW to ALLOCATED
2013-08-27 16:05:40,653 INFO org.apache.hadoop.yarn.server.resourcemanager.RMAuditLogger: USER=ubuntu	OPERATION=AM Allocated Container	TARGET=SchedulerApp	RESULT=SUCCESS	APPID=application_1377618433102_0006	CONTAINERID=container_1377618433102_0006_01_000027
2013-08-27 16:05:40,653 INFO org.apache.hadoop.yarn.server.resourcemanager.scheduler.common.fica.FiCaSchedulerNode: Assigned container container_1377618433102_0006_01_000027 of capacity <memory:1024, vCores:1> on host hadoop-8-7:53314, which currently has 7 containers, <memory:8192, vCores:7> used and <memory:0, vCores:9> available
2013-08-27 16:05:40,654 INFO org.apache.hadoop.yarn.server.resourcemanager.scheduler.capacity.LeafQueue: assignedContainer application=application_1377618433102_0006 container=Container: [ContainerId: container_1377618433102_0006_01_000027, NodeId: hadoop-8-7:53314, NodeHttpAddress: hadoop-8-7:8042, Resource: <memory:1024, vCores:1>, Priority: 20, State: NEW, Token: null, Status: container_id {, app_attempt_id {, application_id {, id: 6, cluster_timestamp: 1377618433102, }, attemptId: 1, }, id: 27, }, state: C_NEW, ] containerId=container_1377618433102_0006_01_000027 queue=default: capacity=1.0, absoluteCapacity=1.0, usedResources=<memory:48128, vCores:42>usedCapacity=0.9791667, absoluteUsedCapacity=0.9791667, numApps=5, numContainers=42 usedCapacity=0.9791667 absoluteUsedCapacity=0.9791667 used=<memory:48128, vCores:42> cluster=<memory:49152, vCores:96>
2013-08-27 16:05:40,654 INFO org.apache.hadoop.yarn.server.resourcemanager.scheduler.capacity.ParentQueue: Re-sorting queues since queue: root.default stats: default: capacity=1.0, absoluteCapacity=1.0, usedResources=<memory:49152, vCores:43>usedCapacity=1.0, absoluteUsedCapacity=1.0, numApps=5, numContainers=43
2013-08-27 16:05:40,654 INFO org.apache.hadoop.yarn.server.resourcemanager.scheduler.capacity.ParentQueue: assignedContainer queue=root usedCapacity=1.0 absoluteUsedCapacity=1.0 used=<memory:49152, vCores:43> cluster=<memory:49152, vCores:96>
2013-08-27 16:05:40,711 INFO org.apache.hadoop.yarn.server.resourcemanager.rmcontainer.RMContainerImpl: container_1377618433102_0006_01_000027 Container Transitioned from ALLOCATED to ACQUIRED
2013-08-27 16:05:41,075 INFO org.apache.hadoop.yarn.server.resourcemanager.rmcontainer.RMContainerImpl: container_1377618433102_0006_01_000014 Container Transitioned from RUNNING to COMPLETED
2013-08-27 16:05:41,076 INFO org.apache.hadoop.yarn.server.resourcemanager.scheduler.common.fica.FiCaSchedulerApp: Completed container: container_1377618433102_0006_01_000014 in state: COMPLETED event:FINISHED
2013-08-27 16:05:41,076 INFO org.apache.hadoop.yarn.server.resourcemanager.RMAuditLogger: USER=ubuntu	OPERATION=AM Released Container	TARGET=SchedulerApp	RESULT=SUCCESS	APPID=application_1377618433102_0006	CONTAINERID=container_1377618433102_0006_01_000014
2013-08-27 16:05:41,076 INFO org.apache.hadoop.yarn.server.resourcemanager.scheduler.common.fica.FiCaSchedulerNode: Released container container_1377618433102_0006_01_000014 of capacity <memory:1024, vCores:1> on host hadoop-8-6:45732, which currently has 6 containers, <memory:7168, vCores:6> used and <memory:1024, vCores:10> available, release resources=true
2013-08-27 16:05:41,076 INFO org.apache.hadoop.yarn.server.resourcemanager.scheduler.capacity.LeafQueue: default used=<memory:48128, vCores:42> numContainers=42 user=ubuntu user-resources=<memory:48128, vCores:42>
2013-08-27 16:05:41,077 INFO org.apache.hadoop.yarn.server.resourcemanager.scheduler.capacity.LeafQueue: completedContainer container=Container: [ContainerId: container_1377618433102_0006_01_000014, NodeId: hadoop-8-6:45732, NodeHttpAddress: hadoop-8-6:8042, Resource: <memory:1024, vCores:1>, Priority: 20, State: NEW, Token: null, Status: container_id {, app_attempt_id {, application_id {, id: 6, cluster_timestamp: 1377618433102, }, attemptId: 1, }, id: 14, }, state: C_COMPLETE, diagnostics: "Container killed by the ApplicationMaster.\n\n", exit_status: 143, ] resource=<memory:1024, vCores:1> queue=default: capacity=1.0, absoluteCapacity=1.0, usedResources=<memory:48128, vCores:42>usedCapacity=0.9791667, absoluteUsedCapacity=0.9791667, numApps=5, numContainers=42 usedCapacity=0.9791667 absoluteUsedCapacity=0.9791667 used=<memory:48128, vCores:42> cluster=<memory:49152, vCores:96>
2013-08-27 16:05:41,077 INFO org.apache.hadoop.yarn.server.resourcemanager.scheduler.capacity.ParentQueue: completedContainer queue=root usedCapacity=0.9791667 absoluteUsedCapacity=0.9791667 used=<memory:48128, vCores:42> cluster=<memory:49152, vCores:96>
2013-08-27 16:05:41,077 INFO org.apache.hadoop.yarn.server.resourcemanager.scheduler.capacity.CapacityScheduler: Application appattempt_1377618433102_0006_000001 released container container_1377618433102_0006_01_000014 on node: host: hadoop-8-6:45732 #containers=6 available=1024 used=7168 with event: FINISHED
2013-08-27 16:05:41,078 INFO org.apache.hadoop.yarn.server.resourcemanager.rmcontainer.RMContainerImpl: container_1377618433102_0006_01_000028 Container Transitioned from NEW to ALLOCATED
2013-08-27 16:05:41,078 INFO org.apache.hadoop.yarn.server.resourcemanager.RMAuditLogger: USER=ubuntu	OPERATION=AM Allocated Container	TARGET=SchedulerApp	RESULT=SUCCESS	APPID=application_1377618433102_0006	CONTAINERID=container_1377618433102_0006_01_000028
2013-08-27 16:05:41,078 INFO org.apache.hadoop.yarn.server.resourcemanager.scheduler.common.fica.FiCaSchedulerNode: Assigned container container_1377618433102_0006_01_000028 of capacity <memory:1024, vCores:1> on host hadoop-8-6:45732, which currently has 7 containers, <memory:8192, vCores:7> used and <memory:0, vCores:9> available
2013-08-27 16:05:41,079 INFO org.apache.hadoop.yarn.server.resourcemanager.scheduler.capacity.LeafQueue: assignedContainer application=application_1377618433102_0006 container=Container: [ContainerId: container_1377618433102_0006_01_000028, NodeId: hadoop-8-6:45732, NodeHttpAddress: hadoop-8-6:8042, Resource: <memory:1024, vCores:1>, Priority: 10, State: NEW, Token: null, Status: container_id {, app_attempt_id {, application_id {, id: 6, cluster_timestamp: 1377618433102, }, attemptId: 1, }, id: 28, }, state: C_NEW, ] containerId=container_1377618433102_0006_01_000028 queue=default: capacity=1.0, absoluteCapacity=1.0, usedResources=<memory:48128, vCores:42>usedCapacity=0.9791667, absoluteUsedCapacity=0.9791667, numApps=5, numContainers=42 usedCapacity=0.9791667 absoluteUsedCapacity=0.9791667 used=<memory:48128, vCores:42> cluster=<memory:49152, vCores:96>
2013-08-27 16:05:41,079 INFO org.apache.hadoop.yarn.server.resourcemanager.scheduler.capacity.ParentQueue: Re-sorting queues since queue: root.default stats: default: capacity=1.0, absoluteCapacity=1.0, usedResources=<memory:49152, vCores:43>usedCapacity=1.0, absoluteUsedCapacity=1.0, numApps=5, numContainers=43
2013-08-27 16:05:41,079 INFO org.apache.hadoop.yarn.server.resourcemanager.scheduler.capacity.ParentQueue: assignedContainer queue=root usedCapacity=1.0 absoluteUsedCapacity=1.0 used=<memory:49152, vCores:43> cluster=<memory:49152, vCores:96>
