2013-08-07 02:30:59,134 INFO org.apache.hadoop.yarn.server.resourcemanager.ResourceManager: STARTUP_MSG: 
/************************************************************
STARTUP_MSG: Starting ResourceManager
STARTUP_MSG:   host = hadoop-200-1/192.168.100.2
STARTUP_MSG:   args = []
STARTUP_MSG:   version = 3.0.0-SNAPSHOT
STARTUP_MSG:   build = https://github.com/lalithsuresh/hadoop-common -r 0cb423bd4868928bb06cd93f882bb0913172fd17; compiled by 'lsuresh' on 2013-04-08T15:47Z
STARTUP_MSG:   java = 1.7.0_17
************************************************************/
2013-08-07 02:30:59,149 INFO org.apache.hadoop.yarn.server.resourcemanager.ResourceManager: registered UNIX signal handlers for [TERM, HUP, INT]
2013-08-07 02:30:59,894 INFO org.apache.hadoop.yarn.server.resourcemanager.security.ApplicationTokenSecretManager: Rolling master-key for application-tokens
2013-08-07 02:30:59,936 INFO org.apache.hadoop.yarn.server.resourcemanager.security.RMContainerTokenSecretManager: ContainerTokenKeyRollingInterval: 86400000ms and ContainerTokenKeyActivationDelay: 900000ms
2013-08-07 02:30:59,941 INFO org.apache.hadoop.yarn.service.AbstractService: Service:Dispatcher is inited.
2013-08-07 02:30:59,944 INFO org.apache.hadoop.yarn.event.AsyncDispatcher: Registering class org.apache.hadoop.yarn.server.resourcemanager.recovery.RMStateStoreEventType for class org.apache.hadoop.yarn.server.resourcemanager.recovery.RMStateStore$ForwardingEventHandler
2013-08-07 02:30:59,944 INFO org.apache.hadoop.yarn.service.AbstractService: Service:Dispatcher is started.
2013-08-07 02:30:59,956 INFO org.apache.hadoop.yarn.event.AsyncDispatcher: Registering class org.apache.hadoop.yarn.server.resourcemanager.NodesListManagerEventType for class org.apache.hadoop.yarn.server.resourcemanager.NodesListManager
2013-08-07 02:30:59,957 INFO org.apache.hadoop.yarn.server.resourcemanager.ResourceManager: Using Scheduler: org.apache.hadoop.yarn.server.resourcemanager.scheduler.capacity.CapacityScheduler
2013-08-07 02:31:00,268 INFO org.apache.hadoop.yarn.event.AsyncDispatcher: Registering class org.apache.hadoop.yarn.server.resourcemanager.scheduler.event.SchedulerEventType for class org.apache.hadoop.yarn.server.resourcemanager.ResourceManager$SchedulerEventDispatcher
2013-08-07 02:31:00,271 INFO org.apache.hadoop.yarn.event.AsyncDispatcher: Registering class org.apache.hadoop.yarn.server.resourcemanager.rmapp.RMAppEventType for class org.apache.hadoop.yarn.server.resourcemanager.ResourceManager$ApplicationEventDispatcher
2013-08-07 02:31:00,274 INFO org.apache.hadoop.yarn.event.AsyncDispatcher: Registering class org.apache.hadoop.yarn.server.resourcemanager.rmapp.attempt.RMAppAttemptEventType for class org.apache.hadoop.yarn.server.resourcemanager.ResourceManager$ApplicationAttemptEventDispatcher
2013-08-07 02:31:00,277 INFO org.apache.hadoop.yarn.event.AsyncDispatcher: Registering class org.apache.hadoop.yarn.server.resourcemanager.rmnode.RMNodeEventType for class org.apache.hadoop.yarn.server.resourcemanager.ResourceManager$NodeEventDispatcher
2013-08-07 02:31:01,066 WARN org.apache.hadoop.util.NativeCodeLoader: Unable to load native-hadoop library for your platform... using builtin-java classes where applicable
2013-08-07 02:31:01,114 INFO org.apache.hadoop.yarn.server.resourcemanager.scheduler.capacity.ParentQueue: root, capacity=1.0, asboluteCapacity=1.0, maxCapacity=1.0, asboluteMaxCapacity=1.0, state=RUNNING, acls=SUBMIT_APPLICATIONS:*ADMINISTER_QUEUE:*
2013-08-07 02:31:01,114 INFO org.apache.hadoop.yarn.server.resourcemanager.scheduler.capacity.ParentQueue: Initialized parent-queue root name=root, fullname=root
2013-08-07 02:31:01,131 INFO org.apache.hadoop.yarn.server.resourcemanager.scheduler.capacity.LeafQueue: Initializing default
capacity = 1.0 [= (float) configuredCapacity / 100 ]
asboluteCapacity = 1.0 [= parentAbsoluteCapacity * capacity ]
maxCapacity = 1.0 [= configuredMaxCapacity ]
absoluteMaxCapacity = 1.0 [= 1.0 maximumCapacity undefined, (parentAbsoluteMaxCapacity * maximumCapacity) / 100 otherwise ]
userLimit = 100 [= configuredUserLimit ]
userLimitFactor = 1.0 [= configuredUserLimitFactor ]
maxApplications = 10000 [= configuredMaximumSystemApplicationsPerQueue or (int)(configuredMaximumSystemApplications * absoluteCapacity)]
maxApplicationsPerUser = 10000 [= (int)(maxApplications * (userLimit / 100.0f) * userLimitFactor) ]
maxActiveApplications = 1 [= max((int)ceil((clusterResourceMemory / minimumAllocation) * maxAMResourcePerQueuePercent * absoluteMaxCapacity),1) ]
maxActiveAppsUsingAbsCap = 1 [= max((int)ceil((clusterResourceMemory / minimumAllocation) *maxAMResourcePercent * absoluteCapacity),1) ]
maxActiveApplicationsPerUser = 1 [= max((int)(maxActiveApplications * (userLimit / 100.0f) * userLimitFactor),1) ]
usedCapacity = 0.0 [= usedResourcesMemory / (clusterResourceMemory * absoluteCapacity)]
absoluteUsedCapacity = 0.0 [= usedResourcesMemory / clusterResourceMemory]
maxAMResourcePerQueuePercent = 0.1 [= configuredMaximumAMResourcePercent ]
minimumAllocationFactor = 0.875 [= (float)(maximumAllocationMemory - minimumAllocationMemory) / maximumAllocationMemory ]
numContainers = 0 [= currentNumContainers ]
state = RUNNING [= configuredState ]
acls = SUBMIT_APPLICATIONS:*ADMINISTER_QUEUE:* [= configuredAcls ]

2013-08-07 02:31:01,131 INFO org.apache.hadoop.yarn.server.resourcemanager.scheduler.capacity.CapacityScheduler: Initialized queue: default: capacity=1.0, absoluteCapacity=1.0, usedResources=<memory:0, vCores:0>usedCapacity=0.0, absoluteUsedCapacity=0.0, numApps=0, numContainers=0
2013-08-07 02:31:01,131 INFO org.apache.hadoop.yarn.server.resourcemanager.scheduler.capacity.CapacityScheduler: Initialized queue: root: numChildQueue= 1, capacity=1.0, absoluteCapacity=1.0, usedResources=<memory:0, vCores:0>usedCapacity=0.0, numApps=0, numContainers=0
2013-08-07 02:31:01,131 INFO org.apache.hadoop.yarn.server.resourcemanager.scheduler.capacity.CapacityScheduler: Initialized root queue root: numChildQueue= 1, capacity=1.0, absoluteCapacity=1.0, usedResources=<memory:0, vCores:0>usedCapacity=0.0, numApps=0, numContainers=0
2013-08-07 02:31:01,132 INFO org.apache.hadoop.yarn.server.resourcemanager.scheduler.capacity.CapacityScheduler: Initialized CapacityScheduler with calculator=class org.apache.hadoop.yarn.server.resourcemanager.resource.DefaultResourceCalculator, minimumAllocation=<<memory:1024, vCores:1>>, maximumAllocation=<<memory:8192, vCores:32>>
2013-08-07 02:31:01,464 INFO org.apache.hadoop.yarn.event.AsyncDispatcher: Registering class org.apache.hadoop.yarn.server.resourcemanager.RMAppManagerEventType for class org.apache.hadoop.yarn.server.resourcemanager.RMAppManager
2013-08-07 02:31:01,484 INFO org.apache.hadoop.yarn.event.AsyncDispatcher: Registering class org.apache.hadoop.yarn.server.resourcemanager.amlauncher.AMLauncherEventType for class org.apache.hadoop.yarn.server.resourcemanager.amlauncher.ApplicationMasterLauncher
2013-08-07 02:31:01,566 INFO org.apache.hadoop.yarn.server.resourcemanager.RMNMInfo: Registered RMNMInfo MBean
2013-08-07 02:31:01,566 INFO org.apache.hadoop.yarn.service.AbstractService: Service:Dispatcher is inited.
2013-08-07 02:31:01,566 INFO org.apache.hadoop.yarn.service.AbstractService: Service:org.apache.hadoop.yarn.server.resourcemanager.rmcontainer.ContainerAllocationExpirer is inited.
2013-08-07 02:31:01,566 INFO org.apache.hadoop.yarn.service.AbstractService: Service:AMLivelinessMonitor is inited.
2013-08-07 02:31:01,567 INFO org.apache.hadoop.yarn.service.AbstractService: Service:AMLivelinessMonitor is inited.
2013-08-07 02:31:01,567 INFO org.apache.hadoop.yarn.service.AbstractService: Service:org.apache.hadoop.yarn.server.resourcemanager.security.DelegationTokenRenewer is inited.
2013-08-07 02:31:01,568 INFO org.apache.hadoop.util.HostsFileReader: Refreshing hosts (include/exclude) list
2013-08-07 02:31:01,568 INFO org.apache.hadoop.yarn.service.AbstractService: Service:org.apache.hadoop.yarn.server.resourcemanager.NodesListManager is inited.
2013-08-07 02:31:01,568 INFO org.apache.hadoop.yarn.service.AbstractService: Service:org.apache.hadoop.yarn.server.resourcemanager.ResourceManager$SchedulerEventDispatcher is inited.
2013-08-07 02:31:01,568 INFO org.apache.hadoop.yarn.service.AbstractService: Service:NMLivelinessMonitor is inited.
2013-08-07 02:31:01,575 INFO org.apache.hadoop.yarn.service.AbstractService: Service:org.apache.hadoop.yarn.server.resourcemanager.ResourceTrackerService is inited.
2013-08-07 02:31:01,575 INFO org.apache.hadoop.yarn.service.AbstractService: Service:org.apache.hadoop.yarn.server.resourcemanager.ApplicationMasterService is inited.
2013-08-07 02:31:01,575 INFO org.apache.hadoop.yarn.service.AbstractService: Service:org.apache.hadoop.yarn.server.resourcemanager.ClientRMService is inited.
2013-08-07 02:31:01,575 INFO org.apache.hadoop.yarn.service.AbstractService: Service:org.apache.hadoop.yarn.server.resourcemanager.AdminService is inited.
2013-08-07 02:31:01,576 INFO org.apache.hadoop.yarn.service.AbstractService: Service:org.apache.hadoop.yarn.server.resourcemanager.amlauncher.ApplicationMasterLauncher is inited.
2013-08-07 02:31:01,576 INFO org.apache.hadoop.yarn.service.AbstractService: Service:ResourceManager is inited.
2013-08-07 02:31:01,576 INFO org.apache.hadoop.yarn.server.resourcemanager.security.RMContainerTokenSecretManager: Rolling master-key for container-tokens
2013-08-07 02:31:01,576 INFO org.apache.hadoop.yarn.server.resourcemanager.security.ApplicationTokenSecretManager: Rolling master-key for application-tokens
2013-08-07 02:31:01,700 INFO org.mortbay.log: Logging to org.slf4j.impl.Log4jLoggerAdapter(org.mortbay.log) via org.mortbay.log.Slf4jLog
2013-08-07 02:31:01,782 INFO org.apache.hadoop.http.HttpServer: Added global filter 'safety' (class=org.apache.hadoop.http.HttpServer$QuotingInputFilter)
2013-08-07 02:31:01,786 INFO org.apache.hadoop.http.HttpServer: Added filter static_user_filter (class=org.apache.hadoop.http.lib.StaticUserWebFilter$StaticUserFilter) to context cluster
2013-08-07 02:31:01,786 INFO org.apache.hadoop.http.HttpServer: Added filter static_user_filter (class=org.apache.hadoop.http.lib.StaticUserWebFilter$StaticUserFilter) to context static
2013-08-07 02:31:01,786 INFO org.apache.hadoop.http.HttpServer: Added filter static_user_filter (class=org.apache.hadoop.http.lib.StaticUserWebFilter$StaticUserFilter) to context logs
2013-08-07 02:31:01,792 INFO org.apache.hadoop.http.HttpServer: adding path spec: /cluster
2013-08-07 02:31:01,792 INFO org.apache.hadoop.http.HttpServer: adding path spec: /cluster/*
2013-08-07 02:31:01,792 INFO org.apache.hadoop.http.HttpServer: adding path spec: /ws
2013-08-07 02:31:01,793 INFO org.apache.hadoop.http.HttpServer: adding path spec: /ws/*
2013-08-07 02:31:01,795 INFO org.apache.hadoop.http.HttpServer: Added global filter 'guice' (class=com.google.inject.servlet.GuiceFilter)
2013-08-07 02:31:01,802 INFO org.apache.hadoop.http.HttpServer: Jetty bound to port 8088
2013-08-07 02:31:01,803 INFO org.mortbay.log: jetty-6.1.26
2013-08-07 02:31:01,844 INFO org.mortbay.log: Extract jar:file:/home/ubuntu/hadoop-3.0.0-SNAPSHOT/share/hadoop/yarn/hadoop-yarn-common-3.0.0-SNAPSHOT.jar!/webapps/cluster to /tmp/Jetty_0_0_0_0_8088_cluster____u0rgz3/webapp
2013-08-07 02:31:02,226 INFO org.mortbay.log: Started SelectChannelConnector@0.0.0.0:8088
2013-08-07 02:31:02,226 INFO org.apache.hadoop.yarn.webapp.WebApps: Web app /cluster started at 8088
2013-08-07 02:31:03,130 INFO org.apache.hadoop.yarn.webapp.WebApps: Registered webapp guice modules
2013-08-07 02:31:03,226 INFO org.apache.hadoop.metrics2.impl.MetricsConfig: loaded properties from hadoop-metrics2.properties
2013-08-07 02:31:03,256 INFO org.apache.hadoop.metrics2.impl.MetricsSystemImpl: Scheduled snapshot period at 10 second(s).
2013-08-07 02:31:03,256 INFO org.apache.hadoop.metrics2.impl.MetricsSystemImpl: ResourceManager metrics system started
2013-08-07 02:31:03,269 INFO org.apache.hadoop.security.token.delegation.AbstractDelegationTokenSecretManager: Updating the current master key for generating delegation tokens
2013-08-07 02:31:03,272 INFO org.apache.hadoop.yarn.service.AbstractService: Service:Dispatcher is started.
2013-08-07 02:31:03,273 INFO org.apache.hadoop.security.token.delegation.AbstractDelegationTokenSecretManager: Starting expired delegation token remover thread, tokenRemoverScanInterval=60 min(s)
2013-08-07 02:31:03,273 INFO org.apache.hadoop.security.token.delegation.AbstractDelegationTokenSecretManager: Updating the current master key for generating delegation tokens
2013-08-07 02:31:03,274 INFO org.apache.hadoop.yarn.service.AbstractService: Service:org.apache.hadoop.yarn.server.resourcemanager.rmcontainer.ContainerAllocationExpirer is started.
2013-08-07 02:31:03,275 INFO org.apache.hadoop.yarn.service.AbstractService: Service:AMLivelinessMonitor is started.
2013-08-07 02:31:03,275 INFO org.apache.hadoop.yarn.service.AbstractService: Service:AMLivelinessMonitor is started.
2013-08-07 02:31:03,275 INFO org.apache.hadoop.yarn.service.AbstractService: Service:org.apache.hadoop.yarn.server.resourcemanager.security.DelegationTokenRenewer is started.
2013-08-07 02:31:03,276 INFO org.apache.hadoop.yarn.service.AbstractService: Service:org.apache.hadoop.yarn.server.resourcemanager.NodesListManager is started.
2013-08-07 02:31:03,277 INFO org.apache.hadoop.yarn.service.AbstractService: Service:org.apache.hadoop.yarn.server.resourcemanager.ResourceManager$SchedulerEventDispatcher is started.
2013-08-07 02:31:03,277 INFO org.apache.hadoop.yarn.service.AbstractService: Service:NMLivelinessMonitor is started.
2013-08-07 02:31:03,278 INFO org.apache.hadoop.yarn.service.AbstractService: Service:org.apache.hadoop.yarn.server.resourcemanager.ResourceTrackerService is started.
2013-08-07 02:31:03,342 INFO org.apache.hadoop.ipc.Server: Starting Socket Reader #1 for port 54110
2013-08-07 02:31:03,378 INFO org.apache.hadoop.yarn.factories.impl.pb.RpcServerFactoryPBImpl: Adding protocol org.apache.hadoop.yarn.server.api.ResourceTrackerPB to the server
2013-08-07 02:31:03,379 INFO org.apache.hadoop.ipc.Server: IPC Server Responder: starting
2013-08-07 02:31:03,381 INFO org.apache.hadoop.ipc.Server: IPC Server listener on 54110: starting
2013-08-07 02:31:03,507 INFO org.apache.hadoop.ipc.Server: Starting Socket Reader #1 for port 54112
2013-08-07 02:31:03,522 INFO org.apache.hadoop.yarn.factories.impl.pb.RpcServerFactoryPBImpl: Adding protocol org.apache.hadoop.yarn.api.AMRMProtocolPB to the server
2013-08-07 02:31:03,523 INFO org.apache.hadoop.ipc.Server: IPC Server Responder: starting
2013-08-07 02:31:03,525 INFO org.apache.hadoop.ipc.Server: IPC Server listener on 54112: starting
2013-08-07 02:31:03,547 INFO org.apache.hadoop.yarn.service.AbstractService: Service:org.apache.hadoop.yarn.server.resourcemanager.ApplicationMasterService is started.
2013-08-07 02:31:03,600 INFO org.apache.hadoop.ipc.Server: Starting Socket Reader #1 for port 54111
2013-08-07 02:31:03,606 INFO org.apache.hadoop.yarn.factories.impl.pb.RpcServerFactoryPBImpl: Adding protocol org.apache.hadoop.yarn.api.ClientRMProtocolPB to the server
2013-08-07 02:31:03,607 INFO org.apache.hadoop.ipc.Server: IPC Server Responder: starting
2013-08-07 02:31:03,608 INFO org.apache.hadoop.ipc.Server: IPC Server listener on 54111: starting
2013-08-07 02:31:03,663 INFO org.apache.hadoop.yarn.service.AbstractService: Service:org.apache.hadoop.yarn.server.resourcemanager.ClientRMService is started.
2013-08-07 02:31:03,697 INFO org.apache.hadoop.ipc.Server: Starting Socket Reader #1 for port 8033
2013-08-07 02:31:03,702 INFO org.apache.hadoop.yarn.factories.impl.pb.RpcServerFactoryPBImpl: Adding protocol org.apache.hadoop.yarn.api.RMAdminProtocolPB to the server
2013-08-07 02:31:03,703 INFO org.apache.hadoop.ipc.Server: IPC Server Responder: starting
2013-08-07 02:31:03,704 INFO org.apache.hadoop.ipc.Server: IPC Server listener on 8033: starting
2013-08-07 02:31:03,718 INFO org.apache.hadoop.yarn.service.AbstractService: Service:org.apache.hadoop.yarn.server.resourcemanager.AdminService is started.
2013-08-07 02:31:03,718 INFO org.apache.hadoop.yarn.service.AbstractService: Service:org.apache.hadoop.yarn.server.resourcemanager.amlauncher.ApplicationMasterLauncher is started.
2013-08-07 02:31:03,721 INFO org.apache.hadoop.yarn.service.AbstractService: Service:ResourceManager is started.
2013-08-07 02:31:13,396 INFO org.apache.hadoop.yarn.util.RackResolver: Resolved hadoop-200-2 to /default-rack
2013-08-07 02:31:13,396 INFO org.apache.hadoop.yarn.util.RackResolver: Resolved hadoop-200-5 to /default-rack
2013-08-07 02:31:13,408 INFO org.apache.hadoop.yarn.server.resourcemanager.ResourceTrackerService: NodeManager from node hadoop-200-5(cmPort: 38287 httpPort: 8042) registered with capability: <memory:8192, vCores:16>, assigned nodeId hadoop-200-5:38287
2013-08-07 02:31:13,408 INFO org.apache.hadoop.yarn.server.resourcemanager.ResourceTrackerService: NodeManager from node hadoop-200-2(cmPort: 33271 httpPort: 8042) registered with capability: <memory:8192, vCores:16>, assigned nodeId hadoop-200-2:33271
2013-08-07 02:31:13,433 INFO org.apache.hadoop.yarn.server.resourcemanager.rmnode.RMNodeImpl: hadoop-200-5:38287 Node Transitioned from NEW to RUNNING
2013-08-07 02:31:13,434 INFO org.apache.hadoop.yarn.server.resourcemanager.rmnode.RMNodeImpl: hadoop-200-2:33271 Node Transitioned from NEW to RUNNING
2013-08-07 02:31:13,444 INFO org.apache.hadoop.yarn.server.resourcemanager.scheduler.capacity.CapacityScheduler: Added node hadoop-200-5:38287 clusterResource: <memory:8192, vCores:16>
2013-08-07 02:31:13,444 INFO org.apache.hadoop.yarn.server.resourcemanager.scheduler.capacity.CapacityScheduler: Added node hadoop-200-2:33271 clusterResource: <memory:16384, vCores:32>
2013-08-07 02:31:13,515 INFO org.apache.hadoop.yarn.util.RackResolver: Resolved hadoop-200-3 to /default-rack
2013-08-07 02:31:13,516 INFO org.apache.hadoop.yarn.server.resourcemanager.ResourceTrackerService: NodeManager from node hadoop-200-3(cmPort: 34020 httpPort: 8042) registered with capability: <memory:8192, vCores:16>, assigned nodeId hadoop-200-3:34020
2013-08-07 02:31:13,516 INFO org.apache.hadoop.yarn.server.resourcemanager.rmnode.RMNodeImpl: hadoop-200-3:34020 Node Transitioned from NEW to RUNNING
2013-08-07 02:31:13,517 INFO org.apache.hadoop.yarn.server.resourcemanager.scheduler.capacity.CapacityScheduler: Added node hadoop-200-3:34020 clusterResource: <memory:24576, vCores:48>
2013-08-07 02:31:13,656 INFO org.apache.hadoop.yarn.util.RackResolver: Resolved hadoop-200-6 to /default-rack
2013-08-07 02:31:13,656 INFO org.apache.hadoop.yarn.server.resourcemanager.ResourceTrackerService: NodeManager from node hadoop-200-6(cmPort: 44827 httpPort: 8042) registered with capability: <memory:8192, vCores:16>, assigned nodeId hadoop-200-6:44827
2013-08-07 02:31:13,657 INFO org.apache.hadoop.yarn.server.resourcemanager.rmnode.RMNodeImpl: hadoop-200-6:44827 Node Transitioned from NEW to RUNNING
2013-08-07 02:31:13,658 INFO org.apache.hadoop.yarn.server.resourcemanager.scheduler.capacity.CapacityScheduler: Added node hadoop-200-6:44827 clusterResource: <memory:32768, vCores:64>
2013-08-07 02:31:13,722 INFO org.apache.hadoop.yarn.util.RackResolver: Resolved hadoop-200-7 to /default-rack
2013-08-07 02:31:13,722 INFO org.apache.hadoop.yarn.server.resourcemanager.ResourceTrackerService: NodeManager from node hadoop-200-7(cmPort: 59851 httpPort: 8042) registered with capability: <memory:8192, vCores:16>, assigned nodeId hadoop-200-7:59851
2013-08-07 02:31:13,724 INFO org.apache.hadoop.yarn.server.resourcemanager.rmnode.RMNodeImpl: hadoop-200-7:59851 Node Transitioned from NEW to RUNNING
2013-08-07 02:31:13,724 INFO org.apache.hadoop.yarn.server.resourcemanager.scheduler.capacity.CapacityScheduler: Added node hadoop-200-7:59851 clusterResource: <memory:40960, vCores:80>
2013-08-07 02:31:13,772 INFO org.apache.hadoop.yarn.util.RackResolver: Resolved hadoop-200-4 to /default-rack
2013-08-07 02:31:13,772 INFO org.apache.hadoop.yarn.server.resourcemanager.ResourceTrackerService: NodeManager from node hadoop-200-4(cmPort: 56924 httpPort: 8042) registered with capability: <memory:8192, vCores:16>, assigned nodeId hadoop-200-4:56924
2013-08-07 02:31:13,773 INFO org.apache.hadoop.yarn.server.resourcemanager.rmnode.RMNodeImpl: hadoop-200-4:56924 Node Transitioned from NEW to RUNNING
2013-08-07 02:31:13,774 INFO org.apache.hadoop.yarn.server.resourcemanager.scheduler.capacity.CapacityScheduler: Added node hadoop-200-4:56924 clusterResource: <memory:49152, vCores:96>
2013-08-07 02:31:19,326 INFO org.apache.hadoop.yarn.server.resourcemanager.ClientRMService: Allocated new applicationId: 1
2013-08-07 02:31:22,738 INFO org.apache.hadoop.yarn.server.resourcemanager.ClientRMService: Storing Application with id application_1375842659078_0001
2013-08-07 02:31:22,742 INFO org.apache.hadoop.yarn.server.resourcemanager.recovery.RMStateStore: Storing info for app: application_1375842659078_0001
2013-08-07 02:31:22,742 INFO org.apache.hadoop.yarn.server.resourcemanager.ClientRMService: Application with id 1 submitted by user ubuntu
2013-08-07 02:31:22,746 INFO org.apache.hadoop.yarn.server.resourcemanager.RMAuditLogger: USER=ubuntu	IP=192.168.100.2	OPERATION=Submit Application Request	TARGET=ClientRMService	RESULT=SUCCESS	APPID=application_1375842659078_0001
2013-08-07 02:31:22,794 INFO org.apache.hadoop.yarn.server.resourcemanager.rmapp.RMAppImpl: application_1375842659078_0001 State change from NEW to SUBMITTED
2013-08-07 02:31:22,796 INFO org.apache.hadoop.yarn.server.resourcemanager.ApplicationMasterService: Registering appattempt_1375842659078_0001_000001
2013-08-07 02:31:22,797 INFO org.apache.hadoop.yarn.server.resourcemanager.rmapp.attempt.RMAppAttemptImpl: appattempt_1375842659078_0001_000001 State change from NEW to SUBMITTED
2013-08-07 02:31:22,832 INFO org.apache.hadoop.yarn.server.resourcemanager.scheduler.capacity.LeafQueue: Application application_1375842659078_0001 from user: ubuntu activated in queue: default
2013-08-07 02:31:22,832 INFO org.apache.hadoop.yarn.server.resourcemanager.scheduler.capacity.LeafQueue: Application added - appId: application_1375842659078_0001 user: org.apache.hadoop.yarn.server.resourcemanager.scheduler.capacity.LeafQueue$User@593bf558, leaf-queue: default #user-pending-applications: 0 #user-active-applications: 1 #queue-pending-applications: 0 #queue-active-applications: 1
2013-08-07 02:31:22,833 INFO org.apache.hadoop.yarn.server.resourcemanager.scheduler.capacity.ParentQueue: Application added - appId: application_1375842659078_0001 user: ubuntu leaf-queue of parent: root #applications: 1
2013-08-07 02:31:22,833 INFO org.apache.hadoop.yarn.server.resourcemanager.scheduler.capacity.CapacityScheduler: Application Submission: appattempt_1375842659078_0001_000001, user: ubuntu queue: default: capacity=1.0, absoluteCapacity=1.0, usedResources=<memory:0, vCores:0>usedCapacity=0.0, absoluteUsedCapacity=0.0, numApps=1, numContainers=0, currently active: 1
2013-08-07 02:31:22,839 INFO org.apache.hadoop.yarn.server.resourcemanager.rmapp.attempt.RMAppAttemptImpl: appattempt_1375842659078_0001_000001 State change from SUBMITTED to SCHEDULED
2013-08-07 02:31:22,840 INFO org.apache.hadoop.yarn.server.resourcemanager.rmapp.RMAppImpl: application_1375842659078_0001 State change from SUBMITTED to ACCEPTED
2013-08-07 02:31:22,874 INFO org.apache.hadoop.yarn.server.resourcemanager.rmcontainer.RMContainerImpl: container_1375842659078_0001_01_000001 Container Transitioned from NEW to ALLOCATED
2013-08-07 02:31:22,874 INFO org.apache.hadoop.yarn.server.resourcemanager.RMAuditLogger: USER=ubuntu	OPERATION=AM Allocated Container	TARGET=SchedulerApp	RESULT=SUCCESS	APPID=application_1375842659078_0001	CONTAINERID=container_1375842659078_0001_01_000001
2013-08-07 02:31:22,875 INFO org.apache.hadoop.yarn.server.resourcemanager.scheduler.common.fica.FiCaSchedulerNode: Assigned container container_1375842659078_0001_01_000001 of capacity <memory:2048, vCores:1> on host hadoop-200-7:59851, which currently has 1 containers, <memory:2048, vCores:1> used and <memory:6144, vCores:15> available
2013-08-07 02:31:22,882 INFO org.apache.hadoop.yarn.server.resourcemanager.scheduler.capacity.LeafQueue: assignedContainer application=application_1375842659078_0001 container=Container: [ContainerId: container_1375842659078_0001_01_000001, NodeId: hadoop-200-7:59851, NodeHttpAddress: hadoop-200-7:8042, Resource: <memory:2048, vCores:1>, Priority: 0, State: NEW, Token: null, Status: container_id {, app_attempt_id {, application_id {, id: 1, cluster_timestamp: 1375842659078, }, attemptId: 1, }, id: 1, }, state: C_NEW, ] containerId=container_1375842659078_0001_01_000001 queue=default: capacity=1.0, absoluteCapacity=1.0, usedResources=<memory:0, vCores:0>usedCapacity=0.0, absoluteUsedCapacity=0.0, numApps=1, numContainers=0 usedCapacity=0.0 absoluteUsedCapacity=0.0 used=<memory:0, vCores:0> cluster=<memory:49152, vCores:96>
2013-08-07 02:31:22,882 INFO org.apache.hadoop.yarn.server.resourcemanager.scheduler.capacity.ParentQueue: Re-sorting queues since queue: root.default stats: default: capacity=1.0, absoluteCapacity=1.0, usedResources=<memory:2048, vCores:1>usedCapacity=0.041666668, absoluteUsedCapacity=0.041666668, numApps=1, numContainers=1
2013-08-07 02:31:22,883 INFO org.apache.hadoop.yarn.server.resourcemanager.scheduler.capacity.ParentQueue: assignedContainer queue=root usedCapacity=0.041666668 absoluteUsedCapacity=0.041666668 used=<memory:2048, vCores:1> cluster=<memory:49152, vCores:96>
2013-08-07 02:31:22,886 INFO org.apache.hadoop.yarn.server.resourcemanager.rmcontainer.RMContainerImpl: container_1375842659078_0001_01_000001 Container Transitioned from ALLOCATED to ACQUIRED
2013-08-07 02:31:22,896 INFO org.apache.hadoop.yarn.server.resourcemanager.rmapp.attempt.RMAppAttemptImpl: Storing attempt: AppId: application_1375842659078_0001 AttemptId: appattempt_1375842659078_0001_000001 MasterContainer: Container: [ContainerId: container_1375842659078_0001_01_000001, NodeId: hadoop-200-7:59851, NodeHttpAddress: hadoop-200-7:8042, Resource: <memory:2048, vCores:1>, Priority: 0, State: NEW, Token: null, Status: container_id {, app_attempt_id {, application_id {, id: 1, cluster_timestamp: 1375842659078, }, attemptId: 1, }, id: 1, }, state: C_NEW, ]
2013-08-07 02:31:22,899 INFO org.apache.hadoop.yarn.server.resourcemanager.rmapp.attempt.RMAppAttemptImpl: appattempt_1375842659078_0001_000001 State change from SCHEDULED to ALLOCATED_SAVING
2013-08-07 02:31:22,903 INFO org.apache.hadoop.yarn.server.resourcemanager.recovery.RMStateStore: Storing info for attempt: appattempt_1375842659078_0001_000001
2013-08-07 02:31:22,906 INFO org.apache.hadoop.yarn.server.resourcemanager.rmapp.attempt.RMAppAttemptImpl: appattempt_1375842659078_0001_000001 State change from ALLOCATED_SAVING to ALLOCATED
2013-08-07 02:31:22,914 INFO org.apache.hadoop.yarn.server.resourcemanager.amlauncher.AMLauncher: Launching masterappattempt_1375842659078_0001_000001
2013-08-07 02:31:22,967 INFO org.apache.hadoop.yarn.server.resourcemanager.amlauncher.AMLauncher: Setting up container Container: [ContainerId: container_1375842659078_0001_01_000001, NodeId: hadoop-200-7:59851, NodeHttpAddress: hadoop-200-7:8042, Resource: <memory:2048, vCores:1>, Priority: 0, State: NEW, Token: null, Status: container_id {, app_attempt_id {, application_id {, id: 1, cluster_timestamp: 1375842659078, }, attemptId: 1, }, id: 1, }, state: C_NEW, ] for AM appattempt_1375842659078_0001_000001
2013-08-07 02:31:22,967 INFO org.apache.hadoop.yarn.server.resourcemanager.amlauncher.AMLauncher: Command to launch container container_1375842659078_0001_01_000001 : $JAVA_HOME/bin/java -Dlog4j.configuration=container-log4j.properties -Dyarn.app.mapreduce.container.log.dir=<LOG_DIR> -Dyarn.app.mapreduce.container.log.filesize=0 -Dhadoop.root.logger=INFO,CLA  -Xmx1024m org.apache.hadoop.mapreduce.v2.app.MRAppMaster 1><LOG_DIR>/stdout 2><LOG_DIR>/stderr 
2013-08-07 02:31:23,924 INFO org.apache.hadoop.yarn.server.resourcemanager.amlauncher.AMLauncher: Done launching container Container: [ContainerId: container_1375842659078_0001_01_000001, NodeId: hadoop-200-7:59851, NodeHttpAddress: hadoop-200-7:8042, Resource: <memory:2048, vCores:1>, Priority: 0, State: NEW, Token: null, Status: container_id {, app_attempt_id {, application_id {, id: 1, cluster_timestamp: 1375842659078, }, attemptId: 1, }, id: 1, }, state: C_NEW, ] for AM appattempt_1375842659078_0001_000001
2013-08-07 02:31:23,925 INFO org.apache.hadoop.yarn.server.resourcemanager.rmapp.attempt.RMAppAttemptImpl: appattempt_1375842659078_0001_000001 State change from ALLOCATED to LAUNCHED
2013-08-07 02:31:24,896 INFO org.apache.hadoop.yarn.server.resourcemanager.rmcontainer.RMContainerImpl: container_1375842659078_0001_01_000001 Container Transitioned from ACQUIRED to RUNNING
2013-08-07 02:31:32,020 INFO org.apache.hadoop.yarn.server.resourcemanager.ApplicationMasterService: AM registration appattempt_1375842659078_0001_000001
2013-08-07 02:31:32,024 INFO org.apache.hadoop.yarn.server.resourcemanager.RMAuditLogger: USER=ubuntu	IP=192.168.100.9	OPERATION=Register App Master	TARGET=ApplicationMasterService	RESULT=SUCCESS	APPID=application_1375842659078_0001	APPATTEMPTID=appattempt_1375842659078_0001_000001
2013-08-07 02:31:32,030 INFO org.apache.hadoop.yarn.server.resourcemanager.rmapp.attempt.RMAppAttemptImpl: appattempt_1375842659078_0001_000001 State change from LAUNCHED to RUNNING
2013-08-07 02:31:32,030 INFO org.apache.hadoop.yarn.server.resourcemanager.rmapp.RMAppImpl: application_1375842659078_0001 State change from ACCEPTED to RUNNING
2013-08-07 02:31:33,624 INFO org.apache.hadoop.yarn.server.resourcemanager.rmcontainer.RMContainerImpl: container_1375842659078_0001_01_000002 Container Transitioned from NEW to ALLOCATED
2013-08-07 02:31:33,624 INFO org.apache.hadoop.yarn.server.resourcemanager.RMAuditLogger: USER=ubuntu	OPERATION=AM Allocated Container	TARGET=SchedulerApp	RESULT=SUCCESS	APPID=application_1375842659078_0001	CONTAINERID=container_1375842659078_0001_01_000002
2013-08-07 02:31:33,624 INFO org.apache.hadoop.yarn.server.resourcemanager.scheduler.common.fica.FiCaSchedulerNode: Assigned container container_1375842659078_0001_01_000002 of capacity <memory:1024, vCores:1> on host hadoop-200-5:38287, which currently has 1 containers, <memory:1024, vCores:1> used and <memory:7168, vCores:15> available
2013-08-07 02:31:33,626 INFO org.apache.hadoop.yarn.server.resourcemanager.scheduler.capacity.LeafQueue: assignedContainer application=application_1375842659078_0001 container=Container: [ContainerId: container_1375842659078_0001_01_000002, NodeId: hadoop-200-5:38287, NodeHttpAddress: hadoop-200-5:8042, Resource: <memory:1024, vCores:1>, Priority: 20, State: NEW, Token: null, Status: container_id {, app_attempt_id {, application_id {, id: 1, cluster_timestamp: 1375842659078, }, attemptId: 1, }, id: 2, }, state: C_NEW, ] containerId=container_1375842659078_0001_01_000002 queue=default: capacity=1.0, absoluteCapacity=1.0, usedResources=<memory:2048, vCores:1>usedCapacity=0.041666668, absoluteUsedCapacity=0.041666668, numApps=1, numContainers=1 usedCapacity=0.041666668 absoluteUsedCapacity=0.041666668 used=<memory:2048, vCores:1> cluster=<memory:49152, vCores:96>
2013-08-07 02:31:33,626 INFO org.apache.hadoop.yarn.server.resourcemanager.scheduler.capacity.ParentQueue: Re-sorting queues since queue: root.default stats: default: capacity=1.0, absoluteCapacity=1.0, usedResources=<memory:3072, vCores:2>usedCapacity=0.0625, absoluteUsedCapacity=0.0625, numApps=1, numContainers=2
2013-08-07 02:31:33,627 INFO org.apache.hadoop.yarn.server.resourcemanager.scheduler.capacity.ParentQueue: assignedContainer queue=root usedCapacity=0.0625 absoluteUsedCapacity=0.0625 used=<memory:3072, vCores:2> cluster=<memory:49152, vCores:96>
2013-08-07 02:31:33,631 INFO org.apache.hadoop.yarn.server.resourcemanager.rmcontainer.RMContainerImpl: container_1375842659078_0001_01_000003 Container Transitioned from NEW to ALLOCATED
2013-08-07 02:31:33,631 INFO org.apache.hadoop.yarn.server.resourcemanager.RMAuditLogger: USER=ubuntu	OPERATION=AM Allocated Container	TARGET=SchedulerApp	RESULT=SUCCESS	APPID=application_1375842659078_0001	CONTAINERID=container_1375842659078_0001_01_000003
2013-08-07 02:31:33,631 INFO org.apache.hadoop.yarn.server.resourcemanager.scheduler.common.fica.FiCaSchedulerNode: Assigned container container_1375842659078_0001_01_000003 of capacity <memory:1024, vCores:1> on host hadoop-200-2:33271, which currently has 1 containers, <memory:1024, vCores:1> used and <memory:7168, vCores:15> available
2013-08-07 02:31:33,633 INFO org.apache.hadoop.yarn.server.resourcemanager.scheduler.capacity.LeafQueue: assignedContainer application=application_1375842659078_0001 container=Container: [ContainerId: container_1375842659078_0001_01_000003, NodeId: hadoop-200-2:33271, NodeHttpAddress: hadoop-200-2:8042, Resource: <memory:1024, vCores:1>, Priority: 20, State: NEW, Token: null, Status: container_id {, app_attempt_id {, application_id {, id: 1, cluster_timestamp: 1375842659078, }, attemptId: 1, }, id: 3, }, state: C_NEW, ] containerId=container_1375842659078_0001_01_000003 queue=default: capacity=1.0, absoluteCapacity=1.0, usedResources=<memory:3072, vCores:2>usedCapacity=0.0625, absoluteUsedCapacity=0.0625, numApps=1, numContainers=2 usedCapacity=0.0625 absoluteUsedCapacity=0.0625 used=<memory:3072, vCores:2> cluster=<memory:49152, vCores:96>
2013-08-07 02:31:33,633 INFO org.apache.hadoop.yarn.server.resourcemanager.scheduler.capacity.ParentQueue: Re-sorting queues since queue: root.default stats: default: capacity=1.0, absoluteCapacity=1.0, usedResources=<memory:4096, vCores:3>usedCapacity=0.083333336, absoluteUsedCapacity=0.083333336, numApps=1, numContainers=3
2013-08-07 02:31:33,634 INFO org.apache.hadoop.yarn.server.resourcemanager.scheduler.capacity.ParentQueue: assignedContainer queue=root usedCapacity=0.083333336 absoluteUsedCapacity=0.083333336 used=<memory:4096, vCores:3> cluster=<memory:49152, vCores:96>
2013-08-07 02:31:34,097 INFO org.apache.hadoop.yarn.server.resourcemanager.rmcontainer.RMContainerImpl: container_1375842659078_0001_01_000002 Container Transitioned from ALLOCATED to ACQUIRED
2013-08-07 02:31:34,099 INFO org.apache.hadoop.yarn.server.resourcemanager.rmcontainer.RMContainerImpl: container_1375842659078_0001_01_000003 Container Transitioned from ALLOCATED to ACQUIRED
2013-08-07 02:31:35,135 INFO org.apache.hadoop.yarn.server.resourcemanager.scheduler.AppSchedulingInfo: checking for deactivate... 
2013-08-07 02:31:35,733 INFO org.apache.hadoop.yarn.server.resourcemanager.rmcontainer.RMContainerImpl: container_1375842659078_0001_01_000002 Container Transitioned from ACQUIRED to RUNNING
2013-08-07 02:31:35,743 INFO org.apache.hadoop.yarn.server.resourcemanager.rmcontainer.RMContainerImpl: container_1375842659078_0001_01_000003 Container Transitioned from ACQUIRED to RUNNING
2013-08-07 02:33:28,139 INFO org.apache.hadoop.yarn.server.resourcemanager.rmcontainer.RMContainerImpl: container_1375842659078_0001_01_000002 Container Transitioned from RUNNING to COMPLETED
2013-08-07 02:33:28,140 INFO org.apache.hadoop.yarn.server.resourcemanager.scheduler.common.fica.FiCaSchedulerApp: Completed container: container_1375842659078_0001_01_000002 in state: COMPLETED event:FINISHED
2013-08-07 02:33:28,140 INFO org.apache.hadoop.yarn.server.resourcemanager.RMAuditLogger: USER=ubuntu	OPERATION=AM Released Container	TARGET=SchedulerApp	RESULT=SUCCESS	APPID=application_1375842659078_0001	CONTAINERID=container_1375842659078_0001_01_000002
2013-08-07 02:33:28,140 INFO org.apache.hadoop.yarn.server.resourcemanager.scheduler.common.fica.FiCaSchedulerNode: Released container container_1375842659078_0001_01_000002 of capacity <memory:1024, vCores:1> on host hadoop-200-5:38287, which currently has 0 containers, <memory:0, vCores:0> used and <memory:8192, vCores:16> available, release resources=true
2013-08-07 02:33:28,140 INFO org.apache.hadoop.yarn.server.resourcemanager.scheduler.capacity.LeafQueue: default used=<memory:3072, vCores:2> numContainers=2 user=ubuntu user-resources=<memory:3072, vCores:2>
2013-08-07 02:33:28,143 INFO org.apache.hadoop.yarn.server.resourcemanager.scheduler.capacity.LeafQueue: completedContainer container=Container: [ContainerId: container_1375842659078_0001_01_000002, NodeId: hadoop-200-5:38287, NodeHttpAddress: hadoop-200-5:8042, Resource: <memory:1024, vCores:1>, Priority: 20, State: NEW, Token: null, Status: container_id {, app_attempt_id {, application_id {, id: 1, cluster_timestamp: 1375842659078, }, attemptId: 1, }, id: 2, }, state: C_COMPLETE, diagnostics: "Container killed by the ApplicationMaster.\n\n", exit_status: 143, ] resource=<memory:1024, vCores:1> queue=default: capacity=1.0, absoluteCapacity=1.0, usedResources=<memory:3072, vCores:2>usedCapacity=0.0625, absoluteUsedCapacity=0.0625, numApps=1, numContainers=2 usedCapacity=0.0625 absoluteUsedCapacity=0.0625 used=<memory:3072, vCores:2> cluster=<memory:49152, vCores:96>
2013-08-07 02:33:28,143 INFO org.apache.hadoop.yarn.server.resourcemanager.scheduler.capacity.ParentQueue: completedContainer queue=root usedCapacity=0.0625 absoluteUsedCapacity=0.0625 used=<memory:3072, vCores:2> cluster=<memory:49152, vCores:96>
2013-08-07 02:33:28,143 INFO org.apache.hadoop.yarn.server.resourcemanager.scheduler.capacity.CapacityScheduler: Application appattempt_1375842659078_0001_000001 released container container_1375842659078_0001_01_000002 on node: host: hadoop-200-5:38287 #containers=0 available=8192 used=0 with event: FINISHED
2013-08-07 02:33:31,021 INFO org.apache.hadoop.yarn.server.resourcemanager.rmcontainer.RMContainerImpl: container_1375842659078_0001_01_000003 Container Transitioned from RUNNING to COMPLETED
2013-08-07 02:33:31,021 INFO org.apache.hadoop.yarn.server.resourcemanager.scheduler.common.fica.FiCaSchedulerApp: Completed container: container_1375842659078_0001_01_000003 in state: COMPLETED event:FINISHED
2013-08-07 02:33:31,022 INFO org.apache.hadoop.yarn.server.resourcemanager.RMAuditLogger: USER=ubuntu	OPERATION=AM Released Container	TARGET=SchedulerApp	RESULT=SUCCESS	APPID=application_1375842659078_0001	CONTAINERID=container_1375842659078_0001_01_000003
2013-08-07 02:33:31,022 INFO org.apache.hadoop.yarn.server.resourcemanager.scheduler.common.fica.FiCaSchedulerNode: Released container container_1375842659078_0001_01_000003 of capacity <memory:1024, vCores:1> on host hadoop-200-2:33271, which currently has 0 containers, <memory:0, vCores:0> used and <memory:8192, vCores:16> available, release resources=true
2013-08-07 02:33:31,022 INFO org.apache.hadoop.yarn.server.resourcemanager.scheduler.capacity.LeafQueue: default used=<memory:2048, vCores:1> numContainers=1 user=ubuntu user-resources=<memory:2048, vCores:1>
2013-08-07 02:33:31,024 INFO org.apache.hadoop.yarn.server.resourcemanager.scheduler.capacity.LeafQueue: completedContainer container=Container: [ContainerId: container_1375842659078_0001_01_000003, NodeId: hadoop-200-2:33271, NodeHttpAddress: hadoop-200-2:8042, Resource: <memory:1024, vCores:1>, Priority: 20, State: NEW, Token: null, Status: container_id {, app_attempt_id {, application_id {, id: 1, cluster_timestamp: 1375842659078, }, attemptId: 1, }, id: 3, }, state: C_COMPLETE, diagnostics: "Container killed by the ApplicationMaster.\n\n", exit_status: 143, ] resource=<memory:1024, vCores:1> queue=default: capacity=1.0, absoluteCapacity=1.0, usedResources=<memory:2048, vCores:1>usedCapacity=0.041666668, absoluteUsedCapacity=0.041666668, numApps=1, numContainers=1 usedCapacity=0.041666668 absoluteUsedCapacity=0.041666668 used=<memory:2048, vCores:1> cluster=<memory:49152, vCores:96>
2013-08-07 02:33:31,024 INFO org.apache.hadoop.yarn.server.resourcemanager.scheduler.capacity.ParentQueue: completedContainer queue=root usedCapacity=0.041666668 absoluteUsedCapacity=0.041666668 used=<memory:2048, vCores:1> cluster=<memory:49152, vCores:96>
2013-08-07 02:33:31,024 INFO org.apache.hadoop.yarn.server.resourcemanager.scheduler.capacity.CapacityScheduler: Application appattempt_1375842659078_0001_000001 released container container_1375842659078_0001_01_000003 on node: host: hadoop-200-2:33271 #containers=0 available=8192 used=0 with event: FINISHED
2013-08-07 02:33:35,172 INFO org.apache.hadoop.yarn.server.resourcemanager.rmapp.attempt.RMAppAttemptImpl: appattempt_1375842659078_0001_000001 State change from RUNNING to FINISHING
2013-08-07 02:33:35,174 INFO org.apache.hadoop.yarn.server.resourcemanager.rmapp.RMAppImpl: application_1375842659078_0001 State change from RUNNING to FINISHING
2013-08-07 02:33:35,806 INFO org.apache.hadoop.yarn.server.resourcemanager.rmcontainer.RMContainerImpl: container_1375842659078_0001_01_000001 Container Transitioned from RUNNING to COMPLETED
2013-08-07 02:33:35,806 INFO org.apache.hadoop.yarn.server.resourcemanager.scheduler.common.fica.FiCaSchedulerApp: Completed container: container_1375842659078_0001_01_000001 in state: COMPLETED event:FINISHED
2013-08-07 02:33:35,806 INFO org.apache.hadoop.yarn.server.resourcemanager.RMAuditLogger: USER=ubuntu	OPERATION=AM Released Container	TARGET=SchedulerApp	RESULT=SUCCESS	APPID=application_1375842659078_0001	CONTAINERID=container_1375842659078_0001_01_000001
2013-08-07 02:33:35,806 INFO org.apache.hadoop.yarn.server.resourcemanager.scheduler.common.fica.FiCaSchedulerNode: Released container container_1375842659078_0001_01_000001 of capacity <memory:2048, vCores:1> on host hadoop-200-7:59851, which currently has 0 containers, <memory:0, vCores:0> used and <memory:8192, vCores:16> available, release resources=true
2013-08-07 02:33:35,807 INFO org.apache.hadoop.yarn.server.resourcemanager.scheduler.capacity.LeafQueue: default used=<memory:0, vCores:0> numContainers=0 user=ubuntu user-resources=<memory:0, vCores:0>
2013-08-07 02:33:35,809 INFO org.apache.hadoop.yarn.server.resourcemanager.scheduler.capacity.LeafQueue: completedContainer container=Container: [ContainerId: container_1375842659078_0001_01_000001, NodeId: hadoop-200-7:59851, NodeHttpAddress: hadoop-200-7:8042, Resource: <memory:2048, vCores:1>, Priority: 0, State: NEW, Token: null, Status: container_id {, app_attempt_id {, application_id {, id: 1, cluster_timestamp: 1375842659078, }, attemptId: 1, }, id: 1, }, state: C_COMPLETE, diagnostics: "", exit_status: 0, ] resource=<memory:2048, vCores:1> queue=default: capacity=1.0, absoluteCapacity=1.0, usedResources=<memory:0, vCores:0>usedCapacity=0.0, absoluteUsedCapacity=0.0, numApps=1, numContainers=0 usedCapacity=0.0 absoluteUsedCapacity=0.0 used=<memory:0, vCores:0> cluster=<memory:49152, vCores:96>
2013-08-07 02:33:35,809 INFO org.apache.hadoop.yarn.server.resourcemanager.scheduler.capacity.ParentQueue: completedContainer queue=root usedCapacity=0.0 absoluteUsedCapacity=0.0 used=<memory:0, vCores:0> cluster=<memory:49152, vCores:96>
2013-08-07 02:33:35,809 INFO org.apache.hadoop.yarn.server.resourcemanager.rmapp.attempt.RMAppAttemptImpl: appattempt_1375842659078_0001_000001 State change from FINISHING to FINISHED
2013-08-07 02:33:35,813 INFO org.apache.hadoop.yarn.server.resourcemanager.scheduler.capacity.CapacityScheduler: Application appattempt_1375842659078_0001_000001 released container container_1375842659078_0001_01_000001 on node: host: hadoop-200-7:59851 #containers=0 available=8192 used=0 with event: FINISHED
2013-08-07 02:33:35,814 INFO org.apache.hadoop.yarn.server.resourcemanager.rmapp.RMAppImpl: application_1375842659078_0001 State change from FINISHING to FINISHED
2013-08-07 02:33:35,815 INFO org.apache.hadoop.yarn.server.resourcemanager.RMAuditLogger: USER=ubuntu	OPERATION=Application Finished - Succeeded	TARGET=RMAppManager	RESULT=SUCCESS	APPID=application_1375842659078_0001
2013-08-07 02:33:35,815 INFO org.apache.hadoop.yarn.server.resourcemanager.scheduler.capacity.CapacityScheduler: Application appattempt_1375842659078_0001_000001 is done. finalState=FINISHED
2013-08-07 02:33:35,816 INFO org.apache.hadoop.yarn.server.resourcemanager.amlauncher.AMLauncher: Cleaning master appattempt_1375842659078_0001_000001
2013-08-07 02:33:35,817 INFO org.apache.hadoop.yarn.server.resourcemanager.scheduler.AppSchedulingInfo: Application application_1375842659078_0001 requests cleared
2013-08-07 02:33:35,821 INFO org.apache.hadoop.yarn.server.resourcemanager.scheduler.capacity.LeafQueue: Application removed - appId: application_1375842659078_0001 user: ubuntu queue: default #user-pending-applications: 0 #user-active-applications: 0 #queue-pending-applications: 0 #queue-active-applications: 0
2013-08-07 02:33:35,821 INFO org.apache.hadoop.yarn.server.resourcemanager.scheduler.capacity.ParentQueue: Application removed - appId: application_1375842659078_0001 user: ubuntu leaf-queue of parent: root #applications: 0
2013-08-07 02:33:35,823 INFO org.apache.hadoop.yarn.server.resourcemanager.recovery.RMStateStore: Removing info for app: application_1375842659078_0001
2013-08-07 02:33:35,826 INFO org.apache.hadoop.yarn.server.resourcemanager.RMAppManager$ApplicationSummary: appId=application_1375842659078_0001,name=TeraGen,user=ubuntu,queue=default,state=FINISHED,trackingUrl=hadoop-200-1.novalocal:8088/proxy/application_1375842659078_0001/jobhistory/job/job_1375842659078_0001,appMasterHost=hadoop-200-7,startTime=1375842682731,finishTime=1375842815174
2013-08-07 02:33:35,871 INFO org.apache.hadoop.yarn.server.resourcemanager.ClientRMService: Allocated new applicationId: 2
2013-08-07 02:33:37,795 INFO org.apache.hadoop.yarn.server.resourcemanager.ClientRMService: Storing Application with id application_1375842659078_0002
2013-08-07 02:33:37,795 INFO org.apache.hadoop.yarn.server.resourcemanager.recovery.RMStateStore: Storing info for app: application_1375842659078_0002
2013-08-07 02:33:37,795 INFO org.apache.hadoop.yarn.server.resourcemanager.ClientRMService: Application with id 2 submitted by user ubuntu
2013-08-07 02:33:37,795 INFO org.apache.hadoop.yarn.server.resourcemanager.RMAuditLogger: USER=ubuntu	IP=192.168.100.2	OPERATION=Submit Application Request	TARGET=ClientRMService	RESULT=SUCCESS	APPID=application_1375842659078_0002
2013-08-07 02:33:37,798 INFO org.apache.hadoop.yarn.server.resourcemanager.rmapp.RMAppImpl: application_1375842659078_0002 State change from NEW to SUBMITTED
2013-08-07 02:33:37,799 INFO org.apache.hadoop.yarn.server.resourcemanager.ApplicationMasterService: Registering appattempt_1375842659078_0002_000001
2013-08-07 02:33:37,799 INFO org.apache.hadoop.yarn.server.resourcemanager.rmapp.attempt.RMAppAttemptImpl: appattempt_1375842659078_0002_000001 State change from NEW to SUBMITTED
2013-08-07 02:33:37,799 INFO org.apache.hadoop.yarn.server.resourcemanager.scheduler.capacity.LeafQueue: Application application_1375842659078_0002 from user: ubuntu activated in queue: default
2013-08-07 02:33:37,800 INFO org.apache.hadoop.yarn.server.resourcemanager.scheduler.capacity.LeafQueue: Application added - appId: application_1375842659078_0002 user: org.apache.hadoop.yarn.server.resourcemanager.scheduler.capacity.LeafQueue$User@6a1491ea, leaf-queue: default #user-pending-applications: 0 #user-active-applications: 1 #queue-pending-applications: 0 #queue-active-applications: 1
2013-08-07 02:33:37,800 INFO org.apache.hadoop.yarn.server.resourcemanager.scheduler.capacity.ParentQueue: Application added - appId: application_1375842659078_0002 user: ubuntu leaf-queue of parent: root #applications: 1
2013-08-07 02:33:37,800 INFO org.apache.hadoop.yarn.server.resourcemanager.scheduler.capacity.CapacityScheduler: Application Submission: appattempt_1375842659078_0002_000001, user: ubuntu queue: default: capacity=1.0, absoluteCapacity=1.0, usedResources=<memory:0, vCores:0>usedCapacity=0.0, absoluteUsedCapacity=0.0, numApps=1, numContainers=0, currently active: 1
2013-08-07 02:33:37,801 INFO org.apache.hadoop.yarn.server.resourcemanager.rmapp.attempt.RMAppAttemptImpl: appattempt_1375842659078_0002_000001 State change from SUBMITTED to SCHEDULED
2013-08-07 02:33:37,801 INFO org.apache.hadoop.yarn.server.resourcemanager.rmapp.RMAppImpl: application_1375842659078_0002 State change from SUBMITTED to ACCEPTED
2013-08-07 02:33:37,816 INFO org.apache.hadoop.yarn.server.resourcemanager.rmcontainer.RMContainerImpl: container_1375842659078_0002_01_000001 Container Transitioned from NEW to ALLOCATED
2013-08-07 02:33:37,816 INFO org.apache.hadoop.yarn.server.resourcemanager.RMAuditLogger: USER=ubuntu	OPERATION=AM Allocated Container	TARGET=SchedulerApp	RESULT=SUCCESS	APPID=application_1375842659078_0002	CONTAINERID=container_1375842659078_0002_01_000001
2013-08-07 02:33:37,817 INFO org.apache.hadoop.yarn.server.resourcemanager.scheduler.common.fica.FiCaSchedulerNode: Assigned container container_1375842659078_0002_01_000001 of capacity <memory:2048, vCores:1> on host hadoop-200-7:59851, which currently has 1 containers, <memory:2048, vCores:1> used and <memory:6144, vCores:15> available
2013-08-07 02:33:37,818 INFO org.apache.hadoop.yarn.server.resourcemanager.scheduler.capacity.LeafQueue: assignedContainer application=application_1375842659078_0002 container=Container: [ContainerId: container_1375842659078_0002_01_000001, NodeId: hadoop-200-7:59851, NodeHttpAddress: hadoop-200-7:8042, Resource: <memory:2048, vCores:1>, Priority: 0, State: NEW, Token: null, Status: container_id {, app_attempt_id {, application_id {, id: 2, cluster_timestamp: 1375842659078, }, attemptId: 1, }, id: 1, }, state: C_NEW, ] containerId=container_1375842659078_0002_01_000001 queue=default: capacity=1.0, absoluteCapacity=1.0, usedResources=<memory:0, vCores:0>usedCapacity=0.0, absoluteUsedCapacity=0.0, numApps=1, numContainers=0 usedCapacity=0.0 absoluteUsedCapacity=0.0 used=<memory:0, vCores:0> cluster=<memory:49152, vCores:96>
2013-08-07 02:33:37,818 INFO org.apache.hadoop.yarn.server.resourcemanager.scheduler.capacity.ParentQueue: Re-sorting queues since queue: root.default stats: default: capacity=1.0, absoluteCapacity=1.0, usedResources=<memory:2048, vCores:1>usedCapacity=0.041666668, absoluteUsedCapacity=0.041666668, numApps=1, numContainers=1
2013-08-07 02:33:37,819 INFO org.apache.hadoop.yarn.server.resourcemanager.scheduler.capacity.ParentQueue: assignedContainer queue=root usedCapacity=0.041666668 absoluteUsedCapacity=0.041666668 used=<memory:2048, vCores:1> cluster=<memory:49152, vCores:96>
2013-08-07 02:33:37,820 INFO org.apache.hadoop.yarn.server.resourcemanager.rmcontainer.RMContainerImpl: container_1375842659078_0002_01_000001 Container Transitioned from ALLOCATED to ACQUIRED
2013-08-07 02:33:37,823 INFO org.apache.hadoop.yarn.server.resourcemanager.rmapp.attempt.RMAppAttemptImpl: Storing attempt: AppId: application_1375842659078_0002 AttemptId: appattempt_1375842659078_0002_000001 MasterContainer: Container: [ContainerId: container_1375842659078_0002_01_000001, NodeId: hadoop-200-7:59851, NodeHttpAddress: hadoop-200-7:8042, Resource: <memory:2048, vCores:1>, Priority: 0, State: NEW, Token: null, Status: container_id {, app_attempt_id {, application_id {, id: 2, cluster_timestamp: 1375842659078, }, attemptId: 1, }, id: 1, }, state: C_NEW, ]
2013-08-07 02:33:37,823 INFO org.apache.hadoop.yarn.server.resourcemanager.recovery.RMStateStore: Storing info for attempt: appattempt_1375842659078_0002_000001
2013-08-07 02:33:37,823 INFO org.apache.hadoop.yarn.server.resourcemanager.rmapp.attempt.RMAppAttemptImpl: appattempt_1375842659078_0002_000001 State change from SCHEDULED to ALLOCATED_SAVING
2013-08-07 02:33:37,824 INFO org.apache.hadoop.yarn.server.resourcemanager.rmapp.attempt.RMAppAttemptImpl: appattempt_1375842659078_0002_000001 State change from ALLOCATED_SAVING to ALLOCATED
2013-08-07 02:33:37,826 INFO org.apache.hadoop.yarn.server.resourcemanager.amlauncher.AMLauncher: Launching masterappattempt_1375842659078_0002_000001
2013-08-07 02:33:37,829 INFO org.apache.hadoop.yarn.server.resourcemanager.amlauncher.AMLauncher: Setting up container Container: [ContainerId: container_1375842659078_0002_01_000001, NodeId: hadoop-200-7:59851, NodeHttpAddress: hadoop-200-7:8042, Resource: <memory:2048, vCores:1>, Priority: 0, State: NEW, Token: null, Status: container_id {, app_attempt_id {, application_id {, id: 2, cluster_timestamp: 1375842659078, }, attemptId: 1, }, id: 1, }, state: C_NEW, ] for AM appattempt_1375842659078_0002_000001
2013-08-07 02:33:37,829 INFO org.apache.hadoop.yarn.server.resourcemanager.amlauncher.AMLauncher: Command to launch container container_1375842659078_0002_01_000001 : $JAVA_HOME/bin/java -Dlog4j.configuration=container-log4j.properties -Dyarn.app.mapreduce.container.log.dir=<LOG_DIR> -Dyarn.app.mapreduce.container.log.filesize=0 -Dhadoop.root.logger=INFO,CLA  -Xmx1024m org.apache.hadoop.mapreduce.v2.app.MRAppMaster 1><LOG_DIR>/stdout 2><LOG_DIR>/stderr 
2013-08-07 02:33:37,844 INFO org.apache.hadoop.yarn.server.resourcemanager.amlauncher.AMLauncher: Done launching container Container: [ContainerId: container_1375842659078_0002_01_000001, NodeId: hadoop-200-7:59851, NodeHttpAddress: hadoop-200-7:8042, Resource: <memory:2048, vCores:1>, Priority: 0, State: NEW, Token: null, Status: container_id {, app_attempt_id {, application_id {, id: 2, cluster_timestamp: 1375842659078, }, attemptId: 1, }, id: 1, }, state: C_NEW, ] for AM appattempt_1375842659078_0002_000001
2013-08-07 02:33:37,844 INFO org.apache.hadoop.yarn.server.resourcemanager.rmapp.attempt.RMAppAttemptImpl: appattempt_1375842659078_0002_000001 State change from ALLOCATED to LAUNCHED
2013-08-07 02:33:38,822 INFO org.apache.hadoop.yarn.server.resourcemanager.rmcontainer.RMContainerImpl: container_1375842659078_0002_01_000001 Container Transitioned from ACQUIRED to RUNNING
2013-08-07 02:33:42,605 INFO org.apache.hadoop.yarn.server.resourcemanager.ApplicationMasterService: AM registration appattempt_1375842659078_0002_000001
2013-08-07 02:33:42,605 INFO org.apache.hadoop.yarn.server.resourcemanager.RMAuditLogger: USER=ubuntu	IP=192.168.100.9	OPERATION=Register App Master	TARGET=ApplicationMasterService	RESULT=SUCCESS	APPID=application_1375842659078_0002	APPATTEMPTID=appattempt_1375842659078_0002_000001
2013-08-07 02:33:42,608 INFO org.apache.hadoop.yarn.server.resourcemanager.rmapp.attempt.RMAppAttemptImpl: appattempt_1375842659078_0002_000001 State change from LAUNCHED to RUNNING
2013-08-07 02:33:42,609 INFO org.apache.hadoop.yarn.server.resourcemanager.rmapp.RMAppImpl: application_1375842659078_0002 State change from ACCEPTED to RUNNING
2013-08-07 02:33:43,849 INFO org.apache.hadoop.yarn.server.resourcemanager.rmcontainer.RMContainerImpl: container_1375842659078_0002_01_000002 Container Transitioned from NEW to ALLOCATED
2013-08-07 02:33:43,849 INFO org.apache.hadoop.yarn.server.resourcemanager.RMAuditLogger: USER=ubuntu	OPERATION=AM Allocated Container	TARGET=SchedulerApp	RESULT=SUCCESS	APPID=application_1375842659078_0002	CONTAINERID=container_1375842659078_0002_01_000002
2013-08-07 02:33:43,849 INFO org.apache.hadoop.yarn.server.resourcemanager.scheduler.common.fica.FiCaSchedulerNode: Assigned container container_1375842659078_0002_01_000002 of capacity <memory:1024, vCores:1> on host hadoop-200-7:59851, which currently has 2 containers, <memory:3072, vCores:2> used and <memory:5120, vCores:14> available
2013-08-07 02:33:43,851 INFO org.apache.hadoop.yarn.server.resourcemanager.scheduler.capacity.LeafQueue: assignedContainer application=application_1375842659078_0002 container=Container: [ContainerId: container_1375842659078_0002_01_000002, NodeId: hadoop-200-7:59851, NodeHttpAddress: hadoop-200-7:8042, Resource: <memory:1024, vCores:1>, Priority: 20, State: NEW, Token: null, Status: container_id {, app_attempt_id {, application_id {, id: 2, cluster_timestamp: 1375842659078, }, attemptId: 1, }, id: 2, }, state: C_NEW, ] containerId=container_1375842659078_0002_01_000002 queue=default: capacity=1.0, absoluteCapacity=1.0, usedResources=<memory:2048, vCores:1>usedCapacity=0.041666668, absoluteUsedCapacity=0.041666668, numApps=1, numContainers=1 usedCapacity=0.041666668 absoluteUsedCapacity=0.041666668 used=<memory:2048, vCores:1> cluster=<memory:49152, vCores:96>
2013-08-07 02:33:43,851 INFO org.apache.hadoop.yarn.server.resourcemanager.scheduler.capacity.ParentQueue: Re-sorting queues since queue: root.default stats: default: capacity=1.0, absoluteCapacity=1.0, usedResources=<memory:3072, vCores:2>usedCapacity=0.0625, absoluteUsedCapacity=0.0625, numApps=1, numContainers=2
2013-08-07 02:33:43,851 INFO org.apache.hadoop.yarn.server.resourcemanager.scheduler.capacity.ParentQueue: assignedContainer queue=root usedCapacity=0.0625 absoluteUsedCapacity=0.0625 used=<memory:3072, vCores:2> cluster=<memory:49152, vCores:96>
2013-08-07 02:33:44,070 INFO org.apache.hadoop.yarn.server.resourcemanager.rmcontainer.RMContainerImpl: container_1375842659078_0002_01_000003 Container Transitioned from NEW to ALLOCATED
2013-08-07 02:33:44,071 INFO org.apache.hadoop.yarn.server.resourcemanager.RMAuditLogger: USER=ubuntu	OPERATION=AM Allocated Container	TARGET=SchedulerApp	RESULT=SUCCESS	APPID=application_1375842659078_0002	CONTAINERID=container_1375842659078_0002_01_000003
2013-08-07 02:33:44,071 INFO org.apache.hadoop.yarn.server.resourcemanager.scheduler.common.fica.FiCaSchedulerNode: Assigned container container_1375842659078_0002_01_000003 of capacity <memory:1024, vCores:1> on host hadoop-200-2:33271, which currently has 1 containers, <memory:1024, vCores:1> used and <memory:7168, vCores:15> available
2013-08-07 02:33:44,072 INFO org.apache.hadoop.yarn.server.resourcemanager.scheduler.capacity.LeafQueue: assignedContainer application=application_1375842659078_0002 container=Container: [ContainerId: container_1375842659078_0002_01_000003, NodeId: hadoop-200-2:33271, NodeHttpAddress: hadoop-200-2:8042, Resource: <memory:1024, vCores:1>, Priority: 20, State: NEW, Token: null, Status: container_id {, app_attempt_id {, application_id {, id: 2, cluster_timestamp: 1375842659078, }, attemptId: 1, }, id: 3, }, state: C_NEW, ] containerId=container_1375842659078_0002_01_000003 queue=default: capacity=1.0, absoluteCapacity=1.0, usedResources=<memory:3072, vCores:2>usedCapacity=0.0625, absoluteUsedCapacity=0.0625, numApps=1, numContainers=2 usedCapacity=0.0625 absoluteUsedCapacity=0.0625 used=<memory:3072, vCores:2> cluster=<memory:49152, vCores:96>
2013-08-07 02:33:44,073 INFO org.apache.hadoop.yarn.server.resourcemanager.scheduler.capacity.ParentQueue: Re-sorting queues since queue: root.default stats: default: capacity=1.0, absoluteCapacity=1.0, usedResources=<memory:4096, vCores:3>usedCapacity=0.083333336, absoluteUsedCapacity=0.083333336, numApps=1, numContainers=3
2013-08-07 02:33:44,073 INFO org.apache.hadoop.yarn.server.resourcemanager.scheduler.capacity.ParentQueue: assignedContainer queue=root usedCapacity=0.083333336 absoluteUsedCapacity=0.083333336 used=<memory:4096, vCores:3> cluster=<memory:49152, vCores:96>
2013-08-07 02:33:44,688 INFO org.apache.hadoop.yarn.server.resourcemanager.rmcontainer.RMContainerImpl: container_1375842659078_0002_01_000002 Container Transitioned from ALLOCATED to ACQUIRED
2013-08-07 02:33:44,698 INFO org.apache.hadoop.yarn.server.resourcemanager.rmcontainer.RMContainerImpl: container_1375842659078_0002_01_000003 Container Transitioned from ALLOCATED to ACQUIRED
2013-08-07 02:33:45,079 INFO org.apache.hadoop.yarn.server.resourcemanager.rmcontainer.RMContainerImpl: container_1375842659078_0002_01_000003 Container Transitioned from ACQUIRED to RUNNING
2013-08-07 02:33:45,725 INFO org.apache.hadoop.yarn.server.resourcemanager.scheduler.AppSchedulingInfo: checking for deactivate... 
2013-08-07 02:33:45,862 INFO org.apache.hadoop.yarn.server.resourcemanager.rmcontainer.RMContainerImpl: container_1375842659078_0002_01_000002 Container Transitioned from ACQUIRED to RUNNING
2013-08-07 02:35:31,635 INFO org.apache.hadoop.yarn.server.resourcemanager.rmcontainer.RMContainerImpl: container_1375842659078_0002_01_000002 Container Transitioned from RUNNING to COMPLETED
2013-08-07 02:35:31,636 INFO org.apache.hadoop.yarn.server.resourcemanager.scheduler.common.fica.FiCaSchedulerApp: Completed container: container_1375842659078_0002_01_000002 in state: COMPLETED event:FINISHED
2013-08-07 02:35:31,636 INFO org.apache.hadoop.yarn.server.resourcemanager.RMAuditLogger: USER=ubuntu	OPERATION=AM Released Container	TARGET=SchedulerApp	RESULT=SUCCESS	APPID=application_1375842659078_0002	CONTAINERID=container_1375842659078_0002_01_000002
2013-08-07 02:35:31,636 INFO org.apache.hadoop.yarn.server.resourcemanager.scheduler.common.fica.FiCaSchedulerNode: Released container container_1375842659078_0002_01_000002 of capacity <memory:1024, vCores:1> on host hadoop-200-7:59851, which currently has 1 containers, <memory:2048, vCores:1> used and <memory:6144, vCores:15> available, release resources=true
2013-08-07 02:35:31,636 INFO org.apache.hadoop.yarn.server.resourcemanager.scheduler.capacity.LeafQueue: default used=<memory:3072, vCores:2> numContainers=2 user=ubuntu user-resources=<memory:3072, vCores:2>
2013-08-07 02:35:31,651 INFO org.apache.hadoop.yarn.server.resourcemanager.scheduler.capacity.LeafQueue: completedContainer container=Container: [ContainerId: container_1375842659078_0002_01_000002, NodeId: hadoop-200-7:59851, NodeHttpAddress: hadoop-200-7:8042, Resource: <memory:1024, vCores:1>, Priority: 20, State: NEW, Token: null, Status: container_id {, app_attempt_id {, application_id {, id: 2, cluster_timestamp: 1375842659078, }, attemptId: 1, }, id: 2, }, state: C_COMPLETE, diagnostics: "Container killed by the ApplicationMaster.\n\n", exit_status: 143, ] resource=<memory:1024, vCores:1> queue=default: capacity=1.0, absoluteCapacity=1.0, usedResources=<memory:3072, vCores:2>usedCapacity=0.0625, absoluteUsedCapacity=0.0625, numApps=1, numContainers=2 usedCapacity=0.0625 absoluteUsedCapacity=0.0625 used=<memory:3072, vCores:2> cluster=<memory:49152, vCores:96>
2013-08-07 02:35:31,652 INFO org.apache.hadoop.yarn.server.resourcemanager.scheduler.capacity.ParentQueue: completedContainer queue=root usedCapacity=0.0625 absoluteUsedCapacity=0.0625 used=<memory:3072, vCores:2> cluster=<memory:49152, vCores:96>
2013-08-07 02:35:31,652 INFO org.apache.hadoop.yarn.server.resourcemanager.scheduler.capacity.CapacityScheduler: Application appattempt_1375842659078_0002_000001 released container container_1375842659078_0002_01_000002 on node: host: hadoop-200-7:59851 #containers=1 available=6144 used=2048 with event: FINISHED
2013-08-07 02:35:32,496 INFO org.apache.hadoop.yarn.server.resourcemanager.rmcontainer.RMContainerImpl: container_1375842659078_0002_01_000003 Container Transitioned from RUNNING to COMPLETED
2013-08-07 02:35:32,497 INFO org.apache.hadoop.yarn.server.resourcemanager.scheduler.common.fica.FiCaSchedulerApp: Completed container: container_1375842659078_0002_01_000003 in state: COMPLETED event:FINISHED
2013-08-07 02:35:32,497 INFO org.apache.hadoop.yarn.server.resourcemanager.RMAuditLogger: USER=ubuntu	OPERATION=AM Released Container	TARGET=SchedulerApp	RESULT=SUCCESS	APPID=application_1375842659078_0002	CONTAINERID=container_1375842659078_0002_01_000003
2013-08-07 02:35:32,497 INFO org.apache.hadoop.yarn.server.resourcemanager.scheduler.common.fica.FiCaSchedulerNode: Released container container_1375842659078_0002_01_000003 of capacity <memory:1024, vCores:1> on host hadoop-200-2:33271, which currently has 0 containers, <memory:0, vCores:0> used and <memory:8192, vCores:16> available, release resources=true
2013-08-07 02:35:32,497 INFO org.apache.hadoop.yarn.server.resourcemanager.scheduler.capacity.LeafQueue: default used=<memory:2048, vCores:1> numContainers=1 user=ubuntu user-resources=<memory:2048, vCores:1>
2013-08-07 02:35:32,500 INFO org.apache.hadoop.yarn.server.resourcemanager.scheduler.capacity.LeafQueue: completedContainer container=Container: [ContainerId: container_1375842659078_0002_01_000003, NodeId: hadoop-200-2:33271, NodeHttpAddress: hadoop-200-2:8042, Resource: <memory:1024, vCores:1>, Priority: 20, State: NEW, Token: null, Status: container_id {, app_attempt_id {, application_id {, id: 2, cluster_timestamp: 1375842659078, }, attemptId: 1, }, id: 3, }, state: C_COMPLETE, diagnostics: "Container killed by the ApplicationMaster.\n", exit_status: 0, ] resource=<memory:1024, vCores:1> queue=default: capacity=1.0, absoluteCapacity=1.0, usedResources=<memory:2048, vCores:1>usedCapacity=0.041666668, absoluteUsedCapacity=0.041666668, numApps=1, numContainers=1 usedCapacity=0.041666668 absoluteUsedCapacity=0.041666668 used=<memory:2048, vCores:1> cluster=<memory:49152, vCores:96>
2013-08-07 02:35:32,500 INFO org.apache.hadoop.yarn.server.resourcemanager.scheduler.capacity.ParentQueue: completedContainer queue=root usedCapacity=0.041666668 absoluteUsedCapacity=0.041666668 used=<memory:2048, vCores:1> cluster=<memory:49152, vCores:96>
2013-08-07 02:35:32,500 INFO org.apache.hadoop.yarn.server.resourcemanager.scheduler.capacity.CapacityScheduler: Application appattempt_1375842659078_0002_000001 released container container_1375842659078_0002_01_000003 on node: host: hadoop-200-2:33271 #containers=0 available=8192 used=0 with event: FINISHED
2013-08-07 02:35:36,636 INFO org.apache.hadoop.yarn.server.resourcemanager.rmapp.attempt.RMAppAttemptImpl: appattempt_1375842659078_0002_000001 State change from RUNNING to FINISHING
2013-08-07 02:35:36,637 INFO org.apache.hadoop.yarn.server.resourcemanager.rmapp.RMAppImpl: application_1375842659078_0002 State change from RUNNING to FINISHING
2013-08-07 02:35:37,663 INFO org.apache.hadoop.yarn.server.resourcemanager.rmcontainer.RMContainerImpl: container_1375842659078_0002_01_000001 Container Transitioned from RUNNING to COMPLETED
2013-08-07 02:35:37,663 INFO org.apache.hadoop.yarn.server.resourcemanager.scheduler.common.fica.FiCaSchedulerApp: Completed container: container_1375842659078_0002_01_000001 in state: COMPLETED event:FINISHED
2013-08-07 02:35:37,663 INFO org.apache.hadoop.yarn.server.resourcemanager.rmapp.attempt.RMAppAttemptImpl: appattempt_1375842659078_0002_000001 State change from FINISHING to FINISHED
2013-08-07 02:35:37,663 INFO org.apache.hadoop.yarn.server.resourcemanager.RMAuditLogger: USER=ubuntu	OPERATION=AM Released Container	TARGET=SchedulerApp	RESULT=SUCCESS	APPID=application_1375842659078_0002	CONTAINERID=container_1375842659078_0002_01_000001
2013-08-07 02:35:37,664 INFO org.apache.hadoop.yarn.server.resourcemanager.rmapp.RMAppImpl: application_1375842659078_0002 State change from FINISHING to FINISHED
2013-08-07 02:35:37,664 INFO org.apache.hadoop.yarn.server.resourcemanager.scheduler.common.fica.FiCaSchedulerNode: Released container container_1375842659078_0002_01_000001 of capacity <memory:2048, vCores:1> on host hadoop-200-7:59851, which currently has 0 containers, <memory:0, vCores:0> used and <memory:8192, vCores:16> available, release resources=true
2013-08-07 02:35:37,664 INFO org.apache.hadoop.yarn.server.resourcemanager.scheduler.capacity.LeafQueue: default used=<memory:0, vCores:0> numContainers=0 user=ubuntu user-resources=<memory:0, vCores:0>
2013-08-07 02:35:37,666 INFO org.apache.hadoop.yarn.server.resourcemanager.RMAuditLogger: USER=ubuntu	OPERATION=Application Finished - Succeeded	TARGET=RMAppManager	RESULT=SUCCESS	APPID=application_1375842659078_0002
2013-08-07 02:35:37,666 INFO org.apache.hadoop.yarn.server.resourcemanager.amlauncher.AMLauncher: Cleaning master appattempt_1375842659078_0002_000001
2013-08-07 02:35:37,666 INFO org.apache.hadoop.yarn.server.resourcemanager.scheduler.capacity.LeafQueue: completedContainer container=Container: [ContainerId: container_1375842659078_0002_01_000001, NodeId: hadoop-200-7:59851, NodeHttpAddress: hadoop-200-7:8042, Resource: <memory:2048, vCores:1>, Priority: 0, State: NEW, Token: null, Status: container_id {, app_attempt_id {, application_id {, id: 2, cluster_timestamp: 1375842659078, }, attemptId: 1, }, id: 1, }, state: C_COMPLETE, diagnostics: "", exit_status: 0, ] resource=<memory:2048, vCores:1> queue=default: capacity=1.0, absoluteCapacity=1.0, usedResources=<memory:0, vCores:0>usedCapacity=0.0, absoluteUsedCapacity=0.0, numApps=1, numContainers=0 usedCapacity=0.0 absoluteUsedCapacity=0.0 used=<memory:0, vCores:0> cluster=<memory:49152, vCores:96>
2013-08-07 02:35:37,666 INFO org.apache.hadoop.yarn.server.resourcemanager.recovery.RMStateStore: Removing info for app: application_1375842659078_0002
2013-08-07 02:35:37,666 INFO org.apache.hadoop.yarn.server.resourcemanager.scheduler.capacity.ParentQueue: completedContainer queue=root usedCapacity=0.0 absoluteUsedCapacity=0.0 used=<memory:0, vCores:0> cluster=<memory:49152, vCores:96>
2013-08-07 02:35:37,667 INFO org.apache.hadoop.yarn.server.resourcemanager.RMAppManager$ApplicationSummary: appId=application_1375842659078_0002,name=TeraGen,user=ubuntu,queue=default,state=FINISHED,trackingUrl=hadoop-200-1.novalocal:8088/proxy/application_1375842659078_0002/jobhistory/job/job_1375842659078_0002,appMasterHost=hadoop-200-7,startTime=1375842817794,finishTime=1375842936637
2013-08-07 02:35:37,667 INFO org.apache.hadoop.yarn.server.resourcemanager.scheduler.capacity.CapacityScheduler: Application appattempt_1375842659078_0002_000001 released container container_1375842659078_0002_01_000001 on node: host: hadoop-200-7:59851 #containers=0 available=8192 used=0 with event: FINISHED
2013-08-07 02:35:37,667 INFO org.apache.hadoop.yarn.server.resourcemanager.scheduler.capacity.CapacityScheduler: Application appattempt_1375842659078_0002_000001 is done. finalState=FINISHED
2013-08-07 02:35:37,668 INFO org.apache.hadoop.yarn.server.resourcemanager.scheduler.AppSchedulingInfo: Application application_1375842659078_0002 requests cleared
2013-08-07 02:35:37,668 INFO org.apache.hadoop.yarn.server.resourcemanager.scheduler.capacity.LeafQueue: Application removed - appId: application_1375842659078_0002 user: ubuntu queue: default #user-pending-applications: 0 #user-active-applications: 0 #queue-pending-applications: 0 #queue-active-applications: 0
2013-08-07 02:35:37,668 INFO org.apache.hadoop.yarn.server.resourcemanager.scheduler.capacity.ParentQueue: Application removed - appId: application_1375842659078_0002 user: ubuntu leaf-queue of parent: root #applications: 0
2013-08-07 02:35:37,907 INFO org.apache.hadoop.yarn.server.resourcemanager.ClientRMService: Allocated new applicationId: 3
2013-08-07 02:35:39,792 INFO org.apache.hadoop.yarn.server.resourcemanager.ClientRMService: Storing Application with id application_1375842659078_0003
2013-08-07 02:35:39,793 INFO org.apache.hadoop.yarn.server.resourcemanager.recovery.RMStateStore: Storing info for app: application_1375842659078_0003
2013-08-07 02:35:39,793 INFO org.apache.hadoop.yarn.server.resourcemanager.ClientRMService: Application with id 3 submitted by user ubuntu
2013-08-07 02:35:39,793 INFO org.apache.hadoop.yarn.server.resourcemanager.RMAuditLogger: USER=ubuntu	IP=192.168.100.2	OPERATION=Submit Application Request	TARGET=ClientRMService	RESULT=SUCCESS	APPID=application_1375842659078_0003
2013-08-07 02:35:39,794 INFO org.apache.hadoop.yarn.server.resourcemanager.rmapp.RMAppImpl: application_1375842659078_0003 State change from NEW to SUBMITTED
2013-08-07 02:35:39,795 INFO org.apache.hadoop.yarn.server.resourcemanager.ApplicationMasterService: Registering appattempt_1375842659078_0003_000001
2013-08-07 02:35:39,795 INFO org.apache.hadoop.yarn.server.resourcemanager.rmapp.attempt.RMAppAttemptImpl: appattempt_1375842659078_0003_000001 State change from NEW to SUBMITTED
2013-08-07 02:35:39,795 INFO org.apache.hadoop.yarn.server.resourcemanager.scheduler.capacity.LeafQueue: Application application_1375842659078_0003 from user: ubuntu activated in queue: default
2013-08-07 02:35:39,796 INFO org.apache.hadoop.yarn.server.resourcemanager.scheduler.capacity.LeafQueue: Application added - appId: application_1375842659078_0003 user: org.apache.hadoop.yarn.server.resourcemanager.scheduler.capacity.LeafQueue$User@5f69743c, leaf-queue: default #user-pending-applications: 0 #user-active-applications: 1 #queue-pending-applications: 0 #queue-active-applications: 1
2013-08-07 02:35:39,796 INFO org.apache.hadoop.yarn.server.resourcemanager.scheduler.capacity.ParentQueue: Application added - appId: application_1375842659078_0003 user: ubuntu leaf-queue of parent: root #applications: 1
2013-08-07 02:35:39,796 INFO org.apache.hadoop.yarn.server.resourcemanager.scheduler.capacity.CapacityScheduler: Application Submission: appattempt_1375842659078_0003_000001, user: ubuntu queue: default: capacity=1.0, absoluteCapacity=1.0, usedResources=<memory:0, vCores:0>usedCapacity=0.0, absoluteUsedCapacity=0.0, numApps=1, numContainers=0, currently active: 1
2013-08-07 02:35:39,797 INFO org.apache.hadoop.yarn.server.resourcemanager.rmapp.attempt.RMAppAttemptImpl: appattempt_1375842659078_0003_000001 State change from SUBMITTED to SCHEDULED
2013-08-07 02:35:39,797 INFO org.apache.hadoop.yarn.server.resourcemanager.rmapp.RMAppImpl: application_1375842659078_0003 State change from SUBMITTED to ACCEPTED
2013-08-07 02:35:39,835 INFO org.apache.hadoop.yarn.server.resourcemanager.rmcontainer.RMContainerImpl: container_1375842659078_0003_01_000001 Container Transitioned from NEW to ALLOCATED
2013-08-07 02:35:39,835 INFO org.apache.hadoop.yarn.server.resourcemanager.RMAuditLogger: USER=ubuntu	OPERATION=AM Allocated Container	TARGET=SchedulerApp	RESULT=SUCCESS	APPID=application_1375842659078_0003	CONTAINERID=container_1375842659078_0003_01_000001
2013-08-07 02:35:39,835 INFO org.apache.hadoop.yarn.server.resourcemanager.scheduler.common.fica.FiCaSchedulerNode: Assigned container container_1375842659078_0003_01_000001 of capacity <memory:2048, vCores:1> on host hadoop-200-6:44827, which currently has 1 containers, <memory:2048, vCores:1> used and <memory:6144, vCores:15> available
2013-08-07 02:35:39,837 INFO org.apache.hadoop.yarn.server.resourcemanager.scheduler.capacity.LeafQueue: assignedContainer application=application_1375842659078_0003 container=Container: [ContainerId: container_1375842659078_0003_01_000001, NodeId: hadoop-200-6:44827, NodeHttpAddress: hadoop-200-6:8042, Resource: <memory:2048, vCores:1>, Priority: 0, State: NEW, Token: null, Status: container_id {, app_attempt_id {, application_id {, id: 3, cluster_timestamp: 1375842659078, }, attemptId: 1, }, id: 1, }, state: C_NEW, ] containerId=container_1375842659078_0003_01_000001 queue=default: capacity=1.0, absoluteCapacity=1.0, usedResources=<memory:0, vCores:0>usedCapacity=0.0, absoluteUsedCapacity=0.0, numApps=1, numContainers=0 usedCapacity=0.0 absoluteUsedCapacity=0.0 used=<memory:0, vCores:0> cluster=<memory:49152, vCores:96>
2013-08-07 02:35:39,837 INFO org.apache.hadoop.yarn.server.resourcemanager.scheduler.capacity.ParentQueue: Re-sorting queues since queue: root.default stats: default: capacity=1.0, absoluteCapacity=1.0, usedResources=<memory:2048, vCores:1>usedCapacity=0.041666668, absoluteUsedCapacity=0.041666668, numApps=1, numContainers=1
2013-08-07 02:35:39,838 INFO org.apache.hadoop.yarn.server.resourcemanager.scheduler.capacity.ParentQueue: assignedContainer queue=root usedCapacity=0.041666668 absoluteUsedCapacity=0.041666668 used=<memory:2048, vCores:1> cluster=<memory:49152, vCores:96>
2013-08-07 02:35:39,838 INFO org.apache.hadoop.yarn.server.resourcemanager.rmcontainer.RMContainerImpl: container_1375842659078_0003_01_000001 Container Transitioned from ALLOCATED to ACQUIRED
2013-08-07 02:35:39,841 INFO org.apache.hadoop.yarn.server.resourcemanager.rmapp.attempt.RMAppAttemptImpl: Storing attempt: AppId: application_1375842659078_0003 AttemptId: appattempt_1375842659078_0003_000001 MasterContainer: Container: [ContainerId: container_1375842659078_0003_01_000001, NodeId: hadoop-200-6:44827, NodeHttpAddress: hadoop-200-6:8042, Resource: <memory:2048, vCores:1>, Priority: 0, State: NEW, Token: null, Status: container_id {, app_attempt_id {, application_id {, id: 3, cluster_timestamp: 1375842659078, }, attemptId: 1, }, id: 1, }, state: C_NEW, ]
2013-08-07 02:35:39,841 INFO org.apache.hadoop.yarn.server.resourcemanager.rmapp.attempt.RMAppAttemptImpl: appattempt_1375842659078_0003_000001 State change from SCHEDULED to ALLOCATED_SAVING
2013-08-07 02:35:39,841 INFO org.apache.hadoop.yarn.server.resourcemanager.recovery.RMStateStore: Storing info for attempt: appattempt_1375842659078_0003_000001
2013-08-07 02:35:39,859 INFO org.apache.hadoop.yarn.server.resourcemanager.rmapp.attempt.RMAppAttemptImpl: appattempt_1375842659078_0003_000001 State change from ALLOCATED_SAVING to ALLOCATED
2013-08-07 02:35:39,861 INFO org.apache.hadoop.yarn.server.resourcemanager.amlauncher.AMLauncher: Launching masterappattempt_1375842659078_0003_000001
2013-08-07 02:35:39,864 INFO org.apache.hadoop.yarn.server.resourcemanager.amlauncher.AMLauncher: Setting up container Container: [ContainerId: container_1375842659078_0003_01_000001, NodeId: hadoop-200-6:44827, NodeHttpAddress: hadoop-200-6:8042, Resource: <memory:2048, vCores:1>, Priority: 0, State: NEW, Token: null, Status: container_id {, app_attempt_id {, application_id {, id: 3, cluster_timestamp: 1375842659078, }, attemptId: 1, }, id: 1, }, state: C_NEW, ] for AM appattempt_1375842659078_0003_000001
2013-08-07 02:35:39,864 INFO org.apache.hadoop.yarn.server.resourcemanager.amlauncher.AMLauncher: Command to launch container container_1375842659078_0003_01_000001 : $JAVA_HOME/bin/java -Dlog4j.configuration=container-log4j.properties -Dyarn.app.mapreduce.container.log.dir=<LOG_DIR> -Dyarn.app.mapreduce.container.log.filesize=0 -Dhadoop.root.logger=INFO,CLA  -Xmx1024m org.apache.hadoop.mapreduce.v2.app.MRAppMaster 1><LOG_DIR>/stdout 2><LOG_DIR>/stderr 
2013-08-07 02:35:41,657 INFO org.apache.hadoop.yarn.server.resourcemanager.amlauncher.AMLauncher: Done launching container Container: [ContainerId: container_1375842659078_0003_01_000001, NodeId: hadoop-200-6:44827, NodeHttpAddress: hadoop-200-6:8042, Resource: <memory:2048, vCores:1>, Priority: 0, State: NEW, Token: null, Status: container_id {, app_attempt_id {, application_id {, id: 3, cluster_timestamp: 1375842659078, }, attemptId: 1, }, id: 1, }, state: C_NEW, ] for AM appattempt_1375842659078_0003_000001
2013-08-07 02:35:41,658 INFO org.apache.hadoop.yarn.server.resourcemanager.rmapp.attempt.RMAppAttemptImpl: appattempt_1375842659078_0003_000001 State change from ALLOCATED to LAUNCHED
2013-08-07 02:35:41,918 INFO org.apache.hadoop.yarn.server.resourcemanager.rmcontainer.RMContainerImpl: container_1375842659078_0003_01_000001 Container Transitioned from ACQUIRED to RUNNING
2013-08-07 02:35:50,646 INFO org.apache.hadoop.yarn.server.resourcemanager.ApplicationMasterService: AM registration appattempt_1375842659078_0003_000001
2013-08-07 02:35:50,646 INFO org.apache.hadoop.yarn.server.resourcemanager.RMAuditLogger: USER=ubuntu	IP=192.168.100.6	OPERATION=Register App Master	TARGET=ApplicationMasterService	RESULT=SUCCESS	APPID=application_1375842659078_0003	APPATTEMPTID=appattempt_1375842659078_0003_000001
2013-08-07 02:35:50,647 INFO org.apache.hadoop.yarn.server.resourcemanager.rmapp.attempt.RMAppAttemptImpl: appattempt_1375842659078_0003_000001 State change from LAUNCHED to RUNNING
2013-08-07 02:35:50,647 INFO org.apache.hadoop.yarn.server.resourcemanager.rmapp.RMAppImpl: application_1375842659078_0003 State change from ACCEPTED to RUNNING
2013-08-07 02:35:51,711 INFO org.apache.hadoop.yarn.server.resourcemanager.rmcontainer.RMContainerImpl: container_1375842659078_0003_01_000002 Container Transitioned from NEW to ALLOCATED
2013-08-07 02:35:51,711 INFO org.apache.hadoop.yarn.server.resourcemanager.RMAuditLogger: USER=ubuntu	OPERATION=AM Allocated Container	TARGET=SchedulerApp	RESULT=SUCCESS	APPID=application_1375842659078_0003	CONTAINERID=container_1375842659078_0003_01_000002
2013-08-07 02:35:51,711 INFO org.apache.hadoop.yarn.server.resourcemanager.scheduler.common.fica.FiCaSchedulerNode: Assigned container container_1375842659078_0003_01_000002 of capacity <memory:1024, vCores:1> on host hadoop-200-7:59851, which currently has 1 containers, <memory:1024, vCores:1> used and <memory:7168, vCores:15> available
2013-08-07 02:35:51,713 INFO org.apache.hadoop.yarn.server.resourcemanager.scheduler.capacity.LeafQueue: assignedContainer application=application_1375842659078_0003 container=Container: [ContainerId: container_1375842659078_0003_01_000002, NodeId: hadoop-200-7:59851, NodeHttpAddress: hadoop-200-7:8042, Resource: <memory:1024, vCores:1>, Priority: 20, State: NEW, Token: null, Status: container_id {, app_attempt_id {, application_id {, id: 3, cluster_timestamp: 1375842659078, }, attemptId: 1, }, id: 2, }, state: C_NEW, ] containerId=container_1375842659078_0003_01_000002 queue=default: capacity=1.0, absoluteCapacity=1.0, usedResources=<memory:2048, vCores:1>usedCapacity=0.041666668, absoluteUsedCapacity=0.041666668, numApps=1, numContainers=1 usedCapacity=0.041666668 absoluteUsedCapacity=0.041666668 used=<memory:2048, vCores:1> cluster=<memory:49152, vCores:96>
2013-08-07 02:35:51,713 INFO org.apache.hadoop.yarn.server.resourcemanager.scheduler.capacity.ParentQueue: Re-sorting queues since queue: root.default stats: default: capacity=1.0, absoluteCapacity=1.0, usedResources=<memory:3072, vCores:2>usedCapacity=0.0625, absoluteUsedCapacity=0.0625, numApps=1, numContainers=2
2013-08-07 02:35:51,714 INFO org.apache.hadoop.yarn.server.resourcemanager.scheduler.capacity.ParentQueue: assignedContainer queue=root usedCapacity=0.0625 absoluteUsedCapacity=0.0625 used=<memory:3072, vCores:2> cluster=<memory:49152, vCores:96>
2013-08-07 02:35:51,714 INFO org.apache.hadoop.yarn.server.resourcemanager.rmcontainer.RMContainerImpl: container_1375842659078_0003_01_000003 Container Transitioned from NEW to ALLOCATED
2013-08-07 02:35:51,715 INFO org.apache.hadoop.yarn.server.resourcemanager.RMAuditLogger: USER=ubuntu	OPERATION=AM Allocated Container	TARGET=SchedulerApp	RESULT=SUCCESS	APPID=application_1375842659078_0003	CONTAINERID=container_1375842659078_0003_01_000003
2013-08-07 02:35:51,715 INFO org.apache.hadoop.yarn.server.resourcemanager.scheduler.common.fica.FiCaSchedulerNode: Assigned container container_1375842659078_0003_01_000003 of capacity <memory:1024, vCores:1> on host hadoop-200-3:34020, which currently has 1 containers, <memory:1024, vCores:1> used and <memory:7168, vCores:15> available
2013-08-07 02:35:51,716 INFO org.apache.hadoop.yarn.server.resourcemanager.scheduler.capacity.LeafQueue: assignedContainer application=application_1375842659078_0003 container=Container: [ContainerId: container_1375842659078_0003_01_000003, NodeId: hadoop-200-3:34020, NodeHttpAddress: hadoop-200-3:8042, Resource: <memory:1024, vCores:1>, Priority: 20, State: NEW, Token: null, Status: container_id {, app_attempt_id {, application_id {, id: 3, cluster_timestamp: 1375842659078, }, attemptId: 1, }, id: 3, }, state: C_NEW, ] containerId=container_1375842659078_0003_01_000003 queue=default: capacity=1.0, absoluteCapacity=1.0, usedResources=<memory:3072, vCores:2>usedCapacity=0.0625, absoluteUsedCapacity=0.0625, numApps=1, numContainers=2 usedCapacity=0.0625 absoluteUsedCapacity=0.0625 used=<memory:3072, vCores:2> cluster=<memory:49152, vCores:96>
2013-08-07 02:35:51,717 INFO org.apache.hadoop.yarn.server.resourcemanager.scheduler.capacity.ParentQueue: Re-sorting queues since queue: root.default stats: default: capacity=1.0, absoluteCapacity=1.0, usedResources=<memory:4096, vCores:3>usedCapacity=0.083333336, absoluteUsedCapacity=0.083333336, numApps=1, numContainers=3
2013-08-07 02:35:51,717 INFO org.apache.hadoop.yarn.server.resourcemanager.scheduler.capacity.ParentQueue: assignedContainer queue=root usedCapacity=0.083333336 absoluteUsedCapacity=0.083333336 used=<memory:4096, vCores:3> cluster=<memory:49152, vCores:96>
2013-08-07 02:35:52,718 INFO org.apache.hadoop.yarn.server.resourcemanager.rmcontainer.RMContainerImpl: container_1375842659078_0003_01_000002 Container Transitioned from ALLOCATED to ACQUIRED
2013-08-07 02:35:52,720 INFO org.apache.hadoop.yarn.server.resourcemanager.rmcontainer.RMContainerImpl: container_1375842659078_0003_01_000003 Container Transitioned from ALLOCATED to ACQUIRED
2013-08-07 02:35:53,723 INFO org.apache.hadoop.yarn.server.resourcemanager.rmcontainer.RMContainerImpl: container_1375842659078_0003_01_000002 Container Transitioned from ACQUIRED to RUNNING
2013-08-07 02:35:53,756 INFO org.apache.hadoop.yarn.server.resourcemanager.scheduler.AppSchedulingInfo: checking for deactivate... 
2013-08-07 02:35:54,750 INFO org.apache.hadoop.yarn.server.resourcemanager.rmcontainer.RMContainerImpl: container_1375842659078_0003_01_000003 Container Transitioned from ACQUIRED to RUNNING
2013-08-07 02:37:36,210 INFO org.apache.hadoop.yarn.server.resourcemanager.rmcontainer.RMContainerImpl: container_1375842659078_0003_01_000003 Container Transitioned from RUNNING to COMPLETED
2013-08-07 02:37:36,210 INFO org.apache.hadoop.yarn.server.resourcemanager.scheduler.common.fica.FiCaSchedulerApp: Completed container: container_1375842659078_0003_01_000003 in state: COMPLETED event:FINISHED
2013-08-07 02:37:36,210 INFO org.apache.hadoop.yarn.server.resourcemanager.RMAuditLogger: USER=ubuntu	OPERATION=AM Released Container	TARGET=SchedulerApp	RESULT=SUCCESS	APPID=application_1375842659078_0003	CONTAINERID=container_1375842659078_0003_01_000003
2013-08-07 02:37:36,210 INFO org.apache.hadoop.yarn.server.resourcemanager.scheduler.common.fica.FiCaSchedulerNode: Released container container_1375842659078_0003_01_000003 of capacity <memory:1024, vCores:1> on host hadoop-200-3:34020, which currently has 0 containers, <memory:0, vCores:0> used and <memory:8192, vCores:16> available, release resources=true
2013-08-07 02:37:36,211 INFO org.apache.hadoop.yarn.server.resourcemanager.scheduler.capacity.LeafQueue: default used=<memory:3072, vCores:2> numContainers=2 user=ubuntu user-resources=<memory:3072, vCores:2>
2013-08-07 02:37:36,212 INFO org.apache.hadoop.yarn.server.resourcemanager.scheduler.capacity.LeafQueue: completedContainer container=Container: [ContainerId: container_1375842659078_0003_01_000003, NodeId: hadoop-200-3:34020, NodeHttpAddress: hadoop-200-3:8042, Resource: <memory:1024, vCores:1>, Priority: 20, State: NEW, Token: null, Status: container_id {, app_attempt_id {, application_id {, id: 3, cluster_timestamp: 1375842659078, }, attemptId: 1, }, id: 3, }, state: C_COMPLETE, diagnostics: "Container killed by the ApplicationMaster.\n\n", exit_status: 143, ] resource=<memory:1024, vCores:1> queue=default: capacity=1.0, absoluteCapacity=1.0, usedResources=<memory:3072, vCores:2>usedCapacity=0.0625, absoluteUsedCapacity=0.0625, numApps=1, numContainers=2 usedCapacity=0.0625 absoluteUsedCapacity=0.0625 used=<memory:3072, vCores:2> cluster=<memory:49152, vCores:96>
2013-08-07 02:37:36,213 INFO org.apache.hadoop.yarn.server.resourcemanager.scheduler.capacity.ParentQueue: completedContainer queue=root usedCapacity=0.0625 absoluteUsedCapacity=0.0625 used=<memory:3072, vCores:2> cluster=<memory:49152, vCores:96>
2013-08-07 02:37:36,213 INFO org.apache.hadoop.yarn.server.resourcemanager.scheduler.capacity.CapacityScheduler: Application appattempt_1375842659078_0003_000001 released container container_1375842659078_0003_01_000003 on node: host: hadoop-200-3:34020 #containers=0 available=8192 used=0 with event: FINISHED
2013-08-07 02:37:40,767 INFO org.apache.hadoop.yarn.server.resourcemanager.rmcontainer.RMContainerImpl: container_1375842659078_0003_01_000002 Container Transitioned from RUNNING to COMPLETED
2013-08-07 02:37:40,768 INFO org.apache.hadoop.yarn.server.resourcemanager.scheduler.common.fica.FiCaSchedulerApp: Completed container: container_1375842659078_0003_01_000002 in state: COMPLETED event:FINISHED
2013-08-07 02:37:40,768 INFO org.apache.hadoop.yarn.server.resourcemanager.RMAuditLogger: USER=ubuntu	OPERATION=AM Released Container	TARGET=SchedulerApp	RESULT=SUCCESS	APPID=application_1375842659078_0003	CONTAINERID=container_1375842659078_0003_01_000002
2013-08-07 02:37:40,768 INFO org.apache.hadoop.yarn.server.resourcemanager.scheduler.common.fica.FiCaSchedulerNode: Released container container_1375842659078_0003_01_000002 of capacity <memory:1024, vCores:1> on host hadoop-200-7:59851, which currently has 0 containers, <memory:0, vCores:0> used and <memory:8192, vCores:16> available, release resources=true
2013-08-07 02:37:40,768 INFO org.apache.hadoop.yarn.server.resourcemanager.scheduler.capacity.LeafQueue: default used=<memory:2048, vCores:1> numContainers=1 user=ubuntu user-resources=<memory:2048, vCores:1>
2013-08-07 02:37:40,770 INFO org.apache.hadoop.yarn.server.resourcemanager.scheduler.capacity.LeafQueue: completedContainer container=Container: [ContainerId: container_1375842659078_0003_01_000002, NodeId: hadoop-200-7:59851, NodeHttpAddress: hadoop-200-7:8042, Resource: <memory:1024, vCores:1>, Priority: 20, State: NEW, Token: null, Status: container_id {, app_attempt_id {, application_id {, id: 3, cluster_timestamp: 1375842659078, }, attemptId: 1, }, id: 2, }, state: C_COMPLETE, diagnostics: "Container killed by the ApplicationMaster.\n\n", exit_status: 143, ] resource=<memory:1024, vCores:1> queue=default: capacity=1.0, absoluteCapacity=1.0, usedResources=<memory:2048, vCores:1>usedCapacity=0.041666668, absoluteUsedCapacity=0.041666668, numApps=1, numContainers=1 usedCapacity=0.041666668 absoluteUsedCapacity=0.041666668 used=<memory:2048, vCores:1> cluster=<memory:49152, vCores:96>
2013-08-07 02:37:40,770 INFO org.apache.hadoop.yarn.server.resourcemanager.scheduler.capacity.ParentQueue: completedContainer queue=root usedCapacity=0.041666668 absoluteUsedCapacity=0.041666668 used=<memory:2048, vCores:1> cluster=<memory:49152, vCores:96>
2013-08-07 02:37:40,771 INFO org.apache.hadoop.yarn.server.resourcemanager.scheduler.capacity.CapacityScheduler: Application appattempt_1375842659078_0003_000001 released container container_1375842659078_0003_01_000002 on node: host: hadoop-200-7:59851 #containers=0 available=8192 used=0 with event: FINISHED
2013-08-07 02:37:44,937 INFO org.apache.hadoop.yarn.server.resourcemanager.rmapp.attempt.RMAppAttemptImpl: appattempt_1375842659078_0003_000001 State change from RUNNING to FINISHING
2013-08-07 02:37:44,937 INFO org.apache.hadoop.yarn.server.resourcemanager.rmapp.RMAppImpl: application_1375842659078_0003 State change from RUNNING to FINISHING
2013-08-07 02:37:45,461 INFO org.apache.hadoop.yarn.server.resourcemanager.ClientRMService: Allocated new applicationId: 4
2013-08-07 02:37:45,628 INFO org.apache.hadoop.yarn.server.resourcemanager.rmcontainer.RMContainerImpl: container_1375842659078_0003_01_000001 Container Transitioned from RUNNING to COMPLETED
2013-08-07 02:37:45,628 INFO org.apache.hadoop.yarn.server.resourcemanager.scheduler.common.fica.FiCaSchedulerApp: Completed container: container_1375842659078_0003_01_000001 in state: COMPLETED event:FINISHED
2013-08-07 02:37:45,628 INFO org.apache.hadoop.yarn.server.resourcemanager.RMAuditLogger: USER=ubuntu	OPERATION=AM Released Container	TARGET=SchedulerApp	RESULT=SUCCESS	APPID=application_1375842659078_0003	CONTAINERID=container_1375842659078_0003_01_000001
2013-08-07 02:37:45,628 INFO org.apache.hadoop.yarn.server.resourcemanager.scheduler.common.fica.FiCaSchedulerNode: Released container container_1375842659078_0003_01_000001 of capacity <memory:2048, vCores:1> on host hadoop-200-6:44827, which currently has 0 containers, <memory:0, vCores:0> used and <memory:8192, vCores:16> available, release resources=true
2013-08-07 02:37:45,628 INFO org.apache.hadoop.yarn.server.resourcemanager.scheduler.capacity.LeafQueue: default used=<memory:0, vCores:0> numContainers=0 user=ubuntu user-resources=<memory:0, vCores:0>
2013-08-07 02:37:45,629 INFO org.apache.hadoop.yarn.server.resourcemanager.scheduler.capacity.LeafQueue: completedContainer container=Container: [ContainerId: container_1375842659078_0003_01_000001, NodeId: hadoop-200-6:44827, NodeHttpAddress: hadoop-200-6:8042, Resource: <memory:2048, vCores:1>, Priority: 0, State: NEW, Token: null, Status: container_id {, app_attempt_id {, application_id {, id: 3, cluster_timestamp: 1375842659078, }, attemptId: 1, }, id: 1, }, state: C_COMPLETE, diagnostics: "", exit_status: 0, ] resource=<memory:2048, vCores:1> queue=default: capacity=1.0, absoluteCapacity=1.0, usedResources=<memory:0, vCores:0>usedCapacity=0.0, absoluteUsedCapacity=0.0, numApps=1, numContainers=0 usedCapacity=0.0 absoluteUsedCapacity=0.0 used=<memory:0, vCores:0> cluster=<memory:49152, vCores:96>
2013-08-07 02:37:45,629 INFO org.apache.hadoop.yarn.server.resourcemanager.scheduler.capacity.ParentQueue: completedContainer queue=root usedCapacity=0.0 absoluteUsedCapacity=0.0 used=<memory:0, vCores:0> cluster=<memory:49152, vCores:96>
2013-08-07 02:37:45,629 INFO org.apache.hadoop.yarn.server.resourcemanager.scheduler.capacity.CapacityScheduler: Application appattempt_1375842659078_0003_000001 released container container_1375842659078_0003_01_000001 on node: host: hadoop-200-6:44827 #containers=0 available=8192 used=0 with event: FINISHED
2013-08-07 02:37:45,629 INFO org.apache.hadoop.yarn.server.resourcemanager.rmapp.attempt.RMAppAttemptImpl: appattempt_1375842659078_0003_000001 State change from FINISHING to FINISHED
2013-08-07 02:37:45,630 INFO org.apache.hadoop.yarn.server.resourcemanager.rmapp.RMAppImpl: application_1375842659078_0003 State change from FINISHING to FINISHED
2013-08-07 02:37:45,630 INFO org.apache.hadoop.yarn.server.resourcemanager.RMAuditLogger: USER=ubuntu	OPERATION=Application Finished - Succeeded	TARGET=RMAppManager	RESULT=SUCCESS	APPID=application_1375842659078_0003
2013-08-07 02:37:45,630 INFO org.apache.hadoop.yarn.server.resourcemanager.scheduler.capacity.CapacityScheduler: Application appattempt_1375842659078_0003_000001 is done. finalState=FINISHED
2013-08-07 02:37:45,630 INFO org.apache.hadoop.yarn.server.resourcemanager.scheduler.AppSchedulingInfo: Application application_1375842659078_0003 requests cleared
2013-08-07 02:37:45,630 INFO org.apache.hadoop.yarn.server.resourcemanager.scheduler.capacity.LeafQueue: Application removed - appId: application_1375842659078_0003 user: ubuntu queue: default #user-pending-applications: 0 #user-active-applications: 0 #queue-pending-applications: 0 #queue-active-applications: 0
2013-08-07 02:37:45,630 INFO org.apache.hadoop.yarn.server.resourcemanager.scheduler.capacity.ParentQueue: Application removed - appId: application_1375842659078_0003 user: ubuntu leaf-queue of parent: root #applications: 0
2013-08-07 02:37:45,631 INFO org.apache.hadoop.yarn.server.resourcemanager.recovery.RMStateStore: Removing info for app: application_1375842659078_0003
2013-08-07 02:37:45,631 INFO org.apache.hadoop.yarn.server.resourcemanager.RMAppManager$ApplicationSummary: appId=application_1375842659078_0003,name=TeraGen,user=ubuntu,queue=default,state=FINISHED,trackingUrl=hadoop-200-1.novalocal:8088/proxy/application_1375842659078_0003/jobhistory/job/job_1375842659078_0003,appMasterHost=hadoop-200-6,startTime=1375842939792,finishTime=1375843064937
2013-08-07 02:37:45,631 INFO org.apache.hadoop.yarn.server.resourcemanager.amlauncher.AMLauncher: Cleaning master appattempt_1375842659078_0003_000001
2013-08-07 02:37:48,168 INFO org.apache.hadoop.yarn.server.resourcemanager.ClientRMService: Storing Application with id application_1375842659078_0004
2013-08-07 02:37:48,168 INFO org.apache.hadoop.yarn.server.resourcemanager.recovery.RMStateStore: Storing info for app: application_1375842659078_0004
2013-08-07 02:37:48,168 INFO org.apache.hadoop.yarn.server.resourcemanager.ClientRMService: Application with id 4 submitted by user ubuntu
2013-08-07 02:37:48,169 INFO org.apache.hadoop.yarn.server.resourcemanager.RMAuditLogger: USER=ubuntu	IP=192.168.100.2	OPERATION=Submit Application Request	TARGET=ClientRMService	RESULT=SUCCESS	APPID=application_1375842659078_0004
2013-08-07 02:37:48,170 INFO org.apache.hadoop.yarn.server.resourcemanager.rmapp.RMAppImpl: application_1375842659078_0004 State change from NEW to SUBMITTED
2013-08-07 02:37:48,170 INFO org.apache.hadoop.yarn.server.resourcemanager.ApplicationMasterService: Registering appattempt_1375842659078_0004_000001
2013-08-07 02:37:48,170 INFO org.apache.hadoop.yarn.server.resourcemanager.rmapp.attempt.RMAppAttemptImpl: appattempt_1375842659078_0004_000001 State change from NEW to SUBMITTED
2013-08-07 02:37:48,171 INFO org.apache.hadoop.yarn.server.resourcemanager.scheduler.capacity.LeafQueue: Application application_1375842659078_0004 from user: ubuntu activated in queue: default
2013-08-07 02:37:48,171 INFO org.apache.hadoop.yarn.server.resourcemanager.scheduler.capacity.LeafQueue: Application added - appId: application_1375842659078_0004 user: org.apache.hadoop.yarn.server.resourcemanager.scheduler.capacity.LeafQueue$User@7749f1d9, leaf-queue: default #user-pending-applications: 0 #user-active-applications: 1 #queue-pending-applications: 0 #queue-active-applications: 1
2013-08-07 02:37:48,171 INFO org.apache.hadoop.yarn.server.resourcemanager.scheduler.capacity.ParentQueue: Application added - appId: application_1375842659078_0004 user: ubuntu leaf-queue of parent: root #applications: 1
2013-08-07 02:37:48,172 INFO org.apache.hadoop.yarn.server.resourcemanager.scheduler.capacity.CapacityScheduler: Application Submission: appattempt_1375842659078_0004_000001, user: ubuntu queue: default: capacity=1.0, absoluteCapacity=1.0, usedResources=<memory:0, vCores:0>usedCapacity=0.0, absoluteUsedCapacity=0.0, numApps=1, numContainers=0, currently active: 1
2013-08-07 02:37:48,172 INFO org.apache.hadoop.yarn.server.resourcemanager.rmapp.attempt.RMAppAttemptImpl: appattempt_1375842659078_0004_000001 State change from SUBMITTED to SCHEDULED
2013-08-07 02:37:48,172 INFO org.apache.hadoop.yarn.server.resourcemanager.rmapp.RMAppImpl: application_1375842659078_0004 State change from SUBMITTED to ACCEPTED
2013-08-07 02:37:48,186 INFO org.apache.hadoop.yarn.server.resourcemanager.rmcontainer.RMContainerImpl: container_1375842659078_0004_01_000001 Container Transitioned from NEW to ALLOCATED
2013-08-07 02:37:48,186 INFO org.apache.hadoop.yarn.server.resourcemanager.RMAuditLogger: USER=ubuntu	OPERATION=AM Allocated Container	TARGET=SchedulerApp	RESULT=SUCCESS	APPID=application_1375842659078_0004	CONTAINERID=container_1375842659078_0004_01_000001
2013-08-07 02:37:48,186 INFO org.apache.hadoop.yarn.server.resourcemanager.scheduler.common.fica.FiCaSchedulerNode: Assigned container container_1375842659078_0004_01_000001 of capacity <memory:2048, vCores:1> on host hadoop-200-5:38287, which currently has 1 containers, <memory:2048, vCores:1> used and <memory:6144, vCores:15> available
2013-08-07 02:37:48,188 INFO org.apache.hadoop.yarn.server.resourcemanager.scheduler.capacity.LeafQueue: assignedContainer application=application_1375842659078_0004 container=Container: [ContainerId: container_1375842659078_0004_01_000001, NodeId: hadoop-200-5:38287, NodeHttpAddress: hadoop-200-5:8042, Resource: <memory:2048, vCores:1>, Priority: 0, State: NEW, Token: null, Status: container_id {, app_attempt_id {, application_id {, id: 4, cluster_timestamp: 1375842659078, }, attemptId: 1, }, id: 1, }, state: C_NEW, ] containerId=container_1375842659078_0004_01_000001 queue=default: capacity=1.0, absoluteCapacity=1.0, usedResources=<memory:0, vCores:0>usedCapacity=0.0, absoluteUsedCapacity=0.0, numApps=1, numContainers=0 usedCapacity=0.0 absoluteUsedCapacity=0.0 used=<memory:0, vCores:0> cluster=<memory:49152, vCores:96>
2013-08-07 02:37:48,189 INFO org.apache.hadoop.yarn.server.resourcemanager.scheduler.capacity.ParentQueue: Re-sorting queues since queue: root.default stats: default: capacity=1.0, absoluteCapacity=1.0, usedResources=<memory:2048, vCores:1>usedCapacity=0.041666668, absoluteUsedCapacity=0.041666668, numApps=1, numContainers=1
2013-08-07 02:37:48,190 INFO org.apache.hadoop.yarn.server.resourcemanager.rmcontainer.RMContainerImpl: container_1375842659078_0004_01_000001 Container Transitioned from ALLOCATED to ACQUIRED
2013-08-07 02:37:48,191 INFO org.apache.hadoop.yarn.server.resourcemanager.scheduler.capacity.ParentQueue: assignedContainer queue=root usedCapacity=0.041666668 absoluteUsedCapacity=0.041666668 used=<memory:2048, vCores:1> cluster=<memory:49152, vCores:96>
2013-08-07 02:37:48,192 INFO org.apache.hadoop.yarn.server.resourcemanager.rmapp.attempt.RMAppAttemptImpl: Storing attempt: AppId: application_1375842659078_0004 AttemptId: appattempt_1375842659078_0004_000001 MasterContainer: Container: [ContainerId: container_1375842659078_0004_01_000001, NodeId: hadoop-200-5:38287, NodeHttpAddress: hadoop-200-5:8042, Resource: <memory:2048, vCores:1>, Priority: 0, State: NEW, Token: null, Status: container_id {, app_attempt_id {, application_id {, id: 4, cluster_timestamp: 1375842659078, }, attemptId: 1, }, id: 1, }, state: C_NEW, ]
2013-08-07 02:37:48,192 INFO org.apache.hadoop.yarn.server.resourcemanager.rmapp.attempt.RMAppAttemptImpl: appattempt_1375842659078_0004_000001 State change from SCHEDULED to ALLOCATED_SAVING
2013-08-07 02:37:48,192 INFO org.apache.hadoop.yarn.server.resourcemanager.recovery.RMStateStore: Storing info for attempt: appattempt_1375842659078_0004_000001
2013-08-07 02:37:48,197 INFO org.apache.hadoop.yarn.server.resourcemanager.rmapp.attempt.RMAppAttemptImpl: appattempt_1375842659078_0004_000001 State change from ALLOCATED_SAVING to ALLOCATED
2013-08-07 02:37:48,199 INFO org.apache.hadoop.yarn.server.resourcemanager.amlauncher.AMLauncher: Launching masterappattempt_1375842659078_0004_000001
2013-08-07 02:37:48,202 INFO org.apache.hadoop.yarn.server.resourcemanager.amlauncher.AMLauncher: Setting up container Container: [ContainerId: container_1375842659078_0004_01_000001, NodeId: hadoop-200-5:38287, NodeHttpAddress: hadoop-200-5:8042, Resource: <memory:2048, vCores:1>, Priority: 0, State: NEW, Token: null, Status: container_id {, app_attempt_id {, application_id {, id: 4, cluster_timestamp: 1375842659078, }, attemptId: 1, }, id: 1, }, state: C_NEW, ] for AM appattempt_1375842659078_0004_000001
2013-08-07 02:37:48,202 INFO org.apache.hadoop.yarn.server.resourcemanager.amlauncher.AMLauncher: Command to launch container container_1375842659078_0004_01_000001 : $JAVA_HOME/bin/java -Dlog4j.configuration=container-log4j.properties -Dyarn.app.mapreduce.container.log.dir=<LOG_DIR> -Dyarn.app.mapreduce.container.log.filesize=0 -Dhadoop.root.logger=INFO,CLA  -Xmx1024m org.apache.hadoop.mapreduce.v2.app.MRAppMaster 1><LOG_DIR>/stdout 2><LOG_DIR>/stderr 
2013-08-07 02:37:48,219 INFO org.apache.hadoop.yarn.server.resourcemanager.amlauncher.AMLauncher: Done launching container Container: [ContainerId: container_1375842659078_0004_01_000001, NodeId: hadoop-200-5:38287, NodeHttpAddress: hadoop-200-5:8042, Resource: <memory:2048, vCores:1>, Priority: 0, State: NEW, Token: null, Status: container_id {, app_attempt_id {, application_id {, id: 4, cluster_timestamp: 1375842659078, }, attemptId: 1, }, id: 1, }, state: C_NEW, ] for AM appattempt_1375842659078_0004_000001
2013-08-07 02:37:48,220 INFO org.apache.hadoop.yarn.server.resourcemanager.rmapp.attempt.RMAppAttemptImpl: appattempt_1375842659078_0004_000001 State change from ALLOCATED to LAUNCHED
2013-08-07 02:37:49,186 INFO org.apache.hadoop.yarn.server.resourcemanager.rmcontainer.RMContainerImpl: container_1375842659078_0004_01_000001 Container Transitioned from ACQUIRED to RUNNING
2013-08-07 02:37:57,356 INFO org.apache.hadoop.yarn.server.resourcemanager.ApplicationMasterService: AM registration appattempt_1375842659078_0004_000001
2013-08-07 02:37:57,356 INFO org.apache.hadoop.yarn.server.resourcemanager.RMAuditLogger: USER=ubuntu	IP=192.168.100.5	OPERATION=Register App Master	TARGET=ApplicationMasterService	RESULT=SUCCESS	APPID=application_1375842659078_0004	APPATTEMPTID=appattempt_1375842659078_0004_000001
2013-08-07 02:37:57,357 INFO org.apache.hadoop.yarn.server.resourcemanager.rmapp.attempt.RMAppAttemptImpl: appattempt_1375842659078_0004_000001 State change from LAUNCHED to RUNNING
2013-08-07 02:37:57,358 INFO org.apache.hadoop.yarn.server.resourcemanager.rmapp.RMAppImpl: application_1375842659078_0004 State change from ACCEPTED to RUNNING
2013-08-07 02:37:58,476 INFO org.apache.hadoop.yarn.server.resourcemanager.rmcontainer.RMContainerImpl: container_1375842659078_0004_01_000002 Container Transitioned from NEW to ALLOCATED
2013-08-07 02:37:58,476 INFO org.apache.hadoop.yarn.server.resourcemanager.RMAuditLogger: USER=ubuntu	OPERATION=AM Allocated Container	TARGET=SchedulerApp	RESULT=SUCCESS	APPID=application_1375842659078_0004	CONTAINERID=container_1375842659078_0004_01_000002
2013-08-07 02:37:58,477 INFO org.apache.hadoop.yarn.server.resourcemanager.scheduler.common.fica.FiCaSchedulerNode: Assigned container container_1375842659078_0004_01_000002 of capacity <memory:1024, vCores:1> on host hadoop-200-4:56924, which currently has 1 containers, <memory:1024, vCores:1> used and <memory:7168, vCores:15> available
2013-08-07 02:37:58,478 INFO org.apache.hadoop.yarn.server.resourcemanager.scheduler.capacity.LeafQueue: assignedContainer application=application_1375842659078_0004 container=Container: [ContainerId: container_1375842659078_0004_01_000002, NodeId: hadoop-200-4:56924, NodeHttpAddress: hadoop-200-4:8042, Resource: <memory:1024, vCores:1>, Priority: 20, State: NEW, Token: null, Status: container_id {, app_attempt_id {, application_id {, id: 4, cluster_timestamp: 1375842659078, }, attemptId: 1, }, id: 2, }, state: C_NEW, ] containerId=container_1375842659078_0004_01_000002 queue=default: capacity=1.0, absoluteCapacity=1.0, usedResources=<memory:2048, vCores:1>usedCapacity=0.041666668, absoluteUsedCapacity=0.041666668, numApps=1, numContainers=1 usedCapacity=0.041666668 absoluteUsedCapacity=0.041666668 used=<memory:2048, vCores:1> cluster=<memory:49152, vCores:96>
2013-08-07 02:37:58,478 INFO org.apache.hadoop.yarn.server.resourcemanager.scheduler.capacity.ParentQueue: Re-sorting queues since queue: root.default stats: default: capacity=1.0, absoluteCapacity=1.0, usedResources=<memory:3072, vCores:2>usedCapacity=0.0625, absoluteUsedCapacity=0.0625, numApps=1, numContainers=2
2013-08-07 02:37:58,479 INFO org.apache.hadoop.yarn.server.resourcemanager.scheduler.capacity.ParentQueue: assignedContainer queue=root usedCapacity=0.0625 absoluteUsedCapacity=0.0625 used=<memory:3072, vCores:2> cluster=<memory:49152, vCores:96>
2013-08-07 02:37:58,674 INFO org.apache.hadoop.yarn.server.resourcemanager.rmcontainer.RMContainerImpl: container_1375842659078_0004_01_000003 Container Transitioned from NEW to ALLOCATED
2013-08-07 02:37:58,674 INFO org.apache.hadoop.yarn.server.resourcemanager.RMAuditLogger: USER=ubuntu	OPERATION=AM Allocated Container	TARGET=SchedulerApp	RESULT=SUCCESS	APPID=application_1375842659078_0004	CONTAINERID=container_1375842659078_0004_01_000003
2013-08-07 02:37:58,674 INFO org.apache.hadoop.yarn.server.resourcemanager.scheduler.common.fica.FiCaSchedulerNode: Assigned container container_1375842659078_0004_01_000003 of capacity <memory:1024, vCores:1> on host hadoop-200-6:44827, which currently has 1 containers, <memory:1024, vCores:1> used and <memory:7168, vCores:15> available
2013-08-07 02:37:58,676 INFO org.apache.hadoop.yarn.server.resourcemanager.scheduler.capacity.LeafQueue: assignedContainer application=application_1375842659078_0004 container=Container: [ContainerId: container_1375842659078_0004_01_000003, NodeId: hadoop-200-6:44827, NodeHttpAddress: hadoop-200-6:8042, Resource: <memory:1024, vCores:1>, Priority: 20, State: NEW, Token: null, Status: container_id {, app_attempt_id {, application_id {, id: 4, cluster_timestamp: 1375842659078, }, attemptId: 1, }, id: 3, }, state: C_NEW, ] containerId=container_1375842659078_0004_01_000003 queue=default: capacity=1.0, absoluteCapacity=1.0, usedResources=<memory:3072, vCores:2>usedCapacity=0.0625, absoluteUsedCapacity=0.0625, numApps=1, numContainers=2 usedCapacity=0.0625 absoluteUsedCapacity=0.0625 used=<memory:3072, vCores:2> cluster=<memory:49152, vCores:96>
2013-08-07 02:37:58,676 INFO org.apache.hadoop.yarn.server.resourcemanager.scheduler.capacity.ParentQueue: Re-sorting queues since queue: root.default stats: default: capacity=1.0, absoluteCapacity=1.0, usedResources=<memory:4096, vCores:3>usedCapacity=0.083333336, absoluteUsedCapacity=0.083333336, numApps=1, numContainers=3
2013-08-07 02:37:58,676 INFO org.apache.hadoop.yarn.server.resourcemanager.scheduler.capacity.ParentQueue: assignedContainer queue=root usedCapacity=0.083333336 absoluteUsedCapacity=0.083333336 used=<memory:4096, vCores:3> cluster=<memory:49152, vCores:96>
2013-08-07 02:37:59,423 INFO org.apache.hadoop.yarn.server.resourcemanager.rmcontainer.RMContainerImpl: container_1375842659078_0004_01_000002 Container Transitioned from ALLOCATED to ACQUIRED
2013-08-07 02:37:59,426 INFO org.apache.hadoop.yarn.server.resourcemanager.rmcontainer.RMContainerImpl: container_1375842659078_0004_01_000003 Container Transitioned from ALLOCATED to ACQUIRED
2013-08-07 02:38:00,455 INFO org.apache.hadoop.yarn.server.resourcemanager.scheduler.AppSchedulingInfo: checking for deactivate... 
2013-08-07 02:38:00,682 INFO org.apache.hadoop.yarn.server.resourcemanager.rmcontainer.RMContainerImpl: container_1375842659078_0004_01_000003 Container Transitioned from ACQUIRED to RUNNING
2013-08-07 02:38:01,507 INFO org.apache.hadoop.yarn.server.resourcemanager.rmcontainer.RMContainerImpl: container_1375842659078_0004_01_000002 Container Transitioned from ACQUIRED to RUNNING
2013-08-07 02:39:45,296 INFO org.apache.hadoop.yarn.server.resourcemanager.rmcontainer.RMContainerImpl: container_1375842659078_0004_01_000003 Container Transitioned from RUNNING to COMPLETED
2013-08-07 02:39:45,296 INFO org.apache.hadoop.yarn.server.resourcemanager.scheduler.common.fica.FiCaSchedulerApp: Completed container: container_1375842659078_0004_01_000003 in state: COMPLETED event:FINISHED
2013-08-07 02:39:45,296 INFO org.apache.hadoop.yarn.server.resourcemanager.RMAuditLogger: USER=ubuntu	OPERATION=AM Released Container	TARGET=SchedulerApp	RESULT=SUCCESS	APPID=application_1375842659078_0004	CONTAINERID=container_1375842659078_0004_01_000003
2013-08-07 02:39:45,296 INFO org.apache.hadoop.yarn.server.resourcemanager.scheduler.common.fica.FiCaSchedulerNode: Released container container_1375842659078_0004_01_000003 of capacity <memory:1024, vCores:1> on host hadoop-200-6:44827, which currently has 0 containers, <memory:0, vCores:0> used and <memory:8192, vCores:16> available, release resources=true
2013-08-07 02:39:45,297 INFO org.apache.hadoop.yarn.server.resourcemanager.scheduler.capacity.LeafQueue: default used=<memory:3072, vCores:2> numContainers=2 user=ubuntu user-resources=<memory:3072, vCores:2>
2013-08-07 02:39:45,298 INFO org.apache.hadoop.yarn.server.resourcemanager.scheduler.capacity.LeafQueue: completedContainer container=Container: [ContainerId: container_1375842659078_0004_01_000003, NodeId: hadoop-200-6:44827, NodeHttpAddress: hadoop-200-6:8042, Resource: <memory:1024, vCores:1>, Priority: 20, State: NEW, Token: null, Status: container_id {, app_attempt_id {, application_id {, id: 4, cluster_timestamp: 1375842659078, }, attemptId: 1, }, id: 3, }, state: C_COMPLETE, diagnostics: "Container killed by the ApplicationMaster.\n\n", exit_status: 143, ] resource=<memory:1024, vCores:1> queue=default: capacity=1.0, absoluteCapacity=1.0, usedResources=<memory:3072, vCores:2>usedCapacity=0.0625, absoluteUsedCapacity=0.0625, numApps=1, numContainers=2 usedCapacity=0.0625 absoluteUsedCapacity=0.0625 used=<memory:3072, vCores:2> cluster=<memory:49152, vCores:96>
2013-08-07 02:39:45,298 INFO org.apache.hadoop.yarn.server.resourcemanager.scheduler.capacity.ParentQueue: completedContainer queue=root usedCapacity=0.0625 absoluteUsedCapacity=0.0625 used=<memory:3072, vCores:2> cluster=<memory:49152, vCores:96>
2013-08-07 02:39:45,299 INFO org.apache.hadoop.yarn.server.resourcemanager.scheduler.capacity.CapacityScheduler: Application appattempt_1375842659078_0004_000001 released container container_1375842659078_0004_01_000003 on node: host: hadoop-200-6:44827 #containers=0 available=8192 used=0 with event: FINISHED
2013-08-07 02:39:49,381 INFO org.apache.hadoop.yarn.server.resourcemanager.rmcontainer.RMContainerImpl: container_1375842659078_0004_01_000002 Container Transitioned from RUNNING to COMPLETED
2013-08-07 02:39:49,381 INFO org.apache.hadoop.yarn.server.resourcemanager.scheduler.common.fica.FiCaSchedulerApp: Completed container: container_1375842659078_0004_01_000002 in state: COMPLETED event:FINISHED
2013-08-07 02:39:49,381 INFO org.apache.hadoop.yarn.server.resourcemanager.RMAuditLogger: USER=ubuntu	OPERATION=AM Released Container	TARGET=SchedulerApp	RESULT=SUCCESS	APPID=application_1375842659078_0004	CONTAINERID=container_1375842659078_0004_01_000002
2013-08-07 02:39:49,381 INFO org.apache.hadoop.yarn.server.resourcemanager.scheduler.common.fica.FiCaSchedulerNode: Released container container_1375842659078_0004_01_000002 of capacity <memory:1024, vCores:1> on host hadoop-200-4:56924, which currently has 0 containers, <memory:0, vCores:0> used and <memory:8192, vCores:16> available, release resources=true
2013-08-07 02:39:49,381 INFO org.apache.hadoop.yarn.server.resourcemanager.scheduler.capacity.LeafQueue: default used=<memory:2048, vCores:1> numContainers=1 user=ubuntu user-resources=<memory:2048, vCores:1>
2013-08-07 02:39:49,383 INFO org.apache.hadoop.yarn.server.resourcemanager.scheduler.capacity.LeafQueue: completedContainer container=Container: [ContainerId: container_1375842659078_0004_01_000002, NodeId: hadoop-200-4:56924, NodeHttpAddress: hadoop-200-4:8042, Resource: <memory:1024, vCores:1>, Priority: 20, State: NEW, Token: null, Status: container_id {, app_attempt_id {, application_id {, id: 4, cluster_timestamp: 1375842659078, }, attemptId: 1, }, id: 2, }, state: C_COMPLETE, diagnostics: "Container killed by the ApplicationMaster.\n\n", exit_status: 143, ] resource=<memory:1024, vCores:1> queue=default: capacity=1.0, absoluteCapacity=1.0, usedResources=<memory:2048, vCores:1>usedCapacity=0.041666668, absoluteUsedCapacity=0.041666668, numApps=1, numContainers=1 usedCapacity=0.041666668 absoluteUsedCapacity=0.041666668 used=<memory:2048, vCores:1> cluster=<memory:49152, vCores:96>
2013-08-07 02:39:49,383 INFO org.apache.hadoop.yarn.server.resourcemanager.scheduler.capacity.ParentQueue: completedContainer queue=root usedCapacity=0.041666668 absoluteUsedCapacity=0.041666668 used=<memory:2048, vCores:1> cluster=<memory:49152, vCores:96>
2013-08-07 02:39:49,384 INFO org.apache.hadoop.yarn.server.resourcemanager.scheduler.capacity.CapacityScheduler: Application appattempt_1375842659078_0004_000001 released container container_1375842659078_0004_01_000002 on node: host: hadoop-200-4:56924 #containers=0 available=8192 used=0 with event: FINISHED
2013-08-07 02:39:53,566 INFO org.apache.hadoop.yarn.server.resourcemanager.rmapp.attempt.RMAppAttemptImpl: appattempt_1375842659078_0004_000001 State change from RUNNING to FINISHING
2013-08-07 02:39:53,567 INFO org.apache.hadoop.yarn.server.resourcemanager.rmapp.RMAppImpl: application_1375842659078_0004 State change from RUNNING to FINISHING
2013-08-07 02:39:53,857 INFO org.apache.hadoop.yarn.server.resourcemanager.rmcontainer.RMContainerImpl: container_1375842659078_0004_01_000001 Container Transitioned from RUNNING to COMPLETED
2013-08-07 02:39:53,857 INFO org.apache.hadoop.yarn.server.resourcemanager.scheduler.common.fica.FiCaSchedulerApp: Completed container: container_1375842659078_0004_01_000001 in state: COMPLETED event:FINISHED
2013-08-07 02:39:53,857 INFO org.apache.hadoop.yarn.server.resourcemanager.RMAuditLogger: USER=ubuntu	OPERATION=AM Released Container	TARGET=SchedulerApp	RESULT=SUCCESS	APPID=application_1375842659078_0004	CONTAINERID=container_1375842659078_0004_01_000001
2013-08-07 02:39:53,858 INFO org.apache.hadoop.yarn.server.resourcemanager.scheduler.common.fica.FiCaSchedulerNode: Released container container_1375842659078_0004_01_000001 of capacity <memory:2048, vCores:1> on host hadoop-200-5:38287, which currently has 0 containers, <memory:0, vCores:0> used and <memory:8192, vCores:16> available, release resources=true
2013-08-07 02:39:53,858 INFO org.apache.hadoop.yarn.server.resourcemanager.scheduler.capacity.LeafQueue: default used=<memory:0, vCores:0> numContainers=0 user=ubuntu user-resources=<memory:0, vCores:0>
2013-08-07 02:39:53,859 INFO org.apache.hadoop.yarn.server.resourcemanager.scheduler.capacity.LeafQueue: completedContainer container=Container: [ContainerId: container_1375842659078_0004_01_000001, NodeId: hadoop-200-5:38287, NodeHttpAddress: hadoop-200-5:8042, Resource: <memory:2048, vCores:1>, Priority: 0, State: NEW, Token: null, Status: container_id {, app_attempt_id {, application_id {, id: 4, cluster_timestamp: 1375842659078, }, attemptId: 1, }, id: 1, }, state: C_COMPLETE, diagnostics: "", exit_status: 0, ] resource=<memory:2048, vCores:1> queue=default: capacity=1.0, absoluteCapacity=1.0, usedResources=<memory:0, vCores:0>usedCapacity=0.0, absoluteUsedCapacity=0.0, numApps=1, numContainers=0 usedCapacity=0.0 absoluteUsedCapacity=0.0 used=<memory:0, vCores:0> cluster=<memory:49152, vCores:96>
2013-08-07 02:39:53,859 INFO org.apache.hadoop.yarn.server.resourcemanager.scheduler.capacity.ParentQueue: completedContainer queue=root usedCapacity=0.0 absoluteUsedCapacity=0.0 used=<memory:0, vCores:0> cluster=<memory:49152, vCores:96>
2013-08-07 02:39:53,860 INFO org.apache.hadoop.yarn.server.resourcemanager.scheduler.capacity.CapacityScheduler: Application appattempt_1375842659078_0004_000001 released container container_1375842659078_0004_01_000001 on node: host: hadoop-200-5:38287 #containers=0 available=8192 used=0 with event: FINISHED
2013-08-07 02:39:53,860 INFO org.apache.hadoop.yarn.server.resourcemanager.rmapp.attempt.RMAppAttemptImpl: appattempt_1375842659078_0004_000001 State change from FINISHING to FINISHED
2013-08-07 02:39:53,860 INFO org.apache.hadoop.yarn.server.resourcemanager.rmapp.RMAppImpl: application_1375842659078_0004 State change from FINISHING to FINISHED
2013-08-07 02:39:53,861 INFO org.apache.hadoop.yarn.server.resourcemanager.scheduler.capacity.CapacityScheduler: Application appattempt_1375842659078_0004_000001 is done. finalState=FINISHED
2013-08-07 02:39:53,861 INFO org.apache.hadoop.yarn.server.resourcemanager.scheduler.AppSchedulingInfo: Application application_1375842659078_0004 requests cleared
2013-08-07 02:39:53,861 INFO org.apache.hadoop.yarn.server.resourcemanager.scheduler.capacity.LeafQueue: Application removed - appId: application_1375842659078_0004 user: ubuntu queue: default #user-pending-applications: 0 #user-active-applications: 0 #queue-pending-applications: 0 #queue-active-applications: 0
2013-08-07 02:39:53,861 INFO org.apache.hadoop.yarn.server.resourcemanager.scheduler.capacity.ParentQueue: Application removed - appId: application_1375842659078_0004 user: ubuntu leaf-queue of parent: root #applications: 0
2013-08-07 02:39:53,862 INFO org.apache.hadoop.yarn.server.resourcemanager.RMAuditLogger: USER=ubuntu	OPERATION=Application Finished - Succeeded	TARGET=RMAppManager	RESULT=SUCCESS	APPID=application_1375842659078_0004
2013-08-07 02:39:53,862 INFO org.apache.hadoop.yarn.server.resourcemanager.amlauncher.AMLauncher: Cleaning master appattempt_1375842659078_0004_000001
2013-08-07 02:39:53,862 INFO org.apache.hadoop.yarn.server.resourcemanager.recovery.RMStateStore: Removing info for app: application_1375842659078_0004
2013-08-07 02:39:53,863 INFO org.apache.hadoop.yarn.server.resourcemanager.RMAppManager$ApplicationSummary: appId=application_1375842659078_0004,name=TeraGen,user=ubuntu,queue=default,state=FINISHED,trackingUrl=hadoop-200-1.novalocal:8088/proxy/application_1375842659078_0004/jobhistory/job/job_1375842659078_0004,appMasterHost=hadoop-200-5,startTime=1375843068167,finishTime=1375843193566
2013-08-07 02:39:54,452 INFO org.apache.hadoop.yarn.server.resourcemanager.ClientRMService: Allocated new applicationId: 5
2013-08-07 02:39:56,451 INFO org.apache.hadoop.yarn.server.resourcemanager.ClientRMService: Storing Application with id application_1375842659078_0005
2013-08-07 02:39:56,452 INFO org.apache.hadoop.yarn.server.resourcemanager.recovery.RMStateStore: Storing info for app: application_1375842659078_0005
2013-08-07 02:39:56,452 INFO org.apache.hadoop.yarn.server.resourcemanager.ClientRMService: Application with id 5 submitted by user ubuntu
2013-08-07 02:39:56,452 INFO org.apache.hadoop.yarn.server.resourcemanager.RMAuditLogger: USER=ubuntu	IP=192.168.100.2	OPERATION=Submit Application Request	TARGET=ClientRMService	RESULT=SUCCESS	APPID=application_1375842659078_0005
2013-08-07 02:39:56,453 INFO org.apache.hadoop.yarn.server.resourcemanager.rmapp.RMAppImpl: application_1375842659078_0005 State change from NEW to SUBMITTED
2013-08-07 02:39:56,453 INFO org.apache.hadoop.yarn.server.resourcemanager.ApplicationMasterService: Registering appattempt_1375842659078_0005_000001
2013-08-07 02:39:56,453 INFO org.apache.hadoop.yarn.server.resourcemanager.rmapp.attempt.RMAppAttemptImpl: appattempt_1375842659078_0005_000001 State change from NEW to SUBMITTED
2013-08-07 02:39:56,454 INFO org.apache.hadoop.yarn.server.resourcemanager.scheduler.capacity.LeafQueue: Application application_1375842659078_0005 from user: ubuntu activated in queue: default
2013-08-07 02:39:56,454 INFO org.apache.hadoop.yarn.server.resourcemanager.scheduler.capacity.LeafQueue: Application added - appId: application_1375842659078_0005 user: org.apache.hadoop.yarn.server.resourcemanager.scheduler.capacity.LeafQueue$User@6e9cb89b, leaf-queue: default #user-pending-applications: 0 #user-active-applications: 1 #queue-pending-applications: 0 #queue-active-applications: 1
2013-08-07 02:39:56,454 INFO org.apache.hadoop.yarn.server.resourcemanager.scheduler.capacity.ParentQueue: Application added - appId: application_1375842659078_0005 user: ubuntu leaf-queue of parent: root #applications: 1
2013-08-07 02:39:56,454 INFO org.apache.hadoop.yarn.server.resourcemanager.scheduler.capacity.CapacityScheduler: Application Submission: appattempt_1375842659078_0005_000001, user: ubuntu queue: default: capacity=1.0, absoluteCapacity=1.0, usedResources=<memory:0, vCores:0>usedCapacity=0.0, absoluteUsedCapacity=0.0, numApps=1, numContainers=0, currently active: 1
2013-08-07 02:39:56,455 INFO org.apache.hadoop.yarn.server.resourcemanager.rmapp.attempt.RMAppAttemptImpl: appattempt_1375842659078_0005_000001 State change from SUBMITTED to SCHEDULED
2013-08-07 02:39:56,455 INFO org.apache.hadoop.yarn.server.resourcemanager.rmapp.RMAppImpl: application_1375842659078_0005 State change from SUBMITTED to ACCEPTED
2013-08-07 02:39:56,713 INFO org.apache.hadoop.yarn.server.resourcemanager.rmcontainer.RMContainerImpl: container_1375842659078_0005_01_000001 Container Transitioned from NEW to ALLOCATED
2013-08-07 02:39:56,713 INFO org.apache.hadoop.yarn.server.resourcemanager.RMAuditLogger: USER=ubuntu	OPERATION=AM Allocated Container	TARGET=SchedulerApp	RESULT=SUCCESS	APPID=application_1375842659078_0005	CONTAINERID=container_1375842659078_0005_01_000001
2013-08-07 02:39:56,713 INFO org.apache.hadoop.yarn.server.resourcemanager.scheduler.common.fica.FiCaSchedulerNode: Assigned container container_1375842659078_0005_01_000001 of capacity <memory:2048, vCores:1> on host hadoop-200-3:34020, which currently has 1 containers, <memory:2048, vCores:1> used and <memory:6144, vCores:15> available
2013-08-07 02:39:56,714 INFO org.apache.hadoop.yarn.server.resourcemanager.scheduler.capacity.LeafQueue: assignedContainer application=application_1375842659078_0005 container=Container: [ContainerId: container_1375842659078_0005_01_000001, NodeId: hadoop-200-3:34020, NodeHttpAddress: hadoop-200-3:8042, Resource: <memory:2048, vCores:1>, Priority: 0, State: NEW, Token: null, Status: container_id {, app_attempt_id {, application_id {, id: 5, cluster_timestamp: 1375842659078, }, attemptId: 1, }, id: 1, }, state: C_NEW, ] containerId=container_1375842659078_0005_01_000001 queue=default: capacity=1.0, absoluteCapacity=1.0, usedResources=<memory:0, vCores:0>usedCapacity=0.0, absoluteUsedCapacity=0.0, numApps=1, numContainers=0 usedCapacity=0.0 absoluteUsedCapacity=0.0 used=<memory:0, vCores:0> cluster=<memory:49152, vCores:96>
2013-08-07 02:39:56,715 INFO org.apache.hadoop.yarn.server.resourcemanager.scheduler.capacity.ParentQueue: Re-sorting queues since queue: root.default stats: default: capacity=1.0, absoluteCapacity=1.0, usedResources=<memory:2048, vCores:1>usedCapacity=0.041666668, absoluteUsedCapacity=0.041666668, numApps=1, numContainers=1
2013-08-07 02:39:56,715 INFO org.apache.hadoop.yarn.server.resourcemanager.scheduler.capacity.ParentQueue: assignedContainer queue=root usedCapacity=0.041666668 absoluteUsedCapacity=0.041666668 used=<memory:2048, vCores:1> cluster=<memory:49152, vCores:96>
2013-08-07 02:39:56,717 INFO org.apache.hadoop.yarn.server.resourcemanager.rmcontainer.RMContainerImpl: container_1375842659078_0005_01_000001 Container Transitioned from ALLOCATED to ACQUIRED
2013-08-07 02:39:56,718 INFO org.apache.hadoop.yarn.server.resourcemanager.rmapp.attempt.RMAppAttemptImpl: Storing attempt: AppId: application_1375842659078_0005 AttemptId: appattempt_1375842659078_0005_000001 MasterContainer: Container: [ContainerId: container_1375842659078_0005_01_000001, NodeId: hadoop-200-3:34020, NodeHttpAddress: hadoop-200-3:8042, Resource: <memory:2048, vCores:1>, Priority: 0, State: NEW, Token: null, Status: container_id {, app_attempt_id {, application_id {, id: 5, cluster_timestamp: 1375842659078, }, attemptId: 1, }, id: 1, }, state: C_NEW, ]
2013-08-07 02:39:56,719 INFO org.apache.hadoop.yarn.server.resourcemanager.rmapp.attempt.RMAppAttemptImpl: appattempt_1375842659078_0005_000001 State change from SCHEDULED to ALLOCATED_SAVING
2013-08-07 02:39:56,719 INFO org.apache.hadoop.yarn.server.resourcemanager.recovery.RMStateStore: Storing info for attempt: appattempt_1375842659078_0005_000001
2013-08-07 02:39:56,720 INFO org.apache.hadoop.yarn.server.resourcemanager.rmapp.attempt.RMAppAttemptImpl: appattempt_1375842659078_0005_000001 State change from ALLOCATED_SAVING to ALLOCATED
2013-08-07 02:39:56,721 INFO org.apache.hadoop.yarn.server.resourcemanager.amlauncher.AMLauncher: Launching masterappattempt_1375842659078_0005_000001
2013-08-07 02:39:56,724 INFO org.apache.hadoop.yarn.server.resourcemanager.amlauncher.AMLauncher: Setting up container Container: [ContainerId: container_1375842659078_0005_01_000001, NodeId: hadoop-200-3:34020, NodeHttpAddress: hadoop-200-3:8042, Resource: <memory:2048, vCores:1>, Priority: 0, State: NEW, Token: null, Status: container_id {, app_attempt_id {, application_id {, id: 5, cluster_timestamp: 1375842659078, }, attemptId: 1, }, id: 1, }, state: C_NEW, ] for AM appattempt_1375842659078_0005_000001
2013-08-07 02:39:56,724 INFO org.apache.hadoop.yarn.server.resourcemanager.amlauncher.AMLauncher: Command to launch container container_1375842659078_0005_01_000001 : $JAVA_HOME/bin/java -Dlog4j.configuration=container-log4j.properties -Dyarn.app.mapreduce.container.log.dir=<LOG_DIR> -Dyarn.app.mapreduce.container.log.filesize=0 -Dhadoop.root.logger=INFO,CLA  -Xmx1024m org.apache.hadoop.mapreduce.v2.app.MRAppMaster 1><LOG_DIR>/stdout 2><LOG_DIR>/stderr 
2013-08-07 02:39:56,750 INFO org.apache.hadoop.yarn.server.resourcemanager.amlauncher.AMLauncher: Done launching container Container: [ContainerId: container_1375842659078_0005_01_000001, NodeId: hadoop-200-3:34020, NodeHttpAddress: hadoop-200-3:8042, Resource: <memory:2048, vCores:1>, Priority: 0, State: NEW, Token: null, Status: container_id {, app_attempt_id {, application_id {, id: 5, cluster_timestamp: 1375842659078, }, attemptId: 1, }, id: 1, }, state: C_NEW, ] for AM appattempt_1375842659078_0005_000001
2013-08-07 02:39:56,751 INFO org.apache.hadoop.yarn.server.resourcemanager.rmapp.attempt.RMAppAttemptImpl: appattempt_1375842659078_0005_000001 State change from ALLOCATED to LAUNCHED
2013-08-07 02:39:57,719 INFO org.apache.hadoop.yarn.server.resourcemanager.rmcontainer.RMContainerImpl: container_1375842659078_0005_01_000001 Container Transitioned from ACQUIRED to RUNNING
2013-08-07 02:40:06,030 INFO org.apache.hadoop.yarn.server.resourcemanager.ApplicationMasterService: AM registration appattempt_1375842659078_0005_000001
2013-08-07 02:40:06,030 INFO org.apache.hadoop.yarn.server.resourcemanager.RMAuditLogger: USER=ubuntu	IP=192.168.100.4	OPERATION=Register App Master	TARGET=ApplicationMasterService	RESULT=SUCCESS	APPID=application_1375842659078_0005	APPATTEMPTID=appattempt_1375842659078_0005_000001
2013-08-07 02:40:06,031 INFO org.apache.hadoop.yarn.server.resourcemanager.rmapp.attempt.RMAppAttemptImpl: appattempt_1375842659078_0005_000001 State change from LAUNCHED to RUNNING
2013-08-07 02:40:06,036 INFO org.apache.hadoop.yarn.server.resourcemanager.rmapp.RMAppImpl: application_1375842659078_0005 State change from ACCEPTED to RUNNING
2013-08-07 02:40:07,290 INFO org.apache.hadoop.yarn.server.resourcemanager.rmcontainer.RMContainerImpl: container_1375842659078_0005_01_000002 Container Transitioned from NEW to ALLOCATED
2013-08-07 02:40:07,290 INFO org.apache.hadoop.yarn.server.resourcemanager.RMAuditLogger: USER=ubuntu	OPERATION=AM Allocated Container	TARGET=SchedulerApp	RESULT=SUCCESS	APPID=application_1375842659078_0005	CONTAINERID=container_1375842659078_0005_01_000002
2013-08-07 02:40:07,290 INFO org.apache.hadoop.yarn.server.resourcemanager.scheduler.common.fica.FiCaSchedulerNode: Assigned container container_1375842659078_0005_01_000002 of capacity <memory:1024, vCores:1> on host hadoop-200-7:59851, which currently has 1 containers, <memory:1024, vCores:1> used and <memory:7168, vCores:15> available
2013-08-07 02:40:07,291 INFO org.apache.hadoop.yarn.server.resourcemanager.scheduler.capacity.LeafQueue: assignedContainer application=application_1375842659078_0005 container=Container: [ContainerId: container_1375842659078_0005_01_000002, NodeId: hadoop-200-7:59851, NodeHttpAddress: hadoop-200-7:8042, Resource: <memory:1024, vCores:1>, Priority: 20, State: NEW, Token: null, Status: container_id {, app_attempt_id {, application_id {, id: 5, cluster_timestamp: 1375842659078, }, attemptId: 1, }, id: 2, }, state: C_NEW, ] containerId=container_1375842659078_0005_01_000002 queue=default: capacity=1.0, absoluteCapacity=1.0, usedResources=<memory:2048, vCores:1>usedCapacity=0.041666668, absoluteUsedCapacity=0.041666668, numApps=1, numContainers=1 usedCapacity=0.041666668 absoluteUsedCapacity=0.041666668 used=<memory:2048, vCores:1> cluster=<memory:49152, vCores:96>
2013-08-07 02:40:07,292 INFO org.apache.hadoop.yarn.server.resourcemanager.scheduler.capacity.ParentQueue: Re-sorting queues since queue: root.default stats: default: capacity=1.0, absoluteCapacity=1.0, usedResources=<memory:3072, vCores:2>usedCapacity=0.0625, absoluteUsedCapacity=0.0625, numApps=1, numContainers=2
2013-08-07 02:40:07,292 INFO org.apache.hadoop.yarn.server.resourcemanager.scheduler.capacity.ParentQueue: assignedContainer queue=root usedCapacity=0.0625 absoluteUsedCapacity=0.0625 used=<memory:3072, vCores:2> cluster=<memory:49152, vCores:96>
2013-08-07 02:40:07,367 INFO org.apache.hadoop.yarn.server.resourcemanager.rmcontainer.RMContainerImpl: container_1375842659078_0005_01_000003 Container Transitioned from NEW to ALLOCATED
2013-08-07 02:40:07,367 INFO org.apache.hadoop.yarn.server.resourcemanager.RMAuditLogger: USER=ubuntu	OPERATION=AM Allocated Container	TARGET=SchedulerApp	RESULT=SUCCESS	APPID=application_1375842659078_0005	CONTAINERID=container_1375842659078_0005_01_000003
2013-08-07 02:40:07,367 INFO org.apache.hadoop.yarn.server.resourcemanager.scheduler.common.fica.FiCaSchedulerNode: Assigned container container_1375842659078_0005_01_000003 of capacity <memory:1024, vCores:1> on host hadoop-200-6:44827, which currently has 1 containers, <memory:1024, vCores:1> used and <memory:7168, vCores:15> available
2013-08-07 02:40:07,369 INFO org.apache.hadoop.yarn.server.resourcemanager.scheduler.capacity.LeafQueue: assignedContainer application=application_1375842659078_0005 container=Container: [ContainerId: container_1375842659078_0005_01_000003, NodeId: hadoop-200-6:44827, NodeHttpAddress: hadoop-200-6:8042, Resource: <memory:1024, vCores:1>, Priority: 20, State: NEW, Token: null, Status: container_id {, app_attempt_id {, application_id {, id: 5, cluster_timestamp: 1375842659078, }, attemptId: 1, }, id: 3, }, state: C_NEW, ] containerId=container_1375842659078_0005_01_000003 queue=default: capacity=1.0, absoluteCapacity=1.0, usedResources=<memory:3072, vCores:2>usedCapacity=0.0625, absoluteUsedCapacity=0.0625, numApps=1, numContainers=2 usedCapacity=0.0625 absoluteUsedCapacity=0.0625 used=<memory:3072, vCores:2> cluster=<memory:49152, vCores:96>
2013-08-07 02:40:07,369 INFO org.apache.hadoop.yarn.server.resourcemanager.scheduler.capacity.ParentQueue: Re-sorting queues since queue: root.default stats: default: capacity=1.0, absoluteCapacity=1.0, usedResources=<memory:4096, vCores:3>usedCapacity=0.083333336, absoluteUsedCapacity=0.083333336, numApps=1, numContainers=3
2013-08-07 02:40:07,369 INFO org.apache.hadoop.yarn.server.resourcemanager.scheduler.capacity.ParentQueue: assignedContainer queue=root usedCapacity=0.083333336 absoluteUsedCapacity=0.083333336 used=<memory:4096, vCores:3> cluster=<memory:49152, vCores:96>
2013-08-07 02:40:08,098 INFO org.apache.hadoop.yarn.server.resourcemanager.rmcontainer.RMContainerImpl: container_1375842659078_0005_01_000002 Container Transitioned from ALLOCATED to ACQUIRED
2013-08-07 02:40:08,100 INFO org.apache.hadoop.yarn.server.resourcemanager.rmcontainer.RMContainerImpl: container_1375842659078_0005_01_000003 Container Transitioned from ALLOCATED to ACQUIRED
2013-08-07 02:40:08,372 INFO org.apache.hadoop.yarn.server.resourcemanager.rmcontainer.RMContainerImpl: container_1375842659078_0005_01_000003 Container Transitioned from ACQUIRED to RUNNING
2013-08-07 02:40:09,136 INFO org.apache.hadoop.yarn.server.resourcemanager.scheduler.AppSchedulingInfo: checking for deactivate... 
2013-08-07 02:40:09,298 INFO org.apache.hadoop.yarn.server.resourcemanager.rmcontainer.RMContainerImpl: container_1375842659078_0005_01_000002 Container Transitioned from ACQUIRED to RUNNING
2013-08-07 02:41:48,674 INFO org.apache.hadoop.yarn.server.resourcemanager.rmcontainer.RMContainerImpl: container_1375842659078_0005_01_000003 Container Transitioned from RUNNING to COMPLETED
2013-08-07 02:41:48,675 INFO org.apache.hadoop.yarn.server.resourcemanager.scheduler.common.fica.FiCaSchedulerApp: Completed container: container_1375842659078_0005_01_000003 in state: COMPLETED event:FINISHED
2013-08-07 02:41:48,675 INFO org.apache.hadoop.yarn.server.resourcemanager.RMAuditLogger: USER=ubuntu	OPERATION=AM Released Container	TARGET=SchedulerApp	RESULT=SUCCESS	APPID=application_1375842659078_0005	CONTAINERID=container_1375842659078_0005_01_000003
2013-08-07 02:41:48,675 INFO org.apache.hadoop.yarn.server.resourcemanager.scheduler.common.fica.FiCaSchedulerNode: Released container container_1375842659078_0005_01_000003 of capacity <memory:1024, vCores:1> on host hadoop-200-6:44827, which currently has 0 containers, <memory:0, vCores:0> used and <memory:8192, vCores:16> available, release resources=true
2013-08-07 02:41:48,675 INFO org.apache.hadoop.yarn.server.resourcemanager.scheduler.capacity.LeafQueue: default used=<memory:3072, vCores:2> numContainers=2 user=ubuntu user-resources=<memory:3072, vCores:2>
2013-08-07 02:41:48,677 INFO org.apache.hadoop.yarn.server.resourcemanager.scheduler.capacity.LeafQueue: completedContainer container=Container: [ContainerId: container_1375842659078_0005_01_000003, NodeId: hadoop-200-6:44827, NodeHttpAddress: hadoop-200-6:8042, Resource: <memory:1024, vCores:1>, Priority: 20, State: NEW, Token: null, Status: container_id {, app_attempt_id {, application_id {, id: 5, cluster_timestamp: 1375842659078, }, attemptId: 1, }, id: 3, }, state: C_COMPLETE, diagnostics: "Container killed by the ApplicationMaster.\n\n", exit_status: 143, ] resource=<memory:1024, vCores:1> queue=default: capacity=1.0, absoluteCapacity=1.0, usedResources=<memory:3072, vCores:2>usedCapacity=0.0625, absoluteUsedCapacity=0.0625, numApps=1, numContainers=2 usedCapacity=0.0625 absoluteUsedCapacity=0.0625 used=<memory:3072, vCores:2> cluster=<memory:49152, vCores:96>
2013-08-07 02:41:48,677 INFO org.apache.hadoop.yarn.server.resourcemanager.scheduler.capacity.ParentQueue: completedContainer queue=root usedCapacity=0.0625 absoluteUsedCapacity=0.0625 used=<memory:3072, vCores:2> cluster=<memory:49152, vCores:96>
2013-08-07 02:41:48,677 INFO org.apache.hadoop.yarn.server.resourcemanager.scheduler.capacity.CapacityScheduler: Application appattempt_1375842659078_0005_000001 released container container_1375842659078_0005_01_000003 on node: host: hadoop-200-6:44827 #containers=0 available=8192 used=0 with event: FINISHED
2013-08-07 02:41:52,349 INFO org.apache.hadoop.yarn.server.resourcemanager.rmcontainer.RMContainerImpl: container_1375842659078_0005_01_000002 Container Transitioned from RUNNING to COMPLETED
2013-08-07 02:41:52,349 INFO org.apache.hadoop.yarn.server.resourcemanager.scheduler.common.fica.FiCaSchedulerApp: Completed container: container_1375842659078_0005_01_000002 in state: COMPLETED event:FINISHED
2013-08-07 02:41:52,349 INFO org.apache.hadoop.yarn.server.resourcemanager.RMAuditLogger: USER=ubuntu	OPERATION=AM Released Container	TARGET=SchedulerApp	RESULT=SUCCESS	APPID=application_1375842659078_0005	CONTAINERID=container_1375842659078_0005_01_000002
2013-08-07 02:41:52,350 INFO org.apache.hadoop.yarn.server.resourcemanager.scheduler.common.fica.FiCaSchedulerNode: Released container container_1375842659078_0005_01_000002 of capacity <memory:1024, vCores:1> on host hadoop-200-7:59851, which currently has 0 containers, <memory:0, vCores:0> used and <memory:8192, vCores:16> available, release resources=true
2013-08-07 02:41:52,350 INFO org.apache.hadoop.yarn.server.resourcemanager.scheduler.capacity.LeafQueue: default used=<memory:2048, vCores:1> numContainers=1 user=ubuntu user-resources=<memory:2048, vCores:1>
2013-08-07 02:41:52,351 INFO org.apache.hadoop.yarn.server.resourcemanager.scheduler.capacity.LeafQueue: completedContainer container=Container: [ContainerId: container_1375842659078_0005_01_000002, NodeId: hadoop-200-7:59851, NodeHttpAddress: hadoop-200-7:8042, Resource: <memory:1024, vCores:1>, Priority: 20, State: NEW, Token: null, Status: container_id {, app_attempt_id {, application_id {, id: 5, cluster_timestamp: 1375842659078, }, attemptId: 1, }, id: 2, }, state: C_COMPLETE, diagnostics: "Container killed by the ApplicationMaster.\n", exit_status: 0, ] resource=<memory:1024, vCores:1> queue=default: capacity=1.0, absoluteCapacity=1.0, usedResources=<memory:2048, vCores:1>usedCapacity=0.041666668, absoluteUsedCapacity=0.041666668, numApps=1, numContainers=1 usedCapacity=0.041666668 absoluteUsedCapacity=0.041666668 used=<memory:2048, vCores:1> cluster=<memory:49152, vCores:96>
2013-08-07 02:41:52,352 INFO org.apache.hadoop.yarn.server.resourcemanager.scheduler.capacity.ParentQueue: completedContainer queue=root usedCapacity=0.041666668 absoluteUsedCapacity=0.041666668 used=<memory:2048, vCores:1> cluster=<memory:49152, vCores:96>
2013-08-07 02:41:52,352 INFO org.apache.hadoop.yarn.server.resourcemanager.scheduler.capacity.CapacityScheduler: Application appattempt_1375842659078_0005_000001 released container container_1375842659078_0005_01_000002 on node: host: hadoop-200-7:59851 #containers=0 available=8192 used=0 with event: FINISHED
2013-08-07 02:41:56,514 INFO org.apache.hadoop.yarn.server.resourcemanager.rmapp.attempt.RMAppAttemptImpl: appattempt_1375842659078_0005_000001 State change from RUNNING to FINISHING
2013-08-07 02:41:56,515 INFO org.apache.hadoop.yarn.server.resourcemanager.rmapp.RMAppImpl: application_1375842659078_0005 State change from RUNNING to FINISHING
2013-08-07 02:41:57,437 INFO org.apache.hadoop.yarn.server.resourcemanager.rmcontainer.RMContainerImpl: container_1375842659078_0005_01_000001 Container Transitioned from RUNNING to COMPLETED
2013-08-07 02:41:57,437 INFO org.apache.hadoop.yarn.server.resourcemanager.scheduler.common.fica.FiCaSchedulerApp: Completed container: container_1375842659078_0005_01_000001 in state: COMPLETED event:FINISHED
2013-08-07 02:41:57,437 INFO org.apache.hadoop.yarn.server.resourcemanager.RMAuditLogger: USER=ubuntu	OPERATION=AM Released Container	TARGET=SchedulerApp	RESULT=SUCCESS	APPID=application_1375842659078_0005	CONTAINERID=container_1375842659078_0005_01_000001
2013-08-07 02:41:57,437 INFO org.apache.hadoop.yarn.server.resourcemanager.scheduler.common.fica.FiCaSchedulerNode: Released container container_1375842659078_0005_01_000001 of capacity <memory:2048, vCores:1> on host hadoop-200-3:34020, which currently has 0 containers, <memory:0, vCores:0> used and <memory:8192, vCores:16> available, release resources=true
2013-08-07 02:41:57,437 INFO org.apache.hadoop.yarn.server.resourcemanager.scheduler.capacity.LeafQueue: default used=<memory:0, vCores:0> numContainers=0 user=ubuntu user-resources=<memory:0, vCores:0>
2013-08-07 02:41:57,438 INFO org.apache.hadoop.yarn.server.resourcemanager.scheduler.capacity.LeafQueue: completedContainer container=Container: [ContainerId: container_1375842659078_0005_01_000001, NodeId: hadoop-200-3:34020, NodeHttpAddress: hadoop-200-3:8042, Resource: <memory:2048, vCores:1>, Priority: 0, State: NEW, Token: null, Status: container_id {, app_attempt_id {, application_id {, id: 5, cluster_timestamp: 1375842659078, }, attemptId: 1, }, id: 1, }, state: C_COMPLETE, diagnostics: "", exit_status: 0, ] resource=<memory:2048, vCores:1> queue=default: capacity=1.0, absoluteCapacity=1.0, usedResources=<memory:0, vCores:0>usedCapacity=0.0, absoluteUsedCapacity=0.0, numApps=1, numContainers=0 usedCapacity=0.0 absoluteUsedCapacity=0.0 used=<memory:0, vCores:0> cluster=<memory:49152, vCores:96>
2013-08-07 02:41:57,438 INFO org.apache.hadoop.yarn.server.resourcemanager.scheduler.capacity.ParentQueue: completedContainer queue=root usedCapacity=0.0 absoluteUsedCapacity=0.0 used=<memory:0, vCores:0> cluster=<memory:49152, vCores:96>
2013-08-07 02:41:57,438 INFO org.apache.hadoop.yarn.server.resourcemanager.scheduler.capacity.CapacityScheduler: Application appattempt_1375842659078_0005_000001 released container container_1375842659078_0005_01_000001 on node: host: hadoop-200-3:34020 #containers=0 available=8192 used=0 with event: FINISHED
2013-08-07 02:41:57,439 INFO org.apache.hadoop.yarn.server.resourcemanager.rmapp.attempt.RMAppAttemptImpl: appattempt_1375842659078_0005_000001 State change from FINISHING to FINISHED
2013-08-07 02:41:57,439 INFO org.apache.hadoop.yarn.server.resourcemanager.rmapp.RMAppImpl: application_1375842659078_0005 State change from FINISHING to FINISHED
2013-08-07 02:41:57,439 INFO org.apache.hadoop.yarn.server.resourcemanager.scheduler.capacity.CapacityScheduler: Application appattempt_1375842659078_0005_000001 is done. finalState=FINISHED
2013-08-07 02:41:57,439 INFO org.apache.hadoop.yarn.server.resourcemanager.scheduler.AppSchedulingInfo: Application application_1375842659078_0005 requests cleared
2013-08-07 02:41:57,439 INFO org.apache.hadoop.yarn.server.resourcemanager.scheduler.capacity.LeafQueue: Application removed - appId: application_1375842659078_0005 user: ubuntu queue: default #user-pending-applications: 0 #user-active-applications: 0 #queue-pending-applications: 0 #queue-active-applications: 0
2013-08-07 02:41:57,439 INFO org.apache.hadoop.yarn.server.resourcemanager.scheduler.capacity.ParentQueue: Application removed - appId: application_1375842659078_0005 user: ubuntu leaf-queue of parent: root #applications: 0
2013-08-07 02:41:57,439 INFO org.apache.hadoop.yarn.server.resourcemanager.RMAuditLogger: USER=ubuntu	OPERATION=Application Finished - Succeeded	TARGET=RMAppManager	RESULT=SUCCESS	APPID=application_1375842659078_0005
2013-08-07 02:41:57,440 INFO org.apache.hadoop.yarn.server.resourcemanager.recovery.RMStateStore: Removing info for app: application_1375842659078_0005
2013-08-07 02:41:57,440 INFO org.apache.hadoop.yarn.server.resourcemanager.RMAppManager$ApplicationSummary: appId=application_1375842659078_0005,name=TeraGen,user=ubuntu,queue=default,state=FINISHED,trackingUrl=hadoop-200-1.novalocal:8088/proxy/application_1375842659078_0005/jobhistory/job/job_1375842659078_0005,appMasterHost=hadoop-200-3,startTime=1375843196451,finishTime=1375843316515
2013-08-07 02:41:57,440 INFO org.apache.hadoop.yarn.server.resourcemanager.amlauncher.AMLauncher: Cleaning master appattempt_1375842659078_0005_000001
2013-08-07 02:42:01,013 INFO org.apache.hadoop.yarn.server.resourcemanager.ClientRMService: Allocated new applicationId: 6
2013-08-07 02:42:01,810 INFO org.apache.hadoop.yarn.server.resourcemanager.ClientRMService: Allocated new applicationId: 7
2013-08-07 02:42:03,401 INFO org.apache.hadoop.yarn.server.resourcemanager.ClientRMService: Allocated new applicationId: 8
2013-08-07 02:42:03,418 INFO org.apache.hadoop.yarn.server.resourcemanager.ClientRMService: Allocated new applicationId: 9
2013-08-07 02:42:03,441 INFO org.apache.hadoop.yarn.server.resourcemanager.ClientRMService: Allocated new applicationId: 10
2013-08-07 02:42:04,221 INFO org.apache.hadoop.yarn.server.resourcemanager.ClientRMService: Storing Application with id application_1375842659078_0006
2013-08-07 02:42:04,221 INFO org.apache.hadoop.yarn.server.resourcemanager.recovery.RMStateStore: Storing info for app: application_1375842659078_0006
2013-08-07 02:42:04,221 INFO org.apache.hadoop.yarn.server.resourcemanager.ClientRMService: Application with id 6 submitted by user ubuntu
2013-08-07 02:42:04,221 INFO org.apache.hadoop.yarn.server.resourcemanager.RMAuditLogger: USER=ubuntu	IP=192.168.100.2	OPERATION=Submit Application Request	TARGET=ClientRMService	RESULT=SUCCESS	APPID=application_1375842659078_0006
2013-08-07 02:42:04,222 INFO org.apache.hadoop.yarn.server.resourcemanager.rmapp.RMAppImpl: application_1375842659078_0006 State change from NEW to SUBMITTED
2013-08-07 02:42:04,222 INFO org.apache.hadoop.yarn.server.resourcemanager.ApplicationMasterService: Registering appattempt_1375842659078_0006_000001
2013-08-07 02:42:04,222 INFO org.apache.hadoop.yarn.server.resourcemanager.rmapp.attempt.RMAppAttemptImpl: appattempt_1375842659078_0006_000001 State change from NEW to SUBMITTED
2013-08-07 02:42:04,222 INFO org.apache.hadoop.yarn.server.resourcemanager.scheduler.capacity.LeafQueue: Application application_1375842659078_0006 from user: ubuntu activated in queue: default
2013-08-07 02:42:04,222 INFO org.apache.hadoop.yarn.server.resourcemanager.scheduler.capacity.LeafQueue: Application added - appId: application_1375842659078_0006 user: org.apache.hadoop.yarn.server.resourcemanager.scheduler.capacity.LeafQueue$User@26e027e7, leaf-queue: default #user-pending-applications: 0 #user-active-applications: 1 #queue-pending-applications: 0 #queue-active-applications: 1
2013-08-07 02:42:04,222 INFO org.apache.hadoop.yarn.server.resourcemanager.scheduler.capacity.ParentQueue: Application added - appId: application_1375842659078_0006 user: ubuntu leaf-queue of parent: root #applications: 1
2013-08-07 02:42:04,223 INFO org.apache.hadoop.yarn.server.resourcemanager.scheduler.capacity.CapacityScheduler: Application Submission: appattempt_1375842659078_0006_000001, user: ubuntu queue: default: capacity=1.0, absoluteCapacity=1.0, usedResources=<memory:0, vCores:0>usedCapacity=0.0, absoluteUsedCapacity=0.0, numApps=1, numContainers=0, currently active: 1
2013-08-07 02:42:04,223 INFO org.apache.hadoop.yarn.server.resourcemanager.rmapp.attempt.RMAppAttemptImpl: appattempt_1375842659078_0006_000001 State change from SUBMITTED to SCHEDULED
2013-08-07 02:42:04,223 INFO org.apache.hadoop.yarn.server.resourcemanager.rmapp.RMAppImpl: application_1375842659078_0006 State change from SUBMITTED to ACCEPTED
2013-08-07 02:42:04,294 INFO org.apache.hadoop.yarn.server.resourcemanager.ClientRMService: Storing Application with id application_1375842659078_0007
2013-08-07 02:42:04,295 INFO org.apache.hadoop.yarn.server.resourcemanager.recovery.RMStateStore: Storing info for app: application_1375842659078_0007
2013-08-07 02:42:04,295 INFO org.apache.hadoop.yarn.server.resourcemanager.ClientRMService: Application with id 7 submitted by user ubuntu
2013-08-07 02:42:04,295 INFO org.apache.hadoop.yarn.server.resourcemanager.RMAuditLogger: USER=ubuntu	IP=192.168.100.2	OPERATION=Submit Application Request	TARGET=ClientRMService	RESULT=SUCCESS	APPID=application_1375842659078_0007
2013-08-07 02:42:04,295 INFO org.apache.hadoop.yarn.server.resourcemanager.rmapp.RMAppImpl: application_1375842659078_0007 State change from NEW to SUBMITTED
2013-08-07 02:42:04,295 INFO org.apache.hadoop.yarn.server.resourcemanager.ApplicationMasterService: Registering appattempt_1375842659078_0007_000001
2013-08-07 02:42:04,295 INFO org.apache.hadoop.yarn.server.resourcemanager.rmapp.attempt.RMAppAttemptImpl: appattempt_1375842659078_0007_000001 State change from NEW to SUBMITTED
2013-08-07 02:42:04,296 INFO org.apache.hadoop.yarn.server.resourcemanager.scheduler.capacity.LeafQueue: Application application_1375842659078_0007 from user: ubuntu activated in queue: default
2013-08-07 02:42:04,296 INFO org.apache.hadoop.yarn.server.resourcemanager.scheduler.capacity.LeafQueue: Application added - appId: application_1375842659078_0007 user: org.apache.hadoop.yarn.server.resourcemanager.scheduler.capacity.LeafQueue$User@26e027e7, leaf-queue: default #user-pending-applications: 0 #user-active-applications: 2 #queue-pending-applications: 0 #queue-active-applications: 2
2013-08-07 02:42:04,296 INFO org.apache.hadoop.yarn.server.resourcemanager.scheduler.capacity.ParentQueue: Application added - appId: application_1375842659078_0007 user: ubuntu leaf-queue of parent: root #applications: 2
2013-08-07 02:42:04,296 INFO org.apache.hadoop.yarn.server.resourcemanager.scheduler.capacity.CapacityScheduler: Application Submission: appattempt_1375842659078_0007_000001, user: ubuntu queue: default: capacity=1.0, absoluteCapacity=1.0, usedResources=<memory:0, vCores:0>usedCapacity=0.0, absoluteUsedCapacity=0.0, numApps=2, numContainers=0, currently active: 2
2013-08-07 02:42:04,296 INFO org.apache.hadoop.yarn.server.resourcemanager.rmapp.attempt.RMAppAttemptImpl: appattempt_1375842659078_0007_000001 State change from SUBMITTED to SCHEDULED
2013-08-07 02:42:04,296 INFO org.apache.hadoop.yarn.server.resourcemanager.rmapp.RMAppImpl: application_1375842659078_0007 State change from SUBMITTED to ACCEPTED
2013-08-07 02:42:04,358 INFO org.apache.hadoop.yarn.server.resourcemanager.rmcontainer.RMContainerImpl: container_1375842659078_0006_01_000001 Container Transitioned from NEW to ALLOCATED
2013-08-07 02:42:04,358 INFO org.apache.hadoop.yarn.server.resourcemanager.RMAuditLogger: USER=ubuntu	OPERATION=AM Allocated Container	TARGET=SchedulerApp	RESULT=SUCCESS	APPID=application_1375842659078_0006	CONTAINERID=container_1375842659078_0006_01_000001
2013-08-07 02:42:04,358 INFO org.apache.hadoop.yarn.server.resourcemanager.scheduler.common.fica.FiCaSchedulerNode: Assigned container container_1375842659078_0006_01_000001 of capacity <memory:2048, vCores:1> on host hadoop-200-5:38287, which currently has 1 containers, <memory:2048, vCores:1> used and <memory:6144, vCores:15> available
2013-08-07 02:42:04,359 INFO org.apache.hadoop.yarn.server.resourcemanager.scheduler.capacity.LeafQueue: assignedContainer application=application_1375842659078_0006 container=Container: [ContainerId: container_1375842659078_0006_01_000001, NodeId: hadoop-200-5:38287, NodeHttpAddress: hadoop-200-5:8042, Resource: <memory:2048, vCores:1>, Priority: 0, State: NEW, Token: null, Status: container_id {, app_attempt_id {, application_id {, id: 6, cluster_timestamp: 1375842659078, }, attemptId: 1, }, id: 1, }, state: C_NEW, ] containerId=container_1375842659078_0006_01_000001 queue=default: capacity=1.0, absoluteCapacity=1.0, usedResources=<memory:0, vCores:0>usedCapacity=0.0, absoluteUsedCapacity=0.0, numApps=2, numContainers=0 usedCapacity=0.0 absoluteUsedCapacity=0.0 used=<memory:0, vCores:0> cluster=<memory:49152, vCores:96>
2013-08-07 02:42:04,359 INFO org.apache.hadoop.yarn.server.resourcemanager.scheduler.capacity.ParentQueue: Re-sorting queues since queue: root.default stats: default: capacity=1.0, absoluteCapacity=1.0, usedResources=<memory:2048, vCores:1>usedCapacity=0.041666668, absoluteUsedCapacity=0.041666668, numApps=2, numContainers=1
2013-08-07 02:42:04,359 INFO org.apache.hadoop.yarn.server.resourcemanager.scheduler.capacity.ParentQueue: assignedContainer queue=root usedCapacity=0.041666668 absoluteUsedCapacity=0.041666668 used=<memory:2048, vCores:1> cluster=<memory:49152, vCores:96>
2013-08-07 02:42:04,363 INFO org.apache.hadoop.yarn.server.resourcemanager.rmcontainer.RMContainerImpl: container_1375842659078_0006_01_000001 Container Transitioned from ALLOCATED to ACQUIRED
2013-08-07 02:42:04,364 INFO org.apache.hadoop.yarn.server.resourcemanager.rmapp.attempt.RMAppAttemptImpl: Storing attempt: AppId: application_1375842659078_0006 AttemptId: appattempt_1375842659078_0006_000001 MasterContainer: Container: [ContainerId: container_1375842659078_0006_01_000001, NodeId: hadoop-200-5:38287, NodeHttpAddress: hadoop-200-5:8042, Resource: <memory:2048, vCores:1>, Priority: 0, State: NEW, Token: null, Status: container_id {, app_attempt_id {, application_id {, id: 6, cluster_timestamp: 1375842659078, }, attemptId: 1, }, id: 1, }, state: C_NEW, ]
2013-08-07 02:42:04,364 INFO org.apache.hadoop.yarn.server.resourcemanager.recovery.RMStateStore: Storing info for attempt: appattempt_1375842659078_0006_000001
2013-08-07 02:42:04,364 INFO org.apache.hadoop.yarn.server.resourcemanager.rmapp.attempt.RMAppAttemptImpl: appattempt_1375842659078_0006_000001 State change from SCHEDULED to ALLOCATED_SAVING
2013-08-07 02:42:04,364 INFO org.apache.hadoop.yarn.server.resourcemanager.rmapp.attempt.RMAppAttemptImpl: appattempt_1375842659078_0006_000001 State change from ALLOCATED_SAVING to ALLOCATED
2013-08-07 02:42:04,364 INFO org.apache.hadoop.yarn.server.resourcemanager.amlauncher.AMLauncher: Launching masterappattempt_1375842659078_0006_000001
2013-08-07 02:42:04,422 INFO org.apache.hadoop.yarn.server.resourcemanager.amlauncher.AMLauncher: Setting up container Container: [ContainerId: container_1375842659078_0006_01_000001, NodeId: hadoop-200-5:38287, NodeHttpAddress: hadoop-200-5:8042, Resource: <memory:2048, vCores:1>, Priority: 0, State: NEW, Token: null, Status: container_id {, app_attempt_id {, application_id {, id: 6, cluster_timestamp: 1375842659078, }, attemptId: 1, }, id: 1, }, state: C_NEW, ] for AM appattempt_1375842659078_0006_000001
2013-08-07 02:42:04,422 INFO org.apache.hadoop.yarn.server.resourcemanager.amlauncher.AMLauncher: Command to launch container container_1375842659078_0006_01_000001 : $JAVA_HOME/bin/java -Dlog4j.configuration=container-log4j.properties -Dyarn.app.mapreduce.container.log.dir=<LOG_DIR> -Dyarn.app.mapreduce.container.log.filesize=0 -Dhadoop.root.logger=INFO,CLA  -Xmx1024m org.apache.hadoop.mapreduce.v2.app.MRAppMaster 1><LOG_DIR>/stdout 2><LOG_DIR>/stderr 
2013-08-07 02:42:04,434 INFO org.apache.hadoop.yarn.server.resourcemanager.rmcontainer.RMContainerImpl: container_1375842659078_0007_01_000001 Container Transitioned from NEW to ALLOCATED
2013-08-07 02:42:04,434 INFO org.apache.hadoop.yarn.server.resourcemanager.RMAuditLogger: USER=ubuntu	OPERATION=AM Allocated Container	TARGET=SchedulerApp	RESULT=SUCCESS	APPID=application_1375842659078_0007	CONTAINERID=container_1375842659078_0007_01_000001
2013-08-07 02:42:04,434 INFO org.apache.hadoop.yarn.server.resourcemanager.scheduler.common.fica.FiCaSchedulerNode: Assigned container container_1375842659078_0007_01_000001 of capacity <memory:2048, vCores:1> on host hadoop-200-7:59851, which currently has 1 containers, <memory:2048, vCores:1> used and <memory:6144, vCores:15> available
2013-08-07 02:42:04,435 INFO org.apache.hadoop.yarn.server.resourcemanager.scheduler.capacity.LeafQueue: assignedContainer application=application_1375842659078_0007 container=Container: [ContainerId: container_1375842659078_0007_01_000001, NodeId: hadoop-200-7:59851, NodeHttpAddress: hadoop-200-7:8042, Resource: <memory:2048, vCores:1>, Priority: 0, State: NEW, Token: null, Status: container_id {, app_attempt_id {, application_id {, id: 7, cluster_timestamp: 1375842659078, }, attemptId: 1, }, id: 1, }, state: C_NEW, ] containerId=container_1375842659078_0007_01_000001 queue=default: capacity=1.0, absoluteCapacity=1.0, usedResources=<memory:2048, vCores:1>usedCapacity=0.041666668, absoluteUsedCapacity=0.041666668, numApps=2, numContainers=1 usedCapacity=0.041666668 absoluteUsedCapacity=0.041666668 used=<memory:2048, vCores:1> cluster=<memory:49152, vCores:96>
2013-08-07 02:42:04,435 INFO org.apache.hadoop.yarn.server.resourcemanager.scheduler.capacity.ParentQueue: Re-sorting queues since queue: root.default stats: default: capacity=1.0, absoluteCapacity=1.0, usedResources=<memory:4096, vCores:2>usedCapacity=0.083333336, absoluteUsedCapacity=0.083333336, numApps=2, numContainers=2
2013-08-07 02:42:04,435 INFO org.apache.hadoop.yarn.server.resourcemanager.scheduler.capacity.ParentQueue: assignedContainer queue=root usedCapacity=0.083333336 absoluteUsedCapacity=0.083333336 used=<memory:4096, vCores:2> cluster=<memory:49152, vCores:96>
2013-08-07 02:42:04,442 INFO org.apache.hadoop.yarn.server.resourcemanager.rmcontainer.RMContainerImpl: container_1375842659078_0007_01_000001 Container Transitioned from ALLOCATED to ACQUIRED
2013-08-07 02:42:04,443 INFO org.apache.hadoop.yarn.server.resourcemanager.rmapp.attempt.RMAppAttemptImpl: Storing attempt: AppId: application_1375842659078_0007 AttemptId: appattempt_1375842659078_0007_000001 MasterContainer: Container: [ContainerId: container_1375842659078_0007_01_000001, NodeId: hadoop-200-7:59851, NodeHttpAddress: hadoop-200-7:8042, Resource: <memory:2048, vCores:1>, Priority: 0, State: NEW, Token: null, Status: container_id {, app_attempt_id {, application_id {, id: 7, cluster_timestamp: 1375842659078, }, attemptId: 1, }, id: 1, }, state: C_NEW, ]
2013-08-07 02:42:04,444 INFO org.apache.hadoop.yarn.server.resourcemanager.recovery.RMStateStore: Storing info for attempt: appattempt_1375842659078_0007_000001
2013-08-07 02:42:04,444 INFO org.apache.hadoop.yarn.server.resourcemanager.rmapp.attempt.RMAppAttemptImpl: appattempt_1375842659078_0007_000001 State change from SCHEDULED to ALLOCATED_SAVING
2013-08-07 02:42:04,449 INFO org.apache.hadoop.yarn.server.resourcemanager.rmapp.attempt.RMAppAttemptImpl: appattempt_1375842659078_0007_000001 State change from ALLOCATED_SAVING to ALLOCATED
2013-08-07 02:42:04,449 INFO org.apache.hadoop.yarn.server.resourcemanager.amlauncher.AMLauncher: Done launching container Container: [ContainerId: container_1375842659078_0006_01_000001, NodeId: hadoop-200-5:38287, NodeHttpAddress: hadoop-200-5:8042, Resource: <memory:2048, vCores:1>, Priority: 0, State: NEW, Token: null, Status: container_id {, app_attempt_id {, application_id {, id: 6, cluster_timestamp: 1375842659078, }, attemptId: 1, }, id: 1, }, state: C_NEW, ] for AM appattempt_1375842659078_0006_000001
2013-08-07 02:42:04,449 INFO org.apache.hadoop.yarn.server.resourcemanager.amlauncher.AMLauncher: Launching masterappattempt_1375842659078_0007_000001
2013-08-07 02:42:04,451 INFO org.apache.hadoop.yarn.server.resourcemanager.amlauncher.AMLauncher: Setting up container Container: [ContainerId: container_1375842659078_0007_01_000001, NodeId: hadoop-200-7:59851, NodeHttpAddress: hadoop-200-7:8042, Resource: <memory:2048, vCores:1>, Priority: 0, State: NEW, Token: null, Status: container_id {, app_attempt_id {, application_id {, id: 7, cluster_timestamp: 1375842659078, }, attemptId: 1, }, id: 1, }, state: C_NEW, ] for AM appattempt_1375842659078_0007_000001
2013-08-07 02:42:04,451 INFO org.apache.hadoop.yarn.server.resourcemanager.amlauncher.AMLauncher: Command to launch container container_1375842659078_0007_01_000001 : $JAVA_HOME/bin/java -Dlog4j.configuration=container-log4j.properties -Dyarn.app.mapreduce.container.log.dir=<LOG_DIR> -Dyarn.app.mapreduce.container.log.filesize=0 -Dhadoop.root.logger=INFO,CLA  -Xmx1024m org.apache.hadoop.mapreduce.v2.app.MRAppMaster 1><LOG_DIR>/stdout 2><LOG_DIR>/stderr 
2013-08-07 02:42:04,452 INFO org.apache.hadoop.yarn.server.resourcemanager.rmapp.attempt.RMAppAttemptImpl: appattempt_1375842659078_0006_000001 State change from ALLOCATED to LAUNCHED
2013-08-07 02:42:04,469 INFO org.apache.hadoop.yarn.server.resourcemanager.amlauncher.AMLauncher: Done launching container Container: [ContainerId: container_1375842659078_0007_01_000001, NodeId: hadoop-200-7:59851, NodeHttpAddress: hadoop-200-7:8042, Resource: <memory:2048, vCores:1>, Priority: 0, State: NEW, Token: null, Status: container_id {, app_attempt_id {, application_id {, id: 7, cluster_timestamp: 1375842659078, }, attemptId: 1, }, id: 1, }, state: C_NEW, ] for AM appattempt_1375842659078_0007_000001
2013-08-07 02:42:04,469 INFO org.apache.hadoop.yarn.server.resourcemanager.rmapp.attempt.RMAppAttemptImpl: appattempt_1375842659078_0007_000001 State change from ALLOCATED to LAUNCHED
2013-08-07 02:42:04,883 INFO org.apache.hadoop.yarn.server.resourcemanager.ClientRMService: Storing Application with id application_1375842659078_0008
2013-08-07 02:42:04,883 INFO org.apache.hadoop.yarn.server.resourcemanager.recovery.RMStateStore: Storing info for app: application_1375842659078_0008
2013-08-07 02:42:04,884 INFO org.apache.hadoop.yarn.server.resourcemanager.ClientRMService: Application with id 8 submitted by user ubuntu
2013-08-07 02:42:04,884 INFO org.apache.hadoop.yarn.server.resourcemanager.RMAuditLogger: USER=ubuntu	IP=192.168.100.2	OPERATION=Submit Application Request	TARGET=ClientRMService	RESULT=SUCCESS	APPID=application_1375842659078_0008
2013-08-07 02:42:04,883 INFO org.apache.hadoop.yarn.server.resourcemanager.rmapp.RMAppImpl: application_1375842659078_0008 State change from NEW to SUBMITTED
2013-08-07 02:42:04,884 INFO org.apache.hadoop.yarn.server.resourcemanager.ApplicationMasterService: Registering appattempt_1375842659078_0008_000001
2013-08-07 02:42:04,884 INFO org.apache.hadoop.yarn.server.resourcemanager.rmapp.attempt.RMAppAttemptImpl: appattempt_1375842659078_0008_000001 State change from NEW to SUBMITTED
2013-08-07 02:42:04,884 INFO org.apache.hadoop.yarn.server.resourcemanager.scheduler.capacity.LeafQueue: Application application_1375842659078_0008 from user: ubuntu activated in queue: default
2013-08-07 02:42:04,885 INFO org.apache.hadoop.yarn.server.resourcemanager.scheduler.capacity.LeafQueue: Application added - appId: application_1375842659078_0008 user: org.apache.hadoop.yarn.server.resourcemanager.scheduler.capacity.LeafQueue$User@26e027e7, leaf-queue: default #user-pending-applications: 0 #user-active-applications: 3 #queue-pending-applications: 0 #queue-active-applications: 3
2013-08-07 02:42:04,885 INFO org.apache.hadoop.yarn.server.resourcemanager.scheduler.capacity.ParentQueue: Application added - appId: application_1375842659078_0008 user: ubuntu leaf-queue of parent: root #applications: 3
2013-08-07 02:42:04,885 INFO org.apache.hadoop.yarn.server.resourcemanager.scheduler.capacity.CapacityScheduler: Application Submission: appattempt_1375842659078_0008_000001, user: ubuntu queue: default: capacity=1.0, absoluteCapacity=1.0, usedResources=<memory:4096, vCores:2>usedCapacity=0.083333336, absoluteUsedCapacity=0.083333336, numApps=3, numContainers=2, currently active: 3
2013-08-07 02:42:04,885 INFO org.apache.hadoop.yarn.server.resourcemanager.rmapp.attempt.RMAppAttemptImpl: appattempt_1375842659078_0008_000001 State change from SUBMITTED to SCHEDULED
2013-08-07 02:42:04,885 INFO org.apache.hadoop.yarn.server.resourcemanager.rmapp.RMAppImpl: application_1375842659078_0008 State change from SUBMITTED to ACCEPTED
2013-08-07 02:42:04,938 INFO org.apache.hadoop.yarn.server.resourcemanager.ClientRMService: Storing Application with id application_1375842659078_0009
2013-08-07 02:42:04,938 INFO org.apache.hadoop.yarn.server.resourcemanager.recovery.RMStateStore: Storing info for app: application_1375842659078_0009
2013-08-07 02:42:04,938 INFO org.apache.hadoop.yarn.server.resourcemanager.ClientRMService: Application with id 9 submitted by user ubuntu
2013-08-07 02:42:04,938 INFO org.apache.hadoop.yarn.server.resourcemanager.RMAuditLogger: USER=ubuntu	IP=192.168.100.2	OPERATION=Submit Application Request	TARGET=ClientRMService	RESULT=SUCCESS	APPID=application_1375842659078_0009
2013-08-07 02:42:04,940 INFO org.apache.hadoop.yarn.server.resourcemanager.rmapp.RMAppImpl: application_1375842659078_0009 State change from NEW to SUBMITTED
2013-08-07 02:42:04,940 INFO org.apache.hadoop.yarn.server.resourcemanager.ApplicationMasterService: Registering appattempt_1375842659078_0009_000001
2013-08-07 02:42:04,940 INFO org.apache.hadoop.yarn.server.resourcemanager.rmapp.attempt.RMAppAttemptImpl: appattempt_1375842659078_0009_000001 State change from NEW to SUBMITTED
2013-08-07 02:42:04,940 INFO org.apache.hadoop.yarn.server.resourcemanager.scheduler.capacity.LeafQueue: Application application_1375842659078_0009 from user: ubuntu activated in queue: default
2013-08-07 02:42:04,941 INFO org.apache.hadoop.yarn.server.resourcemanager.scheduler.capacity.LeafQueue: Application added - appId: application_1375842659078_0009 user: org.apache.hadoop.yarn.server.resourcemanager.scheduler.capacity.LeafQueue$User@26e027e7, leaf-queue: default #user-pending-applications: 0 #user-active-applications: 4 #queue-pending-applications: 0 #queue-active-applications: 4
2013-08-07 02:42:04,941 INFO org.apache.hadoop.yarn.server.resourcemanager.scheduler.capacity.ParentQueue: Application added - appId: application_1375842659078_0009 user: ubuntu leaf-queue of parent: root #applications: 4
2013-08-07 02:42:04,941 INFO org.apache.hadoop.yarn.server.resourcemanager.scheduler.capacity.CapacityScheduler: Application Submission: appattempt_1375842659078_0009_000001, user: ubuntu queue: default: capacity=1.0, absoluteCapacity=1.0, usedResources=<memory:4096, vCores:2>usedCapacity=0.083333336, absoluteUsedCapacity=0.083333336, numApps=4, numContainers=2, currently active: 4
2013-08-07 02:42:04,941 INFO org.apache.hadoop.yarn.server.resourcemanager.rmapp.attempt.RMAppAttemptImpl: appattempt_1375842659078_0009_000001 State change from SUBMITTED to SCHEDULED
2013-08-07 02:42:04,941 INFO org.apache.hadoop.yarn.server.resourcemanager.rmapp.RMAppImpl: application_1375842659078_0009 State change from SUBMITTED to ACCEPTED
2013-08-07 02:42:04,953 INFO org.apache.hadoop.yarn.server.resourcemanager.ClientRMService: Storing Application with id application_1375842659078_0010
2013-08-07 02:42:04,954 INFO org.apache.hadoop.yarn.server.resourcemanager.recovery.RMStateStore: Storing info for app: application_1375842659078_0010
2013-08-07 02:42:04,955 INFO org.apache.hadoop.yarn.server.resourcemanager.ClientRMService: Application with id 10 submitted by user ubuntu
2013-08-07 02:42:04,955 INFO org.apache.hadoop.yarn.server.resourcemanager.RMAuditLogger: USER=ubuntu	IP=192.168.100.2	OPERATION=Submit Application Request	TARGET=ClientRMService	RESULT=SUCCESS	APPID=application_1375842659078_0010
2013-08-07 02:42:04,957 INFO org.apache.hadoop.yarn.server.resourcemanager.rmapp.RMAppImpl: application_1375842659078_0010 State change from NEW to SUBMITTED
2013-08-07 02:42:04,957 INFO org.apache.hadoop.yarn.server.resourcemanager.ApplicationMasterService: Registering appattempt_1375842659078_0010_000001
2013-08-07 02:42:04,957 INFO org.apache.hadoop.yarn.server.resourcemanager.rmapp.attempt.RMAppAttemptImpl: appattempt_1375842659078_0010_000001 State change from NEW to SUBMITTED
2013-08-07 02:42:04,957 INFO org.apache.hadoop.yarn.server.resourcemanager.scheduler.capacity.LeafQueue: Application application_1375842659078_0010 from user: ubuntu activated in queue: default
2013-08-07 02:42:04,958 INFO org.apache.hadoop.yarn.server.resourcemanager.scheduler.capacity.LeafQueue: Application added - appId: application_1375842659078_0010 user: org.apache.hadoop.yarn.server.resourcemanager.scheduler.capacity.LeafQueue$User@26e027e7, leaf-queue: default #user-pending-applications: 0 #user-active-applications: 5 #queue-pending-applications: 0 #queue-active-applications: 5
2013-08-07 02:42:04,958 INFO org.apache.hadoop.yarn.server.resourcemanager.scheduler.capacity.ParentQueue: Application added - appId: application_1375842659078_0010 user: ubuntu leaf-queue of parent: root #applications: 5
2013-08-07 02:42:04,958 INFO org.apache.hadoop.yarn.server.resourcemanager.scheduler.capacity.CapacityScheduler: Application Submission: appattempt_1375842659078_0010_000001, user: ubuntu queue: default: capacity=1.0, absoluteCapacity=1.0, usedResources=<memory:4096, vCores:2>usedCapacity=0.083333336, absoluteUsedCapacity=0.083333336, numApps=5, numContainers=2, currently active: 5
2013-08-07 02:42:04,958 INFO org.apache.hadoop.yarn.server.resourcemanager.rmapp.attempt.RMAppAttemptImpl: appattempt_1375842659078_0010_000001 State change from SUBMITTED to SCHEDULED
2013-08-07 02:42:04,958 INFO org.apache.hadoop.yarn.server.resourcemanager.rmapp.RMAppImpl: application_1375842659078_0010 State change from SUBMITTED to ACCEPTED
2013-08-07 02:42:05,363 INFO org.apache.hadoop.yarn.server.resourcemanager.rmcontainer.RMContainerImpl: container_1375842659078_0006_01_000001 Container Transitioned from ACQUIRED to RUNNING
2013-08-07 02:42:05,363 INFO org.apache.hadoop.yarn.server.resourcemanager.rmcontainer.RMContainerImpl: container_1375842659078_0008_01_000001 Container Transitioned from NEW to ALLOCATED
2013-08-07 02:42:05,363 INFO org.apache.hadoop.yarn.server.resourcemanager.RMAuditLogger: USER=ubuntu	OPERATION=AM Allocated Container	TARGET=SchedulerApp	RESULT=SUCCESS	APPID=application_1375842659078_0008	CONTAINERID=container_1375842659078_0008_01_000001
2013-08-07 02:42:05,363 INFO org.apache.hadoop.yarn.server.resourcemanager.scheduler.common.fica.FiCaSchedulerNode: Assigned container container_1375842659078_0008_01_000001 of capacity <memory:2048, vCores:1> on host hadoop-200-5:38287, which currently has 2 containers, <memory:4096, vCores:2> used and <memory:4096, vCores:14> available
2013-08-07 02:42:05,364 INFO org.apache.hadoop.yarn.server.resourcemanager.scheduler.capacity.LeafQueue: assignedContainer application=application_1375842659078_0008 container=Container: [ContainerId: container_1375842659078_0008_01_000001, NodeId: hadoop-200-5:38287, NodeHttpAddress: hadoop-200-5:8042, Resource: <memory:2048, vCores:1>, Priority: 0, State: NEW, Token: null, Status: container_id {, app_attempt_id {, application_id {, id: 8, cluster_timestamp: 1375842659078, }, attemptId: 1, }, id: 1, }, state: C_NEW, ] containerId=container_1375842659078_0008_01_000001 queue=default: capacity=1.0, absoluteCapacity=1.0, usedResources=<memory:4096, vCores:2>usedCapacity=0.083333336, absoluteUsedCapacity=0.083333336, numApps=5, numContainers=2 usedCapacity=0.083333336 absoluteUsedCapacity=0.083333336 used=<memory:4096, vCores:2> cluster=<memory:49152, vCores:96>
2013-08-07 02:42:05,364 INFO org.apache.hadoop.yarn.server.resourcemanager.scheduler.capacity.ParentQueue: Re-sorting queues since queue: root.default stats: default: capacity=1.0, absoluteCapacity=1.0, usedResources=<memory:6144, vCores:3>usedCapacity=0.125, absoluteUsedCapacity=0.125, numApps=5, numContainers=3
2013-08-07 02:42:05,364 INFO org.apache.hadoop.yarn.server.resourcemanager.scheduler.capacity.ParentQueue: assignedContainer queue=root usedCapacity=0.125 absoluteUsedCapacity=0.125 used=<memory:6144, vCores:3> cluster=<memory:49152, vCores:96>
2013-08-07 02:42:05,365 INFO org.apache.hadoop.yarn.server.resourcemanager.rmcontainer.RMContainerImpl: container_1375842659078_0008_01_000001 Container Transitioned from ALLOCATED to ACQUIRED
2013-08-07 02:42:05,366 INFO org.apache.hadoop.yarn.server.resourcemanager.rmapp.attempt.RMAppAttemptImpl: Storing attempt: AppId: application_1375842659078_0008 AttemptId: appattempt_1375842659078_0008_000001 MasterContainer: Container: [ContainerId: container_1375842659078_0008_01_000001, NodeId: hadoop-200-5:38287, NodeHttpAddress: hadoop-200-5:8042, Resource: <memory:2048, vCores:1>, Priority: 0, State: NEW, Token: null, Status: container_id {, app_attempt_id {, application_id {, id: 8, cluster_timestamp: 1375842659078, }, attemptId: 1, }, id: 1, }, state: C_NEW, ]
2013-08-07 02:42:05,366 INFO org.apache.hadoop.yarn.server.resourcemanager.rmapp.attempt.RMAppAttemptImpl: appattempt_1375842659078_0008_000001 State change from SCHEDULED to ALLOCATED_SAVING
2013-08-07 02:42:05,366 INFO org.apache.hadoop.yarn.server.resourcemanager.recovery.RMStateStore: Storing info for attempt: appattempt_1375842659078_0008_000001
2013-08-07 02:42:05,367 INFO org.apache.hadoop.yarn.server.resourcemanager.rmapp.attempt.RMAppAttemptImpl: appattempt_1375842659078_0008_000001 State change from ALLOCATED_SAVING to ALLOCATED
2013-08-07 02:42:05,368 INFO org.apache.hadoop.yarn.server.resourcemanager.amlauncher.AMLauncher: Launching masterappattempt_1375842659078_0008_000001
2013-08-07 02:42:05,370 INFO org.apache.hadoop.yarn.server.resourcemanager.amlauncher.AMLauncher: Setting up container Container: [ContainerId: container_1375842659078_0008_01_000001, NodeId: hadoop-200-5:38287, NodeHttpAddress: hadoop-200-5:8042, Resource: <memory:2048, vCores:1>, Priority: 0, State: NEW, Token: null, Status: container_id {, app_attempt_id {, application_id {, id: 8, cluster_timestamp: 1375842659078, }, attemptId: 1, }, id: 1, }, state: C_NEW, ] for AM appattempt_1375842659078_0008_000001
2013-08-07 02:42:05,370 INFO org.apache.hadoop.yarn.server.resourcemanager.amlauncher.AMLauncher: Command to launch container container_1375842659078_0008_01_000001 : $JAVA_HOME/bin/java -Dlog4j.configuration=container-log4j.properties -Dyarn.app.mapreduce.container.log.dir=<LOG_DIR> -Dyarn.app.mapreduce.container.log.filesize=0 -Dhadoop.root.logger=INFO,CLA  -Xmx1024m org.apache.hadoop.mapreduce.v2.app.MRAppMaster 1><LOG_DIR>/stdout 2><LOG_DIR>/stderr 
2013-08-07 02:42:05,383 INFO org.apache.hadoop.yarn.server.resourcemanager.amlauncher.AMLauncher: Done launching container Container: [ContainerId: container_1375842659078_0008_01_000001, NodeId: hadoop-200-5:38287, NodeHttpAddress: hadoop-200-5:8042, Resource: <memory:2048, vCores:1>, Priority: 0, State: NEW, Token: null, Status: container_id {, app_attempt_id {, application_id {, id: 8, cluster_timestamp: 1375842659078, }, attemptId: 1, }, id: 1, }, state: C_NEW, ] for AM appattempt_1375842659078_0008_000001
2013-08-07 02:42:05,383 INFO org.apache.hadoop.yarn.server.resourcemanager.rmapp.attempt.RMAppAttemptImpl: appattempt_1375842659078_0008_000001 State change from ALLOCATED to LAUNCHED
2013-08-07 02:42:05,440 INFO org.apache.hadoop.yarn.server.resourcemanager.rmcontainer.RMContainerImpl: container_1375842659078_0007_01_000001 Container Transitioned from ACQUIRED to RUNNING
2013-08-07 02:42:05,441 INFO org.apache.hadoop.yarn.server.resourcemanager.rmcontainer.RMContainerImpl: container_1375842659078_0009_01_000001 Container Transitioned from NEW to ALLOCATED
2013-08-07 02:42:05,442 INFO org.apache.hadoop.yarn.server.resourcemanager.RMAuditLogger: USER=ubuntu	OPERATION=AM Allocated Container	TARGET=SchedulerApp	RESULT=SUCCESS	APPID=application_1375842659078_0009	CONTAINERID=container_1375842659078_0009_01_000001
2013-08-07 02:42:05,442 INFO org.apache.hadoop.yarn.server.resourcemanager.scheduler.common.fica.FiCaSchedulerNode: Assigned container container_1375842659078_0009_01_000001 of capacity <memory:2048, vCores:1> on host hadoop-200-7:59851, which currently has 2 containers, <memory:4096, vCores:2> used and <memory:4096, vCores:14> available
2013-08-07 02:42:05,443 INFO org.apache.hadoop.yarn.server.resourcemanager.scheduler.capacity.LeafQueue: assignedContainer application=application_1375842659078_0009 container=Container: [ContainerId: container_1375842659078_0009_01_000001, NodeId: hadoop-200-7:59851, NodeHttpAddress: hadoop-200-7:8042, Resource: <memory:2048, vCores:1>, Priority: 0, State: NEW, Token: null, Status: container_id {, app_attempt_id {, application_id {, id: 9, cluster_timestamp: 1375842659078, }, attemptId: 1, }, id: 1, }, state: C_NEW, ] containerId=container_1375842659078_0009_01_000001 queue=default: capacity=1.0, absoluteCapacity=1.0, usedResources=<memory:6144, vCores:3>usedCapacity=0.125, absoluteUsedCapacity=0.125, numApps=5, numContainers=3 usedCapacity=0.125 absoluteUsedCapacity=0.125 used=<memory:6144, vCores:3> cluster=<memory:49152, vCores:96>
2013-08-07 02:42:05,443 INFO org.apache.hadoop.yarn.server.resourcemanager.scheduler.capacity.ParentQueue: Re-sorting queues since queue: root.default stats: default: capacity=1.0, absoluteCapacity=1.0, usedResources=<memory:8192, vCores:4>usedCapacity=0.16666667, absoluteUsedCapacity=0.16666667, numApps=5, numContainers=4
2013-08-07 02:42:05,445 INFO org.apache.hadoop.yarn.server.resourcemanager.rmcontainer.RMContainerImpl: container_1375842659078_0009_01_000001 Container Transitioned from ALLOCATED to ACQUIRED
2013-08-07 02:42:05,446 INFO org.apache.hadoop.yarn.server.resourcemanager.rmapp.attempt.RMAppAttemptImpl: Storing attempt: AppId: application_1375842659078_0009 AttemptId: appattempt_1375842659078_0009_000001 MasterContainer: Container: [ContainerId: container_1375842659078_0009_01_000001, NodeId: hadoop-200-7:59851, NodeHttpAddress: hadoop-200-7:8042, Resource: <memory:2048, vCores:1>, Priority: 0, State: NEW, Token: null, Status: container_id {, app_attempt_id {, application_id {, id: 9, cluster_timestamp: 1375842659078, }, attemptId: 1, }, id: 1, }, state: C_NEW, ]
2013-08-07 02:42:05,447 INFO org.apache.hadoop.yarn.server.resourcemanager.rmapp.attempt.RMAppAttemptImpl: appattempt_1375842659078_0009_000001 State change from SCHEDULED to ALLOCATED_SAVING
2013-08-07 02:42:05,447 INFO org.apache.hadoop.yarn.server.resourcemanager.recovery.RMStateStore: Storing info for attempt: appattempt_1375842659078_0009_000001
2013-08-07 02:42:05,448 INFO org.apache.hadoop.yarn.server.resourcemanager.rmapp.attempt.RMAppAttemptImpl: appattempt_1375842659078_0009_000001 State change from ALLOCATED_SAVING to ALLOCATED
2013-08-07 02:42:05,447 INFO org.apache.hadoop.yarn.server.resourcemanager.scheduler.capacity.ParentQueue: assignedContainer queue=root usedCapacity=0.16666667 absoluteUsedCapacity=0.16666667 used=<memory:8192, vCores:4> cluster=<memory:49152, vCores:96>
2013-08-07 02:42:05,448 INFO org.apache.hadoop.yarn.server.resourcemanager.amlauncher.AMLauncher: Launching masterappattempt_1375842659078_0009_000001
2013-08-07 02:42:05,451 INFO org.apache.hadoop.yarn.server.resourcemanager.amlauncher.AMLauncher: Setting up container Container: [ContainerId: container_1375842659078_0009_01_000001, NodeId: hadoop-200-7:59851, NodeHttpAddress: hadoop-200-7:8042, Resource: <memory:2048, vCores:1>, Priority: 0, State: NEW, Token: null, Status: container_id {, app_attempt_id {, application_id {, id: 9, cluster_timestamp: 1375842659078, }, attemptId: 1, }, id: 1, }, state: C_NEW, ] for AM appattempt_1375842659078_0009_000001
2013-08-07 02:42:05,451 INFO org.apache.hadoop.yarn.server.resourcemanager.amlauncher.AMLauncher: Command to launch container container_1375842659078_0009_01_000001 : $JAVA_HOME/bin/java -Dlog4j.configuration=container-log4j.properties -Dyarn.app.mapreduce.container.log.dir=<LOG_DIR> -Dyarn.app.mapreduce.container.log.filesize=0 -Dhadoop.root.logger=INFO,CLA  -Xmx1024m org.apache.hadoop.mapreduce.v2.app.MRAppMaster 1><LOG_DIR>/stdout 2><LOG_DIR>/stderr 
2013-08-07 02:42:05,462 INFO org.apache.hadoop.yarn.server.resourcemanager.rmcontainer.RMContainerImpl: container_1375842659078_0010_01_000001 Container Transitioned from NEW to ALLOCATED
2013-08-07 02:42:05,462 INFO org.apache.hadoop.yarn.server.resourcemanager.RMAuditLogger: USER=ubuntu	OPERATION=AM Allocated Container	TARGET=SchedulerApp	RESULT=SUCCESS	APPID=application_1375842659078_0010	CONTAINERID=container_1375842659078_0010_01_000001
2013-08-07 02:42:05,462 INFO org.apache.hadoop.yarn.server.resourcemanager.amlauncher.AMLauncher: Done launching container Container: [ContainerId: container_1375842659078_0009_01_000001, NodeId: hadoop-200-7:59851, NodeHttpAddress: hadoop-200-7:8042, Resource: <memory:2048, vCores:1>, Priority: 0, State: NEW, Token: null, Status: container_id {, app_attempt_id {, application_id {, id: 9, cluster_timestamp: 1375842659078, }, attemptId: 1, }, id: 1, }, state: C_NEW, ] for AM appattempt_1375842659078_0009_000001
2013-08-07 02:42:05,462 INFO org.apache.hadoop.yarn.server.resourcemanager.scheduler.common.fica.FiCaSchedulerNode: Assigned container container_1375842659078_0010_01_000001 of capacity <memory:2048, vCores:1> on host hadoop-200-3:34020, which currently has 1 containers, <memory:2048, vCores:1> used and <memory:6144, vCores:15> available
2013-08-07 02:42:05,464 INFO org.apache.hadoop.yarn.server.resourcemanager.scheduler.capacity.LeafQueue: assignedContainer application=application_1375842659078_0010 container=Container: [ContainerId: container_1375842659078_0010_01_000001, NodeId: hadoop-200-3:34020, NodeHttpAddress: hadoop-200-3:8042, Resource: <memory:2048, vCores:1>, Priority: 0, State: NEW, Token: null, Status: container_id {, app_attempt_id {, application_id {, id: 10, cluster_timestamp: 1375842659078, }, attemptId: 1, }, id: 1, }, state: C_NEW, ] containerId=container_1375842659078_0010_01_000001 queue=default: capacity=1.0, absoluteCapacity=1.0, usedResources=<memory:8192, vCores:4>usedCapacity=0.16666667, absoluteUsedCapacity=0.16666667, numApps=5, numContainers=4 usedCapacity=0.16666667 absoluteUsedCapacity=0.16666667 used=<memory:8192, vCores:4> cluster=<memory:49152, vCores:96>
2013-08-07 02:42:05,465 INFO org.apache.hadoop.yarn.server.resourcemanager.scheduler.capacity.ParentQueue: Re-sorting queues since queue: root.default stats: default: capacity=1.0, absoluteCapacity=1.0, usedResources=<memory:10240, vCores:5>usedCapacity=0.20833333, absoluteUsedCapacity=0.20833333, numApps=5, numContainers=5
2013-08-07 02:42:05,465 INFO org.apache.hadoop.yarn.server.resourcemanager.scheduler.capacity.ParentQueue: assignedContainer queue=root usedCapacity=0.20833333 absoluteUsedCapacity=0.20833333 used=<memory:10240, vCores:5> cluster=<memory:49152, vCores:96>
2013-08-07 02:42:05,466 INFO org.apache.hadoop.yarn.server.resourcemanager.rmcontainer.RMContainerImpl: container_1375842659078_0010_01_000001 Container Transitioned from ALLOCATED to ACQUIRED
2013-08-07 02:42:05,469 INFO org.apache.hadoop.yarn.server.resourcemanager.rmapp.attempt.RMAppAttemptImpl: Storing attempt: AppId: application_1375842659078_0010 AttemptId: appattempt_1375842659078_0010_000001 MasterContainer: Container: [ContainerId: container_1375842659078_0010_01_000001, NodeId: hadoop-200-3:34020, NodeHttpAddress: hadoop-200-3:8042, Resource: <memory:2048, vCores:1>, Priority: 0, State: NEW, Token: null, Status: container_id {, app_attempt_id {, application_id {, id: 10, cluster_timestamp: 1375842659078, }, attemptId: 1, }, id: 1, }, state: C_NEW, ]
2013-08-07 02:42:05,469 INFO org.apache.hadoop.yarn.server.resourcemanager.rmapp.attempt.RMAppAttemptImpl: appattempt_1375842659078_0010_000001 State change from SCHEDULED to ALLOCATED_SAVING
2013-08-07 02:42:05,469 INFO org.apache.hadoop.yarn.server.resourcemanager.recovery.RMStateStore: Storing info for attempt: appattempt_1375842659078_0010_000001
2013-08-07 02:42:05,469 INFO org.apache.hadoop.yarn.server.resourcemanager.rmapp.attempt.RMAppAttemptImpl: appattempt_1375842659078_0009_000001 State change from ALLOCATED to LAUNCHED
2013-08-07 02:42:05,470 INFO org.apache.hadoop.yarn.server.resourcemanager.rmapp.attempt.RMAppAttemptImpl: appattempt_1375842659078_0010_000001 State change from ALLOCATED_SAVING to ALLOCATED
2013-08-07 02:42:05,471 INFO org.apache.hadoop.yarn.server.resourcemanager.amlauncher.AMLauncher: Launching masterappattempt_1375842659078_0010_000001
2013-08-07 02:42:05,473 INFO org.apache.hadoop.yarn.server.resourcemanager.amlauncher.AMLauncher: Setting up container Container: [ContainerId: container_1375842659078_0010_01_000001, NodeId: hadoop-200-3:34020, NodeHttpAddress: hadoop-200-3:8042, Resource: <memory:2048, vCores:1>, Priority: 0, State: NEW, Token: null, Status: container_id {, app_attempt_id {, application_id {, id: 10, cluster_timestamp: 1375842659078, }, attemptId: 1, }, id: 1, }, state: C_NEW, ] for AM appattempt_1375842659078_0010_000001
2013-08-07 02:42:05,473 INFO org.apache.hadoop.yarn.server.resourcemanager.amlauncher.AMLauncher: Command to launch container container_1375842659078_0010_01_000001 : $JAVA_HOME/bin/java -Dlog4j.configuration=container-log4j.properties -Dyarn.app.mapreduce.container.log.dir=<LOG_DIR> -Dyarn.app.mapreduce.container.log.filesize=0 -Dhadoop.root.logger=INFO,CLA  -Xmx1024m org.apache.hadoop.mapreduce.v2.app.MRAppMaster 1><LOG_DIR>/stdout 2><LOG_DIR>/stderr 
2013-08-07 02:42:05,489 INFO org.apache.hadoop.yarn.server.resourcemanager.amlauncher.AMLauncher: Done launching container Container: [ContainerId: container_1375842659078_0010_01_000001, NodeId: hadoop-200-3:34020, NodeHttpAddress: hadoop-200-3:8042, Resource: <memory:2048, vCores:1>, Priority: 0, State: NEW, Token: null, Status: container_id {, app_attempt_id {, application_id {, id: 10, cluster_timestamp: 1375842659078, }, attemptId: 1, }, id: 1, }, state: C_NEW, ] for AM appattempt_1375842659078_0010_000001
2013-08-07 02:42:05,489 INFO org.apache.hadoop.yarn.server.resourcemanager.rmapp.attempt.RMAppAttemptImpl: appattempt_1375842659078_0010_000001 State change from ALLOCATED to LAUNCHED
2013-08-07 02:42:06,368 INFO org.apache.hadoop.yarn.server.resourcemanager.rmcontainer.RMContainerImpl: container_1375842659078_0008_01_000001 Container Transitioned from ACQUIRED to RUNNING
2013-08-07 02:42:06,449 INFO org.apache.hadoop.yarn.server.resourcemanager.rmcontainer.RMContainerImpl: container_1375842659078_0009_01_000001 Container Transitioned from ACQUIRED to RUNNING
2013-08-07 02:42:06,467 INFO org.apache.hadoop.yarn.server.resourcemanager.rmcontainer.RMContainerImpl: container_1375842659078_0010_01_000001 Container Transitioned from ACQUIRED to RUNNING
2013-08-07 02:42:09,661 INFO org.apache.hadoop.yarn.server.resourcemanager.ApplicationMasterService: AM registration appattempt_1375842659078_0006_000001
2013-08-07 02:42:09,662 INFO org.apache.hadoop.yarn.server.resourcemanager.RMAuditLogger: USER=ubuntu	IP=192.168.100.5	OPERATION=Register App Master	TARGET=ApplicationMasterService	RESULT=SUCCESS	APPID=application_1375842659078_0006	APPATTEMPTID=appattempt_1375842659078_0006_000001
2013-08-07 02:42:09,663 INFO org.apache.hadoop.yarn.server.resourcemanager.rmapp.attempt.RMAppAttemptImpl: appattempt_1375842659078_0006_000001 State change from LAUNCHED to RUNNING
2013-08-07 02:42:09,663 INFO org.apache.hadoop.yarn.server.resourcemanager.rmapp.RMAppImpl: application_1375842659078_0006 State change from ACCEPTED to RUNNING
2013-08-07 02:42:10,105 INFO org.apache.hadoop.yarn.server.resourcemanager.ApplicationMasterService: AM registration appattempt_1375842659078_0007_000001
2013-08-07 02:42:10,105 INFO org.apache.hadoop.yarn.server.resourcemanager.RMAuditLogger: USER=ubuntu	IP=192.168.100.9	OPERATION=Register App Master	TARGET=ApplicationMasterService	RESULT=SUCCESS	APPID=application_1375842659078_0007	APPATTEMPTID=appattempt_1375842659078_0007_000001
2013-08-07 02:42:10,106 INFO org.apache.hadoop.yarn.server.resourcemanager.rmapp.attempt.RMAppAttemptImpl: appattempt_1375842659078_0007_000001 State change from LAUNCHED to RUNNING
2013-08-07 02:42:10,106 INFO org.apache.hadoop.yarn.server.resourcemanager.rmapp.RMAppImpl: application_1375842659078_0007 State change from ACCEPTED to RUNNING
2013-08-07 02:42:10,748 INFO org.apache.hadoop.yarn.server.resourcemanager.rmcontainer.RMContainerImpl: container_1375842659078_0006_01_000002 Container Transitioned from NEW to ALLOCATED
2013-08-07 02:42:10,748 INFO org.apache.hadoop.yarn.server.resourcemanager.RMAuditLogger: USER=ubuntu	OPERATION=AM Allocated Container	TARGET=SchedulerApp	RESULT=SUCCESS	APPID=application_1375842659078_0006	CONTAINERID=container_1375842659078_0006_01_000002
2013-08-07 02:42:10,748 INFO org.apache.hadoop.yarn.server.resourcemanager.scheduler.common.fica.FiCaSchedulerNode: Assigned container container_1375842659078_0006_01_000002 of capacity <memory:1024, vCores:1> on host hadoop-200-6:44827, which currently has 1 containers, <memory:1024, vCores:1> used and <memory:7168, vCores:15> available
2013-08-07 02:42:10,749 INFO org.apache.hadoop.yarn.server.resourcemanager.scheduler.capacity.LeafQueue: assignedContainer application=application_1375842659078_0006 container=Container: [ContainerId: container_1375842659078_0006_01_000002, NodeId: hadoop-200-6:44827, NodeHttpAddress: hadoop-200-6:8042, Resource: <memory:1024, vCores:1>, Priority: 20, State: NEW, Token: null, Status: container_id {, app_attempt_id {, application_id {, id: 6, cluster_timestamp: 1375842659078, }, attemptId: 1, }, id: 2, }, state: C_NEW, ] containerId=container_1375842659078_0006_01_000002 queue=default: capacity=1.0, absoluteCapacity=1.0, usedResources=<memory:10240, vCores:5>usedCapacity=0.20833333, absoluteUsedCapacity=0.20833333, numApps=5, numContainers=5 usedCapacity=0.20833333 absoluteUsedCapacity=0.20833333 used=<memory:10240, vCores:5> cluster=<memory:49152, vCores:96>
2013-08-07 02:42:10,750 INFO org.apache.hadoop.yarn.server.resourcemanager.scheduler.capacity.ParentQueue: Re-sorting queues since queue: root.default stats: default: capacity=1.0, absoluteCapacity=1.0, usedResources=<memory:11264, vCores:6>usedCapacity=0.22916667, absoluteUsedCapacity=0.22916667, numApps=5, numContainers=6
2013-08-07 02:42:10,750 INFO org.apache.hadoop.yarn.server.resourcemanager.scheduler.capacity.ParentQueue: assignedContainer queue=root usedCapacity=0.22916667 absoluteUsedCapacity=0.22916667 used=<memory:11264, vCores:6> cluster=<memory:49152, vCores:96>
2013-08-07 02:42:10,752 INFO org.apache.hadoop.yarn.server.resourcemanager.rmcontainer.RMContainerImpl: container_1375842659078_0006_01_000003 Container Transitioned from NEW to ALLOCATED
2013-08-07 02:42:10,752 INFO org.apache.hadoop.yarn.server.resourcemanager.RMAuditLogger: USER=ubuntu	OPERATION=AM Allocated Container	TARGET=SchedulerApp	RESULT=SUCCESS	APPID=application_1375842659078_0006	CONTAINERID=container_1375842659078_0006_01_000003
2013-08-07 02:42:10,753 INFO org.apache.hadoop.yarn.server.resourcemanager.scheduler.common.fica.FiCaSchedulerNode: Assigned container container_1375842659078_0006_01_000003 of capacity <memory:1024, vCores:1> on host hadoop-200-6:44827, which currently has 2 containers, <memory:2048, vCores:2> used and <memory:6144, vCores:14> available
2013-08-07 02:42:10,754 INFO org.apache.hadoop.yarn.server.resourcemanager.scheduler.capacity.LeafQueue: assignedContainer application=application_1375842659078_0006 container=Container: [ContainerId: container_1375842659078_0006_01_000003, NodeId: hadoop-200-6:44827, NodeHttpAddress: hadoop-200-6:8042, Resource: <memory:1024, vCores:1>, Priority: 20, State: NEW, Token: null, Status: container_id {, app_attempt_id {, application_id {, id: 6, cluster_timestamp: 1375842659078, }, attemptId: 1, }, id: 3, }, state: C_NEW, ] containerId=container_1375842659078_0006_01_000003 queue=default: capacity=1.0, absoluteCapacity=1.0, usedResources=<memory:11264, vCores:6>usedCapacity=0.22916667, absoluteUsedCapacity=0.22916667, numApps=5, numContainers=6 usedCapacity=0.22916667 absoluteUsedCapacity=0.22916667 used=<memory:11264, vCores:6> cluster=<memory:49152, vCores:96>
2013-08-07 02:42:10,754 INFO org.apache.hadoop.yarn.server.resourcemanager.scheduler.capacity.ParentQueue: Re-sorting queues since queue: root.default stats: default: capacity=1.0, absoluteCapacity=1.0, usedResources=<memory:12288, vCores:7>usedCapacity=0.25, absoluteUsedCapacity=0.25, numApps=5, numContainers=7
2013-08-07 02:42:10,754 INFO org.apache.hadoop.yarn.server.resourcemanager.scheduler.capacity.ParentQueue: assignedContainer queue=root usedCapacity=0.25 absoluteUsedCapacity=0.25 used=<memory:12288, vCores:7> cluster=<memory:49152, vCores:96>
2013-08-07 02:42:10,755 INFO org.apache.hadoop.yarn.server.resourcemanager.rmcontainer.RMContainerImpl: container_1375842659078_0006_01_000004 Container Transitioned from NEW to ALLOCATED
2013-08-07 02:42:10,755 INFO org.apache.hadoop.yarn.server.resourcemanager.RMAuditLogger: USER=ubuntu	OPERATION=AM Allocated Container	TARGET=SchedulerApp	RESULT=SUCCESS	APPID=application_1375842659078_0006	CONTAINERID=container_1375842659078_0006_01_000004
2013-08-07 02:42:10,755 INFO org.apache.hadoop.yarn.server.resourcemanager.scheduler.common.fica.FiCaSchedulerNode: Assigned container container_1375842659078_0006_01_000004 of capacity <memory:1024, vCores:1> on host hadoop-200-6:44827, which currently has 3 containers, <memory:3072, vCores:3> used and <memory:5120, vCores:13> available
2013-08-07 02:42:10,756 INFO org.apache.hadoop.yarn.server.resourcemanager.scheduler.capacity.LeafQueue: assignedContainer application=application_1375842659078_0006 container=Container: [ContainerId: container_1375842659078_0006_01_000004, NodeId: hadoop-200-6:44827, NodeHttpAddress: hadoop-200-6:8042, Resource: <memory:1024, vCores:1>, Priority: 20, State: NEW, Token: null, Status: container_id {, app_attempt_id {, application_id {, id: 6, cluster_timestamp: 1375842659078, }, attemptId: 1, }, id: 4, }, state: C_NEW, ] containerId=container_1375842659078_0006_01_000004 queue=default: capacity=1.0, absoluteCapacity=1.0, usedResources=<memory:12288, vCores:7>usedCapacity=0.25, absoluteUsedCapacity=0.25, numApps=5, numContainers=7 usedCapacity=0.25 absoluteUsedCapacity=0.25 used=<memory:12288, vCores:7> cluster=<memory:49152, vCores:96>
2013-08-07 02:42:10,756 INFO org.apache.hadoop.yarn.server.resourcemanager.scheduler.capacity.ParentQueue: Re-sorting queues since queue: root.default stats: default: capacity=1.0, absoluteCapacity=1.0, usedResources=<memory:13312, vCores:8>usedCapacity=0.27083334, absoluteUsedCapacity=0.27083334, numApps=5, numContainers=8
2013-08-07 02:42:10,757 INFO org.apache.hadoop.yarn.server.resourcemanager.scheduler.capacity.ParentQueue: assignedContainer queue=root usedCapacity=0.27083334 absoluteUsedCapacity=0.27083334 used=<memory:13312, vCores:8> cluster=<memory:49152, vCores:96>
2013-08-07 02:42:10,757 INFO org.apache.hadoop.yarn.server.resourcemanager.rmcontainer.RMContainerImpl: container_1375842659078_0006_01_000005 Container Transitioned from NEW to ALLOCATED
2013-08-07 02:42:10,757 INFO org.apache.hadoop.yarn.server.resourcemanager.RMAuditLogger: USER=ubuntu	OPERATION=AM Allocated Container	TARGET=SchedulerApp	RESULT=SUCCESS	APPID=application_1375842659078_0006	CONTAINERID=container_1375842659078_0006_01_000005
2013-08-07 02:42:10,758 INFO org.apache.hadoop.yarn.server.resourcemanager.scheduler.common.fica.FiCaSchedulerNode: Assigned container container_1375842659078_0006_01_000005 of capacity <memory:1024, vCores:1> on host hadoop-200-6:44827, which currently has 4 containers, <memory:4096, vCores:4> used and <memory:4096, vCores:12> available
2013-08-07 02:42:10,759 INFO org.apache.hadoop.yarn.server.resourcemanager.scheduler.capacity.LeafQueue: assignedContainer application=application_1375842659078_0006 container=Container: [ContainerId: container_1375842659078_0006_01_000005, NodeId: hadoop-200-6:44827, NodeHttpAddress: hadoop-200-6:8042, Resource: <memory:1024, vCores:1>, Priority: 20, State: NEW, Token: null, Status: container_id {, app_attempt_id {, application_id {, id: 6, cluster_timestamp: 1375842659078, }, attemptId: 1, }, id: 5, }, state: C_NEW, ] containerId=container_1375842659078_0006_01_000005 queue=default: capacity=1.0, absoluteCapacity=1.0, usedResources=<memory:13312, vCores:8>usedCapacity=0.27083334, absoluteUsedCapacity=0.27083334, numApps=5, numContainers=8 usedCapacity=0.27083334 absoluteUsedCapacity=0.27083334 used=<memory:13312, vCores:8> cluster=<memory:49152, vCores:96>
2013-08-07 02:42:10,759 INFO org.apache.hadoop.yarn.server.resourcemanager.scheduler.capacity.ParentQueue: Re-sorting queues since queue: root.default stats: default: capacity=1.0, absoluteCapacity=1.0, usedResources=<memory:14336, vCores:9>usedCapacity=0.29166666, absoluteUsedCapacity=0.29166666, numApps=5, numContainers=9
2013-08-07 02:42:10,759 INFO org.apache.hadoop.yarn.server.resourcemanager.scheduler.capacity.ParentQueue: assignedContainer queue=root usedCapacity=0.29166666 absoluteUsedCapacity=0.29166666 used=<memory:14336, vCores:9> cluster=<memory:49152, vCores:96>
2013-08-07 02:42:10,760 INFO org.apache.hadoop.yarn.server.resourcemanager.rmcontainer.RMContainerImpl: container_1375842659078_0006_01_000006 Container Transitioned from NEW to ALLOCATED
2013-08-07 02:42:10,760 INFO org.apache.hadoop.yarn.server.resourcemanager.RMAuditLogger: USER=ubuntu	OPERATION=AM Allocated Container	TARGET=SchedulerApp	RESULT=SUCCESS	APPID=application_1375842659078_0006	CONTAINERID=container_1375842659078_0006_01_000006
2013-08-07 02:42:10,760 INFO org.apache.hadoop.yarn.server.resourcemanager.scheduler.common.fica.FiCaSchedulerNode: Assigned container container_1375842659078_0006_01_000006 of capacity <memory:1024, vCores:1> on host hadoop-200-6:44827, which currently has 5 containers, <memory:5120, vCores:5> used and <memory:3072, vCores:11> available
2013-08-07 02:42:10,761 INFO org.apache.hadoop.yarn.server.resourcemanager.scheduler.capacity.LeafQueue: assignedContainer application=application_1375842659078_0006 container=Container: [ContainerId: container_1375842659078_0006_01_000006, NodeId: hadoop-200-6:44827, NodeHttpAddress: hadoop-200-6:8042, Resource: <memory:1024, vCores:1>, Priority: 20, State: NEW, Token: null, Status: container_id {, app_attempt_id {, application_id {, id: 6, cluster_timestamp: 1375842659078, }, attemptId: 1, }, id: 6, }, state: C_NEW, ] containerId=container_1375842659078_0006_01_000006 queue=default: capacity=1.0, absoluteCapacity=1.0, usedResources=<memory:14336, vCores:9>usedCapacity=0.29166666, absoluteUsedCapacity=0.29166666, numApps=5, numContainers=9 usedCapacity=0.29166666 absoluteUsedCapacity=0.29166666 used=<memory:14336, vCores:9> cluster=<memory:49152, vCores:96>
2013-08-07 02:42:10,761 INFO org.apache.hadoop.yarn.server.resourcemanager.scheduler.capacity.ParentQueue: Re-sorting queues since queue: root.default stats: default: capacity=1.0, absoluteCapacity=1.0, usedResources=<memory:15360, vCores:10>usedCapacity=0.3125, absoluteUsedCapacity=0.3125, numApps=5, numContainers=10
2013-08-07 02:42:10,761 INFO org.apache.hadoop.yarn.server.resourcemanager.scheduler.capacity.ParentQueue: assignedContainer queue=root usedCapacity=0.3125 absoluteUsedCapacity=0.3125 used=<memory:15360, vCores:10> cluster=<memory:49152, vCores:96>
2013-08-07 02:42:10,762 INFO org.apache.hadoop.yarn.server.resourcemanager.rmcontainer.RMContainerImpl: container_1375842659078_0006_01_000007 Container Transitioned from NEW to ALLOCATED
2013-08-07 02:42:10,762 INFO org.apache.hadoop.yarn.server.resourcemanager.RMAuditLogger: USER=ubuntu	OPERATION=AM Allocated Container	TARGET=SchedulerApp	RESULT=SUCCESS	APPID=application_1375842659078_0006	CONTAINERID=container_1375842659078_0006_01_000007
2013-08-07 02:42:10,762 INFO org.apache.hadoop.yarn.server.resourcemanager.scheduler.common.fica.FiCaSchedulerNode: Assigned container container_1375842659078_0006_01_000007 of capacity <memory:1024, vCores:1> on host hadoop-200-6:44827, which currently has 6 containers, <memory:6144, vCores:6> used and <memory:2048, vCores:10> available
2013-08-07 02:42:10,763 INFO org.apache.hadoop.yarn.server.resourcemanager.scheduler.capacity.LeafQueue: assignedContainer application=application_1375842659078_0006 container=Container: [ContainerId: container_1375842659078_0006_01_000007, NodeId: hadoop-200-6:44827, NodeHttpAddress: hadoop-200-6:8042, Resource: <memory:1024, vCores:1>, Priority: 20, State: NEW, Token: null, Status: container_id {, app_attempt_id {, application_id {, id: 6, cluster_timestamp: 1375842659078, }, attemptId: 1, }, id: 7, }, state: C_NEW, ] containerId=container_1375842659078_0006_01_000007 queue=default: capacity=1.0, absoluteCapacity=1.0, usedResources=<memory:15360, vCores:10>usedCapacity=0.3125, absoluteUsedCapacity=0.3125, numApps=5, numContainers=10 usedCapacity=0.3125 absoluteUsedCapacity=0.3125 used=<memory:15360, vCores:10> cluster=<memory:49152, vCores:96>
2013-08-07 02:42:10,764 INFO org.apache.hadoop.yarn.server.resourcemanager.scheduler.capacity.ParentQueue: Re-sorting queues since queue: root.default stats: default: capacity=1.0, absoluteCapacity=1.0, usedResources=<memory:16384, vCores:11>usedCapacity=0.33333334, absoluteUsedCapacity=0.33333334, numApps=5, numContainers=11
2013-08-07 02:42:10,764 INFO org.apache.hadoop.yarn.server.resourcemanager.scheduler.capacity.ParentQueue: assignedContainer queue=root usedCapacity=0.33333334 absoluteUsedCapacity=0.33333334 used=<memory:16384, vCores:11> cluster=<memory:49152, vCores:96>
2013-08-07 02:42:10,764 INFO org.apache.hadoop.yarn.server.resourcemanager.rmcontainer.RMContainerImpl: container_1375842659078_0006_01_000008 Container Transitioned from NEW to ALLOCATED
2013-08-07 02:42:10,764 INFO org.apache.hadoop.yarn.server.resourcemanager.RMAuditLogger: USER=ubuntu	OPERATION=AM Allocated Container	TARGET=SchedulerApp	RESULT=SUCCESS	APPID=application_1375842659078_0006	CONTAINERID=container_1375842659078_0006_01_000008
2013-08-07 02:42:10,765 INFO org.apache.hadoop.yarn.server.resourcemanager.scheduler.common.fica.FiCaSchedulerNode: Assigned container container_1375842659078_0006_01_000008 of capacity <memory:1024, vCores:1> on host hadoop-200-6:44827, which currently has 7 containers, <memory:7168, vCores:7> used and <memory:1024, vCores:9> available
2013-08-07 02:42:10,766 INFO org.apache.hadoop.yarn.server.resourcemanager.scheduler.capacity.LeafQueue: assignedContainer application=application_1375842659078_0006 container=Container: [ContainerId: container_1375842659078_0006_01_000008, NodeId: hadoop-200-6:44827, NodeHttpAddress: hadoop-200-6:8042, Resource: <memory:1024, vCores:1>, Priority: 20, State: NEW, Token: null, Status: container_id {, app_attempt_id {, application_id {, id: 6, cluster_timestamp: 1375842659078, }, attemptId: 1, }, id: 8, }, state: C_NEW, ] containerId=container_1375842659078_0006_01_000008 queue=default: capacity=1.0, absoluteCapacity=1.0, usedResources=<memory:16384, vCores:11>usedCapacity=0.33333334, absoluteUsedCapacity=0.33333334, numApps=5, numContainers=11 usedCapacity=0.33333334 absoluteUsedCapacity=0.33333334 used=<memory:16384, vCores:11> cluster=<memory:49152, vCores:96>
2013-08-07 02:42:10,766 INFO org.apache.hadoop.yarn.server.resourcemanager.scheduler.capacity.ParentQueue: Re-sorting queues since queue: root.default stats: default: capacity=1.0, absoluteCapacity=1.0, usedResources=<memory:17408, vCores:12>usedCapacity=0.35416666, absoluteUsedCapacity=0.35416666, numApps=5, numContainers=12
2013-08-07 02:42:10,766 INFO org.apache.hadoop.yarn.server.resourcemanager.scheduler.capacity.ParentQueue: assignedContainer queue=root usedCapacity=0.35416666 absoluteUsedCapacity=0.35416666 used=<memory:17408, vCores:12> cluster=<memory:49152, vCores:96>
2013-08-07 02:42:10,767 INFO org.apache.hadoop.yarn.server.resourcemanager.rmcontainer.RMContainerImpl: container_1375842659078_0006_01_000009 Container Transitioned from NEW to ALLOCATED
2013-08-07 02:42:10,767 INFO org.apache.hadoop.yarn.server.resourcemanager.RMAuditLogger: USER=ubuntu	OPERATION=AM Allocated Container	TARGET=SchedulerApp	RESULT=SUCCESS	APPID=application_1375842659078_0006	CONTAINERID=container_1375842659078_0006_01_000009
2013-08-07 02:42:10,767 INFO org.apache.hadoop.yarn.server.resourcemanager.scheduler.common.fica.FiCaSchedulerNode: Assigned container container_1375842659078_0006_01_000009 of capacity <memory:1024, vCores:1> on host hadoop-200-6:44827, which currently has 8 containers, <memory:8192, vCores:8> used and <memory:0, vCores:8> available
2013-08-07 02:42:10,768 INFO org.apache.hadoop.yarn.server.resourcemanager.scheduler.capacity.LeafQueue: assignedContainer application=application_1375842659078_0006 container=Container: [ContainerId: container_1375842659078_0006_01_000009, NodeId: hadoop-200-6:44827, NodeHttpAddress: hadoop-200-6:8042, Resource: <memory:1024, vCores:1>, Priority: 20, State: NEW, Token: null, Status: container_id {, app_attempt_id {, application_id {, id: 6, cluster_timestamp: 1375842659078, }, attemptId: 1, }, id: 9, }, state: C_NEW, ] containerId=container_1375842659078_0006_01_000009 queue=default: capacity=1.0, absoluteCapacity=1.0, usedResources=<memory:17408, vCores:12>usedCapacity=0.35416666, absoluteUsedCapacity=0.35416666, numApps=5, numContainers=12 usedCapacity=0.35416666 absoluteUsedCapacity=0.35416666 used=<memory:17408, vCores:12> cluster=<memory:49152, vCores:96>
2013-08-07 02:42:10,768 INFO org.apache.hadoop.yarn.server.resourcemanager.scheduler.capacity.ParentQueue: Re-sorting queues since queue: root.default stats: default: capacity=1.0, absoluteCapacity=1.0, usedResources=<memory:18432, vCores:13>usedCapacity=0.375, absoluteUsedCapacity=0.375, numApps=5, numContainers=13
2013-08-07 02:42:10,768 INFO org.apache.hadoop.yarn.server.resourcemanager.scheduler.capacity.ParentQueue: assignedContainer queue=root usedCapacity=0.375 absoluteUsedCapacity=0.375 used=<memory:18432, vCores:13> cluster=<memory:49152, vCores:96>
2013-08-07 02:42:10,882 INFO org.apache.hadoop.yarn.server.resourcemanager.rmcontainer.RMContainerImpl: container_1375842659078_0006_01_000010 Container Transitioned from NEW to ALLOCATED
2013-08-07 02:42:10,882 INFO org.apache.hadoop.yarn.server.resourcemanager.RMAuditLogger: USER=ubuntu	OPERATION=AM Allocated Container	TARGET=SchedulerApp	RESULT=SUCCESS	APPID=application_1375842659078_0006	CONTAINERID=container_1375842659078_0006_01_000010
2013-08-07 02:42:10,882 INFO org.apache.hadoop.yarn.server.resourcemanager.scheduler.common.fica.FiCaSchedulerNode: Assigned container container_1375842659078_0006_01_000010 of capacity <memory:1024, vCores:1> on host hadoop-200-2:33271, which currently has 1 containers, <memory:1024, vCores:1> used and <memory:7168, vCores:15> available
2013-08-07 02:42:10,884 INFO org.apache.hadoop.yarn.server.resourcemanager.scheduler.capacity.LeafQueue: assignedContainer application=application_1375842659078_0006 container=Container: [ContainerId: container_1375842659078_0006_01_000010, NodeId: hadoop-200-2:33271, NodeHttpAddress: hadoop-200-2:8042, Resource: <memory:1024, vCores:1>, Priority: 20, State: NEW, Token: null, Status: container_id {, app_attempt_id {, application_id {, id: 6, cluster_timestamp: 1375842659078, }, attemptId: 1, }, id: 10, }, state: C_NEW, ] containerId=container_1375842659078_0006_01_000010 queue=default: capacity=1.0, absoluteCapacity=1.0, usedResources=<memory:18432, vCores:13>usedCapacity=0.375, absoluteUsedCapacity=0.375, numApps=5, numContainers=13 usedCapacity=0.375 absoluteUsedCapacity=0.375 used=<memory:18432, vCores:13> cluster=<memory:49152, vCores:96>
2013-08-07 02:42:10,884 INFO org.apache.hadoop.yarn.server.resourcemanager.scheduler.capacity.ParentQueue: Re-sorting queues since queue: root.default stats: default: capacity=1.0, absoluteCapacity=1.0, usedResources=<memory:19456, vCores:14>usedCapacity=0.39583334, absoluteUsedCapacity=0.39583334, numApps=5, numContainers=14
2013-08-07 02:42:10,884 INFO org.apache.hadoop.yarn.server.resourcemanager.scheduler.capacity.ParentQueue: assignedContainer queue=root usedCapacity=0.39583334 absoluteUsedCapacity=0.39583334 used=<memory:19456, vCores:14> cluster=<memory:49152, vCores:96>
2013-08-07 02:42:10,885 INFO org.apache.hadoop.yarn.server.resourcemanager.rmcontainer.RMContainerImpl: container_1375842659078_0006_01_000011 Container Transitioned from NEW to ALLOCATED
2013-08-07 02:42:10,885 INFO org.apache.hadoop.yarn.server.resourcemanager.RMAuditLogger: USER=ubuntu	OPERATION=AM Allocated Container	TARGET=SchedulerApp	RESULT=SUCCESS	APPID=application_1375842659078_0006	CONTAINERID=container_1375842659078_0006_01_000011
2013-08-07 02:42:10,885 INFO org.apache.hadoop.yarn.server.resourcemanager.scheduler.common.fica.FiCaSchedulerNode: Assigned container container_1375842659078_0006_01_000011 of capacity <memory:1024, vCores:1> on host hadoop-200-2:33271, which currently has 2 containers, <memory:2048, vCores:2> used and <memory:6144, vCores:14> available
2013-08-07 02:42:10,886 INFO org.apache.hadoop.yarn.server.resourcemanager.scheduler.capacity.LeafQueue: assignedContainer application=application_1375842659078_0006 container=Container: [ContainerId: container_1375842659078_0006_01_000011, NodeId: hadoop-200-2:33271, NodeHttpAddress: hadoop-200-2:8042, Resource: <memory:1024, vCores:1>, Priority: 20, State: NEW, Token: null, Status: container_id {, app_attempt_id {, application_id {, id: 6, cluster_timestamp: 1375842659078, }, attemptId: 1, }, id: 11, }, state: C_NEW, ] containerId=container_1375842659078_0006_01_000011 queue=default: capacity=1.0, absoluteCapacity=1.0, usedResources=<memory:19456, vCores:14>usedCapacity=0.39583334, absoluteUsedCapacity=0.39583334, numApps=5, numContainers=14 usedCapacity=0.39583334 absoluteUsedCapacity=0.39583334 used=<memory:19456, vCores:14> cluster=<memory:49152, vCores:96>
2013-08-07 02:42:10,886 INFO org.apache.hadoop.yarn.server.resourcemanager.scheduler.capacity.ParentQueue: Re-sorting queues since queue: root.default stats: default: capacity=1.0, absoluteCapacity=1.0, usedResources=<memory:20480, vCores:15>usedCapacity=0.41666666, absoluteUsedCapacity=0.41666666, numApps=5, numContainers=15
2013-08-07 02:42:10,886 INFO org.apache.hadoop.yarn.server.resourcemanager.scheduler.capacity.ParentQueue: assignedContainer queue=root usedCapacity=0.41666666 absoluteUsedCapacity=0.41666666 used=<memory:20480, vCores:15> cluster=<memory:49152, vCores:96>
2013-08-07 02:42:10,887 INFO org.apache.hadoop.yarn.server.resourcemanager.rmcontainer.RMContainerImpl: container_1375842659078_0006_01_000012 Container Transitioned from NEW to ALLOCATED
2013-08-07 02:42:10,887 INFO org.apache.hadoop.yarn.server.resourcemanager.RMAuditLogger: USER=ubuntu	OPERATION=AM Allocated Container	TARGET=SchedulerApp	RESULT=SUCCESS	APPID=application_1375842659078_0006	CONTAINERID=container_1375842659078_0006_01_000012
2013-08-07 02:42:10,887 INFO org.apache.hadoop.yarn.server.resourcemanager.scheduler.common.fica.FiCaSchedulerNode: Assigned container container_1375842659078_0006_01_000012 of capacity <memory:1024, vCores:1> on host hadoop-200-2:33271, which currently has 3 containers, <memory:3072, vCores:3> used and <memory:5120, vCores:13> available
2013-08-07 02:42:10,888 INFO org.apache.hadoop.yarn.server.resourcemanager.scheduler.capacity.LeafQueue: assignedContainer application=application_1375842659078_0006 container=Container: [ContainerId: container_1375842659078_0006_01_000012, NodeId: hadoop-200-2:33271, NodeHttpAddress: hadoop-200-2:8042, Resource: <memory:1024, vCores:1>, Priority: 20, State: NEW, Token: null, Status: container_id {, app_attempt_id {, application_id {, id: 6, cluster_timestamp: 1375842659078, }, attemptId: 1, }, id: 12, }, state: C_NEW, ] containerId=container_1375842659078_0006_01_000012 queue=default: capacity=1.0, absoluteCapacity=1.0, usedResources=<memory:20480, vCores:15>usedCapacity=0.41666666, absoluteUsedCapacity=0.41666666, numApps=5, numContainers=15 usedCapacity=0.41666666 absoluteUsedCapacity=0.41666666 used=<memory:20480, vCores:15> cluster=<memory:49152, vCores:96>
2013-08-07 02:42:10,888 INFO org.apache.hadoop.yarn.server.resourcemanager.scheduler.capacity.ParentQueue: Re-sorting queues since queue: root.default stats: default: capacity=1.0, absoluteCapacity=1.0, usedResources=<memory:21504, vCores:16>usedCapacity=0.4375, absoluteUsedCapacity=0.4375, numApps=5, numContainers=16
2013-08-07 02:42:10,889 INFO org.apache.hadoop.yarn.server.resourcemanager.scheduler.capacity.ParentQueue: assignedContainer queue=root usedCapacity=0.4375 absoluteUsedCapacity=0.4375 used=<memory:21504, vCores:16> cluster=<memory:49152, vCores:96>
2013-08-07 02:42:10,889 INFO org.apache.hadoop.yarn.server.resourcemanager.rmcontainer.RMContainerImpl: container_1375842659078_0006_01_000013 Container Transitioned from NEW to ALLOCATED
2013-08-07 02:42:10,889 INFO org.apache.hadoop.yarn.server.resourcemanager.RMAuditLogger: USER=ubuntu	OPERATION=AM Allocated Container	TARGET=SchedulerApp	RESULT=SUCCESS	APPID=application_1375842659078_0006	CONTAINERID=container_1375842659078_0006_01_000013
2013-08-07 02:42:10,889 INFO org.apache.hadoop.yarn.server.resourcemanager.scheduler.common.fica.FiCaSchedulerNode: Assigned container container_1375842659078_0006_01_000013 of capacity <memory:1024, vCores:1> on host hadoop-200-2:33271, which currently has 4 containers, <memory:4096, vCores:4> used and <memory:4096, vCores:12> available
2013-08-07 02:42:10,890 INFO org.apache.hadoop.yarn.server.resourcemanager.scheduler.capacity.LeafQueue: assignedContainer application=application_1375842659078_0006 container=Container: [ContainerId: container_1375842659078_0006_01_000013, NodeId: hadoop-200-2:33271, NodeHttpAddress: hadoop-200-2:8042, Resource: <memory:1024, vCores:1>, Priority: 20, State: NEW, Token: null, Status: container_id {, app_attempt_id {, application_id {, id: 6, cluster_timestamp: 1375842659078, }, attemptId: 1, }, id: 13, }, state: C_NEW, ] containerId=container_1375842659078_0006_01_000013 queue=default: capacity=1.0, absoluteCapacity=1.0, usedResources=<memory:21504, vCores:16>usedCapacity=0.4375, absoluteUsedCapacity=0.4375, numApps=5, numContainers=16 usedCapacity=0.4375 absoluteUsedCapacity=0.4375 used=<memory:21504, vCores:16> cluster=<memory:49152, vCores:96>
2013-08-07 02:42:10,891 INFO org.apache.hadoop.yarn.server.resourcemanager.scheduler.capacity.ParentQueue: Re-sorting queues since queue: root.default stats: default: capacity=1.0, absoluteCapacity=1.0, usedResources=<memory:22528, vCores:17>usedCapacity=0.45833334, absoluteUsedCapacity=0.45833334, numApps=5, numContainers=17
2013-08-07 02:42:10,891 INFO org.apache.hadoop.yarn.server.resourcemanager.scheduler.capacity.ParentQueue: assignedContainer queue=root usedCapacity=0.45833334 absoluteUsedCapacity=0.45833334 used=<memory:22528, vCores:17> cluster=<memory:49152, vCores:96>
2013-08-07 02:42:10,891 INFO org.apache.hadoop.yarn.server.resourcemanager.rmcontainer.RMContainerImpl: container_1375842659078_0006_01_000014 Container Transitioned from NEW to ALLOCATED
2013-08-07 02:42:10,891 INFO org.apache.hadoop.yarn.server.resourcemanager.RMAuditLogger: USER=ubuntu	OPERATION=AM Allocated Container	TARGET=SchedulerApp	RESULT=SUCCESS	APPID=application_1375842659078_0006	CONTAINERID=container_1375842659078_0006_01_000014
2013-08-07 02:42:10,892 INFO org.apache.hadoop.yarn.server.resourcemanager.scheduler.common.fica.FiCaSchedulerNode: Assigned container container_1375842659078_0006_01_000014 of capacity <memory:1024, vCores:1> on host hadoop-200-2:33271, which currently has 5 containers, <memory:5120, vCores:5> used and <memory:3072, vCores:11> available
2013-08-07 02:42:10,893 INFO org.apache.hadoop.yarn.server.resourcemanager.scheduler.capacity.LeafQueue: assignedContainer application=application_1375842659078_0006 container=Container: [ContainerId: container_1375842659078_0006_01_000014, NodeId: hadoop-200-2:33271, NodeHttpAddress: hadoop-200-2:8042, Resource: <memory:1024, vCores:1>, Priority: 20, State: NEW, Token: null, Status: container_id {, app_attempt_id {, application_id {, id: 6, cluster_timestamp: 1375842659078, }, attemptId: 1, }, id: 14, }, state: C_NEW, ] containerId=container_1375842659078_0006_01_000014 queue=default: capacity=1.0, absoluteCapacity=1.0, usedResources=<memory:22528, vCores:17>usedCapacity=0.45833334, absoluteUsedCapacity=0.45833334, numApps=5, numContainers=17 usedCapacity=0.45833334 absoluteUsedCapacity=0.45833334 used=<memory:22528, vCores:17> cluster=<memory:49152, vCores:96>
2013-08-07 02:42:10,893 INFO org.apache.hadoop.yarn.server.resourcemanager.scheduler.capacity.ParentQueue: Re-sorting queues since queue: root.default stats: default: capacity=1.0, absoluteCapacity=1.0, usedResources=<memory:23552, vCores:18>usedCapacity=0.47916666, absoluteUsedCapacity=0.47916666, numApps=5, numContainers=18
2013-08-07 02:42:10,893 INFO org.apache.hadoop.yarn.server.resourcemanager.scheduler.capacity.ParentQueue: assignedContainer queue=root usedCapacity=0.47916666 absoluteUsedCapacity=0.47916666 used=<memory:23552, vCores:18> cluster=<memory:49152, vCores:96>
2013-08-07 02:42:10,894 INFO org.apache.hadoop.yarn.server.resourcemanager.rmcontainer.RMContainerImpl: container_1375842659078_0006_01_000015 Container Transitioned from NEW to ALLOCATED
2013-08-07 02:42:10,894 INFO org.apache.hadoop.yarn.server.resourcemanager.RMAuditLogger: USER=ubuntu	OPERATION=AM Allocated Container	TARGET=SchedulerApp	RESULT=SUCCESS	APPID=application_1375842659078_0006	CONTAINERID=container_1375842659078_0006_01_000015
2013-08-07 02:42:10,894 INFO org.apache.hadoop.yarn.server.resourcemanager.scheduler.common.fica.FiCaSchedulerNode: Assigned container container_1375842659078_0006_01_000015 of capacity <memory:1024, vCores:1> on host hadoop-200-2:33271, which currently has 6 containers, <memory:6144, vCores:6> used and <memory:2048, vCores:10> available
2013-08-07 02:42:10,895 INFO org.apache.hadoop.yarn.server.resourcemanager.scheduler.capacity.LeafQueue: assignedContainer application=application_1375842659078_0006 container=Container: [ContainerId: container_1375842659078_0006_01_000015, NodeId: hadoop-200-2:33271, NodeHttpAddress: hadoop-200-2:8042, Resource: <memory:1024, vCores:1>, Priority: 20, State: NEW, Token: null, Status: container_id {, app_attempt_id {, application_id {, id: 6, cluster_timestamp: 1375842659078, }, attemptId: 1, }, id: 15, }, state: C_NEW, ] containerId=container_1375842659078_0006_01_000015 queue=default: capacity=1.0, absoluteCapacity=1.0, usedResources=<memory:23552, vCores:18>usedCapacity=0.47916666, absoluteUsedCapacity=0.47916666, numApps=5, numContainers=18 usedCapacity=0.47916666 absoluteUsedCapacity=0.47916666 used=<memory:23552, vCores:18> cluster=<memory:49152, vCores:96>
2013-08-07 02:42:10,895 INFO org.apache.hadoop.yarn.server.resourcemanager.scheduler.capacity.ParentQueue: Re-sorting queues since queue: root.default stats: default: capacity=1.0, absoluteCapacity=1.0, usedResources=<memory:24576, vCores:19>usedCapacity=0.5, absoluteUsedCapacity=0.5, numApps=5, numContainers=19
2013-08-07 02:42:10,895 INFO org.apache.hadoop.yarn.server.resourcemanager.scheduler.capacity.ParentQueue: assignedContainer queue=root usedCapacity=0.5 absoluteUsedCapacity=0.5 used=<memory:24576, vCores:19> cluster=<memory:49152, vCores:96>
2013-08-07 02:42:10,896 INFO org.apache.hadoop.yarn.server.resourcemanager.rmcontainer.RMContainerImpl: container_1375842659078_0006_01_000016 Container Transitioned from NEW to ALLOCATED
2013-08-07 02:42:10,896 INFO org.apache.hadoop.yarn.server.resourcemanager.RMAuditLogger: USER=ubuntu	OPERATION=AM Allocated Container	TARGET=SchedulerApp	RESULT=SUCCESS	APPID=application_1375842659078_0006	CONTAINERID=container_1375842659078_0006_01_000016
2013-08-07 02:42:10,896 INFO org.apache.hadoop.yarn.server.resourcemanager.scheduler.common.fica.FiCaSchedulerNode: Assigned container container_1375842659078_0006_01_000016 of capacity <memory:1024, vCores:1> on host hadoop-200-2:33271, which currently has 7 containers, <memory:7168, vCores:7> used and <memory:1024, vCores:9> available
2013-08-07 02:42:10,897 INFO org.apache.hadoop.yarn.server.resourcemanager.scheduler.capacity.LeafQueue: assignedContainer application=application_1375842659078_0006 container=Container: [ContainerId: container_1375842659078_0006_01_000016, NodeId: hadoop-200-2:33271, NodeHttpAddress: hadoop-200-2:8042, Resource: <memory:1024, vCores:1>, Priority: 20, State: NEW, Token: null, Status: container_id {, app_attempt_id {, application_id {, id: 6, cluster_timestamp: 1375842659078, }, attemptId: 1, }, id: 16, }, state: C_NEW, ] containerId=container_1375842659078_0006_01_000016 queue=default: capacity=1.0, absoluteCapacity=1.0, usedResources=<memory:24576, vCores:19>usedCapacity=0.5, absoluteUsedCapacity=0.5, numApps=5, numContainers=19 usedCapacity=0.5 absoluteUsedCapacity=0.5 used=<memory:24576, vCores:19> cluster=<memory:49152, vCores:96>
2013-08-07 02:42:10,897 INFO org.apache.hadoop.yarn.server.resourcemanager.scheduler.capacity.ParentQueue: Re-sorting queues since queue: root.default stats: default: capacity=1.0, absoluteCapacity=1.0, usedResources=<memory:25600, vCores:20>usedCapacity=0.5208333, absoluteUsedCapacity=0.5208333, numApps=5, numContainers=20
2013-08-07 02:42:10,898 INFO org.apache.hadoop.yarn.server.resourcemanager.scheduler.capacity.ParentQueue: assignedContainer queue=root usedCapacity=0.5208333 absoluteUsedCapacity=0.5208333 used=<memory:25600, vCores:20> cluster=<memory:49152, vCores:96>
2013-08-07 02:42:10,898 INFO org.apache.hadoop.yarn.server.resourcemanager.rmcontainer.RMContainerImpl: container_1375842659078_0006_01_000017 Container Transitioned from NEW to ALLOCATED
2013-08-07 02:42:10,898 INFO org.apache.hadoop.yarn.server.resourcemanager.RMAuditLogger: USER=ubuntu	OPERATION=AM Allocated Container	TARGET=SchedulerApp	RESULT=SUCCESS	APPID=application_1375842659078_0006	CONTAINERID=container_1375842659078_0006_01_000017
2013-08-07 02:42:10,898 INFO org.apache.hadoop.yarn.server.resourcemanager.scheduler.common.fica.FiCaSchedulerNode: Assigned container container_1375842659078_0006_01_000017 of capacity <memory:1024, vCores:1> on host hadoop-200-2:33271, which currently has 8 containers, <memory:8192, vCores:8> used and <memory:0, vCores:8> available
2013-08-07 02:42:10,899 INFO org.apache.hadoop.yarn.server.resourcemanager.scheduler.capacity.LeafQueue: assignedContainer application=application_1375842659078_0006 container=Container: [ContainerId: container_1375842659078_0006_01_000017, NodeId: hadoop-200-2:33271, NodeHttpAddress: hadoop-200-2:8042, Resource: <memory:1024, vCores:1>, Priority: 20, State: NEW, Token: null, Status: container_id {, app_attempt_id {, application_id {, id: 6, cluster_timestamp: 1375842659078, }, attemptId: 1, }, id: 17, }, state: C_NEW, ] containerId=container_1375842659078_0006_01_000017 queue=default: capacity=1.0, absoluteCapacity=1.0, usedResources=<memory:25600, vCores:20>usedCapacity=0.5208333, absoluteUsedCapacity=0.5208333, numApps=5, numContainers=20 usedCapacity=0.5208333 absoluteUsedCapacity=0.5208333 used=<memory:25600, vCores:20> cluster=<memory:49152, vCores:96>
2013-08-07 02:42:10,900 INFO org.apache.hadoop.yarn.server.resourcemanager.scheduler.capacity.ParentQueue: Re-sorting queues since queue: root.default stats: default: capacity=1.0, absoluteCapacity=1.0, usedResources=<memory:26624, vCores:21>usedCapacity=0.5416667, absoluteUsedCapacity=0.5416667, numApps=5, numContainers=21
2013-08-07 02:42:10,900 INFO org.apache.hadoop.yarn.server.resourcemanager.scheduler.capacity.ParentQueue: assignedContainer queue=root usedCapacity=0.5416667 absoluteUsedCapacity=0.5416667 used=<memory:26624, vCores:21> cluster=<memory:49152, vCores:96>
2013-08-07 02:42:10,901 INFO org.apache.hadoop.yarn.server.resourcemanager.rmcontainer.RMContainerImpl: container_1375842659078_0006_01_000018 Container Transitioned from NEW to ALLOCATED
2013-08-07 02:42:10,902 INFO org.apache.hadoop.yarn.server.resourcemanager.RMAuditLogger: USER=ubuntu	OPERATION=AM Allocated Container	TARGET=SchedulerApp	RESULT=SUCCESS	APPID=application_1375842659078_0006	CONTAINERID=container_1375842659078_0006_01_000018
2013-08-07 02:42:10,902 INFO org.apache.hadoop.yarn.server.resourcemanager.scheduler.common.fica.FiCaSchedulerNode: Assigned container container_1375842659078_0006_01_000018 of capacity <memory:1024, vCores:1> on host hadoop-200-4:56924, which currently has 1 containers, <memory:1024, vCores:1> used and <memory:7168, vCores:15> available
2013-08-07 02:42:10,903 INFO org.apache.hadoop.yarn.server.resourcemanager.scheduler.capacity.LeafQueue: assignedContainer application=application_1375842659078_0006 container=Container: [ContainerId: container_1375842659078_0006_01_000018, NodeId: hadoop-200-4:56924, NodeHttpAddress: hadoop-200-4:8042, Resource: <memory:1024, vCores:1>, Priority: 20, State: NEW, Token: null, Status: container_id {, app_attempt_id {, application_id {, id: 6, cluster_timestamp: 1375842659078, }, attemptId: 1, }, id: 18, }, state: C_NEW, ] containerId=container_1375842659078_0006_01_000018 queue=default: capacity=1.0, absoluteCapacity=1.0, usedResources=<memory:26624, vCores:21>usedCapacity=0.5416667, absoluteUsedCapacity=0.5416667, numApps=5, numContainers=21 usedCapacity=0.5416667 absoluteUsedCapacity=0.5416667 used=<memory:26624, vCores:21> cluster=<memory:49152, vCores:96>
2013-08-07 02:42:10,903 INFO org.apache.hadoop.yarn.server.resourcemanager.scheduler.capacity.ParentQueue: Re-sorting queues since queue: root.default stats: default: capacity=1.0, absoluteCapacity=1.0, usedResources=<memory:27648, vCores:22>usedCapacity=0.5625, absoluteUsedCapacity=0.5625, numApps=5, numContainers=22
2013-08-07 02:42:10,903 INFO org.apache.hadoop.yarn.server.resourcemanager.scheduler.capacity.ParentQueue: assignedContainer queue=root usedCapacity=0.5625 absoluteUsedCapacity=0.5625 used=<memory:27648, vCores:22> cluster=<memory:49152, vCores:96>
2013-08-07 02:42:10,904 INFO org.apache.hadoop.yarn.server.resourcemanager.rmcontainer.RMContainerImpl: container_1375842659078_0006_01_000019 Container Transitioned from NEW to ALLOCATED
2013-08-07 02:42:10,904 INFO org.apache.hadoop.yarn.server.resourcemanager.RMAuditLogger: USER=ubuntu	OPERATION=AM Allocated Container	TARGET=SchedulerApp	RESULT=SUCCESS	APPID=application_1375842659078_0006	CONTAINERID=container_1375842659078_0006_01_000019
2013-08-07 02:42:10,904 INFO org.apache.hadoop.yarn.server.resourcemanager.scheduler.common.fica.FiCaSchedulerNode: Assigned container container_1375842659078_0006_01_000019 of capacity <memory:1024, vCores:1> on host hadoop-200-4:56924, which currently has 2 containers, <memory:2048, vCores:2> used and <memory:6144, vCores:14> available
2013-08-07 02:42:10,905 INFO org.apache.hadoop.yarn.server.resourcemanager.scheduler.capacity.LeafQueue: assignedContainer application=application_1375842659078_0006 container=Container: [ContainerId: container_1375842659078_0006_01_000019, NodeId: hadoop-200-4:56924, NodeHttpAddress: hadoop-200-4:8042, Resource: <memory:1024, vCores:1>, Priority: 20, State: NEW, Token: null, Status: container_id {, app_attempt_id {, application_id {, id: 6, cluster_timestamp: 1375842659078, }, attemptId: 1, }, id: 19, }, state: C_NEW, ] containerId=container_1375842659078_0006_01_000019 queue=default: capacity=1.0, absoluteCapacity=1.0, usedResources=<memory:27648, vCores:22>usedCapacity=0.5625, absoluteUsedCapacity=0.5625, numApps=5, numContainers=22 usedCapacity=0.5625 absoluteUsedCapacity=0.5625 used=<memory:27648, vCores:22> cluster=<memory:49152, vCores:96>
2013-08-07 02:42:10,905 INFO org.apache.hadoop.yarn.server.resourcemanager.scheduler.capacity.ParentQueue: Re-sorting queues since queue: root.default stats: default: capacity=1.0, absoluteCapacity=1.0, usedResources=<memory:28672, vCores:23>usedCapacity=0.5833333, absoluteUsedCapacity=0.5833333, numApps=5, numContainers=23
2013-08-07 02:42:10,905 INFO org.apache.hadoop.yarn.server.resourcemanager.scheduler.capacity.ParentQueue: assignedContainer queue=root usedCapacity=0.5833333 absoluteUsedCapacity=0.5833333 used=<memory:28672, vCores:23> cluster=<memory:49152, vCores:96>
2013-08-07 02:42:10,906 INFO org.apache.hadoop.yarn.server.resourcemanager.rmcontainer.RMContainerImpl: container_1375842659078_0006_01_000020 Container Transitioned from NEW to ALLOCATED
2013-08-07 02:42:10,906 INFO org.apache.hadoop.yarn.server.resourcemanager.RMAuditLogger: USER=ubuntu	OPERATION=AM Allocated Container	TARGET=SchedulerApp	RESULT=SUCCESS	APPID=application_1375842659078_0006	CONTAINERID=container_1375842659078_0006_01_000020
2013-08-07 02:42:10,906 INFO org.apache.hadoop.yarn.server.resourcemanager.scheduler.common.fica.FiCaSchedulerNode: Assigned container container_1375842659078_0006_01_000020 of capacity <memory:1024, vCores:1> on host hadoop-200-4:56924, which currently has 3 containers, <memory:3072, vCores:3> used and <memory:5120, vCores:13> available
2013-08-07 02:42:10,907 INFO org.apache.hadoop.yarn.server.resourcemanager.scheduler.capacity.LeafQueue: assignedContainer application=application_1375842659078_0006 container=Container: [ContainerId: container_1375842659078_0006_01_000020, NodeId: hadoop-200-4:56924, NodeHttpAddress: hadoop-200-4:8042, Resource: <memory:1024, vCores:1>, Priority: 20, State: NEW, Token: null, Status: container_id {, app_attempt_id {, application_id {, id: 6, cluster_timestamp: 1375842659078, }, attemptId: 1, }, id: 20, }, state: C_NEW, ] containerId=container_1375842659078_0006_01_000020 queue=default: capacity=1.0, absoluteCapacity=1.0, usedResources=<memory:28672, vCores:23>usedCapacity=0.5833333, absoluteUsedCapacity=0.5833333, numApps=5, numContainers=23 usedCapacity=0.5833333 absoluteUsedCapacity=0.5833333 used=<memory:28672, vCores:23> cluster=<memory:49152, vCores:96>
2013-08-07 02:42:10,908 INFO org.apache.hadoop.yarn.server.resourcemanager.scheduler.capacity.ParentQueue: Re-sorting queues since queue: root.default stats: default: capacity=1.0, absoluteCapacity=1.0, usedResources=<memory:29696, vCores:24>usedCapacity=0.6041667, absoluteUsedCapacity=0.6041667, numApps=5, numContainers=24
2013-08-07 02:42:10,908 INFO org.apache.hadoop.yarn.server.resourcemanager.scheduler.capacity.ParentQueue: assignedContainer queue=root usedCapacity=0.6041667 absoluteUsedCapacity=0.6041667 used=<memory:29696, vCores:24> cluster=<memory:49152, vCores:96>
2013-08-07 02:42:10,908 INFO org.apache.hadoop.yarn.server.resourcemanager.rmcontainer.RMContainerImpl: container_1375842659078_0006_01_000021 Container Transitioned from NEW to ALLOCATED
2013-08-07 02:42:10,908 INFO org.apache.hadoop.yarn.server.resourcemanager.RMAuditLogger: USER=ubuntu	OPERATION=AM Allocated Container	TARGET=SchedulerApp	RESULT=SUCCESS	APPID=application_1375842659078_0006	CONTAINERID=container_1375842659078_0006_01_000021
2013-08-07 02:42:10,909 INFO org.apache.hadoop.yarn.server.resourcemanager.scheduler.common.fica.FiCaSchedulerNode: Assigned container container_1375842659078_0006_01_000021 of capacity <memory:1024, vCores:1> on host hadoop-200-4:56924, which currently has 4 containers, <memory:4096, vCores:4> used and <memory:4096, vCores:12> available
2013-08-07 02:42:10,910 INFO org.apache.hadoop.yarn.server.resourcemanager.scheduler.capacity.LeafQueue: assignedContainer application=application_1375842659078_0006 container=Container: [ContainerId: container_1375842659078_0006_01_000021, NodeId: hadoop-200-4:56924, NodeHttpAddress: hadoop-200-4:8042, Resource: <memory:1024, vCores:1>, Priority: 20, State: NEW, Token: null, Status: container_id {, app_attempt_id {, application_id {, id: 6, cluster_timestamp: 1375842659078, }, attemptId: 1, }, id: 21, }, state: C_NEW, ] containerId=container_1375842659078_0006_01_000021 queue=default: capacity=1.0, absoluteCapacity=1.0, usedResources=<memory:29696, vCores:24>usedCapacity=0.6041667, absoluteUsedCapacity=0.6041667, numApps=5, numContainers=24 usedCapacity=0.6041667 absoluteUsedCapacity=0.6041667 used=<memory:29696, vCores:24> cluster=<memory:49152, vCores:96>
2013-08-07 02:42:10,910 INFO org.apache.hadoop.yarn.server.resourcemanager.scheduler.capacity.ParentQueue: Re-sorting queues since queue: root.default stats: default: capacity=1.0, absoluteCapacity=1.0, usedResources=<memory:30720, vCores:25>usedCapacity=0.625, absoluteUsedCapacity=0.625, numApps=5, numContainers=25
2013-08-07 02:42:10,910 INFO org.apache.hadoop.yarn.server.resourcemanager.scheduler.capacity.ParentQueue: assignedContainer queue=root usedCapacity=0.625 absoluteUsedCapacity=0.625 used=<memory:30720, vCores:25> cluster=<memory:49152, vCores:96>
2013-08-07 02:42:10,910 INFO org.apache.hadoop.yarn.server.resourcemanager.rmcontainer.RMContainerImpl: container_1375842659078_0006_01_000022 Container Transitioned from NEW to ALLOCATED
2013-08-07 02:42:10,911 INFO org.apache.hadoop.yarn.server.resourcemanager.RMAuditLogger: USER=ubuntu	OPERATION=AM Allocated Container	TARGET=SchedulerApp	RESULT=SUCCESS	APPID=application_1375842659078_0006	CONTAINERID=container_1375842659078_0006_01_000022
2013-08-07 02:42:10,911 INFO org.apache.hadoop.yarn.server.resourcemanager.scheduler.common.fica.FiCaSchedulerNode: Assigned container container_1375842659078_0006_01_000022 of capacity <memory:1024, vCores:1> on host hadoop-200-4:56924, which currently has 5 containers, <memory:5120, vCores:5> used and <memory:3072, vCores:11> available
2013-08-07 02:42:10,912 INFO org.apache.hadoop.yarn.server.resourcemanager.scheduler.capacity.LeafQueue: assignedContainer application=application_1375842659078_0006 container=Container: [ContainerId: container_1375842659078_0006_01_000022, NodeId: hadoop-200-4:56924, NodeHttpAddress: hadoop-200-4:8042, Resource: <memory:1024, vCores:1>, Priority: 20, State: NEW, Token: null, Status: container_id {, app_attempt_id {, application_id {, id: 6, cluster_timestamp: 1375842659078, }, attemptId: 1, }, id: 22, }, state: C_NEW, ] containerId=container_1375842659078_0006_01_000022 queue=default: capacity=1.0, absoluteCapacity=1.0, usedResources=<memory:30720, vCores:25>usedCapacity=0.625, absoluteUsedCapacity=0.625, numApps=5, numContainers=25 usedCapacity=0.625 absoluteUsedCapacity=0.625 used=<memory:30720, vCores:25> cluster=<memory:49152, vCores:96>
2013-08-07 02:42:10,912 INFO org.apache.hadoop.yarn.server.resourcemanager.scheduler.capacity.ParentQueue: Re-sorting queues since queue: root.default stats: default: capacity=1.0, absoluteCapacity=1.0, usedResources=<memory:31744, vCores:26>usedCapacity=0.6458333, absoluteUsedCapacity=0.6458333, numApps=5, numContainers=26
2013-08-07 02:42:10,912 INFO org.apache.hadoop.yarn.server.resourcemanager.scheduler.capacity.ParentQueue: assignedContainer queue=root usedCapacity=0.6458333 absoluteUsedCapacity=0.6458333 used=<memory:31744, vCores:26> cluster=<memory:49152, vCores:96>
2013-08-07 02:42:10,913 INFO org.apache.hadoop.yarn.server.resourcemanager.rmcontainer.RMContainerImpl: container_1375842659078_0006_01_000023 Container Transitioned from NEW to ALLOCATED
2013-08-07 02:42:10,913 INFO org.apache.hadoop.yarn.server.resourcemanager.RMAuditLogger: USER=ubuntu	OPERATION=AM Allocated Container	TARGET=SchedulerApp	RESULT=SUCCESS	APPID=application_1375842659078_0006	CONTAINERID=container_1375842659078_0006_01_000023
2013-08-07 02:42:10,913 INFO org.apache.hadoop.yarn.server.resourcemanager.scheduler.common.fica.FiCaSchedulerNode: Assigned container container_1375842659078_0006_01_000023 of capacity <memory:1024, vCores:1> on host hadoop-200-4:56924, which currently has 6 containers, <memory:6144, vCores:6> used and <memory:2048, vCores:10> available
2013-08-07 02:42:10,914 INFO org.apache.hadoop.yarn.server.resourcemanager.scheduler.capacity.LeafQueue: assignedContainer application=application_1375842659078_0006 container=Container: [ContainerId: container_1375842659078_0006_01_000023, NodeId: hadoop-200-4:56924, NodeHttpAddress: hadoop-200-4:8042, Resource: <memory:1024, vCores:1>, Priority: 20, State: NEW, Token: null, Status: container_id {, app_attempt_id {, application_id {, id: 6, cluster_timestamp: 1375842659078, }, attemptId: 1, }, id: 23, }, state: C_NEW, ] containerId=container_1375842659078_0006_01_000023 queue=default: capacity=1.0, absoluteCapacity=1.0, usedResources=<memory:31744, vCores:26>usedCapacity=0.6458333, absoluteUsedCapacity=0.6458333, numApps=5, numContainers=26 usedCapacity=0.6458333 absoluteUsedCapacity=0.6458333 used=<memory:31744, vCores:26> cluster=<memory:49152, vCores:96>
2013-08-07 02:42:10,914 INFO org.apache.hadoop.yarn.server.resourcemanager.scheduler.capacity.ParentQueue: Re-sorting queues since queue: root.default stats: default: capacity=1.0, absoluteCapacity=1.0, usedResources=<memory:32768, vCores:27>usedCapacity=0.6666667, absoluteUsedCapacity=0.6666667, numApps=5, numContainers=27
2013-08-07 02:42:10,914 INFO org.apache.hadoop.yarn.server.resourcemanager.scheduler.capacity.ParentQueue: assignedContainer queue=root usedCapacity=0.6666667 absoluteUsedCapacity=0.6666667 used=<memory:32768, vCores:27> cluster=<memory:49152, vCores:96>
2013-08-07 02:42:10,915 INFO org.apache.hadoop.yarn.server.resourcemanager.rmcontainer.RMContainerImpl: container_1375842659078_0006_01_000024 Container Transitioned from NEW to ALLOCATED
2013-08-07 02:42:10,915 INFO org.apache.hadoop.yarn.server.resourcemanager.RMAuditLogger: USER=ubuntu	OPERATION=AM Allocated Container	TARGET=SchedulerApp	RESULT=SUCCESS	APPID=application_1375842659078_0006	CONTAINERID=container_1375842659078_0006_01_000024
2013-08-07 02:42:10,915 INFO org.apache.hadoop.yarn.server.resourcemanager.scheduler.common.fica.FiCaSchedulerNode: Assigned container container_1375842659078_0006_01_000024 of capacity <memory:1024, vCores:1> on host hadoop-200-4:56924, which currently has 7 containers, <memory:7168, vCores:7> used and <memory:1024, vCores:9> available
2013-08-07 02:42:10,916 INFO org.apache.hadoop.yarn.server.resourcemanager.scheduler.capacity.LeafQueue: assignedContainer application=application_1375842659078_0006 container=Container: [ContainerId: container_1375842659078_0006_01_000024, NodeId: hadoop-200-4:56924, NodeHttpAddress: hadoop-200-4:8042, Resource: <memory:1024, vCores:1>, Priority: 20, State: NEW, Token: null, Status: container_id {, app_attempt_id {, application_id {, id: 6, cluster_timestamp: 1375842659078, }, attemptId: 1, }, id: 24, }, state: C_NEW, ] containerId=container_1375842659078_0006_01_000024 queue=default: capacity=1.0, absoluteCapacity=1.0, usedResources=<memory:32768, vCores:27>usedCapacity=0.6666667, absoluteUsedCapacity=0.6666667, numApps=5, numContainers=27 usedCapacity=0.6666667 absoluteUsedCapacity=0.6666667 used=<memory:32768, vCores:27> cluster=<memory:49152, vCores:96>
2013-08-07 02:42:10,916 INFO org.apache.hadoop.yarn.server.resourcemanager.scheduler.capacity.ParentQueue: Re-sorting queues since queue: root.default stats: default: capacity=1.0, absoluteCapacity=1.0, usedResources=<memory:33792, vCores:28>usedCapacity=0.6875, absoluteUsedCapacity=0.6875, numApps=5, numContainers=28
2013-08-07 02:42:10,917 INFO org.apache.hadoop.yarn.server.resourcemanager.scheduler.capacity.ParentQueue: assignedContainer queue=root usedCapacity=0.6875 absoluteUsedCapacity=0.6875 used=<memory:33792, vCores:28> cluster=<memory:49152, vCores:96>
2013-08-07 02:42:10,917 INFO org.apache.hadoop.yarn.server.resourcemanager.rmcontainer.RMContainerImpl: container_1375842659078_0006_01_000025 Container Transitioned from NEW to ALLOCATED
2013-08-07 02:42:10,917 INFO org.apache.hadoop.yarn.server.resourcemanager.RMAuditLogger: USER=ubuntu	OPERATION=AM Allocated Container	TARGET=SchedulerApp	RESULT=SUCCESS	APPID=application_1375842659078_0006	CONTAINERID=container_1375842659078_0006_01_000025
2013-08-07 02:42:10,917 INFO org.apache.hadoop.yarn.server.resourcemanager.scheduler.common.fica.FiCaSchedulerNode: Assigned container container_1375842659078_0006_01_000025 of capacity <memory:1024, vCores:1> on host hadoop-200-4:56924, which currently has 8 containers, <memory:8192, vCores:8> used and <memory:0, vCores:8> available
2013-08-07 02:42:10,918 INFO org.apache.hadoop.yarn.server.resourcemanager.scheduler.capacity.LeafQueue: assignedContainer application=application_1375842659078_0006 container=Container: [ContainerId: container_1375842659078_0006_01_000025, NodeId: hadoop-200-4:56924, NodeHttpAddress: hadoop-200-4:8042, Resource: <memory:1024, vCores:1>, Priority: 20, State: NEW, Token: null, Status: container_id {, app_attempt_id {, application_id {, id: 6, cluster_timestamp: 1375842659078, }, attemptId: 1, }, id: 25, }, state: C_NEW, ] containerId=container_1375842659078_0006_01_000025 queue=default: capacity=1.0, absoluteCapacity=1.0, usedResources=<memory:33792, vCores:28>usedCapacity=0.6875, absoluteUsedCapacity=0.6875, numApps=5, numContainers=28 usedCapacity=0.6875 absoluteUsedCapacity=0.6875 used=<memory:33792, vCores:28> cluster=<memory:49152, vCores:96>
2013-08-07 02:42:10,919 INFO org.apache.hadoop.yarn.server.resourcemanager.scheduler.capacity.ParentQueue: Re-sorting queues since queue: root.default stats: default: capacity=1.0, absoluteCapacity=1.0, usedResources=<memory:34816, vCores:29>usedCapacity=0.7083333, absoluteUsedCapacity=0.7083333, numApps=5, numContainers=29
2013-08-07 02:42:10,919 INFO org.apache.hadoop.yarn.server.resourcemanager.scheduler.capacity.ParentQueue: assignedContainer queue=root usedCapacity=0.7083333 absoluteUsedCapacity=0.7083333 used=<memory:34816, vCores:29> cluster=<memory:49152, vCores:96>
2013-08-07 02:42:11,105 INFO org.apache.hadoop.yarn.server.resourcemanager.ApplicationMasterService: AM registration appattempt_1375842659078_0008_000001
2013-08-07 02:42:11,106 INFO org.apache.hadoop.yarn.server.resourcemanager.RMAuditLogger: USER=ubuntu	IP=192.168.100.5	OPERATION=Register App Master	TARGET=ApplicationMasterService	RESULT=SUCCESS	APPID=application_1375842659078_0008	APPATTEMPTID=appattempt_1375842659078_0008_000001
2013-08-07 02:42:11,107 INFO org.apache.hadoop.yarn.server.resourcemanager.rmapp.attempt.RMAppAttemptImpl: appattempt_1375842659078_0008_000001 State change from LAUNCHED to RUNNING
2013-08-07 02:42:11,107 INFO org.apache.hadoop.yarn.server.resourcemanager.rmapp.RMAppImpl: application_1375842659078_0008 State change from ACCEPTED to RUNNING
2013-08-07 02:42:11,122 INFO org.apache.hadoop.yarn.server.resourcemanager.ApplicationMasterService: AM registration appattempt_1375842659078_0009_000001
2013-08-07 02:42:11,123 INFO org.apache.hadoop.yarn.server.resourcemanager.RMAuditLogger: USER=ubuntu	IP=192.168.100.9	OPERATION=Register App Master	TARGET=ApplicationMasterService	RESULT=SUCCESS	APPID=application_1375842659078_0009	APPATTEMPTID=appattempt_1375842659078_0009_000001
2013-08-07 02:42:11,123 INFO org.apache.hadoop.yarn.server.resourcemanager.rmapp.attempt.RMAppAttemptImpl: appattempt_1375842659078_0009_000001 State change from LAUNCHED to RUNNING
2013-08-07 02:42:11,123 INFO org.apache.hadoop.yarn.server.resourcemanager.rmapp.RMAppImpl: application_1375842659078_0009 State change from ACCEPTED to RUNNING
2013-08-07 02:42:11,393 INFO org.apache.hadoop.yarn.server.resourcemanager.rmcontainer.RMContainerImpl: container_1375842659078_0006_01_000026 Container Transitioned from NEW to ALLOCATED
2013-08-07 02:42:11,394 INFO org.apache.hadoop.yarn.server.resourcemanager.RMAuditLogger: USER=ubuntu	OPERATION=AM Allocated Container	TARGET=SchedulerApp	RESULT=SUCCESS	APPID=application_1375842659078_0006	CONTAINERID=container_1375842659078_0006_01_000026
2013-08-07 02:42:11,394 INFO org.apache.hadoop.yarn.server.resourcemanager.scheduler.common.fica.FiCaSchedulerNode: Assigned container container_1375842659078_0006_01_000026 of capacity <memory:1024, vCores:1> on host hadoop-200-5:38287, which currently has 3 containers, <memory:5120, vCores:3> used and <memory:3072, vCores:13> available
2013-08-07 02:42:11,395 INFO org.apache.hadoop.yarn.server.resourcemanager.scheduler.capacity.LeafQueue: assignedContainer application=application_1375842659078_0006 container=Container: [ContainerId: container_1375842659078_0006_01_000026, NodeId: hadoop-200-5:38287, NodeHttpAddress: hadoop-200-5:8042, Resource: <memory:1024, vCores:1>, Priority: 20, State: NEW, Token: null, Status: container_id {, app_attempt_id {, application_id {, id: 6, cluster_timestamp: 1375842659078, }, attemptId: 1, }, id: 26, }, state: C_NEW, ] containerId=container_1375842659078_0006_01_000026 queue=default: capacity=1.0, absoluteCapacity=1.0, usedResources=<memory:34816, vCores:29>usedCapacity=0.7083333, absoluteUsedCapacity=0.7083333, numApps=5, numContainers=29 usedCapacity=0.7083333 absoluteUsedCapacity=0.7083333 used=<memory:34816, vCores:29> cluster=<memory:49152, vCores:96>
2013-08-07 02:42:11,395 INFO org.apache.hadoop.yarn.server.resourcemanager.scheduler.capacity.ParentQueue: Re-sorting queues since queue: root.default stats: default: capacity=1.0, absoluteCapacity=1.0, usedResources=<memory:35840, vCores:30>usedCapacity=0.7291667, absoluteUsedCapacity=0.7291667, numApps=5, numContainers=30
2013-08-07 02:42:11,395 INFO org.apache.hadoop.yarn.server.resourcemanager.scheduler.capacity.ParentQueue: assignedContainer queue=root usedCapacity=0.7291667 absoluteUsedCapacity=0.7291667 used=<memory:35840, vCores:30> cluster=<memory:49152, vCores:96>
2013-08-07 02:42:11,396 INFO org.apache.hadoop.yarn.server.resourcemanager.rmcontainer.RMContainerImpl: container_1375842659078_0006_01_000027 Container Transitioned from NEW to ALLOCATED
2013-08-07 02:42:11,396 INFO org.apache.hadoop.yarn.server.resourcemanager.RMAuditLogger: USER=ubuntu	OPERATION=AM Allocated Container	TARGET=SchedulerApp	RESULT=SUCCESS	APPID=application_1375842659078_0006	CONTAINERID=container_1375842659078_0006_01_000027
2013-08-07 02:42:11,396 INFO org.apache.hadoop.yarn.server.resourcemanager.scheduler.common.fica.FiCaSchedulerNode: Assigned container container_1375842659078_0006_01_000027 of capacity <memory:1024, vCores:1> on host hadoop-200-5:38287, which currently has 4 containers, <memory:6144, vCores:4> used and <memory:2048, vCores:12> available
2013-08-07 02:42:11,397 INFO org.apache.hadoop.yarn.server.resourcemanager.scheduler.capacity.LeafQueue: assignedContainer application=application_1375842659078_0006 container=Container: [ContainerId: container_1375842659078_0006_01_000027, NodeId: hadoop-200-5:38287, NodeHttpAddress: hadoop-200-5:8042, Resource: <memory:1024, vCores:1>, Priority: 20, State: NEW, Token: null, Status: container_id {, app_attempt_id {, application_id {, id: 6, cluster_timestamp: 1375842659078, }, attemptId: 1, }, id: 27, }, state: C_NEW, ] containerId=container_1375842659078_0006_01_000027 queue=default: capacity=1.0, absoluteCapacity=1.0, usedResources=<memory:35840, vCores:30>usedCapacity=0.7291667, absoluteUsedCapacity=0.7291667, numApps=5, numContainers=30 usedCapacity=0.7291667 absoluteUsedCapacity=0.7291667 used=<memory:35840, vCores:30> cluster=<memory:49152, vCores:96>
2013-08-07 02:42:11,397 INFO org.apache.hadoop.yarn.server.resourcemanager.scheduler.capacity.ParentQueue: Re-sorting queues since queue: root.default stats: default: capacity=1.0, absoluteCapacity=1.0, usedResources=<memory:36864, vCores:31>usedCapacity=0.75, absoluteUsedCapacity=0.75, numApps=5, numContainers=31
2013-08-07 02:42:11,397 INFO org.apache.hadoop.yarn.server.resourcemanager.scheduler.capacity.ParentQueue: assignedContainer queue=root usedCapacity=0.75 absoluteUsedCapacity=0.75 used=<memory:36864, vCores:31> cluster=<memory:49152, vCores:96>
2013-08-07 02:42:11,398 INFO org.apache.hadoop.yarn.server.resourcemanager.rmcontainer.RMContainerImpl: container_1375842659078_0006_01_000028 Container Transitioned from NEW to ALLOCATED
2013-08-07 02:42:11,398 INFO org.apache.hadoop.yarn.server.resourcemanager.RMAuditLogger: USER=ubuntu	OPERATION=AM Allocated Container	TARGET=SchedulerApp	RESULT=SUCCESS	APPID=application_1375842659078_0006	CONTAINERID=container_1375842659078_0006_01_000028
2013-08-07 02:42:11,398 INFO org.apache.hadoop.yarn.server.resourcemanager.scheduler.common.fica.FiCaSchedulerNode: Assigned container container_1375842659078_0006_01_000028 of capacity <memory:1024, vCores:1> on host hadoop-200-5:38287, which currently has 5 containers, <memory:7168, vCores:5> used and <memory:1024, vCores:11> available
2013-08-07 02:42:11,399 INFO org.apache.hadoop.yarn.server.resourcemanager.scheduler.capacity.LeafQueue: assignedContainer application=application_1375842659078_0006 container=Container: [ContainerId: container_1375842659078_0006_01_000028, NodeId: hadoop-200-5:38287, NodeHttpAddress: hadoop-200-5:8042, Resource: <memory:1024, vCores:1>, Priority: 20, State: NEW, Token: null, Status: container_id {, app_attempt_id {, application_id {, id: 6, cluster_timestamp: 1375842659078, }, attemptId: 1, }, id: 28, }, state: C_NEW, ] containerId=container_1375842659078_0006_01_000028 queue=default: capacity=1.0, absoluteCapacity=1.0, usedResources=<memory:36864, vCores:31>usedCapacity=0.75, absoluteUsedCapacity=0.75, numApps=5, numContainers=31 usedCapacity=0.75 absoluteUsedCapacity=0.75 used=<memory:36864, vCores:31> cluster=<memory:49152, vCores:96>
2013-08-07 02:42:11,399 INFO org.apache.hadoop.yarn.server.resourcemanager.scheduler.capacity.ParentQueue: Re-sorting queues since queue: root.default stats: default: capacity=1.0, absoluteCapacity=1.0, usedResources=<memory:37888, vCores:32>usedCapacity=0.7708333, absoluteUsedCapacity=0.7708333, numApps=5, numContainers=32
2013-08-07 02:42:11,400 INFO org.apache.hadoop.yarn.server.resourcemanager.scheduler.capacity.ParentQueue: assignedContainer queue=root usedCapacity=0.7708333 absoluteUsedCapacity=0.7708333 used=<memory:37888, vCores:32> cluster=<memory:49152, vCores:96>
2013-08-07 02:42:11,400 INFO org.apache.hadoop.yarn.server.resourcemanager.rmcontainer.RMContainerImpl: container_1375842659078_0006_01_000029 Container Transitioned from NEW to ALLOCATED
2013-08-07 02:42:11,400 INFO org.apache.hadoop.yarn.server.resourcemanager.RMAuditLogger: USER=ubuntu	OPERATION=AM Allocated Container	TARGET=SchedulerApp	RESULT=SUCCESS	APPID=application_1375842659078_0006	CONTAINERID=container_1375842659078_0006_01_000029
2013-08-07 02:42:11,400 INFO org.apache.hadoop.yarn.server.resourcemanager.scheduler.common.fica.FiCaSchedulerNode: Assigned container container_1375842659078_0006_01_000029 of capacity <memory:1024, vCores:1> on host hadoop-200-5:38287, which currently has 6 containers, <memory:8192, vCores:6> used and <memory:0, vCores:10> available
2013-08-07 02:42:11,401 INFO org.apache.hadoop.yarn.server.resourcemanager.scheduler.capacity.LeafQueue: assignedContainer application=application_1375842659078_0006 container=Container: [ContainerId: container_1375842659078_0006_01_000029, NodeId: hadoop-200-5:38287, NodeHttpAddress: hadoop-200-5:8042, Resource: <memory:1024, vCores:1>, Priority: 20, State: NEW, Token: null, Status: container_id {, app_attempt_id {, application_id {, id: 6, cluster_timestamp: 1375842659078, }, attemptId: 1, }, id: 29, }, state: C_NEW, ] containerId=container_1375842659078_0006_01_000029 queue=default: capacity=1.0, absoluteCapacity=1.0, usedResources=<memory:37888, vCores:32>usedCapacity=0.7708333, absoluteUsedCapacity=0.7708333, numApps=5, numContainers=32 usedCapacity=0.7708333 absoluteUsedCapacity=0.7708333 used=<memory:37888, vCores:32> cluster=<memory:49152, vCores:96>
2013-08-07 02:42:11,402 INFO org.apache.hadoop.yarn.server.resourcemanager.scheduler.capacity.ParentQueue: Re-sorting queues since queue: root.default stats: default: capacity=1.0, absoluteCapacity=1.0, usedResources=<memory:38912, vCores:33>usedCapacity=0.7916667, absoluteUsedCapacity=0.7916667, numApps=5, numContainers=33
2013-08-07 02:42:11,402 INFO org.apache.hadoop.yarn.server.resourcemanager.scheduler.capacity.ParentQueue: assignedContainer queue=root usedCapacity=0.7916667 absoluteUsedCapacity=0.7916667 used=<memory:38912, vCores:33> cluster=<memory:49152, vCores:96>
2013-08-07 02:42:11,468 INFO org.apache.hadoop.yarn.server.resourcemanager.rmcontainer.RMContainerImpl: container_1375842659078_0006_01_000030 Container Transitioned from NEW to ALLOCATED
2013-08-07 02:42:11,469 INFO org.apache.hadoop.yarn.server.resourcemanager.RMAuditLogger: USER=ubuntu	OPERATION=AM Allocated Container	TARGET=SchedulerApp	RESULT=SUCCESS	APPID=application_1375842659078_0006	CONTAINERID=container_1375842659078_0006_01_000030
2013-08-07 02:42:11,469 INFO org.apache.hadoop.yarn.server.resourcemanager.scheduler.common.fica.FiCaSchedulerNode: Assigned container container_1375842659078_0006_01_000030 of capacity <memory:1024, vCores:1> on host hadoop-200-7:59851, which currently has 3 containers, <memory:5120, vCores:3> used and <memory:3072, vCores:13> available
2013-08-07 02:42:11,470 INFO org.apache.hadoop.yarn.server.resourcemanager.scheduler.capacity.LeafQueue: assignedContainer application=application_1375842659078_0006 container=Container: [ContainerId: container_1375842659078_0006_01_000030, NodeId: hadoop-200-7:59851, NodeHttpAddress: hadoop-200-7:8042, Resource: <memory:1024, vCores:1>, Priority: 20, State: NEW, Token: null, Status: container_id {, app_attempt_id {, application_id {, id: 6, cluster_timestamp: 1375842659078, }, attemptId: 1, }, id: 30, }, state: C_NEW, ] containerId=container_1375842659078_0006_01_000030 queue=default: capacity=1.0, absoluteCapacity=1.0, usedResources=<memory:38912, vCores:33>usedCapacity=0.7916667, absoluteUsedCapacity=0.7916667, numApps=5, numContainers=33 usedCapacity=0.7916667 absoluteUsedCapacity=0.7916667 used=<memory:38912, vCores:33> cluster=<memory:49152, vCores:96>
2013-08-07 02:42:11,470 INFO org.apache.hadoop.yarn.server.resourcemanager.scheduler.capacity.ParentQueue: Re-sorting queues since queue: root.default stats: default: capacity=1.0, absoluteCapacity=1.0, usedResources=<memory:39936, vCores:34>usedCapacity=0.8125, absoluteUsedCapacity=0.8125, numApps=5, numContainers=34
2013-08-07 02:42:11,470 INFO org.apache.hadoop.yarn.server.resourcemanager.scheduler.capacity.ParentQueue: assignedContainer queue=root usedCapacity=0.8125 absoluteUsedCapacity=0.8125 used=<memory:39936, vCores:34> cluster=<memory:49152, vCores:96>
2013-08-07 02:42:11,471 INFO org.apache.hadoop.yarn.server.resourcemanager.rmcontainer.RMContainerImpl: container_1375842659078_0006_01_000031 Container Transitioned from NEW to ALLOCATED
2013-08-07 02:42:11,471 INFO org.apache.hadoop.yarn.server.resourcemanager.RMAuditLogger: USER=ubuntu	OPERATION=AM Allocated Container	TARGET=SchedulerApp	RESULT=SUCCESS	APPID=application_1375842659078_0006	CONTAINERID=container_1375842659078_0006_01_000031
2013-08-07 02:42:11,471 INFO org.apache.hadoop.yarn.server.resourcemanager.scheduler.common.fica.FiCaSchedulerNode: Assigned container container_1375842659078_0006_01_000031 of capacity <memory:1024, vCores:1> on host hadoop-200-7:59851, which currently has 4 containers, <memory:6144, vCores:4> used and <memory:2048, vCores:12> available
2013-08-07 02:42:11,472 INFO org.apache.hadoop.yarn.server.resourcemanager.scheduler.capacity.LeafQueue: assignedContainer application=application_1375842659078_0006 container=Container: [ContainerId: container_1375842659078_0006_01_000031, NodeId: hadoop-200-7:59851, NodeHttpAddress: hadoop-200-7:8042, Resource: <memory:1024, vCores:1>, Priority: 20, State: NEW, Token: null, Status: container_id {, app_attempt_id {, application_id {, id: 6, cluster_timestamp: 1375842659078, }, attemptId: 1, }, id: 31, }, state: C_NEW, ] containerId=container_1375842659078_0006_01_000031 queue=default: capacity=1.0, absoluteCapacity=1.0, usedResources=<memory:39936, vCores:34>usedCapacity=0.8125, absoluteUsedCapacity=0.8125, numApps=5, numContainers=34 usedCapacity=0.8125 absoluteUsedCapacity=0.8125 used=<memory:39936, vCores:34> cluster=<memory:49152, vCores:96>
2013-08-07 02:42:11,472 INFO org.apache.hadoop.yarn.server.resourcemanager.scheduler.capacity.ParentQueue: Re-sorting queues since queue: root.default stats: default: capacity=1.0, absoluteCapacity=1.0, usedResources=<memory:40960, vCores:35>usedCapacity=0.8333333, absoluteUsedCapacity=0.8333333, numApps=5, numContainers=35
2013-08-07 02:42:11,473 INFO org.apache.hadoop.yarn.server.resourcemanager.scheduler.capacity.ParentQueue: assignedContainer queue=root usedCapacity=0.8333333 absoluteUsedCapacity=0.8333333 used=<memory:40960, vCores:35> cluster=<memory:49152, vCores:96>
2013-08-07 02:42:11,473 INFO org.apache.hadoop.yarn.server.resourcemanager.rmcontainer.RMContainerImpl: container_1375842659078_0006_01_000032 Container Transitioned from NEW to ALLOCATED
2013-08-07 02:42:11,473 INFO org.apache.hadoop.yarn.server.resourcemanager.RMAuditLogger: USER=ubuntu	OPERATION=AM Allocated Container	TARGET=SchedulerApp	RESULT=SUCCESS	APPID=application_1375842659078_0006	CONTAINERID=container_1375842659078_0006_01_000032
2013-08-07 02:42:11,473 INFO org.apache.hadoop.yarn.server.resourcemanager.scheduler.common.fica.FiCaSchedulerNode: Assigned container container_1375842659078_0006_01_000032 of capacity <memory:1024, vCores:1> on host hadoop-200-7:59851, which currently has 5 containers, <memory:7168, vCores:5> used and <memory:1024, vCores:11> available
2013-08-07 02:42:11,474 INFO org.apache.hadoop.yarn.server.resourcemanager.scheduler.capacity.LeafQueue: assignedContainer application=application_1375842659078_0006 container=Container: [ContainerId: container_1375842659078_0006_01_000032, NodeId: hadoop-200-7:59851, NodeHttpAddress: hadoop-200-7:8042, Resource: <memory:1024, vCores:1>, Priority: 20, State: NEW, Token: null, Status: container_id {, app_attempt_id {, application_id {, id: 6, cluster_timestamp: 1375842659078, }, attemptId: 1, }, id: 32, }, state: C_NEW, ] containerId=container_1375842659078_0006_01_000032 queue=default: capacity=1.0, absoluteCapacity=1.0, usedResources=<memory:40960, vCores:35>usedCapacity=0.8333333, absoluteUsedCapacity=0.8333333, numApps=5, numContainers=35 usedCapacity=0.8333333 absoluteUsedCapacity=0.8333333 used=<memory:40960, vCores:35> cluster=<memory:49152, vCores:96>
2013-08-07 02:42:11,475 INFO org.apache.hadoop.yarn.server.resourcemanager.scheduler.capacity.ParentQueue: Re-sorting queues since queue: root.default stats: default: capacity=1.0, absoluteCapacity=1.0, usedResources=<memory:41984, vCores:36>usedCapacity=0.8541667, absoluteUsedCapacity=0.8541667, numApps=5, numContainers=36
2013-08-07 02:42:11,475 INFO org.apache.hadoop.yarn.server.resourcemanager.scheduler.capacity.ParentQueue: assignedContainer queue=root usedCapacity=0.8541667 absoluteUsedCapacity=0.8541667 used=<memory:41984, vCores:36> cluster=<memory:49152, vCores:96>
2013-08-07 02:42:11,475 INFO org.apache.hadoop.yarn.server.resourcemanager.rmcontainer.RMContainerImpl: container_1375842659078_0006_01_000033 Container Transitioned from NEW to ALLOCATED
2013-08-07 02:42:11,475 INFO org.apache.hadoop.yarn.server.resourcemanager.RMAuditLogger: USER=ubuntu	OPERATION=AM Allocated Container	TARGET=SchedulerApp	RESULT=SUCCESS	APPID=application_1375842659078_0006	CONTAINERID=container_1375842659078_0006_01_000033
2013-08-07 02:42:11,476 INFO org.apache.hadoop.yarn.server.resourcemanager.scheduler.common.fica.FiCaSchedulerNode: Assigned container container_1375842659078_0006_01_000033 of capacity <memory:1024, vCores:1> on host hadoop-200-7:59851, which currently has 6 containers, <memory:8192, vCores:6> used and <memory:0, vCores:10> available
2013-08-07 02:42:11,477 INFO org.apache.hadoop.yarn.server.resourcemanager.scheduler.capacity.LeafQueue: assignedContainer application=application_1375842659078_0006 container=Container: [ContainerId: container_1375842659078_0006_01_000033, NodeId: hadoop-200-7:59851, NodeHttpAddress: hadoop-200-7:8042, Resource: <memory:1024, vCores:1>, Priority: 20, State: NEW, Token: null, Status: container_id {, app_attempt_id {, application_id {, id: 6, cluster_timestamp: 1375842659078, }, attemptId: 1, }, id: 33, }, state: C_NEW, ] containerId=container_1375842659078_0006_01_000033 queue=default: capacity=1.0, absoluteCapacity=1.0, usedResources=<memory:41984, vCores:36>usedCapacity=0.8541667, absoluteUsedCapacity=0.8541667, numApps=5, numContainers=36 usedCapacity=0.8541667 absoluteUsedCapacity=0.8541667 used=<memory:41984, vCores:36> cluster=<memory:49152, vCores:96>
2013-08-07 02:42:11,477 INFO org.apache.hadoop.yarn.server.resourcemanager.scheduler.capacity.ParentQueue: Re-sorting queues since queue: root.default stats: default: capacity=1.0, absoluteCapacity=1.0, usedResources=<memory:43008, vCores:37>usedCapacity=0.875, absoluteUsedCapacity=0.875, numApps=5, numContainers=37
2013-08-07 02:42:11,477 INFO org.apache.hadoop.yarn.server.resourcemanager.scheduler.capacity.ParentQueue: assignedContainer queue=root usedCapacity=0.875 absoluteUsedCapacity=0.875 used=<memory:43008, vCores:37> cluster=<memory:49152, vCores:96>
2013-08-07 02:42:11,489 INFO org.apache.hadoop.yarn.server.resourcemanager.rmcontainer.RMContainerImpl: container_1375842659078_0006_01_000034 Container Transitioned from NEW to ALLOCATED
2013-08-07 02:42:11,489 INFO org.apache.hadoop.yarn.server.resourcemanager.RMAuditLogger: USER=ubuntu	OPERATION=AM Allocated Container	TARGET=SchedulerApp	RESULT=SUCCESS	APPID=application_1375842659078_0006	CONTAINERID=container_1375842659078_0006_01_000034
2013-08-07 02:42:11,490 INFO org.apache.hadoop.yarn.server.resourcemanager.scheduler.common.fica.FiCaSchedulerNode: Assigned container container_1375842659078_0006_01_000034 of capacity <memory:1024, vCores:1> on host hadoop-200-3:34020, which currently has 2 containers, <memory:3072, vCores:2> used and <memory:5120, vCores:14> available
2013-08-07 02:42:11,491 INFO org.apache.hadoop.yarn.server.resourcemanager.scheduler.capacity.LeafQueue: assignedContainer application=application_1375842659078_0006 container=Container: [ContainerId: container_1375842659078_0006_01_000034, NodeId: hadoop-200-3:34020, NodeHttpAddress: hadoop-200-3:8042, Resource: <memory:1024, vCores:1>, Priority: 20, State: NEW, Token: null, Status: container_id {, app_attempt_id {, application_id {, id: 6, cluster_timestamp: 1375842659078, }, attemptId: 1, }, id: 34, }, state: C_NEW, ] containerId=container_1375842659078_0006_01_000034 queue=default: capacity=1.0, absoluteCapacity=1.0, usedResources=<memory:43008, vCores:37>usedCapacity=0.875, absoluteUsedCapacity=0.875, numApps=5, numContainers=37 usedCapacity=0.875 absoluteUsedCapacity=0.875 used=<memory:43008, vCores:37> cluster=<memory:49152, vCores:96>
2013-08-07 02:42:11,491 INFO org.apache.hadoop.yarn.server.resourcemanager.scheduler.capacity.ParentQueue: Re-sorting queues since queue: root.default stats: default: capacity=1.0, absoluteCapacity=1.0, usedResources=<memory:44032, vCores:38>usedCapacity=0.8958333, absoluteUsedCapacity=0.8958333, numApps=5, numContainers=38
2013-08-07 02:42:11,491 INFO org.apache.hadoop.yarn.server.resourcemanager.scheduler.capacity.ParentQueue: assignedContainer queue=root usedCapacity=0.8958333 absoluteUsedCapacity=0.8958333 used=<memory:44032, vCores:38> cluster=<memory:49152, vCores:96>
2013-08-07 02:42:11,491 INFO org.apache.hadoop.yarn.server.resourcemanager.rmcontainer.RMContainerImpl: container_1375842659078_0006_01_000035 Container Transitioned from NEW to ALLOCATED
2013-08-07 02:42:11,492 INFO org.apache.hadoop.yarn.server.resourcemanager.RMAuditLogger: USER=ubuntu	OPERATION=AM Allocated Container	TARGET=SchedulerApp	RESULT=SUCCESS	APPID=application_1375842659078_0006	CONTAINERID=container_1375842659078_0006_01_000035
2013-08-07 02:42:11,492 INFO org.apache.hadoop.yarn.server.resourcemanager.scheduler.common.fica.FiCaSchedulerNode: Assigned container container_1375842659078_0006_01_000035 of capacity <memory:1024, vCores:1> on host hadoop-200-3:34020, which currently has 3 containers, <memory:4096, vCores:3> used and <memory:4096, vCores:13> available
2013-08-07 02:42:11,493 INFO org.apache.hadoop.yarn.server.resourcemanager.scheduler.capacity.LeafQueue: assignedContainer application=application_1375842659078_0006 container=Container: [ContainerId: container_1375842659078_0006_01_000035, NodeId: hadoop-200-3:34020, NodeHttpAddress: hadoop-200-3:8042, Resource: <memory:1024, vCores:1>, Priority: 20, State: NEW, Token: null, Status: container_id {, app_attempt_id {, application_id {, id: 6, cluster_timestamp: 1375842659078, }, attemptId: 1, }, id: 35, }, state: C_NEW, ] containerId=container_1375842659078_0006_01_000035 queue=default: capacity=1.0, absoluteCapacity=1.0, usedResources=<memory:44032, vCores:38>usedCapacity=0.8958333, absoluteUsedCapacity=0.8958333, numApps=5, numContainers=38 usedCapacity=0.8958333 absoluteUsedCapacity=0.8958333 used=<memory:44032, vCores:38> cluster=<memory:49152, vCores:96>
2013-08-07 02:42:11,493 INFO org.apache.hadoop.yarn.server.resourcemanager.scheduler.capacity.ParentQueue: Re-sorting queues since queue: root.default stats: default: capacity=1.0, absoluteCapacity=1.0, usedResources=<memory:45056, vCores:39>usedCapacity=0.9166667, absoluteUsedCapacity=0.9166667, numApps=5, numContainers=39
2013-08-07 02:42:11,493 INFO org.apache.hadoop.yarn.server.resourcemanager.scheduler.capacity.ParentQueue: assignedContainer queue=root usedCapacity=0.9166667 absoluteUsedCapacity=0.9166667 used=<memory:45056, vCores:39> cluster=<memory:49152, vCores:96>
2013-08-07 02:42:11,494 INFO org.apache.hadoop.yarn.server.resourcemanager.rmcontainer.RMContainerImpl: container_1375842659078_0006_01_000036 Container Transitioned from NEW to ALLOCATED
2013-08-07 02:42:11,494 INFO org.apache.hadoop.yarn.server.resourcemanager.RMAuditLogger: USER=ubuntu	OPERATION=AM Allocated Container	TARGET=SchedulerApp	RESULT=SUCCESS	APPID=application_1375842659078_0006	CONTAINERID=container_1375842659078_0006_01_000036
2013-08-07 02:42:11,494 INFO org.apache.hadoop.yarn.server.resourcemanager.scheduler.common.fica.FiCaSchedulerNode: Assigned container container_1375842659078_0006_01_000036 of capacity <memory:1024, vCores:1> on host hadoop-200-3:34020, which currently has 4 containers, <memory:5120, vCores:4> used and <memory:3072, vCores:12> available
2013-08-07 02:42:11,495 INFO org.apache.hadoop.yarn.server.resourcemanager.scheduler.capacity.LeafQueue: assignedContainer application=application_1375842659078_0006 container=Container: [ContainerId: container_1375842659078_0006_01_000036, NodeId: hadoop-200-3:34020, NodeHttpAddress: hadoop-200-3:8042, Resource: <memory:1024, vCores:1>, Priority: 20, State: NEW, Token: null, Status: container_id {, app_attempt_id {, application_id {, id: 6, cluster_timestamp: 1375842659078, }, attemptId: 1, }, id: 36, }, state: C_NEW, ] containerId=container_1375842659078_0006_01_000036 queue=default: capacity=1.0, absoluteCapacity=1.0, usedResources=<memory:45056, vCores:39>usedCapacity=0.9166667, absoluteUsedCapacity=0.9166667, numApps=5, numContainers=39 usedCapacity=0.9166667 absoluteUsedCapacity=0.9166667 used=<memory:45056, vCores:39> cluster=<memory:49152, vCores:96>
2013-08-07 02:42:11,495 INFO org.apache.hadoop.yarn.server.resourcemanager.scheduler.capacity.ParentQueue: Re-sorting queues since queue: root.default stats: default: capacity=1.0, absoluteCapacity=1.0, usedResources=<memory:46080, vCores:40>usedCapacity=0.9375, absoluteUsedCapacity=0.9375, numApps=5, numContainers=40
2013-08-07 02:42:11,495 INFO org.apache.hadoop.yarn.server.resourcemanager.scheduler.capacity.ParentQueue: assignedContainer queue=root usedCapacity=0.9375 absoluteUsedCapacity=0.9375 used=<memory:46080, vCores:40> cluster=<memory:49152, vCores:96>
2013-08-07 02:42:11,496 INFO org.apache.hadoop.yarn.server.resourcemanager.rmcontainer.RMContainerImpl: container_1375842659078_0006_01_000037 Container Transitioned from NEW to ALLOCATED
2013-08-07 02:42:11,496 INFO org.apache.hadoop.yarn.server.resourcemanager.RMAuditLogger: USER=ubuntu	OPERATION=AM Allocated Container	TARGET=SchedulerApp	RESULT=SUCCESS	APPID=application_1375842659078_0006	CONTAINERID=container_1375842659078_0006_01_000037
2013-08-07 02:42:11,496 INFO org.apache.hadoop.yarn.server.resourcemanager.scheduler.common.fica.FiCaSchedulerNode: Assigned container container_1375842659078_0006_01_000037 of capacity <memory:1024, vCores:1> on host hadoop-200-3:34020, which currently has 5 containers, <memory:6144, vCores:5> used and <memory:2048, vCores:11> available
2013-08-07 02:42:11,497 INFO org.apache.hadoop.yarn.server.resourcemanager.scheduler.capacity.LeafQueue: assignedContainer application=application_1375842659078_0006 container=Container: [ContainerId: container_1375842659078_0006_01_000037, NodeId: hadoop-200-3:34020, NodeHttpAddress: hadoop-200-3:8042, Resource: <memory:1024, vCores:1>, Priority: 20, State: NEW, Token: null, Status: container_id {, app_attempt_id {, application_id {, id: 6, cluster_timestamp: 1375842659078, }, attemptId: 1, }, id: 37, }, state: C_NEW, ] containerId=container_1375842659078_0006_01_000037 queue=default: capacity=1.0, absoluteCapacity=1.0, usedResources=<memory:46080, vCores:40>usedCapacity=0.9375, absoluteUsedCapacity=0.9375, numApps=5, numContainers=40 usedCapacity=0.9375 absoluteUsedCapacity=0.9375 used=<memory:46080, vCores:40> cluster=<memory:49152, vCores:96>
2013-08-07 02:42:11,497 INFO org.apache.hadoop.yarn.server.resourcemanager.scheduler.capacity.ParentQueue: Re-sorting queues since queue: root.default stats: default: capacity=1.0, absoluteCapacity=1.0, usedResources=<memory:47104, vCores:41>usedCapacity=0.9583333, absoluteUsedCapacity=0.9583333, numApps=5, numContainers=41
2013-08-07 02:42:11,497 INFO org.apache.hadoop.yarn.server.resourcemanager.scheduler.capacity.ParentQueue: assignedContainer queue=root usedCapacity=0.9583333 absoluteUsedCapacity=0.9583333 used=<memory:47104, vCores:41> cluster=<memory:49152, vCores:96>
2013-08-07 02:42:11,498 INFO org.apache.hadoop.yarn.server.resourcemanager.rmcontainer.RMContainerImpl: container_1375842659078_0006_01_000038 Container Transitioned from NEW to ALLOCATED
2013-08-07 02:42:11,498 INFO org.apache.hadoop.yarn.server.resourcemanager.RMAuditLogger: USER=ubuntu	OPERATION=AM Allocated Container	TARGET=SchedulerApp	RESULT=SUCCESS	APPID=application_1375842659078_0006	CONTAINERID=container_1375842659078_0006_01_000038
2013-08-07 02:42:11,498 INFO org.apache.hadoop.yarn.server.resourcemanager.scheduler.common.fica.FiCaSchedulerNode: Assigned container container_1375842659078_0006_01_000038 of capacity <memory:1024, vCores:1> on host hadoop-200-3:34020, which currently has 6 containers, <memory:7168, vCores:6> used and <memory:1024, vCores:10> available
2013-08-07 02:42:11,499 INFO org.apache.hadoop.yarn.server.resourcemanager.scheduler.capacity.LeafQueue: assignedContainer application=application_1375842659078_0006 container=Container: [ContainerId: container_1375842659078_0006_01_000038, NodeId: hadoop-200-3:34020, NodeHttpAddress: hadoop-200-3:8042, Resource: <memory:1024, vCores:1>, Priority: 20, State: NEW, Token: null, Status: container_id {, app_attempt_id {, application_id {, id: 6, cluster_timestamp: 1375842659078, }, attemptId: 1, }, id: 38, }, state: C_NEW, ] containerId=container_1375842659078_0006_01_000038 queue=default: capacity=1.0, absoluteCapacity=1.0, usedResources=<memory:47104, vCores:41>usedCapacity=0.9583333, absoluteUsedCapacity=0.9583333, numApps=5, numContainers=41 usedCapacity=0.9583333 absoluteUsedCapacity=0.9583333 used=<memory:47104, vCores:41> cluster=<memory:49152, vCores:96>
2013-08-07 02:42:11,499 INFO org.apache.hadoop.yarn.server.resourcemanager.scheduler.capacity.ParentQueue: Re-sorting queues since queue: root.default stats: default: capacity=1.0, absoluteCapacity=1.0, usedResources=<memory:48128, vCores:42>usedCapacity=0.9791667, absoluteUsedCapacity=0.9791667, numApps=5, numContainers=42
2013-08-07 02:42:11,500 INFO org.apache.hadoop.yarn.server.resourcemanager.scheduler.capacity.ParentQueue: assignedContainer queue=root usedCapacity=0.9791667 absoluteUsedCapacity=0.9791667 used=<memory:48128, vCores:42> cluster=<memory:49152, vCores:96>
2013-08-07 02:42:11,500 INFO org.apache.hadoop.yarn.server.resourcemanager.rmcontainer.RMContainerImpl: container_1375842659078_0006_01_000039 Container Transitioned from NEW to ALLOCATED
2013-08-07 02:42:11,500 INFO org.apache.hadoop.yarn.server.resourcemanager.RMAuditLogger: USER=ubuntu	OPERATION=AM Allocated Container	TARGET=SchedulerApp	RESULT=SUCCESS	APPID=application_1375842659078_0006	CONTAINERID=container_1375842659078_0006_01_000039
2013-08-07 02:42:11,500 INFO org.apache.hadoop.yarn.server.resourcemanager.scheduler.common.fica.FiCaSchedulerNode: Assigned container container_1375842659078_0006_01_000039 of capacity <memory:1024, vCores:1> on host hadoop-200-3:34020, which currently has 7 containers, <memory:8192, vCores:7> used and <memory:0, vCores:9> available
2013-08-07 02:42:11,501 INFO org.apache.hadoop.yarn.server.resourcemanager.scheduler.capacity.LeafQueue: assignedContainer application=application_1375842659078_0006 container=Container: [ContainerId: container_1375842659078_0006_01_000039, NodeId: hadoop-200-3:34020, NodeHttpAddress: hadoop-200-3:8042, Resource: <memory:1024, vCores:1>, Priority: 20, State: NEW, Token: null, Status: container_id {, app_attempt_id {, application_id {, id: 6, cluster_timestamp: 1375842659078, }, attemptId: 1, }, id: 39, }, state: C_NEW, ] containerId=container_1375842659078_0006_01_000039 queue=default: capacity=1.0, absoluteCapacity=1.0, usedResources=<memory:48128, vCores:42>usedCapacity=0.9791667, absoluteUsedCapacity=0.9791667, numApps=5, numContainers=42 usedCapacity=0.9791667 absoluteUsedCapacity=0.9791667 used=<memory:48128, vCores:42> cluster=<memory:49152, vCores:96>
2013-08-07 02:42:11,501 INFO org.apache.hadoop.yarn.server.resourcemanager.scheduler.capacity.ParentQueue: Re-sorting queues since queue: root.default stats: default: capacity=1.0, absoluteCapacity=1.0, usedResources=<memory:49152, vCores:43>usedCapacity=1.0, absoluteUsedCapacity=1.0, numApps=5, numContainers=43
2013-08-07 02:42:11,502 INFO org.apache.hadoop.yarn.server.resourcemanager.scheduler.capacity.ParentQueue: assignedContainer queue=root usedCapacity=1.0 absoluteUsedCapacity=1.0 used=<memory:49152, vCores:43> cluster=<memory:49152, vCores:96>
2013-08-07 02:42:11,701 INFO org.apache.hadoop.yarn.server.resourcemanager.rmcontainer.RMContainerImpl: container_1375842659078_0006_01_000002 Container Transitioned from ALLOCATED to ACQUIRED
2013-08-07 02:42:11,703 INFO org.apache.hadoop.yarn.server.resourcemanager.rmcontainer.RMContainerImpl: container_1375842659078_0006_01_000003 Container Transitioned from ALLOCATED to ACQUIRED
2013-08-07 02:42:11,711 INFO org.apache.hadoop.yarn.server.resourcemanager.rmcontainer.RMContainerImpl: container_1375842659078_0006_01_000004 Container Transitioned from ALLOCATED to ACQUIRED
2013-08-07 02:42:11,712 INFO org.apache.hadoop.yarn.server.resourcemanager.rmcontainer.RMContainerImpl: container_1375842659078_0006_01_000005 Container Transitioned from ALLOCATED to ACQUIRED
2013-08-07 02:42:11,713 INFO org.apache.hadoop.yarn.server.resourcemanager.rmcontainer.RMContainerImpl: container_1375842659078_0006_01_000006 Container Transitioned from ALLOCATED to ACQUIRED
2013-08-07 02:42:11,714 INFO org.apache.hadoop.yarn.server.resourcemanager.rmcontainer.RMContainerImpl: container_1375842659078_0006_01_000007 Container Transitioned from ALLOCATED to ACQUIRED
2013-08-07 02:42:11,715 INFO org.apache.hadoop.yarn.server.resourcemanager.rmcontainer.RMContainerImpl: container_1375842659078_0006_01_000008 Container Transitioned from ALLOCATED to ACQUIRED
2013-08-07 02:42:11,717 INFO org.apache.hadoop.yarn.server.resourcemanager.rmcontainer.RMContainerImpl: container_1375842659078_0006_01_000009 Container Transitioned from ALLOCATED to ACQUIRED
2013-08-07 02:42:11,718 INFO org.apache.hadoop.yarn.server.resourcemanager.rmcontainer.RMContainerImpl: container_1375842659078_0006_01_000010 Container Transitioned from ALLOCATED to ACQUIRED
2013-08-07 02:42:11,719 INFO org.apache.hadoop.yarn.server.resourcemanager.rmcontainer.RMContainerImpl: container_1375842659078_0006_01_000011 Container Transitioned from ALLOCATED to ACQUIRED
2013-08-07 02:42:11,719 INFO org.apache.hadoop.yarn.server.resourcemanager.rmcontainer.RMContainerImpl: container_1375842659078_0006_01_000012 Container Transitioned from ALLOCATED to ACQUIRED
2013-08-07 02:42:11,719 INFO org.apache.hadoop.yarn.server.resourcemanager.rmcontainer.RMContainerImpl: container_1375842659078_0006_01_000013 Container Transitioned from ALLOCATED to ACQUIRED
2013-08-07 02:42:11,720 INFO org.apache.hadoop.yarn.server.resourcemanager.rmcontainer.RMContainerImpl: container_1375842659078_0006_01_000014 Container Transitioned from ALLOCATED to ACQUIRED
2013-08-07 02:42:11,720 INFO org.apache.hadoop.yarn.server.resourcemanager.rmcontainer.RMContainerImpl: container_1375842659078_0006_01_000015 Container Transitioned from ALLOCATED to ACQUIRED
2013-08-07 02:42:11,720 INFO org.apache.hadoop.yarn.server.resourcemanager.rmcontainer.RMContainerImpl: container_1375842659078_0006_01_000016 Container Transitioned from ALLOCATED to ACQUIRED
2013-08-07 02:42:11,720 INFO org.apache.hadoop.yarn.server.resourcemanager.rmcontainer.RMContainerImpl: container_1375842659078_0006_01_000017 Container Transitioned from ALLOCATED to ACQUIRED
2013-08-07 02:42:11,720 INFO org.apache.hadoop.yarn.server.resourcemanager.rmcontainer.RMContainerImpl: container_1375842659078_0006_01_000018 Container Transitioned from ALLOCATED to ACQUIRED
2013-08-07 02:42:11,721 INFO org.apache.hadoop.yarn.server.resourcemanager.rmcontainer.RMContainerImpl: container_1375842659078_0006_01_000019 Container Transitioned from ALLOCATED to ACQUIRED
2013-08-07 02:42:11,721 INFO org.apache.hadoop.yarn.server.resourcemanager.rmcontainer.RMContainerImpl: container_1375842659078_0006_01_000020 Container Transitioned from ALLOCATED to ACQUIRED
2013-08-07 02:42:11,721 INFO org.apache.hadoop.yarn.server.resourcemanager.rmcontainer.RMContainerImpl: container_1375842659078_0006_01_000021 Container Transitioned from ALLOCATED to ACQUIRED
2013-08-07 02:42:11,721 INFO org.apache.hadoop.yarn.server.resourcemanager.rmcontainer.RMContainerImpl: container_1375842659078_0006_01_000022 Container Transitioned from ALLOCATED to ACQUIRED
2013-08-07 02:42:11,722 INFO org.apache.hadoop.yarn.server.resourcemanager.rmcontainer.RMContainerImpl: container_1375842659078_0006_01_000023 Container Transitioned from ALLOCATED to ACQUIRED
2013-08-07 02:42:11,722 INFO org.apache.hadoop.yarn.server.resourcemanager.rmcontainer.RMContainerImpl: container_1375842659078_0006_01_000024 Container Transitioned from ALLOCATED to ACQUIRED
2013-08-07 02:42:11,722 INFO org.apache.hadoop.yarn.server.resourcemanager.rmcontainer.RMContainerImpl: container_1375842659078_0006_01_000025 Container Transitioned from ALLOCATED to ACQUIRED
2013-08-07 02:42:11,722 INFO org.apache.hadoop.yarn.server.resourcemanager.rmcontainer.RMContainerImpl: container_1375842659078_0006_01_000026 Container Transitioned from ALLOCATED to ACQUIRED
2013-08-07 02:42:11,722 INFO org.apache.hadoop.yarn.server.resourcemanager.rmcontainer.RMContainerImpl: container_1375842659078_0006_01_000027 Container Transitioned from ALLOCATED to ACQUIRED
2013-08-07 02:42:11,722 INFO org.apache.hadoop.yarn.server.resourcemanager.rmcontainer.RMContainerImpl: container_1375842659078_0006_01_000028 Container Transitioned from ALLOCATED to ACQUIRED
2013-08-07 02:42:11,723 INFO org.apache.hadoop.yarn.server.resourcemanager.rmcontainer.RMContainerImpl: container_1375842659078_0006_01_000029 Container Transitioned from ALLOCATED to ACQUIRED
2013-08-07 02:42:11,723 INFO org.apache.hadoop.yarn.server.resourcemanager.rmcontainer.RMContainerImpl: container_1375842659078_0006_01_000030 Container Transitioned from ALLOCATED to ACQUIRED
2013-08-07 02:42:11,723 INFO org.apache.hadoop.yarn.server.resourcemanager.rmcontainer.RMContainerImpl: container_1375842659078_0006_01_000031 Container Transitioned from ALLOCATED to ACQUIRED
2013-08-07 02:42:11,723 INFO org.apache.hadoop.yarn.server.resourcemanager.rmcontainer.RMContainerImpl: container_1375842659078_0006_01_000032 Container Transitioned from ALLOCATED to ACQUIRED
2013-08-07 02:42:11,723 INFO org.apache.hadoop.yarn.server.resourcemanager.rmcontainer.RMContainerImpl: container_1375842659078_0006_01_000033 Container Transitioned from ALLOCATED to ACQUIRED
2013-08-07 02:42:11,724 INFO org.apache.hadoop.yarn.server.resourcemanager.rmcontainer.RMContainerImpl: container_1375842659078_0006_01_000034 Container Transitioned from ALLOCATED to ACQUIRED
2013-08-07 02:42:11,724 INFO org.apache.hadoop.yarn.server.resourcemanager.rmcontainer.RMContainerImpl: container_1375842659078_0006_01_000035 Container Transitioned from ALLOCATED to ACQUIRED
2013-08-07 02:42:11,724 INFO org.apache.hadoop.yarn.server.resourcemanager.rmcontainer.RMContainerImpl: container_1375842659078_0006_01_000036 Container Transitioned from ALLOCATED to ACQUIRED
2013-08-07 02:42:11,724 INFO org.apache.hadoop.yarn.server.resourcemanager.rmcontainer.RMContainerImpl: container_1375842659078_0006_01_000037 Container Transitioned from ALLOCATED to ACQUIRED
2013-08-07 02:42:11,724 INFO org.apache.hadoop.yarn.server.resourcemanager.rmcontainer.RMContainerImpl: container_1375842659078_0006_01_000038 Container Transitioned from ALLOCATED to ACQUIRED
2013-08-07 02:42:11,725 INFO org.apache.hadoop.yarn.server.resourcemanager.rmcontainer.RMContainerImpl: container_1375842659078_0006_01_000039 Container Transitioned from ALLOCATED to ACQUIRED
2013-08-07 02:42:12,095 INFO org.apache.hadoop.yarn.server.resourcemanager.ApplicationMasterService: AM registration appattempt_1375842659078_0010_000001
2013-08-07 02:42:12,095 INFO org.apache.hadoop.yarn.server.resourcemanager.RMAuditLogger: USER=ubuntu	IP=192.168.100.4	OPERATION=Register App Master	TARGET=ApplicationMasterService	RESULT=SUCCESS	APPID=application_1375842659078_0010	APPATTEMPTID=appattempt_1375842659078_0010_000001
2013-08-07 02:42:12,097 INFO org.apache.hadoop.yarn.server.resourcemanager.rmapp.attempt.RMAppAttemptImpl: appattempt_1375842659078_0010_000001 State change from LAUNCHED to RUNNING
2013-08-07 02:42:12,097 INFO org.apache.hadoop.yarn.server.resourcemanager.rmapp.RMAppImpl: application_1375842659078_0010 State change from ACCEPTED to RUNNING
2013-08-07 02:42:12,412 INFO org.apache.hadoop.yarn.server.resourcemanager.rmcontainer.RMContainerImpl: container_1375842659078_0006_01_000026 Container Transitioned from ACQUIRED to RUNNING
2013-08-07 02:42:12,413 INFO org.apache.hadoop.yarn.server.resourcemanager.rmcontainer.RMContainerImpl: container_1375842659078_0006_01_000027 Container Transitioned from ACQUIRED to RUNNING
2013-08-07 02:42:12,414 INFO org.apache.hadoop.yarn.server.resourcemanager.rmcontainer.RMContainerImpl: container_1375842659078_0006_01_000028 Container Transitioned from ACQUIRED to RUNNING
2013-08-07 02:42:12,415 INFO org.apache.hadoop.yarn.server.resourcemanager.rmcontainer.RMContainerImpl: container_1375842659078_0006_01_000029 Container Transitioned from ACQUIRED to RUNNING
2013-08-07 02:42:12,489 INFO org.apache.hadoop.yarn.server.resourcemanager.rmcontainer.RMContainerImpl: container_1375842659078_0006_01_000030 Container Transitioned from ACQUIRED to RUNNING
2013-08-07 02:42:12,490 INFO org.apache.hadoop.yarn.server.resourcemanager.rmcontainer.RMContainerImpl: container_1375842659078_0006_01_000031 Container Transitioned from ACQUIRED to RUNNING
2013-08-07 02:42:12,490 INFO org.apache.hadoop.yarn.server.resourcemanager.rmcontainer.RMContainerImpl: container_1375842659078_0006_01_000032 Container Transitioned from ACQUIRED to RUNNING
2013-08-07 02:42:12,491 INFO org.apache.hadoop.yarn.server.resourcemanager.rmcontainer.RMContainerImpl: container_1375842659078_0006_01_000033 Container Transitioned from ACQUIRED to RUNNING
2013-08-07 02:42:12,526 INFO org.apache.hadoop.yarn.server.resourcemanager.rmcontainer.RMContainerImpl: container_1375842659078_0006_01_000034 Container Transitioned from ACQUIRED to RUNNING
2013-08-07 02:42:12,526 INFO org.apache.hadoop.yarn.server.resourcemanager.rmcontainer.RMContainerImpl: container_1375842659078_0006_01_000035 Container Transitioned from ACQUIRED to RUNNING
2013-08-07 02:42:12,527 INFO org.apache.hadoop.yarn.server.resourcemanager.rmcontainer.RMContainerImpl: container_1375842659078_0006_01_000036 Container Transitioned from ACQUIRED to RUNNING
2013-08-07 02:42:12,528 INFO org.apache.hadoop.yarn.server.resourcemanager.rmcontainer.RMContainerImpl: container_1375842659078_0006_01_000037 Container Transitioned from ACQUIRED to RUNNING
2013-08-07 02:42:12,528 INFO org.apache.hadoop.yarn.server.resourcemanager.rmcontainer.RMContainerImpl: container_1375842659078_0006_01_000038 Container Transitioned from ACQUIRED to RUNNING
2013-08-07 02:42:12,537 INFO org.apache.hadoop.yarn.server.resourcemanager.rmcontainer.RMContainerImpl: container_1375842659078_0006_01_000039 Container Transitioned from ACQUIRED to RUNNING
2013-08-07 02:42:12,787 INFO org.apache.hadoop.yarn.server.resourcemanager.rmcontainer.RMContainerImpl: container_1375842659078_0006_01_000002 Container Transitioned from ACQUIRED to RUNNING
2013-08-07 02:42:12,787 INFO org.apache.hadoop.yarn.server.resourcemanager.rmcontainer.RMContainerImpl: container_1375842659078_0006_01_000003 Container Transitioned from ACQUIRED to RUNNING
2013-08-07 02:42:12,787 INFO org.apache.hadoop.yarn.server.resourcemanager.rmcontainer.RMContainerImpl: container_1375842659078_0006_01_000004 Container Transitioned from ACQUIRED to RUNNING
2013-08-07 02:42:12,788 INFO org.apache.hadoop.yarn.server.resourcemanager.rmcontainer.RMContainerImpl: container_1375842659078_0006_01_000005 Container Transitioned from ACQUIRED to RUNNING
2013-08-07 02:42:12,788 INFO org.apache.hadoop.yarn.server.resourcemanager.rmcontainer.RMContainerImpl: container_1375842659078_0006_01_000006 Container Transitioned from ACQUIRED to RUNNING
2013-08-07 02:42:12,788 INFO org.apache.hadoop.yarn.server.resourcemanager.rmcontainer.RMContainerImpl: container_1375842659078_0006_01_000007 Container Transitioned from ACQUIRED to RUNNING
2013-08-07 02:42:12,788 INFO org.apache.hadoop.yarn.server.resourcemanager.rmcontainer.RMContainerImpl: container_1375842659078_0006_01_000008 Container Transitioned from ACQUIRED to RUNNING
2013-08-07 02:42:12,788 INFO org.apache.hadoop.yarn.server.resourcemanager.rmcontainer.RMContainerImpl: container_1375842659078_0006_01_000009 Container Transitioned from ACQUIRED to RUNNING
2013-08-07 02:42:12,938 INFO org.apache.hadoop.yarn.server.resourcemanager.rmcontainer.RMContainerImpl: container_1375842659078_0006_01_000010 Container Transitioned from ACQUIRED to RUNNING
2013-08-07 02:42:12,939 INFO org.apache.hadoop.yarn.server.resourcemanager.rmcontainer.RMContainerImpl: container_1375842659078_0006_01_000011 Container Transitioned from ACQUIRED to RUNNING
2013-08-07 02:42:12,940 INFO org.apache.hadoop.yarn.server.resourcemanager.rmcontainer.RMContainerImpl: container_1375842659078_0006_01_000012 Container Transitioned from ACQUIRED to RUNNING
2013-08-07 02:42:12,942 INFO org.apache.hadoop.yarn.server.resourcemanager.rmcontainer.RMContainerImpl: container_1375842659078_0006_01_000013 Container Transitioned from ACQUIRED to RUNNING
2013-08-07 02:42:12,942 INFO org.apache.hadoop.yarn.server.resourcemanager.rmcontainer.RMContainerImpl: container_1375842659078_0006_01_000014 Container Transitioned from ACQUIRED to RUNNING
2013-08-07 02:42:12,943 INFO org.apache.hadoop.yarn.server.resourcemanager.rmcontainer.RMContainerImpl: container_1375842659078_0006_01_000015 Container Transitioned from ACQUIRED to RUNNING
2013-08-07 02:42:12,945 INFO org.apache.hadoop.yarn.server.resourcemanager.rmcontainer.RMContainerImpl: container_1375842659078_0006_01_000016 Container Transitioned from ACQUIRED to RUNNING
2013-08-07 02:42:12,945 INFO org.apache.hadoop.yarn.server.resourcemanager.rmcontainer.RMContainerImpl: container_1375842659078_0006_01_000017 Container Transitioned from ACQUIRED to RUNNING
2013-08-07 02:42:12,946 INFO org.apache.hadoop.yarn.server.resourcemanager.rmcontainer.RMContainerImpl: container_1375842659078_0006_01_000018 Container Transitioned from ACQUIRED to RUNNING
2013-08-07 02:42:12,946 INFO org.apache.hadoop.yarn.server.resourcemanager.rmcontainer.RMContainerImpl: container_1375842659078_0006_01_000019 Container Transitioned from ACQUIRED to RUNNING
2013-08-07 02:42:12,946 INFO org.apache.hadoop.yarn.server.resourcemanager.rmcontainer.RMContainerImpl: container_1375842659078_0006_01_000020 Container Transitioned from ACQUIRED to RUNNING
2013-08-07 02:42:12,946 INFO org.apache.hadoop.yarn.server.resourcemanager.rmcontainer.RMContainerImpl: container_1375842659078_0006_01_000021 Container Transitioned from ACQUIRED to RUNNING
2013-08-07 02:42:12,946 INFO org.apache.hadoop.yarn.server.resourcemanager.rmcontainer.RMContainerImpl: container_1375842659078_0006_01_000022 Container Transitioned from ACQUIRED to RUNNING
2013-08-07 02:42:12,946 INFO org.apache.hadoop.yarn.server.resourcemanager.rmcontainer.RMContainerImpl: container_1375842659078_0006_01_000023 Container Transitioned from ACQUIRED to RUNNING
2013-08-07 02:42:12,947 INFO org.apache.hadoop.yarn.server.resourcemanager.rmcontainer.RMContainerImpl: container_1375842659078_0006_01_000024 Container Transitioned from ACQUIRED to RUNNING
2013-08-07 02:42:12,947 INFO org.apache.hadoop.yarn.server.resourcemanager.rmcontainer.RMContainerImpl: container_1375842659078_0006_01_000025 Container Transitioned from ACQUIRED to RUNNING
2013-08-07 02:42:29,035 INFO org.apache.hadoop.yarn.server.resourcemanager.rmcontainer.RMContainerImpl: container_1375842659078_0006_01_000028 Container Transitioned from RUNNING to COMPLETED
2013-08-07 02:42:29,035 INFO org.apache.hadoop.yarn.server.resourcemanager.scheduler.common.fica.FiCaSchedulerApp: Completed container: container_1375842659078_0006_01_000028 in state: COMPLETED event:FINISHED
2013-08-07 02:42:29,035 INFO org.apache.hadoop.yarn.server.resourcemanager.RMAuditLogger: USER=ubuntu	OPERATION=AM Released Container	TARGET=SchedulerApp	RESULT=SUCCESS	APPID=application_1375842659078_0006	CONTAINERID=container_1375842659078_0006_01_000028
2013-08-07 02:42:29,035 INFO org.apache.hadoop.yarn.server.resourcemanager.scheduler.common.fica.FiCaSchedulerNode: Released container container_1375842659078_0006_01_000028 of capacity <memory:1024, vCores:1> on host hadoop-200-5:38287, which currently has 5 containers, <memory:7168, vCores:5> used and <memory:1024, vCores:11> available, release resources=true
2013-08-07 02:42:29,035 INFO org.apache.hadoop.yarn.server.resourcemanager.scheduler.capacity.LeafQueue: default used=<memory:48128, vCores:42> numContainers=42 user=ubuntu user-resources=<memory:48128, vCores:42>
2013-08-07 02:42:29,038 INFO org.apache.hadoop.yarn.server.resourcemanager.scheduler.capacity.LeafQueue: completedContainer container=Container: [ContainerId: container_1375842659078_0006_01_000028, NodeId: hadoop-200-5:38287, NodeHttpAddress: hadoop-200-5:8042, Resource: <memory:1024, vCores:1>, Priority: 20, State: NEW, Token: null, Status: container_id {, app_attempt_id {, application_id {, id: 6, cluster_timestamp: 1375842659078, }, attemptId: 1, }, id: 28, }, state: C_COMPLETE, diagnostics: "Container killed by the ApplicationMaster.\n\n", exit_status: 143, ] resource=<memory:1024, vCores:1> queue=default: capacity=1.0, absoluteCapacity=1.0, usedResources=<memory:48128, vCores:42>usedCapacity=0.9791667, absoluteUsedCapacity=0.9791667, numApps=5, numContainers=42 usedCapacity=0.9791667 absoluteUsedCapacity=0.9791667 used=<memory:48128, vCores:42> cluster=<memory:49152, vCores:96>
2013-08-07 02:42:29,039 INFO org.apache.hadoop.yarn.server.resourcemanager.scheduler.capacity.ParentQueue: completedContainer queue=root usedCapacity=0.9791667 absoluteUsedCapacity=0.9791667 used=<memory:48128, vCores:42> cluster=<memory:49152, vCores:96>
2013-08-07 02:42:29,039 INFO org.apache.hadoop.yarn.server.resourcemanager.scheduler.capacity.CapacityScheduler: Application appattempt_1375842659078_0006_000001 released container container_1375842659078_0006_01_000028 on node: host: hadoop-200-5:38287 #containers=5 available=1024 used=7168 with event: FINISHED
2013-08-07 02:42:29,039 INFO org.apache.hadoop.yarn.server.resourcemanager.rmcontainer.RMContainerImpl: container_1375842659078_0006_01_000040 Container Transitioned from NEW to ALLOCATED
2013-08-07 02:42:29,040 INFO org.apache.hadoop.yarn.server.resourcemanager.RMAuditLogger: USER=ubuntu	OPERATION=AM Allocated Container	TARGET=SchedulerApp	RESULT=SUCCESS	APPID=application_1375842659078_0006	CONTAINERID=container_1375842659078_0006_01_000040
2013-08-07 02:42:29,040 INFO org.apache.hadoop.yarn.server.resourcemanager.scheduler.common.fica.FiCaSchedulerNode: Assigned container container_1375842659078_0006_01_000040 of capacity <memory:1024, vCores:1> on host hadoop-200-5:38287, which currently has 6 containers, <memory:8192, vCores:6> used and <memory:0, vCores:10> available
2013-08-07 02:42:29,041 INFO org.apache.hadoop.yarn.server.resourcemanager.scheduler.capacity.LeafQueue: assignedContainer application=application_1375842659078_0006 container=Container: [ContainerId: container_1375842659078_0006_01_000040, NodeId: hadoop-200-5:38287, NodeHttpAddress: hadoop-200-5:8042, Resource: <memory:1024, vCores:1>, Priority: 20, State: NEW, Token: null, Status: container_id {, app_attempt_id {, application_id {, id: 6, cluster_timestamp: 1375842659078, }, attemptId: 1, }, id: 40, }, state: C_NEW, ] containerId=container_1375842659078_0006_01_000040 queue=default: capacity=1.0, absoluteCapacity=1.0, usedResources=<memory:48128, vCores:42>usedCapacity=0.9791667, absoluteUsedCapacity=0.9791667, numApps=5, numContainers=42 usedCapacity=0.9791667 absoluteUsedCapacity=0.9791667 used=<memory:48128, vCores:42> cluster=<memory:49152, vCores:96>
2013-08-07 02:42:29,041 INFO org.apache.hadoop.yarn.server.resourcemanager.scheduler.capacity.ParentQueue: Re-sorting queues since queue: root.default stats: default: capacity=1.0, absoluteCapacity=1.0, usedResources=<memory:49152, vCores:43>usedCapacity=1.0, absoluteUsedCapacity=1.0, numApps=5, numContainers=43
2013-08-07 02:42:29,041 INFO org.apache.hadoop.yarn.server.resourcemanager.scheduler.capacity.ParentQueue: assignedContainer queue=root usedCapacity=1.0 absoluteUsedCapacity=1.0 used=<memory:49152, vCores:43> cluster=<memory:49152, vCores:96>
2013-08-07 02:42:29,982 INFO org.apache.hadoop.yarn.server.resourcemanager.rmcontainer.RMContainerImpl: container_1375842659078_0006_01_000040 Container Transitioned from ALLOCATED to ACQUIRED
2013-08-07 02:42:30,051 INFO org.apache.hadoop.yarn.server.resourcemanager.rmcontainer.RMContainerImpl: container_1375842659078_0006_01_000040 Container Transitioned from ACQUIRED to RUNNING
2013-08-07 02:42:30,051 INFO org.apache.hadoop.yarn.server.resourcemanager.rmcontainer.RMContainerImpl: container_1375842659078_0006_01_000027 Container Transitioned from RUNNING to COMPLETED
2013-08-07 02:42:30,051 INFO org.apache.hadoop.yarn.server.resourcemanager.scheduler.common.fica.FiCaSchedulerApp: Completed container: container_1375842659078_0006_01_000027 in state: COMPLETED event:FINISHED
2013-08-07 02:42:30,051 INFO org.apache.hadoop.yarn.server.resourcemanager.RMAuditLogger: USER=ubuntu	OPERATION=AM Released Container	TARGET=SchedulerApp	RESULT=SUCCESS	APPID=application_1375842659078_0006	CONTAINERID=container_1375842659078_0006_01_000027
2013-08-07 02:42:30,051 INFO org.apache.hadoop.yarn.server.resourcemanager.scheduler.common.fica.FiCaSchedulerNode: Released container container_1375842659078_0006_01_000027 of capacity <memory:1024, vCores:1> on host hadoop-200-5:38287, which currently has 5 containers, <memory:7168, vCores:5> used and <memory:1024, vCores:11> available, release resources=true
2013-08-07 02:42:30,052 INFO org.apache.hadoop.yarn.server.resourcemanager.scheduler.capacity.LeafQueue: default used=<memory:48128, vCores:42> numContainers=42 user=ubuntu user-resources=<memory:48128, vCores:42>
2013-08-07 02:42:30,053 INFO org.apache.hadoop.yarn.server.resourcemanager.scheduler.capacity.LeafQueue: completedContainer container=Container: [ContainerId: container_1375842659078_0006_01_000027, NodeId: hadoop-200-5:38287, NodeHttpAddress: hadoop-200-5:8042, Resource: <memory:1024, vCores:1>, Priority: 20, State: NEW, Token: null, Status: container_id {, app_attempt_id {, application_id {, id: 6, cluster_timestamp: 1375842659078, }, attemptId: 1, }, id: 27, }, state: C_COMPLETE, diagnostics: "Container killed by the ApplicationMaster.\n\n", exit_status: 143, ] resource=<memory:1024, vCores:1> queue=default: capacity=1.0, absoluteCapacity=1.0, usedResources=<memory:48128, vCores:42>usedCapacity=0.9791667, absoluteUsedCapacity=0.9791667, numApps=5, numContainers=42 usedCapacity=0.9791667 absoluteUsedCapacity=0.9791667 used=<memory:48128, vCores:42> cluster=<memory:49152, vCores:96>
2013-08-07 02:42:30,053 INFO org.apache.hadoop.yarn.server.resourcemanager.scheduler.capacity.ParentQueue: completedContainer queue=root usedCapacity=0.9791667 absoluteUsedCapacity=0.9791667 used=<memory:48128, vCores:42> cluster=<memory:49152, vCores:96>
2013-08-07 02:42:30,053 INFO org.apache.hadoop.yarn.server.resourcemanager.scheduler.capacity.CapacityScheduler: Application appattempt_1375842659078_0006_000001 released container container_1375842659078_0006_01_000027 on node: host: hadoop-200-5:38287 #containers=5 available=1024 used=7168 with event: FINISHED
2013-08-07 02:42:30,054 INFO org.apache.hadoop.yarn.server.resourcemanager.rmcontainer.RMContainerImpl: container_1375842659078_0006_01_000041 Container Transitioned from NEW to ALLOCATED
2013-08-07 02:42:30,054 INFO org.apache.hadoop.yarn.server.resourcemanager.RMAuditLogger: USER=ubuntu	OPERATION=AM Allocated Container	TARGET=SchedulerApp	RESULT=SUCCESS	APPID=application_1375842659078_0006	CONTAINERID=container_1375842659078_0006_01_000041
2013-08-07 02:42:30,054 INFO org.apache.hadoop.yarn.server.resourcemanager.scheduler.common.fica.FiCaSchedulerNode: Assigned container container_1375842659078_0006_01_000041 of capacity <memory:1024, vCores:1> on host hadoop-200-5:38287, which currently has 6 containers, <memory:8192, vCores:6> used and <memory:0, vCores:10> available
2013-08-07 02:42:30,055 INFO org.apache.hadoop.yarn.server.resourcemanager.scheduler.capacity.LeafQueue: assignedContainer application=application_1375842659078_0006 container=Container: [ContainerId: container_1375842659078_0006_01_000041, NodeId: hadoop-200-5:38287, NodeHttpAddress: hadoop-200-5:8042, Resource: <memory:1024, vCores:1>, Priority: 20, State: NEW, Token: null, Status: container_id {, app_attempt_id {, application_id {, id: 6, cluster_timestamp: 1375842659078, }, attemptId: 1, }, id: 41, }, state: C_NEW, ] containerId=container_1375842659078_0006_01_000041 queue=default: capacity=1.0, absoluteCapacity=1.0, usedResources=<memory:48128, vCores:42>usedCapacity=0.9791667, absoluteUsedCapacity=0.9791667, numApps=5, numContainers=42 usedCapacity=0.9791667 absoluteUsedCapacity=0.9791667 used=<memory:48128, vCores:42> cluster=<memory:49152, vCores:96>
2013-08-07 02:42:30,055 INFO org.apache.hadoop.yarn.server.resourcemanager.scheduler.capacity.ParentQueue: Re-sorting queues since queue: root.default stats: default: capacity=1.0, absoluteCapacity=1.0, usedResources=<memory:49152, vCores:43>usedCapacity=1.0, absoluteUsedCapacity=1.0, numApps=5, numContainers=43
2013-08-07 02:42:30,056 INFO org.apache.hadoop.yarn.server.resourcemanager.scheduler.capacity.ParentQueue: assignedContainer queue=root usedCapacity=1.0 absoluteUsedCapacity=1.0 used=<memory:49152, vCores:43> cluster=<memory:49152, vCores:96>
2013-08-07 02:42:30,966 INFO org.apache.hadoop.yarn.server.resourcemanager.rmcontainer.RMContainerImpl: container_1375842659078_0006_01_000031 Container Transitioned from RUNNING to COMPLETED
2013-08-07 02:42:30,966 INFO org.apache.hadoop.yarn.server.resourcemanager.scheduler.common.fica.FiCaSchedulerApp: Completed container: container_1375842659078_0006_01_000031 in state: COMPLETED event:FINISHED
2013-08-07 02:42:30,966 INFO org.apache.hadoop.yarn.server.resourcemanager.RMAuditLogger: USER=ubuntu	OPERATION=AM Released Container	TARGET=SchedulerApp	RESULT=SUCCESS	APPID=application_1375842659078_0006	CONTAINERID=container_1375842659078_0006_01_000031
2013-08-07 02:42:30,966 INFO org.apache.hadoop.yarn.server.resourcemanager.scheduler.common.fica.FiCaSchedulerNode: Released container container_1375842659078_0006_01_000031 of capacity <memory:1024, vCores:1> on host hadoop-200-7:59851, which currently has 5 containers, <memory:7168, vCores:5> used and <memory:1024, vCores:11> available, release resources=true
2013-08-07 02:42:30,966 INFO org.apache.hadoop.yarn.server.resourcemanager.scheduler.capacity.LeafQueue: default used=<memory:48128, vCores:42> numContainers=42 user=ubuntu user-resources=<memory:48128, vCores:42>
2013-08-07 02:42:30,968 INFO org.apache.hadoop.yarn.server.resourcemanager.scheduler.capacity.LeafQueue: completedContainer container=Container: [ContainerId: container_1375842659078_0006_01_000031, NodeId: hadoop-200-7:59851, NodeHttpAddress: hadoop-200-7:8042, Resource: <memory:1024, vCores:1>, Priority: 20, State: NEW, Token: null, Status: container_id {, app_attempt_id {, application_id {, id: 6, cluster_timestamp: 1375842659078, }, attemptId: 1, }, id: 31, }, state: C_COMPLETE, diagnostics: "Container killed by the ApplicationMaster.\n\n", exit_status: 143, ] resource=<memory:1024, vCores:1> queue=default: capacity=1.0, absoluteCapacity=1.0, usedResources=<memory:48128, vCores:42>usedCapacity=0.9791667, absoluteUsedCapacity=0.9791667, numApps=5, numContainers=42 usedCapacity=0.9791667 absoluteUsedCapacity=0.9791667 used=<memory:48128, vCores:42> cluster=<memory:49152, vCores:96>
2013-08-07 02:42:30,968 INFO org.apache.hadoop.yarn.server.resourcemanager.scheduler.capacity.ParentQueue: completedContainer queue=root usedCapacity=0.9791667 absoluteUsedCapacity=0.9791667 used=<memory:48128, vCores:42> cluster=<memory:49152, vCores:96>
2013-08-07 02:42:30,968 INFO org.apache.hadoop.yarn.server.resourcemanager.scheduler.capacity.CapacityScheduler: Application appattempt_1375842659078_0006_000001 released container container_1375842659078_0006_01_000031 on node: host: hadoop-200-7:59851 #containers=5 available=1024 used=7168 with event: FINISHED
2013-08-07 02:42:30,968 INFO org.apache.hadoop.yarn.server.resourcemanager.rmcontainer.RMContainerImpl: container_1375842659078_0007_01_000002 Container Transitioned from NEW to ALLOCATED
2013-08-07 02:42:30,969 INFO org.apache.hadoop.yarn.server.resourcemanager.RMAuditLogger: USER=ubuntu	OPERATION=AM Allocated Container	TARGET=SchedulerApp	RESULT=SUCCESS	APPID=application_1375842659078_0007	CONTAINERID=container_1375842659078_0007_01_000002
2013-08-07 02:42:30,969 INFO org.apache.hadoop.yarn.server.resourcemanager.scheduler.common.fica.FiCaSchedulerNode: Assigned container container_1375842659078_0007_01_000002 of capacity <memory:1024, vCores:1> on host hadoop-200-7:59851, which currently has 6 containers, <memory:8192, vCores:6> used and <memory:0, vCores:10> available
2013-08-07 02:42:30,970 INFO org.apache.hadoop.yarn.server.resourcemanager.scheduler.capacity.LeafQueue: assignedContainer application=application_1375842659078_0007 container=Container: [ContainerId: container_1375842659078_0007_01_000002, NodeId: hadoop-200-7:59851, NodeHttpAddress: hadoop-200-7:8042, Resource: <memory:1024, vCores:1>, Priority: 20, State: NEW, Token: null, Status: container_id {, app_attempt_id {, application_id {, id: 7, cluster_timestamp: 1375842659078, }, attemptId: 1, }, id: 2, }, state: C_NEW, ] containerId=container_1375842659078_0007_01_000002 queue=default: capacity=1.0, absoluteCapacity=1.0, usedResources=<memory:48128, vCores:42>usedCapacity=0.9791667, absoluteUsedCapacity=0.9791667, numApps=5, numContainers=42 usedCapacity=0.9791667 absoluteUsedCapacity=0.9791667 used=<memory:48128, vCores:42> cluster=<memory:49152, vCores:96>
2013-08-07 02:42:30,970 INFO org.apache.hadoop.yarn.server.resourcemanager.scheduler.capacity.ParentQueue: Re-sorting queues since queue: root.default stats: default: capacity=1.0, absoluteCapacity=1.0, usedResources=<memory:49152, vCores:43>usedCapacity=1.0, absoluteUsedCapacity=1.0, numApps=5, numContainers=43
2013-08-07 02:42:30,970 INFO org.apache.hadoop.yarn.server.resourcemanager.scheduler.capacity.ParentQueue: assignedContainer queue=root usedCapacity=1.0 absoluteUsedCapacity=1.0 used=<memory:49152, vCores:43> cluster=<memory:49152, vCores:96>
2013-08-07 02:42:31,040 INFO org.apache.hadoop.yarn.server.resourcemanager.rmcontainer.RMContainerImpl: container_1375842659078_0006_01_000041 Container Transitioned from ALLOCATED to ACQUIRED
2013-08-07 02:42:31,245 INFO org.apache.hadoop.yarn.server.resourcemanager.rmcontainer.RMContainerImpl: container_1375842659078_0007_01_000002 Container Transitioned from ALLOCATED to ACQUIRED
2013-08-07 02:42:31,717 INFO org.apache.hadoop.yarn.server.resourcemanager.rmcontainer.RMContainerImpl: container_1375842659078_0006_01_000041 Container Transitioned from ACQUIRED to RUNNING
2013-08-07 02:42:31,718 INFO org.apache.hadoop.yarn.server.resourcemanager.rmcontainer.RMContainerImpl: container_1375842659078_0006_01_000029 Container Transitioned from RUNNING to COMPLETED
2013-08-07 02:42:31,718 INFO org.apache.hadoop.yarn.server.resourcemanager.scheduler.common.fica.FiCaSchedulerApp: Completed container: container_1375842659078_0006_01_000029 in state: COMPLETED event:FINISHED
2013-08-07 02:42:31,718 INFO org.apache.hadoop.yarn.server.resourcemanager.RMAuditLogger: USER=ubuntu	OPERATION=AM Released Container	TARGET=SchedulerApp	RESULT=SUCCESS	APPID=application_1375842659078_0006	CONTAINERID=container_1375842659078_0006_01_000029
2013-08-07 02:42:31,718 INFO org.apache.hadoop.yarn.server.resourcemanager.scheduler.common.fica.FiCaSchedulerNode: Released container container_1375842659078_0006_01_000029 of capacity <memory:1024, vCores:1> on host hadoop-200-5:38287, which currently has 5 containers, <memory:7168, vCores:5> used and <memory:1024, vCores:11> available, release resources=true
2013-08-07 02:42:31,718 INFO org.apache.hadoop.yarn.server.resourcemanager.scheduler.capacity.LeafQueue: default used=<memory:48128, vCores:42> numContainers=42 user=ubuntu user-resources=<memory:48128, vCores:42>
2013-08-07 02:42:31,719 INFO org.apache.hadoop.yarn.server.resourcemanager.scheduler.capacity.LeafQueue: completedContainer container=Container: [ContainerId: container_1375842659078_0006_01_000029, NodeId: hadoop-200-5:38287, NodeHttpAddress: hadoop-200-5:8042, Resource: <memory:1024, vCores:1>, Priority: 20, State: NEW, Token: null, Status: container_id {, app_attempt_id {, application_id {, id: 6, cluster_timestamp: 1375842659078, }, attemptId: 1, }, id: 29, }, state: C_COMPLETE, diagnostics: "Container killed by the ApplicationMaster.\n\n", exit_status: 143, ] resource=<memory:1024, vCores:1> queue=default: capacity=1.0, absoluteCapacity=1.0, usedResources=<memory:48128, vCores:42>usedCapacity=0.9791667, absoluteUsedCapacity=0.9791667, numApps=5, numContainers=42 usedCapacity=0.9791667 absoluteUsedCapacity=0.9791667 used=<memory:48128, vCores:42> cluster=<memory:49152, vCores:96>
2013-08-07 02:42:31,720 INFO org.apache.hadoop.yarn.server.resourcemanager.scheduler.capacity.ParentQueue: completedContainer queue=root usedCapacity=0.9791667 absoluteUsedCapacity=0.9791667 used=<memory:48128, vCores:42> cluster=<memory:49152, vCores:96>
2013-08-07 02:42:31,720 INFO org.apache.hadoop.yarn.server.resourcemanager.scheduler.capacity.CapacityScheduler: Application appattempt_1375842659078_0006_000001 released container container_1375842659078_0006_01_000029 on node: host: hadoop-200-5:38287 #containers=5 available=1024 used=7168 with event: FINISHED
2013-08-07 02:42:31,720 INFO org.apache.hadoop.yarn.server.resourcemanager.rmcontainer.RMContainerImpl: container_1375842659078_0006_01_000042 Container Transitioned from NEW to ALLOCATED
2013-08-07 02:42:31,720 INFO org.apache.hadoop.yarn.server.resourcemanager.RMAuditLogger: USER=ubuntu	OPERATION=AM Allocated Container	TARGET=SchedulerApp	RESULT=SUCCESS	APPID=application_1375842659078_0006	CONTAINERID=container_1375842659078_0006_01_000042
2013-08-07 02:42:31,721 INFO org.apache.hadoop.yarn.server.resourcemanager.scheduler.common.fica.FiCaSchedulerNode: Assigned container container_1375842659078_0006_01_000042 of capacity <memory:1024, vCores:1> on host hadoop-200-5:38287, which currently has 6 containers, <memory:8192, vCores:6> used and <memory:0, vCores:10> available
2013-08-07 02:42:31,721 INFO org.apache.hadoop.yarn.server.resourcemanager.scheduler.capacity.LeafQueue: assignedContainer application=application_1375842659078_0006 container=Container: [ContainerId: container_1375842659078_0006_01_000042, NodeId: hadoop-200-5:38287, NodeHttpAddress: hadoop-200-5:8042, Resource: <memory:1024, vCores:1>, Priority: 10, State: NEW, Token: null, Status: container_id {, app_attempt_id {, application_id {, id: 6, cluster_timestamp: 1375842659078, }, attemptId: 1, }, id: 42, }, state: C_NEW, ] containerId=container_1375842659078_0006_01_000042 queue=default: capacity=1.0, absoluteCapacity=1.0, usedResources=<memory:48128, vCores:42>usedCapacity=0.9791667, absoluteUsedCapacity=0.9791667, numApps=5, numContainers=42 usedCapacity=0.9791667 absoluteUsedCapacity=0.9791667 used=<memory:48128, vCores:42> cluster=<memory:49152, vCores:96>
2013-08-07 02:42:31,722 INFO org.apache.hadoop.yarn.server.resourcemanager.scheduler.capacity.ParentQueue: Re-sorting queues since queue: root.default stats: default: capacity=1.0, absoluteCapacity=1.0, usedResources=<memory:49152, vCores:43>usedCapacity=1.0, absoluteUsedCapacity=1.0, numApps=5, numContainers=43
2013-08-07 02:42:31,722 INFO org.apache.hadoop.yarn.server.resourcemanager.scheduler.capacity.ParentQueue: assignedContainer queue=root usedCapacity=1.0 absoluteUsedCapacity=1.0 used=<memory:49152, vCores:43> cluster=<memory:49152, vCores:96>
2013-08-07 02:42:31,987 INFO org.apache.hadoop.yarn.server.resourcemanager.rmcontainer.RMContainerImpl: container_1375842659078_0007_01_000002 Container Transitioned from ACQUIRED to RUNNING
2013-08-07 02:42:32,052 INFO org.apache.hadoop.yarn.server.resourcemanager.rmcontainer.RMContainerImpl: container_1375842659078_0006_01_000042 Container Transitioned from ALLOCATED to ACQUIRED
2013-08-07 02:42:32,727 INFO org.apache.hadoop.yarn.server.resourcemanager.rmcontainer.RMContainerImpl: container_1375842659078_0006_01_000042 Container Transitioned from ACQUIRED to RUNNING
2013-08-07 02:42:36,159 INFO org.apache.hadoop.yarn.server.resourcemanager.rmcontainer.RMContainerImpl: container_1375842659078_0006_01_000017 Container Transitioned from RUNNING to COMPLETED
2013-08-07 02:42:36,159 INFO org.apache.hadoop.yarn.server.resourcemanager.scheduler.common.fica.FiCaSchedulerApp: Completed container: container_1375842659078_0006_01_000017 in state: COMPLETED event:FINISHED
2013-08-07 02:42:36,160 INFO org.apache.hadoop.yarn.server.resourcemanager.RMAuditLogger: USER=ubuntu	OPERATION=AM Released Container	TARGET=SchedulerApp	RESULT=SUCCESS	APPID=application_1375842659078_0006	CONTAINERID=container_1375842659078_0006_01_000017
2013-08-07 02:42:36,160 INFO org.apache.hadoop.yarn.server.resourcemanager.scheduler.common.fica.FiCaSchedulerNode: Released container container_1375842659078_0006_01_000017 of capacity <memory:1024, vCores:1> on host hadoop-200-2:33271, which currently has 7 containers, <memory:7168, vCores:7> used and <memory:1024, vCores:9> available, release resources=true
2013-08-07 02:42:36,160 INFO org.apache.hadoop.yarn.server.resourcemanager.scheduler.capacity.LeafQueue: default used=<memory:48128, vCores:42> numContainers=42 user=ubuntu user-resources=<memory:48128, vCores:42>
2013-08-07 02:42:36,161 INFO org.apache.hadoop.yarn.server.resourcemanager.scheduler.capacity.LeafQueue: completedContainer container=Container: [ContainerId: container_1375842659078_0006_01_000017, NodeId: hadoop-200-2:33271, NodeHttpAddress: hadoop-200-2:8042, Resource: <memory:1024, vCores:1>, Priority: 20, State: NEW, Token: null, Status: container_id {, app_attempt_id {, application_id {, id: 6, cluster_timestamp: 1375842659078, }, attemptId: 1, }, id: 17, }, state: C_COMPLETE, diagnostics: "Container killed by the ApplicationMaster.\n", exit_status: 0, ] resource=<memory:1024, vCores:1> queue=default: capacity=1.0, absoluteCapacity=1.0, usedResources=<memory:48128, vCores:42>usedCapacity=0.9791667, absoluteUsedCapacity=0.9791667, numApps=5, numContainers=42 usedCapacity=0.9791667 absoluteUsedCapacity=0.9791667 used=<memory:48128, vCores:42> cluster=<memory:49152, vCores:96>
2013-08-07 02:42:36,161 INFO org.apache.hadoop.yarn.server.resourcemanager.scheduler.capacity.ParentQueue: completedContainer queue=root usedCapacity=0.9791667 absoluteUsedCapacity=0.9791667 used=<memory:48128, vCores:42> cluster=<memory:49152, vCores:96>
2013-08-07 02:42:36,162 INFO org.apache.hadoop.yarn.server.resourcemanager.scheduler.capacity.CapacityScheduler: Application appattempt_1375842659078_0006_000001 released container container_1375842659078_0006_01_000017 on node: host: hadoop-200-2:33271 #containers=7 available=1024 used=7168 with event: FINISHED
2013-08-07 02:42:36,162 INFO org.apache.hadoop.yarn.server.resourcemanager.rmcontainer.RMContainerImpl: container_1375842659078_0006_01_000043 Container Transitioned from NEW to ALLOCATED
2013-08-07 02:42:36,162 INFO org.apache.hadoop.yarn.server.resourcemanager.RMAuditLogger: USER=ubuntu	OPERATION=AM Allocated Container	TARGET=SchedulerApp	RESULT=SUCCESS	APPID=application_1375842659078_0006	CONTAINERID=container_1375842659078_0006_01_000043
2013-08-07 02:42:36,162 INFO org.apache.hadoop.yarn.server.resourcemanager.scheduler.common.fica.FiCaSchedulerNode: Assigned container container_1375842659078_0006_01_000043 of capacity <memory:1024, vCores:1> on host hadoop-200-2:33271, which currently has 8 containers, <memory:8192, vCores:8> used and <memory:0, vCores:8> available
2013-08-07 02:42:36,163 INFO org.apache.hadoop.yarn.server.resourcemanager.scheduler.capacity.LeafQueue: assignedContainer application=application_1375842659078_0006 container=Container: [ContainerId: container_1375842659078_0006_01_000043, NodeId: hadoop-200-2:33271, NodeHttpAddress: hadoop-200-2:8042, Resource: <memory:1024, vCores:1>, Priority: 10, State: NEW, Token: null, Status: container_id {, app_attempt_id {, application_id {, id: 6, cluster_timestamp: 1375842659078, }, attemptId: 1, }, id: 43, }, state: C_NEW, ] containerId=container_1375842659078_0006_01_000043 queue=default: capacity=1.0, absoluteCapacity=1.0, usedResources=<memory:48128, vCores:42>usedCapacity=0.9791667, absoluteUsedCapacity=0.9791667, numApps=5, numContainers=42 usedCapacity=0.9791667 absoluteUsedCapacity=0.9791667 used=<memory:48128, vCores:42> cluster=<memory:49152, vCores:96>
2013-08-07 02:42:36,163 INFO org.apache.hadoop.yarn.server.resourcemanager.scheduler.capacity.ParentQueue: Re-sorting queues since queue: root.default stats: default: capacity=1.0, absoluteCapacity=1.0, usedResources=<memory:49152, vCores:43>usedCapacity=1.0, absoluteUsedCapacity=1.0, numApps=5, numContainers=43
2013-08-07 02:42:36,164 INFO org.apache.hadoop.yarn.server.resourcemanager.scheduler.capacity.ParentQueue: assignedContainer queue=root usedCapacity=1.0 absoluteUsedCapacity=1.0 used=<memory:49152, vCores:43> cluster=<memory:49152, vCores:96>
2013-08-07 02:42:37,078 INFO org.apache.hadoop.yarn.server.resourcemanager.rmcontainer.RMContainerImpl: container_1375842659078_0006_01_000043 Container Transitioned from ALLOCATED to ACQUIRED
2013-08-07 02:42:37,177 INFO org.apache.hadoop.yarn.server.resourcemanager.rmcontainer.RMContainerImpl: container_1375842659078_0006_01_000043 Container Transitioned from ACQUIRED to RUNNING
2013-08-07 02:42:38,395 INFO org.apache.hadoop.yarn.server.resourcemanager.rmcontainer.RMContainerImpl: container_1375842659078_0006_01_000037 Container Transitioned from RUNNING to COMPLETED
2013-08-07 02:42:38,396 INFO org.apache.hadoop.yarn.server.resourcemanager.scheduler.common.fica.FiCaSchedulerApp: Completed container: container_1375842659078_0006_01_000037 in state: COMPLETED event:FINISHED
2013-08-07 02:42:38,396 INFO org.apache.hadoop.yarn.server.resourcemanager.RMAuditLogger: USER=ubuntu	OPERATION=AM Released Container	TARGET=SchedulerApp	RESULT=SUCCESS	APPID=application_1375842659078_0006	CONTAINERID=container_1375842659078_0006_01_000037
2013-08-07 02:42:38,396 INFO org.apache.hadoop.yarn.server.resourcemanager.scheduler.common.fica.FiCaSchedulerNode: Released container container_1375842659078_0006_01_000037 of capacity <memory:1024, vCores:1> on host hadoop-200-3:34020, which currently has 6 containers, <memory:7168, vCores:6> used and <memory:1024, vCores:10> available, release resources=true
2013-08-07 02:42:38,396 INFO org.apache.hadoop.yarn.server.resourcemanager.scheduler.capacity.LeafQueue: default used=<memory:48128, vCores:42> numContainers=42 user=ubuntu user-resources=<memory:48128, vCores:42>
2013-08-07 02:42:38,397 INFO org.apache.hadoop.yarn.server.resourcemanager.scheduler.capacity.LeafQueue: completedContainer container=Container: [ContainerId: container_1375842659078_0006_01_000037, NodeId: hadoop-200-3:34020, NodeHttpAddress: hadoop-200-3:8042, Resource: <memory:1024, vCores:1>, Priority: 20, State: NEW, Token: null, Status: container_id {, app_attempt_id {, application_id {, id: 6, cluster_timestamp: 1375842659078, }, attemptId: 1, }, id: 37, }, state: C_COMPLETE, diagnostics: "Container killed by the ApplicationMaster.\n\n", exit_status: 143, ] resource=<memory:1024, vCores:1> queue=default: capacity=1.0, absoluteCapacity=1.0, usedResources=<memory:48128, vCores:42>usedCapacity=0.9791667, absoluteUsedCapacity=0.9791667, numApps=5, numContainers=42 usedCapacity=0.9791667 absoluteUsedCapacity=0.9791667 used=<memory:48128, vCores:42> cluster=<memory:49152, vCores:96>
2013-08-07 02:42:38,398 INFO org.apache.hadoop.yarn.server.resourcemanager.scheduler.capacity.ParentQueue: completedContainer queue=root usedCapacity=0.9791667 absoluteUsedCapacity=0.9791667 used=<memory:48128, vCores:42> cluster=<memory:49152, vCores:96>
2013-08-07 02:42:38,398 INFO org.apache.hadoop.yarn.server.resourcemanager.scheduler.capacity.CapacityScheduler: Application appattempt_1375842659078_0006_000001 released container container_1375842659078_0006_01_000037 on node: host: hadoop-200-3:34020 #containers=6 available=1024 used=7168 with event: FINISHED
2013-08-07 02:42:38,398 INFO org.apache.hadoop.yarn.server.resourcemanager.rmcontainer.RMContainerImpl: container_1375842659078_0006_01_000044 Container Transitioned from NEW to ALLOCATED
2013-08-07 02:42:38,398 INFO org.apache.hadoop.yarn.server.resourcemanager.RMAuditLogger: USER=ubuntu	OPERATION=AM Allocated Container	TARGET=SchedulerApp	RESULT=SUCCESS	APPID=application_1375842659078_0006	CONTAINERID=container_1375842659078_0006_01_000044
2013-08-07 02:42:38,398 INFO org.apache.hadoop.yarn.server.resourcemanager.scheduler.common.fica.FiCaSchedulerNode: Assigned container container_1375842659078_0006_01_000044 of capacity <memory:1024, vCores:1> on host hadoop-200-3:34020, which currently has 7 containers, <memory:8192, vCores:7> used and <memory:0, vCores:9> available
2013-08-07 02:42:38,399 INFO org.apache.hadoop.yarn.server.resourcemanager.scheduler.capacity.LeafQueue: assignedContainer application=application_1375842659078_0006 container=Container: [ContainerId: container_1375842659078_0006_01_000044, NodeId: hadoop-200-3:34020, NodeHttpAddress: hadoop-200-3:8042, Resource: <memory:1024, vCores:1>, Priority: 10, State: NEW, Token: null, Status: container_id {, app_attempt_id {, application_id {, id: 6, cluster_timestamp: 1375842659078, }, attemptId: 1, }, id: 44, }, state: C_NEW, ] containerId=container_1375842659078_0006_01_000044 queue=default: capacity=1.0, absoluteCapacity=1.0, usedResources=<memory:48128, vCores:42>usedCapacity=0.9791667, absoluteUsedCapacity=0.9791667, numApps=5, numContainers=42 usedCapacity=0.9791667 absoluteUsedCapacity=0.9791667 used=<memory:48128, vCores:42> cluster=<memory:49152, vCores:96>
2013-08-07 02:42:38,399 INFO org.apache.hadoop.yarn.server.resourcemanager.scheduler.capacity.ParentQueue: Re-sorting queues since queue: root.default stats: default: capacity=1.0, absoluteCapacity=1.0, usedResources=<memory:49152, vCores:43>usedCapacity=1.0, absoluteUsedCapacity=1.0, numApps=5, numContainers=43
2013-08-07 02:42:38,400 INFO org.apache.hadoop.yarn.server.resourcemanager.scheduler.capacity.ParentQueue: assignedContainer queue=root usedCapacity=1.0 absoluteUsedCapacity=1.0 used=<memory:49152, vCores:43> cluster=<memory:49152, vCores:96>
2013-08-07 02:42:39,002 INFO org.apache.hadoop.yarn.server.resourcemanager.rmcontainer.RMContainerImpl: container_1375842659078_0006_01_000033 Container Transitioned from RUNNING to COMPLETED
2013-08-07 02:42:39,002 INFO org.apache.hadoop.yarn.server.resourcemanager.scheduler.common.fica.FiCaSchedulerApp: Completed container: container_1375842659078_0006_01_000033 in state: COMPLETED event:FINISHED
2013-08-07 02:42:39,003 INFO org.apache.hadoop.yarn.server.resourcemanager.RMAuditLogger: USER=ubuntu	OPERATION=AM Released Container	TARGET=SchedulerApp	RESULT=SUCCESS	APPID=application_1375842659078_0006	CONTAINERID=container_1375842659078_0006_01_000033
2013-08-07 02:42:39,003 INFO org.apache.hadoop.yarn.server.resourcemanager.scheduler.common.fica.FiCaSchedulerNode: Released container container_1375842659078_0006_01_000033 of capacity <memory:1024, vCores:1> on host hadoop-200-7:59851, which currently has 5 containers, <memory:7168, vCores:5> used and <memory:1024, vCores:11> available, release resources=true
2013-08-07 02:42:39,003 INFO org.apache.hadoop.yarn.server.resourcemanager.scheduler.capacity.LeafQueue: default used=<memory:48128, vCores:42> numContainers=42 user=ubuntu user-resources=<memory:48128, vCores:42>
2013-08-07 02:42:39,004 INFO org.apache.hadoop.yarn.server.resourcemanager.scheduler.capacity.LeafQueue: completedContainer container=Container: [ContainerId: container_1375842659078_0006_01_000033, NodeId: hadoop-200-7:59851, NodeHttpAddress: hadoop-200-7:8042, Resource: <memory:1024, vCores:1>, Priority: 20, State: NEW, Token: null, Status: container_id {, app_attempt_id {, application_id {, id: 6, cluster_timestamp: 1375842659078, }, attemptId: 1, }, id: 33, }, state: C_COMPLETE, diagnostics: "Container killed by the ApplicationMaster.\n\n", exit_status: 143, ] resource=<memory:1024, vCores:1> queue=default: capacity=1.0, absoluteCapacity=1.0, usedResources=<memory:48128, vCores:42>usedCapacity=0.9791667, absoluteUsedCapacity=0.9791667, numApps=5, numContainers=42 usedCapacity=0.9791667 absoluteUsedCapacity=0.9791667 used=<memory:48128, vCores:42> cluster=<memory:49152, vCores:96>
2013-08-07 02:42:39,004 INFO org.apache.hadoop.yarn.server.resourcemanager.scheduler.capacity.ParentQueue: completedContainer queue=root usedCapacity=0.9791667 absoluteUsedCapacity=0.9791667 used=<memory:48128, vCores:42> cluster=<memory:49152, vCores:96>
2013-08-07 02:42:39,004 INFO org.apache.hadoop.yarn.server.resourcemanager.scheduler.capacity.CapacityScheduler: Application appattempt_1375842659078_0006_000001 released container container_1375842659078_0006_01_000033 on node: host: hadoop-200-7:59851 #containers=5 available=1024 used=7168 with event: FINISHED
2013-08-07 02:42:39,005 INFO org.apache.hadoop.yarn.server.resourcemanager.rmcontainer.RMContainerImpl: container_1375842659078_0006_01_000045 Container Transitioned from NEW to ALLOCATED
2013-08-07 02:42:39,005 INFO org.apache.hadoop.yarn.server.resourcemanager.RMAuditLogger: USER=ubuntu	OPERATION=AM Allocated Container	TARGET=SchedulerApp	RESULT=SUCCESS	APPID=application_1375842659078_0006	CONTAINERID=container_1375842659078_0006_01_000045
2013-08-07 02:42:39,005 INFO org.apache.hadoop.yarn.server.resourcemanager.scheduler.common.fica.FiCaSchedulerNode: Assigned container container_1375842659078_0006_01_000045 of capacity <memory:1024, vCores:1> on host hadoop-200-7:59851, which currently has 6 containers, <memory:8192, vCores:6> used and <memory:0, vCores:10> available
2013-08-07 02:42:39,006 INFO org.apache.hadoop.yarn.server.resourcemanager.scheduler.capacity.LeafQueue: assignedContainer application=application_1375842659078_0006 container=Container: [ContainerId: container_1375842659078_0006_01_000045, NodeId: hadoop-200-7:59851, NodeHttpAddress: hadoop-200-7:8042, Resource: <memory:1024, vCores:1>, Priority: 10, State: NEW, Token: null, Status: container_id {, app_attempt_id {, application_id {, id: 6, cluster_timestamp: 1375842659078, }, attemptId: 1, }, id: 45, }, state: C_NEW, ] containerId=container_1375842659078_0006_01_000045 queue=default: capacity=1.0, absoluteCapacity=1.0, usedResources=<memory:48128, vCores:42>usedCapacity=0.9791667, absoluteUsedCapacity=0.9791667, numApps=5, numContainers=42 usedCapacity=0.9791667 absoluteUsedCapacity=0.9791667 used=<memory:48128, vCores:42> cluster=<memory:49152, vCores:96>
2013-08-07 02:42:39,006 INFO org.apache.hadoop.yarn.server.resourcemanager.scheduler.capacity.ParentQueue: Re-sorting queues since queue: root.default stats: default: capacity=1.0, absoluteCapacity=1.0, usedResources=<memory:49152, vCores:43>usedCapacity=1.0, absoluteUsedCapacity=1.0, numApps=5, numContainers=43
2013-08-07 02:42:39,007 INFO org.apache.hadoop.yarn.server.resourcemanager.scheduler.capacity.ParentQueue: assignedContainer queue=root usedCapacity=1.0 absoluteUsedCapacity=1.0 used=<memory:49152, vCores:43> cluster=<memory:49152, vCores:96>
2013-08-07 02:42:39,089 INFO org.apache.hadoop.yarn.server.resourcemanager.rmcontainer.RMContainerImpl: container_1375842659078_0006_01_000044 Container Transitioned from ALLOCATED to ACQUIRED
2013-08-07 02:42:39,089 INFO org.apache.hadoop.yarn.server.resourcemanager.rmcontainer.RMContainerImpl: container_1375842659078_0006_01_000045 Container Transitioned from ALLOCATED to ACQUIRED
2013-08-07 02:42:39,417 INFO org.apache.hadoop.yarn.server.resourcemanager.rmcontainer.RMContainerImpl: container_1375842659078_0006_01_000044 Container Transitioned from ACQUIRED to RUNNING
2013-08-07 02:42:39,705 INFO org.apache.hadoop.yarn.server.resourcemanager.rmcontainer.RMContainerImpl: container_1375842659078_0006_01_000045 Container Transitioned from ACQUIRED to RUNNING
2013-08-07 02:42:40,717 INFO org.apache.hadoop.yarn.server.resourcemanager.rmcontainer.RMContainerImpl: container_1375842659078_0006_01_000030 Container Transitioned from RUNNING to COMPLETED
2013-08-07 02:42:40,718 INFO org.apache.hadoop.yarn.server.resourcemanager.scheduler.common.fica.FiCaSchedulerApp: Completed container: container_1375842659078_0006_01_000030 in state: COMPLETED event:FINISHED
2013-08-07 02:42:40,718 INFO org.apache.hadoop.yarn.server.resourcemanager.RMAuditLogger: USER=ubuntu	OPERATION=AM Released Container	TARGET=SchedulerApp	RESULT=SUCCESS	APPID=application_1375842659078_0006	CONTAINERID=container_1375842659078_0006_01_000030
2013-08-07 02:42:40,718 INFO org.apache.hadoop.yarn.server.resourcemanager.scheduler.common.fica.FiCaSchedulerNode: Released container container_1375842659078_0006_01_000030 of capacity <memory:1024, vCores:1> on host hadoop-200-7:59851, which currently has 5 containers, <memory:7168, vCores:5> used and <memory:1024, vCores:11> available, release resources=true
2013-08-07 02:42:40,718 INFO org.apache.hadoop.yarn.server.resourcemanager.scheduler.capacity.LeafQueue: default used=<memory:48128, vCores:42> numContainers=42 user=ubuntu user-resources=<memory:48128, vCores:42>
2013-08-07 02:42:40,719 INFO org.apache.hadoop.yarn.server.resourcemanager.scheduler.capacity.LeafQueue: completedContainer container=Container: [ContainerId: container_1375842659078_0006_01_000030, NodeId: hadoop-200-7:59851, NodeHttpAddress: hadoop-200-7:8042, Resource: <memory:1024, vCores:1>, Priority: 20, State: NEW, Token: null, Status: container_id {, app_attempt_id {, application_id {, id: 6, cluster_timestamp: 1375842659078, }, attemptId: 1, }, id: 30, }, state: C_COMPLETE, diagnostics: "Container killed by the ApplicationMaster.\n\n", exit_status: 143, ] resource=<memory:1024, vCores:1> queue=default: capacity=1.0, absoluteCapacity=1.0, usedResources=<memory:48128, vCores:42>usedCapacity=0.9791667, absoluteUsedCapacity=0.9791667, numApps=5, numContainers=42 usedCapacity=0.9791667 absoluteUsedCapacity=0.9791667 used=<memory:48128, vCores:42> cluster=<memory:49152, vCores:96>
2013-08-07 02:42:40,719 INFO org.apache.hadoop.yarn.server.resourcemanager.scheduler.capacity.ParentQueue: completedContainer queue=root usedCapacity=0.9791667 absoluteUsedCapacity=0.9791667 used=<memory:48128, vCores:42> cluster=<memory:49152, vCores:96>
2013-08-07 02:42:40,719 INFO org.apache.hadoop.yarn.server.resourcemanager.scheduler.capacity.CapacityScheduler: Application appattempt_1375842659078_0006_000001 released container container_1375842659078_0006_01_000030 on node: host: hadoop-200-7:59851 #containers=5 available=1024 used=7168 with event: FINISHED
2013-08-07 02:42:40,720 INFO org.apache.hadoop.yarn.server.resourcemanager.rmcontainer.RMContainerImpl: container_1375842659078_0006_01_000046 Container Transitioned from NEW to ALLOCATED
2013-08-07 02:42:40,720 INFO org.apache.hadoop.yarn.server.resourcemanager.RMAuditLogger: USER=ubuntu	OPERATION=AM Allocated Container	TARGET=SchedulerApp	RESULT=SUCCESS	APPID=application_1375842659078_0006	CONTAINERID=container_1375842659078_0006_01_000046
2013-08-07 02:42:40,720 INFO org.apache.hadoop.yarn.server.resourcemanager.scheduler.common.fica.FiCaSchedulerNode: Assigned container container_1375842659078_0006_01_000046 of capacity <memory:1024, vCores:1> on host hadoop-200-7:59851, which currently has 6 containers, <memory:8192, vCores:6> used and <memory:0, vCores:10> available
2013-08-07 02:42:40,721 INFO org.apache.hadoop.yarn.server.resourcemanager.scheduler.capacity.LeafQueue: assignedContainer application=application_1375842659078_0006 container=Container: [ContainerId: container_1375842659078_0006_01_000046, NodeId: hadoop-200-7:59851, NodeHttpAddress: hadoop-200-7:8042, Resource: <memory:1024, vCores:1>, Priority: 10, State: NEW, Token: null, Status: container_id {, app_attempt_id {, application_id {, id: 6, cluster_timestamp: 1375842659078, }, attemptId: 1, }, id: 46, }, state: C_NEW, ] containerId=container_1375842659078_0006_01_000046 queue=default: capacity=1.0, absoluteCapacity=1.0, usedResources=<memory:48128, vCores:42>usedCapacity=0.9791667, absoluteUsedCapacity=0.9791667, numApps=5, numContainers=42 usedCapacity=0.9791667 absoluteUsedCapacity=0.9791667 used=<memory:48128, vCores:42> cluster=<memory:49152, vCores:96>
2013-08-07 02:42:40,721 INFO org.apache.hadoop.yarn.server.resourcemanager.scheduler.capacity.ParentQueue: Re-sorting queues since queue: root.default stats: default: capacity=1.0, absoluteCapacity=1.0, usedResources=<memory:49152, vCores:43>usedCapacity=1.0, absoluteUsedCapacity=1.0, numApps=5, numContainers=43
2013-08-07 02:42:40,722 INFO org.apache.hadoop.yarn.server.resourcemanager.scheduler.capacity.ParentQueue: assignedContainer queue=root usedCapacity=1.0 absoluteUsedCapacity=1.0 used=<memory:49152, vCores:43> cluster=<memory:49152, vCores:96>
2013-08-07 02:42:40,878 INFO org.apache.hadoop.yarn.server.resourcemanager.rmcontainer.RMContainerImpl: container_1375842659078_0006_01_000026 Container Transitioned from RUNNING to COMPLETED
2013-08-07 02:42:40,878 INFO org.apache.hadoop.yarn.server.resourcemanager.scheduler.common.fica.FiCaSchedulerApp: Completed container: container_1375842659078_0006_01_000026 in state: COMPLETED event:FINISHED
2013-08-07 02:42:40,878 INFO org.apache.hadoop.yarn.server.resourcemanager.RMAuditLogger: USER=ubuntu	OPERATION=AM Released Container	TARGET=SchedulerApp	RESULT=SUCCESS	APPID=application_1375842659078_0006	CONTAINERID=container_1375842659078_0006_01_000026
2013-08-07 02:42:40,878 INFO org.apache.hadoop.yarn.server.resourcemanager.scheduler.common.fica.FiCaSchedulerNode: Released container container_1375842659078_0006_01_000026 of capacity <memory:1024, vCores:1> on host hadoop-200-5:38287, which currently has 5 containers, <memory:7168, vCores:5> used and <memory:1024, vCores:11> available, release resources=true
2013-08-07 02:42:40,878 INFO org.apache.hadoop.yarn.server.resourcemanager.scheduler.capacity.LeafQueue: default used=<memory:48128, vCores:42> numContainers=42 user=ubuntu user-resources=<memory:48128, vCores:42>
2013-08-07 02:42:40,879 INFO org.apache.hadoop.yarn.server.resourcemanager.scheduler.capacity.LeafQueue: completedContainer container=Container: [ContainerId: container_1375842659078_0006_01_000026, NodeId: hadoop-200-5:38287, NodeHttpAddress: hadoop-200-5:8042, Resource: <memory:1024, vCores:1>, Priority: 20, State: NEW, Token: null, Status: container_id {, app_attempt_id {, application_id {, id: 6, cluster_timestamp: 1375842659078, }, attemptId: 1, }, id: 26, }, state: C_COMPLETE, diagnostics: "Container killed by the ApplicationMaster.\n\n", exit_status: 143, ] resource=<memory:1024, vCores:1> queue=default: capacity=1.0, absoluteCapacity=1.0, usedResources=<memory:48128, vCores:42>usedCapacity=0.9791667, absoluteUsedCapacity=0.9791667, numApps=5, numContainers=42 usedCapacity=0.9791667 absoluteUsedCapacity=0.9791667 used=<memory:48128, vCores:42> cluster=<memory:49152, vCores:96>
2013-08-07 02:42:40,879 INFO org.apache.hadoop.yarn.server.resourcemanager.scheduler.capacity.ParentQueue: completedContainer queue=root usedCapacity=0.9791667 absoluteUsedCapacity=0.9791667 used=<memory:48128, vCores:42> cluster=<memory:49152, vCores:96>
2013-08-07 02:42:40,880 INFO org.apache.hadoop.yarn.server.resourcemanager.scheduler.capacity.CapacityScheduler: Application appattempt_1375842659078_0006_000001 released container container_1375842659078_0006_01_000026 on node: host: hadoop-200-5:38287 #containers=5 available=1024 used=7168 with event: FINISHED
2013-08-07 02:42:40,880 INFO org.apache.hadoop.yarn.server.resourcemanager.rmcontainer.RMContainerImpl: container_1375842659078_0006_01_000047 Container Transitioned from NEW to ALLOCATED
2013-08-07 02:42:40,880 INFO org.apache.hadoop.yarn.server.resourcemanager.RMAuditLogger: USER=ubuntu	OPERATION=AM Allocated Container	TARGET=SchedulerApp	RESULT=SUCCESS	APPID=application_1375842659078_0006	CONTAINERID=container_1375842659078_0006_01_000047
2013-08-07 02:42:40,880 INFO org.apache.hadoop.yarn.server.resourcemanager.scheduler.common.fica.FiCaSchedulerNode: Assigned container container_1375842659078_0006_01_000047 of capacity <memory:1024, vCores:1> on host hadoop-200-5:38287, which currently has 6 containers, <memory:8192, vCores:6> used and <memory:0, vCores:10> available
2013-08-07 02:42:40,881 INFO org.apache.hadoop.yarn.server.resourcemanager.scheduler.capacity.LeafQueue: assignedContainer application=application_1375842659078_0006 container=Container: [ContainerId: container_1375842659078_0006_01_000047, NodeId: hadoop-200-5:38287, NodeHttpAddress: hadoop-200-5:8042, Resource: <memory:1024, vCores:1>, Priority: 20, State: NEW, Token: null, Status: container_id {, app_attempt_id {, application_id {, id: 6, cluster_timestamp: 1375842659078, }, attemptId: 1, }, id: 47, }, state: C_NEW, ] containerId=container_1375842659078_0006_01_000047 queue=default: capacity=1.0, absoluteCapacity=1.0, usedResources=<memory:48128, vCores:42>usedCapacity=0.9791667, absoluteUsedCapacity=0.9791667, numApps=5, numContainers=42 usedCapacity=0.9791667 absoluteUsedCapacity=0.9791667 used=<memory:48128, vCores:42> cluster=<memory:49152, vCores:96>
2013-08-07 02:42:40,881 INFO org.apache.hadoop.yarn.server.resourcemanager.scheduler.capacity.ParentQueue: Re-sorting queues since queue: root.default stats: default: capacity=1.0, absoluteCapacity=1.0, usedResources=<memory:49152, vCores:43>usedCapacity=1.0, absoluteUsedCapacity=1.0, numApps=5, numContainers=43
2013-08-07 02:42:40,882 INFO org.apache.hadoop.yarn.server.resourcemanager.scheduler.capacity.ParentQueue: assignedContainer queue=root usedCapacity=1.0 absoluteUsedCapacity=1.0 used=<memory:49152, vCores:43> cluster=<memory:49152, vCores:96>
2013-08-07 02:42:41,104 INFO org.apache.hadoop.yarn.server.resourcemanager.rmcontainer.RMContainerImpl: container_1375842659078_0006_01_000046 Container Transitioned from ALLOCATED to ACQUIRED
2013-08-07 02:42:41,105 INFO org.apache.hadoop.yarn.server.resourcemanager.rmcontainer.RMContainerImpl: container_1375842659078_0006_01_000047 Container Transitioned from ALLOCATED to ACQUIRED
2013-08-07 02:42:41,216 INFO org.apache.hadoop.yarn.server.resourcemanager.rmcontainer.RMContainerImpl: container_1375842659078_0006_01_000016 Container Transitioned from RUNNING to COMPLETED
2013-08-07 02:42:41,217 INFO org.apache.hadoop.yarn.server.resourcemanager.scheduler.common.fica.FiCaSchedulerApp: Completed container: container_1375842659078_0006_01_000016 in state: COMPLETED event:FINISHED
2013-08-07 02:42:41,217 INFO org.apache.hadoop.yarn.server.resourcemanager.RMAuditLogger: USER=ubuntu	OPERATION=AM Released Container	TARGET=SchedulerApp	RESULT=SUCCESS	APPID=application_1375842659078_0006	CONTAINERID=container_1375842659078_0006_01_000016
2013-08-07 02:42:41,217 INFO org.apache.hadoop.yarn.server.resourcemanager.scheduler.common.fica.FiCaSchedulerNode: Released container container_1375842659078_0006_01_000016 of capacity <memory:1024, vCores:1> on host hadoop-200-2:33271, which currently has 7 containers, <memory:7168, vCores:7> used and <memory:1024, vCores:9> available, release resources=true
2013-08-07 02:42:41,217 INFO org.apache.hadoop.yarn.server.resourcemanager.scheduler.capacity.LeafQueue: default used=<memory:48128, vCores:42> numContainers=42 user=ubuntu user-resources=<memory:48128, vCores:42>
2013-08-07 02:42:41,218 INFO org.apache.hadoop.yarn.server.resourcemanager.scheduler.capacity.LeafQueue: completedContainer container=Container: [ContainerId: container_1375842659078_0006_01_000016, NodeId: hadoop-200-2:33271, NodeHttpAddress: hadoop-200-2:8042, Resource: <memory:1024, vCores:1>, Priority: 20, State: NEW, Token: null, Status: container_id {, app_attempt_id {, application_id {, id: 6, cluster_timestamp: 1375842659078, }, attemptId: 1, }, id: 16, }, state: C_COMPLETE, diagnostics: "Container killed by the ApplicationMaster.\n\n", exit_status: 143, ] resource=<memory:1024, vCores:1> queue=default: capacity=1.0, absoluteCapacity=1.0, usedResources=<memory:48128, vCores:42>usedCapacity=0.9791667, absoluteUsedCapacity=0.9791667, numApps=5, numContainers=42 usedCapacity=0.9791667 absoluteUsedCapacity=0.9791667 used=<memory:48128, vCores:42> cluster=<memory:49152, vCores:96>
2013-08-07 02:42:41,219 INFO org.apache.hadoop.yarn.server.resourcemanager.scheduler.capacity.ParentQueue: completedContainer queue=root usedCapacity=0.9791667 absoluteUsedCapacity=0.9791667 used=<memory:48128, vCores:42> cluster=<memory:49152, vCores:96>
2013-08-07 02:42:41,219 INFO org.apache.hadoop.yarn.server.resourcemanager.scheduler.capacity.CapacityScheduler: Application appattempt_1375842659078_0006_000001 released container container_1375842659078_0006_01_000016 on node: host: hadoop-200-2:33271 #containers=7 available=1024 used=7168 with event: FINISHED
2013-08-07 02:42:41,219 INFO org.apache.hadoop.yarn.server.resourcemanager.rmcontainer.RMContainerImpl: container_1375842659078_0007_01_000003 Container Transitioned from NEW to ALLOCATED
2013-08-07 02:42:41,219 INFO org.apache.hadoop.yarn.server.resourcemanager.RMAuditLogger: USER=ubuntu	OPERATION=AM Allocated Container	TARGET=SchedulerApp	RESULT=SUCCESS	APPID=application_1375842659078_0007	CONTAINERID=container_1375842659078_0007_01_000003
2013-08-07 02:42:41,219 INFO org.apache.hadoop.yarn.server.resourcemanager.scheduler.common.fica.FiCaSchedulerNode: Assigned container container_1375842659078_0007_01_000003 of capacity <memory:1024, vCores:1> on host hadoop-200-2:33271, which currently has 8 containers, <memory:8192, vCores:8> used and <memory:0, vCores:8> available
2013-08-07 02:42:41,220 INFO org.apache.hadoop.yarn.server.resourcemanager.scheduler.capacity.LeafQueue: assignedContainer application=application_1375842659078_0007 container=Container: [ContainerId: container_1375842659078_0007_01_000003, NodeId: hadoop-200-2:33271, NodeHttpAddress: hadoop-200-2:8042, Resource: <memory:1024, vCores:1>, Priority: 20, State: NEW, Token: null, Status: container_id {, app_attempt_id {, application_id {, id: 7, cluster_timestamp: 1375842659078, }, attemptId: 1, }, id: 3, }, state: C_NEW, ] containerId=container_1375842659078_0007_01_000003 queue=default: capacity=1.0, absoluteCapacity=1.0, usedResources=<memory:48128, vCores:42>usedCapacity=0.9791667, absoluteUsedCapacity=0.9791667, numApps=5, numContainers=42 usedCapacity=0.9791667 absoluteUsedCapacity=0.9791667 used=<memory:48128, vCores:42> cluster=<memory:49152, vCores:96>
2013-08-07 02:42:41,221 INFO org.apache.hadoop.yarn.server.resourcemanager.scheduler.capacity.ParentQueue: Re-sorting queues since queue: root.default stats: default: capacity=1.0, absoluteCapacity=1.0, usedResources=<memory:49152, vCores:43>usedCapacity=1.0, absoluteUsedCapacity=1.0, numApps=5, numContainers=43
2013-08-07 02:42:41,221 INFO org.apache.hadoop.yarn.server.resourcemanager.scheduler.capacity.ParentQueue: assignedContainer queue=root usedCapacity=1.0 absoluteUsedCapacity=1.0 used=<memory:49152, vCores:43> cluster=<memory:49152, vCores:96>
2013-08-07 02:42:41,319 INFO org.apache.hadoop.yarn.server.resourcemanager.rmcontainer.RMContainerImpl: container_1375842659078_0007_01_000003 Container Transitioned from ALLOCATED to ACQUIRED
2013-08-07 02:42:41,537 INFO org.apache.hadoop.yarn.server.resourcemanager.rmcontainer.RMContainerImpl: container_1375842659078_0006_01_000046 Container Transitioned from ACQUIRED to RUNNING
2013-08-07 02:42:41,889 INFO org.apache.hadoop.yarn.server.resourcemanager.rmcontainer.RMContainerImpl: container_1375842659078_0006_01_000047 Container Transitioned from ACQUIRED to RUNNING
2013-08-07 02:42:42,112 INFO org.apache.hadoop.yarn.server.resourcemanager.scheduler.AppSchedulingInfo: checking for deactivate... 
2013-08-07 02:42:42,112 INFO org.apache.hadoop.yarn.server.resourcemanager.scheduler.AppSchedulingInfo: checking for deactivate... 
2013-08-07 02:42:42,223 INFO org.apache.hadoop.yarn.server.resourcemanager.rmcontainer.RMContainerImpl: container_1375842659078_0007_01_000003 Container Transitioned from ACQUIRED to RUNNING
2013-08-07 02:42:42,494 INFO org.apache.hadoop.yarn.server.resourcemanager.rmcontainer.RMContainerImpl: container_1375842659078_0006_01_000035 Container Transitioned from RUNNING to COMPLETED
2013-08-07 02:42:42,494 INFO org.apache.hadoop.yarn.server.resourcemanager.scheduler.common.fica.FiCaSchedulerApp: Completed container: container_1375842659078_0006_01_000035 in state: COMPLETED event:FINISHED
2013-08-07 02:42:42,494 INFO org.apache.hadoop.yarn.server.resourcemanager.RMAuditLogger: USER=ubuntu	OPERATION=AM Released Container	TARGET=SchedulerApp	RESULT=SUCCESS	APPID=application_1375842659078_0006	CONTAINERID=container_1375842659078_0006_01_000035
2013-08-07 02:42:42,494 INFO org.apache.hadoop.yarn.server.resourcemanager.scheduler.common.fica.FiCaSchedulerNode: Released container container_1375842659078_0006_01_000035 of capacity <memory:1024, vCores:1> on host hadoop-200-3:34020, which currently has 6 containers, <memory:7168, vCores:6> used and <memory:1024, vCores:10> available, release resources=true
2013-08-07 02:42:42,495 INFO org.apache.hadoop.yarn.server.resourcemanager.scheduler.capacity.LeafQueue: default used=<memory:48128, vCores:42> numContainers=42 user=ubuntu user-resources=<memory:48128, vCores:42>
2013-08-07 02:42:42,496 INFO org.apache.hadoop.yarn.server.resourcemanager.scheduler.capacity.LeafQueue: completedContainer container=Container: [ContainerId: container_1375842659078_0006_01_000035, NodeId: hadoop-200-3:34020, NodeHttpAddress: hadoop-200-3:8042, Resource: <memory:1024, vCores:1>, Priority: 20, State: NEW, Token: null, Status: container_id {, app_attempt_id {, application_id {, id: 6, cluster_timestamp: 1375842659078, }, attemptId: 1, }, id: 35, }, state: C_COMPLETE, diagnostics: "Container killed by the ApplicationMaster.\n\n", exit_status: 143, ] resource=<memory:1024, vCores:1> queue=default: capacity=1.0, absoluteCapacity=1.0, usedResources=<memory:48128, vCores:42>usedCapacity=0.9791667, absoluteUsedCapacity=0.9791667, numApps=5, numContainers=42 usedCapacity=0.9791667 absoluteUsedCapacity=0.9791667 used=<memory:48128, vCores:42> cluster=<memory:49152, vCores:96>
2013-08-07 02:42:42,496 INFO org.apache.hadoop.yarn.server.resourcemanager.scheduler.capacity.ParentQueue: completedContainer queue=root usedCapacity=0.9791667 absoluteUsedCapacity=0.9791667 used=<memory:48128, vCores:42> cluster=<memory:49152, vCores:96>
2013-08-07 02:42:42,496 INFO org.apache.hadoop.yarn.server.resourcemanager.scheduler.capacity.CapacityScheduler: Application appattempt_1375842659078_0006_000001 released container container_1375842659078_0006_01_000035 on node: host: hadoop-200-3:34020 #containers=6 available=1024 used=7168 with event: FINISHED
2013-08-07 02:42:42,497 INFO org.apache.hadoop.yarn.server.resourcemanager.rmcontainer.RMContainerImpl: container_1375842659078_0007_01_000004 Container Transitioned from NEW to ALLOCATED
2013-08-07 02:42:42,497 INFO org.apache.hadoop.yarn.server.resourcemanager.RMAuditLogger: USER=ubuntu	OPERATION=AM Allocated Container	TARGET=SchedulerApp	RESULT=SUCCESS	APPID=application_1375842659078_0007	CONTAINERID=container_1375842659078_0007_01_000004
2013-08-07 02:42:42,497 INFO org.apache.hadoop.yarn.server.resourcemanager.scheduler.common.fica.FiCaSchedulerNode: Assigned container container_1375842659078_0007_01_000004 of capacity <memory:1024, vCores:1> on host hadoop-200-3:34020, which currently has 7 containers, <memory:8192, vCores:7> used and <memory:0, vCores:9> available
2013-08-07 02:42:42,498 INFO org.apache.hadoop.yarn.server.resourcemanager.scheduler.capacity.LeafQueue: assignedContainer application=application_1375842659078_0007 container=Container: [ContainerId: container_1375842659078_0007_01_000004, NodeId: hadoop-200-3:34020, NodeHttpAddress: hadoop-200-3:8042, Resource: <memory:1024, vCores:1>, Priority: 20, State: NEW, Token: null, Status: container_id {, app_attempt_id {, application_id {, id: 7, cluster_timestamp: 1375842659078, }, attemptId: 1, }, id: 4, }, state: C_NEW, ] containerId=container_1375842659078_0007_01_000004 queue=default: capacity=1.0, absoluteCapacity=1.0, usedResources=<memory:48128, vCores:42>usedCapacity=0.9791667, absoluteUsedCapacity=0.9791667, numApps=5, numContainers=42 usedCapacity=0.9791667 absoluteUsedCapacity=0.9791667 used=<memory:48128, vCores:42> cluster=<memory:49152, vCores:96>
2013-08-07 02:42:42,498 INFO org.apache.hadoop.yarn.server.resourcemanager.scheduler.capacity.ParentQueue: Re-sorting queues since queue: root.default stats: default: capacity=1.0, absoluteCapacity=1.0, usedResources=<memory:49152, vCores:43>usedCapacity=1.0, absoluteUsedCapacity=1.0, numApps=5, numContainers=43
2013-08-07 02:42:42,498 INFO org.apache.hadoop.yarn.server.resourcemanager.scheduler.capacity.ParentQueue: assignedContainer queue=root usedCapacity=1.0 absoluteUsedCapacity=1.0 used=<memory:49152, vCores:43> cluster=<memory:49152, vCores:96>
2013-08-07 02:42:42,542 INFO org.apache.hadoop.yarn.server.resourcemanager.rmcontainer.RMContainerImpl: container_1375842659078_0006_01_000032 Container Transitioned from RUNNING to COMPLETED
2013-08-07 02:42:42,542 INFO org.apache.hadoop.yarn.server.resourcemanager.scheduler.common.fica.FiCaSchedulerApp: Completed container: container_1375842659078_0006_01_000032 in state: COMPLETED event:FINISHED
2013-08-07 02:42:42,542 INFO org.apache.hadoop.yarn.server.resourcemanager.RMAuditLogger: USER=ubuntu	OPERATION=AM Released Container	TARGET=SchedulerApp	RESULT=SUCCESS	APPID=application_1375842659078_0006	CONTAINERID=container_1375842659078_0006_01_000032
2013-08-07 02:42:42,542 INFO org.apache.hadoop.yarn.server.resourcemanager.scheduler.common.fica.FiCaSchedulerNode: Released container container_1375842659078_0006_01_000032 of capacity <memory:1024, vCores:1> on host hadoop-200-7:59851, which currently has 5 containers, <memory:7168, vCores:5> used and <memory:1024, vCores:11> available, release resources=true
2013-08-07 02:42:42,542 INFO org.apache.hadoop.yarn.server.resourcemanager.scheduler.capacity.LeafQueue: default used=<memory:48128, vCores:42> numContainers=42 user=ubuntu user-resources=<memory:48128, vCores:42>
2013-08-07 02:42:42,544 INFO org.apache.hadoop.yarn.server.resourcemanager.scheduler.capacity.LeafQueue: completedContainer container=Container: [ContainerId: container_1375842659078_0006_01_000032, NodeId: hadoop-200-7:59851, NodeHttpAddress: hadoop-200-7:8042, Resource: <memory:1024, vCores:1>, Priority: 20, State: NEW, Token: null, Status: container_id {, app_attempt_id {, application_id {, id: 6, cluster_timestamp: 1375842659078, }, attemptId: 1, }, id: 32, }, state: C_COMPLETE, diagnostics: "Container killed by the ApplicationMaster.\n\n", exit_status: 143, ] resource=<memory:1024, vCores:1> queue=default: capacity=1.0, absoluteCapacity=1.0, usedResources=<memory:48128, vCores:42>usedCapacity=0.9791667, absoluteUsedCapacity=0.9791667, numApps=5, numContainers=42 usedCapacity=0.9791667 absoluteUsedCapacity=0.9791667 used=<memory:48128, vCores:42> cluster=<memory:49152, vCores:96>
2013-08-07 02:42:42,544 INFO org.apache.hadoop.yarn.server.resourcemanager.scheduler.capacity.ParentQueue: completedContainer queue=root usedCapacity=0.9791667 absoluteUsedCapacity=0.9791667 used=<memory:48128, vCores:42> cluster=<memory:49152, vCores:96>
2013-08-07 02:42:42,544 INFO org.apache.hadoop.yarn.server.resourcemanager.scheduler.capacity.CapacityScheduler: Application appattempt_1375842659078_0006_000001 released container container_1375842659078_0006_01_000032 on node: host: hadoop-200-7:59851 #containers=5 available=1024 used=7168 with event: FINISHED
2013-08-07 02:42:42,545 INFO org.apache.hadoop.yarn.server.resourcemanager.rmcontainer.RMContainerImpl: container_1375842659078_0007_01_000005 Container Transitioned from NEW to ALLOCATED
2013-08-07 02:42:42,545 INFO org.apache.hadoop.yarn.server.resourcemanager.RMAuditLogger: USER=ubuntu	OPERATION=AM Allocated Container	TARGET=SchedulerApp	RESULT=SUCCESS	APPID=application_1375842659078_0007	CONTAINERID=container_1375842659078_0007_01_000005
2013-08-07 02:42:42,545 INFO org.apache.hadoop.yarn.server.resourcemanager.scheduler.common.fica.FiCaSchedulerNode: Assigned container container_1375842659078_0007_01_000005 of capacity <memory:1024, vCores:1> on host hadoop-200-7:59851, which currently has 6 containers, <memory:8192, vCores:6> used and <memory:0, vCores:10> available
2013-08-07 02:42:42,546 INFO org.apache.hadoop.yarn.server.resourcemanager.scheduler.capacity.LeafQueue: assignedContainer application=application_1375842659078_0007 container=Container: [ContainerId: container_1375842659078_0007_01_000005, NodeId: hadoop-200-7:59851, NodeHttpAddress: hadoop-200-7:8042, Resource: <memory:1024, vCores:1>, Priority: 20, State: NEW, Token: null, Status: container_id {, app_attempt_id {, application_id {, id: 7, cluster_timestamp: 1375842659078, }, attemptId: 1, }, id: 5, }, state: C_NEW, ] containerId=container_1375842659078_0007_01_000005 queue=default: capacity=1.0, absoluteCapacity=1.0, usedResources=<memory:48128, vCores:42>usedCapacity=0.9791667, absoluteUsedCapacity=0.9791667, numApps=5, numContainers=42 usedCapacity=0.9791667 absoluteUsedCapacity=0.9791667 used=<memory:48128, vCores:42> cluster=<memory:49152, vCores:96>
2013-08-07 02:42:42,546 INFO org.apache.hadoop.yarn.server.resourcemanager.scheduler.capacity.ParentQueue: Re-sorting queues since queue: root.default stats: default: capacity=1.0, absoluteCapacity=1.0, usedResources=<memory:49152, vCores:43>usedCapacity=1.0, absoluteUsedCapacity=1.0, numApps=5, numContainers=43
2013-08-07 02:42:42,546 INFO org.apache.hadoop.yarn.server.resourcemanager.scheduler.capacity.ParentQueue: assignedContainer queue=root usedCapacity=1.0 absoluteUsedCapacity=1.0 used=<memory:49152, vCores:43> cluster=<memory:49152, vCores:96>
2013-08-07 02:42:43,280 INFO org.apache.hadoop.yarn.server.resourcemanager.rmcontainer.RMContainerImpl: container_1375842659078_0006_01_000020 Container Transitioned from RUNNING to COMPLETED
2013-08-07 02:42:43,280 INFO org.apache.hadoop.yarn.server.resourcemanager.scheduler.common.fica.FiCaSchedulerApp: Completed container: container_1375842659078_0006_01_000020 in state: COMPLETED event:FINISHED
2013-08-07 02:42:43,280 INFO org.apache.hadoop.yarn.server.resourcemanager.RMAuditLogger: USER=ubuntu	OPERATION=AM Released Container	TARGET=SchedulerApp	RESULT=SUCCESS	APPID=application_1375842659078_0006	CONTAINERID=container_1375842659078_0006_01_000020
2013-08-07 02:42:43,280 INFO org.apache.hadoop.yarn.server.resourcemanager.scheduler.common.fica.FiCaSchedulerNode: Released container container_1375842659078_0006_01_000020 of capacity <memory:1024, vCores:1> on host hadoop-200-4:56924, which currently has 7 containers, <memory:7168, vCores:7> used and <memory:1024, vCores:9> available, release resources=true
2013-08-07 02:42:43,280 INFO org.apache.hadoop.yarn.server.resourcemanager.scheduler.capacity.LeafQueue: default used=<memory:48128, vCores:42> numContainers=42 user=ubuntu user-resources=<memory:48128, vCores:42>
2013-08-07 02:42:43,282 INFO org.apache.hadoop.yarn.server.resourcemanager.scheduler.capacity.LeafQueue: completedContainer container=Container: [ContainerId: container_1375842659078_0006_01_000020, NodeId: hadoop-200-4:56924, NodeHttpAddress: hadoop-200-4:8042, Resource: <memory:1024, vCores:1>, Priority: 20, State: NEW, Token: null, Status: container_id {, app_attempt_id {, application_id {, id: 6, cluster_timestamp: 1375842659078, }, attemptId: 1, }, id: 20, }, state: C_COMPLETE, diagnostics: "Container killed by the ApplicationMaster.\n\n", exit_status: 143, ] resource=<memory:1024, vCores:1> queue=default: capacity=1.0, absoluteCapacity=1.0, usedResources=<memory:48128, vCores:42>usedCapacity=0.9791667, absoluteUsedCapacity=0.9791667, numApps=5, numContainers=42 usedCapacity=0.9791667 absoluteUsedCapacity=0.9791667 used=<memory:48128, vCores:42> cluster=<memory:49152, vCores:96>
2013-08-07 02:42:43,282 INFO org.apache.hadoop.yarn.server.resourcemanager.scheduler.capacity.ParentQueue: completedContainer queue=root usedCapacity=0.9791667 absoluteUsedCapacity=0.9791667 used=<memory:48128, vCores:42> cluster=<memory:49152, vCores:96>
2013-08-07 02:42:43,282 INFO org.apache.hadoop.yarn.server.resourcemanager.scheduler.capacity.CapacityScheduler: Application appattempt_1375842659078_0006_000001 released container container_1375842659078_0006_01_000020 on node: host: hadoop-200-4:56924 #containers=7 available=1024 used=7168 with event: FINISHED
2013-08-07 02:42:43,283 INFO org.apache.hadoop.yarn.server.resourcemanager.rmcontainer.RMContainerImpl: container_1375842659078_0007_01_000006 Container Transitioned from NEW to ALLOCATED
2013-08-07 02:42:43,283 INFO org.apache.hadoop.yarn.server.resourcemanager.RMAuditLogger: USER=ubuntu	OPERATION=AM Allocated Container	TARGET=SchedulerApp	RESULT=SUCCESS	APPID=application_1375842659078_0007	CONTAINERID=container_1375842659078_0007_01_000006
2013-08-07 02:42:43,283 INFO org.apache.hadoop.yarn.server.resourcemanager.scheduler.common.fica.FiCaSchedulerNode: Assigned container container_1375842659078_0007_01_000006 of capacity <memory:1024, vCores:1> on host hadoop-200-4:56924, which currently has 8 containers, <memory:8192, vCores:8> used and <memory:0, vCores:8> available
2013-08-07 02:42:43,284 INFO org.apache.hadoop.yarn.server.resourcemanager.scheduler.capacity.LeafQueue: assignedContainer application=application_1375842659078_0007 container=Container: [ContainerId: container_1375842659078_0007_01_000006, NodeId: hadoop-200-4:56924, NodeHttpAddress: hadoop-200-4:8042, Resource: <memory:1024, vCores:1>, Priority: 20, State: NEW, Token: null, Status: container_id {, app_attempt_id {, application_id {, id: 7, cluster_timestamp: 1375842659078, }, attemptId: 1, }, id: 6, }, state: C_NEW, ] containerId=container_1375842659078_0007_01_000006 queue=default: capacity=1.0, absoluteCapacity=1.0, usedResources=<memory:48128, vCores:42>usedCapacity=0.9791667, absoluteUsedCapacity=0.9791667, numApps=5, numContainers=42 usedCapacity=0.9791667 absoluteUsedCapacity=0.9791667 used=<memory:48128, vCores:42> cluster=<memory:49152, vCores:96>
2013-08-07 02:42:43,284 INFO org.apache.hadoop.yarn.server.resourcemanager.scheduler.capacity.ParentQueue: Re-sorting queues since queue: root.default stats: default: capacity=1.0, absoluteCapacity=1.0, usedResources=<memory:49152, vCores:43>usedCapacity=1.0, absoluteUsedCapacity=1.0, numApps=5, numContainers=43
2013-08-07 02:42:43,284 INFO org.apache.hadoop.yarn.server.resourcemanager.scheduler.capacity.ParentQueue: assignedContainer queue=root usedCapacity=1.0 absoluteUsedCapacity=1.0 used=<memory:49152, vCores:43> cluster=<memory:49152, vCores:96>
2013-08-07 02:42:43,349 INFO org.apache.hadoop.yarn.server.resourcemanager.rmcontainer.RMContainerImpl: container_1375842659078_0007_01_000004 Container Transitioned from ALLOCATED to ACQUIRED
2013-08-07 02:42:43,351 INFO org.apache.hadoop.yarn.server.resourcemanager.rmcontainer.RMContainerImpl: container_1375842659078_0007_01_000005 Container Transitioned from ALLOCATED to ACQUIRED
2013-08-07 02:42:43,351 INFO org.apache.hadoop.yarn.server.resourcemanager.rmcontainer.RMContainerImpl: container_1375842659078_0007_01_000006 Container Transitioned from ALLOCATED to ACQUIRED
2013-08-07 02:42:43,540 INFO org.apache.hadoop.yarn.server.resourcemanager.rmcontainer.RMContainerImpl: container_1375842659078_0007_01_000004 Container Transitioned from ACQUIRED to RUNNING
2013-08-07 02:42:43,550 INFO org.apache.hadoop.yarn.server.resourcemanager.rmcontainer.RMContainerImpl: container_1375842659078_0007_01_000005 Container Transitioned from ACQUIRED to RUNNING
2013-08-07 02:42:44,518 INFO org.apache.hadoop.yarn.server.resourcemanager.rmcontainer.RMContainerImpl: container_1375842659078_0007_01_000006 Container Transitioned from ACQUIRED to RUNNING
2013-08-07 02:42:46,477 INFO org.apache.hadoop.yarn.server.resourcemanager.rmcontainer.RMContainerImpl: container_1375842659078_0006_01_000018 Container Transitioned from RUNNING to COMPLETED
2013-08-07 02:42:46,478 INFO org.apache.hadoop.yarn.server.resourcemanager.scheduler.common.fica.FiCaSchedulerApp: Completed container: container_1375842659078_0006_01_000018 in state: COMPLETED event:FINISHED
2013-08-07 02:42:46,478 INFO org.apache.hadoop.yarn.server.resourcemanager.RMAuditLogger: USER=ubuntu	OPERATION=AM Released Container	TARGET=SchedulerApp	RESULT=SUCCESS	APPID=application_1375842659078_0006	CONTAINERID=container_1375842659078_0006_01_000018
2013-08-07 02:42:46,478 INFO org.apache.hadoop.yarn.server.resourcemanager.scheduler.common.fica.FiCaSchedulerNode: Released container container_1375842659078_0006_01_000018 of capacity <memory:1024, vCores:1> on host hadoop-200-4:56924, which currently has 7 containers, <memory:7168, vCores:7> used and <memory:1024, vCores:9> available, release resources=true
2013-08-07 02:42:46,478 INFO org.apache.hadoop.yarn.server.resourcemanager.scheduler.capacity.LeafQueue: default used=<memory:48128, vCores:42> numContainers=42 user=ubuntu user-resources=<memory:48128, vCores:42>
2013-08-07 02:42:46,479 INFO org.apache.hadoop.yarn.server.resourcemanager.scheduler.capacity.LeafQueue: completedContainer container=Container: [ContainerId: container_1375842659078_0006_01_000018, NodeId: hadoop-200-4:56924, NodeHttpAddress: hadoop-200-4:8042, Resource: <memory:1024, vCores:1>, Priority: 20, State: NEW, Token: null, Status: container_id {, app_attempt_id {, application_id {, id: 6, cluster_timestamp: 1375842659078, }, attemptId: 1, }, id: 18, }, state: C_COMPLETE, diagnostics: "Container killed by the ApplicationMaster.\n", exit_status: 0, ] resource=<memory:1024, vCores:1> queue=default: capacity=1.0, absoluteCapacity=1.0, usedResources=<memory:48128, vCores:42>usedCapacity=0.9791667, absoluteUsedCapacity=0.9791667, numApps=5, numContainers=42 usedCapacity=0.9791667 absoluteUsedCapacity=0.9791667 used=<memory:48128, vCores:42> cluster=<memory:49152, vCores:96>
2013-08-07 02:42:46,479 INFO org.apache.hadoop.yarn.server.resourcemanager.scheduler.capacity.ParentQueue: completedContainer queue=root usedCapacity=0.9791667 absoluteUsedCapacity=0.9791667 used=<memory:48128, vCores:42> cluster=<memory:49152, vCores:96>
2013-08-07 02:42:46,479 INFO org.apache.hadoop.yarn.server.resourcemanager.scheduler.capacity.CapacityScheduler: Application appattempt_1375842659078_0006_000001 released container container_1375842659078_0006_01_000018 on node: host: hadoop-200-4:56924 #containers=7 available=1024 used=7168 with event: FINISHED
2013-08-07 02:42:46,480 INFO org.apache.hadoop.yarn.server.resourcemanager.rmcontainer.RMContainerImpl: container_1375842659078_0006_01_000019 Container Transitioned from RUNNING to COMPLETED
2013-08-07 02:42:46,480 INFO org.apache.hadoop.yarn.server.resourcemanager.scheduler.common.fica.FiCaSchedulerApp: Completed container: container_1375842659078_0006_01_000019 in state: COMPLETED event:FINISHED
2013-08-07 02:42:46,480 INFO org.apache.hadoop.yarn.server.resourcemanager.RMAuditLogger: USER=ubuntu	OPERATION=AM Released Container	TARGET=SchedulerApp	RESULT=SUCCESS	APPID=application_1375842659078_0006	CONTAINERID=container_1375842659078_0006_01_000019
2013-08-07 02:42:46,480 INFO org.apache.hadoop.yarn.server.resourcemanager.scheduler.common.fica.FiCaSchedulerNode: Released container container_1375842659078_0006_01_000019 of capacity <memory:1024, vCores:1> on host hadoop-200-4:56924, which currently has 6 containers, <memory:6144, vCores:6> used and <memory:2048, vCores:10> available, release resources=true
2013-08-07 02:42:46,480 INFO org.apache.hadoop.yarn.server.resourcemanager.scheduler.capacity.LeafQueue: default used=<memory:47104, vCores:41> numContainers=41 user=ubuntu user-resources=<memory:47104, vCores:41>
2013-08-07 02:42:46,481 INFO org.apache.hadoop.yarn.server.resourcemanager.scheduler.capacity.LeafQueue: completedContainer container=Container: [ContainerId: container_1375842659078_0006_01_000019, NodeId: hadoop-200-4:56924, NodeHttpAddress: hadoop-200-4:8042, Resource: <memory:1024, vCores:1>, Priority: 20, State: NEW, Token: null, Status: container_id {, app_attempt_id {, application_id {, id: 6, cluster_timestamp: 1375842659078, }, attemptId: 1, }, id: 19, }, state: C_COMPLETE, diagnostics: "Container killed by the ApplicationMaster.\n\n", exit_status: 143, ] resource=<memory:1024, vCores:1> queue=default: capacity=1.0, absoluteCapacity=1.0, usedResources=<memory:47104, vCores:41>usedCapacity=0.9583333, absoluteUsedCapacity=0.9583333, numApps=5, numContainers=41 usedCapacity=0.9583333 absoluteUsedCapacity=0.9583333 used=<memory:47104, vCores:41> cluster=<memory:49152, vCores:96>
2013-08-07 02:42:46,481 INFO org.apache.hadoop.yarn.server.resourcemanager.scheduler.capacity.ParentQueue: completedContainer queue=root usedCapacity=0.9583333 absoluteUsedCapacity=0.9583333 used=<memory:47104, vCores:41> cluster=<memory:49152, vCores:96>
2013-08-07 02:42:46,482 INFO org.apache.hadoop.yarn.server.resourcemanager.scheduler.capacity.CapacityScheduler: Application appattempt_1375842659078_0006_000001 released container container_1375842659078_0006_01_000019 on node: host: hadoop-200-4:56924 #containers=6 available=2048 used=6144 with event: FINISHED
2013-08-07 02:42:46,482 INFO org.apache.hadoop.yarn.server.resourcemanager.rmcontainer.RMContainerImpl: container_1375842659078_0006_01_000021 Container Transitioned from RUNNING to COMPLETED
2013-08-07 02:42:46,482 INFO org.apache.hadoop.yarn.server.resourcemanager.scheduler.common.fica.FiCaSchedulerApp: Completed container: container_1375842659078_0006_01_000021 in state: COMPLETED event:FINISHED
2013-08-07 02:42:46,482 INFO org.apache.hadoop.yarn.server.resourcemanager.RMAuditLogger: USER=ubuntu	OPERATION=AM Released Container	TARGET=SchedulerApp	RESULT=SUCCESS	APPID=application_1375842659078_0006	CONTAINERID=container_1375842659078_0006_01_000021
2013-08-07 02:42:46,482 INFO org.apache.hadoop.yarn.server.resourcemanager.scheduler.common.fica.FiCaSchedulerNode: Released container container_1375842659078_0006_01_000021 of capacity <memory:1024, vCores:1> on host hadoop-200-4:56924, which currently has 5 containers, <memory:5120, vCores:5> used and <memory:3072, vCores:11> available, release resources=true
2013-08-07 02:42:46,482 INFO org.apache.hadoop.yarn.server.resourcemanager.scheduler.capacity.LeafQueue: default used=<memory:46080, vCores:40> numContainers=40 user=ubuntu user-resources=<memory:46080, vCores:40>
2013-08-07 02:42:46,483 INFO org.apache.hadoop.yarn.server.resourcemanager.scheduler.capacity.LeafQueue: completedContainer container=Container: [ContainerId: container_1375842659078_0006_01_000021, NodeId: hadoop-200-4:56924, NodeHttpAddress: hadoop-200-4:8042, Resource: <memory:1024, vCores:1>, Priority: 20, State: NEW, Token: null, Status: container_id {, app_attempt_id {, application_id {, id: 6, cluster_timestamp: 1375842659078, }, attemptId: 1, }, id: 21, }, state: C_COMPLETE, diagnostics: "Container killed by the ApplicationMaster.\n", exit_status: 0, ] resource=<memory:1024, vCores:1> queue=default: capacity=1.0, absoluteCapacity=1.0, usedResources=<memory:46080, vCores:40>usedCapacity=0.9375, absoluteUsedCapacity=0.9375, numApps=5, numContainers=40 usedCapacity=0.9375 absoluteUsedCapacity=0.9375 used=<memory:46080, vCores:40> cluster=<memory:49152, vCores:96>
2013-08-07 02:42:46,484 INFO org.apache.hadoop.yarn.server.resourcemanager.scheduler.capacity.ParentQueue: completedContainer queue=root usedCapacity=0.9375 absoluteUsedCapacity=0.9375 used=<memory:46080, vCores:40> cluster=<memory:49152, vCores:96>
2013-08-07 02:42:46,484 INFO org.apache.hadoop.yarn.server.resourcemanager.scheduler.capacity.CapacityScheduler: Application appattempt_1375842659078_0006_000001 released container container_1375842659078_0006_01_000021 on node: host: hadoop-200-4:56924 #containers=5 available=3072 used=5120 with event: FINISHED
2013-08-07 02:42:46,484 INFO org.apache.hadoop.yarn.server.resourcemanager.rmcontainer.RMContainerImpl: container_1375842659078_0006_01_000025 Container Transitioned from RUNNING to COMPLETED
2013-08-07 02:42:46,484 INFO org.apache.hadoop.yarn.server.resourcemanager.scheduler.common.fica.FiCaSchedulerApp: Completed container: container_1375842659078_0006_01_000025 in state: COMPLETED event:FINISHED
2013-08-07 02:42:46,484 INFO org.apache.hadoop.yarn.server.resourcemanager.RMAuditLogger: USER=ubuntu	OPERATION=AM Released Container	TARGET=SchedulerApp	RESULT=SUCCESS	APPID=application_1375842659078_0006	CONTAINERID=container_1375842659078_0006_01_000025
2013-08-07 02:42:46,484 INFO org.apache.hadoop.yarn.server.resourcemanager.scheduler.common.fica.FiCaSchedulerNode: Released container container_1375842659078_0006_01_000025 of capacity <memory:1024, vCores:1> on host hadoop-200-4:56924, which currently has 4 containers, <memory:4096, vCores:4> used and <memory:4096, vCores:12> available, release resources=true
2013-08-07 02:42:46,484 INFO org.apache.hadoop.yarn.server.resourcemanager.scheduler.capacity.LeafQueue: default used=<memory:45056, vCores:39> numContainers=39 user=ubuntu user-resources=<memory:45056, vCores:39>
2013-08-07 02:42:46,485 INFO org.apache.hadoop.yarn.server.resourcemanager.scheduler.capacity.LeafQueue: completedContainer container=Container: [ContainerId: container_1375842659078_0006_01_000025, NodeId: hadoop-200-4:56924, NodeHttpAddress: hadoop-200-4:8042, Resource: <memory:1024, vCores:1>, Priority: 20, State: NEW, Token: null, Status: container_id {, app_attempt_id {, application_id {, id: 6, cluster_timestamp: 1375842659078, }, attemptId: 1, }, id: 25, }, state: C_COMPLETE, diagnostics: "Container killed by the ApplicationMaster.\n", exit_status: 0, ] resource=<memory:1024, vCores:1> queue=default: capacity=1.0, absoluteCapacity=1.0, usedResources=<memory:45056, vCores:39>usedCapacity=0.9166667, absoluteUsedCapacity=0.9166667, numApps=5, numContainers=39 usedCapacity=0.9166667 absoluteUsedCapacity=0.9166667 used=<memory:45056, vCores:39> cluster=<memory:49152, vCores:96>
2013-08-07 02:42:46,486 INFO org.apache.hadoop.yarn.server.resourcemanager.scheduler.capacity.ParentQueue: completedContainer queue=root usedCapacity=0.9166667 absoluteUsedCapacity=0.9166667 used=<memory:45056, vCores:39> cluster=<memory:49152, vCores:96>
2013-08-07 02:42:46,486 INFO org.apache.hadoop.yarn.server.resourcemanager.scheduler.capacity.CapacityScheduler: Application appattempt_1375842659078_0006_000001 released container container_1375842659078_0006_01_000025 on node: host: hadoop-200-4:56924 #containers=4 available=4096 used=4096 with event: FINISHED
2013-08-07 02:42:46,486 INFO org.apache.hadoop.yarn.server.resourcemanager.rmcontainer.RMContainerImpl: container_1375842659078_0007_01_000007 Container Transitioned from NEW to ALLOCATED
2013-08-07 02:42:46,486 INFO org.apache.hadoop.yarn.server.resourcemanager.RMAuditLogger: USER=ubuntu	OPERATION=AM Allocated Container	TARGET=SchedulerApp	RESULT=SUCCESS	APPID=application_1375842659078_0007	CONTAINERID=container_1375842659078_0007_01_000007
2013-08-07 02:42:46,486 INFO org.apache.hadoop.yarn.server.resourcemanager.scheduler.common.fica.FiCaSchedulerNode: Assigned container container_1375842659078_0007_01_000007 of capacity <memory:1024, vCores:1> on host hadoop-200-4:56924, which currently has 5 containers, <memory:5120, vCores:5> used and <memory:3072, vCores:11> available
2013-08-07 02:42:46,487 INFO org.apache.hadoop.yarn.server.resourcemanager.scheduler.capacity.LeafQueue: assignedContainer application=application_1375842659078_0007 container=Container: [ContainerId: container_1375842659078_0007_01_000007, NodeId: hadoop-200-4:56924, NodeHttpAddress: hadoop-200-4:8042, Resource: <memory:1024, vCores:1>, Priority: 20, State: NEW, Token: null, Status: container_id {, app_attempt_id {, application_id {, id: 7, cluster_timestamp: 1375842659078, }, attemptId: 1, }, id: 7, }, state: C_NEW, ] containerId=container_1375842659078_0007_01_000007 queue=default: capacity=1.0, absoluteCapacity=1.0, usedResources=<memory:45056, vCores:39>usedCapacity=0.9166667, absoluteUsedCapacity=0.9166667, numApps=5, numContainers=39 usedCapacity=0.9166667 absoluteUsedCapacity=0.9166667 used=<memory:45056, vCores:39> cluster=<memory:49152, vCores:96>
2013-08-07 02:42:46,488 INFO org.apache.hadoop.yarn.server.resourcemanager.scheduler.capacity.ParentQueue: Re-sorting queues since queue: root.default stats: default: capacity=1.0, absoluteCapacity=1.0, usedResources=<memory:46080, vCores:40>usedCapacity=0.9375, absoluteUsedCapacity=0.9375, numApps=5, numContainers=40
2013-08-07 02:42:46,488 INFO org.apache.hadoop.yarn.server.resourcemanager.scheduler.capacity.ParentQueue: assignedContainer queue=root usedCapacity=0.9375 absoluteUsedCapacity=0.9375 used=<memory:46080, vCores:40> cluster=<memory:49152, vCores:96>
2013-08-07 02:42:46,488 INFO org.apache.hadoop.yarn.server.resourcemanager.rmcontainer.RMContainerImpl: container_1375842659078_0007_01_000008 Container Transitioned from NEW to ALLOCATED
2013-08-07 02:42:46,488 INFO org.apache.hadoop.yarn.server.resourcemanager.RMAuditLogger: USER=ubuntu	OPERATION=AM Allocated Container	TARGET=SchedulerApp	RESULT=SUCCESS	APPID=application_1375842659078_0007	CONTAINERID=container_1375842659078_0007_01_000008
2013-08-07 02:42:46,488 INFO org.apache.hadoop.yarn.server.resourcemanager.scheduler.common.fica.FiCaSchedulerNode: Assigned container container_1375842659078_0007_01_000008 of capacity <memory:1024, vCores:1> on host hadoop-200-4:56924, which currently has 6 containers, <memory:6144, vCores:6> used and <memory:2048, vCores:10> available
2013-08-07 02:42:46,489 INFO org.apache.hadoop.yarn.server.resourcemanager.scheduler.capacity.LeafQueue: assignedContainer application=application_1375842659078_0007 container=Container: [ContainerId: container_1375842659078_0007_01_000008, NodeId: hadoop-200-4:56924, NodeHttpAddress: hadoop-200-4:8042, Resource: <memory:1024, vCores:1>, Priority: 20, State: NEW, Token: null, Status: container_id {, app_attempt_id {, application_id {, id: 7, cluster_timestamp: 1375842659078, }, attemptId: 1, }, id: 8, }, state: C_NEW, ] containerId=container_1375842659078_0007_01_000008 queue=default: capacity=1.0, absoluteCapacity=1.0, usedResources=<memory:46080, vCores:40>usedCapacity=0.9375, absoluteUsedCapacity=0.9375, numApps=5, numContainers=40 usedCapacity=0.9375 absoluteUsedCapacity=0.9375 used=<memory:46080, vCores:40> cluster=<memory:49152, vCores:96>
2013-08-07 02:42:46,490 INFO org.apache.hadoop.yarn.server.resourcemanager.scheduler.capacity.ParentQueue: Re-sorting queues since queue: root.default stats: default: capacity=1.0, absoluteCapacity=1.0, usedResources=<memory:47104, vCores:41>usedCapacity=0.9583333, absoluteUsedCapacity=0.9583333, numApps=5, numContainers=41
2013-08-07 02:42:46,490 INFO org.apache.hadoop.yarn.server.resourcemanager.scheduler.capacity.ParentQueue: assignedContainer queue=root usedCapacity=0.9583333 absoluteUsedCapacity=0.9583333 used=<memory:47104, vCores:41> cluster=<memory:49152, vCores:96>
2013-08-07 02:42:46,490 INFO org.apache.hadoop.yarn.server.resourcemanager.rmcontainer.RMContainerImpl: container_1375842659078_0007_01_000009 Container Transitioned from NEW to ALLOCATED
2013-08-07 02:42:46,490 INFO org.apache.hadoop.yarn.server.resourcemanager.RMAuditLogger: USER=ubuntu	OPERATION=AM Allocated Container	TARGET=SchedulerApp	RESULT=SUCCESS	APPID=application_1375842659078_0007	CONTAINERID=container_1375842659078_0007_01_000009
2013-08-07 02:42:46,490 INFO org.apache.hadoop.yarn.server.resourcemanager.scheduler.common.fica.FiCaSchedulerNode: Assigned container container_1375842659078_0007_01_000009 of capacity <memory:1024, vCores:1> on host hadoop-200-4:56924, which currently has 7 containers, <memory:7168, vCores:7> used and <memory:1024, vCores:9> available
2013-08-07 02:42:46,491 INFO org.apache.hadoop.yarn.server.resourcemanager.scheduler.capacity.LeafQueue: assignedContainer application=application_1375842659078_0007 container=Container: [ContainerId: container_1375842659078_0007_01_000009, NodeId: hadoop-200-4:56924, NodeHttpAddress: hadoop-200-4:8042, Resource: <memory:1024, vCores:1>, Priority: 20, State: NEW, Token: null, Status: container_id {, app_attempt_id {, application_id {, id: 7, cluster_timestamp: 1375842659078, }, attemptId: 1, }, id: 9, }, state: C_NEW, ] containerId=container_1375842659078_0007_01_000009 queue=default: capacity=1.0, absoluteCapacity=1.0, usedResources=<memory:47104, vCores:41>usedCapacity=0.9583333, absoluteUsedCapacity=0.9583333, numApps=5, numContainers=41 usedCapacity=0.9583333 absoluteUsedCapacity=0.9583333 used=<memory:47104, vCores:41> cluster=<memory:49152, vCores:96>
2013-08-07 02:42:46,492 INFO org.apache.hadoop.yarn.server.resourcemanager.scheduler.capacity.ParentQueue: Re-sorting queues since queue: root.default stats: default: capacity=1.0, absoluteCapacity=1.0, usedResources=<memory:48128, vCores:42>usedCapacity=0.9791667, absoluteUsedCapacity=0.9791667, numApps=5, numContainers=42
2013-08-07 02:42:46,492 INFO org.apache.hadoop.yarn.server.resourcemanager.scheduler.capacity.ParentQueue: assignedContainer queue=root usedCapacity=0.9791667 absoluteUsedCapacity=0.9791667 used=<memory:48128, vCores:42> cluster=<memory:49152, vCores:96>
2013-08-07 02:42:46,492 INFO org.apache.hadoop.yarn.server.resourcemanager.rmcontainer.RMContainerImpl: container_1375842659078_0007_01_000010 Container Transitioned from NEW to ALLOCATED
2013-08-07 02:42:46,492 INFO org.apache.hadoop.yarn.server.resourcemanager.RMAuditLogger: USER=ubuntu	OPERATION=AM Allocated Container	TARGET=SchedulerApp	RESULT=SUCCESS	APPID=application_1375842659078_0007	CONTAINERID=container_1375842659078_0007_01_000010
2013-08-07 02:42:46,492 INFO org.apache.hadoop.yarn.server.resourcemanager.scheduler.common.fica.FiCaSchedulerNode: Assigned container container_1375842659078_0007_01_000010 of capacity <memory:1024, vCores:1> on host hadoop-200-4:56924, which currently has 8 containers, <memory:8192, vCores:8> used and <memory:0, vCores:8> available
2013-08-07 02:42:46,493 INFO org.apache.hadoop.yarn.server.resourcemanager.scheduler.capacity.LeafQueue: assignedContainer application=application_1375842659078_0007 container=Container: [ContainerId: container_1375842659078_0007_01_000010, NodeId: hadoop-200-4:56924, NodeHttpAddress: hadoop-200-4:8042, Resource: <memory:1024, vCores:1>, Priority: 20, State: NEW, Token: null, Status: container_id {, app_attempt_id {, application_id {, id: 7, cluster_timestamp: 1375842659078, }, attemptId: 1, }, id: 10, }, state: C_NEW, ] containerId=container_1375842659078_0007_01_000010 queue=default: capacity=1.0, absoluteCapacity=1.0, usedResources=<memory:48128, vCores:42>usedCapacity=0.9791667, absoluteUsedCapacity=0.9791667, numApps=5, numContainers=42 usedCapacity=0.9791667 absoluteUsedCapacity=0.9791667 used=<memory:48128, vCores:42> cluster=<memory:49152, vCores:96>
2013-08-07 02:42:46,493 INFO org.apache.hadoop.yarn.server.resourcemanager.scheduler.capacity.ParentQueue: Re-sorting queues since queue: root.default stats: default: capacity=1.0, absoluteCapacity=1.0, usedResources=<memory:49152, vCores:43>usedCapacity=1.0, absoluteUsedCapacity=1.0, numApps=5, numContainers=43
2013-08-07 02:42:46,494 INFO org.apache.hadoop.yarn.server.resourcemanager.scheduler.capacity.ParentQueue: assignedContainer queue=root usedCapacity=1.0 absoluteUsedCapacity=1.0 used=<memory:49152, vCores:43> cluster=<memory:49152, vCores:96>
2013-08-07 02:42:46,721 INFO org.apache.hadoop.yarn.server.resourcemanager.rmcontainer.RMContainerImpl: container_1375842659078_0006_01_000039 Container Transitioned from RUNNING to COMPLETED
2013-08-07 02:42:46,721 INFO org.apache.hadoop.yarn.server.resourcemanager.scheduler.common.fica.FiCaSchedulerApp: Completed container: container_1375842659078_0006_01_000039 in state: COMPLETED event:FINISHED
2013-08-07 02:42:46,721 INFO org.apache.hadoop.yarn.server.resourcemanager.RMAuditLogger: USER=ubuntu	OPERATION=AM Released Container	TARGET=SchedulerApp	RESULT=SUCCESS	APPID=application_1375842659078_0006	CONTAINERID=container_1375842659078_0006_01_000039
2013-08-07 02:42:46,721 INFO org.apache.hadoop.yarn.server.resourcemanager.scheduler.common.fica.FiCaSchedulerNode: Released container container_1375842659078_0006_01_000039 of capacity <memory:1024, vCores:1> on host hadoop-200-3:34020, which currently has 6 containers, <memory:7168, vCores:6> used and <memory:1024, vCores:10> available, release resources=true
2013-08-07 02:42:46,721 INFO org.apache.hadoop.yarn.server.resourcemanager.scheduler.capacity.LeafQueue: default used=<memory:48128, vCores:42> numContainers=42 user=ubuntu user-resources=<memory:48128, vCores:42>
2013-08-07 02:42:46,722 INFO org.apache.hadoop.yarn.server.resourcemanager.scheduler.capacity.LeafQueue: completedContainer container=Container: [ContainerId: container_1375842659078_0006_01_000039, NodeId: hadoop-200-3:34020, NodeHttpAddress: hadoop-200-3:8042, Resource: <memory:1024, vCores:1>, Priority: 20, State: NEW, Token: null, Status: container_id {, app_attempt_id {, application_id {, id: 6, cluster_timestamp: 1375842659078, }, attemptId: 1, }, id: 39, }, state: C_COMPLETE, diagnostics: "Container killed by the ApplicationMaster.\n\n", exit_status: 143, ] resource=<memory:1024, vCores:1> queue=default: capacity=1.0, absoluteCapacity=1.0, usedResources=<memory:48128, vCores:42>usedCapacity=0.9791667, absoluteUsedCapacity=0.9791667, numApps=5, numContainers=42 usedCapacity=0.9791667 absoluteUsedCapacity=0.9791667 used=<memory:48128, vCores:42> cluster=<memory:49152, vCores:96>
2013-08-07 02:42:46,723 INFO org.apache.hadoop.yarn.server.resourcemanager.scheduler.capacity.ParentQueue: completedContainer queue=root usedCapacity=0.9791667 absoluteUsedCapacity=0.9791667 used=<memory:48128, vCores:42> cluster=<memory:49152, vCores:96>
2013-08-07 02:42:46,723 INFO org.apache.hadoop.yarn.server.resourcemanager.scheduler.capacity.CapacityScheduler: Application appattempt_1375842659078_0006_000001 released container container_1375842659078_0006_01_000039 on node: host: hadoop-200-3:34020 #containers=6 available=1024 used=7168 with event: FINISHED
2013-08-07 02:42:46,723 INFO org.apache.hadoop.yarn.server.resourcemanager.rmcontainer.RMContainerImpl: container_1375842659078_0007_01_000011 Container Transitioned from NEW to ALLOCATED
2013-08-07 02:42:46,723 INFO org.apache.hadoop.yarn.server.resourcemanager.RMAuditLogger: USER=ubuntu	OPERATION=AM Allocated Container	TARGET=SchedulerApp	RESULT=SUCCESS	APPID=application_1375842659078_0007	CONTAINERID=container_1375842659078_0007_01_000011
2013-08-07 02:42:46,723 INFO org.apache.hadoop.yarn.server.resourcemanager.scheduler.common.fica.FiCaSchedulerNode: Assigned container container_1375842659078_0007_01_000011 of capacity <memory:1024, vCores:1> on host hadoop-200-3:34020, which currently has 7 containers, <memory:8192, vCores:7> used and <memory:0, vCores:9> available
2013-08-07 02:42:46,724 INFO org.apache.hadoop.yarn.server.resourcemanager.scheduler.capacity.LeafQueue: assignedContainer application=application_1375842659078_0007 container=Container: [ContainerId: container_1375842659078_0007_01_000011, NodeId: hadoop-200-3:34020, NodeHttpAddress: hadoop-200-3:8042, Resource: <memory:1024, vCores:1>, Priority: 20, State: NEW, Token: null, Status: container_id {, app_attempt_id {, application_id {, id: 7, cluster_timestamp: 1375842659078, }, attemptId: 1, }, id: 11, }, state: C_NEW, ] containerId=container_1375842659078_0007_01_000011 queue=default: capacity=1.0, absoluteCapacity=1.0, usedResources=<memory:48128, vCores:42>usedCapacity=0.9791667, absoluteUsedCapacity=0.9791667, numApps=5, numContainers=42 usedCapacity=0.9791667 absoluteUsedCapacity=0.9791667 used=<memory:48128, vCores:42> cluster=<memory:49152, vCores:96>
2013-08-07 02:42:46,725 INFO org.apache.hadoop.yarn.server.resourcemanager.scheduler.capacity.ParentQueue: Re-sorting queues since queue: root.default stats: default: capacity=1.0, absoluteCapacity=1.0, usedResources=<memory:49152, vCores:43>usedCapacity=1.0, absoluteUsedCapacity=1.0, numApps=5, numContainers=43
2013-08-07 02:42:46,725 INFO org.apache.hadoop.yarn.server.resourcemanager.scheduler.capacity.ParentQueue: assignedContainer queue=root usedCapacity=1.0 absoluteUsedCapacity=1.0 used=<memory:49152, vCores:43> cluster=<memory:49152, vCores:96>
2013-08-07 02:42:47,449 INFO org.apache.hadoop.yarn.server.resourcemanager.rmcontainer.RMContainerImpl: container_1375842659078_0007_01_000007 Container Transitioned from ALLOCATED to ACQUIRED
2013-08-07 02:42:47,450 INFO org.apache.hadoop.yarn.server.resourcemanager.rmcontainer.RMContainerImpl: container_1375842659078_0007_01_000008 Container Transitioned from ALLOCATED to ACQUIRED
2013-08-07 02:42:47,450 INFO org.apache.hadoop.yarn.server.resourcemanager.rmcontainer.RMContainerImpl: container_1375842659078_0007_01_000009 Container Transitioned from ALLOCATED to ACQUIRED
2013-08-07 02:42:47,450 INFO org.apache.hadoop.yarn.server.resourcemanager.rmcontainer.RMContainerImpl: container_1375842659078_0007_01_000010 Container Transitioned from ALLOCATED to ACQUIRED
2013-08-07 02:42:47,450 INFO org.apache.hadoop.yarn.server.resourcemanager.rmcontainer.RMContainerImpl: container_1375842659078_0007_01_000011 Container Transitioned from ALLOCATED to ACQUIRED
2013-08-07 02:42:47,599 INFO org.apache.hadoop.yarn.server.resourcemanager.rmcontainer.RMContainerImpl: container_1375842659078_0007_01_000007 Container Transitioned from ACQUIRED to RUNNING
2013-08-07 02:42:47,600 INFO org.apache.hadoop.yarn.server.resourcemanager.rmcontainer.RMContainerImpl: container_1375842659078_0007_01_000008 Container Transitioned from ACQUIRED to RUNNING
2013-08-07 02:42:47,600 INFO org.apache.hadoop.yarn.server.resourcemanager.rmcontainer.RMContainerImpl: container_1375842659078_0007_01_000009 Container Transitioned from ACQUIRED to RUNNING
2013-08-07 02:42:47,600 INFO org.apache.hadoop.yarn.server.resourcemanager.rmcontainer.RMContainerImpl: container_1375842659078_0007_01_000010 Container Transitioned from ACQUIRED to RUNNING
2013-08-07 02:42:47,734 INFO org.apache.hadoop.yarn.server.resourcemanager.rmcontainer.RMContainerImpl: container_1375842659078_0007_01_000011 Container Transitioned from ACQUIRED to RUNNING
2013-08-07 02:42:48,033 INFO org.apache.hadoop.yarn.server.resourcemanager.rmcontainer.RMContainerImpl: container_1375842659078_0006_01_000014 Container Transitioned from RUNNING to COMPLETED
2013-08-07 02:42:48,033 INFO org.apache.hadoop.yarn.server.resourcemanager.scheduler.common.fica.FiCaSchedulerApp: Completed container: container_1375842659078_0006_01_000014 in state: COMPLETED event:FINISHED
2013-08-07 02:42:48,034 INFO org.apache.hadoop.yarn.server.resourcemanager.RMAuditLogger: USER=ubuntu	OPERATION=AM Released Container	TARGET=SchedulerApp	RESULT=SUCCESS	APPID=application_1375842659078_0006	CONTAINERID=container_1375842659078_0006_01_000014
2013-08-07 02:42:48,034 INFO org.apache.hadoop.yarn.server.resourcemanager.scheduler.common.fica.FiCaSchedulerNode: Released container container_1375842659078_0006_01_000014 of capacity <memory:1024, vCores:1> on host hadoop-200-2:33271, which currently has 7 containers, <memory:7168, vCores:7> used and <memory:1024, vCores:9> available, release resources=true
2013-08-07 02:42:48,034 INFO org.apache.hadoop.yarn.server.resourcemanager.scheduler.capacity.LeafQueue: default used=<memory:48128, vCores:42> numContainers=42 user=ubuntu user-resources=<memory:48128, vCores:42>
2013-08-07 02:42:48,035 INFO org.apache.hadoop.yarn.server.resourcemanager.scheduler.capacity.LeafQueue: completedContainer container=Container: [ContainerId: container_1375842659078_0006_01_000014, NodeId: hadoop-200-2:33271, NodeHttpAddress: hadoop-200-2:8042, Resource: <memory:1024, vCores:1>, Priority: 20, State: NEW, Token: null, Status: container_id {, app_attempt_id {, application_id {, id: 6, cluster_timestamp: 1375842659078, }, attemptId: 1, }, id: 14, }, state: C_COMPLETE, diagnostics: "Container killed by the ApplicationMaster.\n\n", exit_status: 143, ] resource=<memory:1024, vCores:1> queue=default: capacity=1.0, absoluteCapacity=1.0, usedResources=<memory:48128, vCores:42>usedCapacity=0.9791667, absoluteUsedCapacity=0.9791667, numApps=5, numContainers=42 usedCapacity=0.9791667 absoluteUsedCapacity=0.9791667 used=<memory:48128, vCores:42> cluster=<memory:49152, vCores:96>
2013-08-07 02:42:48,038 INFO org.apache.hadoop.yarn.server.resourcemanager.scheduler.capacity.ParentQueue: completedContainer queue=root usedCapacity=0.9791667 absoluteUsedCapacity=0.9791667 used=<memory:48128, vCores:42> cluster=<memory:49152, vCores:96>
2013-08-07 02:42:48,039 INFO org.apache.hadoop.yarn.server.resourcemanager.scheduler.capacity.CapacityScheduler: Application appattempt_1375842659078_0006_000001 released container container_1375842659078_0006_01_000014 on node: host: hadoop-200-2:33271 #containers=7 available=1024 used=7168 with event: FINISHED
2013-08-07 02:42:48,039 INFO org.apache.hadoop.yarn.server.resourcemanager.rmcontainer.RMContainerImpl: container_1375842659078_0006_01_000048 Container Transitioned from NEW to ALLOCATED
2013-08-07 02:42:48,039 INFO org.apache.hadoop.yarn.server.resourcemanager.RMAuditLogger: USER=ubuntu	OPERATION=AM Allocated Container	TARGET=SchedulerApp	RESULT=SUCCESS	APPID=application_1375842659078_0006	CONTAINERID=container_1375842659078_0006_01_000048
2013-08-07 02:42:48,039 INFO org.apache.hadoop.yarn.server.resourcemanager.scheduler.common.fica.FiCaSchedulerNode: Assigned container container_1375842659078_0006_01_000048 of capacity <memory:1024, vCores:1> on host hadoop-200-2:33271, which currently has 8 containers, <memory:8192, vCores:8> used and <memory:0, vCores:8> available
2013-08-07 02:42:48,040 INFO org.apache.hadoop.yarn.server.resourcemanager.scheduler.capacity.LeafQueue: assignedContainer application=application_1375842659078_0006 container=Container: [ContainerId: container_1375842659078_0006_01_000048, NodeId: hadoop-200-2:33271, NodeHttpAddress: hadoop-200-2:8042, Resource: <memory:1024, vCores:1>, Priority: 20, State: NEW, Token: null, Status: container_id {, app_attempt_id {, application_id {, id: 6, cluster_timestamp: 1375842659078, }, attemptId: 1, }, id: 48, }, state: C_NEW, ] containerId=container_1375842659078_0006_01_000048 queue=default: capacity=1.0, absoluteCapacity=1.0, usedResources=<memory:48128, vCores:42>usedCapacity=0.9791667, absoluteUsedCapacity=0.9791667, numApps=5, numContainers=42 usedCapacity=0.9791667 absoluteUsedCapacity=0.9791667 used=<memory:48128, vCores:42> cluster=<memory:49152, vCores:96>
2013-08-07 02:42:48,041 INFO org.apache.hadoop.yarn.server.resourcemanager.scheduler.capacity.ParentQueue: Re-sorting queues since queue: root.default stats: default: capacity=1.0, absoluteCapacity=1.0, usedResources=<memory:49152, vCores:43>usedCapacity=1.0, absoluteUsedCapacity=1.0, numApps=5, numContainers=43
2013-08-07 02:42:48,041 INFO org.apache.hadoop.yarn.server.resourcemanager.scheduler.capacity.ParentQueue: assignedContainer queue=root usedCapacity=1.0 absoluteUsedCapacity=1.0 used=<memory:49152, vCores:43> cluster=<memory:49152, vCores:96>
2013-08-07 02:42:48,141 INFO org.apache.hadoop.yarn.server.resourcemanager.rmcontainer.RMContainerImpl: container_1375842659078_0006_01_000048 Container Transitioned from ALLOCATED to ACQUIRED
2013-08-07 02:42:48,926 INFO org.apache.hadoop.yarn.server.resourcemanager.rmcontainer.RMContainerImpl: container_1375842659078_0006_01_000006 Container Transitioned from RUNNING to COMPLETED
2013-08-07 02:42:48,927 INFO org.apache.hadoop.yarn.server.resourcemanager.scheduler.common.fica.FiCaSchedulerApp: Completed container: container_1375842659078_0006_01_000006 in state: COMPLETED event:FINISHED
2013-08-07 02:42:48,927 INFO org.apache.hadoop.yarn.server.resourcemanager.RMAuditLogger: USER=ubuntu	OPERATION=AM Released Container	TARGET=SchedulerApp	RESULT=SUCCESS	APPID=application_1375842659078_0006	CONTAINERID=container_1375842659078_0006_01_000006
2013-08-07 02:42:48,927 INFO org.apache.hadoop.yarn.server.resourcemanager.scheduler.common.fica.FiCaSchedulerNode: Released container container_1375842659078_0006_01_000006 of capacity <memory:1024, vCores:1> on host hadoop-200-6:44827, which currently has 7 containers, <memory:7168, vCores:7> used and <memory:1024, vCores:9> available, release resources=true
2013-08-07 02:42:48,927 INFO org.apache.hadoop.yarn.server.resourcemanager.scheduler.capacity.LeafQueue: default used=<memory:48128, vCores:42> numContainers=42 user=ubuntu user-resources=<memory:48128, vCores:42>
2013-08-07 02:42:48,928 INFO org.apache.hadoop.yarn.server.resourcemanager.scheduler.capacity.LeafQueue: completedContainer container=Container: [ContainerId: container_1375842659078_0006_01_000006, NodeId: hadoop-200-6:44827, NodeHttpAddress: hadoop-200-6:8042, Resource: <memory:1024, vCores:1>, Priority: 20, State: NEW, Token: null, Status: container_id {, app_attempt_id {, application_id {, id: 6, cluster_timestamp: 1375842659078, }, attemptId: 1, }, id: 6, }, state: C_COMPLETE, diagnostics: "Container killed by the ApplicationMaster.\n\n", exit_status: 143, ] resource=<memory:1024, vCores:1> queue=default: capacity=1.0, absoluteCapacity=1.0, usedResources=<memory:48128, vCores:42>usedCapacity=0.9791667, absoluteUsedCapacity=0.9791667, numApps=5, numContainers=42 usedCapacity=0.9791667 absoluteUsedCapacity=0.9791667 used=<memory:48128, vCores:42> cluster=<memory:49152, vCores:96>
2013-08-07 02:42:48,929 INFO org.apache.hadoop.yarn.server.resourcemanager.scheduler.capacity.ParentQueue: completedContainer queue=root usedCapacity=0.9791667 absoluteUsedCapacity=0.9791667 used=<memory:48128, vCores:42> cluster=<memory:49152, vCores:96>
2013-08-07 02:42:48,929 INFO org.apache.hadoop.yarn.server.resourcemanager.scheduler.capacity.CapacityScheduler: Application appattempt_1375842659078_0006_000001 released container container_1375842659078_0006_01_000006 on node: host: hadoop-200-6:44827 #containers=7 available=1024 used=7168 with event: FINISHED
2013-08-07 02:42:48,929 INFO org.apache.hadoop.yarn.server.resourcemanager.rmcontainer.RMContainerImpl: container_1375842659078_0007_01_000012 Container Transitioned from NEW to ALLOCATED
2013-08-07 02:42:48,929 INFO org.apache.hadoop.yarn.server.resourcemanager.RMAuditLogger: USER=ubuntu	OPERATION=AM Allocated Container	TARGET=SchedulerApp	RESULT=SUCCESS	APPID=application_1375842659078_0007	CONTAINERID=container_1375842659078_0007_01_000012
2013-08-07 02:42:48,930 INFO org.apache.hadoop.yarn.server.resourcemanager.scheduler.common.fica.FiCaSchedulerNode: Assigned container container_1375842659078_0007_01_000012 of capacity <memory:1024, vCores:1> on host hadoop-200-6:44827, which currently has 8 containers, <memory:8192, vCores:8> used and <memory:0, vCores:8> available
2013-08-07 02:42:48,930 INFO org.apache.hadoop.yarn.server.resourcemanager.scheduler.capacity.LeafQueue: assignedContainer application=application_1375842659078_0007 container=Container: [ContainerId: container_1375842659078_0007_01_000012, NodeId: hadoop-200-6:44827, NodeHttpAddress: hadoop-200-6:8042, Resource: <memory:1024, vCores:1>, Priority: 20, State: NEW, Token: null, Status: container_id {, app_attempt_id {, application_id {, id: 7, cluster_timestamp: 1375842659078, }, attemptId: 1, }, id: 12, }, state: C_NEW, ] containerId=container_1375842659078_0007_01_000012 queue=default: capacity=1.0, absoluteCapacity=1.0, usedResources=<memory:48128, vCores:42>usedCapacity=0.9791667, absoluteUsedCapacity=0.9791667, numApps=5, numContainers=42 usedCapacity=0.9791667 absoluteUsedCapacity=0.9791667 used=<memory:48128, vCores:42> cluster=<memory:49152, vCores:96>
2013-08-07 02:42:48,931 INFO org.apache.hadoop.yarn.server.resourcemanager.scheduler.capacity.ParentQueue: Re-sorting queues since queue: root.default stats: default: capacity=1.0, absoluteCapacity=1.0, usedResources=<memory:49152, vCores:43>usedCapacity=1.0, absoluteUsedCapacity=1.0, numApps=5, numContainers=43
2013-08-07 02:42:48,931 INFO org.apache.hadoop.yarn.server.resourcemanager.scheduler.capacity.ParentQueue: assignedContainer queue=root usedCapacity=1.0 absoluteUsedCapacity=1.0 used=<memory:49152, vCores:43> cluster=<memory:49152, vCores:96>
2013-08-07 02:42:49,077 INFO org.apache.hadoop.yarn.server.resourcemanager.rmcontainer.RMContainerImpl: container_1375842659078_0006_01_000048 Container Transitioned from ACQUIRED to RUNNING
2013-08-07 02:42:49,077 INFO org.apache.hadoop.yarn.server.resourcemanager.rmcontainer.RMContainerImpl: container_1375842659078_0006_01_000013 Container Transitioned from RUNNING to COMPLETED
2013-08-07 02:42:49,078 INFO org.apache.hadoop.yarn.server.resourcemanager.scheduler.common.fica.FiCaSchedulerApp: Completed container: container_1375842659078_0006_01_000013 in state: COMPLETED event:FINISHED
2013-08-07 02:42:49,078 INFO org.apache.hadoop.yarn.server.resourcemanager.RMAuditLogger: USER=ubuntu	OPERATION=AM Released Container	TARGET=SchedulerApp	RESULT=SUCCESS	APPID=application_1375842659078_0006	CONTAINERID=container_1375842659078_0006_01_000013
2013-08-07 02:42:49,078 INFO org.apache.hadoop.yarn.server.resourcemanager.scheduler.common.fica.FiCaSchedulerNode: Released container container_1375842659078_0006_01_000013 of capacity <memory:1024, vCores:1> on host hadoop-200-2:33271, which currently has 7 containers, <memory:7168, vCores:7> used and <memory:1024, vCores:9> available, release resources=true
2013-08-07 02:42:49,079 INFO org.apache.hadoop.yarn.server.resourcemanager.scheduler.capacity.LeafQueue: default used=<memory:48128, vCores:42> numContainers=42 user=ubuntu user-resources=<memory:48128, vCores:42>
2013-08-07 02:42:49,080 INFO org.apache.hadoop.yarn.server.resourcemanager.scheduler.capacity.LeafQueue: completedContainer container=Container: [ContainerId: container_1375842659078_0006_01_000013, NodeId: hadoop-200-2:33271, NodeHttpAddress: hadoop-200-2:8042, Resource: <memory:1024, vCores:1>, Priority: 20, State: NEW, Token: null, Status: container_id {, app_attempt_id {, application_id {, id: 6, cluster_timestamp: 1375842659078, }, attemptId: 1, }, id: 13, }, state: C_COMPLETE, diagnostics: "Container killed by the ApplicationMaster.\n\n", exit_status: 143, ] resource=<memory:1024, vCores:1> queue=default: capacity=1.0, absoluteCapacity=1.0, usedResources=<memory:48128, vCores:42>usedCapacity=0.9791667, absoluteUsedCapacity=0.9791667, numApps=5, numContainers=42 usedCapacity=0.9791667 absoluteUsedCapacity=0.9791667 used=<memory:48128, vCores:42> cluster=<memory:49152, vCores:96>
2013-08-07 02:42:49,080 INFO org.apache.hadoop.yarn.server.resourcemanager.scheduler.capacity.ParentQueue: completedContainer queue=root usedCapacity=0.9791667 absoluteUsedCapacity=0.9791667 used=<memory:48128, vCores:42> cluster=<memory:49152, vCores:96>
2013-08-07 02:42:49,080 INFO org.apache.hadoop.yarn.server.resourcemanager.scheduler.capacity.CapacityScheduler: Application appattempt_1375842659078_0006_000001 released container container_1375842659078_0006_01_000013 on node: host: hadoop-200-2:33271 #containers=7 available=1024 used=7168 with event: FINISHED
2013-08-07 02:42:49,080 INFO org.apache.hadoop.yarn.server.resourcemanager.rmcontainer.RMContainerImpl: container_1375842659078_0007_01_000013 Container Transitioned from NEW to ALLOCATED
2013-08-07 02:42:49,081 INFO org.apache.hadoop.yarn.server.resourcemanager.RMAuditLogger: USER=ubuntu	OPERATION=AM Allocated Container	TARGET=SchedulerApp	RESULT=SUCCESS	APPID=application_1375842659078_0007	CONTAINERID=container_1375842659078_0007_01_000013
2013-08-07 02:42:49,081 INFO org.apache.hadoop.yarn.server.resourcemanager.scheduler.common.fica.FiCaSchedulerNode: Assigned container container_1375842659078_0007_01_000013 of capacity <memory:1024, vCores:1> on host hadoop-200-2:33271, which currently has 8 containers, <memory:8192, vCores:8> used and <memory:0, vCores:8> available
