2013-08-07 03:16:58,525 INFO org.apache.hadoop.yarn.server.resourcemanager.ResourceManager: STARTUP_MSG: 
/************************************************************
STARTUP_MSG: Starting ResourceManager
STARTUP_MSG:   host = hadoop-200-1/192.168.100.5
STARTUP_MSG:   args = []
STARTUP_MSG:   version = 3.0.0-SNAPSHOT
STARTUP_MSG:   build = https://github.com/lalithsuresh/hadoop-common -r 0cb423bd4868928bb06cd93f882bb0913172fd17; compiled by 'lsuresh' on 2013-04-08T15:47Z
STARTUP_MSG:   java = 1.7.0_17
************************************************************/
2013-08-07 03:16:58,539 INFO org.apache.hadoop.yarn.server.resourcemanager.ResourceManager: registered UNIX signal handlers for [TERM, HUP, INT]
2013-08-07 03:16:59,226 INFO org.apache.hadoop.yarn.server.resourcemanager.security.ApplicationTokenSecretManager: Rolling master-key for application-tokens
2013-08-07 03:16:59,262 INFO org.apache.hadoop.yarn.server.resourcemanager.security.RMContainerTokenSecretManager: ContainerTokenKeyRollingInterval: 86400000ms and ContainerTokenKeyActivationDelay: 900000ms
2013-08-07 03:16:59,264 INFO org.apache.hadoop.yarn.service.AbstractService: Service:Dispatcher is inited.
2013-08-07 03:16:59,266 INFO org.apache.hadoop.yarn.event.AsyncDispatcher: Registering class org.apache.hadoop.yarn.server.resourcemanager.recovery.RMStateStoreEventType for class org.apache.hadoop.yarn.server.resourcemanager.recovery.RMStateStore$ForwardingEventHandler
2013-08-07 03:16:59,266 INFO org.apache.hadoop.yarn.service.AbstractService: Service:Dispatcher is started.
2013-08-07 03:16:59,289 INFO org.apache.hadoop.yarn.event.AsyncDispatcher: Registering class org.apache.hadoop.yarn.server.resourcemanager.NodesListManagerEventType for class org.apache.hadoop.yarn.server.resourcemanager.NodesListManager
2013-08-07 03:16:59,290 INFO org.apache.hadoop.yarn.server.resourcemanager.ResourceManager: Using Scheduler: org.apache.hadoop.yarn.server.resourcemanager.scheduler.capacity.CapacityScheduler
2013-08-07 03:16:59,444 INFO org.apache.hadoop.yarn.event.AsyncDispatcher: Registering class org.apache.hadoop.yarn.server.resourcemanager.scheduler.event.SchedulerEventType for class org.apache.hadoop.yarn.server.resourcemanager.ResourceManager$SchedulerEventDispatcher
2013-08-07 03:16:59,446 INFO org.apache.hadoop.yarn.event.AsyncDispatcher: Registering class org.apache.hadoop.yarn.server.resourcemanager.rmapp.RMAppEventType for class org.apache.hadoop.yarn.server.resourcemanager.ResourceManager$ApplicationEventDispatcher
2013-08-07 03:16:59,448 INFO org.apache.hadoop.yarn.event.AsyncDispatcher: Registering class org.apache.hadoop.yarn.server.resourcemanager.rmapp.attempt.RMAppAttemptEventType for class org.apache.hadoop.yarn.server.resourcemanager.ResourceManager$ApplicationAttemptEventDispatcher
2013-08-07 03:16:59,449 INFO org.apache.hadoop.yarn.event.AsyncDispatcher: Registering class org.apache.hadoop.yarn.server.resourcemanager.rmnode.RMNodeEventType for class org.apache.hadoop.yarn.server.resourcemanager.ResourceManager$NodeEventDispatcher
2013-08-07 03:17:00,132 WARN org.apache.hadoop.util.NativeCodeLoader: Unable to load native-hadoop library for your platform... using builtin-java classes where applicable
2013-08-07 03:17:00,198 INFO org.apache.hadoop.yarn.server.resourcemanager.scheduler.capacity.ParentQueue: root, capacity=1.0, asboluteCapacity=1.0, maxCapacity=1.0, asboluteMaxCapacity=1.0, state=RUNNING, acls=ADMINISTER_QUEUE:*SUBMIT_APPLICATIONS:*
2013-08-07 03:17:00,198 INFO org.apache.hadoop.yarn.server.resourcemanager.scheduler.capacity.ParentQueue: Initialized parent-queue root name=root, fullname=root
2013-08-07 03:17:00,218 INFO org.apache.hadoop.yarn.server.resourcemanager.scheduler.capacity.LeafQueue: Initializing default
capacity = 1.0 [= (float) configuredCapacity / 100 ]
asboluteCapacity = 1.0 [= parentAbsoluteCapacity * capacity ]
maxCapacity = 1.0 [= configuredMaxCapacity ]
absoluteMaxCapacity = 1.0 [= 1.0 maximumCapacity undefined, (parentAbsoluteMaxCapacity * maximumCapacity) / 100 otherwise ]
userLimit = 100 [= configuredUserLimit ]
userLimitFactor = 1.0 [= configuredUserLimitFactor ]
maxApplications = 10000 [= configuredMaximumSystemApplicationsPerQueue or (int)(configuredMaximumSystemApplications * absoluteCapacity)]
maxApplicationsPerUser = 10000 [= (int)(maxApplications * (userLimit / 100.0f) * userLimitFactor) ]
maxActiveApplications = 1 [= max((int)ceil((clusterResourceMemory / minimumAllocation) * maxAMResourcePerQueuePercent * absoluteMaxCapacity),1) ]
maxActiveAppsUsingAbsCap = 1 [= max((int)ceil((clusterResourceMemory / minimumAllocation) *maxAMResourcePercent * absoluteCapacity),1) ]
maxActiveApplicationsPerUser = 1 [= max((int)(maxActiveApplications * (userLimit / 100.0f) * userLimitFactor),1) ]
usedCapacity = 0.0 [= usedResourcesMemory / (clusterResourceMemory * absoluteCapacity)]
absoluteUsedCapacity = 0.0 [= usedResourcesMemory / clusterResourceMemory]
maxAMResourcePerQueuePercent = 0.1 [= configuredMaximumAMResourcePercent ]
minimumAllocationFactor = 0.875 [= (float)(maximumAllocationMemory - minimumAllocationMemory) / maximumAllocationMemory ]
numContainers = 0 [= currentNumContainers ]
state = RUNNING [= configuredState ]
acls = ADMINISTER_QUEUE:*SUBMIT_APPLICATIONS:* [= configuredAcls ]

2013-08-07 03:17:00,218 INFO org.apache.hadoop.yarn.server.resourcemanager.scheduler.capacity.CapacityScheduler: Initialized queue: default: capacity=1.0, absoluteCapacity=1.0, usedResources=<memory:0, vCores:0>usedCapacity=0.0, absoluteUsedCapacity=0.0, numApps=0, numContainers=0
2013-08-07 03:17:00,219 INFO org.apache.hadoop.yarn.server.resourcemanager.scheduler.capacity.CapacityScheduler: Initialized queue: root: numChildQueue= 1, capacity=1.0, absoluteCapacity=1.0, usedResources=<memory:0, vCores:0>usedCapacity=0.0, numApps=0, numContainers=0
2013-08-07 03:17:00,219 INFO org.apache.hadoop.yarn.server.resourcemanager.scheduler.capacity.CapacityScheduler: Initialized root queue root: numChildQueue= 1, capacity=1.0, absoluteCapacity=1.0, usedResources=<memory:0, vCores:0>usedCapacity=0.0, numApps=0, numContainers=0
2013-08-07 03:17:00,219 INFO org.apache.hadoop.yarn.server.resourcemanager.scheduler.capacity.CapacityScheduler: Initialized CapacityScheduler with calculator=class org.apache.hadoop.yarn.server.resourcemanager.resource.DefaultResourceCalculator, minimumAllocation=<<memory:1024, vCores:1>>, maximumAllocation=<<memory:8192, vCores:32>>
2013-08-07 03:17:00,665 INFO org.apache.hadoop.yarn.event.AsyncDispatcher: Registering class org.apache.hadoop.yarn.server.resourcemanager.RMAppManagerEventType for class org.apache.hadoop.yarn.server.resourcemanager.RMAppManager
2013-08-07 03:17:00,687 INFO org.apache.hadoop.yarn.event.AsyncDispatcher: Registering class org.apache.hadoop.yarn.server.resourcemanager.amlauncher.AMLauncherEventType for class org.apache.hadoop.yarn.server.resourcemanager.amlauncher.ApplicationMasterLauncher
2013-08-07 03:17:00,790 INFO org.apache.hadoop.yarn.server.resourcemanager.RMNMInfo: Registered RMNMInfo MBean
2013-08-07 03:17:00,790 INFO org.apache.hadoop.yarn.service.AbstractService: Service:Dispatcher is inited.
2013-08-07 03:17:00,790 INFO org.apache.hadoop.yarn.service.AbstractService: Service:org.apache.hadoop.yarn.server.resourcemanager.rmcontainer.ContainerAllocationExpirer is inited.
2013-08-07 03:17:00,790 INFO org.apache.hadoop.yarn.service.AbstractService: Service:AMLivelinessMonitor is inited.
2013-08-07 03:17:00,791 INFO org.apache.hadoop.yarn.service.AbstractService: Service:AMLivelinessMonitor is inited.
2013-08-07 03:17:00,791 INFO org.apache.hadoop.yarn.service.AbstractService: Service:org.apache.hadoop.yarn.server.resourcemanager.security.DelegationTokenRenewer is inited.
2013-08-07 03:17:00,793 INFO org.apache.hadoop.util.HostsFileReader: Refreshing hosts (include/exclude) list
2013-08-07 03:17:00,793 INFO org.apache.hadoop.yarn.service.AbstractService: Service:org.apache.hadoop.yarn.server.resourcemanager.NodesListManager is inited.
2013-08-07 03:17:00,793 INFO org.apache.hadoop.yarn.service.AbstractService: Service:org.apache.hadoop.yarn.server.resourcemanager.ResourceManager$SchedulerEventDispatcher is inited.
2013-08-07 03:17:00,793 INFO org.apache.hadoop.yarn.service.AbstractService: Service:NMLivelinessMonitor is inited.
2013-08-07 03:17:00,802 INFO org.apache.hadoop.yarn.service.AbstractService: Service:org.apache.hadoop.yarn.server.resourcemanager.ResourceTrackerService is inited.
2013-08-07 03:17:00,802 INFO org.apache.hadoop.yarn.service.AbstractService: Service:org.apache.hadoop.yarn.server.resourcemanager.ApplicationMasterService is inited.
2013-08-07 03:17:00,802 INFO org.apache.hadoop.yarn.service.AbstractService: Service:org.apache.hadoop.yarn.server.resourcemanager.ClientRMService is inited.
2013-08-07 03:17:00,802 INFO org.apache.hadoop.yarn.service.AbstractService: Service:org.apache.hadoop.yarn.server.resourcemanager.AdminService is inited.
2013-08-07 03:17:00,803 INFO org.apache.hadoop.yarn.service.AbstractService: Service:org.apache.hadoop.yarn.server.resourcemanager.amlauncher.ApplicationMasterLauncher is inited.
2013-08-07 03:17:00,803 INFO org.apache.hadoop.yarn.service.AbstractService: Service:ResourceManager is inited.
2013-08-07 03:17:00,803 INFO org.apache.hadoop.yarn.server.resourcemanager.security.RMContainerTokenSecretManager: Rolling master-key for container-tokens
2013-08-07 03:17:00,803 INFO org.apache.hadoop.yarn.server.resourcemanager.security.ApplicationTokenSecretManager: Rolling master-key for application-tokens
2013-08-07 03:17:00,962 INFO org.mortbay.log: Logging to org.slf4j.impl.Log4jLoggerAdapter(org.mortbay.log) via org.mortbay.log.Slf4jLog
2013-08-07 03:17:01,052 INFO org.apache.hadoop.http.HttpServer: Added global filter 'safety' (class=org.apache.hadoop.http.HttpServer$QuotingInputFilter)
2013-08-07 03:17:01,057 INFO org.apache.hadoop.http.HttpServer: Added filter static_user_filter (class=org.apache.hadoop.http.lib.StaticUserWebFilter$StaticUserFilter) to context cluster
2013-08-07 03:17:01,057 INFO org.apache.hadoop.http.HttpServer: Added filter static_user_filter (class=org.apache.hadoop.http.lib.StaticUserWebFilter$StaticUserFilter) to context static
2013-08-07 03:17:01,057 INFO org.apache.hadoop.http.HttpServer: Added filter static_user_filter (class=org.apache.hadoop.http.lib.StaticUserWebFilter$StaticUserFilter) to context logs
2013-08-07 03:17:01,063 INFO org.apache.hadoop.http.HttpServer: adding path spec: /cluster
2013-08-07 03:17:01,064 INFO org.apache.hadoop.http.HttpServer: adding path spec: /cluster/*
2013-08-07 03:17:01,064 INFO org.apache.hadoop.http.HttpServer: adding path spec: /ws
2013-08-07 03:17:01,064 INFO org.apache.hadoop.http.HttpServer: adding path spec: /ws/*
2013-08-07 03:17:01,067 INFO org.apache.hadoop.http.HttpServer: Added global filter 'guice' (class=com.google.inject.servlet.GuiceFilter)
2013-08-07 03:17:01,075 INFO org.apache.hadoop.http.HttpServer: Jetty bound to port 8088
2013-08-07 03:17:01,076 INFO org.mortbay.log: jetty-6.1.26
2013-08-07 03:17:01,130 INFO org.mortbay.log: Extract jar:file:/home/ubuntu/hadoop-3.0.0-SNAPSHOT/share/hadoop/yarn/hadoop-yarn-common-3.0.0-SNAPSHOT.jar!/webapps/cluster to /tmp/Jetty_0_0_0_0_8088_cluster____u0rgz3/webapp
2013-08-07 03:17:01,663 INFO org.mortbay.log: Started SelectChannelConnector@0.0.0.0:8088
2013-08-07 03:17:01,664 INFO org.apache.hadoop.yarn.webapp.WebApps: Web app /cluster started at 8088
2013-08-07 03:17:02,606 INFO org.apache.hadoop.yarn.webapp.WebApps: Registered webapp guice modules
2013-08-07 03:17:02,727 INFO org.apache.hadoop.metrics2.impl.MetricsConfig: loaded properties from hadoop-metrics2.properties
2013-08-07 03:17:02,765 INFO org.apache.hadoop.metrics2.impl.MetricsSystemImpl: Scheduled snapshot period at 10 second(s).
2013-08-07 03:17:02,765 INFO org.apache.hadoop.metrics2.impl.MetricsSystemImpl: ResourceManager metrics system started
2013-08-07 03:17:02,781 INFO org.apache.hadoop.security.token.delegation.AbstractDelegationTokenSecretManager: Updating the current master key for generating delegation tokens
2013-08-07 03:17:02,785 INFO org.apache.hadoop.yarn.service.AbstractService: Service:Dispatcher is started.
2013-08-07 03:17:02,786 INFO org.apache.hadoop.security.token.delegation.AbstractDelegationTokenSecretManager: Starting expired delegation token remover thread, tokenRemoverScanInterval=60 min(s)
2013-08-07 03:17:02,786 INFO org.apache.hadoop.security.token.delegation.AbstractDelegationTokenSecretManager: Updating the current master key for generating delegation tokens
2013-08-07 03:17:02,788 INFO org.apache.hadoop.yarn.service.AbstractService: Service:org.apache.hadoop.yarn.server.resourcemanager.rmcontainer.ContainerAllocationExpirer is started.
2013-08-07 03:17:02,789 INFO org.apache.hadoop.yarn.service.AbstractService: Service:AMLivelinessMonitor is started.
2013-08-07 03:17:02,789 INFO org.apache.hadoop.yarn.service.AbstractService: Service:AMLivelinessMonitor is started.
2013-08-07 03:17:02,789 INFO org.apache.hadoop.yarn.service.AbstractService: Service:org.apache.hadoop.yarn.server.resourcemanager.security.DelegationTokenRenewer is started.
2013-08-07 03:17:02,791 INFO org.apache.hadoop.yarn.service.AbstractService: Service:org.apache.hadoop.yarn.server.resourcemanager.NodesListManager is started.
2013-08-07 03:17:02,792 INFO org.apache.hadoop.yarn.service.AbstractService: Service:org.apache.hadoop.yarn.server.resourcemanager.ResourceManager$SchedulerEventDispatcher is started.
2013-08-07 03:17:02,793 INFO org.apache.hadoop.yarn.service.AbstractService: Service:NMLivelinessMonitor is started.
2013-08-07 03:17:02,793 INFO org.apache.hadoop.yarn.service.AbstractService: Service:org.apache.hadoop.yarn.server.resourcemanager.ResourceTrackerService is started.
2013-08-07 03:17:02,875 INFO org.apache.hadoop.ipc.Server: Starting Socket Reader #1 for port 54110
2013-08-07 03:17:02,919 INFO org.apache.hadoop.yarn.factories.impl.pb.RpcServerFactoryPBImpl: Adding protocol org.apache.hadoop.yarn.server.api.ResourceTrackerPB to the server
2013-08-07 03:17:02,921 INFO org.apache.hadoop.ipc.Server: IPC Server Responder: starting
2013-08-07 03:17:02,922 INFO org.apache.hadoop.ipc.Server: IPC Server listener on 54110: starting
2013-08-07 03:17:03,052 INFO org.apache.hadoop.ipc.Server: Starting Socket Reader #1 for port 54112
2013-08-07 03:17:03,081 INFO org.apache.hadoop.yarn.factories.impl.pb.RpcServerFactoryPBImpl: Adding protocol org.apache.hadoop.yarn.api.AMRMProtocolPB to the server
2013-08-07 03:17:03,082 INFO org.apache.hadoop.ipc.Server: IPC Server Responder: starting
2013-08-07 03:17:03,083 INFO org.apache.hadoop.ipc.Server: IPC Server listener on 54112: starting
2013-08-07 03:17:03,107 INFO org.apache.hadoop.yarn.service.AbstractService: Service:org.apache.hadoop.yarn.server.resourcemanager.ApplicationMasterService is started.
2013-08-07 03:17:03,161 INFO org.apache.hadoop.ipc.Server: Starting Socket Reader #1 for port 54111
2013-08-07 03:17:03,167 INFO org.apache.hadoop.yarn.factories.impl.pb.RpcServerFactoryPBImpl: Adding protocol org.apache.hadoop.yarn.api.ClientRMProtocolPB to the server
2013-08-07 03:17:03,169 INFO org.apache.hadoop.ipc.Server: IPC Server Responder: starting
2013-08-07 03:17:03,169 INFO org.apache.hadoop.ipc.Server: IPC Server listener on 54111: starting
2013-08-07 03:17:03,214 INFO org.apache.hadoop.yarn.service.AbstractService: Service:org.apache.hadoop.yarn.server.resourcemanager.ClientRMService is started.
2013-08-07 03:17:03,251 INFO org.apache.hadoop.ipc.Server: Starting Socket Reader #1 for port 8033
2013-08-07 03:17:03,266 INFO org.apache.hadoop.yarn.factories.impl.pb.RpcServerFactoryPBImpl: Adding protocol org.apache.hadoop.yarn.api.RMAdminProtocolPB to the server
2013-08-07 03:17:03,267 INFO org.apache.hadoop.ipc.Server: IPC Server Responder: starting
2013-08-07 03:17:03,269 INFO org.apache.hadoop.ipc.Server: IPC Server listener on 8033: starting
2013-08-07 03:17:03,269 INFO org.apache.hadoop.yarn.service.AbstractService: Service:org.apache.hadoop.yarn.server.resourcemanager.AdminService is started.
2013-08-07 03:17:03,279 INFO org.apache.hadoop.yarn.service.AbstractService: Service:org.apache.hadoop.yarn.server.resourcemanager.amlauncher.ApplicationMasterLauncher is started.
2013-08-07 03:17:03,280 INFO org.apache.hadoop.yarn.service.AbstractService: Service:ResourceManager is started.
2013-08-07 03:17:13,249 INFO org.apache.hadoop.yarn.util.RackResolver: Resolved hadoop-200-3 to /default-rack
2013-08-07 03:17:13,249 INFO org.apache.hadoop.yarn.util.RackResolver: Resolved hadoop-200-2 to /default-rack
2013-08-07 03:17:13,261 INFO org.apache.hadoop.yarn.util.RackResolver: Resolved hadoop-200-4 to /default-rack
2013-08-07 03:17:13,261 INFO org.apache.hadoop.yarn.util.RackResolver: Resolved hadoop-200-5 to /default-rack
2013-08-07 03:17:13,262 INFO org.apache.hadoop.yarn.util.RackResolver: Resolved hadoop-200-7 to /default-rack
2013-08-07 03:17:13,262 INFO org.apache.hadoop.yarn.util.RackResolver: Resolved hadoop-200-6 to /default-rack
2013-08-07 03:17:13,273 INFO org.apache.hadoop.yarn.server.resourcemanager.ResourceTrackerService: NodeManager from node hadoop-200-4(cmPort: 45217 httpPort: 8042) registered with capability: <memory:8192, vCores:16>, assigned nodeId hadoop-200-4:45217
2013-08-07 03:17:13,274 INFO org.apache.hadoop.yarn.server.resourcemanager.ResourceTrackerService: NodeManager from node hadoop-200-5(cmPort: 34756 httpPort: 8042) registered with capability: <memory:8192, vCores:16>, assigned nodeId hadoop-200-5:34756
2013-08-07 03:17:13,274 INFO org.apache.hadoop.yarn.server.resourcemanager.ResourceTrackerService: NodeManager from node hadoop-200-7(cmPort: 47421 httpPort: 8042) registered with capability: <memory:8192, vCores:16>, assigned nodeId hadoop-200-7:47421
2013-08-07 03:17:13,274 INFO org.apache.hadoop.yarn.server.resourcemanager.ResourceTrackerService: NodeManager from node hadoop-200-6(cmPort: 45851 httpPort: 8042) registered with capability: <memory:8192, vCores:16>, assigned nodeId hadoop-200-6:45851
2013-08-07 03:17:13,274 INFO org.apache.hadoop.yarn.server.resourcemanager.ResourceTrackerService: NodeManager from node hadoop-200-2(cmPort: 46099 httpPort: 8042) registered with capability: <memory:8192, vCores:16>, assigned nodeId hadoop-200-2:46099
2013-08-07 03:17:13,274 INFO org.apache.hadoop.yarn.server.resourcemanager.ResourceTrackerService: NodeManager from node hadoop-200-3(cmPort: 52180 httpPort: 8042) registered with capability: <memory:8192, vCores:16>, assigned nodeId hadoop-200-3:52180
2013-08-07 03:17:13,285 INFO org.apache.hadoop.yarn.server.resourcemanager.rmnode.RMNodeImpl: hadoop-200-4:45217 Node Transitioned from NEW to RUNNING
2013-08-07 03:17:13,286 INFO org.apache.hadoop.yarn.server.resourcemanager.rmnode.RMNodeImpl: hadoop-200-5:34756 Node Transitioned from NEW to RUNNING
2013-08-07 03:17:13,286 INFO org.apache.hadoop.yarn.server.resourcemanager.rmnode.RMNodeImpl: hadoop-200-7:47421 Node Transitioned from NEW to RUNNING
2013-08-07 03:17:13,287 INFO org.apache.hadoop.yarn.server.resourcemanager.rmnode.RMNodeImpl: hadoop-200-3:52180 Node Transitioned from NEW to RUNNING
2013-08-07 03:17:13,288 INFO org.apache.hadoop.yarn.server.resourcemanager.rmnode.RMNodeImpl: hadoop-200-6:45851 Node Transitioned from NEW to RUNNING
2013-08-07 03:17:13,289 INFO org.apache.hadoop.yarn.server.resourcemanager.rmnode.RMNodeImpl: hadoop-200-2:46099 Node Transitioned from NEW to RUNNING
2013-08-07 03:17:13,293 INFO org.apache.hadoop.yarn.server.resourcemanager.scheduler.capacity.CapacityScheduler: Added node hadoop-200-4:45217 clusterResource: <memory:8192, vCores:16>
2013-08-07 03:17:13,293 INFO org.apache.hadoop.yarn.server.resourcemanager.scheduler.capacity.CapacityScheduler: Added node hadoop-200-5:34756 clusterResource: <memory:16384, vCores:32>
2013-08-07 03:17:13,293 INFO org.apache.hadoop.yarn.server.resourcemanager.scheduler.capacity.CapacityScheduler: Added node hadoop-200-7:47421 clusterResource: <memory:24576, vCores:48>
2013-08-07 03:17:13,294 INFO org.apache.hadoop.yarn.server.resourcemanager.scheduler.capacity.CapacityScheduler: Added node hadoop-200-3:52180 clusterResource: <memory:32768, vCores:64>
2013-08-07 03:17:13,294 INFO org.apache.hadoop.yarn.server.resourcemanager.scheduler.capacity.CapacityScheduler: Added node hadoop-200-6:45851 clusterResource: <memory:40960, vCores:80>
2013-08-07 03:17:13,295 INFO org.apache.hadoop.yarn.server.resourcemanager.scheduler.capacity.CapacityScheduler: Added node hadoop-200-2:46099 clusterResource: <memory:49152, vCores:96>
2013-08-07 03:17:18,375 INFO org.apache.hadoop.yarn.server.resourcemanager.ClientRMService: Allocated new applicationId: 1
2013-08-07 03:17:21,851 INFO org.apache.hadoop.yarn.server.resourcemanager.ClientRMService: Storing Application with id application_1375845418464_0001
2013-08-07 03:17:21,856 INFO org.apache.hadoop.yarn.server.resourcemanager.recovery.RMStateStore: Storing info for app: application_1375845418464_0001
2013-08-07 03:17:21,856 INFO org.apache.hadoop.yarn.server.resourcemanager.ClientRMService: Application with id 1 submitted by user ubuntu
2013-08-07 03:17:21,860 INFO org.apache.hadoop.yarn.server.resourcemanager.RMAuditLogger: USER=ubuntu	IP=192.168.100.5	OPERATION=Submit Application Request	TARGET=ClientRMService	RESULT=SUCCESS	APPID=application_1375845418464_0001
2013-08-07 03:17:21,901 INFO org.apache.hadoop.yarn.server.resourcemanager.rmapp.RMAppImpl: application_1375845418464_0001 State change from NEW to SUBMITTED
2013-08-07 03:17:21,902 INFO org.apache.hadoop.yarn.server.resourcemanager.ApplicationMasterService: Registering appattempt_1375845418464_0001_000001
2013-08-07 03:17:21,903 INFO org.apache.hadoop.yarn.server.resourcemanager.rmapp.attempt.RMAppAttemptImpl: appattempt_1375845418464_0001_000001 State change from NEW to SUBMITTED
2013-08-07 03:17:21,937 INFO org.apache.hadoop.yarn.server.resourcemanager.scheduler.capacity.LeafQueue: Application application_1375845418464_0001 from user: ubuntu activated in queue: default
2013-08-07 03:17:21,937 INFO org.apache.hadoop.yarn.server.resourcemanager.scheduler.capacity.LeafQueue: Application added - appId: application_1375845418464_0001 user: org.apache.hadoop.yarn.server.resourcemanager.scheduler.capacity.LeafQueue$User@37101d13, leaf-queue: default #user-pending-applications: 0 #user-active-applications: 1 #queue-pending-applications: 0 #queue-active-applications: 1
2013-08-07 03:17:21,937 INFO org.apache.hadoop.yarn.server.resourcemanager.scheduler.capacity.ParentQueue: Application added - appId: application_1375845418464_0001 user: ubuntu leaf-queue of parent: root #applications: 1
2013-08-07 03:17:21,938 INFO org.apache.hadoop.yarn.server.resourcemanager.scheduler.capacity.CapacityScheduler: Application Submission: appattempt_1375845418464_0001_000001, user: ubuntu queue: default: capacity=1.0, absoluteCapacity=1.0, usedResources=<memory:0, vCores:0>usedCapacity=0.0, absoluteUsedCapacity=0.0, numApps=1, numContainers=0, currently active: 1
2013-08-07 03:17:21,944 INFO org.apache.hadoop.yarn.server.resourcemanager.rmapp.attempt.RMAppAttemptImpl: appattempt_1375845418464_0001_000001 State change from SUBMITTED to SCHEDULED
2013-08-07 03:17:21,944 INFO org.apache.hadoop.yarn.server.resourcemanager.rmapp.RMAppImpl: application_1375845418464_0001 State change from SUBMITTED to ACCEPTED
2013-08-07 03:17:22,457 INFO org.apache.hadoop.yarn.server.resourcemanager.rmcontainer.RMContainerImpl: container_1375845418464_0001_01_000001 Container Transitioned from NEW to ALLOCATED
2013-08-07 03:17:22,458 INFO org.apache.hadoop.yarn.server.resourcemanager.RMAuditLogger: USER=ubuntu	OPERATION=AM Allocated Container	TARGET=SchedulerApp	RESULT=SUCCESS	APPID=application_1375845418464_0001	CONTAINERID=container_1375845418464_0001_01_000001
2013-08-07 03:17:22,459 INFO org.apache.hadoop.yarn.server.resourcemanager.scheduler.common.fica.FiCaSchedulerNode: Assigned container container_1375845418464_0001_01_000001 of capacity <memory:2048, vCores:1> on host hadoop-200-2:46099, which currently has 1 containers, <memory:2048, vCores:1> used and <memory:6144, vCores:15> available
2013-08-07 03:17:22,465 INFO org.apache.hadoop.yarn.server.resourcemanager.scheduler.capacity.LeafQueue: assignedContainer application=application_1375845418464_0001 container=Container: [ContainerId: container_1375845418464_0001_01_000001, NodeId: hadoop-200-2:46099, NodeHttpAddress: hadoop-200-2:8042, Resource: <memory:2048, vCores:1>, Priority: 0, State: NEW, Token: null, Status: container_id {, app_attempt_id {, application_id {, id: 1, cluster_timestamp: 1375845418464, }, attemptId: 1, }, id: 1, }, state: C_NEW, ] containerId=container_1375845418464_0001_01_000001 queue=default: capacity=1.0, absoluteCapacity=1.0, usedResources=<memory:0, vCores:0>usedCapacity=0.0, absoluteUsedCapacity=0.0, numApps=1, numContainers=0 usedCapacity=0.0 absoluteUsedCapacity=0.0 used=<memory:0, vCores:0> cluster=<memory:49152, vCores:96>
2013-08-07 03:17:22,465 INFO org.apache.hadoop.yarn.server.resourcemanager.scheduler.capacity.ParentQueue: Re-sorting queues since queue: root.default stats: default: capacity=1.0, absoluteCapacity=1.0, usedResources=<memory:2048, vCores:1>usedCapacity=0.041666668, absoluteUsedCapacity=0.041666668, numApps=1, numContainers=1
2013-08-07 03:17:22,466 INFO org.apache.hadoop.yarn.server.resourcemanager.scheduler.capacity.ParentQueue: assignedContainer queue=root usedCapacity=0.041666668 absoluteUsedCapacity=0.041666668 used=<memory:2048, vCores:1> cluster=<memory:49152, vCores:96>
2013-08-07 03:17:22,470 INFO org.apache.hadoop.yarn.server.resourcemanager.rmcontainer.RMContainerImpl: container_1375845418464_0001_01_000001 Container Transitioned from ALLOCATED to ACQUIRED
2013-08-07 03:17:22,473 INFO org.apache.hadoop.yarn.server.resourcemanager.rmapp.attempt.RMAppAttemptImpl: Storing attempt: AppId: application_1375845418464_0001 AttemptId: appattempt_1375845418464_0001_000001 MasterContainer: Container: [ContainerId: container_1375845418464_0001_01_000001, NodeId: hadoop-200-2:46099, NodeHttpAddress: hadoop-200-2:8042, Resource: <memory:2048, vCores:1>, Priority: 0, State: NEW, Token: null, Status: container_id {, app_attempt_id {, application_id {, id: 1, cluster_timestamp: 1375845418464, }, attemptId: 1, }, id: 1, }, state: C_NEW, ]
2013-08-07 03:17:22,476 INFO org.apache.hadoop.yarn.server.resourcemanager.rmapp.attempt.RMAppAttemptImpl: appattempt_1375845418464_0001_000001 State change from SCHEDULED to ALLOCATED_SAVING
2013-08-07 03:17:22,480 INFO org.apache.hadoop.yarn.server.resourcemanager.recovery.RMStateStore: Storing info for attempt: appattempt_1375845418464_0001_000001
2013-08-07 03:17:22,484 INFO org.apache.hadoop.yarn.server.resourcemanager.rmapp.attempt.RMAppAttemptImpl: appattempt_1375845418464_0001_000001 State change from ALLOCATED_SAVING to ALLOCATED
2013-08-07 03:17:22,491 INFO org.apache.hadoop.yarn.server.resourcemanager.amlauncher.AMLauncher: Launching masterappattempt_1375845418464_0001_000001
2013-08-07 03:17:22,534 INFO org.apache.hadoop.yarn.server.resourcemanager.amlauncher.AMLauncher: Setting up container Container: [ContainerId: container_1375845418464_0001_01_000001, NodeId: hadoop-200-2:46099, NodeHttpAddress: hadoop-200-2:8042, Resource: <memory:2048, vCores:1>, Priority: 0, State: NEW, Token: null, Status: container_id {, app_attempt_id {, application_id {, id: 1, cluster_timestamp: 1375845418464, }, attemptId: 1, }, id: 1, }, state: C_NEW, ] for AM appattempt_1375845418464_0001_000001
2013-08-07 03:17:22,534 INFO org.apache.hadoop.yarn.server.resourcemanager.amlauncher.AMLauncher: Command to launch container container_1375845418464_0001_01_000001 : $JAVA_HOME/bin/java -Dlog4j.configuration=container-log4j.properties -Dyarn.app.mapreduce.container.log.dir=<LOG_DIR> -Dyarn.app.mapreduce.container.log.filesize=0 -Dhadoop.root.logger=INFO,CLA  -Xmx1024m org.apache.hadoop.mapreduce.v2.app.MRAppMaster 1><LOG_DIR>/stdout 2><LOG_DIR>/stderr 
2013-08-07 03:17:23,468 INFO org.apache.hadoop.yarn.server.resourcemanager.rmcontainer.RMContainerImpl: container_1375845418464_0001_01_000001 Container Transitioned from ACQUIRED to RUNNING
2013-08-07 03:17:23,470 INFO org.apache.hadoop.yarn.server.resourcemanager.amlauncher.AMLauncher: Done launching container Container: [ContainerId: container_1375845418464_0001_01_000001, NodeId: hadoop-200-2:46099, NodeHttpAddress: hadoop-200-2:8042, Resource: <memory:2048, vCores:1>, Priority: 0, State: NEW, Token: null, Status: container_id {, app_attempt_id {, application_id {, id: 1, cluster_timestamp: 1375845418464, }, attemptId: 1, }, id: 1, }, state: C_NEW, ] for AM appattempt_1375845418464_0001_000001
2013-08-07 03:17:23,471 INFO org.apache.hadoop.yarn.server.resourcemanager.rmapp.attempt.RMAppAttemptImpl: appattempt_1375845418464_0001_000001 State change from ALLOCATED to LAUNCHED
2013-08-07 03:17:31,682 INFO org.apache.hadoop.yarn.server.resourcemanager.ApplicationMasterService: AM registration appattempt_1375845418464_0001_000001
2013-08-07 03:17:31,684 INFO org.apache.hadoop.yarn.server.resourcemanager.RMAuditLogger: USER=ubuntu	IP=192.168.100.6	OPERATION=Register App Master	TARGET=ApplicationMasterService	RESULT=SUCCESS	APPID=application_1375845418464_0001	APPATTEMPTID=appattempt_1375845418464_0001_000001
2013-08-07 03:17:31,689 INFO org.apache.hadoop.yarn.server.resourcemanager.rmapp.attempt.RMAppAttemptImpl: appattempt_1375845418464_0001_000001 State change from LAUNCHED to RUNNING
2013-08-07 03:17:31,689 INFO org.apache.hadoop.yarn.server.resourcemanager.rmapp.RMAppImpl: application_1375845418464_0001 State change from ACCEPTED to RUNNING
2013-08-07 03:17:33,472 INFO org.apache.hadoop.yarn.server.resourcemanager.rmcontainer.RMContainerImpl: container_1375845418464_0001_01_000002 Container Transitioned from NEW to ALLOCATED
2013-08-07 03:17:33,472 INFO org.apache.hadoop.yarn.server.resourcemanager.RMAuditLogger: USER=ubuntu	OPERATION=AM Allocated Container	TARGET=SchedulerApp	RESULT=SUCCESS	APPID=application_1375845418464_0001	CONTAINERID=container_1375845418464_0001_01_000002
2013-08-07 03:17:33,473 INFO org.apache.hadoop.yarn.server.resourcemanager.scheduler.common.fica.FiCaSchedulerNode: Assigned container container_1375845418464_0001_01_000002 of capacity <memory:1024, vCores:1> on host hadoop-200-5:34756, which currently has 1 containers, <memory:1024, vCores:1> used and <memory:7168, vCores:15> available
2013-08-07 03:17:33,475 INFO org.apache.hadoop.yarn.server.resourcemanager.scheduler.capacity.LeafQueue: assignedContainer application=application_1375845418464_0001 container=Container: [ContainerId: container_1375845418464_0001_01_000002, NodeId: hadoop-200-5:34756, NodeHttpAddress: hadoop-200-5:8042, Resource: <memory:1024, vCores:1>, Priority: 20, State: NEW, Token: null, Status: container_id {, app_attempt_id {, application_id {, id: 1, cluster_timestamp: 1375845418464, }, attemptId: 1, }, id: 2, }, state: C_NEW, ] containerId=container_1375845418464_0001_01_000002 queue=default: capacity=1.0, absoluteCapacity=1.0, usedResources=<memory:2048, vCores:1>usedCapacity=0.041666668, absoluteUsedCapacity=0.041666668, numApps=1, numContainers=1 usedCapacity=0.041666668 absoluteUsedCapacity=0.041666668 used=<memory:2048, vCores:1> cluster=<memory:49152, vCores:96>
2013-08-07 03:17:33,475 INFO org.apache.hadoop.yarn.server.resourcemanager.scheduler.capacity.ParentQueue: Re-sorting queues since queue: root.default stats: default: capacity=1.0, absoluteCapacity=1.0, usedResources=<memory:3072, vCores:2>usedCapacity=0.0625, absoluteUsedCapacity=0.0625, numApps=1, numContainers=2
2013-08-07 03:17:33,475 INFO org.apache.hadoop.yarn.server.resourcemanager.scheduler.capacity.ParentQueue: assignedContainer queue=root usedCapacity=0.0625 absoluteUsedCapacity=0.0625 used=<memory:3072, vCores:2> cluster=<memory:49152, vCores:96>
2013-08-07 03:17:33,483 INFO org.apache.hadoop.yarn.server.resourcemanager.rmcontainer.RMContainerImpl: container_1375845418464_0001_01_000003 Container Transitioned from NEW to ALLOCATED
2013-08-07 03:17:33,483 INFO org.apache.hadoop.yarn.server.resourcemanager.RMAuditLogger: USER=ubuntu	OPERATION=AM Allocated Container	TARGET=SchedulerApp	RESULT=SUCCESS	APPID=application_1375845418464_0001	CONTAINERID=container_1375845418464_0001_01_000003
2013-08-07 03:17:33,483 INFO org.apache.hadoop.yarn.server.resourcemanager.scheduler.common.fica.FiCaSchedulerNode: Assigned container container_1375845418464_0001_01_000003 of capacity <memory:1024, vCores:1> on host hadoop-200-7:47421, which currently has 1 containers, <memory:1024, vCores:1> used and <memory:7168, vCores:15> available
2013-08-07 03:17:33,485 INFO org.apache.hadoop.yarn.server.resourcemanager.scheduler.capacity.LeafQueue: assignedContainer application=application_1375845418464_0001 container=Container: [ContainerId: container_1375845418464_0001_01_000003, NodeId: hadoop-200-7:47421, NodeHttpAddress: hadoop-200-7:8042, Resource: <memory:1024, vCores:1>, Priority: 20, State: NEW, Token: null, Status: container_id {, app_attempt_id {, application_id {, id: 1, cluster_timestamp: 1375845418464, }, attemptId: 1, }, id: 3, }, state: C_NEW, ] containerId=container_1375845418464_0001_01_000003 queue=default: capacity=1.0, absoluteCapacity=1.0, usedResources=<memory:3072, vCores:2>usedCapacity=0.0625, absoluteUsedCapacity=0.0625, numApps=1, numContainers=2 usedCapacity=0.0625 absoluteUsedCapacity=0.0625 used=<memory:3072, vCores:2> cluster=<memory:49152, vCores:96>
2013-08-07 03:17:33,485 INFO org.apache.hadoop.yarn.server.resourcemanager.scheduler.capacity.ParentQueue: Re-sorting queues since queue: root.default stats: default: capacity=1.0, absoluteCapacity=1.0, usedResources=<memory:4096, vCores:3>usedCapacity=0.083333336, absoluteUsedCapacity=0.083333336, numApps=1, numContainers=3
2013-08-07 03:17:33,485 INFO org.apache.hadoop.yarn.server.resourcemanager.scheduler.capacity.ParentQueue: assignedContainer queue=root usedCapacity=0.083333336 absoluteUsedCapacity=0.083333336 used=<memory:4096, vCores:3> cluster=<memory:49152, vCores:96>
2013-08-07 03:17:33,757 INFO org.apache.hadoop.yarn.server.resourcemanager.rmcontainer.RMContainerImpl: container_1375845418464_0001_01_000002 Container Transitioned from ALLOCATED to ACQUIRED
2013-08-07 03:17:33,759 INFO org.apache.hadoop.yarn.server.resourcemanager.rmcontainer.RMContainerImpl: container_1375845418464_0001_01_000003 Container Transitioned from ALLOCATED to ACQUIRED
2013-08-07 03:17:34,802 INFO org.apache.hadoop.yarn.server.resourcemanager.scheduler.AppSchedulingInfo: checking for deactivate... 
2013-08-07 03:17:35,569 INFO org.apache.hadoop.yarn.server.resourcemanager.rmcontainer.RMContainerImpl: container_1375845418464_0001_01_000003 Container Transitioned from ACQUIRED to RUNNING
2013-08-07 03:17:35,573 INFO org.apache.hadoop.yarn.server.resourcemanager.rmcontainer.RMContainerImpl: container_1375845418464_0001_01_000002 Container Transitioned from ACQUIRED to RUNNING
2013-08-07 03:19:24,699 INFO org.apache.hadoop.yarn.server.resourcemanager.rmcontainer.RMContainerImpl: container_1375845418464_0001_01_000003 Container Transitioned from RUNNING to COMPLETED
2013-08-07 03:19:24,699 INFO org.apache.hadoop.yarn.server.resourcemanager.scheduler.common.fica.FiCaSchedulerApp: Completed container: container_1375845418464_0001_01_000003 in state: COMPLETED event:FINISHED
2013-08-07 03:19:24,699 INFO org.apache.hadoop.yarn.server.resourcemanager.RMAuditLogger: USER=ubuntu	OPERATION=AM Released Container	TARGET=SchedulerApp	RESULT=SUCCESS	APPID=application_1375845418464_0001	CONTAINERID=container_1375845418464_0001_01_000003
2013-08-07 03:19:24,700 INFO org.apache.hadoop.yarn.server.resourcemanager.scheduler.common.fica.FiCaSchedulerNode: Released container container_1375845418464_0001_01_000003 of capacity <memory:1024, vCores:1> on host hadoop-200-7:47421, which currently has 0 containers, <memory:0, vCores:0> used and <memory:8192, vCores:16> available, release resources=true
2013-08-07 03:19:24,700 INFO org.apache.hadoop.yarn.server.resourcemanager.scheduler.capacity.LeafQueue: default used=<memory:3072, vCores:2> numContainers=2 user=ubuntu user-resources=<memory:3072, vCores:2>
2013-08-07 03:19:24,702 INFO org.apache.hadoop.yarn.server.resourcemanager.scheduler.capacity.LeafQueue: completedContainer container=Container: [ContainerId: container_1375845418464_0001_01_000003, NodeId: hadoop-200-7:47421, NodeHttpAddress: hadoop-200-7:8042, Resource: <memory:1024, vCores:1>, Priority: 20, State: NEW, Token: null, Status: container_id {, app_attempt_id {, application_id {, id: 1, cluster_timestamp: 1375845418464, }, attemptId: 1, }, id: 3, }, state: C_COMPLETE, diagnostics: "Container killed by the ApplicationMaster.\n\n", exit_status: 143, ] resource=<memory:1024, vCores:1> queue=default: capacity=1.0, absoluteCapacity=1.0, usedResources=<memory:3072, vCores:2>usedCapacity=0.0625, absoluteUsedCapacity=0.0625, numApps=1, numContainers=2 usedCapacity=0.0625 absoluteUsedCapacity=0.0625 used=<memory:3072, vCores:2> cluster=<memory:49152, vCores:96>
2013-08-07 03:19:24,703 INFO org.apache.hadoop.yarn.server.resourcemanager.scheduler.capacity.ParentQueue: completedContainer queue=root usedCapacity=0.0625 absoluteUsedCapacity=0.0625 used=<memory:3072, vCores:2> cluster=<memory:49152, vCores:96>
2013-08-07 03:19:24,703 INFO org.apache.hadoop.yarn.server.resourcemanager.scheduler.capacity.CapacityScheduler: Application appattempt_1375845418464_0001_000001 released container container_1375845418464_0001_01_000003 on node: host: hadoop-200-7:47421 #containers=0 available=8192 used=0 with event: FINISHED
2013-08-07 03:19:31,414 INFO org.apache.hadoop.yarn.server.resourcemanager.rmcontainer.RMContainerImpl: container_1375845418464_0001_01_000002 Container Transitioned from RUNNING to COMPLETED
2013-08-07 03:19:31,415 INFO org.apache.hadoop.yarn.server.resourcemanager.scheduler.common.fica.FiCaSchedulerApp: Completed container: container_1375845418464_0001_01_000002 in state: COMPLETED event:FINISHED
2013-08-07 03:19:31,415 INFO org.apache.hadoop.yarn.server.resourcemanager.RMAuditLogger: USER=ubuntu	OPERATION=AM Released Container	TARGET=SchedulerApp	RESULT=SUCCESS	APPID=application_1375845418464_0001	CONTAINERID=container_1375845418464_0001_01_000002
2013-08-07 03:19:31,415 INFO org.apache.hadoop.yarn.server.resourcemanager.scheduler.common.fica.FiCaSchedulerNode: Released container container_1375845418464_0001_01_000002 of capacity <memory:1024, vCores:1> on host hadoop-200-5:34756, which currently has 0 containers, <memory:0, vCores:0> used and <memory:8192, vCores:16> available, release resources=true
2013-08-07 03:19:31,415 INFO org.apache.hadoop.yarn.server.resourcemanager.scheduler.capacity.LeafQueue: default used=<memory:2048, vCores:1> numContainers=1 user=ubuntu user-resources=<memory:2048, vCores:1>
2013-08-07 03:19:31,417 INFO org.apache.hadoop.yarn.server.resourcemanager.scheduler.capacity.LeafQueue: completedContainer container=Container: [ContainerId: container_1375845418464_0001_01_000002, NodeId: hadoop-200-5:34756, NodeHttpAddress: hadoop-200-5:8042, Resource: <memory:1024, vCores:1>, Priority: 20, State: NEW, Token: null, Status: container_id {, app_attempt_id {, application_id {, id: 1, cluster_timestamp: 1375845418464, }, attemptId: 1, }, id: 2, }, state: C_COMPLETE, diagnostics: "Container killed by the ApplicationMaster.\n\n", exit_status: 143, ] resource=<memory:1024, vCores:1> queue=default: capacity=1.0, absoluteCapacity=1.0, usedResources=<memory:2048, vCores:1>usedCapacity=0.041666668, absoluteUsedCapacity=0.041666668, numApps=1, numContainers=1 usedCapacity=0.041666668 absoluteUsedCapacity=0.041666668 used=<memory:2048, vCores:1> cluster=<memory:49152, vCores:96>
2013-08-07 03:19:31,417 INFO org.apache.hadoop.yarn.server.resourcemanager.scheduler.capacity.ParentQueue: completedContainer queue=root usedCapacity=0.041666668 absoluteUsedCapacity=0.041666668 used=<memory:2048, vCores:1> cluster=<memory:49152, vCores:96>
2013-08-07 03:19:31,418 INFO org.apache.hadoop.yarn.server.resourcemanager.scheduler.capacity.CapacityScheduler: Application appattempt_1375845418464_0001_000001 released container container_1375845418464_0001_01_000002 on node: host: hadoop-200-5:34756 #containers=0 available=8192 used=0 with event: FINISHED
2013-08-07 03:19:35,588 INFO org.apache.hadoop.yarn.server.resourcemanager.rmapp.attempt.RMAppAttemptImpl: appattempt_1375845418464_0001_000001 State change from RUNNING to FINISHING
2013-08-07 03:19:35,589 INFO org.apache.hadoop.yarn.server.resourcemanager.rmapp.RMAppImpl: application_1375845418464_0001 State change from RUNNING to FINISHING
2013-08-07 03:19:36,238 INFO org.apache.hadoop.yarn.server.resourcemanager.rmcontainer.RMContainerImpl: container_1375845418464_0001_01_000001 Container Transitioned from RUNNING to COMPLETED
2013-08-07 03:19:36,238 INFO org.apache.hadoop.yarn.server.resourcemanager.scheduler.common.fica.FiCaSchedulerApp: Completed container: container_1375845418464_0001_01_000001 in state: COMPLETED event:FINISHED
2013-08-07 03:19:36,238 INFO org.apache.hadoop.yarn.server.resourcemanager.RMAuditLogger: USER=ubuntu	OPERATION=AM Released Container	TARGET=SchedulerApp	RESULT=SUCCESS	APPID=application_1375845418464_0001	CONTAINERID=container_1375845418464_0001_01_000001
2013-08-07 03:19:36,239 INFO org.apache.hadoop.yarn.server.resourcemanager.scheduler.common.fica.FiCaSchedulerNode: Released container container_1375845418464_0001_01_000001 of capacity <memory:2048, vCores:1> on host hadoop-200-2:46099, which currently has 0 containers, <memory:0, vCores:0> used and <memory:8192, vCores:16> available, release resources=true
2013-08-07 03:19:36,239 INFO org.apache.hadoop.yarn.server.resourcemanager.scheduler.capacity.LeafQueue: default used=<memory:0, vCores:0> numContainers=0 user=ubuntu user-resources=<memory:0, vCores:0>
2013-08-07 03:19:36,241 INFO org.apache.hadoop.yarn.server.resourcemanager.scheduler.capacity.LeafQueue: completedContainer container=Container: [ContainerId: container_1375845418464_0001_01_000001, NodeId: hadoop-200-2:46099, NodeHttpAddress: hadoop-200-2:8042, Resource: <memory:2048, vCores:1>, Priority: 0, State: NEW, Token: null, Status: container_id {, app_attempt_id {, application_id {, id: 1, cluster_timestamp: 1375845418464, }, attemptId: 1, }, id: 1, }, state: C_COMPLETE, diagnostics: "", exit_status: 0, ] resource=<memory:2048, vCores:1> queue=default: capacity=1.0, absoluteCapacity=1.0, usedResources=<memory:0, vCores:0>usedCapacity=0.0, absoluteUsedCapacity=0.0, numApps=1, numContainers=0 usedCapacity=0.0 absoluteUsedCapacity=0.0 used=<memory:0, vCores:0> cluster=<memory:49152, vCores:96>
2013-08-07 03:19:36,241 INFO org.apache.hadoop.yarn.server.resourcemanager.scheduler.capacity.ParentQueue: completedContainer queue=root usedCapacity=0.0 absoluteUsedCapacity=0.0 used=<memory:0, vCores:0> cluster=<memory:49152, vCores:96>
2013-08-07 03:19:36,241 INFO org.apache.hadoop.yarn.server.resourcemanager.scheduler.capacity.CapacityScheduler: Application appattempt_1375845418464_0001_000001 released container container_1375845418464_0001_01_000001 on node: host: hadoop-200-2:46099 #containers=0 available=8192 used=0 with event: FINISHED
2013-08-07 03:19:36,244 INFO org.apache.hadoop.yarn.server.resourcemanager.rmapp.attempt.RMAppAttemptImpl: appattempt_1375845418464_0001_000001 State change from FINISHING to FINISHED
2013-08-07 03:19:36,247 INFO org.apache.hadoop.yarn.server.resourcemanager.rmapp.RMAppImpl: application_1375845418464_0001 State change from FINISHING to FINISHED
2013-08-07 03:19:36,247 INFO org.apache.hadoop.yarn.server.resourcemanager.scheduler.capacity.CapacityScheduler: Application appattempt_1375845418464_0001_000001 is done. finalState=FINISHED
2013-08-07 03:19:36,248 INFO org.apache.hadoop.yarn.server.resourcemanager.RMAuditLogger: USER=ubuntu	OPERATION=Application Finished - Succeeded	TARGET=RMAppManager	RESULT=SUCCESS	APPID=application_1375845418464_0001
2013-08-07 03:19:36,248 INFO org.apache.hadoop.yarn.server.resourcemanager.amlauncher.AMLauncher: Cleaning master appattempt_1375845418464_0001_000001
2013-08-07 03:19:36,262 INFO org.apache.hadoop.yarn.server.resourcemanager.scheduler.AppSchedulingInfo: Application application_1375845418464_0001 requests cleared
2013-08-07 03:19:36,262 INFO org.apache.hadoop.yarn.server.resourcemanager.scheduler.capacity.LeafQueue: Application removed - appId: application_1375845418464_0001 user: ubuntu queue: default #user-pending-applications: 0 #user-active-applications: 0 #queue-pending-applications: 0 #queue-active-applications: 0
2013-08-07 03:19:36,263 INFO org.apache.hadoop.yarn.server.resourcemanager.scheduler.capacity.ParentQueue: Application removed - appId: application_1375845418464_0001 user: ubuntu leaf-queue of parent: root #applications: 0
2013-08-07 03:19:36,265 INFO org.apache.hadoop.yarn.server.resourcemanager.recovery.RMStateStore: Removing info for app: application_1375845418464_0001
2013-08-07 03:19:36,268 INFO org.apache.hadoop.yarn.server.resourcemanager.RMAppManager$ApplicationSummary: appId=application_1375845418464_0001,name=TeraGen,user=ubuntu,queue=default,state=FINISHED,trackingUrl=hadoop-200-1.novalocal:8088/proxy/application_1375845418464_0001/jobhistory/job/job_1375845418464_0001,appMasterHost=hadoop-200-2,startTime=1375845441844,finishTime=1375845575589
2013-08-07 03:19:37,239 INFO org.apache.hadoop.yarn.server.resourcemanager.ClientRMService: Allocated new applicationId: 2
2013-08-07 03:19:39,157 INFO org.apache.hadoop.yarn.server.resourcemanager.ClientRMService: Storing Application with id application_1375845418464_0002
2013-08-07 03:19:39,157 INFO org.apache.hadoop.yarn.server.resourcemanager.recovery.RMStateStore: Storing info for app: application_1375845418464_0002
2013-08-07 03:19:39,157 INFO org.apache.hadoop.yarn.server.resourcemanager.ClientRMService: Application with id 2 submitted by user ubuntu
2013-08-07 03:19:39,157 INFO org.apache.hadoop.yarn.server.resourcemanager.RMAuditLogger: USER=ubuntu	IP=192.168.100.5	OPERATION=Submit Application Request	TARGET=ClientRMService	RESULT=SUCCESS	APPID=application_1375845418464_0002
2013-08-07 03:19:39,163 INFO org.apache.hadoop.yarn.server.resourcemanager.rmapp.RMAppImpl: application_1375845418464_0002 State change from NEW to SUBMITTED
2013-08-07 03:19:39,163 INFO org.apache.hadoop.yarn.server.resourcemanager.ApplicationMasterService: Registering appattempt_1375845418464_0002_000001
2013-08-07 03:19:39,163 INFO org.apache.hadoop.yarn.server.resourcemanager.rmapp.attempt.RMAppAttemptImpl: appattempt_1375845418464_0002_000001 State change from NEW to SUBMITTED
2013-08-07 03:19:39,164 INFO org.apache.hadoop.yarn.server.resourcemanager.scheduler.capacity.LeafQueue: Application application_1375845418464_0002 from user: ubuntu activated in queue: default
2013-08-07 03:19:39,164 INFO org.apache.hadoop.yarn.server.resourcemanager.scheduler.capacity.LeafQueue: Application added - appId: application_1375845418464_0002 user: org.apache.hadoop.yarn.server.resourcemanager.scheduler.capacity.LeafQueue$User@1885bc7b, leaf-queue: default #user-pending-applications: 0 #user-active-applications: 1 #queue-pending-applications: 0 #queue-active-applications: 1
2013-08-07 03:19:39,164 INFO org.apache.hadoop.yarn.server.resourcemanager.scheduler.capacity.ParentQueue: Application added - appId: application_1375845418464_0002 user: ubuntu leaf-queue of parent: root #applications: 1
2013-08-07 03:19:39,164 INFO org.apache.hadoop.yarn.server.resourcemanager.scheduler.capacity.CapacityScheduler: Application Submission: appattempt_1375845418464_0002_000001, user: ubuntu queue: default: capacity=1.0, absoluteCapacity=1.0, usedResources=<memory:0, vCores:0>usedCapacity=0.0, absoluteUsedCapacity=0.0, numApps=1, numContainers=0, currently active: 1
2013-08-07 03:19:39,165 INFO org.apache.hadoop.yarn.server.resourcemanager.rmapp.attempt.RMAppAttemptImpl: appattempt_1375845418464_0002_000001 State change from SUBMITTED to SCHEDULED
2013-08-07 03:19:39,165 INFO org.apache.hadoop.yarn.server.resourcemanager.rmapp.RMAppImpl: application_1375845418464_0002 State change from SUBMITTED to ACCEPTED
2013-08-07 03:19:39,253 INFO org.apache.hadoop.yarn.server.resourcemanager.rmcontainer.RMContainerImpl: container_1375845418464_0002_01_000001 Container Transitioned from NEW to ALLOCATED
2013-08-07 03:19:39,253 INFO org.apache.hadoop.yarn.server.resourcemanager.RMAuditLogger: USER=ubuntu	OPERATION=AM Allocated Container	TARGET=SchedulerApp	RESULT=SUCCESS	APPID=application_1375845418464_0002	CONTAINERID=container_1375845418464_0002_01_000001
2013-08-07 03:19:39,253 INFO org.apache.hadoop.yarn.server.resourcemanager.scheduler.common.fica.FiCaSchedulerNode: Assigned container container_1375845418464_0002_01_000001 of capacity <memory:2048, vCores:1> on host hadoop-200-2:46099, which currently has 1 containers, <memory:2048, vCores:1> used and <memory:6144, vCores:15> available
2013-08-07 03:19:39,255 INFO org.apache.hadoop.yarn.server.resourcemanager.scheduler.capacity.LeafQueue: assignedContainer application=application_1375845418464_0002 container=Container: [ContainerId: container_1375845418464_0002_01_000001, NodeId: hadoop-200-2:46099, NodeHttpAddress: hadoop-200-2:8042, Resource: <memory:2048, vCores:1>, Priority: 0, State: NEW, Token: null, Status: container_id {, app_attempt_id {, application_id {, id: 2, cluster_timestamp: 1375845418464, }, attemptId: 1, }, id: 1, }, state: C_NEW, ] containerId=container_1375845418464_0002_01_000001 queue=default: capacity=1.0, absoluteCapacity=1.0, usedResources=<memory:0, vCores:0>usedCapacity=0.0, absoluteUsedCapacity=0.0, numApps=1, numContainers=0 usedCapacity=0.0 absoluteUsedCapacity=0.0 used=<memory:0, vCores:0> cluster=<memory:49152, vCores:96>
2013-08-07 03:19:39,255 INFO org.apache.hadoop.yarn.server.resourcemanager.scheduler.capacity.ParentQueue: Re-sorting queues since queue: root.default stats: default: capacity=1.0, absoluteCapacity=1.0, usedResources=<memory:2048, vCores:1>usedCapacity=0.041666668, absoluteUsedCapacity=0.041666668, numApps=1, numContainers=1
2013-08-07 03:19:39,255 INFO org.apache.hadoop.yarn.server.resourcemanager.scheduler.capacity.ParentQueue: assignedContainer queue=root usedCapacity=0.041666668 absoluteUsedCapacity=0.041666668 used=<memory:2048, vCores:1> cluster=<memory:49152, vCores:96>
2013-08-07 03:19:39,257 INFO org.apache.hadoop.yarn.server.resourcemanager.rmcontainer.RMContainerImpl: container_1375845418464_0002_01_000001 Container Transitioned from ALLOCATED to ACQUIRED
2013-08-07 03:19:39,259 INFO org.apache.hadoop.yarn.server.resourcemanager.rmapp.attempt.RMAppAttemptImpl: Storing attempt: AppId: application_1375845418464_0002 AttemptId: appattempt_1375845418464_0002_000001 MasterContainer: Container: [ContainerId: container_1375845418464_0002_01_000001, NodeId: hadoop-200-2:46099, NodeHttpAddress: hadoop-200-2:8042, Resource: <memory:2048, vCores:1>, Priority: 0, State: NEW, Token: null, Status: container_id {, app_attempt_id {, application_id {, id: 2, cluster_timestamp: 1375845418464, }, attemptId: 1, }, id: 1, }, state: C_NEW, ]
2013-08-07 03:19:39,259 INFO org.apache.hadoop.yarn.server.resourcemanager.rmapp.attempt.RMAppAttemptImpl: appattempt_1375845418464_0002_000001 State change from SCHEDULED to ALLOCATED_SAVING
2013-08-07 03:19:39,259 INFO org.apache.hadoop.yarn.server.resourcemanager.recovery.RMStateStore: Storing info for attempt: appattempt_1375845418464_0002_000001
2013-08-07 03:19:39,260 INFO org.apache.hadoop.yarn.server.resourcemanager.rmapp.attempt.RMAppAttemptImpl: appattempt_1375845418464_0002_000001 State change from ALLOCATED_SAVING to ALLOCATED
2013-08-07 03:19:39,265 INFO org.apache.hadoop.yarn.server.resourcemanager.amlauncher.AMLauncher: Launching masterappattempt_1375845418464_0002_000001
2013-08-07 03:19:39,268 INFO org.apache.hadoop.yarn.server.resourcemanager.amlauncher.AMLauncher: Setting up container Container: [ContainerId: container_1375845418464_0002_01_000001, NodeId: hadoop-200-2:46099, NodeHttpAddress: hadoop-200-2:8042, Resource: <memory:2048, vCores:1>, Priority: 0, State: NEW, Token: null, Status: container_id {, app_attempt_id {, application_id {, id: 2, cluster_timestamp: 1375845418464, }, attemptId: 1, }, id: 1, }, state: C_NEW, ] for AM appattempt_1375845418464_0002_000001
2013-08-07 03:19:39,268 INFO org.apache.hadoop.yarn.server.resourcemanager.amlauncher.AMLauncher: Command to launch container container_1375845418464_0002_01_000001 : $JAVA_HOME/bin/java -Dlog4j.configuration=container-log4j.properties -Dyarn.app.mapreduce.container.log.dir=<LOG_DIR> -Dyarn.app.mapreduce.container.log.filesize=0 -Dhadoop.root.logger=INFO,CLA  -Xmx1024m org.apache.hadoop.mapreduce.v2.app.MRAppMaster 1><LOG_DIR>/stdout 2><LOG_DIR>/stderr 
2013-08-07 03:19:39,283 INFO org.apache.hadoop.yarn.server.resourcemanager.amlauncher.AMLauncher: Done launching container Container: [ContainerId: container_1375845418464_0002_01_000001, NodeId: hadoop-200-2:46099, NodeHttpAddress: hadoop-200-2:8042, Resource: <memory:2048, vCores:1>, Priority: 0, State: NEW, Token: null, Status: container_id {, app_attempt_id {, application_id {, id: 2, cluster_timestamp: 1375845418464, }, attemptId: 1, }, id: 1, }, state: C_NEW, ] for AM appattempt_1375845418464_0002_000001
2013-08-07 03:19:39,284 INFO org.apache.hadoop.yarn.server.resourcemanager.rmapp.attempt.RMAppAttemptImpl: appattempt_1375845418464_0002_000001 State change from ALLOCATED to LAUNCHED
2013-08-07 03:19:40,258 INFO org.apache.hadoop.yarn.server.resourcemanager.rmcontainer.RMContainerImpl: container_1375845418464_0002_01_000001 Container Transitioned from ACQUIRED to RUNNING
2013-08-07 03:19:43,817 INFO org.apache.hadoop.yarn.server.resourcemanager.ApplicationMasterService: AM registration appattempt_1375845418464_0002_000001
2013-08-07 03:19:43,817 INFO org.apache.hadoop.yarn.server.resourcemanager.RMAuditLogger: USER=ubuntu	IP=192.168.100.6	OPERATION=Register App Master	TARGET=ApplicationMasterService	RESULT=SUCCESS	APPID=application_1375845418464_0002	APPATTEMPTID=appattempt_1375845418464_0002_000001
2013-08-07 03:19:43,821 INFO org.apache.hadoop.yarn.server.resourcemanager.rmapp.attempt.RMAppAttemptImpl: appattempt_1375845418464_0002_000001 State change from LAUNCHED to RUNNING
2013-08-07 03:19:43,821 INFO org.apache.hadoop.yarn.server.resourcemanager.rmapp.RMAppImpl: application_1375845418464_0002 State change from ACCEPTED to RUNNING
2013-08-07 03:19:45,019 INFO org.apache.hadoop.yarn.server.resourcemanager.rmcontainer.RMContainerImpl: container_1375845418464_0002_01_000002 Container Transitioned from NEW to ALLOCATED
2013-08-07 03:19:45,020 INFO org.apache.hadoop.yarn.server.resourcemanager.RMAuditLogger: USER=ubuntu	OPERATION=AM Allocated Container	TARGET=SchedulerApp	RESULT=SUCCESS	APPID=application_1375845418464_0002	CONTAINERID=container_1375845418464_0002_01_000002
2013-08-07 03:19:45,020 INFO org.apache.hadoop.yarn.server.resourcemanager.scheduler.common.fica.FiCaSchedulerNode: Assigned container container_1375845418464_0002_01_000002 of capacity <memory:1024, vCores:1> on host hadoop-200-3:52180, which currently has 1 containers, <memory:1024, vCores:1> used and <memory:7168, vCores:15> available
2013-08-07 03:19:45,022 INFO org.apache.hadoop.yarn.server.resourcemanager.scheduler.capacity.LeafQueue: assignedContainer application=application_1375845418464_0002 container=Container: [ContainerId: container_1375845418464_0002_01_000002, NodeId: hadoop-200-3:52180, NodeHttpAddress: hadoop-200-3:8042, Resource: <memory:1024, vCores:1>, Priority: 20, State: NEW, Token: null, Status: container_id {, app_attempt_id {, application_id {, id: 2, cluster_timestamp: 1375845418464, }, attemptId: 1, }, id: 2, }, state: C_NEW, ] containerId=container_1375845418464_0002_01_000002 queue=default: capacity=1.0, absoluteCapacity=1.0, usedResources=<memory:2048, vCores:1>usedCapacity=0.041666668, absoluteUsedCapacity=0.041666668, numApps=1, numContainers=1 usedCapacity=0.041666668 absoluteUsedCapacity=0.041666668 used=<memory:2048, vCores:1> cluster=<memory:49152, vCores:96>
2013-08-07 03:19:45,022 INFO org.apache.hadoop.yarn.server.resourcemanager.scheduler.capacity.ParentQueue: Re-sorting queues since queue: root.default stats: default: capacity=1.0, absoluteCapacity=1.0, usedResources=<memory:3072, vCores:2>usedCapacity=0.0625, absoluteUsedCapacity=0.0625, numApps=1, numContainers=2
2013-08-07 03:19:45,022 INFO org.apache.hadoop.yarn.server.resourcemanager.scheduler.capacity.ParentQueue: assignedContainer queue=root usedCapacity=0.0625 absoluteUsedCapacity=0.0625 used=<memory:3072, vCores:2> cluster=<memory:49152, vCores:96>
2013-08-07 03:19:45,028 INFO org.apache.hadoop.yarn.server.resourcemanager.rmcontainer.RMContainerImpl: container_1375845418464_0002_01_000003 Container Transitioned from NEW to ALLOCATED
2013-08-07 03:19:45,029 INFO org.apache.hadoop.yarn.server.resourcemanager.RMAuditLogger: USER=ubuntu	OPERATION=AM Allocated Container	TARGET=SchedulerApp	RESULT=SUCCESS	APPID=application_1375845418464_0002	CONTAINERID=container_1375845418464_0002_01_000003
2013-08-07 03:19:45,029 INFO org.apache.hadoop.yarn.server.resourcemanager.scheduler.common.fica.FiCaSchedulerNode: Assigned container container_1375845418464_0002_01_000003 of capacity <memory:1024, vCores:1> on host hadoop-200-4:45217, which currently has 1 containers, <memory:1024, vCores:1> used and <memory:7168, vCores:15> available
2013-08-07 03:19:45,030 INFO org.apache.hadoop.yarn.server.resourcemanager.scheduler.capacity.LeafQueue: assignedContainer application=application_1375845418464_0002 container=Container: [ContainerId: container_1375845418464_0002_01_000003, NodeId: hadoop-200-4:45217, NodeHttpAddress: hadoop-200-4:8042, Resource: <memory:1024, vCores:1>, Priority: 20, State: NEW, Token: null, Status: container_id {, app_attempt_id {, application_id {, id: 2, cluster_timestamp: 1375845418464, }, attemptId: 1, }, id: 3, }, state: C_NEW, ] containerId=container_1375845418464_0002_01_000003 queue=default: capacity=1.0, absoluteCapacity=1.0, usedResources=<memory:3072, vCores:2>usedCapacity=0.0625, absoluteUsedCapacity=0.0625, numApps=1, numContainers=2 usedCapacity=0.0625 absoluteUsedCapacity=0.0625 used=<memory:3072, vCores:2> cluster=<memory:49152, vCores:96>
2013-08-07 03:19:45,031 INFO org.apache.hadoop.yarn.server.resourcemanager.scheduler.capacity.ParentQueue: Re-sorting queues since queue: root.default stats: default: capacity=1.0, absoluteCapacity=1.0, usedResources=<memory:4096, vCores:3>usedCapacity=0.083333336, absoluteUsedCapacity=0.083333336, numApps=1, numContainers=3
2013-08-07 03:19:45,031 INFO org.apache.hadoop.yarn.server.resourcemanager.scheduler.capacity.ParentQueue: assignedContainer queue=root usedCapacity=0.083333336 absoluteUsedCapacity=0.083333336 used=<memory:4096, vCores:3> cluster=<memory:49152, vCores:96>
2013-08-07 03:19:45,862 INFO org.apache.hadoop.yarn.server.resourcemanager.rmcontainer.RMContainerImpl: container_1375845418464_0002_01_000002 Container Transitioned from ALLOCATED to ACQUIRED
2013-08-07 03:19:45,863 INFO org.apache.hadoop.yarn.server.resourcemanager.rmcontainer.RMContainerImpl: container_1375845418464_0002_01_000003 Container Transitioned from ALLOCATED to ACQUIRED
2013-08-07 03:19:46,892 INFO org.apache.hadoop.yarn.server.resourcemanager.scheduler.AppSchedulingInfo: checking for deactivate... 
2013-08-07 03:19:47,051 INFO org.apache.hadoop.yarn.server.resourcemanager.rmcontainer.RMContainerImpl: container_1375845418464_0002_01_000002 Container Transitioned from ACQUIRED to RUNNING
2013-08-07 03:19:47,055 INFO org.apache.hadoop.yarn.server.resourcemanager.rmcontainer.RMContainerImpl: container_1375845418464_0002_01_000003 Container Transitioned from ACQUIRED to RUNNING
2013-08-07 03:21:36,119 INFO org.apache.hadoop.yarn.server.resourcemanager.rmcontainer.RMContainerImpl: container_1375845418464_0002_01_000003 Container Transitioned from RUNNING to COMPLETED
2013-08-07 03:21:36,119 INFO org.apache.hadoop.yarn.server.resourcemanager.scheduler.common.fica.FiCaSchedulerApp: Completed container: container_1375845418464_0002_01_000003 in state: COMPLETED event:FINISHED
2013-08-07 03:21:36,120 INFO org.apache.hadoop.yarn.server.resourcemanager.RMAuditLogger: USER=ubuntu	OPERATION=AM Released Container	TARGET=SchedulerApp	RESULT=SUCCESS	APPID=application_1375845418464_0002	CONTAINERID=container_1375845418464_0002_01_000003
2013-08-07 03:21:36,120 INFO org.apache.hadoop.yarn.server.resourcemanager.scheduler.common.fica.FiCaSchedulerNode: Released container container_1375845418464_0002_01_000003 of capacity <memory:1024, vCores:1> on host hadoop-200-4:45217, which currently has 0 containers, <memory:0, vCores:0> used and <memory:8192, vCores:16> available, release resources=true
2013-08-07 03:21:36,120 INFO org.apache.hadoop.yarn.server.resourcemanager.scheduler.capacity.LeafQueue: default used=<memory:3072, vCores:2> numContainers=2 user=ubuntu user-resources=<memory:3072, vCores:2>
2013-08-07 03:21:36,134 INFO org.apache.hadoop.yarn.server.resourcemanager.scheduler.capacity.LeafQueue: completedContainer container=Container: [ContainerId: container_1375845418464_0002_01_000003, NodeId: hadoop-200-4:45217, NodeHttpAddress: hadoop-200-4:8042, Resource: <memory:1024, vCores:1>, Priority: 20, State: NEW, Token: null, Status: container_id {, app_attempt_id {, application_id {, id: 2, cluster_timestamp: 1375845418464, }, attemptId: 1, }, id: 3, }, state: C_COMPLETE, diagnostics: "Container killed by the ApplicationMaster.\n\n", exit_status: 143, ] resource=<memory:1024, vCores:1> queue=default: capacity=1.0, absoluteCapacity=1.0, usedResources=<memory:3072, vCores:2>usedCapacity=0.0625, absoluteUsedCapacity=0.0625, numApps=1, numContainers=2 usedCapacity=0.0625 absoluteUsedCapacity=0.0625 used=<memory:3072, vCores:2> cluster=<memory:49152, vCores:96>
2013-08-07 03:21:36,134 INFO org.apache.hadoop.yarn.server.resourcemanager.scheduler.capacity.ParentQueue: completedContainer queue=root usedCapacity=0.0625 absoluteUsedCapacity=0.0625 used=<memory:3072, vCores:2> cluster=<memory:49152, vCores:96>
2013-08-07 03:21:36,134 INFO org.apache.hadoop.yarn.server.resourcemanager.scheduler.capacity.CapacityScheduler: Application appattempt_1375845418464_0002_000001 released container container_1375845418464_0002_01_000003 on node: host: hadoop-200-4:45217 #containers=0 available=8192 used=0 with event: FINISHED
2013-08-07 03:21:36,398 INFO org.apache.hadoop.yarn.server.resourcemanager.rmcontainer.RMContainerImpl: container_1375845418464_0002_01_000002 Container Transitioned from RUNNING to COMPLETED
2013-08-07 03:21:36,398 INFO org.apache.hadoop.yarn.server.resourcemanager.scheduler.common.fica.FiCaSchedulerApp: Completed container: container_1375845418464_0002_01_000002 in state: COMPLETED event:FINISHED
2013-08-07 03:21:36,400 INFO org.apache.hadoop.yarn.server.resourcemanager.RMAuditLogger: USER=ubuntu	OPERATION=AM Released Container	TARGET=SchedulerApp	RESULT=SUCCESS	APPID=application_1375845418464_0002	CONTAINERID=container_1375845418464_0002_01_000002
2013-08-07 03:21:36,400 INFO org.apache.hadoop.yarn.server.resourcemanager.scheduler.common.fica.FiCaSchedulerNode: Released container container_1375845418464_0002_01_000002 of capacity <memory:1024, vCores:1> on host hadoop-200-3:52180, which currently has 0 containers, <memory:0, vCores:0> used and <memory:8192, vCores:16> available, release resources=true
2013-08-07 03:21:36,400 INFO org.apache.hadoop.yarn.server.resourcemanager.scheduler.capacity.LeafQueue: default used=<memory:2048, vCores:1> numContainers=1 user=ubuntu user-resources=<memory:2048, vCores:1>
2013-08-07 03:21:36,403 INFO org.apache.hadoop.yarn.server.resourcemanager.scheduler.capacity.LeafQueue: completedContainer container=Container: [ContainerId: container_1375845418464_0002_01_000002, NodeId: hadoop-200-3:52180, NodeHttpAddress: hadoop-200-3:8042, Resource: <memory:1024, vCores:1>, Priority: 20, State: NEW, Token: null, Status: container_id {, app_attempt_id {, application_id {, id: 2, cluster_timestamp: 1375845418464, }, attemptId: 1, }, id: 2, }, state: C_COMPLETE, diagnostics: "Container killed by the ApplicationMaster.\n\n", exit_status: 143, ] resource=<memory:1024, vCores:1> queue=default: capacity=1.0, absoluteCapacity=1.0, usedResources=<memory:2048, vCores:1>usedCapacity=0.041666668, absoluteUsedCapacity=0.041666668, numApps=1, numContainers=1 usedCapacity=0.041666668 absoluteUsedCapacity=0.041666668 used=<memory:2048, vCores:1> cluster=<memory:49152, vCores:96>
2013-08-07 03:21:36,403 INFO org.apache.hadoop.yarn.server.resourcemanager.scheduler.capacity.ParentQueue: completedContainer queue=root usedCapacity=0.041666668 absoluteUsedCapacity=0.041666668 used=<memory:2048, vCores:1> cluster=<memory:49152, vCores:96>
2013-08-07 03:21:36,403 INFO org.apache.hadoop.yarn.server.resourcemanager.scheduler.capacity.CapacityScheduler: Application appattempt_1375845418464_0002_000001 released container container_1375845418464_0002_01_000002 on node: host: hadoop-200-3:52180 #containers=0 available=8192 used=0 with event: FINISHED
2013-08-07 03:21:40,548 INFO org.apache.hadoop.yarn.server.resourcemanager.rmapp.attempt.RMAppAttemptImpl: appattempt_1375845418464_0002_000001 State change from RUNNING to FINISHING
2013-08-07 03:21:40,549 INFO org.apache.hadoop.yarn.server.resourcemanager.rmapp.RMAppImpl: application_1375845418464_0002 State change from RUNNING to FINISHING
2013-08-07 03:21:40,852 INFO org.apache.hadoop.yarn.server.resourcemanager.rmcontainer.RMContainerImpl: container_1375845418464_0002_01_000001 Container Transitioned from RUNNING to COMPLETED
2013-08-07 03:21:40,852 INFO org.apache.hadoop.yarn.server.resourcemanager.scheduler.common.fica.FiCaSchedulerApp: Completed container: container_1375845418464_0002_01_000001 in state: COMPLETED event:FINISHED
2013-08-07 03:21:40,852 INFO org.apache.hadoop.yarn.server.resourcemanager.RMAuditLogger: USER=ubuntu	OPERATION=AM Released Container	TARGET=SchedulerApp	RESULT=SUCCESS	APPID=application_1375845418464_0002	CONTAINERID=container_1375845418464_0002_01_000001
2013-08-07 03:21:40,852 INFO org.apache.hadoop.yarn.server.resourcemanager.scheduler.common.fica.FiCaSchedulerNode: Released container container_1375845418464_0002_01_000001 of capacity <memory:2048, vCores:1> on host hadoop-200-2:46099, which currently has 0 containers, <memory:0, vCores:0> used and <memory:8192, vCores:16> available, release resources=true
2013-08-07 03:21:40,853 INFO org.apache.hadoop.yarn.server.resourcemanager.scheduler.capacity.LeafQueue: default used=<memory:0, vCores:0> numContainers=0 user=ubuntu user-resources=<memory:0, vCores:0>
2013-08-07 03:21:40,853 INFO org.apache.hadoop.yarn.server.resourcemanager.rmapp.attempt.RMAppAttemptImpl: appattempt_1375845418464_0002_000001 State change from FINISHING to FINISHED
2013-08-07 03:21:40,854 INFO org.apache.hadoop.yarn.server.resourcemanager.rmapp.RMAppImpl: application_1375845418464_0002 State change from FINISHING to FINISHED
2013-08-07 03:21:40,854 INFO org.apache.hadoop.yarn.server.resourcemanager.scheduler.capacity.LeafQueue: completedContainer container=Container: [ContainerId: container_1375845418464_0002_01_000001, NodeId: hadoop-200-2:46099, NodeHttpAddress: hadoop-200-2:8042, Resource: <memory:2048, vCores:1>, Priority: 0, State: NEW, Token: null, Status: container_id {, app_attempt_id {, application_id {, id: 2, cluster_timestamp: 1375845418464, }, attemptId: 1, }, id: 1, }, state: C_COMPLETE, diagnostics: "", exit_status: 0, ] resource=<memory:2048, vCores:1> queue=default: capacity=1.0, absoluteCapacity=1.0, usedResources=<memory:0, vCores:0>usedCapacity=0.0, absoluteUsedCapacity=0.0, numApps=1, numContainers=0 usedCapacity=0.0 absoluteUsedCapacity=0.0 used=<memory:0, vCores:0> cluster=<memory:49152, vCores:96>
2013-08-07 03:21:40,854 INFO org.apache.hadoop.yarn.server.resourcemanager.RMAuditLogger: USER=ubuntu	OPERATION=Application Finished - Succeeded	TARGET=RMAppManager	RESULT=SUCCESS	APPID=application_1375845418464_0002
2013-08-07 03:21:40,855 INFO org.apache.hadoop.yarn.server.resourcemanager.scheduler.capacity.ParentQueue: completedContainer queue=root usedCapacity=0.0 absoluteUsedCapacity=0.0 used=<memory:0, vCores:0> cluster=<memory:49152, vCores:96>
2013-08-07 03:21:40,865 INFO org.apache.hadoop.yarn.server.resourcemanager.recovery.RMStateStore: Removing info for app: application_1375845418464_0002
2013-08-07 03:21:40,865 INFO org.apache.hadoop.yarn.server.resourcemanager.scheduler.capacity.CapacityScheduler: Application appattempt_1375845418464_0002_000001 released container container_1375845418464_0002_01_000001 on node: host: hadoop-200-2:46099 #containers=0 available=8192 used=0 with event: FINISHED
2013-08-07 03:21:40,866 INFO org.apache.hadoop.yarn.server.resourcemanager.RMAppManager$ApplicationSummary: appId=application_1375845418464_0002,name=TeraGen,user=ubuntu,queue=default,state=FINISHED,trackingUrl=hadoop-200-1.novalocal:8088/proxy/application_1375845418464_0002/jobhistory/job/job_1375845418464_0002,appMasterHost=hadoop-200-2,startTime=1375845579156,finishTime=1375845700549
2013-08-07 03:21:40,866 INFO org.apache.hadoop.yarn.server.resourcemanager.scheduler.capacity.CapacityScheduler: Application appattempt_1375845418464_0002_000001 is done. finalState=FINISHED
2013-08-07 03:21:40,866 INFO org.apache.hadoop.yarn.server.resourcemanager.scheduler.AppSchedulingInfo: Application application_1375845418464_0002 requests cleared
2013-08-07 03:21:40,866 INFO org.apache.hadoop.yarn.server.resourcemanager.scheduler.capacity.LeafQueue: Application removed - appId: application_1375845418464_0002 user: ubuntu queue: default #user-pending-applications: 0 #user-active-applications: 0 #queue-pending-applications: 0 #queue-active-applications: 0
2013-08-07 03:21:40,866 INFO org.apache.hadoop.yarn.server.resourcemanager.scheduler.capacity.ParentQueue: Application removed - appId: application_1375845418464_0002 user: ubuntu leaf-queue of parent: root #applications: 0
2013-08-07 03:21:40,867 INFO org.apache.hadoop.yarn.server.resourcemanager.amlauncher.AMLauncher: Cleaning master appattempt_1375845418464_0002_000001
2013-08-07 03:21:42,725 INFO org.apache.hadoop.yarn.server.resourcemanager.ClientRMService: Allocated new applicationId: 3
2013-08-07 03:21:44,683 INFO org.apache.hadoop.yarn.server.resourcemanager.ClientRMService: Storing Application with id application_1375845418464_0003
2013-08-07 03:21:44,683 INFO org.apache.hadoop.yarn.server.resourcemanager.recovery.RMStateStore: Storing info for app: application_1375845418464_0003
2013-08-07 03:21:44,684 INFO org.apache.hadoop.yarn.server.resourcemanager.ClientRMService: Application with id 3 submitted by user ubuntu
2013-08-07 03:21:44,684 INFO org.apache.hadoop.yarn.server.resourcemanager.RMAuditLogger: USER=ubuntu	IP=192.168.100.5	OPERATION=Submit Application Request	TARGET=ClientRMService	RESULT=SUCCESS	APPID=application_1375845418464_0003
2013-08-07 03:21:44,685 INFO org.apache.hadoop.yarn.server.resourcemanager.rmapp.RMAppImpl: application_1375845418464_0003 State change from NEW to SUBMITTED
2013-08-07 03:21:44,685 INFO org.apache.hadoop.yarn.server.resourcemanager.ApplicationMasterService: Registering appattempt_1375845418464_0003_000001
2013-08-07 03:21:44,685 INFO org.apache.hadoop.yarn.server.resourcemanager.rmapp.attempt.RMAppAttemptImpl: appattempt_1375845418464_0003_000001 State change from NEW to SUBMITTED
2013-08-07 03:21:44,686 INFO org.apache.hadoop.yarn.server.resourcemanager.scheduler.capacity.LeafQueue: Application application_1375845418464_0003 from user: ubuntu activated in queue: default
2013-08-07 03:21:44,686 INFO org.apache.hadoop.yarn.server.resourcemanager.scheduler.capacity.LeafQueue: Application added - appId: application_1375845418464_0003 user: org.apache.hadoop.yarn.server.resourcemanager.scheduler.capacity.LeafQueue$User@4ee2dd22, leaf-queue: default #user-pending-applications: 0 #user-active-applications: 1 #queue-pending-applications: 0 #queue-active-applications: 1
2013-08-07 03:21:44,686 INFO org.apache.hadoop.yarn.server.resourcemanager.scheduler.capacity.ParentQueue: Application added - appId: application_1375845418464_0003 user: ubuntu leaf-queue of parent: root #applications: 1
2013-08-07 03:21:44,687 INFO org.apache.hadoop.yarn.server.resourcemanager.scheduler.capacity.CapacityScheduler: Application Submission: appattempt_1375845418464_0003_000001, user: ubuntu queue: default: capacity=1.0, absoluteCapacity=1.0, usedResources=<memory:0, vCores:0>usedCapacity=0.0, absoluteUsedCapacity=0.0, numApps=1, numContainers=0, currently active: 1
2013-08-07 03:21:44,687 INFO org.apache.hadoop.yarn.server.resourcemanager.rmapp.attempt.RMAppAttemptImpl: appattempt_1375845418464_0003_000001 State change from SUBMITTED to SCHEDULED
2013-08-07 03:21:44,687 INFO org.apache.hadoop.yarn.server.resourcemanager.rmapp.RMAppImpl: application_1375845418464_0003 State change from SUBMITTED to ACCEPTED
2013-08-07 03:21:44,868 INFO org.apache.hadoop.yarn.server.resourcemanager.rmcontainer.RMContainerImpl: container_1375845418464_0003_01_000001 Container Transitioned from NEW to ALLOCATED
2013-08-07 03:21:44,868 INFO org.apache.hadoop.yarn.server.resourcemanager.RMAuditLogger: USER=ubuntu	OPERATION=AM Allocated Container	TARGET=SchedulerApp	RESULT=SUCCESS	APPID=application_1375845418464_0003	CONTAINERID=container_1375845418464_0003_01_000001
2013-08-07 03:21:44,868 INFO org.apache.hadoop.yarn.server.resourcemanager.scheduler.common.fica.FiCaSchedulerNode: Assigned container container_1375845418464_0003_01_000001 of capacity <memory:2048, vCores:1> on host hadoop-200-2:46099, which currently has 1 containers, <memory:2048, vCores:1> used and <memory:6144, vCores:15> available
2013-08-07 03:21:44,869 INFO org.apache.hadoop.yarn.server.resourcemanager.scheduler.capacity.LeafQueue: assignedContainer application=application_1375845418464_0003 container=Container: [ContainerId: container_1375845418464_0003_01_000001, NodeId: hadoop-200-2:46099, NodeHttpAddress: hadoop-200-2:8042, Resource: <memory:2048, vCores:1>, Priority: 0, State: NEW, Token: null, Status: container_id {, app_attempt_id {, application_id {, id: 3, cluster_timestamp: 1375845418464, }, attemptId: 1, }, id: 1, }, state: C_NEW, ] containerId=container_1375845418464_0003_01_000001 queue=default: capacity=1.0, absoluteCapacity=1.0, usedResources=<memory:0, vCores:0>usedCapacity=0.0, absoluteUsedCapacity=0.0, numApps=1, numContainers=0 usedCapacity=0.0 absoluteUsedCapacity=0.0 used=<memory:0, vCores:0> cluster=<memory:49152, vCores:96>
2013-08-07 03:21:44,870 INFO org.apache.hadoop.yarn.server.resourcemanager.scheduler.capacity.ParentQueue: Re-sorting queues since queue: root.default stats: default: capacity=1.0, absoluteCapacity=1.0, usedResources=<memory:2048, vCores:1>usedCapacity=0.041666668, absoluteUsedCapacity=0.041666668, numApps=1, numContainers=1
2013-08-07 03:21:44,870 INFO org.apache.hadoop.yarn.server.resourcemanager.scheduler.capacity.ParentQueue: assignedContainer queue=root usedCapacity=0.041666668 absoluteUsedCapacity=0.041666668 used=<memory:2048, vCores:1> cluster=<memory:49152, vCores:96>
2013-08-07 03:21:44,871 INFO org.apache.hadoop.yarn.server.resourcemanager.rmcontainer.RMContainerImpl: container_1375845418464_0003_01_000001 Container Transitioned from ALLOCATED to ACQUIRED
2013-08-07 03:21:44,873 INFO org.apache.hadoop.yarn.server.resourcemanager.rmapp.attempt.RMAppAttemptImpl: Storing attempt: AppId: application_1375845418464_0003 AttemptId: appattempt_1375845418464_0003_000001 MasterContainer: Container: [ContainerId: container_1375845418464_0003_01_000001, NodeId: hadoop-200-2:46099, NodeHttpAddress: hadoop-200-2:8042, Resource: <memory:2048, vCores:1>, Priority: 0, State: NEW, Token: null, Status: container_id {, app_attempt_id {, application_id {, id: 3, cluster_timestamp: 1375845418464, }, attemptId: 1, }, id: 1, }, state: C_NEW, ]
2013-08-07 03:21:44,873 INFO org.apache.hadoop.yarn.server.resourcemanager.rmapp.attempt.RMAppAttemptImpl: appattempt_1375845418464_0003_000001 State change from SCHEDULED to ALLOCATED_SAVING
2013-08-07 03:21:44,874 INFO org.apache.hadoop.yarn.server.resourcemanager.recovery.RMStateStore: Storing info for attempt: appattempt_1375845418464_0003_000001
2013-08-07 03:21:44,875 INFO org.apache.hadoop.yarn.server.resourcemanager.rmapp.attempt.RMAppAttemptImpl: appattempt_1375845418464_0003_000001 State change from ALLOCATED_SAVING to ALLOCATED
2013-08-07 03:21:44,876 INFO org.apache.hadoop.yarn.server.resourcemanager.amlauncher.AMLauncher: Launching masterappattempt_1375845418464_0003_000001
2013-08-07 03:21:44,879 INFO org.apache.hadoop.yarn.server.resourcemanager.amlauncher.AMLauncher: Setting up container Container: [ContainerId: container_1375845418464_0003_01_000001, NodeId: hadoop-200-2:46099, NodeHttpAddress: hadoop-200-2:8042, Resource: <memory:2048, vCores:1>, Priority: 0, State: NEW, Token: null, Status: container_id {, app_attempt_id {, application_id {, id: 3, cluster_timestamp: 1375845418464, }, attemptId: 1, }, id: 1, }, state: C_NEW, ] for AM appattempt_1375845418464_0003_000001
2013-08-07 03:21:44,880 INFO org.apache.hadoop.yarn.server.resourcemanager.amlauncher.AMLauncher: Command to launch container container_1375845418464_0003_01_000001 : $JAVA_HOME/bin/java -Dlog4j.configuration=container-log4j.properties -Dyarn.app.mapreduce.container.log.dir=<LOG_DIR> -Dyarn.app.mapreduce.container.log.filesize=0 -Dhadoop.root.logger=INFO,CLA  -Xmx1024m org.apache.hadoop.mapreduce.v2.app.MRAppMaster 1><LOG_DIR>/stdout 2><LOG_DIR>/stderr 
2013-08-07 03:21:44,896 INFO org.apache.hadoop.yarn.server.resourcemanager.amlauncher.AMLauncher: Done launching container Container: [ContainerId: container_1375845418464_0003_01_000001, NodeId: hadoop-200-2:46099, NodeHttpAddress: hadoop-200-2:8042, Resource: <memory:2048, vCores:1>, Priority: 0, State: NEW, Token: null, Status: container_id {, app_attempt_id {, application_id {, id: 3, cluster_timestamp: 1375845418464, }, attemptId: 1, }, id: 1, }, state: C_NEW, ] for AM appattempt_1375845418464_0003_000001
2013-08-07 03:21:44,897 INFO org.apache.hadoop.yarn.server.resourcemanager.rmapp.attempt.RMAppAttemptImpl: appattempt_1375845418464_0003_000001 State change from ALLOCATED to LAUNCHED
2013-08-07 03:21:45,874 INFO org.apache.hadoop.yarn.server.resourcemanager.rmcontainer.RMContainerImpl: container_1375845418464_0003_01_000001 Container Transitioned from ACQUIRED to RUNNING
2013-08-07 03:21:50,981 INFO org.apache.hadoop.yarn.server.resourcemanager.ApplicationMasterService: AM registration appattempt_1375845418464_0003_000001
2013-08-07 03:21:50,981 INFO org.apache.hadoop.yarn.server.resourcemanager.RMAuditLogger: USER=ubuntu	IP=192.168.100.6	OPERATION=Register App Master	TARGET=ApplicationMasterService	RESULT=SUCCESS	APPID=application_1375845418464_0003	APPATTEMPTID=appattempt_1375845418464_0003_000001
2013-08-07 03:21:50,986 INFO org.apache.hadoop.yarn.server.resourcemanager.rmapp.attempt.RMAppAttemptImpl: appattempt_1375845418464_0003_000001 State change from LAUNCHED to RUNNING
2013-08-07 03:21:50,986 INFO org.apache.hadoop.yarn.server.resourcemanager.rmapp.RMAppImpl: application_1375845418464_0003 State change from ACCEPTED to RUNNING
2013-08-07 03:21:52,179 INFO org.apache.hadoop.yarn.server.resourcemanager.rmcontainer.RMContainerImpl: container_1375845418464_0003_01_000002 Container Transitioned from NEW to ALLOCATED
2013-08-07 03:21:52,179 INFO org.apache.hadoop.yarn.server.resourcemanager.RMAuditLogger: USER=ubuntu	OPERATION=AM Allocated Container	TARGET=SchedulerApp	RESULT=SUCCESS	APPID=application_1375845418464_0003	CONTAINERID=container_1375845418464_0003_01_000002
2013-08-07 03:21:52,179 INFO org.apache.hadoop.yarn.server.resourcemanager.scheduler.common.fica.FiCaSchedulerNode: Assigned container container_1375845418464_0003_01_000002 of capacity <memory:1024, vCores:1> on host hadoop-200-4:45217, which currently has 1 containers, <memory:1024, vCores:1> used and <memory:7168, vCores:15> available
2013-08-07 03:21:52,181 INFO org.apache.hadoop.yarn.server.resourcemanager.scheduler.capacity.LeafQueue: assignedContainer application=application_1375845418464_0003 container=Container: [ContainerId: container_1375845418464_0003_01_000002, NodeId: hadoop-200-4:45217, NodeHttpAddress: hadoop-200-4:8042, Resource: <memory:1024, vCores:1>, Priority: 20, State: NEW, Token: null, Status: container_id {, app_attempt_id {, application_id {, id: 3, cluster_timestamp: 1375845418464, }, attemptId: 1, }, id: 2, }, state: C_NEW, ] containerId=container_1375845418464_0003_01_000002 queue=default: capacity=1.0, absoluteCapacity=1.0, usedResources=<memory:2048, vCores:1>usedCapacity=0.041666668, absoluteUsedCapacity=0.041666668, numApps=1, numContainers=1 usedCapacity=0.041666668 absoluteUsedCapacity=0.041666668 used=<memory:2048, vCores:1> cluster=<memory:49152, vCores:96>
2013-08-07 03:21:52,181 INFO org.apache.hadoop.yarn.server.resourcemanager.scheduler.capacity.ParentQueue: Re-sorting queues since queue: root.default stats: default: capacity=1.0, absoluteCapacity=1.0, usedResources=<memory:3072, vCores:2>usedCapacity=0.0625, absoluteUsedCapacity=0.0625, numApps=1, numContainers=2
2013-08-07 03:21:52,181 INFO org.apache.hadoop.yarn.server.resourcemanager.scheduler.capacity.ParentQueue: assignedContainer queue=root usedCapacity=0.0625 absoluteUsedCapacity=0.0625 used=<memory:3072, vCores:2> cluster=<memory:49152, vCores:96>
2013-08-07 03:21:52,257 INFO org.apache.hadoop.yarn.server.resourcemanager.rmcontainer.RMContainerImpl: container_1375845418464_0003_01_000003 Container Transitioned from NEW to ALLOCATED
2013-08-07 03:21:52,257 INFO org.apache.hadoop.yarn.server.resourcemanager.RMAuditLogger: USER=ubuntu	OPERATION=AM Allocated Container	TARGET=SchedulerApp	RESULT=SUCCESS	APPID=application_1375845418464_0003	CONTAINERID=container_1375845418464_0003_01_000003
2013-08-07 03:21:52,257 INFO org.apache.hadoop.yarn.server.resourcemanager.scheduler.common.fica.FiCaSchedulerNode: Assigned container container_1375845418464_0003_01_000003 of capacity <memory:1024, vCores:1> on host hadoop-200-7:47421, which currently has 1 containers, <memory:1024, vCores:1> used and <memory:7168, vCores:15> available
2013-08-07 03:21:52,259 INFO org.apache.hadoop.yarn.server.resourcemanager.scheduler.capacity.LeafQueue: assignedContainer application=application_1375845418464_0003 container=Container: [ContainerId: container_1375845418464_0003_01_000003, NodeId: hadoop-200-7:47421, NodeHttpAddress: hadoop-200-7:8042, Resource: <memory:1024, vCores:1>, Priority: 20, State: NEW, Token: null, Status: container_id {, app_attempt_id {, application_id {, id: 3, cluster_timestamp: 1375845418464, }, attemptId: 1, }, id: 3, }, state: C_NEW, ] containerId=container_1375845418464_0003_01_000003 queue=default: capacity=1.0, absoluteCapacity=1.0, usedResources=<memory:3072, vCores:2>usedCapacity=0.0625, absoluteUsedCapacity=0.0625, numApps=1, numContainers=2 usedCapacity=0.0625 absoluteUsedCapacity=0.0625 used=<memory:3072, vCores:2> cluster=<memory:49152, vCores:96>
2013-08-07 03:21:52,259 INFO org.apache.hadoop.yarn.server.resourcemanager.scheduler.capacity.ParentQueue: Re-sorting queues since queue: root.default stats: default: capacity=1.0, absoluteCapacity=1.0, usedResources=<memory:4096, vCores:3>usedCapacity=0.083333336, absoluteUsedCapacity=0.083333336, numApps=1, numContainers=3
2013-08-07 03:21:52,259 INFO org.apache.hadoop.yarn.server.resourcemanager.scheduler.capacity.ParentQueue: assignedContainer queue=root usedCapacity=0.083333336 absoluteUsedCapacity=0.083333336 used=<memory:4096, vCores:3> cluster=<memory:49152, vCores:96>
2013-08-07 03:21:53,049 INFO org.apache.hadoop.yarn.server.resourcemanager.rmcontainer.RMContainerImpl: container_1375845418464_0003_01_000002 Container Transitioned from ALLOCATED to ACQUIRED
2013-08-07 03:21:53,051 INFO org.apache.hadoop.yarn.server.resourcemanager.rmcontainer.RMContainerImpl: container_1375845418464_0003_01_000003 Container Transitioned from ALLOCATED to ACQUIRED
2013-08-07 03:21:54,080 INFO org.apache.hadoop.yarn.server.resourcemanager.scheduler.AppSchedulingInfo: checking for deactivate... 
2013-08-07 03:21:54,188 INFO org.apache.hadoop.yarn.server.resourcemanager.rmcontainer.RMContainerImpl: container_1375845418464_0003_01_000002 Container Transitioned from ACQUIRED to RUNNING
2013-08-07 03:21:54,265 INFO org.apache.hadoop.yarn.server.resourcemanager.rmcontainer.RMContainerImpl: container_1375845418464_0003_01_000003 Container Transitioned from ACQUIRED to RUNNING
2013-08-07 03:23:40,016 INFO org.apache.hadoop.yarn.server.resourcemanager.rmcontainer.RMContainerImpl: container_1375845418464_0003_01_000002 Container Transitioned from RUNNING to COMPLETED
2013-08-07 03:23:40,016 INFO org.apache.hadoop.yarn.server.resourcemanager.scheduler.common.fica.FiCaSchedulerApp: Completed container: container_1375845418464_0003_01_000002 in state: COMPLETED event:FINISHED
2013-08-07 03:23:40,016 INFO org.apache.hadoop.yarn.server.resourcemanager.RMAuditLogger: USER=ubuntu	OPERATION=AM Released Container	TARGET=SchedulerApp	RESULT=SUCCESS	APPID=application_1375845418464_0003	CONTAINERID=container_1375845418464_0003_01_000002
2013-08-07 03:23:40,016 INFO org.apache.hadoop.yarn.server.resourcemanager.scheduler.common.fica.FiCaSchedulerNode: Released container container_1375845418464_0003_01_000002 of capacity <memory:1024, vCores:1> on host hadoop-200-4:45217, which currently has 0 containers, <memory:0, vCores:0> used and <memory:8192, vCores:16> available, release resources=true
2013-08-07 03:23:40,017 INFO org.apache.hadoop.yarn.server.resourcemanager.scheduler.capacity.LeafQueue: default used=<memory:3072, vCores:2> numContainers=2 user=ubuntu user-resources=<memory:3072, vCores:2>
2013-08-07 03:23:40,019 INFO org.apache.hadoop.yarn.server.resourcemanager.scheduler.capacity.LeafQueue: completedContainer container=Container: [ContainerId: container_1375845418464_0003_01_000002, NodeId: hadoop-200-4:45217, NodeHttpAddress: hadoop-200-4:8042, Resource: <memory:1024, vCores:1>, Priority: 20, State: NEW, Token: null, Status: container_id {, app_attempt_id {, application_id {, id: 3, cluster_timestamp: 1375845418464, }, attemptId: 1, }, id: 2, }, state: C_COMPLETE, diagnostics: "Container killed by the ApplicationMaster.\n", exit_status: 0, ] resource=<memory:1024, vCores:1> queue=default: capacity=1.0, absoluteCapacity=1.0, usedResources=<memory:3072, vCores:2>usedCapacity=0.0625, absoluteUsedCapacity=0.0625, numApps=1, numContainers=2 usedCapacity=0.0625 absoluteUsedCapacity=0.0625 used=<memory:3072, vCores:2> cluster=<memory:49152, vCores:96>
2013-08-07 03:23:40,019 INFO org.apache.hadoop.yarn.server.resourcemanager.scheduler.capacity.ParentQueue: completedContainer queue=root usedCapacity=0.0625 absoluteUsedCapacity=0.0625 used=<memory:3072, vCores:2> cluster=<memory:49152, vCores:96>
2013-08-07 03:23:40,019 INFO org.apache.hadoop.yarn.server.resourcemanager.scheduler.capacity.CapacityScheduler: Application appattempt_1375845418464_0003_000001 released container container_1375845418464_0003_01_000002 on node: host: hadoop-200-4:45217 #containers=0 available=8192 used=0 with event: FINISHED
2013-08-07 03:23:44,206 INFO org.apache.hadoop.yarn.server.resourcemanager.rmcontainer.RMContainerImpl: container_1375845418464_0003_01_000003 Container Transitioned from RUNNING to COMPLETED
2013-08-07 03:23:44,206 INFO org.apache.hadoop.yarn.server.resourcemanager.scheduler.common.fica.FiCaSchedulerApp: Completed container: container_1375845418464_0003_01_000003 in state: COMPLETED event:FINISHED
2013-08-07 03:23:44,206 INFO org.apache.hadoop.yarn.server.resourcemanager.RMAuditLogger: USER=ubuntu	OPERATION=AM Released Container	TARGET=SchedulerApp	RESULT=SUCCESS	APPID=application_1375845418464_0003	CONTAINERID=container_1375845418464_0003_01_000003
2013-08-07 03:23:44,207 INFO org.apache.hadoop.yarn.server.resourcemanager.scheduler.common.fica.FiCaSchedulerNode: Released container container_1375845418464_0003_01_000003 of capacity <memory:1024, vCores:1> on host hadoop-200-7:47421, which currently has 0 containers, <memory:0, vCores:0> used and <memory:8192, vCores:16> available, release resources=true
2013-08-07 03:23:44,207 INFO org.apache.hadoop.yarn.server.resourcemanager.scheduler.capacity.LeafQueue: default used=<memory:2048, vCores:1> numContainers=1 user=ubuntu user-resources=<memory:2048, vCores:1>
2013-08-07 03:23:44,209 INFO org.apache.hadoop.yarn.server.resourcemanager.scheduler.capacity.LeafQueue: completedContainer container=Container: [ContainerId: container_1375845418464_0003_01_000003, NodeId: hadoop-200-7:47421, NodeHttpAddress: hadoop-200-7:8042, Resource: <memory:1024, vCores:1>, Priority: 20, State: NEW, Token: null, Status: container_id {, app_attempt_id {, application_id {, id: 3, cluster_timestamp: 1375845418464, }, attemptId: 1, }, id: 3, }, state: C_COMPLETE, diagnostics: "Container killed by the ApplicationMaster.\n\n", exit_status: 143, ] resource=<memory:1024, vCores:1> queue=default: capacity=1.0, absoluteCapacity=1.0, usedResources=<memory:2048, vCores:1>usedCapacity=0.041666668, absoluteUsedCapacity=0.041666668, numApps=1, numContainers=1 usedCapacity=0.041666668 absoluteUsedCapacity=0.041666668 used=<memory:2048, vCores:1> cluster=<memory:49152, vCores:96>
2013-08-07 03:23:44,209 INFO org.apache.hadoop.yarn.server.resourcemanager.scheduler.capacity.ParentQueue: completedContainer queue=root usedCapacity=0.041666668 absoluteUsedCapacity=0.041666668 used=<memory:2048, vCores:1> cluster=<memory:49152, vCores:96>
2013-08-07 03:23:44,209 INFO org.apache.hadoop.yarn.server.resourcemanager.scheduler.capacity.CapacityScheduler: Application appattempt_1375845418464_0003_000001 released container container_1375845418464_0003_01_000003 on node: host: hadoop-200-7:47421 #containers=0 available=8192 used=0 with event: FINISHED
2013-08-07 03:23:48,366 INFO org.apache.hadoop.yarn.server.resourcemanager.rmapp.attempt.RMAppAttemptImpl: appattempt_1375845418464_0003_000001 State change from RUNNING to FINISHING
2013-08-07 03:23:48,367 INFO org.apache.hadoop.yarn.server.resourcemanager.rmapp.RMAppImpl: application_1375845418464_0003 State change from RUNNING to FINISHING
2013-08-07 03:23:49,466 INFO org.apache.hadoop.yarn.server.resourcemanager.rmcontainer.RMContainerImpl: container_1375845418464_0003_01_000001 Container Transitioned from RUNNING to COMPLETED
2013-08-07 03:23:49,466 INFO org.apache.hadoop.yarn.server.resourcemanager.scheduler.common.fica.FiCaSchedulerApp: Completed container: container_1375845418464_0003_01_000001 in state: COMPLETED event:FINISHED
2013-08-07 03:23:49,467 INFO org.apache.hadoop.yarn.server.resourcemanager.RMAuditLogger: USER=ubuntu	OPERATION=AM Released Container	TARGET=SchedulerApp	RESULT=SUCCESS	APPID=application_1375845418464_0003	CONTAINERID=container_1375845418464_0003_01_000001
2013-08-07 03:23:49,467 INFO org.apache.hadoop.yarn.server.resourcemanager.scheduler.common.fica.FiCaSchedulerNode: Released container container_1375845418464_0003_01_000001 of capacity <memory:2048, vCores:1> on host hadoop-200-2:46099, which currently has 0 containers, <memory:0, vCores:0> used and <memory:8192, vCores:16> available, release resources=true
2013-08-07 03:23:49,467 INFO org.apache.hadoop.yarn.server.resourcemanager.rmapp.attempt.RMAppAttemptImpl: appattempt_1375845418464_0003_000001 State change from FINISHING to FINISHED
2013-08-07 03:23:49,467 INFO org.apache.hadoop.yarn.server.resourcemanager.scheduler.capacity.LeafQueue: default used=<memory:0, vCores:0> numContainers=0 user=ubuntu user-resources=<memory:0, vCores:0>
2013-08-07 03:23:49,467 INFO org.apache.hadoop.yarn.server.resourcemanager.rmapp.RMAppImpl: application_1375845418464_0003 State change from FINISHING to FINISHED
2013-08-07 03:23:49,468 INFO org.apache.hadoop.yarn.server.resourcemanager.RMAuditLogger: USER=ubuntu	OPERATION=Application Finished - Succeeded	TARGET=RMAppManager	RESULT=SUCCESS	APPID=application_1375845418464_0003
2013-08-07 03:23:49,468 INFO org.apache.hadoop.yarn.server.resourcemanager.recovery.RMStateStore: Removing info for app: application_1375845418464_0003
2013-08-07 03:23:49,471 INFO org.apache.hadoop.yarn.server.resourcemanager.amlauncher.AMLauncher: Cleaning master appattempt_1375845418464_0003_000001
2013-08-07 03:23:49,471 INFO org.apache.hadoop.yarn.server.resourcemanager.scheduler.capacity.LeafQueue: completedContainer container=Container: [ContainerId: container_1375845418464_0003_01_000001, NodeId: hadoop-200-2:46099, NodeHttpAddress: hadoop-200-2:8042, Resource: <memory:2048, vCores:1>, Priority: 0, State: NEW, Token: null, Status: container_id {, app_attempt_id {, application_id {, id: 3, cluster_timestamp: 1375845418464, }, attemptId: 1, }, id: 1, }, state: C_COMPLETE, diagnostics: "", exit_status: 0, ] resource=<memory:2048, vCores:1> queue=default: capacity=1.0, absoluteCapacity=1.0, usedResources=<memory:0, vCores:0>usedCapacity=0.0, absoluteUsedCapacity=0.0, numApps=1, numContainers=0 usedCapacity=0.0 absoluteUsedCapacity=0.0 used=<memory:0, vCores:0> cluster=<memory:49152, vCores:96>
2013-08-07 03:23:49,472 INFO org.apache.hadoop.yarn.server.resourcemanager.scheduler.capacity.ParentQueue: completedContainer queue=root usedCapacity=0.0 absoluteUsedCapacity=0.0 used=<memory:0, vCores:0> cluster=<memory:49152, vCores:96>
2013-08-07 03:23:49,472 INFO org.apache.hadoop.yarn.server.resourcemanager.scheduler.capacity.CapacityScheduler: Application appattempt_1375845418464_0003_000001 released container container_1375845418464_0003_01_000001 on node: host: hadoop-200-2:46099 #containers=0 available=8192 used=0 with event: FINISHED
2013-08-07 03:23:49,472 INFO org.apache.hadoop.yarn.server.resourcemanager.scheduler.capacity.CapacityScheduler: Application appattempt_1375845418464_0003_000001 is done. finalState=FINISHED
2013-08-07 03:23:49,472 INFO org.apache.hadoop.yarn.server.resourcemanager.scheduler.AppSchedulingInfo: Application application_1375845418464_0003 requests cleared
2013-08-07 03:23:49,472 INFO org.apache.hadoop.yarn.server.resourcemanager.scheduler.capacity.LeafQueue: Application removed - appId: application_1375845418464_0003 user: ubuntu queue: default #user-pending-applications: 0 #user-active-applications: 0 #queue-pending-applications: 0 #queue-active-applications: 0
2013-08-07 03:23:49,473 INFO org.apache.hadoop.yarn.server.resourcemanager.scheduler.capacity.ParentQueue: Application removed - appId: application_1375845418464_0003 user: ubuntu leaf-queue of parent: root #applications: 0
2013-08-07 03:23:49,468 INFO org.apache.hadoop.yarn.server.resourcemanager.RMAppManager$ApplicationSummary: appId=application_1375845418464_0003,name=TeraGen,user=ubuntu,queue=default,state=FINISHED,trackingUrl=hadoop-200-1.novalocal:8088/proxy/application_1375845418464_0003/jobhistory/job/job_1375845418464_0003,appMasterHost=hadoop-200-2,startTime=1375845704683,finishTime=1375845828367
2013-08-07 03:23:49,800 INFO org.apache.hadoop.yarn.server.resourcemanager.ClientRMService: Allocated new applicationId: 4
2013-08-07 03:23:51,761 INFO org.apache.hadoop.yarn.server.resourcemanager.ClientRMService: Storing Application with id application_1375845418464_0004
2013-08-07 03:23:51,761 INFO org.apache.hadoop.yarn.server.resourcemanager.recovery.RMStateStore: Storing info for app: application_1375845418464_0004
2013-08-07 03:23:51,761 INFO org.apache.hadoop.yarn.server.resourcemanager.ClientRMService: Application with id 4 submitted by user ubuntu
2013-08-07 03:23:51,761 INFO org.apache.hadoop.yarn.server.resourcemanager.RMAuditLogger: USER=ubuntu	IP=192.168.100.5	OPERATION=Submit Application Request	TARGET=ClientRMService	RESULT=SUCCESS	APPID=application_1375845418464_0004
2013-08-07 03:23:51,762 INFO org.apache.hadoop.yarn.server.resourcemanager.rmapp.RMAppImpl: application_1375845418464_0004 State change from NEW to SUBMITTED
2013-08-07 03:23:51,762 INFO org.apache.hadoop.yarn.server.resourcemanager.ApplicationMasterService: Registering appattempt_1375845418464_0004_000001
2013-08-07 03:23:51,762 INFO org.apache.hadoop.yarn.server.resourcemanager.rmapp.attempt.RMAppAttemptImpl: appattempt_1375845418464_0004_000001 State change from NEW to SUBMITTED
2013-08-07 03:23:51,763 INFO org.apache.hadoop.yarn.server.resourcemanager.scheduler.capacity.LeafQueue: Application application_1375845418464_0004 from user: ubuntu activated in queue: default
2013-08-07 03:23:51,763 INFO org.apache.hadoop.yarn.server.resourcemanager.scheduler.capacity.LeafQueue: Application added - appId: application_1375845418464_0004 user: org.apache.hadoop.yarn.server.resourcemanager.scheduler.capacity.LeafQueue$User@7858e204, leaf-queue: default #user-pending-applications: 0 #user-active-applications: 1 #queue-pending-applications: 0 #queue-active-applications: 1
2013-08-07 03:23:51,763 INFO org.apache.hadoop.yarn.server.resourcemanager.scheduler.capacity.ParentQueue: Application added - appId: application_1375845418464_0004 user: ubuntu leaf-queue of parent: root #applications: 1
2013-08-07 03:23:51,763 INFO org.apache.hadoop.yarn.server.resourcemanager.scheduler.capacity.CapacityScheduler: Application Submission: appattempt_1375845418464_0004_000001, user: ubuntu queue: default: capacity=1.0, absoluteCapacity=1.0, usedResources=<memory:0, vCores:0>usedCapacity=0.0, absoluteUsedCapacity=0.0, numApps=1, numContainers=0, currently active: 1
2013-08-07 03:23:51,764 INFO org.apache.hadoop.yarn.server.resourcemanager.rmapp.attempt.RMAppAttemptImpl: appattempt_1375845418464_0004_000001 State change from SUBMITTED to SCHEDULED
2013-08-07 03:23:51,764 INFO org.apache.hadoop.yarn.server.resourcemanager.rmapp.RMAppImpl: application_1375845418464_0004 State change from SUBMITTED to ACCEPTED
2013-08-07 03:23:51,916 INFO org.apache.hadoop.yarn.server.resourcemanager.rmcontainer.RMContainerImpl: container_1375845418464_0004_01_000001 Container Transitioned from NEW to ALLOCATED
2013-08-07 03:23:51,916 INFO org.apache.hadoop.yarn.server.resourcemanager.RMAuditLogger: USER=ubuntu	OPERATION=AM Allocated Container	TARGET=SchedulerApp	RESULT=SUCCESS	APPID=application_1375845418464_0004	CONTAINERID=container_1375845418464_0004_01_000001
2013-08-07 03:23:51,916 INFO org.apache.hadoop.yarn.server.resourcemanager.scheduler.common.fica.FiCaSchedulerNode: Assigned container container_1375845418464_0004_01_000001 of capacity <memory:2048, vCores:1> on host hadoop-200-3:52180, which currently has 1 containers, <memory:2048, vCores:1> used and <memory:6144, vCores:15> available
2013-08-07 03:23:51,918 INFO org.apache.hadoop.yarn.server.resourcemanager.scheduler.capacity.LeafQueue: assignedContainer application=application_1375845418464_0004 container=Container: [ContainerId: container_1375845418464_0004_01_000001, NodeId: hadoop-200-3:52180, NodeHttpAddress: hadoop-200-3:8042, Resource: <memory:2048, vCores:1>, Priority: 0, State: NEW, Token: null, Status: container_id {, app_attempt_id {, application_id {, id: 4, cluster_timestamp: 1375845418464, }, attemptId: 1, }, id: 1, }, state: C_NEW, ] containerId=container_1375845418464_0004_01_000001 queue=default: capacity=1.0, absoluteCapacity=1.0, usedResources=<memory:0, vCores:0>usedCapacity=0.0, absoluteUsedCapacity=0.0, numApps=1, numContainers=0 usedCapacity=0.0 absoluteUsedCapacity=0.0 used=<memory:0, vCores:0> cluster=<memory:49152, vCores:96>
2013-08-07 03:23:51,918 INFO org.apache.hadoop.yarn.server.resourcemanager.scheduler.capacity.ParentQueue: Re-sorting queues since queue: root.default stats: default: capacity=1.0, absoluteCapacity=1.0, usedResources=<memory:2048, vCores:1>usedCapacity=0.041666668, absoluteUsedCapacity=0.041666668, numApps=1, numContainers=1
2013-08-07 03:23:51,918 INFO org.apache.hadoop.yarn.server.resourcemanager.scheduler.capacity.ParentQueue: assignedContainer queue=root usedCapacity=0.041666668 absoluteUsedCapacity=0.041666668 used=<memory:2048, vCores:1> cluster=<memory:49152, vCores:96>
2013-08-07 03:23:51,920 INFO org.apache.hadoop.yarn.server.resourcemanager.rmcontainer.RMContainerImpl: container_1375845418464_0004_01_000001 Container Transitioned from ALLOCATED to ACQUIRED
2013-08-07 03:23:51,922 INFO org.apache.hadoop.yarn.server.resourcemanager.rmapp.attempt.RMAppAttemptImpl: Storing attempt: AppId: application_1375845418464_0004 AttemptId: appattempt_1375845418464_0004_000001 MasterContainer: Container: [ContainerId: container_1375845418464_0004_01_000001, NodeId: hadoop-200-3:52180, NodeHttpAddress: hadoop-200-3:8042, Resource: <memory:2048, vCores:1>, Priority: 0, State: NEW, Token: null, Status: container_id {, app_attempt_id {, application_id {, id: 4, cluster_timestamp: 1375845418464, }, attemptId: 1, }, id: 1, }, state: C_NEW, ]
2013-08-07 03:23:51,923 INFO org.apache.hadoop.yarn.server.resourcemanager.recovery.RMStateStore: Storing info for attempt: appattempt_1375845418464_0004_000001
2013-08-07 03:23:51,923 INFO org.apache.hadoop.yarn.server.resourcemanager.rmapp.attempt.RMAppAttemptImpl: appattempt_1375845418464_0004_000001 State change from SCHEDULED to ALLOCATED_SAVING
2013-08-07 03:23:51,925 INFO org.apache.hadoop.yarn.server.resourcemanager.rmapp.attempt.RMAppAttemptImpl: appattempt_1375845418464_0004_000001 State change from ALLOCATED_SAVING to ALLOCATED
2013-08-07 03:23:51,926 INFO org.apache.hadoop.yarn.server.resourcemanager.amlauncher.AMLauncher: Launching masterappattempt_1375845418464_0004_000001
2013-08-07 03:23:51,930 INFO org.apache.hadoop.yarn.server.resourcemanager.amlauncher.AMLauncher: Setting up container Container: [ContainerId: container_1375845418464_0004_01_000001, NodeId: hadoop-200-3:52180, NodeHttpAddress: hadoop-200-3:8042, Resource: <memory:2048, vCores:1>, Priority: 0, State: NEW, Token: null, Status: container_id {, app_attempt_id {, application_id {, id: 4, cluster_timestamp: 1375845418464, }, attemptId: 1, }, id: 1, }, state: C_NEW, ] for AM appattempt_1375845418464_0004_000001
2013-08-07 03:23:51,930 INFO org.apache.hadoop.yarn.server.resourcemanager.amlauncher.AMLauncher: Command to launch container container_1375845418464_0004_01_000001 : $JAVA_HOME/bin/java -Dlog4j.configuration=container-log4j.properties -Dyarn.app.mapreduce.container.log.dir=<LOG_DIR> -Dyarn.app.mapreduce.container.log.filesize=0 -Dhadoop.root.logger=INFO,CLA  -Xmx1024m org.apache.hadoop.mapreduce.v2.app.MRAppMaster 1><LOG_DIR>/stdout 2><LOG_DIR>/stderr 
2013-08-07 03:23:51,946 INFO org.apache.hadoop.yarn.server.resourcemanager.amlauncher.AMLauncher: Done launching container Container: [ContainerId: container_1375845418464_0004_01_000001, NodeId: hadoop-200-3:52180, NodeHttpAddress: hadoop-200-3:8042, Resource: <memory:2048, vCores:1>, Priority: 0, State: NEW, Token: null, Status: container_id {, app_attempt_id {, application_id {, id: 4, cluster_timestamp: 1375845418464, }, attemptId: 1, }, id: 1, }, state: C_NEW, ] for AM appattempt_1375845418464_0004_000001
2013-08-07 03:23:51,946 INFO org.apache.hadoop.yarn.server.resourcemanager.rmapp.attempt.RMAppAttemptImpl: appattempt_1375845418464_0004_000001 State change from ALLOCATED to LAUNCHED
2013-08-07 03:23:52,921 INFO org.apache.hadoop.yarn.server.resourcemanager.rmcontainer.RMContainerImpl: container_1375845418464_0004_01_000001 Container Transitioned from ACQUIRED to RUNNING
2013-08-07 03:23:59,736 INFO org.apache.hadoop.yarn.server.resourcemanager.ApplicationMasterService: AM registration appattempt_1375845418464_0004_000001
2013-08-07 03:23:59,737 INFO org.apache.hadoop.yarn.server.resourcemanager.RMAuditLogger: USER=ubuntu	IP=192.168.100.9	OPERATION=Register App Master	TARGET=ApplicationMasterService	RESULT=SUCCESS	APPID=application_1375845418464_0004	APPATTEMPTID=appattempt_1375845418464_0004_000001
2013-08-07 03:23:59,738 INFO org.apache.hadoop.yarn.server.resourcemanager.rmapp.attempt.RMAppAttemptImpl: appattempt_1375845418464_0004_000001 State change from LAUNCHED to RUNNING
2013-08-07 03:23:59,738 INFO org.apache.hadoop.yarn.server.resourcemanager.rmapp.RMAppImpl: application_1375845418464_0004 State change from ACCEPTED to RUNNING
2013-08-07 03:24:00,969 INFO org.apache.hadoop.yarn.server.resourcemanager.rmcontainer.RMContainerImpl: container_1375845418464_0004_01_000002 Container Transitioned from NEW to ALLOCATED
2013-08-07 03:24:00,970 INFO org.apache.hadoop.yarn.server.resourcemanager.RMAuditLogger: USER=ubuntu	OPERATION=AM Allocated Container	TARGET=SchedulerApp	RESULT=SUCCESS	APPID=application_1375845418464_0004	CONTAINERID=container_1375845418464_0004_01_000002
2013-08-07 03:24:00,970 INFO org.apache.hadoop.yarn.server.resourcemanager.scheduler.common.fica.FiCaSchedulerNode: Assigned container container_1375845418464_0004_01_000002 of capacity <memory:1024, vCores:1> on host hadoop-200-3:52180, which currently has 2 containers, <memory:3072, vCores:2> used and <memory:5120, vCores:14> available
2013-08-07 03:24:00,971 INFO org.apache.hadoop.yarn.server.resourcemanager.scheduler.capacity.LeafQueue: assignedContainer application=application_1375845418464_0004 container=Container: [ContainerId: container_1375845418464_0004_01_000002, NodeId: hadoop-200-3:52180, NodeHttpAddress: hadoop-200-3:8042, Resource: <memory:1024, vCores:1>, Priority: 20, State: NEW, Token: null, Status: container_id {, app_attempt_id {, application_id {, id: 4, cluster_timestamp: 1375845418464, }, attemptId: 1, }, id: 2, }, state: C_NEW, ] containerId=container_1375845418464_0004_01_000002 queue=default: capacity=1.0, absoluteCapacity=1.0, usedResources=<memory:2048, vCores:1>usedCapacity=0.041666668, absoluteUsedCapacity=0.041666668, numApps=1, numContainers=1 usedCapacity=0.041666668 absoluteUsedCapacity=0.041666668 used=<memory:2048, vCores:1> cluster=<memory:49152, vCores:96>
2013-08-07 03:24:00,972 INFO org.apache.hadoop.yarn.server.resourcemanager.scheduler.capacity.ParentQueue: Re-sorting queues since queue: root.default stats: default: capacity=1.0, absoluteCapacity=1.0, usedResources=<memory:3072, vCores:2>usedCapacity=0.0625, absoluteUsedCapacity=0.0625, numApps=1, numContainers=2
2013-08-07 03:24:00,972 INFO org.apache.hadoop.yarn.server.resourcemanager.scheduler.capacity.ParentQueue: assignedContainer queue=root usedCapacity=0.0625 absoluteUsedCapacity=0.0625 used=<memory:3072, vCores:2> cluster=<memory:49152, vCores:96>
2013-08-07 03:24:01,047 INFO org.apache.hadoop.yarn.server.resourcemanager.rmcontainer.RMContainerImpl: container_1375845418464_0004_01_000003 Container Transitioned from NEW to ALLOCATED
2013-08-07 03:24:01,047 INFO org.apache.hadoop.yarn.server.resourcemanager.RMAuditLogger: USER=ubuntu	OPERATION=AM Allocated Container	TARGET=SchedulerApp	RESULT=SUCCESS	APPID=application_1375845418464_0004	CONTAINERID=container_1375845418464_0004_01_000003
2013-08-07 03:24:01,047 INFO org.apache.hadoop.yarn.server.resourcemanager.scheduler.common.fica.FiCaSchedulerNode: Assigned container container_1375845418464_0004_01_000003 of capacity <memory:1024, vCores:1> on host hadoop-200-6:45851, which currently has 1 containers, <memory:1024, vCores:1> used and <memory:7168, vCores:15> available
2013-08-07 03:24:01,049 INFO org.apache.hadoop.yarn.server.resourcemanager.scheduler.capacity.LeafQueue: assignedContainer application=application_1375845418464_0004 container=Container: [ContainerId: container_1375845418464_0004_01_000003, NodeId: hadoop-200-6:45851, NodeHttpAddress: hadoop-200-6:8042, Resource: <memory:1024, vCores:1>, Priority: 20, State: NEW, Token: null, Status: container_id {, app_attempt_id {, application_id {, id: 4, cluster_timestamp: 1375845418464, }, attemptId: 1, }, id: 3, }, state: C_NEW, ] containerId=container_1375845418464_0004_01_000003 queue=default: capacity=1.0, absoluteCapacity=1.0, usedResources=<memory:3072, vCores:2>usedCapacity=0.0625, absoluteUsedCapacity=0.0625, numApps=1, numContainers=2 usedCapacity=0.0625 absoluteUsedCapacity=0.0625 used=<memory:3072, vCores:2> cluster=<memory:49152, vCores:96>
2013-08-07 03:24:01,049 INFO org.apache.hadoop.yarn.server.resourcemanager.scheduler.capacity.ParentQueue: Re-sorting queues since queue: root.default stats: default: capacity=1.0, absoluteCapacity=1.0, usedResources=<memory:4096, vCores:3>usedCapacity=0.083333336, absoluteUsedCapacity=0.083333336, numApps=1, numContainers=3
2013-08-07 03:24:01,049 INFO org.apache.hadoop.yarn.server.resourcemanager.scheduler.capacity.ParentQueue: assignedContainer queue=root usedCapacity=0.083333336 absoluteUsedCapacity=0.083333336 used=<memory:4096, vCores:3> cluster=<memory:49152, vCores:96>
2013-08-07 03:24:01,806 INFO org.apache.hadoop.yarn.server.resourcemanager.rmcontainer.RMContainerImpl: container_1375845418464_0004_01_000002 Container Transitioned from ALLOCATED to ACQUIRED
2013-08-07 03:24:01,815 INFO org.apache.hadoop.yarn.server.resourcemanager.rmcontainer.RMContainerImpl: container_1375845418464_0004_01_000003 Container Transitioned from ALLOCATED to ACQUIRED
2013-08-07 03:24:02,858 INFO org.apache.hadoop.yarn.server.resourcemanager.scheduler.AppSchedulingInfo: checking for deactivate... 
2013-08-07 03:24:02,981 INFO org.apache.hadoop.yarn.server.resourcemanager.rmcontainer.RMContainerImpl: container_1375845418464_0004_01_000002 Container Transitioned from ACQUIRED to RUNNING
2013-08-07 03:24:03,215 INFO org.apache.hadoop.yarn.server.resourcemanager.rmcontainer.RMContainerImpl: container_1375845418464_0004_01_000003 Container Transitioned from ACQUIRED to RUNNING
2013-08-07 03:25:51,759 INFO org.apache.hadoop.yarn.server.resourcemanager.rmcontainer.RMContainerImpl: container_1375845418464_0004_01_000002 Container Transitioned from RUNNING to COMPLETED
2013-08-07 03:25:51,759 INFO org.apache.hadoop.yarn.server.resourcemanager.scheduler.common.fica.FiCaSchedulerApp: Completed container: container_1375845418464_0004_01_000002 in state: COMPLETED event:FINISHED
2013-08-07 03:25:51,759 INFO org.apache.hadoop.yarn.server.resourcemanager.RMAuditLogger: USER=ubuntu	OPERATION=AM Released Container	TARGET=SchedulerApp	RESULT=SUCCESS	APPID=application_1375845418464_0004	CONTAINERID=container_1375845418464_0004_01_000002
2013-08-07 03:25:51,759 INFO org.apache.hadoop.yarn.server.resourcemanager.scheduler.common.fica.FiCaSchedulerNode: Released container container_1375845418464_0004_01_000002 of capacity <memory:1024, vCores:1> on host hadoop-200-3:52180, which currently has 1 containers, <memory:2048, vCores:1> used and <memory:6144, vCores:15> available, release resources=true
2013-08-07 03:25:51,759 INFO org.apache.hadoop.yarn.server.resourcemanager.scheduler.capacity.LeafQueue: default used=<memory:3072, vCores:2> numContainers=2 user=ubuntu user-resources=<memory:3072, vCores:2>
2013-08-07 03:25:51,761 INFO org.apache.hadoop.yarn.server.resourcemanager.scheduler.capacity.LeafQueue: completedContainer container=Container: [ContainerId: container_1375845418464_0004_01_000002, NodeId: hadoop-200-3:52180, NodeHttpAddress: hadoop-200-3:8042, Resource: <memory:1024, vCores:1>, Priority: 20, State: NEW, Token: null, Status: container_id {, app_attempt_id {, application_id {, id: 4, cluster_timestamp: 1375845418464, }, attemptId: 1, }, id: 2, }, state: C_COMPLETE, diagnostics: "Container killed by the ApplicationMaster.\n", exit_status: 0, ] resource=<memory:1024, vCores:1> queue=default: capacity=1.0, absoluteCapacity=1.0, usedResources=<memory:3072, vCores:2>usedCapacity=0.0625, absoluteUsedCapacity=0.0625, numApps=1, numContainers=2 usedCapacity=0.0625 absoluteUsedCapacity=0.0625 used=<memory:3072, vCores:2> cluster=<memory:49152, vCores:96>
2013-08-07 03:25:51,762 INFO org.apache.hadoop.yarn.server.resourcemanager.scheduler.capacity.ParentQueue: completedContainer queue=root usedCapacity=0.0625 absoluteUsedCapacity=0.0625 used=<memory:3072, vCores:2> cluster=<memory:49152, vCores:96>
2013-08-07 03:25:51,762 INFO org.apache.hadoop.yarn.server.resourcemanager.scheduler.capacity.CapacityScheduler: Application appattempt_1375845418464_0004_000001 released container container_1375845418464_0004_01_000002 on node: host: hadoop-200-3:52180 #containers=1 available=6144 used=2048 with event: FINISHED
2013-08-07 03:25:54,060 INFO org.apache.hadoop.yarn.server.resourcemanager.rmcontainer.RMContainerImpl: container_1375845418464_0004_01_000003 Container Transitioned from RUNNING to COMPLETED
2013-08-07 03:25:54,061 INFO org.apache.hadoop.yarn.server.resourcemanager.scheduler.common.fica.FiCaSchedulerApp: Completed container: container_1375845418464_0004_01_000003 in state: COMPLETED event:FINISHED
2013-08-07 03:25:54,061 INFO org.apache.hadoop.yarn.server.resourcemanager.RMAuditLogger: USER=ubuntu	OPERATION=AM Released Container	TARGET=SchedulerApp	RESULT=SUCCESS	APPID=application_1375845418464_0004	CONTAINERID=container_1375845418464_0004_01_000003
2013-08-07 03:25:54,061 INFO org.apache.hadoop.yarn.server.resourcemanager.scheduler.common.fica.FiCaSchedulerNode: Released container container_1375845418464_0004_01_000003 of capacity <memory:1024, vCores:1> on host hadoop-200-6:45851, which currently has 0 containers, <memory:0, vCores:0> used and <memory:8192, vCores:16> available, release resources=true
2013-08-07 03:25:54,061 INFO org.apache.hadoop.yarn.server.resourcemanager.scheduler.capacity.LeafQueue: default used=<memory:2048, vCores:1> numContainers=1 user=ubuntu user-resources=<memory:2048, vCores:1>
2013-08-07 03:25:54,063 INFO org.apache.hadoop.yarn.server.resourcemanager.scheduler.capacity.LeafQueue: completedContainer container=Container: [ContainerId: container_1375845418464_0004_01_000003, NodeId: hadoop-200-6:45851, NodeHttpAddress: hadoop-200-6:8042, Resource: <memory:1024, vCores:1>, Priority: 20, State: NEW, Token: null, Status: container_id {, app_attempt_id {, application_id {, id: 4, cluster_timestamp: 1375845418464, }, attemptId: 1, }, id: 3, }, state: C_COMPLETE, diagnostics: "Container killed by the ApplicationMaster.\n\n", exit_status: 143, ] resource=<memory:1024, vCores:1> queue=default: capacity=1.0, absoluteCapacity=1.0, usedResources=<memory:2048, vCores:1>usedCapacity=0.041666668, absoluteUsedCapacity=0.041666668, numApps=1, numContainers=1 usedCapacity=0.041666668 absoluteUsedCapacity=0.041666668 used=<memory:2048, vCores:1> cluster=<memory:49152, vCores:96>
2013-08-07 03:25:54,063 INFO org.apache.hadoop.yarn.server.resourcemanager.scheduler.capacity.ParentQueue: completedContainer queue=root usedCapacity=0.041666668 absoluteUsedCapacity=0.041666668 used=<memory:2048, vCores:1> cluster=<memory:49152, vCores:96>
2013-08-07 03:25:54,063 INFO org.apache.hadoop.yarn.server.resourcemanager.scheduler.capacity.CapacityScheduler: Application appattempt_1375845418464_0004_000001 released container container_1375845418464_0004_01_000003 on node: host: hadoop-200-6:45851 #containers=0 available=8192 used=0 with event: FINISHED
2013-08-07 03:25:58,246 INFO org.apache.hadoop.yarn.server.resourcemanager.rmapp.attempt.RMAppAttemptImpl: appattempt_1375845418464_0004_000001 State change from RUNNING to FINISHING
2013-08-07 03:25:58,247 INFO org.apache.hadoop.yarn.server.resourcemanager.rmapp.RMAppImpl: application_1375845418464_0004 State change from RUNNING to FINISHING
2013-08-07 03:25:58,790 INFO org.apache.hadoop.yarn.server.resourcemanager.rmcontainer.RMContainerImpl: container_1375845418464_0004_01_000001 Container Transitioned from RUNNING to COMPLETED
2013-08-07 03:25:58,791 INFO org.apache.hadoop.yarn.server.resourcemanager.scheduler.common.fica.FiCaSchedulerApp: Completed container: container_1375845418464_0004_01_000001 in state: COMPLETED event:FINISHED
2013-08-07 03:25:58,791 INFO org.apache.hadoop.yarn.server.resourcemanager.RMAuditLogger: USER=ubuntu	OPERATION=AM Released Container	TARGET=SchedulerApp	RESULT=SUCCESS	APPID=application_1375845418464_0004	CONTAINERID=container_1375845418464_0004_01_000001
2013-08-07 03:25:58,791 INFO org.apache.hadoop.yarn.server.resourcemanager.scheduler.common.fica.FiCaSchedulerNode: Released container container_1375845418464_0004_01_000001 of capacity <memory:2048, vCores:1> on host hadoop-200-3:52180, which currently has 0 containers, <memory:0, vCores:0> used and <memory:8192, vCores:16> available, release resources=true
2013-08-07 03:25:58,791 INFO org.apache.hadoop.yarn.server.resourcemanager.scheduler.capacity.LeafQueue: default used=<memory:0, vCores:0> numContainers=0 user=ubuntu user-resources=<memory:0, vCores:0>
2013-08-07 03:25:58,792 INFO org.apache.hadoop.yarn.server.resourcemanager.scheduler.capacity.LeafQueue: completedContainer container=Container: [ContainerId: container_1375845418464_0004_01_000001, NodeId: hadoop-200-3:52180, NodeHttpAddress: hadoop-200-3:8042, Resource: <memory:2048, vCores:1>, Priority: 0, State: NEW, Token: null, Status: container_id {, app_attempt_id {, application_id {, id: 4, cluster_timestamp: 1375845418464, }, attemptId: 1, }, id: 1, }, state: C_COMPLETE, diagnostics: "", exit_status: 0, ] resource=<memory:2048, vCores:1> queue=default: capacity=1.0, absoluteCapacity=1.0, usedResources=<memory:0, vCores:0>usedCapacity=0.0, absoluteUsedCapacity=0.0, numApps=1, numContainers=0 usedCapacity=0.0 absoluteUsedCapacity=0.0 used=<memory:0, vCores:0> cluster=<memory:49152, vCores:96>
2013-08-07 03:25:58,793 INFO org.apache.hadoop.yarn.server.resourcemanager.scheduler.capacity.ParentQueue: completedContainer queue=root usedCapacity=0.0 absoluteUsedCapacity=0.0 used=<memory:0, vCores:0> cluster=<memory:49152, vCores:96>
2013-08-07 03:25:58,793 INFO org.apache.hadoop.yarn.server.resourcemanager.scheduler.capacity.CapacityScheduler: Application appattempt_1375845418464_0004_000001 released container container_1375845418464_0004_01_000001 on node: host: hadoop-200-3:52180 #containers=0 available=8192 used=0 with event: FINISHED
2013-08-07 03:25:58,793 INFO org.apache.hadoop.yarn.server.resourcemanager.rmapp.attempt.RMAppAttemptImpl: appattempt_1375845418464_0004_000001 State change from FINISHING to FINISHED
2013-08-07 03:25:58,794 INFO org.apache.hadoop.yarn.server.resourcemanager.rmapp.RMAppImpl: application_1375845418464_0004 State change from FINISHING to FINISHED
2013-08-07 03:25:58,794 INFO org.apache.hadoop.yarn.server.resourcemanager.scheduler.capacity.CapacityScheduler: Application appattempt_1375845418464_0004_000001 is done. finalState=FINISHED
2013-08-07 03:25:58,794 INFO org.apache.hadoop.yarn.server.resourcemanager.scheduler.AppSchedulingInfo: Application application_1375845418464_0004 requests cleared
2013-08-07 03:25:58,794 INFO org.apache.hadoop.yarn.server.resourcemanager.scheduler.capacity.LeafQueue: Application removed - appId: application_1375845418464_0004 user: ubuntu queue: default #user-pending-applications: 0 #user-active-applications: 0 #queue-pending-applications: 0 #queue-active-applications: 0
2013-08-07 03:25:58,794 INFO org.apache.hadoop.yarn.server.resourcemanager.scheduler.capacity.ParentQueue: Application removed - appId: application_1375845418464_0004 user: ubuntu leaf-queue of parent: root #applications: 0
2013-08-07 03:25:58,795 INFO org.apache.hadoop.yarn.server.resourcemanager.RMAuditLogger: USER=ubuntu	OPERATION=Application Finished - Succeeded	TARGET=RMAppManager	RESULT=SUCCESS	APPID=application_1375845418464_0004
2013-08-07 03:25:58,795 INFO org.apache.hadoop.yarn.server.resourcemanager.recovery.RMStateStore: Removing info for app: application_1375845418464_0004
2013-08-07 03:25:58,795 INFO org.apache.hadoop.yarn.server.resourcemanager.RMAppManager$ApplicationSummary: appId=application_1375845418464_0004,name=TeraGen,user=ubuntu,queue=default,state=FINISHED,trackingUrl=hadoop-200-1.novalocal:8088/proxy/application_1375845418464_0004/jobhistory/job/job_1375845418464_0004,appMasterHost=hadoop-200-3,startTime=1375845831760,finishTime=1375845958247
2013-08-07 03:25:58,796 INFO org.apache.hadoop.yarn.server.resourcemanager.amlauncher.AMLauncher: Cleaning master appattempt_1375845418464_0004_000001
2013-08-07 03:25:59,043 INFO org.apache.hadoop.yarn.server.resourcemanager.ClientRMService: Allocated new applicationId: 5
2013-08-07 03:26:00,846 INFO org.apache.hadoop.yarn.server.resourcemanager.ClientRMService: Storing Application with id application_1375845418464_0005
2013-08-07 03:26:00,846 INFO org.apache.hadoop.yarn.server.resourcemanager.recovery.RMStateStore: Storing info for app: application_1375845418464_0005
2013-08-07 03:26:00,847 INFO org.apache.hadoop.yarn.server.resourcemanager.ClientRMService: Application with id 5 submitted by user ubuntu
2013-08-07 03:26:00,847 INFO org.apache.hadoop.yarn.server.resourcemanager.RMAuditLogger: USER=ubuntu	IP=192.168.100.5	OPERATION=Submit Application Request	TARGET=ClientRMService	RESULT=SUCCESS	APPID=application_1375845418464_0005
2013-08-07 03:26:00,848 INFO org.apache.hadoop.yarn.server.resourcemanager.rmapp.RMAppImpl: application_1375845418464_0005 State change from NEW to SUBMITTED
2013-08-07 03:26:00,849 INFO org.apache.hadoop.yarn.server.resourcemanager.ApplicationMasterService: Registering appattempt_1375845418464_0005_000001
2013-08-07 03:26:00,849 INFO org.apache.hadoop.yarn.server.resourcemanager.rmapp.attempt.RMAppAttemptImpl: appattempt_1375845418464_0005_000001 State change from NEW to SUBMITTED
2013-08-07 03:26:00,850 INFO org.apache.hadoop.yarn.server.resourcemanager.scheduler.capacity.LeafQueue: Application application_1375845418464_0005 from user: ubuntu activated in queue: default
2013-08-07 03:26:00,850 INFO org.apache.hadoop.yarn.server.resourcemanager.scheduler.capacity.LeafQueue: Application added - appId: application_1375845418464_0005 user: org.apache.hadoop.yarn.server.resourcemanager.scheduler.capacity.LeafQueue$User@286ff682, leaf-queue: default #user-pending-applications: 0 #user-active-applications: 1 #queue-pending-applications: 0 #queue-active-applications: 1
2013-08-07 03:26:00,850 INFO org.apache.hadoop.yarn.server.resourcemanager.scheduler.capacity.ParentQueue: Application added - appId: application_1375845418464_0005 user: ubuntu leaf-queue of parent: root #applications: 1
2013-08-07 03:26:00,850 INFO org.apache.hadoop.yarn.server.resourcemanager.scheduler.capacity.CapacityScheduler: Application Submission: appattempt_1375845418464_0005_000001, user: ubuntu queue: default: capacity=1.0, absoluteCapacity=1.0, usedResources=<memory:0, vCores:0>usedCapacity=0.0, absoluteUsedCapacity=0.0, numApps=1, numContainers=0, currently active: 1
2013-08-07 03:26:00,852 INFO org.apache.hadoop.yarn.server.resourcemanager.rmapp.attempt.RMAppAttemptImpl: appattempt_1375845418464_0005_000001 State change from SUBMITTED to SCHEDULED
2013-08-07 03:26:00,852 INFO org.apache.hadoop.yarn.server.resourcemanager.rmapp.RMAppImpl: application_1375845418464_0005 State change from SUBMITTED to ACCEPTED
2013-08-07 03:26:00,901 INFO org.apache.hadoop.yarn.server.resourcemanager.rmcontainer.RMContainerImpl: container_1375845418464_0005_01_000001 Container Transitioned from NEW to ALLOCATED
2013-08-07 03:26:00,901 INFO org.apache.hadoop.yarn.server.resourcemanager.RMAuditLogger: USER=ubuntu	OPERATION=AM Allocated Container	TARGET=SchedulerApp	RESULT=SUCCESS	APPID=application_1375845418464_0005	CONTAINERID=container_1375845418464_0005_01_000001
2013-08-07 03:26:00,901 INFO org.apache.hadoop.yarn.server.resourcemanager.scheduler.common.fica.FiCaSchedulerNode: Assigned container container_1375845418464_0005_01_000001 of capacity <memory:2048, vCores:1> on host hadoop-200-2:46099, which currently has 1 containers, <memory:2048, vCores:1> used and <memory:6144, vCores:15> available
2013-08-07 03:26:00,902 INFO org.apache.hadoop.yarn.server.resourcemanager.scheduler.capacity.LeafQueue: assignedContainer application=application_1375845418464_0005 container=Container: [ContainerId: container_1375845418464_0005_01_000001, NodeId: hadoop-200-2:46099, NodeHttpAddress: hadoop-200-2:8042, Resource: <memory:2048, vCores:1>, Priority: 0, State: NEW, Token: null, Status: container_id {, app_attempt_id {, application_id {, id: 5, cluster_timestamp: 1375845418464, }, attemptId: 1, }, id: 1, }, state: C_NEW, ] containerId=container_1375845418464_0005_01_000001 queue=default: capacity=1.0, absoluteCapacity=1.0, usedResources=<memory:0, vCores:0>usedCapacity=0.0, absoluteUsedCapacity=0.0, numApps=1, numContainers=0 usedCapacity=0.0 absoluteUsedCapacity=0.0 used=<memory:0, vCores:0> cluster=<memory:49152, vCores:96>
2013-08-07 03:26:00,903 INFO org.apache.hadoop.yarn.server.resourcemanager.scheduler.capacity.ParentQueue: Re-sorting queues since queue: root.default stats: default: capacity=1.0, absoluteCapacity=1.0, usedResources=<memory:2048, vCores:1>usedCapacity=0.041666668, absoluteUsedCapacity=0.041666668, numApps=1, numContainers=1
2013-08-07 03:26:00,904 INFO org.apache.hadoop.yarn.server.resourcemanager.scheduler.capacity.ParentQueue: assignedContainer queue=root usedCapacity=0.041666668 absoluteUsedCapacity=0.041666668 used=<memory:2048, vCores:1> cluster=<memory:49152, vCores:96>
2013-08-07 03:26:00,904 INFO org.apache.hadoop.yarn.server.resourcemanager.rmcontainer.RMContainerImpl: container_1375845418464_0005_01_000001 Container Transitioned from ALLOCATED to ACQUIRED
2013-08-07 03:26:00,906 INFO org.apache.hadoop.yarn.server.resourcemanager.rmapp.attempt.RMAppAttemptImpl: Storing attempt: AppId: application_1375845418464_0005 AttemptId: appattempt_1375845418464_0005_000001 MasterContainer: Container: [ContainerId: container_1375845418464_0005_01_000001, NodeId: hadoop-200-2:46099, NodeHttpAddress: hadoop-200-2:8042, Resource: <memory:2048, vCores:1>, Priority: 0, State: NEW, Token: null, Status: container_id {, app_attempt_id {, application_id {, id: 5, cluster_timestamp: 1375845418464, }, attemptId: 1, }, id: 1, }, state: C_NEW, ]
2013-08-07 03:26:00,907 INFO org.apache.hadoop.yarn.server.resourcemanager.rmapp.attempt.RMAppAttemptImpl: appattempt_1375845418464_0005_000001 State change from SCHEDULED to ALLOCATED_SAVING
2013-08-07 03:26:00,907 INFO org.apache.hadoop.yarn.server.resourcemanager.recovery.RMStateStore: Storing info for attempt: appattempt_1375845418464_0005_000001
2013-08-07 03:26:00,908 INFO org.apache.hadoop.yarn.server.resourcemanager.rmapp.attempt.RMAppAttemptImpl: appattempt_1375845418464_0005_000001 State change from ALLOCATED_SAVING to ALLOCATED
2013-08-07 03:26:00,910 INFO org.apache.hadoop.yarn.server.resourcemanager.amlauncher.AMLauncher: Launching masterappattempt_1375845418464_0005_000001
2013-08-07 03:26:00,912 INFO org.apache.hadoop.yarn.server.resourcemanager.amlauncher.AMLauncher: Setting up container Container: [ContainerId: container_1375845418464_0005_01_000001, NodeId: hadoop-200-2:46099, NodeHttpAddress: hadoop-200-2:8042, Resource: <memory:2048, vCores:1>, Priority: 0, State: NEW, Token: null, Status: container_id {, app_attempt_id {, application_id {, id: 5, cluster_timestamp: 1375845418464, }, attemptId: 1, }, id: 1, }, state: C_NEW, ] for AM appattempt_1375845418464_0005_000001
2013-08-07 03:26:00,912 INFO org.apache.hadoop.yarn.server.resourcemanager.amlauncher.AMLauncher: Command to launch container container_1375845418464_0005_01_000001 : $JAVA_HOME/bin/java -Dlog4j.configuration=container-log4j.properties -Dyarn.app.mapreduce.container.log.dir=<LOG_DIR> -Dyarn.app.mapreduce.container.log.filesize=0 -Dhadoop.root.logger=INFO,CLA  -Xmx1024m org.apache.hadoop.mapreduce.v2.app.MRAppMaster 1><LOG_DIR>/stdout 2><LOG_DIR>/stderr 
2013-08-07 03:26:00,946 INFO org.apache.hadoop.yarn.server.resourcemanager.amlauncher.AMLauncher: Done launching container Container: [ContainerId: container_1375845418464_0005_01_000001, NodeId: hadoop-200-2:46099, NodeHttpAddress: hadoop-200-2:8042, Resource: <memory:2048, vCores:1>, Priority: 0, State: NEW, Token: null, Status: container_id {, app_attempt_id {, application_id {, id: 5, cluster_timestamp: 1375845418464, }, attemptId: 1, }, id: 1, }, state: C_NEW, ] for AM appattempt_1375845418464_0005_000001
2013-08-07 03:26:00,947 INFO org.apache.hadoop.yarn.server.resourcemanager.rmapp.attempt.RMAppAttemptImpl: appattempt_1375845418464_0005_000001 State change from ALLOCATED to LAUNCHED
2013-08-07 03:26:01,906 INFO org.apache.hadoop.yarn.server.resourcemanager.rmcontainer.RMContainerImpl: container_1375845418464_0005_01_000001 Container Transitioned from ACQUIRED to RUNNING
2013-08-07 03:26:07,551 INFO org.apache.hadoop.yarn.server.resourcemanager.ApplicationMasterService: AM registration appattempt_1375845418464_0005_000001
2013-08-07 03:26:07,552 INFO org.apache.hadoop.yarn.server.resourcemanager.RMAuditLogger: USER=ubuntu	IP=192.168.100.6	OPERATION=Register App Master	TARGET=ApplicationMasterService	RESULT=SUCCESS	APPID=application_1375845418464_0005	APPATTEMPTID=appattempt_1375845418464_0005_000001
2013-08-07 03:26:07,553 INFO org.apache.hadoop.yarn.server.resourcemanager.rmapp.attempt.RMAppAttemptImpl: appattempt_1375845418464_0005_000001 State change from LAUNCHED to RUNNING
2013-08-07 03:26:07,553 INFO org.apache.hadoop.yarn.server.resourcemanager.rmapp.RMAppImpl: application_1375845418464_0005 State change from ACCEPTED to RUNNING
2013-08-07 03:26:08,738 INFO org.apache.hadoop.yarn.server.resourcemanager.rmcontainer.RMContainerImpl: container_1375845418464_0005_01_000002 Container Transitioned from NEW to ALLOCATED
2013-08-07 03:26:08,739 INFO org.apache.hadoop.yarn.server.resourcemanager.RMAuditLogger: USER=ubuntu	OPERATION=AM Allocated Container	TARGET=SchedulerApp	RESULT=SUCCESS	APPID=application_1375845418464_0005	CONTAINERID=container_1375845418464_0005_01_000002
2013-08-07 03:26:08,739 INFO org.apache.hadoop.yarn.server.resourcemanager.scheduler.common.fica.FiCaSchedulerNode: Assigned container container_1375845418464_0005_01_000002 of capacity <memory:1024, vCores:1> on host hadoop-200-7:47421, which currently has 1 containers, <memory:1024, vCores:1> used and <memory:7168, vCores:15> available
2013-08-07 03:26:08,740 INFO org.apache.hadoop.yarn.server.resourcemanager.scheduler.capacity.LeafQueue: assignedContainer application=application_1375845418464_0005 container=Container: [ContainerId: container_1375845418464_0005_01_000002, NodeId: hadoop-200-7:47421, NodeHttpAddress: hadoop-200-7:8042, Resource: <memory:1024, vCores:1>, Priority: 20, State: NEW, Token: null, Status: container_id {, app_attempt_id {, application_id {, id: 5, cluster_timestamp: 1375845418464, }, attemptId: 1, }, id: 2, }, state: C_NEW, ] containerId=container_1375845418464_0005_01_000002 queue=default: capacity=1.0, absoluteCapacity=1.0, usedResources=<memory:2048, vCores:1>usedCapacity=0.041666668, absoluteUsedCapacity=0.041666668, numApps=1, numContainers=1 usedCapacity=0.041666668 absoluteUsedCapacity=0.041666668 used=<memory:2048, vCores:1> cluster=<memory:49152, vCores:96>
2013-08-07 03:26:08,740 INFO org.apache.hadoop.yarn.server.resourcemanager.scheduler.capacity.ParentQueue: Re-sorting queues since queue: root.default stats: default: capacity=1.0, absoluteCapacity=1.0, usedResources=<memory:3072, vCores:2>usedCapacity=0.0625, absoluteUsedCapacity=0.0625, numApps=1, numContainers=2
2013-08-07 03:26:08,740 INFO org.apache.hadoop.yarn.server.resourcemanager.scheduler.capacity.ParentQueue: assignedContainer queue=root usedCapacity=0.0625 absoluteUsedCapacity=0.0625 used=<memory:3072, vCores:2> cluster=<memory:49152, vCores:96>
2013-08-07 03:26:08,823 INFO org.apache.hadoop.yarn.server.resourcemanager.rmcontainer.RMContainerImpl: container_1375845418464_0005_01_000003 Container Transitioned from NEW to ALLOCATED
2013-08-07 03:26:08,823 INFO org.apache.hadoop.yarn.server.resourcemanager.RMAuditLogger: USER=ubuntu	OPERATION=AM Allocated Container	TARGET=SchedulerApp	RESULT=SUCCESS	APPID=application_1375845418464_0005	CONTAINERID=container_1375845418464_0005_01_000003
2013-08-07 03:26:08,823 INFO org.apache.hadoop.yarn.server.resourcemanager.scheduler.common.fica.FiCaSchedulerNode: Assigned container container_1375845418464_0005_01_000003 of capacity <memory:1024, vCores:1> on host hadoop-200-3:52180, which currently has 1 containers, <memory:1024, vCores:1> used and <memory:7168, vCores:15> available
2013-08-07 03:26:08,824 INFO org.apache.hadoop.yarn.server.resourcemanager.scheduler.capacity.LeafQueue: assignedContainer application=application_1375845418464_0005 container=Container: [ContainerId: container_1375845418464_0005_01_000003, NodeId: hadoop-200-3:52180, NodeHttpAddress: hadoop-200-3:8042, Resource: <memory:1024, vCores:1>, Priority: 20, State: NEW, Token: null, Status: container_id {, app_attempt_id {, application_id {, id: 5, cluster_timestamp: 1375845418464, }, attemptId: 1, }, id: 3, }, state: C_NEW, ] containerId=container_1375845418464_0005_01_000003 queue=default: capacity=1.0, absoluteCapacity=1.0, usedResources=<memory:3072, vCores:2>usedCapacity=0.0625, absoluteUsedCapacity=0.0625, numApps=1, numContainers=2 usedCapacity=0.0625 absoluteUsedCapacity=0.0625 used=<memory:3072, vCores:2> cluster=<memory:49152, vCores:96>
2013-08-07 03:26:08,824 INFO org.apache.hadoop.yarn.server.resourcemanager.scheduler.capacity.ParentQueue: Re-sorting queues since queue: root.default stats: default: capacity=1.0, absoluteCapacity=1.0, usedResources=<memory:4096, vCores:3>usedCapacity=0.083333336, absoluteUsedCapacity=0.083333336, numApps=1, numContainers=3
2013-08-07 03:26:08,825 INFO org.apache.hadoop.yarn.server.resourcemanager.scheduler.capacity.ParentQueue: assignedContainer queue=root usedCapacity=0.083333336 absoluteUsedCapacity=0.083333336 used=<memory:4096, vCores:3> cluster=<memory:49152, vCores:96>
2013-08-07 03:26:09,606 INFO org.apache.hadoop.yarn.server.resourcemanager.rmcontainer.RMContainerImpl: container_1375845418464_0005_01_000002 Container Transitioned from ALLOCATED to ACQUIRED
2013-08-07 03:26:09,610 INFO org.apache.hadoop.yarn.server.resourcemanager.rmcontainer.RMContainerImpl: container_1375845418464_0005_01_000003 Container Transitioned from ALLOCATED to ACQUIRED
2013-08-07 03:26:10,642 INFO org.apache.hadoop.yarn.server.resourcemanager.scheduler.AppSchedulingInfo: checking for deactivate... 
2013-08-07 03:26:10,747 INFO org.apache.hadoop.yarn.server.resourcemanager.rmcontainer.RMContainerImpl: container_1375845418464_0005_01_000002 Container Transitioned from ACQUIRED to RUNNING
2013-08-07 03:26:10,833 INFO org.apache.hadoop.yarn.server.resourcemanager.rmcontainer.RMContainerImpl: container_1375845418464_0005_01_000003 Container Transitioned from ACQUIRED to RUNNING
2013-08-07 03:27:51,099 INFO org.apache.hadoop.yarn.server.resourcemanager.rmcontainer.RMContainerImpl: container_1375845418464_0005_01_000002 Container Transitioned from RUNNING to COMPLETED
2013-08-07 03:27:51,099 INFO org.apache.hadoop.yarn.server.resourcemanager.scheduler.common.fica.FiCaSchedulerApp: Completed container: container_1375845418464_0005_01_000002 in state: COMPLETED event:FINISHED
2013-08-07 03:27:51,099 INFO org.apache.hadoop.yarn.server.resourcemanager.RMAuditLogger: USER=ubuntu	OPERATION=AM Released Container	TARGET=SchedulerApp	RESULT=SUCCESS	APPID=application_1375845418464_0005	CONTAINERID=container_1375845418464_0005_01_000002
2013-08-07 03:27:51,100 INFO org.apache.hadoop.yarn.server.resourcemanager.scheduler.common.fica.FiCaSchedulerNode: Released container container_1375845418464_0005_01_000002 of capacity <memory:1024, vCores:1> on host hadoop-200-7:47421, which currently has 0 containers, <memory:0, vCores:0> used and <memory:8192, vCores:16> available, release resources=true
2013-08-07 03:27:51,100 INFO org.apache.hadoop.yarn.server.resourcemanager.scheduler.capacity.LeafQueue: default used=<memory:3072, vCores:2> numContainers=2 user=ubuntu user-resources=<memory:3072, vCores:2>
2013-08-07 03:27:51,101 INFO org.apache.hadoop.yarn.server.resourcemanager.scheduler.capacity.LeafQueue: completedContainer container=Container: [ContainerId: container_1375845418464_0005_01_000002, NodeId: hadoop-200-7:47421, NodeHttpAddress: hadoop-200-7:8042, Resource: <memory:1024, vCores:1>, Priority: 20, State: NEW, Token: null, Status: container_id {, app_attempt_id {, application_id {, id: 5, cluster_timestamp: 1375845418464, }, attemptId: 1, }, id: 2, }, state: C_COMPLETE, diagnostics: "Container killed by the ApplicationMaster.\n\n", exit_status: 143, ] resource=<memory:1024, vCores:1> queue=default: capacity=1.0, absoluteCapacity=1.0, usedResources=<memory:3072, vCores:2>usedCapacity=0.0625, absoluteUsedCapacity=0.0625, numApps=1, numContainers=2 usedCapacity=0.0625 absoluteUsedCapacity=0.0625 used=<memory:3072, vCores:2> cluster=<memory:49152, vCores:96>
2013-08-07 03:27:51,102 INFO org.apache.hadoop.yarn.server.resourcemanager.scheduler.capacity.ParentQueue: completedContainer queue=root usedCapacity=0.0625 absoluteUsedCapacity=0.0625 used=<memory:3072, vCores:2> cluster=<memory:49152, vCores:96>
2013-08-07 03:27:51,102 INFO org.apache.hadoop.yarn.server.resourcemanager.scheduler.capacity.CapacityScheduler: Application appattempt_1375845418464_0005_000001 released container container_1375845418464_0005_01_000002 on node: host: hadoop-200-7:47421 #containers=0 available=8192 used=0 with event: FINISHED
2013-08-07 03:27:54,709 INFO org.apache.hadoop.yarn.server.resourcemanager.rmcontainer.RMContainerImpl: container_1375845418464_0005_01_000003 Container Transitioned from RUNNING to COMPLETED
2013-08-07 03:27:54,709 INFO org.apache.hadoop.yarn.server.resourcemanager.scheduler.common.fica.FiCaSchedulerApp: Completed container: container_1375845418464_0005_01_000003 in state: COMPLETED event:FINISHED
2013-08-07 03:27:54,709 INFO org.apache.hadoop.yarn.server.resourcemanager.RMAuditLogger: USER=ubuntu	OPERATION=AM Released Container	TARGET=SchedulerApp	RESULT=SUCCESS	APPID=application_1375845418464_0005	CONTAINERID=container_1375845418464_0005_01_000003
2013-08-07 03:27:54,709 INFO org.apache.hadoop.yarn.server.resourcemanager.scheduler.common.fica.FiCaSchedulerNode: Released container container_1375845418464_0005_01_000003 of capacity <memory:1024, vCores:1> on host hadoop-200-3:52180, which currently has 0 containers, <memory:0, vCores:0> used and <memory:8192, vCores:16> available, release resources=true
2013-08-07 03:27:54,709 INFO org.apache.hadoop.yarn.server.resourcemanager.scheduler.capacity.LeafQueue: default used=<memory:2048, vCores:1> numContainers=1 user=ubuntu user-resources=<memory:2048, vCores:1>
2013-08-07 03:27:54,711 INFO org.apache.hadoop.yarn.server.resourcemanager.scheduler.capacity.LeafQueue: completedContainer container=Container: [ContainerId: container_1375845418464_0005_01_000003, NodeId: hadoop-200-3:52180, NodeHttpAddress: hadoop-200-3:8042, Resource: <memory:1024, vCores:1>, Priority: 20, State: NEW, Token: null, Status: container_id {, app_attempt_id {, application_id {, id: 5, cluster_timestamp: 1375845418464, }, attemptId: 1, }, id: 3, }, state: C_COMPLETE, diagnostics: "Container killed by the ApplicationMaster.\n\n", exit_status: 143, ] resource=<memory:1024, vCores:1> queue=default: capacity=1.0, absoluteCapacity=1.0, usedResources=<memory:2048, vCores:1>usedCapacity=0.041666668, absoluteUsedCapacity=0.041666668, numApps=1, numContainers=1 usedCapacity=0.041666668 absoluteUsedCapacity=0.041666668 used=<memory:2048, vCores:1> cluster=<memory:49152, vCores:96>
2013-08-07 03:27:54,711 INFO org.apache.hadoop.yarn.server.resourcemanager.scheduler.capacity.ParentQueue: completedContainer queue=root usedCapacity=0.041666668 absoluteUsedCapacity=0.041666668 used=<memory:2048, vCores:1> cluster=<memory:49152, vCores:96>
2013-08-07 03:27:54,711 INFO org.apache.hadoop.yarn.server.resourcemanager.scheduler.capacity.CapacityScheduler: Application appattempt_1375845418464_0005_000001 released container container_1375845418464_0005_01_000003 on node: host: hadoop-200-3:52180 #containers=0 available=8192 used=0 with event: FINISHED
2013-08-07 03:27:58,851 INFO org.apache.hadoop.yarn.server.resourcemanager.rmapp.attempt.RMAppAttemptImpl: appattempt_1375845418464_0005_000001 State change from RUNNING to FINISHING
2013-08-07 03:27:58,851 INFO org.apache.hadoop.yarn.server.resourcemanager.rmapp.RMAppImpl: application_1375845418464_0005 State change from RUNNING to FINISHING
2013-08-07 03:27:59,434 INFO org.apache.hadoop.yarn.server.resourcemanager.rmcontainer.RMContainerImpl: container_1375845418464_0005_01_000001 Container Transitioned from RUNNING to COMPLETED
2013-08-07 03:27:59,435 INFO org.apache.hadoop.yarn.server.resourcemanager.scheduler.common.fica.FiCaSchedulerApp: Completed container: container_1375845418464_0005_01_000001 in state: COMPLETED event:FINISHED
2013-08-07 03:27:59,435 INFO org.apache.hadoop.yarn.server.resourcemanager.RMAuditLogger: USER=ubuntu	OPERATION=AM Released Container	TARGET=SchedulerApp	RESULT=SUCCESS	APPID=application_1375845418464_0005	CONTAINERID=container_1375845418464_0005_01_000001
2013-08-07 03:27:59,435 INFO org.apache.hadoop.yarn.server.resourcemanager.scheduler.common.fica.FiCaSchedulerNode: Released container container_1375845418464_0005_01_000001 of capacity <memory:2048, vCores:1> on host hadoop-200-2:46099, which currently has 0 containers, <memory:0, vCores:0> used and <memory:8192, vCores:16> available, release resources=true
2013-08-07 03:27:59,435 INFO org.apache.hadoop.yarn.server.resourcemanager.scheduler.capacity.LeafQueue: default used=<memory:0, vCores:0> numContainers=0 user=ubuntu user-resources=<memory:0, vCores:0>
2013-08-07 03:27:59,436 INFO org.apache.hadoop.yarn.server.resourcemanager.scheduler.capacity.LeafQueue: completedContainer container=Container: [ContainerId: container_1375845418464_0005_01_000001, NodeId: hadoop-200-2:46099, NodeHttpAddress: hadoop-200-2:8042, Resource: <memory:2048, vCores:1>, Priority: 0, State: NEW, Token: null, Status: container_id {, app_attempt_id {, application_id {, id: 5, cluster_timestamp: 1375845418464, }, attemptId: 1, }, id: 1, }, state: C_COMPLETE, diagnostics: "", exit_status: 0, ] resource=<memory:2048, vCores:1> queue=default: capacity=1.0, absoluteCapacity=1.0, usedResources=<memory:0, vCores:0>usedCapacity=0.0, absoluteUsedCapacity=0.0, numApps=1, numContainers=0 usedCapacity=0.0 absoluteUsedCapacity=0.0 used=<memory:0, vCores:0> cluster=<memory:49152, vCores:96>
2013-08-07 03:27:59,436 INFO org.apache.hadoop.yarn.server.resourcemanager.scheduler.capacity.ParentQueue: completedContainer queue=root usedCapacity=0.0 absoluteUsedCapacity=0.0 used=<memory:0, vCores:0> cluster=<memory:49152, vCores:96>
2013-08-07 03:27:59,436 INFO org.apache.hadoop.yarn.server.resourcemanager.scheduler.capacity.CapacityScheduler: Application appattempt_1375845418464_0005_000001 released container container_1375845418464_0005_01_000001 on node: host: hadoop-200-2:46099 #containers=0 available=8192 used=0 with event: FINISHED
2013-08-07 03:27:59,436 INFO org.apache.hadoop.yarn.server.resourcemanager.rmapp.attempt.RMAppAttemptImpl: appattempt_1375845418464_0005_000001 State change from FINISHING to FINISHED
2013-08-07 03:27:59,441 INFO org.apache.hadoop.yarn.server.resourcemanager.rmapp.RMAppImpl: application_1375845418464_0005 State change from FINISHING to FINISHED
2013-08-07 03:27:59,441 INFO org.apache.hadoop.yarn.server.resourcemanager.scheduler.capacity.CapacityScheduler: Application appattempt_1375845418464_0005_000001 is done. finalState=FINISHED
2013-08-07 03:27:59,441 INFO org.apache.hadoop.yarn.server.resourcemanager.scheduler.AppSchedulingInfo: Application application_1375845418464_0005 requests cleared
2013-08-07 03:27:59,441 INFO org.apache.hadoop.yarn.server.resourcemanager.scheduler.capacity.LeafQueue: Application removed - appId: application_1375845418464_0005 user: ubuntu queue: default #user-pending-applications: 0 #user-active-applications: 0 #queue-pending-applications: 0 #queue-active-applications: 0
2013-08-07 03:27:59,441 INFO org.apache.hadoop.yarn.server.resourcemanager.scheduler.capacity.ParentQueue: Application removed - appId: application_1375845418464_0005 user: ubuntu leaf-queue of parent: root #applications: 0
2013-08-07 03:27:59,441 INFO org.apache.hadoop.yarn.server.resourcemanager.RMAuditLogger: USER=ubuntu	OPERATION=Application Finished - Succeeded	TARGET=RMAppManager	RESULT=SUCCESS	APPID=application_1375845418464_0005
2013-08-07 03:27:59,442 INFO org.apache.hadoop.yarn.server.resourcemanager.recovery.RMStateStore: Removing info for app: application_1375845418464_0005
2013-08-07 03:27:59,442 INFO org.apache.hadoop.yarn.server.resourcemanager.RMAppManager$ApplicationSummary: appId=application_1375845418464_0005,name=TeraGen,user=ubuntu,queue=default,state=FINISHED,trackingUrl=hadoop-200-1.novalocal:8088/proxy/application_1375845418464_0005/jobhistory/job/job_1375845418464_0005,appMasterHost=hadoop-200-2,startTime=1375845960845,finishTime=1375846078851
2013-08-07 03:27:59,442 INFO org.apache.hadoop.yarn.server.resourcemanager.amlauncher.AMLauncher: Cleaning master appattempt_1375845418464_0005_000001
2013-08-07 03:28:03,693 INFO org.apache.hadoop.yarn.server.resourcemanager.ClientRMService: Allocated new applicationId: 6
2013-08-07 03:28:03,786 INFO org.apache.hadoop.yarn.server.resourcemanager.ClientRMService: Allocated new applicationId: 7
2013-08-07 03:28:04,132 INFO org.apache.hadoop.yarn.server.resourcemanager.ClientRMService: Allocated new applicationId: 8
2013-08-07 03:28:04,618 INFO org.apache.hadoop.yarn.server.resourcemanager.ClientRMService: Allocated new applicationId: 9
2013-08-07 03:28:04,673 INFO org.apache.hadoop.yarn.server.resourcemanager.ClientRMService: Allocated new applicationId: 10
2013-08-07 03:28:05,273 INFO org.apache.hadoop.yarn.server.resourcemanager.ClientRMService: Storing Application with id application_1375845418464_0006
2013-08-07 03:28:05,273 INFO org.apache.hadoop.yarn.server.resourcemanager.recovery.RMStateStore: Storing info for app: application_1375845418464_0006
2013-08-07 03:28:05,274 INFO org.apache.hadoop.yarn.server.resourcemanager.ClientRMService: Application with id 6 submitted by user ubuntu
2013-08-07 03:28:05,274 INFO org.apache.hadoop.yarn.server.resourcemanager.RMAuditLogger: USER=ubuntu	IP=192.168.100.5	OPERATION=Submit Application Request	TARGET=ClientRMService	RESULT=SUCCESS	APPID=application_1375845418464_0006
2013-08-07 03:28:05,274 INFO org.apache.hadoop.yarn.server.resourcemanager.rmapp.RMAppImpl: application_1375845418464_0006 State change from NEW to SUBMITTED
2013-08-07 03:28:05,274 INFO org.apache.hadoop.yarn.server.resourcemanager.ApplicationMasterService: Registering appattempt_1375845418464_0006_000001
2013-08-07 03:28:05,274 INFO org.apache.hadoop.yarn.server.resourcemanager.rmapp.attempt.RMAppAttemptImpl: appattempt_1375845418464_0006_000001 State change from NEW to SUBMITTED
2013-08-07 03:28:05,275 INFO org.apache.hadoop.yarn.server.resourcemanager.scheduler.capacity.LeafQueue: Application application_1375845418464_0006 from user: ubuntu activated in queue: default
2013-08-07 03:28:05,275 INFO org.apache.hadoop.yarn.server.resourcemanager.scheduler.capacity.LeafQueue: Application added - appId: application_1375845418464_0006 user: org.apache.hadoop.yarn.server.resourcemanager.scheduler.capacity.LeafQueue$User@3a792e4, leaf-queue: default #user-pending-applications: 0 #user-active-applications: 1 #queue-pending-applications: 0 #queue-active-applications: 1
2013-08-07 03:28:05,275 INFO org.apache.hadoop.yarn.server.resourcemanager.scheduler.capacity.ParentQueue: Application added - appId: application_1375845418464_0006 user: ubuntu leaf-queue of parent: root #applications: 1
2013-08-07 03:28:05,275 INFO org.apache.hadoop.yarn.server.resourcemanager.scheduler.capacity.CapacityScheduler: Application Submission: appattempt_1375845418464_0006_000001, user: ubuntu queue: default: capacity=1.0, absoluteCapacity=1.0, usedResources=<memory:0, vCores:0>usedCapacity=0.0, absoluteUsedCapacity=0.0, numApps=1, numContainers=0, currently active: 1
2013-08-07 03:28:05,275 INFO org.apache.hadoop.yarn.server.resourcemanager.rmapp.attempt.RMAppAttemptImpl: appattempt_1375845418464_0006_000001 State change from SUBMITTED to SCHEDULED
2013-08-07 03:28:05,275 INFO org.apache.hadoop.yarn.server.resourcemanager.rmapp.RMAppImpl: application_1375845418464_0006 State change from SUBMITTED to ACCEPTED
2013-08-07 03:28:05,396 INFO org.apache.hadoop.yarn.server.resourcemanager.ClientRMService: Storing Application with id application_1375845418464_0007
2013-08-07 03:28:05,396 INFO org.apache.hadoop.yarn.server.resourcemanager.recovery.RMStateStore: Storing info for app: application_1375845418464_0007
2013-08-07 03:28:05,396 INFO org.apache.hadoop.yarn.server.resourcemanager.ClientRMService: Application with id 7 submitted by user ubuntu
2013-08-07 03:28:05,396 INFO org.apache.hadoop.yarn.server.resourcemanager.RMAuditLogger: USER=ubuntu	IP=192.168.100.5	OPERATION=Submit Application Request	TARGET=ClientRMService	RESULT=SUCCESS	APPID=application_1375845418464_0007
2013-08-07 03:28:05,396 INFO org.apache.hadoop.yarn.server.resourcemanager.rmapp.RMAppImpl: application_1375845418464_0007 State change from NEW to SUBMITTED
2013-08-07 03:28:05,396 INFO org.apache.hadoop.yarn.server.resourcemanager.ApplicationMasterService: Registering appattempt_1375845418464_0007_000001
2013-08-07 03:28:05,396 INFO org.apache.hadoop.yarn.server.resourcemanager.rmapp.attempt.RMAppAttemptImpl: appattempt_1375845418464_0007_000001 State change from NEW to SUBMITTED
2013-08-07 03:28:05,397 INFO org.apache.hadoop.yarn.server.resourcemanager.scheduler.capacity.LeafQueue: Application application_1375845418464_0007 from user: ubuntu activated in queue: default
2013-08-07 03:28:05,397 INFO org.apache.hadoop.yarn.server.resourcemanager.scheduler.capacity.LeafQueue: Application added - appId: application_1375845418464_0007 user: org.apache.hadoop.yarn.server.resourcemanager.scheduler.capacity.LeafQueue$User@3a792e4, leaf-queue: default #user-pending-applications: 0 #user-active-applications: 2 #queue-pending-applications: 0 #queue-active-applications: 2
2013-08-07 03:28:05,397 INFO org.apache.hadoop.yarn.server.resourcemanager.scheduler.capacity.ParentQueue: Application added - appId: application_1375845418464_0007 user: ubuntu leaf-queue of parent: root #applications: 2
2013-08-07 03:28:05,397 INFO org.apache.hadoop.yarn.server.resourcemanager.scheduler.capacity.CapacityScheduler: Application Submission: appattempt_1375845418464_0007_000001, user: ubuntu queue: default: capacity=1.0, absoluteCapacity=1.0, usedResources=<memory:0, vCores:0>usedCapacity=0.0, absoluteUsedCapacity=0.0, numApps=2, numContainers=0, currently active: 2
2013-08-07 03:28:05,397 INFO org.apache.hadoop.yarn.server.resourcemanager.rmapp.attempt.RMAppAttemptImpl: appattempt_1375845418464_0007_000001 State change from SUBMITTED to SCHEDULED
2013-08-07 03:28:05,397 INFO org.apache.hadoop.yarn.server.resourcemanager.rmapp.RMAppImpl: application_1375845418464_0007 State change from SUBMITTED to ACCEPTED
2013-08-07 03:28:05,454 INFO org.apache.hadoop.yarn.server.resourcemanager.rmcontainer.RMContainerImpl: container_1375845418464_0006_01_000001 Container Transitioned from NEW to ALLOCATED
2013-08-07 03:28:05,454 INFO org.apache.hadoop.yarn.server.resourcemanager.RMAuditLogger: USER=ubuntu	OPERATION=AM Allocated Container	TARGET=SchedulerApp	RESULT=SUCCESS	APPID=application_1375845418464_0006	CONTAINERID=container_1375845418464_0006_01_000001
2013-08-07 03:28:05,454 INFO org.apache.hadoop.yarn.server.resourcemanager.scheduler.common.fica.FiCaSchedulerNode: Assigned container container_1375845418464_0006_01_000001 of capacity <memory:2048, vCores:1> on host hadoop-200-2:46099, which currently has 1 containers, <memory:2048, vCores:1> used and <memory:6144, vCores:15> available
2013-08-07 03:28:05,455 INFO org.apache.hadoop.yarn.server.resourcemanager.scheduler.capacity.LeafQueue: assignedContainer application=application_1375845418464_0006 container=Container: [ContainerId: container_1375845418464_0006_01_000001, NodeId: hadoop-200-2:46099, NodeHttpAddress: hadoop-200-2:8042, Resource: <memory:2048, vCores:1>, Priority: 0, State: NEW, Token: null, Status: container_id {, app_attempt_id {, application_id {, id: 6, cluster_timestamp: 1375845418464, }, attemptId: 1, }, id: 1, }, state: C_NEW, ] containerId=container_1375845418464_0006_01_000001 queue=default: capacity=1.0, absoluteCapacity=1.0, usedResources=<memory:0, vCores:0>usedCapacity=0.0, absoluteUsedCapacity=0.0, numApps=2, numContainers=0 usedCapacity=0.0 absoluteUsedCapacity=0.0 used=<memory:0, vCores:0> cluster=<memory:49152, vCores:96>
2013-08-07 03:28:05,455 INFO org.apache.hadoop.yarn.server.resourcemanager.scheduler.capacity.ParentQueue: Re-sorting queues since queue: root.default stats: default: capacity=1.0, absoluteCapacity=1.0, usedResources=<memory:2048, vCores:1>usedCapacity=0.041666668, absoluteUsedCapacity=0.041666668, numApps=2, numContainers=1
2013-08-07 03:28:05,455 INFO org.apache.hadoop.yarn.server.resourcemanager.scheduler.capacity.ParentQueue: assignedContainer queue=root usedCapacity=0.041666668 absoluteUsedCapacity=0.041666668 used=<memory:2048, vCores:1> cluster=<memory:49152, vCores:96>
2013-08-07 03:28:05,455 INFO org.apache.hadoop.yarn.server.resourcemanager.rmcontainer.RMContainerImpl: container_1375845418464_0006_01_000001 Container Transitioned from ALLOCATED to ACQUIRED
2013-08-07 03:28:05,456 INFO org.apache.hadoop.yarn.server.resourcemanager.rmapp.attempt.RMAppAttemptImpl: Storing attempt: AppId: application_1375845418464_0006 AttemptId: appattempt_1375845418464_0006_000001 MasterContainer: Container: [ContainerId: container_1375845418464_0006_01_000001, NodeId: hadoop-200-2:46099, NodeHttpAddress: hadoop-200-2:8042, Resource: <memory:2048, vCores:1>, Priority: 0, State: NEW, Token: null, Status: container_id {, app_attempt_id {, application_id {, id: 6, cluster_timestamp: 1375845418464, }, attemptId: 1, }, id: 1, }, state: C_NEW, ]
2013-08-07 03:28:05,456 INFO org.apache.hadoop.yarn.server.resourcemanager.rmapp.attempt.RMAppAttemptImpl: appattempt_1375845418464_0006_000001 State change from SCHEDULED to ALLOCATED_SAVING
2013-08-07 03:28:05,456 INFO org.apache.hadoop.yarn.server.resourcemanager.recovery.RMStateStore: Storing info for attempt: appattempt_1375845418464_0006_000001
2013-08-07 03:28:05,459 INFO org.apache.hadoop.yarn.server.resourcemanager.rmapp.attempt.RMAppAttemptImpl: appattempt_1375845418464_0006_000001 State change from ALLOCATED_SAVING to ALLOCATED
2013-08-07 03:28:05,459 INFO org.apache.hadoop.yarn.server.resourcemanager.amlauncher.AMLauncher: Launching masterappattempt_1375845418464_0006_000001
2013-08-07 03:28:05,460 INFO org.apache.hadoop.yarn.server.resourcemanager.amlauncher.AMLauncher: Setting up container Container: [ContainerId: container_1375845418464_0006_01_000001, NodeId: hadoop-200-2:46099, NodeHttpAddress: hadoop-200-2:8042, Resource: <memory:2048, vCores:1>, Priority: 0, State: NEW, Token: null, Status: container_id {, app_attempt_id {, application_id {, id: 6, cluster_timestamp: 1375845418464, }, attemptId: 1, }, id: 1, }, state: C_NEW, ] for AM appattempt_1375845418464_0006_000001
2013-08-07 03:28:05,460 INFO org.apache.hadoop.yarn.server.resourcemanager.amlauncher.AMLauncher: Command to launch container container_1375845418464_0006_01_000001 : $JAVA_HOME/bin/java -Dlog4j.configuration=container-log4j.properties -Dyarn.app.mapreduce.container.log.dir=<LOG_DIR> -Dyarn.app.mapreduce.container.log.filesize=0 -Dhadoop.root.logger=INFO,CLA  -Xmx1024m org.apache.hadoop.mapreduce.v2.app.MRAppMaster 1><LOG_DIR>/stdout 2><LOG_DIR>/stderr 
2013-08-07 03:28:05,472 INFO org.apache.hadoop.yarn.server.resourcemanager.amlauncher.AMLauncher: Done launching container Container: [ContainerId: container_1375845418464_0006_01_000001, NodeId: hadoop-200-2:46099, NodeHttpAddress: hadoop-200-2:8042, Resource: <memory:2048, vCores:1>, Priority: 0, State: NEW, Token: null, Status: container_id {, app_attempt_id {, application_id {, id: 6, cluster_timestamp: 1375845418464, }, attemptId: 1, }, id: 1, }, state: C_NEW, ] for AM appattempt_1375845418464_0006_000001
2013-08-07 03:28:05,473 INFO org.apache.hadoop.yarn.server.resourcemanager.rmapp.attempt.RMAppAttemptImpl: appattempt_1375845418464_0006_000001 State change from ALLOCATED to LAUNCHED
2013-08-07 03:28:05,548 INFO org.apache.hadoop.yarn.server.resourcemanager.ClientRMService: Storing Application with id application_1375845418464_0008
2013-08-07 03:28:05,549 INFO org.apache.hadoop.yarn.server.resourcemanager.recovery.RMStateStore: Storing info for app: application_1375845418464_0008
2013-08-07 03:28:05,549 INFO org.apache.hadoop.yarn.server.resourcemanager.ClientRMService: Application with id 8 submitted by user ubuntu
2013-08-07 03:28:05,549 INFO org.apache.hadoop.yarn.server.resourcemanager.RMAuditLogger: USER=ubuntu	IP=192.168.100.5	OPERATION=Submit Application Request	TARGET=ClientRMService	RESULT=SUCCESS	APPID=application_1375845418464_0008
2013-08-07 03:28:05,548 INFO org.apache.hadoop.yarn.server.resourcemanager.rmapp.RMAppImpl: application_1375845418464_0008 State change from NEW to SUBMITTED
2013-08-07 03:28:05,549 INFO org.apache.hadoop.yarn.server.resourcemanager.ApplicationMasterService: Registering appattempt_1375845418464_0008_000001
2013-08-07 03:28:05,549 INFO org.apache.hadoop.yarn.server.resourcemanager.rmapp.attempt.RMAppAttemptImpl: appattempt_1375845418464_0008_000001 State change from NEW to SUBMITTED
2013-08-07 03:28:05,550 INFO org.apache.hadoop.yarn.server.resourcemanager.scheduler.capacity.LeafQueue: Application application_1375845418464_0008 from user: ubuntu activated in queue: default
2013-08-07 03:28:05,550 INFO org.apache.hadoop.yarn.server.resourcemanager.scheduler.capacity.LeafQueue: Application added - appId: application_1375845418464_0008 user: org.apache.hadoop.yarn.server.resourcemanager.scheduler.capacity.LeafQueue$User@3a792e4, leaf-queue: default #user-pending-applications: 0 #user-active-applications: 3 #queue-pending-applications: 0 #queue-active-applications: 3
2013-08-07 03:28:05,550 INFO org.apache.hadoop.yarn.server.resourcemanager.scheduler.capacity.ParentQueue: Application added - appId: application_1375845418464_0008 user: ubuntu leaf-queue of parent: root #applications: 3
2013-08-07 03:28:05,550 INFO org.apache.hadoop.yarn.server.resourcemanager.scheduler.capacity.CapacityScheduler: Application Submission: appattempt_1375845418464_0008_000001, user: ubuntu queue: default: capacity=1.0, absoluteCapacity=1.0, usedResources=<memory:2048, vCores:1>usedCapacity=0.041666668, absoluteUsedCapacity=0.041666668, numApps=3, numContainers=1, currently active: 3
2013-08-07 03:28:05,551 INFO org.apache.hadoop.yarn.server.resourcemanager.rmapp.attempt.RMAppAttemptImpl: appattempt_1375845418464_0008_000001 State change from SUBMITTED to SCHEDULED
2013-08-07 03:28:05,551 INFO org.apache.hadoop.yarn.server.resourcemanager.rmapp.RMAppImpl: application_1375845418464_0008 State change from SUBMITTED to ACCEPTED
2013-08-07 03:28:05,572 INFO org.apache.hadoop.yarn.server.resourcemanager.rmcontainer.RMContainerImpl: container_1375845418464_0007_01_000001 Container Transitioned from NEW to ALLOCATED
2013-08-07 03:28:05,573 INFO org.apache.hadoop.yarn.server.resourcemanager.RMAuditLogger: USER=ubuntu	OPERATION=AM Allocated Container	TARGET=SchedulerApp	RESULT=SUCCESS	APPID=application_1375845418464_0007	CONTAINERID=container_1375845418464_0007_01_000001
2013-08-07 03:28:05,573 INFO org.apache.hadoop.yarn.server.resourcemanager.scheduler.common.fica.FiCaSchedulerNode: Assigned container container_1375845418464_0007_01_000001 of capacity <memory:2048, vCores:1> on host hadoop-200-6:45851, which currently has 1 containers, <memory:2048, vCores:1> used and <memory:6144, vCores:15> available
2013-08-07 03:28:05,573 INFO org.apache.hadoop.yarn.server.resourcemanager.scheduler.capacity.LeafQueue: assignedContainer application=application_1375845418464_0007 container=Container: [ContainerId: container_1375845418464_0007_01_000001, NodeId: hadoop-200-6:45851, NodeHttpAddress: hadoop-200-6:8042, Resource: <memory:2048, vCores:1>, Priority: 0, State: NEW, Token: null, Status: container_id {, app_attempt_id {, application_id {, id: 7, cluster_timestamp: 1375845418464, }, attemptId: 1, }, id: 1, }, state: C_NEW, ] containerId=container_1375845418464_0007_01_000001 queue=default: capacity=1.0, absoluteCapacity=1.0, usedResources=<memory:2048, vCores:1>usedCapacity=0.041666668, absoluteUsedCapacity=0.041666668, numApps=3, numContainers=1 usedCapacity=0.041666668 absoluteUsedCapacity=0.041666668 used=<memory:2048, vCores:1> cluster=<memory:49152, vCores:96>
2013-08-07 03:28:05,574 INFO org.apache.hadoop.yarn.server.resourcemanager.scheduler.capacity.ParentQueue: Re-sorting queues since queue: root.default stats: default: capacity=1.0, absoluteCapacity=1.0, usedResources=<memory:4096, vCores:2>usedCapacity=0.083333336, absoluteUsedCapacity=0.083333336, numApps=3, numContainers=2
2013-08-07 03:28:05,574 INFO org.apache.hadoop.yarn.server.resourcemanager.rmcontainer.RMContainerImpl: container_1375845418464_0007_01_000001 Container Transitioned from ALLOCATED to ACQUIRED
2013-08-07 03:28:05,574 INFO org.apache.hadoop.yarn.server.resourcemanager.scheduler.capacity.ParentQueue: assignedContainer queue=root usedCapacity=0.083333336 absoluteUsedCapacity=0.083333336 used=<memory:4096, vCores:2> cluster=<memory:49152, vCores:96>
2013-08-07 03:28:05,575 INFO org.apache.hadoop.yarn.server.resourcemanager.rmapp.attempt.RMAppAttemptImpl: Storing attempt: AppId: application_1375845418464_0007 AttemptId: appattempt_1375845418464_0007_000001 MasterContainer: Container: [ContainerId: container_1375845418464_0007_01_000001, NodeId: hadoop-200-6:45851, NodeHttpAddress: hadoop-200-6:8042, Resource: <memory:2048, vCores:1>, Priority: 0, State: NEW, Token: null, Status: container_id {, app_attempt_id {, application_id {, id: 7, cluster_timestamp: 1375845418464, }, attemptId: 1, }, id: 1, }, state: C_NEW, ]
2013-08-07 03:28:05,575 INFO org.apache.hadoop.yarn.server.resourcemanager.recovery.RMStateStore: Storing info for attempt: appattempt_1375845418464_0007_000001
2013-08-07 03:28:05,575 INFO org.apache.hadoop.yarn.server.resourcemanager.rmapp.attempt.RMAppAttemptImpl: appattempt_1375845418464_0007_000001 State change from SCHEDULED to ALLOCATED_SAVING
2013-08-07 03:28:05,575 INFO org.apache.hadoop.yarn.server.resourcemanager.rmapp.attempt.RMAppAttemptImpl: appattempt_1375845418464_0007_000001 State change from ALLOCATED_SAVING to ALLOCATED
2013-08-07 03:28:05,576 INFO org.apache.hadoop.yarn.server.resourcemanager.amlauncher.AMLauncher: Launching masterappattempt_1375845418464_0007_000001
2013-08-07 03:28:05,577 INFO org.apache.hadoop.yarn.server.resourcemanager.amlauncher.AMLauncher: Setting up container Container: [ContainerId: container_1375845418464_0007_01_000001, NodeId: hadoop-200-6:45851, NodeHttpAddress: hadoop-200-6:8042, Resource: <memory:2048, vCores:1>, Priority: 0, State: NEW, Token: null, Status: container_id {, app_attempt_id {, application_id {, id: 7, cluster_timestamp: 1375845418464, }, attemptId: 1, }, id: 1, }, state: C_NEW, ] for AM appattempt_1375845418464_0007_000001
2013-08-07 03:28:05,577 INFO org.apache.hadoop.yarn.server.resourcemanager.amlauncher.AMLauncher: Command to launch container container_1375845418464_0007_01_000001 : $JAVA_HOME/bin/java -Dlog4j.configuration=container-log4j.properties -Dyarn.app.mapreduce.container.log.dir=<LOG_DIR> -Dyarn.app.mapreduce.container.log.filesize=0 -Dhadoop.root.logger=INFO,CLA  -Xmx1024m org.apache.hadoop.mapreduce.v2.app.MRAppMaster 1><LOG_DIR>/stdout 2><LOG_DIR>/stderr 
2013-08-07 03:28:05,589 INFO org.apache.hadoop.yarn.server.resourcemanager.amlauncher.AMLauncher: Done launching container Container: [ContainerId: container_1375845418464_0007_01_000001, NodeId: hadoop-200-6:45851, NodeHttpAddress: hadoop-200-6:8042, Resource: <memory:2048, vCores:1>, Priority: 0, State: NEW, Token: null, Status: container_id {, app_attempt_id {, application_id {, id: 7, cluster_timestamp: 1375845418464, }, attemptId: 1, }, id: 1, }, state: C_NEW, ] for AM appattempt_1375845418464_0007_000001
2013-08-07 03:28:05,590 INFO org.apache.hadoop.yarn.server.resourcemanager.rmapp.attempt.RMAppAttemptImpl: appattempt_1375845418464_0007_000001 State change from ALLOCATED to LAUNCHED
2013-08-07 03:28:05,742 INFO org.apache.hadoop.yarn.server.resourcemanager.rmcontainer.RMContainerImpl: container_1375845418464_0008_01_000001 Container Transitioned from NEW to ALLOCATED
2013-08-07 03:28:05,743 INFO org.apache.hadoop.yarn.server.resourcemanager.RMAuditLogger: USER=ubuntu	OPERATION=AM Allocated Container	TARGET=SchedulerApp	RESULT=SUCCESS	APPID=application_1375845418464_0008	CONTAINERID=container_1375845418464_0008_01_000001
2013-08-07 03:28:05,743 INFO org.apache.hadoop.yarn.server.resourcemanager.scheduler.common.fica.FiCaSchedulerNode: Assigned container container_1375845418464_0008_01_000001 of capacity <memory:2048, vCores:1> on host hadoop-200-3:52180, which currently has 1 containers, <memory:2048, vCores:1> used and <memory:6144, vCores:15> available
2013-08-07 03:28:05,743 INFO org.apache.hadoop.yarn.server.resourcemanager.scheduler.capacity.LeafQueue: assignedContainer application=application_1375845418464_0008 container=Container: [ContainerId: container_1375845418464_0008_01_000001, NodeId: hadoop-200-3:52180, NodeHttpAddress: hadoop-200-3:8042, Resource: <memory:2048, vCores:1>, Priority: 0, State: NEW, Token: null, Status: container_id {, app_attempt_id {, application_id {, id: 8, cluster_timestamp: 1375845418464, }, attemptId: 1, }, id: 1, }, state: C_NEW, ] containerId=container_1375845418464_0008_01_000001 queue=default: capacity=1.0, absoluteCapacity=1.0, usedResources=<memory:4096, vCores:2>usedCapacity=0.083333336, absoluteUsedCapacity=0.083333336, numApps=3, numContainers=2 usedCapacity=0.083333336 absoluteUsedCapacity=0.083333336 used=<memory:4096, vCores:2> cluster=<memory:49152, vCores:96>
2013-08-07 03:28:05,744 INFO org.apache.hadoop.yarn.server.resourcemanager.scheduler.capacity.ParentQueue: Re-sorting queues since queue: root.default stats: default: capacity=1.0, absoluteCapacity=1.0, usedResources=<memory:6144, vCores:3>usedCapacity=0.125, absoluteUsedCapacity=0.125, numApps=3, numContainers=3
2013-08-07 03:28:05,744 INFO org.apache.hadoop.yarn.server.resourcemanager.scheduler.capacity.ParentQueue: assignedContainer queue=root usedCapacity=0.125 absoluteUsedCapacity=0.125 used=<memory:6144, vCores:3> cluster=<memory:49152, vCores:96>
2013-08-07 03:28:05,744 INFO org.apache.hadoop.yarn.server.resourcemanager.rmcontainer.RMContainerImpl: container_1375845418464_0008_01_000001 Container Transitioned from ALLOCATED to ACQUIRED
2013-08-07 03:28:05,746 INFO org.apache.hadoop.yarn.server.resourcemanager.rmapp.attempt.RMAppAttemptImpl: Storing attempt: AppId: application_1375845418464_0008 AttemptId: appattempt_1375845418464_0008_000001 MasterContainer: Container: [ContainerId: container_1375845418464_0008_01_000001, NodeId: hadoop-200-3:52180, NodeHttpAddress: hadoop-200-3:8042, Resource: <memory:2048, vCores:1>, Priority: 0, State: NEW, Token: null, Status: container_id {, app_attempt_id {, application_id {, id: 8, cluster_timestamp: 1375845418464, }, attemptId: 1, }, id: 1, }, state: C_NEW, ]
2013-08-07 03:28:05,746 INFO org.apache.hadoop.yarn.server.resourcemanager.recovery.RMStateStore: Storing info for attempt: appattempt_1375845418464_0008_000001
2013-08-07 03:28:05,747 INFO org.apache.hadoop.yarn.server.resourcemanager.rmapp.attempt.RMAppAttemptImpl: appattempt_1375845418464_0008_000001 State change from SCHEDULED to ALLOCATED_SAVING
2013-08-07 03:28:05,747 INFO org.apache.hadoop.yarn.server.resourcemanager.rmapp.attempt.RMAppAttemptImpl: appattempt_1375845418464_0008_000001 State change from ALLOCATED_SAVING to ALLOCATED
2013-08-07 03:28:05,747 INFO org.apache.hadoop.yarn.server.resourcemanager.amlauncher.AMLauncher: Launching masterappattempt_1375845418464_0008_000001
2013-08-07 03:28:05,749 INFO org.apache.hadoop.yarn.server.resourcemanager.amlauncher.AMLauncher: Setting up container Container: [ContainerId: container_1375845418464_0008_01_000001, NodeId: hadoop-200-3:52180, NodeHttpAddress: hadoop-200-3:8042, Resource: <memory:2048, vCores:1>, Priority: 0, State: NEW, Token: null, Status: container_id {, app_attempt_id {, application_id {, id: 8, cluster_timestamp: 1375845418464, }, attemptId: 1, }, id: 1, }, state: C_NEW, ] for AM appattempt_1375845418464_0008_000001
2013-08-07 03:28:05,749 INFO org.apache.hadoop.yarn.server.resourcemanager.amlauncher.AMLauncher: Command to launch container container_1375845418464_0008_01_000001 : $JAVA_HOME/bin/java -Dlog4j.configuration=container-log4j.properties -Dyarn.app.mapreduce.container.log.dir=<LOG_DIR> -Dyarn.app.mapreduce.container.log.filesize=0 -Dhadoop.root.logger=INFO,CLA  -Xmx1024m org.apache.hadoop.mapreduce.v2.app.MRAppMaster 1><LOG_DIR>/stdout 2><LOG_DIR>/stderr 
2013-08-07 03:28:05,761 INFO org.apache.hadoop.yarn.server.resourcemanager.amlauncher.AMLauncher: Done launching container Container: [ContainerId: container_1375845418464_0008_01_000001, NodeId: hadoop-200-3:52180, NodeHttpAddress: hadoop-200-3:8042, Resource: <memory:2048, vCores:1>, Priority: 0, State: NEW, Token: null, Status: container_id {, app_attempt_id {, application_id {, id: 8, cluster_timestamp: 1375845418464, }, attemptId: 1, }, id: 1, }, state: C_NEW, ] for AM appattempt_1375845418464_0008_000001
2013-08-07 03:28:05,761 INFO org.apache.hadoop.yarn.server.resourcemanager.rmapp.attempt.RMAppAttemptImpl: appattempt_1375845418464_0008_000001 State change from ALLOCATED to LAUNCHED
2013-08-07 03:28:06,055 INFO org.apache.hadoop.yarn.server.resourcemanager.ClientRMService: Storing Application with id application_1375845418464_0009
2013-08-07 03:28:06,061 INFO org.apache.hadoop.yarn.server.resourcemanager.recovery.RMStateStore: Storing info for app: application_1375845418464_0009
2013-08-07 03:28:06,061 INFO org.apache.hadoop.yarn.server.resourcemanager.ClientRMService: Application with id 9 submitted by user ubuntu
2013-08-07 03:28:06,062 INFO org.apache.hadoop.yarn.server.resourcemanager.RMAuditLogger: USER=ubuntu	IP=192.168.100.5	OPERATION=Submit Application Request	TARGET=ClientRMService	RESULT=SUCCESS	APPID=application_1375845418464_0009
2013-08-07 03:28:06,062 INFO org.apache.hadoop.yarn.server.resourcemanager.rmapp.RMAppImpl: application_1375845418464_0009 State change from NEW to SUBMITTED
2013-08-07 03:28:06,063 INFO org.apache.hadoop.yarn.server.resourcemanager.ApplicationMasterService: Registering appattempt_1375845418464_0009_000001
2013-08-07 03:28:06,063 INFO org.apache.hadoop.yarn.server.resourcemanager.rmapp.attempt.RMAppAttemptImpl: appattempt_1375845418464_0009_000001 State change from NEW to SUBMITTED
2013-08-07 03:28:06,063 INFO org.apache.hadoop.yarn.server.resourcemanager.scheduler.capacity.LeafQueue: Application application_1375845418464_0009 from user: ubuntu activated in queue: default
2013-08-07 03:28:06,063 INFO org.apache.hadoop.yarn.server.resourcemanager.scheduler.capacity.LeafQueue: Application added - appId: application_1375845418464_0009 user: org.apache.hadoop.yarn.server.resourcemanager.scheduler.capacity.LeafQueue$User@3a792e4, leaf-queue: default #user-pending-applications: 0 #user-active-applications: 4 #queue-pending-applications: 0 #queue-active-applications: 4
2013-08-07 03:28:06,063 INFO org.apache.hadoop.yarn.server.resourcemanager.scheduler.capacity.ParentQueue: Application added - appId: application_1375845418464_0009 user: ubuntu leaf-queue of parent: root #applications: 4
2013-08-07 03:28:06,063 INFO org.apache.hadoop.yarn.server.resourcemanager.scheduler.capacity.CapacityScheduler: Application Submission: appattempt_1375845418464_0009_000001, user: ubuntu queue: default: capacity=1.0, absoluteCapacity=1.0, usedResources=<memory:6144, vCores:3>usedCapacity=0.125, absoluteUsedCapacity=0.125, numApps=4, numContainers=3, currently active: 4
2013-08-07 03:28:06,064 INFO org.apache.hadoop.yarn.server.resourcemanager.rmapp.attempt.RMAppAttemptImpl: appattempt_1375845418464_0009_000001 State change from SUBMITTED to SCHEDULED
2013-08-07 03:28:06,064 INFO org.apache.hadoop.yarn.server.resourcemanager.rmapp.RMAppImpl: application_1375845418464_0009 State change from SUBMITTED to ACCEPTED
2013-08-07 03:28:06,146 INFO org.apache.hadoop.yarn.server.resourcemanager.rmcontainer.RMContainerImpl: container_1375845418464_0009_01_000001 Container Transitioned from NEW to ALLOCATED
2013-08-07 03:28:06,146 INFO org.apache.hadoop.yarn.server.resourcemanager.RMAuditLogger: USER=ubuntu	OPERATION=AM Allocated Container	TARGET=SchedulerApp	RESULT=SUCCESS	APPID=application_1375845418464_0009	CONTAINERID=container_1375845418464_0009_01_000001
2013-08-07 03:28:06,146 INFO org.apache.hadoop.yarn.server.resourcemanager.scheduler.common.fica.FiCaSchedulerNode: Assigned container container_1375845418464_0009_01_000001 of capacity <memory:2048, vCores:1> on host hadoop-200-7:47421, which currently has 1 containers, <memory:2048, vCores:1> used and <memory:6144, vCores:15> available
2013-08-07 03:28:06,147 INFO org.apache.hadoop.yarn.server.resourcemanager.scheduler.capacity.LeafQueue: assignedContainer application=application_1375845418464_0009 container=Container: [ContainerId: container_1375845418464_0009_01_000001, NodeId: hadoop-200-7:47421, NodeHttpAddress: hadoop-200-7:8042, Resource: <memory:2048, vCores:1>, Priority: 0, State: NEW, Token: null, Status: container_id {, app_attempt_id {, application_id {, id: 9, cluster_timestamp: 1375845418464, }, attemptId: 1, }, id: 1, }, state: C_NEW, ] containerId=container_1375845418464_0009_01_000001 queue=default: capacity=1.0, absoluteCapacity=1.0, usedResources=<memory:6144, vCores:3>usedCapacity=0.125, absoluteUsedCapacity=0.125, numApps=4, numContainers=3 usedCapacity=0.125 absoluteUsedCapacity=0.125 used=<memory:6144, vCores:3> cluster=<memory:49152, vCores:96>
2013-08-07 03:28:06,148 INFO org.apache.hadoop.yarn.server.resourcemanager.scheduler.capacity.ParentQueue: Re-sorting queues since queue: root.default stats: default: capacity=1.0, absoluteCapacity=1.0, usedResources=<memory:8192, vCores:4>usedCapacity=0.16666667, absoluteUsedCapacity=0.16666667, numApps=4, numContainers=4
2013-08-07 03:28:06,148 INFO org.apache.hadoop.yarn.server.resourcemanager.scheduler.capacity.ParentQueue: assignedContainer queue=root usedCapacity=0.16666667 absoluteUsedCapacity=0.16666667 used=<memory:8192, vCores:4> cluster=<memory:49152, vCores:96>
2013-08-07 03:28:06,149 INFO org.apache.hadoop.yarn.server.resourcemanager.rmcontainer.RMContainerImpl: container_1375845418464_0009_01_000001 Container Transitioned from ALLOCATED to ACQUIRED
2013-08-07 03:28:06,151 INFO org.apache.hadoop.yarn.server.resourcemanager.rmapp.attempt.RMAppAttemptImpl: Storing attempt: AppId: application_1375845418464_0009 AttemptId: appattempt_1375845418464_0009_000001 MasterContainer: Container: [ContainerId: container_1375845418464_0009_01_000001, NodeId: hadoop-200-7:47421, NodeHttpAddress: hadoop-200-7:8042, Resource: <memory:2048, vCores:1>, Priority: 0, State: NEW, Token: null, Status: container_id {, app_attempt_id {, application_id {, id: 9, cluster_timestamp: 1375845418464, }, attemptId: 1, }, id: 1, }, state: C_NEW, ]
2013-08-07 03:28:06,151 INFO org.apache.hadoop.yarn.server.resourcemanager.recovery.RMStateStore: Storing info for attempt: appattempt_1375845418464_0009_000001
2013-08-07 03:28:06,151 INFO org.apache.hadoop.yarn.server.resourcemanager.rmapp.attempt.RMAppAttemptImpl: appattempt_1375845418464_0009_000001 State change from SCHEDULED to ALLOCATED_SAVING
2013-08-07 03:28:06,152 INFO org.apache.hadoop.yarn.server.resourcemanager.rmapp.attempt.RMAppAttemptImpl: appattempt_1375845418464_0009_000001 State change from ALLOCATED_SAVING to ALLOCATED
2013-08-07 03:28:06,152 INFO org.apache.hadoop.yarn.server.resourcemanager.amlauncher.AMLauncher: Launching masterappattempt_1375845418464_0009_000001
2013-08-07 03:28:06,154 INFO org.apache.hadoop.yarn.server.resourcemanager.amlauncher.AMLauncher: Setting up container Container: [ContainerId: container_1375845418464_0009_01_000001, NodeId: hadoop-200-7:47421, NodeHttpAddress: hadoop-200-7:8042, Resource: <memory:2048, vCores:1>, Priority: 0, State: NEW, Token: null, Status: container_id {, app_attempt_id {, application_id {, id: 9, cluster_timestamp: 1375845418464, }, attemptId: 1, }, id: 1, }, state: C_NEW, ] for AM appattempt_1375845418464_0009_000001
2013-08-07 03:28:06,154 INFO org.apache.hadoop.yarn.server.resourcemanager.amlauncher.AMLauncher: Command to launch container container_1375845418464_0009_01_000001 : $JAVA_HOME/bin/java -Dlog4j.configuration=container-log4j.properties -Dyarn.app.mapreduce.container.log.dir=<LOG_DIR> -Dyarn.app.mapreduce.container.log.filesize=0 -Dhadoop.root.logger=INFO,CLA  -Xmx1024m org.apache.hadoop.mapreduce.v2.app.MRAppMaster 1><LOG_DIR>/stdout 2><LOG_DIR>/stderr 
2013-08-07 03:28:06,162 INFO org.apache.hadoop.yarn.server.resourcemanager.ClientRMService: Storing Application with id application_1375845418464_0010
2013-08-07 03:28:06,162 INFO org.apache.hadoop.yarn.server.resourcemanager.recovery.RMStateStore: Storing info for app: application_1375845418464_0010
2013-08-07 03:28:06,163 INFO org.apache.hadoop.yarn.server.resourcemanager.ClientRMService: Application with id 10 submitted by user ubuntu
2013-08-07 03:28:06,163 INFO org.apache.hadoop.yarn.server.resourcemanager.RMAuditLogger: USER=ubuntu	IP=192.168.100.5	OPERATION=Submit Application Request	TARGET=ClientRMService	RESULT=SUCCESS	APPID=application_1375845418464_0010
2013-08-07 03:28:06,164 INFO org.apache.hadoop.yarn.server.resourcemanager.rmapp.RMAppImpl: application_1375845418464_0010 State change from NEW to SUBMITTED
2013-08-07 03:28:06,164 INFO org.apache.hadoop.yarn.server.resourcemanager.ApplicationMasterService: Registering appattempt_1375845418464_0010_000001
2013-08-07 03:28:06,164 INFO org.apache.hadoop.yarn.server.resourcemanager.rmapp.attempt.RMAppAttemptImpl: appattempt_1375845418464_0010_000001 State change from NEW to SUBMITTED
2013-08-07 03:28:06,165 INFO org.apache.hadoop.yarn.server.resourcemanager.scheduler.capacity.LeafQueue: Application application_1375845418464_0010 from user: ubuntu activated in queue: default
2013-08-07 03:28:06,165 INFO org.apache.hadoop.yarn.server.resourcemanager.scheduler.capacity.LeafQueue: Application added - appId: application_1375845418464_0010 user: org.apache.hadoop.yarn.server.resourcemanager.scheduler.capacity.LeafQueue$User@3a792e4, leaf-queue: default #user-pending-applications: 0 #user-active-applications: 5 #queue-pending-applications: 0 #queue-active-applications: 5
2013-08-07 03:28:06,165 INFO org.apache.hadoop.yarn.server.resourcemanager.scheduler.capacity.ParentQueue: Application added - appId: application_1375845418464_0010 user: ubuntu leaf-queue of parent: root #applications: 5
2013-08-07 03:28:06,165 INFO org.apache.hadoop.yarn.server.resourcemanager.scheduler.capacity.CapacityScheduler: Application Submission: appattempt_1375845418464_0010_000001, user: ubuntu queue: default: capacity=1.0, absoluteCapacity=1.0, usedResources=<memory:8192, vCores:4>usedCapacity=0.16666667, absoluteUsedCapacity=0.16666667, numApps=5, numContainers=4, currently active: 5
2013-08-07 03:28:06,166 INFO org.apache.hadoop.yarn.server.resourcemanager.rmapp.attempt.RMAppAttemptImpl: appattempt_1375845418464_0010_000001 State change from SUBMITTED to SCHEDULED
2013-08-07 03:28:06,166 INFO org.apache.hadoop.yarn.server.resourcemanager.rmapp.RMAppImpl: application_1375845418464_0010 State change from SUBMITTED to ACCEPTED
2013-08-07 03:28:06,173 INFO org.apache.hadoop.yarn.server.resourcemanager.amlauncher.AMLauncher: Done launching container Container: [ContainerId: container_1375845418464_0009_01_000001, NodeId: hadoop-200-7:47421, NodeHttpAddress: hadoop-200-7:8042, Resource: <memory:2048, vCores:1>, Priority: 0, State: NEW, Token: null, Status: container_id {, app_attempt_id {, application_id {, id: 9, cluster_timestamp: 1375845418464, }, attemptId: 1, }, id: 1, }, state: C_NEW, ] for AM appattempt_1375845418464_0009_000001
2013-08-07 03:28:06,173 INFO org.apache.hadoop.yarn.server.resourcemanager.rmapp.attempt.RMAppAttemptImpl: appattempt_1375845418464_0009_000001 State change from ALLOCATED to LAUNCHED
2013-08-07 03:28:06,270 INFO org.apache.hadoop.yarn.server.resourcemanager.rmcontainer.RMContainerImpl: container_1375845418464_0010_01_000001 Container Transitioned from NEW to ALLOCATED
2013-08-07 03:28:06,273 INFO org.apache.hadoop.yarn.server.resourcemanager.RMAuditLogger: USER=ubuntu	OPERATION=AM Allocated Container	TARGET=SchedulerApp	RESULT=SUCCESS	APPID=application_1375845418464_0010	CONTAINERID=container_1375845418464_0010_01_000001
2013-08-07 03:28:06,273 INFO org.apache.hadoop.yarn.server.resourcemanager.scheduler.common.fica.FiCaSchedulerNode: Assigned container container_1375845418464_0010_01_000001 of capacity <memory:2048, vCores:1> on host hadoop-200-5:34756, which currently has 1 containers, <memory:2048, vCores:1> used and <memory:6144, vCores:15> available
2013-08-07 03:28:06,274 INFO org.apache.hadoop.yarn.server.resourcemanager.scheduler.capacity.LeafQueue: assignedContainer application=application_1375845418464_0010 container=Container: [ContainerId: container_1375845418464_0010_01_000001, NodeId: hadoop-200-5:34756, NodeHttpAddress: hadoop-200-5:8042, Resource: <memory:2048, vCores:1>, Priority: 0, State: NEW, Token: null, Status: container_id {, app_attempt_id {, application_id {, id: 10, cluster_timestamp: 1375845418464, }, attemptId: 1, }, id: 1, }, state: C_NEW, ] containerId=container_1375845418464_0010_01_000001 queue=default: capacity=1.0, absoluteCapacity=1.0, usedResources=<memory:8192, vCores:4>usedCapacity=0.16666667, absoluteUsedCapacity=0.16666667, numApps=5, numContainers=4 usedCapacity=0.16666667 absoluteUsedCapacity=0.16666667 used=<memory:8192, vCores:4> cluster=<memory:49152, vCores:96>
2013-08-07 03:28:06,275 INFO org.apache.hadoop.yarn.server.resourcemanager.scheduler.capacity.ParentQueue: Re-sorting queues since queue: root.default stats: default: capacity=1.0, absoluteCapacity=1.0, usedResources=<memory:10240, vCores:5>usedCapacity=0.20833333, absoluteUsedCapacity=0.20833333, numApps=5, numContainers=5
2013-08-07 03:28:06,276 INFO org.apache.hadoop.yarn.server.resourcemanager.rmcontainer.RMContainerImpl: container_1375845418464_0010_01_000001 Container Transitioned from ALLOCATED to ACQUIRED
2013-08-07 03:28:06,277 INFO org.apache.hadoop.yarn.server.resourcemanager.scheduler.capacity.ParentQueue: assignedContainer queue=root usedCapacity=0.20833333 absoluteUsedCapacity=0.20833333 used=<memory:10240, vCores:5> cluster=<memory:49152, vCores:96>
2013-08-07 03:28:06,278 INFO org.apache.hadoop.yarn.server.resourcemanager.rmapp.attempt.RMAppAttemptImpl: Storing attempt: AppId: application_1375845418464_0010 AttemptId: appattempt_1375845418464_0010_000001 MasterContainer: Container: [ContainerId: container_1375845418464_0010_01_000001, NodeId: hadoop-200-5:34756, NodeHttpAddress: hadoop-200-5:8042, Resource: <memory:2048, vCores:1>, Priority: 0, State: NEW, Token: null, Status: container_id {, app_attempt_id {, application_id {, id: 10, cluster_timestamp: 1375845418464, }, attemptId: 1, }, id: 1, }, state: C_NEW, ]
2013-08-07 03:28:06,278 INFO org.apache.hadoop.yarn.server.resourcemanager.rmapp.attempt.RMAppAttemptImpl: appattempt_1375845418464_0010_000001 State change from SCHEDULED to ALLOCATED_SAVING
2013-08-07 03:28:06,278 INFO org.apache.hadoop.yarn.server.resourcemanager.recovery.RMStateStore: Storing info for attempt: appattempt_1375845418464_0010_000001
2013-08-07 03:28:06,278 INFO org.apache.hadoop.yarn.server.resourcemanager.rmapp.attempt.RMAppAttemptImpl: appattempt_1375845418464_0010_000001 State change from ALLOCATED_SAVING to ALLOCATED
2013-08-07 03:28:06,279 INFO org.apache.hadoop.yarn.server.resourcemanager.amlauncher.AMLauncher: Launching masterappattempt_1375845418464_0010_000001
2013-08-07 03:28:06,280 INFO org.apache.hadoop.yarn.server.resourcemanager.amlauncher.AMLauncher: Setting up container Container: [ContainerId: container_1375845418464_0010_01_000001, NodeId: hadoop-200-5:34756, NodeHttpAddress: hadoop-200-5:8042, Resource: <memory:2048, vCores:1>, Priority: 0, State: NEW, Token: null, Status: container_id {, app_attempt_id {, application_id {, id: 10, cluster_timestamp: 1375845418464, }, attemptId: 1, }, id: 1, }, state: C_NEW, ] for AM appattempt_1375845418464_0010_000001
2013-08-07 03:28:06,281 INFO org.apache.hadoop.yarn.server.resourcemanager.amlauncher.AMLauncher: Command to launch container container_1375845418464_0010_01_000001 : $JAVA_HOME/bin/java -Dlog4j.configuration=container-log4j.properties -Dyarn.app.mapreduce.container.log.dir=<LOG_DIR> -Dyarn.app.mapreduce.container.log.filesize=0 -Dhadoop.root.logger=INFO,CLA  -Xmx1024m org.apache.hadoop.mapreduce.v2.app.MRAppMaster 1><LOG_DIR>/stdout 2><LOG_DIR>/stderr 
2013-08-07 03:28:06,295 INFO org.apache.hadoop.yarn.server.resourcemanager.amlauncher.AMLauncher: Done launching container Container: [ContainerId: container_1375845418464_0010_01_000001, NodeId: hadoop-200-5:34756, NodeHttpAddress: hadoop-200-5:8042, Resource: <memory:2048, vCores:1>, Priority: 0, State: NEW, Token: null, Status: container_id {, app_attempt_id {, application_id {, id: 10, cluster_timestamp: 1375845418464, }, attemptId: 1, }, id: 1, }, state: C_NEW, ] for AM appattempt_1375845418464_0010_000001
2013-08-07 03:28:06,296 INFO org.apache.hadoop.yarn.server.resourcemanager.rmapp.attempt.RMAppAttemptImpl: appattempt_1375845418464_0010_000001 State change from ALLOCATED to LAUNCHED
2013-08-07 03:28:06,459 INFO org.apache.hadoop.yarn.server.resourcemanager.rmcontainer.RMContainerImpl: container_1375845418464_0006_01_000001 Container Transitioned from ACQUIRED to RUNNING
2013-08-07 03:28:06,578 INFO org.apache.hadoop.yarn.server.resourcemanager.rmcontainer.RMContainerImpl: container_1375845418464_0007_01_000001 Container Transitioned from ACQUIRED to RUNNING
2013-08-07 03:28:06,748 INFO org.apache.hadoop.yarn.server.resourcemanager.rmcontainer.RMContainerImpl: container_1375845418464_0008_01_000001 Container Transitioned from ACQUIRED to RUNNING
2013-08-07 03:28:07,151 INFO org.apache.hadoop.yarn.server.resourcemanager.rmcontainer.RMContainerImpl: container_1375845418464_0009_01_000001 Container Transitioned from ACQUIRED to RUNNING
2013-08-07 03:28:07,275 INFO org.apache.hadoop.yarn.server.resourcemanager.rmcontainer.RMContainerImpl: container_1375845418464_0010_01_000001 Container Transitioned from ACQUIRED to RUNNING
2013-08-07 03:28:11,241 INFO org.apache.hadoop.yarn.server.resourcemanager.ApplicationMasterService: AM registration appattempt_1375845418464_0006_000001
2013-08-07 03:28:11,242 INFO org.apache.hadoop.yarn.server.resourcemanager.RMAuditLogger: USER=ubuntu	IP=192.168.100.6	OPERATION=Register App Master	TARGET=ApplicationMasterService	RESULT=SUCCESS	APPID=application_1375845418464_0006	APPATTEMPTID=appattempt_1375845418464_0006_000001
2013-08-07 03:28:11,243 INFO org.apache.hadoop.yarn.server.resourcemanager.rmapp.attempt.RMAppAttemptImpl: appattempt_1375845418464_0006_000001 State change from LAUNCHED to RUNNING
2013-08-07 03:28:11,243 INFO org.apache.hadoop.yarn.server.resourcemanager.rmapp.RMAppImpl: application_1375845418464_0006 State change from ACCEPTED to RUNNING
2013-08-07 03:28:12,300 INFO org.apache.hadoop.yarn.server.resourcemanager.rmcontainer.RMContainerImpl: container_1375845418464_0006_01_000002 Container Transitioned from NEW to ALLOCATED
2013-08-07 03:28:12,301 INFO org.apache.hadoop.yarn.server.resourcemanager.RMAuditLogger: USER=ubuntu	OPERATION=AM Allocated Container	TARGET=SchedulerApp	RESULT=SUCCESS	APPID=application_1375845418464_0006	CONTAINERID=container_1375845418464_0006_01_000002
2013-08-07 03:28:12,301 INFO org.apache.hadoop.yarn.server.resourcemanager.scheduler.common.fica.FiCaSchedulerNode: Assigned container container_1375845418464_0006_01_000002 of capacity <memory:1024, vCores:1> on host hadoop-200-5:34756, which currently has 2 containers, <memory:3072, vCores:2> used and <memory:5120, vCores:14> available
2013-08-07 03:28:12,302 INFO org.apache.hadoop.yarn.server.resourcemanager.scheduler.capacity.LeafQueue: assignedContainer application=application_1375845418464_0006 container=Container: [ContainerId: container_1375845418464_0006_01_000002, NodeId: hadoop-200-5:34756, NodeHttpAddress: hadoop-200-5:8042, Resource: <memory:1024, vCores:1>, Priority: 20, State: NEW, Token: null, Status: container_id {, app_attempt_id {, application_id {, id: 6, cluster_timestamp: 1375845418464, }, attemptId: 1, }, id: 2, }, state: C_NEW, ] containerId=container_1375845418464_0006_01_000002 queue=default: capacity=1.0, absoluteCapacity=1.0, usedResources=<memory:10240, vCores:5>usedCapacity=0.20833333, absoluteUsedCapacity=0.20833333, numApps=5, numContainers=5 usedCapacity=0.20833333 absoluteUsedCapacity=0.20833333 used=<memory:10240, vCores:5> cluster=<memory:49152, vCores:96>
2013-08-07 03:28:12,302 INFO org.apache.hadoop.yarn.server.resourcemanager.scheduler.capacity.ParentQueue: Re-sorting queues since queue: root.default stats: default: capacity=1.0, absoluteCapacity=1.0, usedResources=<memory:11264, vCores:6>usedCapacity=0.22916667, absoluteUsedCapacity=0.22916667, numApps=5, numContainers=6
2013-08-07 03:28:12,303 INFO org.apache.hadoop.yarn.server.resourcemanager.scheduler.capacity.ParentQueue: assignedContainer queue=root usedCapacity=0.22916667 absoluteUsedCapacity=0.22916667 used=<memory:11264, vCores:6> cluster=<memory:49152, vCores:96>
2013-08-07 03:28:12,303 INFO org.apache.hadoop.yarn.server.resourcemanager.rmcontainer.RMContainerImpl: container_1375845418464_0006_01_000003 Container Transitioned from NEW to ALLOCATED
2013-08-07 03:28:12,303 INFO org.apache.hadoop.yarn.server.resourcemanager.RMAuditLogger: USER=ubuntu	OPERATION=AM Allocated Container	TARGET=SchedulerApp	RESULT=SUCCESS	APPID=application_1375845418464_0006	CONTAINERID=container_1375845418464_0006_01_000003
2013-08-07 03:28:12,303 INFO org.apache.hadoop.yarn.server.resourcemanager.scheduler.common.fica.FiCaSchedulerNode: Assigned container container_1375845418464_0006_01_000003 of capacity <memory:1024, vCores:1> on host hadoop-200-5:34756, which currently has 3 containers, <memory:4096, vCores:3> used and <memory:4096, vCores:13> available
2013-08-07 03:28:12,304 INFO org.apache.hadoop.yarn.server.resourcemanager.scheduler.capacity.LeafQueue: assignedContainer application=application_1375845418464_0006 container=Container: [ContainerId: container_1375845418464_0006_01_000003, NodeId: hadoop-200-5:34756, NodeHttpAddress: hadoop-200-5:8042, Resource: <memory:1024, vCores:1>, Priority: 20, State: NEW, Token: null, Status: container_id {, app_attempt_id {, application_id {, id: 6, cluster_timestamp: 1375845418464, }, attemptId: 1, }, id: 3, }, state: C_NEW, ] containerId=container_1375845418464_0006_01_000003 queue=default: capacity=1.0, absoluteCapacity=1.0, usedResources=<memory:11264, vCores:6>usedCapacity=0.22916667, absoluteUsedCapacity=0.22916667, numApps=5, numContainers=6 usedCapacity=0.22916667 absoluteUsedCapacity=0.22916667 used=<memory:11264, vCores:6> cluster=<memory:49152, vCores:96>
2013-08-07 03:28:12,305 INFO org.apache.hadoop.yarn.server.resourcemanager.scheduler.capacity.ParentQueue: Re-sorting queues since queue: root.default stats: default: capacity=1.0, absoluteCapacity=1.0, usedResources=<memory:12288, vCores:7>usedCapacity=0.25, absoluteUsedCapacity=0.25, numApps=5, numContainers=7
2013-08-07 03:28:12,305 INFO org.apache.hadoop.yarn.server.resourcemanager.scheduler.capacity.ParentQueue: assignedContainer queue=root usedCapacity=0.25 absoluteUsedCapacity=0.25 used=<memory:12288, vCores:7> cluster=<memory:49152, vCores:96>
2013-08-07 03:28:12,305 INFO org.apache.hadoop.yarn.server.resourcemanager.rmcontainer.RMContainerImpl: container_1375845418464_0006_01_000004 Container Transitioned from NEW to ALLOCATED
2013-08-07 03:28:12,305 INFO org.apache.hadoop.yarn.server.resourcemanager.RMAuditLogger: USER=ubuntu	OPERATION=AM Allocated Container	TARGET=SchedulerApp	RESULT=SUCCESS	APPID=application_1375845418464_0006	CONTAINERID=container_1375845418464_0006_01_000004
2013-08-07 03:28:12,306 INFO org.apache.hadoop.yarn.server.resourcemanager.scheduler.common.fica.FiCaSchedulerNode: Assigned container container_1375845418464_0006_01_000004 of capacity <memory:1024, vCores:1> on host hadoop-200-5:34756, which currently has 4 containers, <memory:5120, vCores:4> used and <memory:3072, vCores:12> available
2013-08-07 03:28:12,307 INFO org.apache.hadoop.yarn.server.resourcemanager.scheduler.capacity.LeafQueue: assignedContainer application=application_1375845418464_0006 container=Container: [ContainerId: container_1375845418464_0006_01_000004, NodeId: hadoop-200-5:34756, NodeHttpAddress: hadoop-200-5:8042, Resource: <memory:1024, vCores:1>, Priority: 20, State: NEW, Token: null, Status: container_id {, app_attempt_id {, application_id {, id: 6, cluster_timestamp: 1375845418464, }, attemptId: 1, }, id: 4, }, state: C_NEW, ] containerId=container_1375845418464_0006_01_000004 queue=default: capacity=1.0, absoluteCapacity=1.0, usedResources=<memory:12288, vCores:7>usedCapacity=0.25, absoluteUsedCapacity=0.25, numApps=5, numContainers=7 usedCapacity=0.25 absoluteUsedCapacity=0.25 used=<memory:12288, vCores:7> cluster=<memory:49152, vCores:96>
2013-08-07 03:28:12,307 INFO org.apache.hadoop.yarn.server.resourcemanager.scheduler.capacity.ParentQueue: Re-sorting queues since queue: root.default stats: default: capacity=1.0, absoluteCapacity=1.0, usedResources=<memory:13312, vCores:8>usedCapacity=0.27083334, absoluteUsedCapacity=0.27083334, numApps=5, numContainers=8
2013-08-07 03:28:12,307 INFO org.apache.hadoop.yarn.server.resourcemanager.scheduler.capacity.ParentQueue: assignedContainer queue=root usedCapacity=0.27083334 absoluteUsedCapacity=0.27083334 used=<memory:13312, vCores:8> cluster=<memory:49152, vCores:96>
2013-08-07 03:28:12,308 INFO org.apache.hadoop.yarn.server.resourcemanager.rmcontainer.RMContainerImpl: container_1375845418464_0006_01_000005 Container Transitioned from NEW to ALLOCATED
2013-08-07 03:28:12,308 INFO org.apache.hadoop.yarn.server.resourcemanager.RMAuditLogger: USER=ubuntu	OPERATION=AM Allocated Container	TARGET=SchedulerApp	RESULT=SUCCESS	APPID=application_1375845418464_0006	CONTAINERID=container_1375845418464_0006_01_000005
2013-08-07 03:28:12,308 INFO org.apache.hadoop.yarn.server.resourcemanager.scheduler.common.fica.FiCaSchedulerNode: Assigned container container_1375845418464_0006_01_000005 of capacity <memory:1024, vCores:1> on host hadoop-200-5:34756, which currently has 5 containers, <memory:6144, vCores:5> used and <memory:2048, vCores:11> available
2013-08-07 03:28:12,309 INFO org.apache.hadoop.yarn.server.resourcemanager.scheduler.capacity.LeafQueue: assignedContainer application=application_1375845418464_0006 container=Container: [ContainerId: container_1375845418464_0006_01_000005, NodeId: hadoop-200-5:34756, NodeHttpAddress: hadoop-200-5:8042, Resource: <memory:1024, vCores:1>, Priority: 20, State: NEW, Token: null, Status: container_id {, app_attempt_id {, application_id {, id: 6, cluster_timestamp: 1375845418464, }, attemptId: 1, }, id: 5, }, state: C_NEW, ] containerId=container_1375845418464_0006_01_000005 queue=default: capacity=1.0, absoluteCapacity=1.0, usedResources=<memory:13312, vCores:8>usedCapacity=0.27083334, absoluteUsedCapacity=0.27083334, numApps=5, numContainers=8 usedCapacity=0.27083334 absoluteUsedCapacity=0.27083334 used=<memory:13312, vCores:8> cluster=<memory:49152, vCores:96>
2013-08-07 03:28:12,309 INFO org.apache.hadoop.yarn.server.resourcemanager.scheduler.capacity.ParentQueue: Re-sorting queues since queue: root.default stats: default: capacity=1.0, absoluteCapacity=1.0, usedResources=<memory:14336, vCores:9>usedCapacity=0.29166666, absoluteUsedCapacity=0.29166666, numApps=5, numContainers=9
2013-08-07 03:28:12,309 INFO org.apache.hadoop.yarn.server.resourcemanager.scheduler.capacity.ParentQueue: assignedContainer queue=root usedCapacity=0.29166666 absoluteUsedCapacity=0.29166666 used=<memory:14336, vCores:9> cluster=<memory:49152, vCores:96>
2013-08-07 03:28:12,310 INFO org.apache.hadoop.yarn.server.resourcemanager.rmcontainer.RMContainerImpl: container_1375845418464_0006_01_000006 Container Transitioned from NEW to ALLOCATED
2013-08-07 03:28:12,310 INFO org.apache.hadoop.yarn.server.resourcemanager.RMAuditLogger: USER=ubuntu	OPERATION=AM Allocated Container	TARGET=SchedulerApp	RESULT=SUCCESS	APPID=application_1375845418464_0006	CONTAINERID=container_1375845418464_0006_01_000006
2013-08-07 03:28:12,310 INFO org.apache.hadoop.yarn.server.resourcemanager.scheduler.common.fica.FiCaSchedulerNode: Assigned container container_1375845418464_0006_01_000006 of capacity <memory:1024, vCores:1> on host hadoop-200-5:34756, which currently has 6 containers, <memory:7168, vCores:6> used and <memory:1024, vCores:10> available
2013-08-07 03:28:12,311 INFO org.apache.hadoop.yarn.server.resourcemanager.scheduler.capacity.LeafQueue: assignedContainer application=application_1375845418464_0006 container=Container: [ContainerId: container_1375845418464_0006_01_000006, NodeId: hadoop-200-5:34756, NodeHttpAddress: hadoop-200-5:8042, Resource: <memory:1024, vCores:1>, Priority: 20, State: NEW, Token: null, Status: container_id {, app_attempt_id {, application_id {, id: 6, cluster_timestamp: 1375845418464, }, attemptId: 1, }, id: 6, }, state: C_NEW, ] containerId=container_1375845418464_0006_01_000006 queue=default: capacity=1.0, absoluteCapacity=1.0, usedResources=<memory:14336, vCores:9>usedCapacity=0.29166666, absoluteUsedCapacity=0.29166666, numApps=5, numContainers=9 usedCapacity=0.29166666 absoluteUsedCapacity=0.29166666 used=<memory:14336, vCores:9> cluster=<memory:49152, vCores:96>
2013-08-07 03:28:12,311 INFO org.apache.hadoop.yarn.server.resourcemanager.scheduler.capacity.ParentQueue: Re-sorting queues since queue: root.default stats: default: capacity=1.0, absoluteCapacity=1.0, usedResources=<memory:15360, vCores:10>usedCapacity=0.3125, absoluteUsedCapacity=0.3125, numApps=5, numContainers=10
2013-08-07 03:28:12,311 INFO org.apache.hadoop.yarn.server.resourcemanager.scheduler.capacity.ParentQueue: assignedContainer queue=root usedCapacity=0.3125 absoluteUsedCapacity=0.3125 used=<memory:15360, vCores:10> cluster=<memory:49152, vCores:96>
2013-08-07 03:28:12,312 INFO org.apache.hadoop.yarn.server.resourcemanager.rmcontainer.RMContainerImpl: container_1375845418464_0006_01_000007 Container Transitioned from NEW to ALLOCATED
2013-08-07 03:28:12,312 INFO org.apache.hadoop.yarn.server.resourcemanager.RMAuditLogger: USER=ubuntu	OPERATION=AM Allocated Container	TARGET=SchedulerApp	RESULT=SUCCESS	APPID=application_1375845418464_0006	CONTAINERID=container_1375845418464_0006_01_000007
2013-08-07 03:28:12,312 INFO org.apache.hadoop.yarn.server.resourcemanager.scheduler.common.fica.FiCaSchedulerNode: Assigned container container_1375845418464_0006_01_000007 of capacity <memory:1024, vCores:1> on host hadoop-200-5:34756, which currently has 7 containers, <memory:8192, vCores:7> used and <memory:0, vCores:9> available
2013-08-07 03:28:12,313 INFO org.apache.hadoop.yarn.server.resourcemanager.scheduler.capacity.LeafQueue: assignedContainer application=application_1375845418464_0006 container=Container: [ContainerId: container_1375845418464_0006_01_000007, NodeId: hadoop-200-5:34756, NodeHttpAddress: hadoop-200-5:8042, Resource: <memory:1024, vCores:1>, Priority: 20, State: NEW, Token: null, Status: container_id {, app_attempt_id {, application_id {, id: 6, cluster_timestamp: 1375845418464, }, attemptId: 1, }, id: 7, }, state: C_NEW, ] containerId=container_1375845418464_0006_01_000007 queue=default: capacity=1.0, absoluteCapacity=1.0, usedResources=<memory:15360, vCores:10>usedCapacity=0.3125, absoluteUsedCapacity=0.3125, numApps=5, numContainers=10 usedCapacity=0.3125 absoluteUsedCapacity=0.3125 used=<memory:15360, vCores:10> cluster=<memory:49152, vCores:96>
2013-08-07 03:28:12,313 INFO org.apache.hadoop.yarn.server.resourcemanager.scheduler.capacity.ParentQueue: Re-sorting queues since queue: root.default stats: default: capacity=1.0, absoluteCapacity=1.0, usedResources=<memory:16384, vCores:11>usedCapacity=0.33333334, absoluteUsedCapacity=0.33333334, numApps=5, numContainers=11
2013-08-07 03:28:12,314 INFO org.apache.hadoop.yarn.server.resourcemanager.scheduler.capacity.ParentQueue: assignedContainer queue=root usedCapacity=0.33333334 absoluteUsedCapacity=0.33333334 used=<memory:16384, vCores:11> cluster=<memory:49152, vCores:96>
2013-08-07 03:28:12,343 INFO org.apache.hadoop.yarn.server.resourcemanager.ApplicationMasterService: AM registration appattempt_1375845418464_0008_000001
2013-08-07 03:28:12,344 INFO org.apache.hadoop.yarn.server.resourcemanager.RMAuditLogger: USER=ubuntu	IP=192.168.100.9	OPERATION=Register App Master	TARGET=ApplicationMasterService	RESULT=SUCCESS	APPID=application_1375845418464_0008	APPATTEMPTID=appattempt_1375845418464_0008_000001
2013-08-07 03:28:12,344 INFO org.apache.hadoop.yarn.server.resourcemanager.rmapp.attempt.RMAppAttemptImpl: appattempt_1375845418464_0008_000001 State change from LAUNCHED to RUNNING
2013-08-07 03:28:12,345 INFO org.apache.hadoop.yarn.server.resourcemanager.rmapp.RMAppImpl: application_1375845418464_0008 State change from ACCEPTED to RUNNING
2013-08-07 03:28:12,493 INFO org.apache.hadoop.yarn.server.resourcemanager.rmcontainer.RMContainerImpl: container_1375845418464_0006_01_000008 Container Transitioned from NEW to ALLOCATED
2013-08-07 03:28:12,493 INFO org.apache.hadoop.yarn.server.resourcemanager.RMAuditLogger: USER=ubuntu	OPERATION=AM Allocated Container	TARGET=SchedulerApp	RESULT=SUCCESS	APPID=application_1375845418464_0006	CONTAINERID=container_1375845418464_0006_01_000008
2013-08-07 03:28:12,494 INFO org.apache.hadoop.yarn.server.resourcemanager.scheduler.common.fica.FiCaSchedulerNode: Assigned container container_1375845418464_0006_01_000008 of capacity <memory:1024, vCores:1> on host hadoop-200-2:46099, which currently has 2 containers, <memory:3072, vCores:2> used and <memory:5120, vCores:14> available
2013-08-07 03:28:12,496 INFO org.apache.hadoop.yarn.server.resourcemanager.scheduler.capacity.LeafQueue: assignedContainer application=application_1375845418464_0006 container=Container: [ContainerId: container_1375845418464_0006_01_000008, NodeId: hadoop-200-2:46099, NodeHttpAddress: hadoop-200-2:8042, Resource: <memory:1024, vCores:1>, Priority: 20, State: NEW, Token: null, Status: container_id {, app_attempt_id {, application_id {, id: 6, cluster_timestamp: 1375845418464, }, attemptId: 1, }, id: 8, }, state: C_NEW, ] containerId=container_1375845418464_0006_01_000008 queue=default: capacity=1.0, absoluteCapacity=1.0, usedResources=<memory:16384, vCores:11>usedCapacity=0.33333334, absoluteUsedCapacity=0.33333334, numApps=5, numContainers=11 usedCapacity=0.33333334 absoluteUsedCapacity=0.33333334 used=<memory:16384, vCores:11> cluster=<memory:49152, vCores:96>
2013-08-07 03:28:12,497 INFO org.apache.hadoop.yarn.server.resourcemanager.scheduler.capacity.ParentQueue: Re-sorting queues since queue: root.default stats: default: capacity=1.0, absoluteCapacity=1.0, usedResources=<memory:17408, vCores:12>usedCapacity=0.35416666, absoluteUsedCapacity=0.35416666, numApps=5, numContainers=12
2013-08-07 03:28:12,497 INFO org.apache.hadoop.yarn.server.resourcemanager.scheduler.capacity.ParentQueue: assignedContainer queue=root usedCapacity=0.35416666 absoluteUsedCapacity=0.35416666 used=<memory:17408, vCores:12> cluster=<memory:49152, vCores:96>
2013-08-07 03:28:12,497 INFO org.apache.hadoop.yarn.server.resourcemanager.rmcontainer.RMContainerImpl: container_1375845418464_0006_01_000009 Container Transitioned from NEW to ALLOCATED
2013-08-07 03:28:12,498 INFO org.apache.hadoop.yarn.server.resourcemanager.RMAuditLogger: USER=ubuntu	OPERATION=AM Allocated Container	TARGET=SchedulerApp	RESULT=SUCCESS	APPID=application_1375845418464_0006	CONTAINERID=container_1375845418464_0006_01_000009
2013-08-07 03:28:12,498 INFO org.apache.hadoop.yarn.server.resourcemanager.scheduler.common.fica.FiCaSchedulerNode: Assigned container container_1375845418464_0006_01_000009 of capacity <memory:1024, vCores:1> on host hadoop-200-2:46099, which currently has 3 containers, <memory:4096, vCores:3> used and <memory:4096, vCores:13> available
2013-08-07 03:28:12,499 INFO org.apache.hadoop.yarn.server.resourcemanager.scheduler.capacity.LeafQueue: assignedContainer application=application_1375845418464_0006 container=Container: [ContainerId: container_1375845418464_0006_01_000009, NodeId: hadoop-200-2:46099, NodeHttpAddress: hadoop-200-2:8042, Resource: <memory:1024, vCores:1>, Priority: 20, State: NEW, Token: null, Status: container_id {, app_attempt_id {, application_id {, id: 6, cluster_timestamp: 1375845418464, }, attemptId: 1, }, id: 9, }, state: C_NEW, ] containerId=container_1375845418464_0006_01_000009 queue=default: capacity=1.0, absoluteCapacity=1.0, usedResources=<memory:17408, vCores:12>usedCapacity=0.35416666, absoluteUsedCapacity=0.35416666, numApps=5, numContainers=12 usedCapacity=0.35416666 absoluteUsedCapacity=0.35416666 used=<memory:17408, vCores:12> cluster=<memory:49152, vCores:96>
2013-08-07 03:28:12,499 INFO org.apache.hadoop.yarn.server.resourcemanager.scheduler.capacity.ParentQueue: Re-sorting queues since queue: root.default stats: default: capacity=1.0, absoluteCapacity=1.0, usedResources=<memory:18432, vCores:13>usedCapacity=0.375, absoluteUsedCapacity=0.375, numApps=5, numContainers=13
2013-08-07 03:28:12,499 INFO org.apache.hadoop.yarn.server.resourcemanager.scheduler.capacity.ParentQueue: assignedContainer queue=root usedCapacity=0.375 absoluteUsedCapacity=0.375 used=<memory:18432, vCores:13> cluster=<memory:49152, vCores:96>
2013-08-07 03:28:12,500 INFO org.apache.hadoop.yarn.server.resourcemanager.rmcontainer.RMContainerImpl: container_1375845418464_0006_01_000010 Container Transitioned from NEW to ALLOCATED
2013-08-07 03:28:12,500 INFO org.apache.hadoop.yarn.server.resourcemanager.RMAuditLogger: USER=ubuntu	OPERATION=AM Allocated Container	TARGET=SchedulerApp	RESULT=SUCCESS	APPID=application_1375845418464_0006	CONTAINERID=container_1375845418464_0006_01_000010
2013-08-07 03:28:12,500 INFO org.apache.hadoop.yarn.server.resourcemanager.scheduler.common.fica.FiCaSchedulerNode: Assigned container container_1375845418464_0006_01_000010 of capacity <memory:1024, vCores:1> on host hadoop-200-2:46099, which currently has 4 containers, <memory:5120, vCores:4> used and <memory:3072, vCores:12> available
2013-08-07 03:28:12,501 INFO org.apache.hadoop.yarn.server.resourcemanager.scheduler.capacity.LeafQueue: assignedContainer application=application_1375845418464_0006 container=Container: [ContainerId: container_1375845418464_0006_01_000010, NodeId: hadoop-200-2:46099, NodeHttpAddress: hadoop-200-2:8042, Resource: <memory:1024, vCores:1>, Priority: 20, State: NEW, Token: null, Status: container_id {, app_attempt_id {, application_id {, id: 6, cluster_timestamp: 1375845418464, }, attemptId: 1, }, id: 10, }, state: C_NEW, ] containerId=container_1375845418464_0006_01_000010 queue=default: capacity=1.0, absoluteCapacity=1.0, usedResources=<memory:18432, vCores:13>usedCapacity=0.375, absoluteUsedCapacity=0.375, numApps=5, numContainers=13 usedCapacity=0.375 absoluteUsedCapacity=0.375 used=<memory:18432, vCores:13> cluster=<memory:49152, vCores:96>
2013-08-07 03:28:12,501 INFO org.apache.hadoop.yarn.server.resourcemanager.scheduler.capacity.ParentQueue: Re-sorting queues since queue: root.default stats: default: capacity=1.0, absoluteCapacity=1.0, usedResources=<memory:19456, vCores:14>usedCapacity=0.39583334, absoluteUsedCapacity=0.39583334, numApps=5, numContainers=14
2013-08-07 03:28:12,501 INFO org.apache.hadoop.yarn.server.resourcemanager.scheduler.capacity.ParentQueue: assignedContainer queue=root usedCapacity=0.39583334 absoluteUsedCapacity=0.39583334 used=<memory:19456, vCores:14> cluster=<memory:49152, vCores:96>
2013-08-07 03:28:12,502 INFO org.apache.hadoop.yarn.server.resourcemanager.rmcontainer.RMContainerImpl: container_1375845418464_0006_01_000011 Container Transitioned from NEW to ALLOCATED
2013-08-07 03:28:12,502 INFO org.apache.hadoop.yarn.server.resourcemanager.RMAuditLogger: USER=ubuntu	OPERATION=AM Allocated Container	TARGET=SchedulerApp	RESULT=SUCCESS	APPID=application_1375845418464_0006	CONTAINERID=container_1375845418464_0006_01_000011
2013-08-07 03:28:12,502 INFO org.apache.hadoop.yarn.server.resourcemanager.scheduler.common.fica.FiCaSchedulerNode: Assigned container container_1375845418464_0006_01_000011 of capacity <memory:1024, vCores:1> on host hadoop-200-2:46099, which currently has 5 containers, <memory:6144, vCores:5> used and <memory:2048, vCores:11> available
2013-08-07 03:28:12,503 INFO org.apache.hadoop.yarn.server.resourcemanager.scheduler.capacity.LeafQueue: assignedContainer application=application_1375845418464_0006 container=Container: [ContainerId: container_1375845418464_0006_01_000011, NodeId: hadoop-200-2:46099, NodeHttpAddress: hadoop-200-2:8042, Resource: <memory:1024, vCores:1>, Priority: 20, State: NEW, Token: null, Status: container_id {, app_attempt_id {, application_id {, id: 6, cluster_timestamp: 1375845418464, }, attemptId: 1, }, id: 11, }, state: C_NEW, ] containerId=container_1375845418464_0006_01_000011 queue=default: capacity=1.0, absoluteCapacity=1.0, usedResources=<memory:19456, vCores:14>usedCapacity=0.39583334, absoluteUsedCapacity=0.39583334, numApps=5, numContainers=14 usedCapacity=0.39583334 absoluteUsedCapacity=0.39583334 used=<memory:19456, vCores:14> cluster=<memory:49152, vCores:96>
2013-08-07 03:28:12,503 INFO org.apache.hadoop.yarn.server.resourcemanager.scheduler.capacity.ParentQueue: Re-sorting queues since queue: root.default stats: default: capacity=1.0, absoluteCapacity=1.0, usedResources=<memory:20480, vCores:15>usedCapacity=0.41666666, absoluteUsedCapacity=0.41666666, numApps=5, numContainers=15
2013-08-07 03:28:12,503 INFO org.apache.hadoop.yarn.server.resourcemanager.scheduler.capacity.ParentQueue: assignedContainer queue=root usedCapacity=0.41666666 absoluteUsedCapacity=0.41666666 used=<memory:20480, vCores:15> cluster=<memory:49152, vCores:96>
2013-08-07 03:28:12,504 INFO org.apache.hadoop.yarn.server.resourcemanager.rmcontainer.RMContainerImpl: container_1375845418464_0006_01_000012 Container Transitioned from NEW to ALLOCATED
2013-08-07 03:28:12,504 INFO org.apache.hadoop.yarn.server.resourcemanager.RMAuditLogger: USER=ubuntu	OPERATION=AM Allocated Container	TARGET=SchedulerApp	RESULT=SUCCESS	APPID=application_1375845418464_0006	CONTAINERID=container_1375845418464_0006_01_000012
2013-08-07 03:28:12,504 INFO org.apache.hadoop.yarn.server.resourcemanager.scheduler.common.fica.FiCaSchedulerNode: Assigned container container_1375845418464_0006_01_000012 of capacity <memory:1024, vCores:1> on host hadoop-200-2:46099, which currently has 6 containers, <memory:7168, vCores:6> used and <memory:1024, vCores:10> available
2013-08-07 03:28:12,505 INFO org.apache.hadoop.yarn.server.resourcemanager.scheduler.capacity.LeafQueue: assignedContainer application=application_1375845418464_0006 container=Container: [ContainerId: container_1375845418464_0006_01_000012, NodeId: hadoop-200-2:46099, NodeHttpAddress: hadoop-200-2:8042, Resource: <memory:1024, vCores:1>, Priority: 20, State: NEW, Token: null, Status: container_id {, app_attempt_id {, application_id {, id: 6, cluster_timestamp: 1375845418464, }, attemptId: 1, }, id: 12, }, state: C_NEW, ] containerId=container_1375845418464_0006_01_000012 queue=default: capacity=1.0, absoluteCapacity=1.0, usedResources=<memory:20480, vCores:15>usedCapacity=0.41666666, absoluteUsedCapacity=0.41666666, numApps=5, numContainers=15 usedCapacity=0.41666666 absoluteUsedCapacity=0.41666666 used=<memory:20480, vCores:15> cluster=<memory:49152, vCores:96>
2013-08-07 03:28:12,505 INFO org.apache.hadoop.yarn.server.resourcemanager.scheduler.capacity.ParentQueue: Re-sorting queues since queue: root.default stats: default: capacity=1.0, absoluteCapacity=1.0, usedResources=<memory:21504, vCores:16>usedCapacity=0.4375, absoluteUsedCapacity=0.4375, numApps=5, numContainers=16
2013-08-07 03:28:12,506 INFO org.apache.hadoop.yarn.server.resourcemanager.scheduler.capacity.ParentQueue: assignedContainer queue=root usedCapacity=0.4375 absoluteUsedCapacity=0.4375 used=<memory:21504, vCores:16> cluster=<memory:49152, vCores:96>
2013-08-07 03:28:12,506 INFO org.apache.hadoop.yarn.server.resourcemanager.rmcontainer.RMContainerImpl: container_1375845418464_0006_01_000013 Container Transitioned from NEW to ALLOCATED
2013-08-07 03:28:12,506 INFO org.apache.hadoop.yarn.server.resourcemanager.RMAuditLogger: USER=ubuntu	OPERATION=AM Allocated Container	TARGET=SchedulerApp	RESULT=SUCCESS	APPID=application_1375845418464_0006	CONTAINERID=container_1375845418464_0006_01_000013
2013-08-07 03:28:12,506 INFO org.apache.hadoop.yarn.server.resourcemanager.scheduler.common.fica.FiCaSchedulerNode: Assigned container container_1375845418464_0006_01_000013 of capacity <memory:1024, vCores:1> on host hadoop-200-2:46099, which currently has 7 containers, <memory:8192, vCores:7> used and <memory:0, vCores:9> available
2013-08-07 03:28:12,507 INFO org.apache.hadoop.yarn.server.resourcemanager.scheduler.capacity.LeafQueue: assignedContainer application=application_1375845418464_0006 container=Container: [ContainerId: container_1375845418464_0006_01_000013, NodeId: hadoop-200-2:46099, NodeHttpAddress: hadoop-200-2:8042, Resource: <memory:1024, vCores:1>, Priority: 20, State: NEW, Token: null, Status: container_id {, app_attempt_id {, application_id {, id: 6, cluster_timestamp: 1375845418464, }, attemptId: 1, }, id: 13, }, state: C_NEW, ] containerId=container_1375845418464_0006_01_000013 queue=default: capacity=1.0, absoluteCapacity=1.0, usedResources=<memory:21504, vCores:16>usedCapacity=0.4375, absoluteUsedCapacity=0.4375, numApps=5, numContainers=16 usedCapacity=0.4375 absoluteUsedCapacity=0.4375 used=<memory:21504, vCores:16> cluster=<memory:49152, vCores:96>
2013-08-07 03:28:12,508 INFO org.apache.hadoop.yarn.server.resourcemanager.scheduler.capacity.ParentQueue: Re-sorting queues since queue: root.default stats: default: capacity=1.0, absoluteCapacity=1.0, usedResources=<memory:22528, vCores:17>usedCapacity=0.45833334, absoluteUsedCapacity=0.45833334, numApps=5, numContainers=17
2013-08-07 03:28:12,508 INFO org.apache.hadoop.yarn.server.resourcemanager.scheduler.capacity.ParentQueue: assignedContainer queue=root usedCapacity=0.45833334 absoluteUsedCapacity=0.45833334 used=<memory:22528, vCores:17> cluster=<memory:49152, vCores:96>
2013-08-07 03:28:12,607 INFO org.apache.hadoop.yarn.server.resourcemanager.rmcontainer.RMContainerImpl: container_1375845418464_0006_01_000014 Container Transitioned from NEW to ALLOCATED
2013-08-07 03:28:12,607 INFO org.apache.hadoop.yarn.server.resourcemanager.RMAuditLogger: USER=ubuntu	OPERATION=AM Allocated Container	TARGET=SchedulerApp	RESULT=SUCCESS	APPID=application_1375845418464_0006	CONTAINERID=container_1375845418464_0006_01_000014
2013-08-07 03:28:12,607 INFO org.apache.hadoop.yarn.server.resourcemanager.scheduler.common.fica.FiCaSchedulerNode: Assigned container container_1375845418464_0006_01_000014 of capacity <memory:1024, vCores:1> on host hadoop-200-6:45851, which currently has 2 containers, <memory:3072, vCores:2> used and <memory:5120, vCores:14> available
2013-08-07 03:28:12,608 INFO org.apache.hadoop.yarn.server.resourcemanager.scheduler.capacity.LeafQueue: assignedContainer application=application_1375845418464_0006 container=Container: [ContainerId: container_1375845418464_0006_01_000014, NodeId: hadoop-200-6:45851, NodeHttpAddress: hadoop-200-6:8042, Resource: <memory:1024, vCores:1>, Priority: 20, State: NEW, Token: null, Status: container_id {, app_attempt_id {, application_id {, id: 6, cluster_timestamp: 1375845418464, }, attemptId: 1, }, id: 14, }, state: C_NEW, ] containerId=container_1375845418464_0006_01_000014 queue=default: capacity=1.0, absoluteCapacity=1.0, usedResources=<memory:22528, vCores:17>usedCapacity=0.45833334, absoluteUsedCapacity=0.45833334, numApps=5, numContainers=17 usedCapacity=0.45833334 absoluteUsedCapacity=0.45833334 used=<memory:22528, vCores:17> cluster=<memory:49152, vCores:96>
2013-08-07 03:28:12,609 INFO org.apache.hadoop.yarn.server.resourcemanager.scheduler.capacity.ParentQueue: Re-sorting queues since queue: root.default stats: default: capacity=1.0, absoluteCapacity=1.0, usedResources=<memory:23552, vCores:18>usedCapacity=0.47916666, absoluteUsedCapacity=0.47916666, numApps=5, numContainers=18
2013-08-07 03:28:12,609 INFO org.apache.hadoop.yarn.server.resourcemanager.scheduler.capacity.ParentQueue: assignedContainer queue=root usedCapacity=0.47916666 absoluteUsedCapacity=0.47916666 used=<memory:23552, vCores:18> cluster=<memory:49152, vCores:96>
2013-08-07 03:28:12,609 INFO org.apache.hadoop.yarn.server.resourcemanager.rmcontainer.RMContainerImpl: container_1375845418464_0006_01_000015 Container Transitioned from NEW to ALLOCATED
2013-08-07 03:28:12,610 INFO org.apache.hadoop.yarn.server.resourcemanager.RMAuditLogger: USER=ubuntu	OPERATION=AM Allocated Container	TARGET=SchedulerApp	RESULT=SUCCESS	APPID=application_1375845418464_0006	CONTAINERID=container_1375845418464_0006_01_000015
2013-08-07 03:28:12,610 INFO org.apache.hadoop.yarn.server.resourcemanager.scheduler.common.fica.FiCaSchedulerNode: Assigned container container_1375845418464_0006_01_000015 of capacity <memory:1024, vCores:1> on host hadoop-200-6:45851, which currently has 3 containers, <memory:4096, vCores:3> used and <memory:4096, vCores:13> available
2013-08-07 03:28:12,611 INFO org.apache.hadoop.yarn.server.resourcemanager.scheduler.capacity.LeafQueue: assignedContainer application=application_1375845418464_0006 container=Container: [ContainerId: container_1375845418464_0006_01_000015, NodeId: hadoop-200-6:45851, NodeHttpAddress: hadoop-200-6:8042, Resource: <memory:1024, vCores:1>, Priority: 20, State: NEW, Token: null, Status: container_id {, app_attempt_id {, application_id {, id: 6, cluster_timestamp: 1375845418464, }, attemptId: 1, }, id: 15, }, state: C_NEW, ] containerId=container_1375845418464_0006_01_000015 queue=default: capacity=1.0, absoluteCapacity=1.0, usedResources=<memory:23552, vCores:18>usedCapacity=0.47916666, absoluteUsedCapacity=0.47916666, numApps=5, numContainers=18 usedCapacity=0.47916666 absoluteUsedCapacity=0.47916666 used=<memory:23552, vCores:18> cluster=<memory:49152, vCores:96>
2013-08-07 03:28:12,611 INFO org.apache.hadoop.yarn.server.resourcemanager.scheduler.capacity.ParentQueue: Re-sorting queues since queue: root.default stats: default: capacity=1.0, absoluteCapacity=1.0, usedResources=<memory:24576, vCores:19>usedCapacity=0.5, absoluteUsedCapacity=0.5, numApps=5, numContainers=19
2013-08-07 03:28:12,611 INFO org.apache.hadoop.yarn.server.resourcemanager.scheduler.capacity.ParentQueue: assignedContainer queue=root usedCapacity=0.5 absoluteUsedCapacity=0.5 used=<memory:24576, vCores:19> cluster=<memory:49152, vCores:96>
2013-08-07 03:28:12,612 INFO org.apache.hadoop.yarn.server.resourcemanager.rmcontainer.RMContainerImpl: container_1375845418464_0006_01_000016 Container Transitioned from NEW to ALLOCATED
2013-08-07 03:28:12,612 INFO org.apache.hadoop.yarn.server.resourcemanager.RMAuditLogger: USER=ubuntu	OPERATION=AM Allocated Container	TARGET=SchedulerApp	RESULT=SUCCESS	APPID=application_1375845418464_0006	CONTAINERID=container_1375845418464_0006_01_000016
2013-08-07 03:28:12,612 INFO org.apache.hadoop.yarn.server.resourcemanager.scheduler.common.fica.FiCaSchedulerNode: Assigned container container_1375845418464_0006_01_000016 of capacity <memory:1024, vCores:1> on host hadoop-200-6:45851, which currently has 4 containers, <memory:5120, vCores:4> used and <memory:3072, vCores:12> available
2013-08-07 03:28:12,613 INFO org.apache.hadoop.yarn.server.resourcemanager.scheduler.capacity.LeafQueue: assignedContainer application=application_1375845418464_0006 container=Container: [ContainerId: container_1375845418464_0006_01_000016, NodeId: hadoop-200-6:45851, NodeHttpAddress: hadoop-200-6:8042, Resource: <memory:1024, vCores:1>, Priority: 20, State: NEW, Token: null, Status: container_id {, app_attempt_id {, application_id {, id: 6, cluster_timestamp: 1375845418464, }, attemptId: 1, }, id: 16, }, state: C_NEW, ] containerId=container_1375845418464_0006_01_000016 queue=default: capacity=1.0, absoluteCapacity=1.0, usedResources=<memory:24576, vCores:19>usedCapacity=0.5, absoluteUsedCapacity=0.5, numApps=5, numContainers=19 usedCapacity=0.5 absoluteUsedCapacity=0.5 used=<memory:24576, vCores:19> cluster=<memory:49152, vCores:96>
2013-08-07 03:28:12,613 INFO org.apache.hadoop.yarn.server.resourcemanager.scheduler.capacity.ParentQueue: Re-sorting queues since queue: root.default stats: default: capacity=1.0, absoluteCapacity=1.0, usedResources=<memory:25600, vCores:20>usedCapacity=0.5208333, absoluteUsedCapacity=0.5208333, numApps=5, numContainers=20
2013-08-07 03:28:12,613 INFO org.apache.hadoop.yarn.server.resourcemanager.scheduler.capacity.ParentQueue: assignedContainer queue=root usedCapacity=0.5208333 absoluteUsedCapacity=0.5208333 used=<memory:25600, vCores:20> cluster=<memory:49152, vCores:96>
2013-08-07 03:28:12,614 INFO org.apache.hadoop.yarn.server.resourcemanager.rmcontainer.RMContainerImpl: container_1375845418464_0006_01_000017 Container Transitioned from NEW to ALLOCATED
2013-08-07 03:28:12,614 INFO org.apache.hadoop.yarn.server.resourcemanager.RMAuditLogger: USER=ubuntu	OPERATION=AM Allocated Container	TARGET=SchedulerApp	RESULT=SUCCESS	APPID=application_1375845418464_0006	CONTAINERID=container_1375845418464_0006_01_000017
2013-08-07 03:28:12,614 INFO org.apache.hadoop.yarn.server.resourcemanager.scheduler.common.fica.FiCaSchedulerNode: Assigned container container_1375845418464_0006_01_000017 of capacity <memory:1024, vCores:1> on host hadoop-200-6:45851, which currently has 5 containers, <memory:6144, vCores:5> used and <memory:2048, vCores:11> available
2013-08-07 03:28:12,615 INFO org.apache.hadoop.yarn.server.resourcemanager.scheduler.capacity.LeafQueue: assignedContainer application=application_1375845418464_0006 container=Container: [ContainerId: container_1375845418464_0006_01_000017, NodeId: hadoop-200-6:45851, NodeHttpAddress: hadoop-200-6:8042, Resource: <memory:1024, vCores:1>, Priority: 20, State: NEW, Token: null, Status: container_id {, app_attempt_id {, application_id {, id: 6, cluster_timestamp: 1375845418464, }, attemptId: 1, }, id: 17, }, state: C_NEW, ] containerId=container_1375845418464_0006_01_000017 queue=default: capacity=1.0, absoluteCapacity=1.0, usedResources=<memory:25600, vCores:20>usedCapacity=0.5208333, absoluteUsedCapacity=0.5208333, numApps=5, numContainers=20 usedCapacity=0.5208333 absoluteUsedCapacity=0.5208333 used=<memory:25600, vCores:20> cluster=<memory:49152, vCores:96>
2013-08-07 03:28:12,615 INFO org.apache.hadoop.yarn.server.resourcemanager.scheduler.capacity.ParentQueue: Re-sorting queues since queue: root.default stats: default: capacity=1.0, absoluteCapacity=1.0, usedResources=<memory:26624, vCores:21>usedCapacity=0.5416667, absoluteUsedCapacity=0.5416667, numApps=5, numContainers=21
2013-08-07 03:28:12,615 INFO org.apache.hadoop.yarn.server.resourcemanager.scheduler.capacity.ParentQueue: assignedContainer queue=root usedCapacity=0.5416667 absoluteUsedCapacity=0.5416667 used=<memory:26624, vCores:21> cluster=<memory:49152, vCores:96>
2013-08-07 03:28:12,616 INFO org.apache.hadoop.yarn.server.resourcemanager.rmcontainer.RMContainerImpl: container_1375845418464_0006_01_000018 Container Transitioned from NEW to ALLOCATED
2013-08-07 03:28:12,616 INFO org.apache.hadoop.yarn.server.resourcemanager.RMAuditLogger: USER=ubuntu	OPERATION=AM Allocated Container	TARGET=SchedulerApp	RESULT=SUCCESS	APPID=application_1375845418464_0006	CONTAINERID=container_1375845418464_0006_01_000018
2013-08-07 03:28:12,616 INFO org.apache.hadoop.yarn.server.resourcemanager.scheduler.common.fica.FiCaSchedulerNode: Assigned container container_1375845418464_0006_01_000018 of capacity <memory:1024, vCores:1> on host hadoop-200-6:45851, which currently has 6 containers, <memory:7168, vCores:6> used and <memory:1024, vCores:10> available
2013-08-07 03:28:12,617 INFO org.apache.hadoop.yarn.server.resourcemanager.scheduler.capacity.LeafQueue: assignedContainer application=application_1375845418464_0006 container=Container: [ContainerId: container_1375845418464_0006_01_000018, NodeId: hadoop-200-6:45851, NodeHttpAddress: hadoop-200-6:8042, Resource: <memory:1024, vCores:1>, Priority: 20, State: NEW, Token: null, Status: container_id {, app_attempt_id {, application_id {, id: 6, cluster_timestamp: 1375845418464, }, attemptId: 1, }, id: 18, }, state: C_NEW, ] containerId=container_1375845418464_0006_01_000018 queue=default: capacity=1.0, absoluteCapacity=1.0, usedResources=<memory:26624, vCores:21>usedCapacity=0.5416667, absoluteUsedCapacity=0.5416667, numApps=5, numContainers=21 usedCapacity=0.5416667 absoluteUsedCapacity=0.5416667 used=<memory:26624, vCores:21> cluster=<memory:49152, vCores:96>
2013-08-07 03:28:12,617 INFO org.apache.hadoop.yarn.server.resourcemanager.scheduler.capacity.ParentQueue: Re-sorting queues since queue: root.default stats: default: capacity=1.0, absoluteCapacity=1.0, usedResources=<memory:27648, vCores:22>usedCapacity=0.5625, absoluteUsedCapacity=0.5625, numApps=5, numContainers=22
2013-08-07 03:28:12,617 INFO org.apache.hadoop.yarn.server.resourcemanager.scheduler.capacity.ParentQueue: assignedContainer queue=root usedCapacity=0.5625 absoluteUsedCapacity=0.5625 used=<memory:27648, vCores:22> cluster=<memory:49152, vCores:96>
2013-08-07 03:28:12,618 INFO org.apache.hadoop.yarn.server.resourcemanager.rmcontainer.RMContainerImpl: container_1375845418464_0006_01_000019 Container Transitioned from NEW to ALLOCATED
2013-08-07 03:28:12,618 INFO org.apache.hadoop.yarn.server.resourcemanager.RMAuditLogger: USER=ubuntu	OPERATION=AM Allocated Container	TARGET=SchedulerApp	RESULT=SUCCESS	APPID=application_1375845418464_0006	CONTAINERID=container_1375845418464_0006_01_000019
2013-08-07 03:28:12,618 INFO org.apache.hadoop.yarn.server.resourcemanager.scheduler.common.fica.FiCaSchedulerNode: Assigned container container_1375845418464_0006_01_000019 of capacity <memory:1024, vCores:1> on host hadoop-200-6:45851, which currently has 7 containers, <memory:8192, vCores:7> used and <memory:0, vCores:9> available
2013-08-07 03:28:12,619 INFO org.apache.hadoop.yarn.server.resourcemanager.scheduler.capacity.LeafQueue: assignedContainer application=application_1375845418464_0006 container=Container: [ContainerId: container_1375845418464_0006_01_000019, NodeId: hadoop-200-6:45851, NodeHttpAddress: hadoop-200-6:8042, Resource: <memory:1024, vCores:1>, Priority: 20, State: NEW, Token: null, Status: container_id {, app_attempt_id {, application_id {, id: 6, cluster_timestamp: 1375845418464, }, attemptId: 1, }, id: 19, }, state: C_NEW, ] containerId=container_1375845418464_0006_01_000019 queue=default: capacity=1.0, absoluteCapacity=1.0, usedResources=<memory:27648, vCores:22>usedCapacity=0.5625, absoluteUsedCapacity=0.5625, numApps=5, numContainers=22 usedCapacity=0.5625 absoluteUsedCapacity=0.5625 used=<memory:27648, vCores:22> cluster=<memory:49152, vCores:96>
2013-08-07 03:28:12,619 INFO org.apache.hadoop.yarn.server.resourcemanager.scheduler.capacity.ParentQueue: Re-sorting queues since queue: root.default stats: default: capacity=1.0, absoluteCapacity=1.0, usedResources=<memory:28672, vCores:23>usedCapacity=0.5833333, absoluteUsedCapacity=0.5833333, numApps=5, numContainers=23
2013-08-07 03:28:12,620 INFO org.apache.hadoop.yarn.server.resourcemanager.scheduler.capacity.ParentQueue: assignedContainer queue=root usedCapacity=0.5833333 absoluteUsedCapacity=0.5833333 used=<memory:28672, vCores:23> cluster=<memory:49152, vCores:96>
2013-08-07 03:28:12,778 INFO org.apache.hadoop.yarn.server.resourcemanager.rmcontainer.RMContainerImpl: container_1375845418464_0006_01_000020 Container Transitioned from NEW to ALLOCATED
2013-08-07 03:28:12,779 INFO org.apache.hadoop.yarn.server.resourcemanager.RMAuditLogger: USER=ubuntu	OPERATION=AM Allocated Container	TARGET=SchedulerApp	RESULT=SUCCESS	APPID=application_1375845418464_0006	CONTAINERID=container_1375845418464_0006_01_000020
2013-08-07 03:28:12,779 INFO org.apache.hadoop.yarn.server.resourcemanager.scheduler.common.fica.FiCaSchedulerNode: Assigned container container_1375845418464_0006_01_000020 of capacity <memory:1024, vCores:1> on host hadoop-200-3:52180, which currently has 2 containers, <memory:3072, vCores:2> used and <memory:5120, vCores:14> available
2013-08-07 03:28:12,780 INFO org.apache.hadoop.yarn.server.resourcemanager.scheduler.capacity.LeafQueue: assignedContainer application=application_1375845418464_0006 container=Container: [ContainerId: container_1375845418464_0006_01_000020, NodeId: hadoop-200-3:52180, NodeHttpAddress: hadoop-200-3:8042, Resource: <memory:1024, vCores:1>, Priority: 20, State: NEW, Token: null, Status: container_id {, app_attempt_id {, application_id {, id: 6, cluster_timestamp: 1375845418464, }, attemptId: 1, }, id: 20, }, state: C_NEW, ] containerId=container_1375845418464_0006_01_000020 queue=default: capacity=1.0, absoluteCapacity=1.0, usedResources=<memory:28672, vCores:23>usedCapacity=0.5833333, absoluteUsedCapacity=0.5833333, numApps=5, numContainers=23 usedCapacity=0.5833333 absoluteUsedCapacity=0.5833333 used=<memory:28672, vCores:23> cluster=<memory:49152, vCores:96>
2013-08-07 03:28:12,780 INFO org.apache.hadoop.yarn.server.resourcemanager.scheduler.capacity.ParentQueue: Re-sorting queues since queue: root.default stats: default: capacity=1.0, absoluteCapacity=1.0, usedResources=<memory:29696, vCores:24>usedCapacity=0.6041667, absoluteUsedCapacity=0.6041667, numApps=5, numContainers=24
2013-08-07 03:28:12,780 INFO org.apache.hadoop.yarn.server.resourcemanager.scheduler.capacity.ParentQueue: assignedContainer queue=root usedCapacity=0.6041667 absoluteUsedCapacity=0.6041667 used=<memory:29696, vCores:24> cluster=<memory:49152, vCores:96>
2013-08-07 03:28:12,781 INFO org.apache.hadoop.yarn.server.resourcemanager.rmcontainer.RMContainerImpl: container_1375845418464_0006_01_000021 Container Transitioned from NEW to ALLOCATED
2013-08-07 03:28:12,781 INFO org.apache.hadoop.yarn.server.resourcemanager.RMAuditLogger: USER=ubuntu	OPERATION=AM Allocated Container	TARGET=SchedulerApp	RESULT=SUCCESS	APPID=application_1375845418464_0006	CONTAINERID=container_1375845418464_0006_01_000021
2013-08-07 03:28:12,781 INFO org.apache.hadoop.yarn.server.resourcemanager.scheduler.common.fica.FiCaSchedulerNode: Assigned container container_1375845418464_0006_01_000021 of capacity <memory:1024, vCores:1> on host hadoop-200-3:52180, which currently has 3 containers, <memory:4096, vCores:3> used and <memory:4096, vCores:13> available
2013-08-07 03:28:12,782 INFO org.apache.hadoop.yarn.server.resourcemanager.scheduler.capacity.LeafQueue: assignedContainer application=application_1375845418464_0006 container=Container: [ContainerId: container_1375845418464_0006_01_000021, NodeId: hadoop-200-3:52180, NodeHttpAddress: hadoop-200-3:8042, Resource: <memory:1024, vCores:1>, Priority: 20, State: NEW, Token: null, Status: container_id {, app_attempt_id {, application_id {, id: 6, cluster_timestamp: 1375845418464, }, attemptId: 1, }, id: 21, }, state: C_NEW, ] containerId=container_1375845418464_0006_01_000021 queue=default: capacity=1.0, absoluteCapacity=1.0, usedResources=<memory:29696, vCores:24>usedCapacity=0.6041667, absoluteUsedCapacity=0.6041667, numApps=5, numContainers=24 usedCapacity=0.6041667 absoluteUsedCapacity=0.6041667 used=<memory:29696, vCores:24> cluster=<memory:49152, vCores:96>
2013-08-07 03:28:12,782 INFO org.apache.hadoop.yarn.server.resourcemanager.scheduler.capacity.ParentQueue: Re-sorting queues since queue: root.default stats: default: capacity=1.0, absoluteCapacity=1.0, usedResources=<memory:30720, vCores:25>usedCapacity=0.625, absoluteUsedCapacity=0.625, numApps=5, numContainers=25
2013-08-07 03:28:12,782 INFO org.apache.hadoop.yarn.server.resourcemanager.scheduler.capacity.ParentQueue: assignedContainer queue=root usedCapacity=0.625 absoluteUsedCapacity=0.625 used=<memory:30720, vCores:25> cluster=<memory:49152, vCores:96>
2013-08-07 03:28:12,783 INFO org.apache.hadoop.yarn.server.resourcemanager.rmcontainer.RMContainerImpl: container_1375845418464_0006_01_000022 Container Transitioned from NEW to ALLOCATED
2013-08-07 03:28:12,783 INFO org.apache.hadoop.yarn.server.resourcemanager.RMAuditLogger: USER=ubuntu	OPERATION=AM Allocated Container	TARGET=SchedulerApp	RESULT=SUCCESS	APPID=application_1375845418464_0006	CONTAINERID=container_1375845418464_0006_01_000022
2013-08-07 03:28:12,783 INFO org.apache.hadoop.yarn.server.resourcemanager.scheduler.common.fica.FiCaSchedulerNode: Assigned container container_1375845418464_0006_01_000022 of capacity <memory:1024, vCores:1> on host hadoop-200-3:52180, which currently has 4 containers, <memory:5120, vCores:4> used and <memory:3072, vCores:12> available
2013-08-07 03:28:12,784 INFO org.apache.hadoop.yarn.server.resourcemanager.scheduler.capacity.LeafQueue: assignedContainer application=application_1375845418464_0006 container=Container: [ContainerId: container_1375845418464_0006_01_000022, NodeId: hadoop-200-3:52180, NodeHttpAddress: hadoop-200-3:8042, Resource: <memory:1024, vCores:1>, Priority: 20, State: NEW, Token: null, Status: container_id {, app_attempt_id {, application_id {, id: 6, cluster_timestamp: 1375845418464, }, attemptId: 1, }, id: 22, }, state: C_NEW, ] containerId=container_1375845418464_0006_01_000022 queue=default: capacity=1.0, absoluteCapacity=1.0, usedResources=<memory:30720, vCores:25>usedCapacity=0.625, absoluteUsedCapacity=0.625, numApps=5, numContainers=25 usedCapacity=0.625 absoluteUsedCapacity=0.625 used=<memory:30720, vCores:25> cluster=<memory:49152, vCores:96>
2013-08-07 03:28:12,784 INFO org.apache.hadoop.yarn.server.resourcemanager.scheduler.capacity.ParentQueue: Re-sorting queues since queue: root.default stats: default: capacity=1.0, absoluteCapacity=1.0, usedResources=<memory:31744, vCores:26>usedCapacity=0.6458333, absoluteUsedCapacity=0.6458333, numApps=5, numContainers=26
2013-08-07 03:28:12,784 INFO org.apache.hadoop.yarn.server.resourcemanager.scheduler.capacity.ParentQueue: assignedContainer queue=root usedCapacity=0.6458333 absoluteUsedCapacity=0.6458333 used=<memory:31744, vCores:26> cluster=<memory:49152, vCores:96>
2013-08-07 03:28:12,785 INFO org.apache.hadoop.yarn.server.resourcemanager.rmcontainer.RMContainerImpl: container_1375845418464_0006_01_000023 Container Transitioned from NEW to ALLOCATED
2013-08-07 03:28:12,785 INFO org.apache.hadoop.yarn.server.resourcemanager.RMAuditLogger: USER=ubuntu	OPERATION=AM Allocated Container	TARGET=SchedulerApp	RESULT=SUCCESS	APPID=application_1375845418464_0006	CONTAINERID=container_1375845418464_0006_01_000023
2013-08-07 03:28:12,785 INFO org.apache.hadoop.yarn.server.resourcemanager.scheduler.common.fica.FiCaSchedulerNode: Assigned container container_1375845418464_0006_01_000023 of capacity <memory:1024, vCores:1> on host hadoop-200-3:52180, which currently has 5 containers, <memory:6144, vCores:5> used and <memory:2048, vCores:11> available
2013-08-07 03:28:12,786 INFO org.apache.hadoop.yarn.server.resourcemanager.scheduler.capacity.LeafQueue: assignedContainer application=application_1375845418464_0006 container=Container: [ContainerId: container_1375845418464_0006_01_000023, NodeId: hadoop-200-3:52180, NodeHttpAddress: hadoop-200-3:8042, Resource: <memory:1024, vCores:1>, Priority: 20, State: NEW, Token: null, Status: container_id {, app_attempt_id {, application_id {, id: 6, cluster_timestamp: 1375845418464, }, attemptId: 1, }, id: 23, }, state: C_NEW, ] containerId=container_1375845418464_0006_01_000023 queue=default: capacity=1.0, absoluteCapacity=1.0, usedResources=<memory:31744, vCores:26>usedCapacity=0.6458333, absoluteUsedCapacity=0.6458333, numApps=5, numContainers=26 usedCapacity=0.6458333 absoluteUsedCapacity=0.6458333 used=<memory:31744, vCores:26> cluster=<memory:49152, vCores:96>
2013-08-07 03:28:12,786 INFO org.apache.hadoop.yarn.server.resourcemanager.scheduler.capacity.ParentQueue: Re-sorting queues since queue: root.default stats: default: capacity=1.0, absoluteCapacity=1.0, usedResources=<memory:32768, vCores:27>usedCapacity=0.6666667, absoluteUsedCapacity=0.6666667, numApps=5, numContainers=27
2013-08-07 03:28:12,787 INFO org.apache.hadoop.yarn.server.resourcemanager.scheduler.capacity.ParentQueue: assignedContainer queue=root usedCapacity=0.6666667 absoluteUsedCapacity=0.6666667 used=<memory:32768, vCores:27> cluster=<memory:49152, vCores:96>
2013-08-07 03:28:12,787 INFO org.apache.hadoop.yarn.server.resourcemanager.rmcontainer.RMContainerImpl: container_1375845418464_0006_01_000024 Container Transitioned from NEW to ALLOCATED
2013-08-07 03:28:12,787 INFO org.apache.hadoop.yarn.server.resourcemanager.RMAuditLogger: USER=ubuntu	OPERATION=AM Allocated Container	TARGET=SchedulerApp	RESULT=SUCCESS	APPID=application_1375845418464_0006	CONTAINERID=container_1375845418464_0006_01_000024
2013-08-07 03:28:12,787 INFO org.apache.hadoop.yarn.server.resourcemanager.scheduler.common.fica.FiCaSchedulerNode: Assigned container container_1375845418464_0006_01_000024 of capacity <memory:1024, vCores:1> on host hadoop-200-3:52180, which currently has 6 containers, <memory:7168, vCores:6> used and <memory:1024, vCores:10> available
2013-08-07 03:28:12,788 INFO org.apache.hadoop.yarn.server.resourcemanager.scheduler.capacity.LeafQueue: assignedContainer application=application_1375845418464_0006 container=Container: [ContainerId: container_1375845418464_0006_01_000024, NodeId: hadoop-200-3:52180, NodeHttpAddress: hadoop-200-3:8042, Resource: <memory:1024, vCores:1>, Priority: 20, State: NEW, Token: null, Status: container_id {, app_attempt_id {, application_id {, id: 6, cluster_timestamp: 1375845418464, }, attemptId: 1, }, id: 24, }, state: C_NEW, ] containerId=container_1375845418464_0006_01_000024 queue=default: capacity=1.0, absoluteCapacity=1.0, usedResources=<memory:32768, vCores:27>usedCapacity=0.6666667, absoluteUsedCapacity=0.6666667, numApps=5, numContainers=27 usedCapacity=0.6666667 absoluteUsedCapacity=0.6666667 used=<memory:32768, vCores:27> cluster=<memory:49152, vCores:96>
2013-08-07 03:28:12,788 INFO org.apache.hadoop.yarn.server.resourcemanager.scheduler.capacity.ParentQueue: Re-sorting queues since queue: root.default stats: default: capacity=1.0, absoluteCapacity=1.0, usedResources=<memory:33792, vCores:28>usedCapacity=0.6875, absoluteUsedCapacity=0.6875, numApps=5, numContainers=28
2013-08-07 03:28:12,789 INFO org.apache.hadoop.yarn.server.resourcemanager.scheduler.capacity.ParentQueue: assignedContainer queue=root usedCapacity=0.6875 absoluteUsedCapacity=0.6875 used=<memory:33792, vCores:28> cluster=<memory:49152, vCores:96>
2013-08-07 03:28:12,789 INFO org.apache.hadoop.yarn.server.resourcemanager.rmcontainer.RMContainerImpl: container_1375845418464_0006_01_000025 Container Transitioned from NEW to ALLOCATED
2013-08-07 03:28:12,789 INFO org.apache.hadoop.yarn.server.resourcemanager.RMAuditLogger: USER=ubuntu	OPERATION=AM Allocated Container	TARGET=SchedulerApp	RESULT=SUCCESS	APPID=application_1375845418464_0006	CONTAINERID=container_1375845418464_0006_01_000025
2013-08-07 03:28:12,789 INFO org.apache.hadoop.yarn.server.resourcemanager.scheduler.common.fica.FiCaSchedulerNode: Assigned container container_1375845418464_0006_01_000025 of capacity <memory:1024, vCores:1> on host hadoop-200-3:52180, which currently has 7 containers, <memory:8192, vCores:7> used and <memory:0, vCores:9> available
2013-08-07 03:28:12,790 INFO org.apache.hadoop.yarn.server.resourcemanager.scheduler.capacity.LeafQueue: assignedContainer application=application_1375845418464_0006 container=Container: [ContainerId: container_1375845418464_0006_01_000025, NodeId: hadoop-200-3:52180, NodeHttpAddress: hadoop-200-3:8042, Resource: <memory:1024, vCores:1>, Priority: 20, State: NEW, Token: null, Status: container_id {, app_attempt_id {, application_id {, id: 6, cluster_timestamp: 1375845418464, }, attemptId: 1, }, id: 25, }, state: C_NEW, ] containerId=container_1375845418464_0006_01_000025 queue=default: capacity=1.0, absoluteCapacity=1.0, usedResources=<memory:33792, vCores:28>usedCapacity=0.6875, absoluteUsedCapacity=0.6875, numApps=5, numContainers=28 usedCapacity=0.6875 absoluteUsedCapacity=0.6875 used=<memory:33792, vCores:28> cluster=<memory:49152, vCores:96>
2013-08-07 03:28:12,791 INFO org.apache.hadoop.yarn.server.resourcemanager.scheduler.capacity.ParentQueue: Re-sorting queues since queue: root.default stats: default: capacity=1.0, absoluteCapacity=1.0, usedResources=<memory:34816, vCores:29>usedCapacity=0.7083333, absoluteUsedCapacity=0.7083333, numApps=5, numContainers=29
2013-08-07 03:28:12,791 INFO org.apache.hadoop.yarn.server.resourcemanager.scheduler.capacity.ParentQueue: assignedContainer queue=root usedCapacity=0.7083333 absoluteUsedCapacity=0.7083333 used=<memory:34816, vCores:29> cluster=<memory:49152, vCores:96>
2013-08-07 03:28:13,037 INFO org.apache.hadoop.yarn.server.resourcemanager.rmcontainer.RMContainerImpl: container_1375845418464_0006_01_000026 Container Transitioned from NEW to ALLOCATED
2013-08-07 03:28:13,037 INFO org.apache.hadoop.yarn.server.resourcemanager.RMAuditLogger: USER=ubuntu	OPERATION=AM Allocated Container	TARGET=SchedulerApp	RESULT=SUCCESS	APPID=application_1375845418464_0006	CONTAINERID=container_1375845418464_0006_01_000026
2013-08-07 03:28:13,037 INFO org.apache.hadoop.yarn.server.resourcemanager.scheduler.common.fica.FiCaSchedulerNode: Assigned container container_1375845418464_0006_01_000026 of capacity <memory:1024, vCores:1> on host hadoop-200-4:45217, which currently has 1 containers, <memory:1024, vCores:1> used and <memory:7168, vCores:15> available
2013-08-07 03:28:13,038 INFO org.apache.hadoop.yarn.server.resourcemanager.scheduler.capacity.LeafQueue: assignedContainer application=application_1375845418464_0006 container=Container: [ContainerId: container_1375845418464_0006_01_000026, NodeId: hadoop-200-4:45217, NodeHttpAddress: hadoop-200-4:8042, Resource: <memory:1024, vCores:1>, Priority: 20, State: NEW, Token: null, Status: container_id {, app_attempt_id {, application_id {, id: 6, cluster_timestamp: 1375845418464, }, attemptId: 1, }, id: 26, }, state: C_NEW, ] containerId=container_1375845418464_0006_01_000026 queue=default: capacity=1.0, absoluteCapacity=1.0, usedResources=<memory:34816, vCores:29>usedCapacity=0.7083333, absoluteUsedCapacity=0.7083333, numApps=5, numContainers=29 usedCapacity=0.7083333 absoluteUsedCapacity=0.7083333 used=<memory:34816, vCores:29> cluster=<memory:49152, vCores:96>
2013-08-07 03:28:13,039 INFO org.apache.hadoop.yarn.server.resourcemanager.scheduler.capacity.ParentQueue: Re-sorting queues since queue: root.default stats: default: capacity=1.0, absoluteCapacity=1.0, usedResources=<memory:35840, vCores:30>usedCapacity=0.7291667, absoluteUsedCapacity=0.7291667, numApps=5, numContainers=30
2013-08-07 03:28:13,039 INFO org.apache.hadoop.yarn.server.resourcemanager.scheduler.capacity.ParentQueue: assignedContainer queue=root usedCapacity=0.7291667 absoluteUsedCapacity=0.7291667 used=<memory:35840, vCores:30> cluster=<memory:49152, vCores:96>
2013-08-07 03:28:13,039 INFO org.apache.hadoop.yarn.server.resourcemanager.rmcontainer.RMContainerImpl: container_1375845418464_0006_01_000027 Container Transitioned from NEW to ALLOCATED
2013-08-07 03:28:13,040 INFO org.apache.hadoop.yarn.server.resourcemanager.RMAuditLogger: USER=ubuntu	OPERATION=AM Allocated Container	TARGET=SchedulerApp	RESULT=SUCCESS	APPID=application_1375845418464_0006	CONTAINERID=container_1375845418464_0006_01_000027
2013-08-07 03:28:13,040 INFO org.apache.hadoop.yarn.server.resourcemanager.scheduler.common.fica.FiCaSchedulerNode: Assigned container container_1375845418464_0006_01_000027 of capacity <memory:1024, vCores:1> on host hadoop-200-4:45217, which currently has 2 containers, <memory:2048, vCores:2> used and <memory:6144, vCores:14> available
2013-08-07 03:28:13,041 INFO org.apache.hadoop.yarn.server.resourcemanager.scheduler.capacity.LeafQueue: assignedContainer application=application_1375845418464_0006 container=Container: [ContainerId: container_1375845418464_0006_01_000027, NodeId: hadoop-200-4:45217, NodeHttpAddress: hadoop-200-4:8042, Resource: <memory:1024, vCores:1>, Priority: 20, State: NEW, Token: null, Status: container_id {, app_attempt_id {, application_id {, id: 6, cluster_timestamp: 1375845418464, }, attemptId: 1, }, id: 27, }, state: C_NEW, ] containerId=container_1375845418464_0006_01_000027 queue=default: capacity=1.0, absoluteCapacity=1.0, usedResources=<memory:35840, vCores:30>usedCapacity=0.7291667, absoluteUsedCapacity=0.7291667, numApps=5, numContainers=30 usedCapacity=0.7291667 absoluteUsedCapacity=0.7291667 used=<memory:35840, vCores:30> cluster=<memory:49152, vCores:96>
2013-08-07 03:28:13,041 INFO org.apache.hadoop.yarn.server.resourcemanager.scheduler.capacity.ParentQueue: Re-sorting queues since queue: root.default stats: default: capacity=1.0, absoluteCapacity=1.0, usedResources=<memory:36864, vCores:31>usedCapacity=0.75, absoluteUsedCapacity=0.75, numApps=5, numContainers=31
2013-08-07 03:28:13,041 INFO org.apache.hadoop.yarn.server.resourcemanager.scheduler.capacity.ParentQueue: assignedContainer queue=root usedCapacity=0.75 absoluteUsedCapacity=0.75 used=<memory:36864, vCores:31> cluster=<memory:49152, vCores:96>
2013-08-07 03:28:13,042 INFO org.apache.hadoop.yarn.server.resourcemanager.rmcontainer.RMContainerImpl: container_1375845418464_0006_01_000028 Container Transitioned from NEW to ALLOCATED
2013-08-07 03:28:13,042 INFO org.apache.hadoop.yarn.server.resourcemanager.RMAuditLogger: USER=ubuntu	OPERATION=AM Allocated Container	TARGET=SchedulerApp	RESULT=SUCCESS	APPID=application_1375845418464_0006	CONTAINERID=container_1375845418464_0006_01_000028
2013-08-07 03:28:13,042 INFO org.apache.hadoop.yarn.server.resourcemanager.scheduler.common.fica.FiCaSchedulerNode: Assigned container container_1375845418464_0006_01_000028 of capacity <memory:1024, vCores:1> on host hadoop-200-4:45217, which currently has 3 containers, <memory:3072, vCores:3> used and <memory:5120, vCores:13> available
2013-08-07 03:28:13,043 INFO org.apache.hadoop.yarn.server.resourcemanager.scheduler.capacity.LeafQueue: assignedContainer application=application_1375845418464_0006 container=Container: [ContainerId: container_1375845418464_0006_01_000028, NodeId: hadoop-200-4:45217, NodeHttpAddress: hadoop-200-4:8042, Resource: <memory:1024, vCores:1>, Priority: 20, State: NEW, Token: null, Status: container_id {, app_attempt_id {, application_id {, id: 6, cluster_timestamp: 1375845418464, }, attemptId: 1, }, id: 28, }, state: C_NEW, ] containerId=container_1375845418464_0006_01_000028 queue=default: capacity=1.0, absoluteCapacity=1.0, usedResources=<memory:36864, vCores:31>usedCapacity=0.75, absoluteUsedCapacity=0.75, numApps=5, numContainers=31 usedCapacity=0.75 absoluteUsedCapacity=0.75 used=<memory:36864, vCores:31> cluster=<memory:49152, vCores:96>
2013-08-07 03:28:13,043 INFO org.apache.hadoop.yarn.server.resourcemanager.scheduler.capacity.ParentQueue: Re-sorting queues since queue: root.default stats: default: capacity=1.0, absoluteCapacity=1.0, usedResources=<memory:37888, vCores:32>usedCapacity=0.7708333, absoluteUsedCapacity=0.7708333, numApps=5, numContainers=32
2013-08-07 03:28:13,043 INFO org.apache.hadoop.yarn.server.resourcemanager.scheduler.capacity.ParentQueue: assignedContainer queue=root usedCapacity=0.7708333 absoluteUsedCapacity=0.7708333 used=<memory:37888, vCores:32> cluster=<memory:49152, vCores:96>
2013-08-07 03:28:13,044 INFO org.apache.hadoop.yarn.server.resourcemanager.rmcontainer.RMContainerImpl: container_1375845418464_0006_01_000029 Container Transitioned from NEW to ALLOCATED
2013-08-07 03:28:13,044 INFO org.apache.hadoop.yarn.server.resourcemanager.RMAuditLogger: USER=ubuntu	OPERATION=AM Allocated Container	TARGET=SchedulerApp	RESULT=SUCCESS	APPID=application_1375845418464_0006	CONTAINERID=container_1375845418464_0006_01_000029
2013-08-07 03:28:13,044 INFO org.apache.hadoop.yarn.server.resourcemanager.scheduler.common.fica.FiCaSchedulerNode: Assigned container container_1375845418464_0006_01_000029 of capacity <memory:1024, vCores:1> on host hadoop-200-4:45217, which currently has 4 containers, <memory:4096, vCores:4> used and <memory:4096, vCores:12> available
2013-08-07 03:28:13,045 INFO org.apache.hadoop.yarn.server.resourcemanager.scheduler.capacity.LeafQueue: assignedContainer application=application_1375845418464_0006 container=Container: [ContainerId: container_1375845418464_0006_01_000029, NodeId: hadoop-200-4:45217, NodeHttpAddress: hadoop-200-4:8042, Resource: <memory:1024, vCores:1>, Priority: 20, State: NEW, Token: null, Status: container_id {, app_attempt_id {, application_id {, id: 6, cluster_timestamp: 1375845418464, }, attemptId: 1, }, id: 29, }, state: C_NEW, ] containerId=container_1375845418464_0006_01_000029 queue=default: capacity=1.0, absoluteCapacity=1.0, usedResources=<memory:37888, vCores:32>usedCapacity=0.7708333, absoluteUsedCapacity=0.7708333, numApps=5, numContainers=32 usedCapacity=0.7708333 absoluteUsedCapacity=0.7708333 used=<memory:37888, vCores:32> cluster=<memory:49152, vCores:96>
2013-08-07 03:28:13,045 INFO org.apache.hadoop.yarn.server.resourcemanager.scheduler.capacity.ParentQueue: Re-sorting queues since queue: root.default stats: default: capacity=1.0, absoluteCapacity=1.0, usedResources=<memory:38912, vCores:33>usedCapacity=0.7916667, absoluteUsedCapacity=0.7916667, numApps=5, numContainers=33
2013-08-07 03:28:13,045 INFO org.apache.hadoop.yarn.server.resourcemanager.scheduler.capacity.ParentQueue: assignedContainer queue=root usedCapacity=0.7916667 absoluteUsedCapacity=0.7916667 used=<memory:38912, vCores:33> cluster=<memory:49152, vCores:96>
2013-08-07 03:28:13,046 INFO org.apache.hadoop.yarn.server.resourcemanager.rmcontainer.RMContainerImpl: container_1375845418464_0006_01_000030 Container Transitioned from NEW to ALLOCATED
2013-08-07 03:28:13,046 INFO org.apache.hadoop.yarn.server.resourcemanager.RMAuditLogger: USER=ubuntu	OPERATION=AM Allocated Container	TARGET=SchedulerApp	RESULT=SUCCESS	APPID=application_1375845418464_0006	CONTAINERID=container_1375845418464_0006_01_000030
2013-08-07 03:28:13,046 INFO org.apache.hadoop.yarn.server.resourcemanager.scheduler.common.fica.FiCaSchedulerNode: Assigned container container_1375845418464_0006_01_000030 of capacity <memory:1024, vCores:1> on host hadoop-200-4:45217, which currently has 5 containers, <memory:5120, vCores:5> used and <memory:3072, vCores:11> available
2013-08-07 03:28:13,047 INFO org.apache.hadoop.yarn.server.resourcemanager.scheduler.capacity.LeafQueue: assignedContainer application=application_1375845418464_0006 container=Container: [ContainerId: container_1375845418464_0006_01_000030, NodeId: hadoop-200-4:45217, NodeHttpAddress: hadoop-200-4:8042, Resource: <memory:1024, vCores:1>, Priority: 20, State: NEW, Token: null, Status: container_id {, app_attempt_id {, application_id {, id: 6, cluster_timestamp: 1375845418464, }, attemptId: 1, }, id: 30, }, state: C_NEW, ] containerId=container_1375845418464_0006_01_000030 queue=default: capacity=1.0, absoluteCapacity=1.0, usedResources=<memory:38912, vCores:33>usedCapacity=0.7916667, absoluteUsedCapacity=0.7916667, numApps=5, numContainers=33 usedCapacity=0.7916667 absoluteUsedCapacity=0.7916667 used=<memory:38912, vCores:33> cluster=<memory:49152, vCores:96>
2013-08-07 03:28:13,047 INFO org.apache.hadoop.yarn.server.resourcemanager.scheduler.capacity.ParentQueue: Re-sorting queues since queue: root.default stats: default: capacity=1.0, absoluteCapacity=1.0, usedResources=<memory:39936, vCores:34>usedCapacity=0.8125, absoluteUsedCapacity=0.8125, numApps=5, numContainers=34
2013-08-07 03:28:13,047 INFO org.apache.hadoop.yarn.server.resourcemanager.scheduler.capacity.ParentQueue: assignedContainer queue=root usedCapacity=0.8125 absoluteUsedCapacity=0.8125 used=<memory:39936, vCores:34> cluster=<memory:49152, vCores:96>
2013-08-07 03:28:13,048 INFO org.apache.hadoop.yarn.server.resourcemanager.rmcontainer.RMContainerImpl: container_1375845418464_0006_01_000031 Container Transitioned from NEW to ALLOCATED
2013-08-07 03:28:13,048 INFO org.apache.hadoop.yarn.server.resourcemanager.RMAuditLogger: USER=ubuntu	OPERATION=AM Allocated Container	TARGET=SchedulerApp	RESULT=SUCCESS	APPID=application_1375845418464_0006	CONTAINERID=container_1375845418464_0006_01_000031
2013-08-07 03:28:13,048 INFO org.apache.hadoop.yarn.server.resourcemanager.scheduler.common.fica.FiCaSchedulerNode: Assigned container container_1375845418464_0006_01_000031 of capacity <memory:1024, vCores:1> on host hadoop-200-4:45217, which currently has 6 containers, <memory:6144, vCores:6> used and <memory:2048, vCores:10> available
2013-08-07 03:28:13,049 INFO org.apache.hadoop.yarn.server.resourcemanager.scheduler.capacity.LeafQueue: assignedContainer application=application_1375845418464_0006 container=Container: [ContainerId: container_1375845418464_0006_01_000031, NodeId: hadoop-200-4:45217, NodeHttpAddress: hadoop-200-4:8042, Resource: <memory:1024, vCores:1>, Priority: 20, State: NEW, Token: null, Status: container_id {, app_attempt_id {, application_id {, id: 6, cluster_timestamp: 1375845418464, }, attemptId: 1, }, id: 31, }, state: C_NEW, ] containerId=container_1375845418464_0006_01_000031 queue=default: capacity=1.0, absoluteCapacity=1.0, usedResources=<memory:39936, vCores:34>usedCapacity=0.8125, absoluteUsedCapacity=0.8125, numApps=5, numContainers=34 usedCapacity=0.8125 absoluteUsedCapacity=0.8125 used=<memory:39936, vCores:34> cluster=<memory:49152, vCores:96>
2013-08-07 03:28:13,049 INFO org.apache.hadoop.yarn.server.resourcemanager.scheduler.capacity.ParentQueue: Re-sorting queues since queue: root.default stats: default: capacity=1.0, absoluteCapacity=1.0, usedResources=<memory:40960, vCores:35>usedCapacity=0.8333333, absoluteUsedCapacity=0.8333333, numApps=5, numContainers=35
2013-08-07 03:28:13,049 INFO org.apache.hadoop.yarn.server.resourcemanager.scheduler.capacity.ParentQueue: assignedContainer queue=root usedCapacity=0.8333333 absoluteUsedCapacity=0.8333333 used=<memory:40960, vCores:35> cluster=<memory:49152, vCores:96>
2013-08-07 03:28:13,053 INFO org.apache.hadoop.yarn.server.resourcemanager.rmcontainer.RMContainerImpl: container_1375845418464_0006_01_000032 Container Transitioned from NEW to ALLOCATED
2013-08-07 03:28:13,053 INFO org.apache.hadoop.yarn.server.resourcemanager.RMAuditLogger: USER=ubuntu	OPERATION=AM Allocated Container	TARGET=SchedulerApp	RESULT=SUCCESS	APPID=application_1375845418464_0006	CONTAINERID=container_1375845418464_0006_01_000032
2013-08-07 03:28:13,053 INFO org.apache.hadoop.yarn.server.resourcemanager.scheduler.common.fica.FiCaSchedulerNode: Assigned container container_1375845418464_0006_01_000032 of capacity <memory:1024, vCores:1> on host hadoop-200-4:45217, which currently has 7 containers, <memory:7168, vCores:7> used and <memory:1024, vCores:9> available
2013-08-07 03:28:13,055 INFO org.apache.hadoop.yarn.server.resourcemanager.scheduler.capacity.LeafQueue: assignedContainer application=application_1375845418464_0006 container=Container: [ContainerId: container_1375845418464_0006_01_000032, NodeId: hadoop-200-4:45217, NodeHttpAddress: hadoop-200-4:8042, Resource: <memory:1024, vCores:1>, Priority: 20, State: NEW, Token: null, Status: container_id {, app_attempt_id {, application_id {, id: 6, cluster_timestamp: 1375845418464, }, attemptId: 1, }, id: 32, }, state: C_NEW, ] containerId=container_1375845418464_0006_01_000032 queue=default: capacity=1.0, absoluteCapacity=1.0, usedResources=<memory:40960, vCores:35>usedCapacity=0.8333333, absoluteUsedCapacity=0.8333333, numApps=5, numContainers=35 usedCapacity=0.8333333 absoluteUsedCapacity=0.8333333 used=<memory:40960, vCores:35> cluster=<memory:49152, vCores:96>
2013-08-07 03:28:13,055 INFO org.apache.hadoop.yarn.server.resourcemanager.scheduler.capacity.ParentQueue: Re-sorting queues since queue: root.default stats: default: capacity=1.0, absoluteCapacity=1.0, usedResources=<memory:41984, vCores:36>usedCapacity=0.8541667, absoluteUsedCapacity=0.8541667, numApps=5, numContainers=36
2013-08-07 03:28:13,055 INFO org.apache.hadoop.yarn.server.resourcemanager.scheduler.capacity.ParentQueue: assignedContainer queue=root usedCapacity=0.8541667 absoluteUsedCapacity=0.8541667 used=<memory:41984, vCores:36> cluster=<memory:49152, vCores:96>
2013-08-07 03:28:13,056 INFO org.apache.hadoop.yarn.server.resourcemanager.rmcontainer.RMContainerImpl: container_1375845418464_0006_01_000033 Container Transitioned from NEW to ALLOCATED
2013-08-07 03:28:13,056 INFO org.apache.hadoop.yarn.server.resourcemanager.RMAuditLogger: USER=ubuntu	OPERATION=AM Allocated Container	TARGET=SchedulerApp	RESULT=SUCCESS	APPID=application_1375845418464_0006	CONTAINERID=container_1375845418464_0006_01_000033
2013-08-07 03:28:13,056 INFO org.apache.hadoop.yarn.server.resourcemanager.scheduler.common.fica.FiCaSchedulerNode: Assigned container container_1375845418464_0006_01_000033 of capacity <memory:1024, vCores:1> on host hadoop-200-4:45217, which currently has 8 containers, <memory:8192, vCores:8> used and <memory:0, vCores:8> available
2013-08-07 03:28:13,057 INFO org.apache.hadoop.yarn.server.resourcemanager.scheduler.capacity.LeafQueue: assignedContainer application=application_1375845418464_0006 container=Container: [ContainerId: container_1375845418464_0006_01_000033, NodeId: hadoop-200-4:45217, NodeHttpAddress: hadoop-200-4:8042, Resource: <memory:1024, vCores:1>, Priority: 20, State: NEW, Token: null, Status: container_id {, app_attempt_id {, application_id {, id: 6, cluster_timestamp: 1375845418464, }, attemptId: 1, }, id: 33, }, state: C_NEW, ] containerId=container_1375845418464_0006_01_000033 queue=default: capacity=1.0, absoluteCapacity=1.0, usedResources=<memory:41984, vCores:36>usedCapacity=0.8541667, absoluteUsedCapacity=0.8541667, numApps=5, numContainers=36 usedCapacity=0.8541667 absoluteUsedCapacity=0.8541667 used=<memory:41984, vCores:36> cluster=<memory:49152, vCores:96>
2013-08-07 03:28:13,057 INFO org.apache.hadoop.yarn.server.resourcemanager.scheduler.capacity.ParentQueue: Re-sorting queues since queue: root.default stats: default: capacity=1.0, absoluteCapacity=1.0, usedResources=<memory:43008, vCores:37>usedCapacity=0.875, absoluteUsedCapacity=0.875, numApps=5, numContainers=37
2013-08-07 03:28:13,057 INFO org.apache.hadoop.yarn.server.resourcemanager.scheduler.capacity.ParentQueue: assignedContainer queue=root usedCapacity=0.875 absoluteUsedCapacity=0.875 used=<memory:43008, vCores:37> cluster=<memory:49152, vCores:96>
2013-08-07 03:28:13,179 INFO org.apache.hadoop.yarn.server.resourcemanager.rmcontainer.RMContainerImpl: container_1375845418464_0006_01_000034 Container Transitioned from NEW to ALLOCATED
2013-08-07 03:28:13,179 INFO org.apache.hadoop.yarn.server.resourcemanager.RMAuditLogger: USER=ubuntu	OPERATION=AM Allocated Container	TARGET=SchedulerApp	RESULT=SUCCESS	APPID=application_1375845418464_0006	CONTAINERID=container_1375845418464_0006_01_000034
2013-08-07 03:28:13,179 INFO org.apache.hadoop.yarn.server.resourcemanager.scheduler.common.fica.FiCaSchedulerNode: Assigned container container_1375845418464_0006_01_000034 of capacity <memory:1024, vCores:1> on host hadoop-200-7:47421, which currently has 2 containers, <memory:3072, vCores:2> used and <memory:5120, vCores:14> available
2013-08-07 03:28:13,180 INFO org.apache.hadoop.yarn.server.resourcemanager.scheduler.capacity.LeafQueue: assignedContainer application=application_1375845418464_0006 container=Container: [ContainerId: container_1375845418464_0006_01_000034, NodeId: hadoop-200-7:47421, NodeHttpAddress: hadoop-200-7:8042, Resource: <memory:1024, vCores:1>, Priority: 20, State: NEW, Token: null, Status: container_id {, app_attempt_id {, application_id {, id: 6, cluster_timestamp: 1375845418464, }, attemptId: 1, }, id: 34, }, state: C_NEW, ] containerId=container_1375845418464_0006_01_000034 queue=default: capacity=1.0, absoluteCapacity=1.0, usedResources=<memory:43008, vCores:37>usedCapacity=0.875, absoluteUsedCapacity=0.875, numApps=5, numContainers=37 usedCapacity=0.875 absoluteUsedCapacity=0.875 used=<memory:43008, vCores:37> cluster=<memory:49152, vCores:96>
2013-08-07 03:28:13,180 INFO org.apache.hadoop.yarn.server.resourcemanager.scheduler.capacity.ParentQueue: Re-sorting queues since queue: root.default stats: default: capacity=1.0, absoluteCapacity=1.0, usedResources=<memory:44032, vCores:38>usedCapacity=0.8958333, absoluteUsedCapacity=0.8958333, numApps=5, numContainers=38
2013-08-07 03:28:13,181 INFO org.apache.hadoop.yarn.server.resourcemanager.scheduler.capacity.ParentQueue: assignedContainer queue=root usedCapacity=0.8958333 absoluteUsedCapacity=0.8958333 used=<memory:44032, vCores:38> cluster=<memory:49152, vCores:96>
2013-08-07 03:28:13,181 INFO org.apache.hadoop.yarn.server.resourcemanager.rmcontainer.RMContainerImpl: container_1375845418464_0006_01_000035 Container Transitioned from NEW to ALLOCATED
2013-08-07 03:28:13,181 INFO org.apache.hadoop.yarn.server.resourcemanager.RMAuditLogger: USER=ubuntu	OPERATION=AM Allocated Container	TARGET=SchedulerApp	RESULT=SUCCESS	APPID=application_1375845418464_0006	CONTAINERID=container_1375845418464_0006_01_000035
2013-08-07 03:28:13,181 INFO org.apache.hadoop.yarn.server.resourcemanager.scheduler.common.fica.FiCaSchedulerNode: Assigned container container_1375845418464_0006_01_000035 of capacity <memory:1024, vCores:1> on host hadoop-200-7:47421, which currently has 3 containers, <memory:4096, vCores:3> used and <memory:4096, vCores:13> available
2013-08-07 03:28:13,182 INFO org.apache.hadoop.yarn.server.resourcemanager.scheduler.capacity.LeafQueue: assignedContainer application=application_1375845418464_0006 container=Container: [ContainerId: container_1375845418464_0006_01_000035, NodeId: hadoop-200-7:47421, NodeHttpAddress: hadoop-200-7:8042, Resource: <memory:1024, vCores:1>, Priority: 20, State: NEW, Token: null, Status: container_id {, app_attempt_id {, application_id {, id: 6, cluster_timestamp: 1375845418464, }, attemptId: 1, }, id: 35, }, state: C_NEW, ] containerId=container_1375845418464_0006_01_000035 queue=default: capacity=1.0, absoluteCapacity=1.0, usedResources=<memory:44032, vCores:38>usedCapacity=0.8958333, absoluteUsedCapacity=0.8958333, numApps=5, numContainers=38 usedCapacity=0.8958333 absoluteUsedCapacity=0.8958333 used=<memory:44032, vCores:38> cluster=<memory:49152, vCores:96>
2013-08-07 03:28:13,182 INFO org.apache.hadoop.yarn.server.resourcemanager.scheduler.capacity.ParentQueue: Re-sorting queues since queue: root.default stats: default: capacity=1.0, absoluteCapacity=1.0, usedResources=<memory:45056, vCores:39>usedCapacity=0.9166667, absoluteUsedCapacity=0.9166667, numApps=5, numContainers=39
2013-08-07 03:28:13,183 INFO org.apache.hadoop.yarn.server.resourcemanager.scheduler.capacity.ParentQueue: assignedContainer queue=root usedCapacity=0.9166667 absoluteUsedCapacity=0.9166667 used=<memory:45056, vCores:39> cluster=<memory:49152, vCores:96>
2013-08-07 03:28:13,183 INFO org.apache.hadoop.yarn.server.resourcemanager.rmcontainer.RMContainerImpl: container_1375845418464_0006_01_000036 Container Transitioned from NEW to ALLOCATED
2013-08-07 03:28:13,183 INFO org.apache.hadoop.yarn.server.resourcemanager.RMAuditLogger: USER=ubuntu	OPERATION=AM Allocated Container	TARGET=SchedulerApp	RESULT=SUCCESS	APPID=application_1375845418464_0006	CONTAINERID=container_1375845418464_0006_01_000036
2013-08-07 03:28:13,183 INFO org.apache.hadoop.yarn.server.resourcemanager.scheduler.common.fica.FiCaSchedulerNode: Assigned container container_1375845418464_0006_01_000036 of capacity <memory:1024, vCores:1> on host hadoop-200-7:47421, which currently has 4 containers, <memory:5120, vCores:4> used and <memory:3072, vCores:12> available
2013-08-07 03:28:13,184 INFO org.apache.hadoop.yarn.server.resourcemanager.scheduler.capacity.LeafQueue: assignedContainer application=application_1375845418464_0006 container=Container: [ContainerId: container_1375845418464_0006_01_000036, NodeId: hadoop-200-7:47421, NodeHttpAddress: hadoop-200-7:8042, Resource: <memory:1024, vCores:1>, Priority: 20, State: NEW, Token: null, Status: container_id {, app_attempt_id {, application_id {, id: 6, cluster_timestamp: 1375845418464, }, attemptId: 1, }, id: 36, }, state: C_NEW, ] containerId=container_1375845418464_0006_01_000036 queue=default: capacity=1.0, absoluteCapacity=1.0, usedResources=<memory:45056, vCores:39>usedCapacity=0.9166667, absoluteUsedCapacity=0.9166667, numApps=5, numContainers=39 usedCapacity=0.9166667 absoluteUsedCapacity=0.9166667 used=<memory:45056, vCores:39> cluster=<memory:49152, vCores:96>
2013-08-07 03:28:13,184 INFO org.apache.hadoop.yarn.server.resourcemanager.scheduler.capacity.ParentQueue: Re-sorting queues since queue: root.default stats: default: capacity=1.0, absoluteCapacity=1.0, usedResources=<memory:46080, vCores:40>usedCapacity=0.9375, absoluteUsedCapacity=0.9375, numApps=5, numContainers=40
2013-08-07 03:28:13,185 INFO org.apache.hadoop.yarn.server.resourcemanager.scheduler.capacity.ParentQueue: assignedContainer queue=root usedCapacity=0.9375 absoluteUsedCapacity=0.9375 used=<memory:46080, vCores:40> cluster=<memory:49152, vCores:96>
2013-08-07 03:28:13,185 INFO org.apache.hadoop.yarn.server.resourcemanager.rmcontainer.RMContainerImpl: container_1375845418464_0006_01_000037 Container Transitioned from NEW to ALLOCATED
2013-08-07 03:28:13,185 INFO org.apache.hadoop.yarn.server.resourcemanager.RMAuditLogger: USER=ubuntu	OPERATION=AM Allocated Container	TARGET=SchedulerApp	RESULT=SUCCESS	APPID=application_1375845418464_0006	CONTAINERID=container_1375845418464_0006_01_000037
2013-08-07 03:28:13,185 INFO org.apache.hadoop.yarn.server.resourcemanager.scheduler.common.fica.FiCaSchedulerNode: Assigned container container_1375845418464_0006_01_000037 of capacity <memory:1024, vCores:1> on host hadoop-200-7:47421, which currently has 5 containers, <memory:6144, vCores:5> used and <memory:2048, vCores:11> available
2013-08-07 03:28:13,186 INFO org.apache.hadoop.yarn.server.resourcemanager.scheduler.capacity.LeafQueue: assignedContainer application=application_1375845418464_0006 container=Container: [ContainerId: container_1375845418464_0006_01_000037, NodeId: hadoop-200-7:47421, NodeHttpAddress: hadoop-200-7:8042, Resource: <memory:1024, vCores:1>, Priority: 20, State: NEW, Token: null, Status: container_id {, app_attempt_id {, application_id {, id: 6, cluster_timestamp: 1375845418464, }, attemptId: 1, }, id: 37, }, state: C_NEW, ] containerId=container_1375845418464_0006_01_000037 queue=default: capacity=1.0, absoluteCapacity=1.0, usedResources=<memory:46080, vCores:40>usedCapacity=0.9375, absoluteUsedCapacity=0.9375, numApps=5, numContainers=40 usedCapacity=0.9375 absoluteUsedCapacity=0.9375 used=<memory:46080, vCores:40> cluster=<memory:49152, vCores:96>
2013-08-07 03:28:13,187 INFO org.apache.hadoop.yarn.server.resourcemanager.scheduler.capacity.ParentQueue: Re-sorting queues since queue: root.default stats: default: capacity=1.0, absoluteCapacity=1.0, usedResources=<memory:47104, vCores:41>usedCapacity=0.9583333, absoluteUsedCapacity=0.9583333, numApps=5, numContainers=41
2013-08-07 03:28:13,187 INFO org.apache.hadoop.yarn.server.resourcemanager.scheduler.capacity.ParentQueue: assignedContainer queue=root usedCapacity=0.9583333 absoluteUsedCapacity=0.9583333 used=<memory:47104, vCores:41> cluster=<memory:49152, vCores:96>
2013-08-07 03:28:13,187 INFO org.apache.hadoop.yarn.server.resourcemanager.rmcontainer.RMContainerImpl: container_1375845418464_0006_01_000038 Container Transitioned from NEW to ALLOCATED
2013-08-07 03:28:13,187 INFO org.apache.hadoop.yarn.server.resourcemanager.RMAuditLogger: USER=ubuntu	OPERATION=AM Allocated Container	TARGET=SchedulerApp	RESULT=SUCCESS	APPID=application_1375845418464_0006	CONTAINERID=container_1375845418464_0006_01_000038
2013-08-07 03:28:13,188 INFO org.apache.hadoop.yarn.server.resourcemanager.scheduler.common.fica.FiCaSchedulerNode: Assigned container container_1375845418464_0006_01_000038 of capacity <memory:1024, vCores:1> on host hadoop-200-7:47421, which currently has 6 containers, <memory:7168, vCores:6> used and <memory:1024, vCores:10> available
2013-08-07 03:28:13,188 INFO org.apache.hadoop.yarn.server.resourcemanager.scheduler.capacity.LeafQueue: assignedContainer application=application_1375845418464_0006 container=Container: [ContainerId: container_1375845418464_0006_01_000038, NodeId: hadoop-200-7:47421, NodeHttpAddress: hadoop-200-7:8042, Resource: <memory:1024, vCores:1>, Priority: 20, State: NEW, Token: null, Status: container_id {, app_attempt_id {, application_id {, id: 6, cluster_timestamp: 1375845418464, }, attemptId: 1, }, id: 38, }, state: C_NEW, ] containerId=container_1375845418464_0006_01_000038 queue=default: capacity=1.0, absoluteCapacity=1.0, usedResources=<memory:47104, vCores:41>usedCapacity=0.9583333, absoluteUsedCapacity=0.9583333, numApps=5, numContainers=41 usedCapacity=0.9583333 absoluteUsedCapacity=0.9583333 used=<memory:47104, vCores:41> cluster=<memory:49152, vCores:96>
2013-08-07 03:28:13,189 INFO org.apache.hadoop.yarn.server.resourcemanager.scheduler.capacity.ParentQueue: Re-sorting queues since queue: root.default stats: default: capacity=1.0, absoluteCapacity=1.0, usedResources=<memory:48128, vCores:42>usedCapacity=0.9791667, absoluteUsedCapacity=0.9791667, numApps=5, numContainers=42
2013-08-07 03:28:13,189 INFO org.apache.hadoop.yarn.server.resourcemanager.scheduler.capacity.ParentQueue: assignedContainer queue=root usedCapacity=0.9791667 absoluteUsedCapacity=0.9791667 used=<memory:48128, vCores:42> cluster=<memory:49152, vCores:96>
2013-08-07 03:28:13,189 INFO org.apache.hadoop.yarn.server.resourcemanager.rmcontainer.RMContainerImpl: container_1375845418464_0006_01_000039 Container Transitioned from NEW to ALLOCATED
2013-08-07 03:28:13,189 INFO org.apache.hadoop.yarn.server.resourcemanager.RMAuditLogger: USER=ubuntu	OPERATION=AM Allocated Container	TARGET=SchedulerApp	RESULT=SUCCESS	APPID=application_1375845418464_0006	CONTAINERID=container_1375845418464_0006_01_000039
2013-08-07 03:28:13,190 INFO org.apache.hadoop.yarn.server.resourcemanager.scheduler.common.fica.FiCaSchedulerNode: Assigned container container_1375845418464_0006_01_000039 of capacity <memory:1024, vCores:1> on host hadoop-200-7:47421, which currently has 7 containers, <memory:8192, vCores:7> used and <memory:0, vCores:9> available
2013-08-07 03:28:13,190 INFO org.apache.hadoop.yarn.server.resourcemanager.scheduler.capacity.LeafQueue: assignedContainer application=application_1375845418464_0006 container=Container: [ContainerId: container_1375845418464_0006_01_000039, NodeId: hadoop-200-7:47421, NodeHttpAddress: hadoop-200-7:8042, Resource: <memory:1024, vCores:1>, Priority: 20, State: NEW, Token: null, Status: container_id {, app_attempt_id {, application_id {, id: 6, cluster_timestamp: 1375845418464, }, attemptId: 1, }, id: 39, }, state: C_NEW, ] containerId=container_1375845418464_0006_01_000039 queue=default: capacity=1.0, absoluteCapacity=1.0, usedResources=<memory:48128, vCores:42>usedCapacity=0.9791667, absoluteUsedCapacity=0.9791667, numApps=5, numContainers=42 usedCapacity=0.9791667 absoluteUsedCapacity=0.9791667 used=<memory:48128, vCores:42> cluster=<memory:49152, vCores:96>
2013-08-07 03:28:13,191 INFO org.apache.hadoop.yarn.server.resourcemanager.scheduler.capacity.ParentQueue: Re-sorting queues since queue: root.default stats: default: capacity=1.0, absoluteCapacity=1.0, usedResources=<memory:49152, vCores:43>usedCapacity=1.0, absoluteUsedCapacity=1.0, numApps=5, numContainers=43
2013-08-07 03:28:13,191 INFO org.apache.hadoop.yarn.server.resourcemanager.scheduler.capacity.ParentQueue: assignedContainer queue=root usedCapacity=1.0 absoluteUsedCapacity=1.0 used=<memory:49152, vCores:43> cluster=<memory:49152, vCores:96>
2013-08-07 03:28:13,305 INFO org.apache.hadoop.yarn.server.resourcemanager.rmcontainer.RMContainerImpl: container_1375845418464_0006_01_000002 Container Transitioned from ALLOCATED to ACQUIRED
2013-08-07 03:28:13,307 INFO org.apache.hadoop.yarn.server.resourcemanager.rmcontainer.RMContainerImpl: container_1375845418464_0006_01_000003 Container Transitioned from ALLOCATED to ACQUIRED
2013-08-07 03:28:13,309 INFO org.apache.hadoop.yarn.server.resourcemanager.rmcontainer.RMContainerImpl: container_1375845418464_0006_01_000004 Container Transitioned from ALLOCATED to ACQUIRED
2013-08-07 03:28:13,310 INFO org.apache.hadoop.yarn.server.resourcemanager.rmcontainer.RMContainerImpl: container_1375845418464_0006_01_000005 Container Transitioned from ALLOCATED to ACQUIRED
2013-08-07 03:28:13,311 INFO org.apache.hadoop.yarn.server.resourcemanager.rmcontainer.RMContainerImpl: container_1375845418464_0006_01_000006 Container Transitioned from ALLOCATED to ACQUIRED
2013-08-07 03:28:13,312 INFO org.apache.hadoop.yarn.server.resourcemanager.rmcontainer.RMContainerImpl: container_1375845418464_0006_01_000007 Container Transitioned from ALLOCATED to ACQUIRED
2013-08-07 03:28:13,312 INFO org.apache.hadoop.yarn.server.resourcemanager.rmcontainer.RMContainerImpl: container_1375845418464_0006_01_000008 Container Transitioned from ALLOCATED to ACQUIRED
2013-08-07 03:28:13,314 INFO org.apache.hadoop.yarn.server.resourcemanager.rmcontainer.RMContainerImpl: container_1375845418464_0006_01_000009 Container Transitioned from ALLOCATED to ACQUIRED
2013-08-07 03:28:13,315 INFO org.apache.hadoop.yarn.server.resourcemanager.rmcontainer.RMContainerImpl: container_1375845418464_0006_01_000010 Container Transitioned from ALLOCATED to ACQUIRED
2013-08-07 03:28:13,316 INFO org.apache.hadoop.yarn.server.resourcemanager.rmcontainer.RMContainerImpl: container_1375845418464_0006_01_000011 Container Transitioned from ALLOCATED to ACQUIRED
2013-08-07 03:28:13,317 INFO org.apache.hadoop.yarn.server.resourcemanager.rmcontainer.RMContainerImpl: container_1375845418464_0006_01_000012 Container Transitioned from ALLOCATED to ACQUIRED
2013-08-07 03:28:13,317 INFO org.apache.hadoop.yarn.server.resourcemanager.rmcontainer.RMContainerImpl: container_1375845418464_0006_01_000013 Container Transitioned from ALLOCATED to ACQUIRED
2013-08-07 03:28:13,317 INFO org.apache.hadoop.yarn.server.resourcemanager.rmcontainer.RMContainerImpl: container_1375845418464_0006_01_000014 Container Transitioned from ALLOCATED to ACQUIRED
2013-08-07 03:28:13,317 INFO org.apache.hadoop.yarn.server.resourcemanager.rmcontainer.RMContainerImpl: container_1375845418464_0006_01_000015 Container Transitioned from ALLOCATED to ACQUIRED
2013-08-07 03:28:13,317 INFO org.apache.hadoop.yarn.server.resourcemanager.rmcontainer.RMContainerImpl: container_1375845418464_0006_01_000016 Container Transitioned from ALLOCATED to ACQUIRED
2013-08-07 03:28:13,317 INFO org.apache.hadoop.yarn.server.resourcemanager.rmcontainer.RMContainerImpl: container_1375845418464_0006_01_000017 Container Transitioned from ALLOCATED to ACQUIRED
2013-08-07 03:28:13,318 INFO org.apache.hadoop.yarn.server.resourcemanager.rmcontainer.RMContainerImpl: container_1375845418464_0006_01_000018 Container Transitioned from ALLOCATED to ACQUIRED
2013-08-07 03:28:13,318 INFO org.apache.hadoop.yarn.server.resourcemanager.rmcontainer.RMContainerImpl: container_1375845418464_0006_01_000019 Container Transitioned from ALLOCATED to ACQUIRED
2013-08-07 03:28:13,318 INFO org.apache.hadoop.yarn.server.resourcemanager.rmcontainer.RMContainerImpl: container_1375845418464_0006_01_000020 Container Transitioned from ALLOCATED to ACQUIRED
2013-08-07 03:28:13,318 INFO org.apache.hadoop.yarn.server.resourcemanager.rmcontainer.RMContainerImpl: container_1375845418464_0006_01_000021 Container Transitioned from ALLOCATED to ACQUIRED
2013-08-07 03:28:13,319 INFO org.apache.hadoop.yarn.server.resourcemanager.rmcontainer.RMContainerImpl: container_1375845418464_0006_01_000022 Container Transitioned from ALLOCATED to ACQUIRED
2013-08-07 03:28:13,319 INFO org.apache.hadoop.yarn.server.resourcemanager.rmcontainer.RMContainerImpl: container_1375845418464_0006_01_000023 Container Transitioned from ALLOCATED to ACQUIRED
2013-08-07 03:28:13,319 INFO org.apache.hadoop.yarn.server.resourcemanager.rmcontainer.RMContainerImpl: container_1375845418464_0006_01_000024 Container Transitioned from ALLOCATED to ACQUIRED
2013-08-07 03:28:13,319 INFO org.apache.hadoop.yarn.server.resourcemanager.rmcontainer.RMContainerImpl: container_1375845418464_0006_01_000025 Container Transitioned from ALLOCATED to ACQUIRED
2013-08-07 03:28:13,319 INFO org.apache.hadoop.yarn.server.resourcemanager.rmcontainer.RMContainerImpl: container_1375845418464_0006_01_000026 Container Transitioned from ALLOCATED to ACQUIRED
2013-08-07 03:28:13,319 INFO org.apache.hadoop.yarn.server.resourcemanager.rmcontainer.RMContainerImpl: container_1375845418464_0006_01_000027 Container Transitioned from ALLOCATED to ACQUIRED
2013-08-07 03:28:13,320 INFO org.apache.hadoop.yarn.server.resourcemanager.rmcontainer.RMContainerImpl: container_1375845418464_0006_01_000028 Container Transitioned from ALLOCATED to ACQUIRED
2013-08-07 03:28:13,320 INFO org.apache.hadoop.yarn.server.resourcemanager.rmcontainer.RMContainerImpl: container_1375845418464_0006_01_000029 Container Transitioned from ALLOCATED to ACQUIRED
2013-08-07 03:28:13,320 INFO org.apache.hadoop.yarn.server.resourcemanager.rmcontainer.RMContainerImpl: container_1375845418464_0006_01_000030 Container Transitioned from ALLOCATED to ACQUIRED
2013-08-07 03:28:13,320 INFO org.apache.hadoop.yarn.server.resourcemanager.rmcontainer.RMContainerImpl: container_1375845418464_0006_01_000031 Container Transitioned from ALLOCATED to ACQUIRED
2013-08-07 03:28:13,320 INFO org.apache.hadoop.yarn.server.resourcemanager.rmcontainer.RMContainerImpl: container_1375845418464_0006_01_000032 Container Transitioned from ALLOCATED to ACQUIRED
2013-08-07 03:28:13,321 INFO org.apache.hadoop.yarn.server.resourcemanager.rmcontainer.RMContainerImpl: container_1375845418464_0006_01_000033 Container Transitioned from ALLOCATED to ACQUIRED
2013-08-07 03:28:13,321 INFO org.apache.hadoop.yarn.server.resourcemanager.rmcontainer.RMContainerImpl: container_1375845418464_0006_01_000034 Container Transitioned from ALLOCATED to ACQUIRED
2013-08-07 03:28:13,321 INFO org.apache.hadoop.yarn.server.resourcemanager.rmcontainer.RMContainerImpl: container_1375845418464_0006_01_000035 Container Transitioned from ALLOCATED to ACQUIRED
2013-08-07 03:28:13,321 INFO org.apache.hadoop.yarn.server.resourcemanager.rmcontainer.RMContainerImpl: container_1375845418464_0006_01_000036 Container Transitioned from ALLOCATED to ACQUIRED
2013-08-07 03:28:13,321 INFO org.apache.hadoop.yarn.server.resourcemanager.rmcontainer.RMContainerImpl: container_1375845418464_0006_01_000037 Container Transitioned from ALLOCATED to ACQUIRED
2013-08-07 03:28:13,322 INFO org.apache.hadoop.yarn.server.resourcemanager.rmcontainer.RMContainerImpl: container_1375845418464_0006_01_000038 Container Transitioned from ALLOCATED to ACQUIRED
2013-08-07 03:28:13,322 INFO org.apache.hadoop.yarn.server.resourcemanager.rmcontainer.RMContainerImpl: container_1375845418464_0006_01_000039 Container Transitioned from ALLOCATED to ACQUIRED
2013-08-07 03:28:13,659 INFO org.apache.hadoop.yarn.server.resourcemanager.ApplicationMasterService: AM registration appattempt_1375845418464_0007_000001
2013-08-07 03:28:13,659 INFO org.apache.hadoop.yarn.server.resourcemanager.RMAuditLogger: USER=ubuntu	IP=192.168.100.15	OPERATION=Register App Master	TARGET=ApplicationMasterService	RESULT=SUCCESS	APPID=application_1375845418464_0007	APPATTEMPTID=appattempt_1375845418464_0007_000001
2013-08-07 03:28:13,660 INFO org.apache.hadoop.yarn.server.resourcemanager.rmapp.attempt.RMAppAttemptImpl: appattempt_1375845418464_0007_000001 State change from LAUNCHED to RUNNING
2013-08-07 03:28:13,660 INFO org.apache.hadoop.yarn.server.resourcemanager.rmapp.RMAppImpl: application_1375845418464_0007 State change from ACCEPTED to RUNNING
2013-08-07 03:28:13,856 INFO org.apache.hadoop.yarn.server.resourcemanager.ApplicationMasterService: AM registration appattempt_1375845418464_0010_000001
2013-08-07 03:28:13,856 INFO org.apache.hadoop.yarn.server.resourcemanager.RMAuditLogger: USER=ubuntu	IP=192.168.100.14	OPERATION=Register App Master	TARGET=ApplicationMasterService	RESULT=SUCCESS	APPID=application_1375845418464_0010	APPATTEMPTID=appattempt_1375845418464_0010_000001
2013-08-07 03:28:13,857 INFO org.apache.hadoop.yarn.server.resourcemanager.rmapp.attempt.RMAppAttemptImpl: appattempt_1375845418464_0010_000001 State change from LAUNCHED to RUNNING
2013-08-07 03:28:13,857 INFO org.apache.hadoop.yarn.server.resourcemanager.rmapp.RMAppImpl: application_1375845418464_0010 State change from ACCEPTED to RUNNING
2013-08-07 03:28:13,880 INFO org.apache.hadoop.yarn.server.resourcemanager.ApplicationMasterService: AM registration appattempt_1375845418464_0009_000001
2013-08-07 03:28:13,880 INFO org.apache.hadoop.yarn.server.resourcemanager.RMAuditLogger: USER=ubuntu	IP=192.168.100.17	OPERATION=Register App Master	TARGET=ApplicationMasterService	RESULT=SUCCESS	APPID=application_1375845418464_0009	APPATTEMPTID=appattempt_1375845418464_0009_000001
2013-08-07 03:28:13,881 INFO org.apache.hadoop.yarn.server.resourcemanager.rmapp.attempt.RMAppAttemptImpl: appattempt_1375845418464_0009_000001 State change from LAUNCHED to RUNNING
2013-08-07 03:28:13,881 INFO org.apache.hadoop.yarn.server.resourcemanager.rmapp.RMAppImpl: application_1375845418464_0009 State change from ACCEPTED to RUNNING
2013-08-07 03:28:14,052 INFO org.apache.hadoop.yarn.server.resourcemanager.rmcontainer.RMContainerImpl: container_1375845418464_0006_01_000026 Container Transitioned from ACQUIRED to RUNNING
2013-08-07 03:28:14,053 INFO org.apache.hadoop.yarn.server.resourcemanager.rmcontainer.RMContainerImpl: container_1375845418464_0006_01_000027 Container Transitioned from ACQUIRED to RUNNING
2013-08-07 03:28:14,053 INFO org.apache.hadoop.yarn.server.resourcemanager.rmcontainer.RMContainerImpl: container_1375845418464_0006_01_000028 Container Transitioned from ACQUIRED to RUNNING
2013-08-07 03:28:14,054 INFO org.apache.hadoop.yarn.server.resourcemanager.rmcontainer.RMContainerImpl: container_1375845418464_0006_01_000029 Container Transitioned from ACQUIRED to RUNNING
2013-08-07 03:28:14,054 INFO org.apache.hadoop.yarn.server.resourcemanager.rmcontainer.RMContainerImpl: container_1375845418464_0006_01_000030 Container Transitioned from ACQUIRED to RUNNING
2013-08-07 03:28:14,055 INFO org.apache.hadoop.yarn.server.resourcemanager.rmcontainer.RMContainerImpl: container_1375845418464_0006_01_000031 Container Transitioned from ACQUIRED to RUNNING
2013-08-07 03:28:14,055 INFO org.apache.hadoop.yarn.server.resourcemanager.rmcontainer.RMContainerImpl: container_1375845418464_0006_01_000032 Container Transitioned from ACQUIRED to RUNNING
2013-08-07 03:28:14,056 INFO org.apache.hadoop.yarn.server.resourcemanager.rmcontainer.RMContainerImpl: container_1375845418464_0006_01_000033 Container Transitioned from ACQUIRED to RUNNING
2013-08-07 03:28:14,190 INFO org.apache.hadoop.yarn.server.resourcemanager.rmcontainer.RMContainerImpl: container_1375845418464_0006_01_000034 Container Transitioned from ACQUIRED to RUNNING
2013-08-07 03:28:14,190 INFO org.apache.hadoop.yarn.server.resourcemanager.rmcontainer.RMContainerImpl: container_1375845418464_0006_01_000035 Container Transitioned from ACQUIRED to RUNNING
2013-08-07 03:28:14,191 INFO org.apache.hadoop.yarn.server.resourcemanager.rmcontainer.RMContainerImpl: container_1375845418464_0006_01_000036 Container Transitioned from ACQUIRED to RUNNING
2013-08-07 03:28:14,191 INFO org.apache.hadoop.yarn.server.resourcemanager.rmcontainer.RMContainerImpl: container_1375845418464_0006_01_000037 Container Transitioned from ACQUIRED to RUNNING
2013-08-07 03:28:14,192 INFO org.apache.hadoop.yarn.server.resourcemanager.rmcontainer.RMContainerImpl: container_1375845418464_0006_01_000038 Container Transitioned from ACQUIRED to RUNNING
2013-08-07 03:28:14,192 INFO org.apache.hadoop.yarn.server.resourcemanager.rmcontainer.RMContainerImpl: container_1375845418464_0006_01_000039 Container Transitioned from ACQUIRED to RUNNING
2013-08-07 03:28:14,373 INFO org.apache.hadoop.yarn.server.resourcemanager.rmcontainer.RMContainerImpl: container_1375845418464_0006_01_000002 Container Transitioned from ACQUIRED to RUNNING
2013-08-07 03:28:14,374 INFO org.apache.hadoop.yarn.server.resourcemanager.rmcontainer.RMContainerImpl: container_1375845418464_0006_01_000003 Container Transitioned from ACQUIRED to RUNNING
2013-08-07 03:28:14,374 INFO org.apache.hadoop.yarn.server.resourcemanager.rmcontainer.RMContainerImpl: container_1375845418464_0006_01_000004 Container Transitioned from ACQUIRED to RUNNING
2013-08-07 03:28:14,374 INFO org.apache.hadoop.yarn.server.resourcemanager.rmcontainer.RMContainerImpl: container_1375845418464_0006_01_000005 Container Transitioned from ACQUIRED to RUNNING
2013-08-07 03:28:14,374 INFO org.apache.hadoop.yarn.server.resourcemanager.rmcontainer.RMContainerImpl: container_1375845418464_0006_01_000006 Container Transitioned from ACQUIRED to RUNNING
2013-08-07 03:28:14,374 INFO org.apache.hadoop.yarn.server.resourcemanager.rmcontainer.RMContainerImpl: container_1375845418464_0006_01_000007 Container Transitioned from ACQUIRED to RUNNING
2013-08-07 03:28:14,508 INFO org.apache.hadoop.yarn.server.resourcemanager.rmcontainer.RMContainerImpl: container_1375845418464_0006_01_000008 Container Transitioned from ACQUIRED to RUNNING
2013-08-07 03:28:14,508 INFO org.apache.hadoop.yarn.server.resourcemanager.rmcontainer.RMContainerImpl: container_1375845418464_0006_01_000009 Container Transitioned from ACQUIRED to RUNNING
2013-08-07 03:28:14,508 INFO org.apache.hadoop.yarn.server.resourcemanager.rmcontainer.RMContainerImpl: container_1375845418464_0006_01_000010 Container Transitioned from ACQUIRED to RUNNING
2013-08-07 03:28:14,509 INFO org.apache.hadoop.yarn.server.resourcemanager.rmcontainer.RMContainerImpl: container_1375845418464_0006_01_000011 Container Transitioned from ACQUIRED to RUNNING
2013-08-07 03:28:14,509 INFO org.apache.hadoop.yarn.server.resourcemanager.rmcontainer.RMContainerImpl: container_1375845418464_0006_01_000012 Container Transitioned from ACQUIRED to RUNNING
2013-08-07 03:28:14,510 INFO org.apache.hadoop.yarn.server.resourcemanager.rmcontainer.RMContainerImpl: container_1375845418464_0006_01_000013 Container Transitioned from ACQUIRED to RUNNING
2013-08-07 03:28:14,649 INFO org.apache.hadoop.yarn.server.resourcemanager.rmcontainer.RMContainerImpl: container_1375845418464_0006_01_000014 Container Transitioned from ACQUIRED to RUNNING
2013-08-07 03:28:14,649 INFO org.apache.hadoop.yarn.server.resourcemanager.rmcontainer.RMContainerImpl: container_1375845418464_0006_01_000015 Container Transitioned from ACQUIRED to RUNNING
2013-08-07 03:28:14,651 INFO org.apache.hadoop.yarn.server.resourcemanager.rmcontainer.RMContainerImpl: container_1375845418464_0006_01_000016 Container Transitioned from ACQUIRED to RUNNING
2013-08-07 03:28:14,651 INFO org.apache.hadoop.yarn.server.resourcemanager.rmcontainer.RMContainerImpl: container_1375845418464_0006_01_000017 Container Transitioned from ACQUIRED to RUNNING
2013-08-07 03:28:14,651 INFO org.apache.hadoop.yarn.server.resourcemanager.rmcontainer.RMContainerImpl: container_1375845418464_0006_01_000018 Container Transitioned from ACQUIRED to RUNNING
2013-08-07 03:28:14,651 INFO org.apache.hadoop.yarn.server.resourcemanager.rmcontainer.RMContainerImpl: container_1375845418464_0006_01_000019 Container Transitioned from ACQUIRED to RUNNING
2013-08-07 03:28:14,818 INFO org.apache.hadoop.yarn.server.resourcemanager.rmcontainer.RMContainerImpl: container_1375845418464_0006_01_000020 Container Transitioned from ACQUIRED to RUNNING
2013-08-07 03:28:14,818 INFO org.apache.hadoop.yarn.server.resourcemanager.rmcontainer.RMContainerImpl: container_1375845418464_0006_01_000021 Container Transitioned from ACQUIRED to RUNNING
2013-08-07 03:28:14,818 INFO org.apache.hadoop.yarn.server.resourcemanager.rmcontainer.RMContainerImpl: container_1375845418464_0006_01_000022 Container Transitioned from ACQUIRED to RUNNING
2013-08-07 03:28:14,818 INFO org.apache.hadoop.yarn.server.resourcemanager.rmcontainer.RMContainerImpl: container_1375845418464_0006_01_000023 Container Transitioned from ACQUIRED to RUNNING
2013-08-07 03:28:14,818 INFO org.apache.hadoop.yarn.server.resourcemanager.rmcontainer.RMContainerImpl: container_1375845418464_0006_01_000024 Container Transitioned from ACQUIRED to RUNNING
2013-08-07 03:28:14,818 INFO org.apache.hadoop.yarn.server.resourcemanager.rmcontainer.RMContainerImpl: container_1375845418464_0006_01_000025 Container Transitioned from ACQUIRED to RUNNING
2013-08-07 03:28:34,598 INFO org.apache.hadoop.yarn.server.resourcemanager.rmcontainer.RMContainerImpl: container_1375845418464_0006_01_000010 Container Transitioned from RUNNING to COMPLETED
2013-08-07 03:28:34,598 INFO org.apache.hadoop.yarn.server.resourcemanager.scheduler.common.fica.FiCaSchedulerApp: Completed container: container_1375845418464_0006_01_000010 in state: COMPLETED event:FINISHED
2013-08-07 03:28:34,598 INFO org.apache.hadoop.yarn.server.resourcemanager.RMAuditLogger: USER=ubuntu	OPERATION=AM Released Container	TARGET=SchedulerApp	RESULT=SUCCESS	APPID=application_1375845418464_0006	CONTAINERID=container_1375845418464_0006_01_000010
2013-08-07 03:28:34,598 INFO org.apache.hadoop.yarn.server.resourcemanager.scheduler.common.fica.FiCaSchedulerNode: Released container container_1375845418464_0006_01_000010 of capacity <memory:1024, vCores:1> on host hadoop-200-2:46099, which currently has 6 containers, <memory:7168, vCores:6> used and <memory:1024, vCores:10> available, release resources=true
2013-08-07 03:28:34,599 INFO org.apache.hadoop.yarn.server.resourcemanager.scheduler.capacity.LeafQueue: default used=<memory:48128, vCores:42> numContainers=42 user=ubuntu user-resources=<memory:48128, vCores:42>
2013-08-07 03:28:34,601 INFO org.apache.hadoop.yarn.server.resourcemanager.scheduler.capacity.LeafQueue: completedContainer container=Container: [ContainerId: container_1375845418464_0006_01_000010, NodeId: hadoop-200-2:46099, NodeHttpAddress: hadoop-200-2:8042, Resource: <memory:1024, vCores:1>, Priority: 20, State: NEW, Token: null, Status: container_id {, app_attempt_id {, application_id {, id: 6, cluster_timestamp: 1375845418464, }, attemptId: 1, }, id: 10, }, state: C_COMPLETE, diagnostics: "Container killed by the ApplicationMaster.\n\n", exit_status: 143, ] resource=<memory:1024, vCores:1> queue=default: capacity=1.0, absoluteCapacity=1.0, usedResources=<memory:48128, vCores:42>usedCapacity=0.9791667, absoluteUsedCapacity=0.9791667, numApps=5, numContainers=42 usedCapacity=0.9791667 absoluteUsedCapacity=0.9791667 used=<memory:48128, vCores:42> cluster=<memory:49152, vCores:96>
2013-08-07 03:28:34,602 INFO org.apache.hadoop.yarn.server.resourcemanager.scheduler.capacity.ParentQueue: completedContainer queue=root usedCapacity=0.9791667 absoluteUsedCapacity=0.9791667 used=<memory:48128, vCores:42> cluster=<memory:49152, vCores:96>
2013-08-07 03:28:34,602 INFO org.apache.hadoop.yarn.server.resourcemanager.scheduler.capacity.CapacityScheduler: Application appattempt_1375845418464_0006_000001 released container container_1375845418464_0006_01_000010 on node: host: hadoop-200-2:46099 #containers=6 available=1024 used=7168 with event: FINISHED
2013-08-07 03:28:34,602 INFO org.apache.hadoop.yarn.server.resourcemanager.rmcontainer.RMContainerImpl: container_1375845418464_0006_01_000040 Container Transitioned from NEW to ALLOCATED
2013-08-07 03:28:34,602 INFO org.apache.hadoop.yarn.server.resourcemanager.RMAuditLogger: USER=ubuntu	OPERATION=AM Allocated Container	TARGET=SchedulerApp	RESULT=SUCCESS	APPID=application_1375845418464_0006	CONTAINERID=container_1375845418464_0006_01_000040
2013-08-07 03:28:34,603 INFO org.apache.hadoop.yarn.server.resourcemanager.scheduler.common.fica.FiCaSchedulerNode: Assigned container container_1375845418464_0006_01_000040 of capacity <memory:1024, vCores:1> on host hadoop-200-2:46099, which currently has 7 containers, <memory:8192, vCores:7> used and <memory:0, vCores:9> available
2013-08-07 03:28:34,603 INFO org.apache.hadoop.yarn.server.resourcemanager.scheduler.capacity.LeafQueue: assignedContainer application=application_1375845418464_0006 container=Container: [ContainerId: container_1375845418464_0006_01_000040, NodeId: hadoop-200-2:46099, NodeHttpAddress: hadoop-200-2:8042, Resource: <memory:1024, vCores:1>, Priority: 20, State: NEW, Token: null, Status: container_id {, app_attempt_id {, application_id {, id: 6, cluster_timestamp: 1375845418464, }, attemptId: 1, }, id: 40, }, state: C_NEW, ] containerId=container_1375845418464_0006_01_000040 queue=default: capacity=1.0, absoluteCapacity=1.0, usedResources=<memory:48128, vCores:42>usedCapacity=0.9791667, absoluteUsedCapacity=0.9791667, numApps=5, numContainers=42 usedCapacity=0.9791667 absoluteUsedCapacity=0.9791667 used=<memory:48128, vCores:42> cluster=<memory:49152, vCores:96>
2013-08-07 03:28:34,604 INFO org.apache.hadoop.yarn.server.resourcemanager.scheduler.capacity.ParentQueue: Re-sorting queues since queue: root.default stats: default: capacity=1.0, absoluteCapacity=1.0, usedResources=<memory:49152, vCores:43>usedCapacity=1.0, absoluteUsedCapacity=1.0, numApps=5, numContainers=43
2013-08-07 03:28:34,604 INFO org.apache.hadoop.yarn.server.resourcemanager.scheduler.capacity.ParentQueue: assignedContainer queue=root usedCapacity=1.0 absoluteUsedCapacity=1.0 used=<memory:49152, vCores:43> cluster=<memory:49152, vCores:96>
2013-08-07 03:28:35,052 INFO org.apache.hadoop.yarn.server.resourcemanager.rmcontainer.RMContainerImpl: container_1375845418464_0006_01_000034 Container Transitioned from RUNNING to COMPLETED
2013-08-07 03:28:35,052 INFO org.apache.hadoop.yarn.server.resourcemanager.scheduler.common.fica.FiCaSchedulerApp: Completed container: container_1375845418464_0006_01_000034 in state: COMPLETED event:FINISHED
2013-08-07 03:28:35,052 INFO org.apache.hadoop.yarn.server.resourcemanager.RMAuditLogger: USER=ubuntu	OPERATION=AM Released Container	TARGET=SchedulerApp	RESULT=SUCCESS	APPID=application_1375845418464_0006	CONTAINERID=container_1375845418464_0006_01_000034
2013-08-07 03:28:35,052 INFO org.apache.hadoop.yarn.server.resourcemanager.scheduler.common.fica.FiCaSchedulerNode: Released container container_1375845418464_0006_01_000034 of capacity <memory:1024, vCores:1> on host hadoop-200-7:47421, which currently has 6 containers, <memory:7168, vCores:6> used and <memory:1024, vCores:10> available, release resources=true
2013-08-07 03:28:35,053 INFO org.apache.hadoop.yarn.server.resourcemanager.scheduler.capacity.LeafQueue: default used=<memory:48128, vCores:42> numContainers=42 user=ubuntu user-resources=<memory:48128, vCores:42>
2013-08-07 03:28:35,054 INFO org.apache.hadoop.yarn.server.resourcemanager.scheduler.capacity.LeafQueue: completedContainer container=Container: [ContainerId: container_1375845418464_0006_01_000034, NodeId: hadoop-200-7:47421, NodeHttpAddress: hadoop-200-7:8042, Resource: <memory:1024, vCores:1>, Priority: 20, State: NEW, Token: null, Status: container_id {, app_attempt_id {, application_id {, id: 6, cluster_timestamp: 1375845418464, }, attemptId: 1, }, id: 34, }, state: C_COMPLETE, diagnostics: "", exit_status: 0, ] resource=<memory:1024, vCores:1> queue=default: capacity=1.0, absoluteCapacity=1.0, usedResources=<memory:48128, vCores:42>usedCapacity=0.9791667, absoluteUsedCapacity=0.9791667, numApps=5, numContainers=42 usedCapacity=0.9791667 absoluteUsedCapacity=0.9791667 used=<memory:48128, vCores:42> cluster=<memory:49152, vCores:96>
2013-08-07 03:28:35,054 INFO org.apache.hadoop.yarn.server.resourcemanager.scheduler.capacity.ParentQueue: completedContainer queue=root usedCapacity=0.9791667 absoluteUsedCapacity=0.9791667 used=<memory:48128, vCores:42> cluster=<memory:49152, vCores:96>
2013-08-07 03:28:35,054 INFO org.apache.hadoop.yarn.server.resourcemanager.scheduler.capacity.CapacityScheduler: Application appattempt_1375845418464_0006_000001 released container container_1375845418464_0006_01_000034 on node: host: hadoop-200-7:47421 #containers=6 available=1024 used=7168 with event: FINISHED
2013-08-07 03:28:35,055 INFO org.apache.hadoop.yarn.server.resourcemanager.rmcontainer.RMContainerImpl: container_1375845418464_0006_01_000041 Container Transitioned from NEW to ALLOCATED
2013-08-07 03:28:35,055 INFO org.apache.hadoop.yarn.server.resourcemanager.RMAuditLogger: USER=ubuntu	OPERATION=AM Allocated Container	TARGET=SchedulerApp	RESULT=SUCCESS	APPID=application_1375845418464_0006	CONTAINERID=container_1375845418464_0006_01_000041
2013-08-07 03:28:35,055 INFO org.apache.hadoop.yarn.server.resourcemanager.scheduler.common.fica.FiCaSchedulerNode: Assigned container container_1375845418464_0006_01_000041 of capacity <memory:1024, vCores:1> on host hadoop-200-7:47421, which currently has 7 containers, <memory:8192, vCores:7> used and <memory:0, vCores:9> available
2013-08-07 03:28:35,056 INFO org.apache.hadoop.yarn.server.resourcemanager.scheduler.capacity.LeafQueue: assignedContainer application=application_1375845418464_0006 container=Container: [ContainerId: container_1375845418464_0006_01_000041, NodeId: hadoop-200-7:47421, NodeHttpAddress: hadoop-200-7:8042, Resource: <memory:1024, vCores:1>, Priority: 20, State: NEW, Token: null, Status: container_id {, app_attempt_id {, application_id {, id: 6, cluster_timestamp: 1375845418464, }, attemptId: 1, }, id: 41, }, state: C_NEW, ] containerId=container_1375845418464_0006_01_000041 queue=default: capacity=1.0, absoluteCapacity=1.0, usedResources=<memory:48128, vCores:42>usedCapacity=0.9791667, absoluteUsedCapacity=0.9791667, numApps=5, numContainers=42 usedCapacity=0.9791667 absoluteUsedCapacity=0.9791667 used=<memory:48128, vCores:42> cluster=<memory:49152, vCores:96>
2013-08-07 03:28:35,056 INFO org.apache.hadoop.yarn.server.resourcemanager.scheduler.capacity.ParentQueue: Re-sorting queues since queue: root.default stats: default: capacity=1.0, absoluteCapacity=1.0, usedResources=<memory:49152, vCores:43>usedCapacity=1.0, absoluteUsedCapacity=1.0, numApps=5, numContainers=43
2013-08-07 03:28:35,056 INFO org.apache.hadoop.yarn.server.resourcemanager.scheduler.capacity.ParentQueue: assignedContainer queue=root usedCapacity=1.0 absoluteUsedCapacity=1.0 used=<memory:49152, vCores:43> cluster=<memory:49152, vCores:96>
2013-08-07 03:28:35,354 INFO org.apache.hadoop.yarn.server.resourcemanager.rmcontainer.RMContainerImpl: container_1375845418464_0006_01_000006 Container Transitioned from RUNNING to COMPLETED
2013-08-07 03:28:35,354 INFO org.apache.hadoop.yarn.server.resourcemanager.scheduler.common.fica.FiCaSchedulerApp: Completed container: container_1375845418464_0006_01_000006 in state: COMPLETED event:FINISHED
2013-08-07 03:28:35,354 INFO org.apache.hadoop.yarn.server.resourcemanager.RMAuditLogger: USER=ubuntu	OPERATION=AM Released Container	TARGET=SchedulerApp	RESULT=SUCCESS	APPID=application_1375845418464_0006	CONTAINERID=container_1375845418464_0006_01_000006
2013-08-07 03:28:35,354 INFO org.apache.hadoop.yarn.server.resourcemanager.scheduler.common.fica.FiCaSchedulerNode: Released container container_1375845418464_0006_01_000006 of capacity <memory:1024, vCores:1> on host hadoop-200-5:34756, which currently has 6 containers, <memory:7168, vCores:6> used and <memory:1024, vCores:10> available, release resources=true
2013-08-07 03:28:35,354 INFO org.apache.hadoop.yarn.server.resourcemanager.scheduler.capacity.LeafQueue: default used=<memory:48128, vCores:42> numContainers=42 user=ubuntu user-resources=<memory:48128, vCores:42>
2013-08-07 03:28:35,355 INFO org.apache.hadoop.yarn.server.resourcemanager.scheduler.capacity.LeafQueue: completedContainer container=Container: [ContainerId: container_1375845418464_0006_01_000006, NodeId: hadoop-200-5:34756, NodeHttpAddress: hadoop-200-5:8042, Resource: <memory:1024, vCores:1>, Priority: 20, State: NEW, Token: null, Status: container_id {, app_attempt_id {, application_id {, id: 6, cluster_timestamp: 1375845418464, }, attemptId: 1, }, id: 6, }, state: C_COMPLETE, diagnostics: "Container killed by the ApplicationMaster.\n\n", exit_status: 143, ] resource=<memory:1024, vCores:1> queue=default: capacity=1.0, absoluteCapacity=1.0, usedResources=<memory:48128, vCores:42>usedCapacity=0.9791667, absoluteUsedCapacity=0.9791667, numApps=5, numContainers=42 usedCapacity=0.9791667 absoluteUsedCapacity=0.9791667 used=<memory:48128, vCores:42> cluster=<memory:49152, vCores:96>
2013-08-07 03:28:35,356 INFO org.apache.hadoop.yarn.server.resourcemanager.scheduler.capacity.ParentQueue: completedContainer queue=root usedCapacity=0.9791667 absoluteUsedCapacity=0.9791667 used=<memory:48128, vCores:42> cluster=<memory:49152, vCores:96>
2013-08-07 03:28:35,356 INFO org.apache.hadoop.yarn.server.resourcemanager.scheduler.capacity.CapacityScheduler: Application appattempt_1375845418464_0006_000001 released container container_1375845418464_0006_01_000006 on node: host: hadoop-200-5:34756 #containers=6 available=1024 used=7168 with event: FINISHED
2013-08-07 03:28:35,356 INFO org.apache.hadoop.yarn.server.resourcemanager.rmcontainer.RMContainerImpl: container_1375845418464_0007_01_000002 Container Transitioned from NEW to ALLOCATED
2013-08-07 03:28:35,356 INFO org.apache.hadoop.yarn.server.resourcemanager.RMAuditLogger: USER=ubuntu	OPERATION=AM Allocated Container	TARGET=SchedulerApp	RESULT=SUCCESS	APPID=application_1375845418464_0007	CONTAINERID=container_1375845418464_0007_01_000002
2013-08-07 03:28:35,357 INFO org.apache.hadoop.yarn.server.resourcemanager.scheduler.common.fica.FiCaSchedulerNode: Assigned container container_1375845418464_0007_01_000002 of capacity <memory:1024, vCores:1> on host hadoop-200-5:34756, which currently has 7 containers, <memory:8192, vCores:7> used and <memory:0, vCores:9> available
2013-08-07 03:28:35,358 INFO org.apache.hadoop.yarn.server.resourcemanager.scheduler.capacity.LeafQueue: assignedContainer application=application_1375845418464_0007 container=Container: [ContainerId: container_1375845418464_0007_01_000002, NodeId: hadoop-200-5:34756, NodeHttpAddress: hadoop-200-5:8042, Resource: <memory:1024, vCores:1>, Priority: 20, State: NEW, Token: null, Status: container_id {, app_attempt_id {, application_id {, id: 7, cluster_timestamp: 1375845418464, }, attemptId: 1, }, id: 2, }, state: C_NEW, ] containerId=container_1375845418464_0007_01_000002 queue=default: capacity=1.0, absoluteCapacity=1.0, usedResources=<memory:48128, vCores:42>usedCapacity=0.9791667, absoluteUsedCapacity=0.9791667, numApps=5, numContainers=42 usedCapacity=0.9791667 absoluteUsedCapacity=0.9791667 used=<memory:48128, vCores:42> cluster=<memory:49152, vCores:96>
2013-08-07 03:28:35,358 INFO org.apache.hadoop.yarn.server.resourcemanager.scheduler.capacity.ParentQueue: Re-sorting queues since queue: root.default stats: default: capacity=1.0, absoluteCapacity=1.0, usedResources=<memory:49152, vCores:43>usedCapacity=1.0, absoluteUsedCapacity=1.0, numApps=5, numContainers=43
2013-08-07 03:28:35,358 INFO org.apache.hadoop.yarn.server.resourcemanager.scheduler.capacity.ParentQueue: assignedContainer queue=root usedCapacity=1.0 absoluteUsedCapacity=1.0 used=<memory:49152, vCores:43> cluster=<memory:49152, vCores:96>
2013-08-07 03:28:35,502 INFO org.apache.hadoop.yarn.server.resourcemanager.rmcontainer.RMContainerImpl: container_1375845418464_0006_01_000040 Container Transitioned from ALLOCATED to ACQUIRED
2013-08-07 03:28:35,503 INFO org.apache.hadoop.yarn.server.resourcemanager.rmcontainer.RMContainerImpl: container_1375845418464_0006_01_000041 Container Transitioned from ALLOCATED to ACQUIRED
2013-08-07 03:28:35,609 INFO org.apache.hadoop.yarn.server.resourcemanager.rmcontainer.RMContainerImpl: container_1375845418464_0006_01_000040 Container Transitioned from ACQUIRED to RUNNING
2013-08-07 03:28:36,041 INFO org.apache.hadoop.yarn.server.resourcemanager.rmcontainer.RMContainerImpl: container_1375845418464_0007_01_000002 Container Transitioned from ALLOCATED to ACQUIRED
2013-08-07 03:28:36,134 INFO org.apache.hadoop.yarn.server.resourcemanager.rmcontainer.RMContainerImpl: container_1375845418464_0006_01_000041 Container Transitioned from ACQUIRED to RUNNING
2013-08-07 03:28:36,135 INFO org.apache.hadoop.yarn.server.resourcemanager.rmcontainer.RMContainerImpl: container_1375845418464_0006_01_000016 Container Transitioned from RUNNING to COMPLETED
2013-08-07 03:28:36,135 INFO org.apache.hadoop.yarn.server.resourcemanager.scheduler.common.fica.FiCaSchedulerApp: Completed container: container_1375845418464_0006_01_000016 in state: COMPLETED event:FINISHED
2013-08-07 03:28:36,135 INFO org.apache.hadoop.yarn.server.resourcemanager.RMAuditLogger: USER=ubuntu	OPERATION=AM Released Container	TARGET=SchedulerApp	RESULT=SUCCESS	APPID=application_1375845418464_0006	CONTAINERID=container_1375845418464_0006_01_000016
2013-08-07 03:28:36,135 INFO org.apache.hadoop.yarn.server.resourcemanager.scheduler.common.fica.FiCaSchedulerNode: Released container container_1375845418464_0006_01_000016 of capacity <memory:1024, vCores:1> on host hadoop-200-6:45851, which currently has 6 containers, <memory:7168, vCores:6> used and <memory:1024, vCores:10> available, release resources=true
2013-08-07 03:28:36,135 INFO org.apache.hadoop.yarn.server.resourcemanager.scheduler.capacity.LeafQueue: default used=<memory:48128, vCores:42> numContainers=42 user=ubuntu user-resources=<memory:48128, vCores:42>
2013-08-07 03:28:36,136 INFO org.apache.hadoop.yarn.server.resourcemanager.scheduler.capacity.LeafQueue: completedContainer container=Container: [ContainerId: container_1375845418464_0006_01_000016, NodeId: hadoop-200-6:45851, NodeHttpAddress: hadoop-200-6:8042, Resource: <memory:1024, vCores:1>, Priority: 20, State: NEW, Token: null, Status: container_id {, app_attempt_id {, application_id {, id: 6, cluster_timestamp: 1375845418464, }, attemptId: 1, }, id: 16, }, state: C_COMPLETE, diagnostics: "Container killed by the ApplicationMaster.\n\n", exit_status: 143, ] resource=<memory:1024, vCores:1> queue=default: capacity=1.0, absoluteCapacity=1.0, usedResources=<memory:48128, vCores:42>usedCapacity=0.9791667, absoluteUsedCapacity=0.9791667, numApps=5, numContainers=42 usedCapacity=0.9791667 absoluteUsedCapacity=0.9791667 used=<memory:48128, vCores:42> cluster=<memory:49152, vCores:96>
2013-08-07 03:28:36,137 INFO org.apache.hadoop.yarn.server.resourcemanager.scheduler.capacity.ParentQueue: completedContainer queue=root usedCapacity=0.9791667 absoluteUsedCapacity=0.9791667 used=<memory:48128, vCores:42> cluster=<memory:49152, vCores:96>
2013-08-07 03:28:36,137 INFO org.apache.hadoop.yarn.server.resourcemanager.scheduler.capacity.CapacityScheduler: Application appattempt_1375845418464_0006_000001 released container container_1375845418464_0006_01_000016 on node: host: hadoop-200-6:45851 #containers=6 available=1024 used=7168 with event: FINISHED
2013-08-07 03:28:36,137 INFO org.apache.hadoop.yarn.server.resourcemanager.rmcontainer.RMContainerImpl: container_1375845418464_0007_01_000003 Container Transitioned from NEW to ALLOCATED
2013-08-07 03:28:36,138 INFO org.apache.hadoop.yarn.server.resourcemanager.RMAuditLogger: USER=ubuntu	OPERATION=AM Allocated Container	TARGET=SchedulerApp	RESULT=SUCCESS	APPID=application_1375845418464_0007	CONTAINERID=container_1375845418464_0007_01_000003
2013-08-07 03:28:36,138 INFO org.apache.hadoop.yarn.server.resourcemanager.scheduler.common.fica.FiCaSchedulerNode: Assigned container container_1375845418464_0007_01_000003 of capacity <memory:1024, vCores:1> on host hadoop-200-6:45851, which currently has 7 containers, <memory:8192, vCores:7> used and <memory:0, vCores:9> available
2013-08-07 03:28:36,139 INFO org.apache.hadoop.yarn.server.resourcemanager.scheduler.capacity.LeafQueue: assignedContainer application=application_1375845418464_0007 container=Container: [ContainerId: container_1375845418464_0007_01_000003, NodeId: hadoop-200-6:45851, NodeHttpAddress: hadoop-200-6:8042, Resource: <memory:1024, vCores:1>, Priority: 20, State: NEW, Token: null, Status: container_id {, app_attempt_id {, application_id {, id: 7, cluster_timestamp: 1375845418464, }, attemptId: 1, }, id: 3, }, state: C_NEW, ] containerId=container_1375845418464_0007_01_000003 queue=default: capacity=1.0, absoluteCapacity=1.0, usedResources=<memory:48128, vCores:42>usedCapacity=0.9791667, absoluteUsedCapacity=0.9791667, numApps=5, numContainers=42 usedCapacity=0.9791667 absoluteUsedCapacity=0.9791667 used=<memory:48128, vCores:42> cluster=<memory:49152, vCores:96>
2013-08-07 03:28:36,139 INFO org.apache.hadoop.yarn.server.resourcemanager.scheduler.capacity.ParentQueue: Re-sorting queues since queue: root.default stats: default: capacity=1.0, absoluteCapacity=1.0, usedResources=<memory:49152, vCores:43>usedCapacity=1.0, absoluteUsedCapacity=1.0, numApps=5, numContainers=43
2013-08-07 03:28:36,139 INFO org.apache.hadoop.yarn.server.resourcemanager.scheduler.capacity.ParentQueue: assignedContainer queue=root usedCapacity=1.0 absoluteUsedCapacity=1.0 used=<memory:49152, vCores:43> cluster=<memory:49152, vCores:96>
2013-08-07 03:28:36,363 INFO org.apache.hadoop.yarn.server.resourcemanager.rmcontainer.RMContainerImpl: container_1375845418464_0006_01_000003 Container Transitioned from RUNNING to COMPLETED
2013-08-07 03:28:36,363 INFO org.apache.hadoop.yarn.server.resourcemanager.scheduler.common.fica.FiCaSchedulerApp: Completed container: container_1375845418464_0006_01_000003 in state: COMPLETED event:FINISHED
2013-08-07 03:28:36,363 INFO org.apache.hadoop.yarn.server.resourcemanager.RMAuditLogger: USER=ubuntu	OPERATION=AM Released Container	TARGET=SchedulerApp	RESULT=SUCCESS	APPID=application_1375845418464_0006	CONTAINERID=container_1375845418464_0006_01_000003
2013-08-07 03:28:36,364 INFO org.apache.hadoop.yarn.server.resourcemanager.scheduler.common.fica.FiCaSchedulerNode: Released container container_1375845418464_0006_01_000003 of capacity <memory:1024, vCores:1> on host hadoop-200-5:34756, which currently has 6 containers, <memory:7168, vCores:6> used and <memory:1024, vCores:10> available, release resources=true
2013-08-07 03:28:36,364 INFO org.apache.hadoop.yarn.server.resourcemanager.scheduler.capacity.LeafQueue: default used=<memory:48128, vCores:42> numContainers=42 user=ubuntu user-resources=<memory:48128, vCores:42>
2013-08-07 03:28:36,365 INFO org.apache.hadoop.yarn.server.resourcemanager.scheduler.capacity.LeafQueue: completedContainer container=Container: [ContainerId: container_1375845418464_0006_01_000003, NodeId: hadoop-200-5:34756, NodeHttpAddress: hadoop-200-5:8042, Resource: <memory:1024, vCores:1>, Priority: 20, State: NEW, Token: null, Status: container_id {, app_attempt_id {, application_id {, id: 6, cluster_timestamp: 1375845418464, }, attemptId: 1, }, id: 3, }, state: C_COMPLETE, diagnostics: "Container killed by the ApplicationMaster.\n\n", exit_status: 143, ] resource=<memory:1024, vCores:1> queue=default: capacity=1.0, absoluteCapacity=1.0, usedResources=<memory:48128, vCores:42>usedCapacity=0.9791667, absoluteUsedCapacity=0.9791667, numApps=5, numContainers=42 usedCapacity=0.9791667 absoluteUsedCapacity=0.9791667 used=<memory:48128, vCores:42> cluster=<memory:49152, vCores:96>
2013-08-07 03:28:36,365 INFO org.apache.hadoop.yarn.server.resourcemanager.scheduler.capacity.ParentQueue: completedContainer queue=root usedCapacity=0.9791667 absoluteUsedCapacity=0.9791667 used=<memory:48128, vCores:42> cluster=<memory:49152, vCores:96>
2013-08-07 03:28:36,365 INFO org.apache.hadoop.yarn.server.resourcemanager.scheduler.capacity.CapacityScheduler: Application appattempt_1375845418464_0006_000001 released container container_1375845418464_0006_01_000003 on node: host: hadoop-200-5:34756 #containers=6 available=1024 used=7168 with event: FINISHED
2013-08-07 03:28:36,366 INFO org.apache.hadoop.yarn.server.resourcemanager.rmcontainer.RMContainerImpl: container_1375845418464_0007_01_000004 Container Transitioned from NEW to ALLOCATED
2013-08-07 03:28:36,366 INFO org.apache.hadoop.yarn.server.resourcemanager.RMAuditLogger: USER=ubuntu	OPERATION=AM Allocated Container	TARGET=SchedulerApp	RESULT=SUCCESS	APPID=application_1375845418464_0007	CONTAINERID=container_1375845418464_0007_01_000004
2013-08-07 03:28:36,366 INFO org.apache.hadoop.yarn.server.resourcemanager.scheduler.common.fica.FiCaSchedulerNode: Assigned container container_1375845418464_0007_01_000004 of capacity <memory:1024, vCores:1> on host hadoop-200-5:34756, which currently has 7 containers, <memory:8192, vCores:7> used and <memory:0, vCores:9> available
2013-08-07 03:28:36,367 INFO org.apache.hadoop.yarn.server.resourcemanager.scheduler.capacity.LeafQueue: assignedContainer application=application_1375845418464_0007 container=Container: [ContainerId: container_1375845418464_0007_01_000004, NodeId: hadoop-200-5:34756, NodeHttpAddress: hadoop-200-5:8042, Resource: <memory:1024, vCores:1>, Priority: 20, State: NEW, Token: null, Status: container_id {, app_attempt_id {, application_id {, id: 7, cluster_timestamp: 1375845418464, }, attemptId: 1, }, id: 4, }, state: C_NEW, ] containerId=container_1375845418464_0007_01_000004 queue=default: capacity=1.0, absoluteCapacity=1.0, usedResources=<memory:48128, vCores:42>usedCapacity=0.9791667, absoluteUsedCapacity=0.9791667, numApps=5, numContainers=42 usedCapacity=0.9791667 absoluteUsedCapacity=0.9791667 used=<memory:48128, vCores:42> cluster=<memory:49152, vCores:96>
2013-08-07 03:28:36,367 INFO org.apache.hadoop.yarn.server.resourcemanager.scheduler.capacity.ParentQueue: Re-sorting queues since queue: root.default stats: default: capacity=1.0, absoluteCapacity=1.0, usedResources=<memory:49152, vCores:43>usedCapacity=1.0, absoluteUsedCapacity=1.0, numApps=5, numContainers=43
2013-08-07 03:28:36,367 INFO org.apache.hadoop.yarn.server.resourcemanager.scheduler.capacity.ParentQueue: assignedContainer queue=root usedCapacity=1.0 absoluteUsedCapacity=1.0 used=<memory:49152, vCores:43> cluster=<memory:49152, vCores:96>
2013-08-07 03:28:37,069 INFO org.apache.hadoop.yarn.server.resourcemanager.rmcontainer.RMContainerImpl: container_1375845418464_0007_01_000003 Container Transitioned from ALLOCATED to ACQUIRED
2013-08-07 03:28:37,070 INFO org.apache.hadoop.yarn.server.resourcemanager.rmcontainer.RMContainerImpl: container_1375845418464_0007_01_000004 Container Transitioned from ALLOCATED to ACQUIRED
2013-08-07 03:28:37,370 INFO org.apache.hadoop.yarn.server.resourcemanager.rmcontainer.RMContainerImpl: container_1375845418464_0007_01_000002 Container Transitioned from ACQUIRED to RUNNING
2013-08-07 03:28:37,370 INFO org.apache.hadoop.yarn.server.resourcemanager.rmcontainer.RMContainerImpl: container_1375845418464_0007_01_000004 Container Transitioned from ACQUIRED to RUNNING
2013-08-07 03:28:38,065 INFO org.apache.hadoop.yarn.server.resourcemanager.rmcontainer.RMContainerImpl: container_1375845418464_0006_01_000022 Container Transitioned from RUNNING to COMPLETED
2013-08-07 03:28:38,065 INFO org.apache.hadoop.yarn.server.resourcemanager.scheduler.common.fica.FiCaSchedulerApp: Completed container: container_1375845418464_0006_01_000022 in state: COMPLETED event:FINISHED
2013-08-07 03:28:38,066 INFO org.apache.hadoop.yarn.server.resourcemanager.RMAuditLogger: USER=ubuntu	OPERATION=AM Released Container	TARGET=SchedulerApp	RESULT=SUCCESS	APPID=application_1375845418464_0006	CONTAINERID=container_1375845418464_0006_01_000022
2013-08-07 03:28:38,066 INFO org.apache.hadoop.yarn.server.resourcemanager.scheduler.common.fica.FiCaSchedulerNode: Released container container_1375845418464_0006_01_000022 of capacity <memory:1024, vCores:1> on host hadoop-200-3:52180, which currently has 6 containers, <memory:7168, vCores:6> used and <memory:1024, vCores:10> available, release resources=true
2013-08-07 03:28:38,066 INFO org.apache.hadoop.yarn.server.resourcemanager.scheduler.capacity.LeafQueue: default used=<memory:48128, vCores:42> numContainers=42 user=ubuntu user-resources=<memory:48128, vCores:42>
2013-08-07 03:28:38,067 INFO org.apache.hadoop.yarn.server.resourcemanager.scheduler.capacity.LeafQueue: completedContainer container=Container: [ContainerId: container_1375845418464_0006_01_000022, NodeId: hadoop-200-3:52180, NodeHttpAddress: hadoop-200-3:8042, Resource: <memory:1024, vCores:1>, Priority: 20, State: NEW, Token: null, Status: container_id {, app_attempt_id {, application_id {, id: 6, cluster_timestamp: 1375845418464, }, attemptId: 1, }, id: 22, }, state: C_COMPLETE, diagnostics: "Container killed by the ApplicationMaster.\n\n", exit_status: 143, ] resource=<memory:1024, vCores:1> queue=default: capacity=1.0, absoluteCapacity=1.0, usedResources=<memory:48128, vCores:42>usedCapacity=0.9791667, absoluteUsedCapacity=0.9791667, numApps=5, numContainers=42 usedCapacity=0.9791667 absoluteUsedCapacity=0.9791667 used=<memory:48128, vCores:42> cluster=<memory:49152, vCores:96>
2013-08-07 03:28:38,067 INFO org.apache.hadoop.yarn.server.resourcemanager.scheduler.capacity.ParentQueue: completedContainer queue=root usedCapacity=0.9791667 absoluteUsedCapacity=0.9791667 used=<memory:48128, vCores:42> cluster=<memory:49152, vCores:96>
2013-08-07 03:28:38,067 INFO org.apache.hadoop.yarn.server.resourcemanager.scheduler.capacity.CapacityScheduler: Application appattempt_1375845418464_0006_000001 released container container_1375845418464_0006_01_000022 on node: host: hadoop-200-3:52180 #containers=6 available=1024 used=7168 with event: FINISHED
2013-08-07 03:28:38,068 INFO org.apache.hadoop.yarn.server.resourcemanager.rmcontainer.RMContainerImpl: container_1375845418464_0006_01_000042 Container Transitioned from NEW to ALLOCATED
2013-08-07 03:28:38,068 INFO org.apache.hadoop.yarn.server.resourcemanager.RMAuditLogger: USER=ubuntu	OPERATION=AM Allocated Container	TARGET=SchedulerApp	RESULT=SUCCESS	APPID=application_1375845418464_0006	CONTAINERID=container_1375845418464_0006_01_000042
2013-08-07 03:28:38,068 INFO org.apache.hadoop.yarn.server.resourcemanager.scheduler.common.fica.FiCaSchedulerNode: Assigned container container_1375845418464_0006_01_000042 of capacity <memory:1024, vCores:1> on host hadoop-200-3:52180, which currently has 7 containers, <memory:8192, vCores:7> used and <memory:0, vCores:9> available
2013-08-07 03:28:38,069 INFO org.apache.hadoop.yarn.server.resourcemanager.scheduler.capacity.LeafQueue: assignedContainer application=application_1375845418464_0006 container=Container: [ContainerId: container_1375845418464_0006_01_000042, NodeId: hadoop-200-3:52180, NodeHttpAddress: hadoop-200-3:8042, Resource: <memory:1024, vCores:1>, Priority: 10, State: NEW, Token: null, Status: container_id {, app_attempt_id {, application_id {, id: 6, cluster_timestamp: 1375845418464, }, attemptId: 1, }, id: 42, }, state: C_NEW, ] containerId=container_1375845418464_0006_01_000042 queue=default: capacity=1.0, absoluteCapacity=1.0, usedResources=<memory:48128, vCores:42>usedCapacity=0.9791667, absoluteUsedCapacity=0.9791667, numApps=5, numContainers=42 usedCapacity=0.9791667 absoluteUsedCapacity=0.9791667 used=<memory:48128, vCores:42> cluster=<memory:49152, vCores:96>
2013-08-07 03:28:38,069 INFO org.apache.hadoop.yarn.server.resourcemanager.scheduler.capacity.ParentQueue: Re-sorting queues since queue: root.default stats: default: capacity=1.0, absoluteCapacity=1.0, usedResources=<memory:49152, vCores:43>usedCapacity=1.0, absoluteUsedCapacity=1.0, numApps=5, numContainers=43
2013-08-07 03:28:38,070 INFO org.apache.hadoop.yarn.server.resourcemanager.scheduler.capacity.ParentQueue: assignedContainer queue=root usedCapacity=1.0 absoluteUsedCapacity=1.0 used=<memory:49152, vCores:43> cluster=<memory:49152, vCores:96>
2013-08-07 03:28:38,158 INFO org.apache.hadoop.yarn.server.resourcemanager.rmcontainer.RMContainerImpl: container_1375845418464_0007_01_000003 Container Transitioned from ACQUIRED to RUNNING
2013-08-07 03:28:38,527 INFO org.apache.hadoop.yarn.server.resourcemanager.rmcontainer.RMContainerImpl: container_1375845418464_0006_01_000042 Container Transitioned from ALLOCATED to ACQUIRED
2013-08-07 03:28:38,607 INFO org.apache.hadoop.yarn.server.resourcemanager.rmcontainer.RMContainerImpl: container_1375845418464_0006_01_000035 Container Transitioned from RUNNING to COMPLETED
2013-08-07 03:28:38,607 INFO org.apache.hadoop.yarn.server.resourcemanager.scheduler.common.fica.FiCaSchedulerApp: Completed container: container_1375845418464_0006_01_000035 in state: COMPLETED event:FINISHED
2013-08-07 03:28:38,607 INFO org.apache.hadoop.yarn.server.resourcemanager.RMAuditLogger: USER=ubuntu	OPERATION=AM Released Container	TARGET=SchedulerApp	RESULT=SUCCESS	APPID=application_1375845418464_0006	CONTAINERID=container_1375845418464_0006_01_000035
2013-08-07 03:28:38,607 INFO org.apache.hadoop.yarn.server.resourcemanager.scheduler.common.fica.FiCaSchedulerNode: Released container container_1375845418464_0006_01_000035 of capacity <memory:1024, vCores:1> on host hadoop-200-7:47421, which currently has 6 containers, <memory:7168, vCores:6> used and <memory:1024, vCores:10> available, release resources=true
2013-08-07 03:28:38,608 INFO org.apache.hadoop.yarn.server.resourcemanager.scheduler.capacity.LeafQueue: default used=<memory:48128, vCores:42> numContainers=42 user=ubuntu user-resources=<memory:48128, vCores:42>
2013-08-07 03:28:38,609 INFO org.apache.hadoop.yarn.server.resourcemanager.scheduler.capacity.LeafQueue: completedContainer container=Container: [ContainerId: container_1375845418464_0006_01_000035, NodeId: hadoop-200-7:47421, NodeHttpAddress: hadoop-200-7:8042, Resource: <memory:1024, vCores:1>, Priority: 20, State: NEW, Token: null, Status: container_id {, app_attempt_id {, application_id {, id: 6, cluster_timestamp: 1375845418464, }, attemptId: 1, }, id: 35, }, state: C_COMPLETE, diagnostics: "Container killed by the ApplicationMaster.\n\n", exit_status: 143, ] resource=<memory:1024, vCores:1> queue=default: capacity=1.0, absoluteCapacity=1.0, usedResources=<memory:48128, vCores:42>usedCapacity=0.9791667, absoluteUsedCapacity=0.9791667, numApps=5, numContainers=42 usedCapacity=0.9791667 absoluteUsedCapacity=0.9791667 used=<memory:48128, vCores:42> cluster=<memory:49152, vCores:96>
2013-08-07 03:28:38,609 INFO org.apache.hadoop.yarn.server.resourcemanager.scheduler.capacity.ParentQueue: completedContainer queue=root usedCapacity=0.9791667 absoluteUsedCapacity=0.9791667 used=<memory:48128, vCores:42> cluster=<memory:49152, vCores:96>
2013-08-07 03:28:38,609 INFO org.apache.hadoop.yarn.server.resourcemanager.scheduler.capacity.CapacityScheduler: Application appattempt_1375845418464_0006_000001 released container container_1375845418464_0006_01_000035 on node: host: hadoop-200-7:47421 #containers=6 available=1024 used=7168 with event: FINISHED
2013-08-07 03:28:38,609 INFO org.apache.hadoop.yarn.server.resourcemanager.rmcontainer.RMContainerImpl: container_1375845418464_0006_01_000037 Container Transitioned from RUNNING to COMPLETED
2013-08-07 03:28:38,609 INFO org.apache.hadoop.yarn.server.resourcemanager.scheduler.common.fica.FiCaSchedulerApp: Completed container: container_1375845418464_0006_01_000037 in state: COMPLETED event:FINISHED
2013-08-07 03:28:38,610 INFO org.apache.hadoop.yarn.server.resourcemanager.RMAuditLogger: USER=ubuntu	OPERATION=AM Released Container	TARGET=SchedulerApp	RESULT=SUCCESS	APPID=application_1375845418464_0006	CONTAINERID=container_1375845418464_0006_01_000037
2013-08-07 03:28:38,610 INFO org.apache.hadoop.yarn.server.resourcemanager.scheduler.common.fica.FiCaSchedulerNode: Released container container_1375845418464_0006_01_000037 of capacity <memory:1024, vCores:1> on host hadoop-200-7:47421, which currently has 5 containers, <memory:6144, vCores:5> used and <memory:2048, vCores:11> available, release resources=true
2013-08-07 03:28:38,610 INFO org.apache.hadoop.yarn.server.resourcemanager.scheduler.capacity.LeafQueue: default used=<memory:47104, vCores:41> numContainers=41 user=ubuntu user-resources=<memory:47104, vCores:41>
2013-08-07 03:28:38,611 INFO org.apache.hadoop.yarn.server.resourcemanager.scheduler.capacity.LeafQueue: completedContainer container=Container: [ContainerId: container_1375845418464_0006_01_000037, NodeId: hadoop-200-7:47421, NodeHttpAddress: hadoop-200-7:8042, Resource: <memory:1024, vCores:1>, Priority: 20, State: NEW, Token: null, Status: container_id {, app_attempt_id {, application_id {, id: 6, cluster_timestamp: 1375845418464, }, attemptId: 1, }, id: 37, }, state: C_COMPLETE, diagnostics: "Container killed by the ApplicationMaster.\n\n", exit_status: 143, ] resource=<memory:1024, vCores:1> queue=default: capacity=1.0, absoluteCapacity=1.0, usedResources=<memory:47104, vCores:41>usedCapacity=0.9583333, absoluteUsedCapacity=0.9583333, numApps=5, numContainers=41 usedCapacity=0.9583333 absoluteUsedCapacity=0.9583333 used=<memory:47104, vCores:41> cluster=<memory:49152, vCores:96>
2013-08-07 03:28:38,611 INFO org.apache.hadoop.yarn.server.resourcemanager.scheduler.capacity.ParentQueue: completedContainer queue=root usedCapacity=0.9583333 absoluteUsedCapacity=0.9583333 used=<memory:47104, vCores:41> cluster=<memory:49152, vCores:96>
2013-08-07 03:28:38,611 INFO org.apache.hadoop.yarn.server.resourcemanager.scheduler.capacity.CapacityScheduler: Application appattempt_1375845418464_0006_000001 released container container_1375845418464_0006_01_000037 on node: host: hadoop-200-7:47421 #containers=5 available=2048 used=6144 with event: FINISHED
2013-08-07 03:28:38,612 INFO org.apache.hadoop.yarn.server.resourcemanager.rmcontainer.RMContainerImpl: container_1375845418464_0006_01_000043 Container Transitioned from NEW to ALLOCATED
2013-08-07 03:28:38,612 INFO org.apache.hadoop.yarn.server.resourcemanager.RMAuditLogger: USER=ubuntu	OPERATION=AM Allocated Container	TARGET=SchedulerApp	RESULT=SUCCESS	APPID=application_1375845418464_0006	CONTAINERID=container_1375845418464_0006_01_000043
2013-08-07 03:28:38,612 INFO org.apache.hadoop.yarn.server.resourcemanager.scheduler.common.fica.FiCaSchedulerNode: Assigned container container_1375845418464_0006_01_000043 of capacity <memory:1024, vCores:1> on host hadoop-200-7:47421, which currently has 6 containers, <memory:7168, vCores:6> used and <memory:1024, vCores:10> available
2013-08-07 03:28:38,613 INFO org.apache.hadoop.yarn.server.resourcemanager.scheduler.capacity.LeafQueue: assignedContainer application=application_1375845418464_0006 container=Container: [ContainerId: container_1375845418464_0006_01_000043, NodeId: hadoop-200-7:47421, NodeHttpAddress: hadoop-200-7:8042, Resource: <memory:1024, vCores:1>, Priority: 10, State: NEW, Token: null, Status: container_id {, app_attempt_id {, application_id {, id: 6, cluster_timestamp: 1375845418464, }, attemptId: 1, }, id: 43, }, state: C_NEW, ] containerId=container_1375845418464_0006_01_000043 queue=default: capacity=1.0, absoluteCapacity=1.0, usedResources=<memory:47104, vCores:41>usedCapacity=0.9583333, absoluteUsedCapacity=0.9583333, numApps=5, numContainers=41 usedCapacity=0.9583333 absoluteUsedCapacity=0.9583333 used=<memory:47104, vCores:41> cluster=<memory:49152, vCores:96>
2013-08-07 03:28:38,613 INFO org.apache.hadoop.yarn.server.resourcemanager.scheduler.capacity.ParentQueue: Re-sorting queues since queue: root.default stats: default: capacity=1.0, absoluteCapacity=1.0, usedResources=<memory:48128, vCores:42>usedCapacity=0.9791667, absoluteUsedCapacity=0.9791667, numApps=5, numContainers=42
2013-08-07 03:28:38,613 INFO org.apache.hadoop.yarn.server.resourcemanager.scheduler.capacity.ParentQueue: assignedContainer queue=root usedCapacity=0.9791667 absoluteUsedCapacity=0.9791667 used=<memory:48128, vCores:42> cluster=<memory:49152, vCores:96>
2013-08-07 03:28:38,751 INFO org.apache.hadoop.yarn.server.resourcemanager.rmcontainer.RMContainerImpl: container_1375845418464_0006_01_000042 Container Transitioned from ACQUIRED to RUNNING
2013-08-07 03:28:38,752 INFO org.apache.hadoop.yarn.server.resourcemanager.rmcontainer.RMContainerImpl: container_1375845418464_0006_01_000025 Container Transitioned from RUNNING to COMPLETED
2013-08-07 03:28:38,752 INFO org.apache.hadoop.yarn.server.resourcemanager.scheduler.common.fica.FiCaSchedulerApp: Completed container: container_1375845418464_0006_01_000025 in state: COMPLETED event:FINISHED
2013-08-07 03:28:38,752 INFO org.apache.hadoop.yarn.server.resourcemanager.RMAuditLogger: USER=ubuntu	OPERATION=AM Released Container	TARGET=SchedulerApp	RESULT=SUCCESS	APPID=application_1375845418464_0006	CONTAINERID=container_1375845418464_0006_01_000025
2013-08-07 03:28:38,752 INFO org.apache.hadoop.yarn.server.resourcemanager.scheduler.common.fica.FiCaSchedulerNode: Released container container_1375845418464_0006_01_000025 of capacity <memory:1024, vCores:1> on host hadoop-200-3:52180, which currently has 6 containers, <memory:7168, vCores:6> used and <memory:1024, vCores:10> available, release resources=true
2013-08-07 03:28:38,752 INFO org.apache.hadoop.yarn.server.resourcemanager.scheduler.capacity.LeafQueue: default used=<memory:47104, vCores:41> numContainers=41 user=ubuntu user-resources=<memory:47104, vCores:41>
2013-08-07 03:28:38,753 INFO org.apache.hadoop.yarn.server.resourcemanager.scheduler.capacity.LeafQueue: completedContainer container=Container: [ContainerId: container_1375845418464_0006_01_000025, NodeId: hadoop-200-3:52180, NodeHttpAddress: hadoop-200-3:8042, Resource: <memory:1024, vCores:1>, Priority: 20, State: NEW, Token: null, Status: container_id {, app_attempt_id {, application_id {, id: 6, cluster_timestamp: 1375845418464, }, attemptId: 1, }, id: 25, }, state: C_COMPLETE, diagnostics: "Container killed by the ApplicationMaster.\n\n", exit_status: 143, ] resource=<memory:1024, vCores:1> queue=default: capacity=1.0, absoluteCapacity=1.0, usedResources=<memory:47104, vCores:41>usedCapacity=0.9583333, absoluteUsedCapacity=0.9583333, numApps=5, numContainers=41 usedCapacity=0.9583333 absoluteUsedCapacity=0.9583333 used=<memory:47104, vCores:41> cluster=<memory:49152, vCores:96>
2013-08-07 03:28:38,754 INFO org.apache.hadoop.yarn.server.resourcemanager.scheduler.capacity.ParentQueue: completedContainer queue=root usedCapacity=0.9583333 absoluteUsedCapacity=0.9583333 used=<memory:47104, vCores:41> cluster=<memory:49152, vCores:96>
2013-08-07 03:28:38,754 INFO org.apache.hadoop.yarn.server.resourcemanager.scheduler.capacity.CapacityScheduler: Application appattempt_1375845418464_0006_000001 released container container_1375845418464_0006_01_000025 on node: host: hadoop-200-3:52180 #containers=6 available=1024 used=7168 with event: FINISHED
2013-08-07 03:28:38,754 INFO org.apache.hadoop.yarn.server.resourcemanager.rmcontainer.RMContainerImpl: container_1375845418464_0006_01_000044 Container Transitioned from NEW to ALLOCATED
2013-08-07 03:28:38,754 INFO org.apache.hadoop.yarn.server.resourcemanager.RMAuditLogger: USER=ubuntu	OPERATION=AM Allocated Container	TARGET=SchedulerApp	RESULT=SUCCESS	APPID=application_1375845418464_0006	CONTAINERID=container_1375845418464_0006_01_000044
2013-08-07 03:28:38,754 INFO org.apache.hadoop.yarn.server.resourcemanager.scheduler.common.fica.FiCaSchedulerNode: Assigned container container_1375845418464_0006_01_000044 of capacity <memory:1024, vCores:1> on host hadoop-200-3:52180, which currently has 7 containers, <memory:8192, vCores:7> used and <memory:0, vCores:9> available
2013-08-07 03:28:38,755 INFO org.apache.hadoop.yarn.server.resourcemanager.scheduler.capacity.LeafQueue: assignedContainer application=application_1375845418464_0006 container=Container: [ContainerId: container_1375845418464_0006_01_000044, NodeId: hadoop-200-3:52180, NodeHttpAddress: hadoop-200-3:8042, Resource: <memory:1024, vCores:1>, Priority: 10, State: NEW, Token: null, Status: container_id {, app_attempt_id {, application_id {, id: 6, cluster_timestamp: 1375845418464, }, attemptId: 1, }, id: 44, }, state: C_NEW, ] containerId=container_1375845418464_0006_01_000044 queue=default: capacity=1.0, absoluteCapacity=1.0, usedResources=<memory:47104, vCores:41>usedCapacity=0.9583333, absoluteUsedCapacity=0.9583333, numApps=5, numContainers=41 usedCapacity=0.9583333 absoluteUsedCapacity=0.9583333 used=<memory:47104, vCores:41> cluster=<memory:49152, vCores:96>
2013-08-07 03:28:38,756 INFO org.apache.hadoop.yarn.server.resourcemanager.scheduler.capacity.ParentQueue: Re-sorting queues since queue: root.default stats: default: capacity=1.0, absoluteCapacity=1.0, usedResources=<memory:48128, vCores:42>usedCapacity=0.9791667, absoluteUsedCapacity=0.9791667, numApps=5, numContainers=42
2013-08-07 03:28:38,756 INFO org.apache.hadoop.yarn.server.resourcemanager.scheduler.capacity.ParentQueue: assignedContainer queue=root usedCapacity=0.9791667 absoluteUsedCapacity=0.9791667 used=<memory:48128, vCores:42> cluster=<memory:49152, vCores:96>
2013-08-07 03:28:39,207 INFO org.apache.hadoop.yarn.server.resourcemanager.rmcontainer.RMContainerImpl: container_1375845418464_0006_01_000023 Container Transitioned from RUNNING to COMPLETED
2013-08-07 03:28:39,207 INFO org.apache.hadoop.yarn.server.resourcemanager.scheduler.common.fica.FiCaSchedulerApp: Completed container: container_1375845418464_0006_01_000023 in state: COMPLETED event:FINISHED
2013-08-07 03:28:39,207 INFO org.apache.hadoop.yarn.server.resourcemanager.RMAuditLogger: USER=ubuntu	OPERATION=AM Released Container	TARGET=SchedulerApp	RESULT=SUCCESS	APPID=application_1375845418464_0006	CONTAINERID=container_1375845418464_0006_01_000023
2013-08-07 03:28:39,208 INFO org.apache.hadoop.yarn.server.resourcemanager.scheduler.common.fica.FiCaSchedulerNode: Released container container_1375845418464_0006_01_000023 of capacity <memory:1024, vCores:1> on host hadoop-200-3:52180, which currently has 6 containers, <memory:7168, vCores:6> used and <memory:1024, vCores:10> available, release resources=true
2013-08-07 03:28:39,208 INFO org.apache.hadoop.yarn.server.resourcemanager.scheduler.capacity.LeafQueue: default used=<memory:47104, vCores:41> numContainers=41 user=ubuntu user-resources=<memory:47104, vCores:41>
2013-08-07 03:28:39,209 INFO org.apache.hadoop.yarn.server.resourcemanager.scheduler.capacity.LeafQueue: completedContainer container=Container: [ContainerId: container_1375845418464_0006_01_000023, NodeId: hadoop-200-3:52180, NodeHttpAddress: hadoop-200-3:8042, Resource: <memory:1024, vCores:1>, Priority: 20, State: NEW, Token: null, Status: container_id {, app_attempt_id {, application_id {, id: 6, cluster_timestamp: 1375845418464, }, attemptId: 1, }, id: 23, }, state: C_COMPLETE, diagnostics: "Container killed by the ApplicationMaster.\n\n", exit_status: 143, ] resource=<memory:1024, vCores:1> queue=default: capacity=1.0, absoluteCapacity=1.0, usedResources=<memory:47104, vCores:41>usedCapacity=0.9583333, absoluteUsedCapacity=0.9583333, numApps=5, numContainers=41 usedCapacity=0.9583333 absoluteUsedCapacity=0.9583333 used=<memory:47104, vCores:41> cluster=<memory:49152, vCores:96>
2013-08-07 03:28:39,209 INFO org.apache.hadoop.yarn.server.resourcemanager.scheduler.capacity.ParentQueue: completedContainer queue=root usedCapacity=0.9583333 absoluteUsedCapacity=0.9583333 used=<memory:47104, vCores:41> cluster=<memory:49152, vCores:96>
2013-08-07 03:28:39,209 INFO org.apache.hadoop.yarn.server.resourcemanager.scheduler.capacity.CapacityScheduler: Application appattempt_1375845418464_0006_000001 released container container_1375845418464_0006_01_000023 on node: host: hadoop-200-3:52180 #containers=6 available=1024 used=7168 with event: FINISHED
2013-08-07 03:28:39,210 INFO org.apache.hadoop.yarn.server.resourcemanager.rmcontainer.RMContainerImpl: container_1375845418464_0006_01_000045 Container Transitioned from NEW to ALLOCATED
2013-08-07 03:28:39,210 INFO org.apache.hadoop.yarn.server.resourcemanager.RMAuditLogger: USER=ubuntu	OPERATION=AM Allocated Container	TARGET=SchedulerApp	RESULT=SUCCESS	APPID=application_1375845418464_0006	CONTAINERID=container_1375845418464_0006_01_000045
2013-08-07 03:28:39,210 INFO org.apache.hadoop.yarn.server.resourcemanager.scheduler.common.fica.FiCaSchedulerNode: Assigned container container_1375845418464_0006_01_000045 of capacity <memory:1024, vCores:1> on host hadoop-200-3:52180, which currently has 7 containers, <memory:8192, vCores:7> used and <memory:0, vCores:9> available
2013-08-07 03:28:39,211 INFO org.apache.hadoop.yarn.server.resourcemanager.scheduler.capacity.LeafQueue: assignedContainer application=application_1375845418464_0006 container=Container: [ContainerId: container_1375845418464_0006_01_000045, NodeId: hadoop-200-3:52180, NodeHttpAddress: hadoop-200-3:8042, Resource: <memory:1024, vCores:1>, Priority: 10, State: NEW, Token: null, Status: container_id {, app_attempt_id {, application_id {, id: 6, cluster_timestamp: 1375845418464, }, attemptId: 1, }, id: 45, }, state: C_NEW, ] containerId=container_1375845418464_0006_01_000045 queue=default: capacity=1.0, absoluteCapacity=1.0, usedResources=<memory:47104, vCores:41>usedCapacity=0.9583333, absoluteUsedCapacity=0.9583333, numApps=5, numContainers=41 usedCapacity=0.9583333 absoluteUsedCapacity=0.9583333 used=<memory:47104, vCores:41> cluster=<memory:49152, vCores:96>
2013-08-07 03:28:39,211 INFO org.apache.hadoop.yarn.server.resourcemanager.scheduler.capacity.ParentQueue: Re-sorting queues since queue: root.default stats: default: capacity=1.0, absoluteCapacity=1.0, usedResources=<memory:48128, vCores:42>usedCapacity=0.9791667, absoluteUsedCapacity=0.9791667, numApps=5, numContainers=42
2013-08-07 03:28:39,211 INFO org.apache.hadoop.yarn.server.resourcemanager.scheduler.capacity.ParentQueue: assignedContainer queue=root usedCapacity=0.9791667 absoluteUsedCapacity=0.9791667 used=<memory:48128, vCores:42> cluster=<memory:49152, vCores:96>
2013-08-07 03:28:39,536 INFO org.apache.hadoop.yarn.server.resourcemanager.rmcontainer.RMContainerImpl: container_1375845418464_0006_01_000043 Container Transitioned from ALLOCATED to ACQUIRED
2013-08-07 03:28:39,537 INFO org.apache.hadoop.yarn.server.resourcemanager.rmcontainer.RMContainerImpl: container_1375845418464_0006_01_000044 Container Transitioned from ALLOCATED to ACQUIRED
2013-08-07 03:28:39,537 INFO org.apache.hadoop.yarn.server.resourcemanager.rmcontainer.RMContainerImpl: container_1375845418464_0006_01_000045 Container Transitioned from ALLOCATED to ACQUIRED
2013-08-07 03:28:39,654 INFO org.apache.hadoop.yarn.server.resourcemanager.rmcontainer.RMContainerImpl: container_1375845418464_0006_01_000046 Container Transitioned from NEW to ALLOCATED
2013-08-07 03:28:39,654 INFO org.apache.hadoop.yarn.server.resourcemanager.RMAuditLogger: USER=ubuntu	OPERATION=AM Allocated Container	TARGET=SchedulerApp	RESULT=SUCCESS	APPID=application_1375845418464_0006	CONTAINERID=container_1375845418464_0006_01_000046
2013-08-07 03:28:39,654 INFO org.apache.hadoop.yarn.server.resourcemanager.scheduler.common.fica.FiCaSchedulerNode: Assigned container container_1375845418464_0006_01_000046 of capacity <memory:1024, vCores:1> on host hadoop-200-7:47421, which currently has 7 containers, <memory:8192, vCores:7> used and <memory:0, vCores:9> available
2013-08-07 03:28:39,655 INFO org.apache.hadoop.yarn.server.resourcemanager.scheduler.capacity.LeafQueue: assignedContainer application=application_1375845418464_0006 container=Container: [ContainerId: container_1375845418464_0006_01_000046, NodeId: hadoop-200-7:47421, NodeHttpAddress: hadoop-200-7:8042, Resource: <memory:1024, vCores:1>, Priority: 10, State: NEW, Token: null, Status: container_id {, app_attempt_id {, application_id {, id: 6, cluster_timestamp: 1375845418464, }, attemptId: 1, }, id: 46, }, state: C_NEW, ] containerId=container_1375845418464_0006_01_000046 queue=default: capacity=1.0, absoluteCapacity=1.0, usedResources=<memory:48128, vCores:42>usedCapacity=0.9791667, absoluteUsedCapacity=0.9791667, numApps=5, numContainers=42 usedCapacity=0.9791667 absoluteUsedCapacity=0.9791667 used=<memory:48128, vCores:42> cluster=<memory:49152, vCores:96>
2013-08-07 03:28:39,655 INFO org.apache.hadoop.yarn.server.resourcemanager.scheduler.capacity.ParentQueue: Re-sorting queues since queue: root.default stats: default: capacity=1.0, absoluteCapacity=1.0, usedResources=<memory:49152, vCores:43>usedCapacity=1.0, absoluteUsedCapacity=1.0, numApps=5, numContainers=43
2013-08-07 03:28:39,655 INFO org.apache.hadoop.yarn.server.resourcemanager.scheduler.capacity.ParentQueue: assignedContainer queue=root usedCapacity=1.0 absoluteUsedCapacity=1.0 used=<memory:49152, vCores:43> cluster=<memory:49152, vCores:96>
2013-08-07 03:28:40,236 INFO org.apache.hadoop.yarn.server.resourcemanager.rmcontainer.RMContainerImpl: container_1375845418464_0006_01_000044 Container Transitioned from ACQUIRED to RUNNING
2013-08-07 03:28:40,236 INFO org.apache.hadoop.yarn.server.resourcemanager.rmcontainer.RMContainerImpl: container_1375845418464_0006_01_000045 Container Transitioned from ACQUIRED to RUNNING
2013-08-07 03:28:40,236 INFO org.apache.hadoop.yarn.server.resourcemanager.rmcontainer.RMContainerImpl: container_1375845418464_0006_01_000024 Container Transitioned from RUNNING to COMPLETED
2013-08-07 03:28:40,236 INFO org.apache.hadoop.yarn.server.resourcemanager.scheduler.common.fica.FiCaSchedulerApp: Completed container: container_1375845418464_0006_01_000024 in state: COMPLETED event:FINISHED
2013-08-07 03:28:40,237 INFO org.apache.hadoop.yarn.server.resourcemanager.RMAuditLogger: USER=ubuntu	OPERATION=AM Released Container	TARGET=SchedulerApp	RESULT=SUCCESS	APPID=application_1375845418464_0006	CONTAINERID=container_1375845418464_0006_01_000024
2013-08-07 03:28:40,237 INFO org.apache.hadoop.yarn.server.resourcemanager.scheduler.common.fica.FiCaSchedulerNode: Released container container_1375845418464_0006_01_000024 of capacity <memory:1024, vCores:1> on host hadoop-200-3:52180, which currently has 6 containers, <memory:7168, vCores:6> used and <memory:1024, vCores:10> available, release resources=true
2013-08-07 03:28:40,237 INFO org.apache.hadoop.yarn.server.resourcemanager.scheduler.capacity.LeafQueue: default used=<memory:48128, vCores:42> numContainers=42 user=ubuntu user-resources=<memory:48128, vCores:42>
2013-08-07 03:28:40,238 INFO org.apache.hadoop.yarn.server.resourcemanager.scheduler.capacity.LeafQueue: completedContainer container=Container: [ContainerId: container_1375845418464_0006_01_000024, NodeId: hadoop-200-3:52180, NodeHttpAddress: hadoop-200-3:8042, Resource: <memory:1024, vCores:1>, Priority: 20, State: NEW, Token: null, Status: container_id {, app_attempt_id {, application_id {, id: 6, cluster_timestamp: 1375845418464, }, attemptId: 1, }, id: 24, }, state: C_COMPLETE, diagnostics: "Container killed by the ApplicationMaster.\n", exit_status: 0, ] resource=<memory:1024, vCores:1> queue=default: capacity=1.0, absoluteCapacity=1.0, usedResources=<memory:48128, vCores:42>usedCapacity=0.9791667, absoluteUsedCapacity=0.9791667, numApps=5, numContainers=42 usedCapacity=0.9791667 absoluteUsedCapacity=0.9791667 used=<memory:48128, vCores:42> cluster=<memory:49152, vCores:96>
2013-08-07 03:28:40,238 INFO org.apache.hadoop.yarn.server.resourcemanager.scheduler.capacity.ParentQueue: completedContainer queue=root usedCapacity=0.9791667 absoluteUsedCapacity=0.9791667 used=<memory:48128, vCores:42> cluster=<memory:49152, vCores:96>
2013-08-07 03:28:40,238 INFO org.apache.hadoop.yarn.server.resourcemanager.scheduler.capacity.CapacityScheduler: Application appattempt_1375845418464_0006_000001 released container container_1375845418464_0006_01_000024 on node: host: hadoop-200-3:52180 #containers=6 available=1024 used=7168 with event: FINISHED
2013-08-07 03:28:40,239 INFO org.apache.hadoop.yarn.server.resourcemanager.rmcontainer.RMContainerImpl: container_1375845418464_0006_01_000047 Container Transitioned from NEW to ALLOCATED
2013-08-07 03:28:40,239 INFO org.apache.hadoop.yarn.server.resourcemanager.RMAuditLogger: USER=ubuntu	OPERATION=AM Allocated Container	TARGET=SchedulerApp	RESULT=SUCCESS	APPID=application_1375845418464_0006	CONTAINERID=container_1375845418464_0006_01_000047
2013-08-07 03:28:40,239 INFO org.apache.hadoop.yarn.server.resourcemanager.scheduler.common.fica.FiCaSchedulerNode: Assigned container container_1375845418464_0006_01_000047 of capacity <memory:1024, vCores:1> on host hadoop-200-3:52180, which currently has 7 containers, <memory:8192, vCores:7> used and <memory:0, vCores:9> available
2013-08-07 03:28:40,240 INFO org.apache.hadoop.yarn.server.resourcemanager.scheduler.capacity.LeafQueue: assignedContainer application=application_1375845418464_0006 container=Container: [ContainerId: container_1375845418464_0006_01_000047, NodeId: hadoop-200-3:52180, NodeHttpAddress: hadoop-200-3:8042, Resource: <memory:1024, vCores:1>, Priority: 10, State: NEW, Token: null, Status: container_id {, app_attempt_id {, application_id {, id: 6, cluster_timestamp: 1375845418464, }, attemptId: 1, }, id: 47, }, state: C_NEW, ] containerId=container_1375845418464_0006_01_000047 queue=default: capacity=1.0, absoluteCapacity=1.0, usedResources=<memory:48128, vCores:42>usedCapacity=0.9791667, absoluteUsedCapacity=0.9791667, numApps=5, numContainers=42 usedCapacity=0.9791667 absoluteUsedCapacity=0.9791667 used=<memory:48128, vCores:42> cluster=<memory:49152, vCores:96>
2013-08-07 03:28:40,240 INFO org.apache.hadoop.yarn.server.resourcemanager.scheduler.capacity.ParentQueue: Re-sorting queues since queue: root.default stats: default: capacity=1.0, absoluteCapacity=1.0, usedResources=<memory:49152, vCores:43>usedCapacity=1.0, absoluteUsedCapacity=1.0, numApps=5, numContainers=43
2013-08-07 03:28:40,240 INFO org.apache.hadoop.yarn.server.resourcemanager.scheduler.capacity.ParentQueue: assignedContainer queue=root usedCapacity=1.0 absoluteUsedCapacity=1.0 used=<memory:49152, vCores:43> cluster=<memory:49152, vCores:96>
2013-08-07 03:28:40,556 INFO org.apache.hadoop.yarn.server.resourcemanager.rmcontainer.RMContainerImpl: container_1375845418464_0006_01_000046 Container Transitioned from ALLOCATED to ACQUIRED
2013-08-07 03:28:40,557 INFO org.apache.hadoop.yarn.server.resourcemanager.rmcontainer.RMContainerImpl: container_1375845418464_0006_01_000047 Container Transitioned from ALLOCATED to ACQUIRED
2013-08-07 03:28:40,707 INFO org.apache.hadoop.yarn.server.resourcemanager.rmcontainer.RMContainerImpl: container_1375845418464_0006_01_000043 Container Transitioned from ACQUIRED to RUNNING
2013-08-07 03:28:41,259 INFO org.apache.hadoop.yarn.server.resourcemanager.rmcontainer.RMContainerImpl: container_1375845418464_0006_01_000047 Container Transitioned from ACQUIRED to RUNNING
2013-08-07 03:28:41,563 INFO org.apache.hadoop.yarn.server.resourcemanager.scheduler.AppSchedulingInfo: checking for deactivate... 
2013-08-07 03:28:41,563 INFO org.apache.hadoop.yarn.server.resourcemanager.scheduler.AppSchedulingInfo: checking for deactivate... 
2013-08-07 03:28:41,778 INFO org.apache.hadoop.yarn.server.resourcemanager.rmcontainer.RMContainerImpl: container_1375845418464_0006_01_000046 Container Transitioned from ACQUIRED to RUNNING
2013-08-07 03:28:41,901 INFO org.apache.hadoop.yarn.server.resourcemanager.rmcontainer.RMContainerImpl: container_1375845418464_0006_01_000014 Container Transitioned from RUNNING to COMPLETED
2013-08-07 03:28:41,902 INFO org.apache.hadoop.yarn.server.resourcemanager.scheduler.common.fica.FiCaSchedulerApp: Completed container: container_1375845418464_0006_01_000014 in state: COMPLETED event:FINISHED
2013-08-07 03:28:41,902 INFO org.apache.hadoop.yarn.server.resourcemanager.RMAuditLogger: USER=ubuntu	OPERATION=AM Released Container	TARGET=SchedulerApp	RESULT=SUCCESS	APPID=application_1375845418464_0006	CONTAINERID=container_1375845418464_0006_01_000014
2013-08-07 03:28:41,902 INFO org.apache.hadoop.yarn.server.resourcemanager.scheduler.common.fica.FiCaSchedulerNode: Released container container_1375845418464_0006_01_000014 of capacity <memory:1024, vCores:1> on host hadoop-200-6:45851, which currently has 6 containers, <memory:7168, vCores:6> used and <memory:1024, vCores:10> available, release resources=true
2013-08-07 03:28:41,902 INFO org.apache.hadoop.yarn.server.resourcemanager.scheduler.capacity.LeafQueue: default used=<memory:48128, vCores:42> numContainers=42 user=ubuntu user-resources=<memory:48128, vCores:42>
2013-08-07 03:28:41,903 INFO org.apache.hadoop.yarn.server.resourcemanager.scheduler.capacity.LeafQueue: completedContainer container=Container: [ContainerId: container_1375845418464_0006_01_000014, NodeId: hadoop-200-6:45851, NodeHttpAddress: hadoop-200-6:8042, Resource: <memory:1024, vCores:1>, Priority: 20, State: NEW, Token: null, Status: container_id {, app_attempt_id {, application_id {, id: 6, cluster_timestamp: 1375845418464, }, attemptId: 1, }, id: 14, }, state: C_COMPLETE, diagnostics: "Container killed by the ApplicationMaster.\n\n", exit_status: 143, ] resource=<memory:1024, vCores:1> queue=default: capacity=1.0, absoluteCapacity=1.0, usedResources=<memory:48128, vCores:42>usedCapacity=0.9791667, absoluteUsedCapacity=0.9791667, numApps=5, numContainers=42 usedCapacity=0.9791667 absoluteUsedCapacity=0.9791667 used=<memory:48128, vCores:42> cluster=<memory:49152, vCores:96>
2013-08-07 03:28:41,903 INFO org.apache.hadoop.yarn.server.resourcemanager.scheduler.capacity.ParentQueue: completedContainer queue=root usedCapacity=0.9791667 absoluteUsedCapacity=0.9791667 used=<memory:48128, vCores:42> cluster=<memory:49152, vCores:96>
2013-08-07 03:28:41,904 INFO org.apache.hadoop.yarn.server.resourcemanager.scheduler.capacity.CapacityScheduler: Application appattempt_1375845418464_0006_000001 released container container_1375845418464_0006_01_000014 on node: host: hadoop-200-6:45851 #containers=6 available=1024 used=7168 with event: FINISHED
2013-08-07 03:28:41,904 INFO org.apache.hadoop.yarn.server.resourcemanager.rmcontainer.RMContainerImpl: container_1375845418464_0007_01_000005 Container Transitioned from NEW to ALLOCATED
2013-08-07 03:28:41,904 INFO org.apache.hadoop.yarn.server.resourcemanager.RMAuditLogger: USER=ubuntu	OPERATION=AM Allocated Container	TARGET=SchedulerApp	RESULT=SUCCESS	APPID=application_1375845418464_0007	CONTAINERID=container_1375845418464_0007_01_000005
2013-08-07 03:28:41,904 INFO org.apache.hadoop.yarn.server.resourcemanager.scheduler.common.fica.FiCaSchedulerNode: Assigned container container_1375845418464_0007_01_000005 of capacity <memory:1024, vCores:1> on host hadoop-200-6:45851, which currently has 7 containers, <memory:8192, vCores:7> used and <memory:0, vCores:9> available
2013-08-07 03:28:41,905 INFO org.apache.hadoop.yarn.server.resourcemanager.scheduler.capacity.LeafQueue: assignedContainer application=application_1375845418464_0007 container=Container: [ContainerId: container_1375845418464_0007_01_000005, NodeId: hadoop-200-6:45851, NodeHttpAddress: hadoop-200-6:8042, Resource: <memory:1024, vCores:1>, Priority: 20, State: NEW, Token: null, Status: container_id {, app_attempt_id {, application_id {, id: 7, cluster_timestamp: 1375845418464, }, attemptId: 1, }, id: 5, }, state: C_NEW, ] containerId=container_1375845418464_0007_01_000005 queue=default: capacity=1.0, absoluteCapacity=1.0, usedResources=<memory:48128, vCores:42>usedCapacity=0.9791667, absoluteUsedCapacity=0.9791667, numApps=5, numContainers=42 usedCapacity=0.9791667 absoluteUsedCapacity=0.9791667 used=<memory:48128, vCores:42> cluster=<memory:49152, vCores:96>
2013-08-07 03:28:41,905 INFO org.apache.hadoop.yarn.server.resourcemanager.scheduler.capacity.ParentQueue: Re-sorting queues since queue: root.default stats: default: capacity=1.0, absoluteCapacity=1.0, usedResources=<memory:49152, vCores:43>usedCapacity=1.0, absoluteUsedCapacity=1.0, numApps=5, numContainers=43
2013-08-07 03:28:41,906 INFO org.apache.hadoop.yarn.server.resourcemanager.scheduler.capacity.ParentQueue: assignedContainer queue=root usedCapacity=1.0 absoluteUsedCapacity=1.0 used=<memory:49152, vCores:43> cluster=<memory:49152, vCores:96>
2013-08-07 03:28:42,098 INFO org.apache.hadoop.yarn.server.resourcemanager.rmcontainer.RMContainerImpl: container_1375845418464_0007_01_000005 Container Transitioned from ALLOCATED to ACQUIRED
2013-08-07 03:28:42,433 INFO org.apache.hadoop.yarn.server.resourcemanager.rmcontainer.RMContainerImpl: container_1375845418464_0007_01_000005 Container Transitioned from ACQUIRED to RUNNING
2013-08-07 03:28:42,434 INFO org.apache.hadoop.yarn.server.resourcemanager.rmcontainer.RMContainerImpl: container_1375845418464_0006_01_000017 Container Transitioned from RUNNING to COMPLETED
2013-08-07 03:28:42,434 INFO org.apache.hadoop.yarn.server.resourcemanager.scheduler.common.fica.FiCaSchedulerApp: Completed container: container_1375845418464_0006_01_000017 in state: COMPLETED event:FINISHED
2013-08-07 03:28:42,434 INFO org.apache.hadoop.yarn.server.resourcemanager.RMAuditLogger: USER=ubuntu	OPERATION=AM Released Container	TARGET=SchedulerApp	RESULT=SUCCESS	APPID=application_1375845418464_0006	CONTAINERID=container_1375845418464_0006_01_000017
2013-08-07 03:28:42,434 INFO org.apache.hadoop.yarn.server.resourcemanager.scheduler.common.fica.FiCaSchedulerNode: Released container container_1375845418464_0006_01_000017 of capacity <memory:1024, vCores:1> on host hadoop-200-6:45851, which currently has 6 containers, <memory:7168, vCores:6> used and <memory:1024, vCores:10> available, release resources=true
2013-08-07 03:28:42,434 INFO org.apache.hadoop.yarn.server.resourcemanager.scheduler.capacity.LeafQueue: default used=<memory:48128, vCores:42> numContainers=42 user=ubuntu user-resources=<memory:48128, vCores:42>
2013-08-07 03:28:42,435 INFO org.apache.hadoop.yarn.server.resourcemanager.scheduler.capacity.LeafQueue: completedContainer container=Container: [ContainerId: container_1375845418464_0006_01_000017, NodeId: hadoop-200-6:45851, NodeHttpAddress: hadoop-200-6:8042, Resource: <memory:1024, vCores:1>, Priority: 20, State: NEW, Token: null, Status: container_id {, app_attempt_id {, application_id {, id: 6, cluster_timestamp: 1375845418464, }, attemptId: 1, }, id: 17, }, state: C_COMPLETE, diagnostics: "Container killed by the ApplicationMaster.\n\n", exit_status: 143, ] resource=<memory:1024, vCores:1> queue=default: capacity=1.0, absoluteCapacity=1.0, usedResources=<memory:48128, vCores:42>usedCapacity=0.9791667, absoluteUsedCapacity=0.9791667, numApps=5, numContainers=42 usedCapacity=0.9791667 absoluteUsedCapacity=0.9791667 used=<memory:48128, vCores:42> cluster=<memory:49152, vCores:96>
2013-08-07 03:28:42,436 INFO org.apache.hadoop.yarn.server.resourcemanager.scheduler.capacity.ParentQueue: completedContainer queue=root usedCapacity=0.9791667 absoluteUsedCapacity=0.9791667 used=<memory:48128, vCores:42> cluster=<memory:49152, vCores:96>
2013-08-07 03:28:42,436 INFO org.apache.hadoop.yarn.server.resourcemanager.scheduler.capacity.CapacityScheduler: Application appattempt_1375845418464_0006_000001 released container container_1375845418464_0006_01_000017 on node: host: hadoop-200-6:45851 #containers=6 available=1024 used=7168 with event: FINISHED
2013-08-07 03:28:42,436 INFO org.apache.hadoop.yarn.server.resourcemanager.rmcontainer.RMContainerImpl: container_1375845418464_0007_01_000006 Container Transitioned from NEW to ALLOCATED
2013-08-07 03:28:42,436 INFO org.apache.hadoop.yarn.server.resourcemanager.RMAuditLogger: USER=ubuntu	OPERATION=AM Allocated Container	TARGET=SchedulerApp	RESULT=SUCCESS	APPID=application_1375845418464_0007	CONTAINERID=container_1375845418464_0007_01_000006
2013-08-07 03:28:42,437 INFO org.apache.hadoop.yarn.server.resourcemanager.scheduler.common.fica.FiCaSchedulerNode: Assigned container container_1375845418464_0007_01_000006 of capacity <memory:1024, vCores:1> on host hadoop-200-6:45851, which currently has 7 containers, <memory:8192, vCores:7> used and <memory:0, vCores:9> available
2013-08-07 03:28:42,437 INFO org.apache.hadoop.yarn.server.resourcemanager.scheduler.capacity.LeafQueue: assignedContainer application=application_1375845418464_0007 container=Container: [ContainerId: container_1375845418464_0007_01_000006, NodeId: hadoop-200-6:45851, NodeHttpAddress: hadoop-200-6:8042, Resource: <memory:1024, vCores:1>, Priority: 20, State: NEW, Token: null, Status: container_id {, app_attempt_id {, application_id {, id: 7, cluster_timestamp: 1375845418464, }, attemptId: 1, }, id: 6, }, state: C_NEW, ] containerId=container_1375845418464_0007_01_000006 queue=default: capacity=1.0, absoluteCapacity=1.0, usedResources=<memory:48128, vCores:42>usedCapacity=0.9791667, absoluteUsedCapacity=0.9791667, numApps=5, numContainers=42 usedCapacity=0.9791667 absoluteUsedCapacity=0.9791667 used=<memory:48128, vCores:42> cluster=<memory:49152, vCores:96>
2013-08-07 03:28:42,438 INFO org.apache.hadoop.yarn.server.resourcemanager.scheduler.capacity.ParentQueue: Re-sorting queues since queue: root.default stats: default: capacity=1.0, absoluteCapacity=1.0, usedResources=<memory:49152, vCores:43>usedCapacity=1.0, absoluteUsedCapacity=1.0, numApps=5, numContainers=43
2013-08-07 03:28:42,438 INFO org.apache.hadoop.yarn.server.resourcemanager.scheduler.capacity.ParentQueue: assignedContainer queue=root usedCapacity=1.0 absoluteUsedCapacity=1.0 used=<memory:49152, vCores:43> cluster=<memory:49152, vCores:96>
2013-08-07 03:28:43,111 INFO org.apache.hadoop.yarn.server.resourcemanager.rmcontainer.RMContainerImpl: container_1375845418464_0007_01_000006 Container Transitioned from ALLOCATED to ACQUIRED
2013-08-07 03:28:43,444 INFO org.apache.hadoop.yarn.server.resourcemanager.rmcontainer.RMContainerImpl: container_1375845418464_0007_01_000006 Container Transitioned from ACQUIRED to RUNNING
2013-08-07 03:28:43,445 INFO org.apache.hadoop.yarn.server.resourcemanager.rmcontainer.RMContainerImpl: container_1375845418464_0006_01_000019 Container Transitioned from RUNNING to COMPLETED
2013-08-07 03:28:43,445 INFO org.apache.hadoop.yarn.server.resourcemanager.scheduler.common.fica.FiCaSchedulerApp: Completed container: container_1375845418464_0006_01_000019 in state: COMPLETED event:FINISHED
2013-08-07 03:28:43,445 INFO org.apache.hadoop.yarn.server.resourcemanager.RMAuditLogger: USER=ubuntu	OPERATION=AM Released Container	TARGET=SchedulerApp	RESULT=SUCCESS	APPID=application_1375845418464_0006	CONTAINERID=container_1375845418464_0006_01_000019
2013-08-07 03:28:43,445 INFO org.apache.hadoop.yarn.server.resourcemanager.scheduler.common.fica.FiCaSchedulerNode: Released container container_1375845418464_0006_01_000019 of capacity <memory:1024, vCores:1> on host hadoop-200-6:45851, which currently has 6 containers, <memory:7168, vCores:6> used and <memory:1024, vCores:10> available, release resources=true
2013-08-07 03:28:43,445 INFO org.apache.hadoop.yarn.server.resourcemanager.scheduler.capacity.LeafQueue: default used=<memory:48128, vCores:42> numContainers=42 user=ubuntu user-resources=<memory:48128, vCores:42>
2013-08-07 03:28:43,446 INFO org.apache.hadoop.yarn.server.resourcemanager.scheduler.capacity.LeafQueue: completedContainer container=Container: [ContainerId: container_1375845418464_0006_01_000019, NodeId: hadoop-200-6:45851, NodeHttpAddress: hadoop-200-6:8042, Resource: <memory:1024, vCores:1>, Priority: 20, State: NEW, Token: null, Status: container_id {, app_attempt_id {, application_id {, id: 6, cluster_timestamp: 1375845418464, }, attemptId: 1, }, id: 19, }, state: C_COMPLETE, diagnostics: "Container killed by the ApplicationMaster.\n\n", exit_status: 143, ] resource=<memory:1024, vCores:1> queue=default: capacity=1.0, absoluteCapacity=1.0, usedResources=<memory:48128, vCores:42>usedCapacity=0.9791667, absoluteUsedCapacity=0.9791667, numApps=5, numContainers=42 usedCapacity=0.9791667 absoluteUsedCapacity=0.9791667 used=<memory:48128, vCores:42> cluster=<memory:49152, vCores:96>
2013-08-07 03:28:43,446 INFO org.apache.hadoop.yarn.server.resourcemanager.scheduler.capacity.ParentQueue: completedContainer queue=root usedCapacity=0.9791667 absoluteUsedCapacity=0.9791667 used=<memory:48128, vCores:42> cluster=<memory:49152, vCores:96>
2013-08-07 03:28:43,447 INFO org.apache.hadoop.yarn.server.resourcemanager.scheduler.capacity.CapacityScheduler: Application appattempt_1375845418464_0006_000001 released container container_1375845418464_0006_01_000019 on node: host: hadoop-200-6:45851 #containers=6 available=1024 used=7168 with event: FINISHED
2013-08-07 03:28:43,447 INFO org.apache.hadoop.yarn.server.resourcemanager.rmcontainer.RMContainerImpl: container_1375845418464_0007_01_000007 Container Transitioned from NEW to ALLOCATED
2013-08-07 03:28:43,447 INFO org.apache.hadoop.yarn.server.resourcemanager.RMAuditLogger: USER=ubuntu	OPERATION=AM Allocated Container	TARGET=SchedulerApp	RESULT=SUCCESS	APPID=application_1375845418464_0007	CONTAINERID=container_1375845418464_0007_01_000007
2013-08-07 03:28:43,447 INFO org.apache.hadoop.yarn.server.resourcemanager.scheduler.common.fica.FiCaSchedulerNode: Assigned container container_1375845418464_0007_01_000007 of capacity <memory:1024, vCores:1> on host hadoop-200-6:45851, which currently has 7 containers, <memory:8192, vCores:7> used and <memory:0, vCores:9> available
2013-08-07 03:28:43,448 INFO org.apache.hadoop.yarn.server.resourcemanager.scheduler.capacity.LeafQueue: assignedContainer application=application_1375845418464_0007 container=Container: [ContainerId: container_1375845418464_0007_01_000007, NodeId: hadoop-200-6:45851, NodeHttpAddress: hadoop-200-6:8042, Resource: <memory:1024, vCores:1>, Priority: 20, State: NEW, Token: null, Status: container_id {, app_attempt_id {, application_id {, id: 7, cluster_timestamp: 1375845418464, }, attemptId: 1, }, id: 7, }, state: C_NEW, ] containerId=container_1375845418464_0007_01_000007 queue=default: capacity=1.0, absoluteCapacity=1.0, usedResources=<memory:48128, vCores:42>usedCapacity=0.9791667, absoluteUsedCapacity=0.9791667, numApps=5, numContainers=42 usedCapacity=0.9791667 absoluteUsedCapacity=0.9791667 used=<memory:48128, vCores:42> cluster=<memory:49152, vCores:96>
2013-08-07 03:28:43,448 INFO org.apache.hadoop.yarn.server.resourcemanager.scheduler.capacity.ParentQueue: Re-sorting queues since queue: root.default stats: default: capacity=1.0, absoluteCapacity=1.0, usedResources=<memory:49152, vCores:43>usedCapacity=1.0, absoluteUsedCapacity=1.0, numApps=5, numContainers=43
2013-08-07 03:28:43,449 INFO org.apache.hadoop.yarn.server.resourcemanager.scheduler.capacity.ParentQueue: assignedContainer queue=root usedCapacity=1.0 absoluteUsedCapacity=1.0 used=<memory:49152, vCores:43> cluster=<memory:49152, vCores:96>
2013-08-07 03:28:43,799 INFO org.apache.hadoop.yarn.server.resourcemanager.rmcontainer.RMContainerImpl: container_1375845418464_0006_01_000026 Container Transitioned from RUNNING to COMPLETED
2013-08-07 03:28:43,800 INFO org.apache.hadoop.yarn.server.resourcemanager.scheduler.common.fica.FiCaSchedulerApp: Completed container: container_1375845418464_0006_01_000026 in state: COMPLETED event:FINISHED
2013-08-07 03:28:43,800 INFO org.apache.hadoop.yarn.server.resourcemanager.RMAuditLogger: USER=ubuntu	OPERATION=AM Released Container	TARGET=SchedulerApp	RESULT=SUCCESS	APPID=application_1375845418464_0006	CONTAINERID=container_1375845418464_0006_01_000026
2013-08-07 03:28:43,800 INFO org.apache.hadoop.yarn.server.resourcemanager.scheduler.common.fica.FiCaSchedulerNode: Released container container_1375845418464_0006_01_000026 of capacity <memory:1024, vCores:1> on host hadoop-200-4:45217, which currently has 7 containers, <memory:7168, vCores:7> used and <memory:1024, vCores:9> available, release resources=true
2013-08-07 03:28:43,800 INFO org.apache.hadoop.yarn.server.resourcemanager.scheduler.capacity.LeafQueue: default used=<memory:48128, vCores:42> numContainers=42 user=ubuntu user-resources=<memory:48128, vCores:42>
2013-08-07 03:28:43,801 INFO org.apache.hadoop.yarn.server.resourcemanager.scheduler.capacity.LeafQueue: completedContainer container=Container: [ContainerId: container_1375845418464_0006_01_000026, NodeId: hadoop-200-4:45217, NodeHttpAddress: hadoop-200-4:8042, Resource: <memory:1024, vCores:1>, Priority: 20, State: NEW, Token: null, Status: container_id {, app_attempt_id {, application_id {, id: 6, cluster_timestamp: 1375845418464, }, attemptId: 1, }, id: 26, }, state: C_COMPLETE, diagnostics: "Container killed by the ApplicationMaster.\n", exit_status: 0, ] resource=<memory:1024, vCores:1> queue=default: capacity=1.0, absoluteCapacity=1.0, usedResources=<memory:48128, vCores:42>usedCapacity=0.9791667, absoluteUsedCapacity=0.9791667, numApps=5, numContainers=42 usedCapacity=0.9791667 absoluteUsedCapacity=0.9791667 used=<memory:48128, vCores:42> cluster=<memory:49152, vCores:96>
2013-08-07 03:28:43,802 INFO org.apache.hadoop.yarn.server.resourcemanager.scheduler.capacity.ParentQueue: completedContainer queue=root usedCapacity=0.9791667 absoluteUsedCapacity=0.9791667 used=<memory:48128, vCores:42> cluster=<memory:49152, vCores:96>
2013-08-07 03:28:43,802 INFO org.apache.hadoop.yarn.server.resourcemanager.scheduler.capacity.CapacityScheduler: Application appattempt_1375845418464_0006_000001 released container container_1375845418464_0006_01_000026 on node: host: hadoop-200-4:45217 #containers=7 available=1024 used=7168 with event: FINISHED
2013-08-07 03:28:43,802 INFO org.apache.hadoop.yarn.server.resourcemanager.rmcontainer.RMContainerImpl: container_1375845418464_0007_01_000008 Container Transitioned from NEW to ALLOCATED
2013-08-07 03:28:43,802 INFO org.apache.hadoop.yarn.server.resourcemanager.RMAuditLogger: USER=ubuntu	OPERATION=AM Allocated Container	TARGET=SchedulerApp	RESULT=SUCCESS	APPID=application_1375845418464_0007	CONTAINERID=container_1375845418464_0007_01_000008
2013-08-07 03:28:43,802 INFO org.apache.hadoop.yarn.server.resourcemanager.scheduler.common.fica.FiCaSchedulerNode: Assigned container container_1375845418464_0007_01_000008 of capacity <memory:1024, vCores:1> on host hadoop-200-4:45217, which currently has 8 containers, <memory:8192, vCores:8> used and <memory:0, vCores:8> available
2013-08-07 03:28:43,803 INFO org.apache.hadoop.yarn.server.resourcemanager.scheduler.capacity.LeafQueue: assignedContainer application=application_1375845418464_0007 container=Container: [ContainerId: container_1375845418464_0007_01_000008, NodeId: hadoop-200-4:45217, NodeHttpAddress: hadoop-200-4:8042, Resource: <memory:1024, vCores:1>, Priority: 20, State: NEW, Token: null, Status: container_id {, app_attempt_id {, application_id {, id: 7, cluster_timestamp: 1375845418464, }, attemptId: 1, }, id: 8, }, state: C_NEW, ] containerId=container_1375845418464_0007_01_000008 queue=default: capacity=1.0, absoluteCapacity=1.0, usedResources=<memory:48128, vCores:42>usedCapacity=0.9791667, absoluteUsedCapacity=0.9791667, numApps=5, numContainers=42 usedCapacity=0.9791667 absoluteUsedCapacity=0.9791667 used=<memory:48128, vCores:42> cluster=<memory:49152, vCores:96>
2013-08-07 03:28:43,804 INFO org.apache.hadoop.yarn.server.resourcemanager.scheduler.capacity.ParentQueue: Re-sorting queues since queue: root.default stats: default: capacity=1.0, absoluteCapacity=1.0, usedResources=<memory:49152, vCores:43>usedCapacity=1.0, absoluteUsedCapacity=1.0, numApps=5, numContainers=43
2013-08-07 03:28:43,804 INFO org.apache.hadoop.yarn.server.resourcemanager.scheduler.capacity.ParentQueue: assignedContainer queue=root usedCapacity=1.0 absoluteUsedCapacity=1.0 used=<memory:49152, vCores:43> cluster=<memory:49152, vCores:96>
2013-08-07 03:28:44,117 INFO org.apache.hadoop.yarn.server.resourcemanager.rmcontainer.RMContainerImpl: container_1375845418464_0007_01_000007 Container Transitioned from ALLOCATED to ACQUIRED
2013-08-07 03:28:44,119 INFO org.apache.hadoop.yarn.server.resourcemanager.rmcontainer.RMContainerImpl: container_1375845418464_0007_01_000008 Container Transitioned from ALLOCATED to ACQUIRED
2013-08-07 03:28:44,587 INFO org.apache.hadoop.yarn.server.resourcemanager.rmcontainer.RMContainerImpl: container_1375845418464_0007_01_000007 Container Transitioned from ACQUIRED to RUNNING
2013-08-07 03:28:44,812 INFO org.apache.hadoop.yarn.server.resourcemanager.rmcontainer.RMContainerImpl: container_1375845418464_0007_01_000008 Container Transitioned from ACQUIRED to RUNNING
2013-08-07 03:28:44,812 INFO org.apache.hadoop.yarn.server.resourcemanager.rmcontainer.RMContainerImpl: container_1375845418464_0006_01_000032 Container Transitioned from RUNNING to COMPLETED
2013-08-07 03:28:44,812 INFO org.apache.hadoop.yarn.server.resourcemanager.scheduler.common.fica.FiCaSchedulerApp: Completed container: container_1375845418464_0006_01_000032 in state: COMPLETED event:FINISHED
2013-08-07 03:28:44,812 INFO org.apache.hadoop.yarn.server.resourcemanager.RMAuditLogger: USER=ubuntu	OPERATION=AM Released Container	TARGET=SchedulerApp	RESULT=SUCCESS	APPID=application_1375845418464_0006	CONTAINERID=container_1375845418464_0006_01_000032
2013-08-07 03:28:44,813 INFO org.apache.hadoop.yarn.server.resourcemanager.scheduler.common.fica.FiCaSchedulerNode: Released container container_1375845418464_0006_01_000032 of capacity <memory:1024, vCores:1> on host hadoop-200-4:45217, which currently has 7 containers, <memory:7168, vCores:7> used and <memory:1024, vCores:9> available, release resources=true
2013-08-07 03:28:44,813 INFO org.apache.hadoop.yarn.server.resourcemanager.scheduler.capacity.LeafQueue: default used=<memory:48128, vCores:42> numContainers=42 user=ubuntu user-resources=<memory:48128, vCores:42>
2013-08-07 03:28:44,814 INFO org.apache.hadoop.yarn.server.resourcemanager.scheduler.capacity.LeafQueue: completedContainer container=Container: [ContainerId: container_1375845418464_0006_01_000032, NodeId: hadoop-200-4:45217, NodeHttpAddress: hadoop-200-4:8042, Resource: <memory:1024, vCores:1>, Priority: 20, State: NEW, Token: null, Status: container_id {, app_attempt_id {, application_id {, id: 6, cluster_timestamp: 1375845418464, }, attemptId: 1, }, id: 32, }, state: C_COMPLETE, diagnostics: "Container killed by the ApplicationMaster.\n\n", exit_status: 143, ] resource=<memory:1024, vCores:1> queue=default: capacity=1.0, absoluteCapacity=1.0, usedResources=<memory:48128, vCores:42>usedCapacity=0.9791667, absoluteUsedCapacity=0.9791667, numApps=5, numContainers=42 usedCapacity=0.9791667 absoluteUsedCapacity=0.9791667 used=<memory:48128, vCores:42> cluster=<memory:49152, vCores:96>
2013-08-07 03:28:44,814 INFO org.apache.hadoop.yarn.server.resourcemanager.scheduler.capacity.ParentQueue: completedContainer queue=root usedCapacity=0.9791667 absoluteUsedCapacity=0.9791667 used=<memory:48128, vCores:42> cluster=<memory:49152, vCores:96>
2013-08-07 03:28:44,814 INFO org.apache.hadoop.yarn.server.resourcemanager.scheduler.capacity.CapacityScheduler: Application appattempt_1375845418464_0006_000001 released container container_1375845418464_0006_01_000032 on node: host: hadoop-200-4:45217 #containers=7 available=1024 used=7168 with event: FINISHED
2013-08-07 03:28:44,815 INFO org.apache.hadoop.yarn.server.resourcemanager.rmcontainer.RMContainerImpl: container_1375845418464_0007_01_000009 Container Transitioned from NEW to ALLOCATED
2013-08-07 03:28:44,815 INFO org.apache.hadoop.yarn.server.resourcemanager.RMAuditLogger: USER=ubuntu	OPERATION=AM Allocated Container	TARGET=SchedulerApp	RESULT=SUCCESS	APPID=application_1375845418464_0007	CONTAINERID=container_1375845418464_0007_01_000009
2013-08-07 03:28:44,815 INFO org.apache.hadoop.yarn.server.resourcemanager.scheduler.common.fica.FiCaSchedulerNode: Assigned container container_1375845418464_0007_01_000009 of capacity <memory:1024, vCores:1> on host hadoop-200-4:45217, which currently has 8 containers, <memory:8192, vCores:8> used and <memory:0, vCores:8> available
2013-08-07 03:28:44,816 INFO org.apache.hadoop.yarn.server.resourcemanager.scheduler.capacity.LeafQueue: assignedContainer application=application_1375845418464_0007 container=Container: [ContainerId: container_1375845418464_0007_01_000009, NodeId: hadoop-200-4:45217, NodeHttpAddress: hadoop-200-4:8042, Resource: <memory:1024, vCores:1>, Priority: 20, State: NEW, Token: null, Status: container_id {, app_attempt_id {, application_id {, id: 7, cluster_timestamp: 1375845418464, }, attemptId: 1, }, id: 9, }, state: C_NEW, ] containerId=container_1375845418464_0007_01_000009 queue=default: capacity=1.0, absoluteCapacity=1.0, usedResources=<memory:48128, vCores:42>usedCapacity=0.9791667, absoluteUsedCapacity=0.9791667, numApps=5, numContainers=42 usedCapacity=0.9791667 absoluteUsedCapacity=0.9791667 used=<memory:48128, vCores:42> cluster=<memory:49152, vCores:96>
2013-08-07 03:28:44,816 INFO org.apache.hadoop.yarn.server.resourcemanager.scheduler.capacity.ParentQueue: Re-sorting queues since queue: root.default stats: default: capacity=1.0, absoluteCapacity=1.0, usedResources=<memory:49152, vCores:43>usedCapacity=1.0, absoluteUsedCapacity=1.0, numApps=5, numContainers=43
2013-08-07 03:28:44,816 INFO org.apache.hadoop.yarn.server.resourcemanager.scheduler.capacity.ParentQueue: assignedContainer queue=root usedCapacity=1.0 absoluteUsedCapacity=1.0 used=<memory:49152, vCores:43> cluster=<memory:49152, vCores:96>
2013-08-07 03:28:45,128 INFO org.apache.hadoop.yarn.server.resourcemanager.rmcontainer.RMContainerImpl: container_1375845418464_0007_01_000009 Container Transitioned from ALLOCATED to ACQUIRED
2013-08-07 03:28:45,361 INFO org.apache.hadoop.yarn.server.resourcemanager.rmcontainer.RMContainerImpl: container_1375845418464_0007_01_000009 Container Transitioned from ACQUIRED to RUNNING
2013-08-07 03:28:46,370 INFO org.apache.hadoop.yarn.server.resourcemanager.rmcontainer.RMContainerImpl: container_1375845418464_0006_01_000030 Container Transitioned from RUNNING to COMPLETED
2013-08-07 03:28:46,370 INFO org.apache.hadoop.yarn.server.resourcemanager.scheduler.common.fica.FiCaSchedulerApp: Completed container: container_1375845418464_0006_01_000030 in state: COMPLETED event:FINISHED
2013-08-07 03:28:46,370 INFO org.apache.hadoop.yarn.server.resourcemanager.RMAuditLogger: USER=ubuntu	OPERATION=AM Released Container	TARGET=SchedulerApp	RESULT=SUCCESS	APPID=application_1375845418464_0006	CONTAINERID=container_1375845418464_0006_01_000030
2013-08-07 03:28:46,370 INFO org.apache.hadoop.yarn.server.resourcemanager.scheduler.common.fica.FiCaSchedulerNode: Released container container_1375845418464_0006_01_000030 of capacity <memory:1024, vCores:1> on host hadoop-200-4:45217, which currently has 7 containers, <memory:7168, vCores:7> used and <memory:1024, vCores:9> available, release resources=true
2013-08-07 03:28:46,370 INFO org.apache.hadoop.yarn.server.resourcemanager.scheduler.capacity.LeafQueue: default used=<memory:48128, vCores:42> numContainers=42 user=ubuntu user-resources=<memory:48128, vCores:42>
2013-08-07 03:28:46,372 INFO org.apache.hadoop.yarn.server.resourcemanager.scheduler.capacity.LeafQueue: completedContainer container=Container: [ContainerId: container_1375845418464_0006_01_000030, NodeId: hadoop-200-4:45217, NodeHttpAddress: hadoop-200-4:8042, Resource: <memory:1024, vCores:1>, Priority: 20, State: NEW, Token: null, Status: container_id {, app_attempt_id {, application_id {, id: 6, cluster_timestamp: 1375845418464, }, attemptId: 1, }, id: 30, }, state: C_COMPLETE, diagnostics: "Container killed by the ApplicationMaster.\n\n", exit_status: 143, ] resource=<memory:1024, vCores:1> queue=default: capacity=1.0, absoluteCapacity=1.0, usedResources=<memory:48128, vCores:42>usedCapacity=0.9791667, absoluteUsedCapacity=0.9791667, numApps=5, numContainers=42 usedCapacity=0.9791667 absoluteUsedCapacity=0.9791667 used=<memory:48128, vCores:42> cluster=<memory:49152, vCores:96>
2013-08-07 03:28:46,372 INFO org.apache.hadoop.yarn.server.resourcemanager.scheduler.capacity.ParentQueue: completedContainer queue=root usedCapacity=0.9791667 absoluteUsedCapacity=0.9791667 used=<memory:48128, vCores:42> cluster=<memory:49152, vCores:96>
2013-08-07 03:28:46,372 INFO org.apache.hadoop.yarn.server.resourcemanager.scheduler.capacity.CapacityScheduler: Application appattempt_1375845418464_0006_000001 released container container_1375845418464_0006_01_000030 on node: host: hadoop-200-4:45217 #containers=7 available=1024 used=7168 with event: FINISHED
2013-08-07 03:28:46,372 INFO org.apache.hadoop.yarn.server.resourcemanager.rmcontainer.RMContainerImpl: container_1375845418464_0007_01_000010 Container Transitioned from NEW to ALLOCATED
2013-08-07 03:28:46,373 INFO org.apache.hadoop.yarn.server.resourcemanager.RMAuditLogger: USER=ubuntu	OPERATION=AM Allocated Container	TARGET=SchedulerApp	RESULT=SUCCESS	APPID=application_1375845418464_0007	CONTAINERID=container_1375845418464_0007_01_000010
2013-08-07 03:28:46,373 INFO org.apache.hadoop.yarn.server.resourcemanager.scheduler.common.fica.FiCaSchedulerNode: Assigned container container_1375845418464_0007_01_000010 of capacity <memory:1024, vCores:1> on host hadoop-200-4:45217, which currently has 8 containers, <memory:8192, vCores:8> used and <memory:0, vCores:8> available
2013-08-07 03:28:46,374 INFO org.apache.hadoop.yarn.server.resourcemanager.scheduler.capacity.LeafQueue: assignedContainer application=application_1375845418464_0007 container=Container: [ContainerId: container_1375845418464_0007_01_000010, NodeId: hadoop-200-4:45217, NodeHttpAddress: hadoop-200-4:8042, Resource: <memory:1024, vCores:1>, Priority: 20, State: NEW, Token: null, Status: container_id {, app_attempt_id {, application_id {, id: 7, cluster_timestamp: 1375845418464, }, attemptId: 1, }, id: 10, }, state: C_NEW, ] containerId=container_1375845418464_0007_01_000010 queue=default: capacity=1.0, absoluteCapacity=1.0, usedResources=<memory:48128, vCores:42>usedCapacity=0.9791667, absoluteUsedCapacity=0.9791667, numApps=5, numContainers=42 usedCapacity=0.9791667 absoluteUsedCapacity=0.9791667 used=<memory:48128, vCores:42> cluster=<memory:49152, vCores:96>
2013-08-07 03:28:46,374 INFO org.apache.hadoop.yarn.server.resourcemanager.scheduler.capacity.ParentQueue: Re-sorting queues since queue: root.default stats: default: capacity=1.0, absoluteCapacity=1.0, usedResources=<memory:49152, vCores:43>usedCapacity=1.0, absoluteUsedCapacity=1.0, numApps=5, numContainers=43
2013-08-07 03:28:46,374 INFO org.apache.hadoop.yarn.server.resourcemanager.scheduler.capacity.ParentQueue: assignedContainer queue=root usedCapacity=1.0 absoluteUsedCapacity=1.0 used=<memory:49152, vCores:43> cluster=<memory:49152, vCores:96>
2013-08-07 03:28:47,138 INFO org.apache.hadoop.yarn.server.resourcemanager.rmcontainer.RMContainerImpl: container_1375845418464_0007_01_000010 Container Transitioned from ALLOCATED to ACQUIRED
2013-08-07 03:28:47,249 INFO org.apache.hadoop.yarn.server.resourcemanager.rmcontainer.RMContainerImpl: container_1375845418464_0006_01_000018 Container Transitioned from RUNNING to COMPLETED
2013-08-07 03:28:47,249 INFO org.apache.hadoop.yarn.server.resourcemanager.scheduler.common.fica.FiCaSchedulerApp: Completed container: container_1375845418464_0006_01_000018 in state: COMPLETED event:FINISHED
2013-08-07 03:28:47,249 INFO org.apache.hadoop.yarn.server.resourcemanager.RMAuditLogger: USER=ubuntu	OPERATION=AM Released Container	TARGET=SchedulerApp	RESULT=SUCCESS	APPID=application_1375845418464_0006	CONTAINERID=container_1375845418464_0006_01_000018
2013-08-07 03:28:47,249 INFO org.apache.hadoop.yarn.server.resourcemanager.scheduler.common.fica.FiCaSchedulerNode: Released container container_1375845418464_0006_01_000018 of capacity <memory:1024, vCores:1> on host hadoop-200-6:45851, which currently has 6 containers, <memory:7168, vCores:6> used and <memory:1024, vCores:10> available, release resources=true
2013-08-07 03:28:47,250 INFO org.apache.hadoop.yarn.server.resourcemanager.scheduler.capacity.LeafQueue: default used=<memory:48128, vCores:42> numContainers=42 user=ubuntu user-resources=<memory:48128, vCores:42>
2013-08-07 03:28:47,251 INFO org.apache.hadoop.yarn.server.resourcemanager.scheduler.capacity.LeafQueue: completedContainer container=Container: [ContainerId: container_1375845418464_0006_01_000018, NodeId: hadoop-200-6:45851, NodeHttpAddress: hadoop-200-6:8042, Resource: <memory:1024, vCores:1>, Priority: 20, State: NEW, Token: null, Status: container_id {, app_attempt_id {, application_id {, id: 6, cluster_timestamp: 1375845418464, }, attemptId: 1, }, id: 18, }, state: C_COMPLETE, diagnostics: "Container killed by the ApplicationMaster.\n\n", exit_status: 143, ] resource=<memory:1024, vCores:1> queue=default: capacity=1.0, absoluteCapacity=1.0, usedResources=<memory:48128, vCores:42>usedCapacity=0.9791667, absoluteUsedCapacity=0.9791667, numApps=5, numContainers=42 usedCapacity=0.9791667 absoluteUsedCapacity=0.9791667 used=<memory:48128, vCores:42> cluster=<memory:49152, vCores:96>
2013-08-07 03:28:47,251 INFO org.apache.hadoop.yarn.server.resourcemanager.scheduler.capacity.ParentQueue: completedContainer queue=root usedCapacity=0.9791667 absoluteUsedCapacity=0.9791667 used=<memory:48128, vCores:42> cluster=<memory:49152, vCores:96>
2013-08-07 03:28:47,251 INFO org.apache.hadoop.yarn.server.resourcemanager.scheduler.capacity.CapacityScheduler: Application appattempt_1375845418464_0006_000001 released container container_1375845418464_0006_01_000018 on node: host: hadoop-200-6:45851 #containers=6 available=1024 used=7168 with event: FINISHED
2013-08-07 03:28:47,251 INFO org.apache.hadoop.yarn.server.resourcemanager.rmcontainer.RMContainerImpl: container_1375845418464_0007_01_000011 Container Transitioned from NEW to ALLOCATED
2013-08-07 03:28:47,252 INFO org.apache.hadoop.yarn.server.resourcemanager.RMAuditLogger: USER=ubuntu	OPERATION=AM Allocated Container	TARGET=SchedulerApp	RESULT=SUCCESS	APPID=application_1375845418464_0007	CONTAINERID=container_1375845418464_0007_01_000011
2013-08-07 03:28:47,252 INFO org.apache.hadoop.yarn.server.resourcemanager.scheduler.common.fica.FiCaSchedulerNode: Assigned container container_1375845418464_0007_01_000011 of capacity <memory:1024, vCores:1> on host hadoop-200-6:45851, which currently has 7 containers, <memory:8192, vCores:7> used and <memory:0, vCores:9> available
2013-08-07 03:28:47,253 INFO org.apache.hadoop.yarn.server.resourcemanager.scheduler.capacity.LeafQueue: assignedContainer application=application_1375845418464_0007 container=Container: [ContainerId: container_1375845418464_0007_01_000011, NodeId: hadoop-200-6:45851, NodeHttpAddress: hadoop-200-6:8042, Resource: <memory:1024, vCores:1>, Priority: 20, State: NEW, Token: null, Status: container_id {, app_attempt_id {, application_id {, id: 7, cluster_timestamp: 1375845418464, }, attemptId: 1, }, id: 11, }, state: C_NEW, ] containerId=container_1375845418464_0007_01_000011 queue=default: capacity=1.0, absoluteCapacity=1.0, usedResources=<memory:48128, vCores:42>usedCapacity=0.9791667, absoluteUsedCapacity=0.9791667, numApps=5, numContainers=42 usedCapacity=0.9791667 absoluteUsedCapacity=0.9791667 used=<memory:48128, vCores:42> cluster=<memory:49152, vCores:96>
2013-08-07 03:28:47,253 INFO org.apache.hadoop.yarn.server.resourcemanager.scheduler.capacity.ParentQueue: Re-sorting queues since queue: root.default stats: default: capacity=1.0, absoluteCapacity=1.0, usedResources=<memory:49152, vCores:43>usedCapacity=1.0, absoluteUsedCapacity=1.0, numApps=5, numContainers=43
2013-08-07 03:28:47,253 INFO org.apache.hadoop.yarn.server.resourcemanager.scheduler.capacity.ParentQueue: assignedContainer queue=root usedCapacity=1.0 absoluteUsedCapacity=1.0 used=<memory:49152, vCores:43> cluster=<memory:49152, vCores:96>
2013-08-07 03:28:47,379 INFO org.apache.hadoop.yarn.server.resourcemanager.rmcontainer.RMContainerImpl: container_1375845418464_0007_01_000010 Container Transitioned from ACQUIRED to RUNNING
2013-08-07 03:28:47,941 INFO org.apache.hadoop.yarn.server.resourcemanager.rmcontainer.RMContainerImpl: container_1375845418464_0006_01_000013 Container Transitioned from RUNNING to COMPLETED
2013-08-07 03:28:47,941 INFO org.apache.hadoop.yarn.server.resourcemanager.scheduler.common.fica.FiCaSchedulerApp: Completed container: container_1375845418464_0006_01_000013 in state: COMPLETED event:FINISHED
2013-08-07 03:28:47,941 INFO org.apache.hadoop.yarn.server.resourcemanager.RMAuditLogger: USER=ubuntu	OPERATION=AM Released Container	TARGET=SchedulerApp	RESULT=SUCCESS	APPID=application_1375845418464_0006	CONTAINERID=container_1375845418464_0006_01_000013
2013-08-07 03:28:47,941 INFO org.apache.hadoop.yarn.server.resourcemanager.scheduler.common.fica.FiCaSchedulerNode: Released container container_1375845418464_0006_01_000013 of capacity <memory:1024, vCores:1> on host hadoop-200-2:46099, which currently has 6 containers, <memory:7168, vCores:6> used and <memory:1024, vCores:10> available, release resources=true
2013-08-07 03:28:47,941 INFO org.apache.hadoop.yarn.server.resourcemanager.scheduler.capacity.LeafQueue: default used=<memory:48128, vCores:42> numContainers=42 user=ubuntu user-resources=<memory:48128, vCores:42>
2013-08-07 03:28:47,943 INFO org.apache.hadoop.yarn.server.resourcemanager.scheduler.capacity.LeafQueue: completedContainer container=Container: [ContainerId: container_1375845418464_0006_01_000013, NodeId: hadoop-200-2:46099, NodeHttpAddress: hadoop-200-2:8042, Resource: <memory:1024, vCores:1>, Priority: 20, State: NEW, Token: null, Status: container_id {, app_attempt_id {, application_id {, id: 6, cluster_timestamp: 1375845418464, }, attemptId: 1, }, id: 13, }, state: C_COMPLETE, diagnostics: "Container killed by the ApplicationMaster.\n\n", exit_status: 143, ] resource=<memory:1024, vCores:1> queue=default: capacity=1.0, absoluteCapacity=1.0, usedResources=<memory:48128, vCores:42>usedCapacity=0.9791667, absoluteUsedCapacity=0.9791667, numApps=5, numContainers=42 usedCapacity=0.9791667 absoluteUsedCapacity=0.9791667 used=<memory:48128, vCores:42> cluster=<memory:49152, vCores:96>
2013-08-07 03:28:47,943 INFO org.apache.hadoop.yarn.server.resourcemanager.scheduler.capacity.ParentQueue: completedContainer queue=root usedCapacity=0.9791667 absoluteUsedCapacity=0.9791667 used=<memory:48128, vCores:42> cluster=<memory:49152, vCores:96>
2013-08-07 03:28:47,943 INFO org.apache.hadoop.yarn.server.resourcemanager.scheduler.capacity.CapacityScheduler: Application appattempt_1375845418464_0006_000001 released container container_1375845418464_0006_01_000013 on node: host: hadoop-200-2:46099 #containers=6 available=1024 used=7168 with event: FINISHED
2013-08-07 03:28:47,943 INFO org.apache.hadoop.yarn.server.resourcemanager.rmcontainer.RMContainerImpl: container_1375845418464_0007_01_000012 Container Transitioned from NEW to ALLOCATED
2013-08-07 03:28:47,944 INFO org.apache.hadoop.yarn.server.resourcemanager.RMAuditLogger: USER=ubuntu	OPERATION=AM Allocated Container	TARGET=SchedulerApp	RESULT=SUCCESS	APPID=application_1375845418464_0007	CONTAINERID=container_1375845418464_0007_01_000012
2013-08-07 03:28:47,944 INFO org.apache.hadoop.yarn.server.resourcemanager.scheduler.common.fica.FiCaSchedulerNode: Assigned container container_1375845418464_0007_01_000012 of capacity <memory:1024, vCores:1> on host hadoop-200-2:46099, which currently has 7 containers, <memory:8192, vCores:7> used and <memory:0, vCores:9> available
2013-08-07 03:28:47,944 INFO org.apache.hadoop.yarn.server.resourcemanager.scheduler.capacity.LeafQueue: assignedContainer application=application_1375845418464_0007 container=Container: [ContainerId: container_1375845418464_0007_01_000012, NodeId: hadoop-200-2:46099, NodeHttpAddress: hadoop-200-2:8042, Resource: <memory:1024, vCores:1>, Priority: 20, State: NEW, Token: null, Status: container_id {, app_attempt_id {, application_id {, id: 7, cluster_timestamp: 1375845418464, }, attemptId: 1, }, id: 12, }, state: C_NEW, ] containerId=container_1375845418464_0007_01_000012 queue=default: capacity=1.0, absoluteCapacity=1.0, usedResources=<memory:48128, vCores:42>usedCapacity=0.9791667, absoluteUsedCapacity=0.9791667, numApps=5, numContainers=42 usedCapacity=0.9791667 absoluteUsedCapacity=0.9791667 used=<memory:48128, vCores:42> cluster=<memory:49152, vCores:96>
2013-08-07 03:28:47,945 INFO org.apache.hadoop.yarn.server.resourcemanager.scheduler.capacity.ParentQueue: Re-sorting queues since queue: root.default stats: default: capacity=1.0, absoluteCapacity=1.0, usedResources=<memory:49152, vCores:43>usedCapacity=1.0, absoluteUsedCapacity=1.0, numApps=5, numContainers=43
2013-08-07 03:28:47,945 INFO org.apache.hadoop.yarn.server.resourcemanager.scheduler.capacity.ParentQueue: assignedContainer queue=root usedCapacity=1.0 absoluteUsedCapacity=1.0 used=<memory:49152, vCores:43> cluster=<memory:49152, vCores:96>
2013-08-07 03:28:48,034 INFO org.apache.hadoop.yarn.server.resourcemanager.rmcontainer.RMContainerImpl: container_1375845418464_0006_01_000011 Container Transitioned from RUNNING to COMPLETED
2013-08-07 03:28:48,034 INFO org.apache.hadoop.yarn.server.resourcemanager.scheduler.common.fica.FiCaSchedulerApp: Completed container: container_1375845418464_0006_01_000011 in state: COMPLETED event:FINISHED
2013-08-07 03:28:48,034 INFO org.apache.hadoop.yarn.server.resourcemanager.RMAuditLogger: USER=ubuntu	OPERATION=AM Released Container	TARGET=SchedulerApp	RESULT=SUCCESS	APPID=application_1375845418464_0006	CONTAINERID=container_1375845418464_0006_01_000011
2013-08-07 03:28:48,034 INFO org.apache.hadoop.yarn.server.resourcemanager.scheduler.common.fica.FiCaSchedulerNode: Released container container_1375845418464_0006_01_000011 of capacity <memory:1024, vCores:1> on host hadoop-200-2:46099, which currently has 6 containers, <memory:7168, vCores:6> used and <memory:1024, vCores:10> available, release resources=true
2013-08-07 03:28:48,034 INFO org.apache.hadoop.yarn.server.resourcemanager.scheduler.capacity.LeafQueue: default used=<memory:48128, vCores:42> numContainers=42 user=ubuntu user-resources=<memory:48128, vCores:42>
2013-08-07 03:28:48,035 INFO org.apache.hadoop.yarn.server.resourcemanager.scheduler.capacity.LeafQueue: completedContainer container=Container: [ContainerId: container_1375845418464_0006_01_000011, NodeId: hadoop-200-2:46099, NodeHttpAddress: hadoop-200-2:8042, Resource: <memory:1024, vCores:1>, Priority: 20, State: NEW, Token: null, Status: container_id {, app_attempt_id {, application_id {, id: 6, cluster_timestamp: 1375845418464, }, attemptId: 1, }, id: 11, }, state: C_COMPLETE, diagnostics: "Container killed by the ApplicationMaster.\n\n", exit_status: 143, ] resource=<memory:1024, vCores:1> queue=default: capacity=1.0, absoluteCapacity=1.0, usedResources=<memory:48128, vCores:42>usedCapacity=0.9791667, absoluteUsedCapacity=0.9791667, numApps=5, numContainers=42 usedCapacity=0.9791667 absoluteUsedCapacity=0.9791667 used=<memory:48128, vCores:42> cluster=<memory:49152, vCores:96>
2013-08-07 03:28:48,035 INFO org.apache.hadoop.yarn.server.resourcemanager.scheduler.capacity.ParentQueue: completedContainer queue=root usedCapacity=0.9791667 absoluteUsedCapacity=0.9791667 used=<memory:48128, vCores:42> cluster=<memory:49152, vCores:96>
2013-08-07 03:28:48,036 INFO org.apache.hadoop.yarn.server.resourcemanager.scheduler.capacity.CapacityScheduler: Application appattempt_1375845418464_0006_000001 released container container_1375845418464_0006_01_000011 on node: host: hadoop-200-2:46099 #containers=6 available=1024 used=7168 with event: FINISHED
2013-08-07 03:28:48,036 INFO org.apache.hadoop.yarn.server.resourcemanager.rmcontainer.RMContainerImpl: container_1375845418464_0007_01_000013 Container Transitioned from NEW to ALLOCATED
2013-08-07 03:28:48,036 INFO org.apache.hadoop.yarn.server.resourcemanager.RMAuditLogger: USER=ubuntu	OPERATION=AM Allocated Container	TARGET=SchedulerApp	RESULT=SUCCESS	APPID=application_1375845418464_0007	CONTAINERID=container_1375845418464_0007_01_000013
2013-08-07 03:28:48,036 INFO org.apache.hadoop.yarn.server.resourcemanager.scheduler.common.fica.FiCaSchedulerNode: Assigned container container_1375845418464_0007_01_000013 of capacity <memory:1024, vCores:1> on host hadoop-200-2:46099, which currently has 7 containers, <memory:8192, vCores:7> used and <memory:0, vCores:9> available
2013-08-07 03:28:48,037 INFO org.apache.hadoop.yarn.server.resourcemanager.scheduler.capacity.LeafQueue: assignedContainer application=application_1375845418464_0007 container=Container: [ContainerId: container_1375845418464_0007_01_000013, NodeId: hadoop-200-2:46099, NodeHttpAddress: hadoop-200-2:8042, Resource: <memory:1024, vCores:1>, Priority: 20, State: NEW, Token: null, Status: container_id {, app_attempt_id {, application_id {, id: 7, cluster_timestamp: 1375845418464, }, attemptId: 1, }, id: 13, }, state: C_NEW, ] containerId=container_1375845418464_0007_01_000013 queue=default: capacity=1.0, absoluteCapacity=1.0, usedResources=<memory:48128, vCores:42>usedCapacity=0.9791667, absoluteUsedCapacity=0.9791667, numApps=5, numContainers=42 usedCapacity=0.9791667 absoluteUsedCapacity=0.9791667 used=<memory:48128, vCores:42> cluster=<memory:49152, vCores:96>
2013-08-07 03:28:48,037 INFO org.apache.hadoop.yarn.server.resourcemanager.scheduler.capacity.ParentQueue: Re-sorting queues since queue: root.default stats: default: capacity=1.0, absoluteCapacity=1.0, usedResources=<memory:49152, vCores:43>usedCapacity=1.0, absoluteUsedCapacity=1.0, numApps=5, numContainers=43
2013-08-07 03:28:48,037 INFO org.apache.hadoop.yarn.server.resourcemanager.scheduler.capacity.ParentQueue: assignedContainer queue=root usedCapacity=1.0 absoluteUsedCapacity=1.0 used=<memory:49152, vCores:43> cluster=<memory:49152, vCores:96>
2013-08-07 03:28:48,144 INFO org.apache.hadoop.yarn.server.resourcemanager.rmcontainer.RMContainerImpl: container_1375845418464_0007_01_000011 Container Transitioned from ALLOCATED to ACQUIRED
2013-08-07 03:28:48,146 INFO org.apache.hadoop.yarn.server.resourcemanager.rmcontainer.RMContainerImpl: container_1375845418464_0007_01_000012 Container Transitioned from ALLOCATED to ACQUIRED
2013-08-07 03:28:48,146 INFO org.apache.hadoop.yarn.server.resourcemanager.rmcontainer.RMContainerImpl: container_1375845418464_0007_01_000013 Container Transitioned from ALLOCATED to ACQUIRED
2013-08-07 03:28:48,259 INFO org.apache.hadoop.yarn.server.resourcemanager.rmcontainer.RMContainerImpl: container_1375845418464_0007_01_000011 Container Transitioned from ACQUIRED to RUNNING
2013-08-07 03:28:48,461 INFO org.apache.hadoop.yarn.server.resourcemanager.rmcontainer.RMContainerImpl: container_1375845418464_0007_01_000012 Container Transitioned from ACQUIRED to RUNNING
2013-08-07 03:28:48,461 INFO org.apache.hadoop.yarn.server.resourcemanager.rmcontainer.RMContainerImpl: container_1375845418464_0007_01_000013 Container Transitioned from ACQUIRED to RUNNING
2013-08-07 03:28:48,462 INFO org.apache.hadoop.yarn.server.resourcemanager.rmcontainer.RMContainerImpl: container_1375845418464_0006_01_000012 Container Transitioned from RUNNING to COMPLETED
2013-08-07 03:28:48,462 INFO org.apache.hadoop.yarn.server.resourcemanager.scheduler.common.fica.FiCaSchedulerApp: Completed container: container_1375845418464_0006_01_000012 in state: COMPLETED event:FINISHED
2013-08-07 03:28:48,463 INFO org.apache.hadoop.yarn.server.resourcemanager.RMAuditLogger: USER=ubuntu	OPERATION=AM Released Container	TARGET=SchedulerApp	RESULT=SUCCESS	APPID=application_1375845418464_0006	CONTAINERID=container_1375845418464_0006_01_000012
2013-08-07 03:28:48,463 INFO org.apache.hadoop.yarn.server.resourcemanager.scheduler.common.fica.FiCaSchedulerNode: Released container container_1375845418464_0006_01_000012 of capacity <memory:1024, vCores:1> on host hadoop-200-2:46099, which currently has 6 containers, <memory:7168, vCores:6> used and <memory:1024, vCores:10> available, release resources=true
2013-08-07 03:28:48,463 INFO org.apache.hadoop.yarn.server.resourcemanager.scheduler.capacity.LeafQueue: default used=<memory:48128, vCores:42> numContainers=42 user=ubuntu user-resources=<memory:48128, vCores:42>
2013-08-07 03:28:48,464 INFO org.apache.hadoop.yarn.server.resourcemanager.scheduler.capacity.LeafQueue: completedContainer container=Container: [ContainerId: container_1375845418464_0006_01_000012, NodeId: hadoop-200-2:46099, NodeHttpAddress: hadoop-200-2:8042, Resource: <memory:1024, vCores:1>, Priority: 20, State: NEW, Token: null, Status: container_id {, app_attempt_id {, application_id {, id: 6, cluster_timestamp: 1375845418464, }, attemptId: 1, }, id: 12, }, state: C_COMPLETE, diagnostics: "", exit_status: 0, ] resource=<memory:1024, vCores:1> queue=default: capacity=1.0, absoluteCapacity=1.0, usedResources=<memory:48128, vCores:42>usedCapacity=0.9791667, absoluteUsedCapacity=0.9791667, numApps=5, numContainers=42 usedCapacity=0.9791667 absoluteUsedCapacity=0.9791667 used=<memory:48128, vCores:42> cluster=<memory:49152, vCores:96>
2013-08-07 03:28:48,464 INFO org.apache.hadoop.yarn.server.resourcemanager.scheduler.capacity.ParentQueue: completedContainer queue=root usedCapacity=0.9791667 absoluteUsedCapacity=0.9791667 used=<memory:48128, vCores:42> cluster=<memory:49152, vCores:96>
2013-08-07 03:28:48,464 INFO org.apache.hadoop.yarn.server.resourcemanager.scheduler.capacity.CapacityScheduler: Application appattempt_1375845418464_0006_000001 released container container_1375845418464_0006_01_000012 on node: host: hadoop-200-2:46099 #containers=6 available=1024 used=7168 with event: FINISHED
2013-08-07 03:28:48,465 INFO org.apache.hadoop.yarn.server.resourcemanager.rmcontainer.RMContainerImpl: container_1375845418464_0007_01_000014 Container Transitioned from NEW to ALLOCATED
2013-08-07 03:28:48,465 INFO org.apache.hadoop.yarn.server.resourcemanager.RMAuditLogger: USER=ubuntu	OPERATION=AM Allocated Container	TARGET=SchedulerApp	RESULT=SUCCESS	APPID=application_1375845418464_0007	CONTAINERID=container_1375845418464_0007_01_000014
2013-08-07 03:28:48,465 INFO org.apache.hadoop.yarn.server.resourcemanager.scheduler.common.fica.FiCaSchedulerNode: Assigned container container_1375845418464_0007_01_000014 of capacity <memory:1024, vCores:1> on host hadoop-200-2:46099, which currently has 7 containers, <memory:8192, vCores:7> used and <memory:0, vCores:9> available
