2013-08-10 17:55:10,858 INFO org.apache.hadoop.yarn.server.resourcemanager.ResourceManager: STARTUP_MSG: 
/************************************************************
STARTUP_MSG: Starting ResourceManager
STARTUP_MSG:   host = hadoop-221-1/192.168.100.24
STARTUP_MSG:   args = []
STARTUP_MSG:   version = 3.0.0-SNAPSHOT
STARTUP_MSG:   build = https://github.com/lalithsuresh/hadoop-common -r 0cb423bd4868928bb06cd93f882bb0913172fd17; compiled by 'lsuresh' on 2013-04-08T15:47Z
STARTUP_MSG:   java = 1.7.0_17
************************************************************/
2013-08-10 17:55:10,872 INFO org.apache.hadoop.yarn.server.resourcemanager.ResourceManager: registered UNIX signal handlers for [TERM, HUP, INT]
2013-08-10 17:55:11,565 INFO org.apache.hadoop.yarn.server.resourcemanager.security.ApplicationTokenSecretManager: Rolling master-key for application-tokens
2013-08-10 17:55:11,582 INFO org.apache.hadoop.yarn.server.resourcemanager.security.RMContainerTokenSecretManager: ContainerTokenKeyRollingInterval: 86400000ms and ContainerTokenKeyActivationDelay: 900000ms
2013-08-10 17:55:11,584 INFO org.apache.hadoop.yarn.service.AbstractService: Service:Dispatcher is inited.
2013-08-10 17:55:11,586 INFO org.apache.hadoop.yarn.event.AsyncDispatcher: Registering class org.apache.hadoop.yarn.server.resourcemanager.recovery.RMStateStoreEventType for class org.apache.hadoop.yarn.server.resourcemanager.recovery.RMStateStore$ForwardingEventHandler
2013-08-10 17:55:11,586 INFO org.apache.hadoop.yarn.service.AbstractService: Service:Dispatcher is started.
2013-08-10 17:55:11,591 INFO org.apache.hadoop.yarn.event.AsyncDispatcher: Registering class org.apache.hadoop.yarn.server.resourcemanager.NodesListManagerEventType for class org.apache.hadoop.yarn.server.resourcemanager.NodesListManager
2013-08-10 17:55:11,591 INFO org.apache.hadoop.yarn.server.resourcemanager.ResourceManager: Using Scheduler: org.apache.hadoop.yarn.server.resourcemanager.scheduler.capacity.CapacityScheduler
2013-08-10 17:55:11,750 INFO org.apache.hadoop.yarn.event.AsyncDispatcher: Registering class org.apache.hadoop.yarn.server.resourcemanager.scheduler.event.SchedulerEventType for class org.apache.hadoop.yarn.server.resourcemanager.ResourceManager$SchedulerEventDispatcher
2013-08-10 17:55:11,752 INFO org.apache.hadoop.yarn.event.AsyncDispatcher: Registering class org.apache.hadoop.yarn.server.resourcemanager.rmapp.RMAppEventType for class org.apache.hadoop.yarn.server.resourcemanager.ResourceManager$ApplicationEventDispatcher
2013-08-10 17:55:11,753 INFO org.apache.hadoop.yarn.event.AsyncDispatcher: Registering class org.apache.hadoop.yarn.server.resourcemanager.rmapp.attempt.RMAppAttemptEventType for class org.apache.hadoop.yarn.server.resourcemanager.ResourceManager$ApplicationAttemptEventDispatcher
2013-08-10 17:55:11,755 INFO org.apache.hadoop.yarn.event.AsyncDispatcher: Registering class org.apache.hadoop.yarn.server.resourcemanager.rmnode.RMNodeEventType for class org.apache.hadoop.yarn.server.resourcemanager.ResourceManager$NodeEventDispatcher
2013-08-10 17:55:12,346 WARN org.apache.hadoop.util.NativeCodeLoader: Unable to load native-hadoop library for your platform... using builtin-java classes where applicable
2013-08-10 17:55:12,389 INFO org.apache.hadoop.yarn.server.resourcemanager.scheduler.capacity.ParentQueue: root, capacity=1.0, asboluteCapacity=1.0, maxCapacity=1.0, asboluteMaxCapacity=1.0, state=RUNNING, acls=SUBMIT_APPLICATIONS:*ADMINISTER_QUEUE:*
2013-08-10 17:55:12,389 INFO org.apache.hadoop.yarn.server.resourcemanager.scheduler.capacity.ParentQueue: Initialized parent-queue root name=root, fullname=root
2013-08-10 17:55:12,408 INFO org.apache.hadoop.yarn.server.resourcemanager.scheduler.capacity.LeafQueue: Initializing default
capacity = 1.0 [= (float) configuredCapacity / 100 ]
asboluteCapacity = 1.0 [= parentAbsoluteCapacity * capacity ]
maxCapacity = 1.0 [= configuredMaxCapacity ]
absoluteMaxCapacity = 1.0 [= 1.0 maximumCapacity undefined, (parentAbsoluteMaxCapacity * maximumCapacity) / 100 otherwise ]
userLimit = 100 [= configuredUserLimit ]
userLimitFactor = 1.0 [= configuredUserLimitFactor ]
maxApplications = 10000 [= configuredMaximumSystemApplicationsPerQueue or (int)(configuredMaximumSystemApplications * absoluteCapacity)]
maxApplicationsPerUser = 10000 [= (int)(maxApplications * (userLimit / 100.0f) * userLimitFactor) ]
maxActiveApplications = 1 [= max((int)ceil((clusterResourceMemory / minimumAllocation) * maxAMResourcePerQueuePercent * absoluteMaxCapacity),1) ]
maxActiveAppsUsingAbsCap = 1 [= max((int)ceil((clusterResourceMemory / minimumAllocation) *maxAMResourcePercent * absoluteCapacity),1) ]
maxActiveApplicationsPerUser = 1 [= max((int)(maxActiveApplications * (userLimit / 100.0f) * userLimitFactor),1) ]
usedCapacity = 0.0 [= usedResourcesMemory / (clusterResourceMemory * absoluteCapacity)]
absoluteUsedCapacity = 0.0 [= usedResourcesMemory / clusterResourceMemory]
maxAMResourcePerQueuePercent = 0.1 [= configuredMaximumAMResourcePercent ]
minimumAllocationFactor = 0.875 [= (float)(maximumAllocationMemory - minimumAllocationMemory) / maximumAllocationMemory ]
numContainers = 0 [= currentNumContainers ]
state = RUNNING [= configuredState ]
acls = SUBMIT_APPLICATIONS:*ADMINISTER_QUEUE:* [= configuredAcls ]

2013-08-10 17:55:12,408 INFO org.apache.hadoop.yarn.server.resourcemanager.scheduler.capacity.CapacityScheduler: Initialized queue: default: capacity=1.0, absoluteCapacity=1.0, usedResources=<memory:0, vCores:0>usedCapacity=0.0, absoluteUsedCapacity=0.0, numApps=0, numContainers=0
2013-08-10 17:55:12,409 INFO org.apache.hadoop.yarn.server.resourcemanager.scheduler.capacity.CapacityScheduler: Initialized queue: root: numChildQueue= 1, capacity=1.0, absoluteCapacity=1.0, usedResources=<memory:0, vCores:0>usedCapacity=0.0, numApps=0, numContainers=0
2013-08-10 17:55:12,409 INFO org.apache.hadoop.yarn.server.resourcemanager.scheduler.capacity.CapacityScheduler: Initialized root queue root: numChildQueue= 1, capacity=1.0, absoluteCapacity=1.0, usedResources=<memory:0, vCores:0>usedCapacity=0.0, numApps=0, numContainers=0
2013-08-10 17:55:12,409 INFO org.apache.hadoop.yarn.server.resourcemanager.scheduler.capacity.CapacityScheduler: Initialized CapacityScheduler with calculator=class org.apache.hadoop.yarn.server.resourcemanager.resource.DefaultResourceCalculator, minimumAllocation=<<memory:1024, vCores:1>>, maximumAllocation=<<memory:8192, vCores:32>>
2013-08-10 17:55:12,831 INFO org.apache.hadoop.yarn.event.AsyncDispatcher: Registering class org.apache.hadoop.yarn.server.resourcemanager.RMAppManagerEventType for class org.apache.hadoop.yarn.server.resourcemanager.RMAppManager
2013-08-10 17:55:12,850 INFO org.apache.hadoop.yarn.event.AsyncDispatcher: Registering class org.apache.hadoop.yarn.server.resourcemanager.amlauncher.AMLauncherEventType for class org.apache.hadoop.yarn.server.resourcemanager.amlauncher.ApplicationMasterLauncher
2013-08-10 17:55:12,933 INFO org.apache.hadoop.yarn.server.resourcemanager.RMNMInfo: Registered RMNMInfo MBean
2013-08-10 17:55:12,933 INFO org.apache.hadoop.yarn.service.AbstractService: Service:Dispatcher is inited.
2013-08-10 17:55:12,933 INFO org.apache.hadoop.yarn.service.AbstractService: Service:org.apache.hadoop.yarn.server.resourcemanager.rmcontainer.ContainerAllocationExpirer is inited.
2013-08-10 17:55:12,933 INFO org.apache.hadoop.yarn.service.AbstractService: Service:AMLivelinessMonitor is inited.
2013-08-10 17:55:12,933 INFO org.apache.hadoop.yarn.service.AbstractService: Service:AMLivelinessMonitor is inited.
2013-08-10 17:55:12,933 INFO org.apache.hadoop.yarn.service.AbstractService: Service:org.apache.hadoop.yarn.server.resourcemanager.security.DelegationTokenRenewer is inited.
2013-08-10 17:55:12,935 INFO org.apache.hadoop.util.HostsFileReader: Refreshing hosts (include/exclude) list
2013-08-10 17:55:12,935 INFO org.apache.hadoop.yarn.service.AbstractService: Service:org.apache.hadoop.yarn.server.resourcemanager.NodesListManager is inited.
2013-08-10 17:55:12,935 INFO org.apache.hadoop.yarn.service.AbstractService: Service:org.apache.hadoop.yarn.server.resourcemanager.ResourceManager$SchedulerEventDispatcher is inited.
2013-08-10 17:55:12,935 INFO org.apache.hadoop.yarn.service.AbstractService: Service:NMLivelinessMonitor is inited.
2013-08-10 17:55:12,942 INFO org.apache.hadoop.yarn.service.AbstractService: Service:org.apache.hadoop.yarn.server.resourcemanager.ResourceTrackerService is inited.
2013-08-10 17:55:12,942 INFO org.apache.hadoop.yarn.service.AbstractService: Service:org.apache.hadoop.yarn.server.resourcemanager.ApplicationMasterService is inited.
2013-08-10 17:55:12,942 INFO org.apache.hadoop.yarn.service.AbstractService: Service:org.apache.hadoop.yarn.server.resourcemanager.ClientRMService is inited.
2013-08-10 17:55:12,942 INFO org.apache.hadoop.yarn.service.AbstractService: Service:org.apache.hadoop.yarn.server.resourcemanager.AdminService is inited.
2013-08-10 17:55:12,943 INFO org.apache.hadoop.yarn.service.AbstractService: Service:org.apache.hadoop.yarn.server.resourcemanager.amlauncher.ApplicationMasterLauncher is inited.
2013-08-10 17:55:12,943 INFO org.apache.hadoop.yarn.service.AbstractService: Service:ResourceManager is inited.
2013-08-10 17:55:12,943 INFO org.apache.hadoop.yarn.server.resourcemanager.security.RMContainerTokenSecretManager: Rolling master-key for container-tokens
2013-08-10 17:55:12,943 INFO org.apache.hadoop.yarn.server.resourcemanager.security.ApplicationTokenSecretManager: Rolling master-key for application-tokens
2013-08-10 17:55:13,087 INFO org.mortbay.log: Logging to org.slf4j.impl.Log4jLoggerAdapter(org.mortbay.log) via org.mortbay.log.Slf4jLog
2013-08-10 17:55:13,191 INFO org.apache.hadoop.http.HttpServer: Added global filter 'safety' (class=org.apache.hadoop.http.HttpServer$QuotingInputFilter)
2013-08-10 17:55:13,196 INFO org.apache.hadoop.http.HttpServer: Added filter static_user_filter (class=org.apache.hadoop.http.lib.StaticUserWebFilter$StaticUserFilter) to context cluster
2013-08-10 17:55:13,196 INFO org.apache.hadoop.http.HttpServer: Added filter static_user_filter (class=org.apache.hadoop.http.lib.StaticUserWebFilter$StaticUserFilter) to context static
2013-08-10 17:55:13,196 INFO org.apache.hadoop.http.HttpServer: Added filter static_user_filter (class=org.apache.hadoop.http.lib.StaticUserWebFilter$StaticUserFilter) to context logs
2013-08-10 17:55:13,204 INFO org.apache.hadoop.http.HttpServer: adding path spec: /cluster
2013-08-10 17:55:13,204 INFO org.apache.hadoop.http.HttpServer: adding path spec: /cluster/*
2013-08-10 17:55:13,204 INFO org.apache.hadoop.http.HttpServer: adding path spec: /ws
2013-08-10 17:55:13,205 INFO org.apache.hadoop.http.HttpServer: adding path spec: /ws/*
2013-08-10 17:55:13,207 INFO org.apache.hadoop.http.HttpServer: Added global filter 'guice' (class=com.google.inject.servlet.GuiceFilter)
2013-08-10 17:55:13,217 INFO org.apache.hadoop.http.HttpServer: Jetty bound to port 8088
2013-08-10 17:55:13,218 INFO org.mortbay.log: jetty-6.1.26
2013-08-10 17:55:13,273 INFO org.mortbay.log: Extract jar:file:/home/ubuntu/hadoop-3.0.0-SNAPSHOT/share/hadoop/yarn/hadoop-yarn-common-3.0.0-SNAPSHOT.jar!/webapps/cluster to /tmp/Jetty_0_0_0_0_8088_cluster____u0rgz3/webapp
2013-08-10 17:55:13,779 INFO org.mortbay.log: Started SelectChannelConnector@0.0.0.0:8088
2013-08-10 17:55:13,779 INFO org.apache.hadoop.yarn.webapp.WebApps: Web app /cluster started at 8088
2013-08-10 17:55:14,655 INFO org.apache.hadoop.yarn.webapp.WebApps: Registered webapp guice modules
2013-08-10 17:55:14,760 INFO org.apache.hadoop.metrics2.impl.MetricsConfig: loaded properties from hadoop-metrics2.properties
2013-08-10 17:55:14,793 INFO org.apache.hadoop.metrics2.impl.MetricsSystemImpl: Scheduled snapshot period at 10 second(s).
2013-08-10 17:55:14,793 INFO org.apache.hadoop.metrics2.impl.MetricsSystemImpl: ResourceManager metrics system started
2013-08-10 17:55:14,809 INFO org.apache.hadoop.security.token.delegation.AbstractDelegationTokenSecretManager: Updating the current master key for generating delegation tokens
2013-08-10 17:55:14,813 INFO org.apache.hadoop.yarn.service.AbstractService: Service:Dispatcher is started.
2013-08-10 17:55:14,813 INFO org.apache.hadoop.security.token.delegation.AbstractDelegationTokenSecretManager: Starting expired delegation token remover thread, tokenRemoverScanInterval=60 min(s)
2013-08-10 17:55:14,813 INFO org.apache.hadoop.security.token.delegation.AbstractDelegationTokenSecretManager: Updating the current master key for generating delegation tokens
2013-08-10 17:55:14,815 INFO org.apache.hadoop.yarn.service.AbstractService: Service:org.apache.hadoop.yarn.server.resourcemanager.rmcontainer.ContainerAllocationExpirer is started.
2013-08-10 17:55:14,816 INFO org.apache.hadoop.yarn.service.AbstractService: Service:AMLivelinessMonitor is started.
2013-08-10 17:55:14,816 INFO org.apache.hadoop.yarn.service.AbstractService: Service:AMLivelinessMonitor is started.
2013-08-10 17:55:14,816 INFO org.apache.hadoop.yarn.service.AbstractService: Service:org.apache.hadoop.yarn.server.resourcemanager.security.DelegationTokenRenewer is started.
2013-08-10 17:55:14,817 INFO org.apache.hadoop.yarn.service.AbstractService: Service:org.apache.hadoop.yarn.server.resourcemanager.NodesListManager is started.
2013-08-10 17:55:14,818 INFO org.apache.hadoop.yarn.service.AbstractService: Service:org.apache.hadoop.yarn.server.resourcemanager.ResourceManager$SchedulerEventDispatcher is started.
2013-08-10 17:55:14,818 INFO org.apache.hadoop.yarn.service.AbstractService: Service:NMLivelinessMonitor is started.
2013-08-10 17:55:14,819 INFO org.apache.hadoop.yarn.service.AbstractService: Service:org.apache.hadoop.yarn.server.resourcemanager.ResourceTrackerService is started.
2013-08-10 17:55:14,889 INFO org.apache.hadoop.ipc.Server: Starting Socket Reader #1 for port 54110
2013-08-10 17:55:14,946 INFO org.apache.hadoop.yarn.factories.impl.pb.RpcServerFactoryPBImpl: Adding protocol org.apache.hadoop.yarn.server.api.ResourceTrackerPB to the server
2013-08-10 17:55:14,947 INFO org.apache.hadoop.ipc.Server: IPC Server Responder: starting
2013-08-10 17:55:14,949 INFO org.apache.hadoop.ipc.Server: IPC Server listener on 54110: starting
2013-08-10 17:55:15,093 INFO org.apache.hadoop.ipc.Server: Starting Socket Reader #1 for port 54112
2013-08-10 17:55:15,102 INFO org.apache.hadoop.yarn.factories.impl.pb.RpcServerFactoryPBImpl: Adding protocol org.apache.hadoop.yarn.api.AMRMProtocolPB to the server
2013-08-10 17:55:15,104 INFO org.apache.hadoop.ipc.Server: IPC Server listener on 54112: starting
2013-08-10 17:55:15,105 INFO org.apache.hadoop.ipc.Server: IPC Server Responder: starting
2013-08-10 17:55:15,134 INFO org.apache.hadoop.yarn.service.AbstractService: Service:org.apache.hadoop.yarn.server.resourcemanager.ApplicationMasterService is started.
2013-08-10 17:55:15,186 INFO org.apache.hadoop.ipc.Server: Starting Socket Reader #1 for port 54111
2013-08-10 17:55:15,192 INFO org.apache.hadoop.yarn.factories.impl.pb.RpcServerFactoryPBImpl: Adding protocol org.apache.hadoop.yarn.api.ClientRMProtocolPB to the server
2013-08-10 17:55:15,193 INFO org.apache.hadoop.ipc.Server: IPC Server Responder: starting
2013-08-10 17:55:15,201 INFO org.apache.hadoop.ipc.Server: IPC Server listener on 54111: starting
2013-08-10 17:55:15,244 INFO org.apache.hadoop.yarn.service.AbstractService: Service:org.apache.hadoop.yarn.server.resourcemanager.ClientRMService is started.
2013-08-10 17:55:15,290 INFO org.apache.hadoop.ipc.Server: Starting Socket Reader #1 for port 8033
2013-08-10 17:55:15,295 INFO org.apache.hadoop.yarn.factories.impl.pb.RpcServerFactoryPBImpl: Adding protocol org.apache.hadoop.yarn.api.RMAdminProtocolPB to the server
2013-08-10 17:55:15,296 INFO org.apache.hadoop.ipc.Server: IPC Server Responder: starting
2013-08-10 17:55:15,297 INFO org.apache.hadoop.ipc.Server: IPC Server listener on 8033: starting
2013-08-10 17:55:15,299 INFO org.apache.hadoop.yarn.service.AbstractService: Service:org.apache.hadoop.yarn.server.resourcemanager.AdminService is started.
2013-08-10 17:55:15,300 INFO org.apache.hadoop.yarn.service.AbstractService: Service:org.apache.hadoop.yarn.server.resourcemanager.amlauncher.ApplicationMasterLauncher is started.
2013-08-10 17:55:15,301 INFO org.apache.hadoop.yarn.service.AbstractService: Service:ResourceManager is started.
2013-08-10 17:55:25,317 INFO org.apache.hadoop.yarn.util.RackResolver: Resolved hadoop-221-6 to /default-rack
2013-08-10 17:55:25,320 INFO org.apache.hadoop.yarn.util.RackResolver: Resolved hadoop-221-4 to /default-rack
2013-08-10 17:55:25,321 INFO org.apache.hadoop.yarn.util.RackResolver: Resolved hadoop-221-2 to /default-rack
2013-08-10 17:55:25,321 INFO org.apache.hadoop.yarn.util.RackResolver: Resolved hadoop-221-7 to /default-rack
2013-08-10 17:55:25,323 INFO org.apache.hadoop.yarn.util.RackResolver: Resolved hadoop-221-5 to /default-rack
2013-08-10 17:55:25,334 INFO org.apache.hadoop.yarn.util.RackResolver: Resolved hadoop-221-3 to /default-rack
2013-08-10 17:55:25,336 INFO org.apache.hadoop.yarn.server.resourcemanager.ResourceTrackerService: NodeManager from node hadoop-221-7(cmPort: 56906 httpPort: 8042) registered with capability: <memory:8192, vCores:16>, assigned nodeId hadoop-221-7:56906
2013-08-10 17:55:25,336 INFO org.apache.hadoop.yarn.server.resourcemanager.ResourceTrackerService: NodeManager from node hadoop-221-5(cmPort: 56475 httpPort: 8042) registered with capability: <memory:8192, vCores:16>, assigned nodeId hadoop-221-5:56475
2013-08-10 17:55:25,336 INFO org.apache.hadoop.yarn.server.resourcemanager.ResourceTrackerService: NodeManager from node hadoop-221-2(cmPort: 56306 httpPort: 8042) registered with capability: <memory:8192, vCores:16>, assigned nodeId hadoop-221-2:56306
2013-08-10 17:55:25,336 INFO org.apache.hadoop.yarn.server.resourcemanager.ResourceTrackerService: NodeManager from node hadoop-221-4(cmPort: 33277 httpPort: 8042) registered with capability: <memory:8192, vCores:16>, assigned nodeId hadoop-221-4:33277
2013-08-10 17:55:25,356 INFO org.apache.hadoop.yarn.server.resourcemanager.ResourceTrackerService: NodeManager from node hadoop-221-6(cmPort: 39509 httpPort: 8042) registered with capability: <memory:8192, vCores:16>, assigned nodeId hadoop-221-6:39509
2013-08-10 17:55:25,337 INFO org.apache.hadoop.yarn.server.resourcemanager.ResourceTrackerService: NodeManager from node hadoop-221-3(cmPort: 38242 httpPort: 8042) registered with capability: <memory:8192, vCores:16>, assigned nodeId hadoop-221-3:38242
2013-08-10 17:55:25,363 INFO org.apache.hadoop.yarn.server.resourcemanager.rmnode.RMNodeImpl: hadoop-221-7:56906 Node Transitioned from NEW to RUNNING
2013-08-10 17:55:25,373 INFO org.apache.hadoop.yarn.server.resourcemanager.rmnode.RMNodeImpl: hadoop-221-5:56475 Node Transitioned from NEW to RUNNING
2013-08-10 17:55:25,374 INFO org.apache.hadoop.yarn.server.resourcemanager.rmnode.RMNodeImpl: hadoop-221-4:33277 Node Transitioned from NEW to RUNNING
2013-08-10 17:55:25,375 INFO org.apache.hadoop.yarn.server.resourcemanager.rmnode.RMNodeImpl: hadoop-221-2:56306 Node Transitioned from NEW to RUNNING
2013-08-10 17:55:25,375 INFO org.apache.hadoop.yarn.server.resourcemanager.rmnode.RMNodeImpl: hadoop-221-3:38242 Node Transitioned from NEW to RUNNING
2013-08-10 17:55:25,375 INFO org.apache.hadoop.yarn.server.resourcemanager.rmnode.RMNodeImpl: hadoop-221-6:39509 Node Transitioned from NEW to RUNNING
2013-08-10 17:55:25,384 INFO org.apache.hadoop.yarn.server.resourcemanager.scheduler.capacity.CapacityScheduler: Added node hadoop-221-7:56906 clusterResource: <memory:8192, vCores:16>
2013-08-10 17:55:25,384 INFO org.apache.hadoop.yarn.server.resourcemanager.scheduler.capacity.CapacityScheduler: Added node hadoop-221-5:56475 clusterResource: <memory:16384, vCores:32>
2013-08-10 17:55:25,384 INFO org.apache.hadoop.yarn.server.resourcemanager.scheduler.capacity.CapacityScheduler: Added node hadoop-221-4:33277 clusterResource: <memory:24576, vCores:48>
2013-08-10 17:55:25,385 INFO org.apache.hadoop.yarn.server.resourcemanager.scheduler.capacity.CapacityScheduler: Added node hadoop-221-2:56306 clusterResource: <memory:32768, vCores:64>
2013-08-10 17:55:25,385 INFO org.apache.hadoop.yarn.server.resourcemanager.scheduler.capacity.CapacityScheduler: Added node hadoop-221-3:38242 clusterResource: <memory:40960, vCores:80>
2013-08-10 17:55:25,385 INFO org.apache.hadoop.yarn.server.resourcemanager.scheduler.capacity.CapacityScheduler: Added node hadoop-221-6:39509 clusterResource: <memory:49152, vCores:96>
2013-08-10 17:55:31,760 INFO org.apache.hadoop.yarn.server.resourcemanager.ClientRMService: Allocated new applicationId: 1
2013-08-10 17:55:35,157 INFO org.apache.hadoop.yarn.server.resourcemanager.ClientRMService: Storing Application with id application_1376157310799_0001
2013-08-10 17:55:35,161 INFO org.apache.hadoop.yarn.server.resourcemanager.recovery.RMStateStore: Storing info for app: application_1376157310799_0001
2013-08-10 17:55:35,166 INFO org.apache.hadoop.yarn.server.resourcemanager.ClientRMService: Application with id 1 submitted by user ubuntu
2013-08-10 17:55:35,170 INFO org.apache.hadoop.yarn.server.resourcemanager.RMAuditLogger: USER=ubuntu	IP=192.168.100.24	OPERATION=Submit Application Request	TARGET=ClientRMService	RESULT=SUCCESS	APPID=application_1376157310799_0001
2013-08-10 17:55:35,215 INFO org.apache.hadoop.yarn.server.resourcemanager.rmapp.RMAppImpl: application_1376157310799_0001 State change from NEW to SUBMITTED
2013-08-10 17:55:35,216 INFO org.apache.hadoop.yarn.server.resourcemanager.ApplicationMasterService: Registering appattempt_1376157310799_0001_000001
2013-08-10 17:55:35,217 INFO org.apache.hadoop.yarn.server.resourcemanager.rmapp.attempt.RMAppAttemptImpl: appattempt_1376157310799_0001_000001 State change from NEW to SUBMITTED
2013-08-10 17:55:35,251 INFO org.apache.hadoop.yarn.server.resourcemanager.scheduler.capacity.LeafQueue: Application application_1376157310799_0001 from user: ubuntu activated in queue: default
2013-08-10 17:55:35,251 INFO org.apache.hadoop.yarn.server.resourcemanager.scheduler.capacity.LeafQueue: Application added - appId: application_1376157310799_0001 user: org.apache.hadoop.yarn.server.resourcemanager.scheduler.capacity.LeafQueue$User@1d4ef680, leaf-queue: default #user-pending-applications: 0 #user-active-applications: 1 #queue-pending-applications: 0 #queue-active-applications: 1
2013-08-10 17:55:35,251 INFO org.apache.hadoop.yarn.server.resourcemanager.scheduler.capacity.ParentQueue: Application added - appId: application_1376157310799_0001 user: ubuntu leaf-queue of parent: root #applications: 1
2013-08-10 17:55:35,252 INFO org.apache.hadoop.yarn.server.resourcemanager.scheduler.capacity.CapacityScheduler: Application Submission: appattempt_1376157310799_0001_000001, user: ubuntu queue: default: capacity=1.0, absoluteCapacity=1.0, usedResources=<memory:0, vCores:0>usedCapacity=0.0, absoluteUsedCapacity=0.0, numApps=1, numContainers=0, currently active: 1
2013-08-10 17:55:35,257 INFO org.apache.hadoop.yarn.server.resourcemanager.rmapp.attempt.RMAppAttemptImpl: appattempt_1376157310799_0001_000001 State change from SUBMITTED to SCHEDULED
2013-08-10 17:55:35,260 INFO org.apache.hadoop.yarn.server.resourcemanager.rmapp.RMAppImpl: application_1376157310799_0001 State change from SUBMITTED to ACCEPTED
2013-08-10 17:55:35,549 INFO org.apache.hadoop.yarn.server.resourcemanager.rmcontainer.RMContainerImpl: container_1376157310799_0001_01_000001 Container Transitioned from NEW to ALLOCATED
2013-08-10 17:55:35,549 INFO org.apache.hadoop.yarn.server.resourcemanager.RMAuditLogger: USER=ubuntu	OPERATION=AM Allocated Container	TARGET=SchedulerApp	RESULT=SUCCESS	APPID=application_1376157310799_0001	CONTAINERID=container_1376157310799_0001_01_000001
2013-08-10 17:55:35,550 INFO org.apache.hadoop.yarn.server.resourcemanager.scheduler.common.fica.FiCaSchedulerNode: Assigned container container_1376157310799_0001_01_000001 of capacity <memory:2048, vCores:1> on host hadoop-221-6:39509, which currently has 1 containers, <memory:2048, vCores:1> used and <memory:6144, vCores:15> available
2013-08-10 17:55:35,557 INFO org.apache.hadoop.yarn.server.resourcemanager.scheduler.capacity.LeafQueue: assignedContainer application=application_1376157310799_0001 container=Container: [ContainerId: container_1376157310799_0001_01_000001, NodeId: hadoop-221-6:39509, NodeHttpAddress: hadoop-221-6:8042, Resource: <memory:2048, vCores:1>, Priority: 0, State: NEW, Token: null, Status: container_id {, app_attempt_id {, application_id {, id: 1, cluster_timestamp: 1376157310799, }, attemptId: 1, }, id: 1, }, state: C_NEW, ] containerId=container_1376157310799_0001_01_000001 queue=default: capacity=1.0, absoluteCapacity=1.0, usedResources=<memory:0, vCores:0>usedCapacity=0.0, absoluteUsedCapacity=0.0, numApps=1, numContainers=0 usedCapacity=0.0 absoluteUsedCapacity=0.0 used=<memory:0, vCores:0> cluster=<memory:49152, vCores:96>
2013-08-10 17:55:35,558 INFO org.apache.hadoop.yarn.server.resourcemanager.scheduler.capacity.ParentQueue: Re-sorting queues since queue: root.default stats: default: capacity=1.0, absoluteCapacity=1.0, usedResources=<memory:2048, vCores:1>usedCapacity=0.041666668, absoluteUsedCapacity=0.041666668, numApps=1, numContainers=1
2013-08-10 17:55:35,560 INFO org.apache.hadoop.yarn.server.resourcemanager.rmcontainer.RMContainerImpl: container_1376157310799_0001_01_000001 Container Transitioned from ALLOCATED to ACQUIRED
2013-08-10 17:55:35,563 INFO org.apache.hadoop.yarn.server.resourcemanager.rmapp.attempt.RMAppAttemptImpl: Storing attempt: AppId: application_1376157310799_0001 AttemptId: appattempt_1376157310799_0001_000001 MasterContainer: Container: [ContainerId: container_1376157310799_0001_01_000001, NodeId: hadoop-221-6:39509, NodeHttpAddress: hadoop-221-6:8042, Resource: <memory:2048, vCores:1>, Priority: 0, State: NEW, Token: null, Status: container_id {, app_attempt_id {, application_id {, id: 1, cluster_timestamp: 1376157310799, }, attemptId: 1, }, id: 1, }, state: C_NEW, ]
2013-08-10 17:55:35,564 INFO org.apache.hadoop.yarn.server.resourcemanager.scheduler.capacity.ParentQueue: assignedContainer queue=root usedCapacity=0.041666668 absoluteUsedCapacity=0.041666668 used=<memory:2048, vCores:1> cluster=<memory:49152, vCores:96>
2013-08-10 17:55:35,566 INFO org.apache.hadoop.yarn.server.resourcemanager.rmapp.attempt.RMAppAttemptImpl: appattempt_1376157310799_0001_000001 State change from SCHEDULED to ALLOCATED_SAVING
2013-08-10 17:55:35,571 INFO org.apache.hadoop.yarn.server.resourcemanager.recovery.RMStateStore: Storing info for attempt: appattempt_1376157310799_0001_000001
2013-08-10 17:55:35,574 INFO org.apache.hadoop.yarn.server.resourcemanager.rmapp.attempt.RMAppAttemptImpl: appattempt_1376157310799_0001_000001 State change from ALLOCATED_SAVING to ALLOCATED
2013-08-10 17:55:35,581 INFO org.apache.hadoop.yarn.server.resourcemanager.amlauncher.AMLauncher: Launching masterappattempt_1376157310799_0001_000001
2013-08-10 17:55:35,626 INFO org.apache.hadoop.yarn.server.resourcemanager.amlauncher.AMLauncher: Setting up container Container: [ContainerId: container_1376157310799_0001_01_000001, NodeId: hadoop-221-6:39509, NodeHttpAddress: hadoop-221-6:8042, Resource: <memory:2048, vCores:1>, Priority: 0, State: NEW, Token: null, Status: container_id {, app_attempt_id {, application_id {, id: 1, cluster_timestamp: 1376157310799, }, attemptId: 1, }, id: 1, }, state: C_NEW, ] for AM appattempt_1376157310799_0001_000001
2013-08-10 17:55:35,627 INFO org.apache.hadoop.yarn.server.resourcemanager.amlauncher.AMLauncher: Command to launch container container_1376157310799_0001_01_000001 : $JAVA_HOME/bin/java -Dlog4j.configuration=container-log4j.properties -Dyarn.app.mapreduce.container.log.dir=<LOG_DIR> -Dyarn.app.mapreduce.container.log.filesize=0 -Dhadoop.root.logger=INFO,CLA  -Xmx1024m org.apache.hadoop.mapreduce.v2.app.MRAppMaster 1><LOG_DIR>/stdout 2><LOG_DIR>/stderr 
2013-08-10 17:55:36,553 INFO org.apache.hadoop.yarn.server.resourcemanager.rmcontainer.RMContainerImpl: container_1376157310799_0001_01_000001 Container Transitioned from ACQUIRED to RUNNING
2013-08-10 17:55:36,563 INFO org.apache.hadoop.yarn.server.resourcemanager.amlauncher.AMLauncher: Done launching container Container: [ContainerId: container_1376157310799_0001_01_000001, NodeId: hadoop-221-6:39509, NodeHttpAddress: hadoop-221-6:8042, Resource: <memory:2048, vCores:1>, Priority: 0, State: NEW, Token: null, Status: container_id {, app_attempt_id {, application_id {, id: 1, cluster_timestamp: 1376157310799, }, attemptId: 1, }, id: 1, }, state: C_NEW, ] for AM appattempt_1376157310799_0001_000001
2013-08-10 17:55:36,564 INFO org.apache.hadoop.yarn.server.resourcemanager.rmapp.attempt.RMAppAttemptImpl: appattempt_1376157310799_0001_000001 State change from ALLOCATED to LAUNCHED
2013-08-10 17:55:45,093 INFO org.apache.hadoop.yarn.server.resourcemanager.ApplicationMasterService: AM registration appattempt_1376157310799_0001_000001
2013-08-10 17:55:45,101 INFO org.apache.hadoop.yarn.server.resourcemanager.RMAuditLogger: USER=ubuntu	IP=192.168.100.35	OPERATION=Register App Master	TARGET=ApplicationMasterService	RESULT=SUCCESS	APPID=application_1376157310799_0001	APPATTEMPTID=appattempt_1376157310799_0001_000001
2013-08-10 17:55:45,105 INFO org.apache.hadoop.yarn.server.resourcemanager.rmapp.attempt.RMAppAttemptImpl: appattempt_1376157310799_0001_000001 State change from LAUNCHED to RUNNING
2013-08-10 17:55:45,106 INFO org.apache.hadoop.yarn.server.resourcemanager.rmapp.RMAppImpl: application_1376157310799_0001 State change from ACCEPTED to RUNNING
2013-08-10 17:55:46,566 INFO org.apache.hadoop.yarn.server.resourcemanager.rmcontainer.RMContainerImpl: container_1376157310799_0001_01_000002 Container Transitioned from NEW to ALLOCATED
2013-08-10 17:55:46,566 INFO org.apache.hadoop.yarn.server.resourcemanager.RMAuditLogger: USER=ubuntu	OPERATION=AM Allocated Container	TARGET=SchedulerApp	RESULT=SUCCESS	APPID=application_1376157310799_0001	CONTAINERID=container_1376157310799_0001_01_000002
2013-08-10 17:55:46,566 INFO org.apache.hadoop.yarn.server.resourcemanager.scheduler.common.fica.FiCaSchedulerNode: Assigned container container_1376157310799_0001_01_000002 of capacity <memory:1024, vCores:1> on host hadoop-221-7:56906, which currently has 1 containers, <memory:1024, vCores:1> used and <memory:7168, vCores:15> available
2013-08-10 17:55:46,568 INFO org.apache.hadoop.yarn.server.resourcemanager.scheduler.capacity.LeafQueue: assignedContainer application=application_1376157310799_0001 container=Container: [ContainerId: container_1376157310799_0001_01_000002, NodeId: hadoop-221-7:56906, NodeHttpAddress: hadoop-221-7:8042, Resource: <memory:1024, vCores:1>, Priority: 20, State: NEW, Token: null, Status: container_id {, app_attempt_id {, application_id {, id: 1, cluster_timestamp: 1376157310799, }, attemptId: 1, }, id: 2, }, state: C_NEW, ] containerId=container_1376157310799_0001_01_000002 queue=default: capacity=1.0, absoluteCapacity=1.0, usedResources=<memory:2048, vCores:1>usedCapacity=0.041666668, absoluteUsedCapacity=0.041666668, numApps=1, numContainers=1 usedCapacity=0.041666668 absoluteUsedCapacity=0.041666668 used=<memory:2048, vCores:1> cluster=<memory:49152, vCores:96>
2013-08-10 17:55:46,569 INFO org.apache.hadoop.yarn.server.resourcemanager.scheduler.capacity.ParentQueue: Re-sorting queues since queue: root.default stats: default: capacity=1.0, absoluteCapacity=1.0, usedResources=<memory:3072, vCores:2>usedCapacity=0.0625, absoluteUsedCapacity=0.0625, numApps=1, numContainers=2
2013-08-10 17:55:46,569 INFO org.apache.hadoop.yarn.server.resourcemanager.scheduler.capacity.ParentQueue: assignedContainer queue=root usedCapacity=0.0625 absoluteUsedCapacity=0.0625 used=<memory:3072, vCores:2> cluster=<memory:49152, vCores:96>
2013-08-10 17:55:46,571 INFO org.apache.hadoop.yarn.server.resourcemanager.rmcontainer.RMContainerImpl: container_1376157310799_0001_01_000003 Container Transitioned from NEW to ALLOCATED
2013-08-10 17:55:46,571 INFO org.apache.hadoop.yarn.server.resourcemanager.RMAuditLogger: USER=ubuntu	OPERATION=AM Allocated Container	TARGET=SchedulerApp	RESULT=SUCCESS	APPID=application_1376157310799_0001	CONTAINERID=container_1376157310799_0001_01_000003
2013-08-10 17:55:46,571 INFO org.apache.hadoop.yarn.server.resourcemanager.scheduler.common.fica.FiCaSchedulerNode: Assigned container container_1376157310799_0001_01_000003 of capacity <memory:1024, vCores:1> on host hadoop-221-5:56475, which currently has 1 containers, <memory:1024, vCores:1> used and <memory:7168, vCores:15> available
2013-08-10 17:55:46,573 INFO org.apache.hadoop.yarn.server.resourcemanager.scheduler.capacity.LeafQueue: assignedContainer application=application_1376157310799_0001 container=Container: [ContainerId: container_1376157310799_0001_01_000003, NodeId: hadoop-221-5:56475, NodeHttpAddress: hadoop-221-5:8042, Resource: <memory:1024, vCores:1>, Priority: 20, State: NEW, Token: null, Status: container_id {, app_attempt_id {, application_id {, id: 1, cluster_timestamp: 1376157310799, }, attemptId: 1, }, id: 3, }, state: C_NEW, ] containerId=container_1376157310799_0001_01_000003 queue=default: capacity=1.0, absoluteCapacity=1.0, usedResources=<memory:3072, vCores:2>usedCapacity=0.0625, absoluteUsedCapacity=0.0625, numApps=1, numContainers=2 usedCapacity=0.0625 absoluteUsedCapacity=0.0625 used=<memory:3072, vCores:2> cluster=<memory:49152, vCores:96>
2013-08-10 17:55:46,573 INFO org.apache.hadoop.yarn.server.resourcemanager.scheduler.capacity.ParentQueue: Re-sorting queues since queue: root.default stats: default: capacity=1.0, absoluteCapacity=1.0, usedResources=<memory:4096, vCores:3>usedCapacity=0.083333336, absoluteUsedCapacity=0.083333336, numApps=1, numContainers=3
2013-08-10 17:55:46,573 INFO org.apache.hadoop.yarn.server.resourcemanager.scheduler.capacity.ParentQueue: assignedContainer queue=root usedCapacity=0.083333336 absoluteUsedCapacity=0.083333336 used=<memory:4096, vCores:3> cluster=<memory:49152, vCores:96>
2013-08-10 17:55:47,182 INFO org.apache.hadoop.yarn.server.resourcemanager.rmcontainer.RMContainerImpl: container_1376157310799_0001_01_000002 Container Transitioned from ALLOCATED to ACQUIRED
2013-08-10 17:55:47,184 INFO org.apache.hadoop.yarn.server.resourcemanager.rmcontainer.RMContainerImpl: container_1376157310799_0001_01_000003 Container Transitioned from ALLOCATED to ACQUIRED
2013-08-10 17:55:48,220 INFO org.apache.hadoop.yarn.server.resourcemanager.scheduler.AppSchedulingInfo: checking for deactivate... 
2013-08-10 17:55:48,594 INFO org.apache.hadoop.yarn.server.resourcemanager.rmcontainer.RMContainerImpl: container_1376157310799_0001_01_000002 Container Transitioned from ACQUIRED to RUNNING
2013-08-10 17:55:48,602 INFO org.apache.hadoop.yarn.server.resourcemanager.rmcontainer.RMContainerImpl: container_1376157310799_0001_01_000003 Container Transitioned from ACQUIRED to RUNNING
2013-08-10 17:58:44,085 INFO org.apache.hadoop.yarn.server.resourcemanager.rmcontainer.RMContainerImpl: container_1376157310799_0001_01_000003 Container Transitioned from RUNNING to COMPLETED
2013-08-10 17:58:44,085 INFO org.apache.hadoop.yarn.server.resourcemanager.scheduler.common.fica.FiCaSchedulerApp: Completed container: container_1376157310799_0001_01_000003 in state: COMPLETED event:FINISHED
2013-08-10 17:58:44,085 INFO org.apache.hadoop.yarn.server.resourcemanager.RMAuditLogger: USER=ubuntu	OPERATION=AM Released Container	TARGET=SchedulerApp	RESULT=SUCCESS	APPID=application_1376157310799_0001	CONTAINERID=container_1376157310799_0001_01_000003
2013-08-10 17:58:44,086 INFO org.apache.hadoop.yarn.server.resourcemanager.scheduler.common.fica.FiCaSchedulerNode: Released container container_1376157310799_0001_01_000003 of capacity <memory:1024, vCores:1> on host hadoop-221-5:56475, which currently has 0 containers, <memory:0, vCores:0> used and <memory:8192, vCores:16> available, release resources=true
2013-08-10 17:58:44,086 INFO org.apache.hadoop.yarn.server.resourcemanager.scheduler.capacity.LeafQueue: default used=<memory:3072, vCores:2> numContainers=2 user=ubuntu user-resources=<memory:3072, vCores:2>
2013-08-10 17:58:44,088 INFO org.apache.hadoop.yarn.server.resourcemanager.scheduler.capacity.LeafQueue: completedContainer container=Container: [ContainerId: container_1376157310799_0001_01_000003, NodeId: hadoop-221-5:56475, NodeHttpAddress: hadoop-221-5:8042, Resource: <memory:1024, vCores:1>, Priority: 20, State: NEW, Token: null, Status: container_id {, app_attempt_id {, application_id {, id: 1, cluster_timestamp: 1376157310799, }, attemptId: 1, }, id: 3, }, state: C_COMPLETE, diagnostics: "Container killed by the ApplicationMaster.\n\n", exit_status: 143, ] resource=<memory:1024, vCores:1> queue=default: capacity=1.0, absoluteCapacity=1.0, usedResources=<memory:3072, vCores:2>usedCapacity=0.0625, absoluteUsedCapacity=0.0625, numApps=1, numContainers=2 usedCapacity=0.0625 absoluteUsedCapacity=0.0625 used=<memory:3072, vCores:2> cluster=<memory:49152, vCores:96>
2013-08-10 17:58:44,089 INFO org.apache.hadoop.yarn.server.resourcemanager.scheduler.capacity.ParentQueue: completedContainer queue=root usedCapacity=0.0625 absoluteUsedCapacity=0.0625 used=<memory:3072, vCores:2> cluster=<memory:49152, vCores:96>
2013-08-10 17:58:44,089 INFO org.apache.hadoop.yarn.server.resourcemanager.scheduler.capacity.CapacityScheduler: Application appattempt_1376157310799_0001_000001 released container container_1376157310799_0001_01_000003 on node: host: hadoop-221-5:56475 #containers=0 available=8192 used=0 with event: FINISHED
2013-08-10 17:58:47,348 INFO org.apache.hadoop.yarn.server.resourcemanager.rmcontainer.RMContainerImpl: container_1376157310799_0001_01_000002 Container Transitioned from RUNNING to COMPLETED
2013-08-10 17:58:47,349 INFO org.apache.hadoop.yarn.server.resourcemanager.scheduler.common.fica.FiCaSchedulerApp: Completed container: container_1376157310799_0001_01_000002 in state: COMPLETED event:FINISHED
2013-08-10 17:58:47,349 INFO org.apache.hadoop.yarn.server.resourcemanager.RMAuditLogger: USER=ubuntu	OPERATION=AM Released Container	TARGET=SchedulerApp	RESULT=SUCCESS	APPID=application_1376157310799_0001	CONTAINERID=container_1376157310799_0001_01_000002
2013-08-10 17:58:47,349 INFO org.apache.hadoop.yarn.server.resourcemanager.scheduler.common.fica.FiCaSchedulerNode: Released container container_1376157310799_0001_01_000002 of capacity <memory:1024, vCores:1> on host hadoop-221-7:56906, which currently has 0 containers, <memory:0, vCores:0> used and <memory:8192, vCores:16> available, release resources=true
2013-08-10 17:58:47,349 INFO org.apache.hadoop.yarn.server.resourcemanager.scheduler.capacity.LeafQueue: default used=<memory:2048, vCores:1> numContainers=1 user=ubuntu user-resources=<memory:2048, vCores:1>
2013-08-10 17:58:47,351 INFO org.apache.hadoop.yarn.server.resourcemanager.scheduler.capacity.LeafQueue: completedContainer container=Container: [ContainerId: container_1376157310799_0001_01_000002, NodeId: hadoop-221-7:56906, NodeHttpAddress: hadoop-221-7:8042, Resource: <memory:1024, vCores:1>, Priority: 20, State: NEW, Token: null, Status: container_id {, app_attempt_id {, application_id {, id: 1, cluster_timestamp: 1376157310799, }, attemptId: 1, }, id: 2, }, state: C_COMPLETE, diagnostics: "Container killed by the ApplicationMaster.\n\n", exit_status: 143, ] resource=<memory:1024, vCores:1> queue=default: capacity=1.0, absoluteCapacity=1.0, usedResources=<memory:2048, vCores:1>usedCapacity=0.041666668, absoluteUsedCapacity=0.041666668, numApps=1, numContainers=1 usedCapacity=0.041666668 absoluteUsedCapacity=0.041666668 used=<memory:2048, vCores:1> cluster=<memory:49152, vCores:96>
2013-08-10 17:58:47,352 INFO org.apache.hadoop.yarn.server.resourcemanager.scheduler.capacity.ParentQueue: completedContainer queue=root usedCapacity=0.041666668 absoluteUsedCapacity=0.041666668 used=<memory:2048, vCores:1> cluster=<memory:49152, vCores:96>
2013-08-10 17:58:47,352 INFO org.apache.hadoop.yarn.server.resourcemanager.scheduler.capacity.CapacityScheduler: Application appattempt_1376157310799_0001_000001 released container container_1376157310799_0001_01_000002 on node: host: hadoop-221-7:56906 #containers=0 available=8192 used=0 with event: FINISHED
2013-08-10 17:58:51,509 INFO org.apache.hadoop.yarn.server.resourcemanager.rmapp.attempt.RMAppAttemptImpl: appattempt_1376157310799_0001_000001 State change from RUNNING to FINISHING
2013-08-10 17:58:51,517 INFO org.apache.hadoop.yarn.server.resourcemanager.rmapp.RMAppImpl: application_1376157310799_0001 State change from RUNNING to FINISHING
2013-08-10 17:58:51,914 INFO org.apache.hadoop.yarn.server.resourcemanager.rmcontainer.RMContainerImpl: container_1376157310799_0001_01_000001 Container Transitioned from RUNNING to COMPLETED
2013-08-10 17:58:51,914 INFO org.apache.hadoop.yarn.server.resourcemanager.scheduler.common.fica.FiCaSchedulerApp: Completed container: container_1376157310799_0001_01_000001 in state: COMPLETED event:FINISHED
2013-08-10 17:58:51,914 INFO org.apache.hadoop.yarn.server.resourcemanager.RMAuditLogger: USER=ubuntu	OPERATION=AM Released Container	TARGET=SchedulerApp	RESULT=SUCCESS	APPID=application_1376157310799_0001	CONTAINERID=container_1376157310799_0001_01_000001
2013-08-10 17:58:51,914 INFO org.apache.hadoop.yarn.server.resourcemanager.scheduler.common.fica.FiCaSchedulerNode: Released container container_1376157310799_0001_01_000001 of capacity <memory:2048, vCores:1> on host hadoop-221-6:39509, which currently has 0 containers, <memory:0, vCores:0> used and <memory:8192, vCores:16> available, release resources=true
2013-08-10 17:58:51,914 INFO org.apache.hadoop.yarn.server.resourcemanager.scheduler.capacity.LeafQueue: default used=<memory:0, vCores:0> numContainers=0 user=ubuntu user-resources=<memory:0, vCores:0>
2013-08-10 17:58:51,915 INFO org.apache.hadoop.yarn.server.resourcemanager.scheduler.capacity.LeafQueue: completedContainer container=Container: [ContainerId: container_1376157310799_0001_01_000001, NodeId: hadoop-221-6:39509, NodeHttpAddress: hadoop-221-6:8042, Resource: <memory:2048, vCores:1>, Priority: 0, State: NEW, Token: null, Status: container_id {, app_attempt_id {, application_id {, id: 1, cluster_timestamp: 1376157310799, }, attemptId: 1, }, id: 1, }, state: C_COMPLETE, diagnostics: "", exit_status: 0, ] resource=<memory:2048, vCores:1> queue=default: capacity=1.0, absoluteCapacity=1.0, usedResources=<memory:0, vCores:0>usedCapacity=0.0, absoluteUsedCapacity=0.0, numApps=1, numContainers=0 usedCapacity=0.0 absoluteUsedCapacity=0.0 used=<memory:0, vCores:0> cluster=<memory:49152, vCores:96>
2013-08-10 17:58:51,915 INFO org.apache.hadoop.yarn.server.resourcemanager.scheduler.capacity.ParentQueue: completedContainer queue=root usedCapacity=0.0 absoluteUsedCapacity=0.0 used=<memory:0, vCores:0> cluster=<memory:49152, vCores:96>
2013-08-10 17:58:51,915 INFO org.apache.hadoop.yarn.server.resourcemanager.scheduler.capacity.CapacityScheduler: Application appattempt_1376157310799_0001_000001 released container container_1376157310799_0001_01_000001 on node: host: hadoop-221-6:39509 #containers=0 available=8192 used=0 with event: FINISHED
2013-08-10 17:58:51,917 INFO org.apache.hadoop.yarn.server.resourcemanager.rmapp.attempt.RMAppAttemptImpl: appattempt_1376157310799_0001_000001 State change from FINISHING to FINISHED
2013-08-10 17:58:51,918 INFO org.apache.hadoop.yarn.server.resourcemanager.rmapp.RMAppImpl: application_1376157310799_0001 State change from FINISHING to FINISHED
2013-08-10 17:58:51,918 INFO org.apache.hadoop.yarn.server.resourcemanager.scheduler.capacity.CapacityScheduler: Application appattempt_1376157310799_0001_000001 is done. finalState=FINISHED
2013-08-10 17:58:51,919 INFO org.apache.hadoop.yarn.server.resourcemanager.scheduler.AppSchedulingInfo: Application application_1376157310799_0001 requests cleared
2013-08-10 17:58:51,919 INFO org.apache.hadoop.yarn.server.resourcemanager.scheduler.capacity.LeafQueue: Application removed - appId: application_1376157310799_0001 user: ubuntu queue: default #user-pending-applications: 0 #user-active-applications: 0 #queue-pending-applications: 0 #queue-active-applications: 0
2013-08-10 17:58:51,919 INFO org.apache.hadoop.yarn.server.resourcemanager.scheduler.capacity.ParentQueue: Application removed - appId: application_1376157310799_0001 user: ubuntu leaf-queue of parent: root #applications: 0
2013-08-10 17:58:51,919 INFO org.apache.hadoop.yarn.server.resourcemanager.RMAuditLogger: USER=ubuntu	OPERATION=Application Finished - Succeeded	TARGET=RMAppManager	RESULT=SUCCESS	APPID=application_1376157310799_0001
2013-08-10 17:58:51,920 INFO org.apache.hadoop.yarn.server.resourcemanager.amlauncher.AMLauncher: Cleaning master appattempt_1376157310799_0001_000001
2013-08-10 17:58:51,921 INFO org.apache.hadoop.yarn.server.resourcemanager.recovery.RMStateStore: Removing info for app: application_1376157310799_0001
2013-08-10 17:58:51,925 INFO org.apache.hadoop.yarn.server.resourcemanager.RMAppManager$ApplicationSummary: appId=application_1376157310799_0001,name=TeraGen,user=ubuntu,queue=default,state=FINISHED,trackingUrl=hadoop-221-1.novalocal:8088/proxy/application_1376157310799_0001/jobhistory/job/job_1376157310799_0001,appMasterHost=hadoop-221-6,startTime=1376157335150,finishTime=1376157531517
2013-08-10 17:59:03,585 INFO org.apache.hadoop.yarn.server.resourcemanager.ClientRMService: Allocated new applicationId: 2
2013-08-10 17:59:05,474 INFO org.apache.hadoop.yarn.server.resourcemanager.ClientRMService: Storing Application with id application_1376157310799_0002
2013-08-10 17:59:05,475 INFO org.apache.hadoop.yarn.server.resourcemanager.recovery.RMStateStore: Storing info for app: application_1376157310799_0002
2013-08-10 17:59:05,475 INFO org.apache.hadoop.yarn.server.resourcemanager.ClientRMService: Application with id 2 submitted by user ubuntu
2013-08-10 17:59:05,475 INFO org.apache.hadoop.yarn.server.resourcemanager.RMAuditLogger: USER=ubuntu	IP=192.168.100.24	OPERATION=Submit Application Request	TARGET=ClientRMService	RESULT=SUCCESS	APPID=application_1376157310799_0002
2013-08-10 17:59:05,482 INFO org.apache.hadoop.yarn.server.resourcemanager.rmapp.RMAppImpl: application_1376157310799_0002 State change from NEW to SUBMITTED
2013-08-10 17:59:05,482 INFO org.apache.hadoop.yarn.server.resourcemanager.ApplicationMasterService: Registering appattempt_1376157310799_0002_000001
2013-08-10 17:59:05,482 INFO org.apache.hadoop.yarn.server.resourcemanager.rmapp.attempt.RMAppAttemptImpl: appattempt_1376157310799_0002_000001 State change from NEW to SUBMITTED
2013-08-10 17:59:05,483 INFO org.apache.hadoop.yarn.server.resourcemanager.scheduler.capacity.LeafQueue: Application application_1376157310799_0002 from user: ubuntu activated in queue: default
2013-08-10 17:59:05,483 INFO org.apache.hadoop.yarn.server.resourcemanager.scheduler.capacity.LeafQueue: Application added - appId: application_1376157310799_0002 user: org.apache.hadoop.yarn.server.resourcemanager.scheduler.capacity.LeafQueue$User@20a852a7, leaf-queue: default #user-pending-applications: 0 #user-active-applications: 1 #queue-pending-applications: 0 #queue-active-applications: 1
2013-08-10 17:59:05,483 INFO org.apache.hadoop.yarn.server.resourcemanager.scheduler.capacity.ParentQueue: Application added - appId: application_1376157310799_0002 user: ubuntu leaf-queue of parent: root #applications: 1
2013-08-10 17:59:05,483 INFO org.apache.hadoop.yarn.server.resourcemanager.scheduler.capacity.CapacityScheduler: Application Submission: appattempt_1376157310799_0002_000001, user: ubuntu queue: default: capacity=1.0, absoluteCapacity=1.0, usedResources=<memory:0, vCores:0>usedCapacity=0.0, absoluteUsedCapacity=0.0, numApps=1, numContainers=0, currently active: 1
2013-08-10 17:59:05,484 INFO org.apache.hadoop.yarn.server.resourcemanager.rmapp.attempt.RMAppAttemptImpl: appattempt_1376157310799_0002_000001 State change from SUBMITTED to SCHEDULED
2013-08-10 17:59:05,484 INFO org.apache.hadoop.yarn.server.resourcemanager.rmapp.RMAppImpl: application_1376157310799_0002 State change from SUBMITTED to ACCEPTED
2013-08-10 17:59:05,507 INFO org.apache.hadoop.yarn.server.resourcemanager.rmcontainer.RMContainerImpl: container_1376157310799_0002_01_000001 Container Transitioned from NEW to ALLOCATED
2013-08-10 17:59:05,507 INFO org.apache.hadoop.yarn.server.resourcemanager.RMAuditLogger: USER=ubuntu	OPERATION=AM Allocated Container	TARGET=SchedulerApp	RESULT=SUCCESS	APPID=application_1376157310799_0002	CONTAINERID=container_1376157310799_0002_01_000001
2013-08-10 17:59:05,507 INFO org.apache.hadoop.yarn.server.resourcemanager.scheduler.common.fica.FiCaSchedulerNode: Assigned container container_1376157310799_0002_01_000001 of capacity <memory:2048, vCores:1> on host hadoop-221-4:33277, which currently has 1 containers, <memory:2048, vCores:1> used and <memory:6144, vCores:15> available
2013-08-10 17:59:05,509 INFO org.apache.hadoop.yarn.server.resourcemanager.scheduler.capacity.LeafQueue: assignedContainer application=application_1376157310799_0002 container=Container: [ContainerId: container_1376157310799_0002_01_000001, NodeId: hadoop-221-4:33277, NodeHttpAddress: hadoop-221-4:8042, Resource: <memory:2048, vCores:1>, Priority: 0, State: NEW, Token: null, Status: container_id {, app_attempt_id {, application_id {, id: 2, cluster_timestamp: 1376157310799, }, attemptId: 1, }, id: 1, }, state: C_NEW, ] containerId=container_1376157310799_0002_01_000001 queue=default: capacity=1.0, absoluteCapacity=1.0, usedResources=<memory:0, vCores:0>usedCapacity=0.0, absoluteUsedCapacity=0.0, numApps=1, numContainers=0 usedCapacity=0.0 absoluteUsedCapacity=0.0 used=<memory:0, vCores:0> cluster=<memory:49152, vCores:96>
2013-08-10 17:59:05,509 INFO org.apache.hadoop.yarn.server.resourcemanager.scheduler.capacity.ParentQueue: Re-sorting queues since queue: root.default stats: default: capacity=1.0, absoluteCapacity=1.0, usedResources=<memory:2048, vCores:1>usedCapacity=0.041666668, absoluteUsedCapacity=0.041666668, numApps=1, numContainers=1
2013-08-10 17:59:05,510 INFO org.apache.hadoop.yarn.server.resourcemanager.scheduler.capacity.ParentQueue: assignedContainer queue=root usedCapacity=0.041666668 absoluteUsedCapacity=0.041666668 used=<memory:2048, vCores:1> cluster=<memory:49152, vCores:96>
2013-08-10 17:59:05,511 INFO org.apache.hadoop.yarn.server.resourcemanager.rmcontainer.RMContainerImpl: container_1376157310799_0002_01_000001 Container Transitioned from ALLOCATED to ACQUIRED
2013-08-10 17:59:05,513 INFO org.apache.hadoop.yarn.server.resourcemanager.rmapp.attempt.RMAppAttemptImpl: Storing attempt: AppId: application_1376157310799_0002 AttemptId: appattempt_1376157310799_0002_000001 MasterContainer: Container: [ContainerId: container_1376157310799_0002_01_000001, NodeId: hadoop-221-4:33277, NodeHttpAddress: hadoop-221-4:8042, Resource: <memory:2048, vCores:1>, Priority: 0, State: NEW, Token: null, Status: container_id {, app_attempt_id {, application_id {, id: 2, cluster_timestamp: 1376157310799, }, attemptId: 1, }, id: 1, }, state: C_NEW, ]
2013-08-10 17:59:05,514 INFO org.apache.hadoop.yarn.server.resourcemanager.recovery.RMStateStore: Storing info for attempt: appattempt_1376157310799_0002_000001
2013-08-10 17:59:05,514 INFO org.apache.hadoop.yarn.server.resourcemanager.rmapp.attempt.RMAppAttemptImpl: appattempt_1376157310799_0002_000001 State change from SCHEDULED to ALLOCATED_SAVING
2013-08-10 17:59:05,515 INFO org.apache.hadoop.yarn.server.resourcemanager.rmapp.attempt.RMAppAttemptImpl: appattempt_1376157310799_0002_000001 State change from ALLOCATED_SAVING to ALLOCATED
2013-08-10 17:59:05,516 INFO org.apache.hadoop.yarn.server.resourcemanager.amlauncher.AMLauncher: Launching masterappattempt_1376157310799_0002_000001
2013-08-10 17:59:05,519 INFO org.apache.hadoop.yarn.server.resourcemanager.amlauncher.AMLauncher: Setting up container Container: [ContainerId: container_1376157310799_0002_01_000001, NodeId: hadoop-221-4:33277, NodeHttpAddress: hadoop-221-4:8042, Resource: <memory:2048, vCores:1>, Priority: 0, State: NEW, Token: null, Status: container_id {, app_attempt_id {, application_id {, id: 2, cluster_timestamp: 1376157310799, }, attemptId: 1, }, id: 1, }, state: C_NEW, ] for AM appattempt_1376157310799_0002_000001
2013-08-10 17:59:05,519 INFO org.apache.hadoop.yarn.server.resourcemanager.amlauncher.AMLauncher: Command to launch container container_1376157310799_0002_01_000001 : $JAVA_HOME/bin/java -Dlog4j.configuration=container-log4j.properties -Dyarn.app.mapreduce.container.log.dir=<LOG_DIR> -Dyarn.app.mapreduce.container.log.filesize=0 -Dhadoop.root.logger=INFO,CLA  -Xmx1024m org.apache.hadoop.mapreduce.v2.app.MRAppMaster 1><LOG_DIR>/stdout 2><LOG_DIR>/stderr 
2013-08-10 17:59:06,397 INFO org.apache.hadoop.yarn.server.resourcemanager.amlauncher.AMLauncher: Done launching container Container: [ContainerId: container_1376157310799_0002_01_000001, NodeId: hadoop-221-4:33277, NodeHttpAddress: hadoop-221-4:8042, Resource: <memory:2048, vCores:1>, Priority: 0, State: NEW, Token: null, Status: container_id {, app_attempt_id {, application_id {, id: 2, cluster_timestamp: 1376157310799, }, attemptId: 1, }, id: 1, }, state: C_NEW, ] for AM appattempt_1376157310799_0002_000001
2013-08-10 17:59:06,397 INFO org.apache.hadoop.yarn.server.resourcemanager.rmapp.attempt.RMAppAttemptImpl: appattempt_1376157310799_0002_000001 State change from ALLOCATED to LAUNCHED
2013-08-10 17:59:06,717 INFO org.apache.hadoop.yarn.server.resourcemanager.rmcontainer.RMContainerImpl: container_1376157310799_0002_01_000001 Container Transitioned from ACQUIRED to RUNNING
2013-08-10 17:59:15,830 INFO org.apache.hadoop.yarn.server.resourcemanager.ApplicationMasterService: AM registration appattempt_1376157310799_0002_000001
2013-08-10 17:59:15,831 INFO org.apache.hadoop.yarn.server.resourcemanager.RMAuditLogger: USER=ubuntu	IP=192.168.100.31	OPERATION=Register App Master	TARGET=ApplicationMasterService	RESULT=SUCCESS	APPID=application_1376157310799_0002	APPATTEMPTID=appattempt_1376157310799_0002_000001
2013-08-10 17:59:15,841 INFO org.apache.hadoop.yarn.server.resourcemanager.rmapp.attempt.RMAppAttemptImpl: appattempt_1376157310799_0002_000001 State change from LAUNCHED to RUNNING
2013-08-10 17:59:15,841 INFO org.apache.hadoop.yarn.server.resourcemanager.rmapp.RMAppImpl: application_1376157310799_0002 State change from ACCEPTED to RUNNING
2013-08-10 17:59:17,022 INFO org.apache.hadoop.yarn.server.resourcemanager.rmcontainer.RMContainerImpl: container_1376157310799_0002_01_000002 Container Transitioned from NEW to ALLOCATED
2013-08-10 17:59:17,022 INFO org.apache.hadoop.yarn.server.resourcemanager.RMAuditLogger: USER=ubuntu	OPERATION=AM Allocated Container	TARGET=SchedulerApp	RESULT=SUCCESS	APPID=application_1376157310799_0002	CONTAINERID=container_1376157310799_0002_01_000002
2013-08-10 17:59:17,023 INFO org.apache.hadoop.yarn.server.resourcemanager.scheduler.common.fica.FiCaSchedulerNode: Assigned container container_1376157310799_0002_01_000002 of capacity <memory:1024, vCores:1> on host hadoop-221-6:39509, which currently has 1 containers, <memory:1024, vCores:1> used and <memory:7168, vCores:15> available
2013-08-10 17:59:17,024 INFO org.apache.hadoop.yarn.server.resourcemanager.scheduler.capacity.LeafQueue: assignedContainer application=application_1376157310799_0002 container=Container: [ContainerId: container_1376157310799_0002_01_000002, NodeId: hadoop-221-6:39509, NodeHttpAddress: hadoop-221-6:8042, Resource: <memory:1024, vCores:1>, Priority: 20, State: NEW, Token: null, Status: container_id {, app_attempt_id {, application_id {, id: 2, cluster_timestamp: 1376157310799, }, attemptId: 1, }, id: 2, }, state: C_NEW, ] containerId=container_1376157310799_0002_01_000002 queue=default: capacity=1.0, absoluteCapacity=1.0, usedResources=<memory:2048, vCores:1>usedCapacity=0.041666668, absoluteUsedCapacity=0.041666668, numApps=1, numContainers=1 usedCapacity=0.041666668 absoluteUsedCapacity=0.041666668 used=<memory:2048, vCores:1> cluster=<memory:49152, vCores:96>
2013-08-10 17:59:17,025 INFO org.apache.hadoop.yarn.server.resourcemanager.scheduler.capacity.ParentQueue: Re-sorting queues since queue: root.default stats: default: capacity=1.0, absoluteCapacity=1.0, usedResources=<memory:3072, vCores:2>usedCapacity=0.0625, absoluteUsedCapacity=0.0625, numApps=1, numContainers=2
2013-08-10 17:59:17,025 INFO org.apache.hadoop.yarn.server.resourcemanager.scheduler.capacity.ParentQueue: assignedContainer queue=root usedCapacity=0.0625 absoluteUsedCapacity=0.0625 used=<memory:3072, vCores:2> cluster=<memory:49152, vCores:96>
2013-08-10 17:59:17,213 INFO org.apache.hadoop.yarn.server.resourcemanager.rmcontainer.RMContainerImpl: container_1376157310799_0002_01_000003 Container Transitioned from NEW to ALLOCATED
2013-08-10 17:59:17,213 INFO org.apache.hadoop.yarn.server.resourcemanager.RMAuditLogger: USER=ubuntu	OPERATION=AM Allocated Container	TARGET=SchedulerApp	RESULT=SUCCESS	APPID=application_1376157310799_0002	CONTAINERID=container_1376157310799_0002_01_000003
2013-08-10 17:59:17,213 INFO org.apache.hadoop.yarn.server.resourcemanager.scheduler.common.fica.FiCaSchedulerNode: Assigned container container_1376157310799_0002_01_000003 of capacity <memory:1024, vCores:1> on host hadoop-221-5:56475, which currently has 1 containers, <memory:1024, vCores:1> used and <memory:7168, vCores:15> available
2013-08-10 17:59:17,215 INFO org.apache.hadoop.yarn.server.resourcemanager.scheduler.capacity.LeafQueue: assignedContainer application=application_1376157310799_0002 container=Container: [ContainerId: container_1376157310799_0002_01_000003, NodeId: hadoop-221-5:56475, NodeHttpAddress: hadoop-221-5:8042, Resource: <memory:1024, vCores:1>, Priority: 20, State: NEW, Token: null, Status: container_id {, app_attempt_id {, application_id {, id: 2, cluster_timestamp: 1376157310799, }, attemptId: 1, }, id: 3, }, state: C_NEW, ] containerId=container_1376157310799_0002_01_000003 queue=default: capacity=1.0, absoluteCapacity=1.0, usedResources=<memory:3072, vCores:2>usedCapacity=0.0625, absoluteUsedCapacity=0.0625, numApps=1, numContainers=2 usedCapacity=0.0625 absoluteUsedCapacity=0.0625 used=<memory:3072, vCores:2> cluster=<memory:49152, vCores:96>
2013-08-10 17:59:17,215 INFO org.apache.hadoop.yarn.server.resourcemanager.scheduler.capacity.ParentQueue: Re-sorting queues since queue: root.default stats: default: capacity=1.0, absoluteCapacity=1.0, usedResources=<memory:4096, vCores:3>usedCapacity=0.083333336, absoluteUsedCapacity=0.083333336, numApps=1, numContainers=3
2013-08-10 17:59:17,215 INFO org.apache.hadoop.yarn.server.resourcemanager.scheduler.capacity.ParentQueue: assignedContainer queue=root usedCapacity=0.083333336 absoluteUsedCapacity=0.083333336 used=<memory:4096, vCores:3> cluster=<memory:49152, vCores:96>
2013-08-10 17:59:17,909 INFO org.apache.hadoop.yarn.server.resourcemanager.rmcontainer.RMContainerImpl: container_1376157310799_0002_01_000002 Container Transitioned from ALLOCATED to ACQUIRED
2013-08-10 17:59:17,910 INFO org.apache.hadoop.yarn.server.resourcemanager.rmcontainer.RMContainerImpl: container_1376157310799_0002_01_000003 Container Transitioned from ALLOCATED to ACQUIRED
2013-08-10 17:59:18,218 INFO org.apache.hadoop.yarn.server.resourcemanager.rmcontainer.RMContainerImpl: container_1376157310799_0002_01_000003 Container Transitioned from ACQUIRED to RUNNING
2013-08-10 17:59:18,939 INFO org.apache.hadoop.yarn.server.resourcemanager.scheduler.AppSchedulingInfo: checking for deactivate... 
2013-08-10 17:59:19,032 INFO org.apache.hadoop.yarn.server.resourcemanager.rmcontainer.RMContainerImpl: container_1376157310799_0002_01_000002 Container Transitioned from ACQUIRED to RUNNING
2013-08-10 18:02:15,398 INFO org.apache.hadoop.yarn.server.resourcemanager.rmcontainer.RMContainerImpl: container_1376157310799_0002_01_000002 Container Transitioned from RUNNING to COMPLETED
2013-08-10 18:02:15,398 INFO org.apache.hadoop.yarn.server.resourcemanager.scheduler.common.fica.FiCaSchedulerApp: Completed container: container_1376157310799_0002_01_000002 in state: COMPLETED event:FINISHED
2013-08-10 18:02:15,398 INFO org.apache.hadoop.yarn.server.resourcemanager.RMAuditLogger: USER=ubuntu	OPERATION=AM Released Container	TARGET=SchedulerApp	RESULT=SUCCESS	APPID=application_1376157310799_0002	CONTAINERID=container_1376157310799_0002_01_000002
2013-08-10 18:02:15,398 INFO org.apache.hadoop.yarn.server.resourcemanager.scheduler.common.fica.FiCaSchedulerNode: Released container container_1376157310799_0002_01_000002 of capacity <memory:1024, vCores:1> on host hadoop-221-6:39509, which currently has 0 containers, <memory:0, vCores:0> used and <memory:8192, vCores:16> available, release resources=true
2013-08-10 18:02:15,399 INFO org.apache.hadoop.yarn.server.resourcemanager.scheduler.capacity.LeafQueue: default used=<memory:3072, vCores:2> numContainers=2 user=ubuntu user-resources=<memory:3072, vCores:2>
2013-08-10 18:02:15,412 INFO org.apache.hadoop.yarn.server.resourcemanager.scheduler.capacity.LeafQueue: completedContainer container=Container: [ContainerId: container_1376157310799_0002_01_000002, NodeId: hadoop-221-6:39509, NodeHttpAddress: hadoop-221-6:8042, Resource: <memory:1024, vCores:1>, Priority: 20, State: NEW, Token: null, Status: container_id {, app_attempt_id {, application_id {, id: 2, cluster_timestamp: 1376157310799, }, attemptId: 1, }, id: 2, }, state: C_COMPLETE, diagnostics: "Container killed by the ApplicationMaster.\n\n", exit_status: 143, ] resource=<memory:1024, vCores:1> queue=default: capacity=1.0, absoluteCapacity=1.0, usedResources=<memory:3072, vCores:2>usedCapacity=0.0625, absoluteUsedCapacity=0.0625, numApps=1, numContainers=2 usedCapacity=0.0625 absoluteUsedCapacity=0.0625 used=<memory:3072, vCores:2> cluster=<memory:49152, vCores:96>
2013-08-10 18:02:15,412 INFO org.apache.hadoop.yarn.server.resourcemanager.scheduler.capacity.ParentQueue: completedContainer queue=root usedCapacity=0.0625 absoluteUsedCapacity=0.0625 used=<memory:3072, vCores:2> cluster=<memory:49152, vCores:96>
2013-08-10 18:02:15,412 INFO org.apache.hadoop.yarn.server.resourcemanager.scheduler.capacity.CapacityScheduler: Application appattempt_1376157310799_0002_000001 released container container_1376157310799_0002_01_000002 on node: host: hadoop-221-6:39509 #containers=0 available=8192 used=0 with event: FINISHED
2013-08-10 18:02:15,507 INFO org.apache.hadoop.yarn.server.resourcemanager.rmcontainer.RMContainerImpl: container_1376157310799_0002_01_000003 Container Transitioned from RUNNING to COMPLETED
2013-08-10 18:02:15,508 INFO org.apache.hadoop.yarn.server.resourcemanager.scheduler.common.fica.FiCaSchedulerApp: Completed container: container_1376157310799_0002_01_000003 in state: COMPLETED event:FINISHED
2013-08-10 18:02:15,508 INFO org.apache.hadoop.yarn.server.resourcemanager.RMAuditLogger: USER=ubuntu	OPERATION=AM Released Container	TARGET=SchedulerApp	RESULT=SUCCESS	APPID=application_1376157310799_0002	CONTAINERID=container_1376157310799_0002_01_000003
2013-08-10 18:02:15,508 INFO org.apache.hadoop.yarn.server.resourcemanager.scheduler.common.fica.FiCaSchedulerNode: Released container container_1376157310799_0002_01_000003 of capacity <memory:1024, vCores:1> on host hadoop-221-5:56475, which currently has 0 containers, <memory:0, vCores:0> used and <memory:8192, vCores:16> available, release resources=true
2013-08-10 18:02:15,508 INFO org.apache.hadoop.yarn.server.resourcemanager.scheduler.capacity.LeafQueue: default used=<memory:2048, vCores:1> numContainers=1 user=ubuntu user-resources=<memory:2048, vCores:1>
2013-08-10 18:02:15,510 INFO org.apache.hadoop.yarn.server.resourcemanager.scheduler.capacity.LeafQueue: completedContainer container=Container: [ContainerId: container_1376157310799_0002_01_000003, NodeId: hadoop-221-5:56475, NodeHttpAddress: hadoop-221-5:8042, Resource: <memory:1024, vCores:1>, Priority: 20, State: NEW, Token: null, Status: container_id {, app_attempt_id {, application_id {, id: 2, cluster_timestamp: 1376157310799, }, attemptId: 1, }, id: 3, }, state: C_COMPLETE, diagnostics: "Container killed by the ApplicationMaster.\n\n", exit_status: 143, ] resource=<memory:1024, vCores:1> queue=default: capacity=1.0, absoluteCapacity=1.0, usedResources=<memory:2048, vCores:1>usedCapacity=0.041666668, absoluteUsedCapacity=0.041666668, numApps=1, numContainers=1 usedCapacity=0.041666668 absoluteUsedCapacity=0.041666668 used=<memory:2048, vCores:1> cluster=<memory:49152, vCores:96>
2013-08-10 18:02:15,510 INFO org.apache.hadoop.yarn.server.resourcemanager.scheduler.capacity.ParentQueue: completedContainer queue=root usedCapacity=0.041666668 absoluteUsedCapacity=0.041666668 used=<memory:2048, vCores:1> cluster=<memory:49152, vCores:96>
2013-08-10 18:02:15,511 INFO org.apache.hadoop.yarn.server.resourcemanager.scheduler.capacity.CapacityScheduler: Application appattempt_1376157310799_0002_000001 released container container_1376157310799_0002_01_000003 on node: host: hadoop-221-5:56475 #containers=0 available=8192 used=0 with event: FINISHED
2013-08-10 18:02:19,643 INFO org.apache.hadoop.yarn.server.resourcemanager.rmapp.attempt.RMAppAttemptImpl: appattempt_1376157310799_0002_000001 State change from RUNNING to FINISHING
2013-08-10 18:02:19,645 INFO org.apache.hadoop.yarn.server.resourcemanager.rmapp.RMAppImpl: application_1376157310799_0002 State change from RUNNING to FINISHING
2013-08-10 18:02:20,035 INFO org.apache.hadoop.yarn.server.resourcemanager.rmcontainer.RMContainerImpl: container_1376157310799_0002_01_000001 Container Transitioned from RUNNING to COMPLETED
2013-08-10 18:02:20,035 INFO org.apache.hadoop.yarn.server.resourcemanager.scheduler.common.fica.FiCaSchedulerApp: Completed container: container_1376157310799_0002_01_000001 in state: COMPLETED event:FINISHED
2013-08-10 18:02:20,035 INFO org.apache.hadoop.yarn.server.resourcemanager.RMAuditLogger: USER=ubuntu	OPERATION=AM Released Container	TARGET=SchedulerApp	RESULT=SUCCESS	APPID=application_1376157310799_0002	CONTAINERID=container_1376157310799_0002_01_000001
2013-08-10 18:02:20,035 INFO org.apache.hadoop.yarn.server.resourcemanager.scheduler.common.fica.FiCaSchedulerNode: Released container container_1376157310799_0002_01_000001 of capacity <memory:2048, vCores:1> on host hadoop-221-4:33277, which currently has 0 containers, <memory:0, vCores:0> used and <memory:8192, vCores:16> available, release resources=true
2013-08-10 18:02:20,035 INFO org.apache.hadoop.yarn.server.resourcemanager.scheduler.capacity.LeafQueue: default used=<memory:0, vCores:0> numContainers=0 user=ubuntu user-resources=<memory:0, vCores:0>
2013-08-10 18:02:20,036 INFO org.apache.hadoop.yarn.server.resourcemanager.scheduler.capacity.LeafQueue: completedContainer container=Container: [ContainerId: container_1376157310799_0002_01_000001, NodeId: hadoop-221-4:33277, NodeHttpAddress: hadoop-221-4:8042, Resource: <memory:2048, vCores:1>, Priority: 0, State: NEW, Token: null, Status: container_id {, app_attempt_id {, application_id {, id: 2, cluster_timestamp: 1376157310799, }, attemptId: 1, }, id: 1, }, state: C_COMPLETE, diagnostics: "", exit_status: 0, ] resource=<memory:2048, vCores:1> queue=default: capacity=1.0, absoluteCapacity=1.0, usedResources=<memory:0, vCores:0>usedCapacity=0.0, absoluteUsedCapacity=0.0, numApps=1, numContainers=0 usedCapacity=0.0 absoluteUsedCapacity=0.0 used=<memory:0, vCores:0> cluster=<memory:49152, vCores:96>
2013-08-10 18:02:20,036 INFO org.apache.hadoop.yarn.server.resourcemanager.scheduler.capacity.ParentQueue: completedContainer queue=root usedCapacity=0.0 absoluteUsedCapacity=0.0 used=<memory:0, vCores:0> cluster=<memory:49152, vCores:96>
2013-08-10 18:02:20,036 INFO org.apache.hadoop.yarn.server.resourcemanager.scheduler.capacity.CapacityScheduler: Application appattempt_1376157310799_0002_000001 released container container_1376157310799_0002_01_000001 on node: host: hadoop-221-4:33277 #containers=0 available=8192 used=0 with event: FINISHED
2013-08-10 18:02:20,037 INFO org.apache.hadoop.yarn.server.resourcemanager.rmapp.attempt.RMAppAttemptImpl: appattempt_1376157310799_0002_000001 State change from FINISHING to FINISHED
2013-08-10 18:02:20,037 INFO org.apache.hadoop.yarn.server.resourcemanager.rmapp.RMAppImpl: application_1376157310799_0002 State change from FINISHING to FINISHED
2013-08-10 18:02:20,038 INFO org.apache.hadoop.yarn.server.resourcemanager.RMAuditLogger: USER=ubuntu	OPERATION=Application Finished - Succeeded	TARGET=RMAppManager	RESULT=SUCCESS	APPID=application_1376157310799_0002
2013-08-10 18:02:20,038 INFO org.apache.hadoop.yarn.server.resourcemanager.scheduler.capacity.CapacityScheduler: Application appattempt_1376157310799_0002_000001 is done. finalState=FINISHED
2013-08-10 18:02:20,038 INFO org.apache.hadoop.yarn.server.resourcemanager.amlauncher.AMLauncher: Cleaning master appattempt_1376157310799_0002_000001
2013-08-10 18:02:20,038 INFO org.apache.hadoop.yarn.server.resourcemanager.scheduler.AppSchedulingInfo: Application application_1376157310799_0002 requests cleared
2013-08-10 18:02:20,038 INFO org.apache.hadoop.yarn.server.resourcemanager.recovery.RMStateStore: Removing info for app: application_1376157310799_0002
2013-08-10 18:02:20,039 INFO org.apache.hadoop.yarn.server.resourcemanager.scheduler.capacity.LeafQueue: Application removed - appId: application_1376157310799_0002 user: ubuntu queue: default #user-pending-applications: 0 #user-active-applications: 0 #queue-pending-applications: 0 #queue-active-applications: 0
2013-08-10 18:02:20,039 INFO org.apache.hadoop.yarn.server.resourcemanager.scheduler.capacity.ParentQueue: Application removed - appId: application_1376157310799_0002 user: ubuntu leaf-queue of parent: root #applications: 0
2013-08-10 18:02:20,039 INFO org.apache.hadoop.yarn.server.resourcemanager.RMAppManager$ApplicationSummary: appId=application_1376157310799_0002,name=TeraGen,user=ubuntu,queue=default,state=FINISHED,trackingUrl=hadoop-221-1.novalocal:8088/proxy/application_1376157310799_0002/jobhistory/job/job_1376157310799_0002,appMasterHost=hadoop-221-4,startTime=1376157545474,finishTime=1376157739645
2013-08-10 18:02:20,522 INFO org.apache.hadoop.yarn.server.resourcemanager.ClientRMService: Allocated new applicationId: 3
2013-08-10 18:02:22,351 INFO org.apache.hadoop.yarn.server.resourcemanager.ClientRMService: Storing Application with id application_1376157310799_0003
2013-08-10 18:02:22,351 INFO org.apache.hadoop.yarn.server.resourcemanager.recovery.RMStateStore: Storing info for app: application_1376157310799_0003
2013-08-10 18:02:22,351 INFO org.apache.hadoop.yarn.server.resourcemanager.ClientRMService: Application with id 3 submitted by user ubuntu
2013-08-10 18:02:22,351 INFO org.apache.hadoop.yarn.server.resourcemanager.RMAuditLogger: USER=ubuntu	IP=192.168.100.24	OPERATION=Submit Application Request	TARGET=ClientRMService	RESULT=SUCCESS	APPID=application_1376157310799_0003
2013-08-10 18:02:22,357 INFO org.apache.hadoop.yarn.server.resourcemanager.rmapp.RMAppImpl: application_1376157310799_0003 State change from NEW to SUBMITTED
2013-08-10 18:02:22,357 INFO org.apache.hadoop.yarn.server.resourcemanager.ApplicationMasterService: Registering appattempt_1376157310799_0003_000001
2013-08-10 18:02:22,358 INFO org.apache.hadoop.yarn.server.resourcemanager.rmapp.attempt.RMAppAttemptImpl: appattempt_1376157310799_0003_000001 State change from NEW to SUBMITTED
2013-08-10 18:02:22,358 INFO org.apache.hadoop.yarn.server.resourcemanager.scheduler.capacity.LeafQueue: Application application_1376157310799_0003 from user: ubuntu activated in queue: default
2013-08-10 18:02:22,358 INFO org.apache.hadoop.yarn.server.resourcemanager.scheduler.capacity.LeafQueue: Application added - appId: application_1376157310799_0003 user: org.apache.hadoop.yarn.server.resourcemanager.scheduler.capacity.LeafQueue$User@5be0a2fc, leaf-queue: default #user-pending-applications: 0 #user-active-applications: 1 #queue-pending-applications: 0 #queue-active-applications: 1
2013-08-10 18:02:22,359 INFO org.apache.hadoop.yarn.server.resourcemanager.scheduler.capacity.ParentQueue: Application added - appId: application_1376157310799_0003 user: ubuntu leaf-queue of parent: root #applications: 1
2013-08-10 18:02:22,359 INFO org.apache.hadoop.yarn.server.resourcemanager.scheduler.capacity.CapacityScheduler: Application Submission: appattempt_1376157310799_0003_000001, user: ubuntu queue: default: capacity=1.0, absoluteCapacity=1.0, usedResources=<memory:0, vCores:0>usedCapacity=0.0, absoluteUsedCapacity=0.0, numApps=1, numContainers=0, currently active: 1
2013-08-10 18:02:22,359 INFO org.apache.hadoop.yarn.server.resourcemanager.rmapp.attempt.RMAppAttemptImpl: appattempt_1376157310799_0003_000001 State change from SUBMITTED to SCHEDULED
2013-08-10 18:02:22,360 INFO org.apache.hadoop.yarn.server.resourcemanager.rmapp.RMAppImpl: application_1376157310799_0003 State change from SUBMITTED to ACCEPTED
2013-08-10 18:02:22,403 INFO org.apache.hadoop.yarn.server.resourcemanager.rmcontainer.RMContainerImpl: container_1376157310799_0003_01_000001 Container Transitioned from NEW to ALLOCATED
2013-08-10 18:02:22,403 INFO org.apache.hadoop.yarn.server.resourcemanager.RMAuditLogger: USER=ubuntu	OPERATION=AM Allocated Container	TARGET=SchedulerApp	RESULT=SUCCESS	APPID=application_1376157310799_0003	CONTAINERID=container_1376157310799_0003_01_000001
2013-08-10 18:02:22,403 INFO org.apache.hadoop.yarn.server.resourcemanager.scheduler.common.fica.FiCaSchedulerNode: Assigned container container_1376157310799_0003_01_000001 of capacity <memory:2048, vCores:1> on host hadoop-221-3:38242, which currently has 1 containers, <memory:2048, vCores:1> used and <memory:6144, vCores:15> available
2013-08-10 18:02:22,406 INFO org.apache.hadoop.yarn.server.resourcemanager.scheduler.capacity.LeafQueue: assignedContainer application=application_1376157310799_0003 container=Container: [ContainerId: container_1376157310799_0003_01_000001, NodeId: hadoop-221-3:38242, NodeHttpAddress: hadoop-221-3:8042, Resource: <memory:2048, vCores:1>, Priority: 0, State: NEW, Token: null, Status: container_id {, app_attempt_id {, application_id {, id: 3, cluster_timestamp: 1376157310799, }, attemptId: 1, }, id: 1, }, state: C_NEW, ] containerId=container_1376157310799_0003_01_000001 queue=default: capacity=1.0, absoluteCapacity=1.0, usedResources=<memory:0, vCores:0>usedCapacity=0.0, absoluteUsedCapacity=0.0, numApps=1, numContainers=0 usedCapacity=0.0 absoluteUsedCapacity=0.0 used=<memory:0, vCores:0> cluster=<memory:49152, vCores:96>
2013-08-10 18:02:22,406 INFO org.apache.hadoop.yarn.server.resourcemanager.scheduler.capacity.ParentQueue: Re-sorting queues since queue: root.default stats: default: capacity=1.0, absoluteCapacity=1.0, usedResources=<memory:2048, vCores:1>usedCapacity=0.041666668, absoluteUsedCapacity=0.041666668, numApps=1, numContainers=1
2013-08-10 18:02:22,406 INFO org.apache.hadoop.yarn.server.resourcemanager.scheduler.capacity.ParentQueue: assignedContainer queue=root usedCapacity=0.041666668 absoluteUsedCapacity=0.041666668 used=<memory:2048, vCores:1> cluster=<memory:49152, vCores:96>
2013-08-10 18:02:22,407 INFO org.apache.hadoop.yarn.server.resourcemanager.rmcontainer.RMContainerImpl: container_1376157310799_0003_01_000001 Container Transitioned from ALLOCATED to ACQUIRED
2013-08-10 18:02:22,409 INFO org.apache.hadoop.yarn.server.resourcemanager.rmapp.attempt.RMAppAttemptImpl: Storing attempt: AppId: application_1376157310799_0003 AttemptId: appattempt_1376157310799_0003_000001 MasterContainer: Container: [ContainerId: container_1376157310799_0003_01_000001, NodeId: hadoop-221-3:38242, NodeHttpAddress: hadoop-221-3:8042, Resource: <memory:2048, vCores:1>, Priority: 0, State: NEW, Token: null, Status: container_id {, app_attempt_id {, application_id {, id: 3, cluster_timestamp: 1376157310799, }, attemptId: 1, }, id: 1, }, state: C_NEW, ]
2013-08-10 18:02:22,409 INFO org.apache.hadoop.yarn.server.resourcemanager.rmapp.attempt.RMAppAttemptImpl: appattempt_1376157310799_0003_000001 State change from SCHEDULED to ALLOCATED_SAVING
2013-08-10 18:02:22,410 INFO org.apache.hadoop.yarn.server.resourcemanager.recovery.RMStateStore: Storing info for attempt: appattempt_1376157310799_0003_000001
2013-08-10 18:02:22,411 INFO org.apache.hadoop.yarn.server.resourcemanager.rmapp.attempt.RMAppAttemptImpl: appattempt_1376157310799_0003_000001 State change from ALLOCATED_SAVING to ALLOCATED
2013-08-10 18:02:22,413 INFO org.apache.hadoop.yarn.server.resourcemanager.amlauncher.AMLauncher: Launching masterappattempt_1376157310799_0003_000001
2013-08-10 18:02:22,416 INFO org.apache.hadoop.yarn.server.resourcemanager.amlauncher.AMLauncher: Setting up container Container: [ContainerId: container_1376157310799_0003_01_000001, NodeId: hadoop-221-3:38242, NodeHttpAddress: hadoop-221-3:8042, Resource: <memory:2048, vCores:1>, Priority: 0, State: NEW, Token: null, Status: container_id {, app_attempt_id {, application_id {, id: 3, cluster_timestamp: 1376157310799, }, attemptId: 1, }, id: 1, }, state: C_NEW, ] for AM appattempt_1376157310799_0003_000001
2013-08-10 18:02:22,416 INFO org.apache.hadoop.yarn.server.resourcemanager.amlauncher.AMLauncher: Command to launch container container_1376157310799_0003_01_000001 : $JAVA_HOME/bin/java -Dlog4j.configuration=container-log4j.properties -Dyarn.app.mapreduce.container.log.dir=<LOG_DIR> -Dyarn.app.mapreduce.container.log.filesize=0 -Dhadoop.root.logger=INFO,CLA  -Xmx1024m org.apache.hadoop.mapreduce.v2.app.MRAppMaster 1><LOG_DIR>/stdout 2><LOG_DIR>/stderr 
2013-08-10 18:02:23,337 INFO org.apache.hadoop.yarn.server.resourcemanager.amlauncher.AMLauncher: Done launching container Container: [ContainerId: container_1376157310799_0003_01_000001, NodeId: hadoop-221-3:38242, NodeHttpAddress: hadoop-221-3:8042, Resource: <memory:2048, vCores:1>, Priority: 0, State: NEW, Token: null, Status: container_id {, app_attempt_id {, application_id {, id: 3, cluster_timestamp: 1376157310799, }, attemptId: 1, }, id: 1, }, state: C_NEW, ] for AM appattempt_1376157310799_0003_000001
2013-08-10 18:02:23,338 INFO org.apache.hadoop.yarn.server.resourcemanager.rmapp.attempt.RMAppAttemptImpl: appattempt_1376157310799_0003_000001 State change from ALLOCATED to LAUNCHED
2013-08-10 18:02:23,434 INFO org.apache.hadoop.yarn.server.resourcemanager.rmcontainer.RMContainerImpl: container_1376157310799_0003_01_000001 Container Transitioned from ACQUIRED to RUNNING
2013-08-10 18:02:30,401 INFO org.apache.hadoop.yarn.server.resourcemanager.ApplicationMasterService: AM registration appattempt_1376157310799_0003_000001
2013-08-10 18:02:30,401 INFO org.apache.hadoop.yarn.server.resourcemanager.RMAuditLogger: USER=ubuntu	IP=192.168.100.26	OPERATION=Register App Master	TARGET=ApplicationMasterService	RESULT=SUCCESS	APPID=application_1376157310799_0003	APPATTEMPTID=appattempt_1376157310799_0003_000001
2013-08-10 18:02:30,402 INFO org.apache.hadoop.yarn.server.resourcemanager.rmapp.attempt.RMAppAttemptImpl: appattempt_1376157310799_0003_000001 State change from LAUNCHED to RUNNING
2013-08-10 18:02:30,438 INFO org.apache.hadoop.yarn.server.resourcemanager.rmapp.RMAppImpl: application_1376157310799_0003 State change from ACCEPTED to RUNNING
2013-08-10 18:02:31,561 INFO org.apache.hadoop.yarn.server.resourcemanager.rmcontainer.RMContainerImpl: container_1376157310799_0003_01_000002 Container Transitioned from NEW to ALLOCATED
2013-08-10 18:02:31,561 INFO org.apache.hadoop.yarn.server.resourcemanager.RMAuditLogger: USER=ubuntu	OPERATION=AM Allocated Container	TARGET=SchedulerApp	RESULT=SUCCESS	APPID=application_1376157310799_0003	CONTAINERID=container_1376157310799_0003_01_000002
2013-08-10 18:02:31,561 INFO org.apache.hadoop.yarn.server.resourcemanager.scheduler.common.fica.FiCaSchedulerNode: Assigned container container_1376157310799_0003_01_000002 of capacity <memory:1024, vCores:1> on host hadoop-221-5:56475, which currently has 1 containers, <memory:1024, vCores:1> used and <memory:7168, vCores:15> available
2013-08-10 18:02:31,563 INFO org.apache.hadoop.yarn.server.resourcemanager.scheduler.capacity.LeafQueue: assignedContainer application=application_1376157310799_0003 container=Container: [ContainerId: container_1376157310799_0003_01_000002, NodeId: hadoop-221-5:56475, NodeHttpAddress: hadoop-221-5:8042, Resource: <memory:1024, vCores:1>, Priority: 20, State: NEW, Token: null, Status: container_id {, app_attempt_id {, application_id {, id: 3, cluster_timestamp: 1376157310799, }, attemptId: 1, }, id: 2, }, state: C_NEW, ] containerId=container_1376157310799_0003_01_000002 queue=default: capacity=1.0, absoluteCapacity=1.0, usedResources=<memory:2048, vCores:1>usedCapacity=0.041666668, absoluteUsedCapacity=0.041666668, numApps=1, numContainers=1 usedCapacity=0.041666668 absoluteUsedCapacity=0.041666668 used=<memory:2048, vCores:1> cluster=<memory:49152, vCores:96>
2013-08-10 18:02:31,563 INFO org.apache.hadoop.yarn.server.resourcemanager.scheduler.capacity.ParentQueue: Re-sorting queues since queue: root.default stats: default: capacity=1.0, absoluteCapacity=1.0, usedResources=<memory:3072, vCores:2>usedCapacity=0.0625, absoluteUsedCapacity=0.0625, numApps=1, numContainers=2
2013-08-10 18:02:31,563 INFO org.apache.hadoop.yarn.server.resourcemanager.scheduler.capacity.ParentQueue: assignedContainer queue=root usedCapacity=0.0625 absoluteUsedCapacity=0.0625 used=<memory:3072, vCores:2> cluster=<memory:49152, vCores:96>
2013-08-10 18:02:32,090 INFO org.apache.hadoop.yarn.server.resourcemanager.rmcontainer.RMContainerImpl: container_1376157310799_0003_01_000003 Container Transitioned from NEW to ALLOCATED
2013-08-10 18:02:32,091 INFO org.apache.hadoop.yarn.server.resourcemanager.RMAuditLogger: USER=ubuntu	OPERATION=AM Allocated Container	TARGET=SchedulerApp	RESULT=SUCCESS	APPID=application_1376157310799_0003	CONTAINERID=container_1376157310799_0003_01_000003
2013-08-10 18:02:32,091 INFO org.apache.hadoop.yarn.server.resourcemanager.scheduler.common.fica.FiCaSchedulerNode: Assigned container container_1376157310799_0003_01_000003 of capacity <memory:1024, vCores:1> on host hadoop-221-4:33277, which currently has 1 containers, <memory:1024, vCores:1> used and <memory:7168, vCores:15> available
2013-08-10 18:02:32,092 INFO org.apache.hadoop.yarn.server.resourcemanager.scheduler.capacity.LeafQueue: assignedContainer application=application_1376157310799_0003 container=Container: [ContainerId: container_1376157310799_0003_01_000003, NodeId: hadoop-221-4:33277, NodeHttpAddress: hadoop-221-4:8042, Resource: <memory:1024, vCores:1>, Priority: 20, State: NEW, Token: null, Status: container_id {, app_attempt_id {, application_id {, id: 3, cluster_timestamp: 1376157310799, }, attemptId: 1, }, id: 3, }, state: C_NEW, ] containerId=container_1376157310799_0003_01_000003 queue=default: capacity=1.0, absoluteCapacity=1.0, usedResources=<memory:3072, vCores:2>usedCapacity=0.0625, absoluteUsedCapacity=0.0625, numApps=1, numContainers=2 usedCapacity=0.0625 absoluteUsedCapacity=0.0625 used=<memory:3072, vCores:2> cluster=<memory:49152, vCores:96>
2013-08-10 18:02:32,093 INFO org.apache.hadoop.yarn.server.resourcemanager.scheduler.capacity.ParentQueue: Re-sorting queues since queue: root.default stats: default: capacity=1.0, absoluteCapacity=1.0, usedResources=<memory:4096, vCores:3>usedCapacity=0.083333336, absoluteUsedCapacity=0.083333336, numApps=1, numContainers=3
2013-08-10 18:02:32,093 INFO org.apache.hadoop.yarn.server.resourcemanager.scheduler.capacity.ParentQueue: assignedContainer queue=root usedCapacity=0.083333336 absoluteUsedCapacity=0.083333336 used=<memory:4096, vCores:3> cluster=<memory:49152, vCores:96>
2013-08-10 18:02:32,499 INFO org.apache.hadoop.yarn.server.resourcemanager.rmcontainer.RMContainerImpl: container_1376157310799_0003_01_000002 Container Transitioned from ALLOCATED to ACQUIRED
2013-08-10 18:02:32,501 INFO org.apache.hadoop.yarn.server.resourcemanager.rmcontainer.RMContainerImpl: container_1376157310799_0003_01_000003 Container Transitioned from ALLOCATED to ACQUIRED
2013-08-10 18:02:33,097 INFO org.apache.hadoop.yarn.server.resourcemanager.rmcontainer.RMContainerImpl: container_1376157310799_0003_01_000003 Container Transitioned from ACQUIRED to RUNNING
2013-08-10 18:02:33,534 INFO org.apache.hadoop.yarn.server.resourcemanager.scheduler.AppSchedulingInfo: checking for deactivate... 
2013-08-10 18:02:33,571 INFO org.apache.hadoop.yarn.server.resourcemanager.rmcontainer.RMContainerImpl: container_1376157310799_0003_01_000002 Container Transitioned from ACQUIRED to RUNNING
2013-08-10 18:05:07,179 INFO org.apache.hadoop.yarn.server.resourcemanager.rmcontainer.RMContainerImpl: container_1376157310799_0003_01_000002 Container Transitioned from RUNNING to COMPLETED
2013-08-10 18:05:07,179 INFO org.apache.hadoop.yarn.server.resourcemanager.scheduler.common.fica.FiCaSchedulerApp: Completed container: container_1376157310799_0003_01_000002 in state: COMPLETED event:FINISHED
2013-08-10 18:05:07,180 INFO org.apache.hadoop.yarn.server.resourcemanager.RMAuditLogger: USER=ubuntu	OPERATION=AM Released Container	TARGET=SchedulerApp	RESULT=SUCCESS	APPID=application_1376157310799_0003	CONTAINERID=container_1376157310799_0003_01_000002
2013-08-10 18:05:07,180 INFO org.apache.hadoop.yarn.server.resourcemanager.scheduler.common.fica.FiCaSchedulerNode: Released container container_1376157310799_0003_01_000002 of capacity <memory:1024, vCores:1> on host hadoop-221-5:56475, which currently has 0 containers, <memory:0, vCores:0> used and <memory:8192, vCores:16> available, release resources=true
2013-08-10 18:05:07,180 INFO org.apache.hadoop.yarn.server.resourcemanager.scheduler.capacity.LeafQueue: default used=<memory:3072, vCores:2> numContainers=2 user=ubuntu user-resources=<memory:3072, vCores:2>
2013-08-10 18:05:07,182 INFO org.apache.hadoop.yarn.server.resourcemanager.scheduler.capacity.LeafQueue: completedContainer container=Container: [ContainerId: container_1376157310799_0003_01_000002, NodeId: hadoop-221-5:56475, NodeHttpAddress: hadoop-221-5:8042, Resource: <memory:1024, vCores:1>, Priority: 20, State: NEW, Token: null, Status: container_id {, app_attempt_id {, application_id {, id: 3, cluster_timestamp: 1376157310799, }, attemptId: 1, }, id: 2, }, state: C_COMPLETE, diagnostics: "Container killed by the ApplicationMaster.\n\n", exit_status: 143, ] resource=<memory:1024, vCores:1> queue=default: capacity=1.0, absoluteCapacity=1.0, usedResources=<memory:3072, vCores:2>usedCapacity=0.0625, absoluteUsedCapacity=0.0625, numApps=1, numContainers=2 usedCapacity=0.0625 absoluteUsedCapacity=0.0625 used=<memory:3072, vCores:2> cluster=<memory:49152, vCores:96>
2013-08-10 18:05:07,182 INFO org.apache.hadoop.yarn.server.resourcemanager.scheduler.capacity.ParentQueue: completedContainer queue=root usedCapacity=0.0625 absoluteUsedCapacity=0.0625 used=<memory:3072, vCores:2> cluster=<memory:49152, vCores:96>
2013-08-10 18:05:07,182 INFO org.apache.hadoop.yarn.server.resourcemanager.scheduler.capacity.CapacityScheduler: Application appattempt_1376157310799_0003_000001 released container container_1376157310799_0003_01_000002 on node: host: hadoop-221-5:56475 #containers=0 available=8192 used=0 with event: FINISHED
2013-08-10 18:05:17,151 INFO org.apache.hadoop.yarn.server.resourcemanager.rmcontainer.RMContainerImpl: container_1376157310799_0003_01_000003 Container Transitioned from RUNNING to COMPLETED
2013-08-10 18:05:17,152 INFO org.apache.hadoop.yarn.server.resourcemanager.scheduler.common.fica.FiCaSchedulerApp: Completed container: container_1376157310799_0003_01_000003 in state: COMPLETED event:FINISHED
2013-08-10 18:05:17,152 INFO org.apache.hadoop.yarn.server.resourcemanager.RMAuditLogger: USER=ubuntu	OPERATION=AM Released Container	TARGET=SchedulerApp	RESULT=SUCCESS	APPID=application_1376157310799_0003	CONTAINERID=container_1376157310799_0003_01_000003
2013-08-10 18:05:17,152 INFO org.apache.hadoop.yarn.server.resourcemanager.scheduler.common.fica.FiCaSchedulerNode: Released container container_1376157310799_0003_01_000003 of capacity <memory:1024, vCores:1> on host hadoop-221-4:33277, which currently has 0 containers, <memory:0, vCores:0> used and <memory:8192, vCores:16> available, release resources=true
2013-08-10 18:05:17,152 INFO org.apache.hadoop.yarn.server.resourcemanager.scheduler.capacity.LeafQueue: default used=<memory:2048, vCores:1> numContainers=1 user=ubuntu user-resources=<memory:2048, vCores:1>
2013-08-10 18:05:17,154 INFO org.apache.hadoop.yarn.server.resourcemanager.scheduler.capacity.LeafQueue: completedContainer container=Container: [ContainerId: container_1376157310799_0003_01_000003, NodeId: hadoop-221-4:33277, NodeHttpAddress: hadoop-221-4:8042, Resource: <memory:1024, vCores:1>, Priority: 20, State: NEW, Token: null, Status: container_id {, app_attempt_id {, application_id {, id: 3, cluster_timestamp: 1376157310799, }, attemptId: 1, }, id: 3, }, state: C_COMPLETE, diagnostics: "Container killed by the ApplicationMaster.\n\n", exit_status: 143, ] resource=<memory:1024, vCores:1> queue=default: capacity=1.0, absoluteCapacity=1.0, usedResources=<memory:2048, vCores:1>usedCapacity=0.041666668, absoluteUsedCapacity=0.041666668, numApps=1, numContainers=1 usedCapacity=0.041666668 absoluteUsedCapacity=0.041666668 used=<memory:2048, vCores:1> cluster=<memory:49152, vCores:96>
2013-08-10 18:05:17,154 INFO org.apache.hadoop.yarn.server.resourcemanager.scheduler.capacity.ParentQueue: completedContainer queue=root usedCapacity=0.041666668 absoluteUsedCapacity=0.041666668 used=<memory:2048, vCores:1> cluster=<memory:49152, vCores:96>
2013-08-10 18:05:17,154 INFO org.apache.hadoop.yarn.server.resourcemanager.scheduler.capacity.CapacityScheduler: Application appattempt_1376157310799_0003_000001 released container container_1376157310799_0003_01_000003 on node: host: hadoop-221-4:33277 #containers=0 available=8192 used=0 with event: FINISHED
2013-08-10 18:05:21,314 INFO org.apache.hadoop.yarn.server.resourcemanager.rmapp.attempt.RMAppAttemptImpl: appattempt_1376157310799_0003_000001 State change from RUNNING to FINISHING
2013-08-10 18:05:21,315 INFO org.apache.hadoop.yarn.server.resourcemanager.rmapp.RMAppImpl: application_1376157310799_0003 State change from RUNNING to FINISHING
2013-08-10 18:05:21,593 INFO org.apache.hadoop.yarn.server.resourcemanager.rmcontainer.RMContainerImpl: container_1376157310799_0003_01_000001 Container Transitioned from RUNNING to COMPLETED
2013-08-10 18:05:21,593 INFO org.apache.hadoop.yarn.server.resourcemanager.scheduler.common.fica.FiCaSchedulerApp: Completed container: container_1376157310799_0003_01_000001 in state: COMPLETED event:FINISHED
2013-08-10 18:05:21,593 INFO org.apache.hadoop.yarn.server.resourcemanager.RMAuditLogger: USER=ubuntu	OPERATION=AM Released Container	TARGET=SchedulerApp	RESULT=SUCCESS	APPID=application_1376157310799_0003	CONTAINERID=container_1376157310799_0003_01_000001
2013-08-10 18:05:21,593 INFO org.apache.hadoop.yarn.server.resourcemanager.scheduler.common.fica.FiCaSchedulerNode: Released container container_1376157310799_0003_01_000001 of capacity <memory:2048, vCores:1> on host hadoop-221-3:38242, which currently has 0 containers, <memory:0, vCores:0> used and <memory:8192, vCores:16> available, release resources=true
2013-08-10 18:05:21,593 INFO org.apache.hadoop.yarn.server.resourcemanager.scheduler.capacity.LeafQueue: default used=<memory:0, vCores:0> numContainers=0 user=ubuntu user-resources=<memory:0, vCores:0>
2013-08-10 18:05:21,595 INFO org.apache.hadoop.yarn.server.resourcemanager.scheduler.capacity.LeafQueue: completedContainer container=Container: [ContainerId: container_1376157310799_0003_01_000001, NodeId: hadoop-221-3:38242, NodeHttpAddress: hadoop-221-3:8042, Resource: <memory:2048, vCores:1>, Priority: 0, State: NEW, Token: null, Status: container_id {, app_attempt_id {, application_id {, id: 3, cluster_timestamp: 1376157310799, }, attemptId: 1, }, id: 1, }, state: C_COMPLETE, diagnostics: "", exit_status: 0, ] resource=<memory:2048, vCores:1> queue=default: capacity=1.0, absoluteCapacity=1.0, usedResources=<memory:0, vCores:0>usedCapacity=0.0, absoluteUsedCapacity=0.0, numApps=1, numContainers=0 usedCapacity=0.0 absoluteUsedCapacity=0.0 used=<memory:0, vCores:0> cluster=<memory:49152, vCores:96>
2013-08-10 18:05:21,595 INFO org.apache.hadoop.yarn.server.resourcemanager.scheduler.capacity.ParentQueue: completedContainer queue=root usedCapacity=0.0 absoluteUsedCapacity=0.0 used=<memory:0, vCores:0> cluster=<memory:49152, vCores:96>
2013-08-10 18:05:21,595 INFO org.apache.hadoop.yarn.server.resourcemanager.scheduler.capacity.CapacityScheduler: Application appattempt_1376157310799_0003_000001 released container container_1376157310799_0003_01_000001 on node: host: hadoop-221-3:38242 #containers=0 available=8192 used=0 with event: FINISHED
2013-08-10 18:05:21,596 INFO org.apache.hadoop.yarn.server.resourcemanager.rmapp.attempt.RMAppAttemptImpl: appattempt_1376157310799_0003_000001 State change from FINISHING to FINISHED
2013-08-10 18:05:21,596 INFO org.apache.hadoop.yarn.server.resourcemanager.rmapp.RMAppImpl: application_1376157310799_0003 State change from FINISHING to FINISHED
2013-08-10 18:05:21,597 INFO org.apache.hadoop.yarn.server.resourcemanager.RMAuditLogger: USER=ubuntu	OPERATION=Application Finished - Succeeded	TARGET=RMAppManager	RESULT=SUCCESS	APPID=application_1376157310799_0003
2013-08-10 18:05:21,597 INFO org.apache.hadoop.yarn.server.resourcemanager.scheduler.capacity.CapacityScheduler: Application appattempt_1376157310799_0003_000001 is done. finalState=FINISHED
2013-08-10 18:05:21,597 INFO org.apache.hadoop.yarn.server.resourcemanager.scheduler.AppSchedulingInfo: Application application_1376157310799_0003 requests cleared
2013-08-10 18:05:21,597 INFO org.apache.hadoop.yarn.server.resourcemanager.scheduler.capacity.LeafQueue: Application removed - appId: application_1376157310799_0003 user: ubuntu queue: default #user-pending-applications: 0 #user-active-applications: 0 #queue-pending-applications: 0 #queue-active-applications: 0
2013-08-10 18:05:21,597 INFO org.apache.hadoop.yarn.server.resourcemanager.scheduler.capacity.ParentQueue: Application removed - appId: application_1376157310799_0003 user: ubuntu leaf-queue of parent: root #applications: 0
2013-08-10 18:05:21,598 INFO org.apache.hadoop.yarn.server.resourcemanager.recovery.RMStateStore: Removing info for app: application_1376157310799_0003
2013-08-10 18:05:21,598 INFO org.apache.hadoop.yarn.server.resourcemanager.RMAppManager$ApplicationSummary: appId=application_1376157310799_0003,name=TeraGen,user=ubuntu,queue=default,state=FINISHED,trackingUrl=hadoop-221-1.novalocal:8088/proxy/application_1376157310799_0003/jobhistory/job/job_1376157310799_0003,appMasterHost=hadoop-221-3,startTime=1376157742350,finishTime=1376157921315
2013-08-10 18:05:21,599 INFO org.apache.hadoop.yarn.server.resourcemanager.amlauncher.AMLauncher: Cleaning master appattempt_1376157310799_0003_000001
2013-08-10 18:05:22,661 INFO org.apache.hadoop.yarn.server.resourcemanager.ClientRMService: Allocated new applicationId: 4
2013-08-10 18:05:24,590 INFO org.apache.hadoop.yarn.server.resourcemanager.ClientRMService: Storing Application with id application_1376157310799_0004
2013-08-10 18:05:24,590 INFO org.apache.hadoop.yarn.server.resourcemanager.recovery.RMStateStore: Storing info for app: application_1376157310799_0004
2013-08-10 18:05:24,590 INFO org.apache.hadoop.yarn.server.resourcemanager.ClientRMService: Application with id 4 submitted by user ubuntu
2013-08-10 18:05:24,590 INFO org.apache.hadoop.yarn.server.resourcemanager.RMAuditLogger: USER=ubuntu	IP=192.168.100.24	OPERATION=Submit Application Request	TARGET=ClientRMService	RESULT=SUCCESS	APPID=application_1376157310799_0004
2013-08-10 18:05:24,591 INFO org.apache.hadoop.yarn.server.resourcemanager.rmapp.RMAppImpl: application_1376157310799_0004 State change from NEW to SUBMITTED
2013-08-10 18:05:24,592 INFO org.apache.hadoop.yarn.server.resourcemanager.ApplicationMasterService: Registering appattempt_1376157310799_0004_000001
2013-08-10 18:05:24,592 INFO org.apache.hadoop.yarn.server.resourcemanager.rmapp.attempt.RMAppAttemptImpl: appattempt_1376157310799_0004_000001 State change from NEW to SUBMITTED
2013-08-10 18:05:24,592 INFO org.apache.hadoop.yarn.server.resourcemanager.scheduler.capacity.LeafQueue: Application application_1376157310799_0004 from user: ubuntu activated in queue: default
2013-08-10 18:05:24,593 INFO org.apache.hadoop.yarn.server.resourcemanager.scheduler.capacity.LeafQueue: Application added - appId: application_1376157310799_0004 user: org.apache.hadoop.yarn.server.resourcemanager.scheduler.capacity.LeafQueue$User@38359154, leaf-queue: default #user-pending-applications: 0 #user-active-applications: 1 #queue-pending-applications: 0 #queue-active-applications: 1
2013-08-10 18:05:24,593 INFO org.apache.hadoop.yarn.server.resourcemanager.scheduler.capacity.ParentQueue: Application added - appId: application_1376157310799_0004 user: ubuntu leaf-queue of parent: root #applications: 1
2013-08-10 18:05:24,593 INFO org.apache.hadoop.yarn.server.resourcemanager.scheduler.capacity.CapacityScheduler: Application Submission: appattempt_1376157310799_0004_000001, user: ubuntu queue: default: capacity=1.0, absoluteCapacity=1.0, usedResources=<memory:0, vCores:0>usedCapacity=0.0, absoluteUsedCapacity=0.0, numApps=1, numContainers=0, currently active: 1
2013-08-10 18:05:24,593 INFO org.apache.hadoop.yarn.server.resourcemanager.rmapp.attempt.RMAppAttemptImpl: appattempt_1376157310799_0004_000001 State change from SUBMITTED to SCHEDULED
2013-08-10 18:05:24,593 INFO org.apache.hadoop.yarn.server.resourcemanager.rmapp.RMAppImpl: application_1376157310799_0004 State change from SUBMITTED to ACCEPTED
2013-08-10 18:05:24,605 INFO org.apache.hadoop.yarn.server.resourcemanager.rmcontainer.RMContainerImpl: container_1376157310799_0004_01_000001 Container Transitioned from NEW to ALLOCATED
2013-08-10 18:05:24,605 INFO org.apache.hadoop.yarn.server.resourcemanager.RMAuditLogger: USER=ubuntu	OPERATION=AM Allocated Container	TARGET=SchedulerApp	RESULT=SUCCESS	APPID=application_1376157310799_0004	CONTAINERID=container_1376157310799_0004_01_000001
2013-08-10 18:05:24,606 INFO org.apache.hadoop.yarn.server.resourcemanager.scheduler.common.fica.FiCaSchedulerNode: Assigned container container_1376157310799_0004_01_000001 of capacity <memory:2048, vCores:1> on host hadoop-221-3:38242, which currently has 1 containers, <memory:2048, vCores:1> used and <memory:6144, vCores:15> available
2013-08-10 18:05:24,607 INFO org.apache.hadoop.yarn.server.resourcemanager.scheduler.capacity.LeafQueue: assignedContainer application=application_1376157310799_0004 container=Container: [ContainerId: container_1376157310799_0004_01_000001, NodeId: hadoop-221-3:38242, NodeHttpAddress: hadoop-221-3:8042, Resource: <memory:2048, vCores:1>, Priority: 0, State: NEW, Token: null, Status: container_id {, app_attempt_id {, application_id {, id: 4, cluster_timestamp: 1376157310799, }, attemptId: 1, }, id: 1, }, state: C_NEW, ] containerId=container_1376157310799_0004_01_000001 queue=default: capacity=1.0, absoluteCapacity=1.0, usedResources=<memory:0, vCores:0>usedCapacity=0.0, absoluteUsedCapacity=0.0, numApps=1, numContainers=0 usedCapacity=0.0 absoluteUsedCapacity=0.0 used=<memory:0, vCores:0> cluster=<memory:49152, vCores:96>
2013-08-10 18:05:24,607 INFO org.apache.hadoop.yarn.server.resourcemanager.scheduler.capacity.ParentQueue: Re-sorting queues since queue: root.default stats: default: capacity=1.0, absoluteCapacity=1.0, usedResources=<memory:2048, vCores:1>usedCapacity=0.041666668, absoluteUsedCapacity=0.041666668, numApps=1, numContainers=1
2013-08-10 18:05:24,607 INFO org.apache.hadoop.yarn.server.resourcemanager.scheduler.capacity.ParentQueue: assignedContainer queue=root usedCapacity=0.041666668 absoluteUsedCapacity=0.041666668 used=<memory:2048, vCores:1> cluster=<memory:49152, vCores:96>
2013-08-10 18:05:24,609 INFO org.apache.hadoop.yarn.server.resourcemanager.rmcontainer.RMContainerImpl: container_1376157310799_0004_01_000001 Container Transitioned from ALLOCATED to ACQUIRED
2013-08-10 18:05:24,611 INFO org.apache.hadoop.yarn.server.resourcemanager.rmapp.attempt.RMAppAttemptImpl: Storing attempt: AppId: application_1376157310799_0004 AttemptId: appattempt_1376157310799_0004_000001 MasterContainer: Container: [ContainerId: container_1376157310799_0004_01_000001, NodeId: hadoop-221-3:38242, NodeHttpAddress: hadoop-221-3:8042, Resource: <memory:2048, vCores:1>, Priority: 0, State: NEW, Token: null, Status: container_id {, app_attempt_id {, application_id {, id: 4, cluster_timestamp: 1376157310799, }, attemptId: 1, }, id: 1, }, state: C_NEW, ]
2013-08-10 18:05:24,611 INFO org.apache.hadoop.yarn.server.resourcemanager.rmapp.attempt.RMAppAttemptImpl: appattempt_1376157310799_0004_000001 State change from SCHEDULED to ALLOCATED_SAVING
2013-08-10 18:05:24,611 INFO org.apache.hadoop.yarn.server.resourcemanager.recovery.RMStateStore: Storing info for attempt: appattempt_1376157310799_0004_000001
2013-08-10 18:05:24,613 INFO org.apache.hadoop.yarn.server.resourcemanager.rmapp.attempt.RMAppAttemptImpl: appattempt_1376157310799_0004_000001 State change from ALLOCATED_SAVING to ALLOCATED
2013-08-10 18:05:24,615 INFO org.apache.hadoop.yarn.server.resourcemanager.amlauncher.AMLauncher: Launching masterappattempt_1376157310799_0004_000001
2013-08-10 18:05:24,617 INFO org.apache.hadoop.yarn.server.resourcemanager.amlauncher.AMLauncher: Setting up container Container: [ContainerId: container_1376157310799_0004_01_000001, NodeId: hadoop-221-3:38242, NodeHttpAddress: hadoop-221-3:8042, Resource: <memory:2048, vCores:1>, Priority: 0, State: NEW, Token: null, Status: container_id {, app_attempt_id {, application_id {, id: 4, cluster_timestamp: 1376157310799, }, attemptId: 1, }, id: 1, }, state: C_NEW, ] for AM appattempt_1376157310799_0004_000001
2013-08-10 18:05:24,618 INFO org.apache.hadoop.yarn.server.resourcemanager.amlauncher.AMLauncher: Command to launch container container_1376157310799_0004_01_000001 : $JAVA_HOME/bin/java -Dlog4j.configuration=container-log4j.properties -Dyarn.app.mapreduce.container.log.dir=<LOG_DIR> -Dyarn.app.mapreduce.container.log.filesize=0 -Dhadoop.root.logger=INFO,CLA  -Xmx1024m org.apache.hadoop.mapreduce.v2.app.MRAppMaster 1><LOG_DIR>/stdout 2><LOG_DIR>/stderr 
2013-08-10 18:05:24,637 INFO org.apache.hadoop.yarn.server.resourcemanager.amlauncher.AMLauncher: Done launching container Container: [ContainerId: container_1376157310799_0004_01_000001, NodeId: hadoop-221-3:38242, NodeHttpAddress: hadoop-221-3:8042, Resource: <memory:2048, vCores:1>, Priority: 0, State: NEW, Token: null, Status: container_id {, app_attempt_id {, application_id {, id: 4, cluster_timestamp: 1376157310799, }, attemptId: 1, }, id: 1, }, state: C_NEW, ] for AM appattempt_1376157310799_0004_000001
2013-08-10 18:05:24,638 INFO org.apache.hadoop.yarn.server.resourcemanager.rmapp.attempt.RMAppAttemptImpl: appattempt_1376157310799_0004_000001 State change from ALLOCATED to LAUNCHED
2013-08-10 18:05:25,611 INFO org.apache.hadoop.yarn.server.resourcemanager.rmcontainer.RMContainerImpl: container_1376157310799_0004_01_000001 Container Transitioned from ACQUIRED to RUNNING
2013-08-10 18:05:30,178 INFO org.apache.hadoop.yarn.server.resourcemanager.ApplicationMasterService: AM registration appattempt_1376157310799_0004_000001
2013-08-10 18:05:30,179 INFO org.apache.hadoop.yarn.server.resourcemanager.RMAuditLogger: USER=ubuntu	IP=192.168.100.26	OPERATION=Register App Master	TARGET=ApplicationMasterService	RESULT=SUCCESS	APPID=application_1376157310799_0004	APPATTEMPTID=appattempt_1376157310799_0004_000001
2013-08-10 18:05:30,180 INFO org.apache.hadoop.yarn.server.resourcemanager.rmapp.attempt.RMAppAttemptImpl: appattempt_1376157310799_0004_000001 State change from LAUNCHED to RUNNING
2013-08-10 18:05:30,180 INFO org.apache.hadoop.yarn.server.resourcemanager.rmapp.RMAppImpl: application_1376157310799_0004 State change from ACCEPTED to RUNNING
2013-08-10 18:05:31,258 INFO org.apache.hadoop.yarn.server.resourcemanager.rmcontainer.RMContainerImpl: container_1376157310799_0004_01_000002 Container Transitioned from NEW to ALLOCATED
2013-08-10 18:05:31,259 INFO org.apache.hadoop.yarn.server.resourcemanager.RMAuditLogger: USER=ubuntu	OPERATION=AM Allocated Container	TARGET=SchedulerApp	RESULT=SUCCESS	APPID=application_1376157310799_0004	CONTAINERID=container_1376157310799_0004_01_000002
2013-08-10 18:05:31,259 INFO org.apache.hadoop.yarn.server.resourcemanager.scheduler.common.fica.FiCaSchedulerNode: Assigned container container_1376157310799_0004_01_000002 of capacity <memory:1024, vCores:1> on host hadoop-221-5:56475, which currently has 1 containers, <memory:1024, vCores:1> used and <memory:7168, vCores:15> available
2013-08-10 18:05:31,260 INFO org.apache.hadoop.yarn.server.resourcemanager.scheduler.capacity.LeafQueue: assignedContainer application=application_1376157310799_0004 container=Container: [ContainerId: container_1376157310799_0004_01_000002, NodeId: hadoop-221-5:56475, NodeHttpAddress: hadoop-221-5:8042, Resource: <memory:1024, vCores:1>, Priority: 20, State: NEW, Token: null, Status: container_id {, app_attempt_id {, application_id {, id: 4, cluster_timestamp: 1376157310799, }, attemptId: 1, }, id: 2, }, state: C_NEW, ] containerId=container_1376157310799_0004_01_000002 queue=default: capacity=1.0, absoluteCapacity=1.0, usedResources=<memory:2048, vCores:1>usedCapacity=0.041666668, absoluteUsedCapacity=0.041666668, numApps=1, numContainers=1 usedCapacity=0.041666668 absoluteUsedCapacity=0.041666668 used=<memory:2048, vCores:1> cluster=<memory:49152, vCores:96>
2013-08-10 18:05:31,260 INFO org.apache.hadoop.yarn.server.resourcemanager.scheduler.capacity.ParentQueue: Re-sorting queues since queue: root.default stats: default: capacity=1.0, absoluteCapacity=1.0, usedResources=<memory:3072, vCores:2>usedCapacity=0.0625, absoluteUsedCapacity=0.0625, numApps=1, numContainers=2
2013-08-10 18:05:31,261 INFO org.apache.hadoop.yarn.server.resourcemanager.scheduler.capacity.ParentQueue: assignedContainer queue=root usedCapacity=0.0625 absoluteUsedCapacity=0.0625 used=<memory:3072, vCores:2> cluster=<memory:49152, vCores:96>
2013-08-10 18:05:31,337 INFO org.apache.hadoop.yarn.server.resourcemanager.rmcontainer.RMContainerImpl: container_1376157310799_0004_01_000003 Container Transitioned from NEW to ALLOCATED
2013-08-10 18:05:31,337 INFO org.apache.hadoop.yarn.server.resourcemanager.RMAuditLogger: USER=ubuntu	OPERATION=AM Allocated Container	TARGET=SchedulerApp	RESULT=SUCCESS	APPID=application_1376157310799_0004	CONTAINERID=container_1376157310799_0004_01_000003
2013-08-10 18:05:31,337 INFO org.apache.hadoop.yarn.server.resourcemanager.scheduler.common.fica.FiCaSchedulerNode: Assigned container container_1376157310799_0004_01_000003 of capacity <memory:1024, vCores:1> on host hadoop-221-6:39509, which currently has 1 containers, <memory:1024, vCores:1> used and <memory:7168, vCores:15> available
2013-08-10 18:05:31,338 INFO org.apache.hadoop.yarn.server.resourcemanager.scheduler.capacity.LeafQueue: assignedContainer application=application_1376157310799_0004 container=Container: [ContainerId: container_1376157310799_0004_01_000003, NodeId: hadoop-221-6:39509, NodeHttpAddress: hadoop-221-6:8042, Resource: <memory:1024, vCores:1>, Priority: 20, State: NEW, Token: null, Status: container_id {, app_attempt_id {, application_id {, id: 4, cluster_timestamp: 1376157310799, }, attemptId: 1, }, id: 3, }, state: C_NEW, ] containerId=container_1376157310799_0004_01_000003 queue=default: capacity=1.0, absoluteCapacity=1.0, usedResources=<memory:3072, vCores:2>usedCapacity=0.0625, absoluteUsedCapacity=0.0625, numApps=1, numContainers=2 usedCapacity=0.0625 absoluteUsedCapacity=0.0625 used=<memory:3072, vCores:2> cluster=<memory:49152, vCores:96>
2013-08-10 18:05:31,339 INFO org.apache.hadoop.yarn.server.resourcemanager.scheduler.capacity.ParentQueue: Re-sorting queues since queue: root.default stats: default: capacity=1.0, absoluteCapacity=1.0, usedResources=<memory:4096, vCores:3>usedCapacity=0.083333336, absoluteUsedCapacity=0.083333336, numApps=1, numContainers=3
2013-08-10 18:05:31,339 INFO org.apache.hadoop.yarn.server.resourcemanager.scheduler.capacity.ParentQueue: assignedContainer queue=root usedCapacity=0.083333336 absoluteUsedCapacity=0.083333336 used=<memory:4096, vCores:3> cluster=<memory:49152, vCores:96>
2013-08-10 18:05:32,239 INFO org.apache.hadoop.yarn.server.resourcemanager.rmcontainer.RMContainerImpl: container_1376157310799_0004_01_000002 Container Transitioned from ALLOCATED to ACQUIRED
2013-08-10 18:05:32,246 INFO org.apache.hadoop.yarn.server.resourcemanager.rmcontainer.RMContainerImpl: container_1376157310799_0004_01_000003 Container Transitioned from ALLOCATED to ACQUIRED
2013-08-10 18:05:33,267 INFO org.apache.hadoop.yarn.server.resourcemanager.rmcontainer.RMContainerImpl: container_1376157310799_0004_01_000002 Container Transitioned from ACQUIRED to RUNNING
2013-08-10 18:05:33,275 INFO org.apache.hadoop.yarn.server.resourcemanager.scheduler.AppSchedulingInfo: checking for deactivate... 
2013-08-10 18:05:33,352 INFO org.apache.hadoop.yarn.server.resourcemanager.rmcontainer.RMContainerImpl: container_1376157310799_0004_01_000003 Container Transitioned from ACQUIRED to RUNNING
2013-08-10 18:08:17,818 INFO org.apache.hadoop.yarn.server.resourcemanager.rmcontainer.RMContainerImpl: container_1376157310799_0004_01_000003 Container Transitioned from RUNNING to COMPLETED
2013-08-10 18:08:17,818 INFO org.apache.hadoop.yarn.server.resourcemanager.scheduler.common.fica.FiCaSchedulerApp: Completed container: container_1376157310799_0004_01_000003 in state: COMPLETED event:FINISHED
2013-08-10 18:08:17,818 INFO org.apache.hadoop.yarn.server.resourcemanager.RMAuditLogger: USER=ubuntu	OPERATION=AM Released Container	TARGET=SchedulerApp	RESULT=SUCCESS	APPID=application_1376157310799_0004	CONTAINERID=container_1376157310799_0004_01_000003
2013-08-10 18:08:17,818 INFO org.apache.hadoop.yarn.server.resourcemanager.scheduler.common.fica.FiCaSchedulerNode: Released container container_1376157310799_0004_01_000003 of capacity <memory:1024, vCores:1> on host hadoop-221-6:39509, which currently has 0 containers, <memory:0, vCores:0> used and <memory:8192, vCores:16> available, release resources=true
2013-08-10 18:08:17,818 INFO org.apache.hadoop.yarn.server.resourcemanager.scheduler.capacity.LeafQueue: default used=<memory:3072, vCores:2> numContainers=2 user=ubuntu user-resources=<memory:3072, vCores:2>
2013-08-10 18:08:17,820 INFO org.apache.hadoop.yarn.server.resourcemanager.scheduler.capacity.LeafQueue: completedContainer container=Container: [ContainerId: container_1376157310799_0004_01_000003, NodeId: hadoop-221-6:39509, NodeHttpAddress: hadoop-221-6:8042, Resource: <memory:1024, vCores:1>, Priority: 20, State: NEW, Token: null, Status: container_id {, app_attempt_id {, application_id {, id: 4, cluster_timestamp: 1376157310799, }, attemptId: 1, }, id: 3, }, state: C_COMPLETE, diagnostics: "Container killed by the ApplicationMaster.\n\n", exit_status: 143, ] resource=<memory:1024, vCores:1> queue=default: capacity=1.0, absoluteCapacity=1.0, usedResources=<memory:3072, vCores:2>usedCapacity=0.0625, absoluteUsedCapacity=0.0625, numApps=1, numContainers=2 usedCapacity=0.0625 absoluteUsedCapacity=0.0625 used=<memory:3072, vCores:2> cluster=<memory:49152, vCores:96>
2013-08-10 18:08:17,820 INFO org.apache.hadoop.yarn.server.resourcemanager.scheduler.capacity.ParentQueue: completedContainer queue=root usedCapacity=0.0625 absoluteUsedCapacity=0.0625 used=<memory:3072, vCores:2> cluster=<memory:49152, vCores:96>
2013-08-10 18:08:17,821 INFO org.apache.hadoop.yarn.server.resourcemanager.scheduler.capacity.CapacityScheduler: Application appattempt_1376157310799_0004_000001 released container container_1376157310799_0004_01_000003 on node: host: hadoop-221-6:39509 #containers=0 available=8192 used=0 with event: FINISHED
2013-08-10 18:08:18,139 INFO org.apache.hadoop.yarn.server.resourcemanager.rmcontainer.RMContainerImpl: container_1376157310799_0004_01_000002 Container Transitioned from RUNNING to COMPLETED
2013-08-10 18:08:18,139 INFO org.apache.hadoop.yarn.server.resourcemanager.scheduler.common.fica.FiCaSchedulerApp: Completed container: container_1376157310799_0004_01_000002 in state: COMPLETED event:FINISHED
2013-08-10 18:08:18,139 INFO org.apache.hadoop.yarn.server.resourcemanager.RMAuditLogger: USER=ubuntu	OPERATION=AM Released Container	TARGET=SchedulerApp	RESULT=SUCCESS	APPID=application_1376157310799_0004	CONTAINERID=container_1376157310799_0004_01_000002
2013-08-10 18:08:18,139 INFO org.apache.hadoop.yarn.server.resourcemanager.scheduler.common.fica.FiCaSchedulerNode: Released container container_1376157310799_0004_01_000002 of capacity <memory:1024, vCores:1> on host hadoop-221-5:56475, which currently has 0 containers, <memory:0, vCores:0> used and <memory:8192, vCores:16> available, release resources=true
2013-08-10 18:08:18,140 INFO org.apache.hadoop.yarn.server.resourcemanager.scheduler.capacity.LeafQueue: default used=<memory:2048, vCores:1> numContainers=1 user=ubuntu user-resources=<memory:2048, vCores:1>
2013-08-10 18:08:18,141 INFO org.apache.hadoop.yarn.server.resourcemanager.scheduler.capacity.LeafQueue: completedContainer container=Container: [ContainerId: container_1376157310799_0004_01_000002, NodeId: hadoop-221-5:56475, NodeHttpAddress: hadoop-221-5:8042, Resource: <memory:1024, vCores:1>, Priority: 20, State: NEW, Token: null, Status: container_id {, app_attempt_id {, application_id {, id: 4, cluster_timestamp: 1376157310799, }, attemptId: 1, }, id: 2, }, state: C_COMPLETE, diagnostics: "Container killed by the ApplicationMaster.\n\n", exit_status: 143, ] resource=<memory:1024, vCores:1> queue=default: capacity=1.0, absoluteCapacity=1.0, usedResources=<memory:2048, vCores:1>usedCapacity=0.041666668, absoluteUsedCapacity=0.041666668, numApps=1, numContainers=1 usedCapacity=0.041666668 absoluteUsedCapacity=0.041666668 used=<memory:2048, vCores:1> cluster=<memory:49152, vCores:96>
2013-08-10 18:08:18,141 INFO org.apache.hadoop.yarn.server.resourcemanager.scheduler.capacity.ParentQueue: completedContainer queue=root usedCapacity=0.041666668 absoluteUsedCapacity=0.041666668 used=<memory:2048, vCores:1> cluster=<memory:49152, vCores:96>
2013-08-10 18:08:18,142 INFO org.apache.hadoop.yarn.server.resourcemanager.scheduler.capacity.CapacityScheduler: Application appattempt_1376157310799_0004_000001 released container container_1376157310799_0004_01_000002 on node: host: hadoop-221-5:56475 #containers=0 available=8192 used=0 with event: FINISHED
2013-08-10 18:08:22,293 INFO org.apache.hadoop.yarn.server.resourcemanager.rmapp.attempt.RMAppAttemptImpl: appattempt_1376157310799_0004_000001 State change from RUNNING to FINISHING
2013-08-10 18:08:22,294 INFO org.apache.hadoop.yarn.server.resourcemanager.rmapp.RMAppImpl: application_1376157310799_0004 State change from RUNNING to FINISHING
2013-08-10 18:08:23,237 INFO org.apache.hadoop.yarn.server.resourcemanager.rmcontainer.RMContainerImpl: container_1376157310799_0004_01_000001 Container Transitioned from RUNNING to COMPLETED
2013-08-10 18:08:23,237 INFO org.apache.hadoop.yarn.server.resourcemanager.scheduler.common.fica.FiCaSchedulerApp: Completed container: container_1376157310799_0004_01_000001 in state: COMPLETED event:FINISHED
2013-08-10 18:08:23,237 INFO org.apache.hadoop.yarn.server.resourcemanager.rmapp.attempt.RMAppAttemptImpl: appattempt_1376157310799_0004_000001 State change from FINISHING to FINISHED
2013-08-10 18:08:23,237 INFO org.apache.hadoop.yarn.server.resourcemanager.RMAuditLogger: USER=ubuntu	OPERATION=AM Released Container	TARGET=SchedulerApp	RESULT=SUCCESS	APPID=application_1376157310799_0004	CONTAINERID=container_1376157310799_0004_01_000001
2013-08-10 18:08:23,237 INFO org.apache.hadoop.yarn.server.resourcemanager.rmapp.RMAppImpl: application_1376157310799_0004 State change from FINISHING to FINISHED
2013-08-10 18:08:23,237 INFO org.apache.hadoop.yarn.server.resourcemanager.scheduler.common.fica.FiCaSchedulerNode: Released container container_1376157310799_0004_01_000001 of capacity <memory:2048, vCores:1> on host hadoop-221-3:38242, which currently has 0 containers, <memory:0, vCores:0> used and <memory:8192, vCores:16> available, release resources=true
2013-08-10 18:08:23,238 INFO org.apache.hadoop.yarn.server.resourcemanager.scheduler.capacity.LeafQueue: default used=<memory:0, vCores:0> numContainers=0 user=ubuntu user-resources=<memory:0, vCores:0>
2013-08-10 18:08:23,238 INFO org.apache.hadoop.yarn.server.resourcemanager.RMAuditLogger: USER=ubuntu	OPERATION=Application Finished - Succeeded	TARGET=RMAppManager	RESULT=SUCCESS	APPID=application_1376157310799_0004
2013-08-10 18:08:23,239 INFO org.apache.hadoop.yarn.server.resourcemanager.amlauncher.AMLauncher: Cleaning master appattempt_1376157310799_0004_000001
2013-08-10 18:08:23,239 INFO org.apache.hadoop.yarn.server.resourcemanager.recovery.RMStateStore: Removing info for app: application_1376157310799_0004
2013-08-10 18:08:23,239 INFO org.apache.hadoop.yarn.server.resourcemanager.RMAppManager$ApplicationSummary: appId=application_1376157310799_0004,name=TeraGen,user=ubuntu,queue=default,state=FINISHED,trackingUrl=hadoop-221-1.novalocal:8088/proxy/application_1376157310799_0004/jobhistory/job/job_1376157310799_0004,appMasterHost=hadoop-221-3,startTime=1376157924589,finishTime=1376158102294
2013-08-10 18:08:23,239 INFO org.apache.hadoop.yarn.server.resourcemanager.scheduler.capacity.LeafQueue: completedContainer container=Container: [ContainerId: container_1376157310799_0004_01_000001, NodeId: hadoop-221-3:38242, NodeHttpAddress: hadoop-221-3:8042, Resource: <memory:2048, vCores:1>, Priority: 0, State: NEW, Token: null, Status: container_id {, app_attempt_id {, application_id {, id: 4, cluster_timestamp: 1376157310799, }, attemptId: 1, }, id: 1, }, state: C_COMPLETE, diagnostics: "", exit_status: 0, ] resource=<memory:2048, vCores:1> queue=default: capacity=1.0, absoluteCapacity=1.0, usedResources=<memory:0, vCores:0>usedCapacity=0.0, absoluteUsedCapacity=0.0, numApps=1, numContainers=0 usedCapacity=0.0 absoluteUsedCapacity=0.0 used=<memory:0, vCores:0> cluster=<memory:49152, vCores:96>
2013-08-10 18:08:23,239 INFO org.apache.hadoop.yarn.server.resourcemanager.scheduler.capacity.ParentQueue: completedContainer queue=root usedCapacity=0.0 absoluteUsedCapacity=0.0 used=<memory:0, vCores:0> cluster=<memory:49152, vCores:96>
2013-08-10 18:08:23,240 INFO org.apache.hadoop.yarn.server.resourcemanager.scheduler.capacity.CapacityScheduler: Application appattempt_1376157310799_0004_000001 released container container_1376157310799_0004_01_000001 on node: host: hadoop-221-3:38242 #containers=0 available=8192 used=0 with event: FINISHED
2013-08-10 18:08:23,240 INFO org.apache.hadoop.yarn.server.resourcemanager.scheduler.capacity.CapacityScheduler: Application appattempt_1376157310799_0004_000001 is done. finalState=FINISHED
2013-08-10 18:08:23,240 INFO org.apache.hadoop.yarn.server.resourcemanager.scheduler.AppSchedulingInfo: Application application_1376157310799_0004 requests cleared
2013-08-10 18:08:23,240 INFO org.apache.hadoop.yarn.server.resourcemanager.scheduler.capacity.LeafQueue: Application removed - appId: application_1376157310799_0004 user: ubuntu queue: default #user-pending-applications: 0 #user-active-applications: 0 #queue-pending-applications: 0 #queue-active-applications: 0
2013-08-10 18:08:23,240 INFO org.apache.hadoop.yarn.server.resourcemanager.scheduler.capacity.ParentQueue: Application removed - appId: application_1376157310799_0004 user: ubuntu leaf-queue of parent: root #applications: 0
2013-08-10 18:08:24,308 INFO org.apache.hadoop.yarn.server.resourcemanager.ClientRMService: Allocated new applicationId: 5
2013-08-10 18:08:27,073 INFO org.apache.hadoop.yarn.server.resourcemanager.ClientRMService: Storing Application with id application_1376157310799_0005
2013-08-10 18:08:27,073 INFO org.apache.hadoop.yarn.server.resourcemanager.recovery.RMStateStore: Storing info for app: application_1376157310799_0005
2013-08-10 18:08:27,074 INFO org.apache.hadoop.yarn.server.resourcemanager.ClientRMService: Application with id 5 submitted by user ubuntu
2013-08-10 18:08:27,074 INFO org.apache.hadoop.yarn.server.resourcemanager.RMAuditLogger: USER=ubuntu	IP=192.168.100.24	OPERATION=Submit Application Request	TARGET=ClientRMService	RESULT=SUCCESS	APPID=application_1376157310799_0005
2013-08-10 18:08:27,075 INFO org.apache.hadoop.yarn.server.resourcemanager.rmapp.RMAppImpl: application_1376157310799_0005 State change from NEW to SUBMITTED
2013-08-10 18:08:27,075 INFO org.apache.hadoop.yarn.server.resourcemanager.ApplicationMasterService: Registering appattempt_1376157310799_0005_000001
2013-08-10 18:08:27,075 INFO org.apache.hadoop.yarn.server.resourcemanager.rmapp.attempt.RMAppAttemptImpl: appattempt_1376157310799_0005_000001 State change from NEW to SUBMITTED
2013-08-10 18:08:27,076 INFO org.apache.hadoop.yarn.server.resourcemanager.scheduler.capacity.LeafQueue: Application application_1376157310799_0005 from user: ubuntu activated in queue: default
2013-08-10 18:08:27,076 INFO org.apache.hadoop.yarn.server.resourcemanager.scheduler.capacity.LeafQueue: Application added - appId: application_1376157310799_0005 user: org.apache.hadoop.yarn.server.resourcemanager.scheduler.capacity.LeafQueue$User@62e3d8e8, leaf-queue: default #user-pending-applications: 0 #user-active-applications: 1 #queue-pending-applications: 0 #queue-active-applications: 1
2013-08-10 18:08:27,076 INFO org.apache.hadoop.yarn.server.resourcemanager.scheduler.capacity.ParentQueue: Application added - appId: application_1376157310799_0005 user: ubuntu leaf-queue of parent: root #applications: 1
2013-08-10 18:08:27,076 INFO org.apache.hadoop.yarn.server.resourcemanager.scheduler.capacity.CapacityScheduler: Application Submission: appattempt_1376157310799_0005_000001, user: ubuntu queue: default: capacity=1.0, absoluteCapacity=1.0, usedResources=<memory:0, vCores:0>usedCapacity=0.0, absoluteUsedCapacity=0.0, numApps=1, numContainers=0, currently active: 1
2013-08-10 18:08:27,077 INFO org.apache.hadoop.yarn.server.resourcemanager.rmapp.attempt.RMAppAttemptImpl: appattempt_1376157310799_0005_000001 State change from SUBMITTED to SCHEDULED
2013-08-10 18:08:27,077 INFO org.apache.hadoop.yarn.server.resourcemanager.rmapp.RMAppImpl: application_1376157310799_0005 State change from SUBMITTED to ACCEPTED
2013-08-10 18:08:27,159 INFO org.apache.hadoop.yarn.server.resourcemanager.rmcontainer.RMContainerImpl: container_1376157310799_0005_01_000001 Container Transitioned from NEW to ALLOCATED
2013-08-10 18:08:27,159 INFO org.apache.hadoop.yarn.server.resourcemanager.RMAuditLogger: USER=ubuntu	OPERATION=AM Allocated Container	TARGET=SchedulerApp	RESULT=SUCCESS	APPID=application_1376157310799_0005	CONTAINERID=container_1376157310799_0005_01_000001
2013-08-10 18:08:27,159 INFO org.apache.hadoop.yarn.server.resourcemanager.scheduler.common.fica.FiCaSchedulerNode: Assigned container container_1376157310799_0005_01_000001 of capacity <memory:2048, vCores:1> on host hadoop-221-4:33277, which currently has 1 containers, <memory:2048, vCores:1> used and <memory:6144, vCores:15> available
2013-08-10 18:08:27,161 INFO org.apache.hadoop.yarn.server.resourcemanager.scheduler.capacity.LeafQueue: assignedContainer application=application_1376157310799_0005 container=Container: [ContainerId: container_1376157310799_0005_01_000001, NodeId: hadoop-221-4:33277, NodeHttpAddress: hadoop-221-4:8042, Resource: <memory:2048, vCores:1>, Priority: 0, State: NEW, Token: null, Status: container_id {, app_attempt_id {, application_id {, id: 5, cluster_timestamp: 1376157310799, }, attemptId: 1, }, id: 1, }, state: C_NEW, ] containerId=container_1376157310799_0005_01_000001 queue=default: capacity=1.0, absoluteCapacity=1.0, usedResources=<memory:0, vCores:0>usedCapacity=0.0, absoluteUsedCapacity=0.0, numApps=1, numContainers=0 usedCapacity=0.0 absoluteUsedCapacity=0.0 used=<memory:0, vCores:0> cluster=<memory:49152, vCores:96>
2013-08-10 18:08:27,161 INFO org.apache.hadoop.yarn.server.resourcemanager.scheduler.capacity.ParentQueue: Re-sorting queues since queue: root.default stats: default: capacity=1.0, absoluteCapacity=1.0, usedResources=<memory:2048, vCores:1>usedCapacity=0.041666668, absoluteUsedCapacity=0.041666668, numApps=1, numContainers=1
2013-08-10 18:08:27,162 INFO org.apache.hadoop.yarn.server.resourcemanager.rmcontainer.RMContainerImpl: container_1376157310799_0005_01_000001 Container Transitioned from ALLOCATED to ACQUIRED
2013-08-10 18:08:27,163 INFO org.apache.hadoop.yarn.server.resourcemanager.scheduler.capacity.ParentQueue: assignedContainer queue=root usedCapacity=0.041666668 absoluteUsedCapacity=0.041666668 used=<memory:2048, vCores:1> cluster=<memory:49152, vCores:96>
2013-08-10 18:08:27,164 INFO org.apache.hadoop.yarn.server.resourcemanager.rmapp.attempt.RMAppAttemptImpl: Storing attempt: AppId: application_1376157310799_0005 AttemptId: appattempt_1376157310799_0005_000001 MasterContainer: Container: [ContainerId: container_1376157310799_0005_01_000001, NodeId: hadoop-221-4:33277, NodeHttpAddress: hadoop-221-4:8042, Resource: <memory:2048, vCores:1>, Priority: 0, State: NEW, Token: null, Status: container_id {, app_attempt_id {, application_id {, id: 5, cluster_timestamp: 1376157310799, }, attemptId: 1, }, id: 1, }, state: C_NEW, ]
2013-08-10 18:08:27,164 INFO org.apache.hadoop.yarn.server.resourcemanager.recovery.RMStateStore: Storing info for attempt: appattempt_1376157310799_0005_000001
2013-08-10 18:08:27,165 INFO org.apache.hadoop.yarn.server.resourcemanager.rmapp.attempt.RMAppAttemptImpl: appattempt_1376157310799_0005_000001 State change from SCHEDULED to ALLOCATED_SAVING
2013-08-10 18:08:27,165 INFO org.apache.hadoop.yarn.server.resourcemanager.rmapp.attempt.RMAppAttemptImpl: appattempt_1376157310799_0005_000001 State change from ALLOCATED_SAVING to ALLOCATED
2013-08-10 18:08:27,167 INFO org.apache.hadoop.yarn.server.resourcemanager.amlauncher.AMLauncher: Launching masterappattempt_1376157310799_0005_000001
2013-08-10 18:08:27,169 INFO org.apache.hadoop.yarn.server.resourcemanager.amlauncher.AMLauncher: Setting up container Container: [ContainerId: container_1376157310799_0005_01_000001, NodeId: hadoop-221-4:33277, NodeHttpAddress: hadoop-221-4:8042, Resource: <memory:2048, vCores:1>, Priority: 0, State: NEW, Token: null, Status: container_id {, app_attempt_id {, application_id {, id: 5, cluster_timestamp: 1376157310799, }, attemptId: 1, }, id: 1, }, state: C_NEW, ] for AM appattempt_1376157310799_0005_000001
2013-08-10 18:08:27,170 INFO org.apache.hadoop.yarn.server.resourcemanager.amlauncher.AMLauncher: Command to launch container container_1376157310799_0005_01_000001 : $JAVA_HOME/bin/java -Dlog4j.configuration=container-log4j.properties -Dyarn.app.mapreduce.container.log.dir=<LOG_DIR> -Dyarn.app.mapreduce.container.log.filesize=0 -Dhadoop.root.logger=INFO,CLA  -Xmx1024m org.apache.hadoop.mapreduce.v2.app.MRAppMaster 1><LOG_DIR>/stdout 2><LOG_DIR>/stderr 
2013-08-10 18:08:27,187 INFO org.apache.hadoop.yarn.server.resourcemanager.amlauncher.AMLauncher: Done launching container Container: [ContainerId: container_1376157310799_0005_01_000001, NodeId: hadoop-221-4:33277, NodeHttpAddress: hadoop-221-4:8042, Resource: <memory:2048, vCores:1>, Priority: 0, State: NEW, Token: null, Status: container_id {, app_attempt_id {, application_id {, id: 5, cluster_timestamp: 1376157310799, }, attemptId: 1, }, id: 1, }, state: C_NEW, ] for AM appattempt_1376157310799_0005_000001
2013-08-10 18:08:27,187 INFO org.apache.hadoop.yarn.server.resourcemanager.rmapp.attempt.RMAppAttemptImpl: appattempt_1376157310799_0005_000001 State change from ALLOCATED to LAUNCHED
2013-08-10 18:08:28,165 INFO org.apache.hadoop.yarn.server.resourcemanager.rmcontainer.RMContainerImpl: container_1376157310799_0005_01_000001 Container Transitioned from ACQUIRED to RUNNING
2013-08-10 18:08:34,289 INFO org.apache.hadoop.yarn.server.resourcemanager.ApplicationMasterService: AM registration appattempt_1376157310799_0005_000001
2013-08-10 18:08:34,289 INFO org.apache.hadoop.yarn.server.resourcemanager.RMAuditLogger: USER=ubuntu	IP=192.168.100.31	OPERATION=Register App Master	TARGET=ApplicationMasterService	RESULT=SUCCESS	APPID=application_1376157310799_0005	APPATTEMPTID=appattempt_1376157310799_0005_000001
2013-08-10 18:08:34,291 INFO org.apache.hadoop.yarn.server.resourcemanager.rmapp.attempt.RMAppAttemptImpl: appattempt_1376157310799_0005_000001 State change from LAUNCHED to RUNNING
2013-08-10 18:08:34,291 INFO org.apache.hadoop.yarn.server.resourcemanager.rmapp.RMAppImpl: application_1376157310799_0005 State change from ACCEPTED to RUNNING
2013-08-10 18:08:35,511 INFO org.apache.hadoop.yarn.server.resourcemanager.rmcontainer.RMContainerImpl: container_1376157310799_0005_01_000002 Container Transitioned from NEW to ALLOCATED
2013-08-10 18:08:35,512 INFO org.apache.hadoop.yarn.server.resourcemanager.RMAuditLogger: USER=ubuntu	OPERATION=AM Allocated Container	TARGET=SchedulerApp	RESULT=SUCCESS	APPID=application_1376157310799_0005	CONTAINERID=container_1376157310799_0005_01_000002
2013-08-10 18:08:35,512 INFO org.apache.hadoop.yarn.server.resourcemanager.scheduler.common.fica.FiCaSchedulerNode: Assigned container container_1376157310799_0005_01_000002 of capacity <memory:1024, vCores:1> on host hadoop-221-2:56306, which currently has 1 containers, <memory:1024, vCores:1> used and <memory:7168, vCores:15> available
2013-08-10 18:08:35,513 INFO org.apache.hadoop.yarn.server.resourcemanager.scheduler.capacity.LeafQueue: assignedContainer application=application_1376157310799_0005 container=Container: [ContainerId: container_1376157310799_0005_01_000002, NodeId: hadoop-221-2:56306, NodeHttpAddress: hadoop-221-2:8042, Resource: <memory:1024, vCores:1>, Priority: 20, State: NEW, Token: null, Status: container_id {, app_attempt_id {, application_id {, id: 5, cluster_timestamp: 1376157310799, }, attemptId: 1, }, id: 2, }, state: C_NEW, ] containerId=container_1376157310799_0005_01_000002 queue=default: capacity=1.0, absoluteCapacity=1.0, usedResources=<memory:2048, vCores:1>usedCapacity=0.041666668, absoluteUsedCapacity=0.041666668, numApps=1, numContainers=1 usedCapacity=0.041666668 absoluteUsedCapacity=0.041666668 used=<memory:2048, vCores:1> cluster=<memory:49152, vCores:96>
2013-08-10 18:08:35,514 INFO org.apache.hadoop.yarn.server.resourcemanager.scheduler.capacity.ParentQueue: Re-sorting queues since queue: root.default stats: default: capacity=1.0, absoluteCapacity=1.0, usedResources=<memory:3072, vCores:2>usedCapacity=0.0625, absoluteUsedCapacity=0.0625, numApps=1, numContainers=2
2013-08-10 18:08:35,514 INFO org.apache.hadoop.yarn.server.resourcemanager.scheduler.capacity.ParentQueue: assignedContainer queue=root usedCapacity=0.0625 absoluteUsedCapacity=0.0625 used=<memory:3072, vCores:2> cluster=<memory:49152, vCores:96>
2013-08-10 18:08:35,883 INFO org.apache.hadoop.yarn.server.resourcemanager.rmcontainer.RMContainerImpl: container_1376157310799_0005_01_000003 Container Transitioned from NEW to ALLOCATED
2013-08-10 18:08:35,884 INFO org.apache.hadoop.yarn.server.resourcemanager.RMAuditLogger: USER=ubuntu	OPERATION=AM Allocated Container	TARGET=SchedulerApp	RESULT=SUCCESS	APPID=application_1376157310799_0005	CONTAINERID=container_1376157310799_0005_01_000003
2013-08-10 18:08:35,884 INFO org.apache.hadoop.yarn.server.resourcemanager.scheduler.common.fica.FiCaSchedulerNode: Assigned container container_1376157310799_0005_01_000003 of capacity <memory:1024, vCores:1> on host hadoop-221-6:39509, which currently has 1 containers, <memory:1024, vCores:1> used and <memory:7168, vCores:15> available
2013-08-10 18:08:35,885 INFO org.apache.hadoop.yarn.server.resourcemanager.scheduler.capacity.LeafQueue: assignedContainer application=application_1376157310799_0005 container=Container: [ContainerId: container_1376157310799_0005_01_000003, NodeId: hadoop-221-6:39509, NodeHttpAddress: hadoop-221-6:8042, Resource: <memory:1024, vCores:1>, Priority: 20, State: NEW, Token: null, Status: container_id {, app_attempt_id {, application_id {, id: 5, cluster_timestamp: 1376157310799, }, attemptId: 1, }, id: 3, }, state: C_NEW, ] containerId=container_1376157310799_0005_01_000003 queue=default: capacity=1.0, absoluteCapacity=1.0, usedResources=<memory:3072, vCores:2>usedCapacity=0.0625, absoluteUsedCapacity=0.0625, numApps=1, numContainers=2 usedCapacity=0.0625 absoluteUsedCapacity=0.0625 used=<memory:3072, vCores:2> cluster=<memory:49152, vCores:96>
2013-08-10 18:08:35,885 INFO org.apache.hadoop.yarn.server.resourcemanager.scheduler.capacity.ParentQueue: Re-sorting queues since queue: root.default stats: default: capacity=1.0, absoluteCapacity=1.0, usedResources=<memory:4096, vCores:3>usedCapacity=0.083333336, absoluteUsedCapacity=0.083333336, numApps=1, numContainers=3
2013-08-10 18:08:35,885 INFO org.apache.hadoop.yarn.server.resourcemanager.scheduler.capacity.ParentQueue: assignedContainer queue=root usedCapacity=0.083333336 absoluteUsedCapacity=0.083333336 used=<memory:4096, vCores:3> cluster=<memory:49152, vCores:96>
2013-08-10 18:08:36,379 INFO org.apache.hadoop.yarn.server.resourcemanager.rmcontainer.RMContainerImpl: container_1376157310799_0005_01_000002 Container Transitioned from ALLOCATED to ACQUIRED
2013-08-10 18:08:36,382 INFO org.apache.hadoop.yarn.server.resourcemanager.rmcontainer.RMContainerImpl: container_1376157310799_0005_01_000003 Container Transitioned from ALLOCATED to ACQUIRED
2013-08-10 18:08:36,888 INFO org.apache.hadoop.yarn.server.resourcemanager.rmcontainer.RMContainerImpl: container_1376157310799_0005_01_000003 Container Transitioned from ACQUIRED to RUNNING
2013-08-10 18:08:37,413 INFO org.apache.hadoop.yarn.server.resourcemanager.scheduler.AppSchedulingInfo: checking for deactivate... 
2013-08-10 18:08:37,541 INFO org.apache.hadoop.yarn.server.resourcemanager.rmcontainer.RMContainerImpl: container_1376157310799_0005_01_000002 Container Transitioned from ACQUIRED to RUNNING
2013-08-10 18:11:14,254 INFO org.apache.hadoop.yarn.server.resourcemanager.rmcontainer.RMContainerImpl: container_1376157310799_0005_01_000003 Container Transitioned from RUNNING to COMPLETED
2013-08-10 18:11:14,255 INFO org.apache.hadoop.yarn.server.resourcemanager.scheduler.common.fica.FiCaSchedulerApp: Completed container: container_1376157310799_0005_01_000003 in state: COMPLETED event:FINISHED
2013-08-10 18:11:14,255 INFO org.apache.hadoop.yarn.server.resourcemanager.RMAuditLogger: USER=ubuntu	OPERATION=AM Released Container	TARGET=SchedulerApp	RESULT=SUCCESS	APPID=application_1376157310799_0005	CONTAINERID=container_1376157310799_0005_01_000003
2013-08-10 18:11:14,255 INFO org.apache.hadoop.yarn.server.resourcemanager.scheduler.common.fica.FiCaSchedulerNode: Released container container_1376157310799_0005_01_000003 of capacity <memory:1024, vCores:1> on host hadoop-221-6:39509, which currently has 0 containers, <memory:0, vCores:0> used and <memory:8192, vCores:16> available, release resources=true
2013-08-10 18:11:14,255 INFO org.apache.hadoop.yarn.server.resourcemanager.scheduler.capacity.LeafQueue: default used=<memory:3072, vCores:2> numContainers=2 user=ubuntu user-resources=<memory:3072, vCores:2>
2013-08-10 18:11:14,257 INFO org.apache.hadoop.yarn.server.resourcemanager.scheduler.capacity.LeafQueue: completedContainer container=Container: [ContainerId: container_1376157310799_0005_01_000003, NodeId: hadoop-221-6:39509, NodeHttpAddress: hadoop-221-6:8042, Resource: <memory:1024, vCores:1>, Priority: 20, State: NEW, Token: null, Status: container_id {, app_attempt_id {, application_id {, id: 5, cluster_timestamp: 1376157310799, }, attemptId: 1, }, id: 3, }, state: C_COMPLETE, diagnostics: "Container killed by the ApplicationMaster.\n\n", exit_status: 143, ] resource=<memory:1024, vCores:1> queue=default: capacity=1.0, absoluteCapacity=1.0, usedResources=<memory:3072, vCores:2>usedCapacity=0.0625, absoluteUsedCapacity=0.0625, numApps=1, numContainers=2 usedCapacity=0.0625 absoluteUsedCapacity=0.0625 used=<memory:3072, vCores:2> cluster=<memory:49152, vCores:96>
2013-08-10 18:11:14,257 INFO org.apache.hadoop.yarn.server.resourcemanager.scheduler.capacity.ParentQueue: completedContainer queue=root usedCapacity=0.0625 absoluteUsedCapacity=0.0625 used=<memory:3072, vCores:2> cluster=<memory:49152, vCores:96>
2013-08-10 18:11:14,258 INFO org.apache.hadoop.yarn.server.resourcemanager.scheduler.capacity.CapacityScheduler: Application appattempt_1376157310799_0005_000001 released container container_1376157310799_0005_01_000003 on node: host: hadoop-221-6:39509 #containers=0 available=8192 used=0 with event: FINISHED
2013-08-10 18:11:33,736 INFO org.apache.hadoop.yarn.server.resourcemanager.rmcontainer.RMContainerImpl: container_1376157310799_0005_01_000002 Container Transitioned from RUNNING to COMPLETED
2013-08-10 18:11:33,737 INFO org.apache.hadoop.yarn.server.resourcemanager.scheduler.common.fica.FiCaSchedulerApp: Completed container: container_1376157310799_0005_01_000002 in state: COMPLETED event:FINISHED
2013-08-10 18:11:33,737 INFO org.apache.hadoop.yarn.server.resourcemanager.RMAuditLogger: USER=ubuntu	OPERATION=AM Released Container	TARGET=SchedulerApp	RESULT=SUCCESS	APPID=application_1376157310799_0005	CONTAINERID=container_1376157310799_0005_01_000002
2013-08-10 18:11:33,737 INFO org.apache.hadoop.yarn.server.resourcemanager.scheduler.common.fica.FiCaSchedulerNode: Released container container_1376157310799_0005_01_000002 of capacity <memory:1024, vCores:1> on host hadoop-221-2:56306, which currently has 0 containers, <memory:0, vCores:0> used and <memory:8192, vCores:16> available, release resources=true
2013-08-10 18:11:33,737 INFO org.apache.hadoop.yarn.server.resourcemanager.scheduler.capacity.LeafQueue: default used=<memory:2048, vCores:1> numContainers=1 user=ubuntu user-resources=<memory:2048, vCores:1>
2013-08-10 18:11:33,739 INFO org.apache.hadoop.yarn.server.resourcemanager.scheduler.capacity.LeafQueue: completedContainer container=Container: [ContainerId: container_1376157310799_0005_01_000002, NodeId: hadoop-221-2:56306, NodeHttpAddress: hadoop-221-2:8042, Resource: <memory:1024, vCores:1>, Priority: 20, State: NEW, Token: null, Status: container_id {, app_attempt_id {, application_id {, id: 5, cluster_timestamp: 1376157310799, }, attemptId: 1, }, id: 2, }, state: C_COMPLETE, diagnostics: "Container killed by the ApplicationMaster.\n\n", exit_status: 143, ] resource=<memory:1024, vCores:1> queue=default: capacity=1.0, absoluteCapacity=1.0, usedResources=<memory:2048, vCores:1>usedCapacity=0.041666668, absoluteUsedCapacity=0.041666668, numApps=1, numContainers=1 usedCapacity=0.041666668 absoluteUsedCapacity=0.041666668 used=<memory:2048, vCores:1> cluster=<memory:49152, vCores:96>
2013-08-10 18:11:33,739 INFO org.apache.hadoop.yarn.server.resourcemanager.scheduler.capacity.ParentQueue: completedContainer queue=root usedCapacity=0.041666668 absoluteUsedCapacity=0.041666668 used=<memory:2048, vCores:1> cluster=<memory:49152, vCores:96>
2013-08-10 18:11:33,739 INFO org.apache.hadoop.yarn.server.resourcemanager.scheduler.capacity.CapacityScheduler: Application appattempt_1376157310799_0005_000001 released container container_1376157310799_0005_01_000002 on node: host: hadoop-221-2:56306 #containers=0 available=8192 used=0 with event: FINISHED
2013-08-10 18:11:37,929 INFO org.apache.hadoop.yarn.server.resourcemanager.rmapp.attempt.RMAppAttemptImpl: appattempt_1376157310799_0005_000001 State change from RUNNING to FINISHING
2013-08-10 18:11:37,929 INFO org.apache.hadoop.yarn.server.resourcemanager.rmapp.RMAppImpl: application_1376157310799_0005 State change from RUNNING to FINISHING
2013-08-10 18:11:38,314 INFO org.apache.hadoop.yarn.server.resourcemanager.rmcontainer.RMContainerImpl: container_1376157310799_0005_01_000001 Container Transitioned from RUNNING to COMPLETED
2013-08-10 18:11:38,314 INFO org.apache.hadoop.yarn.server.resourcemanager.rmapp.attempt.RMAppAttemptImpl: appattempt_1376157310799_0005_000001 State change from FINISHING to FINISHED
2013-08-10 18:11:38,314 INFO org.apache.hadoop.yarn.server.resourcemanager.scheduler.common.fica.FiCaSchedulerApp: Completed container: container_1376157310799_0005_01_000001 in state: COMPLETED event:FINISHED
2013-08-10 18:11:38,314 INFO org.apache.hadoop.yarn.server.resourcemanager.rmapp.RMAppImpl: application_1376157310799_0005 State change from FINISHING to FINISHED
2013-08-10 18:11:38,314 INFO org.apache.hadoop.yarn.server.resourcemanager.RMAuditLogger: USER=ubuntu	OPERATION=AM Released Container	TARGET=SchedulerApp	RESULT=SUCCESS	APPID=application_1376157310799_0005	CONTAINERID=container_1376157310799_0005_01_000001
2013-08-10 18:11:38,314 INFO org.apache.hadoop.yarn.server.resourcemanager.scheduler.common.fica.FiCaSchedulerNode: Released container container_1376157310799_0005_01_000001 of capacity <memory:2048, vCores:1> on host hadoop-221-4:33277, which currently has 0 containers, <memory:0, vCores:0> used and <memory:8192, vCores:16> available, release resources=true
2013-08-10 18:11:38,314 INFO org.apache.hadoop.yarn.server.resourcemanager.scheduler.capacity.LeafQueue: default used=<memory:0, vCores:0> numContainers=0 user=ubuntu user-resources=<memory:0, vCores:0>
2013-08-10 18:11:38,315 INFO org.apache.hadoop.yarn.server.resourcemanager.RMAuditLogger: USER=ubuntu	OPERATION=Application Finished - Succeeded	TARGET=RMAppManager	RESULT=SUCCESS	APPID=application_1376157310799_0005
2013-08-10 18:11:38,315 INFO org.apache.hadoop.yarn.server.resourcemanager.recovery.RMStateStore: Removing info for app: application_1376157310799_0005
2013-08-10 18:11:38,315 INFO org.apache.hadoop.yarn.server.resourcemanager.RMAppManager$ApplicationSummary: appId=application_1376157310799_0005,name=TeraGen,user=ubuntu,queue=default,state=FINISHED,trackingUrl=hadoop-221-1.novalocal:8088/proxy/application_1376157310799_0005/jobhistory/job/job_1376157310799_0005,appMasterHost=hadoop-221-4,startTime=1376158107073,finishTime=1376158297929
2013-08-10 18:11:38,315 INFO org.apache.hadoop.yarn.server.resourcemanager.scheduler.capacity.LeafQueue: completedContainer container=Container: [ContainerId: container_1376157310799_0005_01_000001, NodeId: hadoop-221-4:33277, NodeHttpAddress: hadoop-221-4:8042, Resource: <memory:2048, vCores:1>, Priority: 0, State: NEW, Token: null, Status: container_id {, app_attempt_id {, application_id {, id: 5, cluster_timestamp: 1376157310799, }, attemptId: 1, }, id: 1, }, state: C_COMPLETE, diagnostics: "", exit_status: 0, ] resource=<memory:2048, vCores:1> queue=default: capacity=1.0, absoluteCapacity=1.0, usedResources=<memory:0, vCores:0>usedCapacity=0.0, absoluteUsedCapacity=0.0, numApps=1, numContainers=0 usedCapacity=0.0 absoluteUsedCapacity=0.0 used=<memory:0, vCores:0> cluster=<memory:49152, vCores:96>
2013-08-10 18:11:38,315 INFO org.apache.hadoop.yarn.server.resourcemanager.scheduler.capacity.ParentQueue: completedContainer queue=root usedCapacity=0.0 absoluteUsedCapacity=0.0 used=<memory:0, vCores:0> cluster=<memory:49152, vCores:96>
2013-08-10 18:11:38,316 INFO org.apache.hadoop.yarn.server.resourcemanager.scheduler.capacity.CapacityScheduler: Application appattempt_1376157310799_0005_000001 released container container_1376157310799_0005_01_000001 on node: host: hadoop-221-4:33277 #containers=0 available=8192 used=0 with event: FINISHED
2013-08-10 18:11:38,316 INFO org.apache.hadoop.yarn.server.resourcemanager.scheduler.capacity.CapacityScheduler: Application appattempt_1376157310799_0005_000001 is done. finalState=FINISHED
2013-08-10 18:11:38,316 INFO org.apache.hadoop.yarn.server.resourcemanager.scheduler.AppSchedulingInfo: Application application_1376157310799_0005 requests cleared
2013-08-10 18:11:38,316 INFO org.apache.hadoop.yarn.server.resourcemanager.scheduler.capacity.LeafQueue: Application removed - appId: application_1376157310799_0005 user: ubuntu queue: default #user-pending-applications: 0 #user-active-applications: 0 #queue-pending-applications: 0 #queue-active-applications: 0
2013-08-10 18:11:38,316 INFO org.apache.hadoop.yarn.server.resourcemanager.scheduler.capacity.ParentQueue: Application removed - appId: application_1376157310799_0005 user: ubuntu leaf-queue of parent: root #applications: 0
2013-08-10 18:11:38,325 INFO org.apache.hadoop.yarn.server.resourcemanager.amlauncher.AMLauncher: Cleaning master appattempt_1376157310799_0005_000001
2013-08-10 18:11:44,105 INFO org.apache.hadoop.yarn.server.resourcemanager.ClientRMService: Allocated new applicationId: 6
2013-08-10 18:11:44,353 INFO org.apache.hadoop.yarn.server.resourcemanager.ClientRMService: Allocated new applicationId: 7
2013-08-10 18:11:44,632 INFO org.apache.hadoop.yarn.server.resourcemanager.ClientRMService: Allocated new applicationId: 8
2013-08-10 18:11:44,727 INFO org.apache.hadoop.yarn.server.resourcemanager.ClientRMService: Allocated new applicationId: 9
2013-08-10 18:11:45,224 INFO org.apache.hadoop.yarn.server.resourcemanager.ClientRMService: Allocated new applicationId: 10
2013-08-10 18:11:46,436 INFO org.apache.hadoop.yarn.server.resourcemanager.ClientRMService: Storing Application with id application_1376157310799_0006
2013-08-10 18:11:46,436 INFO org.apache.hadoop.yarn.server.resourcemanager.recovery.RMStateStore: Storing info for app: application_1376157310799_0006
2013-08-10 18:11:46,436 INFO org.apache.hadoop.yarn.server.resourcemanager.ClientRMService: Application with id 6 submitted by user ubuntu
2013-08-10 18:11:46,436 INFO org.apache.hadoop.yarn.server.resourcemanager.RMAuditLogger: USER=ubuntu	IP=192.168.100.24	OPERATION=Submit Application Request	TARGET=ClientRMService	RESULT=SUCCESS	APPID=application_1376157310799_0006
2013-08-10 18:11:46,457 INFO org.apache.hadoop.yarn.server.resourcemanager.rmapp.RMAppImpl: application_1376157310799_0006 State change from NEW to SUBMITTED
2013-08-10 18:11:46,457 INFO org.apache.hadoop.yarn.server.resourcemanager.ApplicationMasterService: Registering appattempt_1376157310799_0006_000001
2013-08-10 18:11:46,457 INFO org.apache.hadoop.yarn.server.resourcemanager.rmapp.attempt.RMAppAttemptImpl: appattempt_1376157310799_0006_000001 State change from NEW to SUBMITTED
2013-08-10 18:11:46,460 INFO org.apache.hadoop.yarn.server.resourcemanager.scheduler.capacity.LeafQueue: Application application_1376157310799_0006 from user: ubuntu activated in queue: default
2013-08-10 18:11:46,461 INFO org.apache.hadoop.yarn.server.resourcemanager.scheduler.capacity.LeafQueue: Application added - appId: application_1376157310799_0006 user: org.apache.hadoop.yarn.server.resourcemanager.scheduler.capacity.LeafQueue$User@9a9303c, leaf-queue: default #user-pending-applications: 0 #user-active-applications: 1 #queue-pending-applications: 0 #queue-active-applications: 1
2013-08-10 18:11:46,461 INFO org.apache.hadoop.yarn.server.resourcemanager.scheduler.capacity.ParentQueue: Application added - appId: application_1376157310799_0006 user: ubuntu leaf-queue of parent: root #applications: 1
2013-08-10 18:11:46,461 INFO org.apache.hadoop.yarn.server.resourcemanager.scheduler.capacity.CapacityScheduler: Application Submission: appattempt_1376157310799_0006_000001, user: ubuntu queue: default: capacity=1.0, absoluteCapacity=1.0, usedResources=<memory:0, vCores:0>usedCapacity=0.0, absoluteUsedCapacity=0.0, numApps=1, numContainers=0, currently active: 1
2013-08-10 18:11:46,462 INFO org.apache.hadoop.yarn.server.resourcemanager.rmapp.attempt.RMAppAttemptImpl: appattempt_1376157310799_0006_000001 State change from SUBMITTED to SCHEDULED
2013-08-10 18:11:46,462 INFO org.apache.hadoop.yarn.server.resourcemanager.rmapp.RMAppImpl: application_1376157310799_0006 State change from SUBMITTED to ACCEPTED
2013-08-10 18:11:46,782 INFO org.apache.hadoop.yarn.server.resourcemanager.rmcontainer.RMContainerImpl: container_1376157310799_0006_01_000001 Container Transitioned from NEW to ALLOCATED
2013-08-10 18:11:46,782 INFO org.apache.hadoop.yarn.server.resourcemanager.RMAuditLogger: USER=ubuntu	OPERATION=AM Allocated Container	TARGET=SchedulerApp	RESULT=SUCCESS	APPID=application_1376157310799_0006	CONTAINERID=container_1376157310799_0006_01_000001
2013-08-10 18:11:46,782 INFO org.apache.hadoop.yarn.server.resourcemanager.scheduler.common.fica.FiCaSchedulerNode: Assigned container container_1376157310799_0006_01_000001 of capacity <memory:2048, vCores:1> on host hadoop-221-2:56306, which currently has 1 containers, <memory:2048, vCores:1> used and <memory:6144, vCores:15> available
2013-08-10 18:11:46,783 INFO org.apache.hadoop.yarn.server.resourcemanager.scheduler.capacity.LeafQueue: assignedContainer application=application_1376157310799_0006 container=Container: [ContainerId: container_1376157310799_0006_01_000001, NodeId: hadoop-221-2:56306, NodeHttpAddress: hadoop-221-2:8042, Resource: <memory:2048, vCores:1>, Priority: 0, State: NEW, Token: null, Status: container_id {, app_attempt_id {, application_id {, id: 6, cluster_timestamp: 1376157310799, }, attemptId: 1, }, id: 1, }, state: C_NEW, ] containerId=container_1376157310799_0006_01_000001 queue=default: capacity=1.0, absoluteCapacity=1.0, usedResources=<memory:0, vCores:0>usedCapacity=0.0, absoluteUsedCapacity=0.0, numApps=1, numContainers=0 usedCapacity=0.0 absoluteUsedCapacity=0.0 used=<memory:0, vCores:0> cluster=<memory:49152, vCores:96>
2013-08-10 18:11:46,801 INFO org.apache.hadoop.yarn.server.resourcemanager.scheduler.capacity.ParentQueue: Re-sorting queues since queue: root.default stats: default: capacity=1.0, absoluteCapacity=1.0, usedResources=<memory:2048, vCores:1>usedCapacity=0.041666668, absoluteUsedCapacity=0.041666668, numApps=1, numContainers=1
2013-08-10 18:11:46,802 INFO org.apache.hadoop.yarn.server.resourcemanager.scheduler.capacity.ParentQueue: assignedContainer queue=root usedCapacity=0.041666668 absoluteUsedCapacity=0.041666668 used=<memory:2048, vCores:1> cluster=<memory:49152, vCores:96>
2013-08-10 18:11:46,802 INFO org.apache.hadoop.yarn.server.resourcemanager.rmcontainer.RMContainerImpl: container_1376157310799_0006_01_000001 Container Transitioned from ALLOCATED to ACQUIRED
2013-08-10 18:11:46,804 INFO org.apache.hadoop.yarn.server.resourcemanager.rmapp.attempt.RMAppAttemptImpl: Storing attempt: AppId: application_1376157310799_0006 AttemptId: appattempt_1376157310799_0006_000001 MasterContainer: Container: [ContainerId: container_1376157310799_0006_01_000001, NodeId: hadoop-221-2:56306, NodeHttpAddress: hadoop-221-2:8042, Resource: <memory:2048, vCores:1>, Priority: 0, State: NEW, Token: null, Status: container_id {, app_attempt_id {, application_id {, id: 6, cluster_timestamp: 1376157310799, }, attemptId: 1, }, id: 1, }, state: C_NEW, ]
2013-08-10 18:11:46,804 INFO org.apache.hadoop.yarn.server.resourcemanager.rmapp.attempt.RMAppAttemptImpl: appattempt_1376157310799_0006_000001 State change from SCHEDULED to ALLOCATED_SAVING
2013-08-10 18:11:46,804 INFO org.apache.hadoop.yarn.server.resourcemanager.recovery.RMStateStore: Storing info for attempt: appattempt_1376157310799_0006_000001
2013-08-10 18:11:46,805 INFO org.apache.hadoop.yarn.server.resourcemanager.rmapp.attempt.RMAppAttemptImpl: appattempt_1376157310799_0006_000001 State change from ALLOCATED_SAVING to ALLOCATED
2013-08-10 18:11:46,805 INFO org.apache.hadoop.yarn.server.resourcemanager.amlauncher.AMLauncher: Launching masterappattempt_1376157310799_0006_000001
2013-08-10 18:11:46,807 INFO org.apache.hadoop.yarn.server.resourcemanager.amlauncher.AMLauncher: Setting up container Container: [ContainerId: container_1376157310799_0006_01_000001, NodeId: hadoop-221-2:56306, NodeHttpAddress: hadoop-221-2:8042, Resource: <memory:2048, vCores:1>, Priority: 0, State: NEW, Token: null, Status: container_id {, app_attempt_id {, application_id {, id: 6, cluster_timestamp: 1376157310799, }, attemptId: 1, }, id: 1, }, state: C_NEW, ] for AM appattempt_1376157310799_0006_000001
2013-08-10 18:11:46,807 INFO org.apache.hadoop.yarn.server.resourcemanager.amlauncher.AMLauncher: Command to launch container container_1376157310799_0006_01_000001 : $JAVA_HOME/bin/java -Dlog4j.configuration=container-log4j.properties -Dyarn.app.mapreduce.container.log.dir=<LOG_DIR> -Dyarn.app.mapreduce.container.log.filesize=0 -Dhadoop.root.logger=INFO,CLA  -Xmx1024m org.apache.hadoop.mapreduce.v2.app.MRAppMaster 1><LOG_DIR>/stdout 2><LOG_DIR>/stderr 
2013-08-10 18:11:46,821 INFO org.apache.hadoop.yarn.server.resourcemanager.amlauncher.AMLauncher: Done launching container Container: [ContainerId: container_1376157310799_0006_01_000001, NodeId: hadoop-221-2:56306, NodeHttpAddress: hadoop-221-2:8042, Resource: <memory:2048, vCores:1>, Priority: 0, State: NEW, Token: null, Status: container_id {, app_attempt_id {, application_id {, id: 6, cluster_timestamp: 1376157310799, }, attemptId: 1, }, id: 1, }, state: C_NEW, ] for AM appattempt_1376157310799_0006_000001
2013-08-10 18:11:46,821 INFO org.apache.hadoop.yarn.server.resourcemanager.rmapp.attempt.RMAppAttemptImpl: appattempt_1376157310799_0006_000001 State change from ALLOCATED to LAUNCHED
2013-08-10 18:11:46,835 INFO org.apache.hadoop.yarn.server.resourcemanager.ClientRMService: Storing Application with id application_1376157310799_0008
2013-08-10 18:11:46,836 INFO org.apache.hadoop.yarn.server.resourcemanager.recovery.RMStateStore: Storing info for app: application_1376157310799_0008
2013-08-10 18:11:46,836 INFO org.apache.hadoop.yarn.server.resourcemanager.ClientRMService: Application with id 8 submitted by user ubuntu
2013-08-10 18:11:46,836 INFO org.apache.hadoop.yarn.server.resourcemanager.RMAuditLogger: USER=ubuntu	IP=192.168.100.24	OPERATION=Submit Application Request	TARGET=ClientRMService	RESULT=SUCCESS	APPID=application_1376157310799_0008
2013-08-10 18:11:46,836 INFO org.apache.hadoop.yarn.server.resourcemanager.rmapp.RMAppImpl: application_1376157310799_0008 State change from NEW to SUBMITTED
2013-08-10 18:11:46,837 INFO org.apache.hadoop.yarn.server.resourcemanager.ApplicationMasterService: Registering appattempt_1376157310799_0008_000001
2013-08-10 18:11:46,837 INFO org.apache.hadoop.yarn.server.resourcemanager.rmapp.attempt.RMAppAttemptImpl: appattempt_1376157310799_0008_000001 State change from NEW to SUBMITTED
2013-08-10 18:11:46,837 INFO org.apache.hadoop.yarn.server.resourcemanager.scheduler.capacity.LeafQueue: Application application_1376157310799_0008 from user: ubuntu activated in queue: default
2013-08-10 18:11:46,837 INFO org.apache.hadoop.yarn.server.resourcemanager.scheduler.capacity.LeafQueue: Application added - appId: application_1376157310799_0008 user: org.apache.hadoop.yarn.server.resourcemanager.scheduler.capacity.LeafQueue$User@9a9303c, leaf-queue: default #user-pending-applications: 0 #user-active-applications: 2 #queue-pending-applications: 0 #queue-active-applications: 2
2013-08-10 18:11:46,837 INFO org.apache.hadoop.yarn.server.resourcemanager.scheduler.capacity.ParentQueue: Application added - appId: application_1376157310799_0008 user: ubuntu leaf-queue of parent: root #applications: 2
2013-08-10 18:11:46,837 INFO org.apache.hadoop.yarn.server.resourcemanager.scheduler.capacity.CapacityScheduler: Application Submission: appattempt_1376157310799_0008_000001, user: ubuntu queue: default: capacity=1.0, absoluteCapacity=1.0, usedResources=<memory:2048, vCores:1>usedCapacity=0.041666668, absoluteUsedCapacity=0.041666668, numApps=2, numContainers=1, currently active: 2
2013-08-10 18:11:46,838 INFO org.apache.hadoop.yarn.server.resourcemanager.rmapp.attempt.RMAppAttemptImpl: appattempt_1376157310799_0008_000001 State change from SUBMITTED to SCHEDULED
2013-08-10 18:11:46,838 INFO org.apache.hadoop.yarn.server.resourcemanager.rmapp.RMAppImpl: application_1376157310799_0008 State change from SUBMITTED to ACCEPTED
2013-08-10 18:11:46,873 INFO org.apache.hadoop.yarn.server.resourcemanager.ClientRMService: Storing Application with id application_1376157310799_0009
2013-08-10 18:11:46,873 INFO org.apache.hadoop.yarn.server.resourcemanager.recovery.RMStateStore: Storing info for app: application_1376157310799_0009
2013-08-10 18:11:46,873 INFO org.apache.hadoop.yarn.server.resourcemanager.ClientRMService: Application with id 9 submitted by user ubuntu
2013-08-10 18:11:46,873 INFO org.apache.hadoop.yarn.server.resourcemanager.RMAuditLogger: USER=ubuntu	IP=192.168.100.24	OPERATION=Submit Application Request	TARGET=ClientRMService	RESULT=SUCCESS	APPID=application_1376157310799_0009
2013-08-10 18:11:46,873 INFO org.apache.hadoop.yarn.server.resourcemanager.rmapp.RMAppImpl: application_1376157310799_0009 State change from NEW to SUBMITTED
2013-08-10 18:11:46,874 INFO org.apache.hadoop.yarn.server.resourcemanager.ApplicationMasterService: Registering appattempt_1376157310799_0009_000001
2013-08-10 18:11:46,874 INFO org.apache.hadoop.yarn.server.resourcemanager.rmapp.attempt.RMAppAttemptImpl: appattempt_1376157310799_0009_000001 State change from NEW to SUBMITTED
2013-08-10 18:11:46,874 INFO org.apache.hadoop.yarn.server.resourcemanager.scheduler.capacity.LeafQueue: Application application_1376157310799_0009 from user: ubuntu activated in queue: default
2013-08-10 18:11:46,874 INFO org.apache.hadoop.yarn.server.resourcemanager.scheduler.capacity.LeafQueue: Application added - appId: application_1376157310799_0009 user: org.apache.hadoop.yarn.server.resourcemanager.scheduler.capacity.LeafQueue$User@9a9303c, leaf-queue: default #user-pending-applications: 0 #user-active-applications: 3 #queue-pending-applications: 0 #queue-active-applications: 3
2013-08-10 18:11:46,874 INFO org.apache.hadoop.yarn.server.resourcemanager.scheduler.capacity.ParentQueue: Application added - appId: application_1376157310799_0009 user: ubuntu leaf-queue of parent: root #applications: 3
2013-08-10 18:11:46,875 INFO org.apache.hadoop.yarn.server.resourcemanager.scheduler.capacity.CapacityScheduler: Application Submission: appattempt_1376157310799_0009_000001, user: ubuntu queue: default: capacity=1.0, absoluteCapacity=1.0, usedResources=<memory:2048, vCores:1>usedCapacity=0.041666668, absoluteUsedCapacity=0.041666668, numApps=3, numContainers=1, currently active: 3
2013-08-10 18:11:46,875 INFO org.apache.hadoop.yarn.server.resourcemanager.rmapp.attempt.RMAppAttemptImpl: appattempt_1376157310799_0009_000001 State change from SUBMITTED to SCHEDULED
2013-08-10 18:11:46,875 INFO org.apache.hadoop.yarn.server.resourcemanager.rmapp.RMAppImpl: application_1376157310799_0009 State change from SUBMITTED to ACCEPTED
2013-08-10 18:11:46,957 INFO org.apache.hadoop.yarn.server.resourcemanager.ClientRMService: Storing Application with id application_1376157310799_0007
2013-08-10 18:11:46,957 INFO org.apache.hadoop.yarn.server.resourcemanager.recovery.RMStateStore: Storing info for app: application_1376157310799_0007
2013-08-10 18:11:46,957 INFO org.apache.hadoop.yarn.server.resourcemanager.ClientRMService: Application with id 7 submitted by user ubuntu
2013-08-10 18:11:46,957 INFO org.apache.hadoop.yarn.server.resourcemanager.RMAuditLogger: USER=ubuntu	IP=192.168.100.24	OPERATION=Submit Application Request	TARGET=ClientRMService	RESULT=SUCCESS	APPID=application_1376157310799_0007
2013-08-10 18:11:46,958 INFO org.apache.hadoop.yarn.server.resourcemanager.rmapp.RMAppImpl: application_1376157310799_0007 State change from NEW to SUBMITTED
2013-08-10 18:11:46,958 INFO org.apache.hadoop.yarn.server.resourcemanager.ApplicationMasterService: Registering appattempt_1376157310799_0007_000001
2013-08-10 18:11:46,958 INFO org.apache.hadoop.yarn.server.resourcemanager.rmapp.attempt.RMAppAttemptImpl: appattempt_1376157310799_0007_000001 State change from NEW to SUBMITTED
2013-08-10 18:11:46,958 INFO org.apache.hadoop.yarn.server.resourcemanager.scheduler.capacity.LeafQueue: Application application_1376157310799_0007 from user: ubuntu activated in queue: default
2013-08-10 18:11:46,958 INFO org.apache.hadoop.yarn.server.resourcemanager.scheduler.capacity.LeafQueue: Application added - appId: application_1376157310799_0007 user: org.apache.hadoop.yarn.server.resourcemanager.scheduler.capacity.LeafQueue$User@9a9303c, leaf-queue: default #user-pending-applications: 0 #user-active-applications: 4 #queue-pending-applications: 0 #queue-active-applications: 4
2013-08-10 18:11:46,958 INFO org.apache.hadoop.yarn.server.resourcemanager.scheduler.capacity.ParentQueue: Application added - appId: application_1376157310799_0007 user: ubuntu leaf-queue of parent: root #applications: 4
2013-08-10 18:11:46,958 INFO org.apache.hadoop.yarn.server.resourcemanager.scheduler.capacity.CapacityScheduler: Application Submission: appattempt_1376157310799_0007_000001, user: ubuntu queue: default: capacity=1.0, absoluteCapacity=1.0, usedResources=<memory:2048, vCores:1>usedCapacity=0.041666668, absoluteUsedCapacity=0.041666668, numApps=4, numContainers=1, currently active: 4
2013-08-10 18:11:46,959 INFO org.apache.hadoop.yarn.server.resourcemanager.rmapp.attempt.RMAppAttemptImpl: appattempt_1376157310799_0007_000001 State change from SUBMITTED to SCHEDULED
2013-08-10 18:11:46,959 INFO org.apache.hadoop.yarn.server.resourcemanager.rmapp.RMAppImpl: application_1376157310799_0007 State change from SUBMITTED to ACCEPTED
2013-08-10 18:11:46,970 INFO org.apache.hadoop.yarn.server.resourcemanager.rmcontainer.RMContainerImpl: container_1376157310799_0007_01_000001 Container Transitioned from NEW to ALLOCATED
2013-08-10 18:11:46,970 INFO org.apache.hadoop.yarn.server.resourcemanager.RMAuditLogger: USER=ubuntu	OPERATION=AM Allocated Container	TARGET=SchedulerApp	RESULT=SUCCESS	APPID=application_1376157310799_0007	CONTAINERID=container_1376157310799_0007_01_000001
2013-08-10 18:11:46,971 INFO org.apache.hadoop.yarn.server.resourcemanager.scheduler.common.fica.FiCaSchedulerNode: Assigned container container_1376157310799_0007_01_000001 of capacity <memory:2048, vCores:1> on host hadoop-221-7:56906, which currently has 1 containers, <memory:2048, vCores:1> used and <memory:6144, vCores:15> available
2013-08-10 18:11:46,971 INFO org.apache.hadoop.yarn.server.resourcemanager.scheduler.capacity.LeafQueue: assignedContainer application=application_1376157310799_0007 container=Container: [ContainerId: container_1376157310799_0007_01_000001, NodeId: hadoop-221-7:56906, NodeHttpAddress: hadoop-221-7:8042, Resource: <memory:2048, vCores:1>, Priority: 0, State: NEW, Token: null, Status: container_id {, app_attempt_id {, application_id {, id: 7, cluster_timestamp: 1376157310799, }, attemptId: 1, }, id: 1, }, state: C_NEW, ] containerId=container_1376157310799_0007_01_000001 queue=default: capacity=1.0, absoluteCapacity=1.0, usedResources=<memory:2048, vCores:1>usedCapacity=0.041666668, absoluteUsedCapacity=0.041666668, numApps=4, numContainers=1 usedCapacity=0.041666668 absoluteUsedCapacity=0.041666668 used=<memory:2048, vCores:1> cluster=<memory:49152, vCores:96>
2013-08-10 18:11:46,972 INFO org.apache.hadoop.yarn.server.resourcemanager.scheduler.capacity.ParentQueue: Re-sorting queues since queue: root.default stats: default: capacity=1.0, absoluteCapacity=1.0, usedResources=<memory:4096, vCores:2>usedCapacity=0.083333336, absoluteUsedCapacity=0.083333336, numApps=4, numContainers=2
2013-08-10 18:11:46,972 INFO org.apache.hadoop.yarn.server.resourcemanager.scheduler.capacity.ParentQueue: assignedContainer queue=root usedCapacity=0.083333336 absoluteUsedCapacity=0.083333336 used=<memory:4096, vCores:2> cluster=<memory:49152, vCores:96>
2013-08-10 18:11:46,972 INFO org.apache.hadoop.yarn.server.resourcemanager.rmcontainer.RMContainerImpl: container_1376157310799_0007_01_000001 Container Transitioned from ALLOCATED to ACQUIRED
2013-08-10 18:11:46,973 INFO org.apache.hadoop.yarn.server.resourcemanager.rmapp.attempt.RMAppAttemptImpl: Storing attempt: AppId: application_1376157310799_0007 AttemptId: appattempt_1376157310799_0007_000001 MasterContainer: Container: [ContainerId: container_1376157310799_0007_01_000001, NodeId: hadoop-221-7:56906, NodeHttpAddress: hadoop-221-7:8042, Resource: <memory:2048, vCores:1>, Priority: 0, State: NEW, Token: null, Status: container_id {, app_attempt_id {, application_id {, id: 7, cluster_timestamp: 1376157310799, }, attemptId: 1, }, id: 1, }, state: C_NEW, ]
2013-08-10 18:11:46,973 INFO org.apache.hadoop.yarn.server.resourcemanager.recovery.RMStateStore: Storing info for attempt: appattempt_1376157310799_0007_000001
2013-08-10 18:11:46,974 INFO org.apache.hadoop.yarn.server.resourcemanager.rmapp.attempt.RMAppAttemptImpl: appattempt_1376157310799_0007_000001 State change from SCHEDULED to ALLOCATED_SAVING
2013-08-10 18:11:46,974 INFO org.apache.hadoop.yarn.server.resourcemanager.rmapp.attempt.RMAppAttemptImpl: appattempt_1376157310799_0007_000001 State change from ALLOCATED_SAVING to ALLOCATED
2013-08-10 18:11:46,974 INFO org.apache.hadoop.yarn.server.resourcemanager.amlauncher.AMLauncher: Launching masterappattempt_1376157310799_0007_000001
2013-08-10 18:11:46,976 INFO org.apache.hadoop.yarn.server.resourcemanager.amlauncher.AMLauncher: Setting up container Container: [ContainerId: container_1376157310799_0007_01_000001, NodeId: hadoop-221-7:56906, NodeHttpAddress: hadoop-221-7:8042, Resource: <memory:2048, vCores:1>, Priority: 0, State: NEW, Token: null, Status: container_id {, app_attempt_id {, application_id {, id: 7, cluster_timestamp: 1376157310799, }, attemptId: 1, }, id: 1, }, state: C_NEW, ] for AM appattempt_1376157310799_0007_000001
2013-08-10 18:11:46,976 INFO org.apache.hadoop.yarn.server.resourcemanager.amlauncher.AMLauncher: Command to launch container container_1376157310799_0007_01_000001 : $JAVA_HOME/bin/java -Dlog4j.configuration=container-log4j.properties -Dyarn.app.mapreduce.container.log.dir=<LOG_DIR> -Dyarn.app.mapreduce.container.log.filesize=0 -Dhadoop.root.logger=INFO,CLA  -Xmx1024m org.apache.hadoop.mapreduce.v2.app.MRAppMaster 1><LOG_DIR>/stdout 2><LOG_DIR>/stderr 
2013-08-10 18:11:46,989 INFO org.apache.hadoop.yarn.server.resourcemanager.amlauncher.AMLauncher: Done launching container Container: [ContainerId: container_1376157310799_0007_01_000001, NodeId: hadoop-221-7:56906, NodeHttpAddress: hadoop-221-7:8042, Resource: <memory:2048, vCores:1>, Priority: 0, State: NEW, Token: null, Status: container_id {, app_attempt_id {, application_id {, id: 7, cluster_timestamp: 1376157310799, }, attemptId: 1, }, id: 1, }, state: C_NEW, ] for AM appattempt_1376157310799_0007_000001
2013-08-10 18:11:46,989 INFO org.apache.hadoop.yarn.server.resourcemanager.rmapp.attempt.RMAppAttemptImpl: appattempt_1376157310799_0007_000001 State change from ALLOCATED to LAUNCHED
2013-08-10 18:11:47,014 INFO org.apache.hadoop.yarn.server.resourcemanager.rmcontainer.RMContainerImpl: container_1376157310799_0008_01_000001 Container Transitioned from NEW to ALLOCATED
2013-08-10 18:11:47,017 INFO org.apache.hadoop.yarn.server.resourcemanager.RMAuditLogger: USER=ubuntu	OPERATION=AM Allocated Container	TARGET=SchedulerApp	RESULT=SUCCESS	APPID=application_1376157310799_0008	CONTAINERID=container_1376157310799_0008_01_000001
2013-08-10 18:11:47,017 INFO org.apache.hadoop.yarn.server.resourcemanager.scheduler.common.fica.FiCaSchedulerNode: Assigned container container_1376157310799_0008_01_000001 of capacity <memory:2048, vCores:1> on host hadoop-221-5:56475, which currently has 1 containers, <memory:2048, vCores:1> used and <memory:6144, vCores:15> available
2013-08-10 18:11:47,017 INFO org.apache.hadoop.yarn.server.resourcemanager.ClientRMService: Storing Application with id application_1376157310799_0010
2013-08-10 18:11:47,017 INFO org.apache.hadoop.yarn.server.resourcemanager.recovery.RMStateStore: Storing info for app: application_1376157310799_0010
2013-08-10 18:11:47,017 INFO org.apache.hadoop.yarn.server.resourcemanager.ClientRMService: Application with id 10 submitted by user ubuntu
2013-08-10 18:11:47,017 INFO org.apache.hadoop.yarn.server.resourcemanager.RMAuditLogger: USER=ubuntu	IP=192.168.100.24	OPERATION=Submit Application Request	TARGET=ClientRMService	RESULT=SUCCESS	APPID=application_1376157310799_0010
2013-08-10 18:11:47,018 INFO org.apache.hadoop.yarn.server.resourcemanager.scheduler.capacity.LeafQueue: assignedContainer application=application_1376157310799_0008 container=Container: [ContainerId: container_1376157310799_0008_01_000001, NodeId: hadoop-221-5:56475, NodeHttpAddress: hadoop-221-5:8042, Resource: <memory:2048, vCores:1>, Priority: 0, State: NEW, Token: null, Status: container_id {, app_attempt_id {, application_id {, id: 8, cluster_timestamp: 1376157310799, }, attemptId: 1, }, id: 1, }, state: C_NEW, ] containerId=container_1376157310799_0008_01_000001 queue=default: capacity=1.0, absoluteCapacity=1.0, usedResources=<memory:4096, vCores:2>usedCapacity=0.083333336, absoluteUsedCapacity=0.083333336, numApps=4, numContainers=2 usedCapacity=0.083333336 absoluteUsedCapacity=0.083333336 used=<memory:4096, vCores:2> cluster=<memory:49152, vCores:96>
2013-08-10 18:11:47,018 INFO org.apache.hadoop.yarn.server.resourcemanager.scheduler.capacity.ParentQueue: Re-sorting queues since queue: root.default stats: default: capacity=1.0, absoluteCapacity=1.0, usedResources=<memory:6144, vCores:3>usedCapacity=0.125, absoluteUsedCapacity=0.125, numApps=4, numContainers=3
2013-08-10 18:11:47,018 INFO org.apache.hadoop.yarn.server.resourcemanager.scheduler.capacity.ParentQueue: assignedContainer queue=root usedCapacity=0.125 absoluteUsedCapacity=0.125 used=<memory:6144, vCores:3> cluster=<memory:49152, vCores:96>
2013-08-10 18:11:47,019 INFO org.apache.hadoop.yarn.server.resourcemanager.rmcontainer.RMContainerImpl: container_1376157310799_0008_01_000001 Container Transitioned from ALLOCATED to ACQUIRED
2013-08-10 18:11:47,020 INFO org.apache.hadoop.yarn.server.resourcemanager.rmapp.attempt.RMAppAttemptImpl: Storing attempt: AppId: application_1376157310799_0008 AttemptId: appattempt_1376157310799_0008_000001 MasterContainer: Container: [ContainerId: container_1376157310799_0008_01_000001, NodeId: hadoop-221-5:56475, NodeHttpAddress: hadoop-221-5:8042, Resource: <memory:2048, vCores:1>, Priority: 0, State: NEW, Token: null, Status: container_id {, app_attempt_id {, application_id {, id: 8, cluster_timestamp: 1376157310799, }, attemptId: 1, }, id: 1, }, state: C_NEW, ]
2013-08-10 18:11:47,020 INFO org.apache.hadoop.yarn.server.resourcemanager.recovery.RMStateStore: Storing info for attempt: appattempt_1376157310799_0008_000001
2013-08-10 18:11:47,020 INFO org.apache.hadoop.yarn.server.resourcemanager.rmapp.attempt.RMAppAttemptImpl: appattempt_1376157310799_0008_000001 State change from SCHEDULED to ALLOCATED_SAVING
2013-08-10 18:11:47,021 INFO org.apache.hadoop.yarn.server.resourcemanager.rmapp.RMAppImpl: application_1376157310799_0010 State change from NEW to SUBMITTED
2013-08-10 18:11:47,021 INFO org.apache.hadoop.yarn.server.resourcemanager.rmapp.attempt.RMAppAttemptImpl: appattempt_1376157310799_0008_000001 State change from ALLOCATED_SAVING to ALLOCATED
2013-08-10 18:11:47,021 INFO org.apache.hadoop.yarn.server.resourcemanager.ApplicationMasterService: Registering appattempt_1376157310799_0010_000001
2013-08-10 18:11:47,021 INFO org.apache.hadoop.yarn.server.resourcemanager.rmapp.attempt.RMAppAttemptImpl: appattempt_1376157310799_0010_000001 State change from NEW to SUBMITTED
2013-08-10 18:11:47,021 INFO org.apache.hadoop.yarn.server.resourcemanager.amlauncher.AMLauncher: Launching masterappattempt_1376157310799_0008_000001
2013-08-10 18:11:47,022 INFO org.apache.hadoop.yarn.server.resourcemanager.amlauncher.AMLauncher: Setting up container Container: [ContainerId: container_1376157310799_0008_01_000001, NodeId: hadoop-221-5:56475, NodeHttpAddress: hadoop-221-5:8042, Resource: <memory:2048, vCores:1>, Priority: 0, State: NEW, Token: null, Status: container_id {, app_attempt_id {, application_id {, id: 8, cluster_timestamp: 1376157310799, }, attemptId: 1, }, id: 1, }, state: C_NEW, ] for AM appattempt_1376157310799_0008_000001
2013-08-10 18:11:47,023 INFO org.apache.hadoop.yarn.server.resourcemanager.amlauncher.AMLauncher: Command to launch container container_1376157310799_0008_01_000001 : $JAVA_HOME/bin/java -Dlog4j.configuration=container-log4j.properties -Dyarn.app.mapreduce.container.log.dir=<LOG_DIR> -Dyarn.app.mapreduce.container.log.filesize=0 -Dhadoop.root.logger=INFO,CLA  -Xmx1024m org.apache.hadoop.mapreduce.v2.app.MRAppMaster 1><LOG_DIR>/stdout 2><LOG_DIR>/stderr 
2013-08-10 18:11:47,024 INFO org.apache.hadoop.yarn.server.resourcemanager.scheduler.capacity.LeafQueue: Application application_1376157310799_0010 from user: ubuntu activated in queue: default
2013-08-10 18:11:47,024 INFO org.apache.hadoop.yarn.server.resourcemanager.scheduler.capacity.LeafQueue: Application added - appId: application_1376157310799_0010 user: org.apache.hadoop.yarn.server.resourcemanager.scheduler.capacity.LeafQueue$User@9a9303c, leaf-queue: default #user-pending-applications: 0 #user-active-applications: 5 #queue-pending-applications: 0 #queue-active-applications: 5
2013-08-10 18:11:47,024 INFO org.apache.hadoop.yarn.server.resourcemanager.scheduler.capacity.ParentQueue: Application added - appId: application_1376157310799_0010 user: ubuntu leaf-queue of parent: root #applications: 5
2013-08-10 18:11:47,026 INFO org.apache.hadoop.yarn.server.resourcemanager.scheduler.capacity.CapacityScheduler: Application Submission: appattempt_1376157310799_0010_000001, user: ubuntu queue: default: capacity=1.0, absoluteCapacity=1.0, usedResources=<memory:6144, vCores:3>usedCapacity=0.125, absoluteUsedCapacity=0.125, numApps=5, numContainers=3, currently active: 5
2013-08-10 18:11:47,028 INFO org.apache.hadoop.yarn.server.resourcemanager.rmapp.attempt.RMAppAttemptImpl: appattempt_1376157310799_0010_000001 State change from SUBMITTED to SCHEDULED
2013-08-10 18:11:47,031 INFO org.apache.hadoop.yarn.server.resourcemanager.rmapp.RMAppImpl: application_1376157310799_0010 State change from SUBMITTED to ACCEPTED
2013-08-10 18:11:47,038 INFO org.apache.hadoop.yarn.server.resourcemanager.amlauncher.AMLauncher: Done launching container Container: [ContainerId: container_1376157310799_0008_01_000001, NodeId: hadoop-221-5:56475, NodeHttpAddress: hadoop-221-5:8042, Resource: <memory:2048, vCores:1>, Priority: 0, State: NEW, Token: null, Status: container_id {, app_attempt_id {, application_id {, id: 8, cluster_timestamp: 1376157310799, }, attemptId: 1, }, id: 1, }, state: C_NEW, ] for AM appattempt_1376157310799_0008_000001
2013-08-10 18:11:47,038 INFO org.apache.hadoop.yarn.server.resourcemanager.rmapp.attempt.RMAppAttemptImpl: appattempt_1376157310799_0008_000001 State change from ALLOCATED to LAUNCHED
2013-08-10 18:11:47,112 INFO org.apache.hadoop.yarn.server.resourcemanager.rmcontainer.RMContainerImpl: container_1376157310799_0009_01_000001 Container Transitioned from NEW to ALLOCATED
2013-08-10 18:11:47,113 INFO org.apache.hadoop.yarn.server.resourcemanager.RMAuditLogger: USER=ubuntu	OPERATION=AM Allocated Container	TARGET=SchedulerApp	RESULT=SUCCESS	APPID=application_1376157310799_0009	CONTAINERID=container_1376157310799_0009_01_000001
2013-08-10 18:11:47,113 INFO org.apache.hadoop.yarn.server.resourcemanager.scheduler.common.fica.FiCaSchedulerNode: Assigned container container_1376157310799_0009_01_000001 of capacity <memory:2048, vCores:1> on host hadoop-221-3:38242, which currently has 1 containers, <memory:2048, vCores:1> used and <memory:6144, vCores:15> available
2013-08-10 18:11:47,114 INFO org.apache.hadoop.yarn.server.resourcemanager.scheduler.capacity.LeafQueue: assignedContainer application=application_1376157310799_0009 container=Container: [ContainerId: container_1376157310799_0009_01_000001, NodeId: hadoop-221-3:38242, NodeHttpAddress: hadoop-221-3:8042, Resource: <memory:2048, vCores:1>, Priority: 0, State: NEW, Token: null, Status: container_id {, app_attempt_id {, application_id {, id: 9, cluster_timestamp: 1376157310799, }, attemptId: 1, }, id: 1, }, state: C_NEW, ] containerId=container_1376157310799_0009_01_000001 queue=default: capacity=1.0, absoluteCapacity=1.0, usedResources=<memory:6144, vCores:3>usedCapacity=0.125, absoluteUsedCapacity=0.125, numApps=5, numContainers=3 usedCapacity=0.125 absoluteUsedCapacity=0.125 used=<memory:6144, vCores:3> cluster=<memory:49152, vCores:96>
2013-08-10 18:11:47,114 INFO org.apache.hadoop.yarn.server.resourcemanager.scheduler.capacity.ParentQueue: Re-sorting queues since queue: root.default stats: default: capacity=1.0, absoluteCapacity=1.0, usedResources=<memory:8192, vCores:4>usedCapacity=0.16666667, absoluteUsedCapacity=0.16666667, numApps=5, numContainers=4
2013-08-10 18:11:47,114 INFO org.apache.hadoop.yarn.server.resourcemanager.scheduler.capacity.ParentQueue: assignedContainer queue=root usedCapacity=0.16666667 absoluteUsedCapacity=0.16666667 used=<memory:8192, vCores:4> cluster=<memory:49152, vCores:96>
2013-08-10 18:11:47,115 INFO org.apache.hadoop.yarn.server.resourcemanager.rmcontainer.RMContainerImpl: container_1376157310799_0009_01_000001 Container Transitioned from ALLOCATED to ACQUIRED
2013-08-10 18:11:47,116 INFO org.apache.hadoop.yarn.server.resourcemanager.rmapp.attempt.RMAppAttemptImpl: Storing attempt: AppId: application_1376157310799_0009 AttemptId: appattempt_1376157310799_0009_000001 MasterContainer: Container: [ContainerId: container_1376157310799_0009_01_000001, NodeId: hadoop-221-3:38242, NodeHttpAddress: hadoop-221-3:8042, Resource: <memory:2048, vCores:1>, Priority: 0, State: NEW, Token: null, Status: container_id {, app_attempt_id {, application_id {, id: 9, cluster_timestamp: 1376157310799, }, attemptId: 1, }, id: 1, }, state: C_NEW, ]
2013-08-10 18:11:47,116 INFO org.apache.hadoop.yarn.server.resourcemanager.rmapp.attempt.RMAppAttemptImpl: appattempt_1376157310799_0009_000001 State change from SCHEDULED to ALLOCATED_SAVING
2013-08-10 18:11:47,116 INFO org.apache.hadoop.yarn.server.resourcemanager.recovery.RMStateStore: Storing info for attempt: appattempt_1376157310799_0009_000001
2013-08-10 18:11:47,116 INFO org.apache.hadoop.yarn.server.resourcemanager.rmapp.attempt.RMAppAttemptImpl: appattempt_1376157310799_0009_000001 State change from ALLOCATED_SAVING to ALLOCATED
2013-08-10 18:11:47,117 INFO org.apache.hadoop.yarn.server.resourcemanager.amlauncher.AMLauncher: Launching masterappattempt_1376157310799_0009_000001
2013-08-10 18:11:47,118 INFO org.apache.hadoop.yarn.server.resourcemanager.amlauncher.AMLauncher: Setting up container Container: [ContainerId: container_1376157310799_0009_01_000001, NodeId: hadoop-221-3:38242, NodeHttpAddress: hadoop-221-3:8042, Resource: <memory:2048, vCores:1>, Priority: 0, State: NEW, Token: null, Status: container_id {, app_attempt_id {, application_id {, id: 9, cluster_timestamp: 1376157310799, }, attemptId: 1, }, id: 1, }, state: C_NEW, ] for AM appattempt_1376157310799_0009_000001
2013-08-10 18:11:47,118 INFO org.apache.hadoop.yarn.server.resourcemanager.amlauncher.AMLauncher: Command to launch container container_1376157310799_0009_01_000001 : $JAVA_HOME/bin/java -Dlog4j.configuration=container-log4j.properties -Dyarn.app.mapreduce.container.log.dir=<LOG_DIR> -Dyarn.app.mapreduce.container.log.filesize=0 -Dhadoop.root.logger=INFO,CLA  -Xmx1024m org.apache.hadoop.mapreduce.v2.app.MRAppMaster 1><LOG_DIR>/stdout 2><LOG_DIR>/stderr 
2013-08-10 18:11:47,133 INFO org.apache.hadoop.yarn.server.resourcemanager.amlauncher.AMLauncher: Done launching container Container: [ContainerId: container_1376157310799_0009_01_000001, NodeId: hadoop-221-3:38242, NodeHttpAddress: hadoop-221-3:8042, Resource: <memory:2048, vCores:1>, Priority: 0, State: NEW, Token: null, Status: container_id {, app_attempt_id {, application_id {, id: 9, cluster_timestamp: 1376157310799, }, attemptId: 1, }, id: 1, }, state: C_NEW, ] for AM appattempt_1376157310799_0009_000001
2013-08-10 18:11:47,133 INFO org.apache.hadoop.yarn.server.resourcemanager.rmapp.attempt.RMAppAttemptImpl: appattempt_1376157310799_0009_000001 State change from ALLOCATED to LAUNCHED
2013-08-10 18:11:47,349 INFO org.apache.hadoop.yarn.server.resourcemanager.rmcontainer.RMContainerImpl: container_1376157310799_0010_01_000001 Container Transitioned from NEW to ALLOCATED
2013-08-10 18:11:47,350 INFO org.apache.hadoop.yarn.server.resourcemanager.RMAuditLogger: USER=ubuntu	OPERATION=AM Allocated Container	TARGET=SchedulerApp	RESULT=SUCCESS	APPID=application_1376157310799_0010	CONTAINERID=container_1376157310799_0010_01_000001
2013-08-10 18:11:47,350 INFO org.apache.hadoop.yarn.server.resourcemanager.scheduler.common.fica.FiCaSchedulerNode: Assigned container container_1376157310799_0010_01_000001 of capacity <memory:2048, vCores:1> on host hadoop-221-4:33277, which currently has 1 containers, <memory:2048, vCores:1> used and <memory:6144, vCores:15> available
2013-08-10 18:11:47,351 INFO org.apache.hadoop.yarn.server.resourcemanager.scheduler.capacity.LeafQueue: assignedContainer application=application_1376157310799_0010 container=Container: [ContainerId: container_1376157310799_0010_01_000001, NodeId: hadoop-221-4:33277, NodeHttpAddress: hadoop-221-4:8042, Resource: <memory:2048, vCores:1>, Priority: 0, State: NEW, Token: null, Status: container_id {, app_attempt_id {, application_id {, id: 10, cluster_timestamp: 1376157310799, }, attemptId: 1, }, id: 1, }, state: C_NEW, ] containerId=container_1376157310799_0010_01_000001 queue=default: capacity=1.0, absoluteCapacity=1.0, usedResources=<memory:8192, vCores:4>usedCapacity=0.16666667, absoluteUsedCapacity=0.16666667, numApps=5, numContainers=4 usedCapacity=0.16666667 absoluteUsedCapacity=0.16666667 used=<memory:8192, vCores:4> cluster=<memory:49152, vCores:96>
2013-08-10 18:11:47,351 INFO org.apache.hadoop.yarn.server.resourcemanager.scheduler.capacity.ParentQueue: Re-sorting queues since queue: root.default stats: default: capacity=1.0, absoluteCapacity=1.0, usedResources=<memory:10240, vCores:5>usedCapacity=0.20833333, absoluteUsedCapacity=0.20833333, numApps=5, numContainers=5
2013-08-10 18:11:47,352 INFO org.apache.hadoop.yarn.server.resourcemanager.scheduler.capacity.ParentQueue: assignedContainer queue=root usedCapacity=0.20833333 absoluteUsedCapacity=0.20833333 used=<memory:10240, vCores:5> cluster=<memory:49152, vCores:96>
2013-08-10 18:11:47,353 INFO org.apache.hadoop.yarn.server.resourcemanager.rmcontainer.RMContainerImpl: container_1376157310799_0010_01_000001 Container Transitioned from ALLOCATED to ACQUIRED
2013-08-10 18:11:47,353 INFO org.apache.hadoop.yarn.server.resourcemanager.rmapp.attempt.RMAppAttemptImpl: Storing attempt: AppId: application_1376157310799_0010 AttemptId: appattempt_1376157310799_0010_000001 MasterContainer: Container: [ContainerId: container_1376157310799_0010_01_000001, NodeId: hadoop-221-4:33277, NodeHttpAddress: hadoop-221-4:8042, Resource: <memory:2048, vCores:1>, Priority: 0, State: NEW, Token: null, Status: container_id {, app_attempt_id {, application_id {, id: 10, cluster_timestamp: 1376157310799, }, attemptId: 1, }, id: 1, }, state: C_NEW, ]
2013-08-10 18:11:47,354 INFO org.apache.hadoop.yarn.server.resourcemanager.rmapp.attempt.RMAppAttemptImpl: appattempt_1376157310799_0010_000001 State change from SCHEDULED to ALLOCATED_SAVING
2013-08-10 18:11:47,354 INFO org.apache.hadoop.yarn.server.resourcemanager.recovery.RMStateStore: Storing info for attempt: appattempt_1376157310799_0010_000001
2013-08-10 18:11:47,354 INFO org.apache.hadoop.yarn.server.resourcemanager.rmapp.attempt.RMAppAttemptImpl: appattempt_1376157310799_0010_000001 State change from ALLOCATED_SAVING to ALLOCATED
2013-08-10 18:11:47,354 INFO org.apache.hadoop.yarn.server.resourcemanager.amlauncher.AMLauncher: Launching masterappattempt_1376157310799_0010_000001
2013-08-10 18:11:47,355 INFO org.apache.hadoop.yarn.server.resourcemanager.amlauncher.AMLauncher: Setting up container Container: [ContainerId: container_1376157310799_0010_01_000001, NodeId: hadoop-221-4:33277, NodeHttpAddress: hadoop-221-4:8042, Resource: <memory:2048, vCores:1>, Priority: 0, State: NEW, Token: null, Status: container_id {, app_attempt_id {, application_id {, id: 10, cluster_timestamp: 1376157310799, }, attemptId: 1, }, id: 1, }, state: C_NEW, ] for AM appattempt_1376157310799_0010_000001
2013-08-10 18:11:47,356 INFO org.apache.hadoop.yarn.server.resourcemanager.amlauncher.AMLauncher: Command to launch container container_1376157310799_0010_01_000001 : $JAVA_HOME/bin/java -Dlog4j.configuration=container-log4j.properties -Dyarn.app.mapreduce.container.log.dir=<LOG_DIR> -Dyarn.app.mapreduce.container.log.filesize=0 -Dhadoop.root.logger=INFO,CLA  -Xmx1024m org.apache.hadoop.mapreduce.v2.app.MRAppMaster 1><LOG_DIR>/stdout 2><LOG_DIR>/stderr 
2013-08-10 18:11:47,373 INFO org.apache.hadoop.yarn.server.resourcemanager.amlauncher.AMLauncher: Done launching container Container: [ContainerId: container_1376157310799_0010_01_000001, NodeId: hadoop-221-4:33277, NodeHttpAddress: hadoop-221-4:8042, Resource: <memory:2048, vCores:1>, Priority: 0, State: NEW, Token: null, Status: container_id {, app_attempt_id {, application_id {, id: 10, cluster_timestamp: 1376157310799, }, attemptId: 1, }, id: 1, }, state: C_NEW, ] for AM appattempt_1376157310799_0010_000001
2013-08-10 18:11:47,373 INFO org.apache.hadoop.yarn.server.resourcemanager.rmapp.attempt.RMAppAttemptImpl: appattempt_1376157310799_0010_000001 State change from ALLOCATED to LAUNCHED
2013-08-10 18:11:47,787 INFO org.apache.hadoop.yarn.server.resourcemanager.rmcontainer.RMContainerImpl: container_1376157310799_0006_01_000001 Container Transitioned from ACQUIRED to RUNNING
2013-08-10 18:11:47,976 INFO org.apache.hadoop.yarn.server.resourcemanager.rmcontainer.RMContainerImpl: container_1376157310799_0007_01_000001 Container Transitioned from ACQUIRED to RUNNING
2013-08-10 18:11:48,020 INFO org.apache.hadoop.yarn.server.resourcemanager.rmcontainer.RMContainerImpl: container_1376157310799_0008_01_000001 Container Transitioned from ACQUIRED to RUNNING
2013-08-10 18:11:48,118 INFO org.apache.hadoop.yarn.server.resourcemanager.rmcontainer.RMContainerImpl: container_1376157310799_0009_01_000001 Container Transitioned from ACQUIRED to RUNNING
2013-08-10 18:11:48,355 INFO org.apache.hadoop.yarn.server.resourcemanager.rmcontainer.RMContainerImpl: container_1376157310799_0010_01_000001 Container Transitioned from ACQUIRED to RUNNING
2013-08-10 18:11:52,447 INFO org.apache.hadoop.yarn.server.resourcemanager.ApplicationMasterService: AM registration appattempt_1376157310799_0010_000001
2013-08-10 18:11:52,447 INFO org.apache.hadoop.yarn.server.resourcemanager.RMAuditLogger: USER=ubuntu	IP=192.168.100.31	OPERATION=Register App Master	TARGET=ApplicationMasterService	RESULT=SUCCESS	APPID=application_1376157310799_0010	APPATTEMPTID=appattempt_1376157310799_0010_000001
2013-08-10 18:11:52,448 INFO org.apache.hadoop.yarn.server.resourcemanager.rmapp.attempt.RMAppAttemptImpl: appattempt_1376157310799_0010_000001 State change from LAUNCHED to RUNNING
2013-08-10 18:11:52,448 INFO org.apache.hadoop.yarn.server.resourcemanager.rmapp.RMAppImpl: application_1376157310799_0010 State change from ACCEPTED to RUNNING
2013-08-10 18:11:53,820 INFO org.apache.hadoop.yarn.server.resourcemanager.rmcontainer.RMContainerImpl: container_1376157310799_0010_01_000002 Container Transitioned from NEW to ALLOCATED
2013-08-10 18:11:53,821 INFO org.apache.hadoop.yarn.server.resourcemanager.RMAuditLogger: USER=ubuntu	OPERATION=AM Allocated Container	TARGET=SchedulerApp	RESULT=SUCCESS	APPID=application_1376157310799_0010	CONTAINERID=container_1376157310799_0010_01_000002
2013-08-10 18:11:53,821 INFO org.apache.hadoop.yarn.server.resourcemanager.scheduler.common.fica.FiCaSchedulerNode: Assigned container container_1376157310799_0010_01_000002 of capacity <memory:1024, vCores:1> on host hadoop-221-2:56306, which currently has 2 containers, <memory:3072, vCores:2> used and <memory:5120, vCores:14> available
2013-08-10 18:11:53,822 INFO org.apache.hadoop.yarn.server.resourcemanager.scheduler.capacity.LeafQueue: assignedContainer application=application_1376157310799_0010 container=Container: [ContainerId: container_1376157310799_0010_01_000002, NodeId: hadoop-221-2:56306, NodeHttpAddress: hadoop-221-2:8042, Resource: <memory:1024, vCores:1>, Priority: 20, State: NEW, Token: null, Status: container_id {, app_attempt_id {, application_id {, id: 10, cluster_timestamp: 1376157310799, }, attemptId: 1, }, id: 2, }, state: C_NEW, ] containerId=container_1376157310799_0010_01_000002 queue=default: capacity=1.0, absoluteCapacity=1.0, usedResources=<memory:10240, vCores:5>usedCapacity=0.20833333, absoluteUsedCapacity=0.20833333, numApps=5, numContainers=5 usedCapacity=0.20833333 absoluteUsedCapacity=0.20833333 used=<memory:10240, vCores:5> cluster=<memory:49152, vCores:96>
2013-08-10 18:11:53,822 INFO org.apache.hadoop.yarn.server.resourcemanager.scheduler.capacity.ParentQueue: Re-sorting queues since queue: root.default stats: default: capacity=1.0, absoluteCapacity=1.0, usedResources=<memory:11264, vCores:6>usedCapacity=0.22916667, absoluteUsedCapacity=0.22916667, numApps=5, numContainers=6
2013-08-10 18:11:53,823 INFO org.apache.hadoop.yarn.server.resourcemanager.scheduler.capacity.ParentQueue: assignedContainer queue=root usedCapacity=0.22916667 absoluteUsedCapacity=0.22916667 used=<memory:11264, vCores:6> cluster=<memory:49152, vCores:96>
2013-08-10 18:11:53,823 INFO org.apache.hadoop.yarn.server.resourcemanager.rmcontainer.RMContainerImpl: container_1376157310799_0010_01_000003 Container Transitioned from NEW to ALLOCATED
2013-08-10 18:11:53,823 INFO org.apache.hadoop.yarn.server.resourcemanager.RMAuditLogger: USER=ubuntu	OPERATION=AM Allocated Container	TARGET=SchedulerApp	RESULT=SUCCESS	APPID=application_1376157310799_0010	CONTAINERID=container_1376157310799_0010_01_000003
2013-08-10 18:11:53,823 INFO org.apache.hadoop.yarn.server.resourcemanager.scheduler.common.fica.FiCaSchedulerNode: Assigned container container_1376157310799_0010_01_000003 of capacity <memory:1024, vCores:1> on host hadoop-221-2:56306, which currently has 3 containers, <memory:4096, vCores:3> used and <memory:4096, vCores:13> available
2013-08-10 18:11:53,825 INFO org.apache.hadoop.yarn.server.resourcemanager.scheduler.capacity.LeafQueue: assignedContainer application=application_1376157310799_0010 container=Container: [ContainerId: container_1376157310799_0010_01_000003, NodeId: hadoop-221-2:56306, NodeHttpAddress: hadoop-221-2:8042, Resource: <memory:1024, vCores:1>, Priority: 20, State: NEW, Token: null, Status: container_id {, app_attempt_id {, application_id {, id: 10, cluster_timestamp: 1376157310799, }, attemptId: 1, }, id: 3, }, state: C_NEW, ] containerId=container_1376157310799_0010_01_000003 queue=default: capacity=1.0, absoluteCapacity=1.0, usedResources=<memory:11264, vCores:6>usedCapacity=0.22916667, absoluteUsedCapacity=0.22916667, numApps=5, numContainers=6 usedCapacity=0.22916667 absoluteUsedCapacity=0.22916667 used=<memory:11264, vCores:6> cluster=<memory:49152, vCores:96>
2013-08-10 18:11:53,825 INFO org.apache.hadoop.yarn.server.resourcemanager.scheduler.capacity.ParentQueue: Re-sorting queues since queue: root.default stats: default: capacity=1.0, absoluteCapacity=1.0, usedResources=<memory:12288, vCores:7>usedCapacity=0.25, absoluteUsedCapacity=0.25, numApps=5, numContainers=7
2013-08-10 18:11:53,825 INFO org.apache.hadoop.yarn.server.resourcemanager.scheduler.capacity.ParentQueue: assignedContainer queue=root usedCapacity=0.25 absoluteUsedCapacity=0.25 used=<memory:12288, vCores:7> cluster=<memory:49152, vCores:96>
2013-08-10 18:11:53,825 INFO org.apache.hadoop.yarn.server.resourcemanager.rmcontainer.RMContainerImpl: container_1376157310799_0010_01_000004 Container Transitioned from NEW to ALLOCATED
2013-08-10 18:11:53,826 INFO org.apache.hadoop.yarn.server.resourcemanager.RMAuditLogger: USER=ubuntu	OPERATION=AM Allocated Container	TARGET=SchedulerApp	RESULT=SUCCESS	APPID=application_1376157310799_0010	CONTAINERID=container_1376157310799_0010_01_000004
2013-08-10 18:11:53,826 INFO org.apache.hadoop.yarn.server.resourcemanager.scheduler.common.fica.FiCaSchedulerNode: Assigned container container_1376157310799_0010_01_000004 of capacity <memory:1024, vCores:1> on host hadoop-221-2:56306, which currently has 4 containers, <memory:5120, vCores:4> used and <memory:3072, vCores:12> available
2013-08-10 18:11:53,827 INFO org.apache.hadoop.yarn.server.resourcemanager.scheduler.capacity.LeafQueue: assignedContainer application=application_1376157310799_0010 container=Container: [ContainerId: container_1376157310799_0010_01_000004, NodeId: hadoop-221-2:56306, NodeHttpAddress: hadoop-221-2:8042, Resource: <memory:1024, vCores:1>, Priority: 20, State: NEW, Token: null, Status: container_id {, app_attempt_id {, application_id {, id: 10, cluster_timestamp: 1376157310799, }, attemptId: 1, }, id: 4, }, state: C_NEW, ] containerId=container_1376157310799_0010_01_000004 queue=default: capacity=1.0, absoluteCapacity=1.0, usedResources=<memory:12288, vCores:7>usedCapacity=0.25, absoluteUsedCapacity=0.25, numApps=5, numContainers=7 usedCapacity=0.25 absoluteUsedCapacity=0.25 used=<memory:12288, vCores:7> cluster=<memory:49152, vCores:96>
2013-08-10 18:11:53,827 INFO org.apache.hadoop.yarn.server.resourcemanager.scheduler.capacity.ParentQueue: Re-sorting queues since queue: root.default stats: default: capacity=1.0, absoluteCapacity=1.0, usedResources=<memory:13312, vCores:8>usedCapacity=0.27083334, absoluteUsedCapacity=0.27083334, numApps=5, numContainers=8
2013-08-10 18:11:53,827 INFO org.apache.hadoop.yarn.server.resourcemanager.scheduler.capacity.ParentQueue: assignedContainer queue=root usedCapacity=0.27083334 absoluteUsedCapacity=0.27083334 used=<memory:13312, vCores:8> cluster=<memory:49152, vCores:96>
2013-08-10 18:11:53,828 INFO org.apache.hadoop.yarn.server.resourcemanager.rmcontainer.RMContainerImpl: container_1376157310799_0010_01_000005 Container Transitioned from NEW to ALLOCATED
2013-08-10 18:11:53,828 INFO org.apache.hadoop.yarn.server.resourcemanager.RMAuditLogger: USER=ubuntu	OPERATION=AM Allocated Container	TARGET=SchedulerApp	RESULT=SUCCESS	APPID=application_1376157310799_0010	CONTAINERID=container_1376157310799_0010_01_000005
2013-08-10 18:11:53,828 INFO org.apache.hadoop.yarn.server.resourcemanager.scheduler.common.fica.FiCaSchedulerNode: Assigned container container_1376157310799_0010_01_000005 of capacity <memory:1024, vCores:1> on host hadoop-221-2:56306, which currently has 5 containers, <memory:6144, vCores:5> used and <memory:2048, vCores:11> available
2013-08-10 18:11:53,829 INFO org.apache.hadoop.yarn.server.resourcemanager.scheduler.capacity.LeafQueue: assignedContainer application=application_1376157310799_0010 container=Container: [ContainerId: container_1376157310799_0010_01_000005, NodeId: hadoop-221-2:56306, NodeHttpAddress: hadoop-221-2:8042, Resource: <memory:1024, vCores:1>, Priority: 20, State: NEW, Token: null, Status: container_id {, app_attempt_id {, application_id {, id: 10, cluster_timestamp: 1376157310799, }, attemptId: 1, }, id: 5, }, state: C_NEW, ] containerId=container_1376157310799_0010_01_000005 queue=default: capacity=1.0, absoluteCapacity=1.0, usedResources=<memory:13312, vCores:8>usedCapacity=0.27083334, absoluteUsedCapacity=0.27083334, numApps=5, numContainers=8 usedCapacity=0.27083334 absoluteUsedCapacity=0.27083334 used=<memory:13312, vCores:8> cluster=<memory:49152, vCores:96>
2013-08-10 18:11:53,830 INFO org.apache.hadoop.yarn.server.resourcemanager.scheduler.capacity.ParentQueue: Re-sorting queues since queue: root.default stats: default: capacity=1.0, absoluteCapacity=1.0, usedResources=<memory:14336, vCores:9>usedCapacity=0.29166666, absoluteUsedCapacity=0.29166666, numApps=5, numContainers=9
2013-08-10 18:11:53,830 INFO org.apache.hadoop.yarn.server.resourcemanager.scheduler.capacity.ParentQueue: assignedContainer queue=root usedCapacity=0.29166666 absoluteUsedCapacity=0.29166666 used=<memory:14336, vCores:9> cluster=<memory:49152, vCores:96>
2013-08-10 18:11:53,830 INFO org.apache.hadoop.yarn.server.resourcemanager.rmcontainer.RMContainerImpl: container_1376157310799_0010_01_000006 Container Transitioned from NEW to ALLOCATED
2013-08-10 18:11:53,830 INFO org.apache.hadoop.yarn.server.resourcemanager.RMAuditLogger: USER=ubuntu	OPERATION=AM Allocated Container	TARGET=SchedulerApp	RESULT=SUCCESS	APPID=application_1376157310799_0010	CONTAINERID=container_1376157310799_0010_01_000006
2013-08-10 18:11:53,831 INFO org.apache.hadoop.yarn.server.resourcemanager.scheduler.common.fica.FiCaSchedulerNode: Assigned container container_1376157310799_0010_01_000006 of capacity <memory:1024, vCores:1> on host hadoop-221-2:56306, which currently has 6 containers, <memory:7168, vCores:6> used and <memory:1024, vCores:10> available
2013-08-10 18:11:53,832 INFO org.apache.hadoop.yarn.server.resourcemanager.scheduler.capacity.LeafQueue: assignedContainer application=application_1376157310799_0010 container=Container: [ContainerId: container_1376157310799_0010_01_000006, NodeId: hadoop-221-2:56306, NodeHttpAddress: hadoop-221-2:8042, Resource: <memory:1024, vCores:1>, Priority: 20, State: NEW, Token: null, Status: container_id {, app_attempt_id {, application_id {, id: 10, cluster_timestamp: 1376157310799, }, attemptId: 1, }, id: 6, }, state: C_NEW, ] containerId=container_1376157310799_0010_01_000006 queue=default: capacity=1.0, absoluteCapacity=1.0, usedResources=<memory:14336, vCores:9>usedCapacity=0.29166666, absoluteUsedCapacity=0.29166666, numApps=5, numContainers=9 usedCapacity=0.29166666 absoluteUsedCapacity=0.29166666 used=<memory:14336, vCores:9> cluster=<memory:49152, vCores:96>
2013-08-10 18:11:53,832 INFO org.apache.hadoop.yarn.server.resourcemanager.scheduler.capacity.ParentQueue: Re-sorting queues since queue: root.default stats: default: capacity=1.0, absoluteCapacity=1.0, usedResources=<memory:15360, vCores:10>usedCapacity=0.3125, absoluteUsedCapacity=0.3125, numApps=5, numContainers=10
2013-08-10 18:11:53,832 INFO org.apache.hadoop.yarn.server.resourcemanager.scheduler.capacity.ParentQueue: assignedContainer queue=root usedCapacity=0.3125 absoluteUsedCapacity=0.3125 used=<memory:15360, vCores:10> cluster=<memory:49152, vCores:96>
2013-08-10 18:11:53,833 INFO org.apache.hadoop.yarn.server.resourcemanager.rmcontainer.RMContainerImpl: container_1376157310799_0010_01_000007 Container Transitioned from NEW to ALLOCATED
2013-08-10 18:11:53,833 INFO org.apache.hadoop.yarn.server.resourcemanager.RMAuditLogger: USER=ubuntu	OPERATION=AM Allocated Container	TARGET=SchedulerApp	RESULT=SUCCESS	APPID=application_1376157310799_0010	CONTAINERID=container_1376157310799_0010_01_000007
2013-08-10 18:11:53,833 INFO org.apache.hadoop.yarn.server.resourcemanager.scheduler.common.fica.FiCaSchedulerNode: Assigned container container_1376157310799_0010_01_000007 of capacity <memory:1024, vCores:1> on host hadoop-221-2:56306, which currently has 7 containers, <memory:8192, vCores:7> used and <memory:0, vCores:9> available
2013-08-10 18:11:53,834 INFO org.apache.hadoop.yarn.server.resourcemanager.scheduler.capacity.LeafQueue: assignedContainer application=application_1376157310799_0010 container=Container: [ContainerId: container_1376157310799_0010_01_000007, NodeId: hadoop-221-2:56306, NodeHttpAddress: hadoop-221-2:8042, Resource: <memory:1024, vCores:1>, Priority: 20, State: NEW, Token: null, Status: container_id {, app_attempt_id {, application_id {, id: 10, cluster_timestamp: 1376157310799, }, attemptId: 1, }, id: 7, }, state: C_NEW, ] containerId=container_1376157310799_0010_01_000007 queue=default: capacity=1.0, absoluteCapacity=1.0, usedResources=<memory:15360, vCores:10>usedCapacity=0.3125, absoluteUsedCapacity=0.3125, numApps=5, numContainers=10 usedCapacity=0.3125 absoluteUsedCapacity=0.3125 used=<memory:15360, vCores:10> cluster=<memory:49152, vCores:96>
2013-08-10 18:11:53,834 INFO org.apache.hadoop.yarn.server.resourcemanager.scheduler.capacity.ParentQueue: Re-sorting queues since queue: root.default stats: default: capacity=1.0, absoluteCapacity=1.0, usedResources=<memory:16384, vCores:11>usedCapacity=0.33333334, absoluteUsedCapacity=0.33333334, numApps=5, numContainers=11
2013-08-10 18:11:53,834 INFO org.apache.hadoop.yarn.server.resourcemanager.scheduler.capacity.ParentQueue: assignedContainer queue=root usedCapacity=0.33333334 absoluteUsedCapacity=0.33333334 used=<memory:16384, vCores:11> cluster=<memory:49152, vCores:96>
2013-08-10 18:11:54,011 INFO org.apache.hadoop.yarn.server.resourcemanager.rmcontainer.RMContainerImpl: container_1376157310799_0010_01_000008 Container Transitioned from NEW to ALLOCATED
2013-08-10 18:11:54,012 INFO org.apache.hadoop.yarn.server.resourcemanager.RMAuditLogger: USER=ubuntu	OPERATION=AM Allocated Container	TARGET=SchedulerApp	RESULT=SUCCESS	APPID=application_1376157310799_0010	CONTAINERID=container_1376157310799_0010_01_000008
2013-08-10 18:11:54,012 INFO org.apache.hadoop.yarn.server.resourcemanager.scheduler.common.fica.FiCaSchedulerNode: Assigned container container_1376157310799_0010_01_000008 of capacity <memory:1024, vCores:1> on host hadoop-221-7:56906, which currently has 2 containers, <memory:3072, vCores:2> used and <memory:5120, vCores:14> available
2013-08-10 18:11:54,013 INFO org.apache.hadoop.yarn.server.resourcemanager.scheduler.capacity.LeafQueue: assignedContainer application=application_1376157310799_0010 container=Container: [ContainerId: container_1376157310799_0010_01_000008, NodeId: hadoop-221-7:56906, NodeHttpAddress: hadoop-221-7:8042, Resource: <memory:1024, vCores:1>, Priority: 20, State: NEW, Token: null, Status: container_id {, app_attempt_id {, application_id {, id: 10, cluster_timestamp: 1376157310799, }, attemptId: 1, }, id: 8, }, state: C_NEW, ] containerId=container_1376157310799_0010_01_000008 queue=default: capacity=1.0, absoluteCapacity=1.0, usedResources=<memory:16384, vCores:11>usedCapacity=0.33333334, absoluteUsedCapacity=0.33333334, numApps=5, numContainers=11 usedCapacity=0.33333334 absoluteUsedCapacity=0.33333334 used=<memory:16384, vCores:11> cluster=<memory:49152, vCores:96>
2013-08-10 18:11:54,013 INFO org.apache.hadoop.yarn.server.resourcemanager.scheduler.capacity.ParentQueue: Re-sorting queues since queue: root.default stats: default: capacity=1.0, absoluteCapacity=1.0, usedResources=<memory:17408, vCores:12>usedCapacity=0.35416666, absoluteUsedCapacity=0.35416666, numApps=5, numContainers=12
2013-08-10 18:11:54,014 INFO org.apache.hadoop.yarn.server.resourcemanager.scheduler.capacity.ParentQueue: assignedContainer queue=root usedCapacity=0.35416666 absoluteUsedCapacity=0.35416666 used=<memory:17408, vCores:12> cluster=<memory:49152, vCores:96>
2013-08-10 18:11:54,016 INFO org.apache.hadoop.yarn.server.resourcemanager.rmcontainer.RMContainerImpl: container_1376157310799_0010_01_000009 Container Transitioned from NEW to ALLOCATED
2013-08-10 18:11:54,016 INFO org.apache.hadoop.yarn.server.resourcemanager.RMAuditLogger: USER=ubuntu	OPERATION=AM Allocated Container	TARGET=SchedulerApp	RESULT=SUCCESS	APPID=application_1376157310799_0010	CONTAINERID=container_1376157310799_0010_01_000009
2013-08-10 18:11:54,017 INFO org.apache.hadoop.yarn.server.resourcemanager.scheduler.common.fica.FiCaSchedulerNode: Assigned container container_1376157310799_0010_01_000009 of capacity <memory:1024, vCores:1> on host hadoop-221-7:56906, which currently has 3 containers, <memory:4096, vCores:3> used and <memory:4096, vCores:13> available
2013-08-10 18:11:54,018 INFO org.apache.hadoop.yarn.server.resourcemanager.scheduler.capacity.LeafQueue: assignedContainer application=application_1376157310799_0010 container=Container: [ContainerId: container_1376157310799_0010_01_000009, NodeId: hadoop-221-7:56906, NodeHttpAddress: hadoop-221-7:8042, Resource: <memory:1024, vCores:1>, Priority: 20, State: NEW, Token: null, Status: container_id {, app_attempt_id {, application_id {, id: 10, cluster_timestamp: 1376157310799, }, attemptId: 1, }, id: 9, }, state: C_NEW, ] containerId=container_1376157310799_0010_01_000009 queue=default: capacity=1.0, absoluteCapacity=1.0, usedResources=<memory:17408, vCores:12>usedCapacity=0.35416666, absoluteUsedCapacity=0.35416666, numApps=5, numContainers=12 usedCapacity=0.35416666 absoluteUsedCapacity=0.35416666 used=<memory:17408, vCores:12> cluster=<memory:49152, vCores:96>
2013-08-10 18:11:54,018 INFO org.apache.hadoop.yarn.server.resourcemanager.scheduler.capacity.ParentQueue: Re-sorting queues since queue: root.default stats: default: capacity=1.0, absoluteCapacity=1.0, usedResources=<memory:18432, vCores:13>usedCapacity=0.375, absoluteUsedCapacity=0.375, numApps=5, numContainers=13
2013-08-10 18:11:54,018 INFO org.apache.hadoop.yarn.server.resourcemanager.scheduler.capacity.ParentQueue: assignedContainer queue=root usedCapacity=0.375 absoluteUsedCapacity=0.375 used=<memory:18432, vCores:13> cluster=<memory:49152, vCores:96>
2013-08-10 18:11:54,019 INFO org.apache.hadoop.yarn.server.resourcemanager.rmcontainer.RMContainerImpl: container_1376157310799_0010_01_000010 Container Transitioned from NEW to ALLOCATED
2013-08-10 18:11:54,019 INFO org.apache.hadoop.yarn.server.resourcemanager.RMAuditLogger: USER=ubuntu	OPERATION=AM Allocated Container	TARGET=SchedulerApp	RESULT=SUCCESS	APPID=application_1376157310799_0010	CONTAINERID=container_1376157310799_0010_01_000010
2013-08-10 18:11:54,019 INFO org.apache.hadoop.yarn.server.resourcemanager.scheduler.common.fica.FiCaSchedulerNode: Assigned container container_1376157310799_0010_01_000010 of capacity <memory:1024, vCores:1> on host hadoop-221-7:56906, which currently has 4 containers, <memory:5120, vCores:4> used and <memory:3072, vCores:12> available
2013-08-10 18:11:54,020 INFO org.apache.hadoop.yarn.server.resourcemanager.scheduler.capacity.LeafQueue: assignedContainer application=application_1376157310799_0010 container=Container: [ContainerId: container_1376157310799_0010_01_000010, NodeId: hadoop-221-7:56906, NodeHttpAddress: hadoop-221-7:8042, Resource: <memory:1024, vCores:1>, Priority: 20, State: NEW, Token: null, Status: container_id {, app_attempt_id {, application_id {, id: 10, cluster_timestamp: 1376157310799, }, attemptId: 1, }, id: 10, }, state: C_NEW, ] containerId=container_1376157310799_0010_01_000010 queue=default: capacity=1.0, absoluteCapacity=1.0, usedResources=<memory:18432, vCores:13>usedCapacity=0.375, absoluteUsedCapacity=0.375, numApps=5, numContainers=13 usedCapacity=0.375 absoluteUsedCapacity=0.375 used=<memory:18432, vCores:13> cluster=<memory:49152, vCores:96>
2013-08-10 18:11:54,020 INFO org.apache.hadoop.yarn.server.resourcemanager.scheduler.capacity.ParentQueue: Re-sorting queues since queue: root.default stats: default: capacity=1.0, absoluteCapacity=1.0, usedResources=<memory:19456, vCores:14>usedCapacity=0.39583334, absoluteUsedCapacity=0.39583334, numApps=5, numContainers=14
2013-08-10 18:11:54,020 INFO org.apache.hadoop.yarn.server.resourcemanager.scheduler.capacity.ParentQueue: assignedContainer queue=root usedCapacity=0.39583334 absoluteUsedCapacity=0.39583334 used=<memory:19456, vCores:14> cluster=<memory:49152, vCores:96>
2013-08-10 18:11:54,021 INFO org.apache.hadoop.yarn.server.resourcemanager.rmcontainer.RMContainerImpl: container_1376157310799_0010_01_000011 Container Transitioned from NEW to ALLOCATED
2013-08-10 18:11:54,021 INFO org.apache.hadoop.yarn.server.resourcemanager.RMAuditLogger: USER=ubuntu	OPERATION=AM Allocated Container	TARGET=SchedulerApp	RESULT=SUCCESS	APPID=application_1376157310799_0010	CONTAINERID=container_1376157310799_0010_01_000011
2013-08-10 18:11:54,021 INFO org.apache.hadoop.yarn.server.resourcemanager.scheduler.common.fica.FiCaSchedulerNode: Assigned container container_1376157310799_0010_01_000011 of capacity <memory:1024, vCores:1> on host hadoop-221-7:56906, which currently has 5 containers, <memory:6144, vCores:5> used and <memory:2048, vCores:11> available
2013-08-10 18:11:54,022 INFO org.apache.hadoop.yarn.server.resourcemanager.scheduler.capacity.LeafQueue: assignedContainer application=application_1376157310799_0010 container=Container: [ContainerId: container_1376157310799_0010_01_000011, NodeId: hadoop-221-7:56906, NodeHttpAddress: hadoop-221-7:8042, Resource: <memory:1024, vCores:1>, Priority: 20, State: NEW, Token: null, Status: container_id {, app_attempt_id {, application_id {, id: 10, cluster_timestamp: 1376157310799, }, attemptId: 1, }, id: 11, }, state: C_NEW, ] containerId=container_1376157310799_0010_01_000011 queue=default: capacity=1.0, absoluteCapacity=1.0, usedResources=<memory:19456, vCores:14>usedCapacity=0.39583334, absoluteUsedCapacity=0.39583334, numApps=5, numContainers=14 usedCapacity=0.39583334 absoluteUsedCapacity=0.39583334 used=<memory:19456, vCores:14> cluster=<memory:49152, vCores:96>
2013-08-10 18:11:54,022 INFO org.apache.hadoop.yarn.server.resourcemanager.scheduler.capacity.ParentQueue: Re-sorting queues since queue: root.default stats: default: capacity=1.0, absoluteCapacity=1.0, usedResources=<memory:20480, vCores:15>usedCapacity=0.41666666, absoluteUsedCapacity=0.41666666, numApps=5, numContainers=15
2013-08-10 18:11:54,023 INFO org.apache.hadoop.yarn.server.resourcemanager.scheduler.capacity.ParentQueue: assignedContainer queue=root usedCapacity=0.41666666 absoluteUsedCapacity=0.41666666 used=<memory:20480, vCores:15> cluster=<memory:49152, vCores:96>
2013-08-10 18:11:54,023 INFO org.apache.hadoop.yarn.server.resourcemanager.rmcontainer.RMContainerImpl: container_1376157310799_0010_01_000012 Container Transitioned from NEW to ALLOCATED
2013-08-10 18:11:54,023 INFO org.apache.hadoop.yarn.server.resourcemanager.RMAuditLogger: USER=ubuntu	OPERATION=AM Allocated Container	TARGET=SchedulerApp	RESULT=SUCCESS	APPID=application_1376157310799_0010	CONTAINERID=container_1376157310799_0010_01_000012
2013-08-10 18:11:54,023 INFO org.apache.hadoop.yarn.server.resourcemanager.scheduler.common.fica.FiCaSchedulerNode: Assigned container container_1376157310799_0010_01_000012 of capacity <memory:1024, vCores:1> on host hadoop-221-7:56906, which currently has 6 containers, <memory:7168, vCores:6> used and <memory:1024, vCores:10> available
2013-08-10 18:11:54,025 INFO org.apache.hadoop.yarn.server.resourcemanager.scheduler.capacity.LeafQueue: assignedContainer application=application_1376157310799_0010 container=Container: [ContainerId: container_1376157310799_0010_01_000012, NodeId: hadoop-221-7:56906, NodeHttpAddress: hadoop-221-7:8042, Resource: <memory:1024, vCores:1>, Priority: 20, State: NEW, Token: null, Status: container_id {, app_attempt_id {, application_id {, id: 10, cluster_timestamp: 1376157310799, }, attemptId: 1, }, id: 12, }, state: C_NEW, ] containerId=container_1376157310799_0010_01_000012 queue=default: capacity=1.0, absoluteCapacity=1.0, usedResources=<memory:20480, vCores:15>usedCapacity=0.41666666, absoluteUsedCapacity=0.41666666, numApps=5, numContainers=15 usedCapacity=0.41666666 absoluteUsedCapacity=0.41666666 used=<memory:20480, vCores:15> cluster=<memory:49152, vCores:96>
2013-08-10 18:11:54,025 INFO org.apache.hadoop.yarn.server.resourcemanager.scheduler.capacity.ParentQueue: Re-sorting queues since queue: root.default stats: default: capacity=1.0, absoluteCapacity=1.0, usedResources=<memory:21504, vCores:16>usedCapacity=0.4375, absoluteUsedCapacity=0.4375, numApps=5, numContainers=16
2013-08-10 18:11:54,025 INFO org.apache.hadoop.yarn.server.resourcemanager.scheduler.capacity.ParentQueue: assignedContainer queue=root usedCapacity=0.4375 absoluteUsedCapacity=0.4375 used=<memory:21504, vCores:16> cluster=<memory:49152, vCores:96>
2013-08-10 18:11:54,026 INFO org.apache.hadoop.yarn.server.resourcemanager.rmcontainer.RMContainerImpl: container_1376157310799_0010_01_000013 Container Transitioned from NEW to ALLOCATED
2013-08-10 18:11:54,026 INFO org.apache.hadoop.yarn.server.resourcemanager.RMAuditLogger: USER=ubuntu	OPERATION=AM Allocated Container	TARGET=SchedulerApp	RESULT=SUCCESS	APPID=application_1376157310799_0010	CONTAINERID=container_1376157310799_0010_01_000013
2013-08-10 18:11:54,026 INFO org.apache.hadoop.yarn.server.resourcemanager.scheduler.common.fica.FiCaSchedulerNode: Assigned container container_1376157310799_0010_01_000013 of capacity <memory:1024, vCores:1> on host hadoop-221-7:56906, which currently has 7 containers, <memory:8192, vCores:7> used and <memory:0, vCores:9> available
2013-08-10 18:11:54,027 INFO org.apache.hadoop.yarn.server.resourcemanager.scheduler.capacity.LeafQueue: assignedContainer application=application_1376157310799_0010 container=Container: [ContainerId: container_1376157310799_0010_01_000013, NodeId: hadoop-221-7:56906, NodeHttpAddress: hadoop-221-7:8042, Resource: <memory:1024, vCores:1>, Priority: 20, State: NEW, Token: null, Status: container_id {, app_attempt_id {, application_id {, id: 10, cluster_timestamp: 1376157310799, }, attemptId: 1, }, id: 13, }, state: C_NEW, ] containerId=container_1376157310799_0010_01_000013 queue=default: capacity=1.0, absoluteCapacity=1.0, usedResources=<memory:21504, vCores:16>usedCapacity=0.4375, absoluteUsedCapacity=0.4375, numApps=5, numContainers=16 usedCapacity=0.4375 absoluteUsedCapacity=0.4375 used=<memory:21504, vCores:16> cluster=<memory:49152, vCores:96>
2013-08-10 18:11:54,027 INFO org.apache.hadoop.yarn.server.resourcemanager.scheduler.capacity.ParentQueue: Re-sorting queues since queue: root.default stats: default: capacity=1.0, absoluteCapacity=1.0, usedResources=<memory:22528, vCores:17>usedCapacity=0.45833334, absoluteUsedCapacity=0.45833334, numApps=5, numContainers=17
2013-08-10 18:11:54,027 INFO org.apache.hadoop.yarn.server.resourcemanager.scheduler.capacity.ParentQueue: assignedContainer queue=root usedCapacity=0.45833334 absoluteUsedCapacity=0.45833334 used=<memory:22528, vCores:17> cluster=<memory:49152, vCores:96>
2013-08-10 18:11:54,043 INFO org.apache.hadoop.yarn.server.resourcemanager.rmcontainer.RMContainerImpl: container_1376157310799_0010_01_000014 Container Transitioned from NEW to ALLOCATED
2013-08-10 18:11:54,044 INFO org.apache.hadoop.yarn.server.resourcemanager.RMAuditLogger: USER=ubuntu	OPERATION=AM Allocated Container	TARGET=SchedulerApp	RESULT=SUCCESS	APPID=application_1376157310799_0010	CONTAINERID=container_1376157310799_0010_01_000014
2013-08-10 18:11:54,044 INFO org.apache.hadoop.yarn.server.resourcemanager.scheduler.common.fica.FiCaSchedulerNode: Assigned container container_1376157310799_0010_01_000014 of capacity <memory:1024, vCores:1> on host hadoop-221-5:56475, which currently has 2 containers, <memory:3072, vCores:2> used and <memory:5120, vCores:14> available
2013-08-10 18:11:54,045 INFO org.apache.hadoop.yarn.server.resourcemanager.scheduler.capacity.LeafQueue: assignedContainer application=application_1376157310799_0010 container=Container: [ContainerId: container_1376157310799_0010_01_000014, NodeId: hadoop-221-5:56475, NodeHttpAddress: hadoop-221-5:8042, Resource: <memory:1024, vCores:1>, Priority: 20, State: NEW, Token: null, Status: container_id {, app_attempt_id {, application_id {, id: 10, cluster_timestamp: 1376157310799, }, attemptId: 1, }, id: 14, }, state: C_NEW, ] containerId=container_1376157310799_0010_01_000014 queue=default: capacity=1.0, absoluteCapacity=1.0, usedResources=<memory:22528, vCores:17>usedCapacity=0.45833334, absoluteUsedCapacity=0.45833334, numApps=5, numContainers=17 usedCapacity=0.45833334 absoluteUsedCapacity=0.45833334 used=<memory:22528, vCores:17> cluster=<memory:49152, vCores:96>
2013-08-10 18:11:54,045 INFO org.apache.hadoop.yarn.server.resourcemanager.scheduler.capacity.ParentQueue: Re-sorting queues since queue: root.default stats: default: capacity=1.0, absoluteCapacity=1.0, usedResources=<memory:23552, vCores:18>usedCapacity=0.47916666, absoluteUsedCapacity=0.47916666, numApps=5, numContainers=18
2013-08-10 18:11:54,045 INFO org.apache.hadoop.yarn.server.resourcemanager.scheduler.capacity.ParentQueue: assignedContainer queue=root usedCapacity=0.47916666 absoluteUsedCapacity=0.47916666 used=<memory:23552, vCores:18> cluster=<memory:49152, vCores:96>
2013-08-10 18:11:54,046 INFO org.apache.hadoop.yarn.server.resourcemanager.rmcontainer.RMContainerImpl: container_1376157310799_0010_01_000015 Container Transitioned from NEW to ALLOCATED
2013-08-10 18:11:54,046 INFO org.apache.hadoop.yarn.server.resourcemanager.RMAuditLogger: USER=ubuntu	OPERATION=AM Allocated Container	TARGET=SchedulerApp	RESULT=SUCCESS	APPID=application_1376157310799_0010	CONTAINERID=container_1376157310799_0010_01_000015
2013-08-10 18:11:54,046 INFO org.apache.hadoop.yarn.server.resourcemanager.scheduler.common.fica.FiCaSchedulerNode: Assigned container container_1376157310799_0010_01_000015 of capacity <memory:1024, vCores:1> on host hadoop-221-5:56475, which currently has 3 containers, <memory:4096, vCores:3> used and <memory:4096, vCores:13> available
2013-08-10 18:11:54,047 INFO org.apache.hadoop.yarn.server.resourcemanager.scheduler.capacity.LeafQueue: assignedContainer application=application_1376157310799_0010 container=Container: [ContainerId: container_1376157310799_0010_01_000015, NodeId: hadoop-221-5:56475, NodeHttpAddress: hadoop-221-5:8042, Resource: <memory:1024, vCores:1>, Priority: 20, State: NEW, Token: null, Status: container_id {, app_attempt_id {, application_id {, id: 10, cluster_timestamp: 1376157310799, }, attemptId: 1, }, id: 15, }, state: C_NEW, ] containerId=container_1376157310799_0010_01_000015 queue=default: capacity=1.0, absoluteCapacity=1.0, usedResources=<memory:23552, vCores:18>usedCapacity=0.47916666, absoluteUsedCapacity=0.47916666, numApps=5, numContainers=18 usedCapacity=0.47916666 absoluteUsedCapacity=0.47916666 used=<memory:23552, vCores:18> cluster=<memory:49152, vCores:96>
2013-08-10 18:11:54,047 INFO org.apache.hadoop.yarn.server.resourcemanager.scheduler.capacity.ParentQueue: Re-sorting queues since queue: root.default stats: default: capacity=1.0, absoluteCapacity=1.0, usedResources=<memory:24576, vCores:19>usedCapacity=0.5, absoluteUsedCapacity=0.5, numApps=5, numContainers=19
2013-08-10 18:11:54,048 INFO org.apache.hadoop.yarn.server.resourcemanager.scheduler.capacity.ParentQueue: assignedContainer queue=root usedCapacity=0.5 absoluteUsedCapacity=0.5 used=<memory:24576, vCores:19> cluster=<memory:49152, vCores:96>
2013-08-10 18:11:54,048 INFO org.apache.hadoop.yarn.server.resourcemanager.rmcontainer.RMContainerImpl: container_1376157310799_0010_01_000016 Container Transitioned from NEW to ALLOCATED
2013-08-10 18:11:54,048 INFO org.apache.hadoop.yarn.server.resourcemanager.RMAuditLogger: USER=ubuntu	OPERATION=AM Allocated Container	TARGET=SchedulerApp	RESULT=SUCCESS	APPID=application_1376157310799_0010	CONTAINERID=container_1376157310799_0010_01_000016
2013-08-10 18:11:54,048 INFO org.apache.hadoop.yarn.server.resourcemanager.scheduler.common.fica.FiCaSchedulerNode: Assigned container container_1376157310799_0010_01_000016 of capacity <memory:1024, vCores:1> on host hadoop-221-5:56475, which currently has 4 containers, <memory:5120, vCores:4> used and <memory:3072, vCores:12> available
2013-08-10 18:11:54,049 INFO org.apache.hadoop.yarn.server.resourcemanager.scheduler.capacity.LeafQueue: assignedContainer application=application_1376157310799_0010 container=Container: [ContainerId: container_1376157310799_0010_01_000016, NodeId: hadoop-221-5:56475, NodeHttpAddress: hadoop-221-5:8042, Resource: <memory:1024, vCores:1>, Priority: 20, State: NEW, Token: null, Status: container_id {, app_attempt_id {, application_id {, id: 10, cluster_timestamp: 1376157310799, }, attemptId: 1, }, id: 16, }, state: C_NEW, ] containerId=container_1376157310799_0010_01_000016 queue=default: capacity=1.0, absoluteCapacity=1.0, usedResources=<memory:24576, vCores:19>usedCapacity=0.5, absoluteUsedCapacity=0.5, numApps=5, numContainers=19 usedCapacity=0.5 absoluteUsedCapacity=0.5 used=<memory:24576, vCores:19> cluster=<memory:49152, vCores:96>
2013-08-10 18:11:54,050 INFO org.apache.hadoop.yarn.server.resourcemanager.scheduler.capacity.ParentQueue: Re-sorting queues since queue: root.default stats: default: capacity=1.0, absoluteCapacity=1.0, usedResources=<memory:25600, vCores:20>usedCapacity=0.5208333, absoluteUsedCapacity=0.5208333, numApps=5, numContainers=20
2013-08-10 18:11:54,050 INFO org.apache.hadoop.yarn.server.resourcemanager.scheduler.capacity.ParentQueue: assignedContainer queue=root usedCapacity=0.5208333 absoluteUsedCapacity=0.5208333 used=<memory:25600, vCores:20> cluster=<memory:49152, vCores:96>
2013-08-10 18:11:54,050 INFO org.apache.hadoop.yarn.server.resourcemanager.rmcontainer.RMContainerImpl: container_1376157310799_0010_01_000017 Container Transitioned from NEW to ALLOCATED
2013-08-10 18:11:54,051 INFO org.apache.hadoop.yarn.server.resourcemanager.RMAuditLogger: USER=ubuntu	OPERATION=AM Allocated Container	TARGET=SchedulerApp	RESULT=SUCCESS	APPID=application_1376157310799_0010	CONTAINERID=container_1376157310799_0010_01_000017
2013-08-10 18:11:54,051 INFO org.apache.hadoop.yarn.server.resourcemanager.scheduler.common.fica.FiCaSchedulerNode: Assigned container container_1376157310799_0010_01_000017 of capacity <memory:1024, vCores:1> on host hadoop-221-5:56475, which currently has 5 containers, <memory:6144, vCores:5> used and <memory:2048, vCores:11> available
2013-08-10 18:11:54,052 INFO org.apache.hadoop.yarn.server.resourcemanager.scheduler.capacity.LeafQueue: assignedContainer application=application_1376157310799_0010 container=Container: [ContainerId: container_1376157310799_0010_01_000017, NodeId: hadoop-221-5:56475, NodeHttpAddress: hadoop-221-5:8042, Resource: <memory:1024, vCores:1>, Priority: 20, State: NEW, Token: null, Status: container_id {, app_attempt_id {, application_id {, id: 10, cluster_timestamp: 1376157310799, }, attemptId: 1, }, id: 17, }, state: C_NEW, ] containerId=container_1376157310799_0010_01_000017 queue=default: capacity=1.0, absoluteCapacity=1.0, usedResources=<memory:25600, vCores:20>usedCapacity=0.5208333, absoluteUsedCapacity=0.5208333, numApps=5, numContainers=20 usedCapacity=0.5208333 absoluteUsedCapacity=0.5208333 used=<memory:25600, vCores:20> cluster=<memory:49152, vCores:96>
2013-08-10 18:11:54,052 INFO org.apache.hadoop.yarn.server.resourcemanager.scheduler.capacity.ParentQueue: Re-sorting queues since queue: root.default stats: default: capacity=1.0, absoluteCapacity=1.0, usedResources=<memory:26624, vCores:21>usedCapacity=0.5416667, absoluteUsedCapacity=0.5416667, numApps=5, numContainers=21
2013-08-10 18:11:54,052 INFO org.apache.hadoop.yarn.server.resourcemanager.scheduler.capacity.ParentQueue: assignedContainer queue=root usedCapacity=0.5416667 absoluteUsedCapacity=0.5416667 used=<memory:26624, vCores:21> cluster=<memory:49152, vCores:96>
2013-08-10 18:11:54,053 INFO org.apache.hadoop.yarn.server.resourcemanager.rmcontainer.RMContainerImpl: container_1376157310799_0010_01_000018 Container Transitioned from NEW to ALLOCATED
2013-08-10 18:11:54,053 INFO org.apache.hadoop.yarn.server.resourcemanager.RMAuditLogger: USER=ubuntu	OPERATION=AM Allocated Container	TARGET=SchedulerApp	RESULT=SUCCESS	APPID=application_1376157310799_0010	CONTAINERID=container_1376157310799_0010_01_000018
2013-08-10 18:11:54,053 INFO org.apache.hadoop.yarn.server.resourcemanager.scheduler.common.fica.FiCaSchedulerNode: Assigned container container_1376157310799_0010_01_000018 of capacity <memory:1024, vCores:1> on host hadoop-221-5:56475, which currently has 6 containers, <memory:7168, vCores:6> used and <memory:1024, vCores:10> available
2013-08-10 18:11:54,054 INFO org.apache.hadoop.yarn.server.resourcemanager.scheduler.capacity.LeafQueue: assignedContainer application=application_1376157310799_0010 container=Container: [ContainerId: container_1376157310799_0010_01_000018, NodeId: hadoop-221-5:56475, NodeHttpAddress: hadoop-221-5:8042, Resource: <memory:1024, vCores:1>, Priority: 20, State: NEW, Token: null, Status: container_id {, app_attempt_id {, application_id {, id: 10, cluster_timestamp: 1376157310799, }, attemptId: 1, }, id: 18, }, state: C_NEW, ] containerId=container_1376157310799_0010_01_000018 queue=default: capacity=1.0, absoluteCapacity=1.0, usedResources=<memory:26624, vCores:21>usedCapacity=0.5416667, absoluteUsedCapacity=0.5416667, numApps=5, numContainers=21 usedCapacity=0.5416667 absoluteUsedCapacity=0.5416667 used=<memory:26624, vCores:21> cluster=<memory:49152, vCores:96>
2013-08-10 18:11:54,054 INFO org.apache.hadoop.yarn.server.resourcemanager.scheduler.capacity.ParentQueue: Re-sorting queues since queue: root.default stats: default: capacity=1.0, absoluteCapacity=1.0, usedResources=<memory:27648, vCores:22>usedCapacity=0.5625, absoluteUsedCapacity=0.5625, numApps=5, numContainers=22
2013-08-10 18:11:54,054 INFO org.apache.hadoop.yarn.server.resourcemanager.scheduler.capacity.ParentQueue: assignedContainer queue=root usedCapacity=0.5625 absoluteUsedCapacity=0.5625 used=<memory:27648, vCores:22> cluster=<memory:49152, vCores:96>
2013-08-10 18:11:54,055 INFO org.apache.hadoop.yarn.server.resourcemanager.rmcontainer.RMContainerImpl: container_1376157310799_0010_01_000019 Container Transitioned from NEW to ALLOCATED
2013-08-10 18:11:54,055 INFO org.apache.hadoop.yarn.server.resourcemanager.RMAuditLogger: USER=ubuntu	OPERATION=AM Allocated Container	TARGET=SchedulerApp	RESULT=SUCCESS	APPID=application_1376157310799_0010	CONTAINERID=container_1376157310799_0010_01_000019
2013-08-10 18:11:54,055 INFO org.apache.hadoop.yarn.server.resourcemanager.scheduler.common.fica.FiCaSchedulerNode: Assigned container container_1376157310799_0010_01_000019 of capacity <memory:1024, vCores:1> on host hadoop-221-5:56475, which currently has 7 containers, <memory:8192, vCores:7> used and <memory:0, vCores:9> available
2013-08-10 18:11:54,056 INFO org.apache.hadoop.yarn.server.resourcemanager.scheduler.capacity.LeafQueue: assignedContainer application=application_1376157310799_0010 container=Container: [ContainerId: container_1376157310799_0010_01_000019, NodeId: hadoop-221-5:56475, NodeHttpAddress: hadoop-221-5:8042, Resource: <memory:1024, vCores:1>, Priority: 20, State: NEW, Token: null, Status: container_id {, app_attempt_id {, application_id {, id: 10, cluster_timestamp: 1376157310799, }, attemptId: 1, }, id: 19, }, state: C_NEW, ] containerId=container_1376157310799_0010_01_000019 queue=default: capacity=1.0, absoluteCapacity=1.0, usedResources=<memory:27648, vCores:22>usedCapacity=0.5625, absoluteUsedCapacity=0.5625, numApps=5, numContainers=22 usedCapacity=0.5625 absoluteUsedCapacity=0.5625 used=<memory:27648, vCores:22> cluster=<memory:49152, vCores:96>
2013-08-10 18:11:54,057 INFO org.apache.hadoop.yarn.server.resourcemanager.scheduler.capacity.ParentQueue: Re-sorting queues since queue: root.default stats: default: capacity=1.0, absoluteCapacity=1.0, usedResources=<memory:28672, vCores:23>usedCapacity=0.5833333, absoluteUsedCapacity=0.5833333, numApps=5, numContainers=23
2013-08-10 18:11:54,057 INFO org.apache.hadoop.yarn.server.resourcemanager.scheduler.capacity.ParentQueue: assignedContainer queue=root usedCapacity=0.5833333 absoluteUsedCapacity=0.5833333 used=<memory:28672, vCores:23> cluster=<memory:49152, vCores:96>
2013-08-10 18:11:54,160 INFO org.apache.hadoop.yarn.server.resourcemanager.rmcontainer.RMContainerImpl: container_1376157310799_0010_01_000020 Container Transitioned from NEW to ALLOCATED
2013-08-10 18:11:54,161 INFO org.apache.hadoop.yarn.server.resourcemanager.RMAuditLogger: USER=ubuntu	OPERATION=AM Allocated Container	TARGET=SchedulerApp	RESULT=SUCCESS	APPID=application_1376157310799_0010	CONTAINERID=container_1376157310799_0010_01_000020
2013-08-10 18:11:54,161 INFO org.apache.hadoop.yarn.server.resourcemanager.scheduler.common.fica.FiCaSchedulerNode: Assigned container container_1376157310799_0010_01_000020 of capacity <memory:1024, vCores:1> on host hadoop-221-3:38242, which currently has 2 containers, <memory:3072, vCores:2> used and <memory:5120, vCores:14> available
2013-08-10 18:11:54,162 INFO org.apache.hadoop.yarn.server.resourcemanager.scheduler.capacity.LeafQueue: assignedContainer application=application_1376157310799_0010 container=Container: [ContainerId: container_1376157310799_0010_01_000020, NodeId: hadoop-221-3:38242, NodeHttpAddress: hadoop-221-3:8042, Resource: <memory:1024, vCores:1>, Priority: 20, State: NEW, Token: null, Status: container_id {, app_attempt_id {, application_id {, id: 10, cluster_timestamp: 1376157310799, }, attemptId: 1, }, id: 20, }, state: C_NEW, ] containerId=container_1376157310799_0010_01_000020 queue=default: capacity=1.0, absoluteCapacity=1.0, usedResources=<memory:28672, vCores:23>usedCapacity=0.5833333, absoluteUsedCapacity=0.5833333, numApps=5, numContainers=23 usedCapacity=0.5833333 absoluteUsedCapacity=0.5833333 used=<memory:28672, vCores:23> cluster=<memory:49152, vCores:96>
2013-08-10 18:11:54,162 INFO org.apache.hadoop.yarn.server.resourcemanager.scheduler.capacity.ParentQueue: Re-sorting queues since queue: root.default stats: default: capacity=1.0, absoluteCapacity=1.0, usedResources=<memory:29696, vCores:24>usedCapacity=0.6041667, absoluteUsedCapacity=0.6041667, numApps=5, numContainers=24
2013-08-10 18:11:54,162 INFO org.apache.hadoop.yarn.server.resourcemanager.scheduler.capacity.ParentQueue: assignedContainer queue=root usedCapacity=0.6041667 absoluteUsedCapacity=0.6041667 used=<memory:29696, vCores:24> cluster=<memory:49152, vCores:96>
2013-08-10 18:11:54,163 INFO org.apache.hadoop.yarn.server.resourcemanager.rmcontainer.RMContainerImpl: container_1376157310799_0010_01_000021 Container Transitioned from NEW to ALLOCATED
2013-08-10 18:11:54,163 INFO org.apache.hadoop.yarn.server.resourcemanager.RMAuditLogger: USER=ubuntu	OPERATION=AM Allocated Container	TARGET=SchedulerApp	RESULT=SUCCESS	APPID=application_1376157310799_0010	CONTAINERID=container_1376157310799_0010_01_000021
2013-08-10 18:11:54,163 INFO org.apache.hadoop.yarn.server.resourcemanager.scheduler.common.fica.FiCaSchedulerNode: Assigned container container_1376157310799_0010_01_000021 of capacity <memory:1024, vCores:1> on host hadoop-221-3:38242, which currently has 3 containers, <memory:4096, vCores:3> used and <memory:4096, vCores:13> available
2013-08-10 18:11:54,164 INFO org.apache.hadoop.yarn.server.resourcemanager.scheduler.capacity.LeafQueue: assignedContainer application=application_1376157310799_0010 container=Container: [ContainerId: container_1376157310799_0010_01_000021, NodeId: hadoop-221-3:38242, NodeHttpAddress: hadoop-221-3:8042, Resource: <memory:1024, vCores:1>, Priority: 20, State: NEW, Token: null, Status: container_id {, app_attempt_id {, application_id {, id: 10, cluster_timestamp: 1376157310799, }, attemptId: 1, }, id: 21, }, state: C_NEW, ] containerId=container_1376157310799_0010_01_000021 queue=default: capacity=1.0, absoluteCapacity=1.0, usedResources=<memory:29696, vCores:24>usedCapacity=0.6041667, absoluteUsedCapacity=0.6041667, numApps=5, numContainers=24 usedCapacity=0.6041667 absoluteUsedCapacity=0.6041667 used=<memory:29696, vCores:24> cluster=<memory:49152, vCores:96>
2013-08-10 18:11:54,165 INFO org.apache.hadoop.yarn.server.resourcemanager.scheduler.capacity.ParentQueue: Re-sorting queues since queue: root.default stats: default: capacity=1.0, absoluteCapacity=1.0, usedResources=<memory:30720, vCores:25>usedCapacity=0.625, absoluteUsedCapacity=0.625, numApps=5, numContainers=25
2013-08-10 18:11:54,165 INFO org.apache.hadoop.yarn.server.resourcemanager.scheduler.capacity.ParentQueue: assignedContainer queue=root usedCapacity=0.625 absoluteUsedCapacity=0.625 used=<memory:30720, vCores:25> cluster=<memory:49152, vCores:96>
2013-08-10 18:11:54,165 INFO org.apache.hadoop.yarn.server.resourcemanager.rmcontainer.RMContainerImpl: container_1376157310799_0010_01_000022 Container Transitioned from NEW to ALLOCATED
2013-08-10 18:11:54,165 INFO org.apache.hadoop.yarn.server.resourcemanager.RMAuditLogger: USER=ubuntu	OPERATION=AM Allocated Container	TARGET=SchedulerApp	RESULT=SUCCESS	APPID=application_1376157310799_0010	CONTAINERID=container_1376157310799_0010_01_000022
2013-08-10 18:11:54,165 INFO org.apache.hadoop.yarn.server.resourcemanager.scheduler.common.fica.FiCaSchedulerNode: Assigned container container_1376157310799_0010_01_000022 of capacity <memory:1024, vCores:1> on host hadoop-221-3:38242, which currently has 4 containers, <memory:5120, vCores:4> used and <memory:3072, vCores:12> available
2013-08-10 18:11:54,166 INFO org.apache.hadoop.yarn.server.resourcemanager.scheduler.capacity.LeafQueue: assignedContainer application=application_1376157310799_0010 container=Container: [ContainerId: container_1376157310799_0010_01_000022, NodeId: hadoop-221-3:38242, NodeHttpAddress: hadoop-221-3:8042, Resource: <memory:1024, vCores:1>, Priority: 20, State: NEW, Token: null, Status: container_id {, app_attempt_id {, application_id {, id: 10, cluster_timestamp: 1376157310799, }, attemptId: 1, }, id: 22, }, state: C_NEW, ] containerId=container_1376157310799_0010_01_000022 queue=default: capacity=1.0, absoluteCapacity=1.0, usedResources=<memory:30720, vCores:25>usedCapacity=0.625, absoluteUsedCapacity=0.625, numApps=5, numContainers=25 usedCapacity=0.625 absoluteUsedCapacity=0.625 used=<memory:30720, vCores:25> cluster=<memory:49152, vCores:96>
2013-08-10 18:11:54,167 INFO org.apache.hadoop.yarn.server.resourcemanager.scheduler.capacity.ParentQueue: Re-sorting queues since queue: root.default stats: default: capacity=1.0, absoluteCapacity=1.0, usedResources=<memory:31744, vCores:26>usedCapacity=0.6458333, absoluteUsedCapacity=0.6458333, numApps=5, numContainers=26
2013-08-10 18:11:54,167 INFO org.apache.hadoop.yarn.server.resourcemanager.scheduler.capacity.ParentQueue: assignedContainer queue=root usedCapacity=0.6458333 absoluteUsedCapacity=0.6458333 used=<memory:31744, vCores:26> cluster=<memory:49152, vCores:96>
2013-08-10 18:11:54,167 INFO org.apache.hadoop.yarn.server.resourcemanager.rmcontainer.RMContainerImpl: container_1376157310799_0010_01_000023 Container Transitioned from NEW to ALLOCATED
2013-08-10 18:11:54,168 INFO org.apache.hadoop.yarn.server.resourcemanager.RMAuditLogger: USER=ubuntu	OPERATION=AM Allocated Container	TARGET=SchedulerApp	RESULT=SUCCESS	APPID=application_1376157310799_0010	CONTAINERID=container_1376157310799_0010_01_000023
2013-08-10 18:11:54,168 INFO org.apache.hadoop.yarn.server.resourcemanager.scheduler.common.fica.FiCaSchedulerNode: Assigned container container_1376157310799_0010_01_000023 of capacity <memory:1024, vCores:1> on host hadoop-221-3:38242, which currently has 5 containers, <memory:6144, vCores:5> used and <memory:2048, vCores:11> available
2013-08-10 18:11:54,169 INFO org.apache.hadoop.yarn.server.resourcemanager.scheduler.capacity.LeafQueue: assignedContainer application=application_1376157310799_0010 container=Container: [ContainerId: container_1376157310799_0010_01_000023, NodeId: hadoop-221-3:38242, NodeHttpAddress: hadoop-221-3:8042, Resource: <memory:1024, vCores:1>, Priority: 20, State: NEW, Token: null, Status: container_id {, app_attempt_id {, application_id {, id: 10, cluster_timestamp: 1376157310799, }, attemptId: 1, }, id: 23, }, state: C_NEW, ] containerId=container_1376157310799_0010_01_000023 queue=default: capacity=1.0, absoluteCapacity=1.0, usedResources=<memory:31744, vCores:26>usedCapacity=0.6458333, absoluteUsedCapacity=0.6458333, numApps=5, numContainers=26 usedCapacity=0.6458333 absoluteUsedCapacity=0.6458333 used=<memory:31744, vCores:26> cluster=<memory:49152, vCores:96>
2013-08-10 18:11:54,169 INFO org.apache.hadoop.yarn.server.resourcemanager.scheduler.capacity.ParentQueue: Re-sorting queues since queue: root.default stats: default: capacity=1.0, absoluteCapacity=1.0, usedResources=<memory:32768, vCores:27>usedCapacity=0.6666667, absoluteUsedCapacity=0.6666667, numApps=5, numContainers=27
2013-08-10 18:11:54,169 INFO org.apache.hadoop.yarn.server.resourcemanager.scheduler.capacity.ParentQueue: assignedContainer queue=root usedCapacity=0.6666667 absoluteUsedCapacity=0.6666667 used=<memory:32768, vCores:27> cluster=<memory:49152, vCores:96>
2013-08-10 18:11:54,170 INFO org.apache.hadoop.yarn.server.resourcemanager.rmcontainer.RMContainerImpl: container_1376157310799_0010_01_000024 Container Transitioned from NEW to ALLOCATED
2013-08-10 18:11:54,170 INFO org.apache.hadoop.yarn.server.resourcemanager.RMAuditLogger: USER=ubuntu	OPERATION=AM Allocated Container	TARGET=SchedulerApp	RESULT=SUCCESS	APPID=application_1376157310799_0010	CONTAINERID=container_1376157310799_0010_01_000024
2013-08-10 18:11:54,170 INFO org.apache.hadoop.yarn.server.resourcemanager.scheduler.common.fica.FiCaSchedulerNode: Assigned container container_1376157310799_0010_01_000024 of capacity <memory:1024, vCores:1> on host hadoop-221-3:38242, which currently has 6 containers, <memory:7168, vCores:6> used and <memory:1024, vCores:10> available
2013-08-10 18:11:54,171 INFO org.apache.hadoop.yarn.server.resourcemanager.scheduler.capacity.LeafQueue: assignedContainer application=application_1376157310799_0010 container=Container: [ContainerId: container_1376157310799_0010_01_000024, NodeId: hadoop-221-3:38242, NodeHttpAddress: hadoop-221-3:8042, Resource: <memory:1024, vCores:1>, Priority: 20, State: NEW, Token: null, Status: container_id {, app_attempt_id {, application_id {, id: 10, cluster_timestamp: 1376157310799, }, attemptId: 1, }, id: 24, }, state: C_NEW, ] containerId=container_1376157310799_0010_01_000024 queue=default: capacity=1.0, absoluteCapacity=1.0, usedResources=<memory:32768, vCores:27>usedCapacity=0.6666667, absoluteUsedCapacity=0.6666667, numApps=5, numContainers=27 usedCapacity=0.6666667 absoluteUsedCapacity=0.6666667 used=<memory:32768, vCores:27> cluster=<memory:49152, vCores:96>
2013-08-10 18:11:54,171 INFO org.apache.hadoop.yarn.server.resourcemanager.scheduler.capacity.ParentQueue: Re-sorting queues since queue: root.default stats: default: capacity=1.0, absoluteCapacity=1.0, usedResources=<memory:33792, vCores:28>usedCapacity=0.6875, absoluteUsedCapacity=0.6875, numApps=5, numContainers=28
2013-08-10 18:11:54,171 INFO org.apache.hadoop.yarn.server.resourcemanager.scheduler.capacity.ParentQueue: assignedContainer queue=root usedCapacity=0.6875 absoluteUsedCapacity=0.6875 used=<memory:33792, vCores:28> cluster=<memory:49152, vCores:96>
2013-08-10 18:11:54,172 INFO org.apache.hadoop.yarn.server.resourcemanager.rmcontainer.RMContainerImpl: container_1376157310799_0010_01_000025 Container Transitioned from NEW to ALLOCATED
2013-08-10 18:11:54,172 INFO org.apache.hadoop.yarn.server.resourcemanager.RMAuditLogger: USER=ubuntu	OPERATION=AM Allocated Container	TARGET=SchedulerApp	RESULT=SUCCESS	APPID=application_1376157310799_0010	CONTAINERID=container_1376157310799_0010_01_000025
2013-08-10 18:11:54,172 INFO org.apache.hadoop.yarn.server.resourcemanager.scheduler.common.fica.FiCaSchedulerNode: Assigned container container_1376157310799_0010_01_000025 of capacity <memory:1024, vCores:1> on host hadoop-221-3:38242, which currently has 7 containers, <memory:8192, vCores:7> used and <memory:0, vCores:9> available
2013-08-10 18:11:54,173 INFO org.apache.hadoop.yarn.server.resourcemanager.scheduler.capacity.LeafQueue: assignedContainer application=application_1376157310799_0010 container=Container: [ContainerId: container_1376157310799_0010_01_000025, NodeId: hadoop-221-3:38242, NodeHttpAddress: hadoop-221-3:8042, Resource: <memory:1024, vCores:1>, Priority: 20, State: NEW, Token: null, Status: container_id {, app_attempt_id {, application_id {, id: 10, cluster_timestamp: 1376157310799, }, attemptId: 1, }, id: 25, }, state: C_NEW, ] containerId=container_1376157310799_0010_01_000025 queue=default: capacity=1.0, absoluteCapacity=1.0, usedResources=<memory:33792, vCores:28>usedCapacity=0.6875, absoluteUsedCapacity=0.6875, numApps=5, numContainers=28 usedCapacity=0.6875 absoluteUsedCapacity=0.6875 used=<memory:33792, vCores:28> cluster=<memory:49152, vCores:96>
2013-08-10 18:11:54,174 INFO org.apache.hadoop.yarn.server.resourcemanager.scheduler.capacity.ParentQueue: Re-sorting queues since queue: root.default stats: default: capacity=1.0, absoluteCapacity=1.0, usedResources=<memory:34816, vCores:29>usedCapacity=0.7083333, absoluteUsedCapacity=0.7083333, numApps=5, numContainers=29
2013-08-10 18:11:54,174 INFO org.apache.hadoop.yarn.server.resourcemanager.scheduler.capacity.ParentQueue: assignedContainer queue=root usedCapacity=0.7083333 absoluteUsedCapacity=0.7083333 used=<memory:34816, vCores:29> cluster=<memory:49152, vCores:96>
2013-08-10 18:11:54,256 INFO org.apache.hadoop.yarn.server.resourcemanager.ApplicationMasterService: AM registration appattempt_1376157310799_0009_000001
2013-08-10 18:11:54,257 INFO org.apache.hadoop.yarn.server.resourcemanager.RMAuditLogger: USER=ubuntu	IP=192.168.100.26	OPERATION=Register App Master	TARGET=ApplicationMasterService	RESULT=SUCCESS	APPID=application_1376157310799_0009	APPATTEMPTID=appattempt_1376157310799_0009_000001
2013-08-10 18:11:54,258 INFO org.apache.hadoop.yarn.server.resourcemanager.rmapp.attempt.RMAppAttemptImpl: appattempt_1376157310799_0009_000001 State change from LAUNCHED to RUNNING
2013-08-10 18:11:54,258 INFO org.apache.hadoop.yarn.server.resourcemanager.rmapp.RMAppImpl: application_1376157310799_0009 State change from ACCEPTED to RUNNING
2013-08-10 18:11:54,317 INFO org.apache.hadoop.yarn.server.resourcemanager.ApplicationMasterService: AM registration appattempt_1376157310799_0007_000001
2013-08-10 18:11:54,317 INFO org.apache.hadoop.yarn.server.resourcemanager.RMAuditLogger: USER=ubuntu	IP=192.168.100.41	OPERATION=Register App Master	TARGET=ApplicationMasterService	RESULT=SUCCESS	APPID=application_1376157310799_0007	APPATTEMPTID=appattempt_1376157310799_0007_000001
2013-08-10 18:11:54,318 INFO org.apache.hadoop.yarn.server.resourcemanager.rmapp.attempt.RMAppAttemptImpl: appattempt_1376157310799_0007_000001 State change from LAUNCHED to RUNNING
2013-08-10 18:11:54,318 INFO org.apache.hadoop.yarn.server.resourcemanager.rmapp.RMAppImpl: application_1376157310799_0007 State change from ACCEPTED to RUNNING
2013-08-10 18:11:54,386 INFO org.apache.hadoop.yarn.server.resourcemanager.rmcontainer.RMContainerImpl: container_1376157310799_0010_01_000026 Container Transitioned from NEW to ALLOCATED
2013-08-10 18:11:54,386 INFO org.apache.hadoop.yarn.server.resourcemanager.RMAuditLogger: USER=ubuntu	OPERATION=AM Allocated Container	TARGET=SchedulerApp	RESULT=SUCCESS	APPID=application_1376157310799_0010	CONTAINERID=container_1376157310799_0010_01_000026
2013-08-10 18:11:54,386 INFO org.apache.hadoop.yarn.server.resourcemanager.scheduler.common.fica.FiCaSchedulerNode: Assigned container container_1376157310799_0010_01_000026 of capacity <memory:1024, vCores:1> on host hadoop-221-4:33277, which currently has 2 containers, <memory:3072, vCores:2> used and <memory:5120, vCores:14> available
2013-08-10 18:11:54,387 INFO org.apache.hadoop.yarn.server.resourcemanager.scheduler.capacity.LeafQueue: assignedContainer application=application_1376157310799_0010 container=Container: [ContainerId: container_1376157310799_0010_01_000026, NodeId: hadoop-221-4:33277, NodeHttpAddress: hadoop-221-4:8042, Resource: <memory:1024, vCores:1>, Priority: 20, State: NEW, Token: null, Status: container_id {, app_attempt_id {, application_id {, id: 10, cluster_timestamp: 1376157310799, }, attemptId: 1, }, id: 26, }, state: C_NEW, ] containerId=container_1376157310799_0010_01_000026 queue=default: capacity=1.0, absoluteCapacity=1.0, usedResources=<memory:34816, vCores:29>usedCapacity=0.7083333, absoluteUsedCapacity=0.7083333, numApps=5, numContainers=29 usedCapacity=0.7083333 absoluteUsedCapacity=0.7083333 used=<memory:34816, vCores:29> cluster=<memory:49152, vCores:96>
2013-08-10 18:11:54,387 INFO org.apache.hadoop.yarn.server.resourcemanager.scheduler.capacity.ParentQueue: Re-sorting queues since queue: root.default stats: default: capacity=1.0, absoluteCapacity=1.0, usedResources=<memory:35840, vCores:30>usedCapacity=0.7291667, absoluteUsedCapacity=0.7291667, numApps=5, numContainers=30
2013-08-10 18:11:54,388 INFO org.apache.hadoop.yarn.server.resourcemanager.scheduler.capacity.ParentQueue: assignedContainer queue=root usedCapacity=0.7291667 absoluteUsedCapacity=0.7291667 used=<memory:35840, vCores:30> cluster=<memory:49152, vCores:96>
2013-08-10 18:11:54,388 INFO org.apache.hadoop.yarn.server.resourcemanager.rmcontainer.RMContainerImpl: container_1376157310799_0010_01_000027 Container Transitioned from NEW to ALLOCATED
2013-08-10 18:11:54,389 INFO org.apache.hadoop.yarn.server.resourcemanager.RMAuditLogger: USER=ubuntu	OPERATION=AM Allocated Container	TARGET=SchedulerApp	RESULT=SUCCESS	APPID=application_1376157310799_0010	CONTAINERID=container_1376157310799_0010_01_000027
2013-08-10 18:11:54,389 INFO org.apache.hadoop.yarn.server.resourcemanager.scheduler.common.fica.FiCaSchedulerNode: Assigned container container_1376157310799_0010_01_000027 of capacity <memory:1024, vCores:1> on host hadoop-221-4:33277, which currently has 3 containers, <memory:4096, vCores:3> used and <memory:4096, vCores:13> available
2013-08-10 18:11:54,390 INFO org.apache.hadoop.yarn.server.resourcemanager.scheduler.capacity.LeafQueue: assignedContainer application=application_1376157310799_0010 container=Container: [ContainerId: container_1376157310799_0010_01_000027, NodeId: hadoop-221-4:33277, NodeHttpAddress: hadoop-221-4:8042, Resource: <memory:1024, vCores:1>, Priority: 20, State: NEW, Token: null, Status: container_id {, app_attempt_id {, application_id {, id: 10, cluster_timestamp: 1376157310799, }, attemptId: 1, }, id: 27, }, state: C_NEW, ] containerId=container_1376157310799_0010_01_000027 queue=default: capacity=1.0, absoluteCapacity=1.0, usedResources=<memory:35840, vCores:30>usedCapacity=0.7291667, absoluteUsedCapacity=0.7291667, numApps=5, numContainers=30 usedCapacity=0.7291667 absoluteUsedCapacity=0.7291667 used=<memory:35840, vCores:30> cluster=<memory:49152, vCores:96>
2013-08-10 18:11:54,390 INFO org.apache.hadoop.yarn.server.resourcemanager.scheduler.capacity.ParentQueue: Re-sorting queues since queue: root.default stats: default: capacity=1.0, absoluteCapacity=1.0, usedResources=<memory:36864, vCores:31>usedCapacity=0.75, absoluteUsedCapacity=0.75, numApps=5, numContainers=31
2013-08-10 18:11:54,390 INFO org.apache.hadoop.yarn.server.resourcemanager.scheduler.capacity.ParentQueue: assignedContainer queue=root usedCapacity=0.75 absoluteUsedCapacity=0.75 used=<memory:36864, vCores:31> cluster=<memory:49152, vCores:96>
2013-08-10 18:11:54,391 INFO org.apache.hadoop.yarn.server.resourcemanager.rmcontainer.RMContainerImpl: container_1376157310799_0010_01_000028 Container Transitioned from NEW to ALLOCATED
2013-08-10 18:11:54,391 INFO org.apache.hadoop.yarn.server.resourcemanager.RMAuditLogger: USER=ubuntu	OPERATION=AM Allocated Container	TARGET=SchedulerApp	RESULT=SUCCESS	APPID=application_1376157310799_0010	CONTAINERID=container_1376157310799_0010_01_000028
2013-08-10 18:11:54,391 INFO org.apache.hadoop.yarn.server.resourcemanager.scheduler.common.fica.FiCaSchedulerNode: Assigned container container_1376157310799_0010_01_000028 of capacity <memory:1024, vCores:1> on host hadoop-221-4:33277, which currently has 4 containers, <memory:5120, vCores:4> used and <memory:3072, vCores:12> available
2013-08-10 18:11:54,392 INFO org.apache.hadoop.yarn.server.resourcemanager.scheduler.capacity.LeafQueue: assignedContainer application=application_1376157310799_0010 container=Container: [ContainerId: container_1376157310799_0010_01_000028, NodeId: hadoop-221-4:33277, NodeHttpAddress: hadoop-221-4:8042, Resource: <memory:1024, vCores:1>, Priority: 20, State: NEW, Token: null, Status: container_id {, app_attempt_id {, application_id {, id: 10, cluster_timestamp: 1376157310799, }, attemptId: 1, }, id: 28, }, state: C_NEW, ] containerId=container_1376157310799_0010_01_000028 queue=default: capacity=1.0, absoluteCapacity=1.0, usedResources=<memory:36864, vCores:31>usedCapacity=0.75, absoluteUsedCapacity=0.75, numApps=5, numContainers=31 usedCapacity=0.75 absoluteUsedCapacity=0.75 used=<memory:36864, vCores:31> cluster=<memory:49152, vCores:96>
2013-08-10 18:11:54,392 INFO org.apache.hadoop.yarn.server.resourcemanager.scheduler.capacity.ParentQueue: Re-sorting queues since queue: root.default stats: default: capacity=1.0, absoluteCapacity=1.0, usedResources=<memory:37888, vCores:32>usedCapacity=0.7708333, absoluteUsedCapacity=0.7708333, numApps=5, numContainers=32
2013-08-10 18:11:54,392 INFO org.apache.hadoop.yarn.server.resourcemanager.scheduler.capacity.ParentQueue: assignedContainer queue=root usedCapacity=0.7708333 absoluteUsedCapacity=0.7708333 used=<memory:37888, vCores:32> cluster=<memory:49152, vCores:96>
2013-08-10 18:11:54,393 INFO org.apache.hadoop.yarn.server.resourcemanager.rmcontainer.RMContainerImpl: container_1376157310799_0010_01_000029 Container Transitioned from NEW to ALLOCATED
2013-08-10 18:11:54,393 INFO org.apache.hadoop.yarn.server.resourcemanager.RMAuditLogger: USER=ubuntu	OPERATION=AM Allocated Container	TARGET=SchedulerApp	RESULT=SUCCESS	APPID=application_1376157310799_0010	CONTAINERID=container_1376157310799_0010_01_000029
2013-08-10 18:11:54,393 INFO org.apache.hadoop.yarn.server.resourcemanager.scheduler.common.fica.FiCaSchedulerNode: Assigned container container_1376157310799_0010_01_000029 of capacity <memory:1024, vCores:1> on host hadoop-221-4:33277, which currently has 5 containers, <memory:6144, vCores:5> used and <memory:2048, vCores:11> available
2013-08-10 18:11:54,394 INFO org.apache.hadoop.yarn.server.resourcemanager.scheduler.capacity.LeafQueue: assignedContainer application=application_1376157310799_0010 container=Container: [ContainerId: container_1376157310799_0010_01_000029, NodeId: hadoop-221-4:33277, NodeHttpAddress: hadoop-221-4:8042, Resource: <memory:1024, vCores:1>, Priority: 20, State: NEW, Token: null, Status: container_id {, app_attempt_id {, application_id {, id: 10, cluster_timestamp: 1376157310799, }, attemptId: 1, }, id: 29, }, state: C_NEW, ] containerId=container_1376157310799_0010_01_000029 queue=default: capacity=1.0, absoluteCapacity=1.0, usedResources=<memory:37888, vCores:32>usedCapacity=0.7708333, absoluteUsedCapacity=0.7708333, numApps=5, numContainers=32 usedCapacity=0.7708333 absoluteUsedCapacity=0.7708333 used=<memory:37888, vCores:32> cluster=<memory:49152, vCores:96>
2013-08-10 18:11:54,394 INFO org.apache.hadoop.yarn.server.resourcemanager.scheduler.capacity.ParentQueue: Re-sorting queues since queue: root.default stats: default: capacity=1.0, absoluteCapacity=1.0, usedResources=<memory:38912, vCores:33>usedCapacity=0.7916667, absoluteUsedCapacity=0.7916667, numApps=5, numContainers=33
2013-08-10 18:11:54,394 INFO org.apache.hadoop.yarn.server.resourcemanager.scheduler.capacity.ParentQueue: assignedContainer queue=root usedCapacity=0.7916667 absoluteUsedCapacity=0.7916667 used=<memory:38912, vCores:33> cluster=<memory:49152, vCores:96>
2013-08-10 18:11:54,395 INFO org.apache.hadoop.yarn.server.resourcemanager.rmcontainer.RMContainerImpl: container_1376157310799_0010_01_000030 Container Transitioned from NEW to ALLOCATED
2013-08-10 18:11:54,395 INFO org.apache.hadoop.yarn.server.resourcemanager.RMAuditLogger: USER=ubuntu	OPERATION=AM Allocated Container	TARGET=SchedulerApp	RESULT=SUCCESS	APPID=application_1376157310799_0010	CONTAINERID=container_1376157310799_0010_01_000030
2013-08-10 18:11:54,395 INFO org.apache.hadoop.yarn.server.resourcemanager.scheduler.common.fica.FiCaSchedulerNode: Assigned container container_1376157310799_0010_01_000030 of capacity <memory:1024, vCores:1> on host hadoop-221-4:33277, which currently has 6 containers, <memory:7168, vCores:6> used and <memory:1024, vCores:10> available
2013-08-10 18:11:54,396 INFO org.apache.hadoop.yarn.server.resourcemanager.scheduler.capacity.LeafQueue: assignedContainer application=application_1376157310799_0010 container=Container: [ContainerId: container_1376157310799_0010_01_000030, NodeId: hadoop-221-4:33277, NodeHttpAddress: hadoop-221-4:8042, Resource: <memory:1024, vCores:1>, Priority: 20, State: NEW, Token: null, Status: container_id {, app_attempt_id {, application_id {, id: 10, cluster_timestamp: 1376157310799, }, attemptId: 1, }, id: 30, }, state: C_NEW, ] containerId=container_1376157310799_0010_01_000030 queue=default: capacity=1.0, absoluteCapacity=1.0, usedResources=<memory:38912, vCores:33>usedCapacity=0.7916667, absoluteUsedCapacity=0.7916667, numApps=5, numContainers=33 usedCapacity=0.7916667 absoluteUsedCapacity=0.7916667 used=<memory:38912, vCores:33> cluster=<memory:49152, vCores:96>
2013-08-10 18:11:54,397 INFO org.apache.hadoop.yarn.server.resourcemanager.scheduler.capacity.ParentQueue: Re-sorting queues since queue: root.default stats: default: capacity=1.0, absoluteCapacity=1.0, usedResources=<memory:39936, vCores:34>usedCapacity=0.8125, absoluteUsedCapacity=0.8125, numApps=5, numContainers=34
2013-08-10 18:11:54,397 INFO org.apache.hadoop.yarn.server.resourcemanager.scheduler.capacity.ParentQueue: assignedContainer queue=root usedCapacity=0.8125 absoluteUsedCapacity=0.8125 used=<memory:39936, vCores:34> cluster=<memory:49152, vCores:96>
2013-08-10 18:11:54,397 INFO org.apache.hadoop.yarn.server.resourcemanager.rmcontainer.RMContainerImpl: container_1376157310799_0010_01_000031 Container Transitioned from NEW to ALLOCATED
2013-08-10 18:11:54,397 INFO org.apache.hadoop.yarn.server.resourcemanager.RMAuditLogger: USER=ubuntu	OPERATION=AM Allocated Container	TARGET=SchedulerApp	RESULT=SUCCESS	APPID=application_1376157310799_0010	CONTAINERID=container_1376157310799_0010_01_000031
2013-08-10 18:11:54,398 INFO org.apache.hadoop.yarn.server.resourcemanager.scheduler.common.fica.FiCaSchedulerNode: Assigned container container_1376157310799_0010_01_000031 of capacity <memory:1024, vCores:1> on host hadoop-221-4:33277, which currently has 7 containers, <memory:8192, vCores:7> used and <memory:0, vCores:9> available
2013-08-10 18:11:54,399 INFO org.apache.hadoop.yarn.server.resourcemanager.scheduler.capacity.LeafQueue: assignedContainer application=application_1376157310799_0010 container=Container: [ContainerId: container_1376157310799_0010_01_000031, NodeId: hadoop-221-4:33277, NodeHttpAddress: hadoop-221-4:8042, Resource: <memory:1024, vCores:1>, Priority: 20, State: NEW, Token: null, Status: container_id {, app_attempt_id {, application_id {, id: 10, cluster_timestamp: 1376157310799, }, attemptId: 1, }, id: 31, }, state: C_NEW, ] containerId=container_1376157310799_0010_01_000031 queue=default: capacity=1.0, absoluteCapacity=1.0, usedResources=<memory:39936, vCores:34>usedCapacity=0.8125, absoluteUsedCapacity=0.8125, numApps=5, numContainers=34 usedCapacity=0.8125 absoluteUsedCapacity=0.8125 used=<memory:39936, vCores:34> cluster=<memory:49152, vCores:96>
2013-08-10 18:11:54,399 INFO org.apache.hadoop.yarn.server.resourcemanager.scheduler.capacity.ParentQueue: Re-sorting queues since queue: root.default stats: default: capacity=1.0, absoluteCapacity=1.0, usedResources=<memory:40960, vCores:35>usedCapacity=0.8333333, absoluteUsedCapacity=0.8333333, numApps=5, numContainers=35
2013-08-10 18:11:54,399 INFO org.apache.hadoop.yarn.server.resourcemanager.scheduler.capacity.ParentQueue: assignedContainer queue=root usedCapacity=0.8333333 absoluteUsedCapacity=0.8333333 used=<memory:40960, vCores:35> cluster=<memory:49152, vCores:96>
2013-08-10 18:11:54,408 INFO org.apache.hadoop.yarn.server.resourcemanager.rmcontainer.RMContainerImpl: container_1376157310799_0010_01_000032 Container Transitioned from NEW to ALLOCATED
2013-08-10 18:11:54,408 INFO org.apache.hadoop.yarn.server.resourcemanager.RMAuditLogger: USER=ubuntu	OPERATION=AM Allocated Container	TARGET=SchedulerApp	RESULT=SUCCESS	APPID=application_1376157310799_0010	CONTAINERID=container_1376157310799_0010_01_000032
2013-08-10 18:11:54,408 INFO org.apache.hadoop.yarn.server.resourcemanager.scheduler.common.fica.FiCaSchedulerNode: Assigned container container_1376157310799_0010_01_000032 of capacity <memory:1024, vCores:1> on host hadoop-221-6:39509, which currently has 1 containers, <memory:1024, vCores:1> used and <memory:7168, vCores:15> available
2013-08-10 18:11:54,409 INFO org.apache.hadoop.yarn.server.resourcemanager.scheduler.capacity.LeafQueue: assignedContainer application=application_1376157310799_0010 container=Container: [ContainerId: container_1376157310799_0010_01_000032, NodeId: hadoop-221-6:39509, NodeHttpAddress: hadoop-221-6:8042, Resource: <memory:1024, vCores:1>, Priority: 20, State: NEW, Token: null, Status: container_id {, app_attempt_id {, application_id {, id: 10, cluster_timestamp: 1376157310799, }, attemptId: 1, }, id: 32, }, state: C_NEW, ] containerId=container_1376157310799_0010_01_000032 queue=default: capacity=1.0, absoluteCapacity=1.0, usedResources=<memory:40960, vCores:35>usedCapacity=0.8333333, absoluteUsedCapacity=0.8333333, numApps=5, numContainers=35 usedCapacity=0.8333333 absoluteUsedCapacity=0.8333333 used=<memory:40960, vCores:35> cluster=<memory:49152, vCores:96>
2013-08-10 18:11:54,409 INFO org.apache.hadoop.yarn.server.resourcemanager.scheduler.capacity.ParentQueue: Re-sorting queues since queue: root.default stats: default: capacity=1.0, absoluteCapacity=1.0, usedResources=<memory:41984, vCores:36>usedCapacity=0.8541667, absoluteUsedCapacity=0.8541667, numApps=5, numContainers=36
2013-08-10 18:11:54,409 INFO org.apache.hadoop.yarn.server.resourcemanager.scheduler.capacity.ParentQueue: assignedContainer queue=root usedCapacity=0.8541667 absoluteUsedCapacity=0.8541667 used=<memory:41984, vCores:36> cluster=<memory:49152, vCores:96>
2013-08-10 18:11:54,410 INFO org.apache.hadoop.yarn.server.resourcemanager.rmcontainer.RMContainerImpl: container_1376157310799_0010_01_000033 Container Transitioned from NEW to ALLOCATED
2013-08-10 18:11:54,410 INFO org.apache.hadoop.yarn.server.resourcemanager.RMAuditLogger: USER=ubuntu	OPERATION=AM Allocated Container	TARGET=SchedulerApp	RESULT=SUCCESS	APPID=application_1376157310799_0010	CONTAINERID=container_1376157310799_0010_01_000033
2013-08-10 18:11:54,410 INFO org.apache.hadoop.yarn.server.resourcemanager.scheduler.common.fica.FiCaSchedulerNode: Assigned container container_1376157310799_0010_01_000033 of capacity <memory:1024, vCores:1> on host hadoop-221-6:39509, which currently has 2 containers, <memory:2048, vCores:2> used and <memory:6144, vCores:14> available
2013-08-10 18:11:54,411 INFO org.apache.hadoop.yarn.server.resourcemanager.scheduler.capacity.LeafQueue: assignedContainer application=application_1376157310799_0010 container=Container: [ContainerId: container_1376157310799_0010_01_000033, NodeId: hadoop-221-6:39509, NodeHttpAddress: hadoop-221-6:8042, Resource: <memory:1024, vCores:1>, Priority: 20, State: NEW, Token: null, Status: container_id {, app_attempt_id {, application_id {, id: 10, cluster_timestamp: 1376157310799, }, attemptId: 1, }, id: 33, }, state: C_NEW, ] containerId=container_1376157310799_0010_01_000033 queue=default: capacity=1.0, absoluteCapacity=1.0, usedResources=<memory:41984, vCores:36>usedCapacity=0.8541667, absoluteUsedCapacity=0.8541667, numApps=5, numContainers=36 usedCapacity=0.8541667 absoluteUsedCapacity=0.8541667 used=<memory:41984, vCores:36> cluster=<memory:49152, vCores:96>
2013-08-10 18:11:54,411 INFO org.apache.hadoop.yarn.server.resourcemanager.scheduler.capacity.ParentQueue: Re-sorting queues since queue: root.default stats: default: capacity=1.0, absoluteCapacity=1.0, usedResources=<memory:43008, vCores:37>usedCapacity=0.875, absoluteUsedCapacity=0.875, numApps=5, numContainers=37
2013-08-10 18:11:54,412 INFO org.apache.hadoop.yarn.server.resourcemanager.scheduler.capacity.ParentQueue: assignedContainer queue=root usedCapacity=0.875 absoluteUsedCapacity=0.875 used=<memory:43008, vCores:37> cluster=<memory:49152, vCores:96>
2013-08-10 18:11:54,412 INFO org.apache.hadoop.yarn.server.resourcemanager.rmcontainer.RMContainerImpl: container_1376157310799_0010_01_000034 Container Transitioned from NEW to ALLOCATED
2013-08-10 18:11:54,412 INFO org.apache.hadoop.yarn.server.resourcemanager.RMAuditLogger: USER=ubuntu	OPERATION=AM Allocated Container	TARGET=SchedulerApp	RESULT=SUCCESS	APPID=application_1376157310799_0010	CONTAINERID=container_1376157310799_0010_01_000034
2013-08-10 18:11:54,413 INFO org.apache.hadoop.yarn.server.resourcemanager.scheduler.common.fica.FiCaSchedulerNode: Assigned container container_1376157310799_0010_01_000034 of capacity <memory:1024, vCores:1> on host hadoop-221-6:39509, which currently has 3 containers, <memory:3072, vCores:3> used and <memory:5120, vCores:13> available
2013-08-10 18:11:54,413 INFO org.apache.hadoop.yarn.server.resourcemanager.scheduler.capacity.LeafQueue: assignedContainer application=application_1376157310799_0010 container=Container: [ContainerId: container_1376157310799_0010_01_000034, NodeId: hadoop-221-6:39509, NodeHttpAddress: hadoop-221-6:8042, Resource: <memory:1024, vCores:1>, Priority: 20, State: NEW, Token: null, Status: container_id {, app_attempt_id {, application_id {, id: 10, cluster_timestamp: 1376157310799, }, attemptId: 1, }, id: 34, }, state: C_NEW, ] containerId=container_1376157310799_0010_01_000034 queue=default: capacity=1.0, absoluteCapacity=1.0, usedResources=<memory:43008, vCores:37>usedCapacity=0.875, absoluteUsedCapacity=0.875, numApps=5, numContainers=37 usedCapacity=0.875 absoluteUsedCapacity=0.875 used=<memory:43008, vCores:37> cluster=<memory:49152, vCores:96>
2013-08-10 18:11:54,414 INFO org.apache.hadoop.yarn.server.resourcemanager.scheduler.capacity.ParentQueue: Re-sorting queues since queue: root.default stats: default: capacity=1.0, absoluteCapacity=1.0, usedResources=<memory:44032, vCores:38>usedCapacity=0.8958333, absoluteUsedCapacity=0.8958333, numApps=5, numContainers=38
2013-08-10 18:11:54,414 INFO org.apache.hadoop.yarn.server.resourcemanager.scheduler.capacity.ParentQueue: assignedContainer queue=root usedCapacity=0.8958333 absoluteUsedCapacity=0.8958333 used=<memory:44032, vCores:38> cluster=<memory:49152, vCores:96>
2013-08-10 18:11:54,415 INFO org.apache.hadoop.yarn.server.resourcemanager.rmcontainer.RMContainerImpl: container_1376157310799_0010_01_000035 Container Transitioned from NEW to ALLOCATED
2013-08-10 18:11:54,415 INFO org.apache.hadoop.yarn.server.resourcemanager.RMAuditLogger: USER=ubuntu	OPERATION=AM Allocated Container	TARGET=SchedulerApp	RESULT=SUCCESS	APPID=application_1376157310799_0010	CONTAINERID=container_1376157310799_0010_01_000035
2013-08-10 18:11:54,415 INFO org.apache.hadoop.yarn.server.resourcemanager.scheduler.common.fica.FiCaSchedulerNode: Assigned container container_1376157310799_0010_01_000035 of capacity <memory:1024, vCores:1> on host hadoop-221-6:39509, which currently has 4 containers, <memory:4096, vCores:4> used and <memory:4096, vCores:12> available
2013-08-10 18:11:54,416 INFO org.apache.hadoop.yarn.server.resourcemanager.scheduler.capacity.LeafQueue: assignedContainer application=application_1376157310799_0010 container=Container: [ContainerId: container_1376157310799_0010_01_000035, NodeId: hadoop-221-6:39509, NodeHttpAddress: hadoop-221-6:8042, Resource: <memory:1024, vCores:1>, Priority: 20, State: NEW, Token: null, Status: container_id {, app_attempt_id {, application_id {, id: 10, cluster_timestamp: 1376157310799, }, attemptId: 1, }, id: 35, }, state: C_NEW, ] containerId=container_1376157310799_0010_01_000035 queue=default: capacity=1.0, absoluteCapacity=1.0, usedResources=<memory:44032, vCores:38>usedCapacity=0.8958333, absoluteUsedCapacity=0.8958333, numApps=5, numContainers=38 usedCapacity=0.8958333 absoluteUsedCapacity=0.8958333 used=<memory:44032, vCores:38> cluster=<memory:49152, vCores:96>
2013-08-10 18:11:54,416 INFO org.apache.hadoop.yarn.server.resourcemanager.scheduler.capacity.ParentQueue: Re-sorting queues since queue: root.default stats: default: capacity=1.0, absoluteCapacity=1.0, usedResources=<memory:45056, vCores:39>usedCapacity=0.9166667, absoluteUsedCapacity=0.9166667, numApps=5, numContainers=39
2013-08-10 18:11:54,416 INFO org.apache.hadoop.yarn.server.resourcemanager.scheduler.capacity.ParentQueue: assignedContainer queue=root usedCapacity=0.9166667 absoluteUsedCapacity=0.9166667 used=<memory:45056, vCores:39> cluster=<memory:49152, vCores:96>
2013-08-10 18:11:54,417 INFO org.apache.hadoop.yarn.server.resourcemanager.rmcontainer.RMContainerImpl: container_1376157310799_0010_01_000036 Container Transitioned from NEW to ALLOCATED
2013-08-10 18:11:54,417 INFO org.apache.hadoop.yarn.server.resourcemanager.RMAuditLogger: USER=ubuntu	OPERATION=AM Allocated Container	TARGET=SchedulerApp	RESULT=SUCCESS	APPID=application_1376157310799_0010	CONTAINERID=container_1376157310799_0010_01_000036
2013-08-10 18:11:54,417 INFO org.apache.hadoop.yarn.server.resourcemanager.scheduler.common.fica.FiCaSchedulerNode: Assigned container container_1376157310799_0010_01_000036 of capacity <memory:1024, vCores:1> on host hadoop-221-6:39509, which currently has 5 containers, <memory:5120, vCores:5> used and <memory:3072, vCores:11> available
2013-08-10 18:11:54,418 INFO org.apache.hadoop.yarn.server.resourcemanager.scheduler.capacity.LeafQueue: assignedContainer application=application_1376157310799_0010 container=Container: [ContainerId: container_1376157310799_0010_01_000036, NodeId: hadoop-221-6:39509, NodeHttpAddress: hadoop-221-6:8042, Resource: <memory:1024, vCores:1>, Priority: 20, State: NEW, Token: null, Status: container_id {, app_attempt_id {, application_id {, id: 10, cluster_timestamp: 1376157310799, }, attemptId: 1, }, id: 36, }, state: C_NEW, ] containerId=container_1376157310799_0010_01_000036 queue=default: capacity=1.0, absoluteCapacity=1.0, usedResources=<memory:45056, vCores:39>usedCapacity=0.9166667, absoluteUsedCapacity=0.9166667, numApps=5, numContainers=39 usedCapacity=0.9166667 absoluteUsedCapacity=0.9166667 used=<memory:45056, vCores:39> cluster=<memory:49152, vCores:96>
2013-08-10 18:11:54,418 INFO org.apache.hadoop.yarn.server.resourcemanager.scheduler.capacity.ParentQueue: Re-sorting queues since queue: root.default stats: default: capacity=1.0, absoluteCapacity=1.0, usedResources=<memory:46080, vCores:40>usedCapacity=0.9375, absoluteUsedCapacity=0.9375, numApps=5, numContainers=40
2013-08-10 18:11:54,418 INFO org.apache.hadoop.yarn.server.resourcemanager.scheduler.capacity.ParentQueue: assignedContainer queue=root usedCapacity=0.9375 absoluteUsedCapacity=0.9375 used=<memory:46080, vCores:40> cluster=<memory:49152, vCores:96>
2013-08-10 18:11:54,419 INFO org.apache.hadoop.yarn.server.resourcemanager.rmcontainer.RMContainerImpl: container_1376157310799_0010_01_000037 Container Transitioned from NEW to ALLOCATED
2013-08-10 18:11:54,419 INFO org.apache.hadoop.yarn.server.resourcemanager.RMAuditLogger: USER=ubuntu	OPERATION=AM Allocated Container	TARGET=SchedulerApp	RESULT=SUCCESS	APPID=application_1376157310799_0010	CONTAINERID=container_1376157310799_0010_01_000037
2013-08-10 18:11:54,419 INFO org.apache.hadoop.yarn.server.resourcemanager.scheduler.common.fica.FiCaSchedulerNode: Assigned container container_1376157310799_0010_01_000037 of capacity <memory:1024, vCores:1> on host hadoop-221-6:39509, which currently has 6 containers, <memory:6144, vCores:6> used and <memory:2048, vCores:10> available
2013-08-10 18:11:54,420 INFO org.apache.hadoop.yarn.server.resourcemanager.scheduler.capacity.LeafQueue: assignedContainer application=application_1376157310799_0010 container=Container: [ContainerId: container_1376157310799_0010_01_000037, NodeId: hadoop-221-6:39509, NodeHttpAddress: hadoop-221-6:8042, Resource: <memory:1024, vCores:1>, Priority: 20, State: NEW, Token: null, Status: container_id {, app_attempt_id {, application_id {, id: 10, cluster_timestamp: 1376157310799, }, attemptId: 1, }, id: 37, }, state: C_NEW, ] containerId=container_1376157310799_0010_01_000037 queue=default: capacity=1.0, absoluteCapacity=1.0, usedResources=<memory:46080, vCores:40>usedCapacity=0.9375, absoluteUsedCapacity=0.9375, numApps=5, numContainers=40 usedCapacity=0.9375 absoluteUsedCapacity=0.9375 used=<memory:46080, vCores:40> cluster=<memory:49152, vCores:96>
2013-08-10 18:11:54,420 INFO org.apache.hadoop.yarn.server.resourcemanager.scheduler.capacity.ParentQueue: Re-sorting queues since queue: root.default stats: default: capacity=1.0, absoluteCapacity=1.0, usedResources=<memory:47104, vCores:41>usedCapacity=0.9583333, absoluteUsedCapacity=0.9583333, numApps=5, numContainers=41
2013-08-10 18:11:54,421 INFO org.apache.hadoop.yarn.server.resourcemanager.scheduler.capacity.ParentQueue: assignedContainer queue=root usedCapacity=0.9583333 absoluteUsedCapacity=0.9583333 used=<memory:47104, vCores:41> cluster=<memory:49152, vCores:96>
2013-08-10 18:11:54,421 INFO org.apache.hadoop.yarn.server.resourcemanager.rmcontainer.RMContainerImpl: container_1376157310799_0010_01_000038 Container Transitioned from NEW to ALLOCATED
2013-08-10 18:11:54,421 INFO org.apache.hadoop.yarn.server.resourcemanager.RMAuditLogger: USER=ubuntu	OPERATION=AM Allocated Container	TARGET=SchedulerApp	RESULT=SUCCESS	APPID=application_1376157310799_0010	CONTAINERID=container_1376157310799_0010_01_000038
2013-08-10 18:11:54,421 INFO org.apache.hadoop.yarn.server.resourcemanager.scheduler.common.fica.FiCaSchedulerNode: Assigned container container_1376157310799_0010_01_000038 of capacity <memory:1024, vCores:1> on host hadoop-221-6:39509, which currently has 7 containers, <memory:7168, vCores:7> used and <memory:1024, vCores:9> available
2013-08-10 18:11:54,422 INFO org.apache.hadoop.yarn.server.resourcemanager.scheduler.capacity.LeafQueue: assignedContainer application=application_1376157310799_0010 container=Container: [ContainerId: container_1376157310799_0010_01_000038, NodeId: hadoop-221-6:39509, NodeHttpAddress: hadoop-221-6:8042, Resource: <memory:1024, vCores:1>, Priority: 20, State: NEW, Token: null, Status: container_id {, app_attempt_id {, application_id {, id: 10, cluster_timestamp: 1376157310799, }, attemptId: 1, }, id: 38, }, state: C_NEW, ] containerId=container_1376157310799_0010_01_000038 queue=default: capacity=1.0, absoluteCapacity=1.0, usedResources=<memory:47104, vCores:41>usedCapacity=0.9583333, absoluteUsedCapacity=0.9583333, numApps=5, numContainers=41 usedCapacity=0.9583333 absoluteUsedCapacity=0.9583333 used=<memory:47104, vCores:41> cluster=<memory:49152, vCores:96>
2013-08-10 18:11:54,423 INFO org.apache.hadoop.yarn.server.resourcemanager.scheduler.capacity.ParentQueue: Re-sorting queues since queue: root.default stats: default: capacity=1.0, absoluteCapacity=1.0, usedResources=<memory:48128, vCores:42>usedCapacity=0.9791667, absoluteUsedCapacity=0.9791667, numApps=5, numContainers=42
2013-08-10 18:11:54,423 INFO org.apache.hadoop.yarn.server.resourcemanager.scheduler.capacity.ParentQueue: assignedContainer queue=root usedCapacity=0.9791667 absoluteUsedCapacity=0.9791667 used=<memory:48128, vCores:42> cluster=<memory:49152, vCores:96>
2013-08-10 18:11:54,423 INFO org.apache.hadoop.yarn.server.resourcemanager.rmcontainer.RMContainerImpl: container_1376157310799_0010_01_000039 Container Transitioned from NEW to ALLOCATED
2013-08-10 18:11:54,423 INFO org.apache.hadoop.yarn.server.resourcemanager.RMAuditLogger: USER=ubuntu	OPERATION=AM Allocated Container	TARGET=SchedulerApp	RESULT=SUCCESS	APPID=application_1376157310799_0010	CONTAINERID=container_1376157310799_0010_01_000039
2013-08-10 18:11:54,424 INFO org.apache.hadoop.yarn.server.resourcemanager.scheduler.common.fica.FiCaSchedulerNode: Assigned container container_1376157310799_0010_01_000039 of capacity <memory:1024, vCores:1> on host hadoop-221-6:39509, which currently has 8 containers, <memory:8192, vCores:8> used and <memory:0, vCores:8> available
2013-08-10 18:11:54,425 INFO org.apache.hadoop.yarn.server.resourcemanager.scheduler.capacity.LeafQueue: assignedContainer application=application_1376157310799_0010 container=Container: [ContainerId: container_1376157310799_0010_01_000039, NodeId: hadoop-221-6:39509, NodeHttpAddress: hadoop-221-6:8042, Resource: <memory:1024, vCores:1>, Priority: 20, State: NEW, Token: null, Status: container_id {, app_attempt_id {, application_id {, id: 10, cluster_timestamp: 1376157310799, }, attemptId: 1, }, id: 39, }, state: C_NEW, ] containerId=container_1376157310799_0010_01_000039 queue=default: capacity=1.0, absoluteCapacity=1.0, usedResources=<memory:48128, vCores:42>usedCapacity=0.9791667, absoluteUsedCapacity=0.9791667, numApps=5, numContainers=42 usedCapacity=0.9791667 absoluteUsedCapacity=0.9791667 used=<memory:48128, vCores:42> cluster=<memory:49152, vCores:96>
2013-08-10 18:11:54,425 INFO org.apache.hadoop.yarn.server.resourcemanager.scheduler.capacity.ParentQueue: Re-sorting queues since queue: root.default stats: default: capacity=1.0, absoluteCapacity=1.0, usedResources=<memory:49152, vCores:43>usedCapacity=1.0, absoluteUsedCapacity=1.0, numApps=5, numContainers=43
2013-08-10 18:11:54,425 INFO org.apache.hadoop.yarn.server.resourcemanager.scheduler.capacity.ParentQueue: assignedContainer queue=root usedCapacity=1.0 absoluteUsedCapacity=1.0 used=<memory:49152, vCores:43> cluster=<memory:49152, vCores:96>
2013-08-10 18:11:54,545 INFO org.apache.hadoop.yarn.server.resourcemanager.rmcontainer.RMContainerImpl: container_1376157310799_0010_01_000002 Container Transitioned from ALLOCATED to ACQUIRED
2013-08-10 18:11:54,547 INFO org.apache.hadoop.yarn.server.resourcemanager.rmcontainer.RMContainerImpl: container_1376157310799_0010_01_000003 Container Transitioned from ALLOCATED to ACQUIRED
2013-08-10 18:11:54,548 INFO org.apache.hadoop.yarn.server.resourcemanager.rmcontainer.RMContainerImpl: container_1376157310799_0010_01_000004 Container Transitioned from ALLOCATED to ACQUIRED
2013-08-10 18:11:54,550 INFO org.apache.hadoop.yarn.server.resourcemanager.rmcontainer.RMContainerImpl: container_1376157310799_0010_01_000005 Container Transitioned from ALLOCATED to ACQUIRED
2013-08-10 18:11:54,551 INFO org.apache.hadoop.yarn.server.resourcemanager.rmcontainer.RMContainerImpl: container_1376157310799_0010_01_000006 Container Transitioned from ALLOCATED to ACQUIRED
2013-08-10 18:11:54,552 INFO org.apache.hadoop.yarn.server.resourcemanager.rmcontainer.RMContainerImpl: container_1376157310799_0010_01_000007 Container Transitioned from ALLOCATED to ACQUIRED
2013-08-10 18:11:54,553 INFO org.apache.hadoop.yarn.server.resourcemanager.rmcontainer.RMContainerImpl: container_1376157310799_0010_01_000008 Container Transitioned from ALLOCATED to ACQUIRED
2013-08-10 18:11:54,555 INFO org.apache.hadoop.yarn.server.resourcemanager.rmcontainer.RMContainerImpl: container_1376157310799_0010_01_000009 Container Transitioned from ALLOCATED to ACQUIRED
2013-08-10 18:11:54,555 INFO org.apache.hadoop.yarn.server.resourcemanager.rmcontainer.RMContainerImpl: container_1376157310799_0010_01_000010 Container Transitioned from ALLOCATED to ACQUIRED
2013-08-10 18:11:54,557 INFO org.apache.hadoop.yarn.server.resourcemanager.rmcontainer.RMContainerImpl: container_1376157310799_0010_01_000011 Container Transitioned from ALLOCATED to ACQUIRED
2013-08-10 18:11:54,557 INFO org.apache.hadoop.yarn.server.resourcemanager.rmcontainer.RMContainerImpl: container_1376157310799_0010_01_000012 Container Transitioned from ALLOCATED to ACQUIRED
2013-08-10 18:11:54,557 INFO org.apache.hadoop.yarn.server.resourcemanager.rmcontainer.RMContainerImpl: container_1376157310799_0010_01_000013 Container Transitioned from ALLOCATED to ACQUIRED
2013-08-10 18:11:54,557 INFO org.apache.hadoop.yarn.server.resourcemanager.rmcontainer.RMContainerImpl: container_1376157310799_0010_01_000014 Container Transitioned from ALLOCATED to ACQUIRED
2013-08-10 18:11:54,557 INFO org.apache.hadoop.yarn.server.resourcemanager.rmcontainer.RMContainerImpl: container_1376157310799_0010_01_000015 Container Transitioned from ALLOCATED to ACQUIRED
2013-08-10 18:11:54,558 INFO org.apache.hadoop.yarn.server.resourcemanager.rmcontainer.RMContainerImpl: container_1376157310799_0010_01_000016 Container Transitioned from ALLOCATED to ACQUIRED
2013-08-10 18:11:54,558 INFO org.apache.hadoop.yarn.server.resourcemanager.rmcontainer.RMContainerImpl: container_1376157310799_0010_01_000017 Container Transitioned from ALLOCATED to ACQUIRED
2013-08-10 18:11:54,558 INFO org.apache.hadoop.yarn.server.resourcemanager.rmcontainer.RMContainerImpl: container_1376157310799_0010_01_000018 Container Transitioned from ALLOCATED to ACQUIRED
2013-08-10 18:11:54,558 INFO org.apache.hadoop.yarn.server.resourcemanager.rmcontainer.RMContainerImpl: container_1376157310799_0010_01_000019 Container Transitioned from ALLOCATED to ACQUIRED
2013-08-10 18:11:54,559 INFO org.apache.hadoop.yarn.server.resourcemanager.rmcontainer.RMContainerImpl: container_1376157310799_0010_01_000020 Container Transitioned from ALLOCATED to ACQUIRED
2013-08-10 18:11:54,559 INFO org.apache.hadoop.yarn.server.resourcemanager.rmcontainer.RMContainerImpl: container_1376157310799_0010_01_000021 Container Transitioned from ALLOCATED to ACQUIRED
2013-08-10 18:11:54,559 INFO org.apache.hadoop.yarn.server.resourcemanager.rmcontainer.RMContainerImpl: container_1376157310799_0010_01_000022 Container Transitioned from ALLOCATED to ACQUIRED
2013-08-10 18:11:54,559 INFO org.apache.hadoop.yarn.server.resourcemanager.rmcontainer.RMContainerImpl: container_1376157310799_0010_01_000023 Container Transitioned from ALLOCATED to ACQUIRED
2013-08-10 18:11:54,559 INFO org.apache.hadoop.yarn.server.resourcemanager.rmcontainer.RMContainerImpl: container_1376157310799_0010_01_000024 Container Transitioned from ALLOCATED to ACQUIRED
2013-08-10 18:11:54,560 INFO org.apache.hadoop.yarn.server.resourcemanager.rmcontainer.RMContainerImpl: container_1376157310799_0010_01_000025 Container Transitioned from ALLOCATED to ACQUIRED
2013-08-10 18:11:54,560 INFO org.apache.hadoop.yarn.server.resourcemanager.rmcontainer.RMContainerImpl: container_1376157310799_0010_01_000026 Container Transitioned from ALLOCATED to ACQUIRED
2013-08-10 18:11:54,560 INFO org.apache.hadoop.yarn.server.resourcemanager.rmcontainer.RMContainerImpl: container_1376157310799_0010_01_000027 Container Transitioned from ALLOCATED to ACQUIRED
2013-08-10 18:11:54,560 INFO org.apache.hadoop.yarn.server.resourcemanager.rmcontainer.RMContainerImpl: container_1376157310799_0010_01_000028 Container Transitioned from ALLOCATED to ACQUIRED
2013-08-10 18:11:54,560 INFO org.apache.hadoop.yarn.server.resourcemanager.rmcontainer.RMContainerImpl: container_1376157310799_0010_01_000029 Container Transitioned from ALLOCATED to ACQUIRED
2013-08-10 18:11:54,561 INFO org.apache.hadoop.yarn.server.resourcemanager.rmcontainer.RMContainerImpl: container_1376157310799_0010_01_000030 Container Transitioned from ALLOCATED to ACQUIRED
2013-08-10 18:11:54,561 INFO org.apache.hadoop.yarn.server.resourcemanager.rmcontainer.RMContainerImpl: container_1376157310799_0010_01_000031 Container Transitioned from ALLOCATED to ACQUIRED
2013-08-10 18:11:54,561 INFO org.apache.hadoop.yarn.server.resourcemanager.rmcontainer.RMContainerImpl: container_1376157310799_0010_01_000032 Container Transitioned from ALLOCATED to ACQUIRED
2013-08-10 18:11:54,561 INFO org.apache.hadoop.yarn.server.resourcemanager.rmcontainer.RMContainerImpl: container_1376157310799_0010_01_000033 Container Transitioned from ALLOCATED to ACQUIRED
2013-08-10 18:11:54,561 INFO org.apache.hadoop.yarn.server.resourcemanager.rmcontainer.RMContainerImpl: container_1376157310799_0010_01_000034 Container Transitioned from ALLOCATED to ACQUIRED
2013-08-10 18:11:54,562 INFO org.apache.hadoop.yarn.server.resourcemanager.rmcontainer.RMContainerImpl: container_1376157310799_0010_01_000035 Container Transitioned from ALLOCATED to ACQUIRED
2013-08-10 18:11:54,562 INFO org.apache.hadoop.yarn.server.resourcemanager.rmcontainer.RMContainerImpl: container_1376157310799_0010_01_000036 Container Transitioned from ALLOCATED to ACQUIRED
2013-08-10 18:11:54,562 INFO org.apache.hadoop.yarn.server.resourcemanager.rmcontainer.RMContainerImpl: container_1376157310799_0010_01_000037 Container Transitioned from ALLOCATED to ACQUIRED
2013-08-10 18:11:54,562 INFO org.apache.hadoop.yarn.server.resourcemanager.rmcontainer.RMContainerImpl: container_1376157310799_0010_01_000038 Container Transitioned from ALLOCATED to ACQUIRED
2013-08-10 18:11:54,562 INFO org.apache.hadoop.yarn.server.resourcemanager.rmcontainer.RMContainerImpl: container_1376157310799_0010_01_000039 Container Transitioned from ALLOCATED to ACQUIRED
2013-08-10 18:11:54,709 INFO org.apache.hadoop.yarn.server.resourcemanager.ApplicationMasterService: AM registration appattempt_1376157310799_0008_000001
2013-08-10 18:11:54,709 INFO org.apache.hadoop.yarn.server.resourcemanager.RMAuditLogger: USER=ubuntu	IP=192.168.100.40	OPERATION=Register App Master	TARGET=ApplicationMasterService	RESULT=SUCCESS	APPID=application_1376157310799_0008	APPATTEMPTID=appattempt_1376157310799_0008_000001
2013-08-10 18:11:54,710 INFO org.apache.hadoop.yarn.server.resourcemanager.rmapp.attempt.RMAppAttemptImpl: appattempt_1376157310799_0008_000001 State change from LAUNCHED to RUNNING
2013-08-10 18:11:54,711 INFO org.apache.hadoop.yarn.server.resourcemanager.rmapp.RMAppImpl: application_1376157310799_0008 State change from ACCEPTED to RUNNING
2013-08-10 18:11:55,036 INFO org.apache.hadoop.yarn.server.resourcemanager.rmcontainer.RMContainerImpl: container_1376157310799_0010_01_000008 Container Transitioned from ACQUIRED to RUNNING
2013-08-10 18:11:55,036 INFO org.apache.hadoop.yarn.server.resourcemanager.rmcontainer.RMContainerImpl: container_1376157310799_0010_01_000009 Container Transitioned from ACQUIRED to RUNNING
2013-08-10 18:11:55,037 INFO org.apache.hadoop.yarn.server.resourcemanager.rmcontainer.RMContainerImpl: container_1376157310799_0010_01_000010 Container Transitioned from ACQUIRED to RUNNING
2013-08-10 18:11:55,037 INFO org.apache.hadoop.yarn.server.resourcemanager.rmcontainer.RMContainerImpl: container_1376157310799_0010_01_000011 Container Transitioned from ACQUIRED to RUNNING
2013-08-10 18:11:55,038 INFO org.apache.hadoop.yarn.server.resourcemanager.rmcontainer.RMContainerImpl: container_1376157310799_0010_01_000012 Container Transitioned from ACQUIRED to RUNNING
2013-08-10 18:11:55,038 INFO org.apache.hadoop.yarn.server.resourcemanager.rmcontainer.RMContainerImpl: container_1376157310799_0010_01_000013 Container Transitioned from ACQUIRED to RUNNING
2013-08-10 18:11:55,039 INFO org.apache.hadoop.yarn.server.resourcemanager.ApplicationMasterService: AM registration appattempt_1376157310799_0006_000001
2013-08-10 18:11:55,039 INFO org.apache.hadoop.yarn.server.resourcemanager.RMAuditLogger: USER=ubuntu	IP=192.168.100.25	OPERATION=Register App Master	TARGET=ApplicationMasterService	RESULT=SUCCESS	APPID=application_1376157310799_0006	APPATTEMPTID=appattempt_1376157310799_0006_000001
2013-08-10 18:11:55,040 INFO org.apache.hadoop.yarn.server.resourcemanager.rmapp.attempt.RMAppAttemptImpl: appattempt_1376157310799_0006_000001 State change from LAUNCHED to RUNNING
2013-08-10 18:11:55,040 INFO org.apache.hadoop.yarn.server.resourcemanager.rmapp.RMAppImpl: application_1376157310799_0006 State change from ACCEPTED to RUNNING
2013-08-10 18:11:55,080 INFO org.apache.hadoop.yarn.server.resourcemanager.rmcontainer.RMContainerImpl: container_1376157310799_0010_01_000014 Container Transitioned from ACQUIRED to RUNNING
2013-08-10 18:11:55,080 INFO org.apache.hadoop.yarn.server.resourcemanager.rmcontainer.RMContainerImpl: container_1376157310799_0010_01_000015 Container Transitioned from ACQUIRED to RUNNING
2013-08-10 18:11:55,081 INFO org.apache.hadoop.yarn.server.resourcemanager.rmcontainer.RMContainerImpl: container_1376157310799_0010_01_000016 Container Transitioned from ACQUIRED to RUNNING
2013-08-10 18:11:55,081 INFO org.apache.hadoop.yarn.server.resourcemanager.rmcontainer.RMContainerImpl: container_1376157310799_0010_01_000017 Container Transitioned from ACQUIRED to RUNNING
2013-08-10 18:11:55,082 INFO org.apache.hadoop.yarn.server.resourcemanager.rmcontainer.RMContainerImpl: container_1376157310799_0010_01_000018 Container Transitioned from ACQUIRED to RUNNING
2013-08-10 18:11:55,082 INFO org.apache.hadoop.yarn.server.resourcemanager.rmcontainer.RMContainerImpl: container_1376157310799_0010_01_000019 Container Transitioned from ACQUIRED to RUNNING
2013-08-10 18:11:55,202 INFO org.apache.hadoop.yarn.server.resourcemanager.rmcontainer.RMContainerImpl: container_1376157310799_0010_01_000020 Container Transitioned from ACQUIRED to RUNNING
2013-08-10 18:11:55,203 INFO org.apache.hadoop.yarn.server.resourcemanager.rmcontainer.RMContainerImpl: container_1376157310799_0010_01_000021 Container Transitioned from ACQUIRED to RUNNING
2013-08-10 18:11:55,203 INFO org.apache.hadoop.yarn.server.resourcemanager.rmcontainer.RMContainerImpl: container_1376157310799_0010_01_000022 Container Transitioned from ACQUIRED to RUNNING
2013-08-10 18:11:55,204 INFO org.apache.hadoop.yarn.server.resourcemanager.rmcontainer.RMContainerImpl: container_1376157310799_0010_01_000023 Container Transitioned from ACQUIRED to RUNNING
2013-08-10 18:11:55,205 INFO org.apache.hadoop.yarn.server.resourcemanager.rmcontainer.RMContainerImpl: container_1376157310799_0010_01_000024 Container Transitioned from ACQUIRED to RUNNING
2013-08-10 18:11:55,205 INFO org.apache.hadoop.yarn.server.resourcemanager.rmcontainer.RMContainerImpl: container_1376157310799_0010_01_000025 Container Transitioned from ACQUIRED to RUNNING
2013-08-10 18:11:55,418 INFO org.apache.hadoop.yarn.server.resourcemanager.rmcontainer.RMContainerImpl: container_1376157310799_0010_01_000032 Container Transitioned from ACQUIRED to RUNNING
2013-08-10 18:11:55,418 INFO org.apache.hadoop.yarn.server.resourcemanager.rmcontainer.RMContainerImpl: container_1376157310799_0010_01_000033 Container Transitioned from ACQUIRED to RUNNING
2013-08-10 18:11:55,418 INFO org.apache.hadoop.yarn.server.resourcemanager.rmcontainer.RMContainerImpl: container_1376157310799_0010_01_000034 Container Transitioned from ACQUIRED to RUNNING
2013-08-10 18:11:55,419 INFO org.apache.hadoop.yarn.server.resourcemanager.rmcontainer.RMContainerImpl: container_1376157310799_0010_01_000035 Container Transitioned from ACQUIRED to RUNNING
2013-08-10 18:11:55,420 INFO org.apache.hadoop.yarn.server.resourcemanager.rmcontainer.RMContainerImpl: container_1376157310799_0010_01_000036 Container Transitioned from ACQUIRED to RUNNING
2013-08-10 18:11:55,420 INFO org.apache.hadoop.yarn.server.resourcemanager.rmcontainer.RMContainerImpl: container_1376157310799_0010_01_000037 Container Transitioned from ACQUIRED to RUNNING
2013-08-10 18:11:55,421 INFO org.apache.hadoop.yarn.server.resourcemanager.rmcontainer.RMContainerImpl: container_1376157310799_0010_01_000038 Container Transitioned from ACQUIRED to RUNNING
2013-08-10 18:11:55,421 INFO org.apache.hadoop.yarn.server.resourcemanager.rmcontainer.RMContainerImpl: container_1376157310799_0010_01_000039 Container Transitioned from ACQUIRED to RUNNING
2013-08-10 18:11:55,423 INFO org.apache.hadoop.yarn.server.resourcemanager.rmcontainer.RMContainerImpl: container_1376157310799_0010_01_000026 Container Transitioned from ACQUIRED to RUNNING
2013-08-10 18:11:55,423 INFO org.apache.hadoop.yarn.server.resourcemanager.rmcontainer.RMContainerImpl: container_1376157310799_0010_01_000027 Container Transitioned from ACQUIRED to RUNNING
2013-08-10 18:11:55,423 INFO org.apache.hadoop.yarn.server.resourcemanager.rmcontainer.RMContainerImpl: container_1376157310799_0010_01_000028 Container Transitioned from ACQUIRED to RUNNING
2013-08-10 18:11:55,423 INFO org.apache.hadoop.yarn.server.resourcemanager.rmcontainer.RMContainerImpl: container_1376157310799_0010_01_000029 Container Transitioned from ACQUIRED to RUNNING
2013-08-10 18:11:55,423 INFO org.apache.hadoop.yarn.server.resourcemanager.rmcontainer.RMContainerImpl: container_1376157310799_0010_01_000030 Container Transitioned from ACQUIRED to RUNNING
2013-08-10 18:11:55,423 INFO org.apache.hadoop.yarn.server.resourcemanager.rmcontainer.RMContainerImpl: container_1376157310799_0010_01_000031 Container Transitioned from ACQUIRED to RUNNING
2013-08-10 18:11:55,901 INFO org.apache.hadoop.yarn.server.resourcemanager.rmcontainer.RMContainerImpl: container_1376157310799_0010_01_000002 Container Transitioned from ACQUIRED to RUNNING
2013-08-10 18:11:55,902 INFO org.apache.hadoop.yarn.server.resourcemanager.rmcontainer.RMContainerImpl: container_1376157310799_0010_01_000003 Container Transitioned from ACQUIRED to RUNNING
2013-08-10 18:11:55,902 INFO org.apache.hadoop.yarn.server.resourcemanager.rmcontainer.RMContainerImpl: container_1376157310799_0010_01_000004 Container Transitioned from ACQUIRED to RUNNING
2013-08-10 18:11:55,902 INFO org.apache.hadoop.yarn.server.resourcemanager.rmcontainer.RMContainerImpl: container_1376157310799_0010_01_000005 Container Transitioned from ACQUIRED to RUNNING
2013-08-10 18:11:55,902 INFO org.apache.hadoop.yarn.server.resourcemanager.rmcontainer.RMContainerImpl: container_1376157310799_0010_01_000006 Container Transitioned from ACQUIRED to RUNNING
2013-08-10 18:11:55,902 INFO org.apache.hadoop.yarn.server.resourcemanager.rmcontainer.RMContainerImpl: container_1376157310799_0010_01_000007 Container Transitioned from ACQUIRED to RUNNING
2013-08-10 18:12:18,141 INFO org.apache.hadoop.yarn.server.resourcemanager.rmcontainer.RMContainerImpl: container_1376157310799_0010_01_000006 Container Transitioned from RUNNING to COMPLETED
2013-08-10 18:12:18,141 INFO org.apache.hadoop.yarn.server.resourcemanager.scheduler.common.fica.FiCaSchedulerApp: Completed container: container_1376157310799_0010_01_000006 in state: COMPLETED event:FINISHED
2013-08-10 18:12:18,141 INFO org.apache.hadoop.yarn.server.resourcemanager.RMAuditLogger: USER=ubuntu	OPERATION=AM Released Container	TARGET=SchedulerApp	RESULT=SUCCESS	APPID=application_1376157310799_0010	CONTAINERID=container_1376157310799_0010_01_000006
2013-08-10 18:12:18,141 INFO org.apache.hadoop.yarn.server.resourcemanager.scheduler.common.fica.FiCaSchedulerNode: Released container container_1376157310799_0010_01_000006 of capacity <memory:1024, vCores:1> on host hadoop-221-2:56306, which currently has 6 containers, <memory:7168, vCores:6> used and <memory:1024, vCores:10> available, release resources=true
2013-08-10 18:12:18,142 INFO org.apache.hadoop.yarn.server.resourcemanager.scheduler.capacity.LeafQueue: default used=<memory:48128, vCores:42> numContainers=42 user=ubuntu user-resources=<memory:48128, vCores:42>
2013-08-10 18:12:18,144 INFO org.apache.hadoop.yarn.server.resourcemanager.scheduler.capacity.LeafQueue: completedContainer container=Container: [ContainerId: container_1376157310799_0010_01_000006, NodeId: hadoop-221-2:56306, NodeHttpAddress: hadoop-221-2:8042, Resource: <memory:1024, vCores:1>, Priority: 20, State: NEW, Token: null, Status: container_id {, app_attempt_id {, application_id {, id: 10, cluster_timestamp: 1376157310799, }, attemptId: 1, }, id: 6, }, state: C_COMPLETE, diagnostics: "", exit_status: 0, ] resource=<memory:1024, vCores:1> queue=default: capacity=1.0, absoluteCapacity=1.0, usedResources=<memory:48128, vCores:42>usedCapacity=0.9791667, absoluteUsedCapacity=0.9791667, numApps=5, numContainers=42 usedCapacity=0.9791667 absoluteUsedCapacity=0.9791667 used=<memory:48128, vCores:42> cluster=<memory:49152, vCores:96>
2013-08-10 18:12:18,145 INFO org.apache.hadoop.yarn.server.resourcemanager.scheduler.capacity.ParentQueue: completedContainer queue=root usedCapacity=0.9791667 absoluteUsedCapacity=0.9791667 used=<memory:48128, vCores:42> cluster=<memory:49152, vCores:96>
2013-08-10 18:12:18,145 INFO org.apache.hadoop.yarn.server.resourcemanager.scheduler.capacity.CapacityScheduler: Application appattempt_1376157310799_0010_000001 released container container_1376157310799_0010_01_000006 on node: host: hadoop-221-2:56306 #containers=6 available=1024 used=7168 with event: FINISHED
2013-08-10 18:12:18,145 INFO org.apache.hadoop.yarn.server.resourcemanager.rmcontainer.RMContainerImpl: container_1376157310799_0006_01_000002 Container Transitioned from NEW to ALLOCATED
2013-08-10 18:12:18,145 INFO org.apache.hadoop.yarn.server.resourcemanager.RMAuditLogger: USER=ubuntu	OPERATION=AM Allocated Container	TARGET=SchedulerApp	RESULT=SUCCESS	APPID=application_1376157310799_0006	CONTAINERID=container_1376157310799_0006_01_000002
2013-08-10 18:12:18,146 INFO org.apache.hadoop.yarn.server.resourcemanager.scheduler.common.fica.FiCaSchedulerNode: Assigned container container_1376157310799_0006_01_000002 of capacity <memory:1024, vCores:1> on host hadoop-221-2:56306, which currently has 7 containers, <memory:8192, vCores:7> used and <memory:0, vCores:9> available
2013-08-10 18:12:18,147 INFO org.apache.hadoop.yarn.server.resourcemanager.scheduler.capacity.LeafQueue: assignedContainer application=application_1376157310799_0006 container=Container: [ContainerId: container_1376157310799_0006_01_000002, NodeId: hadoop-221-2:56306, NodeHttpAddress: hadoop-221-2:8042, Resource: <memory:1024, vCores:1>, Priority: 20, State: NEW, Token: null, Status: container_id {, app_attempt_id {, application_id {, id: 6, cluster_timestamp: 1376157310799, }, attemptId: 1, }, id: 2, }, state: C_NEW, ] containerId=container_1376157310799_0006_01_000002 queue=default: capacity=1.0, absoluteCapacity=1.0, usedResources=<memory:48128, vCores:42>usedCapacity=0.9791667, absoluteUsedCapacity=0.9791667, numApps=5, numContainers=42 usedCapacity=0.9791667 absoluteUsedCapacity=0.9791667 used=<memory:48128, vCores:42> cluster=<memory:49152, vCores:96>
2013-08-10 18:12:18,147 INFO org.apache.hadoop.yarn.server.resourcemanager.scheduler.capacity.ParentQueue: Re-sorting queues since queue: root.default stats: default: capacity=1.0, absoluteCapacity=1.0, usedResources=<memory:49152, vCores:43>usedCapacity=1.0, absoluteUsedCapacity=1.0, numApps=5, numContainers=43
2013-08-10 18:12:18,147 INFO org.apache.hadoop.yarn.server.resourcemanager.scheduler.capacity.ParentQueue: assignedContainer queue=root usedCapacity=1.0 absoluteUsedCapacity=1.0 used=<memory:49152, vCores:43> cluster=<memory:49152, vCores:96>
2013-08-10 18:12:18,296 INFO org.apache.hadoop.yarn.server.resourcemanager.rmcontainer.RMContainerImpl: container_1376157310799_0006_01_000002 Container Transitioned from ALLOCATED to ACQUIRED
2013-08-10 18:12:20,158 INFO org.apache.hadoop.yarn.server.resourcemanager.rmcontainer.RMContainerImpl: container_1376157310799_0010_01_000007 Container Transitioned from RUNNING to COMPLETED
2013-08-10 18:12:20,159 INFO org.apache.hadoop.yarn.server.resourcemanager.scheduler.common.fica.FiCaSchedulerApp: Completed container: container_1376157310799_0010_01_000007 in state: COMPLETED event:FINISHED
2013-08-10 18:12:20,159 INFO org.apache.hadoop.yarn.server.resourcemanager.RMAuditLogger: USER=ubuntu	OPERATION=AM Released Container	TARGET=SchedulerApp	RESULT=SUCCESS	APPID=application_1376157310799_0010	CONTAINERID=container_1376157310799_0010_01_000007
2013-08-10 18:12:20,159 INFO org.apache.hadoop.yarn.server.resourcemanager.scheduler.common.fica.FiCaSchedulerNode: Released container container_1376157310799_0010_01_000007 of capacity <memory:1024, vCores:1> on host hadoop-221-2:56306, which currently has 6 containers, <memory:7168, vCores:6> used and <memory:1024, vCores:10> available, release resources=true
2013-08-10 18:12:20,159 INFO org.apache.hadoop.yarn.server.resourcemanager.scheduler.capacity.LeafQueue: default used=<memory:48128, vCores:42> numContainers=42 user=ubuntu user-resources=<memory:48128, vCores:42>
2013-08-10 18:12:20,161 INFO org.apache.hadoop.yarn.server.resourcemanager.scheduler.capacity.LeafQueue: completedContainer container=Container: [ContainerId: container_1376157310799_0010_01_000007, NodeId: hadoop-221-2:56306, NodeHttpAddress: hadoop-221-2:8042, Resource: <memory:1024, vCores:1>, Priority: 20, State: NEW, Token: null, Status: container_id {, app_attempt_id {, application_id {, id: 10, cluster_timestamp: 1376157310799, }, attemptId: 1, }, id: 7, }, state: C_COMPLETE, diagnostics: "Container killed by the ApplicationMaster.\n\n", exit_status: 143, ] resource=<memory:1024, vCores:1> queue=default: capacity=1.0, absoluteCapacity=1.0, usedResources=<memory:48128, vCores:42>usedCapacity=0.9791667, absoluteUsedCapacity=0.9791667, numApps=5, numContainers=42 usedCapacity=0.9791667 absoluteUsedCapacity=0.9791667 used=<memory:48128, vCores:42> cluster=<memory:49152, vCores:96>
2013-08-10 18:12:20,162 INFO org.apache.hadoop.yarn.server.resourcemanager.scheduler.capacity.ParentQueue: completedContainer queue=root usedCapacity=0.9791667 absoluteUsedCapacity=0.9791667 used=<memory:48128, vCores:42> cluster=<memory:49152, vCores:96>
2013-08-10 18:12:20,162 INFO org.apache.hadoop.yarn.server.resourcemanager.scheduler.capacity.CapacityScheduler: Application appattempt_1376157310799_0010_000001 released container container_1376157310799_0010_01_000007 on node: host: hadoop-221-2:56306 #containers=6 available=1024 used=7168 with event: FINISHED
2013-08-10 18:12:20,162 INFO org.apache.hadoop.yarn.server.resourcemanager.rmcontainer.RMContainerImpl: container_1376157310799_0006_01_000003 Container Transitioned from NEW to ALLOCATED
2013-08-10 18:12:20,162 INFO org.apache.hadoop.yarn.server.resourcemanager.RMAuditLogger: USER=ubuntu	OPERATION=AM Allocated Container	TARGET=SchedulerApp	RESULT=SUCCESS	APPID=application_1376157310799_0006	CONTAINERID=container_1376157310799_0006_01_000003
2013-08-10 18:12:20,163 INFO org.apache.hadoop.yarn.server.resourcemanager.scheduler.common.fica.FiCaSchedulerNode: Assigned container container_1376157310799_0006_01_000003 of capacity <memory:1024, vCores:1> on host hadoop-221-2:56306, which currently has 7 containers, <memory:8192, vCores:7> used and <memory:0, vCores:9> available
2013-08-10 18:12:20,164 INFO org.apache.hadoop.yarn.server.resourcemanager.scheduler.capacity.LeafQueue: assignedContainer application=application_1376157310799_0006 container=Container: [ContainerId: container_1376157310799_0006_01_000003, NodeId: hadoop-221-2:56306, NodeHttpAddress: hadoop-221-2:8042, Resource: <memory:1024, vCores:1>, Priority: 20, State: NEW, Token: null, Status: container_id {, app_attempt_id {, application_id {, id: 6, cluster_timestamp: 1376157310799, }, attemptId: 1, }, id: 3, }, state: C_NEW, ] containerId=container_1376157310799_0006_01_000003 queue=default: capacity=1.0, absoluteCapacity=1.0, usedResources=<memory:48128, vCores:42>usedCapacity=0.9791667, absoluteUsedCapacity=0.9791667, numApps=5, numContainers=42 usedCapacity=0.9791667 absoluteUsedCapacity=0.9791667 used=<memory:48128, vCores:42> cluster=<memory:49152, vCores:96>
2013-08-10 18:12:20,164 INFO org.apache.hadoop.yarn.server.resourcemanager.scheduler.capacity.ParentQueue: Re-sorting queues since queue: root.default stats: default: capacity=1.0, absoluteCapacity=1.0, usedResources=<memory:49152, vCores:43>usedCapacity=1.0, absoluteUsedCapacity=1.0, numApps=5, numContainers=43
2013-08-10 18:12:20,164 INFO org.apache.hadoop.yarn.server.resourcemanager.scheduler.capacity.ParentQueue: assignedContainer queue=root usedCapacity=1.0 absoluteUsedCapacity=1.0 used=<memory:49152, vCores:43> cluster=<memory:49152, vCores:96>
2013-08-10 18:12:21,162 INFO org.apache.hadoop.yarn.server.resourcemanager.rmcontainer.RMContainerImpl: container_1376157310799_0006_01_000003 Container Transitioned from ALLOCATED to ACQUIRED
2013-08-10 18:12:21,170 INFO org.apache.hadoop.yarn.server.resourcemanager.rmcontainer.RMContainerImpl: container_1376157310799_0006_01_000002 Container Transitioned from ACQUIRED to RUNNING
2013-08-10 18:12:22,177 INFO org.apache.hadoop.yarn.server.resourcemanager.rmcontainer.RMContainerImpl: container_1376157310799_0006_01_000003 Container Transitioned from ACQUIRED to RUNNING
2013-08-10 18:12:22,732 INFO org.apache.hadoop.yarn.server.resourcemanager.rmcontainer.RMContainerImpl: container_1376157310799_0010_01_000021 Container Transitioned from RUNNING to COMPLETED
2013-08-10 18:12:22,732 INFO org.apache.hadoop.yarn.server.resourcemanager.scheduler.common.fica.FiCaSchedulerApp: Completed container: container_1376157310799_0010_01_000021 in state: COMPLETED event:FINISHED
2013-08-10 18:12:22,732 INFO org.apache.hadoop.yarn.server.resourcemanager.RMAuditLogger: USER=ubuntu	OPERATION=AM Released Container	TARGET=SchedulerApp	RESULT=SUCCESS	APPID=application_1376157310799_0010	CONTAINERID=container_1376157310799_0010_01_000021
2013-08-10 18:12:22,732 INFO org.apache.hadoop.yarn.server.resourcemanager.scheduler.common.fica.FiCaSchedulerNode: Released container container_1376157310799_0010_01_000021 of capacity <memory:1024, vCores:1> on host hadoop-221-3:38242, which currently has 6 containers, <memory:7168, vCores:6> used and <memory:1024, vCores:10> available, release resources=true
2013-08-10 18:12:22,733 INFO org.apache.hadoop.yarn.server.resourcemanager.scheduler.capacity.LeafQueue: default used=<memory:48128, vCores:42> numContainers=42 user=ubuntu user-resources=<memory:48128, vCores:42>
2013-08-10 18:12:22,734 INFO org.apache.hadoop.yarn.server.resourcemanager.scheduler.capacity.LeafQueue: completedContainer container=Container: [ContainerId: container_1376157310799_0010_01_000021, NodeId: hadoop-221-3:38242, NodeHttpAddress: hadoop-221-3:8042, Resource: <memory:1024, vCores:1>, Priority: 20, State: NEW, Token: null, Status: container_id {, app_attempt_id {, application_id {, id: 10, cluster_timestamp: 1376157310799, }, attemptId: 1, }, id: 21, }, state: C_COMPLETE, diagnostics: "Container killed by the ApplicationMaster.\n\n", exit_status: 143, ] resource=<memory:1024, vCores:1> queue=default: capacity=1.0, absoluteCapacity=1.0, usedResources=<memory:48128, vCores:42>usedCapacity=0.9791667, absoluteUsedCapacity=0.9791667, numApps=5, numContainers=42 usedCapacity=0.9791667 absoluteUsedCapacity=0.9791667 used=<memory:48128, vCores:42> cluster=<memory:49152, vCores:96>
2013-08-10 18:12:22,734 INFO org.apache.hadoop.yarn.server.resourcemanager.scheduler.capacity.ParentQueue: completedContainer queue=root usedCapacity=0.9791667 absoluteUsedCapacity=0.9791667 used=<memory:48128, vCores:42> cluster=<memory:49152, vCores:96>
2013-08-10 18:12:22,734 INFO org.apache.hadoop.yarn.server.resourcemanager.scheduler.capacity.CapacityScheduler: Application appattempt_1376157310799_0010_000001 released container container_1376157310799_0010_01_000021 on node: host: hadoop-221-3:38242 #containers=6 available=1024 used=7168 with event: FINISHED
2013-08-10 18:12:22,735 INFO org.apache.hadoop.yarn.server.resourcemanager.rmcontainer.RMContainerImpl: container_1376157310799_0006_01_000004 Container Transitioned from NEW to ALLOCATED
2013-08-10 18:12:22,735 INFO org.apache.hadoop.yarn.server.resourcemanager.RMAuditLogger: USER=ubuntu	OPERATION=AM Allocated Container	TARGET=SchedulerApp	RESULT=SUCCESS	APPID=application_1376157310799_0006	CONTAINERID=container_1376157310799_0006_01_000004
2013-08-10 18:12:22,735 INFO org.apache.hadoop.yarn.server.resourcemanager.scheduler.common.fica.FiCaSchedulerNode: Assigned container container_1376157310799_0006_01_000004 of capacity <memory:1024, vCores:1> on host hadoop-221-3:38242, which currently has 7 containers, <memory:8192, vCores:7> used and <memory:0, vCores:9> available
2013-08-10 18:12:22,736 INFO org.apache.hadoop.yarn.server.resourcemanager.scheduler.capacity.LeafQueue: assignedContainer application=application_1376157310799_0006 container=Container: [ContainerId: container_1376157310799_0006_01_000004, NodeId: hadoop-221-3:38242, NodeHttpAddress: hadoop-221-3:8042, Resource: <memory:1024, vCores:1>, Priority: 20, State: NEW, Token: null, Status: container_id {, app_attempt_id {, application_id {, id: 6, cluster_timestamp: 1376157310799, }, attemptId: 1, }, id: 4, }, state: C_NEW, ] containerId=container_1376157310799_0006_01_000004 queue=default: capacity=1.0, absoluteCapacity=1.0, usedResources=<memory:48128, vCores:42>usedCapacity=0.9791667, absoluteUsedCapacity=0.9791667, numApps=5, numContainers=42 usedCapacity=0.9791667 absoluteUsedCapacity=0.9791667 used=<memory:48128, vCores:42> cluster=<memory:49152, vCores:96>
2013-08-10 18:12:22,736 INFO org.apache.hadoop.yarn.server.resourcemanager.scheduler.capacity.ParentQueue: Re-sorting queues since queue: root.default stats: default: capacity=1.0, absoluteCapacity=1.0, usedResources=<memory:49152, vCores:43>usedCapacity=1.0, absoluteUsedCapacity=1.0, numApps=5, numContainers=43
2013-08-10 18:12:22,737 INFO org.apache.hadoop.yarn.server.resourcemanager.scheduler.capacity.ParentQueue: assignedContainer queue=root usedCapacity=1.0 absoluteUsedCapacity=1.0 used=<memory:49152, vCores:43> cluster=<memory:49152, vCores:96>
2013-08-10 18:12:23,177 INFO org.apache.hadoop.yarn.server.resourcemanager.rmcontainer.RMContainerImpl: container_1376157310799_0006_01_000004 Container Transitioned from ALLOCATED to ACQUIRED
2013-08-10 18:12:23,284 INFO org.apache.hadoop.yarn.server.resourcemanager.rmcontainer.RMContainerImpl: container_1376157310799_0010_01_000011 Container Transitioned from RUNNING to COMPLETED
2013-08-10 18:12:23,284 INFO org.apache.hadoop.yarn.server.resourcemanager.scheduler.common.fica.FiCaSchedulerApp: Completed container: container_1376157310799_0010_01_000011 in state: COMPLETED event:FINISHED
2013-08-10 18:12:23,284 INFO org.apache.hadoop.yarn.server.resourcemanager.RMAuditLogger: USER=ubuntu	OPERATION=AM Released Container	TARGET=SchedulerApp	RESULT=SUCCESS	APPID=application_1376157310799_0010	CONTAINERID=container_1376157310799_0010_01_000011
2013-08-10 18:12:23,285 INFO org.apache.hadoop.yarn.server.resourcemanager.scheduler.common.fica.FiCaSchedulerNode: Released container container_1376157310799_0010_01_000011 of capacity <memory:1024, vCores:1> on host hadoop-221-7:56906, which currently has 6 containers, <memory:7168, vCores:6> used and <memory:1024, vCores:10> available, release resources=true
2013-08-10 18:12:23,285 INFO org.apache.hadoop.yarn.server.resourcemanager.scheduler.capacity.LeafQueue: default used=<memory:48128, vCores:42> numContainers=42 user=ubuntu user-resources=<memory:48128, vCores:42>
2013-08-10 18:12:23,286 INFO org.apache.hadoop.yarn.server.resourcemanager.scheduler.capacity.LeafQueue: completedContainer container=Container: [ContainerId: container_1376157310799_0010_01_000011, NodeId: hadoop-221-7:56906, NodeHttpAddress: hadoop-221-7:8042, Resource: <memory:1024, vCores:1>, Priority: 20, State: NEW, Token: null, Status: container_id {, app_attempt_id {, application_id {, id: 10, cluster_timestamp: 1376157310799, }, attemptId: 1, }, id: 11, }, state: C_COMPLETE, diagnostics: "Container killed by the ApplicationMaster.\n", exit_status: 0, ] resource=<memory:1024, vCores:1> queue=default: capacity=1.0, absoluteCapacity=1.0, usedResources=<memory:48128, vCores:42>usedCapacity=0.9791667, absoluteUsedCapacity=0.9791667, numApps=5, numContainers=42 usedCapacity=0.9791667 absoluteUsedCapacity=0.9791667 used=<memory:48128, vCores:42> cluster=<memory:49152, vCores:96>
2013-08-10 18:12:23,286 INFO org.apache.hadoop.yarn.server.resourcemanager.scheduler.capacity.ParentQueue: completedContainer queue=root usedCapacity=0.9791667 absoluteUsedCapacity=0.9791667 used=<memory:48128, vCores:42> cluster=<memory:49152, vCores:96>
2013-08-10 18:12:23,286 INFO org.apache.hadoop.yarn.server.resourcemanager.scheduler.capacity.CapacityScheduler: Application appattempt_1376157310799_0010_000001 released container container_1376157310799_0010_01_000011 on node: host: hadoop-221-7:56906 #containers=6 available=1024 used=7168 with event: FINISHED
2013-08-10 18:12:23,287 INFO org.apache.hadoop.yarn.server.resourcemanager.rmcontainer.RMContainerImpl: container_1376157310799_0010_01_000012 Container Transitioned from RUNNING to COMPLETED
2013-08-10 18:12:23,287 INFO org.apache.hadoop.yarn.server.resourcemanager.scheduler.common.fica.FiCaSchedulerApp: Completed container: container_1376157310799_0010_01_000012 in state: COMPLETED event:FINISHED
2013-08-10 18:12:23,287 INFO org.apache.hadoop.yarn.server.resourcemanager.RMAuditLogger: USER=ubuntu	OPERATION=AM Released Container	TARGET=SchedulerApp	RESULT=SUCCESS	APPID=application_1376157310799_0010	CONTAINERID=container_1376157310799_0010_01_000012
2013-08-10 18:12:23,287 INFO org.apache.hadoop.yarn.server.resourcemanager.scheduler.common.fica.FiCaSchedulerNode: Released container container_1376157310799_0010_01_000012 of capacity <memory:1024, vCores:1> on host hadoop-221-7:56906, which currently has 5 containers, <memory:6144, vCores:5> used and <memory:2048, vCores:11> available, release resources=true
2013-08-10 18:12:23,287 INFO org.apache.hadoop.yarn.server.resourcemanager.scheduler.capacity.LeafQueue: default used=<memory:47104, vCores:41> numContainers=41 user=ubuntu user-resources=<memory:47104, vCores:41>
2013-08-10 18:12:23,289 INFO org.apache.hadoop.yarn.server.resourcemanager.scheduler.capacity.LeafQueue: completedContainer container=Container: [ContainerId: container_1376157310799_0010_01_000012, NodeId: hadoop-221-7:56906, NodeHttpAddress: hadoop-221-7:8042, Resource: <memory:1024, vCores:1>, Priority: 20, State: NEW, Token: null, Status: container_id {, app_attempt_id {, application_id {, id: 10, cluster_timestamp: 1376157310799, }, attemptId: 1, }, id: 12, }, state: C_COMPLETE, diagnostics: "Container killed by the ApplicationMaster.\n", exit_status: 0, ] resource=<memory:1024, vCores:1> queue=default: capacity=1.0, absoluteCapacity=1.0, usedResources=<memory:47104, vCores:41>usedCapacity=0.9583333, absoluteUsedCapacity=0.9583333, numApps=5, numContainers=41 usedCapacity=0.9583333 absoluteUsedCapacity=0.9583333 used=<memory:47104, vCores:41> cluster=<memory:49152, vCores:96>
2013-08-10 18:12:23,289 INFO org.apache.hadoop.yarn.server.resourcemanager.scheduler.capacity.ParentQueue: completedContainer queue=root usedCapacity=0.9583333 absoluteUsedCapacity=0.9583333 used=<memory:47104, vCores:41> cluster=<memory:49152, vCores:96>
2013-08-10 18:12:23,289 INFO org.apache.hadoop.yarn.server.resourcemanager.scheduler.capacity.CapacityScheduler: Application appattempt_1376157310799_0010_000001 released container container_1376157310799_0010_01_000012 on node: host: hadoop-221-7:56906 #containers=5 available=2048 used=6144 with event: FINISHED
2013-08-10 18:12:23,289 INFO org.apache.hadoop.yarn.server.resourcemanager.rmcontainer.RMContainerImpl: container_1376157310799_0006_01_000005 Container Transitioned from NEW to ALLOCATED
2013-08-10 18:12:23,290 INFO org.apache.hadoop.yarn.server.resourcemanager.RMAuditLogger: USER=ubuntu	OPERATION=AM Allocated Container	TARGET=SchedulerApp	RESULT=SUCCESS	APPID=application_1376157310799_0006	CONTAINERID=container_1376157310799_0006_01_000005
2013-08-10 18:12:23,290 INFO org.apache.hadoop.yarn.server.resourcemanager.scheduler.common.fica.FiCaSchedulerNode: Assigned container container_1376157310799_0006_01_000005 of capacity <memory:1024, vCores:1> on host hadoop-221-7:56906, which currently has 6 containers, <memory:7168, vCores:6> used and <memory:1024, vCores:10> available
2013-08-10 18:12:23,291 INFO org.apache.hadoop.yarn.server.resourcemanager.scheduler.capacity.LeafQueue: assignedContainer application=application_1376157310799_0006 container=Container: [ContainerId: container_1376157310799_0006_01_000005, NodeId: hadoop-221-7:56906, NodeHttpAddress: hadoop-221-7:8042, Resource: <memory:1024, vCores:1>, Priority: 20, State: NEW, Token: null, Status: container_id {, app_attempt_id {, application_id {, id: 6, cluster_timestamp: 1376157310799, }, attemptId: 1, }, id: 5, }, state: C_NEW, ] containerId=container_1376157310799_0006_01_000005 queue=default: capacity=1.0, absoluteCapacity=1.0, usedResources=<memory:47104, vCores:41>usedCapacity=0.9583333, absoluteUsedCapacity=0.9583333, numApps=5, numContainers=41 usedCapacity=0.9583333 absoluteUsedCapacity=0.9583333 used=<memory:47104, vCores:41> cluster=<memory:49152, vCores:96>
2013-08-10 18:12:23,291 INFO org.apache.hadoop.yarn.server.resourcemanager.scheduler.capacity.ParentQueue: Re-sorting queues since queue: root.default stats: default: capacity=1.0, absoluteCapacity=1.0, usedResources=<memory:48128, vCores:42>usedCapacity=0.9791667, absoluteUsedCapacity=0.9791667, numApps=5, numContainers=42
2013-08-10 18:12:23,291 INFO org.apache.hadoop.yarn.server.resourcemanager.scheduler.capacity.ParentQueue: assignedContainer queue=root usedCapacity=0.9791667 absoluteUsedCapacity=0.9791667 used=<memory:48128, vCores:42> cluster=<memory:49152, vCores:96>
2013-08-10 18:12:23,292 INFO org.apache.hadoop.yarn.server.resourcemanager.rmcontainer.RMContainerImpl: container_1376157310799_0006_01_000006 Container Transitioned from NEW to ALLOCATED
2013-08-10 18:12:23,292 INFO org.apache.hadoop.yarn.server.resourcemanager.RMAuditLogger: USER=ubuntu	OPERATION=AM Allocated Container	TARGET=SchedulerApp	RESULT=SUCCESS	APPID=application_1376157310799_0006	CONTAINERID=container_1376157310799_0006_01_000006
2013-08-10 18:12:23,292 INFO org.apache.hadoop.yarn.server.resourcemanager.scheduler.common.fica.FiCaSchedulerNode: Assigned container container_1376157310799_0006_01_000006 of capacity <memory:1024, vCores:1> on host hadoop-221-7:56906, which currently has 7 containers, <memory:8192, vCores:7> used and <memory:0, vCores:9> available
2013-08-10 18:12:23,293 INFO org.apache.hadoop.yarn.server.resourcemanager.scheduler.capacity.LeafQueue: assignedContainer application=application_1376157310799_0006 container=Container: [ContainerId: container_1376157310799_0006_01_000006, NodeId: hadoop-221-7:56906, NodeHttpAddress: hadoop-221-7:8042, Resource: <memory:1024, vCores:1>, Priority: 20, State: NEW, Token: null, Status: container_id {, app_attempt_id {, application_id {, id: 6, cluster_timestamp: 1376157310799, }, attemptId: 1, }, id: 6, }, state: C_NEW, ] containerId=container_1376157310799_0006_01_000006 queue=default: capacity=1.0, absoluteCapacity=1.0, usedResources=<memory:48128, vCores:42>usedCapacity=0.9791667, absoluteUsedCapacity=0.9791667, numApps=5, numContainers=42 usedCapacity=0.9791667 absoluteUsedCapacity=0.9791667 used=<memory:48128, vCores:42> cluster=<memory:49152, vCores:96>
2013-08-10 18:12:23,293 INFO org.apache.hadoop.yarn.server.resourcemanager.scheduler.capacity.ParentQueue: Re-sorting queues since queue: root.default stats: default: capacity=1.0, absoluteCapacity=1.0, usedResources=<memory:49152, vCores:43>usedCapacity=1.0, absoluteUsedCapacity=1.0, numApps=5, numContainers=43
2013-08-10 18:12:23,294 INFO org.apache.hadoop.yarn.server.resourcemanager.scheduler.capacity.ParentQueue: assignedContainer queue=root usedCapacity=1.0 absoluteUsedCapacity=1.0 used=<memory:49152, vCores:43> cluster=<memory:49152, vCores:96>
2013-08-10 18:12:23,763 INFO org.apache.hadoop.yarn.server.resourcemanager.rmcontainer.RMContainerImpl: container_1376157310799_0006_01_000004 Container Transitioned from ACQUIRED to RUNNING
2013-08-10 18:12:24,187 INFO org.apache.hadoop.yarn.server.resourcemanager.rmcontainer.RMContainerImpl: container_1376157310799_0006_01_000005 Container Transitioned from ALLOCATED to ACQUIRED
2013-08-10 18:12:24,188 INFO org.apache.hadoop.yarn.server.resourcemanager.rmcontainer.RMContainerImpl: container_1376157310799_0006_01_000006 Container Transitioned from ALLOCATED to ACQUIRED
2013-08-10 18:12:24,323 INFO org.apache.hadoop.yarn.server.resourcemanager.rmcontainer.RMContainerImpl: container_1376157310799_0006_01_000005 Container Transitioned from ACQUIRED to RUNNING
2013-08-10 18:12:24,323 INFO org.apache.hadoop.yarn.server.resourcemanager.rmcontainer.RMContainerImpl: container_1376157310799_0006_01_000006 Container Transitioned from ACQUIRED to RUNNING
2013-08-10 18:12:26,435 INFO org.apache.hadoop.yarn.server.resourcemanager.rmcontainer.RMContainerImpl: container_1376157310799_0010_01_000010 Container Transitioned from RUNNING to COMPLETED
2013-08-10 18:12:26,436 INFO org.apache.hadoop.yarn.server.resourcemanager.scheduler.common.fica.FiCaSchedulerApp: Completed container: container_1376157310799_0010_01_000010 in state: COMPLETED event:FINISHED
2013-08-10 18:12:26,436 INFO org.apache.hadoop.yarn.server.resourcemanager.RMAuditLogger: USER=ubuntu	OPERATION=AM Released Container	TARGET=SchedulerApp	RESULT=SUCCESS	APPID=application_1376157310799_0010	CONTAINERID=container_1376157310799_0010_01_000010
2013-08-10 18:12:26,436 INFO org.apache.hadoop.yarn.server.resourcemanager.scheduler.common.fica.FiCaSchedulerNode: Released container container_1376157310799_0010_01_000010 of capacity <memory:1024, vCores:1> on host hadoop-221-7:56906, which currently has 6 containers, <memory:7168, vCores:6> used and <memory:1024, vCores:10> available, release resources=true
2013-08-10 18:12:26,436 INFO org.apache.hadoop.yarn.server.resourcemanager.scheduler.capacity.LeafQueue: default used=<memory:48128, vCores:42> numContainers=42 user=ubuntu user-resources=<memory:48128, vCores:42>
2013-08-10 18:12:26,438 INFO org.apache.hadoop.yarn.server.resourcemanager.scheduler.capacity.LeafQueue: completedContainer container=Container: [ContainerId: container_1376157310799_0010_01_000010, NodeId: hadoop-221-7:56906, NodeHttpAddress: hadoop-221-7:8042, Resource: <memory:1024, vCores:1>, Priority: 20, State: NEW, Token: null, Status: container_id {, app_attempt_id {, application_id {, id: 10, cluster_timestamp: 1376157310799, }, attemptId: 1, }, id: 10, }, state: C_COMPLETE, diagnostics: "Container killed by the ApplicationMaster.\n\n", exit_status: 143, ] resource=<memory:1024, vCores:1> queue=default: capacity=1.0, absoluteCapacity=1.0, usedResources=<memory:48128, vCores:42>usedCapacity=0.9791667, absoluteUsedCapacity=0.9791667, numApps=5, numContainers=42 usedCapacity=0.9791667 absoluteUsedCapacity=0.9791667 used=<memory:48128, vCores:42> cluster=<memory:49152, vCores:96>
2013-08-10 18:12:26,438 INFO org.apache.hadoop.yarn.server.resourcemanager.scheduler.capacity.ParentQueue: completedContainer queue=root usedCapacity=0.9791667 absoluteUsedCapacity=0.9791667 used=<memory:48128, vCores:42> cluster=<memory:49152, vCores:96>
2013-08-10 18:12:26,438 INFO org.apache.hadoop.yarn.server.resourcemanager.scheduler.capacity.CapacityScheduler: Application appattempt_1376157310799_0010_000001 released container container_1376157310799_0010_01_000010 on node: host: hadoop-221-7:56906 #containers=6 available=1024 used=7168 with event: FINISHED
2013-08-10 18:12:26,438 INFO org.apache.hadoop.yarn.server.resourcemanager.rmcontainer.RMContainerImpl: container_1376157310799_0006_01_000007 Container Transitioned from NEW to ALLOCATED
2013-08-10 18:12:26,439 INFO org.apache.hadoop.yarn.server.resourcemanager.RMAuditLogger: USER=ubuntu	OPERATION=AM Allocated Container	TARGET=SchedulerApp	RESULT=SUCCESS	APPID=application_1376157310799_0006	CONTAINERID=container_1376157310799_0006_01_000007
2013-08-10 18:12:26,439 INFO org.apache.hadoop.yarn.server.resourcemanager.scheduler.common.fica.FiCaSchedulerNode: Assigned container container_1376157310799_0006_01_000007 of capacity <memory:1024, vCores:1> on host hadoop-221-7:56906, which currently has 7 containers, <memory:8192, vCores:7> used and <memory:0, vCores:9> available
2013-08-10 18:12:26,440 INFO org.apache.hadoop.yarn.server.resourcemanager.scheduler.capacity.LeafQueue: assignedContainer application=application_1376157310799_0006 container=Container: [ContainerId: container_1376157310799_0006_01_000007, NodeId: hadoop-221-7:56906, NodeHttpAddress: hadoop-221-7:8042, Resource: <memory:1024, vCores:1>, Priority: 20, State: NEW, Token: null, Status: container_id {, app_attempt_id {, application_id {, id: 6, cluster_timestamp: 1376157310799, }, attemptId: 1, }, id: 7, }, state: C_NEW, ] containerId=container_1376157310799_0006_01_000007 queue=default: capacity=1.0, absoluteCapacity=1.0, usedResources=<memory:48128, vCores:42>usedCapacity=0.9791667, absoluteUsedCapacity=0.9791667, numApps=5, numContainers=42 usedCapacity=0.9791667 absoluteUsedCapacity=0.9791667 used=<memory:48128, vCores:42> cluster=<memory:49152, vCores:96>
2013-08-10 18:12:26,440 INFO org.apache.hadoop.yarn.server.resourcemanager.scheduler.capacity.ParentQueue: Re-sorting queues since queue: root.default stats: default: capacity=1.0, absoluteCapacity=1.0, usedResources=<memory:49152, vCores:43>usedCapacity=1.0, absoluteUsedCapacity=1.0, numApps=5, numContainers=43
2013-08-10 18:12:26,440 INFO org.apache.hadoop.yarn.server.resourcemanager.scheduler.capacity.ParentQueue: assignedContainer queue=root usedCapacity=1.0 absoluteUsedCapacity=1.0 used=<memory:49152, vCores:43> cluster=<memory:49152, vCores:96>
2013-08-10 18:12:26,505 INFO org.apache.hadoop.yarn.server.resourcemanager.rmcontainer.RMContainerImpl: container_1376157310799_0006_01_000007 Container Transitioned from ALLOCATED to ACQUIRED
2013-08-10 18:12:27,445 INFO org.apache.hadoop.yarn.server.resourcemanager.rmcontainer.RMContainerImpl: container_1376157310799_0006_01_000007 Container Transitioned from ACQUIRED to RUNNING
2013-08-10 18:12:29,108 INFO org.apache.hadoop.yarn.server.resourcemanager.rmcontainer.RMContainerImpl: container_1376157310799_0010_01_000023 Container Transitioned from RUNNING to COMPLETED
2013-08-10 18:12:29,109 INFO org.apache.hadoop.yarn.server.resourcemanager.scheduler.common.fica.FiCaSchedulerApp: Completed container: container_1376157310799_0010_01_000023 in state: COMPLETED event:FINISHED
2013-08-10 18:12:29,109 INFO org.apache.hadoop.yarn.server.resourcemanager.RMAuditLogger: USER=ubuntu	OPERATION=AM Released Container	TARGET=SchedulerApp	RESULT=SUCCESS	APPID=application_1376157310799_0010	CONTAINERID=container_1376157310799_0010_01_000023
2013-08-10 18:12:29,109 INFO org.apache.hadoop.yarn.server.resourcemanager.scheduler.common.fica.FiCaSchedulerNode: Released container container_1376157310799_0010_01_000023 of capacity <memory:1024, vCores:1> on host hadoop-221-3:38242, which currently has 6 containers, <memory:7168, vCores:6> used and <memory:1024, vCores:10> available, release resources=true
2013-08-10 18:12:29,109 INFO org.apache.hadoop.yarn.server.resourcemanager.scheduler.capacity.LeafQueue: default used=<memory:48128, vCores:42> numContainers=42 user=ubuntu user-resources=<memory:48128, vCores:42>
2013-08-10 18:12:29,110 INFO org.apache.hadoop.yarn.server.resourcemanager.scheduler.capacity.LeafQueue: completedContainer container=Container: [ContainerId: container_1376157310799_0010_01_000023, NodeId: hadoop-221-3:38242, NodeHttpAddress: hadoop-221-3:8042, Resource: <memory:1024, vCores:1>, Priority: 20, State: NEW, Token: null, Status: container_id {, app_attempt_id {, application_id {, id: 10, cluster_timestamp: 1376157310799, }, attemptId: 1, }, id: 23, }, state: C_COMPLETE, diagnostics: "Container killed by the ApplicationMaster.\n\n", exit_status: 143, ] resource=<memory:1024, vCores:1> queue=default: capacity=1.0, absoluteCapacity=1.0, usedResources=<memory:48128, vCores:42>usedCapacity=0.9791667, absoluteUsedCapacity=0.9791667, numApps=5, numContainers=42 usedCapacity=0.9791667 absoluteUsedCapacity=0.9791667 used=<memory:48128, vCores:42> cluster=<memory:49152, vCores:96>
2013-08-10 18:12:29,110 INFO org.apache.hadoop.yarn.server.resourcemanager.scheduler.capacity.ParentQueue: completedContainer queue=root usedCapacity=0.9791667 absoluteUsedCapacity=0.9791667 used=<memory:48128, vCores:42> cluster=<memory:49152, vCores:96>
2013-08-10 18:12:29,111 INFO org.apache.hadoop.yarn.server.resourcemanager.scheduler.capacity.CapacityScheduler: Application appattempt_1376157310799_0010_000001 released container container_1376157310799_0010_01_000023 on node: host: hadoop-221-3:38242 #containers=6 available=1024 used=7168 with event: FINISHED
2013-08-10 18:12:29,111 INFO org.apache.hadoop.yarn.server.resourcemanager.rmcontainer.RMContainerImpl: container_1376157310799_0006_01_000008 Container Transitioned from NEW to ALLOCATED
2013-08-10 18:12:29,111 INFO org.apache.hadoop.yarn.server.resourcemanager.RMAuditLogger: USER=ubuntu	OPERATION=AM Allocated Container	TARGET=SchedulerApp	RESULT=SUCCESS	APPID=application_1376157310799_0006	CONTAINERID=container_1376157310799_0006_01_000008
2013-08-10 18:12:29,111 INFO org.apache.hadoop.yarn.server.resourcemanager.scheduler.common.fica.FiCaSchedulerNode: Assigned container container_1376157310799_0006_01_000008 of capacity <memory:1024, vCores:1> on host hadoop-221-3:38242, which currently has 7 containers, <memory:8192, vCores:7> used and <memory:0, vCores:9> available
2013-08-10 18:12:29,112 INFO org.apache.hadoop.yarn.server.resourcemanager.scheduler.capacity.LeafQueue: assignedContainer application=application_1376157310799_0006 container=Container: [ContainerId: container_1376157310799_0006_01_000008, NodeId: hadoop-221-3:38242, NodeHttpAddress: hadoop-221-3:8042, Resource: <memory:1024, vCores:1>, Priority: 20, State: NEW, Token: null, Status: container_id {, app_attempt_id {, application_id {, id: 6, cluster_timestamp: 1376157310799, }, attemptId: 1, }, id: 8, }, state: C_NEW, ] containerId=container_1376157310799_0006_01_000008 queue=default: capacity=1.0, absoluteCapacity=1.0, usedResources=<memory:48128, vCores:42>usedCapacity=0.9791667, absoluteUsedCapacity=0.9791667, numApps=5, numContainers=42 usedCapacity=0.9791667 absoluteUsedCapacity=0.9791667 used=<memory:48128, vCores:42> cluster=<memory:49152, vCores:96>
2013-08-10 18:12:29,113 INFO org.apache.hadoop.yarn.server.resourcemanager.scheduler.capacity.ParentQueue: Re-sorting queues since queue: root.default stats: default: capacity=1.0, absoluteCapacity=1.0, usedResources=<memory:49152, vCores:43>usedCapacity=1.0, absoluteUsedCapacity=1.0, numApps=5, numContainers=43
2013-08-10 18:12:29,113 INFO org.apache.hadoop.yarn.server.resourcemanager.scheduler.capacity.ParentQueue: assignedContainer queue=root usedCapacity=1.0 absoluteUsedCapacity=1.0 used=<memory:49152, vCores:43> cluster=<memory:49152, vCores:96>
2013-08-10 18:12:29,518 INFO org.apache.hadoop.yarn.server.resourcemanager.rmcontainer.RMContainerImpl: container_1376157310799_0006_01_000008 Container Transitioned from ALLOCATED to ACQUIRED
2013-08-10 18:12:29,597 INFO org.apache.hadoop.yarn.server.resourcemanager.rmcontainer.RMContainerImpl: container_1376157310799_0010_01_000033 Container Transitioned from RUNNING to COMPLETED
2013-08-10 18:12:29,597 INFO org.apache.hadoop.yarn.server.resourcemanager.scheduler.common.fica.FiCaSchedulerApp: Completed container: container_1376157310799_0010_01_000033 in state: COMPLETED event:FINISHED
2013-08-10 18:12:29,597 INFO org.apache.hadoop.yarn.server.resourcemanager.RMAuditLogger: USER=ubuntu	OPERATION=AM Released Container	TARGET=SchedulerApp	RESULT=SUCCESS	APPID=application_1376157310799_0010	CONTAINERID=container_1376157310799_0010_01_000033
2013-08-10 18:12:29,597 INFO org.apache.hadoop.yarn.server.resourcemanager.scheduler.common.fica.FiCaSchedulerNode: Released container container_1376157310799_0010_01_000033 of capacity <memory:1024, vCores:1> on host hadoop-221-6:39509, which currently has 7 containers, <memory:7168, vCores:7> used and <memory:1024, vCores:9> available, release resources=true
2013-08-10 18:12:29,597 INFO org.apache.hadoop.yarn.server.resourcemanager.scheduler.capacity.LeafQueue: default used=<memory:48128, vCores:42> numContainers=42 user=ubuntu user-resources=<memory:48128, vCores:42>
2013-08-10 18:12:29,598 INFO org.apache.hadoop.yarn.server.resourcemanager.scheduler.capacity.LeafQueue: completedContainer container=Container: [ContainerId: container_1376157310799_0010_01_000033, NodeId: hadoop-221-6:39509, NodeHttpAddress: hadoop-221-6:8042, Resource: <memory:1024, vCores:1>, Priority: 20, State: NEW, Token: null, Status: container_id {, app_attempt_id {, application_id {, id: 10, cluster_timestamp: 1376157310799, }, attemptId: 1, }, id: 33, }, state: C_COMPLETE, diagnostics: "Container killed by the ApplicationMaster.\n", exit_status: 0, ] resource=<memory:1024, vCores:1> queue=default: capacity=1.0, absoluteCapacity=1.0, usedResources=<memory:48128, vCores:42>usedCapacity=0.9791667, absoluteUsedCapacity=0.9791667, numApps=5, numContainers=42 usedCapacity=0.9791667 absoluteUsedCapacity=0.9791667 used=<memory:48128, vCores:42> cluster=<memory:49152, vCores:96>
2013-08-10 18:12:29,599 INFO org.apache.hadoop.yarn.server.resourcemanager.scheduler.capacity.ParentQueue: completedContainer queue=root usedCapacity=0.9791667 absoluteUsedCapacity=0.9791667 used=<memory:48128, vCores:42> cluster=<memory:49152, vCores:96>
2013-08-10 18:12:29,599 INFO org.apache.hadoop.yarn.server.resourcemanager.scheduler.capacity.CapacityScheduler: Application appattempt_1376157310799_0010_000001 released container container_1376157310799_0010_01_000033 on node: host: hadoop-221-6:39509 #containers=7 available=1024 used=7168 with event: FINISHED
2013-08-10 18:12:29,599 INFO org.apache.hadoop.yarn.server.resourcemanager.rmcontainer.RMContainerImpl: container_1376157310799_0010_01_000039 Container Transitioned from RUNNING to COMPLETED
2013-08-10 18:12:29,599 INFO org.apache.hadoop.yarn.server.resourcemanager.scheduler.common.fica.FiCaSchedulerApp: Completed container: container_1376157310799_0010_01_000039 in state: COMPLETED event:FINISHED
2013-08-10 18:12:29,599 INFO org.apache.hadoop.yarn.server.resourcemanager.RMAuditLogger: USER=ubuntu	OPERATION=AM Released Container	TARGET=SchedulerApp	RESULT=SUCCESS	APPID=application_1376157310799_0010	CONTAINERID=container_1376157310799_0010_01_000039
2013-08-10 18:12:29,600 INFO org.apache.hadoop.yarn.server.resourcemanager.scheduler.common.fica.FiCaSchedulerNode: Released container container_1376157310799_0010_01_000039 of capacity <memory:1024, vCores:1> on host hadoop-221-6:39509, which currently has 6 containers, <memory:6144, vCores:6> used and <memory:2048, vCores:10> available, release resources=true
2013-08-10 18:12:29,600 INFO org.apache.hadoop.yarn.server.resourcemanager.scheduler.capacity.LeafQueue: default used=<memory:47104, vCores:41> numContainers=41 user=ubuntu user-resources=<memory:47104, vCores:41>
2013-08-10 18:12:29,601 INFO org.apache.hadoop.yarn.server.resourcemanager.scheduler.capacity.LeafQueue: completedContainer container=Container: [ContainerId: container_1376157310799_0010_01_000039, NodeId: hadoop-221-6:39509, NodeHttpAddress: hadoop-221-6:8042, Resource: <memory:1024, vCores:1>, Priority: 20, State: NEW, Token: null, Status: container_id {, app_attempt_id {, application_id {, id: 10, cluster_timestamp: 1376157310799, }, attemptId: 1, }, id: 39, }, state: C_COMPLETE, diagnostics: "Container killed by the ApplicationMaster.\n\n", exit_status: 143, ] resource=<memory:1024, vCores:1> queue=default: capacity=1.0, absoluteCapacity=1.0, usedResources=<memory:47104, vCores:41>usedCapacity=0.9583333, absoluteUsedCapacity=0.9583333, numApps=5, numContainers=41 usedCapacity=0.9583333 absoluteUsedCapacity=0.9583333 used=<memory:47104, vCores:41> cluster=<memory:49152, vCores:96>
2013-08-10 18:12:29,601 INFO org.apache.hadoop.yarn.server.resourcemanager.scheduler.capacity.ParentQueue: completedContainer queue=root usedCapacity=0.9583333 absoluteUsedCapacity=0.9583333 used=<memory:47104, vCores:41> cluster=<memory:49152, vCores:96>
2013-08-10 18:12:29,601 INFO org.apache.hadoop.yarn.server.resourcemanager.scheduler.capacity.CapacityScheduler: Application appattempt_1376157310799_0010_000001 released container container_1376157310799_0010_01_000039 on node: host: hadoop-221-6:39509 #containers=6 available=2048 used=6144 with event: FINISHED
2013-08-10 18:12:29,602 INFO org.apache.hadoop.yarn.server.resourcemanager.rmcontainer.RMContainerImpl: container_1376157310799_0006_01_000009 Container Transitioned from NEW to ALLOCATED
2013-08-10 18:12:29,602 INFO org.apache.hadoop.yarn.server.resourcemanager.RMAuditLogger: USER=ubuntu	OPERATION=AM Allocated Container	TARGET=SchedulerApp	RESULT=SUCCESS	APPID=application_1376157310799_0006	CONTAINERID=container_1376157310799_0006_01_000009
2013-08-10 18:12:29,602 INFO org.apache.hadoop.yarn.server.resourcemanager.scheduler.common.fica.FiCaSchedulerNode: Assigned container container_1376157310799_0006_01_000009 of capacity <memory:1024, vCores:1> on host hadoop-221-6:39509, which currently has 7 containers, <memory:7168, vCores:7> used and <memory:1024, vCores:9> available
2013-08-10 18:12:29,603 INFO org.apache.hadoop.yarn.server.resourcemanager.scheduler.capacity.LeafQueue: assignedContainer application=application_1376157310799_0006 container=Container: [ContainerId: container_1376157310799_0006_01_000009, NodeId: hadoop-221-6:39509, NodeHttpAddress: hadoop-221-6:8042, Resource: <memory:1024, vCores:1>, Priority: 20, State: NEW, Token: null, Status: container_id {, app_attempt_id {, application_id {, id: 6, cluster_timestamp: 1376157310799, }, attemptId: 1, }, id: 9, }, state: C_NEW, ] containerId=container_1376157310799_0006_01_000009 queue=default: capacity=1.0, absoluteCapacity=1.0, usedResources=<memory:47104, vCores:41>usedCapacity=0.9583333, absoluteUsedCapacity=0.9583333, numApps=5, numContainers=41 usedCapacity=0.9583333 absoluteUsedCapacity=0.9583333 used=<memory:47104, vCores:41> cluster=<memory:49152, vCores:96>
2013-08-10 18:12:29,603 INFO org.apache.hadoop.yarn.server.resourcemanager.scheduler.capacity.ParentQueue: Re-sorting queues since queue: root.default stats: default: capacity=1.0, absoluteCapacity=1.0, usedResources=<memory:48128, vCores:42>usedCapacity=0.9791667, absoluteUsedCapacity=0.9791667, numApps=5, numContainers=42
2013-08-10 18:12:29,604 INFO org.apache.hadoop.yarn.server.resourcemanager.scheduler.capacity.ParentQueue: assignedContainer queue=root usedCapacity=0.9791667 absoluteUsedCapacity=0.9791667 used=<memory:48128, vCores:42> cluster=<memory:49152, vCores:96>
2013-08-10 18:12:29,604 INFO org.apache.hadoop.yarn.server.resourcemanager.rmcontainer.RMContainerImpl: container_1376157310799_0006_01_000010 Container Transitioned from NEW to ALLOCATED
2013-08-10 18:12:29,604 INFO org.apache.hadoop.yarn.server.resourcemanager.RMAuditLogger: USER=ubuntu	OPERATION=AM Allocated Container	TARGET=SchedulerApp	RESULT=SUCCESS	APPID=application_1376157310799_0006	CONTAINERID=container_1376157310799_0006_01_000010
2013-08-10 18:12:29,604 INFO org.apache.hadoop.yarn.server.resourcemanager.scheduler.common.fica.FiCaSchedulerNode: Assigned container container_1376157310799_0006_01_000010 of capacity <memory:1024, vCores:1> on host hadoop-221-6:39509, which currently has 8 containers, <memory:8192, vCores:8> used and <memory:0, vCores:8> available
2013-08-10 18:12:29,605 INFO org.apache.hadoop.yarn.server.resourcemanager.scheduler.capacity.LeafQueue: assignedContainer application=application_1376157310799_0006 container=Container: [ContainerId: container_1376157310799_0006_01_000010, NodeId: hadoop-221-6:39509, NodeHttpAddress: hadoop-221-6:8042, Resource: <memory:1024, vCores:1>, Priority: 20, State: NEW, Token: null, Status: container_id {, app_attempt_id {, application_id {, id: 6, cluster_timestamp: 1376157310799, }, attemptId: 1, }, id: 10, }, state: C_NEW, ] containerId=container_1376157310799_0006_01_000010 queue=default: capacity=1.0, absoluteCapacity=1.0, usedResources=<memory:48128, vCores:42>usedCapacity=0.9791667, absoluteUsedCapacity=0.9791667, numApps=5, numContainers=42 usedCapacity=0.9791667 absoluteUsedCapacity=0.9791667 used=<memory:48128, vCores:42> cluster=<memory:49152, vCores:96>
2013-08-10 18:12:29,606 INFO org.apache.hadoop.yarn.server.resourcemanager.scheduler.capacity.ParentQueue: Re-sorting queues since queue: root.default stats: default: capacity=1.0, absoluteCapacity=1.0, usedResources=<memory:49152, vCores:43>usedCapacity=1.0, absoluteUsedCapacity=1.0, numApps=5, numContainers=43
2013-08-10 18:12:29,606 INFO org.apache.hadoop.yarn.server.resourcemanager.scheduler.capacity.ParentQueue: assignedContainer queue=root usedCapacity=1.0 absoluteUsedCapacity=1.0 used=<memory:49152, vCores:43> cluster=<memory:49152, vCores:96>
2013-08-10 18:12:30,114 INFO org.apache.hadoop.yarn.server.resourcemanager.rmcontainer.RMContainerImpl: container_1376157310799_0006_01_000008 Container Transitioned from ACQUIRED to RUNNING
2013-08-10 18:12:30,526 INFO org.apache.hadoop.yarn.server.resourcemanager.rmcontainer.RMContainerImpl: container_1376157310799_0006_01_000009 Container Transitioned from ALLOCATED to ACQUIRED
2013-08-10 18:12:30,527 INFO org.apache.hadoop.yarn.server.resourcemanager.rmcontainer.RMContainerImpl: container_1376157310799_0006_01_000010 Container Transitioned from ALLOCATED to ACQUIRED
2013-08-10 18:12:30,607 INFO org.apache.hadoop.yarn.server.resourcemanager.rmcontainer.RMContainerImpl: container_1376157310799_0006_01_000009 Container Transitioned from ACQUIRED to RUNNING
2013-08-10 18:12:30,608 INFO org.apache.hadoop.yarn.server.resourcemanager.rmcontainer.RMContainerImpl: container_1376157310799_0006_01_000010 Container Transitioned from ACQUIRED to RUNNING
2013-08-10 18:12:30,608 INFO org.apache.hadoop.yarn.server.resourcemanager.rmcontainer.RMContainerImpl: container_1376157310799_0010_01_000038 Container Transitioned from RUNNING to COMPLETED
2013-08-10 18:12:30,608 INFO org.apache.hadoop.yarn.server.resourcemanager.scheduler.common.fica.FiCaSchedulerApp: Completed container: container_1376157310799_0010_01_000038 in state: COMPLETED event:FINISHED
2013-08-10 18:12:30,608 INFO org.apache.hadoop.yarn.server.resourcemanager.RMAuditLogger: USER=ubuntu	OPERATION=AM Released Container	TARGET=SchedulerApp	RESULT=SUCCESS	APPID=application_1376157310799_0010	CONTAINERID=container_1376157310799_0010_01_000038
2013-08-10 18:12:30,608 INFO org.apache.hadoop.yarn.server.resourcemanager.scheduler.common.fica.FiCaSchedulerNode: Released container container_1376157310799_0010_01_000038 of capacity <memory:1024, vCores:1> on host hadoop-221-6:39509, which currently has 7 containers, <memory:7168, vCores:7> used and <memory:1024, vCores:9> available, release resources=true
2013-08-10 18:12:30,609 INFO org.apache.hadoop.yarn.server.resourcemanager.scheduler.capacity.LeafQueue: default used=<memory:48128, vCores:42> numContainers=42 user=ubuntu user-resources=<memory:48128, vCores:42>
2013-08-10 18:12:30,610 INFO org.apache.hadoop.yarn.server.resourcemanager.scheduler.capacity.LeafQueue: completedContainer container=Container: [ContainerId: container_1376157310799_0010_01_000038, NodeId: hadoop-221-6:39509, NodeHttpAddress: hadoop-221-6:8042, Resource: <memory:1024, vCores:1>, Priority: 20, State: NEW, Token: null, Status: container_id {, app_attempt_id {, application_id {, id: 10, cluster_timestamp: 1376157310799, }, attemptId: 1, }, id: 38, }, state: C_COMPLETE, diagnostics: "Container killed by the ApplicationMaster.\n\n", exit_status: 143, ] resource=<memory:1024, vCores:1> queue=default: capacity=1.0, absoluteCapacity=1.0, usedResources=<memory:48128, vCores:42>usedCapacity=0.9791667, absoluteUsedCapacity=0.9791667, numApps=5, numContainers=42 usedCapacity=0.9791667 absoluteUsedCapacity=0.9791667 used=<memory:48128, vCores:42> cluster=<memory:49152, vCores:96>
2013-08-10 18:12:30,610 INFO org.apache.hadoop.yarn.server.resourcemanager.scheduler.capacity.ParentQueue: completedContainer queue=root usedCapacity=0.9791667 absoluteUsedCapacity=0.9791667 used=<memory:48128, vCores:42> cluster=<memory:49152, vCores:96>
2013-08-10 18:12:30,610 INFO org.apache.hadoop.yarn.server.resourcemanager.scheduler.capacity.CapacityScheduler: Application appattempt_1376157310799_0010_000001 released container container_1376157310799_0010_01_000038 on node: host: hadoop-221-6:39509 #containers=7 available=1024 used=7168 with event: FINISHED
2013-08-10 18:12:30,611 INFO org.apache.hadoop.yarn.server.resourcemanager.rmcontainer.RMContainerImpl: container_1376157310799_0006_01_000011 Container Transitioned from NEW to ALLOCATED
2013-08-10 18:12:30,611 INFO org.apache.hadoop.yarn.server.resourcemanager.RMAuditLogger: USER=ubuntu	OPERATION=AM Allocated Container	TARGET=SchedulerApp	RESULT=SUCCESS	APPID=application_1376157310799_0006	CONTAINERID=container_1376157310799_0006_01_000011
2013-08-10 18:12:30,611 INFO org.apache.hadoop.yarn.server.resourcemanager.scheduler.common.fica.FiCaSchedulerNode: Assigned container container_1376157310799_0006_01_000011 of capacity <memory:1024, vCores:1> on host hadoop-221-6:39509, which currently has 8 containers, <memory:8192, vCores:8> used and <memory:0, vCores:8> available
2013-08-10 18:12:30,612 INFO org.apache.hadoop.yarn.server.resourcemanager.scheduler.capacity.LeafQueue: assignedContainer application=application_1376157310799_0006 container=Container: [ContainerId: container_1376157310799_0006_01_000011, NodeId: hadoop-221-6:39509, NodeHttpAddress: hadoop-221-6:8042, Resource: <memory:1024, vCores:1>, Priority: 20, State: NEW, Token: null, Status: container_id {, app_attempt_id {, application_id {, id: 6, cluster_timestamp: 1376157310799, }, attemptId: 1, }, id: 11, }, state: C_NEW, ] containerId=container_1376157310799_0006_01_000011 queue=default: capacity=1.0, absoluteCapacity=1.0, usedResources=<memory:48128, vCores:42>usedCapacity=0.9791667, absoluteUsedCapacity=0.9791667, numApps=5, numContainers=42 usedCapacity=0.9791667 absoluteUsedCapacity=0.9791667 used=<memory:48128, vCores:42> cluster=<memory:49152, vCores:96>
2013-08-10 18:12:30,612 INFO org.apache.hadoop.yarn.server.resourcemanager.scheduler.capacity.ParentQueue: Re-sorting queues since queue: root.default stats: default: capacity=1.0, absoluteCapacity=1.0, usedResources=<memory:49152, vCores:43>usedCapacity=1.0, absoluteUsedCapacity=1.0, numApps=5, numContainers=43
2013-08-10 18:12:30,612 INFO org.apache.hadoop.yarn.server.resourcemanager.scheduler.capacity.ParentQueue: assignedContainer queue=root usedCapacity=1.0 absoluteUsedCapacity=1.0 used=<memory:49152, vCores:43> cluster=<memory:49152, vCores:96>
2013-08-10 18:12:31,080 INFO org.apache.hadoop.yarn.server.resourcemanager.rmcontainer.RMContainerImpl: container_1376157310799_0010_01_000024 Container Transitioned from RUNNING to COMPLETED
2013-08-10 18:12:31,080 INFO org.apache.hadoop.yarn.server.resourcemanager.scheduler.common.fica.FiCaSchedulerApp: Completed container: container_1376157310799_0010_01_000024 in state: COMPLETED event:FINISHED
2013-08-10 18:12:31,080 INFO org.apache.hadoop.yarn.server.resourcemanager.RMAuditLogger: USER=ubuntu	OPERATION=AM Released Container	TARGET=SchedulerApp	RESULT=SUCCESS	APPID=application_1376157310799_0010	CONTAINERID=container_1376157310799_0010_01_000024
2013-08-10 18:12:31,080 INFO org.apache.hadoop.yarn.server.resourcemanager.scheduler.common.fica.FiCaSchedulerNode: Released container container_1376157310799_0010_01_000024 of capacity <memory:1024, vCores:1> on host hadoop-221-3:38242, which currently has 6 containers, <memory:7168, vCores:6> used and <memory:1024, vCores:10> available, release resources=true
2013-08-10 18:12:31,081 INFO org.apache.hadoop.yarn.server.resourcemanager.scheduler.capacity.LeafQueue: default used=<memory:48128, vCores:42> numContainers=42 user=ubuntu user-resources=<memory:48128, vCores:42>
2013-08-10 18:12:31,082 INFO org.apache.hadoop.yarn.server.resourcemanager.scheduler.capacity.LeafQueue: completedContainer container=Container: [ContainerId: container_1376157310799_0010_01_000024, NodeId: hadoop-221-3:38242, NodeHttpAddress: hadoop-221-3:8042, Resource: <memory:1024, vCores:1>, Priority: 20, State: NEW, Token: null, Status: container_id {, app_attempt_id {, application_id {, id: 10, cluster_timestamp: 1376157310799, }, attemptId: 1, }, id: 24, }, state: C_COMPLETE, diagnostics: "Container killed by the ApplicationMaster.\n\n", exit_status: 143, ] resource=<memory:1024, vCores:1> queue=default: capacity=1.0, absoluteCapacity=1.0, usedResources=<memory:48128, vCores:42>usedCapacity=0.9791667, absoluteUsedCapacity=0.9791667, numApps=5, numContainers=42 usedCapacity=0.9791667 absoluteUsedCapacity=0.9791667 used=<memory:48128, vCores:42> cluster=<memory:49152, vCores:96>
2013-08-10 18:12:31,082 INFO org.apache.hadoop.yarn.server.resourcemanager.scheduler.capacity.ParentQueue: completedContainer queue=root usedCapacity=0.9791667 absoluteUsedCapacity=0.9791667 used=<memory:48128, vCores:42> cluster=<memory:49152, vCores:96>
2013-08-10 18:12:31,082 INFO org.apache.hadoop.yarn.server.resourcemanager.scheduler.capacity.CapacityScheduler: Application appattempt_1376157310799_0010_000001 released container container_1376157310799_0010_01_000024 on node: host: hadoop-221-3:38242 #containers=6 available=1024 used=7168 with event: FINISHED
2013-08-10 18:12:31,083 INFO org.apache.hadoop.yarn.server.resourcemanager.rmcontainer.RMContainerImpl: container_1376157310799_0006_01_000012 Container Transitioned from NEW to ALLOCATED
2013-08-10 18:12:31,083 INFO org.apache.hadoop.yarn.server.resourcemanager.RMAuditLogger: USER=ubuntu	OPERATION=AM Allocated Container	TARGET=SchedulerApp	RESULT=SUCCESS	APPID=application_1376157310799_0006	CONTAINERID=container_1376157310799_0006_01_000012
2013-08-10 18:12:31,083 INFO org.apache.hadoop.yarn.server.resourcemanager.scheduler.common.fica.FiCaSchedulerNode: Assigned container container_1376157310799_0006_01_000012 of capacity <memory:1024, vCores:1> on host hadoop-221-3:38242, which currently has 7 containers, <memory:8192, vCores:7> used and <memory:0, vCores:9> available
2013-08-10 18:12:31,088 INFO org.apache.hadoop.yarn.server.resourcemanager.scheduler.capacity.LeafQueue: assignedContainer application=application_1376157310799_0006 container=Container: [ContainerId: container_1376157310799_0006_01_000012, NodeId: hadoop-221-3:38242, NodeHttpAddress: hadoop-221-3:8042, Resource: <memory:1024, vCores:1>, Priority: 20, State: NEW, Token: null, Status: container_id {, app_attempt_id {, application_id {, id: 6, cluster_timestamp: 1376157310799, }, attemptId: 1, }, id: 12, }, state: C_NEW, ] containerId=container_1376157310799_0006_01_000012 queue=default: capacity=1.0, absoluteCapacity=1.0, usedResources=<memory:48128, vCores:42>usedCapacity=0.9791667, absoluteUsedCapacity=0.9791667, numApps=5, numContainers=42 usedCapacity=0.9791667 absoluteUsedCapacity=0.9791667 used=<memory:48128, vCores:42> cluster=<memory:49152, vCores:96>
2013-08-10 18:12:31,088 INFO org.apache.hadoop.yarn.server.resourcemanager.scheduler.capacity.ParentQueue: Re-sorting queues since queue: root.default stats: default: capacity=1.0, absoluteCapacity=1.0, usedResources=<memory:49152, vCores:43>usedCapacity=1.0, absoluteUsedCapacity=1.0, numApps=5, numContainers=43
2013-08-10 18:12:31,088 INFO org.apache.hadoop.yarn.server.resourcemanager.scheduler.capacity.ParentQueue: assignedContainer queue=root usedCapacity=1.0 absoluteUsedCapacity=1.0 used=<memory:49152, vCores:43> cluster=<memory:49152, vCores:96>
2013-08-10 18:12:31,540 INFO org.apache.hadoop.yarn.server.resourcemanager.rmcontainer.RMContainerImpl: container_1376157310799_0006_01_000011 Container Transitioned from ALLOCATED to ACQUIRED
2013-08-10 18:12:31,541 INFO org.apache.hadoop.yarn.server.resourcemanager.rmcontainer.RMContainerImpl: container_1376157310799_0006_01_000012 Container Transitioned from ALLOCATED to ACQUIRED
2013-08-10 18:12:31,634 INFO org.apache.hadoop.yarn.server.resourcemanager.rmcontainer.RMContainerImpl: container_1376157310799_0006_01_000011 Container Transitioned from ACQUIRED to RUNNING
2013-08-10 18:12:33,093 INFO org.apache.hadoop.yarn.server.resourcemanager.rmcontainer.RMContainerImpl: container_1376157310799_0006_01_000012 Container Transitioned from ACQUIRED to RUNNING
2013-08-10 18:12:33,093 INFO org.apache.hadoop.yarn.server.resourcemanager.rmcontainer.RMContainerImpl: container_1376157310799_0010_01_000020 Container Transitioned from RUNNING to COMPLETED
2013-08-10 18:12:33,094 INFO org.apache.hadoop.yarn.server.resourcemanager.scheduler.common.fica.FiCaSchedulerApp: Completed container: container_1376157310799_0010_01_000020 in state: COMPLETED event:FINISHED
2013-08-10 18:12:33,094 INFO org.apache.hadoop.yarn.server.resourcemanager.RMAuditLogger: USER=ubuntu	OPERATION=AM Released Container	TARGET=SchedulerApp	RESULT=SUCCESS	APPID=application_1376157310799_0010	CONTAINERID=container_1376157310799_0010_01_000020
2013-08-10 18:12:33,094 INFO org.apache.hadoop.yarn.server.resourcemanager.scheduler.common.fica.FiCaSchedulerNode: Released container container_1376157310799_0010_01_000020 of capacity <memory:1024, vCores:1> on host hadoop-221-3:38242, which currently has 6 containers, <memory:7168, vCores:6> used and <memory:1024, vCores:10> available, release resources=true
2013-08-10 18:12:33,094 INFO org.apache.hadoop.yarn.server.resourcemanager.scheduler.capacity.LeafQueue: default used=<memory:48128, vCores:42> numContainers=42 user=ubuntu user-resources=<memory:48128, vCores:42>
2013-08-10 18:12:33,095 INFO org.apache.hadoop.yarn.server.resourcemanager.scheduler.capacity.LeafQueue: completedContainer container=Container: [ContainerId: container_1376157310799_0010_01_000020, NodeId: hadoop-221-3:38242, NodeHttpAddress: hadoop-221-3:8042, Resource: <memory:1024, vCores:1>, Priority: 20, State: NEW, Token: null, Status: container_id {, app_attempt_id {, application_id {, id: 10, cluster_timestamp: 1376157310799, }, attemptId: 1, }, id: 20, }, state: C_COMPLETE, diagnostics: "Container killed by the ApplicationMaster.\n\n", exit_status: 143, ] resource=<memory:1024, vCores:1> queue=default: capacity=1.0, absoluteCapacity=1.0, usedResources=<memory:48128, vCores:42>usedCapacity=0.9791667, absoluteUsedCapacity=0.9791667, numApps=5, numContainers=42 usedCapacity=0.9791667 absoluteUsedCapacity=0.9791667 used=<memory:48128, vCores:42> cluster=<memory:49152, vCores:96>
2013-08-10 18:12:33,095 INFO org.apache.hadoop.yarn.server.resourcemanager.scheduler.capacity.ParentQueue: completedContainer queue=root usedCapacity=0.9791667 absoluteUsedCapacity=0.9791667 used=<memory:48128, vCores:42> cluster=<memory:49152, vCores:96>
2013-08-10 18:12:33,096 INFO org.apache.hadoop.yarn.server.resourcemanager.scheduler.capacity.CapacityScheduler: Application appattempt_1376157310799_0010_000001 released container container_1376157310799_0010_01_000020 on node: host: hadoop-221-3:38242 #containers=6 available=1024 used=7168 with event: FINISHED
2013-08-10 18:12:33,096 INFO org.apache.hadoop.yarn.server.resourcemanager.rmcontainer.RMContainerImpl: container_1376157310799_0006_01_000013 Container Transitioned from NEW to ALLOCATED
2013-08-10 18:12:33,096 INFO org.apache.hadoop.yarn.server.resourcemanager.RMAuditLogger: USER=ubuntu	OPERATION=AM Allocated Container	TARGET=SchedulerApp	RESULT=SUCCESS	APPID=application_1376157310799_0006	CONTAINERID=container_1376157310799_0006_01_000013
2013-08-10 18:12:33,097 INFO org.apache.hadoop.yarn.server.resourcemanager.scheduler.common.fica.FiCaSchedulerNode: Assigned container container_1376157310799_0006_01_000013 of capacity <memory:1024, vCores:1> on host hadoop-221-3:38242, which currently has 7 containers, <memory:8192, vCores:7> used and <memory:0, vCores:9> available
2013-08-10 18:12:33,097 INFO org.apache.hadoop.yarn.server.resourcemanager.scheduler.capacity.LeafQueue: assignedContainer application=application_1376157310799_0006 container=Container: [ContainerId: container_1376157310799_0006_01_000013, NodeId: hadoop-221-3:38242, NodeHttpAddress: hadoop-221-3:8042, Resource: <memory:1024, vCores:1>, Priority: 20, State: NEW, Token: null, Status: container_id {, app_attempt_id {, application_id {, id: 6, cluster_timestamp: 1376157310799, }, attemptId: 1, }, id: 13, }, state: C_NEW, ] containerId=container_1376157310799_0006_01_000013 queue=default: capacity=1.0, absoluteCapacity=1.0, usedResources=<memory:48128, vCores:42>usedCapacity=0.9791667, absoluteUsedCapacity=0.9791667, numApps=5, numContainers=42 usedCapacity=0.9791667 absoluteUsedCapacity=0.9791667 used=<memory:48128, vCores:42> cluster=<memory:49152, vCores:96>
2013-08-10 18:12:33,098 INFO org.apache.hadoop.yarn.server.resourcemanager.scheduler.capacity.ParentQueue: Re-sorting queues since queue: root.default stats: default: capacity=1.0, absoluteCapacity=1.0, usedResources=<memory:49152, vCores:43>usedCapacity=1.0, absoluteUsedCapacity=1.0, numApps=5, numContainers=43
2013-08-10 18:12:33,098 INFO org.apache.hadoop.yarn.server.resourcemanager.scheduler.capacity.ParentQueue: assignedContainer queue=root usedCapacity=1.0 absoluteUsedCapacity=1.0 used=<memory:49152, vCores:43> cluster=<memory:49152, vCores:96>
2013-08-10 18:12:33,322 INFO org.apache.hadoop.yarn.server.resourcemanager.rmcontainer.RMContainerImpl: container_1376157310799_0010_01_000008 Container Transitioned from RUNNING to COMPLETED
2013-08-10 18:12:33,322 INFO org.apache.hadoop.yarn.server.resourcemanager.scheduler.common.fica.FiCaSchedulerApp: Completed container: container_1376157310799_0010_01_000008 in state: COMPLETED event:FINISHED
2013-08-10 18:12:33,322 INFO org.apache.hadoop.yarn.server.resourcemanager.RMAuditLogger: USER=ubuntu	OPERATION=AM Released Container	TARGET=SchedulerApp	RESULT=SUCCESS	APPID=application_1376157310799_0010	CONTAINERID=container_1376157310799_0010_01_000008
2013-08-10 18:12:33,322 INFO org.apache.hadoop.yarn.server.resourcemanager.scheduler.common.fica.FiCaSchedulerNode: Released container container_1376157310799_0010_01_000008 of capacity <memory:1024, vCores:1> on host hadoop-221-7:56906, which currently has 6 containers, <memory:7168, vCores:6> used and <memory:1024, vCores:10> available, release resources=true
2013-08-10 18:12:33,322 INFO org.apache.hadoop.yarn.server.resourcemanager.scheduler.capacity.LeafQueue: default used=<memory:48128, vCores:42> numContainers=42 user=ubuntu user-resources=<memory:48128, vCores:42>
2013-08-10 18:12:33,323 INFO org.apache.hadoop.yarn.server.resourcemanager.scheduler.capacity.LeafQueue: completedContainer container=Container: [ContainerId: container_1376157310799_0010_01_000008, NodeId: hadoop-221-7:56906, NodeHttpAddress: hadoop-221-7:8042, Resource: <memory:1024, vCores:1>, Priority: 20, State: NEW, Token: null, Status: container_id {, app_attempt_id {, application_id {, id: 10, cluster_timestamp: 1376157310799, }, attemptId: 1, }, id: 8, }, state: C_COMPLETE, diagnostics: "", exit_status: 0, ] resource=<memory:1024, vCores:1> queue=default: capacity=1.0, absoluteCapacity=1.0, usedResources=<memory:48128, vCores:42>usedCapacity=0.9791667, absoluteUsedCapacity=0.9791667, numApps=5, numContainers=42 usedCapacity=0.9791667 absoluteUsedCapacity=0.9791667 used=<memory:48128, vCores:42> cluster=<memory:49152, vCores:96>
2013-08-10 18:12:33,323 INFO org.apache.hadoop.yarn.server.resourcemanager.scheduler.capacity.ParentQueue: completedContainer queue=root usedCapacity=0.9791667 absoluteUsedCapacity=0.9791667 used=<memory:48128, vCores:42> cluster=<memory:49152, vCores:96>
2013-08-10 18:12:33,324 INFO org.apache.hadoop.yarn.server.resourcemanager.scheduler.capacity.CapacityScheduler: Application appattempt_1376157310799_0010_000001 released container container_1376157310799_0010_01_000008 on node: host: hadoop-221-7:56906 #containers=6 available=1024 used=7168 with event: FINISHED
2013-08-10 18:12:33,324 INFO org.apache.hadoop.yarn.server.resourcemanager.rmcontainer.RMContainerImpl: container_1376157310799_0010_01_000009 Container Transitioned from RUNNING to COMPLETED
2013-08-10 18:12:33,324 INFO org.apache.hadoop.yarn.server.resourcemanager.scheduler.common.fica.FiCaSchedulerApp: Completed container: container_1376157310799_0010_01_000009 in state: COMPLETED event:FINISHED
2013-08-10 18:12:33,324 INFO org.apache.hadoop.yarn.server.resourcemanager.RMAuditLogger: USER=ubuntu	OPERATION=AM Released Container	TARGET=SchedulerApp	RESULT=SUCCESS	APPID=application_1376157310799_0010	CONTAINERID=container_1376157310799_0010_01_000009
2013-08-10 18:12:33,324 INFO org.apache.hadoop.yarn.server.resourcemanager.scheduler.common.fica.FiCaSchedulerNode: Released container container_1376157310799_0010_01_000009 of capacity <memory:1024, vCores:1> on host hadoop-221-7:56906, which currently has 5 containers, <memory:6144, vCores:5> used and <memory:2048, vCores:11> available, release resources=true
2013-08-10 18:12:33,325 INFO org.apache.hadoop.yarn.server.resourcemanager.scheduler.capacity.LeafQueue: default used=<memory:47104, vCores:41> numContainers=41 user=ubuntu user-resources=<memory:47104, vCores:41>
2013-08-10 18:12:33,326 INFO org.apache.hadoop.yarn.server.resourcemanager.scheduler.capacity.LeafQueue: completedContainer container=Container: [ContainerId: container_1376157310799_0010_01_000009, NodeId: hadoop-221-7:56906, NodeHttpAddress: hadoop-221-7:8042, Resource: <memory:1024, vCores:1>, Priority: 20, State: NEW, Token: null, Status: container_id {, app_attempt_id {, application_id {, id: 10, cluster_timestamp: 1376157310799, }, attemptId: 1, }, id: 9, }, state: C_COMPLETE, diagnostics: "Container killed by the ApplicationMaster.\n\n", exit_status: 143, ] resource=<memory:1024, vCores:1> queue=default: capacity=1.0, absoluteCapacity=1.0, usedResources=<memory:47104, vCores:41>usedCapacity=0.9583333, absoluteUsedCapacity=0.9583333, numApps=5, numContainers=41 usedCapacity=0.9583333 absoluteUsedCapacity=0.9583333 used=<memory:47104, vCores:41> cluster=<memory:49152, vCores:96>
2013-08-10 18:12:33,326 INFO org.apache.hadoop.yarn.server.resourcemanager.scheduler.capacity.ParentQueue: completedContainer queue=root usedCapacity=0.9583333 absoluteUsedCapacity=0.9583333 used=<memory:47104, vCores:41> cluster=<memory:49152, vCores:96>
2013-08-10 18:12:33,326 INFO org.apache.hadoop.yarn.server.resourcemanager.scheduler.capacity.CapacityScheduler: Application appattempt_1376157310799_0010_000001 released container container_1376157310799_0010_01_000009 on node: host: hadoop-221-7:56906 #containers=5 available=2048 used=6144 with event: FINISHED
2013-08-10 18:12:33,326 INFO org.apache.hadoop.yarn.server.resourcemanager.rmcontainer.RMContainerImpl: container_1376157310799_0010_01_000013 Container Transitioned from RUNNING to COMPLETED
2013-08-10 18:12:33,326 INFO org.apache.hadoop.yarn.server.resourcemanager.scheduler.common.fica.FiCaSchedulerApp: Completed container: container_1376157310799_0010_01_000013 in state: COMPLETED event:FINISHED
2013-08-10 18:12:33,327 INFO org.apache.hadoop.yarn.server.resourcemanager.RMAuditLogger: USER=ubuntu	OPERATION=AM Released Container	TARGET=SchedulerApp	RESULT=SUCCESS	APPID=application_1376157310799_0010	CONTAINERID=container_1376157310799_0010_01_000013
2013-08-10 18:12:33,327 INFO org.apache.hadoop.yarn.server.resourcemanager.scheduler.common.fica.FiCaSchedulerNode: Released container container_1376157310799_0010_01_000013 of capacity <memory:1024, vCores:1> on host hadoop-221-7:56906, which currently has 4 containers, <memory:5120, vCores:4> used and <memory:3072, vCores:12> available, release resources=true
2013-08-10 18:12:33,327 INFO org.apache.hadoop.yarn.server.resourcemanager.scheduler.capacity.LeafQueue: default used=<memory:46080, vCores:40> numContainers=40 user=ubuntu user-resources=<memory:46080, vCores:40>
2013-08-10 18:12:33,328 INFO org.apache.hadoop.yarn.server.resourcemanager.scheduler.capacity.LeafQueue: completedContainer container=Container: [ContainerId: container_1376157310799_0010_01_000013, NodeId: hadoop-221-7:56906, NodeHttpAddress: hadoop-221-7:8042, Resource: <memory:1024, vCores:1>, Priority: 20, State: NEW, Token: null, Status: container_id {, app_attempt_id {, application_id {, id: 10, cluster_timestamp: 1376157310799, }, attemptId: 1, }, id: 13, }, state: C_COMPLETE, diagnostics: "", exit_status: 0, ] resource=<memory:1024, vCores:1> queue=default: capacity=1.0, absoluteCapacity=1.0, usedResources=<memory:46080, vCores:40>usedCapacity=0.9375, absoluteUsedCapacity=0.9375, numApps=5, numContainers=40 usedCapacity=0.9375 absoluteUsedCapacity=0.9375 used=<memory:46080, vCores:40> cluster=<memory:49152, vCores:96>
2013-08-10 18:12:33,328 INFO org.apache.hadoop.yarn.server.resourcemanager.scheduler.capacity.ParentQueue: completedContainer queue=root usedCapacity=0.9375 absoluteUsedCapacity=0.9375 used=<memory:46080, vCores:40> cluster=<memory:49152, vCores:96>
2013-08-10 18:12:33,328 INFO org.apache.hadoop.yarn.server.resourcemanager.scheduler.capacity.CapacityScheduler: Application appattempt_1376157310799_0010_000001 released container container_1376157310799_0010_01_000013 on node: host: hadoop-221-7:56906 #containers=4 available=3072 used=5120 with event: FINISHED
2013-08-10 18:12:33,329 INFO org.apache.hadoop.yarn.server.resourcemanager.rmcontainer.RMContainerImpl: container_1376157310799_0006_01_000014 Container Transitioned from NEW to ALLOCATED
2013-08-10 18:12:33,329 INFO org.apache.hadoop.yarn.server.resourcemanager.RMAuditLogger: USER=ubuntu	OPERATION=AM Allocated Container	TARGET=SchedulerApp	RESULT=SUCCESS	APPID=application_1376157310799_0006	CONTAINERID=container_1376157310799_0006_01_000014
2013-08-10 18:12:33,329 INFO org.apache.hadoop.yarn.server.resourcemanager.scheduler.common.fica.FiCaSchedulerNode: Assigned container container_1376157310799_0006_01_000014 of capacity <memory:1024, vCores:1> on host hadoop-221-7:56906, which currently has 5 containers, <memory:6144, vCores:5> used and <memory:2048, vCores:11> available
2013-08-10 18:12:33,330 INFO org.apache.hadoop.yarn.server.resourcemanager.scheduler.capacity.LeafQueue: assignedContainer application=application_1376157310799_0006 container=Container: [ContainerId: container_1376157310799_0006_01_000014, NodeId: hadoop-221-7:56906, NodeHttpAddress: hadoop-221-7:8042, Resource: <memory:1024, vCores:1>, Priority: 20, State: NEW, Token: null, Status: container_id {, app_attempt_id {, application_id {, id: 6, cluster_timestamp: 1376157310799, }, attemptId: 1, }, id: 14, }, state: C_NEW, ] containerId=container_1376157310799_0006_01_000014 queue=default: capacity=1.0, absoluteCapacity=1.0, usedResources=<memory:46080, vCores:40>usedCapacity=0.9375, absoluteUsedCapacity=0.9375, numApps=5, numContainers=40 usedCapacity=0.9375 absoluteUsedCapacity=0.9375 used=<memory:46080, vCores:40> cluster=<memory:49152, vCores:96>
2013-08-10 18:12:33,330 INFO org.apache.hadoop.yarn.server.resourcemanager.scheduler.capacity.ParentQueue: Re-sorting queues since queue: root.default stats: default: capacity=1.0, absoluteCapacity=1.0, usedResources=<memory:47104, vCores:41>usedCapacity=0.9583333, absoluteUsedCapacity=0.9583333, numApps=5, numContainers=41
2013-08-10 18:12:33,331 INFO org.apache.hadoop.yarn.server.resourcemanager.scheduler.capacity.ParentQueue: assignedContainer queue=root usedCapacity=0.9583333 absoluteUsedCapacity=0.9583333 used=<memory:47104, vCores:41> cluster=<memory:49152, vCores:96>
2013-08-10 18:12:33,331 INFO org.apache.hadoop.yarn.server.resourcemanager.rmcontainer.RMContainerImpl: container_1376157310799_0006_01_000015 Container Transitioned from NEW to ALLOCATED
2013-08-10 18:12:33,331 INFO org.apache.hadoop.yarn.server.resourcemanager.RMAuditLogger: USER=ubuntu	OPERATION=AM Allocated Container	TARGET=SchedulerApp	RESULT=SUCCESS	APPID=application_1376157310799_0006	CONTAINERID=container_1376157310799_0006_01_000015
2013-08-10 18:12:33,331 INFO org.apache.hadoop.yarn.server.resourcemanager.scheduler.common.fica.FiCaSchedulerNode: Assigned container container_1376157310799_0006_01_000015 of capacity <memory:1024, vCores:1> on host hadoop-221-7:56906, which currently has 6 containers, <memory:7168, vCores:6> used and <memory:1024, vCores:10> available
2013-08-10 18:12:33,332 INFO org.apache.hadoop.yarn.server.resourcemanager.scheduler.capacity.LeafQueue: assignedContainer application=application_1376157310799_0006 container=Container: [ContainerId: container_1376157310799_0006_01_000015, NodeId: hadoop-221-7:56906, NodeHttpAddress: hadoop-221-7:8042, Resource: <memory:1024, vCores:1>, Priority: 20, State: NEW, Token: null, Status: container_id {, app_attempt_id {, application_id {, id: 6, cluster_timestamp: 1376157310799, }, attemptId: 1, }, id: 15, }, state: C_NEW, ] containerId=container_1376157310799_0006_01_000015 queue=default: capacity=1.0, absoluteCapacity=1.0, usedResources=<memory:47104, vCores:41>usedCapacity=0.9583333, absoluteUsedCapacity=0.9583333, numApps=5, numContainers=41 usedCapacity=0.9583333 absoluteUsedCapacity=0.9583333 used=<memory:47104, vCores:41> cluster=<memory:49152, vCores:96>
2013-08-10 18:12:33,333 INFO org.apache.hadoop.yarn.server.resourcemanager.scheduler.capacity.ParentQueue: Re-sorting queues since queue: root.default stats: default: capacity=1.0, absoluteCapacity=1.0, usedResources=<memory:48128, vCores:42>usedCapacity=0.9791667, absoluteUsedCapacity=0.9791667, numApps=5, numContainers=42
2013-08-10 18:12:33,333 INFO org.apache.hadoop.yarn.server.resourcemanager.scheduler.capacity.ParentQueue: assignedContainer queue=root usedCapacity=0.9791667 absoluteUsedCapacity=0.9791667 used=<memory:48128, vCores:42> cluster=<memory:49152, vCores:96>
2013-08-10 18:12:33,333 INFO org.apache.hadoop.yarn.server.resourcemanager.rmcontainer.RMContainerImpl: container_1376157310799_0006_01_000016 Container Transitioned from NEW to ALLOCATED
2013-08-10 18:12:33,333 INFO org.apache.hadoop.yarn.server.resourcemanager.RMAuditLogger: USER=ubuntu	OPERATION=AM Allocated Container	TARGET=SchedulerApp	RESULT=SUCCESS	APPID=application_1376157310799_0006	CONTAINERID=container_1376157310799_0006_01_000016
2013-08-10 18:12:33,333 INFO org.apache.hadoop.yarn.server.resourcemanager.scheduler.common.fica.FiCaSchedulerNode: Assigned container container_1376157310799_0006_01_000016 of capacity <memory:1024, vCores:1> on host hadoop-221-7:56906, which currently has 7 containers, <memory:8192, vCores:7> used and <memory:0, vCores:9> available
2013-08-10 18:12:33,334 INFO org.apache.hadoop.yarn.server.resourcemanager.scheduler.capacity.LeafQueue: assignedContainer application=application_1376157310799_0006 container=Container: [ContainerId: container_1376157310799_0006_01_000016, NodeId: hadoop-221-7:56906, NodeHttpAddress: hadoop-221-7:8042, Resource: <memory:1024, vCores:1>, Priority: 20, State: NEW, Token: null, Status: container_id {, app_attempt_id {, application_id {, id: 6, cluster_timestamp: 1376157310799, }, attemptId: 1, }, id: 16, }, state: C_NEW, ] containerId=container_1376157310799_0006_01_000016 queue=default: capacity=1.0, absoluteCapacity=1.0, usedResources=<memory:48128, vCores:42>usedCapacity=0.9791667, absoluteUsedCapacity=0.9791667, numApps=5, numContainers=42 usedCapacity=0.9791667 absoluteUsedCapacity=0.9791667 used=<memory:48128, vCores:42> cluster=<memory:49152, vCores:96>
2013-08-10 18:12:33,335 INFO org.apache.hadoop.yarn.server.resourcemanager.scheduler.capacity.ParentQueue: Re-sorting queues since queue: root.default stats: default: capacity=1.0, absoluteCapacity=1.0, usedResources=<memory:49152, vCores:43>usedCapacity=1.0, absoluteUsedCapacity=1.0, numApps=5, numContainers=43
2013-08-10 18:12:33,335 INFO org.apache.hadoop.yarn.server.resourcemanager.scheduler.capacity.ParentQueue: assignedContainer queue=root usedCapacity=1.0 absoluteUsedCapacity=1.0 used=<memory:49152, vCores:43> cluster=<memory:49152, vCores:96>
2013-08-10 18:12:33,550 INFO org.apache.hadoop.yarn.server.resourcemanager.rmcontainer.RMContainerImpl: container_1376157310799_0006_01_000013 Container Transitioned from ALLOCATED to ACQUIRED
2013-08-10 18:12:33,551 INFO org.apache.hadoop.yarn.server.resourcemanager.rmcontainer.RMContainerImpl: container_1376157310799_0006_01_000014 Container Transitioned from ALLOCATED to ACQUIRED
2013-08-10 18:12:33,551 INFO org.apache.hadoop.yarn.server.resourcemanager.rmcontainer.RMContainerImpl: container_1376157310799_0006_01_000015 Container Transitioned from ALLOCATED to ACQUIRED
2013-08-10 18:12:33,551 INFO org.apache.hadoop.yarn.server.resourcemanager.rmcontainer.RMContainerImpl: container_1376157310799_0006_01_000016 Container Transitioned from ALLOCATED to ACQUIRED
2013-08-10 18:12:34,105 INFO org.apache.hadoop.yarn.server.resourcemanager.rmcontainer.RMContainerImpl: container_1376157310799_0006_01_000013 Container Transitioned from ACQUIRED to RUNNING
2013-08-10 18:12:34,337 INFO org.apache.hadoop.yarn.server.resourcemanager.rmcontainer.RMContainerImpl: container_1376157310799_0006_01_000014 Container Transitioned from ACQUIRED to RUNNING
2013-08-10 18:12:34,337 INFO org.apache.hadoop.yarn.server.resourcemanager.rmcontainer.RMContainerImpl: container_1376157310799_0006_01_000015 Container Transitioned from ACQUIRED to RUNNING
2013-08-10 18:12:34,338 INFO org.apache.hadoop.yarn.server.resourcemanager.rmcontainer.RMContainerImpl: container_1376157310799_0006_01_000016 Container Transitioned from ACQUIRED to RUNNING
2013-08-10 18:12:34,668 INFO org.apache.hadoop.yarn.server.resourcemanager.rmcontainer.RMContainerImpl: container_1376157310799_0010_01_000018 Container Transitioned from RUNNING to COMPLETED
2013-08-10 18:12:34,669 INFO org.apache.hadoop.yarn.server.resourcemanager.scheduler.common.fica.FiCaSchedulerApp: Completed container: container_1376157310799_0010_01_000018 in state: COMPLETED event:FINISHED
2013-08-10 18:12:34,669 INFO org.apache.hadoop.yarn.server.resourcemanager.RMAuditLogger: USER=ubuntu	OPERATION=AM Released Container	TARGET=SchedulerApp	RESULT=SUCCESS	APPID=application_1376157310799_0010	CONTAINERID=container_1376157310799_0010_01_000018
2013-08-10 18:12:34,669 INFO org.apache.hadoop.yarn.server.resourcemanager.scheduler.common.fica.FiCaSchedulerNode: Released container container_1376157310799_0010_01_000018 of capacity <memory:1024, vCores:1> on host hadoop-221-5:56475, which currently has 6 containers, <memory:7168, vCores:6> used and <memory:1024, vCores:10> available, release resources=true
2013-08-10 18:12:34,669 INFO org.apache.hadoop.yarn.server.resourcemanager.scheduler.capacity.LeafQueue: default used=<memory:48128, vCores:42> numContainers=42 user=ubuntu user-resources=<memory:48128, vCores:42>
2013-08-10 18:12:34,670 INFO org.apache.hadoop.yarn.server.resourcemanager.scheduler.capacity.LeafQueue: completedContainer container=Container: [ContainerId: container_1376157310799_0010_01_000018, NodeId: hadoop-221-5:56475, NodeHttpAddress: hadoop-221-5:8042, Resource: <memory:1024, vCores:1>, Priority: 20, State: NEW, Token: null, Status: container_id {, app_attempt_id {, application_id {, id: 10, cluster_timestamp: 1376157310799, }, attemptId: 1, }, id: 18, }, state: C_COMPLETE, diagnostics: "", exit_status: 0, ] resource=<memory:1024, vCores:1> queue=default: capacity=1.0, absoluteCapacity=1.0, usedResources=<memory:48128, vCores:42>usedCapacity=0.9791667, absoluteUsedCapacity=0.9791667, numApps=5, numContainers=42 usedCapacity=0.9791667 absoluteUsedCapacity=0.9791667 used=<memory:48128, vCores:42> cluster=<memory:49152, vCores:96>
2013-08-10 18:12:34,671 INFO org.apache.hadoop.yarn.server.resourcemanager.scheduler.capacity.ParentQueue: completedContainer queue=root usedCapacity=0.9791667 absoluteUsedCapacity=0.9791667 used=<memory:48128, vCores:42> cluster=<memory:49152, vCores:96>
2013-08-10 18:12:34,671 INFO org.apache.hadoop.yarn.server.resourcemanager.scheduler.capacity.CapacityScheduler: Application appattempt_1376157310799_0010_000001 released container container_1376157310799_0010_01_000018 on node: host: hadoop-221-5:56475 #containers=6 available=1024 used=7168 with event: FINISHED
2013-08-10 18:12:34,671 INFO org.apache.hadoop.yarn.server.resourcemanager.rmcontainer.RMContainerImpl: container_1376157310799_0006_01_000017 Container Transitioned from NEW to ALLOCATED
2013-08-10 18:12:34,671 INFO org.apache.hadoop.yarn.server.resourcemanager.RMAuditLogger: USER=ubuntu	OPERATION=AM Allocated Container	TARGET=SchedulerApp	RESULT=SUCCESS	APPID=application_1376157310799_0006	CONTAINERID=container_1376157310799_0006_01_000017
2013-08-10 18:12:34,672 INFO org.apache.hadoop.yarn.server.resourcemanager.scheduler.common.fica.FiCaSchedulerNode: Assigned container container_1376157310799_0006_01_000017 of capacity <memory:1024, vCores:1> on host hadoop-221-5:56475, which currently has 7 containers, <memory:8192, vCores:7> used and <memory:0, vCores:9> available
2013-08-10 18:12:34,673 INFO org.apache.hadoop.yarn.server.resourcemanager.scheduler.capacity.LeafQueue: assignedContainer application=application_1376157310799_0006 container=Container: [ContainerId: container_1376157310799_0006_01_000017, NodeId: hadoop-221-5:56475, NodeHttpAddress: hadoop-221-5:8042, Resource: <memory:1024, vCores:1>, Priority: 20, State: NEW, Token: null, Status: container_id {, app_attempt_id {, application_id {, id: 6, cluster_timestamp: 1376157310799, }, attemptId: 1, }, id: 17, }, state: C_NEW, ] containerId=container_1376157310799_0006_01_000017 queue=default: capacity=1.0, absoluteCapacity=1.0, usedResources=<memory:48128, vCores:42>usedCapacity=0.9791667, absoluteUsedCapacity=0.9791667, numApps=5, numContainers=42 usedCapacity=0.9791667 absoluteUsedCapacity=0.9791667 used=<memory:48128, vCores:42> cluster=<memory:49152, vCores:96>
2013-08-10 18:12:34,673 INFO org.apache.hadoop.yarn.server.resourcemanager.scheduler.capacity.ParentQueue: Re-sorting queues since queue: root.default stats: default: capacity=1.0, absoluteCapacity=1.0, usedResources=<memory:49152, vCores:43>usedCapacity=1.0, absoluteUsedCapacity=1.0, numApps=5, numContainers=43
2013-08-10 18:12:34,673 INFO org.apache.hadoop.yarn.server.resourcemanager.scheduler.capacity.ParentQueue: assignedContainer queue=root usedCapacity=1.0 absoluteUsedCapacity=1.0 used=<memory:49152, vCores:43> cluster=<memory:49152, vCores:96>
2013-08-10 18:12:34,984 INFO org.apache.hadoop.yarn.server.resourcemanager.rmcontainer.RMContainerImpl: container_1376157310799_0010_01_000028 Container Transitioned from RUNNING to COMPLETED
2013-08-10 18:12:34,984 INFO org.apache.hadoop.yarn.server.resourcemanager.scheduler.common.fica.FiCaSchedulerApp: Completed container: container_1376157310799_0010_01_000028 in state: COMPLETED event:FINISHED
2013-08-10 18:12:34,985 INFO org.apache.hadoop.yarn.server.resourcemanager.RMAuditLogger: USER=ubuntu	OPERATION=AM Released Container	TARGET=SchedulerApp	RESULT=SUCCESS	APPID=application_1376157310799_0010	CONTAINERID=container_1376157310799_0010_01_000028
2013-08-10 18:12:34,985 INFO org.apache.hadoop.yarn.server.resourcemanager.scheduler.common.fica.FiCaSchedulerNode: Released container container_1376157310799_0010_01_000028 of capacity <memory:1024, vCores:1> on host hadoop-221-4:33277, which currently has 6 containers, <memory:7168, vCores:6> used and <memory:1024, vCores:10> available, release resources=true
2013-08-10 18:12:34,985 INFO org.apache.hadoop.yarn.server.resourcemanager.scheduler.capacity.LeafQueue: default used=<memory:48128, vCores:42> numContainers=42 user=ubuntu user-resources=<memory:48128, vCores:42>
2013-08-10 18:12:34,986 INFO org.apache.hadoop.yarn.server.resourcemanager.scheduler.capacity.LeafQueue: completedContainer container=Container: [ContainerId: container_1376157310799_0010_01_000028, NodeId: hadoop-221-4:33277, NodeHttpAddress: hadoop-221-4:8042, Resource: <memory:1024, vCores:1>, Priority: 20, State: NEW, Token: null, Status: container_id {, app_attempt_id {, application_id {, id: 10, cluster_timestamp: 1376157310799, }, attemptId: 1, }, id: 28, }, state: C_COMPLETE, diagnostics: "", exit_status: 0, ] resource=<memory:1024, vCores:1> queue=default: capacity=1.0, absoluteCapacity=1.0, usedResources=<memory:48128, vCores:42>usedCapacity=0.9791667, absoluteUsedCapacity=0.9791667, numApps=5, numContainers=42 usedCapacity=0.9791667 absoluteUsedCapacity=0.9791667 used=<memory:48128, vCores:42> cluster=<memory:49152, vCores:96>
2013-08-10 18:12:34,986 INFO org.apache.hadoop.yarn.server.resourcemanager.scheduler.capacity.ParentQueue: completedContainer queue=root usedCapacity=0.9791667 absoluteUsedCapacity=0.9791667 used=<memory:48128, vCores:42> cluster=<memory:49152, vCores:96>
2013-08-10 18:12:34,986 INFO org.apache.hadoop.yarn.server.resourcemanager.scheduler.capacity.CapacityScheduler: Application appattempt_1376157310799_0010_000001 released container container_1376157310799_0010_01_000028 on node: host: hadoop-221-4:33277 #containers=6 available=1024 used=7168 with event: FINISHED
2013-08-10 18:12:34,987 INFO org.apache.hadoop.yarn.server.resourcemanager.rmcontainer.RMContainerImpl: container_1376157310799_0010_01_000030 Container Transitioned from RUNNING to COMPLETED
2013-08-10 18:12:34,987 INFO org.apache.hadoop.yarn.server.resourcemanager.scheduler.common.fica.FiCaSchedulerApp: Completed container: container_1376157310799_0010_01_000030 in state: COMPLETED event:FINISHED
2013-08-10 18:12:34,987 INFO org.apache.hadoop.yarn.server.resourcemanager.RMAuditLogger: USER=ubuntu	OPERATION=AM Released Container	TARGET=SchedulerApp	RESULT=SUCCESS	APPID=application_1376157310799_0010	CONTAINERID=container_1376157310799_0010_01_000030
2013-08-10 18:12:34,987 INFO org.apache.hadoop.yarn.server.resourcemanager.scheduler.common.fica.FiCaSchedulerNode: Released container container_1376157310799_0010_01_000030 of capacity <memory:1024, vCores:1> on host hadoop-221-4:33277, which currently has 5 containers, <memory:6144, vCores:5> used and <memory:2048, vCores:11> available, release resources=true
2013-08-10 18:12:34,987 INFO org.apache.hadoop.yarn.server.resourcemanager.scheduler.capacity.LeafQueue: default used=<memory:47104, vCores:41> numContainers=41 user=ubuntu user-resources=<memory:47104, vCores:41>
2013-08-10 18:12:34,988 INFO org.apache.hadoop.yarn.server.resourcemanager.scheduler.capacity.LeafQueue: completedContainer container=Container: [ContainerId: container_1376157310799_0010_01_000030, NodeId: hadoop-221-4:33277, NodeHttpAddress: hadoop-221-4:8042, Resource: <memory:1024, vCores:1>, Priority: 20, State: NEW, Token: null, Status: container_id {, app_attempt_id {, application_id {, id: 10, cluster_timestamp: 1376157310799, }, attemptId: 1, }, id: 30, }, state: C_COMPLETE, diagnostics: "", exit_status: 0, ] resource=<memory:1024, vCores:1> queue=default: capacity=1.0, absoluteCapacity=1.0, usedResources=<memory:47104, vCores:41>usedCapacity=0.9583333, absoluteUsedCapacity=0.9583333, numApps=5, numContainers=41 usedCapacity=0.9583333 absoluteUsedCapacity=0.9583333 used=<memory:47104, vCores:41> cluster=<memory:49152, vCores:96>
2013-08-10 18:12:34,988 INFO org.apache.hadoop.yarn.server.resourcemanager.scheduler.capacity.ParentQueue: completedContainer queue=root usedCapacity=0.9583333 absoluteUsedCapacity=0.9583333 used=<memory:47104, vCores:41> cluster=<memory:49152, vCores:96>
2013-08-10 18:12:34,989 INFO org.apache.hadoop.yarn.server.resourcemanager.scheduler.capacity.CapacityScheduler: Application appattempt_1376157310799_0010_000001 released container container_1376157310799_0010_01_000030 on node: host: hadoop-221-4:33277 #containers=5 available=2048 used=6144 with event: FINISHED
2013-08-10 18:12:34,989 INFO org.apache.hadoop.yarn.server.resourcemanager.rmcontainer.RMContainerImpl: container_1376157310799_0006_01_000018 Container Transitioned from NEW to ALLOCATED
2013-08-10 18:12:34,989 INFO org.apache.hadoop.yarn.server.resourcemanager.RMAuditLogger: USER=ubuntu	OPERATION=AM Allocated Container	TARGET=SchedulerApp	RESULT=SUCCESS	APPID=application_1376157310799_0006	CONTAINERID=container_1376157310799_0006_01_000018
2013-08-10 18:12:34,990 INFO org.apache.hadoop.yarn.server.resourcemanager.scheduler.common.fica.FiCaSchedulerNode: Assigned container container_1376157310799_0006_01_000018 of capacity <memory:1024, vCores:1> on host hadoop-221-4:33277, which currently has 6 containers, <memory:7168, vCores:6> used and <memory:1024, vCores:10> available
2013-08-10 18:12:34,990 INFO org.apache.hadoop.yarn.server.resourcemanager.scheduler.capacity.LeafQueue: assignedContainer application=application_1376157310799_0006 container=Container: [ContainerId: container_1376157310799_0006_01_000018, NodeId: hadoop-221-4:33277, NodeHttpAddress: hadoop-221-4:8042, Resource: <memory:1024, vCores:1>, Priority: 20, State: NEW, Token: null, Status: container_id {, app_attempt_id {, application_id {, id: 6, cluster_timestamp: 1376157310799, }, attemptId: 1, }, id: 18, }, state: C_NEW, ] containerId=container_1376157310799_0006_01_000018 queue=default: capacity=1.0, absoluteCapacity=1.0, usedResources=<memory:47104, vCores:41>usedCapacity=0.9583333, absoluteUsedCapacity=0.9583333, numApps=5, numContainers=41 usedCapacity=0.9583333 absoluteUsedCapacity=0.9583333 used=<memory:47104, vCores:41> cluster=<memory:49152, vCores:96>
2013-08-10 18:12:34,991 INFO org.apache.hadoop.yarn.server.resourcemanager.scheduler.capacity.ParentQueue: Re-sorting queues since queue: root.default stats: default: capacity=1.0, absoluteCapacity=1.0, usedResources=<memory:48128, vCores:42>usedCapacity=0.9791667, absoluteUsedCapacity=0.9791667, numApps=5, numContainers=42
2013-08-10 18:12:34,991 INFO org.apache.hadoop.yarn.server.resourcemanager.scheduler.capacity.ParentQueue: assignedContainer queue=root usedCapacity=0.9791667 absoluteUsedCapacity=0.9791667 used=<memory:48128, vCores:42> cluster=<memory:49152, vCores:96>
2013-08-10 18:12:34,991 INFO org.apache.hadoop.yarn.server.resourcemanager.rmcontainer.RMContainerImpl: container_1376157310799_0006_01_000019 Container Transitioned from NEW to ALLOCATED
2013-08-10 18:12:34,992 INFO org.apache.hadoop.yarn.server.resourcemanager.RMAuditLogger: USER=ubuntu	OPERATION=AM Allocated Container	TARGET=SchedulerApp	RESULT=SUCCESS	APPID=application_1376157310799_0006	CONTAINERID=container_1376157310799_0006_01_000019
2013-08-10 18:12:34,992 INFO org.apache.hadoop.yarn.server.resourcemanager.scheduler.common.fica.FiCaSchedulerNode: Assigned container container_1376157310799_0006_01_000019 of capacity <memory:1024, vCores:1> on host hadoop-221-4:33277, which currently has 7 containers, <memory:8192, vCores:7> used and <memory:0, vCores:9> available
2013-08-10 18:12:34,993 INFO org.apache.hadoop.yarn.server.resourcemanager.scheduler.capacity.LeafQueue: assignedContainer application=application_1376157310799_0006 container=Container: [ContainerId: container_1376157310799_0006_01_000019, NodeId: hadoop-221-4:33277, NodeHttpAddress: hadoop-221-4:8042, Resource: <memory:1024, vCores:1>, Priority: 20, State: NEW, Token: null, Status: container_id {, app_attempt_id {, application_id {, id: 6, cluster_timestamp: 1376157310799, }, attemptId: 1, }, id: 19, }, state: C_NEW, ] containerId=container_1376157310799_0006_01_000019 queue=default: capacity=1.0, absoluteCapacity=1.0, usedResources=<memory:48128, vCores:42>usedCapacity=0.9791667, absoluteUsedCapacity=0.9791667, numApps=5, numContainers=42 usedCapacity=0.9791667 absoluteUsedCapacity=0.9791667 used=<memory:48128, vCores:42> cluster=<memory:49152, vCores:96>
2013-08-10 18:12:34,993 INFO org.apache.hadoop.yarn.server.resourcemanager.scheduler.capacity.ParentQueue: Re-sorting queues since queue: root.default stats: default: capacity=1.0, absoluteCapacity=1.0, usedResources=<memory:49152, vCores:43>usedCapacity=1.0, absoluteUsedCapacity=1.0, numApps=5, numContainers=43
2013-08-10 18:12:34,993 INFO org.apache.hadoop.yarn.server.resourcemanager.scheduler.capacity.ParentQueue: assignedContainer queue=root usedCapacity=1.0 absoluteUsedCapacity=1.0 used=<memory:49152, vCores:43> cluster=<memory:49152, vCores:96>
2013-08-10 18:12:35,568 INFO org.apache.hadoop.yarn.server.resourcemanager.rmcontainer.RMContainerImpl: container_1376157310799_0006_01_000017 Container Transitioned from ALLOCATED to ACQUIRED
2013-08-10 18:12:35,570 INFO org.apache.hadoop.yarn.server.resourcemanager.rmcontainer.RMContainerImpl: container_1376157310799_0006_01_000018 Container Transitioned from ALLOCATED to ACQUIRED
2013-08-10 18:12:35,570 INFO org.apache.hadoop.yarn.server.resourcemanager.rmcontainer.RMContainerImpl: container_1376157310799_0006_01_000019 Container Transitioned from ALLOCATED to ACQUIRED
2013-08-10 18:12:35,842 INFO org.apache.hadoop.yarn.server.resourcemanager.rmcontainer.RMContainerImpl: container_1376157310799_0010_01_000019 Container Transitioned from RUNNING to COMPLETED
2013-08-10 18:12:35,842 INFO org.apache.hadoop.yarn.server.resourcemanager.scheduler.common.fica.FiCaSchedulerApp: Completed container: container_1376157310799_0010_01_000019 in state: COMPLETED event:FINISHED
2013-08-10 18:12:35,842 INFO org.apache.hadoop.yarn.server.resourcemanager.RMAuditLogger: USER=ubuntu	OPERATION=AM Released Container	TARGET=SchedulerApp	RESULT=SUCCESS	APPID=application_1376157310799_0010	CONTAINERID=container_1376157310799_0010_01_000019
2013-08-10 18:12:35,842 INFO org.apache.hadoop.yarn.server.resourcemanager.scheduler.common.fica.FiCaSchedulerNode: Released container container_1376157310799_0010_01_000019 of capacity <memory:1024, vCores:1> on host hadoop-221-5:56475, which currently has 6 containers, <memory:7168, vCores:6> used and <memory:1024, vCores:10> available, release resources=true
2013-08-10 18:12:35,842 INFO org.apache.hadoop.yarn.server.resourcemanager.scheduler.capacity.LeafQueue: default used=<memory:48128, vCores:42> numContainers=42 user=ubuntu user-resources=<memory:48128, vCores:42>
2013-08-10 18:12:35,844 INFO org.apache.hadoop.yarn.server.resourcemanager.scheduler.capacity.LeafQueue: completedContainer container=Container: [ContainerId: container_1376157310799_0010_01_000019, NodeId: hadoop-221-5:56475, NodeHttpAddress: hadoop-221-5:8042, Resource: <memory:1024, vCores:1>, Priority: 20, State: NEW, Token: null, Status: container_id {, app_attempt_id {, application_id {, id: 10, cluster_timestamp: 1376157310799, }, attemptId: 1, }, id: 19, }, state: C_COMPLETE, diagnostics: "", exit_status: 0, ] resource=<memory:1024, vCores:1> queue=default: capacity=1.0, absoluteCapacity=1.0, usedResources=<memory:48128, vCores:42>usedCapacity=0.9791667, absoluteUsedCapacity=0.9791667, numApps=5, numContainers=42 usedCapacity=0.9791667 absoluteUsedCapacity=0.9791667 used=<memory:48128, vCores:42> cluster=<memory:49152, vCores:96>
2013-08-10 18:12:35,844 INFO org.apache.hadoop.yarn.server.resourcemanager.scheduler.capacity.ParentQueue: completedContainer queue=root usedCapacity=0.9791667 absoluteUsedCapacity=0.9791667 used=<memory:48128, vCores:42> cluster=<memory:49152, vCores:96>
2013-08-10 18:12:35,844 INFO org.apache.hadoop.yarn.server.resourcemanager.scheduler.capacity.CapacityScheduler: Application appattempt_1376157310799_0010_000001 released container container_1376157310799_0010_01_000019 on node: host: hadoop-221-5:56475 #containers=6 available=1024 used=7168 with event: FINISHED
2013-08-10 18:12:35,845 INFO org.apache.hadoop.yarn.server.resourcemanager.rmcontainer.RMContainerImpl: container_1376157310799_0006_01_000020 Container Transitioned from NEW to ALLOCATED
2013-08-10 18:12:35,845 INFO org.apache.hadoop.yarn.server.resourcemanager.RMAuditLogger: USER=ubuntu	OPERATION=AM Allocated Container	TARGET=SchedulerApp	RESULT=SUCCESS	APPID=application_1376157310799_0006	CONTAINERID=container_1376157310799_0006_01_000020
2013-08-10 18:12:35,845 INFO org.apache.hadoop.yarn.server.resourcemanager.scheduler.common.fica.FiCaSchedulerNode: Assigned container container_1376157310799_0006_01_000020 of capacity <memory:1024, vCores:1> on host hadoop-221-5:56475, which currently has 7 containers, <memory:8192, vCores:7> used and <memory:0, vCores:9> available
2013-08-10 18:12:35,846 INFO org.apache.hadoop.yarn.server.resourcemanager.scheduler.capacity.LeafQueue: assignedContainer application=application_1376157310799_0006 container=Container: [ContainerId: container_1376157310799_0006_01_000020, NodeId: hadoop-221-5:56475, NodeHttpAddress: hadoop-221-5:8042, Resource: <memory:1024, vCores:1>, Priority: 20, State: NEW, Token: null, Status: container_id {, app_attempt_id {, application_id {, id: 6, cluster_timestamp: 1376157310799, }, attemptId: 1, }, id: 20, }, state: C_NEW, ] containerId=container_1376157310799_0006_01_000020 queue=default: capacity=1.0, absoluteCapacity=1.0, usedResources=<memory:48128, vCores:42>usedCapacity=0.9791667, absoluteUsedCapacity=0.9791667, numApps=5, numContainers=42 usedCapacity=0.9791667 absoluteUsedCapacity=0.9791667 used=<memory:48128, vCores:42> cluster=<memory:49152, vCores:96>
2013-08-10 18:12:35,846 INFO org.apache.hadoop.yarn.server.resourcemanager.scheduler.capacity.ParentQueue: Re-sorting queues since queue: root.default stats: default: capacity=1.0, absoluteCapacity=1.0, usedResources=<memory:49152, vCores:43>usedCapacity=1.0, absoluteUsedCapacity=1.0, numApps=5, numContainers=43
2013-08-10 18:12:35,846 INFO org.apache.hadoop.yarn.server.resourcemanager.scheduler.capacity.ParentQueue: assignedContainer queue=root usedCapacity=1.0 absoluteUsedCapacity=1.0 used=<memory:49152, vCores:43> cluster=<memory:49152, vCores:96>
2013-08-10 18:12:36,615 INFO org.apache.hadoop.yarn.server.resourcemanager.rmcontainer.RMContainerImpl: container_1376157310799_0006_01_000020 Container Transitioned from ALLOCATED to ACQUIRED
2013-08-10 18:12:36,918 INFO org.apache.hadoop.yarn.server.resourcemanager.rmcontainer.RMContainerImpl: container_1376157310799_0006_01_000017 Container Transitioned from ACQUIRED to RUNNING
2013-08-10 18:12:36,918 INFO org.apache.hadoop.yarn.server.resourcemanager.rmcontainer.RMContainerImpl: container_1376157310799_0006_01_000020 Container Transitioned from ACQUIRED to RUNNING
2013-08-10 18:12:37,310 INFO org.apache.hadoop.yarn.server.resourcemanager.rmcontainer.RMContainerImpl: container_1376157310799_0006_01_000018 Container Transitioned from ACQUIRED to RUNNING
2013-08-10 18:12:37,310 INFO org.apache.hadoop.yarn.server.resourcemanager.rmcontainer.RMContainerImpl: container_1376157310799_0006_01_000019 Container Transitioned from ACQUIRED to RUNNING
2013-08-10 18:12:37,822 INFO org.apache.hadoop.yarn.server.resourcemanager.rmcontainer.RMContainerImpl: container_1376157310799_0010_01_000017 Container Transitioned from RUNNING to COMPLETED
2013-08-10 18:12:37,822 INFO org.apache.hadoop.yarn.server.resourcemanager.scheduler.common.fica.FiCaSchedulerApp: Completed container: container_1376157310799_0010_01_000017 in state: COMPLETED event:FINISHED
2013-08-10 18:12:37,822 INFO org.apache.hadoop.yarn.server.resourcemanager.RMAuditLogger: USER=ubuntu	OPERATION=AM Released Container	TARGET=SchedulerApp	RESULT=SUCCESS	APPID=application_1376157310799_0010	CONTAINERID=container_1376157310799_0010_01_000017
2013-08-10 18:12:37,823 INFO org.apache.hadoop.yarn.server.resourcemanager.scheduler.common.fica.FiCaSchedulerNode: Released container container_1376157310799_0010_01_000017 of capacity <memory:1024, vCores:1> on host hadoop-221-5:56475, which currently has 6 containers, <memory:7168, vCores:6> used and <memory:1024, vCores:10> available, release resources=true
2013-08-10 18:12:37,823 INFO org.apache.hadoop.yarn.server.resourcemanager.scheduler.capacity.LeafQueue: default used=<memory:48128, vCores:42> numContainers=42 user=ubuntu user-resources=<memory:48128, vCores:42>
2013-08-10 18:12:37,824 INFO org.apache.hadoop.yarn.server.resourcemanager.scheduler.capacity.LeafQueue: completedContainer container=Container: [ContainerId: container_1376157310799_0010_01_000017, NodeId: hadoop-221-5:56475, NodeHttpAddress: hadoop-221-5:8042, Resource: <memory:1024, vCores:1>, Priority: 20, State: NEW, Token: null, Status: container_id {, app_attempt_id {, application_id {, id: 10, cluster_timestamp: 1376157310799, }, attemptId: 1, }, id: 17, }, state: C_COMPLETE, diagnostics: "", exit_status: 0, ] resource=<memory:1024, vCores:1> queue=default: capacity=1.0, absoluteCapacity=1.0, usedResources=<memory:48128, vCores:42>usedCapacity=0.9791667, absoluteUsedCapacity=0.9791667, numApps=5, numContainers=42 usedCapacity=0.9791667 absoluteUsedCapacity=0.9791667 used=<memory:48128, vCores:42> cluster=<memory:49152, vCores:96>
2013-08-10 18:12:37,824 INFO org.apache.hadoop.yarn.server.resourcemanager.scheduler.capacity.ParentQueue: completedContainer queue=root usedCapacity=0.9791667 absoluteUsedCapacity=0.9791667 used=<memory:48128, vCores:42> cluster=<memory:49152, vCores:96>
2013-08-10 18:12:37,824 INFO org.apache.hadoop.yarn.server.resourcemanager.scheduler.capacity.CapacityScheduler: Application appattempt_1376157310799_0010_000001 released container container_1376157310799_0010_01_000017 on node: host: hadoop-221-5:56475 #containers=6 available=1024 used=7168 with event: FINISHED
2013-08-10 18:12:37,825 INFO org.apache.hadoop.yarn.server.resourcemanager.rmcontainer.RMContainerImpl: container_1376157310799_0006_01_000021 Container Transitioned from NEW to ALLOCATED
2013-08-10 18:12:37,825 INFO org.apache.hadoop.yarn.server.resourcemanager.RMAuditLogger: USER=ubuntu	OPERATION=AM Allocated Container	TARGET=SchedulerApp	RESULT=SUCCESS	APPID=application_1376157310799_0006	CONTAINERID=container_1376157310799_0006_01_000021
2013-08-10 18:12:37,825 INFO org.apache.hadoop.yarn.server.resourcemanager.scheduler.common.fica.FiCaSchedulerNode: Assigned container container_1376157310799_0006_01_000021 of capacity <memory:1024, vCores:1> on host hadoop-221-5:56475, which currently has 7 containers, <memory:8192, vCores:7> used and <memory:0, vCores:9> available
2013-08-10 18:12:37,826 INFO org.apache.hadoop.yarn.server.resourcemanager.scheduler.capacity.LeafQueue: assignedContainer application=application_1376157310799_0006 container=Container: [ContainerId: container_1376157310799_0006_01_000021, NodeId: hadoop-221-5:56475, NodeHttpAddress: hadoop-221-5:8042, Resource: <memory:1024, vCores:1>, Priority: 20, State: NEW, Token: null, Status: container_id {, app_attempt_id {, application_id {, id: 6, cluster_timestamp: 1376157310799, }, attemptId: 1, }, id: 21, }, state: C_NEW, ] containerId=container_1376157310799_0006_01_000021 queue=default: capacity=1.0, absoluteCapacity=1.0, usedResources=<memory:48128, vCores:42>usedCapacity=0.9791667, absoluteUsedCapacity=0.9791667, numApps=5, numContainers=42 usedCapacity=0.9791667 absoluteUsedCapacity=0.9791667 used=<memory:48128, vCores:42> cluster=<memory:49152, vCores:96>
2013-08-10 18:12:37,826 INFO org.apache.hadoop.yarn.server.resourcemanager.scheduler.capacity.ParentQueue: Re-sorting queues since queue: root.default stats: default: capacity=1.0, absoluteCapacity=1.0, usedResources=<memory:49152, vCores:43>usedCapacity=1.0, absoluteUsedCapacity=1.0, numApps=5, numContainers=43
2013-08-10 18:12:37,827 INFO org.apache.hadoop.yarn.server.resourcemanager.scheduler.capacity.ParentQueue: assignedContainer queue=root usedCapacity=1.0 absoluteUsedCapacity=1.0 used=<memory:49152, vCores:43> cluster=<memory:49152, vCores:96>
2013-08-10 18:12:38,626 INFO org.apache.hadoop.yarn.server.resourcemanager.rmcontainer.RMContainerImpl: container_1376157310799_0006_01_000021 Container Transitioned from ALLOCATED to ACQUIRED
2013-08-10 18:12:38,828 INFO org.apache.hadoop.yarn.server.resourcemanager.rmcontainer.RMContainerImpl: container_1376157310799_0006_01_000021 Container Transitioned from ACQUIRED to RUNNING
2013-08-10 18:12:39,617 INFO org.apache.hadoop.yarn.server.resourcemanager.rmcontainer.RMContainerImpl: container_1376157310799_0010_01_000002 Container Transitioned from RUNNING to COMPLETED
2013-08-10 18:12:39,617 INFO org.apache.hadoop.yarn.server.resourcemanager.scheduler.common.fica.FiCaSchedulerApp: Completed container: container_1376157310799_0010_01_000002 in state: COMPLETED event:FINISHED
2013-08-10 18:12:39,617 INFO org.apache.hadoop.yarn.server.resourcemanager.RMAuditLogger: USER=ubuntu	OPERATION=AM Released Container	TARGET=SchedulerApp	RESULT=SUCCESS	APPID=application_1376157310799_0010	CONTAINERID=container_1376157310799_0010_01_000002
2013-08-10 18:12:39,617 INFO org.apache.hadoop.yarn.server.resourcemanager.scheduler.common.fica.FiCaSchedulerNode: Released container container_1376157310799_0010_01_000002 of capacity <memory:1024, vCores:1> on host hadoop-221-2:56306, which currently has 6 containers, <memory:7168, vCores:6> used and <memory:1024, vCores:10> available, release resources=true
2013-08-10 18:12:39,618 INFO org.apache.hadoop.yarn.server.resourcemanager.scheduler.capacity.LeafQueue: default used=<memory:48128, vCores:42> numContainers=42 user=ubuntu user-resources=<memory:48128, vCores:42>
2013-08-10 18:12:39,619 INFO org.apache.hadoop.yarn.server.resourcemanager.scheduler.capacity.LeafQueue: completedContainer container=Container: [ContainerId: container_1376157310799_0010_01_000002, NodeId: hadoop-221-2:56306, NodeHttpAddress: hadoop-221-2:8042, Resource: <memory:1024, vCores:1>, Priority: 20, State: NEW, Token: null, Status: container_id {, app_attempt_id {, application_id {, id: 10, cluster_timestamp: 1376157310799, }, attemptId: 1, }, id: 2, }, state: C_COMPLETE, diagnostics: "", exit_status: 0, ] resource=<memory:1024, vCores:1> queue=default: capacity=1.0, absoluteCapacity=1.0, usedResources=<memory:48128, vCores:42>usedCapacity=0.9791667, absoluteUsedCapacity=0.9791667, numApps=5, numContainers=42 usedCapacity=0.9791667 absoluteUsedCapacity=0.9791667 used=<memory:48128, vCores:42> cluster=<memory:49152, vCores:96>
2013-08-10 18:12:39,619 INFO org.apache.hadoop.yarn.server.resourcemanager.scheduler.capacity.ParentQueue: completedContainer queue=root usedCapacity=0.9791667 absoluteUsedCapacity=0.9791667 used=<memory:48128, vCores:42> cluster=<memory:49152, vCores:96>
2013-08-10 18:12:39,619 INFO org.apache.hadoop.yarn.server.resourcemanager.scheduler.capacity.CapacityScheduler: Application appattempt_1376157310799_0010_000001 released container container_1376157310799_0010_01_000002 on node: host: hadoop-221-2:56306 #containers=6 available=1024 used=7168 with event: FINISHED
2013-08-10 18:12:39,620 INFO org.apache.hadoop.yarn.server.resourcemanager.rmcontainer.RMContainerImpl: container_1376157310799_0006_01_000022 Container Transitioned from NEW to ALLOCATED
2013-08-10 18:12:39,620 INFO org.apache.hadoop.yarn.server.resourcemanager.RMAuditLogger: USER=ubuntu	OPERATION=AM Allocated Container	TARGET=SchedulerApp	RESULT=SUCCESS	APPID=application_1376157310799_0006	CONTAINERID=container_1376157310799_0006_01_000022
2013-08-10 18:12:39,620 INFO org.apache.hadoop.yarn.server.resourcemanager.scheduler.common.fica.FiCaSchedulerNode: Assigned container container_1376157310799_0006_01_000022 of capacity <memory:1024, vCores:1> on host hadoop-221-2:56306, which currently has 7 containers, <memory:8192, vCores:7> used and <memory:0, vCores:9> available
