2013-08-09 20:38:56,070 INFO org.apache.hadoop.yarn.server.resourcemanager.ResourceManager: STARTUP_MSG: 
/************************************************************
STARTUP_MSG: Starting ResourceManager
STARTUP_MSG:   host = hadoop-210-1/192.168.100.4
STARTUP_MSG:   args = []
STARTUP_MSG:   version = 3.0.0-SNAPSHOT
STARTUP_MSG:   build = https://github.com/lalithsuresh/hadoop-common -r 0cb423bd4868928bb06cd93f882bb0913172fd17; compiled by 'lsuresh' on 2013-04-08T15:47Z
STARTUP_MSG:   java = 1.7.0_17
************************************************************/
2013-08-09 20:38:56,085 INFO org.apache.hadoop.yarn.server.resourcemanager.ResourceManager: registered UNIX signal handlers for [TERM, HUP, INT]
2013-08-09 20:38:56,723 INFO org.apache.hadoop.yarn.server.resourcemanager.security.ApplicationTokenSecretManager: Rolling master-key for application-tokens
2013-08-09 20:38:56,786 INFO org.apache.hadoop.yarn.server.resourcemanager.security.RMContainerTokenSecretManager: ContainerTokenKeyRollingInterval: 86400000ms and ContainerTokenKeyActivationDelay: 900000ms
2013-08-09 20:38:56,788 INFO org.apache.hadoop.yarn.service.AbstractService: Service:Dispatcher is inited.
2013-08-09 20:38:56,790 INFO org.apache.hadoop.yarn.event.AsyncDispatcher: Registering class org.apache.hadoop.yarn.server.resourcemanager.recovery.RMStateStoreEventType for class org.apache.hadoop.yarn.server.resourcemanager.recovery.RMStateStore$ForwardingEventHandler
2013-08-09 20:38:56,790 INFO org.apache.hadoop.yarn.service.AbstractService: Service:Dispatcher is started.
2013-08-09 20:38:56,795 INFO org.apache.hadoop.yarn.event.AsyncDispatcher: Registering class org.apache.hadoop.yarn.server.resourcemanager.NodesListManagerEventType for class org.apache.hadoop.yarn.server.resourcemanager.NodesListManager
2013-08-09 20:38:56,795 INFO org.apache.hadoop.yarn.server.resourcemanager.ResourceManager: Using Scheduler: org.apache.hadoop.yarn.server.resourcemanager.scheduler.capacity.CapacityScheduler
2013-08-09 20:38:56,946 INFO org.apache.hadoop.yarn.event.AsyncDispatcher: Registering class org.apache.hadoop.yarn.server.resourcemanager.scheduler.event.SchedulerEventType for class org.apache.hadoop.yarn.server.resourcemanager.ResourceManager$SchedulerEventDispatcher
2013-08-09 20:38:56,947 INFO org.apache.hadoop.yarn.event.AsyncDispatcher: Registering class org.apache.hadoop.yarn.server.resourcemanager.rmapp.RMAppEventType for class org.apache.hadoop.yarn.server.resourcemanager.ResourceManager$ApplicationEventDispatcher
2013-08-09 20:38:56,949 INFO org.apache.hadoop.yarn.event.AsyncDispatcher: Registering class org.apache.hadoop.yarn.server.resourcemanager.rmapp.attempt.RMAppAttemptEventType for class org.apache.hadoop.yarn.server.resourcemanager.ResourceManager$ApplicationAttemptEventDispatcher
2013-08-09 20:38:56,950 INFO org.apache.hadoop.yarn.event.AsyncDispatcher: Registering class org.apache.hadoop.yarn.server.resourcemanager.rmnode.RMNodeEventType for class org.apache.hadoop.yarn.server.resourcemanager.ResourceManager$NodeEventDispatcher
2013-08-09 20:38:57,570 WARN org.apache.hadoop.util.NativeCodeLoader: Unable to load native-hadoop library for your platform... using builtin-java classes where applicable
2013-08-09 20:38:57,600 INFO org.apache.hadoop.yarn.server.resourcemanager.scheduler.capacity.ParentQueue: root, capacity=1.0, asboluteCapacity=1.0, maxCapacity=1.0, asboluteMaxCapacity=1.0, state=RUNNING, acls=ADMINISTER_QUEUE:*SUBMIT_APPLICATIONS:*
2013-08-09 20:38:57,600 INFO org.apache.hadoop.yarn.server.resourcemanager.scheduler.capacity.ParentQueue: Initialized parent-queue root name=root, fullname=root
2013-08-09 20:38:57,621 INFO org.apache.hadoop.yarn.server.resourcemanager.scheduler.capacity.LeafQueue: Initializing default
capacity = 1.0 [= (float) configuredCapacity / 100 ]
asboluteCapacity = 1.0 [= parentAbsoluteCapacity * capacity ]
maxCapacity = 1.0 [= configuredMaxCapacity ]
absoluteMaxCapacity = 1.0 [= 1.0 maximumCapacity undefined, (parentAbsoluteMaxCapacity * maximumCapacity) / 100 otherwise ]
userLimit = 100 [= configuredUserLimit ]
userLimitFactor = 1.0 [= configuredUserLimitFactor ]
maxApplications = 10000 [= configuredMaximumSystemApplicationsPerQueue or (int)(configuredMaximumSystemApplications * absoluteCapacity)]
maxApplicationsPerUser = 10000 [= (int)(maxApplications * (userLimit / 100.0f) * userLimitFactor) ]
maxActiveApplications = 1 [= max((int)ceil((clusterResourceMemory / minimumAllocation) * maxAMResourcePerQueuePercent * absoluteMaxCapacity),1) ]
maxActiveAppsUsingAbsCap = 1 [= max((int)ceil((clusterResourceMemory / minimumAllocation) *maxAMResourcePercent * absoluteCapacity),1) ]
maxActiveApplicationsPerUser = 1 [= max((int)(maxActiveApplications * (userLimit / 100.0f) * userLimitFactor),1) ]
usedCapacity = 0.0 [= usedResourcesMemory / (clusterResourceMemory * absoluteCapacity)]
absoluteUsedCapacity = 0.0 [= usedResourcesMemory / clusterResourceMemory]
maxAMResourcePerQueuePercent = 0.1 [= configuredMaximumAMResourcePercent ]
minimumAllocationFactor = 0.875 [= (float)(maximumAllocationMemory - minimumAllocationMemory) / maximumAllocationMemory ]
numContainers = 0 [= currentNumContainers ]
state = RUNNING [= configuredState ]
acls = ADMINISTER_QUEUE:*SUBMIT_APPLICATIONS:* [= configuredAcls ]

2013-08-09 20:38:57,621 INFO org.apache.hadoop.yarn.server.resourcemanager.scheduler.capacity.CapacityScheduler: Initialized queue: default: capacity=1.0, absoluteCapacity=1.0, usedResources=<memory:0, vCores:0>usedCapacity=0.0, absoluteUsedCapacity=0.0, numApps=0, numContainers=0
2013-08-09 20:38:57,622 INFO org.apache.hadoop.yarn.server.resourcemanager.scheduler.capacity.CapacityScheduler: Initialized queue: root: numChildQueue= 1, capacity=1.0, absoluteCapacity=1.0, usedResources=<memory:0, vCores:0>usedCapacity=0.0, numApps=0, numContainers=0
2013-08-09 20:38:57,622 INFO org.apache.hadoop.yarn.server.resourcemanager.scheduler.capacity.CapacityScheduler: Initialized root queue root: numChildQueue= 1, capacity=1.0, absoluteCapacity=1.0, usedResources=<memory:0, vCores:0>usedCapacity=0.0, numApps=0, numContainers=0
2013-08-09 20:38:57,622 INFO org.apache.hadoop.yarn.server.resourcemanager.scheduler.capacity.CapacityScheduler: Initialized CapacityScheduler with calculator=class org.apache.hadoop.yarn.server.resourcemanager.resource.DefaultResourceCalculator, minimumAllocation=<<memory:1024, vCores:1>>, maximumAllocation=<<memory:8192, vCores:32>>
2013-08-09 20:38:57,975 INFO org.apache.hadoop.yarn.event.AsyncDispatcher: Registering class org.apache.hadoop.yarn.server.resourcemanager.RMAppManagerEventType for class org.apache.hadoop.yarn.server.resourcemanager.RMAppManager
2013-08-09 20:38:57,987 INFO org.apache.hadoop.yarn.event.AsyncDispatcher: Registering class org.apache.hadoop.yarn.server.resourcemanager.amlauncher.AMLauncherEventType for class org.apache.hadoop.yarn.server.resourcemanager.amlauncher.ApplicationMasterLauncher
2013-08-09 20:38:58,073 INFO org.apache.hadoop.yarn.server.resourcemanager.RMNMInfo: Registered RMNMInfo MBean
2013-08-09 20:38:58,074 INFO org.apache.hadoop.yarn.service.AbstractService: Service:Dispatcher is inited.
2013-08-09 20:38:58,074 INFO org.apache.hadoop.yarn.service.AbstractService: Service:org.apache.hadoop.yarn.server.resourcemanager.rmcontainer.ContainerAllocationExpirer is inited.
2013-08-09 20:38:58,074 INFO org.apache.hadoop.yarn.service.AbstractService: Service:AMLivelinessMonitor is inited.
2013-08-09 20:38:58,074 INFO org.apache.hadoop.yarn.service.AbstractService: Service:AMLivelinessMonitor is inited.
2013-08-09 20:38:58,074 INFO org.apache.hadoop.yarn.service.AbstractService: Service:org.apache.hadoop.yarn.server.resourcemanager.security.DelegationTokenRenewer is inited.
2013-08-09 20:38:58,076 INFO org.apache.hadoop.util.HostsFileReader: Refreshing hosts (include/exclude) list
2013-08-09 20:38:58,076 INFO org.apache.hadoop.yarn.service.AbstractService: Service:org.apache.hadoop.yarn.server.resourcemanager.NodesListManager is inited.
2013-08-09 20:38:58,076 INFO org.apache.hadoop.yarn.service.AbstractService: Service:org.apache.hadoop.yarn.server.resourcemanager.ResourceManager$SchedulerEventDispatcher is inited.
2013-08-09 20:38:58,077 INFO org.apache.hadoop.yarn.service.AbstractService: Service:NMLivelinessMonitor is inited.
2013-08-09 20:38:58,085 INFO org.apache.hadoop.yarn.service.AbstractService: Service:org.apache.hadoop.yarn.server.resourcemanager.ResourceTrackerService is inited.
2013-08-09 20:38:58,085 INFO org.apache.hadoop.yarn.service.AbstractService: Service:org.apache.hadoop.yarn.server.resourcemanager.ApplicationMasterService is inited.
2013-08-09 20:38:58,085 INFO org.apache.hadoop.yarn.service.AbstractService: Service:org.apache.hadoop.yarn.server.resourcemanager.ClientRMService is inited.
2013-08-09 20:38:58,086 INFO org.apache.hadoop.yarn.service.AbstractService: Service:org.apache.hadoop.yarn.server.resourcemanager.AdminService is inited.
2013-08-09 20:38:58,086 INFO org.apache.hadoop.yarn.service.AbstractService: Service:org.apache.hadoop.yarn.server.resourcemanager.amlauncher.ApplicationMasterLauncher is inited.
2013-08-09 20:38:58,086 INFO org.apache.hadoop.yarn.service.AbstractService: Service:ResourceManager is inited.
2013-08-09 20:38:58,087 INFO org.apache.hadoop.yarn.server.resourcemanager.security.ApplicationTokenSecretManager: Rolling master-key for application-tokens
2013-08-09 20:38:58,087 INFO org.apache.hadoop.yarn.server.resourcemanager.security.RMContainerTokenSecretManager: Rolling master-key for container-tokens
2013-08-09 20:38:58,251 INFO org.mortbay.log: Logging to org.slf4j.impl.Log4jLoggerAdapter(org.mortbay.log) via org.mortbay.log.Slf4jLog
2013-08-09 20:38:58,358 INFO org.apache.hadoop.http.HttpServer: Added global filter 'safety' (class=org.apache.hadoop.http.HttpServer$QuotingInputFilter)
2013-08-09 20:38:58,363 INFO org.apache.hadoop.http.HttpServer: Added filter static_user_filter (class=org.apache.hadoop.http.lib.StaticUserWebFilter$StaticUserFilter) to context cluster
2013-08-09 20:38:58,363 INFO org.apache.hadoop.http.HttpServer: Added filter static_user_filter (class=org.apache.hadoop.http.lib.StaticUserWebFilter$StaticUserFilter) to context static
2013-08-09 20:38:58,364 INFO org.apache.hadoop.http.HttpServer: Added filter static_user_filter (class=org.apache.hadoop.http.lib.StaticUserWebFilter$StaticUserFilter) to context logs
2013-08-09 20:38:58,371 INFO org.apache.hadoop.http.HttpServer: adding path spec: /cluster
2013-08-09 20:38:58,371 INFO org.apache.hadoop.http.HttpServer: adding path spec: /cluster/*
2013-08-09 20:38:58,372 INFO org.apache.hadoop.http.HttpServer: adding path spec: /ws
2013-08-09 20:38:58,372 INFO org.apache.hadoop.http.HttpServer: adding path spec: /ws/*
2013-08-09 20:38:58,375 INFO org.apache.hadoop.http.HttpServer: Added global filter 'guice' (class=com.google.inject.servlet.GuiceFilter)
2013-08-09 20:38:58,385 INFO org.apache.hadoop.http.HttpServer: Jetty bound to port 8088
2013-08-09 20:38:58,385 INFO org.mortbay.log: jetty-6.1.26
2013-08-09 20:38:58,440 INFO org.mortbay.log: Extract jar:file:/home/ubuntu/hadoop-3.0.0-SNAPSHOT/share/hadoop/yarn/hadoop-yarn-common-3.0.0-SNAPSHOT.jar!/webapps/cluster to /tmp/Jetty_0_0_0_0_8088_cluster____u0rgz3/webapp
2013-08-09 20:38:58,898 INFO org.mortbay.log: Started SelectChannelConnector@0.0.0.0:8088
2013-08-09 20:38:58,898 INFO org.apache.hadoop.yarn.webapp.WebApps: Web app /cluster started at 8088
2013-08-09 20:38:59,611 INFO org.apache.hadoop.yarn.webapp.WebApps: Registered webapp guice modules
2013-08-09 20:38:59,725 INFO org.apache.hadoop.metrics2.impl.MetricsConfig: loaded properties from hadoop-metrics2.properties
2013-08-09 20:38:59,763 INFO org.apache.hadoop.metrics2.impl.MetricsSystemImpl: Scheduled snapshot period at 10 second(s).
2013-08-09 20:38:59,763 INFO org.apache.hadoop.metrics2.impl.MetricsSystemImpl: ResourceManager metrics system started
2013-08-09 20:38:59,783 INFO org.apache.hadoop.security.token.delegation.AbstractDelegationTokenSecretManager: Updating the current master key for generating delegation tokens
2013-08-09 20:38:59,787 INFO org.apache.hadoop.yarn.service.AbstractService: Service:Dispatcher is started.
2013-08-09 20:38:59,789 INFO org.apache.hadoop.security.token.delegation.AbstractDelegationTokenSecretManager: Starting expired delegation token remover thread, tokenRemoverScanInterval=60 min(s)
2013-08-09 20:38:59,790 INFO org.apache.hadoop.yarn.service.AbstractService: Service:org.apache.hadoop.yarn.server.resourcemanager.rmcontainer.ContainerAllocationExpirer is started.
2013-08-09 20:38:59,791 INFO org.apache.hadoop.security.token.delegation.AbstractDelegationTokenSecretManager: Updating the current master key for generating delegation tokens
2013-08-09 20:38:59,791 INFO org.apache.hadoop.yarn.service.AbstractService: Service:AMLivelinessMonitor is started.
2013-08-09 20:38:59,792 INFO org.apache.hadoop.yarn.service.AbstractService: Service:AMLivelinessMonitor is started.
2013-08-09 20:38:59,792 INFO org.apache.hadoop.yarn.service.AbstractService: Service:org.apache.hadoop.yarn.server.resourcemanager.security.DelegationTokenRenewer is started.
2013-08-09 20:38:59,793 INFO org.apache.hadoop.yarn.service.AbstractService: Service:org.apache.hadoop.yarn.server.resourcemanager.NodesListManager is started.
2013-08-09 20:38:59,794 INFO org.apache.hadoop.yarn.service.AbstractService: Service:org.apache.hadoop.yarn.server.resourcemanager.ResourceManager$SchedulerEventDispatcher is started.
2013-08-09 20:38:59,795 INFO org.apache.hadoop.yarn.service.AbstractService: Service:NMLivelinessMonitor is started.
2013-08-09 20:38:59,795 INFO org.apache.hadoop.yarn.service.AbstractService: Service:org.apache.hadoop.yarn.server.resourcemanager.ResourceTrackerService is started.
2013-08-09 20:38:59,877 INFO org.apache.hadoop.ipc.Server: Starting Socket Reader #1 for port 54110
2013-08-09 20:38:59,923 INFO org.apache.hadoop.yarn.factories.impl.pb.RpcServerFactoryPBImpl: Adding protocol org.apache.hadoop.yarn.server.api.ResourceTrackerPB to the server
2013-08-09 20:38:59,986 INFO org.apache.hadoop.ipc.Server: IPC Server listener on 54110: starting
2013-08-09 20:38:59,986 INFO org.apache.hadoop.ipc.Server: IPC Server Responder: starting
2013-08-09 20:39:00,110 INFO org.apache.hadoop.ipc.Server: Starting Socket Reader #1 for port 54112
2013-08-09 20:39:00,129 INFO org.apache.hadoop.yarn.factories.impl.pb.RpcServerFactoryPBImpl: Adding protocol org.apache.hadoop.yarn.api.AMRMProtocolPB to the server
2013-08-09 20:39:00,131 INFO org.apache.hadoop.ipc.Server: IPC Server Responder: starting
2013-08-09 20:39:00,132 INFO org.apache.hadoop.ipc.Server: IPC Server listener on 54112: starting
2013-08-09 20:39:00,183 INFO org.apache.hadoop.yarn.service.AbstractService: Service:org.apache.hadoop.yarn.server.resourcemanager.ApplicationMasterService is started.
2013-08-09 20:39:00,252 INFO org.apache.hadoop.ipc.Server: Starting Socket Reader #1 for port 54111
2013-08-09 20:39:00,259 INFO org.apache.hadoop.yarn.factories.impl.pb.RpcServerFactoryPBImpl: Adding protocol org.apache.hadoop.yarn.api.ClientRMProtocolPB to the server
2013-08-09 20:39:00,260 INFO org.apache.hadoop.ipc.Server: IPC Server Responder: starting
2013-08-09 20:39:00,268 INFO org.apache.hadoop.ipc.Server: IPC Server listener on 54111: starting
2013-08-09 20:39:00,349 INFO org.apache.hadoop.yarn.service.AbstractService: Service:org.apache.hadoop.yarn.server.resourcemanager.ClientRMService is started.
2013-08-09 20:39:00,385 INFO org.apache.hadoop.ipc.Server: Starting Socket Reader #1 for port 8033
2013-08-09 20:39:00,391 INFO org.apache.hadoop.yarn.factories.impl.pb.RpcServerFactoryPBImpl: Adding protocol org.apache.hadoop.yarn.api.RMAdminProtocolPB to the server
2013-08-09 20:39:00,393 INFO org.apache.hadoop.ipc.Server: IPC Server Responder: starting
2013-08-09 20:39:00,394 INFO org.apache.hadoop.ipc.Server: IPC Server listener on 8033: starting
2013-08-09 20:39:00,394 INFO org.apache.hadoop.yarn.service.AbstractService: Service:org.apache.hadoop.yarn.server.resourcemanager.AdminService is started.
2013-08-09 20:39:00,396 INFO org.apache.hadoop.yarn.service.AbstractService: Service:org.apache.hadoop.yarn.server.resourcemanager.amlauncher.ApplicationMasterLauncher is started.
2013-08-09 20:39:00,396 INFO org.apache.hadoop.yarn.service.AbstractService: Service:ResourceManager is started.
2013-08-09 20:39:10,148 INFO org.apache.hadoop.yarn.util.RackResolver: Resolved hadoop-210-3 to /default-rack
2013-08-09 20:39:10,155 INFO org.apache.hadoop.yarn.server.resourcemanager.ResourceTrackerService: NodeManager from node hadoop-210-3(cmPort: 58589 httpPort: 8042) registered with capability: <memory:8192, vCores:16>, assigned nodeId hadoop-210-3:58589
2013-08-09 20:39:10,187 INFO org.apache.hadoop.yarn.server.resourcemanager.rmnode.RMNodeImpl: hadoop-210-3:58589 Node Transitioned from NEW to RUNNING
2013-08-09 20:39:10,190 INFO org.apache.hadoop.yarn.server.resourcemanager.scheduler.capacity.CapacityScheduler: Added node hadoop-210-3:58589 clusterResource: <memory:8192, vCores:16>
2013-08-09 20:39:10,278 INFO org.apache.hadoop.yarn.util.RackResolver: Resolved hadoop-210-6 to /default-rack
2013-08-09 20:39:10,278 INFO org.apache.hadoop.yarn.server.resourcemanager.ResourceTrackerService: NodeManager from node hadoop-210-6(cmPort: 41207 httpPort: 8042) registered with capability: <memory:8192, vCores:16>, assigned nodeId hadoop-210-6:41207
2013-08-09 20:39:10,279 INFO org.apache.hadoop.yarn.server.resourcemanager.rmnode.RMNodeImpl: hadoop-210-6:41207 Node Transitioned from NEW to RUNNING
2013-08-09 20:39:10,279 INFO org.apache.hadoop.yarn.server.resourcemanager.scheduler.capacity.CapacityScheduler: Added node hadoop-210-6:41207 clusterResource: <memory:16384, vCores:32>
2013-08-09 20:39:10,296 INFO org.apache.hadoop.yarn.util.RackResolver: Resolved hadoop-210-2 to /default-rack
2013-08-09 20:39:10,296 INFO org.apache.hadoop.yarn.server.resourcemanager.ResourceTrackerService: NodeManager from node hadoop-210-2(cmPort: 51035 httpPort: 8042) registered with capability: <memory:8192, vCores:16>, assigned nodeId hadoop-210-2:51035
2013-08-09 20:39:10,297 INFO org.apache.hadoop.yarn.server.resourcemanager.rmnode.RMNodeImpl: hadoop-210-2:51035 Node Transitioned from NEW to RUNNING
2013-08-09 20:39:10,297 INFO org.apache.hadoop.yarn.server.resourcemanager.scheduler.capacity.CapacityScheduler: Added node hadoop-210-2:51035 clusterResource: <memory:24576, vCores:48>
2013-08-09 20:39:10,342 INFO org.apache.hadoop.yarn.util.RackResolver: Resolved hadoop-210-7 to /default-rack
2013-08-09 20:39:10,342 INFO org.apache.hadoop.yarn.server.resourcemanager.ResourceTrackerService: NodeManager from node hadoop-210-7(cmPort: 35638 httpPort: 8042) registered with capability: <memory:8192, vCores:16>, assigned nodeId hadoop-210-7:35638
2013-08-09 20:39:10,343 INFO org.apache.hadoop.yarn.server.resourcemanager.rmnode.RMNodeImpl: hadoop-210-7:35638 Node Transitioned from NEW to RUNNING
2013-08-09 20:39:10,344 INFO org.apache.hadoop.yarn.server.resourcemanager.scheduler.capacity.CapacityScheduler: Added node hadoop-210-7:35638 clusterResource: <memory:32768, vCores:64>
2013-08-09 20:39:10,428 INFO org.apache.hadoop.yarn.util.RackResolver: Resolved hadoop-210-5 to /default-rack
2013-08-09 20:39:10,428 INFO org.apache.hadoop.yarn.server.resourcemanager.ResourceTrackerService: NodeManager from node hadoop-210-5(cmPort: 40689 httpPort: 8042) registered with capability: <memory:8192, vCores:16>, assigned nodeId hadoop-210-5:40689
2013-08-09 20:39:10,429 INFO org.apache.hadoop.yarn.server.resourcemanager.rmnode.RMNodeImpl: hadoop-210-5:40689 Node Transitioned from NEW to RUNNING
2013-08-09 20:39:10,430 INFO org.apache.hadoop.yarn.server.resourcemanager.scheduler.capacity.CapacityScheduler: Added node hadoop-210-5:40689 clusterResource: <memory:40960, vCores:80>
2013-08-09 20:39:10,491 INFO org.apache.hadoop.yarn.util.RackResolver: Resolved hadoop-210-4 to /default-rack
2013-08-09 20:39:10,491 INFO org.apache.hadoop.yarn.server.resourcemanager.ResourceTrackerService: NodeManager from node hadoop-210-4(cmPort: 47596 httpPort: 8042) registered with capability: <memory:8192, vCores:16>, assigned nodeId hadoop-210-4:47596
2013-08-09 20:39:10,491 INFO org.apache.hadoop.yarn.server.resourcemanager.rmnode.RMNodeImpl: hadoop-210-4:47596 Node Transitioned from NEW to RUNNING
2013-08-09 20:39:10,492 INFO org.apache.hadoop.yarn.server.resourcemanager.scheduler.capacity.CapacityScheduler: Added node hadoop-210-4:47596 clusterResource: <memory:49152, vCores:96>
2013-08-09 20:41:16,256 INFO org.apache.hadoop.yarn.server.resourcemanager.ClientRMService: Allocated new applicationId: 1
2013-08-09 20:41:19,627 INFO org.apache.hadoop.yarn.server.resourcemanager.ClientRMService: Storing Application with id application_1376080735992_0001
2013-08-09 20:41:19,630 INFO org.apache.hadoop.yarn.server.resourcemanager.recovery.RMStateStore: Storing info for app: application_1376080735992_0001
2013-08-09 20:41:19,630 INFO org.apache.hadoop.yarn.server.resourcemanager.ClientRMService: Application with id 1 submitted by user ubuntu
2013-08-09 20:41:19,633 INFO org.apache.hadoop.yarn.server.resourcemanager.RMAuditLogger: USER=ubuntu	IP=192.168.100.4	OPERATION=Submit Application Request	TARGET=ClientRMService	RESULT=SUCCESS	APPID=application_1376080735992_0001
2013-08-09 20:41:19,682 INFO org.apache.hadoop.yarn.server.resourcemanager.rmapp.RMAppImpl: application_1376080735992_0001 State change from NEW to SUBMITTED
2013-08-09 20:41:19,683 INFO org.apache.hadoop.yarn.server.resourcemanager.ApplicationMasterService: Registering appattempt_1376080735992_0001_000001
2013-08-09 20:41:19,685 INFO org.apache.hadoop.yarn.server.resourcemanager.rmapp.attempt.RMAppAttemptImpl: appattempt_1376080735992_0001_000001 State change from NEW to SUBMITTED
2013-08-09 20:41:19,721 INFO org.apache.hadoop.yarn.server.resourcemanager.scheduler.capacity.LeafQueue: Application application_1376080735992_0001 from user: ubuntu activated in queue: default
2013-08-09 20:41:19,721 INFO org.apache.hadoop.yarn.server.resourcemanager.scheduler.capacity.LeafQueue: Application added - appId: application_1376080735992_0001 user: org.apache.hadoop.yarn.server.resourcemanager.scheduler.capacity.LeafQueue$User@250ea0db, leaf-queue: default #user-pending-applications: 0 #user-active-applications: 1 #queue-pending-applications: 0 #queue-active-applications: 1
2013-08-09 20:41:19,721 INFO org.apache.hadoop.yarn.server.resourcemanager.scheduler.capacity.ParentQueue: Application added - appId: application_1376080735992_0001 user: ubuntu leaf-queue of parent: root #applications: 1
2013-08-09 20:41:19,722 INFO org.apache.hadoop.yarn.server.resourcemanager.scheduler.capacity.CapacityScheduler: Application Submission: appattempt_1376080735992_0001_000001, user: ubuntu queue: default: capacity=1.0, absoluteCapacity=1.0, usedResources=<memory:0, vCores:0>usedCapacity=0.0, absoluteUsedCapacity=0.0, numApps=1, numContainers=0, currently active: 1
2013-08-09 20:41:19,727 INFO org.apache.hadoop.yarn.server.resourcemanager.rmapp.attempt.RMAppAttemptImpl: appattempt_1376080735992_0001_000001 State change from SUBMITTED to SCHEDULED
2013-08-09 20:41:19,728 INFO org.apache.hadoop.yarn.server.resourcemanager.rmapp.RMAppImpl: application_1376080735992_0001 State change from SUBMITTED to ACCEPTED
2013-08-09 20:41:19,838 INFO org.apache.hadoop.yarn.server.resourcemanager.rmcontainer.RMContainerImpl: container_1376080735992_0001_01_000001 Container Transitioned from NEW to ALLOCATED
2013-08-09 20:41:19,838 INFO org.apache.hadoop.yarn.server.resourcemanager.RMAuditLogger: USER=ubuntu	OPERATION=AM Allocated Container	TARGET=SchedulerApp	RESULT=SUCCESS	APPID=application_1376080735992_0001	CONTAINERID=container_1376080735992_0001_01_000001
2013-08-09 20:41:19,839 INFO org.apache.hadoop.yarn.server.resourcemanager.scheduler.common.fica.FiCaSchedulerNode: Assigned container container_1376080735992_0001_01_000001 of capacity <memory:2048, vCores:1> on host hadoop-210-3:58589, which currently has 1 containers, <memory:2048, vCores:1> used and <memory:6144, vCores:15> available
2013-08-09 20:41:19,846 INFO org.apache.hadoop.yarn.server.resourcemanager.scheduler.capacity.LeafQueue: assignedContainer application=application_1376080735992_0001 container=Container: [ContainerId: container_1376080735992_0001_01_000001, NodeId: hadoop-210-3:58589, NodeHttpAddress: hadoop-210-3:8042, Resource: <memory:2048, vCores:1>, Priority: 0, State: NEW, Token: null, Status: container_id {, app_attempt_id {, application_id {, id: 1, cluster_timestamp: 1376080735992, }, attemptId: 1, }, id: 1, }, state: C_NEW, ] containerId=container_1376080735992_0001_01_000001 queue=default: capacity=1.0, absoluteCapacity=1.0, usedResources=<memory:0, vCores:0>usedCapacity=0.0, absoluteUsedCapacity=0.0, numApps=1, numContainers=0 usedCapacity=0.0 absoluteUsedCapacity=0.0 used=<memory:0, vCores:0> cluster=<memory:49152, vCores:96>
2013-08-09 20:41:19,851 INFO org.apache.hadoop.yarn.server.resourcemanager.scheduler.capacity.ParentQueue: Re-sorting queues since queue: root.default stats: default: capacity=1.0, absoluteCapacity=1.0, usedResources=<memory:2048, vCores:1>usedCapacity=0.041666668, absoluteUsedCapacity=0.041666668, numApps=1, numContainers=1
2013-08-09 20:41:19,852 INFO org.apache.hadoop.yarn.server.resourcemanager.scheduler.capacity.ParentQueue: assignedContainer queue=root usedCapacity=0.041666668 absoluteUsedCapacity=0.041666668 used=<memory:2048, vCores:1> cluster=<memory:49152, vCores:96>
2013-08-09 20:41:19,854 INFO org.apache.hadoop.yarn.server.resourcemanager.rmcontainer.RMContainerImpl: container_1376080735992_0001_01_000001 Container Transitioned from ALLOCATED to ACQUIRED
2013-08-09 20:41:19,857 INFO org.apache.hadoop.yarn.server.resourcemanager.rmapp.attempt.RMAppAttemptImpl: Storing attempt: AppId: application_1376080735992_0001 AttemptId: appattempt_1376080735992_0001_000001 MasterContainer: Container: [ContainerId: container_1376080735992_0001_01_000001, NodeId: hadoop-210-3:58589, NodeHttpAddress: hadoop-210-3:8042, Resource: <memory:2048, vCores:1>, Priority: 0, State: NEW, Token: null, Status: container_id {, app_attempt_id {, application_id {, id: 1, cluster_timestamp: 1376080735992, }, attemptId: 1, }, id: 1, }, state: C_NEW, ]
2013-08-09 20:41:19,868 INFO org.apache.hadoop.yarn.server.resourcemanager.rmapp.attempt.RMAppAttemptImpl: appattempt_1376080735992_0001_000001 State change from SCHEDULED to ALLOCATED_SAVING
2013-08-09 20:41:19,869 INFO org.apache.hadoop.yarn.server.resourcemanager.recovery.RMStateStore: Storing info for attempt: appattempt_1376080735992_0001_000001
2013-08-09 20:41:19,873 INFO org.apache.hadoop.yarn.server.resourcemanager.rmapp.attempt.RMAppAttemptImpl: appattempt_1376080735992_0001_000001 State change from ALLOCATED_SAVING to ALLOCATED
2013-08-09 20:41:19,881 INFO org.apache.hadoop.yarn.server.resourcemanager.amlauncher.AMLauncher: Launching masterappattempt_1376080735992_0001_000001
2013-08-09 20:41:19,929 INFO org.apache.hadoop.yarn.server.resourcemanager.amlauncher.AMLauncher: Setting up container Container: [ContainerId: container_1376080735992_0001_01_000001, NodeId: hadoop-210-3:58589, NodeHttpAddress: hadoop-210-3:8042, Resource: <memory:2048, vCores:1>, Priority: 0, State: NEW, Token: null, Status: container_id {, app_attempt_id {, application_id {, id: 1, cluster_timestamp: 1376080735992, }, attemptId: 1, }, id: 1, }, state: C_NEW, ] for AM appattempt_1376080735992_0001_000001
2013-08-09 20:41:19,929 INFO org.apache.hadoop.yarn.server.resourcemanager.amlauncher.AMLauncher: Command to launch container container_1376080735992_0001_01_000001 : $JAVA_HOME/bin/java -Dlog4j.configuration=container-log4j.properties -Dyarn.app.mapreduce.container.log.dir=<LOG_DIR> -Dyarn.app.mapreduce.container.log.filesize=0 -Dhadoop.root.logger=INFO,CLA  -Xmx1024m org.apache.hadoop.mapreduce.v2.app.MRAppMaster 1><LOG_DIR>/stdout 2><LOG_DIR>/stderr 
2013-08-09 20:41:20,849 INFO org.apache.hadoop.yarn.server.resourcemanager.amlauncher.AMLauncher: Done launching container Container: [ContainerId: container_1376080735992_0001_01_000001, NodeId: hadoop-210-3:58589, NodeHttpAddress: hadoop-210-3:8042, Resource: <memory:2048, vCores:1>, Priority: 0, State: NEW, Token: null, Status: container_id {, app_attempt_id {, application_id {, id: 1, cluster_timestamp: 1376080735992, }, attemptId: 1, }, id: 1, }, state: C_NEW, ] for AM appattempt_1376080735992_0001_000001
2013-08-09 20:41:20,850 INFO org.apache.hadoop.yarn.server.resourcemanager.rmapp.attempt.RMAppAttemptImpl: appattempt_1376080735992_0001_000001 State change from ALLOCATED to LAUNCHED
2013-08-09 20:41:21,827 INFO org.apache.hadoop.yarn.server.resourcemanager.rmcontainer.RMContainerImpl: container_1376080735992_0001_01_000001 Container Transitioned from ACQUIRED to RUNNING
2013-08-09 20:41:29,373 INFO org.apache.hadoop.yarn.server.resourcemanager.ApplicationMasterService: AM registration appattempt_1376080735992_0001_000001
2013-08-09 20:41:29,375 INFO org.apache.hadoop.yarn.server.resourcemanager.RMAuditLogger: USER=ubuntu	IP=192.168.100.10	OPERATION=Register App Master	TARGET=ApplicationMasterService	RESULT=SUCCESS	APPID=application_1376080735992_0001	APPATTEMPTID=appattempt_1376080735992_0001_000001
2013-08-09 20:41:29,384 INFO org.apache.hadoop.yarn.server.resourcemanager.rmapp.attempt.RMAppAttemptImpl: appattempt_1376080735992_0001_000001 State change from LAUNCHED to RUNNING
2013-08-09 20:41:29,384 INFO org.apache.hadoop.yarn.server.resourcemanager.rmapp.RMAppImpl: application_1376080735992_0001 State change from ACCEPTED to RUNNING
2013-08-09 20:41:30,867 INFO org.apache.hadoop.yarn.server.resourcemanager.rmcontainer.RMContainerImpl: container_1376080735992_0001_01_000002 Container Transitioned from NEW to ALLOCATED
2013-08-09 20:41:30,868 INFO org.apache.hadoop.yarn.server.resourcemanager.RMAuditLogger: USER=ubuntu	OPERATION=AM Allocated Container	TARGET=SchedulerApp	RESULT=SUCCESS	APPID=application_1376080735992_0001	CONTAINERID=container_1376080735992_0001_01_000002
2013-08-09 20:41:30,868 INFO org.apache.hadoop.yarn.server.resourcemanager.scheduler.common.fica.FiCaSchedulerNode: Assigned container container_1376080735992_0001_01_000002 of capacity <memory:1024, vCores:1> on host hadoop-210-6:41207, which currently has 1 containers, <memory:1024, vCores:1> used and <memory:7168, vCores:15> available
2013-08-09 20:41:30,870 INFO org.apache.hadoop.yarn.server.resourcemanager.scheduler.capacity.LeafQueue: assignedContainer application=application_1376080735992_0001 container=Container: [ContainerId: container_1376080735992_0001_01_000002, NodeId: hadoop-210-6:41207, NodeHttpAddress: hadoop-210-6:8042, Resource: <memory:1024, vCores:1>, Priority: 20, State: NEW, Token: null, Status: container_id {, app_attempt_id {, application_id {, id: 1, cluster_timestamp: 1376080735992, }, attemptId: 1, }, id: 2, }, state: C_NEW, ] containerId=container_1376080735992_0001_01_000002 queue=default: capacity=1.0, absoluteCapacity=1.0, usedResources=<memory:2048, vCores:1>usedCapacity=0.041666668, absoluteUsedCapacity=0.041666668, numApps=1, numContainers=1 usedCapacity=0.041666668 absoluteUsedCapacity=0.041666668 used=<memory:2048, vCores:1> cluster=<memory:49152, vCores:96>
2013-08-09 20:41:30,870 INFO org.apache.hadoop.yarn.server.resourcemanager.scheduler.capacity.ParentQueue: Re-sorting queues since queue: root.default stats: default: capacity=1.0, absoluteCapacity=1.0, usedResources=<memory:3072, vCores:2>usedCapacity=0.0625, absoluteUsedCapacity=0.0625, numApps=1, numContainers=2
2013-08-09 20:41:30,871 INFO org.apache.hadoop.yarn.server.resourcemanager.scheduler.capacity.ParentQueue: assignedContainer queue=root usedCapacity=0.0625 absoluteUsedCapacity=0.0625 used=<memory:3072, vCores:2> cluster=<memory:49152, vCores:96>
2013-08-09 20:41:30,875 INFO org.apache.hadoop.yarn.server.resourcemanager.rmcontainer.RMContainerImpl: container_1376080735992_0001_01_000003 Container Transitioned from NEW to ALLOCATED
2013-08-09 20:41:30,875 INFO org.apache.hadoop.yarn.server.resourcemanager.RMAuditLogger: USER=ubuntu	OPERATION=AM Allocated Container	TARGET=SchedulerApp	RESULT=SUCCESS	APPID=application_1376080735992_0001	CONTAINERID=container_1376080735992_0001_01_000003
2013-08-09 20:41:30,875 INFO org.apache.hadoop.yarn.server.resourcemanager.scheduler.common.fica.FiCaSchedulerNode: Assigned container container_1376080735992_0001_01_000003 of capacity <memory:1024, vCores:1> on host hadoop-210-2:51035, which currently has 1 containers, <memory:1024, vCores:1> used and <memory:7168, vCores:15> available
2013-08-09 20:41:30,877 INFO org.apache.hadoop.yarn.server.resourcemanager.scheduler.capacity.LeafQueue: assignedContainer application=application_1376080735992_0001 container=Container: [ContainerId: container_1376080735992_0001_01_000003, NodeId: hadoop-210-2:51035, NodeHttpAddress: hadoop-210-2:8042, Resource: <memory:1024, vCores:1>, Priority: 20, State: NEW, Token: null, Status: container_id {, app_attempt_id {, application_id {, id: 1, cluster_timestamp: 1376080735992, }, attemptId: 1, }, id: 3, }, state: C_NEW, ] containerId=container_1376080735992_0001_01_000003 queue=default: capacity=1.0, absoluteCapacity=1.0, usedResources=<memory:3072, vCores:2>usedCapacity=0.0625, absoluteUsedCapacity=0.0625, numApps=1, numContainers=2 usedCapacity=0.0625 absoluteUsedCapacity=0.0625 used=<memory:3072, vCores:2> cluster=<memory:49152, vCores:96>
2013-08-09 20:41:30,877 INFO org.apache.hadoop.yarn.server.resourcemanager.scheduler.capacity.ParentQueue: Re-sorting queues since queue: root.default stats: default: capacity=1.0, absoluteCapacity=1.0, usedResources=<memory:4096, vCores:3>usedCapacity=0.083333336, absoluteUsedCapacity=0.083333336, numApps=1, numContainers=3
2013-08-09 20:41:30,878 INFO org.apache.hadoop.yarn.server.resourcemanager.scheduler.capacity.ParentQueue: assignedContainer queue=root usedCapacity=0.083333336 absoluteUsedCapacity=0.083333336 used=<memory:4096, vCores:3> cluster=<memory:49152, vCores:96>
2013-08-09 20:41:31,471 INFO org.apache.hadoop.yarn.server.resourcemanager.rmcontainer.RMContainerImpl: container_1376080735992_0001_01_000002 Container Transitioned from ALLOCATED to ACQUIRED
2013-08-09 20:41:31,473 INFO org.apache.hadoop.yarn.server.resourcemanager.rmcontainer.RMContainerImpl: container_1376080735992_0001_01_000003 Container Transitioned from ALLOCATED to ACQUIRED
2013-08-09 20:41:32,510 INFO org.apache.hadoop.yarn.server.resourcemanager.scheduler.AppSchedulingInfo: checking for deactivate... 
2013-08-09 20:41:32,975 INFO org.apache.hadoop.yarn.server.resourcemanager.rmcontainer.RMContainerImpl: container_1376080735992_0001_01_000003 Container Transitioned from ACQUIRED to RUNNING
2013-08-09 20:41:32,985 INFO org.apache.hadoop.yarn.server.resourcemanager.rmcontainer.RMContainerImpl: container_1376080735992_0001_01_000002 Container Transitioned from ACQUIRED to RUNNING
2013-08-09 20:43:21,695 INFO org.apache.hadoop.yarn.server.resourcemanager.rmcontainer.RMContainerImpl: container_1376080735992_0001_01_000002 Container Transitioned from RUNNING to COMPLETED
2013-08-09 20:43:21,695 INFO org.apache.hadoop.yarn.server.resourcemanager.scheduler.common.fica.FiCaSchedulerApp: Completed container: container_1376080735992_0001_01_000002 in state: COMPLETED event:FINISHED
2013-08-09 20:43:21,695 INFO org.apache.hadoop.yarn.server.resourcemanager.RMAuditLogger: USER=ubuntu	OPERATION=AM Released Container	TARGET=SchedulerApp	RESULT=SUCCESS	APPID=application_1376080735992_0001	CONTAINERID=container_1376080735992_0001_01_000002
2013-08-09 20:43:21,696 INFO org.apache.hadoop.yarn.server.resourcemanager.scheduler.common.fica.FiCaSchedulerNode: Released container container_1376080735992_0001_01_000002 of capacity <memory:1024, vCores:1> on host hadoop-210-6:41207, which currently has 0 containers, <memory:0, vCores:0> used and <memory:8192, vCores:16> available, release resources=true
2013-08-09 20:43:21,696 INFO org.apache.hadoop.yarn.server.resourcemanager.scheduler.capacity.LeafQueue: default used=<memory:3072, vCores:2> numContainers=2 user=ubuntu user-resources=<memory:3072, vCores:2>
2013-08-09 20:43:21,698 INFO org.apache.hadoop.yarn.server.resourcemanager.scheduler.capacity.LeafQueue: completedContainer container=Container: [ContainerId: container_1376080735992_0001_01_000002, NodeId: hadoop-210-6:41207, NodeHttpAddress: hadoop-210-6:8042, Resource: <memory:1024, vCores:1>, Priority: 20, State: NEW, Token: null, Status: container_id {, app_attempt_id {, application_id {, id: 1, cluster_timestamp: 1376080735992, }, attemptId: 1, }, id: 2, }, state: C_COMPLETE, diagnostics: "Container killed by the ApplicationMaster.\n\n", exit_status: 143, ] resource=<memory:1024, vCores:1> queue=default: capacity=1.0, absoluteCapacity=1.0, usedResources=<memory:3072, vCores:2>usedCapacity=0.0625, absoluteUsedCapacity=0.0625, numApps=1, numContainers=2 usedCapacity=0.0625 absoluteUsedCapacity=0.0625 used=<memory:3072, vCores:2> cluster=<memory:49152, vCores:96>
2013-08-09 20:43:21,699 INFO org.apache.hadoop.yarn.server.resourcemanager.scheduler.capacity.ParentQueue: completedContainer queue=root usedCapacity=0.0625 absoluteUsedCapacity=0.0625 used=<memory:3072, vCores:2> cluster=<memory:49152, vCores:96>
2013-08-09 20:43:21,699 INFO org.apache.hadoop.yarn.server.resourcemanager.scheduler.capacity.CapacityScheduler: Application appattempt_1376080735992_0001_000001 released container container_1376080735992_0001_01_000002 on node: host: hadoop-210-6:41207 #containers=0 available=8192 used=0 with event: FINISHED
2013-08-09 20:43:22,191 INFO org.apache.hadoop.yarn.server.resourcemanager.rmcontainer.RMContainerImpl: container_1376080735992_0001_01_000003 Container Transitioned from RUNNING to COMPLETED
2013-08-09 20:43:22,192 INFO org.apache.hadoop.yarn.server.resourcemanager.scheduler.common.fica.FiCaSchedulerApp: Completed container: container_1376080735992_0001_01_000003 in state: COMPLETED event:FINISHED
2013-08-09 20:43:22,192 INFO org.apache.hadoop.yarn.server.resourcemanager.RMAuditLogger: USER=ubuntu	OPERATION=AM Released Container	TARGET=SchedulerApp	RESULT=SUCCESS	APPID=application_1376080735992_0001	CONTAINERID=container_1376080735992_0001_01_000003
2013-08-09 20:43:22,192 INFO org.apache.hadoop.yarn.server.resourcemanager.scheduler.common.fica.FiCaSchedulerNode: Released container container_1376080735992_0001_01_000003 of capacity <memory:1024, vCores:1> on host hadoop-210-2:51035, which currently has 0 containers, <memory:0, vCores:0> used and <memory:8192, vCores:16> available, release resources=true
2013-08-09 20:43:22,192 INFO org.apache.hadoop.yarn.server.resourcemanager.scheduler.capacity.LeafQueue: default used=<memory:2048, vCores:1> numContainers=1 user=ubuntu user-resources=<memory:2048, vCores:1>
2013-08-09 20:43:22,194 INFO org.apache.hadoop.yarn.server.resourcemanager.scheduler.capacity.LeafQueue: completedContainer container=Container: [ContainerId: container_1376080735992_0001_01_000003, NodeId: hadoop-210-2:51035, NodeHttpAddress: hadoop-210-2:8042, Resource: <memory:1024, vCores:1>, Priority: 20, State: NEW, Token: null, Status: container_id {, app_attempt_id {, application_id {, id: 1, cluster_timestamp: 1376080735992, }, attemptId: 1, }, id: 3, }, state: C_COMPLETE, diagnostics: "Container killed by the ApplicationMaster.\n\n", exit_status: 143, ] resource=<memory:1024, vCores:1> queue=default: capacity=1.0, absoluteCapacity=1.0, usedResources=<memory:2048, vCores:1>usedCapacity=0.041666668, absoluteUsedCapacity=0.041666668, numApps=1, numContainers=1 usedCapacity=0.041666668 absoluteUsedCapacity=0.041666668 used=<memory:2048, vCores:1> cluster=<memory:49152, vCores:96>
2013-08-09 20:43:22,195 INFO org.apache.hadoop.yarn.server.resourcemanager.scheduler.capacity.ParentQueue: completedContainer queue=root usedCapacity=0.041666668 absoluteUsedCapacity=0.041666668 used=<memory:2048, vCores:1> cluster=<memory:49152, vCores:96>
2013-08-09 20:43:22,195 INFO org.apache.hadoop.yarn.server.resourcemanager.scheduler.capacity.CapacityScheduler: Application appattempt_1376080735992_0001_000001 released container container_1376080735992_0001_01_000003 on node: host: hadoop-210-2:51035 #containers=0 available=8192 used=0 with event: FINISHED
2013-08-09 20:43:26,350 INFO org.apache.hadoop.yarn.server.resourcemanager.rmapp.attempt.RMAppAttemptImpl: appattempt_1376080735992_0001_000001 State change from RUNNING to FINISHING
2013-08-09 20:43:26,351 INFO org.apache.hadoop.yarn.server.resourcemanager.rmapp.RMAppImpl: application_1376080735992_0001 State change from RUNNING to FINISHING
2013-08-09 20:43:26,842 INFO org.apache.hadoop.yarn.server.resourcemanager.rmcontainer.RMContainerImpl: container_1376080735992_0001_01_000001 Container Transitioned from RUNNING to COMPLETED
2013-08-09 20:43:26,842 INFO org.apache.hadoop.yarn.server.resourcemanager.scheduler.common.fica.FiCaSchedulerApp: Completed container: container_1376080735992_0001_01_000001 in state: COMPLETED event:FINISHED
2013-08-09 20:43:26,842 INFO org.apache.hadoop.yarn.server.resourcemanager.RMAuditLogger: USER=ubuntu	OPERATION=AM Released Container	TARGET=SchedulerApp	RESULT=SUCCESS	APPID=application_1376080735992_0001	CONTAINERID=container_1376080735992_0001_01_000001
2013-08-09 20:43:26,842 INFO org.apache.hadoop.yarn.server.resourcemanager.scheduler.common.fica.FiCaSchedulerNode: Released container container_1376080735992_0001_01_000001 of capacity <memory:2048, vCores:1> on host hadoop-210-3:58589, which currently has 0 containers, <memory:0, vCores:0> used and <memory:8192, vCores:16> available, release resources=true
2013-08-09 20:43:26,843 INFO org.apache.hadoop.yarn.server.resourcemanager.scheduler.capacity.LeafQueue: default used=<memory:0, vCores:0> numContainers=0 user=ubuntu user-resources=<memory:0, vCores:0>
2013-08-09 20:43:26,844 INFO org.apache.hadoop.yarn.server.resourcemanager.scheduler.capacity.LeafQueue: completedContainer container=Container: [ContainerId: container_1376080735992_0001_01_000001, NodeId: hadoop-210-3:58589, NodeHttpAddress: hadoop-210-3:8042, Resource: <memory:2048, vCores:1>, Priority: 0, State: NEW, Token: null, Status: container_id {, app_attempt_id {, application_id {, id: 1, cluster_timestamp: 1376080735992, }, attemptId: 1, }, id: 1, }, state: C_COMPLETE, diagnostics: "", exit_status: 0, ] resource=<memory:2048, vCores:1> queue=default: capacity=1.0, absoluteCapacity=1.0, usedResources=<memory:0, vCores:0>usedCapacity=0.0, absoluteUsedCapacity=0.0, numApps=1, numContainers=0 usedCapacity=0.0 absoluteUsedCapacity=0.0 used=<memory:0, vCores:0> cluster=<memory:49152, vCores:96>
2013-08-09 20:43:26,844 INFO org.apache.hadoop.yarn.server.resourcemanager.scheduler.capacity.ParentQueue: completedContainer queue=root usedCapacity=0.0 absoluteUsedCapacity=0.0 used=<memory:0, vCores:0> cluster=<memory:49152, vCores:96>
2013-08-09 20:43:26,845 INFO org.apache.hadoop.yarn.server.resourcemanager.scheduler.capacity.CapacityScheduler: Application appattempt_1376080735992_0001_000001 released container container_1376080735992_0001_01_000001 on node: host: hadoop-210-3:58589 #containers=0 available=8192 used=0 with event: FINISHED
2013-08-09 20:43:26,848 INFO org.apache.hadoop.yarn.server.resourcemanager.rmapp.attempt.RMAppAttemptImpl: appattempt_1376080735992_0001_000001 State change from FINISHING to FINISHED
2013-08-09 20:43:26,850 INFO org.apache.hadoop.yarn.server.resourcemanager.rmapp.RMAppImpl: application_1376080735992_0001 State change from FINISHING to FINISHED
2013-08-09 20:43:26,850 INFO org.apache.hadoop.yarn.server.resourcemanager.scheduler.capacity.CapacityScheduler: Application appattempt_1376080735992_0001_000001 is done. finalState=FINISHED
2013-08-09 20:43:26,851 INFO org.apache.hadoop.yarn.server.resourcemanager.scheduler.AppSchedulingInfo: Application application_1376080735992_0001 requests cleared
2013-08-09 20:43:26,859 INFO org.apache.hadoop.yarn.server.resourcemanager.RMAuditLogger: USER=ubuntu	OPERATION=Application Finished - Succeeded	TARGET=RMAppManager	RESULT=SUCCESS	APPID=application_1376080735992_0001
2013-08-09 20:43:26,860 INFO org.apache.hadoop.yarn.server.resourcemanager.scheduler.capacity.LeafQueue: Application removed - appId: application_1376080735992_0001 user: ubuntu queue: default #user-pending-applications: 0 #user-active-applications: 0 #queue-pending-applications: 0 #queue-active-applications: 0
2013-08-09 20:43:26,860 INFO org.apache.hadoop.yarn.server.resourcemanager.scheduler.capacity.ParentQueue: Application removed - appId: application_1376080735992_0001 user: ubuntu leaf-queue of parent: root #applications: 0
2013-08-09 20:43:26,863 INFO org.apache.hadoop.yarn.server.resourcemanager.amlauncher.AMLauncher: Cleaning master appattempt_1376080735992_0001_000001
2013-08-09 20:43:26,864 INFO org.apache.hadoop.yarn.server.resourcemanager.recovery.RMStateStore: Removing info for app: application_1376080735992_0001
2013-08-09 20:43:26,869 INFO org.apache.hadoop.yarn.server.resourcemanager.RMAppManager$ApplicationSummary: appId=application_1376080735992_0001,name=TeraGen,user=ubuntu,queue=default,state=FINISHED,trackingUrl=hadoop-210-1.novalocal:8088/proxy/application_1376080735992_0001/jobhistory/job/job_1376080735992_0001,appMasterHost=hadoop-210-3,startTime=1376080879620,finishTime=1376081006351
2013-08-09 20:43:27,820 INFO org.apache.hadoop.yarn.server.resourcemanager.ClientRMService: Allocated new applicationId: 2
2013-08-09 20:43:29,745 INFO org.apache.hadoop.yarn.server.resourcemanager.ClientRMService: Storing Application with id application_1376080735992_0002
2013-08-09 20:43:29,746 INFO org.apache.hadoop.yarn.server.resourcemanager.recovery.RMStateStore: Storing info for app: application_1376080735992_0002
2013-08-09 20:43:29,746 INFO org.apache.hadoop.yarn.server.resourcemanager.ClientRMService: Application with id 2 submitted by user ubuntu
2013-08-09 20:43:29,746 INFO org.apache.hadoop.yarn.server.resourcemanager.RMAuditLogger: USER=ubuntu	IP=192.168.100.4	OPERATION=Submit Application Request	TARGET=ClientRMService	RESULT=SUCCESS	APPID=application_1376080735992_0002
2013-08-09 20:43:29,749 INFO org.apache.hadoop.yarn.server.resourcemanager.rmapp.RMAppImpl: application_1376080735992_0002 State change from NEW to SUBMITTED
2013-08-09 20:43:29,749 INFO org.apache.hadoop.yarn.server.resourcemanager.ApplicationMasterService: Registering appattempt_1376080735992_0002_000001
2013-08-09 20:43:29,750 INFO org.apache.hadoop.yarn.server.resourcemanager.rmapp.attempt.RMAppAttemptImpl: appattempt_1376080735992_0002_000001 State change from NEW to SUBMITTED
2013-08-09 20:43:29,750 INFO org.apache.hadoop.yarn.server.resourcemanager.scheduler.capacity.LeafQueue: Application application_1376080735992_0002 from user: ubuntu activated in queue: default
2013-08-09 20:43:29,751 INFO org.apache.hadoop.yarn.server.resourcemanager.scheduler.capacity.LeafQueue: Application added - appId: application_1376080735992_0002 user: org.apache.hadoop.yarn.server.resourcemanager.scheduler.capacity.LeafQueue$User@7f603546, leaf-queue: default #user-pending-applications: 0 #user-active-applications: 1 #queue-pending-applications: 0 #queue-active-applications: 1
2013-08-09 20:43:29,751 INFO org.apache.hadoop.yarn.server.resourcemanager.scheduler.capacity.ParentQueue: Application added - appId: application_1376080735992_0002 user: ubuntu leaf-queue of parent: root #applications: 1
2013-08-09 20:43:29,751 INFO org.apache.hadoop.yarn.server.resourcemanager.scheduler.capacity.CapacityScheduler: Application Submission: appattempt_1376080735992_0002_000001, user: ubuntu queue: default: capacity=1.0, absoluteCapacity=1.0, usedResources=<memory:0, vCores:0>usedCapacity=0.0, absoluteUsedCapacity=0.0, numApps=1, numContainers=0, currently active: 1
2013-08-09 20:43:29,752 INFO org.apache.hadoop.yarn.server.resourcemanager.rmapp.attempt.RMAppAttemptImpl: appattempt_1376080735992_0002_000001 State change from SUBMITTED to SCHEDULED
2013-08-09 20:43:29,752 INFO org.apache.hadoop.yarn.server.resourcemanager.rmapp.RMAppImpl: application_1376080735992_0002 State change from SUBMITTED to ACCEPTED
2013-08-09 20:43:29,855 INFO org.apache.hadoop.yarn.server.resourcemanager.rmcontainer.RMContainerImpl: container_1376080735992_0002_01_000001 Container Transitioned from NEW to ALLOCATED
2013-08-09 20:43:29,855 INFO org.apache.hadoop.yarn.server.resourcemanager.RMAuditLogger: USER=ubuntu	OPERATION=AM Allocated Container	TARGET=SchedulerApp	RESULT=SUCCESS	APPID=application_1376080735992_0002	CONTAINERID=container_1376080735992_0002_01_000001
2013-08-09 20:43:29,855 INFO org.apache.hadoop.yarn.server.resourcemanager.scheduler.common.fica.FiCaSchedulerNode: Assigned container container_1376080735992_0002_01_000001 of capacity <memory:2048, vCores:1> on host hadoop-210-3:58589, which currently has 1 containers, <memory:2048, vCores:1> used and <memory:6144, vCores:15> available
2013-08-09 20:43:29,857 INFO org.apache.hadoop.yarn.server.resourcemanager.scheduler.capacity.LeafQueue: assignedContainer application=application_1376080735992_0002 container=Container: [ContainerId: container_1376080735992_0002_01_000001, NodeId: hadoop-210-3:58589, NodeHttpAddress: hadoop-210-3:8042, Resource: <memory:2048, vCores:1>, Priority: 0, State: NEW, Token: null, Status: container_id {, app_attempt_id {, application_id {, id: 2, cluster_timestamp: 1376080735992, }, attemptId: 1, }, id: 1, }, state: C_NEW, ] containerId=container_1376080735992_0002_01_000001 queue=default: capacity=1.0, absoluteCapacity=1.0, usedResources=<memory:0, vCores:0>usedCapacity=0.0, absoluteUsedCapacity=0.0, numApps=1, numContainers=0 usedCapacity=0.0 absoluteUsedCapacity=0.0 used=<memory:0, vCores:0> cluster=<memory:49152, vCores:96>
2013-08-09 20:43:29,857 INFO org.apache.hadoop.yarn.server.resourcemanager.scheduler.capacity.ParentQueue: Re-sorting queues since queue: root.default stats: default: capacity=1.0, absoluteCapacity=1.0, usedResources=<memory:2048, vCores:1>usedCapacity=0.041666668, absoluteUsedCapacity=0.041666668, numApps=1, numContainers=1
2013-08-09 20:43:29,858 INFO org.apache.hadoop.yarn.server.resourcemanager.scheduler.capacity.ParentQueue: assignedContainer queue=root usedCapacity=0.041666668 absoluteUsedCapacity=0.041666668 used=<memory:2048, vCores:1> cluster=<memory:49152, vCores:96>
2013-08-09 20:43:29,863 INFO org.apache.hadoop.yarn.server.resourcemanager.rmcontainer.RMContainerImpl: container_1376080735992_0002_01_000001 Container Transitioned from ALLOCATED to ACQUIRED
2013-08-09 20:43:29,865 INFO org.apache.hadoop.yarn.server.resourcemanager.rmapp.attempt.RMAppAttemptImpl: Storing attempt: AppId: application_1376080735992_0002 AttemptId: appattempt_1376080735992_0002_000001 MasterContainer: Container: [ContainerId: container_1376080735992_0002_01_000001, NodeId: hadoop-210-3:58589, NodeHttpAddress: hadoop-210-3:8042, Resource: <memory:2048, vCores:1>, Priority: 0, State: NEW, Token: null, Status: container_id {, app_attempt_id {, application_id {, id: 2, cluster_timestamp: 1376080735992, }, attemptId: 1, }, id: 1, }, state: C_NEW, ]
2013-08-09 20:43:29,865 INFO org.apache.hadoop.yarn.server.resourcemanager.rmapp.attempt.RMAppAttemptImpl: appattempt_1376080735992_0002_000001 State change from SCHEDULED to ALLOCATED_SAVING
2013-08-09 20:43:29,865 INFO org.apache.hadoop.yarn.server.resourcemanager.recovery.RMStateStore: Storing info for attempt: appattempt_1376080735992_0002_000001
2013-08-09 20:43:29,872 INFO org.apache.hadoop.yarn.server.resourcemanager.rmapp.attempt.RMAppAttemptImpl: appattempt_1376080735992_0002_000001 State change from ALLOCATED_SAVING to ALLOCATED
2013-08-09 20:43:29,874 INFO org.apache.hadoop.yarn.server.resourcemanager.amlauncher.AMLauncher: Launching masterappattempt_1376080735992_0002_000001
2013-08-09 20:43:29,877 INFO org.apache.hadoop.yarn.server.resourcemanager.amlauncher.AMLauncher: Setting up container Container: [ContainerId: container_1376080735992_0002_01_000001, NodeId: hadoop-210-3:58589, NodeHttpAddress: hadoop-210-3:8042, Resource: <memory:2048, vCores:1>, Priority: 0, State: NEW, Token: null, Status: container_id {, app_attempt_id {, application_id {, id: 2, cluster_timestamp: 1376080735992, }, attemptId: 1, }, id: 1, }, state: C_NEW, ] for AM appattempt_1376080735992_0002_000001
2013-08-09 20:43:29,877 INFO org.apache.hadoop.yarn.server.resourcemanager.amlauncher.AMLauncher: Command to launch container container_1376080735992_0002_01_000001 : $JAVA_HOME/bin/java -Dlog4j.configuration=container-log4j.properties -Dyarn.app.mapreduce.container.log.dir=<LOG_DIR> -Dyarn.app.mapreduce.container.log.filesize=0 -Dhadoop.root.logger=INFO,CLA  -Xmx1024m org.apache.hadoop.mapreduce.v2.app.MRAppMaster 1><LOG_DIR>/stdout 2><LOG_DIR>/stderr 
2013-08-09 20:43:29,896 INFO org.apache.hadoop.yarn.server.resourcemanager.amlauncher.AMLauncher: Done launching container Container: [ContainerId: container_1376080735992_0002_01_000001, NodeId: hadoop-210-3:58589, NodeHttpAddress: hadoop-210-3:8042, Resource: <memory:2048, vCores:1>, Priority: 0, State: NEW, Token: null, Status: container_id {, app_attempt_id {, application_id {, id: 2, cluster_timestamp: 1376080735992, }, attemptId: 1, }, id: 1, }, state: C_NEW, ] for AM appattempt_1376080735992_0002_000001
2013-08-09 20:43:29,897 INFO org.apache.hadoop.yarn.server.resourcemanager.rmapp.attempt.RMAppAttemptImpl: appattempt_1376080735992_0002_000001 State change from ALLOCATED to LAUNCHED
2013-08-09 20:43:31,290 INFO org.apache.hadoop.yarn.server.resourcemanager.rmcontainer.RMContainerImpl: container_1376080735992_0002_01_000001 Container Transitioned from ACQUIRED to RUNNING
2013-08-09 20:43:36,008 INFO org.apache.hadoop.yarn.server.resourcemanager.ApplicationMasterService: AM registration appattempt_1376080735992_0002_000001
2013-08-09 20:43:36,008 INFO org.apache.hadoop.yarn.server.resourcemanager.RMAuditLogger: USER=ubuntu	IP=192.168.100.10	OPERATION=Register App Master	TARGET=ApplicationMasterService	RESULT=SUCCESS	APPID=application_1376080735992_0002	APPATTEMPTID=appattempt_1376080735992_0002_000001
2013-08-09 20:43:36,024 INFO org.apache.hadoop.yarn.server.resourcemanager.rmapp.attempt.RMAppAttemptImpl: appattempt_1376080735992_0002_000001 State change from LAUNCHED to RUNNING
2013-08-09 20:43:36,024 INFO org.apache.hadoop.yarn.server.resourcemanager.rmapp.RMAppImpl: application_1376080735992_0002 State change from ACCEPTED to RUNNING
2013-08-09 20:43:37,252 INFO org.apache.hadoop.yarn.server.resourcemanager.rmcontainer.RMContainerImpl: container_1376080735992_0002_01_000002 Container Transitioned from NEW to ALLOCATED
2013-08-09 20:43:37,253 INFO org.apache.hadoop.yarn.server.resourcemanager.RMAuditLogger: USER=ubuntu	OPERATION=AM Allocated Container	TARGET=SchedulerApp	RESULT=SUCCESS	APPID=application_1376080735992_0002	CONTAINERID=container_1376080735992_0002_01_000002
2013-08-09 20:43:37,253 INFO org.apache.hadoop.yarn.server.resourcemanager.scheduler.common.fica.FiCaSchedulerNode: Assigned container container_1376080735992_0002_01_000002 of capacity <memory:1024, vCores:1> on host hadoop-210-2:51035, which currently has 1 containers, <memory:1024, vCores:1> used and <memory:7168, vCores:15> available
2013-08-09 20:43:37,255 INFO org.apache.hadoop.yarn.server.resourcemanager.scheduler.capacity.LeafQueue: assignedContainer application=application_1376080735992_0002 container=Container: [ContainerId: container_1376080735992_0002_01_000002, NodeId: hadoop-210-2:51035, NodeHttpAddress: hadoop-210-2:8042, Resource: <memory:1024, vCores:1>, Priority: 20, State: NEW, Token: null, Status: container_id {, app_attempt_id {, application_id {, id: 2, cluster_timestamp: 1376080735992, }, attemptId: 1, }, id: 2, }, state: C_NEW, ] containerId=container_1376080735992_0002_01_000002 queue=default: capacity=1.0, absoluteCapacity=1.0, usedResources=<memory:2048, vCores:1>usedCapacity=0.041666668, absoluteUsedCapacity=0.041666668, numApps=1, numContainers=1 usedCapacity=0.041666668 absoluteUsedCapacity=0.041666668 used=<memory:2048, vCores:1> cluster=<memory:49152, vCores:96>
2013-08-09 20:43:37,256 INFO org.apache.hadoop.yarn.server.resourcemanager.scheduler.capacity.ParentQueue: Re-sorting queues since queue: root.default stats: default: capacity=1.0, absoluteCapacity=1.0, usedResources=<memory:3072, vCores:2>usedCapacity=0.0625, absoluteUsedCapacity=0.0625, numApps=1, numContainers=2
2013-08-09 20:43:37,256 INFO org.apache.hadoop.yarn.server.resourcemanager.scheduler.capacity.ParentQueue: assignedContainer queue=root usedCapacity=0.0625 absoluteUsedCapacity=0.0625 used=<memory:3072, vCores:2> cluster=<memory:49152, vCores:96>
2013-08-09 20:43:37,323 INFO org.apache.hadoop.yarn.server.resourcemanager.rmcontainer.RMContainerImpl: container_1376080735992_0002_01_000003 Container Transitioned from NEW to ALLOCATED
2013-08-09 20:43:37,323 INFO org.apache.hadoop.yarn.server.resourcemanager.RMAuditLogger: USER=ubuntu	OPERATION=AM Allocated Container	TARGET=SchedulerApp	RESULT=SUCCESS	APPID=application_1376080735992_0002	CONTAINERID=container_1376080735992_0002_01_000003
2013-08-09 20:43:37,324 INFO org.apache.hadoop.yarn.server.resourcemanager.scheduler.common.fica.FiCaSchedulerNode: Assigned container container_1376080735992_0002_01_000003 of capacity <memory:1024, vCores:1> on host hadoop-210-3:58589, which currently has 2 containers, <memory:3072, vCores:2> used and <memory:5120, vCores:14> available
2013-08-09 20:43:37,325 INFO org.apache.hadoop.yarn.server.resourcemanager.scheduler.capacity.LeafQueue: assignedContainer application=application_1376080735992_0002 container=Container: [ContainerId: container_1376080735992_0002_01_000003, NodeId: hadoop-210-3:58589, NodeHttpAddress: hadoop-210-3:8042, Resource: <memory:1024, vCores:1>, Priority: 20, State: NEW, Token: null, Status: container_id {, app_attempt_id {, application_id {, id: 2, cluster_timestamp: 1376080735992, }, attemptId: 1, }, id: 3, }, state: C_NEW, ] containerId=container_1376080735992_0002_01_000003 queue=default: capacity=1.0, absoluteCapacity=1.0, usedResources=<memory:3072, vCores:2>usedCapacity=0.0625, absoluteUsedCapacity=0.0625, numApps=1, numContainers=2 usedCapacity=0.0625 absoluteUsedCapacity=0.0625 used=<memory:3072, vCores:2> cluster=<memory:49152, vCores:96>
2013-08-09 20:43:37,326 INFO org.apache.hadoop.yarn.server.resourcemanager.scheduler.capacity.ParentQueue: Re-sorting queues since queue: root.default stats: default: capacity=1.0, absoluteCapacity=1.0, usedResources=<memory:4096, vCores:3>usedCapacity=0.083333336, absoluteUsedCapacity=0.083333336, numApps=1, numContainers=3
2013-08-09 20:43:37,326 INFO org.apache.hadoop.yarn.server.resourcemanager.scheduler.capacity.ParentQueue: assignedContainer queue=root usedCapacity=0.083333336 absoluteUsedCapacity=0.083333336 used=<memory:4096, vCores:3> cluster=<memory:49152, vCores:96>
2013-08-09 20:43:38,068 INFO org.apache.hadoop.yarn.server.resourcemanager.rmcontainer.RMContainerImpl: container_1376080735992_0002_01_000002 Container Transitioned from ALLOCATED to ACQUIRED
2013-08-09 20:43:38,069 INFO org.apache.hadoop.yarn.server.resourcemanager.rmcontainer.RMContainerImpl: container_1376080735992_0002_01_000003 Container Transitioned from ALLOCATED to ACQUIRED
2013-08-09 20:43:39,098 INFO org.apache.hadoop.yarn.server.resourcemanager.scheduler.AppSchedulingInfo: checking for deactivate... 
2013-08-09 20:43:39,262 INFO org.apache.hadoop.yarn.server.resourcemanager.rmcontainer.RMContainerImpl: container_1376080735992_0002_01_000002 Container Transitioned from ACQUIRED to RUNNING
2013-08-09 20:43:39,338 INFO org.apache.hadoop.yarn.server.resourcemanager.rmcontainer.RMContainerImpl: container_1376080735992_0002_01_000003 Container Transitioned from ACQUIRED to RUNNING
2013-08-09 20:45:21,443 INFO org.apache.hadoop.yarn.server.resourcemanager.rmcontainer.RMContainerImpl: container_1376080735992_0002_01_000003 Container Transitioned from RUNNING to COMPLETED
2013-08-09 20:45:21,443 INFO org.apache.hadoop.yarn.server.resourcemanager.scheduler.common.fica.FiCaSchedulerApp: Completed container: container_1376080735992_0002_01_000003 in state: COMPLETED event:FINISHED
2013-08-09 20:45:21,443 INFO org.apache.hadoop.yarn.server.resourcemanager.RMAuditLogger: USER=ubuntu	OPERATION=AM Released Container	TARGET=SchedulerApp	RESULT=SUCCESS	APPID=application_1376080735992_0002	CONTAINERID=container_1376080735992_0002_01_000003
2013-08-09 20:45:21,443 INFO org.apache.hadoop.yarn.server.resourcemanager.scheduler.common.fica.FiCaSchedulerNode: Released container container_1376080735992_0002_01_000003 of capacity <memory:1024, vCores:1> on host hadoop-210-3:58589, which currently has 1 containers, <memory:2048, vCores:1> used and <memory:6144, vCores:15> available, release resources=true
2013-08-09 20:45:21,444 INFO org.apache.hadoop.yarn.server.resourcemanager.scheduler.capacity.LeafQueue: default used=<memory:3072, vCores:2> numContainers=2 user=ubuntu user-resources=<memory:3072, vCores:2>
2013-08-09 20:45:21,458 INFO org.apache.hadoop.yarn.server.resourcemanager.scheduler.capacity.LeafQueue: completedContainer container=Container: [ContainerId: container_1376080735992_0002_01_000003, NodeId: hadoop-210-3:58589, NodeHttpAddress: hadoop-210-3:8042, Resource: <memory:1024, vCores:1>, Priority: 20, State: NEW, Token: null, Status: container_id {, app_attempt_id {, application_id {, id: 2, cluster_timestamp: 1376080735992, }, attemptId: 1, }, id: 3, }, state: C_COMPLETE, diagnostics: "Container killed by the ApplicationMaster.\n", exit_status: 0, ] resource=<memory:1024, vCores:1> queue=default: capacity=1.0, absoluteCapacity=1.0, usedResources=<memory:3072, vCores:2>usedCapacity=0.0625, absoluteUsedCapacity=0.0625, numApps=1, numContainers=2 usedCapacity=0.0625 absoluteUsedCapacity=0.0625 used=<memory:3072, vCores:2> cluster=<memory:49152, vCores:96>
2013-08-09 20:45:21,458 INFO org.apache.hadoop.yarn.server.resourcemanager.scheduler.capacity.ParentQueue: completedContainer queue=root usedCapacity=0.0625 absoluteUsedCapacity=0.0625 used=<memory:3072, vCores:2> cluster=<memory:49152, vCores:96>
2013-08-09 20:45:21,458 INFO org.apache.hadoop.yarn.server.resourcemanager.scheduler.capacity.CapacityScheduler: Application appattempt_1376080735992_0002_000001 released container container_1376080735992_0002_01_000003 on node: host: hadoop-210-3:58589 #containers=1 available=6144 used=2048 with event: FINISHED
2013-08-09 20:45:25,085 INFO org.apache.hadoop.yarn.server.resourcemanager.rmcontainer.RMContainerImpl: container_1376080735992_0002_01_000002 Container Transitioned from RUNNING to COMPLETED
2013-08-09 20:45:25,085 INFO org.apache.hadoop.yarn.server.resourcemanager.scheduler.common.fica.FiCaSchedulerApp: Completed container: container_1376080735992_0002_01_000002 in state: COMPLETED event:FINISHED
2013-08-09 20:45:25,085 INFO org.apache.hadoop.yarn.server.resourcemanager.RMAuditLogger: USER=ubuntu	OPERATION=AM Released Container	TARGET=SchedulerApp	RESULT=SUCCESS	APPID=application_1376080735992_0002	CONTAINERID=container_1376080735992_0002_01_000002
2013-08-09 20:45:25,085 INFO org.apache.hadoop.yarn.server.resourcemanager.scheduler.common.fica.FiCaSchedulerNode: Released container container_1376080735992_0002_01_000002 of capacity <memory:1024, vCores:1> on host hadoop-210-2:51035, which currently has 0 containers, <memory:0, vCores:0> used and <memory:8192, vCores:16> available, release resources=true
2013-08-09 20:45:25,086 INFO org.apache.hadoop.yarn.server.resourcemanager.scheduler.capacity.LeafQueue: default used=<memory:2048, vCores:1> numContainers=1 user=ubuntu user-resources=<memory:2048, vCores:1>
2013-08-09 20:45:25,088 INFO org.apache.hadoop.yarn.server.resourcemanager.scheduler.capacity.LeafQueue: completedContainer container=Container: [ContainerId: container_1376080735992_0002_01_000002, NodeId: hadoop-210-2:51035, NodeHttpAddress: hadoop-210-2:8042, Resource: <memory:1024, vCores:1>, Priority: 20, State: NEW, Token: null, Status: container_id {, app_attempt_id {, application_id {, id: 2, cluster_timestamp: 1376080735992, }, attemptId: 1, }, id: 2, }, state: C_COMPLETE, diagnostics: "Container killed by the ApplicationMaster.\n\n", exit_status: 143, ] resource=<memory:1024, vCores:1> queue=default: capacity=1.0, absoluteCapacity=1.0, usedResources=<memory:2048, vCores:1>usedCapacity=0.041666668, absoluteUsedCapacity=0.041666668, numApps=1, numContainers=1 usedCapacity=0.041666668 absoluteUsedCapacity=0.041666668 used=<memory:2048, vCores:1> cluster=<memory:49152, vCores:96>
2013-08-09 20:45:25,088 INFO org.apache.hadoop.yarn.server.resourcemanager.scheduler.capacity.ParentQueue: completedContainer queue=root usedCapacity=0.041666668 absoluteUsedCapacity=0.041666668 used=<memory:2048, vCores:1> cluster=<memory:49152, vCores:96>
2013-08-09 20:45:25,088 INFO org.apache.hadoop.yarn.server.resourcemanager.scheduler.capacity.CapacityScheduler: Application appattempt_1376080735992_0002_000001 released container container_1376080735992_0002_01_000002 on node: host: hadoop-210-2:51035 #containers=0 available=8192 used=0 with event: FINISHED
2013-08-09 20:45:29,251 INFO org.apache.hadoop.yarn.server.resourcemanager.rmapp.attempt.RMAppAttemptImpl: appattempt_1376080735992_0002_000001 State change from RUNNING to FINISHING
2013-08-09 20:45:29,252 INFO org.apache.hadoop.yarn.server.resourcemanager.rmapp.RMAppImpl: application_1376080735992_0002 State change from RUNNING to FINISHING
2013-08-09 20:45:29,767 INFO org.apache.hadoop.yarn.server.resourcemanager.rmcontainer.RMContainerImpl: container_1376080735992_0002_01_000001 Container Transitioned from RUNNING to COMPLETED
2013-08-09 20:45:29,767 INFO org.apache.hadoop.yarn.server.resourcemanager.scheduler.common.fica.FiCaSchedulerApp: Completed container: container_1376080735992_0002_01_000001 in state: COMPLETED event:FINISHED
2013-08-09 20:45:29,767 INFO org.apache.hadoop.yarn.server.resourcemanager.RMAuditLogger: USER=ubuntu	OPERATION=AM Released Container	TARGET=SchedulerApp	RESULT=SUCCESS	APPID=application_1376080735992_0002	CONTAINERID=container_1376080735992_0002_01_000001
2013-08-09 20:45:29,767 INFO org.apache.hadoop.yarn.server.resourcemanager.scheduler.common.fica.FiCaSchedulerNode: Released container container_1376080735992_0002_01_000001 of capacity <memory:2048, vCores:1> on host hadoop-210-3:58589, which currently has 0 containers, <memory:0, vCores:0> used and <memory:8192, vCores:16> available, release resources=true
2013-08-09 20:45:29,767 INFO org.apache.hadoop.yarn.server.resourcemanager.scheduler.capacity.LeafQueue: default used=<memory:0, vCores:0> numContainers=0 user=ubuntu user-resources=<memory:0, vCores:0>
2013-08-09 20:45:29,768 INFO org.apache.hadoop.yarn.server.resourcemanager.scheduler.capacity.LeafQueue: completedContainer container=Container: [ContainerId: container_1376080735992_0002_01_000001, NodeId: hadoop-210-3:58589, NodeHttpAddress: hadoop-210-3:8042, Resource: <memory:2048, vCores:1>, Priority: 0, State: NEW, Token: null, Status: container_id {, app_attempt_id {, application_id {, id: 2, cluster_timestamp: 1376080735992, }, attemptId: 1, }, id: 1, }, state: C_COMPLETE, diagnostics: "", exit_status: 0, ] resource=<memory:2048, vCores:1> queue=default: capacity=1.0, absoluteCapacity=1.0, usedResources=<memory:0, vCores:0>usedCapacity=0.0, absoluteUsedCapacity=0.0, numApps=1, numContainers=0 usedCapacity=0.0 absoluteUsedCapacity=0.0 used=<memory:0, vCores:0> cluster=<memory:49152, vCores:96>
2013-08-09 20:45:29,768 INFO org.apache.hadoop.yarn.server.resourcemanager.scheduler.capacity.ParentQueue: completedContainer queue=root usedCapacity=0.0 absoluteUsedCapacity=0.0 used=<memory:0, vCores:0> cluster=<memory:49152, vCores:96>
2013-08-09 20:45:29,768 INFO org.apache.hadoop.yarn.server.resourcemanager.scheduler.capacity.CapacityScheduler: Application appattempt_1376080735992_0002_000001 released container container_1376080735992_0002_01_000001 on node: host: hadoop-210-3:58589 #containers=0 available=8192 used=0 with event: FINISHED
2013-08-09 20:45:29,768 INFO org.apache.hadoop.yarn.server.resourcemanager.rmapp.attempt.RMAppAttemptImpl: appattempt_1376080735992_0002_000001 State change from FINISHING to FINISHED
2013-08-09 20:45:29,769 INFO org.apache.hadoop.yarn.server.resourcemanager.rmapp.RMAppImpl: application_1376080735992_0002 State change from FINISHING to FINISHED
2013-08-09 20:45:29,769 INFO org.apache.hadoop.yarn.server.resourcemanager.scheduler.capacity.CapacityScheduler: Application appattempt_1376080735992_0002_000001 is done. finalState=FINISHED
2013-08-09 20:45:29,769 INFO org.apache.hadoop.yarn.server.resourcemanager.scheduler.AppSchedulingInfo: Application application_1376080735992_0002 requests cleared
2013-08-09 20:45:29,769 INFO org.apache.hadoop.yarn.server.resourcemanager.scheduler.capacity.LeafQueue: Application removed - appId: application_1376080735992_0002 user: ubuntu queue: default #user-pending-applications: 0 #user-active-applications: 0 #queue-pending-applications: 0 #queue-active-applications: 0
2013-08-09 20:45:29,769 INFO org.apache.hadoop.yarn.server.resourcemanager.scheduler.capacity.ParentQueue: Application removed - appId: application_1376080735992_0002 user: ubuntu leaf-queue of parent: root #applications: 0
2013-08-09 20:45:29,769 INFO org.apache.hadoop.yarn.server.resourcemanager.RMAuditLogger: USER=ubuntu	OPERATION=Application Finished - Succeeded	TARGET=RMAppManager	RESULT=SUCCESS	APPID=application_1376080735992_0002
2013-08-09 20:45:29,770 INFO org.apache.hadoop.yarn.server.resourcemanager.RMAppManager$ApplicationSummary: appId=application_1376080735992_0002,name=TeraGen,user=ubuntu,queue=default,state=FINISHED,trackingUrl=hadoop-210-1.novalocal:8088/proxy/application_1376080735992_0002/jobhistory/job/job_1376080735992_0002,appMasterHost=hadoop-210-3,startTime=1376081009745,finishTime=1376081129251
2013-08-09 20:45:29,770 INFO org.apache.hadoop.yarn.server.resourcemanager.recovery.RMStateStore: Removing info for app: application_1376080735992_0002
2013-08-09 20:45:29,770 INFO org.apache.hadoop.yarn.server.resourcemanager.amlauncher.AMLauncher: Cleaning master appattempt_1376080735992_0002_000001
2013-08-09 20:45:30,835 INFO org.apache.hadoop.yarn.server.resourcemanager.ClientRMService: Allocated new applicationId: 3
2013-08-09 20:45:32,751 INFO org.apache.hadoop.yarn.server.resourcemanager.ClientRMService: Storing Application with id application_1376080735992_0003
2013-08-09 20:45:32,751 INFO org.apache.hadoop.yarn.server.resourcemanager.recovery.RMStateStore: Storing info for app: application_1376080735992_0003
2013-08-09 20:45:32,751 INFO org.apache.hadoop.yarn.server.resourcemanager.ClientRMService: Application with id 3 submitted by user ubuntu
2013-08-09 20:45:32,751 INFO org.apache.hadoop.yarn.server.resourcemanager.RMAuditLogger: USER=ubuntu	IP=192.168.100.4	OPERATION=Submit Application Request	TARGET=ClientRMService	RESULT=SUCCESS	APPID=application_1376080735992_0003
2013-08-09 20:45:32,752 INFO org.apache.hadoop.yarn.server.resourcemanager.rmapp.RMAppImpl: application_1376080735992_0003 State change from NEW to SUBMITTED
2013-08-09 20:45:32,752 INFO org.apache.hadoop.yarn.server.resourcemanager.ApplicationMasterService: Registering appattempt_1376080735992_0003_000001
2013-08-09 20:45:32,753 INFO org.apache.hadoop.yarn.server.resourcemanager.rmapp.attempt.RMAppAttemptImpl: appattempt_1376080735992_0003_000001 State change from NEW to SUBMITTED
2013-08-09 20:45:32,753 INFO org.apache.hadoop.yarn.server.resourcemanager.scheduler.capacity.LeafQueue: Application application_1376080735992_0003 from user: ubuntu activated in queue: default
2013-08-09 20:45:32,753 INFO org.apache.hadoop.yarn.server.resourcemanager.scheduler.capacity.LeafQueue: Application added - appId: application_1376080735992_0003 user: org.apache.hadoop.yarn.server.resourcemanager.scheduler.capacity.LeafQueue$User@2aec4bcb, leaf-queue: default #user-pending-applications: 0 #user-active-applications: 1 #queue-pending-applications: 0 #queue-active-applications: 1
2013-08-09 20:45:32,754 INFO org.apache.hadoop.yarn.server.resourcemanager.scheduler.capacity.ParentQueue: Application added - appId: application_1376080735992_0003 user: ubuntu leaf-queue of parent: root #applications: 1
2013-08-09 20:45:32,754 INFO org.apache.hadoop.yarn.server.resourcemanager.scheduler.capacity.CapacityScheduler: Application Submission: appattempt_1376080735992_0003_000001, user: ubuntu queue: default: capacity=1.0, absoluteCapacity=1.0, usedResources=<memory:0, vCores:0>usedCapacity=0.0, absoluteUsedCapacity=0.0, numApps=1, numContainers=0, currently active: 1
2013-08-09 20:45:32,754 INFO org.apache.hadoop.yarn.server.resourcemanager.rmapp.attempt.RMAppAttemptImpl: appattempt_1376080735992_0003_000001 State change from SUBMITTED to SCHEDULED
2013-08-09 20:45:32,755 INFO org.apache.hadoop.yarn.server.resourcemanager.rmapp.RMAppImpl: application_1376080735992_0003 State change from SUBMITTED to ACCEPTED
2013-08-09 20:45:32,779 INFO org.apache.hadoop.yarn.server.resourcemanager.rmcontainer.RMContainerImpl: container_1376080735992_0003_01_000001 Container Transitioned from NEW to ALLOCATED
2013-08-09 20:45:32,779 INFO org.apache.hadoop.yarn.server.resourcemanager.RMAuditLogger: USER=ubuntu	OPERATION=AM Allocated Container	TARGET=SchedulerApp	RESULT=SUCCESS	APPID=application_1376080735992_0003	CONTAINERID=container_1376080735992_0003_01_000001
2013-08-09 20:45:32,779 INFO org.apache.hadoop.yarn.server.resourcemanager.scheduler.common.fica.FiCaSchedulerNode: Assigned container container_1376080735992_0003_01_000001 of capacity <memory:2048, vCores:1> on host hadoop-210-3:58589, which currently has 1 containers, <memory:2048, vCores:1> used and <memory:6144, vCores:15> available
2013-08-09 20:45:32,781 INFO org.apache.hadoop.yarn.server.resourcemanager.scheduler.capacity.LeafQueue: assignedContainer application=application_1376080735992_0003 container=Container: [ContainerId: container_1376080735992_0003_01_000001, NodeId: hadoop-210-3:58589, NodeHttpAddress: hadoop-210-3:8042, Resource: <memory:2048, vCores:1>, Priority: 0, State: NEW, Token: null, Status: container_id {, app_attempt_id {, application_id {, id: 3, cluster_timestamp: 1376080735992, }, attemptId: 1, }, id: 1, }, state: C_NEW, ] containerId=container_1376080735992_0003_01_000001 queue=default: capacity=1.0, absoluteCapacity=1.0, usedResources=<memory:0, vCores:0>usedCapacity=0.0, absoluteUsedCapacity=0.0, numApps=1, numContainers=0 usedCapacity=0.0 absoluteUsedCapacity=0.0 used=<memory:0, vCores:0> cluster=<memory:49152, vCores:96>
2013-08-09 20:45:32,781 INFO org.apache.hadoop.yarn.server.resourcemanager.scheduler.capacity.ParentQueue: Re-sorting queues since queue: root.default stats: default: capacity=1.0, absoluteCapacity=1.0, usedResources=<memory:2048, vCores:1>usedCapacity=0.041666668, absoluteUsedCapacity=0.041666668, numApps=1, numContainers=1
2013-08-09 20:45:32,781 INFO org.apache.hadoop.yarn.server.resourcemanager.scheduler.capacity.ParentQueue: assignedContainer queue=root usedCapacity=0.041666668 absoluteUsedCapacity=0.041666668 used=<memory:2048, vCores:1> cluster=<memory:49152, vCores:96>
2013-08-09 20:45:32,783 INFO org.apache.hadoop.yarn.server.resourcemanager.rmcontainer.RMContainerImpl: container_1376080735992_0003_01_000001 Container Transitioned from ALLOCATED to ACQUIRED
2013-08-09 20:45:32,785 INFO org.apache.hadoop.yarn.server.resourcemanager.rmapp.attempt.RMAppAttemptImpl: Storing attempt: AppId: application_1376080735992_0003 AttemptId: appattempt_1376080735992_0003_000001 MasterContainer: Container: [ContainerId: container_1376080735992_0003_01_000001, NodeId: hadoop-210-3:58589, NodeHttpAddress: hadoop-210-3:8042, Resource: <memory:2048, vCores:1>, Priority: 0, State: NEW, Token: null, Status: container_id {, app_attempt_id {, application_id {, id: 3, cluster_timestamp: 1376080735992, }, attemptId: 1, }, id: 1, }, state: C_NEW, ]
2013-08-09 20:45:32,785 INFO org.apache.hadoop.yarn.server.resourcemanager.rmapp.attempt.RMAppAttemptImpl: appattempt_1376080735992_0003_000001 State change from SCHEDULED to ALLOCATED_SAVING
2013-08-09 20:45:32,785 INFO org.apache.hadoop.yarn.server.resourcemanager.recovery.RMStateStore: Storing info for attempt: appattempt_1376080735992_0003_000001
2013-08-09 20:45:32,786 INFO org.apache.hadoop.yarn.server.resourcemanager.rmapp.attempt.RMAppAttemptImpl: appattempt_1376080735992_0003_000001 State change from ALLOCATED_SAVING to ALLOCATED
2013-08-09 20:45:32,788 INFO org.apache.hadoop.yarn.server.resourcemanager.amlauncher.AMLauncher: Launching masterappattempt_1376080735992_0003_000001
2013-08-09 20:45:32,790 INFO org.apache.hadoop.yarn.server.resourcemanager.amlauncher.AMLauncher: Setting up container Container: [ContainerId: container_1376080735992_0003_01_000001, NodeId: hadoop-210-3:58589, NodeHttpAddress: hadoop-210-3:8042, Resource: <memory:2048, vCores:1>, Priority: 0, State: NEW, Token: null, Status: container_id {, app_attempt_id {, application_id {, id: 3, cluster_timestamp: 1376080735992, }, attemptId: 1, }, id: 1, }, state: C_NEW, ] for AM appattempt_1376080735992_0003_000001
2013-08-09 20:45:32,790 INFO org.apache.hadoop.yarn.server.resourcemanager.amlauncher.AMLauncher: Command to launch container container_1376080735992_0003_01_000001 : $JAVA_HOME/bin/java -Dlog4j.configuration=container-log4j.properties -Dyarn.app.mapreduce.container.log.dir=<LOG_DIR> -Dyarn.app.mapreduce.container.log.filesize=0 -Dhadoop.root.logger=INFO,CLA  -Xmx1024m org.apache.hadoop.mapreduce.v2.app.MRAppMaster 1><LOG_DIR>/stdout 2><LOG_DIR>/stderr 
2013-08-09 20:45:32,806 INFO org.apache.hadoop.yarn.server.resourcemanager.amlauncher.AMLauncher: Done launching container Container: [ContainerId: container_1376080735992_0003_01_000001, NodeId: hadoop-210-3:58589, NodeHttpAddress: hadoop-210-3:8042, Resource: <memory:2048, vCores:1>, Priority: 0, State: NEW, Token: null, Status: container_id {, app_attempt_id {, application_id {, id: 3, cluster_timestamp: 1376080735992, }, attemptId: 1, }, id: 1, }, state: C_NEW, ] for AM appattempt_1376080735992_0003_000001
2013-08-09 20:45:32,806 INFO org.apache.hadoop.yarn.server.resourcemanager.rmapp.attempt.RMAppAttemptImpl: appattempt_1376080735992_0003_000001 State change from ALLOCATED to LAUNCHED
2013-08-09 20:45:33,786 INFO org.apache.hadoop.yarn.server.resourcemanager.rmcontainer.RMContainerImpl: container_1376080735992_0003_01_000001 Container Transitioned from ACQUIRED to RUNNING
2013-08-09 20:45:38,914 INFO org.apache.hadoop.yarn.server.resourcemanager.ApplicationMasterService: AM registration appattempt_1376080735992_0003_000001
2013-08-09 20:45:38,914 INFO org.apache.hadoop.yarn.server.resourcemanager.RMAuditLogger: USER=ubuntu	IP=192.168.100.10	OPERATION=Register App Master	TARGET=ApplicationMasterService	RESULT=SUCCESS	APPID=application_1376080735992_0003	APPATTEMPTID=appattempt_1376080735992_0003_000001
2013-08-09 20:45:38,915 INFO org.apache.hadoop.yarn.server.resourcemanager.rmapp.attempt.RMAppAttemptImpl: appattempt_1376080735992_0003_000001 State change from LAUNCHED to RUNNING
2013-08-09 20:45:38,915 INFO org.apache.hadoop.yarn.server.resourcemanager.rmapp.RMAppImpl: application_1376080735992_0003 State change from ACCEPTED to RUNNING
2013-08-09 20:45:39,955 INFO org.apache.hadoop.yarn.server.resourcemanager.rmcontainer.RMContainerImpl: container_1376080735992_0003_01_000002 Container Transitioned from NEW to ALLOCATED
2013-08-09 20:45:39,956 INFO org.apache.hadoop.yarn.server.resourcemanager.RMAuditLogger: USER=ubuntu	OPERATION=AM Allocated Container	TARGET=SchedulerApp	RESULT=SUCCESS	APPID=application_1376080735992_0003	CONTAINERID=container_1376080735992_0003_01_000002
2013-08-09 20:45:39,956 INFO org.apache.hadoop.yarn.server.resourcemanager.scheduler.common.fica.FiCaSchedulerNode: Assigned container container_1376080735992_0003_01_000002 of capacity <memory:1024, vCores:1> on host hadoop-210-7:35638, which currently has 1 containers, <memory:1024, vCores:1> used and <memory:7168, vCores:15> available
2013-08-09 20:45:39,957 INFO org.apache.hadoop.yarn.server.resourcemanager.scheduler.capacity.LeafQueue: assignedContainer application=application_1376080735992_0003 container=Container: [ContainerId: container_1376080735992_0003_01_000002, NodeId: hadoop-210-7:35638, NodeHttpAddress: hadoop-210-7:8042, Resource: <memory:1024, vCores:1>, Priority: 20, State: NEW, Token: null, Status: container_id {, app_attempt_id {, application_id {, id: 3, cluster_timestamp: 1376080735992, }, attemptId: 1, }, id: 2, }, state: C_NEW, ] containerId=container_1376080735992_0003_01_000002 queue=default: capacity=1.0, absoluteCapacity=1.0, usedResources=<memory:2048, vCores:1>usedCapacity=0.041666668, absoluteUsedCapacity=0.041666668, numApps=1, numContainers=1 usedCapacity=0.041666668 absoluteUsedCapacity=0.041666668 used=<memory:2048, vCores:1> cluster=<memory:49152, vCores:96>
2013-08-09 20:45:39,958 INFO org.apache.hadoop.yarn.server.resourcemanager.scheduler.capacity.ParentQueue: Re-sorting queues since queue: root.default stats: default: capacity=1.0, absoluteCapacity=1.0, usedResources=<memory:3072, vCores:2>usedCapacity=0.0625, absoluteUsedCapacity=0.0625, numApps=1, numContainers=2
2013-08-09 20:45:39,958 INFO org.apache.hadoop.yarn.server.resourcemanager.scheduler.capacity.ParentQueue: assignedContainer queue=root usedCapacity=0.0625 absoluteUsedCapacity=0.0625 used=<memory:3072, vCores:2> cluster=<memory:49152, vCores:96>
2013-08-09 20:45:40,045 INFO org.apache.hadoop.yarn.server.resourcemanager.rmcontainer.RMContainerImpl: container_1376080735992_0003_01_000003 Container Transitioned from NEW to ALLOCATED
2013-08-09 20:45:40,045 INFO org.apache.hadoop.yarn.server.resourcemanager.RMAuditLogger: USER=ubuntu	OPERATION=AM Allocated Container	TARGET=SchedulerApp	RESULT=SUCCESS	APPID=application_1376080735992_0003	CONTAINERID=container_1376080735992_0003_01_000003
2013-08-09 20:45:40,045 INFO org.apache.hadoop.yarn.server.resourcemanager.scheduler.common.fica.FiCaSchedulerNode: Assigned container container_1376080735992_0003_01_000003 of capacity <memory:1024, vCores:1> on host hadoop-210-4:47596, which currently has 1 containers, <memory:1024, vCores:1> used and <memory:7168, vCores:15> available
2013-08-09 20:45:40,047 INFO org.apache.hadoop.yarn.server.resourcemanager.scheduler.capacity.LeafQueue: assignedContainer application=application_1376080735992_0003 container=Container: [ContainerId: container_1376080735992_0003_01_000003, NodeId: hadoop-210-4:47596, NodeHttpAddress: hadoop-210-4:8042, Resource: <memory:1024, vCores:1>, Priority: 20, State: NEW, Token: null, Status: container_id {, app_attempt_id {, application_id {, id: 3, cluster_timestamp: 1376080735992, }, attemptId: 1, }, id: 3, }, state: C_NEW, ] containerId=container_1376080735992_0003_01_000003 queue=default: capacity=1.0, absoluteCapacity=1.0, usedResources=<memory:3072, vCores:2>usedCapacity=0.0625, absoluteUsedCapacity=0.0625, numApps=1, numContainers=2 usedCapacity=0.0625 absoluteUsedCapacity=0.0625 used=<memory:3072, vCores:2> cluster=<memory:49152, vCores:96>
2013-08-09 20:45:40,047 INFO org.apache.hadoop.yarn.server.resourcemanager.scheduler.capacity.ParentQueue: Re-sorting queues since queue: root.default stats: default: capacity=1.0, absoluteCapacity=1.0, usedResources=<memory:4096, vCores:3>usedCapacity=0.083333336, absoluteUsedCapacity=0.083333336, numApps=1, numContainers=3
2013-08-09 20:45:40,047 INFO org.apache.hadoop.yarn.server.resourcemanager.scheduler.capacity.ParentQueue: assignedContainer queue=root usedCapacity=0.083333336 absoluteUsedCapacity=0.083333336 used=<memory:4096, vCores:3> cluster=<memory:49152, vCores:96>
2013-08-09 20:45:40,965 INFO org.apache.hadoop.yarn.server.resourcemanager.rmcontainer.RMContainerImpl: container_1376080735992_0003_01_000002 Container Transitioned from ALLOCATED to ACQUIRED
2013-08-09 20:45:40,967 INFO org.apache.hadoop.yarn.server.resourcemanager.rmcontainer.RMContainerImpl: container_1376080735992_0003_01_000003 Container Transitioned from ALLOCATED to ACQUIRED
2013-08-09 20:45:42,044 INFO org.apache.hadoop.yarn.server.resourcemanager.scheduler.AppSchedulingInfo: checking for deactivate... 
2013-08-09 20:45:42,992 INFO org.apache.hadoop.yarn.server.resourcemanager.rmcontainer.RMContainerImpl: container_1376080735992_0003_01_000002 Container Transitioned from ACQUIRED to RUNNING
2013-08-09 20:45:43,083 INFO org.apache.hadoop.yarn.server.resourcemanager.rmcontainer.RMContainerImpl: container_1376080735992_0003_01_000003 Container Transitioned from ACQUIRED to RUNNING
2013-08-09 20:47:32,441 INFO org.apache.hadoop.yarn.server.resourcemanager.rmcontainer.RMContainerImpl: container_1376080735992_0003_01_000003 Container Transitioned from RUNNING to COMPLETED
2013-08-09 20:47:32,441 INFO org.apache.hadoop.yarn.server.resourcemanager.scheduler.common.fica.FiCaSchedulerApp: Completed container: container_1376080735992_0003_01_000003 in state: COMPLETED event:FINISHED
2013-08-09 20:47:32,441 INFO org.apache.hadoop.yarn.server.resourcemanager.RMAuditLogger: USER=ubuntu	OPERATION=AM Released Container	TARGET=SchedulerApp	RESULT=SUCCESS	APPID=application_1376080735992_0003	CONTAINERID=container_1376080735992_0003_01_000003
2013-08-09 20:47:32,442 INFO org.apache.hadoop.yarn.server.resourcemanager.scheduler.common.fica.FiCaSchedulerNode: Released container container_1376080735992_0003_01_000003 of capacity <memory:1024, vCores:1> on host hadoop-210-4:47596, which currently has 0 containers, <memory:0, vCores:0> used and <memory:8192, vCores:16> available, release resources=true
2013-08-09 20:47:32,442 INFO org.apache.hadoop.yarn.server.resourcemanager.scheduler.capacity.LeafQueue: default used=<memory:3072, vCores:2> numContainers=2 user=ubuntu user-resources=<memory:3072, vCores:2>
2013-08-09 20:47:32,444 INFO org.apache.hadoop.yarn.server.resourcemanager.scheduler.capacity.LeafQueue: completedContainer container=Container: [ContainerId: container_1376080735992_0003_01_000003, NodeId: hadoop-210-4:47596, NodeHttpAddress: hadoop-210-4:8042, Resource: <memory:1024, vCores:1>, Priority: 20, State: NEW, Token: null, Status: container_id {, app_attempt_id {, application_id {, id: 3, cluster_timestamp: 1376080735992, }, attemptId: 1, }, id: 3, }, state: C_COMPLETE, diagnostics: "Container killed by the ApplicationMaster.\n\n", exit_status: 143, ] resource=<memory:1024, vCores:1> queue=default: capacity=1.0, absoluteCapacity=1.0, usedResources=<memory:3072, vCores:2>usedCapacity=0.0625, absoluteUsedCapacity=0.0625, numApps=1, numContainers=2 usedCapacity=0.0625 absoluteUsedCapacity=0.0625 used=<memory:3072, vCores:2> cluster=<memory:49152, vCores:96>
2013-08-09 20:47:32,444 INFO org.apache.hadoop.yarn.server.resourcemanager.scheduler.capacity.ParentQueue: completedContainer queue=root usedCapacity=0.0625 absoluteUsedCapacity=0.0625 used=<memory:3072, vCores:2> cluster=<memory:49152, vCores:96>
2013-08-09 20:47:32,444 INFO org.apache.hadoop.yarn.server.resourcemanager.scheduler.capacity.CapacityScheduler: Application appattempt_1376080735992_0003_000001 released container container_1376080735992_0003_01_000003 on node: host: hadoop-210-4:47596 #containers=0 available=8192 used=0 with event: FINISHED
2013-08-09 20:47:40,073 INFO org.apache.hadoop.yarn.server.resourcemanager.rmcontainer.RMContainerImpl: container_1376080735992_0003_01_000002 Container Transitioned from RUNNING to COMPLETED
2013-08-09 20:47:40,074 INFO org.apache.hadoop.yarn.server.resourcemanager.scheduler.common.fica.FiCaSchedulerApp: Completed container: container_1376080735992_0003_01_000002 in state: COMPLETED event:FINISHED
2013-08-09 20:47:40,074 INFO org.apache.hadoop.yarn.server.resourcemanager.RMAuditLogger: USER=ubuntu	OPERATION=AM Released Container	TARGET=SchedulerApp	RESULT=SUCCESS	APPID=application_1376080735992_0003	CONTAINERID=container_1376080735992_0003_01_000002
2013-08-09 20:47:40,074 INFO org.apache.hadoop.yarn.server.resourcemanager.scheduler.common.fica.FiCaSchedulerNode: Released container container_1376080735992_0003_01_000002 of capacity <memory:1024, vCores:1> on host hadoop-210-7:35638, which currently has 0 containers, <memory:0, vCores:0> used and <memory:8192, vCores:16> available, release resources=true
2013-08-09 20:47:40,074 INFO org.apache.hadoop.yarn.server.resourcemanager.scheduler.capacity.LeafQueue: default used=<memory:2048, vCores:1> numContainers=1 user=ubuntu user-resources=<memory:2048, vCores:1>
2013-08-09 20:47:40,076 INFO org.apache.hadoop.yarn.server.resourcemanager.scheduler.capacity.LeafQueue: completedContainer container=Container: [ContainerId: container_1376080735992_0003_01_000002, NodeId: hadoop-210-7:35638, NodeHttpAddress: hadoop-210-7:8042, Resource: <memory:1024, vCores:1>, Priority: 20, State: NEW, Token: null, Status: container_id {, app_attempt_id {, application_id {, id: 3, cluster_timestamp: 1376080735992, }, attemptId: 1, }, id: 2, }, state: C_COMPLETE, diagnostics: "Container killed by the ApplicationMaster.\n", exit_status: 0, ] resource=<memory:1024, vCores:1> queue=default: capacity=1.0, absoluteCapacity=1.0, usedResources=<memory:2048, vCores:1>usedCapacity=0.041666668, absoluteUsedCapacity=0.041666668, numApps=1, numContainers=1 usedCapacity=0.041666668 absoluteUsedCapacity=0.041666668 used=<memory:2048, vCores:1> cluster=<memory:49152, vCores:96>
2013-08-09 20:47:40,076 INFO org.apache.hadoop.yarn.server.resourcemanager.scheduler.capacity.ParentQueue: completedContainer queue=root usedCapacity=0.041666668 absoluteUsedCapacity=0.041666668 used=<memory:2048, vCores:1> cluster=<memory:49152, vCores:96>
2013-08-09 20:47:40,077 INFO org.apache.hadoop.yarn.server.resourcemanager.scheduler.capacity.CapacityScheduler: Application appattempt_1376080735992_0003_000001 released container container_1376080735992_0003_01_000002 on node: host: hadoop-210-7:35638 #containers=0 available=8192 used=0 with event: FINISHED
2013-08-09 20:47:43,217 INFO org.apache.hadoop.yarn.server.resourcemanager.rmapp.attempt.RMAppAttemptImpl: appattempt_1376080735992_0003_000001 State change from RUNNING to FINISHING
2013-08-09 20:47:43,218 INFO org.apache.hadoop.yarn.server.resourcemanager.rmapp.RMAppImpl: application_1376080735992_0003 State change from RUNNING to FINISHING
2013-08-09 20:47:43,486 INFO org.apache.hadoop.yarn.server.resourcemanager.rmcontainer.RMContainerImpl: container_1376080735992_0003_01_000001 Container Transitioned from RUNNING to COMPLETED
2013-08-09 20:47:43,487 INFO org.apache.hadoop.yarn.server.resourcemanager.scheduler.common.fica.FiCaSchedulerApp: Completed container: container_1376080735992_0003_01_000001 in state: COMPLETED event:FINISHED
2013-08-09 20:47:43,487 INFO org.apache.hadoop.yarn.server.resourcemanager.RMAuditLogger: USER=ubuntu	OPERATION=AM Released Container	TARGET=SchedulerApp	RESULT=SUCCESS	APPID=application_1376080735992_0003	CONTAINERID=container_1376080735992_0003_01_000001
2013-08-09 20:47:43,487 INFO org.apache.hadoop.yarn.server.resourcemanager.rmapp.attempt.RMAppAttemptImpl: appattempt_1376080735992_0003_000001 State change from FINISHING to FINISHED
2013-08-09 20:47:43,487 INFO org.apache.hadoop.yarn.server.resourcemanager.scheduler.common.fica.FiCaSchedulerNode: Released container container_1376080735992_0003_01_000001 of capacity <memory:2048, vCores:1> on host hadoop-210-3:58589, which currently has 0 containers, <memory:0, vCores:0> used and <memory:8192, vCores:16> available, release resources=true
2013-08-09 20:47:43,487 INFO org.apache.hadoop.yarn.server.resourcemanager.scheduler.capacity.LeafQueue: default used=<memory:0, vCores:0> numContainers=0 user=ubuntu user-resources=<memory:0, vCores:0>
2013-08-09 20:47:43,487 INFO org.apache.hadoop.yarn.server.resourcemanager.rmapp.RMAppImpl: application_1376080735992_0003 State change from FINISHING to FINISHED
2013-08-09 20:47:43,488 INFO org.apache.hadoop.yarn.server.resourcemanager.RMAuditLogger: USER=ubuntu	OPERATION=Application Finished - Succeeded	TARGET=RMAppManager	RESULT=SUCCESS	APPID=application_1376080735992_0003
2013-08-09 20:47:43,488 INFO org.apache.hadoop.yarn.server.resourcemanager.amlauncher.AMLauncher: Cleaning master appattempt_1376080735992_0003_000001
2013-08-09 20:47:43,488 INFO org.apache.hadoop.yarn.server.resourcemanager.recovery.RMStateStore: Removing info for app: application_1376080735992_0003
2013-08-09 20:47:43,489 INFO org.apache.hadoop.yarn.server.resourcemanager.scheduler.capacity.LeafQueue: completedContainer container=Container: [ContainerId: container_1376080735992_0003_01_000001, NodeId: hadoop-210-3:58589, NodeHttpAddress: hadoop-210-3:8042, Resource: <memory:2048, vCores:1>, Priority: 0, State: NEW, Token: null, Status: container_id {, app_attempt_id {, application_id {, id: 3, cluster_timestamp: 1376080735992, }, attemptId: 1, }, id: 1, }, state: C_COMPLETE, diagnostics: "", exit_status: 0, ] resource=<memory:2048, vCores:1> queue=default: capacity=1.0, absoluteCapacity=1.0, usedResources=<memory:0, vCores:0>usedCapacity=0.0, absoluteUsedCapacity=0.0, numApps=1, numContainers=0 usedCapacity=0.0 absoluteUsedCapacity=0.0 used=<memory:0, vCores:0> cluster=<memory:49152, vCores:96>
2013-08-09 20:47:43,489 INFO org.apache.hadoop.yarn.server.resourcemanager.RMAppManager$ApplicationSummary: appId=application_1376080735992_0003,name=TeraGen,user=ubuntu,queue=default,state=FINISHED,trackingUrl=hadoop-210-1.novalocal:8088/proxy/application_1376080735992_0003/jobhistory/job/job_1376080735992_0003,appMasterHost=hadoop-210-3,startTime=1376081132750,finishTime=1376081263218
2013-08-09 20:47:43,489 INFO org.apache.hadoop.yarn.server.resourcemanager.scheduler.capacity.ParentQueue: completedContainer queue=root usedCapacity=0.0 absoluteUsedCapacity=0.0 used=<memory:0, vCores:0> cluster=<memory:49152, vCores:96>
2013-08-09 20:47:43,523 INFO org.apache.hadoop.yarn.server.resourcemanager.scheduler.capacity.CapacityScheduler: Application appattempt_1376080735992_0003_000001 released container container_1376080735992_0003_01_000001 on node: host: hadoop-210-3:58589 #containers=0 available=8192 used=0 with event: FINISHED
2013-08-09 20:47:43,523 INFO org.apache.hadoop.yarn.server.resourcemanager.scheduler.capacity.CapacityScheduler: Application appattempt_1376080735992_0003_000001 is done. finalState=FINISHED
2013-08-09 20:47:43,523 INFO org.apache.hadoop.yarn.server.resourcemanager.scheduler.AppSchedulingInfo: Application application_1376080735992_0003 requests cleared
2013-08-09 20:47:43,524 INFO org.apache.hadoop.yarn.server.resourcemanager.scheduler.capacity.LeafQueue: Application removed - appId: application_1376080735992_0003 user: ubuntu queue: default #user-pending-applications: 0 #user-active-applications: 0 #queue-pending-applications: 0 #queue-active-applications: 0
2013-08-09 20:47:43,524 INFO org.apache.hadoop.yarn.server.resourcemanager.scheduler.capacity.ParentQueue: Application removed - appId: application_1376080735992_0003 user: ubuntu leaf-queue of parent: root #applications: 0
2013-08-09 20:47:45,259 INFO org.apache.hadoop.yarn.server.resourcemanager.ClientRMService: Allocated new applicationId: 4
2013-08-09 20:47:47,141 INFO org.apache.hadoop.yarn.server.resourcemanager.ClientRMService: Storing Application with id application_1376080735992_0004
2013-08-09 20:47:47,142 INFO org.apache.hadoop.yarn.server.resourcemanager.recovery.RMStateStore: Storing info for app: application_1376080735992_0004
2013-08-09 20:47:47,142 INFO org.apache.hadoop.yarn.server.resourcemanager.ClientRMService: Application with id 4 submitted by user ubuntu
2013-08-09 20:47:47,142 INFO org.apache.hadoop.yarn.server.resourcemanager.RMAuditLogger: USER=ubuntu	IP=192.168.100.4	OPERATION=Submit Application Request	TARGET=ClientRMService	RESULT=SUCCESS	APPID=application_1376080735992_0004
2013-08-09 20:47:47,143 INFO org.apache.hadoop.yarn.server.resourcemanager.rmapp.RMAppImpl: application_1376080735992_0004 State change from NEW to SUBMITTED
2013-08-09 20:47:47,144 INFO org.apache.hadoop.yarn.server.resourcemanager.ApplicationMasterService: Registering appattempt_1376080735992_0004_000001
2013-08-09 20:47:47,144 INFO org.apache.hadoop.yarn.server.resourcemanager.rmapp.attempt.RMAppAttemptImpl: appattempt_1376080735992_0004_000001 State change from NEW to SUBMITTED
2013-08-09 20:47:47,145 INFO org.apache.hadoop.yarn.server.resourcemanager.scheduler.capacity.LeafQueue: Application application_1376080735992_0004 from user: ubuntu activated in queue: default
2013-08-09 20:47:47,145 INFO org.apache.hadoop.yarn.server.resourcemanager.scheduler.capacity.LeafQueue: Application added - appId: application_1376080735992_0004 user: org.apache.hadoop.yarn.server.resourcemanager.scheduler.capacity.LeafQueue$User@5b5b6746, leaf-queue: default #user-pending-applications: 0 #user-active-applications: 1 #queue-pending-applications: 0 #queue-active-applications: 1
2013-08-09 20:47:47,146 INFO org.apache.hadoop.yarn.server.resourcemanager.scheduler.capacity.ParentQueue: Application added - appId: application_1376080735992_0004 user: ubuntu leaf-queue of parent: root #applications: 1
2013-08-09 20:47:47,146 INFO org.apache.hadoop.yarn.server.resourcemanager.scheduler.capacity.CapacityScheduler: Application Submission: appattempt_1376080735992_0004_000001, user: ubuntu queue: default: capacity=1.0, absoluteCapacity=1.0, usedResources=<memory:0, vCores:0>usedCapacity=0.0, absoluteUsedCapacity=0.0, numApps=1, numContainers=0, currently active: 1
2013-08-09 20:47:47,146 INFO org.apache.hadoop.yarn.server.resourcemanager.rmapp.attempt.RMAppAttemptImpl: appattempt_1376080735992_0004_000001 State change from SUBMITTED to SCHEDULED
2013-08-09 20:47:47,147 INFO org.apache.hadoop.yarn.server.resourcemanager.rmapp.RMAppImpl: application_1376080735992_0004 State change from SUBMITTED to ACCEPTED
2013-08-09 20:47:47,500 INFO org.apache.hadoop.yarn.server.resourcemanager.rmcontainer.RMContainerImpl: container_1376080735992_0004_01_000001 Container Transitioned from NEW to ALLOCATED
2013-08-09 20:47:47,500 INFO org.apache.hadoop.yarn.server.resourcemanager.RMAuditLogger: USER=ubuntu	OPERATION=AM Allocated Container	TARGET=SchedulerApp	RESULT=SUCCESS	APPID=application_1376080735992_0004	CONTAINERID=container_1376080735992_0004_01_000001
2013-08-09 20:47:47,500 INFO org.apache.hadoop.yarn.server.resourcemanager.scheduler.common.fica.FiCaSchedulerNode: Assigned container container_1376080735992_0004_01_000001 of capacity <memory:2048, vCores:1> on host hadoop-210-4:47596, which currently has 1 containers, <memory:2048, vCores:1> used and <memory:6144, vCores:15> available
2013-08-09 20:47:47,502 INFO org.apache.hadoop.yarn.server.resourcemanager.scheduler.capacity.LeafQueue: assignedContainer application=application_1376080735992_0004 container=Container: [ContainerId: container_1376080735992_0004_01_000001, NodeId: hadoop-210-4:47596, NodeHttpAddress: hadoop-210-4:8042, Resource: <memory:2048, vCores:1>, Priority: 0, State: NEW, Token: null, Status: container_id {, app_attempt_id {, application_id {, id: 4, cluster_timestamp: 1376080735992, }, attemptId: 1, }, id: 1, }, state: C_NEW, ] containerId=container_1376080735992_0004_01_000001 queue=default: capacity=1.0, absoluteCapacity=1.0, usedResources=<memory:0, vCores:0>usedCapacity=0.0, absoluteUsedCapacity=0.0, numApps=1, numContainers=0 usedCapacity=0.0 absoluteUsedCapacity=0.0 used=<memory:0, vCores:0> cluster=<memory:49152, vCores:96>
2013-08-09 20:47:47,502 INFO org.apache.hadoop.yarn.server.resourcemanager.scheduler.capacity.ParentQueue: Re-sorting queues since queue: root.default stats: default: capacity=1.0, absoluteCapacity=1.0, usedResources=<memory:2048, vCores:1>usedCapacity=0.041666668, absoluteUsedCapacity=0.041666668, numApps=1, numContainers=1
2013-08-09 20:47:47,502 INFO org.apache.hadoop.yarn.server.resourcemanager.scheduler.capacity.ParentQueue: assignedContainer queue=root usedCapacity=0.041666668 absoluteUsedCapacity=0.041666668 used=<memory:2048, vCores:1> cluster=<memory:49152, vCores:96>
2013-08-09 20:47:47,504 INFO org.apache.hadoop.yarn.server.resourcemanager.rmcontainer.RMContainerImpl: container_1376080735992_0004_01_000001 Container Transitioned from ALLOCATED to ACQUIRED
2013-08-09 20:47:47,506 INFO org.apache.hadoop.yarn.server.resourcemanager.rmapp.attempt.RMAppAttemptImpl: Storing attempt: AppId: application_1376080735992_0004 AttemptId: appattempt_1376080735992_0004_000001 MasterContainer: Container: [ContainerId: container_1376080735992_0004_01_000001, NodeId: hadoop-210-4:47596, NodeHttpAddress: hadoop-210-4:8042, Resource: <memory:2048, vCores:1>, Priority: 0, State: NEW, Token: null, Status: container_id {, app_attempt_id {, application_id {, id: 4, cluster_timestamp: 1376080735992, }, attemptId: 1, }, id: 1, }, state: C_NEW, ]
2013-08-09 20:47:47,506 INFO org.apache.hadoop.yarn.server.resourcemanager.rmapp.attempt.RMAppAttemptImpl: appattempt_1376080735992_0004_000001 State change from SCHEDULED to ALLOCATED_SAVING
2013-08-09 20:47:47,506 INFO org.apache.hadoop.yarn.server.resourcemanager.recovery.RMStateStore: Storing info for attempt: appattempt_1376080735992_0004_000001
2013-08-09 20:47:47,509 INFO org.apache.hadoop.yarn.server.resourcemanager.rmapp.attempt.RMAppAttemptImpl: appattempt_1376080735992_0004_000001 State change from ALLOCATED_SAVING to ALLOCATED
2013-08-09 20:47:47,511 INFO org.apache.hadoop.yarn.server.resourcemanager.amlauncher.AMLauncher: Launching masterappattempt_1376080735992_0004_000001
2013-08-09 20:47:47,513 INFO org.apache.hadoop.yarn.server.resourcemanager.amlauncher.AMLauncher: Setting up container Container: [ContainerId: container_1376080735992_0004_01_000001, NodeId: hadoop-210-4:47596, NodeHttpAddress: hadoop-210-4:8042, Resource: <memory:2048, vCores:1>, Priority: 0, State: NEW, Token: null, Status: container_id {, app_attempt_id {, application_id {, id: 4, cluster_timestamp: 1376080735992, }, attemptId: 1, }, id: 1, }, state: C_NEW, ] for AM appattempt_1376080735992_0004_000001
2013-08-09 20:47:47,514 INFO org.apache.hadoop.yarn.server.resourcemanager.amlauncher.AMLauncher: Command to launch container container_1376080735992_0004_01_000001 : $JAVA_HOME/bin/java -Dlog4j.configuration=container-log4j.properties -Dyarn.app.mapreduce.container.log.dir=<LOG_DIR> -Dyarn.app.mapreduce.container.log.filesize=0 -Dhadoop.root.logger=INFO,CLA  -Xmx1024m org.apache.hadoop.mapreduce.v2.app.MRAppMaster 1><LOG_DIR>/stdout 2><LOG_DIR>/stderr 
2013-08-09 20:47:47,528 INFO org.apache.hadoop.yarn.server.resourcemanager.amlauncher.AMLauncher: Done launching container Container: [ContainerId: container_1376080735992_0004_01_000001, NodeId: hadoop-210-4:47596, NodeHttpAddress: hadoop-210-4:8042, Resource: <memory:2048, vCores:1>, Priority: 0, State: NEW, Token: null, Status: container_id {, app_attempt_id {, application_id {, id: 4, cluster_timestamp: 1376080735992, }, attemptId: 1, }, id: 1, }, state: C_NEW, ] for AM appattempt_1376080735992_0004_000001
2013-08-09 20:47:47,528 INFO org.apache.hadoop.yarn.server.resourcemanager.rmapp.attempt.RMAppAttemptImpl: appattempt_1376080735992_0004_000001 State change from ALLOCATED to LAUNCHED
2013-08-09 20:47:48,508 INFO org.apache.hadoop.yarn.server.resourcemanager.rmcontainer.RMContainerImpl: container_1376080735992_0004_01_000001 Container Transitioned from ACQUIRED to RUNNING
2013-08-09 20:47:55,744 INFO org.apache.hadoop.yarn.server.resourcemanager.ApplicationMasterService: AM registration appattempt_1376080735992_0004_000001
2013-08-09 20:47:55,745 INFO org.apache.hadoop.yarn.server.resourcemanager.RMAuditLogger: USER=ubuntu	IP=192.168.100.11	OPERATION=Register App Master	TARGET=ApplicationMasterService	RESULT=SUCCESS	APPID=application_1376080735992_0004	APPATTEMPTID=appattempt_1376080735992_0004_000001
2013-08-09 20:47:55,746 INFO org.apache.hadoop.yarn.server.resourcemanager.rmapp.attempt.RMAppAttemptImpl: appattempt_1376080735992_0004_000001 State change from LAUNCHED to RUNNING
2013-08-09 20:47:55,746 INFO org.apache.hadoop.yarn.server.resourcemanager.rmapp.RMAppImpl: application_1376080735992_0004 State change from ACCEPTED to RUNNING
2013-08-09 20:47:56,967 INFO org.apache.hadoop.yarn.server.resourcemanager.rmcontainer.RMContainerImpl: container_1376080735992_0004_01_000002 Container Transitioned from NEW to ALLOCATED
2013-08-09 20:47:56,967 INFO org.apache.hadoop.yarn.server.resourcemanager.RMAuditLogger: USER=ubuntu	OPERATION=AM Allocated Container	TARGET=SchedulerApp	RESULT=SUCCESS	APPID=application_1376080735992_0004	CONTAINERID=container_1376080735992_0004_01_000002
2013-08-09 20:47:56,967 INFO org.apache.hadoop.yarn.server.resourcemanager.scheduler.common.fica.FiCaSchedulerNode: Assigned container container_1376080735992_0004_01_000002 of capacity <memory:1024, vCores:1> on host hadoop-210-6:41207, which currently has 1 containers, <memory:1024, vCores:1> used and <memory:7168, vCores:15> available
2013-08-09 20:47:56,969 INFO org.apache.hadoop.yarn.server.resourcemanager.scheduler.capacity.LeafQueue: assignedContainer application=application_1376080735992_0004 container=Container: [ContainerId: container_1376080735992_0004_01_000002, NodeId: hadoop-210-6:41207, NodeHttpAddress: hadoop-210-6:8042, Resource: <memory:1024, vCores:1>, Priority: 20, State: NEW, Token: null, Status: container_id {, app_attempt_id {, application_id {, id: 4, cluster_timestamp: 1376080735992, }, attemptId: 1, }, id: 2, }, state: C_NEW, ] containerId=container_1376080735992_0004_01_000002 queue=default: capacity=1.0, absoluteCapacity=1.0, usedResources=<memory:2048, vCores:1>usedCapacity=0.041666668, absoluteUsedCapacity=0.041666668, numApps=1, numContainers=1 usedCapacity=0.041666668 absoluteUsedCapacity=0.041666668 used=<memory:2048, vCores:1> cluster=<memory:49152, vCores:96>
2013-08-09 20:47:56,969 INFO org.apache.hadoop.yarn.server.resourcemanager.scheduler.capacity.ParentQueue: Re-sorting queues since queue: root.default stats: default: capacity=1.0, absoluteCapacity=1.0, usedResources=<memory:3072, vCores:2>usedCapacity=0.0625, absoluteUsedCapacity=0.0625, numApps=1, numContainers=2
2013-08-09 20:47:56,969 INFO org.apache.hadoop.yarn.server.resourcemanager.scheduler.capacity.ParentQueue: assignedContainer queue=root usedCapacity=0.0625 absoluteUsedCapacity=0.0625 used=<memory:3072, vCores:2> cluster=<memory:49152, vCores:96>
2013-08-09 20:47:57,120 INFO org.apache.hadoop.yarn.server.resourcemanager.rmcontainer.RMContainerImpl: container_1376080735992_0004_01_000003 Container Transitioned from NEW to ALLOCATED
2013-08-09 20:47:57,120 INFO org.apache.hadoop.yarn.server.resourcemanager.RMAuditLogger: USER=ubuntu	OPERATION=AM Allocated Container	TARGET=SchedulerApp	RESULT=SUCCESS	APPID=application_1376080735992_0004	CONTAINERID=container_1376080735992_0004_01_000003
2013-08-09 20:47:57,120 INFO org.apache.hadoop.yarn.server.resourcemanager.scheduler.common.fica.FiCaSchedulerNode: Assigned container container_1376080735992_0004_01_000003 of capacity <memory:1024, vCores:1> on host hadoop-210-5:40689, which currently has 1 containers, <memory:1024, vCores:1> used and <memory:7168, vCores:15> available
2013-08-09 20:47:57,121 INFO org.apache.hadoop.yarn.server.resourcemanager.scheduler.capacity.LeafQueue: assignedContainer application=application_1376080735992_0004 container=Container: [ContainerId: container_1376080735992_0004_01_000003, NodeId: hadoop-210-5:40689, NodeHttpAddress: hadoop-210-5:8042, Resource: <memory:1024, vCores:1>, Priority: 20, State: NEW, Token: null, Status: container_id {, app_attempt_id {, application_id {, id: 4, cluster_timestamp: 1376080735992, }, attemptId: 1, }, id: 3, }, state: C_NEW, ] containerId=container_1376080735992_0004_01_000003 queue=default: capacity=1.0, absoluteCapacity=1.0, usedResources=<memory:3072, vCores:2>usedCapacity=0.0625, absoluteUsedCapacity=0.0625, numApps=1, numContainers=2 usedCapacity=0.0625 absoluteUsedCapacity=0.0625 used=<memory:3072, vCores:2> cluster=<memory:49152, vCores:96>
2013-08-09 20:47:57,121 INFO org.apache.hadoop.yarn.server.resourcemanager.scheduler.capacity.ParentQueue: Re-sorting queues since queue: root.default stats: default: capacity=1.0, absoluteCapacity=1.0, usedResources=<memory:4096, vCores:3>usedCapacity=0.083333336, absoluteUsedCapacity=0.083333336, numApps=1, numContainers=3
2013-08-09 20:47:57,122 INFO org.apache.hadoop.yarn.server.resourcemanager.scheduler.capacity.ParentQueue: assignedContainer queue=root usedCapacity=0.083333336 absoluteUsedCapacity=0.083333336 used=<memory:4096, vCores:3> cluster=<memory:49152, vCores:96>
2013-08-09 20:47:57,811 INFO org.apache.hadoop.yarn.server.resourcemanager.rmcontainer.RMContainerImpl: container_1376080735992_0004_01_000002 Container Transitioned from ALLOCATED to ACQUIRED
2013-08-09 20:47:57,812 INFO org.apache.hadoop.yarn.server.resourcemanager.rmcontainer.RMContainerImpl: container_1376080735992_0004_01_000003 Container Transitioned from ALLOCATED to ACQUIRED
2013-08-09 20:47:58,844 INFO org.apache.hadoop.yarn.server.resourcemanager.scheduler.AppSchedulingInfo: checking for deactivate... 
2013-08-09 20:47:58,976 INFO org.apache.hadoop.yarn.server.resourcemanager.rmcontainer.RMContainerImpl: container_1376080735992_0004_01_000002 Container Transitioned from ACQUIRED to RUNNING
2013-08-09 20:47:59,149 INFO org.apache.hadoop.yarn.server.resourcemanager.rmcontainer.RMContainerImpl: container_1376080735992_0004_01_000003 Container Transitioned from ACQUIRED to RUNNING
2013-08-09 20:49:57,459 INFO org.apache.hadoop.yarn.server.resourcemanager.rmcontainer.RMContainerImpl: container_1376080735992_0004_01_000003 Container Transitioned from RUNNING to COMPLETED
2013-08-09 20:49:57,460 INFO org.apache.hadoop.yarn.server.resourcemanager.scheduler.common.fica.FiCaSchedulerApp: Completed container: container_1376080735992_0004_01_000003 in state: COMPLETED event:FINISHED
2013-08-09 20:49:57,460 INFO org.apache.hadoop.yarn.server.resourcemanager.RMAuditLogger: USER=ubuntu	OPERATION=AM Released Container	TARGET=SchedulerApp	RESULT=SUCCESS	APPID=application_1376080735992_0004	CONTAINERID=container_1376080735992_0004_01_000003
2013-08-09 20:49:57,460 INFO org.apache.hadoop.yarn.server.resourcemanager.scheduler.common.fica.FiCaSchedulerNode: Released container container_1376080735992_0004_01_000003 of capacity <memory:1024, vCores:1> on host hadoop-210-5:40689, which currently has 0 containers, <memory:0, vCores:0> used and <memory:8192, vCores:16> available, release resources=true
2013-08-09 20:49:57,460 INFO org.apache.hadoop.yarn.server.resourcemanager.scheduler.capacity.LeafQueue: default used=<memory:3072, vCores:2> numContainers=2 user=ubuntu user-resources=<memory:3072, vCores:2>
2013-08-09 20:49:57,462 INFO org.apache.hadoop.yarn.server.resourcemanager.scheduler.capacity.LeafQueue: completedContainer container=Container: [ContainerId: container_1376080735992_0004_01_000003, NodeId: hadoop-210-5:40689, NodeHttpAddress: hadoop-210-5:8042, Resource: <memory:1024, vCores:1>, Priority: 20, State: NEW, Token: null, Status: container_id {, app_attempt_id {, application_id {, id: 4, cluster_timestamp: 1376080735992, }, attemptId: 1, }, id: 3, }, state: C_COMPLETE, diagnostics: "Container killed by the ApplicationMaster.\n\n", exit_status: 143, ] resource=<memory:1024, vCores:1> queue=default: capacity=1.0, absoluteCapacity=1.0, usedResources=<memory:3072, vCores:2>usedCapacity=0.0625, absoluteUsedCapacity=0.0625, numApps=1, numContainers=2 usedCapacity=0.0625 absoluteUsedCapacity=0.0625 used=<memory:3072, vCores:2> cluster=<memory:49152, vCores:96>
2013-08-09 20:49:57,462 INFO org.apache.hadoop.yarn.server.resourcemanager.scheduler.capacity.ParentQueue: completedContainer queue=root usedCapacity=0.0625 absoluteUsedCapacity=0.0625 used=<memory:3072, vCores:2> cluster=<memory:49152, vCores:96>
2013-08-09 20:49:57,462 INFO org.apache.hadoop.yarn.server.resourcemanager.scheduler.capacity.CapacityScheduler: Application appattempt_1376080735992_0004_000001 released container container_1376080735992_0004_01_000003 on node: host: hadoop-210-5:40689 #containers=0 available=8192 used=0 with event: FINISHED
2013-08-09 20:49:59,258 INFO org.apache.hadoop.yarn.server.resourcemanager.rmcontainer.RMContainerImpl: container_1376080735992_0004_01_000002 Container Transitioned from RUNNING to COMPLETED
2013-08-09 20:49:59,259 INFO org.apache.hadoop.yarn.server.resourcemanager.scheduler.common.fica.FiCaSchedulerApp: Completed container: container_1376080735992_0004_01_000002 in state: COMPLETED event:FINISHED
2013-08-09 20:49:59,259 INFO org.apache.hadoop.yarn.server.resourcemanager.RMAuditLogger: USER=ubuntu	OPERATION=AM Released Container	TARGET=SchedulerApp	RESULT=SUCCESS	APPID=application_1376080735992_0004	CONTAINERID=container_1376080735992_0004_01_000002
2013-08-09 20:49:59,259 INFO org.apache.hadoop.yarn.server.resourcemanager.scheduler.common.fica.FiCaSchedulerNode: Released container container_1376080735992_0004_01_000002 of capacity <memory:1024, vCores:1> on host hadoop-210-6:41207, which currently has 0 containers, <memory:0, vCores:0> used and <memory:8192, vCores:16> available, release resources=true
2013-08-09 20:49:59,259 INFO org.apache.hadoop.yarn.server.resourcemanager.scheduler.capacity.LeafQueue: default used=<memory:2048, vCores:1> numContainers=1 user=ubuntu user-resources=<memory:2048, vCores:1>
2013-08-09 20:49:59,261 INFO org.apache.hadoop.yarn.server.resourcemanager.scheduler.capacity.LeafQueue: completedContainer container=Container: [ContainerId: container_1376080735992_0004_01_000002, NodeId: hadoop-210-6:41207, NodeHttpAddress: hadoop-210-6:8042, Resource: <memory:1024, vCores:1>, Priority: 20, State: NEW, Token: null, Status: container_id {, app_attempt_id {, application_id {, id: 4, cluster_timestamp: 1376080735992, }, attemptId: 1, }, id: 2, }, state: C_COMPLETE, diagnostics: "Container killed by the ApplicationMaster.\n", exit_status: 0, ] resource=<memory:1024, vCores:1> queue=default: capacity=1.0, absoluteCapacity=1.0, usedResources=<memory:2048, vCores:1>usedCapacity=0.041666668, absoluteUsedCapacity=0.041666668, numApps=1, numContainers=1 usedCapacity=0.041666668 absoluteUsedCapacity=0.041666668 used=<memory:2048, vCores:1> cluster=<memory:49152, vCores:96>
2013-08-09 20:49:59,261 INFO org.apache.hadoop.yarn.server.resourcemanager.scheduler.capacity.ParentQueue: completedContainer queue=root usedCapacity=0.041666668 absoluteUsedCapacity=0.041666668 used=<memory:2048, vCores:1> cluster=<memory:49152, vCores:96>
2013-08-09 20:49:59,261 INFO org.apache.hadoop.yarn.server.resourcemanager.scheduler.capacity.CapacityScheduler: Application appattempt_1376080735992_0004_000001 released container container_1376080735992_0004_01_000002 on node: host: hadoop-210-6:41207 #containers=0 available=8192 used=0 with event: FINISHED
2013-08-09 20:50:03,612 INFO org.apache.hadoop.yarn.server.resourcemanager.rmapp.attempt.RMAppAttemptImpl: appattempt_1376080735992_0004_000001 State change from RUNNING to FINISHING
2013-08-09 20:50:03,613 INFO org.apache.hadoop.yarn.server.resourcemanager.rmapp.RMAppImpl: application_1376080735992_0004 State change from RUNNING to FINISHING
2013-08-09 20:50:03,942 INFO org.apache.hadoop.yarn.server.resourcemanager.rmcontainer.RMContainerImpl: container_1376080735992_0004_01_000001 Container Transitioned from RUNNING to COMPLETED
2013-08-09 20:50:03,942 INFO org.apache.hadoop.yarn.server.resourcemanager.scheduler.common.fica.FiCaSchedulerApp: Completed container: container_1376080735992_0004_01_000001 in state: COMPLETED event:FINISHED
2013-08-09 20:50:03,942 INFO org.apache.hadoop.yarn.server.resourcemanager.RMAuditLogger: USER=ubuntu	OPERATION=AM Released Container	TARGET=SchedulerApp	RESULT=SUCCESS	APPID=application_1376080735992_0004	CONTAINERID=container_1376080735992_0004_01_000001
2013-08-09 20:50:03,942 INFO org.apache.hadoop.yarn.server.resourcemanager.scheduler.common.fica.FiCaSchedulerNode: Released container container_1376080735992_0004_01_000001 of capacity <memory:2048, vCores:1> on host hadoop-210-4:47596, which currently has 0 containers, <memory:0, vCores:0> used and <memory:8192, vCores:16> available, release resources=true
2013-08-09 20:50:03,943 INFO org.apache.hadoop.yarn.server.resourcemanager.scheduler.capacity.LeafQueue: default used=<memory:0, vCores:0> numContainers=0 user=ubuntu user-resources=<memory:0, vCores:0>
2013-08-09 20:50:03,944 INFO org.apache.hadoop.yarn.server.resourcemanager.scheduler.capacity.LeafQueue: completedContainer container=Container: [ContainerId: container_1376080735992_0004_01_000001, NodeId: hadoop-210-4:47596, NodeHttpAddress: hadoop-210-4:8042, Resource: <memory:2048, vCores:1>, Priority: 0, State: NEW, Token: null, Status: container_id {, app_attempt_id {, application_id {, id: 4, cluster_timestamp: 1376080735992, }, attemptId: 1, }, id: 1, }, state: C_COMPLETE, diagnostics: "", exit_status: 0, ] resource=<memory:2048, vCores:1> queue=default: capacity=1.0, absoluteCapacity=1.0, usedResources=<memory:0, vCores:0>usedCapacity=0.0, absoluteUsedCapacity=0.0, numApps=1, numContainers=0 usedCapacity=0.0 absoluteUsedCapacity=0.0 used=<memory:0, vCores:0> cluster=<memory:49152, vCores:96>
2013-08-09 20:50:03,944 INFO org.apache.hadoop.yarn.server.resourcemanager.scheduler.capacity.ParentQueue: completedContainer queue=root usedCapacity=0.0 absoluteUsedCapacity=0.0 used=<memory:0, vCores:0> cluster=<memory:49152, vCores:96>
2013-08-09 20:50:03,944 INFO org.apache.hadoop.yarn.server.resourcemanager.scheduler.capacity.CapacityScheduler: Application appattempt_1376080735992_0004_000001 released container container_1376080735992_0004_01_000001 on node: host: hadoop-210-4:47596 #containers=0 available=8192 used=0 with event: FINISHED
2013-08-09 20:50:03,945 INFO org.apache.hadoop.yarn.server.resourcemanager.rmapp.attempt.RMAppAttemptImpl: appattempt_1376080735992_0004_000001 State change from FINISHING to FINISHED
2013-08-09 20:50:03,945 INFO org.apache.hadoop.yarn.server.resourcemanager.rmapp.RMAppImpl: application_1376080735992_0004 State change from FINISHING to FINISHED
2013-08-09 20:50:03,946 INFO org.apache.hadoop.yarn.server.resourcemanager.RMAuditLogger: USER=ubuntu	OPERATION=Application Finished - Succeeded	TARGET=RMAppManager	RESULT=SUCCESS	APPID=application_1376080735992_0004
2013-08-09 20:50:03,946 INFO org.apache.hadoop.yarn.server.resourcemanager.scheduler.capacity.CapacityScheduler: Application appattempt_1376080735992_0004_000001 is done. finalState=FINISHED
2013-08-09 20:50:03,946 INFO org.apache.hadoop.yarn.server.resourcemanager.scheduler.AppSchedulingInfo: Application application_1376080735992_0004 requests cleared
2013-08-09 20:50:03,946 INFO org.apache.hadoop.yarn.server.resourcemanager.scheduler.capacity.LeafQueue: Application removed - appId: application_1376080735992_0004 user: ubuntu queue: default #user-pending-applications: 0 #user-active-applications: 0 #queue-pending-applications: 0 #queue-active-applications: 0
2013-08-09 20:50:03,946 INFO org.apache.hadoop.yarn.server.resourcemanager.scheduler.capacity.ParentQueue: Application removed - appId: application_1376080735992_0004 user: ubuntu leaf-queue of parent: root #applications: 0
2013-08-09 20:50:03,947 INFO org.apache.hadoop.yarn.server.resourcemanager.amlauncher.AMLauncher: Cleaning master appattempt_1376080735992_0004_000001
2013-08-09 20:50:03,947 INFO org.apache.hadoop.yarn.server.resourcemanager.recovery.RMStateStore: Removing info for app: application_1376080735992_0004
2013-08-09 20:50:03,947 INFO org.apache.hadoop.yarn.server.resourcemanager.RMAppManager$ApplicationSummary: appId=application_1376080735992_0004,name=TeraGen,user=ubuntu,queue=default,state=FINISHED,trackingUrl=hadoop-210-1.novalocal:8088/proxy/application_1376080735992_0004/jobhistory/job/job_1376080735992_0004,appMasterHost=hadoop-210-4,startTime=1376081267141,finishTime=1376081403613
2013-08-09 20:50:04,416 INFO org.apache.hadoop.yarn.server.resourcemanager.ClientRMService: Allocated new applicationId: 5
2013-08-09 20:50:06,300 INFO org.apache.hadoop.yarn.server.resourcemanager.ClientRMService: Storing Application with id application_1376080735992_0005
2013-08-09 20:50:06,300 INFO org.apache.hadoop.yarn.server.resourcemanager.recovery.RMStateStore: Storing info for app: application_1376080735992_0005
2013-08-09 20:50:06,301 INFO org.apache.hadoop.yarn.server.resourcemanager.ClientRMService: Application with id 5 submitted by user ubuntu
2013-08-09 20:50:06,301 INFO org.apache.hadoop.yarn.server.resourcemanager.RMAuditLogger: USER=ubuntu	IP=192.168.100.4	OPERATION=Submit Application Request	TARGET=ClientRMService	RESULT=SUCCESS	APPID=application_1376080735992_0005
2013-08-09 20:50:06,302 INFO org.apache.hadoop.yarn.server.resourcemanager.rmapp.RMAppImpl: application_1376080735992_0005 State change from NEW to SUBMITTED
2013-08-09 20:50:06,302 INFO org.apache.hadoop.yarn.server.resourcemanager.ApplicationMasterService: Registering appattempt_1376080735992_0005_000001
2013-08-09 20:50:06,303 INFO org.apache.hadoop.yarn.server.resourcemanager.rmapp.attempt.RMAppAttemptImpl: appattempt_1376080735992_0005_000001 State change from NEW to SUBMITTED
2013-08-09 20:50:06,303 INFO org.apache.hadoop.yarn.server.resourcemanager.scheduler.capacity.LeafQueue: Application application_1376080735992_0005 from user: ubuntu activated in queue: default
2013-08-09 20:50:06,303 INFO org.apache.hadoop.yarn.server.resourcemanager.scheduler.capacity.LeafQueue: Application added - appId: application_1376080735992_0005 user: org.apache.hadoop.yarn.server.resourcemanager.scheduler.capacity.LeafQueue$User@13bdbb15, leaf-queue: default #user-pending-applications: 0 #user-active-applications: 1 #queue-pending-applications: 0 #queue-active-applications: 1
2013-08-09 20:50:06,303 INFO org.apache.hadoop.yarn.server.resourcemanager.scheduler.capacity.ParentQueue: Application added - appId: application_1376080735992_0005 user: ubuntu leaf-queue of parent: root #applications: 1
2013-08-09 20:50:06,304 INFO org.apache.hadoop.yarn.server.resourcemanager.scheduler.capacity.CapacityScheduler: Application Submission: appattempt_1376080735992_0005_000001, user: ubuntu queue: default: capacity=1.0, absoluteCapacity=1.0, usedResources=<memory:0, vCores:0>usedCapacity=0.0, absoluteUsedCapacity=0.0, numApps=1, numContainers=0, currently active: 1
2013-08-09 20:50:06,304 INFO org.apache.hadoop.yarn.server.resourcemanager.rmapp.attempt.RMAppAttemptImpl: appattempt_1376080735992_0005_000001 State change from SUBMITTED to SCHEDULED
2013-08-09 20:50:06,304 INFO org.apache.hadoop.yarn.server.resourcemanager.rmapp.RMAppImpl: application_1376080735992_0005 State change from SUBMITTED to ACCEPTED
2013-08-09 20:50:06,495 INFO org.apache.hadoop.yarn.server.resourcemanager.rmcontainer.RMContainerImpl: container_1376080735992_0005_01_000001 Container Transitioned from NEW to ALLOCATED
2013-08-09 20:50:06,496 INFO org.apache.hadoop.yarn.server.resourcemanager.RMAuditLogger: USER=ubuntu	OPERATION=AM Allocated Container	TARGET=SchedulerApp	RESULT=SUCCESS	APPID=application_1376080735992_0005	CONTAINERID=container_1376080735992_0005_01_000001
2013-08-09 20:50:06,496 INFO org.apache.hadoop.yarn.server.resourcemanager.scheduler.common.fica.FiCaSchedulerNode: Assigned container container_1376080735992_0005_01_000001 of capacity <memory:2048, vCores:1> on host hadoop-210-5:40689, which currently has 1 containers, <memory:2048, vCores:1> used and <memory:6144, vCores:15> available
2013-08-09 20:50:06,497 INFO org.apache.hadoop.yarn.server.resourcemanager.scheduler.capacity.LeafQueue: assignedContainer application=application_1376080735992_0005 container=Container: [ContainerId: container_1376080735992_0005_01_000001, NodeId: hadoop-210-5:40689, NodeHttpAddress: hadoop-210-5:8042, Resource: <memory:2048, vCores:1>, Priority: 0, State: NEW, Token: null, Status: container_id {, app_attempt_id {, application_id {, id: 5, cluster_timestamp: 1376080735992, }, attemptId: 1, }, id: 1, }, state: C_NEW, ] containerId=container_1376080735992_0005_01_000001 queue=default: capacity=1.0, absoluteCapacity=1.0, usedResources=<memory:0, vCores:0>usedCapacity=0.0, absoluteUsedCapacity=0.0, numApps=1, numContainers=0 usedCapacity=0.0 absoluteUsedCapacity=0.0 used=<memory:0, vCores:0> cluster=<memory:49152, vCores:96>
2013-08-09 20:50:06,497 INFO org.apache.hadoop.yarn.server.resourcemanager.scheduler.capacity.ParentQueue: Re-sorting queues since queue: root.default stats: default: capacity=1.0, absoluteCapacity=1.0, usedResources=<memory:2048, vCores:1>usedCapacity=0.041666668, absoluteUsedCapacity=0.041666668, numApps=1, numContainers=1
2013-08-09 20:50:06,498 INFO org.apache.hadoop.yarn.server.resourcemanager.scheduler.capacity.ParentQueue: assignedContainer queue=root usedCapacity=0.041666668 absoluteUsedCapacity=0.041666668 used=<memory:2048, vCores:1> cluster=<memory:49152, vCores:96>
2013-08-09 20:50:06,499 INFO org.apache.hadoop.yarn.server.resourcemanager.rmcontainer.RMContainerImpl: container_1376080735992_0005_01_000001 Container Transitioned from ALLOCATED to ACQUIRED
2013-08-09 20:50:06,501 INFO org.apache.hadoop.yarn.server.resourcemanager.rmapp.attempt.RMAppAttemptImpl: Storing attempt: AppId: application_1376080735992_0005 AttemptId: appattempt_1376080735992_0005_000001 MasterContainer: Container: [ContainerId: container_1376080735992_0005_01_000001, NodeId: hadoop-210-5:40689, NodeHttpAddress: hadoop-210-5:8042, Resource: <memory:2048, vCores:1>, Priority: 0, State: NEW, Token: null, Status: container_id {, app_attempt_id {, application_id {, id: 5, cluster_timestamp: 1376080735992, }, attemptId: 1, }, id: 1, }, state: C_NEW, ]
2013-08-09 20:50:06,501 INFO org.apache.hadoop.yarn.server.resourcemanager.rmapp.attempt.RMAppAttemptImpl: appattempt_1376080735992_0005_000001 State change from SCHEDULED to ALLOCATED_SAVING
2013-08-09 20:50:06,501 INFO org.apache.hadoop.yarn.server.resourcemanager.recovery.RMStateStore: Storing info for attempt: appattempt_1376080735992_0005_000001
2013-08-09 20:50:06,502 INFO org.apache.hadoop.yarn.server.resourcemanager.rmapp.attempt.RMAppAttemptImpl: appattempt_1376080735992_0005_000001 State change from ALLOCATED_SAVING to ALLOCATED
2013-08-09 20:50:06,504 INFO org.apache.hadoop.yarn.server.resourcemanager.amlauncher.AMLauncher: Launching masterappattempt_1376080735992_0005_000001
2013-08-09 20:50:06,506 INFO org.apache.hadoop.yarn.server.resourcemanager.amlauncher.AMLauncher: Setting up container Container: [ContainerId: container_1376080735992_0005_01_000001, NodeId: hadoop-210-5:40689, NodeHttpAddress: hadoop-210-5:8042, Resource: <memory:2048, vCores:1>, Priority: 0, State: NEW, Token: null, Status: container_id {, app_attempt_id {, application_id {, id: 5, cluster_timestamp: 1376080735992, }, attemptId: 1, }, id: 1, }, state: C_NEW, ] for AM appattempt_1376080735992_0005_000001
2013-08-09 20:50:06,507 INFO org.apache.hadoop.yarn.server.resourcemanager.amlauncher.AMLauncher: Command to launch container container_1376080735992_0005_01_000001 : $JAVA_HOME/bin/java -Dlog4j.configuration=container-log4j.properties -Dyarn.app.mapreduce.container.log.dir=<LOG_DIR> -Dyarn.app.mapreduce.container.log.filesize=0 -Dhadoop.root.logger=INFO,CLA  -Xmx1024m org.apache.hadoop.mapreduce.v2.app.MRAppMaster 1><LOG_DIR>/stdout 2><LOG_DIR>/stderr 
2013-08-09 20:50:06,523 INFO org.apache.hadoop.yarn.server.resourcemanager.amlauncher.AMLauncher: Done launching container Container: [ContainerId: container_1376080735992_0005_01_000001, NodeId: hadoop-210-5:40689, NodeHttpAddress: hadoop-210-5:8042, Resource: <memory:2048, vCores:1>, Priority: 0, State: NEW, Token: null, Status: container_id {, app_attempt_id {, application_id {, id: 5, cluster_timestamp: 1376080735992, }, attemptId: 1, }, id: 1, }, state: C_NEW, ] for AM appattempt_1376080735992_0005_000001
2013-08-09 20:50:06,524 INFO org.apache.hadoop.yarn.server.resourcemanager.rmapp.attempt.RMAppAttemptImpl: appattempt_1376080735992_0005_000001 State change from ALLOCATED to LAUNCHED
2013-08-09 20:50:07,501 INFO org.apache.hadoop.yarn.server.resourcemanager.rmcontainer.RMContainerImpl: container_1376080735992_0005_01_000001 Container Transitioned from ACQUIRED to RUNNING
2013-08-09 20:50:14,220 INFO org.apache.hadoop.yarn.server.resourcemanager.ApplicationMasterService: AM registration appattempt_1376080735992_0005_000001
2013-08-09 20:50:14,221 INFO org.apache.hadoop.yarn.server.resourcemanager.RMAuditLogger: USER=ubuntu	IP=192.168.100.13	OPERATION=Register App Master	TARGET=ApplicationMasterService	RESULT=SUCCESS	APPID=application_1376080735992_0005	APPATTEMPTID=appattempt_1376080735992_0005_000001
2013-08-09 20:50:14,222 INFO org.apache.hadoop.yarn.server.resourcemanager.rmapp.attempt.RMAppAttemptImpl: appattempt_1376080735992_0005_000001 State change from LAUNCHED to RUNNING
2013-08-09 20:50:14,222 INFO org.apache.hadoop.yarn.server.resourcemanager.rmapp.RMAppImpl: application_1376080735992_0005 State change from ACCEPTED to RUNNING
2013-08-09 20:50:15,316 INFO org.apache.hadoop.yarn.server.resourcemanager.rmcontainer.RMContainerImpl: container_1376080735992_0005_01_000002 Container Transitioned from NEW to ALLOCATED
2013-08-09 20:50:15,316 INFO org.apache.hadoop.yarn.server.resourcemanager.RMAuditLogger: USER=ubuntu	OPERATION=AM Allocated Container	TARGET=SchedulerApp	RESULT=SUCCESS	APPID=application_1376080735992_0005	CONTAINERID=container_1376080735992_0005_01_000002
2013-08-09 20:50:15,316 INFO org.apache.hadoop.yarn.server.resourcemanager.scheduler.common.fica.FiCaSchedulerNode: Assigned container container_1376080735992_0005_01_000002 of capacity <memory:1024, vCores:1> on host hadoop-210-6:41207, which currently has 1 containers, <memory:1024, vCores:1> used and <memory:7168, vCores:15> available
2013-08-09 20:50:15,317 INFO org.apache.hadoop.yarn.server.resourcemanager.scheduler.capacity.LeafQueue: assignedContainer application=application_1376080735992_0005 container=Container: [ContainerId: container_1376080735992_0005_01_000002, NodeId: hadoop-210-6:41207, NodeHttpAddress: hadoop-210-6:8042, Resource: <memory:1024, vCores:1>, Priority: 20, State: NEW, Token: null, Status: container_id {, app_attempt_id {, application_id {, id: 5, cluster_timestamp: 1376080735992, }, attemptId: 1, }, id: 2, }, state: C_NEW, ] containerId=container_1376080735992_0005_01_000002 queue=default: capacity=1.0, absoluteCapacity=1.0, usedResources=<memory:2048, vCores:1>usedCapacity=0.041666668, absoluteUsedCapacity=0.041666668, numApps=1, numContainers=1 usedCapacity=0.041666668 absoluteUsedCapacity=0.041666668 used=<memory:2048, vCores:1> cluster=<memory:49152, vCores:96>
2013-08-09 20:50:15,318 INFO org.apache.hadoop.yarn.server.resourcemanager.scheduler.capacity.ParentQueue: Re-sorting queues since queue: root.default stats: default: capacity=1.0, absoluteCapacity=1.0, usedResources=<memory:3072, vCores:2>usedCapacity=0.0625, absoluteUsedCapacity=0.0625, numApps=1, numContainers=2
2013-08-09 20:50:15,318 INFO org.apache.hadoop.yarn.server.resourcemanager.scheduler.capacity.ParentQueue: assignedContainer queue=root usedCapacity=0.0625 absoluteUsedCapacity=0.0625 used=<memory:3072, vCores:2> cluster=<memory:49152, vCores:96>
2013-08-09 20:50:15,540 INFO org.apache.hadoop.yarn.server.resourcemanager.rmcontainer.RMContainerImpl: container_1376080735992_0005_01_000003 Container Transitioned from NEW to ALLOCATED
2013-08-09 20:50:15,540 INFO org.apache.hadoop.yarn.server.resourcemanager.RMAuditLogger: USER=ubuntu	OPERATION=AM Allocated Container	TARGET=SchedulerApp	RESULT=SUCCESS	APPID=application_1376080735992_0005	CONTAINERID=container_1376080735992_0005_01_000003
2013-08-09 20:50:15,540 INFO org.apache.hadoop.yarn.server.resourcemanager.scheduler.common.fica.FiCaSchedulerNode: Assigned container container_1376080735992_0005_01_000003 of capacity <memory:1024, vCores:1> on host hadoop-210-5:40689, which currently has 2 containers, <memory:3072, vCores:2> used and <memory:5120, vCores:14> available
2013-08-09 20:50:15,541 INFO org.apache.hadoop.yarn.server.resourcemanager.scheduler.capacity.LeafQueue: assignedContainer application=application_1376080735992_0005 container=Container: [ContainerId: container_1376080735992_0005_01_000003, NodeId: hadoop-210-5:40689, NodeHttpAddress: hadoop-210-5:8042, Resource: <memory:1024, vCores:1>, Priority: 20, State: NEW, Token: null, Status: container_id {, app_attempt_id {, application_id {, id: 5, cluster_timestamp: 1376080735992, }, attemptId: 1, }, id: 3, }, state: C_NEW, ] containerId=container_1376080735992_0005_01_000003 queue=default: capacity=1.0, absoluteCapacity=1.0, usedResources=<memory:3072, vCores:2>usedCapacity=0.0625, absoluteUsedCapacity=0.0625, numApps=1, numContainers=2 usedCapacity=0.0625 absoluteUsedCapacity=0.0625 used=<memory:3072, vCores:2> cluster=<memory:49152, vCores:96>
2013-08-09 20:50:15,542 INFO org.apache.hadoop.yarn.server.resourcemanager.scheduler.capacity.ParentQueue: Re-sorting queues since queue: root.default stats: default: capacity=1.0, absoluteCapacity=1.0, usedResources=<memory:4096, vCores:3>usedCapacity=0.083333336, absoluteUsedCapacity=0.083333336, numApps=1, numContainers=3
2013-08-09 20:50:15,542 INFO org.apache.hadoop.yarn.server.resourcemanager.scheduler.capacity.ParentQueue: assignedContainer queue=root usedCapacity=0.083333336 absoluteUsedCapacity=0.083333336 used=<memory:4096, vCores:3> cluster=<memory:49152, vCores:96>
2013-08-09 20:50:16,281 INFO org.apache.hadoop.yarn.server.resourcemanager.rmcontainer.RMContainerImpl: container_1376080735992_0005_01_000002 Container Transitioned from ALLOCATED to ACQUIRED
2013-08-09 20:50:16,283 INFO org.apache.hadoop.yarn.server.resourcemanager.rmcontainer.RMContainerImpl: container_1376080735992_0005_01_000003 Container Transitioned from ALLOCATED to ACQUIRED
2013-08-09 20:50:16,549 INFO org.apache.hadoop.yarn.server.resourcemanager.rmcontainer.RMContainerImpl: container_1376080735992_0005_01_000003 Container Transitioned from ACQUIRED to RUNNING
2013-08-09 20:50:17,309 INFO org.apache.hadoop.yarn.server.resourcemanager.scheduler.AppSchedulingInfo: checking for deactivate... 
2013-08-09 20:50:17,325 INFO org.apache.hadoop.yarn.server.resourcemanager.rmcontainer.RMContainerImpl: container_1376080735992_0005_01_000002 Container Transitioned from ACQUIRED to RUNNING
2013-08-09 20:51:55,750 INFO org.apache.hadoop.yarn.server.resourcemanager.rmcontainer.RMContainerImpl: container_1376080735992_0005_01_000002 Container Transitioned from RUNNING to COMPLETED
2013-08-09 20:51:55,750 INFO org.apache.hadoop.yarn.server.resourcemanager.scheduler.common.fica.FiCaSchedulerApp: Completed container: container_1376080735992_0005_01_000002 in state: COMPLETED event:FINISHED
2013-08-09 20:51:55,751 INFO org.apache.hadoop.yarn.server.resourcemanager.RMAuditLogger: USER=ubuntu	OPERATION=AM Released Container	TARGET=SchedulerApp	RESULT=SUCCESS	APPID=application_1376080735992_0005	CONTAINERID=container_1376080735992_0005_01_000002
2013-08-09 20:51:55,751 INFO org.apache.hadoop.yarn.server.resourcemanager.scheduler.common.fica.FiCaSchedulerNode: Released container container_1376080735992_0005_01_000002 of capacity <memory:1024, vCores:1> on host hadoop-210-6:41207, which currently has 0 containers, <memory:0, vCores:0> used and <memory:8192, vCores:16> available, release resources=true
2013-08-09 20:51:55,751 INFO org.apache.hadoop.yarn.server.resourcemanager.scheduler.capacity.LeafQueue: default used=<memory:3072, vCores:2> numContainers=2 user=ubuntu user-resources=<memory:3072, vCores:2>
2013-08-09 20:51:55,753 INFO org.apache.hadoop.yarn.server.resourcemanager.scheduler.capacity.LeafQueue: completedContainer container=Container: [ContainerId: container_1376080735992_0005_01_000002, NodeId: hadoop-210-6:41207, NodeHttpAddress: hadoop-210-6:8042, Resource: <memory:1024, vCores:1>, Priority: 20, State: NEW, Token: null, Status: container_id {, app_attempt_id {, application_id {, id: 5, cluster_timestamp: 1376080735992, }, attemptId: 1, }, id: 2, }, state: C_COMPLETE, diagnostics: "Container killed by the ApplicationMaster.\n\n", exit_status: 143, ] resource=<memory:1024, vCores:1> queue=default: capacity=1.0, absoluteCapacity=1.0, usedResources=<memory:3072, vCores:2>usedCapacity=0.0625, absoluteUsedCapacity=0.0625, numApps=1, numContainers=2 usedCapacity=0.0625 absoluteUsedCapacity=0.0625 used=<memory:3072, vCores:2> cluster=<memory:49152, vCores:96>
2013-08-09 20:51:55,753 INFO org.apache.hadoop.yarn.server.resourcemanager.scheduler.capacity.ParentQueue: completedContainer queue=root usedCapacity=0.0625 absoluteUsedCapacity=0.0625 used=<memory:3072, vCores:2> cluster=<memory:49152, vCores:96>
2013-08-09 20:51:55,753 INFO org.apache.hadoop.yarn.server.resourcemanager.scheduler.capacity.CapacityScheduler: Application appattempt_1376080735992_0005_000001 released container container_1376080735992_0005_01_000002 on node: host: hadoop-210-6:41207 #containers=0 available=8192 used=0 with event: FINISHED
2013-08-09 20:52:00,447 INFO org.apache.hadoop.yarn.server.resourcemanager.rmcontainer.RMContainerImpl: container_1376080735992_0005_01_000003 Container Transitioned from RUNNING to COMPLETED
2013-08-09 20:52:00,447 INFO org.apache.hadoop.yarn.server.resourcemanager.scheduler.common.fica.FiCaSchedulerApp: Completed container: container_1376080735992_0005_01_000003 in state: COMPLETED event:FINISHED
2013-08-09 20:52:00,447 INFO org.apache.hadoop.yarn.server.resourcemanager.RMAuditLogger: USER=ubuntu	OPERATION=AM Released Container	TARGET=SchedulerApp	RESULT=SUCCESS	APPID=application_1376080735992_0005	CONTAINERID=container_1376080735992_0005_01_000003
2013-08-09 20:52:00,447 INFO org.apache.hadoop.yarn.server.resourcemanager.scheduler.common.fica.FiCaSchedulerNode: Released container container_1376080735992_0005_01_000003 of capacity <memory:1024, vCores:1> on host hadoop-210-5:40689, which currently has 1 containers, <memory:2048, vCores:1> used and <memory:6144, vCores:15> available, release resources=true
2013-08-09 20:52:00,448 INFO org.apache.hadoop.yarn.server.resourcemanager.scheduler.capacity.LeafQueue: default used=<memory:2048, vCores:1> numContainers=1 user=ubuntu user-resources=<memory:2048, vCores:1>
2013-08-09 20:52:00,449 INFO org.apache.hadoop.yarn.server.resourcemanager.scheduler.capacity.LeafQueue: completedContainer container=Container: [ContainerId: container_1376080735992_0005_01_000003, NodeId: hadoop-210-5:40689, NodeHttpAddress: hadoop-210-5:8042, Resource: <memory:1024, vCores:1>, Priority: 20, State: NEW, Token: null, Status: container_id {, app_attempt_id {, application_id {, id: 5, cluster_timestamp: 1376080735992, }, attemptId: 1, }, id: 3, }, state: C_COMPLETE, diagnostics: "Container killed by the ApplicationMaster.\n\n", exit_status: 143, ] resource=<memory:1024, vCores:1> queue=default: capacity=1.0, absoluteCapacity=1.0, usedResources=<memory:2048, vCores:1>usedCapacity=0.041666668, absoluteUsedCapacity=0.041666668, numApps=1, numContainers=1 usedCapacity=0.041666668 absoluteUsedCapacity=0.041666668 used=<memory:2048, vCores:1> cluster=<memory:49152, vCores:96>
2013-08-09 20:52:00,449 INFO org.apache.hadoop.yarn.server.resourcemanager.scheduler.capacity.ParentQueue: completedContainer queue=root usedCapacity=0.041666668 absoluteUsedCapacity=0.041666668 used=<memory:2048, vCores:1> cluster=<memory:49152, vCores:96>
2013-08-09 20:52:00,450 INFO org.apache.hadoop.yarn.server.resourcemanager.scheduler.capacity.CapacityScheduler: Application appattempt_1376080735992_0005_000001 released container container_1376080735992_0005_01_000003 on node: host: hadoop-210-5:40689 #containers=1 available=6144 used=2048 with event: FINISHED
2013-08-09 20:52:04,576 INFO org.apache.hadoop.yarn.server.resourcemanager.rmapp.attempt.RMAppAttemptImpl: appattempt_1376080735992_0005_000001 State change from RUNNING to FINISHING
2013-08-09 20:52:04,577 INFO org.apache.hadoop.yarn.server.resourcemanager.rmapp.RMAppImpl: application_1376080735992_0005 State change from RUNNING to FINISHING
2013-08-09 20:52:05,467 INFO org.apache.hadoop.yarn.server.resourcemanager.rmcontainer.RMContainerImpl: container_1376080735992_0005_01_000001 Container Transitioned from RUNNING to COMPLETED
2013-08-09 20:52:05,468 INFO org.apache.hadoop.yarn.server.resourcemanager.scheduler.common.fica.FiCaSchedulerApp: Completed container: container_1376080735992_0005_01_000001 in state: COMPLETED event:FINISHED
2013-08-09 20:52:05,468 INFO org.apache.hadoop.yarn.server.resourcemanager.rmapp.attempt.RMAppAttemptImpl: appattempt_1376080735992_0005_000001 State change from FINISHING to FINISHED
2013-08-09 20:52:05,468 INFO org.apache.hadoop.yarn.server.resourcemanager.RMAuditLogger: USER=ubuntu	OPERATION=AM Released Container	TARGET=SchedulerApp	RESULT=SUCCESS	APPID=application_1376080735992_0005	CONTAINERID=container_1376080735992_0005_01_000001
2013-08-09 20:52:05,468 INFO org.apache.hadoop.yarn.server.resourcemanager.rmapp.RMAppImpl: application_1376080735992_0005 State change from FINISHING to FINISHED
2013-08-09 20:52:05,468 INFO org.apache.hadoop.yarn.server.resourcemanager.scheduler.common.fica.FiCaSchedulerNode: Released container container_1376080735992_0005_01_000001 of capacity <memory:2048, vCores:1> on host hadoop-210-5:40689, which currently has 0 containers, <memory:0, vCores:0> used and <memory:8192, vCores:16> available, release resources=true
2013-08-09 20:52:05,468 INFO org.apache.hadoop.yarn.server.resourcemanager.RMAuditLogger: USER=ubuntu	OPERATION=Application Finished - Succeeded	TARGET=RMAppManager	RESULT=SUCCESS	APPID=application_1376080735992_0005
2013-08-09 20:52:05,469 INFO org.apache.hadoop.yarn.server.resourcemanager.scheduler.capacity.LeafQueue: default used=<memory:0, vCores:0> numContainers=0 user=ubuntu user-resources=<memory:0, vCores:0>
2013-08-09 20:52:05,469 INFO org.apache.hadoop.yarn.server.resourcemanager.recovery.RMStateStore: Removing info for app: application_1376080735992_0005
2013-08-09 20:52:05,469 INFO org.apache.hadoop.yarn.server.resourcemanager.amlauncher.AMLauncher: Cleaning master appattempt_1376080735992_0005_000001
2013-08-09 20:52:05,469 INFO org.apache.hadoop.yarn.server.resourcemanager.RMAppManager$ApplicationSummary: appId=application_1376080735992_0005,name=TeraGen,user=ubuntu,queue=default,state=FINISHED,trackingUrl=hadoop-210-1.novalocal:8088/proxy/application_1376080735992_0005/jobhistory/job/job_1376080735992_0005,appMasterHost=hadoop-210-5,startTime=1376081406300,finishTime=1376081524577
2013-08-09 20:52:05,470 INFO org.apache.hadoop.yarn.server.resourcemanager.scheduler.capacity.LeafQueue: completedContainer container=Container: [ContainerId: container_1376080735992_0005_01_000001, NodeId: hadoop-210-5:40689, NodeHttpAddress: hadoop-210-5:8042, Resource: <memory:2048, vCores:1>, Priority: 0, State: NEW, Token: null, Status: container_id {, app_attempt_id {, application_id {, id: 5, cluster_timestamp: 1376080735992, }, attemptId: 1, }, id: 1, }, state: C_COMPLETE, diagnostics: "", exit_status: 0, ] resource=<memory:2048, vCores:1> queue=default: capacity=1.0, absoluteCapacity=1.0, usedResources=<memory:0, vCores:0>usedCapacity=0.0, absoluteUsedCapacity=0.0, numApps=1, numContainers=0 usedCapacity=0.0 absoluteUsedCapacity=0.0 used=<memory:0, vCores:0> cluster=<memory:49152, vCores:96>
2013-08-09 20:52:05,470 INFO org.apache.hadoop.yarn.server.resourcemanager.scheduler.capacity.ParentQueue: completedContainer queue=root usedCapacity=0.0 absoluteUsedCapacity=0.0 used=<memory:0, vCores:0> cluster=<memory:49152, vCores:96>
2013-08-09 20:52:05,470 INFO org.apache.hadoop.yarn.server.resourcemanager.scheduler.capacity.CapacityScheduler: Application appattempt_1376080735992_0005_000001 released container container_1376080735992_0005_01_000001 on node: host: hadoop-210-5:40689 #containers=0 available=8192 used=0 with event: FINISHED
2013-08-09 20:52:05,471 INFO org.apache.hadoop.yarn.server.resourcemanager.scheduler.capacity.CapacityScheduler: Application appattempt_1376080735992_0005_000001 is done. finalState=FINISHED
2013-08-09 20:52:05,471 INFO org.apache.hadoop.yarn.server.resourcemanager.scheduler.AppSchedulingInfo: Application application_1376080735992_0005 requests cleared
2013-08-09 20:52:05,471 INFO org.apache.hadoop.yarn.server.resourcemanager.scheduler.capacity.LeafQueue: Application removed - appId: application_1376080735992_0005 user: ubuntu queue: default #user-pending-applications: 0 #user-active-applications: 0 #queue-pending-applications: 0 #queue-active-applications: 0
2013-08-09 20:52:05,471 INFO org.apache.hadoop.yarn.server.resourcemanager.scheduler.capacity.ParentQueue: Application removed - appId: application_1376080735992_0005 user: ubuntu leaf-queue of parent: root #applications: 0
2013-08-09 20:53:20,164 INFO org.apache.hadoop.yarn.server.resourcemanager.ClientRMService: Allocated new applicationId: 6
2013-08-09 20:53:20,195 INFO org.apache.hadoop.yarn.server.resourcemanager.ClientRMService: Allocated new applicationId: 7
2013-08-09 20:53:20,271 INFO org.apache.hadoop.yarn.server.resourcemanager.ClientRMService: Allocated new applicationId: 8
2013-08-09 20:53:20,396 INFO org.apache.hadoop.yarn.server.resourcemanager.ClientRMService: Allocated new applicationId: 9
2013-08-09 20:53:20,972 INFO org.apache.hadoop.yarn.server.resourcemanager.ClientRMService: Allocated new applicationId: 10
2013-08-09 20:53:21,748 INFO org.apache.hadoop.yarn.server.resourcemanager.ClientRMService: Storing Application with id application_1376080735992_0006
2013-08-09 20:53:21,749 INFO org.apache.hadoop.yarn.server.resourcemanager.recovery.RMStateStore: Storing info for app: application_1376080735992_0006
2013-08-09 20:53:21,749 INFO org.apache.hadoop.yarn.server.resourcemanager.ClientRMService: Application with id 6 submitted by user ubuntu
2013-08-09 20:53:21,749 INFO org.apache.hadoop.yarn.server.resourcemanager.RMAuditLogger: USER=ubuntu	IP=192.168.100.4	OPERATION=Submit Application Request	TARGET=ClientRMService	RESULT=SUCCESS	APPID=application_1376080735992_0006
2013-08-09 20:53:21,751 INFO org.apache.hadoop.yarn.server.resourcemanager.rmapp.RMAppImpl: application_1376080735992_0006 State change from NEW to SUBMITTED
2013-08-09 20:53:21,751 INFO org.apache.hadoop.yarn.server.resourcemanager.ApplicationMasterService: Registering appattempt_1376080735992_0006_000001
2013-08-09 20:53:21,752 INFO org.apache.hadoop.yarn.server.resourcemanager.rmapp.attempt.RMAppAttemptImpl: appattempt_1376080735992_0006_000001 State change from NEW to SUBMITTED
2013-08-09 20:53:21,752 INFO org.apache.hadoop.yarn.server.resourcemanager.scheduler.capacity.LeafQueue: Application application_1376080735992_0006 from user: ubuntu activated in queue: default
2013-08-09 20:53:21,752 INFO org.apache.hadoop.yarn.server.resourcemanager.scheduler.capacity.LeafQueue: Application added - appId: application_1376080735992_0006 user: org.apache.hadoop.yarn.server.resourcemanager.scheduler.capacity.LeafQueue$User@494082d3, leaf-queue: default #user-pending-applications: 0 #user-active-applications: 1 #queue-pending-applications: 0 #queue-active-applications: 1
2013-08-09 20:53:21,752 INFO org.apache.hadoop.yarn.server.resourcemanager.scheduler.capacity.ParentQueue: Application added - appId: application_1376080735992_0006 user: ubuntu leaf-queue of parent: root #applications: 1
2013-08-09 20:53:21,752 INFO org.apache.hadoop.yarn.server.resourcemanager.scheduler.capacity.CapacityScheduler: Application Submission: appattempt_1376080735992_0006_000001, user: ubuntu queue: default: capacity=1.0, absoluteCapacity=1.0, usedResources=<memory:0, vCores:0>usedCapacity=0.0, absoluteUsedCapacity=0.0, numApps=1, numContainers=0, currently active: 1
2013-08-09 20:53:21,752 INFO org.apache.hadoop.yarn.server.resourcemanager.rmapp.attempt.RMAppAttemptImpl: appattempt_1376080735992_0006_000001 State change from SUBMITTED to SCHEDULED
2013-08-09 20:53:21,752 INFO org.apache.hadoop.yarn.server.resourcemanager.rmapp.RMAppImpl: application_1376080735992_0006 State change from SUBMITTED to ACCEPTED
2013-08-09 20:53:21,753 INFO org.apache.hadoop.yarn.server.resourcemanager.ClientRMService: Storing Application with id application_1376080735992_0007
2013-08-09 20:53:21,753 INFO org.apache.hadoop.yarn.server.resourcemanager.recovery.RMStateStore: Storing info for app: application_1376080735992_0007
2013-08-09 20:53:21,753 INFO org.apache.hadoop.yarn.server.resourcemanager.ClientRMService: Application with id 7 submitted by user ubuntu
2013-08-09 20:53:21,753 INFO org.apache.hadoop.yarn.server.resourcemanager.RMAuditLogger: USER=ubuntu	IP=192.168.100.4	OPERATION=Submit Application Request	TARGET=ClientRMService	RESULT=SUCCESS	APPID=application_1376080735992_0007
2013-08-09 20:53:21,754 INFO org.apache.hadoop.yarn.server.resourcemanager.rmapp.RMAppImpl: application_1376080735992_0007 State change from NEW to SUBMITTED
2013-08-09 20:53:21,754 INFO org.apache.hadoop.yarn.server.resourcemanager.ApplicationMasterService: Registering appattempt_1376080735992_0007_000001
2013-08-09 20:53:21,754 INFO org.apache.hadoop.yarn.server.resourcemanager.rmapp.attempt.RMAppAttemptImpl: appattempt_1376080735992_0007_000001 State change from NEW to SUBMITTED
2013-08-09 20:53:21,754 INFO org.apache.hadoop.yarn.server.resourcemanager.scheduler.capacity.LeafQueue: Application application_1376080735992_0007 from user: ubuntu activated in queue: default
2013-08-09 20:53:21,754 INFO org.apache.hadoop.yarn.server.resourcemanager.scheduler.capacity.LeafQueue: Application added - appId: application_1376080735992_0007 user: org.apache.hadoop.yarn.server.resourcemanager.scheduler.capacity.LeafQueue$User@494082d3, leaf-queue: default #user-pending-applications: 0 #user-active-applications: 2 #queue-pending-applications: 0 #queue-active-applications: 2
2013-08-09 20:53:21,754 INFO org.apache.hadoop.yarn.server.resourcemanager.scheduler.capacity.ParentQueue: Application added - appId: application_1376080735992_0007 user: ubuntu leaf-queue of parent: root #applications: 2
2013-08-09 20:53:21,755 INFO org.apache.hadoop.yarn.server.resourcemanager.scheduler.capacity.CapacityScheduler: Application Submission: appattempt_1376080735992_0007_000001, user: ubuntu queue: default: capacity=1.0, absoluteCapacity=1.0, usedResources=<memory:0, vCores:0>usedCapacity=0.0, absoluteUsedCapacity=0.0, numApps=2, numContainers=0, currently active: 2
2013-08-09 20:53:21,760 INFO org.apache.hadoop.yarn.server.resourcemanager.rmapp.attempt.RMAppAttemptImpl: appattempt_1376080735992_0007_000001 State change from SUBMITTED to SCHEDULED
2013-08-09 20:53:21,761 INFO org.apache.hadoop.yarn.server.resourcemanager.rmapp.RMAppImpl: application_1376080735992_0007 State change from SUBMITTED to ACCEPTED
2013-08-09 20:53:21,788 INFO org.apache.hadoop.yarn.server.resourcemanager.ClientRMService: Storing Application with id application_1376080735992_0009
2013-08-09 20:53:21,788 INFO org.apache.hadoop.yarn.server.resourcemanager.recovery.RMStateStore: Storing info for app: application_1376080735992_0009
2013-08-09 20:53:21,788 INFO org.apache.hadoop.yarn.server.resourcemanager.ClientRMService: Application with id 9 submitted by user ubuntu
2013-08-09 20:53:21,789 INFO org.apache.hadoop.yarn.server.resourcemanager.RMAuditLogger: USER=ubuntu	IP=192.168.100.4	OPERATION=Submit Application Request	TARGET=ClientRMService	RESULT=SUCCESS	APPID=application_1376080735992_0009
2013-08-09 20:53:21,795 INFO org.apache.hadoop.yarn.server.resourcemanager.rmapp.RMAppImpl: application_1376080735992_0009 State change from NEW to SUBMITTED
2013-08-09 20:53:21,795 INFO org.apache.hadoop.yarn.server.resourcemanager.ApplicationMasterService: Registering appattempt_1376080735992_0009_000001
2013-08-09 20:53:21,795 INFO org.apache.hadoop.yarn.server.resourcemanager.rmapp.attempt.RMAppAttemptImpl: appattempt_1376080735992_0009_000001 State change from NEW to SUBMITTED
2013-08-09 20:53:21,796 INFO org.apache.hadoop.yarn.server.resourcemanager.scheduler.capacity.LeafQueue: Application application_1376080735992_0009 from user: ubuntu activated in queue: default
2013-08-09 20:53:21,796 INFO org.apache.hadoop.yarn.server.resourcemanager.scheduler.capacity.LeafQueue: Application added - appId: application_1376080735992_0009 user: org.apache.hadoop.yarn.server.resourcemanager.scheduler.capacity.LeafQueue$User@494082d3, leaf-queue: default #user-pending-applications: 0 #user-active-applications: 3 #queue-pending-applications: 0 #queue-active-applications: 3
2013-08-09 20:53:21,796 INFO org.apache.hadoop.yarn.server.resourcemanager.scheduler.capacity.ParentQueue: Application added - appId: application_1376080735992_0009 user: ubuntu leaf-queue of parent: root #applications: 3
2013-08-09 20:53:21,796 INFO org.apache.hadoop.yarn.server.resourcemanager.scheduler.capacity.CapacityScheduler: Application Submission: appattempt_1376080735992_0009_000001, user: ubuntu queue: default: capacity=1.0, absoluteCapacity=1.0, usedResources=<memory:0, vCores:0>usedCapacity=0.0, absoluteUsedCapacity=0.0, numApps=3, numContainers=0, currently active: 3
2013-08-09 20:53:21,797 INFO org.apache.hadoop.yarn.server.resourcemanager.rmapp.attempt.RMAppAttemptImpl: appattempt_1376080735992_0009_000001 State change from SUBMITTED to SCHEDULED
2013-08-09 20:53:21,797 INFO org.apache.hadoop.yarn.server.resourcemanager.rmapp.RMAppImpl: application_1376080735992_0009 State change from SUBMITTED to ACCEPTED
2013-08-09 20:53:21,799 INFO org.apache.hadoop.yarn.server.resourcemanager.ClientRMService: Storing Application with id application_1376080735992_0008
2013-08-09 20:53:21,799 INFO org.apache.hadoop.yarn.server.resourcemanager.recovery.RMStateStore: Storing info for app: application_1376080735992_0008
2013-08-09 20:53:21,799 INFO org.apache.hadoop.yarn.server.resourcemanager.ClientRMService: Application with id 8 submitted by user ubuntu
2013-08-09 20:53:21,799 INFO org.apache.hadoop.yarn.server.resourcemanager.RMAuditLogger: USER=ubuntu	IP=192.168.100.4	OPERATION=Submit Application Request	TARGET=ClientRMService	RESULT=SUCCESS	APPID=application_1376080735992_0008
2013-08-09 20:53:21,800 INFO org.apache.hadoop.yarn.server.resourcemanager.rmapp.RMAppImpl: application_1376080735992_0008 State change from NEW to SUBMITTED
2013-08-09 20:53:21,800 INFO org.apache.hadoop.yarn.server.resourcemanager.ApplicationMasterService: Registering appattempt_1376080735992_0008_000001
2013-08-09 20:53:21,800 INFO org.apache.hadoop.yarn.server.resourcemanager.rmapp.attempt.RMAppAttemptImpl: appattempt_1376080735992_0008_000001 State change from NEW to SUBMITTED
2013-08-09 20:53:21,804 INFO org.apache.hadoop.yarn.server.resourcemanager.scheduler.capacity.LeafQueue: Application application_1376080735992_0008 from user: ubuntu activated in queue: default
2013-08-09 20:53:21,804 INFO org.apache.hadoop.yarn.server.resourcemanager.scheduler.capacity.LeafQueue: Application added - appId: application_1376080735992_0008 user: org.apache.hadoop.yarn.server.resourcemanager.scheduler.capacity.LeafQueue$User@494082d3, leaf-queue: default #user-pending-applications: 0 #user-active-applications: 4 #queue-pending-applications: 0 #queue-active-applications: 4
2013-08-09 20:53:21,804 INFO org.apache.hadoop.yarn.server.resourcemanager.scheduler.capacity.ParentQueue: Application added - appId: application_1376080735992_0008 user: ubuntu leaf-queue of parent: root #applications: 4
2013-08-09 20:53:21,804 INFO org.apache.hadoop.yarn.server.resourcemanager.scheduler.capacity.CapacityScheduler: Application Submission: appattempt_1376080735992_0008_000001, user: ubuntu queue: default: capacity=1.0, absoluteCapacity=1.0, usedResources=<memory:0, vCores:0>usedCapacity=0.0, absoluteUsedCapacity=0.0, numApps=4, numContainers=0, currently active: 4
2013-08-09 20:53:21,805 INFO org.apache.hadoop.yarn.server.resourcemanager.rmapp.attempt.RMAppAttemptImpl: appattempt_1376080735992_0008_000001 State change from SUBMITTED to SCHEDULED
2013-08-09 20:53:21,805 INFO org.apache.hadoop.yarn.server.resourcemanager.rmapp.RMAppImpl: application_1376080735992_0008 State change from SUBMITTED to ACCEPTED
2013-08-09 20:53:22,032 INFO org.apache.hadoop.yarn.server.resourcemanager.rmcontainer.RMContainerImpl: container_1376080735992_0006_01_000001 Container Transitioned from NEW to ALLOCATED
2013-08-09 20:53:22,032 INFO org.apache.hadoop.yarn.server.resourcemanager.RMAuditLogger: USER=ubuntu	OPERATION=AM Allocated Container	TARGET=SchedulerApp	RESULT=SUCCESS	APPID=application_1376080735992_0006	CONTAINERID=container_1376080735992_0006_01_000001
2013-08-09 20:53:22,032 INFO org.apache.hadoop.yarn.server.resourcemanager.scheduler.common.fica.FiCaSchedulerNode: Assigned container container_1376080735992_0006_01_000001 of capacity <memory:2048, vCores:1> on host hadoop-210-6:41207, which currently has 1 containers, <memory:2048, vCores:1> used and <memory:6144, vCores:15> available
2013-08-09 20:53:22,033 INFO org.apache.hadoop.yarn.server.resourcemanager.scheduler.capacity.LeafQueue: assignedContainer application=application_1376080735992_0006 container=Container: [ContainerId: container_1376080735992_0006_01_000001, NodeId: hadoop-210-6:41207, NodeHttpAddress: hadoop-210-6:8042, Resource: <memory:2048, vCores:1>, Priority: 0, State: NEW, Token: null, Status: container_id {, app_attempt_id {, application_id {, id: 6, cluster_timestamp: 1376080735992, }, attemptId: 1, }, id: 1, }, state: C_NEW, ] containerId=container_1376080735992_0006_01_000001 queue=default: capacity=1.0, absoluteCapacity=1.0, usedResources=<memory:0, vCores:0>usedCapacity=0.0, absoluteUsedCapacity=0.0, numApps=4, numContainers=0 usedCapacity=0.0 absoluteUsedCapacity=0.0 used=<memory:0, vCores:0> cluster=<memory:49152, vCores:96>
2013-08-09 20:53:22,033 INFO org.apache.hadoop.yarn.server.resourcemanager.scheduler.capacity.ParentQueue: Re-sorting queues since queue: root.default stats: default: capacity=1.0, absoluteCapacity=1.0, usedResources=<memory:2048, vCores:1>usedCapacity=0.041666668, absoluteUsedCapacity=0.041666668, numApps=4, numContainers=1
2013-08-09 20:53:22,033 INFO org.apache.hadoop.yarn.server.resourcemanager.scheduler.capacity.ParentQueue: assignedContainer queue=root usedCapacity=0.041666668 absoluteUsedCapacity=0.041666668 used=<memory:2048, vCores:1> cluster=<memory:49152, vCores:96>
2013-08-09 20:53:22,034 INFO org.apache.hadoop.yarn.server.resourcemanager.rmcontainer.RMContainerImpl: container_1376080735992_0006_01_000001 Container Transitioned from ALLOCATED to ACQUIRED
2013-08-09 20:53:22,034 INFO org.apache.hadoop.yarn.server.resourcemanager.rmapp.attempt.RMAppAttemptImpl: Storing attempt: AppId: application_1376080735992_0006 AttemptId: appattempt_1376080735992_0006_000001 MasterContainer: Container: [ContainerId: container_1376080735992_0006_01_000001, NodeId: hadoop-210-6:41207, NodeHttpAddress: hadoop-210-6:8042, Resource: <memory:2048, vCores:1>, Priority: 0, State: NEW, Token: null, Status: container_id {, app_attempt_id {, application_id {, id: 6, cluster_timestamp: 1376080735992, }, attemptId: 1, }, id: 1, }, state: C_NEW, ]
2013-08-09 20:53:22,035 INFO org.apache.hadoop.yarn.server.resourcemanager.recovery.RMStateStore: Storing info for attempt: appattempt_1376080735992_0006_000001
2013-08-09 20:53:22,035 INFO org.apache.hadoop.yarn.server.resourcemanager.rmapp.attempt.RMAppAttemptImpl: appattempt_1376080735992_0006_000001 State change from SCHEDULED to ALLOCATED_SAVING
2013-08-09 20:53:22,035 INFO org.apache.hadoop.yarn.server.resourcemanager.rmapp.attempt.RMAppAttemptImpl: appattempt_1376080735992_0006_000001 State change from ALLOCATED_SAVING to ALLOCATED
2013-08-09 20:53:22,035 INFO org.apache.hadoop.yarn.server.resourcemanager.amlauncher.AMLauncher: Launching masterappattempt_1376080735992_0006_000001
2013-08-09 20:53:22,036 INFO org.apache.hadoop.yarn.server.resourcemanager.amlauncher.AMLauncher: Setting up container Container: [ContainerId: container_1376080735992_0006_01_000001, NodeId: hadoop-210-6:41207, NodeHttpAddress: hadoop-210-6:8042, Resource: <memory:2048, vCores:1>, Priority: 0, State: NEW, Token: null, Status: container_id {, app_attempt_id {, application_id {, id: 6, cluster_timestamp: 1376080735992, }, attemptId: 1, }, id: 1, }, state: C_NEW, ] for AM appattempt_1376080735992_0006_000001
2013-08-09 20:53:22,037 INFO org.apache.hadoop.yarn.server.resourcemanager.amlauncher.AMLauncher: Command to launch container container_1376080735992_0006_01_000001 : $JAVA_HOME/bin/java -Dlog4j.configuration=container-log4j.properties -Dyarn.app.mapreduce.container.log.dir=<LOG_DIR> -Dyarn.app.mapreduce.container.log.filesize=0 -Dhadoop.root.logger=INFO,CLA  -Xmx1024m org.apache.hadoop.mapreduce.v2.app.MRAppMaster 1><LOG_DIR>/stdout 2><LOG_DIR>/stderr 
2013-08-09 20:53:22,050 INFO org.apache.hadoop.yarn.server.resourcemanager.amlauncher.AMLauncher: Done launching container Container: [ContainerId: container_1376080735992_0006_01_000001, NodeId: hadoop-210-6:41207, NodeHttpAddress: hadoop-210-6:8042, Resource: <memory:2048, vCores:1>, Priority: 0, State: NEW, Token: null, Status: container_id {, app_attempt_id {, application_id {, id: 6, cluster_timestamp: 1376080735992, }, attemptId: 1, }, id: 1, }, state: C_NEW, ] for AM appattempt_1376080735992_0006_000001
2013-08-09 20:53:22,050 INFO org.apache.hadoop.yarn.server.resourcemanager.rmapp.attempt.RMAppAttemptImpl: appattempt_1376080735992_0006_000001 State change from ALLOCATED to LAUNCHED
2013-08-09 20:53:22,345 INFO org.apache.hadoop.yarn.server.resourcemanager.ClientRMService: Storing Application with id application_1376080735992_0010
2013-08-09 20:53:22,347 INFO org.apache.hadoop.yarn.server.resourcemanager.recovery.RMStateStore: Storing info for app: application_1376080735992_0010
2013-08-09 20:53:22,347 INFO org.apache.hadoop.yarn.server.resourcemanager.ClientRMService: Application with id 10 submitted by user ubuntu
2013-08-09 20:53:22,347 INFO org.apache.hadoop.yarn.server.resourcemanager.RMAuditLogger: USER=ubuntu	IP=192.168.100.4	OPERATION=Submit Application Request	TARGET=ClientRMService	RESULT=SUCCESS	APPID=application_1376080735992_0010
2013-08-09 20:53:22,348 INFO org.apache.hadoop.yarn.server.resourcemanager.rmapp.RMAppImpl: application_1376080735992_0010 State change from NEW to SUBMITTED
2013-08-09 20:53:22,348 INFO org.apache.hadoop.yarn.server.resourcemanager.ApplicationMasterService: Registering appattempt_1376080735992_0010_000001
2013-08-09 20:53:22,348 INFO org.apache.hadoop.yarn.server.resourcemanager.rmapp.attempt.RMAppAttemptImpl: appattempt_1376080735992_0010_000001 State change from NEW to SUBMITTED
2013-08-09 20:53:22,349 INFO org.apache.hadoop.yarn.server.resourcemanager.scheduler.capacity.LeafQueue: Application application_1376080735992_0010 from user: ubuntu activated in queue: default
2013-08-09 20:53:22,349 INFO org.apache.hadoop.yarn.server.resourcemanager.scheduler.capacity.LeafQueue: Application added - appId: application_1376080735992_0010 user: org.apache.hadoop.yarn.server.resourcemanager.scheduler.capacity.LeafQueue$User@494082d3, leaf-queue: default #user-pending-applications: 0 #user-active-applications: 5 #queue-pending-applications: 0 #queue-active-applications: 5
2013-08-09 20:53:22,349 INFO org.apache.hadoop.yarn.server.resourcemanager.scheduler.capacity.ParentQueue: Application added - appId: application_1376080735992_0010 user: ubuntu leaf-queue of parent: root #applications: 5
2013-08-09 20:53:22,349 INFO org.apache.hadoop.yarn.server.resourcemanager.scheduler.capacity.CapacityScheduler: Application Submission: appattempt_1376080735992_0010_000001, user: ubuntu queue: default: capacity=1.0, absoluteCapacity=1.0, usedResources=<memory:2048, vCores:1>usedCapacity=0.041666668, absoluteUsedCapacity=0.041666668, numApps=5, numContainers=1, currently active: 5
2013-08-09 20:53:22,350 INFO org.apache.hadoop.yarn.server.resourcemanager.rmapp.attempt.RMAppAttemptImpl: appattempt_1376080735992_0010_000001 State change from SUBMITTED to SCHEDULED
2013-08-09 20:53:22,350 INFO org.apache.hadoop.yarn.server.resourcemanager.rmapp.RMAppImpl: application_1376080735992_0010 State change from SUBMITTED to ACCEPTED
2013-08-09 20:53:22,378 INFO org.apache.hadoop.yarn.server.resourcemanager.rmcontainer.RMContainerImpl: container_1376080735992_0007_01_000001 Container Transitioned from NEW to ALLOCATED
2013-08-09 20:53:22,379 INFO org.apache.hadoop.yarn.server.resourcemanager.RMAuditLogger: USER=ubuntu	OPERATION=AM Allocated Container	TARGET=SchedulerApp	RESULT=SUCCESS	APPID=application_1376080735992_0007	CONTAINERID=container_1376080735992_0007_01_000001
2013-08-09 20:53:22,379 INFO org.apache.hadoop.yarn.server.resourcemanager.scheduler.common.fica.FiCaSchedulerNode: Assigned container container_1376080735992_0007_01_000001 of capacity <memory:2048, vCores:1> on host hadoop-210-7:35638, which currently has 1 containers, <memory:2048, vCores:1> used and <memory:6144, vCores:15> available
2013-08-09 20:53:22,380 INFO org.apache.hadoop.yarn.server.resourcemanager.scheduler.capacity.LeafQueue: assignedContainer application=application_1376080735992_0007 container=Container: [ContainerId: container_1376080735992_0007_01_000001, NodeId: hadoop-210-7:35638, NodeHttpAddress: hadoop-210-7:8042, Resource: <memory:2048, vCores:1>, Priority: 0, State: NEW, Token: null, Status: container_id {, app_attempt_id {, application_id {, id: 7, cluster_timestamp: 1376080735992, }, attemptId: 1, }, id: 1, }, state: C_NEW, ] containerId=container_1376080735992_0007_01_000001 queue=default: capacity=1.0, absoluteCapacity=1.0, usedResources=<memory:2048, vCores:1>usedCapacity=0.041666668, absoluteUsedCapacity=0.041666668, numApps=5, numContainers=1 usedCapacity=0.041666668 absoluteUsedCapacity=0.041666668 used=<memory:2048, vCores:1> cluster=<memory:49152, vCores:96>
2013-08-09 20:53:22,380 INFO org.apache.hadoop.yarn.server.resourcemanager.scheduler.capacity.ParentQueue: Re-sorting queues since queue: root.default stats: default: capacity=1.0, absoluteCapacity=1.0, usedResources=<memory:4096, vCores:2>usedCapacity=0.083333336, absoluteUsedCapacity=0.083333336, numApps=5, numContainers=2
2013-08-09 20:53:22,382 INFO org.apache.hadoop.yarn.server.resourcemanager.rmcontainer.RMContainerImpl: container_1376080735992_0007_01_000001 Container Transitioned from ALLOCATED to ACQUIRED
2013-08-09 20:53:22,382 INFO org.apache.hadoop.yarn.server.resourcemanager.scheduler.capacity.ParentQueue: assignedContainer queue=root usedCapacity=0.083333336 absoluteUsedCapacity=0.083333336 used=<memory:4096, vCores:2> cluster=<memory:49152, vCores:96>
2013-08-09 20:53:22,383 INFO org.apache.hadoop.yarn.server.resourcemanager.rmapp.attempt.RMAppAttemptImpl: Storing attempt: AppId: application_1376080735992_0007 AttemptId: appattempt_1376080735992_0007_000001 MasterContainer: Container: [ContainerId: container_1376080735992_0007_01_000001, NodeId: hadoop-210-7:35638, NodeHttpAddress: hadoop-210-7:8042, Resource: <memory:2048, vCores:1>, Priority: 0, State: NEW, Token: null, Status: container_id {, app_attempt_id {, application_id {, id: 7, cluster_timestamp: 1376080735992, }, attemptId: 1, }, id: 1, }, state: C_NEW, ]
2013-08-09 20:53:22,383 INFO org.apache.hadoop.yarn.server.resourcemanager.rmapp.attempt.RMAppAttemptImpl: appattempt_1376080735992_0007_000001 State change from SCHEDULED to ALLOCATED_SAVING
2013-08-09 20:53:22,384 INFO org.apache.hadoop.yarn.server.resourcemanager.recovery.RMStateStore: Storing info for attempt: appattempt_1376080735992_0007_000001
2013-08-09 20:53:22,384 INFO org.apache.hadoop.yarn.server.resourcemanager.rmapp.attempt.RMAppAttemptImpl: appattempt_1376080735992_0007_000001 State change from ALLOCATED_SAVING to ALLOCATED
2013-08-09 20:53:22,385 INFO org.apache.hadoop.yarn.server.resourcemanager.amlauncher.AMLauncher: Launching masterappattempt_1376080735992_0007_000001
2013-08-09 20:53:22,388 INFO org.apache.hadoop.yarn.server.resourcemanager.amlauncher.AMLauncher: Setting up container Container: [ContainerId: container_1376080735992_0007_01_000001, NodeId: hadoop-210-7:35638, NodeHttpAddress: hadoop-210-7:8042, Resource: <memory:2048, vCores:1>, Priority: 0, State: NEW, Token: null, Status: container_id {, app_attempt_id {, application_id {, id: 7, cluster_timestamp: 1376080735992, }, attemptId: 1, }, id: 1, }, state: C_NEW, ] for AM appattempt_1376080735992_0007_000001
2013-08-09 20:53:22,388 INFO org.apache.hadoop.yarn.server.resourcemanager.amlauncher.AMLauncher: Command to launch container container_1376080735992_0007_01_000001 : $JAVA_HOME/bin/java -Dlog4j.configuration=container-log4j.properties -Dyarn.app.mapreduce.container.log.dir=<LOG_DIR> -Dyarn.app.mapreduce.container.log.filesize=0 -Dhadoop.root.logger=INFO,CLA  -Xmx1024m org.apache.hadoop.mapreduce.v2.app.MRAppMaster 1><LOG_DIR>/stdout 2><LOG_DIR>/stderr 
2013-08-09 20:53:22,411 INFO org.apache.hadoop.yarn.server.resourcemanager.amlauncher.AMLauncher: Done launching container Container: [ContainerId: container_1376080735992_0007_01_000001, NodeId: hadoop-210-7:35638, NodeHttpAddress: hadoop-210-7:8042, Resource: <memory:2048, vCores:1>, Priority: 0, State: NEW, Token: null, Status: container_id {, app_attempt_id {, application_id {, id: 7, cluster_timestamp: 1376080735992, }, attemptId: 1, }, id: 1, }, state: C_NEW, ] for AM appattempt_1376080735992_0007_000001
2013-08-09 20:53:22,411 INFO org.apache.hadoop.yarn.server.resourcemanager.rmapp.attempt.RMAppAttemptImpl: appattempt_1376080735992_0007_000001 State change from ALLOCATED to LAUNCHED
2013-08-09 20:53:22,608 INFO org.apache.hadoop.yarn.server.resourcemanager.rmcontainer.RMContainerImpl: container_1376080735992_0008_01_000001 Container Transitioned from NEW to ALLOCATED
2013-08-09 20:53:22,610 INFO org.apache.hadoop.yarn.server.resourcemanager.RMAuditLogger: USER=ubuntu	OPERATION=AM Allocated Container	TARGET=SchedulerApp	RESULT=SUCCESS	APPID=application_1376080735992_0008	CONTAINERID=container_1376080735992_0008_01_000001
2013-08-09 20:53:22,610 INFO org.apache.hadoop.yarn.server.resourcemanager.scheduler.common.fica.FiCaSchedulerNode: Assigned container container_1376080735992_0008_01_000001 of capacity <memory:2048, vCores:1> on host hadoop-210-3:58589, which currently has 1 containers, <memory:2048, vCores:1> used and <memory:6144, vCores:15> available
2013-08-09 20:53:22,611 INFO org.apache.hadoop.yarn.server.resourcemanager.scheduler.capacity.LeafQueue: assignedContainer application=application_1376080735992_0008 container=Container: [ContainerId: container_1376080735992_0008_01_000001, NodeId: hadoop-210-3:58589, NodeHttpAddress: hadoop-210-3:8042, Resource: <memory:2048, vCores:1>, Priority: 0, State: NEW, Token: null, Status: container_id {, app_attempt_id {, application_id {, id: 8, cluster_timestamp: 1376080735992, }, attemptId: 1, }, id: 1, }, state: C_NEW, ] containerId=container_1376080735992_0008_01_000001 queue=default: capacity=1.0, absoluteCapacity=1.0, usedResources=<memory:4096, vCores:2>usedCapacity=0.083333336, absoluteUsedCapacity=0.083333336, numApps=5, numContainers=2 usedCapacity=0.083333336 absoluteUsedCapacity=0.083333336 used=<memory:4096, vCores:2> cluster=<memory:49152, vCores:96>
2013-08-09 20:53:22,612 INFO org.apache.hadoop.yarn.server.resourcemanager.scheduler.capacity.ParentQueue: Re-sorting queues since queue: root.default stats: default: capacity=1.0, absoluteCapacity=1.0, usedResources=<memory:6144, vCores:3>usedCapacity=0.125, absoluteUsedCapacity=0.125, numApps=5, numContainers=3
2013-08-09 20:53:22,612 INFO org.apache.hadoop.yarn.server.resourcemanager.scheduler.capacity.ParentQueue: assignedContainer queue=root usedCapacity=0.125 absoluteUsedCapacity=0.125 used=<memory:6144, vCores:3> cluster=<memory:49152, vCores:96>
2013-08-09 20:53:22,613 INFO org.apache.hadoop.yarn.server.resourcemanager.rmcontainer.RMContainerImpl: container_1376080735992_0008_01_000001 Container Transitioned from ALLOCATED to ACQUIRED
2013-08-09 20:53:22,614 INFO org.apache.hadoop.yarn.server.resourcemanager.rmapp.attempt.RMAppAttemptImpl: Storing attempt: AppId: application_1376080735992_0008 AttemptId: appattempt_1376080735992_0008_000001 MasterContainer: Container: [ContainerId: container_1376080735992_0008_01_000001, NodeId: hadoop-210-3:58589, NodeHttpAddress: hadoop-210-3:8042, Resource: <memory:2048, vCores:1>, Priority: 0, State: NEW, Token: null, Status: container_id {, app_attempt_id {, application_id {, id: 8, cluster_timestamp: 1376080735992, }, attemptId: 1, }, id: 1, }, state: C_NEW, ]
2013-08-09 20:53:22,615 INFO org.apache.hadoop.yarn.server.resourcemanager.rmapp.attempt.RMAppAttemptImpl: appattempt_1376080735992_0008_000001 State change from SCHEDULED to ALLOCATED_SAVING
2013-08-09 20:53:22,615 INFO org.apache.hadoop.yarn.server.resourcemanager.recovery.RMStateStore: Storing info for attempt: appattempt_1376080735992_0008_000001
2013-08-09 20:53:22,617 INFO org.apache.hadoop.yarn.server.resourcemanager.rmapp.attempt.RMAppAttemptImpl: appattempt_1376080735992_0008_000001 State change from ALLOCATED_SAVING to ALLOCATED
2013-08-09 20:53:22,617 INFO org.apache.hadoop.yarn.server.resourcemanager.rmcontainer.RMContainerImpl: container_1376080735992_0009_01_000001 Container Transitioned from NEW to ALLOCATED
2013-08-09 20:53:22,617 INFO org.apache.hadoop.yarn.server.resourcemanager.amlauncher.AMLauncher: Launching masterappattempt_1376080735992_0008_000001
2013-08-09 20:53:22,617 INFO org.apache.hadoop.yarn.server.resourcemanager.RMAuditLogger: USER=ubuntu	OPERATION=AM Allocated Container	TARGET=SchedulerApp	RESULT=SUCCESS	APPID=application_1376080735992_0009	CONTAINERID=container_1376080735992_0009_01_000001
2013-08-09 20:53:22,618 INFO org.apache.hadoop.yarn.server.resourcemanager.scheduler.common.fica.FiCaSchedulerNode: Assigned container container_1376080735992_0009_01_000001 of capacity <memory:2048, vCores:1> on host hadoop-210-4:47596, which currently has 1 containers, <memory:2048, vCores:1> used and <memory:6144, vCores:15> available
2013-08-09 20:53:22,619 INFO org.apache.hadoop.yarn.server.resourcemanager.scheduler.capacity.LeafQueue: assignedContainer application=application_1376080735992_0009 container=Container: [ContainerId: container_1376080735992_0009_01_000001, NodeId: hadoop-210-4:47596, NodeHttpAddress: hadoop-210-4:8042, Resource: <memory:2048, vCores:1>, Priority: 0, State: NEW, Token: null, Status: container_id {, app_attempt_id {, application_id {, id: 9, cluster_timestamp: 1376080735992, }, attemptId: 1, }, id: 1, }, state: C_NEW, ] containerId=container_1376080735992_0009_01_000001 queue=default: capacity=1.0, absoluteCapacity=1.0, usedResources=<memory:6144, vCores:3>usedCapacity=0.125, absoluteUsedCapacity=0.125, numApps=5, numContainers=3 usedCapacity=0.125 absoluteUsedCapacity=0.125 used=<memory:6144, vCores:3> cluster=<memory:49152, vCores:96>
2013-08-09 20:53:22,619 INFO org.apache.hadoop.yarn.server.resourcemanager.scheduler.capacity.ParentQueue: Re-sorting queues since queue: root.default stats: default: capacity=1.0, absoluteCapacity=1.0, usedResources=<memory:8192, vCores:4>usedCapacity=0.16666667, absoluteUsedCapacity=0.16666667, numApps=5, numContainers=4
2013-08-09 20:53:22,620 INFO org.apache.hadoop.yarn.server.resourcemanager.scheduler.capacity.ParentQueue: assignedContainer queue=root usedCapacity=0.16666667 absoluteUsedCapacity=0.16666667 used=<memory:8192, vCores:4> cluster=<memory:49152, vCores:96>
2013-08-09 20:53:22,621 INFO org.apache.hadoop.yarn.server.resourcemanager.rmcontainer.RMContainerImpl: container_1376080735992_0009_01_000001 Container Transitioned from ALLOCATED to ACQUIRED
2013-08-09 20:53:22,622 INFO org.apache.hadoop.yarn.server.resourcemanager.amlauncher.AMLauncher: Setting up container Container: [ContainerId: container_1376080735992_0008_01_000001, NodeId: hadoop-210-3:58589, NodeHttpAddress: hadoop-210-3:8042, Resource: <memory:2048, vCores:1>, Priority: 0, State: NEW, Token: null, Status: container_id {, app_attempt_id {, application_id {, id: 8, cluster_timestamp: 1376080735992, }, attemptId: 1, }, id: 1, }, state: C_NEW, ] for AM appattempt_1376080735992_0008_000001
2013-08-09 20:53:22,622 INFO org.apache.hadoop.yarn.server.resourcemanager.amlauncher.AMLauncher: Command to launch container container_1376080735992_0008_01_000001 : $JAVA_HOME/bin/java -Dlog4j.configuration=container-log4j.properties -Dyarn.app.mapreduce.container.log.dir=<LOG_DIR> -Dyarn.app.mapreduce.container.log.filesize=0 -Dhadoop.root.logger=INFO,CLA  -Xmx1024m org.apache.hadoop.mapreduce.v2.app.MRAppMaster 1><LOG_DIR>/stdout 2><LOG_DIR>/stderr 
2013-08-09 20:53:22,623 INFO org.apache.hadoop.yarn.server.resourcemanager.rmapp.attempt.RMAppAttemptImpl: Storing attempt: AppId: application_1376080735992_0009 AttemptId: appattempt_1376080735992_0009_000001 MasterContainer: Container: [ContainerId: container_1376080735992_0009_01_000001, NodeId: hadoop-210-4:47596, NodeHttpAddress: hadoop-210-4:8042, Resource: <memory:2048, vCores:1>, Priority: 0, State: NEW, Token: null, Status: container_id {, app_attempt_id {, application_id {, id: 9, cluster_timestamp: 1376080735992, }, attemptId: 1, }, id: 1, }, state: C_NEW, ]
2013-08-09 20:53:22,623 INFO org.apache.hadoop.yarn.server.resourcemanager.rmapp.attempt.RMAppAttemptImpl: appattempt_1376080735992_0009_000001 State change from SCHEDULED to ALLOCATED_SAVING
2013-08-09 20:53:22,623 INFO org.apache.hadoop.yarn.server.resourcemanager.recovery.RMStateStore: Storing info for attempt: appattempt_1376080735992_0009_000001
2013-08-09 20:53:22,628 INFO org.apache.hadoop.yarn.server.resourcemanager.rmapp.attempt.RMAppAttemptImpl: appattempt_1376080735992_0009_000001 State change from ALLOCATED_SAVING to ALLOCATED
2013-08-09 20:53:22,628 INFO org.apache.hadoop.yarn.server.resourcemanager.amlauncher.AMLauncher: Launching masterappattempt_1376080735992_0009_000001
2013-08-09 20:53:22,643 INFO org.apache.hadoop.yarn.server.resourcemanager.amlauncher.AMLauncher: Setting up container Container: [ContainerId: container_1376080735992_0009_01_000001, NodeId: hadoop-210-4:47596, NodeHttpAddress: hadoop-210-4:8042, Resource: <memory:2048, vCores:1>, Priority: 0, State: NEW, Token: null, Status: container_id {, app_attempt_id {, application_id {, id: 9, cluster_timestamp: 1376080735992, }, attemptId: 1, }, id: 1, }, state: C_NEW, ] for AM appattempt_1376080735992_0009_000001
2013-08-09 20:53:22,643 INFO org.apache.hadoop.yarn.server.resourcemanager.amlauncher.AMLauncher: Command to launch container container_1376080735992_0009_01_000001 : $JAVA_HOME/bin/java -Dlog4j.configuration=container-log4j.properties -Dyarn.app.mapreduce.container.log.dir=<LOG_DIR> -Dyarn.app.mapreduce.container.log.filesize=0 -Dhadoop.root.logger=INFO,CLA  -Xmx1024m org.apache.hadoop.mapreduce.v2.app.MRAppMaster 1><LOG_DIR>/stdout 2><LOG_DIR>/stderr 
2013-08-09 20:53:22,652 INFO org.apache.hadoop.yarn.server.resourcemanager.amlauncher.AMLauncher: Done launching container Container: [ContainerId: container_1376080735992_0008_01_000001, NodeId: hadoop-210-3:58589, NodeHttpAddress: hadoop-210-3:8042, Resource: <memory:2048, vCores:1>, Priority: 0, State: NEW, Token: null, Status: container_id {, app_attempt_id {, application_id {, id: 8, cluster_timestamp: 1376080735992, }, attemptId: 1, }, id: 1, }, state: C_NEW, ] for AM appattempt_1376080735992_0008_000001
2013-08-09 20:53:22,652 INFO org.apache.hadoop.yarn.server.resourcemanager.rmapp.attempt.RMAppAttemptImpl: appattempt_1376080735992_0008_000001 State change from ALLOCATED to LAUNCHED
2013-08-09 20:53:22,661 INFO org.apache.hadoop.yarn.server.resourcemanager.amlauncher.AMLauncher: Done launching container Container: [ContainerId: container_1376080735992_0009_01_000001, NodeId: hadoop-210-4:47596, NodeHttpAddress: hadoop-210-4:8042, Resource: <memory:2048, vCores:1>, Priority: 0, State: NEW, Token: null, Status: container_id {, app_attempt_id {, application_id {, id: 9, cluster_timestamp: 1376080735992, }, attemptId: 1, }, id: 1, }, state: C_NEW, ] for AM appattempt_1376080735992_0009_000001
2013-08-09 20:53:22,661 INFO org.apache.hadoop.yarn.server.resourcemanager.rmapp.attempt.RMAppAttemptImpl: appattempt_1376080735992_0009_000001 State change from ALLOCATED to LAUNCHED
2013-08-09 20:53:22,679 INFO org.apache.hadoop.yarn.server.resourcemanager.rmcontainer.RMContainerImpl: container_1376080735992_0010_01_000001 Container Transitioned from NEW to ALLOCATED
2013-08-09 20:53:22,681 INFO org.apache.hadoop.yarn.server.resourcemanager.RMAuditLogger: USER=ubuntu	OPERATION=AM Allocated Container	TARGET=SchedulerApp	RESULT=SUCCESS	APPID=application_1376080735992_0010	CONTAINERID=container_1376080735992_0010_01_000001
2013-08-09 20:53:22,681 INFO org.apache.hadoop.yarn.server.resourcemanager.scheduler.common.fica.FiCaSchedulerNode: Assigned container container_1376080735992_0010_01_000001 of capacity <memory:2048, vCores:1> on host hadoop-210-2:51035, which currently has 1 containers, <memory:2048, vCores:1> used and <memory:6144, vCores:15> available
2013-08-09 20:53:22,683 INFO org.apache.hadoop.yarn.server.resourcemanager.scheduler.capacity.LeafQueue: assignedContainer application=application_1376080735992_0010 container=Container: [ContainerId: container_1376080735992_0010_01_000001, NodeId: hadoop-210-2:51035, NodeHttpAddress: hadoop-210-2:8042, Resource: <memory:2048, vCores:1>, Priority: 0, State: NEW, Token: null, Status: container_id {, app_attempt_id {, application_id {, id: 10, cluster_timestamp: 1376080735992, }, attemptId: 1, }, id: 1, }, state: C_NEW, ] containerId=container_1376080735992_0010_01_000001 queue=default: capacity=1.0, absoluteCapacity=1.0, usedResources=<memory:8192, vCores:4>usedCapacity=0.16666667, absoluteUsedCapacity=0.16666667, numApps=5, numContainers=4 usedCapacity=0.16666667 absoluteUsedCapacity=0.16666667 used=<memory:8192, vCores:4> cluster=<memory:49152, vCores:96>
2013-08-09 20:53:22,683 INFO org.apache.hadoop.yarn.server.resourcemanager.scheduler.capacity.ParentQueue: Re-sorting queues since queue: root.default stats: default: capacity=1.0, absoluteCapacity=1.0, usedResources=<memory:10240, vCores:5>usedCapacity=0.20833333, absoluteUsedCapacity=0.20833333, numApps=5, numContainers=5
2013-08-09 20:53:22,684 INFO org.apache.hadoop.yarn.server.resourcemanager.rmcontainer.RMContainerImpl: container_1376080735992_0010_01_000001 Container Transitioned from ALLOCATED to ACQUIRED
2013-08-09 20:53:22,684 INFO org.apache.hadoop.yarn.server.resourcemanager.scheduler.capacity.ParentQueue: assignedContainer queue=root usedCapacity=0.20833333 absoluteUsedCapacity=0.20833333 used=<memory:10240, vCores:5> cluster=<memory:49152, vCores:96>
2013-08-09 20:53:22,686 INFO org.apache.hadoop.yarn.server.resourcemanager.rmapp.attempt.RMAppAttemptImpl: Storing attempt: AppId: application_1376080735992_0010 AttemptId: appattempt_1376080735992_0010_000001 MasterContainer: Container: [ContainerId: container_1376080735992_0010_01_000001, NodeId: hadoop-210-2:51035, NodeHttpAddress: hadoop-210-2:8042, Resource: <memory:2048, vCores:1>, Priority: 0, State: NEW, Token: null, Status: container_id {, app_attempt_id {, application_id {, id: 10, cluster_timestamp: 1376080735992, }, attemptId: 1, }, id: 1, }, state: C_NEW, ]
2013-08-09 20:53:22,686 INFO org.apache.hadoop.yarn.server.resourcemanager.rmapp.attempt.RMAppAttemptImpl: appattempt_1376080735992_0010_000001 State change from SCHEDULED to ALLOCATED_SAVING
2013-08-09 20:53:22,686 INFO org.apache.hadoop.yarn.server.resourcemanager.recovery.RMStateStore: Storing info for attempt: appattempt_1376080735992_0010_000001
2013-08-09 20:53:22,687 INFO org.apache.hadoop.yarn.server.resourcemanager.rmapp.attempt.RMAppAttemptImpl: appattempt_1376080735992_0010_000001 State change from ALLOCATED_SAVING to ALLOCATED
2013-08-09 20:53:22,687 INFO org.apache.hadoop.yarn.server.resourcemanager.amlauncher.AMLauncher: Launching masterappattempt_1376080735992_0010_000001
2013-08-09 20:53:22,690 INFO org.apache.hadoop.yarn.server.resourcemanager.amlauncher.AMLauncher: Setting up container Container: [ContainerId: container_1376080735992_0010_01_000001, NodeId: hadoop-210-2:51035, NodeHttpAddress: hadoop-210-2:8042, Resource: <memory:2048, vCores:1>, Priority: 0, State: NEW, Token: null, Status: container_id {, app_attempt_id {, application_id {, id: 10, cluster_timestamp: 1376080735992, }, attemptId: 1, }, id: 1, }, state: C_NEW, ] for AM appattempt_1376080735992_0010_000001
2013-08-09 20:53:22,690 INFO org.apache.hadoop.yarn.server.resourcemanager.amlauncher.AMLauncher: Command to launch container container_1376080735992_0010_01_000001 : $JAVA_HOME/bin/java -Dlog4j.configuration=container-log4j.properties -Dyarn.app.mapreduce.container.log.dir=<LOG_DIR> -Dyarn.app.mapreduce.container.log.filesize=0 -Dhadoop.root.logger=INFO,CLA  -Xmx1024m org.apache.hadoop.mapreduce.v2.app.MRAppMaster 1><LOG_DIR>/stdout 2><LOG_DIR>/stderr 
2013-08-09 20:53:22,703 INFO org.apache.hadoop.yarn.server.resourcemanager.amlauncher.AMLauncher: Done launching container Container: [ContainerId: container_1376080735992_0010_01_000001, NodeId: hadoop-210-2:51035, NodeHttpAddress: hadoop-210-2:8042, Resource: <memory:2048, vCores:1>, Priority: 0, State: NEW, Token: null, Status: container_id {, app_attempt_id {, application_id {, id: 10, cluster_timestamp: 1376080735992, }, attemptId: 1, }, id: 1, }, state: C_NEW, ] for AM appattempt_1376080735992_0010_000001
2013-08-09 20:53:22,703 INFO org.apache.hadoop.yarn.server.resourcemanager.rmapp.attempt.RMAppAttemptImpl: appattempt_1376080735992_0010_000001 State change from ALLOCATED to LAUNCHED
2013-08-09 20:53:23,037 INFO org.apache.hadoop.yarn.server.resourcemanager.rmcontainer.RMContainerImpl: container_1376080735992_0006_01_000001 Container Transitioned from ACQUIRED to RUNNING
2013-08-09 20:53:23,384 INFO org.apache.hadoop.yarn.server.resourcemanager.rmcontainer.RMContainerImpl: container_1376080735992_0007_01_000001 Container Transitioned from ACQUIRED to RUNNING
2013-08-09 20:53:23,613 INFO org.apache.hadoop.yarn.server.resourcemanager.rmcontainer.RMContainerImpl: container_1376080735992_0008_01_000001 Container Transitioned from ACQUIRED to RUNNING
2013-08-09 20:53:23,614 INFO org.apache.hadoop.yarn.server.resourcemanager.rmcontainer.RMContainerImpl: container_1376080735992_0009_01_000001 Container Transitioned from ACQUIRED to RUNNING
2013-08-09 20:53:23,683 INFO org.apache.hadoop.yarn.server.resourcemanager.rmcontainer.RMContainerImpl: container_1376080735992_0010_01_000001 Container Transitioned from ACQUIRED to RUNNING
2013-08-09 20:53:29,440 INFO org.apache.hadoop.yarn.server.resourcemanager.ApplicationMasterService: AM registration appattempt_1376080735992_0009_000001
2013-08-09 20:53:29,440 INFO org.apache.hadoop.yarn.server.resourcemanager.RMAuditLogger: USER=ubuntu	IP=192.168.100.11	OPERATION=Register App Master	TARGET=ApplicationMasterService	RESULT=SUCCESS	APPID=application_1376080735992_0009	APPATTEMPTID=appattempt_1376080735992_0009_000001
2013-08-09 20:53:29,441 INFO org.apache.hadoop.yarn.server.resourcemanager.rmapp.attempt.RMAppAttemptImpl: appattempt_1376080735992_0009_000001 State change from LAUNCHED to RUNNING
2013-08-09 20:53:29,441 INFO org.apache.hadoop.yarn.server.resourcemanager.rmapp.RMAppImpl: application_1376080735992_0009 State change from ACCEPTED to RUNNING
2013-08-09 20:53:29,467 INFO org.apache.hadoop.yarn.server.resourcemanager.ApplicationMasterService: AM registration appattempt_1376080735992_0008_000001
2013-08-09 20:53:29,467 INFO org.apache.hadoop.yarn.server.resourcemanager.RMAuditLogger: USER=ubuntu	IP=192.168.100.10	OPERATION=Register App Master	TARGET=ApplicationMasterService	RESULT=SUCCESS	APPID=application_1376080735992_0008	APPATTEMPTID=appattempt_1376080735992_0008_000001
2013-08-09 20:53:29,468 INFO org.apache.hadoop.yarn.server.resourcemanager.rmapp.attempt.RMAppAttemptImpl: appattempt_1376080735992_0008_000001 State change from LAUNCHED to RUNNING
2013-08-09 20:53:29,468 INFO org.apache.hadoop.yarn.server.resourcemanager.rmapp.RMAppImpl: application_1376080735992_0008 State change from ACCEPTED to RUNNING
2013-08-09 20:53:29,527 INFO org.apache.hadoop.yarn.server.resourcemanager.ApplicationMasterService: AM registration appattempt_1376080735992_0006_000001
2013-08-09 20:53:29,527 INFO org.apache.hadoop.yarn.server.resourcemanager.RMAuditLogger: USER=ubuntu	IP=192.168.100.14	OPERATION=Register App Master	TARGET=ApplicationMasterService	RESULT=SUCCESS	APPID=application_1376080735992_0006	APPATTEMPTID=appattempt_1376080735992_0006_000001
2013-08-09 20:53:29,528 INFO org.apache.hadoop.yarn.server.resourcemanager.rmapp.attempt.RMAppAttemptImpl: appattempt_1376080735992_0006_000001 State change from LAUNCHED to RUNNING
2013-08-09 20:53:29,528 INFO org.apache.hadoop.yarn.server.resourcemanager.rmapp.RMAppImpl: application_1376080735992_0006 State change from ACCEPTED to RUNNING
2013-08-09 20:53:30,164 INFO org.apache.hadoop.yarn.server.resourcemanager.ApplicationMasterService: AM registration appattempt_1376080735992_0007_000001
2013-08-09 20:53:30,164 INFO org.apache.hadoop.yarn.server.resourcemanager.RMAuditLogger: USER=ubuntu	IP=192.168.100.15	OPERATION=Register App Master	TARGET=ApplicationMasterService	RESULT=SUCCESS	APPID=application_1376080735992_0007	APPATTEMPTID=appattempt_1376080735992_0007_000001
2013-08-09 20:53:30,165 INFO org.apache.hadoop.yarn.server.resourcemanager.rmapp.attempt.RMAppAttemptImpl: appattempt_1376080735992_0007_000001 State change from LAUNCHED to RUNNING
2013-08-09 20:53:30,165 INFO org.apache.hadoop.yarn.server.resourcemanager.rmapp.RMAppImpl: application_1376080735992_0007 State change from ACCEPTED to RUNNING
2013-08-09 20:53:30,340 INFO org.apache.hadoop.yarn.server.resourcemanager.ApplicationMasterService: AM registration appattempt_1376080735992_0010_000001
2013-08-09 20:53:30,341 INFO org.apache.hadoop.yarn.server.resourcemanager.RMAuditLogger: USER=ubuntu	IP=192.168.100.9	OPERATION=Register App Master	TARGET=ApplicationMasterService	RESULT=SUCCESS	APPID=application_1376080735992_0010	APPATTEMPTID=appattempt_1376080735992_0010_000001
2013-08-09 20:53:30,341 INFO org.apache.hadoop.yarn.server.resourcemanager.rmapp.attempt.RMAppAttemptImpl: appattempt_1376080735992_0010_000001 State change from LAUNCHED to RUNNING
2013-08-09 20:53:30,342 INFO org.apache.hadoop.yarn.server.resourcemanager.rmapp.RMAppImpl: application_1376080735992_0010 State change from ACCEPTED to RUNNING
2013-08-09 20:53:30,646 INFO org.apache.hadoop.yarn.server.resourcemanager.rmcontainer.RMContainerImpl: container_1376080735992_0006_01_000002 Container Transitioned from NEW to ALLOCATED
2013-08-09 20:53:30,647 INFO org.apache.hadoop.yarn.server.resourcemanager.RMAuditLogger: USER=ubuntu	OPERATION=AM Allocated Container	TARGET=SchedulerApp	RESULT=SUCCESS	APPID=application_1376080735992_0006	CONTAINERID=container_1376080735992_0006_01_000002
2013-08-09 20:53:30,647 INFO org.apache.hadoop.yarn.server.resourcemanager.scheduler.common.fica.FiCaSchedulerNode: Assigned container container_1376080735992_0006_01_000002 of capacity <memory:1024, vCores:1> on host hadoop-210-4:47596, which currently has 2 containers, <memory:3072, vCores:2> used and <memory:5120, vCores:14> available
2013-08-09 20:53:30,648 INFO org.apache.hadoop.yarn.server.resourcemanager.scheduler.capacity.LeafQueue: assignedContainer application=application_1376080735992_0006 container=Container: [ContainerId: container_1376080735992_0006_01_000002, NodeId: hadoop-210-4:47596, NodeHttpAddress: hadoop-210-4:8042, Resource: <memory:1024, vCores:1>, Priority: 20, State: NEW, Token: null, Status: container_id {, app_attempt_id {, application_id {, id: 6, cluster_timestamp: 1376080735992, }, attemptId: 1, }, id: 2, }, state: C_NEW, ] containerId=container_1376080735992_0006_01_000002 queue=default: capacity=1.0, absoluteCapacity=1.0, usedResources=<memory:10240, vCores:5>usedCapacity=0.20833333, absoluteUsedCapacity=0.20833333, numApps=5, numContainers=5 usedCapacity=0.20833333 absoluteUsedCapacity=0.20833333 used=<memory:10240, vCores:5> cluster=<memory:49152, vCores:96>
2013-08-09 20:53:30,648 INFO org.apache.hadoop.yarn.server.resourcemanager.scheduler.capacity.ParentQueue: Re-sorting queues since queue: root.default stats: default: capacity=1.0, absoluteCapacity=1.0, usedResources=<memory:11264, vCores:6>usedCapacity=0.22916667, absoluteUsedCapacity=0.22916667, numApps=5, numContainers=6
2013-08-09 20:53:30,649 INFO org.apache.hadoop.yarn.server.resourcemanager.scheduler.capacity.ParentQueue: assignedContainer queue=root usedCapacity=0.22916667 absoluteUsedCapacity=0.22916667 used=<memory:11264, vCores:6> cluster=<memory:49152, vCores:96>
2013-08-09 20:53:30,649 INFO org.apache.hadoop.yarn.server.resourcemanager.rmcontainer.RMContainerImpl: container_1376080735992_0006_01_000003 Container Transitioned from NEW to ALLOCATED
2013-08-09 20:53:30,649 INFO org.apache.hadoop.yarn.server.resourcemanager.RMAuditLogger: USER=ubuntu	OPERATION=AM Allocated Container	TARGET=SchedulerApp	RESULT=SUCCESS	APPID=application_1376080735992_0006	CONTAINERID=container_1376080735992_0006_01_000003
2013-08-09 20:53:30,649 INFO org.apache.hadoop.yarn.server.resourcemanager.scheduler.common.fica.FiCaSchedulerNode: Assigned container container_1376080735992_0006_01_000003 of capacity <memory:1024, vCores:1> on host hadoop-210-4:47596, which currently has 3 containers, <memory:4096, vCores:3> used and <memory:4096, vCores:13> available
2013-08-09 20:53:30,651 INFO org.apache.hadoop.yarn.server.resourcemanager.scheduler.capacity.LeafQueue: assignedContainer application=application_1376080735992_0006 container=Container: [ContainerId: container_1376080735992_0006_01_000003, NodeId: hadoop-210-4:47596, NodeHttpAddress: hadoop-210-4:8042, Resource: <memory:1024, vCores:1>, Priority: 20, State: NEW, Token: null, Status: container_id {, app_attempt_id {, application_id {, id: 6, cluster_timestamp: 1376080735992, }, attemptId: 1, }, id: 3, }, state: C_NEW, ] containerId=container_1376080735992_0006_01_000003 queue=default: capacity=1.0, absoluteCapacity=1.0, usedResources=<memory:11264, vCores:6>usedCapacity=0.22916667, absoluteUsedCapacity=0.22916667, numApps=5, numContainers=6 usedCapacity=0.22916667 absoluteUsedCapacity=0.22916667 used=<memory:11264, vCores:6> cluster=<memory:49152, vCores:96>
2013-08-09 20:53:30,651 INFO org.apache.hadoop.yarn.server.resourcemanager.scheduler.capacity.ParentQueue: Re-sorting queues since queue: root.default stats: default: capacity=1.0, absoluteCapacity=1.0, usedResources=<memory:12288, vCores:7>usedCapacity=0.25, absoluteUsedCapacity=0.25, numApps=5, numContainers=7
2013-08-09 20:53:30,651 INFO org.apache.hadoop.yarn.server.resourcemanager.scheduler.capacity.ParentQueue: assignedContainer queue=root usedCapacity=0.25 absoluteUsedCapacity=0.25 used=<memory:12288, vCores:7> cluster=<memory:49152, vCores:96>
2013-08-09 20:53:30,651 INFO org.apache.hadoop.yarn.server.resourcemanager.rmcontainer.RMContainerImpl: container_1376080735992_0006_01_000004 Container Transitioned from NEW to ALLOCATED
2013-08-09 20:53:30,652 INFO org.apache.hadoop.yarn.server.resourcemanager.RMAuditLogger: USER=ubuntu	OPERATION=AM Allocated Container	TARGET=SchedulerApp	RESULT=SUCCESS	APPID=application_1376080735992_0006	CONTAINERID=container_1376080735992_0006_01_000004
2013-08-09 20:53:30,652 INFO org.apache.hadoop.yarn.server.resourcemanager.scheduler.common.fica.FiCaSchedulerNode: Assigned container container_1376080735992_0006_01_000004 of capacity <memory:1024, vCores:1> on host hadoop-210-4:47596, which currently has 4 containers, <memory:5120, vCores:4> used and <memory:3072, vCores:12> available
2013-08-09 20:53:30,657 INFO org.apache.hadoop.yarn.server.resourcemanager.scheduler.capacity.LeafQueue: assignedContainer application=application_1376080735992_0006 container=Container: [ContainerId: container_1376080735992_0006_01_000004, NodeId: hadoop-210-4:47596, NodeHttpAddress: hadoop-210-4:8042, Resource: <memory:1024, vCores:1>, Priority: 20, State: NEW, Token: null, Status: container_id {, app_attempt_id {, application_id {, id: 6, cluster_timestamp: 1376080735992, }, attemptId: 1, }, id: 4, }, state: C_NEW, ] containerId=container_1376080735992_0006_01_000004 queue=default: capacity=1.0, absoluteCapacity=1.0, usedResources=<memory:12288, vCores:7>usedCapacity=0.25, absoluteUsedCapacity=0.25, numApps=5, numContainers=7 usedCapacity=0.25 absoluteUsedCapacity=0.25 used=<memory:12288, vCores:7> cluster=<memory:49152, vCores:96>
2013-08-09 20:53:30,657 INFO org.apache.hadoop.yarn.server.resourcemanager.scheduler.capacity.ParentQueue: Re-sorting queues since queue: root.default stats: default: capacity=1.0, absoluteCapacity=1.0, usedResources=<memory:13312, vCores:8>usedCapacity=0.27083334, absoluteUsedCapacity=0.27083334, numApps=5, numContainers=8
2013-08-09 20:53:30,657 INFO org.apache.hadoop.yarn.server.resourcemanager.scheduler.capacity.ParentQueue: assignedContainer queue=root usedCapacity=0.27083334 absoluteUsedCapacity=0.27083334 used=<memory:13312, vCores:8> cluster=<memory:49152, vCores:96>
2013-08-09 20:53:30,658 INFO org.apache.hadoop.yarn.server.resourcemanager.rmcontainer.RMContainerImpl: container_1376080735992_0006_01_000005 Container Transitioned from NEW to ALLOCATED
2013-08-09 20:53:30,658 INFO org.apache.hadoop.yarn.server.resourcemanager.RMAuditLogger: USER=ubuntu	OPERATION=AM Allocated Container	TARGET=SchedulerApp	RESULT=SUCCESS	APPID=application_1376080735992_0006	CONTAINERID=container_1376080735992_0006_01_000005
2013-08-09 20:53:30,658 INFO org.apache.hadoop.yarn.server.resourcemanager.scheduler.common.fica.FiCaSchedulerNode: Assigned container container_1376080735992_0006_01_000005 of capacity <memory:1024, vCores:1> on host hadoop-210-4:47596, which currently has 5 containers, <memory:6144, vCores:5> used and <memory:2048, vCores:11> available
2013-08-09 20:53:30,659 INFO org.apache.hadoop.yarn.server.resourcemanager.scheduler.capacity.LeafQueue: assignedContainer application=application_1376080735992_0006 container=Container: [ContainerId: container_1376080735992_0006_01_000005, NodeId: hadoop-210-4:47596, NodeHttpAddress: hadoop-210-4:8042, Resource: <memory:1024, vCores:1>, Priority: 20, State: NEW, Token: null, Status: container_id {, app_attempt_id {, application_id {, id: 6, cluster_timestamp: 1376080735992, }, attemptId: 1, }, id: 5, }, state: C_NEW, ] containerId=container_1376080735992_0006_01_000005 queue=default: capacity=1.0, absoluteCapacity=1.0, usedResources=<memory:13312, vCores:8>usedCapacity=0.27083334, absoluteUsedCapacity=0.27083334, numApps=5, numContainers=8 usedCapacity=0.27083334 absoluteUsedCapacity=0.27083334 used=<memory:13312, vCores:8> cluster=<memory:49152, vCores:96>
2013-08-09 20:53:30,659 INFO org.apache.hadoop.yarn.server.resourcemanager.scheduler.capacity.ParentQueue: Re-sorting queues since queue: root.default stats: default: capacity=1.0, absoluteCapacity=1.0, usedResources=<memory:14336, vCores:9>usedCapacity=0.29166666, absoluteUsedCapacity=0.29166666, numApps=5, numContainers=9
2013-08-09 20:53:30,659 INFO org.apache.hadoop.yarn.server.resourcemanager.scheduler.capacity.ParentQueue: assignedContainer queue=root usedCapacity=0.29166666 absoluteUsedCapacity=0.29166666 used=<memory:14336, vCores:9> cluster=<memory:49152, vCores:96>
2013-08-09 20:53:30,660 INFO org.apache.hadoop.yarn.server.resourcemanager.rmcontainer.RMContainerImpl: container_1376080735992_0006_01_000006 Container Transitioned from NEW to ALLOCATED
2013-08-09 20:53:30,660 INFO org.apache.hadoop.yarn.server.resourcemanager.RMAuditLogger: USER=ubuntu	OPERATION=AM Allocated Container	TARGET=SchedulerApp	RESULT=SUCCESS	APPID=application_1376080735992_0006	CONTAINERID=container_1376080735992_0006_01_000006
2013-08-09 20:53:30,660 INFO org.apache.hadoop.yarn.server.resourcemanager.scheduler.common.fica.FiCaSchedulerNode: Assigned container container_1376080735992_0006_01_000006 of capacity <memory:1024, vCores:1> on host hadoop-210-4:47596, which currently has 6 containers, <memory:7168, vCores:6> used and <memory:1024, vCores:10> available
2013-08-09 20:53:30,662 INFO org.apache.hadoop.yarn.server.resourcemanager.scheduler.capacity.LeafQueue: assignedContainer application=application_1376080735992_0006 container=Container: [ContainerId: container_1376080735992_0006_01_000006, NodeId: hadoop-210-4:47596, NodeHttpAddress: hadoop-210-4:8042, Resource: <memory:1024, vCores:1>, Priority: 20, State: NEW, Token: null, Status: container_id {, app_attempt_id {, application_id {, id: 6, cluster_timestamp: 1376080735992, }, attemptId: 1, }, id: 6, }, state: C_NEW, ] containerId=container_1376080735992_0006_01_000006 queue=default: capacity=1.0, absoluteCapacity=1.0, usedResources=<memory:14336, vCores:9>usedCapacity=0.29166666, absoluteUsedCapacity=0.29166666, numApps=5, numContainers=9 usedCapacity=0.29166666 absoluteUsedCapacity=0.29166666 used=<memory:14336, vCores:9> cluster=<memory:49152, vCores:96>
2013-08-09 20:53:30,662 INFO org.apache.hadoop.yarn.server.resourcemanager.scheduler.capacity.ParentQueue: Re-sorting queues since queue: root.default stats: default: capacity=1.0, absoluteCapacity=1.0, usedResources=<memory:15360, vCores:10>usedCapacity=0.3125, absoluteUsedCapacity=0.3125, numApps=5, numContainers=10
2013-08-09 20:53:30,662 INFO org.apache.hadoop.yarn.server.resourcemanager.scheduler.capacity.ParentQueue: assignedContainer queue=root usedCapacity=0.3125 absoluteUsedCapacity=0.3125 used=<memory:15360, vCores:10> cluster=<memory:49152, vCores:96>
2013-08-09 20:53:30,663 INFO org.apache.hadoop.yarn.server.resourcemanager.rmcontainer.RMContainerImpl: container_1376080735992_0006_01_000007 Container Transitioned from NEW to ALLOCATED
2013-08-09 20:53:30,663 INFO org.apache.hadoop.yarn.server.resourcemanager.RMAuditLogger: USER=ubuntu	OPERATION=AM Allocated Container	TARGET=SchedulerApp	RESULT=SUCCESS	APPID=application_1376080735992_0006	CONTAINERID=container_1376080735992_0006_01_000007
2013-08-09 20:53:30,663 INFO org.apache.hadoop.yarn.server.resourcemanager.scheduler.common.fica.FiCaSchedulerNode: Assigned container container_1376080735992_0006_01_000007 of capacity <memory:1024, vCores:1> on host hadoop-210-4:47596, which currently has 7 containers, <memory:8192, vCores:7> used and <memory:0, vCores:9> available
2013-08-09 20:53:30,664 INFO org.apache.hadoop.yarn.server.resourcemanager.scheduler.capacity.LeafQueue: assignedContainer application=application_1376080735992_0006 container=Container: [ContainerId: container_1376080735992_0006_01_000007, NodeId: hadoop-210-4:47596, NodeHttpAddress: hadoop-210-4:8042, Resource: <memory:1024, vCores:1>, Priority: 20, State: NEW, Token: null, Status: container_id {, app_attempt_id {, application_id {, id: 6, cluster_timestamp: 1376080735992, }, attemptId: 1, }, id: 7, }, state: C_NEW, ] containerId=container_1376080735992_0006_01_000007 queue=default: capacity=1.0, absoluteCapacity=1.0, usedResources=<memory:15360, vCores:10>usedCapacity=0.3125, absoluteUsedCapacity=0.3125, numApps=5, numContainers=10 usedCapacity=0.3125 absoluteUsedCapacity=0.3125 used=<memory:15360, vCores:10> cluster=<memory:49152, vCores:96>
2013-08-09 20:53:30,664 INFO org.apache.hadoop.yarn.server.resourcemanager.scheduler.capacity.ParentQueue: Re-sorting queues since queue: root.default stats: default: capacity=1.0, absoluteCapacity=1.0, usedResources=<memory:16384, vCores:11>usedCapacity=0.33333334, absoluteUsedCapacity=0.33333334, numApps=5, numContainers=11
2013-08-09 20:53:30,664 INFO org.apache.hadoop.yarn.server.resourcemanager.scheduler.capacity.ParentQueue: assignedContainer queue=root usedCapacity=0.33333334 absoluteUsedCapacity=0.33333334 used=<memory:16384, vCores:11> cluster=<memory:49152, vCores:96>
2013-08-09 20:53:30,665 INFO org.apache.hadoop.yarn.server.resourcemanager.rmcontainer.RMContainerImpl: container_1376080735992_0006_01_000008 Container Transitioned from NEW to ALLOCATED
2013-08-09 20:53:30,665 INFO org.apache.hadoop.yarn.server.resourcemanager.RMAuditLogger: USER=ubuntu	OPERATION=AM Allocated Container	TARGET=SchedulerApp	RESULT=SUCCESS	APPID=application_1376080735992_0006	CONTAINERID=container_1376080735992_0006_01_000008
2013-08-09 20:53:30,665 INFO org.apache.hadoop.yarn.server.resourcemanager.scheduler.common.fica.FiCaSchedulerNode: Assigned container container_1376080735992_0006_01_000008 of capacity <memory:1024, vCores:1> on host hadoop-210-3:58589, which currently has 2 containers, <memory:3072, vCores:2> used and <memory:5120, vCores:14> available
2013-08-09 20:53:30,666 INFO org.apache.hadoop.yarn.server.resourcemanager.scheduler.capacity.LeafQueue: assignedContainer application=application_1376080735992_0006 container=Container: [ContainerId: container_1376080735992_0006_01_000008, NodeId: hadoop-210-3:58589, NodeHttpAddress: hadoop-210-3:8042, Resource: <memory:1024, vCores:1>, Priority: 20, State: NEW, Token: null, Status: container_id {, app_attempt_id {, application_id {, id: 6, cluster_timestamp: 1376080735992, }, attemptId: 1, }, id: 8, }, state: C_NEW, ] containerId=container_1376080735992_0006_01_000008 queue=default: capacity=1.0, absoluteCapacity=1.0, usedResources=<memory:16384, vCores:11>usedCapacity=0.33333334, absoluteUsedCapacity=0.33333334, numApps=5, numContainers=11 usedCapacity=0.33333334 absoluteUsedCapacity=0.33333334 used=<memory:16384, vCores:11> cluster=<memory:49152, vCores:96>
2013-08-09 20:53:30,666 INFO org.apache.hadoop.yarn.server.resourcemanager.scheduler.capacity.ParentQueue: Re-sorting queues since queue: root.default stats: default: capacity=1.0, absoluteCapacity=1.0, usedResources=<memory:17408, vCores:12>usedCapacity=0.35416666, absoluteUsedCapacity=0.35416666, numApps=5, numContainers=12
2013-08-09 20:53:30,666 INFO org.apache.hadoop.yarn.server.resourcemanager.scheduler.capacity.ParentQueue: assignedContainer queue=root usedCapacity=0.35416666 absoluteUsedCapacity=0.35416666 used=<memory:17408, vCores:12> cluster=<memory:49152, vCores:96>
2013-08-09 20:53:30,667 INFO org.apache.hadoop.yarn.server.resourcemanager.rmcontainer.RMContainerImpl: container_1376080735992_0006_01_000009 Container Transitioned from NEW to ALLOCATED
2013-08-09 20:53:30,667 INFO org.apache.hadoop.yarn.server.resourcemanager.RMAuditLogger: USER=ubuntu	OPERATION=AM Allocated Container	TARGET=SchedulerApp	RESULT=SUCCESS	APPID=application_1376080735992_0006	CONTAINERID=container_1376080735992_0006_01_000009
2013-08-09 20:53:30,667 INFO org.apache.hadoop.yarn.server.resourcemanager.scheduler.common.fica.FiCaSchedulerNode: Assigned container container_1376080735992_0006_01_000009 of capacity <memory:1024, vCores:1> on host hadoop-210-3:58589, which currently has 3 containers, <memory:4096, vCores:3> used and <memory:4096, vCores:13> available
2013-08-09 20:53:30,668 INFO org.apache.hadoop.yarn.server.resourcemanager.scheduler.capacity.LeafQueue: assignedContainer application=application_1376080735992_0006 container=Container: [ContainerId: container_1376080735992_0006_01_000009, NodeId: hadoop-210-3:58589, NodeHttpAddress: hadoop-210-3:8042, Resource: <memory:1024, vCores:1>, Priority: 20, State: NEW, Token: null, Status: container_id {, app_attempt_id {, application_id {, id: 6, cluster_timestamp: 1376080735992, }, attemptId: 1, }, id: 9, }, state: C_NEW, ] containerId=container_1376080735992_0006_01_000009 queue=default: capacity=1.0, absoluteCapacity=1.0, usedResources=<memory:17408, vCores:12>usedCapacity=0.35416666, absoluteUsedCapacity=0.35416666, numApps=5, numContainers=12 usedCapacity=0.35416666 absoluteUsedCapacity=0.35416666 used=<memory:17408, vCores:12> cluster=<memory:49152, vCores:96>
2013-08-09 20:53:30,669 INFO org.apache.hadoop.yarn.server.resourcemanager.scheduler.capacity.ParentQueue: Re-sorting queues since queue: root.default stats: default: capacity=1.0, absoluteCapacity=1.0, usedResources=<memory:18432, vCores:13>usedCapacity=0.375, absoluteUsedCapacity=0.375, numApps=5, numContainers=13
2013-08-09 20:53:30,669 INFO org.apache.hadoop.yarn.server.resourcemanager.scheduler.capacity.ParentQueue: assignedContainer queue=root usedCapacity=0.375 absoluteUsedCapacity=0.375 used=<memory:18432, vCores:13> cluster=<memory:49152, vCores:96>
2013-08-09 20:53:30,669 INFO org.apache.hadoop.yarn.server.resourcemanager.rmcontainer.RMContainerImpl: container_1376080735992_0006_01_000010 Container Transitioned from NEW to ALLOCATED
2013-08-09 20:53:30,669 INFO org.apache.hadoop.yarn.server.resourcemanager.RMAuditLogger: USER=ubuntu	OPERATION=AM Allocated Container	TARGET=SchedulerApp	RESULT=SUCCESS	APPID=application_1376080735992_0006	CONTAINERID=container_1376080735992_0006_01_000010
2013-08-09 20:53:30,670 INFO org.apache.hadoop.yarn.server.resourcemanager.scheduler.common.fica.FiCaSchedulerNode: Assigned container container_1376080735992_0006_01_000010 of capacity <memory:1024, vCores:1> on host hadoop-210-3:58589, which currently has 4 containers, <memory:5120, vCores:4> used and <memory:3072, vCores:12> available
2013-08-09 20:53:30,671 INFO org.apache.hadoop.yarn.server.resourcemanager.scheduler.capacity.LeafQueue: assignedContainer application=application_1376080735992_0006 container=Container: [ContainerId: container_1376080735992_0006_01_000010, NodeId: hadoop-210-3:58589, NodeHttpAddress: hadoop-210-3:8042, Resource: <memory:1024, vCores:1>, Priority: 20, State: NEW, Token: null, Status: container_id {, app_attempt_id {, application_id {, id: 6, cluster_timestamp: 1376080735992, }, attemptId: 1, }, id: 10, }, state: C_NEW, ] containerId=container_1376080735992_0006_01_000010 queue=default: capacity=1.0, absoluteCapacity=1.0, usedResources=<memory:18432, vCores:13>usedCapacity=0.375, absoluteUsedCapacity=0.375, numApps=5, numContainers=13 usedCapacity=0.375 absoluteUsedCapacity=0.375 used=<memory:18432, vCores:13> cluster=<memory:49152, vCores:96>
2013-08-09 20:53:30,671 INFO org.apache.hadoop.yarn.server.resourcemanager.scheduler.capacity.ParentQueue: Re-sorting queues since queue: root.default stats: default: capacity=1.0, absoluteCapacity=1.0, usedResources=<memory:19456, vCores:14>usedCapacity=0.39583334, absoluteUsedCapacity=0.39583334, numApps=5, numContainers=14
2013-08-09 20:53:30,671 INFO org.apache.hadoop.yarn.server.resourcemanager.scheduler.capacity.ParentQueue: assignedContainer queue=root usedCapacity=0.39583334 absoluteUsedCapacity=0.39583334 used=<memory:19456, vCores:14> cluster=<memory:49152, vCores:96>
2013-08-09 20:53:30,671 INFO org.apache.hadoop.yarn.server.resourcemanager.rmcontainer.RMContainerImpl: container_1376080735992_0006_01_000011 Container Transitioned from NEW to ALLOCATED
2013-08-09 20:53:30,672 INFO org.apache.hadoop.yarn.server.resourcemanager.RMAuditLogger: USER=ubuntu	OPERATION=AM Allocated Container	TARGET=SchedulerApp	RESULT=SUCCESS	APPID=application_1376080735992_0006	CONTAINERID=container_1376080735992_0006_01_000011
2013-08-09 20:53:30,672 INFO org.apache.hadoop.yarn.server.resourcemanager.scheduler.common.fica.FiCaSchedulerNode: Assigned container container_1376080735992_0006_01_000011 of capacity <memory:1024, vCores:1> on host hadoop-210-3:58589, which currently has 5 containers, <memory:6144, vCores:5> used and <memory:2048, vCores:11> available
2013-08-09 20:53:30,673 INFO org.apache.hadoop.yarn.server.resourcemanager.scheduler.capacity.LeafQueue: assignedContainer application=application_1376080735992_0006 container=Container: [ContainerId: container_1376080735992_0006_01_000011, NodeId: hadoop-210-3:58589, NodeHttpAddress: hadoop-210-3:8042, Resource: <memory:1024, vCores:1>, Priority: 20, State: NEW, Token: null, Status: container_id {, app_attempt_id {, application_id {, id: 6, cluster_timestamp: 1376080735992, }, attemptId: 1, }, id: 11, }, state: C_NEW, ] containerId=container_1376080735992_0006_01_000011 queue=default: capacity=1.0, absoluteCapacity=1.0, usedResources=<memory:19456, vCores:14>usedCapacity=0.39583334, absoluteUsedCapacity=0.39583334, numApps=5, numContainers=14 usedCapacity=0.39583334 absoluteUsedCapacity=0.39583334 used=<memory:19456, vCores:14> cluster=<memory:49152, vCores:96>
2013-08-09 20:53:30,673 INFO org.apache.hadoop.yarn.server.resourcemanager.scheduler.capacity.ParentQueue: Re-sorting queues since queue: root.default stats: default: capacity=1.0, absoluteCapacity=1.0, usedResources=<memory:20480, vCores:15>usedCapacity=0.41666666, absoluteUsedCapacity=0.41666666, numApps=5, numContainers=15
2013-08-09 20:53:30,673 INFO org.apache.hadoop.yarn.server.resourcemanager.scheduler.capacity.ParentQueue: assignedContainer queue=root usedCapacity=0.41666666 absoluteUsedCapacity=0.41666666 used=<memory:20480, vCores:15> cluster=<memory:49152, vCores:96>
2013-08-09 20:53:30,674 INFO org.apache.hadoop.yarn.server.resourcemanager.rmcontainer.RMContainerImpl: container_1376080735992_0006_01_000012 Container Transitioned from NEW to ALLOCATED
2013-08-09 20:53:30,674 INFO org.apache.hadoop.yarn.server.resourcemanager.RMAuditLogger: USER=ubuntu	OPERATION=AM Allocated Container	TARGET=SchedulerApp	RESULT=SUCCESS	APPID=application_1376080735992_0006	CONTAINERID=container_1376080735992_0006_01_000012
2013-08-09 20:53:30,674 INFO org.apache.hadoop.yarn.server.resourcemanager.scheduler.common.fica.FiCaSchedulerNode: Assigned container container_1376080735992_0006_01_000012 of capacity <memory:1024, vCores:1> on host hadoop-210-3:58589, which currently has 6 containers, <memory:7168, vCores:6> used and <memory:1024, vCores:10> available
2013-08-09 20:53:30,675 INFO org.apache.hadoop.yarn.server.resourcemanager.scheduler.capacity.LeafQueue: assignedContainer application=application_1376080735992_0006 container=Container: [ContainerId: container_1376080735992_0006_01_000012, NodeId: hadoop-210-3:58589, NodeHttpAddress: hadoop-210-3:8042, Resource: <memory:1024, vCores:1>, Priority: 20, State: NEW, Token: null, Status: container_id {, app_attempt_id {, application_id {, id: 6, cluster_timestamp: 1376080735992, }, attemptId: 1, }, id: 12, }, state: C_NEW, ] containerId=container_1376080735992_0006_01_000012 queue=default: capacity=1.0, absoluteCapacity=1.0, usedResources=<memory:20480, vCores:15>usedCapacity=0.41666666, absoluteUsedCapacity=0.41666666, numApps=5, numContainers=15 usedCapacity=0.41666666 absoluteUsedCapacity=0.41666666 used=<memory:20480, vCores:15> cluster=<memory:49152, vCores:96>
2013-08-09 20:53:30,675 INFO org.apache.hadoop.yarn.server.resourcemanager.scheduler.capacity.ParentQueue: Re-sorting queues since queue: root.default stats: default: capacity=1.0, absoluteCapacity=1.0, usedResources=<memory:21504, vCores:16>usedCapacity=0.4375, absoluteUsedCapacity=0.4375, numApps=5, numContainers=16
2013-08-09 20:53:30,676 INFO org.apache.hadoop.yarn.server.resourcemanager.scheduler.capacity.ParentQueue: assignedContainer queue=root usedCapacity=0.4375 absoluteUsedCapacity=0.4375 used=<memory:21504, vCores:16> cluster=<memory:49152, vCores:96>
2013-08-09 20:53:30,676 INFO org.apache.hadoop.yarn.server.resourcemanager.rmcontainer.RMContainerImpl: container_1376080735992_0006_01_000013 Container Transitioned from NEW to ALLOCATED
2013-08-09 20:53:30,676 INFO org.apache.hadoop.yarn.server.resourcemanager.RMAuditLogger: USER=ubuntu	OPERATION=AM Allocated Container	TARGET=SchedulerApp	RESULT=SUCCESS	APPID=application_1376080735992_0006	CONTAINERID=container_1376080735992_0006_01_000013
2013-08-09 20:53:30,676 INFO org.apache.hadoop.yarn.server.resourcemanager.scheduler.common.fica.FiCaSchedulerNode: Assigned container container_1376080735992_0006_01_000013 of capacity <memory:1024, vCores:1> on host hadoop-210-3:58589, which currently has 7 containers, <memory:8192, vCores:7> used and <memory:0, vCores:9> available
2013-08-09 20:53:30,677 INFO org.apache.hadoop.yarn.server.resourcemanager.scheduler.capacity.LeafQueue: assignedContainer application=application_1376080735992_0006 container=Container: [ContainerId: container_1376080735992_0006_01_000013, NodeId: hadoop-210-3:58589, NodeHttpAddress: hadoop-210-3:8042, Resource: <memory:1024, vCores:1>, Priority: 20, State: NEW, Token: null, Status: container_id {, app_attempt_id {, application_id {, id: 6, cluster_timestamp: 1376080735992, }, attemptId: 1, }, id: 13, }, state: C_NEW, ] containerId=container_1376080735992_0006_01_000013 queue=default: capacity=1.0, absoluteCapacity=1.0, usedResources=<memory:21504, vCores:16>usedCapacity=0.4375, absoluteUsedCapacity=0.4375, numApps=5, numContainers=16 usedCapacity=0.4375 absoluteUsedCapacity=0.4375 used=<memory:21504, vCores:16> cluster=<memory:49152, vCores:96>
2013-08-09 20:53:30,678 INFO org.apache.hadoop.yarn.server.resourcemanager.scheduler.capacity.ParentQueue: Re-sorting queues since queue: root.default stats: default: capacity=1.0, absoluteCapacity=1.0, usedResources=<memory:22528, vCores:17>usedCapacity=0.45833334, absoluteUsedCapacity=0.45833334, numApps=5, numContainers=17
2013-08-09 20:53:30,678 INFO org.apache.hadoop.yarn.server.resourcemanager.scheduler.capacity.ParentQueue: assignedContainer queue=root usedCapacity=0.45833334 absoluteUsedCapacity=0.45833334 used=<memory:22528, vCores:17> cluster=<memory:49152, vCores:96>
2013-08-09 20:53:30,722 INFO org.apache.hadoop.yarn.server.resourcemanager.rmcontainer.RMContainerImpl: container_1376080735992_0006_01_000014 Container Transitioned from NEW to ALLOCATED
2013-08-09 20:53:30,722 INFO org.apache.hadoop.yarn.server.resourcemanager.RMAuditLogger: USER=ubuntu	OPERATION=AM Allocated Container	TARGET=SchedulerApp	RESULT=SUCCESS	APPID=application_1376080735992_0006	CONTAINERID=container_1376080735992_0006_01_000014
2013-08-09 20:53:30,722 INFO org.apache.hadoop.yarn.server.resourcemanager.scheduler.common.fica.FiCaSchedulerNode: Assigned container container_1376080735992_0006_01_000014 of capacity <memory:1024, vCores:1> on host hadoop-210-2:51035, which currently has 2 containers, <memory:3072, vCores:2> used and <memory:5120, vCores:14> available
2013-08-09 20:53:30,723 INFO org.apache.hadoop.yarn.server.resourcemanager.scheduler.capacity.LeafQueue: assignedContainer application=application_1376080735992_0006 container=Container: [ContainerId: container_1376080735992_0006_01_000014, NodeId: hadoop-210-2:51035, NodeHttpAddress: hadoop-210-2:8042, Resource: <memory:1024, vCores:1>, Priority: 20, State: NEW, Token: null, Status: container_id {, app_attempt_id {, application_id {, id: 6, cluster_timestamp: 1376080735992, }, attemptId: 1, }, id: 14, }, state: C_NEW, ] containerId=container_1376080735992_0006_01_000014 queue=default: capacity=1.0, absoluteCapacity=1.0, usedResources=<memory:22528, vCores:17>usedCapacity=0.45833334, absoluteUsedCapacity=0.45833334, numApps=5, numContainers=17 usedCapacity=0.45833334 absoluteUsedCapacity=0.45833334 used=<memory:22528, vCores:17> cluster=<memory:49152, vCores:96>
2013-08-09 20:53:30,723 INFO org.apache.hadoop.yarn.server.resourcemanager.scheduler.capacity.ParentQueue: Re-sorting queues since queue: root.default stats: default: capacity=1.0, absoluteCapacity=1.0, usedResources=<memory:23552, vCores:18>usedCapacity=0.47916666, absoluteUsedCapacity=0.47916666, numApps=5, numContainers=18
2013-08-09 20:53:30,723 INFO org.apache.hadoop.yarn.server.resourcemanager.scheduler.capacity.ParentQueue: assignedContainer queue=root usedCapacity=0.47916666 absoluteUsedCapacity=0.47916666 used=<memory:23552, vCores:18> cluster=<memory:49152, vCores:96>
2013-08-09 20:53:30,724 INFO org.apache.hadoop.yarn.server.resourcemanager.rmcontainer.RMContainerImpl: container_1376080735992_0006_01_000015 Container Transitioned from NEW to ALLOCATED
2013-08-09 20:53:30,724 INFO org.apache.hadoop.yarn.server.resourcemanager.RMAuditLogger: USER=ubuntu	OPERATION=AM Allocated Container	TARGET=SchedulerApp	RESULT=SUCCESS	APPID=application_1376080735992_0006	CONTAINERID=container_1376080735992_0006_01_000015
2013-08-09 20:53:30,725 INFO org.apache.hadoop.yarn.server.resourcemanager.scheduler.common.fica.FiCaSchedulerNode: Assigned container container_1376080735992_0006_01_000015 of capacity <memory:1024, vCores:1> on host hadoop-210-2:51035, which currently has 3 containers, <memory:4096, vCores:3> used and <memory:4096, vCores:13> available
2013-08-09 20:53:30,727 INFO org.apache.hadoop.yarn.server.resourcemanager.scheduler.capacity.LeafQueue: assignedContainer application=application_1376080735992_0006 container=Container: [ContainerId: container_1376080735992_0006_01_000015, NodeId: hadoop-210-2:51035, NodeHttpAddress: hadoop-210-2:8042, Resource: <memory:1024, vCores:1>, Priority: 20, State: NEW, Token: null, Status: container_id {, app_attempt_id {, application_id {, id: 6, cluster_timestamp: 1376080735992, }, attemptId: 1, }, id: 15, }, state: C_NEW, ] containerId=container_1376080735992_0006_01_000015 queue=default: capacity=1.0, absoluteCapacity=1.0, usedResources=<memory:23552, vCores:18>usedCapacity=0.47916666, absoluteUsedCapacity=0.47916666, numApps=5, numContainers=18 usedCapacity=0.47916666 absoluteUsedCapacity=0.47916666 used=<memory:23552, vCores:18> cluster=<memory:49152, vCores:96>
2013-08-09 20:53:30,727 INFO org.apache.hadoop.yarn.server.resourcemanager.scheduler.capacity.ParentQueue: Re-sorting queues since queue: root.default stats: default: capacity=1.0, absoluteCapacity=1.0, usedResources=<memory:24576, vCores:19>usedCapacity=0.5, absoluteUsedCapacity=0.5, numApps=5, numContainers=19
2013-08-09 20:53:30,727 INFO org.apache.hadoop.yarn.server.resourcemanager.scheduler.capacity.ParentQueue: assignedContainer queue=root usedCapacity=0.5 absoluteUsedCapacity=0.5 used=<memory:24576, vCores:19> cluster=<memory:49152, vCores:96>
2013-08-09 20:53:30,728 INFO org.apache.hadoop.yarn.server.resourcemanager.rmcontainer.RMContainerImpl: container_1376080735992_0006_01_000016 Container Transitioned from NEW to ALLOCATED
2013-08-09 20:53:30,728 INFO org.apache.hadoop.yarn.server.resourcemanager.RMAuditLogger: USER=ubuntu	OPERATION=AM Allocated Container	TARGET=SchedulerApp	RESULT=SUCCESS	APPID=application_1376080735992_0006	CONTAINERID=container_1376080735992_0006_01_000016
2013-08-09 20:53:30,728 INFO org.apache.hadoop.yarn.server.resourcemanager.scheduler.common.fica.FiCaSchedulerNode: Assigned container container_1376080735992_0006_01_000016 of capacity <memory:1024, vCores:1> on host hadoop-210-2:51035, which currently has 4 containers, <memory:5120, vCores:4> used and <memory:3072, vCores:12> available
2013-08-09 20:53:30,729 INFO org.apache.hadoop.yarn.server.resourcemanager.scheduler.capacity.LeafQueue: assignedContainer application=application_1376080735992_0006 container=Container: [ContainerId: container_1376080735992_0006_01_000016, NodeId: hadoop-210-2:51035, NodeHttpAddress: hadoop-210-2:8042, Resource: <memory:1024, vCores:1>, Priority: 20, State: NEW, Token: null, Status: container_id {, app_attempt_id {, application_id {, id: 6, cluster_timestamp: 1376080735992, }, attemptId: 1, }, id: 16, }, state: C_NEW, ] containerId=container_1376080735992_0006_01_000016 queue=default: capacity=1.0, absoluteCapacity=1.0, usedResources=<memory:24576, vCores:19>usedCapacity=0.5, absoluteUsedCapacity=0.5, numApps=5, numContainers=19 usedCapacity=0.5 absoluteUsedCapacity=0.5 used=<memory:24576, vCores:19> cluster=<memory:49152, vCores:96>
2013-08-09 20:53:30,729 INFO org.apache.hadoop.yarn.server.resourcemanager.scheduler.capacity.ParentQueue: Re-sorting queues since queue: root.default stats: default: capacity=1.0, absoluteCapacity=1.0, usedResources=<memory:25600, vCores:20>usedCapacity=0.5208333, absoluteUsedCapacity=0.5208333, numApps=5, numContainers=20
2013-08-09 20:53:30,730 INFO org.apache.hadoop.yarn.server.resourcemanager.scheduler.capacity.ParentQueue: assignedContainer queue=root usedCapacity=0.5208333 absoluteUsedCapacity=0.5208333 used=<memory:25600, vCores:20> cluster=<memory:49152, vCores:96>
2013-08-09 20:53:30,730 INFO org.apache.hadoop.yarn.server.resourcemanager.rmcontainer.RMContainerImpl: container_1376080735992_0006_01_000017 Container Transitioned from NEW to ALLOCATED
2013-08-09 20:53:30,730 INFO org.apache.hadoop.yarn.server.resourcemanager.RMAuditLogger: USER=ubuntu	OPERATION=AM Allocated Container	TARGET=SchedulerApp	RESULT=SUCCESS	APPID=application_1376080735992_0006	CONTAINERID=container_1376080735992_0006_01_000017
2013-08-09 20:53:30,730 INFO org.apache.hadoop.yarn.server.resourcemanager.scheduler.common.fica.FiCaSchedulerNode: Assigned container container_1376080735992_0006_01_000017 of capacity <memory:1024, vCores:1> on host hadoop-210-2:51035, which currently has 5 containers, <memory:6144, vCores:5> used and <memory:2048, vCores:11> available
2013-08-09 20:53:30,731 INFO org.apache.hadoop.yarn.server.resourcemanager.scheduler.capacity.LeafQueue: assignedContainer application=application_1376080735992_0006 container=Container: [ContainerId: container_1376080735992_0006_01_000017, NodeId: hadoop-210-2:51035, NodeHttpAddress: hadoop-210-2:8042, Resource: <memory:1024, vCores:1>, Priority: 20, State: NEW, Token: null, Status: container_id {, app_attempt_id {, application_id {, id: 6, cluster_timestamp: 1376080735992, }, attemptId: 1, }, id: 17, }, state: C_NEW, ] containerId=container_1376080735992_0006_01_000017 queue=default: capacity=1.0, absoluteCapacity=1.0, usedResources=<memory:25600, vCores:20>usedCapacity=0.5208333, absoluteUsedCapacity=0.5208333, numApps=5, numContainers=20 usedCapacity=0.5208333 absoluteUsedCapacity=0.5208333 used=<memory:25600, vCores:20> cluster=<memory:49152, vCores:96>
2013-08-09 20:53:30,732 INFO org.apache.hadoop.yarn.server.resourcemanager.scheduler.capacity.ParentQueue: Re-sorting queues since queue: root.default stats: default: capacity=1.0, absoluteCapacity=1.0, usedResources=<memory:26624, vCores:21>usedCapacity=0.5416667, absoluteUsedCapacity=0.5416667, numApps=5, numContainers=21
2013-08-09 20:53:30,732 INFO org.apache.hadoop.yarn.server.resourcemanager.scheduler.capacity.ParentQueue: assignedContainer queue=root usedCapacity=0.5416667 absoluteUsedCapacity=0.5416667 used=<memory:26624, vCores:21> cluster=<memory:49152, vCores:96>
2013-08-09 20:53:30,732 INFO org.apache.hadoop.yarn.server.resourcemanager.rmcontainer.RMContainerImpl: container_1376080735992_0006_01_000018 Container Transitioned from NEW to ALLOCATED
2013-08-09 20:53:30,732 INFO org.apache.hadoop.yarn.server.resourcemanager.RMAuditLogger: USER=ubuntu	OPERATION=AM Allocated Container	TARGET=SchedulerApp	RESULT=SUCCESS	APPID=application_1376080735992_0006	CONTAINERID=container_1376080735992_0006_01_000018
2013-08-09 20:53:30,732 INFO org.apache.hadoop.yarn.server.resourcemanager.scheduler.common.fica.FiCaSchedulerNode: Assigned container container_1376080735992_0006_01_000018 of capacity <memory:1024, vCores:1> on host hadoop-210-2:51035, which currently has 6 containers, <memory:7168, vCores:6> used and <memory:1024, vCores:10> available
2013-08-09 20:53:30,733 INFO org.apache.hadoop.yarn.server.resourcemanager.scheduler.capacity.LeafQueue: assignedContainer application=application_1376080735992_0006 container=Container: [ContainerId: container_1376080735992_0006_01_000018, NodeId: hadoop-210-2:51035, NodeHttpAddress: hadoop-210-2:8042, Resource: <memory:1024, vCores:1>, Priority: 20, State: NEW, Token: null, Status: container_id {, app_attempt_id {, application_id {, id: 6, cluster_timestamp: 1376080735992, }, attemptId: 1, }, id: 18, }, state: C_NEW, ] containerId=container_1376080735992_0006_01_000018 queue=default: capacity=1.0, absoluteCapacity=1.0, usedResources=<memory:26624, vCores:21>usedCapacity=0.5416667, absoluteUsedCapacity=0.5416667, numApps=5, numContainers=21 usedCapacity=0.5416667 absoluteUsedCapacity=0.5416667 used=<memory:26624, vCores:21> cluster=<memory:49152, vCores:96>
2013-08-09 20:53:30,734 INFO org.apache.hadoop.yarn.server.resourcemanager.scheduler.capacity.ParentQueue: Re-sorting queues since queue: root.default stats: default: capacity=1.0, absoluteCapacity=1.0, usedResources=<memory:27648, vCores:22>usedCapacity=0.5625, absoluteUsedCapacity=0.5625, numApps=5, numContainers=22
2013-08-09 20:53:30,734 INFO org.apache.hadoop.yarn.server.resourcemanager.scheduler.capacity.ParentQueue: assignedContainer queue=root usedCapacity=0.5625 absoluteUsedCapacity=0.5625 used=<memory:27648, vCores:22> cluster=<memory:49152, vCores:96>
2013-08-09 20:53:30,734 INFO org.apache.hadoop.yarn.server.resourcemanager.rmcontainer.RMContainerImpl: container_1376080735992_0006_01_000019 Container Transitioned from NEW to ALLOCATED
2013-08-09 20:53:30,734 INFO org.apache.hadoop.yarn.server.resourcemanager.RMAuditLogger: USER=ubuntu	OPERATION=AM Allocated Container	TARGET=SchedulerApp	RESULT=SUCCESS	APPID=application_1376080735992_0006	CONTAINERID=container_1376080735992_0006_01_000019
2013-08-09 20:53:30,735 INFO org.apache.hadoop.yarn.server.resourcemanager.scheduler.common.fica.FiCaSchedulerNode: Assigned container container_1376080735992_0006_01_000019 of capacity <memory:1024, vCores:1> on host hadoop-210-2:51035, which currently has 7 containers, <memory:8192, vCores:7> used and <memory:0, vCores:9> available
2013-08-09 20:53:30,736 INFO org.apache.hadoop.yarn.server.resourcemanager.scheduler.capacity.LeafQueue: assignedContainer application=application_1376080735992_0006 container=Container: [ContainerId: container_1376080735992_0006_01_000019, NodeId: hadoop-210-2:51035, NodeHttpAddress: hadoop-210-2:8042, Resource: <memory:1024, vCores:1>, Priority: 20, State: NEW, Token: null, Status: container_id {, app_attempt_id {, application_id {, id: 6, cluster_timestamp: 1376080735992, }, attemptId: 1, }, id: 19, }, state: C_NEW, ] containerId=container_1376080735992_0006_01_000019 queue=default: capacity=1.0, absoluteCapacity=1.0, usedResources=<memory:27648, vCores:22>usedCapacity=0.5625, absoluteUsedCapacity=0.5625, numApps=5, numContainers=22 usedCapacity=0.5625 absoluteUsedCapacity=0.5625 used=<memory:27648, vCores:22> cluster=<memory:49152, vCores:96>
2013-08-09 20:53:30,736 INFO org.apache.hadoop.yarn.server.resourcemanager.scheduler.capacity.ParentQueue: Re-sorting queues since queue: root.default stats: default: capacity=1.0, absoluteCapacity=1.0, usedResources=<memory:28672, vCores:23>usedCapacity=0.5833333, absoluteUsedCapacity=0.5833333, numApps=5, numContainers=23
2013-08-09 20:53:30,736 INFO org.apache.hadoop.yarn.server.resourcemanager.scheduler.capacity.ParentQueue: assignedContainer queue=root usedCapacity=0.5833333 absoluteUsedCapacity=0.5833333 used=<memory:28672, vCores:23> cluster=<memory:49152, vCores:96>
2013-08-09 20:53:30,737 INFO org.apache.hadoop.yarn.server.resourcemanager.rmcontainer.RMContainerImpl: container_1376080735992_0006_01_000020 Container Transitioned from NEW to ALLOCATED
2013-08-09 20:53:30,737 INFO org.apache.hadoop.yarn.server.resourcemanager.RMAuditLogger: USER=ubuntu	OPERATION=AM Allocated Container	TARGET=SchedulerApp	RESULT=SUCCESS	APPID=application_1376080735992_0006	CONTAINERID=container_1376080735992_0006_01_000020
2013-08-09 20:53:30,737 INFO org.apache.hadoop.yarn.server.resourcemanager.scheduler.common.fica.FiCaSchedulerNode: Assigned container container_1376080735992_0006_01_000020 of capacity <memory:1024, vCores:1> on host hadoop-210-5:40689, which currently has 1 containers, <memory:1024, vCores:1> used and <memory:7168, vCores:15> available
2013-08-09 20:53:30,738 INFO org.apache.hadoop.yarn.server.resourcemanager.scheduler.capacity.LeafQueue: assignedContainer application=application_1376080735992_0006 container=Container: [ContainerId: container_1376080735992_0006_01_000020, NodeId: hadoop-210-5:40689, NodeHttpAddress: hadoop-210-5:8042, Resource: <memory:1024, vCores:1>, Priority: 20, State: NEW, Token: null, Status: container_id {, app_attempt_id {, application_id {, id: 6, cluster_timestamp: 1376080735992, }, attemptId: 1, }, id: 20, }, state: C_NEW, ] containerId=container_1376080735992_0006_01_000020 queue=default: capacity=1.0, absoluteCapacity=1.0, usedResources=<memory:28672, vCores:23>usedCapacity=0.5833333, absoluteUsedCapacity=0.5833333, numApps=5, numContainers=23 usedCapacity=0.5833333 absoluteUsedCapacity=0.5833333 used=<memory:28672, vCores:23> cluster=<memory:49152, vCores:96>
2013-08-09 20:53:30,739 INFO org.apache.hadoop.yarn.server.resourcemanager.scheduler.capacity.ParentQueue: Re-sorting queues since queue: root.default stats: default: capacity=1.0, absoluteCapacity=1.0, usedResources=<memory:29696, vCores:24>usedCapacity=0.6041667, absoluteUsedCapacity=0.6041667, numApps=5, numContainers=24
2013-08-09 20:53:30,739 INFO org.apache.hadoop.yarn.server.resourcemanager.scheduler.capacity.ParentQueue: assignedContainer queue=root usedCapacity=0.6041667 absoluteUsedCapacity=0.6041667 used=<memory:29696, vCores:24> cluster=<memory:49152, vCores:96>
2013-08-09 20:53:30,739 INFO org.apache.hadoop.yarn.server.resourcemanager.rmcontainer.RMContainerImpl: container_1376080735992_0006_01_000021 Container Transitioned from NEW to ALLOCATED
2013-08-09 20:53:30,739 INFO org.apache.hadoop.yarn.server.resourcemanager.RMAuditLogger: USER=ubuntu	OPERATION=AM Allocated Container	TARGET=SchedulerApp	RESULT=SUCCESS	APPID=application_1376080735992_0006	CONTAINERID=container_1376080735992_0006_01_000021
2013-08-09 20:53:30,740 INFO org.apache.hadoop.yarn.server.resourcemanager.scheduler.common.fica.FiCaSchedulerNode: Assigned container container_1376080735992_0006_01_000021 of capacity <memory:1024, vCores:1> on host hadoop-210-5:40689, which currently has 2 containers, <memory:2048, vCores:2> used and <memory:6144, vCores:14> available
2013-08-09 20:53:30,741 INFO org.apache.hadoop.yarn.server.resourcemanager.scheduler.capacity.LeafQueue: assignedContainer application=application_1376080735992_0006 container=Container: [ContainerId: container_1376080735992_0006_01_000021, NodeId: hadoop-210-5:40689, NodeHttpAddress: hadoop-210-5:8042, Resource: <memory:1024, vCores:1>, Priority: 20, State: NEW, Token: null, Status: container_id {, app_attempt_id {, application_id {, id: 6, cluster_timestamp: 1376080735992, }, attemptId: 1, }, id: 21, }, state: C_NEW, ] containerId=container_1376080735992_0006_01_000021 queue=default: capacity=1.0, absoluteCapacity=1.0, usedResources=<memory:29696, vCores:24>usedCapacity=0.6041667, absoluteUsedCapacity=0.6041667, numApps=5, numContainers=24 usedCapacity=0.6041667 absoluteUsedCapacity=0.6041667 used=<memory:29696, vCores:24> cluster=<memory:49152, vCores:96>
2013-08-09 20:53:30,741 INFO org.apache.hadoop.yarn.server.resourcemanager.scheduler.capacity.ParentQueue: Re-sorting queues since queue: root.default stats: default: capacity=1.0, absoluteCapacity=1.0, usedResources=<memory:30720, vCores:25>usedCapacity=0.625, absoluteUsedCapacity=0.625, numApps=5, numContainers=25
2013-08-09 20:53:30,741 INFO org.apache.hadoop.yarn.server.resourcemanager.scheduler.capacity.ParentQueue: assignedContainer queue=root usedCapacity=0.625 absoluteUsedCapacity=0.625 used=<memory:30720, vCores:25> cluster=<memory:49152, vCores:96>
2013-08-09 20:53:30,741 INFO org.apache.hadoop.yarn.server.resourcemanager.rmcontainer.RMContainerImpl: container_1376080735992_0006_01_000022 Container Transitioned from NEW to ALLOCATED
2013-08-09 20:53:30,742 INFO org.apache.hadoop.yarn.server.resourcemanager.RMAuditLogger: USER=ubuntu	OPERATION=AM Allocated Container	TARGET=SchedulerApp	RESULT=SUCCESS	APPID=application_1376080735992_0006	CONTAINERID=container_1376080735992_0006_01_000022
2013-08-09 20:53:30,742 INFO org.apache.hadoop.yarn.server.resourcemanager.scheduler.common.fica.FiCaSchedulerNode: Assigned container container_1376080735992_0006_01_000022 of capacity <memory:1024, vCores:1> on host hadoop-210-5:40689, which currently has 3 containers, <memory:3072, vCores:3> used and <memory:5120, vCores:13> available
2013-08-09 20:53:30,743 INFO org.apache.hadoop.yarn.server.resourcemanager.scheduler.capacity.LeafQueue: assignedContainer application=application_1376080735992_0006 container=Container: [ContainerId: container_1376080735992_0006_01_000022, NodeId: hadoop-210-5:40689, NodeHttpAddress: hadoop-210-5:8042, Resource: <memory:1024, vCores:1>, Priority: 20, State: NEW, Token: null, Status: container_id {, app_attempt_id {, application_id {, id: 6, cluster_timestamp: 1376080735992, }, attemptId: 1, }, id: 22, }, state: C_NEW, ] containerId=container_1376080735992_0006_01_000022 queue=default: capacity=1.0, absoluteCapacity=1.0, usedResources=<memory:30720, vCores:25>usedCapacity=0.625, absoluteUsedCapacity=0.625, numApps=5, numContainers=25 usedCapacity=0.625 absoluteUsedCapacity=0.625 used=<memory:30720, vCores:25> cluster=<memory:49152, vCores:96>
2013-08-09 20:53:30,743 INFO org.apache.hadoop.yarn.server.resourcemanager.scheduler.capacity.ParentQueue: Re-sorting queues since queue: root.default stats: default: capacity=1.0, absoluteCapacity=1.0, usedResources=<memory:31744, vCores:26>usedCapacity=0.6458333, absoluteUsedCapacity=0.6458333, numApps=5, numContainers=26
2013-08-09 20:53:30,743 INFO org.apache.hadoop.yarn.server.resourcemanager.scheduler.capacity.ParentQueue: assignedContainer queue=root usedCapacity=0.6458333 absoluteUsedCapacity=0.6458333 used=<memory:31744, vCores:26> cluster=<memory:49152, vCores:96>
2013-08-09 20:53:30,744 INFO org.apache.hadoop.yarn.server.resourcemanager.rmcontainer.RMContainerImpl: container_1376080735992_0006_01_000023 Container Transitioned from NEW to ALLOCATED
2013-08-09 20:53:30,744 INFO org.apache.hadoop.yarn.server.resourcemanager.RMAuditLogger: USER=ubuntu	OPERATION=AM Allocated Container	TARGET=SchedulerApp	RESULT=SUCCESS	APPID=application_1376080735992_0006	CONTAINERID=container_1376080735992_0006_01_000023
2013-08-09 20:53:30,744 INFO org.apache.hadoop.yarn.server.resourcemanager.scheduler.common.fica.FiCaSchedulerNode: Assigned container container_1376080735992_0006_01_000023 of capacity <memory:1024, vCores:1> on host hadoop-210-5:40689, which currently has 4 containers, <memory:4096, vCores:4> used and <memory:4096, vCores:12> available
2013-08-09 20:53:30,745 INFO org.apache.hadoop.yarn.server.resourcemanager.scheduler.capacity.LeafQueue: assignedContainer application=application_1376080735992_0006 container=Container: [ContainerId: container_1376080735992_0006_01_000023, NodeId: hadoop-210-5:40689, NodeHttpAddress: hadoop-210-5:8042, Resource: <memory:1024, vCores:1>, Priority: 20, State: NEW, Token: null, Status: container_id {, app_attempt_id {, application_id {, id: 6, cluster_timestamp: 1376080735992, }, attemptId: 1, }, id: 23, }, state: C_NEW, ] containerId=container_1376080735992_0006_01_000023 queue=default: capacity=1.0, absoluteCapacity=1.0, usedResources=<memory:31744, vCores:26>usedCapacity=0.6458333, absoluteUsedCapacity=0.6458333, numApps=5, numContainers=26 usedCapacity=0.6458333 absoluteUsedCapacity=0.6458333 used=<memory:31744, vCores:26> cluster=<memory:49152, vCores:96>
2013-08-09 20:53:30,745 INFO org.apache.hadoop.yarn.server.resourcemanager.scheduler.capacity.ParentQueue: Re-sorting queues since queue: root.default stats: default: capacity=1.0, absoluteCapacity=1.0, usedResources=<memory:32768, vCores:27>usedCapacity=0.6666667, absoluteUsedCapacity=0.6666667, numApps=5, numContainers=27
2013-08-09 20:53:30,745 INFO org.apache.hadoop.yarn.server.resourcemanager.scheduler.capacity.ParentQueue: assignedContainer queue=root usedCapacity=0.6666667 absoluteUsedCapacity=0.6666667 used=<memory:32768, vCores:27> cluster=<memory:49152, vCores:96>
2013-08-09 20:53:30,746 INFO org.apache.hadoop.yarn.server.resourcemanager.rmcontainer.RMContainerImpl: container_1376080735992_0006_01_000024 Container Transitioned from NEW to ALLOCATED
2013-08-09 20:53:30,746 INFO org.apache.hadoop.yarn.server.resourcemanager.RMAuditLogger: USER=ubuntu	OPERATION=AM Allocated Container	TARGET=SchedulerApp	RESULT=SUCCESS	APPID=application_1376080735992_0006	CONTAINERID=container_1376080735992_0006_01_000024
2013-08-09 20:53:30,746 INFO org.apache.hadoop.yarn.server.resourcemanager.scheduler.common.fica.FiCaSchedulerNode: Assigned container container_1376080735992_0006_01_000024 of capacity <memory:1024, vCores:1> on host hadoop-210-5:40689, which currently has 5 containers, <memory:5120, vCores:5> used and <memory:3072, vCores:11> available
2013-08-09 20:53:30,747 INFO org.apache.hadoop.yarn.server.resourcemanager.scheduler.capacity.LeafQueue: assignedContainer application=application_1376080735992_0006 container=Container: [ContainerId: container_1376080735992_0006_01_000024, NodeId: hadoop-210-5:40689, NodeHttpAddress: hadoop-210-5:8042, Resource: <memory:1024, vCores:1>, Priority: 20, State: NEW, Token: null, Status: container_id {, app_attempt_id {, application_id {, id: 6, cluster_timestamp: 1376080735992, }, attemptId: 1, }, id: 24, }, state: C_NEW, ] containerId=container_1376080735992_0006_01_000024 queue=default: capacity=1.0, absoluteCapacity=1.0, usedResources=<memory:32768, vCores:27>usedCapacity=0.6666667, absoluteUsedCapacity=0.6666667, numApps=5, numContainers=27 usedCapacity=0.6666667 absoluteUsedCapacity=0.6666667 used=<memory:32768, vCores:27> cluster=<memory:49152, vCores:96>
2013-08-09 20:53:30,747 INFO org.apache.hadoop.yarn.server.resourcemanager.scheduler.capacity.ParentQueue: Re-sorting queues since queue: root.default stats: default: capacity=1.0, absoluteCapacity=1.0, usedResources=<memory:33792, vCores:28>usedCapacity=0.6875, absoluteUsedCapacity=0.6875, numApps=5, numContainers=28
2013-08-09 20:53:30,748 INFO org.apache.hadoop.yarn.server.resourcemanager.scheduler.capacity.ParentQueue: assignedContainer queue=root usedCapacity=0.6875 absoluteUsedCapacity=0.6875 used=<memory:33792, vCores:28> cluster=<memory:49152, vCores:96>
2013-08-09 20:53:30,748 INFO org.apache.hadoop.yarn.server.resourcemanager.rmcontainer.RMContainerImpl: container_1376080735992_0006_01_000025 Container Transitioned from NEW to ALLOCATED
2013-08-09 20:53:30,748 INFO org.apache.hadoop.yarn.server.resourcemanager.RMAuditLogger: USER=ubuntu	OPERATION=AM Allocated Container	TARGET=SchedulerApp	RESULT=SUCCESS	APPID=application_1376080735992_0006	CONTAINERID=container_1376080735992_0006_01_000025
2013-08-09 20:53:30,749 INFO org.apache.hadoop.yarn.server.resourcemanager.scheduler.common.fica.FiCaSchedulerNode: Assigned container container_1376080735992_0006_01_000025 of capacity <memory:1024, vCores:1> on host hadoop-210-5:40689, which currently has 6 containers, <memory:6144, vCores:6> used and <memory:2048, vCores:10> available
2013-08-09 20:53:30,750 INFO org.apache.hadoop.yarn.server.resourcemanager.scheduler.capacity.LeafQueue: assignedContainer application=application_1376080735992_0006 container=Container: [ContainerId: container_1376080735992_0006_01_000025, NodeId: hadoop-210-5:40689, NodeHttpAddress: hadoop-210-5:8042, Resource: <memory:1024, vCores:1>, Priority: 20, State: NEW, Token: null, Status: container_id {, app_attempt_id {, application_id {, id: 6, cluster_timestamp: 1376080735992, }, attemptId: 1, }, id: 25, }, state: C_NEW, ] containerId=container_1376080735992_0006_01_000025 queue=default: capacity=1.0, absoluteCapacity=1.0, usedResources=<memory:33792, vCores:28>usedCapacity=0.6875, absoluteUsedCapacity=0.6875, numApps=5, numContainers=28 usedCapacity=0.6875 absoluteUsedCapacity=0.6875 used=<memory:33792, vCores:28> cluster=<memory:49152, vCores:96>
2013-08-09 20:53:30,750 INFO org.apache.hadoop.yarn.server.resourcemanager.scheduler.capacity.ParentQueue: Re-sorting queues since queue: root.default stats: default: capacity=1.0, absoluteCapacity=1.0, usedResources=<memory:34816, vCores:29>usedCapacity=0.7083333, absoluteUsedCapacity=0.7083333, numApps=5, numContainers=29
2013-08-09 20:53:30,750 INFO org.apache.hadoop.yarn.server.resourcemanager.scheduler.capacity.ParentQueue: assignedContainer queue=root usedCapacity=0.7083333 absoluteUsedCapacity=0.7083333 used=<memory:34816, vCores:29> cluster=<memory:49152, vCores:96>
2013-08-09 20:53:30,751 INFO org.apache.hadoop.yarn.server.resourcemanager.rmcontainer.RMContainerImpl: container_1376080735992_0006_01_000026 Container Transitioned from NEW to ALLOCATED
2013-08-09 20:53:30,751 INFO org.apache.hadoop.yarn.server.resourcemanager.RMAuditLogger: USER=ubuntu	OPERATION=AM Allocated Container	TARGET=SchedulerApp	RESULT=SUCCESS	APPID=application_1376080735992_0006	CONTAINERID=container_1376080735992_0006_01_000026
2013-08-09 20:53:30,751 INFO org.apache.hadoop.yarn.server.resourcemanager.scheduler.common.fica.FiCaSchedulerNode: Assigned container container_1376080735992_0006_01_000026 of capacity <memory:1024, vCores:1> on host hadoop-210-5:40689, which currently has 7 containers, <memory:7168, vCores:7> used and <memory:1024, vCores:9> available
2013-08-09 20:53:30,752 INFO org.apache.hadoop.yarn.server.resourcemanager.scheduler.capacity.LeafQueue: assignedContainer application=application_1376080735992_0006 container=Container: [ContainerId: container_1376080735992_0006_01_000026, NodeId: hadoop-210-5:40689, NodeHttpAddress: hadoop-210-5:8042, Resource: <memory:1024, vCores:1>, Priority: 20, State: NEW, Token: null, Status: container_id {, app_attempt_id {, application_id {, id: 6, cluster_timestamp: 1376080735992, }, attemptId: 1, }, id: 26, }, state: C_NEW, ] containerId=container_1376080735992_0006_01_000026 queue=default: capacity=1.0, absoluteCapacity=1.0, usedResources=<memory:34816, vCores:29>usedCapacity=0.7083333, absoluteUsedCapacity=0.7083333, numApps=5, numContainers=29 usedCapacity=0.7083333 absoluteUsedCapacity=0.7083333 used=<memory:34816, vCores:29> cluster=<memory:49152, vCores:96>
2013-08-09 20:53:30,752 INFO org.apache.hadoop.yarn.server.resourcemanager.scheduler.capacity.ParentQueue: Re-sorting queues since queue: root.default stats: default: capacity=1.0, absoluteCapacity=1.0, usedResources=<memory:35840, vCores:30>usedCapacity=0.7291667, absoluteUsedCapacity=0.7291667, numApps=5, numContainers=30
2013-08-09 20:53:30,752 INFO org.apache.hadoop.yarn.server.resourcemanager.scheduler.capacity.ParentQueue: assignedContainer queue=root usedCapacity=0.7291667 absoluteUsedCapacity=0.7291667 used=<memory:35840, vCores:30> cluster=<memory:49152, vCores:96>
2013-08-09 20:53:30,753 INFO org.apache.hadoop.yarn.server.resourcemanager.rmcontainer.RMContainerImpl: container_1376080735992_0006_01_000027 Container Transitioned from NEW to ALLOCATED
2013-08-09 20:53:30,753 INFO org.apache.hadoop.yarn.server.resourcemanager.RMAuditLogger: USER=ubuntu	OPERATION=AM Allocated Container	TARGET=SchedulerApp	RESULT=SUCCESS	APPID=application_1376080735992_0006	CONTAINERID=container_1376080735992_0006_01_000027
2013-08-09 20:53:30,753 INFO org.apache.hadoop.yarn.server.resourcemanager.scheduler.common.fica.FiCaSchedulerNode: Assigned container container_1376080735992_0006_01_000027 of capacity <memory:1024, vCores:1> on host hadoop-210-5:40689, which currently has 8 containers, <memory:8192, vCores:8> used and <memory:0, vCores:8> available
2013-08-09 20:53:30,754 INFO org.apache.hadoop.yarn.server.resourcemanager.scheduler.capacity.LeafQueue: assignedContainer application=application_1376080735992_0006 container=Container: [ContainerId: container_1376080735992_0006_01_000027, NodeId: hadoop-210-5:40689, NodeHttpAddress: hadoop-210-5:8042, Resource: <memory:1024, vCores:1>, Priority: 20, State: NEW, Token: null, Status: container_id {, app_attempt_id {, application_id {, id: 6, cluster_timestamp: 1376080735992, }, attemptId: 1, }, id: 27, }, state: C_NEW, ] containerId=container_1376080735992_0006_01_000027 queue=default: capacity=1.0, absoluteCapacity=1.0, usedResources=<memory:35840, vCores:30>usedCapacity=0.7291667, absoluteUsedCapacity=0.7291667, numApps=5, numContainers=30 usedCapacity=0.7291667 absoluteUsedCapacity=0.7291667 used=<memory:35840, vCores:30> cluster=<memory:49152, vCores:96>
2013-08-09 20:53:30,754 INFO org.apache.hadoop.yarn.server.resourcemanager.scheduler.capacity.ParentQueue: Re-sorting queues since queue: root.default stats: default: capacity=1.0, absoluteCapacity=1.0, usedResources=<memory:36864, vCores:31>usedCapacity=0.75, absoluteUsedCapacity=0.75, numApps=5, numContainers=31
2013-08-09 20:53:30,755 INFO org.apache.hadoop.yarn.server.resourcemanager.scheduler.capacity.ParentQueue: assignedContainer queue=root usedCapacity=0.75 absoluteUsedCapacity=0.75 used=<memory:36864, vCores:31> cluster=<memory:49152, vCores:96>
2013-08-09 20:53:31,077 INFO org.apache.hadoop.yarn.server.resourcemanager.rmcontainer.RMContainerImpl: container_1376080735992_0006_01_000028 Container Transitioned from NEW to ALLOCATED
2013-08-09 20:53:31,077 INFO org.apache.hadoop.yarn.server.resourcemanager.RMAuditLogger: USER=ubuntu	OPERATION=AM Allocated Container	TARGET=SchedulerApp	RESULT=SUCCESS	APPID=application_1376080735992_0006	CONTAINERID=container_1376080735992_0006_01_000028
2013-08-09 20:53:31,077 INFO org.apache.hadoop.yarn.server.resourcemanager.scheduler.common.fica.FiCaSchedulerNode: Assigned container container_1376080735992_0006_01_000028 of capacity <memory:1024, vCores:1> on host hadoop-210-6:41207, which currently has 2 containers, <memory:3072, vCores:2> used and <memory:5120, vCores:14> available
2013-08-09 20:53:31,078 INFO org.apache.hadoop.yarn.server.resourcemanager.scheduler.capacity.LeafQueue: assignedContainer application=application_1376080735992_0006 container=Container: [ContainerId: container_1376080735992_0006_01_000028, NodeId: hadoop-210-6:41207, NodeHttpAddress: hadoop-210-6:8042, Resource: <memory:1024, vCores:1>, Priority: 20, State: NEW, Token: null, Status: container_id {, app_attempt_id {, application_id {, id: 6, cluster_timestamp: 1376080735992, }, attemptId: 1, }, id: 28, }, state: C_NEW, ] containerId=container_1376080735992_0006_01_000028 queue=default: capacity=1.0, absoluteCapacity=1.0, usedResources=<memory:36864, vCores:31>usedCapacity=0.75, absoluteUsedCapacity=0.75, numApps=5, numContainers=31 usedCapacity=0.75 absoluteUsedCapacity=0.75 used=<memory:36864, vCores:31> cluster=<memory:49152, vCores:96>
2013-08-09 20:53:31,079 INFO org.apache.hadoop.yarn.server.resourcemanager.scheduler.capacity.ParentQueue: Re-sorting queues since queue: root.default stats: default: capacity=1.0, absoluteCapacity=1.0, usedResources=<memory:37888, vCores:32>usedCapacity=0.7708333, absoluteUsedCapacity=0.7708333, numApps=5, numContainers=32
2013-08-09 20:53:31,079 INFO org.apache.hadoop.yarn.server.resourcemanager.scheduler.capacity.ParentQueue: assignedContainer queue=root usedCapacity=0.7708333 absoluteUsedCapacity=0.7708333 used=<memory:37888, vCores:32> cluster=<memory:49152, vCores:96>
2013-08-09 20:53:31,079 INFO org.apache.hadoop.yarn.server.resourcemanager.rmcontainer.RMContainerImpl: container_1376080735992_0006_01_000029 Container Transitioned from NEW to ALLOCATED
2013-08-09 20:53:31,079 INFO org.apache.hadoop.yarn.server.resourcemanager.RMAuditLogger: USER=ubuntu	OPERATION=AM Allocated Container	TARGET=SchedulerApp	RESULT=SUCCESS	APPID=application_1376080735992_0006	CONTAINERID=container_1376080735992_0006_01_000029
2013-08-09 20:53:31,080 INFO org.apache.hadoop.yarn.server.resourcemanager.scheduler.common.fica.FiCaSchedulerNode: Assigned container container_1376080735992_0006_01_000029 of capacity <memory:1024, vCores:1> on host hadoop-210-6:41207, which currently has 3 containers, <memory:4096, vCores:3> used and <memory:4096, vCores:13> available
2013-08-09 20:53:31,081 INFO org.apache.hadoop.yarn.server.resourcemanager.scheduler.capacity.LeafQueue: assignedContainer application=application_1376080735992_0006 container=Container: [ContainerId: container_1376080735992_0006_01_000029, NodeId: hadoop-210-6:41207, NodeHttpAddress: hadoop-210-6:8042, Resource: <memory:1024, vCores:1>, Priority: 20, State: NEW, Token: null, Status: container_id {, app_attempt_id {, application_id {, id: 6, cluster_timestamp: 1376080735992, }, attemptId: 1, }, id: 29, }, state: C_NEW, ] containerId=container_1376080735992_0006_01_000029 queue=default: capacity=1.0, absoluteCapacity=1.0, usedResources=<memory:37888, vCores:32>usedCapacity=0.7708333, absoluteUsedCapacity=0.7708333, numApps=5, numContainers=32 usedCapacity=0.7708333 absoluteUsedCapacity=0.7708333 used=<memory:37888, vCores:32> cluster=<memory:49152, vCores:96>
2013-08-09 20:53:31,081 INFO org.apache.hadoop.yarn.server.resourcemanager.scheduler.capacity.ParentQueue: Re-sorting queues since queue: root.default stats: default: capacity=1.0, absoluteCapacity=1.0, usedResources=<memory:38912, vCores:33>usedCapacity=0.7916667, absoluteUsedCapacity=0.7916667, numApps=5, numContainers=33
2013-08-09 20:53:31,081 INFO org.apache.hadoop.yarn.server.resourcemanager.scheduler.capacity.ParentQueue: assignedContainer queue=root usedCapacity=0.7916667 absoluteUsedCapacity=0.7916667 used=<memory:38912, vCores:33> cluster=<memory:49152, vCores:96>
2013-08-09 20:53:31,082 INFO org.apache.hadoop.yarn.server.resourcemanager.rmcontainer.RMContainerImpl: container_1376080735992_0006_01_000030 Container Transitioned from NEW to ALLOCATED
2013-08-09 20:53:31,082 INFO org.apache.hadoop.yarn.server.resourcemanager.RMAuditLogger: USER=ubuntu	OPERATION=AM Allocated Container	TARGET=SchedulerApp	RESULT=SUCCESS	APPID=application_1376080735992_0006	CONTAINERID=container_1376080735992_0006_01_000030
2013-08-09 20:53:31,082 INFO org.apache.hadoop.yarn.server.resourcemanager.scheduler.common.fica.FiCaSchedulerNode: Assigned container container_1376080735992_0006_01_000030 of capacity <memory:1024, vCores:1> on host hadoop-210-6:41207, which currently has 4 containers, <memory:5120, vCores:4> used and <memory:3072, vCores:12> available
2013-08-09 20:53:31,083 INFO org.apache.hadoop.yarn.server.resourcemanager.scheduler.capacity.LeafQueue: assignedContainer application=application_1376080735992_0006 container=Container: [ContainerId: container_1376080735992_0006_01_000030, NodeId: hadoop-210-6:41207, NodeHttpAddress: hadoop-210-6:8042, Resource: <memory:1024, vCores:1>, Priority: 20, State: NEW, Token: null, Status: container_id {, app_attempt_id {, application_id {, id: 6, cluster_timestamp: 1376080735992, }, attemptId: 1, }, id: 30, }, state: C_NEW, ] containerId=container_1376080735992_0006_01_000030 queue=default: capacity=1.0, absoluteCapacity=1.0, usedResources=<memory:38912, vCores:33>usedCapacity=0.7916667, absoluteUsedCapacity=0.7916667, numApps=5, numContainers=33 usedCapacity=0.7916667 absoluteUsedCapacity=0.7916667 used=<memory:38912, vCores:33> cluster=<memory:49152, vCores:96>
2013-08-09 20:53:31,083 INFO org.apache.hadoop.yarn.server.resourcemanager.scheduler.capacity.ParentQueue: Re-sorting queues since queue: root.default stats: default: capacity=1.0, absoluteCapacity=1.0, usedResources=<memory:39936, vCores:34>usedCapacity=0.8125, absoluteUsedCapacity=0.8125, numApps=5, numContainers=34
2013-08-09 20:53:31,083 INFO org.apache.hadoop.yarn.server.resourcemanager.scheduler.capacity.ParentQueue: assignedContainer queue=root usedCapacity=0.8125 absoluteUsedCapacity=0.8125 used=<memory:39936, vCores:34> cluster=<memory:49152, vCores:96>
2013-08-09 20:53:31,084 INFO org.apache.hadoop.yarn.server.resourcemanager.rmcontainer.RMContainerImpl: container_1376080735992_0006_01_000031 Container Transitioned from NEW to ALLOCATED
2013-08-09 20:53:31,084 INFO org.apache.hadoop.yarn.server.resourcemanager.RMAuditLogger: USER=ubuntu	OPERATION=AM Allocated Container	TARGET=SchedulerApp	RESULT=SUCCESS	APPID=application_1376080735992_0006	CONTAINERID=container_1376080735992_0006_01_000031
2013-08-09 20:53:31,084 INFO org.apache.hadoop.yarn.server.resourcemanager.scheduler.common.fica.FiCaSchedulerNode: Assigned container container_1376080735992_0006_01_000031 of capacity <memory:1024, vCores:1> on host hadoop-210-6:41207, which currently has 5 containers, <memory:6144, vCores:5> used and <memory:2048, vCores:11> available
2013-08-09 20:53:31,085 INFO org.apache.hadoop.yarn.server.resourcemanager.scheduler.capacity.LeafQueue: assignedContainer application=application_1376080735992_0006 container=Container: [ContainerId: container_1376080735992_0006_01_000031, NodeId: hadoop-210-6:41207, NodeHttpAddress: hadoop-210-6:8042, Resource: <memory:1024, vCores:1>, Priority: 20, State: NEW, Token: null, Status: container_id {, app_attempt_id {, application_id {, id: 6, cluster_timestamp: 1376080735992, }, attemptId: 1, }, id: 31, }, state: C_NEW, ] containerId=container_1376080735992_0006_01_000031 queue=default: capacity=1.0, absoluteCapacity=1.0, usedResources=<memory:39936, vCores:34>usedCapacity=0.8125, absoluteUsedCapacity=0.8125, numApps=5, numContainers=34 usedCapacity=0.8125 absoluteUsedCapacity=0.8125 used=<memory:39936, vCores:34> cluster=<memory:49152, vCores:96>
2013-08-09 20:53:31,085 INFO org.apache.hadoop.yarn.server.resourcemanager.scheduler.capacity.ParentQueue: Re-sorting queues since queue: root.default stats: default: capacity=1.0, absoluteCapacity=1.0, usedResources=<memory:40960, vCores:35>usedCapacity=0.8333333, absoluteUsedCapacity=0.8333333, numApps=5, numContainers=35
2013-08-09 20:53:31,086 INFO org.apache.hadoop.yarn.server.resourcemanager.scheduler.capacity.ParentQueue: assignedContainer queue=root usedCapacity=0.8333333 absoluteUsedCapacity=0.8333333 used=<memory:40960, vCores:35> cluster=<memory:49152, vCores:96>
2013-08-09 20:53:31,086 INFO org.apache.hadoop.yarn.server.resourcemanager.rmcontainer.RMContainerImpl: container_1376080735992_0006_01_000032 Container Transitioned from NEW to ALLOCATED
2013-08-09 20:53:31,086 INFO org.apache.hadoop.yarn.server.resourcemanager.RMAuditLogger: USER=ubuntu	OPERATION=AM Allocated Container	TARGET=SchedulerApp	RESULT=SUCCESS	APPID=application_1376080735992_0006	CONTAINERID=container_1376080735992_0006_01_000032
2013-08-09 20:53:31,086 INFO org.apache.hadoop.yarn.server.resourcemanager.scheduler.common.fica.FiCaSchedulerNode: Assigned container container_1376080735992_0006_01_000032 of capacity <memory:1024, vCores:1> on host hadoop-210-6:41207, which currently has 6 containers, <memory:7168, vCores:6> used and <memory:1024, vCores:10> available
2013-08-09 20:53:31,087 INFO org.apache.hadoop.yarn.server.resourcemanager.scheduler.capacity.LeafQueue: assignedContainer application=application_1376080735992_0006 container=Container: [ContainerId: container_1376080735992_0006_01_000032, NodeId: hadoop-210-6:41207, NodeHttpAddress: hadoop-210-6:8042, Resource: <memory:1024, vCores:1>, Priority: 20, State: NEW, Token: null, Status: container_id {, app_attempt_id {, application_id {, id: 6, cluster_timestamp: 1376080735992, }, attemptId: 1, }, id: 32, }, state: C_NEW, ] containerId=container_1376080735992_0006_01_000032 queue=default: capacity=1.0, absoluteCapacity=1.0, usedResources=<memory:40960, vCores:35>usedCapacity=0.8333333, absoluteUsedCapacity=0.8333333, numApps=5, numContainers=35 usedCapacity=0.8333333 absoluteUsedCapacity=0.8333333 used=<memory:40960, vCores:35> cluster=<memory:49152, vCores:96>
2013-08-09 20:53:31,088 INFO org.apache.hadoop.yarn.server.resourcemanager.scheduler.capacity.ParentQueue: Re-sorting queues since queue: root.default stats: default: capacity=1.0, absoluteCapacity=1.0, usedResources=<memory:41984, vCores:36>usedCapacity=0.8541667, absoluteUsedCapacity=0.8541667, numApps=5, numContainers=36
2013-08-09 20:53:31,088 INFO org.apache.hadoop.yarn.server.resourcemanager.scheduler.capacity.ParentQueue: assignedContainer queue=root usedCapacity=0.8541667 absoluteUsedCapacity=0.8541667 used=<memory:41984, vCores:36> cluster=<memory:49152, vCores:96>
2013-08-09 20:53:31,088 INFO org.apache.hadoop.yarn.server.resourcemanager.rmcontainer.RMContainerImpl: container_1376080735992_0006_01_000033 Container Transitioned from NEW to ALLOCATED
2013-08-09 20:53:31,089 INFO org.apache.hadoop.yarn.server.resourcemanager.RMAuditLogger: USER=ubuntu	OPERATION=AM Allocated Container	TARGET=SchedulerApp	RESULT=SUCCESS	APPID=application_1376080735992_0006	CONTAINERID=container_1376080735992_0006_01_000033
2013-08-09 20:53:31,089 INFO org.apache.hadoop.yarn.server.resourcemanager.scheduler.common.fica.FiCaSchedulerNode: Assigned container container_1376080735992_0006_01_000033 of capacity <memory:1024, vCores:1> on host hadoop-210-6:41207, which currently has 7 containers, <memory:8192, vCores:7> used and <memory:0, vCores:9> available
2013-08-09 20:53:31,090 INFO org.apache.hadoop.yarn.server.resourcemanager.scheduler.capacity.LeafQueue: assignedContainer application=application_1376080735992_0006 container=Container: [ContainerId: container_1376080735992_0006_01_000033, NodeId: hadoop-210-6:41207, NodeHttpAddress: hadoop-210-6:8042, Resource: <memory:1024, vCores:1>, Priority: 20, State: NEW, Token: null, Status: container_id {, app_attempt_id {, application_id {, id: 6, cluster_timestamp: 1376080735992, }, attemptId: 1, }, id: 33, }, state: C_NEW, ] containerId=container_1376080735992_0006_01_000033 queue=default: capacity=1.0, absoluteCapacity=1.0, usedResources=<memory:41984, vCores:36>usedCapacity=0.8541667, absoluteUsedCapacity=0.8541667, numApps=5, numContainers=36 usedCapacity=0.8541667 absoluteUsedCapacity=0.8541667 used=<memory:41984, vCores:36> cluster=<memory:49152, vCores:96>
2013-08-09 20:53:31,090 INFO org.apache.hadoop.yarn.server.resourcemanager.scheduler.capacity.ParentQueue: Re-sorting queues since queue: root.default stats: default: capacity=1.0, absoluteCapacity=1.0, usedResources=<memory:43008, vCores:37>usedCapacity=0.875, absoluteUsedCapacity=0.875, numApps=5, numContainers=37
2013-08-09 20:53:31,090 INFO org.apache.hadoop.yarn.server.resourcemanager.scheduler.capacity.ParentQueue: assignedContainer queue=root usedCapacity=0.875 absoluteUsedCapacity=0.875 used=<memory:43008, vCores:37> cluster=<memory:49152, vCores:96>
2013-08-09 20:53:31,422 INFO org.apache.hadoop.yarn.server.resourcemanager.rmcontainer.RMContainerImpl: container_1376080735992_0006_01_000034 Container Transitioned from NEW to ALLOCATED
2013-08-09 20:53:31,422 INFO org.apache.hadoop.yarn.server.resourcemanager.RMAuditLogger: USER=ubuntu	OPERATION=AM Allocated Container	TARGET=SchedulerApp	RESULT=SUCCESS	APPID=application_1376080735992_0006	CONTAINERID=container_1376080735992_0006_01_000034
2013-08-09 20:53:31,422 INFO org.apache.hadoop.yarn.server.resourcemanager.scheduler.common.fica.FiCaSchedulerNode: Assigned container container_1376080735992_0006_01_000034 of capacity <memory:1024, vCores:1> on host hadoop-210-7:35638, which currently has 2 containers, <memory:3072, vCores:2> used and <memory:5120, vCores:14> available
2013-08-09 20:53:31,424 INFO org.apache.hadoop.yarn.server.resourcemanager.scheduler.capacity.LeafQueue: assignedContainer application=application_1376080735992_0006 container=Container: [ContainerId: container_1376080735992_0006_01_000034, NodeId: hadoop-210-7:35638, NodeHttpAddress: hadoop-210-7:8042, Resource: <memory:1024, vCores:1>, Priority: 20, State: NEW, Token: null, Status: container_id {, app_attempt_id {, application_id {, id: 6, cluster_timestamp: 1376080735992, }, attemptId: 1, }, id: 34, }, state: C_NEW, ] containerId=container_1376080735992_0006_01_000034 queue=default: capacity=1.0, absoluteCapacity=1.0, usedResources=<memory:43008, vCores:37>usedCapacity=0.875, absoluteUsedCapacity=0.875, numApps=5, numContainers=37 usedCapacity=0.875 absoluteUsedCapacity=0.875 used=<memory:43008, vCores:37> cluster=<memory:49152, vCores:96>
2013-08-09 20:53:31,424 INFO org.apache.hadoop.yarn.server.resourcemanager.scheduler.capacity.ParentQueue: Re-sorting queues since queue: root.default stats: default: capacity=1.0, absoluteCapacity=1.0, usedResources=<memory:44032, vCores:38>usedCapacity=0.8958333, absoluteUsedCapacity=0.8958333, numApps=5, numContainers=38
2013-08-09 20:53:31,424 INFO org.apache.hadoop.yarn.server.resourcemanager.scheduler.capacity.ParentQueue: assignedContainer queue=root usedCapacity=0.8958333 absoluteUsedCapacity=0.8958333 used=<memory:44032, vCores:38> cluster=<memory:49152, vCores:96>
2013-08-09 20:53:31,425 INFO org.apache.hadoop.yarn.server.resourcemanager.rmcontainer.RMContainerImpl: container_1376080735992_0006_01_000035 Container Transitioned from NEW to ALLOCATED
2013-08-09 20:53:31,425 INFO org.apache.hadoop.yarn.server.resourcemanager.RMAuditLogger: USER=ubuntu	OPERATION=AM Allocated Container	TARGET=SchedulerApp	RESULT=SUCCESS	APPID=application_1376080735992_0006	CONTAINERID=container_1376080735992_0006_01_000035
2013-08-09 20:53:31,425 INFO org.apache.hadoop.yarn.server.resourcemanager.scheduler.common.fica.FiCaSchedulerNode: Assigned container container_1376080735992_0006_01_000035 of capacity <memory:1024, vCores:1> on host hadoop-210-7:35638, which currently has 3 containers, <memory:4096, vCores:3> used and <memory:4096, vCores:13> available
2013-08-09 20:53:31,426 INFO org.apache.hadoop.yarn.server.resourcemanager.scheduler.capacity.LeafQueue: assignedContainer application=application_1376080735992_0006 container=Container: [ContainerId: container_1376080735992_0006_01_000035, NodeId: hadoop-210-7:35638, NodeHttpAddress: hadoop-210-7:8042, Resource: <memory:1024, vCores:1>, Priority: 20, State: NEW, Token: null, Status: container_id {, app_attempt_id {, application_id {, id: 6, cluster_timestamp: 1376080735992, }, attemptId: 1, }, id: 35, }, state: C_NEW, ] containerId=container_1376080735992_0006_01_000035 queue=default: capacity=1.0, absoluteCapacity=1.0, usedResources=<memory:44032, vCores:38>usedCapacity=0.8958333, absoluteUsedCapacity=0.8958333, numApps=5, numContainers=38 usedCapacity=0.8958333 absoluteUsedCapacity=0.8958333 used=<memory:44032, vCores:38> cluster=<memory:49152, vCores:96>
2013-08-09 20:53:31,426 INFO org.apache.hadoop.yarn.server.resourcemanager.scheduler.capacity.ParentQueue: Re-sorting queues since queue: root.default stats: default: capacity=1.0, absoluteCapacity=1.0, usedResources=<memory:45056, vCores:39>usedCapacity=0.9166667, absoluteUsedCapacity=0.9166667, numApps=5, numContainers=39
2013-08-09 20:53:31,426 INFO org.apache.hadoop.yarn.server.resourcemanager.scheduler.capacity.ParentQueue: assignedContainer queue=root usedCapacity=0.9166667 absoluteUsedCapacity=0.9166667 used=<memory:45056, vCores:39> cluster=<memory:49152, vCores:96>
2013-08-09 20:53:31,427 INFO org.apache.hadoop.yarn.server.resourcemanager.rmcontainer.RMContainerImpl: container_1376080735992_0006_01_000036 Container Transitioned from NEW to ALLOCATED
2013-08-09 20:53:31,427 INFO org.apache.hadoop.yarn.server.resourcemanager.RMAuditLogger: USER=ubuntu	OPERATION=AM Allocated Container	TARGET=SchedulerApp	RESULT=SUCCESS	APPID=application_1376080735992_0006	CONTAINERID=container_1376080735992_0006_01_000036
2013-08-09 20:53:31,427 INFO org.apache.hadoop.yarn.server.resourcemanager.scheduler.common.fica.FiCaSchedulerNode: Assigned container container_1376080735992_0006_01_000036 of capacity <memory:1024, vCores:1> on host hadoop-210-7:35638, which currently has 4 containers, <memory:5120, vCores:4> used and <memory:3072, vCores:12> available
2013-08-09 20:53:31,428 INFO org.apache.hadoop.yarn.server.resourcemanager.scheduler.capacity.LeafQueue: assignedContainer application=application_1376080735992_0006 container=Container: [ContainerId: container_1376080735992_0006_01_000036, NodeId: hadoop-210-7:35638, NodeHttpAddress: hadoop-210-7:8042, Resource: <memory:1024, vCores:1>, Priority: 20, State: NEW, Token: null, Status: container_id {, app_attempt_id {, application_id {, id: 6, cluster_timestamp: 1376080735992, }, attemptId: 1, }, id: 36, }, state: C_NEW, ] containerId=container_1376080735992_0006_01_000036 queue=default: capacity=1.0, absoluteCapacity=1.0, usedResources=<memory:45056, vCores:39>usedCapacity=0.9166667, absoluteUsedCapacity=0.9166667, numApps=5, numContainers=39 usedCapacity=0.9166667 absoluteUsedCapacity=0.9166667 used=<memory:45056, vCores:39> cluster=<memory:49152, vCores:96>
2013-08-09 20:53:31,428 INFO org.apache.hadoop.yarn.server.resourcemanager.scheduler.capacity.ParentQueue: Re-sorting queues since queue: root.default stats: default: capacity=1.0, absoluteCapacity=1.0, usedResources=<memory:46080, vCores:40>usedCapacity=0.9375, absoluteUsedCapacity=0.9375, numApps=5, numContainers=40
2013-08-09 20:53:31,429 INFO org.apache.hadoop.yarn.server.resourcemanager.scheduler.capacity.ParentQueue: assignedContainer queue=root usedCapacity=0.9375 absoluteUsedCapacity=0.9375 used=<memory:46080, vCores:40> cluster=<memory:49152, vCores:96>
2013-08-09 20:53:31,429 INFO org.apache.hadoop.yarn.server.resourcemanager.rmcontainer.RMContainerImpl: container_1376080735992_0006_01_000037 Container Transitioned from NEW to ALLOCATED
2013-08-09 20:53:31,429 INFO org.apache.hadoop.yarn.server.resourcemanager.RMAuditLogger: USER=ubuntu	OPERATION=AM Allocated Container	TARGET=SchedulerApp	RESULT=SUCCESS	APPID=application_1376080735992_0006	CONTAINERID=container_1376080735992_0006_01_000037
2013-08-09 20:53:31,429 INFO org.apache.hadoop.yarn.server.resourcemanager.scheduler.common.fica.FiCaSchedulerNode: Assigned container container_1376080735992_0006_01_000037 of capacity <memory:1024, vCores:1> on host hadoop-210-7:35638, which currently has 5 containers, <memory:6144, vCores:5> used and <memory:2048, vCores:11> available
2013-08-09 20:53:31,430 INFO org.apache.hadoop.yarn.server.resourcemanager.scheduler.capacity.LeafQueue: assignedContainer application=application_1376080735992_0006 container=Container: [ContainerId: container_1376080735992_0006_01_000037, NodeId: hadoop-210-7:35638, NodeHttpAddress: hadoop-210-7:8042, Resource: <memory:1024, vCores:1>, Priority: 20, State: NEW, Token: null, Status: container_id {, app_attempt_id {, application_id {, id: 6, cluster_timestamp: 1376080735992, }, attemptId: 1, }, id: 37, }, state: C_NEW, ] containerId=container_1376080735992_0006_01_000037 queue=default: capacity=1.0, absoluteCapacity=1.0, usedResources=<memory:46080, vCores:40>usedCapacity=0.9375, absoluteUsedCapacity=0.9375, numApps=5, numContainers=40 usedCapacity=0.9375 absoluteUsedCapacity=0.9375 used=<memory:46080, vCores:40> cluster=<memory:49152, vCores:96>
2013-08-09 20:53:31,431 INFO org.apache.hadoop.yarn.server.resourcemanager.scheduler.capacity.ParentQueue: Re-sorting queues since queue: root.default stats: default: capacity=1.0, absoluteCapacity=1.0, usedResources=<memory:47104, vCores:41>usedCapacity=0.9583333, absoluteUsedCapacity=0.9583333, numApps=5, numContainers=41
2013-08-09 20:53:31,431 INFO org.apache.hadoop.yarn.server.resourcemanager.scheduler.capacity.ParentQueue: assignedContainer queue=root usedCapacity=0.9583333 absoluteUsedCapacity=0.9583333 used=<memory:47104, vCores:41> cluster=<memory:49152, vCores:96>
2013-08-09 20:53:31,431 INFO org.apache.hadoop.yarn.server.resourcemanager.rmcontainer.RMContainerImpl: container_1376080735992_0006_01_000038 Container Transitioned from NEW to ALLOCATED
2013-08-09 20:53:31,431 INFO org.apache.hadoop.yarn.server.resourcemanager.RMAuditLogger: USER=ubuntu	OPERATION=AM Allocated Container	TARGET=SchedulerApp	RESULT=SUCCESS	APPID=application_1376080735992_0006	CONTAINERID=container_1376080735992_0006_01_000038
2013-08-09 20:53:31,432 INFO org.apache.hadoop.yarn.server.resourcemanager.scheduler.common.fica.FiCaSchedulerNode: Assigned container container_1376080735992_0006_01_000038 of capacity <memory:1024, vCores:1> on host hadoop-210-7:35638, which currently has 6 containers, <memory:7168, vCores:6> used and <memory:1024, vCores:10> available
2013-08-09 20:53:31,433 INFO org.apache.hadoop.yarn.server.resourcemanager.scheduler.capacity.LeafQueue: assignedContainer application=application_1376080735992_0006 container=Container: [ContainerId: container_1376080735992_0006_01_000038, NodeId: hadoop-210-7:35638, NodeHttpAddress: hadoop-210-7:8042, Resource: <memory:1024, vCores:1>, Priority: 20, State: NEW, Token: null, Status: container_id {, app_attempt_id {, application_id {, id: 6, cluster_timestamp: 1376080735992, }, attemptId: 1, }, id: 38, }, state: C_NEW, ] containerId=container_1376080735992_0006_01_000038 queue=default: capacity=1.0, absoluteCapacity=1.0, usedResources=<memory:47104, vCores:41>usedCapacity=0.9583333, absoluteUsedCapacity=0.9583333, numApps=5, numContainers=41 usedCapacity=0.9583333 absoluteUsedCapacity=0.9583333 used=<memory:47104, vCores:41> cluster=<memory:49152, vCores:96>
2013-08-09 20:53:31,433 INFO org.apache.hadoop.yarn.server.resourcemanager.scheduler.capacity.ParentQueue: Re-sorting queues since queue: root.default stats: default: capacity=1.0, absoluteCapacity=1.0, usedResources=<memory:48128, vCores:42>usedCapacity=0.9791667, absoluteUsedCapacity=0.9791667, numApps=5, numContainers=42
2013-08-09 20:53:31,433 INFO org.apache.hadoop.yarn.server.resourcemanager.scheduler.capacity.ParentQueue: assignedContainer queue=root usedCapacity=0.9791667 absoluteUsedCapacity=0.9791667 used=<memory:48128, vCores:42> cluster=<memory:49152, vCores:96>
2013-08-09 20:53:31,434 INFO org.apache.hadoop.yarn.server.resourcemanager.rmcontainer.RMContainerImpl: container_1376080735992_0006_01_000039 Container Transitioned from NEW to ALLOCATED
2013-08-09 20:53:31,434 INFO org.apache.hadoop.yarn.server.resourcemanager.RMAuditLogger: USER=ubuntu	OPERATION=AM Allocated Container	TARGET=SchedulerApp	RESULT=SUCCESS	APPID=application_1376080735992_0006	CONTAINERID=container_1376080735992_0006_01_000039
2013-08-09 20:53:31,434 INFO org.apache.hadoop.yarn.server.resourcemanager.scheduler.common.fica.FiCaSchedulerNode: Assigned container container_1376080735992_0006_01_000039 of capacity <memory:1024, vCores:1> on host hadoop-210-7:35638, which currently has 7 containers, <memory:8192, vCores:7> used and <memory:0, vCores:9> available
2013-08-09 20:53:31,435 INFO org.apache.hadoop.yarn.server.resourcemanager.scheduler.capacity.LeafQueue: assignedContainer application=application_1376080735992_0006 container=Container: [ContainerId: container_1376080735992_0006_01_000039, NodeId: hadoop-210-7:35638, NodeHttpAddress: hadoop-210-7:8042, Resource: <memory:1024, vCores:1>, Priority: 20, State: NEW, Token: null, Status: container_id {, app_attempt_id {, application_id {, id: 6, cluster_timestamp: 1376080735992, }, attemptId: 1, }, id: 39, }, state: C_NEW, ] containerId=container_1376080735992_0006_01_000039 queue=default: capacity=1.0, absoluteCapacity=1.0, usedResources=<memory:48128, vCores:42>usedCapacity=0.9791667, absoluteUsedCapacity=0.9791667, numApps=5, numContainers=42 usedCapacity=0.9791667 absoluteUsedCapacity=0.9791667 used=<memory:48128, vCores:42> cluster=<memory:49152, vCores:96>
2013-08-09 20:53:31,435 INFO org.apache.hadoop.yarn.server.resourcemanager.scheduler.capacity.ParentQueue: Re-sorting queues since queue: root.default stats: default: capacity=1.0, absoluteCapacity=1.0, usedResources=<memory:49152, vCores:43>usedCapacity=1.0, absoluteUsedCapacity=1.0, numApps=5, numContainers=43
2013-08-09 20:53:31,435 INFO org.apache.hadoop.yarn.server.resourcemanager.scheduler.capacity.ParentQueue: assignedContainer queue=root usedCapacity=1.0 absoluteUsedCapacity=1.0 used=<memory:49152, vCores:43> cluster=<memory:49152, vCores:96>
2013-08-09 20:53:31,626 INFO org.apache.hadoop.yarn.server.resourcemanager.rmcontainer.RMContainerImpl: container_1376080735992_0006_01_000002 Container Transitioned from ALLOCATED to ACQUIRED
2013-08-09 20:53:31,628 INFO org.apache.hadoop.yarn.server.resourcemanager.rmcontainer.RMContainerImpl: container_1376080735992_0006_01_000003 Container Transitioned from ALLOCATED to ACQUIRED
2013-08-09 20:53:31,629 INFO org.apache.hadoop.yarn.server.resourcemanager.rmcontainer.RMContainerImpl: container_1376080735992_0006_01_000004 Container Transitioned from ALLOCATED to ACQUIRED
2013-08-09 20:53:31,630 INFO org.apache.hadoop.yarn.server.resourcemanager.rmcontainer.RMContainerImpl: container_1376080735992_0006_01_000005 Container Transitioned from ALLOCATED to ACQUIRED
2013-08-09 20:53:31,631 INFO org.apache.hadoop.yarn.server.resourcemanager.rmcontainer.RMContainerImpl: container_1376080735992_0006_01_000006 Container Transitioned from ALLOCATED to ACQUIRED
2013-08-09 20:53:31,632 INFO org.apache.hadoop.yarn.server.resourcemanager.rmcontainer.RMContainerImpl: container_1376080735992_0006_01_000007 Container Transitioned from ALLOCATED to ACQUIRED
2013-08-09 20:53:31,633 INFO org.apache.hadoop.yarn.server.resourcemanager.rmcontainer.RMContainerImpl: container_1376080735992_0006_01_000008 Container Transitioned from ALLOCATED to ACQUIRED
2013-08-09 20:53:31,634 INFO org.apache.hadoop.yarn.server.resourcemanager.rmcontainer.RMContainerImpl: container_1376080735992_0006_01_000009 Container Transitioned from ALLOCATED to ACQUIRED
2013-08-09 20:53:31,635 INFO org.apache.hadoop.yarn.server.resourcemanager.rmcontainer.RMContainerImpl: container_1376080735992_0006_01_000010 Container Transitioned from ALLOCATED to ACQUIRED
2013-08-09 20:53:31,637 INFO org.apache.hadoop.yarn.server.resourcemanager.rmcontainer.RMContainerImpl: container_1376080735992_0006_01_000011 Container Transitioned from ALLOCATED to ACQUIRED
2013-08-09 20:53:31,637 INFO org.apache.hadoop.yarn.server.resourcemanager.rmcontainer.RMContainerImpl: container_1376080735992_0006_01_000012 Container Transitioned from ALLOCATED to ACQUIRED
2013-08-09 20:53:31,638 INFO org.apache.hadoop.yarn.server.resourcemanager.rmcontainer.RMContainerImpl: container_1376080735992_0006_01_000013 Container Transitioned from ALLOCATED to ACQUIRED
2013-08-09 20:53:31,638 INFO org.apache.hadoop.yarn.server.resourcemanager.rmcontainer.RMContainerImpl: container_1376080735992_0006_01_000014 Container Transitioned from ALLOCATED to ACQUIRED
2013-08-09 20:53:31,638 INFO org.apache.hadoop.yarn.server.resourcemanager.rmcontainer.RMContainerImpl: container_1376080735992_0006_01_000015 Container Transitioned from ALLOCATED to ACQUIRED
2013-08-09 20:53:31,638 INFO org.apache.hadoop.yarn.server.resourcemanager.rmcontainer.RMContainerImpl: container_1376080735992_0006_01_000016 Container Transitioned from ALLOCATED to ACQUIRED
2013-08-09 20:53:31,638 INFO org.apache.hadoop.yarn.server.resourcemanager.rmcontainer.RMContainerImpl: container_1376080735992_0006_01_000017 Container Transitioned from ALLOCATED to ACQUIRED
2013-08-09 20:53:31,639 INFO org.apache.hadoop.yarn.server.resourcemanager.rmcontainer.RMContainerImpl: container_1376080735992_0006_01_000018 Container Transitioned from ALLOCATED to ACQUIRED
2013-08-09 20:53:31,639 INFO org.apache.hadoop.yarn.server.resourcemanager.rmcontainer.RMContainerImpl: container_1376080735992_0006_01_000019 Container Transitioned from ALLOCATED to ACQUIRED
2013-08-09 20:53:31,639 INFO org.apache.hadoop.yarn.server.resourcemanager.rmcontainer.RMContainerImpl: container_1376080735992_0006_01_000020 Container Transitioned from ALLOCATED to ACQUIRED
2013-08-09 20:53:31,639 INFO org.apache.hadoop.yarn.server.resourcemanager.rmcontainer.RMContainerImpl: container_1376080735992_0006_01_000021 Container Transitioned from ALLOCATED to ACQUIRED
2013-08-09 20:53:31,639 INFO org.apache.hadoop.yarn.server.resourcemanager.rmcontainer.RMContainerImpl: container_1376080735992_0006_01_000022 Container Transitioned from ALLOCATED to ACQUIRED
2013-08-09 20:53:31,640 INFO org.apache.hadoop.yarn.server.resourcemanager.rmcontainer.RMContainerImpl: container_1376080735992_0006_01_000023 Container Transitioned from ALLOCATED to ACQUIRED
2013-08-09 20:53:31,640 INFO org.apache.hadoop.yarn.server.resourcemanager.rmcontainer.RMContainerImpl: container_1376080735992_0006_01_000024 Container Transitioned from ALLOCATED to ACQUIRED
2013-08-09 20:53:31,640 INFO org.apache.hadoop.yarn.server.resourcemanager.rmcontainer.RMContainerImpl: container_1376080735992_0006_01_000025 Container Transitioned from ALLOCATED to ACQUIRED
2013-08-09 20:53:31,640 INFO org.apache.hadoop.yarn.server.resourcemanager.rmcontainer.RMContainerImpl: container_1376080735992_0006_01_000026 Container Transitioned from ALLOCATED to ACQUIRED
2013-08-09 20:53:31,640 INFO org.apache.hadoop.yarn.server.resourcemanager.rmcontainer.RMContainerImpl: container_1376080735992_0006_01_000027 Container Transitioned from ALLOCATED to ACQUIRED
2013-08-09 20:53:31,641 INFO org.apache.hadoop.yarn.server.resourcemanager.rmcontainer.RMContainerImpl: container_1376080735992_0006_01_000028 Container Transitioned from ALLOCATED to ACQUIRED
2013-08-09 20:53:31,641 INFO org.apache.hadoop.yarn.server.resourcemanager.rmcontainer.RMContainerImpl: container_1376080735992_0006_01_000029 Container Transitioned from ALLOCATED to ACQUIRED
2013-08-09 20:53:31,641 INFO org.apache.hadoop.yarn.server.resourcemanager.rmcontainer.RMContainerImpl: container_1376080735992_0006_01_000030 Container Transitioned from ALLOCATED to ACQUIRED
2013-08-09 20:53:31,641 INFO org.apache.hadoop.yarn.server.resourcemanager.rmcontainer.RMContainerImpl: container_1376080735992_0006_01_000031 Container Transitioned from ALLOCATED to ACQUIRED
2013-08-09 20:53:31,641 INFO org.apache.hadoop.yarn.server.resourcemanager.rmcontainer.RMContainerImpl: container_1376080735992_0006_01_000032 Container Transitioned from ALLOCATED to ACQUIRED
2013-08-09 20:53:31,642 INFO org.apache.hadoop.yarn.server.resourcemanager.rmcontainer.RMContainerImpl: container_1376080735992_0006_01_000033 Container Transitioned from ALLOCATED to ACQUIRED
2013-08-09 20:53:31,642 INFO org.apache.hadoop.yarn.server.resourcemanager.rmcontainer.RMContainerImpl: container_1376080735992_0006_01_000034 Container Transitioned from ALLOCATED to ACQUIRED
2013-08-09 20:53:31,642 INFO org.apache.hadoop.yarn.server.resourcemanager.rmcontainer.RMContainerImpl: container_1376080735992_0006_01_000035 Container Transitioned from ALLOCATED to ACQUIRED
2013-08-09 20:53:31,642 INFO org.apache.hadoop.yarn.server.resourcemanager.rmcontainer.RMContainerImpl: container_1376080735992_0006_01_000036 Container Transitioned from ALLOCATED to ACQUIRED
2013-08-09 20:53:31,642 INFO org.apache.hadoop.yarn.server.resourcemanager.rmcontainer.RMContainerImpl: container_1376080735992_0006_01_000037 Container Transitioned from ALLOCATED to ACQUIRED
2013-08-09 20:53:31,643 INFO org.apache.hadoop.yarn.server.resourcemanager.rmcontainer.RMContainerImpl: container_1376080735992_0006_01_000038 Container Transitioned from ALLOCATED to ACQUIRED
2013-08-09 20:53:31,643 INFO org.apache.hadoop.yarn.server.resourcemanager.rmcontainer.RMContainerImpl: container_1376080735992_0006_01_000039 Container Transitioned from ALLOCATED to ACQUIRED
2013-08-09 20:53:32,446 INFO org.apache.hadoop.yarn.server.resourcemanager.rmcontainer.RMContainerImpl: container_1376080735992_0006_01_000034 Container Transitioned from ACQUIRED to RUNNING
2013-08-09 20:53:32,447 INFO org.apache.hadoop.yarn.server.resourcemanager.rmcontainer.RMContainerImpl: container_1376080735992_0006_01_000035 Container Transitioned from ACQUIRED to RUNNING
2013-08-09 20:53:32,449 INFO org.apache.hadoop.yarn.server.resourcemanager.rmcontainer.RMContainerImpl: container_1376080735992_0006_01_000036 Container Transitioned from ACQUIRED to RUNNING
2013-08-09 20:53:32,450 INFO org.apache.hadoop.yarn.server.resourcemanager.rmcontainer.RMContainerImpl: container_1376080735992_0006_01_000037 Container Transitioned from ACQUIRED to RUNNING
2013-08-09 20:53:32,451 INFO org.apache.hadoop.yarn.server.resourcemanager.rmcontainer.RMContainerImpl: container_1376080735992_0006_01_000038 Container Transitioned from ACQUIRED to RUNNING
2013-08-09 20:53:32,452 INFO org.apache.hadoop.yarn.server.resourcemanager.rmcontainer.RMContainerImpl: container_1376080735992_0006_01_000039 Container Transitioned from ACQUIRED to RUNNING
2013-08-09 20:53:32,679 INFO org.apache.hadoop.yarn.server.resourcemanager.rmcontainer.RMContainerImpl: container_1376080735992_0006_01_000002 Container Transitioned from ACQUIRED to RUNNING
2013-08-09 20:53:32,680 INFO org.apache.hadoop.yarn.server.resourcemanager.rmcontainer.RMContainerImpl: container_1376080735992_0006_01_000003 Container Transitioned from ACQUIRED to RUNNING
2013-08-09 20:53:32,680 INFO org.apache.hadoop.yarn.server.resourcemanager.rmcontainer.RMContainerImpl: container_1376080735992_0006_01_000004 Container Transitioned from ACQUIRED to RUNNING
2013-08-09 20:53:32,681 INFO org.apache.hadoop.yarn.server.resourcemanager.rmcontainer.RMContainerImpl: container_1376080735992_0006_01_000005 Container Transitioned from ACQUIRED to RUNNING
2013-08-09 20:53:32,682 INFO org.apache.hadoop.yarn.server.resourcemanager.rmcontainer.RMContainerImpl: container_1376080735992_0006_01_000006 Container Transitioned from ACQUIRED to RUNNING
2013-08-09 20:53:32,683 INFO org.apache.hadoop.yarn.server.resourcemanager.rmcontainer.RMContainerImpl: container_1376080735992_0006_01_000007 Container Transitioned from ACQUIRED to RUNNING
2013-08-09 20:53:32,687 INFO org.apache.hadoop.yarn.server.resourcemanager.rmcontainer.RMContainerImpl: container_1376080735992_0006_01_000008 Container Transitioned from ACQUIRED to RUNNING
2013-08-09 20:53:32,688 INFO org.apache.hadoop.yarn.server.resourcemanager.rmcontainer.RMContainerImpl: container_1376080735992_0006_01_000009 Container Transitioned from ACQUIRED to RUNNING
2013-08-09 20:53:32,688 INFO org.apache.hadoop.yarn.server.resourcemanager.rmcontainer.RMContainerImpl: container_1376080735992_0006_01_000010 Container Transitioned from ACQUIRED to RUNNING
2013-08-09 20:53:32,689 INFO org.apache.hadoop.yarn.server.resourcemanager.rmcontainer.RMContainerImpl: container_1376080735992_0006_01_000011 Container Transitioned from ACQUIRED to RUNNING
2013-08-09 20:53:32,689 INFO org.apache.hadoop.yarn.server.resourcemanager.rmcontainer.RMContainerImpl: container_1376080735992_0006_01_000012 Container Transitioned from ACQUIRED to RUNNING
2013-08-09 20:53:32,690 INFO org.apache.hadoop.yarn.server.resourcemanager.rmcontainer.RMContainerImpl: container_1376080735992_0006_01_000013 Container Transitioned from ACQUIRED to RUNNING
2013-08-09 20:53:32,756 INFO org.apache.hadoop.yarn.server.resourcemanager.rmcontainer.RMContainerImpl: container_1376080735992_0006_01_000014 Container Transitioned from ACQUIRED to RUNNING
2013-08-09 20:53:32,757 INFO org.apache.hadoop.yarn.server.resourcemanager.rmcontainer.RMContainerImpl: container_1376080735992_0006_01_000015 Container Transitioned from ACQUIRED to RUNNING
2013-08-09 20:53:32,758 INFO org.apache.hadoop.yarn.server.resourcemanager.rmcontainer.RMContainerImpl: container_1376080735992_0006_01_000016 Container Transitioned from ACQUIRED to RUNNING
2013-08-09 20:53:32,758 INFO org.apache.hadoop.yarn.server.resourcemanager.rmcontainer.RMContainerImpl: container_1376080735992_0006_01_000017 Container Transitioned from ACQUIRED to RUNNING
2013-08-09 20:53:32,759 INFO org.apache.hadoop.yarn.server.resourcemanager.rmcontainer.RMContainerImpl: container_1376080735992_0006_01_000018 Container Transitioned from ACQUIRED to RUNNING
2013-08-09 20:53:32,760 INFO org.apache.hadoop.yarn.server.resourcemanager.rmcontainer.RMContainerImpl: container_1376080735992_0006_01_000019 Container Transitioned from ACQUIRED to RUNNING
2013-08-09 20:53:32,763 INFO org.apache.hadoop.yarn.server.resourcemanager.rmcontainer.RMContainerImpl: container_1376080735992_0006_01_000020 Container Transitioned from ACQUIRED to RUNNING
2013-08-09 20:53:32,763 INFO org.apache.hadoop.yarn.server.resourcemanager.rmcontainer.RMContainerImpl: container_1376080735992_0006_01_000021 Container Transitioned from ACQUIRED to RUNNING
2013-08-09 20:53:32,764 INFO org.apache.hadoop.yarn.server.resourcemanager.rmcontainer.RMContainerImpl: container_1376080735992_0006_01_000022 Container Transitioned from ACQUIRED to RUNNING
2013-08-09 20:53:32,765 INFO org.apache.hadoop.yarn.server.resourcemanager.rmcontainer.RMContainerImpl: container_1376080735992_0006_01_000023 Container Transitioned from ACQUIRED to RUNNING
2013-08-09 20:53:32,766 INFO org.apache.hadoop.yarn.server.resourcemanager.rmcontainer.RMContainerImpl: container_1376080735992_0006_01_000024 Container Transitioned from ACQUIRED to RUNNING
2013-08-09 20:53:32,767 INFO org.apache.hadoop.yarn.server.resourcemanager.rmcontainer.RMContainerImpl: container_1376080735992_0006_01_000025 Container Transitioned from ACQUIRED to RUNNING
2013-08-09 20:53:32,767 INFO org.apache.hadoop.yarn.server.resourcemanager.rmcontainer.RMContainerImpl: container_1376080735992_0006_01_000026 Container Transitioned from ACQUIRED to RUNNING
2013-08-09 20:53:32,767 INFO org.apache.hadoop.yarn.server.resourcemanager.rmcontainer.RMContainerImpl: container_1376080735992_0006_01_000027 Container Transitioned from ACQUIRED to RUNNING
2013-08-09 20:53:33,092 INFO org.apache.hadoop.yarn.server.resourcemanager.rmcontainer.RMContainerImpl: container_1376080735992_0006_01_000028 Container Transitioned from ACQUIRED to RUNNING
2013-08-09 20:53:33,092 INFO org.apache.hadoop.yarn.server.resourcemanager.rmcontainer.RMContainerImpl: container_1376080735992_0006_01_000029 Container Transitioned from ACQUIRED to RUNNING
2013-08-09 20:53:33,093 INFO org.apache.hadoop.yarn.server.resourcemanager.rmcontainer.RMContainerImpl: container_1376080735992_0006_01_000030 Container Transitioned from ACQUIRED to RUNNING
2013-08-09 20:53:33,093 INFO org.apache.hadoop.yarn.server.resourcemanager.rmcontainer.RMContainerImpl: container_1376080735992_0006_01_000031 Container Transitioned from ACQUIRED to RUNNING
2013-08-09 20:53:33,093 INFO org.apache.hadoop.yarn.server.resourcemanager.rmcontainer.RMContainerImpl: container_1376080735992_0006_01_000032 Container Transitioned from ACQUIRED to RUNNING
2013-08-09 20:53:33,093 INFO org.apache.hadoop.yarn.server.resourcemanager.rmcontainer.RMContainerImpl: container_1376080735992_0006_01_000033 Container Transitioned from ACQUIRED to RUNNING
2013-08-09 20:53:54,350 INFO org.apache.hadoop.yarn.server.resourcemanager.rmcontainer.RMContainerImpl: container_1376080735992_0006_01_000007 Container Transitioned from RUNNING to COMPLETED
2013-08-09 20:53:54,350 INFO org.apache.hadoop.yarn.server.resourcemanager.scheduler.common.fica.FiCaSchedulerApp: Completed container: container_1376080735992_0006_01_000007 in state: COMPLETED event:FINISHED
2013-08-09 20:53:54,350 INFO org.apache.hadoop.yarn.server.resourcemanager.RMAuditLogger: USER=ubuntu	OPERATION=AM Released Container	TARGET=SchedulerApp	RESULT=SUCCESS	APPID=application_1376080735992_0006	CONTAINERID=container_1376080735992_0006_01_000007
2013-08-09 20:53:54,350 INFO org.apache.hadoop.yarn.server.resourcemanager.scheduler.common.fica.FiCaSchedulerNode: Released container container_1376080735992_0006_01_000007 of capacity <memory:1024, vCores:1> on host hadoop-210-4:47596, which currently has 6 containers, <memory:7168, vCores:6> used and <memory:1024, vCores:10> available, release resources=true
2013-08-09 20:53:54,351 INFO org.apache.hadoop.yarn.server.resourcemanager.scheduler.capacity.LeafQueue: default used=<memory:48128, vCores:42> numContainers=42 user=ubuntu user-resources=<memory:48128, vCores:42>
2013-08-09 20:53:54,353 INFO org.apache.hadoop.yarn.server.resourcemanager.scheduler.capacity.LeafQueue: completedContainer container=Container: [ContainerId: container_1376080735992_0006_01_000007, NodeId: hadoop-210-4:47596, NodeHttpAddress: hadoop-210-4:8042, Resource: <memory:1024, vCores:1>, Priority: 20, State: NEW, Token: null, Status: container_id {, app_attempt_id {, application_id {, id: 6, cluster_timestamp: 1376080735992, }, attemptId: 1, }, id: 7, }, state: C_COMPLETE, diagnostics: "", exit_status: 0, ] resource=<memory:1024, vCores:1> queue=default: capacity=1.0, absoluteCapacity=1.0, usedResources=<memory:48128, vCores:42>usedCapacity=0.9791667, absoluteUsedCapacity=0.9791667, numApps=5, numContainers=42 usedCapacity=0.9791667 absoluteUsedCapacity=0.9791667 used=<memory:48128, vCores:42> cluster=<memory:49152, vCores:96>
2013-08-09 20:53:54,354 INFO org.apache.hadoop.yarn.server.resourcemanager.scheduler.capacity.ParentQueue: completedContainer queue=root usedCapacity=0.9791667 absoluteUsedCapacity=0.9791667 used=<memory:48128, vCores:42> cluster=<memory:49152, vCores:96>
2013-08-09 20:53:54,354 INFO org.apache.hadoop.yarn.server.resourcemanager.scheduler.capacity.CapacityScheduler: Application appattempt_1376080735992_0006_000001 released container container_1376080735992_0006_01_000007 on node: host: hadoop-210-4:47596 #containers=6 available=1024 used=7168 with event: FINISHED
2013-08-09 20:53:54,354 INFO org.apache.hadoop.yarn.server.resourcemanager.rmcontainer.RMContainerImpl: container_1376080735992_0006_01_000040 Container Transitioned from NEW to ALLOCATED
2013-08-09 20:53:54,355 INFO org.apache.hadoop.yarn.server.resourcemanager.RMAuditLogger: USER=ubuntu	OPERATION=AM Allocated Container	TARGET=SchedulerApp	RESULT=SUCCESS	APPID=application_1376080735992_0006	CONTAINERID=container_1376080735992_0006_01_000040
2013-08-09 20:53:54,355 INFO org.apache.hadoop.yarn.server.resourcemanager.scheduler.common.fica.FiCaSchedulerNode: Assigned container container_1376080735992_0006_01_000040 of capacity <memory:1024, vCores:1> on host hadoop-210-4:47596, which currently has 7 containers, <memory:8192, vCores:7> used and <memory:0, vCores:9> available
2013-08-09 20:53:54,356 INFO org.apache.hadoop.yarn.server.resourcemanager.scheduler.capacity.LeafQueue: assignedContainer application=application_1376080735992_0006 container=Container: [ContainerId: container_1376080735992_0006_01_000040, NodeId: hadoop-210-4:47596, NodeHttpAddress: hadoop-210-4:8042, Resource: <memory:1024, vCores:1>, Priority: 20, State: NEW, Token: null, Status: container_id {, app_attempt_id {, application_id {, id: 6, cluster_timestamp: 1376080735992, }, attemptId: 1, }, id: 40, }, state: C_NEW, ] containerId=container_1376080735992_0006_01_000040 queue=default: capacity=1.0, absoluteCapacity=1.0, usedResources=<memory:48128, vCores:42>usedCapacity=0.9791667, absoluteUsedCapacity=0.9791667, numApps=5, numContainers=42 usedCapacity=0.9791667 absoluteUsedCapacity=0.9791667 used=<memory:48128, vCores:42> cluster=<memory:49152, vCores:96>
2013-08-09 20:53:54,356 INFO org.apache.hadoop.yarn.server.resourcemanager.scheduler.capacity.ParentQueue: Re-sorting queues since queue: root.default stats: default: capacity=1.0, absoluteCapacity=1.0, usedResources=<memory:49152, vCores:43>usedCapacity=1.0, absoluteUsedCapacity=1.0, numApps=5, numContainers=43
2013-08-09 20:53:54,356 INFO org.apache.hadoop.yarn.server.resourcemanager.scheduler.capacity.ParentQueue: assignedContainer queue=root usedCapacity=1.0 absoluteUsedCapacity=1.0 used=<memory:49152, vCores:43> cluster=<memory:49152, vCores:96>
2013-08-09 20:53:54,934 INFO org.apache.hadoop.yarn.server.resourcemanager.rmcontainer.RMContainerImpl: container_1376080735992_0006_01_000003 Container Transitioned from RUNNING to COMPLETED
2013-08-09 20:53:54,935 INFO org.apache.hadoop.yarn.server.resourcemanager.scheduler.common.fica.FiCaSchedulerApp: Completed container: container_1376080735992_0006_01_000003 in state: COMPLETED event:FINISHED
2013-08-09 20:53:54,935 INFO org.apache.hadoop.yarn.server.resourcemanager.RMAuditLogger: USER=ubuntu	OPERATION=AM Released Container	TARGET=SchedulerApp	RESULT=SUCCESS	APPID=application_1376080735992_0006	CONTAINERID=container_1376080735992_0006_01_000003
2013-08-09 20:53:54,935 INFO org.apache.hadoop.yarn.server.resourcemanager.scheduler.common.fica.FiCaSchedulerNode: Released container container_1376080735992_0006_01_000003 of capacity <memory:1024, vCores:1> on host hadoop-210-4:47596, which currently has 6 containers, <memory:7168, vCores:6> used and <memory:1024, vCores:10> available, release resources=true
2013-08-09 20:53:54,935 INFO org.apache.hadoop.yarn.server.resourcemanager.scheduler.capacity.LeafQueue: default used=<memory:48128, vCores:42> numContainers=42 user=ubuntu user-resources=<memory:48128, vCores:42>
2013-08-09 20:53:54,936 INFO org.apache.hadoop.yarn.server.resourcemanager.scheduler.capacity.LeafQueue: completedContainer container=Container: [ContainerId: container_1376080735992_0006_01_000003, NodeId: hadoop-210-4:47596, NodeHttpAddress: hadoop-210-4:8042, Resource: <memory:1024, vCores:1>, Priority: 20, State: NEW, Token: null, Status: container_id {, app_attempt_id {, application_id {, id: 6, cluster_timestamp: 1376080735992, }, attemptId: 1, }, id: 3, }, state: C_COMPLETE, diagnostics: "Container killed by the ApplicationMaster.\n\n", exit_status: 143, ] resource=<memory:1024, vCores:1> queue=default: capacity=1.0, absoluteCapacity=1.0, usedResources=<memory:48128, vCores:42>usedCapacity=0.9791667, absoluteUsedCapacity=0.9791667, numApps=5, numContainers=42 usedCapacity=0.9791667 absoluteUsedCapacity=0.9791667 used=<memory:48128, vCores:42> cluster=<memory:49152, vCores:96>
2013-08-09 20:53:54,937 INFO org.apache.hadoop.yarn.server.resourcemanager.scheduler.capacity.ParentQueue: completedContainer queue=root usedCapacity=0.9791667 absoluteUsedCapacity=0.9791667 used=<memory:48128, vCores:42> cluster=<memory:49152, vCores:96>
2013-08-09 20:53:54,937 INFO org.apache.hadoop.yarn.server.resourcemanager.scheduler.capacity.CapacityScheduler: Application appattempt_1376080735992_0006_000001 released container container_1376080735992_0006_01_000003 on node: host: hadoop-210-4:47596 #containers=6 available=1024 used=7168 with event: FINISHED
2013-08-09 20:53:54,938 INFO org.apache.hadoop.yarn.server.resourcemanager.rmcontainer.RMContainerImpl: container_1376080735992_0006_01_000041 Container Transitioned from NEW to ALLOCATED
2013-08-09 20:53:54,938 INFO org.apache.hadoop.yarn.server.resourcemanager.RMAuditLogger: USER=ubuntu	OPERATION=AM Allocated Container	TARGET=SchedulerApp	RESULT=SUCCESS	APPID=application_1376080735992_0006	CONTAINERID=container_1376080735992_0006_01_000041
2013-08-09 20:53:54,938 INFO org.apache.hadoop.yarn.server.resourcemanager.scheduler.common.fica.FiCaSchedulerNode: Assigned container container_1376080735992_0006_01_000041 of capacity <memory:1024, vCores:1> on host hadoop-210-4:47596, which currently has 7 containers, <memory:8192, vCores:7> used and <memory:0, vCores:9> available
2013-08-09 20:53:54,939 INFO org.apache.hadoop.yarn.server.resourcemanager.scheduler.capacity.LeafQueue: assignedContainer application=application_1376080735992_0006 container=Container: [ContainerId: container_1376080735992_0006_01_000041, NodeId: hadoop-210-4:47596, NodeHttpAddress: hadoop-210-4:8042, Resource: <memory:1024, vCores:1>, Priority: 20, State: NEW, Token: null, Status: container_id {, app_attempt_id {, application_id {, id: 6, cluster_timestamp: 1376080735992, }, attemptId: 1, }, id: 41, }, state: C_NEW, ] containerId=container_1376080735992_0006_01_000041 queue=default: capacity=1.0, absoluteCapacity=1.0, usedResources=<memory:48128, vCores:42>usedCapacity=0.9791667, absoluteUsedCapacity=0.9791667, numApps=5, numContainers=42 usedCapacity=0.9791667 absoluteUsedCapacity=0.9791667 used=<memory:48128, vCores:42> cluster=<memory:49152, vCores:96>
2013-08-09 20:53:54,939 INFO org.apache.hadoop.yarn.server.resourcemanager.scheduler.capacity.ParentQueue: Re-sorting queues since queue: root.default stats: default: capacity=1.0, absoluteCapacity=1.0, usedResources=<memory:49152, vCores:43>usedCapacity=1.0, absoluteUsedCapacity=1.0, numApps=5, numContainers=43
2013-08-09 20:53:54,939 INFO org.apache.hadoop.yarn.server.resourcemanager.scheduler.capacity.ParentQueue: assignedContainer queue=root usedCapacity=1.0 absoluteUsedCapacity=1.0 used=<memory:49152, vCores:43> cluster=<memory:49152, vCores:96>
2013-08-09 20:53:55,109 INFO org.apache.hadoop.yarn.server.resourcemanager.rmcontainer.RMContainerImpl: container_1376080735992_0006_01_000040 Container Transitioned from ALLOCATED to ACQUIRED
2013-08-09 20:53:55,111 INFO org.apache.hadoop.yarn.server.resourcemanager.rmcontainer.RMContainerImpl: container_1376080735992_0006_01_000041 Container Transitioned from ALLOCATED to ACQUIRED
2013-08-09 20:53:55,600 INFO org.apache.hadoop.yarn.server.resourcemanager.rmcontainer.RMContainerImpl: container_1376080735992_0006_01_000016 Container Transitioned from RUNNING to COMPLETED
2013-08-09 20:53:55,600 INFO org.apache.hadoop.yarn.server.resourcemanager.scheduler.common.fica.FiCaSchedulerApp: Completed container: container_1376080735992_0006_01_000016 in state: COMPLETED event:FINISHED
2013-08-09 20:53:55,600 INFO org.apache.hadoop.yarn.server.resourcemanager.RMAuditLogger: USER=ubuntu	OPERATION=AM Released Container	TARGET=SchedulerApp	RESULT=SUCCESS	APPID=application_1376080735992_0006	CONTAINERID=container_1376080735992_0006_01_000016
2013-08-09 20:53:55,600 INFO org.apache.hadoop.yarn.server.resourcemanager.scheduler.common.fica.FiCaSchedulerNode: Released container container_1376080735992_0006_01_000016 of capacity <memory:1024, vCores:1> on host hadoop-210-2:51035, which currently has 6 containers, <memory:7168, vCores:6> used and <memory:1024, vCores:10> available, release resources=true
2013-08-09 20:53:55,600 INFO org.apache.hadoop.yarn.server.resourcemanager.scheduler.capacity.LeafQueue: default used=<memory:48128, vCores:42> numContainers=42 user=ubuntu user-resources=<memory:48128, vCores:42>
2013-08-09 20:53:55,602 INFO org.apache.hadoop.yarn.server.resourcemanager.scheduler.capacity.LeafQueue: completedContainer container=Container: [ContainerId: container_1376080735992_0006_01_000016, NodeId: hadoop-210-2:51035, NodeHttpAddress: hadoop-210-2:8042, Resource: <memory:1024, vCores:1>, Priority: 20, State: NEW, Token: null, Status: container_id {, app_attempt_id {, application_id {, id: 6, cluster_timestamp: 1376080735992, }, attemptId: 1, }, id: 16, }, state: C_COMPLETE, diagnostics: "", exit_status: 0, ] resource=<memory:1024, vCores:1> queue=default: capacity=1.0, absoluteCapacity=1.0, usedResources=<memory:48128, vCores:42>usedCapacity=0.9791667, absoluteUsedCapacity=0.9791667, numApps=5, numContainers=42 usedCapacity=0.9791667 absoluteUsedCapacity=0.9791667 used=<memory:48128, vCores:42> cluster=<memory:49152, vCores:96>
2013-08-09 20:53:55,602 INFO org.apache.hadoop.yarn.server.resourcemanager.scheduler.capacity.ParentQueue: completedContainer queue=root usedCapacity=0.9791667 absoluteUsedCapacity=0.9791667 used=<memory:48128, vCores:42> cluster=<memory:49152, vCores:96>
2013-08-09 20:53:55,602 INFO org.apache.hadoop.yarn.server.resourcemanager.scheduler.capacity.CapacityScheduler: Application appattempt_1376080735992_0006_000001 released container container_1376080735992_0006_01_000016 on node: host: hadoop-210-2:51035 #containers=6 available=1024 used=7168 with event: FINISHED
2013-08-09 20:53:55,603 INFO org.apache.hadoop.yarn.server.resourcemanager.rmcontainer.RMContainerImpl: container_1376080735992_0007_01_000002 Container Transitioned from NEW to ALLOCATED
2013-08-09 20:53:55,603 INFO org.apache.hadoop.yarn.server.resourcemanager.RMAuditLogger: USER=ubuntu	OPERATION=AM Allocated Container	TARGET=SchedulerApp	RESULT=SUCCESS	APPID=application_1376080735992_0007	CONTAINERID=container_1376080735992_0007_01_000002
2013-08-09 20:53:55,603 INFO org.apache.hadoop.yarn.server.resourcemanager.scheduler.common.fica.FiCaSchedulerNode: Assigned container container_1376080735992_0007_01_000002 of capacity <memory:1024, vCores:1> on host hadoop-210-2:51035, which currently has 7 containers, <memory:8192, vCores:7> used and <memory:0, vCores:9> available
2013-08-09 20:53:55,604 INFO org.apache.hadoop.yarn.server.resourcemanager.scheduler.capacity.LeafQueue: assignedContainer application=application_1376080735992_0007 container=Container: [ContainerId: container_1376080735992_0007_01_000002, NodeId: hadoop-210-2:51035, NodeHttpAddress: hadoop-210-2:8042, Resource: <memory:1024, vCores:1>, Priority: 20, State: NEW, Token: null, Status: container_id {, app_attempt_id {, application_id {, id: 7, cluster_timestamp: 1376080735992, }, attemptId: 1, }, id: 2, }, state: C_NEW, ] containerId=container_1376080735992_0007_01_000002 queue=default: capacity=1.0, absoluteCapacity=1.0, usedResources=<memory:48128, vCores:42>usedCapacity=0.9791667, absoluteUsedCapacity=0.9791667, numApps=5, numContainers=42 usedCapacity=0.9791667 absoluteUsedCapacity=0.9791667 used=<memory:48128, vCores:42> cluster=<memory:49152, vCores:96>
2013-08-09 20:53:55,604 INFO org.apache.hadoop.yarn.server.resourcemanager.scheduler.capacity.ParentQueue: Re-sorting queues since queue: root.default stats: default: capacity=1.0, absoluteCapacity=1.0, usedResources=<memory:49152, vCores:43>usedCapacity=1.0, absoluteUsedCapacity=1.0, numApps=5, numContainers=43
2013-08-09 20:53:55,605 INFO org.apache.hadoop.yarn.server.resourcemanager.scheduler.capacity.ParentQueue: assignedContainer queue=root usedCapacity=1.0 absoluteUsedCapacity=1.0 used=<memory:49152, vCores:43> cluster=<memory:49152, vCores:96>
2013-08-09 20:53:55,718 INFO org.apache.hadoop.yarn.server.resourcemanager.rmcontainer.RMContainerImpl: container_1376080735992_0007_01_000002 Container Transitioned from ALLOCATED to ACQUIRED
2013-08-09 20:53:55,819 INFO org.apache.hadoop.yarn.server.resourcemanager.rmcontainer.RMContainerImpl: container_1376080735992_0006_01_000014 Container Transitioned from RUNNING to COMPLETED
2013-08-09 20:53:55,819 INFO org.apache.hadoop.yarn.server.resourcemanager.scheduler.common.fica.FiCaSchedulerApp: Completed container: container_1376080735992_0006_01_000014 in state: COMPLETED event:FINISHED
2013-08-09 20:53:55,819 INFO org.apache.hadoop.yarn.server.resourcemanager.RMAuditLogger: USER=ubuntu	OPERATION=AM Released Container	TARGET=SchedulerApp	RESULT=SUCCESS	APPID=application_1376080735992_0006	CONTAINERID=container_1376080735992_0006_01_000014
2013-08-09 20:53:55,820 INFO org.apache.hadoop.yarn.server.resourcemanager.scheduler.common.fica.FiCaSchedulerNode: Released container container_1376080735992_0006_01_000014 of capacity <memory:1024, vCores:1> on host hadoop-210-2:51035, which currently has 6 containers, <memory:7168, vCores:6> used and <memory:1024, vCores:10> available, release resources=true
2013-08-09 20:53:55,820 INFO org.apache.hadoop.yarn.server.resourcemanager.scheduler.capacity.LeafQueue: default used=<memory:48128, vCores:42> numContainers=42 user=ubuntu user-resources=<memory:48128, vCores:42>
2013-08-09 20:53:55,821 INFO org.apache.hadoop.yarn.server.resourcemanager.scheduler.capacity.LeafQueue: completedContainer container=Container: [ContainerId: container_1376080735992_0006_01_000014, NodeId: hadoop-210-2:51035, NodeHttpAddress: hadoop-210-2:8042, Resource: <memory:1024, vCores:1>, Priority: 20, State: NEW, Token: null, Status: container_id {, app_attempt_id {, application_id {, id: 6, cluster_timestamp: 1376080735992, }, attemptId: 1, }, id: 14, }, state: C_COMPLETE, diagnostics: "", exit_status: 0, ] resource=<memory:1024, vCores:1> queue=default: capacity=1.0, absoluteCapacity=1.0, usedResources=<memory:48128, vCores:42>usedCapacity=0.9791667, absoluteUsedCapacity=0.9791667, numApps=5, numContainers=42 usedCapacity=0.9791667 absoluteUsedCapacity=0.9791667 used=<memory:48128, vCores:42> cluster=<memory:49152, vCores:96>
2013-08-09 20:53:55,821 INFO org.apache.hadoop.yarn.server.resourcemanager.scheduler.capacity.ParentQueue: completedContainer queue=root usedCapacity=0.9791667 absoluteUsedCapacity=0.9791667 used=<memory:48128, vCores:42> cluster=<memory:49152, vCores:96>
2013-08-09 20:53:55,821 INFO org.apache.hadoop.yarn.server.resourcemanager.scheduler.capacity.CapacityScheduler: Application appattempt_1376080735992_0006_000001 released container container_1376080735992_0006_01_000014 on node: host: hadoop-210-2:51035 #containers=6 available=1024 used=7168 with event: FINISHED
2013-08-09 20:53:55,822 INFO org.apache.hadoop.yarn.server.resourcemanager.rmcontainer.RMContainerImpl: container_1376080735992_0007_01_000003 Container Transitioned from NEW to ALLOCATED
2013-08-09 20:53:55,822 INFO org.apache.hadoop.yarn.server.resourcemanager.RMAuditLogger: USER=ubuntu	OPERATION=AM Allocated Container	TARGET=SchedulerApp	RESULT=SUCCESS	APPID=application_1376080735992_0007	CONTAINERID=container_1376080735992_0007_01_000003
2013-08-09 20:53:55,822 INFO org.apache.hadoop.yarn.server.resourcemanager.scheduler.common.fica.FiCaSchedulerNode: Assigned container container_1376080735992_0007_01_000003 of capacity <memory:1024, vCores:1> on host hadoop-210-2:51035, which currently has 7 containers, <memory:8192, vCores:7> used and <memory:0, vCores:9> available
2013-08-09 20:53:55,823 INFO org.apache.hadoop.yarn.server.resourcemanager.scheduler.capacity.LeafQueue: assignedContainer application=application_1376080735992_0007 container=Container: [ContainerId: container_1376080735992_0007_01_000003, NodeId: hadoop-210-2:51035, NodeHttpAddress: hadoop-210-2:8042, Resource: <memory:1024, vCores:1>, Priority: 20, State: NEW, Token: null, Status: container_id {, app_attempt_id {, application_id {, id: 7, cluster_timestamp: 1376080735992, }, attemptId: 1, }, id: 3, }, state: C_NEW, ] containerId=container_1376080735992_0007_01_000003 queue=default: capacity=1.0, absoluteCapacity=1.0, usedResources=<memory:48128, vCores:42>usedCapacity=0.9791667, absoluteUsedCapacity=0.9791667, numApps=5, numContainers=42 usedCapacity=0.9791667 absoluteUsedCapacity=0.9791667 used=<memory:48128, vCores:42> cluster=<memory:49152, vCores:96>
2013-08-09 20:53:55,823 INFO org.apache.hadoop.yarn.server.resourcemanager.scheduler.capacity.ParentQueue: Re-sorting queues since queue: root.default stats: default: capacity=1.0, absoluteCapacity=1.0, usedResources=<memory:49152, vCores:43>usedCapacity=1.0, absoluteUsedCapacity=1.0, numApps=5, numContainers=43
2013-08-09 20:53:55,823 INFO org.apache.hadoop.yarn.server.resourcemanager.scheduler.capacity.ParentQueue: assignedContainer queue=root usedCapacity=1.0 absoluteUsedCapacity=1.0 used=<memory:49152, vCores:43> cluster=<memory:49152, vCores:96>
2013-08-09 20:53:55,941 INFO org.apache.hadoop.yarn.server.resourcemanager.rmcontainer.RMContainerImpl: container_1376080735992_0006_01_000040 Container Transitioned from ACQUIRED to RUNNING
2013-08-09 20:53:55,941 INFO org.apache.hadoop.yarn.server.resourcemanager.rmcontainer.RMContainerImpl: container_1376080735992_0006_01_000041 Container Transitioned from ACQUIRED to RUNNING
2013-08-09 20:53:55,942 INFO org.apache.hadoop.yarn.server.resourcemanager.rmcontainer.RMContainerImpl: container_1376080735992_0006_01_000005 Container Transitioned from RUNNING to COMPLETED
2013-08-09 20:53:55,942 INFO org.apache.hadoop.yarn.server.resourcemanager.scheduler.common.fica.FiCaSchedulerApp: Completed container: container_1376080735992_0006_01_000005 in state: COMPLETED event:FINISHED
2013-08-09 20:53:55,942 INFO org.apache.hadoop.yarn.server.resourcemanager.RMAuditLogger: USER=ubuntu	OPERATION=AM Released Container	TARGET=SchedulerApp	RESULT=SUCCESS	APPID=application_1376080735992_0006	CONTAINERID=container_1376080735992_0006_01_000005
2013-08-09 20:53:55,942 INFO org.apache.hadoop.yarn.server.resourcemanager.scheduler.common.fica.FiCaSchedulerNode: Released container container_1376080735992_0006_01_000005 of capacity <memory:1024, vCores:1> on host hadoop-210-4:47596, which currently has 6 containers, <memory:7168, vCores:6> used and <memory:1024, vCores:10> available, release resources=true
2013-08-09 20:53:55,942 INFO org.apache.hadoop.yarn.server.resourcemanager.scheduler.capacity.LeafQueue: default used=<memory:48128, vCores:42> numContainers=42 user=ubuntu user-resources=<memory:48128, vCores:42>
2013-08-09 20:53:55,944 INFO org.apache.hadoop.yarn.server.resourcemanager.scheduler.capacity.LeafQueue: completedContainer container=Container: [ContainerId: container_1376080735992_0006_01_000005, NodeId: hadoop-210-4:47596, NodeHttpAddress: hadoop-210-4:8042, Resource: <memory:1024, vCores:1>, Priority: 20, State: NEW, Token: null, Status: container_id {, app_attempt_id {, application_id {, id: 6, cluster_timestamp: 1376080735992, }, attemptId: 1, }, id: 5, }, state: C_COMPLETE, diagnostics: "", exit_status: 0, ] resource=<memory:1024, vCores:1> queue=default: capacity=1.0, absoluteCapacity=1.0, usedResources=<memory:48128, vCores:42>usedCapacity=0.9791667, absoluteUsedCapacity=0.9791667, numApps=5, numContainers=42 usedCapacity=0.9791667 absoluteUsedCapacity=0.9791667 used=<memory:48128, vCores:42> cluster=<memory:49152, vCores:96>
2013-08-09 20:53:55,944 INFO org.apache.hadoop.yarn.server.resourcemanager.scheduler.capacity.ParentQueue: completedContainer queue=root usedCapacity=0.9791667 absoluteUsedCapacity=0.9791667 used=<memory:48128, vCores:42> cluster=<memory:49152, vCores:96>
2013-08-09 20:53:55,944 INFO org.apache.hadoop.yarn.server.resourcemanager.scheduler.capacity.CapacityScheduler: Application appattempt_1376080735992_0006_000001 released container container_1376080735992_0006_01_000005 on node: host: hadoop-210-4:47596 #containers=6 available=1024 used=7168 with event: FINISHED
2013-08-09 20:53:55,945 INFO org.apache.hadoop.yarn.server.resourcemanager.rmcontainer.RMContainerImpl: container_1376080735992_0007_01_000004 Container Transitioned from NEW to ALLOCATED
2013-08-09 20:53:55,945 INFO org.apache.hadoop.yarn.server.resourcemanager.RMAuditLogger: USER=ubuntu	OPERATION=AM Allocated Container	TARGET=SchedulerApp	RESULT=SUCCESS	APPID=application_1376080735992_0007	CONTAINERID=container_1376080735992_0007_01_000004
2013-08-09 20:53:55,945 INFO org.apache.hadoop.yarn.server.resourcemanager.scheduler.common.fica.FiCaSchedulerNode: Assigned container container_1376080735992_0007_01_000004 of capacity <memory:1024, vCores:1> on host hadoop-210-4:47596, which currently has 7 containers, <memory:8192, vCores:7> used and <memory:0, vCores:9> available
2013-08-09 20:53:55,946 INFO org.apache.hadoop.yarn.server.resourcemanager.scheduler.capacity.LeafQueue: assignedContainer application=application_1376080735992_0007 container=Container: [ContainerId: container_1376080735992_0007_01_000004, NodeId: hadoop-210-4:47596, NodeHttpAddress: hadoop-210-4:8042, Resource: <memory:1024, vCores:1>, Priority: 20, State: NEW, Token: null, Status: container_id {, app_attempt_id {, application_id {, id: 7, cluster_timestamp: 1376080735992, }, attemptId: 1, }, id: 4, }, state: C_NEW, ] containerId=container_1376080735992_0007_01_000004 queue=default: capacity=1.0, absoluteCapacity=1.0, usedResources=<memory:48128, vCores:42>usedCapacity=0.9791667, absoluteUsedCapacity=0.9791667, numApps=5, numContainers=42 usedCapacity=0.9791667 absoluteUsedCapacity=0.9791667 used=<memory:48128, vCores:42> cluster=<memory:49152, vCores:96>
2013-08-09 20:53:55,946 INFO org.apache.hadoop.yarn.server.resourcemanager.scheduler.capacity.ParentQueue: Re-sorting queues since queue: root.default stats: default: capacity=1.0, absoluteCapacity=1.0, usedResources=<memory:49152, vCores:43>usedCapacity=1.0, absoluteUsedCapacity=1.0, numApps=5, numContainers=43
2013-08-09 20:53:55,946 INFO org.apache.hadoop.yarn.server.resourcemanager.scheduler.capacity.ParentQueue: assignedContainer queue=root usedCapacity=1.0 absoluteUsedCapacity=1.0 used=<memory:49152, vCores:43> cluster=<memory:49152, vCores:96>
2013-08-09 20:53:56,137 INFO org.apache.hadoop.yarn.server.resourcemanager.scheduler.AppSchedulingInfo: checking for deactivate... 
2013-08-09 20:53:57,062 INFO org.apache.hadoop.yarn.server.resourcemanager.rmcontainer.RMContainerImpl: container_1376080735992_0007_01_000003 Container Transitioned from ALLOCATED to ACQUIRED
2013-08-09 20:53:57,063 INFO org.apache.hadoop.yarn.server.resourcemanager.rmcontainer.RMContainerImpl: container_1376080735992_0007_01_000004 Container Transitioned from ALLOCATED to ACQUIRED
2013-08-09 20:53:57,851 INFO org.apache.hadoop.yarn.server.resourcemanager.rmcontainer.RMContainerImpl: container_1376080735992_0007_01_000002 Container Transitioned from ACQUIRED to RUNNING
2013-08-09 20:53:57,851 INFO org.apache.hadoop.yarn.server.resourcemanager.rmcontainer.RMContainerImpl: container_1376080735992_0007_01_000003 Container Transitioned from ACQUIRED to RUNNING
2013-08-09 20:53:57,952 INFO org.apache.hadoop.yarn.server.resourcemanager.rmcontainer.RMContainerImpl: container_1376080735992_0007_01_000004 Container Transitioned from ACQUIRED to RUNNING
2013-08-09 20:54:01,497 INFO org.apache.hadoop.yarn.server.resourcemanager.rmcontainer.RMContainerImpl: container_1376080735992_0006_01_000030 Container Transitioned from RUNNING to COMPLETED
2013-08-09 20:54:01,497 INFO org.apache.hadoop.yarn.server.resourcemanager.scheduler.common.fica.FiCaSchedulerApp: Completed container: container_1376080735992_0006_01_000030 in state: COMPLETED event:FINISHED
2013-08-09 20:54:01,497 INFO org.apache.hadoop.yarn.server.resourcemanager.RMAuditLogger: USER=ubuntu	OPERATION=AM Released Container	TARGET=SchedulerApp	RESULT=SUCCESS	APPID=application_1376080735992_0006	CONTAINERID=container_1376080735992_0006_01_000030
2013-08-09 20:54:01,498 INFO org.apache.hadoop.yarn.server.resourcemanager.scheduler.common.fica.FiCaSchedulerNode: Released container container_1376080735992_0006_01_000030 of capacity <memory:1024, vCores:1> on host hadoop-210-6:41207, which currently has 6 containers, <memory:7168, vCores:6> used and <memory:1024, vCores:10> available, release resources=true
2013-08-09 20:54:01,498 INFO org.apache.hadoop.yarn.server.resourcemanager.scheduler.capacity.LeafQueue: default used=<memory:48128, vCores:42> numContainers=42 user=ubuntu user-resources=<memory:48128, vCores:42>
2013-08-09 20:54:01,499 INFO org.apache.hadoop.yarn.server.resourcemanager.scheduler.capacity.LeafQueue: completedContainer container=Container: [ContainerId: container_1376080735992_0006_01_000030, NodeId: hadoop-210-6:41207, NodeHttpAddress: hadoop-210-6:8042, Resource: <memory:1024, vCores:1>, Priority: 20, State: NEW, Token: null, Status: container_id {, app_attempt_id {, application_id {, id: 6, cluster_timestamp: 1376080735992, }, attemptId: 1, }, id: 30, }, state: C_COMPLETE, diagnostics: "Container killed by the ApplicationMaster.\n", exit_status: 0, ] resource=<memory:1024, vCores:1> queue=default: capacity=1.0, absoluteCapacity=1.0, usedResources=<memory:48128, vCores:42>usedCapacity=0.9791667, absoluteUsedCapacity=0.9791667, numApps=5, numContainers=42 usedCapacity=0.9791667 absoluteUsedCapacity=0.9791667 used=<memory:48128, vCores:42> cluster=<memory:49152, vCores:96>
2013-08-09 20:54:01,499 INFO org.apache.hadoop.yarn.server.resourcemanager.scheduler.capacity.ParentQueue: completedContainer queue=root usedCapacity=0.9791667 absoluteUsedCapacity=0.9791667 used=<memory:48128, vCores:42> cluster=<memory:49152, vCores:96>
2013-08-09 20:54:01,500 INFO org.apache.hadoop.yarn.server.resourcemanager.scheduler.capacity.CapacityScheduler: Application appattempt_1376080735992_0006_000001 released container container_1376080735992_0006_01_000030 on node: host: hadoop-210-6:41207 #containers=6 available=1024 used=7168 with event: FINISHED
2013-08-09 20:54:01,500 INFO org.apache.hadoop.yarn.server.resourcemanager.rmcontainer.RMContainerImpl: container_1376080735992_0006_01_000032 Container Transitioned from RUNNING to COMPLETED
2013-08-09 20:54:01,500 INFO org.apache.hadoop.yarn.server.resourcemanager.scheduler.common.fica.FiCaSchedulerApp: Completed container: container_1376080735992_0006_01_000032 in state: COMPLETED event:FINISHED
2013-08-09 20:54:01,500 INFO org.apache.hadoop.yarn.server.resourcemanager.RMAuditLogger: USER=ubuntu	OPERATION=AM Released Container	TARGET=SchedulerApp	RESULT=SUCCESS	APPID=application_1376080735992_0006	CONTAINERID=container_1376080735992_0006_01_000032
2013-08-09 20:54:01,500 INFO org.apache.hadoop.yarn.server.resourcemanager.scheduler.common.fica.FiCaSchedulerNode: Released container container_1376080735992_0006_01_000032 of capacity <memory:1024, vCores:1> on host hadoop-210-6:41207, which currently has 5 containers, <memory:6144, vCores:5> used and <memory:2048, vCores:11> available, release resources=true
2013-08-09 20:54:01,500 INFO org.apache.hadoop.yarn.server.resourcemanager.scheduler.capacity.LeafQueue: default used=<memory:47104, vCores:41> numContainers=41 user=ubuntu user-resources=<memory:47104, vCores:41>
2013-08-09 20:54:01,501 INFO org.apache.hadoop.yarn.server.resourcemanager.scheduler.capacity.LeafQueue: completedContainer container=Container: [ContainerId: container_1376080735992_0006_01_000032, NodeId: hadoop-210-6:41207, NodeHttpAddress: hadoop-210-6:8042, Resource: <memory:1024, vCores:1>, Priority: 20, State: NEW, Token: null, Status: container_id {, app_attempt_id {, application_id {, id: 6, cluster_timestamp: 1376080735992, }, attemptId: 1, }, id: 32, }, state: C_COMPLETE, diagnostics: "Container killed by the ApplicationMaster.\n", exit_status: 0, ] resource=<memory:1024, vCores:1> queue=default: capacity=1.0, absoluteCapacity=1.0, usedResources=<memory:47104, vCores:41>usedCapacity=0.9583333, absoluteUsedCapacity=0.9583333, numApps=5, numContainers=41 usedCapacity=0.9583333 absoluteUsedCapacity=0.9583333 used=<memory:47104, vCores:41> cluster=<memory:49152, vCores:96>
2013-08-09 20:54:01,502 INFO org.apache.hadoop.yarn.server.resourcemanager.scheduler.capacity.ParentQueue: completedContainer queue=root usedCapacity=0.9583333 absoluteUsedCapacity=0.9583333 used=<memory:47104, vCores:41> cluster=<memory:49152, vCores:96>
2013-08-09 20:54:01,502 INFO org.apache.hadoop.yarn.server.resourcemanager.scheduler.capacity.CapacityScheduler: Application appattempt_1376080735992_0006_000001 released container container_1376080735992_0006_01_000032 on node: host: hadoop-210-6:41207 #containers=5 available=2048 used=6144 with event: FINISHED
2013-08-09 20:54:01,502 INFO org.apache.hadoop.yarn.server.resourcemanager.rmcontainer.RMContainerImpl: container_1376080735992_0006_01_000042 Container Transitioned from NEW to ALLOCATED
2013-08-09 20:54:01,503 INFO org.apache.hadoop.yarn.server.resourcemanager.RMAuditLogger: USER=ubuntu	OPERATION=AM Allocated Container	TARGET=SchedulerApp	RESULT=SUCCESS	APPID=application_1376080735992_0006	CONTAINERID=container_1376080735992_0006_01_000042
2013-08-09 20:54:01,503 INFO org.apache.hadoop.yarn.server.resourcemanager.scheduler.common.fica.FiCaSchedulerNode: Assigned container container_1376080735992_0006_01_000042 of capacity <memory:1024, vCores:1> on host hadoop-210-6:41207, which currently has 6 containers, <memory:7168, vCores:6> used and <memory:1024, vCores:10> available
2013-08-09 20:54:01,504 INFO org.apache.hadoop.yarn.server.resourcemanager.scheduler.capacity.LeafQueue: assignedContainer application=application_1376080735992_0006 container=Container: [ContainerId: container_1376080735992_0006_01_000042, NodeId: hadoop-210-6:41207, NodeHttpAddress: hadoop-210-6:8042, Resource: <memory:1024, vCores:1>, Priority: 10, State: NEW, Token: null, Status: container_id {, app_attempt_id {, application_id {, id: 6, cluster_timestamp: 1376080735992, }, attemptId: 1, }, id: 42, }, state: C_NEW, ] containerId=container_1376080735992_0006_01_000042 queue=default: capacity=1.0, absoluteCapacity=1.0, usedResources=<memory:47104, vCores:41>usedCapacity=0.9583333, absoluteUsedCapacity=0.9583333, numApps=5, numContainers=41 usedCapacity=0.9583333 absoluteUsedCapacity=0.9583333 used=<memory:47104, vCores:41> cluster=<memory:49152, vCores:96>
2013-08-09 20:54:01,504 INFO org.apache.hadoop.yarn.server.resourcemanager.scheduler.capacity.ParentQueue: Re-sorting queues since queue: root.default stats: default: capacity=1.0, absoluteCapacity=1.0, usedResources=<memory:48128, vCores:42>usedCapacity=0.9791667, absoluteUsedCapacity=0.9791667, numApps=5, numContainers=42
2013-08-09 20:54:01,504 INFO org.apache.hadoop.yarn.server.resourcemanager.scheduler.capacity.ParentQueue: assignedContainer queue=root usedCapacity=0.9791667 absoluteUsedCapacity=0.9791667 used=<memory:48128, vCores:42> cluster=<memory:49152, vCores:96>
2013-08-09 20:54:02,200 INFO org.apache.hadoop.yarn.server.resourcemanager.rmcontainer.RMContainerImpl: container_1376080735992_0006_01_000042 Container Transitioned from ALLOCATED to ACQUIRED
2013-08-09 20:54:02,507 INFO org.apache.hadoop.yarn.server.resourcemanager.rmcontainer.RMContainerImpl: container_1376080735992_0006_01_000042 Container Transitioned from ACQUIRED to RUNNING
2013-08-09 20:54:02,507 INFO org.apache.hadoop.yarn.server.resourcemanager.rmcontainer.RMContainerImpl: container_1376080735992_0006_01_000043 Container Transitioned from NEW to ALLOCATED
2013-08-09 20:54:02,508 INFO org.apache.hadoop.yarn.server.resourcemanager.RMAuditLogger: USER=ubuntu	OPERATION=AM Allocated Container	TARGET=SchedulerApp	RESULT=SUCCESS	APPID=application_1376080735992_0006	CONTAINERID=container_1376080735992_0006_01_000043
2013-08-09 20:54:02,508 INFO org.apache.hadoop.yarn.server.resourcemanager.scheduler.common.fica.FiCaSchedulerNode: Assigned container container_1376080735992_0006_01_000043 of capacity <memory:1024, vCores:1> on host hadoop-210-6:41207, which currently has 7 containers, <memory:8192, vCores:7> used and <memory:0, vCores:9> available
2013-08-09 20:54:02,509 INFO org.apache.hadoop.yarn.server.resourcemanager.scheduler.capacity.LeafQueue: assignedContainer application=application_1376080735992_0006 container=Container: [ContainerId: container_1376080735992_0006_01_000043, NodeId: hadoop-210-6:41207, NodeHttpAddress: hadoop-210-6:8042, Resource: <memory:1024, vCores:1>, Priority: 10, State: NEW, Token: null, Status: container_id {, app_attempt_id {, application_id {, id: 6, cluster_timestamp: 1376080735992, }, attemptId: 1, }, id: 43, }, state: C_NEW, ] containerId=container_1376080735992_0006_01_000043 queue=default: capacity=1.0, absoluteCapacity=1.0, usedResources=<memory:48128, vCores:42>usedCapacity=0.9791667, absoluteUsedCapacity=0.9791667, numApps=5, numContainers=42 usedCapacity=0.9791667 absoluteUsedCapacity=0.9791667 used=<memory:48128, vCores:42> cluster=<memory:49152, vCores:96>
2013-08-09 20:54:02,509 INFO org.apache.hadoop.yarn.server.resourcemanager.scheduler.capacity.ParentQueue: Re-sorting queues since queue: root.default stats: default: capacity=1.0, absoluteCapacity=1.0, usedResources=<memory:49152, vCores:43>usedCapacity=1.0, absoluteUsedCapacity=1.0, numApps=5, numContainers=43
2013-08-09 20:54:02,509 INFO org.apache.hadoop.yarn.server.resourcemanager.scheduler.capacity.ParentQueue: assignedContainer queue=root usedCapacity=1.0 absoluteUsedCapacity=1.0 used=<memory:49152, vCores:43> cluster=<memory:49152, vCores:96>
2013-08-09 20:54:03,218 INFO org.apache.hadoop.yarn.server.resourcemanager.rmcontainer.RMContainerImpl: container_1376080735992_0006_01_000043 Container Transitioned from ALLOCATED to ACQUIRED
2013-08-09 20:54:03,513 INFO org.apache.hadoop.yarn.server.resourcemanager.rmcontainer.RMContainerImpl: container_1376080735992_0006_01_000043 Container Transitioned from ACQUIRED to RUNNING
2013-08-09 20:54:04,428 INFO org.apache.hadoop.yarn.server.resourcemanager.rmcontainer.RMContainerImpl: container_1376080735992_0006_01_000012 Container Transitioned from RUNNING to COMPLETED
2013-08-09 20:54:04,428 INFO org.apache.hadoop.yarn.server.resourcemanager.scheduler.common.fica.FiCaSchedulerApp: Completed container: container_1376080735992_0006_01_000012 in state: COMPLETED event:FINISHED
2013-08-09 20:54:04,428 INFO org.apache.hadoop.yarn.server.resourcemanager.RMAuditLogger: USER=ubuntu	OPERATION=AM Released Container	TARGET=SchedulerApp	RESULT=SUCCESS	APPID=application_1376080735992_0006	CONTAINERID=container_1376080735992_0006_01_000012
2013-08-09 20:54:04,428 INFO org.apache.hadoop.yarn.server.resourcemanager.scheduler.common.fica.FiCaSchedulerNode: Released container container_1376080735992_0006_01_000012 of capacity <memory:1024, vCores:1> on host hadoop-210-3:58589, which currently has 6 containers, <memory:7168, vCores:6> used and <memory:1024, vCores:10> available, release resources=true
2013-08-09 20:54:04,428 INFO org.apache.hadoop.yarn.server.resourcemanager.scheduler.capacity.LeafQueue: default used=<memory:48128, vCores:42> numContainers=42 user=ubuntu user-resources=<memory:48128, vCores:42>
2013-08-09 20:54:04,430 INFO org.apache.hadoop.yarn.server.resourcemanager.scheduler.capacity.LeafQueue: completedContainer container=Container: [ContainerId: container_1376080735992_0006_01_000012, NodeId: hadoop-210-3:58589, NodeHttpAddress: hadoop-210-3:8042, Resource: <memory:1024, vCores:1>, Priority: 20, State: NEW, Token: null, Status: container_id {, app_attempt_id {, application_id {, id: 6, cluster_timestamp: 1376080735992, }, attemptId: 1, }, id: 12, }, state: C_COMPLETE, diagnostics: "Container killed by the ApplicationMaster.\n\n", exit_status: 143, ] resource=<memory:1024, vCores:1> queue=default: capacity=1.0, absoluteCapacity=1.0, usedResources=<memory:48128, vCores:42>usedCapacity=0.9791667, absoluteUsedCapacity=0.9791667, numApps=5, numContainers=42 usedCapacity=0.9791667 absoluteUsedCapacity=0.9791667 used=<memory:48128, vCores:42> cluster=<memory:49152, vCores:96>
2013-08-09 20:54:04,430 INFO org.apache.hadoop.yarn.server.resourcemanager.scheduler.capacity.ParentQueue: completedContainer queue=root usedCapacity=0.9791667 absoluteUsedCapacity=0.9791667 used=<memory:48128, vCores:42> cluster=<memory:49152, vCores:96>
2013-08-09 20:54:04,430 INFO org.apache.hadoop.yarn.server.resourcemanager.scheduler.capacity.CapacityScheduler: Application appattempt_1376080735992_0006_000001 released container container_1376080735992_0006_01_000012 on node: host: hadoop-210-3:58589 #containers=6 available=1024 used=7168 with event: FINISHED
2013-08-09 20:54:04,431 INFO org.apache.hadoop.yarn.server.resourcemanager.rmcontainer.RMContainerImpl: container_1376080735992_0006_01_000044 Container Transitioned from NEW to ALLOCATED
2013-08-09 20:54:04,431 INFO org.apache.hadoop.yarn.server.resourcemanager.RMAuditLogger: USER=ubuntu	OPERATION=AM Allocated Container	TARGET=SchedulerApp	RESULT=SUCCESS	APPID=application_1376080735992_0006	CONTAINERID=container_1376080735992_0006_01_000044
2013-08-09 20:54:04,431 INFO org.apache.hadoop.yarn.server.resourcemanager.scheduler.common.fica.FiCaSchedulerNode: Assigned container container_1376080735992_0006_01_000044 of capacity <memory:1024, vCores:1> on host hadoop-210-3:58589, which currently has 7 containers, <memory:8192, vCores:7> used and <memory:0, vCores:9> available
2013-08-09 20:54:04,432 INFO org.apache.hadoop.yarn.server.resourcemanager.scheduler.capacity.LeafQueue: assignedContainer application=application_1376080735992_0006 container=Container: [ContainerId: container_1376080735992_0006_01_000044, NodeId: hadoop-210-3:58589, NodeHttpAddress: hadoop-210-3:8042, Resource: <memory:1024, vCores:1>, Priority: 10, State: NEW, Token: null, Status: container_id {, app_attempt_id {, application_id {, id: 6, cluster_timestamp: 1376080735992, }, attemptId: 1, }, id: 44, }, state: C_NEW, ] containerId=container_1376080735992_0006_01_000044 queue=default: capacity=1.0, absoluteCapacity=1.0, usedResources=<memory:48128, vCores:42>usedCapacity=0.9791667, absoluteUsedCapacity=0.9791667, numApps=5, numContainers=42 usedCapacity=0.9791667 absoluteUsedCapacity=0.9791667 used=<memory:48128, vCores:42> cluster=<memory:49152, vCores:96>
2013-08-09 20:54:04,432 INFO org.apache.hadoop.yarn.server.resourcemanager.scheduler.capacity.ParentQueue: Re-sorting queues since queue: root.default stats: default: capacity=1.0, absoluteCapacity=1.0, usedResources=<memory:49152, vCores:43>usedCapacity=1.0, absoluteUsedCapacity=1.0, numApps=5, numContainers=43
2013-08-09 20:54:04,432 INFO org.apache.hadoop.yarn.server.resourcemanager.scheduler.capacity.ParentQueue: assignedContainer queue=root usedCapacity=1.0 absoluteUsedCapacity=1.0 used=<memory:49152, vCores:43> cluster=<memory:49152, vCores:96>
2013-08-09 20:54:05,230 INFO org.apache.hadoop.yarn.server.resourcemanager.rmcontainer.RMContainerImpl: container_1376080735992_0006_01_000044 Container Transitioned from ALLOCATED to ACQUIRED
2013-08-09 20:54:05,437 INFO org.apache.hadoop.yarn.server.resourcemanager.rmcontainer.RMContainerImpl: container_1376080735992_0006_01_000044 Container Transitioned from ACQUIRED to RUNNING
2013-08-09 20:54:05,437 INFO org.apache.hadoop.yarn.server.resourcemanager.rmcontainer.RMContainerImpl: container_1376080735992_0006_01_000013 Container Transitioned from RUNNING to COMPLETED
2013-08-09 20:54:05,438 INFO org.apache.hadoop.yarn.server.resourcemanager.scheduler.common.fica.FiCaSchedulerApp: Completed container: container_1376080735992_0006_01_000013 in state: COMPLETED event:FINISHED
2013-08-09 20:54:05,438 INFO org.apache.hadoop.yarn.server.resourcemanager.RMAuditLogger: USER=ubuntu	OPERATION=AM Released Container	TARGET=SchedulerApp	RESULT=SUCCESS	APPID=application_1376080735992_0006	CONTAINERID=container_1376080735992_0006_01_000013
2013-08-09 20:54:05,438 INFO org.apache.hadoop.yarn.server.resourcemanager.scheduler.common.fica.FiCaSchedulerNode: Released container container_1376080735992_0006_01_000013 of capacity <memory:1024, vCores:1> on host hadoop-210-3:58589, which currently has 6 containers, <memory:7168, vCores:6> used and <memory:1024, vCores:10> available, release resources=true
2013-08-09 20:54:05,438 INFO org.apache.hadoop.yarn.server.resourcemanager.scheduler.capacity.LeafQueue: default used=<memory:48128, vCores:42> numContainers=42 user=ubuntu user-resources=<memory:48128, vCores:42>
2013-08-09 20:54:05,439 INFO org.apache.hadoop.yarn.server.resourcemanager.scheduler.capacity.LeafQueue: completedContainer container=Container: [ContainerId: container_1376080735992_0006_01_000013, NodeId: hadoop-210-3:58589, NodeHttpAddress: hadoop-210-3:8042, Resource: <memory:1024, vCores:1>, Priority: 20, State: NEW, Token: null, Status: container_id {, app_attempt_id {, application_id {, id: 6, cluster_timestamp: 1376080735992, }, attemptId: 1, }, id: 13, }, state: C_COMPLETE, diagnostics: "Container killed by the ApplicationMaster.\n\n", exit_status: 143, ] resource=<memory:1024, vCores:1> queue=default: capacity=1.0, absoluteCapacity=1.0, usedResources=<memory:48128, vCores:42>usedCapacity=0.9791667, absoluteUsedCapacity=0.9791667, numApps=5, numContainers=42 usedCapacity=0.9791667 absoluteUsedCapacity=0.9791667 used=<memory:48128, vCores:42> cluster=<memory:49152, vCores:96>
2013-08-09 20:54:05,440 INFO org.apache.hadoop.yarn.server.resourcemanager.scheduler.capacity.ParentQueue: completedContainer queue=root usedCapacity=0.9791667 absoluteUsedCapacity=0.9791667 used=<memory:48128, vCores:42> cluster=<memory:49152, vCores:96>
2013-08-09 20:54:05,440 INFO org.apache.hadoop.yarn.server.resourcemanager.scheduler.capacity.CapacityScheduler: Application appattempt_1376080735992_0006_000001 released container container_1376080735992_0006_01_000013 on node: host: hadoop-210-3:58589 #containers=6 available=1024 used=7168 with event: FINISHED
2013-08-09 20:54:05,440 INFO org.apache.hadoop.yarn.server.resourcemanager.rmcontainer.RMContainerImpl: container_1376080735992_0006_01_000045 Container Transitioned from NEW to ALLOCATED
2013-08-09 20:54:05,440 INFO org.apache.hadoop.yarn.server.resourcemanager.RMAuditLogger: USER=ubuntu	OPERATION=AM Allocated Container	TARGET=SchedulerApp	RESULT=SUCCESS	APPID=application_1376080735992_0006	CONTAINERID=container_1376080735992_0006_01_000045
2013-08-09 20:54:05,441 INFO org.apache.hadoop.yarn.server.resourcemanager.scheduler.common.fica.FiCaSchedulerNode: Assigned container container_1376080735992_0006_01_000045 of capacity <memory:1024, vCores:1> on host hadoop-210-3:58589, which currently has 7 containers, <memory:8192, vCores:7> used and <memory:0, vCores:9> available
2013-08-09 20:54:05,441 INFO org.apache.hadoop.yarn.server.resourcemanager.scheduler.capacity.LeafQueue: assignedContainer application=application_1376080735992_0006 container=Container: [ContainerId: container_1376080735992_0006_01_000045, NodeId: hadoop-210-3:58589, NodeHttpAddress: hadoop-210-3:8042, Resource: <memory:1024, vCores:1>, Priority: 10, State: NEW, Token: null, Status: container_id {, app_attempt_id {, application_id {, id: 6, cluster_timestamp: 1376080735992, }, attemptId: 1, }, id: 45, }, state: C_NEW, ] containerId=container_1376080735992_0006_01_000045 queue=default: capacity=1.0, absoluteCapacity=1.0, usedResources=<memory:48128, vCores:42>usedCapacity=0.9791667, absoluteUsedCapacity=0.9791667, numApps=5, numContainers=42 usedCapacity=0.9791667 absoluteUsedCapacity=0.9791667 used=<memory:48128, vCores:42> cluster=<memory:49152, vCores:96>
2013-08-09 20:54:05,442 INFO org.apache.hadoop.yarn.server.resourcemanager.scheduler.capacity.ParentQueue: Re-sorting queues since queue: root.default stats: default: capacity=1.0, absoluteCapacity=1.0, usedResources=<memory:49152, vCores:43>usedCapacity=1.0, absoluteUsedCapacity=1.0, numApps=5, numContainers=43
2013-08-09 20:54:05,442 INFO org.apache.hadoop.yarn.server.resourcemanager.scheduler.capacity.ParentQueue: assignedContainer queue=root usedCapacity=1.0 absoluteUsedCapacity=1.0 used=<memory:49152, vCores:43> cluster=<memory:49152, vCores:96>
2013-08-09 20:54:05,921 INFO org.apache.hadoop.yarn.server.resourcemanager.rmcontainer.RMContainerImpl: container_1376080735992_0006_01_000035 Container Transitioned from RUNNING to COMPLETED
2013-08-09 20:54:05,922 INFO org.apache.hadoop.yarn.server.resourcemanager.scheduler.common.fica.FiCaSchedulerApp: Completed container: container_1376080735992_0006_01_000035 in state: COMPLETED event:FINISHED
2013-08-09 20:54:05,922 INFO org.apache.hadoop.yarn.server.resourcemanager.RMAuditLogger: USER=ubuntu	OPERATION=AM Released Container	TARGET=SchedulerApp	RESULT=SUCCESS	APPID=application_1376080735992_0006	CONTAINERID=container_1376080735992_0006_01_000035
2013-08-09 20:54:05,922 INFO org.apache.hadoop.yarn.server.resourcemanager.scheduler.common.fica.FiCaSchedulerNode: Released container container_1376080735992_0006_01_000035 of capacity <memory:1024, vCores:1> on host hadoop-210-7:35638, which currently has 6 containers, <memory:7168, vCores:6> used and <memory:1024, vCores:10> available, release resources=true
2013-08-09 20:54:05,922 INFO org.apache.hadoop.yarn.server.resourcemanager.scheduler.capacity.LeafQueue: default used=<memory:48128, vCores:42> numContainers=42 user=ubuntu user-resources=<memory:48128, vCores:42>
2013-08-09 20:54:05,923 INFO org.apache.hadoop.yarn.server.resourcemanager.scheduler.capacity.LeafQueue: completedContainer container=Container: [ContainerId: container_1376080735992_0006_01_000035, NodeId: hadoop-210-7:35638, NodeHttpAddress: hadoop-210-7:8042, Resource: <memory:1024, vCores:1>, Priority: 20, State: NEW, Token: null, Status: container_id {, app_attempt_id {, application_id {, id: 6, cluster_timestamp: 1376080735992, }, attemptId: 1, }, id: 35, }, state: C_COMPLETE, diagnostics: "Container killed by the ApplicationMaster.\n\n", exit_status: 143, ] resource=<memory:1024, vCores:1> queue=default: capacity=1.0, absoluteCapacity=1.0, usedResources=<memory:48128, vCores:42>usedCapacity=0.9791667, absoluteUsedCapacity=0.9791667, numApps=5, numContainers=42 usedCapacity=0.9791667 absoluteUsedCapacity=0.9791667 used=<memory:48128, vCores:42> cluster=<memory:49152, vCores:96>
2013-08-09 20:54:05,924 INFO org.apache.hadoop.yarn.server.resourcemanager.scheduler.capacity.ParentQueue: completedContainer queue=root usedCapacity=0.9791667 absoluteUsedCapacity=0.9791667 used=<memory:48128, vCores:42> cluster=<memory:49152, vCores:96>
2013-08-09 20:54:05,924 INFO org.apache.hadoop.yarn.server.resourcemanager.scheduler.capacity.CapacityScheduler: Application appattempt_1376080735992_0006_000001 released container container_1376080735992_0006_01_000035 on node: host: hadoop-210-7:35638 #containers=6 available=1024 used=7168 with event: FINISHED
2013-08-09 20:54:05,924 INFO org.apache.hadoop.yarn.server.resourcemanager.rmcontainer.RMContainerImpl: container_1376080735992_0006_01_000046 Container Transitioned from NEW to ALLOCATED
2013-08-09 20:54:05,924 INFO org.apache.hadoop.yarn.server.resourcemanager.RMAuditLogger: USER=ubuntu	OPERATION=AM Allocated Container	TARGET=SchedulerApp	RESULT=SUCCESS	APPID=application_1376080735992_0006	CONTAINERID=container_1376080735992_0006_01_000046
2013-08-09 20:54:05,925 INFO org.apache.hadoop.yarn.server.resourcemanager.scheduler.common.fica.FiCaSchedulerNode: Assigned container container_1376080735992_0006_01_000046 of capacity <memory:1024, vCores:1> on host hadoop-210-7:35638, which currently has 7 containers, <memory:8192, vCores:7> used and <memory:0, vCores:9> available
2013-08-09 20:54:05,926 INFO org.apache.hadoop.yarn.server.resourcemanager.scheduler.capacity.LeafQueue: assignedContainer application=application_1376080735992_0006 container=Container: [ContainerId: container_1376080735992_0006_01_000046, NodeId: hadoop-210-7:35638, NodeHttpAddress: hadoop-210-7:8042, Resource: <memory:1024, vCores:1>, Priority: 10, State: NEW, Token: null, Status: container_id {, app_attempt_id {, application_id {, id: 6, cluster_timestamp: 1376080735992, }, attemptId: 1, }, id: 46, }, state: C_NEW, ] containerId=container_1376080735992_0006_01_000046 queue=default: capacity=1.0, absoluteCapacity=1.0, usedResources=<memory:48128, vCores:42>usedCapacity=0.9791667, absoluteUsedCapacity=0.9791667, numApps=5, numContainers=42 usedCapacity=0.9791667 absoluteUsedCapacity=0.9791667 used=<memory:48128, vCores:42> cluster=<memory:49152, vCores:96>
2013-08-09 20:54:05,926 INFO org.apache.hadoop.yarn.server.resourcemanager.scheduler.capacity.ParentQueue: Re-sorting queues since queue: root.default stats: default: capacity=1.0, absoluteCapacity=1.0, usedResources=<memory:49152, vCores:43>usedCapacity=1.0, absoluteUsedCapacity=1.0, numApps=5, numContainers=43
2013-08-09 20:54:05,926 INFO org.apache.hadoop.yarn.server.resourcemanager.scheduler.capacity.ParentQueue: assignedContainer queue=root usedCapacity=1.0 absoluteUsedCapacity=1.0 used=<memory:49152, vCores:43> cluster=<memory:49152, vCores:96>
2013-08-09 20:54:06,245 INFO org.apache.hadoop.yarn.server.resourcemanager.rmcontainer.RMContainerImpl: container_1376080735992_0006_01_000045 Container Transitioned from ALLOCATED to ACQUIRED
2013-08-09 20:54:06,246 INFO org.apache.hadoop.yarn.server.resourcemanager.rmcontainer.RMContainerImpl: container_1376080735992_0006_01_000046 Container Transitioned from ALLOCATED to ACQUIRED
2013-08-09 20:54:06,453 INFO org.apache.hadoop.yarn.server.resourcemanager.rmcontainer.RMContainerImpl: container_1376080735992_0006_01_000045 Container Transitioned from ACQUIRED to RUNNING
2013-08-09 20:54:06,931 INFO org.apache.hadoop.yarn.server.resourcemanager.rmcontainer.RMContainerImpl: container_1376080735992_0006_01_000046 Container Transitioned from ACQUIRED to RUNNING
2013-08-09 20:54:07,262 INFO org.apache.hadoop.yarn.server.resourcemanager.scheduler.AppSchedulingInfo: checking for deactivate... 
2013-08-09 20:54:07,795 INFO org.apache.hadoop.yarn.server.resourcemanager.rmcontainer.RMContainerImpl: container_1376080735992_0006_01_000031 Container Transitioned from RUNNING to COMPLETED
2013-08-09 20:54:07,796 INFO org.apache.hadoop.yarn.server.resourcemanager.scheduler.common.fica.FiCaSchedulerApp: Completed container: container_1376080735992_0006_01_000031 in state: COMPLETED event:FINISHED
2013-08-09 20:54:07,796 INFO org.apache.hadoop.yarn.server.resourcemanager.RMAuditLogger: USER=ubuntu	OPERATION=AM Released Container	TARGET=SchedulerApp	RESULT=SUCCESS	APPID=application_1376080735992_0006	CONTAINERID=container_1376080735992_0006_01_000031
2013-08-09 20:54:07,796 INFO org.apache.hadoop.yarn.server.resourcemanager.scheduler.common.fica.FiCaSchedulerNode: Released container container_1376080735992_0006_01_000031 of capacity <memory:1024, vCores:1> on host hadoop-210-6:41207, which currently has 6 containers, <memory:7168, vCores:6> used and <memory:1024, vCores:10> available, release resources=true
2013-08-09 20:54:07,796 INFO org.apache.hadoop.yarn.server.resourcemanager.scheduler.capacity.LeafQueue: default used=<memory:48128, vCores:42> numContainers=42 user=ubuntu user-resources=<memory:48128, vCores:42>
2013-08-09 20:54:07,797 INFO org.apache.hadoop.yarn.server.resourcemanager.scheduler.capacity.LeafQueue: completedContainer container=Container: [ContainerId: container_1376080735992_0006_01_000031, NodeId: hadoop-210-6:41207, NodeHttpAddress: hadoop-210-6:8042, Resource: <memory:1024, vCores:1>, Priority: 20, State: NEW, Token: null, Status: container_id {, app_attempt_id {, application_id {, id: 6, cluster_timestamp: 1376080735992, }, attemptId: 1, }, id: 31, }, state: C_COMPLETE, diagnostics: "Container killed by the ApplicationMaster.\n\n", exit_status: 143, ] resource=<memory:1024, vCores:1> queue=default: capacity=1.0, absoluteCapacity=1.0, usedResources=<memory:48128, vCores:42>usedCapacity=0.9791667, absoluteUsedCapacity=0.9791667, numApps=5, numContainers=42 usedCapacity=0.9791667 absoluteUsedCapacity=0.9791667 used=<memory:48128, vCores:42> cluster=<memory:49152, vCores:96>
2013-08-09 20:54:07,797 INFO org.apache.hadoop.yarn.server.resourcemanager.scheduler.capacity.ParentQueue: completedContainer queue=root usedCapacity=0.9791667 absoluteUsedCapacity=0.9791667 used=<memory:48128, vCores:42> cluster=<memory:49152, vCores:96>
2013-08-09 20:54:07,798 INFO org.apache.hadoop.yarn.server.resourcemanager.scheduler.capacity.CapacityScheduler: Application appattempt_1376080735992_0006_000001 released container container_1376080735992_0006_01_000031 on node: host: hadoop-210-6:41207 #containers=6 available=1024 used=7168 with event: FINISHED
2013-08-09 20:54:07,798 INFO org.apache.hadoop.yarn.server.resourcemanager.rmcontainer.RMContainerImpl: container_1376080735992_0007_01_000005 Container Transitioned from NEW to ALLOCATED
2013-08-09 20:54:07,798 INFO org.apache.hadoop.yarn.server.resourcemanager.RMAuditLogger: USER=ubuntu	OPERATION=AM Allocated Container	TARGET=SchedulerApp	RESULT=SUCCESS	APPID=application_1376080735992_0007	CONTAINERID=container_1376080735992_0007_01_000005
2013-08-09 20:54:07,799 INFO org.apache.hadoop.yarn.server.resourcemanager.scheduler.common.fica.FiCaSchedulerNode: Assigned container container_1376080735992_0007_01_000005 of capacity <memory:1024, vCores:1> on host hadoop-210-6:41207, which currently has 7 containers, <memory:8192, vCores:7> used and <memory:0, vCores:9> available
2013-08-09 20:54:07,800 INFO org.apache.hadoop.yarn.server.resourcemanager.scheduler.capacity.LeafQueue: assignedContainer application=application_1376080735992_0007 container=Container: [ContainerId: container_1376080735992_0007_01_000005, NodeId: hadoop-210-6:41207, NodeHttpAddress: hadoop-210-6:8042, Resource: <memory:1024, vCores:1>, Priority: 20, State: NEW, Token: null, Status: container_id {, app_attempt_id {, application_id {, id: 7, cluster_timestamp: 1376080735992, }, attemptId: 1, }, id: 5, }, state: C_NEW, ] containerId=container_1376080735992_0007_01_000005 queue=default: capacity=1.0, absoluteCapacity=1.0, usedResources=<memory:48128, vCores:42>usedCapacity=0.9791667, absoluteUsedCapacity=0.9791667, numApps=5, numContainers=42 usedCapacity=0.9791667 absoluteUsedCapacity=0.9791667 used=<memory:48128, vCores:42> cluster=<memory:49152, vCores:96>
2013-08-09 20:54:07,800 INFO org.apache.hadoop.yarn.server.resourcemanager.scheduler.capacity.ParentQueue: Re-sorting queues since queue: root.default stats: default: capacity=1.0, absoluteCapacity=1.0, usedResources=<memory:49152, vCores:43>usedCapacity=1.0, absoluteUsedCapacity=1.0, numApps=5, numContainers=43
2013-08-09 20:54:07,800 INFO org.apache.hadoop.yarn.server.resourcemanager.scheduler.capacity.ParentQueue: assignedContainer queue=root usedCapacity=1.0 absoluteUsedCapacity=1.0 used=<memory:49152, vCores:43> cluster=<memory:49152, vCores:96>
2013-08-09 20:54:08,011 INFO org.apache.hadoop.yarn.server.resourcemanager.rmcontainer.RMContainerImpl: container_1376080735992_0006_01_000008 Container Transitioned from RUNNING to COMPLETED
2013-08-09 20:54:08,011 INFO org.apache.hadoop.yarn.server.resourcemanager.scheduler.common.fica.FiCaSchedulerApp: Completed container: container_1376080735992_0006_01_000008 in state: COMPLETED event:FINISHED
2013-08-09 20:54:08,011 INFO org.apache.hadoop.yarn.server.resourcemanager.RMAuditLogger: USER=ubuntu	OPERATION=AM Released Container	TARGET=SchedulerApp	RESULT=SUCCESS	APPID=application_1376080735992_0006	CONTAINERID=container_1376080735992_0006_01_000008
2013-08-09 20:54:08,012 INFO org.apache.hadoop.yarn.server.resourcemanager.scheduler.common.fica.FiCaSchedulerNode: Released container container_1376080735992_0006_01_000008 of capacity <memory:1024, vCores:1> on host hadoop-210-3:58589, which currently has 6 containers, <memory:7168, vCores:6> used and <memory:1024, vCores:10> available, release resources=true
2013-08-09 20:54:08,012 INFO org.apache.hadoop.yarn.server.resourcemanager.scheduler.capacity.LeafQueue: default used=<memory:48128, vCores:42> numContainers=42 user=ubuntu user-resources=<memory:48128, vCores:42>
2013-08-09 20:54:08,013 INFO org.apache.hadoop.yarn.server.resourcemanager.scheduler.capacity.LeafQueue: completedContainer container=Container: [ContainerId: container_1376080735992_0006_01_000008, NodeId: hadoop-210-3:58589, NodeHttpAddress: hadoop-210-3:8042, Resource: <memory:1024, vCores:1>, Priority: 20, State: NEW, Token: null, Status: container_id {, app_attempt_id {, application_id {, id: 6, cluster_timestamp: 1376080735992, }, attemptId: 1, }, id: 8, }, state: C_COMPLETE, diagnostics: "Container killed by the ApplicationMaster.\n", exit_status: 0, ] resource=<memory:1024, vCores:1> queue=default: capacity=1.0, absoluteCapacity=1.0, usedResources=<memory:48128, vCores:42>usedCapacity=0.9791667, absoluteUsedCapacity=0.9791667, numApps=5, numContainers=42 usedCapacity=0.9791667 absoluteUsedCapacity=0.9791667 used=<memory:48128, vCores:42> cluster=<memory:49152, vCores:96>
2013-08-09 20:54:08,013 INFO org.apache.hadoop.yarn.server.resourcemanager.scheduler.capacity.ParentQueue: completedContainer queue=root usedCapacity=0.9791667 absoluteUsedCapacity=0.9791667 used=<memory:48128, vCores:42> cluster=<memory:49152, vCores:96>
2013-08-09 20:54:08,013 INFO org.apache.hadoop.yarn.server.resourcemanager.scheduler.capacity.CapacityScheduler: Application appattempt_1376080735992_0006_000001 released container container_1376080735992_0006_01_000008 on node: host: hadoop-210-3:58589 #containers=6 available=1024 used=7168 with event: FINISHED
2013-08-09 20:54:08,014 INFO org.apache.hadoop.yarn.server.resourcemanager.rmcontainer.RMContainerImpl: container_1376080735992_0007_01_000006 Container Transitioned from NEW to ALLOCATED
2013-08-09 20:54:08,014 INFO org.apache.hadoop.yarn.server.resourcemanager.RMAuditLogger: USER=ubuntu	OPERATION=AM Allocated Container	TARGET=SchedulerApp	RESULT=SUCCESS	APPID=application_1376080735992_0007	CONTAINERID=container_1376080735992_0007_01_000006
2013-08-09 20:54:08,014 INFO org.apache.hadoop.yarn.server.resourcemanager.scheduler.common.fica.FiCaSchedulerNode: Assigned container container_1376080735992_0007_01_000006 of capacity <memory:1024, vCores:1> on host hadoop-210-3:58589, which currently has 7 containers, <memory:8192, vCores:7> used and <memory:0, vCores:9> available
2013-08-09 20:54:08,015 INFO org.apache.hadoop.yarn.server.resourcemanager.scheduler.capacity.LeafQueue: assignedContainer application=application_1376080735992_0007 container=Container: [ContainerId: container_1376080735992_0007_01_000006, NodeId: hadoop-210-3:58589, NodeHttpAddress: hadoop-210-3:8042, Resource: <memory:1024, vCores:1>, Priority: 20, State: NEW, Token: null, Status: container_id {, app_attempt_id {, application_id {, id: 7, cluster_timestamp: 1376080735992, }, attemptId: 1, }, id: 6, }, state: C_NEW, ] containerId=container_1376080735992_0007_01_000006 queue=default: capacity=1.0, absoluteCapacity=1.0, usedResources=<memory:48128, vCores:42>usedCapacity=0.9791667, absoluteUsedCapacity=0.9791667, numApps=5, numContainers=42 usedCapacity=0.9791667 absoluteUsedCapacity=0.9791667 used=<memory:48128, vCores:42> cluster=<memory:49152, vCores:96>
2013-08-09 20:54:08,015 INFO org.apache.hadoop.yarn.server.resourcemanager.scheduler.capacity.ParentQueue: Re-sorting queues since queue: root.default stats: default: capacity=1.0, absoluteCapacity=1.0, usedResources=<memory:49152, vCores:43>usedCapacity=1.0, absoluteUsedCapacity=1.0, numApps=5, numContainers=43
2013-08-09 20:54:08,015 INFO org.apache.hadoop.yarn.server.resourcemanager.scheduler.capacity.ParentQueue: assignedContainer queue=root usedCapacity=1.0 absoluteUsedCapacity=1.0 used=<memory:49152, vCores:43> cluster=<memory:49152, vCores:96>
2013-08-09 20:54:08,183 INFO org.apache.hadoop.yarn.server.resourcemanager.rmcontainer.RMContainerImpl: container_1376080735992_0007_01_000005 Container Transitioned from ALLOCATED to ACQUIRED
2013-08-09 20:54:08,185 INFO org.apache.hadoop.yarn.server.resourcemanager.rmcontainer.RMContainerImpl: container_1376080735992_0007_01_000006 Container Transitioned from ALLOCATED to ACQUIRED
2013-08-09 20:54:08,208 INFO org.apache.hadoop.yarn.server.resourcemanager.rmcontainer.RMContainerImpl: container_1376080735992_0006_01_000004 Container Transitioned from RUNNING to COMPLETED
2013-08-09 20:54:08,208 INFO org.apache.hadoop.yarn.server.resourcemanager.scheduler.common.fica.FiCaSchedulerApp: Completed container: container_1376080735992_0006_01_000004 in state: COMPLETED event:FINISHED
2013-08-09 20:54:08,208 INFO org.apache.hadoop.yarn.server.resourcemanager.RMAuditLogger: USER=ubuntu	OPERATION=AM Released Container	TARGET=SchedulerApp	RESULT=SUCCESS	APPID=application_1376080735992_0006	CONTAINERID=container_1376080735992_0006_01_000004
2013-08-09 20:54:08,208 INFO org.apache.hadoop.yarn.server.resourcemanager.scheduler.common.fica.FiCaSchedulerNode: Released container container_1376080735992_0006_01_000004 of capacity <memory:1024, vCores:1> on host hadoop-210-4:47596, which currently has 6 containers, <memory:7168, vCores:6> used and <memory:1024, vCores:10> available, release resources=true
2013-08-09 20:54:08,209 INFO org.apache.hadoop.yarn.server.resourcemanager.scheduler.capacity.LeafQueue: default used=<memory:48128, vCores:42> numContainers=42 user=ubuntu user-resources=<memory:48128, vCores:42>
2013-08-09 20:54:08,210 INFO org.apache.hadoop.yarn.server.resourcemanager.scheduler.capacity.LeafQueue: completedContainer container=Container: [ContainerId: container_1376080735992_0006_01_000004, NodeId: hadoop-210-4:47596, NodeHttpAddress: hadoop-210-4:8042, Resource: <memory:1024, vCores:1>, Priority: 20, State: NEW, Token: null, Status: container_id {, app_attempt_id {, application_id {, id: 6, cluster_timestamp: 1376080735992, }, attemptId: 1, }, id: 4, }, state: C_COMPLETE, diagnostics: "Container killed by the ApplicationMaster.\n", exit_status: 0, ] resource=<memory:1024, vCores:1> queue=default: capacity=1.0, absoluteCapacity=1.0, usedResources=<memory:48128, vCores:42>usedCapacity=0.9791667, absoluteUsedCapacity=0.9791667, numApps=5, numContainers=42 usedCapacity=0.9791667 absoluteUsedCapacity=0.9791667 used=<memory:48128, vCores:42> cluster=<memory:49152, vCores:96>
2013-08-09 20:54:08,210 INFO org.apache.hadoop.yarn.server.resourcemanager.scheduler.capacity.ParentQueue: completedContainer queue=root usedCapacity=0.9791667 absoluteUsedCapacity=0.9791667 used=<memory:48128, vCores:42> cluster=<memory:49152, vCores:96>
2013-08-09 20:54:08,210 INFO org.apache.hadoop.yarn.server.resourcemanager.scheduler.capacity.CapacityScheduler: Application appattempt_1376080735992_0006_000001 released container container_1376080735992_0006_01_000004 on node: host: hadoop-210-4:47596 #containers=6 available=1024 used=7168 with event: FINISHED
2013-08-09 20:54:08,211 INFO org.apache.hadoop.yarn.server.resourcemanager.rmcontainer.RMContainerImpl: container_1376080735992_0007_01_000007 Container Transitioned from NEW to ALLOCATED
2013-08-09 20:54:08,211 INFO org.apache.hadoop.yarn.server.resourcemanager.RMAuditLogger: USER=ubuntu	OPERATION=AM Allocated Container	TARGET=SchedulerApp	RESULT=SUCCESS	APPID=application_1376080735992_0007	CONTAINERID=container_1376080735992_0007_01_000007
2013-08-09 20:54:08,211 INFO org.apache.hadoop.yarn.server.resourcemanager.scheduler.common.fica.FiCaSchedulerNode: Assigned container container_1376080735992_0007_01_000007 of capacity <memory:1024, vCores:1> on host hadoop-210-4:47596, which currently has 7 containers, <memory:8192, vCores:7> used and <memory:0, vCores:9> available
2013-08-09 20:54:08,212 INFO org.apache.hadoop.yarn.server.resourcemanager.scheduler.capacity.LeafQueue: assignedContainer application=application_1376080735992_0007 container=Container: [ContainerId: container_1376080735992_0007_01_000007, NodeId: hadoop-210-4:47596, NodeHttpAddress: hadoop-210-4:8042, Resource: <memory:1024, vCores:1>, Priority: 20, State: NEW, Token: null, Status: container_id {, app_attempt_id {, application_id {, id: 7, cluster_timestamp: 1376080735992, }, attemptId: 1, }, id: 7, }, state: C_NEW, ] containerId=container_1376080735992_0007_01_000007 queue=default: capacity=1.0, absoluteCapacity=1.0, usedResources=<memory:48128, vCores:42>usedCapacity=0.9791667, absoluteUsedCapacity=0.9791667, numApps=5, numContainers=42 usedCapacity=0.9791667 absoluteUsedCapacity=0.9791667 used=<memory:48128, vCores:42> cluster=<memory:49152, vCores:96>
2013-08-09 20:54:08,212 INFO org.apache.hadoop.yarn.server.resourcemanager.scheduler.capacity.ParentQueue: Re-sorting queues since queue: root.default stats: default: capacity=1.0, absoluteCapacity=1.0, usedResources=<memory:49152, vCores:43>usedCapacity=1.0, absoluteUsedCapacity=1.0, numApps=5, numContainers=43
2013-08-09 20:54:08,212 INFO org.apache.hadoop.yarn.server.resourcemanager.scheduler.capacity.ParentQueue: assignedContainer queue=root usedCapacity=1.0 absoluteUsedCapacity=1.0 used=<memory:49152, vCores:43> cluster=<memory:49152, vCores:96>
2013-08-09 20:54:09,005 INFO org.apache.hadoop.yarn.server.resourcemanager.rmcontainer.RMContainerImpl: container_1376080735992_0006_01_000034 Container Transitioned from RUNNING to COMPLETED
2013-08-09 20:54:09,005 INFO org.apache.hadoop.yarn.server.resourcemanager.scheduler.common.fica.FiCaSchedulerApp: Completed container: container_1376080735992_0006_01_000034 in state: COMPLETED event:FINISHED
2013-08-09 20:54:09,005 INFO org.apache.hadoop.yarn.server.resourcemanager.RMAuditLogger: USER=ubuntu	OPERATION=AM Released Container	TARGET=SchedulerApp	RESULT=SUCCESS	APPID=application_1376080735992_0006	CONTAINERID=container_1376080735992_0006_01_000034
2013-08-09 20:54:09,006 INFO org.apache.hadoop.yarn.server.resourcemanager.scheduler.common.fica.FiCaSchedulerNode: Released container container_1376080735992_0006_01_000034 of capacity <memory:1024, vCores:1> on host hadoop-210-7:35638, which currently has 6 containers, <memory:7168, vCores:6> used and <memory:1024, vCores:10> available, release resources=true
2013-08-09 20:54:09,006 INFO org.apache.hadoop.yarn.server.resourcemanager.scheduler.capacity.LeafQueue: default used=<memory:48128, vCores:42> numContainers=42 user=ubuntu user-resources=<memory:48128, vCores:42>
2013-08-09 20:54:09,007 INFO org.apache.hadoop.yarn.server.resourcemanager.scheduler.capacity.LeafQueue: completedContainer container=Container: [ContainerId: container_1376080735992_0006_01_000034, NodeId: hadoop-210-7:35638, NodeHttpAddress: hadoop-210-7:8042, Resource: <memory:1024, vCores:1>, Priority: 20, State: NEW, Token: null, Status: container_id {, app_attempt_id {, application_id {, id: 6, cluster_timestamp: 1376080735992, }, attemptId: 1, }, id: 34, }, state: C_COMPLETE, diagnostics: "Container killed by the ApplicationMaster.\n\n", exit_status: 143, ] resource=<memory:1024, vCores:1> queue=default: capacity=1.0, absoluteCapacity=1.0, usedResources=<memory:48128, vCores:42>usedCapacity=0.9791667, absoluteUsedCapacity=0.9791667, numApps=5, numContainers=42 usedCapacity=0.9791667 absoluteUsedCapacity=0.9791667 used=<memory:48128, vCores:42> cluster=<memory:49152, vCores:96>
2013-08-09 20:54:09,007 INFO org.apache.hadoop.yarn.server.resourcemanager.scheduler.capacity.ParentQueue: completedContainer queue=root usedCapacity=0.9791667 absoluteUsedCapacity=0.9791667 used=<memory:48128, vCores:42> cluster=<memory:49152, vCores:96>
2013-08-09 20:54:09,007 INFO org.apache.hadoop.yarn.server.resourcemanager.scheduler.capacity.CapacityScheduler: Application appattempt_1376080735992_0006_000001 released container container_1376080735992_0006_01_000034 on node: host: hadoop-210-7:35638 #containers=6 available=1024 used=7168 with event: FINISHED
2013-08-09 20:54:09,008 INFO org.apache.hadoop.yarn.server.resourcemanager.rmcontainer.RMContainerImpl: container_1376080735992_0006_01_000038 Container Transitioned from RUNNING to COMPLETED
2013-08-09 20:54:09,008 INFO org.apache.hadoop.yarn.server.resourcemanager.scheduler.common.fica.FiCaSchedulerApp: Completed container: container_1376080735992_0006_01_000038 in state: COMPLETED event:FINISHED
2013-08-09 20:54:09,008 INFO org.apache.hadoop.yarn.server.resourcemanager.RMAuditLogger: USER=ubuntu	OPERATION=AM Released Container	TARGET=SchedulerApp	RESULT=SUCCESS	APPID=application_1376080735992_0006	CONTAINERID=container_1376080735992_0006_01_000038
2013-08-09 20:54:09,008 INFO org.apache.hadoop.yarn.server.resourcemanager.scheduler.common.fica.FiCaSchedulerNode: Released container container_1376080735992_0006_01_000038 of capacity <memory:1024, vCores:1> on host hadoop-210-7:35638, which currently has 5 containers, <memory:6144, vCores:5> used and <memory:2048, vCores:11> available, release resources=true
2013-08-09 20:54:09,008 INFO org.apache.hadoop.yarn.server.resourcemanager.scheduler.capacity.LeafQueue: default used=<memory:47104, vCores:41> numContainers=41 user=ubuntu user-resources=<memory:47104, vCores:41>
2013-08-09 20:54:09,009 INFO org.apache.hadoop.yarn.server.resourcemanager.scheduler.capacity.LeafQueue: completedContainer container=Container: [ContainerId: container_1376080735992_0006_01_000038, NodeId: hadoop-210-7:35638, NodeHttpAddress: hadoop-210-7:8042, Resource: <memory:1024, vCores:1>, Priority: 20, State: NEW, Token: null, Status: container_id {, app_attempt_id {, application_id {, id: 6, cluster_timestamp: 1376080735992, }, attemptId: 1, }, id: 38, }, state: C_COMPLETE, diagnostics: "Container killed by the ApplicationMaster.\n\n", exit_status: 143, ] resource=<memory:1024, vCores:1> queue=default: capacity=1.0, absoluteCapacity=1.0, usedResources=<memory:47104, vCores:41>usedCapacity=0.9583333, absoluteUsedCapacity=0.9583333, numApps=5, numContainers=41 usedCapacity=0.9583333 absoluteUsedCapacity=0.9583333 used=<memory:47104, vCores:41> cluster=<memory:49152, vCores:96>
2013-08-09 20:54:09,009 INFO org.apache.hadoop.yarn.server.resourcemanager.scheduler.capacity.ParentQueue: completedContainer queue=root usedCapacity=0.9583333 absoluteUsedCapacity=0.9583333 used=<memory:47104, vCores:41> cluster=<memory:49152, vCores:96>
2013-08-09 20:54:09,010 INFO org.apache.hadoop.yarn.server.resourcemanager.scheduler.capacity.CapacityScheduler: Application appattempt_1376080735992_0006_000001 released container container_1376080735992_0006_01_000038 on node: host: hadoop-210-7:35638 #containers=5 available=2048 used=6144 with event: FINISHED
2013-08-09 20:54:09,010 INFO org.apache.hadoop.yarn.server.resourcemanager.rmcontainer.RMContainerImpl: container_1376080735992_0006_01_000039 Container Transitioned from RUNNING to COMPLETED
2013-08-09 20:54:09,010 INFO org.apache.hadoop.yarn.server.resourcemanager.scheduler.common.fica.FiCaSchedulerApp: Completed container: container_1376080735992_0006_01_000039 in state: COMPLETED event:FINISHED
2013-08-09 20:54:09,010 INFO org.apache.hadoop.yarn.server.resourcemanager.RMAuditLogger: USER=ubuntu	OPERATION=AM Released Container	TARGET=SchedulerApp	RESULT=SUCCESS	APPID=application_1376080735992_0006	CONTAINERID=container_1376080735992_0006_01_000039
2013-08-09 20:54:09,010 INFO org.apache.hadoop.yarn.server.resourcemanager.scheduler.common.fica.FiCaSchedulerNode: Released container container_1376080735992_0006_01_000039 of capacity <memory:1024, vCores:1> on host hadoop-210-7:35638, which currently has 4 containers, <memory:5120, vCores:4> used and <memory:3072, vCores:12> available, release resources=true
2013-08-09 20:54:09,011 INFO org.apache.hadoop.yarn.server.resourcemanager.scheduler.capacity.LeafQueue: default used=<memory:46080, vCores:40> numContainers=40 user=ubuntu user-resources=<memory:46080, vCores:40>
2013-08-09 20:54:09,012 INFO org.apache.hadoop.yarn.server.resourcemanager.scheduler.capacity.LeafQueue: completedContainer container=Container: [ContainerId: container_1376080735992_0006_01_000039, NodeId: hadoop-210-7:35638, NodeHttpAddress: hadoop-210-7:8042, Resource: <memory:1024, vCores:1>, Priority: 20, State: NEW, Token: null, Status: container_id {, app_attempt_id {, application_id {, id: 6, cluster_timestamp: 1376080735992, }, attemptId: 1, }, id: 39, }, state: C_COMPLETE, diagnostics: "Container killed by the ApplicationMaster.\n\n", exit_status: 143, ] resource=<memory:1024, vCores:1> queue=default: capacity=1.0, absoluteCapacity=1.0, usedResources=<memory:46080, vCores:40>usedCapacity=0.9375, absoluteUsedCapacity=0.9375, numApps=5, numContainers=40 usedCapacity=0.9375 absoluteUsedCapacity=0.9375 used=<memory:46080, vCores:40> cluster=<memory:49152, vCores:96>
2013-08-09 20:54:09,012 INFO org.apache.hadoop.yarn.server.resourcemanager.scheduler.capacity.ParentQueue: completedContainer queue=root usedCapacity=0.9375 absoluteUsedCapacity=0.9375 used=<memory:46080, vCores:40> cluster=<memory:49152, vCores:96>
2013-08-09 20:54:09,012 INFO org.apache.hadoop.yarn.server.resourcemanager.scheduler.capacity.CapacityScheduler: Application appattempt_1376080735992_0006_000001 released container container_1376080735992_0006_01_000039 on node: host: hadoop-210-7:35638 #containers=4 available=3072 used=5120 with event: FINISHED
2013-08-09 20:54:09,013 INFO org.apache.hadoop.yarn.server.resourcemanager.rmcontainer.RMContainerImpl: container_1376080735992_0007_01_000008 Container Transitioned from NEW to ALLOCATED
2013-08-09 20:54:09,013 INFO org.apache.hadoop.yarn.server.resourcemanager.RMAuditLogger: USER=ubuntu	OPERATION=AM Allocated Container	TARGET=SchedulerApp	RESULT=SUCCESS	APPID=application_1376080735992_0007	CONTAINERID=container_1376080735992_0007_01_000008
2013-08-09 20:54:09,013 INFO org.apache.hadoop.yarn.server.resourcemanager.scheduler.common.fica.FiCaSchedulerNode: Assigned container container_1376080735992_0007_01_000008 of capacity <memory:1024, vCores:1> on host hadoop-210-7:35638, which currently has 5 containers, <memory:6144, vCores:5> used and <memory:2048, vCores:11> available
2013-08-09 20:54:09,014 INFO org.apache.hadoop.yarn.server.resourcemanager.scheduler.capacity.LeafQueue: assignedContainer application=application_1376080735992_0007 container=Container: [ContainerId: container_1376080735992_0007_01_000008, NodeId: hadoop-210-7:35638, NodeHttpAddress: hadoop-210-7:8042, Resource: <memory:1024, vCores:1>, Priority: 20, State: NEW, Token: null, Status: container_id {, app_attempt_id {, application_id {, id: 7, cluster_timestamp: 1376080735992, }, attemptId: 1, }, id: 8, }, state: C_NEW, ] containerId=container_1376080735992_0007_01_000008 queue=default: capacity=1.0, absoluteCapacity=1.0, usedResources=<memory:46080, vCores:40>usedCapacity=0.9375, absoluteUsedCapacity=0.9375, numApps=5, numContainers=40 usedCapacity=0.9375 absoluteUsedCapacity=0.9375 used=<memory:46080, vCores:40> cluster=<memory:49152, vCores:96>
2013-08-09 20:54:09,015 INFO org.apache.hadoop.yarn.server.resourcemanager.scheduler.capacity.ParentQueue: Re-sorting queues since queue: root.default stats: default: capacity=1.0, absoluteCapacity=1.0, usedResources=<memory:47104, vCores:41>usedCapacity=0.9583333, absoluteUsedCapacity=0.9583333, numApps=5, numContainers=41
2013-08-09 20:54:09,015 INFO org.apache.hadoop.yarn.server.resourcemanager.scheduler.capacity.ParentQueue: assignedContainer queue=root usedCapacity=0.9583333 absoluteUsedCapacity=0.9583333 used=<memory:47104, vCores:41> cluster=<memory:49152, vCores:96>
2013-08-09 20:54:09,015 INFO org.apache.hadoop.yarn.server.resourcemanager.rmcontainer.RMContainerImpl: container_1376080735992_0007_01_000009 Container Transitioned from NEW to ALLOCATED
2013-08-09 20:54:09,015 INFO org.apache.hadoop.yarn.server.resourcemanager.RMAuditLogger: USER=ubuntu	OPERATION=AM Allocated Container	TARGET=SchedulerApp	RESULT=SUCCESS	APPID=application_1376080735992_0007	CONTAINERID=container_1376080735992_0007_01_000009
2013-08-09 20:54:09,016 INFO org.apache.hadoop.yarn.server.resourcemanager.scheduler.common.fica.FiCaSchedulerNode: Assigned container container_1376080735992_0007_01_000009 of capacity <memory:1024, vCores:1> on host hadoop-210-7:35638, which currently has 6 containers, <memory:7168, vCores:6> used and <memory:1024, vCores:10> available
2013-08-09 20:54:09,017 INFO org.apache.hadoop.yarn.server.resourcemanager.scheduler.capacity.LeafQueue: assignedContainer application=application_1376080735992_0007 container=Container: [ContainerId: container_1376080735992_0007_01_000009, NodeId: hadoop-210-7:35638, NodeHttpAddress: hadoop-210-7:8042, Resource: <memory:1024, vCores:1>, Priority: 20, State: NEW, Token: null, Status: container_id {, app_attempt_id {, application_id {, id: 7, cluster_timestamp: 1376080735992, }, attemptId: 1, }, id: 9, }, state: C_NEW, ] containerId=container_1376080735992_0007_01_000009 queue=default: capacity=1.0, absoluteCapacity=1.0, usedResources=<memory:47104, vCores:41>usedCapacity=0.9583333, absoluteUsedCapacity=0.9583333, numApps=5, numContainers=41 usedCapacity=0.9583333 absoluteUsedCapacity=0.9583333 used=<memory:47104, vCores:41> cluster=<memory:49152, vCores:96>
2013-08-09 20:54:09,017 INFO org.apache.hadoop.yarn.server.resourcemanager.scheduler.capacity.ParentQueue: Re-sorting queues since queue: root.default stats: default: capacity=1.0, absoluteCapacity=1.0, usedResources=<memory:48128, vCores:42>usedCapacity=0.9791667, absoluteUsedCapacity=0.9791667, numApps=5, numContainers=42
2013-08-09 20:54:09,017 INFO org.apache.hadoop.yarn.server.resourcemanager.scheduler.capacity.ParentQueue: assignedContainer queue=root usedCapacity=0.9791667 absoluteUsedCapacity=0.9791667 used=<memory:48128, vCores:42> cluster=<memory:49152, vCores:96>
2013-08-09 20:54:09,018 INFO org.apache.hadoop.yarn.server.resourcemanager.rmcontainer.RMContainerImpl: container_1376080735992_0007_01_000010 Container Transitioned from NEW to ALLOCATED
2013-08-09 20:54:09,018 INFO org.apache.hadoop.yarn.server.resourcemanager.RMAuditLogger: USER=ubuntu	OPERATION=AM Allocated Container	TARGET=SchedulerApp	RESULT=SUCCESS	APPID=application_1376080735992_0007	CONTAINERID=container_1376080735992_0007_01_000010
2013-08-09 20:54:09,018 INFO org.apache.hadoop.yarn.server.resourcemanager.scheduler.common.fica.FiCaSchedulerNode: Assigned container container_1376080735992_0007_01_000010 of capacity <memory:1024, vCores:1> on host hadoop-210-7:35638, which currently has 7 containers, <memory:8192, vCores:7> used and <memory:0, vCores:9> available
2013-08-09 20:54:09,019 INFO org.apache.hadoop.yarn.server.resourcemanager.scheduler.capacity.LeafQueue: assignedContainer application=application_1376080735992_0007 container=Container: [ContainerId: container_1376080735992_0007_01_000010, NodeId: hadoop-210-7:35638, NodeHttpAddress: hadoop-210-7:8042, Resource: <memory:1024, vCores:1>, Priority: 20, State: NEW, Token: null, Status: container_id {, app_attempt_id {, application_id {, id: 7, cluster_timestamp: 1376080735992, }, attemptId: 1, }, id: 10, }, state: C_NEW, ] containerId=container_1376080735992_0007_01_000010 queue=default: capacity=1.0, absoluteCapacity=1.0, usedResources=<memory:48128, vCores:42>usedCapacity=0.9791667, absoluteUsedCapacity=0.9791667, numApps=5, numContainers=42 usedCapacity=0.9791667 absoluteUsedCapacity=0.9791667 used=<memory:48128, vCores:42> cluster=<memory:49152, vCores:96>
2013-08-09 20:54:09,020 INFO org.apache.hadoop.yarn.server.resourcemanager.scheduler.capacity.ParentQueue: Re-sorting queues since queue: root.default stats: default: capacity=1.0, absoluteCapacity=1.0, usedResources=<memory:49152, vCores:43>usedCapacity=1.0, absoluteUsedCapacity=1.0, numApps=5, numContainers=43
2013-08-09 20:54:09,020 INFO org.apache.hadoop.yarn.server.resourcemanager.scheduler.capacity.ParentQueue: assignedContainer queue=root usedCapacity=1.0 absoluteUsedCapacity=1.0 used=<memory:49152, vCores:43> cluster=<memory:49152, vCores:96>
2013-08-09 20:54:09,037 INFO org.apache.hadoop.yarn.server.resourcemanager.rmcontainer.RMContainerImpl: container_1376080735992_0007_01_000006 Container Transitioned from ACQUIRED to RUNNING
2013-08-09 20:54:09,223 INFO org.apache.hadoop.yarn.server.resourcemanager.rmcontainer.RMContainerImpl: container_1376080735992_0007_01_000007 Container Transitioned from ALLOCATED to ACQUIRED
2013-08-09 20:54:09,225 INFO org.apache.hadoop.yarn.server.resourcemanager.rmcontainer.RMContainerImpl: container_1376080735992_0007_01_000008 Container Transitioned from ALLOCATED to ACQUIRED
2013-08-09 20:54:09,225 INFO org.apache.hadoop.yarn.server.resourcemanager.rmcontainer.RMContainerImpl: container_1376080735992_0007_01_000009 Container Transitioned from ALLOCATED to ACQUIRED
2013-08-09 20:54:09,225 INFO org.apache.hadoop.yarn.server.resourcemanager.rmcontainer.RMContainerImpl: container_1376080735992_0007_01_000010 Container Transitioned from ALLOCATED to ACQUIRED
2013-08-09 20:54:09,673 INFO org.apache.hadoop.yarn.server.resourcemanager.rmcontainer.RMContainerImpl: container_1376080735992_0006_01_000011 Container Transitioned from RUNNING to COMPLETED
2013-08-09 20:54:09,673 INFO org.apache.hadoop.yarn.server.resourcemanager.scheduler.common.fica.FiCaSchedulerApp: Completed container: container_1376080735992_0006_01_000011 in state: COMPLETED event:FINISHED
2013-08-09 20:54:09,673 INFO org.apache.hadoop.yarn.server.resourcemanager.RMAuditLogger: USER=ubuntu	OPERATION=AM Released Container	TARGET=SchedulerApp	RESULT=SUCCESS	APPID=application_1376080735992_0006	CONTAINERID=container_1376080735992_0006_01_000011
2013-08-09 20:54:09,673 INFO org.apache.hadoop.yarn.server.resourcemanager.scheduler.common.fica.FiCaSchedulerNode: Released container container_1376080735992_0006_01_000011 of capacity <memory:1024, vCores:1> on host hadoop-210-3:58589, which currently has 6 containers, <memory:7168, vCores:6> used and <memory:1024, vCores:10> available, release resources=true
2013-08-09 20:54:09,673 INFO org.apache.hadoop.yarn.server.resourcemanager.scheduler.capacity.LeafQueue: default used=<memory:48128, vCores:42> numContainers=42 user=ubuntu user-resources=<memory:48128, vCores:42>
2013-08-09 20:54:09,675 INFO org.apache.hadoop.yarn.server.resourcemanager.scheduler.capacity.LeafQueue: completedContainer container=Container: [ContainerId: container_1376080735992_0006_01_000011, NodeId: hadoop-210-3:58589, NodeHttpAddress: hadoop-210-3:8042, Resource: <memory:1024, vCores:1>, Priority: 20, State: NEW, Token: null, Status: container_id {, app_attempt_id {, application_id {, id: 6, cluster_timestamp: 1376080735992, }, attemptId: 1, }, id: 11, }, state: C_COMPLETE, diagnostics: "Container killed by the ApplicationMaster.\n\n", exit_status: 143, ] resource=<memory:1024, vCores:1> queue=default: capacity=1.0, absoluteCapacity=1.0, usedResources=<memory:48128, vCores:42>usedCapacity=0.9791667, absoluteUsedCapacity=0.9791667, numApps=5, numContainers=42 usedCapacity=0.9791667 absoluteUsedCapacity=0.9791667 used=<memory:48128, vCores:42> cluster=<memory:49152, vCores:96>
2013-08-09 20:54:09,675 INFO org.apache.hadoop.yarn.server.resourcemanager.scheduler.capacity.ParentQueue: completedContainer queue=root usedCapacity=0.9791667 absoluteUsedCapacity=0.9791667 used=<memory:48128, vCores:42> cluster=<memory:49152, vCores:96>
2013-08-09 20:54:09,675 INFO org.apache.hadoop.yarn.server.resourcemanager.scheduler.capacity.CapacityScheduler: Application appattempt_1376080735992_0006_000001 released container container_1376080735992_0006_01_000011 on node: host: hadoop-210-3:58589 #containers=6 available=1024 used=7168 with event: FINISHED
2013-08-09 20:54:09,676 INFO org.apache.hadoop.yarn.server.resourcemanager.rmcontainer.RMContainerImpl: container_1376080735992_0007_01_000011 Container Transitioned from NEW to ALLOCATED
2013-08-09 20:54:09,676 INFO org.apache.hadoop.yarn.server.resourcemanager.RMAuditLogger: USER=ubuntu	OPERATION=AM Allocated Container	TARGET=SchedulerApp	RESULT=SUCCESS	APPID=application_1376080735992_0007	CONTAINERID=container_1376080735992_0007_01_000011
2013-08-09 20:54:09,676 INFO org.apache.hadoop.yarn.server.resourcemanager.scheduler.common.fica.FiCaSchedulerNode: Assigned container container_1376080735992_0007_01_000011 of capacity <memory:1024, vCores:1> on host hadoop-210-3:58589, which currently has 7 containers, <memory:8192, vCores:7> used and <memory:0, vCores:9> available
2013-08-09 20:54:09,677 INFO org.apache.hadoop.yarn.server.resourcemanager.scheduler.capacity.LeafQueue: assignedContainer application=application_1376080735992_0007 container=Container: [ContainerId: container_1376080735992_0007_01_000011, NodeId: hadoop-210-3:58589, NodeHttpAddress: hadoop-210-3:8042, Resource: <memory:1024, vCores:1>, Priority: 20, State: NEW, Token: null, Status: container_id {, app_attempt_id {, application_id {, id: 7, cluster_timestamp: 1376080735992, }, attemptId: 1, }, id: 11, }, state: C_NEW, ] containerId=container_1376080735992_0007_01_000011 queue=default: capacity=1.0, absoluteCapacity=1.0, usedResources=<memory:48128, vCores:42>usedCapacity=0.9791667, absoluteUsedCapacity=0.9791667, numApps=5, numContainers=42 usedCapacity=0.9791667 absoluteUsedCapacity=0.9791667 used=<memory:48128, vCores:42> cluster=<memory:49152, vCores:96>
2013-08-09 20:54:09,677 INFO org.apache.hadoop.yarn.server.resourcemanager.scheduler.capacity.ParentQueue: Re-sorting queues since queue: root.default stats: default: capacity=1.0, absoluteCapacity=1.0, usedResources=<memory:49152, vCores:43>usedCapacity=1.0, absoluteUsedCapacity=1.0, numApps=5, numContainers=43
2013-08-09 20:54:09,678 INFO org.apache.hadoop.yarn.server.resourcemanager.scheduler.capacity.ParentQueue: assignedContainer queue=root usedCapacity=1.0 absoluteUsedCapacity=1.0 used=<memory:49152, vCores:43> cluster=<memory:49152, vCores:96>
2013-08-09 20:54:09,711 INFO org.apache.hadoop.yarn.server.resourcemanager.rmcontainer.RMContainerImpl: container_1376080735992_0007_01_000005 Container Transitioned from ACQUIRED to RUNNING
2013-08-09 20:54:10,024 INFO org.apache.hadoop.yarn.server.resourcemanager.rmcontainer.RMContainerImpl: container_1376080735992_0007_01_000008 Container Transitioned from ACQUIRED to RUNNING
2013-08-09 20:54:10,024 INFO org.apache.hadoop.yarn.server.resourcemanager.rmcontainer.RMContainerImpl: container_1376080735992_0007_01_000009 Container Transitioned from ACQUIRED to RUNNING
2013-08-09 20:54:10,024 INFO org.apache.hadoop.yarn.server.resourcemanager.rmcontainer.RMContainerImpl: container_1376080735992_0007_01_000010 Container Transitioned from ACQUIRED to RUNNING
2013-08-09 20:54:10,025 INFO org.apache.hadoop.yarn.server.resourcemanager.rmcontainer.RMContainerImpl: container_1376080735992_0006_01_000036 Container Transitioned from RUNNING to COMPLETED
2013-08-09 20:54:10,025 INFO org.apache.hadoop.yarn.server.resourcemanager.scheduler.common.fica.FiCaSchedulerApp: Completed container: container_1376080735992_0006_01_000036 in state: COMPLETED event:FINISHED
2013-08-09 20:54:10,025 INFO org.apache.hadoop.yarn.server.resourcemanager.RMAuditLogger: USER=ubuntu	OPERATION=AM Released Container	TARGET=SchedulerApp	RESULT=SUCCESS	APPID=application_1376080735992_0006	CONTAINERID=container_1376080735992_0006_01_000036
2013-08-09 20:54:10,025 INFO org.apache.hadoop.yarn.server.resourcemanager.scheduler.common.fica.FiCaSchedulerNode: Released container container_1376080735992_0006_01_000036 of capacity <memory:1024, vCores:1> on host hadoop-210-7:35638, which currently has 6 containers, <memory:7168, vCores:6> used and <memory:1024, vCores:10> available, release resources=true
2013-08-09 20:54:10,025 INFO org.apache.hadoop.yarn.server.resourcemanager.scheduler.capacity.LeafQueue: default used=<memory:48128, vCores:42> numContainers=42 user=ubuntu user-resources=<memory:48128, vCores:42>
2013-08-09 20:54:10,027 INFO org.apache.hadoop.yarn.server.resourcemanager.scheduler.capacity.LeafQueue: completedContainer container=Container: [ContainerId: container_1376080735992_0006_01_000036, NodeId: hadoop-210-7:35638, NodeHttpAddress: hadoop-210-7:8042, Resource: <memory:1024, vCores:1>, Priority: 20, State: NEW, Token: null, Status: container_id {, app_attempt_id {, application_id {, id: 6, cluster_timestamp: 1376080735992, }, attemptId: 1, }, id: 36, }, state: C_COMPLETE, diagnostics: "Container killed by the ApplicationMaster.\n\n", exit_status: 143, ] resource=<memory:1024, vCores:1> queue=default: capacity=1.0, absoluteCapacity=1.0, usedResources=<memory:48128, vCores:42>usedCapacity=0.9791667, absoluteUsedCapacity=0.9791667, numApps=5, numContainers=42 usedCapacity=0.9791667 absoluteUsedCapacity=0.9791667 used=<memory:48128, vCores:42> cluster=<memory:49152, vCores:96>
2013-08-09 20:54:10,027 INFO org.apache.hadoop.yarn.server.resourcemanager.scheduler.capacity.ParentQueue: completedContainer queue=root usedCapacity=0.9791667 absoluteUsedCapacity=0.9791667 used=<memory:48128, vCores:42> cluster=<memory:49152, vCores:96>
2013-08-09 20:54:10,027 INFO org.apache.hadoop.yarn.server.resourcemanager.scheduler.capacity.CapacityScheduler: Application appattempt_1376080735992_0006_000001 released container container_1376080735992_0006_01_000036 on node: host: hadoop-210-7:35638 #containers=6 available=1024 used=7168 with event: FINISHED
2013-08-09 20:54:10,028 INFO org.apache.hadoop.yarn.server.resourcemanager.rmcontainer.RMContainerImpl: container_1376080735992_0007_01_000012 Container Transitioned from NEW to ALLOCATED
2013-08-09 20:54:10,028 INFO org.apache.hadoop.yarn.server.resourcemanager.RMAuditLogger: USER=ubuntu	OPERATION=AM Allocated Container	TARGET=SchedulerApp	RESULT=SUCCESS	APPID=application_1376080735992_0007	CONTAINERID=container_1376080735992_0007_01_000012
2013-08-09 20:54:10,028 INFO org.apache.hadoop.yarn.server.resourcemanager.scheduler.common.fica.FiCaSchedulerNode: Assigned container container_1376080735992_0007_01_000012 of capacity <memory:1024, vCores:1> on host hadoop-210-7:35638, which currently has 7 containers, <memory:8192, vCores:7> used and <memory:0, vCores:9> available
2013-08-09 20:54:10,029 INFO org.apache.hadoop.yarn.server.resourcemanager.scheduler.capacity.LeafQueue: assignedContainer application=application_1376080735992_0007 container=Container: [ContainerId: container_1376080735992_0007_01_000012, NodeId: hadoop-210-7:35638, NodeHttpAddress: hadoop-210-7:8042, Resource: <memory:1024, vCores:1>, Priority: 20, State: NEW, Token: null, Status: container_id {, app_attempt_id {, application_id {, id: 7, cluster_timestamp: 1376080735992, }, attemptId: 1, }, id: 12, }, state: C_NEW, ] containerId=container_1376080735992_0007_01_000012 queue=default: capacity=1.0, absoluteCapacity=1.0, usedResources=<memory:48128, vCores:42>usedCapacity=0.9791667, absoluteUsedCapacity=0.9791667, numApps=5, numContainers=42 usedCapacity=0.9791667 absoluteUsedCapacity=0.9791667 used=<memory:48128, vCores:42> cluster=<memory:49152, vCores:96>
2013-08-09 20:54:10,029 INFO org.apache.hadoop.yarn.server.resourcemanager.scheduler.capacity.ParentQueue: Re-sorting queues since queue: root.default stats: default: capacity=1.0, absoluteCapacity=1.0, usedResources=<memory:49152, vCores:43>usedCapacity=1.0, absoluteUsedCapacity=1.0, numApps=5, numContainers=43
2013-08-09 20:54:10,029 INFO org.apache.hadoop.yarn.server.resourcemanager.scheduler.capacity.ParentQueue: assignedContainer queue=root usedCapacity=1.0 absoluteUsedCapacity=1.0 used=<memory:49152, vCores:43> cluster=<memory:49152, vCores:96>
2013-08-09 20:54:10,241 INFO org.apache.hadoop.yarn.server.resourcemanager.rmcontainer.RMContainerImpl: container_1376080735992_0007_01_000007 Container Transitioned from ACQUIRED to RUNNING
2013-08-09 20:54:10,252 INFO org.apache.hadoop.yarn.server.resourcemanager.rmcontainer.RMContainerImpl: container_1376080735992_0007_01_000011 Container Transitioned from ALLOCATED to ACQUIRED
2013-08-09 20:54:10,253 INFO org.apache.hadoop.yarn.server.resourcemanager.rmcontainer.RMContainerImpl: container_1376080735992_0007_01_000012 Container Transitioned from ALLOCATED to ACQUIRED
2013-08-09 20:54:10,436 INFO org.apache.hadoop.yarn.server.resourcemanager.rmcontainer.RMContainerImpl: container_1376080735992_0006_01_000033 Container Transitioned from RUNNING to COMPLETED
2013-08-09 20:54:10,436 INFO org.apache.hadoop.yarn.server.resourcemanager.scheduler.common.fica.FiCaSchedulerApp: Completed container: container_1376080735992_0006_01_000033 in state: COMPLETED event:FINISHED
2013-08-09 20:54:10,436 INFO org.apache.hadoop.yarn.server.resourcemanager.RMAuditLogger: USER=ubuntu	OPERATION=AM Released Container	TARGET=SchedulerApp	RESULT=SUCCESS	APPID=application_1376080735992_0006	CONTAINERID=container_1376080735992_0006_01_000033
2013-08-09 20:54:10,437 INFO org.apache.hadoop.yarn.server.resourcemanager.scheduler.common.fica.FiCaSchedulerNode: Released container container_1376080735992_0006_01_000033 of capacity <memory:1024, vCores:1> on host hadoop-210-6:41207, which currently has 6 containers, <memory:7168, vCores:6> used and <memory:1024, vCores:10> available, release resources=true
2013-08-09 20:54:10,437 INFO org.apache.hadoop.yarn.server.resourcemanager.scheduler.capacity.LeafQueue: default used=<memory:48128, vCores:42> numContainers=42 user=ubuntu user-resources=<memory:48128, vCores:42>
2013-08-09 20:54:10,438 INFO org.apache.hadoop.yarn.server.resourcemanager.scheduler.capacity.LeafQueue: completedContainer container=Container: [ContainerId: container_1376080735992_0006_01_000033, NodeId: hadoop-210-6:41207, NodeHttpAddress: hadoop-210-6:8042, Resource: <memory:1024, vCores:1>, Priority: 20, State: NEW, Token: null, Status: container_id {, app_attempt_id {, application_id {, id: 6, cluster_timestamp: 1376080735992, }, attemptId: 1, }, id: 33, }, state: C_COMPLETE, diagnostics: "", exit_status: 0, ] resource=<memory:1024, vCores:1> queue=default: capacity=1.0, absoluteCapacity=1.0, usedResources=<memory:48128, vCores:42>usedCapacity=0.9791667, absoluteUsedCapacity=0.9791667, numApps=5, numContainers=42 usedCapacity=0.9791667 absoluteUsedCapacity=0.9791667 used=<memory:48128, vCores:42> cluster=<memory:49152, vCores:96>
2013-08-09 20:54:10,438 INFO org.apache.hadoop.yarn.server.resourcemanager.scheduler.capacity.ParentQueue: completedContainer queue=root usedCapacity=0.9791667 absoluteUsedCapacity=0.9791667 used=<memory:48128, vCores:42> cluster=<memory:49152, vCores:96>
2013-08-09 20:54:10,438 INFO org.apache.hadoop.yarn.server.resourcemanager.scheduler.capacity.CapacityScheduler: Application appattempt_1376080735992_0006_000001 released container container_1376080735992_0006_01_000033 on node: host: hadoop-210-6:41207 #containers=6 available=1024 used=7168 with event: FINISHED
2013-08-09 20:54:10,439 INFO org.apache.hadoop.yarn.server.resourcemanager.rmcontainer.RMContainerImpl: container_1376080735992_0007_01_000013 Container Transitioned from NEW to ALLOCATED
2013-08-09 20:54:10,439 INFO org.apache.hadoop.yarn.server.resourcemanager.RMAuditLogger: USER=ubuntu	OPERATION=AM Allocated Container	TARGET=SchedulerApp	RESULT=SUCCESS	APPID=application_1376080735992_0007	CONTAINERID=container_1376080735992_0007_01_000013
2013-08-09 20:54:10,439 INFO org.apache.hadoop.yarn.server.resourcemanager.scheduler.common.fica.FiCaSchedulerNode: Assigned container container_1376080735992_0007_01_000013 of capacity <memory:1024, vCores:1> on host hadoop-210-6:41207, which currently has 7 containers, <memory:8192, vCores:7> used and <memory:0, vCores:9> available
2013-08-09 20:54:10,440 INFO org.apache.hadoop.yarn.server.resourcemanager.scheduler.capacity.LeafQueue: assignedContainer application=application_1376080735992_0007 container=Container: [ContainerId: container_1376080735992_0007_01_000013, NodeId: hadoop-210-6:41207, NodeHttpAddress: hadoop-210-6:8042, Resource: <memory:1024, vCores:1>, Priority: 20, State: NEW, Token: null, Status: container_id {, app_attempt_id {, application_id {, id: 7, cluster_timestamp: 1376080735992, }, attemptId: 1, }, id: 13, }, state: C_NEW, ] containerId=container_1376080735992_0007_01_000013 queue=default: capacity=1.0, absoluteCapacity=1.0, usedResources=<memory:48128, vCores:42>usedCapacity=0.9791667, absoluteUsedCapacity=0.9791667, numApps=5, numContainers=42 usedCapacity=0.9791667 absoluteUsedCapacity=0.9791667 used=<memory:48128, vCores:42> cluster=<memory:49152, vCores:96>
2013-08-09 20:54:10,441 INFO org.apache.hadoop.yarn.server.resourcemanager.scheduler.capacity.ParentQueue: Re-sorting queues since queue: root.default stats: default: capacity=1.0, absoluteCapacity=1.0, usedResources=<memory:49152, vCores:43>usedCapacity=1.0, absoluteUsedCapacity=1.0, numApps=5, numContainers=43
2013-08-09 20:54:10,441 INFO org.apache.hadoop.yarn.server.resourcemanager.scheduler.capacity.ParentQueue: assignedContainer queue=root usedCapacity=1.0 absoluteUsedCapacity=1.0 used=<memory:49152, vCores:43> cluster=<memory:49152, vCores:96>
2013-08-09 20:54:10,543 INFO org.apache.hadoop.yarn.server.resourcemanager.rmcontainer.RMContainerImpl: container_1376080735992_0007_01_000012 Container Transitioned from ACQUIRED to RUNNING
2013-08-09 20:54:10,691 INFO org.apache.hadoop.yarn.server.resourcemanager.rmcontainer.RMContainerImpl: container_1376080735992_0007_01_000011 Container Transitioned from ACQUIRED to RUNNING
2013-08-09 20:54:10,691 INFO org.apache.hadoop.yarn.server.resourcemanager.rmcontainer.RMContainerImpl: container_1376080735992_0006_01_000010 Container Transitioned from RUNNING to COMPLETED
2013-08-09 20:54:10,691 INFO org.apache.hadoop.yarn.server.resourcemanager.scheduler.common.fica.FiCaSchedulerApp: Completed container: container_1376080735992_0006_01_000010 in state: COMPLETED event:FINISHED
2013-08-09 20:54:10,691 INFO org.apache.hadoop.yarn.server.resourcemanager.RMAuditLogger: USER=ubuntu	OPERATION=AM Released Container	TARGET=SchedulerApp	RESULT=SUCCESS	APPID=application_1376080735992_0006	CONTAINERID=container_1376080735992_0006_01_000010
2013-08-09 20:54:10,692 INFO org.apache.hadoop.yarn.server.resourcemanager.scheduler.common.fica.FiCaSchedulerNode: Released container container_1376080735992_0006_01_000010 of capacity <memory:1024, vCores:1> on host hadoop-210-3:58589, which currently has 6 containers, <memory:7168, vCores:6> used and <memory:1024, vCores:10> available, release resources=true
2013-08-09 20:54:10,692 INFO org.apache.hadoop.yarn.server.resourcemanager.scheduler.capacity.LeafQueue: default used=<memory:48128, vCores:42> numContainers=42 user=ubuntu user-resources=<memory:48128, vCores:42>
2013-08-09 20:54:10,693 INFO org.apache.hadoop.yarn.server.resourcemanager.scheduler.capacity.LeafQueue: completedContainer container=Container: [ContainerId: container_1376080735992_0006_01_000010, NodeId: hadoop-210-3:58589, NodeHttpAddress: hadoop-210-3:8042, Resource: <memory:1024, vCores:1>, Priority: 20, State: NEW, Token: null, Status: container_id {, app_attempt_id {, application_id {, id: 6, cluster_timestamp: 1376080735992, }, attemptId: 1, }, id: 10, }, state: C_COMPLETE, diagnostics: "Container killed by the ApplicationMaster.\n\n", exit_status: 143, ] resource=<memory:1024, vCores:1> queue=default: capacity=1.0, absoluteCapacity=1.0, usedResources=<memory:48128, vCores:42>usedCapacity=0.9791667, absoluteUsedCapacity=0.9791667, numApps=5, numContainers=42 usedCapacity=0.9791667 absoluteUsedCapacity=0.9791667 used=<memory:48128, vCores:42> cluster=<memory:49152, vCores:96>
2013-08-09 20:54:10,693 INFO org.apache.hadoop.yarn.server.resourcemanager.scheduler.capacity.ParentQueue: completedContainer queue=root usedCapacity=0.9791667 absoluteUsedCapacity=0.9791667 used=<memory:48128, vCores:42> cluster=<memory:49152, vCores:96>
2013-08-09 20:54:10,693 INFO org.apache.hadoop.yarn.server.resourcemanager.scheduler.capacity.CapacityScheduler: Application appattempt_1376080735992_0006_000001 released container container_1376080735992_0006_01_000010 on node: host: hadoop-210-3:58589 #containers=6 available=1024 used=7168 with event: FINISHED
2013-08-09 20:54:10,694 INFO org.apache.hadoop.yarn.server.resourcemanager.rmcontainer.RMContainerImpl: container_1376080735992_0007_01_000014 Container Transitioned from NEW to ALLOCATED
2013-08-09 20:54:10,694 INFO org.apache.hadoop.yarn.server.resourcemanager.RMAuditLogger: USER=ubuntu	OPERATION=AM Allocated Container	TARGET=SchedulerApp	RESULT=SUCCESS	APPID=application_1376080735992_0007	CONTAINERID=container_1376080735992_0007_01_000014
2013-08-09 20:54:10,694 INFO org.apache.hadoop.yarn.server.resourcemanager.scheduler.common.fica.FiCaSchedulerNode: Assigned container container_1376080735992_0007_01_000014 of capacity <memory:1024, vCores:1> on host hadoop-210-3:58589, which currently has 7 containers, <memory:8192, vCores:7> used and <memory:0, vCores:9> available
2013-08-09 20:54:10,695 INFO org.apache.hadoop.yarn.server.resourcemanager.scheduler.capacity.LeafQueue: assignedContainer application=application_1376080735992_0007 container=Container: [ContainerId: container_1376080735992_0007_01_000014, NodeId: hadoop-210-3:58589, NodeHttpAddress: hadoop-210-3:8042, Resource: <memory:1024, vCores:1>, Priority: 20, State: NEW, Token: null, Status: container_id {, app_attempt_id {, application_id {, id: 7, cluster_timestamp: 1376080735992, }, attemptId: 1, }, id: 14, }, state: C_NEW, ] containerId=container_1376080735992_0007_01_000014 queue=default: capacity=1.0, absoluteCapacity=1.0, usedResources=<memory:48128, vCores:42>usedCapacity=0.9791667, absoluteUsedCapacity=0.9791667, numApps=5, numContainers=42 usedCapacity=0.9791667 absoluteUsedCapacity=0.9791667 used=<memory:48128, vCores:42> cluster=<memory:49152, vCores:96>
2013-08-09 20:54:10,695 INFO org.apache.hadoop.yarn.server.resourcemanager.scheduler.capacity.ParentQueue: Re-sorting queues since queue: root.default stats: default: capacity=1.0, absoluteCapacity=1.0, usedResources=<memory:49152, vCores:43>usedCapacity=1.0, absoluteUsedCapacity=1.0, numApps=5, numContainers=43
2013-08-09 20:54:10,696 INFO org.apache.hadoop.yarn.server.resourcemanager.scheduler.capacity.ParentQueue: assignedContainer queue=root usedCapacity=1.0 absoluteUsedCapacity=1.0 used=<memory:49152, vCores:43> cluster=<memory:49152, vCores:96>
2013-08-09 20:54:11,263 INFO org.apache.hadoop.yarn.server.resourcemanager.rmcontainer.RMContainerImpl: container_1376080735992_0007_01_000013 Container Transitioned from ALLOCATED to ACQUIRED
2013-08-09 20:54:11,264 INFO org.apache.hadoop.yarn.server.resourcemanager.rmcontainer.RMContainerImpl: container_1376080735992_0007_01_000014 Container Transitioned from ALLOCATED to ACQUIRED
2013-08-09 20:54:11,560 INFO org.apache.hadoop.yarn.server.resourcemanager.rmcontainer.RMContainerImpl: container_1376080735992_0006_01_000037 Container Transitioned from RUNNING to COMPLETED
2013-08-09 20:54:11,560 INFO org.apache.hadoop.yarn.server.resourcemanager.scheduler.common.fica.FiCaSchedulerApp: Completed container: container_1376080735992_0006_01_000037 in state: COMPLETED event:FINISHED
2013-08-09 20:54:11,560 INFO org.apache.hadoop.yarn.server.resourcemanager.RMAuditLogger: USER=ubuntu	OPERATION=AM Released Container	TARGET=SchedulerApp	RESULT=SUCCESS	APPID=application_1376080735992_0006	CONTAINERID=container_1376080735992_0006_01_000037
2013-08-09 20:54:11,560 INFO org.apache.hadoop.yarn.server.resourcemanager.scheduler.common.fica.FiCaSchedulerNode: Released container container_1376080735992_0006_01_000037 of capacity <memory:1024, vCores:1> on host hadoop-210-7:35638, which currently has 6 containers, <memory:7168, vCores:6> used and <memory:1024, vCores:10> available, release resources=true
2013-08-09 20:54:11,560 INFO org.apache.hadoop.yarn.server.resourcemanager.scheduler.capacity.LeafQueue: default used=<memory:48128, vCores:42> numContainers=42 user=ubuntu user-resources=<memory:48128, vCores:42>
2013-08-09 20:54:11,561 INFO org.apache.hadoop.yarn.server.resourcemanager.scheduler.capacity.LeafQueue: completedContainer container=Container: [ContainerId: container_1376080735992_0006_01_000037, NodeId: hadoop-210-7:35638, NodeHttpAddress: hadoop-210-7:8042, Resource: <memory:1024, vCores:1>, Priority: 20, State: NEW, Token: null, Status: container_id {, app_attempt_id {, application_id {, id: 6, cluster_timestamp: 1376080735992, }, attemptId: 1, }, id: 37, }, state: C_COMPLETE, diagnostics: "Container killed by the ApplicationMaster.\n\n", exit_status: 143, ] resource=<memory:1024, vCores:1> queue=default: capacity=1.0, absoluteCapacity=1.0, usedResources=<memory:48128, vCores:42>usedCapacity=0.9791667, absoluteUsedCapacity=0.9791667, numApps=5, numContainers=42 usedCapacity=0.9791667 absoluteUsedCapacity=0.9791667 used=<memory:48128, vCores:42> cluster=<memory:49152, vCores:96>
2013-08-09 20:54:11,562 INFO org.apache.hadoop.yarn.server.resourcemanager.scheduler.capacity.ParentQueue: completedContainer queue=root usedCapacity=0.9791667 absoluteUsedCapacity=0.9791667 used=<memory:48128, vCores:42> cluster=<memory:49152, vCores:96>
2013-08-09 20:54:11,562 INFO org.apache.hadoop.yarn.server.resourcemanager.scheduler.capacity.CapacityScheduler: Application appattempt_1376080735992_0006_000001 released container container_1376080735992_0006_01_000037 on node: host: hadoop-210-7:35638 #containers=6 available=1024 used=7168 with event: FINISHED
2013-08-09 20:54:11,564 INFO org.apache.hadoop.yarn.server.resourcemanager.rmcontainer.RMContainerImpl: container_1376080735992_0007_01_000015 Container Transitioned from NEW to ALLOCATED
2013-08-09 20:54:11,564 INFO org.apache.hadoop.yarn.server.resourcemanager.RMAuditLogger: USER=ubuntu	OPERATION=AM Allocated Container	TARGET=SchedulerApp	RESULT=SUCCESS	APPID=application_1376080735992_0007	CONTAINERID=container_1376080735992_0007_01_000015
2013-08-09 20:54:11,564 INFO org.apache.hadoop.yarn.server.resourcemanager.scheduler.common.fica.FiCaSchedulerNode: Assigned container container_1376080735992_0007_01_000015 of capacity <memory:1024, vCores:1> on host hadoop-210-7:35638, which currently has 7 containers, <memory:8192, vCores:7> used and <memory:0, vCores:9> available
