2013-08-11 01:37:05,898 INFO org.apache.hadoop.yarn.server.resourcemanager.ResourceManager: STARTUP_MSG: 
/************************************************************
STARTUP_MSG: Starting ResourceManager
STARTUP_MSG:   host = hadoop-321-1/192.168.100.15
STARTUP_MSG:   args = []
STARTUP_MSG:   version = 3.0.0-SNAPSHOT
STARTUP_MSG:   build = https://github.com/lalithsuresh/hadoop-common -r 0cb423bd4868928bb06cd93f882bb0913172fd17; compiled by 'lsuresh' on 2013-04-08T15:47Z
STARTUP_MSG:   java = 1.7.0_17
************************************************************/
2013-08-11 01:37:05,913 INFO org.apache.hadoop.yarn.server.resourcemanager.ResourceManager: registered UNIX signal handlers for [TERM, HUP, INT]
2013-08-11 01:37:06,592 INFO org.apache.hadoop.yarn.server.resourcemanager.security.ApplicationTokenSecretManager: Rolling master-key for application-tokens
2013-08-11 01:37:06,640 INFO org.apache.hadoop.yarn.server.resourcemanager.security.RMContainerTokenSecretManager: ContainerTokenKeyRollingInterval: 86400000ms and ContainerTokenKeyActivationDelay: 900000ms
2013-08-11 01:37:06,644 INFO org.apache.hadoop.yarn.service.AbstractService: Service:Dispatcher is inited.
2013-08-11 01:37:06,646 INFO org.apache.hadoop.yarn.event.AsyncDispatcher: Registering class org.apache.hadoop.yarn.server.resourcemanager.recovery.RMStateStoreEventType for class org.apache.hadoop.yarn.server.resourcemanager.recovery.RMStateStore$ForwardingEventHandler
2013-08-11 01:37:06,646 INFO org.apache.hadoop.yarn.service.AbstractService: Service:Dispatcher is started.
2013-08-11 01:37:06,654 INFO org.apache.hadoop.yarn.event.AsyncDispatcher: Registering class org.apache.hadoop.yarn.server.resourcemanager.NodesListManagerEventType for class org.apache.hadoop.yarn.server.resourcemanager.NodesListManager
2013-08-11 01:37:06,654 INFO org.apache.hadoop.yarn.server.resourcemanager.ResourceManager: Using Scheduler: org.apache.hadoop.yarn.server.resourcemanager.scheduler.capacity.CapacityScheduler
2013-08-11 01:37:06,901 INFO org.apache.hadoop.yarn.event.AsyncDispatcher: Registering class org.apache.hadoop.yarn.server.resourcemanager.scheduler.event.SchedulerEventType for class org.apache.hadoop.yarn.server.resourcemanager.ResourceManager$SchedulerEventDispatcher
2013-08-11 01:37:06,903 INFO org.apache.hadoop.yarn.event.AsyncDispatcher: Registering class org.apache.hadoop.yarn.server.resourcemanager.rmapp.RMAppEventType for class org.apache.hadoop.yarn.server.resourcemanager.ResourceManager$ApplicationEventDispatcher
2013-08-11 01:37:06,906 INFO org.apache.hadoop.yarn.event.AsyncDispatcher: Registering class org.apache.hadoop.yarn.server.resourcemanager.rmapp.attempt.RMAppAttemptEventType for class org.apache.hadoop.yarn.server.resourcemanager.ResourceManager$ApplicationAttemptEventDispatcher
2013-08-11 01:37:06,908 INFO org.apache.hadoop.yarn.event.AsyncDispatcher: Registering class org.apache.hadoop.yarn.server.resourcemanager.rmnode.RMNodeEventType for class org.apache.hadoop.yarn.server.resourcemanager.ResourceManager$NodeEventDispatcher
2013-08-11 01:37:07,456 WARN org.apache.hadoop.util.NativeCodeLoader: Unable to load native-hadoop library for your platform... using builtin-java classes where applicable
2013-08-11 01:37:07,478 INFO org.apache.hadoop.yarn.server.resourcemanager.scheduler.capacity.ParentQueue: root, capacity=1.0, asboluteCapacity=1.0, maxCapacity=1.0, asboluteMaxCapacity=1.0, state=RUNNING, acls=ADMINISTER_QUEUE:*SUBMIT_APPLICATIONS:*
2013-08-11 01:37:07,478 INFO org.apache.hadoop.yarn.server.resourcemanager.scheduler.capacity.ParentQueue: Initialized parent-queue root name=root, fullname=root
2013-08-11 01:37:07,491 INFO org.apache.hadoop.yarn.server.resourcemanager.scheduler.capacity.LeafQueue: Initializing default
capacity = 1.0 [= (float) configuredCapacity / 100 ]
asboluteCapacity = 1.0 [= parentAbsoluteCapacity * capacity ]
maxCapacity = 1.0 [= configuredMaxCapacity ]
absoluteMaxCapacity = 1.0 [= 1.0 maximumCapacity undefined, (parentAbsoluteMaxCapacity * maximumCapacity) / 100 otherwise ]
userLimit = 100 [= configuredUserLimit ]
userLimitFactor = 1.0 [= configuredUserLimitFactor ]
maxApplications = 10000 [= configuredMaximumSystemApplicationsPerQueue or (int)(configuredMaximumSystemApplications * absoluteCapacity)]
maxApplicationsPerUser = 10000 [= (int)(maxApplications * (userLimit / 100.0f) * userLimitFactor) ]
maxActiveApplications = 1 [= max((int)ceil((clusterResourceMemory / minimumAllocation) * maxAMResourcePerQueuePercent * absoluteMaxCapacity),1) ]
maxActiveAppsUsingAbsCap = 1 [= max((int)ceil((clusterResourceMemory / minimumAllocation) *maxAMResourcePercent * absoluteCapacity),1) ]
maxActiveApplicationsPerUser = 1 [= max((int)(maxActiveApplications * (userLimit / 100.0f) * userLimitFactor),1) ]
usedCapacity = 0.0 [= usedResourcesMemory / (clusterResourceMemory * absoluteCapacity)]
absoluteUsedCapacity = 0.0 [= usedResourcesMemory / clusterResourceMemory]
maxAMResourcePerQueuePercent = 0.1 [= configuredMaximumAMResourcePercent ]
minimumAllocationFactor = 0.875 [= (float)(maximumAllocationMemory - minimumAllocationMemory) / maximumAllocationMemory ]
numContainers = 0 [= currentNumContainers ]
state = RUNNING [= configuredState ]
acls = ADMINISTER_QUEUE:*SUBMIT_APPLICATIONS:* [= configuredAcls ]

2013-08-11 01:37:07,492 INFO org.apache.hadoop.yarn.server.resourcemanager.scheduler.capacity.CapacityScheduler: Initialized queue: default: capacity=1.0, absoluteCapacity=1.0, usedResources=<memory:0, vCores:0>usedCapacity=0.0, absoluteUsedCapacity=0.0, numApps=0, numContainers=0
2013-08-11 01:37:07,492 INFO org.apache.hadoop.yarn.server.resourcemanager.scheduler.capacity.CapacityScheduler: Initialized queue: root: numChildQueue= 1, capacity=1.0, absoluteCapacity=1.0, usedResources=<memory:0, vCores:0>usedCapacity=0.0, numApps=0, numContainers=0
2013-08-11 01:37:07,492 INFO org.apache.hadoop.yarn.server.resourcemanager.scheduler.capacity.CapacityScheduler: Initialized root queue root: numChildQueue= 1, capacity=1.0, absoluteCapacity=1.0, usedResources=<memory:0, vCores:0>usedCapacity=0.0, numApps=0, numContainers=0
2013-08-11 01:37:07,492 INFO org.apache.hadoop.yarn.server.resourcemanager.scheduler.capacity.CapacityScheduler: Initialized CapacityScheduler with calculator=class org.apache.hadoop.yarn.server.resourcemanager.resource.DefaultResourceCalculator, minimumAllocation=<<memory:1024, vCores:1>>, maximumAllocation=<<memory:8192, vCores:32>>
2013-08-11 01:37:07,754 INFO org.apache.hadoop.yarn.event.AsyncDispatcher: Registering class org.apache.hadoop.yarn.server.resourcemanager.RMAppManagerEventType for class org.apache.hadoop.yarn.server.resourcemanager.RMAppManager
2013-08-11 01:37:07,769 INFO org.apache.hadoop.yarn.event.AsyncDispatcher: Registering class org.apache.hadoop.yarn.server.resourcemanager.amlauncher.AMLauncherEventType for class org.apache.hadoop.yarn.server.resourcemanager.amlauncher.ApplicationMasterLauncher
2013-08-11 01:37:07,835 INFO org.apache.hadoop.yarn.server.resourcemanager.RMNMInfo: Registered RMNMInfo MBean
2013-08-11 01:37:07,835 INFO org.apache.hadoop.yarn.service.AbstractService: Service:Dispatcher is inited.
2013-08-11 01:37:07,835 INFO org.apache.hadoop.yarn.service.AbstractService: Service:org.apache.hadoop.yarn.server.resourcemanager.rmcontainer.ContainerAllocationExpirer is inited.
2013-08-11 01:37:07,835 INFO org.apache.hadoop.yarn.service.AbstractService: Service:AMLivelinessMonitor is inited.
2013-08-11 01:37:07,835 INFO org.apache.hadoop.yarn.service.AbstractService: Service:AMLivelinessMonitor is inited.
2013-08-11 01:37:07,835 INFO org.apache.hadoop.yarn.service.AbstractService: Service:org.apache.hadoop.yarn.server.resourcemanager.security.DelegationTokenRenewer is inited.
2013-08-11 01:37:07,837 INFO org.apache.hadoop.util.HostsFileReader: Refreshing hosts (include/exclude) list
2013-08-11 01:37:07,837 INFO org.apache.hadoop.yarn.service.AbstractService: Service:org.apache.hadoop.yarn.server.resourcemanager.NodesListManager is inited.
2013-08-11 01:37:07,837 INFO org.apache.hadoop.yarn.service.AbstractService: Service:org.apache.hadoop.yarn.server.resourcemanager.ResourceManager$SchedulerEventDispatcher is inited.
2013-08-11 01:37:07,837 INFO org.apache.hadoop.yarn.service.AbstractService: Service:NMLivelinessMonitor is inited.
2013-08-11 01:37:07,842 INFO org.apache.hadoop.yarn.service.AbstractService: Service:org.apache.hadoop.yarn.server.resourcemanager.ResourceTrackerService is inited.
2013-08-11 01:37:07,842 INFO org.apache.hadoop.yarn.service.AbstractService: Service:org.apache.hadoop.yarn.server.resourcemanager.ApplicationMasterService is inited.
2013-08-11 01:37:07,842 INFO org.apache.hadoop.yarn.service.AbstractService: Service:org.apache.hadoop.yarn.server.resourcemanager.ClientRMService is inited.
2013-08-11 01:37:07,842 INFO org.apache.hadoop.yarn.service.AbstractService: Service:org.apache.hadoop.yarn.server.resourcemanager.AdminService is inited.
2013-08-11 01:37:07,843 INFO org.apache.hadoop.yarn.service.AbstractService: Service:org.apache.hadoop.yarn.server.resourcemanager.amlauncher.ApplicationMasterLauncher is inited.
2013-08-11 01:37:07,843 INFO org.apache.hadoop.yarn.service.AbstractService: Service:ResourceManager is inited.
2013-08-11 01:37:07,843 INFO org.apache.hadoop.yarn.server.resourcemanager.security.RMContainerTokenSecretManager: Rolling master-key for container-tokens
2013-08-11 01:37:07,843 INFO org.apache.hadoop.yarn.server.resourcemanager.security.ApplicationTokenSecretManager: Rolling master-key for application-tokens
2013-08-11 01:37:07,953 INFO org.mortbay.log: Logging to org.slf4j.impl.Log4jLoggerAdapter(org.mortbay.log) via org.mortbay.log.Slf4jLog
2013-08-11 01:37:08,009 INFO org.apache.hadoop.http.HttpServer: Added global filter 'safety' (class=org.apache.hadoop.http.HttpServer$QuotingInputFilter)
2013-08-11 01:37:08,012 INFO org.apache.hadoop.http.HttpServer: Added filter static_user_filter (class=org.apache.hadoop.http.lib.StaticUserWebFilter$StaticUserFilter) to context cluster
2013-08-11 01:37:08,012 INFO org.apache.hadoop.http.HttpServer: Added filter static_user_filter (class=org.apache.hadoop.http.lib.StaticUserWebFilter$StaticUserFilter) to context logs
2013-08-11 01:37:08,012 INFO org.apache.hadoop.http.HttpServer: Added filter static_user_filter (class=org.apache.hadoop.http.lib.StaticUserWebFilter$StaticUserFilter) to context static
2013-08-11 01:37:08,016 INFO org.apache.hadoop.http.HttpServer: adding path spec: /cluster
2013-08-11 01:37:08,016 INFO org.apache.hadoop.http.HttpServer: adding path spec: /cluster/*
2013-08-11 01:37:08,017 INFO org.apache.hadoop.http.HttpServer: adding path spec: /ws
2013-08-11 01:37:08,017 INFO org.apache.hadoop.http.HttpServer: adding path spec: /ws/*
2013-08-11 01:37:08,018 INFO org.apache.hadoop.http.HttpServer: Added global filter 'guice' (class=com.google.inject.servlet.GuiceFilter)
2013-08-11 01:37:08,023 INFO org.apache.hadoop.http.HttpServer: Jetty bound to port 8088
2013-08-11 01:37:08,024 INFO org.mortbay.log: jetty-6.1.26
2013-08-11 01:37:08,054 INFO org.mortbay.log: Extract jar:file:/home/ubuntu/hadoop-3.0.0-SNAPSHOT/share/hadoop/yarn/hadoop-yarn-common-3.0.0-SNAPSHOT.jar!/webapps/cluster to /tmp/Jetty_0_0_0_0_8088_cluster____u0rgz3/webapp
2013-08-11 01:37:08,417 INFO org.mortbay.log: Started SelectChannelConnector@0.0.0.0:8088
2013-08-11 01:37:08,417 INFO org.apache.hadoop.yarn.webapp.WebApps: Web app /cluster started at 8088
2013-08-11 01:37:09,145 INFO org.apache.hadoop.yarn.webapp.WebApps: Registered webapp guice modules
2013-08-11 01:37:09,267 INFO org.apache.hadoop.metrics2.impl.MetricsConfig: loaded properties from hadoop-metrics2.properties
2013-08-11 01:37:09,307 INFO org.apache.hadoop.metrics2.impl.MetricsSystemImpl: Scheduled snapshot period at 10 second(s).
2013-08-11 01:37:09,307 INFO org.apache.hadoop.metrics2.impl.MetricsSystemImpl: ResourceManager metrics system started
2013-08-11 01:37:09,323 INFO org.apache.hadoop.security.token.delegation.AbstractDelegationTokenSecretManager: Updating the current master key for generating delegation tokens
2013-08-11 01:37:09,327 INFO org.apache.hadoop.yarn.service.AbstractService: Service:Dispatcher is started.
2013-08-11 01:37:09,327 INFO org.apache.hadoop.security.token.delegation.AbstractDelegationTokenSecretManager: Starting expired delegation token remover thread, tokenRemoverScanInterval=60 min(s)
2013-08-11 01:37:09,327 INFO org.apache.hadoop.security.token.delegation.AbstractDelegationTokenSecretManager: Updating the current master key for generating delegation tokens
2013-08-11 01:37:09,329 INFO org.apache.hadoop.yarn.service.AbstractService: Service:org.apache.hadoop.yarn.server.resourcemanager.rmcontainer.ContainerAllocationExpirer is started.
2013-08-11 01:37:09,330 INFO org.apache.hadoop.yarn.service.AbstractService: Service:AMLivelinessMonitor is started.
2013-08-11 01:37:09,330 INFO org.apache.hadoop.yarn.service.AbstractService: Service:AMLivelinessMonitor is started.
2013-08-11 01:37:09,330 INFO org.apache.hadoop.yarn.service.AbstractService: Service:org.apache.hadoop.yarn.server.resourcemanager.security.DelegationTokenRenewer is started.
2013-08-11 01:37:09,331 INFO org.apache.hadoop.yarn.service.AbstractService: Service:org.apache.hadoop.yarn.server.resourcemanager.NodesListManager is started.
2013-08-11 01:37:09,332 INFO org.apache.hadoop.yarn.service.AbstractService: Service:org.apache.hadoop.yarn.server.resourcemanager.ResourceManager$SchedulerEventDispatcher is started.
2013-08-11 01:37:09,333 INFO org.apache.hadoop.yarn.service.AbstractService: Service:NMLivelinessMonitor is started.
2013-08-11 01:37:09,333 INFO org.apache.hadoop.yarn.service.AbstractService: Service:org.apache.hadoop.yarn.server.resourcemanager.ResourceTrackerService is started.
2013-08-11 01:37:09,381 INFO org.apache.hadoop.ipc.Server: Starting Socket Reader #1 for port 54110
2013-08-11 01:37:09,428 INFO org.apache.hadoop.yarn.factories.impl.pb.RpcServerFactoryPBImpl: Adding protocol org.apache.hadoop.yarn.server.api.ResourceTrackerPB to the server
2013-08-11 01:37:09,429 INFO org.apache.hadoop.ipc.Server: IPC Server Responder: starting
2013-08-11 01:37:09,431 INFO org.apache.hadoop.ipc.Server: IPC Server listener on 54110: starting
2013-08-11 01:37:09,563 INFO org.apache.hadoop.ipc.Server: Starting Socket Reader #1 for port 54112
2013-08-11 01:37:09,571 INFO org.apache.hadoop.yarn.factories.impl.pb.RpcServerFactoryPBImpl: Adding protocol org.apache.hadoop.yarn.api.AMRMProtocolPB to the server
2013-08-11 01:37:09,571 INFO org.apache.hadoop.ipc.Server: IPC Server Responder: starting
2013-08-11 01:37:09,572 INFO org.apache.hadoop.ipc.Server: IPC Server listener on 54112: starting
2013-08-11 01:37:09,606 INFO org.apache.hadoop.yarn.service.AbstractService: Service:org.apache.hadoop.yarn.server.resourcemanager.ApplicationMasterService is started.
2013-08-11 01:37:09,635 INFO org.apache.hadoop.ipc.Server: Starting Socket Reader #1 for port 54111
2013-08-11 01:37:09,638 INFO org.apache.hadoop.yarn.factories.impl.pb.RpcServerFactoryPBImpl: Adding protocol org.apache.hadoop.yarn.api.ClientRMProtocolPB to the server
2013-08-11 01:37:09,639 INFO org.apache.hadoop.ipc.Server: IPC Server Responder: starting
2013-08-11 01:37:09,639 INFO org.apache.hadoop.ipc.Server: IPC Server listener on 54111: starting
2013-08-11 01:37:09,675 INFO org.apache.hadoop.yarn.service.AbstractService: Service:org.apache.hadoop.yarn.server.resourcemanager.ClientRMService is started.
2013-08-11 01:37:09,694 INFO org.apache.hadoop.ipc.Server: Starting Socket Reader #1 for port 8033
2013-08-11 01:37:09,697 INFO org.apache.hadoop.yarn.factories.impl.pb.RpcServerFactoryPBImpl: Adding protocol org.apache.hadoop.yarn.api.RMAdminProtocolPB to the server
2013-08-11 01:37:09,697 INFO org.apache.hadoop.ipc.Server: IPC Server Responder: starting
2013-08-11 01:37:09,698 INFO org.apache.hadoop.yarn.service.AbstractService: Service:org.apache.hadoop.yarn.server.resourcemanager.AdminService is started.
2013-08-11 01:37:09,699 INFO org.apache.hadoop.ipc.Server: IPC Server listener on 8033: starting
2013-08-11 01:37:09,699 INFO org.apache.hadoop.yarn.service.AbstractService: Service:org.apache.hadoop.yarn.server.resourcemanager.amlauncher.ApplicationMasterLauncher is started.
2013-08-11 01:37:09,699 INFO org.apache.hadoop.yarn.service.AbstractService: Service:ResourceManager is started.
2013-08-11 01:37:19,910 INFO org.apache.hadoop.yarn.util.RackResolver: Resolved hadoop-321-4 to /default-rack
2013-08-11 01:37:19,911 INFO org.apache.hadoop.yarn.util.RackResolver: Resolved hadoop-321-7 to /default-rack
2013-08-11 01:37:19,912 INFO org.apache.hadoop.yarn.util.RackResolver: Resolved hadoop-321-3 to /default-rack
2013-08-11 01:37:19,912 INFO org.apache.hadoop.yarn.util.RackResolver: Resolved hadoop-321-6 to /default-rack
2013-08-11 01:37:19,936 INFO org.apache.hadoop.yarn.server.resourcemanager.ResourceTrackerService: NodeManager from node hadoop-321-3(cmPort: 44876 httpPort: 8042) registered with capability: <memory:8192, vCores:16>, assigned nodeId hadoop-321-3:44876
2013-08-11 01:37:19,938 INFO org.apache.hadoop.yarn.server.resourcemanager.ResourceTrackerService: NodeManager from node hadoop-321-6(cmPort: 34867 httpPort: 8042) registered with capability: <memory:8192, vCores:16>, assigned nodeId hadoop-321-6:34867
2013-08-11 01:37:19,936 INFO org.apache.hadoop.yarn.server.resourcemanager.ResourceTrackerService: NodeManager from node hadoop-321-7(cmPort: 41950 httpPort: 8042) registered with capability: <memory:8192, vCores:16>, assigned nodeId hadoop-321-7:41950
2013-08-11 01:37:19,941 INFO org.apache.hadoop.yarn.server.resourcemanager.ResourceTrackerService: NodeManager from node hadoop-321-4(cmPort: 43757 httpPort: 8042) registered with capability: <memory:8192, vCores:16>, assigned nodeId hadoop-321-4:43757
2013-08-11 01:37:19,960 INFO org.apache.hadoop.yarn.server.resourcemanager.rmnode.RMNodeImpl: hadoop-321-3:44876 Node Transitioned from NEW to RUNNING
2013-08-11 01:37:19,965 INFO org.apache.hadoop.yarn.server.resourcemanager.rmnode.RMNodeImpl: hadoop-321-7:41950 Node Transitioned from NEW to RUNNING
2013-08-11 01:37:19,967 INFO org.apache.hadoop.yarn.server.resourcemanager.rmnode.RMNodeImpl: hadoop-321-6:34867 Node Transitioned from NEW to RUNNING
2013-08-11 01:37:19,968 INFO org.apache.hadoop.yarn.server.resourcemanager.rmnode.RMNodeImpl: hadoop-321-4:43757 Node Transitioned from NEW to RUNNING
2013-08-11 01:37:19,977 INFO org.apache.hadoop.yarn.server.resourcemanager.scheduler.capacity.CapacityScheduler: Added node hadoop-321-3:44876 clusterResource: <memory:8192, vCores:16>
2013-08-11 01:37:19,978 INFO org.apache.hadoop.yarn.server.resourcemanager.scheduler.capacity.CapacityScheduler: Added node hadoop-321-7:41950 clusterResource: <memory:16384, vCores:32>
2013-08-11 01:37:19,978 INFO org.apache.hadoop.yarn.server.resourcemanager.scheduler.capacity.CapacityScheduler: Added node hadoop-321-6:34867 clusterResource: <memory:24576, vCores:48>
2013-08-11 01:37:19,978 INFO org.apache.hadoop.yarn.server.resourcemanager.scheduler.capacity.CapacityScheduler: Added node hadoop-321-4:43757 clusterResource: <memory:32768, vCores:64>
2013-08-11 01:37:20,104 INFO org.apache.hadoop.yarn.util.RackResolver: Resolved hadoop-321-5 to /default-rack
2013-08-11 01:37:20,105 INFO org.apache.hadoop.yarn.server.resourcemanager.ResourceTrackerService: NodeManager from node hadoop-321-5(cmPort: 60845 httpPort: 8042) registered with capability: <memory:8192, vCores:16>, assigned nodeId hadoop-321-5:60845
2013-08-11 01:37:20,106 INFO org.apache.hadoop.yarn.server.resourcemanager.rmnode.RMNodeImpl: hadoop-321-5:60845 Node Transitioned from NEW to RUNNING
2013-08-11 01:37:20,106 INFO org.apache.hadoop.yarn.server.resourcemanager.scheduler.capacity.CapacityScheduler: Added node hadoop-321-5:60845 clusterResource: <memory:40960, vCores:80>
2013-08-11 01:37:20,146 INFO org.apache.hadoop.yarn.util.RackResolver: Resolved hadoop-321-2 to /default-rack
2013-08-11 01:37:20,147 INFO org.apache.hadoop.yarn.server.resourcemanager.ResourceTrackerService: NodeManager from node hadoop-321-2(cmPort: 46202 httpPort: 8042) registered with capability: <memory:8192, vCores:16>, assigned nodeId hadoop-321-2:46202
2013-08-11 01:37:20,148 INFO org.apache.hadoop.yarn.server.resourcemanager.rmnode.RMNodeImpl: hadoop-321-2:46202 Node Transitioned from NEW to RUNNING
2013-08-11 01:37:20,148 INFO org.apache.hadoop.yarn.server.resourcemanager.scheduler.capacity.CapacityScheduler: Added node hadoop-321-2:46202 clusterResource: <memory:49152, vCores:96>
2013-08-11 01:37:26,632 INFO org.apache.hadoop.yarn.server.resourcemanager.ClientRMService: Allocated new applicationId: 1
2013-08-11 01:37:30,185 INFO org.apache.hadoop.yarn.server.resourcemanager.ClientRMService: Storing Application with id application_1376185025835_0001
2013-08-11 01:37:30,188 INFO org.apache.hadoop.yarn.server.resourcemanager.recovery.RMStateStore: Storing info for app: application_1376185025835_0001
2013-08-11 01:37:30,188 INFO org.apache.hadoop.yarn.server.resourcemanager.ClientRMService: Application with id 1 submitted by user ubuntu
2013-08-11 01:37:30,191 INFO org.apache.hadoop.yarn.server.resourcemanager.RMAuditLogger: USER=ubuntu	IP=192.168.100.15	OPERATION=Submit Application Request	TARGET=ClientRMService	RESULT=SUCCESS	APPID=application_1376185025835_0001
2013-08-11 01:37:30,240 INFO org.apache.hadoop.yarn.server.resourcemanager.rmapp.RMAppImpl: application_1376185025835_0001 State change from NEW to SUBMITTED
2013-08-11 01:37:30,243 INFO org.apache.hadoop.yarn.server.resourcemanager.ApplicationMasterService: Registering appattempt_1376185025835_0001_000001
2013-08-11 01:37:30,244 INFO org.apache.hadoop.yarn.server.resourcemanager.rmapp.attempt.RMAppAttemptImpl: appattempt_1376185025835_0001_000001 State change from NEW to SUBMITTED
2013-08-11 01:37:30,278 INFO org.apache.hadoop.yarn.server.resourcemanager.scheduler.capacity.LeafQueue: Application application_1376185025835_0001 from user: ubuntu activated in queue: default
2013-08-11 01:37:30,279 INFO org.apache.hadoop.yarn.server.resourcemanager.scheduler.capacity.LeafQueue: Application added - appId: application_1376185025835_0001 user: org.apache.hadoop.yarn.server.resourcemanager.scheduler.capacity.LeafQueue$User@16d29dd9, leaf-queue: default #user-pending-applications: 0 #user-active-applications: 1 #queue-pending-applications: 0 #queue-active-applications: 1
2013-08-11 01:37:30,279 INFO org.apache.hadoop.yarn.server.resourcemanager.scheduler.capacity.ParentQueue: Application added - appId: application_1376185025835_0001 user: ubuntu leaf-queue of parent: root #applications: 1
2013-08-11 01:37:30,279 INFO org.apache.hadoop.yarn.server.resourcemanager.scheduler.capacity.CapacityScheduler: Application Submission: appattempt_1376185025835_0001_000001, user: ubuntu queue: default: capacity=1.0, absoluteCapacity=1.0, usedResources=<memory:0, vCores:0>usedCapacity=0.0, absoluteUsedCapacity=0.0, numApps=1, numContainers=0, currently active: 1
2013-08-11 01:37:30,289 INFO org.apache.hadoop.yarn.server.resourcemanager.rmapp.attempt.RMAppAttemptImpl: appattempt_1376185025835_0001_000001 State change from SUBMITTED to SCHEDULED
2013-08-11 01:37:30,289 INFO org.apache.hadoop.yarn.server.resourcemanager.rmapp.RMAppImpl: application_1376185025835_0001 State change from SUBMITTED to ACCEPTED
2013-08-11 01:37:31,157 INFO org.apache.hadoop.yarn.server.resourcemanager.rmcontainer.RMContainerImpl: container_1376185025835_0001_01_000001 Container Transitioned from NEW to ALLOCATED
2013-08-11 01:37:31,157 INFO org.apache.hadoop.yarn.server.resourcemanager.RMAuditLogger: USER=ubuntu	OPERATION=AM Allocated Container	TARGET=SchedulerApp	RESULT=SUCCESS	APPID=application_1376185025835_0001	CONTAINERID=container_1376185025835_0001_01_000001
2013-08-11 01:37:31,158 INFO org.apache.hadoop.yarn.server.resourcemanager.scheduler.common.fica.FiCaSchedulerNode: Assigned container container_1376185025835_0001_01_000001 of capacity <memory:2048, vCores:1> on host hadoop-321-3:44876, which currently has 1 containers, <memory:2048, vCores:1> used and <memory:6144, vCores:15> available
2013-08-11 01:37:31,164 INFO org.apache.hadoop.yarn.server.resourcemanager.scheduler.capacity.LeafQueue: assignedContainer application=application_1376185025835_0001 container=Container: [ContainerId: container_1376185025835_0001_01_000001, NodeId: hadoop-321-3:44876, NodeHttpAddress: hadoop-321-3:8042, Resource: <memory:2048, vCores:1>, Priority: 0, State: NEW, Token: null, Status: container_id {, app_attempt_id {, application_id {, id: 1, cluster_timestamp: 1376185025835, }, attemptId: 1, }, id: 1, }, state: C_NEW, ] containerId=container_1376185025835_0001_01_000001 queue=default: capacity=1.0, absoluteCapacity=1.0, usedResources=<memory:0, vCores:0>usedCapacity=0.0, absoluteUsedCapacity=0.0, numApps=1, numContainers=0 usedCapacity=0.0 absoluteUsedCapacity=0.0 used=<memory:0, vCores:0> cluster=<memory:49152, vCores:96>
2013-08-11 01:37:31,165 INFO org.apache.hadoop.yarn.server.resourcemanager.scheduler.capacity.ParentQueue: Re-sorting queues since queue: root.default stats: default: capacity=1.0, absoluteCapacity=1.0, usedResources=<memory:2048, vCores:1>usedCapacity=0.041666668, absoluteUsedCapacity=0.041666668, numApps=1, numContainers=1
2013-08-11 01:37:31,168 INFO org.apache.hadoop.yarn.server.resourcemanager.scheduler.capacity.ParentQueue: assignedContainer queue=root usedCapacity=0.041666668 absoluteUsedCapacity=0.041666668 used=<memory:2048, vCores:1> cluster=<memory:49152, vCores:96>
2013-08-11 01:37:31,170 INFO org.apache.hadoop.yarn.server.resourcemanager.rmcontainer.RMContainerImpl: container_1376185025835_0001_01_000001 Container Transitioned from ALLOCATED to ACQUIRED
2013-08-11 01:37:31,173 INFO org.apache.hadoop.yarn.server.resourcemanager.rmapp.attempt.RMAppAttemptImpl: Storing attempt: AppId: application_1376185025835_0001 AttemptId: appattempt_1376185025835_0001_000001 MasterContainer: Container: [ContainerId: container_1376185025835_0001_01_000001, NodeId: hadoop-321-3:44876, NodeHttpAddress: hadoop-321-3:8042, Resource: <memory:2048, vCores:1>, Priority: 0, State: NEW, Token: null, Status: container_id {, app_attempt_id {, application_id {, id: 1, cluster_timestamp: 1376185025835, }, attemptId: 1, }, id: 1, }, state: C_NEW, ]
2013-08-11 01:37:31,176 INFO org.apache.hadoop.yarn.server.resourcemanager.rmapp.attempt.RMAppAttemptImpl: appattempt_1376185025835_0001_000001 State change from SCHEDULED to ALLOCATED_SAVING
2013-08-11 01:37:31,180 INFO org.apache.hadoop.yarn.server.resourcemanager.recovery.RMStateStore: Storing info for attempt: appattempt_1376185025835_0001_000001
2013-08-11 01:37:31,183 INFO org.apache.hadoop.yarn.server.resourcemanager.rmapp.attempt.RMAppAttemptImpl: appattempt_1376185025835_0001_000001 State change from ALLOCATED_SAVING to ALLOCATED
2013-08-11 01:37:31,190 INFO org.apache.hadoop.yarn.server.resourcemanager.amlauncher.AMLauncher: Launching masterappattempt_1376185025835_0001_000001
2013-08-11 01:37:31,234 INFO org.apache.hadoop.yarn.server.resourcemanager.amlauncher.AMLauncher: Setting up container Container: [ContainerId: container_1376185025835_0001_01_000001, NodeId: hadoop-321-3:44876, NodeHttpAddress: hadoop-321-3:8042, Resource: <memory:2048, vCores:1>, Priority: 0, State: NEW, Token: null, Status: container_id {, app_attempt_id {, application_id {, id: 1, cluster_timestamp: 1376185025835, }, attemptId: 1, }, id: 1, }, state: C_NEW, ] for AM appattempt_1376185025835_0001_000001
2013-08-11 01:37:31,234 INFO org.apache.hadoop.yarn.server.resourcemanager.amlauncher.AMLauncher: Command to launch container container_1376185025835_0001_01_000001 : $JAVA_HOME/bin/java -Dlog4j.configuration=container-log4j.properties -Dyarn.app.mapreduce.container.log.dir=<LOG_DIR> -Dyarn.app.mapreduce.container.log.filesize=0 -Dhadoop.root.logger=INFO,CLA  -Xmx1024m org.apache.hadoop.mapreduce.v2.app.MRAppMaster 1><LOG_DIR>/stdout 2><LOG_DIR>/stderr 
2013-08-11 01:37:32,139 INFO org.apache.hadoop.yarn.server.resourcemanager.amlauncher.AMLauncher: Done launching container Container: [ContainerId: container_1376185025835_0001_01_000001, NodeId: hadoop-321-3:44876, NodeHttpAddress: hadoop-321-3:8042, Resource: <memory:2048, vCores:1>, Priority: 0, State: NEW, Token: null, Status: container_id {, app_attempt_id {, application_id {, id: 1, cluster_timestamp: 1376185025835, }, attemptId: 1, }, id: 1, }, state: C_NEW, ] for AM appattempt_1376185025835_0001_000001
2013-08-11 01:37:32,140 INFO org.apache.hadoop.yarn.server.resourcemanager.rmapp.attempt.RMAppAttemptImpl: appattempt_1376185025835_0001_000001 State change from ALLOCATED to LAUNCHED
2013-08-11 01:37:32,163 INFO org.apache.hadoop.yarn.server.resourcemanager.rmcontainer.RMContainerImpl: container_1376185025835_0001_01_000001 Container Transitioned from ACQUIRED to RUNNING
2013-08-11 01:37:40,370 INFO org.apache.hadoop.yarn.server.resourcemanager.ApplicationMasterService: AM registration appattempt_1376185025835_0001_000001
2013-08-11 01:37:40,372 INFO org.apache.hadoop.yarn.server.resourcemanager.RMAuditLogger: USER=ubuntu	IP=192.168.100.18	OPERATION=Register App Master	TARGET=ApplicationMasterService	RESULT=SUCCESS	APPID=application_1376185025835_0001	APPATTEMPTID=appattempt_1376185025835_0001_000001
2013-08-11 01:37:40,377 INFO org.apache.hadoop.yarn.server.resourcemanager.rmapp.attempt.RMAppAttemptImpl: appattempt_1376185025835_0001_000001 State change from LAUNCHED to RUNNING
2013-08-11 01:37:40,377 INFO org.apache.hadoop.yarn.server.resourcemanager.rmapp.RMAppImpl: application_1376185025835_0001 State change from ACCEPTED to RUNNING
2013-08-11 01:37:42,177 INFO org.apache.hadoop.yarn.server.resourcemanager.rmcontainer.RMContainerImpl: container_1376185025835_0001_01_000002 Container Transitioned from NEW to ALLOCATED
2013-08-11 01:37:42,177 INFO org.apache.hadoop.yarn.server.resourcemanager.RMAuditLogger: USER=ubuntu	OPERATION=AM Allocated Container	TARGET=SchedulerApp	RESULT=SUCCESS	APPID=application_1376185025835_0001	CONTAINERID=container_1376185025835_0001_01_000002
2013-08-11 01:37:42,178 INFO org.apache.hadoop.yarn.server.resourcemanager.scheduler.common.fica.FiCaSchedulerNode: Assigned container container_1376185025835_0001_01_000002 of capacity <memory:1024, vCores:1> on host hadoop-321-7:41950, which currently has 1 containers, <memory:1024, vCores:1> used and <memory:7168, vCores:15> available
2013-08-11 01:37:42,180 INFO org.apache.hadoop.yarn.server.resourcemanager.scheduler.capacity.LeafQueue: assignedContainer application=application_1376185025835_0001 container=Container: [ContainerId: container_1376185025835_0001_01_000002, NodeId: hadoop-321-7:41950, NodeHttpAddress: hadoop-321-7:8042, Resource: <memory:1024, vCores:1>, Priority: 20, State: NEW, Token: null, Status: container_id {, app_attempt_id {, application_id {, id: 1, cluster_timestamp: 1376185025835, }, attemptId: 1, }, id: 2, }, state: C_NEW, ] containerId=container_1376185025835_0001_01_000002 queue=default: capacity=1.0, absoluteCapacity=1.0, usedResources=<memory:2048, vCores:1>usedCapacity=0.041666668, absoluteUsedCapacity=0.041666668, numApps=1, numContainers=1 usedCapacity=0.041666668 absoluteUsedCapacity=0.041666668 used=<memory:2048, vCores:1> cluster=<memory:49152, vCores:96>
2013-08-11 01:37:42,181 INFO org.apache.hadoop.yarn.server.resourcemanager.scheduler.capacity.ParentQueue: Re-sorting queues since queue: root.default stats: default: capacity=1.0, absoluteCapacity=1.0, usedResources=<memory:3072, vCores:2>usedCapacity=0.0625, absoluteUsedCapacity=0.0625, numApps=1, numContainers=2
2013-08-11 01:37:42,181 INFO org.apache.hadoop.yarn.server.resourcemanager.scheduler.capacity.ParentQueue: assignedContainer queue=root usedCapacity=0.0625 absoluteUsedCapacity=0.0625 used=<memory:3072, vCores:2> cluster=<memory:49152, vCores:96>
2013-08-11 01:37:42,184 INFO org.apache.hadoop.yarn.server.resourcemanager.rmcontainer.RMContainerImpl: container_1376185025835_0001_01_000003 Container Transitioned from NEW to ALLOCATED
2013-08-11 01:37:42,185 INFO org.apache.hadoop.yarn.server.resourcemanager.RMAuditLogger: USER=ubuntu	OPERATION=AM Allocated Container	TARGET=SchedulerApp	RESULT=SUCCESS	APPID=application_1376185025835_0001	CONTAINERID=container_1376185025835_0001_01_000003
2013-08-11 01:37:42,185 INFO org.apache.hadoop.yarn.server.resourcemanager.scheduler.common.fica.FiCaSchedulerNode: Assigned container container_1376185025835_0001_01_000003 of capacity <memory:1024, vCores:1> on host hadoop-321-4:43757, which currently has 1 containers, <memory:1024, vCores:1> used and <memory:7168, vCores:15> available
2013-08-11 01:37:42,186 INFO org.apache.hadoop.yarn.server.resourcemanager.scheduler.capacity.LeafQueue: assignedContainer application=application_1376185025835_0001 container=Container: [ContainerId: container_1376185025835_0001_01_000003, NodeId: hadoop-321-4:43757, NodeHttpAddress: hadoop-321-4:8042, Resource: <memory:1024, vCores:1>, Priority: 20, State: NEW, Token: null, Status: container_id {, app_attempt_id {, application_id {, id: 1, cluster_timestamp: 1376185025835, }, attemptId: 1, }, id: 3, }, state: C_NEW, ] containerId=container_1376185025835_0001_01_000003 queue=default: capacity=1.0, absoluteCapacity=1.0, usedResources=<memory:3072, vCores:2>usedCapacity=0.0625, absoluteUsedCapacity=0.0625, numApps=1, numContainers=2 usedCapacity=0.0625 absoluteUsedCapacity=0.0625 used=<memory:3072, vCores:2> cluster=<memory:49152, vCores:96>
2013-08-11 01:37:42,187 INFO org.apache.hadoop.yarn.server.resourcemanager.scheduler.capacity.ParentQueue: Re-sorting queues since queue: root.default stats: default: capacity=1.0, absoluteCapacity=1.0, usedResources=<memory:4096, vCores:3>usedCapacity=0.083333336, absoluteUsedCapacity=0.083333336, numApps=1, numContainers=3
2013-08-11 01:37:42,187 INFO org.apache.hadoop.yarn.server.resourcemanager.scheduler.capacity.ParentQueue: assignedContainer queue=root usedCapacity=0.083333336 absoluteUsedCapacity=0.083333336 used=<memory:4096, vCores:3> cluster=<memory:49152, vCores:96>
2013-08-11 01:37:42,434 INFO org.apache.hadoop.yarn.server.resourcemanager.rmcontainer.RMContainerImpl: container_1376185025835_0001_01_000002 Container Transitioned from ALLOCATED to ACQUIRED
2013-08-11 01:37:42,436 INFO org.apache.hadoop.yarn.server.resourcemanager.rmcontainer.RMContainerImpl: container_1376185025835_0001_01_000003 Container Transitioned from ALLOCATED to ACQUIRED
2013-08-11 01:37:43,466 INFO org.apache.hadoop.yarn.server.resourcemanager.scheduler.AppSchedulingInfo: checking for deactivate... 
2013-08-11 01:37:44,210 INFO org.apache.hadoop.yarn.server.resourcemanager.rmcontainer.RMContainerImpl: container_1376185025835_0001_01_000002 Container Transitioned from ACQUIRED to RUNNING
2013-08-11 01:37:44,267 INFO org.apache.hadoop.yarn.server.resourcemanager.rmcontainer.RMContainerImpl: container_1376185025835_0001_01_000003 Container Transitioned from ACQUIRED to RUNNING
2013-08-11 01:40:28,557 INFO org.apache.hadoop.yarn.server.resourcemanager.rmcontainer.RMContainerImpl: container_1376185025835_0001_01_000003 Container Transitioned from RUNNING to COMPLETED
2013-08-11 01:40:28,558 INFO org.apache.hadoop.yarn.server.resourcemanager.scheduler.common.fica.FiCaSchedulerApp: Completed container: container_1376185025835_0001_01_000003 in state: COMPLETED event:FINISHED
2013-08-11 01:40:28,558 INFO org.apache.hadoop.yarn.server.resourcemanager.RMAuditLogger: USER=ubuntu	OPERATION=AM Released Container	TARGET=SchedulerApp	RESULT=SUCCESS	APPID=application_1376185025835_0001	CONTAINERID=container_1376185025835_0001_01_000003
2013-08-11 01:40:28,558 INFO org.apache.hadoop.yarn.server.resourcemanager.scheduler.common.fica.FiCaSchedulerNode: Released container container_1376185025835_0001_01_000003 of capacity <memory:1024, vCores:1> on host hadoop-321-4:43757, which currently has 0 containers, <memory:0, vCores:0> used and <memory:8192, vCores:16> available, release resources=true
2013-08-11 01:40:28,558 INFO org.apache.hadoop.yarn.server.resourcemanager.scheduler.capacity.LeafQueue: default used=<memory:3072, vCores:2> numContainers=2 user=ubuntu user-resources=<memory:3072, vCores:2>
2013-08-11 01:40:28,561 INFO org.apache.hadoop.yarn.server.resourcemanager.scheduler.capacity.LeafQueue: completedContainer container=Container: [ContainerId: container_1376185025835_0001_01_000003, NodeId: hadoop-321-4:43757, NodeHttpAddress: hadoop-321-4:8042, Resource: <memory:1024, vCores:1>, Priority: 20, State: NEW, Token: null, Status: container_id {, app_attempt_id {, application_id {, id: 1, cluster_timestamp: 1376185025835, }, attemptId: 1, }, id: 3, }, state: C_COMPLETE, diagnostics: "Container killed by the ApplicationMaster.\n\n", exit_status: 143, ] resource=<memory:1024, vCores:1> queue=default: capacity=1.0, absoluteCapacity=1.0, usedResources=<memory:3072, vCores:2>usedCapacity=0.0625, absoluteUsedCapacity=0.0625, numApps=1, numContainers=2 usedCapacity=0.0625 absoluteUsedCapacity=0.0625 used=<memory:3072, vCores:2> cluster=<memory:49152, vCores:96>
2013-08-11 01:40:28,561 INFO org.apache.hadoop.yarn.server.resourcemanager.scheduler.capacity.ParentQueue: completedContainer queue=root usedCapacity=0.0625 absoluteUsedCapacity=0.0625 used=<memory:3072, vCores:2> cluster=<memory:49152, vCores:96>
2013-08-11 01:40:28,561 INFO org.apache.hadoop.yarn.server.resourcemanager.scheduler.capacity.CapacityScheduler: Application appattempt_1376185025835_0001_000001 released container container_1376185025835_0001_01_000003 on node: host: hadoop-321-4:43757 #containers=0 available=8192 used=0 with event: FINISHED
2013-08-11 01:40:33,352 INFO org.apache.hadoop.yarn.server.resourcemanager.rmcontainer.RMContainerImpl: container_1376185025835_0001_01_000002 Container Transitioned from RUNNING to COMPLETED
2013-08-11 01:40:33,353 INFO org.apache.hadoop.yarn.server.resourcemanager.scheduler.common.fica.FiCaSchedulerApp: Completed container: container_1376185025835_0001_01_000002 in state: COMPLETED event:FINISHED
2013-08-11 01:40:33,353 INFO org.apache.hadoop.yarn.server.resourcemanager.RMAuditLogger: USER=ubuntu	OPERATION=AM Released Container	TARGET=SchedulerApp	RESULT=SUCCESS	APPID=application_1376185025835_0001	CONTAINERID=container_1376185025835_0001_01_000002
2013-08-11 01:40:33,353 INFO org.apache.hadoop.yarn.server.resourcemanager.scheduler.common.fica.FiCaSchedulerNode: Released container container_1376185025835_0001_01_000002 of capacity <memory:1024, vCores:1> on host hadoop-321-7:41950, which currently has 0 containers, <memory:0, vCores:0> used and <memory:8192, vCores:16> available, release resources=true
2013-08-11 01:40:33,353 INFO org.apache.hadoop.yarn.server.resourcemanager.scheduler.capacity.LeafQueue: default used=<memory:2048, vCores:1> numContainers=1 user=ubuntu user-resources=<memory:2048, vCores:1>
2013-08-11 01:40:33,355 INFO org.apache.hadoop.yarn.server.resourcemanager.scheduler.capacity.LeafQueue: completedContainer container=Container: [ContainerId: container_1376185025835_0001_01_000002, NodeId: hadoop-321-7:41950, NodeHttpAddress: hadoop-321-7:8042, Resource: <memory:1024, vCores:1>, Priority: 20, State: NEW, Token: null, Status: container_id {, app_attempt_id {, application_id {, id: 1, cluster_timestamp: 1376185025835, }, attemptId: 1, }, id: 2, }, state: C_COMPLETE, diagnostics: "Container killed by the ApplicationMaster.\n\n", exit_status: 143, ] resource=<memory:1024, vCores:1> queue=default: capacity=1.0, absoluteCapacity=1.0, usedResources=<memory:2048, vCores:1>usedCapacity=0.041666668, absoluteUsedCapacity=0.041666668, numApps=1, numContainers=1 usedCapacity=0.041666668 absoluteUsedCapacity=0.041666668 used=<memory:2048, vCores:1> cluster=<memory:49152, vCores:96>
2013-08-11 01:40:33,355 INFO org.apache.hadoop.yarn.server.resourcemanager.scheduler.capacity.ParentQueue: completedContainer queue=root usedCapacity=0.041666668 absoluteUsedCapacity=0.041666668 used=<memory:2048, vCores:1> cluster=<memory:49152, vCores:96>
2013-08-11 01:40:33,356 INFO org.apache.hadoop.yarn.server.resourcemanager.scheduler.capacity.CapacityScheduler: Application appattempt_1376185025835_0001_000001 released container container_1376185025835_0001_01_000002 on node: host: hadoop-321-7:41950 #containers=0 available=8192 used=0 with event: FINISHED
2013-08-11 01:40:37,142 INFO org.apache.hadoop.yarn.server.resourcemanager.rmapp.attempt.RMAppAttemptImpl: appattempt_1376185025835_0001_000001 State change from RUNNING to FINISHING
2013-08-11 01:40:37,143 INFO org.apache.hadoop.yarn.server.resourcemanager.rmapp.RMAppImpl: application_1376185025835_0001 State change from RUNNING to FINISHING
2013-08-11 01:40:37,925 INFO org.apache.hadoop.yarn.server.resourcemanager.rmcontainer.RMContainerImpl: container_1376185025835_0001_01_000001 Container Transitioned from RUNNING to COMPLETED
2013-08-11 01:40:37,925 INFO org.apache.hadoop.yarn.server.resourcemanager.scheduler.common.fica.FiCaSchedulerApp: Completed container: container_1376185025835_0001_01_000001 in state: COMPLETED event:FINISHED
2013-08-11 01:40:37,927 INFO org.apache.hadoop.yarn.server.resourcemanager.RMAuditLogger: USER=ubuntu	OPERATION=AM Released Container	TARGET=SchedulerApp	RESULT=SUCCESS	APPID=application_1376185025835_0001	CONTAINERID=container_1376185025835_0001_01_000001
2013-08-11 01:40:37,927 INFO org.apache.hadoop.yarn.server.resourcemanager.scheduler.common.fica.FiCaSchedulerNode: Released container container_1376185025835_0001_01_000001 of capacity <memory:2048, vCores:1> on host hadoop-321-3:44876, which currently has 0 containers, <memory:0, vCores:0> used and <memory:8192, vCores:16> available, release resources=true
2013-08-11 01:40:37,928 INFO org.apache.hadoop.yarn.server.resourcemanager.scheduler.capacity.LeafQueue: default used=<memory:0, vCores:0> numContainers=0 user=ubuntu user-resources=<memory:0, vCores:0>
2013-08-11 01:40:37,930 INFO org.apache.hadoop.yarn.server.resourcemanager.scheduler.capacity.LeafQueue: completedContainer container=Container: [ContainerId: container_1376185025835_0001_01_000001, NodeId: hadoop-321-3:44876, NodeHttpAddress: hadoop-321-3:8042, Resource: <memory:2048, vCores:1>, Priority: 0, State: NEW, Token: null, Status: container_id {, app_attempt_id {, application_id {, id: 1, cluster_timestamp: 1376185025835, }, attemptId: 1, }, id: 1, }, state: C_COMPLETE, diagnostics: "", exit_status: 0, ] resource=<memory:2048, vCores:1> queue=default: capacity=1.0, absoluteCapacity=1.0, usedResources=<memory:0, vCores:0>usedCapacity=0.0, absoluteUsedCapacity=0.0, numApps=1, numContainers=0 usedCapacity=0.0 absoluteUsedCapacity=0.0 used=<memory:0, vCores:0> cluster=<memory:49152, vCores:96>
2013-08-11 01:40:37,930 INFO org.apache.hadoop.yarn.server.resourcemanager.scheduler.capacity.ParentQueue: completedContainer queue=root usedCapacity=0.0 absoluteUsedCapacity=0.0 used=<memory:0, vCores:0> cluster=<memory:49152, vCores:96>
2013-08-11 01:40:37,930 INFO org.apache.hadoop.yarn.server.resourcemanager.scheduler.capacity.CapacityScheduler: Application appattempt_1376185025835_0001_000001 released container container_1376185025835_0001_01_000001 on node: host: hadoop-321-3:44876 #containers=0 available=8192 used=0 with event: FINISHED
2013-08-11 01:40:37,932 INFO org.apache.hadoop.yarn.server.resourcemanager.rmapp.attempt.RMAppAttemptImpl: appattempt_1376185025835_0001_000001 State change from FINISHING to FINISHED
2013-08-11 01:40:37,935 INFO org.apache.hadoop.yarn.server.resourcemanager.rmapp.RMAppImpl: application_1376185025835_0001 State change from FINISHING to FINISHED
2013-08-11 01:40:37,935 INFO org.apache.hadoop.yarn.server.resourcemanager.scheduler.capacity.CapacityScheduler: Application appattempt_1376185025835_0001_000001 is done. finalState=FINISHED
2013-08-11 01:40:37,936 INFO org.apache.hadoop.yarn.server.resourcemanager.scheduler.AppSchedulingInfo: Application application_1376185025835_0001 requests cleared
2013-08-11 01:40:37,937 INFO org.apache.hadoop.yarn.server.resourcemanager.scheduler.capacity.LeafQueue: Application removed - appId: application_1376185025835_0001 user: ubuntu queue: default #user-pending-applications: 0 #user-active-applications: 0 #queue-pending-applications: 0 #queue-active-applications: 0
2013-08-11 01:40:37,937 INFO org.apache.hadoop.yarn.server.resourcemanager.scheduler.capacity.ParentQueue: Application removed - appId: application_1376185025835_0001 user: ubuntu leaf-queue of parent: root #applications: 0
2013-08-11 01:40:37,938 INFO org.apache.hadoop.yarn.server.resourcemanager.RMAuditLogger: USER=ubuntu	OPERATION=Application Finished - Succeeded	TARGET=RMAppManager	RESULT=SUCCESS	APPID=application_1376185025835_0001
2013-08-11 01:40:37,938 INFO org.apache.hadoop.yarn.server.resourcemanager.amlauncher.AMLauncher: Cleaning master appattempt_1376185025835_0001_000001
2013-08-11 01:40:37,943 INFO org.apache.hadoop.yarn.server.resourcemanager.recovery.RMStateStore: Removing info for app: application_1376185025835_0001
2013-08-11 01:40:37,946 INFO org.apache.hadoop.yarn.server.resourcemanager.RMAppManager$ApplicationSummary: appId=application_1376185025835_0001,name=TeraGen,user=ubuntu,queue=default,state=FINISHED,trackingUrl=hadoop-321-1.novalocal:8088/proxy/application_1376185025835_0001/jobhistory/job/job_1376185025835_0001,appMasterHost=hadoop-321-3,startTime=1376185050178,finishTime=1376185237143
2013-08-11 01:40:38,834 INFO org.apache.hadoop.yarn.server.resourcemanager.ClientRMService: Allocated new applicationId: 2
2013-08-11 01:40:40,808 INFO org.apache.hadoop.yarn.server.resourcemanager.ClientRMService: Storing Application with id application_1376185025835_0002
2013-08-11 01:40:40,808 INFO org.apache.hadoop.yarn.server.resourcemanager.recovery.RMStateStore: Storing info for app: application_1376185025835_0002
2013-08-11 01:40:40,809 INFO org.apache.hadoop.yarn.server.resourcemanager.ClientRMService: Application with id 2 submitted by user ubuntu
2013-08-11 01:40:40,809 INFO org.apache.hadoop.yarn.server.resourcemanager.RMAuditLogger: USER=ubuntu	IP=192.168.100.15	OPERATION=Submit Application Request	TARGET=ClientRMService	RESULT=SUCCESS	APPID=application_1376185025835_0002
2013-08-11 01:40:40,811 INFO org.apache.hadoop.yarn.server.resourcemanager.rmapp.RMAppImpl: application_1376185025835_0002 State change from NEW to SUBMITTED
2013-08-11 01:40:40,811 INFO org.apache.hadoop.yarn.server.resourcemanager.ApplicationMasterService: Registering appattempt_1376185025835_0002_000001
2013-08-11 01:40:40,811 INFO org.apache.hadoop.yarn.server.resourcemanager.rmapp.attempt.RMAppAttemptImpl: appattempt_1376185025835_0002_000001 State change from NEW to SUBMITTED
2013-08-11 01:40:40,812 INFO org.apache.hadoop.yarn.server.resourcemanager.scheduler.capacity.LeafQueue: Application application_1376185025835_0002 from user: ubuntu activated in queue: default
2013-08-11 01:40:40,812 INFO org.apache.hadoop.yarn.server.resourcemanager.scheduler.capacity.LeafQueue: Application added - appId: application_1376185025835_0002 user: org.apache.hadoop.yarn.server.resourcemanager.scheduler.capacity.LeafQueue$User@1a0c00, leaf-queue: default #user-pending-applications: 0 #user-active-applications: 1 #queue-pending-applications: 0 #queue-active-applications: 1
2013-08-11 01:40:40,812 INFO org.apache.hadoop.yarn.server.resourcemanager.scheduler.capacity.ParentQueue: Application added - appId: application_1376185025835_0002 user: ubuntu leaf-queue of parent: root #applications: 1
2013-08-11 01:40:40,812 INFO org.apache.hadoop.yarn.server.resourcemanager.scheduler.capacity.CapacityScheduler: Application Submission: appattempt_1376185025835_0002_000001, user: ubuntu queue: default: capacity=1.0, absoluteCapacity=1.0, usedResources=<memory:0, vCores:0>usedCapacity=0.0, absoluteUsedCapacity=0.0, numApps=1, numContainers=0, currently active: 1
2013-08-11 01:40:40,813 INFO org.apache.hadoop.yarn.server.resourcemanager.rmapp.attempt.RMAppAttemptImpl: appattempt_1376185025835_0002_000001 State change from SUBMITTED to SCHEDULED
2013-08-11 01:40:40,813 INFO org.apache.hadoop.yarn.server.resourcemanager.rmapp.RMAppImpl: application_1376185025835_0002 State change from SUBMITTED to ACCEPTED
2013-08-11 01:40:40,940 INFO org.apache.hadoop.yarn.server.resourcemanager.rmcontainer.RMContainerImpl: container_1376185025835_0002_01_000001 Container Transitioned from NEW to ALLOCATED
2013-08-11 01:40:40,940 INFO org.apache.hadoop.yarn.server.resourcemanager.RMAuditLogger: USER=ubuntu	OPERATION=AM Allocated Container	TARGET=SchedulerApp	RESULT=SUCCESS	APPID=application_1376185025835_0002	CONTAINERID=container_1376185025835_0002_01_000001
2013-08-11 01:40:40,940 INFO org.apache.hadoop.yarn.server.resourcemanager.scheduler.common.fica.FiCaSchedulerNode: Assigned container container_1376185025835_0002_01_000001 of capacity <memory:2048, vCores:1> on host hadoop-321-3:44876, which currently has 1 containers, <memory:2048, vCores:1> used and <memory:6144, vCores:15> available
2013-08-11 01:40:40,942 INFO org.apache.hadoop.yarn.server.resourcemanager.scheduler.capacity.LeafQueue: assignedContainer application=application_1376185025835_0002 container=Container: [ContainerId: container_1376185025835_0002_01_000001, NodeId: hadoop-321-3:44876, NodeHttpAddress: hadoop-321-3:8042, Resource: <memory:2048, vCores:1>, Priority: 0, State: NEW, Token: null, Status: container_id {, app_attempt_id {, application_id {, id: 2, cluster_timestamp: 1376185025835, }, attemptId: 1, }, id: 1, }, state: C_NEW, ] containerId=container_1376185025835_0002_01_000001 queue=default: capacity=1.0, absoluteCapacity=1.0, usedResources=<memory:0, vCores:0>usedCapacity=0.0, absoluteUsedCapacity=0.0, numApps=1, numContainers=0 usedCapacity=0.0 absoluteUsedCapacity=0.0 used=<memory:0, vCores:0> cluster=<memory:49152, vCores:96>
2013-08-11 01:40:40,942 INFO org.apache.hadoop.yarn.server.resourcemanager.scheduler.capacity.ParentQueue: Re-sorting queues since queue: root.default stats: default: capacity=1.0, absoluteCapacity=1.0, usedResources=<memory:2048, vCores:1>usedCapacity=0.041666668, absoluteUsedCapacity=0.041666668, numApps=1, numContainers=1
2013-08-11 01:40:40,942 INFO org.apache.hadoop.yarn.server.resourcemanager.scheduler.capacity.ParentQueue: assignedContainer queue=root usedCapacity=0.041666668 absoluteUsedCapacity=0.041666668 used=<memory:2048, vCores:1> cluster=<memory:49152, vCores:96>
2013-08-11 01:40:40,944 INFO org.apache.hadoop.yarn.server.resourcemanager.rmcontainer.RMContainerImpl: container_1376185025835_0002_01_000001 Container Transitioned from ALLOCATED to ACQUIRED
2013-08-11 01:40:40,946 INFO org.apache.hadoop.yarn.server.resourcemanager.rmapp.attempt.RMAppAttemptImpl: Storing attempt: AppId: application_1376185025835_0002 AttemptId: appattempt_1376185025835_0002_000001 MasterContainer: Container: [ContainerId: container_1376185025835_0002_01_000001, NodeId: hadoop-321-3:44876, NodeHttpAddress: hadoop-321-3:8042, Resource: <memory:2048, vCores:1>, Priority: 0, State: NEW, Token: null, Status: container_id {, app_attempt_id {, application_id {, id: 2, cluster_timestamp: 1376185025835, }, attemptId: 1, }, id: 1, }, state: C_NEW, ]
2013-08-11 01:40:40,946 INFO org.apache.hadoop.yarn.server.resourcemanager.rmapp.attempt.RMAppAttemptImpl: appattempt_1376185025835_0002_000001 State change from SCHEDULED to ALLOCATED_SAVING
2013-08-11 01:40:40,946 INFO org.apache.hadoop.yarn.server.resourcemanager.recovery.RMStateStore: Storing info for attempt: appattempt_1376185025835_0002_000001
2013-08-11 01:40:40,947 INFO org.apache.hadoop.yarn.server.resourcemanager.rmapp.attempt.RMAppAttemptImpl: appattempt_1376185025835_0002_000001 State change from ALLOCATED_SAVING to ALLOCATED
2013-08-11 01:40:40,949 INFO org.apache.hadoop.yarn.server.resourcemanager.amlauncher.AMLauncher: Launching masterappattempt_1376185025835_0002_000001
2013-08-11 01:40:40,952 INFO org.apache.hadoop.yarn.server.resourcemanager.amlauncher.AMLauncher: Setting up container Container: [ContainerId: container_1376185025835_0002_01_000001, NodeId: hadoop-321-3:44876, NodeHttpAddress: hadoop-321-3:8042, Resource: <memory:2048, vCores:1>, Priority: 0, State: NEW, Token: null, Status: container_id {, app_attempt_id {, application_id {, id: 2, cluster_timestamp: 1376185025835, }, attemptId: 1, }, id: 1, }, state: C_NEW, ] for AM appattempt_1376185025835_0002_000001
2013-08-11 01:40:40,952 INFO org.apache.hadoop.yarn.server.resourcemanager.amlauncher.AMLauncher: Command to launch container container_1376185025835_0002_01_000001 : $JAVA_HOME/bin/java -Dlog4j.configuration=container-log4j.properties -Dyarn.app.mapreduce.container.log.dir=<LOG_DIR> -Dyarn.app.mapreduce.container.log.filesize=0 -Dhadoop.root.logger=INFO,CLA  -Xmx1024m org.apache.hadoop.mapreduce.v2.app.MRAppMaster 1><LOG_DIR>/stdout 2><LOG_DIR>/stderr 
2013-08-11 01:40:40,974 INFO org.apache.hadoop.yarn.server.resourcemanager.amlauncher.AMLauncher: Done launching container Container: [ContainerId: container_1376185025835_0002_01_000001, NodeId: hadoop-321-3:44876, NodeHttpAddress: hadoop-321-3:8042, Resource: <memory:2048, vCores:1>, Priority: 0, State: NEW, Token: null, Status: container_id {, app_attempt_id {, application_id {, id: 2, cluster_timestamp: 1376185025835, }, attemptId: 1, }, id: 1, }, state: C_NEW, ] for AM appattempt_1376185025835_0002_000001
2013-08-11 01:40:40,975 INFO org.apache.hadoop.yarn.server.resourcemanager.rmapp.attempt.RMAppAttemptImpl: appattempt_1376185025835_0002_000001 State change from ALLOCATED to LAUNCHED
2013-08-11 01:40:41,948 INFO org.apache.hadoop.yarn.server.resourcemanager.rmcontainer.RMContainerImpl: container_1376185025835_0002_01_000001 Container Transitioned from ACQUIRED to RUNNING
2013-08-11 01:40:48,280 INFO org.apache.hadoop.yarn.server.resourcemanager.ApplicationMasterService: AM registration appattempt_1376185025835_0002_000001
2013-08-11 01:40:48,280 INFO org.apache.hadoop.yarn.server.resourcemanager.RMAuditLogger: USER=ubuntu	IP=192.168.100.18	OPERATION=Register App Master	TARGET=ApplicationMasterService	RESULT=SUCCESS	APPID=application_1376185025835_0002	APPATTEMPTID=appattempt_1376185025835_0002_000001
2013-08-11 01:40:48,282 INFO org.apache.hadoop.yarn.server.resourcemanager.rmapp.attempt.RMAppAttemptImpl: appattempt_1376185025835_0002_000001 State change from LAUNCHED to RUNNING
2013-08-11 01:40:48,283 INFO org.apache.hadoop.yarn.server.resourcemanager.rmapp.RMAppImpl: application_1376185025835_0002 State change from ACCEPTED to RUNNING
2013-08-11 01:40:49,396 INFO org.apache.hadoop.yarn.server.resourcemanager.rmcontainer.RMContainerImpl: container_1376185025835_0002_01_000002 Container Transitioned from NEW to ALLOCATED
2013-08-11 01:40:49,396 INFO org.apache.hadoop.yarn.server.resourcemanager.RMAuditLogger: USER=ubuntu	OPERATION=AM Allocated Container	TARGET=SchedulerApp	RESULT=SUCCESS	APPID=application_1376185025835_0002	CONTAINERID=container_1376185025835_0002_01_000002
2013-08-11 01:40:49,397 INFO org.apache.hadoop.yarn.server.resourcemanager.scheduler.common.fica.FiCaSchedulerNode: Assigned container container_1376185025835_0002_01_000002 of capacity <memory:1024, vCores:1> on host hadoop-321-3:44876, which currently has 2 containers, <memory:3072, vCores:2> used and <memory:5120, vCores:14> available
2013-08-11 01:40:49,398 INFO org.apache.hadoop.yarn.server.resourcemanager.scheduler.capacity.LeafQueue: assignedContainer application=application_1376185025835_0002 container=Container: [ContainerId: container_1376185025835_0002_01_000002, NodeId: hadoop-321-3:44876, NodeHttpAddress: hadoop-321-3:8042, Resource: <memory:1024, vCores:1>, Priority: 20, State: NEW, Token: null, Status: container_id {, app_attempt_id {, application_id {, id: 2, cluster_timestamp: 1376185025835, }, attemptId: 1, }, id: 2, }, state: C_NEW, ] containerId=container_1376185025835_0002_01_000002 queue=default: capacity=1.0, absoluteCapacity=1.0, usedResources=<memory:2048, vCores:1>usedCapacity=0.041666668, absoluteUsedCapacity=0.041666668, numApps=1, numContainers=1 usedCapacity=0.041666668 absoluteUsedCapacity=0.041666668 used=<memory:2048, vCores:1> cluster=<memory:49152, vCores:96>
2013-08-11 01:40:49,399 INFO org.apache.hadoop.yarn.server.resourcemanager.scheduler.capacity.ParentQueue: Re-sorting queues since queue: root.default stats: default: capacity=1.0, absoluteCapacity=1.0, usedResources=<memory:3072, vCores:2>usedCapacity=0.0625, absoluteUsedCapacity=0.0625, numApps=1, numContainers=2
2013-08-11 01:40:49,399 INFO org.apache.hadoop.yarn.server.resourcemanager.scheduler.capacity.ParentQueue: assignedContainer queue=root usedCapacity=0.0625 absoluteUsedCapacity=0.0625 used=<memory:3072, vCores:2> cluster=<memory:49152, vCores:96>
2013-08-11 01:40:49,418 INFO org.apache.hadoop.yarn.server.resourcemanager.rmcontainer.RMContainerImpl: container_1376185025835_0002_01_000003 Container Transitioned from NEW to ALLOCATED
2013-08-11 01:40:49,418 INFO org.apache.hadoop.yarn.server.resourcemanager.RMAuditLogger: USER=ubuntu	OPERATION=AM Allocated Container	TARGET=SchedulerApp	RESULT=SUCCESS	APPID=application_1376185025835_0002	CONTAINERID=container_1376185025835_0002_01_000003
2013-08-11 01:40:49,418 INFO org.apache.hadoop.yarn.server.resourcemanager.scheduler.common.fica.FiCaSchedulerNode: Assigned container container_1376185025835_0002_01_000003 of capacity <memory:1024, vCores:1> on host hadoop-321-7:41950, which currently has 1 containers, <memory:1024, vCores:1> used and <memory:7168, vCores:15> available
2013-08-11 01:40:49,420 INFO org.apache.hadoop.yarn.server.resourcemanager.scheduler.capacity.LeafQueue: assignedContainer application=application_1376185025835_0002 container=Container: [ContainerId: container_1376185025835_0002_01_000003, NodeId: hadoop-321-7:41950, NodeHttpAddress: hadoop-321-7:8042, Resource: <memory:1024, vCores:1>, Priority: 20, State: NEW, Token: null, Status: container_id {, app_attempt_id {, application_id {, id: 2, cluster_timestamp: 1376185025835, }, attemptId: 1, }, id: 3, }, state: C_NEW, ] containerId=container_1376185025835_0002_01_000003 queue=default: capacity=1.0, absoluteCapacity=1.0, usedResources=<memory:3072, vCores:2>usedCapacity=0.0625, absoluteUsedCapacity=0.0625, numApps=1, numContainers=2 usedCapacity=0.0625 absoluteUsedCapacity=0.0625 used=<memory:3072, vCores:2> cluster=<memory:49152, vCores:96>
2013-08-11 01:40:49,420 INFO org.apache.hadoop.yarn.server.resourcemanager.scheduler.capacity.ParentQueue: Re-sorting queues since queue: root.default stats: default: capacity=1.0, absoluteCapacity=1.0, usedResources=<memory:4096, vCores:3>usedCapacity=0.083333336, absoluteUsedCapacity=0.083333336, numApps=1, numContainers=3
2013-08-11 01:40:49,420 INFO org.apache.hadoop.yarn.server.resourcemanager.scheduler.capacity.ParentQueue: assignedContainer queue=root usedCapacity=0.083333336 absoluteUsedCapacity=0.083333336 used=<memory:4096, vCores:3> cluster=<memory:49152, vCores:96>
2013-08-11 01:40:50,336 INFO org.apache.hadoop.yarn.server.resourcemanager.rmcontainer.RMContainerImpl: container_1376185025835_0002_01_000002 Container Transitioned from ALLOCATED to ACQUIRED
2013-08-11 01:40:50,345 INFO org.apache.hadoop.yarn.server.resourcemanager.rmcontainer.RMContainerImpl: container_1376185025835_0002_01_000003 Container Transitioned from ALLOCATED to ACQUIRED
2013-08-11 01:40:51,373 INFO org.apache.hadoop.yarn.server.resourcemanager.scheduler.AppSchedulingInfo: checking for deactivate... 
2013-08-11 01:40:51,407 INFO org.apache.hadoop.yarn.server.resourcemanager.rmcontainer.RMContainerImpl: container_1376185025835_0002_01_000002 Container Transitioned from ACQUIRED to RUNNING
2013-08-11 01:40:51,427 INFO org.apache.hadoop.yarn.server.resourcemanager.rmcontainer.RMContainerImpl: container_1376185025835_0002_01_000003 Container Transitioned from ACQUIRED to RUNNING
2013-08-11 01:43:44,572 INFO org.apache.hadoop.yarn.server.resourcemanager.rmcontainer.RMContainerImpl: container_1376185025835_0002_01_000003 Container Transitioned from RUNNING to COMPLETED
2013-08-11 01:43:44,573 INFO org.apache.hadoop.yarn.server.resourcemanager.scheduler.common.fica.FiCaSchedulerApp: Completed container: container_1376185025835_0002_01_000003 in state: COMPLETED event:FINISHED
2013-08-11 01:43:44,573 INFO org.apache.hadoop.yarn.server.resourcemanager.RMAuditLogger: USER=ubuntu	OPERATION=AM Released Container	TARGET=SchedulerApp	RESULT=SUCCESS	APPID=application_1376185025835_0002	CONTAINERID=container_1376185025835_0002_01_000003
2013-08-11 01:43:44,573 INFO org.apache.hadoop.yarn.server.resourcemanager.scheduler.common.fica.FiCaSchedulerNode: Released container container_1376185025835_0002_01_000003 of capacity <memory:1024, vCores:1> on host hadoop-321-7:41950, which currently has 0 containers, <memory:0, vCores:0> used and <memory:8192, vCores:16> available, release resources=true
2013-08-11 01:43:44,573 INFO org.apache.hadoop.yarn.server.resourcemanager.scheduler.capacity.LeafQueue: default used=<memory:3072, vCores:2> numContainers=2 user=ubuntu user-resources=<memory:3072, vCores:2>
2013-08-11 01:43:44,587 INFO org.apache.hadoop.yarn.server.resourcemanager.scheduler.capacity.LeafQueue: completedContainer container=Container: [ContainerId: container_1376185025835_0002_01_000003, NodeId: hadoop-321-7:41950, NodeHttpAddress: hadoop-321-7:8042, Resource: <memory:1024, vCores:1>, Priority: 20, State: NEW, Token: null, Status: container_id {, app_attempt_id {, application_id {, id: 2, cluster_timestamp: 1376185025835, }, attemptId: 1, }, id: 3, }, state: C_COMPLETE, diagnostics: "Container killed by the ApplicationMaster.\n\n", exit_status: 143, ] resource=<memory:1024, vCores:1> queue=default: capacity=1.0, absoluteCapacity=1.0, usedResources=<memory:3072, vCores:2>usedCapacity=0.0625, absoluteUsedCapacity=0.0625, numApps=1, numContainers=2 usedCapacity=0.0625 absoluteUsedCapacity=0.0625 used=<memory:3072, vCores:2> cluster=<memory:49152, vCores:96>
2013-08-11 01:43:44,587 INFO org.apache.hadoop.yarn.server.resourcemanager.scheduler.capacity.ParentQueue: completedContainer queue=root usedCapacity=0.0625 absoluteUsedCapacity=0.0625 used=<memory:3072, vCores:2> cluster=<memory:49152, vCores:96>
2013-08-11 01:43:44,587 INFO org.apache.hadoop.yarn.server.resourcemanager.scheduler.capacity.CapacityScheduler: Application appattempt_1376185025835_0002_000001 released container container_1376185025835_0002_01_000003 on node: host: hadoop-321-7:41950 #containers=0 available=8192 used=0 with event: FINISHED
2013-08-11 01:43:48,796 INFO org.apache.hadoop.yarn.server.resourcemanager.rmcontainer.RMContainerImpl: container_1376185025835_0002_01_000002 Container Transitioned from RUNNING to COMPLETED
2013-08-11 01:43:48,797 INFO org.apache.hadoop.yarn.server.resourcemanager.scheduler.common.fica.FiCaSchedulerApp: Completed container: container_1376185025835_0002_01_000002 in state: COMPLETED event:FINISHED
2013-08-11 01:43:48,797 INFO org.apache.hadoop.yarn.server.resourcemanager.RMAuditLogger: USER=ubuntu	OPERATION=AM Released Container	TARGET=SchedulerApp	RESULT=SUCCESS	APPID=application_1376185025835_0002	CONTAINERID=container_1376185025835_0002_01_000002
2013-08-11 01:43:48,797 INFO org.apache.hadoop.yarn.server.resourcemanager.scheduler.common.fica.FiCaSchedulerNode: Released container container_1376185025835_0002_01_000002 of capacity <memory:1024, vCores:1> on host hadoop-321-3:44876, which currently has 1 containers, <memory:2048, vCores:1> used and <memory:6144, vCores:15> available, release resources=true
2013-08-11 01:43:48,797 INFO org.apache.hadoop.yarn.server.resourcemanager.scheduler.capacity.LeafQueue: default used=<memory:2048, vCores:1> numContainers=1 user=ubuntu user-resources=<memory:2048, vCores:1>
2013-08-11 01:43:48,800 INFO org.apache.hadoop.yarn.server.resourcemanager.scheduler.capacity.LeafQueue: completedContainer container=Container: [ContainerId: container_1376185025835_0002_01_000002, NodeId: hadoop-321-3:44876, NodeHttpAddress: hadoop-321-3:8042, Resource: <memory:1024, vCores:1>, Priority: 20, State: NEW, Token: null, Status: container_id {, app_attempt_id {, application_id {, id: 2, cluster_timestamp: 1376185025835, }, attemptId: 1, }, id: 2, }, state: C_COMPLETE, diagnostics: "Container killed by the ApplicationMaster.\n\n", exit_status: 143, ] resource=<memory:1024, vCores:1> queue=default: capacity=1.0, absoluteCapacity=1.0, usedResources=<memory:2048, vCores:1>usedCapacity=0.041666668, absoluteUsedCapacity=0.041666668, numApps=1, numContainers=1 usedCapacity=0.041666668 absoluteUsedCapacity=0.041666668 used=<memory:2048, vCores:1> cluster=<memory:49152, vCores:96>
2013-08-11 01:43:48,800 INFO org.apache.hadoop.yarn.server.resourcemanager.scheduler.capacity.ParentQueue: completedContainer queue=root usedCapacity=0.041666668 absoluteUsedCapacity=0.041666668 used=<memory:2048, vCores:1> cluster=<memory:49152, vCores:96>
2013-08-11 01:43:48,800 INFO org.apache.hadoop.yarn.server.resourcemanager.scheduler.capacity.CapacityScheduler: Application appattempt_1376185025835_0002_000001 released container container_1376185025835_0002_01_000002 on node: host: hadoop-321-3:44876 #containers=1 available=6144 used=2048 with event: FINISHED
2013-08-11 01:43:54,741 INFO org.apache.hadoop.yarn.server.resourcemanager.rmapp.attempt.RMAppAttemptImpl: appattempt_1376185025835_0002_000001 State change from RUNNING to FINISHING
2013-08-11 01:43:54,743 INFO org.apache.hadoop.yarn.server.resourcemanager.rmapp.RMAppImpl: application_1376185025835_0002 State change from RUNNING to FINISHING
2013-08-11 01:43:55,675 INFO org.apache.hadoop.yarn.server.resourcemanager.ClientRMService: Allocated new applicationId: 3
2013-08-11 01:43:55,843 INFO org.apache.hadoop.yarn.server.resourcemanager.rmcontainer.RMContainerImpl: container_1376185025835_0002_01_000001 Container Transitioned from RUNNING to COMPLETED
2013-08-11 01:43:55,843 INFO org.apache.hadoop.yarn.server.resourcemanager.scheduler.common.fica.FiCaSchedulerApp: Completed container: container_1376185025835_0002_01_000001 in state: COMPLETED event:FINISHED
2013-08-11 01:43:55,843 INFO org.apache.hadoop.yarn.server.resourcemanager.rmapp.attempt.RMAppAttemptImpl: appattempt_1376185025835_0002_000001 State change from FINISHING to FINISHED
2013-08-11 01:43:55,844 INFO org.apache.hadoop.yarn.server.resourcemanager.RMAuditLogger: USER=ubuntu	OPERATION=AM Released Container	TARGET=SchedulerApp	RESULT=SUCCESS	APPID=application_1376185025835_0002	CONTAINERID=container_1376185025835_0002_01_000001
2013-08-11 01:43:55,844 INFO org.apache.hadoop.yarn.server.resourcemanager.scheduler.common.fica.FiCaSchedulerNode: Released container container_1376185025835_0002_01_000001 of capacity <memory:2048, vCores:1> on host hadoop-321-3:44876, which currently has 0 containers, <memory:0, vCores:0> used and <memory:8192, vCores:16> available, release resources=true
2013-08-11 01:43:55,844 INFO org.apache.hadoop.yarn.server.resourcemanager.scheduler.capacity.LeafQueue: default used=<memory:0, vCores:0> numContainers=0 user=ubuntu user-resources=<memory:0, vCores:0>
2013-08-11 01:43:55,846 INFO org.apache.hadoop.yarn.server.resourcemanager.scheduler.capacity.LeafQueue: completedContainer container=Container: [ContainerId: container_1376185025835_0002_01_000001, NodeId: hadoop-321-3:44876, NodeHttpAddress: hadoop-321-3:8042, Resource: <memory:2048, vCores:1>, Priority: 0, State: NEW, Token: null, Status: container_id {, app_attempt_id {, application_id {, id: 2, cluster_timestamp: 1376185025835, }, attemptId: 1, }, id: 1, }, state: C_COMPLETE, diagnostics: "", exit_status: 0, ] resource=<memory:2048, vCores:1> queue=default: capacity=1.0, absoluteCapacity=1.0, usedResources=<memory:0, vCores:0>usedCapacity=0.0, absoluteUsedCapacity=0.0, numApps=1, numContainers=0 usedCapacity=0.0 absoluteUsedCapacity=0.0 used=<memory:0, vCores:0> cluster=<memory:49152, vCores:96>
2013-08-11 01:43:55,846 INFO org.apache.hadoop.yarn.server.resourcemanager.scheduler.capacity.ParentQueue: completedContainer queue=root usedCapacity=0.0 absoluteUsedCapacity=0.0 used=<memory:0, vCores:0> cluster=<memory:49152, vCores:96>
2013-08-11 01:43:55,846 INFO org.apache.hadoop.yarn.server.resourcemanager.scheduler.capacity.CapacityScheduler: Application appattempt_1376185025835_0002_000001 released container container_1376185025835_0002_01_000001 on node: host: hadoop-321-3:44876 #containers=0 available=8192 used=0 with event: FINISHED
2013-08-11 01:43:55,844 INFO org.apache.hadoop.yarn.server.resourcemanager.rmapp.RMAppImpl: application_1376185025835_0002 State change from FINISHING to FINISHED
2013-08-11 01:43:55,848 INFO org.apache.hadoop.yarn.server.resourcemanager.scheduler.capacity.CapacityScheduler: Application appattempt_1376185025835_0002_000001 is done. finalState=FINISHED
2013-08-11 01:43:55,848 INFO org.apache.hadoop.yarn.server.resourcemanager.RMAuditLogger: USER=ubuntu	OPERATION=Application Finished - Succeeded	TARGET=RMAppManager	RESULT=SUCCESS	APPID=application_1376185025835_0002
2013-08-11 01:43:55,848 INFO org.apache.hadoop.yarn.server.resourcemanager.scheduler.AppSchedulingInfo: Application application_1376185025835_0002 requests cleared
2013-08-11 01:43:55,848 INFO org.apache.hadoop.yarn.server.resourcemanager.scheduler.capacity.LeafQueue: Application removed - appId: application_1376185025835_0002 user: ubuntu queue: default #user-pending-applications: 0 #user-active-applications: 0 #queue-pending-applications: 0 #queue-active-applications: 0
2013-08-11 01:43:55,848 INFO org.apache.hadoop.yarn.server.resourcemanager.scheduler.capacity.ParentQueue: Application removed - appId: application_1376185025835_0002 user: ubuntu leaf-queue of parent: root #applications: 0
2013-08-11 01:43:55,849 INFO org.apache.hadoop.yarn.server.resourcemanager.recovery.RMStateStore: Removing info for app: application_1376185025835_0002
2013-08-11 01:43:55,849 INFO org.apache.hadoop.yarn.server.resourcemanager.RMAppManager$ApplicationSummary: appId=application_1376185025835_0002,name=TeraGen,user=ubuntu,queue=default,state=FINISHED,trackingUrl=hadoop-321-1.novalocal:8088/proxy/application_1376185025835_0002/jobhistory/job/job_1376185025835_0002,appMasterHost=hadoop-321-3,startTime=1376185240808,finishTime=1376185434743
2013-08-11 01:43:55,850 INFO org.apache.hadoop.yarn.server.resourcemanager.amlauncher.AMLauncher: Cleaning master appattempt_1376185025835_0002_000001
2013-08-11 01:43:57,617 INFO org.apache.hadoop.yarn.server.resourcemanager.ClientRMService: Storing Application with id application_1376185025835_0003
2013-08-11 01:43:57,618 INFO org.apache.hadoop.yarn.server.resourcemanager.recovery.RMStateStore: Storing info for app: application_1376185025835_0003
2013-08-11 01:43:57,618 INFO org.apache.hadoop.yarn.server.resourcemanager.ClientRMService: Application with id 3 submitted by user ubuntu
2013-08-11 01:43:57,618 INFO org.apache.hadoop.yarn.server.resourcemanager.RMAuditLogger: USER=ubuntu	IP=192.168.100.15	OPERATION=Submit Application Request	TARGET=ClientRMService	RESULT=SUCCESS	APPID=application_1376185025835_0003
2013-08-11 01:43:57,620 INFO org.apache.hadoop.yarn.server.resourcemanager.rmapp.RMAppImpl: application_1376185025835_0003 State change from NEW to SUBMITTED
2013-08-11 01:43:57,620 INFO org.apache.hadoop.yarn.server.resourcemanager.ApplicationMasterService: Registering appattempt_1376185025835_0003_000001
2013-08-11 01:43:57,621 INFO org.apache.hadoop.yarn.server.resourcemanager.rmapp.attempt.RMAppAttemptImpl: appattempt_1376185025835_0003_000001 State change from NEW to SUBMITTED
2013-08-11 01:43:57,621 INFO org.apache.hadoop.yarn.server.resourcemanager.scheduler.capacity.LeafQueue: Application application_1376185025835_0003 from user: ubuntu activated in queue: default
2013-08-11 01:43:57,622 INFO org.apache.hadoop.yarn.server.resourcemanager.scheduler.capacity.LeafQueue: Application added - appId: application_1376185025835_0003 user: org.apache.hadoop.yarn.server.resourcemanager.scheduler.capacity.LeafQueue$User@4688bbdd, leaf-queue: default #user-pending-applications: 0 #user-active-applications: 1 #queue-pending-applications: 0 #queue-active-applications: 1
2013-08-11 01:43:57,622 INFO org.apache.hadoop.yarn.server.resourcemanager.scheduler.capacity.ParentQueue: Application added - appId: application_1376185025835_0003 user: ubuntu leaf-queue of parent: root #applications: 1
2013-08-11 01:43:57,622 INFO org.apache.hadoop.yarn.server.resourcemanager.scheduler.capacity.CapacityScheduler: Application Submission: appattempt_1376185025835_0003_000001, user: ubuntu queue: default: capacity=1.0, absoluteCapacity=1.0, usedResources=<memory:0, vCores:0>usedCapacity=0.0, absoluteUsedCapacity=0.0, numApps=1, numContainers=0, currently active: 1
2013-08-11 01:43:57,624 INFO org.apache.hadoop.yarn.server.resourcemanager.rmapp.attempt.RMAppAttemptImpl: appattempt_1376185025835_0003_000001 State change from SUBMITTED to SCHEDULED
2013-08-11 01:43:57,624 INFO org.apache.hadoop.yarn.server.resourcemanager.rmapp.RMAppImpl: application_1376185025835_0003 State change from SUBMITTED to ACCEPTED
2013-08-11 01:43:57,775 INFO org.apache.hadoop.yarn.server.resourcemanager.rmcontainer.RMContainerImpl: container_1376185025835_0003_01_000001 Container Transitioned from NEW to ALLOCATED
2013-08-11 01:43:57,775 INFO org.apache.hadoop.yarn.server.resourcemanager.RMAuditLogger: USER=ubuntu	OPERATION=AM Allocated Container	TARGET=SchedulerApp	RESULT=SUCCESS	APPID=application_1376185025835_0003	CONTAINERID=container_1376185025835_0003_01_000001
2013-08-11 01:43:57,775 INFO org.apache.hadoop.yarn.server.resourcemanager.scheduler.common.fica.FiCaSchedulerNode: Assigned container container_1376185025835_0003_01_000001 of capacity <memory:2048, vCores:1> on host hadoop-321-2:46202, which currently has 1 containers, <memory:2048, vCores:1> used and <memory:6144, vCores:15> available
2013-08-11 01:43:57,777 INFO org.apache.hadoop.yarn.server.resourcemanager.scheduler.capacity.LeafQueue: assignedContainer application=application_1376185025835_0003 container=Container: [ContainerId: container_1376185025835_0003_01_000001, NodeId: hadoop-321-2:46202, NodeHttpAddress: hadoop-321-2:8042, Resource: <memory:2048, vCores:1>, Priority: 0, State: NEW, Token: null, Status: container_id {, app_attempt_id {, application_id {, id: 3, cluster_timestamp: 1376185025835, }, attemptId: 1, }, id: 1, }, state: C_NEW, ] containerId=container_1376185025835_0003_01_000001 queue=default: capacity=1.0, absoluteCapacity=1.0, usedResources=<memory:0, vCores:0>usedCapacity=0.0, absoluteUsedCapacity=0.0, numApps=1, numContainers=0 usedCapacity=0.0 absoluteUsedCapacity=0.0 used=<memory:0, vCores:0> cluster=<memory:49152, vCores:96>
2013-08-11 01:43:57,777 INFO org.apache.hadoop.yarn.server.resourcemanager.scheduler.capacity.ParentQueue: Re-sorting queues since queue: root.default stats: default: capacity=1.0, absoluteCapacity=1.0, usedResources=<memory:2048, vCores:1>usedCapacity=0.041666668, absoluteUsedCapacity=0.041666668, numApps=1, numContainers=1
2013-08-11 01:43:57,778 INFO org.apache.hadoop.yarn.server.resourcemanager.scheduler.capacity.ParentQueue: assignedContainer queue=root usedCapacity=0.041666668 absoluteUsedCapacity=0.041666668 used=<memory:2048, vCores:1> cluster=<memory:49152, vCores:96>
2013-08-11 01:43:57,779 INFO org.apache.hadoop.yarn.server.resourcemanager.rmcontainer.RMContainerImpl: container_1376185025835_0003_01_000001 Container Transitioned from ALLOCATED to ACQUIRED
2013-08-11 01:43:57,781 INFO org.apache.hadoop.yarn.server.resourcemanager.rmapp.attempt.RMAppAttemptImpl: Storing attempt: AppId: application_1376185025835_0003 AttemptId: appattempt_1376185025835_0003_000001 MasterContainer: Container: [ContainerId: container_1376185025835_0003_01_000001, NodeId: hadoop-321-2:46202, NodeHttpAddress: hadoop-321-2:8042, Resource: <memory:2048, vCores:1>, Priority: 0, State: NEW, Token: null, Status: container_id {, app_attempt_id {, application_id {, id: 3, cluster_timestamp: 1376185025835, }, attemptId: 1, }, id: 1, }, state: C_NEW, ]
2013-08-11 01:43:57,781 INFO org.apache.hadoop.yarn.server.resourcemanager.recovery.RMStateStore: Storing info for attempt: appattempt_1376185025835_0003_000001
2013-08-11 01:43:57,782 INFO org.apache.hadoop.yarn.server.resourcemanager.rmapp.attempt.RMAppAttemptImpl: appattempt_1376185025835_0003_000001 State change from SCHEDULED to ALLOCATED_SAVING
2013-08-11 01:43:57,782 INFO org.apache.hadoop.yarn.server.resourcemanager.rmapp.attempt.RMAppAttemptImpl: appattempt_1376185025835_0003_000001 State change from ALLOCATED_SAVING to ALLOCATED
2013-08-11 01:43:57,783 INFO org.apache.hadoop.yarn.server.resourcemanager.amlauncher.AMLauncher: Launching masterappattempt_1376185025835_0003_000001
2013-08-11 01:43:57,786 INFO org.apache.hadoop.yarn.server.resourcemanager.amlauncher.AMLauncher: Setting up container Container: [ContainerId: container_1376185025835_0003_01_000001, NodeId: hadoop-321-2:46202, NodeHttpAddress: hadoop-321-2:8042, Resource: <memory:2048, vCores:1>, Priority: 0, State: NEW, Token: null, Status: container_id {, app_attempt_id {, application_id {, id: 3, cluster_timestamp: 1376185025835, }, attemptId: 1, }, id: 1, }, state: C_NEW, ] for AM appattempt_1376185025835_0003_000001
2013-08-11 01:43:57,786 INFO org.apache.hadoop.yarn.server.resourcemanager.amlauncher.AMLauncher: Command to launch container container_1376185025835_0003_01_000001 : $JAVA_HOME/bin/java -Dlog4j.configuration=container-log4j.properties -Dyarn.app.mapreduce.container.log.dir=<LOG_DIR> -Dyarn.app.mapreduce.container.log.filesize=0 -Dhadoop.root.logger=INFO,CLA  -Xmx1024m org.apache.hadoop.mapreduce.v2.app.MRAppMaster 1><LOG_DIR>/stdout 2><LOG_DIR>/stderr 
2013-08-11 01:43:58,627 INFO org.apache.hadoop.yarn.server.resourcemanager.amlauncher.AMLauncher: Done launching container Container: [ContainerId: container_1376185025835_0003_01_000001, NodeId: hadoop-321-2:46202, NodeHttpAddress: hadoop-321-2:8042, Resource: <memory:2048, vCores:1>, Priority: 0, State: NEW, Token: null, Status: container_id {, app_attempt_id {, application_id {, id: 3, cluster_timestamp: 1376185025835, }, attemptId: 1, }, id: 1, }, state: C_NEW, ] for AM appattempt_1376185025835_0003_000001
2013-08-11 01:43:58,628 INFO org.apache.hadoop.yarn.server.resourcemanager.rmapp.attempt.RMAppAttemptImpl: appattempt_1376185025835_0003_000001 State change from ALLOCATED to LAUNCHED
2013-08-11 01:43:58,858 INFO org.apache.hadoop.yarn.server.resourcemanager.rmcontainer.RMContainerImpl: container_1376185025835_0003_01_000001 Container Transitioned from ACQUIRED to RUNNING
2013-08-11 01:44:07,325 INFO org.apache.hadoop.yarn.server.resourcemanager.ApplicationMasterService: AM registration appattempt_1376185025835_0003_000001
2013-08-11 01:44:07,326 INFO org.apache.hadoop.yarn.server.resourcemanager.RMAuditLogger: USER=ubuntu	IP=192.168.100.17	OPERATION=Register App Master	TARGET=ApplicationMasterService	RESULT=SUCCESS	APPID=application_1376185025835_0003	APPATTEMPTID=appattempt_1376185025835_0003_000001
2013-08-11 01:44:07,327 INFO org.apache.hadoop.yarn.server.resourcemanager.rmapp.attempt.RMAppAttemptImpl: appattempt_1376185025835_0003_000001 State change from LAUNCHED to RUNNING
2013-08-11 01:44:07,327 INFO org.apache.hadoop.yarn.server.resourcemanager.rmapp.RMAppImpl: application_1376185025835_0003 State change from ACCEPTED to RUNNING
2013-08-11 01:44:08,414 INFO org.apache.hadoop.yarn.server.resourcemanager.rmcontainer.RMContainerImpl: container_1376185025835_0003_01_000002 Container Transitioned from NEW to ALLOCATED
2013-08-11 01:44:08,414 INFO org.apache.hadoop.yarn.server.resourcemanager.RMAuditLogger: USER=ubuntu	OPERATION=AM Allocated Container	TARGET=SchedulerApp	RESULT=SUCCESS	APPID=application_1376185025835_0003	CONTAINERID=container_1376185025835_0003_01_000002
2013-08-11 01:44:08,414 INFO org.apache.hadoop.yarn.server.resourcemanager.scheduler.common.fica.FiCaSchedulerNode: Assigned container container_1376185025835_0003_01_000002 of capacity <memory:1024, vCores:1> on host hadoop-321-5:60845, which currently has 1 containers, <memory:1024, vCores:1> used and <memory:7168, vCores:15> available
2013-08-11 01:44:08,416 INFO org.apache.hadoop.yarn.server.resourcemanager.scheduler.capacity.LeafQueue: assignedContainer application=application_1376185025835_0003 container=Container: [ContainerId: container_1376185025835_0003_01_000002, NodeId: hadoop-321-5:60845, NodeHttpAddress: hadoop-321-5:8042, Resource: <memory:1024, vCores:1>, Priority: 20, State: NEW, Token: null, Status: container_id {, app_attempt_id {, application_id {, id: 3, cluster_timestamp: 1376185025835, }, attemptId: 1, }, id: 2, }, state: C_NEW, ] containerId=container_1376185025835_0003_01_000002 queue=default: capacity=1.0, absoluteCapacity=1.0, usedResources=<memory:2048, vCores:1>usedCapacity=0.041666668, absoluteUsedCapacity=0.041666668, numApps=1, numContainers=1 usedCapacity=0.041666668 absoluteUsedCapacity=0.041666668 used=<memory:2048, vCores:1> cluster=<memory:49152, vCores:96>
2013-08-11 01:44:08,416 INFO org.apache.hadoop.yarn.server.resourcemanager.scheduler.capacity.ParentQueue: Re-sorting queues since queue: root.default stats: default: capacity=1.0, absoluteCapacity=1.0, usedResources=<memory:3072, vCores:2>usedCapacity=0.0625, absoluteUsedCapacity=0.0625, numApps=1, numContainers=2
2013-08-11 01:44:08,416 INFO org.apache.hadoop.yarn.server.resourcemanager.scheduler.capacity.ParentQueue: assignedContainer queue=root usedCapacity=0.0625 absoluteUsedCapacity=0.0625 used=<memory:3072, vCores:2> cluster=<memory:49152, vCores:96>
2013-08-11 01:44:08,489 INFO org.apache.hadoop.yarn.server.resourcemanager.rmcontainer.RMContainerImpl: container_1376185025835_0003_01_000003 Container Transitioned from NEW to ALLOCATED
2013-08-11 01:44:08,489 INFO org.apache.hadoop.yarn.server.resourcemanager.RMAuditLogger: USER=ubuntu	OPERATION=AM Allocated Container	TARGET=SchedulerApp	RESULT=SUCCESS	APPID=application_1376185025835_0003	CONTAINERID=container_1376185025835_0003_01_000003
2013-08-11 01:44:08,490 INFO org.apache.hadoop.yarn.server.resourcemanager.scheduler.common.fica.FiCaSchedulerNode: Assigned container container_1376185025835_0003_01_000003 of capacity <memory:1024, vCores:1> on host hadoop-321-4:43757, which currently has 1 containers, <memory:1024, vCores:1> used and <memory:7168, vCores:15> available
2013-08-11 01:44:08,491 INFO org.apache.hadoop.yarn.server.resourcemanager.scheduler.capacity.LeafQueue: assignedContainer application=application_1376185025835_0003 container=Container: [ContainerId: container_1376185025835_0003_01_000003, NodeId: hadoop-321-4:43757, NodeHttpAddress: hadoop-321-4:8042, Resource: <memory:1024, vCores:1>, Priority: 20, State: NEW, Token: null, Status: container_id {, app_attempt_id {, application_id {, id: 3, cluster_timestamp: 1376185025835, }, attemptId: 1, }, id: 3, }, state: C_NEW, ] containerId=container_1376185025835_0003_01_000003 queue=default: capacity=1.0, absoluteCapacity=1.0, usedResources=<memory:3072, vCores:2>usedCapacity=0.0625, absoluteUsedCapacity=0.0625, numApps=1, numContainers=2 usedCapacity=0.0625 absoluteUsedCapacity=0.0625 used=<memory:3072, vCores:2> cluster=<memory:49152, vCores:96>
2013-08-11 01:44:08,491 INFO org.apache.hadoop.yarn.server.resourcemanager.scheduler.capacity.ParentQueue: Re-sorting queues since queue: root.default stats: default: capacity=1.0, absoluteCapacity=1.0, usedResources=<memory:4096, vCores:3>usedCapacity=0.083333336, absoluteUsedCapacity=0.083333336, numApps=1, numContainers=3
2013-08-11 01:44:08,492 INFO org.apache.hadoop.yarn.server.resourcemanager.scheduler.capacity.ParentQueue: assignedContainer queue=root usedCapacity=0.083333336 absoluteUsedCapacity=0.083333336 used=<memory:4096, vCores:3> cluster=<memory:49152, vCores:96>
2013-08-11 01:44:09,383 INFO org.apache.hadoop.yarn.server.resourcemanager.rmcontainer.RMContainerImpl: container_1376185025835_0003_01_000002 Container Transitioned from ALLOCATED to ACQUIRED
2013-08-11 01:44:09,385 INFO org.apache.hadoop.yarn.server.resourcemanager.rmcontainer.RMContainerImpl: container_1376185025835_0003_01_000003 Container Transitioned from ALLOCATED to ACQUIRED
2013-08-11 01:44:10,414 INFO org.apache.hadoop.yarn.server.resourcemanager.scheduler.AppSchedulingInfo: checking for deactivate... 
2013-08-11 01:44:10,450 INFO org.apache.hadoop.yarn.server.resourcemanager.rmcontainer.RMContainerImpl: container_1376185025835_0003_01_000002 Container Transitioned from ACQUIRED to RUNNING
2013-08-11 01:44:10,498 INFO org.apache.hadoop.yarn.server.resourcemanager.rmcontainer.RMContainerImpl: container_1376185025835_0003_01_000003 Container Transitioned from ACQUIRED to RUNNING
2013-08-11 01:46:53,805 INFO org.apache.hadoop.yarn.server.resourcemanager.rmcontainer.RMContainerImpl: container_1376185025835_0003_01_000003 Container Transitioned from RUNNING to COMPLETED
2013-08-11 01:46:53,806 INFO org.apache.hadoop.yarn.server.resourcemanager.scheduler.common.fica.FiCaSchedulerApp: Completed container: container_1376185025835_0003_01_000003 in state: COMPLETED event:FINISHED
2013-08-11 01:46:53,806 INFO org.apache.hadoop.yarn.server.resourcemanager.RMAuditLogger: USER=ubuntu	OPERATION=AM Released Container	TARGET=SchedulerApp	RESULT=SUCCESS	APPID=application_1376185025835_0003	CONTAINERID=container_1376185025835_0003_01_000003
2013-08-11 01:46:53,807 INFO org.apache.hadoop.yarn.server.resourcemanager.scheduler.common.fica.FiCaSchedulerNode: Released container container_1376185025835_0003_01_000003 of capacity <memory:1024, vCores:1> on host hadoop-321-4:43757, which currently has 0 containers, <memory:0, vCores:0> used and <memory:8192, vCores:16> available, release resources=true
2013-08-11 01:46:53,807 INFO org.apache.hadoop.yarn.server.resourcemanager.scheduler.capacity.LeafQueue: default used=<memory:3072, vCores:2> numContainers=2 user=ubuntu user-resources=<memory:3072, vCores:2>
2013-08-11 01:46:53,809 INFO org.apache.hadoop.yarn.server.resourcemanager.scheduler.capacity.LeafQueue: completedContainer container=Container: [ContainerId: container_1376185025835_0003_01_000003, NodeId: hadoop-321-4:43757, NodeHttpAddress: hadoop-321-4:8042, Resource: <memory:1024, vCores:1>, Priority: 20, State: NEW, Token: null, Status: container_id {, app_attempt_id {, application_id {, id: 3, cluster_timestamp: 1376185025835, }, attemptId: 1, }, id: 3, }, state: C_COMPLETE, diagnostics: "Container killed by the ApplicationMaster.\n\n", exit_status: 143, ] resource=<memory:1024, vCores:1> queue=default: capacity=1.0, absoluteCapacity=1.0, usedResources=<memory:3072, vCores:2>usedCapacity=0.0625, absoluteUsedCapacity=0.0625, numApps=1, numContainers=2 usedCapacity=0.0625 absoluteUsedCapacity=0.0625 used=<memory:3072, vCores:2> cluster=<memory:49152, vCores:96>
2013-08-11 01:46:53,809 INFO org.apache.hadoop.yarn.server.resourcemanager.scheduler.capacity.ParentQueue: completedContainer queue=root usedCapacity=0.0625 absoluteUsedCapacity=0.0625 used=<memory:3072, vCores:2> cluster=<memory:49152, vCores:96>
2013-08-11 01:46:53,810 INFO org.apache.hadoop.yarn.server.resourcemanager.scheduler.capacity.CapacityScheduler: Application appattempt_1376185025835_0003_000001 released container container_1376185025835_0003_01_000003 on node: host: hadoop-321-4:43757 #containers=0 available=8192 used=0 with event: FINISHED
2013-08-11 01:46:57,440 INFO org.apache.hadoop.yarn.server.resourcemanager.rmcontainer.RMContainerImpl: container_1376185025835_0003_01_000002 Container Transitioned from RUNNING to COMPLETED
2013-08-11 01:46:57,440 INFO org.apache.hadoop.yarn.server.resourcemanager.scheduler.common.fica.FiCaSchedulerApp: Completed container: container_1376185025835_0003_01_000002 in state: COMPLETED event:FINISHED
2013-08-11 01:46:57,440 INFO org.apache.hadoop.yarn.server.resourcemanager.RMAuditLogger: USER=ubuntu	OPERATION=AM Released Container	TARGET=SchedulerApp	RESULT=SUCCESS	APPID=application_1376185025835_0003	CONTAINERID=container_1376185025835_0003_01_000002
2013-08-11 01:46:57,441 INFO org.apache.hadoop.yarn.server.resourcemanager.scheduler.common.fica.FiCaSchedulerNode: Released container container_1376185025835_0003_01_000002 of capacity <memory:1024, vCores:1> on host hadoop-321-5:60845, which currently has 0 containers, <memory:0, vCores:0> used and <memory:8192, vCores:16> available, release resources=true
2013-08-11 01:46:57,441 INFO org.apache.hadoop.yarn.server.resourcemanager.scheduler.capacity.LeafQueue: default used=<memory:2048, vCores:1> numContainers=1 user=ubuntu user-resources=<memory:2048, vCores:1>
2013-08-11 01:46:57,443 INFO org.apache.hadoop.yarn.server.resourcemanager.scheduler.capacity.LeafQueue: completedContainer container=Container: [ContainerId: container_1376185025835_0003_01_000002, NodeId: hadoop-321-5:60845, NodeHttpAddress: hadoop-321-5:8042, Resource: <memory:1024, vCores:1>, Priority: 20, State: NEW, Token: null, Status: container_id {, app_attempt_id {, application_id {, id: 3, cluster_timestamp: 1376185025835, }, attemptId: 1, }, id: 2, }, state: C_COMPLETE, diagnostics: "Container killed by the ApplicationMaster.\n\n", exit_status: 143, ] resource=<memory:1024, vCores:1> queue=default: capacity=1.0, absoluteCapacity=1.0, usedResources=<memory:2048, vCores:1>usedCapacity=0.041666668, absoluteUsedCapacity=0.041666668, numApps=1, numContainers=1 usedCapacity=0.041666668 absoluteUsedCapacity=0.041666668 used=<memory:2048, vCores:1> cluster=<memory:49152, vCores:96>
2013-08-11 01:46:57,443 INFO org.apache.hadoop.yarn.server.resourcemanager.scheduler.capacity.ParentQueue: completedContainer queue=root usedCapacity=0.041666668 absoluteUsedCapacity=0.041666668 used=<memory:2048, vCores:1> cluster=<memory:49152, vCores:96>
2013-08-11 01:46:57,443 INFO org.apache.hadoop.yarn.server.resourcemanager.scheduler.capacity.CapacityScheduler: Application appattempt_1376185025835_0003_000001 released container container_1376185025835_0003_01_000002 on node: host: hadoop-321-5:60845 #containers=0 available=8192 used=0 with event: FINISHED
2013-08-11 01:47:01,863 INFO org.apache.hadoop.yarn.server.resourcemanager.rmapp.attempt.RMAppAttemptImpl: appattempt_1376185025835_0003_000001 State change from RUNNING to FINISHING
2013-08-11 01:47:01,864 INFO org.apache.hadoop.yarn.server.resourcemanager.rmapp.RMAppImpl: application_1376185025835_0003 State change from RUNNING to FINISHING
2013-08-11 01:47:02,049 INFO org.apache.hadoop.yarn.server.resourcemanager.rmcontainer.RMContainerImpl: container_1376185025835_0003_01_000001 Container Transitioned from RUNNING to COMPLETED
2013-08-11 01:47:02,049 INFO org.apache.hadoop.yarn.server.resourcemanager.scheduler.common.fica.FiCaSchedulerApp: Completed container: container_1376185025835_0003_01_000001 in state: COMPLETED event:FINISHED
2013-08-11 01:47:02,049 INFO org.apache.hadoop.yarn.server.resourcemanager.RMAuditLogger: USER=ubuntu	OPERATION=AM Released Container	TARGET=SchedulerApp	RESULT=SUCCESS	APPID=application_1376185025835_0003	CONTAINERID=container_1376185025835_0003_01_000001
2013-08-11 01:47:02,049 INFO org.apache.hadoop.yarn.server.resourcemanager.rmapp.attempt.RMAppAttemptImpl: appattempt_1376185025835_0003_000001 State change from FINISHING to FINISHED
2013-08-11 01:47:02,049 INFO org.apache.hadoop.yarn.server.resourcemanager.scheduler.common.fica.FiCaSchedulerNode: Released container container_1376185025835_0003_01_000001 of capacity <memory:2048, vCores:1> on host hadoop-321-2:46202, which currently has 0 containers, <memory:0, vCores:0> used and <memory:8192, vCores:16> available, release resources=true
2013-08-11 01:47:02,049 INFO org.apache.hadoop.yarn.server.resourcemanager.scheduler.capacity.LeafQueue: default used=<memory:0, vCores:0> numContainers=0 user=ubuntu user-resources=<memory:0, vCores:0>
2013-08-11 01:47:02,049 INFO org.apache.hadoop.yarn.server.resourcemanager.rmapp.RMAppImpl: application_1376185025835_0003 State change from FINISHING to FINISHED
2013-08-11 01:47:02,050 INFO org.apache.hadoop.yarn.server.resourcemanager.RMAuditLogger: USER=ubuntu	OPERATION=Application Finished - Succeeded	TARGET=RMAppManager	RESULT=SUCCESS	APPID=application_1376185025835_0003
2013-08-11 01:47:02,050 INFO org.apache.hadoop.yarn.server.resourcemanager.scheduler.capacity.LeafQueue: completedContainer container=Container: [ContainerId: container_1376185025835_0003_01_000001, NodeId: hadoop-321-2:46202, NodeHttpAddress: hadoop-321-2:8042, Resource: <memory:2048, vCores:1>, Priority: 0, State: NEW, Token: null, Status: container_id {, app_attempt_id {, application_id {, id: 3, cluster_timestamp: 1376185025835, }, attemptId: 1, }, id: 1, }, state: C_COMPLETE, diagnostics: "", exit_status: 0, ] resource=<memory:2048, vCores:1> queue=default: capacity=1.0, absoluteCapacity=1.0, usedResources=<memory:0, vCores:0>usedCapacity=0.0, absoluteUsedCapacity=0.0, numApps=1, numContainers=0 usedCapacity=0.0 absoluteUsedCapacity=0.0 used=<memory:0, vCores:0> cluster=<memory:49152, vCores:96>
2013-08-11 01:47:02,050 INFO org.apache.hadoop.yarn.server.resourcemanager.scheduler.capacity.ParentQueue: completedContainer queue=root usedCapacity=0.0 absoluteUsedCapacity=0.0 used=<memory:0, vCores:0> cluster=<memory:49152, vCores:96>
2013-08-11 01:47:02,050 INFO org.apache.hadoop.yarn.server.resourcemanager.scheduler.capacity.CapacityScheduler: Application appattempt_1376185025835_0003_000001 released container container_1376185025835_0003_01_000001 on node: host: hadoop-321-2:46202 #containers=0 available=8192 used=0 with event: FINISHED
2013-08-11 01:47:02,050 INFO org.apache.hadoop.yarn.server.resourcemanager.recovery.RMStateStore: Removing info for app: application_1376185025835_0003
2013-08-11 01:47:02,064 INFO org.apache.hadoop.yarn.server.resourcemanager.amlauncher.AMLauncher: Cleaning master appattempt_1376185025835_0003_000001
2013-08-11 01:47:02,051 INFO org.apache.hadoop.yarn.server.resourcemanager.RMAppManager$ApplicationSummary: appId=application_1376185025835_0003,name=TeraGen,user=ubuntu,queue=default,state=FINISHED,trackingUrl=hadoop-321-1.novalocal:8088/proxy/application_1376185025835_0003/jobhistory/job/job_1376185025835_0003,appMasterHost=hadoop-321-2,startTime=1376185437617,finishTime=1376185621864
2013-08-11 01:47:02,050 INFO org.apache.hadoop.yarn.server.resourcemanager.scheduler.capacity.CapacityScheduler: Application appattempt_1376185025835_0003_000001 is done. finalState=FINISHED
2013-08-11 01:47:02,064 INFO org.apache.hadoop.yarn.server.resourcemanager.scheduler.AppSchedulingInfo: Application application_1376185025835_0003 requests cleared
2013-08-11 01:47:02,064 INFO org.apache.hadoop.yarn.server.resourcemanager.scheduler.capacity.LeafQueue: Application removed - appId: application_1376185025835_0003 user: ubuntu queue: default #user-pending-applications: 0 #user-active-applications: 0 #queue-pending-applications: 0 #queue-active-applications: 0
2013-08-11 01:47:02,064 INFO org.apache.hadoop.yarn.server.resourcemanager.scheduler.capacity.ParentQueue: Application removed - appId: application_1376185025835_0003 user: ubuntu leaf-queue of parent: root #applications: 0
2013-08-11 01:47:03,771 INFO org.apache.hadoop.yarn.server.resourcemanager.ClientRMService: Allocated new applicationId: 4
2013-08-11 01:47:05,681 INFO org.apache.hadoop.yarn.server.resourcemanager.ClientRMService: Storing Application with id application_1376185025835_0004
2013-08-11 01:47:05,681 INFO org.apache.hadoop.yarn.server.resourcemanager.recovery.RMStateStore: Storing info for app: application_1376185025835_0004
2013-08-11 01:47:05,681 INFO org.apache.hadoop.yarn.server.resourcemanager.ClientRMService: Application with id 4 submitted by user ubuntu
2013-08-11 01:47:05,681 INFO org.apache.hadoop.yarn.server.resourcemanager.RMAuditLogger: USER=ubuntu	IP=192.168.100.15	OPERATION=Submit Application Request	TARGET=ClientRMService	RESULT=SUCCESS	APPID=application_1376185025835_0004
2013-08-11 01:47:05,682 INFO org.apache.hadoop.yarn.server.resourcemanager.rmapp.RMAppImpl: application_1376185025835_0004 State change from NEW to SUBMITTED
2013-08-11 01:47:05,683 INFO org.apache.hadoop.yarn.server.resourcemanager.ApplicationMasterService: Registering appattempt_1376185025835_0004_000001
2013-08-11 01:47:05,683 INFO org.apache.hadoop.yarn.server.resourcemanager.rmapp.attempt.RMAppAttemptImpl: appattempt_1376185025835_0004_000001 State change from NEW to SUBMITTED
2013-08-11 01:47:05,684 INFO org.apache.hadoop.yarn.server.resourcemanager.scheduler.capacity.LeafQueue: Application application_1376185025835_0004 from user: ubuntu activated in queue: default
2013-08-11 01:47:05,684 INFO org.apache.hadoop.yarn.server.resourcemanager.scheduler.capacity.LeafQueue: Application added - appId: application_1376185025835_0004 user: org.apache.hadoop.yarn.server.resourcemanager.scheduler.capacity.LeafQueue$User@1ce9118a, leaf-queue: default #user-pending-applications: 0 #user-active-applications: 1 #queue-pending-applications: 0 #queue-active-applications: 1
2013-08-11 01:47:05,684 INFO org.apache.hadoop.yarn.server.resourcemanager.scheduler.capacity.ParentQueue: Application added - appId: application_1376185025835_0004 user: ubuntu leaf-queue of parent: root #applications: 1
2013-08-11 01:47:05,684 INFO org.apache.hadoop.yarn.server.resourcemanager.scheduler.capacity.CapacityScheduler: Application Submission: appattempt_1376185025835_0004_000001, user: ubuntu queue: default: capacity=1.0, absoluteCapacity=1.0, usedResources=<memory:0, vCores:0>usedCapacity=0.0, absoluteUsedCapacity=0.0, numApps=1, numContainers=0, currently active: 1
2013-08-11 01:47:05,685 INFO org.apache.hadoop.yarn.server.resourcemanager.rmapp.attempt.RMAppAttemptImpl: appattempt_1376185025835_0004_000001 State change from SUBMITTED to SCHEDULED
2013-08-11 01:47:05,685 INFO org.apache.hadoop.yarn.server.resourcemanager.rmapp.RMAppImpl: application_1376185025835_0004 State change from SUBMITTED to ACCEPTED
2013-08-11 01:47:05,697 INFO org.apache.hadoop.yarn.server.resourcemanager.rmcontainer.RMContainerImpl: container_1376185025835_0004_01_000001 Container Transitioned from NEW to ALLOCATED
2013-08-11 01:47:05,697 INFO org.apache.hadoop.yarn.server.resourcemanager.RMAuditLogger: USER=ubuntu	OPERATION=AM Allocated Container	TARGET=SchedulerApp	RESULT=SUCCESS	APPID=application_1376185025835_0004	CONTAINERID=container_1376185025835_0004_01_000001
2013-08-11 01:47:05,697 INFO org.apache.hadoop.yarn.server.resourcemanager.scheduler.common.fica.FiCaSchedulerNode: Assigned container container_1376185025835_0004_01_000001 of capacity <memory:2048, vCores:1> on host hadoop-321-3:44876, which currently has 1 containers, <memory:2048, vCores:1> used and <memory:6144, vCores:15> available
2013-08-11 01:47:05,698 INFO org.apache.hadoop.yarn.server.resourcemanager.scheduler.capacity.LeafQueue: assignedContainer application=application_1376185025835_0004 container=Container: [ContainerId: container_1376185025835_0004_01_000001, NodeId: hadoop-321-3:44876, NodeHttpAddress: hadoop-321-3:8042, Resource: <memory:2048, vCores:1>, Priority: 0, State: NEW, Token: null, Status: container_id {, app_attempt_id {, application_id {, id: 4, cluster_timestamp: 1376185025835, }, attemptId: 1, }, id: 1, }, state: C_NEW, ] containerId=container_1376185025835_0004_01_000001 queue=default: capacity=1.0, absoluteCapacity=1.0, usedResources=<memory:0, vCores:0>usedCapacity=0.0, absoluteUsedCapacity=0.0, numApps=1, numContainers=0 usedCapacity=0.0 absoluteUsedCapacity=0.0 used=<memory:0, vCores:0> cluster=<memory:49152, vCores:96>
2013-08-11 01:47:05,699 INFO org.apache.hadoop.yarn.server.resourcemanager.scheduler.capacity.ParentQueue: Re-sorting queues since queue: root.default stats: default: capacity=1.0, absoluteCapacity=1.0, usedResources=<memory:2048, vCores:1>usedCapacity=0.041666668, absoluteUsedCapacity=0.041666668, numApps=1, numContainers=1
2013-08-11 01:47:05,700 INFO org.apache.hadoop.yarn.server.resourcemanager.rmcontainer.RMContainerImpl: container_1376185025835_0004_01_000001 Container Transitioned from ALLOCATED to ACQUIRED
2013-08-11 01:47:05,702 INFO org.apache.hadoop.yarn.server.resourcemanager.rmapp.attempt.RMAppAttemptImpl: Storing attempt: AppId: application_1376185025835_0004 AttemptId: appattempt_1376185025835_0004_000001 MasterContainer: Container: [ContainerId: container_1376185025835_0004_01_000001, NodeId: hadoop-321-3:44876, NodeHttpAddress: hadoop-321-3:8042, Resource: <memory:2048, vCores:1>, Priority: 0, State: NEW, Token: null, Status: container_id {, app_attempt_id {, application_id {, id: 4, cluster_timestamp: 1376185025835, }, attemptId: 1, }, id: 1, }, state: C_NEW, ]
2013-08-11 01:47:05,702 INFO org.apache.hadoop.yarn.server.resourcemanager.rmapp.attempt.RMAppAttemptImpl: appattempt_1376185025835_0004_000001 State change from SCHEDULED to ALLOCATED_SAVING
2013-08-11 01:47:05,703 INFO org.apache.hadoop.yarn.server.resourcemanager.recovery.RMStateStore: Storing info for attempt: appattempt_1376185025835_0004_000001
2013-08-11 01:47:05,704 INFO org.apache.hadoop.yarn.server.resourcemanager.scheduler.capacity.ParentQueue: assignedContainer queue=root usedCapacity=0.041666668 absoluteUsedCapacity=0.041666668 used=<memory:2048, vCores:1> cluster=<memory:49152, vCores:96>
2013-08-11 01:47:05,705 INFO org.apache.hadoop.yarn.server.resourcemanager.rmapp.attempt.RMAppAttemptImpl: appattempt_1376185025835_0004_000001 State change from ALLOCATED_SAVING to ALLOCATED
2013-08-11 01:47:05,707 INFO org.apache.hadoop.yarn.server.resourcemanager.amlauncher.AMLauncher: Launching masterappattempt_1376185025835_0004_000001
2013-08-11 01:47:05,709 INFO org.apache.hadoop.yarn.server.resourcemanager.amlauncher.AMLauncher: Setting up container Container: [ContainerId: container_1376185025835_0004_01_000001, NodeId: hadoop-321-3:44876, NodeHttpAddress: hadoop-321-3:8042, Resource: <memory:2048, vCores:1>, Priority: 0, State: NEW, Token: null, Status: container_id {, app_attempt_id {, application_id {, id: 4, cluster_timestamp: 1376185025835, }, attemptId: 1, }, id: 1, }, state: C_NEW, ] for AM appattempt_1376185025835_0004_000001
2013-08-11 01:47:05,710 INFO org.apache.hadoop.yarn.server.resourcemanager.amlauncher.AMLauncher: Command to launch container container_1376185025835_0004_01_000001 : $JAVA_HOME/bin/java -Dlog4j.configuration=container-log4j.properties -Dyarn.app.mapreduce.container.log.dir=<LOG_DIR> -Dyarn.app.mapreduce.container.log.filesize=0 -Dhadoop.root.logger=INFO,CLA  -Xmx1024m org.apache.hadoop.mapreduce.v2.app.MRAppMaster 1><LOG_DIR>/stdout 2><LOG_DIR>/stderr 
2013-08-11 01:47:05,728 INFO org.apache.hadoop.yarn.server.resourcemanager.amlauncher.AMLauncher: Done launching container Container: [ContainerId: container_1376185025835_0004_01_000001, NodeId: hadoop-321-3:44876, NodeHttpAddress: hadoop-321-3:8042, Resource: <memory:2048, vCores:1>, Priority: 0, State: NEW, Token: null, Status: container_id {, app_attempt_id {, application_id {, id: 4, cluster_timestamp: 1376185025835, }, attemptId: 1, }, id: 1, }, state: C_NEW, ] for AM appattempt_1376185025835_0004_000001
2013-08-11 01:47:05,728 INFO org.apache.hadoop.yarn.server.resourcemanager.rmapp.attempt.RMAppAttemptImpl: appattempt_1376185025835_0004_000001 State change from ALLOCATED to LAUNCHED
2013-08-11 01:47:06,701 INFO org.apache.hadoop.yarn.server.resourcemanager.rmcontainer.RMContainerImpl: container_1376185025835_0004_01_000001 Container Transitioned from ACQUIRED to RUNNING
2013-08-11 01:47:12,485 INFO org.apache.hadoop.yarn.server.resourcemanager.ApplicationMasterService: AM registration appattempt_1376185025835_0004_000001
2013-08-11 01:47:12,486 INFO org.apache.hadoop.yarn.server.resourcemanager.RMAuditLogger: USER=ubuntu	IP=192.168.100.18	OPERATION=Register App Master	TARGET=ApplicationMasterService	RESULT=SUCCESS	APPID=application_1376185025835_0004	APPATTEMPTID=appattempt_1376185025835_0004_000001
2013-08-11 01:47:12,487 INFO org.apache.hadoop.yarn.server.resourcemanager.rmapp.attempt.RMAppAttemptImpl: appattempt_1376185025835_0004_000001 State change from LAUNCHED to RUNNING
2013-08-11 01:47:12,487 INFO org.apache.hadoop.yarn.server.resourcemanager.rmapp.RMAppImpl: application_1376185025835_0004 State change from ACCEPTED to RUNNING
2013-08-11 01:47:13,731 INFO org.apache.hadoop.yarn.server.resourcemanager.rmcontainer.RMContainerImpl: container_1376185025835_0004_01_000002 Container Transitioned from NEW to ALLOCATED
2013-08-11 01:47:13,731 INFO org.apache.hadoop.yarn.server.resourcemanager.RMAuditLogger: USER=ubuntu	OPERATION=AM Allocated Container	TARGET=SchedulerApp	RESULT=SUCCESS	APPID=application_1376185025835_0004	CONTAINERID=container_1376185025835_0004_01_000002
2013-08-11 01:47:13,731 INFO org.apache.hadoop.yarn.server.resourcemanager.scheduler.common.fica.FiCaSchedulerNode: Assigned container container_1376185025835_0004_01_000002 of capacity <memory:1024, vCores:1> on host hadoop-321-3:44876, which currently has 2 containers, <memory:3072, vCores:2> used and <memory:5120, vCores:14> available
2013-08-11 01:47:13,733 INFO org.apache.hadoop.yarn.server.resourcemanager.scheduler.capacity.LeafQueue: assignedContainer application=application_1376185025835_0004 container=Container: [ContainerId: container_1376185025835_0004_01_000002, NodeId: hadoop-321-3:44876, NodeHttpAddress: hadoop-321-3:8042, Resource: <memory:1024, vCores:1>, Priority: 20, State: NEW, Token: null, Status: container_id {, app_attempt_id {, application_id {, id: 4, cluster_timestamp: 1376185025835, }, attemptId: 1, }, id: 2, }, state: C_NEW, ] containerId=container_1376185025835_0004_01_000002 queue=default: capacity=1.0, absoluteCapacity=1.0, usedResources=<memory:2048, vCores:1>usedCapacity=0.041666668, absoluteUsedCapacity=0.041666668, numApps=1, numContainers=1 usedCapacity=0.041666668 absoluteUsedCapacity=0.041666668 used=<memory:2048, vCores:1> cluster=<memory:49152, vCores:96>
2013-08-11 01:47:13,733 INFO org.apache.hadoop.yarn.server.resourcemanager.scheduler.capacity.ParentQueue: Re-sorting queues since queue: root.default stats: default: capacity=1.0, absoluteCapacity=1.0, usedResources=<memory:3072, vCores:2>usedCapacity=0.0625, absoluteUsedCapacity=0.0625, numApps=1, numContainers=2
2013-08-11 01:47:13,733 INFO org.apache.hadoop.yarn.server.resourcemanager.scheduler.capacity.ParentQueue: assignedContainer queue=root usedCapacity=0.0625 absoluteUsedCapacity=0.0625 used=<memory:3072, vCores:2> cluster=<memory:49152, vCores:96>
2013-08-11 01:47:13,878 INFO org.apache.hadoop.yarn.server.resourcemanager.rmcontainer.RMContainerImpl: container_1376185025835_0004_01_000003 Container Transitioned from NEW to ALLOCATED
2013-08-11 01:47:13,878 INFO org.apache.hadoop.yarn.server.resourcemanager.RMAuditLogger: USER=ubuntu	OPERATION=AM Allocated Container	TARGET=SchedulerApp	RESULT=SUCCESS	APPID=application_1376185025835_0004	CONTAINERID=container_1376185025835_0004_01_000003
2013-08-11 01:47:13,879 INFO org.apache.hadoop.yarn.server.resourcemanager.scheduler.common.fica.FiCaSchedulerNode: Assigned container container_1376185025835_0004_01_000003 of capacity <memory:1024, vCores:1> on host hadoop-321-4:43757, which currently has 1 containers, <memory:1024, vCores:1> used and <memory:7168, vCores:15> available
2013-08-11 01:47:13,880 INFO org.apache.hadoop.yarn.server.resourcemanager.scheduler.capacity.LeafQueue: assignedContainer application=application_1376185025835_0004 container=Container: [ContainerId: container_1376185025835_0004_01_000003, NodeId: hadoop-321-4:43757, NodeHttpAddress: hadoop-321-4:8042, Resource: <memory:1024, vCores:1>, Priority: 20, State: NEW, Token: null, Status: container_id {, app_attempt_id {, application_id {, id: 4, cluster_timestamp: 1376185025835, }, attemptId: 1, }, id: 3, }, state: C_NEW, ] containerId=container_1376185025835_0004_01_000003 queue=default: capacity=1.0, absoluteCapacity=1.0, usedResources=<memory:3072, vCores:2>usedCapacity=0.0625, absoluteUsedCapacity=0.0625, numApps=1, numContainers=2 usedCapacity=0.0625 absoluteUsedCapacity=0.0625 used=<memory:3072, vCores:2> cluster=<memory:49152, vCores:96>
2013-08-11 01:47:13,880 INFO org.apache.hadoop.yarn.server.resourcemanager.scheduler.capacity.ParentQueue: Re-sorting queues since queue: root.default stats: default: capacity=1.0, absoluteCapacity=1.0, usedResources=<memory:4096, vCores:3>usedCapacity=0.083333336, absoluteUsedCapacity=0.083333336, numApps=1, numContainers=3
2013-08-11 01:47:13,880 INFO org.apache.hadoop.yarn.server.resourcemanager.scheduler.capacity.ParentQueue: assignedContainer queue=root usedCapacity=0.083333336 absoluteUsedCapacity=0.083333336 used=<memory:4096, vCores:3> cluster=<memory:49152, vCores:96>
2013-08-11 01:47:14,541 INFO org.apache.hadoop.yarn.server.resourcemanager.rmcontainer.RMContainerImpl: container_1376185025835_0004_01_000002 Container Transitioned from ALLOCATED to ACQUIRED
2013-08-11 01:47:14,543 INFO org.apache.hadoop.yarn.server.resourcemanager.rmcontainer.RMContainerImpl: container_1376185025835_0004_01_000003 Container Transitioned from ALLOCATED to ACQUIRED
2013-08-11 01:47:14,885 INFO org.apache.hadoop.yarn.server.resourcemanager.rmcontainer.RMContainerImpl: container_1376185025835_0004_01_000003 Container Transitioned from ACQUIRED to RUNNING
2013-08-11 01:47:15,578 INFO org.apache.hadoop.yarn.server.resourcemanager.scheduler.AppSchedulingInfo: checking for deactivate... 
2013-08-11 01:47:15,752 INFO org.apache.hadoop.yarn.server.resourcemanager.rmcontainer.RMContainerImpl: container_1376185025835_0004_01_000002 Container Transitioned from ACQUIRED to RUNNING
2013-08-11 01:50:12,103 INFO org.apache.hadoop.yarn.server.resourcemanager.rmcontainer.RMContainerImpl: container_1376185025835_0004_01_000002 Container Transitioned from RUNNING to COMPLETED
2013-08-11 01:50:12,104 INFO org.apache.hadoop.yarn.server.resourcemanager.scheduler.common.fica.FiCaSchedulerApp: Completed container: container_1376185025835_0004_01_000002 in state: COMPLETED event:FINISHED
2013-08-11 01:50:12,104 INFO org.apache.hadoop.yarn.server.resourcemanager.RMAuditLogger: USER=ubuntu	OPERATION=AM Released Container	TARGET=SchedulerApp	RESULT=SUCCESS	APPID=application_1376185025835_0004	CONTAINERID=container_1376185025835_0004_01_000002
2013-08-11 01:50:12,104 INFO org.apache.hadoop.yarn.server.resourcemanager.scheduler.common.fica.FiCaSchedulerNode: Released container container_1376185025835_0004_01_000002 of capacity <memory:1024, vCores:1> on host hadoop-321-3:44876, which currently has 1 containers, <memory:2048, vCores:1> used and <memory:6144, vCores:15> available, release resources=true
2013-08-11 01:50:12,104 INFO org.apache.hadoop.yarn.server.resourcemanager.scheduler.capacity.LeafQueue: default used=<memory:3072, vCores:2> numContainers=2 user=ubuntu user-resources=<memory:3072, vCores:2>
2013-08-11 01:50:12,106 INFO org.apache.hadoop.yarn.server.resourcemanager.scheduler.capacity.LeafQueue: completedContainer container=Container: [ContainerId: container_1376185025835_0004_01_000002, NodeId: hadoop-321-3:44876, NodeHttpAddress: hadoop-321-3:8042, Resource: <memory:1024, vCores:1>, Priority: 20, State: NEW, Token: null, Status: container_id {, app_attempt_id {, application_id {, id: 4, cluster_timestamp: 1376185025835, }, attemptId: 1, }, id: 2, }, state: C_COMPLETE, diagnostics: "Container killed by the ApplicationMaster.\n\n", exit_status: 143, ] resource=<memory:1024, vCores:1> queue=default: capacity=1.0, absoluteCapacity=1.0, usedResources=<memory:3072, vCores:2>usedCapacity=0.0625, absoluteUsedCapacity=0.0625, numApps=1, numContainers=2 usedCapacity=0.0625 absoluteUsedCapacity=0.0625 used=<memory:3072, vCores:2> cluster=<memory:49152, vCores:96>
2013-08-11 01:50:12,106 INFO org.apache.hadoop.yarn.server.resourcemanager.scheduler.capacity.ParentQueue: completedContainer queue=root usedCapacity=0.0625 absoluteUsedCapacity=0.0625 used=<memory:3072, vCores:2> cluster=<memory:49152, vCores:96>
2013-08-11 01:50:12,106 INFO org.apache.hadoop.yarn.server.resourcemanager.scheduler.capacity.CapacityScheduler: Application appattempt_1376185025835_0004_000001 released container container_1376185025835_0004_01_000002 on node: host: hadoop-321-3:44876 #containers=1 available=6144 used=2048 with event: FINISHED
2013-08-11 01:50:15,361 INFO org.apache.hadoop.yarn.server.resourcemanager.rmcontainer.RMContainerImpl: container_1376185025835_0004_01_000003 Container Transitioned from RUNNING to COMPLETED
2013-08-11 01:50:15,361 INFO org.apache.hadoop.yarn.server.resourcemanager.scheduler.common.fica.FiCaSchedulerApp: Completed container: container_1376185025835_0004_01_000003 in state: COMPLETED event:FINISHED
2013-08-11 01:50:15,361 INFO org.apache.hadoop.yarn.server.resourcemanager.RMAuditLogger: USER=ubuntu	OPERATION=AM Released Container	TARGET=SchedulerApp	RESULT=SUCCESS	APPID=application_1376185025835_0004	CONTAINERID=container_1376185025835_0004_01_000003
2013-08-11 01:50:15,361 INFO org.apache.hadoop.yarn.server.resourcemanager.scheduler.common.fica.FiCaSchedulerNode: Released container container_1376185025835_0004_01_000003 of capacity <memory:1024, vCores:1> on host hadoop-321-4:43757, which currently has 0 containers, <memory:0, vCores:0> used and <memory:8192, vCores:16> available, release resources=true
2013-08-11 01:50:15,362 INFO org.apache.hadoop.yarn.server.resourcemanager.scheduler.capacity.LeafQueue: default used=<memory:2048, vCores:1> numContainers=1 user=ubuntu user-resources=<memory:2048, vCores:1>
2013-08-11 01:50:15,363 INFO org.apache.hadoop.yarn.server.resourcemanager.scheduler.capacity.LeafQueue: completedContainer container=Container: [ContainerId: container_1376185025835_0004_01_000003, NodeId: hadoop-321-4:43757, NodeHttpAddress: hadoop-321-4:8042, Resource: <memory:1024, vCores:1>, Priority: 20, State: NEW, Token: null, Status: container_id {, app_attempt_id {, application_id {, id: 4, cluster_timestamp: 1376185025835, }, attemptId: 1, }, id: 3, }, state: C_COMPLETE, diagnostics: "Container killed by the ApplicationMaster.\n\n", exit_status: 143, ] resource=<memory:1024, vCores:1> queue=default: capacity=1.0, absoluteCapacity=1.0, usedResources=<memory:2048, vCores:1>usedCapacity=0.041666668, absoluteUsedCapacity=0.041666668, numApps=1, numContainers=1 usedCapacity=0.041666668 absoluteUsedCapacity=0.041666668 used=<memory:2048, vCores:1> cluster=<memory:49152, vCores:96>
2013-08-11 01:50:15,364 INFO org.apache.hadoop.yarn.server.resourcemanager.scheduler.capacity.ParentQueue: completedContainer queue=root usedCapacity=0.041666668 absoluteUsedCapacity=0.041666668 used=<memory:2048, vCores:1> cluster=<memory:49152, vCores:96>
2013-08-11 01:50:15,364 INFO org.apache.hadoop.yarn.server.resourcemanager.scheduler.capacity.CapacityScheduler: Application appattempt_1376185025835_0004_000001 released container container_1376185025835_0004_01_000003 on node: host: hadoop-321-4:43757 #containers=0 available=8192 used=0 with event: FINISHED
2013-08-11 01:50:19,524 INFO org.apache.hadoop.yarn.server.resourcemanager.rmapp.attempt.RMAppAttemptImpl: appattempt_1376185025835_0004_000001 State change from RUNNING to FINISHING
2013-08-11 01:50:19,524 INFO org.apache.hadoop.yarn.server.resourcemanager.rmapp.RMAppImpl: application_1376185025835_0004 State change from RUNNING to FINISHING
2013-08-11 01:50:20,135 INFO org.apache.hadoop.yarn.server.resourcemanager.rmcontainer.RMContainerImpl: container_1376185025835_0004_01_000001 Container Transitioned from RUNNING to COMPLETED
2013-08-11 01:50:20,135 INFO org.apache.hadoop.yarn.server.resourcemanager.scheduler.common.fica.FiCaSchedulerApp: Completed container: container_1376185025835_0004_01_000001 in state: COMPLETED event:FINISHED
2013-08-11 01:50:20,135 INFO org.apache.hadoop.yarn.server.resourcemanager.RMAuditLogger: USER=ubuntu	OPERATION=AM Released Container	TARGET=SchedulerApp	RESULT=SUCCESS	APPID=application_1376185025835_0004	CONTAINERID=container_1376185025835_0004_01_000001
2013-08-11 01:50:20,135 INFO org.apache.hadoop.yarn.server.resourcemanager.scheduler.common.fica.FiCaSchedulerNode: Released container container_1376185025835_0004_01_000001 of capacity <memory:2048, vCores:1> on host hadoop-321-3:44876, which currently has 0 containers, <memory:0, vCores:0> used and <memory:8192, vCores:16> available, release resources=true
2013-08-11 01:50:20,136 INFO org.apache.hadoop.yarn.server.resourcemanager.scheduler.capacity.LeafQueue: default used=<memory:0, vCores:0> numContainers=0 user=ubuntu user-resources=<memory:0, vCores:0>
2013-08-11 01:50:20,137 INFO org.apache.hadoop.yarn.server.resourcemanager.scheduler.capacity.LeafQueue: completedContainer container=Container: [ContainerId: container_1376185025835_0004_01_000001, NodeId: hadoop-321-3:44876, NodeHttpAddress: hadoop-321-3:8042, Resource: <memory:2048, vCores:1>, Priority: 0, State: NEW, Token: null, Status: container_id {, app_attempt_id {, application_id {, id: 4, cluster_timestamp: 1376185025835, }, attemptId: 1, }, id: 1, }, state: C_COMPLETE, diagnostics: "", exit_status: 0, ] resource=<memory:2048, vCores:1> queue=default: capacity=1.0, absoluteCapacity=1.0, usedResources=<memory:0, vCores:0>usedCapacity=0.0, absoluteUsedCapacity=0.0, numApps=1, numContainers=0 usedCapacity=0.0 absoluteUsedCapacity=0.0 used=<memory:0, vCores:0> cluster=<memory:49152, vCores:96>
2013-08-11 01:50:20,137 INFO org.apache.hadoop.yarn.server.resourcemanager.scheduler.capacity.ParentQueue: completedContainer queue=root usedCapacity=0.0 absoluteUsedCapacity=0.0 used=<memory:0, vCores:0> cluster=<memory:49152, vCores:96>
2013-08-11 01:50:20,137 INFO org.apache.hadoop.yarn.server.resourcemanager.scheduler.capacity.CapacityScheduler: Application appattempt_1376185025835_0004_000001 released container container_1376185025835_0004_01_000001 on node: host: hadoop-321-3:44876 #containers=0 available=8192 used=0 with event: FINISHED
2013-08-11 01:50:20,138 INFO org.apache.hadoop.yarn.server.resourcemanager.rmapp.attempt.RMAppAttemptImpl: appattempt_1376185025835_0004_000001 State change from FINISHING to FINISHED
2013-08-11 01:50:20,138 INFO org.apache.hadoop.yarn.server.resourcemanager.rmapp.RMAppImpl: application_1376185025835_0004 State change from FINISHING to FINISHED
2013-08-11 01:50:20,139 INFO org.apache.hadoop.yarn.server.resourcemanager.RMAuditLogger: USER=ubuntu	OPERATION=Application Finished - Succeeded	TARGET=RMAppManager	RESULT=SUCCESS	APPID=application_1376185025835_0004
2013-08-11 01:50:20,139 INFO org.apache.hadoop.yarn.server.resourcemanager.RMAppManager$ApplicationSummary: appId=application_1376185025835_0004,name=TeraGen,user=ubuntu,queue=default,state=FINISHED,trackingUrl=hadoop-321-1.novalocal:8088/proxy/application_1376185025835_0004/jobhistory/job/job_1376185025835_0004,appMasterHost=hadoop-321-3,startTime=1376185625680,finishTime=1376185819524
2013-08-11 01:50:20,139 INFO org.apache.hadoop.yarn.server.resourcemanager.recovery.RMStateStore: Removing info for app: application_1376185025835_0004
2013-08-11 01:50:20,139 INFO org.apache.hadoop.yarn.server.resourcemanager.scheduler.capacity.CapacityScheduler: Application appattempt_1376185025835_0004_000001 is done. finalState=FINISHED
2013-08-11 01:50:20,140 INFO org.apache.hadoop.yarn.server.resourcemanager.scheduler.AppSchedulingInfo: Application application_1376185025835_0004 requests cleared
2013-08-11 01:50:20,140 INFO org.apache.hadoop.yarn.server.resourcemanager.scheduler.capacity.LeafQueue: Application removed - appId: application_1376185025835_0004 user: ubuntu queue: default #user-pending-applications: 0 #user-active-applications: 0 #queue-pending-applications: 0 #queue-active-applications: 0
2013-08-11 01:50:20,140 INFO org.apache.hadoop.yarn.server.resourcemanager.scheduler.capacity.ParentQueue: Application removed - appId: application_1376185025835_0004 user: ubuntu leaf-queue of parent: root #applications: 0
2013-08-11 01:50:20,140 INFO org.apache.hadoop.yarn.server.resourcemanager.amlauncher.AMLauncher: Cleaning master appattempt_1376185025835_0004_000001
2013-08-11 01:50:20,706 INFO org.apache.hadoop.yarn.server.resourcemanager.ClientRMService: Allocated new applicationId: 5
2013-08-11 01:50:22,620 INFO org.apache.hadoop.yarn.server.resourcemanager.ClientRMService: Storing Application with id application_1376185025835_0005
2013-08-11 01:50:22,620 INFO org.apache.hadoop.yarn.server.resourcemanager.recovery.RMStateStore: Storing info for app: application_1376185025835_0005
2013-08-11 01:50:22,620 INFO org.apache.hadoop.yarn.server.resourcemanager.ClientRMService: Application with id 5 submitted by user ubuntu
2013-08-11 01:50:22,620 INFO org.apache.hadoop.yarn.server.resourcemanager.RMAuditLogger: USER=ubuntu	IP=192.168.100.15	OPERATION=Submit Application Request	TARGET=ClientRMService	RESULT=SUCCESS	APPID=application_1376185025835_0005
2013-08-11 01:50:22,622 INFO org.apache.hadoop.yarn.server.resourcemanager.rmapp.RMAppImpl: application_1376185025835_0005 State change from NEW to SUBMITTED
2013-08-11 01:50:22,622 INFO org.apache.hadoop.yarn.server.resourcemanager.ApplicationMasterService: Registering appattempt_1376185025835_0005_000001
2013-08-11 01:50:22,622 INFO org.apache.hadoop.yarn.server.resourcemanager.rmapp.attempt.RMAppAttemptImpl: appattempt_1376185025835_0005_000001 State change from NEW to SUBMITTED
2013-08-11 01:50:22,623 INFO org.apache.hadoop.yarn.server.resourcemanager.scheduler.capacity.LeafQueue: Application application_1376185025835_0005 from user: ubuntu activated in queue: default
2013-08-11 01:50:22,623 INFO org.apache.hadoop.yarn.server.resourcemanager.scheduler.capacity.LeafQueue: Application added - appId: application_1376185025835_0005 user: org.apache.hadoop.yarn.server.resourcemanager.scheduler.capacity.LeafQueue$User@46b4ea68, leaf-queue: default #user-pending-applications: 0 #user-active-applications: 1 #queue-pending-applications: 0 #queue-active-applications: 1
2013-08-11 01:50:22,623 INFO org.apache.hadoop.yarn.server.resourcemanager.scheduler.capacity.ParentQueue: Application added - appId: application_1376185025835_0005 user: ubuntu leaf-queue of parent: root #applications: 1
2013-08-11 01:50:22,623 INFO org.apache.hadoop.yarn.server.resourcemanager.scheduler.capacity.CapacityScheduler: Application Submission: appattempt_1376185025835_0005_000001, user: ubuntu queue: default: capacity=1.0, absoluteCapacity=1.0, usedResources=<memory:0, vCores:0>usedCapacity=0.0, absoluteUsedCapacity=0.0, numApps=1, numContainers=0, currently active: 1
2013-08-11 01:50:22,624 INFO org.apache.hadoop.yarn.server.resourcemanager.rmapp.attempt.RMAppAttemptImpl: appattempt_1376185025835_0005_000001 State change from SUBMITTED to SCHEDULED
2013-08-11 01:50:22,624 INFO org.apache.hadoop.yarn.server.resourcemanager.rmapp.RMAppImpl: application_1376185025835_0005 State change from SUBMITTED to ACCEPTED
2013-08-11 01:50:22,718 INFO org.apache.hadoop.yarn.server.resourcemanager.rmcontainer.RMContainerImpl: container_1376185025835_0005_01_000001 Container Transitioned from NEW to ALLOCATED
2013-08-11 01:50:22,719 INFO org.apache.hadoop.yarn.server.resourcemanager.RMAuditLogger: USER=ubuntu	OPERATION=AM Allocated Container	TARGET=SchedulerApp	RESULT=SUCCESS	APPID=application_1376185025835_0005	CONTAINERID=container_1376185025835_0005_01_000001
2013-08-11 01:50:22,719 INFO org.apache.hadoop.yarn.server.resourcemanager.scheduler.common.fica.FiCaSchedulerNode: Assigned container container_1376185025835_0005_01_000001 of capacity <memory:2048, vCores:1> on host hadoop-321-2:46202, which currently has 1 containers, <memory:2048, vCores:1> used and <memory:6144, vCores:15> available
2013-08-11 01:50:22,720 INFO org.apache.hadoop.yarn.server.resourcemanager.scheduler.capacity.LeafQueue: assignedContainer application=application_1376185025835_0005 container=Container: [ContainerId: container_1376185025835_0005_01_000001, NodeId: hadoop-321-2:46202, NodeHttpAddress: hadoop-321-2:8042, Resource: <memory:2048, vCores:1>, Priority: 0, State: NEW, Token: null, Status: container_id {, app_attempt_id {, application_id {, id: 5, cluster_timestamp: 1376185025835, }, attemptId: 1, }, id: 1, }, state: C_NEW, ] containerId=container_1376185025835_0005_01_000001 queue=default: capacity=1.0, absoluteCapacity=1.0, usedResources=<memory:0, vCores:0>usedCapacity=0.0, absoluteUsedCapacity=0.0, numApps=1, numContainers=0 usedCapacity=0.0 absoluteUsedCapacity=0.0 used=<memory:0, vCores:0> cluster=<memory:49152, vCores:96>
2013-08-11 01:50:22,720 INFO org.apache.hadoop.yarn.server.resourcemanager.scheduler.capacity.ParentQueue: Re-sorting queues since queue: root.default stats: default: capacity=1.0, absoluteCapacity=1.0, usedResources=<memory:2048, vCores:1>usedCapacity=0.041666668, absoluteUsedCapacity=0.041666668, numApps=1, numContainers=1
2013-08-11 01:50:22,721 INFO org.apache.hadoop.yarn.server.resourcemanager.scheduler.capacity.ParentQueue: assignedContainer queue=root usedCapacity=0.041666668 absoluteUsedCapacity=0.041666668 used=<memory:2048, vCores:1> cluster=<memory:49152, vCores:96>
2013-08-11 01:50:22,722 INFO org.apache.hadoop.yarn.server.resourcemanager.rmcontainer.RMContainerImpl: container_1376185025835_0005_01_000001 Container Transitioned from ALLOCATED to ACQUIRED
2013-08-11 01:50:22,732 INFO org.apache.hadoop.yarn.server.resourcemanager.rmapp.attempt.RMAppAttemptImpl: Storing attempt: AppId: application_1376185025835_0005 AttemptId: appattempt_1376185025835_0005_000001 MasterContainer: Container: [ContainerId: container_1376185025835_0005_01_000001, NodeId: hadoop-321-2:46202, NodeHttpAddress: hadoop-321-2:8042, Resource: <memory:2048, vCores:1>, Priority: 0, State: NEW, Token: null, Status: container_id {, app_attempt_id {, application_id {, id: 5, cluster_timestamp: 1376185025835, }, attemptId: 1, }, id: 1, }, state: C_NEW, ]
2013-08-11 01:50:22,732 INFO org.apache.hadoop.yarn.server.resourcemanager.rmapp.attempt.RMAppAttemptImpl: appattempt_1376185025835_0005_000001 State change from SCHEDULED to ALLOCATED_SAVING
2013-08-11 01:50:22,732 INFO org.apache.hadoop.yarn.server.resourcemanager.recovery.RMStateStore: Storing info for attempt: appattempt_1376185025835_0005_000001
2013-08-11 01:50:22,736 INFO org.apache.hadoop.yarn.server.resourcemanager.rmapp.attempt.RMAppAttemptImpl: appattempt_1376185025835_0005_000001 State change from ALLOCATED_SAVING to ALLOCATED
2013-08-11 01:50:22,738 INFO org.apache.hadoop.yarn.server.resourcemanager.amlauncher.AMLauncher: Launching masterappattempt_1376185025835_0005_000001
2013-08-11 01:50:22,741 INFO org.apache.hadoop.yarn.server.resourcemanager.amlauncher.AMLauncher: Setting up container Container: [ContainerId: container_1376185025835_0005_01_000001, NodeId: hadoop-321-2:46202, NodeHttpAddress: hadoop-321-2:8042, Resource: <memory:2048, vCores:1>, Priority: 0, State: NEW, Token: null, Status: container_id {, app_attempt_id {, application_id {, id: 5, cluster_timestamp: 1376185025835, }, attemptId: 1, }, id: 1, }, state: C_NEW, ] for AM appattempt_1376185025835_0005_000001
2013-08-11 01:50:22,741 INFO org.apache.hadoop.yarn.server.resourcemanager.amlauncher.AMLauncher: Command to launch container container_1376185025835_0005_01_000001 : $JAVA_HOME/bin/java -Dlog4j.configuration=container-log4j.properties -Dyarn.app.mapreduce.container.log.dir=<LOG_DIR> -Dyarn.app.mapreduce.container.log.filesize=0 -Dhadoop.root.logger=INFO,CLA  -Xmx1024m org.apache.hadoop.mapreduce.v2.app.MRAppMaster 1><LOG_DIR>/stdout 2><LOG_DIR>/stderr 
2013-08-11 01:50:22,754 INFO org.apache.hadoop.yarn.server.resourcemanager.amlauncher.AMLauncher: Done launching container Container: [ContainerId: container_1376185025835_0005_01_000001, NodeId: hadoop-321-2:46202, NodeHttpAddress: hadoop-321-2:8042, Resource: <memory:2048, vCores:1>, Priority: 0, State: NEW, Token: null, Status: container_id {, app_attempt_id {, application_id {, id: 5, cluster_timestamp: 1376185025835, }, attemptId: 1, }, id: 1, }, state: C_NEW, ] for AM appattempt_1376185025835_0005_000001
2013-08-11 01:50:22,754 INFO org.apache.hadoop.yarn.server.resourcemanager.rmapp.attempt.RMAppAttemptImpl: appattempt_1376185025835_0005_000001 State change from ALLOCATED to LAUNCHED
2013-08-11 01:50:23,724 INFO org.apache.hadoop.yarn.server.resourcemanager.rmcontainer.RMContainerImpl: container_1376185025835_0005_01_000001 Container Transitioned from ACQUIRED to RUNNING
2013-08-11 01:50:29,922 INFO org.apache.hadoop.yarn.server.resourcemanager.ApplicationMasterService: AM registration appattempt_1376185025835_0005_000001
2013-08-11 01:50:29,922 INFO org.apache.hadoop.yarn.server.resourcemanager.RMAuditLogger: USER=ubuntu	IP=192.168.100.17	OPERATION=Register App Master	TARGET=ApplicationMasterService	RESULT=SUCCESS	APPID=application_1376185025835_0005	APPATTEMPTID=appattempt_1376185025835_0005_000001
2013-08-11 01:50:29,924 INFO org.apache.hadoop.yarn.server.resourcemanager.rmapp.attempt.RMAppAttemptImpl: appattempt_1376185025835_0005_000001 State change from LAUNCHED to RUNNING
2013-08-11 01:50:29,924 INFO org.apache.hadoop.yarn.server.resourcemanager.rmapp.RMAppImpl: application_1376185025835_0005 State change from ACCEPTED to RUNNING
2013-08-11 01:50:31,151 INFO org.apache.hadoop.yarn.server.resourcemanager.rmcontainer.RMContainerImpl: container_1376185025835_0005_01_000002 Container Transitioned from NEW to ALLOCATED
2013-08-11 01:50:31,151 INFO org.apache.hadoop.yarn.server.resourcemanager.RMAuditLogger: USER=ubuntu	OPERATION=AM Allocated Container	TARGET=SchedulerApp	RESULT=SUCCESS	APPID=application_1376185025835_0005	CONTAINERID=container_1376185025835_0005_01_000002
2013-08-11 01:50:31,152 INFO org.apache.hadoop.yarn.server.resourcemanager.scheduler.common.fica.FiCaSchedulerNode: Assigned container container_1376185025835_0005_01_000002 of capacity <memory:1024, vCores:1> on host hadoop-321-6:34867, which currently has 1 containers, <memory:1024, vCores:1> used and <memory:7168, vCores:15> available
2013-08-11 01:50:31,153 INFO org.apache.hadoop.yarn.server.resourcemanager.scheduler.capacity.LeafQueue: assignedContainer application=application_1376185025835_0005 container=Container: [ContainerId: container_1376185025835_0005_01_000002, NodeId: hadoop-321-6:34867, NodeHttpAddress: hadoop-321-6:8042, Resource: <memory:1024, vCores:1>, Priority: 20, State: NEW, Token: null, Status: container_id {, app_attempt_id {, application_id {, id: 5, cluster_timestamp: 1376185025835, }, attemptId: 1, }, id: 2, }, state: C_NEW, ] containerId=container_1376185025835_0005_01_000002 queue=default: capacity=1.0, absoluteCapacity=1.0, usedResources=<memory:2048, vCores:1>usedCapacity=0.041666668, absoluteUsedCapacity=0.041666668, numApps=1, numContainers=1 usedCapacity=0.041666668 absoluteUsedCapacity=0.041666668 used=<memory:2048, vCores:1> cluster=<memory:49152, vCores:96>
2013-08-11 01:50:31,153 INFO org.apache.hadoop.yarn.server.resourcemanager.scheduler.capacity.ParentQueue: Re-sorting queues since queue: root.default stats: default: capacity=1.0, absoluteCapacity=1.0, usedResources=<memory:3072, vCores:2>usedCapacity=0.0625, absoluteUsedCapacity=0.0625, numApps=1, numContainers=2
2013-08-11 01:50:31,153 INFO org.apache.hadoop.yarn.server.resourcemanager.scheduler.capacity.ParentQueue: assignedContainer queue=root usedCapacity=0.0625 absoluteUsedCapacity=0.0625 used=<memory:3072, vCores:2> cluster=<memory:49152, vCores:96>
2013-08-11 01:50:31,178 INFO org.apache.hadoop.yarn.server.resourcemanager.rmcontainer.RMContainerImpl: container_1376185025835_0005_01_000003 Container Transitioned from NEW to ALLOCATED
2013-08-11 01:50:31,178 INFO org.apache.hadoop.yarn.server.resourcemanager.RMAuditLogger: USER=ubuntu	OPERATION=AM Allocated Container	TARGET=SchedulerApp	RESULT=SUCCESS	APPID=application_1376185025835_0005	CONTAINERID=container_1376185025835_0005_01_000003
2013-08-11 01:50:31,178 INFO org.apache.hadoop.yarn.server.resourcemanager.scheduler.common.fica.FiCaSchedulerNode: Assigned container container_1376185025835_0005_01_000003 of capacity <memory:1024, vCores:1> on host hadoop-321-3:44876, which currently has 1 containers, <memory:1024, vCores:1> used and <memory:7168, vCores:15> available
2013-08-11 01:50:31,179 INFO org.apache.hadoop.yarn.server.resourcemanager.scheduler.capacity.LeafQueue: assignedContainer application=application_1376185025835_0005 container=Container: [ContainerId: container_1376185025835_0005_01_000003, NodeId: hadoop-321-3:44876, NodeHttpAddress: hadoop-321-3:8042, Resource: <memory:1024, vCores:1>, Priority: 20, State: NEW, Token: null, Status: container_id {, app_attempt_id {, application_id {, id: 5, cluster_timestamp: 1376185025835, }, attemptId: 1, }, id: 3, }, state: C_NEW, ] containerId=container_1376185025835_0005_01_000003 queue=default: capacity=1.0, absoluteCapacity=1.0, usedResources=<memory:3072, vCores:2>usedCapacity=0.0625, absoluteUsedCapacity=0.0625, numApps=1, numContainers=2 usedCapacity=0.0625 absoluteUsedCapacity=0.0625 used=<memory:3072, vCores:2> cluster=<memory:49152, vCores:96>
2013-08-11 01:50:31,180 INFO org.apache.hadoop.yarn.server.resourcemanager.scheduler.capacity.ParentQueue: Re-sorting queues since queue: root.default stats: default: capacity=1.0, absoluteCapacity=1.0, usedResources=<memory:4096, vCores:3>usedCapacity=0.083333336, absoluteUsedCapacity=0.083333336, numApps=1, numContainers=3
2013-08-11 01:50:31,180 INFO org.apache.hadoop.yarn.server.resourcemanager.scheduler.capacity.ParentQueue: assignedContainer queue=root usedCapacity=0.083333336 absoluteUsedCapacity=0.083333336 used=<memory:4096, vCores:3> cluster=<memory:49152, vCores:96>
2013-08-11 01:50:31,982 INFO org.apache.hadoop.yarn.server.resourcemanager.rmcontainer.RMContainerImpl: container_1376185025835_0005_01_000002 Container Transitioned from ALLOCATED to ACQUIRED
2013-08-11 01:50:31,986 INFO org.apache.hadoop.yarn.server.resourcemanager.rmcontainer.RMContainerImpl: container_1376185025835_0005_01_000003 Container Transitioned from ALLOCATED to ACQUIRED
2013-08-11 01:50:33,018 INFO org.apache.hadoop.yarn.server.resourcemanager.scheduler.AppSchedulingInfo: checking for deactivate... 
2013-08-11 01:50:33,181 INFO org.apache.hadoop.yarn.server.resourcemanager.rmcontainer.RMContainerImpl: container_1376185025835_0005_01_000002 Container Transitioned from ACQUIRED to RUNNING
2013-08-11 01:50:33,190 INFO org.apache.hadoop.yarn.server.resourcemanager.rmcontainer.RMContainerImpl: container_1376185025835_0005_01_000003 Container Transitioned from ACQUIRED to RUNNING
2013-08-11 01:53:21,690 INFO org.apache.hadoop.yarn.server.resourcemanager.rmcontainer.RMContainerImpl: container_1376185025835_0005_01_000002 Container Transitioned from RUNNING to COMPLETED
2013-08-11 01:53:21,691 INFO org.apache.hadoop.yarn.server.resourcemanager.scheduler.common.fica.FiCaSchedulerApp: Completed container: container_1376185025835_0005_01_000002 in state: COMPLETED event:FINISHED
2013-08-11 01:53:21,691 INFO org.apache.hadoop.yarn.server.resourcemanager.RMAuditLogger: USER=ubuntu	OPERATION=AM Released Container	TARGET=SchedulerApp	RESULT=SUCCESS	APPID=application_1376185025835_0005	CONTAINERID=container_1376185025835_0005_01_000002
2013-08-11 01:53:21,692 INFO org.apache.hadoop.yarn.server.resourcemanager.scheduler.common.fica.FiCaSchedulerNode: Released container container_1376185025835_0005_01_000002 of capacity <memory:1024, vCores:1> on host hadoop-321-6:34867, which currently has 0 containers, <memory:0, vCores:0> used and <memory:8192, vCores:16> available, release resources=true
2013-08-11 01:53:21,692 INFO org.apache.hadoop.yarn.server.resourcemanager.scheduler.capacity.LeafQueue: default used=<memory:3072, vCores:2> numContainers=2 user=ubuntu user-resources=<memory:3072, vCores:2>
2013-08-11 01:53:21,693 INFO org.apache.hadoop.yarn.server.resourcemanager.scheduler.capacity.LeafQueue: completedContainer container=Container: [ContainerId: container_1376185025835_0005_01_000002, NodeId: hadoop-321-6:34867, NodeHttpAddress: hadoop-321-6:8042, Resource: <memory:1024, vCores:1>, Priority: 20, State: NEW, Token: null, Status: container_id {, app_attempt_id {, application_id {, id: 5, cluster_timestamp: 1376185025835, }, attemptId: 1, }, id: 2, }, state: C_COMPLETE, diagnostics: "Container killed by the ApplicationMaster.\n\n", exit_status: 143, ] resource=<memory:1024, vCores:1> queue=default: capacity=1.0, absoluteCapacity=1.0, usedResources=<memory:3072, vCores:2>usedCapacity=0.0625, absoluteUsedCapacity=0.0625, numApps=1, numContainers=2 usedCapacity=0.0625 absoluteUsedCapacity=0.0625 used=<memory:3072, vCores:2> cluster=<memory:49152, vCores:96>
2013-08-11 01:53:21,694 INFO org.apache.hadoop.yarn.server.resourcemanager.scheduler.capacity.ParentQueue: completedContainer queue=root usedCapacity=0.0625 absoluteUsedCapacity=0.0625 used=<memory:3072, vCores:2> cluster=<memory:49152, vCores:96>
2013-08-11 01:53:21,694 INFO org.apache.hadoop.yarn.server.resourcemanager.scheduler.capacity.CapacityScheduler: Application appattempt_1376185025835_0005_000001 released container container_1376185025835_0005_01_000002 on node: host: hadoop-321-6:34867 #containers=0 available=8192 used=0 with event: FINISHED
2013-08-11 01:53:26,707 INFO org.apache.hadoop.yarn.server.resourcemanager.rmcontainer.RMContainerImpl: container_1376185025835_0005_01_000003 Container Transitioned from RUNNING to COMPLETED
2013-08-11 01:53:26,707 INFO org.apache.hadoop.yarn.server.resourcemanager.scheduler.common.fica.FiCaSchedulerApp: Completed container: container_1376185025835_0005_01_000003 in state: COMPLETED event:FINISHED
2013-08-11 01:53:26,708 INFO org.apache.hadoop.yarn.server.resourcemanager.RMAuditLogger: USER=ubuntu	OPERATION=AM Released Container	TARGET=SchedulerApp	RESULT=SUCCESS	APPID=application_1376185025835_0005	CONTAINERID=container_1376185025835_0005_01_000003
2013-08-11 01:53:26,708 INFO org.apache.hadoop.yarn.server.resourcemanager.scheduler.common.fica.FiCaSchedulerNode: Released container container_1376185025835_0005_01_000003 of capacity <memory:1024, vCores:1> on host hadoop-321-3:44876, which currently has 0 containers, <memory:0, vCores:0> used and <memory:8192, vCores:16> available, release resources=true
2013-08-11 01:53:26,708 INFO org.apache.hadoop.yarn.server.resourcemanager.scheduler.capacity.LeafQueue: default used=<memory:2048, vCores:1> numContainers=1 user=ubuntu user-resources=<memory:2048, vCores:1>
2013-08-11 01:53:26,709 INFO org.apache.hadoop.yarn.server.resourcemanager.scheduler.capacity.LeafQueue: completedContainer container=Container: [ContainerId: container_1376185025835_0005_01_000003, NodeId: hadoop-321-3:44876, NodeHttpAddress: hadoop-321-3:8042, Resource: <memory:1024, vCores:1>, Priority: 20, State: NEW, Token: null, Status: container_id {, app_attempt_id {, application_id {, id: 5, cluster_timestamp: 1376185025835, }, attemptId: 1, }, id: 3, }, state: C_COMPLETE, diagnostics: "Container killed by the ApplicationMaster.\n\n", exit_status: 143, ] resource=<memory:1024, vCores:1> queue=default: capacity=1.0, absoluteCapacity=1.0, usedResources=<memory:2048, vCores:1>usedCapacity=0.041666668, absoluteUsedCapacity=0.041666668, numApps=1, numContainers=1 usedCapacity=0.041666668 absoluteUsedCapacity=0.041666668 used=<memory:2048, vCores:1> cluster=<memory:49152, vCores:96>
2013-08-11 01:53:26,710 INFO org.apache.hadoop.yarn.server.resourcemanager.scheduler.capacity.ParentQueue: completedContainer queue=root usedCapacity=0.041666668 absoluteUsedCapacity=0.041666668 used=<memory:2048, vCores:1> cluster=<memory:49152, vCores:96>
2013-08-11 01:53:26,710 INFO org.apache.hadoop.yarn.server.resourcemanager.scheduler.capacity.CapacityScheduler: Application appattempt_1376185025835_0005_000001 released container container_1376185025835_0005_01_000003 on node: host: hadoop-321-3:44876 #containers=0 available=8192 used=0 with event: FINISHED
2013-08-11 01:53:30,879 INFO org.apache.hadoop.yarn.server.resourcemanager.rmapp.attempt.RMAppAttemptImpl: appattempt_1376185025835_0005_000001 State change from RUNNING to FINISHING
2013-08-11 01:53:30,879 INFO org.apache.hadoop.yarn.server.resourcemanager.rmapp.RMAppImpl: application_1376185025835_0005 State change from RUNNING to FINISHING
2013-08-11 01:53:31,655 INFO org.apache.hadoop.yarn.server.resourcemanager.rmcontainer.RMContainerImpl: container_1376185025835_0005_01_000001 Container Transitioned from RUNNING to COMPLETED
2013-08-11 01:53:31,655 INFO org.apache.hadoop.yarn.server.resourcemanager.scheduler.common.fica.FiCaSchedulerApp: Completed container: container_1376185025835_0005_01_000001 in state: COMPLETED event:FINISHED
2013-08-11 01:53:31,655 INFO org.apache.hadoop.yarn.server.resourcemanager.RMAuditLogger: USER=ubuntu	OPERATION=AM Released Container	TARGET=SchedulerApp	RESULT=SUCCESS	APPID=application_1376185025835_0005	CONTAINERID=container_1376185025835_0005_01_000001
2013-08-11 01:53:31,655 INFO org.apache.hadoop.yarn.server.resourcemanager.scheduler.common.fica.FiCaSchedulerNode: Released container container_1376185025835_0005_01_000001 of capacity <memory:2048, vCores:1> on host hadoop-321-2:46202, which currently has 0 containers, <memory:0, vCores:0> used and <memory:8192, vCores:16> available, release resources=true
2013-08-11 01:53:31,655 INFO org.apache.hadoop.yarn.server.resourcemanager.scheduler.capacity.LeafQueue: default used=<memory:0, vCores:0> numContainers=0 user=ubuntu user-resources=<memory:0, vCores:0>
2013-08-11 01:53:31,656 INFO org.apache.hadoop.yarn.server.resourcemanager.scheduler.capacity.LeafQueue: completedContainer container=Container: [ContainerId: container_1376185025835_0005_01_000001, NodeId: hadoop-321-2:46202, NodeHttpAddress: hadoop-321-2:8042, Resource: <memory:2048, vCores:1>, Priority: 0, State: NEW, Token: null, Status: container_id {, app_attempt_id {, application_id {, id: 5, cluster_timestamp: 1376185025835, }, attemptId: 1, }, id: 1, }, state: C_COMPLETE, diagnostics: "", exit_status: 0, ] resource=<memory:2048, vCores:1> queue=default: capacity=1.0, absoluteCapacity=1.0, usedResources=<memory:0, vCores:0>usedCapacity=0.0, absoluteUsedCapacity=0.0, numApps=1, numContainers=0 usedCapacity=0.0 absoluteUsedCapacity=0.0 used=<memory:0, vCores:0> cluster=<memory:49152, vCores:96>
2013-08-11 01:53:31,656 INFO org.apache.hadoop.yarn.server.resourcemanager.scheduler.capacity.ParentQueue: completedContainer queue=root usedCapacity=0.0 absoluteUsedCapacity=0.0 used=<memory:0, vCores:0> cluster=<memory:49152, vCores:96>
2013-08-11 01:53:31,656 INFO org.apache.hadoop.yarn.server.resourcemanager.scheduler.capacity.CapacityScheduler: Application appattempt_1376185025835_0005_000001 released container container_1376185025835_0005_01_000001 on node: host: hadoop-321-2:46202 #containers=0 available=8192 used=0 with event: FINISHED
2013-08-11 01:53:31,656 INFO org.apache.hadoop.yarn.server.resourcemanager.rmapp.attempt.RMAppAttemptImpl: appattempt_1376185025835_0005_000001 State change from FINISHING to FINISHED
2013-08-11 01:53:31,656 INFO org.apache.hadoop.yarn.server.resourcemanager.rmapp.RMAppImpl: application_1376185025835_0005 State change from FINISHING to FINISHED
2013-08-11 01:53:31,656 INFO org.apache.hadoop.yarn.server.resourcemanager.scheduler.capacity.CapacityScheduler: Application appattempt_1376185025835_0005_000001 is done. finalState=FINISHED
2013-08-11 01:53:31,657 INFO org.apache.hadoop.yarn.server.resourcemanager.scheduler.AppSchedulingInfo: Application application_1376185025835_0005 requests cleared
2013-08-11 01:53:31,657 INFO org.apache.hadoop.yarn.server.resourcemanager.scheduler.capacity.LeafQueue: Application removed - appId: application_1376185025835_0005 user: ubuntu queue: default #user-pending-applications: 0 #user-active-applications: 0 #queue-pending-applications: 0 #queue-active-applications: 0
2013-08-11 01:53:31,657 INFO org.apache.hadoop.yarn.server.resourcemanager.scheduler.capacity.ParentQueue: Application removed - appId: application_1376185025835_0005 user: ubuntu leaf-queue of parent: root #applications: 0
2013-08-11 01:53:31,657 INFO org.apache.hadoop.yarn.server.resourcemanager.RMAuditLogger: USER=ubuntu	OPERATION=Application Finished - Succeeded	TARGET=RMAppManager	RESULT=SUCCESS	APPID=application_1376185025835_0005
2013-08-11 01:53:31,657 INFO org.apache.hadoop.yarn.server.resourcemanager.recovery.RMStateStore: Removing info for app: application_1376185025835_0005
2013-08-11 01:53:31,657 INFO org.apache.hadoop.yarn.server.resourcemanager.amlauncher.AMLauncher: Cleaning master appattempt_1376185025835_0005_000001
2013-08-11 01:53:31,657 INFO org.apache.hadoop.yarn.server.resourcemanager.RMAppManager$ApplicationSummary: appId=application_1376185025835_0005,name=TeraGen,user=ubuntu,queue=default,state=FINISHED,trackingUrl=hadoop-321-1.novalocal:8088/proxy/application_1376185025835_0005/jobhistory/job/job_1376185025835_0005,appMasterHost=hadoop-321-2,startTime=1376185822619,finishTime=1376186010879
2013-08-11 01:53:37,463 INFO org.apache.hadoop.yarn.server.resourcemanager.ClientRMService: Allocated new applicationId: 6
2013-08-11 01:53:37,473 INFO org.apache.hadoop.yarn.server.resourcemanager.ClientRMService: Allocated new applicationId: 7
2013-08-11 01:53:37,599 INFO org.apache.hadoop.yarn.server.resourcemanager.ClientRMService: Allocated new applicationId: 8
2013-08-11 01:53:38,519 INFO org.apache.hadoop.yarn.server.resourcemanager.ClientRMService: Allocated new applicationId: 9
2013-08-11 01:53:38,611 INFO org.apache.hadoop.yarn.server.resourcemanager.ClientRMService: Allocated new applicationId: 10
2013-08-11 01:53:39,199 INFO org.apache.hadoop.yarn.server.resourcemanager.ClientRMService: Storing Application with id application_1376185025835_0006
2013-08-11 01:53:39,199 INFO org.apache.hadoop.yarn.server.resourcemanager.recovery.RMStateStore: Storing info for app: application_1376185025835_0006
2013-08-11 01:53:39,199 INFO org.apache.hadoop.yarn.server.resourcemanager.ClientRMService: Application with id 6 submitted by user ubuntu
2013-08-11 01:53:39,199 INFO org.apache.hadoop.yarn.server.resourcemanager.RMAuditLogger: USER=ubuntu	IP=192.168.100.15	OPERATION=Submit Application Request	TARGET=ClientRMService	RESULT=SUCCESS	APPID=application_1376185025835_0006
2013-08-11 01:53:39,200 INFO org.apache.hadoop.yarn.server.resourcemanager.rmapp.RMAppImpl: application_1376185025835_0006 State change from NEW to SUBMITTED
2013-08-11 01:53:39,200 INFO org.apache.hadoop.yarn.server.resourcemanager.ApplicationMasterService: Registering appattempt_1376185025835_0006_000001
2013-08-11 01:53:39,200 INFO org.apache.hadoop.yarn.server.resourcemanager.rmapp.attempt.RMAppAttemptImpl: appattempt_1376185025835_0006_000001 State change from NEW to SUBMITTED
2013-08-11 01:53:39,200 INFO org.apache.hadoop.yarn.server.resourcemanager.scheduler.capacity.LeafQueue: Application application_1376185025835_0006 from user: ubuntu activated in queue: default
2013-08-11 01:53:39,200 INFO org.apache.hadoop.yarn.server.resourcemanager.scheduler.capacity.LeafQueue: Application added - appId: application_1376185025835_0006 user: org.apache.hadoop.yarn.server.resourcemanager.scheduler.capacity.LeafQueue$User@9fa52db, leaf-queue: default #user-pending-applications: 0 #user-active-applications: 1 #queue-pending-applications: 0 #queue-active-applications: 1
2013-08-11 01:53:39,200 INFO org.apache.hadoop.yarn.server.resourcemanager.scheduler.capacity.ParentQueue: Application added - appId: application_1376185025835_0006 user: ubuntu leaf-queue of parent: root #applications: 1
2013-08-11 01:53:39,200 INFO org.apache.hadoop.yarn.server.resourcemanager.scheduler.capacity.CapacityScheduler: Application Submission: appattempt_1376185025835_0006_000001, user: ubuntu queue: default: capacity=1.0, absoluteCapacity=1.0, usedResources=<memory:0, vCores:0>usedCapacity=0.0, absoluteUsedCapacity=0.0, numApps=1, numContainers=0, currently active: 1
2013-08-11 01:53:39,201 INFO org.apache.hadoop.yarn.server.resourcemanager.rmapp.attempt.RMAppAttemptImpl: appattempt_1376185025835_0006_000001 State change from SUBMITTED to SCHEDULED
2013-08-11 01:53:39,201 INFO org.apache.hadoop.yarn.server.resourcemanager.rmapp.RMAppImpl: application_1376185025835_0006 State change from SUBMITTED to ACCEPTED
2013-08-11 01:53:39,212 INFO org.apache.hadoop.yarn.server.resourcemanager.ClientRMService: Storing Application with id application_1376185025835_0008
2013-08-11 01:53:39,212 INFO org.apache.hadoop.yarn.server.resourcemanager.recovery.RMStateStore: Storing info for app: application_1376185025835_0008
2013-08-11 01:53:39,212 INFO org.apache.hadoop.yarn.server.resourcemanager.ClientRMService: Application with id 8 submitted by user ubuntu
2013-08-11 01:53:39,212 INFO org.apache.hadoop.yarn.server.resourcemanager.RMAuditLogger: USER=ubuntu	IP=192.168.100.15	OPERATION=Submit Application Request	TARGET=ClientRMService	RESULT=SUCCESS	APPID=application_1376185025835_0008
2013-08-11 01:53:39,214 INFO org.apache.hadoop.yarn.server.resourcemanager.rmapp.RMAppImpl: application_1376185025835_0008 State change from NEW to SUBMITTED
2013-08-11 01:53:39,214 INFO org.apache.hadoop.yarn.server.resourcemanager.ApplicationMasterService: Registering appattempt_1376185025835_0008_000001
2013-08-11 01:53:39,216 INFO org.apache.hadoop.yarn.server.resourcemanager.rmapp.attempt.RMAppAttemptImpl: appattempt_1376185025835_0008_000001 State change from NEW to SUBMITTED
2013-08-11 01:53:39,216 INFO org.apache.hadoop.yarn.server.resourcemanager.ClientRMService: Storing Application with id application_1376185025835_0007
2013-08-11 01:53:39,216 INFO org.apache.hadoop.yarn.server.resourcemanager.recovery.RMStateStore: Storing info for app: application_1376185025835_0007
2013-08-11 01:53:39,216 INFO org.apache.hadoop.yarn.server.resourcemanager.ClientRMService: Application with id 7 submitted by user ubuntu
2013-08-11 01:53:39,216 INFO org.apache.hadoop.yarn.server.resourcemanager.RMAuditLogger: USER=ubuntu	IP=192.168.100.15	OPERATION=Submit Application Request	TARGET=ClientRMService	RESULT=SUCCESS	APPID=application_1376185025835_0007
2013-08-11 01:53:39,216 INFO org.apache.hadoop.yarn.server.resourcemanager.scheduler.capacity.LeafQueue: Application application_1376185025835_0008 from user: ubuntu activated in queue: default
2013-08-11 01:53:39,216 INFO org.apache.hadoop.yarn.server.resourcemanager.scheduler.capacity.LeafQueue: Application added - appId: application_1376185025835_0008 user: org.apache.hadoop.yarn.server.resourcemanager.scheduler.capacity.LeafQueue$User@9fa52db, leaf-queue: default #user-pending-applications: 0 #user-active-applications: 2 #queue-pending-applications: 0 #queue-active-applications: 2
2013-08-11 01:53:39,216 INFO org.apache.hadoop.yarn.server.resourcemanager.scheduler.capacity.ParentQueue: Application added - appId: application_1376185025835_0008 user: ubuntu leaf-queue of parent: root #applications: 2
2013-08-11 01:53:39,216 INFO org.apache.hadoop.yarn.server.resourcemanager.scheduler.capacity.CapacityScheduler: Application Submission: appattempt_1376185025835_0008_000001, user: ubuntu queue: default: capacity=1.0, absoluteCapacity=1.0, usedResources=<memory:0, vCores:0>usedCapacity=0.0, absoluteUsedCapacity=0.0, numApps=2, numContainers=0, currently active: 2
2013-08-11 01:53:39,217 INFO org.apache.hadoop.yarn.server.resourcemanager.rmapp.RMAppImpl: application_1376185025835_0007 State change from NEW to SUBMITTED
2013-08-11 01:53:39,217 INFO org.apache.hadoop.yarn.server.resourcemanager.rmapp.attempt.RMAppAttemptImpl: appattempt_1376185025835_0008_000001 State change from SUBMITTED to SCHEDULED
2013-08-11 01:53:39,217 INFO org.apache.hadoop.yarn.server.resourcemanager.ApplicationMasterService: Registering appattempt_1376185025835_0007_000001
2013-08-11 01:53:39,217 INFO org.apache.hadoop.yarn.server.resourcemanager.rmapp.attempt.RMAppAttemptImpl: appattempt_1376185025835_0007_000001 State change from NEW to SUBMITTED
2013-08-11 01:53:39,218 INFO org.apache.hadoop.yarn.server.resourcemanager.rmapp.RMAppImpl: application_1376185025835_0008 State change from SUBMITTED to ACCEPTED
2013-08-11 01:53:39,218 INFO org.apache.hadoop.yarn.server.resourcemanager.scheduler.capacity.LeafQueue: Application application_1376185025835_0007 from user: ubuntu activated in queue: default
2013-08-11 01:53:39,218 INFO org.apache.hadoop.yarn.server.resourcemanager.scheduler.capacity.LeafQueue: Application added - appId: application_1376185025835_0007 user: org.apache.hadoop.yarn.server.resourcemanager.scheduler.capacity.LeafQueue$User@9fa52db, leaf-queue: default #user-pending-applications: 0 #user-active-applications: 3 #queue-pending-applications: 0 #queue-active-applications: 3
2013-08-11 01:53:39,219 INFO org.apache.hadoop.yarn.server.resourcemanager.scheduler.capacity.ParentQueue: Application added - appId: application_1376185025835_0007 user: ubuntu leaf-queue of parent: root #applications: 3
2013-08-11 01:53:39,219 INFO org.apache.hadoop.yarn.server.resourcemanager.scheduler.capacity.CapacityScheduler: Application Submission: appattempt_1376185025835_0007_000001, user: ubuntu queue: default: capacity=1.0, absoluteCapacity=1.0, usedResources=<memory:0, vCores:0>usedCapacity=0.0, absoluteUsedCapacity=0.0, numApps=3, numContainers=0, currently active: 3
2013-08-11 01:53:39,220 INFO org.apache.hadoop.yarn.server.resourcemanager.rmapp.attempt.RMAppAttemptImpl: appattempt_1376185025835_0007_000001 State change from SUBMITTED to SCHEDULED
2013-08-11 01:53:39,220 INFO org.apache.hadoop.yarn.server.resourcemanager.rmapp.RMAppImpl: application_1376185025835_0007 State change from SUBMITTED to ACCEPTED
2013-08-11 01:53:39,696 INFO org.apache.hadoop.yarn.server.resourcemanager.rmcontainer.RMContainerImpl: container_1376185025835_0006_01_000001 Container Transitioned from NEW to ALLOCATED
2013-08-11 01:53:39,696 INFO org.apache.hadoop.yarn.server.resourcemanager.RMAuditLogger: USER=ubuntu	OPERATION=AM Allocated Container	TARGET=SchedulerApp	RESULT=SUCCESS	APPID=application_1376185025835_0006	CONTAINERID=container_1376185025835_0006_01_000001
2013-08-11 01:53:39,696 INFO org.apache.hadoop.yarn.server.resourcemanager.scheduler.common.fica.FiCaSchedulerNode: Assigned container container_1376185025835_0006_01_000001 of capacity <memory:2048, vCores:1> on host hadoop-321-2:46202, which currently has 1 containers, <memory:2048, vCores:1> used and <memory:6144, vCores:15> available
2013-08-11 01:53:39,696 INFO org.apache.hadoop.yarn.server.resourcemanager.scheduler.capacity.LeafQueue: assignedContainer application=application_1376185025835_0006 container=Container: [ContainerId: container_1376185025835_0006_01_000001, NodeId: hadoop-321-2:46202, NodeHttpAddress: hadoop-321-2:8042, Resource: <memory:2048, vCores:1>, Priority: 0, State: NEW, Token: null, Status: container_id {, app_attempt_id {, application_id {, id: 6, cluster_timestamp: 1376185025835, }, attemptId: 1, }, id: 1, }, state: C_NEW, ] containerId=container_1376185025835_0006_01_000001 queue=default: capacity=1.0, absoluteCapacity=1.0, usedResources=<memory:0, vCores:0>usedCapacity=0.0, absoluteUsedCapacity=0.0, numApps=3, numContainers=0 usedCapacity=0.0 absoluteUsedCapacity=0.0 used=<memory:0, vCores:0> cluster=<memory:49152, vCores:96>
2013-08-11 01:53:39,697 INFO org.apache.hadoop.yarn.server.resourcemanager.scheduler.capacity.ParentQueue: Re-sorting queues since queue: root.default stats: default: capacity=1.0, absoluteCapacity=1.0, usedResources=<memory:2048, vCores:1>usedCapacity=0.041666668, absoluteUsedCapacity=0.041666668, numApps=3, numContainers=1
2013-08-11 01:53:39,697 INFO org.apache.hadoop.yarn.server.resourcemanager.scheduler.capacity.ParentQueue: assignedContainer queue=root usedCapacity=0.041666668 absoluteUsedCapacity=0.041666668 used=<memory:2048, vCores:1> cluster=<memory:49152, vCores:96>
2013-08-11 01:53:39,704 INFO org.apache.hadoop.yarn.server.resourcemanager.rmcontainer.RMContainerImpl: container_1376185025835_0006_01_000001 Container Transitioned from ALLOCATED to ACQUIRED
2013-08-11 01:53:39,705 INFO org.apache.hadoop.yarn.server.resourcemanager.rmapp.attempt.RMAppAttemptImpl: Storing attempt: AppId: application_1376185025835_0006 AttemptId: appattempt_1376185025835_0006_000001 MasterContainer: Container: [ContainerId: container_1376185025835_0006_01_000001, NodeId: hadoop-321-2:46202, NodeHttpAddress: hadoop-321-2:8042, Resource: <memory:2048, vCores:1>, Priority: 0, State: NEW, Token: null, Status: container_id {, app_attempt_id {, application_id {, id: 6, cluster_timestamp: 1376185025835, }, attemptId: 1, }, id: 1, }, state: C_NEW, ]
2013-08-11 01:53:39,705 INFO org.apache.hadoop.yarn.server.resourcemanager.rmapp.attempt.RMAppAttemptImpl: appattempt_1376185025835_0006_000001 State change from SCHEDULED to ALLOCATED_SAVING
2013-08-11 01:53:39,705 INFO org.apache.hadoop.yarn.server.resourcemanager.recovery.RMStateStore: Storing info for attempt: appattempt_1376185025835_0006_000001
2013-08-11 01:53:39,705 INFO org.apache.hadoop.yarn.server.resourcemanager.rmapp.attempt.RMAppAttemptImpl: appattempt_1376185025835_0006_000001 State change from ALLOCATED_SAVING to ALLOCATED
2013-08-11 01:53:39,706 INFO org.apache.hadoop.yarn.server.resourcemanager.amlauncher.AMLauncher: Launching masterappattempt_1376185025835_0006_000001
2013-08-11 01:53:39,707 INFO org.apache.hadoop.yarn.server.resourcemanager.amlauncher.AMLauncher: Setting up container Container: [ContainerId: container_1376185025835_0006_01_000001, NodeId: hadoop-321-2:46202, NodeHttpAddress: hadoop-321-2:8042, Resource: <memory:2048, vCores:1>, Priority: 0, State: NEW, Token: null, Status: container_id {, app_attempt_id {, application_id {, id: 6, cluster_timestamp: 1376185025835, }, attemptId: 1, }, id: 1, }, state: C_NEW, ] for AM appattempt_1376185025835_0006_000001
2013-08-11 01:53:39,707 INFO org.apache.hadoop.yarn.server.resourcemanager.amlauncher.AMLauncher: Command to launch container container_1376185025835_0006_01_000001 : $JAVA_HOME/bin/java -Dlog4j.configuration=container-log4j.properties -Dyarn.app.mapreduce.container.log.dir=<LOG_DIR> -Dyarn.app.mapreduce.container.log.filesize=0 -Dhadoop.root.logger=INFO,CLA  -Xmx1024m org.apache.hadoop.mapreduce.v2.app.MRAppMaster 1><LOG_DIR>/stdout 2><LOG_DIR>/stderr 
2013-08-11 01:53:39,718 INFO org.apache.hadoop.yarn.server.resourcemanager.amlauncher.AMLauncher: Done launching container Container: [ContainerId: container_1376185025835_0006_01_000001, NodeId: hadoop-321-2:46202, NodeHttpAddress: hadoop-321-2:8042, Resource: <memory:2048, vCores:1>, Priority: 0, State: NEW, Token: null, Status: container_id {, app_attempt_id {, application_id {, id: 6, cluster_timestamp: 1376185025835, }, attemptId: 1, }, id: 1, }, state: C_NEW, ] for AM appattempt_1376185025835_0006_000001
2013-08-11 01:53:39,718 INFO org.apache.hadoop.yarn.server.resourcemanager.rmapp.attempt.RMAppAttemptImpl: appattempt_1376185025835_0006_000001 State change from ALLOCATED to LAUNCHED
2013-08-11 01:53:39,775 INFO org.apache.hadoop.yarn.server.resourcemanager.rmcontainer.RMContainerImpl: container_1376185025835_0007_01_000001 Container Transitioned from NEW to ALLOCATED
2013-08-11 01:53:39,785 INFO org.apache.hadoop.yarn.server.resourcemanager.RMAuditLogger: USER=ubuntu	OPERATION=AM Allocated Container	TARGET=SchedulerApp	RESULT=SUCCESS	APPID=application_1376185025835_0007	CONTAINERID=container_1376185025835_0007_01_000001
2013-08-11 01:53:39,785 INFO org.apache.hadoop.yarn.server.resourcemanager.scheduler.common.fica.FiCaSchedulerNode: Assigned container container_1376185025835_0007_01_000001 of capacity <memory:2048, vCores:1> on host hadoop-321-3:44876, which currently has 1 containers, <memory:2048, vCores:1> used and <memory:6144, vCores:15> available
2013-08-11 01:53:39,786 INFO org.apache.hadoop.yarn.server.resourcemanager.scheduler.capacity.LeafQueue: assignedContainer application=application_1376185025835_0007 container=Container: [ContainerId: container_1376185025835_0007_01_000001, NodeId: hadoop-321-3:44876, NodeHttpAddress: hadoop-321-3:8042, Resource: <memory:2048, vCores:1>, Priority: 0, State: NEW, Token: null, Status: container_id {, app_attempt_id {, application_id {, id: 7, cluster_timestamp: 1376185025835, }, attemptId: 1, }, id: 1, }, state: C_NEW, ] containerId=container_1376185025835_0007_01_000001 queue=default: capacity=1.0, absoluteCapacity=1.0, usedResources=<memory:2048, vCores:1>usedCapacity=0.041666668, absoluteUsedCapacity=0.041666668, numApps=3, numContainers=1 usedCapacity=0.041666668 absoluteUsedCapacity=0.041666668 used=<memory:2048, vCores:1> cluster=<memory:49152, vCores:96>
2013-08-11 01:53:39,787 INFO org.apache.hadoop.yarn.server.resourcemanager.scheduler.capacity.ParentQueue: Re-sorting queues since queue: root.default stats: default: capacity=1.0, absoluteCapacity=1.0, usedResources=<memory:4096, vCores:2>usedCapacity=0.083333336, absoluteUsedCapacity=0.083333336, numApps=3, numContainers=2
2013-08-11 01:53:39,787 INFO org.apache.hadoop.yarn.server.resourcemanager.scheduler.capacity.ParentQueue: assignedContainer queue=root usedCapacity=0.083333336 absoluteUsedCapacity=0.083333336 used=<memory:4096, vCores:2> cluster=<memory:49152, vCores:96>
2013-08-11 01:53:39,787 INFO org.apache.hadoop.yarn.server.resourcemanager.rmcontainer.RMContainerImpl: container_1376185025835_0007_01_000001 Container Transitioned from ALLOCATED to ACQUIRED
2013-08-11 01:53:39,788 INFO org.apache.hadoop.yarn.server.resourcemanager.rmapp.attempt.RMAppAttemptImpl: Storing attempt: AppId: application_1376185025835_0007 AttemptId: appattempt_1376185025835_0007_000001 MasterContainer: Container: [ContainerId: container_1376185025835_0007_01_000001, NodeId: hadoop-321-3:44876, NodeHttpAddress: hadoop-321-3:8042, Resource: <memory:2048, vCores:1>, Priority: 0, State: NEW, Token: null, Status: container_id {, app_attempt_id {, application_id {, id: 7, cluster_timestamp: 1376185025835, }, attemptId: 1, }, id: 1, }, state: C_NEW, ]
2013-08-11 01:53:39,788 INFO org.apache.hadoop.yarn.server.resourcemanager.recovery.RMStateStore: Storing info for attempt: appattempt_1376185025835_0007_000001
2013-08-11 01:53:39,788 INFO org.apache.hadoop.yarn.server.resourcemanager.rmapp.attempt.RMAppAttemptImpl: appattempt_1376185025835_0007_000001 State change from SCHEDULED to ALLOCATED_SAVING
2013-08-11 01:53:39,789 INFO org.apache.hadoop.yarn.server.resourcemanager.rmapp.attempt.RMAppAttemptImpl: appattempt_1376185025835_0007_000001 State change from ALLOCATED_SAVING to ALLOCATED
2013-08-11 01:53:39,789 INFO org.apache.hadoop.yarn.server.resourcemanager.rmcontainer.RMContainerImpl: container_1376185025835_0008_01_000001 Container Transitioned from NEW to ALLOCATED
2013-08-11 01:53:39,789 INFO org.apache.hadoop.yarn.server.resourcemanager.RMAuditLogger: USER=ubuntu	OPERATION=AM Allocated Container	TARGET=SchedulerApp	RESULT=SUCCESS	APPID=application_1376185025835_0008	CONTAINERID=container_1376185025835_0008_01_000001
2013-08-11 01:53:39,789 INFO org.apache.hadoop.yarn.server.resourcemanager.scheduler.common.fica.FiCaSchedulerNode: Assigned container container_1376185025835_0008_01_000001 of capacity <memory:2048, vCores:1> on host hadoop-321-6:34867, which currently has 1 containers, <memory:2048, vCores:1> used and <memory:6144, vCores:15> available
2013-08-11 01:53:39,790 INFO org.apache.hadoop.yarn.server.resourcemanager.scheduler.capacity.LeafQueue: assignedContainer application=application_1376185025835_0008 container=Container: [ContainerId: container_1376185025835_0008_01_000001, NodeId: hadoop-321-6:34867, NodeHttpAddress: hadoop-321-6:8042, Resource: <memory:2048, vCores:1>, Priority: 0, State: NEW, Token: null, Status: container_id {, app_attempt_id {, application_id {, id: 8, cluster_timestamp: 1376185025835, }, attemptId: 1, }, id: 1, }, state: C_NEW, ] containerId=container_1376185025835_0008_01_000001 queue=default: capacity=1.0, absoluteCapacity=1.0, usedResources=<memory:4096, vCores:2>usedCapacity=0.083333336, absoluteUsedCapacity=0.083333336, numApps=3, numContainers=2 usedCapacity=0.083333336 absoluteUsedCapacity=0.083333336 used=<memory:4096, vCores:2> cluster=<memory:49152, vCores:96>
2013-08-11 01:53:39,790 INFO org.apache.hadoop.yarn.server.resourcemanager.scheduler.capacity.ParentQueue: Re-sorting queues since queue: root.default stats: default: capacity=1.0, absoluteCapacity=1.0, usedResources=<memory:6144, vCores:3>usedCapacity=0.125, absoluteUsedCapacity=0.125, numApps=3, numContainers=3
2013-08-11 01:53:39,790 INFO org.apache.hadoop.yarn.server.resourcemanager.scheduler.capacity.ParentQueue: assignedContainer queue=root usedCapacity=0.125 absoluteUsedCapacity=0.125 used=<memory:6144, vCores:3> cluster=<memory:49152, vCores:96>
2013-08-11 01:53:39,790 INFO org.apache.hadoop.yarn.server.resourcemanager.amlauncher.AMLauncher: Launching masterappattempt_1376185025835_0007_000001
2013-08-11 01:53:39,794 INFO org.apache.hadoop.yarn.server.resourcemanager.rmcontainer.RMContainerImpl: container_1376185025835_0008_01_000001 Container Transitioned from ALLOCATED to ACQUIRED
2013-08-11 01:53:39,794 INFO org.apache.hadoop.yarn.server.resourcemanager.amlauncher.AMLauncher: Setting up container Container: [ContainerId: container_1376185025835_0007_01_000001, NodeId: hadoop-321-3:44876, NodeHttpAddress: hadoop-321-3:8042, Resource: <memory:2048, vCores:1>, Priority: 0, State: NEW, Token: null, Status: container_id {, app_attempt_id {, application_id {, id: 7, cluster_timestamp: 1376185025835, }, attemptId: 1, }, id: 1, }, state: C_NEW, ] for AM appattempt_1376185025835_0007_000001
2013-08-11 01:53:39,794 INFO org.apache.hadoop.yarn.server.resourcemanager.amlauncher.AMLauncher: Command to launch container container_1376185025835_0007_01_000001 : $JAVA_HOME/bin/java -Dlog4j.configuration=container-log4j.properties -Dyarn.app.mapreduce.container.log.dir=<LOG_DIR> -Dyarn.app.mapreduce.container.log.filesize=0 -Dhadoop.root.logger=INFO,CLA  -Xmx1024m org.apache.hadoop.mapreduce.v2.app.MRAppMaster 1><LOG_DIR>/stdout 2><LOG_DIR>/stderr 
2013-08-11 01:53:39,794 INFO org.apache.hadoop.yarn.server.resourcemanager.rmapp.attempt.RMAppAttemptImpl: Storing attempt: AppId: application_1376185025835_0008 AttemptId: appattempt_1376185025835_0008_000001 MasterContainer: Container: [ContainerId: container_1376185025835_0008_01_000001, NodeId: hadoop-321-6:34867, NodeHttpAddress: hadoop-321-6:8042, Resource: <memory:2048, vCores:1>, Priority: 0, State: NEW, Token: null, Status: container_id {, app_attempt_id {, application_id {, id: 8, cluster_timestamp: 1376185025835, }, attemptId: 1, }, id: 1, }, state: C_NEW, ]
2013-08-11 01:53:39,796 INFO org.apache.hadoop.yarn.server.resourcemanager.recovery.RMStateStore: Storing info for attempt: appattempt_1376185025835_0008_000001
2013-08-11 01:53:39,797 INFO org.apache.hadoop.yarn.server.resourcemanager.rmapp.attempt.RMAppAttemptImpl: appattempt_1376185025835_0008_000001 State change from SCHEDULED to ALLOCATED_SAVING
2013-08-11 01:53:39,806 INFO org.apache.hadoop.yarn.server.resourcemanager.rmapp.attempt.RMAppAttemptImpl: appattempt_1376185025835_0008_000001 State change from ALLOCATED_SAVING to ALLOCATED
2013-08-11 01:53:39,806 INFO org.apache.hadoop.yarn.server.resourcemanager.amlauncher.AMLauncher: Launching masterappattempt_1376185025835_0008_000001
2013-08-11 01:53:39,807 INFO org.apache.hadoop.yarn.server.resourcemanager.amlauncher.AMLauncher: Setting up container Container: [ContainerId: container_1376185025835_0008_01_000001, NodeId: hadoop-321-6:34867, NodeHttpAddress: hadoop-321-6:8042, Resource: <memory:2048, vCores:1>, Priority: 0, State: NEW, Token: null, Status: container_id {, app_attempt_id {, application_id {, id: 8, cluster_timestamp: 1376185025835, }, attemptId: 1, }, id: 1, }, state: C_NEW, ] for AM appattempt_1376185025835_0008_000001
2013-08-11 01:53:39,807 INFO org.apache.hadoop.yarn.server.resourcemanager.amlauncher.AMLauncher: Command to launch container container_1376185025835_0008_01_000001 : $JAVA_HOME/bin/java -Dlog4j.configuration=container-log4j.properties -Dyarn.app.mapreduce.container.log.dir=<LOG_DIR> -Dyarn.app.mapreduce.container.log.filesize=0 -Dhadoop.root.logger=INFO,CLA  -Xmx1024m org.apache.hadoop.mapreduce.v2.app.MRAppMaster 1><LOG_DIR>/stdout 2><LOG_DIR>/stderr 
2013-08-11 01:53:39,813 INFO org.apache.hadoop.yarn.server.resourcemanager.amlauncher.AMLauncher: Done launching container Container: [ContainerId: container_1376185025835_0007_01_000001, NodeId: hadoop-321-3:44876, NodeHttpAddress: hadoop-321-3:8042, Resource: <memory:2048, vCores:1>, Priority: 0, State: NEW, Token: null, Status: container_id {, app_attempt_id {, application_id {, id: 7, cluster_timestamp: 1376185025835, }, attemptId: 1, }, id: 1, }, state: C_NEW, ] for AM appattempt_1376185025835_0007_000001
2013-08-11 01:53:39,813 INFO org.apache.hadoop.yarn.server.resourcemanager.rmapp.attempt.RMAppAttemptImpl: appattempt_1376185025835_0007_000001 State change from ALLOCATED to LAUNCHED
2013-08-11 01:53:39,819 INFO org.apache.hadoop.yarn.server.resourcemanager.amlauncher.AMLauncher: Done launching container Container: [ContainerId: container_1376185025835_0008_01_000001, NodeId: hadoop-321-6:34867, NodeHttpAddress: hadoop-321-6:8042, Resource: <memory:2048, vCores:1>, Priority: 0, State: NEW, Token: null, Status: container_id {, app_attempt_id {, application_id {, id: 8, cluster_timestamp: 1376185025835, }, attemptId: 1, }, id: 1, }, state: C_NEW, ] for AM appattempt_1376185025835_0008_000001
2013-08-11 01:53:39,819 INFO org.apache.hadoop.yarn.server.resourcemanager.rmapp.attempt.RMAppAttemptImpl: appattempt_1376185025835_0008_000001 State change from ALLOCATED to LAUNCHED
2013-08-11 01:53:39,855 INFO org.apache.hadoop.yarn.server.resourcemanager.ClientRMService: Storing Application with id application_1376185025835_0009
2013-08-11 01:53:39,856 INFO org.apache.hadoop.yarn.server.resourcemanager.recovery.RMStateStore: Storing info for app: application_1376185025835_0009
2013-08-11 01:53:39,856 INFO org.apache.hadoop.yarn.server.resourcemanager.ClientRMService: Application with id 9 submitted by user ubuntu
2013-08-11 01:53:39,856 INFO org.apache.hadoop.yarn.server.resourcemanager.RMAuditLogger: USER=ubuntu	IP=192.168.100.15	OPERATION=Submit Application Request	TARGET=ClientRMService	RESULT=SUCCESS	APPID=application_1376185025835_0009
2013-08-11 01:53:39,855 INFO org.apache.hadoop.yarn.server.resourcemanager.rmapp.RMAppImpl: application_1376185025835_0009 State change from NEW to SUBMITTED
2013-08-11 01:53:39,856 INFO org.apache.hadoop.yarn.server.resourcemanager.ApplicationMasterService: Registering appattempt_1376185025835_0009_000001
2013-08-11 01:53:39,856 INFO org.apache.hadoop.yarn.server.resourcemanager.rmapp.attempt.RMAppAttemptImpl: appattempt_1376185025835_0009_000001 State change from NEW to SUBMITTED
2013-08-11 01:53:39,856 INFO org.apache.hadoop.yarn.server.resourcemanager.scheduler.capacity.LeafQueue: Application application_1376185025835_0009 from user: ubuntu activated in queue: default
2013-08-11 01:53:39,858 INFO org.apache.hadoop.yarn.server.resourcemanager.scheduler.capacity.LeafQueue: Application added - appId: application_1376185025835_0009 user: org.apache.hadoop.yarn.server.resourcemanager.scheduler.capacity.LeafQueue$User@9fa52db, leaf-queue: default #user-pending-applications: 0 #user-active-applications: 4 #queue-pending-applications: 0 #queue-active-applications: 4
2013-08-11 01:53:39,858 INFO org.apache.hadoop.yarn.server.resourcemanager.scheduler.capacity.ParentQueue: Application added - appId: application_1376185025835_0009 user: ubuntu leaf-queue of parent: root #applications: 4
2013-08-11 01:53:39,858 INFO org.apache.hadoop.yarn.server.resourcemanager.scheduler.capacity.CapacityScheduler: Application Submission: appattempt_1376185025835_0009_000001, user: ubuntu queue: default: capacity=1.0, absoluteCapacity=1.0, usedResources=<memory:6144, vCores:3>usedCapacity=0.125, absoluteUsedCapacity=0.125, numApps=4, numContainers=3, currently active: 4
2013-08-11 01:53:39,858 INFO org.apache.hadoop.yarn.server.resourcemanager.rmapp.attempt.RMAppAttemptImpl: appattempt_1376185025835_0009_000001 State change from SUBMITTED to SCHEDULED
2013-08-11 01:53:39,858 INFO org.apache.hadoop.yarn.server.resourcemanager.rmapp.RMAppImpl: application_1376185025835_0009 State change from SUBMITTED to ACCEPTED
2013-08-11 01:53:39,895 INFO org.apache.hadoop.yarn.server.resourcemanager.ClientRMService: Storing Application with id application_1376185025835_0010
2013-08-11 01:53:39,896 INFO org.apache.hadoop.yarn.server.resourcemanager.recovery.RMStateStore: Storing info for app: application_1376185025835_0010
2013-08-11 01:53:39,896 INFO org.apache.hadoop.yarn.server.resourcemanager.ClientRMService: Application with id 10 submitted by user ubuntu
2013-08-11 01:53:39,896 INFO org.apache.hadoop.yarn.server.resourcemanager.RMAuditLogger: USER=ubuntu	IP=192.168.100.15	OPERATION=Submit Application Request	TARGET=ClientRMService	RESULT=SUCCESS	APPID=application_1376185025835_0010
2013-08-11 01:53:39,896 INFO org.apache.hadoop.yarn.server.resourcemanager.rmapp.RMAppImpl: application_1376185025835_0010 State change from NEW to SUBMITTED
2013-08-11 01:53:39,898 INFO org.apache.hadoop.yarn.server.resourcemanager.ApplicationMasterService: Registering appattempt_1376185025835_0010_000001
2013-08-11 01:53:39,898 INFO org.apache.hadoop.yarn.server.resourcemanager.rmapp.attempt.RMAppAttemptImpl: appattempt_1376185025835_0010_000001 State change from NEW to SUBMITTED
2013-08-11 01:53:39,898 INFO org.apache.hadoop.yarn.server.resourcemanager.scheduler.capacity.LeafQueue: Application application_1376185025835_0010 from user: ubuntu activated in queue: default
2013-08-11 01:53:39,898 INFO org.apache.hadoop.yarn.server.resourcemanager.scheduler.capacity.LeafQueue: Application added - appId: application_1376185025835_0010 user: org.apache.hadoop.yarn.server.resourcemanager.scheduler.capacity.LeafQueue$User@9fa52db, leaf-queue: default #user-pending-applications: 0 #user-active-applications: 5 #queue-pending-applications: 0 #queue-active-applications: 5
2013-08-11 01:53:39,898 INFO org.apache.hadoop.yarn.server.resourcemanager.scheduler.capacity.ParentQueue: Application added - appId: application_1376185025835_0010 user: ubuntu leaf-queue of parent: root #applications: 5
2013-08-11 01:53:39,898 INFO org.apache.hadoop.yarn.server.resourcemanager.scheduler.capacity.CapacityScheduler: Application Submission: appattempt_1376185025835_0010_000001, user: ubuntu queue: default: capacity=1.0, absoluteCapacity=1.0, usedResources=<memory:6144, vCores:3>usedCapacity=0.125, absoluteUsedCapacity=0.125, numApps=5, numContainers=3, currently active: 5
2013-08-11 01:53:39,899 INFO org.apache.hadoop.yarn.server.resourcemanager.rmapp.attempt.RMAppAttemptImpl: appattempt_1376185025835_0010_000001 State change from SUBMITTED to SCHEDULED
2013-08-11 01:53:39,899 INFO org.apache.hadoop.yarn.server.resourcemanager.rmapp.RMAppImpl: application_1376185025835_0010 State change from SUBMITTED to ACCEPTED
2013-08-11 01:53:40,145 INFO org.apache.hadoop.yarn.server.resourcemanager.rmcontainer.RMContainerImpl: container_1376185025835_0009_01_000001 Container Transitioned from NEW to ALLOCATED
2013-08-11 01:53:40,145 INFO org.apache.hadoop.yarn.server.resourcemanager.RMAuditLogger: USER=ubuntu	OPERATION=AM Allocated Container	TARGET=SchedulerApp	RESULT=SUCCESS	APPID=application_1376185025835_0009	CONTAINERID=container_1376185025835_0009_01_000001
2013-08-11 01:53:40,145 INFO org.apache.hadoop.yarn.server.resourcemanager.scheduler.common.fica.FiCaSchedulerNode: Assigned container container_1376185025835_0009_01_000001 of capacity <memory:2048, vCores:1> on host hadoop-321-5:60845, which currently has 1 containers, <memory:2048, vCores:1> used and <memory:6144, vCores:15> available
2013-08-11 01:53:40,146 INFO org.apache.hadoop.yarn.server.resourcemanager.scheduler.capacity.LeafQueue: assignedContainer application=application_1376185025835_0009 container=Container: [ContainerId: container_1376185025835_0009_01_000001, NodeId: hadoop-321-5:60845, NodeHttpAddress: hadoop-321-5:8042, Resource: <memory:2048, vCores:1>, Priority: 0, State: NEW, Token: null, Status: container_id {, app_attempt_id {, application_id {, id: 9, cluster_timestamp: 1376185025835, }, attemptId: 1, }, id: 1, }, state: C_NEW, ] containerId=container_1376185025835_0009_01_000001 queue=default: capacity=1.0, absoluteCapacity=1.0, usedResources=<memory:6144, vCores:3>usedCapacity=0.125, absoluteUsedCapacity=0.125, numApps=5, numContainers=3 usedCapacity=0.125 absoluteUsedCapacity=0.125 used=<memory:6144, vCores:3> cluster=<memory:49152, vCores:96>
2013-08-11 01:53:40,146 INFO org.apache.hadoop.yarn.server.resourcemanager.scheduler.capacity.ParentQueue: Re-sorting queues since queue: root.default stats: default: capacity=1.0, absoluteCapacity=1.0, usedResources=<memory:8192, vCores:4>usedCapacity=0.16666667, absoluteUsedCapacity=0.16666667, numApps=5, numContainers=4
2013-08-11 01:53:40,146 INFO org.apache.hadoop.yarn.server.resourcemanager.scheduler.capacity.ParentQueue: assignedContainer queue=root usedCapacity=0.16666667 absoluteUsedCapacity=0.16666667 used=<memory:8192, vCores:4> cluster=<memory:49152, vCores:96>
2013-08-11 01:53:40,147 INFO org.apache.hadoop.yarn.server.resourcemanager.rmcontainer.RMContainerImpl: container_1376185025835_0009_01_000001 Container Transitioned from ALLOCATED to ACQUIRED
2013-08-11 01:53:40,148 INFO org.apache.hadoop.yarn.server.resourcemanager.rmapp.attempt.RMAppAttemptImpl: Storing attempt: AppId: application_1376185025835_0009 AttemptId: appattempt_1376185025835_0009_000001 MasterContainer: Container: [ContainerId: container_1376185025835_0009_01_000001, NodeId: hadoop-321-5:60845, NodeHttpAddress: hadoop-321-5:8042, Resource: <memory:2048, vCores:1>, Priority: 0, State: NEW, Token: null, Status: container_id {, app_attempt_id {, application_id {, id: 9, cluster_timestamp: 1376185025835, }, attemptId: 1, }, id: 1, }, state: C_NEW, ]
2013-08-11 01:53:40,148 INFO org.apache.hadoop.yarn.server.resourcemanager.rmapp.attempt.RMAppAttemptImpl: appattempt_1376185025835_0009_000001 State change from SCHEDULED to ALLOCATED_SAVING
2013-08-11 01:53:40,148 INFO org.apache.hadoop.yarn.server.resourcemanager.recovery.RMStateStore: Storing info for attempt: appattempt_1376185025835_0009_000001
2013-08-11 01:53:40,149 INFO org.apache.hadoop.yarn.server.resourcemanager.rmapp.attempt.RMAppAttemptImpl: appattempt_1376185025835_0009_000001 State change from ALLOCATED_SAVING to ALLOCATED
2013-08-11 01:53:40,149 INFO org.apache.hadoop.yarn.server.resourcemanager.amlauncher.AMLauncher: Launching masterappattempt_1376185025835_0009_000001
2013-08-11 01:53:40,151 INFO org.apache.hadoop.yarn.server.resourcemanager.amlauncher.AMLauncher: Setting up container Container: [ContainerId: container_1376185025835_0009_01_000001, NodeId: hadoop-321-5:60845, NodeHttpAddress: hadoop-321-5:8042, Resource: <memory:2048, vCores:1>, Priority: 0, State: NEW, Token: null, Status: container_id {, app_attempt_id {, application_id {, id: 9, cluster_timestamp: 1376185025835, }, attemptId: 1, }, id: 1, }, state: C_NEW, ] for AM appattempt_1376185025835_0009_000001
2013-08-11 01:53:40,151 INFO org.apache.hadoop.yarn.server.resourcemanager.amlauncher.AMLauncher: Command to launch container container_1376185025835_0009_01_000001 : $JAVA_HOME/bin/java -Dlog4j.configuration=container-log4j.properties -Dyarn.app.mapreduce.container.log.dir=<LOG_DIR> -Dyarn.app.mapreduce.container.log.filesize=0 -Dhadoop.root.logger=INFO,CLA  -Xmx1024m org.apache.hadoop.mapreduce.v2.app.MRAppMaster 1><LOG_DIR>/stdout 2><LOG_DIR>/stderr 
2013-08-11 01:53:40,155 INFO org.apache.hadoop.yarn.server.resourcemanager.rmcontainer.RMContainerImpl: container_1376185025835_0010_01_000001 Container Transitioned from NEW to ALLOCATED
2013-08-11 01:53:40,155 INFO org.apache.hadoop.yarn.server.resourcemanager.RMAuditLogger: USER=ubuntu	OPERATION=AM Allocated Container	TARGET=SchedulerApp	RESULT=SUCCESS	APPID=application_1376185025835_0010	CONTAINERID=container_1376185025835_0010_01_000001
2013-08-11 01:53:40,155 INFO org.apache.hadoop.yarn.server.resourcemanager.scheduler.common.fica.FiCaSchedulerNode: Assigned container container_1376185025835_0010_01_000001 of capacity <memory:2048, vCores:1> on host hadoop-321-4:43757, which currently has 1 containers, <memory:2048, vCores:1> used and <memory:6144, vCores:15> available
2013-08-11 01:53:40,156 INFO org.apache.hadoop.yarn.server.resourcemanager.scheduler.capacity.LeafQueue: assignedContainer application=application_1376185025835_0010 container=Container: [ContainerId: container_1376185025835_0010_01_000001, NodeId: hadoop-321-4:43757, NodeHttpAddress: hadoop-321-4:8042, Resource: <memory:2048, vCores:1>, Priority: 0, State: NEW, Token: null, Status: container_id {, app_attempt_id {, application_id {, id: 10, cluster_timestamp: 1376185025835, }, attemptId: 1, }, id: 1, }, state: C_NEW, ] containerId=container_1376185025835_0010_01_000001 queue=default: capacity=1.0, absoluteCapacity=1.0, usedResources=<memory:8192, vCores:4>usedCapacity=0.16666667, absoluteUsedCapacity=0.16666667, numApps=5, numContainers=4 usedCapacity=0.16666667 absoluteUsedCapacity=0.16666667 used=<memory:8192, vCores:4> cluster=<memory:49152, vCores:96>
2013-08-11 01:53:40,156 INFO org.apache.hadoop.yarn.server.resourcemanager.scheduler.capacity.ParentQueue: Re-sorting queues since queue: root.default stats: default: capacity=1.0, absoluteCapacity=1.0, usedResources=<memory:10240, vCores:5>usedCapacity=0.20833333, absoluteUsedCapacity=0.20833333, numApps=5, numContainers=5
2013-08-11 01:53:40,156 INFO org.apache.hadoop.yarn.server.resourcemanager.scheduler.capacity.ParentQueue: assignedContainer queue=root usedCapacity=0.20833333 absoluteUsedCapacity=0.20833333 used=<memory:10240, vCores:5> cluster=<memory:49152, vCores:96>
2013-08-11 01:53:40,157 INFO org.apache.hadoop.yarn.server.resourcemanager.rmcontainer.RMContainerImpl: container_1376185025835_0010_01_000001 Container Transitioned from ALLOCATED to ACQUIRED
2013-08-11 01:53:40,159 INFO org.apache.hadoop.yarn.server.resourcemanager.rmapp.attempt.RMAppAttemptImpl: Storing attempt: AppId: application_1376185025835_0010 AttemptId: appattempt_1376185025835_0010_000001 MasterContainer: Container: [ContainerId: container_1376185025835_0010_01_000001, NodeId: hadoop-321-4:43757, NodeHttpAddress: hadoop-321-4:8042, Resource: <memory:2048, vCores:1>, Priority: 0, State: NEW, Token: null, Status: container_id {, app_attempt_id {, application_id {, id: 10, cluster_timestamp: 1376185025835, }, attemptId: 1, }, id: 1, }, state: C_NEW, ]
2013-08-11 01:53:40,159 INFO org.apache.hadoop.yarn.server.resourcemanager.rmapp.attempt.RMAppAttemptImpl: appattempt_1376185025835_0010_000001 State change from SCHEDULED to ALLOCATED_SAVING
2013-08-11 01:53:40,159 INFO org.apache.hadoop.yarn.server.resourcemanager.recovery.RMStateStore: Storing info for attempt: appattempt_1376185025835_0010_000001
2013-08-11 01:53:40,160 INFO org.apache.hadoop.yarn.server.resourcemanager.rmapp.attempt.RMAppAttemptImpl: appattempt_1376185025835_0010_000001 State change from ALLOCATED_SAVING to ALLOCATED
2013-08-11 01:53:40,160 INFO org.apache.hadoop.yarn.server.resourcemanager.amlauncher.AMLauncher: Launching masterappattempt_1376185025835_0010_000001
2013-08-11 01:53:40,161 INFO org.apache.hadoop.yarn.server.resourcemanager.amlauncher.AMLauncher: Setting up container Container: [ContainerId: container_1376185025835_0010_01_000001, NodeId: hadoop-321-4:43757, NodeHttpAddress: hadoop-321-4:8042, Resource: <memory:2048, vCores:1>, Priority: 0, State: NEW, Token: null, Status: container_id {, app_attempt_id {, application_id {, id: 10, cluster_timestamp: 1376185025835, }, attemptId: 1, }, id: 1, }, state: C_NEW, ] for AM appattempt_1376185025835_0010_000001
2013-08-11 01:53:40,162 INFO org.apache.hadoop.yarn.server.resourcemanager.amlauncher.AMLauncher: Command to launch container container_1376185025835_0010_01_000001 : $JAVA_HOME/bin/java -Dlog4j.configuration=container-log4j.properties -Dyarn.app.mapreduce.container.log.dir=<LOG_DIR> -Dyarn.app.mapreduce.container.log.filesize=0 -Dhadoop.root.logger=INFO,CLA  -Xmx1024m org.apache.hadoop.mapreduce.v2.app.MRAppMaster 1><LOG_DIR>/stdout 2><LOG_DIR>/stderr 
2013-08-11 01:53:40,166 INFO org.apache.hadoop.yarn.server.resourcemanager.amlauncher.AMLauncher: Done launching container Container: [ContainerId: container_1376185025835_0009_01_000001, NodeId: hadoop-321-5:60845, NodeHttpAddress: hadoop-321-5:8042, Resource: <memory:2048, vCores:1>, Priority: 0, State: NEW, Token: null, Status: container_id {, app_attempt_id {, application_id {, id: 9, cluster_timestamp: 1376185025835, }, attemptId: 1, }, id: 1, }, state: C_NEW, ] for AM appattempt_1376185025835_0009_000001
2013-08-11 01:53:40,167 INFO org.apache.hadoop.yarn.server.resourcemanager.rmapp.attempt.RMAppAttemptImpl: appattempt_1376185025835_0009_000001 State change from ALLOCATED to LAUNCHED
2013-08-11 01:53:40,177 INFO org.apache.hadoop.yarn.server.resourcemanager.amlauncher.AMLauncher: Done launching container Container: [ContainerId: container_1376185025835_0010_01_000001, NodeId: hadoop-321-4:43757, NodeHttpAddress: hadoop-321-4:8042, Resource: <memory:2048, vCores:1>, Priority: 0, State: NEW, Token: null, Status: container_id {, app_attempt_id {, application_id {, id: 10, cluster_timestamp: 1376185025835, }, attemptId: 1, }, id: 1, }, state: C_NEW, ] for AM appattempt_1376185025835_0010_000001
2013-08-11 01:53:40,178 INFO org.apache.hadoop.yarn.server.resourcemanager.rmapp.attempt.RMAppAttemptImpl: appattempt_1376185025835_0010_000001 State change from ALLOCATED to LAUNCHED
2013-08-11 01:53:40,701 INFO org.apache.hadoop.yarn.server.resourcemanager.rmcontainer.RMContainerImpl: container_1376185025835_0006_01_000001 Container Transitioned from ACQUIRED to RUNNING
2013-08-11 01:53:40,780 INFO org.apache.hadoop.yarn.server.resourcemanager.rmcontainer.RMContainerImpl: container_1376185025835_0007_01_000001 Container Transitioned from ACQUIRED to RUNNING
2013-08-11 01:53:40,791 INFO org.apache.hadoop.yarn.server.resourcemanager.rmcontainer.RMContainerImpl: container_1376185025835_0008_01_000001 Container Transitioned from ACQUIRED to RUNNING
2013-08-11 01:53:41,151 INFO org.apache.hadoop.yarn.server.resourcemanager.rmcontainer.RMContainerImpl: container_1376185025835_0009_01_000001 Container Transitioned from ACQUIRED to RUNNING
2013-08-11 01:53:41,159 INFO org.apache.hadoop.yarn.server.resourcemanager.rmcontainer.RMContainerImpl: container_1376185025835_0010_01_000001 Container Transitioned from ACQUIRED to RUNNING
2013-08-11 01:53:45,415 INFO org.apache.hadoop.yarn.server.resourcemanager.ApplicationMasterService: AM registration appattempt_1376185025835_0006_000001
2013-08-11 01:53:45,415 INFO org.apache.hadoop.yarn.server.resourcemanager.RMAuditLogger: USER=ubuntu	IP=192.168.100.17	OPERATION=Register App Master	TARGET=ApplicationMasterService	RESULT=SUCCESS	APPID=application_1376185025835_0006	APPATTEMPTID=appattempt_1376185025835_0006_000001
2013-08-11 01:53:45,416 INFO org.apache.hadoop.yarn.server.resourcemanager.rmapp.attempt.RMAppAttemptImpl: appattempt_1376185025835_0006_000001 State change from LAUNCHED to RUNNING
2013-08-11 01:53:45,416 INFO org.apache.hadoop.yarn.server.resourcemanager.rmapp.RMAppImpl: application_1376185025835_0006 State change from ACCEPTED to RUNNING
2013-08-11 01:53:46,731 INFO org.apache.hadoop.yarn.server.resourcemanager.rmcontainer.RMContainerImpl: container_1376185025835_0006_01_000002 Container Transitioned from NEW to ALLOCATED
2013-08-11 01:53:46,731 INFO org.apache.hadoop.yarn.server.resourcemanager.RMAuditLogger: USER=ubuntu	OPERATION=AM Allocated Container	TARGET=SchedulerApp	RESULT=SUCCESS	APPID=application_1376185025835_0006	CONTAINERID=container_1376185025835_0006_01_000002
2013-08-11 01:53:46,732 INFO org.apache.hadoop.yarn.server.resourcemanager.scheduler.common.fica.FiCaSchedulerNode: Assigned container container_1376185025835_0006_01_000002 of capacity <memory:1024, vCores:1> on host hadoop-321-2:46202, which currently has 2 containers, <memory:3072, vCores:2> used and <memory:5120, vCores:14> available
2013-08-11 01:53:46,733 INFO org.apache.hadoop.yarn.server.resourcemanager.scheduler.capacity.LeafQueue: assignedContainer application=application_1376185025835_0006 container=Container: [ContainerId: container_1376185025835_0006_01_000002, NodeId: hadoop-321-2:46202, NodeHttpAddress: hadoop-321-2:8042, Resource: <memory:1024, vCores:1>, Priority: 20, State: NEW, Token: null, Status: container_id {, app_attempt_id {, application_id {, id: 6, cluster_timestamp: 1376185025835, }, attemptId: 1, }, id: 2, }, state: C_NEW, ] containerId=container_1376185025835_0006_01_000002 queue=default: capacity=1.0, absoluteCapacity=1.0, usedResources=<memory:10240, vCores:5>usedCapacity=0.20833333, absoluteUsedCapacity=0.20833333, numApps=5, numContainers=5 usedCapacity=0.20833333 absoluteUsedCapacity=0.20833333 used=<memory:10240, vCores:5> cluster=<memory:49152, vCores:96>
2013-08-11 01:53:46,733 INFO org.apache.hadoop.yarn.server.resourcemanager.scheduler.capacity.ParentQueue: Re-sorting queues since queue: root.default stats: default: capacity=1.0, absoluteCapacity=1.0, usedResources=<memory:11264, vCores:6>usedCapacity=0.22916667, absoluteUsedCapacity=0.22916667, numApps=5, numContainers=6
2013-08-11 01:53:46,733 INFO org.apache.hadoop.yarn.server.resourcemanager.scheduler.capacity.ParentQueue: assignedContainer queue=root usedCapacity=0.22916667 absoluteUsedCapacity=0.22916667 used=<memory:11264, vCores:6> cluster=<memory:49152, vCores:96>
2013-08-11 01:53:46,734 INFO org.apache.hadoop.yarn.server.resourcemanager.rmcontainer.RMContainerImpl: container_1376185025835_0006_01_000003 Container Transitioned from NEW to ALLOCATED
2013-08-11 01:53:46,734 INFO org.apache.hadoop.yarn.server.resourcemanager.RMAuditLogger: USER=ubuntu	OPERATION=AM Allocated Container	TARGET=SchedulerApp	RESULT=SUCCESS	APPID=application_1376185025835_0006	CONTAINERID=container_1376185025835_0006_01_000003
2013-08-11 01:53:46,734 INFO org.apache.hadoop.yarn.server.resourcemanager.scheduler.common.fica.FiCaSchedulerNode: Assigned container container_1376185025835_0006_01_000003 of capacity <memory:1024, vCores:1> on host hadoop-321-2:46202, which currently has 3 containers, <memory:4096, vCores:3> used and <memory:4096, vCores:13> available
2013-08-11 01:53:46,735 INFO org.apache.hadoop.yarn.server.resourcemanager.scheduler.capacity.LeafQueue: assignedContainer application=application_1376185025835_0006 container=Container: [ContainerId: container_1376185025835_0006_01_000003, NodeId: hadoop-321-2:46202, NodeHttpAddress: hadoop-321-2:8042, Resource: <memory:1024, vCores:1>, Priority: 20, State: NEW, Token: null, Status: container_id {, app_attempt_id {, application_id {, id: 6, cluster_timestamp: 1376185025835, }, attemptId: 1, }, id: 3, }, state: C_NEW, ] containerId=container_1376185025835_0006_01_000003 queue=default: capacity=1.0, absoluteCapacity=1.0, usedResources=<memory:11264, vCores:6>usedCapacity=0.22916667, absoluteUsedCapacity=0.22916667, numApps=5, numContainers=6 usedCapacity=0.22916667 absoluteUsedCapacity=0.22916667 used=<memory:11264, vCores:6> cluster=<memory:49152, vCores:96>
2013-08-11 01:53:46,735 INFO org.apache.hadoop.yarn.server.resourcemanager.scheduler.capacity.ParentQueue: Re-sorting queues since queue: root.default stats: default: capacity=1.0, absoluteCapacity=1.0, usedResources=<memory:12288, vCores:7>usedCapacity=0.25, absoluteUsedCapacity=0.25, numApps=5, numContainers=7
2013-08-11 01:53:46,736 INFO org.apache.hadoop.yarn.server.resourcemanager.scheduler.capacity.ParentQueue: assignedContainer queue=root usedCapacity=0.25 absoluteUsedCapacity=0.25 used=<memory:12288, vCores:7> cluster=<memory:49152, vCores:96>
2013-08-11 01:53:46,736 INFO org.apache.hadoop.yarn.server.resourcemanager.rmcontainer.RMContainerImpl: container_1376185025835_0006_01_000004 Container Transitioned from NEW to ALLOCATED
2013-08-11 01:53:46,736 INFO org.apache.hadoop.yarn.server.resourcemanager.RMAuditLogger: USER=ubuntu	OPERATION=AM Allocated Container	TARGET=SchedulerApp	RESULT=SUCCESS	APPID=application_1376185025835_0006	CONTAINERID=container_1376185025835_0006_01_000004
2013-08-11 01:53:46,736 INFO org.apache.hadoop.yarn.server.resourcemanager.scheduler.common.fica.FiCaSchedulerNode: Assigned container container_1376185025835_0006_01_000004 of capacity <memory:1024, vCores:1> on host hadoop-321-2:46202, which currently has 4 containers, <memory:5120, vCores:4> used and <memory:3072, vCores:12> available
2013-08-11 01:53:46,737 INFO org.apache.hadoop.yarn.server.resourcemanager.scheduler.capacity.LeafQueue: assignedContainer application=application_1376185025835_0006 container=Container: [ContainerId: container_1376185025835_0006_01_000004, NodeId: hadoop-321-2:46202, NodeHttpAddress: hadoop-321-2:8042, Resource: <memory:1024, vCores:1>, Priority: 20, State: NEW, Token: null, Status: container_id {, app_attempt_id {, application_id {, id: 6, cluster_timestamp: 1376185025835, }, attemptId: 1, }, id: 4, }, state: C_NEW, ] containerId=container_1376185025835_0006_01_000004 queue=default: capacity=1.0, absoluteCapacity=1.0, usedResources=<memory:12288, vCores:7>usedCapacity=0.25, absoluteUsedCapacity=0.25, numApps=5, numContainers=7 usedCapacity=0.25 absoluteUsedCapacity=0.25 used=<memory:12288, vCores:7> cluster=<memory:49152, vCores:96>
2013-08-11 01:53:46,737 INFO org.apache.hadoop.yarn.server.resourcemanager.scheduler.capacity.ParentQueue: Re-sorting queues since queue: root.default stats: default: capacity=1.0, absoluteCapacity=1.0, usedResources=<memory:13312, vCores:8>usedCapacity=0.27083334, absoluteUsedCapacity=0.27083334, numApps=5, numContainers=8
2013-08-11 01:53:46,738 INFO org.apache.hadoop.yarn.server.resourcemanager.scheduler.capacity.ParentQueue: assignedContainer queue=root usedCapacity=0.27083334 absoluteUsedCapacity=0.27083334 used=<memory:13312, vCores:8> cluster=<memory:49152, vCores:96>
2013-08-11 01:53:46,738 INFO org.apache.hadoop.yarn.server.resourcemanager.rmcontainer.RMContainerImpl: container_1376185025835_0006_01_000005 Container Transitioned from NEW to ALLOCATED
2013-08-11 01:53:46,738 INFO org.apache.hadoop.yarn.server.resourcemanager.RMAuditLogger: USER=ubuntu	OPERATION=AM Allocated Container	TARGET=SchedulerApp	RESULT=SUCCESS	APPID=application_1376185025835_0006	CONTAINERID=container_1376185025835_0006_01_000005
2013-08-11 01:53:46,738 INFO org.apache.hadoop.yarn.server.resourcemanager.scheduler.common.fica.FiCaSchedulerNode: Assigned container container_1376185025835_0006_01_000005 of capacity <memory:1024, vCores:1> on host hadoop-321-2:46202, which currently has 5 containers, <memory:6144, vCores:5> used and <memory:2048, vCores:11> available
2013-08-11 01:53:46,740 INFO org.apache.hadoop.yarn.server.resourcemanager.scheduler.capacity.LeafQueue: assignedContainer application=application_1376185025835_0006 container=Container: [ContainerId: container_1376185025835_0006_01_000005, NodeId: hadoop-321-2:46202, NodeHttpAddress: hadoop-321-2:8042, Resource: <memory:1024, vCores:1>, Priority: 20, State: NEW, Token: null, Status: container_id {, app_attempt_id {, application_id {, id: 6, cluster_timestamp: 1376185025835, }, attemptId: 1, }, id: 5, }, state: C_NEW, ] containerId=container_1376185025835_0006_01_000005 queue=default: capacity=1.0, absoluteCapacity=1.0, usedResources=<memory:13312, vCores:8>usedCapacity=0.27083334, absoluteUsedCapacity=0.27083334, numApps=5, numContainers=8 usedCapacity=0.27083334 absoluteUsedCapacity=0.27083334 used=<memory:13312, vCores:8> cluster=<memory:49152, vCores:96>
2013-08-11 01:53:46,740 INFO org.apache.hadoop.yarn.server.resourcemanager.scheduler.capacity.ParentQueue: Re-sorting queues since queue: root.default stats: default: capacity=1.0, absoluteCapacity=1.0, usedResources=<memory:14336, vCores:9>usedCapacity=0.29166666, absoluteUsedCapacity=0.29166666, numApps=5, numContainers=9
2013-08-11 01:53:46,740 INFO org.apache.hadoop.yarn.server.resourcemanager.scheduler.capacity.ParentQueue: assignedContainer queue=root usedCapacity=0.29166666 absoluteUsedCapacity=0.29166666 used=<memory:14336, vCores:9> cluster=<memory:49152, vCores:96>
2013-08-11 01:53:46,740 INFO org.apache.hadoop.yarn.server.resourcemanager.rmcontainer.RMContainerImpl: container_1376185025835_0006_01_000006 Container Transitioned from NEW to ALLOCATED
2013-08-11 01:53:46,740 INFO org.apache.hadoop.yarn.server.resourcemanager.RMAuditLogger: USER=ubuntu	OPERATION=AM Allocated Container	TARGET=SchedulerApp	RESULT=SUCCESS	APPID=application_1376185025835_0006	CONTAINERID=container_1376185025835_0006_01_000006
2013-08-11 01:53:46,741 INFO org.apache.hadoop.yarn.server.resourcemanager.scheduler.common.fica.FiCaSchedulerNode: Assigned container container_1376185025835_0006_01_000006 of capacity <memory:1024, vCores:1> on host hadoop-321-2:46202, which currently has 6 containers, <memory:7168, vCores:6> used and <memory:1024, vCores:10> available
2013-08-11 01:53:46,742 INFO org.apache.hadoop.yarn.server.resourcemanager.scheduler.capacity.LeafQueue: assignedContainer application=application_1376185025835_0006 container=Container: [ContainerId: container_1376185025835_0006_01_000006, NodeId: hadoop-321-2:46202, NodeHttpAddress: hadoop-321-2:8042, Resource: <memory:1024, vCores:1>, Priority: 20, State: NEW, Token: null, Status: container_id {, app_attempt_id {, application_id {, id: 6, cluster_timestamp: 1376185025835, }, attemptId: 1, }, id: 6, }, state: C_NEW, ] containerId=container_1376185025835_0006_01_000006 queue=default: capacity=1.0, absoluteCapacity=1.0, usedResources=<memory:14336, vCores:9>usedCapacity=0.29166666, absoluteUsedCapacity=0.29166666, numApps=5, numContainers=9 usedCapacity=0.29166666 absoluteUsedCapacity=0.29166666 used=<memory:14336, vCores:9> cluster=<memory:49152, vCores:96>
2013-08-11 01:53:46,742 INFO org.apache.hadoop.yarn.server.resourcemanager.scheduler.capacity.ParentQueue: Re-sorting queues since queue: root.default stats: default: capacity=1.0, absoluteCapacity=1.0, usedResources=<memory:15360, vCores:10>usedCapacity=0.3125, absoluteUsedCapacity=0.3125, numApps=5, numContainers=10
2013-08-11 01:53:46,742 INFO org.apache.hadoop.yarn.server.resourcemanager.scheduler.capacity.ParentQueue: assignedContainer queue=root usedCapacity=0.3125 absoluteUsedCapacity=0.3125 used=<memory:15360, vCores:10> cluster=<memory:49152, vCores:96>
2013-08-11 01:53:46,743 INFO org.apache.hadoop.yarn.server.resourcemanager.rmcontainer.RMContainerImpl: container_1376185025835_0006_01_000007 Container Transitioned from NEW to ALLOCATED
2013-08-11 01:53:46,743 INFO org.apache.hadoop.yarn.server.resourcemanager.RMAuditLogger: USER=ubuntu	OPERATION=AM Allocated Container	TARGET=SchedulerApp	RESULT=SUCCESS	APPID=application_1376185025835_0006	CONTAINERID=container_1376185025835_0006_01_000007
2013-08-11 01:53:46,743 INFO org.apache.hadoop.yarn.server.resourcemanager.scheduler.common.fica.FiCaSchedulerNode: Assigned container container_1376185025835_0006_01_000007 of capacity <memory:1024, vCores:1> on host hadoop-321-2:46202, which currently has 7 containers, <memory:8192, vCores:7> used and <memory:0, vCores:9> available
2013-08-11 01:53:46,744 INFO org.apache.hadoop.yarn.server.resourcemanager.scheduler.capacity.LeafQueue: assignedContainer application=application_1376185025835_0006 container=Container: [ContainerId: container_1376185025835_0006_01_000007, NodeId: hadoop-321-2:46202, NodeHttpAddress: hadoop-321-2:8042, Resource: <memory:1024, vCores:1>, Priority: 20, State: NEW, Token: null, Status: container_id {, app_attempt_id {, application_id {, id: 6, cluster_timestamp: 1376185025835, }, attemptId: 1, }, id: 7, }, state: C_NEW, ] containerId=container_1376185025835_0006_01_000007 queue=default: capacity=1.0, absoluteCapacity=1.0, usedResources=<memory:15360, vCores:10>usedCapacity=0.3125, absoluteUsedCapacity=0.3125, numApps=5, numContainers=10 usedCapacity=0.3125 absoluteUsedCapacity=0.3125 used=<memory:15360, vCores:10> cluster=<memory:49152, vCores:96>
2013-08-11 01:53:46,744 INFO org.apache.hadoop.yarn.server.resourcemanager.scheduler.capacity.ParentQueue: Re-sorting queues since queue: root.default stats: default: capacity=1.0, absoluteCapacity=1.0, usedResources=<memory:16384, vCores:11>usedCapacity=0.33333334, absoluteUsedCapacity=0.33333334, numApps=5, numContainers=11
2013-08-11 01:53:46,744 INFO org.apache.hadoop.yarn.server.resourcemanager.scheduler.capacity.ParentQueue: assignedContainer queue=root usedCapacity=0.33333334 absoluteUsedCapacity=0.33333334 used=<memory:16384, vCores:11> cluster=<memory:49152, vCores:96>
2013-08-11 01:53:46,803 INFO org.apache.hadoop.yarn.server.resourcemanager.rmcontainer.RMContainerImpl: container_1376185025835_0006_01_000008 Container Transitioned from NEW to ALLOCATED
2013-08-11 01:53:46,803 INFO org.apache.hadoop.yarn.server.resourcemanager.RMAuditLogger: USER=ubuntu	OPERATION=AM Allocated Container	TARGET=SchedulerApp	RESULT=SUCCESS	APPID=application_1376185025835_0006	CONTAINERID=container_1376185025835_0006_01_000008
2013-08-11 01:53:46,803 INFO org.apache.hadoop.yarn.server.resourcemanager.scheduler.common.fica.FiCaSchedulerNode: Assigned container container_1376185025835_0006_01_000008 of capacity <memory:1024, vCores:1> on host hadoop-321-3:44876, which currently has 2 containers, <memory:3072, vCores:2> used and <memory:5120, vCores:14> available
2013-08-11 01:53:46,804 INFO org.apache.hadoop.yarn.server.resourcemanager.scheduler.capacity.LeafQueue: assignedContainer application=application_1376185025835_0006 container=Container: [ContainerId: container_1376185025835_0006_01_000008, NodeId: hadoop-321-3:44876, NodeHttpAddress: hadoop-321-3:8042, Resource: <memory:1024, vCores:1>, Priority: 20, State: NEW, Token: null, Status: container_id {, app_attempt_id {, application_id {, id: 6, cluster_timestamp: 1376185025835, }, attemptId: 1, }, id: 8, }, state: C_NEW, ] containerId=container_1376185025835_0006_01_000008 queue=default: capacity=1.0, absoluteCapacity=1.0, usedResources=<memory:16384, vCores:11>usedCapacity=0.33333334, absoluteUsedCapacity=0.33333334, numApps=5, numContainers=11 usedCapacity=0.33333334 absoluteUsedCapacity=0.33333334 used=<memory:16384, vCores:11> cluster=<memory:49152, vCores:96>
2013-08-11 01:53:46,804 INFO org.apache.hadoop.yarn.server.resourcemanager.scheduler.capacity.ParentQueue: Re-sorting queues since queue: root.default stats: default: capacity=1.0, absoluteCapacity=1.0, usedResources=<memory:17408, vCores:12>usedCapacity=0.35416666, absoluteUsedCapacity=0.35416666, numApps=5, numContainers=12
2013-08-11 01:53:46,804 INFO org.apache.hadoop.yarn.server.resourcemanager.scheduler.capacity.ParentQueue: assignedContainer queue=root usedCapacity=0.35416666 absoluteUsedCapacity=0.35416666 used=<memory:17408, vCores:12> cluster=<memory:49152, vCores:96>
2013-08-11 01:53:46,805 INFO org.apache.hadoop.yarn.server.resourcemanager.rmcontainer.RMContainerImpl: container_1376185025835_0006_01_000009 Container Transitioned from NEW to ALLOCATED
2013-08-11 01:53:46,805 INFO org.apache.hadoop.yarn.server.resourcemanager.RMAuditLogger: USER=ubuntu	OPERATION=AM Allocated Container	TARGET=SchedulerApp	RESULT=SUCCESS	APPID=application_1376185025835_0006	CONTAINERID=container_1376185025835_0006_01_000009
2013-08-11 01:53:46,805 INFO org.apache.hadoop.yarn.server.resourcemanager.scheduler.common.fica.FiCaSchedulerNode: Assigned container container_1376185025835_0006_01_000009 of capacity <memory:1024, vCores:1> on host hadoop-321-3:44876, which currently has 3 containers, <memory:4096, vCores:3> used and <memory:4096, vCores:13> available
2013-08-11 01:53:46,806 INFO org.apache.hadoop.yarn.server.resourcemanager.scheduler.capacity.LeafQueue: assignedContainer application=application_1376185025835_0006 container=Container: [ContainerId: container_1376185025835_0006_01_000009, NodeId: hadoop-321-3:44876, NodeHttpAddress: hadoop-321-3:8042, Resource: <memory:1024, vCores:1>, Priority: 20, State: NEW, Token: null, Status: container_id {, app_attempt_id {, application_id {, id: 6, cluster_timestamp: 1376185025835, }, attemptId: 1, }, id: 9, }, state: C_NEW, ] containerId=container_1376185025835_0006_01_000009 queue=default: capacity=1.0, absoluteCapacity=1.0, usedResources=<memory:17408, vCores:12>usedCapacity=0.35416666, absoluteUsedCapacity=0.35416666, numApps=5, numContainers=12 usedCapacity=0.35416666 absoluteUsedCapacity=0.35416666 used=<memory:17408, vCores:12> cluster=<memory:49152, vCores:96>
2013-08-11 01:53:46,806 INFO org.apache.hadoop.yarn.server.resourcemanager.scheduler.capacity.ParentQueue: Re-sorting queues since queue: root.default stats: default: capacity=1.0, absoluteCapacity=1.0, usedResources=<memory:18432, vCores:13>usedCapacity=0.375, absoluteUsedCapacity=0.375, numApps=5, numContainers=13
2013-08-11 01:53:46,806 INFO org.apache.hadoop.yarn.server.resourcemanager.scheduler.capacity.ParentQueue: assignedContainer queue=root usedCapacity=0.375 absoluteUsedCapacity=0.375 used=<memory:18432, vCores:13> cluster=<memory:49152, vCores:96>
2013-08-11 01:53:46,807 INFO org.apache.hadoop.yarn.server.resourcemanager.rmcontainer.RMContainerImpl: container_1376185025835_0006_01_000010 Container Transitioned from NEW to ALLOCATED
2013-08-11 01:53:46,807 INFO org.apache.hadoop.yarn.server.resourcemanager.RMAuditLogger: USER=ubuntu	OPERATION=AM Allocated Container	TARGET=SchedulerApp	RESULT=SUCCESS	APPID=application_1376185025835_0006	CONTAINERID=container_1376185025835_0006_01_000010
2013-08-11 01:53:46,807 INFO org.apache.hadoop.yarn.server.resourcemanager.scheduler.common.fica.FiCaSchedulerNode: Assigned container container_1376185025835_0006_01_000010 of capacity <memory:1024, vCores:1> on host hadoop-321-3:44876, which currently has 4 containers, <memory:5120, vCores:4> used and <memory:3072, vCores:12> available
2013-08-11 01:53:46,808 INFO org.apache.hadoop.yarn.server.resourcemanager.scheduler.capacity.LeafQueue: assignedContainer application=application_1376185025835_0006 container=Container: [ContainerId: container_1376185025835_0006_01_000010, NodeId: hadoop-321-3:44876, NodeHttpAddress: hadoop-321-3:8042, Resource: <memory:1024, vCores:1>, Priority: 20, State: NEW, Token: null, Status: container_id {, app_attempt_id {, application_id {, id: 6, cluster_timestamp: 1376185025835, }, attemptId: 1, }, id: 10, }, state: C_NEW, ] containerId=container_1376185025835_0006_01_000010 queue=default: capacity=1.0, absoluteCapacity=1.0, usedResources=<memory:18432, vCores:13>usedCapacity=0.375, absoluteUsedCapacity=0.375, numApps=5, numContainers=13 usedCapacity=0.375 absoluteUsedCapacity=0.375 used=<memory:18432, vCores:13> cluster=<memory:49152, vCores:96>
2013-08-11 01:53:46,808 INFO org.apache.hadoop.yarn.server.resourcemanager.scheduler.capacity.ParentQueue: Re-sorting queues since queue: root.default stats: default: capacity=1.0, absoluteCapacity=1.0, usedResources=<memory:19456, vCores:14>usedCapacity=0.39583334, absoluteUsedCapacity=0.39583334, numApps=5, numContainers=14
2013-08-11 01:53:46,809 INFO org.apache.hadoop.yarn.server.resourcemanager.scheduler.capacity.ParentQueue: assignedContainer queue=root usedCapacity=0.39583334 absoluteUsedCapacity=0.39583334 used=<memory:19456, vCores:14> cluster=<memory:49152, vCores:96>
2013-08-11 01:53:46,809 INFO org.apache.hadoop.yarn.server.resourcemanager.rmcontainer.RMContainerImpl: container_1376185025835_0006_01_000011 Container Transitioned from NEW to ALLOCATED
2013-08-11 01:53:46,809 INFO org.apache.hadoop.yarn.server.resourcemanager.RMAuditLogger: USER=ubuntu	OPERATION=AM Allocated Container	TARGET=SchedulerApp	RESULT=SUCCESS	APPID=application_1376185025835_0006	CONTAINERID=container_1376185025835_0006_01_000011
2013-08-11 01:53:46,809 INFO org.apache.hadoop.yarn.server.resourcemanager.scheduler.common.fica.FiCaSchedulerNode: Assigned container container_1376185025835_0006_01_000011 of capacity <memory:1024, vCores:1> on host hadoop-321-3:44876, which currently has 5 containers, <memory:6144, vCores:5> used and <memory:2048, vCores:11> available
2013-08-11 01:53:46,810 INFO org.apache.hadoop.yarn.server.resourcemanager.scheduler.capacity.LeafQueue: assignedContainer application=application_1376185025835_0006 container=Container: [ContainerId: container_1376185025835_0006_01_000011, NodeId: hadoop-321-3:44876, NodeHttpAddress: hadoop-321-3:8042, Resource: <memory:1024, vCores:1>, Priority: 20, State: NEW, Token: null, Status: container_id {, app_attempt_id {, application_id {, id: 6, cluster_timestamp: 1376185025835, }, attemptId: 1, }, id: 11, }, state: C_NEW, ] containerId=container_1376185025835_0006_01_000011 queue=default: capacity=1.0, absoluteCapacity=1.0, usedResources=<memory:19456, vCores:14>usedCapacity=0.39583334, absoluteUsedCapacity=0.39583334, numApps=5, numContainers=14 usedCapacity=0.39583334 absoluteUsedCapacity=0.39583334 used=<memory:19456, vCores:14> cluster=<memory:49152, vCores:96>
2013-08-11 01:53:46,811 INFO org.apache.hadoop.yarn.server.resourcemanager.scheduler.capacity.ParentQueue: Re-sorting queues since queue: root.default stats: default: capacity=1.0, absoluteCapacity=1.0, usedResources=<memory:20480, vCores:15>usedCapacity=0.41666666, absoluteUsedCapacity=0.41666666, numApps=5, numContainers=15
2013-08-11 01:53:46,811 INFO org.apache.hadoop.yarn.server.resourcemanager.scheduler.capacity.ParentQueue: assignedContainer queue=root usedCapacity=0.41666666 absoluteUsedCapacity=0.41666666 used=<memory:20480, vCores:15> cluster=<memory:49152, vCores:96>
2013-08-11 01:53:46,811 INFO org.apache.hadoop.yarn.server.resourcemanager.rmcontainer.RMContainerImpl: container_1376185025835_0006_01_000012 Container Transitioned from NEW to ALLOCATED
2013-08-11 01:53:46,812 INFO org.apache.hadoop.yarn.server.resourcemanager.RMAuditLogger: USER=ubuntu	OPERATION=AM Allocated Container	TARGET=SchedulerApp	RESULT=SUCCESS	APPID=application_1376185025835_0006	CONTAINERID=container_1376185025835_0006_01_000012
2013-08-11 01:53:46,812 INFO org.apache.hadoop.yarn.server.resourcemanager.scheduler.common.fica.FiCaSchedulerNode: Assigned container container_1376185025835_0006_01_000012 of capacity <memory:1024, vCores:1> on host hadoop-321-3:44876, which currently has 6 containers, <memory:7168, vCores:6> used and <memory:1024, vCores:10> available
2013-08-11 01:53:46,813 INFO org.apache.hadoop.yarn.server.resourcemanager.scheduler.capacity.LeafQueue: assignedContainer application=application_1376185025835_0006 container=Container: [ContainerId: container_1376185025835_0006_01_000012, NodeId: hadoop-321-3:44876, NodeHttpAddress: hadoop-321-3:8042, Resource: <memory:1024, vCores:1>, Priority: 20, State: NEW, Token: null, Status: container_id {, app_attempt_id {, application_id {, id: 6, cluster_timestamp: 1376185025835, }, attemptId: 1, }, id: 12, }, state: C_NEW, ] containerId=container_1376185025835_0006_01_000012 queue=default: capacity=1.0, absoluteCapacity=1.0, usedResources=<memory:20480, vCores:15>usedCapacity=0.41666666, absoluteUsedCapacity=0.41666666, numApps=5, numContainers=15 usedCapacity=0.41666666 absoluteUsedCapacity=0.41666666 used=<memory:20480, vCores:15> cluster=<memory:49152, vCores:96>
2013-08-11 01:53:46,813 INFO org.apache.hadoop.yarn.server.resourcemanager.scheduler.capacity.ParentQueue: Re-sorting queues since queue: root.default stats: default: capacity=1.0, absoluteCapacity=1.0, usedResources=<memory:21504, vCores:16>usedCapacity=0.4375, absoluteUsedCapacity=0.4375, numApps=5, numContainers=16
2013-08-11 01:53:46,813 INFO org.apache.hadoop.yarn.server.resourcemanager.scheduler.capacity.ParentQueue: assignedContainer queue=root usedCapacity=0.4375 absoluteUsedCapacity=0.4375 used=<memory:21504, vCores:16> cluster=<memory:49152, vCores:96>
2013-08-11 01:53:46,814 INFO org.apache.hadoop.yarn.server.resourcemanager.rmcontainer.RMContainerImpl: container_1376185025835_0006_01_000013 Container Transitioned from NEW to ALLOCATED
2013-08-11 01:53:46,814 INFO org.apache.hadoop.yarn.server.resourcemanager.RMAuditLogger: USER=ubuntu	OPERATION=AM Allocated Container	TARGET=SchedulerApp	RESULT=SUCCESS	APPID=application_1376185025835_0006	CONTAINERID=container_1376185025835_0006_01_000013
2013-08-11 01:53:46,814 INFO org.apache.hadoop.yarn.server.resourcemanager.scheduler.common.fica.FiCaSchedulerNode: Assigned container container_1376185025835_0006_01_000013 of capacity <memory:1024, vCores:1> on host hadoop-321-3:44876, which currently has 7 containers, <memory:8192, vCores:7> used and <memory:0, vCores:9> available
2013-08-11 01:53:46,815 INFO org.apache.hadoop.yarn.server.resourcemanager.scheduler.capacity.LeafQueue: assignedContainer application=application_1376185025835_0006 container=Container: [ContainerId: container_1376185025835_0006_01_000013, NodeId: hadoop-321-3:44876, NodeHttpAddress: hadoop-321-3:8042, Resource: <memory:1024, vCores:1>, Priority: 20, State: NEW, Token: null, Status: container_id {, app_attempt_id {, application_id {, id: 6, cluster_timestamp: 1376185025835, }, attemptId: 1, }, id: 13, }, state: C_NEW, ] containerId=container_1376185025835_0006_01_000013 queue=default: capacity=1.0, absoluteCapacity=1.0, usedResources=<memory:21504, vCores:16>usedCapacity=0.4375, absoluteUsedCapacity=0.4375, numApps=5, numContainers=16 usedCapacity=0.4375 absoluteUsedCapacity=0.4375 used=<memory:21504, vCores:16> cluster=<memory:49152, vCores:96>
2013-08-11 01:53:46,815 INFO org.apache.hadoop.yarn.server.resourcemanager.scheduler.capacity.ParentQueue: Re-sorting queues since queue: root.default stats: default: capacity=1.0, absoluteCapacity=1.0, usedResources=<memory:22528, vCores:17>usedCapacity=0.45833334, absoluteUsedCapacity=0.45833334, numApps=5, numContainers=17
2013-08-11 01:53:46,815 INFO org.apache.hadoop.yarn.server.resourcemanager.scheduler.capacity.ParentQueue: assignedContainer queue=root usedCapacity=0.45833334 absoluteUsedCapacity=0.45833334 used=<memory:22528, vCores:17> cluster=<memory:49152, vCores:96>
2013-08-11 01:53:46,824 INFO org.apache.hadoop.yarn.server.resourcemanager.rmcontainer.RMContainerImpl: container_1376185025835_0006_01_000014 Container Transitioned from NEW to ALLOCATED
2013-08-11 01:53:46,824 INFO org.apache.hadoop.yarn.server.resourcemanager.RMAuditLogger: USER=ubuntu	OPERATION=AM Allocated Container	TARGET=SchedulerApp	RESULT=SUCCESS	APPID=application_1376185025835_0006	CONTAINERID=container_1376185025835_0006_01_000014
2013-08-11 01:53:46,824 INFO org.apache.hadoop.yarn.server.resourcemanager.scheduler.common.fica.FiCaSchedulerNode: Assigned container container_1376185025835_0006_01_000014 of capacity <memory:1024, vCores:1> on host hadoop-321-6:34867, which currently has 2 containers, <memory:3072, vCores:2> used and <memory:5120, vCores:14> available
2013-08-11 01:53:46,825 INFO org.apache.hadoop.yarn.server.resourcemanager.scheduler.capacity.LeafQueue: assignedContainer application=application_1376185025835_0006 container=Container: [ContainerId: container_1376185025835_0006_01_000014, NodeId: hadoop-321-6:34867, NodeHttpAddress: hadoop-321-6:8042, Resource: <memory:1024, vCores:1>, Priority: 20, State: NEW, Token: null, Status: container_id {, app_attempt_id {, application_id {, id: 6, cluster_timestamp: 1376185025835, }, attemptId: 1, }, id: 14, }, state: C_NEW, ] containerId=container_1376185025835_0006_01_000014 queue=default: capacity=1.0, absoluteCapacity=1.0, usedResources=<memory:22528, vCores:17>usedCapacity=0.45833334, absoluteUsedCapacity=0.45833334, numApps=5, numContainers=17 usedCapacity=0.45833334 absoluteUsedCapacity=0.45833334 used=<memory:22528, vCores:17> cluster=<memory:49152, vCores:96>
2013-08-11 01:53:46,826 INFO org.apache.hadoop.yarn.server.resourcemanager.scheduler.capacity.ParentQueue: Re-sorting queues since queue: root.default stats: default: capacity=1.0, absoluteCapacity=1.0, usedResources=<memory:23552, vCores:18>usedCapacity=0.47916666, absoluteUsedCapacity=0.47916666, numApps=5, numContainers=18
2013-08-11 01:53:46,826 INFO org.apache.hadoop.yarn.server.resourcemanager.scheduler.capacity.ParentQueue: assignedContainer queue=root usedCapacity=0.47916666 absoluteUsedCapacity=0.47916666 used=<memory:23552, vCores:18> cluster=<memory:49152, vCores:96>
2013-08-11 01:53:46,826 INFO org.apache.hadoop.yarn.server.resourcemanager.rmcontainer.RMContainerImpl: container_1376185025835_0006_01_000015 Container Transitioned from NEW to ALLOCATED
2013-08-11 01:53:46,826 INFO org.apache.hadoop.yarn.server.resourcemanager.RMAuditLogger: USER=ubuntu	OPERATION=AM Allocated Container	TARGET=SchedulerApp	RESULT=SUCCESS	APPID=application_1376185025835_0006	CONTAINERID=container_1376185025835_0006_01_000015
2013-08-11 01:53:46,826 INFO org.apache.hadoop.yarn.server.resourcemanager.scheduler.common.fica.FiCaSchedulerNode: Assigned container container_1376185025835_0006_01_000015 of capacity <memory:1024, vCores:1> on host hadoop-321-6:34867, which currently has 3 containers, <memory:4096, vCores:3> used and <memory:4096, vCores:13> available
2013-08-11 01:53:46,827 INFO org.apache.hadoop.yarn.server.resourcemanager.scheduler.capacity.LeafQueue: assignedContainer application=application_1376185025835_0006 container=Container: [ContainerId: container_1376185025835_0006_01_000015, NodeId: hadoop-321-6:34867, NodeHttpAddress: hadoop-321-6:8042, Resource: <memory:1024, vCores:1>, Priority: 20, State: NEW, Token: null, Status: container_id {, app_attempt_id {, application_id {, id: 6, cluster_timestamp: 1376185025835, }, attemptId: 1, }, id: 15, }, state: C_NEW, ] containerId=container_1376185025835_0006_01_000015 queue=default: capacity=1.0, absoluteCapacity=1.0, usedResources=<memory:23552, vCores:18>usedCapacity=0.47916666, absoluteUsedCapacity=0.47916666, numApps=5, numContainers=18 usedCapacity=0.47916666 absoluteUsedCapacity=0.47916666 used=<memory:23552, vCores:18> cluster=<memory:49152, vCores:96>
2013-08-11 01:53:46,828 INFO org.apache.hadoop.yarn.server.resourcemanager.scheduler.capacity.ParentQueue: Re-sorting queues since queue: root.default stats: default: capacity=1.0, absoluteCapacity=1.0, usedResources=<memory:24576, vCores:19>usedCapacity=0.5, absoluteUsedCapacity=0.5, numApps=5, numContainers=19
2013-08-11 01:53:46,828 INFO org.apache.hadoop.yarn.server.resourcemanager.scheduler.capacity.ParentQueue: assignedContainer queue=root usedCapacity=0.5 absoluteUsedCapacity=0.5 used=<memory:24576, vCores:19> cluster=<memory:49152, vCores:96>
2013-08-11 01:53:46,828 INFO org.apache.hadoop.yarn.server.resourcemanager.rmcontainer.RMContainerImpl: container_1376185025835_0006_01_000016 Container Transitioned from NEW to ALLOCATED
2013-08-11 01:53:46,828 INFO org.apache.hadoop.yarn.server.resourcemanager.RMAuditLogger: USER=ubuntu	OPERATION=AM Allocated Container	TARGET=SchedulerApp	RESULT=SUCCESS	APPID=application_1376185025835_0006	CONTAINERID=container_1376185025835_0006_01_000016
2013-08-11 01:53:46,828 INFO org.apache.hadoop.yarn.server.resourcemanager.scheduler.common.fica.FiCaSchedulerNode: Assigned container container_1376185025835_0006_01_000016 of capacity <memory:1024, vCores:1> on host hadoop-321-6:34867, which currently has 4 containers, <memory:5120, vCores:4> used and <memory:3072, vCores:12> available
2013-08-11 01:53:46,829 INFO org.apache.hadoop.yarn.server.resourcemanager.scheduler.capacity.LeafQueue: assignedContainer application=application_1376185025835_0006 container=Container: [ContainerId: container_1376185025835_0006_01_000016, NodeId: hadoop-321-6:34867, NodeHttpAddress: hadoop-321-6:8042, Resource: <memory:1024, vCores:1>, Priority: 20, State: NEW, Token: null, Status: container_id {, app_attempt_id {, application_id {, id: 6, cluster_timestamp: 1376185025835, }, attemptId: 1, }, id: 16, }, state: C_NEW, ] containerId=container_1376185025835_0006_01_000016 queue=default: capacity=1.0, absoluteCapacity=1.0, usedResources=<memory:24576, vCores:19>usedCapacity=0.5, absoluteUsedCapacity=0.5, numApps=5, numContainers=19 usedCapacity=0.5 absoluteUsedCapacity=0.5 used=<memory:24576, vCores:19> cluster=<memory:49152, vCores:96>
2013-08-11 01:53:46,830 INFO org.apache.hadoop.yarn.server.resourcemanager.scheduler.capacity.ParentQueue: Re-sorting queues since queue: root.default stats: default: capacity=1.0, absoluteCapacity=1.0, usedResources=<memory:25600, vCores:20>usedCapacity=0.5208333, absoluteUsedCapacity=0.5208333, numApps=5, numContainers=20
2013-08-11 01:53:46,830 INFO org.apache.hadoop.yarn.server.resourcemanager.scheduler.capacity.ParentQueue: assignedContainer queue=root usedCapacity=0.5208333 absoluteUsedCapacity=0.5208333 used=<memory:25600, vCores:20> cluster=<memory:49152, vCores:96>
2013-08-11 01:53:46,830 INFO org.apache.hadoop.yarn.server.resourcemanager.rmcontainer.RMContainerImpl: container_1376185025835_0006_01_000017 Container Transitioned from NEW to ALLOCATED
2013-08-11 01:53:46,830 INFO org.apache.hadoop.yarn.server.resourcemanager.RMAuditLogger: USER=ubuntu	OPERATION=AM Allocated Container	TARGET=SchedulerApp	RESULT=SUCCESS	APPID=application_1376185025835_0006	CONTAINERID=container_1376185025835_0006_01_000017
2013-08-11 01:53:46,831 INFO org.apache.hadoop.yarn.server.resourcemanager.scheduler.common.fica.FiCaSchedulerNode: Assigned container container_1376185025835_0006_01_000017 of capacity <memory:1024, vCores:1> on host hadoop-321-6:34867, which currently has 5 containers, <memory:6144, vCores:5> used and <memory:2048, vCores:11> available
2013-08-11 01:53:46,832 INFO org.apache.hadoop.yarn.server.resourcemanager.scheduler.capacity.LeafQueue: assignedContainer application=application_1376185025835_0006 container=Container: [ContainerId: container_1376185025835_0006_01_000017, NodeId: hadoop-321-6:34867, NodeHttpAddress: hadoop-321-6:8042, Resource: <memory:1024, vCores:1>, Priority: 20, State: NEW, Token: null, Status: container_id {, app_attempt_id {, application_id {, id: 6, cluster_timestamp: 1376185025835, }, attemptId: 1, }, id: 17, }, state: C_NEW, ] containerId=container_1376185025835_0006_01_000017 queue=default: capacity=1.0, absoluteCapacity=1.0, usedResources=<memory:25600, vCores:20>usedCapacity=0.5208333, absoluteUsedCapacity=0.5208333, numApps=5, numContainers=20 usedCapacity=0.5208333 absoluteUsedCapacity=0.5208333 used=<memory:25600, vCores:20> cluster=<memory:49152, vCores:96>
2013-08-11 01:53:46,832 INFO org.apache.hadoop.yarn.server.resourcemanager.scheduler.capacity.ParentQueue: Re-sorting queues since queue: root.default stats: default: capacity=1.0, absoluteCapacity=1.0, usedResources=<memory:26624, vCores:21>usedCapacity=0.5416667, absoluteUsedCapacity=0.5416667, numApps=5, numContainers=21
2013-08-11 01:53:46,832 INFO org.apache.hadoop.yarn.server.resourcemanager.scheduler.capacity.ParentQueue: assignedContainer queue=root usedCapacity=0.5416667 absoluteUsedCapacity=0.5416667 used=<memory:26624, vCores:21> cluster=<memory:49152, vCores:96>
2013-08-11 01:53:46,832 INFO org.apache.hadoop.yarn.server.resourcemanager.rmcontainer.RMContainerImpl: container_1376185025835_0006_01_000018 Container Transitioned from NEW to ALLOCATED
2013-08-11 01:53:46,832 INFO org.apache.hadoop.yarn.server.resourcemanager.RMAuditLogger: USER=ubuntu	OPERATION=AM Allocated Container	TARGET=SchedulerApp	RESULT=SUCCESS	APPID=application_1376185025835_0006	CONTAINERID=container_1376185025835_0006_01_000018
2013-08-11 01:53:46,833 INFO org.apache.hadoop.yarn.server.resourcemanager.scheduler.common.fica.FiCaSchedulerNode: Assigned container container_1376185025835_0006_01_000018 of capacity <memory:1024, vCores:1> on host hadoop-321-6:34867, which currently has 6 containers, <memory:7168, vCores:6> used and <memory:1024, vCores:10> available
2013-08-11 01:53:46,834 INFO org.apache.hadoop.yarn.server.resourcemanager.scheduler.capacity.LeafQueue: assignedContainer application=application_1376185025835_0006 container=Container: [ContainerId: container_1376185025835_0006_01_000018, NodeId: hadoop-321-6:34867, NodeHttpAddress: hadoop-321-6:8042, Resource: <memory:1024, vCores:1>, Priority: 20, State: NEW, Token: null, Status: container_id {, app_attempt_id {, application_id {, id: 6, cluster_timestamp: 1376185025835, }, attemptId: 1, }, id: 18, }, state: C_NEW, ] containerId=container_1376185025835_0006_01_000018 queue=default: capacity=1.0, absoluteCapacity=1.0, usedResources=<memory:26624, vCores:21>usedCapacity=0.5416667, absoluteUsedCapacity=0.5416667, numApps=5, numContainers=21 usedCapacity=0.5416667 absoluteUsedCapacity=0.5416667 used=<memory:26624, vCores:21> cluster=<memory:49152, vCores:96>
2013-08-11 01:53:46,834 INFO org.apache.hadoop.yarn.server.resourcemanager.scheduler.capacity.ParentQueue: Re-sorting queues since queue: root.default stats: default: capacity=1.0, absoluteCapacity=1.0, usedResources=<memory:27648, vCores:22>usedCapacity=0.5625, absoluteUsedCapacity=0.5625, numApps=5, numContainers=22
2013-08-11 01:53:46,834 INFO org.apache.hadoop.yarn.server.resourcemanager.scheduler.capacity.ParentQueue: assignedContainer queue=root usedCapacity=0.5625 absoluteUsedCapacity=0.5625 used=<memory:27648, vCores:22> cluster=<memory:49152, vCores:96>
2013-08-11 01:53:46,834 INFO org.apache.hadoop.yarn.server.resourcemanager.rmcontainer.RMContainerImpl: container_1376185025835_0006_01_000019 Container Transitioned from NEW to ALLOCATED
2013-08-11 01:53:46,834 INFO org.apache.hadoop.yarn.server.resourcemanager.RMAuditLogger: USER=ubuntu	OPERATION=AM Allocated Container	TARGET=SchedulerApp	RESULT=SUCCESS	APPID=application_1376185025835_0006	CONTAINERID=container_1376185025835_0006_01_000019
2013-08-11 01:53:46,835 INFO org.apache.hadoop.yarn.server.resourcemanager.scheduler.common.fica.FiCaSchedulerNode: Assigned container container_1376185025835_0006_01_000019 of capacity <memory:1024, vCores:1> on host hadoop-321-6:34867, which currently has 7 containers, <memory:8192, vCores:7> used and <memory:0, vCores:9> available
2013-08-11 01:53:46,836 INFO org.apache.hadoop.yarn.server.resourcemanager.scheduler.capacity.LeafQueue: assignedContainer application=application_1376185025835_0006 container=Container: [ContainerId: container_1376185025835_0006_01_000019, NodeId: hadoop-321-6:34867, NodeHttpAddress: hadoop-321-6:8042, Resource: <memory:1024, vCores:1>, Priority: 20, State: NEW, Token: null, Status: container_id {, app_attempt_id {, application_id {, id: 6, cluster_timestamp: 1376185025835, }, attemptId: 1, }, id: 19, }, state: C_NEW, ] containerId=container_1376185025835_0006_01_000019 queue=default: capacity=1.0, absoluteCapacity=1.0, usedResources=<memory:27648, vCores:22>usedCapacity=0.5625, absoluteUsedCapacity=0.5625, numApps=5, numContainers=22 usedCapacity=0.5625 absoluteUsedCapacity=0.5625 used=<memory:27648, vCores:22> cluster=<memory:49152, vCores:96>
2013-08-11 01:53:46,836 INFO org.apache.hadoop.yarn.server.resourcemanager.scheduler.capacity.ParentQueue: Re-sorting queues since queue: root.default stats: default: capacity=1.0, absoluteCapacity=1.0, usedResources=<memory:28672, vCores:23>usedCapacity=0.5833333, absoluteUsedCapacity=0.5833333, numApps=5, numContainers=23
2013-08-11 01:53:46,836 INFO org.apache.hadoop.yarn.server.resourcemanager.scheduler.capacity.ParentQueue: assignedContainer queue=root usedCapacity=0.5833333 absoluteUsedCapacity=0.5833333 used=<memory:28672, vCores:23> cluster=<memory:49152, vCores:96>
2013-08-11 01:53:46,842 INFO org.apache.hadoop.yarn.server.resourcemanager.ApplicationMasterService: AM registration appattempt_1376185025835_0007_000001
2013-08-11 01:53:46,843 INFO org.apache.hadoop.yarn.server.resourcemanager.RMAuditLogger: USER=ubuntu	IP=192.168.100.18	OPERATION=Register App Master	TARGET=ApplicationMasterService	RESULT=SUCCESS	APPID=application_1376185025835_0007	APPATTEMPTID=appattempt_1376185025835_0007_000001
2013-08-11 01:53:46,844 INFO org.apache.hadoop.yarn.server.resourcemanager.rmapp.attempt.RMAppAttemptImpl: appattempt_1376185025835_0007_000001 State change from LAUNCHED to RUNNING
2013-08-11 01:53:46,844 INFO org.apache.hadoop.yarn.server.resourcemanager.rmapp.RMAppImpl: application_1376185025835_0007 State change from ACCEPTED to RUNNING
2013-08-11 01:53:47,185 INFO org.apache.hadoop.yarn.server.resourcemanager.rmcontainer.RMContainerImpl: container_1376185025835_0006_01_000020 Container Transitioned from NEW to ALLOCATED
2013-08-11 01:53:47,185 INFO org.apache.hadoop.yarn.server.resourcemanager.RMAuditLogger: USER=ubuntu	OPERATION=AM Allocated Container	TARGET=SchedulerApp	RESULT=SUCCESS	APPID=application_1376185025835_0006	CONTAINERID=container_1376185025835_0006_01_000020
2013-08-11 01:53:47,185 INFO org.apache.hadoop.yarn.server.resourcemanager.scheduler.common.fica.FiCaSchedulerNode: Assigned container container_1376185025835_0006_01_000020 of capacity <memory:1024, vCores:1> on host hadoop-321-4:43757, which currently has 2 containers, <memory:3072, vCores:2> used and <memory:5120, vCores:14> available
2013-08-11 01:53:47,186 INFO org.apache.hadoop.yarn.server.resourcemanager.scheduler.capacity.LeafQueue: assignedContainer application=application_1376185025835_0006 container=Container: [ContainerId: container_1376185025835_0006_01_000020, NodeId: hadoop-321-4:43757, NodeHttpAddress: hadoop-321-4:8042, Resource: <memory:1024, vCores:1>, Priority: 20, State: NEW, Token: null, Status: container_id {, app_attempt_id {, application_id {, id: 6, cluster_timestamp: 1376185025835, }, attemptId: 1, }, id: 20, }, state: C_NEW, ] containerId=container_1376185025835_0006_01_000020 queue=default: capacity=1.0, absoluteCapacity=1.0, usedResources=<memory:28672, vCores:23>usedCapacity=0.5833333, absoluteUsedCapacity=0.5833333, numApps=5, numContainers=23 usedCapacity=0.5833333 absoluteUsedCapacity=0.5833333 used=<memory:28672, vCores:23> cluster=<memory:49152, vCores:96>
2013-08-11 01:53:47,187 INFO org.apache.hadoop.yarn.server.resourcemanager.scheduler.capacity.ParentQueue: Re-sorting queues since queue: root.default stats: default: capacity=1.0, absoluteCapacity=1.0, usedResources=<memory:29696, vCores:24>usedCapacity=0.6041667, absoluteUsedCapacity=0.6041667, numApps=5, numContainers=24
2013-08-11 01:53:47,187 INFO org.apache.hadoop.yarn.server.resourcemanager.scheduler.capacity.ParentQueue: assignedContainer queue=root usedCapacity=0.6041667 absoluteUsedCapacity=0.6041667 used=<memory:29696, vCores:24> cluster=<memory:49152, vCores:96>
2013-08-11 01:53:47,187 INFO org.apache.hadoop.yarn.server.resourcemanager.rmcontainer.RMContainerImpl: container_1376185025835_0006_01_000021 Container Transitioned from NEW to ALLOCATED
2013-08-11 01:53:47,187 INFO org.apache.hadoop.yarn.server.resourcemanager.RMAuditLogger: USER=ubuntu	OPERATION=AM Allocated Container	TARGET=SchedulerApp	RESULT=SUCCESS	APPID=application_1376185025835_0006	CONTAINERID=container_1376185025835_0006_01_000021
2013-08-11 01:53:47,188 INFO org.apache.hadoop.yarn.server.resourcemanager.scheduler.common.fica.FiCaSchedulerNode: Assigned container container_1376185025835_0006_01_000021 of capacity <memory:1024, vCores:1> on host hadoop-321-4:43757, which currently has 3 containers, <memory:4096, vCores:3> used and <memory:4096, vCores:13> available
2013-08-11 01:53:47,188 INFO org.apache.hadoop.yarn.server.resourcemanager.scheduler.capacity.LeafQueue: assignedContainer application=application_1376185025835_0006 container=Container: [ContainerId: container_1376185025835_0006_01_000021, NodeId: hadoop-321-4:43757, NodeHttpAddress: hadoop-321-4:8042, Resource: <memory:1024, vCores:1>, Priority: 20, State: NEW, Token: null, Status: container_id {, app_attempt_id {, application_id {, id: 6, cluster_timestamp: 1376185025835, }, attemptId: 1, }, id: 21, }, state: C_NEW, ] containerId=container_1376185025835_0006_01_000021 queue=default: capacity=1.0, absoluteCapacity=1.0, usedResources=<memory:29696, vCores:24>usedCapacity=0.6041667, absoluteUsedCapacity=0.6041667, numApps=5, numContainers=24 usedCapacity=0.6041667 absoluteUsedCapacity=0.6041667 used=<memory:29696, vCores:24> cluster=<memory:49152, vCores:96>
2013-08-11 01:53:47,189 INFO org.apache.hadoop.yarn.server.resourcemanager.scheduler.capacity.ParentQueue: Re-sorting queues since queue: root.default stats: default: capacity=1.0, absoluteCapacity=1.0, usedResources=<memory:30720, vCores:25>usedCapacity=0.625, absoluteUsedCapacity=0.625, numApps=5, numContainers=25
2013-08-11 01:53:47,189 INFO org.apache.hadoop.yarn.server.resourcemanager.scheduler.capacity.ParentQueue: assignedContainer queue=root usedCapacity=0.625 absoluteUsedCapacity=0.625 used=<memory:30720, vCores:25> cluster=<memory:49152, vCores:96>
2013-08-11 01:53:47,189 INFO org.apache.hadoop.yarn.server.resourcemanager.rmcontainer.RMContainerImpl: container_1376185025835_0006_01_000022 Container Transitioned from NEW to ALLOCATED
2013-08-11 01:53:47,189 INFO org.apache.hadoop.yarn.server.resourcemanager.RMAuditLogger: USER=ubuntu	OPERATION=AM Allocated Container	TARGET=SchedulerApp	RESULT=SUCCESS	APPID=application_1376185025835_0006	CONTAINERID=container_1376185025835_0006_01_000022
2013-08-11 01:53:47,190 INFO org.apache.hadoop.yarn.server.resourcemanager.scheduler.common.fica.FiCaSchedulerNode: Assigned container container_1376185025835_0006_01_000022 of capacity <memory:1024, vCores:1> on host hadoop-321-4:43757, which currently has 4 containers, <memory:5120, vCores:4> used and <memory:3072, vCores:12> available
2013-08-11 01:53:47,190 INFO org.apache.hadoop.yarn.server.resourcemanager.scheduler.capacity.LeafQueue: assignedContainer application=application_1376185025835_0006 container=Container: [ContainerId: container_1376185025835_0006_01_000022, NodeId: hadoop-321-4:43757, NodeHttpAddress: hadoop-321-4:8042, Resource: <memory:1024, vCores:1>, Priority: 20, State: NEW, Token: null, Status: container_id {, app_attempt_id {, application_id {, id: 6, cluster_timestamp: 1376185025835, }, attemptId: 1, }, id: 22, }, state: C_NEW, ] containerId=container_1376185025835_0006_01_000022 queue=default: capacity=1.0, absoluteCapacity=1.0, usedResources=<memory:30720, vCores:25>usedCapacity=0.625, absoluteUsedCapacity=0.625, numApps=5, numContainers=25 usedCapacity=0.625 absoluteUsedCapacity=0.625 used=<memory:30720, vCores:25> cluster=<memory:49152, vCores:96>
2013-08-11 01:53:47,191 INFO org.apache.hadoop.yarn.server.resourcemanager.scheduler.capacity.ParentQueue: Re-sorting queues since queue: root.default stats: default: capacity=1.0, absoluteCapacity=1.0, usedResources=<memory:31744, vCores:26>usedCapacity=0.6458333, absoluteUsedCapacity=0.6458333, numApps=5, numContainers=26
2013-08-11 01:53:47,191 INFO org.apache.hadoop.yarn.server.resourcemanager.scheduler.capacity.ParentQueue: assignedContainer queue=root usedCapacity=0.6458333 absoluteUsedCapacity=0.6458333 used=<memory:31744, vCores:26> cluster=<memory:49152, vCores:96>
2013-08-11 01:53:47,191 INFO org.apache.hadoop.yarn.server.resourcemanager.rmcontainer.RMContainerImpl: container_1376185025835_0006_01_000023 Container Transitioned from NEW to ALLOCATED
2013-08-11 01:53:47,191 INFO org.apache.hadoop.yarn.server.resourcemanager.RMAuditLogger: USER=ubuntu	OPERATION=AM Allocated Container	TARGET=SchedulerApp	RESULT=SUCCESS	APPID=application_1376185025835_0006	CONTAINERID=container_1376185025835_0006_01_000023
2013-08-11 01:53:47,192 INFO org.apache.hadoop.yarn.server.resourcemanager.scheduler.common.fica.FiCaSchedulerNode: Assigned container container_1376185025835_0006_01_000023 of capacity <memory:1024, vCores:1> on host hadoop-321-4:43757, which currently has 5 containers, <memory:6144, vCores:5> used and <memory:2048, vCores:11> available
2013-08-11 01:53:47,193 INFO org.apache.hadoop.yarn.server.resourcemanager.scheduler.capacity.LeafQueue: assignedContainer application=application_1376185025835_0006 container=Container: [ContainerId: container_1376185025835_0006_01_000023, NodeId: hadoop-321-4:43757, NodeHttpAddress: hadoop-321-4:8042, Resource: <memory:1024, vCores:1>, Priority: 20, State: NEW, Token: null, Status: container_id {, app_attempt_id {, application_id {, id: 6, cluster_timestamp: 1376185025835, }, attemptId: 1, }, id: 23, }, state: C_NEW, ] containerId=container_1376185025835_0006_01_000023 queue=default: capacity=1.0, absoluteCapacity=1.0, usedResources=<memory:31744, vCores:26>usedCapacity=0.6458333, absoluteUsedCapacity=0.6458333, numApps=5, numContainers=26 usedCapacity=0.6458333 absoluteUsedCapacity=0.6458333 used=<memory:31744, vCores:26> cluster=<memory:49152, vCores:96>
2013-08-11 01:53:47,193 INFO org.apache.hadoop.yarn.server.resourcemanager.scheduler.capacity.ParentQueue: Re-sorting queues since queue: root.default stats: default: capacity=1.0, absoluteCapacity=1.0, usedResources=<memory:32768, vCores:27>usedCapacity=0.6666667, absoluteUsedCapacity=0.6666667, numApps=5, numContainers=27
2013-08-11 01:53:47,193 INFO org.apache.hadoop.yarn.server.resourcemanager.scheduler.capacity.ParentQueue: assignedContainer queue=root usedCapacity=0.6666667 absoluteUsedCapacity=0.6666667 used=<memory:32768, vCores:27> cluster=<memory:49152, vCores:96>
2013-08-11 01:53:47,193 INFO org.apache.hadoop.yarn.server.resourcemanager.rmcontainer.RMContainerImpl: container_1376185025835_0006_01_000024 Container Transitioned from NEW to ALLOCATED
2013-08-11 01:53:47,194 INFO org.apache.hadoop.yarn.server.resourcemanager.RMAuditLogger: USER=ubuntu	OPERATION=AM Allocated Container	TARGET=SchedulerApp	RESULT=SUCCESS	APPID=application_1376185025835_0006	CONTAINERID=container_1376185025835_0006_01_000024
2013-08-11 01:53:47,194 INFO org.apache.hadoop.yarn.server.resourcemanager.scheduler.common.fica.FiCaSchedulerNode: Assigned container container_1376185025835_0006_01_000024 of capacity <memory:1024, vCores:1> on host hadoop-321-4:43757, which currently has 6 containers, <memory:7168, vCores:6> used and <memory:1024, vCores:10> available
2013-08-11 01:53:47,195 INFO org.apache.hadoop.yarn.server.resourcemanager.scheduler.capacity.LeafQueue: assignedContainer application=application_1376185025835_0006 container=Container: [ContainerId: container_1376185025835_0006_01_000024, NodeId: hadoop-321-4:43757, NodeHttpAddress: hadoop-321-4:8042, Resource: <memory:1024, vCores:1>, Priority: 20, State: NEW, Token: null, Status: container_id {, app_attempt_id {, application_id {, id: 6, cluster_timestamp: 1376185025835, }, attemptId: 1, }, id: 24, }, state: C_NEW, ] containerId=container_1376185025835_0006_01_000024 queue=default: capacity=1.0, absoluteCapacity=1.0, usedResources=<memory:32768, vCores:27>usedCapacity=0.6666667, absoluteUsedCapacity=0.6666667, numApps=5, numContainers=27 usedCapacity=0.6666667 absoluteUsedCapacity=0.6666667 used=<memory:32768, vCores:27> cluster=<memory:49152, vCores:96>
2013-08-11 01:53:47,195 INFO org.apache.hadoop.yarn.server.resourcemanager.scheduler.capacity.ParentQueue: Re-sorting queues since queue: root.default stats: default: capacity=1.0, absoluteCapacity=1.0, usedResources=<memory:33792, vCores:28>usedCapacity=0.6875, absoluteUsedCapacity=0.6875, numApps=5, numContainers=28
2013-08-11 01:53:47,195 INFO org.apache.hadoop.yarn.server.resourcemanager.scheduler.capacity.ParentQueue: assignedContainer queue=root usedCapacity=0.6875 absoluteUsedCapacity=0.6875 used=<memory:33792, vCores:28> cluster=<memory:49152, vCores:96>
2013-08-11 01:53:47,196 INFO org.apache.hadoop.yarn.server.resourcemanager.rmcontainer.RMContainerImpl: container_1376185025835_0006_01_000025 Container Transitioned from NEW to ALLOCATED
2013-08-11 01:53:47,196 INFO org.apache.hadoop.yarn.server.resourcemanager.RMAuditLogger: USER=ubuntu	OPERATION=AM Allocated Container	TARGET=SchedulerApp	RESULT=SUCCESS	APPID=application_1376185025835_0006	CONTAINERID=container_1376185025835_0006_01_000025
2013-08-11 01:53:47,196 INFO org.apache.hadoop.yarn.server.resourcemanager.scheduler.common.fica.FiCaSchedulerNode: Assigned container container_1376185025835_0006_01_000025 of capacity <memory:1024, vCores:1> on host hadoop-321-4:43757, which currently has 7 containers, <memory:8192, vCores:7> used and <memory:0, vCores:9> available
2013-08-11 01:53:47,197 INFO org.apache.hadoop.yarn.server.resourcemanager.scheduler.capacity.LeafQueue: assignedContainer application=application_1376185025835_0006 container=Container: [ContainerId: container_1376185025835_0006_01_000025, NodeId: hadoop-321-4:43757, NodeHttpAddress: hadoop-321-4:8042, Resource: <memory:1024, vCores:1>, Priority: 20, State: NEW, Token: null, Status: container_id {, app_attempt_id {, application_id {, id: 6, cluster_timestamp: 1376185025835, }, attemptId: 1, }, id: 25, }, state: C_NEW, ] containerId=container_1376185025835_0006_01_000025 queue=default: capacity=1.0, absoluteCapacity=1.0, usedResources=<memory:33792, vCores:28>usedCapacity=0.6875, absoluteUsedCapacity=0.6875, numApps=5, numContainers=28 usedCapacity=0.6875 absoluteUsedCapacity=0.6875 used=<memory:33792, vCores:28> cluster=<memory:49152, vCores:96>
2013-08-11 01:53:47,197 INFO org.apache.hadoop.yarn.server.resourcemanager.scheduler.capacity.ParentQueue: Re-sorting queues since queue: root.default stats: default: capacity=1.0, absoluteCapacity=1.0, usedResources=<memory:34816, vCores:29>usedCapacity=0.7083333, absoluteUsedCapacity=0.7083333, numApps=5, numContainers=29
2013-08-11 01:53:47,197 INFO org.apache.hadoop.yarn.server.resourcemanager.scheduler.capacity.ParentQueue: assignedContainer queue=root usedCapacity=0.7083333 absoluteUsedCapacity=0.7083333 used=<memory:34816, vCores:29> cluster=<memory:49152, vCores:96>
2013-08-11 01:53:47,225 INFO org.apache.hadoop.yarn.server.resourcemanager.rmcontainer.RMContainerImpl: container_1376185025835_0006_01_000026 Container Transitioned from NEW to ALLOCATED
2013-08-11 01:53:47,225 INFO org.apache.hadoop.yarn.server.resourcemanager.RMAuditLogger: USER=ubuntu	OPERATION=AM Allocated Container	TARGET=SchedulerApp	RESULT=SUCCESS	APPID=application_1376185025835_0006	CONTAINERID=container_1376185025835_0006_01_000026
2013-08-11 01:53:47,225 INFO org.apache.hadoop.yarn.server.resourcemanager.scheduler.common.fica.FiCaSchedulerNode: Assigned container container_1376185025835_0006_01_000026 of capacity <memory:1024, vCores:1> on host hadoop-321-7:41950, which currently has 1 containers, <memory:1024, vCores:1> used and <memory:7168, vCores:15> available
2013-08-11 01:53:47,226 INFO org.apache.hadoop.yarn.server.resourcemanager.scheduler.capacity.LeafQueue: assignedContainer application=application_1376185025835_0006 container=Container: [ContainerId: container_1376185025835_0006_01_000026, NodeId: hadoop-321-7:41950, NodeHttpAddress: hadoop-321-7:8042, Resource: <memory:1024, vCores:1>, Priority: 20, State: NEW, Token: null, Status: container_id {, app_attempt_id {, application_id {, id: 6, cluster_timestamp: 1376185025835, }, attemptId: 1, }, id: 26, }, state: C_NEW, ] containerId=container_1376185025835_0006_01_000026 queue=default: capacity=1.0, absoluteCapacity=1.0, usedResources=<memory:34816, vCores:29>usedCapacity=0.7083333, absoluteUsedCapacity=0.7083333, numApps=5, numContainers=29 usedCapacity=0.7083333 absoluteUsedCapacity=0.7083333 used=<memory:34816, vCores:29> cluster=<memory:49152, vCores:96>
2013-08-11 01:53:47,226 INFO org.apache.hadoop.yarn.server.resourcemanager.scheduler.capacity.ParentQueue: Re-sorting queues since queue: root.default stats: default: capacity=1.0, absoluteCapacity=1.0, usedResources=<memory:35840, vCores:30>usedCapacity=0.7291667, absoluteUsedCapacity=0.7291667, numApps=5, numContainers=30
2013-08-11 01:53:47,226 INFO org.apache.hadoop.yarn.server.resourcemanager.scheduler.capacity.ParentQueue: assignedContainer queue=root usedCapacity=0.7291667 absoluteUsedCapacity=0.7291667 used=<memory:35840, vCores:30> cluster=<memory:49152, vCores:96>
2013-08-11 01:53:47,227 INFO org.apache.hadoop.yarn.server.resourcemanager.rmcontainer.RMContainerImpl: container_1376185025835_0006_01_000027 Container Transitioned from NEW to ALLOCATED
2013-08-11 01:53:47,227 INFO org.apache.hadoop.yarn.server.resourcemanager.RMAuditLogger: USER=ubuntu	OPERATION=AM Allocated Container	TARGET=SchedulerApp	RESULT=SUCCESS	APPID=application_1376185025835_0006	CONTAINERID=container_1376185025835_0006_01_000027
2013-08-11 01:53:47,227 INFO org.apache.hadoop.yarn.server.resourcemanager.scheduler.common.fica.FiCaSchedulerNode: Assigned container container_1376185025835_0006_01_000027 of capacity <memory:1024, vCores:1> on host hadoop-321-7:41950, which currently has 2 containers, <memory:2048, vCores:2> used and <memory:6144, vCores:14> available
2013-08-11 01:53:47,228 INFO org.apache.hadoop.yarn.server.resourcemanager.scheduler.capacity.LeafQueue: assignedContainer application=application_1376185025835_0006 container=Container: [ContainerId: container_1376185025835_0006_01_000027, NodeId: hadoop-321-7:41950, NodeHttpAddress: hadoop-321-7:8042, Resource: <memory:1024, vCores:1>, Priority: 20, State: NEW, Token: null, Status: container_id {, app_attempt_id {, application_id {, id: 6, cluster_timestamp: 1376185025835, }, attemptId: 1, }, id: 27, }, state: C_NEW, ] containerId=container_1376185025835_0006_01_000027 queue=default: capacity=1.0, absoluteCapacity=1.0, usedResources=<memory:35840, vCores:30>usedCapacity=0.7291667, absoluteUsedCapacity=0.7291667, numApps=5, numContainers=30 usedCapacity=0.7291667 absoluteUsedCapacity=0.7291667 used=<memory:35840, vCores:30> cluster=<memory:49152, vCores:96>
2013-08-11 01:53:47,228 INFO org.apache.hadoop.yarn.server.resourcemanager.scheduler.capacity.ParentQueue: Re-sorting queues since queue: root.default stats: default: capacity=1.0, absoluteCapacity=1.0, usedResources=<memory:36864, vCores:31>usedCapacity=0.75, absoluteUsedCapacity=0.75, numApps=5, numContainers=31
2013-08-11 01:53:47,228 INFO org.apache.hadoop.yarn.server.resourcemanager.scheduler.capacity.ParentQueue: assignedContainer queue=root usedCapacity=0.75 absoluteUsedCapacity=0.75 used=<memory:36864, vCores:31> cluster=<memory:49152, vCores:96>
2013-08-11 01:53:47,229 INFO org.apache.hadoop.yarn.server.resourcemanager.rmcontainer.RMContainerImpl: container_1376185025835_0006_01_000028 Container Transitioned from NEW to ALLOCATED
2013-08-11 01:53:47,229 INFO org.apache.hadoop.yarn.server.resourcemanager.RMAuditLogger: USER=ubuntu	OPERATION=AM Allocated Container	TARGET=SchedulerApp	RESULT=SUCCESS	APPID=application_1376185025835_0006	CONTAINERID=container_1376185025835_0006_01_000028
2013-08-11 01:53:47,229 INFO org.apache.hadoop.yarn.server.resourcemanager.scheduler.common.fica.FiCaSchedulerNode: Assigned container container_1376185025835_0006_01_000028 of capacity <memory:1024, vCores:1> on host hadoop-321-7:41950, which currently has 3 containers, <memory:3072, vCores:3> used and <memory:5120, vCores:13> available
2013-08-11 01:53:47,230 INFO org.apache.hadoop.yarn.server.resourcemanager.scheduler.capacity.LeafQueue: assignedContainer application=application_1376185025835_0006 container=Container: [ContainerId: container_1376185025835_0006_01_000028, NodeId: hadoop-321-7:41950, NodeHttpAddress: hadoop-321-7:8042, Resource: <memory:1024, vCores:1>, Priority: 20, State: NEW, Token: null, Status: container_id {, app_attempt_id {, application_id {, id: 6, cluster_timestamp: 1376185025835, }, attemptId: 1, }, id: 28, }, state: C_NEW, ] containerId=container_1376185025835_0006_01_000028 queue=default: capacity=1.0, absoluteCapacity=1.0, usedResources=<memory:36864, vCores:31>usedCapacity=0.75, absoluteUsedCapacity=0.75, numApps=5, numContainers=31 usedCapacity=0.75 absoluteUsedCapacity=0.75 used=<memory:36864, vCores:31> cluster=<memory:49152, vCores:96>
2013-08-11 01:53:47,230 INFO org.apache.hadoop.yarn.server.resourcemanager.scheduler.capacity.ParentQueue: Re-sorting queues since queue: root.default stats: default: capacity=1.0, absoluteCapacity=1.0, usedResources=<memory:37888, vCores:32>usedCapacity=0.7708333, absoluteUsedCapacity=0.7708333, numApps=5, numContainers=32
2013-08-11 01:53:47,230 INFO org.apache.hadoop.yarn.server.resourcemanager.scheduler.capacity.ParentQueue: assignedContainer queue=root usedCapacity=0.7708333 absoluteUsedCapacity=0.7708333 used=<memory:37888, vCores:32> cluster=<memory:49152, vCores:96>
2013-08-11 01:53:47,231 INFO org.apache.hadoop.yarn.server.resourcemanager.rmcontainer.RMContainerImpl: container_1376185025835_0006_01_000029 Container Transitioned from NEW to ALLOCATED
2013-08-11 01:53:47,231 INFO org.apache.hadoop.yarn.server.resourcemanager.RMAuditLogger: USER=ubuntu	OPERATION=AM Allocated Container	TARGET=SchedulerApp	RESULT=SUCCESS	APPID=application_1376185025835_0006	CONTAINERID=container_1376185025835_0006_01_000029
2013-08-11 01:53:47,231 INFO org.apache.hadoop.yarn.server.resourcemanager.scheduler.common.fica.FiCaSchedulerNode: Assigned container container_1376185025835_0006_01_000029 of capacity <memory:1024, vCores:1> on host hadoop-321-7:41950, which currently has 4 containers, <memory:4096, vCores:4> used and <memory:4096, vCores:12> available
2013-08-11 01:53:47,232 INFO org.apache.hadoop.yarn.server.resourcemanager.scheduler.capacity.LeafQueue: assignedContainer application=application_1376185025835_0006 container=Container: [ContainerId: container_1376185025835_0006_01_000029, NodeId: hadoop-321-7:41950, NodeHttpAddress: hadoop-321-7:8042, Resource: <memory:1024, vCores:1>, Priority: 20, State: NEW, Token: null, Status: container_id {, app_attempt_id {, application_id {, id: 6, cluster_timestamp: 1376185025835, }, attemptId: 1, }, id: 29, }, state: C_NEW, ] containerId=container_1376185025835_0006_01_000029 queue=default: capacity=1.0, absoluteCapacity=1.0, usedResources=<memory:37888, vCores:32>usedCapacity=0.7708333, absoluteUsedCapacity=0.7708333, numApps=5, numContainers=32 usedCapacity=0.7708333 absoluteUsedCapacity=0.7708333 used=<memory:37888, vCores:32> cluster=<memory:49152, vCores:96>
2013-08-11 01:53:47,232 INFO org.apache.hadoop.yarn.server.resourcemanager.scheduler.capacity.ParentQueue: Re-sorting queues since queue: root.default stats: default: capacity=1.0, absoluteCapacity=1.0, usedResources=<memory:38912, vCores:33>usedCapacity=0.7916667, absoluteUsedCapacity=0.7916667, numApps=5, numContainers=33
2013-08-11 01:53:47,232 INFO org.apache.hadoop.yarn.server.resourcemanager.scheduler.capacity.ParentQueue: assignedContainer queue=root usedCapacity=0.7916667 absoluteUsedCapacity=0.7916667 used=<memory:38912, vCores:33> cluster=<memory:49152, vCores:96>
2013-08-11 01:53:47,233 INFO org.apache.hadoop.yarn.server.resourcemanager.rmcontainer.RMContainerImpl: container_1376185025835_0006_01_000030 Container Transitioned from NEW to ALLOCATED
2013-08-11 01:53:47,233 INFO org.apache.hadoop.yarn.server.resourcemanager.RMAuditLogger: USER=ubuntu	OPERATION=AM Allocated Container	TARGET=SchedulerApp	RESULT=SUCCESS	APPID=application_1376185025835_0006	CONTAINERID=container_1376185025835_0006_01_000030
2013-08-11 01:53:47,233 INFO org.apache.hadoop.yarn.server.resourcemanager.scheduler.common.fica.FiCaSchedulerNode: Assigned container container_1376185025835_0006_01_000030 of capacity <memory:1024, vCores:1> on host hadoop-321-7:41950, which currently has 5 containers, <memory:5120, vCores:5> used and <memory:3072, vCores:11> available
2013-08-11 01:53:47,234 INFO org.apache.hadoop.yarn.server.resourcemanager.scheduler.capacity.LeafQueue: assignedContainer application=application_1376185025835_0006 container=Container: [ContainerId: container_1376185025835_0006_01_000030, NodeId: hadoop-321-7:41950, NodeHttpAddress: hadoop-321-7:8042, Resource: <memory:1024, vCores:1>, Priority: 20, State: NEW, Token: null, Status: container_id {, app_attempt_id {, application_id {, id: 6, cluster_timestamp: 1376185025835, }, attemptId: 1, }, id: 30, }, state: C_NEW, ] containerId=container_1376185025835_0006_01_000030 queue=default: capacity=1.0, absoluteCapacity=1.0, usedResources=<memory:38912, vCores:33>usedCapacity=0.7916667, absoluteUsedCapacity=0.7916667, numApps=5, numContainers=33 usedCapacity=0.7916667 absoluteUsedCapacity=0.7916667 used=<memory:38912, vCores:33> cluster=<memory:49152, vCores:96>
2013-08-11 01:53:47,234 INFO org.apache.hadoop.yarn.server.resourcemanager.scheduler.capacity.ParentQueue: Re-sorting queues since queue: root.default stats: default: capacity=1.0, absoluteCapacity=1.0, usedResources=<memory:39936, vCores:34>usedCapacity=0.8125, absoluteUsedCapacity=0.8125, numApps=5, numContainers=34
2013-08-11 01:53:47,234 INFO org.apache.hadoop.yarn.server.resourcemanager.scheduler.capacity.ParentQueue: assignedContainer queue=root usedCapacity=0.8125 absoluteUsedCapacity=0.8125 used=<memory:39936, vCores:34> cluster=<memory:49152, vCores:96>
2013-08-11 01:53:47,235 INFO org.apache.hadoop.yarn.server.resourcemanager.rmcontainer.RMContainerImpl: container_1376185025835_0006_01_000031 Container Transitioned from NEW to ALLOCATED
2013-08-11 01:53:47,235 INFO org.apache.hadoop.yarn.server.resourcemanager.RMAuditLogger: USER=ubuntu	OPERATION=AM Allocated Container	TARGET=SchedulerApp	RESULT=SUCCESS	APPID=application_1376185025835_0006	CONTAINERID=container_1376185025835_0006_01_000031
2013-08-11 01:53:47,235 INFO org.apache.hadoop.yarn.server.resourcemanager.scheduler.common.fica.FiCaSchedulerNode: Assigned container container_1376185025835_0006_01_000031 of capacity <memory:1024, vCores:1> on host hadoop-321-7:41950, which currently has 6 containers, <memory:6144, vCores:6> used and <memory:2048, vCores:10> available
2013-08-11 01:53:47,236 INFO org.apache.hadoop.yarn.server.resourcemanager.scheduler.capacity.LeafQueue: assignedContainer application=application_1376185025835_0006 container=Container: [ContainerId: container_1376185025835_0006_01_000031, NodeId: hadoop-321-7:41950, NodeHttpAddress: hadoop-321-7:8042, Resource: <memory:1024, vCores:1>, Priority: 20, State: NEW, Token: null, Status: container_id {, app_attempt_id {, application_id {, id: 6, cluster_timestamp: 1376185025835, }, attemptId: 1, }, id: 31, }, state: C_NEW, ] containerId=container_1376185025835_0006_01_000031 queue=default: capacity=1.0, absoluteCapacity=1.0, usedResources=<memory:39936, vCores:34>usedCapacity=0.8125, absoluteUsedCapacity=0.8125, numApps=5, numContainers=34 usedCapacity=0.8125 absoluteUsedCapacity=0.8125 used=<memory:39936, vCores:34> cluster=<memory:49152, vCores:96>
2013-08-11 01:53:47,236 INFO org.apache.hadoop.yarn.server.resourcemanager.scheduler.capacity.ParentQueue: Re-sorting queues since queue: root.default stats: default: capacity=1.0, absoluteCapacity=1.0, usedResources=<memory:40960, vCores:35>usedCapacity=0.8333333, absoluteUsedCapacity=0.8333333, numApps=5, numContainers=35
2013-08-11 01:53:47,236 INFO org.apache.hadoop.yarn.server.resourcemanager.scheduler.capacity.ParentQueue: assignedContainer queue=root usedCapacity=0.8333333 absoluteUsedCapacity=0.8333333 used=<memory:40960, vCores:35> cluster=<memory:49152, vCores:96>
2013-08-11 01:53:47,237 INFO org.apache.hadoop.yarn.server.resourcemanager.rmcontainer.RMContainerImpl: container_1376185025835_0006_01_000032 Container Transitioned from NEW to ALLOCATED
2013-08-11 01:53:47,237 INFO org.apache.hadoop.yarn.server.resourcemanager.RMAuditLogger: USER=ubuntu	OPERATION=AM Allocated Container	TARGET=SchedulerApp	RESULT=SUCCESS	APPID=application_1376185025835_0006	CONTAINERID=container_1376185025835_0006_01_000032
2013-08-11 01:53:47,237 INFO org.apache.hadoop.yarn.server.resourcemanager.scheduler.common.fica.FiCaSchedulerNode: Assigned container container_1376185025835_0006_01_000032 of capacity <memory:1024, vCores:1> on host hadoop-321-7:41950, which currently has 7 containers, <memory:7168, vCores:7> used and <memory:1024, vCores:9> available
2013-08-11 01:53:47,238 INFO org.apache.hadoop.yarn.server.resourcemanager.scheduler.capacity.LeafQueue: assignedContainer application=application_1376185025835_0006 container=Container: [ContainerId: container_1376185025835_0006_01_000032, NodeId: hadoop-321-7:41950, NodeHttpAddress: hadoop-321-7:8042, Resource: <memory:1024, vCores:1>, Priority: 20, State: NEW, Token: null, Status: container_id {, app_attempt_id {, application_id {, id: 6, cluster_timestamp: 1376185025835, }, attemptId: 1, }, id: 32, }, state: C_NEW, ] containerId=container_1376185025835_0006_01_000032 queue=default: capacity=1.0, absoluteCapacity=1.0, usedResources=<memory:40960, vCores:35>usedCapacity=0.8333333, absoluteUsedCapacity=0.8333333, numApps=5, numContainers=35 usedCapacity=0.8333333 absoluteUsedCapacity=0.8333333 used=<memory:40960, vCores:35> cluster=<memory:49152, vCores:96>
2013-08-11 01:53:47,238 INFO org.apache.hadoop.yarn.server.resourcemanager.scheduler.capacity.ParentQueue: Re-sorting queues since queue: root.default stats: default: capacity=1.0, absoluteCapacity=1.0, usedResources=<memory:41984, vCores:36>usedCapacity=0.8541667, absoluteUsedCapacity=0.8541667, numApps=5, numContainers=36
2013-08-11 01:53:47,238 INFO org.apache.hadoop.yarn.server.resourcemanager.scheduler.capacity.ParentQueue: assignedContainer queue=root usedCapacity=0.8541667 absoluteUsedCapacity=0.8541667 used=<memory:41984, vCores:36> cluster=<memory:49152, vCores:96>
2013-08-11 01:53:47,239 INFO org.apache.hadoop.yarn.server.resourcemanager.rmcontainer.RMContainerImpl: container_1376185025835_0006_01_000033 Container Transitioned from NEW to ALLOCATED
2013-08-11 01:53:47,239 INFO org.apache.hadoop.yarn.server.resourcemanager.RMAuditLogger: USER=ubuntu	OPERATION=AM Allocated Container	TARGET=SchedulerApp	RESULT=SUCCESS	APPID=application_1376185025835_0006	CONTAINERID=container_1376185025835_0006_01_000033
2013-08-11 01:53:47,239 INFO org.apache.hadoop.yarn.server.resourcemanager.scheduler.common.fica.FiCaSchedulerNode: Assigned container container_1376185025835_0006_01_000033 of capacity <memory:1024, vCores:1> on host hadoop-321-7:41950, which currently has 8 containers, <memory:8192, vCores:8> used and <memory:0, vCores:8> available
2013-08-11 01:53:47,240 INFO org.apache.hadoop.yarn.server.resourcemanager.scheduler.capacity.LeafQueue: assignedContainer application=application_1376185025835_0006 container=Container: [ContainerId: container_1376185025835_0006_01_000033, NodeId: hadoop-321-7:41950, NodeHttpAddress: hadoop-321-7:8042, Resource: <memory:1024, vCores:1>, Priority: 20, State: NEW, Token: null, Status: container_id {, app_attempt_id {, application_id {, id: 6, cluster_timestamp: 1376185025835, }, attemptId: 1, }, id: 33, }, state: C_NEW, ] containerId=container_1376185025835_0006_01_000033 queue=default: capacity=1.0, absoluteCapacity=1.0, usedResources=<memory:41984, vCores:36>usedCapacity=0.8541667, absoluteUsedCapacity=0.8541667, numApps=5, numContainers=36 usedCapacity=0.8541667 absoluteUsedCapacity=0.8541667 used=<memory:41984, vCores:36> cluster=<memory:49152, vCores:96>
2013-08-11 01:53:47,240 INFO org.apache.hadoop.yarn.server.resourcemanager.scheduler.capacity.ParentQueue: Re-sorting queues since queue: root.default stats: default: capacity=1.0, absoluteCapacity=1.0, usedResources=<memory:43008, vCores:37>usedCapacity=0.875, absoluteUsedCapacity=0.875, numApps=5, numContainers=37
2013-08-11 01:53:47,241 INFO org.apache.hadoop.yarn.server.resourcemanager.scheduler.capacity.ParentQueue: assignedContainer queue=root usedCapacity=0.875 absoluteUsedCapacity=0.875 used=<memory:43008, vCores:37> cluster=<memory:49152, vCores:96>
2013-08-11 01:53:47,289 INFO org.apache.hadoop.yarn.server.resourcemanager.rmcontainer.RMContainerImpl: container_1376185025835_0006_01_000034 Container Transitioned from NEW to ALLOCATED
2013-08-11 01:53:47,289 INFO org.apache.hadoop.yarn.server.resourcemanager.RMAuditLogger: USER=ubuntu	OPERATION=AM Allocated Container	TARGET=SchedulerApp	RESULT=SUCCESS	APPID=application_1376185025835_0006	CONTAINERID=container_1376185025835_0006_01_000034
2013-08-11 01:53:47,289 INFO org.apache.hadoop.yarn.server.resourcemanager.scheduler.common.fica.FiCaSchedulerNode: Assigned container container_1376185025835_0006_01_000034 of capacity <memory:1024, vCores:1> on host hadoop-321-5:60845, which currently has 2 containers, <memory:3072, vCores:2> used and <memory:5120, vCores:14> available
2013-08-11 01:53:47,290 INFO org.apache.hadoop.yarn.server.resourcemanager.scheduler.capacity.LeafQueue: assignedContainer application=application_1376185025835_0006 container=Container: [ContainerId: container_1376185025835_0006_01_000034, NodeId: hadoop-321-5:60845, NodeHttpAddress: hadoop-321-5:8042, Resource: <memory:1024, vCores:1>, Priority: 20, State: NEW, Token: null, Status: container_id {, app_attempt_id {, application_id {, id: 6, cluster_timestamp: 1376185025835, }, attemptId: 1, }, id: 34, }, state: C_NEW, ] containerId=container_1376185025835_0006_01_000034 queue=default: capacity=1.0, absoluteCapacity=1.0, usedResources=<memory:43008, vCores:37>usedCapacity=0.875, absoluteUsedCapacity=0.875, numApps=5, numContainers=37 usedCapacity=0.875 absoluteUsedCapacity=0.875 used=<memory:43008, vCores:37> cluster=<memory:49152, vCores:96>
2013-08-11 01:53:47,290 INFO org.apache.hadoop.yarn.server.resourcemanager.scheduler.capacity.ParentQueue: Re-sorting queues since queue: root.default stats: default: capacity=1.0, absoluteCapacity=1.0, usedResources=<memory:44032, vCores:38>usedCapacity=0.8958333, absoluteUsedCapacity=0.8958333, numApps=5, numContainers=38
2013-08-11 01:53:47,291 INFO org.apache.hadoop.yarn.server.resourcemanager.scheduler.capacity.ParentQueue: assignedContainer queue=root usedCapacity=0.8958333 absoluteUsedCapacity=0.8958333 used=<memory:44032, vCores:38> cluster=<memory:49152, vCores:96>
2013-08-11 01:53:47,291 INFO org.apache.hadoop.yarn.server.resourcemanager.rmcontainer.RMContainerImpl: container_1376185025835_0006_01_000035 Container Transitioned from NEW to ALLOCATED
2013-08-11 01:53:47,291 INFO org.apache.hadoop.yarn.server.resourcemanager.RMAuditLogger: USER=ubuntu	OPERATION=AM Allocated Container	TARGET=SchedulerApp	RESULT=SUCCESS	APPID=application_1376185025835_0006	CONTAINERID=container_1376185025835_0006_01_000035
2013-08-11 01:53:47,291 INFO org.apache.hadoop.yarn.server.resourcemanager.scheduler.common.fica.FiCaSchedulerNode: Assigned container container_1376185025835_0006_01_000035 of capacity <memory:1024, vCores:1> on host hadoop-321-5:60845, which currently has 3 containers, <memory:4096, vCores:3> used and <memory:4096, vCores:13> available
2013-08-11 01:53:47,292 INFO org.apache.hadoop.yarn.server.resourcemanager.scheduler.capacity.LeafQueue: assignedContainer application=application_1376185025835_0006 container=Container: [ContainerId: container_1376185025835_0006_01_000035, NodeId: hadoop-321-5:60845, NodeHttpAddress: hadoop-321-5:8042, Resource: <memory:1024, vCores:1>, Priority: 20, State: NEW, Token: null, Status: container_id {, app_attempt_id {, application_id {, id: 6, cluster_timestamp: 1376185025835, }, attemptId: 1, }, id: 35, }, state: C_NEW, ] containerId=container_1376185025835_0006_01_000035 queue=default: capacity=1.0, absoluteCapacity=1.0, usedResources=<memory:44032, vCores:38>usedCapacity=0.8958333, absoluteUsedCapacity=0.8958333, numApps=5, numContainers=38 usedCapacity=0.8958333 absoluteUsedCapacity=0.8958333 used=<memory:44032, vCores:38> cluster=<memory:49152, vCores:96>
2013-08-11 01:53:47,293 INFO org.apache.hadoop.yarn.server.resourcemanager.scheduler.capacity.ParentQueue: Re-sorting queues since queue: root.default stats: default: capacity=1.0, absoluteCapacity=1.0, usedResources=<memory:45056, vCores:39>usedCapacity=0.9166667, absoluteUsedCapacity=0.9166667, numApps=5, numContainers=39
2013-08-11 01:53:47,293 INFO org.apache.hadoop.yarn.server.resourcemanager.scheduler.capacity.ParentQueue: assignedContainer queue=root usedCapacity=0.9166667 absoluteUsedCapacity=0.9166667 used=<memory:45056, vCores:39> cluster=<memory:49152, vCores:96>
2013-08-11 01:53:47,293 INFO org.apache.hadoop.yarn.server.resourcemanager.rmcontainer.RMContainerImpl: container_1376185025835_0006_01_000036 Container Transitioned from NEW to ALLOCATED
2013-08-11 01:53:47,293 INFO org.apache.hadoop.yarn.server.resourcemanager.RMAuditLogger: USER=ubuntu	OPERATION=AM Allocated Container	TARGET=SchedulerApp	RESULT=SUCCESS	APPID=application_1376185025835_0006	CONTAINERID=container_1376185025835_0006_01_000036
2013-08-11 01:53:47,293 INFO org.apache.hadoop.yarn.server.resourcemanager.scheduler.common.fica.FiCaSchedulerNode: Assigned container container_1376185025835_0006_01_000036 of capacity <memory:1024, vCores:1> on host hadoop-321-5:60845, which currently has 4 containers, <memory:5120, vCores:4> used and <memory:3072, vCores:12> available
2013-08-11 01:53:47,294 INFO org.apache.hadoop.yarn.server.resourcemanager.scheduler.capacity.LeafQueue: assignedContainer application=application_1376185025835_0006 container=Container: [ContainerId: container_1376185025835_0006_01_000036, NodeId: hadoop-321-5:60845, NodeHttpAddress: hadoop-321-5:8042, Resource: <memory:1024, vCores:1>, Priority: 20, State: NEW, Token: null, Status: container_id {, app_attempt_id {, application_id {, id: 6, cluster_timestamp: 1376185025835, }, attemptId: 1, }, id: 36, }, state: C_NEW, ] containerId=container_1376185025835_0006_01_000036 queue=default: capacity=1.0, absoluteCapacity=1.0, usedResources=<memory:45056, vCores:39>usedCapacity=0.9166667, absoluteUsedCapacity=0.9166667, numApps=5, numContainers=39 usedCapacity=0.9166667 absoluteUsedCapacity=0.9166667 used=<memory:45056, vCores:39> cluster=<memory:49152, vCores:96>
2013-08-11 01:53:47,295 INFO org.apache.hadoop.yarn.server.resourcemanager.scheduler.capacity.ParentQueue: Re-sorting queues since queue: root.default stats: default: capacity=1.0, absoluteCapacity=1.0, usedResources=<memory:46080, vCores:40>usedCapacity=0.9375, absoluteUsedCapacity=0.9375, numApps=5, numContainers=40
2013-08-11 01:53:47,295 INFO org.apache.hadoop.yarn.server.resourcemanager.scheduler.capacity.ParentQueue: assignedContainer queue=root usedCapacity=0.9375 absoluteUsedCapacity=0.9375 used=<memory:46080, vCores:40> cluster=<memory:49152, vCores:96>
2013-08-11 01:53:47,295 INFO org.apache.hadoop.yarn.server.resourcemanager.rmcontainer.RMContainerImpl: container_1376185025835_0006_01_000037 Container Transitioned from NEW to ALLOCATED
2013-08-11 01:53:47,296 INFO org.apache.hadoop.yarn.server.resourcemanager.RMAuditLogger: USER=ubuntu	OPERATION=AM Allocated Container	TARGET=SchedulerApp	RESULT=SUCCESS	APPID=application_1376185025835_0006	CONTAINERID=container_1376185025835_0006_01_000037
2013-08-11 01:53:47,296 INFO org.apache.hadoop.yarn.server.resourcemanager.scheduler.common.fica.FiCaSchedulerNode: Assigned container container_1376185025835_0006_01_000037 of capacity <memory:1024, vCores:1> on host hadoop-321-5:60845, which currently has 5 containers, <memory:6144, vCores:5> used and <memory:2048, vCores:11> available
2013-08-11 01:53:47,297 INFO org.apache.hadoop.yarn.server.resourcemanager.scheduler.capacity.LeafQueue: assignedContainer application=application_1376185025835_0006 container=Container: [ContainerId: container_1376185025835_0006_01_000037, NodeId: hadoop-321-5:60845, NodeHttpAddress: hadoop-321-5:8042, Resource: <memory:1024, vCores:1>, Priority: 20, State: NEW, Token: null, Status: container_id {, app_attempt_id {, application_id {, id: 6, cluster_timestamp: 1376185025835, }, attemptId: 1, }, id: 37, }, state: C_NEW, ] containerId=container_1376185025835_0006_01_000037 queue=default: capacity=1.0, absoluteCapacity=1.0, usedResources=<memory:46080, vCores:40>usedCapacity=0.9375, absoluteUsedCapacity=0.9375, numApps=5, numContainers=40 usedCapacity=0.9375 absoluteUsedCapacity=0.9375 used=<memory:46080, vCores:40> cluster=<memory:49152, vCores:96>
2013-08-11 01:53:47,297 INFO org.apache.hadoop.yarn.server.resourcemanager.scheduler.capacity.ParentQueue: Re-sorting queues since queue: root.default stats: default: capacity=1.0, absoluteCapacity=1.0, usedResources=<memory:47104, vCores:41>usedCapacity=0.9583333, absoluteUsedCapacity=0.9583333, numApps=5, numContainers=41
2013-08-11 01:53:47,297 INFO org.apache.hadoop.yarn.server.resourcemanager.scheduler.capacity.ParentQueue: assignedContainer queue=root usedCapacity=0.9583333 absoluteUsedCapacity=0.9583333 used=<memory:47104, vCores:41> cluster=<memory:49152, vCores:96>
2013-08-11 01:53:47,297 INFO org.apache.hadoop.yarn.server.resourcemanager.rmcontainer.RMContainerImpl: container_1376185025835_0006_01_000038 Container Transitioned from NEW to ALLOCATED
2013-08-11 01:53:47,298 INFO org.apache.hadoop.yarn.server.resourcemanager.RMAuditLogger: USER=ubuntu	OPERATION=AM Allocated Container	TARGET=SchedulerApp	RESULT=SUCCESS	APPID=application_1376185025835_0006	CONTAINERID=container_1376185025835_0006_01_000038
2013-08-11 01:53:47,298 INFO org.apache.hadoop.yarn.server.resourcemanager.scheduler.common.fica.FiCaSchedulerNode: Assigned container container_1376185025835_0006_01_000038 of capacity <memory:1024, vCores:1> on host hadoop-321-5:60845, which currently has 6 containers, <memory:7168, vCores:6> used and <memory:1024, vCores:10> available
2013-08-11 01:53:47,299 INFO org.apache.hadoop.yarn.server.resourcemanager.scheduler.capacity.LeafQueue: assignedContainer application=application_1376185025835_0006 container=Container: [ContainerId: container_1376185025835_0006_01_000038, NodeId: hadoop-321-5:60845, NodeHttpAddress: hadoop-321-5:8042, Resource: <memory:1024, vCores:1>, Priority: 20, State: NEW, Token: null, Status: container_id {, app_attempt_id {, application_id {, id: 6, cluster_timestamp: 1376185025835, }, attemptId: 1, }, id: 38, }, state: C_NEW, ] containerId=container_1376185025835_0006_01_000038 queue=default: capacity=1.0, absoluteCapacity=1.0, usedResources=<memory:47104, vCores:41>usedCapacity=0.9583333, absoluteUsedCapacity=0.9583333, numApps=5, numContainers=41 usedCapacity=0.9583333 absoluteUsedCapacity=0.9583333 used=<memory:47104, vCores:41> cluster=<memory:49152, vCores:96>
2013-08-11 01:53:47,299 INFO org.apache.hadoop.yarn.server.resourcemanager.scheduler.capacity.ParentQueue: Re-sorting queues since queue: root.default stats: default: capacity=1.0, absoluteCapacity=1.0, usedResources=<memory:48128, vCores:42>usedCapacity=0.9791667, absoluteUsedCapacity=0.9791667, numApps=5, numContainers=42
2013-08-11 01:53:47,299 INFO org.apache.hadoop.yarn.server.resourcemanager.scheduler.capacity.ParentQueue: assignedContainer queue=root usedCapacity=0.9791667 absoluteUsedCapacity=0.9791667 used=<memory:48128, vCores:42> cluster=<memory:49152, vCores:96>
2013-08-11 01:53:47,300 INFO org.apache.hadoop.yarn.server.resourcemanager.rmcontainer.RMContainerImpl: container_1376185025835_0006_01_000039 Container Transitioned from NEW to ALLOCATED
2013-08-11 01:53:47,300 INFO org.apache.hadoop.yarn.server.resourcemanager.RMAuditLogger: USER=ubuntu	OPERATION=AM Allocated Container	TARGET=SchedulerApp	RESULT=SUCCESS	APPID=application_1376185025835_0006	CONTAINERID=container_1376185025835_0006_01_000039
2013-08-11 01:53:47,300 INFO org.apache.hadoop.yarn.server.resourcemanager.scheduler.common.fica.FiCaSchedulerNode: Assigned container container_1376185025835_0006_01_000039 of capacity <memory:1024, vCores:1> on host hadoop-321-5:60845, which currently has 7 containers, <memory:8192, vCores:7> used and <memory:0, vCores:9> available
2013-08-11 01:53:47,301 INFO org.apache.hadoop.yarn.server.resourcemanager.scheduler.capacity.LeafQueue: assignedContainer application=application_1376185025835_0006 container=Container: [ContainerId: container_1376185025835_0006_01_000039, NodeId: hadoop-321-5:60845, NodeHttpAddress: hadoop-321-5:8042, Resource: <memory:1024, vCores:1>, Priority: 20, State: NEW, Token: null, Status: container_id {, app_attempt_id {, application_id {, id: 6, cluster_timestamp: 1376185025835, }, attemptId: 1, }, id: 39, }, state: C_NEW, ] containerId=container_1376185025835_0006_01_000039 queue=default: capacity=1.0, absoluteCapacity=1.0, usedResources=<memory:48128, vCores:42>usedCapacity=0.9791667, absoluteUsedCapacity=0.9791667, numApps=5, numContainers=42 usedCapacity=0.9791667 absoluteUsedCapacity=0.9791667 used=<memory:48128, vCores:42> cluster=<memory:49152, vCores:96>
2013-08-11 01:53:47,301 INFO org.apache.hadoop.yarn.server.resourcemanager.scheduler.capacity.ParentQueue: Re-sorting queues since queue: root.default stats: default: capacity=1.0, absoluteCapacity=1.0, usedResources=<memory:49152, vCores:43>usedCapacity=1.0, absoluteUsedCapacity=1.0, numApps=5, numContainers=43
2013-08-11 01:53:47,301 INFO org.apache.hadoop.yarn.server.resourcemanager.scheduler.capacity.ParentQueue: assignedContainer queue=root usedCapacity=1.0 absoluteUsedCapacity=1.0 used=<memory:49152, vCores:43> cluster=<memory:49152, vCores:96>
2013-08-11 01:53:47,501 INFO org.apache.hadoop.yarn.server.resourcemanager.rmcontainer.RMContainerImpl: container_1376185025835_0006_01_000002 Container Transitioned from ALLOCATED to ACQUIRED
2013-08-11 01:53:47,502 INFO org.apache.hadoop.yarn.server.resourcemanager.rmcontainer.RMContainerImpl: container_1376185025835_0006_01_000003 Container Transitioned from ALLOCATED to ACQUIRED
2013-08-11 01:53:47,503 INFO org.apache.hadoop.yarn.server.resourcemanager.rmcontainer.RMContainerImpl: container_1376185025835_0006_01_000004 Container Transitioned from ALLOCATED to ACQUIRED
2013-08-11 01:53:47,504 INFO org.apache.hadoop.yarn.server.resourcemanager.rmcontainer.RMContainerImpl: container_1376185025835_0006_01_000005 Container Transitioned from ALLOCATED to ACQUIRED
2013-08-11 01:53:47,505 INFO org.apache.hadoop.yarn.server.resourcemanager.rmcontainer.RMContainerImpl: container_1376185025835_0006_01_000006 Container Transitioned from ALLOCATED to ACQUIRED
2013-08-11 01:53:47,505 INFO org.apache.hadoop.yarn.server.resourcemanager.rmcontainer.RMContainerImpl: container_1376185025835_0006_01_000007 Container Transitioned from ALLOCATED to ACQUIRED
2013-08-11 01:53:47,506 INFO org.apache.hadoop.yarn.server.resourcemanager.rmcontainer.RMContainerImpl: container_1376185025835_0006_01_000008 Container Transitioned from ALLOCATED to ACQUIRED
2013-08-11 01:53:47,508 INFO org.apache.hadoop.yarn.server.resourcemanager.rmcontainer.RMContainerImpl: container_1376185025835_0006_01_000009 Container Transitioned from ALLOCATED to ACQUIRED
2013-08-11 01:53:47,508 INFO org.apache.hadoop.yarn.server.resourcemanager.rmcontainer.RMContainerImpl: container_1376185025835_0006_01_000010 Container Transitioned from ALLOCATED to ACQUIRED
2013-08-11 01:53:47,509 INFO org.apache.hadoop.yarn.server.resourcemanager.rmcontainer.RMContainerImpl: container_1376185025835_0006_01_000011 Container Transitioned from ALLOCATED to ACQUIRED
2013-08-11 01:53:47,510 INFO org.apache.hadoop.yarn.server.resourcemanager.rmcontainer.RMContainerImpl: container_1376185025835_0006_01_000012 Container Transitioned from ALLOCATED to ACQUIRED
2013-08-11 01:53:47,510 INFO org.apache.hadoop.yarn.server.resourcemanager.rmcontainer.RMContainerImpl: container_1376185025835_0006_01_000013 Container Transitioned from ALLOCATED to ACQUIRED
2013-08-11 01:53:47,510 INFO org.apache.hadoop.yarn.server.resourcemanager.rmcontainer.RMContainerImpl: container_1376185025835_0006_01_000014 Container Transitioned from ALLOCATED to ACQUIRED
2013-08-11 01:53:47,510 INFO org.apache.hadoop.yarn.server.resourcemanager.rmcontainer.RMContainerImpl: container_1376185025835_0006_01_000015 Container Transitioned from ALLOCATED to ACQUIRED
2013-08-11 01:53:47,510 INFO org.apache.hadoop.yarn.server.resourcemanager.rmcontainer.RMContainerImpl: container_1376185025835_0006_01_000016 Container Transitioned from ALLOCATED to ACQUIRED
2013-08-11 01:53:47,511 INFO org.apache.hadoop.yarn.server.resourcemanager.rmcontainer.RMContainerImpl: container_1376185025835_0006_01_000017 Container Transitioned from ALLOCATED to ACQUIRED
2013-08-11 01:53:47,511 INFO org.apache.hadoop.yarn.server.resourcemanager.rmcontainer.RMContainerImpl: container_1376185025835_0006_01_000018 Container Transitioned from ALLOCATED to ACQUIRED
2013-08-11 01:53:47,511 INFO org.apache.hadoop.yarn.server.resourcemanager.rmcontainer.RMContainerImpl: container_1376185025835_0006_01_000019 Container Transitioned from ALLOCATED to ACQUIRED
2013-08-11 01:53:47,511 INFO org.apache.hadoop.yarn.server.resourcemanager.rmcontainer.RMContainerImpl: container_1376185025835_0006_01_000020 Container Transitioned from ALLOCATED to ACQUIRED
2013-08-11 01:53:47,511 INFO org.apache.hadoop.yarn.server.resourcemanager.rmcontainer.RMContainerImpl: container_1376185025835_0006_01_000021 Container Transitioned from ALLOCATED to ACQUIRED
2013-08-11 01:53:47,512 INFO org.apache.hadoop.yarn.server.resourcemanager.rmcontainer.RMContainerImpl: container_1376185025835_0006_01_000022 Container Transitioned from ALLOCATED to ACQUIRED
2013-08-11 01:53:47,512 INFO org.apache.hadoop.yarn.server.resourcemanager.rmcontainer.RMContainerImpl: container_1376185025835_0006_01_000023 Container Transitioned from ALLOCATED to ACQUIRED
2013-08-11 01:53:47,512 INFO org.apache.hadoop.yarn.server.resourcemanager.rmcontainer.RMContainerImpl: container_1376185025835_0006_01_000024 Container Transitioned from ALLOCATED to ACQUIRED
2013-08-11 01:53:47,512 INFO org.apache.hadoop.yarn.server.resourcemanager.rmcontainer.RMContainerImpl: container_1376185025835_0006_01_000025 Container Transitioned from ALLOCATED to ACQUIRED
2013-08-11 01:53:47,512 INFO org.apache.hadoop.yarn.server.resourcemanager.rmcontainer.RMContainerImpl: container_1376185025835_0006_01_000026 Container Transitioned from ALLOCATED to ACQUIRED
2013-08-11 01:53:47,513 INFO org.apache.hadoop.yarn.server.resourcemanager.rmcontainer.RMContainerImpl: container_1376185025835_0006_01_000027 Container Transitioned from ALLOCATED to ACQUIRED
2013-08-11 01:53:47,513 INFO org.apache.hadoop.yarn.server.resourcemanager.rmcontainer.RMContainerImpl: container_1376185025835_0006_01_000028 Container Transitioned from ALLOCATED to ACQUIRED
2013-08-11 01:53:47,513 INFO org.apache.hadoop.yarn.server.resourcemanager.rmcontainer.RMContainerImpl: container_1376185025835_0006_01_000029 Container Transitioned from ALLOCATED to ACQUIRED
2013-08-11 01:53:47,513 INFO org.apache.hadoop.yarn.server.resourcemanager.rmcontainer.RMContainerImpl: container_1376185025835_0006_01_000030 Container Transitioned from ALLOCATED to ACQUIRED
2013-08-11 01:53:47,513 INFO org.apache.hadoop.yarn.server.resourcemanager.rmcontainer.RMContainerImpl: container_1376185025835_0006_01_000031 Container Transitioned from ALLOCATED to ACQUIRED
2013-08-11 01:53:47,514 INFO org.apache.hadoop.yarn.server.resourcemanager.rmcontainer.RMContainerImpl: container_1376185025835_0006_01_000032 Container Transitioned from ALLOCATED to ACQUIRED
2013-08-11 01:53:47,514 INFO org.apache.hadoop.yarn.server.resourcemanager.rmcontainer.RMContainerImpl: container_1376185025835_0006_01_000033 Container Transitioned from ALLOCATED to ACQUIRED
2013-08-11 01:53:47,514 INFO org.apache.hadoop.yarn.server.resourcemanager.rmcontainer.RMContainerImpl: container_1376185025835_0006_01_000034 Container Transitioned from ALLOCATED to ACQUIRED
2013-08-11 01:53:47,514 INFO org.apache.hadoop.yarn.server.resourcemanager.rmcontainer.RMContainerImpl: container_1376185025835_0006_01_000035 Container Transitioned from ALLOCATED to ACQUIRED
2013-08-11 01:53:47,514 INFO org.apache.hadoop.yarn.server.resourcemanager.rmcontainer.RMContainerImpl: container_1376185025835_0006_01_000036 Container Transitioned from ALLOCATED to ACQUIRED
2013-08-11 01:53:47,514 INFO org.apache.hadoop.yarn.server.resourcemanager.rmcontainer.RMContainerImpl: container_1376185025835_0006_01_000037 Container Transitioned from ALLOCATED to ACQUIRED
2013-08-11 01:53:47,515 INFO org.apache.hadoop.yarn.server.resourcemanager.rmcontainer.RMContainerImpl: container_1376185025835_0006_01_000038 Container Transitioned from ALLOCATED to ACQUIRED
2013-08-11 01:53:47,515 INFO org.apache.hadoop.yarn.server.resourcemanager.rmcontainer.RMContainerImpl: container_1376185025835_0006_01_000039 Container Transitioned from ALLOCATED to ACQUIRED
2013-08-11 01:53:47,707 INFO org.apache.hadoop.yarn.server.resourcemanager.ApplicationMasterService: AM registration appattempt_1376185025835_0010_000001
2013-08-11 01:53:47,707 INFO org.apache.hadoop.yarn.server.resourcemanager.RMAuditLogger: USER=ubuntu	IP=192.168.100.19	OPERATION=Register App Master	TARGET=ApplicationMasterService	RESULT=SUCCESS	APPID=application_1376185025835_0010	APPATTEMPTID=appattempt_1376185025835_0010_000001
2013-08-11 01:53:47,709 INFO org.apache.hadoop.yarn.server.resourcemanager.rmapp.attempt.RMAppAttemptImpl: appattempt_1376185025835_0010_000001 State change from LAUNCHED to RUNNING
2013-08-11 01:53:47,709 INFO org.apache.hadoop.yarn.server.resourcemanager.rmapp.RMAppImpl: application_1376185025835_0010 State change from ACCEPTED to RUNNING
2013-08-11 01:53:47,773 INFO org.apache.hadoop.yarn.server.resourcemanager.ApplicationMasterService: AM registration appattempt_1376185025835_0008_000001
2013-08-11 01:53:47,773 INFO org.apache.hadoop.yarn.server.resourcemanager.RMAuditLogger: USER=ubuntu	IP=192.168.100.22	OPERATION=Register App Master	TARGET=ApplicationMasterService	RESULT=SUCCESS	APPID=application_1376185025835_0008	APPATTEMPTID=appattempt_1376185025835_0008_000001
2013-08-11 01:53:47,774 INFO org.apache.hadoop.yarn.server.resourcemanager.rmapp.attempt.RMAppAttemptImpl: appattempt_1376185025835_0008_000001 State change from LAUNCHED to RUNNING
2013-08-11 01:53:47,774 INFO org.apache.hadoop.yarn.server.resourcemanager.rmapp.RMAppImpl: application_1376185025835_0008 State change from ACCEPTED to RUNNING
2013-08-11 01:53:48,205 INFO org.apache.hadoop.yarn.server.resourcemanager.rmcontainer.RMContainerImpl: container_1376185025835_0006_01_000020 Container Transitioned from ACQUIRED to RUNNING
2013-08-11 01:53:48,206 INFO org.apache.hadoop.yarn.server.resourcemanager.rmcontainer.RMContainerImpl: container_1376185025835_0006_01_000021 Container Transitioned from ACQUIRED to RUNNING
2013-08-11 01:53:48,207 INFO org.apache.hadoop.yarn.server.resourcemanager.rmcontainer.RMContainerImpl: container_1376185025835_0006_01_000022 Container Transitioned from ACQUIRED to RUNNING
2013-08-11 01:53:48,207 INFO org.apache.hadoop.yarn.server.resourcemanager.rmcontainer.RMContainerImpl: container_1376185025835_0006_01_000023 Container Transitioned from ACQUIRED to RUNNING
2013-08-11 01:53:48,208 INFO org.apache.hadoop.yarn.server.resourcemanager.rmcontainer.RMContainerImpl: container_1376185025835_0006_01_000024 Container Transitioned from ACQUIRED to RUNNING
2013-08-11 01:53:48,209 INFO org.apache.hadoop.yarn.server.resourcemanager.rmcontainer.RMContainerImpl: container_1376185025835_0006_01_000025 Container Transitioned from ACQUIRED to RUNNING
2013-08-11 01:53:48,252 INFO org.apache.hadoop.yarn.server.resourcemanager.rmcontainer.RMContainerImpl: container_1376185025835_0006_01_000026 Container Transitioned from ACQUIRED to RUNNING
2013-08-11 01:53:48,253 INFO org.apache.hadoop.yarn.server.resourcemanager.rmcontainer.RMContainerImpl: container_1376185025835_0006_01_000027 Container Transitioned from ACQUIRED to RUNNING
2013-08-11 01:53:48,253 INFO org.apache.hadoop.yarn.server.resourcemanager.rmcontainer.RMContainerImpl: container_1376185025835_0006_01_000028 Container Transitioned from ACQUIRED to RUNNING
2013-08-11 01:53:48,254 INFO org.apache.hadoop.yarn.server.resourcemanager.rmcontainer.RMContainerImpl: container_1376185025835_0006_01_000029 Container Transitioned from ACQUIRED to RUNNING
2013-08-11 01:53:48,255 INFO org.apache.hadoop.yarn.server.resourcemanager.rmcontainer.RMContainerImpl: container_1376185025835_0006_01_000030 Container Transitioned from ACQUIRED to RUNNING
2013-08-11 01:53:48,255 INFO org.apache.hadoop.yarn.server.resourcemanager.rmcontainer.RMContainerImpl: container_1376185025835_0006_01_000031 Container Transitioned from ACQUIRED to RUNNING
2013-08-11 01:53:48,256 INFO org.apache.hadoop.yarn.server.resourcemanager.rmcontainer.RMContainerImpl: container_1376185025835_0006_01_000032 Container Transitioned from ACQUIRED to RUNNING
2013-08-11 01:53:48,256 INFO org.apache.hadoop.yarn.server.resourcemanager.rmcontainer.RMContainerImpl: container_1376185025835_0006_01_000033 Container Transitioned from ACQUIRED to RUNNING
2013-08-11 01:53:48,276 INFO org.apache.hadoop.yarn.server.resourcemanager.ApplicationMasterService: AM registration appattempt_1376185025835_0009_000001
2013-08-11 01:53:48,277 INFO org.apache.hadoop.yarn.server.resourcemanager.RMAuditLogger: USER=ubuntu	IP=192.168.100.21	OPERATION=Register App Master	TARGET=ApplicationMasterService	RESULT=SUCCESS	APPID=application_1376185025835_0009	APPATTEMPTID=appattempt_1376185025835_0009_000001
2013-08-11 01:53:48,277 INFO org.apache.hadoop.yarn.server.resourcemanager.rmapp.attempt.RMAppAttemptImpl: appattempt_1376185025835_0009_000001 State change from LAUNCHED to RUNNING
2013-08-11 01:53:48,278 INFO org.apache.hadoop.yarn.server.resourcemanager.rmapp.RMAppImpl: application_1376185025835_0009 State change from ACCEPTED to RUNNING
2013-08-11 01:53:48,311 INFO org.apache.hadoop.yarn.server.resourcemanager.rmcontainer.RMContainerImpl: container_1376185025835_0006_01_000034 Container Transitioned from ACQUIRED to RUNNING
2013-08-11 01:53:48,312 INFO org.apache.hadoop.yarn.server.resourcemanager.rmcontainer.RMContainerImpl: container_1376185025835_0006_01_000035 Container Transitioned from ACQUIRED to RUNNING
2013-08-11 01:53:48,313 INFO org.apache.hadoop.yarn.server.resourcemanager.rmcontainer.RMContainerImpl: container_1376185025835_0006_01_000036 Container Transitioned from ACQUIRED to RUNNING
2013-08-11 01:53:48,313 INFO org.apache.hadoop.yarn.server.resourcemanager.rmcontainer.RMContainerImpl: container_1376185025835_0006_01_000037 Container Transitioned from ACQUIRED to RUNNING
2013-08-11 01:53:48,314 INFO org.apache.hadoop.yarn.server.resourcemanager.rmcontainer.RMContainerImpl: container_1376185025835_0006_01_000038 Container Transitioned from ACQUIRED to RUNNING
2013-08-11 01:53:48,316 INFO org.apache.hadoop.yarn.server.resourcemanager.rmcontainer.RMContainerImpl: container_1376185025835_0006_01_000039 Container Transitioned from ACQUIRED to RUNNING
2013-08-11 01:53:48,746 INFO org.apache.hadoop.yarn.server.resourcemanager.rmcontainer.RMContainerImpl: container_1376185025835_0006_01_000002 Container Transitioned from ACQUIRED to RUNNING
2013-08-11 01:53:48,747 INFO org.apache.hadoop.yarn.server.resourcemanager.rmcontainer.RMContainerImpl: container_1376185025835_0006_01_000003 Container Transitioned from ACQUIRED to RUNNING
2013-08-11 01:53:48,747 INFO org.apache.hadoop.yarn.server.resourcemanager.rmcontainer.RMContainerImpl: container_1376185025835_0006_01_000004 Container Transitioned from ACQUIRED to RUNNING
2013-08-11 01:53:48,747 INFO org.apache.hadoop.yarn.server.resourcemanager.rmcontainer.RMContainerImpl: container_1376185025835_0006_01_000005 Container Transitioned from ACQUIRED to RUNNING
2013-08-11 01:53:48,747 INFO org.apache.hadoop.yarn.server.resourcemanager.rmcontainer.RMContainerImpl: container_1376185025835_0006_01_000006 Container Transitioned from ACQUIRED to RUNNING
2013-08-11 01:53:48,748 INFO org.apache.hadoop.yarn.server.resourcemanager.rmcontainer.RMContainerImpl: container_1376185025835_0006_01_000007 Container Transitioned from ACQUIRED to RUNNING
2013-08-11 01:53:48,817 INFO org.apache.hadoop.yarn.server.resourcemanager.rmcontainer.RMContainerImpl: container_1376185025835_0006_01_000008 Container Transitioned from ACQUIRED to RUNNING
2013-08-11 01:53:48,817 INFO org.apache.hadoop.yarn.server.resourcemanager.rmcontainer.RMContainerImpl: container_1376185025835_0006_01_000009 Container Transitioned from ACQUIRED to RUNNING
2013-08-11 01:53:48,817 INFO org.apache.hadoop.yarn.server.resourcemanager.rmcontainer.RMContainerImpl: container_1376185025835_0006_01_000010 Container Transitioned from ACQUIRED to RUNNING
2013-08-11 01:53:48,817 INFO org.apache.hadoop.yarn.server.resourcemanager.rmcontainer.RMContainerImpl: container_1376185025835_0006_01_000011 Container Transitioned from ACQUIRED to RUNNING
2013-08-11 01:53:48,818 INFO org.apache.hadoop.yarn.server.resourcemanager.rmcontainer.RMContainerImpl: container_1376185025835_0006_01_000012 Container Transitioned from ACQUIRED to RUNNING
2013-08-11 01:53:48,818 INFO org.apache.hadoop.yarn.server.resourcemanager.rmcontainer.RMContainerImpl: container_1376185025835_0006_01_000013 Container Transitioned from ACQUIRED to RUNNING
2013-08-11 01:53:48,911 INFO org.apache.hadoop.yarn.server.resourcemanager.rmcontainer.RMContainerImpl: container_1376185025835_0006_01_000014 Container Transitioned from ACQUIRED to RUNNING
2013-08-11 01:53:48,911 INFO org.apache.hadoop.yarn.server.resourcemanager.rmcontainer.RMContainerImpl: container_1376185025835_0006_01_000015 Container Transitioned from ACQUIRED to RUNNING
2013-08-11 01:53:48,911 INFO org.apache.hadoop.yarn.server.resourcemanager.rmcontainer.RMContainerImpl: container_1376185025835_0006_01_000016 Container Transitioned from ACQUIRED to RUNNING
2013-08-11 01:53:48,911 INFO org.apache.hadoop.yarn.server.resourcemanager.rmcontainer.RMContainerImpl: container_1376185025835_0006_01_000017 Container Transitioned from ACQUIRED to RUNNING
2013-08-11 01:53:48,911 INFO org.apache.hadoop.yarn.server.resourcemanager.rmcontainer.RMContainerImpl: container_1376185025835_0006_01_000018 Container Transitioned from ACQUIRED to RUNNING
2013-08-11 01:53:48,912 INFO org.apache.hadoop.yarn.server.resourcemanager.rmcontainer.RMContainerImpl: container_1376185025835_0006_01_000019 Container Transitioned from ACQUIRED to RUNNING
2013-08-11 01:54:13,039 INFO org.apache.hadoop.yarn.server.resourcemanager.rmcontainer.RMContainerImpl: container_1376185025835_0006_01_000039 Container Transitioned from RUNNING to COMPLETED
2013-08-11 01:54:13,039 INFO org.apache.hadoop.yarn.server.resourcemanager.scheduler.common.fica.FiCaSchedulerApp: Completed container: container_1376185025835_0006_01_000039 in state: COMPLETED event:FINISHED
2013-08-11 01:54:13,039 INFO org.apache.hadoop.yarn.server.resourcemanager.RMAuditLogger: USER=ubuntu	OPERATION=AM Released Container	TARGET=SchedulerApp	RESULT=SUCCESS	APPID=application_1376185025835_0006	CONTAINERID=container_1376185025835_0006_01_000039
2013-08-11 01:54:13,040 INFO org.apache.hadoop.yarn.server.resourcemanager.scheduler.common.fica.FiCaSchedulerNode: Released container container_1376185025835_0006_01_000039 of capacity <memory:1024, vCores:1> on host hadoop-321-5:60845, which currently has 6 containers, <memory:7168, vCores:6> used and <memory:1024, vCores:10> available, release resources=true
2013-08-11 01:54:13,040 INFO org.apache.hadoop.yarn.server.resourcemanager.scheduler.capacity.LeafQueue: default used=<memory:48128, vCores:42> numContainers=42 user=ubuntu user-resources=<memory:48128, vCores:42>
2013-08-11 01:54:13,042 INFO org.apache.hadoop.yarn.server.resourcemanager.scheduler.capacity.LeafQueue: completedContainer container=Container: [ContainerId: container_1376185025835_0006_01_000039, NodeId: hadoop-321-5:60845, NodeHttpAddress: hadoop-321-5:8042, Resource: <memory:1024, vCores:1>, Priority: 20, State: NEW, Token: null, Status: container_id {, app_attempt_id {, application_id {, id: 6, cluster_timestamp: 1376185025835, }, attemptId: 1, }, id: 39, }, state: C_COMPLETE, diagnostics: "Container killed by the ApplicationMaster.\n\n", exit_status: 143, ] resource=<memory:1024, vCores:1> queue=default: capacity=1.0, absoluteCapacity=1.0, usedResources=<memory:48128, vCores:42>usedCapacity=0.9791667, absoluteUsedCapacity=0.9791667, numApps=5, numContainers=42 usedCapacity=0.9791667 absoluteUsedCapacity=0.9791667 used=<memory:48128, vCores:42> cluster=<memory:49152, vCores:96>
2013-08-11 01:54:13,043 INFO org.apache.hadoop.yarn.server.resourcemanager.scheduler.capacity.ParentQueue: completedContainer queue=root usedCapacity=0.9791667 absoluteUsedCapacity=0.9791667 used=<memory:48128, vCores:42> cluster=<memory:49152, vCores:96>
2013-08-11 01:54:13,043 INFO org.apache.hadoop.yarn.server.resourcemanager.scheduler.capacity.CapacityScheduler: Application appattempt_1376185025835_0006_000001 released container container_1376185025835_0006_01_000039 on node: host: hadoop-321-5:60845 #containers=6 available=1024 used=7168 with event: FINISHED
2013-08-11 01:54:13,043 INFO org.apache.hadoop.yarn.server.resourcemanager.rmcontainer.RMContainerImpl: container_1376185025835_0006_01_000040 Container Transitioned from NEW to ALLOCATED
2013-08-11 01:54:13,043 INFO org.apache.hadoop.yarn.server.resourcemanager.RMAuditLogger: USER=ubuntu	OPERATION=AM Allocated Container	TARGET=SchedulerApp	RESULT=SUCCESS	APPID=application_1376185025835_0006	CONTAINERID=container_1376185025835_0006_01_000040
2013-08-11 01:54:13,044 INFO org.apache.hadoop.yarn.server.resourcemanager.scheduler.common.fica.FiCaSchedulerNode: Assigned container container_1376185025835_0006_01_000040 of capacity <memory:1024, vCores:1> on host hadoop-321-5:60845, which currently has 7 containers, <memory:8192, vCores:7> used and <memory:0, vCores:9> available
2013-08-11 01:54:13,044 INFO org.apache.hadoop.yarn.server.resourcemanager.scheduler.capacity.LeafQueue: assignedContainer application=application_1376185025835_0006 container=Container: [ContainerId: container_1376185025835_0006_01_000040, NodeId: hadoop-321-5:60845, NodeHttpAddress: hadoop-321-5:8042, Resource: <memory:1024, vCores:1>, Priority: 20, State: NEW, Token: null, Status: container_id {, app_attempt_id {, application_id {, id: 6, cluster_timestamp: 1376185025835, }, attemptId: 1, }, id: 40, }, state: C_NEW, ] containerId=container_1376185025835_0006_01_000040 queue=default: capacity=1.0, absoluteCapacity=1.0, usedResources=<memory:48128, vCores:42>usedCapacity=0.9791667, absoluteUsedCapacity=0.9791667, numApps=5, numContainers=42 usedCapacity=0.9791667 absoluteUsedCapacity=0.9791667 used=<memory:48128, vCores:42> cluster=<memory:49152, vCores:96>
2013-08-11 01:54:13,045 INFO org.apache.hadoop.yarn.server.resourcemanager.scheduler.capacity.ParentQueue: Re-sorting queues since queue: root.default stats: default: capacity=1.0, absoluteCapacity=1.0, usedResources=<memory:49152, vCores:43>usedCapacity=1.0, absoluteUsedCapacity=1.0, numApps=5, numContainers=43
2013-08-11 01:54:13,045 INFO org.apache.hadoop.yarn.server.resourcemanager.scheduler.capacity.ParentQueue: assignedContainer queue=root usedCapacity=1.0 absoluteUsedCapacity=1.0 used=<memory:49152, vCores:43> cluster=<memory:49152, vCores:96>
2013-08-11 01:54:13,743 INFO org.apache.hadoop.yarn.server.resourcemanager.rmcontainer.RMContainerImpl: container_1376185025835_0006_01_000040 Container Transitioned from ALLOCATED to ACQUIRED
2013-08-11 01:54:14,314 INFO org.apache.hadoop.yarn.server.resourcemanager.rmcontainer.RMContainerImpl: container_1376185025835_0006_01_000002 Container Transitioned from RUNNING to COMPLETED
2013-08-11 01:54:14,314 INFO org.apache.hadoop.yarn.server.resourcemanager.scheduler.common.fica.FiCaSchedulerApp: Completed container: container_1376185025835_0006_01_000002 in state: COMPLETED event:FINISHED
2013-08-11 01:54:14,314 INFO org.apache.hadoop.yarn.server.resourcemanager.RMAuditLogger: USER=ubuntu	OPERATION=AM Released Container	TARGET=SchedulerApp	RESULT=SUCCESS	APPID=application_1376185025835_0006	CONTAINERID=container_1376185025835_0006_01_000002
2013-08-11 01:54:14,314 INFO org.apache.hadoop.yarn.server.resourcemanager.scheduler.common.fica.FiCaSchedulerNode: Released container container_1376185025835_0006_01_000002 of capacity <memory:1024, vCores:1> on host hadoop-321-2:46202, which currently has 6 containers, <memory:7168, vCores:6> used and <memory:1024, vCores:10> available, release resources=true
2013-08-11 01:54:14,315 INFO org.apache.hadoop.yarn.server.resourcemanager.scheduler.capacity.LeafQueue: default used=<memory:48128, vCores:42> numContainers=42 user=ubuntu user-resources=<memory:48128, vCores:42>
2013-08-11 01:54:14,316 INFO org.apache.hadoop.yarn.server.resourcemanager.scheduler.capacity.LeafQueue: completedContainer container=Container: [ContainerId: container_1376185025835_0006_01_000002, NodeId: hadoop-321-2:46202, NodeHttpAddress: hadoop-321-2:8042, Resource: <memory:1024, vCores:1>, Priority: 20, State: NEW, Token: null, Status: container_id {, app_attempt_id {, application_id {, id: 6, cluster_timestamp: 1376185025835, }, attemptId: 1, }, id: 2, }, state: C_COMPLETE, diagnostics: "Container killed by the ApplicationMaster.\n\n", exit_status: 143, ] resource=<memory:1024, vCores:1> queue=default: capacity=1.0, absoluteCapacity=1.0, usedResources=<memory:48128, vCores:42>usedCapacity=0.9791667, absoluteUsedCapacity=0.9791667, numApps=5, numContainers=42 usedCapacity=0.9791667 absoluteUsedCapacity=0.9791667 used=<memory:48128, vCores:42> cluster=<memory:49152, vCores:96>
2013-08-11 01:54:14,316 INFO org.apache.hadoop.yarn.server.resourcemanager.scheduler.capacity.ParentQueue: completedContainer queue=root usedCapacity=0.9791667 absoluteUsedCapacity=0.9791667 used=<memory:48128, vCores:42> cluster=<memory:49152, vCores:96>
2013-08-11 01:54:14,316 INFO org.apache.hadoop.yarn.server.resourcemanager.scheduler.capacity.CapacityScheduler: Application appattempt_1376185025835_0006_000001 released container container_1376185025835_0006_01_000002 on node: host: hadoop-321-2:46202 #containers=6 available=1024 used=7168 with event: FINISHED
2013-08-11 01:54:14,317 INFO org.apache.hadoop.yarn.server.resourcemanager.rmcontainer.RMContainerImpl: container_1376185025835_0006_01_000041 Container Transitioned from NEW to ALLOCATED
2013-08-11 01:54:14,317 INFO org.apache.hadoop.yarn.server.resourcemanager.RMAuditLogger: USER=ubuntu	OPERATION=AM Allocated Container	TARGET=SchedulerApp	RESULT=SUCCESS	APPID=application_1376185025835_0006	CONTAINERID=container_1376185025835_0006_01_000041
2013-08-11 01:54:14,317 INFO org.apache.hadoop.yarn.server.resourcemanager.scheduler.common.fica.FiCaSchedulerNode: Assigned container container_1376185025835_0006_01_000041 of capacity <memory:1024, vCores:1> on host hadoop-321-2:46202, which currently has 7 containers, <memory:8192, vCores:7> used and <memory:0, vCores:9> available
2013-08-11 01:54:14,318 INFO org.apache.hadoop.yarn.server.resourcemanager.scheduler.capacity.LeafQueue: assignedContainer application=application_1376185025835_0006 container=Container: [ContainerId: container_1376185025835_0006_01_000041, NodeId: hadoop-321-2:46202, NodeHttpAddress: hadoop-321-2:8042, Resource: <memory:1024, vCores:1>, Priority: 10, State: NEW, Token: null, Status: container_id {, app_attempt_id {, application_id {, id: 6, cluster_timestamp: 1376185025835, }, attemptId: 1, }, id: 41, }, state: C_NEW, ] containerId=container_1376185025835_0006_01_000041 queue=default: capacity=1.0, absoluteCapacity=1.0, usedResources=<memory:48128, vCores:42>usedCapacity=0.9791667, absoluteUsedCapacity=0.9791667, numApps=5, numContainers=42 usedCapacity=0.9791667 absoluteUsedCapacity=0.9791667 used=<memory:48128, vCores:42> cluster=<memory:49152, vCores:96>
2013-08-11 01:54:14,318 INFO org.apache.hadoop.yarn.server.resourcemanager.scheduler.capacity.ParentQueue: Re-sorting queues since queue: root.default stats: default: capacity=1.0, absoluteCapacity=1.0, usedResources=<memory:49152, vCores:43>usedCapacity=1.0, absoluteUsedCapacity=1.0, numApps=5, numContainers=43
2013-08-11 01:54:14,318 INFO org.apache.hadoop.yarn.server.resourcemanager.scheduler.capacity.ParentQueue: assignedContainer queue=root usedCapacity=1.0 absoluteUsedCapacity=1.0 used=<memory:49152, vCores:43> cluster=<memory:49152, vCores:96>
2013-08-11 01:54:15,172 INFO org.apache.hadoop.yarn.server.resourcemanager.rmcontainer.RMContainerImpl: container_1376185025835_0006_01_000040 Container Transitioned from ACQUIRED to RUNNING
2013-08-11 01:54:15,316 INFO org.apache.hadoop.yarn.server.resourcemanager.rmcontainer.RMContainerImpl: container_1376185025835_0006_01_000041 Container Transitioned from ALLOCATED to ACQUIRED
2013-08-11 01:54:15,705 INFO org.apache.hadoop.yarn.server.resourcemanager.rmcontainer.RMContainerImpl: container_1376185025835_0006_01_000041 Container Transitioned from ACQUIRED to RUNNING
2013-08-11 01:54:15,705 INFO org.apache.hadoop.yarn.server.resourcemanager.rmcontainer.RMContainerImpl: container_1376185025835_0006_01_000005 Container Transitioned from RUNNING to COMPLETED
2013-08-11 01:54:15,705 INFO org.apache.hadoop.yarn.server.resourcemanager.scheduler.common.fica.FiCaSchedulerApp: Completed container: container_1376185025835_0006_01_000005 in state: COMPLETED event:FINISHED
2013-08-11 01:54:15,706 INFO org.apache.hadoop.yarn.server.resourcemanager.RMAuditLogger: USER=ubuntu	OPERATION=AM Released Container	TARGET=SchedulerApp	RESULT=SUCCESS	APPID=application_1376185025835_0006	CONTAINERID=container_1376185025835_0006_01_000005
2013-08-11 01:54:15,706 INFO org.apache.hadoop.yarn.server.resourcemanager.scheduler.common.fica.FiCaSchedulerNode: Released container container_1376185025835_0006_01_000005 of capacity <memory:1024, vCores:1> on host hadoop-321-2:46202, which currently has 6 containers, <memory:7168, vCores:6> used and <memory:1024, vCores:10> available, release resources=true
2013-08-11 01:54:15,706 INFO org.apache.hadoop.yarn.server.resourcemanager.scheduler.capacity.LeafQueue: default used=<memory:48128, vCores:42> numContainers=42 user=ubuntu user-resources=<memory:48128, vCores:42>
2013-08-11 01:54:15,707 INFO org.apache.hadoop.yarn.server.resourcemanager.scheduler.capacity.LeafQueue: completedContainer container=Container: [ContainerId: container_1376185025835_0006_01_000005, NodeId: hadoop-321-2:46202, NodeHttpAddress: hadoop-321-2:8042, Resource: <memory:1024, vCores:1>, Priority: 20, State: NEW, Token: null, Status: container_id {, app_attempt_id {, application_id {, id: 6, cluster_timestamp: 1376185025835, }, attemptId: 1, }, id: 5, }, state: C_COMPLETE, diagnostics: "Container killed by the ApplicationMaster.\n\n", exit_status: 143, ] resource=<memory:1024, vCores:1> queue=default: capacity=1.0, absoluteCapacity=1.0, usedResources=<memory:48128, vCores:42>usedCapacity=0.9791667, absoluteUsedCapacity=0.9791667, numApps=5, numContainers=42 usedCapacity=0.9791667 absoluteUsedCapacity=0.9791667 used=<memory:48128, vCores:42> cluster=<memory:49152, vCores:96>
2013-08-11 01:54:15,707 INFO org.apache.hadoop.yarn.server.resourcemanager.scheduler.capacity.ParentQueue: completedContainer queue=root usedCapacity=0.9791667 absoluteUsedCapacity=0.9791667 used=<memory:48128, vCores:42> cluster=<memory:49152, vCores:96>
2013-08-11 01:54:15,708 INFO org.apache.hadoop.yarn.server.resourcemanager.scheduler.capacity.CapacityScheduler: Application appattempt_1376185025835_0006_000001 released container container_1376185025835_0006_01_000005 on node: host: hadoop-321-2:46202 #containers=6 available=1024 used=7168 with event: FINISHED
2013-08-11 01:54:15,708 INFO org.apache.hadoop.yarn.server.resourcemanager.rmcontainer.RMContainerImpl: container_1376185025835_0006_01_000042 Container Transitioned from NEW to ALLOCATED
2013-08-11 01:54:15,708 INFO org.apache.hadoop.yarn.server.resourcemanager.RMAuditLogger: USER=ubuntu	OPERATION=AM Allocated Container	TARGET=SchedulerApp	RESULT=SUCCESS	APPID=application_1376185025835_0006	CONTAINERID=container_1376185025835_0006_01_000042
2013-08-11 01:54:15,708 INFO org.apache.hadoop.yarn.server.resourcemanager.scheduler.common.fica.FiCaSchedulerNode: Assigned container container_1376185025835_0006_01_000042 of capacity <memory:1024, vCores:1> on host hadoop-321-2:46202, which currently has 7 containers, <memory:8192, vCores:7> used and <memory:0, vCores:9> available
2013-08-11 01:54:15,709 INFO org.apache.hadoop.yarn.server.resourcemanager.scheduler.capacity.LeafQueue: assignedContainer application=application_1376185025835_0006 container=Container: [ContainerId: container_1376185025835_0006_01_000042, NodeId: hadoop-321-2:46202, NodeHttpAddress: hadoop-321-2:8042, Resource: <memory:1024, vCores:1>, Priority: 20, State: NEW, Token: null, Status: container_id {, app_attempt_id {, application_id {, id: 6, cluster_timestamp: 1376185025835, }, attemptId: 1, }, id: 42, }, state: C_NEW, ] containerId=container_1376185025835_0006_01_000042 queue=default: capacity=1.0, absoluteCapacity=1.0, usedResources=<memory:48128, vCores:42>usedCapacity=0.9791667, absoluteUsedCapacity=0.9791667, numApps=5, numContainers=42 usedCapacity=0.9791667 absoluteUsedCapacity=0.9791667 used=<memory:48128, vCores:42> cluster=<memory:49152, vCores:96>
2013-08-11 01:54:15,709 INFO org.apache.hadoop.yarn.server.resourcemanager.scheduler.capacity.ParentQueue: Re-sorting queues since queue: root.default stats: default: capacity=1.0, absoluteCapacity=1.0, usedResources=<memory:49152, vCores:43>usedCapacity=1.0, absoluteUsedCapacity=1.0, numApps=5, numContainers=43
2013-08-11 01:54:15,710 INFO org.apache.hadoop.yarn.server.resourcemanager.scheduler.capacity.ParentQueue: assignedContainer queue=root usedCapacity=1.0 absoluteUsedCapacity=1.0 used=<memory:49152, vCores:43> cluster=<memory:49152, vCores:96>
2013-08-11 01:54:16,335 INFO org.apache.hadoop.yarn.server.resourcemanager.rmcontainer.RMContainerImpl: container_1376185025835_0006_01_000042 Container Transitioned from ALLOCATED to ACQUIRED
2013-08-11 01:54:16,729 INFO org.apache.hadoop.yarn.server.resourcemanager.rmcontainer.RMContainerImpl: container_1376185025835_0006_01_000042 Container Transitioned from ACQUIRED to RUNNING
2013-08-11 01:54:17,370 INFO org.apache.hadoop.yarn.server.resourcemanager.rmcontainer.RMContainerImpl: container_1376185025835_0006_01_000031 Container Transitioned from RUNNING to COMPLETED
2013-08-11 01:54:17,370 INFO org.apache.hadoop.yarn.server.resourcemanager.scheduler.common.fica.FiCaSchedulerApp: Completed container: container_1376185025835_0006_01_000031 in state: COMPLETED event:FINISHED
2013-08-11 01:54:17,371 INFO org.apache.hadoop.yarn.server.resourcemanager.RMAuditLogger: USER=ubuntu	OPERATION=AM Released Container	TARGET=SchedulerApp	RESULT=SUCCESS	APPID=application_1376185025835_0006	CONTAINERID=container_1376185025835_0006_01_000031
2013-08-11 01:54:17,371 INFO org.apache.hadoop.yarn.server.resourcemanager.scheduler.common.fica.FiCaSchedulerNode: Released container container_1376185025835_0006_01_000031 of capacity <memory:1024, vCores:1> on host hadoop-321-7:41950, which currently has 7 containers, <memory:7168, vCores:7> used and <memory:1024, vCores:9> available, release resources=true
2013-08-11 01:54:17,371 INFO org.apache.hadoop.yarn.server.resourcemanager.scheduler.capacity.LeafQueue: default used=<memory:48128, vCores:42> numContainers=42 user=ubuntu user-resources=<memory:48128, vCores:42>
2013-08-11 01:54:17,372 INFO org.apache.hadoop.yarn.server.resourcemanager.scheduler.capacity.LeafQueue: completedContainer container=Container: [ContainerId: container_1376185025835_0006_01_000031, NodeId: hadoop-321-7:41950, NodeHttpAddress: hadoop-321-7:8042, Resource: <memory:1024, vCores:1>, Priority: 20, State: NEW, Token: null, Status: container_id {, app_attempt_id {, application_id {, id: 6, cluster_timestamp: 1376185025835, }, attemptId: 1, }, id: 31, }, state: C_COMPLETE, diagnostics: "Container killed by the ApplicationMaster.\n", exit_status: 0, ] resource=<memory:1024, vCores:1> queue=default: capacity=1.0, absoluteCapacity=1.0, usedResources=<memory:48128, vCores:42>usedCapacity=0.9791667, absoluteUsedCapacity=0.9791667, numApps=5, numContainers=42 usedCapacity=0.9791667 absoluteUsedCapacity=0.9791667 used=<memory:48128, vCores:42> cluster=<memory:49152, vCores:96>
2013-08-11 01:54:17,372 INFO org.apache.hadoop.yarn.server.resourcemanager.scheduler.capacity.ParentQueue: completedContainer queue=root usedCapacity=0.9791667 absoluteUsedCapacity=0.9791667 used=<memory:48128, vCores:42> cluster=<memory:49152, vCores:96>
2013-08-11 01:54:17,372 INFO org.apache.hadoop.yarn.server.resourcemanager.scheduler.capacity.CapacityScheduler: Application appattempt_1376185025835_0006_000001 released container container_1376185025835_0006_01_000031 on node: host: hadoop-321-7:41950 #containers=7 available=1024 used=7168 with event: FINISHED
2013-08-11 01:54:17,373 INFO org.apache.hadoop.yarn.server.resourcemanager.rmcontainer.RMContainerImpl: container_1376185025835_0006_01_000043 Container Transitioned from NEW to ALLOCATED
2013-08-11 01:54:17,373 INFO org.apache.hadoop.yarn.server.resourcemanager.RMAuditLogger: USER=ubuntu	OPERATION=AM Allocated Container	TARGET=SchedulerApp	RESULT=SUCCESS	APPID=application_1376185025835_0006	CONTAINERID=container_1376185025835_0006_01_000043
2013-08-11 01:54:17,373 INFO org.apache.hadoop.yarn.server.resourcemanager.scheduler.common.fica.FiCaSchedulerNode: Assigned container container_1376185025835_0006_01_000043 of capacity <memory:1024, vCores:1> on host hadoop-321-7:41950, which currently has 8 containers, <memory:8192, vCores:8> used and <memory:0, vCores:8> available
2013-08-11 01:54:17,374 INFO org.apache.hadoop.yarn.server.resourcemanager.scheduler.capacity.LeafQueue: assignedContainer application=application_1376185025835_0006 container=Container: [ContainerId: container_1376185025835_0006_01_000043, NodeId: hadoop-321-7:41950, NodeHttpAddress: hadoop-321-7:8042, Resource: <memory:1024, vCores:1>, Priority: 10, State: NEW, Token: null, Status: container_id {, app_attempt_id {, application_id {, id: 6, cluster_timestamp: 1376185025835, }, attemptId: 1, }, id: 43, }, state: C_NEW, ] containerId=container_1376185025835_0006_01_000043 queue=default: capacity=1.0, absoluteCapacity=1.0, usedResources=<memory:48128, vCores:42>usedCapacity=0.9791667, absoluteUsedCapacity=0.9791667, numApps=5, numContainers=42 usedCapacity=0.9791667 absoluteUsedCapacity=0.9791667 used=<memory:48128, vCores:42> cluster=<memory:49152, vCores:96>
2013-08-11 01:54:17,374 INFO org.apache.hadoop.yarn.server.resourcemanager.scheduler.capacity.ParentQueue: Re-sorting queues since queue: root.default stats: default: capacity=1.0, absoluteCapacity=1.0, usedResources=<memory:49152, vCores:43>usedCapacity=1.0, absoluteUsedCapacity=1.0, numApps=5, numContainers=43
2013-08-11 01:54:17,374 INFO org.apache.hadoop.yarn.server.resourcemanager.scheduler.capacity.ParentQueue: assignedContainer queue=root usedCapacity=1.0 absoluteUsedCapacity=1.0 used=<memory:49152, vCores:43> cluster=<memory:49152, vCores:96>
2013-08-11 01:54:18,968 INFO org.apache.hadoop.yarn.server.resourcemanager.scheduler.AppSchedulingInfo: checking for deactivate... 
2013-08-11 01:54:18,970 INFO org.apache.hadoop.yarn.server.resourcemanager.rmcontainer.RMContainerImpl: container_1376185025835_0006_01_000043 Container Transitioned from ALLOCATED to ACQUIRED
2013-08-11 01:54:19,274 INFO org.apache.hadoop.yarn.server.resourcemanager.rmcontainer.RMContainerImpl: container_1376185025835_0006_01_000043 Container Transitioned from ACQUIRED to RUNNING
2013-08-11 01:54:20,128 INFO org.apache.hadoop.yarn.server.resourcemanager.rmcontainer.RMContainerImpl: container_1376185025835_0006_01_000009 Container Transitioned from RUNNING to COMPLETED
2013-08-11 01:54:20,128 INFO org.apache.hadoop.yarn.server.resourcemanager.scheduler.common.fica.FiCaSchedulerApp: Completed container: container_1376185025835_0006_01_000009 in state: COMPLETED event:FINISHED
2013-08-11 01:54:20,128 INFO org.apache.hadoop.yarn.server.resourcemanager.RMAuditLogger: USER=ubuntu	OPERATION=AM Released Container	TARGET=SchedulerApp	RESULT=SUCCESS	APPID=application_1376185025835_0006	CONTAINERID=container_1376185025835_0006_01_000009
2013-08-11 01:54:20,128 INFO org.apache.hadoop.yarn.server.resourcemanager.scheduler.common.fica.FiCaSchedulerNode: Released container container_1376185025835_0006_01_000009 of capacity <memory:1024, vCores:1> on host hadoop-321-3:44876, which currently has 6 containers, <memory:7168, vCores:6> used and <memory:1024, vCores:10> available, release resources=true
2013-08-11 01:54:20,129 INFO org.apache.hadoop.yarn.server.resourcemanager.scheduler.capacity.LeafQueue: default used=<memory:48128, vCores:42> numContainers=42 user=ubuntu user-resources=<memory:48128, vCores:42>
2013-08-11 01:54:20,130 INFO org.apache.hadoop.yarn.server.resourcemanager.scheduler.capacity.LeafQueue: completedContainer container=Container: [ContainerId: container_1376185025835_0006_01_000009, NodeId: hadoop-321-3:44876, NodeHttpAddress: hadoop-321-3:8042, Resource: <memory:1024, vCores:1>, Priority: 20, State: NEW, Token: null, Status: container_id {, app_attempt_id {, application_id {, id: 6, cluster_timestamp: 1376185025835, }, attemptId: 1, }, id: 9, }, state: C_COMPLETE, diagnostics: "", exit_status: 0, ] resource=<memory:1024, vCores:1> queue=default: capacity=1.0, absoluteCapacity=1.0, usedResources=<memory:48128, vCores:42>usedCapacity=0.9791667, absoluteUsedCapacity=0.9791667, numApps=5, numContainers=42 usedCapacity=0.9791667 absoluteUsedCapacity=0.9791667 used=<memory:48128, vCores:42> cluster=<memory:49152, vCores:96>
2013-08-11 01:54:20,130 INFO org.apache.hadoop.yarn.server.resourcemanager.scheduler.capacity.ParentQueue: completedContainer queue=root usedCapacity=0.9791667 absoluteUsedCapacity=0.9791667 used=<memory:48128, vCores:42> cluster=<memory:49152, vCores:96>
2013-08-11 01:54:20,130 INFO org.apache.hadoop.yarn.server.resourcemanager.scheduler.capacity.CapacityScheduler: Application appattempt_1376185025835_0006_000001 released container container_1376185025835_0006_01_000009 on node: host: hadoop-321-3:44876 #containers=6 available=1024 used=7168 with event: FINISHED
2013-08-11 01:54:20,131 INFO org.apache.hadoop.yarn.server.resourcemanager.rmcontainer.RMContainerImpl: container_1376185025835_0006_01_000013 Container Transitioned from RUNNING to COMPLETED
2013-08-11 01:54:20,131 INFO org.apache.hadoop.yarn.server.resourcemanager.scheduler.common.fica.FiCaSchedulerApp: Completed container: container_1376185025835_0006_01_000013 in state: COMPLETED event:FINISHED
2013-08-11 01:54:20,131 INFO org.apache.hadoop.yarn.server.resourcemanager.RMAuditLogger: USER=ubuntu	OPERATION=AM Released Container	TARGET=SchedulerApp	RESULT=SUCCESS	APPID=application_1376185025835_0006	CONTAINERID=container_1376185025835_0006_01_000013
2013-08-11 01:54:20,131 INFO org.apache.hadoop.yarn.server.resourcemanager.scheduler.common.fica.FiCaSchedulerNode: Released container container_1376185025835_0006_01_000013 of capacity <memory:1024, vCores:1> on host hadoop-321-3:44876, which currently has 5 containers, <memory:6144, vCores:5> used and <memory:2048, vCores:11> available, release resources=true
2013-08-11 01:54:20,131 INFO org.apache.hadoop.yarn.server.resourcemanager.scheduler.capacity.LeafQueue: default used=<memory:47104, vCores:41> numContainers=41 user=ubuntu user-resources=<memory:47104, vCores:41>
2013-08-11 01:54:20,132 INFO org.apache.hadoop.yarn.server.resourcemanager.scheduler.capacity.LeafQueue: completedContainer container=Container: [ContainerId: container_1376185025835_0006_01_000013, NodeId: hadoop-321-3:44876, NodeHttpAddress: hadoop-321-3:8042, Resource: <memory:1024, vCores:1>, Priority: 20, State: NEW, Token: null, Status: container_id {, app_attempt_id {, application_id {, id: 6, cluster_timestamp: 1376185025835, }, attemptId: 1, }, id: 13, }, state: C_COMPLETE, diagnostics: "", exit_status: 0, ] resource=<memory:1024, vCores:1> queue=default: capacity=1.0, absoluteCapacity=1.0, usedResources=<memory:47104, vCores:41>usedCapacity=0.9583333, absoluteUsedCapacity=0.9583333, numApps=5, numContainers=41 usedCapacity=0.9583333 absoluteUsedCapacity=0.9583333 used=<memory:47104, vCores:41> cluster=<memory:49152, vCores:96>
2013-08-11 01:54:20,132 INFO org.apache.hadoop.yarn.server.resourcemanager.scheduler.capacity.ParentQueue: completedContainer queue=root usedCapacity=0.9583333 absoluteUsedCapacity=0.9583333 used=<memory:47104, vCores:41> cluster=<memory:49152, vCores:96>
2013-08-11 01:54:20,132 INFO org.apache.hadoop.yarn.server.resourcemanager.scheduler.capacity.CapacityScheduler: Application appattempt_1376185025835_0006_000001 released container container_1376185025835_0006_01_000013 on node: host: hadoop-321-3:44876 #containers=5 available=2048 used=6144 with event: FINISHED
2013-08-11 01:54:20,133 INFO org.apache.hadoop.yarn.server.resourcemanager.rmcontainer.RMContainerImpl: container_1376185025835_0006_01_000044 Container Transitioned from NEW to ALLOCATED
2013-08-11 01:54:20,133 INFO org.apache.hadoop.yarn.server.resourcemanager.RMAuditLogger: USER=ubuntu	OPERATION=AM Allocated Container	TARGET=SchedulerApp	RESULT=SUCCESS	APPID=application_1376185025835_0006	CONTAINERID=container_1376185025835_0006_01_000044
2013-08-11 01:54:20,133 INFO org.apache.hadoop.yarn.server.resourcemanager.scheduler.common.fica.FiCaSchedulerNode: Assigned container container_1376185025835_0006_01_000044 of capacity <memory:1024, vCores:1> on host hadoop-321-3:44876, which currently has 6 containers, <memory:7168, vCores:6> used and <memory:1024, vCores:10> available
2013-08-11 01:54:20,134 INFO org.apache.hadoop.yarn.server.resourcemanager.scheduler.capacity.LeafQueue: assignedContainer application=application_1376185025835_0006 container=Container: [ContainerId: container_1376185025835_0006_01_000044, NodeId: hadoop-321-3:44876, NodeHttpAddress: hadoop-321-3:8042, Resource: <memory:1024, vCores:1>, Priority: 10, State: NEW, Token: null, Status: container_id {, app_attempt_id {, application_id {, id: 6, cluster_timestamp: 1376185025835, }, attemptId: 1, }, id: 44, }, state: C_NEW, ] containerId=container_1376185025835_0006_01_000044 queue=default: capacity=1.0, absoluteCapacity=1.0, usedResources=<memory:47104, vCores:41>usedCapacity=0.9583333, absoluteUsedCapacity=0.9583333, numApps=5, numContainers=41 usedCapacity=0.9583333 absoluteUsedCapacity=0.9583333 used=<memory:47104, vCores:41> cluster=<memory:49152, vCores:96>
2013-08-11 01:54:20,134 INFO org.apache.hadoop.yarn.server.resourcemanager.scheduler.capacity.ParentQueue: Re-sorting queues since queue: root.default stats: default: capacity=1.0, absoluteCapacity=1.0, usedResources=<memory:48128, vCores:42>usedCapacity=0.9791667, absoluteUsedCapacity=0.9791667, numApps=5, numContainers=42
2013-08-11 01:54:20,134 INFO org.apache.hadoop.yarn.server.resourcemanager.scheduler.capacity.ParentQueue: assignedContainer queue=root usedCapacity=0.9791667 absoluteUsedCapacity=0.9791667 used=<memory:48128, vCores:42> cluster=<memory:49152, vCores:96>
2013-08-11 01:54:20,286 INFO org.apache.hadoop.yarn.server.resourcemanager.rmcontainer.RMContainerImpl: container_1376185025835_0006_01_000027 Container Transitioned from RUNNING to COMPLETED
2013-08-11 01:54:20,286 INFO org.apache.hadoop.yarn.server.resourcemanager.scheduler.common.fica.FiCaSchedulerApp: Completed container: container_1376185025835_0006_01_000027 in state: COMPLETED event:FINISHED
2013-08-11 01:54:20,286 INFO org.apache.hadoop.yarn.server.resourcemanager.RMAuditLogger: USER=ubuntu	OPERATION=AM Released Container	TARGET=SchedulerApp	RESULT=SUCCESS	APPID=application_1376185025835_0006	CONTAINERID=container_1376185025835_0006_01_000027
2013-08-11 01:54:20,287 INFO org.apache.hadoop.yarn.server.resourcemanager.scheduler.common.fica.FiCaSchedulerNode: Released container container_1376185025835_0006_01_000027 of capacity <memory:1024, vCores:1> on host hadoop-321-7:41950, which currently has 7 containers, <memory:7168, vCores:7> used and <memory:1024, vCores:9> available, release resources=true
2013-08-11 01:54:20,287 INFO org.apache.hadoop.yarn.server.resourcemanager.scheduler.capacity.LeafQueue: default used=<memory:47104, vCores:41> numContainers=41 user=ubuntu user-resources=<memory:47104, vCores:41>
2013-08-11 01:54:20,288 INFO org.apache.hadoop.yarn.server.resourcemanager.scheduler.capacity.LeafQueue: completedContainer container=Container: [ContainerId: container_1376185025835_0006_01_000027, NodeId: hadoop-321-7:41950, NodeHttpAddress: hadoop-321-7:8042, Resource: <memory:1024, vCores:1>, Priority: 20, State: NEW, Token: null, Status: container_id {, app_attempt_id {, application_id {, id: 6, cluster_timestamp: 1376185025835, }, attemptId: 1, }, id: 27, }, state: C_COMPLETE, diagnostics: "Container killed by the ApplicationMaster.\n\n", exit_status: 143, ] resource=<memory:1024, vCores:1> queue=default: capacity=1.0, absoluteCapacity=1.0, usedResources=<memory:47104, vCores:41>usedCapacity=0.9583333, absoluteUsedCapacity=0.9583333, numApps=5, numContainers=41 usedCapacity=0.9583333 absoluteUsedCapacity=0.9583333 used=<memory:47104, vCores:41> cluster=<memory:49152, vCores:96>
2013-08-11 01:54:20,288 INFO org.apache.hadoop.yarn.server.resourcemanager.scheduler.capacity.ParentQueue: completedContainer queue=root usedCapacity=0.9583333 absoluteUsedCapacity=0.9583333 used=<memory:47104, vCores:41> cluster=<memory:49152, vCores:96>
2013-08-11 01:54:20,288 INFO org.apache.hadoop.yarn.server.resourcemanager.scheduler.capacity.CapacityScheduler: Application appattempt_1376185025835_0006_000001 released container container_1376185025835_0006_01_000027 on node: host: hadoop-321-7:41950 #containers=7 available=1024 used=7168 with event: FINISHED
2013-08-11 01:54:20,288 INFO org.apache.hadoop.yarn.server.resourcemanager.rmcontainer.RMContainerImpl: container_1376185025835_0006_01_000029 Container Transitioned from RUNNING to COMPLETED
2013-08-11 01:54:20,288 INFO org.apache.hadoop.yarn.server.resourcemanager.scheduler.common.fica.FiCaSchedulerApp: Completed container: container_1376185025835_0006_01_000029 in state: COMPLETED event:FINISHED
2013-08-11 01:54:20,289 INFO org.apache.hadoop.yarn.server.resourcemanager.RMAuditLogger: USER=ubuntu	OPERATION=AM Released Container	TARGET=SchedulerApp	RESULT=SUCCESS	APPID=application_1376185025835_0006	CONTAINERID=container_1376185025835_0006_01_000029
2013-08-11 01:54:20,289 INFO org.apache.hadoop.yarn.server.resourcemanager.scheduler.common.fica.FiCaSchedulerNode: Released container container_1376185025835_0006_01_000029 of capacity <memory:1024, vCores:1> on host hadoop-321-7:41950, which currently has 6 containers, <memory:6144, vCores:6> used and <memory:2048, vCores:10> available, release resources=true
2013-08-11 01:54:20,289 INFO org.apache.hadoop.yarn.server.resourcemanager.scheduler.capacity.LeafQueue: default used=<memory:46080, vCores:40> numContainers=40 user=ubuntu user-resources=<memory:46080, vCores:40>
2013-08-11 01:54:20,290 INFO org.apache.hadoop.yarn.server.resourcemanager.scheduler.capacity.LeafQueue: completedContainer container=Container: [ContainerId: container_1376185025835_0006_01_000029, NodeId: hadoop-321-7:41950, NodeHttpAddress: hadoop-321-7:8042, Resource: <memory:1024, vCores:1>, Priority: 20, State: NEW, Token: null, Status: container_id {, app_attempt_id {, application_id {, id: 6, cluster_timestamp: 1376185025835, }, attemptId: 1, }, id: 29, }, state: C_COMPLETE, diagnostics: "Container killed by the ApplicationMaster.\n", exit_status: 0, ] resource=<memory:1024, vCores:1> queue=default: capacity=1.0, absoluteCapacity=1.0, usedResources=<memory:46080, vCores:40>usedCapacity=0.9375, absoluteUsedCapacity=0.9375, numApps=5, numContainers=40 usedCapacity=0.9375 absoluteUsedCapacity=0.9375 used=<memory:46080, vCores:40> cluster=<memory:49152, vCores:96>
2013-08-11 01:54:20,290 INFO org.apache.hadoop.yarn.server.resourcemanager.scheduler.capacity.ParentQueue: completedContainer queue=root usedCapacity=0.9375 absoluteUsedCapacity=0.9375 used=<memory:46080, vCores:40> cluster=<memory:49152, vCores:96>
2013-08-11 01:54:20,290 INFO org.apache.hadoop.yarn.server.resourcemanager.scheduler.capacity.CapacityScheduler: Application appattempt_1376185025835_0006_000001 released container container_1376185025835_0006_01_000029 on node: host: hadoop-321-7:41950 #containers=6 available=2048 used=6144 with event: FINISHED
2013-08-11 01:54:20,290 INFO org.apache.hadoop.yarn.server.resourcemanager.rmcontainer.RMContainerImpl: container_1376185025835_0006_01_000045 Container Transitioned from NEW to ALLOCATED
2013-08-11 01:54:20,291 INFO org.apache.hadoop.yarn.server.resourcemanager.RMAuditLogger: USER=ubuntu	OPERATION=AM Allocated Container	TARGET=SchedulerApp	RESULT=SUCCESS	APPID=application_1376185025835_0006	CONTAINERID=container_1376185025835_0006_01_000045
2013-08-11 01:54:20,291 INFO org.apache.hadoop.yarn.server.resourcemanager.scheduler.common.fica.FiCaSchedulerNode: Assigned container container_1376185025835_0006_01_000045 of capacity <memory:1024, vCores:1> on host hadoop-321-7:41950, which currently has 7 containers, <memory:7168, vCores:7> used and <memory:1024, vCores:9> available
2013-08-11 01:54:20,292 INFO org.apache.hadoop.yarn.server.resourcemanager.scheduler.capacity.LeafQueue: assignedContainer application=application_1376185025835_0006 container=Container: [ContainerId: container_1376185025835_0006_01_000045, NodeId: hadoop-321-7:41950, NodeHttpAddress: hadoop-321-7:8042, Resource: <memory:1024, vCores:1>, Priority: 10, State: NEW, Token: null, Status: container_id {, app_attempt_id {, application_id {, id: 6, cluster_timestamp: 1376185025835, }, attemptId: 1, }, id: 45, }, state: C_NEW, ] containerId=container_1376185025835_0006_01_000045 queue=default: capacity=1.0, absoluteCapacity=1.0, usedResources=<memory:46080, vCores:40>usedCapacity=0.9375, absoluteUsedCapacity=0.9375, numApps=5, numContainers=40 usedCapacity=0.9375 absoluteUsedCapacity=0.9375 used=<memory:46080, vCores:40> cluster=<memory:49152, vCores:96>
2013-08-11 01:54:20,292 INFO org.apache.hadoop.yarn.server.resourcemanager.scheduler.capacity.ParentQueue: Re-sorting queues since queue: root.default stats: default: capacity=1.0, absoluteCapacity=1.0, usedResources=<memory:47104, vCores:41>usedCapacity=0.9583333, absoluteUsedCapacity=0.9583333, numApps=5, numContainers=41
2013-08-11 01:54:20,292 INFO org.apache.hadoop.yarn.server.resourcemanager.scheduler.capacity.ParentQueue: assignedContainer queue=root usedCapacity=0.9583333 absoluteUsedCapacity=0.9583333 used=<memory:47104, vCores:41> cluster=<memory:49152, vCores:96>
2013-08-11 01:54:20,344 INFO org.apache.hadoop.yarn.server.resourcemanager.rmcontainer.RMContainerImpl: container_1376185025835_0006_01_000022 Container Transitioned from RUNNING to COMPLETED
2013-08-11 01:54:20,344 INFO org.apache.hadoop.yarn.server.resourcemanager.scheduler.common.fica.FiCaSchedulerApp: Completed container: container_1376185025835_0006_01_000022 in state: COMPLETED event:FINISHED
2013-08-11 01:54:20,344 INFO org.apache.hadoop.yarn.server.resourcemanager.RMAuditLogger: USER=ubuntu	OPERATION=AM Released Container	TARGET=SchedulerApp	RESULT=SUCCESS	APPID=application_1376185025835_0006	CONTAINERID=container_1376185025835_0006_01_000022
2013-08-11 01:54:20,344 INFO org.apache.hadoop.yarn.server.resourcemanager.scheduler.common.fica.FiCaSchedulerNode: Released container container_1376185025835_0006_01_000022 of capacity <memory:1024, vCores:1> on host hadoop-321-4:43757, which currently has 6 containers, <memory:7168, vCores:6> used and <memory:1024, vCores:10> available, release resources=true
2013-08-11 01:54:20,344 INFO org.apache.hadoop.yarn.server.resourcemanager.scheduler.capacity.LeafQueue: default used=<memory:46080, vCores:40> numContainers=40 user=ubuntu user-resources=<memory:46080, vCores:40>
2013-08-11 01:54:20,345 INFO org.apache.hadoop.yarn.server.resourcemanager.scheduler.capacity.LeafQueue: completedContainer container=Container: [ContainerId: container_1376185025835_0006_01_000022, NodeId: hadoop-321-4:43757, NodeHttpAddress: hadoop-321-4:8042, Resource: <memory:1024, vCores:1>, Priority: 20, State: NEW, Token: null, Status: container_id {, app_attempt_id {, application_id {, id: 6, cluster_timestamp: 1376185025835, }, attemptId: 1, }, id: 22, }, state: C_COMPLETE, diagnostics: "Container killed by the ApplicationMaster.\n", exit_status: 0, ] resource=<memory:1024, vCores:1> queue=default: capacity=1.0, absoluteCapacity=1.0, usedResources=<memory:46080, vCores:40>usedCapacity=0.9375, absoluteUsedCapacity=0.9375, numApps=5, numContainers=40 usedCapacity=0.9375 absoluteUsedCapacity=0.9375 used=<memory:46080, vCores:40> cluster=<memory:49152, vCores:96>
2013-08-11 01:54:20,346 INFO org.apache.hadoop.yarn.server.resourcemanager.scheduler.capacity.ParentQueue: completedContainer queue=root usedCapacity=0.9375 absoluteUsedCapacity=0.9375 used=<memory:46080, vCores:40> cluster=<memory:49152, vCores:96>
2013-08-11 01:54:20,346 INFO org.apache.hadoop.yarn.server.resourcemanager.scheduler.capacity.CapacityScheduler: Application appattempt_1376185025835_0006_000001 released container container_1376185025835_0006_01_000022 on node: host: hadoop-321-4:43757 #containers=6 available=1024 used=7168 with event: FINISHED
2013-08-11 01:54:20,346 INFO org.apache.hadoop.yarn.server.resourcemanager.rmcontainer.RMContainerImpl: container_1376185025835_0006_01_000024 Container Transitioned from RUNNING to COMPLETED
2013-08-11 01:54:20,346 INFO org.apache.hadoop.yarn.server.resourcemanager.scheduler.common.fica.FiCaSchedulerApp: Completed container: container_1376185025835_0006_01_000024 in state: COMPLETED event:FINISHED
2013-08-11 01:54:20,346 INFO org.apache.hadoop.yarn.server.resourcemanager.RMAuditLogger: USER=ubuntu	OPERATION=AM Released Container	TARGET=SchedulerApp	RESULT=SUCCESS	APPID=application_1376185025835_0006	CONTAINERID=container_1376185025835_0006_01_000024
2013-08-11 01:54:20,346 INFO org.apache.hadoop.yarn.server.resourcemanager.scheduler.common.fica.FiCaSchedulerNode: Released container container_1376185025835_0006_01_000024 of capacity <memory:1024, vCores:1> on host hadoop-321-4:43757, which currently has 5 containers, <memory:6144, vCores:5> used and <memory:2048, vCores:11> available, release resources=true
2013-08-11 01:54:20,346 INFO org.apache.hadoop.yarn.server.resourcemanager.scheduler.capacity.LeafQueue: default used=<memory:45056, vCores:39> numContainers=39 user=ubuntu user-resources=<memory:45056, vCores:39>
2013-08-11 01:54:20,347 INFO org.apache.hadoop.yarn.server.resourcemanager.scheduler.capacity.LeafQueue: completedContainer container=Container: [ContainerId: container_1376185025835_0006_01_000024, NodeId: hadoop-321-4:43757, NodeHttpAddress: hadoop-321-4:8042, Resource: <memory:1024, vCores:1>, Priority: 20, State: NEW, Token: null, Status: container_id {, app_attempt_id {, application_id {, id: 6, cluster_timestamp: 1376185025835, }, attemptId: 1, }, id: 24, }, state: C_COMPLETE, diagnostics: "Container killed by the ApplicationMaster.\n", exit_status: 0, ] resource=<memory:1024, vCores:1> queue=default: capacity=1.0, absoluteCapacity=1.0, usedResources=<memory:45056, vCores:39>usedCapacity=0.9166667, absoluteUsedCapacity=0.9166667, numApps=5, numContainers=39 usedCapacity=0.9166667 absoluteUsedCapacity=0.9166667 used=<memory:45056, vCores:39> cluster=<memory:49152, vCores:96>
2013-08-11 01:54:20,347 INFO org.apache.hadoop.yarn.server.resourcemanager.scheduler.capacity.ParentQueue: completedContainer queue=root usedCapacity=0.9166667 absoluteUsedCapacity=0.9166667 used=<memory:45056, vCores:39> cluster=<memory:49152, vCores:96>
2013-08-11 01:54:20,348 INFO org.apache.hadoop.yarn.server.resourcemanager.scheduler.capacity.CapacityScheduler: Application appattempt_1376185025835_0006_000001 released container container_1376185025835_0006_01_000024 on node: host: hadoop-321-4:43757 #containers=5 available=2048 used=6144 with event: FINISHED
2013-08-11 01:54:20,348 INFO org.apache.hadoop.yarn.server.resourcemanager.rmcontainer.RMContainerImpl: container_1376185025835_0006_01_000025 Container Transitioned from RUNNING to COMPLETED
2013-08-11 01:54:20,348 INFO org.apache.hadoop.yarn.server.resourcemanager.scheduler.common.fica.FiCaSchedulerApp: Completed container: container_1376185025835_0006_01_000025 in state: COMPLETED event:FINISHED
2013-08-11 01:54:20,348 INFO org.apache.hadoop.yarn.server.resourcemanager.RMAuditLogger: USER=ubuntu	OPERATION=AM Released Container	TARGET=SchedulerApp	RESULT=SUCCESS	APPID=application_1376185025835_0006	CONTAINERID=container_1376185025835_0006_01_000025
2013-08-11 01:54:20,348 INFO org.apache.hadoop.yarn.server.resourcemanager.scheduler.common.fica.FiCaSchedulerNode: Released container container_1376185025835_0006_01_000025 of capacity <memory:1024, vCores:1> on host hadoop-321-4:43757, which currently has 4 containers, <memory:5120, vCores:4> used and <memory:3072, vCores:12> available, release resources=true
2013-08-11 01:54:20,348 INFO org.apache.hadoop.yarn.server.resourcemanager.scheduler.capacity.LeafQueue: default used=<memory:44032, vCores:38> numContainers=38 user=ubuntu user-resources=<memory:44032, vCores:38>
2013-08-11 01:54:20,349 INFO org.apache.hadoop.yarn.server.resourcemanager.scheduler.capacity.LeafQueue: completedContainer container=Container: [ContainerId: container_1376185025835_0006_01_000025, NodeId: hadoop-321-4:43757, NodeHttpAddress: hadoop-321-4:8042, Resource: <memory:1024, vCores:1>, Priority: 20, State: NEW, Token: null, Status: container_id {, app_attempt_id {, application_id {, id: 6, cluster_timestamp: 1376185025835, }, attemptId: 1, }, id: 25, }, state: C_COMPLETE, diagnostics: "Container killed by the ApplicationMaster.\n", exit_status: 0, ] resource=<memory:1024, vCores:1> queue=default: capacity=1.0, absoluteCapacity=1.0, usedResources=<memory:44032, vCores:38>usedCapacity=0.8958333, absoluteUsedCapacity=0.8958333, numApps=5, numContainers=38 usedCapacity=0.8958333 absoluteUsedCapacity=0.8958333 used=<memory:44032, vCores:38> cluster=<memory:49152, vCores:96>
2013-08-11 01:54:20,349 INFO org.apache.hadoop.yarn.server.resourcemanager.scheduler.capacity.ParentQueue: completedContainer queue=root usedCapacity=0.8958333 absoluteUsedCapacity=0.8958333 used=<memory:44032, vCores:38> cluster=<memory:49152, vCores:96>
2013-08-11 01:54:20,349 INFO org.apache.hadoop.yarn.server.resourcemanager.scheduler.capacity.CapacityScheduler: Application appattempt_1376185025835_0006_000001 released container container_1376185025835_0006_01_000025 on node: host: hadoop-321-4:43757 #containers=4 available=3072 used=5120 with event: FINISHED
2013-08-11 01:54:20,350 INFO org.apache.hadoop.yarn.server.resourcemanager.rmcontainer.RMContainerImpl: container_1376185025835_0006_01_000046 Container Transitioned from NEW to ALLOCATED
2013-08-11 01:54:20,350 INFO org.apache.hadoop.yarn.server.resourcemanager.RMAuditLogger: USER=ubuntu	OPERATION=AM Allocated Container	TARGET=SchedulerApp	RESULT=SUCCESS	APPID=application_1376185025835_0006	CONTAINERID=container_1376185025835_0006_01_000046
2013-08-11 01:54:20,350 INFO org.apache.hadoop.yarn.server.resourcemanager.scheduler.common.fica.FiCaSchedulerNode: Assigned container container_1376185025835_0006_01_000046 of capacity <memory:1024, vCores:1> on host hadoop-321-4:43757, which currently has 5 containers, <memory:6144, vCores:5> used and <memory:2048, vCores:11> available
2013-08-11 01:54:20,351 INFO org.apache.hadoop.yarn.server.resourcemanager.scheduler.capacity.LeafQueue: assignedContainer application=application_1376185025835_0006 container=Container: [ContainerId: container_1376185025835_0006_01_000046, NodeId: hadoop-321-4:43757, NodeHttpAddress: hadoop-321-4:8042, Resource: <memory:1024, vCores:1>, Priority: 10, State: NEW, Token: null, Status: container_id {, app_attempt_id {, application_id {, id: 6, cluster_timestamp: 1376185025835, }, attemptId: 1, }, id: 46, }, state: C_NEW, ] containerId=container_1376185025835_0006_01_000046 queue=default: capacity=1.0, absoluteCapacity=1.0, usedResources=<memory:44032, vCores:38>usedCapacity=0.8958333, absoluteUsedCapacity=0.8958333, numApps=5, numContainers=38 usedCapacity=0.8958333 absoluteUsedCapacity=0.8958333 used=<memory:44032, vCores:38> cluster=<memory:49152, vCores:96>
2013-08-11 01:54:20,351 INFO org.apache.hadoop.yarn.server.resourcemanager.scheduler.capacity.ParentQueue: Re-sorting queues since queue: root.default stats: default: capacity=1.0, absoluteCapacity=1.0, usedResources=<memory:45056, vCores:39>usedCapacity=0.9166667, absoluteUsedCapacity=0.9166667, numApps=5, numContainers=39
2013-08-11 01:54:20,351 INFO org.apache.hadoop.yarn.server.resourcemanager.scheduler.capacity.ParentQueue: assignedContainer queue=root usedCapacity=0.9166667 absoluteUsedCapacity=0.9166667 used=<memory:45056, vCores:39> cluster=<memory:49152, vCores:96>
2013-08-11 01:54:20,700 INFO org.apache.hadoop.yarn.server.resourcemanager.rmcontainer.RMContainerImpl: container_1376185025835_0006_01_000018 Container Transitioned from RUNNING to COMPLETED
2013-08-11 01:54:20,700 INFO org.apache.hadoop.yarn.server.resourcemanager.scheduler.common.fica.FiCaSchedulerApp: Completed container: container_1376185025835_0006_01_000018 in state: COMPLETED event:FINISHED
2013-08-11 01:54:20,700 INFO org.apache.hadoop.yarn.server.resourcemanager.RMAuditLogger: USER=ubuntu	OPERATION=AM Released Container	TARGET=SchedulerApp	RESULT=SUCCESS	APPID=application_1376185025835_0006	CONTAINERID=container_1376185025835_0006_01_000018
2013-08-11 01:54:20,700 INFO org.apache.hadoop.yarn.server.resourcemanager.scheduler.common.fica.FiCaSchedulerNode: Released container container_1376185025835_0006_01_000018 of capacity <memory:1024, vCores:1> on host hadoop-321-6:34867, which currently has 6 containers, <memory:7168, vCores:6> used and <memory:1024, vCores:10> available, release resources=true
2013-08-11 01:54:20,700 INFO org.apache.hadoop.yarn.server.resourcemanager.scheduler.capacity.LeafQueue: default used=<memory:44032, vCores:38> numContainers=38 user=ubuntu user-resources=<memory:44032, vCores:38>
2013-08-11 01:54:20,702 INFO org.apache.hadoop.yarn.server.resourcemanager.scheduler.capacity.LeafQueue: completedContainer container=Container: [ContainerId: container_1376185025835_0006_01_000018, NodeId: hadoop-321-6:34867, NodeHttpAddress: hadoop-321-6:8042, Resource: <memory:1024, vCores:1>, Priority: 20, State: NEW, Token: null, Status: container_id {, app_attempt_id {, application_id {, id: 6, cluster_timestamp: 1376185025835, }, attemptId: 1, }, id: 18, }, state: C_COMPLETE, diagnostics: "Container killed by the ApplicationMaster.\n", exit_status: 0, ] resource=<memory:1024, vCores:1> queue=default: capacity=1.0, absoluteCapacity=1.0, usedResources=<memory:44032, vCores:38>usedCapacity=0.8958333, absoluteUsedCapacity=0.8958333, numApps=5, numContainers=38 usedCapacity=0.8958333 absoluteUsedCapacity=0.8958333 used=<memory:44032, vCores:38> cluster=<memory:49152, vCores:96>
2013-08-11 01:54:20,702 INFO org.apache.hadoop.yarn.server.resourcemanager.scheduler.capacity.ParentQueue: completedContainer queue=root usedCapacity=0.8958333 absoluteUsedCapacity=0.8958333 used=<memory:44032, vCores:38> cluster=<memory:49152, vCores:96>
2013-08-11 01:54:20,702 INFO org.apache.hadoop.yarn.server.resourcemanager.scheduler.capacity.CapacityScheduler: Application appattempt_1376185025835_0006_000001 released container container_1376185025835_0006_01_000018 on node: host: hadoop-321-6:34867 #containers=6 available=1024 used=7168 with event: FINISHED
2013-08-11 01:54:20,702 INFO org.apache.hadoop.yarn.server.resourcemanager.rmcontainer.RMContainerImpl: container_1376185025835_0006_01_000047 Container Transitioned from NEW to ALLOCATED
2013-08-11 01:54:20,703 INFO org.apache.hadoop.yarn.server.resourcemanager.RMAuditLogger: USER=ubuntu	OPERATION=AM Allocated Container	TARGET=SchedulerApp	RESULT=SUCCESS	APPID=application_1376185025835_0006	CONTAINERID=container_1376185025835_0006_01_000047
2013-08-11 01:54:20,703 INFO org.apache.hadoop.yarn.server.resourcemanager.scheduler.common.fica.FiCaSchedulerNode: Assigned container container_1376185025835_0006_01_000047 of capacity <memory:1024, vCores:1> on host hadoop-321-6:34867, which currently has 7 containers, <memory:8192, vCores:7> used and <memory:0, vCores:9> available
2013-08-11 01:54:20,704 INFO org.apache.hadoop.yarn.server.resourcemanager.scheduler.capacity.LeafQueue: assignedContainer application=application_1376185025835_0006 container=Container: [ContainerId: container_1376185025835_0006_01_000047, NodeId: hadoop-321-6:34867, NodeHttpAddress: hadoop-321-6:8042, Resource: <memory:1024, vCores:1>, Priority: 20, State: NEW, Token: null, Status: container_id {, app_attempt_id {, application_id {, id: 6, cluster_timestamp: 1376185025835, }, attemptId: 1, }, id: 47, }, state: C_NEW, ] containerId=container_1376185025835_0006_01_000047 queue=default: capacity=1.0, absoluteCapacity=1.0, usedResources=<memory:44032, vCores:38>usedCapacity=0.8958333, absoluteUsedCapacity=0.8958333, numApps=5, numContainers=38 usedCapacity=0.8958333 absoluteUsedCapacity=0.8958333 used=<memory:44032, vCores:38> cluster=<memory:49152, vCores:96>
2013-08-11 01:54:20,704 INFO org.apache.hadoop.yarn.server.resourcemanager.scheduler.capacity.ParentQueue: Re-sorting queues since queue: root.default stats: default: capacity=1.0, absoluteCapacity=1.0, usedResources=<memory:45056, vCores:39>usedCapacity=0.9166667, absoluteUsedCapacity=0.9166667, numApps=5, numContainers=39
2013-08-11 01:54:20,704 INFO org.apache.hadoop.yarn.server.resourcemanager.scheduler.capacity.ParentQueue: assignedContainer queue=root usedCapacity=0.9166667 absoluteUsedCapacity=0.9166667 used=<memory:45056, vCores:39> cluster=<memory:49152, vCores:96>
2013-08-11 01:54:20,799 INFO org.apache.hadoop.yarn.server.resourcemanager.rmcontainer.RMContainerImpl: container_1376185025835_0006_01_000003 Container Transitioned from RUNNING to COMPLETED
2013-08-11 01:54:20,799 INFO org.apache.hadoop.yarn.server.resourcemanager.scheduler.common.fica.FiCaSchedulerApp: Completed container: container_1376185025835_0006_01_000003 in state: COMPLETED event:FINISHED
2013-08-11 01:54:20,799 INFO org.apache.hadoop.yarn.server.resourcemanager.RMAuditLogger: USER=ubuntu	OPERATION=AM Released Container	TARGET=SchedulerApp	RESULT=SUCCESS	APPID=application_1376185025835_0006	CONTAINERID=container_1376185025835_0006_01_000003
2013-08-11 01:54:20,800 INFO org.apache.hadoop.yarn.server.resourcemanager.scheduler.common.fica.FiCaSchedulerNode: Released container container_1376185025835_0006_01_000003 of capacity <memory:1024, vCores:1> on host hadoop-321-2:46202, which currently has 6 containers, <memory:7168, vCores:6> used and <memory:1024, vCores:10> available, release resources=true
2013-08-11 01:54:20,800 INFO org.apache.hadoop.yarn.server.resourcemanager.scheduler.capacity.LeafQueue: default used=<memory:44032, vCores:38> numContainers=38 user=ubuntu user-resources=<memory:44032, vCores:38>
2013-08-11 01:54:20,801 INFO org.apache.hadoop.yarn.server.resourcemanager.scheduler.capacity.LeafQueue: completedContainer container=Container: [ContainerId: container_1376185025835_0006_01_000003, NodeId: hadoop-321-2:46202, NodeHttpAddress: hadoop-321-2:8042, Resource: <memory:1024, vCores:1>, Priority: 20, State: NEW, Token: null, Status: container_id {, app_attempt_id {, application_id {, id: 6, cluster_timestamp: 1376185025835, }, attemptId: 1, }, id: 3, }, state: C_COMPLETE, diagnostics: "Container killed by the ApplicationMaster.\n\n", exit_status: 143, ] resource=<memory:1024, vCores:1> queue=default: capacity=1.0, absoluteCapacity=1.0, usedResources=<memory:44032, vCores:38>usedCapacity=0.8958333, absoluteUsedCapacity=0.8958333, numApps=5, numContainers=38 usedCapacity=0.8958333 absoluteUsedCapacity=0.8958333 used=<memory:44032, vCores:38> cluster=<memory:49152, vCores:96>
2013-08-11 01:54:20,801 INFO org.apache.hadoop.yarn.server.resourcemanager.scheduler.capacity.ParentQueue: completedContainer queue=root usedCapacity=0.8958333 absoluteUsedCapacity=0.8958333 used=<memory:44032, vCores:38> cluster=<memory:49152, vCores:96>
2013-08-11 01:54:20,801 INFO org.apache.hadoop.yarn.server.resourcemanager.scheduler.capacity.CapacityScheduler: Application appattempt_1376185025835_0006_000001 released container container_1376185025835_0006_01_000003 on node: host: hadoop-321-2:46202 #containers=6 available=1024 used=7168 with event: FINISHED
2013-08-11 01:54:20,802 INFO org.apache.hadoop.yarn.server.resourcemanager.rmcontainer.RMContainerImpl: container_1376185025835_0007_01_000002 Container Transitioned from NEW to ALLOCATED
2013-08-11 01:54:20,802 INFO org.apache.hadoop.yarn.server.resourcemanager.RMAuditLogger: USER=ubuntu	OPERATION=AM Allocated Container	TARGET=SchedulerApp	RESULT=SUCCESS	APPID=application_1376185025835_0007	CONTAINERID=container_1376185025835_0007_01_000002
2013-08-11 01:54:20,802 INFO org.apache.hadoop.yarn.server.resourcemanager.scheduler.common.fica.FiCaSchedulerNode: Assigned container container_1376185025835_0007_01_000002 of capacity <memory:1024, vCores:1> on host hadoop-321-2:46202, which currently has 7 containers, <memory:8192, vCores:7> used and <memory:0, vCores:9> available
2013-08-11 01:54:20,803 INFO org.apache.hadoop.yarn.server.resourcemanager.scheduler.capacity.LeafQueue: assignedContainer application=application_1376185025835_0007 container=Container: [ContainerId: container_1376185025835_0007_01_000002, NodeId: hadoop-321-2:46202, NodeHttpAddress: hadoop-321-2:8042, Resource: <memory:1024, vCores:1>, Priority: 20, State: NEW, Token: null, Status: container_id {, app_attempt_id {, application_id {, id: 7, cluster_timestamp: 1376185025835, }, attemptId: 1, }, id: 2, }, state: C_NEW, ] containerId=container_1376185025835_0007_01_000002 queue=default: capacity=1.0, absoluteCapacity=1.0, usedResources=<memory:44032, vCores:38>usedCapacity=0.8958333, absoluteUsedCapacity=0.8958333, numApps=5, numContainers=38 usedCapacity=0.8958333 absoluteUsedCapacity=0.8958333 used=<memory:44032, vCores:38> cluster=<memory:49152, vCores:96>
2013-08-11 01:54:20,803 INFO org.apache.hadoop.yarn.server.resourcemanager.scheduler.capacity.ParentQueue: Re-sorting queues since queue: root.default stats: default: capacity=1.0, absoluteCapacity=1.0, usedResources=<memory:45056, vCores:39>usedCapacity=0.9166667, absoluteUsedCapacity=0.9166667, numApps=5, numContainers=39
2013-08-11 01:54:20,803 INFO org.apache.hadoop.yarn.server.resourcemanager.rmcontainer.RMContainerImpl: container_1376185025835_0007_01_000002 Container Transitioned from ALLOCATED to ACQUIRED
2013-08-11 01:54:20,808 INFO org.apache.hadoop.yarn.server.resourcemanager.scheduler.capacity.ParentQueue: assignedContainer queue=root usedCapacity=0.9166667 absoluteUsedCapacity=0.9166667 used=<memory:45056, vCores:39> cluster=<memory:49152, vCores:96>
2013-08-11 01:54:20,817 INFO org.apache.hadoop.yarn.server.resourcemanager.rmcontainer.RMContainerImpl: container_1376185025835_0006_01_000015 Container Transitioned from RUNNING to COMPLETED
2013-08-11 01:54:20,817 INFO org.apache.hadoop.yarn.server.resourcemanager.scheduler.common.fica.FiCaSchedulerApp: Completed container: container_1376185025835_0006_01_000015 in state: COMPLETED event:FINISHED
2013-08-11 01:54:20,818 INFO org.apache.hadoop.yarn.server.resourcemanager.RMAuditLogger: USER=ubuntu	OPERATION=AM Released Container	TARGET=SchedulerApp	RESULT=SUCCESS	APPID=application_1376185025835_0006	CONTAINERID=container_1376185025835_0006_01_000015
2013-08-11 01:54:20,818 INFO org.apache.hadoop.yarn.server.resourcemanager.scheduler.common.fica.FiCaSchedulerNode: Released container container_1376185025835_0006_01_000015 of capacity <memory:1024, vCores:1> on host hadoop-321-6:34867, which currently has 6 containers, <memory:7168, vCores:6> used and <memory:1024, vCores:10> available, release resources=true
2013-08-11 01:54:20,818 INFO org.apache.hadoop.yarn.server.resourcemanager.scheduler.capacity.LeafQueue: default used=<memory:44032, vCores:38> numContainers=38 user=ubuntu user-resources=<memory:44032, vCores:38>
2013-08-11 01:54:20,819 INFO org.apache.hadoop.yarn.server.resourcemanager.scheduler.capacity.LeafQueue: completedContainer container=Container: [ContainerId: container_1376185025835_0006_01_000015, NodeId: hadoop-321-6:34867, NodeHttpAddress: hadoop-321-6:8042, Resource: <memory:1024, vCores:1>, Priority: 20, State: NEW, Token: null, Status: container_id {, app_attempt_id {, application_id {, id: 6, cluster_timestamp: 1376185025835, }, attemptId: 1, }, id: 15, }, state: C_COMPLETE, diagnostics: "Container killed by the ApplicationMaster.\n\n", exit_status: 143, ] resource=<memory:1024, vCores:1> queue=default: capacity=1.0, absoluteCapacity=1.0, usedResources=<memory:44032, vCores:38>usedCapacity=0.8958333, absoluteUsedCapacity=0.8958333, numApps=5, numContainers=38 usedCapacity=0.8958333 absoluteUsedCapacity=0.8958333 used=<memory:44032, vCores:38> cluster=<memory:49152, vCores:96>
2013-08-11 01:54:20,819 INFO org.apache.hadoop.yarn.server.resourcemanager.scheduler.capacity.ParentQueue: completedContainer queue=root usedCapacity=0.8958333 absoluteUsedCapacity=0.8958333 used=<memory:44032, vCores:38> cluster=<memory:49152, vCores:96>
2013-08-11 01:54:20,819 INFO org.apache.hadoop.yarn.server.resourcemanager.scheduler.capacity.CapacityScheduler: Application appattempt_1376185025835_0006_000001 released container container_1376185025835_0006_01_000015 on node: host: hadoop-321-6:34867 #containers=6 available=1024 used=7168 with event: FINISHED
2013-08-11 01:54:20,820 INFO org.apache.hadoop.yarn.server.resourcemanager.rmcontainer.RMContainerImpl: container_1376185025835_0007_01_000003 Container Transitioned from NEW to ALLOCATED
2013-08-11 01:54:20,820 INFO org.apache.hadoop.yarn.server.resourcemanager.RMAuditLogger: USER=ubuntu	OPERATION=AM Allocated Container	TARGET=SchedulerApp	RESULT=SUCCESS	APPID=application_1376185025835_0007	CONTAINERID=container_1376185025835_0007_01_000003
2013-08-11 01:54:20,820 INFO org.apache.hadoop.yarn.server.resourcemanager.scheduler.common.fica.FiCaSchedulerNode: Assigned container container_1376185025835_0007_01_000003 of capacity <memory:1024, vCores:1> on host hadoop-321-6:34867, which currently has 7 containers, <memory:8192, vCores:7> used and <memory:0, vCores:9> available
2013-08-11 01:54:20,821 INFO org.apache.hadoop.yarn.server.resourcemanager.scheduler.capacity.LeafQueue: assignedContainer application=application_1376185025835_0007 container=Container: [ContainerId: container_1376185025835_0007_01_000003, NodeId: hadoop-321-6:34867, NodeHttpAddress: hadoop-321-6:8042, Resource: <memory:1024, vCores:1>, Priority: 20, State: NEW, Token: null, Status: container_id {, app_attempt_id {, application_id {, id: 7, cluster_timestamp: 1376185025835, }, attemptId: 1, }, id: 3, }, state: C_NEW, ] containerId=container_1376185025835_0007_01_000003 queue=default: capacity=1.0, absoluteCapacity=1.0, usedResources=<memory:44032, vCores:38>usedCapacity=0.8958333, absoluteUsedCapacity=0.8958333, numApps=5, numContainers=38 usedCapacity=0.8958333 absoluteUsedCapacity=0.8958333 used=<memory:44032, vCores:38> cluster=<memory:49152, vCores:96>
2013-08-11 01:54:20,821 INFO org.apache.hadoop.yarn.server.resourcemanager.scheduler.capacity.ParentQueue: Re-sorting queues since queue: root.default stats: default: capacity=1.0, absoluteCapacity=1.0, usedResources=<memory:45056, vCores:39>usedCapacity=0.9166667, absoluteUsedCapacity=0.9166667, numApps=5, numContainers=39
2013-08-11 01:54:20,821 INFO org.apache.hadoop.yarn.server.resourcemanager.scheduler.capacity.ParentQueue: assignedContainer queue=root usedCapacity=0.9166667 absoluteUsedCapacity=0.9166667 used=<memory:45056, vCores:39> cluster=<memory:49152, vCores:96>
2013-08-11 01:54:20,878 INFO org.apache.hadoop.yarn.server.resourcemanager.rmcontainer.RMContainerImpl: container_1376185025835_0006_01_000016 Container Transitioned from RUNNING to COMPLETED
2013-08-11 01:54:20,878 INFO org.apache.hadoop.yarn.server.resourcemanager.scheduler.common.fica.FiCaSchedulerApp: Completed container: container_1376185025835_0006_01_000016 in state: COMPLETED event:FINISHED
2013-08-11 01:54:20,878 INFO org.apache.hadoop.yarn.server.resourcemanager.RMAuditLogger: USER=ubuntu	OPERATION=AM Released Container	TARGET=SchedulerApp	RESULT=SUCCESS	APPID=application_1376185025835_0006	CONTAINERID=container_1376185025835_0006_01_000016
2013-08-11 01:54:20,878 INFO org.apache.hadoop.yarn.server.resourcemanager.scheduler.common.fica.FiCaSchedulerNode: Released container container_1376185025835_0006_01_000016 of capacity <memory:1024, vCores:1> on host hadoop-321-6:34867, which currently has 6 containers, <memory:7168, vCores:6> used and <memory:1024, vCores:10> available, release resources=true
2013-08-11 01:54:20,882 INFO org.apache.hadoop.yarn.server.resourcemanager.scheduler.capacity.LeafQueue: default used=<memory:44032, vCores:38> numContainers=38 user=ubuntu user-resources=<memory:44032, vCores:38>
2013-08-11 01:54:20,883 INFO org.apache.hadoop.yarn.server.resourcemanager.scheduler.capacity.LeafQueue: completedContainer container=Container: [ContainerId: container_1376185025835_0006_01_000016, NodeId: hadoop-321-6:34867, NodeHttpAddress: hadoop-321-6:8042, Resource: <memory:1024, vCores:1>, Priority: 20, State: NEW, Token: null, Status: container_id {, app_attempt_id {, application_id {, id: 6, cluster_timestamp: 1376185025835, }, attemptId: 1, }, id: 16, }, state: C_COMPLETE, diagnostics: "Container killed by the ApplicationMaster.\n\n", exit_status: 143, ] resource=<memory:1024, vCores:1> queue=default: capacity=1.0, absoluteCapacity=1.0, usedResources=<memory:44032, vCores:38>usedCapacity=0.8958333, absoluteUsedCapacity=0.8958333, numApps=5, numContainers=38 usedCapacity=0.8958333 absoluteUsedCapacity=0.8958333 used=<memory:44032, vCores:38> cluster=<memory:49152, vCores:96>
2013-08-11 01:54:20,884 INFO org.apache.hadoop.yarn.server.resourcemanager.scheduler.capacity.ParentQueue: completedContainer queue=root usedCapacity=0.8958333 absoluteUsedCapacity=0.8958333 used=<memory:44032, vCores:38> cluster=<memory:49152, vCores:96>
2013-08-11 01:54:20,884 INFO org.apache.hadoop.yarn.server.resourcemanager.scheduler.capacity.CapacityScheduler: Application appattempt_1376185025835_0006_000001 released container container_1376185025835_0006_01_000016 on node: host: hadoop-321-6:34867 #containers=6 available=1024 used=7168 with event: FINISHED
2013-08-11 01:54:20,884 INFO org.apache.hadoop.yarn.server.resourcemanager.rmcontainer.RMContainerImpl: container_1376185025835_0007_01_000004 Container Transitioned from NEW to ALLOCATED
2013-08-11 01:54:20,885 INFO org.apache.hadoop.yarn.server.resourcemanager.RMAuditLogger: USER=ubuntu	OPERATION=AM Allocated Container	TARGET=SchedulerApp	RESULT=SUCCESS	APPID=application_1376185025835_0007	CONTAINERID=container_1376185025835_0007_01_000004
2013-08-11 01:54:20,885 INFO org.apache.hadoop.yarn.server.resourcemanager.scheduler.common.fica.FiCaSchedulerNode: Assigned container container_1376185025835_0007_01_000004 of capacity <memory:1024, vCores:1> on host hadoop-321-6:34867, which currently has 7 containers, <memory:8192, vCores:7> used and <memory:0, vCores:9> available
2013-08-11 01:54:20,886 INFO org.apache.hadoop.yarn.server.resourcemanager.scheduler.capacity.LeafQueue: assignedContainer application=application_1376185025835_0007 container=Container: [ContainerId: container_1376185025835_0007_01_000004, NodeId: hadoop-321-6:34867, NodeHttpAddress: hadoop-321-6:8042, Resource: <memory:1024, vCores:1>, Priority: 20, State: NEW, Token: null, Status: container_id {, app_attempt_id {, application_id {, id: 7, cluster_timestamp: 1376185025835, }, attemptId: 1, }, id: 4, }, state: C_NEW, ] containerId=container_1376185025835_0007_01_000004 queue=default: capacity=1.0, absoluteCapacity=1.0, usedResources=<memory:44032, vCores:38>usedCapacity=0.8958333, absoluteUsedCapacity=0.8958333, numApps=5, numContainers=38 usedCapacity=0.8958333 absoluteUsedCapacity=0.8958333 used=<memory:44032, vCores:38> cluster=<memory:49152, vCores:96>
2013-08-11 01:54:20,886 INFO org.apache.hadoop.yarn.server.resourcemanager.scheduler.capacity.ParentQueue: Re-sorting queues since queue: root.default stats: default: capacity=1.0, absoluteCapacity=1.0, usedResources=<memory:45056, vCores:39>usedCapacity=0.9166667, absoluteUsedCapacity=0.9166667, numApps=5, numContainers=39
2013-08-11 01:54:20,886 INFO org.apache.hadoop.yarn.server.resourcemanager.scheduler.capacity.ParentQueue: assignedContainer queue=root usedCapacity=0.9166667 absoluteUsedCapacity=0.9166667 used=<memory:45056, vCores:39> cluster=<memory:49152, vCores:96>
2013-08-11 01:54:21,006 INFO org.apache.hadoop.yarn.server.resourcemanager.rmcontainer.RMContainerImpl: container_1376185025835_0006_01_000044 Container Transitioned from ALLOCATED to ACQUIRED
2013-08-11 01:54:21,007 INFO org.apache.hadoop.yarn.server.resourcemanager.rmcontainer.RMContainerImpl: container_1376185025835_0006_01_000045 Container Transitioned from ALLOCATED to ACQUIRED
2013-08-11 01:54:21,007 INFO org.apache.hadoop.yarn.server.resourcemanager.rmcontainer.RMContainerImpl: container_1376185025835_0006_01_000046 Container Transitioned from ALLOCATED to ACQUIRED
2013-08-11 01:54:21,008 INFO org.apache.hadoop.yarn.server.resourcemanager.rmcontainer.RMContainerImpl: container_1376185025835_0006_01_000047 Container Transitioned from ALLOCATED to ACQUIRED
2013-08-11 01:54:21,141 INFO org.apache.hadoop.yarn.server.resourcemanager.rmcontainer.RMContainerImpl: container_1376185025835_0006_01_000046 Container Transitioned from ACQUIRED to RUNNING
2013-08-11 01:54:21,142 INFO org.apache.hadoop.yarn.server.resourcemanager.rmcontainer.RMContainerImpl: container_1376185025835_0007_01_000005 Container Transitioned from NEW to ALLOCATED
2013-08-11 01:54:21,142 INFO org.apache.hadoop.yarn.server.resourcemanager.RMAuditLogger: USER=ubuntu	OPERATION=AM Allocated Container	TARGET=SchedulerApp	RESULT=SUCCESS	APPID=application_1376185025835_0007	CONTAINERID=container_1376185025835_0007_01_000005
2013-08-11 01:54:21,142 INFO org.apache.hadoop.yarn.server.resourcemanager.scheduler.common.fica.FiCaSchedulerNode: Assigned container container_1376185025835_0007_01_000005 of capacity <memory:1024, vCores:1> on host hadoop-321-4:43757, which currently has 6 containers, <memory:7168, vCores:6> used and <memory:1024, vCores:10> available
2013-08-11 01:54:21,143 INFO org.apache.hadoop.yarn.server.resourcemanager.scheduler.capacity.LeafQueue: assignedContainer application=application_1376185025835_0007 container=Container: [ContainerId: container_1376185025835_0007_01_000005, NodeId: hadoop-321-4:43757, NodeHttpAddress: hadoop-321-4:8042, Resource: <memory:1024, vCores:1>, Priority: 20, State: NEW, Token: null, Status: container_id {, app_attempt_id {, application_id {, id: 7, cluster_timestamp: 1376185025835, }, attemptId: 1, }, id: 5, }, state: C_NEW, ] containerId=container_1376185025835_0007_01_000005 queue=default: capacity=1.0, absoluteCapacity=1.0, usedResources=<memory:45056, vCores:39>usedCapacity=0.9166667, absoluteUsedCapacity=0.9166667, numApps=5, numContainers=39 usedCapacity=0.9166667 absoluteUsedCapacity=0.9166667 used=<memory:45056, vCores:39> cluster=<memory:49152, vCores:96>
2013-08-11 01:54:21,144 INFO org.apache.hadoop.yarn.server.resourcemanager.scheduler.capacity.ParentQueue: Re-sorting queues since queue: root.default stats: default: capacity=1.0, absoluteCapacity=1.0, usedResources=<memory:46080, vCores:40>usedCapacity=0.9375, absoluteUsedCapacity=0.9375, numApps=5, numContainers=40
2013-08-11 01:54:21,144 INFO org.apache.hadoop.yarn.server.resourcemanager.scheduler.capacity.ParentQueue: assignedContainer queue=root usedCapacity=0.9375 absoluteUsedCapacity=0.9375 used=<memory:46080, vCores:40> cluster=<memory:49152, vCores:96>
2013-08-11 01:54:21,144 INFO org.apache.hadoop.yarn.server.resourcemanager.rmcontainer.RMContainerImpl: container_1376185025835_0007_01_000006 Container Transitioned from NEW to ALLOCATED
2013-08-11 01:54:21,144 INFO org.apache.hadoop.yarn.server.resourcemanager.RMAuditLogger: USER=ubuntu	OPERATION=AM Allocated Container	TARGET=SchedulerApp	RESULT=SUCCESS	APPID=application_1376185025835_0007	CONTAINERID=container_1376185025835_0007_01_000006
2013-08-11 01:54:21,144 INFO org.apache.hadoop.yarn.server.resourcemanager.scheduler.common.fica.FiCaSchedulerNode: Assigned container container_1376185025835_0007_01_000006 of capacity <memory:1024, vCores:1> on host hadoop-321-4:43757, which currently has 7 containers, <memory:8192, vCores:7> used and <memory:0, vCores:9> available
2013-08-11 01:54:21,145 INFO org.apache.hadoop.yarn.server.resourcemanager.scheduler.capacity.LeafQueue: assignedContainer application=application_1376185025835_0007 container=Container: [ContainerId: container_1376185025835_0007_01_000006, NodeId: hadoop-321-4:43757, NodeHttpAddress: hadoop-321-4:8042, Resource: <memory:1024, vCores:1>, Priority: 20, State: NEW, Token: null, Status: container_id {, app_attempt_id {, application_id {, id: 7, cluster_timestamp: 1376185025835, }, attemptId: 1, }, id: 6, }, state: C_NEW, ] containerId=container_1376185025835_0007_01_000006 queue=default: capacity=1.0, absoluteCapacity=1.0, usedResources=<memory:46080, vCores:40>usedCapacity=0.9375, absoluteUsedCapacity=0.9375, numApps=5, numContainers=40 usedCapacity=0.9375 absoluteUsedCapacity=0.9375 used=<memory:46080, vCores:40> cluster=<memory:49152, vCores:96>
2013-08-11 01:54:21,145 INFO org.apache.hadoop.yarn.server.resourcemanager.scheduler.capacity.ParentQueue: Re-sorting queues since queue: root.default stats: default: capacity=1.0, absoluteCapacity=1.0, usedResources=<memory:47104, vCores:41>usedCapacity=0.9583333, absoluteUsedCapacity=0.9583333, numApps=5, numContainers=41
2013-08-11 01:54:21,146 INFO org.apache.hadoop.yarn.server.resourcemanager.scheduler.capacity.ParentQueue: assignedContainer queue=root usedCapacity=0.9583333 absoluteUsedCapacity=0.9583333 used=<memory:47104, vCores:41> cluster=<memory:49152, vCores:96>
2013-08-11 01:54:21,195 INFO org.apache.hadoop.yarn.server.resourcemanager.rmcontainer.RMContainerImpl: container_1376185025835_0007_01_000007 Container Transitioned from NEW to ALLOCATED
2013-08-11 01:54:21,196 INFO org.apache.hadoop.yarn.server.resourcemanager.RMAuditLogger: USER=ubuntu	OPERATION=AM Allocated Container	TARGET=SchedulerApp	RESULT=SUCCESS	APPID=application_1376185025835_0007	CONTAINERID=container_1376185025835_0007_01_000007
2013-08-11 01:54:21,196 INFO org.apache.hadoop.yarn.server.resourcemanager.scheduler.common.fica.FiCaSchedulerNode: Assigned container container_1376185025835_0007_01_000007 of capacity <memory:1024, vCores:1> on host hadoop-321-3:44876, which currently has 7 containers, <memory:8192, vCores:7> used and <memory:0, vCores:9> available
2013-08-11 01:54:21,197 INFO org.apache.hadoop.yarn.server.resourcemanager.scheduler.capacity.LeafQueue: assignedContainer application=application_1376185025835_0007 container=Container: [ContainerId: container_1376185025835_0007_01_000007, NodeId: hadoop-321-3:44876, NodeHttpAddress: hadoop-321-3:8042, Resource: <memory:1024, vCores:1>, Priority: 20, State: NEW, Token: null, Status: container_id {, app_attempt_id {, application_id {, id: 7, cluster_timestamp: 1376185025835, }, attemptId: 1, }, id: 7, }, state: C_NEW, ] containerId=container_1376185025835_0007_01_000007 queue=default: capacity=1.0, absoluteCapacity=1.0, usedResources=<memory:47104, vCores:41>usedCapacity=0.9583333, absoluteUsedCapacity=0.9583333, numApps=5, numContainers=41 usedCapacity=0.9583333 absoluteUsedCapacity=0.9583333 used=<memory:47104, vCores:41> cluster=<memory:49152, vCores:96>
2013-08-11 01:54:21,197 INFO org.apache.hadoop.yarn.server.resourcemanager.scheduler.capacity.ParentQueue: Re-sorting queues since queue: root.default stats: default: capacity=1.0, absoluteCapacity=1.0, usedResources=<memory:48128, vCores:42>usedCapacity=0.9791667, absoluteUsedCapacity=0.9791667, numApps=5, numContainers=42
2013-08-11 01:54:21,197 INFO org.apache.hadoop.yarn.server.resourcemanager.scheduler.capacity.ParentQueue: assignedContainer queue=root usedCapacity=0.9791667 absoluteUsedCapacity=0.9791667 used=<memory:48128, vCores:42> cluster=<memory:49152, vCores:96>
2013-08-11 01:54:21,307 INFO org.apache.hadoop.yarn.server.resourcemanager.rmcontainer.RMContainerImpl: container_1376185025835_0006_01_000045 Container Transitioned from ACQUIRED to RUNNING
2013-08-11 01:54:21,308 INFO org.apache.hadoop.yarn.server.resourcemanager.rmcontainer.RMContainerImpl: container_1376185025835_0007_01_000008 Container Transitioned from NEW to ALLOCATED
2013-08-11 01:54:21,308 INFO org.apache.hadoop.yarn.server.resourcemanager.RMAuditLogger: USER=ubuntu	OPERATION=AM Allocated Container	TARGET=SchedulerApp	RESULT=SUCCESS	APPID=application_1376185025835_0007	CONTAINERID=container_1376185025835_0007_01_000008
2013-08-11 01:54:21,308 INFO org.apache.hadoop.yarn.server.resourcemanager.scheduler.common.fica.FiCaSchedulerNode: Assigned container container_1376185025835_0007_01_000008 of capacity <memory:1024, vCores:1> on host hadoop-321-7:41950, which currently has 8 containers, <memory:8192, vCores:8> used and <memory:0, vCores:8> available
2013-08-11 01:54:21,309 INFO org.apache.hadoop.yarn.server.resourcemanager.scheduler.capacity.LeafQueue: assignedContainer application=application_1376185025835_0007 container=Container: [ContainerId: container_1376185025835_0007_01_000008, NodeId: hadoop-321-7:41950, NodeHttpAddress: hadoop-321-7:8042, Resource: <memory:1024, vCores:1>, Priority: 20, State: NEW, Token: null, Status: container_id {, app_attempt_id {, application_id {, id: 7, cluster_timestamp: 1376185025835, }, attemptId: 1, }, id: 8, }, state: C_NEW, ] containerId=container_1376185025835_0007_01_000008 queue=default: capacity=1.0, absoluteCapacity=1.0, usedResources=<memory:48128, vCores:42>usedCapacity=0.9791667, absoluteUsedCapacity=0.9791667, numApps=5, numContainers=42 usedCapacity=0.9791667 absoluteUsedCapacity=0.9791667 used=<memory:48128, vCores:42> cluster=<memory:49152, vCores:96>
2013-08-11 01:54:21,309 INFO org.apache.hadoop.yarn.server.resourcemanager.scheduler.capacity.ParentQueue: Re-sorting queues since queue: root.default stats: default: capacity=1.0, absoluteCapacity=1.0, usedResources=<memory:49152, vCores:43>usedCapacity=1.0, absoluteUsedCapacity=1.0, numApps=5, numContainers=43
2013-08-11 01:54:21,309 INFO org.apache.hadoop.yarn.server.resourcemanager.scheduler.capacity.ParentQueue: assignedContainer queue=root usedCapacity=1.0 absoluteUsedCapacity=1.0 used=<memory:49152, vCores:43> cluster=<memory:49152, vCores:96>
2013-08-11 01:54:21,889 INFO org.apache.hadoop.yarn.server.resourcemanager.rmcontainer.RMContainerImpl: container_1376185025835_0006_01_000047 Container Transitioned from ACQUIRED to RUNNING
2013-08-11 01:54:21,890 INFO org.apache.hadoop.yarn.server.resourcemanager.rmcontainer.RMContainerImpl: container_1376185025835_0006_01_000014 Container Transitioned from RUNNING to COMPLETED
2013-08-11 01:54:21,890 INFO org.apache.hadoop.yarn.server.resourcemanager.scheduler.common.fica.FiCaSchedulerApp: Completed container: container_1376185025835_0006_01_000014 in state: COMPLETED event:FINISHED
2013-08-11 01:54:21,890 INFO org.apache.hadoop.yarn.server.resourcemanager.RMAuditLogger: USER=ubuntu	OPERATION=AM Released Container	TARGET=SchedulerApp	RESULT=SUCCESS	APPID=application_1376185025835_0006	CONTAINERID=container_1376185025835_0006_01_000014
2013-08-11 01:54:21,890 INFO org.apache.hadoop.yarn.server.resourcemanager.scheduler.common.fica.FiCaSchedulerNode: Released container container_1376185025835_0006_01_000014 of capacity <memory:1024, vCores:1> on host hadoop-321-6:34867, which currently has 6 containers, <memory:7168, vCores:6> used and <memory:1024, vCores:10> available, release resources=true
2013-08-11 01:54:21,890 INFO org.apache.hadoop.yarn.server.resourcemanager.scheduler.capacity.LeafQueue: default used=<memory:48128, vCores:42> numContainers=42 user=ubuntu user-resources=<memory:48128, vCores:42>
2013-08-11 01:54:21,891 INFO org.apache.hadoop.yarn.server.resourcemanager.scheduler.capacity.LeafQueue: completedContainer container=Container: [ContainerId: container_1376185025835_0006_01_000014, NodeId: hadoop-321-6:34867, NodeHttpAddress: hadoop-321-6:8042, Resource: <memory:1024, vCores:1>, Priority: 20, State: NEW, Token: null, Status: container_id {, app_attempt_id {, application_id {, id: 6, cluster_timestamp: 1376185025835, }, attemptId: 1, }, id: 14, }, state: C_COMPLETE, diagnostics: "Container killed by the ApplicationMaster.\n\n", exit_status: 143, ] resource=<memory:1024, vCores:1> queue=default: capacity=1.0, absoluteCapacity=1.0, usedResources=<memory:48128, vCores:42>usedCapacity=0.9791667, absoluteUsedCapacity=0.9791667, numApps=5, numContainers=42 usedCapacity=0.9791667 absoluteUsedCapacity=0.9791667 used=<memory:48128, vCores:42> cluster=<memory:49152, vCores:96>
2013-08-11 01:54:21,892 INFO org.apache.hadoop.yarn.server.resourcemanager.scheduler.capacity.ParentQueue: completedContainer queue=root usedCapacity=0.9791667 absoluteUsedCapacity=0.9791667 used=<memory:48128, vCores:42> cluster=<memory:49152, vCores:96>
2013-08-11 01:54:21,892 INFO org.apache.hadoop.yarn.server.resourcemanager.scheduler.capacity.CapacityScheduler: Application appattempt_1376185025835_0006_000001 released container container_1376185025835_0006_01_000014 on node: host: hadoop-321-6:34867 #containers=6 available=1024 used=7168 with event: FINISHED
2013-08-11 01:54:21,892 INFO org.apache.hadoop.yarn.server.resourcemanager.rmcontainer.RMContainerImpl: container_1376185025835_0006_01_000017 Container Transitioned from RUNNING to COMPLETED
2013-08-11 01:54:21,892 INFO org.apache.hadoop.yarn.server.resourcemanager.scheduler.common.fica.FiCaSchedulerApp: Completed container: container_1376185025835_0006_01_000017 in state: COMPLETED event:FINISHED
2013-08-11 01:54:21,892 INFO org.apache.hadoop.yarn.server.resourcemanager.RMAuditLogger: USER=ubuntu	OPERATION=AM Released Container	TARGET=SchedulerApp	RESULT=SUCCESS	APPID=application_1376185025835_0006	CONTAINERID=container_1376185025835_0006_01_000017
2013-08-11 01:54:21,892 INFO org.apache.hadoop.yarn.server.resourcemanager.scheduler.common.fica.FiCaSchedulerNode: Released container container_1376185025835_0006_01_000017 of capacity <memory:1024, vCores:1> on host hadoop-321-6:34867, which currently has 5 containers, <memory:6144, vCores:5> used and <memory:2048, vCores:11> available, release resources=true
2013-08-11 01:54:21,892 INFO org.apache.hadoop.yarn.server.resourcemanager.scheduler.capacity.LeafQueue: default used=<memory:47104, vCores:41> numContainers=41 user=ubuntu user-resources=<memory:47104, vCores:41>
2013-08-11 01:54:21,893 INFO org.apache.hadoop.yarn.server.resourcemanager.scheduler.capacity.LeafQueue: completedContainer container=Container: [ContainerId: container_1376185025835_0006_01_000017, NodeId: hadoop-321-6:34867, NodeHttpAddress: hadoop-321-6:8042, Resource: <memory:1024, vCores:1>, Priority: 20, State: NEW, Token: null, Status: container_id {, app_attempt_id {, application_id {, id: 6, cluster_timestamp: 1376185025835, }, attemptId: 1, }, id: 17, }, state: C_COMPLETE, diagnostics: "", exit_status: 0, ] resource=<memory:1024, vCores:1> queue=default: capacity=1.0, absoluteCapacity=1.0, usedResources=<memory:47104, vCores:41>usedCapacity=0.9583333, absoluteUsedCapacity=0.9583333, numApps=5, numContainers=41 usedCapacity=0.9583333 absoluteUsedCapacity=0.9583333 used=<memory:47104, vCores:41> cluster=<memory:49152, vCores:96>
2013-08-11 01:54:21,894 INFO org.apache.hadoop.yarn.server.resourcemanager.scheduler.capacity.ParentQueue: completedContainer queue=root usedCapacity=0.9583333 absoluteUsedCapacity=0.9583333 used=<memory:47104, vCores:41> cluster=<memory:49152, vCores:96>
2013-08-11 01:54:21,894 INFO org.apache.hadoop.yarn.server.resourcemanager.scheduler.capacity.CapacityScheduler: Application appattempt_1376185025835_0006_000001 released container container_1376185025835_0006_01_000017 on node: host: hadoop-321-6:34867 #containers=5 available=2048 used=6144 with event: FINISHED
2013-08-11 01:54:21,894 INFO org.apache.hadoop.yarn.server.resourcemanager.rmcontainer.RMContainerImpl: container_1376185025835_0006_01_000019 Container Transitioned from RUNNING to COMPLETED
2013-08-11 01:54:21,894 INFO org.apache.hadoop.yarn.server.resourcemanager.scheduler.common.fica.FiCaSchedulerApp: Completed container: container_1376185025835_0006_01_000019 in state: COMPLETED event:FINISHED
2013-08-11 01:54:21,894 INFO org.apache.hadoop.yarn.server.resourcemanager.RMAuditLogger: USER=ubuntu	OPERATION=AM Released Container	TARGET=SchedulerApp	RESULT=SUCCESS	APPID=application_1376185025835_0006	CONTAINERID=container_1376185025835_0006_01_000019
2013-08-11 01:54:21,894 INFO org.apache.hadoop.yarn.server.resourcemanager.scheduler.common.fica.FiCaSchedulerNode: Released container container_1376185025835_0006_01_000019 of capacity <memory:1024, vCores:1> on host hadoop-321-6:34867, which currently has 4 containers, <memory:5120, vCores:4> used and <memory:3072, vCores:12> available, release resources=true
2013-08-11 01:54:21,894 INFO org.apache.hadoop.yarn.server.resourcemanager.scheduler.capacity.LeafQueue: default used=<memory:46080, vCores:40> numContainers=40 user=ubuntu user-resources=<memory:46080, vCores:40>
2013-08-11 01:54:21,895 INFO org.apache.hadoop.yarn.server.resourcemanager.scheduler.capacity.LeafQueue: completedContainer container=Container: [ContainerId: container_1376185025835_0006_01_000019, NodeId: hadoop-321-6:34867, NodeHttpAddress: hadoop-321-6:8042, Resource: <memory:1024, vCores:1>, Priority: 20, State: NEW, Token: null, Status: container_id {, app_attempt_id {, application_id {, id: 6, cluster_timestamp: 1376185025835, }, attemptId: 1, }, id: 19, }, state: C_COMPLETE, diagnostics: "Container killed by the ApplicationMaster.\n\n", exit_status: 143, ] resource=<memory:1024, vCores:1> queue=default: capacity=1.0, absoluteCapacity=1.0, usedResources=<memory:46080, vCores:40>usedCapacity=0.9375, absoluteUsedCapacity=0.9375, numApps=5, numContainers=40 usedCapacity=0.9375 absoluteUsedCapacity=0.9375 used=<memory:46080, vCores:40> cluster=<memory:49152, vCores:96>
2013-08-11 01:54:21,895 INFO org.apache.hadoop.yarn.server.resourcemanager.scheduler.capacity.ParentQueue: completedContainer queue=root usedCapacity=0.9375 absoluteUsedCapacity=0.9375 used=<memory:46080, vCores:40> cluster=<memory:49152, vCores:96>
2013-08-11 01:54:21,896 INFO org.apache.hadoop.yarn.server.resourcemanager.scheduler.capacity.CapacityScheduler: Application appattempt_1376185025835_0006_000001 released container container_1376185025835_0006_01_000019 on node: host: hadoop-321-6:34867 #containers=4 available=3072 used=5120 with event: FINISHED
2013-08-11 01:54:21,896 INFO org.apache.hadoop.yarn.server.resourcemanager.rmcontainer.RMContainerImpl: container_1376185025835_0007_01_000009 Container Transitioned from NEW to ALLOCATED
2013-08-11 01:54:21,896 INFO org.apache.hadoop.yarn.server.resourcemanager.RMAuditLogger: USER=ubuntu	OPERATION=AM Allocated Container	TARGET=SchedulerApp	RESULT=SUCCESS	APPID=application_1376185025835_0007	CONTAINERID=container_1376185025835_0007_01_000009
2013-08-11 01:54:21,896 INFO org.apache.hadoop.yarn.server.resourcemanager.scheduler.common.fica.FiCaSchedulerNode: Assigned container container_1376185025835_0007_01_000009 of capacity <memory:1024, vCores:1> on host hadoop-321-6:34867, which currently has 5 containers, <memory:6144, vCores:5> used and <memory:2048, vCores:11> available
2013-08-11 01:54:21,897 INFO org.apache.hadoop.yarn.server.resourcemanager.scheduler.capacity.LeafQueue: assignedContainer application=application_1376185025835_0007 container=Container: [ContainerId: container_1376185025835_0007_01_000009, NodeId: hadoop-321-6:34867, NodeHttpAddress: hadoop-321-6:8042, Resource: <memory:1024, vCores:1>, Priority: 20, State: NEW, Token: null, Status: container_id {, app_attempt_id {, application_id {, id: 7, cluster_timestamp: 1376185025835, }, attemptId: 1, }, id: 9, }, state: C_NEW, ] containerId=container_1376185025835_0007_01_000009 queue=default: capacity=1.0, absoluteCapacity=1.0, usedResources=<memory:46080, vCores:40>usedCapacity=0.9375, absoluteUsedCapacity=0.9375, numApps=5, numContainers=40 usedCapacity=0.9375 absoluteUsedCapacity=0.9375 used=<memory:46080, vCores:40> cluster=<memory:49152, vCores:96>
2013-08-11 01:54:21,897 INFO org.apache.hadoop.yarn.server.resourcemanager.scheduler.capacity.ParentQueue: Re-sorting queues since queue: root.default stats: default: capacity=1.0, absoluteCapacity=1.0, usedResources=<memory:47104, vCores:41>usedCapacity=0.9583333, absoluteUsedCapacity=0.9583333, numApps=5, numContainers=41
2013-08-11 01:54:21,898 INFO org.apache.hadoop.yarn.server.resourcemanager.scheduler.capacity.ParentQueue: assignedContainer queue=root usedCapacity=0.9583333 absoluteUsedCapacity=0.9583333 used=<memory:47104, vCores:41> cluster=<memory:49152, vCores:96>
2013-08-11 01:54:21,898 INFO org.apache.hadoop.yarn.server.resourcemanager.rmcontainer.RMContainerImpl: container_1376185025835_0007_01_000010 Container Transitioned from NEW to ALLOCATED
2013-08-11 01:54:21,898 INFO org.apache.hadoop.yarn.server.resourcemanager.RMAuditLogger: USER=ubuntu	OPERATION=AM Allocated Container	TARGET=SchedulerApp	RESULT=SUCCESS	APPID=application_1376185025835_0007	CONTAINERID=container_1376185025835_0007_01_000010
2013-08-11 01:54:21,898 INFO org.apache.hadoop.yarn.server.resourcemanager.scheduler.common.fica.FiCaSchedulerNode: Assigned container container_1376185025835_0007_01_000010 of capacity <memory:1024, vCores:1> on host hadoop-321-6:34867, which currently has 6 containers, <memory:7168, vCores:6> used and <memory:1024, vCores:10> available
2013-08-11 01:54:21,899 INFO org.apache.hadoop.yarn.server.resourcemanager.scheduler.capacity.LeafQueue: assignedContainer application=application_1376185025835_0007 container=Container: [ContainerId: container_1376185025835_0007_01_000010, NodeId: hadoop-321-6:34867, NodeHttpAddress: hadoop-321-6:8042, Resource: <memory:1024, vCores:1>, Priority: 20, State: NEW, Token: null, Status: container_id {, app_attempt_id {, application_id {, id: 7, cluster_timestamp: 1376185025835, }, attemptId: 1, }, id: 10, }, state: C_NEW, ] containerId=container_1376185025835_0007_01_000010 queue=default: capacity=1.0, absoluteCapacity=1.0, usedResources=<memory:47104, vCores:41>usedCapacity=0.9583333, absoluteUsedCapacity=0.9583333, numApps=5, numContainers=41 usedCapacity=0.9583333 absoluteUsedCapacity=0.9583333 used=<memory:47104, vCores:41> cluster=<memory:49152, vCores:96>
2013-08-11 01:54:21,899 INFO org.apache.hadoop.yarn.server.resourcemanager.scheduler.capacity.ParentQueue: Re-sorting queues since queue: root.default stats: default: capacity=1.0, absoluteCapacity=1.0, usedResources=<memory:48128, vCores:42>usedCapacity=0.9791667, absoluteUsedCapacity=0.9791667, numApps=5, numContainers=42
2013-08-11 01:54:21,900 INFO org.apache.hadoop.yarn.server.resourcemanager.scheduler.capacity.ParentQueue: assignedContainer queue=root usedCapacity=0.9791667 absoluteUsedCapacity=0.9791667 used=<memory:48128, vCores:42> cluster=<memory:49152, vCores:96>
2013-08-11 01:54:21,900 INFO org.apache.hadoop.yarn.server.resourcemanager.rmcontainer.RMContainerImpl: container_1376185025835_0007_01_000011 Container Transitioned from NEW to ALLOCATED
2013-08-11 01:54:21,900 INFO org.apache.hadoop.yarn.server.resourcemanager.RMAuditLogger: USER=ubuntu	OPERATION=AM Allocated Container	TARGET=SchedulerApp	RESULT=SUCCESS	APPID=application_1376185025835_0007	CONTAINERID=container_1376185025835_0007_01_000011
2013-08-11 01:54:21,900 INFO org.apache.hadoop.yarn.server.resourcemanager.scheduler.common.fica.FiCaSchedulerNode: Assigned container container_1376185025835_0007_01_000011 of capacity <memory:1024, vCores:1> on host hadoop-321-6:34867, which currently has 7 containers, <memory:8192, vCores:7> used and <memory:0, vCores:9> available
2013-08-11 01:54:21,901 INFO org.apache.hadoop.yarn.server.resourcemanager.scheduler.capacity.LeafQueue: assignedContainer application=application_1376185025835_0007 container=Container: [ContainerId: container_1376185025835_0007_01_000011, NodeId: hadoop-321-6:34867, NodeHttpAddress: hadoop-321-6:8042, Resource: <memory:1024, vCores:1>, Priority: 20, State: NEW, Token: null, Status: container_id {, app_attempt_id {, application_id {, id: 7, cluster_timestamp: 1376185025835, }, attemptId: 1, }, id: 11, }, state: C_NEW, ] containerId=container_1376185025835_0007_01_000011 queue=default: capacity=1.0, absoluteCapacity=1.0, usedResources=<memory:48128, vCores:42>usedCapacity=0.9791667, absoluteUsedCapacity=0.9791667, numApps=5, numContainers=42 usedCapacity=0.9791667 absoluteUsedCapacity=0.9791667 used=<memory:48128, vCores:42> cluster=<memory:49152, vCores:96>
2013-08-11 01:54:21,901 INFO org.apache.hadoop.yarn.server.resourcemanager.scheduler.capacity.ParentQueue: Re-sorting queues since queue: root.default stats: default: capacity=1.0, absoluteCapacity=1.0, usedResources=<memory:49152, vCores:43>usedCapacity=1.0, absoluteUsedCapacity=1.0, numApps=5, numContainers=43
2013-08-11 01:54:21,901 INFO org.apache.hadoop.yarn.server.resourcemanager.scheduler.capacity.ParentQueue: assignedContainer queue=root usedCapacity=1.0 absoluteUsedCapacity=1.0 used=<memory:49152, vCores:43> cluster=<memory:49152, vCores:96>
2013-08-11 01:54:22,028 INFO org.apache.hadoop.yarn.server.resourcemanager.scheduler.AppSchedulingInfo: checking for deactivate... 
2013-08-11 01:54:22,029 INFO org.apache.hadoop.yarn.server.resourcemanager.scheduler.AppSchedulingInfo: checking for deactivate... 
2013-08-11 01:54:22,152 INFO org.apache.hadoop.yarn.server.resourcemanager.rmcontainer.RMContainerImpl: container_1376185025835_0006_01_000020 Container Transitioned from RUNNING to COMPLETED
2013-08-11 01:54:22,152 INFO org.apache.hadoop.yarn.server.resourcemanager.scheduler.common.fica.FiCaSchedulerApp: Completed container: container_1376185025835_0006_01_000020 in state: COMPLETED event:FINISHED
2013-08-11 01:54:22,152 INFO org.apache.hadoop.yarn.server.resourcemanager.RMAuditLogger: USER=ubuntu	OPERATION=AM Released Container	TARGET=SchedulerApp	RESULT=SUCCESS	APPID=application_1376185025835_0006	CONTAINERID=container_1376185025835_0006_01_000020
2013-08-11 01:54:22,152 INFO org.apache.hadoop.yarn.server.resourcemanager.scheduler.common.fica.FiCaSchedulerNode: Released container container_1376185025835_0006_01_000020 of capacity <memory:1024, vCores:1> on host hadoop-321-4:43757, which currently has 6 containers, <memory:7168, vCores:6> used and <memory:1024, vCores:10> available, release resources=true
2013-08-11 01:54:22,152 INFO org.apache.hadoop.yarn.server.resourcemanager.scheduler.capacity.LeafQueue: default used=<memory:48128, vCores:42> numContainers=42 user=ubuntu user-resources=<memory:48128, vCores:42>
2013-08-11 01:54:22,153 INFO org.apache.hadoop.yarn.server.resourcemanager.scheduler.capacity.LeafQueue: completedContainer container=Container: [ContainerId: container_1376185025835_0006_01_000020, NodeId: hadoop-321-4:43757, NodeHttpAddress: hadoop-321-4:8042, Resource: <memory:1024, vCores:1>, Priority: 20, State: NEW, Token: null, Status: container_id {, app_attempt_id {, application_id {, id: 6, cluster_timestamp: 1376185025835, }, attemptId: 1, }, id: 20, }, state: C_COMPLETE, diagnostics: "Container killed by the ApplicationMaster.\n\n", exit_status: 143, ] resource=<memory:1024, vCores:1> queue=default: capacity=1.0, absoluteCapacity=1.0, usedResources=<memory:48128, vCores:42>usedCapacity=0.9791667, absoluteUsedCapacity=0.9791667, numApps=5, numContainers=42 usedCapacity=0.9791667 absoluteUsedCapacity=0.9791667 used=<memory:48128, vCores:42> cluster=<memory:49152, vCores:96>
2013-08-11 01:54:22,153 INFO org.apache.hadoop.yarn.server.resourcemanager.scheduler.capacity.ParentQueue: completedContainer queue=root usedCapacity=0.9791667 absoluteUsedCapacity=0.9791667 used=<memory:48128, vCores:42> cluster=<memory:49152, vCores:96>
2013-08-11 01:54:22,153 INFO org.apache.hadoop.yarn.server.resourcemanager.scheduler.capacity.CapacityScheduler: Application appattempt_1376185025835_0006_000001 released container container_1376185025835_0006_01_000020 on node: host: hadoop-321-4:43757 #containers=6 available=1024 used=7168 with event: FINISHED
2013-08-11 01:54:22,154 INFO org.apache.hadoop.yarn.server.resourcemanager.rmcontainer.RMContainerImpl: container_1376185025835_0007_01_000012 Container Transitioned from NEW to ALLOCATED
2013-08-11 01:54:22,154 INFO org.apache.hadoop.yarn.server.resourcemanager.RMAuditLogger: USER=ubuntu	OPERATION=AM Allocated Container	TARGET=SchedulerApp	RESULT=SUCCESS	APPID=application_1376185025835_0007	CONTAINERID=container_1376185025835_0007_01_000012
2013-08-11 01:54:22,154 INFO org.apache.hadoop.yarn.server.resourcemanager.scheduler.common.fica.FiCaSchedulerNode: Assigned container container_1376185025835_0007_01_000012 of capacity <memory:1024, vCores:1> on host hadoop-321-4:43757, which currently has 7 containers, <memory:8192, vCores:7> used and <memory:0, vCores:9> available
2013-08-11 01:54:22,155 INFO org.apache.hadoop.yarn.server.resourcemanager.scheduler.capacity.LeafQueue: assignedContainer application=application_1376185025835_0007 container=Container: [ContainerId: container_1376185025835_0007_01_000012, NodeId: hadoop-321-4:43757, NodeHttpAddress: hadoop-321-4:8042, Resource: <memory:1024, vCores:1>, Priority: 20, State: NEW, Token: null, Status: container_id {, app_attempt_id {, application_id {, id: 7, cluster_timestamp: 1376185025835, }, attemptId: 1, }, id: 12, }, state: C_NEW, ] containerId=container_1376185025835_0007_01_000012 queue=default: capacity=1.0, absoluteCapacity=1.0, usedResources=<memory:48128, vCores:42>usedCapacity=0.9791667, absoluteUsedCapacity=0.9791667, numApps=5, numContainers=42 usedCapacity=0.9791667 absoluteUsedCapacity=0.9791667 used=<memory:48128, vCores:42> cluster=<memory:49152, vCores:96>
2013-08-11 01:54:22,155 INFO org.apache.hadoop.yarn.server.resourcemanager.scheduler.capacity.ParentQueue: Re-sorting queues since queue: root.default stats: default: capacity=1.0, absoluteCapacity=1.0, usedResources=<memory:49152, vCores:43>usedCapacity=1.0, absoluteUsedCapacity=1.0, numApps=5, numContainers=43
2013-08-11 01:54:22,155 INFO org.apache.hadoop.yarn.server.resourcemanager.scheduler.capacity.ParentQueue: assignedContainer queue=root usedCapacity=1.0 absoluteUsedCapacity=1.0 used=<memory:49152, vCores:43> cluster=<memory:49152, vCores:96>
2013-08-11 01:54:22,176 INFO org.apache.hadoop.yarn.server.resourcemanager.rmcontainer.RMContainerImpl: container_1376185025835_0007_01_000003 Container Transitioned from ALLOCATED to ACQUIRED
2013-08-11 01:54:22,177 INFO org.apache.hadoop.yarn.server.resourcemanager.rmcontainer.RMContainerImpl: container_1376185025835_0007_01_000004 Container Transitioned from ALLOCATED to ACQUIRED
2013-08-11 01:54:22,177 INFO org.apache.hadoop.yarn.server.resourcemanager.rmcontainer.RMContainerImpl: container_1376185025835_0007_01_000005 Container Transitioned from ALLOCATED to ACQUIRED
2013-08-11 01:54:22,177 INFO org.apache.hadoop.yarn.server.resourcemanager.rmcontainer.RMContainerImpl: container_1376185025835_0007_01_000006 Container Transitioned from ALLOCATED to ACQUIRED
2013-08-11 01:54:22,177 INFO org.apache.hadoop.yarn.server.resourcemanager.rmcontainer.RMContainerImpl: container_1376185025835_0007_01_000007 Container Transitioned from ALLOCATED to ACQUIRED
2013-08-11 01:54:22,178 INFO org.apache.hadoop.yarn.server.resourcemanager.rmcontainer.RMContainerImpl: container_1376185025835_0007_01_000008 Container Transitioned from ALLOCATED to ACQUIRED
2013-08-11 01:54:22,178 INFO org.apache.hadoop.yarn.server.resourcemanager.rmcontainer.RMContainerImpl: container_1376185025835_0007_01_000009 Container Transitioned from ALLOCATED to ACQUIRED
2013-08-11 01:54:22,178 INFO org.apache.hadoop.yarn.server.resourcemanager.rmcontainer.RMContainerImpl: container_1376185025835_0007_01_000010 Container Transitioned from ALLOCATED to ACQUIRED
2013-08-11 01:54:22,178 INFO org.apache.hadoop.yarn.server.resourcemanager.rmcontainer.RMContainerImpl: container_1376185025835_0007_01_000011 Container Transitioned from ALLOCATED to ACQUIRED
2013-08-11 01:54:22,178 INFO org.apache.hadoop.yarn.server.resourcemanager.rmcontainer.RMContainerImpl: container_1376185025835_0007_01_000012 Container Transitioned from ALLOCATED to ACQUIRED
2013-08-11 01:54:22,208 INFO org.apache.hadoop.yarn.server.resourcemanager.rmcontainer.RMContainerImpl: container_1376185025835_0006_01_000044 Container Transitioned from ACQUIRED to RUNNING
2013-08-11 01:54:22,418 INFO org.apache.hadoop.yarn.server.resourcemanager.rmcontainer.RMContainerImpl: container_1376185025835_0007_01_000002 Container Transitioned from ACQUIRED to RUNNING
2013-08-11 01:54:22,418 INFO org.apache.hadoop.yarn.server.resourcemanager.rmcontainer.RMContainerImpl: container_1376185025835_0006_01_000006 Container Transitioned from RUNNING to COMPLETED
2013-08-11 01:54:22,419 INFO org.apache.hadoop.yarn.server.resourcemanager.scheduler.common.fica.FiCaSchedulerApp: Completed container: container_1376185025835_0006_01_000006 in state: COMPLETED event:FINISHED
2013-08-11 01:54:22,419 INFO org.apache.hadoop.yarn.server.resourcemanager.RMAuditLogger: USER=ubuntu	OPERATION=AM Released Container	TARGET=SchedulerApp	RESULT=SUCCESS	APPID=application_1376185025835_0006	CONTAINERID=container_1376185025835_0006_01_000006
2013-08-11 01:54:22,419 INFO org.apache.hadoop.yarn.server.resourcemanager.scheduler.common.fica.FiCaSchedulerNode: Released container container_1376185025835_0006_01_000006 of capacity <memory:1024, vCores:1> on host hadoop-321-2:46202, which currently has 6 containers, <memory:7168, vCores:6> used and <memory:1024, vCores:10> available, release resources=true
2013-08-11 01:54:22,420 INFO org.apache.hadoop.yarn.server.resourcemanager.scheduler.capacity.LeafQueue: default used=<memory:48128, vCores:42> numContainers=42 user=ubuntu user-resources=<memory:48128, vCores:42>
2013-08-11 01:54:22,421 INFO org.apache.hadoop.yarn.server.resourcemanager.scheduler.capacity.LeafQueue: completedContainer container=Container: [ContainerId: container_1376185025835_0006_01_000006, NodeId: hadoop-321-2:46202, NodeHttpAddress: hadoop-321-2:8042, Resource: <memory:1024, vCores:1>, Priority: 20, State: NEW, Token: null, Status: container_id {, app_attempt_id {, application_id {, id: 6, cluster_timestamp: 1376185025835, }, attemptId: 1, }, id: 6, }, state: C_COMPLETE, diagnostics: "Container killed by the ApplicationMaster.\n\n", exit_status: 143, ] resource=<memory:1024, vCores:1> queue=default: capacity=1.0, absoluteCapacity=1.0, usedResources=<memory:48128, vCores:42>usedCapacity=0.9791667, absoluteUsedCapacity=0.9791667, numApps=5, numContainers=42 usedCapacity=0.9791667 absoluteUsedCapacity=0.9791667 used=<memory:48128, vCores:42> cluster=<memory:49152, vCores:96>
2013-08-11 01:54:22,421 INFO org.apache.hadoop.yarn.server.resourcemanager.scheduler.capacity.ParentQueue: completedContainer queue=root usedCapacity=0.9791667 absoluteUsedCapacity=0.9791667 used=<memory:48128, vCores:42> cluster=<memory:49152, vCores:96>
2013-08-11 01:54:22,421 INFO org.apache.hadoop.yarn.server.resourcemanager.scheduler.capacity.CapacityScheduler: Application appattempt_1376185025835_0006_000001 released container container_1376185025835_0006_01_000006 on node: host: hadoop-321-2:46202 #containers=6 available=1024 used=7168 with event: FINISHED
2013-08-11 01:54:22,421 INFO org.apache.hadoop.yarn.server.resourcemanager.rmcontainer.RMContainerImpl: container_1376185025835_0007_01_000013 Container Transitioned from NEW to ALLOCATED
2013-08-11 01:54:22,422 INFO org.apache.hadoop.yarn.server.resourcemanager.RMAuditLogger: USER=ubuntu	OPERATION=AM Allocated Container	TARGET=SchedulerApp	RESULT=SUCCESS	APPID=application_1376185025835_0007	CONTAINERID=container_1376185025835_0007_01_000013
2013-08-11 01:54:22,422 INFO org.apache.hadoop.yarn.server.resourcemanager.scheduler.common.fica.FiCaSchedulerNode: Assigned container container_1376185025835_0007_01_000013 of capacity <memory:1024, vCores:1> on host hadoop-321-2:46202, which currently has 7 containers, <memory:8192, vCores:7> used and <memory:0, vCores:9> available
2013-08-11 01:54:22,422 INFO org.apache.hadoop.yarn.server.resourcemanager.scheduler.capacity.LeafQueue: assignedContainer application=application_1376185025835_0007 container=Container: [ContainerId: container_1376185025835_0007_01_000013, NodeId: hadoop-321-2:46202, NodeHttpAddress: hadoop-321-2:8042, Resource: <memory:1024, vCores:1>, Priority: 20, State: NEW, Token: null, Status: container_id {, app_attempt_id {, application_id {, id: 7, cluster_timestamp: 1376185025835, }, attemptId: 1, }, id: 13, }, state: C_NEW, ] containerId=container_1376185025835_0007_01_000013 queue=default: capacity=1.0, absoluteCapacity=1.0, usedResources=<memory:48128, vCores:42>usedCapacity=0.9791667, absoluteUsedCapacity=0.9791667, numApps=5, numContainers=42 usedCapacity=0.9791667 absoluteUsedCapacity=0.9791667 used=<memory:48128, vCores:42> cluster=<memory:49152, vCores:96>
2013-08-11 01:54:22,423 INFO org.apache.hadoop.yarn.server.resourcemanager.scheduler.capacity.ParentQueue: Re-sorting queues since queue: root.default stats: default: capacity=1.0, absoluteCapacity=1.0, usedResources=<memory:49152, vCores:43>usedCapacity=1.0, absoluteUsedCapacity=1.0, numApps=5, numContainers=43
2013-08-11 01:54:22,423 INFO org.apache.hadoop.yarn.server.resourcemanager.scheduler.capacity.ParentQueue: assignedContainer queue=root usedCapacity=1.0 absoluteUsedCapacity=1.0 used=<memory:49152, vCores:43> cluster=<memory:49152, vCores:96>
2013-08-11 01:54:22,911 INFO org.apache.hadoop.yarn.server.resourcemanager.rmcontainer.RMContainerImpl: container_1376185025835_0007_01_000003 Container Transitioned from ACQUIRED to RUNNING
2013-08-11 01:54:22,912 INFO org.apache.hadoop.yarn.server.resourcemanager.rmcontainer.RMContainerImpl: container_1376185025835_0007_01_000004 Container Transitioned from ACQUIRED to RUNNING
2013-08-11 01:54:22,912 INFO org.apache.hadoop.yarn.server.resourcemanager.rmcontainer.RMContainerImpl: container_1376185025835_0007_01_000009 Container Transitioned from ACQUIRED to RUNNING
2013-08-11 01:54:22,912 INFO org.apache.hadoop.yarn.server.resourcemanager.rmcontainer.RMContainerImpl: container_1376185025835_0007_01_000010 Container Transitioned from ACQUIRED to RUNNING
2013-08-11 01:54:22,912 INFO org.apache.hadoop.yarn.server.resourcemanager.rmcontainer.RMContainerImpl: container_1376185025835_0007_01_000011 Container Transitioned from ACQUIRED to RUNNING
2013-08-11 01:54:23,164 INFO org.apache.hadoop.yarn.server.resourcemanager.rmcontainer.RMContainerImpl: container_1376185025835_0007_01_000005 Container Transitioned from ACQUIRED to RUNNING
2013-08-11 01:54:23,165 INFO org.apache.hadoop.yarn.server.resourcemanager.rmcontainer.RMContainerImpl: container_1376185025835_0007_01_000006 Container Transitioned from ACQUIRED to RUNNING
2013-08-11 01:54:23,165 INFO org.apache.hadoop.yarn.server.resourcemanager.rmcontainer.RMContainerImpl: container_1376185025835_0007_01_000012 Container Transitioned from ACQUIRED to RUNNING
2013-08-11 01:54:23,215 INFO org.apache.hadoop.yarn.server.resourcemanager.rmcontainer.RMContainerImpl: container_1376185025835_0007_01_000007 Container Transitioned from ACQUIRED to RUNNING
2013-08-11 01:54:23,254 INFO org.apache.hadoop.yarn.server.resourcemanager.rmcontainer.RMContainerImpl: container_1376185025835_0007_01_000013 Container Transitioned from ALLOCATED to ACQUIRED
2013-08-11 01:54:23,327 INFO org.apache.hadoop.yarn.server.resourcemanager.rmcontainer.RMContainerImpl: container_1376185025835_0007_01_000008 Container Transitioned from ACQUIRED to RUNNING
2013-08-11 01:54:23,439 INFO org.apache.hadoop.yarn.server.resourcemanager.rmcontainer.RMContainerImpl: container_1376185025835_0007_01_000013 Container Transitioned from ACQUIRED to RUNNING
2013-08-11 01:54:24,734 INFO org.apache.hadoop.yarn.server.resourcemanager.rmcontainer.RMContainerImpl: container_1376185025835_0006_01_000010 Container Transitioned from RUNNING to COMPLETED
2013-08-11 01:54:24,734 INFO org.apache.hadoop.yarn.server.resourcemanager.scheduler.common.fica.FiCaSchedulerApp: Completed container: container_1376185025835_0006_01_000010 in state: COMPLETED event:FINISHED
2013-08-11 01:54:24,734 INFO org.apache.hadoop.yarn.server.resourcemanager.RMAuditLogger: USER=ubuntu	OPERATION=AM Released Container	TARGET=SchedulerApp	RESULT=SUCCESS	APPID=application_1376185025835_0006	CONTAINERID=container_1376185025835_0006_01_000010
2013-08-11 01:54:24,735 INFO org.apache.hadoop.yarn.server.resourcemanager.scheduler.common.fica.FiCaSchedulerNode: Released container container_1376185025835_0006_01_000010 of capacity <memory:1024, vCores:1> on host hadoop-321-3:44876, which currently has 6 containers, <memory:7168, vCores:6> used and <memory:1024, vCores:10> available, release resources=true
2013-08-11 01:54:24,735 INFO org.apache.hadoop.yarn.server.resourcemanager.scheduler.capacity.LeafQueue: default used=<memory:48128, vCores:42> numContainers=42 user=ubuntu user-resources=<memory:48128, vCores:42>
2013-08-11 01:54:24,736 INFO org.apache.hadoop.yarn.server.resourcemanager.scheduler.capacity.LeafQueue: completedContainer container=Container: [ContainerId: container_1376185025835_0006_01_000010, NodeId: hadoop-321-3:44876, NodeHttpAddress: hadoop-321-3:8042, Resource: <memory:1024, vCores:1>, Priority: 20, State: NEW, Token: null, Status: container_id {, app_attempt_id {, application_id {, id: 6, cluster_timestamp: 1376185025835, }, attemptId: 1, }, id: 10, }, state: C_COMPLETE, diagnostics: "Container killed by the ApplicationMaster.\n", exit_status: 0, ] resource=<memory:1024, vCores:1> queue=default: capacity=1.0, absoluteCapacity=1.0, usedResources=<memory:48128, vCores:42>usedCapacity=0.9791667, absoluteUsedCapacity=0.9791667, numApps=5, numContainers=42 usedCapacity=0.9791667 absoluteUsedCapacity=0.9791667 used=<memory:48128, vCores:42> cluster=<memory:49152, vCores:96>
2013-08-11 01:54:24,736 INFO org.apache.hadoop.yarn.server.resourcemanager.scheduler.capacity.ParentQueue: completedContainer queue=root usedCapacity=0.9791667 absoluteUsedCapacity=0.9791667 used=<memory:48128, vCores:42> cluster=<memory:49152, vCores:96>
2013-08-11 01:54:24,736 INFO org.apache.hadoop.yarn.server.resourcemanager.scheduler.capacity.CapacityScheduler: Application appattempt_1376185025835_0006_000001 released container container_1376185025835_0006_01_000010 on node: host: hadoop-321-3:44876 #containers=6 available=1024 used=7168 with event: FINISHED
2013-08-11 01:54:24,737 INFO org.apache.hadoop.yarn.server.resourcemanager.rmcontainer.RMContainerImpl: container_1376185025835_0007_01_000014 Container Transitioned from NEW to ALLOCATED
2013-08-11 01:54:24,737 INFO org.apache.hadoop.yarn.server.resourcemanager.RMAuditLogger: USER=ubuntu	OPERATION=AM Allocated Container	TARGET=SchedulerApp	RESULT=SUCCESS	APPID=application_1376185025835_0007	CONTAINERID=container_1376185025835_0007_01_000014
