2013-08-16 20:39:26,273 INFO org.apache.hadoop.yarn.server.resourcemanager.ResourceManager: STARTUP_MSG: 
/************************************************************
STARTUP_MSG: Starting ResourceManager
STARTUP_MSG:   host = hadoop-512-1/192.168.100.6
STARTUP_MSG:   args = []
STARTUP_MSG:   version = 3.0.0-SNAPSHOT
STARTUP_MSG:   build = https://github.com/lalithsuresh/hadoop-common -r 0cb423bd4868928bb06cd93f882bb0913172fd17; compiled by 'lsuresh' on 2013-04-08T15:47Z
STARTUP_MSG:   java = 1.7.0_17
************************************************************/
2013-08-16 20:39:26,288 INFO org.apache.hadoop.yarn.server.resourcemanager.ResourceManager: registered UNIX signal handlers for [TERM, HUP, INT]
2013-08-16 20:39:27,029 INFO org.apache.hadoop.yarn.server.resourcemanager.security.ApplicationTokenSecretManager: Rolling master-key for application-tokens
2013-08-16 20:39:27,076 INFO org.apache.hadoop.yarn.server.resourcemanager.security.RMContainerTokenSecretManager: ContainerTokenKeyRollingInterval: 86400000ms and ContainerTokenKeyActivationDelay: 900000ms
2013-08-16 20:39:27,080 INFO org.apache.hadoop.yarn.service.AbstractService: Service:Dispatcher is inited.
2013-08-16 20:39:27,084 INFO org.apache.hadoop.yarn.event.AsyncDispatcher: Registering class org.apache.hadoop.yarn.server.resourcemanager.recovery.RMStateStoreEventType for class org.apache.hadoop.yarn.server.resourcemanager.recovery.RMStateStore$ForwardingEventHandler
2013-08-16 20:39:27,084 INFO org.apache.hadoop.yarn.service.AbstractService: Service:Dispatcher is started.
2013-08-16 20:39:27,094 INFO org.apache.hadoop.yarn.event.AsyncDispatcher: Registering class org.apache.hadoop.yarn.server.resourcemanager.NodesListManagerEventType for class org.apache.hadoop.yarn.server.resourcemanager.NodesListManager
2013-08-16 20:39:27,094 INFO org.apache.hadoop.yarn.server.resourcemanager.ResourceManager: Using Scheduler: org.apache.hadoop.yarn.server.resourcemanager.scheduler.capacity.CapacityScheduler
2013-08-16 20:39:27,386 INFO org.apache.hadoop.yarn.event.AsyncDispatcher: Registering class org.apache.hadoop.yarn.server.resourcemanager.scheduler.event.SchedulerEventType for class org.apache.hadoop.yarn.server.resourcemanager.ResourceManager$SchedulerEventDispatcher
2013-08-16 20:39:27,396 INFO org.apache.hadoop.yarn.event.AsyncDispatcher: Registering class org.apache.hadoop.yarn.server.resourcemanager.rmapp.RMAppEventType for class org.apache.hadoop.yarn.server.resourcemanager.ResourceManager$ApplicationEventDispatcher
2013-08-16 20:39:27,399 INFO org.apache.hadoop.yarn.event.AsyncDispatcher: Registering class org.apache.hadoop.yarn.server.resourcemanager.rmapp.attempt.RMAppAttemptEventType for class org.apache.hadoop.yarn.server.resourcemanager.ResourceManager$ApplicationAttemptEventDispatcher
2013-08-16 20:39:27,416 INFO org.apache.hadoop.yarn.event.AsyncDispatcher: Registering class org.apache.hadoop.yarn.server.resourcemanager.rmnode.RMNodeEventType for class org.apache.hadoop.yarn.server.resourcemanager.ResourceManager$NodeEventDispatcher
2013-08-16 20:39:28,178 WARN org.apache.hadoop.util.NativeCodeLoader: Unable to load native-hadoop library for your platform... using builtin-java classes where applicable
2013-08-16 20:39:28,226 INFO org.apache.hadoop.yarn.server.resourcemanager.scheduler.capacity.ParentQueue: root, capacity=1.0, asboluteCapacity=1.0, maxCapacity=1.0, asboluteMaxCapacity=1.0, state=RUNNING, acls=SUBMIT_APPLICATIONS:*ADMINISTER_QUEUE:*
2013-08-16 20:39:28,226 INFO org.apache.hadoop.yarn.server.resourcemanager.scheduler.capacity.ParentQueue: Initialized parent-queue root name=root, fullname=root
2013-08-16 20:39:28,246 INFO org.apache.hadoop.yarn.server.resourcemanager.scheduler.capacity.LeafQueue: Initializing default
capacity = 1.0 [= (float) configuredCapacity / 100 ]
asboluteCapacity = 1.0 [= parentAbsoluteCapacity * capacity ]
maxCapacity = 1.0 [= configuredMaxCapacity ]
absoluteMaxCapacity = 1.0 [= 1.0 maximumCapacity undefined, (parentAbsoluteMaxCapacity * maximumCapacity) / 100 otherwise ]
userLimit = 100 [= configuredUserLimit ]
userLimitFactor = 1.0 [= configuredUserLimitFactor ]
maxApplications = 10000 [= configuredMaximumSystemApplicationsPerQueue or (int)(configuredMaximumSystemApplications * absoluteCapacity)]
maxApplicationsPerUser = 10000 [= (int)(maxApplications * (userLimit / 100.0f) * userLimitFactor) ]
maxActiveApplications = 1 [= max((int)ceil((clusterResourceMemory / minimumAllocation) * maxAMResourcePerQueuePercent * absoluteMaxCapacity),1) ]
maxActiveAppsUsingAbsCap = 1 [= max((int)ceil((clusterResourceMemory / minimumAllocation) *maxAMResourcePercent * absoluteCapacity),1) ]
maxActiveApplicationsPerUser = 1 [= max((int)(maxActiveApplications * (userLimit / 100.0f) * userLimitFactor),1) ]
usedCapacity = 0.0 [= usedResourcesMemory / (clusterResourceMemory * absoluteCapacity)]
absoluteUsedCapacity = 0.0 [= usedResourcesMemory / clusterResourceMemory]
maxAMResourcePerQueuePercent = 0.1 [= configuredMaximumAMResourcePercent ]
minimumAllocationFactor = 0.875 [= (float)(maximumAllocationMemory - minimumAllocationMemory) / maximumAllocationMemory ]
numContainers = 0 [= currentNumContainers ]
state = RUNNING [= configuredState ]
acls = SUBMIT_APPLICATIONS:*ADMINISTER_QUEUE:* [= configuredAcls ]

2013-08-16 20:39:28,247 INFO org.apache.hadoop.yarn.server.resourcemanager.scheduler.capacity.CapacityScheduler: Initialized queue: default: capacity=1.0, absoluteCapacity=1.0, usedResources=<memory:0, vCores:0>usedCapacity=0.0, absoluteUsedCapacity=0.0, numApps=0, numContainers=0
2013-08-16 20:39:28,247 INFO org.apache.hadoop.yarn.server.resourcemanager.scheduler.capacity.CapacityScheduler: Initialized queue: root: numChildQueue= 1, capacity=1.0, absoluteCapacity=1.0, usedResources=<memory:0, vCores:0>usedCapacity=0.0, numApps=0, numContainers=0
2013-08-16 20:39:28,247 INFO org.apache.hadoop.yarn.server.resourcemanager.scheduler.capacity.CapacityScheduler: Initialized root queue root: numChildQueue= 1, capacity=1.0, absoluteCapacity=1.0, usedResources=<memory:0, vCores:0>usedCapacity=0.0, numApps=0, numContainers=0
2013-08-16 20:39:28,247 INFO org.apache.hadoop.yarn.server.resourcemanager.scheduler.capacity.CapacityScheduler: Initialized CapacityScheduler with calculator=class org.apache.hadoop.yarn.server.resourcemanager.resource.DefaultResourceCalculator, minimumAllocation=<<memory:1024, vCores:1>>, maximumAllocation=<<memory:8192, vCores:32>>
2013-08-16 20:39:28,680 INFO org.apache.hadoop.yarn.event.AsyncDispatcher: Registering class org.apache.hadoop.yarn.server.resourcemanager.RMAppManagerEventType for class org.apache.hadoop.yarn.server.resourcemanager.RMAppManager
2013-08-16 20:39:28,702 INFO org.apache.hadoop.yarn.event.AsyncDispatcher: Registering class org.apache.hadoop.yarn.server.resourcemanager.amlauncher.AMLauncherEventType for class org.apache.hadoop.yarn.server.resourcemanager.amlauncher.ApplicationMasterLauncher
2013-08-16 20:39:28,803 INFO org.apache.hadoop.yarn.server.resourcemanager.RMNMInfo: Registered RMNMInfo MBean
2013-08-16 20:39:28,803 INFO org.apache.hadoop.yarn.service.AbstractService: Service:Dispatcher is inited.
2013-08-16 20:39:28,803 INFO org.apache.hadoop.yarn.service.AbstractService: Service:org.apache.hadoop.yarn.server.resourcemanager.rmcontainer.ContainerAllocationExpirer is inited.
2013-08-16 20:39:28,803 INFO org.apache.hadoop.yarn.service.AbstractService: Service:AMLivelinessMonitor is inited.
2013-08-16 20:39:28,803 INFO org.apache.hadoop.yarn.service.AbstractService: Service:AMLivelinessMonitor is inited.
2013-08-16 20:39:28,804 INFO org.apache.hadoop.yarn.service.AbstractService: Service:org.apache.hadoop.yarn.server.resourcemanager.security.DelegationTokenRenewer is inited.
2013-08-16 20:39:28,805 INFO org.apache.hadoop.util.HostsFileReader: Refreshing hosts (include/exclude) list
2013-08-16 20:39:28,806 INFO org.apache.hadoop.yarn.service.AbstractService: Service:org.apache.hadoop.yarn.server.resourcemanager.NodesListManager is inited.
2013-08-16 20:39:28,806 INFO org.apache.hadoop.yarn.service.AbstractService: Service:org.apache.hadoop.yarn.server.resourcemanager.ResourceManager$SchedulerEventDispatcher is inited.
2013-08-16 20:39:28,806 INFO org.apache.hadoop.yarn.service.AbstractService: Service:NMLivelinessMonitor is inited.
2013-08-16 20:39:28,814 INFO org.apache.hadoop.yarn.service.AbstractService: Service:org.apache.hadoop.yarn.server.resourcemanager.ResourceTrackerService is inited.
2013-08-16 20:39:28,814 INFO org.apache.hadoop.yarn.service.AbstractService: Service:org.apache.hadoop.yarn.server.resourcemanager.ApplicationMasterService is inited.
2013-08-16 20:39:28,814 INFO org.apache.hadoop.yarn.service.AbstractService: Service:org.apache.hadoop.yarn.server.resourcemanager.ClientRMService is inited.
2013-08-16 20:39:28,815 INFO org.apache.hadoop.yarn.service.AbstractService: Service:org.apache.hadoop.yarn.server.resourcemanager.AdminService is inited.
2013-08-16 20:39:28,815 INFO org.apache.hadoop.yarn.service.AbstractService: Service:org.apache.hadoop.yarn.server.resourcemanager.amlauncher.ApplicationMasterLauncher is inited.
2013-08-16 20:39:28,815 INFO org.apache.hadoop.yarn.service.AbstractService: Service:ResourceManager is inited.
2013-08-16 20:39:28,815 INFO org.apache.hadoop.yarn.server.resourcemanager.security.ApplicationTokenSecretManager: Rolling master-key for application-tokens
2013-08-16 20:39:28,816 INFO org.apache.hadoop.yarn.server.resourcemanager.security.RMContainerTokenSecretManager: Rolling master-key for container-tokens
2013-08-16 20:39:28,978 INFO org.mortbay.log: Logging to org.slf4j.impl.Log4jLoggerAdapter(org.mortbay.log) via org.mortbay.log.Slf4jLog
2013-08-16 20:39:29,080 INFO org.apache.hadoop.http.HttpServer: Added global filter 'safety' (class=org.apache.hadoop.http.HttpServer$QuotingInputFilter)
2013-08-16 20:39:29,084 INFO org.apache.hadoop.http.HttpServer: Added filter static_user_filter (class=org.apache.hadoop.http.lib.StaticUserWebFilter$StaticUserFilter) to context cluster
2013-08-16 20:39:29,085 INFO org.apache.hadoop.http.HttpServer: Added filter static_user_filter (class=org.apache.hadoop.http.lib.StaticUserWebFilter$StaticUserFilter) to context static
2013-08-16 20:39:29,085 INFO org.apache.hadoop.http.HttpServer: Added filter static_user_filter (class=org.apache.hadoop.http.lib.StaticUserWebFilter$StaticUserFilter) to context logs
2013-08-16 20:39:29,092 INFO org.apache.hadoop.http.HttpServer: adding path spec: /cluster
2013-08-16 20:39:29,093 INFO org.apache.hadoop.http.HttpServer: adding path spec: /cluster/*
2013-08-16 20:39:29,093 INFO org.apache.hadoop.http.HttpServer: adding path spec: /ws
2013-08-16 20:39:29,093 INFO org.apache.hadoop.http.HttpServer: adding path spec: /ws/*
2013-08-16 20:39:29,096 INFO org.apache.hadoop.http.HttpServer: Added global filter 'guice' (class=com.google.inject.servlet.GuiceFilter)
2013-08-16 20:39:29,106 INFO org.apache.hadoop.http.HttpServer: Jetty bound to port 8088
2013-08-16 20:39:29,106 INFO org.mortbay.log: jetty-6.1.26
2013-08-16 20:39:29,160 INFO org.mortbay.log: Extract jar:file:/home/ubuntu/hadoop-3.0.0-SNAPSHOT/share/hadoop/yarn/hadoop-yarn-common-3.0.0-SNAPSHOT.jar!/webapps/cluster to /tmp/Jetty_0_0_0_0_8088_cluster____u0rgz3/webapp
2013-08-16 20:39:29,670 INFO org.mortbay.log: Started SelectChannelConnector@0.0.0.0:8088
2013-08-16 20:39:29,670 INFO org.apache.hadoop.yarn.webapp.WebApps: Web app /cluster started at 8088
2013-08-16 20:39:30,617 INFO org.apache.hadoop.yarn.webapp.WebApps: Registered webapp guice modules
2013-08-16 20:39:30,737 INFO org.apache.hadoop.metrics2.impl.MetricsConfig: loaded properties from hadoop-metrics2.properties
2013-08-16 20:39:30,772 INFO org.apache.hadoop.metrics2.impl.MetricsSystemImpl: Scheduled snapshot period at 10 second(s).
2013-08-16 20:39:30,773 INFO org.apache.hadoop.metrics2.impl.MetricsSystemImpl: ResourceManager metrics system started
2013-08-16 20:39:30,789 INFO org.apache.hadoop.security.token.delegation.AbstractDelegationTokenSecretManager: Updating the current master key for generating delegation tokens
2013-08-16 20:39:30,792 INFO org.apache.hadoop.yarn.service.AbstractService: Service:Dispatcher is started.
2013-08-16 20:39:30,793 INFO org.apache.hadoop.security.token.delegation.AbstractDelegationTokenSecretManager: Starting expired delegation token remover thread, tokenRemoverScanInterval=60 min(s)
2013-08-16 20:39:30,793 INFO org.apache.hadoop.security.token.delegation.AbstractDelegationTokenSecretManager: Updating the current master key for generating delegation tokens
2013-08-16 20:39:30,795 INFO org.apache.hadoop.yarn.service.AbstractService: Service:org.apache.hadoop.yarn.server.resourcemanager.rmcontainer.ContainerAllocationExpirer is started.
2013-08-16 20:39:30,795 INFO org.apache.hadoop.yarn.service.AbstractService: Service:AMLivelinessMonitor is started.
2013-08-16 20:39:30,796 INFO org.apache.hadoop.yarn.service.AbstractService: Service:AMLivelinessMonitor is started.
2013-08-16 20:39:30,796 INFO org.apache.hadoop.yarn.service.AbstractService: Service:org.apache.hadoop.yarn.server.resourcemanager.security.DelegationTokenRenewer is started.
2013-08-16 20:39:30,797 INFO org.apache.hadoop.yarn.service.AbstractService: Service:org.apache.hadoop.yarn.server.resourcemanager.NodesListManager is started.
2013-08-16 20:39:30,797 INFO org.apache.hadoop.yarn.service.AbstractService: Service:org.apache.hadoop.yarn.server.resourcemanager.ResourceManager$SchedulerEventDispatcher is started.
2013-08-16 20:39:30,798 INFO org.apache.hadoop.yarn.service.AbstractService: Service:NMLivelinessMonitor is started.
2013-08-16 20:39:30,798 INFO org.apache.hadoop.yarn.service.AbstractService: Service:org.apache.hadoop.yarn.server.resourcemanager.ResourceTrackerService is started.
2013-08-16 20:39:30,876 INFO org.apache.hadoop.ipc.Server: Starting Socket Reader #1 for port 54110
2013-08-16 20:39:30,921 INFO org.apache.hadoop.yarn.factories.impl.pb.RpcServerFactoryPBImpl: Adding protocol org.apache.hadoop.yarn.server.api.ResourceTrackerPB to the server
2013-08-16 20:39:30,922 INFO org.apache.hadoop.ipc.Server: IPC Server listener on 54110: starting
2013-08-16 20:39:30,922 INFO org.apache.hadoop.ipc.Server: IPC Server Responder: starting
2013-08-16 20:39:31,050 INFO org.apache.hadoop.ipc.Server: Starting Socket Reader #1 for port 54112
2013-08-16 20:39:31,068 INFO org.apache.hadoop.yarn.factories.impl.pb.RpcServerFactoryPBImpl: Adding protocol org.apache.hadoop.yarn.api.AMRMProtocolPB to the server
2013-08-16 20:39:31,069 INFO org.apache.hadoop.ipc.Server: IPC Server Responder: starting
2013-08-16 20:39:31,070 INFO org.apache.hadoop.ipc.Server: IPC Server listener on 54112: starting
2013-08-16 20:39:31,099 INFO org.apache.hadoop.yarn.service.AbstractService: Service:org.apache.hadoop.yarn.server.resourcemanager.ApplicationMasterService is started.
2013-08-16 20:39:31,153 INFO org.apache.hadoop.ipc.Server: Starting Socket Reader #1 for port 54111
2013-08-16 20:39:31,159 INFO org.apache.hadoop.yarn.factories.impl.pb.RpcServerFactoryPBImpl: Adding protocol org.apache.hadoop.yarn.api.ClientRMProtocolPB to the server
2013-08-16 20:39:31,160 INFO org.apache.hadoop.ipc.Server: IPC Server Responder: starting
2013-08-16 20:39:31,161 INFO org.apache.hadoop.ipc.Server: IPC Server listener on 54111: starting
2013-08-16 20:39:31,207 INFO org.apache.hadoop.yarn.service.AbstractService: Service:org.apache.hadoop.yarn.server.resourcemanager.ClientRMService is started.
2013-08-16 20:39:31,242 INFO org.apache.hadoop.ipc.Server: Starting Socket Reader #1 for port 8033
2013-08-16 20:39:31,248 INFO org.apache.hadoop.yarn.factories.impl.pb.RpcServerFactoryPBImpl: Adding protocol org.apache.hadoop.yarn.api.RMAdminProtocolPB to the server
2013-08-16 20:39:31,249 INFO org.apache.hadoop.ipc.Server: IPC Server Responder: starting
2013-08-16 20:39:31,249 INFO org.apache.hadoop.ipc.Server: IPC Server listener on 8033: starting
2013-08-16 20:39:31,252 INFO org.apache.hadoop.yarn.service.AbstractService: Service:org.apache.hadoop.yarn.server.resourcemanager.AdminService is started.
2013-08-16 20:39:31,253 INFO org.apache.hadoop.yarn.service.AbstractService: Service:org.apache.hadoop.yarn.server.resourcemanager.amlauncher.ApplicationMasterLauncher is started.
2013-08-16 20:39:31,253 INFO org.apache.hadoop.yarn.service.AbstractService: Service:ResourceManager is started.
2013-08-16 20:39:40,903 INFO org.apache.hadoop.yarn.util.RackResolver: Resolved hadoop-512-5 to /default-rack
2013-08-16 20:39:40,904 INFO org.apache.hadoop.yarn.util.RackResolver: Resolved hadoop-512-4 to /default-rack
2013-08-16 20:39:40,914 INFO org.apache.hadoop.yarn.util.RackResolver: Resolved hadoop-512-6 to /default-rack
2013-08-16 20:39:40,915 INFO org.apache.hadoop.yarn.util.RackResolver: Resolved hadoop-512-3 to /default-rack
2013-08-16 20:39:40,916 INFO org.apache.hadoop.yarn.util.RackResolver: Resolved hadoop-512-2 to /default-rack
2013-08-16 20:39:40,924 INFO org.apache.hadoop.yarn.server.resourcemanager.ResourceTrackerService: NodeManager from node hadoop-512-3(cmPort: 58863 httpPort: 8042) registered with capability: <memory:8192, vCores:16>, assigned nodeId hadoop-512-3:58863
2013-08-16 20:39:40,924 INFO org.apache.hadoop.yarn.server.resourcemanager.ResourceTrackerService: NodeManager from node hadoop-512-4(cmPort: 51823 httpPort: 8042) registered with capability: <memory:8192, vCores:16>, assigned nodeId hadoop-512-4:51823
2013-08-16 20:39:40,930 INFO org.apache.hadoop.yarn.server.resourcemanager.ResourceTrackerService: NodeManager from node hadoop-512-6(cmPort: 40600 httpPort: 8042) registered with capability: <memory:8192, vCores:16>, assigned nodeId hadoop-512-6:40600
2013-08-16 20:39:40,923 INFO org.apache.hadoop.yarn.server.resourcemanager.ResourceTrackerService: NodeManager from node hadoop-512-5(cmPort: 53603 httpPort: 8042) registered with capability: <memory:8192, vCores:16>, assigned nodeId hadoop-512-5:53603
2013-08-16 20:39:40,918 INFO org.apache.hadoop.yarn.util.RackResolver: Resolved hadoop-512-7 to /default-rack
2013-08-16 20:39:40,930 INFO org.apache.hadoop.yarn.server.resourcemanager.ResourceTrackerService: NodeManager from node hadoop-512-2(cmPort: 41669 httpPort: 8042) registered with capability: <memory:8192, vCores:16>, assigned nodeId hadoop-512-2:41669
2013-08-16 20:39:40,941 INFO org.apache.hadoop.yarn.server.resourcemanager.ResourceTrackerService: NodeManager from node hadoop-512-7(cmPort: 51513 httpPort: 8042) registered with capability: <memory:8192, vCores:16>, assigned nodeId hadoop-512-7:51513
2013-08-16 20:39:40,956 INFO org.apache.hadoop.yarn.server.resourcemanager.rmnode.RMNodeImpl: hadoop-512-5:53603 Node Transitioned from NEW to RUNNING
2013-08-16 20:39:40,956 INFO org.apache.hadoop.yarn.server.resourcemanager.rmnode.RMNodeImpl: hadoop-512-3:58863 Node Transitioned from NEW to RUNNING
2013-08-16 20:39:40,956 INFO org.apache.hadoop.yarn.server.resourcemanager.rmnode.RMNodeImpl: hadoop-512-4:51823 Node Transitioned from NEW to RUNNING
2013-08-16 20:39:40,957 INFO org.apache.hadoop.yarn.server.resourcemanager.rmnode.RMNodeImpl: hadoop-512-6:40600 Node Transitioned from NEW to RUNNING
2013-08-16 20:39:40,957 INFO org.apache.hadoop.yarn.server.resourcemanager.rmnode.RMNodeImpl: hadoop-512-2:41669 Node Transitioned from NEW to RUNNING
2013-08-16 20:39:40,958 INFO org.apache.hadoop.yarn.server.resourcemanager.rmnode.RMNodeImpl: hadoop-512-7:51513 Node Transitioned from NEW to RUNNING
2013-08-16 20:39:40,961 INFO org.apache.hadoop.yarn.server.resourcemanager.scheduler.capacity.CapacityScheduler: Added node hadoop-512-5:53603 clusterResource: <memory:8192, vCores:16>
2013-08-16 20:39:40,962 INFO org.apache.hadoop.yarn.server.resourcemanager.scheduler.capacity.CapacityScheduler: Added node hadoop-512-3:58863 clusterResource: <memory:16384, vCores:32>
2013-08-16 20:39:40,962 INFO org.apache.hadoop.yarn.server.resourcemanager.scheduler.capacity.CapacityScheduler: Added node hadoop-512-4:51823 clusterResource: <memory:24576, vCores:48>
2013-08-16 20:39:40,962 INFO org.apache.hadoop.yarn.server.resourcemanager.scheduler.capacity.CapacityScheduler: Added node hadoop-512-6:40600 clusterResource: <memory:32768, vCores:64>
2013-08-16 20:39:40,963 INFO org.apache.hadoop.yarn.server.resourcemanager.scheduler.capacity.CapacityScheduler: Added node hadoop-512-2:41669 clusterResource: <memory:40960, vCores:80>
2013-08-16 20:39:40,963 INFO org.apache.hadoop.yarn.server.resourcemanager.scheduler.capacity.CapacityScheduler: Added node hadoop-512-7:51513 clusterResource: <memory:49152, vCores:96>
2013-08-16 20:39:46,927 INFO org.apache.hadoop.yarn.server.resourcemanager.ClientRMService: Allocated new applicationId: 1
2013-08-16 20:39:50,390 INFO org.apache.hadoop.yarn.server.resourcemanager.ClientRMService: Storing Application with id application_1376685566219_0001
2013-08-16 20:39:50,397 INFO org.apache.hadoop.yarn.server.resourcemanager.recovery.RMStateStore: Storing info for app: application_1376685566219_0001
2013-08-16 20:39:50,397 INFO org.apache.hadoop.yarn.server.resourcemanager.ClientRMService: Application with id 1 submitted by user ubuntu
2013-08-16 20:39:50,401 INFO org.apache.hadoop.yarn.server.resourcemanager.RMAuditLogger: USER=ubuntu	IP=192.168.100.6	OPERATION=Submit Application Request	TARGET=ClientRMService	RESULT=SUCCESS	APPID=application_1376685566219_0001
2013-08-16 20:39:50,442 INFO org.apache.hadoop.yarn.server.resourcemanager.rmapp.RMAppImpl: application_1376685566219_0001 State change from NEW to SUBMITTED
2013-08-16 20:39:50,443 INFO org.apache.hadoop.yarn.server.resourcemanager.ApplicationMasterService: Registering appattempt_1376685566219_0001_000001
2013-08-16 20:39:50,444 INFO org.apache.hadoop.yarn.server.resourcemanager.rmapp.attempt.RMAppAttemptImpl: appattempt_1376685566219_0001_000001 State change from NEW to SUBMITTED
2013-08-16 20:39:50,487 INFO org.apache.hadoop.yarn.server.resourcemanager.scheduler.capacity.LeafQueue: Application application_1376685566219_0001 from user: ubuntu activated in queue: default
2013-08-16 20:39:50,487 INFO org.apache.hadoop.yarn.server.resourcemanager.scheduler.capacity.LeafQueue: Application added - appId: application_1376685566219_0001 user: org.apache.hadoop.yarn.server.resourcemanager.scheduler.capacity.LeafQueue$User@44aab8fd, leaf-queue: default #user-pending-applications: 0 #user-active-applications: 1 #queue-pending-applications: 0 #queue-active-applications: 1
2013-08-16 20:39:50,487 INFO org.apache.hadoop.yarn.server.resourcemanager.scheduler.capacity.ParentQueue: Application added - appId: application_1376685566219_0001 user: ubuntu leaf-queue of parent: root #applications: 1
2013-08-16 20:39:50,488 INFO org.apache.hadoop.yarn.server.resourcemanager.scheduler.capacity.CapacityScheduler: Application Submission: appattempt_1376685566219_0001_000001, user: ubuntu queue: default: capacity=1.0, absoluteCapacity=1.0, usedResources=<memory:0, vCores:0>usedCapacity=0.0, absoluteUsedCapacity=0.0, numApps=1, numContainers=0, currently active: 1
2013-08-16 20:39:50,494 INFO org.apache.hadoop.yarn.server.resourcemanager.rmapp.attempt.RMAppAttemptImpl: appattempt_1376685566219_0001_000001 State change from SUBMITTED to SCHEDULED
2013-08-16 20:39:50,494 INFO org.apache.hadoop.yarn.server.resourcemanager.rmapp.RMAppImpl: application_1376685566219_0001 State change from SUBMITTED to ACCEPTED
2013-08-16 20:39:51,112 INFO org.apache.hadoop.yarn.server.resourcemanager.rmcontainer.RMContainerImpl: container_1376685566219_0001_01_000001 Container Transitioned from NEW to ALLOCATED
2013-08-16 20:39:51,113 INFO org.apache.hadoop.yarn.server.resourcemanager.RMAuditLogger: USER=ubuntu	OPERATION=AM Allocated Container	TARGET=SchedulerApp	RESULT=SUCCESS	APPID=application_1376685566219_0001	CONTAINERID=container_1376685566219_0001_01_000001
2013-08-16 20:39:51,114 INFO org.apache.hadoop.yarn.server.resourcemanager.scheduler.common.fica.FiCaSchedulerNode: Assigned container container_1376685566219_0001_01_000001 of capacity <memory:2048, vCores:1> on host hadoop-512-3:58863, which currently has 1 containers, <memory:2048, vCores:1> used and <memory:6144, vCores:15> available
2013-08-16 20:39:51,120 INFO org.apache.hadoop.yarn.server.resourcemanager.scheduler.capacity.LeafQueue: assignedContainer application=application_1376685566219_0001 container=Container: [ContainerId: container_1376685566219_0001_01_000001, NodeId: hadoop-512-3:58863, NodeHttpAddress: hadoop-512-3:8042, Resource: <memory:2048, vCores:1>, Priority: 0, State: NEW, Token: null, Status: container_id {, app_attempt_id {, application_id {, id: 1, cluster_timestamp: 1376685566219, }, attemptId: 1, }, id: 1, }, state: C_NEW, ] containerId=container_1376685566219_0001_01_000001 queue=default: capacity=1.0, absoluteCapacity=1.0, usedResources=<memory:0, vCores:0>usedCapacity=0.0, absoluteUsedCapacity=0.0, numApps=1, numContainers=0 usedCapacity=0.0 absoluteUsedCapacity=0.0 used=<memory:0, vCores:0> cluster=<memory:49152, vCores:96>
2013-08-16 20:39:51,120 INFO org.apache.hadoop.yarn.server.resourcemanager.scheduler.capacity.ParentQueue: Re-sorting queues since queue: root.default stats: default: capacity=1.0, absoluteCapacity=1.0, usedResources=<memory:2048, vCores:1>usedCapacity=0.041666668, absoluteUsedCapacity=0.041666668, numApps=1, numContainers=1
2013-08-16 20:39:51,121 INFO org.apache.hadoop.yarn.server.resourcemanager.scheduler.capacity.ParentQueue: assignedContainer queue=root usedCapacity=0.041666668 absoluteUsedCapacity=0.041666668 used=<memory:2048, vCores:1> cluster=<memory:49152, vCores:96>
2013-08-16 20:39:51,124 INFO org.apache.hadoop.yarn.server.resourcemanager.rmcontainer.RMContainerImpl: container_1376685566219_0001_01_000001 Container Transitioned from ALLOCATED to ACQUIRED
2013-08-16 20:39:51,127 INFO org.apache.hadoop.yarn.server.resourcemanager.rmapp.attempt.RMAppAttemptImpl: Storing attempt: AppId: application_1376685566219_0001 AttemptId: appattempt_1376685566219_0001_000001 MasterContainer: Container: [ContainerId: container_1376685566219_0001_01_000001, NodeId: hadoop-512-3:58863, NodeHttpAddress: hadoop-512-3:8042, Resource: <memory:2048, vCores:1>, Priority: 0, State: NEW, Token: null, Status: container_id {, app_attempt_id {, application_id {, id: 1, cluster_timestamp: 1376685566219, }, attemptId: 1, }, id: 1, }, state: C_NEW, ]
2013-08-16 20:39:51,131 INFO org.apache.hadoop.yarn.server.resourcemanager.rmapp.attempt.RMAppAttemptImpl: appattempt_1376685566219_0001_000001 State change from SCHEDULED to ALLOCATED_SAVING
2013-08-16 20:39:51,135 INFO org.apache.hadoop.yarn.server.resourcemanager.recovery.RMStateStore: Storing info for attempt: appattempt_1376685566219_0001_000001
2013-08-16 20:39:51,138 INFO org.apache.hadoop.yarn.server.resourcemanager.rmapp.attempt.RMAppAttemptImpl: appattempt_1376685566219_0001_000001 State change from ALLOCATED_SAVING to ALLOCATED
2013-08-16 20:39:51,145 INFO org.apache.hadoop.yarn.server.resourcemanager.amlauncher.AMLauncher: Launching masterappattempt_1376685566219_0001_000001
2013-08-16 20:39:51,188 INFO org.apache.hadoop.yarn.server.resourcemanager.amlauncher.AMLauncher: Setting up container Container: [ContainerId: container_1376685566219_0001_01_000001, NodeId: hadoop-512-3:58863, NodeHttpAddress: hadoop-512-3:8042, Resource: <memory:2048, vCores:1>, Priority: 0, State: NEW, Token: null, Status: container_id {, app_attempt_id {, application_id {, id: 1, cluster_timestamp: 1376685566219, }, attemptId: 1, }, id: 1, }, state: C_NEW, ] for AM appattempt_1376685566219_0001_000001
2013-08-16 20:39:51,189 INFO org.apache.hadoop.yarn.server.resourcemanager.amlauncher.AMLauncher: Command to launch container container_1376685566219_0001_01_000001 : $JAVA_HOME/bin/java -Dlog4j.configuration=container-log4j.properties -Dyarn.app.mapreduce.container.log.dir=<LOG_DIR> -Dyarn.app.mapreduce.container.log.filesize=0 -Dhadoop.root.logger=INFO,CLA  -Xmx1024m org.apache.hadoop.mapreduce.v2.app.MRAppMaster 1><LOG_DIR>/stdout 2><LOG_DIR>/stderr 
2013-08-16 20:39:52,093 INFO org.apache.hadoop.yarn.server.resourcemanager.amlauncher.AMLauncher: Done launching container Container: [ContainerId: container_1376685566219_0001_01_000001, NodeId: hadoop-512-3:58863, NodeHttpAddress: hadoop-512-3:8042, Resource: <memory:2048, vCores:1>, Priority: 0, State: NEW, Token: null, Status: container_id {, app_attempt_id {, application_id {, id: 1, cluster_timestamp: 1376685566219, }, attemptId: 1, }, id: 1, }, state: C_NEW, ] for AM appattempt_1376685566219_0001_000001
2013-08-16 20:39:52,095 INFO org.apache.hadoop.yarn.server.resourcemanager.rmapp.attempt.RMAppAttemptImpl: appattempt_1376685566219_0001_000001 State change from ALLOCATED to LAUNCHED
2013-08-16 20:39:52,134 INFO org.apache.hadoop.yarn.server.resourcemanager.rmcontainer.RMContainerImpl: container_1376685566219_0001_01_000001 Container Transitioned from ACQUIRED to RUNNING
2013-08-16 20:40:01,212 INFO org.apache.hadoop.yarn.server.resourcemanager.ApplicationMasterService: AM registration appattempt_1376685566219_0001_000001
2013-08-16 20:40:01,214 INFO org.apache.hadoop.yarn.server.resourcemanager.RMAuditLogger: USER=ubuntu	IP=192.168.100.10	OPERATION=Register App Master	TARGET=ApplicationMasterService	RESULT=SUCCESS	APPID=application_1376685566219_0001	APPATTEMPTID=appattempt_1376685566219_0001_000001
2013-08-16 20:40:01,220 INFO org.apache.hadoop.yarn.server.resourcemanager.rmapp.attempt.RMAppAttemptImpl: appattempt_1376685566219_0001_000001 State change from LAUNCHED to RUNNING
2013-08-16 20:40:01,220 INFO org.apache.hadoop.yarn.server.resourcemanager.rmapp.RMAppImpl: application_1376685566219_0001 State change from ACCEPTED to RUNNING
2013-08-16 20:40:03,132 INFO org.apache.hadoop.yarn.server.resourcemanager.rmcontainer.RMContainerImpl: container_1376685566219_0001_01_000002 Container Transitioned from NEW to ALLOCATED
2013-08-16 20:40:03,133 INFO org.apache.hadoop.yarn.server.resourcemanager.RMAuditLogger: USER=ubuntu	OPERATION=AM Allocated Container	TARGET=SchedulerApp	RESULT=SUCCESS	APPID=application_1376685566219_0001	CONTAINERID=container_1376685566219_0001_01_000002
2013-08-16 20:40:03,133 INFO org.apache.hadoop.yarn.server.resourcemanager.scheduler.common.fica.FiCaSchedulerNode: Assigned container container_1376685566219_0001_01_000002 of capacity <memory:1024, vCores:1> on host hadoop-512-2:41669, which currently has 1 containers, <memory:1024, vCores:1> used and <memory:7168, vCores:15> available
2013-08-16 20:40:03,135 INFO org.apache.hadoop.yarn.server.resourcemanager.scheduler.capacity.LeafQueue: assignedContainer application=application_1376685566219_0001 container=Container: [ContainerId: container_1376685566219_0001_01_000002, NodeId: hadoop-512-2:41669, NodeHttpAddress: hadoop-512-2:8042, Resource: <memory:1024, vCores:1>, Priority: 20, State: NEW, Token: null, Status: container_id {, app_attempt_id {, application_id {, id: 1, cluster_timestamp: 1376685566219, }, attemptId: 1, }, id: 2, }, state: C_NEW, ] containerId=container_1376685566219_0001_01_000002 queue=default: capacity=1.0, absoluteCapacity=1.0, usedResources=<memory:2048, vCores:1>usedCapacity=0.041666668, absoluteUsedCapacity=0.041666668, numApps=1, numContainers=1 usedCapacity=0.041666668 absoluteUsedCapacity=0.041666668 used=<memory:2048, vCores:1> cluster=<memory:49152, vCores:96>
2013-08-16 20:40:03,135 INFO org.apache.hadoop.yarn.server.resourcemanager.scheduler.capacity.ParentQueue: Re-sorting queues since queue: root.default stats: default: capacity=1.0, absoluteCapacity=1.0, usedResources=<memory:3072, vCores:2>usedCapacity=0.0625, absoluteUsedCapacity=0.0625, numApps=1, numContainers=2
2013-08-16 20:40:03,135 INFO org.apache.hadoop.yarn.server.resourcemanager.scheduler.capacity.ParentQueue: assignedContainer queue=root usedCapacity=0.0625 absoluteUsedCapacity=0.0625 used=<memory:3072, vCores:2> cluster=<memory:49152, vCores:96>
2013-08-16 20:40:03,136 INFO org.apache.hadoop.yarn.server.resourcemanager.rmcontainer.RMContainerImpl: container_1376685566219_0001_01_000003 Container Transitioned from NEW to ALLOCATED
2013-08-16 20:40:03,136 INFO org.apache.hadoop.yarn.server.resourcemanager.RMAuditLogger: USER=ubuntu	OPERATION=AM Allocated Container	TARGET=SchedulerApp	RESULT=SUCCESS	APPID=application_1376685566219_0001	CONTAINERID=container_1376685566219_0001_01_000003
2013-08-16 20:40:03,136 INFO org.apache.hadoop.yarn.server.resourcemanager.scheduler.common.fica.FiCaSchedulerNode: Assigned container container_1376685566219_0001_01_000003 of capacity <memory:1024, vCores:1> on host hadoop-512-7:51513, which currently has 1 containers, <memory:1024, vCores:1> used and <memory:7168, vCores:15> available
2013-08-16 20:40:03,139 INFO org.apache.hadoop.yarn.server.resourcemanager.scheduler.capacity.LeafQueue: assignedContainer application=application_1376685566219_0001 container=Container: [ContainerId: container_1376685566219_0001_01_000003, NodeId: hadoop-512-7:51513, NodeHttpAddress: hadoop-512-7:8042, Resource: <memory:1024, vCores:1>, Priority: 20, State: NEW, Token: null, Status: container_id {, app_attempt_id {, application_id {, id: 1, cluster_timestamp: 1376685566219, }, attemptId: 1, }, id: 3, }, state: C_NEW, ] containerId=container_1376685566219_0001_01_000003 queue=default: capacity=1.0, absoluteCapacity=1.0, usedResources=<memory:3072, vCores:2>usedCapacity=0.0625, absoluteUsedCapacity=0.0625, numApps=1, numContainers=2 usedCapacity=0.0625 absoluteUsedCapacity=0.0625 used=<memory:3072, vCores:2> cluster=<memory:49152, vCores:96>
2013-08-16 20:40:03,139 INFO org.apache.hadoop.yarn.server.resourcemanager.scheduler.capacity.ParentQueue: Re-sorting queues since queue: root.default stats: default: capacity=1.0, absoluteCapacity=1.0, usedResources=<memory:4096, vCores:3>usedCapacity=0.083333336, absoluteUsedCapacity=0.083333336, numApps=1, numContainers=3
2013-08-16 20:40:03,140 INFO org.apache.hadoop.yarn.server.resourcemanager.scheduler.capacity.ParentQueue: assignedContainer queue=root usedCapacity=0.083333336 absoluteUsedCapacity=0.083333336 used=<memory:4096, vCores:3> cluster=<memory:49152, vCores:96>
2013-08-16 20:40:03,294 INFO org.apache.hadoop.yarn.server.resourcemanager.rmcontainer.RMContainerImpl: container_1376685566219_0001_01_000002 Container Transitioned from ALLOCATED to ACQUIRED
2013-08-16 20:40:03,296 INFO org.apache.hadoop.yarn.server.resourcemanager.rmcontainer.RMContainerImpl: container_1376685566219_0001_01_000003 Container Transitioned from ALLOCATED to ACQUIRED
2013-08-16 20:40:04,328 INFO org.apache.hadoop.yarn.server.resourcemanager.scheduler.AppSchedulingInfo: checking for deactivate... 
2013-08-16 20:40:05,169 INFO org.apache.hadoop.yarn.server.resourcemanager.rmcontainer.RMContainerImpl: container_1376685566219_0001_01_000002 Container Transitioned from ACQUIRED to RUNNING
2013-08-16 20:40:05,173 INFO org.apache.hadoop.yarn.server.resourcemanager.rmcontainer.RMContainerImpl: container_1376685566219_0001_01_000003 Container Transitioned from ACQUIRED to RUNNING
2013-08-16 20:41:43,599 INFO org.apache.hadoop.yarn.server.resourcemanager.rmcontainer.RMContainerImpl: container_1376685566219_0001_01_000002 Container Transitioned from RUNNING to COMPLETED
2013-08-16 20:41:43,600 INFO org.apache.hadoop.yarn.server.resourcemanager.scheduler.common.fica.FiCaSchedulerApp: Completed container: container_1376685566219_0001_01_000002 in state: COMPLETED event:FINISHED
2013-08-16 20:41:43,600 INFO org.apache.hadoop.yarn.server.resourcemanager.RMAuditLogger: USER=ubuntu	OPERATION=AM Released Container	TARGET=SchedulerApp	RESULT=SUCCESS	APPID=application_1376685566219_0001	CONTAINERID=container_1376685566219_0001_01_000002
2013-08-16 20:41:43,600 INFO org.apache.hadoop.yarn.server.resourcemanager.scheduler.common.fica.FiCaSchedulerNode: Released container container_1376685566219_0001_01_000002 of capacity <memory:1024, vCores:1> on host hadoop-512-2:41669, which currently has 0 containers, <memory:0, vCores:0> used and <memory:8192, vCores:16> available, release resources=true
2013-08-16 20:41:43,600 INFO org.apache.hadoop.yarn.server.resourcemanager.scheduler.capacity.LeafQueue: default used=<memory:3072, vCores:2> numContainers=2 user=ubuntu user-resources=<memory:3072, vCores:2>
2013-08-16 20:41:43,603 INFO org.apache.hadoop.yarn.server.resourcemanager.scheduler.capacity.LeafQueue: completedContainer container=Container: [ContainerId: container_1376685566219_0001_01_000002, NodeId: hadoop-512-2:41669, NodeHttpAddress: hadoop-512-2:8042, Resource: <memory:1024, vCores:1>, Priority: 20, State: NEW, Token: null, Status: container_id {, app_attempt_id {, application_id {, id: 1, cluster_timestamp: 1376685566219, }, attemptId: 1, }, id: 2, }, state: C_COMPLETE, diagnostics: "Container killed by the ApplicationMaster.\n\n", exit_status: 143, ] resource=<memory:1024, vCores:1> queue=default: capacity=1.0, absoluteCapacity=1.0, usedResources=<memory:3072, vCores:2>usedCapacity=0.0625, absoluteUsedCapacity=0.0625, numApps=1, numContainers=2 usedCapacity=0.0625 absoluteUsedCapacity=0.0625 used=<memory:3072, vCores:2> cluster=<memory:49152, vCores:96>
2013-08-16 20:41:43,603 INFO org.apache.hadoop.yarn.server.resourcemanager.scheduler.capacity.ParentQueue: completedContainer queue=root usedCapacity=0.0625 absoluteUsedCapacity=0.0625 used=<memory:3072, vCores:2> cluster=<memory:49152, vCores:96>
2013-08-16 20:41:43,603 INFO org.apache.hadoop.yarn.server.resourcemanager.scheduler.capacity.CapacityScheduler: Application appattempt_1376685566219_0001_000001 released container container_1376685566219_0001_01_000002 on node: host: hadoop-512-2:41669 #containers=0 available=8192 used=0 with event: FINISHED
2013-08-16 20:41:49,243 INFO org.apache.hadoop.yarn.server.resourcemanager.rmcontainer.RMContainerImpl: container_1376685566219_0001_01_000003 Container Transitioned from RUNNING to COMPLETED
2013-08-16 20:41:49,243 INFO org.apache.hadoop.yarn.server.resourcemanager.scheduler.common.fica.FiCaSchedulerApp: Completed container: container_1376685566219_0001_01_000003 in state: COMPLETED event:FINISHED
2013-08-16 20:41:49,243 INFO org.apache.hadoop.yarn.server.resourcemanager.RMAuditLogger: USER=ubuntu	OPERATION=AM Released Container	TARGET=SchedulerApp	RESULT=SUCCESS	APPID=application_1376685566219_0001	CONTAINERID=container_1376685566219_0001_01_000003
2013-08-16 20:41:49,243 INFO org.apache.hadoop.yarn.server.resourcemanager.scheduler.common.fica.FiCaSchedulerNode: Released container container_1376685566219_0001_01_000003 of capacity <memory:1024, vCores:1> on host hadoop-512-7:51513, which currently has 0 containers, <memory:0, vCores:0> used and <memory:8192, vCores:16> available, release resources=true
2013-08-16 20:41:49,243 INFO org.apache.hadoop.yarn.server.resourcemanager.scheduler.capacity.LeafQueue: default used=<memory:2048, vCores:1> numContainers=1 user=ubuntu user-resources=<memory:2048, vCores:1>
2013-08-16 20:41:49,245 INFO org.apache.hadoop.yarn.server.resourcemanager.scheduler.capacity.LeafQueue: completedContainer container=Container: [ContainerId: container_1376685566219_0001_01_000003, NodeId: hadoop-512-7:51513, NodeHttpAddress: hadoop-512-7:8042, Resource: <memory:1024, vCores:1>, Priority: 20, State: NEW, Token: null, Status: container_id {, app_attempt_id {, application_id {, id: 1, cluster_timestamp: 1376685566219, }, attemptId: 1, }, id: 3, }, state: C_COMPLETE, diagnostics: "Container killed by the ApplicationMaster.\n\n", exit_status: 143, ] resource=<memory:1024, vCores:1> queue=default: capacity=1.0, absoluteCapacity=1.0, usedResources=<memory:2048, vCores:1>usedCapacity=0.041666668, absoluteUsedCapacity=0.041666668, numApps=1, numContainers=1 usedCapacity=0.041666668 absoluteUsedCapacity=0.041666668 used=<memory:2048, vCores:1> cluster=<memory:49152, vCores:96>
2013-08-16 20:41:49,246 INFO org.apache.hadoop.yarn.server.resourcemanager.scheduler.capacity.ParentQueue: completedContainer queue=root usedCapacity=0.041666668 absoluteUsedCapacity=0.041666668 used=<memory:2048, vCores:1> cluster=<memory:49152, vCores:96>
2013-08-16 20:41:49,246 INFO org.apache.hadoop.yarn.server.resourcemanager.scheduler.capacity.CapacityScheduler: Application appattempt_1376685566219_0001_000001 released container container_1376685566219_0001_01_000003 on node: host: hadoop-512-7:51513 #containers=0 available=8192 used=0 with event: FINISHED
2013-08-16 20:41:53,462 INFO org.apache.hadoop.yarn.server.resourcemanager.rmapp.attempt.RMAppAttemptImpl: appattempt_1376685566219_0001_000001 State change from RUNNING to FINISHING
2013-08-16 20:41:53,463 INFO org.apache.hadoop.yarn.server.resourcemanager.rmapp.RMAppImpl: application_1376685566219_0001 State change from RUNNING to FINISHING
2013-08-16 20:41:53,922 INFO org.apache.hadoop.yarn.server.resourcemanager.rmcontainer.RMContainerImpl: container_1376685566219_0001_01_000001 Container Transitioned from RUNNING to COMPLETED
2013-08-16 20:41:53,922 INFO org.apache.hadoop.yarn.server.resourcemanager.scheduler.common.fica.FiCaSchedulerApp: Completed container: container_1376685566219_0001_01_000001 in state: COMPLETED event:FINISHED
2013-08-16 20:41:53,922 INFO org.apache.hadoop.yarn.server.resourcemanager.RMAuditLogger: USER=ubuntu	OPERATION=AM Released Container	TARGET=SchedulerApp	RESULT=SUCCESS	APPID=application_1376685566219_0001	CONTAINERID=container_1376685566219_0001_01_000001
2013-08-16 20:41:53,922 INFO org.apache.hadoop.yarn.server.resourcemanager.scheduler.common.fica.FiCaSchedulerNode: Released container container_1376685566219_0001_01_000001 of capacity <memory:2048, vCores:1> on host hadoop-512-3:58863, which currently has 0 containers, <memory:0, vCores:0> used and <memory:8192, vCores:16> available, release resources=true
2013-08-16 20:41:53,923 INFO org.apache.hadoop.yarn.server.resourcemanager.scheduler.capacity.LeafQueue: default used=<memory:0, vCores:0> numContainers=0 user=ubuntu user-resources=<memory:0, vCores:0>
2013-08-16 20:41:53,924 INFO org.apache.hadoop.yarn.server.resourcemanager.scheduler.capacity.LeafQueue: completedContainer container=Container: [ContainerId: container_1376685566219_0001_01_000001, NodeId: hadoop-512-3:58863, NodeHttpAddress: hadoop-512-3:8042, Resource: <memory:2048, vCores:1>, Priority: 0, State: NEW, Token: null, Status: container_id {, app_attempt_id {, application_id {, id: 1, cluster_timestamp: 1376685566219, }, attemptId: 1, }, id: 1, }, state: C_COMPLETE, diagnostics: "", exit_status: 0, ] resource=<memory:2048, vCores:1> queue=default: capacity=1.0, absoluteCapacity=1.0, usedResources=<memory:0, vCores:0>usedCapacity=0.0, absoluteUsedCapacity=0.0, numApps=1, numContainers=0 usedCapacity=0.0 absoluteUsedCapacity=0.0 used=<memory:0, vCores:0> cluster=<memory:49152, vCores:96>
2013-08-16 20:41:53,925 INFO org.apache.hadoop.yarn.server.resourcemanager.scheduler.capacity.ParentQueue: completedContainer queue=root usedCapacity=0.0 absoluteUsedCapacity=0.0 used=<memory:0, vCores:0> cluster=<memory:49152, vCores:96>
2013-08-16 20:41:53,925 INFO org.apache.hadoop.yarn.server.resourcemanager.scheduler.capacity.CapacityScheduler: Application appattempt_1376685566219_0001_000001 released container container_1376685566219_0001_01_000001 on node: host: hadoop-512-3:58863 #containers=0 available=8192 used=0 with event: FINISHED
2013-08-16 20:41:53,925 INFO org.apache.hadoop.yarn.server.resourcemanager.rmapp.attempt.RMAppAttemptImpl: appattempt_1376685566219_0001_000001 State change from FINISHING to FINISHED
2013-08-16 20:41:53,927 INFO org.apache.hadoop.yarn.server.resourcemanager.rmapp.RMAppImpl: application_1376685566219_0001 State change from FINISHING to FINISHED
2013-08-16 20:41:53,928 INFO org.apache.hadoop.yarn.server.resourcemanager.scheduler.capacity.CapacityScheduler: Application appattempt_1376685566219_0001_000001 is done. finalState=FINISHED
2013-08-16 20:41:53,928 INFO org.apache.hadoop.yarn.server.resourcemanager.RMAuditLogger: USER=ubuntu	OPERATION=Application Finished - Succeeded	TARGET=RMAppManager	RESULT=SUCCESS	APPID=application_1376685566219_0001
2013-08-16 20:41:53,928 INFO org.apache.hadoop.yarn.server.resourcemanager.amlauncher.AMLauncher: Cleaning master appattempt_1376685566219_0001_000001
2013-08-16 20:41:53,940 INFO org.apache.hadoop.yarn.server.resourcemanager.scheduler.AppSchedulingInfo: Application application_1376685566219_0001 requests cleared
2013-08-16 20:41:53,940 INFO org.apache.hadoop.yarn.server.resourcemanager.scheduler.capacity.LeafQueue: Application removed - appId: application_1376685566219_0001 user: ubuntu queue: default #user-pending-applications: 0 #user-active-applications: 0 #queue-pending-applications: 0 #queue-active-applications: 0
2013-08-16 20:41:53,941 INFO org.apache.hadoop.yarn.server.resourcemanager.scheduler.capacity.ParentQueue: Application removed - appId: application_1376685566219_0001 user: ubuntu leaf-queue of parent: root #applications: 0
2013-08-16 20:41:53,944 INFO org.apache.hadoop.yarn.server.resourcemanager.recovery.RMStateStore: Removing info for app: application_1376685566219_0001
2013-08-16 20:41:53,945 INFO org.apache.hadoop.yarn.server.resourcemanager.RMAppManager$ApplicationSummary: appId=application_1376685566219_0001,name=TeraGen,user=ubuntu,queue=default,state=FINISHED,trackingUrl=hadoop-512-1.novalocal:8088/proxy/application_1376685566219_0001/jobhistory/job/job_1376685566219_0001,appMasterHost=hadoop-512-3,startTime=1376685590383,finishTime=1376685713463
2013-08-16 20:41:55,267 INFO org.apache.hadoop.yarn.server.resourcemanager.ClientRMService: Allocated new applicationId: 2
2013-08-16 20:41:57,129 INFO org.apache.hadoop.yarn.server.resourcemanager.ClientRMService: Storing Application with id application_1376685566219_0002
2013-08-16 20:41:57,129 INFO org.apache.hadoop.yarn.server.resourcemanager.recovery.RMStateStore: Storing info for app: application_1376685566219_0002
2013-08-16 20:41:57,129 INFO org.apache.hadoop.yarn.server.resourcemanager.ClientRMService: Application with id 2 submitted by user ubuntu
2013-08-16 20:41:57,130 INFO org.apache.hadoop.yarn.server.resourcemanager.RMAuditLogger: USER=ubuntu	IP=192.168.100.6	OPERATION=Submit Application Request	TARGET=ClientRMService	RESULT=SUCCESS	APPID=application_1376685566219_0002
2013-08-16 20:41:57,132 INFO org.apache.hadoop.yarn.server.resourcemanager.rmapp.RMAppImpl: application_1376685566219_0002 State change from NEW to SUBMITTED
2013-08-16 20:41:57,132 INFO org.apache.hadoop.yarn.server.resourcemanager.ApplicationMasterService: Registering appattempt_1376685566219_0002_000001
2013-08-16 20:41:57,132 INFO org.apache.hadoop.yarn.server.resourcemanager.rmapp.attempt.RMAppAttemptImpl: appattempt_1376685566219_0002_000001 State change from NEW to SUBMITTED
2013-08-16 20:41:57,133 INFO org.apache.hadoop.yarn.server.resourcemanager.scheduler.capacity.LeafQueue: Application application_1376685566219_0002 from user: ubuntu activated in queue: default
2013-08-16 20:41:57,133 INFO org.apache.hadoop.yarn.server.resourcemanager.scheduler.capacity.LeafQueue: Application added - appId: application_1376685566219_0002 user: org.apache.hadoop.yarn.server.resourcemanager.scheduler.capacity.LeafQueue$User@79e35e65, leaf-queue: default #user-pending-applications: 0 #user-active-applications: 1 #queue-pending-applications: 0 #queue-active-applications: 1
2013-08-16 20:41:57,133 INFO org.apache.hadoop.yarn.server.resourcemanager.scheduler.capacity.ParentQueue: Application added - appId: application_1376685566219_0002 user: ubuntu leaf-queue of parent: root #applications: 1
2013-08-16 20:41:57,133 INFO org.apache.hadoop.yarn.server.resourcemanager.scheduler.capacity.CapacityScheduler: Application Submission: appattempt_1376685566219_0002_000001, user: ubuntu queue: default: capacity=1.0, absoluteCapacity=1.0, usedResources=<memory:0, vCores:0>usedCapacity=0.0, absoluteUsedCapacity=0.0, numApps=1, numContainers=0, currently active: 1
2013-08-16 20:41:57,134 INFO org.apache.hadoop.yarn.server.resourcemanager.rmapp.attempt.RMAppAttemptImpl: appattempt_1376685566219_0002_000001 State change from SUBMITTED to SCHEDULED
2013-08-16 20:41:57,134 INFO org.apache.hadoop.yarn.server.resourcemanager.rmapp.RMAppImpl: application_1376685566219_0002 State change from SUBMITTED to ACCEPTED
2013-08-16 20:41:57,279 INFO org.apache.hadoop.yarn.server.resourcemanager.rmcontainer.RMContainerImpl: container_1376685566219_0002_01_000001 Container Transitioned from NEW to ALLOCATED
2013-08-16 20:41:57,279 INFO org.apache.hadoop.yarn.server.resourcemanager.RMAuditLogger: USER=ubuntu	OPERATION=AM Allocated Container	TARGET=SchedulerApp	RESULT=SUCCESS	APPID=application_1376685566219_0002	CONTAINERID=container_1376685566219_0002_01_000001
2013-08-16 20:41:57,279 INFO org.apache.hadoop.yarn.server.resourcemanager.scheduler.common.fica.FiCaSchedulerNode: Assigned container container_1376685566219_0002_01_000001 of capacity <memory:2048, vCores:1> on host hadoop-512-7:51513, which currently has 1 containers, <memory:2048, vCores:1> used and <memory:6144, vCores:15> available
2013-08-16 20:41:57,281 INFO org.apache.hadoop.yarn.server.resourcemanager.scheduler.capacity.LeafQueue: assignedContainer application=application_1376685566219_0002 container=Container: [ContainerId: container_1376685566219_0002_01_000001, NodeId: hadoop-512-7:51513, NodeHttpAddress: hadoop-512-7:8042, Resource: <memory:2048, vCores:1>, Priority: 0, State: NEW, Token: null, Status: container_id {, app_attempt_id {, application_id {, id: 2, cluster_timestamp: 1376685566219, }, attemptId: 1, }, id: 1, }, state: C_NEW, ] containerId=container_1376685566219_0002_01_000001 queue=default: capacity=1.0, absoluteCapacity=1.0, usedResources=<memory:0, vCores:0>usedCapacity=0.0, absoluteUsedCapacity=0.0, numApps=1, numContainers=0 usedCapacity=0.0 absoluteUsedCapacity=0.0 used=<memory:0, vCores:0> cluster=<memory:49152, vCores:96>
2013-08-16 20:41:57,281 INFO org.apache.hadoop.yarn.server.resourcemanager.scheduler.capacity.ParentQueue: Re-sorting queues since queue: root.default stats: default: capacity=1.0, absoluteCapacity=1.0, usedResources=<memory:2048, vCores:1>usedCapacity=0.041666668, absoluteUsedCapacity=0.041666668, numApps=1, numContainers=1
2013-08-16 20:41:57,281 INFO org.apache.hadoop.yarn.server.resourcemanager.scheduler.capacity.ParentQueue: assignedContainer queue=root usedCapacity=0.041666668 absoluteUsedCapacity=0.041666668 used=<memory:2048, vCores:1> cluster=<memory:49152, vCores:96>
2013-08-16 20:41:57,283 INFO org.apache.hadoop.yarn.server.resourcemanager.rmcontainer.RMContainerImpl: container_1376685566219_0002_01_000001 Container Transitioned from ALLOCATED to ACQUIRED
2013-08-16 20:41:57,285 INFO org.apache.hadoop.yarn.server.resourcemanager.rmapp.attempt.RMAppAttemptImpl: Storing attempt: AppId: application_1376685566219_0002 AttemptId: appattempt_1376685566219_0002_000001 MasterContainer: Container: [ContainerId: container_1376685566219_0002_01_000001, NodeId: hadoop-512-7:51513, NodeHttpAddress: hadoop-512-7:8042, Resource: <memory:2048, vCores:1>, Priority: 0, State: NEW, Token: null, Status: container_id {, app_attempt_id {, application_id {, id: 2, cluster_timestamp: 1376685566219, }, attemptId: 1, }, id: 1, }, state: C_NEW, ]
2013-08-16 20:41:57,285 INFO org.apache.hadoop.yarn.server.resourcemanager.rmapp.attempt.RMAppAttemptImpl: appattempt_1376685566219_0002_000001 State change from SCHEDULED to ALLOCATED_SAVING
2013-08-16 20:41:57,286 INFO org.apache.hadoop.yarn.server.resourcemanager.recovery.RMStateStore: Storing info for attempt: appattempt_1376685566219_0002_000001
2013-08-16 20:41:57,287 INFO org.apache.hadoop.yarn.server.resourcemanager.rmapp.attempt.RMAppAttemptImpl: appattempt_1376685566219_0002_000001 State change from ALLOCATED_SAVING to ALLOCATED
2013-08-16 20:41:57,289 INFO org.apache.hadoop.yarn.server.resourcemanager.amlauncher.AMLauncher: Launching masterappattempt_1376685566219_0002_000001
2013-08-16 20:41:57,292 INFO org.apache.hadoop.yarn.server.resourcemanager.amlauncher.AMLauncher: Setting up container Container: [ContainerId: container_1376685566219_0002_01_000001, NodeId: hadoop-512-7:51513, NodeHttpAddress: hadoop-512-7:8042, Resource: <memory:2048, vCores:1>, Priority: 0, State: NEW, Token: null, Status: container_id {, app_attempt_id {, application_id {, id: 2, cluster_timestamp: 1376685566219, }, attemptId: 1, }, id: 1, }, state: C_NEW, ] for AM appattempt_1376685566219_0002_000001
2013-08-16 20:41:57,292 INFO org.apache.hadoop.yarn.server.resourcemanager.amlauncher.AMLauncher: Command to launch container container_1376685566219_0002_01_000001 : $JAVA_HOME/bin/java -Dlog4j.configuration=container-log4j.properties -Dyarn.app.mapreduce.container.log.dir=<LOG_DIR> -Dyarn.app.mapreduce.container.log.filesize=0 -Dhadoop.root.logger=INFO,CLA  -Xmx1024m org.apache.hadoop.mapreduce.v2.app.MRAppMaster 1><LOG_DIR>/stdout 2><LOG_DIR>/stderr 
2013-08-16 20:41:57,310 INFO org.apache.hadoop.yarn.server.resourcemanager.amlauncher.AMLauncher: Done launching container Container: [ContainerId: container_1376685566219_0002_01_000001, NodeId: hadoop-512-7:51513, NodeHttpAddress: hadoop-512-7:8042, Resource: <memory:2048, vCores:1>, Priority: 0, State: NEW, Token: null, Status: container_id {, app_attempt_id {, application_id {, id: 2, cluster_timestamp: 1376685566219, }, attemptId: 1, }, id: 1, }, state: C_NEW, ] for AM appattempt_1376685566219_0002_000001
2013-08-16 20:41:57,311 INFO org.apache.hadoop.yarn.server.resourcemanager.rmapp.attempt.RMAppAttemptImpl: appattempt_1376685566219_0002_000001 State change from ALLOCATED to LAUNCHED
2013-08-16 20:41:58,289 INFO org.apache.hadoop.yarn.server.resourcemanager.rmcontainer.RMContainerImpl: container_1376685566219_0002_01_000001 Container Transitioned from ACQUIRED to RUNNING
2013-08-16 20:42:04,134 INFO org.apache.hadoop.yarn.server.resourcemanager.ApplicationMasterService: AM registration appattempt_1376685566219_0002_000001
2013-08-16 20:42:04,135 INFO org.apache.hadoop.yarn.server.resourcemanager.RMAuditLogger: USER=ubuntu	IP=192.168.100.33	OPERATION=Register App Master	TARGET=ApplicationMasterService	RESULT=SUCCESS	APPID=application_1376685566219_0002	APPATTEMPTID=appattempt_1376685566219_0002_000001
2013-08-16 20:42:04,137 INFO org.apache.hadoop.yarn.server.resourcemanager.rmapp.attempt.RMAppAttemptImpl: appattempt_1376685566219_0002_000001 State change from LAUNCHED to RUNNING
2013-08-16 20:42:04,137 INFO org.apache.hadoop.yarn.server.resourcemanager.rmapp.RMAppImpl: application_1376685566219_0002 State change from ACCEPTED to RUNNING
2013-08-16 20:42:05,323 INFO org.apache.hadoop.yarn.server.resourcemanager.rmcontainer.RMContainerImpl: container_1376685566219_0002_01_000002 Container Transitioned from NEW to ALLOCATED
2013-08-16 20:42:05,323 INFO org.apache.hadoop.yarn.server.resourcemanager.RMAuditLogger: USER=ubuntu	OPERATION=AM Allocated Container	TARGET=SchedulerApp	RESULT=SUCCESS	APPID=application_1376685566219_0002	CONTAINERID=container_1376685566219_0002_01_000002
2013-08-16 20:42:05,324 INFO org.apache.hadoop.yarn.server.resourcemanager.scheduler.common.fica.FiCaSchedulerNode: Assigned container container_1376685566219_0002_01_000002 of capacity <memory:1024, vCores:1> on host hadoop-512-7:51513, which currently has 2 containers, <memory:3072, vCores:2> used and <memory:5120, vCores:14> available
2013-08-16 20:42:05,325 INFO org.apache.hadoop.yarn.server.resourcemanager.scheduler.capacity.LeafQueue: assignedContainer application=application_1376685566219_0002 container=Container: [ContainerId: container_1376685566219_0002_01_000002, NodeId: hadoop-512-7:51513, NodeHttpAddress: hadoop-512-7:8042, Resource: <memory:1024, vCores:1>, Priority: 20, State: NEW, Token: null, Status: container_id {, app_attempt_id {, application_id {, id: 2, cluster_timestamp: 1376685566219, }, attemptId: 1, }, id: 2, }, state: C_NEW, ] containerId=container_1376685566219_0002_01_000002 queue=default: capacity=1.0, absoluteCapacity=1.0, usedResources=<memory:2048, vCores:1>usedCapacity=0.041666668, absoluteUsedCapacity=0.041666668, numApps=1, numContainers=1 usedCapacity=0.041666668 absoluteUsedCapacity=0.041666668 used=<memory:2048, vCores:1> cluster=<memory:49152, vCores:96>
2013-08-16 20:42:05,325 INFO org.apache.hadoop.yarn.server.resourcemanager.scheduler.capacity.ParentQueue: Re-sorting queues since queue: root.default stats: default: capacity=1.0, absoluteCapacity=1.0, usedResources=<memory:3072, vCores:2>usedCapacity=0.0625, absoluteUsedCapacity=0.0625, numApps=1, numContainers=2
2013-08-16 20:42:05,326 INFO org.apache.hadoop.yarn.server.resourcemanager.scheduler.capacity.ParentQueue: assignedContainer queue=root usedCapacity=0.0625 absoluteUsedCapacity=0.0625 used=<memory:3072, vCores:2> cluster=<memory:49152, vCores:96>
2013-08-16 20:42:05,644 INFO org.apache.hadoop.yarn.server.resourcemanager.rmcontainer.RMContainerImpl: container_1376685566219_0002_01_000003 Container Transitioned from NEW to ALLOCATED
2013-08-16 20:42:05,644 INFO org.apache.hadoop.yarn.server.resourcemanager.RMAuditLogger: USER=ubuntu	OPERATION=AM Allocated Container	TARGET=SchedulerApp	RESULT=SUCCESS	APPID=application_1376685566219_0002	CONTAINERID=container_1376685566219_0002_01_000003
2013-08-16 20:42:05,644 INFO org.apache.hadoop.yarn.server.resourcemanager.scheduler.common.fica.FiCaSchedulerNode: Assigned container container_1376685566219_0002_01_000003 of capacity <memory:1024, vCores:1> on host hadoop-512-4:51823, which currently has 1 containers, <memory:1024, vCores:1> used and <memory:7168, vCores:15> available
2013-08-16 20:42:05,646 INFO org.apache.hadoop.yarn.server.resourcemanager.scheduler.capacity.LeafQueue: assignedContainer application=application_1376685566219_0002 container=Container: [ContainerId: container_1376685566219_0002_01_000003, NodeId: hadoop-512-4:51823, NodeHttpAddress: hadoop-512-4:8042, Resource: <memory:1024, vCores:1>, Priority: 20, State: NEW, Token: null, Status: container_id {, app_attempt_id {, application_id {, id: 2, cluster_timestamp: 1376685566219, }, attemptId: 1, }, id: 3, }, state: C_NEW, ] containerId=container_1376685566219_0002_01_000003 queue=default: capacity=1.0, absoluteCapacity=1.0, usedResources=<memory:3072, vCores:2>usedCapacity=0.0625, absoluteUsedCapacity=0.0625, numApps=1, numContainers=2 usedCapacity=0.0625 absoluteUsedCapacity=0.0625 used=<memory:3072, vCores:2> cluster=<memory:49152, vCores:96>
2013-08-16 20:42:05,646 INFO org.apache.hadoop.yarn.server.resourcemanager.scheduler.capacity.ParentQueue: Re-sorting queues since queue: root.default stats: default: capacity=1.0, absoluteCapacity=1.0, usedResources=<memory:4096, vCores:3>usedCapacity=0.083333336, absoluteUsedCapacity=0.083333336, numApps=1, numContainers=3
2013-08-16 20:42:05,646 INFO org.apache.hadoop.yarn.server.resourcemanager.scheduler.capacity.ParentQueue: assignedContainer queue=root usedCapacity=0.083333336 absoluteUsedCapacity=0.083333336 used=<memory:4096, vCores:3> cluster=<memory:49152, vCores:96>
2013-08-16 20:42:06,189 INFO org.apache.hadoop.yarn.server.resourcemanager.rmcontainer.RMContainerImpl: container_1376685566219_0002_01_000002 Container Transitioned from ALLOCATED to ACQUIRED
2013-08-16 20:42:06,191 INFO org.apache.hadoop.yarn.server.resourcemanager.rmcontainer.RMContainerImpl: container_1376685566219_0002_01_000003 Container Transitioned from ALLOCATED to ACQUIRED
2013-08-16 20:42:07,219 INFO org.apache.hadoop.yarn.server.resourcemanager.scheduler.AppSchedulingInfo: checking for deactivate... 
2013-08-16 20:42:07,337 INFO org.apache.hadoop.yarn.server.resourcemanager.rmcontainer.RMContainerImpl: container_1376685566219_0002_01_000002 Container Transitioned from ACQUIRED to RUNNING
2013-08-16 20:42:07,747 INFO org.apache.hadoop.yarn.server.resourcemanager.rmcontainer.RMContainerImpl: container_1376685566219_0002_01_000003 Container Transitioned from ACQUIRED to RUNNING
2013-08-16 20:43:46,501 INFO org.apache.hadoop.yarn.server.resourcemanager.rmcontainer.RMContainerImpl: container_1376685566219_0002_01_000002 Container Transitioned from RUNNING to COMPLETED
2013-08-16 20:43:46,501 INFO org.apache.hadoop.yarn.server.resourcemanager.scheduler.common.fica.FiCaSchedulerApp: Completed container: container_1376685566219_0002_01_000002 in state: COMPLETED event:FINISHED
2013-08-16 20:43:46,501 INFO org.apache.hadoop.yarn.server.resourcemanager.RMAuditLogger: USER=ubuntu	OPERATION=AM Released Container	TARGET=SchedulerApp	RESULT=SUCCESS	APPID=application_1376685566219_0002	CONTAINERID=container_1376685566219_0002_01_000002
2013-08-16 20:43:46,501 INFO org.apache.hadoop.yarn.server.resourcemanager.scheduler.common.fica.FiCaSchedulerNode: Released container container_1376685566219_0002_01_000002 of capacity <memory:1024, vCores:1> on host hadoop-512-7:51513, which currently has 1 containers, <memory:2048, vCores:1> used and <memory:6144, vCores:15> available, release resources=true
2013-08-16 20:43:46,501 INFO org.apache.hadoop.yarn.server.resourcemanager.scheduler.capacity.LeafQueue: default used=<memory:3072, vCores:2> numContainers=2 user=ubuntu user-resources=<memory:3072, vCores:2>
2013-08-16 20:43:46,515 INFO org.apache.hadoop.yarn.server.resourcemanager.scheduler.capacity.LeafQueue: completedContainer container=Container: [ContainerId: container_1376685566219_0002_01_000002, NodeId: hadoop-512-7:51513, NodeHttpAddress: hadoop-512-7:8042, Resource: <memory:1024, vCores:1>, Priority: 20, State: NEW, Token: null, Status: container_id {, app_attempt_id {, application_id {, id: 2, cluster_timestamp: 1376685566219, }, attemptId: 1, }, id: 2, }, state: C_COMPLETE, diagnostics: "Container killed by the ApplicationMaster.\n\n", exit_status: 143, ] resource=<memory:1024, vCores:1> queue=default: capacity=1.0, absoluteCapacity=1.0, usedResources=<memory:3072, vCores:2>usedCapacity=0.0625, absoluteUsedCapacity=0.0625, numApps=1, numContainers=2 usedCapacity=0.0625 absoluteUsedCapacity=0.0625 used=<memory:3072, vCores:2> cluster=<memory:49152, vCores:96>
2013-08-16 20:43:46,515 INFO org.apache.hadoop.yarn.server.resourcemanager.scheduler.capacity.ParentQueue: completedContainer queue=root usedCapacity=0.0625 absoluteUsedCapacity=0.0625 used=<memory:3072, vCores:2> cluster=<memory:49152, vCores:96>
2013-08-16 20:43:46,516 INFO org.apache.hadoop.yarn.server.resourcemanager.scheduler.capacity.CapacityScheduler: Application appattempt_1376685566219_0002_000001 released container container_1376685566219_0002_01_000002 on node: host: hadoop-512-7:51513 #containers=1 available=6144 used=2048 with event: FINISHED
2013-08-16 20:43:58,041 INFO org.apache.hadoop.yarn.server.resourcemanager.rmcontainer.RMContainerImpl: container_1376685566219_0002_01_000003 Container Transitioned from RUNNING to COMPLETED
2013-08-16 20:43:58,041 INFO org.apache.hadoop.yarn.server.resourcemanager.scheduler.common.fica.FiCaSchedulerApp: Completed container: container_1376685566219_0002_01_000003 in state: COMPLETED event:FINISHED
2013-08-16 20:43:58,042 INFO org.apache.hadoop.yarn.server.resourcemanager.RMAuditLogger: USER=ubuntu	OPERATION=AM Released Container	TARGET=SchedulerApp	RESULT=SUCCESS	APPID=application_1376685566219_0002	CONTAINERID=container_1376685566219_0002_01_000003
2013-08-16 20:43:58,042 INFO org.apache.hadoop.yarn.server.resourcemanager.scheduler.common.fica.FiCaSchedulerNode: Released container container_1376685566219_0002_01_000003 of capacity <memory:1024, vCores:1> on host hadoop-512-4:51823, which currently has 0 containers, <memory:0, vCores:0> used and <memory:8192, vCores:16> available, release resources=true
2013-08-16 20:43:58,042 INFO org.apache.hadoop.yarn.server.resourcemanager.scheduler.capacity.LeafQueue: default used=<memory:2048, vCores:1> numContainers=1 user=ubuntu user-resources=<memory:2048, vCores:1>
2013-08-16 20:43:58,044 INFO org.apache.hadoop.yarn.server.resourcemanager.scheduler.capacity.LeafQueue: completedContainer container=Container: [ContainerId: container_1376685566219_0002_01_000003, NodeId: hadoop-512-4:51823, NodeHttpAddress: hadoop-512-4:8042, Resource: <memory:1024, vCores:1>, Priority: 20, State: NEW, Token: null, Status: container_id {, app_attempt_id {, application_id {, id: 2, cluster_timestamp: 1376685566219, }, attemptId: 1, }, id: 3, }, state: C_COMPLETE, diagnostics: "Container killed by the ApplicationMaster.\n\n", exit_status: 143, ] resource=<memory:1024, vCores:1> queue=default: capacity=1.0, absoluteCapacity=1.0, usedResources=<memory:2048, vCores:1>usedCapacity=0.041666668, absoluteUsedCapacity=0.041666668, numApps=1, numContainers=1 usedCapacity=0.041666668 absoluteUsedCapacity=0.041666668 used=<memory:2048, vCores:1> cluster=<memory:49152, vCores:96>
2013-08-16 20:43:58,045 INFO org.apache.hadoop.yarn.server.resourcemanager.scheduler.capacity.ParentQueue: completedContainer queue=root usedCapacity=0.041666668 absoluteUsedCapacity=0.041666668 used=<memory:2048, vCores:1> cluster=<memory:49152, vCores:96>
2013-08-16 20:43:58,045 INFO org.apache.hadoop.yarn.server.resourcemanager.scheduler.capacity.CapacityScheduler: Application appattempt_1376685566219_0002_000001 released container container_1376685566219_0002_01_000003 on node: host: hadoop-512-4:51823 #containers=0 available=8192 used=0 with event: FINISHED
2013-08-16 20:44:02,219 INFO org.apache.hadoop.yarn.server.resourcemanager.rmapp.attempt.RMAppAttemptImpl: appattempt_1376685566219_0002_000001 State change from RUNNING to FINISHING
2013-08-16 20:44:02,220 INFO org.apache.hadoop.yarn.server.resourcemanager.rmapp.RMAppImpl: application_1376685566219_0002 State change from RUNNING to FINISHING
2013-08-16 20:44:02,577 INFO org.apache.hadoop.yarn.server.resourcemanager.rmcontainer.RMContainerImpl: container_1376685566219_0002_01_000001 Container Transitioned from RUNNING to COMPLETED
2013-08-16 20:44:02,577 INFO org.apache.hadoop.yarn.server.resourcemanager.scheduler.common.fica.FiCaSchedulerApp: Completed container: container_1376685566219_0002_01_000001 in state: COMPLETED event:FINISHED
2013-08-16 20:44:02,577 INFO org.apache.hadoop.yarn.server.resourcemanager.RMAuditLogger: USER=ubuntu	OPERATION=AM Released Container	TARGET=SchedulerApp	RESULT=SUCCESS	APPID=application_1376685566219_0002	CONTAINERID=container_1376685566219_0002_01_000001
2013-08-16 20:44:02,578 INFO org.apache.hadoop.yarn.server.resourcemanager.scheduler.common.fica.FiCaSchedulerNode: Released container container_1376685566219_0002_01_000001 of capacity <memory:2048, vCores:1> on host hadoop-512-7:51513, which currently has 0 containers, <memory:0, vCores:0> used and <memory:8192, vCores:16> available, release resources=true
2013-08-16 20:44:02,578 INFO org.apache.hadoop.yarn.server.resourcemanager.rmapp.attempt.RMAppAttemptImpl: appattempt_1376685566219_0002_000001 State change from FINISHING to FINISHED
2013-08-16 20:44:02,578 INFO org.apache.hadoop.yarn.server.resourcemanager.scheduler.capacity.LeafQueue: default used=<memory:0, vCores:0> numContainers=0 user=ubuntu user-resources=<memory:0, vCores:0>
2013-08-16 20:44:02,578 INFO org.apache.hadoop.yarn.server.resourcemanager.rmapp.RMAppImpl: application_1376685566219_0002 State change from FINISHING to FINISHED
2013-08-16 20:44:02,579 INFO org.apache.hadoop.yarn.server.resourcemanager.RMAuditLogger: USER=ubuntu	OPERATION=Application Finished - Succeeded	TARGET=RMAppManager	RESULT=SUCCESS	APPID=application_1376685566219_0002
2013-08-16 20:44:02,579 INFO org.apache.hadoop.yarn.server.resourcemanager.scheduler.capacity.LeafQueue: completedContainer container=Container: [ContainerId: container_1376685566219_0002_01_000001, NodeId: hadoop-512-7:51513, NodeHttpAddress: hadoop-512-7:8042, Resource: <memory:2048, vCores:1>, Priority: 0, State: NEW, Token: null, Status: container_id {, app_attempt_id {, application_id {, id: 2, cluster_timestamp: 1376685566219, }, attemptId: 1, }, id: 1, }, state: C_COMPLETE, diagnostics: "", exit_status: 0, ] resource=<memory:2048, vCores:1> queue=default: capacity=1.0, absoluteCapacity=1.0, usedResources=<memory:0, vCores:0>usedCapacity=0.0, absoluteUsedCapacity=0.0, numApps=1, numContainers=0 usedCapacity=0.0 absoluteUsedCapacity=0.0 used=<memory:0, vCores:0> cluster=<memory:49152, vCores:96>
2013-08-16 20:44:02,579 INFO org.apache.hadoop.yarn.server.resourcemanager.scheduler.capacity.ParentQueue: completedContainer queue=root usedCapacity=0.0 absoluteUsedCapacity=0.0 used=<memory:0, vCores:0> cluster=<memory:49152, vCores:96>
2013-08-16 20:44:02,579 INFO org.apache.hadoop.yarn.server.resourcemanager.recovery.RMStateStore: Removing info for app: application_1376685566219_0002
2013-08-16 20:44:02,588 INFO org.apache.hadoop.yarn.server.resourcemanager.scheduler.capacity.CapacityScheduler: Application appattempt_1376685566219_0002_000001 released container container_1376685566219_0002_01_000001 on node: host: hadoop-512-7:51513 #containers=0 available=8192 used=0 with event: FINISHED
2013-08-16 20:44:02,579 INFO org.apache.hadoop.yarn.server.resourcemanager.amlauncher.AMLauncher: Cleaning master appattempt_1376685566219_0002_000001
2013-08-16 20:44:02,589 INFO org.apache.hadoop.yarn.server.resourcemanager.RMAppManager$ApplicationSummary: appId=application_1376685566219_0002,name=TeraGen,user=ubuntu,queue=default,state=FINISHED,trackingUrl=hadoop-512-1.novalocal:8088/proxy/application_1376685566219_0002/jobhistory/job/job_1376685566219_0002,appMasterHost=hadoop-512-7,startTime=1376685717128,finishTime=1376685842220
2013-08-16 20:44:02,589 INFO org.apache.hadoop.yarn.server.resourcemanager.scheduler.capacity.CapacityScheduler: Application appattempt_1376685566219_0002_000001 is done. finalState=FINISHED
2013-08-16 20:44:02,589 INFO org.apache.hadoop.yarn.server.resourcemanager.scheduler.AppSchedulingInfo: Application application_1376685566219_0002 requests cleared
2013-08-16 20:44:02,589 INFO org.apache.hadoop.yarn.server.resourcemanager.scheduler.capacity.LeafQueue: Application removed - appId: application_1376685566219_0002 user: ubuntu queue: default #user-pending-applications: 0 #user-active-applications: 0 #queue-pending-applications: 0 #queue-active-applications: 0
2013-08-16 20:44:02,589 INFO org.apache.hadoop.yarn.server.resourcemanager.scheduler.capacity.ParentQueue: Application removed - appId: application_1376685566219_0002 user: ubuntu leaf-queue of parent: root #applications: 0
2013-08-16 20:44:03,216 INFO org.apache.hadoop.yarn.server.resourcemanager.ClientRMService: Allocated new applicationId: 3
2013-08-16 20:44:05,176 INFO org.apache.hadoop.yarn.server.resourcemanager.ClientRMService: Storing Application with id application_1376685566219_0003
2013-08-16 20:44:05,177 INFO org.apache.hadoop.yarn.server.resourcemanager.recovery.RMStateStore: Storing info for app: application_1376685566219_0003
2013-08-16 20:44:05,177 INFO org.apache.hadoop.yarn.server.resourcemanager.ClientRMService: Application with id 3 submitted by user ubuntu
2013-08-16 20:44:05,177 INFO org.apache.hadoop.yarn.server.resourcemanager.RMAuditLogger: USER=ubuntu	IP=192.168.100.6	OPERATION=Submit Application Request	TARGET=ClientRMService	RESULT=SUCCESS	APPID=application_1376685566219_0003
2013-08-16 20:44:05,179 INFO org.apache.hadoop.yarn.server.resourcemanager.rmapp.RMAppImpl: application_1376685566219_0003 State change from NEW to SUBMITTED
2013-08-16 20:44:05,179 INFO org.apache.hadoop.yarn.server.resourcemanager.ApplicationMasterService: Registering appattempt_1376685566219_0003_000001
2013-08-16 20:44:05,179 INFO org.apache.hadoop.yarn.server.resourcemanager.rmapp.attempt.RMAppAttemptImpl: appattempt_1376685566219_0003_000001 State change from NEW to SUBMITTED
2013-08-16 20:44:05,180 INFO org.apache.hadoop.yarn.server.resourcemanager.scheduler.capacity.LeafQueue: Application application_1376685566219_0003 from user: ubuntu activated in queue: default
2013-08-16 20:44:05,180 INFO org.apache.hadoop.yarn.server.resourcemanager.scheduler.capacity.LeafQueue: Application added - appId: application_1376685566219_0003 user: org.apache.hadoop.yarn.server.resourcemanager.scheduler.capacity.LeafQueue$User@740b918, leaf-queue: default #user-pending-applications: 0 #user-active-applications: 1 #queue-pending-applications: 0 #queue-active-applications: 1
2013-08-16 20:44:05,180 INFO org.apache.hadoop.yarn.server.resourcemanager.scheduler.capacity.ParentQueue: Application added - appId: application_1376685566219_0003 user: ubuntu leaf-queue of parent: root #applications: 1
2013-08-16 20:44:05,181 INFO org.apache.hadoop.yarn.server.resourcemanager.scheduler.capacity.CapacityScheduler: Application Submission: appattempt_1376685566219_0003_000001, user: ubuntu queue: default: capacity=1.0, absoluteCapacity=1.0, usedResources=<memory:0, vCores:0>usedCapacity=0.0, absoluteUsedCapacity=0.0, numApps=1, numContainers=0, currently active: 1
2013-08-16 20:44:05,181 INFO org.apache.hadoop.yarn.server.resourcemanager.rmapp.attempt.RMAppAttemptImpl: appattempt_1376685566219_0003_000001 State change from SUBMITTED to SCHEDULED
2013-08-16 20:44:05,181 INFO org.apache.hadoop.yarn.server.resourcemanager.rmapp.RMAppImpl: application_1376685566219_0003 State change from SUBMITTED to ACCEPTED
2013-08-16 20:44:05,436 INFO org.apache.hadoop.yarn.server.resourcemanager.rmcontainer.RMContainerImpl: container_1376685566219_0003_01_000001 Container Transitioned from NEW to ALLOCATED
2013-08-16 20:44:05,436 INFO org.apache.hadoop.yarn.server.resourcemanager.RMAuditLogger: USER=ubuntu	OPERATION=AM Allocated Container	TARGET=SchedulerApp	RESULT=SUCCESS	APPID=application_1376685566219_0003	CONTAINERID=container_1376685566219_0003_01_000001
2013-08-16 20:44:05,436 INFO org.apache.hadoop.yarn.server.resourcemanager.scheduler.common.fica.FiCaSchedulerNode: Assigned container container_1376685566219_0003_01_000001 of capacity <memory:2048, vCores:1> on host hadoop-512-3:58863, which currently has 1 containers, <memory:2048, vCores:1> used and <memory:6144, vCores:15> available
2013-08-16 20:44:05,438 INFO org.apache.hadoop.yarn.server.resourcemanager.scheduler.capacity.LeafQueue: assignedContainer application=application_1376685566219_0003 container=Container: [ContainerId: container_1376685566219_0003_01_000001, NodeId: hadoop-512-3:58863, NodeHttpAddress: hadoop-512-3:8042, Resource: <memory:2048, vCores:1>, Priority: 0, State: NEW, Token: null, Status: container_id {, app_attempt_id {, application_id {, id: 3, cluster_timestamp: 1376685566219, }, attemptId: 1, }, id: 1, }, state: C_NEW, ] containerId=container_1376685566219_0003_01_000001 queue=default: capacity=1.0, absoluteCapacity=1.0, usedResources=<memory:0, vCores:0>usedCapacity=0.0, absoluteUsedCapacity=0.0, numApps=1, numContainers=0 usedCapacity=0.0 absoluteUsedCapacity=0.0 used=<memory:0, vCores:0> cluster=<memory:49152, vCores:96>
2013-08-16 20:44:05,438 INFO org.apache.hadoop.yarn.server.resourcemanager.scheduler.capacity.ParentQueue: Re-sorting queues since queue: root.default stats: default: capacity=1.0, absoluteCapacity=1.0, usedResources=<memory:2048, vCores:1>usedCapacity=0.041666668, absoluteUsedCapacity=0.041666668, numApps=1, numContainers=1
2013-08-16 20:44:05,438 INFO org.apache.hadoop.yarn.server.resourcemanager.scheduler.capacity.ParentQueue: assignedContainer queue=root usedCapacity=0.041666668 absoluteUsedCapacity=0.041666668 used=<memory:2048, vCores:1> cluster=<memory:49152, vCores:96>
2013-08-16 20:44:05,440 INFO org.apache.hadoop.yarn.server.resourcemanager.rmcontainer.RMContainerImpl: container_1376685566219_0003_01_000001 Container Transitioned from ALLOCATED to ACQUIRED
2013-08-16 20:44:05,442 INFO org.apache.hadoop.yarn.server.resourcemanager.rmapp.attempt.RMAppAttemptImpl: Storing attempt: AppId: application_1376685566219_0003 AttemptId: appattempt_1376685566219_0003_000001 MasterContainer: Container: [ContainerId: container_1376685566219_0003_01_000001, NodeId: hadoop-512-3:58863, NodeHttpAddress: hadoop-512-3:8042, Resource: <memory:2048, vCores:1>, Priority: 0, State: NEW, Token: null, Status: container_id {, app_attempt_id {, application_id {, id: 3, cluster_timestamp: 1376685566219, }, attemptId: 1, }, id: 1, }, state: C_NEW, ]
2013-08-16 20:44:05,442 INFO org.apache.hadoop.yarn.server.resourcemanager.rmapp.attempt.RMAppAttemptImpl: appattempt_1376685566219_0003_000001 State change from SCHEDULED to ALLOCATED_SAVING
2013-08-16 20:44:05,443 INFO org.apache.hadoop.yarn.server.resourcemanager.recovery.RMStateStore: Storing info for attempt: appattempt_1376685566219_0003_000001
2013-08-16 20:44:05,444 INFO org.apache.hadoop.yarn.server.resourcemanager.rmapp.attempt.RMAppAttemptImpl: appattempt_1376685566219_0003_000001 State change from ALLOCATED_SAVING to ALLOCATED
2013-08-16 20:44:05,446 INFO org.apache.hadoop.yarn.server.resourcemanager.amlauncher.AMLauncher: Launching masterappattempt_1376685566219_0003_000001
2013-08-16 20:44:05,449 INFO org.apache.hadoop.yarn.server.resourcemanager.amlauncher.AMLauncher: Setting up container Container: [ContainerId: container_1376685566219_0003_01_000001, NodeId: hadoop-512-3:58863, NodeHttpAddress: hadoop-512-3:8042, Resource: <memory:2048, vCores:1>, Priority: 0, State: NEW, Token: null, Status: container_id {, app_attempt_id {, application_id {, id: 3, cluster_timestamp: 1376685566219, }, attemptId: 1, }, id: 1, }, state: C_NEW, ] for AM appattempt_1376685566219_0003_000001
2013-08-16 20:44:05,449 INFO org.apache.hadoop.yarn.server.resourcemanager.amlauncher.AMLauncher: Command to launch container container_1376685566219_0003_01_000001 : $JAVA_HOME/bin/java -Dlog4j.configuration=container-log4j.properties -Dyarn.app.mapreduce.container.log.dir=<LOG_DIR> -Dyarn.app.mapreduce.container.log.filesize=0 -Dhadoop.root.logger=INFO,CLA  -Xmx1024m org.apache.hadoop.mapreduce.v2.app.MRAppMaster 1><LOG_DIR>/stdout 2><LOG_DIR>/stderr 
2013-08-16 20:44:05,478 INFO org.apache.hadoop.yarn.server.resourcemanager.amlauncher.AMLauncher: Done launching container Container: [ContainerId: container_1376685566219_0003_01_000001, NodeId: hadoop-512-3:58863, NodeHttpAddress: hadoop-512-3:8042, Resource: <memory:2048, vCores:1>, Priority: 0, State: NEW, Token: null, Status: container_id {, app_attempt_id {, application_id {, id: 3, cluster_timestamp: 1376685566219, }, attemptId: 1, }, id: 1, }, state: C_NEW, ] for AM appattempt_1376685566219_0003_000001
2013-08-16 20:44:05,478 INFO org.apache.hadoop.yarn.server.resourcemanager.rmapp.attempt.RMAppAttemptImpl: appattempt_1376685566219_0003_000001 State change from ALLOCATED to LAUNCHED
2013-08-16 20:44:06,442 INFO org.apache.hadoop.yarn.server.resourcemanager.rmcontainer.RMContainerImpl: container_1376685566219_0003_01_000001 Container Transitioned from ACQUIRED to RUNNING
2013-08-16 20:44:11,903 INFO org.apache.hadoop.yarn.server.resourcemanager.ApplicationMasterService: AM registration appattempt_1376685566219_0003_000001
2013-08-16 20:44:11,903 INFO org.apache.hadoop.yarn.server.resourcemanager.RMAuditLogger: USER=ubuntu	IP=192.168.100.10	OPERATION=Register App Master	TARGET=ApplicationMasterService	RESULT=SUCCESS	APPID=application_1376685566219_0003	APPATTEMPTID=appattempt_1376685566219_0003_000001
2013-08-16 20:44:11,904 INFO org.apache.hadoop.yarn.server.resourcemanager.rmapp.attempt.RMAppAttemptImpl: appattempt_1376685566219_0003_000001 State change from LAUNCHED to RUNNING
2013-08-16 20:44:11,904 INFO org.apache.hadoop.yarn.server.resourcemanager.rmapp.RMAppImpl: application_1376685566219_0003 State change from ACCEPTED to RUNNING
2013-08-16 20:44:13,097 INFO org.apache.hadoop.yarn.server.resourcemanager.rmcontainer.RMContainerImpl: container_1376685566219_0003_01_000002 Container Transitioned from NEW to ALLOCATED
2013-08-16 20:44:13,098 INFO org.apache.hadoop.yarn.server.resourcemanager.RMAuditLogger: USER=ubuntu	OPERATION=AM Allocated Container	TARGET=SchedulerApp	RESULT=SUCCESS	APPID=application_1376685566219_0003	CONTAINERID=container_1376685566219_0003_01_000002
2013-08-16 20:44:13,098 INFO org.apache.hadoop.yarn.server.resourcemanager.scheduler.common.fica.FiCaSchedulerNode: Assigned container container_1376685566219_0003_01_000002 of capacity <memory:1024, vCores:1> on host hadoop-512-4:51823, which currently has 1 containers, <memory:1024, vCores:1> used and <memory:7168, vCores:15> available
2013-08-16 20:44:13,100 INFO org.apache.hadoop.yarn.server.resourcemanager.scheduler.capacity.LeafQueue: assignedContainer application=application_1376685566219_0003 container=Container: [ContainerId: container_1376685566219_0003_01_000002, NodeId: hadoop-512-4:51823, NodeHttpAddress: hadoop-512-4:8042, Resource: <memory:1024, vCores:1>, Priority: 20, State: NEW, Token: null, Status: container_id {, app_attempt_id {, application_id {, id: 3, cluster_timestamp: 1376685566219, }, attemptId: 1, }, id: 2, }, state: C_NEW, ] containerId=container_1376685566219_0003_01_000002 queue=default: capacity=1.0, absoluteCapacity=1.0, usedResources=<memory:2048, vCores:1>usedCapacity=0.041666668, absoluteUsedCapacity=0.041666668, numApps=1, numContainers=1 usedCapacity=0.041666668 absoluteUsedCapacity=0.041666668 used=<memory:2048, vCores:1> cluster=<memory:49152, vCores:96>
2013-08-16 20:44:13,100 INFO org.apache.hadoop.yarn.server.resourcemanager.scheduler.capacity.ParentQueue: Re-sorting queues since queue: root.default stats: default: capacity=1.0, absoluteCapacity=1.0, usedResources=<memory:3072, vCores:2>usedCapacity=0.0625, absoluteUsedCapacity=0.0625, numApps=1, numContainers=2
2013-08-16 20:44:13,100 INFO org.apache.hadoop.yarn.server.resourcemanager.scheduler.capacity.ParentQueue: assignedContainer queue=root usedCapacity=0.0625 absoluteUsedCapacity=0.0625 used=<memory:3072, vCores:2> cluster=<memory:49152, vCores:96>
2013-08-16 20:44:13,155 INFO org.apache.hadoop.yarn.server.resourcemanager.rmcontainer.RMContainerImpl: container_1376685566219_0003_01_000003 Container Transitioned from NEW to ALLOCATED
2013-08-16 20:44:13,156 INFO org.apache.hadoop.yarn.server.resourcemanager.RMAuditLogger: USER=ubuntu	OPERATION=AM Allocated Container	TARGET=SchedulerApp	RESULT=SUCCESS	APPID=application_1376685566219_0003	CONTAINERID=container_1376685566219_0003_01_000003
2013-08-16 20:44:13,156 INFO org.apache.hadoop.yarn.server.resourcemanager.scheduler.common.fica.FiCaSchedulerNode: Assigned container container_1376685566219_0003_01_000003 of capacity <memory:1024, vCores:1> on host hadoop-512-2:41669, which currently has 1 containers, <memory:1024, vCores:1> used and <memory:7168, vCores:15> available
2013-08-16 20:44:13,157 INFO org.apache.hadoop.yarn.server.resourcemanager.scheduler.capacity.LeafQueue: assignedContainer application=application_1376685566219_0003 container=Container: [ContainerId: container_1376685566219_0003_01_000003, NodeId: hadoop-512-2:41669, NodeHttpAddress: hadoop-512-2:8042, Resource: <memory:1024, vCores:1>, Priority: 20, State: NEW, Token: null, Status: container_id {, app_attempt_id {, application_id {, id: 3, cluster_timestamp: 1376685566219, }, attemptId: 1, }, id: 3, }, state: C_NEW, ] containerId=container_1376685566219_0003_01_000003 queue=default: capacity=1.0, absoluteCapacity=1.0, usedResources=<memory:3072, vCores:2>usedCapacity=0.0625, absoluteUsedCapacity=0.0625, numApps=1, numContainers=2 usedCapacity=0.0625 absoluteUsedCapacity=0.0625 used=<memory:3072, vCores:2> cluster=<memory:49152, vCores:96>
2013-08-16 20:44:13,158 INFO org.apache.hadoop.yarn.server.resourcemanager.scheduler.capacity.ParentQueue: Re-sorting queues since queue: root.default stats: default: capacity=1.0, absoluteCapacity=1.0, usedResources=<memory:4096, vCores:3>usedCapacity=0.083333336, absoluteUsedCapacity=0.083333336, numApps=1, numContainers=3
2013-08-16 20:44:13,158 INFO org.apache.hadoop.yarn.server.resourcemanager.scheduler.capacity.ParentQueue: assignedContainer queue=root usedCapacity=0.083333336 absoluteUsedCapacity=0.083333336 used=<memory:4096, vCores:3> cluster=<memory:49152, vCores:96>
2013-08-16 20:44:13,952 INFO org.apache.hadoop.yarn.server.resourcemanager.rmcontainer.RMContainerImpl: container_1376685566219_0003_01_000002 Container Transitioned from ALLOCATED to ACQUIRED
2013-08-16 20:44:13,954 INFO org.apache.hadoop.yarn.server.resourcemanager.rmcontainer.RMContainerImpl: container_1376685566219_0003_01_000003 Container Transitioned from ALLOCATED to ACQUIRED
2013-08-16 20:44:14,986 INFO org.apache.hadoop.yarn.server.resourcemanager.scheduler.AppSchedulingInfo: checking for deactivate... 
2013-08-16 20:44:15,107 INFO org.apache.hadoop.yarn.server.resourcemanager.rmcontainer.RMContainerImpl: container_1376685566219_0003_01_000002 Container Transitioned from ACQUIRED to RUNNING
2013-08-16 20:44:15,164 INFO org.apache.hadoop.yarn.server.resourcemanager.rmcontainer.RMContainerImpl: container_1376685566219_0003_01_000003 Container Transitioned from ACQUIRED to RUNNING
2013-08-16 20:45:58,844 INFO org.apache.hadoop.yarn.server.resourcemanager.rmcontainer.RMContainerImpl: container_1376685566219_0003_01_000003 Container Transitioned from RUNNING to COMPLETED
2013-08-16 20:45:58,845 INFO org.apache.hadoop.yarn.server.resourcemanager.scheduler.common.fica.FiCaSchedulerApp: Completed container: container_1376685566219_0003_01_000003 in state: COMPLETED event:FINISHED
2013-08-16 20:45:58,845 INFO org.apache.hadoop.yarn.server.resourcemanager.RMAuditLogger: USER=ubuntu	OPERATION=AM Released Container	TARGET=SchedulerApp	RESULT=SUCCESS	APPID=application_1376685566219_0003	CONTAINERID=container_1376685566219_0003_01_000003
2013-08-16 20:45:58,845 INFO org.apache.hadoop.yarn.server.resourcemanager.scheduler.common.fica.FiCaSchedulerNode: Released container container_1376685566219_0003_01_000003 of capacity <memory:1024, vCores:1> on host hadoop-512-2:41669, which currently has 0 containers, <memory:0, vCores:0> used and <memory:8192, vCores:16> available, release resources=true
2013-08-16 20:45:58,845 INFO org.apache.hadoop.yarn.server.resourcemanager.scheduler.capacity.LeafQueue: default used=<memory:3072, vCores:2> numContainers=2 user=ubuntu user-resources=<memory:3072, vCores:2>
2013-08-16 20:45:58,847 INFO org.apache.hadoop.yarn.server.resourcemanager.scheduler.capacity.LeafQueue: completedContainer container=Container: [ContainerId: container_1376685566219_0003_01_000003, NodeId: hadoop-512-2:41669, NodeHttpAddress: hadoop-512-2:8042, Resource: <memory:1024, vCores:1>, Priority: 20, State: NEW, Token: null, Status: container_id {, app_attempt_id {, application_id {, id: 3, cluster_timestamp: 1376685566219, }, attemptId: 1, }, id: 3, }, state: C_COMPLETE, diagnostics: "Container killed by the ApplicationMaster.\n\n", exit_status: 143, ] resource=<memory:1024, vCores:1> queue=default: capacity=1.0, absoluteCapacity=1.0, usedResources=<memory:3072, vCores:2>usedCapacity=0.0625, absoluteUsedCapacity=0.0625, numApps=1, numContainers=2 usedCapacity=0.0625 absoluteUsedCapacity=0.0625 used=<memory:3072, vCores:2> cluster=<memory:49152, vCores:96>
2013-08-16 20:45:58,848 INFO org.apache.hadoop.yarn.server.resourcemanager.scheduler.capacity.ParentQueue: completedContainer queue=root usedCapacity=0.0625 absoluteUsedCapacity=0.0625 used=<memory:3072, vCores:2> cluster=<memory:49152, vCores:96>
2013-08-16 20:45:58,848 INFO org.apache.hadoop.yarn.server.resourcemanager.scheduler.capacity.CapacityScheduler: Application appattempt_1376685566219_0003_000001 released container container_1376685566219_0003_01_000003 on node: host: hadoop-512-2:41669 #containers=0 available=8192 used=0 with event: FINISHED
2013-08-16 20:46:07,163 INFO org.apache.hadoop.yarn.server.resourcemanager.rmcontainer.RMContainerImpl: container_1376685566219_0003_01_000002 Container Transitioned from RUNNING to COMPLETED
2013-08-16 20:46:07,163 INFO org.apache.hadoop.yarn.server.resourcemanager.scheduler.common.fica.FiCaSchedulerApp: Completed container: container_1376685566219_0003_01_000002 in state: COMPLETED event:FINISHED
2013-08-16 20:46:07,163 INFO org.apache.hadoop.yarn.server.resourcemanager.RMAuditLogger: USER=ubuntu	OPERATION=AM Released Container	TARGET=SchedulerApp	RESULT=SUCCESS	APPID=application_1376685566219_0003	CONTAINERID=container_1376685566219_0003_01_000002
2013-08-16 20:46:07,164 INFO org.apache.hadoop.yarn.server.resourcemanager.scheduler.common.fica.FiCaSchedulerNode: Released container container_1376685566219_0003_01_000002 of capacity <memory:1024, vCores:1> on host hadoop-512-4:51823, which currently has 0 containers, <memory:0, vCores:0> used and <memory:8192, vCores:16> available, release resources=true
2013-08-16 20:46:07,164 INFO org.apache.hadoop.yarn.server.resourcemanager.scheduler.capacity.LeafQueue: default used=<memory:2048, vCores:1> numContainers=1 user=ubuntu user-resources=<memory:2048, vCores:1>
2013-08-16 20:46:07,166 INFO org.apache.hadoop.yarn.server.resourcemanager.scheduler.capacity.LeafQueue: completedContainer container=Container: [ContainerId: container_1376685566219_0003_01_000002, NodeId: hadoop-512-4:51823, NodeHttpAddress: hadoop-512-4:8042, Resource: <memory:1024, vCores:1>, Priority: 20, State: NEW, Token: null, Status: container_id {, app_attempt_id {, application_id {, id: 3, cluster_timestamp: 1376685566219, }, attemptId: 1, }, id: 2, }, state: C_COMPLETE, diagnostics: "Container killed by the ApplicationMaster.\n\n", exit_status: 143, ] resource=<memory:1024, vCores:1> queue=default: capacity=1.0, absoluteCapacity=1.0, usedResources=<memory:2048, vCores:1>usedCapacity=0.041666668, absoluteUsedCapacity=0.041666668, numApps=1, numContainers=1 usedCapacity=0.041666668 absoluteUsedCapacity=0.041666668 used=<memory:2048, vCores:1> cluster=<memory:49152, vCores:96>
2013-08-16 20:46:07,166 INFO org.apache.hadoop.yarn.server.resourcemanager.scheduler.capacity.ParentQueue: completedContainer queue=root usedCapacity=0.041666668 absoluteUsedCapacity=0.041666668 used=<memory:2048, vCores:1> cluster=<memory:49152, vCores:96>
2013-08-16 20:46:07,166 INFO org.apache.hadoop.yarn.server.resourcemanager.scheduler.capacity.CapacityScheduler: Application appattempt_1376685566219_0003_000001 released container container_1376685566219_0003_01_000002 on node: host: hadoop-512-4:51823 #containers=0 available=8192 used=0 with event: FINISHED
2013-08-16 20:46:11,331 INFO org.apache.hadoop.yarn.server.resourcemanager.rmapp.attempt.RMAppAttemptImpl: appattempt_1376685566219_0003_000001 State change from RUNNING to FINISHING
2013-08-16 20:46:11,332 INFO org.apache.hadoop.yarn.server.resourcemanager.rmapp.RMAppImpl: application_1376685566219_0003 State change from RUNNING to FINISHING
2013-08-16 20:46:11,811 INFO org.apache.hadoop.yarn.server.resourcemanager.rmcontainer.RMContainerImpl: container_1376685566219_0003_01_000001 Container Transitioned from RUNNING to COMPLETED
2013-08-16 20:46:11,811 INFO org.apache.hadoop.yarn.server.resourcemanager.scheduler.common.fica.FiCaSchedulerApp: Completed container: container_1376685566219_0003_01_000001 in state: COMPLETED event:FINISHED
2013-08-16 20:46:11,811 INFO org.apache.hadoop.yarn.server.resourcemanager.RMAuditLogger: USER=ubuntu	OPERATION=AM Released Container	TARGET=SchedulerApp	RESULT=SUCCESS	APPID=application_1376685566219_0003	CONTAINERID=container_1376685566219_0003_01_000001
2013-08-16 20:46:11,811 INFO org.apache.hadoop.yarn.server.resourcemanager.rmapp.attempt.RMAppAttemptImpl: appattempt_1376685566219_0003_000001 State change from FINISHING to FINISHED
2013-08-16 20:46:11,811 INFO org.apache.hadoop.yarn.server.resourcemanager.scheduler.common.fica.FiCaSchedulerNode: Released container container_1376685566219_0003_01_000001 of capacity <memory:2048, vCores:1> on host hadoop-512-3:58863, which currently has 0 containers, <memory:0, vCores:0> used and <memory:8192, vCores:16> available, release resources=true
2013-08-16 20:46:11,812 INFO org.apache.hadoop.yarn.server.resourcemanager.scheduler.capacity.LeafQueue: default used=<memory:0, vCores:0> numContainers=0 user=ubuntu user-resources=<memory:0, vCores:0>
2013-08-16 20:46:11,812 INFO org.apache.hadoop.yarn.server.resourcemanager.rmapp.RMAppImpl: application_1376685566219_0003 State change from FINISHING to FINISHED
2013-08-16 20:46:11,813 INFO org.apache.hadoop.yarn.server.resourcemanager.RMAuditLogger: USER=ubuntu	OPERATION=Application Finished - Succeeded	TARGET=RMAppManager	RESULT=SUCCESS	APPID=application_1376685566219_0003
2013-08-16 20:46:11,813 INFO org.apache.hadoop.yarn.server.resourcemanager.amlauncher.AMLauncher: Cleaning master appattempt_1376685566219_0003_000001
2013-08-16 20:46:11,813 INFO org.apache.hadoop.yarn.server.resourcemanager.recovery.RMStateStore: Removing info for app: application_1376685566219_0003
2013-08-16 20:46:11,814 INFO org.apache.hadoop.yarn.server.resourcemanager.RMAppManager$ApplicationSummary: appId=application_1376685566219_0003,name=TeraGen,user=ubuntu,queue=default,state=FINISHED,trackingUrl=hadoop-512-1.novalocal:8088/proxy/application_1376685566219_0003/jobhistory/job/job_1376685566219_0003,appMasterHost=hadoop-512-3,startTime=1376685845176,finishTime=1376685971332
2013-08-16 20:46:11,815 INFO org.apache.hadoop.yarn.server.resourcemanager.scheduler.capacity.LeafQueue: completedContainer container=Container: [ContainerId: container_1376685566219_0003_01_000001, NodeId: hadoop-512-3:58863, NodeHttpAddress: hadoop-512-3:8042, Resource: <memory:2048, vCores:1>, Priority: 0, State: NEW, Token: null, Status: container_id {, app_attempt_id {, application_id {, id: 3, cluster_timestamp: 1376685566219, }, attemptId: 1, }, id: 1, }, state: C_COMPLETE, diagnostics: "", exit_status: 0, ] resource=<memory:2048, vCores:1> queue=default: capacity=1.0, absoluteCapacity=1.0, usedResources=<memory:0, vCores:0>usedCapacity=0.0, absoluteUsedCapacity=0.0, numApps=1, numContainers=0 usedCapacity=0.0 absoluteUsedCapacity=0.0 used=<memory:0, vCores:0> cluster=<memory:49152, vCores:96>
2013-08-16 20:46:11,816 INFO org.apache.hadoop.yarn.server.resourcemanager.scheduler.capacity.ParentQueue: completedContainer queue=root usedCapacity=0.0 absoluteUsedCapacity=0.0 used=<memory:0, vCores:0> cluster=<memory:49152, vCores:96>
2013-08-16 20:46:11,816 INFO org.apache.hadoop.yarn.server.resourcemanager.scheduler.capacity.CapacityScheduler: Application appattempt_1376685566219_0003_000001 released container container_1376685566219_0003_01_000001 on node: host: hadoop-512-3:58863 #containers=0 available=8192 used=0 with event: FINISHED
2013-08-16 20:46:11,818 INFO org.apache.hadoop.yarn.server.resourcemanager.scheduler.capacity.CapacityScheduler: Application appattempt_1376685566219_0003_000001 is done. finalState=FINISHED
2013-08-16 20:46:11,819 INFO org.apache.hadoop.yarn.server.resourcemanager.scheduler.AppSchedulingInfo: Application application_1376685566219_0003 requests cleared
2013-08-16 20:46:11,819 INFO org.apache.hadoop.yarn.server.resourcemanager.scheduler.capacity.LeafQueue: Application removed - appId: application_1376685566219_0003 user: ubuntu queue: default #user-pending-applications: 0 #user-active-applications: 0 #queue-pending-applications: 0 #queue-active-applications: 0
2013-08-16 20:46:11,820 INFO org.apache.hadoop.yarn.server.resourcemanager.scheduler.capacity.ParentQueue: Application removed - appId: application_1376685566219_0003 user: ubuntu leaf-queue of parent: root #applications: 0
2013-08-16 20:46:12,455 INFO org.apache.hadoop.yarn.server.resourcemanager.ClientRMService: Allocated new applicationId: 4
2013-08-16 20:46:14,380 INFO org.apache.hadoop.yarn.server.resourcemanager.ClientRMService: Storing Application with id application_1376685566219_0004
2013-08-16 20:46:14,380 INFO org.apache.hadoop.yarn.server.resourcemanager.recovery.RMStateStore: Storing info for app: application_1376685566219_0004
2013-08-16 20:46:14,380 INFO org.apache.hadoop.yarn.server.resourcemanager.ClientRMService: Application with id 4 submitted by user ubuntu
2013-08-16 20:46:14,380 INFO org.apache.hadoop.yarn.server.resourcemanager.RMAuditLogger: USER=ubuntu	IP=192.168.100.6	OPERATION=Submit Application Request	TARGET=ClientRMService	RESULT=SUCCESS	APPID=application_1376685566219_0004
2013-08-16 20:46:14,381 INFO org.apache.hadoop.yarn.server.resourcemanager.rmapp.RMAppImpl: application_1376685566219_0004 State change from NEW to SUBMITTED
2013-08-16 20:46:14,382 INFO org.apache.hadoop.yarn.server.resourcemanager.ApplicationMasterService: Registering appattempt_1376685566219_0004_000001
2013-08-16 20:46:14,382 INFO org.apache.hadoop.yarn.server.resourcemanager.rmapp.attempt.RMAppAttemptImpl: appattempt_1376685566219_0004_000001 State change from NEW to SUBMITTED
2013-08-16 20:46:14,383 INFO org.apache.hadoop.yarn.server.resourcemanager.scheduler.capacity.LeafQueue: Application application_1376685566219_0004 from user: ubuntu activated in queue: default
2013-08-16 20:46:14,383 INFO org.apache.hadoop.yarn.server.resourcemanager.scheduler.capacity.LeafQueue: Application added - appId: application_1376685566219_0004 user: org.apache.hadoop.yarn.server.resourcemanager.scheduler.capacity.LeafQueue$User@6b12f091, leaf-queue: default #user-pending-applications: 0 #user-active-applications: 1 #queue-pending-applications: 0 #queue-active-applications: 1
2013-08-16 20:46:14,383 INFO org.apache.hadoop.yarn.server.resourcemanager.scheduler.capacity.ParentQueue: Application added - appId: application_1376685566219_0004 user: ubuntu leaf-queue of parent: root #applications: 1
2013-08-16 20:46:14,383 INFO org.apache.hadoop.yarn.server.resourcemanager.scheduler.capacity.CapacityScheduler: Application Submission: appattempt_1376685566219_0004_000001, user: ubuntu queue: default: capacity=1.0, absoluteCapacity=1.0, usedResources=<memory:0, vCores:0>usedCapacity=0.0, absoluteUsedCapacity=0.0, numApps=1, numContainers=0, currently active: 1
2013-08-16 20:46:14,384 INFO org.apache.hadoop.yarn.server.resourcemanager.rmapp.attempt.RMAppAttemptImpl: appattempt_1376685566219_0004_000001 State change from SUBMITTED to SCHEDULED
2013-08-16 20:46:14,384 INFO org.apache.hadoop.yarn.server.resourcemanager.rmapp.RMAppImpl: application_1376685566219_0004 State change from SUBMITTED to ACCEPTED
2013-08-16 20:46:14,663 INFO org.apache.hadoop.yarn.server.resourcemanager.rmcontainer.RMContainerImpl: container_1376685566219_0004_01_000001 Container Transitioned from NEW to ALLOCATED
2013-08-16 20:46:14,663 INFO org.apache.hadoop.yarn.server.resourcemanager.RMAuditLogger: USER=ubuntu	OPERATION=AM Allocated Container	TARGET=SchedulerApp	RESULT=SUCCESS	APPID=application_1376685566219_0004	CONTAINERID=container_1376685566219_0004_01_000001
2013-08-16 20:46:14,663 INFO org.apache.hadoop.yarn.server.resourcemanager.scheduler.common.fica.FiCaSchedulerNode: Assigned container container_1376685566219_0004_01_000001 of capacity <memory:2048, vCores:1> on host hadoop-512-5:53603, which currently has 1 containers, <memory:2048, vCores:1> used and <memory:6144, vCores:15> available
2013-08-16 20:46:14,665 INFO org.apache.hadoop.yarn.server.resourcemanager.scheduler.capacity.LeafQueue: assignedContainer application=application_1376685566219_0004 container=Container: [ContainerId: container_1376685566219_0004_01_000001, NodeId: hadoop-512-5:53603, NodeHttpAddress: hadoop-512-5:8042, Resource: <memory:2048, vCores:1>, Priority: 0, State: NEW, Token: null, Status: container_id {, app_attempt_id {, application_id {, id: 4, cluster_timestamp: 1376685566219, }, attemptId: 1, }, id: 1, }, state: C_NEW, ] containerId=container_1376685566219_0004_01_000001 queue=default: capacity=1.0, absoluteCapacity=1.0, usedResources=<memory:0, vCores:0>usedCapacity=0.0, absoluteUsedCapacity=0.0, numApps=1, numContainers=0 usedCapacity=0.0 absoluteUsedCapacity=0.0 used=<memory:0, vCores:0> cluster=<memory:49152, vCores:96>
2013-08-16 20:46:14,665 INFO org.apache.hadoop.yarn.server.resourcemanager.scheduler.capacity.ParentQueue: Re-sorting queues since queue: root.default stats: default: capacity=1.0, absoluteCapacity=1.0, usedResources=<memory:2048, vCores:1>usedCapacity=0.041666668, absoluteUsedCapacity=0.041666668, numApps=1, numContainers=1
2013-08-16 20:46:14,665 INFO org.apache.hadoop.yarn.server.resourcemanager.scheduler.capacity.ParentQueue: assignedContainer queue=root usedCapacity=0.041666668 absoluteUsedCapacity=0.041666668 used=<memory:2048, vCores:1> cluster=<memory:49152, vCores:96>
2013-08-16 20:46:14,667 INFO org.apache.hadoop.yarn.server.resourcemanager.rmcontainer.RMContainerImpl: container_1376685566219_0004_01_000001 Container Transitioned from ALLOCATED to ACQUIRED
2013-08-16 20:46:14,669 INFO org.apache.hadoop.yarn.server.resourcemanager.rmapp.attempt.RMAppAttemptImpl: Storing attempt: AppId: application_1376685566219_0004 AttemptId: appattempt_1376685566219_0004_000001 MasterContainer: Container: [ContainerId: container_1376685566219_0004_01_000001, NodeId: hadoop-512-5:53603, NodeHttpAddress: hadoop-512-5:8042, Resource: <memory:2048, vCores:1>, Priority: 0, State: NEW, Token: null, Status: container_id {, app_attempt_id {, application_id {, id: 4, cluster_timestamp: 1376685566219, }, attemptId: 1, }, id: 1, }, state: C_NEW, ]
2013-08-16 20:46:14,669 INFO org.apache.hadoop.yarn.server.resourcemanager.rmapp.attempt.RMAppAttemptImpl: appattempt_1376685566219_0004_000001 State change from SCHEDULED to ALLOCATED_SAVING
2013-08-16 20:46:14,669 INFO org.apache.hadoop.yarn.server.resourcemanager.recovery.RMStateStore: Storing info for attempt: appattempt_1376685566219_0004_000001
2013-08-16 20:46:14,671 INFO org.apache.hadoop.yarn.server.resourcemanager.rmapp.attempt.RMAppAttemptImpl: appattempt_1376685566219_0004_000001 State change from ALLOCATED_SAVING to ALLOCATED
2013-08-16 20:46:14,673 INFO org.apache.hadoop.yarn.server.resourcemanager.amlauncher.AMLauncher: Launching masterappattempt_1376685566219_0004_000001
2013-08-16 20:46:14,676 INFO org.apache.hadoop.yarn.server.resourcemanager.amlauncher.AMLauncher: Setting up container Container: [ContainerId: container_1376685566219_0004_01_000001, NodeId: hadoop-512-5:53603, NodeHttpAddress: hadoop-512-5:8042, Resource: <memory:2048, vCores:1>, Priority: 0, State: NEW, Token: null, Status: container_id {, app_attempt_id {, application_id {, id: 4, cluster_timestamp: 1376685566219, }, attemptId: 1, }, id: 1, }, state: C_NEW, ] for AM appattempt_1376685566219_0004_000001
2013-08-16 20:46:14,676 INFO org.apache.hadoop.yarn.server.resourcemanager.amlauncher.AMLauncher: Command to launch container container_1376685566219_0004_01_000001 : $JAVA_HOME/bin/java -Dlog4j.configuration=container-log4j.properties -Dyarn.app.mapreduce.container.log.dir=<LOG_DIR> -Dyarn.app.mapreduce.container.log.filesize=0 -Dhadoop.root.logger=INFO,CLA  -Xmx1024m org.apache.hadoop.mapreduce.v2.app.MRAppMaster 1><LOG_DIR>/stdout 2><LOG_DIR>/stderr 
2013-08-16 20:46:15,559 INFO org.apache.hadoop.yarn.server.resourcemanager.amlauncher.AMLauncher: Done launching container Container: [ContainerId: container_1376685566219_0004_01_000001, NodeId: hadoop-512-5:53603, NodeHttpAddress: hadoop-512-5:8042, Resource: <memory:2048, vCores:1>, Priority: 0, State: NEW, Token: null, Status: container_id {, app_attempt_id {, application_id {, id: 4, cluster_timestamp: 1376685566219, }, attemptId: 1, }, id: 1, }, state: C_NEW, ] for AM appattempt_1376685566219_0004_000001
2013-08-16 20:46:15,559 INFO org.apache.hadoop.yarn.server.resourcemanager.rmapp.attempt.RMAppAttemptImpl: appattempt_1376685566219_0004_000001 State change from ALLOCATED to LAUNCHED
2013-08-16 20:46:15,832 INFO org.apache.hadoop.yarn.server.resourcemanager.rmcontainer.RMContainerImpl: container_1376685566219_0004_01_000001 Container Transitioned from ACQUIRED to RUNNING
2013-08-16 20:46:24,316 INFO org.apache.hadoop.yarn.server.resourcemanager.ApplicationMasterService: AM registration appattempt_1376685566219_0004_000001
2013-08-16 20:46:24,316 INFO org.apache.hadoop.yarn.server.resourcemanager.RMAuditLogger: USER=ubuntu	IP=192.168.100.17	OPERATION=Register App Master	TARGET=ApplicationMasterService	RESULT=SUCCESS	APPID=application_1376685566219_0004	APPATTEMPTID=appattempt_1376685566219_0004_000001
2013-08-16 20:46:24,317 INFO org.apache.hadoop.yarn.server.resourcemanager.rmapp.attempt.RMAppAttemptImpl: appattempt_1376685566219_0004_000001 State change from LAUNCHED to RUNNING
2013-08-16 20:46:24,317 INFO org.apache.hadoop.yarn.server.resourcemanager.rmapp.RMAppImpl: application_1376685566219_0004 State change from ACCEPTED to RUNNING
2013-08-16 20:46:25,862 INFO org.apache.hadoop.yarn.server.resourcemanager.rmcontainer.RMContainerImpl: container_1376685566219_0004_01_000002 Container Transitioned from NEW to ALLOCATED
2013-08-16 20:46:25,863 INFO org.apache.hadoop.yarn.server.resourcemanager.RMAuditLogger: USER=ubuntu	OPERATION=AM Allocated Container	TARGET=SchedulerApp	RESULT=SUCCESS	APPID=application_1376685566219_0004	CONTAINERID=container_1376685566219_0004_01_000002
2013-08-16 20:46:25,863 INFO org.apache.hadoop.yarn.server.resourcemanager.scheduler.common.fica.FiCaSchedulerNode: Assigned container container_1376685566219_0004_01_000002 of capacity <memory:1024, vCores:1> on host hadoop-512-3:58863, which currently has 1 containers, <memory:1024, vCores:1> used and <memory:7168, vCores:15> available
2013-08-16 20:46:25,864 INFO org.apache.hadoop.yarn.server.resourcemanager.scheduler.capacity.LeafQueue: assignedContainer application=application_1376685566219_0004 container=Container: [ContainerId: container_1376685566219_0004_01_000002, NodeId: hadoop-512-3:58863, NodeHttpAddress: hadoop-512-3:8042, Resource: <memory:1024, vCores:1>, Priority: 20, State: NEW, Token: null, Status: container_id {, app_attempt_id {, application_id {, id: 4, cluster_timestamp: 1376685566219, }, attemptId: 1, }, id: 2, }, state: C_NEW, ] containerId=container_1376685566219_0004_01_000002 queue=default: capacity=1.0, absoluteCapacity=1.0, usedResources=<memory:2048, vCores:1>usedCapacity=0.041666668, absoluteUsedCapacity=0.041666668, numApps=1, numContainers=1 usedCapacity=0.041666668 absoluteUsedCapacity=0.041666668 used=<memory:2048, vCores:1> cluster=<memory:49152, vCores:96>
2013-08-16 20:46:25,865 INFO org.apache.hadoop.yarn.server.resourcemanager.scheduler.capacity.ParentQueue: Re-sorting queues since queue: root.default stats: default: capacity=1.0, absoluteCapacity=1.0, usedResources=<memory:3072, vCores:2>usedCapacity=0.0625, absoluteUsedCapacity=0.0625, numApps=1, numContainers=2
2013-08-16 20:46:25,865 INFO org.apache.hadoop.yarn.server.resourcemanager.scheduler.capacity.ParentQueue: assignedContainer queue=root usedCapacity=0.0625 absoluteUsedCapacity=0.0625 used=<memory:3072, vCores:2> cluster=<memory:49152, vCores:96>
2013-08-16 20:46:25,886 INFO org.apache.hadoop.yarn.server.resourcemanager.rmcontainer.RMContainerImpl: container_1376685566219_0004_01_000003 Container Transitioned from NEW to ALLOCATED
2013-08-16 20:46:25,886 INFO org.apache.hadoop.yarn.server.resourcemanager.RMAuditLogger: USER=ubuntu	OPERATION=AM Allocated Container	TARGET=SchedulerApp	RESULT=SUCCESS	APPID=application_1376685566219_0004	CONTAINERID=container_1376685566219_0004_01_000003
2013-08-16 20:46:25,886 INFO org.apache.hadoop.yarn.server.resourcemanager.scheduler.common.fica.FiCaSchedulerNode: Assigned container container_1376685566219_0004_01_000003 of capacity <memory:1024, vCores:1> on host hadoop-512-5:53603, which currently has 2 containers, <memory:3072, vCores:2> used and <memory:5120, vCores:14> available
2013-08-16 20:46:25,888 INFO org.apache.hadoop.yarn.server.resourcemanager.scheduler.capacity.LeafQueue: assignedContainer application=application_1376685566219_0004 container=Container: [ContainerId: container_1376685566219_0004_01_000003, NodeId: hadoop-512-5:53603, NodeHttpAddress: hadoop-512-5:8042, Resource: <memory:1024, vCores:1>, Priority: 20, State: NEW, Token: null, Status: container_id {, app_attempt_id {, application_id {, id: 4, cluster_timestamp: 1376685566219, }, attemptId: 1, }, id: 3, }, state: C_NEW, ] containerId=container_1376685566219_0004_01_000003 queue=default: capacity=1.0, absoluteCapacity=1.0, usedResources=<memory:3072, vCores:2>usedCapacity=0.0625, absoluteUsedCapacity=0.0625, numApps=1, numContainers=2 usedCapacity=0.0625 absoluteUsedCapacity=0.0625 used=<memory:3072, vCores:2> cluster=<memory:49152, vCores:96>
2013-08-16 20:46:25,888 INFO org.apache.hadoop.yarn.server.resourcemanager.scheduler.capacity.ParentQueue: Re-sorting queues since queue: root.default stats: default: capacity=1.0, absoluteCapacity=1.0, usedResources=<memory:4096, vCores:3>usedCapacity=0.083333336, absoluteUsedCapacity=0.083333336, numApps=1, numContainers=3
2013-08-16 20:46:25,888 INFO org.apache.hadoop.yarn.server.resourcemanager.scheduler.capacity.ParentQueue: assignedContainer queue=root usedCapacity=0.083333336 absoluteUsedCapacity=0.083333336 used=<memory:4096, vCores:3> cluster=<memory:49152, vCores:96>
2013-08-16 20:46:26,373 INFO org.apache.hadoop.yarn.server.resourcemanager.rmcontainer.RMContainerImpl: container_1376685566219_0004_01_000002 Container Transitioned from ALLOCATED to ACQUIRED
2013-08-16 20:46:26,376 INFO org.apache.hadoop.yarn.server.resourcemanager.rmcontainer.RMContainerImpl: container_1376685566219_0004_01_000003 Container Transitioned from ALLOCATED to ACQUIRED
2013-08-16 20:46:26,868 INFO org.apache.hadoop.yarn.server.resourcemanager.rmcontainer.RMContainerImpl: container_1376685566219_0004_01_000002 Container Transitioned from ACQUIRED to RUNNING
2013-08-16 20:46:26,897 INFO org.apache.hadoop.yarn.server.resourcemanager.rmcontainer.RMContainerImpl: container_1376685566219_0004_01_000003 Container Transitioned from ACQUIRED to RUNNING
2013-08-16 20:46:27,408 INFO org.apache.hadoop.yarn.server.resourcemanager.scheduler.AppSchedulingInfo: checking for deactivate... 
2013-08-16 20:48:10,377 INFO org.apache.hadoop.yarn.server.resourcemanager.rmcontainer.RMContainerImpl: container_1376685566219_0004_01_000003 Container Transitioned from RUNNING to COMPLETED
2013-08-16 20:48:10,377 INFO org.apache.hadoop.yarn.server.resourcemanager.scheduler.common.fica.FiCaSchedulerApp: Completed container: container_1376685566219_0004_01_000003 in state: COMPLETED event:FINISHED
2013-08-16 20:48:10,377 INFO org.apache.hadoop.yarn.server.resourcemanager.RMAuditLogger: USER=ubuntu	OPERATION=AM Released Container	TARGET=SchedulerApp	RESULT=SUCCESS	APPID=application_1376685566219_0004	CONTAINERID=container_1376685566219_0004_01_000003
2013-08-16 20:48:10,377 INFO org.apache.hadoop.yarn.server.resourcemanager.scheduler.common.fica.FiCaSchedulerNode: Released container container_1376685566219_0004_01_000003 of capacity <memory:1024, vCores:1> on host hadoop-512-5:53603, which currently has 1 containers, <memory:2048, vCores:1> used and <memory:6144, vCores:15> available, release resources=true
2013-08-16 20:48:10,378 INFO org.apache.hadoop.yarn.server.resourcemanager.scheduler.capacity.LeafQueue: default used=<memory:3072, vCores:2> numContainers=2 user=ubuntu user-resources=<memory:3072, vCores:2>
2013-08-16 20:48:10,379 INFO org.apache.hadoop.yarn.server.resourcemanager.scheduler.capacity.LeafQueue: completedContainer container=Container: [ContainerId: container_1376685566219_0004_01_000003, NodeId: hadoop-512-5:53603, NodeHttpAddress: hadoop-512-5:8042, Resource: <memory:1024, vCores:1>, Priority: 20, State: NEW, Token: null, Status: container_id {, app_attempt_id {, application_id {, id: 4, cluster_timestamp: 1376685566219, }, attemptId: 1, }, id: 3, }, state: C_COMPLETE, diagnostics: "Container killed by the ApplicationMaster.\n\n", exit_status: 143, ] resource=<memory:1024, vCores:1> queue=default: capacity=1.0, absoluteCapacity=1.0, usedResources=<memory:3072, vCores:2>usedCapacity=0.0625, absoluteUsedCapacity=0.0625, numApps=1, numContainers=2 usedCapacity=0.0625 absoluteUsedCapacity=0.0625 used=<memory:3072, vCores:2> cluster=<memory:49152, vCores:96>
2013-08-16 20:48:10,379 INFO org.apache.hadoop.yarn.server.resourcemanager.scheduler.capacity.ParentQueue: completedContainer queue=root usedCapacity=0.0625 absoluteUsedCapacity=0.0625 used=<memory:3072, vCores:2> cluster=<memory:49152, vCores:96>
2013-08-16 20:48:10,380 INFO org.apache.hadoop.yarn.server.resourcemanager.scheduler.capacity.CapacityScheduler: Application appattempt_1376685566219_0004_000001 released container container_1376685566219_0004_01_000003 on node: host: hadoop-512-5:53603 #containers=1 available=6144 used=2048 with event: FINISHED
2013-08-16 20:48:18,193 INFO org.apache.hadoop.yarn.server.resourcemanager.rmcontainer.RMContainerImpl: container_1376685566219_0004_01_000002 Container Transitioned from RUNNING to COMPLETED
2013-08-16 20:48:18,193 INFO org.apache.hadoop.yarn.server.resourcemanager.scheduler.common.fica.FiCaSchedulerApp: Completed container: container_1376685566219_0004_01_000002 in state: COMPLETED event:FINISHED
2013-08-16 20:48:18,193 INFO org.apache.hadoop.yarn.server.resourcemanager.RMAuditLogger: USER=ubuntu	OPERATION=AM Released Container	TARGET=SchedulerApp	RESULT=SUCCESS	APPID=application_1376685566219_0004	CONTAINERID=container_1376685566219_0004_01_000002
2013-08-16 20:48:18,193 INFO org.apache.hadoop.yarn.server.resourcemanager.scheduler.common.fica.FiCaSchedulerNode: Released container container_1376685566219_0004_01_000002 of capacity <memory:1024, vCores:1> on host hadoop-512-3:58863, which currently has 0 containers, <memory:0, vCores:0> used and <memory:8192, vCores:16> available, release resources=true
2013-08-16 20:48:18,193 INFO org.apache.hadoop.yarn.server.resourcemanager.scheduler.capacity.LeafQueue: default used=<memory:2048, vCores:1> numContainers=1 user=ubuntu user-resources=<memory:2048, vCores:1>
2013-08-16 20:48:18,195 INFO org.apache.hadoop.yarn.server.resourcemanager.scheduler.capacity.LeafQueue: completedContainer container=Container: [ContainerId: container_1376685566219_0004_01_000002, NodeId: hadoop-512-3:58863, NodeHttpAddress: hadoop-512-3:8042, Resource: <memory:1024, vCores:1>, Priority: 20, State: NEW, Token: null, Status: container_id {, app_attempt_id {, application_id {, id: 4, cluster_timestamp: 1376685566219, }, attemptId: 1, }, id: 2, }, state: C_COMPLETE, diagnostics: "Container killed by the ApplicationMaster.\n\n", exit_status: 143, ] resource=<memory:1024, vCores:1> queue=default: capacity=1.0, absoluteCapacity=1.0, usedResources=<memory:2048, vCores:1>usedCapacity=0.041666668, absoluteUsedCapacity=0.041666668, numApps=1, numContainers=1 usedCapacity=0.041666668 absoluteUsedCapacity=0.041666668 used=<memory:2048, vCores:1> cluster=<memory:49152, vCores:96>
2013-08-16 20:48:18,195 INFO org.apache.hadoop.yarn.server.resourcemanager.scheduler.capacity.ParentQueue: completedContainer queue=root usedCapacity=0.041666668 absoluteUsedCapacity=0.041666668 used=<memory:2048, vCores:1> cluster=<memory:49152, vCores:96>
2013-08-16 20:48:18,196 INFO org.apache.hadoop.yarn.server.resourcemanager.scheduler.capacity.CapacityScheduler: Application appattempt_1376685566219_0004_000001 released container container_1376685566219_0004_01_000002 on node: host: hadoop-512-3:58863 #containers=0 available=8192 used=0 with event: FINISHED
2013-08-16 20:48:22,373 INFO org.apache.hadoop.yarn.server.resourcemanager.rmapp.attempt.RMAppAttemptImpl: appattempt_1376685566219_0004_000001 State change from RUNNING to FINISHING
2013-08-16 20:48:22,373 INFO org.apache.hadoop.yarn.server.resourcemanager.rmapp.RMAppImpl: application_1376685566219_0004 State change from RUNNING to FINISHING
2013-08-16 20:48:23,444 INFO org.apache.hadoop.yarn.server.resourcemanager.rmcontainer.RMContainerImpl: container_1376685566219_0004_01_000001 Container Transitioned from RUNNING to COMPLETED
2013-08-16 20:48:23,444 INFO org.apache.hadoop.yarn.server.resourcemanager.rmapp.attempt.RMAppAttemptImpl: appattempt_1376685566219_0004_000001 State change from FINISHING to FINISHED
2013-08-16 20:48:23,444 INFO org.apache.hadoop.yarn.server.resourcemanager.scheduler.common.fica.FiCaSchedulerApp: Completed container: container_1376685566219_0004_01_000001 in state: COMPLETED event:FINISHED
2013-08-16 20:48:23,445 INFO org.apache.hadoop.yarn.server.resourcemanager.rmapp.RMAppImpl: application_1376685566219_0004 State change from FINISHING to FINISHED
2013-08-16 20:48:23,445 INFO org.apache.hadoop.yarn.server.resourcemanager.RMAuditLogger: USER=ubuntu	OPERATION=AM Released Container	TARGET=SchedulerApp	RESULT=SUCCESS	APPID=application_1376685566219_0004	CONTAINERID=container_1376685566219_0004_01_000001
2013-08-16 20:48:23,445 INFO org.apache.hadoop.yarn.server.resourcemanager.scheduler.common.fica.FiCaSchedulerNode: Released container container_1376685566219_0004_01_000001 of capacity <memory:2048, vCores:1> on host hadoop-512-5:53603, which currently has 0 containers, <memory:0, vCores:0> used and <memory:8192, vCores:16> available, release resources=true
2013-08-16 20:48:23,445 INFO org.apache.hadoop.yarn.server.resourcemanager.scheduler.capacity.LeafQueue: default used=<memory:0, vCores:0> numContainers=0 user=ubuntu user-resources=<memory:0, vCores:0>
2013-08-16 20:48:23,445 INFO org.apache.hadoop.yarn.server.resourcemanager.RMAuditLogger: USER=ubuntu	OPERATION=Application Finished - Succeeded	TARGET=RMAppManager	RESULT=SUCCESS	APPID=application_1376685566219_0004
2013-08-16 20:48:23,446 INFO org.apache.hadoop.yarn.server.resourcemanager.amlauncher.AMLauncher: Cleaning master appattempt_1376685566219_0004_000001
2013-08-16 20:48:23,446 INFO org.apache.hadoop.yarn.server.resourcemanager.recovery.RMStateStore: Removing info for app: application_1376685566219_0004
2013-08-16 20:48:23,446 INFO org.apache.hadoop.yarn.server.resourcemanager.RMAppManager$ApplicationSummary: appId=application_1376685566219_0004,name=TeraGen,user=ubuntu,queue=default,state=FINISHED,trackingUrl=hadoop-512-1.novalocal:8088/proxy/application_1376685566219_0004/jobhistory/job/job_1376685566219_0004,appMasterHost=hadoop-512-5,startTime=1376685974379,finishTime=1376686102373
2013-08-16 20:48:23,447 INFO org.apache.hadoop.yarn.server.resourcemanager.scheduler.capacity.LeafQueue: completedContainer container=Container: [ContainerId: container_1376685566219_0004_01_000001, NodeId: hadoop-512-5:53603, NodeHttpAddress: hadoop-512-5:8042, Resource: <memory:2048, vCores:1>, Priority: 0, State: NEW, Token: null, Status: container_id {, app_attempt_id {, application_id {, id: 4, cluster_timestamp: 1376685566219, }, attemptId: 1, }, id: 1, }, state: C_COMPLETE, diagnostics: "", exit_status: 0, ] resource=<memory:2048, vCores:1> queue=default: capacity=1.0, absoluteCapacity=1.0, usedResources=<memory:0, vCores:0>usedCapacity=0.0, absoluteUsedCapacity=0.0, numApps=1, numContainers=0 usedCapacity=0.0 absoluteUsedCapacity=0.0 used=<memory:0, vCores:0> cluster=<memory:49152, vCores:96>
2013-08-16 20:48:23,447 INFO org.apache.hadoop.yarn.server.resourcemanager.scheduler.capacity.ParentQueue: completedContainer queue=root usedCapacity=0.0 absoluteUsedCapacity=0.0 used=<memory:0, vCores:0> cluster=<memory:49152, vCores:96>
2013-08-16 20:48:23,447 INFO org.apache.hadoop.yarn.server.resourcemanager.scheduler.capacity.CapacityScheduler: Application appattempt_1376685566219_0004_000001 released container container_1376685566219_0004_01_000001 on node: host: hadoop-512-5:53603 #containers=0 available=8192 used=0 with event: FINISHED
2013-08-16 20:48:23,447 INFO org.apache.hadoop.yarn.server.resourcemanager.scheduler.capacity.CapacityScheduler: Application appattempt_1376685566219_0004_000001 is done. finalState=FINISHED
2013-08-16 20:48:23,448 INFO org.apache.hadoop.yarn.server.resourcemanager.scheduler.AppSchedulingInfo: Application application_1376685566219_0004 requests cleared
2013-08-16 20:48:23,448 INFO org.apache.hadoop.yarn.server.resourcemanager.scheduler.capacity.LeafQueue: Application removed - appId: application_1376685566219_0004 user: ubuntu queue: default #user-pending-applications: 0 #user-active-applications: 0 #queue-pending-applications: 0 #queue-active-applications: 0
2013-08-16 20:48:23,448 INFO org.apache.hadoop.yarn.server.resourcemanager.scheduler.capacity.ParentQueue: Application removed - appId: application_1376685566219_0004 user: ubuntu leaf-queue of parent: root #applications: 0
2013-08-16 20:48:24,364 INFO org.apache.hadoop.yarn.server.resourcemanager.ClientRMService: Allocated new applicationId: 5
2013-08-16 20:48:26,286 INFO org.apache.hadoop.yarn.server.resourcemanager.ClientRMService: Storing Application with id application_1376685566219_0005
2013-08-16 20:48:26,286 INFO org.apache.hadoop.yarn.server.resourcemanager.recovery.RMStateStore: Storing info for app: application_1376685566219_0005
2013-08-16 20:48:26,286 INFO org.apache.hadoop.yarn.server.resourcemanager.ClientRMService: Application with id 5 submitted by user ubuntu
2013-08-16 20:48:26,286 INFO org.apache.hadoop.yarn.server.resourcemanager.RMAuditLogger: USER=ubuntu	IP=192.168.100.6	OPERATION=Submit Application Request	TARGET=ClientRMService	RESULT=SUCCESS	APPID=application_1376685566219_0005
2013-08-16 20:48:26,287 INFO org.apache.hadoop.yarn.server.resourcemanager.rmapp.RMAppImpl: application_1376685566219_0005 State change from NEW to SUBMITTED
2013-08-16 20:48:26,288 INFO org.apache.hadoop.yarn.server.resourcemanager.ApplicationMasterService: Registering appattempt_1376685566219_0005_000001
2013-08-16 20:48:26,288 INFO org.apache.hadoop.yarn.server.resourcemanager.rmapp.attempt.RMAppAttemptImpl: appattempt_1376685566219_0005_000001 State change from NEW to SUBMITTED
2013-08-16 20:48:26,288 INFO org.apache.hadoop.yarn.server.resourcemanager.scheduler.capacity.LeafQueue: Application application_1376685566219_0005 from user: ubuntu activated in queue: default
2013-08-16 20:48:26,289 INFO org.apache.hadoop.yarn.server.resourcemanager.scheduler.capacity.LeafQueue: Application added - appId: application_1376685566219_0005 user: org.apache.hadoop.yarn.server.resourcemanager.scheduler.capacity.LeafQueue$User@6fb562c3, leaf-queue: default #user-pending-applications: 0 #user-active-applications: 1 #queue-pending-applications: 0 #queue-active-applications: 1
2013-08-16 20:48:26,289 INFO org.apache.hadoop.yarn.server.resourcemanager.scheduler.capacity.ParentQueue: Application added - appId: application_1376685566219_0005 user: ubuntu leaf-queue of parent: root #applications: 1
2013-08-16 20:48:26,289 INFO org.apache.hadoop.yarn.server.resourcemanager.scheduler.capacity.CapacityScheduler: Application Submission: appattempt_1376685566219_0005_000001, user: ubuntu queue: default: capacity=1.0, absoluteCapacity=1.0, usedResources=<memory:0, vCores:0>usedCapacity=0.0, absoluteUsedCapacity=0.0, numApps=1, numContainers=0, currently active: 1
2013-08-16 20:48:26,289 INFO org.apache.hadoop.yarn.server.resourcemanager.rmapp.attempt.RMAppAttemptImpl: appattempt_1376685566219_0005_000001 State change from SUBMITTED to SCHEDULED
2013-08-16 20:48:26,289 INFO org.apache.hadoop.yarn.server.resourcemanager.rmapp.RMAppImpl: application_1376685566219_0005 State change from SUBMITTED to ACCEPTED
2013-08-16 20:48:26,459 INFO org.apache.hadoop.yarn.server.resourcemanager.rmcontainer.RMContainerImpl: container_1376685566219_0005_01_000001 Container Transitioned from NEW to ALLOCATED
2013-08-16 20:48:26,459 INFO org.apache.hadoop.yarn.server.resourcemanager.RMAuditLogger: USER=ubuntu	OPERATION=AM Allocated Container	TARGET=SchedulerApp	RESULT=SUCCESS	APPID=application_1376685566219_0005	CONTAINERID=container_1376685566219_0005_01_000001
2013-08-16 20:48:26,459 INFO org.apache.hadoop.yarn.server.resourcemanager.scheduler.common.fica.FiCaSchedulerNode: Assigned container container_1376685566219_0005_01_000001 of capacity <memory:2048, vCores:1> on host hadoop-512-5:53603, which currently has 1 containers, <memory:2048, vCores:1> used and <memory:6144, vCores:15> available
2013-08-16 20:48:26,461 INFO org.apache.hadoop.yarn.server.resourcemanager.scheduler.capacity.LeafQueue: assignedContainer application=application_1376685566219_0005 container=Container: [ContainerId: container_1376685566219_0005_01_000001, NodeId: hadoop-512-5:53603, NodeHttpAddress: hadoop-512-5:8042, Resource: <memory:2048, vCores:1>, Priority: 0, State: NEW, Token: null, Status: container_id {, app_attempt_id {, application_id {, id: 5, cluster_timestamp: 1376685566219, }, attemptId: 1, }, id: 1, }, state: C_NEW, ] containerId=container_1376685566219_0005_01_000001 queue=default: capacity=1.0, absoluteCapacity=1.0, usedResources=<memory:0, vCores:0>usedCapacity=0.0, absoluteUsedCapacity=0.0, numApps=1, numContainers=0 usedCapacity=0.0 absoluteUsedCapacity=0.0 used=<memory:0, vCores:0> cluster=<memory:49152, vCores:96>
2013-08-16 20:48:26,461 INFO org.apache.hadoop.yarn.server.resourcemanager.scheduler.capacity.ParentQueue: Re-sorting queues since queue: root.default stats: default: capacity=1.0, absoluteCapacity=1.0, usedResources=<memory:2048, vCores:1>usedCapacity=0.041666668, absoluteUsedCapacity=0.041666668, numApps=1, numContainers=1
2013-08-16 20:48:26,462 INFO org.apache.hadoop.yarn.server.resourcemanager.scheduler.capacity.ParentQueue: assignedContainer queue=root usedCapacity=0.041666668 absoluteUsedCapacity=0.041666668 used=<memory:2048, vCores:1> cluster=<memory:49152, vCores:96>
2013-08-16 20:48:26,463 INFO org.apache.hadoop.yarn.server.resourcemanager.rmcontainer.RMContainerImpl: container_1376685566219_0005_01_000001 Container Transitioned from ALLOCATED to ACQUIRED
2013-08-16 20:48:26,465 INFO org.apache.hadoop.yarn.server.resourcemanager.rmapp.attempt.RMAppAttemptImpl: Storing attempt: AppId: application_1376685566219_0005 AttemptId: appattempt_1376685566219_0005_000001 MasterContainer: Container: [ContainerId: container_1376685566219_0005_01_000001, NodeId: hadoop-512-5:53603, NodeHttpAddress: hadoop-512-5:8042, Resource: <memory:2048, vCores:1>, Priority: 0, State: NEW, Token: null, Status: container_id {, app_attempt_id {, application_id {, id: 5, cluster_timestamp: 1376685566219, }, attemptId: 1, }, id: 1, }, state: C_NEW, ]
2013-08-16 20:48:26,465 INFO org.apache.hadoop.yarn.server.resourcemanager.rmapp.attempt.RMAppAttemptImpl: appattempt_1376685566219_0005_000001 State change from SCHEDULED to ALLOCATED_SAVING
2013-08-16 20:48:26,465 INFO org.apache.hadoop.yarn.server.resourcemanager.recovery.RMStateStore: Storing info for attempt: appattempt_1376685566219_0005_000001
2013-08-16 20:48:26,466 INFO org.apache.hadoop.yarn.server.resourcemanager.rmapp.attempt.RMAppAttemptImpl: appattempt_1376685566219_0005_000001 State change from ALLOCATED_SAVING to ALLOCATED
2013-08-16 20:48:26,467 INFO org.apache.hadoop.yarn.server.resourcemanager.amlauncher.AMLauncher: Launching masterappattempt_1376685566219_0005_000001
2013-08-16 20:48:26,470 INFO org.apache.hadoop.yarn.server.resourcemanager.amlauncher.AMLauncher: Setting up container Container: [ContainerId: container_1376685566219_0005_01_000001, NodeId: hadoop-512-5:53603, NodeHttpAddress: hadoop-512-5:8042, Resource: <memory:2048, vCores:1>, Priority: 0, State: NEW, Token: null, Status: container_id {, app_attempt_id {, application_id {, id: 5, cluster_timestamp: 1376685566219, }, attemptId: 1, }, id: 1, }, state: C_NEW, ] for AM appattempt_1376685566219_0005_000001
2013-08-16 20:48:26,470 INFO org.apache.hadoop.yarn.server.resourcemanager.amlauncher.AMLauncher: Command to launch container container_1376685566219_0005_01_000001 : $JAVA_HOME/bin/java -Dlog4j.configuration=container-log4j.properties -Dyarn.app.mapreduce.container.log.dir=<LOG_DIR> -Dyarn.app.mapreduce.container.log.filesize=0 -Dhadoop.root.logger=INFO,CLA  -Xmx1024m org.apache.hadoop.mapreduce.v2.app.MRAppMaster 1><LOG_DIR>/stdout 2><LOG_DIR>/stderr 
2013-08-16 20:48:26,487 INFO org.apache.hadoop.yarn.server.resourcemanager.amlauncher.AMLauncher: Done launching container Container: [ContainerId: container_1376685566219_0005_01_000001, NodeId: hadoop-512-5:53603, NodeHttpAddress: hadoop-512-5:8042, Resource: <memory:2048, vCores:1>, Priority: 0, State: NEW, Token: null, Status: container_id {, app_attempt_id {, application_id {, id: 5, cluster_timestamp: 1376685566219, }, attemptId: 1, }, id: 1, }, state: C_NEW, ] for AM appattempt_1376685566219_0005_000001
2013-08-16 20:48:26,487 INFO org.apache.hadoop.yarn.server.resourcemanager.rmapp.attempt.RMAppAttemptImpl: appattempt_1376685566219_0005_000001 State change from ALLOCATED to LAUNCHED
2013-08-16 20:48:27,465 INFO org.apache.hadoop.yarn.server.resourcemanager.rmcontainer.RMContainerImpl: container_1376685566219_0005_01_000001 Container Transitioned from ACQUIRED to RUNNING
2013-08-16 20:48:33,572 INFO org.apache.hadoop.yarn.server.resourcemanager.ApplicationMasterService: AM registration appattempt_1376685566219_0005_000001
2013-08-16 20:48:33,573 INFO org.apache.hadoop.yarn.server.resourcemanager.RMAuditLogger: USER=ubuntu	IP=192.168.100.17	OPERATION=Register App Master	TARGET=ApplicationMasterService	RESULT=SUCCESS	APPID=application_1376685566219_0005	APPATTEMPTID=appattempt_1376685566219_0005_000001
2013-08-16 20:48:33,574 INFO org.apache.hadoop.yarn.server.resourcemanager.rmapp.attempt.RMAppAttemptImpl: appattempt_1376685566219_0005_000001 State change from LAUNCHED to RUNNING
2013-08-16 20:48:33,578 INFO org.apache.hadoop.yarn.server.resourcemanager.rmapp.RMAppImpl: application_1376685566219_0005 State change from ACCEPTED to RUNNING
2013-08-16 20:48:34,624 INFO org.apache.hadoop.yarn.server.resourcemanager.rmcontainer.RMContainerImpl: container_1376685566219_0005_01_000002 Container Transitioned from NEW to ALLOCATED
2013-08-16 20:48:34,624 INFO org.apache.hadoop.yarn.server.resourcemanager.RMAuditLogger: USER=ubuntu	OPERATION=AM Allocated Container	TARGET=SchedulerApp	RESULT=SUCCESS	APPID=application_1376685566219_0005	CONTAINERID=container_1376685566219_0005_01_000002
2013-08-16 20:48:34,624 INFO org.apache.hadoop.yarn.server.resourcemanager.scheduler.common.fica.FiCaSchedulerNode: Assigned container container_1376685566219_0005_01_000002 of capacity <memory:1024, vCores:1> on host hadoop-512-7:51513, which currently has 1 containers, <memory:1024, vCores:1> used and <memory:7168, vCores:15> available
2013-08-16 20:48:34,626 INFO org.apache.hadoop.yarn.server.resourcemanager.scheduler.capacity.LeafQueue: assignedContainer application=application_1376685566219_0005 container=Container: [ContainerId: container_1376685566219_0005_01_000002, NodeId: hadoop-512-7:51513, NodeHttpAddress: hadoop-512-7:8042, Resource: <memory:1024, vCores:1>, Priority: 20, State: NEW, Token: null, Status: container_id {, app_attempt_id {, application_id {, id: 5, cluster_timestamp: 1376685566219, }, attemptId: 1, }, id: 2, }, state: C_NEW, ] containerId=container_1376685566219_0005_01_000002 queue=default: capacity=1.0, absoluteCapacity=1.0, usedResources=<memory:2048, vCores:1>usedCapacity=0.041666668, absoluteUsedCapacity=0.041666668, numApps=1, numContainers=1 usedCapacity=0.041666668 absoluteUsedCapacity=0.041666668 used=<memory:2048, vCores:1> cluster=<memory:49152, vCores:96>
2013-08-16 20:48:34,626 INFO org.apache.hadoop.yarn.server.resourcemanager.scheduler.capacity.ParentQueue: Re-sorting queues since queue: root.default stats: default: capacity=1.0, absoluteCapacity=1.0, usedResources=<memory:3072, vCores:2>usedCapacity=0.0625, absoluteUsedCapacity=0.0625, numApps=1, numContainers=2
2013-08-16 20:48:34,626 INFO org.apache.hadoop.yarn.server.resourcemanager.scheduler.capacity.ParentQueue: assignedContainer queue=root usedCapacity=0.0625 absoluteUsedCapacity=0.0625 used=<memory:3072, vCores:2> cluster=<memory:49152, vCores:96>
2013-08-16 20:48:34,718 INFO org.apache.hadoop.yarn.server.resourcemanager.rmcontainer.RMContainerImpl: container_1376685566219_0005_01_000003 Container Transitioned from NEW to ALLOCATED
2013-08-16 20:48:34,719 INFO org.apache.hadoop.yarn.server.resourcemanager.RMAuditLogger: USER=ubuntu	OPERATION=AM Allocated Container	TARGET=SchedulerApp	RESULT=SUCCESS	APPID=application_1376685566219_0005	CONTAINERID=container_1376685566219_0005_01_000003
2013-08-16 20:48:34,719 INFO org.apache.hadoop.yarn.server.resourcemanager.scheduler.common.fica.FiCaSchedulerNode: Assigned container container_1376685566219_0005_01_000003 of capacity <memory:1024, vCores:1> on host hadoop-512-6:40600, which currently has 1 containers, <memory:1024, vCores:1> used and <memory:7168, vCores:15> available
2013-08-16 20:48:34,720 INFO org.apache.hadoop.yarn.server.resourcemanager.scheduler.capacity.LeafQueue: assignedContainer application=application_1376685566219_0005 container=Container: [ContainerId: container_1376685566219_0005_01_000003, NodeId: hadoop-512-6:40600, NodeHttpAddress: hadoop-512-6:8042, Resource: <memory:1024, vCores:1>, Priority: 20, State: NEW, Token: null, Status: container_id {, app_attempt_id {, application_id {, id: 5, cluster_timestamp: 1376685566219, }, attemptId: 1, }, id: 3, }, state: C_NEW, ] containerId=container_1376685566219_0005_01_000003 queue=default: capacity=1.0, absoluteCapacity=1.0, usedResources=<memory:3072, vCores:2>usedCapacity=0.0625, absoluteUsedCapacity=0.0625, numApps=1, numContainers=2 usedCapacity=0.0625 absoluteUsedCapacity=0.0625 used=<memory:3072, vCores:2> cluster=<memory:49152, vCores:96>
2013-08-16 20:48:34,720 INFO org.apache.hadoop.yarn.server.resourcemanager.scheduler.capacity.ParentQueue: Re-sorting queues since queue: root.default stats: default: capacity=1.0, absoluteCapacity=1.0, usedResources=<memory:4096, vCores:3>usedCapacity=0.083333336, absoluteUsedCapacity=0.083333336, numApps=1, numContainers=3
2013-08-16 20:48:34,720 INFO org.apache.hadoop.yarn.server.resourcemanager.scheduler.capacity.ParentQueue: assignedContainer queue=root usedCapacity=0.083333336 absoluteUsedCapacity=0.083333336 used=<memory:4096, vCores:3> cluster=<memory:49152, vCores:96>
2013-08-16 20:48:35,644 INFO org.apache.hadoop.yarn.server.resourcemanager.rmcontainer.RMContainerImpl: container_1376685566219_0005_01_000002 Container Transitioned from ALLOCATED to ACQUIRED
2013-08-16 20:48:35,647 INFO org.apache.hadoop.yarn.server.resourcemanager.rmcontainer.RMContainerImpl: container_1376685566219_0005_01_000003 Container Transitioned from ALLOCATED to ACQUIRED
2013-08-16 20:48:36,634 INFO org.apache.hadoop.yarn.server.resourcemanager.rmcontainer.RMContainerImpl: container_1376685566219_0005_01_000002 Container Transitioned from ACQUIRED to RUNNING
2013-08-16 20:48:36,683 INFO org.apache.hadoop.yarn.server.resourcemanager.scheduler.AppSchedulingInfo: checking for deactivate... 
2013-08-16 20:48:37,756 INFO org.apache.hadoop.yarn.server.resourcemanager.rmcontainer.RMContainerImpl: container_1376685566219_0005_01_000003 Container Transitioned from ACQUIRED to RUNNING
2013-08-16 20:50:17,331 INFO org.apache.hadoop.yarn.server.resourcemanager.rmcontainer.RMContainerImpl: container_1376685566219_0005_01_000002 Container Transitioned from RUNNING to COMPLETED
2013-08-16 20:50:17,332 INFO org.apache.hadoop.yarn.server.resourcemanager.scheduler.common.fica.FiCaSchedulerApp: Completed container: container_1376685566219_0005_01_000002 in state: COMPLETED event:FINISHED
2013-08-16 20:50:17,332 INFO org.apache.hadoop.yarn.server.resourcemanager.RMAuditLogger: USER=ubuntu	OPERATION=AM Released Container	TARGET=SchedulerApp	RESULT=SUCCESS	APPID=application_1376685566219_0005	CONTAINERID=container_1376685566219_0005_01_000002
2013-08-16 20:50:17,332 INFO org.apache.hadoop.yarn.server.resourcemanager.scheduler.common.fica.FiCaSchedulerNode: Released container container_1376685566219_0005_01_000002 of capacity <memory:1024, vCores:1> on host hadoop-512-7:51513, which currently has 0 containers, <memory:0, vCores:0> used and <memory:8192, vCores:16> available, release resources=true
2013-08-16 20:50:17,332 INFO org.apache.hadoop.yarn.server.resourcemanager.scheduler.capacity.LeafQueue: default used=<memory:3072, vCores:2> numContainers=2 user=ubuntu user-resources=<memory:3072, vCores:2>
2013-08-16 20:50:17,334 INFO org.apache.hadoop.yarn.server.resourcemanager.scheduler.capacity.LeafQueue: completedContainer container=Container: [ContainerId: container_1376685566219_0005_01_000002, NodeId: hadoop-512-7:51513, NodeHttpAddress: hadoop-512-7:8042, Resource: <memory:1024, vCores:1>, Priority: 20, State: NEW, Token: null, Status: container_id {, app_attempt_id {, application_id {, id: 5, cluster_timestamp: 1376685566219, }, attemptId: 1, }, id: 2, }, state: C_COMPLETE, diagnostics: "Container killed by the ApplicationMaster.\n", exit_status: 0, ] resource=<memory:1024, vCores:1> queue=default: capacity=1.0, absoluteCapacity=1.0, usedResources=<memory:3072, vCores:2>usedCapacity=0.0625, absoluteUsedCapacity=0.0625, numApps=1, numContainers=2 usedCapacity=0.0625 absoluteUsedCapacity=0.0625 used=<memory:3072, vCores:2> cluster=<memory:49152, vCores:96>
2013-08-16 20:50:17,334 INFO org.apache.hadoop.yarn.server.resourcemanager.scheduler.capacity.ParentQueue: completedContainer queue=root usedCapacity=0.0625 absoluteUsedCapacity=0.0625 used=<memory:3072, vCores:2> cluster=<memory:49152, vCores:96>
2013-08-16 20:50:17,335 INFO org.apache.hadoop.yarn.server.resourcemanager.scheduler.capacity.CapacityScheduler: Application appattempt_1376685566219_0005_000001 released container container_1376685566219_0005_01_000002 on node: host: hadoop-512-7:51513 #containers=0 available=8192 used=0 with event: FINISHED
2013-08-16 20:50:33,530 INFO org.apache.hadoop.yarn.server.resourcemanager.rmcontainer.RMContainerImpl: container_1376685566219_0005_01_000003 Container Transitioned from RUNNING to COMPLETED
2013-08-16 20:50:33,530 INFO org.apache.hadoop.yarn.server.resourcemanager.scheduler.common.fica.FiCaSchedulerApp: Completed container: container_1376685566219_0005_01_000003 in state: COMPLETED event:FINISHED
2013-08-16 20:50:33,530 INFO org.apache.hadoop.yarn.server.resourcemanager.RMAuditLogger: USER=ubuntu	OPERATION=AM Released Container	TARGET=SchedulerApp	RESULT=SUCCESS	APPID=application_1376685566219_0005	CONTAINERID=container_1376685566219_0005_01_000003
2013-08-16 20:50:33,530 INFO org.apache.hadoop.yarn.server.resourcemanager.scheduler.common.fica.FiCaSchedulerNode: Released container container_1376685566219_0005_01_000003 of capacity <memory:1024, vCores:1> on host hadoop-512-6:40600, which currently has 0 containers, <memory:0, vCores:0> used and <memory:8192, vCores:16> available, release resources=true
2013-08-16 20:50:33,530 INFO org.apache.hadoop.yarn.server.resourcemanager.scheduler.capacity.LeafQueue: default used=<memory:2048, vCores:1> numContainers=1 user=ubuntu user-resources=<memory:2048, vCores:1>
2013-08-16 20:50:33,532 INFO org.apache.hadoop.yarn.server.resourcemanager.scheduler.capacity.LeafQueue: completedContainer container=Container: [ContainerId: container_1376685566219_0005_01_000003, NodeId: hadoop-512-6:40600, NodeHttpAddress: hadoop-512-6:8042, Resource: <memory:1024, vCores:1>, Priority: 20, State: NEW, Token: null, Status: container_id {, app_attempt_id {, application_id {, id: 5, cluster_timestamp: 1376685566219, }, attemptId: 1, }, id: 3, }, state: C_COMPLETE, diagnostics: "Container killed by the ApplicationMaster.\n\n", exit_status: 143, ] resource=<memory:1024, vCores:1> queue=default: capacity=1.0, absoluteCapacity=1.0, usedResources=<memory:2048, vCores:1>usedCapacity=0.041666668, absoluteUsedCapacity=0.041666668, numApps=1, numContainers=1 usedCapacity=0.041666668 absoluteUsedCapacity=0.041666668 used=<memory:2048, vCores:1> cluster=<memory:49152, vCores:96>
2013-08-16 20:50:33,532 INFO org.apache.hadoop.yarn.server.resourcemanager.scheduler.capacity.ParentQueue: completedContainer queue=root usedCapacity=0.041666668 absoluteUsedCapacity=0.041666668 used=<memory:2048, vCores:1> cluster=<memory:49152, vCores:96>
2013-08-16 20:50:33,532 INFO org.apache.hadoop.yarn.server.resourcemanager.scheduler.capacity.CapacityScheduler: Application appattempt_1376685566219_0005_000001 released container container_1376685566219_0005_01_000003 on node: host: hadoop-512-6:40600 #containers=0 available=8192 used=0 with event: FINISHED
2013-08-16 20:50:36,673 INFO org.apache.hadoop.yarn.server.resourcemanager.rmapp.attempt.RMAppAttemptImpl: appattempt_1376685566219_0005_000001 State change from RUNNING to FINISHING
2013-08-16 20:50:36,675 INFO org.apache.hadoop.yarn.server.resourcemanager.rmapp.RMAppImpl: application_1376685566219_0005 State change from RUNNING to FINISHING
2013-08-16 20:50:37,093 INFO org.apache.hadoop.yarn.server.resourcemanager.rmcontainer.RMContainerImpl: container_1376685566219_0005_01_000001 Container Transitioned from RUNNING to COMPLETED
2013-08-16 20:50:37,094 INFO org.apache.hadoop.yarn.server.resourcemanager.scheduler.common.fica.FiCaSchedulerApp: Completed container: container_1376685566219_0005_01_000001 in state: COMPLETED event:FINISHED
2013-08-16 20:50:37,094 INFO org.apache.hadoop.yarn.server.resourcemanager.RMAuditLogger: USER=ubuntu	OPERATION=AM Released Container	TARGET=SchedulerApp	RESULT=SUCCESS	APPID=application_1376685566219_0005	CONTAINERID=container_1376685566219_0005_01_000001
2013-08-16 20:50:37,094 INFO org.apache.hadoop.yarn.server.resourcemanager.scheduler.common.fica.FiCaSchedulerNode: Released container container_1376685566219_0005_01_000001 of capacity <memory:2048, vCores:1> on host hadoop-512-5:53603, which currently has 0 containers, <memory:0, vCores:0> used and <memory:8192, vCores:16> available, release resources=true
2013-08-16 20:50:37,094 INFO org.apache.hadoop.yarn.server.resourcemanager.scheduler.capacity.LeafQueue: default used=<memory:0, vCores:0> numContainers=0 user=ubuntu user-resources=<memory:0, vCores:0>
2013-08-16 20:50:37,096 INFO org.apache.hadoop.yarn.server.resourcemanager.scheduler.capacity.LeafQueue: completedContainer container=Container: [ContainerId: container_1376685566219_0005_01_000001, NodeId: hadoop-512-5:53603, NodeHttpAddress: hadoop-512-5:8042, Resource: <memory:2048, vCores:1>, Priority: 0, State: NEW, Token: null, Status: container_id {, app_attempt_id {, application_id {, id: 5, cluster_timestamp: 1376685566219, }, attemptId: 1, }, id: 1, }, state: C_COMPLETE, diagnostics: "", exit_status: 0, ] resource=<memory:2048, vCores:1> queue=default: capacity=1.0, absoluteCapacity=1.0, usedResources=<memory:0, vCores:0>usedCapacity=0.0, absoluteUsedCapacity=0.0, numApps=1, numContainers=0 usedCapacity=0.0 absoluteUsedCapacity=0.0 used=<memory:0, vCores:0> cluster=<memory:49152, vCores:96>
2013-08-16 20:50:37,096 INFO org.apache.hadoop.yarn.server.resourcemanager.scheduler.capacity.ParentQueue: completedContainer queue=root usedCapacity=0.0 absoluteUsedCapacity=0.0 used=<memory:0, vCores:0> cluster=<memory:49152, vCores:96>
2013-08-16 20:50:37,096 INFO org.apache.hadoop.yarn.server.resourcemanager.scheduler.capacity.CapacityScheduler: Application appattempt_1376685566219_0005_000001 released container container_1376685566219_0005_01_000001 on node: host: hadoop-512-5:53603 #containers=0 available=8192 used=0 with event: FINISHED
2013-08-16 20:50:37,096 INFO org.apache.hadoop.yarn.server.resourcemanager.rmapp.attempt.RMAppAttemptImpl: appattempt_1376685566219_0005_000001 State change from FINISHING to FINISHED
2013-08-16 20:50:37,097 INFO org.apache.hadoop.yarn.server.resourcemanager.rmapp.RMAppImpl: application_1376685566219_0005 State change from FINISHING to FINISHED
2013-08-16 20:50:37,097 INFO org.apache.hadoop.yarn.server.resourcemanager.scheduler.capacity.CapacityScheduler: Application appattempt_1376685566219_0005_000001 is done. finalState=FINISHED
2013-08-16 20:50:37,097 INFO org.apache.hadoop.yarn.server.resourcemanager.scheduler.AppSchedulingInfo: Application application_1376685566219_0005 requests cleared
2013-08-16 20:50:37,098 INFO org.apache.hadoop.yarn.server.resourcemanager.scheduler.capacity.LeafQueue: Application removed - appId: application_1376685566219_0005 user: ubuntu queue: default #user-pending-applications: 0 #user-active-applications: 0 #queue-pending-applications: 0 #queue-active-applications: 0
2013-08-16 20:50:37,098 INFO org.apache.hadoop.yarn.server.resourcemanager.scheduler.capacity.ParentQueue: Application removed - appId: application_1376685566219_0005 user: ubuntu leaf-queue of parent: root #applications: 0
2013-08-16 20:50:37,098 INFO org.apache.hadoop.yarn.server.resourcemanager.RMAuditLogger: USER=ubuntu	OPERATION=Application Finished - Succeeded	TARGET=RMAppManager	RESULT=SUCCESS	APPID=application_1376685566219_0005
2013-08-16 20:50:37,098 INFO org.apache.hadoop.yarn.server.resourcemanager.recovery.RMStateStore: Removing info for app: application_1376685566219_0005
2013-08-16 20:50:37,098 INFO org.apache.hadoop.yarn.server.resourcemanager.RMAppManager$ApplicationSummary: appId=application_1376685566219_0005,name=TeraGen,user=ubuntu,queue=default,state=FINISHED,trackingUrl=hadoop-512-1.novalocal:8088/proxy/application_1376685566219_0005/jobhistory/job/job_1376685566219_0005,appMasterHost=hadoop-512-5,startTime=1376686106285,finishTime=1376686236674
2013-08-16 20:50:37,099 INFO org.apache.hadoop.yarn.server.resourcemanager.amlauncher.AMLauncher: Cleaning master appattempt_1376685566219_0005_000001
2013-08-16 20:51:21,712 INFO org.apache.hadoop.yarn.server.resourcemanager.ClientRMService: Allocated new applicationId: 6
2013-08-16 20:51:21,839 INFO org.apache.hadoop.yarn.server.resourcemanager.ClientRMService: Allocated new applicationId: 7
2013-08-16 20:51:21,850 INFO org.apache.hadoop.yarn.server.resourcemanager.ClientRMService: Allocated new applicationId: 8
2013-08-16 20:51:22,151 INFO org.apache.hadoop.yarn.server.resourcemanager.ClientRMService: Allocated new applicationId: 9
2013-08-16 20:51:22,833 INFO org.apache.hadoop.yarn.server.resourcemanager.ClientRMService: Allocated new applicationId: 10
2013-08-16 20:51:23,159 INFO org.apache.hadoop.yarn.server.resourcemanager.ClientRMService: Storing Application with id application_1376685566219_0006
2013-08-16 20:51:23,159 INFO org.apache.hadoop.yarn.server.resourcemanager.recovery.RMStateStore: Storing info for app: application_1376685566219_0006
2013-08-16 20:51:23,159 INFO org.apache.hadoop.yarn.server.resourcemanager.ClientRMService: Application with id 6 submitted by user ubuntu
2013-08-16 20:51:23,159 INFO org.apache.hadoop.yarn.server.resourcemanager.RMAuditLogger: USER=ubuntu	IP=192.168.100.6	OPERATION=Submit Application Request	TARGET=ClientRMService	RESULT=SUCCESS	APPID=application_1376685566219_0006
2013-08-16 20:51:23,166 INFO org.apache.hadoop.yarn.server.resourcemanager.rmapp.RMAppImpl: application_1376685566219_0006 State change from NEW to SUBMITTED
2013-08-16 20:51:23,167 INFO org.apache.hadoop.yarn.server.resourcemanager.ApplicationMasterService: Registering appattempt_1376685566219_0006_000001
2013-08-16 20:51:23,167 INFO org.apache.hadoop.yarn.server.resourcemanager.rmapp.attempt.RMAppAttemptImpl: appattempt_1376685566219_0006_000001 State change from NEW to SUBMITTED
2013-08-16 20:51:23,167 INFO org.apache.hadoop.yarn.server.resourcemanager.scheduler.capacity.LeafQueue: Application application_1376685566219_0006 from user: ubuntu activated in queue: default
2013-08-16 20:51:23,167 INFO org.apache.hadoop.yarn.server.resourcemanager.scheduler.capacity.LeafQueue: Application added - appId: application_1376685566219_0006 user: org.apache.hadoop.yarn.server.resourcemanager.scheduler.capacity.LeafQueue$User@d4569d3, leaf-queue: default #user-pending-applications: 0 #user-active-applications: 1 #queue-pending-applications: 0 #queue-active-applications: 1
2013-08-16 20:51:23,167 INFO org.apache.hadoop.yarn.server.resourcemanager.scheduler.capacity.ParentQueue: Application added - appId: application_1376685566219_0006 user: ubuntu leaf-queue of parent: root #applications: 1
2013-08-16 20:51:23,167 INFO org.apache.hadoop.yarn.server.resourcemanager.scheduler.capacity.CapacityScheduler: Application Submission: appattempt_1376685566219_0006_000001, user: ubuntu queue: default: capacity=1.0, absoluteCapacity=1.0, usedResources=<memory:0, vCores:0>usedCapacity=0.0, absoluteUsedCapacity=0.0, numApps=1, numContainers=0, currently active: 1
2013-08-16 20:51:23,167 INFO org.apache.hadoop.yarn.server.resourcemanager.rmapp.attempt.RMAppAttemptImpl: appattempt_1376685566219_0006_000001 State change from SUBMITTED to SCHEDULED
2013-08-16 20:51:23,168 INFO org.apache.hadoop.yarn.server.resourcemanager.rmapp.RMAppImpl: application_1376685566219_0006 State change from SUBMITTED to ACCEPTED
2013-08-16 20:51:23,233 INFO org.apache.hadoop.yarn.server.resourcemanager.rmcontainer.RMContainerImpl: container_1376685566219_0006_01_000001 Container Transitioned from NEW to ALLOCATED
2013-08-16 20:51:23,233 INFO org.apache.hadoop.yarn.server.resourcemanager.RMAuditLogger: USER=ubuntu	OPERATION=AM Allocated Container	TARGET=SchedulerApp	RESULT=SUCCESS	APPID=application_1376685566219_0006	CONTAINERID=container_1376685566219_0006_01_000001
2013-08-16 20:51:23,233 INFO org.apache.hadoop.yarn.server.resourcemanager.scheduler.common.fica.FiCaSchedulerNode: Assigned container container_1376685566219_0006_01_000001 of capacity <memory:2048, vCores:1> on host hadoop-512-5:53603, which currently has 1 containers, <memory:2048, vCores:1> used and <memory:6144, vCores:15> available
2013-08-16 20:51:23,234 INFO org.apache.hadoop.yarn.server.resourcemanager.scheduler.capacity.LeafQueue: assignedContainer application=application_1376685566219_0006 container=Container: [ContainerId: container_1376685566219_0006_01_000001, NodeId: hadoop-512-5:53603, NodeHttpAddress: hadoop-512-5:8042, Resource: <memory:2048, vCores:1>, Priority: 0, State: NEW, Token: null, Status: container_id {, app_attempt_id {, application_id {, id: 6, cluster_timestamp: 1376685566219, }, attemptId: 1, }, id: 1, }, state: C_NEW, ] containerId=container_1376685566219_0006_01_000001 queue=default: capacity=1.0, absoluteCapacity=1.0, usedResources=<memory:0, vCores:0>usedCapacity=0.0, absoluteUsedCapacity=0.0, numApps=1, numContainers=0 usedCapacity=0.0 absoluteUsedCapacity=0.0 used=<memory:0, vCores:0> cluster=<memory:49152, vCores:96>
2013-08-16 20:51:23,234 INFO org.apache.hadoop.yarn.server.resourcemanager.scheduler.capacity.ParentQueue: Re-sorting queues since queue: root.default stats: default: capacity=1.0, absoluteCapacity=1.0, usedResources=<memory:2048, vCores:1>usedCapacity=0.041666668, absoluteUsedCapacity=0.041666668, numApps=1, numContainers=1
2013-08-16 20:51:23,234 INFO org.apache.hadoop.yarn.server.resourcemanager.scheduler.capacity.ParentQueue: assignedContainer queue=root usedCapacity=0.041666668 absoluteUsedCapacity=0.041666668 used=<memory:2048, vCores:1> cluster=<memory:49152, vCores:96>
2013-08-16 20:51:23,238 INFO org.apache.hadoop.yarn.server.resourcemanager.rmcontainer.RMContainerImpl: container_1376685566219_0006_01_000001 Container Transitioned from ALLOCATED to ACQUIRED
2013-08-16 20:51:23,239 INFO org.apache.hadoop.yarn.server.resourcemanager.rmapp.attempt.RMAppAttemptImpl: Storing attempt: AppId: application_1376685566219_0006 AttemptId: appattempt_1376685566219_0006_000001 MasterContainer: Container: [ContainerId: container_1376685566219_0006_01_000001, NodeId: hadoop-512-5:53603, NodeHttpAddress: hadoop-512-5:8042, Resource: <memory:2048, vCores:1>, Priority: 0, State: NEW, Token: null, Status: container_id {, app_attempt_id {, application_id {, id: 6, cluster_timestamp: 1376685566219, }, attemptId: 1, }, id: 1, }, state: C_NEW, ]
2013-08-16 20:51:23,239 INFO org.apache.hadoop.yarn.server.resourcemanager.rmapp.attempt.RMAppAttemptImpl: appattempt_1376685566219_0006_000001 State change from SCHEDULED to ALLOCATED_SAVING
2013-08-16 20:51:23,239 INFO org.apache.hadoop.yarn.server.resourcemanager.recovery.RMStateStore: Storing info for attempt: appattempt_1376685566219_0006_000001
2013-08-16 20:51:23,243 INFO org.apache.hadoop.yarn.server.resourcemanager.rmapp.attempt.RMAppAttemptImpl: appattempt_1376685566219_0006_000001 State change from ALLOCATED_SAVING to ALLOCATED
2013-08-16 20:51:23,244 INFO org.apache.hadoop.yarn.server.resourcemanager.amlauncher.AMLauncher: Launching masterappattempt_1376685566219_0006_000001
2013-08-16 20:51:23,245 INFO org.apache.hadoop.yarn.server.resourcemanager.amlauncher.AMLauncher: Setting up container Container: [ContainerId: container_1376685566219_0006_01_000001, NodeId: hadoop-512-5:53603, NodeHttpAddress: hadoop-512-5:8042, Resource: <memory:2048, vCores:1>, Priority: 0, State: NEW, Token: null, Status: container_id {, app_attempt_id {, application_id {, id: 6, cluster_timestamp: 1376685566219, }, attemptId: 1, }, id: 1, }, state: C_NEW, ] for AM appattempt_1376685566219_0006_000001
2013-08-16 20:51:23,246 INFO org.apache.hadoop.yarn.server.resourcemanager.amlauncher.AMLauncher: Command to launch container container_1376685566219_0006_01_000001 : $JAVA_HOME/bin/java -Dlog4j.configuration=container-log4j.properties -Dyarn.app.mapreduce.container.log.dir=<LOG_DIR> -Dyarn.app.mapreduce.container.log.filesize=0 -Dhadoop.root.logger=INFO,CLA  -Xmx1024m org.apache.hadoop.mapreduce.v2.app.MRAppMaster 1><LOG_DIR>/stdout 2><LOG_DIR>/stderr 
2013-08-16 20:51:23,269 INFO org.apache.hadoop.yarn.server.resourcemanager.amlauncher.AMLauncher: Done launching container Container: [ContainerId: container_1376685566219_0006_01_000001, NodeId: hadoop-512-5:53603, NodeHttpAddress: hadoop-512-5:8042, Resource: <memory:2048, vCores:1>, Priority: 0, State: NEW, Token: null, Status: container_id {, app_attempt_id {, application_id {, id: 6, cluster_timestamp: 1376685566219, }, attemptId: 1, }, id: 1, }, state: C_NEW, ] for AM appattempt_1376685566219_0006_000001
2013-08-16 20:51:23,269 INFO org.apache.hadoop.yarn.server.resourcemanager.rmapp.attempt.RMAppAttemptImpl: appattempt_1376685566219_0006_000001 State change from ALLOCATED to LAUNCHED
2013-08-16 20:51:23,393 INFO org.apache.hadoop.yarn.server.resourcemanager.ClientRMService: Storing Application with id application_1376685566219_0007
2013-08-16 20:51:23,394 INFO org.apache.hadoop.yarn.server.resourcemanager.recovery.RMStateStore: Storing info for app: application_1376685566219_0007
2013-08-16 20:51:23,394 INFO org.apache.hadoop.yarn.server.resourcemanager.ClientRMService: Application with id 7 submitted by user ubuntu
2013-08-16 20:51:23,394 INFO org.apache.hadoop.yarn.server.resourcemanager.RMAuditLogger: USER=ubuntu	IP=192.168.100.6	OPERATION=Submit Application Request	TARGET=ClientRMService	RESULT=SUCCESS	APPID=application_1376685566219_0007
2013-08-16 20:51:23,395 INFO org.apache.hadoop.yarn.server.resourcemanager.rmapp.RMAppImpl: application_1376685566219_0007 State change from NEW to SUBMITTED
2013-08-16 20:51:23,395 INFO org.apache.hadoop.yarn.server.resourcemanager.ApplicationMasterService: Registering appattempt_1376685566219_0007_000001
2013-08-16 20:51:23,395 INFO org.apache.hadoop.yarn.server.resourcemanager.rmapp.attempt.RMAppAttemptImpl: appattempt_1376685566219_0007_000001 State change from NEW to SUBMITTED
2013-08-16 20:51:23,396 INFO org.apache.hadoop.yarn.server.resourcemanager.scheduler.capacity.LeafQueue: Application application_1376685566219_0007 from user: ubuntu activated in queue: default
2013-08-16 20:51:23,396 INFO org.apache.hadoop.yarn.server.resourcemanager.scheduler.capacity.LeafQueue: Application added - appId: application_1376685566219_0007 user: org.apache.hadoop.yarn.server.resourcemanager.scheduler.capacity.LeafQueue$User@d4569d3, leaf-queue: default #user-pending-applications: 0 #user-active-applications: 2 #queue-pending-applications: 0 #queue-active-applications: 2
2013-08-16 20:51:23,396 INFO org.apache.hadoop.yarn.server.resourcemanager.scheduler.capacity.ParentQueue: Application added - appId: application_1376685566219_0007 user: ubuntu leaf-queue of parent: root #applications: 2
2013-08-16 20:51:23,396 INFO org.apache.hadoop.yarn.server.resourcemanager.scheduler.capacity.CapacityScheduler: Application Submission: appattempt_1376685566219_0007_000001, user: ubuntu queue: default: capacity=1.0, absoluteCapacity=1.0, usedResources=<memory:2048, vCores:1>usedCapacity=0.041666668, absoluteUsedCapacity=0.041666668, numApps=2, numContainers=1, currently active: 2
2013-08-16 20:51:23,396 INFO org.apache.hadoop.yarn.server.resourcemanager.rmapp.attempt.RMAppAttemptImpl: appattempt_1376685566219_0007_000001 State change from SUBMITTED to SCHEDULED
2013-08-16 20:51:23,396 INFO org.apache.hadoop.yarn.server.resourcemanager.rmapp.RMAppImpl: application_1376685566219_0007 State change from SUBMITTED to ACCEPTED
2013-08-16 20:51:23,397 INFO org.apache.hadoop.yarn.server.resourcemanager.ClientRMService: Storing Application with id application_1376685566219_0008
2013-08-16 20:51:23,397 INFO org.apache.hadoop.yarn.server.resourcemanager.recovery.RMStateStore: Storing info for app: application_1376685566219_0008
2013-08-16 20:51:23,397 INFO org.apache.hadoop.yarn.server.resourcemanager.ClientRMService: Application with id 8 submitted by user ubuntu
2013-08-16 20:51:23,397 INFO org.apache.hadoop.yarn.server.resourcemanager.RMAuditLogger: USER=ubuntu	IP=192.168.100.6	OPERATION=Submit Application Request	TARGET=ClientRMService	RESULT=SUCCESS	APPID=application_1376685566219_0008
2013-08-16 20:51:23,397 INFO org.apache.hadoop.yarn.server.resourcemanager.rmapp.RMAppImpl: application_1376685566219_0008 State change from NEW to SUBMITTED
2013-08-16 20:51:23,397 INFO org.apache.hadoop.yarn.server.resourcemanager.ApplicationMasterService: Registering appattempt_1376685566219_0008_000001
2013-08-16 20:51:23,398 INFO org.apache.hadoop.yarn.server.resourcemanager.rmapp.attempt.RMAppAttemptImpl: appattempt_1376685566219_0008_000001 State change from NEW to SUBMITTED
2013-08-16 20:51:23,398 INFO org.apache.hadoop.yarn.server.resourcemanager.scheduler.capacity.LeafQueue: Application application_1376685566219_0008 from user: ubuntu activated in queue: default
2013-08-16 20:51:23,398 INFO org.apache.hadoop.yarn.server.resourcemanager.scheduler.capacity.LeafQueue: Application added - appId: application_1376685566219_0008 user: org.apache.hadoop.yarn.server.resourcemanager.scheduler.capacity.LeafQueue$User@d4569d3, leaf-queue: default #user-pending-applications: 0 #user-active-applications: 3 #queue-pending-applications: 0 #queue-active-applications: 3
2013-08-16 20:51:23,398 INFO org.apache.hadoop.yarn.server.resourcemanager.scheduler.capacity.ParentQueue: Application added - appId: application_1376685566219_0008 user: ubuntu leaf-queue of parent: root #applications: 3
2013-08-16 20:51:23,398 INFO org.apache.hadoop.yarn.server.resourcemanager.scheduler.capacity.CapacityScheduler: Application Submission: appattempt_1376685566219_0008_000001, user: ubuntu queue: default: capacity=1.0, absoluteCapacity=1.0, usedResources=<memory:2048, vCores:1>usedCapacity=0.041666668, absoluteUsedCapacity=0.041666668, numApps=3, numContainers=1, currently active: 3
2013-08-16 20:51:23,398 INFO org.apache.hadoop.yarn.server.resourcemanager.rmapp.attempt.RMAppAttemptImpl: appattempt_1376685566219_0008_000001 State change from SUBMITTED to SCHEDULED
2013-08-16 20:51:23,398 INFO org.apache.hadoop.yarn.server.resourcemanager.rmapp.RMAppImpl: application_1376685566219_0008 State change from SUBMITTED to ACCEPTED
2013-08-16 20:51:23,508 INFO org.apache.hadoop.yarn.server.resourcemanager.ClientRMService: Storing Application with id application_1376685566219_0009
2013-08-16 20:51:23,508 INFO org.apache.hadoop.yarn.server.resourcemanager.recovery.RMStateStore: Storing info for app: application_1376685566219_0009
2013-08-16 20:51:23,508 INFO org.apache.hadoop.yarn.server.resourcemanager.ClientRMService: Application with id 9 submitted by user ubuntu
2013-08-16 20:51:23,508 INFO org.apache.hadoop.yarn.server.resourcemanager.RMAuditLogger: USER=ubuntu	IP=192.168.100.6	OPERATION=Submit Application Request	TARGET=ClientRMService	RESULT=SUCCESS	APPID=application_1376685566219_0009
2013-08-16 20:51:23,508 INFO org.apache.hadoop.yarn.server.resourcemanager.rmapp.RMAppImpl: application_1376685566219_0009 State change from NEW to SUBMITTED
2013-08-16 20:51:23,509 INFO org.apache.hadoop.yarn.server.resourcemanager.ApplicationMasterService: Registering appattempt_1376685566219_0009_000001
2013-08-16 20:51:23,509 INFO org.apache.hadoop.yarn.server.resourcemanager.rmapp.attempt.RMAppAttemptImpl: appattempt_1376685566219_0009_000001 State change from NEW to SUBMITTED
2013-08-16 20:51:23,510 INFO org.apache.hadoop.yarn.server.resourcemanager.scheduler.capacity.LeafQueue: Application application_1376685566219_0009 from user: ubuntu activated in queue: default
2013-08-16 20:51:23,510 INFO org.apache.hadoop.yarn.server.resourcemanager.scheduler.capacity.LeafQueue: Application added - appId: application_1376685566219_0009 user: org.apache.hadoop.yarn.server.resourcemanager.scheduler.capacity.LeafQueue$User@d4569d3, leaf-queue: default #user-pending-applications: 0 #user-active-applications: 4 #queue-pending-applications: 0 #queue-active-applications: 4
2013-08-16 20:51:23,510 INFO org.apache.hadoop.yarn.server.resourcemanager.scheduler.capacity.ParentQueue: Application added - appId: application_1376685566219_0009 user: ubuntu leaf-queue of parent: root #applications: 4
2013-08-16 20:51:23,510 INFO org.apache.hadoop.yarn.server.resourcemanager.scheduler.capacity.CapacityScheduler: Application Submission: appattempt_1376685566219_0009_000001, user: ubuntu queue: default: capacity=1.0, absoluteCapacity=1.0, usedResources=<memory:2048, vCores:1>usedCapacity=0.041666668, absoluteUsedCapacity=0.041666668, numApps=4, numContainers=1, currently active: 4
2013-08-16 20:51:23,510 INFO org.apache.hadoop.yarn.server.resourcemanager.rmapp.attempt.RMAppAttemptImpl: appattempt_1376685566219_0009_000001 State change from SUBMITTED to SCHEDULED
2013-08-16 20:51:23,510 INFO org.apache.hadoop.yarn.server.resourcemanager.rmapp.RMAppImpl: application_1376685566219_0009 State change from SUBMITTED to ACCEPTED
2013-08-16 20:51:23,543 INFO org.apache.hadoop.yarn.server.resourcemanager.rmcontainer.RMContainerImpl: container_1376685566219_0007_01_000001 Container Transitioned from NEW to ALLOCATED
2013-08-16 20:51:23,543 INFO org.apache.hadoop.yarn.server.resourcemanager.RMAuditLogger: USER=ubuntu	OPERATION=AM Allocated Container	TARGET=SchedulerApp	RESULT=SUCCESS	APPID=application_1376685566219_0007	CONTAINERID=container_1376685566219_0007_01_000001
2013-08-16 20:51:23,543 INFO org.apache.hadoop.yarn.server.resourcemanager.scheduler.common.fica.FiCaSchedulerNode: Assigned container container_1376685566219_0007_01_000001 of capacity <memory:2048, vCores:1> on host hadoop-512-7:51513, which currently has 1 containers, <memory:2048, vCores:1> used and <memory:6144, vCores:15> available
2013-08-16 20:51:23,544 INFO org.apache.hadoop.yarn.server.resourcemanager.scheduler.capacity.LeafQueue: assignedContainer application=application_1376685566219_0007 container=Container: [ContainerId: container_1376685566219_0007_01_000001, NodeId: hadoop-512-7:51513, NodeHttpAddress: hadoop-512-7:8042, Resource: <memory:2048, vCores:1>, Priority: 0, State: NEW, Token: null, Status: container_id {, app_attempt_id {, application_id {, id: 7, cluster_timestamp: 1376685566219, }, attemptId: 1, }, id: 1, }, state: C_NEW, ] containerId=container_1376685566219_0007_01_000001 queue=default: capacity=1.0, absoluteCapacity=1.0, usedResources=<memory:2048, vCores:1>usedCapacity=0.041666668, absoluteUsedCapacity=0.041666668, numApps=4, numContainers=1 usedCapacity=0.041666668 absoluteUsedCapacity=0.041666668 used=<memory:2048, vCores:1> cluster=<memory:49152, vCores:96>
2013-08-16 20:51:23,544 INFO org.apache.hadoop.yarn.server.resourcemanager.scheduler.capacity.ParentQueue: Re-sorting queues since queue: root.default stats: default: capacity=1.0, absoluteCapacity=1.0, usedResources=<memory:4096, vCores:2>usedCapacity=0.083333336, absoluteUsedCapacity=0.083333336, numApps=4, numContainers=2
2013-08-16 20:51:23,544 INFO org.apache.hadoop.yarn.server.resourcemanager.scheduler.capacity.ParentQueue: assignedContainer queue=root usedCapacity=0.083333336 absoluteUsedCapacity=0.083333336 used=<memory:4096, vCores:2> cluster=<memory:49152, vCores:96>
2013-08-16 20:51:23,545 INFO org.apache.hadoop.yarn.server.resourcemanager.rmcontainer.RMContainerImpl: container_1376685566219_0007_01_000001 Container Transitioned from ALLOCATED to ACQUIRED
2013-08-16 20:51:23,546 INFO org.apache.hadoop.yarn.server.resourcemanager.rmapp.attempt.RMAppAttemptImpl: Storing attempt: AppId: application_1376685566219_0007 AttemptId: appattempt_1376685566219_0007_000001 MasterContainer: Container: [ContainerId: container_1376685566219_0007_01_000001, NodeId: hadoop-512-7:51513, NodeHttpAddress: hadoop-512-7:8042, Resource: <memory:2048, vCores:1>, Priority: 0, State: NEW, Token: null, Status: container_id {, app_attempt_id {, application_id {, id: 7, cluster_timestamp: 1376685566219, }, attemptId: 1, }, id: 1, }, state: C_NEW, ]
2013-08-16 20:51:23,546 INFO org.apache.hadoop.yarn.server.resourcemanager.rmapp.attempt.RMAppAttemptImpl: appattempt_1376685566219_0007_000001 State change from SCHEDULED to ALLOCATED_SAVING
2013-08-16 20:51:23,546 INFO org.apache.hadoop.yarn.server.resourcemanager.recovery.RMStateStore: Storing info for attempt: appattempt_1376685566219_0007_000001
2013-08-16 20:51:23,550 INFO org.apache.hadoop.yarn.server.resourcemanager.rmapp.attempt.RMAppAttemptImpl: appattempt_1376685566219_0007_000001 State change from ALLOCATED_SAVING to ALLOCATED
2013-08-16 20:51:23,550 INFO org.apache.hadoop.yarn.server.resourcemanager.amlauncher.AMLauncher: Launching masterappattempt_1376685566219_0007_000001
2013-08-16 20:51:23,552 INFO org.apache.hadoop.yarn.server.resourcemanager.amlauncher.AMLauncher: Setting up container Container: [ContainerId: container_1376685566219_0007_01_000001, NodeId: hadoop-512-7:51513, NodeHttpAddress: hadoop-512-7:8042, Resource: <memory:2048, vCores:1>, Priority: 0, State: NEW, Token: null, Status: container_id {, app_attempt_id {, application_id {, id: 7, cluster_timestamp: 1376685566219, }, attemptId: 1, }, id: 1, }, state: C_NEW, ] for AM appattempt_1376685566219_0007_000001
2013-08-16 20:51:23,552 INFO org.apache.hadoop.yarn.server.resourcemanager.amlauncher.AMLauncher: Command to launch container container_1376685566219_0007_01_000001 : $JAVA_HOME/bin/java -Dlog4j.configuration=container-log4j.properties -Dyarn.app.mapreduce.container.log.dir=<LOG_DIR> -Dyarn.app.mapreduce.container.log.filesize=0 -Dhadoop.root.logger=INFO,CLA  -Xmx1024m org.apache.hadoop.mapreduce.v2.app.MRAppMaster 1><LOG_DIR>/stdout 2><LOG_DIR>/stderr 
2013-08-16 20:51:23,573 INFO org.apache.hadoop.yarn.server.resourcemanager.amlauncher.AMLauncher: Done launching container Container: [ContainerId: container_1376685566219_0007_01_000001, NodeId: hadoop-512-7:51513, NodeHttpAddress: hadoop-512-7:8042, Resource: <memory:2048, vCores:1>, Priority: 0, State: NEW, Token: null, Status: container_id {, app_attempt_id {, application_id {, id: 7, cluster_timestamp: 1376685566219, }, attemptId: 1, }, id: 1, }, state: C_NEW, ] for AM appattempt_1376685566219_0007_000001
2013-08-16 20:51:23,573 INFO org.apache.hadoop.yarn.server.resourcemanager.rmapp.attempt.RMAppAttemptImpl: appattempt_1376685566219_0007_000001 State change from ALLOCATED to LAUNCHED
2013-08-16 20:51:23,690 INFO org.apache.hadoop.yarn.server.resourcemanager.rmcontainer.RMContainerImpl: container_1376685566219_0008_01_000001 Container Transitioned from NEW to ALLOCATED
2013-08-16 20:51:23,690 INFO org.apache.hadoop.yarn.server.resourcemanager.RMAuditLogger: USER=ubuntu	OPERATION=AM Allocated Container	TARGET=SchedulerApp	RESULT=SUCCESS	APPID=application_1376685566219_0008	CONTAINERID=container_1376685566219_0008_01_000001
2013-08-16 20:51:23,691 INFO org.apache.hadoop.yarn.server.resourcemanager.scheduler.common.fica.FiCaSchedulerNode: Assigned container container_1376685566219_0008_01_000001 of capacity <memory:2048, vCores:1> on host hadoop-512-6:40600, which currently has 1 containers, <memory:2048, vCores:1> used and <memory:6144, vCores:15> available
2013-08-16 20:51:23,691 INFO org.apache.hadoop.yarn.server.resourcemanager.scheduler.capacity.LeafQueue: assignedContainer application=application_1376685566219_0008 container=Container: [ContainerId: container_1376685566219_0008_01_000001, NodeId: hadoop-512-6:40600, NodeHttpAddress: hadoop-512-6:8042, Resource: <memory:2048, vCores:1>, Priority: 0, State: NEW, Token: null, Status: container_id {, app_attempt_id {, application_id {, id: 8, cluster_timestamp: 1376685566219, }, attemptId: 1, }, id: 1, }, state: C_NEW, ] containerId=container_1376685566219_0008_01_000001 queue=default: capacity=1.0, absoluteCapacity=1.0, usedResources=<memory:4096, vCores:2>usedCapacity=0.083333336, absoluteUsedCapacity=0.083333336, numApps=4, numContainers=2 usedCapacity=0.083333336 absoluteUsedCapacity=0.083333336 used=<memory:4096, vCores:2> cluster=<memory:49152, vCores:96>
2013-08-16 20:51:23,691 INFO org.apache.hadoop.yarn.server.resourcemanager.scheduler.capacity.ParentQueue: Re-sorting queues since queue: root.default stats: default: capacity=1.0, absoluteCapacity=1.0, usedResources=<memory:6144, vCores:3>usedCapacity=0.125, absoluteUsedCapacity=0.125, numApps=4, numContainers=3
2013-08-16 20:51:23,692 INFO org.apache.hadoop.yarn.server.resourcemanager.scheduler.capacity.ParentQueue: assignedContainer queue=root usedCapacity=0.125 absoluteUsedCapacity=0.125 used=<memory:6144, vCores:3> cluster=<memory:49152, vCores:96>
2013-08-16 20:51:23,692 INFO org.apache.hadoop.yarn.server.resourcemanager.rmcontainer.RMContainerImpl: container_1376685566219_0008_01_000001 Container Transitioned from ALLOCATED to ACQUIRED
2013-08-16 20:51:23,693 INFO org.apache.hadoop.yarn.server.resourcemanager.rmapp.attempt.RMAppAttemptImpl: Storing attempt: AppId: application_1376685566219_0008 AttemptId: appattempt_1376685566219_0008_000001 MasterContainer: Container: [ContainerId: container_1376685566219_0008_01_000001, NodeId: hadoop-512-6:40600, NodeHttpAddress: hadoop-512-6:8042, Resource: <memory:2048, vCores:1>, Priority: 0, State: NEW, Token: null, Status: container_id {, app_attempt_id {, application_id {, id: 8, cluster_timestamp: 1376685566219, }, attemptId: 1, }, id: 1, }, state: C_NEW, ]
2013-08-16 20:51:23,693 INFO org.apache.hadoop.yarn.server.resourcemanager.rmapp.attempt.RMAppAttemptImpl: appattempt_1376685566219_0008_000001 State change from SCHEDULED to ALLOCATED_SAVING
2013-08-16 20:51:23,693 INFO org.apache.hadoop.yarn.server.resourcemanager.recovery.RMStateStore: Storing info for attempt: appattempt_1376685566219_0008_000001
2013-08-16 20:51:23,693 INFO org.apache.hadoop.yarn.server.resourcemanager.rmapp.attempt.RMAppAttemptImpl: appattempt_1376685566219_0008_000001 State change from ALLOCATED_SAVING to ALLOCATED
2013-08-16 20:51:23,693 INFO org.apache.hadoop.yarn.server.resourcemanager.amlauncher.AMLauncher: Launching masterappattempt_1376685566219_0008_000001
2013-08-16 20:51:23,695 INFO org.apache.hadoop.yarn.server.resourcemanager.amlauncher.AMLauncher: Setting up container Container: [ContainerId: container_1376685566219_0008_01_000001, NodeId: hadoop-512-6:40600, NodeHttpAddress: hadoop-512-6:8042, Resource: <memory:2048, vCores:1>, Priority: 0, State: NEW, Token: null, Status: container_id {, app_attempt_id {, application_id {, id: 8, cluster_timestamp: 1376685566219, }, attemptId: 1, }, id: 1, }, state: C_NEW, ] for AM appattempt_1376685566219_0008_000001
2013-08-16 20:51:23,695 INFO org.apache.hadoop.yarn.server.resourcemanager.amlauncher.AMLauncher: Command to launch container container_1376685566219_0008_01_000001 : $JAVA_HOME/bin/java -Dlog4j.configuration=container-log4j.properties -Dyarn.app.mapreduce.container.log.dir=<LOG_DIR> -Dyarn.app.mapreduce.container.log.filesize=0 -Dhadoop.root.logger=INFO,CLA  -Xmx1024m org.apache.hadoop.mapreduce.v2.app.MRAppMaster 1><LOG_DIR>/stdout 2><LOG_DIR>/stderr 
2013-08-16 20:51:23,705 INFO org.apache.hadoop.yarn.server.resourcemanager.amlauncher.AMLauncher: Done launching container Container: [ContainerId: container_1376685566219_0008_01_000001, NodeId: hadoop-512-6:40600, NodeHttpAddress: hadoop-512-6:8042, Resource: <memory:2048, vCores:1>, Priority: 0, State: NEW, Token: null, Status: container_id {, app_attempt_id {, application_id {, id: 8, cluster_timestamp: 1376685566219, }, attemptId: 1, }, id: 1, }, state: C_NEW, ] for AM appattempt_1376685566219_0008_000001
2013-08-16 20:51:23,705 INFO org.apache.hadoop.yarn.server.resourcemanager.rmapp.attempt.RMAppAttemptImpl: appattempt_1376685566219_0008_000001 State change from ALLOCATED to LAUNCHED
2013-08-16 20:51:23,827 INFO org.apache.hadoop.yarn.server.resourcemanager.rmcontainer.RMContainerImpl: container_1376685566219_0009_01_000001 Container Transitioned from NEW to ALLOCATED
2013-08-16 20:51:23,828 INFO org.apache.hadoop.yarn.server.resourcemanager.RMAuditLogger: USER=ubuntu	OPERATION=AM Allocated Container	TARGET=SchedulerApp	RESULT=SUCCESS	APPID=application_1376685566219_0009	CONTAINERID=container_1376685566219_0009_01_000001
2013-08-16 20:51:23,828 INFO org.apache.hadoop.yarn.server.resourcemanager.scheduler.common.fica.FiCaSchedulerNode: Assigned container container_1376685566219_0009_01_000001 of capacity <memory:2048, vCores:1> on host hadoop-512-3:58863, which currently has 1 containers, <memory:2048, vCores:1> used and <memory:6144, vCores:15> available
2013-08-16 20:51:23,829 INFO org.apache.hadoop.yarn.server.resourcemanager.scheduler.capacity.LeafQueue: assignedContainer application=application_1376685566219_0009 container=Container: [ContainerId: container_1376685566219_0009_01_000001, NodeId: hadoop-512-3:58863, NodeHttpAddress: hadoop-512-3:8042, Resource: <memory:2048, vCores:1>, Priority: 0, State: NEW, Token: null, Status: container_id {, app_attempt_id {, application_id {, id: 9, cluster_timestamp: 1376685566219, }, attemptId: 1, }, id: 1, }, state: C_NEW, ] containerId=container_1376685566219_0009_01_000001 queue=default: capacity=1.0, absoluteCapacity=1.0, usedResources=<memory:6144, vCores:3>usedCapacity=0.125, absoluteUsedCapacity=0.125, numApps=4, numContainers=3 usedCapacity=0.125 absoluteUsedCapacity=0.125 used=<memory:6144, vCores:3> cluster=<memory:49152, vCores:96>
2013-08-16 20:51:23,829 INFO org.apache.hadoop.yarn.server.resourcemanager.scheduler.capacity.ParentQueue: Re-sorting queues since queue: root.default stats: default: capacity=1.0, absoluteCapacity=1.0, usedResources=<memory:8192, vCores:4>usedCapacity=0.16666667, absoluteUsedCapacity=0.16666667, numApps=4, numContainers=4
2013-08-16 20:51:23,829 INFO org.apache.hadoop.yarn.server.resourcemanager.scheduler.capacity.ParentQueue: assignedContainer queue=root usedCapacity=0.16666667 absoluteUsedCapacity=0.16666667 used=<memory:8192, vCores:4> cluster=<memory:49152, vCores:96>
2013-08-16 20:51:23,829 INFO org.apache.hadoop.yarn.server.resourcemanager.rmcontainer.RMContainerImpl: container_1376685566219_0009_01_000001 Container Transitioned from ALLOCATED to ACQUIRED
2013-08-16 20:51:23,830 INFO org.apache.hadoop.yarn.server.resourcemanager.rmapp.attempt.RMAppAttemptImpl: Storing attempt: AppId: application_1376685566219_0009 AttemptId: appattempt_1376685566219_0009_000001 MasterContainer: Container: [ContainerId: container_1376685566219_0009_01_000001, NodeId: hadoop-512-3:58863, NodeHttpAddress: hadoop-512-3:8042, Resource: <memory:2048, vCores:1>, Priority: 0, State: NEW, Token: null, Status: container_id {, app_attempt_id {, application_id {, id: 9, cluster_timestamp: 1376685566219, }, attemptId: 1, }, id: 1, }, state: C_NEW, ]
2013-08-16 20:51:23,830 INFO org.apache.hadoop.yarn.server.resourcemanager.rmapp.attempt.RMAppAttemptImpl: appattempt_1376685566219_0009_000001 State change from SCHEDULED to ALLOCATED_SAVING
2013-08-16 20:51:23,830 INFO org.apache.hadoop.yarn.server.resourcemanager.recovery.RMStateStore: Storing info for attempt: appattempt_1376685566219_0009_000001
2013-08-16 20:51:23,831 INFO org.apache.hadoop.yarn.server.resourcemanager.rmapp.attempt.RMAppAttemptImpl: appattempt_1376685566219_0009_000001 State change from ALLOCATED_SAVING to ALLOCATED
2013-08-16 20:51:23,831 INFO org.apache.hadoop.yarn.server.resourcemanager.amlauncher.AMLauncher: Launching masterappattempt_1376685566219_0009_000001
2013-08-16 20:51:23,832 INFO org.apache.hadoop.yarn.server.resourcemanager.amlauncher.AMLauncher: Setting up container Container: [ContainerId: container_1376685566219_0009_01_000001, NodeId: hadoop-512-3:58863, NodeHttpAddress: hadoop-512-3:8042, Resource: <memory:2048, vCores:1>, Priority: 0, State: NEW, Token: null, Status: container_id {, app_attempt_id {, application_id {, id: 9, cluster_timestamp: 1376685566219, }, attemptId: 1, }, id: 1, }, state: C_NEW, ] for AM appattempt_1376685566219_0009_000001
2013-08-16 20:51:23,832 INFO org.apache.hadoop.yarn.server.resourcemanager.amlauncher.AMLauncher: Command to launch container container_1376685566219_0009_01_000001 : $JAVA_HOME/bin/java -Dlog4j.configuration=container-log4j.properties -Dyarn.app.mapreduce.container.log.dir=<LOG_DIR> -Dyarn.app.mapreduce.container.log.filesize=0 -Dhadoop.root.logger=INFO,CLA  -Xmx1024m org.apache.hadoop.mapreduce.v2.app.MRAppMaster 1><LOG_DIR>/stdout 2><LOG_DIR>/stderr 
2013-08-16 20:51:23,847 INFO org.apache.hadoop.yarn.server.resourcemanager.amlauncher.AMLauncher: Done launching container Container: [ContainerId: container_1376685566219_0009_01_000001, NodeId: hadoop-512-3:58863, NodeHttpAddress: hadoop-512-3:8042, Resource: <memory:2048, vCores:1>, Priority: 0, State: NEW, Token: null, Status: container_id {, app_attempt_id {, application_id {, id: 9, cluster_timestamp: 1376685566219, }, attemptId: 1, }, id: 1, }, state: C_NEW, ] for AM appattempt_1376685566219_0009_000001
2013-08-16 20:51:23,847 INFO org.apache.hadoop.yarn.server.resourcemanager.rmapp.attempt.RMAppAttemptImpl: appattempt_1376685566219_0009_000001 State change from ALLOCATED to LAUNCHED
2013-08-16 20:51:24,036 INFO org.apache.hadoop.yarn.server.resourcemanager.ClientRMService: Storing Application with id application_1376685566219_0010
2013-08-16 20:51:24,038 INFO org.apache.hadoop.yarn.server.resourcemanager.recovery.RMStateStore: Storing info for app: application_1376685566219_0010
2013-08-16 20:51:24,038 INFO org.apache.hadoop.yarn.server.resourcemanager.ClientRMService: Application with id 10 submitted by user ubuntu
2013-08-16 20:51:24,038 INFO org.apache.hadoop.yarn.server.resourcemanager.RMAuditLogger: USER=ubuntu	IP=192.168.100.6	OPERATION=Submit Application Request	TARGET=ClientRMService	RESULT=SUCCESS	APPID=application_1376685566219_0010
2013-08-16 20:51:24,038 INFO org.apache.hadoop.yarn.server.resourcemanager.rmapp.RMAppImpl: application_1376685566219_0010 State change from NEW to SUBMITTED
2013-08-16 20:51:24,039 INFO org.apache.hadoop.yarn.server.resourcemanager.ApplicationMasterService: Registering appattempt_1376685566219_0010_000001
2013-08-16 20:51:24,039 INFO org.apache.hadoop.yarn.server.resourcemanager.rmapp.attempt.RMAppAttemptImpl: appattempt_1376685566219_0010_000001 State change from NEW to SUBMITTED
2013-08-16 20:51:24,040 INFO org.apache.hadoop.yarn.server.resourcemanager.scheduler.capacity.LeafQueue: Application application_1376685566219_0010 from user: ubuntu activated in queue: default
2013-08-16 20:51:24,040 INFO org.apache.hadoop.yarn.server.resourcemanager.scheduler.capacity.LeafQueue: Application added - appId: application_1376685566219_0010 user: org.apache.hadoop.yarn.server.resourcemanager.scheduler.capacity.LeafQueue$User@d4569d3, leaf-queue: default #user-pending-applications: 0 #user-active-applications: 5 #queue-pending-applications: 0 #queue-active-applications: 5
2013-08-16 20:51:24,040 INFO org.apache.hadoop.yarn.server.resourcemanager.scheduler.capacity.ParentQueue: Application added - appId: application_1376685566219_0010 user: ubuntu leaf-queue of parent: root #applications: 5
2013-08-16 20:51:24,040 INFO org.apache.hadoop.yarn.server.resourcemanager.scheduler.capacity.CapacityScheduler: Application Submission: appattempt_1376685566219_0010_000001, user: ubuntu queue: default: capacity=1.0, absoluteCapacity=1.0, usedResources=<memory:8192, vCores:4>usedCapacity=0.16666667, absoluteUsedCapacity=0.16666667, numApps=5, numContainers=4, currently active: 5
2013-08-16 20:51:24,042 INFO org.apache.hadoop.yarn.server.resourcemanager.rmapp.attempt.RMAppAttemptImpl: appattempt_1376685566219_0010_000001 State change from SUBMITTED to SCHEDULED
2013-08-16 20:51:24,042 INFO org.apache.hadoop.yarn.server.resourcemanager.rmapp.RMAppImpl: application_1376685566219_0010 State change from SUBMITTED to ACCEPTED
2013-08-16 20:51:24,170 INFO org.apache.hadoop.yarn.server.resourcemanager.rmcontainer.RMContainerImpl: container_1376685566219_0010_01_000001 Container Transitioned from NEW to ALLOCATED
2013-08-16 20:51:24,171 INFO org.apache.hadoop.yarn.server.resourcemanager.RMAuditLogger: USER=ubuntu	OPERATION=AM Allocated Container	TARGET=SchedulerApp	RESULT=SUCCESS	APPID=application_1376685566219_0010	CONTAINERID=container_1376685566219_0010_01_000001
2013-08-16 20:51:24,171 INFO org.apache.hadoop.yarn.server.resourcemanager.scheduler.common.fica.FiCaSchedulerNode: Assigned container container_1376685566219_0010_01_000001 of capacity <memory:2048, vCores:1> on host hadoop-512-2:41669, which currently has 1 containers, <memory:2048, vCores:1> used and <memory:6144, vCores:15> available
2013-08-16 20:51:24,172 INFO org.apache.hadoop.yarn.server.resourcemanager.scheduler.capacity.LeafQueue: assignedContainer application=application_1376685566219_0010 container=Container: [ContainerId: container_1376685566219_0010_01_000001, NodeId: hadoop-512-2:41669, NodeHttpAddress: hadoop-512-2:8042, Resource: <memory:2048, vCores:1>, Priority: 0, State: NEW, Token: null, Status: container_id {, app_attempt_id {, application_id {, id: 10, cluster_timestamp: 1376685566219, }, attemptId: 1, }, id: 1, }, state: C_NEW, ] containerId=container_1376685566219_0010_01_000001 queue=default: capacity=1.0, absoluteCapacity=1.0, usedResources=<memory:8192, vCores:4>usedCapacity=0.16666667, absoluteUsedCapacity=0.16666667, numApps=5, numContainers=4 usedCapacity=0.16666667 absoluteUsedCapacity=0.16666667 used=<memory:8192, vCores:4> cluster=<memory:49152, vCores:96>
2013-08-16 20:51:24,173 INFO org.apache.hadoop.yarn.server.resourcemanager.scheduler.capacity.ParentQueue: Re-sorting queues since queue: root.default stats: default: capacity=1.0, absoluteCapacity=1.0, usedResources=<memory:10240, vCores:5>usedCapacity=0.20833333, absoluteUsedCapacity=0.20833333, numApps=5, numContainers=5
2013-08-16 20:51:24,173 INFO org.apache.hadoop.yarn.server.resourcemanager.scheduler.capacity.ParentQueue: assignedContainer queue=root usedCapacity=0.20833333 absoluteUsedCapacity=0.20833333 used=<memory:10240, vCores:5> cluster=<memory:49152, vCores:96>
2013-08-16 20:51:24,174 INFO org.apache.hadoop.yarn.server.resourcemanager.rmcontainer.RMContainerImpl: container_1376685566219_0010_01_000001 Container Transitioned from ALLOCATED to ACQUIRED
2013-08-16 20:51:24,175 INFO org.apache.hadoop.yarn.server.resourcemanager.rmapp.attempt.RMAppAttemptImpl: Storing attempt: AppId: application_1376685566219_0010 AttemptId: appattempt_1376685566219_0010_000001 MasterContainer: Container: [ContainerId: container_1376685566219_0010_01_000001, NodeId: hadoop-512-2:41669, NodeHttpAddress: hadoop-512-2:8042, Resource: <memory:2048, vCores:1>, Priority: 0, State: NEW, Token: null, Status: container_id {, app_attempt_id {, application_id {, id: 10, cluster_timestamp: 1376685566219, }, attemptId: 1, }, id: 1, }, state: C_NEW, ]
2013-08-16 20:51:24,175 INFO org.apache.hadoop.yarn.server.resourcemanager.rmapp.attempt.RMAppAttemptImpl: appattempt_1376685566219_0010_000001 State change from SCHEDULED to ALLOCATED_SAVING
2013-08-16 20:51:24,175 INFO org.apache.hadoop.yarn.server.resourcemanager.recovery.RMStateStore: Storing info for attempt: appattempt_1376685566219_0010_000001
2013-08-16 20:51:24,176 INFO org.apache.hadoop.yarn.server.resourcemanager.rmapp.attempt.RMAppAttemptImpl: appattempt_1376685566219_0010_000001 State change from ALLOCATED_SAVING to ALLOCATED
2013-08-16 20:51:24,177 INFO org.apache.hadoop.yarn.server.resourcemanager.amlauncher.AMLauncher: Launching masterappattempt_1376685566219_0010_000001
2013-08-16 20:51:24,179 INFO org.apache.hadoop.yarn.server.resourcemanager.amlauncher.AMLauncher: Setting up container Container: [ContainerId: container_1376685566219_0010_01_000001, NodeId: hadoop-512-2:41669, NodeHttpAddress: hadoop-512-2:8042, Resource: <memory:2048, vCores:1>, Priority: 0, State: NEW, Token: null, Status: container_id {, app_attempt_id {, application_id {, id: 10, cluster_timestamp: 1376685566219, }, attemptId: 1, }, id: 1, }, state: C_NEW, ] for AM appattempt_1376685566219_0010_000001
2013-08-16 20:51:24,179 INFO org.apache.hadoop.yarn.server.resourcemanager.amlauncher.AMLauncher: Command to launch container container_1376685566219_0010_01_000001 : $JAVA_HOME/bin/java -Dlog4j.configuration=container-log4j.properties -Dyarn.app.mapreduce.container.log.dir=<LOG_DIR> -Dyarn.app.mapreduce.container.log.filesize=0 -Dhadoop.root.logger=INFO,CLA  -Xmx1024m org.apache.hadoop.mapreduce.v2.app.MRAppMaster 1><LOG_DIR>/stdout 2><LOG_DIR>/stderr 
2013-08-16 20:51:24,195 INFO org.apache.hadoop.yarn.server.resourcemanager.amlauncher.AMLauncher: Done launching container Container: [ContainerId: container_1376685566219_0010_01_000001, NodeId: hadoop-512-2:41669, NodeHttpAddress: hadoop-512-2:8042, Resource: <memory:2048, vCores:1>, Priority: 0, State: NEW, Token: null, Status: container_id {, app_attempt_id {, application_id {, id: 10, cluster_timestamp: 1376685566219, }, attemptId: 1, }, id: 1, }, state: C_NEW, ] for AM appattempt_1376685566219_0010_000001
2013-08-16 20:51:24,196 INFO org.apache.hadoop.yarn.server.resourcemanager.rmapp.attempt.RMAppAttemptImpl: appattempt_1376685566219_0010_000001 State change from ALLOCATED to LAUNCHED
2013-08-16 20:51:24,238 INFO org.apache.hadoop.yarn.server.resourcemanager.rmcontainer.RMContainerImpl: container_1376685566219_0006_01_000001 Container Transitioned from ACQUIRED to RUNNING
2013-08-16 20:51:24,549 INFO org.apache.hadoop.yarn.server.resourcemanager.rmcontainer.RMContainerImpl: container_1376685566219_0007_01_000001 Container Transitioned from ACQUIRED to RUNNING
2013-08-16 20:51:24,696 INFO org.apache.hadoop.yarn.server.resourcemanager.rmcontainer.RMContainerImpl: container_1376685566219_0008_01_000001 Container Transitioned from ACQUIRED to RUNNING
2013-08-16 20:51:24,832 INFO org.apache.hadoop.yarn.server.resourcemanager.rmcontainer.RMContainerImpl: container_1376685566219_0009_01_000001 Container Transitioned from ACQUIRED to RUNNING
2013-08-16 20:51:25,175 INFO org.apache.hadoop.yarn.server.resourcemanager.rmcontainer.RMContainerImpl: container_1376685566219_0010_01_000001 Container Transitioned from ACQUIRED to RUNNING
2013-08-16 20:51:29,307 INFO org.apache.hadoop.yarn.server.resourcemanager.ApplicationMasterService: AM registration appattempt_1376685566219_0006_000001
2013-08-16 20:51:29,307 INFO org.apache.hadoop.yarn.server.resourcemanager.RMAuditLogger: USER=ubuntu	IP=192.168.100.17	OPERATION=Register App Master	TARGET=ApplicationMasterService	RESULT=SUCCESS	APPID=application_1376685566219_0006	APPATTEMPTID=appattempt_1376685566219_0006_000001
2013-08-16 20:51:29,309 INFO org.apache.hadoop.yarn.server.resourcemanager.rmapp.attempt.RMAppAttemptImpl: appattempt_1376685566219_0006_000001 State change from LAUNCHED to RUNNING
2013-08-16 20:51:29,309 INFO org.apache.hadoop.yarn.server.resourcemanager.rmapp.RMAppImpl: application_1376685566219_0006 State change from ACCEPTED to RUNNING
2013-08-16 20:51:29,729 INFO org.apache.hadoop.yarn.server.resourcemanager.ApplicationMasterService: AM registration appattempt_1376685566219_0009_000001
2013-08-16 20:51:29,729 INFO org.apache.hadoop.yarn.server.resourcemanager.RMAuditLogger: USER=ubuntu	IP=192.168.100.10	OPERATION=Register App Master	TARGET=ApplicationMasterService	RESULT=SUCCESS	APPID=application_1376685566219_0009	APPATTEMPTID=appattempt_1376685566219_0009_000001
2013-08-16 20:51:29,730 INFO org.apache.hadoop.yarn.server.resourcemanager.rmapp.attempt.RMAppAttemptImpl: appattempt_1376685566219_0009_000001 State change from LAUNCHED to RUNNING
2013-08-16 20:51:29,730 INFO org.apache.hadoop.yarn.server.resourcemanager.rmapp.RMAppImpl: application_1376685566219_0009 State change from ACCEPTED to RUNNING
2013-08-16 20:51:30,577 INFO org.apache.hadoop.yarn.server.resourcemanager.rmcontainer.RMContainerImpl: container_1376685566219_0006_01_000002 Container Transitioned from NEW to ALLOCATED
2013-08-16 20:51:30,577 INFO org.apache.hadoop.yarn.server.resourcemanager.RMAuditLogger: USER=ubuntu	OPERATION=AM Allocated Container	TARGET=SchedulerApp	RESULT=SUCCESS	APPID=application_1376685566219_0006	CONTAINERID=container_1376685566219_0006_01_000002
2013-08-16 20:51:30,577 INFO org.apache.hadoop.yarn.server.resourcemanager.scheduler.common.fica.FiCaSchedulerNode: Assigned container container_1376685566219_0006_01_000002 of capacity <memory:1024, vCores:1> on host hadoop-512-7:51513, which currently has 2 containers, <memory:3072, vCores:2> used and <memory:5120, vCores:14> available
2013-08-16 20:51:30,578 INFO org.apache.hadoop.yarn.server.resourcemanager.scheduler.capacity.LeafQueue: assignedContainer application=application_1376685566219_0006 container=Container: [ContainerId: container_1376685566219_0006_01_000002, NodeId: hadoop-512-7:51513, NodeHttpAddress: hadoop-512-7:8042, Resource: <memory:1024, vCores:1>, Priority: 20, State: NEW, Token: null, Status: container_id {, app_attempt_id {, application_id {, id: 6, cluster_timestamp: 1376685566219, }, attemptId: 1, }, id: 2, }, state: C_NEW, ] containerId=container_1376685566219_0006_01_000002 queue=default: capacity=1.0, absoluteCapacity=1.0, usedResources=<memory:10240, vCores:5>usedCapacity=0.20833333, absoluteUsedCapacity=0.20833333, numApps=5, numContainers=5 usedCapacity=0.20833333 absoluteUsedCapacity=0.20833333 used=<memory:10240, vCores:5> cluster=<memory:49152, vCores:96>
2013-08-16 20:51:30,579 INFO org.apache.hadoop.yarn.server.resourcemanager.scheduler.capacity.ParentQueue: Re-sorting queues since queue: root.default stats: default: capacity=1.0, absoluteCapacity=1.0, usedResources=<memory:11264, vCores:6>usedCapacity=0.22916667, absoluteUsedCapacity=0.22916667, numApps=5, numContainers=6
2013-08-16 20:51:30,579 INFO org.apache.hadoop.yarn.server.resourcemanager.scheduler.capacity.ParentQueue: assignedContainer queue=root usedCapacity=0.22916667 absoluteUsedCapacity=0.22916667 used=<memory:11264, vCores:6> cluster=<memory:49152, vCores:96>
2013-08-16 20:51:30,579 INFO org.apache.hadoop.yarn.server.resourcemanager.rmcontainer.RMContainerImpl: container_1376685566219_0006_01_000003 Container Transitioned from NEW to ALLOCATED
2013-08-16 20:51:30,579 INFO org.apache.hadoop.yarn.server.resourcemanager.RMAuditLogger: USER=ubuntu	OPERATION=AM Allocated Container	TARGET=SchedulerApp	RESULT=SUCCESS	APPID=application_1376685566219_0006	CONTAINERID=container_1376685566219_0006_01_000003
2013-08-16 20:51:30,580 INFO org.apache.hadoop.yarn.server.resourcemanager.scheduler.common.fica.FiCaSchedulerNode: Assigned container container_1376685566219_0006_01_000003 of capacity <memory:1024, vCores:1> on host hadoop-512-7:51513, which currently has 3 containers, <memory:4096, vCores:3> used and <memory:4096, vCores:13> available
2013-08-16 20:51:30,581 INFO org.apache.hadoop.yarn.server.resourcemanager.scheduler.capacity.LeafQueue: assignedContainer application=application_1376685566219_0006 container=Container: [ContainerId: container_1376685566219_0006_01_000003, NodeId: hadoop-512-7:51513, NodeHttpAddress: hadoop-512-7:8042, Resource: <memory:1024, vCores:1>, Priority: 20, State: NEW, Token: null, Status: container_id {, app_attempt_id {, application_id {, id: 6, cluster_timestamp: 1376685566219, }, attemptId: 1, }, id: 3, }, state: C_NEW, ] containerId=container_1376685566219_0006_01_000003 queue=default: capacity=1.0, absoluteCapacity=1.0, usedResources=<memory:11264, vCores:6>usedCapacity=0.22916667, absoluteUsedCapacity=0.22916667, numApps=5, numContainers=6 usedCapacity=0.22916667 absoluteUsedCapacity=0.22916667 used=<memory:11264, vCores:6> cluster=<memory:49152, vCores:96>
2013-08-16 20:51:30,581 INFO org.apache.hadoop.yarn.server.resourcemanager.scheduler.capacity.ParentQueue: Re-sorting queues since queue: root.default stats: default: capacity=1.0, absoluteCapacity=1.0, usedResources=<memory:12288, vCores:7>usedCapacity=0.25, absoluteUsedCapacity=0.25, numApps=5, numContainers=7
2013-08-16 20:51:30,581 INFO org.apache.hadoop.yarn.server.resourcemanager.scheduler.capacity.ParentQueue: assignedContainer queue=root usedCapacity=0.25 absoluteUsedCapacity=0.25 used=<memory:12288, vCores:7> cluster=<memory:49152, vCores:96>
2013-08-16 20:51:30,581 INFO org.apache.hadoop.yarn.server.resourcemanager.rmcontainer.RMContainerImpl: container_1376685566219_0006_01_000004 Container Transitioned from NEW to ALLOCATED
2013-08-16 20:51:30,582 INFO org.apache.hadoop.yarn.server.resourcemanager.RMAuditLogger: USER=ubuntu	OPERATION=AM Allocated Container	TARGET=SchedulerApp	RESULT=SUCCESS	APPID=application_1376685566219_0006	CONTAINERID=container_1376685566219_0006_01_000004
2013-08-16 20:51:30,582 INFO org.apache.hadoop.yarn.server.resourcemanager.scheduler.common.fica.FiCaSchedulerNode: Assigned container container_1376685566219_0006_01_000004 of capacity <memory:1024, vCores:1> on host hadoop-512-7:51513, which currently has 4 containers, <memory:5120, vCores:4> used and <memory:3072, vCores:12> available
2013-08-16 20:51:30,583 INFO org.apache.hadoop.yarn.server.resourcemanager.scheduler.capacity.LeafQueue: assignedContainer application=application_1376685566219_0006 container=Container: [ContainerId: container_1376685566219_0006_01_000004, NodeId: hadoop-512-7:51513, NodeHttpAddress: hadoop-512-7:8042, Resource: <memory:1024, vCores:1>, Priority: 20, State: NEW, Token: null, Status: container_id {, app_attempt_id {, application_id {, id: 6, cluster_timestamp: 1376685566219, }, attemptId: 1, }, id: 4, }, state: C_NEW, ] containerId=container_1376685566219_0006_01_000004 queue=default: capacity=1.0, absoluteCapacity=1.0, usedResources=<memory:12288, vCores:7>usedCapacity=0.25, absoluteUsedCapacity=0.25, numApps=5, numContainers=7 usedCapacity=0.25 absoluteUsedCapacity=0.25 used=<memory:12288, vCores:7> cluster=<memory:49152, vCores:96>
2013-08-16 20:51:30,583 INFO org.apache.hadoop.yarn.server.resourcemanager.scheduler.capacity.ParentQueue: Re-sorting queues since queue: root.default stats: default: capacity=1.0, absoluteCapacity=1.0, usedResources=<memory:13312, vCores:8>usedCapacity=0.27083334, absoluteUsedCapacity=0.27083334, numApps=5, numContainers=8
2013-08-16 20:51:30,583 INFO org.apache.hadoop.yarn.server.resourcemanager.scheduler.capacity.ParentQueue: assignedContainer queue=root usedCapacity=0.27083334 absoluteUsedCapacity=0.27083334 used=<memory:13312, vCores:8> cluster=<memory:49152, vCores:96>
2013-08-16 20:51:30,584 INFO org.apache.hadoop.yarn.server.resourcemanager.rmcontainer.RMContainerImpl: container_1376685566219_0006_01_000005 Container Transitioned from NEW to ALLOCATED
2013-08-16 20:51:30,584 INFO org.apache.hadoop.yarn.server.resourcemanager.RMAuditLogger: USER=ubuntu	OPERATION=AM Allocated Container	TARGET=SchedulerApp	RESULT=SUCCESS	APPID=application_1376685566219_0006	CONTAINERID=container_1376685566219_0006_01_000005
2013-08-16 20:51:30,584 INFO org.apache.hadoop.yarn.server.resourcemanager.scheduler.common.fica.FiCaSchedulerNode: Assigned container container_1376685566219_0006_01_000005 of capacity <memory:1024, vCores:1> on host hadoop-512-7:51513, which currently has 5 containers, <memory:6144, vCores:5> used and <memory:2048, vCores:11> available
2013-08-16 20:51:30,585 INFO org.apache.hadoop.yarn.server.resourcemanager.scheduler.capacity.LeafQueue: assignedContainer application=application_1376685566219_0006 container=Container: [ContainerId: container_1376685566219_0006_01_000005, NodeId: hadoop-512-7:51513, NodeHttpAddress: hadoop-512-7:8042, Resource: <memory:1024, vCores:1>, Priority: 20, State: NEW, Token: null, Status: container_id {, app_attempt_id {, application_id {, id: 6, cluster_timestamp: 1376685566219, }, attemptId: 1, }, id: 5, }, state: C_NEW, ] containerId=container_1376685566219_0006_01_000005 queue=default: capacity=1.0, absoluteCapacity=1.0, usedResources=<memory:13312, vCores:8>usedCapacity=0.27083334, absoluteUsedCapacity=0.27083334, numApps=5, numContainers=8 usedCapacity=0.27083334 absoluteUsedCapacity=0.27083334 used=<memory:13312, vCores:8> cluster=<memory:49152, vCores:96>
2013-08-16 20:51:30,585 INFO org.apache.hadoop.yarn.server.resourcemanager.scheduler.capacity.ParentQueue: Re-sorting queues since queue: root.default stats: default: capacity=1.0, absoluteCapacity=1.0, usedResources=<memory:14336, vCores:9>usedCapacity=0.29166666, absoluteUsedCapacity=0.29166666, numApps=5, numContainers=9
2013-08-16 20:51:30,585 INFO org.apache.hadoop.yarn.server.resourcemanager.scheduler.capacity.ParentQueue: assignedContainer queue=root usedCapacity=0.29166666 absoluteUsedCapacity=0.29166666 used=<memory:14336, vCores:9> cluster=<memory:49152, vCores:96>
2013-08-16 20:51:30,586 INFO org.apache.hadoop.yarn.server.resourcemanager.rmcontainer.RMContainerImpl: container_1376685566219_0006_01_000006 Container Transitioned from NEW to ALLOCATED
2013-08-16 20:51:30,586 INFO org.apache.hadoop.yarn.server.resourcemanager.RMAuditLogger: USER=ubuntu	OPERATION=AM Allocated Container	TARGET=SchedulerApp	RESULT=SUCCESS	APPID=application_1376685566219_0006	CONTAINERID=container_1376685566219_0006_01_000006
2013-08-16 20:51:30,586 INFO org.apache.hadoop.yarn.server.resourcemanager.scheduler.common.fica.FiCaSchedulerNode: Assigned container container_1376685566219_0006_01_000006 of capacity <memory:1024, vCores:1> on host hadoop-512-7:51513, which currently has 6 containers, <memory:7168, vCores:6> used and <memory:1024, vCores:10> available
2013-08-16 20:51:30,587 INFO org.apache.hadoop.yarn.server.resourcemanager.scheduler.capacity.LeafQueue: assignedContainer application=application_1376685566219_0006 container=Container: [ContainerId: container_1376685566219_0006_01_000006, NodeId: hadoop-512-7:51513, NodeHttpAddress: hadoop-512-7:8042, Resource: <memory:1024, vCores:1>, Priority: 20, State: NEW, Token: null, Status: container_id {, app_attempt_id {, application_id {, id: 6, cluster_timestamp: 1376685566219, }, attemptId: 1, }, id: 6, }, state: C_NEW, ] containerId=container_1376685566219_0006_01_000006 queue=default: capacity=1.0, absoluteCapacity=1.0, usedResources=<memory:14336, vCores:9>usedCapacity=0.29166666, absoluteUsedCapacity=0.29166666, numApps=5, numContainers=9 usedCapacity=0.29166666 absoluteUsedCapacity=0.29166666 used=<memory:14336, vCores:9> cluster=<memory:49152, vCores:96>
2013-08-16 20:51:30,587 INFO org.apache.hadoop.yarn.server.resourcemanager.scheduler.capacity.ParentQueue: Re-sorting queues since queue: root.default stats: default: capacity=1.0, absoluteCapacity=1.0, usedResources=<memory:15360, vCores:10>usedCapacity=0.3125, absoluteUsedCapacity=0.3125, numApps=5, numContainers=10
2013-08-16 20:51:30,588 INFO org.apache.hadoop.yarn.server.resourcemanager.scheduler.capacity.ParentQueue: assignedContainer queue=root usedCapacity=0.3125 absoluteUsedCapacity=0.3125 used=<memory:15360, vCores:10> cluster=<memory:49152, vCores:96>
2013-08-16 20:51:30,588 INFO org.apache.hadoop.yarn.server.resourcemanager.rmcontainer.RMContainerImpl: container_1376685566219_0006_01_000007 Container Transitioned from NEW to ALLOCATED
2013-08-16 20:51:30,588 INFO org.apache.hadoop.yarn.server.resourcemanager.RMAuditLogger: USER=ubuntu	OPERATION=AM Allocated Container	TARGET=SchedulerApp	RESULT=SUCCESS	APPID=application_1376685566219_0006	CONTAINERID=container_1376685566219_0006_01_000007
2013-08-16 20:51:30,588 INFO org.apache.hadoop.yarn.server.resourcemanager.scheduler.common.fica.FiCaSchedulerNode: Assigned container container_1376685566219_0006_01_000007 of capacity <memory:1024, vCores:1> on host hadoop-512-7:51513, which currently has 7 containers, <memory:8192, vCores:7> used and <memory:0, vCores:9> available
2013-08-16 20:51:30,589 INFO org.apache.hadoop.yarn.server.resourcemanager.scheduler.capacity.LeafQueue: assignedContainer application=application_1376685566219_0006 container=Container: [ContainerId: container_1376685566219_0006_01_000007, NodeId: hadoop-512-7:51513, NodeHttpAddress: hadoop-512-7:8042, Resource: <memory:1024, vCores:1>, Priority: 20, State: NEW, Token: null, Status: container_id {, app_attempt_id {, application_id {, id: 6, cluster_timestamp: 1376685566219, }, attemptId: 1, }, id: 7, }, state: C_NEW, ] containerId=container_1376685566219_0006_01_000007 queue=default: capacity=1.0, absoluteCapacity=1.0, usedResources=<memory:15360, vCores:10>usedCapacity=0.3125, absoluteUsedCapacity=0.3125, numApps=5, numContainers=10 usedCapacity=0.3125 absoluteUsedCapacity=0.3125 used=<memory:15360, vCores:10> cluster=<memory:49152, vCores:96>
2013-08-16 20:51:30,589 INFO org.apache.hadoop.yarn.server.resourcemanager.scheduler.capacity.ParentQueue: Re-sorting queues since queue: root.default stats: default: capacity=1.0, absoluteCapacity=1.0, usedResources=<memory:16384, vCores:11>usedCapacity=0.33333334, absoluteUsedCapacity=0.33333334, numApps=5, numContainers=11
2013-08-16 20:51:30,590 INFO org.apache.hadoop.yarn.server.resourcemanager.scheduler.capacity.ParentQueue: assignedContainer queue=root usedCapacity=0.33333334 absoluteUsedCapacity=0.33333334 used=<memory:16384, vCores:11> cluster=<memory:49152, vCores:96>
2013-08-16 20:51:30,603 INFO org.apache.hadoop.yarn.server.resourcemanager.ApplicationMasterService: AM registration appattempt_1376685566219_0007_000001
2013-08-16 20:51:30,604 INFO org.apache.hadoop.yarn.server.resourcemanager.RMAuditLogger: USER=ubuntu	IP=192.168.100.33	OPERATION=Register App Master	TARGET=ApplicationMasterService	RESULT=SUCCESS	APPID=application_1376685566219_0007	APPATTEMPTID=appattempt_1376685566219_0007_000001
2013-08-16 20:51:30,605 INFO org.apache.hadoop.yarn.server.resourcemanager.rmapp.attempt.RMAppAttemptImpl: appattempt_1376685566219_0007_000001 State change from LAUNCHED to RUNNING
2013-08-16 20:51:30,605 INFO org.apache.hadoop.yarn.server.resourcemanager.rmapp.RMAppImpl: application_1376685566219_0007 State change from ACCEPTED to RUNNING
2013-08-16 20:51:30,732 INFO org.apache.hadoop.yarn.server.resourcemanager.rmcontainer.RMContainerImpl: container_1376685566219_0006_01_000008 Container Transitioned from NEW to ALLOCATED
2013-08-16 20:51:30,733 INFO org.apache.hadoop.yarn.server.resourcemanager.RMAuditLogger: USER=ubuntu	OPERATION=AM Allocated Container	TARGET=SchedulerApp	RESULT=SUCCESS	APPID=application_1376685566219_0006	CONTAINERID=container_1376685566219_0006_01_000008
2013-08-16 20:51:30,733 INFO org.apache.hadoop.yarn.server.resourcemanager.scheduler.common.fica.FiCaSchedulerNode: Assigned container container_1376685566219_0006_01_000008 of capacity <memory:1024, vCores:1> on host hadoop-512-6:40600, which currently has 2 containers, <memory:3072, vCores:2> used and <memory:5120, vCores:14> available
2013-08-16 20:51:30,734 INFO org.apache.hadoop.yarn.server.resourcemanager.scheduler.capacity.LeafQueue: assignedContainer application=application_1376685566219_0006 container=Container: [ContainerId: container_1376685566219_0006_01_000008, NodeId: hadoop-512-6:40600, NodeHttpAddress: hadoop-512-6:8042, Resource: <memory:1024, vCores:1>, Priority: 20, State: NEW, Token: null, Status: container_id {, app_attempt_id {, application_id {, id: 6, cluster_timestamp: 1376685566219, }, attemptId: 1, }, id: 8, }, state: C_NEW, ] containerId=container_1376685566219_0006_01_000008 queue=default: capacity=1.0, absoluteCapacity=1.0, usedResources=<memory:16384, vCores:11>usedCapacity=0.33333334, absoluteUsedCapacity=0.33333334, numApps=5, numContainers=11 usedCapacity=0.33333334 absoluteUsedCapacity=0.33333334 used=<memory:16384, vCores:11> cluster=<memory:49152, vCores:96>
2013-08-16 20:51:30,734 INFO org.apache.hadoop.yarn.server.resourcemanager.scheduler.capacity.ParentQueue: Re-sorting queues since queue: root.default stats: default: capacity=1.0, absoluteCapacity=1.0, usedResources=<memory:17408, vCores:12>usedCapacity=0.35416666, absoluteUsedCapacity=0.35416666, numApps=5, numContainers=12
2013-08-16 20:51:30,734 INFO org.apache.hadoop.yarn.server.resourcemanager.scheduler.capacity.ParentQueue: assignedContainer queue=root usedCapacity=0.35416666 absoluteUsedCapacity=0.35416666 used=<memory:17408, vCores:12> cluster=<memory:49152, vCores:96>
2013-08-16 20:51:30,735 INFO org.apache.hadoop.yarn.server.resourcemanager.rmcontainer.RMContainerImpl: container_1376685566219_0006_01_000009 Container Transitioned from NEW to ALLOCATED
2013-08-16 20:51:30,735 INFO org.apache.hadoop.yarn.server.resourcemanager.RMAuditLogger: USER=ubuntu	OPERATION=AM Allocated Container	TARGET=SchedulerApp	RESULT=SUCCESS	APPID=application_1376685566219_0006	CONTAINERID=container_1376685566219_0006_01_000009
2013-08-16 20:51:30,735 INFO org.apache.hadoop.yarn.server.resourcemanager.scheduler.common.fica.FiCaSchedulerNode: Assigned container container_1376685566219_0006_01_000009 of capacity <memory:1024, vCores:1> on host hadoop-512-6:40600, which currently has 3 containers, <memory:4096, vCores:3> used and <memory:4096, vCores:13> available
2013-08-16 20:51:30,736 INFO org.apache.hadoop.yarn.server.resourcemanager.scheduler.capacity.LeafQueue: assignedContainer application=application_1376685566219_0006 container=Container: [ContainerId: container_1376685566219_0006_01_000009, NodeId: hadoop-512-6:40600, NodeHttpAddress: hadoop-512-6:8042, Resource: <memory:1024, vCores:1>, Priority: 20, State: NEW, Token: null, Status: container_id {, app_attempt_id {, application_id {, id: 6, cluster_timestamp: 1376685566219, }, attemptId: 1, }, id: 9, }, state: C_NEW, ] containerId=container_1376685566219_0006_01_000009 queue=default: capacity=1.0, absoluteCapacity=1.0, usedResources=<memory:17408, vCores:12>usedCapacity=0.35416666, absoluteUsedCapacity=0.35416666, numApps=5, numContainers=12 usedCapacity=0.35416666 absoluteUsedCapacity=0.35416666 used=<memory:17408, vCores:12> cluster=<memory:49152, vCores:96>
2013-08-16 20:51:30,736 INFO org.apache.hadoop.yarn.server.resourcemanager.scheduler.capacity.ParentQueue: Re-sorting queues since queue: root.default stats: default: capacity=1.0, absoluteCapacity=1.0, usedResources=<memory:18432, vCores:13>usedCapacity=0.375, absoluteUsedCapacity=0.375, numApps=5, numContainers=13
2013-08-16 20:51:30,736 INFO org.apache.hadoop.yarn.server.resourcemanager.scheduler.capacity.ParentQueue: assignedContainer queue=root usedCapacity=0.375 absoluteUsedCapacity=0.375 used=<memory:18432, vCores:13> cluster=<memory:49152, vCores:96>
2013-08-16 20:51:30,737 INFO org.apache.hadoop.yarn.server.resourcemanager.rmcontainer.RMContainerImpl: container_1376685566219_0006_01_000010 Container Transitioned from NEW to ALLOCATED
2013-08-16 20:51:30,737 INFO org.apache.hadoop.yarn.server.resourcemanager.RMAuditLogger: USER=ubuntu	OPERATION=AM Allocated Container	TARGET=SchedulerApp	RESULT=SUCCESS	APPID=application_1376685566219_0006	CONTAINERID=container_1376685566219_0006_01_000010
2013-08-16 20:51:30,737 INFO org.apache.hadoop.yarn.server.resourcemanager.scheduler.common.fica.FiCaSchedulerNode: Assigned container container_1376685566219_0006_01_000010 of capacity <memory:1024, vCores:1> on host hadoop-512-6:40600, which currently has 4 containers, <memory:5120, vCores:4> used and <memory:3072, vCores:12> available
2013-08-16 20:51:30,738 INFO org.apache.hadoop.yarn.server.resourcemanager.scheduler.capacity.LeafQueue: assignedContainer application=application_1376685566219_0006 container=Container: [ContainerId: container_1376685566219_0006_01_000010, NodeId: hadoop-512-6:40600, NodeHttpAddress: hadoop-512-6:8042, Resource: <memory:1024, vCores:1>, Priority: 20, State: NEW, Token: null, Status: container_id {, app_attempt_id {, application_id {, id: 6, cluster_timestamp: 1376685566219, }, attemptId: 1, }, id: 10, }, state: C_NEW, ] containerId=container_1376685566219_0006_01_000010 queue=default: capacity=1.0, absoluteCapacity=1.0, usedResources=<memory:18432, vCores:13>usedCapacity=0.375, absoluteUsedCapacity=0.375, numApps=5, numContainers=13 usedCapacity=0.375 absoluteUsedCapacity=0.375 used=<memory:18432, vCores:13> cluster=<memory:49152, vCores:96>
2013-08-16 20:51:30,738 INFO org.apache.hadoop.yarn.server.resourcemanager.scheduler.capacity.ParentQueue: Re-sorting queues since queue: root.default stats: default: capacity=1.0, absoluteCapacity=1.0, usedResources=<memory:19456, vCores:14>usedCapacity=0.39583334, absoluteUsedCapacity=0.39583334, numApps=5, numContainers=14
2013-08-16 20:51:30,739 INFO org.apache.hadoop.yarn.server.resourcemanager.scheduler.capacity.ParentQueue: assignedContainer queue=root usedCapacity=0.39583334 absoluteUsedCapacity=0.39583334 used=<memory:19456, vCores:14> cluster=<memory:49152, vCores:96>
2013-08-16 20:51:30,739 INFO org.apache.hadoop.yarn.server.resourcemanager.rmcontainer.RMContainerImpl: container_1376685566219_0006_01_000011 Container Transitioned from NEW to ALLOCATED
2013-08-16 20:51:30,739 INFO org.apache.hadoop.yarn.server.resourcemanager.RMAuditLogger: USER=ubuntu	OPERATION=AM Allocated Container	TARGET=SchedulerApp	RESULT=SUCCESS	APPID=application_1376685566219_0006	CONTAINERID=container_1376685566219_0006_01_000011
2013-08-16 20:51:30,739 INFO org.apache.hadoop.yarn.server.resourcemanager.scheduler.common.fica.FiCaSchedulerNode: Assigned container container_1376685566219_0006_01_000011 of capacity <memory:1024, vCores:1> on host hadoop-512-6:40600, which currently has 5 containers, <memory:6144, vCores:5> used and <memory:2048, vCores:11> available
2013-08-16 20:51:30,740 INFO org.apache.hadoop.yarn.server.resourcemanager.scheduler.capacity.LeafQueue: assignedContainer application=application_1376685566219_0006 container=Container: [ContainerId: container_1376685566219_0006_01_000011, NodeId: hadoop-512-6:40600, NodeHttpAddress: hadoop-512-6:8042, Resource: <memory:1024, vCores:1>, Priority: 20, State: NEW, Token: null, Status: container_id {, app_attempt_id {, application_id {, id: 6, cluster_timestamp: 1376685566219, }, attemptId: 1, }, id: 11, }, state: C_NEW, ] containerId=container_1376685566219_0006_01_000011 queue=default: capacity=1.0, absoluteCapacity=1.0, usedResources=<memory:19456, vCores:14>usedCapacity=0.39583334, absoluteUsedCapacity=0.39583334, numApps=5, numContainers=14 usedCapacity=0.39583334 absoluteUsedCapacity=0.39583334 used=<memory:19456, vCores:14> cluster=<memory:49152, vCores:96>
2013-08-16 20:51:30,741 INFO org.apache.hadoop.yarn.server.resourcemanager.scheduler.capacity.ParentQueue: Re-sorting queues since queue: root.default stats: default: capacity=1.0, absoluteCapacity=1.0, usedResources=<memory:20480, vCores:15>usedCapacity=0.41666666, absoluteUsedCapacity=0.41666666, numApps=5, numContainers=15
2013-08-16 20:51:30,741 INFO org.apache.hadoop.yarn.server.resourcemanager.scheduler.capacity.ParentQueue: assignedContainer queue=root usedCapacity=0.41666666 absoluteUsedCapacity=0.41666666 used=<memory:20480, vCores:15> cluster=<memory:49152, vCores:96>
2013-08-16 20:51:30,741 INFO org.apache.hadoop.yarn.server.resourcemanager.rmcontainer.RMContainerImpl: container_1376685566219_0006_01_000012 Container Transitioned from NEW to ALLOCATED
2013-08-16 20:51:30,741 INFO org.apache.hadoop.yarn.server.resourcemanager.RMAuditLogger: USER=ubuntu	OPERATION=AM Allocated Container	TARGET=SchedulerApp	RESULT=SUCCESS	APPID=application_1376685566219_0006	CONTAINERID=container_1376685566219_0006_01_000012
2013-08-16 20:51:30,741 INFO org.apache.hadoop.yarn.server.resourcemanager.scheduler.common.fica.FiCaSchedulerNode: Assigned container container_1376685566219_0006_01_000012 of capacity <memory:1024, vCores:1> on host hadoop-512-6:40600, which currently has 6 containers, <memory:7168, vCores:6> used and <memory:1024, vCores:10> available
2013-08-16 20:51:30,742 INFO org.apache.hadoop.yarn.server.resourcemanager.scheduler.capacity.LeafQueue: assignedContainer application=application_1376685566219_0006 container=Container: [ContainerId: container_1376685566219_0006_01_000012, NodeId: hadoop-512-6:40600, NodeHttpAddress: hadoop-512-6:8042, Resource: <memory:1024, vCores:1>, Priority: 20, State: NEW, Token: null, Status: container_id {, app_attempt_id {, application_id {, id: 6, cluster_timestamp: 1376685566219, }, attemptId: 1, }, id: 12, }, state: C_NEW, ] containerId=container_1376685566219_0006_01_000012 queue=default: capacity=1.0, absoluteCapacity=1.0, usedResources=<memory:20480, vCores:15>usedCapacity=0.41666666, absoluteUsedCapacity=0.41666666, numApps=5, numContainers=15 usedCapacity=0.41666666 absoluteUsedCapacity=0.41666666 used=<memory:20480, vCores:15> cluster=<memory:49152, vCores:96>
2013-08-16 20:51:30,743 INFO org.apache.hadoop.yarn.server.resourcemanager.scheduler.capacity.ParentQueue: Re-sorting queues since queue: root.default stats: default: capacity=1.0, absoluteCapacity=1.0, usedResources=<memory:21504, vCores:16>usedCapacity=0.4375, absoluteUsedCapacity=0.4375, numApps=5, numContainers=16
2013-08-16 20:51:30,743 INFO org.apache.hadoop.yarn.server.resourcemanager.scheduler.capacity.ParentQueue: assignedContainer queue=root usedCapacity=0.4375 absoluteUsedCapacity=0.4375 used=<memory:21504, vCores:16> cluster=<memory:49152, vCores:96>
2013-08-16 20:51:30,743 INFO org.apache.hadoop.yarn.server.resourcemanager.rmcontainer.RMContainerImpl: container_1376685566219_0006_01_000013 Container Transitioned from NEW to ALLOCATED
2013-08-16 20:51:30,744 INFO org.apache.hadoop.yarn.server.resourcemanager.RMAuditLogger: USER=ubuntu	OPERATION=AM Allocated Container	TARGET=SchedulerApp	RESULT=SUCCESS	APPID=application_1376685566219_0006	CONTAINERID=container_1376685566219_0006_01_000013
2013-08-16 20:51:30,744 INFO org.apache.hadoop.yarn.server.resourcemanager.scheduler.common.fica.FiCaSchedulerNode: Assigned container container_1376685566219_0006_01_000013 of capacity <memory:1024, vCores:1> on host hadoop-512-6:40600, which currently has 7 containers, <memory:8192, vCores:7> used and <memory:0, vCores:9> available
2013-08-16 20:51:30,745 INFO org.apache.hadoop.yarn.server.resourcemanager.scheduler.capacity.LeafQueue: assignedContainer application=application_1376685566219_0006 container=Container: [ContainerId: container_1376685566219_0006_01_000013, NodeId: hadoop-512-6:40600, NodeHttpAddress: hadoop-512-6:8042, Resource: <memory:1024, vCores:1>, Priority: 20, State: NEW, Token: null, Status: container_id {, app_attempt_id {, application_id {, id: 6, cluster_timestamp: 1376685566219, }, attemptId: 1, }, id: 13, }, state: C_NEW, ] containerId=container_1376685566219_0006_01_000013 queue=default: capacity=1.0, absoluteCapacity=1.0, usedResources=<memory:21504, vCores:16>usedCapacity=0.4375, absoluteUsedCapacity=0.4375, numApps=5, numContainers=16 usedCapacity=0.4375 absoluteUsedCapacity=0.4375 used=<memory:21504, vCores:16> cluster=<memory:49152, vCores:96>
2013-08-16 20:51:30,745 INFO org.apache.hadoop.yarn.server.resourcemanager.scheduler.capacity.ParentQueue: Re-sorting queues since queue: root.default stats: default: capacity=1.0, absoluteCapacity=1.0, usedResources=<memory:22528, vCores:17>usedCapacity=0.45833334, absoluteUsedCapacity=0.45833334, numApps=5, numContainers=17
2013-08-16 20:51:30,745 INFO org.apache.hadoop.yarn.server.resourcemanager.scheduler.capacity.ParentQueue: assignedContainer queue=root usedCapacity=0.45833334 absoluteUsedCapacity=0.45833334 used=<memory:22528, vCores:17> cluster=<memory:49152, vCores:96>
2013-08-16 20:51:30,857 INFO org.apache.hadoop.yarn.server.resourcemanager.rmcontainer.RMContainerImpl: container_1376685566219_0006_01_000014 Container Transitioned from NEW to ALLOCATED
2013-08-16 20:51:30,857 INFO org.apache.hadoop.yarn.server.resourcemanager.RMAuditLogger: USER=ubuntu	OPERATION=AM Allocated Container	TARGET=SchedulerApp	RESULT=SUCCESS	APPID=application_1376685566219_0006	CONTAINERID=container_1376685566219_0006_01_000014
2013-08-16 20:51:30,858 INFO org.apache.hadoop.yarn.server.resourcemanager.scheduler.common.fica.FiCaSchedulerNode: Assigned container container_1376685566219_0006_01_000014 of capacity <memory:1024, vCores:1> on host hadoop-512-3:58863, which currently has 2 containers, <memory:3072, vCores:2> used and <memory:5120, vCores:14> available
2013-08-16 20:51:30,859 INFO org.apache.hadoop.yarn.server.resourcemanager.scheduler.capacity.LeafQueue: assignedContainer application=application_1376685566219_0006 container=Container: [ContainerId: container_1376685566219_0006_01_000014, NodeId: hadoop-512-3:58863, NodeHttpAddress: hadoop-512-3:8042, Resource: <memory:1024, vCores:1>, Priority: 20, State: NEW, Token: null, Status: container_id {, app_attempt_id {, application_id {, id: 6, cluster_timestamp: 1376685566219, }, attemptId: 1, }, id: 14, }, state: C_NEW, ] containerId=container_1376685566219_0006_01_000014 queue=default: capacity=1.0, absoluteCapacity=1.0, usedResources=<memory:22528, vCores:17>usedCapacity=0.45833334, absoluteUsedCapacity=0.45833334, numApps=5, numContainers=17 usedCapacity=0.45833334 absoluteUsedCapacity=0.45833334 used=<memory:22528, vCores:17> cluster=<memory:49152, vCores:96>
2013-08-16 20:51:30,859 INFO org.apache.hadoop.yarn.server.resourcemanager.scheduler.capacity.ParentQueue: Re-sorting queues since queue: root.default stats: default: capacity=1.0, absoluteCapacity=1.0, usedResources=<memory:23552, vCores:18>usedCapacity=0.47916666, absoluteUsedCapacity=0.47916666, numApps=5, numContainers=18
2013-08-16 20:51:30,859 INFO org.apache.hadoop.yarn.server.resourcemanager.scheduler.capacity.ParentQueue: assignedContainer queue=root usedCapacity=0.47916666 absoluteUsedCapacity=0.47916666 used=<memory:23552, vCores:18> cluster=<memory:49152, vCores:96>
2013-08-16 20:51:30,860 INFO org.apache.hadoop.yarn.server.resourcemanager.rmcontainer.RMContainerImpl: container_1376685566219_0006_01_000015 Container Transitioned from NEW to ALLOCATED
2013-08-16 20:51:30,860 INFO org.apache.hadoop.yarn.server.resourcemanager.RMAuditLogger: USER=ubuntu	OPERATION=AM Allocated Container	TARGET=SchedulerApp	RESULT=SUCCESS	APPID=application_1376685566219_0006	CONTAINERID=container_1376685566219_0006_01_000015
2013-08-16 20:51:30,860 INFO org.apache.hadoop.yarn.server.resourcemanager.scheduler.common.fica.FiCaSchedulerNode: Assigned container container_1376685566219_0006_01_000015 of capacity <memory:1024, vCores:1> on host hadoop-512-3:58863, which currently has 3 containers, <memory:4096, vCores:3> used and <memory:4096, vCores:13> available
2013-08-16 20:51:30,861 INFO org.apache.hadoop.yarn.server.resourcemanager.scheduler.capacity.LeafQueue: assignedContainer application=application_1376685566219_0006 container=Container: [ContainerId: container_1376685566219_0006_01_000015, NodeId: hadoop-512-3:58863, NodeHttpAddress: hadoop-512-3:8042, Resource: <memory:1024, vCores:1>, Priority: 20, State: NEW, Token: null, Status: container_id {, app_attempt_id {, application_id {, id: 6, cluster_timestamp: 1376685566219, }, attemptId: 1, }, id: 15, }, state: C_NEW, ] containerId=container_1376685566219_0006_01_000015 queue=default: capacity=1.0, absoluteCapacity=1.0, usedResources=<memory:23552, vCores:18>usedCapacity=0.47916666, absoluteUsedCapacity=0.47916666, numApps=5, numContainers=18 usedCapacity=0.47916666 absoluteUsedCapacity=0.47916666 used=<memory:23552, vCores:18> cluster=<memory:49152, vCores:96>
2013-08-16 20:51:30,861 INFO org.apache.hadoop.yarn.server.resourcemanager.scheduler.capacity.ParentQueue: Re-sorting queues since queue: root.default stats: default: capacity=1.0, absoluteCapacity=1.0, usedResources=<memory:24576, vCores:19>usedCapacity=0.5, absoluteUsedCapacity=0.5, numApps=5, numContainers=19
2013-08-16 20:51:30,861 INFO org.apache.hadoop.yarn.server.resourcemanager.scheduler.capacity.ParentQueue: assignedContainer queue=root usedCapacity=0.5 absoluteUsedCapacity=0.5 used=<memory:24576, vCores:19> cluster=<memory:49152, vCores:96>
2013-08-16 20:51:30,862 INFO org.apache.hadoop.yarn.server.resourcemanager.rmcontainer.RMContainerImpl: container_1376685566219_0006_01_000016 Container Transitioned from NEW to ALLOCATED
2013-08-16 20:51:30,862 INFO org.apache.hadoop.yarn.server.resourcemanager.RMAuditLogger: USER=ubuntu	OPERATION=AM Allocated Container	TARGET=SchedulerApp	RESULT=SUCCESS	APPID=application_1376685566219_0006	CONTAINERID=container_1376685566219_0006_01_000016
2013-08-16 20:51:30,862 INFO org.apache.hadoop.yarn.server.resourcemanager.scheduler.common.fica.FiCaSchedulerNode: Assigned container container_1376685566219_0006_01_000016 of capacity <memory:1024, vCores:1> on host hadoop-512-3:58863, which currently has 4 containers, <memory:5120, vCores:4> used and <memory:3072, vCores:12> available
2013-08-16 20:51:30,863 INFO org.apache.hadoop.yarn.server.resourcemanager.scheduler.capacity.LeafQueue: assignedContainer application=application_1376685566219_0006 container=Container: [ContainerId: container_1376685566219_0006_01_000016, NodeId: hadoop-512-3:58863, NodeHttpAddress: hadoop-512-3:8042, Resource: <memory:1024, vCores:1>, Priority: 20, State: NEW, Token: null, Status: container_id {, app_attempt_id {, application_id {, id: 6, cluster_timestamp: 1376685566219, }, attemptId: 1, }, id: 16, }, state: C_NEW, ] containerId=container_1376685566219_0006_01_000016 queue=default: capacity=1.0, absoluteCapacity=1.0, usedResources=<memory:24576, vCores:19>usedCapacity=0.5, absoluteUsedCapacity=0.5, numApps=5, numContainers=19 usedCapacity=0.5 absoluteUsedCapacity=0.5 used=<memory:24576, vCores:19> cluster=<memory:49152, vCores:96>
2013-08-16 20:51:30,863 INFO org.apache.hadoop.yarn.server.resourcemanager.scheduler.capacity.ParentQueue: Re-sorting queues since queue: root.default stats: default: capacity=1.0, absoluteCapacity=1.0, usedResources=<memory:25600, vCores:20>usedCapacity=0.5208333, absoluteUsedCapacity=0.5208333, numApps=5, numContainers=20
2013-08-16 20:51:30,863 INFO org.apache.hadoop.yarn.server.resourcemanager.scheduler.capacity.ParentQueue: assignedContainer queue=root usedCapacity=0.5208333 absoluteUsedCapacity=0.5208333 used=<memory:25600, vCores:20> cluster=<memory:49152, vCores:96>
2013-08-16 20:51:30,864 INFO org.apache.hadoop.yarn.server.resourcemanager.rmcontainer.RMContainerImpl: container_1376685566219_0006_01_000017 Container Transitioned from NEW to ALLOCATED
2013-08-16 20:51:30,864 INFO org.apache.hadoop.yarn.server.resourcemanager.RMAuditLogger: USER=ubuntu	OPERATION=AM Allocated Container	TARGET=SchedulerApp	RESULT=SUCCESS	APPID=application_1376685566219_0006	CONTAINERID=container_1376685566219_0006_01_000017
2013-08-16 20:51:30,864 INFO org.apache.hadoop.yarn.server.resourcemanager.scheduler.common.fica.FiCaSchedulerNode: Assigned container container_1376685566219_0006_01_000017 of capacity <memory:1024, vCores:1> on host hadoop-512-3:58863, which currently has 5 containers, <memory:6144, vCores:5> used and <memory:2048, vCores:11> available
2013-08-16 20:51:30,865 INFO org.apache.hadoop.yarn.server.resourcemanager.scheduler.capacity.LeafQueue: assignedContainer application=application_1376685566219_0006 container=Container: [ContainerId: container_1376685566219_0006_01_000017, NodeId: hadoop-512-3:58863, NodeHttpAddress: hadoop-512-3:8042, Resource: <memory:1024, vCores:1>, Priority: 20, State: NEW, Token: null, Status: container_id {, app_attempt_id {, application_id {, id: 6, cluster_timestamp: 1376685566219, }, attemptId: 1, }, id: 17, }, state: C_NEW, ] containerId=container_1376685566219_0006_01_000017 queue=default: capacity=1.0, absoluteCapacity=1.0, usedResources=<memory:25600, vCores:20>usedCapacity=0.5208333, absoluteUsedCapacity=0.5208333, numApps=5, numContainers=20 usedCapacity=0.5208333 absoluteUsedCapacity=0.5208333 used=<memory:25600, vCores:20> cluster=<memory:49152, vCores:96>
2013-08-16 20:51:30,865 INFO org.apache.hadoop.yarn.server.resourcemanager.scheduler.capacity.ParentQueue: Re-sorting queues since queue: root.default stats: default: capacity=1.0, absoluteCapacity=1.0, usedResources=<memory:26624, vCores:21>usedCapacity=0.5416667, absoluteUsedCapacity=0.5416667, numApps=5, numContainers=21
2013-08-16 20:51:30,865 INFO org.apache.hadoop.yarn.server.resourcemanager.scheduler.capacity.ParentQueue: assignedContainer queue=root usedCapacity=0.5416667 absoluteUsedCapacity=0.5416667 used=<memory:26624, vCores:21> cluster=<memory:49152, vCores:96>
2013-08-16 20:51:30,866 INFO org.apache.hadoop.yarn.server.resourcemanager.rmcontainer.RMContainerImpl: container_1376685566219_0006_01_000018 Container Transitioned from NEW to ALLOCATED
2013-08-16 20:51:30,866 INFO org.apache.hadoop.yarn.server.resourcemanager.RMAuditLogger: USER=ubuntu	OPERATION=AM Allocated Container	TARGET=SchedulerApp	RESULT=SUCCESS	APPID=application_1376685566219_0006	CONTAINERID=container_1376685566219_0006_01_000018
2013-08-16 20:51:30,866 INFO org.apache.hadoop.yarn.server.resourcemanager.scheduler.common.fica.FiCaSchedulerNode: Assigned container container_1376685566219_0006_01_000018 of capacity <memory:1024, vCores:1> on host hadoop-512-3:58863, which currently has 6 containers, <memory:7168, vCores:6> used and <memory:1024, vCores:10> available
2013-08-16 20:51:30,867 INFO org.apache.hadoop.yarn.server.resourcemanager.scheduler.capacity.LeafQueue: assignedContainer application=application_1376685566219_0006 container=Container: [ContainerId: container_1376685566219_0006_01_000018, NodeId: hadoop-512-3:58863, NodeHttpAddress: hadoop-512-3:8042, Resource: <memory:1024, vCores:1>, Priority: 20, State: NEW, Token: null, Status: container_id {, app_attempt_id {, application_id {, id: 6, cluster_timestamp: 1376685566219, }, attemptId: 1, }, id: 18, }, state: C_NEW, ] containerId=container_1376685566219_0006_01_000018 queue=default: capacity=1.0, absoluteCapacity=1.0, usedResources=<memory:26624, vCores:21>usedCapacity=0.5416667, absoluteUsedCapacity=0.5416667, numApps=5, numContainers=21 usedCapacity=0.5416667 absoluteUsedCapacity=0.5416667 used=<memory:26624, vCores:21> cluster=<memory:49152, vCores:96>
2013-08-16 20:51:30,867 INFO org.apache.hadoop.yarn.server.resourcemanager.scheduler.capacity.ParentQueue: Re-sorting queues since queue: root.default stats: default: capacity=1.0, absoluteCapacity=1.0, usedResources=<memory:27648, vCores:22>usedCapacity=0.5625, absoluteUsedCapacity=0.5625, numApps=5, numContainers=22
2013-08-16 20:51:30,867 INFO org.apache.hadoop.yarn.server.resourcemanager.scheduler.capacity.ParentQueue: assignedContainer queue=root usedCapacity=0.5625 absoluteUsedCapacity=0.5625 used=<memory:27648, vCores:22> cluster=<memory:49152, vCores:96>
2013-08-16 20:51:30,868 INFO org.apache.hadoop.yarn.server.resourcemanager.rmcontainer.RMContainerImpl: container_1376685566219_0006_01_000019 Container Transitioned from NEW to ALLOCATED
2013-08-16 20:51:30,868 INFO org.apache.hadoop.yarn.server.resourcemanager.RMAuditLogger: USER=ubuntu	OPERATION=AM Allocated Container	TARGET=SchedulerApp	RESULT=SUCCESS	APPID=application_1376685566219_0006	CONTAINERID=container_1376685566219_0006_01_000019
2013-08-16 20:51:30,868 INFO org.apache.hadoop.yarn.server.resourcemanager.scheduler.common.fica.FiCaSchedulerNode: Assigned container container_1376685566219_0006_01_000019 of capacity <memory:1024, vCores:1> on host hadoop-512-3:58863, which currently has 7 containers, <memory:8192, vCores:7> used and <memory:0, vCores:9> available
2013-08-16 20:51:30,869 INFO org.apache.hadoop.yarn.server.resourcemanager.scheduler.capacity.LeafQueue: assignedContainer application=application_1376685566219_0006 container=Container: [ContainerId: container_1376685566219_0006_01_000019, NodeId: hadoop-512-3:58863, NodeHttpAddress: hadoop-512-3:8042, Resource: <memory:1024, vCores:1>, Priority: 20, State: NEW, Token: null, Status: container_id {, app_attempt_id {, application_id {, id: 6, cluster_timestamp: 1376685566219, }, attemptId: 1, }, id: 19, }, state: C_NEW, ] containerId=container_1376685566219_0006_01_000019 queue=default: capacity=1.0, absoluteCapacity=1.0, usedResources=<memory:27648, vCores:22>usedCapacity=0.5625, absoluteUsedCapacity=0.5625, numApps=5, numContainers=22 usedCapacity=0.5625 absoluteUsedCapacity=0.5625 used=<memory:27648, vCores:22> cluster=<memory:49152, vCores:96>
2013-08-16 20:51:30,869 INFO org.apache.hadoop.yarn.server.resourcemanager.scheduler.capacity.ParentQueue: Re-sorting queues since queue: root.default stats: default: capacity=1.0, absoluteCapacity=1.0, usedResources=<memory:28672, vCores:23>usedCapacity=0.5833333, absoluteUsedCapacity=0.5833333, numApps=5, numContainers=23
2013-08-16 20:51:30,869 INFO org.apache.hadoop.yarn.server.resourcemanager.scheduler.capacity.ParentQueue: assignedContainer queue=root usedCapacity=0.5833333 absoluteUsedCapacity=0.5833333 used=<memory:28672, vCores:23> cluster=<memory:49152, vCores:96>
2013-08-16 20:51:30,887 INFO org.apache.hadoop.yarn.server.resourcemanager.ApplicationMasterService: AM registration appattempt_1376685566219_0008_000001
2013-08-16 20:51:30,888 INFO org.apache.hadoop.yarn.server.resourcemanager.RMAuditLogger: USER=ubuntu	IP=192.168.100.32	OPERATION=Register App Master	TARGET=ApplicationMasterService	RESULT=SUCCESS	APPID=application_1376685566219_0008	APPATTEMPTID=appattempt_1376685566219_0008_000001
2013-08-16 20:51:30,889 INFO org.apache.hadoop.yarn.server.resourcemanager.rmapp.attempt.RMAppAttemptImpl: appattempt_1376685566219_0008_000001 State change from LAUNCHED to RUNNING
2013-08-16 20:51:30,889 INFO org.apache.hadoop.yarn.server.resourcemanager.rmapp.RMAppImpl: application_1376685566219_0008 State change from ACCEPTED to RUNNING
2013-08-16 20:51:31,205 INFO org.apache.hadoop.yarn.server.resourcemanager.rmcontainer.RMContainerImpl: container_1376685566219_0006_01_000020 Container Transitioned from NEW to ALLOCATED
2013-08-16 20:51:31,205 INFO org.apache.hadoop.yarn.server.resourcemanager.RMAuditLogger: USER=ubuntu	OPERATION=AM Allocated Container	TARGET=SchedulerApp	RESULT=SUCCESS	APPID=application_1376685566219_0006	CONTAINERID=container_1376685566219_0006_01_000020
2013-08-16 20:51:31,206 INFO org.apache.hadoop.yarn.server.resourcemanager.scheduler.common.fica.FiCaSchedulerNode: Assigned container container_1376685566219_0006_01_000020 of capacity <memory:1024, vCores:1> on host hadoop-512-2:41669, which currently has 2 containers, <memory:3072, vCores:2> used and <memory:5120, vCores:14> available
2013-08-16 20:51:31,207 INFO org.apache.hadoop.yarn.server.resourcemanager.scheduler.capacity.LeafQueue: assignedContainer application=application_1376685566219_0006 container=Container: [ContainerId: container_1376685566219_0006_01_000020, NodeId: hadoop-512-2:41669, NodeHttpAddress: hadoop-512-2:8042, Resource: <memory:1024, vCores:1>, Priority: 20, State: NEW, Token: null, Status: container_id {, app_attempt_id {, application_id {, id: 6, cluster_timestamp: 1376685566219, }, attemptId: 1, }, id: 20, }, state: C_NEW, ] containerId=container_1376685566219_0006_01_000020 queue=default: capacity=1.0, absoluteCapacity=1.0, usedResources=<memory:28672, vCores:23>usedCapacity=0.5833333, absoluteUsedCapacity=0.5833333, numApps=5, numContainers=23 usedCapacity=0.5833333 absoluteUsedCapacity=0.5833333 used=<memory:28672, vCores:23> cluster=<memory:49152, vCores:96>
2013-08-16 20:51:31,207 INFO org.apache.hadoop.yarn.server.resourcemanager.scheduler.capacity.ParentQueue: Re-sorting queues since queue: root.default stats: default: capacity=1.0, absoluteCapacity=1.0, usedResources=<memory:29696, vCores:24>usedCapacity=0.6041667, absoluteUsedCapacity=0.6041667, numApps=5, numContainers=24
2013-08-16 20:51:31,207 INFO org.apache.hadoop.yarn.server.resourcemanager.scheduler.capacity.ParentQueue: assignedContainer queue=root usedCapacity=0.6041667 absoluteUsedCapacity=0.6041667 used=<memory:29696, vCores:24> cluster=<memory:49152, vCores:96>
2013-08-16 20:51:31,208 INFO org.apache.hadoop.yarn.server.resourcemanager.rmcontainer.RMContainerImpl: container_1376685566219_0006_01_000021 Container Transitioned from NEW to ALLOCATED
2013-08-16 20:51:31,208 INFO org.apache.hadoop.yarn.server.resourcemanager.RMAuditLogger: USER=ubuntu	OPERATION=AM Allocated Container	TARGET=SchedulerApp	RESULT=SUCCESS	APPID=application_1376685566219_0006	CONTAINERID=container_1376685566219_0006_01_000021
2013-08-16 20:51:31,208 INFO org.apache.hadoop.yarn.server.resourcemanager.scheduler.common.fica.FiCaSchedulerNode: Assigned container container_1376685566219_0006_01_000021 of capacity <memory:1024, vCores:1> on host hadoop-512-2:41669, which currently has 3 containers, <memory:4096, vCores:3> used and <memory:4096, vCores:13> available
2013-08-16 20:51:31,209 INFO org.apache.hadoop.yarn.server.resourcemanager.scheduler.capacity.LeafQueue: assignedContainer application=application_1376685566219_0006 container=Container: [ContainerId: container_1376685566219_0006_01_000021, NodeId: hadoop-512-2:41669, NodeHttpAddress: hadoop-512-2:8042, Resource: <memory:1024, vCores:1>, Priority: 20, State: NEW, Token: null, Status: container_id {, app_attempt_id {, application_id {, id: 6, cluster_timestamp: 1376685566219, }, attemptId: 1, }, id: 21, }, state: C_NEW, ] containerId=container_1376685566219_0006_01_000021 queue=default: capacity=1.0, absoluteCapacity=1.0, usedResources=<memory:29696, vCores:24>usedCapacity=0.6041667, absoluteUsedCapacity=0.6041667, numApps=5, numContainers=24 usedCapacity=0.6041667 absoluteUsedCapacity=0.6041667 used=<memory:29696, vCores:24> cluster=<memory:49152, vCores:96>
2013-08-16 20:51:31,209 INFO org.apache.hadoop.yarn.server.resourcemanager.scheduler.capacity.ParentQueue: Re-sorting queues since queue: root.default stats: default: capacity=1.0, absoluteCapacity=1.0, usedResources=<memory:30720, vCores:25>usedCapacity=0.625, absoluteUsedCapacity=0.625, numApps=5, numContainers=25
2013-08-16 20:51:31,209 INFO org.apache.hadoop.yarn.server.resourcemanager.scheduler.capacity.ParentQueue: assignedContainer queue=root usedCapacity=0.625 absoluteUsedCapacity=0.625 used=<memory:30720, vCores:25> cluster=<memory:49152, vCores:96>
2013-08-16 20:51:31,210 INFO org.apache.hadoop.yarn.server.resourcemanager.rmcontainer.RMContainerImpl: container_1376685566219_0006_01_000022 Container Transitioned from NEW to ALLOCATED
2013-08-16 20:51:31,210 INFO org.apache.hadoop.yarn.server.resourcemanager.RMAuditLogger: USER=ubuntu	OPERATION=AM Allocated Container	TARGET=SchedulerApp	RESULT=SUCCESS	APPID=application_1376685566219_0006	CONTAINERID=container_1376685566219_0006_01_000022
2013-08-16 20:51:31,211 INFO org.apache.hadoop.yarn.server.resourcemanager.scheduler.common.fica.FiCaSchedulerNode: Assigned container container_1376685566219_0006_01_000022 of capacity <memory:1024, vCores:1> on host hadoop-512-2:41669, which currently has 4 containers, <memory:5120, vCores:4> used and <memory:3072, vCores:12> available
2013-08-16 20:51:31,211 INFO org.apache.hadoop.yarn.server.resourcemanager.scheduler.capacity.LeafQueue: assignedContainer application=application_1376685566219_0006 container=Container: [ContainerId: container_1376685566219_0006_01_000022, NodeId: hadoop-512-2:41669, NodeHttpAddress: hadoop-512-2:8042, Resource: <memory:1024, vCores:1>, Priority: 20, State: NEW, Token: null, Status: container_id {, app_attempt_id {, application_id {, id: 6, cluster_timestamp: 1376685566219, }, attemptId: 1, }, id: 22, }, state: C_NEW, ] containerId=container_1376685566219_0006_01_000022 queue=default: capacity=1.0, absoluteCapacity=1.0, usedResources=<memory:30720, vCores:25>usedCapacity=0.625, absoluteUsedCapacity=0.625, numApps=5, numContainers=25 usedCapacity=0.625 absoluteUsedCapacity=0.625 used=<memory:30720, vCores:25> cluster=<memory:49152, vCores:96>
2013-08-16 20:51:31,212 INFO org.apache.hadoop.yarn.server.resourcemanager.scheduler.capacity.ParentQueue: Re-sorting queues since queue: root.default stats: default: capacity=1.0, absoluteCapacity=1.0, usedResources=<memory:31744, vCores:26>usedCapacity=0.6458333, absoluteUsedCapacity=0.6458333, numApps=5, numContainers=26
2013-08-16 20:51:31,212 INFO org.apache.hadoop.yarn.server.resourcemanager.scheduler.capacity.ParentQueue: assignedContainer queue=root usedCapacity=0.6458333 absoluteUsedCapacity=0.6458333 used=<memory:31744, vCores:26> cluster=<memory:49152, vCores:96>
2013-08-16 20:51:31,212 INFO org.apache.hadoop.yarn.server.resourcemanager.rmcontainer.RMContainerImpl: container_1376685566219_0006_01_000023 Container Transitioned from NEW to ALLOCATED
2013-08-16 20:51:31,213 INFO org.apache.hadoop.yarn.server.resourcemanager.RMAuditLogger: USER=ubuntu	OPERATION=AM Allocated Container	TARGET=SchedulerApp	RESULT=SUCCESS	APPID=application_1376685566219_0006	CONTAINERID=container_1376685566219_0006_01_000023
2013-08-16 20:51:31,213 INFO org.apache.hadoop.yarn.server.resourcemanager.scheduler.common.fica.FiCaSchedulerNode: Assigned container container_1376685566219_0006_01_000023 of capacity <memory:1024, vCores:1> on host hadoop-512-2:41669, which currently has 5 containers, <memory:6144, vCores:5> used and <memory:2048, vCores:11> available
2013-08-16 20:51:31,214 INFO org.apache.hadoop.yarn.server.resourcemanager.scheduler.capacity.LeafQueue: assignedContainer application=application_1376685566219_0006 container=Container: [ContainerId: container_1376685566219_0006_01_000023, NodeId: hadoop-512-2:41669, NodeHttpAddress: hadoop-512-2:8042, Resource: <memory:1024, vCores:1>, Priority: 20, State: NEW, Token: null, Status: container_id {, app_attempt_id {, application_id {, id: 6, cluster_timestamp: 1376685566219, }, attemptId: 1, }, id: 23, }, state: C_NEW, ] containerId=container_1376685566219_0006_01_000023 queue=default: capacity=1.0, absoluteCapacity=1.0, usedResources=<memory:31744, vCores:26>usedCapacity=0.6458333, absoluteUsedCapacity=0.6458333, numApps=5, numContainers=26 usedCapacity=0.6458333 absoluteUsedCapacity=0.6458333 used=<memory:31744, vCores:26> cluster=<memory:49152, vCores:96>
2013-08-16 20:51:31,214 INFO org.apache.hadoop.yarn.server.resourcemanager.scheduler.capacity.ParentQueue: Re-sorting queues since queue: root.default stats: default: capacity=1.0, absoluteCapacity=1.0, usedResources=<memory:32768, vCores:27>usedCapacity=0.6666667, absoluteUsedCapacity=0.6666667, numApps=5, numContainers=27
2013-08-16 20:51:31,214 INFO org.apache.hadoop.yarn.server.resourcemanager.scheduler.capacity.ParentQueue: assignedContainer queue=root usedCapacity=0.6666667 absoluteUsedCapacity=0.6666667 used=<memory:32768, vCores:27> cluster=<memory:49152, vCores:96>
2013-08-16 20:51:31,215 INFO org.apache.hadoop.yarn.server.resourcemanager.rmcontainer.RMContainerImpl: container_1376685566219_0006_01_000024 Container Transitioned from NEW to ALLOCATED
2013-08-16 20:51:31,215 INFO org.apache.hadoop.yarn.server.resourcemanager.RMAuditLogger: USER=ubuntu	OPERATION=AM Allocated Container	TARGET=SchedulerApp	RESULT=SUCCESS	APPID=application_1376685566219_0006	CONTAINERID=container_1376685566219_0006_01_000024
2013-08-16 20:51:31,215 INFO org.apache.hadoop.yarn.server.resourcemanager.scheduler.common.fica.FiCaSchedulerNode: Assigned container container_1376685566219_0006_01_000024 of capacity <memory:1024, vCores:1> on host hadoop-512-2:41669, which currently has 6 containers, <memory:7168, vCores:6> used and <memory:1024, vCores:10> available
2013-08-16 20:51:31,216 INFO org.apache.hadoop.yarn.server.resourcemanager.scheduler.capacity.LeafQueue: assignedContainer application=application_1376685566219_0006 container=Container: [ContainerId: container_1376685566219_0006_01_000024, NodeId: hadoop-512-2:41669, NodeHttpAddress: hadoop-512-2:8042, Resource: <memory:1024, vCores:1>, Priority: 20, State: NEW, Token: null, Status: container_id {, app_attempt_id {, application_id {, id: 6, cluster_timestamp: 1376685566219, }, attemptId: 1, }, id: 24, }, state: C_NEW, ] containerId=container_1376685566219_0006_01_000024 queue=default: capacity=1.0, absoluteCapacity=1.0, usedResources=<memory:32768, vCores:27>usedCapacity=0.6666667, absoluteUsedCapacity=0.6666667, numApps=5, numContainers=27 usedCapacity=0.6666667 absoluteUsedCapacity=0.6666667 used=<memory:32768, vCores:27> cluster=<memory:49152, vCores:96>
2013-08-16 20:51:31,216 INFO org.apache.hadoop.yarn.server.resourcemanager.scheduler.capacity.ParentQueue: Re-sorting queues since queue: root.default stats: default: capacity=1.0, absoluteCapacity=1.0, usedResources=<memory:33792, vCores:28>usedCapacity=0.6875, absoluteUsedCapacity=0.6875, numApps=5, numContainers=28
2013-08-16 20:51:31,216 INFO org.apache.hadoop.yarn.server.resourcemanager.scheduler.capacity.ParentQueue: assignedContainer queue=root usedCapacity=0.6875 absoluteUsedCapacity=0.6875 used=<memory:33792, vCores:28> cluster=<memory:49152, vCores:96>
2013-08-16 20:51:31,217 INFO org.apache.hadoop.yarn.server.resourcemanager.rmcontainer.RMContainerImpl: container_1376685566219_0006_01_000025 Container Transitioned from NEW to ALLOCATED
2013-08-16 20:51:31,217 INFO org.apache.hadoop.yarn.server.resourcemanager.RMAuditLogger: USER=ubuntu	OPERATION=AM Allocated Container	TARGET=SchedulerApp	RESULT=SUCCESS	APPID=application_1376685566219_0006	CONTAINERID=container_1376685566219_0006_01_000025
2013-08-16 20:51:31,217 INFO org.apache.hadoop.yarn.server.resourcemanager.scheduler.common.fica.FiCaSchedulerNode: Assigned container container_1376685566219_0006_01_000025 of capacity <memory:1024, vCores:1> on host hadoop-512-2:41669, which currently has 7 containers, <memory:8192, vCores:7> used and <memory:0, vCores:9> available
2013-08-16 20:51:31,218 INFO org.apache.hadoop.yarn.server.resourcemanager.scheduler.capacity.LeafQueue: assignedContainer application=application_1376685566219_0006 container=Container: [ContainerId: container_1376685566219_0006_01_000025, NodeId: hadoop-512-2:41669, NodeHttpAddress: hadoop-512-2:8042, Resource: <memory:1024, vCores:1>, Priority: 20, State: NEW, Token: null, Status: container_id {, app_attempt_id {, application_id {, id: 6, cluster_timestamp: 1376685566219, }, attemptId: 1, }, id: 25, }, state: C_NEW, ] containerId=container_1376685566219_0006_01_000025 queue=default: capacity=1.0, absoluteCapacity=1.0, usedResources=<memory:33792, vCores:28>usedCapacity=0.6875, absoluteUsedCapacity=0.6875, numApps=5, numContainers=28 usedCapacity=0.6875 absoluteUsedCapacity=0.6875 used=<memory:33792, vCores:28> cluster=<memory:49152, vCores:96>
2013-08-16 20:51:31,218 INFO org.apache.hadoop.yarn.server.resourcemanager.scheduler.capacity.ParentQueue: Re-sorting queues since queue: root.default stats: default: capacity=1.0, absoluteCapacity=1.0, usedResources=<memory:34816, vCores:29>usedCapacity=0.7083333, absoluteUsedCapacity=0.7083333, numApps=5, numContainers=29
2013-08-16 20:51:31,219 INFO org.apache.hadoop.yarn.server.resourcemanager.scheduler.capacity.ParentQueue: assignedContainer queue=root usedCapacity=0.7083333 absoluteUsedCapacity=0.7083333 used=<memory:34816, vCores:29> cluster=<memory:49152, vCores:96>
2013-08-16 20:51:31,262 INFO org.apache.hadoop.yarn.server.resourcemanager.ApplicationMasterService: AM registration appattempt_1376685566219_0010_000001
2013-08-16 20:51:31,263 INFO org.apache.hadoop.yarn.server.resourcemanager.RMAuditLogger: USER=ubuntu	IP=192.168.100.8	OPERATION=Register App Master	TARGET=ApplicationMasterService	RESULT=SUCCESS	APPID=application_1376685566219_0010	APPATTEMPTID=appattempt_1376685566219_0010_000001
2013-08-16 20:51:31,264 INFO org.apache.hadoop.yarn.server.resourcemanager.rmapp.attempt.RMAppAttemptImpl: appattempt_1376685566219_0010_000001 State change from LAUNCHED to RUNNING
2013-08-16 20:51:31,264 INFO org.apache.hadoop.yarn.server.resourcemanager.rmapp.RMAppImpl: application_1376685566219_0010 State change from ACCEPTED to RUNNING
2013-08-16 20:51:31,275 INFO org.apache.hadoop.yarn.server.resourcemanager.rmcontainer.RMContainerImpl: container_1376685566219_0006_01_000026 Container Transitioned from NEW to ALLOCATED
2013-08-16 20:51:31,275 INFO org.apache.hadoop.yarn.server.resourcemanager.RMAuditLogger: USER=ubuntu	OPERATION=AM Allocated Container	TARGET=SchedulerApp	RESULT=SUCCESS	APPID=application_1376685566219_0006	CONTAINERID=container_1376685566219_0006_01_000026
2013-08-16 20:51:31,275 INFO org.apache.hadoop.yarn.server.resourcemanager.scheduler.common.fica.FiCaSchedulerNode: Assigned container container_1376685566219_0006_01_000026 of capacity <memory:1024, vCores:1> on host hadoop-512-5:53603, which currently has 2 containers, <memory:3072, vCores:2> used and <memory:5120, vCores:14> available
2013-08-16 20:51:31,276 INFO org.apache.hadoop.yarn.server.resourcemanager.scheduler.capacity.LeafQueue: assignedContainer application=application_1376685566219_0006 container=Container: [ContainerId: container_1376685566219_0006_01_000026, NodeId: hadoop-512-5:53603, NodeHttpAddress: hadoop-512-5:8042, Resource: <memory:1024, vCores:1>, Priority: 20, State: NEW, Token: null, Status: container_id {, app_attempt_id {, application_id {, id: 6, cluster_timestamp: 1376685566219, }, attemptId: 1, }, id: 26, }, state: C_NEW, ] containerId=container_1376685566219_0006_01_000026 queue=default: capacity=1.0, absoluteCapacity=1.0, usedResources=<memory:34816, vCores:29>usedCapacity=0.7083333, absoluteUsedCapacity=0.7083333, numApps=5, numContainers=29 usedCapacity=0.7083333 absoluteUsedCapacity=0.7083333 used=<memory:34816, vCores:29> cluster=<memory:49152, vCores:96>
2013-08-16 20:51:31,276 INFO org.apache.hadoop.yarn.server.resourcemanager.scheduler.capacity.ParentQueue: Re-sorting queues since queue: root.default stats: default: capacity=1.0, absoluteCapacity=1.0, usedResources=<memory:35840, vCores:30>usedCapacity=0.7291667, absoluteUsedCapacity=0.7291667, numApps=5, numContainers=30
2013-08-16 20:51:31,277 INFO org.apache.hadoop.yarn.server.resourcemanager.scheduler.capacity.ParentQueue: assignedContainer queue=root usedCapacity=0.7291667 absoluteUsedCapacity=0.7291667 used=<memory:35840, vCores:30> cluster=<memory:49152, vCores:96>
2013-08-16 20:51:31,277 INFO org.apache.hadoop.yarn.server.resourcemanager.rmcontainer.RMContainerImpl: container_1376685566219_0006_01_000027 Container Transitioned from NEW to ALLOCATED
2013-08-16 20:51:31,277 INFO org.apache.hadoop.yarn.server.resourcemanager.RMAuditLogger: USER=ubuntu	OPERATION=AM Allocated Container	TARGET=SchedulerApp	RESULT=SUCCESS	APPID=application_1376685566219_0006	CONTAINERID=container_1376685566219_0006_01_000027
2013-08-16 20:51:31,277 INFO org.apache.hadoop.yarn.server.resourcemanager.scheduler.common.fica.FiCaSchedulerNode: Assigned container container_1376685566219_0006_01_000027 of capacity <memory:1024, vCores:1> on host hadoop-512-5:53603, which currently has 3 containers, <memory:4096, vCores:3> used and <memory:4096, vCores:13> available
2013-08-16 20:51:31,278 INFO org.apache.hadoop.yarn.server.resourcemanager.scheduler.capacity.LeafQueue: assignedContainer application=application_1376685566219_0006 container=Container: [ContainerId: container_1376685566219_0006_01_000027, NodeId: hadoop-512-5:53603, NodeHttpAddress: hadoop-512-5:8042, Resource: <memory:1024, vCores:1>, Priority: 20, State: NEW, Token: null, Status: container_id {, app_attempt_id {, application_id {, id: 6, cluster_timestamp: 1376685566219, }, attemptId: 1, }, id: 27, }, state: C_NEW, ] containerId=container_1376685566219_0006_01_000027 queue=default: capacity=1.0, absoluteCapacity=1.0, usedResources=<memory:35840, vCores:30>usedCapacity=0.7291667, absoluteUsedCapacity=0.7291667, numApps=5, numContainers=30 usedCapacity=0.7291667 absoluteUsedCapacity=0.7291667 used=<memory:35840, vCores:30> cluster=<memory:49152, vCores:96>
2013-08-16 20:51:31,279 INFO org.apache.hadoop.yarn.server.resourcemanager.scheduler.capacity.ParentQueue: Re-sorting queues since queue: root.default stats: default: capacity=1.0, absoluteCapacity=1.0, usedResources=<memory:36864, vCores:31>usedCapacity=0.75, absoluteUsedCapacity=0.75, numApps=5, numContainers=31
2013-08-16 20:51:31,279 INFO org.apache.hadoop.yarn.server.resourcemanager.scheduler.capacity.ParentQueue: assignedContainer queue=root usedCapacity=0.75 absoluteUsedCapacity=0.75 used=<memory:36864, vCores:31> cluster=<memory:49152, vCores:96>
2013-08-16 20:51:31,279 INFO org.apache.hadoop.yarn.server.resourcemanager.rmcontainer.RMContainerImpl: container_1376685566219_0006_01_000028 Container Transitioned from NEW to ALLOCATED
2013-08-16 20:51:31,280 INFO org.apache.hadoop.yarn.server.resourcemanager.RMAuditLogger: USER=ubuntu	OPERATION=AM Allocated Container	TARGET=SchedulerApp	RESULT=SUCCESS	APPID=application_1376685566219_0006	CONTAINERID=container_1376685566219_0006_01_000028
2013-08-16 20:51:31,280 INFO org.apache.hadoop.yarn.server.resourcemanager.scheduler.common.fica.FiCaSchedulerNode: Assigned container container_1376685566219_0006_01_000028 of capacity <memory:1024, vCores:1> on host hadoop-512-5:53603, which currently has 4 containers, <memory:5120, vCores:4> used and <memory:3072, vCores:12> available
2013-08-16 20:51:31,281 INFO org.apache.hadoop.yarn.server.resourcemanager.scheduler.capacity.LeafQueue: assignedContainer application=application_1376685566219_0006 container=Container: [ContainerId: container_1376685566219_0006_01_000028, NodeId: hadoop-512-5:53603, NodeHttpAddress: hadoop-512-5:8042, Resource: <memory:1024, vCores:1>, Priority: 20, State: NEW, Token: null, Status: container_id {, app_attempt_id {, application_id {, id: 6, cluster_timestamp: 1376685566219, }, attemptId: 1, }, id: 28, }, state: C_NEW, ] containerId=container_1376685566219_0006_01_000028 queue=default: capacity=1.0, absoluteCapacity=1.0, usedResources=<memory:36864, vCores:31>usedCapacity=0.75, absoluteUsedCapacity=0.75, numApps=5, numContainers=31 usedCapacity=0.75 absoluteUsedCapacity=0.75 used=<memory:36864, vCores:31> cluster=<memory:49152, vCores:96>
2013-08-16 20:51:31,281 INFO org.apache.hadoop.yarn.server.resourcemanager.scheduler.capacity.ParentQueue: Re-sorting queues since queue: root.default stats: default: capacity=1.0, absoluteCapacity=1.0, usedResources=<memory:37888, vCores:32>usedCapacity=0.7708333, absoluteUsedCapacity=0.7708333, numApps=5, numContainers=32
2013-08-16 20:51:31,281 INFO org.apache.hadoop.yarn.server.resourcemanager.scheduler.capacity.ParentQueue: assignedContainer queue=root usedCapacity=0.7708333 absoluteUsedCapacity=0.7708333 used=<memory:37888, vCores:32> cluster=<memory:49152, vCores:96>
2013-08-16 20:51:31,281 INFO org.apache.hadoop.yarn.server.resourcemanager.rmcontainer.RMContainerImpl: container_1376685566219_0006_01_000029 Container Transitioned from NEW to ALLOCATED
2013-08-16 20:51:31,282 INFO org.apache.hadoop.yarn.server.resourcemanager.RMAuditLogger: USER=ubuntu	OPERATION=AM Allocated Container	TARGET=SchedulerApp	RESULT=SUCCESS	APPID=application_1376685566219_0006	CONTAINERID=container_1376685566219_0006_01_000029
2013-08-16 20:51:31,282 INFO org.apache.hadoop.yarn.server.resourcemanager.scheduler.common.fica.FiCaSchedulerNode: Assigned container container_1376685566219_0006_01_000029 of capacity <memory:1024, vCores:1> on host hadoop-512-5:53603, which currently has 5 containers, <memory:6144, vCores:5> used and <memory:2048, vCores:11> available
2013-08-16 20:51:31,283 INFO org.apache.hadoop.yarn.server.resourcemanager.scheduler.capacity.LeafQueue: assignedContainer application=application_1376685566219_0006 container=Container: [ContainerId: container_1376685566219_0006_01_000029, NodeId: hadoop-512-5:53603, NodeHttpAddress: hadoop-512-5:8042, Resource: <memory:1024, vCores:1>, Priority: 20, State: NEW, Token: null, Status: container_id {, app_attempt_id {, application_id {, id: 6, cluster_timestamp: 1376685566219, }, attemptId: 1, }, id: 29, }, state: C_NEW, ] containerId=container_1376685566219_0006_01_000029 queue=default: capacity=1.0, absoluteCapacity=1.0, usedResources=<memory:37888, vCores:32>usedCapacity=0.7708333, absoluteUsedCapacity=0.7708333, numApps=5, numContainers=32 usedCapacity=0.7708333 absoluteUsedCapacity=0.7708333 used=<memory:37888, vCores:32> cluster=<memory:49152, vCores:96>
2013-08-16 20:51:31,283 INFO org.apache.hadoop.yarn.server.resourcemanager.scheduler.capacity.ParentQueue: Re-sorting queues since queue: root.default stats: default: capacity=1.0, absoluteCapacity=1.0, usedResources=<memory:38912, vCores:33>usedCapacity=0.7916667, absoluteUsedCapacity=0.7916667, numApps=5, numContainers=33
2013-08-16 20:51:31,283 INFO org.apache.hadoop.yarn.server.resourcemanager.scheduler.capacity.ParentQueue: assignedContainer queue=root usedCapacity=0.7916667 absoluteUsedCapacity=0.7916667 used=<memory:38912, vCores:33> cluster=<memory:49152, vCores:96>
2013-08-16 20:51:31,284 INFO org.apache.hadoop.yarn.server.resourcemanager.rmcontainer.RMContainerImpl: container_1376685566219_0006_01_000030 Container Transitioned from NEW to ALLOCATED
2013-08-16 20:51:31,284 INFO org.apache.hadoop.yarn.server.resourcemanager.RMAuditLogger: USER=ubuntu	OPERATION=AM Allocated Container	TARGET=SchedulerApp	RESULT=SUCCESS	APPID=application_1376685566219_0006	CONTAINERID=container_1376685566219_0006_01_000030
2013-08-16 20:51:31,284 INFO org.apache.hadoop.yarn.server.resourcemanager.scheduler.common.fica.FiCaSchedulerNode: Assigned container container_1376685566219_0006_01_000030 of capacity <memory:1024, vCores:1> on host hadoop-512-5:53603, which currently has 6 containers, <memory:7168, vCores:6> used and <memory:1024, vCores:10> available
2013-08-16 20:51:31,285 INFO org.apache.hadoop.yarn.server.resourcemanager.scheduler.capacity.LeafQueue: assignedContainer application=application_1376685566219_0006 container=Container: [ContainerId: container_1376685566219_0006_01_000030, NodeId: hadoop-512-5:53603, NodeHttpAddress: hadoop-512-5:8042, Resource: <memory:1024, vCores:1>, Priority: 20, State: NEW, Token: null, Status: container_id {, app_attempt_id {, application_id {, id: 6, cluster_timestamp: 1376685566219, }, attemptId: 1, }, id: 30, }, state: C_NEW, ] containerId=container_1376685566219_0006_01_000030 queue=default: capacity=1.0, absoluteCapacity=1.0, usedResources=<memory:38912, vCores:33>usedCapacity=0.7916667, absoluteUsedCapacity=0.7916667, numApps=5, numContainers=33 usedCapacity=0.7916667 absoluteUsedCapacity=0.7916667 used=<memory:38912, vCores:33> cluster=<memory:49152, vCores:96>
2013-08-16 20:51:31,285 INFO org.apache.hadoop.yarn.server.resourcemanager.scheduler.capacity.ParentQueue: Re-sorting queues since queue: root.default stats: default: capacity=1.0, absoluteCapacity=1.0, usedResources=<memory:39936, vCores:34>usedCapacity=0.8125, absoluteUsedCapacity=0.8125, numApps=5, numContainers=34
2013-08-16 20:51:31,285 INFO org.apache.hadoop.yarn.server.resourcemanager.scheduler.capacity.ParentQueue: assignedContainer queue=root usedCapacity=0.8125 absoluteUsedCapacity=0.8125 used=<memory:39936, vCores:34> cluster=<memory:49152, vCores:96>
2013-08-16 20:51:31,286 INFO org.apache.hadoop.yarn.server.resourcemanager.rmcontainer.RMContainerImpl: container_1376685566219_0006_01_000031 Container Transitioned from NEW to ALLOCATED
2013-08-16 20:51:31,286 INFO org.apache.hadoop.yarn.server.resourcemanager.RMAuditLogger: USER=ubuntu	OPERATION=AM Allocated Container	TARGET=SchedulerApp	RESULT=SUCCESS	APPID=application_1376685566219_0006	CONTAINERID=container_1376685566219_0006_01_000031
2013-08-16 20:51:31,286 INFO org.apache.hadoop.yarn.server.resourcemanager.scheduler.common.fica.FiCaSchedulerNode: Assigned container container_1376685566219_0006_01_000031 of capacity <memory:1024, vCores:1> on host hadoop-512-5:53603, which currently has 7 containers, <memory:8192, vCores:7> used and <memory:0, vCores:9> available
2013-08-16 20:51:31,287 INFO org.apache.hadoop.yarn.server.resourcemanager.scheduler.capacity.LeafQueue: assignedContainer application=application_1376685566219_0006 container=Container: [ContainerId: container_1376685566219_0006_01_000031, NodeId: hadoop-512-5:53603, NodeHttpAddress: hadoop-512-5:8042, Resource: <memory:1024, vCores:1>, Priority: 20, State: NEW, Token: null, Status: container_id {, app_attempt_id {, application_id {, id: 6, cluster_timestamp: 1376685566219, }, attemptId: 1, }, id: 31, }, state: C_NEW, ] containerId=container_1376685566219_0006_01_000031 queue=default: capacity=1.0, absoluteCapacity=1.0, usedResources=<memory:39936, vCores:34>usedCapacity=0.8125, absoluteUsedCapacity=0.8125, numApps=5, numContainers=34 usedCapacity=0.8125 absoluteUsedCapacity=0.8125 used=<memory:39936, vCores:34> cluster=<memory:49152, vCores:96>
2013-08-16 20:51:31,287 INFO org.apache.hadoop.yarn.server.resourcemanager.scheduler.capacity.ParentQueue: Re-sorting queues since queue: root.default stats: default: capacity=1.0, absoluteCapacity=1.0, usedResources=<memory:40960, vCores:35>usedCapacity=0.8333333, absoluteUsedCapacity=0.8333333, numApps=5, numContainers=35
2013-08-16 20:51:31,287 INFO org.apache.hadoop.yarn.server.resourcemanager.scheduler.capacity.ParentQueue: assignedContainer queue=root usedCapacity=0.8333333 absoluteUsedCapacity=0.8333333 used=<memory:40960, vCores:35> cluster=<memory:49152, vCores:96>
2013-08-16 20:51:31,330 INFO org.apache.hadoop.yarn.server.resourcemanager.rmcontainer.RMContainerImpl: container_1376685566219_0006_01_000032 Container Transitioned from NEW to ALLOCATED
2013-08-16 20:51:31,330 INFO org.apache.hadoop.yarn.server.resourcemanager.RMAuditLogger: USER=ubuntu	OPERATION=AM Allocated Container	TARGET=SchedulerApp	RESULT=SUCCESS	APPID=application_1376685566219_0006	CONTAINERID=container_1376685566219_0006_01_000032
2013-08-16 20:51:31,331 INFO org.apache.hadoop.yarn.server.resourcemanager.scheduler.common.fica.FiCaSchedulerNode: Assigned container container_1376685566219_0006_01_000032 of capacity <memory:1024, vCores:1> on host hadoop-512-4:51823, which currently has 1 containers, <memory:1024, vCores:1> used and <memory:7168, vCores:15> available
2013-08-16 20:51:31,332 INFO org.apache.hadoop.yarn.server.resourcemanager.scheduler.capacity.LeafQueue: assignedContainer application=application_1376685566219_0006 container=Container: [ContainerId: container_1376685566219_0006_01_000032, NodeId: hadoop-512-4:51823, NodeHttpAddress: hadoop-512-4:8042, Resource: <memory:1024, vCores:1>, Priority: 20, State: NEW, Token: null, Status: container_id {, app_attempt_id {, application_id {, id: 6, cluster_timestamp: 1376685566219, }, attemptId: 1, }, id: 32, }, state: C_NEW, ] containerId=container_1376685566219_0006_01_000032 queue=default: capacity=1.0, absoluteCapacity=1.0, usedResources=<memory:40960, vCores:35>usedCapacity=0.8333333, absoluteUsedCapacity=0.8333333, numApps=5, numContainers=35 usedCapacity=0.8333333 absoluteUsedCapacity=0.8333333 used=<memory:40960, vCores:35> cluster=<memory:49152, vCores:96>
2013-08-16 20:51:31,332 INFO org.apache.hadoop.yarn.server.resourcemanager.scheduler.capacity.ParentQueue: Re-sorting queues since queue: root.default stats: default: capacity=1.0, absoluteCapacity=1.0, usedResources=<memory:41984, vCores:36>usedCapacity=0.8541667, absoluteUsedCapacity=0.8541667, numApps=5, numContainers=36
2013-08-16 20:51:31,332 INFO org.apache.hadoop.yarn.server.resourcemanager.scheduler.capacity.ParentQueue: assignedContainer queue=root usedCapacity=0.8541667 absoluteUsedCapacity=0.8541667 used=<memory:41984, vCores:36> cluster=<memory:49152, vCores:96>
2013-08-16 20:51:31,333 INFO org.apache.hadoop.yarn.server.resourcemanager.rmcontainer.RMContainerImpl: container_1376685566219_0006_01_000033 Container Transitioned from NEW to ALLOCATED
2013-08-16 20:51:31,333 INFO org.apache.hadoop.yarn.server.resourcemanager.RMAuditLogger: USER=ubuntu	OPERATION=AM Allocated Container	TARGET=SchedulerApp	RESULT=SUCCESS	APPID=application_1376685566219_0006	CONTAINERID=container_1376685566219_0006_01_000033
2013-08-16 20:51:31,333 INFO org.apache.hadoop.yarn.server.resourcemanager.scheduler.common.fica.FiCaSchedulerNode: Assigned container container_1376685566219_0006_01_000033 of capacity <memory:1024, vCores:1> on host hadoop-512-4:51823, which currently has 2 containers, <memory:2048, vCores:2> used and <memory:6144, vCores:14> available
2013-08-16 20:51:31,334 INFO org.apache.hadoop.yarn.server.resourcemanager.scheduler.capacity.LeafQueue: assignedContainer application=application_1376685566219_0006 container=Container: [ContainerId: container_1376685566219_0006_01_000033, NodeId: hadoop-512-4:51823, NodeHttpAddress: hadoop-512-4:8042, Resource: <memory:1024, vCores:1>, Priority: 20, State: NEW, Token: null, Status: container_id {, app_attempt_id {, application_id {, id: 6, cluster_timestamp: 1376685566219, }, attemptId: 1, }, id: 33, }, state: C_NEW, ] containerId=container_1376685566219_0006_01_000033 queue=default: capacity=1.0, absoluteCapacity=1.0, usedResources=<memory:41984, vCores:36>usedCapacity=0.8541667, absoluteUsedCapacity=0.8541667, numApps=5, numContainers=36 usedCapacity=0.8541667 absoluteUsedCapacity=0.8541667 used=<memory:41984, vCores:36> cluster=<memory:49152, vCores:96>
2013-08-16 20:51:31,334 INFO org.apache.hadoop.yarn.server.resourcemanager.scheduler.capacity.ParentQueue: Re-sorting queues since queue: root.default stats: default: capacity=1.0, absoluteCapacity=1.0, usedResources=<memory:43008, vCores:37>usedCapacity=0.875, absoluteUsedCapacity=0.875, numApps=5, numContainers=37
2013-08-16 20:51:31,334 INFO org.apache.hadoop.yarn.server.resourcemanager.scheduler.capacity.ParentQueue: assignedContainer queue=root usedCapacity=0.875 absoluteUsedCapacity=0.875 used=<memory:43008, vCores:37> cluster=<memory:49152, vCores:96>
2013-08-16 20:51:31,335 INFO org.apache.hadoop.yarn.server.resourcemanager.rmcontainer.RMContainerImpl: container_1376685566219_0006_01_000034 Container Transitioned from NEW to ALLOCATED
2013-08-16 20:51:31,335 INFO org.apache.hadoop.yarn.server.resourcemanager.RMAuditLogger: USER=ubuntu	OPERATION=AM Allocated Container	TARGET=SchedulerApp	RESULT=SUCCESS	APPID=application_1376685566219_0006	CONTAINERID=container_1376685566219_0006_01_000034
2013-08-16 20:51:31,335 INFO org.apache.hadoop.yarn.server.resourcemanager.scheduler.common.fica.FiCaSchedulerNode: Assigned container container_1376685566219_0006_01_000034 of capacity <memory:1024, vCores:1> on host hadoop-512-4:51823, which currently has 3 containers, <memory:3072, vCores:3> used and <memory:5120, vCores:13> available
2013-08-16 20:51:31,336 INFO org.apache.hadoop.yarn.server.resourcemanager.scheduler.capacity.LeafQueue: assignedContainer application=application_1376685566219_0006 container=Container: [ContainerId: container_1376685566219_0006_01_000034, NodeId: hadoop-512-4:51823, NodeHttpAddress: hadoop-512-4:8042, Resource: <memory:1024, vCores:1>, Priority: 20, State: NEW, Token: null, Status: container_id {, app_attempt_id {, application_id {, id: 6, cluster_timestamp: 1376685566219, }, attemptId: 1, }, id: 34, }, state: C_NEW, ] containerId=container_1376685566219_0006_01_000034 queue=default: capacity=1.0, absoluteCapacity=1.0, usedResources=<memory:43008, vCores:37>usedCapacity=0.875, absoluteUsedCapacity=0.875, numApps=5, numContainers=37 usedCapacity=0.875 absoluteUsedCapacity=0.875 used=<memory:43008, vCores:37> cluster=<memory:49152, vCores:96>
2013-08-16 20:51:31,336 INFO org.apache.hadoop.yarn.server.resourcemanager.scheduler.capacity.ParentQueue: Re-sorting queues since queue: root.default stats: default: capacity=1.0, absoluteCapacity=1.0, usedResources=<memory:44032, vCores:38>usedCapacity=0.8958333, absoluteUsedCapacity=0.8958333, numApps=5, numContainers=38
2013-08-16 20:51:31,336 INFO org.apache.hadoop.yarn.server.resourcemanager.scheduler.capacity.ParentQueue: assignedContainer queue=root usedCapacity=0.8958333 absoluteUsedCapacity=0.8958333 used=<memory:44032, vCores:38> cluster=<memory:49152, vCores:96>
2013-08-16 20:51:31,337 INFO org.apache.hadoop.yarn.server.resourcemanager.rmcontainer.RMContainerImpl: container_1376685566219_0006_01_000035 Container Transitioned from NEW to ALLOCATED
2013-08-16 20:51:31,337 INFO org.apache.hadoop.yarn.server.resourcemanager.RMAuditLogger: USER=ubuntu	OPERATION=AM Allocated Container	TARGET=SchedulerApp	RESULT=SUCCESS	APPID=application_1376685566219_0006	CONTAINERID=container_1376685566219_0006_01_000035
2013-08-16 20:51:31,337 INFO org.apache.hadoop.yarn.server.resourcemanager.scheduler.common.fica.FiCaSchedulerNode: Assigned container container_1376685566219_0006_01_000035 of capacity <memory:1024, vCores:1> on host hadoop-512-4:51823, which currently has 4 containers, <memory:4096, vCores:4> used and <memory:4096, vCores:12> available
2013-08-16 20:51:31,338 INFO org.apache.hadoop.yarn.server.resourcemanager.scheduler.capacity.LeafQueue: assignedContainer application=application_1376685566219_0006 container=Container: [ContainerId: container_1376685566219_0006_01_000035, NodeId: hadoop-512-4:51823, NodeHttpAddress: hadoop-512-4:8042, Resource: <memory:1024, vCores:1>, Priority: 20, State: NEW, Token: null, Status: container_id {, app_attempt_id {, application_id {, id: 6, cluster_timestamp: 1376685566219, }, attemptId: 1, }, id: 35, }, state: C_NEW, ] containerId=container_1376685566219_0006_01_000035 queue=default: capacity=1.0, absoluteCapacity=1.0, usedResources=<memory:44032, vCores:38>usedCapacity=0.8958333, absoluteUsedCapacity=0.8958333, numApps=5, numContainers=38 usedCapacity=0.8958333 absoluteUsedCapacity=0.8958333 used=<memory:44032, vCores:38> cluster=<memory:49152, vCores:96>
2013-08-16 20:51:31,339 INFO org.apache.hadoop.yarn.server.resourcemanager.scheduler.capacity.ParentQueue: Re-sorting queues since queue: root.default stats: default: capacity=1.0, absoluteCapacity=1.0, usedResources=<memory:45056, vCores:39>usedCapacity=0.9166667, absoluteUsedCapacity=0.9166667, numApps=5, numContainers=39
2013-08-16 20:51:31,339 INFO org.apache.hadoop.yarn.server.resourcemanager.scheduler.capacity.ParentQueue: assignedContainer queue=root usedCapacity=0.9166667 absoluteUsedCapacity=0.9166667 used=<memory:45056, vCores:39> cluster=<memory:49152, vCores:96>
2013-08-16 20:51:31,339 INFO org.apache.hadoop.yarn.server.resourcemanager.rmcontainer.RMContainerImpl: container_1376685566219_0006_01_000036 Container Transitioned from NEW to ALLOCATED
2013-08-16 20:51:31,339 INFO org.apache.hadoop.yarn.server.resourcemanager.RMAuditLogger: USER=ubuntu	OPERATION=AM Allocated Container	TARGET=SchedulerApp	RESULT=SUCCESS	APPID=application_1376685566219_0006	CONTAINERID=container_1376685566219_0006_01_000036
2013-08-16 20:51:31,340 INFO org.apache.hadoop.yarn.server.resourcemanager.scheduler.common.fica.FiCaSchedulerNode: Assigned container container_1376685566219_0006_01_000036 of capacity <memory:1024, vCores:1> on host hadoop-512-4:51823, which currently has 5 containers, <memory:5120, vCores:5> used and <memory:3072, vCores:11> available
2013-08-16 20:51:31,340 INFO org.apache.hadoop.yarn.server.resourcemanager.scheduler.capacity.LeafQueue: assignedContainer application=application_1376685566219_0006 container=Container: [ContainerId: container_1376685566219_0006_01_000036, NodeId: hadoop-512-4:51823, NodeHttpAddress: hadoop-512-4:8042, Resource: <memory:1024, vCores:1>, Priority: 20, State: NEW, Token: null, Status: container_id {, app_attempt_id {, application_id {, id: 6, cluster_timestamp: 1376685566219, }, attemptId: 1, }, id: 36, }, state: C_NEW, ] containerId=container_1376685566219_0006_01_000036 queue=default: capacity=1.0, absoluteCapacity=1.0, usedResources=<memory:45056, vCores:39>usedCapacity=0.9166667, absoluteUsedCapacity=0.9166667, numApps=5, numContainers=39 usedCapacity=0.9166667 absoluteUsedCapacity=0.9166667 used=<memory:45056, vCores:39> cluster=<memory:49152, vCores:96>
2013-08-16 20:51:31,341 INFO org.apache.hadoop.yarn.server.resourcemanager.scheduler.capacity.ParentQueue: Re-sorting queues since queue: root.default stats: default: capacity=1.0, absoluteCapacity=1.0, usedResources=<memory:46080, vCores:40>usedCapacity=0.9375, absoluteUsedCapacity=0.9375, numApps=5, numContainers=40
2013-08-16 20:51:31,341 INFO org.apache.hadoop.yarn.server.resourcemanager.scheduler.capacity.ParentQueue: assignedContainer queue=root usedCapacity=0.9375 absoluteUsedCapacity=0.9375 used=<memory:46080, vCores:40> cluster=<memory:49152, vCores:96>
2013-08-16 20:51:31,341 INFO org.apache.hadoop.yarn.server.resourcemanager.rmcontainer.RMContainerImpl: container_1376685566219_0006_01_000037 Container Transitioned from NEW to ALLOCATED
2013-08-16 20:51:31,342 INFO org.apache.hadoop.yarn.server.resourcemanager.RMAuditLogger: USER=ubuntu	OPERATION=AM Allocated Container	TARGET=SchedulerApp	RESULT=SUCCESS	APPID=application_1376685566219_0006	CONTAINERID=container_1376685566219_0006_01_000037
2013-08-16 20:51:31,342 INFO org.apache.hadoop.yarn.server.resourcemanager.scheduler.common.fica.FiCaSchedulerNode: Assigned container container_1376685566219_0006_01_000037 of capacity <memory:1024, vCores:1> on host hadoop-512-4:51823, which currently has 6 containers, <memory:6144, vCores:6> used and <memory:2048, vCores:10> available
2013-08-16 20:51:31,343 INFO org.apache.hadoop.yarn.server.resourcemanager.scheduler.capacity.LeafQueue: assignedContainer application=application_1376685566219_0006 container=Container: [ContainerId: container_1376685566219_0006_01_000037, NodeId: hadoop-512-4:51823, NodeHttpAddress: hadoop-512-4:8042, Resource: <memory:1024, vCores:1>, Priority: 20, State: NEW, Token: null, Status: container_id {, app_attempt_id {, application_id {, id: 6, cluster_timestamp: 1376685566219, }, attemptId: 1, }, id: 37, }, state: C_NEW, ] containerId=container_1376685566219_0006_01_000037 queue=default: capacity=1.0, absoluteCapacity=1.0, usedResources=<memory:46080, vCores:40>usedCapacity=0.9375, absoluteUsedCapacity=0.9375, numApps=5, numContainers=40 usedCapacity=0.9375 absoluteUsedCapacity=0.9375 used=<memory:46080, vCores:40> cluster=<memory:49152, vCores:96>
2013-08-16 20:51:31,343 INFO org.apache.hadoop.yarn.server.resourcemanager.scheduler.capacity.ParentQueue: Re-sorting queues since queue: root.default stats: default: capacity=1.0, absoluteCapacity=1.0, usedResources=<memory:47104, vCores:41>usedCapacity=0.9583333, absoluteUsedCapacity=0.9583333, numApps=5, numContainers=41
2013-08-16 20:51:31,343 INFO org.apache.hadoop.yarn.server.resourcemanager.scheduler.capacity.ParentQueue: assignedContainer queue=root usedCapacity=0.9583333 absoluteUsedCapacity=0.9583333 used=<memory:47104, vCores:41> cluster=<memory:49152, vCores:96>
2013-08-16 20:51:31,344 INFO org.apache.hadoop.yarn.server.resourcemanager.rmcontainer.RMContainerImpl: container_1376685566219_0006_01_000038 Container Transitioned from NEW to ALLOCATED
2013-08-16 20:51:31,344 INFO org.apache.hadoop.yarn.server.resourcemanager.RMAuditLogger: USER=ubuntu	OPERATION=AM Allocated Container	TARGET=SchedulerApp	RESULT=SUCCESS	APPID=application_1376685566219_0006	CONTAINERID=container_1376685566219_0006_01_000038
2013-08-16 20:51:31,344 INFO org.apache.hadoop.yarn.server.resourcemanager.scheduler.common.fica.FiCaSchedulerNode: Assigned container container_1376685566219_0006_01_000038 of capacity <memory:1024, vCores:1> on host hadoop-512-4:51823, which currently has 7 containers, <memory:7168, vCores:7> used and <memory:1024, vCores:9> available
2013-08-16 20:51:31,345 INFO org.apache.hadoop.yarn.server.resourcemanager.scheduler.capacity.LeafQueue: assignedContainer application=application_1376685566219_0006 container=Container: [ContainerId: container_1376685566219_0006_01_000038, NodeId: hadoop-512-4:51823, NodeHttpAddress: hadoop-512-4:8042, Resource: <memory:1024, vCores:1>, Priority: 20, State: NEW, Token: null, Status: container_id {, app_attempt_id {, application_id {, id: 6, cluster_timestamp: 1376685566219, }, attemptId: 1, }, id: 38, }, state: C_NEW, ] containerId=container_1376685566219_0006_01_000038 queue=default: capacity=1.0, absoluteCapacity=1.0, usedResources=<memory:47104, vCores:41>usedCapacity=0.9583333, absoluteUsedCapacity=0.9583333, numApps=5, numContainers=41 usedCapacity=0.9583333 absoluteUsedCapacity=0.9583333 used=<memory:47104, vCores:41> cluster=<memory:49152, vCores:96>
2013-08-16 20:51:31,345 INFO org.apache.hadoop.yarn.server.resourcemanager.scheduler.capacity.ParentQueue: Re-sorting queues since queue: root.default stats: default: capacity=1.0, absoluteCapacity=1.0, usedResources=<memory:48128, vCores:42>usedCapacity=0.9791667, absoluteUsedCapacity=0.9791667, numApps=5, numContainers=42
2013-08-16 20:51:31,345 INFO org.apache.hadoop.yarn.server.resourcemanager.scheduler.capacity.ParentQueue: assignedContainer queue=root usedCapacity=0.9791667 absoluteUsedCapacity=0.9791667 used=<memory:48128, vCores:42> cluster=<memory:49152, vCores:96>
2013-08-16 20:51:31,346 INFO org.apache.hadoop.yarn.server.resourcemanager.rmcontainer.RMContainerImpl: container_1376685566219_0006_01_000039 Container Transitioned from NEW to ALLOCATED
2013-08-16 20:51:31,346 INFO org.apache.hadoop.yarn.server.resourcemanager.RMAuditLogger: USER=ubuntu	OPERATION=AM Allocated Container	TARGET=SchedulerApp	RESULT=SUCCESS	APPID=application_1376685566219_0006	CONTAINERID=container_1376685566219_0006_01_000039
2013-08-16 20:51:31,346 INFO org.apache.hadoop.yarn.server.resourcemanager.scheduler.common.fica.FiCaSchedulerNode: Assigned container container_1376685566219_0006_01_000039 of capacity <memory:1024, vCores:1> on host hadoop-512-4:51823, which currently has 8 containers, <memory:8192, vCores:8> used and <memory:0, vCores:8> available
2013-08-16 20:51:31,347 INFO org.apache.hadoop.yarn.server.resourcemanager.scheduler.capacity.LeafQueue: assignedContainer application=application_1376685566219_0006 container=Container: [ContainerId: container_1376685566219_0006_01_000039, NodeId: hadoop-512-4:51823, NodeHttpAddress: hadoop-512-4:8042, Resource: <memory:1024, vCores:1>, Priority: 20, State: NEW, Token: null, Status: container_id {, app_attempt_id {, application_id {, id: 6, cluster_timestamp: 1376685566219, }, attemptId: 1, }, id: 39, }, state: C_NEW, ] containerId=container_1376685566219_0006_01_000039 queue=default: capacity=1.0, absoluteCapacity=1.0, usedResources=<memory:48128, vCores:42>usedCapacity=0.9791667, absoluteUsedCapacity=0.9791667, numApps=5, numContainers=42 usedCapacity=0.9791667 absoluteUsedCapacity=0.9791667 used=<memory:48128, vCores:42> cluster=<memory:49152, vCores:96>
2013-08-16 20:51:31,348 INFO org.apache.hadoop.yarn.server.resourcemanager.scheduler.capacity.ParentQueue: Re-sorting queues since queue: root.default stats: default: capacity=1.0, absoluteCapacity=1.0, usedResources=<memory:49152, vCores:43>usedCapacity=1.0, absoluteUsedCapacity=1.0, numApps=5, numContainers=43
2013-08-16 20:51:31,348 INFO org.apache.hadoop.yarn.server.resourcemanager.scheduler.capacity.ParentQueue: assignedContainer queue=root usedCapacity=1.0 absoluteUsedCapacity=1.0 used=<memory:49152, vCores:43> cluster=<memory:49152, vCores:96>
2013-08-16 20:51:31,367 INFO org.apache.hadoop.yarn.server.resourcemanager.rmcontainer.RMContainerImpl: container_1376685566219_0006_01_000002 Container Transitioned from ALLOCATED to ACQUIRED
2013-08-16 20:51:31,370 INFO org.apache.hadoop.yarn.server.resourcemanager.rmcontainer.RMContainerImpl: container_1376685566219_0006_01_000003 Container Transitioned from ALLOCATED to ACQUIRED
2013-08-16 20:51:31,371 INFO org.apache.hadoop.yarn.server.resourcemanager.rmcontainer.RMContainerImpl: container_1376685566219_0006_01_000004 Container Transitioned from ALLOCATED to ACQUIRED
2013-08-16 20:51:31,372 INFO org.apache.hadoop.yarn.server.resourcemanager.rmcontainer.RMContainerImpl: container_1376685566219_0006_01_000005 Container Transitioned from ALLOCATED to ACQUIRED
2013-08-16 20:51:31,373 INFO org.apache.hadoop.yarn.server.resourcemanager.rmcontainer.RMContainerImpl: container_1376685566219_0006_01_000006 Container Transitioned from ALLOCATED to ACQUIRED
2013-08-16 20:51:31,374 INFO org.apache.hadoop.yarn.server.resourcemanager.rmcontainer.RMContainerImpl: container_1376685566219_0006_01_000007 Container Transitioned from ALLOCATED to ACQUIRED
2013-08-16 20:51:31,375 INFO org.apache.hadoop.yarn.server.resourcemanager.rmcontainer.RMContainerImpl: container_1376685566219_0006_01_000008 Container Transitioned from ALLOCATED to ACQUIRED
2013-08-16 20:51:31,376 INFO org.apache.hadoop.yarn.server.resourcemanager.rmcontainer.RMContainerImpl: container_1376685566219_0006_01_000009 Container Transitioned from ALLOCATED to ACQUIRED
2013-08-16 20:51:31,377 INFO org.apache.hadoop.yarn.server.resourcemanager.rmcontainer.RMContainerImpl: container_1376685566219_0006_01_000010 Container Transitioned from ALLOCATED to ACQUIRED
2013-08-16 20:51:31,379 INFO org.apache.hadoop.yarn.server.resourcemanager.rmcontainer.RMContainerImpl: container_1376685566219_0006_01_000011 Container Transitioned from ALLOCATED to ACQUIRED
2013-08-16 20:51:31,380 INFO org.apache.hadoop.yarn.server.resourcemanager.rmcontainer.RMContainerImpl: container_1376685566219_0006_01_000012 Container Transitioned from ALLOCATED to ACQUIRED
2013-08-16 20:51:31,380 INFO org.apache.hadoop.yarn.server.resourcemanager.rmcontainer.RMContainerImpl: container_1376685566219_0006_01_000013 Container Transitioned from ALLOCATED to ACQUIRED
2013-08-16 20:51:31,380 INFO org.apache.hadoop.yarn.server.resourcemanager.rmcontainer.RMContainerImpl: container_1376685566219_0006_01_000014 Container Transitioned from ALLOCATED to ACQUIRED
2013-08-16 20:51:31,380 INFO org.apache.hadoop.yarn.server.resourcemanager.rmcontainer.RMContainerImpl: container_1376685566219_0006_01_000015 Container Transitioned from ALLOCATED to ACQUIRED
2013-08-16 20:51:31,380 INFO org.apache.hadoop.yarn.server.resourcemanager.rmcontainer.RMContainerImpl: container_1376685566219_0006_01_000016 Container Transitioned from ALLOCATED to ACQUIRED
2013-08-16 20:51:31,381 INFO org.apache.hadoop.yarn.server.resourcemanager.rmcontainer.RMContainerImpl: container_1376685566219_0006_01_000017 Container Transitioned from ALLOCATED to ACQUIRED
2013-08-16 20:51:31,381 INFO org.apache.hadoop.yarn.server.resourcemanager.rmcontainer.RMContainerImpl: container_1376685566219_0006_01_000018 Container Transitioned from ALLOCATED to ACQUIRED
2013-08-16 20:51:31,381 INFO org.apache.hadoop.yarn.server.resourcemanager.rmcontainer.RMContainerImpl: container_1376685566219_0006_01_000019 Container Transitioned from ALLOCATED to ACQUIRED
2013-08-16 20:51:31,381 INFO org.apache.hadoop.yarn.server.resourcemanager.rmcontainer.RMContainerImpl: container_1376685566219_0006_01_000020 Container Transitioned from ALLOCATED to ACQUIRED
2013-08-16 20:51:31,381 INFO org.apache.hadoop.yarn.server.resourcemanager.rmcontainer.RMContainerImpl: container_1376685566219_0006_01_000021 Container Transitioned from ALLOCATED to ACQUIRED
2013-08-16 20:51:31,381 INFO org.apache.hadoop.yarn.server.resourcemanager.rmcontainer.RMContainerImpl: container_1376685566219_0006_01_000022 Container Transitioned from ALLOCATED to ACQUIRED
2013-08-16 20:51:31,382 INFO org.apache.hadoop.yarn.server.resourcemanager.rmcontainer.RMContainerImpl: container_1376685566219_0006_01_000023 Container Transitioned from ALLOCATED to ACQUIRED
2013-08-16 20:51:31,382 INFO org.apache.hadoop.yarn.server.resourcemanager.rmcontainer.RMContainerImpl: container_1376685566219_0006_01_000024 Container Transitioned from ALLOCATED to ACQUIRED
2013-08-16 20:51:31,382 INFO org.apache.hadoop.yarn.server.resourcemanager.rmcontainer.RMContainerImpl: container_1376685566219_0006_01_000025 Container Transitioned from ALLOCATED to ACQUIRED
2013-08-16 20:51:31,382 INFO org.apache.hadoop.yarn.server.resourcemanager.rmcontainer.RMContainerImpl: container_1376685566219_0006_01_000026 Container Transitioned from ALLOCATED to ACQUIRED
2013-08-16 20:51:31,382 INFO org.apache.hadoop.yarn.server.resourcemanager.rmcontainer.RMContainerImpl: container_1376685566219_0006_01_000027 Container Transitioned from ALLOCATED to ACQUIRED
2013-08-16 20:51:31,383 INFO org.apache.hadoop.yarn.server.resourcemanager.rmcontainer.RMContainerImpl: container_1376685566219_0006_01_000028 Container Transitioned from ALLOCATED to ACQUIRED
2013-08-16 20:51:31,383 INFO org.apache.hadoop.yarn.server.resourcemanager.rmcontainer.RMContainerImpl: container_1376685566219_0006_01_000029 Container Transitioned from ALLOCATED to ACQUIRED
2013-08-16 20:51:31,383 INFO org.apache.hadoop.yarn.server.resourcemanager.rmcontainer.RMContainerImpl: container_1376685566219_0006_01_000030 Container Transitioned from ALLOCATED to ACQUIRED
2013-08-16 20:51:31,383 INFO org.apache.hadoop.yarn.server.resourcemanager.rmcontainer.RMContainerImpl: container_1376685566219_0006_01_000031 Container Transitioned from ALLOCATED to ACQUIRED
2013-08-16 20:51:31,383 INFO org.apache.hadoop.yarn.server.resourcemanager.rmcontainer.RMContainerImpl: container_1376685566219_0006_01_000032 Container Transitioned from ALLOCATED to ACQUIRED
2013-08-16 20:51:31,384 INFO org.apache.hadoop.yarn.server.resourcemanager.rmcontainer.RMContainerImpl: container_1376685566219_0006_01_000033 Container Transitioned from ALLOCATED to ACQUIRED
2013-08-16 20:51:31,384 INFO org.apache.hadoop.yarn.server.resourcemanager.rmcontainer.RMContainerImpl: container_1376685566219_0006_01_000034 Container Transitioned from ALLOCATED to ACQUIRED
2013-08-16 20:51:31,384 INFO org.apache.hadoop.yarn.server.resourcemanager.rmcontainer.RMContainerImpl: container_1376685566219_0006_01_000035 Container Transitioned from ALLOCATED to ACQUIRED
2013-08-16 20:51:31,384 INFO org.apache.hadoop.yarn.server.resourcemanager.rmcontainer.RMContainerImpl: container_1376685566219_0006_01_000036 Container Transitioned from ALLOCATED to ACQUIRED
2013-08-16 20:51:31,384 INFO org.apache.hadoop.yarn.server.resourcemanager.rmcontainer.RMContainerImpl: container_1376685566219_0006_01_000037 Container Transitioned from ALLOCATED to ACQUIRED
2013-08-16 20:51:31,385 INFO org.apache.hadoop.yarn.server.resourcemanager.rmcontainer.RMContainerImpl: container_1376685566219_0006_01_000038 Container Transitioned from ALLOCATED to ACQUIRED
2013-08-16 20:51:31,385 INFO org.apache.hadoop.yarn.server.resourcemanager.rmcontainer.RMContainerImpl: container_1376685566219_0006_01_000039 Container Transitioned from ALLOCATED to ACQUIRED
2013-08-16 20:51:31,875 INFO org.apache.hadoop.yarn.server.resourcemanager.rmcontainer.RMContainerImpl: container_1376685566219_0006_01_000014 Container Transitioned from ACQUIRED to RUNNING
2013-08-16 20:51:31,877 INFO org.apache.hadoop.yarn.server.resourcemanager.rmcontainer.RMContainerImpl: container_1376685566219_0006_01_000015 Container Transitioned from ACQUIRED to RUNNING
2013-08-16 20:51:31,878 INFO org.apache.hadoop.yarn.server.resourcemanager.rmcontainer.RMContainerImpl: container_1376685566219_0006_01_000016 Container Transitioned from ACQUIRED to RUNNING
2013-08-16 20:51:31,880 INFO org.apache.hadoop.yarn.server.resourcemanager.rmcontainer.RMContainerImpl: container_1376685566219_0006_01_000017 Container Transitioned from ACQUIRED to RUNNING
2013-08-16 20:51:31,881 INFO org.apache.hadoop.yarn.server.resourcemanager.rmcontainer.RMContainerImpl: container_1376685566219_0006_01_000018 Container Transitioned from ACQUIRED to RUNNING
2013-08-16 20:51:31,882 INFO org.apache.hadoop.yarn.server.resourcemanager.rmcontainer.RMContainerImpl: container_1376685566219_0006_01_000019 Container Transitioned from ACQUIRED to RUNNING
2013-08-16 20:51:32,220 INFO org.apache.hadoop.yarn.server.resourcemanager.rmcontainer.RMContainerImpl: container_1376685566219_0006_01_000020 Container Transitioned from ACQUIRED to RUNNING
2013-08-16 20:51:32,226 INFO org.apache.hadoop.yarn.server.resourcemanager.rmcontainer.RMContainerImpl: container_1376685566219_0006_01_000021 Container Transitioned from ACQUIRED to RUNNING
2013-08-16 20:51:32,228 INFO org.apache.hadoop.yarn.server.resourcemanager.rmcontainer.RMContainerImpl: container_1376685566219_0006_01_000022 Container Transitioned from ACQUIRED to RUNNING
2013-08-16 20:51:32,230 INFO org.apache.hadoop.yarn.server.resourcemanager.rmcontainer.RMContainerImpl: container_1376685566219_0006_01_000023 Container Transitioned from ACQUIRED to RUNNING
2013-08-16 20:51:32,230 INFO org.apache.hadoop.yarn.server.resourcemanager.rmcontainer.RMContainerImpl: container_1376685566219_0006_01_000024 Container Transitioned from ACQUIRED to RUNNING
2013-08-16 20:51:32,231 INFO org.apache.hadoop.yarn.server.resourcemanager.rmcontainer.RMContainerImpl: container_1376685566219_0006_01_000025 Container Transitioned from ACQUIRED to RUNNING
2013-08-16 20:51:32,305 INFO org.apache.hadoop.yarn.server.resourcemanager.rmcontainer.RMContainerImpl: container_1376685566219_0006_01_000026 Container Transitioned from ACQUIRED to RUNNING
2013-08-16 20:51:32,306 INFO org.apache.hadoop.yarn.server.resourcemanager.rmcontainer.RMContainerImpl: container_1376685566219_0006_01_000027 Container Transitioned from ACQUIRED to RUNNING
2013-08-16 20:51:32,306 INFO org.apache.hadoop.yarn.server.resourcemanager.rmcontainer.RMContainerImpl: container_1376685566219_0006_01_000028 Container Transitioned from ACQUIRED to RUNNING
2013-08-16 20:51:32,307 INFO org.apache.hadoop.yarn.server.resourcemanager.rmcontainer.RMContainerImpl: container_1376685566219_0006_01_000029 Container Transitioned from ACQUIRED to RUNNING
2013-08-16 20:51:32,307 INFO org.apache.hadoop.yarn.server.resourcemanager.rmcontainer.RMContainerImpl: container_1376685566219_0006_01_000030 Container Transitioned from ACQUIRED to RUNNING
2013-08-16 20:51:32,308 INFO org.apache.hadoop.yarn.server.resourcemanager.rmcontainer.RMContainerImpl: container_1376685566219_0006_01_000031 Container Transitioned from ACQUIRED to RUNNING
2013-08-16 20:51:32,360 INFO org.apache.hadoop.yarn.server.resourcemanager.rmcontainer.RMContainerImpl: container_1376685566219_0006_01_000032 Container Transitioned from ACQUIRED to RUNNING
2013-08-16 20:51:32,361 INFO org.apache.hadoop.yarn.server.resourcemanager.rmcontainer.RMContainerImpl: container_1376685566219_0006_01_000033 Container Transitioned from ACQUIRED to RUNNING
2013-08-16 20:51:32,362 INFO org.apache.hadoop.yarn.server.resourcemanager.rmcontainer.RMContainerImpl: container_1376685566219_0006_01_000034 Container Transitioned from ACQUIRED to RUNNING
2013-08-16 20:51:32,362 INFO org.apache.hadoop.yarn.server.resourcemanager.rmcontainer.RMContainerImpl: container_1376685566219_0006_01_000035 Container Transitioned from ACQUIRED to RUNNING
2013-08-16 20:51:32,362 INFO org.apache.hadoop.yarn.server.resourcemanager.rmcontainer.RMContainerImpl: container_1376685566219_0006_01_000036 Container Transitioned from ACQUIRED to RUNNING
2013-08-16 20:51:32,362 INFO org.apache.hadoop.yarn.server.resourcemanager.rmcontainer.RMContainerImpl: container_1376685566219_0006_01_000037 Container Transitioned from ACQUIRED to RUNNING
2013-08-16 20:51:32,362 INFO org.apache.hadoop.yarn.server.resourcemanager.rmcontainer.RMContainerImpl: container_1376685566219_0006_01_000038 Container Transitioned from ACQUIRED to RUNNING
2013-08-16 20:51:32,363 INFO org.apache.hadoop.yarn.server.resourcemanager.rmcontainer.RMContainerImpl: container_1376685566219_0006_01_000039 Container Transitioned from ACQUIRED to RUNNING
2013-08-16 20:51:32,599 INFO org.apache.hadoop.yarn.server.resourcemanager.rmcontainer.RMContainerImpl: container_1376685566219_0006_01_000002 Container Transitioned from ACQUIRED to RUNNING
2013-08-16 20:51:32,599 INFO org.apache.hadoop.yarn.server.resourcemanager.rmcontainer.RMContainerImpl: container_1376685566219_0006_01_000003 Container Transitioned from ACQUIRED to RUNNING
2013-08-16 20:51:32,599 INFO org.apache.hadoop.yarn.server.resourcemanager.rmcontainer.RMContainerImpl: container_1376685566219_0006_01_000004 Container Transitioned from ACQUIRED to RUNNING
2013-08-16 20:51:32,599 INFO org.apache.hadoop.yarn.server.resourcemanager.rmcontainer.RMContainerImpl: container_1376685566219_0006_01_000005 Container Transitioned from ACQUIRED to RUNNING
2013-08-16 20:51:32,599 INFO org.apache.hadoop.yarn.server.resourcemanager.rmcontainer.RMContainerImpl: container_1376685566219_0006_01_000006 Container Transitioned from ACQUIRED to RUNNING
2013-08-16 20:51:32,600 INFO org.apache.hadoop.yarn.server.resourcemanager.rmcontainer.RMContainerImpl: container_1376685566219_0006_01_000007 Container Transitioned from ACQUIRED to RUNNING
2013-08-16 20:51:32,762 INFO org.apache.hadoop.yarn.server.resourcemanager.rmcontainer.RMContainerImpl: container_1376685566219_0006_01_000008 Container Transitioned from ACQUIRED to RUNNING
2013-08-16 20:51:32,762 INFO org.apache.hadoop.yarn.server.resourcemanager.rmcontainer.RMContainerImpl: container_1376685566219_0006_01_000009 Container Transitioned from ACQUIRED to RUNNING
2013-08-16 20:51:32,762 INFO org.apache.hadoop.yarn.server.resourcemanager.rmcontainer.RMContainerImpl: container_1376685566219_0006_01_000010 Container Transitioned from ACQUIRED to RUNNING
2013-08-16 20:51:32,763 INFO org.apache.hadoop.yarn.server.resourcemanager.rmcontainer.RMContainerImpl: container_1376685566219_0006_01_000011 Container Transitioned from ACQUIRED to RUNNING
2013-08-16 20:51:32,763 INFO org.apache.hadoop.yarn.server.resourcemanager.rmcontainer.RMContainerImpl: container_1376685566219_0006_01_000012 Container Transitioned from ACQUIRED to RUNNING
2013-08-16 20:51:32,763 INFO org.apache.hadoop.yarn.server.resourcemanager.rmcontainer.RMContainerImpl: container_1376685566219_0006_01_000013 Container Transitioned from ACQUIRED to RUNNING
2013-08-16 20:51:55,660 INFO org.apache.hadoop.yarn.server.resourcemanager.rmcontainer.RMContainerImpl: container_1376685566219_0006_01_000019 Container Transitioned from RUNNING to COMPLETED
2013-08-16 20:51:55,660 INFO org.apache.hadoop.yarn.server.resourcemanager.scheduler.common.fica.FiCaSchedulerApp: Completed container: container_1376685566219_0006_01_000019 in state: COMPLETED event:FINISHED
2013-08-16 20:51:55,660 INFO org.apache.hadoop.yarn.server.resourcemanager.RMAuditLogger: USER=ubuntu	OPERATION=AM Released Container	TARGET=SchedulerApp	RESULT=SUCCESS	APPID=application_1376685566219_0006	CONTAINERID=container_1376685566219_0006_01_000019
2013-08-16 20:51:55,660 INFO org.apache.hadoop.yarn.server.resourcemanager.scheduler.common.fica.FiCaSchedulerNode: Released container container_1376685566219_0006_01_000019 of capacity <memory:1024, vCores:1> on host hadoop-512-3:58863, which currently has 6 containers, <memory:7168, vCores:6> used and <memory:1024, vCores:10> available, release resources=true
2013-08-16 20:51:55,660 INFO org.apache.hadoop.yarn.server.resourcemanager.scheduler.capacity.LeafQueue: default used=<memory:48128, vCores:42> numContainers=42 user=ubuntu user-resources=<memory:48128, vCores:42>
2013-08-16 20:51:55,663 INFO org.apache.hadoop.yarn.server.resourcemanager.scheduler.capacity.LeafQueue: completedContainer container=Container: [ContainerId: container_1376685566219_0006_01_000019, NodeId: hadoop-512-3:58863, NodeHttpAddress: hadoop-512-3:8042, Resource: <memory:1024, vCores:1>, Priority: 20, State: NEW, Token: null, Status: container_id {, app_attempt_id {, application_id {, id: 6, cluster_timestamp: 1376685566219, }, attemptId: 1, }, id: 19, }, state: C_COMPLETE, diagnostics: "Container killed by the ApplicationMaster.\n\n", exit_status: 143, ] resource=<memory:1024, vCores:1> queue=default: capacity=1.0, absoluteCapacity=1.0, usedResources=<memory:48128, vCores:42>usedCapacity=0.9791667, absoluteUsedCapacity=0.9791667, numApps=5, numContainers=42 usedCapacity=0.9791667 absoluteUsedCapacity=0.9791667 used=<memory:48128, vCores:42> cluster=<memory:49152, vCores:96>
2013-08-16 20:51:55,663 INFO org.apache.hadoop.yarn.server.resourcemanager.scheduler.capacity.ParentQueue: completedContainer queue=root usedCapacity=0.9791667 absoluteUsedCapacity=0.9791667 used=<memory:48128, vCores:42> cluster=<memory:49152, vCores:96>
2013-08-16 20:51:55,663 INFO org.apache.hadoop.yarn.server.resourcemanager.scheduler.capacity.CapacityScheduler: Application appattempt_1376685566219_0006_000001 released container container_1376685566219_0006_01_000019 on node: host: hadoop-512-3:58863 #containers=6 available=1024 used=7168 with event: FINISHED
2013-08-16 20:51:55,664 INFO org.apache.hadoop.yarn.server.resourcemanager.rmcontainer.RMContainerImpl: container_1376685566219_0006_01_000040 Container Transitioned from NEW to ALLOCATED
2013-08-16 20:51:55,664 INFO org.apache.hadoop.yarn.server.resourcemanager.RMAuditLogger: USER=ubuntu	OPERATION=AM Allocated Container	TARGET=SchedulerApp	RESULT=SUCCESS	APPID=application_1376685566219_0006	CONTAINERID=container_1376685566219_0006_01_000040
2013-08-16 20:51:55,664 INFO org.apache.hadoop.yarn.server.resourcemanager.scheduler.common.fica.FiCaSchedulerNode: Assigned container container_1376685566219_0006_01_000040 of capacity <memory:1024, vCores:1> on host hadoop-512-3:58863, which currently has 7 containers, <memory:8192, vCores:7> used and <memory:0, vCores:9> available
2013-08-16 20:51:55,665 INFO org.apache.hadoop.yarn.server.resourcemanager.scheduler.capacity.LeafQueue: assignedContainer application=application_1376685566219_0006 container=Container: [ContainerId: container_1376685566219_0006_01_000040, NodeId: hadoop-512-3:58863, NodeHttpAddress: hadoop-512-3:8042, Resource: <memory:1024, vCores:1>, Priority: 20, State: NEW, Token: null, Status: container_id {, app_attempt_id {, application_id {, id: 6, cluster_timestamp: 1376685566219, }, attemptId: 1, }, id: 40, }, state: C_NEW, ] containerId=container_1376685566219_0006_01_000040 queue=default: capacity=1.0, absoluteCapacity=1.0, usedResources=<memory:48128, vCores:42>usedCapacity=0.9791667, absoluteUsedCapacity=0.9791667, numApps=5, numContainers=42 usedCapacity=0.9791667 absoluteUsedCapacity=0.9791667 used=<memory:48128, vCores:42> cluster=<memory:49152, vCores:96>
2013-08-16 20:51:55,665 INFO org.apache.hadoop.yarn.server.resourcemanager.scheduler.capacity.ParentQueue: Re-sorting queues since queue: root.default stats: default: capacity=1.0, absoluteCapacity=1.0, usedResources=<memory:49152, vCores:43>usedCapacity=1.0, absoluteUsedCapacity=1.0, numApps=5, numContainers=43
2013-08-16 20:51:55,665 INFO org.apache.hadoop.yarn.server.resourcemanager.scheduler.capacity.ParentQueue: assignedContainer queue=root usedCapacity=1.0 absoluteUsedCapacity=1.0 used=<memory:49152, vCores:43> cluster=<memory:49152, vCores:96>
2013-08-16 20:51:56,627 INFO org.apache.hadoop.yarn.server.resourcemanager.rmcontainer.RMContainerImpl: container_1376685566219_0006_01_000040 Container Transitioned from ALLOCATED to ACQUIRED
2013-08-16 20:51:56,668 INFO org.apache.hadoop.yarn.server.resourcemanager.rmcontainer.RMContainerImpl: container_1376685566219_0006_01_000040 Container Transitioned from ACQUIRED to RUNNING
2013-08-16 20:51:57,821 INFO org.apache.hadoop.yarn.server.resourcemanager.rmcontainer.RMContainerImpl: container_1376685566219_0006_01_000022 Container Transitioned from RUNNING to COMPLETED
2013-08-16 20:51:57,821 INFO org.apache.hadoop.yarn.server.resourcemanager.scheduler.common.fica.FiCaSchedulerApp: Completed container: container_1376685566219_0006_01_000022 in state: COMPLETED event:FINISHED
2013-08-16 20:51:57,821 INFO org.apache.hadoop.yarn.server.resourcemanager.RMAuditLogger: USER=ubuntu	OPERATION=AM Released Container	TARGET=SchedulerApp	RESULT=SUCCESS	APPID=application_1376685566219_0006	CONTAINERID=container_1376685566219_0006_01_000022
2013-08-16 20:51:57,821 INFO org.apache.hadoop.yarn.server.resourcemanager.scheduler.common.fica.FiCaSchedulerNode: Released container container_1376685566219_0006_01_000022 of capacity <memory:1024, vCores:1> on host hadoop-512-2:41669, which currently has 6 containers, <memory:7168, vCores:6> used and <memory:1024, vCores:10> available, release resources=true
2013-08-16 20:51:57,821 INFO org.apache.hadoop.yarn.server.resourcemanager.scheduler.capacity.LeafQueue: default used=<memory:48128, vCores:42> numContainers=42 user=ubuntu user-resources=<memory:48128, vCores:42>
2013-08-16 20:51:57,823 INFO org.apache.hadoop.yarn.server.resourcemanager.scheduler.capacity.LeafQueue: completedContainer container=Container: [ContainerId: container_1376685566219_0006_01_000022, NodeId: hadoop-512-2:41669, NodeHttpAddress: hadoop-512-2:8042, Resource: <memory:1024, vCores:1>, Priority: 20, State: NEW, Token: null, Status: container_id {, app_attempt_id {, application_id {, id: 6, cluster_timestamp: 1376685566219, }, attemptId: 1, }, id: 22, }, state: C_COMPLETE, diagnostics: "Container killed by the ApplicationMaster.\n\n", exit_status: 143, ] resource=<memory:1024, vCores:1> queue=default: capacity=1.0, absoluteCapacity=1.0, usedResources=<memory:48128, vCores:42>usedCapacity=0.9791667, absoluteUsedCapacity=0.9791667, numApps=5, numContainers=42 usedCapacity=0.9791667 absoluteUsedCapacity=0.9791667 used=<memory:48128, vCores:42> cluster=<memory:49152, vCores:96>
2013-08-16 20:51:57,823 INFO org.apache.hadoop.yarn.server.resourcemanager.scheduler.capacity.ParentQueue: completedContainer queue=root usedCapacity=0.9791667 absoluteUsedCapacity=0.9791667 used=<memory:48128, vCores:42> cluster=<memory:49152, vCores:96>
2013-08-16 20:51:57,823 INFO org.apache.hadoop.yarn.server.resourcemanager.scheduler.capacity.CapacityScheduler: Application appattempt_1376685566219_0006_000001 released container container_1376685566219_0006_01_000022 on node: host: hadoop-512-2:41669 #containers=6 available=1024 used=7168 with event: FINISHED
2013-08-16 20:51:57,824 INFO org.apache.hadoop.yarn.server.resourcemanager.rmcontainer.RMContainerImpl: container_1376685566219_0006_01_000041 Container Transitioned from NEW to ALLOCATED
2013-08-16 20:51:57,824 INFO org.apache.hadoop.yarn.server.resourcemanager.RMAuditLogger: USER=ubuntu	OPERATION=AM Allocated Container	TARGET=SchedulerApp	RESULT=SUCCESS	APPID=application_1376685566219_0006	CONTAINERID=container_1376685566219_0006_01_000041
2013-08-16 20:51:57,824 INFO org.apache.hadoop.yarn.server.resourcemanager.scheduler.common.fica.FiCaSchedulerNode: Assigned container container_1376685566219_0006_01_000041 of capacity <memory:1024, vCores:1> on host hadoop-512-2:41669, which currently has 7 containers, <memory:8192, vCores:7> used and <memory:0, vCores:9> available
2013-08-16 20:51:57,825 INFO org.apache.hadoop.yarn.server.resourcemanager.scheduler.capacity.LeafQueue: assignedContainer application=application_1376685566219_0006 container=Container: [ContainerId: container_1376685566219_0006_01_000041, NodeId: hadoop-512-2:41669, NodeHttpAddress: hadoop-512-2:8042, Resource: <memory:1024, vCores:1>, Priority: 20, State: NEW, Token: null, Status: container_id {, app_attempt_id {, application_id {, id: 6, cluster_timestamp: 1376685566219, }, attemptId: 1, }, id: 41, }, state: C_NEW, ] containerId=container_1376685566219_0006_01_000041 queue=default: capacity=1.0, absoluteCapacity=1.0, usedResources=<memory:48128, vCores:42>usedCapacity=0.9791667, absoluteUsedCapacity=0.9791667, numApps=5, numContainers=42 usedCapacity=0.9791667 absoluteUsedCapacity=0.9791667 used=<memory:48128, vCores:42> cluster=<memory:49152, vCores:96>
2013-08-16 20:51:57,825 INFO org.apache.hadoop.yarn.server.resourcemanager.scheduler.capacity.ParentQueue: Re-sorting queues since queue: root.default stats: default: capacity=1.0, absoluteCapacity=1.0, usedResources=<memory:49152, vCores:43>usedCapacity=1.0, absoluteUsedCapacity=1.0, numApps=5, numContainers=43
2013-08-16 20:51:57,825 INFO org.apache.hadoop.yarn.server.resourcemanager.scheduler.capacity.ParentQueue: assignedContainer queue=root usedCapacity=1.0 absoluteUsedCapacity=1.0 used=<memory:49152, vCores:43> cluster=<memory:49152, vCores:96>
2013-08-16 20:51:58,646 INFO org.apache.hadoop.yarn.server.resourcemanager.rmcontainer.RMContainerImpl: container_1376685566219_0006_01_000041 Container Transitioned from ALLOCATED to ACQUIRED
2013-08-16 20:51:58,909 INFO org.apache.hadoop.yarn.server.resourcemanager.rmcontainer.RMContainerImpl: container_1376685566219_0006_01_000041 Container Transitioned from ACQUIRED to RUNNING
2013-08-16 20:51:58,909 INFO org.apache.hadoop.yarn.server.resourcemanager.rmcontainer.RMContainerImpl: container_1376685566219_0006_01_000021 Container Transitioned from RUNNING to COMPLETED
2013-08-16 20:51:58,909 INFO org.apache.hadoop.yarn.server.resourcemanager.scheduler.common.fica.FiCaSchedulerApp: Completed container: container_1376685566219_0006_01_000021 in state: COMPLETED event:FINISHED
2013-08-16 20:51:58,909 INFO org.apache.hadoop.yarn.server.resourcemanager.RMAuditLogger: USER=ubuntu	OPERATION=AM Released Container	TARGET=SchedulerApp	RESULT=SUCCESS	APPID=application_1376685566219_0006	CONTAINERID=container_1376685566219_0006_01_000021
2013-08-16 20:51:58,910 INFO org.apache.hadoop.yarn.server.resourcemanager.scheduler.common.fica.FiCaSchedulerNode: Released container container_1376685566219_0006_01_000021 of capacity <memory:1024, vCores:1> on host hadoop-512-2:41669, which currently has 6 containers, <memory:7168, vCores:6> used and <memory:1024, vCores:10> available, release resources=true
2013-08-16 20:51:58,910 INFO org.apache.hadoop.yarn.server.resourcemanager.scheduler.capacity.LeafQueue: default used=<memory:48128, vCores:42> numContainers=42 user=ubuntu user-resources=<memory:48128, vCores:42>
2013-08-16 20:51:58,911 INFO org.apache.hadoop.yarn.server.resourcemanager.scheduler.capacity.LeafQueue: completedContainer container=Container: [ContainerId: container_1376685566219_0006_01_000021, NodeId: hadoop-512-2:41669, NodeHttpAddress: hadoop-512-2:8042, Resource: <memory:1024, vCores:1>, Priority: 20, State: NEW, Token: null, Status: container_id {, app_attempt_id {, application_id {, id: 6, cluster_timestamp: 1376685566219, }, attemptId: 1, }, id: 21, }, state: C_COMPLETE, diagnostics: "Container killed by the ApplicationMaster.\n\n", exit_status: 143, ] resource=<memory:1024, vCores:1> queue=default: capacity=1.0, absoluteCapacity=1.0, usedResources=<memory:48128, vCores:42>usedCapacity=0.9791667, absoluteUsedCapacity=0.9791667, numApps=5, numContainers=42 usedCapacity=0.9791667 absoluteUsedCapacity=0.9791667 used=<memory:48128, vCores:42> cluster=<memory:49152, vCores:96>
2013-08-16 20:51:58,911 INFO org.apache.hadoop.yarn.server.resourcemanager.scheduler.capacity.ParentQueue: completedContainer queue=root usedCapacity=0.9791667 absoluteUsedCapacity=0.9791667 used=<memory:48128, vCores:42> cluster=<memory:49152, vCores:96>
2013-08-16 20:51:58,911 INFO org.apache.hadoop.yarn.server.resourcemanager.scheduler.capacity.CapacityScheduler: Application appattempt_1376685566219_0006_000001 released container container_1376685566219_0006_01_000021 on node: host: hadoop-512-2:41669 #containers=6 available=1024 used=7168 with event: FINISHED
2013-08-16 20:51:58,912 INFO org.apache.hadoop.yarn.server.resourcemanager.rmcontainer.RMContainerImpl: container_1376685566219_0006_01_000042 Container Transitioned from NEW to ALLOCATED
2013-08-16 20:51:58,912 INFO org.apache.hadoop.yarn.server.resourcemanager.RMAuditLogger: USER=ubuntu	OPERATION=AM Allocated Container	TARGET=SchedulerApp	RESULT=SUCCESS	APPID=application_1376685566219_0006	CONTAINERID=container_1376685566219_0006_01_000042
2013-08-16 20:51:58,912 INFO org.apache.hadoop.yarn.server.resourcemanager.scheduler.common.fica.FiCaSchedulerNode: Assigned container container_1376685566219_0006_01_000042 of capacity <memory:1024, vCores:1> on host hadoop-512-2:41669, which currently has 7 containers, <memory:8192, vCores:7> used and <memory:0, vCores:9> available
2013-08-16 20:51:58,913 INFO org.apache.hadoop.yarn.server.resourcemanager.scheduler.capacity.LeafQueue: assignedContainer application=application_1376685566219_0006 container=Container: [ContainerId: container_1376685566219_0006_01_000042, NodeId: hadoop-512-2:41669, NodeHttpAddress: hadoop-512-2:8042, Resource: <memory:1024, vCores:1>, Priority: 10, State: NEW, Token: null, Status: container_id {, app_attempt_id {, application_id {, id: 6, cluster_timestamp: 1376685566219, }, attemptId: 1, }, id: 42, }, state: C_NEW, ] containerId=container_1376685566219_0006_01_000042 queue=default: capacity=1.0, absoluteCapacity=1.0, usedResources=<memory:48128, vCores:42>usedCapacity=0.9791667, absoluteUsedCapacity=0.9791667, numApps=5, numContainers=42 usedCapacity=0.9791667 absoluteUsedCapacity=0.9791667 used=<memory:48128, vCores:42> cluster=<memory:49152, vCores:96>
2013-08-16 20:51:58,913 INFO org.apache.hadoop.yarn.server.resourcemanager.scheduler.capacity.ParentQueue: Re-sorting queues since queue: root.default stats: default: capacity=1.0, absoluteCapacity=1.0, usedResources=<memory:49152, vCores:43>usedCapacity=1.0, absoluteUsedCapacity=1.0, numApps=5, numContainers=43
2013-08-16 20:51:58,913 INFO org.apache.hadoop.yarn.server.resourcemanager.scheduler.capacity.ParentQueue: assignedContainer queue=root usedCapacity=1.0 absoluteUsedCapacity=1.0 used=<memory:49152, vCores:43> cluster=<memory:49152, vCores:96>
2013-08-16 20:51:59,676 INFO org.apache.hadoop.yarn.server.resourcemanager.scheduler.AppSchedulingInfo: checking for deactivate... 
2013-08-16 20:51:59,678 INFO org.apache.hadoop.yarn.server.resourcemanager.rmcontainer.RMContainerImpl: container_1376685566219_0006_01_000042 Container Transitioned from ALLOCATED to ACQUIRED
2013-08-16 20:51:59,689 INFO org.apache.hadoop.yarn.server.resourcemanager.rmcontainer.RMContainerImpl: container_1376685566219_0006_01_000037 Container Transitioned from RUNNING to COMPLETED
2013-08-16 20:51:59,689 INFO org.apache.hadoop.yarn.server.resourcemanager.scheduler.common.fica.FiCaSchedulerApp: Completed container: container_1376685566219_0006_01_000037 in state: COMPLETED event:FINISHED
2013-08-16 20:51:59,689 INFO org.apache.hadoop.yarn.server.resourcemanager.RMAuditLogger: USER=ubuntu	OPERATION=AM Released Container	TARGET=SchedulerApp	RESULT=SUCCESS	APPID=application_1376685566219_0006	CONTAINERID=container_1376685566219_0006_01_000037
2013-08-16 20:51:59,689 INFO org.apache.hadoop.yarn.server.resourcemanager.scheduler.common.fica.FiCaSchedulerNode: Released container container_1376685566219_0006_01_000037 of capacity <memory:1024, vCores:1> on host hadoop-512-4:51823, which currently has 7 containers, <memory:7168, vCores:7> used and <memory:1024, vCores:9> available, release resources=true
2013-08-16 20:51:59,689 INFO org.apache.hadoop.yarn.server.resourcemanager.scheduler.capacity.LeafQueue: default used=<memory:48128, vCores:42> numContainers=42 user=ubuntu user-resources=<memory:48128, vCores:42>
2013-08-16 20:51:59,691 INFO org.apache.hadoop.yarn.server.resourcemanager.scheduler.capacity.LeafQueue: completedContainer container=Container: [ContainerId: container_1376685566219_0006_01_000037, NodeId: hadoop-512-4:51823, NodeHttpAddress: hadoop-512-4:8042, Resource: <memory:1024, vCores:1>, Priority: 20, State: NEW, Token: null, Status: container_id {, app_attempt_id {, application_id {, id: 6, cluster_timestamp: 1376685566219, }, attemptId: 1, }, id: 37, }, state: C_COMPLETE, diagnostics: "Container killed by the ApplicationMaster.\n\n", exit_status: 143, ] resource=<memory:1024, vCores:1> queue=default: capacity=1.0, absoluteCapacity=1.0, usedResources=<memory:48128, vCores:42>usedCapacity=0.9791667, absoluteUsedCapacity=0.9791667, numApps=5, numContainers=42 usedCapacity=0.9791667 absoluteUsedCapacity=0.9791667 used=<memory:48128, vCores:42> cluster=<memory:49152, vCores:96>
2013-08-16 20:51:59,691 INFO org.apache.hadoop.yarn.server.resourcemanager.scheduler.capacity.ParentQueue: completedContainer queue=root usedCapacity=0.9791667 absoluteUsedCapacity=0.9791667 used=<memory:48128, vCores:42> cluster=<memory:49152, vCores:96>
2013-08-16 20:51:59,691 INFO org.apache.hadoop.yarn.server.resourcemanager.scheduler.capacity.CapacityScheduler: Application appattempt_1376685566219_0006_000001 released container container_1376685566219_0006_01_000037 on node: host: hadoop-512-4:51823 #containers=7 available=1024 used=7168 with event: FINISHED
2013-08-16 20:51:59,692 INFO org.apache.hadoop.yarn.server.resourcemanager.rmcontainer.RMContainerImpl: container_1376685566219_0006_01_000043 Container Transitioned from NEW to ALLOCATED
2013-08-16 20:51:59,692 INFO org.apache.hadoop.yarn.server.resourcemanager.RMAuditLogger: USER=ubuntu	OPERATION=AM Allocated Container	TARGET=SchedulerApp	RESULT=SUCCESS	APPID=application_1376685566219_0006	CONTAINERID=container_1376685566219_0006_01_000043
2013-08-16 20:51:59,692 INFO org.apache.hadoop.yarn.server.resourcemanager.scheduler.common.fica.FiCaSchedulerNode: Assigned container container_1376685566219_0006_01_000043 of capacity <memory:1024, vCores:1> on host hadoop-512-4:51823, which currently has 8 containers, <memory:8192, vCores:8> used and <memory:0, vCores:8> available
2013-08-16 20:51:59,693 INFO org.apache.hadoop.yarn.server.resourcemanager.scheduler.capacity.LeafQueue: assignedContainer application=application_1376685566219_0006 container=Container: [ContainerId: container_1376685566219_0006_01_000043, NodeId: hadoop-512-4:51823, NodeHttpAddress: hadoop-512-4:8042, Resource: <memory:1024, vCores:1>, Priority: 10, State: NEW, Token: null, Status: container_id {, app_attempt_id {, application_id {, id: 6, cluster_timestamp: 1376685566219, }, attemptId: 1, }, id: 43, }, state: C_NEW, ] containerId=container_1376685566219_0006_01_000043 queue=default: capacity=1.0, absoluteCapacity=1.0, usedResources=<memory:48128, vCores:42>usedCapacity=0.9791667, absoluteUsedCapacity=0.9791667, numApps=5, numContainers=42 usedCapacity=0.9791667 absoluteUsedCapacity=0.9791667 used=<memory:48128, vCores:42> cluster=<memory:49152, vCores:96>
2013-08-16 20:51:59,693 INFO org.apache.hadoop.yarn.server.resourcemanager.scheduler.capacity.ParentQueue: Re-sorting queues since queue: root.default stats: default: capacity=1.0, absoluteCapacity=1.0, usedResources=<memory:49152, vCores:43>usedCapacity=1.0, absoluteUsedCapacity=1.0, numApps=5, numContainers=43
2013-08-16 20:51:59,693 INFO org.apache.hadoop.yarn.server.resourcemanager.scheduler.capacity.ParentQueue: assignedContainer queue=root usedCapacity=1.0 absoluteUsedCapacity=1.0 used=<memory:49152, vCores:43> cluster=<memory:49152, vCores:96>
2013-08-16 20:51:59,917 INFO org.apache.hadoop.yarn.server.resourcemanager.rmcontainer.RMContainerImpl: container_1376685566219_0006_01_000042 Container Transitioned from ACQUIRED to RUNNING
2013-08-16 20:52:00,689 INFO org.apache.hadoop.yarn.server.resourcemanager.rmcontainer.RMContainerImpl: container_1376685566219_0006_01_000043 Container Transitioned from ALLOCATED to ACQUIRED
2013-08-16 20:52:01,717 INFO org.apache.hadoop.yarn.server.resourcemanager.rmcontainer.RMContainerImpl: container_1376685566219_0006_01_000043 Container Transitioned from ACQUIRED to RUNNING
2013-08-16 20:52:02,787 INFO org.apache.hadoop.yarn.server.resourcemanager.rmcontainer.RMContainerImpl: container_1376685566219_0006_01_000023 Container Transitioned from RUNNING to COMPLETED
2013-08-16 20:52:02,787 INFO org.apache.hadoop.yarn.server.resourcemanager.scheduler.common.fica.FiCaSchedulerApp: Completed container: container_1376685566219_0006_01_000023 in state: COMPLETED event:FINISHED
2013-08-16 20:52:02,787 INFO org.apache.hadoop.yarn.server.resourcemanager.RMAuditLogger: USER=ubuntu	OPERATION=AM Released Container	TARGET=SchedulerApp	RESULT=SUCCESS	APPID=application_1376685566219_0006	CONTAINERID=container_1376685566219_0006_01_000023
2013-08-16 20:52:02,788 INFO org.apache.hadoop.yarn.server.resourcemanager.scheduler.common.fica.FiCaSchedulerNode: Released container container_1376685566219_0006_01_000023 of capacity <memory:1024, vCores:1> on host hadoop-512-2:41669, which currently has 6 containers, <memory:7168, vCores:6> used and <memory:1024, vCores:10> available, release resources=true
2013-08-16 20:52:02,788 INFO org.apache.hadoop.yarn.server.resourcemanager.scheduler.capacity.LeafQueue: default used=<memory:48128, vCores:42> numContainers=42 user=ubuntu user-resources=<memory:48128, vCores:42>
2013-08-16 20:52:02,789 INFO org.apache.hadoop.yarn.server.resourcemanager.scheduler.capacity.LeafQueue: completedContainer container=Container: [ContainerId: container_1376685566219_0006_01_000023, NodeId: hadoop-512-2:41669, NodeHttpAddress: hadoop-512-2:8042, Resource: <memory:1024, vCores:1>, Priority: 20, State: NEW, Token: null, Status: container_id {, app_attempt_id {, application_id {, id: 6, cluster_timestamp: 1376685566219, }, attemptId: 1, }, id: 23, }, state: C_COMPLETE, diagnostics: "Container killed by the ApplicationMaster.\n\n", exit_status: 143, ] resource=<memory:1024, vCores:1> queue=default: capacity=1.0, absoluteCapacity=1.0, usedResources=<memory:48128, vCores:42>usedCapacity=0.9791667, absoluteUsedCapacity=0.9791667, numApps=5, numContainers=42 usedCapacity=0.9791667 absoluteUsedCapacity=0.9791667 used=<memory:48128, vCores:42> cluster=<memory:49152, vCores:96>
2013-08-16 20:52:02,789 INFO org.apache.hadoop.yarn.server.resourcemanager.scheduler.capacity.ParentQueue: completedContainer queue=root usedCapacity=0.9791667 absoluteUsedCapacity=0.9791667 used=<memory:48128, vCores:42> cluster=<memory:49152, vCores:96>
2013-08-16 20:52:02,789 INFO org.apache.hadoop.yarn.server.resourcemanager.scheduler.capacity.CapacityScheduler: Application appattempt_1376685566219_0006_000001 released container container_1376685566219_0006_01_000023 on node: host: hadoop-512-2:41669 #containers=6 available=1024 used=7168 with event: FINISHED
2013-08-16 20:52:02,790 INFO org.apache.hadoop.yarn.server.resourcemanager.rmcontainer.RMContainerImpl: container_1376685566219_0006_01_000044 Container Transitioned from NEW to ALLOCATED
2013-08-16 20:52:02,790 INFO org.apache.hadoop.yarn.server.resourcemanager.RMAuditLogger: USER=ubuntu	OPERATION=AM Allocated Container	TARGET=SchedulerApp	RESULT=SUCCESS	APPID=application_1376685566219_0006	CONTAINERID=container_1376685566219_0006_01_000044
2013-08-16 20:52:02,790 INFO org.apache.hadoop.yarn.server.resourcemanager.scheduler.common.fica.FiCaSchedulerNode: Assigned container container_1376685566219_0006_01_000044 of capacity <memory:1024, vCores:1> on host hadoop-512-2:41669, which currently has 7 containers, <memory:8192, vCores:7> used and <memory:0, vCores:9> available
2013-08-16 20:52:02,791 INFO org.apache.hadoop.yarn.server.resourcemanager.scheduler.capacity.LeafQueue: assignedContainer application=application_1376685566219_0006 container=Container: [ContainerId: container_1376685566219_0006_01_000044, NodeId: hadoop-512-2:41669, NodeHttpAddress: hadoop-512-2:8042, Resource: <memory:1024, vCores:1>, Priority: 10, State: NEW, Token: null, Status: container_id {, app_attempt_id {, application_id {, id: 6, cluster_timestamp: 1376685566219, }, attemptId: 1, }, id: 44, }, state: C_NEW, ] containerId=container_1376685566219_0006_01_000044 queue=default: capacity=1.0, absoluteCapacity=1.0, usedResources=<memory:48128, vCores:42>usedCapacity=0.9791667, absoluteUsedCapacity=0.9791667, numApps=5, numContainers=42 usedCapacity=0.9791667 absoluteUsedCapacity=0.9791667 used=<memory:48128, vCores:42> cluster=<memory:49152, vCores:96>
2013-08-16 20:52:02,791 INFO org.apache.hadoop.yarn.server.resourcemanager.scheduler.capacity.ParentQueue: Re-sorting queues since queue: root.default stats: default: capacity=1.0, absoluteCapacity=1.0, usedResources=<memory:49152, vCores:43>usedCapacity=1.0, absoluteUsedCapacity=1.0, numApps=5, numContainers=43
2013-08-16 20:52:02,791 INFO org.apache.hadoop.yarn.server.resourcemanager.scheduler.capacity.ParentQueue: assignedContainer queue=root usedCapacity=1.0 absoluteUsedCapacity=1.0 used=<memory:49152, vCores:43> cluster=<memory:49152, vCores:96>
2013-08-16 20:52:03,708 INFO org.apache.hadoop.yarn.server.resourcemanager.rmcontainer.RMContainerImpl: container_1376685566219_0006_01_000044 Container Transitioned from ALLOCATED to ACQUIRED
2013-08-16 20:52:03,809 INFO org.apache.hadoop.yarn.server.resourcemanager.rmcontainer.RMContainerImpl: container_1376685566219_0006_01_000044 Container Transitioned from ACQUIRED to RUNNING
2013-08-16 20:52:04,765 INFO org.apache.hadoop.yarn.server.resourcemanager.rmcontainer.RMContainerImpl: container_1376685566219_0006_01_000005 Container Transitioned from RUNNING to COMPLETED
2013-08-16 20:52:04,765 INFO org.apache.hadoop.yarn.server.resourcemanager.scheduler.common.fica.FiCaSchedulerApp: Completed container: container_1376685566219_0006_01_000005 in state: COMPLETED event:FINISHED
2013-08-16 20:52:04,765 INFO org.apache.hadoop.yarn.server.resourcemanager.RMAuditLogger: USER=ubuntu	OPERATION=AM Released Container	TARGET=SchedulerApp	RESULT=SUCCESS	APPID=application_1376685566219_0006	CONTAINERID=container_1376685566219_0006_01_000005
2013-08-16 20:52:04,765 INFO org.apache.hadoop.yarn.server.resourcemanager.scheduler.common.fica.FiCaSchedulerNode: Released container container_1376685566219_0006_01_000005 of capacity <memory:1024, vCores:1> on host hadoop-512-7:51513, which currently has 6 containers, <memory:7168, vCores:6> used and <memory:1024, vCores:10> available, release resources=true
2013-08-16 20:52:04,765 INFO org.apache.hadoop.yarn.server.resourcemanager.scheduler.capacity.LeafQueue: default used=<memory:48128, vCores:42> numContainers=42 user=ubuntu user-resources=<memory:48128, vCores:42>
2013-08-16 20:52:04,767 INFO org.apache.hadoop.yarn.server.resourcemanager.scheduler.capacity.LeafQueue: completedContainer container=Container: [ContainerId: container_1376685566219_0006_01_000005, NodeId: hadoop-512-7:51513, NodeHttpAddress: hadoop-512-7:8042, Resource: <memory:1024, vCores:1>, Priority: 20, State: NEW, Token: null, Status: container_id {, app_attempt_id {, application_id {, id: 6, cluster_timestamp: 1376685566219, }, attemptId: 1, }, id: 5, }, state: C_COMPLETE, diagnostics: "Container killed by the ApplicationMaster.\n\n", exit_status: 143, ] resource=<memory:1024, vCores:1> queue=default: capacity=1.0, absoluteCapacity=1.0, usedResources=<memory:48128, vCores:42>usedCapacity=0.9791667, absoluteUsedCapacity=0.9791667, numApps=5, numContainers=42 usedCapacity=0.9791667 absoluteUsedCapacity=0.9791667 used=<memory:48128, vCores:42> cluster=<memory:49152, vCores:96>
2013-08-16 20:52:04,767 INFO org.apache.hadoop.yarn.server.resourcemanager.scheduler.capacity.ParentQueue: completedContainer queue=root usedCapacity=0.9791667 absoluteUsedCapacity=0.9791667 used=<memory:48128, vCores:42> cluster=<memory:49152, vCores:96>
2013-08-16 20:52:04,767 INFO org.apache.hadoop.yarn.server.resourcemanager.scheduler.capacity.CapacityScheduler: Application appattempt_1376685566219_0006_000001 released container container_1376685566219_0006_01_000005 on node: host: hadoop-512-7:51513 #containers=6 available=1024 used=7168 with event: FINISHED
2013-08-16 20:52:04,768 INFO org.apache.hadoop.yarn.server.resourcemanager.rmcontainer.RMContainerImpl: container_1376685566219_0006_01_000045 Container Transitioned from NEW to ALLOCATED
2013-08-16 20:52:04,768 INFO org.apache.hadoop.yarn.server.resourcemanager.RMAuditLogger: USER=ubuntu	OPERATION=AM Allocated Container	TARGET=SchedulerApp	RESULT=SUCCESS	APPID=application_1376685566219_0006	CONTAINERID=container_1376685566219_0006_01_000045
2013-08-16 20:52:04,768 INFO org.apache.hadoop.yarn.server.resourcemanager.scheduler.common.fica.FiCaSchedulerNode: Assigned container container_1376685566219_0006_01_000045 of capacity <memory:1024, vCores:1> on host hadoop-512-7:51513, which currently has 7 containers, <memory:8192, vCores:7> used and <memory:0, vCores:9> available
2013-08-16 20:52:04,769 INFO org.apache.hadoop.yarn.server.resourcemanager.scheduler.capacity.LeafQueue: assignedContainer application=application_1376685566219_0006 container=Container: [ContainerId: container_1376685566219_0006_01_000045, NodeId: hadoop-512-7:51513, NodeHttpAddress: hadoop-512-7:8042, Resource: <memory:1024, vCores:1>, Priority: 10, State: NEW, Token: null, Status: container_id {, app_attempt_id {, application_id {, id: 6, cluster_timestamp: 1376685566219, }, attemptId: 1, }, id: 45, }, state: C_NEW, ] containerId=container_1376685566219_0006_01_000045 queue=default: capacity=1.0, absoluteCapacity=1.0, usedResources=<memory:48128, vCores:42>usedCapacity=0.9791667, absoluteUsedCapacity=0.9791667, numApps=5, numContainers=42 usedCapacity=0.9791667 absoluteUsedCapacity=0.9791667 used=<memory:48128, vCores:42> cluster=<memory:49152, vCores:96>
2013-08-16 20:52:04,769 INFO org.apache.hadoop.yarn.server.resourcemanager.scheduler.capacity.ParentQueue: Re-sorting queues since queue: root.default stats: default: capacity=1.0, absoluteCapacity=1.0, usedResources=<memory:49152, vCores:43>usedCapacity=1.0, absoluteUsedCapacity=1.0, numApps=5, numContainers=43
2013-08-16 20:52:04,769 INFO org.apache.hadoop.yarn.server.resourcemanager.scheduler.capacity.ParentQueue: assignedContainer queue=root usedCapacity=1.0 absoluteUsedCapacity=1.0 used=<memory:49152, vCores:43> cluster=<memory:49152, vCores:96>
2013-08-16 20:52:05,737 INFO org.apache.hadoop.yarn.server.resourcemanager.rmcontainer.RMContainerImpl: container_1376685566219_0006_01_000045 Container Transitioned from ALLOCATED to ACQUIRED
2013-08-16 20:52:05,774 INFO org.apache.hadoop.yarn.server.resourcemanager.rmcontainer.RMContainerImpl: container_1376685566219_0006_01_000045 Container Transitioned from ACQUIRED to RUNNING
2013-08-16 20:52:06,352 INFO org.apache.hadoop.yarn.server.resourcemanager.rmcontainer.RMContainerImpl: container_1376685566219_0006_01_000010 Container Transitioned from RUNNING to COMPLETED
2013-08-16 20:52:06,352 INFO org.apache.hadoop.yarn.server.resourcemanager.scheduler.common.fica.FiCaSchedulerApp: Completed container: container_1376685566219_0006_01_000010 in state: COMPLETED event:FINISHED
2013-08-16 20:52:06,352 INFO org.apache.hadoop.yarn.server.resourcemanager.RMAuditLogger: USER=ubuntu	OPERATION=AM Released Container	TARGET=SchedulerApp	RESULT=SUCCESS	APPID=application_1376685566219_0006	CONTAINERID=container_1376685566219_0006_01_000010
2013-08-16 20:52:06,352 INFO org.apache.hadoop.yarn.server.resourcemanager.scheduler.common.fica.FiCaSchedulerNode: Released container container_1376685566219_0006_01_000010 of capacity <memory:1024, vCores:1> on host hadoop-512-6:40600, which currently has 6 containers, <memory:7168, vCores:6> used and <memory:1024, vCores:10> available, release resources=true
2013-08-16 20:52:06,352 INFO org.apache.hadoop.yarn.server.resourcemanager.scheduler.capacity.LeafQueue: default used=<memory:48128, vCores:42> numContainers=42 user=ubuntu user-resources=<memory:48128, vCores:42>
2013-08-16 20:52:06,353 INFO org.apache.hadoop.yarn.server.resourcemanager.scheduler.capacity.LeafQueue: completedContainer container=Container: [ContainerId: container_1376685566219_0006_01_000010, NodeId: hadoop-512-6:40600, NodeHttpAddress: hadoop-512-6:8042, Resource: <memory:1024, vCores:1>, Priority: 20, State: NEW, Token: null, Status: container_id {, app_attempt_id {, application_id {, id: 6, cluster_timestamp: 1376685566219, }, attemptId: 1, }, id: 10, }, state: C_COMPLETE, diagnostics: "Container killed by the ApplicationMaster.\n\n", exit_status: 143, ] resource=<memory:1024, vCores:1> queue=default: capacity=1.0, absoluteCapacity=1.0, usedResources=<memory:48128, vCores:42>usedCapacity=0.9791667, absoluteUsedCapacity=0.9791667, numApps=5, numContainers=42 usedCapacity=0.9791667 absoluteUsedCapacity=0.9791667 used=<memory:48128, vCores:42> cluster=<memory:49152, vCores:96>
2013-08-16 20:52:06,353 INFO org.apache.hadoop.yarn.server.resourcemanager.scheduler.capacity.ParentQueue: completedContainer queue=root usedCapacity=0.9791667 absoluteUsedCapacity=0.9791667 used=<memory:48128, vCores:42> cluster=<memory:49152, vCores:96>
2013-08-16 20:52:06,354 INFO org.apache.hadoop.yarn.server.resourcemanager.scheduler.capacity.CapacityScheduler: Application appattempt_1376685566219_0006_000001 released container container_1376685566219_0006_01_000010 on node: host: hadoop-512-6:40600 #containers=6 available=1024 used=7168 with event: FINISHED
2013-08-16 20:52:06,354 INFO org.apache.hadoop.yarn.server.resourcemanager.rmcontainer.RMContainerImpl: container_1376685566219_0006_01_000011 Container Transitioned from RUNNING to COMPLETED
2013-08-16 20:52:06,354 INFO org.apache.hadoop.yarn.server.resourcemanager.scheduler.common.fica.FiCaSchedulerApp: Completed container: container_1376685566219_0006_01_000011 in state: COMPLETED event:FINISHED
2013-08-16 20:52:06,354 INFO org.apache.hadoop.yarn.server.resourcemanager.RMAuditLogger: USER=ubuntu	OPERATION=AM Released Container	TARGET=SchedulerApp	RESULT=SUCCESS	APPID=application_1376685566219_0006	CONTAINERID=container_1376685566219_0006_01_000011
2013-08-16 20:52:06,354 INFO org.apache.hadoop.yarn.server.resourcemanager.scheduler.common.fica.FiCaSchedulerNode: Released container container_1376685566219_0006_01_000011 of capacity <memory:1024, vCores:1> on host hadoop-512-6:40600, which currently has 5 containers, <memory:6144, vCores:5> used and <memory:2048, vCores:11> available, release resources=true
2013-08-16 20:52:06,354 INFO org.apache.hadoop.yarn.server.resourcemanager.scheduler.capacity.LeafQueue: default used=<memory:47104, vCores:41> numContainers=41 user=ubuntu user-resources=<memory:47104, vCores:41>
2013-08-16 20:52:06,355 INFO org.apache.hadoop.yarn.server.resourcemanager.scheduler.capacity.LeafQueue: completedContainer container=Container: [ContainerId: container_1376685566219_0006_01_000011, NodeId: hadoop-512-6:40600, NodeHttpAddress: hadoop-512-6:8042, Resource: <memory:1024, vCores:1>, Priority: 20, State: NEW, Token: null, Status: container_id {, app_attempt_id {, application_id {, id: 6, cluster_timestamp: 1376685566219, }, attemptId: 1, }, id: 11, }, state: C_COMPLETE, diagnostics: "Container killed by the ApplicationMaster.\n\n", exit_status: 143, ] resource=<memory:1024, vCores:1> queue=default: capacity=1.0, absoluteCapacity=1.0, usedResources=<memory:47104, vCores:41>usedCapacity=0.9583333, absoluteUsedCapacity=0.9583333, numApps=5, numContainers=41 usedCapacity=0.9583333 absoluteUsedCapacity=0.9583333 used=<memory:47104, vCores:41> cluster=<memory:49152, vCores:96>
2013-08-16 20:52:06,356 INFO org.apache.hadoop.yarn.server.resourcemanager.scheduler.capacity.ParentQueue: completedContainer queue=root usedCapacity=0.9583333 absoluteUsedCapacity=0.9583333 used=<memory:47104, vCores:41> cluster=<memory:49152, vCores:96>
2013-08-16 20:52:06,356 INFO org.apache.hadoop.yarn.server.resourcemanager.scheduler.capacity.CapacityScheduler: Application appattempt_1376685566219_0006_000001 released container container_1376685566219_0006_01_000011 on node: host: hadoop-512-6:40600 #containers=5 available=2048 used=6144 with event: FINISHED
2013-08-16 20:52:06,356 INFO org.apache.hadoop.yarn.server.resourcemanager.rmcontainer.RMContainerImpl: container_1376685566219_0006_01_000046 Container Transitioned from NEW to ALLOCATED
2013-08-16 20:52:06,356 INFO org.apache.hadoop.yarn.server.resourcemanager.RMAuditLogger: USER=ubuntu	OPERATION=AM Allocated Container	TARGET=SchedulerApp	RESULT=SUCCESS	APPID=application_1376685566219_0006	CONTAINERID=container_1376685566219_0006_01_000046
2013-08-16 20:52:06,356 INFO org.apache.hadoop.yarn.server.resourcemanager.scheduler.common.fica.FiCaSchedulerNode: Assigned container container_1376685566219_0006_01_000046 of capacity <memory:1024, vCores:1> on host hadoop-512-6:40600, which currently has 6 containers, <memory:7168, vCores:6> used and <memory:1024, vCores:10> available
2013-08-16 20:52:06,357 INFO org.apache.hadoop.yarn.server.resourcemanager.scheduler.capacity.LeafQueue: assignedContainer application=application_1376685566219_0006 container=Container: [ContainerId: container_1376685566219_0006_01_000046, NodeId: hadoop-512-6:40600, NodeHttpAddress: hadoop-512-6:8042, Resource: <memory:1024, vCores:1>, Priority: 10, State: NEW, Token: null, Status: container_id {, app_attempt_id {, application_id {, id: 6, cluster_timestamp: 1376685566219, }, attemptId: 1, }, id: 46, }, state: C_NEW, ] containerId=container_1376685566219_0006_01_000046 queue=default: capacity=1.0, absoluteCapacity=1.0, usedResources=<memory:47104, vCores:41>usedCapacity=0.9583333, absoluteUsedCapacity=0.9583333, numApps=5, numContainers=41 usedCapacity=0.9583333 absoluteUsedCapacity=0.9583333 used=<memory:47104, vCores:41> cluster=<memory:49152, vCores:96>
2013-08-16 20:52:06,358 INFO org.apache.hadoop.yarn.server.resourcemanager.scheduler.capacity.ParentQueue: Re-sorting queues since queue: root.default stats: default: capacity=1.0, absoluteCapacity=1.0, usedResources=<memory:48128, vCores:42>usedCapacity=0.9791667, absoluteUsedCapacity=0.9791667, numApps=5, numContainers=42
2013-08-16 20:52:06,358 INFO org.apache.hadoop.yarn.server.resourcemanager.scheduler.capacity.ParentQueue: assignedContainer queue=root usedCapacity=0.9791667 absoluteUsedCapacity=0.9791667 used=<memory:48128, vCores:42> cluster=<memory:49152, vCores:96>
2013-08-16 20:52:06,744 INFO org.apache.hadoop.yarn.server.resourcemanager.rmcontainer.RMContainerImpl: container_1376685566219_0006_01_000046 Container Transitioned from ALLOCATED to ACQUIRED
2013-08-16 20:52:07,360 INFO org.apache.hadoop.yarn.server.resourcemanager.rmcontainer.RMContainerImpl: container_1376685566219_0006_01_000047 Container Transitioned from NEW to ALLOCATED
2013-08-16 20:52:07,360 INFO org.apache.hadoop.yarn.server.resourcemanager.RMAuditLogger: USER=ubuntu	OPERATION=AM Allocated Container	TARGET=SchedulerApp	RESULT=SUCCESS	APPID=application_1376685566219_0006	CONTAINERID=container_1376685566219_0006_01_000047
2013-08-16 20:52:07,360 INFO org.apache.hadoop.yarn.server.resourcemanager.scheduler.common.fica.FiCaSchedulerNode: Assigned container container_1376685566219_0006_01_000047 of capacity <memory:1024, vCores:1> on host hadoop-512-6:40600, which currently has 7 containers, <memory:8192, vCores:7> used and <memory:0, vCores:9> available
2013-08-16 20:52:07,361 INFO org.apache.hadoop.yarn.server.resourcemanager.scheduler.capacity.LeafQueue: assignedContainer application=application_1376685566219_0006 container=Container: [ContainerId: container_1376685566219_0006_01_000047, NodeId: hadoop-512-6:40600, NodeHttpAddress: hadoop-512-6:8042, Resource: <memory:1024, vCores:1>, Priority: 10, State: NEW, Token: null, Status: container_id {, app_attempt_id {, application_id {, id: 6, cluster_timestamp: 1376685566219, }, attemptId: 1, }, id: 47, }, state: C_NEW, ] containerId=container_1376685566219_0006_01_000047 queue=default: capacity=1.0, absoluteCapacity=1.0, usedResources=<memory:48128, vCores:42>usedCapacity=0.9791667, absoluteUsedCapacity=0.9791667, numApps=5, numContainers=42 usedCapacity=0.9791667 absoluteUsedCapacity=0.9791667 used=<memory:48128, vCores:42> cluster=<memory:49152, vCores:96>
2013-08-16 20:52:07,361 INFO org.apache.hadoop.yarn.server.resourcemanager.scheduler.capacity.ParentQueue: Re-sorting queues since queue: root.default stats: default: capacity=1.0, absoluteCapacity=1.0, usedResources=<memory:49152, vCores:43>usedCapacity=1.0, absoluteUsedCapacity=1.0, numApps=5, numContainers=43
2013-08-16 20:52:07,362 INFO org.apache.hadoop.yarn.server.resourcemanager.scheduler.capacity.ParentQueue: assignedContainer queue=root usedCapacity=1.0 absoluteUsedCapacity=1.0 used=<memory:49152, vCores:43> cluster=<memory:49152, vCores:96>
2013-08-16 20:52:08,346 INFO org.apache.hadoop.yarn.server.resourcemanager.rmcontainer.RMContainerImpl: container_1376685566219_0006_01_000047 Container Transitioned from ALLOCATED to ACQUIRED
2013-08-16 20:52:08,382 INFO org.apache.hadoop.yarn.server.resourcemanager.rmcontainer.RMContainerImpl: container_1376685566219_0006_01_000046 Container Transitioned from ACQUIRED to RUNNING
2013-08-16 20:52:08,382 INFO org.apache.hadoop.yarn.server.resourcemanager.rmcontainer.RMContainerImpl: container_1376685566219_0006_01_000047 Container Transitioned from ACQUIRED to RUNNING
2013-08-16 20:52:10,400 INFO org.apache.hadoop.yarn.server.resourcemanager.rmcontainer.RMContainerImpl: container_1376685566219_0006_01_000008 Container Transitioned from RUNNING to COMPLETED
2013-08-16 20:52:10,400 INFO org.apache.hadoop.yarn.server.resourcemanager.scheduler.common.fica.FiCaSchedulerApp: Completed container: container_1376685566219_0006_01_000008 in state: COMPLETED event:FINISHED
2013-08-16 20:52:10,400 INFO org.apache.hadoop.yarn.server.resourcemanager.RMAuditLogger: USER=ubuntu	OPERATION=AM Released Container	TARGET=SchedulerApp	RESULT=SUCCESS	APPID=application_1376685566219_0006	CONTAINERID=container_1376685566219_0006_01_000008
2013-08-16 20:52:10,401 INFO org.apache.hadoop.yarn.server.resourcemanager.scheduler.common.fica.FiCaSchedulerNode: Released container container_1376685566219_0006_01_000008 of capacity <memory:1024, vCores:1> on host hadoop-512-6:40600, which currently has 6 containers, <memory:7168, vCores:6> used and <memory:1024, vCores:10> available, release resources=true
2013-08-16 20:52:10,401 INFO org.apache.hadoop.yarn.server.resourcemanager.scheduler.capacity.LeafQueue: default used=<memory:48128, vCores:42> numContainers=42 user=ubuntu user-resources=<memory:48128, vCores:42>
2013-08-16 20:52:10,402 INFO org.apache.hadoop.yarn.server.resourcemanager.scheduler.capacity.LeafQueue: completedContainer container=Container: [ContainerId: container_1376685566219_0006_01_000008, NodeId: hadoop-512-6:40600, NodeHttpAddress: hadoop-512-6:8042, Resource: <memory:1024, vCores:1>, Priority: 20, State: NEW, Token: null, Status: container_id {, app_attempt_id {, application_id {, id: 6, cluster_timestamp: 1376685566219, }, attemptId: 1, }, id: 8, }, state: C_COMPLETE, diagnostics: "Container killed by the ApplicationMaster.\n\n", exit_status: 143, ] resource=<memory:1024, vCores:1> queue=default: capacity=1.0, absoluteCapacity=1.0, usedResources=<memory:48128, vCores:42>usedCapacity=0.9791667, absoluteUsedCapacity=0.9791667, numApps=5, numContainers=42 usedCapacity=0.9791667 absoluteUsedCapacity=0.9791667 used=<memory:48128, vCores:42> cluster=<memory:49152, vCores:96>
2013-08-16 20:52:10,402 INFO org.apache.hadoop.yarn.server.resourcemanager.scheduler.capacity.ParentQueue: completedContainer queue=root usedCapacity=0.9791667 absoluteUsedCapacity=0.9791667 used=<memory:48128, vCores:42> cluster=<memory:49152, vCores:96>
2013-08-16 20:52:10,402 INFO org.apache.hadoop.yarn.server.resourcemanager.scheduler.capacity.CapacityScheduler: Application appattempt_1376685566219_0006_000001 released container container_1376685566219_0006_01_000008 on node: host: hadoop-512-6:40600 #containers=6 available=1024 used=7168 with event: FINISHED
2013-08-16 20:52:10,403 INFO org.apache.hadoop.yarn.server.resourcemanager.rmcontainer.RMContainerImpl: container_1376685566219_0006_01_000048 Container Transitioned from NEW to ALLOCATED
2013-08-16 20:52:10,403 INFO org.apache.hadoop.yarn.server.resourcemanager.RMAuditLogger: USER=ubuntu	OPERATION=AM Allocated Container	TARGET=SchedulerApp	RESULT=SUCCESS	APPID=application_1376685566219_0006	CONTAINERID=container_1376685566219_0006_01_000048
2013-08-16 20:52:10,403 INFO org.apache.hadoop.yarn.server.resourcemanager.scheduler.common.fica.FiCaSchedulerNode: Assigned container container_1376685566219_0006_01_000048 of capacity <memory:1024, vCores:1> on host hadoop-512-6:40600, which currently has 7 containers, <memory:8192, vCores:7> used and <memory:0, vCores:9> available
2013-08-16 20:52:10,404 INFO org.apache.hadoop.yarn.server.resourcemanager.scheduler.capacity.LeafQueue: assignedContainer application=application_1376685566219_0006 container=Container: [ContainerId: container_1376685566219_0006_01_000048, NodeId: hadoop-512-6:40600, NodeHttpAddress: hadoop-512-6:8042, Resource: <memory:1024, vCores:1>, Priority: 10, State: NEW, Token: null, Status: container_id {, app_attempt_id {, application_id {, id: 6, cluster_timestamp: 1376685566219, }, attemptId: 1, }, id: 48, }, state: C_NEW, ] containerId=container_1376685566219_0006_01_000048 queue=default: capacity=1.0, absoluteCapacity=1.0, usedResources=<memory:48128, vCores:42>usedCapacity=0.9791667, absoluteUsedCapacity=0.9791667, numApps=5, numContainers=42 usedCapacity=0.9791667 absoluteUsedCapacity=0.9791667 used=<memory:48128, vCores:42> cluster=<memory:49152, vCores:96>
2013-08-16 20:52:10,404 INFO org.apache.hadoop.yarn.server.resourcemanager.scheduler.capacity.ParentQueue: Re-sorting queues since queue: root.default stats: default: capacity=1.0, absoluteCapacity=1.0, usedResources=<memory:49152, vCores:43>usedCapacity=1.0, absoluteUsedCapacity=1.0, numApps=5, numContainers=43
2013-08-16 20:52:10,404 INFO org.apache.hadoop.yarn.server.resourcemanager.scheduler.capacity.ParentQueue: assignedContainer queue=root usedCapacity=1.0 absoluteUsedCapacity=1.0 used=<memory:49152, vCores:43> cluster=<memory:49152, vCores:96>
2013-08-16 20:52:10,494 INFO org.apache.hadoop.yarn.server.resourcemanager.rmcontainer.RMContainerImpl: container_1376685566219_0006_01_000039 Container Transitioned from RUNNING to COMPLETED
2013-08-16 20:52:10,494 INFO org.apache.hadoop.yarn.server.resourcemanager.scheduler.common.fica.FiCaSchedulerApp: Completed container: container_1376685566219_0006_01_000039 in state: COMPLETED event:FINISHED
2013-08-16 20:52:10,494 INFO org.apache.hadoop.yarn.server.resourcemanager.RMAuditLogger: USER=ubuntu	OPERATION=AM Released Container	TARGET=SchedulerApp	RESULT=SUCCESS	APPID=application_1376685566219_0006	CONTAINERID=container_1376685566219_0006_01_000039
2013-08-16 20:52:10,495 INFO org.apache.hadoop.yarn.server.resourcemanager.scheduler.common.fica.FiCaSchedulerNode: Released container container_1376685566219_0006_01_000039 of capacity <memory:1024, vCores:1> on host hadoop-512-4:51823, which currently has 7 containers, <memory:7168, vCores:7> used and <memory:1024, vCores:9> available, release resources=true
2013-08-16 20:52:10,495 INFO org.apache.hadoop.yarn.server.resourcemanager.scheduler.capacity.LeafQueue: default used=<memory:48128, vCores:42> numContainers=42 user=ubuntu user-resources=<memory:48128, vCores:42>
2013-08-16 20:52:10,496 INFO org.apache.hadoop.yarn.server.resourcemanager.scheduler.capacity.LeafQueue: completedContainer container=Container: [ContainerId: container_1376685566219_0006_01_000039, NodeId: hadoop-512-4:51823, NodeHttpAddress: hadoop-512-4:8042, Resource: <memory:1024, vCores:1>, Priority: 20, State: NEW, Token: null, Status: container_id {, app_attempt_id {, application_id {, id: 6, cluster_timestamp: 1376685566219, }, attemptId: 1, }, id: 39, }, state: C_COMPLETE, diagnostics: "Container killed by the ApplicationMaster.\n\n", exit_status: 143, ] resource=<memory:1024, vCores:1> queue=default: capacity=1.0, absoluteCapacity=1.0, usedResources=<memory:48128, vCores:42>usedCapacity=0.9791667, absoluteUsedCapacity=0.9791667, numApps=5, numContainers=42 usedCapacity=0.9791667 absoluteUsedCapacity=0.9791667 used=<memory:48128, vCores:42> cluster=<memory:49152, vCores:96>
2013-08-16 20:52:10,496 INFO org.apache.hadoop.yarn.server.resourcemanager.scheduler.capacity.ParentQueue: completedContainer queue=root usedCapacity=0.9791667 absoluteUsedCapacity=0.9791667 used=<memory:48128, vCores:42> cluster=<memory:49152, vCores:96>
2013-08-16 20:52:10,496 INFO org.apache.hadoop.yarn.server.resourcemanager.scheduler.capacity.CapacityScheduler: Application appattempt_1376685566219_0006_000001 released container container_1376685566219_0006_01_000039 on node: host: hadoop-512-4:51823 #containers=7 available=1024 used=7168 with event: FINISHED
2013-08-16 20:52:10,497 INFO org.apache.hadoop.yarn.server.resourcemanager.rmcontainer.RMContainerImpl: container_1376685566219_0006_01_000049 Container Transitioned from NEW to ALLOCATED
2013-08-16 20:52:10,497 INFO org.apache.hadoop.yarn.server.resourcemanager.RMAuditLogger: USER=ubuntu	OPERATION=AM Allocated Container	TARGET=SchedulerApp	RESULT=SUCCESS	APPID=application_1376685566219_0006	CONTAINERID=container_1376685566219_0006_01_000049
2013-08-16 20:52:10,497 INFO org.apache.hadoop.yarn.server.resourcemanager.scheduler.common.fica.FiCaSchedulerNode: Assigned container container_1376685566219_0006_01_000049 of capacity <memory:1024, vCores:1> on host hadoop-512-4:51823, which currently has 8 containers, <memory:8192, vCores:8> used and <memory:0, vCores:8> available
2013-08-16 20:52:10,498 INFO org.apache.hadoop.yarn.server.resourcemanager.scheduler.capacity.LeafQueue: assignedContainer application=application_1376685566219_0006 container=Container: [ContainerId: container_1376685566219_0006_01_000049, NodeId: hadoop-512-4:51823, NodeHttpAddress: hadoop-512-4:8042, Resource: <memory:1024, vCores:1>, Priority: 10, State: NEW, Token: null, Status: container_id {, app_attempt_id {, application_id {, id: 6, cluster_timestamp: 1376685566219, }, attemptId: 1, }, id: 49, }, state: C_NEW, ] containerId=container_1376685566219_0006_01_000049 queue=default: capacity=1.0, absoluteCapacity=1.0, usedResources=<memory:48128, vCores:42>usedCapacity=0.9791667, absoluteUsedCapacity=0.9791667, numApps=5, numContainers=42 usedCapacity=0.9791667 absoluteUsedCapacity=0.9791667 used=<memory:48128, vCores:42> cluster=<memory:49152, vCores:96>
2013-08-16 20:52:10,498 INFO org.apache.hadoop.yarn.server.resourcemanager.scheduler.capacity.ParentQueue: Re-sorting queues since queue: root.default stats: default: capacity=1.0, absoluteCapacity=1.0, usedResources=<memory:49152, vCores:43>usedCapacity=1.0, absoluteUsedCapacity=1.0, numApps=5, numContainers=43
2013-08-16 20:52:10,498 INFO org.apache.hadoop.yarn.server.resourcemanager.scheduler.capacity.ParentQueue: assignedContainer queue=root usedCapacity=1.0 absoluteUsedCapacity=1.0 used=<memory:49152, vCores:43> cluster=<memory:49152, vCores:96>
2013-08-16 20:52:11,377 INFO org.apache.hadoop.yarn.server.resourcemanager.rmcontainer.RMContainerImpl: container_1376685566219_0006_01_000048 Container Transitioned from ALLOCATED to ACQUIRED
2013-08-16 20:52:11,378 INFO org.apache.hadoop.yarn.server.resourcemanager.rmcontainer.RMContainerImpl: container_1376685566219_0006_01_000049 Container Transitioned from ALLOCATED to ACQUIRED
2013-08-16 20:52:11,510 INFO org.apache.hadoop.yarn.server.resourcemanager.rmcontainer.RMContainerImpl: container_1376685566219_0006_01_000049 Container Transitioned from ACQUIRED to RUNNING
2013-08-16 20:52:12,358 INFO org.apache.hadoop.yarn.server.resourcemanager.rmcontainer.RMContainerImpl: container_1376685566219_0006_01_000048 Container Transitioned from ACQUIRED to RUNNING
2013-08-16 20:52:12,358 INFO org.apache.hadoop.yarn.server.resourcemanager.rmcontainer.RMContainerImpl: container_1376685566219_0006_01_000013 Container Transitioned from RUNNING to COMPLETED
2013-08-16 20:52:12,366 INFO org.apache.hadoop.yarn.server.resourcemanager.scheduler.common.fica.FiCaSchedulerApp: Completed container: container_1376685566219_0006_01_000013 in state: COMPLETED event:FINISHED
2013-08-16 20:52:12,366 INFO org.apache.hadoop.yarn.server.resourcemanager.RMAuditLogger: USER=ubuntu	OPERATION=AM Released Container	TARGET=SchedulerApp	RESULT=SUCCESS	APPID=application_1376685566219_0006	CONTAINERID=container_1376685566219_0006_01_000013
2013-08-16 20:52:12,366 INFO org.apache.hadoop.yarn.server.resourcemanager.scheduler.common.fica.FiCaSchedulerNode: Released container container_1376685566219_0006_01_000013 of capacity <memory:1024, vCores:1> on host hadoop-512-6:40600, which currently has 6 containers, <memory:7168, vCores:6> used and <memory:1024, vCores:10> available, release resources=true
2013-08-16 20:52:12,366 INFO org.apache.hadoop.yarn.server.resourcemanager.scheduler.capacity.LeafQueue: default used=<memory:48128, vCores:42> numContainers=42 user=ubuntu user-resources=<memory:48128, vCores:42>
2013-08-16 20:52:12,368 INFO org.apache.hadoop.yarn.server.resourcemanager.scheduler.capacity.LeafQueue: completedContainer container=Container: [ContainerId: container_1376685566219_0006_01_000013, NodeId: hadoop-512-6:40600, NodeHttpAddress: hadoop-512-6:8042, Resource: <memory:1024, vCores:1>, Priority: 20, State: NEW, Token: null, Status: container_id {, app_attempt_id {, application_id {, id: 6, cluster_timestamp: 1376685566219, }, attemptId: 1, }, id: 13, }, state: C_COMPLETE, diagnostics: "Container killed by the ApplicationMaster.\n\n", exit_status: 143, ] resource=<memory:1024, vCores:1> queue=default: capacity=1.0, absoluteCapacity=1.0, usedResources=<memory:48128, vCores:42>usedCapacity=0.9791667, absoluteUsedCapacity=0.9791667, numApps=5, numContainers=42 usedCapacity=0.9791667 absoluteUsedCapacity=0.9791667 used=<memory:48128, vCores:42> cluster=<memory:49152, vCores:96>
2013-08-16 20:52:12,368 INFO org.apache.hadoop.yarn.server.resourcemanager.scheduler.capacity.ParentQueue: completedContainer queue=root usedCapacity=0.9791667 absoluteUsedCapacity=0.9791667 used=<memory:48128, vCores:42> cluster=<memory:49152, vCores:96>
2013-08-16 20:52:12,368 INFO org.apache.hadoop.yarn.server.resourcemanager.scheduler.capacity.CapacityScheduler: Application appattempt_1376685566219_0006_000001 released container container_1376685566219_0006_01_000013 on node: host: hadoop-512-6:40600 #containers=6 available=1024 used=7168 with event: FINISHED
2013-08-16 20:52:12,369 INFO org.apache.hadoop.yarn.server.resourcemanager.rmcontainer.RMContainerImpl: container_1376685566219_0006_01_000050 Container Transitioned from NEW to ALLOCATED
2013-08-16 20:52:12,369 INFO org.apache.hadoop.yarn.server.resourcemanager.RMAuditLogger: USER=ubuntu	OPERATION=AM Allocated Container	TARGET=SchedulerApp	RESULT=SUCCESS	APPID=application_1376685566219_0006	CONTAINERID=container_1376685566219_0006_01_000050
2013-08-16 20:52:12,369 INFO org.apache.hadoop.yarn.server.resourcemanager.scheduler.common.fica.FiCaSchedulerNode: Assigned container container_1376685566219_0006_01_000050 of capacity <memory:1024, vCores:1> on host hadoop-512-6:40600, which currently has 7 containers, <memory:8192, vCores:7> used and <memory:0, vCores:9> available
2013-08-16 20:52:12,370 INFO org.apache.hadoop.yarn.server.resourcemanager.scheduler.capacity.LeafQueue: assignedContainer application=application_1376685566219_0006 container=Container: [ContainerId: container_1376685566219_0006_01_000050, NodeId: hadoop-512-6:40600, NodeHttpAddress: hadoop-512-6:8042, Resource: <memory:1024, vCores:1>, Priority: 10, State: NEW, Token: null, Status: container_id {, app_attempt_id {, application_id {, id: 6, cluster_timestamp: 1376685566219, }, attemptId: 1, }, id: 50, }, state: C_NEW, ] containerId=container_1376685566219_0006_01_000050 queue=default: capacity=1.0, absoluteCapacity=1.0, usedResources=<memory:48128, vCores:42>usedCapacity=0.9791667, absoluteUsedCapacity=0.9791667, numApps=5, numContainers=42 usedCapacity=0.9791667 absoluteUsedCapacity=0.9791667 used=<memory:48128, vCores:42> cluster=<memory:49152, vCores:96>
2013-08-16 20:52:12,370 INFO org.apache.hadoop.yarn.server.resourcemanager.scheduler.capacity.ParentQueue: Re-sorting queues since queue: root.default stats: default: capacity=1.0, absoluteCapacity=1.0, usedResources=<memory:49152, vCores:43>usedCapacity=1.0, absoluteUsedCapacity=1.0, numApps=5, numContainers=43
2013-08-16 20:52:12,370 INFO org.apache.hadoop.yarn.server.resourcemanager.scheduler.capacity.ParentQueue: assignedContainer queue=root usedCapacity=1.0 absoluteUsedCapacity=1.0 used=<memory:49152, vCores:43> cluster=<memory:49152, vCores:96>
2013-08-16 20:52:12,386 INFO org.apache.hadoop.yarn.server.resourcemanager.rmcontainer.RMContainerImpl: container_1376685566219_0006_01_000050 Container Transitioned from ALLOCATED to ACQUIRED
2013-08-16 20:52:13,366 INFO org.apache.hadoop.yarn.server.resourcemanager.rmcontainer.RMContainerImpl: container_1376685566219_0006_01_000050 Container Transitioned from ACQUIRED to RUNNING
2013-08-16 20:52:16,750 INFO org.apache.hadoop.yarn.server.resourcemanager.rmcontainer.RMContainerImpl: container_1376685566219_0006_01_000016 Container Transitioned from RUNNING to COMPLETED
2013-08-16 20:52:16,750 INFO org.apache.hadoop.yarn.server.resourcemanager.scheduler.common.fica.FiCaSchedulerApp: Completed container: container_1376685566219_0006_01_000016 in state: COMPLETED event:FINISHED
2013-08-16 20:52:16,750 INFO org.apache.hadoop.yarn.server.resourcemanager.RMAuditLogger: USER=ubuntu	OPERATION=AM Released Container	TARGET=SchedulerApp	RESULT=SUCCESS	APPID=application_1376685566219_0006	CONTAINERID=container_1376685566219_0006_01_000016
2013-08-16 20:52:16,751 INFO org.apache.hadoop.yarn.server.resourcemanager.scheduler.common.fica.FiCaSchedulerNode: Released container container_1376685566219_0006_01_000016 of capacity <memory:1024, vCores:1> on host hadoop-512-3:58863, which currently has 6 containers, <memory:7168, vCores:6> used and <memory:1024, vCores:10> available, release resources=true
2013-08-16 20:52:16,751 INFO org.apache.hadoop.yarn.server.resourcemanager.scheduler.capacity.LeafQueue: default used=<memory:48128, vCores:42> numContainers=42 user=ubuntu user-resources=<memory:48128, vCores:42>
2013-08-16 20:52:16,752 INFO org.apache.hadoop.yarn.server.resourcemanager.scheduler.capacity.LeafQueue: completedContainer container=Container: [ContainerId: container_1376685566219_0006_01_000016, NodeId: hadoop-512-3:58863, NodeHttpAddress: hadoop-512-3:8042, Resource: <memory:1024, vCores:1>, Priority: 20, State: NEW, Token: null, Status: container_id {, app_attempt_id {, application_id {, id: 6, cluster_timestamp: 1376685566219, }, attemptId: 1, }, id: 16, }, state: C_COMPLETE, diagnostics: "Container killed by the ApplicationMaster.\n", exit_status: 0, ] resource=<memory:1024, vCores:1> queue=default: capacity=1.0, absoluteCapacity=1.0, usedResources=<memory:48128, vCores:42>usedCapacity=0.9791667, absoluteUsedCapacity=0.9791667, numApps=5, numContainers=42 usedCapacity=0.9791667 absoluteUsedCapacity=0.9791667 used=<memory:48128, vCores:42> cluster=<memory:49152, vCores:96>
2013-08-16 20:52:16,752 INFO org.apache.hadoop.yarn.server.resourcemanager.scheduler.capacity.ParentQueue: completedContainer queue=root usedCapacity=0.9791667 absoluteUsedCapacity=0.9791667 used=<memory:48128, vCores:42> cluster=<memory:49152, vCores:96>
2013-08-16 20:52:16,752 INFO org.apache.hadoop.yarn.server.resourcemanager.scheduler.capacity.CapacityScheduler: Application appattempt_1376685566219_0006_000001 released container container_1376685566219_0006_01_000016 on node: host: hadoop-512-3:58863 #containers=6 available=1024 used=7168 with event: FINISHED
2013-08-16 20:52:16,752 INFO org.apache.hadoop.yarn.server.resourcemanager.rmcontainer.RMContainerImpl: container_1376685566219_0006_01_000018 Container Transitioned from RUNNING to COMPLETED
2013-08-16 20:52:16,752 INFO org.apache.hadoop.yarn.server.resourcemanager.scheduler.common.fica.FiCaSchedulerApp: Completed container: container_1376685566219_0006_01_000018 in state: COMPLETED event:FINISHED
2013-08-16 20:52:16,753 INFO org.apache.hadoop.yarn.server.resourcemanager.RMAuditLogger: USER=ubuntu	OPERATION=AM Released Container	TARGET=SchedulerApp	RESULT=SUCCESS	APPID=application_1376685566219_0006	CONTAINERID=container_1376685566219_0006_01_000018
2013-08-16 20:52:16,753 INFO org.apache.hadoop.yarn.server.resourcemanager.scheduler.common.fica.FiCaSchedulerNode: Released container container_1376685566219_0006_01_000018 of capacity <memory:1024, vCores:1> on host hadoop-512-3:58863, which currently has 5 containers, <memory:6144, vCores:5> used and <memory:2048, vCores:11> available, release resources=true
2013-08-16 20:52:16,753 INFO org.apache.hadoop.yarn.server.resourcemanager.scheduler.capacity.LeafQueue: default used=<memory:47104, vCores:41> numContainers=41 user=ubuntu user-resources=<memory:47104, vCores:41>
2013-08-16 20:52:16,754 INFO org.apache.hadoop.yarn.server.resourcemanager.scheduler.capacity.LeafQueue: completedContainer container=Container: [ContainerId: container_1376685566219_0006_01_000018, NodeId: hadoop-512-3:58863, NodeHttpAddress: hadoop-512-3:8042, Resource: <memory:1024, vCores:1>, Priority: 20, State: NEW, Token: null, Status: container_id {, app_attempt_id {, application_id {, id: 6, cluster_timestamp: 1376685566219, }, attemptId: 1, }, id: 18, }, state: C_COMPLETE, diagnostics: "Container killed by the ApplicationMaster.\n", exit_status: 0, ] resource=<memory:1024, vCores:1> queue=default: capacity=1.0, absoluteCapacity=1.0, usedResources=<memory:47104, vCores:41>usedCapacity=0.9583333, absoluteUsedCapacity=0.9583333, numApps=5, numContainers=41 usedCapacity=0.9583333 absoluteUsedCapacity=0.9583333 used=<memory:47104, vCores:41> cluster=<memory:49152, vCores:96>
2013-08-16 20:52:16,754 INFO org.apache.hadoop.yarn.server.resourcemanager.scheduler.capacity.ParentQueue: completedContainer queue=root usedCapacity=0.9583333 absoluteUsedCapacity=0.9583333 used=<memory:47104, vCores:41> cluster=<memory:49152, vCores:96>
2013-08-16 20:52:16,754 INFO org.apache.hadoop.yarn.server.resourcemanager.scheduler.capacity.CapacityScheduler: Application appattempt_1376685566219_0006_000001 released container container_1376685566219_0006_01_000018 on node: host: hadoop-512-3:58863 #containers=5 available=2048 used=6144 with event: FINISHED
2013-08-16 20:52:16,755 INFO org.apache.hadoop.yarn.server.resourcemanager.rmcontainer.RMContainerImpl: container_1376685566219_0006_01_000051 Container Transitioned from NEW to ALLOCATED
2013-08-16 20:52:16,755 INFO org.apache.hadoop.yarn.server.resourcemanager.RMAuditLogger: USER=ubuntu	OPERATION=AM Allocated Container	TARGET=SchedulerApp	RESULT=SUCCESS	APPID=application_1376685566219_0006	CONTAINERID=container_1376685566219_0006_01_000051
2013-08-16 20:52:16,755 INFO org.apache.hadoop.yarn.server.resourcemanager.scheduler.common.fica.FiCaSchedulerNode: Assigned container container_1376685566219_0006_01_000051 of capacity <memory:1024, vCores:1> on host hadoop-512-3:58863, which currently has 6 containers, <memory:7168, vCores:6> used and <memory:1024, vCores:10> available
2013-08-16 20:52:16,756 INFO org.apache.hadoop.yarn.server.resourcemanager.scheduler.capacity.LeafQueue: assignedContainer application=application_1376685566219_0006 container=Container: [ContainerId: container_1376685566219_0006_01_000051, NodeId: hadoop-512-3:58863, NodeHttpAddress: hadoop-512-3:8042, Resource: <memory:1024, vCores:1>, Priority: 10, State: NEW, Token: null, Status: container_id {, app_attempt_id {, application_id {, id: 6, cluster_timestamp: 1376685566219, }, attemptId: 1, }, id: 51, }, state: C_NEW, ] containerId=container_1376685566219_0006_01_000051 queue=default: capacity=1.0, absoluteCapacity=1.0, usedResources=<memory:47104, vCores:41>usedCapacity=0.9583333, absoluteUsedCapacity=0.9583333, numApps=5, numContainers=41 usedCapacity=0.9583333 absoluteUsedCapacity=0.9583333 used=<memory:47104, vCores:41> cluster=<memory:49152, vCores:96>
2013-08-16 20:52:16,756 INFO org.apache.hadoop.yarn.server.resourcemanager.scheduler.capacity.ParentQueue: Re-sorting queues since queue: root.default stats: default: capacity=1.0, absoluteCapacity=1.0, usedResources=<memory:48128, vCores:42>usedCapacity=0.9791667, absoluteUsedCapacity=0.9791667, numApps=5, numContainers=42
2013-08-16 20:52:16,756 INFO org.apache.hadoop.yarn.server.resourcemanager.scheduler.capacity.ParentQueue: assignedContainer queue=root usedCapacity=0.9791667 absoluteUsedCapacity=0.9791667 used=<memory:48128, vCores:42> cluster=<memory:49152, vCores:96>
2013-08-16 20:52:17,409 INFO org.apache.hadoop.yarn.server.resourcemanager.rmcontainer.RMContainerImpl: container_1376685566219_0006_01_000051 Container Transitioned from ALLOCATED to ACQUIRED
2013-08-16 20:52:17,757 INFO org.apache.hadoop.yarn.server.resourcemanager.rmcontainer.RMContainerImpl: container_1376685566219_0006_01_000051 Container Transitioned from ACQUIRED to RUNNING
2013-08-16 20:52:17,758 INFO org.apache.hadoop.yarn.server.resourcemanager.rmcontainer.RMContainerImpl: container_1376685566219_0007_01_000002 Container Transitioned from NEW to ALLOCATED
2013-08-16 20:52:17,758 INFO org.apache.hadoop.yarn.server.resourcemanager.RMAuditLogger: USER=ubuntu	OPERATION=AM Allocated Container	TARGET=SchedulerApp	RESULT=SUCCESS	APPID=application_1376685566219_0007	CONTAINERID=container_1376685566219_0007_01_000002
2013-08-16 20:52:17,758 INFO org.apache.hadoop.yarn.server.resourcemanager.scheduler.common.fica.FiCaSchedulerNode: Assigned container container_1376685566219_0007_01_000002 of capacity <memory:1024, vCores:1> on host hadoop-512-3:58863, which currently has 7 containers, <memory:8192, vCores:7> used and <memory:0, vCores:9> available
2013-08-16 20:52:17,759 INFO org.apache.hadoop.yarn.server.resourcemanager.scheduler.capacity.LeafQueue: assignedContainer application=application_1376685566219_0007 container=Container: [ContainerId: container_1376685566219_0007_01_000002, NodeId: hadoop-512-3:58863, NodeHttpAddress: hadoop-512-3:8042, Resource: <memory:1024, vCores:1>, Priority: 20, State: NEW, Token: null, Status: container_id {, app_attempt_id {, application_id {, id: 7, cluster_timestamp: 1376685566219, }, attemptId: 1, }, id: 2, }, state: C_NEW, ] containerId=container_1376685566219_0007_01_000002 queue=default: capacity=1.0, absoluteCapacity=1.0, usedResources=<memory:48128, vCores:42>usedCapacity=0.9791667, absoluteUsedCapacity=0.9791667, numApps=5, numContainers=42 usedCapacity=0.9791667 absoluteUsedCapacity=0.9791667 used=<memory:48128, vCores:42> cluster=<memory:49152, vCores:96>
2013-08-16 20:52:17,759 INFO org.apache.hadoop.yarn.server.resourcemanager.scheduler.capacity.ParentQueue: Re-sorting queues since queue: root.default stats: default: capacity=1.0, absoluteCapacity=1.0, usedResources=<memory:49152, vCores:43>usedCapacity=1.0, absoluteUsedCapacity=1.0, numApps=5, numContainers=43
2013-08-16 20:52:17,760 INFO org.apache.hadoop.yarn.server.resourcemanager.scheduler.capacity.ParentQueue: assignedContainer queue=root usedCapacity=1.0 absoluteUsedCapacity=1.0 used=<memory:49152, vCores:43> cluster=<memory:49152, vCores:96>
2013-08-16 20:52:18,045 INFO org.apache.hadoop.yarn.server.resourcemanager.rmcontainer.RMContainerImpl: container_1376685566219_0007_01_000002 Container Transitioned from ALLOCATED to ACQUIRED
2013-08-16 20:52:18,421 INFO org.apache.hadoop.yarn.server.resourcemanager.scheduler.AppSchedulingInfo: checking for deactivate... 
2013-08-16 20:52:18,550 INFO org.apache.hadoop.yarn.server.resourcemanager.rmcontainer.RMContainerImpl: container_1376685566219_0006_01_000034 Container Transitioned from RUNNING to COMPLETED
2013-08-16 20:52:18,550 INFO org.apache.hadoop.yarn.server.resourcemanager.scheduler.common.fica.FiCaSchedulerApp: Completed container: container_1376685566219_0006_01_000034 in state: COMPLETED event:FINISHED
2013-08-16 20:52:18,550 INFO org.apache.hadoop.yarn.server.resourcemanager.RMAuditLogger: USER=ubuntu	OPERATION=AM Released Container	TARGET=SchedulerApp	RESULT=SUCCESS	APPID=application_1376685566219_0006	CONTAINERID=container_1376685566219_0006_01_000034
2013-08-16 20:52:18,550 INFO org.apache.hadoop.yarn.server.resourcemanager.scheduler.common.fica.FiCaSchedulerNode: Released container container_1376685566219_0006_01_000034 of capacity <memory:1024, vCores:1> on host hadoop-512-4:51823, which currently has 7 containers, <memory:7168, vCores:7> used and <memory:1024, vCores:9> available, release resources=true
2013-08-16 20:52:18,550 INFO org.apache.hadoop.yarn.server.resourcemanager.scheduler.capacity.LeafQueue: default used=<memory:48128, vCores:42> numContainers=42 user=ubuntu user-resources=<memory:48128, vCores:42>
2013-08-16 20:52:18,551 INFO org.apache.hadoop.yarn.server.resourcemanager.scheduler.capacity.LeafQueue: completedContainer container=Container: [ContainerId: container_1376685566219_0006_01_000034, NodeId: hadoop-512-4:51823, NodeHttpAddress: hadoop-512-4:8042, Resource: <memory:1024, vCores:1>, Priority: 20, State: NEW, Token: null, Status: container_id {, app_attempt_id {, application_id {, id: 6, cluster_timestamp: 1376685566219, }, attemptId: 1, }, id: 34, }, state: C_COMPLETE, diagnostics: "Container killed by the ApplicationMaster.\n\n", exit_status: 143, ] resource=<memory:1024, vCores:1> queue=default: capacity=1.0, absoluteCapacity=1.0, usedResources=<memory:48128, vCores:42>usedCapacity=0.9791667, absoluteUsedCapacity=0.9791667, numApps=5, numContainers=42 usedCapacity=0.9791667 absoluteUsedCapacity=0.9791667 used=<memory:48128, vCores:42> cluster=<memory:49152, vCores:96>
2013-08-16 20:52:18,551 INFO org.apache.hadoop.yarn.server.resourcemanager.scheduler.capacity.ParentQueue: completedContainer queue=root usedCapacity=0.9791667 absoluteUsedCapacity=0.9791667 used=<memory:48128, vCores:42> cluster=<memory:49152, vCores:96>
2013-08-16 20:52:18,552 INFO org.apache.hadoop.yarn.server.resourcemanager.scheduler.capacity.CapacityScheduler: Application appattempt_1376685566219_0006_000001 released container container_1376685566219_0006_01_000034 on node: host: hadoop-512-4:51823 #containers=7 available=1024 used=7168 with event: FINISHED
2013-08-16 20:52:18,552 INFO org.apache.hadoop.yarn.server.resourcemanager.rmcontainer.RMContainerImpl: container_1376685566219_0007_01_000003 Container Transitioned from NEW to ALLOCATED
2013-08-16 20:52:18,552 INFO org.apache.hadoop.yarn.server.resourcemanager.RMAuditLogger: USER=ubuntu	OPERATION=AM Allocated Container	TARGET=SchedulerApp	RESULT=SUCCESS	APPID=application_1376685566219_0007	CONTAINERID=container_1376685566219_0007_01_000003
2013-08-16 20:52:18,552 INFO org.apache.hadoop.yarn.server.resourcemanager.scheduler.common.fica.FiCaSchedulerNode: Assigned container container_1376685566219_0007_01_000003 of capacity <memory:1024, vCores:1> on host hadoop-512-4:51823, which currently has 8 containers, <memory:8192, vCores:8> used and <memory:0, vCores:8> available
2013-08-16 20:52:18,553 INFO org.apache.hadoop.yarn.server.resourcemanager.scheduler.capacity.LeafQueue: assignedContainer application=application_1376685566219_0007 container=Container: [ContainerId: container_1376685566219_0007_01_000003, NodeId: hadoop-512-4:51823, NodeHttpAddress: hadoop-512-4:8042, Resource: <memory:1024, vCores:1>, Priority: 20, State: NEW, Token: null, Status: container_id {, app_attempt_id {, application_id {, id: 7, cluster_timestamp: 1376685566219, }, attemptId: 1, }, id: 3, }, state: C_NEW, ] containerId=container_1376685566219_0007_01_000003 queue=default: capacity=1.0, absoluteCapacity=1.0, usedResources=<memory:48128, vCores:42>usedCapacity=0.9791667, absoluteUsedCapacity=0.9791667, numApps=5, numContainers=42 usedCapacity=0.9791667 absoluteUsedCapacity=0.9791667 used=<memory:48128, vCores:42> cluster=<memory:49152, vCores:96>
2013-08-16 20:52:18,553 INFO org.apache.hadoop.yarn.server.resourcemanager.scheduler.capacity.ParentQueue: Re-sorting queues since queue: root.default stats: default: capacity=1.0, absoluteCapacity=1.0, usedResources=<memory:49152, vCores:43>usedCapacity=1.0, absoluteUsedCapacity=1.0, numApps=5, numContainers=43
2013-08-16 20:52:18,553 INFO org.apache.hadoop.yarn.server.resourcemanager.scheduler.capacity.ParentQueue: assignedContainer queue=root usedCapacity=1.0 absoluteUsedCapacity=1.0 used=<memory:49152, vCores:43> cluster=<memory:49152, vCores:96>
2013-08-16 20:52:18,614 INFO org.apache.hadoop.yarn.server.resourcemanager.rmcontainer.RMContainerImpl: container_1376685566219_0007_01_000002 Container Transitioned from ACQUIRED to RUNNING
2013-08-16 20:52:19,072 INFO org.apache.hadoop.yarn.server.resourcemanager.rmcontainer.RMContainerImpl: container_1376685566219_0007_01_000003 Container Transitioned from ALLOCATED to ACQUIRED
2013-08-16 20:52:19,570 INFO org.apache.hadoop.yarn.server.resourcemanager.rmcontainer.RMContainerImpl: container_1376685566219_0007_01_000003 Container Transitioned from ACQUIRED to RUNNING
2013-08-16 20:52:19,652 INFO org.apache.hadoop.yarn.server.resourcemanager.rmcontainer.RMContainerImpl: container_1376685566219_0006_01_000015 Container Transitioned from RUNNING to COMPLETED
2013-08-16 20:52:19,652 INFO org.apache.hadoop.yarn.server.resourcemanager.scheduler.common.fica.FiCaSchedulerApp: Completed container: container_1376685566219_0006_01_000015 in state: COMPLETED event:FINISHED
2013-08-16 20:52:19,652 INFO org.apache.hadoop.yarn.server.resourcemanager.RMAuditLogger: USER=ubuntu	OPERATION=AM Released Container	TARGET=SchedulerApp	RESULT=SUCCESS	APPID=application_1376685566219_0006	CONTAINERID=container_1376685566219_0006_01_000015
2013-08-16 20:52:19,652 INFO org.apache.hadoop.yarn.server.resourcemanager.scheduler.common.fica.FiCaSchedulerNode: Released container container_1376685566219_0006_01_000015 of capacity <memory:1024, vCores:1> on host hadoop-512-3:58863, which currently has 6 containers, <memory:7168, vCores:6> used and <memory:1024, vCores:10> available, release resources=true
2013-08-16 20:52:19,653 INFO org.apache.hadoop.yarn.server.resourcemanager.scheduler.capacity.LeafQueue: default used=<memory:48128, vCores:42> numContainers=42 user=ubuntu user-resources=<memory:48128, vCores:42>
2013-08-16 20:52:19,654 INFO org.apache.hadoop.yarn.server.resourcemanager.scheduler.capacity.LeafQueue: completedContainer container=Container: [ContainerId: container_1376685566219_0006_01_000015, NodeId: hadoop-512-3:58863, NodeHttpAddress: hadoop-512-3:8042, Resource: <memory:1024, vCores:1>, Priority: 20, State: NEW, Token: null, Status: container_id {, app_attempt_id {, application_id {, id: 6, cluster_timestamp: 1376685566219, }, attemptId: 1, }, id: 15, }, state: C_COMPLETE, diagnostics: "Container killed by the ApplicationMaster.\n", exit_status: 0, ] resource=<memory:1024, vCores:1> queue=default: capacity=1.0, absoluteCapacity=1.0, usedResources=<memory:48128, vCores:42>usedCapacity=0.9791667, absoluteUsedCapacity=0.9791667, numApps=5, numContainers=42 usedCapacity=0.9791667 absoluteUsedCapacity=0.9791667 used=<memory:48128, vCores:42> cluster=<memory:49152, vCores:96>
2013-08-16 20:52:19,654 INFO org.apache.hadoop.yarn.server.resourcemanager.scheduler.capacity.ParentQueue: completedContainer queue=root usedCapacity=0.9791667 absoluteUsedCapacity=0.9791667 used=<memory:48128, vCores:42> cluster=<memory:49152, vCores:96>
2013-08-16 20:52:19,654 INFO org.apache.hadoop.yarn.server.resourcemanager.scheduler.capacity.CapacityScheduler: Application appattempt_1376685566219_0006_000001 released container container_1376685566219_0006_01_000015 on node: host: hadoop-512-3:58863 #containers=6 available=1024 used=7168 with event: FINISHED
2013-08-16 20:52:19,655 INFO org.apache.hadoop.yarn.server.resourcemanager.rmcontainer.RMContainerImpl: container_1376685566219_0007_01_000004 Container Transitioned from NEW to ALLOCATED
2013-08-16 20:52:19,655 INFO org.apache.hadoop.yarn.server.resourcemanager.RMAuditLogger: USER=ubuntu	OPERATION=AM Allocated Container	TARGET=SchedulerApp	RESULT=SUCCESS	APPID=application_1376685566219_0007	CONTAINERID=container_1376685566219_0007_01_000004
2013-08-16 20:52:19,655 INFO org.apache.hadoop.yarn.server.resourcemanager.scheduler.common.fica.FiCaSchedulerNode: Assigned container container_1376685566219_0007_01_000004 of capacity <memory:1024, vCores:1> on host hadoop-512-3:58863, which currently has 7 containers, <memory:8192, vCores:7> used and <memory:0, vCores:9> available
2013-08-16 20:52:19,656 INFO org.apache.hadoop.yarn.server.resourcemanager.scheduler.capacity.LeafQueue: assignedContainer application=application_1376685566219_0007 container=Container: [ContainerId: container_1376685566219_0007_01_000004, NodeId: hadoop-512-3:58863, NodeHttpAddress: hadoop-512-3:8042, Resource: <memory:1024, vCores:1>, Priority: 20, State: NEW, Token: null, Status: container_id {, app_attempt_id {, application_id {, id: 7, cluster_timestamp: 1376685566219, }, attemptId: 1, }, id: 4, }, state: C_NEW, ] containerId=container_1376685566219_0007_01_000004 queue=default: capacity=1.0, absoluteCapacity=1.0, usedResources=<memory:48128, vCores:42>usedCapacity=0.9791667, absoluteUsedCapacity=0.9791667, numApps=5, numContainers=42 usedCapacity=0.9791667 absoluteUsedCapacity=0.9791667 used=<memory:48128, vCores:42> cluster=<memory:49152, vCores:96>
2013-08-16 20:52:19,656 INFO org.apache.hadoop.yarn.server.resourcemanager.scheduler.capacity.ParentQueue: Re-sorting queues since queue: root.default stats: default: capacity=1.0, absoluteCapacity=1.0, usedResources=<memory:49152, vCores:43>usedCapacity=1.0, absoluteUsedCapacity=1.0, numApps=5, numContainers=43
2013-08-16 20:52:19,656 INFO org.apache.hadoop.yarn.server.resourcemanager.scheduler.capacity.ParentQueue: assignedContainer queue=root usedCapacity=1.0 absoluteUsedCapacity=1.0 used=<memory:49152, vCores:43> cluster=<memory:49152, vCores:96>
2013-08-16 20:52:20,085 INFO org.apache.hadoop.yarn.server.resourcemanager.rmcontainer.RMContainerImpl: container_1376685566219_0007_01_000004 Container Transitioned from ALLOCATED to ACQUIRED
2013-08-16 20:52:20,679 INFO org.apache.hadoop.yarn.server.resourcemanager.rmcontainer.RMContainerImpl: container_1376685566219_0007_01_000004 Container Transitioned from ACQUIRED to RUNNING
2013-08-16 20:52:22,399 INFO org.apache.hadoop.yarn.server.resourcemanager.rmcontainer.RMContainerImpl: container_1376685566219_0006_01_000017 Container Transitioned from RUNNING to COMPLETED
2013-08-16 20:52:22,399 INFO org.apache.hadoop.yarn.server.resourcemanager.scheduler.common.fica.FiCaSchedulerApp: Completed container: container_1376685566219_0006_01_000017 in state: COMPLETED event:FINISHED
2013-08-16 20:52:22,399 INFO org.apache.hadoop.yarn.server.resourcemanager.RMAuditLogger: USER=ubuntu	OPERATION=AM Released Container	TARGET=SchedulerApp	RESULT=SUCCESS	APPID=application_1376685566219_0006	CONTAINERID=container_1376685566219_0006_01_000017
2013-08-16 20:52:22,400 INFO org.apache.hadoop.yarn.server.resourcemanager.scheduler.common.fica.FiCaSchedulerNode: Released container container_1376685566219_0006_01_000017 of capacity <memory:1024, vCores:1> on host hadoop-512-3:58863, which currently has 6 containers, <memory:7168, vCores:6> used and <memory:1024, vCores:10> available, release resources=true
2013-08-16 20:52:22,400 INFO org.apache.hadoop.yarn.server.resourcemanager.scheduler.capacity.LeafQueue: default used=<memory:48128, vCores:42> numContainers=42 user=ubuntu user-resources=<memory:48128, vCores:42>
2013-08-16 20:52:22,401 INFO org.apache.hadoop.yarn.server.resourcemanager.scheduler.capacity.LeafQueue: completedContainer container=Container: [ContainerId: container_1376685566219_0006_01_000017, NodeId: hadoop-512-3:58863, NodeHttpAddress: hadoop-512-3:8042, Resource: <memory:1024, vCores:1>, Priority: 20, State: NEW, Token: null, Status: container_id {, app_attempt_id {, application_id {, id: 6, cluster_timestamp: 1376685566219, }, attemptId: 1, }, id: 17, }, state: C_COMPLETE, diagnostics: "Container killed by the ApplicationMaster.\n\n", exit_status: 143, ] resource=<memory:1024, vCores:1> queue=default: capacity=1.0, absoluteCapacity=1.0, usedResources=<memory:48128, vCores:42>usedCapacity=0.9791667, absoluteUsedCapacity=0.9791667, numApps=5, numContainers=42 usedCapacity=0.9791667 absoluteUsedCapacity=0.9791667 used=<memory:48128, vCores:42> cluster=<memory:49152, vCores:96>
2013-08-16 20:52:22,401 INFO org.apache.hadoop.yarn.server.resourcemanager.scheduler.capacity.ParentQueue: completedContainer queue=root usedCapacity=0.9791667 absoluteUsedCapacity=0.9791667 used=<memory:48128, vCores:42> cluster=<memory:49152, vCores:96>
2013-08-16 20:52:22,401 INFO org.apache.hadoop.yarn.server.resourcemanager.scheduler.capacity.CapacityScheduler: Application appattempt_1376685566219_0006_000001 released container container_1376685566219_0006_01_000017 on node: host: hadoop-512-3:58863 #containers=6 available=1024 used=7168 with event: FINISHED
2013-08-16 20:52:22,402 INFO org.apache.hadoop.yarn.server.resourcemanager.rmcontainer.RMContainerImpl: container_1376685566219_0007_01_000005 Container Transitioned from NEW to ALLOCATED
2013-08-16 20:52:22,402 INFO org.apache.hadoop.yarn.server.resourcemanager.RMAuditLogger: USER=ubuntu	OPERATION=AM Allocated Container	TARGET=SchedulerApp	RESULT=SUCCESS	APPID=application_1376685566219_0007	CONTAINERID=container_1376685566219_0007_01_000005
2013-08-16 20:52:22,402 INFO org.apache.hadoop.yarn.server.resourcemanager.scheduler.common.fica.FiCaSchedulerNode: Assigned container container_1376685566219_0007_01_000005 of capacity <memory:1024, vCores:1> on host hadoop-512-3:58863, which currently has 7 containers, <memory:8192, vCores:7> used and <memory:0, vCores:9> available
2013-08-16 20:52:22,403 INFO org.apache.hadoop.yarn.server.resourcemanager.scheduler.capacity.LeafQueue: assignedContainer application=application_1376685566219_0007 container=Container: [ContainerId: container_1376685566219_0007_01_000005, NodeId: hadoop-512-3:58863, NodeHttpAddress: hadoop-512-3:8042, Resource: <memory:1024, vCores:1>, Priority: 20, State: NEW, Token: null, Status: container_id {, app_attempt_id {, application_id {, id: 7, cluster_timestamp: 1376685566219, }, attemptId: 1, }, id: 5, }, state: C_NEW, ] containerId=container_1376685566219_0007_01_000005 queue=default: capacity=1.0, absoluteCapacity=1.0, usedResources=<memory:48128, vCores:42>usedCapacity=0.9791667, absoluteUsedCapacity=0.9791667, numApps=5, numContainers=42 usedCapacity=0.9791667 absoluteUsedCapacity=0.9791667 used=<memory:48128, vCores:42> cluster=<memory:49152, vCores:96>
2013-08-16 20:52:22,403 INFO org.apache.hadoop.yarn.server.resourcemanager.scheduler.capacity.ParentQueue: Re-sorting queues since queue: root.default stats: default: capacity=1.0, absoluteCapacity=1.0, usedResources=<memory:49152, vCores:43>usedCapacity=1.0, absoluteUsedCapacity=1.0, numApps=5, numContainers=43
2013-08-16 20:52:22,403 INFO org.apache.hadoop.yarn.server.resourcemanager.scheduler.capacity.ParentQueue: assignedContainer queue=root usedCapacity=1.0 absoluteUsedCapacity=1.0 used=<memory:49152, vCores:43> cluster=<memory:49152, vCores:96>
2013-08-16 20:52:23,112 INFO org.apache.hadoop.yarn.server.resourcemanager.rmcontainer.RMContainerImpl: container_1376685566219_0007_01_000005 Container Transitioned from ALLOCATED to ACQUIRED
2013-08-16 20:52:23,410 INFO org.apache.hadoop.yarn.server.resourcemanager.rmcontainer.RMContainerImpl: container_1376685566219_0007_01_000005 Container Transitioned from ACQUIRED to RUNNING
2013-08-16 20:52:25,881 INFO org.apache.hadoop.yarn.server.resourcemanager.rmcontainer.RMContainerImpl: container_1376685566219_0006_01_000027 Container Transitioned from RUNNING to COMPLETED
2013-08-16 20:52:25,881 INFO org.apache.hadoop.yarn.server.resourcemanager.scheduler.common.fica.FiCaSchedulerApp: Completed container: container_1376685566219_0006_01_000027 in state: COMPLETED event:FINISHED
2013-08-16 20:52:25,881 INFO org.apache.hadoop.yarn.server.resourcemanager.RMAuditLogger: USER=ubuntu	OPERATION=AM Released Container	TARGET=SchedulerApp	RESULT=SUCCESS	APPID=application_1376685566219_0006	CONTAINERID=container_1376685566219_0006_01_000027
2013-08-16 20:52:25,881 INFO org.apache.hadoop.yarn.server.resourcemanager.scheduler.common.fica.FiCaSchedulerNode: Released container container_1376685566219_0006_01_000027 of capacity <memory:1024, vCores:1> on host hadoop-512-5:53603, which currently has 6 containers, <memory:7168, vCores:6> used and <memory:1024, vCores:10> available, release resources=true
2013-08-16 20:52:25,881 INFO org.apache.hadoop.yarn.server.resourcemanager.scheduler.capacity.LeafQueue: default used=<memory:48128, vCores:42> numContainers=42 user=ubuntu user-resources=<memory:48128, vCores:42>
2013-08-16 20:52:25,883 INFO org.apache.hadoop.yarn.server.resourcemanager.scheduler.capacity.LeafQueue: completedContainer container=Container: [ContainerId: container_1376685566219_0006_01_000027, NodeId: hadoop-512-5:53603, NodeHttpAddress: hadoop-512-5:8042, Resource: <memory:1024, vCores:1>, Priority: 20, State: NEW, Token: null, Status: container_id {, app_attempt_id {, application_id {, id: 6, cluster_timestamp: 1376685566219, }, attemptId: 1, }, id: 27, }, state: C_COMPLETE, diagnostics: "Container killed by the ApplicationMaster.\n\n", exit_status: 143, ] resource=<memory:1024, vCores:1> queue=default: capacity=1.0, absoluteCapacity=1.0, usedResources=<memory:48128, vCores:42>usedCapacity=0.9791667, absoluteUsedCapacity=0.9791667, numApps=5, numContainers=42 usedCapacity=0.9791667 absoluteUsedCapacity=0.9791667 used=<memory:48128, vCores:42> cluster=<memory:49152, vCores:96>
2013-08-16 20:52:25,883 INFO org.apache.hadoop.yarn.server.resourcemanager.scheduler.capacity.ParentQueue: completedContainer queue=root usedCapacity=0.9791667 absoluteUsedCapacity=0.9791667 used=<memory:48128, vCores:42> cluster=<memory:49152, vCores:96>
2013-08-16 20:52:25,883 INFO org.apache.hadoop.yarn.server.resourcemanager.scheduler.capacity.CapacityScheduler: Application appattempt_1376685566219_0006_000001 released container container_1376685566219_0006_01_000027 on node: host: hadoop-512-5:53603 #containers=6 available=1024 used=7168 with event: FINISHED
2013-08-16 20:52:25,883 INFO org.apache.hadoop.yarn.server.resourcemanager.rmcontainer.RMContainerImpl: container_1376685566219_0007_01_000006 Container Transitioned from NEW to ALLOCATED
2013-08-16 20:52:25,884 INFO org.apache.hadoop.yarn.server.resourcemanager.RMAuditLogger: USER=ubuntu	OPERATION=AM Allocated Container	TARGET=SchedulerApp	RESULT=SUCCESS	APPID=application_1376685566219_0007	CONTAINERID=container_1376685566219_0007_01_000006
2013-08-16 20:52:25,884 INFO org.apache.hadoop.yarn.server.resourcemanager.scheduler.common.fica.FiCaSchedulerNode: Assigned container container_1376685566219_0007_01_000006 of capacity <memory:1024, vCores:1> on host hadoop-512-5:53603, which currently has 7 containers, <memory:8192, vCores:7> used and <memory:0, vCores:9> available
2013-08-16 20:52:25,884 INFO org.apache.hadoop.yarn.server.resourcemanager.scheduler.capacity.LeafQueue: assignedContainer application=application_1376685566219_0007 container=Container: [ContainerId: container_1376685566219_0007_01_000006, NodeId: hadoop-512-5:53603, NodeHttpAddress: hadoop-512-5:8042, Resource: <memory:1024, vCores:1>, Priority: 20, State: NEW, Token: null, Status: container_id {, app_attempt_id {, application_id {, id: 7, cluster_timestamp: 1376685566219, }, attemptId: 1, }, id: 6, }, state: C_NEW, ] containerId=container_1376685566219_0007_01_000006 queue=default: capacity=1.0, absoluteCapacity=1.0, usedResources=<memory:48128, vCores:42>usedCapacity=0.9791667, absoluteUsedCapacity=0.9791667, numApps=5, numContainers=42 usedCapacity=0.9791667 absoluteUsedCapacity=0.9791667 used=<memory:48128, vCores:42> cluster=<memory:49152, vCores:96>
2013-08-16 20:52:25,885 INFO org.apache.hadoop.yarn.server.resourcemanager.scheduler.capacity.ParentQueue: Re-sorting queues since queue: root.default stats: default: capacity=1.0, absoluteCapacity=1.0, usedResources=<memory:49152, vCores:43>usedCapacity=1.0, absoluteUsedCapacity=1.0, numApps=5, numContainers=43
2013-08-16 20:52:25,885 INFO org.apache.hadoop.yarn.server.resourcemanager.scheduler.capacity.ParentQueue: assignedContainer queue=root usedCapacity=1.0 absoluteUsedCapacity=1.0 used=<memory:49152, vCores:43> cluster=<memory:49152, vCores:96>
2013-08-16 20:52:26,129 INFO org.apache.hadoop.yarn.server.resourcemanager.rmcontainer.RMContainerImpl: container_1376685566219_0007_01_000006 Container Transitioned from ALLOCATED to ACQUIRED
2013-08-16 20:52:26,887 INFO org.apache.hadoop.yarn.server.resourcemanager.rmcontainer.RMContainerImpl: container_1376685566219_0007_01_000006 Container Transitioned from ACQUIRED to RUNNING
2013-08-16 20:52:28,408 INFO org.apache.hadoop.yarn.server.resourcemanager.rmcontainer.RMContainerImpl: container_1376685566219_0006_01_000020 Container Transitioned from RUNNING to COMPLETED
2013-08-16 20:52:28,409 INFO org.apache.hadoop.yarn.server.resourcemanager.scheduler.common.fica.FiCaSchedulerApp: Completed container: container_1376685566219_0006_01_000020 in state: COMPLETED event:FINISHED
2013-08-16 20:52:28,409 INFO org.apache.hadoop.yarn.server.resourcemanager.RMAuditLogger: USER=ubuntu	OPERATION=AM Released Container	TARGET=SchedulerApp	RESULT=SUCCESS	APPID=application_1376685566219_0006	CONTAINERID=container_1376685566219_0006_01_000020
2013-08-16 20:52:28,409 INFO org.apache.hadoop.yarn.server.resourcemanager.scheduler.common.fica.FiCaSchedulerNode: Released container container_1376685566219_0006_01_000020 of capacity <memory:1024, vCores:1> on host hadoop-512-2:41669, which currently has 6 containers, <memory:7168, vCores:6> used and <memory:1024, vCores:10> available, release resources=true
2013-08-16 20:52:28,409 INFO org.apache.hadoop.yarn.server.resourcemanager.scheduler.capacity.LeafQueue: default used=<memory:48128, vCores:42> numContainers=42 user=ubuntu user-resources=<memory:48128, vCores:42>
2013-08-16 20:52:28,411 INFO org.apache.hadoop.yarn.server.resourcemanager.scheduler.capacity.LeafQueue: completedContainer container=Container: [ContainerId: container_1376685566219_0006_01_000020, NodeId: hadoop-512-2:41669, NodeHttpAddress: hadoop-512-2:8042, Resource: <memory:1024, vCores:1>, Priority: 20, State: NEW, Token: null, Status: container_id {, app_attempt_id {, application_id {, id: 6, cluster_timestamp: 1376685566219, }, attemptId: 1, }, id: 20, }, state: C_COMPLETE, diagnostics: "Container killed by the ApplicationMaster.\n\n", exit_status: 143, ] resource=<memory:1024, vCores:1> queue=default: capacity=1.0, absoluteCapacity=1.0, usedResources=<memory:48128, vCores:42>usedCapacity=0.9791667, absoluteUsedCapacity=0.9791667, numApps=5, numContainers=42 usedCapacity=0.9791667 absoluteUsedCapacity=0.9791667 used=<memory:48128, vCores:42> cluster=<memory:49152, vCores:96>
2013-08-16 20:52:28,411 INFO org.apache.hadoop.yarn.server.resourcemanager.scheduler.capacity.ParentQueue: completedContainer queue=root usedCapacity=0.9791667 absoluteUsedCapacity=0.9791667 used=<memory:48128, vCores:42> cluster=<memory:49152, vCores:96>
2013-08-16 20:52:28,411 INFO org.apache.hadoop.yarn.server.resourcemanager.scheduler.capacity.CapacityScheduler: Application appattempt_1376685566219_0006_000001 released container container_1376685566219_0006_01_000020 on node: host: hadoop-512-2:41669 #containers=6 available=1024 used=7168 with event: FINISHED
2013-08-16 20:52:28,411 INFO org.apache.hadoop.yarn.server.resourcemanager.rmcontainer.RMContainerImpl: container_1376685566219_0007_01_000007 Container Transitioned from NEW to ALLOCATED
2013-08-16 20:52:28,412 INFO org.apache.hadoop.yarn.server.resourcemanager.RMAuditLogger: USER=ubuntu	OPERATION=AM Allocated Container	TARGET=SchedulerApp	RESULT=SUCCESS	APPID=application_1376685566219_0007	CONTAINERID=container_1376685566219_0007_01_000007
2013-08-16 20:52:28,412 INFO org.apache.hadoop.yarn.server.resourcemanager.scheduler.common.fica.FiCaSchedulerNode: Assigned container container_1376685566219_0007_01_000007 of capacity <memory:1024, vCores:1> on host hadoop-512-2:41669, which currently has 7 containers, <memory:8192, vCores:7> used and <memory:0, vCores:9> available
2013-08-16 20:52:28,412 INFO org.apache.hadoop.yarn.server.resourcemanager.scheduler.capacity.LeafQueue: assignedContainer application=application_1376685566219_0007 container=Container: [ContainerId: container_1376685566219_0007_01_000007, NodeId: hadoop-512-2:41669, NodeHttpAddress: hadoop-512-2:8042, Resource: <memory:1024, vCores:1>, Priority: 20, State: NEW, Token: null, Status: container_id {, app_attempt_id {, application_id {, id: 7, cluster_timestamp: 1376685566219, }, attemptId: 1, }, id: 7, }, state: C_NEW, ] containerId=container_1376685566219_0007_01_000007 queue=default: capacity=1.0, absoluteCapacity=1.0, usedResources=<memory:48128, vCores:42>usedCapacity=0.9791667, absoluteUsedCapacity=0.9791667, numApps=5, numContainers=42 usedCapacity=0.9791667 absoluteUsedCapacity=0.9791667 used=<memory:48128, vCores:42> cluster=<memory:49152, vCores:96>
2013-08-16 20:52:28,413 INFO org.apache.hadoop.yarn.server.resourcemanager.scheduler.capacity.ParentQueue: Re-sorting queues since queue: root.default stats: default: capacity=1.0, absoluteCapacity=1.0, usedResources=<memory:49152, vCores:43>usedCapacity=1.0, absoluteUsedCapacity=1.0, numApps=5, numContainers=43
2013-08-16 20:52:28,413 INFO org.apache.hadoop.yarn.server.resourcemanager.scheduler.capacity.ParentQueue: assignedContainer queue=root usedCapacity=1.0 absoluteUsedCapacity=1.0 used=<memory:49152, vCores:43> cluster=<memory:49152, vCores:96>
2013-08-16 20:52:28,425 INFO org.apache.hadoop.yarn.server.resourcemanager.rmcontainer.RMContainerImpl: container_1376685566219_0006_01_000014 Container Transitioned from RUNNING to COMPLETED
2013-08-16 20:52:28,425 INFO org.apache.hadoop.yarn.server.resourcemanager.scheduler.common.fica.FiCaSchedulerApp: Completed container: container_1376685566219_0006_01_000014 in state: COMPLETED event:FINISHED
2013-08-16 20:52:28,425 INFO org.apache.hadoop.yarn.server.resourcemanager.RMAuditLogger: USER=ubuntu	OPERATION=AM Released Container	TARGET=SchedulerApp	RESULT=SUCCESS	APPID=application_1376685566219_0006	CONTAINERID=container_1376685566219_0006_01_000014
2013-08-16 20:52:28,425 INFO org.apache.hadoop.yarn.server.resourcemanager.scheduler.common.fica.FiCaSchedulerNode: Released container container_1376685566219_0006_01_000014 of capacity <memory:1024, vCores:1> on host hadoop-512-3:58863, which currently has 6 containers, <memory:7168, vCores:6> used and <memory:1024, vCores:10> available, release resources=true
2013-08-16 20:52:28,425 INFO org.apache.hadoop.yarn.server.resourcemanager.scheduler.capacity.LeafQueue: default used=<memory:48128, vCores:42> numContainers=42 user=ubuntu user-resources=<memory:48128, vCores:42>
2013-08-16 20:52:28,426 INFO org.apache.hadoop.yarn.server.resourcemanager.scheduler.capacity.LeafQueue: completedContainer container=Container: [ContainerId: container_1376685566219_0006_01_000014, NodeId: hadoop-512-3:58863, NodeHttpAddress: hadoop-512-3:8042, Resource: <memory:1024, vCores:1>, Priority: 20, State: NEW, Token: null, Status: container_id {, app_attempt_id {, application_id {, id: 6, cluster_timestamp: 1376685566219, }, attemptId: 1, }, id: 14, }, state: C_COMPLETE, diagnostics: "Container killed by the ApplicationMaster.\n\n", exit_status: 143, ] resource=<memory:1024, vCores:1> queue=default: capacity=1.0, absoluteCapacity=1.0, usedResources=<memory:48128, vCores:42>usedCapacity=0.9791667, absoluteUsedCapacity=0.9791667, numApps=5, numContainers=42 usedCapacity=0.9791667 absoluteUsedCapacity=0.9791667 used=<memory:48128, vCores:42> cluster=<memory:49152, vCores:96>
2013-08-16 20:52:28,426 INFO org.apache.hadoop.yarn.server.resourcemanager.scheduler.capacity.ParentQueue: completedContainer queue=root usedCapacity=0.9791667 absoluteUsedCapacity=0.9791667 used=<memory:48128, vCores:42> cluster=<memory:49152, vCores:96>
2013-08-16 20:52:28,427 INFO org.apache.hadoop.yarn.server.resourcemanager.scheduler.capacity.CapacityScheduler: Application appattempt_1376685566219_0006_000001 released container container_1376685566219_0006_01_000014 on node: host: hadoop-512-3:58863 #containers=6 available=1024 used=7168 with event: FINISHED
2013-08-16 20:52:28,427 INFO org.apache.hadoop.yarn.server.resourcemanager.rmcontainer.RMContainerImpl: container_1376685566219_0007_01_000008 Container Transitioned from NEW to ALLOCATED
2013-08-16 20:52:28,427 INFO org.apache.hadoop.yarn.server.resourcemanager.RMAuditLogger: USER=ubuntu	OPERATION=AM Allocated Container	TARGET=SchedulerApp	RESULT=SUCCESS	APPID=application_1376685566219_0007	CONTAINERID=container_1376685566219_0007_01_000008
2013-08-16 20:52:28,427 INFO org.apache.hadoop.yarn.server.resourcemanager.scheduler.common.fica.FiCaSchedulerNode: Assigned container container_1376685566219_0007_01_000008 of capacity <memory:1024, vCores:1> on host hadoop-512-3:58863, which currently has 7 containers, <memory:8192, vCores:7> used and <memory:0, vCores:9> available
2013-08-16 20:52:28,428 INFO org.apache.hadoop.yarn.server.resourcemanager.scheduler.capacity.LeafQueue: assignedContainer application=application_1376685566219_0007 container=Container: [ContainerId: container_1376685566219_0007_01_000008, NodeId: hadoop-512-3:58863, NodeHttpAddress: hadoop-512-3:8042, Resource: <memory:1024, vCores:1>, Priority: 20, State: NEW, Token: null, Status: container_id {, app_attempt_id {, application_id {, id: 7, cluster_timestamp: 1376685566219, }, attemptId: 1, }, id: 8, }, state: C_NEW, ] containerId=container_1376685566219_0007_01_000008 queue=default: capacity=1.0, absoluteCapacity=1.0, usedResources=<memory:48128, vCores:42>usedCapacity=0.9791667, absoluteUsedCapacity=0.9791667, numApps=5, numContainers=42 usedCapacity=0.9791667 absoluteUsedCapacity=0.9791667 used=<memory:48128, vCores:42> cluster=<memory:49152, vCores:96>
2013-08-16 20:52:28,428 INFO org.apache.hadoop.yarn.server.resourcemanager.scheduler.capacity.ParentQueue: Re-sorting queues since queue: root.default stats: default: capacity=1.0, absoluteCapacity=1.0, usedResources=<memory:49152, vCores:43>usedCapacity=1.0, absoluteUsedCapacity=1.0, numApps=5, numContainers=43
2013-08-16 20:52:28,428 INFO org.apache.hadoop.yarn.server.resourcemanager.scheduler.capacity.ParentQueue: assignedContainer queue=root usedCapacity=1.0 absoluteUsedCapacity=1.0 used=<memory:49152, vCores:43> cluster=<memory:49152, vCores:96>
2013-08-16 20:52:29,155 INFO org.apache.hadoop.yarn.server.resourcemanager.rmcontainer.RMContainerImpl: container_1376685566219_0007_01_000007 Container Transitioned from ALLOCATED to ACQUIRED
2013-08-16 20:52:29,157 INFO org.apache.hadoop.yarn.server.resourcemanager.rmcontainer.RMContainerImpl: container_1376685566219_0007_01_000008 Container Transitioned from ALLOCATED to ACQUIRED
2013-08-16 20:52:29,418 INFO org.apache.hadoop.yarn.server.resourcemanager.rmcontainer.RMContainerImpl: container_1376685566219_0007_01_000007 Container Transitioned from ACQUIRED to RUNNING
2013-08-16 20:52:29,839 INFO org.apache.hadoop.yarn.server.resourcemanager.rmcontainer.RMContainerImpl: container_1376685566219_0007_01_000008 Container Transitioned from ACQUIRED to RUNNING
2013-08-16 20:52:30,350 INFO org.apache.hadoop.yarn.server.resourcemanager.rmcontainer.RMContainerImpl: container_1376685566219_0006_01_000026 Container Transitioned from RUNNING to COMPLETED
2013-08-16 20:52:30,350 INFO org.apache.hadoop.yarn.server.resourcemanager.scheduler.common.fica.FiCaSchedulerApp: Completed container: container_1376685566219_0006_01_000026 in state: COMPLETED event:FINISHED
2013-08-16 20:52:30,351 INFO org.apache.hadoop.yarn.server.resourcemanager.RMAuditLogger: USER=ubuntu	OPERATION=AM Released Container	TARGET=SchedulerApp	RESULT=SUCCESS	APPID=application_1376685566219_0006	CONTAINERID=container_1376685566219_0006_01_000026
2013-08-16 20:52:30,351 INFO org.apache.hadoop.yarn.server.resourcemanager.scheduler.common.fica.FiCaSchedulerNode: Released container container_1376685566219_0006_01_000026 of capacity <memory:1024, vCores:1> on host hadoop-512-5:53603, which currently has 6 containers, <memory:7168, vCores:6> used and <memory:1024, vCores:10> available, release resources=true
2013-08-16 20:52:30,351 INFO org.apache.hadoop.yarn.server.resourcemanager.scheduler.capacity.LeafQueue: default used=<memory:48128, vCores:42> numContainers=42 user=ubuntu user-resources=<memory:48128, vCores:42>
2013-08-16 20:52:30,352 INFO org.apache.hadoop.yarn.server.resourcemanager.scheduler.capacity.LeafQueue: completedContainer container=Container: [ContainerId: container_1376685566219_0006_01_000026, NodeId: hadoop-512-5:53603, NodeHttpAddress: hadoop-512-5:8042, Resource: <memory:1024, vCores:1>, Priority: 20, State: NEW, Token: null, Status: container_id {, app_attempt_id {, application_id {, id: 6, cluster_timestamp: 1376685566219, }, attemptId: 1, }, id: 26, }, state: C_COMPLETE, diagnostics: "Container killed by the ApplicationMaster.\n", exit_status: 0, ] resource=<memory:1024, vCores:1> queue=default: capacity=1.0, absoluteCapacity=1.0, usedResources=<memory:48128, vCores:42>usedCapacity=0.9791667, absoluteUsedCapacity=0.9791667, numApps=5, numContainers=42 usedCapacity=0.9791667 absoluteUsedCapacity=0.9791667 used=<memory:48128, vCores:42> cluster=<memory:49152, vCores:96>
2013-08-16 20:52:30,352 INFO org.apache.hadoop.yarn.server.resourcemanager.scheduler.capacity.ParentQueue: completedContainer queue=root usedCapacity=0.9791667 absoluteUsedCapacity=0.9791667 used=<memory:48128, vCores:42> cluster=<memory:49152, vCores:96>
2013-08-16 20:52:30,352 INFO org.apache.hadoop.yarn.server.resourcemanager.scheduler.capacity.CapacityScheduler: Application appattempt_1376685566219_0006_000001 released container container_1376685566219_0006_01_000026 on node: host: hadoop-512-5:53603 #containers=6 available=1024 used=7168 with event: FINISHED
2013-08-16 20:52:30,353 INFO org.apache.hadoop.yarn.server.resourcemanager.rmcontainer.RMContainerImpl: container_1376685566219_0007_01_000009 Container Transitioned from NEW to ALLOCATED
2013-08-16 20:52:30,353 INFO org.apache.hadoop.yarn.server.resourcemanager.RMAuditLogger: USER=ubuntu	OPERATION=AM Allocated Container	TARGET=SchedulerApp	RESULT=SUCCESS	APPID=application_1376685566219_0007	CONTAINERID=container_1376685566219_0007_01_000009
2013-08-16 20:52:30,353 INFO org.apache.hadoop.yarn.server.resourcemanager.scheduler.common.fica.FiCaSchedulerNode: Assigned container container_1376685566219_0007_01_000009 of capacity <memory:1024, vCores:1> on host hadoop-512-5:53603, which currently has 7 containers, <memory:8192, vCores:7> used and <memory:0, vCores:9> available
2013-08-16 20:52:30,354 INFO org.apache.hadoop.yarn.server.resourcemanager.scheduler.capacity.LeafQueue: assignedContainer application=application_1376685566219_0007 container=Container: [ContainerId: container_1376685566219_0007_01_000009, NodeId: hadoop-512-5:53603, NodeHttpAddress: hadoop-512-5:8042, Resource: <memory:1024, vCores:1>, Priority: 20, State: NEW, Token: null, Status: container_id {, app_attempt_id {, application_id {, id: 7, cluster_timestamp: 1376685566219, }, attemptId: 1, }, id: 9, }, state: C_NEW, ] containerId=container_1376685566219_0007_01_000009 queue=default: capacity=1.0, absoluteCapacity=1.0, usedResources=<memory:48128, vCores:42>usedCapacity=0.9791667, absoluteUsedCapacity=0.9791667, numApps=5, numContainers=42 usedCapacity=0.9791667 absoluteUsedCapacity=0.9791667 used=<memory:48128, vCores:42> cluster=<memory:49152, vCores:96>
2013-08-16 20:52:30,354 INFO org.apache.hadoop.yarn.server.resourcemanager.scheduler.capacity.ParentQueue: Re-sorting queues since queue: root.default stats: default: capacity=1.0, absoluteCapacity=1.0, usedResources=<memory:49152, vCores:43>usedCapacity=1.0, absoluteUsedCapacity=1.0, numApps=5, numContainers=43
2013-08-16 20:52:30,354 INFO org.apache.hadoop.yarn.server.resourcemanager.scheduler.capacity.ParentQueue: assignedContainer queue=root usedCapacity=1.0 absoluteUsedCapacity=1.0 used=<memory:49152, vCores:43> cluster=<memory:49152, vCores:96>
2013-08-16 20:52:31,079 INFO org.apache.hadoop.yarn.server.resourcemanager.rmcontainer.RMContainerImpl: container_1376685566219_0006_01_000029 Container Transitioned from RUNNING to COMPLETED
2013-08-16 20:52:31,079 INFO org.apache.hadoop.yarn.server.resourcemanager.scheduler.common.fica.FiCaSchedulerApp: Completed container: container_1376685566219_0006_01_000029 in state: COMPLETED event:FINISHED
2013-08-16 20:52:31,079 INFO org.apache.hadoop.yarn.server.resourcemanager.RMAuditLogger: USER=ubuntu	OPERATION=AM Released Container	TARGET=SchedulerApp	RESULT=SUCCESS	APPID=application_1376685566219_0006	CONTAINERID=container_1376685566219_0006_01_000029
2013-08-16 20:52:31,079 INFO org.apache.hadoop.yarn.server.resourcemanager.scheduler.common.fica.FiCaSchedulerNode: Released container container_1376685566219_0006_01_000029 of capacity <memory:1024, vCores:1> on host hadoop-512-5:53603, which currently has 6 containers, <memory:7168, vCores:6> used and <memory:1024, vCores:10> available, release resources=true
2013-08-16 20:52:31,080 INFO org.apache.hadoop.yarn.server.resourcemanager.scheduler.capacity.LeafQueue: default used=<memory:48128, vCores:42> numContainers=42 user=ubuntu user-resources=<memory:48128, vCores:42>
2013-08-16 20:52:31,081 INFO org.apache.hadoop.yarn.server.resourcemanager.scheduler.capacity.LeafQueue: completedContainer container=Container: [ContainerId: container_1376685566219_0006_01_000029, NodeId: hadoop-512-5:53603, NodeHttpAddress: hadoop-512-5:8042, Resource: <memory:1024, vCores:1>, Priority: 20, State: NEW, Token: null, Status: container_id {, app_attempt_id {, application_id {, id: 6, cluster_timestamp: 1376685566219, }, attemptId: 1, }, id: 29, }, state: C_COMPLETE, diagnostics: "Container killed by the ApplicationMaster.\n\n", exit_status: 143, ] resource=<memory:1024, vCores:1> queue=default: capacity=1.0, absoluteCapacity=1.0, usedResources=<memory:48128, vCores:42>usedCapacity=0.9791667, absoluteUsedCapacity=0.9791667, numApps=5, numContainers=42 usedCapacity=0.9791667 absoluteUsedCapacity=0.9791667 used=<memory:48128, vCores:42> cluster=<memory:49152, vCores:96>
2013-08-16 20:52:31,081 INFO org.apache.hadoop.yarn.server.resourcemanager.scheduler.capacity.ParentQueue: completedContainer queue=root usedCapacity=0.9791667 absoluteUsedCapacity=0.9791667 used=<memory:48128, vCores:42> cluster=<memory:49152, vCores:96>
2013-08-16 20:52:31,081 INFO org.apache.hadoop.yarn.server.resourcemanager.scheduler.capacity.CapacityScheduler: Application appattempt_1376685566219_0006_000001 released container container_1376685566219_0006_01_000029 on node: host: hadoop-512-5:53603 #containers=6 available=1024 used=7168 with event: FINISHED
2013-08-16 20:52:31,081 INFO org.apache.hadoop.yarn.server.resourcemanager.rmcontainer.RMContainerImpl: container_1376685566219_0007_01_000010 Container Transitioned from NEW to ALLOCATED
2013-08-16 20:52:31,082 INFO org.apache.hadoop.yarn.server.resourcemanager.RMAuditLogger: USER=ubuntu	OPERATION=AM Allocated Container	TARGET=SchedulerApp	RESULT=SUCCESS	APPID=application_1376685566219_0007	CONTAINERID=container_1376685566219_0007_01_000010
2013-08-16 20:52:31,082 INFO org.apache.hadoop.yarn.server.resourcemanager.scheduler.common.fica.FiCaSchedulerNode: Assigned container container_1376685566219_0007_01_000010 of capacity <memory:1024, vCores:1> on host hadoop-512-5:53603, which currently has 7 containers, <memory:8192, vCores:7> used and <memory:0, vCores:9> available
