2013-08-10 14:12:30,718 INFO org.apache.hadoop.yarn.server.resourcemanager.ResourceManager: STARTUP_MSG: 
/************************************************************
STARTUP_MSG: Starting ResourceManager
STARTUP_MSG:   host = hadoop-221-1/192.168.100.14
STARTUP_MSG:   args = []
STARTUP_MSG:   version = 3.0.0-SNAPSHOT
STARTUP_MSG:   build = https://github.com/lalithsuresh/hadoop-common -r 0cb423bd4868928bb06cd93f882bb0913172fd17; compiled by 'lsuresh' on 2013-04-08T15:47Z
STARTUP_MSG:   java = 1.7.0_17
************************************************************/
2013-08-10 14:12:30,732 INFO org.apache.hadoop.yarn.server.resourcemanager.ResourceManager: registered UNIX signal handlers for [TERM, HUP, INT]
2013-08-10 14:12:31,478 INFO org.apache.hadoop.yarn.server.resourcemanager.security.ApplicationTokenSecretManager: Rolling master-key for application-tokens
2013-08-10 14:12:31,527 INFO org.apache.hadoop.yarn.server.resourcemanager.security.RMContainerTokenSecretManager: ContainerTokenKeyRollingInterval: 86400000ms and ContainerTokenKeyActivationDelay: 900000ms
2013-08-10 14:12:31,531 INFO org.apache.hadoop.yarn.service.AbstractService: Service:Dispatcher is inited.
2013-08-10 14:12:31,533 INFO org.apache.hadoop.yarn.event.AsyncDispatcher: Registering class org.apache.hadoop.yarn.server.resourcemanager.recovery.RMStateStoreEventType for class org.apache.hadoop.yarn.server.resourcemanager.recovery.RMStateStore$ForwardingEventHandler
2013-08-10 14:12:31,533 INFO org.apache.hadoop.yarn.service.AbstractService: Service:Dispatcher is started.
2013-08-10 14:12:31,542 INFO org.apache.hadoop.yarn.event.AsyncDispatcher: Registering class org.apache.hadoop.yarn.server.resourcemanager.NodesListManagerEventType for class org.apache.hadoop.yarn.server.resourcemanager.NodesListManager
2013-08-10 14:12:31,542 INFO org.apache.hadoop.yarn.server.resourcemanager.ResourceManager: Using Scheduler: org.apache.hadoop.yarn.server.resourcemanager.scheduler.capacity.CapacityScheduler
2013-08-10 14:12:31,793 INFO org.apache.hadoop.yarn.event.AsyncDispatcher: Registering class org.apache.hadoop.yarn.server.resourcemanager.scheduler.event.SchedulerEventType for class org.apache.hadoop.yarn.server.resourcemanager.ResourceManager$SchedulerEventDispatcher
2013-08-10 14:12:31,796 INFO org.apache.hadoop.yarn.event.AsyncDispatcher: Registering class org.apache.hadoop.yarn.server.resourcemanager.rmapp.RMAppEventType for class org.apache.hadoop.yarn.server.resourcemanager.ResourceManager$ApplicationEventDispatcher
2013-08-10 14:12:31,799 INFO org.apache.hadoop.yarn.event.AsyncDispatcher: Registering class org.apache.hadoop.yarn.server.resourcemanager.rmapp.attempt.RMAppAttemptEventType for class org.apache.hadoop.yarn.server.resourcemanager.ResourceManager$ApplicationAttemptEventDispatcher
2013-08-10 14:12:31,801 INFO org.apache.hadoop.yarn.event.AsyncDispatcher: Registering class org.apache.hadoop.yarn.server.resourcemanager.rmnode.RMNodeEventType for class org.apache.hadoop.yarn.server.resourcemanager.ResourceManager$NodeEventDispatcher
2013-08-10 14:12:32,373 WARN org.apache.hadoop.util.NativeCodeLoader: Unable to load native-hadoop library for your platform... using builtin-java classes where applicable
2013-08-10 14:12:32,394 INFO org.apache.hadoop.yarn.server.resourcemanager.scheduler.capacity.ParentQueue: root, capacity=1.0, asboluteCapacity=1.0, maxCapacity=1.0, asboluteMaxCapacity=1.0, state=RUNNING, acls=SUBMIT_APPLICATIONS:*ADMINISTER_QUEUE:*
2013-08-10 14:12:32,395 INFO org.apache.hadoop.yarn.server.resourcemanager.scheduler.capacity.ParentQueue: Initialized parent-queue root name=root, fullname=root
2013-08-10 14:12:32,409 INFO org.apache.hadoop.yarn.server.resourcemanager.scheduler.capacity.LeafQueue: Initializing default
capacity = 1.0 [= (float) configuredCapacity / 100 ]
asboluteCapacity = 1.0 [= parentAbsoluteCapacity * capacity ]
maxCapacity = 1.0 [= configuredMaxCapacity ]
absoluteMaxCapacity = 1.0 [= 1.0 maximumCapacity undefined, (parentAbsoluteMaxCapacity * maximumCapacity) / 100 otherwise ]
userLimit = 100 [= configuredUserLimit ]
userLimitFactor = 1.0 [= configuredUserLimitFactor ]
maxApplications = 10000 [= configuredMaximumSystemApplicationsPerQueue or (int)(configuredMaximumSystemApplications * absoluteCapacity)]
maxApplicationsPerUser = 10000 [= (int)(maxApplications * (userLimit / 100.0f) * userLimitFactor) ]
maxActiveApplications = 1 [= max((int)ceil((clusterResourceMemory / minimumAllocation) * maxAMResourcePerQueuePercent * absoluteMaxCapacity),1) ]
maxActiveAppsUsingAbsCap = 1 [= max((int)ceil((clusterResourceMemory / minimumAllocation) *maxAMResourcePercent * absoluteCapacity),1) ]
maxActiveApplicationsPerUser = 1 [= max((int)(maxActiveApplications * (userLimit / 100.0f) * userLimitFactor),1) ]
usedCapacity = 0.0 [= usedResourcesMemory / (clusterResourceMemory * absoluteCapacity)]
absoluteUsedCapacity = 0.0 [= usedResourcesMemory / clusterResourceMemory]
maxAMResourcePerQueuePercent = 0.1 [= configuredMaximumAMResourcePercent ]
minimumAllocationFactor = 0.875 [= (float)(maximumAllocationMemory - minimumAllocationMemory) / maximumAllocationMemory ]
numContainers = 0 [= currentNumContainers ]
state = RUNNING [= configuredState ]
acls = SUBMIT_APPLICATIONS:*ADMINISTER_QUEUE:* [= configuredAcls ]

2013-08-10 14:12:32,410 INFO org.apache.hadoop.yarn.server.resourcemanager.scheduler.capacity.CapacityScheduler: Initialized queue: default: capacity=1.0, absoluteCapacity=1.0, usedResources=<memory:0, vCores:0>usedCapacity=0.0, absoluteUsedCapacity=0.0, numApps=0, numContainers=0
2013-08-10 14:12:32,410 INFO org.apache.hadoop.yarn.server.resourcemanager.scheduler.capacity.CapacityScheduler: Initialized queue: root: numChildQueue= 1, capacity=1.0, absoluteCapacity=1.0, usedResources=<memory:0, vCores:0>usedCapacity=0.0, numApps=0, numContainers=0
2013-08-10 14:12:32,410 INFO org.apache.hadoop.yarn.server.resourcemanager.scheduler.capacity.CapacityScheduler: Initialized root queue root: numChildQueue= 1, capacity=1.0, absoluteCapacity=1.0, usedResources=<memory:0, vCores:0>usedCapacity=0.0, numApps=0, numContainers=0
2013-08-10 14:12:32,410 INFO org.apache.hadoop.yarn.server.resourcemanager.scheduler.capacity.CapacityScheduler: Initialized CapacityScheduler with calculator=class org.apache.hadoop.yarn.server.resourcemanager.resource.DefaultResourceCalculator, minimumAllocation=<<memory:1024, vCores:1>>, maximumAllocation=<<memory:8192, vCores:32>>
2013-08-10 14:12:32,659 INFO org.apache.hadoop.yarn.event.AsyncDispatcher: Registering class org.apache.hadoop.yarn.server.resourcemanager.RMAppManagerEventType for class org.apache.hadoop.yarn.server.resourcemanager.RMAppManager
2013-08-10 14:12:32,673 INFO org.apache.hadoop.yarn.event.AsyncDispatcher: Registering class org.apache.hadoop.yarn.server.resourcemanager.amlauncher.AMLauncherEventType for class org.apache.hadoop.yarn.server.resourcemanager.amlauncher.ApplicationMasterLauncher
2013-08-10 14:12:32,736 INFO org.apache.hadoop.yarn.server.resourcemanager.RMNMInfo: Registered RMNMInfo MBean
2013-08-10 14:12:32,736 INFO org.apache.hadoop.yarn.service.AbstractService: Service:Dispatcher is inited.
2013-08-10 14:12:32,736 INFO org.apache.hadoop.yarn.service.AbstractService: Service:org.apache.hadoop.yarn.server.resourcemanager.rmcontainer.ContainerAllocationExpirer is inited.
2013-08-10 14:12:32,736 INFO org.apache.hadoop.yarn.service.AbstractService: Service:AMLivelinessMonitor is inited.
2013-08-10 14:12:32,736 INFO org.apache.hadoop.yarn.service.AbstractService: Service:AMLivelinessMonitor is inited.
2013-08-10 14:12:32,736 INFO org.apache.hadoop.yarn.service.AbstractService: Service:org.apache.hadoop.yarn.server.resourcemanager.security.DelegationTokenRenewer is inited.
2013-08-10 14:12:32,738 INFO org.apache.hadoop.util.HostsFileReader: Refreshing hosts (include/exclude) list
2013-08-10 14:12:32,738 INFO org.apache.hadoop.yarn.service.AbstractService: Service:org.apache.hadoop.yarn.server.resourcemanager.NodesListManager is inited.
2013-08-10 14:12:32,738 INFO org.apache.hadoop.yarn.service.AbstractService: Service:org.apache.hadoop.yarn.server.resourcemanager.ResourceManager$SchedulerEventDispatcher is inited.
2013-08-10 14:12:32,738 INFO org.apache.hadoop.yarn.service.AbstractService: Service:NMLivelinessMonitor is inited.
2013-08-10 14:12:32,743 INFO org.apache.hadoop.yarn.service.AbstractService: Service:org.apache.hadoop.yarn.server.resourcemanager.ResourceTrackerService is inited.
2013-08-10 14:12:32,743 INFO org.apache.hadoop.yarn.service.AbstractService: Service:org.apache.hadoop.yarn.server.resourcemanager.ApplicationMasterService is inited.
2013-08-10 14:12:32,743 INFO org.apache.hadoop.yarn.service.AbstractService: Service:org.apache.hadoop.yarn.server.resourcemanager.ClientRMService is inited.
2013-08-10 14:12:32,743 INFO org.apache.hadoop.yarn.service.AbstractService: Service:org.apache.hadoop.yarn.server.resourcemanager.AdminService is inited.
2013-08-10 14:12:32,743 INFO org.apache.hadoop.yarn.service.AbstractService: Service:org.apache.hadoop.yarn.server.resourcemanager.amlauncher.ApplicationMasterLauncher is inited.
2013-08-10 14:12:32,743 INFO org.apache.hadoop.yarn.service.AbstractService: Service:ResourceManager is inited.
2013-08-10 14:12:32,744 INFO org.apache.hadoop.yarn.server.resourcemanager.security.RMContainerTokenSecretManager: Rolling master-key for container-tokens
2013-08-10 14:12:32,744 INFO org.apache.hadoop.yarn.server.resourcemanager.security.ApplicationTokenSecretManager: Rolling master-key for application-tokens
2013-08-10 14:12:32,844 INFO org.mortbay.log: Logging to org.slf4j.impl.Log4jLoggerAdapter(org.mortbay.log) via org.mortbay.log.Slf4jLog
2013-08-10 14:12:32,905 INFO org.apache.hadoop.http.HttpServer: Added global filter 'safety' (class=org.apache.hadoop.http.HttpServer$QuotingInputFilter)
2013-08-10 14:12:32,908 INFO org.apache.hadoop.http.HttpServer: Added filter static_user_filter (class=org.apache.hadoop.http.lib.StaticUserWebFilter$StaticUserFilter) to context cluster
2013-08-10 14:12:32,908 INFO org.apache.hadoop.http.HttpServer: Added filter static_user_filter (class=org.apache.hadoop.http.lib.StaticUserWebFilter$StaticUserFilter) to context static
2013-08-10 14:12:32,908 INFO org.apache.hadoop.http.HttpServer: Added filter static_user_filter (class=org.apache.hadoop.http.lib.StaticUserWebFilter$StaticUserFilter) to context logs
2013-08-10 14:12:32,913 INFO org.apache.hadoop.http.HttpServer: adding path spec: /cluster
2013-08-10 14:12:32,913 INFO org.apache.hadoop.http.HttpServer: adding path spec: /cluster/*
2013-08-10 14:12:32,913 INFO org.apache.hadoop.http.HttpServer: adding path spec: /ws
2013-08-10 14:12:32,913 INFO org.apache.hadoop.http.HttpServer: adding path spec: /ws/*
2013-08-10 14:12:32,915 INFO org.apache.hadoop.http.HttpServer: Added global filter 'guice' (class=com.google.inject.servlet.GuiceFilter)
2013-08-10 14:12:32,921 INFO org.apache.hadoop.http.HttpServer: Jetty bound to port 8088
2013-08-10 14:12:32,921 INFO org.mortbay.log: jetty-6.1.26
2013-08-10 14:12:32,953 INFO org.mortbay.log: Extract jar:file:/home/ubuntu/hadoop-3.0.0-SNAPSHOT/share/hadoop/yarn/hadoop-yarn-common-3.0.0-SNAPSHOT.jar!/webapps/cluster to /tmp/Jetty_0_0_0_0_8088_cluster____u0rgz3/webapp
2013-08-10 14:12:33,229 INFO org.mortbay.log: Started SelectChannelConnector@0.0.0.0:8088
2013-08-10 14:12:33,229 INFO org.apache.hadoop.yarn.webapp.WebApps: Web app /cluster started at 8088
2013-08-10 14:12:33,829 INFO org.apache.hadoop.yarn.webapp.WebApps: Registered webapp guice modules
2013-08-10 14:12:33,924 INFO org.apache.hadoop.metrics2.impl.MetricsConfig: loaded properties from hadoop-metrics2.properties
2013-08-10 14:12:33,954 INFO org.apache.hadoop.metrics2.impl.MetricsSystemImpl: Scheduled snapshot period at 10 second(s).
2013-08-10 14:12:33,954 INFO org.apache.hadoop.metrics2.impl.MetricsSystemImpl: ResourceManager metrics system started
2013-08-10 14:12:33,966 INFO org.apache.hadoop.security.token.delegation.AbstractDelegationTokenSecretManager: Updating the current master key for generating delegation tokens
2013-08-10 14:12:33,969 INFO org.apache.hadoop.yarn.service.AbstractService: Service:Dispatcher is started.
2013-08-10 14:12:33,970 INFO org.apache.hadoop.security.token.delegation.AbstractDelegationTokenSecretManager: Starting expired delegation token remover thread, tokenRemoverScanInterval=60 min(s)
2013-08-10 14:12:33,970 INFO org.apache.hadoop.security.token.delegation.AbstractDelegationTokenSecretManager: Updating the current master key for generating delegation tokens
2013-08-10 14:12:33,972 INFO org.apache.hadoop.yarn.service.AbstractService: Service:org.apache.hadoop.yarn.server.resourcemanager.rmcontainer.ContainerAllocationExpirer is started.
2013-08-10 14:12:33,972 INFO org.apache.hadoop.yarn.service.AbstractService: Service:AMLivelinessMonitor is started.
2013-08-10 14:12:33,973 INFO org.apache.hadoop.yarn.service.AbstractService: Service:AMLivelinessMonitor is started.
2013-08-10 14:12:33,973 INFO org.apache.hadoop.yarn.service.AbstractService: Service:org.apache.hadoop.yarn.server.resourcemanager.security.DelegationTokenRenewer is started.
2013-08-10 14:12:33,973 INFO org.apache.hadoop.yarn.service.AbstractService: Service:org.apache.hadoop.yarn.server.resourcemanager.NodesListManager is started.
2013-08-10 14:12:33,974 INFO org.apache.hadoop.yarn.service.AbstractService: Service:org.apache.hadoop.yarn.server.resourcemanager.ResourceManager$SchedulerEventDispatcher is started.
2013-08-10 14:12:33,974 INFO org.apache.hadoop.yarn.service.AbstractService: Service:NMLivelinessMonitor is started.
2013-08-10 14:12:33,975 INFO org.apache.hadoop.yarn.service.AbstractService: Service:org.apache.hadoop.yarn.server.resourcemanager.ResourceTrackerService is started.
2013-08-10 14:12:34,044 INFO org.apache.hadoop.ipc.Server: Starting Socket Reader #1 for port 54110
2013-08-10 14:12:34,077 INFO org.apache.hadoop.yarn.factories.impl.pb.RpcServerFactoryPBImpl: Adding protocol org.apache.hadoop.yarn.server.api.ResourceTrackerPB to the server
2013-08-10 14:12:34,078 INFO org.apache.hadoop.ipc.Server: IPC Server Responder: starting
2013-08-10 14:12:34,078 INFO org.apache.hadoop.ipc.Server: IPC Server listener on 54110: starting
2013-08-10 14:12:34,145 INFO org.apache.hadoop.ipc.Server: Starting Socket Reader #1 for port 54112
2013-08-10 14:12:34,155 INFO org.apache.hadoop.yarn.factories.impl.pb.RpcServerFactoryPBImpl: Adding protocol org.apache.hadoop.yarn.api.AMRMProtocolPB to the server
2013-08-10 14:12:34,157 INFO org.apache.hadoop.ipc.Server: IPC Server Responder: starting
2013-08-10 14:12:34,157 INFO org.apache.hadoop.ipc.Server: IPC Server listener on 54112: starting
2013-08-10 14:12:34,182 INFO org.apache.hadoop.yarn.service.AbstractService: Service:org.apache.hadoop.yarn.server.resourcemanager.ApplicationMasterService is started.
2013-08-10 14:12:34,226 INFO org.apache.hadoop.ipc.Server: Starting Socket Reader #1 for port 54111
2013-08-10 14:12:34,231 INFO org.apache.hadoop.yarn.factories.impl.pb.RpcServerFactoryPBImpl: Adding protocol org.apache.hadoop.yarn.api.ClientRMProtocolPB to the server
2013-08-10 14:12:34,232 INFO org.apache.hadoop.ipc.Server: IPC Server Responder: starting
2013-08-10 14:12:34,233 INFO org.apache.hadoop.ipc.Server: IPC Server listener on 54111: starting
2013-08-10 14:12:34,266 INFO org.apache.hadoop.yarn.service.AbstractService: Service:org.apache.hadoop.yarn.server.resourcemanager.ClientRMService is started.
2013-08-10 14:12:34,299 INFO org.apache.hadoop.ipc.Server: Starting Socket Reader #1 for port 8033
2013-08-10 14:12:34,304 INFO org.apache.hadoop.yarn.factories.impl.pb.RpcServerFactoryPBImpl: Adding protocol org.apache.hadoop.yarn.api.RMAdminProtocolPB to the server
2013-08-10 14:12:34,305 INFO org.apache.hadoop.ipc.Server: IPC Server Responder: starting
2013-08-10 14:12:34,306 INFO org.apache.hadoop.ipc.Server: IPC Server listener on 8033: starting
2013-08-10 14:12:34,306 INFO org.apache.hadoop.yarn.service.AbstractService: Service:org.apache.hadoop.yarn.server.resourcemanager.AdminService is started.
2013-08-10 14:12:34,307 INFO org.apache.hadoop.yarn.service.AbstractService: Service:org.apache.hadoop.yarn.server.resourcemanager.amlauncher.ApplicationMasterLauncher is started.
2013-08-10 14:12:34,308 INFO org.apache.hadoop.yarn.service.AbstractService: Service:ResourceManager is started.
2013-08-10 14:12:45,034 INFO org.apache.hadoop.yarn.util.RackResolver: Resolved hadoop-221-6 to /default-rack
2013-08-10 14:12:45,037 INFO org.apache.hadoop.yarn.util.RackResolver: Resolved hadoop-221-2 to /default-rack
2013-08-10 14:12:45,037 INFO org.apache.hadoop.yarn.util.RackResolver: Resolved hadoop-221-5 to /default-rack
2013-08-10 14:12:45,039 INFO org.apache.hadoop.yarn.util.RackResolver: Resolved hadoop-221-4 to /default-rack
2013-08-10 14:12:45,044 INFO org.apache.hadoop.yarn.server.resourcemanager.ResourceTrackerService: NodeManager from node hadoop-221-2(cmPort: 53277 httpPort: 8042) registered with capability: <memory:8192, vCores:16>, assigned nodeId hadoop-221-2:53277
2013-08-10 14:12:45,044 INFO org.apache.hadoop.yarn.server.resourcemanager.ResourceTrackerService: NodeManager from node hadoop-221-4(cmPort: 43548 httpPort: 8042) registered with capability: <memory:8192, vCores:16>, assigned nodeId hadoop-221-4:43548
2013-08-10 14:12:45,044 INFO org.apache.hadoop.yarn.server.resourcemanager.ResourceTrackerService: NodeManager from node hadoop-221-6(cmPort: 51695 httpPort: 8042) registered with capability: <memory:8192, vCores:16>, assigned nodeId hadoop-221-6:51695
2013-08-10 14:12:45,045 INFO org.apache.hadoop.yarn.server.resourcemanager.ResourceTrackerService: NodeManager from node hadoop-221-5(cmPort: 53998 httpPort: 8042) registered with capability: <memory:8192, vCores:16>, assigned nodeId hadoop-221-5:53998
2013-08-10 14:12:45,058 INFO org.apache.hadoop.yarn.server.resourcemanager.rmnode.RMNodeImpl: hadoop-221-5:53998 Node Transitioned from NEW to RUNNING
2013-08-10 14:12:45,060 INFO org.apache.hadoop.yarn.server.resourcemanager.rmnode.RMNodeImpl: hadoop-221-2:53277 Node Transitioned from NEW to RUNNING
2013-08-10 14:12:45,060 INFO org.apache.hadoop.yarn.server.resourcemanager.rmnode.RMNodeImpl: hadoop-221-6:51695 Node Transitioned from NEW to RUNNING
2013-08-10 14:12:45,061 INFO org.apache.hadoop.yarn.server.resourcemanager.rmnode.RMNodeImpl: hadoop-221-4:43548 Node Transitioned from NEW to RUNNING
2013-08-10 14:12:45,063 INFO org.apache.hadoop.yarn.server.resourcemanager.scheduler.capacity.CapacityScheduler: Added node hadoop-221-5:53998 clusterResource: <memory:8192, vCores:16>
2013-08-10 14:12:45,063 INFO org.apache.hadoop.yarn.server.resourcemanager.scheduler.capacity.CapacityScheduler: Added node hadoop-221-2:53277 clusterResource: <memory:16384, vCores:32>
2013-08-10 14:12:45,064 INFO org.apache.hadoop.yarn.server.resourcemanager.scheduler.capacity.CapacityScheduler: Added node hadoop-221-6:51695 clusterResource: <memory:24576, vCores:48>
2013-08-10 14:12:45,064 INFO org.apache.hadoop.yarn.server.resourcemanager.scheduler.capacity.CapacityScheduler: Added node hadoop-221-4:43548 clusterResource: <memory:32768, vCores:64>
2013-08-10 14:12:45,095 INFO org.apache.hadoop.yarn.util.RackResolver: Resolved hadoop-221-7 to /default-rack
2013-08-10 14:12:45,095 INFO org.apache.hadoop.yarn.server.resourcemanager.ResourceTrackerService: NodeManager from node hadoop-221-7(cmPort: 43558 httpPort: 8042) registered with capability: <memory:8192, vCores:16>, assigned nodeId hadoop-221-7:43558
2013-08-10 14:12:45,096 INFO org.apache.hadoop.yarn.server.resourcemanager.rmnode.RMNodeImpl: hadoop-221-7:43558 Node Transitioned from NEW to RUNNING
2013-08-10 14:12:45,096 INFO org.apache.hadoop.yarn.server.resourcemanager.scheduler.capacity.CapacityScheduler: Added node hadoop-221-7:43558 clusterResource: <memory:40960, vCores:80>
2013-08-10 14:12:45,226 INFO org.apache.hadoop.yarn.util.RackResolver: Resolved hadoop-221-3 to /default-rack
2013-08-10 14:12:45,226 INFO org.apache.hadoop.yarn.server.resourcemanager.ResourceTrackerService: NodeManager from node hadoop-221-3(cmPort: 48808 httpPort: 8042) registered with capability: <memory:8192, vCores:16>, assigned nodeId hadoop-221-3:48808
2013-08-10 14:12:45,226 INFO org.apache.hadoop.yarn.server.resourcemanager.rmnode.RMNodeImpl: hadoop-221-3:48808 Node Transitioned from NEW to RUNNING
2013-08-10 14:12:45,227 INFO org.apache.hadoop.yarn.server.resourcemanager.scheduler.capacity.CapacityScheduler: Added node hadoop-221-3:48808 clusterResource: <memory:49152, vCores:96>
2013-08-10 14:12:51,611 INFO org.apache.hadoop.yarn.server.resourcemanager.ClientRMService: Allocated new applicationId: 1
2013-08-10 14:12:54,944 INFO org.apache.hadoop.yarn.server.resourcemanager.ClientRMService: Storing Application with id application_1376143950665_0001
2013-08-10 14:12:54,948 INFO org.apache.hadoop.yarn.server.resourcemanager.recovery.RMStateStore: Storing info for app: application_1376143950665_0001
2013-08-10 14:12:54,948 INFO org.apache.hadoop.yarn.server.resourcemanager.ClientRMService: Application with id 1 submitted by user ubuntu
2013-08-10 14:12:54,952 INFO org.apache.hadoop.yarn.server.resourcemanager.RMAuditLogger: USER=ubuntu	IP=192.168.100.14	OPERATION=Submit Application Request	TARGET=ClientRMService	RESULT=SUCCESS	APPID=application_1376143950665_0001
2013-08-10 14:12:54,994 INFO org.apache.hadoop.yarn.server.resourcemanager.rmapp.RMAppImpl: application_1376143950665_0001 State change from NEW to SUBMITTED
2013-08-10 14:12:54,998 INFO org.apache.hadoop.yarn.server.resourcemanager.ApplicationMasterService: Registering appattempt_1376143950665_0001_000001
2013-08-10 14:12:55,002 INFO org.apache.hadoop.yarn.server.resourcemanager.rmapp.attempt.RMAppAttemptImpl: appattempt_1376143950665_0001_000001 State change from NEW to SUBMITTED
2013-08-10 14:12:55,039 INFO org.apache.hadoop.yarn.server.resourcemanager.scheduler.capacity.LeafQueue: Application application_1376143950665_0001 from user: ubuntu activated in queue: default
2013-08-10 14:12:55,039 INFO org.apache.hadoop.yarn.server.resourcemanager.scheduler.capacity.LeafQueue: Application added - appId: application_1376143950665_0001 user: org.apache.hadoop.yarn.server.resourcemanager.scheduler.capacity.LeafQueue$User@e09fad3, leaf-queue: default #user-pending-applications: 0 #user-active-applications: 1 #queue-pending-applications: 0 #queue-active-applications: 1
2013-08-10 14:12:55,039 INFO org.apache.hadoop.yarn.server.resourcemanager.scheduler.capacity.ParentQueue: Application added - appId: application_1376143950665_0001 user: ubuntu leaf-queue of parent: root #applications: 1
2013-08-10 14:12:55,040 INFO org.apache.hadoop.yarn.server.resourcemanager.scheduler.capacity.CapacityScheduler: Application Submission: appattempt_1376143950665_0001_000001, user: ubuntu queue: default: capacity=1.0, absoluteCapacity=1.0, usedResources=<memory:0, vCores:0>usedCapacity=0.0, absoluteUsedCapacity=0.0, numApps=1, numContainers=0, currently active: 1
2013-08-10 14:12:55,046 INFO org.apache.hadoop.yarn.server.resourcemanager.rmapp.attempt.RMAppAttemptImpl: appattempt_1376143950665_0001_000001 State change from SUBMITTED to SCHEDULED
2013-08-10 14:12:55,047 INFO org.apache.hadoop.yarn.server.resourcemanager.rmapp.RMAppImpl: application_1376143950665_0001 State change from SUBMITTED to ACCEPTED
2013-08-10 14:12:55,221 INFO org.apache.hadoop.yarn.server.resourcemanager.rmcontainer.RMContainerImpl: container_1376143950665_0001_01_000001 Container Transitioned from NEW to ALLOCATED
2013-08-10 14:12:55,222 INFO org.apache.hadoop.yarn.server.resourcemanager.RMAuditLogger: USER=ubuntu	OPERATION=AM Allocated Container	TARGET=SchedulerApp	RESULT=SUCCESS	APPID=application_1376143950665_0001	CONTAINERID=container_1376143950665_0001_01_000001
2013-08-10 14:12:55,223 INFO org.apache.hadoop.yarn.server.resourcemanager.scheduler.common.fica.FiCaSchedulerNode: Assigned container container_1376143950665_0001_01_000001 of capacity <memory:2048, vCores:1> on host hadoop-221-6:51695, which currently has 1 containers, <memory:2048, vCores:1> used and <memory:6144, vCores:15> available
2013-08-10 14:12:55,230 INFO org.apache.hadoop.yarn.server.resourcemanager.scheduler.capacity.LeafQueue: assignedContainer application=application_1376143950665_0001 container=Container: [ContainerId: container_1376143950665_0001_01_000001, NodeId: hadoop-221-6:51695, NodeHttpAddress: hadoop-221-6:8042, Resource: <memory:2048, vCores:1>, Priority: 0, State: NEW, Token: null, Status: container_id {, app_attempt_id {, application_id {, id: 1, cluster_timestamp: 1376143950665, }, attemptId: 1, }, id: 1, }, state: C_NEW, ] containerId=container_1376143950665_0001_01_000001 queue=default: capacity=1.0, absoluteCapacity=1.0, usedResources=<memory:0, vCores:0>usedCapacity=0.0, absoluteUsedCapacity=0.0, numApps=1, numContainers=0 usedCapacity=0.0 absoluteUsedCapacity=0.0 used=<memory:0, vCores:0> cluster=<memory:49152, vCores:96>
2013-08-10 14:12:55,230 INFO org.apache.hadoop.yarn.server.resourcemanager.scheduler.capacity.ParentQueue: Re-sorting queues since queue: root.default stats: default: capacity=1.0, absoluteCapacity=1.0, usedResources=<memory:2048, vCores:1>usedCapacity=0.041666668, absoluteUsedCapacity=0.041666668, numApps=1, numContainers=1
2013-08-10 14:12:55,231 INFO org.apache.hadoop.yarn.server.resourcemanager.scheduler.capacity.ParentQueue: assignedContainer queue=root usedCapacity=0.041666668 absoluteUsedCapacity=0.041666668 used=<memory:2048, vCores:1> cluster=<memory:49152, vCores:96>
2013-08-10 14:12:55,238 INFO org.apache.hadoop.yarn.server.resourcemanager.rmcontainer.RMContainerImpl: container_1376143950665_0001_01_000001 Container Transitioned from ALLOCATED to ACQUIRED
2013-08-10 14:12:55,242 INFO org.apache.hadoop.yarn.server.resourcemanager.rmapp.attempt.RMAppAttemptImpl: Storing attempt: AppId: application_1376143950665_0001 AttemptId: appattempt_1376143950665_0001_000001 MasterContainer: Container: [ContainerId: container_1376143950665_0001_01_000001, NodeId: hadoop-221-6:51695, NodeHttpAddress: hadoop-221-6:8042, Resource: <memory:2048, vCores:1>, Priority: 0, State: NEW, Token: null, Status: container_id {, app_attempt_id {, application_id {, id: 1, cluster_timestamp: 1376143950665, }, attemptId: 1, }, id: 1, }, state: C_NEW, ]
2013-08-10 14:12:55,245 INFO org.apache.hadoop.yarn.server.resourcemanager.rmapp.attempt.RMAppAttemptImpl: appattempt_1376143950665_0001_000001 State change from SCHEDULED to ALLOCATED_SAVING
2013-08-10 14:12:55,249 INFO org.apache.hadoop.yarn.server.resourcemanager.recovery.RMStateStore: Storing info for attempt: appattempt_1376143950665_0001_000001
2013-08-10 14:12:55,253 INFO org.apache.hadoop.yarn.server.resourcemanager.rmapp.attempt.RMAppAttemptImpl: appattempt_1376143950665_0001_000001 State change from ALLOCATED_SAVING to ALLOCATED
2013-08-10 14:12:55,260 INFO org.apache.hadoop.yarn.server.resourcemanager.amlauncher.AMLauncher: Launching masterappattempt_1376143950665_0001_000001
2013-08-10 14:12:55,301 INFO org.apache.hadoop.yarn.server.resourcemanager.amlauncher.AMLauncher: Setting up container Container: [ContainerId: container_1376143950665_0001_01_000001, NodeId: hadoop-221-6:51695, NodeHttpAddress: hadoop-221-6:8042, Resource: <memory:2048, vCores:1>, Priority: 0, State: NEW, Token: null, Status: container_id {, app_attempt_id {, application_id {, id: 1, cluster_timestamp: 1376143950665, }, attemptId: 1, }, id: 1, }, state: C_NEW, ] for AM appattempt_1376143950665_0001_000001
2013-08-10 14:12:55,301 INFO org.apache.hadoop.yarn.server.resourcemanager.amlauncher.AMLauncher: Command to launch container container_1376143950665_0001_01_000001 : $JAVA_HOME/bin/java -Dlog4j.configuration=container-log4j.properties -Dyarn.app.mapreduce.container.log.dir=<LOG_DIR> -Dyarn.app.mapreduce.container.log.filesize=0 -Dhadoop.root.logger=INFO,CLA  -Xmx1024m org.apache.hadoop.mapreduce.v2.app.MRAppMaster 1><LOG_DIR>/stdout 2><LOG_DIR>/stderr 
2013-08-10 14:12:56,225 INFO org.apache.hadoop.yarn.server.resourcemanager.amlauncher.AMLauncher: Done launching container Container: [ContainerId: container_1376143950665_0001_01_000001, NodeId: hadoop-221-6:51695, NodeHttpAddress: hadoop-221-6:8042, Resource: <memory:2048, vCores:1>, Priority: 0, State: NEW, Token: null, Status: container_id {, app_attempt_id {, application_id {, id: 1, cluster_timestamp: 1376143950665, }, attemptId: 1, }, id: 1, }, state: C_NEW, ] for AM appattempt_1376143950665_0001_000001
2013-08-10 14:12:56,226 INFO org.apache.hadoop.yarn.server.resourcemanager.rmapp.attempt.RMAppAttemptImpl: appattempt_1376143950665_0001_000001 State change from ALLOCATED to LAUNCHED
2013-08-10 14:12:56,229 INFO org.apache.hadoop.yarn.server.resourcemanager.rmcontainer.RMContainerImpl: container_1376143950665_0001_01_000001 Container Transitioned from ACQUIRED to RUNNING
2013-08-10 14:13:05,118 INFO org.apache.hadoop.yarn.server.resourcemanager.ApplicationMasterService: AM registration appattempt_1376143950665_0001_000001
2013-08-10 14:13:05,120 INFO org.apache.hadoop.yarn.server.resourcemanager.RMAuditLogger: USER=ubuntu	IP=192.168.100.39	OPERATION=Register App Master	TARGET=ApplicationMasterService	RESULT=SUCCESS	APPID=application_1376143950665_0001	APPATTEMPTID=appattempt_1376143950665_0001_000001
2013-08-10 14:13:05,125 INFO org.apache.hadoop.yarn.server.resourcemanager.rmapp.attempt.RMAppAttemptImpl: appattempt_1376143950665_0001_000001 State change from LAUNCHED to RUNNING
2013-08-10 14:13:05,125 INFO org.apache.hadoop.yarn.server.resourcemanager.rmapp.RMAppImpl: application_1376143950665_0001 State change from ACCEPTED to RUNNING
2013-08-10 14:13:06,245 INFO org.apache.hadoop.yarn.server.resourcemanager.rmcontainer.RMContainerImpl: container_1376143950665_0001_01_000002 Container Transitioned from NEW to ALLOCATED
2013-08-10 14:13:06,245 INFO org.apache.hadoop.yarn.server.resourcemanager.RMAuditLogger: USER=ubuntu	OPERATION=AM Allocated Container	TARGET=SchedulerApp	RESULT=SUCCESS	APPID=application_1376143950665_0001	CONTAINERID=container_1376143950665_0001_01_000002
2013-08-10 14:13:06,246 INFO org.apache.hadoop.yarn.server.resourcemanager.scheduler.common.fica.FiCaSchedulerNode: Assigned container container_1376143950665_0001_01_000002 of capacity <memory:1024, vCores:1> on host hadoop-221-4:43548, which currently has 1 containers, <memory:1024, vCores:1> used and <memory:7168, vCores:15> available
2013-08-10 14:13:06,247 INFO org.apache.hadoop.yarn.server.resourcemanager.scheduler.capacity.LeafQueue: assignedContainer application=application_1376143950665_0001 container=Container: [ContainerId: container_1376143950665_0001_01_000002, NodeId: hadoop-221-4:43548, NodeHttpAddress: hadoop-221-4:8042, Resource: <memory:1024, vCores:1>, Priority: 20, State: NEW, Token: null, Status: container_id {, app_attempt_id {, application_id {, id: 1, cluster_timestamp: 1376143950665, }, attemptId: 1, }, id: 2, }, state: C_NEW, ] containerId=container_1376143950665_0001_01_000002 queue=default: capacity=1.0, absoluteCapacity=1.0, usedResources=<memory:2048, vCores:1>usedCapacity=0.041666668, absoluteUsedCapacity=0.041666668, numApps=1, numContainers=1 usedCapacity=0.041666668 absoluteUsedCapacity=0.041666668 used=<memory:2048, vCores:1> cluster=<memory:49152, vCores:96>
2013-08-10 14:13:06,248 INFO org.apache.hadoop.yarn.server.resourcemanager.scheduler.capacity.ParentQueue: Re-sorting queues since queue: root.default stats: default: capacity=1.0, absoluteCapacity=1.0, usedResources=<memory:3072, vCores:2>usedCapacity=0.0625, absoluteUsedCapacity=0.0625, numApps=1, numContainers=2
2013-08-10 14:13:06,248 INFO org.apache.hadoop.yarn.server.resourcemanager.scheduler.capacity.ParentQueue: assignedContainer queue=root usedCapacity=0.0625 absoluteUsedCapacity=0.0625 used=<memory:3072, vCores:2> cluster=<memory:49152, vCores:96>
2013-08-10 14:13:06,249 INFO org.apache.hadoop.yarn.server.resourcemanager.rmcontainer.RMContainerImpl: container_1376143950665_0001_01_000003 Container Transitioned from NEW to ALLOCATED
2013-08-10 14:13:06,249 INFO org.apache.hadoop.yarn.server.resourcemanager.RMAuditLogger: USER=ubuntu	OPERATION=AM Allocated Container	TARGET=SchedulerApp	RESULT=SUCCESS	APPID=application_1376143950665_0001	CONTAINERID=container_1376143950665_0001_01_000003
2013-08-10 14:13:06,249 INFO org.apache.hadoop.yarn.server.resourcemanager.scheduler.common.fica.FiCaSchedulerNode: Assigned container container_1376143950665_0001_01_000003 of capacity <memory:1024, vCores:1> on host hadoop-221-5:53998, which currently has 1 containers, <memory:1024, vCores:1> used and <memory:7168, vCores:15> available
2013-08-10 14:13:06,251 INFO org.apache.hadoop.yarn.server.resourcemanager.scheduler.capacity.LeafQueue: assignedContainer application=application_1376143950665_0001 container=Container: [ContainerId: container_1376143950665_0001_01_000003, NodeId: hadoop-221-5:53998, NodeHttpAddress: hadoop-221-5:8042, Resource: <memory:1024, vCores:1>, Priority: 20, State: NEW, Token: null, Status: container_id {, app_attempt_id {, application_id {, id: 1, cluster_timestamp: 1376143950665, }, attemptId: 1, }, id: 3, }, state: C_NEW, ] containerId=container_1376143950665_0001_01_000003 queue=default: capacity=1.0, absoluteCapacity=1.0, usedResources=<memory:3072, vCores:2>usedCapacity=0.0625, absoluteUsedCapacity=0.0625, numApps=1, numContainers=2 usedCapacity=0.0625 absoluteUsedCapacity=0.0625 used=<memory:3072, vCores:2> cluster=<memory:49152, vCores:96>
2013-08-10 14:13:06,251 INFO org.apache.hadoop.yarn.server.resourcemanager.scheduler.capacity.ParentQueue: Re-sorting queues since queue: root.default stats: default: capacity=1.0, absoluteCapacity=1.0, usedResources=<memory:4096, vCores:3>usedCapacity=0.083333336, absoluteUsedCapacity=0.083333336, numApps=1, numContainers=3
2013-08-10 14:13:06,252 INFO org.apache.hadoop.yarn.server.resourcemanager.scheduler.capacity.ParentQueue: assignedContainer queue=root usedCapacity=0.083333336 absoluteUsedCapacity=0.083333336 used=<memory:4096, vCores:3> cluster=<memory:49152, vCores:96>
2013-08-10 14:13:07,191 INFO org.apache.hadoop.yarn.server.resourcemanager.rmcontainer.RMContainerImpl: container_1376143950665_0001_01_000002 Container Transitioned from ALLOCATED to ACQUIRED
2013-08-10 14:13:07,192 INFO org.apache.hadoop.yarn.server.resourcemanager.rmcontainer.RMContainerImpl: container_1376143950665_0001_01_000003 Container Transitioned from ALLOCATED to ACQUIRED
2013-08-10 14:13:08,228 INFO org.apache.hadoop.yarn.server.resourcemanager.scheduler.AppSchedulingInfo: checking for deactivate... 
2013-08-10 14:13:08,280 INFO org.apache.hadoop.yarn.server.resourcemanager.rmcontainer.RMContainerImpl: container_1376143950665_0001_01_000003 Container Transitioned from ACQUIRED to RUNNING
2013-08-10 14:13:08,300 INFO org.apache.hadoop.yarn.server.resourcemanager.rmcontainer.RMContainerImpl: container_1376143950665_0001_01_000002 Container Transitioned from ACQUIRED to RUNNING
2013-08-10 14:15:50,298 INFO org.apache.hadoop.yarn.server.resourcemanager.rmcontainer.RMContainerImpl: container_1376143950665_0001_01_000003 Container Transitioned from RUNNING to COMPLETED
2013-08-10 14:15:50,299 INFO org.apache.hadoop.yarn.server.resourcemanager.scheduler.common.fica.FiCaSchedulerApp: Completed container: container_1376143950665_0001_01_000003 in state: COMPLETED event:FINISHED
2013-08-10 14:15:50,299 INFO org.apache.hadoop.yarn.server.resourcemanager.RMAuditLogger: USER=ubuntu	OPERATION=AM Released Container	TARGET=SchedulerApp	RESULT=SUCCESS	APPID=application_1376143950665_0001	CONTAINERID=container_1376143950665_0001_01_000003
2013-08-10 14:15:50,299 INFO org.apache.hadoop.yarn.server.resourcemanager.scheduler.common.fica.FiCaSchedulerNode: Released container container_1376143950665_0001_01_000003 of capacity <memory:1024, vCores:1> on host hadoop-221-5:53998, which currently has 0 containers, <memory:0, vCores:0> used and <memory:8192, vCores:16> available, release resources=true
2013-08-10 14:15:50,299 INFO org.apache.hadoop.yarn.server.resourcemanager.scheduler.capacity.LeafQueue: default used=<memory:3072, vCores:2> numContainers=2 user=ubuntu user-resources=<memory:3072, vCores:2>
2013-08-10 14:15:50,302 INFO org.apache.hadoop.yarn.server.resourcemanager.scheduler.capacity.LeafQueue: completedContainer container=Container: [ContainerId: container_1376143950665_0001_01_000003, NodeId: hadoop-221-5:53998, NodeHttpAddress: hadoop-221-5:8042, Resource: <memory:1024, vCores:1>, Priority: 20, State: NEW, Token: null, Status: container_id {, app_attempt_id {, application_id {, id: 1, cluster_timestamp: 1376143950665, }, attemptId: 1, }, id: 3, }, state: C_COMPLETE, diagnostics: "Container killed by the ApplicationMaster.\n\n", exit_status: 143, ] resource=<memory:1024, vCores:1> queue=default: capacity=1.0, absoluteCapacity=1.0, usedResources=<memory:3072, vCores:2>usedCapacity=0.0625, absoluteUsedCapacity=0.0625, numApps=1, numContainers=2 usedCapacity=0.0625 absoluteUsedCapacity=0.0625 used=<memory:3072, vCores:2> cluster=<memory:49152, vCores:96>
2013-08-10 14:15:50,302 INFO org.apache.hadoop.yarn.server.resourcemanager.scheduler.capacity.ParentQueue: completedContainer queue=root usedCapacity=0.0625 absoluteUsedCapacity=0.0625 used=<memory:3072, vCores:2> cluster=<memory:49152, vCores:96>
2013-08-10 14:15:50,302 INFO org.apache.hadoop.yarn.server.resourcemanager.scheduler.capacity.CapacityScheduler: Application appattempt_1376143950665_0001_000001 released container container_1376143950665_0001_01_000003 on node: host: hadoop-221-5:53998 #containers=0 available=8192 used=0 with event: FINISHED
2013-08-10 14:16:02,399 INFO org.apache.hadoop.yarn.server.resourcemanager.rmcontainer.RMContainerImpl: container_1376143950665_0001_01_000002 Container Transitioned from RUNNING to COMPLETED
2013-08-10 14:16:02,399 INFO org.apache.hadoop.yarn.server.resourcemanager.scheduler.common.fica.FiCaSchedulerApp: Completed container: container_1376143950665_0001_01_000002 in state: COMPLETED event:FINISHED
2013-08-10 14:16:02,399 INFO org.apache.hadoop.yarn.server.resourcemanager.RMAuditLogger: USER=ubuntu	OPERATION=AM Released Container	TARGET=SchedulerApp	RESULT=SUCCESS	APPID=application_1376143950665_0001	CONTAINERID=container_1376143950665_0001_01_000002
2013-08-10 14:16:02,400 INFO org.apache.hadoop.yarn.server.resourcemanager.scheduler.common.fica.FiCaSchedulerNode: Released container container_1376143950665_0001_01_000002 of capacity <memory:1024, vCores:1> on host hadoop-221-4:43548, which currently has 0 containers, <memory:0, vCores:0> used and <memory:8192, vCores:16> available, release resources=true
2013-08-10 14:16:02,400 INFO org.apache.hadoop.yarn.server.resourcemanager.scheduler.capacity.LeafQueue: default used=<memory:2048, vCores:1> numContainers=1 user=ubuntu user-resources=<memory:2048, vCores:1>
2013-08-10 14:16:02,402 INFO org.apache.hadoop.yarn.server.resourcemanager.scheduler.capacity.LeafQueue: completedContainer container=Container: [ContainerId: container_1376143950665_0001_01_000002, NodeId: hadoop-221-4:43548, NodeHttpAddress: hadoop-221-4:8042, Resource: <memory:1024, vCores:1>, Priority: 20, State: NEW, Token: null, Status: container_id {, app_attempt_id {, application_id {, id: 1, cluster_timestamp: 1376143950665, }, attemptId: 1, }, id: 2, }, state: C_COMPLETE, diagnostics: "Container killed by the ApplicationMaster.\n\n", exit_status: 143, ] resource=<memory:1024, vCores:1> queue=default: capacity=1.0, absoluteCapacity=1.0, usedResources=<memory:2048, vCores:1>usedCapacity=0.041666668, absoluteUsedCapacity=0.041666668, numApps=1, numContainers=1 usedCapacity=0.041666668 absoluteUsedCapacity=0.041666668 used=<memory:2048, vCores:1> cluster=<memory:49152, vCores:96>
2013-08-10 14:16:02,402 INFO org.apache.hadoop.yarn.server.resourcemanager.scheduler.capacity.ParentQueue: completedContainer queue=root usedCapacity=0.041666668 absoluteUsedCapacity=0.041666668 used=<memory:2048, vCores:1> cluster=<memory:49152, vCores:96>
2013-08-10 14:16:02,402 INFO org.apache.hadoop.yarn.server.resourcemanager.scheduler.capacity.CapacityScheduler: Application appattempt_1376143950665_0001_000001 released container container_1376143950665_0001_01_000002 on node: host: hadoop-221-4:43548 #containers=0 available=8192 used=0 with event: FINISHED
2013-08-10 14:16:06,633 INFO org.apache.hadoop.yarn.server.resourcemanager.rmapp.attempt.RMAppAttemptImpl: appattempt_1376143950665_0001_000001 State change from RUNNING to FINISHING
2013-08-10 14:16:06,634 INFO org.apache.hadoop.yarn.server.resourcemanager.rmapp.RMAppImpl: application_1376143950665_0001 State change from RUNNING to FINISHING
2013-08-10 14:16:07,491 INFO org.apache.hadoop.yarn.server.resourcemanager.rmcontainer.RMContainerImpl: container_1376143950665_0001_01_000001 Container Transitioned from RUNNING to COMPLETED
2013-08-10 14:16:07,491 INFO org.apache.hadoop.yarn.server.resourcemanager.scheduler.common.fica.FiCaSchedulerApp: Completed container: container_1376143950665_0001_01_000001 in state: COMPLETED event:FINISHED
2013-08-10 14:16:07,491 INFO org.apache.hadoop.yarn.server.resourcemanager.RMAuditLogger: USER=ubuntu	OPERATION=AM Released Container	TARGET=SchedulerApp	RESULT=SUCCESS	APPID=application_1376143950665_0001	CONTAINERID=container_1376143950665_0001_01_000001
2013-08-10 14:16:07,492 INFO org.apache.hadoop.yarn.server.resourcemanager.scheduler.common.fica.FiCaSchedulerNode: Released container container_1376143950665_0001_01_000001 of capacity <memory:2048, vCores:1> on host hadoop-221-6:51695, which currently has 0 containers, <memory:0, vCores:0> used and <memory:8192, vCores:16> available, release resources=true
2013-08-10 14:16:07,492 INFO org.apache.hadoop.yarn.server.resourcemanager.scheduler.capacity.LeafQueue: default used=<memory:0, vCores:0> numContainers=0 user=ubuntu user-resources=<memory:0, vCores:0>
2013-08-10 14:16:07,493 INFO org.apache.hadoop.yarn.server.resourcemanager.scheduler.capacity.LeafQueue: completedContainer container=Container: [ContainerId: container_1376143950665_0001_01_000001, NodeId: hadoop-221-6:51695, NodeHttpAddress: hadoop-221-6:8042, Resource: <memory:2048, vCores:1>, Priority: 0, State: NEW, Token: null, Status: container_id {, app_attempt_id {, application_id {, id: 1, cluster_timestamp: 1376143950665, }, attemptId: 1, }, id: 1, }, state: C_COMPLETE, diagnostics: "", exit_status: 0, ] resource=<memory:2048, vCores:1> queue=default: capacity=1.0, absoluteCapacity=1.0, usedResources=<memory:0, vCores:0>usedCapacity=0.0, absoluteUsedCapacity=0.0, numApps=1, numContainers=0 usedCapacity=0.0 absoluteUsedCapacity=0.0 used=<memory:0, vCores:0> cluster=<memory:49152, vCores:96>
2013-08-10 14:16:07,493 INFO org.apache.hadoop.yarn.server.resourcemanager.scheduler.capacity.ParentQueue: completedContainer queue=root usedCapacity=0.0 absoluteUsedCapacity=0.0 used=<memory:0, vCores:0> cluster=<memory:49152, vCores:96>
2013-08-10 14:16:07,493 INFO org.apache.hadoop.yarn.server.resourcemanager.scheduler.capacity.CapacityScheduler: Application appattempt_1376143950665_0001_000001 released container container_1376143950665_0001_01_000001 on node: host: hadoop-221-6:51695 #containers=0 available=8192 used=0 with event: FINISHED
2013-08-10 14:16:07,494 INFO org.apache.hadoop.yarn.server.resourcemanager.rmapp.attempt.RMAppAttemptImpl: appattempt_1376143950665_0001_000001 State change from FINISHING to FINISHED
2013-08-10 14:16:07,496 INFO org.apache.hadoop.yarn.server.resourcemanager.rmapp.RMAppImpl: application_1376143950665_0001 State change from FINISHING to FINISHED
2013-08-10 14:16:07,496 INFO org.apache.hadoop.yarn.server.resourcemanager.scheduler.capacity.CapacityScheduler: Application appattempt_1376143950665_0001_000001 is done. finalState=FINISHED
2013-08-10 14:16:07,496 INFO org.apache.hadoop.yarn.server.resourcemanager.RMAuditLogger: USER=ubuntu	OPERATION=Application Finished - Succeeded	TARGET=RMAppManager	RESULT=SUCCESS	APPID=application_1376143950665_0001
2013-08-10 14:16:07,499 INFO org.apache.hadoop.yarn.server.resourcemanager.recovery.RMStateStore: Removing info for app: application_1376143950665_0001
2013-08-10 14:16:07,497 INFO org.apache.hadoop.yarn.server.resourcemanager.scheduler.AppSchedulingInfo: Application application_1376143950665_0001 requests cleared
2013-08-10 14:16:07,501 INFO org.apache.hadoop.yarn.server.resourcemanager.scheduler.capacity.LeafQueue: Application removed - appId: application_1376143950665_0001 user: ubuntu queue: default #user-pending-applications: 0 #user-active-applications: 0 #queue-pending-applications: 0 #queue-active-applications: 0
2013-08-10 14:16:07,501 INFO org.apache.hadoop.yarn.server.resourcemanager.scheduler.capacity.ParentQueue: Application removed - appId: application_1376143950665_0001 user: ubuntu leaf-queue of parent: root #applications: 0
2013-08-10 14:16:07,504 INFO org.apache.hadoop.yarn.server.resourcemanager.RMAppManager$ApplicationSummary: appId=application_1376143950665_0001,name=TeraGen,user=ubuntu,queue=default,state=FINISHED,trackingUrl=hadoop-221-1.novalocal:8088/proxy/application_1376143950665_0001/jobhistory/job/job_1376143950665_0001,appMasterHost=hadoop-221-6,startTime=1376143974937,finishTime=1376144166634
2013-08-10 14:16:07,501 INFO org.apache.hadoop.yarn.server.resourcemanager.amlauncher.AMLauncher: Cleaning master appattempt_1376143950665_0001_000001
2013-08-10 14:16:08,601 INFO org.apache.hadoop.yarn.server.resourcemanager.ClientRMService: Allocated new applicationId: 2
2013-08-10 14:16:10,485 INFO org.apache.hadoop.yarn.server.resourcemanager.ClientRMService: Storing Application with id application_1376143950665_0002
2013-08-10 14:16:10,485 INFO org.apache.hadoop.yarn.server.resourcemanager.recovery.RMStateStore: Storing info for app: application_1376143950665_0002
2013-08-10 14:16:10,485 INFO org.apache.hadoop.yarn.server.resourcemanager.ClientRMService: Application with id 2 submitted by user ubuntu
2013-08-10 14:16:10,485 INFO org.apache.hadoop.yarn.server.resourcemanager.RMAuditLogger: USER=ubuntu	IP=192.168.100.14	OPERATION=Submit Application Request	TARGET=ClientRMService	RESULT=SUCCESS	APPID=application_1376143950665_0002
2013-08-10 14:16:10,488 INFO org.apache.hadoop.yarn.server.resourcemanager.rmapp.RMAppImpl: application_1376143950665_0002 State change from NEW to SUBMITTED
2013-08-10 14:16:10,488 INFO org.apache.hadoop.yarn.server.resourcemanager.ApplicationMasterService: Registering appattempt_1376143950665_0002_000001
2013-08-10 14:16:10,488 INFO org.apache.hadoop.yarn.server.resourcemanager.rmapp.attempt.RMAppAttemptImpl: appattempt_1376143950665_0002_000001 State change from NEW to SUBMITTED
2013-08-10 14:16:10,489 INFO org.apache.hadoop.yarn.server.resourcemanager.scheduler.capacity.LeafQueue: Application application_1376143950665_0002 from user: ubuntu activated in queue: default
2013-08-10 14:16:10,489 INFO org.apache.hadoop.yarn.server.resourcemanager.scheduler.capacity.LeafQueue: Application added - appId: application_1376143950665_0002 user: org.apache.hadoop.yarn.server.resourcemanager.scheduler.capacity.LeafQueue$User@74bc72e0, leaf-queue: default #user-pending-applications: 0 #user-active-applications: 1 #queue-pending-applications: 0 #queue-active-applications: 1
2013-08-10 14:16:10,489 INFO org.apache.hadoop.yarn.server.resourcemanager.scheduler.capacity.ParentQueue: Application added - appId: application_1376143950665_0002 user: ubuntu leaf-queue of parent: root #applications: 1
2013-08-10 14:16:10,490 INFO org.apache.hadoop.yarn.server.resourcemanager.scheduler.capacity.CapacityScheduler: Application Submission: appattempt_1376143950665_0002_000001, user: ubuntu queue: default: capacity=1.0, absoluteCapacity=1.0, usedResources=<memory:0, vCores:0>usedCapacity=0.0, absoluteUsedCapacity=0.0, numApps=1, numContainers=0, currently active: 1
2013-08-10 14:16:10,490 INFO org.apache.hadoop.yarn.server.resourcemanager.rmapp.attempt.RMAppAttemptImpl: appattempt_1376143950665_0002_000001 State change from SUBMITTED to SCHEDULED
2013-08-10 14:16:10,490 INFO org.apache.hadoop.yarn.server.resourcemanager.rmapp.RMAppImpl: application_1376143950665_0002 State change from SUBMITTED to ACCEPTED
2013-08-10 14:16:10,505 INFO org.apache.hadoop.yarn.server.resourcemanager.rmcontainer.RMContainerImpl: container_1376143950665_0002_01_000001 Container Transitioned from NEW to ALLOCATED
2013-08-10 14:16:10,505 INFO org.apache.hadoop.yarn.server.resourcemanager.RMAuditLogger: USER=ubuntu	OPERATION=AM Allocated Container	TARGET=SchedulerApp	RESULT=SUCCESS	APPID=application_1376143950665_0002	CONTAINERID=container_1376143950665_0002_01_000001
2013-08-10 14:16:10,506 INFO org.apache.hadoop.yarn.server.resourcemanager.scheduler.common.fica.FiCaSchedulerNode: Assigned container container_1376143950665_0002_01_000001 of capacity <memory:2048, vCores:1> on host hadoop-221-6:51695, which currently has 1 containers, <memory:2048, vCores:1> used and <memory:6144, vCores:15> available
2013-08-10 14:16:10,507 INFO org.apache.hadoop.yarn.server.resourcemanager.scheduler.capacity.LeafQueue: assignedContainer application=application_1376143950665_0002 container=Container: [ContainerId: container_1376143950665_0002_01_000001, NodeId: hadoop-221-6:51695, NodeHttpAddress: hadoop-221-6:8042, Resource: <memory:2048, vCores:1>, Priority: 0, State: NEW, Token: null, Status: container_id {, app_attempt_id {, application_id {, id: 2, cluster_timestamp: 1376143950665, }, attemptId: 1, }, id: 1, }, state: C_NEW, ] containerId=container_1376143950665_0002_01_000001 queue=default: capacity=1.0, absoluteCapacity=1.0, usedResources=<memory:0, vCores:0>usedCapacity=0.0, absoluteUsedCapacity=0.0, numApps=1, numContainers=0 usedCapacity=0.0 absoluteUsedCapacity=0.0 used=<memory:0, vCores:0> cluster=<memory:49152, vCores:96>
2013-08-10 14:16:10,508 INFO org.apache.hadoop.yarn.server.resourcemanager.scheduler.capacity.ParentQueue: Re-sorting queues since queue: root.default stats: default: capacity=1.0, absoluteCapacity=1.0, usedResources=<memory:2048, vCores:1>usedCapacity=0.041666668, absoluteUsedCapacity=0.041666668, numApps=1, numContainers=1
2013-08-10 14:16:10,508 INFO org.apache.hadoop.yarn.server.resourcemanager.scheduler.capacity.ParentQueue: assignedContainer queue=root usedCapacity=0.041666668 absoluteUsedCapacity=0.041666668 used=<memory:2048, vCores:1> cluster=<memory:49152, vCores:96>
2013-08-10 14:16:10,509 INFO org.apache.hadoop.yarn.server.resourcemanager.rmcontainer.RMContainerImpl: container_1376143950665_0002_01_000001 Container Transitioned from ALLOCATED to ACQUIRED
2013-08-10 14:16:10,511 INFO org.apache.hadoop.yarn.server.resourcemanager.rmapp.attempt.RMAppAttemptImpl: Storing attempt: AppId: application_1376143950665_0002 AttemptId: appattempt_1376143950665_0002_000001 MasterContainer: Container: [ContainerId: container_1376143950665_0002_01_000001, NodeId: hadoop-221-6:51695, NodeHttpAddress: hadoop-221-6:8042, Resource: <memory:2048, vCores:1>, Priority: 0, State: NEW, Token: null, Status: container_id {, app_attempt_id {, application_id {, id: 2, cluster_timestamp: 1376143950665, }, attemptId: 1, }, id: 1, }, state: C_NEW, ]
2013-08-10 14:16:10,511 INFO org.apache.hadoop.yarn.server.resourcemanager.rmapp.attempt.RMAppAttemptImpl: appattempt_1376143950665_0002_000001 State change from SCHEDULED to ALLOCATED_SAVING
2013-08-10 14:16:10,511 INFO org.apache.hadoop.yarn.server.resourcemanager.recovery.RMStateStore: Storing info for attempt: appattempt_1376143950665_0002_000001
2013-08-10 14:16:10,513 INFO org.apache.hadoop.yarn.server.resourcemanager.rmapp.attempt.RMAppAttemptImpl: appattempt_1376143950665_0002_000001 State change from ALLOCATED_SAVING to ALLOCATED
2013-08-10 14:16:10,516 INFO org.apache.hadoop.yarn.server.resourcemanager.amlauncher.AMLauncher: Launching masterappattempt_1376143950665_0002_000001
2013-08-10 14:16:10,519 INFO org.apache.hadoop.yarn.server.resourcemanager.amlauncher.AMLauncher: Setting up container Container: [ContainerId: container_1376143950665_0002_01_000001, NodeId: hadoop-221-6:51695, NodeHttpAddress: hadoop-221-6:8042, Resource: <memory:2048, vCores:1>, Priority: 0, State: NEW, Token: null, Status: container_id {, app_attempt_id {, application_id {, id: 2, cluster_timestamp: 1376143950665, }, attemptId: 1, }, id: 1, }, state: C_NEW, ] for AM appattempt_1376143950665_0002_000001
2013-08-10 14:16:10,520 INFO org.apache.hadoop.yarn.server.resourcemanager.amlauncher.AMLauncher: Command to launch container container_1376143950665_0002_01_000001 : $JAVA_HOME/bin/java -Dlog4j.configuration=container-log4j.properties -Dyarn.app.mapreduce.container.log.dir=<LOG_DIR> -Dyarn.app.mapreduce.container.log.filesize=0 -Dhadoop.root.logger=INFO,CLA  -Xmx1024m org.apache.hadoop.mapreduce.v2.app.MRAppMaster 1><LOG_DIR>/stdout 2><LOG_DIR>/stderr 
2013-08-10 14:16:10,539 INFO org.apache.hadoop.yarn.server.resourcemanager.amlauncher.AMLauncher: Done launching container Container: [ContainerId: container_1376143950665_0002_01_000001, NodeId: hadoop-221-6:51695, NodeHttpAddress: hadoop-221-6:8042, Resource: <memory:2048, vCores:1>, Priority: 0, State: NEW, Token: null, Status: container_id {, app_attempt_id {, application_id {, id: 2, cluster_timestamp: 1376143950665, }, attemptId: 1, }, id: 1, }, state: C_NEW, ] for AM appattempt_1376143950665_0002_000001
2013-08-10 14:16:10,540 INFO org.apache.hadoop.yarn.server.resourcemanager.rmapp.attempt.RMAppAttemptImpl: appattempt_1376143950665_0002_000001 State change from ALLOCATED to LAUNCHED
2013-08-10 14:16:11,511 INFO org.apache.hadoop.yarn.server.resourcemanager.rmcontainer.RMContainerImpl: container_1376143950665_0002_01_000001 Container Transitioned from ACQUIRED to RUNNING
2013-08-10 14:16:16,972 INFO org.apache.hadoop.yarn.server.resourcemanager.ApplicationMasterService: AM registration appattempt_1376143950665_0002_000001
2013-08-10 14:16:16,972 INFO org.apache.hadoop.yarn.server.resourcemanager.RMAuditLogger: USER=ubuntu	IP=192.168.100.39	OPERATION=Register App Master	TARGET=ApplicationMasterService	RESULT=SUCCESS	APPID=application_1376143950665_0002	APPATTEMPTID=appattempt_1376143950665_0002_000001
2013-08-10 14:16:16,974 INFO org.apache.hadoop.yarn.server.resourcemanager.rmapp.attempt.RMAppAttemptImpl: appattempt_1376143950665_0002_000001 State change from LAUNCHED to RUNNING
2013-08-10 14:16:16,975 INFO org.apache.hadoop.yarn.server.resourcemanager.rmapp.RMAppImpl: application_1376143950665_0002 State change from ACCEPTED to RUNNING
2013-08-10 14:16:18,039 INFO org.apache.hadoop.yarn.server.resourcemanager.rmcontainer.RMContainerImpl: container_1376143950665_0002_01_000002 Container Transitioned from NEW to ALLOCATED
2013-08-10 14:16:18,040 INFO org.apache.hadoop.yarn.server.resourcemanager.RMAuditLogger: USER=ubuntu	OPERATION=AM Allocated Container	TARGET=SchedulerApp	RESULT=SUCCESS	APPID=application_1376143950665_0002	CONTAINERID=container_1376143950665_0002_01_000002
2013-08-10 14:16:18,040 INFO org.apache.hadoop.yarn.server.resourcemanager.scheduler.common.fica.FiCaSchedulerNode: Assigned container container_1376143950665_0002_01_000002 of capacity <memory:1024, vCores:1> on host hadoop-221-2:53277, which currently has 1 containers, <memory:1024, vCores:1> used and <memory:7168, vCores:15> available
2013-08-10 14:16:18,042 INFO org.apache.hadoop.yarn.server.resourcemanager.scheduler.capacity.LeafQueue: assignedContainer application=application_1376143950665_0002 container=Container: [ContainerId: container_1376143950665_0002_01_000002, NodeId: hadoop-221-2:53277, NodeHttpAddress: hadoop-221-2:8042, Resource: <memory:1024, vCores:1>, Priority: 20, State: NEW, Token: null, Status: container_id {, app_attempt_id {, application_id {, id: 2, cluster_timestamp: 1376143950665, }, attemptId: 1, }, id: 2, }, state: C_NEW, ] containerId=container_1376143950665_0002_01_000002 queue=default: capacity=1.0, absoluteCapacity=1.0, usedResources=<memory:2048, vCores:1>usedCapacity=0.041666668, absoluteUsedCapacity=0.041666668, numApps=1, numContainers=1 usedCapacity=0.041666668 absoluteUsedCapacity=0.041666668 used=<memory:2048, vCores:1> cluster=<memory:49152, vCores:96>
2013-08-10 14:16:18,042 INFO org.apache.hadoop.yarn.server.resourcemanager.scheduler.capacity.ParentQueue: Re-sorting queues since queue: root.default stats: default: capacity=1.0, absoluteCapacity=1.0, usedResources=<memory:3072, vCores:2>usedCapacity=0.0625, absoluteUsedCapacity=0.0625, numApps=1, numContainers=2
2013-08-10 14:16:18,042 INFO org.apache.hadoop.yarn.server.resourcemanager.scheduler.capacity.ParentQueue: assignedContainer queue=root usedCapacity=0.0625 absoluteUsedCapacity=0.0625 used=<memory:3072, vCores:2> cluster=<memory:49152, vCores:96>
2013-08-10 14:16:18,257 INFO org.apache.hadoop.yarn.server.resourcemanager.rmcontainer.RMContainerImpl: container_1376143950665_0002_01_000003 Container Transitioned from NEW to ALLOCATED
2013-08-10 14:16:18,258 INFO org.apache.hadoop.yarn.server.resourcemanager.RMAuditLogger: USER=ubuntu	OPERATION=AM Allocated Container	TARGET=SchedulerApp	RESULT=SUCCESS	APPID=application_1376143950665_0002	CONTAINERID=container_1376143950665_0002_01_000003
2013-08-10 14:16:18,258 INFO org.apache.hadoop.yarn.server.resourcemanager.scheduler.common.fica.FiCaSchedulerNode: Assigned container container_1376143950665_0002_01_000003 of capacity <memory:1024, vCores:1> on host hadoop-221-7:43558, which currently has 1 containers, <memory:1024, vCores:1> used and <memory:7168, vCores:15> available
2013-08-10 14:16:18,259 INFO org.apache.hadoop.yarn.server.resourcemanager.scheduler.capacity.LeafQueue: assignedContainer application=application_1376143950665_0002 container=Container: [ContainerId: container_1376143950665_0002_01_000003, NodeId: hadoop-221-7:43558, NodeHttpAddress: hadoop-221-7:8042, Resource: <memory:1024, vCores:1>, Priority: 20, State: NEW, Token: null, Status: container_id {, app_attempt_id {, application_id {, id: 2, cluster_timestamp: 1376143950665, }, attemptId: 1, }, id: 3, }, state: C_NEW, ] containerId=container_1376143950665_0002_01_000003 queue=default: capacity=1.0, absoluteCapacity=1.0, usedResources=<memory:3072, vCores:2>usedCapacity=0.0625, absoluteUsedCapacity=0.0625, numApps=1, numContainers=2 usedCapacity=0.0625 absoluteUsedCapacity=0.0625 used=<memory:3072, vCores:2> cluster=<memory:49152, vCores:96>
2013-08-10 14:16:18,260 INFO org.apache.hadoop.yarn.server.resourcemanager.scheduler.capacity.ParentQueue: Re-sorting queues since queue: root.default stats: default: capacity=1.0, absoluteCapacity=1.0, usedResources=<memory:4096, vCores:3>usedCapacity=0.083333336, absoluteUsedCapacity=0.083333336, numApps=1, numContainers=3
2013-08-10 14:16:18,260 INFO org.apache.hadoop.yarn.server.resourcemanager.scheduler.capacity.ParentQueue: assignedContainer queue=root usedCapacity=0.083333336 absoluteUsedCapacity=0.083333336 used=<memory:4096, vCores:3> cluster=<memory:49152, vCores:96>
2013-08-10 14:16:19,036 INFO org.apache.hadoop.yarn.server.resourcemanager.rmcontainer.RMContainerImpl: container_1376143950665_0002_01_000002 Container Transitioned from ALLOCATED to ACQUIRED
2013-08-10 14:16:19,038 INFO org.apache.hadoop.yarn.server.resourcemanager.rmcontainer.RMContainerImpl: container_1376143950665_0002_01_000003 Container Transitioned from ALLOCATED to ACQUIRED
2013-08-10 14:16:20,065 INFO org.apache.hadoop.yarn.server.resourcemanager.scheduler.AppSchedulingInfo: checking for deactivate... 
2013-08-10 14:16:21,144 INFO org.apache.hadoop.yarn.server.resourcemanager.rmcontainer.RMContainerImpl: container_1376143950665_0002_01_000002 Container Transitioned from ACQUIRED to RUNNING
2013-08-10 14:16:21,350 INFO org.apache.hadoop.yarn.server.resourcemanager.rmcontainer.RMContainerImpl: container_1376143950665_0002_01_000003 Container Transitioned from ACQUIRED to RUNNING
2013-08-10 14:19:08,073 INFO org.apache.hadoop.yarn.server.resourcemanager.rmcontainer.RMContainerImpl: container_1376143950665_0002_01_000003 Container Transitioned from RUNNING to COMPLETED
2013-08-10 14:19:08,074 INFO org.apache.hadoop.yarn.server.resourcemanager.scheduler.common.fica.FiCaSchedulerApp: Completed container: container_1376143950665_0002_01_000003 in state: COMPLETED event:FINISHED
2013-08-10 14:19:08,074 INFO org.apache.hadoop.yarn.server.resourcemanager.RMAuditLogger: USER=ubuntu	OPERATION=AM Released Container	TARGET=SchedulerApp	RESULT=SUCCESS	APPID=application_1376143950665_0002	CONTAINERID=container_1376143950665_0002_01_000003
2013-08-10 14:19:08,074 INFO org.apache.hadoop.yarn.server.resourcemanager.scheduler.common.fica.FiCaSchedulerNode: Released container container_1376143950665_0002_01_000003 of capacity <memory:1024, vCores:1> on host hadoop-221-7:43558, which currently has 0 containers, <memory:0, vCores:0> used and <memory:8192, vCores:16> available, release resources=true
2013-08-10 14:19:08,074 INFO org.apache.hadoop.yarn.server.resourcemanager.scheduler.capacity.LeafQueue: default used=<memory:3072, vCores:2> numContainers=2 user=ubuntu user-resources=<memory:3072, vCores:2>
2013-08-10 14:19:08,088 INFO org.apache.hadoop.yarn.server.resourcemanager.scheduler.capacity.LeafQueue: completedContainer container=Container: [ContainerId: container_1376143950665_0002_01_000003, NodeId: hadoop-221-7:43558, NodeHttpAddress: hadoop-221-7:8042, Resource: <memory:1024, vCores:1>, Priority: 20, State: NEW, Token: null, Status: container_id {, app_attempt_id {, application_id {, id: 2, cluster_timestamp: 1376143950665, }, attemptId: 1, }, id: 3, }, state: C_COMPLETE, diagnostics: "Container killed by the ApplicationMaster.\n\n", exit_status: 143, ] resource=<memory:1024, vCores:1> queue=default: capacity=1.0, absoluteCapacity=1.0, usedResources=<memory:3072, vCores:2>usedCapacity=0.0625, absoluteUsedCapacity=0.0625, numApps=1, numContainers=2 usedCapacity=0.0625 absoluteUsedCapacity=0.0625 used=<memory:3072, vCores:2> cluster=<memory:49152, vCores:96>
2013-08-10 14:19:08,088 INFO org.apache.hadoop.yarn.server.resourcemanager.scheduler.capacity.ParentQueue: completedContainer queue=root usedCapacity=0.0625 absoluteUsedCapacity=0.0625 used=<memory:3072, vCores:2> cluster=<memory:49152, vCores:96>
2013-08-10 14:19:08,088 INFO org.apache.hadoop.yarn.server.resourcemanager.scheduler.capacity.CapacityScheduler: Application appattempt_1376143950665_0002_000001 released container container_1376143950665_0002_01_000003 on node: host: hadoop-221-7:43558 #containers=0 available=8192 used=0 with event: FINISHED
2013-08-10 14:19:09,619 INFO org.apache.hadoop.yarn.server.resourcemanager.rmcontainer.RMContainerImpl: container_1376143950665_0002_01_000002 Container Transitioned from RUNNING to COMPLETED
2013-08-10 14:19:09,619 INFO org.apache.hadoop.yarn.server.resourcemanager.scheduler.common.fica.FiCaSchedulerApp: Completed container: container_1376143950665_0002_01_000002 in state: COMPLETED event:FINISHED
2013-08-10 14:19:09,620 INFO org.apache.hadoop.yarn.server.resourcemanager.RMAuditLogger: USER=ubuntu	OPERATION=AM Released Container	TARGET=SchedulerApp	RESULT=SUCCESS	APPID=application_1376143950665_0002	CONTAINERID=container_1376143950665_0002_01_000002
2013-08-10 14:19:09,620 INFO org.apache.hadoop.yarn.server.resourcemanager.scheduler.common.fica.FiCaSchedulerNode: Released container container_1376143950665_0002_01_000002 of capacity <memory:1024, vCores:1> on host hadoop-221-2:53277, which currently has 0 containers, <memory:0, vCores:0> used and <memory:8192, vCores:16> available, release resources=true
2013-08-10 14:19:09,620 INFO org.apache.hadoop.yarn.server.resourcemanager.scheduler.capacity.LeafQueue: default used=<memory:2048, vCores:1> numContainers=1 user=ubuntu user-resources=<memory:2048, vCores:1>
2013-08-10 14:19:09,622 INFO org.apache.hadoop.yarn.server.resourcemanager.scheduler.capacity.LeafQueue: completedContainer container=Container: [ContainerId: container_1376143950665_0002_01_000002, NodeId: hadoop-221-2:53277, NodeHttpAddress: hadoop-221-2:8042, Resource: <memory:1024, vCores:1>, Priority: 20, State: NEW, Token: null, Status: container_id {, app_attempt_id {, application_id {, id: 2, cluster_timestamp: 1376143950665, }, attemptId: 1, }, id: 2, }, state: C_COMPLETE, diagnostics: "Container killed by the ApplicationMaster.\n\n", exit_status: 143, ] resource=<memory:1024, vCores:1> queue=default: capacity=1.0, absoluteCapacity=1.0, usedResources=<memory:2048, vCores:1>usedCapacity=0.041666668, absoluteUsedCapacity=0.041666668, numApps=1, numContainers=1 usedCapacity=0.041666668 absoluteUsedCapacity=0.041666668 used=<memory:2048, vCores:1> cluster=<memory:49152, vCores:96>
2013-08-10 14:19:09,622 INFO org.apache.hadoop.yarn.server.resourcemanager.scheduler.capacity.ParentQueue: completedContainer queue=root usedCapacity=0.041666668 absoluteUsedCapacity=0.041666668 used=<memory:2048, vCores:1> cluster=<memory:49152, vCores:96>
2013-08-10 14:19:09,623 INFO org.apache.hadoop.yarn.server.resourcemanager.scheduler.capacity.CapacityScheduler: Application appattempt_1376143950665_0002_000001 released container container_1376143950665_0002_01_000002 on node: host: hadoop-221-2:53277 #containers=0 available=8192 used=0 with event: FINISHED
2013-08-10 14:19:13,765 INFO org.apache.hadoop.yarn.server.resourcemanager.rmapp.attempt.RMAppAttemptImpl: appattempt_1376143950665_0002_000001 State change from RUNNING to FINISHING
2013-08-10 14:19:13,766 INFO org.apache.hadoop.yarn.server.resourcemanager.rmapp.RMAppImpl: application_1376143950665_0002 State change from RUNNING to FINISHING
2013-08-10 14:19:14,650 INFO org.apache.hadoop.yarn.server.resourcemanager.rmcontainer.RMContainerImpl: container_1376143950665_0002_01_000001 Container Transitioned from RUNNING to COMPLETED
2013-08-10 14:19:14,651 INFO org.apache.hadoop.yarn.server.resourcemanager.scheduler.common.fica.FiCaSchedulerApp: Completed container: container_1376143950665_0002_01_000001 in state: COMPLETED event:FINISHED
2013-08-10 14:19:14,651 INFO org.apache.hadoop.yarn.server.resourcemanager.RMAuditLogger: USER=ubuntu	OPERATION=AM Released Container	TARGET=SchedulerApp	RESULT=SUCCESS	APPID=application_1376143950665_0002	CONTAINERID=container_1376143950665_0002_01_000001
2013-08-10 14:19:14,651 INFO org.apache.hadoop.yarn.server.resourcemanager.scheduler.common.fica.FiCaSchedulerNode: Released container container_1376143950665_0002_01_000001 of capacity <memory:2048, vCores:1> on host hadoop-221-6:51695, which currently has 0 containers, <memory:0, vCores:0> used and <memory:8192, vCores:16> available, release resources=true
2013-08-10 14:19:14,651 INFO org.apache.hadoop.yarn.server.resourcemanager.scheduler.capacity.LeafQueue: default used=<memory:0, vCores:0> numContainers=0 user=ubuntu user-resources=<memory:0, vCores:0>
2013-08-10 14:19:14,653 INFO org.apache.hadoop.yarn.server.resourcemanager.scheduler.capacity.LeafQueue: completedContainer container=Container: [ContainerId: container_1376143950665_0002_01_000001, NodeId: hadoop-221-6:51695, NodeHttpAddress: hadoop-221-6:8042, Resource: <memory:2048, vCores:1>, Priority: 0, State: NEW, Token: null, Status: container_id {, app_attempt_id {, application_id {, id: 2, cluster_timestamp: 1376143950665, }, attemptId: 1, }, id: 1, }, state: C_COMPLETE, diagnostics: "", exit_status: 0, ] resource=<memory:2048, vCores:1> queue=default: capacity=1.0, absoluteCapacity=1.0, usedResources=<memory:0, vCores:0>usedCapacity=0.0, absoluteUsedCapacity=0.0, numApps=1, numContainers=0 usedCapacity=0.0 absoluteUsedCapacity=0.0 used=<memory:0, vCores:0> cluster=<memory:49152, vCores:96>
2013-08-10 14:19:14,653 INFO org.apache.hadoop.yarn.server.resourcemanager.scheduler.capacity.ParentQueue: completedContainer queue=root usedCapacity=0.0 absoluteUsedCapacity=0.0 used=<memory:0, vCores:0> cluster=<memory:49152, vCores:96>
2013-08-10 14:19:14,653 INFO org.apache.hadoop.yarn.server.resourcemanager.scheduler.capacity.CapacityScheduler: Application appattempt_1376143950665_0002_000001 released container container_1376143950665_0002_01_000001 on node: host: hadoop-221-6:51695 #containers=0 available=8192 used=0 with event: FINISHED
2013-08-10 14:19:14,654 INFO org.apache.hadoop.yarn.server.resourcemanager.rmapp.attempt.RMAppAttemptImpl: appattempt_1376143950665_0002_000001 State change from FINISHING to FINISHED
2013-08-10 14:19:14,655 INFO org.apache.hadoop.yarn.server.resourcemanager.rmapp.RMAppImpl: application_1376143950665_0002 State change from FINISHING to FINISHED
2013-08-10 14:19:14,655 INFO org.apache.hadoop.yarn.server.resourcemanager.RMAuditLogger: USER=ubuntu	OPERATION=Application Finished - Succeeded	TARGET=RMAppManager	RESULT=SUCCESS	APPID=application_1376143950665_0002
2013-08-10 14:19:14,655 INFO org.apache.hadoop.yarn.server.resourcemanager.recovery.RMStateStore: Removing info for app: application_1376143950665_0002
2013-08-10 14:19:14,655 INFO org.apache.hadoop.yarn.server.resourcemanager.RMAppManager$ApplicationSummary: appId=application_1376143950665_0002,name=TeraGen,user=ubuntu,queue=default,state=FINISHED,trackingUrl=hadoop-221-1.novalocal:8088/proxy/application_1376143950665_0002/jobhistory/job/job_1376143950665_0002,appMasterHost=hadoop-221-6,startTime=1376144170484,finishTime=1376144353766
2013-08-10 14:19:14,656 INFO org.apache.hadoop.yarn.server.resourcemanager.scheduler.capacity.CapacityScheduler: Application appattempt_1376143950665_0002_000001 is done. finalState=FINISHED
2013-08-10 14:19:14,656 INFO org.apache.hadoop.yarn.server.resourcemanager.scheduler.AppSchedulingInfo: Application application_1376143950665_0002 requests cleared
2013-08-10 14:19:14,656 INFO org.apache.hadoop.yarn.server.resourcemanager.scheduler.capacity.LeafQueue: Application removed - appId: application_1376143950665_0002 user: ubuntu queue: default #user-pending-applications: 0 #user-active-applications: 0 #queue-pending-applications: 0 #queue-active-applications: 0
2013-08-10 14:19:14,656 INFO org.apache.hadoop.yarn.server.resourcemanager.scheduler.capacity.ParentQueue: Application removed - appId: application_1376143950665_0002 user: ubuntu leaf-queue of parent: root #applications: 0
2013-08-10 14:19:14,656 INFO org.apache.hadoop.yarn.server.resourcemanager.amlauncher.AMLauncher: Cleaning master appattempt_1376143950665_0002_000001
2013-08-10 14:19:14,854 INFO org.apache.hadoop.yarn.server.resourcemanager.ClientRMService: Allocated new applicationId: 3
2013-08-10 14:19:16,783 INFO org.apache.hadoop.yarn.server.resourcemanager.ClientRMService: Storing Application with id application_1376143950665_0003
2013-08-10 14:19:16,783 INFO org.apache.hadoop.yarn.server.resourcemanager.recovery.RMStateStore: Storing info for app: application_1376143950665_0003
2013-08-10 14:19:16,783 INFO org.apache.hadoop.yarn.server.resourcemanager.ClientRMService: Application with id 3 submitted by user ubuntu
2013-08-10 14:19:16,783 INFO org.apache.hadoop.yarn.server.resourcemanager.RMAuditLogger: USER=ubuntu	IP=192.168.100.14	OPERATION=Submit Application Request	TARGET=ClientRMService	RESULT=SUCCESS	APPID=application_1376143950665_0003
2013-08-10 14:19:16,786 INFO org.apache.hadoop.yarn.server.resourcemanager.rmapp.RMAppImpl: application_1376143950665_0003 State change from NEW to SUBMITTED
2013-08-10 14:19:16,786 INFO org.apache.hadoop.yarn.server.resourcemanager.ApplicationMasterService: Registering appattempt_1376143950665_0003_000001
2013-08-10 14:19:16,786 INFO org.apache.hadoop.yarn.server.resourcemanager.rmapp.attempt.RMAppAttemptImpl: appattempt_1376143950665_0003_000001 State change from NEW to SUBMITTED
2013-08-10 14:19:16,787 INFO org.apache.hadoop.yarn.server.resourcemanager.scheduler.capacity.LeafQueue: Application application_1376143950665_0003 from user: ubuntu activated in queue: default
2013-08-10 14:19:16,787 INFO org.apache.hadoop.yarn.server.resourcemanager.scheduler.capacity.LeafQueue: Application added - appId: application_1376143950665_0003 user: org.apache.hadoop.yarn.server.resourcemanager.scheduler.capacity.LeafQueue$User@2d6ca6b8, leaf-queue: default #user-pending-applications: 0 #user-active-applications: 1 #queue-pending-applications: 0 #queue-active-applications: 1
2013-08-10 14:19:16,787 INFO org.apache.hadoop.yarn.server.resourcemanager.scheduler.capacity.ParentQueue: Application added - appId: application_1376143950665_0003 user: ubuntu leaf-queue of parent: root #applications: 1
2013-08-10 14:19:16,787 INFO org.apache.hadoop.yarn.server.resourcemanager.scheduler.capacity.CapacityScheduler: Application Submission: appattempt_1376143950665_0003_000001, user: ubuntu queue: default: capacity=1.0, absoluteCapacity=1.0, usedResources=<memory:0, vCores:0>usedCapacity=0.0, absoluteUsedCapacity=0.0, numApps=1, numContainers=0, currently active: 1
2013-08-10 14:19:16,788 INFO org.apache.hadoop.yarn.server.resourcemanager.rmapp.attempt.RMAppAttemptImpl: appattempt_1376143950665_0003_000001 State change from SUBMITTED to SCHEDULED
2013-08-10 14:19:16,788 INFO org.apache.hadoop.yarn.server.resourcemanager.rmapp.RMAppImpl: application_1376143950665_0003 State change from SUBMITTED to ACCEPTED
2013-08-10 14:19:17,116 INFO org.apache.hadoop.yarn.server.resourcemanager.rmcontainer.RMContainerImpl: container_1376143950665_0003_01_000001 Container Transitioned from NEW to ALLOCATED
2013-08-10 14:19:17,116 INFO org.apache.hadoop.yarn.server.resourcemanager.RMAuditLogger: USER=ubuntu	OPERATION=AM Allocated Container	TARGET=SchedulerApp	RESULT=SUCCESS	APPID=application_1376143950665_0003	CONTAINERID=container_1376143950665_0003_01_000001
2013-08-10 14:19:17,116 INFO org.apache.hadoop.yarn.server.resourcemanager.scheduler.common.fica.FiCaSchedulerNode: Assigned container container_1376143950665_0003_01_000001 of capacity <memory:2048, vCores:1> on host hadoop-221-7:43558, which currently has 1 containers, <memory:2048, vCores:1> used and <memory:6144, vCores:15> available
2013-08-10 14:19:17,118 INFO org.apache.hadoop.yarn.server.resourcemanager.scheduler.capacity.LeafQueue: assignedContainer application=application_1376143950665_0003 container=Container: [ContainerId: container_1376143950665_0003_01_000001, NodeId: hadoop-221-7:43558, NodeHttpAddress: hadoop-221-7:8042, Resource: <memory:2048, vCores:1>, Priority: 0, State: NEW, Token: null, Status: container_id {, app_attempt_id {, application_id {, id: 3, cluster_timestamp: 1376143950665, }, attemptId: 1, }, id: 1, }, state: C_NEW, ] containerId=container_1376143950665_0003_01_000001 queue=default: capacity=1.0, absoluteCapacity=1.0, usedResources=<memory:0, vCores:0>usedCapacity=0.0, absoluteUsedCapacity=0.0, numApps=1, numContainers=0 usedCapacity=0.0 absoluteUsedCapacity=0.0 used=<memory:0, vCores:0> cluster=<memory:49152, vCores:96>
2013-08-10 14:19:17,118 INFO org.apache.hadoop.yarn.server.resourcemanager.scheduler.capacity.ParentQueue: Re-sorting queues since queue: root.default stats: default: capacity=1.0, absoluteCapacity=1.0, usedResources=<memory:2048, vCores:1>usedCapacity=0.041666668, absoluteUsedCapacity=0.041666668, numApps=1, numContainers=1
2013-08-10 14:19:17,118 INFO org.apache.hadoop.yarn.server.resourcemanager.scheduler.capacity.ParentQueue: assignedContainer queue=root usedCapacity=0.041666668 absoluteUsedCapacity=0.041666668 used=<memory:2048, vCores:1> cluster=<memory:49152, vCores:96>
2013-08-10 14:19:17,119 INFO org.apache.hadoop.yarn.server.resourcemanager.rmcontainer.RMContainerImpl: container_1376143950665_0003_01_000001 Container Transitioned from ALLOCATED to ACQUIRED
2013-08-10 14:19:17,121 INFO org.apache.hadoop.yarn.server.resourcemanager.rmapp.attempt.RMAppAttemptImpl: Storing attempt: AppId: application_1376143950665_0003 AttemptId: appattempt_1376143950665_0003_000001 MasterContainer: Container: [ContainerId: container_1376143950665_0003_01_000001, NodeId: hadoop-221-7:43558, NodeHttpAddress: hadoop-221-7:8042, Resource: <memory:2048, vCores:1>, Priority: 0, State: NEW, Token: null, Status: container_id {, app_attempt_id {, application_id {, id: 3, cluster_timestamp: 1376143950665, }, attemptId: 1, }, id: 1, }, state: C_NEW, ]
2013-08-10 14:19:17,122 INFO org.apache.hadoop.yarn.server.resourcemanager.recovery.RMStateStore: Storing info for attempt: appattempt_1376143950665_0003_000001
2013-08-10 14:19:17,122 INFO org.apache.hadoop.yarn.server.resourcemanager.rmapp.attempt.RMAppAttemptImpl: appattempt_1376143950665_0003_000001 State change from SCHEDULED to ALLOCATED_SAVING
2013-08-10 14:19:17,123 INFO org.apache.hadoop.yarn.server.resourcemanager.rmapp.attempt.RMAppAttemptImpl: appattempt_1376143950665_0003_000001 State change from ALLOCATED_SAVING to ALLOCATED
2013-08-10 14:19:17,124 INFO org.apache.hadoop.yarn.server.resourcemanager.amlauncher.AMLauncher: Launching masterappattempt_1376143950665_0003_000001
2013-08-10 14:19:17,127 INFO org.apache.hadoop.yarn.server.resourcemanager.amlauncher.AMLauncher: Setting up container Container: [ContainerId: container_1376143950665_0003_01_000001, NodeId: hadoop-221-7:43558, NodeHttpAddress: hadoop-221-7:8042, Resource: <memory:2048, vCores:1>, Priority: 0, State: NEW, Token: null, Status: container_id {, app_attempt_id {, application_id {, id: 3, cluster_timestamp: 1376143950665, }, attemptId: 1, }, id: 1, }, state: C_NEW, ] for AM appattempt_1376143950665_0003_000001
2013-08-10 14:19:17,127 INFO org.apache.hadoop.yarn.server.resourcemanager.amlauncher.AMLauncher: Command to launch container container_1376143950665_0003_01_000001 : $JAVA_HOME/bin/java -Dlog4j.configuration=container-log4j.properties -Dyarn.app.mapreduce.container.log.dir=<LOG_DIR> -Dyarn.app.mapreduce.container.log.filesize=0 -Dhadoop.root.logger=INFO,CLA  -Xmx1024m org.apache.hadoop.mapreduce.v2.app.MRAppMaster 1><LOG_DIR>/stdout 2><LOG_DIR>/stderr 
2013-08-10 14:19:17,142 INFO org.apache.hadoop.yarn.server.resourcemanager.amlauncher.AMLauncher: Done launching container Container: [ContainerId: container_1376143950665_0003_01_000001, NodeId: hadoop-221-7:43558, NodeHttpAddress: hadoop-221-7:8042, Resource: <memory:2048, vCores:1>, Priority: 0, State: NEW, Token: null, Status: container_id {, app_attempt_id {, application_id {, id: 3, cluster_timestamp: 1376143950665, }, attemptId: 1, }, id: 1, }, state: C_NEW, ] for AM appattempt_1376143950665_0003_000001
2013-08-10 14:19:17,142 INFO org.apache.hadoop.yarn.server.resourcemanager.rmapp.attempt.RMAppAttemptImpl: appattempt_1376143950665_0003_000001 State change from ALLOCATED to LAUNCHED
2013-08-10 14:19:18,124 INFO org.apache.hadoop.yarn.server.resourcemanager.rmcontainer.RMContainerImpl: container_1376143950665_0003_01_000001 Container Transitioned from ACQUIRED to RUNNING
2013-08-10 14:19:25,429 INFO org.apache.hadoop.yarn.server.resourcemanager.ApplicationMasterService: AM registration appattempt_1376143950665_0003_000001
2013-08-10 14:19:25,429 INFO org.apache.hadoop.yarn.server.resourcemanager.RMAuditLogger: USER=ubuntu	IP=192.168.100.40	OPERATION=Register App Master	TARGET=ApplicationMasterService	RESULT=SUCCESS	APPID=application_1376143950665_0003	APPATTEMPTID=appattempt_1376143950665_0003_000001
2013-08-10 14:19:25,430 INFO org.apache.hadoop.yarn.server.resourcemanager.rmapp.attempt.RMAppAttemptImpl: appattempt_1376143950665_0003_000001 State change from LAUNCHED to RUNNING
2013-08-10 14:19:25,430 INFO org.apache.hadoop.yarn.server.resourcemanager.rmapp.RMAppImpl: application_1376143950665_0003 State change from ACCEPTED to RUNNING
2013-08-10 14:19:26,685 INFO org.apache.hadoop.yarn.server.resourcemanager.rmcontainer.RMContainerImpl: container_1376143950665_0003_01_000002 Container Transitioned from NEW to ALLOCATED
2013-08-10 14:19:26,685 INFO org.apache.hadoop.yarn.server.resourcemanager.RMAuditLogger: USER=ubuntu	OPERATION=AM Allocated Container	TARGET=SchedulerApp	RESULT=SUCCESS	APPID=application_1376143950665_0003	CONTAINERID=container_1376143950665_0003_01_000002
2013-08-10 14:19:26,685 INFO org.apache.hadoop.yarn.server.resourcemanager.scheduler.common.fica.FiCaSchedulerNode: Assigned container container_1376143950665_0003_01_000002 of capacity <memory:1024, vCores:1> on host hadoop-221-2:53277, which currently has 1 containers, <memory:1024, vCores:1> used and <memory:7168, vCores:15> available
2013-08-10 14:19:26,687 INFO org.apache.hadoop.yarn.server.resourcemanager.scheduler.capacity.LeafQueue: assignedContainer application=application_1376143950665_0003 container=Container: [ContainerId: container_1376143950665_0003_01_000002, NodeId: hadoop-221-2:53277, NodeHttpAddress: hadoop-221-2:8042, Resource: <memory:1024, vCores:1>, Priority: 20, State: NEW, Token: null, Status: container_id {, app_attempt_id {, application_id {, id: 3, cluster_timestamp: 1376143950665, }, attemptId: 1, }, id: 2, }, state: C_NEW, ] containerId=container_1376143950665_0003_01_000002 queue=default: capacity=1.0, absoluteCapacity=1.0, usedResources=<memory:2048, vCores:1>usedCapacity=0.041666668, absoluteUsedCapacity=0.041666668, numApps=1, numContainers=1 usedCapacity=0.041666668 absoluteUsedCapacity=0.041666668 used=<memory:2048, vCores:1> cluster=<memory:49152, vCores:96>
2013-08-10 14:19:26,687 INFO org.apache.hadoop.yarn.server.resourcemanager.scheduler.capacity.ParentQueue: Re-sorting queues since queue: root.default stats: default: capacity=1.0, absoluteCapacity=1.0, usedResources=<memory:3072, vCores:2>usedCapacity=0.0625, absoluteUsedCapacity=0.0625, numApps=1, numContainers=2
2013-08-10 14:19:26,687 INFO org.apache.hadoop.yarn.server.resourcemanager.scheduler.capacity.ParentQueue: assignedContainer queue=root usedCapacity=0.0625 absoluteUsedCapacity=0.0625 used=<memory:3072, vCores:2> cluster=<memory:49152, vCores:96>
2013-08-10 14:19:26,693 INFO org.apache.hadoop.yarn.server.resourcemanager.rmcontainer.RMContainerImpl: container_1376143950665_0003_01_000003 Container Transitioned from NEW to ALLOCATED
2013-08-10 14:19:26,694 INFO org.apache.hadoop.yarn.server.resourcemanager.RMAuditLogger: USER=ubuntu	OPERATION=AM Allocated Container	TARGET=SchedulerApp	RESULT=SUCCESS	APPID=application_1376143950665_0003	CONTAINERID=container_1376143950665_0003_01_000003
2013-08-10 14:19:26,694 INFO org.apache.hadoop.yarn.server.resourcemanager.scheduler.common.fica.FiCaSchedulerNode: Assigned container container_1376143950665_0003_01_000003 of capacity <memory:1024, vCores:1> on host hadoop-221-6:51695, which currently has 1 containers, <memory:1024, vCores:1> used and <memory:7168, vCores:15> available
2013-08-10 14:19:26,695 INFO org.apache.hadoop.yarn.server.resourcemanager.scheduler.capacity.LeafQueue: assignedContainer application=application_1376143950665_0003 container=Container: [ContainerId: container_1376143950665_0003_01_000003, NodeId: hadoop-221-6:51695, NodeHttpAddress: hadoop-221-6:8042, Resource: <memory:1024, vCores:1>, Priority: 20, State: NEW, Token: null, Status: container_id {, app_attempt_id {, application_id {, id: 3, cluster_timestamp: 1376143950665, }, attemptId: 1, }, id: 3, }, state: C_NEW, ] containerId=container_1376143950665_0003_01_000003 queue=default: capacity=1.0, absoluteCapacity=1.0, usedResources=<memory:3072, vCores:2>usedCapacity=0.0625, absoluteUsedCapacity=0.0625, numApps=1, numContainers=2 usedCapacity=0.0625 absoluteUsedCapacity=0.0625 used=<memory:3072, vCores:2> cluster=<memory:49152, vCores:96>
2013-08-10 14:19:26,696 INFO org.apache.hadoop.yarn.server.resourcemanager.scheduler.capacity.ParentQueue: Re-sorting queues since queue: root.default stats: default: capacity=1.0, absoluteCapacity=1.0, usedResources=<memory:4096, vCores:3>usedCapacity=0.083333336, absoluteUsedCapacity=0.083333336, numApps=1, numContainers=3
2013-08-10 14:19:26,696 INFO org.apache.hadoop.yarn.server.resourcemanager.scheduler.capacity.ParentQueue: assignedContainer queue=root usedCapacity=0.083333336 absoluteUsedCapacity=0.083333336 used=<memory:4096, vCores:3> cluster=<memory:49152, vCores:96>
2013-08-10 14:19:27,481 INFO org.apache.hadoop.yarn.server.resourcemanager.rmcontainer.RMContainerImpl: container_1376143950665_0003_01_000002 Container Transitioned from ALLOCATED to ACQUIRED
2013-08-10 14:19:27,484 INFO org.apache.hadoop.yarn.server.resourcemanager.rmcontainer.RMContainerImpl: container_1376143950665_0003_01_000003 Container Transitioned from ALLOCATED to ACQUIRED
2013-08-10 14:19:28,513 INFO org.apache.hadoop.yarn.server.resourcemanager.scheduler.AppSchedulingInfo: checking for deactivate... 
2013-08-10 14:19:28,691 INFO org.apache.hadoop.yarn.server.resourcemanager.rmcontainer.RMContainerImpl: container_1376143950665_0003_01_000002 Container Transitioned from ACQUIRED to RUNNING
2013-08-10 14:19:28,702 INFO org.apache.hadoop.yarn.server.resourcemanager.rmcontainer.RMContainerImpl: container_1376143950665_0003_01_000003 Container Transitioned from ACQUIRED to RUNNING
2013-08-10 14:22:18,793 INFO org.apache.hadoop.yarn.server.resourcemanager.rmcontainer.RMContainerImpl: container_1376143950665_0003_01_000003 Container Transitioned from RUNNING to COMPLETED
2013-08-10 14:22:18,794 INFO org.apache.hadoop.yarn.server.resourcemanager.scheduler.common.fica.FiCaSchedulerApp: Completed container: container_1376143950665_0003_01_000003 in state: COMPLETED event:FINISHED
2013-08-10 14:22:18,794 INFO org.apache.hadoop.yarn.server.resourcemanager.RMAuditLogger: USER=ubuntu	OPERATION=AM Released Container	TARGET=SchedulerApp	RESULT=SUCCESS	APPID=application_1376143950665_0003	CONTAINERID=container_1376143950665_0003_01_000003
2013-08-10 14:22:18,794 INFO org.apache.hadoop.yarn.server.resourcemanager.scheduler.common.fica.FiCaSchedulerNode: Released container container_1376143950665_0003_01_000003 of capacity <memory:1024, vCores:1> on host hadoop-221-6:51695, which currently has 0 containers, <memory:0, vCores:0> used and <memory:8192, vCores:16> available, release resources=true
2013-08-10 14:22:18,794 INFO org.apache.hadoop.yarn.server.resourcemanager.scheduler.capacity.LeafQueue: default used=<memory:3072, vCores:2> numContainers=2 user=ubuntu user-resources=<memory:3072, vCores:2>
2013-08-10 14:22:18,796 INFO org.apache.hadoop.yarn.server.resourcemanager.scheduler.capacity.LeafQueue: completedContainer container=Container: [ContainerId: container_1376143950665_0003_01_000003, NodeId: hadoop-221-6:51695, NodeHttpAddress: hadoop-221-6:8042, Resource: <memory:1024, vCores:1>, Priority: 20, State: NEW, Token: null, Status: container_id {, app_attempt_id {, application_id {, id: 3, cluster_timestamp: 1376143950665, }, attemptId: 1, }, id: 3, }, state: C_COMPLETE, diagnostics: "Container killed by the ApplicationMaster.\n\n", exit_status: 143, ] resource=<memory:1024, vCores:1> queue=default: capacity=1.0, absoluteCapacity=1.0, usedResources=<memory:3072, vCores:2>usedCapacity=0.0625, absoluteUsedCapacity=0.0625, numApps=1, numContainers=2 usedCapacity=0.0625 absoluteUsedCapacity=0.0625 used=<memory:3072, vCores:2> cluster=<memory:49152, vCores:96>
2013-08-10 14:22:18,796 INFO org.apache.hadoop.yarn.server.resourcemanager.scheduler.capacity.ParentQueue: completedContainer queue=root usedCapacity=0.0625 absoluteUsedCapacity=0.0625 used=<memory:3072, vCores:2> cluster=<memory:49152, vCores:96>
2013-08-10 14:22:18,797 INFO org.apache.hadoop.yarn.server.resourcemanager.scheduler.capacity.CapacityScheduler: Application appattempt_1376143950665_0003_000001 released container container_1376143950665_0003_01_000003 on node: host: hadoop-221-6:51695 #containers=0 available=8192 used=0 with event: FINISHED
2013-08-10 14:22:24,613 INFO org.apache.hadoop.yarn.server.resourcemanager.rmcontainer.RMContainerImpl: container_1376143950665_0003_01_000002 Container Transitioned from RUNNING to COMPLETED
2013-08-10 14:22:24,614 INFO org.apache.hadoop.yarn.server.resourcemanager.scheduler.common.fica.FiCaSchedulerApp: Completed container: container_1376143950665_0003_01_000002 in state: COMPLETED event:FINISHED
2013-08-10 14:22:24,614 INFO org.apache.hadoop.yarn.server.resourcemanager.RMAuditLogger: USER=ubuntu	OPERATION=AM Released Container	TARGET=SchedulerApp	RESULT=SUCCESS	APPID=application_1376143950665_0003	CONTAINERID=container_1376143950665_0003_01_000002
2013-08-10 14:22:24,614 INFO org.apache.hadoop.yarn.server.resourcemanager.scheduler.common.fica.FiCaSchedulerNode: Released container container_1376143950665_0003_01_000002 of capacity <memory:1024, vCores:1> on host hadoop-221-2:53277, which currently has 0 containers, <memory:0, vCores:0> used and <memory:8192, vCores:16> available, release resources=true
2013-08-10 14:22:24,614 INFO org.apache.hadoop.yarn.server.resourcemanager.scheduler.capacity.LeafQueue: default used=<memory:2048, vCores:1> numContainers=1 user=ubuntu user-resources=<memory:2048, vCores:1>
2013-08-10 14:22:24,616 INFO org.apache.hadoop.yarn.server.resourcemanager.scheduler.capacity.LeafQueue: completedContainer container=Container: [ContainerId: container_1376143950665_0003_01_000002, NodeId: hadoop-221-2:53277, NodeHttpAddress: hadoop-221-2:8042, Resource: <memory:1024, vCores:1>, Priority: 20, State: NEW, Token: null, Status: container_id {, app_attempt_id {, application_id {, id: 3, cluster_timestamp: 1376143950665, }, attemptId: 1, }, id: 2, }, state: C_COMPLETE, diagnostics: "Container killed by the ApplicationMaster.\n\n", exit_status: 143, ] resource=<memory:1024, vCores:1> queue=default: capacity=1.0, absoluteCapacity=1.0, usedResources=<memory:2048, vCores:1>usedCapacity=0.041666668, absoluteUsedCapacity=0.041666668, numApps=1, numContainers=1 usedCapacity=0.041666668 absoluteUsedCapacity=0.041666668 used=<memory:2048, vCores:1> cluster=<memory:49152, vCores:96>
2013-08-10 14:22:24,617 INFO org.apache.hadoop.yarn.server.resourcemanager.scheduler.capacity.ParentQueue: completedContainer queue=root usedCapacity=0.041666668 absoluteUsedCapacity=0.041666668 used=<memory:2048, vCores:1> cluster=<memory:49152, vCores:96>
2013-08-10 14:22:24,617 INFO org.apache.hadoop.yarn.server.resourcemanager.scheduler.capacity.CapacityScheduler: Application appattempt_1376143950665_0003_000001 released container container_1376143950665_0003_01_000002 on node: host: hadoop-221-2:53277 #containers=0 available=8192 used=0 with event: FINISHED
2013-08-10 14:22:28,801 INFO org.apache.hadoop.yarn.server.resourcemanager.rmapp.attempt.RMAppAttemptImpl: appattempt_1376143950665_0003_000001 State change from RUNNING to FINISHING
2013-08-10 14:22:28,801 INFO org.apache.hadoop.yarn.server.resourcemanager.rmapp.RMAppImpl: application_1376143950665_0003 State change from RUNNING to FINISHING
2013-08-10 14:22:29,252 INFO org.apache.hadoop.yarn.server.resourcemanager.rmcontainer.RMContainerImpl: container_1376143950665_0003_01_000001 Container Transitioned from RUNNING to COMPLETED
2013-08-10 14:22:29,252 INFO org.apache.hadoop.yarn.server.resourcemanager.scheduler.common.fica.FiCaSchedulerApp: Completed container: container_1376143950665_0003_01_000001 in state: COMPLETED event:FINISHED
2013-08-10 14:22:29,252 INFO org.apache.hadoop.yarn.server.resourcemanager.RMAuditLogger: USER=ubuntu	OPERATION=AM Released Container	TARGET=SchedulerApp	RESULT=SUCCESS	APPID=application_1376143950665_0003	CONTAINERID=container_1376143950665_0003_01_000001
2013-08-10 14:22:29,252 INFO org.apache.hadoop.yarn.server.resourcemanager.scheduler.common.fica.FiCaSchedulerNode: Released container container_1376143950665_0003_01_000001 of capacity <memory:2048, vCores:1> on host hadoop-221-7:43558, which currently has 0 containers, <memory:0, vCores:0> used and <memory:8192, vCores:16> available, release resources=true
2013-08-10 14:22:29,253 INFO org.apache.hadoop.yarn.server.resourcemanager.scheduler.capacity.LeafQueue: default used=<memory:0, vCores:0> numContainers=0 user=ubuntu user-resources=<memory:0, vCores:0>
2013-08-10 14:22:29,254 INFO org.apache.hadoop.yarn.server.resourcemanager.scheduler.capacity.LeafQueue: completedContainer container=Container: [ContainerId: container_1376143950665_0003_01_000001, NodeId: hadoop-221-7:43558, NodeHttpAddress: hadoop-221-7:8042, Resource: <memory:2048, vCores:1>, Priority: 0, State: NEW, Token: null, Status: container_id {, app_attempt_id {, application_id {, id: 3, cluster_timestamp: 1376143950665, }, attemptId: 1, }, id: 1, }, state: C_COMPLETE, diagnostics: "", exit_status: 0, ] resource=<memory:2048, vCores:1> queue=default: capacity=1.0, absoluteCapacity=1.0, usedResources=<memory:0, vCores:0>usedCapacity=0.0, absoluteUsedCapacity=0.0, numApps=1, numContainers=0 usedCapacity=0.0 absoluteUsedCapacity=0.0 used=<memory:0, vCores:0> cluster=<memory:49152, vCores:96>
2013-08-10 14:22:29,254 INFO org.apache.hadoop.yarn.server.resourcemanager.scheduler.capacity.ParentQueue: completedContainer queue=root usedCapacity=0.0 absoluteUsedCapacity=0.0 used=<memory:0, vCores:0> cluster=<memory:49152, vCores:96>
2013-08-10 14:22:29,254 INFO org.apache.hadoop.yarn.server.resourcemanager.scheduler.capacity.CapacityScheduler: Application appattempt_1376143950665_0003_000001 released container container_1376143950665_0003_01_000001 on node: host: hadoop-221-7:43558 #containers=0 available=8192 used=0 with event: FINISHED
2013-08-10 14:22:29,256 INFO org.apache.hadoop.yarn.server.resourcemanager.rmapp.attempt.RMAppAttemptImpl: appattempt_1376143950665_0003_000001 State change from FINISHING to FINISHED
2013-08-10 14:22:29,257 INFO org.apache.hadoop.yarn.server.resourcemanager.rmapp.RMAppImpl: application_1376143950665_0003 State change from FINISHING to FINISHED
2013-08-10 14:22:29,257 INFO org.apache.hadoop.yarn.server.resourcemanager.scheduler.capacity.CapacityScheduler: Application appattempt_1376143950665_0003_000001 is done. finalState=FINISHED
2013-08-10 14:22:29,257 INFO org.apache.hadoop.yarn.server.resourcemanager.scheduler.AppSchedulingInfo: Application application_1376143950665_0003 requests cleared
2013-08-10 14:22:29,257 INFO org.apache.hadoop.yarn.server.resourcemanager.RMAuditLogger: USER=ubuntu	OPERATION=Application Finished - Succeeded	TARGET=RMAppManager	RESULT=SUCCESS	APPID=application_1376143950665_0003
2013-08-10 14:22:29,257 INFO org.apache.hadoop.yarn.server.resourcemanager.scheduler.capacity.LeafQueue: Application removed - appId: application_1376143950665_0003 user: ubuntu queue: default #user-pending-applications: 0 #user-active-applications: 0 #queue-pending-applications: 0 #queue-active-applications: 0
2013-08-10 14:22:29,257 INFO org.apache.hadoop.yarn.server.resourcemanager.scheduler.capacity.ParentQueue: Application removed - appId: application_1376143950665_0003 user: ubuntu leaf-queue of parent: root #applications: 0
2013-08-10 14:22:29,258 INFO org.apache.hadoop.yarn.server.resourcemanager.recovery.RMStateStore: Removing info for app: application_1376143950665_0003
2013-08-10 14:22:29,258 INFO org.apache.hadoop.yarn.server.resourcemanager.RMAppManager$ApplicationSummary: appId=application_1376143950665_0003,name=TeraGen,user=ubuntu,queue=default,state=FINISHED,trackingUrl=hadoop-221-1.novalocal:8088/proxy/application_1376143950665_0003/jobhistory/job/job_1376143950665_0003,appMasterHost=hadoop-221-7,startTime=1376144356782,finishTime=1376144548801
2013-08-10 14:22:29,258 INFO org.apache.hadoop.yarn.server.resourcemanager.amlauncher.AMLauncher: Cleaning master appattempt_1376143950665_0003_000001
2013-08-10 14:22:30,454 INFO org.apache.hadoop.yarn.server.resourcemanager.ClientRMService: Allocated new applicationId: 4
2013-08-10 14:22:32,272 INFO org.apache.hadoop.yarn.server.resourcemanager.ClientRMService: Storing Application with id application_1376143950665_0004
2013-08-10 14:22:32,272 INFO org.apache.hadoop.yarn.server.resourcemanager.recovery.RMStateStore: Storing info for app: application_1376143950665_0004
2013-08-10 14:22:32,272 INFO org.apache.hadoop.yarn.server.resourcemanager.ClientRMService: Application with id 4 submitted by user ubuntu
2013-08-10 14:22:32,272 INFO org.apache.hadoop.yarn.server.resourcemanager.RMAuditLogger: USER=ubuntu	IP=192.168.100.14	OPERATION=Submit Application Request	TARGET=ClientRMService	RESULT=SUCCESS	APPID=application_1376143950665_0004
2013-08-10 14:22:32,273 INFO org.apache.hadoop.yarn.server.resourcemanager.rmapp.RMAppImpl: application_1376143950665_0004 State change from NEW to SUBMITTED
2013-08-10 14:22:32,274 INFO org.apache.hadoop.yarn.server.resourcemanager.ApplicationMasterService: Registering appattempt_1376143950665_0004_000001
2013-08-10 14:22:32,274 INFO org.apache.hadoop.yarn.server.resourcemanager.rmapp.attempt.RMAppAttemptImpl: appattempt_1376143950665_0004_000001 State change from NEW to SUBMITTED
2013-08-10 14:22:32,275 INFO org.apache.hadoop.yarn.server.resourcemanager.scheduler.capacity.LeafQueue: Application application_1376143950665_0004 from user: ubuntu activated in queue: default
2013-08-10 14:22:32,275 INFO org.apache.hadoop.yarn.server.resourcemanager.scheduler.capacity.LeafQueue: Application added - appId: application_1376143950665_0004 user: org.apache.hadoop.yarn.server.resourcemanager.scheduler.capacity.LeafQueue$User@484f8660, leaf-queue: default #user-pending-applications: 0 #user-active-applications: 1 #queue-pending-applications: 0 #queue-active-applications: 1
2013-08-10 14:22:32,275 INFO org.apache.hadoop.yarn.server.resourcemanager.scheduler.capacity.ParentQueue: Application added - appId: application_1376143950665_0004 user: ubuntu leaf-queue of parent: root #applications: 1
2013-08-10 14:22:32,275 INFO org.apache.hadoop.yarn.server.resourcemanager.scheduler.capacity.CapacityScheduler: Application Submission: appattempt_1376143950665_0004_000001, user: ubuntu queue: default: capacity=1.0, absoluteCapacity=1.0, usedResources=<memory:0, vCores:0>usedCapacity=0.0, absoluteUsedCapacity=0.0, numApps=1, numContainers=0, currently active: 1
2013-08-10 14:22:32,276 INFO org.apache.hadoop.yarn.server.resourcemanager.rmapp.attempt.RMAppAttemptImpl: appattempt_1376143950665_0004_000001 State change from SUBMITTED to SCHEDULED
2013-08-10 14:22:32,276 INFO org.apache.hadoop.yarn.server.resourcemanager.rmapp.RMAppImpl: application_1376143950665_0004 State change from SUBMITTED to ACCEPTED
2013-08-10 14:22:32,424 INFO org.apache.hadoop.yarn.server.resourcemanager.rmcontainer.RMContainerImpl: container_1376143950665_0004_01_000001 Container Transitioned from NEW to ALLOCATED
2013-08-10 14:22:32,424 INFO org.apache.hadoop.yarn.server.resourcemanager.RMAuditLogger: USER=ubuntu	OPERATION=AM Allocated Container	TARGET=SchedulerApp	RESULT=SUCCESS	APPID=application_1376143950665_0004	CONTAINERID=container_1376143950665_0004_01_000001
2013-08-10 14:22:32,425 INFO org.apache.hadoop.yarn.server.resourcemanager.scheduler.common.fica.FiCaSchedulerNode: Assigned container container_1376143950665_0004_01_000001 of capacity <memory:2048, vCores:1> on host hadoop-221-4:43548, which currently has 1 containers, <memory:2048, vCores:1> used and <memory:6144, vCores:15> available
2013-08-10 14:22:32,426 INFO org.apache.hadoop.yarn.server.resourcemanager.scheduler.capacity.LeafQueue: assignedContainer application=application_1376143950665_0004 container=Container: [ContainerId: container_1376143950665_0004_01_000001, NodeId: hadoop-221-4:43548, NodeHttpAddress: hadoop-221-4:8042, Resource: <memory:2048, vCores:1>, Priority: 0, State: NEW, Token: null, Status: container_id {, app_attempt_id {, application_id {, id: 4, cluster_timestamp: 1376143950665, }, attemptId: 1, }, id: 1, }, state: C_NEW, ] containerId=container_1376143950665_0004_01_000001 queue=default: capacity=1.0, absoluteCapacity=1.0, usedResources=<memory:0, vCores:0>usedCapacity=0.0, absoluteUsedCapacity=0.0, numApps=1, numContainers=0 usedCapacity=0.0 absoluteUsedCapacity=0.0 used=<memory:0, vCores:0> cluster=<memory:49152, vCores:96>
2013-08-10 14:22:32,426 INFO org.apache.hadoop.yarn.server.resourcemanager.scheduler.capacity.ParentQueue: Re-sorting queues since queue: root.default stats: default: capacity=1.0, absoluteCapacity=1.0, usedResources=<memory:2048, vCores:1>usedCapacity=0.041666668, absoluteUsedCapacity=0.041666668, numApps=1, numContainers=1
2013-08-10 14:22:32,429 INFO org.apache.hadoop.yarn.server.resourcemanager.rmcontainer.RMContainerImpl: container_1376143950665_0004_01_000001 Container Transitioned from ALLOCATED to ACQUIRED
2013-08-10 14:22:32,429 INFO org.apache.hadoop.yarn.server.resourcemanager.scheduler.capacity.ParentQueue: assignedContainer queue=root usedCapacity=0.041666668 absoluteUsedCapacity=0.041666668 used=<memory:2048, vCores:1> cluster=<memory:49152, vCores:96>
2013-08-10 14:22:32,432 INFO org.apache.hadoop.yarn.server.resourcemanager.rmapp.attempt.RMAppAttemptImpl: Storing attempt: AppId: application_1376143950665_0004 AttemptId: appattempt_1376143950665_0004_000001 MasterContainer: Container: [ContainerId: container_1376143950665_0004_01_000001, NodeId: hadoop-221-4:43548, NodeHttpAddress: hadoop-221-4:8042, Resource: <memory:2048, vCores:1>, Priority: 0, State: NEW, Token: null, Status: container_id {, app_attempt_id {, application_id {, id: 4, cluster_timestamp: 1376143950665, }, attemptId: 1, }, id: 1, }, state: C_NEW, ]
2013-08-10 14:22:32,432 INFO org.apache.hadoop.yarn.server.resourcemanager.recovery.RMStateStore: Storing info for attempt: appattempt_1376143950665_0004_000001
2013-08-10 14:22:32,432 INFO org.apache.hadoop.yarn.server.resourcemanager.rmapp.attempt.RMAppAttemptImpl: appattempt_1376143950665_0004_000001 State change from SCHEDULED to ALLOCATED_SAVING
2013-08-10 14:22:32,435 INFO org.apache.hadoop.yarn.server.resourcemanager.rmapp.attempt.RMAppAttemptImpl: appattempt_1376143950665_0004_000001 State change from ALLOCATED_SAVING to ALLOCATED
2013-08-10 14:22:32,436 INFO org.apache.hadoop.yarn.server.resourcemanager.amlauncher.AMLauncher: Launching masterappattempt_1376143950665_0004_000001
2013-08-10 14:22:32,440 INFO org.apache.hadoop.yarn.server.resourcemanager.amlauncher.AMLauncher: Setting up container Container: [ContainerId: container_1376143950665_0004_01_000001, NodeId: hadoop-221-4:43548, NodeHttpAddress: hadoop-221-4:8042, Resource: <memory:2048, vCores:1>, Priority: 0, State: NEW, Token: null, Status: container_id {, app_attempt_id {, application_id {, id: 4, cluster_timestamp: 1376143950665, }, attemptId: 1, }, id: 1, }, state: C_NEW, ] for AM appattempt_1376143950665_0004_000001
2013-08-10 14:22:32,440 INFO org.apache.hadoop.yarn.server.resourcemanager.amlauncher.AMLauncher: Command to launch container container_1376143950665_0004_01_000001 : $JAVA_HOME/bin/java -Dlog4j.configuration=container-log4j.properties -Dyarn.app.mapreduce.container.log.dir=<LOG_DIR> -Dyarn.app.mapreduce.container.log.filesize=0 -Dhadoop.root.logger=INFO,CLA  -Xmx1024m org.apache.hadoop.mapreduce.v2.app.MRAppMaster 1><LOG_DIR>/stdout 2><LOG_DIR>/stderr 
2013-08-10 14:22:32,457 INFO org.apache.hadoop.yarn.server.resourcemanager.amlauncher.AMLauncher: Done launching container Container: [ContainerId: container_1376143950665_0004_01_000001, NodeId: hadoop-221-4:43548, NodeHttpAddress: hadoop-221-4:8042, Resource: <memory:2048, vCores:1>, Priority: 0, State: NEW, Token: null, Status: container_id {, app_attempt_id {, application_id {, id: 4, cluster_timestamp: 1376143950665, }, attemptId: 1, }, id: 1, }, state: C_NEW, ] for AM appattempt_1376143950665_0004_000001
2013-08-10 14:22:32,457 INFO org.apache.hadoop.yarn.server.resourcemanager.rmapp.attempt.RMAppAttemptImpl: appattempt_1376143950665_0004_000001 State change from ALLOCATED to LAUNCHED
2013-08-10 14:22:33,430 INFO org.apache.hadoop.yarn.server.resourcemanager.rmcontainer.RMContainerImpl: container_1376143950665_0004_01_000001 Container Transitioned from ACQUIRED to RUNNING
2013-08-10 14:22:40,012 INFO org.apache.hadoop.yarn.server.resourcemanager.ApplicationMasterService: AM registration appattempt_1376143950665_0004_000001
2013-08-10 14:22:40,012 INFO org.apache.hadoop.yarn.server.resourcemanager.RMAuditLogger: USER=ubuntu	IP=192.168.100.37	OPERATION=Register App Master	TARGET=ApplicationMasterService	RESULT=SUCCESS	APPID=application_1376143950665_0004	APPATTEMPTID=appattempt_1376143950665_0004_000001
2013-08-10 14:22:40,013 INFO org.apache.hadoop.yarn.server.resourcemanager.rmapp.attempt.RMAppAttemptImpl: appattempt_1376143950665_0004_000001 State change from LAUNCHED to RUNNING
2013-08-10 14:22:40,013 INFO org.apache.hadoop.yarn.server.resourcemanager.rmapp.RMAppImpl: application_1376143950665_0004 State change from ACCEPTED to RUNNING
2013-08-10 14:22:41,227 INFO org.apache.hadoop.yarn.server.resourcemanager.rmcontainer.RMContainerImpl: container_1376143950665_0004_01_000002 Container Transitioned from NEW to ALLOCATED
2013-08-10 14:22:41,228 INFO org.apache.hadoop.yarn.server.resourcemanager.RMAuditLogger: USER=ubuntu	OPERATION=AM Allocated Container	TARGET=SchedulerApp	RESULT=SUCCESS	APPID=application_1376143950665_0004	CONTAINERID=container_1376143950665_0004_01_000002
2013-08-10 14:22:41,229 INFO org.apache.hadoop.yarn.server.resourcemanager.scheduler.common.fica.FiCaSchedulerNode: Assigned container container_1376143950665_0004_01_000002 of capacity <memory:1024, vCores:1> on host hadoop-221-5:53998, which currently has 1 containers, <memory:1024, vCores:1> used and <memory:7168, vCores:15> available
2013-08-10 14:22:41,230 INFO org.apache.hadoop.yarn.server.resourcemanager.scheduler.capacity.LeafQueue: assignedContainer application=application_1376143950665_0004 container=Container: [ContainerId: container_1376143950665_0004_01_000002, NodeId: hadoop-221-5:53998, NodeHttpAddress: hadoop-221-5:8042, Resource: <memory:1024, vCores:1>, Priority: 20, State: NEW, Token: null, Status: container_id {, app_attempt_id {, application_id {, id: 4, cluster_timestamp: 1376143950665, }, attemptId: 1, }, id: 2, }, state: C_NEW, ] containerId=container_1376143950665_0004_01_000002 queue=default: capacity=1.0, absoluteCapacity=1.0, usedResources=<memory:2048, vCores:1>usedCapacity=0.041666668, absoluteUsedCapacity=0.041666668, numApps=1, numContainers=1 usedCapacity=0.041666668 absoluteUsedCapacity=0.041666668 used=<memory:2048, vCores:1> cluster=<memory:49152, vCores:96>
2013-08-10 14:22:41,231 INFO org.apache.hadoop.yarn.server.resourcemanager.scheduler.capacity.ParentQueue: Re-sorting queues since queue: root.default stats: default: capacity=1.0, absoluteCapacity=1.0, usedResources=<memory:3072, vCores:2>usedCapacity=0.0625, absoluteUsedCapacity=0.0625, numApps=1, numContainers=2
2013-08-10 14:22:41,231 INFO org.apache.hadoop.yarn.server.resourcemanager.scheduler.capacity.ParentQueue: assignedContainer queue=root usedCapacity=0.0625 absoluteUsedCapacity=0.0625 used=<memory:3072, vCores:2> cluster=<memory:49152, vCores:96>
2013-08-10 14:22:41,243 INFO org.apache.hadoop.yarn.server.resourcemanager.rmcontainer.RMContainerImpl: container_1376143950665_0004_01_000003 Container Transitioned from NEW to ALLOCATED
2013-08-10 14:22:41,243 INFO org.apache.hadoop.yarn.server.resourcemanager.RMAuditLogger: USER=ubuntu	OPERATION=AM Allocated Container	TARGET=SchedulerApp	RESULT=SUCCESS	APPID=application_1376143950665_0004	CONTAINERID=container_1376143950665_0004_01_000003
2013-08-10 14:22:41,243 INFO org.apache.hadoop.yarn.server.resourcemanager.scheduler.common.fica.FiCaSchedulerNode: Assigned container container_1376143950665_0004_01_000003 of capacity <memory:1024, vCores:1> on host hadoop-221-3:48808, which currently has 1 containers, <memory:1024, vCores:1> used and <memory:7168, vCores:15> available
2013-08-10 14:22:41,244 INFO org.apache.hadoop.yarn.server.resourcemanager.scheduler.capacity.LeafQueue: assignedContainer application=application_1376143950665_0004 container=Container: [ContainerId: container_1376143950665_0004_01_000003, NodeId: hadoop-221-3:48808, NodeHttpAddress: hadoop-221-3:8042, Resource: <memory:1024, vCores:1>, Priority: 20, State: NEW, Token: null, Status: container_id {, app_attempt_id {, application_id {, id: 4, cluster_timestamp: 1376143950665, }, attemptId: 1, }, id: 3, }, state: C_NEW, ] containerId=container_1376143950665_0004_01_000003 queue=default: capacity=1.0, absoluteCapacity=1.0, usedResources=<memory:3072, vCores:2>usedCapacity=0.0625, absoluteUsedCapacity=0.0625, numApps=1, numContainers=2 usedCapacity=0.0625 absoluteUsedCapacity=0.0625 used=<memory:3072, vCores:2> cluster=<memory:49152, vCores:96>
2013-08-10 14:22:41,245 INFO org.apache.hadoop.yarn.server.resourcemanager.scheduler.capacity.ParentQueue: Re-sorting queues since queue: root.default stats: default: capacity=1.0, absoluteCapacity=1.0, usedResources=<memory:4096, vCores:3>usedCapacity=0.083333336, absoluteUsedCapacity=0.083333336, numApps=1, numContainers=3
2013-08-10 14:22:41,245 INFO org.apache.hadoop.yarn.server.resourcemanager.scheduler.capacity.ParentQueue: assignedContainer queue=root usedCapacity=0.083333336 absoluteUsedCapacity=0.083333336 used=<memory:4096, vCores:3> cluster=<memory:49152, vCores:96>
2013-08-10 14:22:42,079 INFO org.apache.hadoop.yarn.server.resourcemanager.rmcontainer.RMContainerImpl: container_1376143950665_0004_01_000002 Container Transitioned from ALLOCATED to ACQUIRED
2013-08-10 14:22:42,080 INFO org.apache.hadoop.yarn.server.resourcemanager.rmcontainer.RMContainerImpl: container_1376143950665_0004_01_000003 Container Transitioned from ALLOCATED to ACQUIRED
2013-08-10 14:22:43,111 INFO org.apache.hadoop.yarn.server.resourcemanager.scheduler.AppSchedulingInfo: checking for deactivate... 
2013-08-10 14:22:43,236 INFO org.apache.hadoop.yarn.server.resourcemanager.rmcontainer.RMContainerImpl: container_1376143950665_0004_01_000002 Container Transitioned from ACQUIRED to RUNNING
2013-08-10 14:22:43,266 INFO org.apache.hadoop.yarn.server.resourcemanager.rmcontainer.RMContainerImpl: container_1376143950665_0004_01_000003 Container Transitioned from ACQUIRED to RUNNING
2013-08-10 14:25:28,797 INFO org.apache.hadoop.yarn.server.resourcemanager.rmcontainer.RMContainerImpl: container_1376143950665_0004_01_000003 Container Transitioned from RUNNING to COMPLETED
2013-08-10 14:25:28,797 INFO org.apache.hadoop.yarn.server.resourcemanager.scheduler.common.fica.FiCaSchedulerApp: Completed container: container_1376143950665_0004_01_000003 in state: COMPLETED event:FINISHED
2013-08-10 14:25:28,797 INFO org.apache.hadoop.yarn.server.resourcemanager.RMAuditLogger: USER=ubuntu	OPERATION=AM Released Container	TARGET=SchedulerApp	RESULT=SUCCESS	APPID=application_1376143950665_0004	CONTAINERID=container_1376143950665_0004_01_000003
2013-08-10 14:25:28,798 INFO org.apache.hadoop.yarn.server.resourcemanager.scheduler.common.fica.FiCaSchedulerNode: Released container container_1376143950665_0004_01_000003 of capacity <memory:1024, vCores:1> on host hadoop-221-3:48808, which currently has 0 containers, <memory:0, vCores:0> used and <memory:8192, vCores:16> available, release resources=true
2013-08-10 14:25:28,798 INFO org.apache.hadoop.yarn.server.resourcemanager.scheduler.capacity.LeafQueue: default used=<memory:3072, vCores:2> numContainers=2 user=ubuntu user-resources=<memory:3072, vCores:2>
2013-08-10 14:25:28,799 INFO org.apache.hadoop.yarn.server.resourcemanager.scheduler.capacity.LeafQueue: completedContainer container=Container: [ContainerId: container_1376143950665_0004_01_000003, NodeId: hadoop-221-3:48808, NodeHttpAddress: hadoop-221-3:8042, Resource: <memory:1024, vCores:1>, Priority: 20, State: NEW, Token: null, Status: container_id {, app_attempt_id {, application_id {, id: 4, cluster_timestamp: 1376143950665, }, attemptId: 1, }, id: 3, }, state: C_COMPLETE, diagnostics: "Container killed by the ApplicationMaster.\n\n", exit_status: 143, ] resource=<memory:1024, vCores:1> queue=default: capacity=1.0, absoluteCapacity=1.0, usedResources=<memory:3072, vCores:2>usedCapacity=0.0625, absoluteUsedCapacity=0.0625, numApps=1, numContainers=2 usedCapacity=0.0625 absoluteUsedCapacity=0.0625 used=<memory:3072, vCores:2> cluster=<memory:49152, vCores:96>
2013-08-10 14:25:28,800 INFO org.apache.hadoop.yarn.server.resourcemanager.scheduler.capacity.ParentQueue: completedContainer queue=root usedCapacity=0.0625 absoluteUsedCapacity=0.0625 used=<memory:3072, vCores:2> cluster=<memory:49152, vCores:96>
2013-08-10 14:25:28,800 INFO org.apache.hadoop.yarn.server.resourcemanager.scheduler.capacity.CapacityScheduler: Application appattempt_1376143950665_0004_000001 released container container_1376143950665_0004_01_000003 on node: host: hadoop-221-3:48808 #containers=0 available=8192 used=0 with event: FINISHED
2013-08-10 14:25:29,613 INFO org.apache.hadoop.yarn.server.resourcemanager.rmcontainer.RMContainerImpl: container_1376143950665_0004_01_000002 Container Transitioned from RUNNING to COMPLETED
2013-08-10 14:25:29,613 INFO org.apache.hadoop.yarn.server.resourcemanager.scheduler.common.fica.FiCaSchedulerApp: Completed container: container_1376143950665_0004_01_000002 in state: COMPLETED event:FINISHED
2013-08-10 14:25:29,613 INFO org.apache.hadoop.yarn.server.resourcemanager.RMAuditLogger: USER=ubuntu	OPERATION=AM Released Container	TARGET=SchedulerApp	RESULT=SUCCESS	APPID=application_1376143950665_0004	CONTAINERID=container_1376143950665_0004_01_000002
2013-08-10 14:25:29,613 INFO org.apache.hadoop.yarn.server.resourcemanager.scheduler.common.fica.FiCaSchedulerNode: Released container container_1376143950665_0004_01_000002 of capacity <memory:1024, vCores:1> on host hadoop-221-5:53998, which currently has 0 containers, <memory:0, vCores:0> used and <memory:8192, vCores:16> available, release resources=true
2013-08-10 14:25:29,614 INFO org.apache.hadoop.yarn.server.resourcemanager.scheduler.capacity.LeafQueue: default used=<memory:2048, vCores:1> numContainers=1 user=ubuntu user-resources=<memory:2048, vCores:1>
2013-08-10 14:25:29,615 INFO org.apache.hadoop.yarn.server.resourcemanager.scheduler.capacity.LeafQueue: completedContainer container=Container: [ContainerId: container_1376143950665_0004_01_000002, NodeId: hadoop-221-5:53998, NodeHttpAddress: hadoop-221-5:8042, Resource: <memory:1024, vCores:1>, Priority: 20, State: NEW, Token: null, Status: container_id {, app_attempt_id {, application_id {, id: 4, cluster_timestamp: 1376143950665, }, attemptId: 1, }, id: 2, }, state: C_COMPLETE, diagnostics: "Container killed by the ApplicationMaster.\n\n", exit_status: 143, ] resource=<memory:1024, vCores:1> queue=default: capacity=1.0, absoluteCapacity=1.0, usedResources=<memory:2048, vCores:1>usedCapacity=0.041666668, absoluteUsedCapacity=0.041666668, numApps=1, numContainers=1 usedCapacity=0.041666668 absoluteUsedCapacity=0.041666668 used=<memory:2048, vCores:1> cluster=<memory:49152, vCores:96>
2013-08-10 14:25:29,615 INFO org.apache.hadoop.yarn.server.resourcemanager.scheduler.capacity.ParentQueue: completedContainer queue=root usedCapacity=0.041666668 absoluteUsedCapacity=0.041666668 used=<memory:2048, vCores:1> cluster=<memory:49152, vCores:96>
2013-08-10 14:25:29,615 INFO org.apache.hadoop.yarn.server.resourcemanager.scheduler.capacity.CapacityScheduler: Application appattempt_1376143950665_0004_000001 released container container_1376143950665_0004_01_000002 on node: host: hadoop-221-5:53998 #containers=0 available=8192 used=0 with event: FINISHED
2013-08-10 14:25:33,807 INFO org.apache.hadoop.yarn.server.resourcemanager.rmapp.attempt.RMAppAttemptImpl: appattempt_1376143950665_0004_000001 State change from RUNNING to FINISHING
2013-08-10 14:25:33,808 INFO org.apache.hadoop.yarn.server.resourcemanager.rmapp.RMAppImpl: application_1376143950665_0004 State change from RUNNING to FINISHING
2013-08-10 14:25:34,562 INFO org.apache.hadoop.yarn.server.resourcemanager.rmcontainer.RMContainerImpl: container_1376143950665_0004_01_000001 Container Transitioned from RUNNING to COMPLETED
2013-08-10 14:25:34,562 INFO org.apache.hadoop.yarn.server.resourcemanager.scheduler.common.fica.FiCaSchedulerApp: Completed container: container_1376143950665_0004_01_000001 in state: COMPLETED event:FINISHED
2013-08-10 14:25:34,563 INFO org.apache.hadoop.yarn.server.resourcemanager.RMAuditLogger: USER=ubuntu	OPERATION=AM Released Container	TARGET=SchedulerApp	RESULT=SUCCESS	APPID=application_1376143950665_0004	CONTAINERID=container_1376143950665_0004_01_000001
2013-08-10 14:25:34,563 INFO org.apache.hadoop.yarn.server.resourcemanager.scheduler.common.fica.FiCaSchedulerNode: Released container container_1376143950665_0004_01_000001 of capacity <memory:2048, vCores:1> on host hadoop-221-4:43548, which currently has 0 containers, <memory:0, vCores:0> used and <memory:8192, vCores:16> available, release resources=true
2013-08-10 14:25:34,563 INFO org.apache.hadoop.yarn.server.resourcemanager.scheduler.capacity.LeafQueue: default used=<memory:0, vCores:0> numContainers=0 user=ubuntu user-resources=<memory:0, vCores:0>
2013-08-10 14:25:34,563 INFO org.apache.hadoop.yarn.server.resourcemanager.scheduler.capacity.LeafQueue: completedContainer container=Container: [ContainerId: container_1376143950665_0004_01_000001, NodeId: hadoop-221-4:43548, NodeHttpAddress: hadoop-221-4:8042, Resource: <memory:2048, vCores:1>, Priority: 0, State: NEW, Token: null, Status: container_id {, app_attempt_id {, application_id {, id: 4, cluster_timestamp: 1376143950665, }, attemptId: 1, }, id: 1, }, state: C_COMPLETE, diagnostics: "", exit_status: 0, ] resource=<memory:2048, vCores:1> queue=default: capacity=1.0, absoluteCapacity=1.0, usedResources=<memory:0, vCores:0>usedCapacity=0.0, absoluteUsedCapacity=0.0, numApps=1, numContainers=0 usedCapacity=0.0 absoluteUsedCapacity=0.0 used=<memory:0, vCores:0> cluster=<memory:49152, vCores:96>
2013-08-10 14:25:34,564 INFO org.apache.hadoop.yarn.server.resourcemanager.scheduler.capacity.ParentQueue: completedContainer queue=root usedCapacity=0.0 absoluteUsedCapacity=0.0 used=<memory:0, vCores:0> cluster=<memory:49152, vCores:96>
2013-08-10 14:25:34,564 INFO org.apache.hadoop.yarn.server.resourcemanager.scheduler.capacity.CapacityScheduler: Application appattempt_1376143950665_0004_000001 released container container_1376143950665_0004_01_000001 on node: host: hadoop-221-4:43548 #containers=0 available=8192 used=0 with event: FINISHED
2013-08-10 14:25:34,564 INFO org.apache.hadoop.yarn.server.resourcemanager.rmapp.attempt.RMAppAttemptImpl: appattempt_1376143950665_0004_000001 State change from FINISHING to FINISHED
2013-08-10 14:25:34,564 INFO org.apache.hadoop.yarn.server.resourcemanager.rmapp.RMAppImpl: application_1376143950665_0004 State change from FINISHING to FINISHED
2013-08-10 14:25:34,564 INFO org.apache.hadoop.yarn.server.resourcemanager.scheduler.capacity.CapacityScheduler: Application appattempt_1376143950665_0004_000001 is done. finalState=FINISHED
2013-08-10 14:25:34,564 INFO org.apache.hadoop.yarn.server.resourcemanager.scheduler.AppSchedulingInfo: Application application_1376143950665_0004 requests cleared
2013-08-10 14:25:34,564 INFO org.apache.hadoop.yarn.server.resourcemanager.scheduler.capacity.LeafQueue: Application removed - appId: application_1376143950665_0004 user: ubuntu queue: default #user-pending-applications: 0 #user-active-applications: 0 #queue-pending-applications: 0 #queue-active-applications: 0
2013-08-10 14:25:34,564 INFO org.apache.hadoop.yarn.server.resourcemanager.scheduler.capacity.ParentQueue: Application removed - appId: application_1376143950665_0004 user: ubuntu leaf-queue of parent: root #applications: 0
2013-08-10 14:25:34,565 INFO org.apache.hadoop.yarn.server.resourcemanager.RMAuditLogger: USER=ubuntu	OPERATION=Application Finished - Succeeded	TARGET=RMAppManager	RESULT=SUCCESS	APPID=application_1376143950665_0004
2013-08-10 14:25:34,565 INFO org.apache.hadoop.yarn.server.resourcemanager.recovery.RMStateStore: Removing info for app: application_1376143950665_0004
2013-08-10 14:25:34,565 INFO org.apache.hadoop.yarn.server.resourcemanager.RMAppManager$ApplicationSummary: appId=application_1376143950665_0004,name=TeraGen,user=ubuntu,queue=default,state=FINISHED,trackingUrl=hadoop-221-1.novalocal:8088/proxy/application_1376143950665_0004/jobhistory/job/job_1376143950665_0004,appMasterHost=hadoop-221-4,startTime=1376144552271,finishTime=1376144733808
2013-08-10 14:25:34,566 INFO org.apache.hadoop.yarn.server.resourcemanager.amlauncher.AMLauncher: Cleaning master appattempt_1376143950665_0004_000001
2013-08-10 14:25:35,395 INFO org.apache.hadoop.yarn.server.resourcemanager.ClientRMService: Allocated new applicationId: 5
2013-08-10 14:25:37,352 INFO org.apache.hadoop.yarn.server.resourcemanager.ClientRMService: Storing Application with id application_1376143950665_0005
2013-08-10 14:25:37,352 INFO org.apache.hadoop.yarn.server.resourcemanager.recovery.RMStateStore: Storing info for app: application_1376143950665_0005
2013-08-10 14:25:37,353 INFO org.apache.hadoop.yarn.server.resourcemanager.ClientRMService: Application with id 5 submitted by user ubuntu
2013-08-10 14:25:37,353 INFO org.apache.hadoop.yarn.server.resourcemanager.RMAuditLogger: USER=ubuntu	IP=192.168.100.14	OPERATION=Submit Application Request	TARGET=ClientRMService	RESULT=SUCCESS	APPID=application_1376143950665_0005
2013-08-10 14:25:37,355 INFO org.apache.hadoop.yarn.server.resourcemanager.rmapp.RMAppImpl: application_1376143950665_0005 State change from NEW to SUBMITTED
2013-08-10 14:25:37,355 INFO org.apache.hadoop.yarn.server.resourcemanager.ApplicationMasterService: Registering appattempt_1376143950665_0005_000001
2013-08-10 14:25:37,355 INFO org.apache.hadoop.yarn.server.resourcemanager.rmapp.attempt.RMAppAttemptImpl: appattempt_1376143950665_0005_000001 State change from NEW to SUBMITTED
2013-08-10 14:25:37,356 INFO org.apache.hadoop.yarn.server.resourcemanager.scheduler.capacity.LeafQueue: Application application_1376143950665_0005 from user: ubuntu activated in queue: default
2013-08-10 14:25:37,356 INFO org.apache.hadoop.yarn.server.resourcemanager.scheduler.capacity.LeafQueue: Application added - appId: application_1376143950665_0005 user: org.apache.hadoop.yarn.server.resourcemanager.scheduler.capacity.LeafQueue$User@24eca8f6, leaf-queue: default #user-pending-applications: 0 #user-active-applications: 1 #queue-pending-applications: 0 #queue-active-applications: 1
2013-08-10 14:25:37,356 INFO org.apache.hadoop.yarn.server.resourcemanager.scheduler.capacity.ParentQueue: Application added - appId: application_1376143950665_0005 user: ubuntu leaf-queue of parent: root #applications: 1
2013-08-10 14:25:37,356 INFO org.apache.hadoop.yarn.server.resourcemanager.scheduler.capacity.CapacityScheduler: Application Submission: appattempt_1376143950665_0005_000001, user: ubuntu queue: default: capacity=1.0, absoluteCapacity=1.0, usedResources=<memory:0, vCores:0>usedCapacity=0.0, absoluteUsedCapacity=0.0, numApps=1, numContainers=0, currently active: 1
2013-08-10 14:25:37,357 INFO org.apache.hadoop.yarn.server.resourcemanager.rmapp.attempt.RMAppAttemptImpl: appattempt_1376143950665_0005_000001 State change from SUBMITTED to SCHEDULED
2013-08-10 14:25:37,357 INFO org.apache.hadoop.yarn.server.resourcemanager.rmapp.RMAppImpl: application_1376143950665_0005 State change from SUBMITTED to ACCEPTED
2013-08-10 14:25:37,576 INFO org.apache.hadoop.yarn.server.resourcemanager.rmcontainer.RMContainerImpl: container_1376143950665_0005_01_000001 Container Transitioned from NEW to ALLOCATED
2013-08-10 14:25:37,577 INFO org.apache.hadoop.yarn.server.resourcemanager.RMAuditLogger: USER=ubuntu	OPERATION=AM Allocated Container	TARGET=SchedulerApp	RESULT=SUCCESS	APPID=application_1376143950665_0005	CONTAINERID=container_1376143950665_0005_01_000001
2013-08-10 14:25:37,577 INFO org.apache.hadoop.yarn.server.resourcemanager.scheduler.common.fica.FiCaSchedulerNode: Assigned container container_1376143950665_0005_01_000001 of capacity <memory:2048, vCores:1> on host hadoop-221-4:43548, which currently has 1 containers, <memory:2048, vCores:1> used and <memory:6144, vCores:15> available
2013-08-10 14:25:37,578 INFO org.apache.hadoop.yarn.server.resourcemanager.scheduler.capacity.LeafQueue: assignedContainer application=application_1376143950665_0005 container=Container: [ContainerId: container_1376143950665_0005_01_000001, NodeId: hadoop-221-4:43548, NodeHttpAddress: hadoop-221-4:8042, Resource: <memory:2048, vCores:1>, Priority: 0, State: NEW, Token: null, Status: container_id {, app_attempt_id {, application_id {, id: 5, cluster_timestamp: 1376143950665, }, attemptId: 1, }, id: 1, }, state: C_NEW, ] containerId=container_1376143950665_0005_01_000001 queue=default: capacity=1.0, absoluteCapacity=1.0, usedResources=<memory:0, vCores:0>usedCapacity=0.0, absoluteUsedCapacity=0.0, numApps=1, numContainers=0 usedCapacity=0.0 absoluteUsedCapacity=0.0 used=<memory:0, vCores:0> cluster=<memory:49152, vCores:96>
2013-08-10 14:25:37,578 INFO org.apache.hadoop.yarn.server.resourcemanager.scheduler.capacity.ParentQueue: Re-sorting queues since queue: root.default stats: default: capacity=1.0, absoluteCapacity=1.0, usedResources=<memory:2048, vCores:1>usedCapacity=0.041666668, absoluteUsedCapacity=0.041666668, numApps=1, numContainers=1
2013-08-10 14:25:37,579 INFO org.apache.hadoop.yarn.server.resourcemanager.scheduler.capacity.ParentQueue: assignedContainer queue=root usedCapacity=0.041666668 absoluteUsedCapacity=0.041666668 used=<memory:2048, vCores:1> cluster=<memory:49152, vCores:96>
2013-08-10 14:25:37,580 INFO org.apache.hadoop.yarn.server.resourcemanager.rmcontainer.RMContainerImpl: container_1376143950665_0005_01_000001 Container Transitioned from ALLOCATED to ACQUIRED
2013-08-10 14:25:37,582 INFO org.apache.hadoop.yarn.server.resourcemanager.rmapp.attempt.RMAppAttemptImpl: Storing attempt: AppId: application_1376143950665_0005 AttemptId: appattempt_1376143950665_0005_000001 MasterContainer: Container: [ContainerId: container_1376143950665_0005_01_000001, NodeId: hadoop-221-4:43548, NodeHttpAddress: hadoop-221-4:8042, Resource: <memory:2048, vCores:1>, Priority: 0, State: NEW, Token: null, Status: container_id {, app_attempt_id {, application_id {, id: 5, cluster_timestamp: 1376143950665, }, attemptId: 1, }, id: 1, }, state: C_NEW, ]
2013-08-10 14:25:37,582 INFO org.apache.hadoop.yarn.server.resourcemanager.rmapp.attempt.RMAppAttemptImpl: appattempt_1376143950665_0005_000001 State change from SCHEDULED to ALLOCATED_SAVING
2013-08-10 14:25:37,582 INFO org.apache.hadoop.yarn.server.resourcemanager.recovery.RMStateStore: Storing info for attempt: appattempt_1376143950665_0005_000001
2013-08-10 14:25:37,583 INFO org.apache.hadoop.yarn.server.resourcemanager.rmapp.attempt.RMAppAttemptImpl: appattempt_1376143950665_0005_000001 State change from ALLOCATED_SAVING to ALLOCATED
2013-08-10 14:25:37,584 INFO org.apache.hadoop.yarn.server.resourcemanager.amlauncher.AMLauncher: Launching masterappattempt_1376143950665_0005_000001
2013-08-10 14:25:37,587 INFO org.apache.hadoop.yarn.server.resourcemanager.amlauncher.AMLauncher: Setting up container Container: [ContainerId: container_1376143950665_0005_01_000001, NodeId: hadoop-221-4:43548, NodeHttpAddress: hadoop-221-4:8042, Resource: <memory:2048, vCores:1>, Priority: 0, State: NEW, Token: null, Status: container_id {, app_attempt_id {, application_id {, id: 5, cluster_timestamp: 1376143950665, }, attemptId: 1, }, id: 1, }, state: C_NEW, ] for AM appattempt_1376143950665_0005_000001
2013-08-10 14:25:37,587 INFO org.apache.hadoop.yarn.server.resourcemanager.amlauncher.AMLauncher: Command to launch container container_1376143950665_0005_01_000001 : $JAVA_HOME/bin/java -Dlog4j.configuration=container-log4j.properties -Dyarn.app.mapreduce.container.log.dir=<LOG_DIR> -Dyarn.app.mapreduce.container.log.filesize=0 -Dhadoop.root.logger=INFO,CLA  -Xmx1024m org.apache.hadoop.mapreduce.v2.app.MRAppMaster 1><LOG_DIR>/stdout 2><LOG_DIR>/stderr 
2013-08-10 14:25:37,626 INFO org.apache.hadoop.yarn.server.resourcemanager.amlauncher.AMLauncher: Done launching container Container: [ContainerId: container_1376143950665_0005_01_000001, NodeId: hadoop-221-4:43548, NodeHttpAddress: hadoop-221-4:8042, Resource: <memory:2048, vCores:1>, Priority: 0, State: NEW, Token: null, Status: container_id {, app_attempt_id {, application_id {, id: 5, cluster_timestamp: 1376143950665, }, attemptId: 1, }, id: 1, }, state: C_NEW, ] for AM appattempt_1376143950665_0005_000001
2013-08-10 14:25:37,626 INFO org.apache.hadoop.yarn.server.resourcemanager.rmapp.attempt.RMAppAttemptImpl: appattempt_1376143950665_0005_000001 State change from ALLOCATED to LAUNCHED
2013-08-10 14:25:38,582 INFO org.apache.hadoop.yarn.server.resourcemanager.rmcontainer.RMContainerImpl: container_1376143950665_0005_01_000001 Container Transitioned from ACQUIRED to RUNNING
2013-08-10 14:25:42,226 INFO org.apache.hadoop.yarn.server.resourcemanager.ApplicationMasterService: AM registration appattempt_1376143950665_0005_000001
2013-08-10 14:25:42,227 INFO org.apache.hadoop.yarn.server.resourcemanager.RMAuditLogger: USER=ubuntu	IP=192.168.100.37	OPERATION=Register App Master	TARGET=ApplicationMasterService	RESULT=SUCCESS	APPID=application_1376143950665_0005	APPATTEMPTID=appattempt_1376143950665_0005_000001
2013-08-10 14:25:42,228 INFO org.apache.hadoop.yarn.server.resourcemanager.rmapp.attempt.RMAppAttemptImpl: appattempt_1376143950665_0005_000001 State change from LAUNCHED to RUNNING
2013-08-10 14:25:42,228 INFO org.apache.hadoop.yarn.server.resourcemanager.rmapp.RMAppImpl: application_1376143950665_0005 State change from ACCEPTED to RUNNING
2013-08-10 14:25:43,284 INFO org.apache.hadoop.yarn.server.resourcemanager.rmcontainer.RMContainerImpl: container_1376143950665_0005_01_000002 Container Transitioned from NEW to ALLOCATED
2013-08-10 14:25:43,284 INFO org.apache.hadoop.yarn.server.resourcemanager.RMAuditLogger: USER=ubuntu	OPERATION=AM Allocated Container	TARGET=SchedulerApp	RESULT=SUCCESS	APPID=application_1376143950665_0005	CONTAINERID=container_1376143950665_0005_01_000002
2013-08-10 14:25:43,284 INFO org.apache.hadoop.yarn.server.resourcemanager.scheduler.common.fica.FiCaSchedulerNode: Assigned container container_1376143950665_0005_01_000002 of capacity <memory:1024, vCores:1> on host hadoop-221-2:53277, which currently has 1 containers, <memory:1024, vCores:1> used and <memory:7168, vCores:15> available
2013-08-10 14:25:43,286 INFO org.apache.hadoop.yarn.server.resourcemanager.scheduler.capacity.LeafQueue: assignedContainer application=application_1376143950665_0005 container=Container: [ContainerId: container_1376143950665_0005_01_000002, NodeId: hadoop-221-2:53277, NodeHttpAddress: hadoop-221-2:8042, Resource: <memory:1024, vCores:1>, Priority: 20, State: NEW, Token: null, Status: container_id {, app_attempt_id {, application_id {, id: 5, cluster_timestamp: 1376143950665, }, attemptId: 1, }, id: 2, }, state: C_NEW, ] containerId=container_1376143950665_0005_01_000002 queue=default: capacity=1.0, absoluteCapacity=1.0, usedResources=<memory:2048, vCores:1>usedCapacity=0.041666668, absoluteUsedCapacity=0.041666668, numApps=1, numContainers=1 usedCapacity=0.041666668 absoluteUsedCapacity=0.041666668 used=<memory:2048, vCores:1> cluster=<memory:49152, vCores:96>
2013-08-10 14:25:43,286 INFO org.apache.hadoop.yarn.server.resourcemanager.scheduler.capacity.ParentQueue: Re-sorting queues since queue: root.default stats: default: capacity=1.0, absoluteCapacity=1.0, usedResources=<memory:3072, vCores:2>usedCapacity=0.0625, absoluteUsedCapacity=0.0625, numApps=1, numContainers=2
2013-08-10 14:25:43,286 INFO org.apache.hadoop.yarn.server.resourcemanager.scheduler.capacity.ParentQueue: assignedContainer queue=root usedCapacity=0.0625 absoluteUsedCapacity=0.0625 used=<memory:3072, vCores:2> cluster=<memory:49152, vCores:96>
2013-08-10 14:25:43,601 INFO org.apache.hadoop.yarn.server.resourcemanager.rmcontainer.RMContainerImpl: container_1376143950665_0005_01_000003 Container Transitioned from NEW to ALLOCATED
2013-08-10 14:25:43,601 INFO org.apache.hadoop.yarn.server.resourcemanager.RMAuditLogger: USER=ubuntu	OPERATION=AM Allocated Container	TARGET=SchedulerApp	RESULT=SUCCESS	APPID=application_1376143950665_0005	CONTAINERID=container_1376143950665_0005_01_000003
2013-08-10 14:25:43,601 INFO org.apache.hadoop.yarn.server.resourcemanager.scheduler.common.fica.FiCaSchedulerNode: Assigned container container_1376143950665_0005_01_000003 of capacity <memory:1024, vCores:1> on host hadoop-221-4:43548, which currently has 2 containers, <memory:3072, vCores:2> used and <memory:5120, vCores:14> available
2013-08-10 14:25:43,603 INFO org.apache.hadoop.yarn.server.resourcemanager.scheduler.capacity.LeafQueue: assignedContainer application=application_1376143950665_0005 container=Container: [ContainerId: container_1376143950665_0005_01_000003, NodeId: hadoop-221-4:43548, NodeHttpAddress: hadoop-221-4:8042, Resource: <memory:1024, vCores:1>, Priority: 20, State: NEW, Token: null, Status: container_id {, app_attempt_id {, application_id {, id: 5, cluster_timestamp: 1376143950665, }, attemptId: 1, }, id: 3, }, state: C_NEW, ] containerId=container_1376143950665_0005_01_000003 queue=default: capacity=1.0, absoluteCapacity=1.0, usedResources=<memory:3072, vCores:2>usedCapacity=0.0625, absoluteUsedCapacity=0.0625, numApps=1, numContainers=2 usedCapacity=0.0625 absoluteUsedCapacity=0.0625 used=<memory:3072, vCores:2> cluster=<memory:49152, vCores:96>
2013-08-10 14:25:43,603 INFO org.apache.hadoop.yarn.server.resourcemanager.scheduler.capacity.ParentQueue: Re-sorting queues since queue: root.default stats: default: capacity=1.0, absoluteCapacity=1.0, usedResources=<memory:4096, vCores:3>usedCapacity=0.083333336, absoluteUsedCapacity=0.083333336, numApps=1, numContainers=3
2013-08-10 14:25:43,603 INFO org.apache.hadoop.yarn.server.resourcemanager.scheduler.capacity.ParentQueue: assignedContainer queue=root usedCapacity=0.083333336 absoluteUsedCapacity=0.083333336 used=<memory:4096, vCores:3> cluster=<memory:49152, vCores:96>
2013-08-10 14:25:44,270 INFO org.apache.hadoop.yarn.server.resourcemanager.rmcontainer.RMContainerImpl: container_1376143950665_0005_01_000002 Container Transitioned from ALLOCATED to ACQUIRED
2013-08-10 14:25:44,273 INFO org.apache.hadoop.yarn.server.resourcemanager.rmcontainer.RMContainerImpl: container_1376143950665_0005_01_000003 Container Transitioned from ALLOCATED to ACQUIRED
2013-08-10 14:25:44,608 INFO org.apache.hadoop.yarn.server.resourcemanager.rmcontainer.RMContainerImpl: container_1376143950665_0005_01_000003 Container Transitioned from ACQUIRED to RUNNING
2013-08-10 14:25:45,292 INFO org.apache.hadoop.yarn.server.resourcemanager.rmcontainer.RMContainerImpl: container_1376143950665_0005_01_000002 Container Transitioned from ACQUIRED to RUNNING
2013-08-10 14:25:45,301 INFO org.apache.hadoop.yarn.server.resourcemanager.scheduler.AppSchedulingInfo: checking for deactivate... 
2013-08-10 14:28:16,062 INFO org.apache.hadoop.yarn.server.resourcemanager.rmcontainer.RMContainerImpl: container_1376143950665_0005_01_000003 Container Transitioned from RUNNING to COMPLETED
2013-08-10 14:28:16,063 INFO org.apache.hadoop.yarn.server.resourcemanager.scheduler.common.fica.FiCaSchedulerApp: Completed container: container_1376143950665_0005_01_000003 in state: COMPLETED event:FINISHED
2013-08-10 14:28:16,063 INFO org.apache.hadoop.yarn.server.resourcemanager.RMAuditLogger: USER=ubuntu	OPERATION=AM Released Container	TARGET=SchedulerApp	RESULT=SUCCESS	APPID=application_1376143950665_0005	CONTAINERID=container_1376143950665_0005_01_000003
2013-08-10 14:28:16,063 INFO org.apache.hadoop.yarn.server.resourcemanager.scheduler.common.fica.FiCaSchedulerNode: Released container container_1376143950665_0005_01_000003 of capacity <memory:1024, vCores:1> on host hadoop-221-4:43548, which currently has 1 containers, <memory:2048, vCores:1> used and <memory:6144, vCores:15> available, release resources=true
2013-08-10 14:28:16,063 INFO org.apache.hadoop.yarn.server.resourcemanager.scheduler.capacity.LeafQueue: default used=<memory:3072, vCores:2> numContainers=2 user=ubuntu user-resources=<memory:3072, vCores:2>
2013-08-10 14:28:16,065 INFO org.apache.hadoop.yarn.server.resourcemanager.scheduler.capacity.LeafQueue: completedContainer container=Container: [ContainerId: container_1376143950665_0005_01_000003, NodeId: hadoop-221-4:43548, NodeHttpAddress: hadoop-221-4:8042, Resource: <memory:1024, vCores:1>, Priority: 20, State: NEW, Token: null, Status: container_id {, app_attempt_id {, application_id {, id: 5, cluster_timestamp: 1376143950665, }, attemptId: 1, }, id: 3, }, state: C_COMPLETE, diagnostics: "Container killed by the ApplicationMaster.\n\n", exit_status: 143, ] resource=<memory:1024, vCores:1> queue=default: capacity=1.0, absoluteCapacity=1.0, usedResources=<memory:3072, vCores:2>usedCapacity=0.0625, absoluteUsedCapacity=0.0625, numApps=1, numContainers=2 usedCapacity=0.0625 absoluteUsedCapacity=0.0625 used=<memory:3072, vCores:2> cluster=<memory:49152, vCores:96>
2013-08-10 14:28:16,065 INFO org.apache.hadoop.yarn.server.resourcemanager.scheduler.capacity.ParentQueue: completedContainer queue=root usedCapacity=0.0625 absoluteUsedCapacity=0.0625 used=<memory:3072, vCores:2> cluster=<memory:49152, vCores:96>
2013-08-10 14:28:16,065 INFO org.apache.hadoop.yarn.server.resourcemanager.scheduler.capacity.CapacityScheduler: Application appattempt_1376143950665_0005_000001 released container container_1376143950665_0005_01_000003 on node: host: hadoop-221-4:43548 #containers=1 available=6144 used=2048 with event: FINISHED
2013-08-10 14:28:29,132 INFO org.apache.hadoop.yarn.server.resourcemanager.rmcontainer.RMContainerImpl: container_1376143950665_0005_01_000002 Container Transitioned from RUNNING to COMPLETED
2013-08-10 14:28:29,132 INFO org.apache.hadoop.yarn.server.resourcemanager.scheduler.common.fica.FiCaSchedulerApp: Completed container: container_1376143950665_0005_01_000002 in state: COMPLETED event:FINISHED
2013-08-10 14:28:29,133 INFO org.apache.hadoop.yarn.server.resourcemanager.RMAuditLogger: USER=ubuntu	OPERATION=AM Released Container	TARGET=SchedulerApp	RESULT=SUCCESS	APPID=application_1376143950665_0005	CONTAINERID=container_1376143950665_0005_01_000002
2013-08-10 14:28:29,133 INFO org.apache.hadoop.yarn.server.resourcemanager.scheduler.common.fica.FiCaSchedulerNode: Released container container_1376143950665_0005_01_000002 of capacity <memory:1024, vCores:1> on host hadoop-221-2:53277, which currently has 0 containers, <memory:0, vCores:0> used and <memory:8192, vCores:16> available, release resources=true
2013-08-10 14:28:29,134 INFO org.apache.hadoop.yarn.server.resourcemanager.scheduler.capacity.LeafQueue: default used=<memory:2048, vCores:1> numContainers=1 user=ubuntu user-resources=<memory:2048, vCores:1>
2013-08-10 14:28:29,135 INFO org.apache.hadoop.yarn.server.resourcemanager.scheduler.capacity.LeafQueue: completedContainer container=Container: [ContainerId: container_1376143950665_0005_01_000002, NodeId: hadoop-221-2:53277, NodeHttpAddress: hadoop-221-2:8042, Resource: <memory:1024, vCores:1>, Priority: 20, State: NEW, Token: null, Status: container_id {, app_attempt_id {, application_id {, id: 5, cluster_timestamp: 1376143950665, }, attemptId: 1, }, id: 2, }, state: C_COMPLETE, diagnostics: "Container killed by the ApplicationMaster.\n\n", exit_status: 143, ] resource=<memory:1024, vCores:1> queue=default: capacity=1.0, absoluteCapacity=1.0, usedResources=<memory:2048, vCores:1>usedCapacity=0.041666668, absoluteUsedCapacity=0.041666668, numApps=1, numContainers=1 usedCapacity=0.041666668 absoluteUsedCapacity=0.041666668 used=<memory:2048, vCores:1> cluster=<memory:49152, vCores:96>
2013-08-10 14:28:29,135 INFO org.apache.hadoop.yarn.server.resourcemanager.scheduler.capacity.ParentQueue: completedContainer queue=root usedCapacity=0.041666668 absoluteUsedCapacity=0.041666668 used=<memory:2048, vCores:1> cluster=<memory:49152, vCores:96>
2013-08-10 14:28:29,136 INFO org.apache.hadoop.yarn.server.resourcemanager.scheduler.capacity.CapacityScheduler: Application appattempt_1376143950665_0005_000001 released container container_1376143950665_0005_01_000002 on node: host: hadoop-221-2:53277 #containers=0 available=8192 used=0 with event: FINISHED
2013-08-10 14:28:33,276 INFO org.apache.hadoop.yarn.server.resourcemanager.rmapp.attempt.RMAppAttemptImpl: appattempt_1376143950665_0005_000001 State change from RUNNING to FINISHING
2013-08-10 14:28:33,277 INFO org.apache.hadoop.yarn.server.resourcemanager.rmapp.RMAppImpl: application_1376143950665_0005 State change from RUNNING to FINISHING
2013-08-10 14:28:34,155 INFO org.apache.hadoop.yarn.server.resourcemanager.rmcontainer.RMContainerImpl: container_1376143950665_0005_01_000001 Container Transitioned from RUNNING to COMPLETED
2013-08-10 14:28:34,155 INFO org.apache.hadoop.yarn.server.resourcemanager.scheduler.common.fica.FiCaSchedulerApp: Completed container: container_1376143950665_0005_01_000001 in state: COMPLETED event:FINISHED
2013-08-10 14:28:34,155 INFO org.apache.hadoop.yarn.server.resourcemanager.rmapp.attempt.RMAppAttemptImpl: appattempt_1376143950665_0005_000001 State change from FINISHING to FINISHED
2013-08-10 14:28:34,155 INFO org.apache.hadoop.yarn.server.resourcemanager.RMAuditLogger: USER=ubuntu	OPERATION=AM Released Container	TARGET=SchedulerApp	RESULT=SUCCESS	APPID=application_1376143950665_0005	CONTAINERID=container_1376143950665_0005_01_000001
2013-08-10 14:28:34,155 INFO org.apache.hadoop.yarn.server.resourcemanager.rmapp.RMAppImpl: application_1376143950665_0005 State change from FINISHING to FINISHED
2013-08-10 14:28:34,155 INFO org.apache.hadoop.yarn.server.resourcemanager.scheduler.common.fica.FiCaSchedulerNode: Released container container_1376143950665_0005_01_000001 of capacity <memory:2048, vCores:1> on host hadoop-221-4:43548, which currently has 0 containers, <memory:0, vCores:0> used and <memory:8192, vCores:16> available, release resources=true
2013-08-10 14:28:34,155 INFO org.apache.hadoop.yarn.server.resourcemanager.scheduler.capacity.LeafQueue: default used=<memory:0, vCores:0> numContainers=0 user=ubuntu user-resources=<memory:0, vCores:0>
2013-08-10 14:28:34,156 INFO org.apache.hadoop.yarn.server.resourcemanager.RMAuditLogger: USER=ubuntu	OPERATION=Application Finished - Succeeded	TARGET=RMAppManager	RESULT=SUCCESS	APPID=application_1376143950665_0005
2013-08-10 14:28:34,156 INFO org.apache.hadoop.yarn.server.resourcemanager.RMAppManager$ApplicationSummary: appId=application_1376143950665_0005,name=TeraGen,user=ubuntu,queue=default,state=FINISHED,trackingUrl=hadoop-221-1.novalocal:8088/proxy/application_1376143950665_0005/jobhistory/job/job_1376143950665_0005,appMasterHost=hadoop-221-4,startTime=1376144737352,finishTime=1376144913277
2013-08-10 14:28:34,156 INFO org.apache.hadoop.yarn.server.resourcemanager.recovery.RMStateStore: Removing info for app: application_1376143950665_0005
2013-08-10 14:28:34,157 INFO org.apache.hadoop.yarn.server.resourcemanager.amlauncher.AMLauncher: Cleaning master appattempt_1376143950665_0005_000001
2013-08-10 14:28:34,157 INFO org.apache.hadoop.yarn.server.resourcemanager.scheduler.capacity.LeafQueue: completedContainer container=Container: [ContainerId: container_1376143950665_0005_01_000001, NodeId: hadoop-221-4:43548, NodeHttpAddress: hadoop-221-4:8042, Resource: <memory:2048, vCores:1>, Priority: 0, State: NEW, Token: null, Status: container_id {, app_attempt_id {, application_id {, id: 5, cluster_timestamp: 1376143950665, }, attemptId: 1, }, id: 1, }, state: C_COMPLETE, diagnostics: "", exit_status: 0, ] resource=<memory:2048, vCores:1> queue=default: capacity=1.0, absoluteCapacity=1.0, usedResources=<memory:0, vCores:0>usedCapacity=0.0, absoluteUsedCapacity=0.0, numApps=1, numContainers=0 usedCapacity=0.0 absoluteUsedCapacity=0.0 used=<memory:0, vCores:0> cluster=<memory:49152, vCores:96>
2013-08-10 14:28:34,157 INFO org.apache.hadoop.yarn.server.resourcemanager.scheduler.capacity.ParentQueue: completedContainer queue=root usedCapacity=0.0 absoluteUsedCapacity=0.0 used=<memory:0, vCores:0> cluster=<memory:49152, vCores:96>
2013-08-10 14:28:34,157 INFO org.apache.hadoop.yarn.server.resourcemanager.scheduler.capacity.CapacityScheduler: Application appattempt_1376143950665_0005_000001 released container container_1376143950665_0005_01_000001 on node: host: hadoop-221-4:43548 #containers=0 available=8192 used=0 with event: FINISHED
2013-08-10 14:28:34,157 INFO org.apache.hadoop.yarn.server.resourcemanager.scheduler.capacity.CapacityScheduler: Application appattempt_1376143950665_0005_000001 is done. finalState=FINISHED
2013-08-10 14:28:34,158 INFO org.apache.hadoop.yarn.server.resourcemanager.scheduler.AppSchedulingInfo: Application application_1376143950665_0005 requests cleared
2013-08-10 14:28:34,158 INFO org.apache.hadoop.yarn.server.resourcemanager.scheduler.capacity.LeafQueue: Application removed - appId: application_1376143950665_0005 user: ubuntu queue: default #user-pending-applications: 0 #user-active-applications: 0 #queue-pending-applications: 0 #queue-active-applications: 0
2013-08-10 14:28:34,158 INFO org.apache.hadoop.yarn.server.resourcemanager.scheduler.capacity.ParentQueue: Application removed - appId: application_1376143950665_0005 user: ubuntu leaf-queue of parent: root #applications: 0
2013-08-10 14:28:57,777 INFO org.apache.hadoop.yarn.server.resourcemanager.ClientRMService: Allocated new applicationId: 6
2013-08-10 14:28:58,097 INFO org.apache.hadoop.yarn.server.resourcemanager.ClientRMService: Allocated new applicationId: 7
2013-08-10 14:28:58,262 INFO org.apache.hadoop.yarn.server.resourcemanager.ClientRMService: Allocated new applicationId: 8
2013-08-10 14:28:58,617 INFO org.apache.hadoop.yarn.server.resourcemanager.ClientRMService: Allocated new applicationId: 9
2013-08-10 14:28:58,978 INFO org.apache.hadoop.yarn.server.resourcemanager.ClientRMService: Allocated new applicationId: 10
2013-08-10 14:28:59,756 INFO org.apache.hadoop.yarn.server.resourcemanager.ClientRMService: Storing Application with id application_1376143950665_0006
2013-08-10 14:28:59,756 INFO org.apache.hadoop.yarn.server.resourcemanager.recovery.RMStateStore: Storing info for app: application_1376143950665_0006
2013-08-10 14:28:59,756 INFO org.apache.hadoop.yarn.server.resourcemanager.ClientRMService: Application with id 6 submitted by user ubuntu
2013-08-10 14:28:59,756 INFO org.apache.hadoop.yarn.server.resourcemanager.RMAuditLogger: USER=ubuntu	IP=192.168.100.14	OPERATION=Submit Application Request	TARGET=ClientRMService	RESULT=SUCCESS	APPID=application_1376143950665_0006
2013-08-10 14:28:59,757 INFO org.apache.hadoop.yarn.server.resourcemanager.rmapp.RMAppImpl: application_1376143950665_0006 State change from NEW to SUBMITTED
2013-08-10 14:28:59,757 INFO org.apache.hadoop.yarn.server.resourcemanager.ApplicationMasterService: Registering appattempt_1376143950665_0006_000001
2013-08-10 14:28:59,757 INFO org.apache.hadoop.yarn.server.resourcemanager.rmapp.attempt.RMAppAttemptImpl: appattempt_1376143950665_0006_000001 State change from NEW to SUBMITTED
2013-08-10 14:28:59,757 INFO org.apache.hadoop.yarn.server.resourcemanager.scheduler.capacity.LeafQueue: Application application_1376143950665_0006 from user: ubuntu activated in queue: default
2013-08-10 14:28:59,757 INFO org.apache.hadoop.yarn.server.resourcemanager.scheduler.capacity.LeafQueue: Application added - appId: application_1376143950665_0006 user: org.apache.hadoop.yarn.server.resourcemanager.scheduler.capacity.LeafQueue$User@5a6a4fa0, leaf-queue: default #user-pending-applications: 0 #user-active-applications: 1 #queue-pending-applications: 0 #queue-active-applications: 1
2013-08-10 14:28:59,757 INFO org.apache.hadoop.yarn.server.resourcemanager.scheduler.capacity.ParentQueue: Application added - appId: application_1376143950665_0006 user: ubuntu leaf-queue of parent: root #applications: 1
2013-08-10 14:28:59,757 INFO org.apache.hadoop.yarn.server.resourcemanager.scheduler.capacity.CapacityScheduler: Application Submission: appattempt_1376143950665_0006_000001, user: ubuntu queue: default: capacity=1.0, absoluteCapacity=1.0, usedResources=<memory:0, vCores:0>usedCapacity=0.0, absoluteUsedCapacity=0.0, numApps=1, numContainers=0, currently active: 1
2013-08-10 14:28:59,758 INFO org.apache.hadoop.yarn.server.resourcemanager.rmapp.attempt.RMAppAttemptImpl: appattempt_1376143950665_0006_000001 State change from SUBMITTED to SCHEDULED
2013-08-10 14:28:59,758 INFO org.apache.hadoop.yarn.server.resourcemanager.rmapp.RMAppImpl: application_1376143950665_0006 State change from SUBMITTED to ACCEPTED
2013-08-10 14:28:59,866 INFO org.apache.hadoop.yarn.server.resourcemanager.rmcontainer.RMContainerImpl: container_1376143950665_0006_01_000001 Container Transitioned from NEW to ALLOCATED
2013-08-10 14:28:59,866 INFO org.apache.hadoop.yarn.server.resourcemanager.RMAuditLogger: USER=ubuntu	OPERATION=AM Allocated Container	TARGET=SchedulerApp	RESULT=SUCCESS	APPID=application_1376143950665_0006	CONTAINERID=container_1376143950665_0006_01_000001
2013-08-10 14:28:59,866 INFO org.apache.hadoop.yarn.server.resourcemanager.scheduler.common.fica.FiCaSchedulerNode: Assigned container container_1376143950665_0006_01_000001 of capacity <memory:2048, vCores:1> on host hadoop-221-7:43558, which currently has 1 containers, <memory:2048, vCores:1> used and <memory:6144, vCores:15> available
2013-08-10 14:28:59,866 INFO org.apache.hadoop.yarn.server.resourcemanager.scheduler.capacity.LeafQueue: assignedContainer application=application_1376143950665_0006 container=Container: [ContainerId: container_1376143950665_0006_01_000001, NodeId: hadoop-221-7:43558, NodeHttpAddress: hadoop-221-7:8042, Resource: <memory:2048, vCores:1>, Priority: 0, State: NEW, Token: null, Status: container_id {, app_attempt_id {, application_id {, id: 6, cluster_timestamp: 1376143950665, }, attemptId: 1, }, id: 1, }, state: C_NEW, ] containerId=container_1376143950665_0006_01_000001 queue=default: capacity=1.0, absoluteCapacity=1.0, usedResources=<memory:0, vCores:0>usedCapacity=0.0, absoluteUsedCapacity=0.0, numApps=1, numContainers=0 usedCapacity=0.0 absoluteUsedCapacity=0.0 used=<memory:0, vCores:0> cluster=<memory:49152, vCores:96>
2013-08-10 14:28:59,867 INFO org.apache.hadoop.yarn.server.resourcemanager.scheduler.capacity.ParentQueue: Re-sorting queues since queue: root.default stats: default: capacity=1.0, absoluteCapacity=1.0, usedResources=<memory:2048, vCores:1>usedCapacity=0.041666668, absoluteUsedCapacity=0.041666668, numApps=1, numContainers=1
2013-08-10 14:28:59,867 INFO org.apache.hadoop.yarn.server.resourcemanager.scheduler.capacity.ParentQueue: assignedContainer queue=root usedCapacity=0.041666668 absoluteUsedCapacity=0.041666668 used=<memory:2048, vCores:1> cluster=<memory:49152, vCores:96>
2013-08-10 14:28:59,867 INFO org.apache.hadoop.yarn.server.resourcemanager.rmcontainer.RMContainerImpl: container_1376143950665_0006_01_000001 Container Transitioned from ALLOCATED to ACQUIRED
2013-08-10 14:28:59,868 INFO org.apache.hadoop.yarn.server.resourcemanager.rmapp.attempt.RMAppAttemptImpl: Storing attempt: AppId: application_1376143950665_0006 AttemptId: appattempt_1376143950665_0006_000001 MasterContainer: Container: [ContainerId: container_1376143950665_0006_01_000001, NodeId: hadoop-221-7:43558, NodeHttpAddress: hadoop-221-7:8042, Resource: <memory:2048, vCores:1>, Priority: 0, State: NEW, Token: null, Status: container_id {, app_attempt_id {, application_id {, id: 6, cluster_timestamp: 1376143950665, }, attemptId: 1, }, id: 1, }, state: C_NEW, ]
2013-08-10 14:28:59,868 INFO org.apache.hadoop.yarn.server.resourcemanager.rmapp.attempt.RMAppAttemptImpl: appattempt_1376143950665_0006_000001 State change from SCHEDULED to ALLOCATED_SAVING
2013-08-10 14:28:59,868 INFO org.apache.hadoop.yarn.server.resourcemanager.recovery.RMStateStore: Storing info for attempt: appattempt_1376143950665_0006_000001
2013-08-10 14:28:59,879 INFO org.apache.hadoop.yarn.server.resourcemanager.rmapp.attempt.RMAppAttemptImpl: appattempt_1376143950665_0006_000001 State change from ALLOCATED_SAVING to ALLOCATED
2013-08-10 14:28:59,880 INFO org.apache.hadoop.yarn.server.resourcemanager.amlauncher.AMLauncher: Launching masterappattempt_1376143950665_0006_000001
2013-08-10 14:28:59,881 INFO org.apache.hadoop.yarn.server.resourcemanager.amlauncher.AMLauncher: Setting up container Container: [ContainerId: container_1376143950665_0006_01_000001, NodeId: hadoop-221-7:43558, NodeHttpAddress: hadoop-221-7:8042, Resource: <memory:2048, vCores:1>, Priority: 0, State: NEW, Token: null, Status: container_id {, app_attempt_id {, application_id {, id: 6, cluster_timestamp: 1376143950665, }, attemptId: 1, }, id: 1, }, state: C_NEW, ] for AM appattempt_1376143950665_0006_000001
2013-08-10 14:28:59,881 INFO org.apache.hadoop.yarn.server.resourcemanager.amlauncher.AMLauncher: Command to launch container container_1376143950665_0006_01_000001 : $JAVA_HOME/bin/java -Dlog4j.configuration=container-log4j.properties -Dyarn.app.mapreduce.container.log.dir=<LOG_DIR> -Dyarn.app.mapreduce.container.log.filesize=0 -Dhadoop.root.logger=INFO,CLA  -Xmx1024m org.apache.hadoop.mapreduce.v2.app.MRAppMaster 1><LOG_DIR>/stdout 2><LOG_DIR>/stderr 
2013-08-10 14:28:59,897 INFO org.apache.hadoop.yarn.server.resourcemanager.ClientRMService: Storing Application with id application_1376143950665_0007
2013-08-10 14:28:59,897 INFO org.apache.hadoop.yarn.server.resourcemanager.recovery.RMStateStore: Storing info for app: application_1376143950665_0007
2013-08-10 14:28:59,897 INFO org.apache.hadoop.yarn.server.resourcemanager.ClientRMService: Application with id 7 submitted by user ubuntu
2013-08-10 14:28:59,897 INFO org.apache.hadoop.yarn.server.resourcemanager.RMAuditLogger: USER=ubuntu	IP=192.168.100.14	OPERATION=Submit Application Request	TARGET=ClientRMService	RESULT=SUCCESS	APPID=application_1376143950665_0007
2013-08-10 14:28:59,908 INFO org.apache.hadoop.yarn.server.resourcemanager.rmapp.RMAppImpl: application_1376143950665_0007 State change from NEW to SUBMITTED
2013-08-10 14:28:59,909 INFO org.apache.hadoop.yarn.server.resourcemanager.ApplicationMasterService: Registering appattempt_1376143950665_0007_000001
2013-08-10 14:28:59,909 INFO org.apache.hadoop.yarn.server.resourcemanager.rmapp.attempt.RMAppAttemptImpl: appattempt_1376143950665_0007_000001 State change from NEW to SUBMITTED
2013-08-10 14:28:59,909 INFO org.apache.hadoop.yarn.server.resourcemanager.scheduler.capacity.LeafQueue: Application application_1376143950665_0007 from user: ubuntu activated in queue: default
2013-08-10 14:28:59,909 INFO org.apache.hadoop.yarn.server.resourcemanager.scheduler.capacity.LeafQueue: Application added - appId: application_1376143950665_0007 user: org.apache.hadoop.yarn.server.resourcemanager.scheduler.capacity.LeafQueue$User@5a6a4fa0, leaf-queue: default #user-pending-applications: 0 #user-active-applications: 2 #queue-pending-applications: 0 #queue-active-applications: 2
2013-08-10 14:28:59,909 INFO org.apache.hadoop.yarn.server.resourcemanager.scheduler.capacity.ParentQueue: Application added - appId: application_1376143950665_0007 user: ubuntu leaf-queue of parent: root #applications: 2
2013-08-10 14:28:59,910 INFO org.apache.hadoop.yarn.server.resourcemanager.amlauncher.AMLauncher: Done launching container Container: [ContainerId: container_1376143950665_0006_01_000001, NodeId: hadoop-221-7:43558, NodeHttpAddress: hadoop-221-7:8042, Resource: <memory:2048, vCores:1>, Priority: 0, State: NEW, Token: null, Status: container_id {, app_attempt_id {, application_id {, id: 6, cluster_timestamp: 1376143950665, }, attemptId: 1, }, id: 1, }, state: C_NEW, ] for AM appattempt_1376143950665_0006_000001
2013-08-10 14:28:59,910 INFO org.apache.hadoop.yarn.server.resourcemanager.scheduler.capacity.CapacityScheduler: Application Submission: appattempt_1376143950665_0007_000001, user: ubuntu queue: default: capacity=1.0, absoluteCapacity=1.0, usedResources=<memory:2048, vCores:1>usedCapacity=0.041666668, absoluteUsedCapacity=0.041666668, numApps=2, numContainers=1, currently active: 2
2013-08-10 14:28:59,911 INFO org.apache.hadoop.yarn.server.resourcemanager.rmapp.attempt.RMAppAttemptImpl: appattempt_1376143950665_0006_000001 State change from ALLOCATED to LAUNCHED
2013-08-10 14:28:59,911 INFO org.apache.hadoop.yarn.server.resourcemanager.rmapp.attempt.RMAppAttemptImpl: appattempt_1376143950665_0007_000001 State change from SUBMITTED to SCHEDULED
2013-08-10 14:28:59,911 INFO org.apache.hadoop.yarn.server.resourcemanager.rmapp.RMAppImpl: application_1376143950665_0007 State change from SUBMITTED to ACCEPTED
2013-08-10 14:28:59,986 INFO org.apache.hadoop.yarn.server.resourcemanager.ClientRMService: Storing Application with id application_1376143950665_0008
2013-08-10 14:28:59,986 INFO org.apache.hadoop.yarn.server.resourcemanager.recovery.RMStateStore: Storing info for app: application_1376143950665_0008
2013-08-10 14:28:59,986 INFO org.apache.hadoop.yarn.server.resourcemanager.ClientRMService: Application with id 8 submitted by user ubuntu
2013-08-10 14:28:59,987 INFO org.apache.hadoop.yarn.server.resourcemanager.RMAuditLogger: USER=ubuntu	IP=192.168.100.14	OPERATION=Submit Application Request	TARGET=ClientRMService	RESULT=SUCCESS	APPID=application_1376143950665_0008
2013-08-10 14:28:59,988 INFO org.apache.hadoop.yarn.server.resourcemanager.rmapp.RMAppImpl: application_1376143950665_0008 State change from NEW to SUBMITTED
2013-08-10 14:28:59,988 INFO org.apache.hadoop.yarn.server.resourcemanager.ApplicationMasterService: Registering appattempt_1376143950665_0008_000001
2013-08-10 14:28:59,988 INFO org.apache.hadoop.yarn.server.resourcemanager.rmapp.attempt.RMAppAttemptImpl: appattempt_1376143950665_0008_000001 State change from NEW to SUBMITTED
2013-08-10 14:28:59,991 INFO org.apache.hadoop.yarn.server.resourcemanager.scheduler.capacity.LeafQueue: Application application_1376143950665_0008 from user: ubuntu activated in queue: default
2013-08-10 14:28:59,991 INFO org.apache.hadoop.yarn.server.resourcemanager.scheduler.capacity.LeafQueue: Application added - appId: application_1376143950665_0008 user: org.apache.hadoop.yarn.server.resourcemanager.scheduler.capacity.LeafQueue$User@5a6a4fa0, leaf-queue: default #user-pending-applications: 0 #user-active-applications: 3 #queue-pending-applications: 0 #queue-active-applications: 3
2013-08-10 14:28:59,991 INFO org.apache.hadoop.yarn.server.resourcemanager.scheduler.capacity.ParentQueue: Application added - appId: application_1376143950665_0008 user: ubuntu leaf-queue of parent: root #applications: 3
2013-08-10 14:28:59,991 INFO org.apache.hadoop.yarn.server.resourcemanager.scheduler.capacity.CapacityScheduler: Application Submission: appattempt_1376143950665_0008_000001, user: ubuntu queue: default: capacity=1.0, absoluteCapacity=1.0, usedResources=<memory:2048, vCores:1>usedCapacity=0.041666668, absoluteUsedCapacity=0.041666668, numApps=3, numContainers=1, currently active: 3
2013-08-10 14:28:59,997 INFO org.apache.hadoop.yarn.server.resourcemanager.rmapp.attempt.RMAppAttemptImpl: appattempt_1376143950665_0008_000001 State change from SUBMITTED to SCHEDULED
2013-08-10 14:28:59,997 INFO org.apache.hadoop.yarn.server.resourcemanager.rmapp.RMAppImpl: application_1376143950665_0008 State change from SUBMITTED to ACCEPTED
2013-08-10 14:29:00,107 INFO org.apache.hadoop.yarn.server.resourcemanager.ClientRMService: Storing Application with id application_1376143950665_0009
2013-08-10 14:29:00,107 INFO org.apache.hadoop.yarn.server.resourcemanager.recovery.RMStateStore: Storing info for app: application_1376143950665_0009
2013-08-10 14:29:00,107 INFO org.apache.hadoop.yarn.server.resourcemanager.ClientRMService: Application with id 9 submitted by user ubuntu
2013-08-10 14:29:00,108 INFO org.apache.hadoop.yarn.server.resourcemanager.RMAuditLogger: USER=ubuntu	IP=192.168.100.14	OPERATION=Submit Application Request	TARGET=ClientRMService	RESULT=SUCCESS	APPID=application_1376143950665_0009
2013-08-10 14:29:00,108 INFO org.apache.hadoop.yarn.server.resourcemanager.rmapp.RMAppImpl: application_1376143950665_0009 State change from NEW to SUBMITTED
2013-08-10 14:29:00,108 INFO org.apache.hadoop.yarn.server.resourcemanager.ApplicationMasterService: Registering appattempt_1376143950665_0009_000001
2013-08-10 14:29:00,108 INFO org.apache.hadoop.yarn.server.resourcemanager.rmapp.attempt.RMAppAttemptImpl: appattempt_1376143950665_0009_000001 State change from NEW to SUBMITTED
2013-08-10 14:29:00,110 INFO org.apache.hadoop.yarn.server.resourcemanager.scheduler.capacity.LeafQueue: Application application_1376143950665_0009 from user: ubuntu activated in queue: default
2013-08-10 14:29:00,110 INFO org.apache.hadoop.yarn.server.resourcemanager.scheduler.capacity.LeafQueue: Application added - appId: application_1376143950665_0009 user: org.apache.hadoop.yarn.server.resourcemanager.scheduler.capacity.LeafQueue$User@5a6a4fa0, leaf-queue: default #user-pending-applications: 0 #user-active-applications: 4 #queue-pending-applications: 0 #queue-active-applications: 4
2013-08-10 14:29:00,110 INFO org.apache.hadoop.yarn.server.resourcemanager.scheduler.capacity.ParentQueue: Application added - appId: application_1376143950665_0009 user: ubuntu leaf-queue of parent: root #applications: 4
2013-08-10 14:29:00,110 INFO org.apache.hadoop.yarn.server.resourcemanager.scheduler.capacity.CapacityScheduler: Application Submission: appattempt_1376143950665_0009_000001, user: ubuntu queue: default: capacity=1.0, absoluteCapacity=1.0, usedResources=<memory:2048, vCores:1>usedCapacity=0.041666668, absoluteUsedCapacity=0.041666668, numApps=4, numContainers=1, currently active: 4
2013-08-10 14:29:00,110 INFO org.apache.hadoop.yarn.server.resourcemanager.rmapp.attempt.RMAppAttemptImpl: appattempt_1376143950665_0009_000001 State change from SUBMITTED to SCHEDULED
2013-08-10 14:29:00,110 INFO org.apache.hadoop.yarn.server.resourcemanager.rmapp.RMAppImpl: application_1376143950665_0009 State change from SUBMITTED to ACCEPTED
2013-08-10 14:29:00,241 INFO org.apache.hadoop.yarn.server.resourcemanager.rmcontainer.RMContainerImpl: container_1376143950665_0007_01_000001 Container Transitioned from NEW to ALLOCATED
2013-08-10 14:29:00,241 INFO org.apache.hadoop.yarn.server.resourcemanager.RMAuditLogger: USER=ubuntu	OPERATION=AM Allocated Container	TARGET=SchedulerApp	RESULT=SUCCESS	APPID=application_1376143950665_0007	CONTAINERID=container_1376143950665_0007_01_000001
2013-08-10 14:29:00,241 INFO org.apache.hadoop.yarn.server.resourcemanager.scheduler.common.fica.FiCaSchedulerNode: Assigned container container_1376143950665_0007_01_000001 of capacity <memory:2048, vCores:1> on host hadoop-221-2:53277, which currently has 1 containers, <memory:2048, vCores:1> used and <memory:6144, vCores:15> available
2013-08-10 14:29:00,242 INFO org.apache.hadoop.yarn.server.resourcemanager.scheduler.capacity.LeafQueue: assignedContainer application=application_1376143950665_0007 container=Container: [ContainerId: container_1376143950665_0007_01_000001, NodeId: hadoop-221-2:53277, NodeHttpAddress: hadoop-221-2:8042, Resource: <memory:2048, vCores:1>, Priority: 0, State: NEW, Token: null, Status: container_id {, app_attempt_id {, application_id {, id: 7, cluster_timestamp: 1376143950665, }, attemptId: 1, }, id: 1, }, state: C_NEW, ] containerId=container_1376143950665_0007_01_000001 queue=default: capacity=1.0, absoluteCapacity=1.0, usedResources=<memory:2048, vCores:1>usedCapacity=0.041666668, absoluteUsedCapacity=0.041666668, numApps=4, numContainers=1 usedCapacity=0.041666668 absoluteUsedCapacity=0.041666668 used=<memory:2048, vCores:1> cluster=<memory:49152, vCores:96>
2013-08-10 14:29:00,242 INFO org.apache.hadoop.yarn.server.resourcemanager.scheduler.capacity.ParentQueue: Re-sorting queues since queue: root.default stats: default: capacity=1.0, absoluteCapacity=1.0, usedResources=<memory:4096, vCores:2>usedCapacity=0.083333336, absoluteUsedCapacity=0.083333336, numApps=4, numContainers=2
2013-08-10 14:29:00,242 INFO org.apache.hadoop.yarn.server.resourcemanager.scheduler.capacity.ParentQueue: assignedContainer queue=root usedCapacity=0.083333336 absoluteUsedCapacity=0.083333336 used=<memory:4096, vCores:2> cluster=<memory:49152, vCores:96>
2013-08-10 14:29:00,243 INFO org.apache.hadoop.yarn.server.resourcemanager.rmcontainer.RMContainerImpl: container_1376143950665_0007_01_000001 Container Transitioned from ALLOCATED to ACQUIRED
2013-08-10 14:29:00,243 INFO org.apache.hadoop.yarn.server.resourcemanager.rmapp.attempt.RMAppAttemptImpl: Storing attempt: AppId: application_1376143950665_0007 AttemptId: appattempt_1376143950665_0007_000001 MasterContainer: Container: [ContainerId: container_1376143950665_0007_01_000001, NodeId: hadoop-221-2:53277, NodeHttpAddress: hadoop-221-2:8042, Resource: <memory:2048, vCores:1>, Priority: 0, State: NEW, Token: null, Status: container_id {, app_attempt_id {, application_id {, id: 7, cluster_timestamp: 1376143950665, }, attemptId: 1, }, id: 1, }, state: C_NEW, ]
2013-08-10 14:29:00,243 INFO org.apache.hadoop.yarn.server.resourcemanager.rmapp.attempt.RMAppAttemptImpl: appattempt_1376143950665_0007_000001 State change from SCHEDULED to ALLOCATED_SAVING
2013-08-10 14:29:00,244 INFO org.apache.hadoop.yarn.server.resourcemanager.recovery.RMStateStore: Storing info for attempt: appattempt_1376143950665_0007_000001
2013-08-10 14:29:00,244 INFO org.apache.hadoop.yarn.server.resourcemanager.rmapp.attempt.RMAppAttemptImpl: appattempt_1376143950665_0007_000001 State change from ALLOCATED_SAVING to ALLOCATED
2013-08-10 14:29:00,244 INFO org.apache.hadoop.yarn.server.resourcemanager.amlauncher.AMLauncher: Launching masterappattempt_1376143950665_0007_000001
2013-08-10 14:29:00,246 INFO org.apache.hadoop.yarn.server.resourcemanager.amlauncher.AMLauncher: Setting up container Container: [ContainerId: container_1376143950665_0007_01_000001, NodeId: hadoop-221-2:53277, NodeHttpAddress: hadoop-221-2:8042, Resource: <memory:2048, vCores:1>, Priority: 0, State: NEW, Token: null, Status: container_id {, app_attempt_id {, application_id {, id: 7, cluster_timestamp: 1376143950665, }, attemptId: 1, }, id: 1, }, state: C_NEW, ] for AM appattempt_1376143950665_0007_000001
2013-08-10 14:29:00,246 INFO org.apache.hadoop.yarn.server.resourcemanager.amlauncher.AMLauncher: Command to launch container container_1376143950665_0007_01_000001 : $JAVA_HOME/bin/java -Dlog4j.configuration=container-log4j.properties -Dyarn.app.mapreduce.container.log.dir=<LOG_DIR> -Dyarn.app.mapreduce.container.log.filesize=0 -Dhadoop.root.logger=INFO,CLA  -Xmx1024m org.apache.hadoop.mapreduce.v2.app.MRAppMaster 1><LOG_DIR>/stdout 2><LOG_DIR>/stderr 
2013-08-10 14:29:00,255 INFO org.apache.hadoop.yarn.server.resourcemanager.rmcontainer.RMContainerImpl: container_1376143950665_0008_01_000001 Container Transitioned from NEW to ALLOCATED
2013-08-10 14:29:00,255 INFO org.apache.hadoop.yarn.server.resourcemanager.RMAuditLogger: USER=ubuntu	OPERATION=AM Allocated Container	TARGET=SchedulerApp	RESULT=SUCCESS	APPID=application_1376143950665_0008	CONTAINERID=container_1376143950665_0008_01_000001
2013-08-10 14:29:00,255 INFO org.apache.hadoop.yarn.server.resourcemanager.scheduler.common.fica.FiCaSchedulerNode: Assigned container container_1376143950665_0008_01_000001 of capacity <memory:2048, vCores:1> on host hadoop-221-4:43548, which currently has 1 containers, <memory:2048, vCores:1> used and <memory:6144, vCores:15> available
2013-08-10 14:29:00,256 INFO org.apache.hadoop.yarn.server.resourcemanager.scheduler.capacity.LeafQueue: assignedContainer application=application_1376143950665_0008 container=Container: [ContainerId: container_1376143950665_0008_01_000001, NodeId: hadoop-221-4:43548, NodeHttpAddress: hadoop-221-4:8042, Resource: <memory:2048, vCores:1>, Priority: 0, State: NEW, Token: null, Status: container_id {, app_attempt_id {, application_id {, id: 8, cluster_timestamp: 1376143950665, }, attemptId: 1, }, id: 1, }, state: C_NEW, ] containerId=container_1376143950665_0008_01_000001 queue=default: capacity=1.0, absoluteCapacity=1.0, usedResources=<memory:4096, vCores:2>usedCapacity=0.083333336, absoluteUsedCapacity=0.083333336, numApps=4, numContainers=2 usedCapacity=0.083333336 absoluteUsedCapacity=0.083333336 used=<memory:4096, vCores:2> cluster=<memory:49152, vCores:96>
2013-08-10 14:29:00,257 INFO org.apache.hadoop.yarn.server.resourcemanager.scheduler.capacity.ParentQueue: Re-sorting queues since queue: root.default stats: default: capacity=1.0, absoluteCapacity=1.0, usedResources=<memory:6144, vCores:3>usedCapacity=0.125, absoluteUsedCapacity=0.125, numApps=4, numContainers=3
2013-08-10 14:29:00,257 INFO org.apache.hadoop.yarn.server.resourcemanager.scheduler.capacity.ParentQueue: assignedContainer queue=root usedCapacity=0.125 absoluteUsedCapacity=0.125 used=<memory:6144, vCores:3> cluster=<memory:49152, vCores:96>
2013-08-10 14:29:00,260 INFO org.apache.hadoop.yarn.server.resourcemanager.rmcontainer.RMContainerImpl: container_1376143950665_0008_01_000001 Container Transitioned from ALLOCATED to ACQUIRED
2013-08-10 14:29:00,260 INFO org.apache.hadoop.yarn.server.resourcemanager.rmapp.attempt.RMAppAttemptImpl: Storing attempt: AppId: application_1376143950665_0008 AttemptId: appattempt_1376143950665_0008_000001 MasterContainer: Container: [ContainerId: container_1376143950665_0008_01_000001, NodeId: hadoop-221-4:43548, NodeHttpAddress: hadoop-221-4:8042, Resource: <memory:2048, vCores:1>, Priority: 0, State: NEW, Token: null, Status: container_id {, app_attempt_id {, application_id {, id: 8, cluster_timestamp: 1376143950665, }, attemptId: 1, }, id: 1, }, state: C_NEW, ]
2013-08-10 14:29:00,261 INFO org.apache.hadoop.yarn.server.resourcemanager.amlauncher.AMLauncher: Done launching container Container: [ContainerId: container_1376143950665_0007_01_000001, NodeId: hadoop-221-2:53277, NodeHttpAddress: hadoop-221-2:8042, Resource: <memory:2048, vCores:1>, Priority: 0, State: NEW, Token: null, Status: container_id {, app_attempt_id {, application_id {, id: 7, cluster_timestamp: 1376143950665, }, attemptId: 1, }, id: 1, }, state: C_NEW, ] for AM appattempt_1376143950665_0007_000001
2013-08-10 14:29:00,261 INFO org.apache.hadoop.yarn.server.resourcemanager.recovery.RMStateStore: Storing info for attempt: appattempt_1376143950665_0008_000001
2013-08-10 14:29:00,261 INFO org.apache.hadoop.yarn.server.resourcemanager.rmapp.attempt.RMAppAttemptImpl: appattempt_1376143950665_0008_000001 State change from SCHEDULED to ALLOCATED_SAVING
2013-08-10 14:29:00,261 INFO org.apache.hadoop.yarn.server.resourcemanager.rmapp.attempt.RMAppAttemptImpl: appattempt_1376143950665_0007_000001 State change from ALLOCATED to LAUNCHED
2013-08-10 14:29:00,261 INFO org.apache.hadoop.yarn.server.resourcemanager.rmapp.attempt.RMAppAttemptImpl: appattempt_1376143950665_0008_000001 State change from ALLOCATED_SAVING to ALLOCATED
2013-08-10 14:29:00,262 INFO org.apache.hadoop.yarn.server.resourcemanager.amlauncher.AMLauncher: Launching masterappattempt_1376143950665_0008_000001
2013-08-10 14:29:00,263 INFO org.apache.hadoop.yarn.server.resourcemanager.amlauncher.AMLauncher: Setting up container Container: [ContainerId: container_1376143950665_0008_01_000001, NodeId: hadoop-221-4:43548, NodeHttpAddress: hadoop-221-4:8042, Resource: <memory:2048, vCores:1>, Priority: 0, State: NEW, Token: null, Status: container_id {, app_attempt_id {, application_id {, id: 8, cluster_timestamp: 1376143950665, }, attemptId: 1, }, id: 1, }, state: C_NEW, ] for AM appattempt_1376143950665_0008_000001
2013-08-10 14:29:00,263 INFO org.apache.hadoop.yarn.server.resourcemanager.amlauncher.AMLauncher: Command to launch container container_1376143950665_0008_01_000001 : $JAVA_HOME/bin/java -Dlog4j.configuration=container-log4j.properties -Dyarn.app.mapreduce.container.log.dir=<LOG_DIR> -Dyarn.app.mapreduce.container.log.filesize=0 -Dhadoop.root.logger=INFO,CLA  -Xmx1024m org.apache.hadoop.mapreduce.v2.app.MRAppMaster 1><LOG_DIR>/stdout 2><LOG_DIR>/stderr 
2013-08-10 14:29:00,274 INFO org.apache.hadoop.yarn.server.resourcemanager.amlauncher.AMLauncher: Done launching container Container: [ContainerId: container_1376143950665_0008_01_000001, NodeId: hadoop-221-4:43548, NodeHttpAddress: hadoop-221-4:8042, Resource: <memory:2048, vCores:1>, Priority: 0, State: NEW, Token: null, Status: container_id {, app_attempt_id {, application_id {, id: 8, cluster_timestamp: 1376143950665, }, attemptId: 1, }, id: 1, }, state: C_NEW, ] for AM appattempt_1376143950665_0008_000001
2013-08-10 14:29:00,275 INFO org.apache.hadoop.yarn.server.resourcemanager.rmapp.attempt.RMAppAttemptImpl: appattempt_1376143950665_0008_000001 State change from ALLOCATED to LAUNCHED
2013-08-10 14:29:00,457 INFO org.apache.hadoop.yarn.server.resourcemanager.ClientRMService: Storing Application with id application_1376143950665_0010
2013-08-10 14:29:00,457 INFO org.apache.hadoop.yarn.server.resourcemanager.rmapp.RMAppImpl: application_1376143950665_0010 State change from NEW to SUBMITTED
2013-08-10 14:29:00,457 INFO org.apache.hadoop.yarn.server.resourcemanager.recovery.RMStateStore: Storing info for app: application_1376143950665_0010
2013-08-10 14:29:00,458 INFO org.apache.hadoop.yarn.server.resourcemanager.ApplicationMasterService: Registering appattempt_1376143950665_0010_000001
2013-08-10 14:29:00,458 INFO org.apache.hadoop.yarn.server.resourcemanager.ClientRMService: Application with id 10 submitted by user ubuntu
2013-08-10 14:29:00,458 INFO org.apache.hadoop.yarn.server.resourcemanager.rmapp.attempt.RMAppAttemptImpl: appattempt_1376143950665_0010_000001 State change from NEW to SUBMITTED
2013-08-10 14:29:00,458 INFO org.apache.hadoop.yarn.server.resourcemanager.RMAuditLogger: USER=ubuntu	IP=192.168.100.14	OPERATION=Submit Application Request	TARGET=ClientRMService	RESULT=SUCCESS	APPID=application_1376143950665_0010
2013-08-10 14:29:00,458 INFO org.apache.hadoop.yarn.server.resourcemanager.scheduler.capacity.LeafQueue: Application application_1376143950665_0010 from user: ubuntu activated in queue: default
2013-08-10 14:29:00,458 INFO org.apache.hadoop.yarn.server.resourcemanager.scheduler.capacity.LeafQueue: Application added - appId: application_1376143950665_0010 user: org.apache.hadoop.yarn.server.resourcemanager.scheduler.capacity.LeafQueue$User@5a6a4fa0, leaf-queue: default #user-pending-applications: 0 #user-active-applications: 5 #queue-pending-applications: 0 #queue-active-applications: 5
2013-08-10 14:29:00,459 INFO org.apache.hadoop.yarn.server.resourcemanager.scheduler.capacity.ParentQueue: Application added - appId: application_1376143950665_0010 user: ubuntu leaf-queue of parent: root #applications: 5
2013-08-10 14:29:00,459 INFO org.apache.hadoop.yarn.server.resourcemanager.scheduler.capacity.CapacityScheduler: Application Submission: appattempt_1376143950665_0010_000001, user: ubuntu queue: default: capacity=1.0, absoluteCapacity=1.0, usedResources=<memory:6144, vCores:3>usedCapacity=0.125, absoluteUsedCapacity=0.125, numApps=5, numContainers=3, currently active: 5
2013-08-10 14:29:00,459 INFO org.apache.hadoop.yarn.server.resourcemanager.rmapp.attempt.RMAppAttemptImpl: appattempt_1376143950665_0010_000001 State change from SUBMITTED to SCHEDULED
2013-08-10 14:29:00,459 INFO org.apache.hadoop.yarn.server.resourcemanager.rmapp.RMAppImpl: application_1376143950665_0010 State change from SUBMITTED to ACCEPTED
2013-08-10 14:29:00,496 INFO org.apache.hadoop.yarn.server.resourcemanager.rmcontainer.RMContainerImpl: container_1376143950665_0009_01_000001 Container Transitioned from NEW to ALLOCATED
2013-08-10 14:29:00,497 INFO org.apache.hadoop.yarn.server.resourcemanager.RMAuditLogger: USER=ubuntu	OPERATION=AM Allocated Container	TARGET=SchedulerApp	RESULT=SUCCESS	APPID=application_1376143950665_0009	CONTAINERID=container_1376143950665_0009_01_000001
2013-08-10 14:29:00,497 INFO org.apache.hadoop.yarn.server.resourcemanager.scheduler.common.fica.FiCaSchedulerNode: Assigned container container_1376143950665_0009_01_000001 of capacity <memory:2048, vCores:1> on host hadoop-221-5:53998, which currently has 1 containers, <memory:2048, vCores:1> used and <memory:6144, vCores:15> available
2013-08-10 14:29:00,498 INFO org.apache.hadoop.yarn.server.resourcemanager.scheduler.capacity.LeafQueue: assignedContainer application=application_1376143950665_0009 container=Container: [ContainerId: container_1376143950665_0009_01_000001, NodeId: hadoop-221-5:53998, NodeHttpAddress: hadoop-221-5:8042, Resource: <memory:2048, vCores:1>, Priority: 0, State: NEW, Token: null, Status: container_id {, app_attempt_id {, application_id {, id: 9, cluster_timestamp: 1376143950665, }, attemptId: 1, }, id: 1, }, state: C_NEW, ] containerId=container_1376143950665_0009_01_000001 queue=default: capacity=1.0, absoluteCapacity=1.0, usedResources=<memory:6144, vCores:3>usedCapacity=0.125, absoluteUsedCapacity=0.125, numApps=5, numContainers=3 usedCapacity=0.125 absoluteUsedCapacity=0.125 used=<memory:6144, vCores:3> cluster=<memory:49152, vCores:96>
2013-08-10 14:29:00,498 INFO org.apache.hadoop.yarn.server.resourcemanager.scheduler.capacity.ParentQueue: Re-sorting queues since queue: root.default stats: default: capacity=1.0, absoluteCapacity=1.0, usedResources=<memory:8192, vCores:4>usedCapacity=0.16666667, absoluteUsedCapacity=0.16666667, numApps=5, numContainers=4
2013-08-10 14:29:00,498 INFO org.apache.hadoop.yarn.server.resourcemanager.scheduler.capacity.ParentQueue: assignedContainer queue=root usedCapacity=0.16666667 absoluteUsedCapacity=0.16666667 used=<memory:8192, vCores:4> cluster=<memory:49152, vCores:96>
2013-08-10 14:29:00,499 INFO org.apache.hadoop.yarn.server.resourcemanager.rmcontainer.RMContainerImpl: container_1376143950665_0009_01_000001 Container Transitioned from ALLOCATED to ACQUIRED
2013-08-10 14:29:00,500 INFO org.apache.hadoop.yarn.server.resourcemanager.rmapp.attempt.RMAppAttemptImpl: Storing attempt: AppId: application_1376143950665_0009 AttemptId: appattempt_1376143950665_0009_000001 MasterContainer: Container: [ContainerId: container_1376143950665_0009_01_000001, NodeId: hadoop-221-5:53998, NodeHttpAddress: hadoop-221-5:8042, Resource: <memory:2048, vCores:1>, Priority: 0, State: NEW, Token: null, Status: container_id {, app_attempt_id {, application_id {, id: 9, cluster_timestamp: 1376143950665, }, attemptId: 1, }, id: 1, }, state: C_NEW, ]
2013-08-10 14:29:00,501 INFO org.apache.hadoop.yarn.server.resourcemanager.recovery.RMStateStore: Storing info for attempt: appattempt_1376143950665_0009_000001
2013-08-10 14:29:00,501 INFO org.apache.hadoop.yarn.server.resourcemanager.rmapp.attempt.RMAppAttemptImpl: appattempt_1376143950665_0009_000001 State change from SCHEDULED to ALLOCATED_SAVING
2013-08-10 14:29:00,501 INFO org.apache.hadoop.yarn.server.resourcemanager.rmapp.attempt.RMAppAttemptImpl: appattempt_1376143950665_0009_000001 State change from ALLOCATED_SAVING to ALLOCATED
2013-08-10 14:29:00,501 INFO org.apache.hadoop.yarn.server.resourcemanager.amlauncher.AMLauncher: Launching masterappattempt_1376143950665_0009_000001
2013-08-10 14:29:00,503 INFO org.apache.hadoop.yarn.server.resourcemanager.amlauncher.AMLauncher: Setting up container Container: [ContainerId: container_1376143950665_0009_01_000001, NodeId: hadoop-221-5:53998, NodeHttpAddress: hadoop-221-5:8042, Resource: <memory:2048, vCores:1>, Priority: 0, State: NEW, Token: null, Status: container_id {, app_attempt_id {, application_id {, id: 9, cluster_timestamp: 1376143950665, }, attemptId: 1, }, id: 1, }, state: C_NEW, ] for AM appattempt_1376143950665_0009_000001
2013-08-10 14:29:00,503 INFO org.apache.hadoop.yarn.server.resourcemanager.amlauncher.AMLauncher: Command to launch container container_1376143950665_0009_01_000001 : $JAVA_HOME/bin/java -Dlog4j.configuration=container-log4j.properties -Dyarn.app.mapreduce.container.log.dir=<LOG_DIR> -Dyarn.app.mapreduce.container.log.filesize=0 -Dhadoop.root.logger=INFO,CLA  -Xmx1024m org.apache.hadoop.mapreduce.v2.app.MRAppMaster 1><LOG_DIR>/stdout 2><LOG_DIR>/stderr 
2013-08-10 14:29:00,514 INFO org.apache.hadoop.yarn.server.resourcemanager.amlauncher.AMLauncher: Done launching container Container: [ContainerId: container_1376143950665_0009_01_000001, NodeId: hadoop-221-5:53998, NodeHttpAddress: hadoop-221-5:8042, Resource: <memory:2048, vCores:1>, Priority: 0, State: NEW, Token: null, Status: container_id {, app_attempt_id {, application_id {, id: 9, cluster_timestamp: 1376143950665, }, attemptId: 1, }, id: 1, }, state: C_NEW, ] for AM appattempt_1376143950665_0009_000001
2013-08-10 14:29:00,514 INFO org.apache.hadoop.yarn.server.resourcemanager.rmapp.attempt.RMAppAttemptImpl: appattempt_1376143950665_0009_000001 State change from ALLOCATED to LAUNCHED
2013-08-10 14:29:00,537 INFO org.apache.hadoop.yarn.server.resourcemanager.rmcontainer.RMContainerImpl: container_1376143950665_0010_01_000001 Container Transitioned from NEW to ALLOCATED
2013-08-10 14:29:00,538 INFO org.apache.hadoop.yarn.server.resourcemanager.RMAuditLogger: USER=ubuntu	OPERATION=AM Allocated Container	TARGET=SchedulerApp	RESULT=SUCCESS	APPID=application_1376143950665_0010	CONTAINERID=container_1376143950665_0010_01_000001
2013-08-10 14:29:00,538 INFO org.apache.hadoop.yarn.server.resourcemanager.scheduler.common.fica.FiCaSchedulerNode: Assigned container container_1376143950665_0010_01_000001 of capacity <memory:2048, vCores:1> on host hadoop-221-6:51695, which currently has 1 containers, <memory:2048, vCores:1> used and <memory:6144, vCores:15> available
2013-08-10 14:29:00,539 INFO org.apache.hadoop.yarn.server.resourcemanager.scheduler.capacity.LeafQueue: assignedContainer application=application_1376143950665_0010 container=Container: [ContainerId: container_1376143950665_0010_01_000001, NodeId: hadoop-221-6:51695, NodeHttpAddress: hadoop-221-6:8042, Resource: <memory:2048, vCores:1>, Priority: 0, State: NEW, Token: null, Status: container_id {, app_attempt_id {, application_id {, id: 10, cluster_timestamp: 1376143950665, }, attemptId: 1, }, id: 1, }, state: C_NEW, ] containerId=container_1376143950665_0010_01_000001 queue=default: capacity=1.0, absoluteCapacity=1.0, usedResources=<memory:8192, vCores:4>usedCapacity=0.16666667, absoluteUsedCapacity=0.16666667, numApps=5, numContainers=4 usedCapacity=0.16666667 absoluteUsedCapacity=0.16666667 used=<memory:8192, vCores:4> cluster=<memory:49152, vCores:96>
2013-08-10 14:29:00,540 INFO org.apache.hadoop.yarn.server.resourcemanager.scheduler.capacity.ParentQueue: Re-sorting queues since queue: root.default stats: default: capacity=1.0, absoluteCapacity=1.0, usedResources=<memory:10240, vCores:5>usedCapacity=0.20833333, absoluteUsedCapacity=0.20833333, numApps=5, numContainers=5
2013-08-10 14:29:00,540 INFO org.apache.hadoop.yarn.server.resourcemanager.scheduler.capacity.ParentQueue: assignedContainer queue=root usedCapacity=0.20833333 absoluteUsedCapacity=0.20833333 used=<memory:10240, vCores:5> cluster=<memory:49152, vCores:96>
2013-08-10 14:29:00,540 INFO org.apache.hadoop.yarn.server.resourcemanager.rmcontainer.RMContainerImpl: container_1376143950665_0010_01_000001 Container Transitioned from ALLOCATED to ACQUIRED
2013-08-10 14:29:00,541 INFO org.apache.hadoop.yarn.server.resourcemanager.rmapp.attempt.RMAppAttemptImpl: Storing attempt: AppId: application_1376143950665_0010 AttemptId: appattempt_1376143950665_0010_000001 MasterContainer: Container: [ContainerId: container_1376143950665_0010_01_000001, NodeId: hadoop-221-6:51695, NodeHttpAddress: hadoop-221-6:8042, Resource: <memory:2048, vCores:1>, Priority: 0, State: NEW, Token: null, Status: container_id {, app_attempt_id {, application_id {, id: 10, cluster_timestamp: 1376143950665, }, attemptId: 1, }, id: 1, }, state: C_NEW, ]
2013-08-10 14:29:00,542 INFO org.apache.hadoop.yarn.server.resourcemanager.recovery.RMStateStore: Storing info for attempt: appattempt_1376143950665_0010_000001
2013-08-10 14:29:00,542 INFO org.apache.hadoop.yarn.server.resourcemanager.rmapp.attempt.RMAppAttemptImpl: appattempt_1376143950665_0010_000001 State change from SCHEDULED to ALLOCATED_SAVING
2013-08-10 14:29:00,542 INFO org.apache.hadoop.yarn.server.resourcemanager.rmapp.attempt.RMAppAttemptImpl: appattempt_1376143950665_0010_000001 State change from ALLOCATED_SAVING to ALLOCATED
2013-08-10 14:29:00,542 INFO org.apache.hadoop.yarn.server.resourcemanager.amlauncher.AMLauncher: Launching masterappattempt_1376143950665_0010_000001
2013-08-10 14:29:00,544 INFO org.apache.hadoop.yarn.server.resourcemanager.amlauncher.AMLauncher: Setting up container Container: [ContainerId: container_1376143950665_0010_01_000001, NodeId: hadoop-221-6:51695, NodeHttpAddress: hadoop-221-6:8042, Resource: <memory:2048, vCores:1>, Priority: 0, State: NEW, Token: null, Status: container_id {, app_attempt_id {, application_id {, id: 10, cluster_timestamp: 1376143950665, }, attemptId: 1, }, id: 1, }, state: C_NEW, ] for AM appattempt_1376143950665_0010_000001
2013-08-10 14:29:00,544 INFO org.apache.hadoop.yarn.server.resourcemanager.amlauncher.AMLauncher: Command to launch container container_1376143950665_0010_01_000001 : $JAVA_HOME/bin/java -Dlog4j.configuration=container-log4j.properties -Dyarn.app.mapreduce.container.log.dir=<LOG_DIR> -Dyarn.app.mapreduce.container.log.filesize=0 -Dhadoop.root.logger=INFO,CLA  -Xmx1024m org.apache.hadoop.mapreduce.v2.app.MRAppMaster 1><LOG_DIR>/stdout 2><LOG_DIR>/stderr 
2013-08-10 14:29:00,556 INFO org.apache.hadoop.yarn.server.resourcemanager.amlauncher.AMLauncher: Done launching container Container: [ContainerId: container_1376143950665_0010_01_000001, NodeId: hadoop-221-6:51695, NodeHttpAddress: hadoop-221-6:8042, Resource: <memory:2048, vCores:1>, Priority: 0, State: NEW, Token: null, Status: container_id {, app_attempt_id {, application_id {, id: 10, cluster_timestamp: 1376143950665, }, attemptId: 1, }, id: 1, }, state: C_NEW, ] for AM appattempt_1376143950665_0010_000001
2013-08-10 14:29:00,556 INFO org.apache.hadoop.yarn.server.resourcemanager.rmapp.attempt.RMAppAttemptImpl: appattempt_1376143950665_0010_000001 State change from ALLOCATED to LAUNCHED
2013-08-10 14:29:00,870 INFO org.apache.hadoop.yarn.server.resourcemanager.rmcontainer.RMContainerImpl: container_1376143950665_0006_01_000001 Container Transitioned from ACQUIRED to RUNNING
2013-08-10 14:29:01,246 INFO org.apache.hadoop.yarn.server.resourcemanager.rmcontainer.RMContainerImpl: container_1376143950665_0007_01_000001 Container Transitioned from ACQUIRED to RUNNING
2013-08-10 14:29:01,261 INFO org.apache.hadoop.yarn.server.resourcemanager.rmcontainer.RMContainerImpl: container_1376143950665_0008_01_000001 Container Transitioned from ACQUIRED to RUNNING
2013-08-10 14:29:01,503 INFO org.apache.hadoop.yarn.server.resourcemanager.rmcontainer.RMContainerImpl: container_1376143950665_0009_01_000001 Container Transitioned from ACQUIRED to RUNNING
2013-08-10 14:29:01,542 INFO org.apache.hadoop.yarn.server.resourcemanager.rmcontainer.RMContainerImpl: container_1376143950665_0010_01_000001 Container Transitioned from ACQUIRED to RUNNING
2013-08-10 14:29:06,040 INFO org.apache.hadoop.yarn.server.resourcemanager.ApplicationMasterService: AM registration appattempt_1376143950665_0010_000001
2013-08-10 14:29:06,040 INFO org.apache.hadoop.yarn.server.resourcemanager.RMAuditLogger: USER=ubuntu	IP=192.168.100.39	OPERATION=Register App Master	TARGET=ApplicationMasterService	RESULT=SUCCESS	APPID=application_1376143950665_0010	APPATTEMPTID=appattempt_1376143950665_0010_000001
2013-08-10 14:29:06,043 INFO org.apache.hadoop.yarn.server.resourcemanager.rmapp.attempt.RMAppAttemptImpl: appattempt_1376143950665_0010_000001 State change from LAUNCHED to RUNNING
2013-08-10 14:29:06,043 INFO org.apache.hadoop.yarn.server.resourcemanager.rmapp.RMAppImpl: application_1376143950665_0010 State change from ACCEPTED to RUNNING
2013-08-10 14:29:06,966 INFO org.apache.hadoop.yarn.server.resourcemanager.ApplicationMasterService: AM registration appattempt_1376143950665_0008_000001
2013-08-10 14:29:06,966 INFO org.apache.hadoop.yarn.server.resourcemanager.RMAuditLogger: USER=ubuntu	IP=192.168.100.37	OPERATION=Register App Master	TARGET=ApplicationMasterService	RESULT=SUCCESS	APPID=application_1376143950665_0008	APPATTEMPTID=appattempt_1376143950665_0008_000001
2013-08-10 14:29:06,968 INFO org.apache.hadoop.yarn.server.resourcemanager.rmapp.attempt.RMAppAttemptImpl: appattempt_1376143950665_0008_000001 State change from LAUNCHED to RUNNING
2013-08-10 14:29:06,968 INFO org.apache.hadoop.yarn.server.resourcemanager.rmapp.RMAppImpl: application_1376143950665_0008 State change from ACCEPTED to RUNNING
2013-08-10 14:29:06,994 INFO org.apache.hadoop.yarn.server.resourcemanager.ApplicationMasterService: AM registration appattempt_1376143950665_0007_000001
2013-08-10 14:29:06,994 INFO org.apache.hadoop.yarn.server.resourcemanager.RMAuditLogger: USER=ubuntu	IP=192.168.100.35	OPERATION=Register App Master	TARGET=ApplicationMasterService	RESULT=SUCCESS	APPID=application_1376143950665_0007	APPATTEMPTID=appattempt_1376143950665_0007_000001
2013-08-10 14:29:06,995 INFO org.apache.hadoop.yarn.server.resourcemanager.rmapp.attempt.RMAppAttemptImpl: appattempt_1376143950665_0007_000001 State change from LAUNCHED to RUNNING
2013-08-10 14:29:06,995 INFO org.apache.hadoop.yarn.server.resourcemanager.rmapp.RMAppImpl: application_1376143950665_0007 State change from ACCEPTED to RUNNING
2013-08-10 14:29:07,090 INFO org.apache.hadoop.yarn.server.resourcemanager.ApplicationMasterService: AM registration appattempt_1376143950665_0006_000001
2013-08-10 14:29:07,090 INFO org.apache.hadoop.yarn.server.resourcemanager.RMAuditLogger: USER=ubuntu	IP=192.168.100.40	OPERATION=Register App Master	TARGET=ApplicationMasterService	RESULT=SUCCESS	APPID=application_1376143950665_0006	APPATTEMPTID=appattempt_1376143950665_0006_000001
2013-08-10 14:29:07,092 INFO org.apache.hadoop.yarn.server.resourcemanager.rmapp.attempt.RMAppAttemptImpl: appattempt_1376143950665_0006_000001 State change from LAUNCHED to RUNNING
2013-08-10 14:29:07,092 INFO org.apache.hadoop.yarn.server.resourcemanager.rmapp.RMAppImpl: application_1376143950665_0006 State change from ACCEPTED to RUNNING
2013-08-10 14:29:07,274 INFO org.apache.hadoop.yarn.server.resourcemanager.rmcontainer.RMContainerImpl: container_1376143950665_0010_01_000002 Container Transitioned from NEW to ALLOCATED
2013-08-10 14:29:07,275 INFO org.apache.hadoop.yarn.server.resourcemanager.RMAuditLogger: USER=ubuntu	OPERATION=AM Allocated Container	TARGET=SchedulerApp	RESULT=SUCCESS	APPID=application_1376143950665_0010	CONTAINERID=container_1376143950665_0010_01_000002
2013-08-10 14:29:07,275 INFO org.apache.hadoop.yarn.server.resourcemanager.scheduler.common.fica.FiCaSchedulerNode: Assigned container container_1376143950665_0010_01_000002 of capacity <memory:1024, vCores:1> on host hadoop-221-2:53277, which currently has 2 containers, <memory:3072, vCores:2> used and <memory:5120, vCores:14> available
2013-08-10 14:29:07,276 INFO org.apache.hadoop.yarn.server.resourcemanager.scheduler.capacity.LeafQueue: assignedContainer application=application_1376143950665_0010 container=Container: [ContainerId: container_1376143950665_0010_01_000002, NodeId: hadoop-221-2:53277, NodeHttpAddress: hadoop-221-2:8042, Resource: <memory:1024, vCores:1>, Priority: 20, State: NEW, Token: null, Status: container_id {, app_attempt_id {, application_id {, id: 10, cluster_timestamp: 1376143950665, }, attemptId: 1, }, id: 2, }, state: C_NEW, ] containerId=container_1376143950665_0010_01_000002 queue=default: capacity=1.0, absoluteCapacity=1.0, usedResources=<memory:10240, vCores:5>usedCapacity=0.20833333, absoluteUsedCapacity=0.20833333, numApps=5, numContainers=5 usedCapacity=0.20833333 absoluteUsedCapacity=0.20833333 used=<memory:10240, vCores:5> cluster=<memory:49152, vCores:96>
2013-08-10 14:29:07,276 INFO org.apache.hadoop.yarn.server.resourcemanager.scheduler.capacity.ParentQueue: Re-sorting queues since queue: root.default stats: default: capacity=1.0, absoluteCapacity=1.0, usedResources=<memory:11264, vCores:6>usedCapacity=0.22916667, absoluteUsedCapacity=0.22916667, numApps=5, numContainers=6
2013-08-10 14:29:07,277 INFO org.apache.hadoop.yarn.server.resourcemanager.scheduler.capacity.ParentQueue: assignedContainer queue=root usedCapacity=0.22916667 absoluteUsedCapacity=0.22916667 used=<memory:11264, vCores:6> cluster=<memory:49152, vCores:96>
2013-08-10 14:29:07,277 INFO org.apache.hadoop.yarn.server.resourcemanager.rmcontainer.RMContainerImpl: container_1376143950665_0010_01_000003 Container Transitioned from NEW to ALLOCATED
2013-08-10 14:29:07,277 INFO org.apache.hadoop.yarn.server.resourcemanager.RMAuditLogger: USER=ubuntu	OPERATION=AM Allocated Container	TARGET=SchedulerApp	RESULT=SUCCESS	APPID=application_1376143950665_0010	CONTAINERID=container_1376143950665_0010_01_000003
2013-08-10 14:29:07,277 INFO org.apache.hadoop.yarn.server.resourcemanager.scheduler.common.fica.FiCaSchedulerNode: Assigned container container_1376143950665_0010_01_000003 of capacity <memory:1024, vCores:1> on host hadoop-221-2:53277, which currently has 3 containers, <memory:4096, vCores:3> used and <memory:4096, vCores:13> available
2013-08-10 14:29:07,279 INFO org.apache.hadoop.yarn.server.resourcemanager.scheduler.capacity.LeafQueue: assignedContainer application=application_1376143950665_0010 container=Container: [ContainerId: container_1376143950665_0010_01_000003, NodeId: hadoop-221-2:53277, NodeHttpAddress: hadoop-221-2:8042, Resource: <memory:1024, vCores:1>, Priority: 20, State: NEW, Token: null, Status: container_id {, app_attempt_id {, application_id {, id: 10, cluster_timestamp: 1376143950665, }, attemptId: 1, }, id: 3, }, state: C_NEW, ] containerId=container_1376143950665_0010_01_000003 queue=default: capacity=1.0, absoluteCapacity=1.0, usedResources=<memory:11264, vCores:6>usedCapacity=0.22916667, absoluteUsedCapacity=0.22916667, numApps=5, numContainers=6 usedCapacity=0.22916667 absoluteUsedCapacity=0.22916667 used=<memory:11264, vCores:6> cluster=<memory:49152, vCores:96>
2013-08-10 14:29:07,279 INFO org.apache.hadoop.yarn.server.resourcemanager.scheduler.capacity.ParentQueue: Re-sorting queues since queue: root.default stats: default: capacity=1.0, absoluteCapacity=1.0, usedResources=<memory:12288, vCores:7>usedCapacity=0.25, absoluteUsedCapacity=0.25, numApps=5, numContainers=7
2013-08-10 14:29:07,279 INFO org.apache.hadoop.yarn.server.resourcemanager.scheduler.capacity.ParentQueue: assignedContainer queue=root usedCapacity=0.25 absoluteUsedCapacity=0.25 used=<memory:12288, vCores:7> cluster=<memory:49152, vCores:96>
2013-08-10 14:29:07,280 INFO org.apache.hadoop.yarn.server.resourcemanager.rmcontainer.RMContainerImpl: container_1376143950665_0010_01_000004 Container Transitioned from NEW to ALLOCATED
2013-08-10 14:29:07,280 INFO org.apache.hadoop.yarn.server.resourcemanager.RMAuditLogger: USER=ubuntu	OPERATION=AM Allocated Container	TARGET=SchedulerApp	RESULT=SUCCESS	APPID=application_1376143950665_0010	CONTAINERID=container_1376143950665_0010_01_000004
2013-08-10 14:29:07,280 INFO org.apache.hadoop.yarn.server.resourcemanager.scheduler.common.fica.FiCaSchedulerNode: Assigned container container_1376143950665_0010_01_000004 of capacity <memory:1024, vCores:1> on host hadoop-221-2:53277, which currently has 4 containers, <memory:5120, vCores:4> used and <memory:3072, vCores:12> available
2013-08-10 14:29:07,281 INFO org.apache.hadoop.yarn.server.resourcemanager.scheduler.capacity.LeafQueue: assignedContainer application=application_1376143950665_0010 container=Container: [ContainerId: container_1376143950665_0010_01_000004, NodeId: hadoop-221-2:53277, NodeHttpAddress: hadoop-221-2:8042, Resource: <memory:1024, vCores:1>, Priority: 20, State: NEW, Token: null, Status: container_id {, app_attempt_id {, application_id {, id: 10, cluster_timestamp: 1376143950665, }, attemptId: 1, }, id: 4, }, state: C_NEW, ] containerId=container_1376143950665_0010_01_000004 queue=default: capacity=1.0, absoluteCapacity=1.0, usedResources=<memory:12288, vCores:7>usedCapacity=0.25, absoluteUsedCapacity=0.25, numApps=5, numContainers=7 usedCapacity=0.25 absoluteUsedCapacity=0.25 used=<memory:12288, vCores:7> cluster=<memory:49152, vCores:96>
2013-08-10 14:29:07,281 INFO org.apache.hadoop.yarn.server.resourcemanager.scheduler.capacity.ParentQueue: Re-sorting queues since queue: root.default stats: default: capacity=1.0, absoluteCapacity=1.0, usedResources=<memory:13312, vCores:8>usedCapacity=0.27083334, absoluteUsedCapacity=0.27083334, numApps=5, numContainers=8
2013-08-10 14:29:07,281 INFO org.apache.hadoop.yarn.server.resourcemanager.scheduler.capacity.ParentQueue: assignedContainer queue=root usedCapacity=0.27083334 absoluteUsedCapacity=0.27083334 used=<memory:13312, vCores:8> cluster=<memory:49152, vCores:96>
2013-08-10 14:29:07,282 INFO org.apache.hadoop.yarn.server.resourcemanager.rmcontainer.RMContainerImpl: container_1376143950665_0010_01_000005 Container Transitioned from NEW to ALLOCATED
2013-08-10 14:29:07,282 INFO org.apache.hadoop.yarn.server.resourcemanager.RMAuditLogger: USER=ubuntu	OPERATION=AM Allocated Container	TARGET=SchedulerApp	RESULT=SUCCESS	APPID=application_1376143950665_0010	CONTAINERID=container_1376143950665_0010_01_000005
2013-08-10 14:29:07,282 INFO org.apache.hadoop.yarn.server.resourcemanager.scheduler.common.fica.FiCaSchedulerNode: Assigned container container_1376143950665_0010_01_000005 of capacity <memory:1024, vCores:1> on host hadoop-221-2:53277, which currently has 5 containers, <memory:6144, vCores:5> used and <memory:2048, vCores:11> available
2013-08-10 14:29:07,285 INFO org.apache.hadoop.yarn.server.resourcemanager.scheduler.capacity.LeafQueue: assignedContainer application=application_1376143950665_0010 container=Container: [ContainerId: container_1376143950665_0010_01_000005, NodeId: hadoop-221-2:53277, NodeHttpAddress: hadoop-221-2:8042, Resource: <memory:1024, vCores:1>, Priority: 20, State: NEW, Token: null, Status: container_id {, app_attempt_id {, application_id {, id: 10, cluster_timestamp: 1376143950665, }, attemptId: 1, }, id: 5, }, state: C_NEW, ] containerId=container_1376143950665_0010_01_000005 queue=default: capacity=1.0, absoluteCapacity=1.0, usedResources=<memory:13312, vCores:8>usedCapacity=0.27083334, absoluteUsedCapacity=0.27083334, numApps=5, numContainers=8 usedCapacity=0.27083334 absoluteUsedCapacity=0.27083334 used=<memory:13312, vCores:8> cluster=<memory:49152, vCores:96>
2013-08-10 14:29:07,285 INFO org.apache.hadoop.yarn.server.resourcemanager.scheduler.capacity.ParentQueue: Re-sorting queues since queue: root.default stats: default: capacity=1.0, absoluteCapacity=1.0, usedResources=<memory:14336, vCores:9>usedCapacity=0.29166666, absoluteUsedCapacity=0.29166666, numApps=5, numContainers=9
2013-08-10 14:29:07,285 INFO org.apache.hadoop.yarn.server.resourcemanager.scheduler.capacity.ParentQueue: assignedContainer queue=root usedCapacity=0.29166666 absoluteUsedCapacity=0.29166666 used=<memory:14336, vCores:9> cluster=<memory:49152, vCores:96>
2013-08-10 14:29:07,286 INFO org.apache.hadoop.yarn.server.resourcemanager.rmcontainer.RMContainerImpl: container_1376143950665_0010_01_000006 Container Transitioned from NEW to ALLOCATED
2013-08-10 14:29:07,286 INFO org.apache.hadoop.yarn.server.resourcemanager.RMAuditLogger: USER=ubuntu	OPERATION=AM Allocated Container	TARGET=SchedulerApp	RESULT=SUCCESS	APPID=application_1376143950665_0010	CONTAINERID=container_1376143950665_0010_01_000006
2013-08-10 14:29:07,286 INFO org.apache.hadoop.yarn.server.resourcemanager.scheduler.common.fica.FiCaSchedulerNode: Assigned container container_1376143950665_0010_01_000006 of capacity <memory:1024, vCores:1> on host hadoop-221-2:53277, which currently has 6 containers, <memory:7168, vCores:6> used and <memory:1024, vCores:10> available
2013-08-10 14:29:07,287 INFO org.apache.hadoop.yarn.server.resourcemanager.scheduler.capacity.LeafQueue: assignedContainer application=application_1376143950665_0010 container=Container: [ContainerId: container_1376143950665_0010_01_000006, NodeId: hadoop-221-2:53277, NodeHttpAddress: hadoop-221-2:8042, Resource: <memory:1024, vCores:1>, Priority: 20, State: NEW, Token: null, Status: container_id {, app_attempt_id {, application_id {, id: 10, cluster_timestamp: 1376143950665, }, attemptId: 1, }, id: 6, }, state: C_NEW, ] containerId=container_1376143950665_0010_01_000006 queue=default: capacity=1.0, absoluteCapacity=1.0, usedResources=<memory:14336, vCores:9>usedCapacity=0.29166666, absoluteUsedCapacity=0.29166666, numApps=5, numContainers=9 usedCapacity=0.29166666 absoluteUsedCapacity=0.29166666 used=<memory:14336, vCores:9> cluster=<memory:49152, vCores:96>
2013-08-10 14:29:07,287 INFO org.apache.hadoop.yarn.server.resourcemanager.scheduler.capacity.ParentQueue: Re-sorting queues since queue: root.default stats: default: capacity=1.0, absoluteCapacity=1.0, usedResources=<memory:15360, vCores:10>usedCapacity=0.3125, absoluteUsedCapacity=0.3125, numApps=5, numContainers=10
2013-08-10 14:29:07,287 INFO org.apache.hadoop.yarn.server.resourcemanager.scheduler.capacity.ParentQueue: assignedContainer queue=root usedCapacity=0.3125 absoluteUsedCapacity=0.3125 used=<memory:15360, vCores:10> cluster=<memory:49152, vCores:96>
2013-08-10 14:29:07,288 INFO org.apache.hadoop.yarn.server.resourcemanager.rmcontainer.RMContainerImpl: container_1376143950665_0010_01_000007 Container Transitioned from NEW to ALLOCATED
2013-08-10 14:29:07,288 INFO org.apache.hadoop.yarn.server.resourcemanager.RMAuditLogger: USER=ubuntu	OPERATION=AM Allocated Container	TARGET=SchedulerApp	RESULT=SUCCESS	APPID=application_1376143950665_0010	CONTAINERID=container_1376143950665_0010_01_000007
2013-08-10 14:29:07,288 INFO org.apache.hadoop.yarn.server.resourcemanager.scheduler.common.fica.FiCaSchedulerNode: Assigned container container_1376143950665_0010_01_000007 of capacity <memory:1024, vCores:1> on host hadoop-221-2:53277, which currently has 7 containers, <memory:8192, vCores:7> used and <memory:0, vCores:9> available
2013-08-10 14:29:07,289 INFO org.apache.hadoop.yarn.server.resourcemanager.scheduler.capacity.LeafQueue: assignedContainer application=application_1376143950665_0010 container=Container: [ContainerId: container_1376143950665_0010_01_000007, NodeId: hadoop-221-2:53277, NodeHttpAddress: hadoop-221-2:8042, Resource: <memory:1024, vCores:1>, Priority: 20, State: NEW, Token: null, Status: container_id {, app_attempt_id {, application_id {, id: 10, cluster_timestamp: 1376143950665, }, attemptId: 1, }, id: 7, }, state: C_NEW, ] containerId=container_1376143950665_0010_01_000007 queue=default: capacity=1.0, absoluteCapacity=1.0, usedResources=<memory:15360, vCores:10>usedCapacity=0.3125, absoluteUsedCapacity=0.3125, numApps=5, numContainers=10 usedCapacity=0.3125 absoluteUsedCapacity=0.3125 used=<memory:15360, vCores:10> cluster=<memory:49152, vCores:96>
2013-08-10 14:29:07,289 INFO org.apache.hadoop.yarn.server.resourcemanager.scheduler.capacity.ParentQueue: Re-sorting queues since queue: root.default stats: default: capacity=1.0, absoluteCapacity=1.0, usedResources=<memory:16384, vCores:11>usedCapacity=0.33333334, absoluteUsedCapacity=0.33333334, numApps=5, numContainers=11
2013-08-10 14:29:07,290 INFO org.apache.hadoop.yarn.server.resourcemanager.scheduler.capacity.ParentQueue: assignedContainer queue=root usedCapacity=0.33333334 absoluteUsedCapacity=0.33333334 used=<memory:16384, vCores:11> cluster=<memory:49152, vCores:96>
2013-08-10 14:29:07,290 INFO org.apache.hadoop.yarn.server.resourcemanager.rmcontainer.RMContainerImpl: container_1376143950665_0010_01_000008 Container Transitioned from NEW to ALLOCATED
2013-08-10 14:29:07,290 INFO org.apache.hadoop.yarn.server.resourcemanager.RMAuditLogger: USER=ubuntu	OPERATION=AM Allocated Container	TARGET=SchedulerApp	RESULT=SUCCESS	APPID=application_1376143950665_0010	CONTAINERID=container_1376143950665_0010_01_000008
2013-08-10 14:29:07,290 INFO org.apache.hadoop.yarn.server.resourcemanager.scheduler.common.fica.FiCaSchedulerNode: Assigned container container_1376143950665_0010_01_000008 of capacity <memory:1024, vCores:1> on host hadoop-221-4:43548, which currently has 2 containers, <memory:3072, vCores:2> used and <memory:5120, vCores:14> available
2013-08-10 14:29:07,291 INFO org.apache.hadoop.yarn.server.resourcemanager.scheduler.capacity.LeafQueue: assignedContainer application=application_1376143950665_0010 container=Container: [ContainerId: container_1376143950665_0010_01_000008, NodeId: hadoop-221-4:43548, NodeHttpAddress: hadoop-221-4:8042, Resource: <memory:1024, vCores:1>, Priority: 20, State: NEW, Token: null, Status: container_id {, app_attempt_id {, application_id {, id: 10, cluster_timestamp: 1376143950665, }, attemptId: 1, }, id: 8, }, state: C_NEW, ] containerId=container_1376143950665_0010_01_000008 queue=default: capacity=1.0, absoluteCapacity=1.0, usedResources=<memory:16384, vCores:11>usedCapacity=0.33333334, absoluteUsedCapacity=0.33333334, numApps=5, numContainers=11 usedCapacity=0.33333334 absoluteUsedCapacity=0.33333334 used=<memory:16384, vCores:11> cluster=<memory:49152, vCores:96>
2013-08-10 14:29:07,292 INFO org.apache.hadoop.yarn.server.resourcemanager.scheduler.capacity.ParentQueue: Re-sorting queues since queue: root.default stats: default: capacity=1.0, absoluteCapacity=1.0, usedResources=<memory:17408, vCores:12>usedCapacity=0.35416666, absoluteUsedCapacity=0.35416666, numApps=5, numContainers=12
2013-08-10 14:29:07,292 INFO org.apache.hadoop.yarn.server.resourcemanager.scheduler.capacity.ParentQueue: assignedContainer queue=root usedCapacity=0.35416666 absoluteUsedCapacity=0.35416666 used=<memory:17408, vCores:12> cluster=<memory:49152, vCores:96>
2013-08-10 14:29:07,292 INFO org.apache.hadoop.yarn.server.resourcemanager.rmcontainer.RMContainerImpl: container_1376143950665_0010_01_000009 Container Transitioned from NEW to ALLOCATED
2013-08-10 14:29:07,292 INFO org.apache.hadoop.yarn.server.resourcemanager.RMAuditLogger: USER=ubuntu	OPERATION=AM Allocated Container	TARGET=SchedulerApp	RESULT=SUCCESS	APPID=application_1376143950665_0010	CONTAINERID=container_1376143950665_0010_01_000009
2013-08-10 14:29:07,292 INFO org.apache.hadoop.yarn.server.resourcemanager.scheduler.common.fica.FiCaSchedulerNode: Assigned container container_1376143950665_0010_01_000009 of capacity <memory:1024, vCores:1> on host hadoop-221-4:43548, which currently has 3 containers, <memory:4096, vCores:3> used and <memory:4096, vCores:13> available
2013-08-10 14:29:07,293 INFO org.apache.hadoop.yarn.server.resourcemanager.scheduler.capacity.LeafQueue: assignedContainer application=application_1376143950665_0010 container=Container: [ContainerId: container_1376143950665_0010_01_000009, NodeId: hadoop-221-4:43548, NodeHttpAddress: hadoop-221-4:8042, Resource: <memory:1024, vCores:1>, Priority: 20, State: NEW, Token: null, Status: container_id {, app_attempt_id {, application_id {, id: 10, cluster_timestamp: 1376143950665, }, attemptId: 1, }, id: 9, }, state: C_NEW, ] containerId=container_1376143950665_0010_01_000009 queue=default: capacity=1.0, absoluteCapacity=1.0, usedResources=<memory:17408, vCores:12>usedCapacity=0.35416666, absoluteUsedCapacity=0.35416666, numApps=5, numContainers=12 usedCapacity=0.35416666 absoluteUsedCapacity=0.35416666 used=<memory:17408, vCores:12> cluster=<memory:49152, vCores:96>
2013-08-10 14:29:07,294 INFO org.apache.hadoop.yarn.server.resourcemanager.scheduler.capacity.ParentQueue: Re-sorting queues since queue: root.default stats: default: capacity=1.0, absoluteCapacity=1.0, usedResources=<memory:18432, vCores:13>usedCapacity=0.375, absoluteUsedCapacity=0.375, numApps=5, numContainers=13
2013-08-10 14:29:07,294 INFO org.apache.hadoop.yarn.server.resourcemanager.scheduler.capacity.ParentQueue: assignedContainer queue=root usedCapacity=0.375 absoluteUsedCapacity=0.375 used=<memory:18432, vCores:13> cluster=<memory:49152, vCores:96>
2013-08-10 14:29:07,294 INFO org.apache.hadoop.yarn.server.resourcemanager.rmcontainer.RMContainerImpl: container_1376143950665_0010_01_000010 Container Transitioned from NEW to ALLOCATED
2013-08-10 14:29:07,294 INFO org.apache.hadoop.yarn.server.resourcemanager.RMAuditLogger: USER=ubuntu	OPERATION=AM Allocated Container	TARGET=SchedulerApp	RESULT=SUCCESS	APPID=application_1376143950665_0010	CONTAINERID=container_1376143950665_0010_01_000010
2013-08-10 14:29:07,295 INFO org.apache.hadoop.yarn.server.resourcemanager.scheduler.common.fica.FiCaSchedulerNode: Assigned container container_1376143950665_0010_01_000010 of capacity <memory:1024, vCores:1> on host hadoop-221-4:43548, which currently has 4 containers, <memory:5120, vCores:4> used and <memory:3072, vCores:12> available
2013-08-10 14:29:07,296 INFO org.apache.hadoop.yarn.server.resourcemanager.scheduler.capacity.LeafQueue: assignedContainer application=application_1376143950665_0010 container=Container: [ContainerId: container_1376143950665_0010_01_000010, NodeId: hadoop-221-4:43548, NodeHttpAddress: hadoop-221-4:8042, Resource: <memory:1024, vCores:1>, Priority: 20, State: NEW, Token: null, Status: container_id {, app_attempt_id {, application_id {, id: 10, cluster_timestamp: 1376143950665, }, attemptId: 1, }, id: 10, }, state: C_NEW, ] containerId=container_1376143950665_0010_01_000010 queue=default: capacity=1.0, absoluteCapacity=1.0, usedResources=<memory:18432, vCores:13>usedCapacity=0.375, absoluteUsedCapacity=0.375, numApps=5, numContainers=13 usedCapacity=0.375 absoluteUsedCapacity=0.375 used=<memory:18432, vCores:13> cluster=<memory:49152, vCores:96>
2013-08-10 14:29:07,296 INFO org.apache.hadoop.yarn.server.resourcemanager.scheduler.capacity.ParentQueue: Re-sorting queues since queue: root.default stats: default: capacity=1.0, absoluteCapacity=1.0, usedResources=<memory:19456, vCores:14>usedCapacity=0.39583334, absoluteUsedCapacity=0.39583334, numApps=5, numContainers=14
2013-08-10 14:29:07,296 INFO org.apache.hadoop.yarn.server.resourcemanager.scheduler.capacity.ParentQueue: assignedContainer queue=root usedCapacity=0.39583334 absoluteUsedCapacity=0.39583334 used=<memory:19456, vCores:14> cluster=<memory:49152, vCores:96>
2013-08-10 14:29:07,296 INFO org.apache.hadoop.yarn.server.resourcemanager.rmcontainer.RMContainerImpl: container_1376143950665_0010_01_000011 Container Transitioned from NEW to ALLOCATED
2013-08-10 14:29:07,297 INFO org.apache.hadoop.yarn.server.resourcemanager.RMAuditLogger: USER=ubuntu	OPERATION=AM Allocated Container	TARGET=SchedulerApp	RESULT=SUCCESS	APPID=application_1376143950665_0010	CONTAINERID=container_1376143950665_0010_01_000011
2013-08-10 14:29:07,297 INFO org.apache.hadoop.yarn.server.resourcemanager.scheduler.common.fica.FiCaSchedulerNode: Assigned container container_1376143950665_0010_01_000011 of capacity <memory:1024, vCores:1> on host hadoop-221-4:43548, which currently has 5 containers, <memory:6144, vCores:5> used and <memory:2048, vCores:11> available
2013-08-10 14:29:07,298 INFO org.apache.hadoop.yarn.server.resourcemanager.scheduler.capacity.LeafQueue: assignedContainer application=application_1376143950665_0010 container=Container: [ContainerId: container_1376143950665_0010_01_000011, NodeId: hadoop-221-4:43548, NodeHttpAddress: hadoop-221-4:8042, Resource: <memory:1024, vCores:1>, Priority: 20, State: NEW, Token: null, Status: container_id {, app_attempt_id {, application_id {, id: 10, cluster_timestamp: 1376143950665, }, attemptId: 1, }, id: 11, }, state: C_NEW, ] containerId=container_1376143950665_0010_01_000011 queue=default: capacity=1.0, absoluteCapacity=1.0, usedResources=<memory:19456, vCores:14>usedCapacity=0.39583334, absoluteUsedCapacity=0.39583334, numApps=5, numContainers=14 usedCapacity=0.39583334 absoluteUsedCapacity=0.39583334 used=<memory:19456, vCores:14> cluster=<memory:49152, vCores:96>
2013-08-10 14:29:07,298 INFO org.apache.hadoop.yarn.server.resourcemanager.scheduler.capacity.ParentQueue: Re-sorting queues since queue: root.default stats: default: capacity=1.0, absoluteCapacity=1.0, usedResources=<memory:20480, vCores:15>usedCapacity=0.41666666, absoluteUsedCapacity=0.41666666, numApps=5, numContainers=15
2013-08-10 14:29:07,298 INFO org.apache.hadoop.yarn.server.resourcemanager.scheduler.capacity.ParentQueue: assignedContainer queue=root usedCapacity=0.41666666 absoluteUsedCapacity=0.41666666 used=<memory:20480, vCores:15> cluster=<memory:49152, vCores:96>
2013-08-10 14:29:07,299 INFO org.apache.hadoop.yarn.server.resourcemanager.rmcontainer.RMContainerImpl: container_1376143950665_0010_01_000012 Container Transitioned from NEW to ALLOCATED
2013-08-10 14:29:07,299 INFO org.apache.hadoop.yarn.server.resourcemanager.RMAuditLogger: USER=ubuntu	OPERATION=AM Allocated Container	TARGET=SchedulerApp	RESULT=SUCCESS	APPID=application_1376143950665_0010	CONTAINERID=container_1376143950665_0010_01_000012
2013-08-10 14:29:07,299 INFO org.apache.hadoop.yarn.server.resourcemanager.scheduler.common.fica.FiCaSchedulerNode: Assigned container container_1376143950665_0010_01_000012 of capacity <memory:1024, vCores:1> on host hadoop-221-4:43548, which currently has 6 containers, <memory:7168, vCores:6> used and <memory:1024, vCores:10> available
2013-08-10 14:29:07,300 INFO org.apache.hadoop.yarn.server.resourcemanager.scheduler.capacity.LeafQueue: assignedContainer application=application_1376143950665_0010 container=Container: [ContainerId: container_1376143950665_0010_01_000012, NodeId: hadoop-221-4:43548, NodeHttpAddress: hadoop-221-4:8042, Resource: <memory:1024, vCores:1>, Priority: 20, State: NEW, Token: null, Status: container_id {, app_attempt_id {, application_id {, id: 10, cluster_timestamp: 1376143950665, }, attemptId: 1, }, id: 12, }, state: C_NEW, ] containerId=container_1376143950665_0010_01_000012 queue=default: capacity=1.0, absoluteCapacity=1.0, usedResources=<memory:20480, vCores:15>usedCapacity=0.41666666, absoluteUsedCapacity=0.41666666, numApps=5, numContainers=15 usedCapacity=0.41666666 absoluteUsedCapacity=0.41666666 used=<memory:20480, vCores:15> cluster=<memory:49152, vCores:96>
2013-08-10 14:29:07,300 INFO org.apache.hadoop.yarn.server.resourcemanager.scheduler.capacity.ParentQueue: Re-sorting queues since queue: root.default stats: default: capacity=1.0, absoluteCapacity=1.0, usedResources=<memory:21504, vCores:16>usedCapacity=0.4375, absoluteUsedCapacity=0.4375, numApps=5, numContainers=16
2013-08-10 14:29:07,300 INFO org.apache.hadoop.yarn.server.resourcemanager.scheduler.capacity.ParentQueue: assignedContainer queue=root usedCapacity=0.4375 absoluteUsedCapacity=0.4375 used=<memory:21504, vCores:16> cluster=<memory:49152, vCores:96>
2013-08-10 14:29:07,301 INFO org.apache.hadoop.yarn.server.resourcemanager.rmcontainer.RMContainerImpl: container_1376143950665_0010_01_000013 Container Transitioned from NEW to ALLOCATED
2013-08-10 14:29:07,301 INFO org.apache.hadoop.yarn.server.resourcemanager.RMAuditLogger: USER=ubuntu	OPERATION=AM Allocated Container	TARGET=SchedulerApp	RESULT=SUCCESS	APPID=application_1376143950665_0010	CONTAINERID=container_1376143950665_0010_01_000013
2013-08-10 14:29:07,301 INFO org.apache.hadoop.yarn.server.resourcemanager.scheduler.common.fica.FiCaSchedulerNode: Assigned container container_1376143950665_0010_01_000013 of capacity <memory:1024, vCores:1> on host hadoop-221-4:43548, which currently has 7 containers, <memory:8192, vCores:7> used and <memory:0, vCores:9> available
2013-08-10 14:29:07,303 INFO org.apache.hadoop.yarn.server.resourcemanager.scheduler.capacity.LeafQueue: assignedContainer application=application_1376143950665_0010 container=Container: [ContainerId: container_1376143950665_0010_01_000013, NodeId: hadoop-221-4:43548, NodeHttpAddress: hadoop-221-4:8042, Resource: <memory:1024, vCores:1>, Priority: 20, State: NEW, Token: null, Status: container_id {, app_attempt_id {, application_id {, id: 10, cluster_timestamp: 1376143950665, }, attemptId: 1, }, id: 13, }, state: C_NEW, ] containerId=container_1376143950665_0010_01_000013 queue=default: capacity=1.0, absoluteCapacity=1.0, usedResources=<memory:21504, vCores:16>usedCapacity=0.4375, absoluteUsedCapacity=0.4375, numApps=5, numContainers=16 usedCapacity=0.4375 absoluteUsedCapacity=0.4375 used=<memory:21504, vCores:16> cluster=<memory:49152, vCores:96>
2013-08-10 14:29:07,303 INFO org.apache.hadoop.yarn.server.resourcemanager.scheduler.capacity.ParentQueue: Re-sorting queues since queue: root.default stats: default: capacity=1.0, absoluteCapacity=1.0, usedResources=<memory:22528, vCores:17>usedCapacity=0.45833334, absoluteUsedCapacity=0.45833334, numApps=5, numContainers=17
2013-08-10 14:29:07,303 INFO org.apache.hadoop.yarn.server.resourcemanager.scheduler.capacity.ParentQueue: assignedContainer queue=root usedCapacity=0.45833334 absoluteUsedCapacity=0.45833334 used=<memory:22528, vCores:17> cluster=<memory:49152, vCores:96>
2013-08-10 14:29:07,528 INFO org.apache.hadoop.yarn.server.resourcemanager.rmcontainer.RMContainerImpl: container_1376143950665_0010_01_000014 Container Transitioned from NEW to ALLOCATED
2013-08-10 14:29:07,528 INFO org.apache.hadoop.yarn.server.resourcemanager.RMAuditLogger: USER=ubuntu	OPERATION=AM Allocated Container	TARGET=SchedulerApp	RESULT=SUCCESS	APPID=application_1376143950665_0010	CONTAINERID=container_1376143950665_0010_01_000014
2013-08-10 14:29:07,529 INFO org.apache.hadoop.yarn.server.resourcemanager.scheduler.common.fica.FiCaSchedulerNode: Assigned container container_1376143950665_0010_01_000014 of capacity <memory:1024, vCores:1> on host hadoop-221-5:53998, which currently has 2 containers, <memory:3072, vCores:2> used and <memory:5120, vCores:14> available
2013-08-10 14:29:07,530 INFO org.apache.hadoop.yarn.server.resourcemanager.scheduler.capacity.LeafQueue: assignedContainer application=application_1376143950665_0010 container=Container: [ContainerId: container_1376143950665_0010_01_000014, NodeId: hadoop-221-5:53998, NodeHttpAddress: hadoop-221-5:8042, Resource: <memory:1024, vCores:1>, Priority: 20, State: NEW, Token: null, Status: container_id {, app_attempt_id {, application_id {, id: 10, cluster_timestamp: 1376143950665, }, attemptId: 1, }, id: 14, }, state: C_NEW, ] containerId=container_1376143950665_0010_01_000014 queue=default: capacity=1.0, absoluteCapacity=1.0, usedResources=<memory:22528, vCores:17>usedCapacity=0.45833334, absoluteUsedCapacity=0.45833334, numApps=5, numContainers=17 usedCapacity=0.45833334 absoluteUsedCapacity=0.45833334 used=<memory:22528, vCores:17> cluster=<memory:49152, vCores:96>
2013-08-10 14:29:07,530 INFO org.apache.hadoop.yarn.server.resourcemanager.scheduler.capacity.ParentQueue: Re-sorting queues since queue: root.default stats: default: capacity=1.0, absoluteCapacity=1.0, usedResources=<memory:23552, vCores:18>usedCapacity=0.47916666, absoluteUsedCapacity=0.47916666, numApps=5, numContainers=18
2013-08-10 14:29:07,530 INFO org.apache.hadoop.yarn.server.resourcemanager.scheduler.capacity.ParentQueue: assignedContainer queue=root usedCapacity=0.47916666 absoluteUsedCapacity=0.47916666 used=<memory:23552, vCores:18> cluster=<memory:49152, vCores:96>
2013-08-10 14:29:07,531 INFO org.apache.hadoop.yarn.server.resourcemanager.rmcontainer.RMContainerImpl: container_1376143950665_0010_01_000015 Container Transitioned from NEW to ALLOCATED
2013-08-10 14:29:07,531 INFO org.apache.hadoop.yarn.server.resourcemanager.RMAuditLogger: USER=ubuntu	OPERATION=AM Allocated Container	TARGET=SchedulerApp	RESULT=SUCCESS	APPID=application_1376143950665_0010	CONTAINERID=container_1376143950665_0010_01_000015
2013-08-10 14:29:07,533 INFO org.apache.hadoop.yarn.server.resourcemanager.scheduler.common.fica.FiCaSchedulerNode: Assigned container container_1376143950665_0010_01_000015 of capacity <memory:1024, vCores:1> on host hadoop-221-5:53998, which currently has 3 containers, <memory:4096, vCores:3> used and <memory:4096, vCores:13> available
2013-08-10 14:29:07,534 INFO org.apache.hadoop.yarn.server.resourcemanager.scheduler.capacity.LeafQueue: assignedContainer application=application_1376143950665_0010 container=Container: [ContainerId: container_1376143950665_0010_01_000015, NodeId: hadoop-221-5:53998, NodeHttpAddress: hadoop-221-5:8042, Resource: <memory:1024, vCores:1>, Priority: 20, State: NEW, Token: null, Status: container_id {, app_attempt_id {, application_id {, id: 10, cluster_timestamp: 1376143950665, }, attemptId: 1, }, id: 15, }, state: C_NEW, ] containerId=container_1376143950665_0010_01_000015 queue=default: capacity=1.0, absoluteCapacity=1.0, usedResources=<memory:23552, vCores:18>usedCapacity=0.47916666, absoluteUsedCapacity=0.47916666, numApps=5, numContainers=18 usedCapacity=0.47916666 absoluteUsedCapacity=0.47916666 used=<memory:23552, vCores:18> cluster=<memory:49152, vCores:96>
2013-08-10 14:29:07,534 INFO org.apache.hadoop.yarn.server.resourcemanager.scheduler.capacity.ParentQueue: Re-sorting queues since queue: root.default stats: default: capacity=1.0, absoluteCapacity=1.0, usedResources=<memory:24576, vCores:19>usedCapacity=0.5, absoluteUsedCapacity=0.5, numApps=5, numContainers=19
2013-08-10 14:29:07,534 INFO org.apache.hadoop.yarn.server.resourcemanager.scheduler.capacity.ParentQueue: assignedContainer queue=root usedCapacity=0.5 absoluteUsedCapacity=0.5 used=<memory:24576, vCores:19> cluster=<memory:49152, vCores:96>
2013-08-10 14:29:07,534 INFO org.apache.hadoop.yarn.server.resourcemanager.rmcontainer.RMContainerImpl: container_1376143950665_0010_01_000016 Container Transitioned from NEW to ALLOCATED
2013-08-10 14:29:07,535 INFO org.apache.hadoop.yarn.server.resourcemanager.RMAuditLogger: USER=ubuntu	OPERATION=AM Allocated Container	TARGET=SchedulerApp	RESULT=SUCCESS	APPID=application_1376143950665_0010	CONTAINERID=container_1376143950665_0010_01_000016
2013-08-10 14:29:07,535 INFO org.apache.hadoop.yarn.server.resourcemanager.scheduler.common.fica.FiCaSchedulerNode: Assigned container container_1376143950665_0010_01_000016 of capacity <memory:1024, vCores:1> on host hadoop-221-5:53998, which currently has 4 containers, <memory:5120, vCores:4> used and <memory:3072, vCores:12> available
2013-08-10 14:29:07,536 INFO org.apache.hadoop.yarn.server.resourcemanager.scheduler.capacity.LeafQueue: assignedContainer application=application_1376143950665_0010 container=Container: [ContainerId: container_1376143950665_0010_01_000016, NodeId: hadoop-221-5:53998, NodeHttpAddress: hadoop-221-5:8042, Resource: <memory:1024, vCores:1>, Priority: 20, State: NEW, Token: null, Status: container_id {, app_attempt_id {, application_id {, id: 10, cluster_timestamp: 1376143950665, }, attemptId: 1, }, id: 16, }, state: C_NEW, ] containerId=container_1376143950665_0010_01_000016 queue=default: capacity=1.0, absoluteCapacity=1.0, usedResources=<memory:24576, vCores:19>usedCapacity=0.5, absoluteUsedCapacity=0.5, numApps=5, numContainers=19 usedCapacity=0.5 absoluteUsedCapacity=0.5 used=<memory:24576, vCores:19> cluster=<memory:49152, vCores:96>
2013-08-10 14:29:07,536 INFO org.apache.hadoop.yarn.server.resourcemanager.scheduler.capacity.ParentQueue: Re-sorting queues since queue: root.default stats: default: capacity=1.0, absoluteCapacity=1.0, usedResources=<memory:25600, vCores:20>usedCapacity=0.5208333, absoluteUsedCapacity=0.5208333, numApps=5, numContainers=20
2013-08-10 14:29:07,536 INFO org.apache.hadoop.yarn.server.resourcemanager.scheduler.capacity.ParentQueue: assignedContainer queue=root usedCapacity=0.5208333 absoluteUsedCapacity=0.5208333 used=<memory:25600, vCores:20> cluster=<memory:49152, vCores:96>
2013-08-10 14:29:07,537 INFO org.apache.hadoop.yarn.server.resourcemanager.rmcontainer.RMContainerImpl: container_1376143950665_0010_01_000017 Container Transitioned from NEW to ALLOCATED
2013-08-10 14:29:07,537 INFO org.apache.hadoop.yarn.server.resourcemanager.RMAuditLogger: USER=ubuntu	OPERATION=AM Allocated Container	TARGET=SchedulerApp	RESULT=SUCCESS	APPID=application_1376143950665_0010	CONTAINERID=container_1376143950665_0010_01_000017
2013-08-10 14:29:07,537 INFO org.apache.hadoop.yarn.server.resourcemanager.scheduler.common.fica.FiCaSchedulerNode: Assigned container container_1376143950665_0010_01_000017 of capacity <memory:1024, vCores:1> on host hadoop-221-5:53998, which currently has 5 containers, <memory:6144, vCores:5> used and <memory:2048, vCores:11> available
2013-08-10 14:29:07,538 INFO org.apache.hadoop.yarn.server.resourcemanager.scheduler.capacity.LeafQueue: assignedContainer application=application_1376143950665_0010 container=Container: [ContainerId: container_1376143950665_0010_01_000017, NodeId: hadoop-221-5:53998, NodeHttpAddress: hadoop-221-5:8042, Resource: <memory:1024, vCores:1>, Priority: 20, State: NEW, Token: null, Status: container_id {, app_attempt_id {, application_id {, id: 10, cluster_timestamp: 1376143950665, }, attemptId: 1, }, id: 17, }, state: C_NEW, ] containerId=container_1376143950665_0010_01_000017 queue=default: capacity=1.0, absoluteCapacity=1.0, usedResources=<memory:25600, vCores:20>usedCapacity=0.5208333, absoluteUsedCapacity=0.5208333, numApps=5, numContainers=20 usedCapacity=0.5208333 absoluteUsedCapacity=0.5208333 used=<memory:25600, vCores:20> cluster=<memory:49152, vCores:96>
2013-08-10 14:29:07,538 INFO org.apache.hadoop.yarn.server.resourcemanager.scheduler.capacity.ParentQueue: Re-sorting queues since queue: root.default stats: default: capacity=1.0, absoluteCapacity=1.0, usedResources=<memory:26624, vCores:21>usedCapacity=0.5416667, absoluteUsedCapacity=0.5416667, numApps=5, numContainers=21
2013-08-10 14:29:07,538 INFO org.apache.hadoop.yarn.server.resourcemanager.scheduler.capacity.ParentQueue: assignedContainer queue=root usedCapacity=0.5416667 absoluteUsedCapacity=0.5416667 used=<memory:26624, vCores:21> cluster=<memory:49152, vCores:96>
2013-08-10 14:29:07,539 INFO org.apache.hadoop.yarn.server.resourcemanager.rmcontainer.RMContainerImpl: container_1376143950665_0010_01_000018 Container Transitioned from NEW to ALLOCATED
2013-08-10 14:29:07,539 INFO org.apache.hadoop.yarn.server.resourcemanager.RMAuditLogger: USER=ubuntu	OPERATION=AM Allocated Container	TARGET=SchedulerApp	RESULT=SUCCESS	APPID=application_1376143950665_0010	CONTAINERID=container_1376143950665_0010_01_000018
2013-08-10 14:29:07,539 INFO org.apache.hadoop.yarn.server.resourcemanager.scheduler.common.fica.FiCaSchedulerNode: Assigned container container_1376143950665_0010_01_000018 of capacity <memory:1024, vCores:1> on host hadoop-221-5:53998, which currently has 6 containers, <memory:7168, vCores:6> used and <memory:1024, vCores:10> available
2013-08-10 14:29:07,540 INFO org.apache.hadoop.yarn.server.resourcemanager.scheduler.capacity.LeafQueue: assignedContainer application=application_1376143950665_0010 container=Container: [ContainerId: container_1376143950665_0010_01_000018, NodeId: hadoop-221-5:53998, NodeHttpAddress: hadoop-221-5:8042, Resource: <memory:1024, vCores:1>, Priority: 20, State: NEW, Token: null, Status: container_id {, app_attempt_id {, application_id {, id: 10, cluster_timestamp: 1376143950665, }, attemptId: 1, }, id: 18, }, state: C_NEW, ] containerId=container_1376143950665_0010_01_000018 queue=default: capacity=1.0, absoluteCapacity=1.0, usedResources=<memory:26624, vCores:21>usedCapacity=0.5416667, absoluteUsedCapacity=0.5416667, numApps=5, numContainers=21 usedCapacity=0.5416667 absoluteUsedCapacity=0.5416667 used=<memory:26624, vCores:21> cluster=<memory:49152, vCores:96>
2013-08-10 14:29:07,540 INFO org.apache.hadoop.yarn.server.resourcemanager.scheduler.capacity.ParentQueue: Re-sorting queues since queue: root.default stats: default: capacity=1.0, absoluteCapacity=1.0, usedResources=<memory:27648, vCores:22>usedCapacity=0.5625, absoluteUsedCapacity=0.5625, numApps=5, numContainers=22
2013-08-10 14:29:07,540 INFO org.apache.hadoop.yarn.server.resourcemanager.scheduler.capacity.ParentQueue: assignedContainer queue=root usedCapacity=0.5625 absoluteUsedCapacity=0.5625 used=<memory:27648, vCores:22> cluster=<memory:49152, vCores:96>
2013-08-10 14:29:07,541 INFO org.apache.hadoop.yarn.server.resourcemanager.rmcontainer.RMContainerImpl: container_1376143950665_0010_01_000019 Container Transitioned from NEW to ALLOCATED
2013-08-10 14:29:07,541 INFO org.apache.hadoop.yarn.server.resourcemanager.RMAuditLogger: USER=ubuntu	OPERATION=AM Allocated Container	TARGET=SchedulerApp	RESULT=SUCCESS	APPID=application_1376143950665_0010	CONTAINERID=container_1376143950665_0010_01_000019
2013-08-10 14:29:07,541 INFO org.apache.hadoop.yarn.server.resourcemanager.scheduler.common.fica.FiCaSchedulerNode: Assigned container container_1376143950665_0010_01_000019 of capacity <memory:1024, vCores:1> on host hadoop-221-5:53998, which currently has 7 containers, <memory:8192, vCores:7> used and <memory:0, vCores:9> available
2013-08-10 14:29:07,542 INFO org.apache.hadoop.yarn.server.resourcemanager.scheduler.capacity.LeafQueue: assignedContainer application=application_1376143950665_0010 container=Container: [ContainerId: container_1376143950665_0010_01_000019, NodeId: hadoop-221-5:53998, NodeHttpAddress: hadoop-221-5:8042, Resource: <memory:1024, vCores:1>, Priority: 20, State: NEW, Token: null, Status: container_id {, app_attempt_id {, application_id {, id: 10, cluster_timestamp: 1376143950665, }, attemptId: 1, }, id: 19, }, state: C_NEW, ] containerId=container_1376143950665_0010_01_000019 queue=default: capacity=1.0, absoluteCapacity=1.0, usedResources=<memory:27648, vCores:22>usedCapacity=0.5625, absoluteUsedCapacity=0.5625, numApps=5, numContainers=22 usedCapacity=0.5625 absoluteUsedCapacity=0.5625 used=<memory:27648, vCores:22> cluster=<memory:49152, vCores:96>
2013-08-10 14:29:07,542 INFO org.apache.hadoop.yarn.server.resourcemanager.scheduler.capacity.ParentQueue: Re-sorting queues since queue: root.default stats: default: capacity=1.0, absoluteCapacity=1.0, usedResources=<memory:28672, vCores:23>usedCapacity=0.5833333, absoluteUsedCapacity=0.5833333, numApps=5, numContainers=23
2013-08-10 14:29:07,542 INFO org.apache.hadoop.yarn.server.resourcemanager.scheduler.capacity.ParentQueue: assignedContainer queue=root usedCapacity=0.5833333 absoluteUsedCapacity=0.5833333 used=<memory:28672, vCores:23> cluster=<memory:49152, vCores:96>
2013-08-10 14:29:07,566 INFO org.apache.hadoop.yarn.server.resourcemanager.rmcontainer.RMContainerImpl: container_1376143950665_0010_01_000020 Container Transitioned from NEW to ALLOCATED
2013-08-10 14:29:07,566 INFO org.apache.hadoop.yarn.server.resourcemanager.RMAuditLogger: USER=ubuntu	OPERATION=AM Allocated Container	TARGET=SchedulerApp	RESULT=SUCCESS	APPID=application_1376143950665_0010	CONTAINERID=container_1376143950665_0010_01_000020
2013-08-10 14:29:07,566 INFO org.apache.hadoop.yarn.server.resourcemanager.scheduler.common.fica.FiCaSchedulerNode: Assigned container container_1376143950665_0010_01_000020 of capacity <memory:1024, vCores:1> on host hadoop-221-6:51695, which currently has 2 containers, <memory:3072, vCores:2> used and <memory:5120, vCores:14> available
2013-08-10 14:29:07,567 INFO org.apache.hadoop.yarn.server.resourcemanager.scheduler.capacity.LeafQueue: assignedContainer application=application_1376143950665_0010 container=Container: [ContainerId: container_1376143950665_0010_01_000020, NodeId: hadoop-221-6:51695, NodeHttpAddress: hadoop-221-6:8042, Resource: <memory:1024, vCores:1>, Priority: 20, State: NEW, Token: null, Status: container_id {, app_attempt_id {, application_id {, id: 10, cluster_timestamp: 1376143950665, }, attemptId: 1, }, id: 20, }, state: C_NEW, ] containerId=container_1376143950665_0010_01_000020 queue=default: capacity=1.0, absoluteCapacity=1.0, usedResources=<memory:28672, vCores:23>usedCapacity=0.5833333, absoluteUsedCapacity=0.5833333, numApps=5, numContainers=23 usedCapacity=0.5833333 absoluteUsedCapacity=0.5833333 used=<memory:28672, vCores:23> cluster=<memory:49152, vCores:96>
2013-08-10 14:29:07,567 INFO org.apache.hadoop.yarn.server.resourcemanager.scheduler.capacity.ParentQueue: Re-sorting queues since queue: root.default stats: default: capacity=1.0, absoluteCapacity=1.0, usedResources=<memory:29696, vCores:24>usedCapacity=0.6041667, absoluteUsedCapacity=0.6041667, numApps=5, numContainers=24
2013-08-10 14:29:07,567 INFO org.apache.hadoop.yarn.server.resourcemanager.scheduler.capacity.ParentQueue: assignedContainer queue=root usedCapacity=0.6041667 absoluteUsedCapacity=0.6041667 used=<memory:29696, vCores:24> cluster=<memory:49152, vCores:96>
2013-08-10 14:29:07,568 INFO org.apache.hadoop.yarn.server.resourcemanager.rmcontainer.RMContainerImpl: container_1376143950665_0010_01_000021 Container Transitioned from NEW to ALLOCATED
2013-08-10 14:29:07,568 INFO org.apache.hadoop.yarn.server.resourcemanager.RMAuditLogger: USER=ubuntu	OPERATION=AM Allocated Container	TARGET=SchedulerApp	RESULT=SUCCESS	APPID=application_1376143950665_0010	CONTAINERID=container_1376143950665_0010_01_000021
2013-08-10 14:29:07,568 INFO org.apache.hadoop.yarn.server.resourcemanager.scheduler.common.fica.FiCaSchedulerNode: Assigned container container_1376143950665_0010_01_000021 of capacity <memory:1024, vCores:1> on host hadoop-221-6:51695, which currently has 3 containers, <memory:4096, vCores:3> used and <memory:4096, vCores:13> available
2013-08-10 14:29:07,569 INFO org.apache.hadoop.yarn.server.resourcemanager.scheduler.capacity.LeafQueue: assignedContainer application=application_1376143950665_0010 container=Container: [ContainerId: container_1376143950665_0010_01_000021, NodeId: hadoop-221-6:51695, NodeHttpAddress: hadoop-221-6:8042, Resource: <memory:1024, vCores:1>, Priority: 20, State: NEW, Token: null, Status: container_id {, app_attempt_id {, application_id {, id: 10, cluster_timestamp: 1376143950665, }, attemptId: 1, }, id: 21, }, state: C_NEW, ] containerId=container_1376143950665_0010_01_000021 queue=default: capacity=1.0, absoluteCapacity=1.0, usedResources=<memory:29696, vCores:24>usedCapacity=0.6041667, absoluteUsedCapacity=0.6041667, numApps=5, numContainers=24 usedCapacity=0.6041667 absoluteUsedCapacity=0.6041667 used=<memory:29696, vCores:24> cluster=<memory:49152, vCores:96>
2013-08-10 14:29:07,569 INFO org.apache.hadoop.yarn.server.resourcemanager.scheduler.capacity.ParentQueue: Re-sorting queues since queue: root.default stats: default: capacity=1.0, absoluteCapacity=1.0, usedResources=<memory:30720, vCores:25>usedCapacity=0.625, absoluteUsedCapacity=0.625, numApps=5, numContainers=25
2013-08-10 14:29:07,570 INFO org.apache.hadoop.yarn.server.resourcemanager.scheduler.capacity.ParentQueue: assignedContainer queue=root usedCapacity=0.625 absoluteUsedCapacity=0.625 used=<memory:30720, vCores:25> cluster=<memory:49152, vCores:96>
2013-08-10 14:29:07,570 INFO org.apache.hadoop.yarn.server.resourcemanager.rmcontainer.RMContainerImpl: container_1376143950665_0010_01_000022 Container Transitioned from NEW to ALLOCATED
2013-08-10 14:29:07,570 INFO org.apache.hadoop.yarn.server.resourcemanager.RMAuditLogger: USER=ubuntu	OPERATION=AM Allocated Container	TARGET=SchedulerApp	RESULT=SUCCESS	APPID=application_1376143950665_0010	CONTAINERID=container_1376143950665_0010_01_000022
2013-08-10 14:29:07,570 INFO org.apache.hadoop.yarn.server.resourcemanager.scheduler.common.fica.FiCaSchedulerNode: Assigned container container_1376143950665_0010_01_000022 of capacity <memory:1024, vCores:1> on host hadoop-221-6:51695, which currently has 4 containers, <memory:5120, vCores:4> used and <memory:3072, vCores:12> available
2013-08-10 14:29:07,571 INFO org.apache.hadoop.yarn.server.resourcemanager.scheduler.capacity.LeafQueue: assignedContainer application=application_1376143950665_0010 container=Container: [ContainerId: container_1376143950665_0010_01_000022, NodeId: hadoop-221-6:51695, NodeHttpAddress: hadoop-221-6:8042, Resource: <memory:1024, vCores:1>, Priority: 20, State: NEW, Token: null, Status: container_id {, app_attempt_id {, application_id {, id: 10, cluster_timestamp: 1376143950665, }, attemptId: 1, }, id: 22, }, state: C_NEW, ] containerId=container_1376143950665_0010_01_000022 queue=default: capacity=1.0, absoluteCapacity=1.0, usedResources=<memory:30720, vCores:25>usedCapacity=0.625, absoluteUsedCapacity=0.625, numApps=5, numContainers=25 usedCapacity=0.625 absoluteUsedCapacity=0.625 used=<memory:30720, vCores:25> cluster=<memory:49152, vCores:96>
2013-08-10 14:29:07,571 INFO org.apache.hadoop.yarn.server.resourcemanager.scheduler.capacity.ParentQueue: Re-sorting queues since queue: root.default stats: default: capacity=1.0, absoluteCapacity=1.0, usedResources=<memory:31744, vCores:26>usedCapacity=0.6458333, absoluteUsedCapacity=0.6458333, numApps=5, numContainers=26
2013-08-10 14:29:07,572 INFO org.apache.hadoop.yarn.server.resourcemanager.scheduler.capacity.ParentQueue: assignedContainer queue=root usedCapacity=0.6458333 absoluteUsedCapacity=0.6458333 used=<memory:31744, vCores:26> cluster=<memory:49152, vCores:96>
2013-08-10 14:29:07,572 INFO org.apache.hadoop.yarn.server.resourcemanager.rmcontainer.RMContainerImpl: container_1376143950665_0010_01_000023 Container Transitioned from NEW to ALLOCATED
2013-08-10 14:29:07,572 INFO org.apache.hadoop.yarn.server.resourcemanager.RMAuditLogger: USER=ubuntu	OPERATION=AM Allocated Container	TARGET=SchedulerApp	RESULT=SUCCESS	APPID=application_1376143950665_0010	CONTAINERID=container_1376143950665_0010_01_000023
2013-08-10 14:29:07,572 INFO org.apache.hadoop.yarn.server.resourcemanager.scheduler.common.fica.FiCaSchedulerNode: Assigned container container_1376143950665_0010_01_000023 of capacity <memory:1024, vCores:1> on host hadoop-221-6:51695, which currently has 5 containers, <memory:6144, vCores:5> used and <memory:2048, vCores:11> available
2013-08-10 14:29:07,573 INFO org.apache.hadoop.yarn.server.resourcemanager.scheduler.capacity.LeafQueue: assignedContainer application=application_1376143950665_0010 container=Container: [ContainerId: container_1376143950665_0010_01_000023, NodeId: hadoop-221-6:51695, NodeHttpAddress: hadoop-221-6:8042, Resource: <memory:1024, vCores:1>, Priority: 20, State: NEW, Token: null, Status: container_id {, app_attempt_id {, application_id {, id: 10, cluster_timestamp: 1376143950665, }, attemptId: 1, }, id: 23, }, state: C_NEW, ] containerId=container_1376143950665_0010_01_000023 queue=default: capacity=1.0, absoluteCapacity=1.0, usedResources=<memory:31744, vCores:26>usedCapacity=0.6458333, absoluteUsedCapacity=0.6458333, numApps=5, numContainers=26 usedCapacity=0.6458333 absoluteUsedCapacity=0.6458333 used=<memory:31744, vCores:26> cluster=<memory:49152, vCores:96>
2013-08-10 14:29:07,574 INFO org.apache.hadoop.yarn.server.resourcemanager.scheduler.capacity.ParentQueue: Re-sorting queues since queue: root.default stats: default: capacity=1.0, absoluteCapacity=1.0, usedResources=<memory:32768, vCores:27>usedCapacity=0.6666667, absoluteUsedCapacity=0.6666667, numApps=5, numContainers=27
2013-08-10 14:29:07,574 INFO org.apache.hadoop.yarn.server.resourcemanager.scheduler.capacity.ParentQueue: assignedContainer queue=root usedCapacity=0.6666667 absoluteUsedCapacity=0.6666667 used=<memory:32768, vCores:27> cluster=<memory:49152, vCores:96>
2013-08-10 14:29:07,574 INFO org.apache.hadoop.yarn.server.resourcemanager.rmcontainer.RMContainerImpl: container_1376143950665_0010_01_000024 Container Transitioned from NEW to ALLOCATED
2013-08-10 14:29:07,574 INFO org.apache.hadoop.yarn.server.resourcemanager.RMAuditLogger: USER=ubuntu	OPERATION=AM Allocated Container	TARGET=SchedulerApp	RESULT=SUCCESS	APPID=application_1376143950665_0010	CONTAINERID=container_1376143950665_0010_01_000024
2013-08-10 14:29:07,574 INFO org.apache.hadoop.yarn.server.resourcemanager.scheduler.common.fica.FiCaSchedulerNode: Assigned container container_1376143950665_0010_01_000024 of capacity <memory:1024, vCores:1> on host hadoop-221-6:51695, which currently has 6 containers, <memory:7168, vCores:6> used and <memory:1024, vCores:10> available
2013-08-10 14:29:07,575 INFO org.apache.hadoop.yarn.server.resourcemanager.scheduler.capacity.LeafQueue: assignedContainer application=application_1376143950665_0010 container=Container: [ContainerId: container_1376143950665_0010_01_000024, NodeId: hadoop-221-6:51695, NodeHttpAddress: hadoop-221-6:8042, Resource: <memory:1024, vCores:1>, Priority: 20, State: NEW, Token: null, Status: container_id {, app_attempt_id {, application_id {, id: 10, cluster_timestamp: 1376143950665, }, attemptId: 1, }, id: 24, }, state: C_NEW, ] containerId=container_1376143950665_0010_01_000024 queue=default: capacity=1.0, absoluteCapacity=1.0, usedResources=<memory:32768, vCores:27>usedCapacity=0.6666667, absoluteUsedCapacity=0.6666667, numApps=5, numContainers=27 usedCapacity=0.6666667 absoluteUsedCapacity=0.6666667 used=<memory:32768, vCores:27> cluster=<memory:49152, vCores:96>
2013-08-10 14:29:07,576 INFO org.apache.hadoop.yarn.server.resourcemanager.scheduler.capacity.ParentQueue: Re-sorting queues since queue: root.default stats: default: capacity=1.0, absoluteCapacity=1.0, usedResources=<memory:33792, vCores:28>usedCapacity=0.6875, absoluteUsedCapacity=0.6875, numApps=5, numContainers=28
2013-08-10 14:29:07,576 INFO org.apache.hadoop.yarn.server.resourcemanager.scheduler.capacity.ParentQueue: assignedContainer queue=root usedCapacity=0.6875 absoluteUsedCapacity=0.6875 used=<memory:33792, vCores:28> cluster=<memory:49152, vCores:96>
2013-08-10 14:29:07,576 INFO org.apache.hadoop.yarn.server.resourcemanager.rmcontainer.RMContainerImpl: container_1376143950665_0010_01_000025 Container Transitioned from NEW to ALLOCATED
2013-08-10 14:29:07,576 INFO org.apache.hadoop.yarn.server.resourcemanager.RMAuditLogger: USER=ubuntu	OPERATION=AM Allocated Container	TARGET=SchedulerApp	RESULT=SUCCESS	APPID=application_1376143950665_0010	CONTAINERID=container_1376143950665_0010_01_000025
2013-08-10 14:29:07,577 INFO org.apache.hadoop.yarn.server.resourcemanager.scheduler.common.fica.FiCaSchedulerNode: Assigned container container_1376143950665_0010_01_000025 of capacity <memory:1024, vCores:1> on host hadoop-221-6:51695, which currently has 7 containers, <memory:8192, vCores:7> used and <memory:0, vCores:9> available
2013-08-10 14:29:07,577 INFO org.apache.hadoop.yarn.server.resourcemanager.scheduler.capacity.LeafQueue: assignedContainer application=application_1376143950665_0010 container=Container: [ContainerId: container_1376143950665_0010_01_000025, NodeId: hadoop-221-6:51695, NodeHttpAddress: hadoop-221-6:8042, Resource: <memory:1024, vCores:1>, Priority: 20, State: NEW, Token: null, Status: container_id {, app_attempt_id {, application_id {, id: 10, cluster_timestamp: 1376143950665, }, attemptId: 1, }, id: 25, }, state: C_NEW, ] containerId=container_1376143950665_0010_01_000025 queue=default: capacity=1.0, absoluteCapacity=1.0, usedResources=<memory:33792, vCores:28>usedCapacity=0.6875, absoluteUsedCapacity=0.6875, numApps=5, numContainers=28 usedCapacity=0.6875 absoluteUsedCapacity=0.6875 used=<memory:33792, vCores:28> cluster=<memory:49152, vCores:96>
2013-08-10 14:29:07,578 INFO org.apache.hadoop.yarn.server.resourcemanager.scheduler.capacity.ParentQueue: Re-sorting queues since queue: root.default stats: default: capacity=1.0, absoluteCapacity=1.0, usedResources=<memory:34816, vCores:29>usedCapacity=0.7083333, absoluteUsedCapacity=0.7083333, numApps=5, numContainers=29
2013-08-10 14:29:07,578 INFO org.apache.hadoop.yarn.server.resourcemanager.scheduler.capacity.ParentQueue: assignedContainer queue=root usedCapacity=0.7083333 absoluteUsedCapacity=0.7083333 used=<memory:34816, vCores:29> cluster=<memory:49152, vCores:96>
2013-08-10 14:29:07,711 INFO org.apache.hadoop.yarn.server.resourcemanager.rmcontainer.RMContainerImpl: container_1376143950665_0010_01_000026 Container Transitioned from NEW to ALLOCATED
2013-08-10 14:29:07,711 INFO org.apache.hadoop.yarn.server.resourcemanager.RMAuditLogger: USER=ubuntu	OPERATION=AM Allocated Container	TARGET=SchedulerApp	RESULT=SUCCESS	APPID=application_1376143950665_0010	CONTAINERID=container_1376143950665_0010_01_000026
2013-08-10 14:29:07,711 INFO org.apache.hadoop.yarn.server.resourcemanager.scheduler.common.fica.FiCaSchedulerNode: Assigned container container_1376143950665_0010_01_000026 of capacity <memory:1024, vCores:1> on host hadoop-221-3:48808, which currently has 1 containers, <memory:1024, vCores:1> used and <memory:7168, vCores:15> available
2013-08-10 14:29:07,713 INFO org.apache.hadoop.yarn.server.resourcemanager.scheduler.capacity.LeafQueue: assignedContainer application=application_1376143950665_0010 container=Container: [ContainerId: container_1376143950665_0010_01_000026, NodeId: hadoop-221-3:48808, NodeHttpAddress: hadoop-221-3:8042, Resource: <memory:1024, vCores:1>, Priority: 20, State: NEW, Token: null, Status: container_id {, app_attempt_id {, application_id {, id: 10, cluster_timestamp: 1376143950665, }, attemptId: 1, }, id: 26, }, state: C_NEW, ] containerId=container_1376143950665_0010_01_000026 queue=default: capacity=1.0, absoluteCapacity=1.0, usedResources=<memory:34816, vCores:29>usedCapacity=0.7083333, absoluteUsedCapacity=0.7083333, numApps=5, numContainers=29 usedCapacity=0.7083333 absoluteUsedCapacity=0.7083333 used=<memory:34816, vCores:29> cluster=<memory:49152, vCores:96>
2013-08-10 14:29:07,713 INFO org.apache.hadoop.yarn.server.resourcemanager.scheduler.capacity.ParentQueue: Re-sorting queues since queue: root.default stats: default: capacity=1.0, absoluteCapacity=1.0, usedResources=<memory:35840, vCores:30>usedCapacity=0.7291667, absoluteUsedCapacity=0.7291667, numApps=5, numContainers=30
2013-08-10 14:29:07,714 INFO org.apache.hadoop.yarn.server.resourcemanager.scheduler.capacity.ParentQueue: assignedContainer queue=root usedCapacity=0.7291667 absoluteUsedCapacity=0.7291667 used=<memory:35840, vCores:30> cluster=<memory:49152, vCores:96>
2013-08-10 14:29:07,715 INFO org.apache.hadoop.yarn.server.resourcemanager.rmcontainer.RMContainerImpl: container_1376143950665_0010_01_000027 Container Transitioned from NEW to ALLOCATED
2013-08-10 14:29:07,715 INFO org.apache.hadoop.yarn.server.resourcemanager.RMAuditLogger: USER=ubuntu	OPERATION=AM Allocated Container	TARGET=SchedulerApp	RESULT=SUCCESS	APPID=application_1376143950665_0010	CONTAINERID=container_1376143950665_0010_01_000027
2013-08-10 14:29:07,715 INFO org.apache.hadoop.yarn.server.resourcemanager.scheduler.common.fica.FiCaSchedulerNode: Assigned container container_1376143950665_0010_01_000027 of capacity <memory:1024, vCores:1> on host hadoop-221-3:48808, which currently has 2 containers, <memory:2048, vCores:2> used and <memory:6144, vCores:14> available
2013-08-10 14:29:07,716 INFO org.apache.hadoop.yarn.server.resourcemanager.scheduler.capacity.LeafQueue: assignedContainer application=application_1376143950665_0010 container=Container: [ContainerId: container_1376143950665_0010_01_000027, NodeId: hadoop-221-3:48808, NodeHttpAddress: hadoop-221-3:8042, Resource: <memory:1024, vCores:1>, Priority: 20, State: NEW, Token: null, Status: container_id {, app_attempt_id {, application_id {, id: 10, cluster_timestamp: 1376143950665, }, attemptId: 1, }, id: 27, }, state: C_NEW, ] containerId=container_1376143950665_0010_01_000027 queue=default: capacity=1.0, absoluteCapacity=1.0, usedResources=<memory:35840, vCores:30>usedCapacity=0.7291667, absoluteUsedCapacity=0.7291667, numApps=5, numContainers=30 usedCapacity=0.7291667 absoluteUsedCapacity=0.7291667 used=<memory:35840, vCores:30> cluster=<memory:49152, vCores:96>
2013-08-10 14:29:07,716 INFO org.apache.hadoop.yarn.server.resourcemanager.scheduler.capacity.ParentQueue: Re-sorting queues since queue: root.default stats: default: capacity=1.0, absoluteCapacity=1.0, usedResources=<memory:36864, vCores:31>usedCapacity=0.75, absoluteUsedCapacity=0.75, numApps=5, numContainers=31
2013-08-10 14:29:07,716 INFO org.apache.hadoop.yarn.server.resourcemanager.scheduler.capacity.ParentQueue: assignedContainer queue=root usedCapacity=0.75 absoluteUsedCapacity=0.75 used=<memory:36864, vCores:31> cluster=<memory:49152, vCores:96>
2013-08-10 14:29:07,717 INFO org.apache.hadoop.yarn.server.resourcemanager.rmcontainer.RMContainerImpl: container_1376143950665_0010_01_000028 Container Transitioned from NEW to ALLOCATED
2013-08-10 14:29:07,717 INFO org.apache.hadoop.yarn.server.resourcemanager.RMAuditLogger: USER=ubuntu	OPERATION=AM Allocated Container	TARGET=SchedulerApp	RESULT=SUCCESS	APPID=application_1376143950665_0010	CONTAINERID=container_1376143950665_0010_01_000028
2013-08-10 14:29:07,717 INFO org.apache.hadoop.yarn.server.resourcemanager.scheduler.common.fica.FiCaSchedulerNode: Assigned container container_1376143950665_0010_01_000028 of capacity <memory:1024, vCores:1> on host hadoop-221-3:48808, which currently has 3 containers, <memory:3072, vCores:3> used and <memory:5120, vCores:13> available
2013-08-10 14:29:07,718 INFO org.apache.hadoop.yarn.server.resourcemanager.scheduler.capacity.LeafQueue: assignedContainer application=application_1376143950665_0010 container=Container: [ContainerId: container_1376143950665_0010_01_000028, NodeId: hadoop-221-3:48808, NodeHttpAddress: hadoop-221-3:8042, Resource: <memory:1024, vCores:1>, Priority: 20, State: NEW, Token: null, Status: container_id {, app_attempt_id {, application_id {, id: 10, cluster_timestamp: 1376143950665, }, attemptId: 1, }, id: 28, }, state: C_NEW, ] containerId=container_1376143950665_0010_01_000028 queue=default: capacity=1.0, absoluteCapacity=1.0, usedResources=<memory:36864, vCores:31>usedCapacity=0.75, absoluteUsedCapacity=0.75, numApps=5, numContainers=31 usedCapacity=0.75 absoluteUsedCapacity=0.75 used=<memory:36864, vCores:31> cluster=<memory:49152, vCores:96>
2013-08-10 14:29:07,718 INFO org.apache.hadoop.yarn.server.resourcemanager.scheduler.capacity.ParentQueue: Re-sorting queues since queue: root.default stats: default: capacity=1.0, absoluteCapacity=1.0, usedResources=<memory:37888, vCores:32>usedCapacity=0.7708333, absoluteUsedCapacity=0.7708333, numApps=5, numContainers=32
2013-08-10 14:29:07,719 INFO org.apache.hadoop.yarn.server.resourcemanager.scheduler.capacity.ParentQueue: assignedContainer queue=root usedCapacity=0.7708333 absoluteUsedCapacity=0.7708333 used=<memory:37888, vCores:32> cluster=<memory:49152, vCores:96>
2013-08-10 14:29:07,719 INFO org.apache.hadoop.yarn.server.resourcemanager.rmcontainer.RMContainerImpl: container_1376143950665_0010_01_000029 Container Transitioned from NEW to ALLOCATED
2013-08-10 14:29:07,719 INFO org.apache.hadoop.yarn.server.resourcemanager.RMAuditLogger: USER=ubuntu	OPERATION=AM Allocated Container	TARGET=SchedulerApp	RESULT=SUCCESS	APPID=application_1376143950665_0010	CONTAINERID=container_1376143950665_0010_01_000029
2013-08-10 14:29:07,719 INFO org.apache.hadoop.yarn.server.resourcemanager.scheduler.common.fica.FiCaSchedulerNode: Assigned container container_1376143950665_0010_01_000029 of capacity <memory:1024, vCores:1> on host hadoop-221-3:48808, which currently has 4 containers, <memory:4096, vCores:4> used and <memory:4096, vCores:12> available
2013-08-10 14:29:07,720 INFO org.apache.hadoop.yarn.server.resourcemanager.scheduler.capacity.LeafQueue: assignedContainer application=application_1376143950665_0010 container=Container: [ContainerId: container_1376143950665_0010_01_000029, NodeId: hadoop-221-3:48808, NodeHttpAddress: hadoop-221-3:8042, Resource: <memory:1024, vCores:1>, Priority: 20, State: NEW, Token: null, Status: container_id {, app_attempt_id {, application_id {, id: 10, cluster_timestamp: 1376143950665, }, attemptId: 1, }, id: 29, }, state: C_NEW, ] containerId=container_1376143950665_0010_01_000029 queue=default: capacity=1.0, absoluteCapacity=1.0, usedResources=<memory:37888, vCores:32>usedCapacity=0.7708333, absoluteUsedCapacity=0.7708333, numApps=5, numContainers=32 usedCapacity=0.7708333 absoluteUsedCapacity=0.7708333 used=<memory:37888, vCores:32> cluster=<memory:49152, vCores:96>
2013-08-10 14:29:07,720 INFO org.apache.hadoop.yarn.server.resourcemanager.scheduler.capacity.ParentQueue: Re-sorting queues since queue: root.default stats: default: capacity=1.0, absoluteCapacity=1.0, usedResources=<memory:38912, vCores:33>usedCapacity=0.7916667, absoluteUsedCapacity=0.7916667, numApps=5, numContainers=33
2013-08-10 14:29:07,721 INFO org.apache.hadoop.yarn.server.resourcemanager.scheduler.capacity.ParentQueue: assignedContainer queue=root usedCapacity=0.7916667 absoluteUsedCapacity=0.7916667 used=<memory:38912, vCores:33> cluster=<memory:49152, vCores:96>
2013-08-10 14:29:07,721 INFO org.apache.hadoop.yarn.server.resourcemanager.rmcontainer.RMContainerImpl: container_1376143950665_0010_01_000030 Container Transitioned from NEW to ALLOCATED
2013-08-10 14:29:07,721 INFO org.apache.hadoop.yarn.server.resourcemanager.RMAuditLogger: USER=ubuntu	OPERATION=AM Allocated Container	TARGET=SchedulerApp	RESULT=SUCCESS	APPID=application_1376143950665_0010	CONTAINERID=container_1376143950665_0010_01_000030
2013-08-10 14:29:07,721 INFO org.apache.hadoop.yarn.server.resourcemanager.scheduler.common.fica.FiCaSchedulerNode: Assigned container container_1376143950665_0010_01_000030 of capacity <memory:1024, vCores:1> on host hadoop-221-3:48808, which currently has 5 containers, <memory:5120, vCores:5> used and <memory:3072, vCores:11> available
2013-08-10 14:29:07,722 INFO org.apache.hadoop.yarn.server.resourcemanager.scheduler.capacity.LeafQueue: assignedContainer application=application_1376143950665_0010 container=Container: [ContainerId: container_1376143950665_0010_01_000030, NodeId: hadoop-221-3:48808, NodeHttpAddress: hadoop-221-3:8042, Resource: <memory:1024, vCores:1>, Priority: 20, State: NEW, Token: null, Status: container_id {, app_attempt_id {, application_id {, id: 10, cluster_timestamp: 1376143950665, }, attemptId: 1, }, id: 30, }, state: C_NEW, ] containerId=container_1376143950665_0010_01_000030 queue=default: capacity=1.0, absoluteCapacity=1.0, usedResources=<memory:38912, vCores:33>usedCapacity=0.7916667, absoluteUsedCapacity=0.7916667, numApps=5, numContainers=33 usedCapacity=0.7916667 absoluteUsedCapacity=0.7916667 used=<memory:38912, vCores:33> cluster=<memory:49152, vCores:96>
2013-08-10 14:29:07,723 INFO org.apache.hadoop.yarn.server.resourcemanager.scheduler.capacity.ParentQueue: Re-sorting queues since queue: root.default stats: default: capacity=1.0, absoluteCapacity=1.0, usedResources=<memory:39936, vCores:34>usedCapacity=0.8125, absoluteUsedCapacity=0.8125, numApps=5, numContainers=34
2013-08-10 14:29:07,723 INFO org.apache.hadoop.yarn.server.resourcemanager.scheduler.capacity.ParentQueue: assignedContainer queue=root usedCapacity=0.8125 absoluteUsedCapacity=0.8125 used=<memory:39936, vCores:34> cluster=<memory:49152, vCores:96>
2013-08-10 14:29:07,723 INFO org.apache.hadoop.yarn.server.resourcemanager.rmcontainer.RMContainerImpl: container_1376143950665_0010_01_000031 Container Transitioned from NEW to ALLOCATED
2013-08-10 14:29:07,723 INFO org.apache.hadoop.yarn.server.resourcemanager.RMAuditLogger: USER=ubuntu	OPERATION=AM Allocated Container	TARGET=SchedulerApp	RESULT=SUCCESS	APPID=application_1376143950665_0010	CONTAINERID=container_1376143950665_0010_01_000031
2013-08-10 14:29:07,723 INFO org.apache.hadoop.yarn.server.resourcemanager.scheduler.common.fica.FiCaSchedulerNode: Assigned container container_1376143950665_0010_01_000031 of capacity <memory:1024, vCores:1> on host hadoop-221-3:48808, which currently has 6 containers, <memory:6144, vCores:6> used and <memory:2048, vCores:10> available
2013-08-10 14:29:07,724 INFO org.apache.hadoop.yarn.server.resourcemanager.scheduler.capacity.LeafQueue: assignedContainer application=application_1376143950665_0010 container=Container: [ContainerId: container_1376143950665_0010_01_000031, NodeId: hadoop-221-3:48808, NodeHttpAddress: hadoop-221-3:8042, Resource: <memory:1024, vCores:1>, Priority: 20, State: NEW, Token: null, Status: container_id {, app_attempt_id {, application_id {, id: 10, cluster_timestamp: 1376143950665, }, attemptId: 1, }, id: 31, }, state: C_NEW, ] containerId=container_1376143950665_0010_01_000031 queue=default: capacity=1.0, absoluteCapacity=1.0, usedResources=<memory:39936, vCores:34>usedCapacity=0.8125, absoluteUsedCapacity=0.8125, numApps=5, numContainers=34 usedCapacity=0.8125 absoluteUsedCapacity=0.8125 used=<memory:39936, vCores:34> cluster=<memory:49152, vCores:96>
2013-08-10 14:29:07,725 INFO org.apache.hadoop.yarn.server.resourcemanager.scheduler.capacity.ParentQueue: Re-sorting queues since queue: root.default stats: default: capacity=1.0, absoluteCapacity=1.0, usedResources=<memory:40960, vCores:35>usedCapacity=0.8333333, absoluteUsedCapacity=0.8333333, numApps=5, numContainers=35
2013-08-10 14:29:07,725 INFO org.apache.hadoop.yarn.server.resourcemanager.scheduler.capacity.ParentQueue: assignedContainer queue=root usedCapacity=0.8333333 absoluteUsedCapacity=0.8333333 used=<memory:40960, vCores:35> cluster=<memory:49152, vCores:96>
2013-08-10 14:29:07,725 INFO org.apache.hadoop.yarn.server.resourcemanager.rmcontainer.RMContainerImpl: container_1376143950665_0010_01_000032 Container Transitioned from NEW to ALLOCATED
2013-08-10 14:29:07,725 INFO org.apache.hadoop.yarn.server.resourcemanager.RMAuditLogger: USER=ubuntu	OPERATION=AM Allocated Container	TARGET=SchedulerApp	RESULT=SUCCESS	APPID=application_1376143950665_0010	CONTAINERID=container_1376143950665_0010_01_000032
2013-08-10 14:29:07,726 INFO org.apache.hadoop.yarn.server.resourcemanager.scheduler.common.fica.FiCaSchedulerNode: Assigned container container_1376143950665_0010_01_000032 of capacity <memory:1024, vCores:1> on host hadoop-221-3:48808, which currently has 7 containers, <memory:7168, vCores:7> used and <memory:1024, vCores:9> available
2013-08-10 14:29:07,726 INFO org.apache.hadoop.yarn.server.resourcemanager.scheduler.capacity.LeafQueue: assignedContainer application=application_1376143950665_0010 container=Container: [ContainerId: container_1376143950665_0010_01_000032, NodeId: hadoop-221-3:48808, NodeHttpAddress: hadoop-221-3:8042, Resource: <memory:1024, vCores:1>, Priority: 20, State: NEW, Token: null, Status: container_id {, app_attempt_id {, application_id {, id: 10, cluster_timestamp: 1376143950665, }, attemptId: 1, }, id: 32, }, state: C_NEW, ] containerId=container_1376143950665_0010_01_000032 queue=default: capacity=1.0, absoluteCapacity=1.0, usedResources=<memory:40960, vCores:35>usedCapacity=0.8333333, absoluteUsedCapacity=0.8333333, numApps=5, numContainers=35 usedCapacity=0.8333333 absoluteUsedCapacity=0.8333333 used=<memory:40960, vCores:35> cluster=<memory:49152, vCores:96>
2013-08-10 14:29:07,727 INFO org.apache.hadoop.yarn.server.resourcemanager.scheduler.capacity.ParentQueue: Re-sorting queues since queue: root.default stats: default: capacity=1.0, absoluteCapacity=1.0, usedResources=<memory:41984, vCores:36>usedCapacity=0.8541667, absoluteUsedCapacity=0.8541667, numApps=5, numContainers=36
2013-08-10 14:29:07,727 INFO org.apache.hadoop.yarn.server.resourcemanager.scheduler.capacity.ParentQueue: assignedContainer queue=root usedCapacity=0.8541667 absoluteUsedCapacity=0.8541667 used=<memory:41984, vCores:36> cluster=<memory:49152, vCores:96>
2013-08-10 14:29:07,727 INFO org.apache.hadoop.yarn.server.resourcemanager.rmcontainer.RMContainerImpl: container_1376143950665_0010_01_000033 Container Transitioned from NEW to ALLOCATED
2013-08-10 14:29:07,727 INFO org.apache.hadoop.yarn.server.resourcemanager.RMAuditLogger: USER=ubuntu	OPERATION=AM Allocated Container	TARGET=SchedulerApp	RESULT=SUCCESS	APPID=application_1376143950665_0010	CONTAINERID=container_1376143950665_0010_01_000033
2013-08-10 14:29:07,728 INFO org.apache.hadoop.yarn.server.resourcemanager.scheduler.common.fica.FiCaSchedulerNode: Assigned container container_1376143950665_0010_01_000033 of capacity <memory:1024, vCores:1> on host hadoop-221-3:48808, which currently has 8 containers, <memory:8192, vCores:8> used and <memory:0, vCores:8> available
2013-08-10 14:29:07,729 INFO org.apache.hadoop.yarn.server.resourcemanager.scheduler.capacity.LeafQueue: assignedContainer application=application_1376143950665_0010 container=Container: [ContainerId: container_1376143950665_0010_01_000033, NodeId: hadoop-221-3:48808, NodeHttpAddress: hadoop-221-3:8042, Resource: <memory:1024, vCores:1>, Priority: 20, State: NEW, Token: null, Status: container_id {, app_attempt_id {, application_id {, id: 10, cluster_timestamp: 1376143950665, }, attemptId: 1, }, id: 33, }, state: C_NEW, ] containerId=container_1376143950665_0010_01_000033 queue=default: capacity=1.0, absoluteCapacity=1.0, usedResources=<memory:41984, vCores:36>usedCapacity=0.8541667, absoluteUsedCapacity=0.8541667, numApps=5, numContainers=36 usedCapacity=0.8541667 absoluteUsedCapacity=0.8541667 used=<memory:41984, vCores:36> cluster=<memory:49152, vCores:96>
2013-08-10 14:29:07,729 INFO org.apache.hadoop.yarn.server.resourcemanager.scheduler.capacity.ParentQueue: Re-sorting queues since queue: root.default stats: default: capacity=1.0, absoluteCapacity=1.0, usedResources=<memory:43008, vCores:37>usedCapacity=0.875, absoluteUsedCapacity=0.875, numApps=5, numContainers=37
2013-08-10 14:29:07,729 INFO org.apache.hadoop.yarn.server.resourcemanager.scheduler.capacity.ParentQueue: assignedContainer queue=root usedCapacity=0.875 absoluteUsedCapacity=0.875 used=<memory:43008, vCores:37> cluster=<memory:49152, vCores:96>
2013-08-10 14:29:07,905 INFO org.apache.hadoop.yarn.server.resourcemanager.rmcontainer.RMContainerImpl: container_1376143950665_0010_01_000034 Container Transitioned from NEW to ALLOCATED
2013-08-10 14:29:07,905 INFO org.apache.hadoop.yarn.server.resourcemanager.RMAuditLogger: USER=ubuntu	OPERATION=AM Allocated Container	TARGET=SchedulerApp	RESULT=SUCCESS	APPID=application_1376143950665_0010	CONTAINERID=container_1376143950665_0010_01_000034
2013-08-10 14:29:07,905 INFO org.apache.hadoop.yarn.server.resourcemanager.scheduler.common.fica.FiCaSchedulerNode: Assigned container container_1376143950665_0010_01_000034 of capacity <memory:1024, vCores:1> on host hadoop-221-7:43558, which currently has 2 containers, <memory:3072, vCores:2> used and <memory:5120, vCores:14> available
2013-08-10 14:29:07,906 INFO org.apache.hadoop.yarn.server.resourcemanager.scheduler.capacity.LeafQueue: assignedContainer application=application_1376143950665_0010 container=Container: [ContainerId: container_1376143950665_0010_01_000034, NodeId: hadoop-221-7:43558, NodeHttpAddress: hadoop-221-7:8042, Resource: <memory:1024, vCores:1>, Priority: 20, State: NEW, Token: null, Status: container_id {, app_attempt_id {, application_id {, id: 10, cluster_timestamp: 1376143950665, }, attemptId: 1, }, id: 34, }, state: C_NEW, ] containerId=container_1376143950665_0010_01_000034 queue=default: capacity=1.0, absoluteCapacity=1.0, usedResources=<memory:43008, vCores:37>usedCapacity=0.875, absoluteUsedCapacity=0.875, numApps=5, numContainers=37 usedCapacity=0.875 absoluteUsedCapacity=0.875 used=<memory:43008, vCores:37> cluster=<memory:49152, vCores:96>
2013-08-10 14:29:07,906 INFO org.apache.hadoop.yarn.server.resourcemanager.scheduler.capacity.ParentQueue: Re-sorting queues since queue: root.default stats: default: capacity=1.0, absoluteCapacity=1.0, usedResources=<memory:44032, vCores:38>usedCapacity=0.8958333, absoluteUsedCapacity=0.8958333, numApps=5, numContainers=38
2013-08-10 14:29:07,907 INFO org.apache.hadoop.yarn.server.resourcemanager.scheduler.capacity.ParentQueue: assignedContainer queue=root usedCapacity=0.8958333 absoluteUsedCapacity=0.8958333 used=<memory:44032, vCores:38> cluster=<memory:49152, vCores:96>
2013-08-10 14:29:07,907 INFO org.apache.hadoop.yarn.server.resourcemanager.rmcontainer.RMContainerImpl: container_1376143950665_0010_01_000035 Container Transitioned from NEW to ALLOCATED
2013-08-10 14:29:07,907 INFO org.apache.hadoop.yarn.server.resourcemanager.RMAuditLogger: USER=ubuntu	OPERATION=AM Allocated Container	TARGET=SchedulerApp	RESULT=SUCCESS	APPID=application_1376143950665_0010	CONTAINERID=container_1376143950665_0010_01_000035
2013-08-10 14:29:07,907 INFO org.apache.hadoop.yarn.server.resourcemanager.scheduler.common.fica.FiCaSchedulerNode: Assigned container container_1376143950665_0010_01_000035 of capacity <memory:1024, vCores:1> on host hadoop-221-7:43558, which currently has 3 containers, <memory:4096, vCores:3> used and <memory:4096, vCores:13> available
2013-08-10 14:29:07,908 INFO org.apache.hadoop.yarn.server.resourcemanager.scheduler.capacity.LeafQueue: assignedContainer application=application_1376143950665_0010 container=Container: [ContainerId: container_1376143950665_0010_01_000035, NodeId: hadoop-221-7:43558, NodeHttpAddress: hadoop-221-7:8042, Resource: <memory:1024, vCores:1>, Priority: 20, State: NEW, Token: null, Status: container_id {, app_attempt_id {, application_id {, id: 10, cluster_timestamp: 1376143950665, }, attemptId: 1, }, id: 35, }, state: C_NEW, ] containerId=container_1376143950665_0010_01_000035 queue=default: capacity=1.0, absoluteCapacity=1.0, usedResources=<memory:44032, vCores:38>usedCapacity=0.8958333, absoluteUsedCapacity=0.8958333, numApps=5, numContainers=38 usedCapacity=0.8958333 absoluteUsedCapacity=0.8958333 used=<memory:44032, vCores:38> cluster=<memory:49152, vCores:96>
2013-08-10 14:29:07,909 INFO org.apache.hadoop.yarn.server.resourcemanager.scheduler.capacity.ParentQueue: Re-sorting queues since queue: root.default stats: default: capacity=1.0, absoluteCapacity=1.0, usedResources=<memory:45056, vCores:39>usedCapacity=0.9166667, absoluteUsedCapacity=0.9166667, numApps=5, numContainers=39
2013-08-10 14:29:07,909 INFO org.apache.hadoop.yarn.server.resourcemanager.scheduler.capacity.ParentQueue: assignedContainer queue=root usedCapacity=0.9166667 absoluteUsedCapacity=0.9166667 used=<memory:45056, vCores:39> cluster=<memory:49152, vCores:96>
2013-08-10 14:29:07,909 INFO org.apache.hadoop.yarn.server.resourcemanager.rmcontainer.RMContainerImpl: container_1376143950665_0010_01_000036 Container Transitioned from NEW to ALLOCATED
2013-08-10 14:29:07,909 INFO org.apache.hadoop.yarn.server.resourcemanager.RMAuditLogger: USER=ubuntu	OPERATION=AM Allocated Container	TARGET=SchedulerApp	RESULT=SUCCESS	APPID=application_1376143950665_0010	CONTAINERID=container_1376143950665_0010_01_000036
2013-08-10 14:29:07,909 INFO org.apache.hadoop.yarn.server.resourcemanager.scheduler.common.fica.FiCaSchedulerNode: Assigned container container_1376143950665_0010_01_000036 of capacity <memory:1024, vCores:1> on host hadoop-221-7:43558, which currently has 4 containers, <memory:5120, vCores:4> used and <memory:3072, vCores:12> available
2013-08-10 14:29:07,910 INFO org.apache.hadoop.yarn.server.resourcemanager.scheduler.capacity.LeafQueue: assignedContainer application=application_1376143950665_0010 container=Container: [ContainerId: container_1376143950665_0010_01_000036, NodeId: hadoop-221-7:43558, NodeHttpAddress: hadoop-221-7:8042, Resource: <memory:1024, vCores:1>, Priority: 20, State: NEW, Token: null, Status: container_id {, app_attempt_id {, application_id {, id: 10, cluster_timestamp: 1376143950665, }, attemptId: 1, }, id: 36, }, state: C_NEW, ] containerId=container_1376143950665_0010_01_000036 queue=default: capacity=1.0, absoluteCapacity=1.0, usedResources=<memory:45056, vCores:39>usedCapacity=0.9166667, absoluteUsedCapacity=0.9166667, numApps=5, numContainers=39 usedCapacity=0.9166667 absoluteUsedCapacity=0.9166667 used=<memory:45056, vCores:39> cluster=<memory:49152, vCores:96>
2013-08-10 14:29:07,911 INFO org.apache.hadoop.yarn.server.resourcemanager.scheduler.capacity.ParentQueue: Re-sorting queues since queue: root.default stats: default: capacity=1.0, absoluteCapacity=1.0, usedResources=<memory:46080, vCores:40>usedCapacity=0.9375, absoluteUsedCapacity=0.9375, numApps=5, numContainers=40
2013-08-10 14:29:07,911 INFO org.apache.hadoop.yarn.server.resourcemanager.scheduler.capacity.ParentQueue: assignedContainer queue=root usedCapacity=0.9375 absoluteUsedCapacity=0.9375 used=<memory:46080, vCores:40> cluster=<memory:49152, vCores:96>
2013-08-10 14:29:07,911 INFO org.apache.hadoop.yarn.server.resourcemanager.rmcontainer.RMContainerImpl: container_1376143950665_0010_01_000037 Container Transitioned from NEW to ALLOCATED
2013-08-10 14:29:07,911 INFO org.apache.hadoop.yarn.server.resourcemanager.RMAuditLogger: USER=ubuntu	OPERATION=AM Allocated Container	TARGET=SchedulerApp	RESULT=SUCCESS	APPID=application_1376143950665_0010	CONTAINERID=container_1376143950665_0010_01_000037
2013-08-10 14:29:07,911 INFO org.apache.hadoop.yarn.server.resourcemanager.scheduler.common.fica.FiCaSchedulerNode: Assigned container container_1376143950665_0010_01_000037 of capacity <memory:1024, vCores:1> on host hadoop-221-7:43558, which currently has 5 containers, <memory:6144, vCores:5> used and <memory:2048, vCores:11> available
2013-08-10 14:29:07,912 INFO org.apache.hadoop.yarn.server.resourcemanager.scheduler.capacity.LeafQueue: assignedContainer application=application_1376143950665_0010 container=Container: [ContainerId: container_1376143950665_0010_01_000037, NodeId: hadoop-221-7:43558, NodeHttpAddress: hadoop-221-7:8042, Resource: <memory:1024, vCores:1>, Priority: 20, State: NEW, Token: null, Status: container_id {, app_attempt_id {, application_id {, id: 10, cluster_timestamp: 1376143950665, }, attemptId: 1, }, id: 37, }, state: C_NEW, ] containerId=container_1376143950665_0010_01_000037 queue=default: capacity=1.0, absoluteCapacity=1.0, usedResources=<memory:46080, vCores:40>usedCapacity=0.9375, absoluteUsedCapacity=0.9375, numApps=5, numContainers=40 usedCapacity=0.9375 absoluteUsedCapacity=0.9375 used=<memory:46080, vCores:40> cluster=<memory:49152, vCores:96>
2013-08-10 14:29:07,913 INFO org.apache.hadoop.yarn.server.resourcemanager.scheduler.capacity.ParentQueue: Re-sorting queues since queue: root.default stats: default: capacity=1.0, absoluteCapacity=1.0, usedResources=<memory:47104, vCores:41>usedCapacity=0.9583333, absoluteUsedCapacity=0.9583333, numApps=5, numContainers=41
2013-08-10 14:29:07,913 INFO org.apache.hadoop.yarn.server.resourcemanager.scheduler.capacity.ParentQueue: assignedContainer queue=root usedCapacity=0.9583333 absoluteUsedCapacity=0.9583333 used=<memory:47104, vCores:41> cluster=<memory:49152, vCores:96>
2013-08-10 14:29:07,913 INFO org.apache.hadoop.yarn.server.resourcemanager.rmcontainer.RMContainerImpl: container_1376143950665_0010_01_000038 Container Transitioned from NEW to ALLOCATED
2013-08-10 14:29:07,913 INFO org.apache.hadoop.yarn.server.resourcemanager.RMAuditLogger: USER=ubuntu	OPERATION=AM Allocated Container	TARGET=SchedulerApp	RESULT=SUCCESS	APPID=application_1376143950665_0010	CONTAINERID=container_1376143950665_0010_01_000038
2013-08-10 14:29:07,914 INFO org.apache.hadoop.yarn.server.resourcemanager.scheduler.common.fica.FiCaSchedulerNode: Assigned container container_1376143950665_0010_01_000038 of capacity <memory:1024, vCores:1> on host hadoop-221-7:43558, which currently has 6 containers, <memory:7168, vCores:6> used and <memory:1024, vCores:10> available
2013-08-10 14:29:07,914 INFO org.apache.hadoop.yarn.server.resourcemanager.scheduler.capacity.LeafQueue: assignedContainer application=application_1376143950665_0010 container=Container: [ContainerId: container_1376143950665_0010_01_000038, NodeId: hadoop-221-7:43558, NodeHttpAddress: hadoop-221-7:8042, Resource: <memory:1024, vCores:1>, Priority: 20, State: NEW, Token: null, Status: container_id {, app_attempt_id {, application_id {, id: 10, cluster_timestamp: 1376143950665, }, attemptId: 1, }, id: 38, }, state: C_NEW, ] containerId=container_1376143950665_0010_01_000038 queue=default: capacity=1.0, absoluteCapacity=1.0, usedResources=<memory:47104, vCores:41>usedCapacity=0.9583333, absoluteUsedCapacity=0.9583333, numApps=5, numContainers=41 usedCapacity=0.9583333 absoluteUsedCapacity=0.9583333 used=<memory:47104, vCores:41> cluster=<memory:49152, vCores:96>
2013-08-10 14:29:07,915 INFO org.apache.hadoop.yarn.server.resourcemanager.scheduler.capacity.ParentQueue: Re-sorting queues since queue: root.default stats: default: capacity=1.0, absoluteCapacity=1.0, usedResources=<memory:48128, vCores:42>usedCapacity=0.9791667, absoluteUsedCapacity=0.9791667, numApps=5, numContainers=42
2013-08-10 14:29:07,915 INFO org.apache.hadoop.yarn.server.resourcemanager.scheduler.capacity.ParentQueue: assignedContainer queue=root usedCapacity=0.9791667 absoluteUsedCapacity=0.9791667 used=<memory:48128, vCores:42> cluster=<memory:49152, vCores:96>
2013-08-10 14:29:07,915 INFO org.apache.hadoop.yarn.server.resourcemanager.rmcontainer.RMContainerImpl: container_1376143950665_0010_01_000039 Container Transitioned from NEW to ALLOCATED
2013-08-10 14:29:07,915 INFO org.apache.hadoop.yarn.server.resourcemanager.RMAuditLogger: USER=ubuntu	OPERATION=AM Allocated Container	TARGET=SchedulerApp	RESULT=SUCCESS	APPID=application_1376143950665_0010	CONTAINERID=container_1376143950665_0010_01_000039
2013-08-10 14:29:07,916 INFO org.apache.hadoop.yarn.server.resourcemanager.scheduler.common.fica.FiCaSchedulerNode: Assigned container container_1376143950665_0010_01_000039 of capacity <memory:1024, vCores:1> on host hadoop-221-7:43558, which currently has 7 containers, <memory:8192, vCores:7> used and <memory:0, vCores:9> available
2013-08-10 14:29:07,916 INFO org.apache.hadoop.yarn.server.resourcemanager.scheduler.capacity.LeafQueue: assignedContainer application=application_1376143950665_0010 container=Container: [ContainerId: container_1376143950665_0010_01_000039, NodeId: hadoop-221-7:43558, NodeHttpAddress: hadoop-221-7:8042, Resource: <memory:1024, vCores:1>, Priority: 20, State: NEW, Token: null, Status: container_id {, app_attempt_id {, application_id {, id: 10, cluster_timestamp: 1376143950665, }, attemptId: 1, }, id: 39, }, state: C_NEW, ] containerId=container_1376143950665_0010_01_000039 queue=default: capacity=1.0, absoluteCapacity=1.0, usedResources=<memory:48128, vCores:42>usedCapacity=0.9791667, absoluteUsedCapacity=0.9791667, numApps=5, numContainers=42 usedCapacity=0.9791667 absoluteUsedCapacity=0.9791667 used=<memory:48128, vCores:42> cluster=<memory:49152, vCores:96>
2013-08-10 14:29:07,917 INFO org.apache.hadoop.yarn.server.resourcemanager.scheduler.capacity.ParentQueue: Re-sorting queues since queue: root.default stats: default: capacity=1.0, absoluteCapacity=1.0, usedResources=<memory:49152, vCores:43>usedCapacity=1.0, absoluteUsedCapacity=1.0, numApps=5, numContainers=43
2013-08-10 14:29:07,917 INFO org.apache.hadoop.yarn.server.resourcemanager.scheduler.capacity.ParentQueue: assignedContainer queue=root usedCapacity=1.0 absoluteUsedCapacity=1.0 used=<memory:49152, vCores:43> cluster=<memory:49152, vCores:96>
2013-08-10 14:29:08,114 INFO org.apache.hadoop.yarn.server.resourcemanager.rmcontainer.RMContainerImpl: container_1376143950665_0010_01_000002 Container Transitioned from ALLOCATED to ACQUIRED
2013-08-10 14:29:08,115 INFO org.apache.hadoop.yarn.server.resourcemanager.rmcontainer.RMContainerImpl: container_1376143950665_0010_01_000003 Container Transitioned from ALLOCATED to ACQUIRED
2013-08-10 14:29:08,116 INFO org.apache.hadoop.yarn.server.resourcemanager.rmcontainer.RMContainerImpl: container_1376143950665_0010_01_000004 Container Transitioned from ALLOCATED to ACQUIRED
2013-08-10 14:29:08,116 INFO org.apache.hadoop.yarn.server.resourcemanager.rmcontainer.RMContainerImpl: container_1376143950665_0010_01_000005 Container Transitioned from ALLOCATED to ACQUIRED
2013-08-10 14:29:08,117 INFO org.apache.hadoop.yarn.server.resourcemanager.rmcontainer.RMContainerImpl: container_1376143950665_0010_01_000006 Container Transitioned from ALLOCATED to ACQUIRED
2013-08-10 14:29:08,118 INFO org.apache.hadoop.yarn.server.resourcemanager.rmcontainer.RMContainerImpl: container_1376143950665_0010_01_000007 Container Transitioned from ALLOCATED to ACQUIRED
2013-08-10 14:29:08,119 INFO org.apache.hadoop.yarn.server.resourcemanager.rmcontainer.RMContainerImpl: container_1376143950665_0010_01_000008 Container Transitioned from ALLOCATED to ACQUIRED
2013-08-10 14:29:08,119 INFO org.apache.hadoop.yarn.server.resourcemanager.rmcontainer.RMContainerImpl: container_1376143950665_0010_01_000009 Container Transitioned from ALLOCATED to ACQUIRED
2013-08-10 14:29:08,121 INFO org.apache.hadoop.yarn.server.resourcemanager.rmcontainer.RMContainerImpl: container_1376143950665_0010_01_000010 Container Transitioned from ALLOCATED to ACQUIRED
2013-08-10 14:29:08,124 INFO org.apache.hadoop.yarn.server.resourcemanager.rmcontainer.RMContainerImpl: container_1376143950665_0010_01_000011 Container Transitioned from ALLOCATED to ACQUIRED
2013-08-10 14:29:08,124 INFO org.apache.hadoop.yarn.server.resourcemanager.rmcontainer.RMContainerImpl: container_1376143950665_0010_01_000012 Container Transitioned from ALLOCATED to ACQUIRED
2013-08-10 14:29:08,124 INFO org.apache.hadoop.yarn.server.resourcemanager.rmcontainer.RMContainerImpl: container_1376143950665_0010_01_000013 Container Transitioned from ALLOCATED to ACQUIRED
2013-08-10 14:29:08,124 INFO org.apache.hadoop.yarn.server.resourcemanager.rmcontainer.RMContainerImpl: container_1376143950665_0010_01_000014 Container Transitioned from ALLOCATED to ACQUIRED
2013-08-10 14:29:08,125 INFO org.apache.hadoop.yarn.server.resourcemanager.rmcontainer.RMContainerImpl: container_1376143950665_0010_01_000015 Container Transitioned from ALLOCATED to ACQUIRED
2013-08-10 14:29:08,125 INFO org.apache.hadoop.yarn.server.resourcemanager.rmcontainer.RMContainerImpl: container_1376143950665_0010_01_000016 Container Transitioned from ALLOCATED to ACQUIRED
2013-08-10 14:29:08,125 INFO org.apache.hadoop.yarn.server.resourcemanager.rmcontainer.RMContainerImpl: container_1376143950665_0010_01_000017 Container Transitioned from ALLOCATED to ACQUIRED
2013-08-10 14:29:08,125 INFO org.apache.hadoop.yarn.server.resourcemanager.rmcontainer.RMContainerImpl: container_1376143950665_0010_01_000018 Container Transitioned from ALLOCATED to ACQUIRED
2013-08-10 14:29:08,125 INFO org.apache.hadoop.yarn.server.resourcemanager.rmcontainer.RMContainerImpl: container_1376143950665_0010_01_000019 Container Transitioned from ALLOCATED to ACQUIRED
2013-08-10 14:29:08,125 INFO org.apache.hadoop.yarn.server.resourcemanager.rmcontainer.RMContainerImpl: container_1376143950665_0010_01_000020 Container Transitioned from ALLOCATED to ACQUIRED
2013-08-10 14:29:08,126 INFO org.apache.hadoop.yarn.server.resourcemanager.rmcontainer.RMContainerImpl: container_1376143950665_0010_01_000021 Container Transitioned from ALLOCATED to ACQUIRED
2013-08-10 14:29:08,126 INFO org.apache.hadoop.yarn.server.resourcemanager.rmcontainer.RMContainerImpl: container_1376143950665_0010_01_000022 Container Transitioned from ALLOCATED to ACQUIRED
2013-08-10 14:29:08,126 INFO org.apache.hadoop.yarn.server.resourcemanager.rmcontainer.RMContainerImpl: container_1376143950665_0010_01_000023 Container Transitioned from ALLOCATED to ACQUIRED
2013-08-10 14:29:08,126 INFO org.apache.hadoop.yarn.server.resourcemanager.rmcontainer.RMContainerImpl: container_1376143950665_0010_01_000024 Container Transitioned from ALLOCATED to ACQUIRED
2013-08-10 14:29:08,126 INFO org.apache.hadoop.yarn.server.resourcemanager.rmcontainer.RMContainerImpl: container_1376143950665_0010_01_000025 Container Transitioned from ALLOCATED to ACQUIRED
2013-08-10 14:29:08,127 INFO org.apache.hadoop.yarn.server.resourcemanager.rmcontainer.RMContainerImpl: container_1376143950665_0010_01_000026 Container Transitioned from ALLOCATED to ACQUIRED
2013-08-10 14:29:08,127 INFO org.apache.hadoop.yarn.server.resourcemanager.rmcontainer.RMContainerImpl: container_1376143950665_0010_01_000027 Container Transitioned from ALLOCATED to ACQUIRED
2013-08-10 14:29:08,127 INFO org.apache.hadoop.yarn.server.resourcemanager.rmcontainer.RMContainerImpl: container_1376143950665_0010_01_000028 Container Transitioned from ALLOCATED to ACQUIRED
2013-08-10 14:29:08,127 INFO org.apache.hadoop.yarn.server.resourcemanager.rmcontainer.RMContainerImpl: container_1376143950665_0010_01_000029 Container Transitioned from ALLOCATED to ACQUIRED
2013-08-10 14:29:08,127 INFO org.apache.hadoop.yarn.server.resourcemanager.rmcontainer.RMContainerImpl: container_1376143950665_0010_01_000030 Container Transitioned from ALLOCATED to ACQUIRED
2013-08-10 14:29:08,128 INFO org.apache.hadoop.yarn.server.resourcemanager.rmcontainer.RMContainerImpl: container_1376143950665_0010_01_000031 Container Transitioned from ALLOCATED to ACQUIRED
2013-08-10 14:29:08,128 INFO org.apache.hadoop.yarn.server.resourcemanager.rmcontainer.RMContainerImpl: container_1376143950665_0010_01_000032 Container Transitioned from ALLOCATED to ACQUIRED
2013-08-10 14:29:08,128 INFO org.apache.hadoop.yarn.server.resourcemanager.rmcontainer.RMContainerImpl: container_1376143950665_0010_01_000033 Container Transitioned from ALLOCATED to ACQUIRED
2013-08-10 14:29:08,128 INFO org.apache.hadoop.yarn.server.resourcemanager.rmcontainer.RMContainerImpl: container_1376143950665_0010_01_000034 Container Transitioned from ALLOCATED to ACQUIRED
2013-08-10 14:29:08,128 INFO org.apache.hadoop.yarn.server.resourcemanager.rmcontainer.RMContainerImpl: container_1376143950665_0010_01_000035 Container Transitioned from ALLOCATED to ACQUIRED
2013-08-10 14:29:08,129 INFO org.apache.hadoop.yarn.server.resourcemanager.rmcontainer.RMContainerImpl: container_1376143950665_0010_01_000036 Container Transitioned from ALLOCATED to ACQUIRED
2013-08-10 14:29:08,129 INFO org.apache.hadoop.yarn.server.resourcemanager.rmcontainer.RMContainerImpl: container_1376143950665_0010_01_000037 Container Transitioned from ALLOCATED to ACQUIRED
2013-08-10 14:29:08,129 INFO org.apache.hadoop.yarn.server.resourcemanager.rmcontainer.RMContainerImpl: container_1376143950665_0010_01_000038 Container Transitioned from ALLOCATED to ACQUIRED
2013-08-10 14:29:08,129 INFO org.apache.hadoop.yarn.server.resourcemanager.rmcontainer.RMContainerImpl: container_1376143950665_0010_01_000039 Container Transitioned from ALLOCATED to ACQUIRED
2013-08-10 14:29:08,234 INFO org.apache.hadoop.yarn.server.resourcemanager.ApplicationMasterService: AM registration appattempt_1376143950665_0009_000001
2013-08-10 14:29:08,234 INFO org.apache.hadoop.yarn.server.resourcemanager.RMAuditLogger: USER=ubuntu	IP=192.168.100.38	OPERATION=Register App Master	TARGET=ApplicationMasterService	RESULT=SUCCESS	APPID=application_1376143950665_0009	APPATTEMPTID=appattempt_1376143950665_0009_000001
2013-08-10 14:29:08,235 INFO org.apache.hadoop.yarn.server.resourcemanager.rmapp.attempt.RMAppAttemptImpl: appattempt_1376143950665_0009_000001 State change from LAUNCHED to RUNNING
2013-08-10 14:29:08,235 INFO org.apache.hadoop.yarn.server.resourcemanager.rmapp.RMAppImpl: application_1376143950665_0009 State change from ACCEPTED to RUNNING
2013-08-10 14:29:08,735 INFO org.apache.hadoop.yarn.server.resourcemanager.rmcontainer.RMContainerImpl: container_1376143950665_0010_01_000026 Container Transitioned from ACQUIRED to RUNNING
2013-08-10 14:29:08,736 INFO org.apache.hadoop.yarn.server.resourcemanager.rmcontainer.RMContainerImpl: container_1376143950665_0010_01_000027 Container Transitioned from ACQUIRED to RUNNING
2013-08-10 14:29:08,737 INFO org.apache.hadoop.yarn.server.resourcemanager.rmcontainer.RMContainerImpl: container_1376143950665_0010_01_000030 Container Transitioned from ACQUIRED to RUNNING
2013-08-10 14:29:08,738 INFO org.apache.hadoop.yarn.server.resourcemanager.rmcontainer.RMContainerImpl: container_1376143950665_0010_01_000031 Container Transitioned from ACQUIRED to RUNNING
2013-08-10 14:29:08,739 INFO org.apache.hadoop.yarn.server.resourcemanager.rmcontainer.RMContainerImpl: container_1376143950665_0010_01_000032 Container Transitioned from ACQUIRED to RUNNING
2013-08-10 14:29:08,739 INFO org.apache.hadoop.yarn.server.resourcemanager.rmcontainer.RMContainerImpl: container_1376143950665_0010_01_000033 Container Transitioned from ACQUIRED to RUNNING
2013-08-10 14:29:08,928 INFO org.apache.hadoop.yarn.server.resourcemanager.rmcontainer.RMContainerImpl: container_1376143950665_0010_01_000034 Container Transitioned from ACQUIRED to RUNNING
2013-08-10 14:29:08,929 INFO org.apache.hadoop.yarn.server.resourcemanager.rmcontainer.RMContainerImpl: container_1376143950665_0010_01_000035 Container Transitioned from ACQUIRED to RUNNING
2013-08-10 14:29:08,930 INFO org.apache.hadoop.yarn.server.resourcemanager.rmcontainer.RMContainerImpl: container_1376143950665_0010_01_000036 Container Transitioned from ACQUIRED to RUNNING
2013-08-10 14:29:08,932 INFO org.apache.hadoop.yarn.server.resourcemanager.rmcontainer.RMContainerImpl: container_1376143950665_0010_01_000037 Container Transitioned from ACQUIRED to RUNNING
2013-08-10 14:29:08,932 INFO org.apache.hadoop.yarn.server.resourcemanager.rmcontainer.RMContainerImpl: container_1376143950665_0010_01_000038 Container Transitioned from ACQUIRED to RUNNING
2013-08-10 14:29:08,933 INFO org.apache.hadoop.yarn.server.resourcemanager.rmcontainer.RMContainerImpl: container_1376143950665_0010_01_000039 Container Transitioned from ACQUIRED to RUNNING
2013-08-10 14:29:09,299 INFO org.apache.hadoop.yarn.server.resourcemanager.rmcontainer.RMContainerImpl: container_1376143950665_0010_01_000008 Container Transitioned from ACQUIRED to RUNNING
2013-08-10 14:29:09,300 INFO org.apache.hadoop.yarn.server.resourcemanager.rmcontainer.RMContainerImpl: container_1376143950665_0010_01_000009 Container Transitioned from ACQUIRED to RUNNING
2013-08-10 14:29:09,300 INFO org.apache.hadoop.yarn.server.resourcemanager.rmcontainer.RMContainerImpl: container_1376143950665_0010_01_000010 Container Transitioned from ACQUIRED to RUNNING
2013-08-10 14:29:09,300 INFO org.apache.hadoop.yarn.server.resourcemanager.rmcontainer.RMContainerImpl: container_1376143950665_0010_01_000011 Container Transitioned from ACQUIRED to RUNNING
2013-08-10 14:29:09,301 INFO org.apache.hadoop.yarn.server.resourcemanager.rmcontainer.RMContainerImpl: container_1376143950665_0010_01_000012 Container Transitioned from ACQUIRED to RUNNING
2013-08-10 14:29:09,301 INFO org.apache.hadoop.yarn.server.resourcemanager.rmcontainer.RMContainerImpl: container_1376143950665_0010_01_000013 Container Transitioned from ACQUIRED to RUNNING
2013-08-10 14:29:09,310 INFO org.apache.hadoop.yarn.server.resourcemanager.rmcontainer.RMContainerImpl: container_1376143950665_0010_01_000002 Container Transitioned from ACQUIRED to RUNNING
2013-08-10 14:29:09,310 INFO org.apache.hadoop.yarn.server.resourcemanager.rmcontainer.RMContainerImpl: container_1376143950665_0010_01_000003 Container Transitioned from ACQUIRED to RUNNING
2013-08-10 14:29:09,310 INFO org.apache.hadoop.yarn.server.resourcemanager.rmcontainer.RMContainerImpl: container_1376143950665_0010_01_000004 Container Transitioned from ACQUIRED to RUNNING
2013-08-10 14:29:09,311 INFO org.apache.hadoop.yarn.server.resourcemanager.rmcontainer.RMContainerImpl: container_1376143950665_0010_01_000005 Container Transitioned from ACQUIRED to RUNNING
2013-08-10 14:29:09,311 INFO org.apache.hadoop.yarn.server.resourcemanager.rmcontainer.RMContainerImpl: container_1376143950665_0010_01_000006 Container Transitioned from ACQUIRED to RUNNING
2013-08-10 14:29:09,311 INFO org.apache.hadoop.yarn.server.resourcemanager.rmcontainer.RMContainerImpl: container_1376143950665_0010_01_000007 Container Transitioned from ACQUIRED to RUNNING
2013-08-10 14:29:09,541 INFO org.apache.hadoop.yarn.server.resourcemanager.rmcontainer.RMContainerImpl: container_1376143950665_0010_01_000014 Container Transitioned from ACQUIRED to RUNNING
2013-08-10 14:29:09,542 INFO org.apache.hadoop.yarn.server.resourcemanager.rmcontainer.RMContainerImpl: container_1376143950665_0010_01_000015 Container Transitioned from ACQUIRED to RUNNING
2013-08-10 14:29:09,542 INFO org.apache.hadoop.yarn.server.resourcemanager.rmcontainer.RMContainerImpl: container_1376143950665_0010_01_000016 Container Transitioned from ACQUIRED to RUNNING
2013-08-10 14:29:09,543 INFO org.apache.hadoop.yarn.server.resourcemanager.rmcontainer.RMContainerImpl: container_1376143950665_0010_01_000017 Container Transitioned from ACQUIRED to RUNNING
2013-08-10 14:29:09,544 INFO org.apache.hadoop.yarn.server.resourcemanager.rmcontainer.RMContainerImpl: container_1376143950665_0010_01_000018 Container Transitioned from ACQUIRED to RUNNING
2013-08-10 14:29:09,544 INFO org.apache.hadoop.yarn.server.resourcemanager.rmcontainer.RMContainerImpl: container_1376143950665_0010_01_000019 Container Transitioned from ACQUIRED to RUNNING
2013-08-10 14:29:09,590 INFO org.apache.hadoop.yarn.server.resourcemanager.rmcontainer.RMContainerImpl: container_1376143950665_0010_01_000020 Container Transitioned from ACQUIRED to RUNNING
2013-08-10 14:29:09,590 INFO org.apache.hadoop.yarn.server.resourcemanager.rmcontainer.RMContainerImpl: container_1376143950665_0010_01_000021 Container Transitioned from ACQUIRED to RUNNING
2013-08-10 14:29:09,590 INFO org.apache.hadoop.yarn.server.resourcemanager.rmcontainer.RMContainerImpl: container_1376143950665_0010_01_000022 Container Transitioned from ACQUIRED to RUNNING
2013-08-10 14:29:09,591 INFO org.apache.hadoop.yarn.server.resourcemanager.rmcontainer.RMContainerImpl: container_1376143950665_0010_01_000023 Container Transitioned from ACQUIRED to RUNNING
2013-08-10 14:29:09,591 INFO org.apache.hadoop.yarn.server.resourcemanager.rmcontainer.RMContainerImpl: container_1376143950665_0010_01_000024 Container Transitioned from ACQUIRED to RUNNING
2013-08-10 14:29:09,591 INFO org.apache.hadoop.yarn.server.resourcemanager.rmcontainer.RMContainerImpl: container_1376143950665_0010_01_000025 Container Transitioned from ACQUIRED to RUNNING
2013-08-10 14:29:09,848 INFO org.apache.hadoop.yarn.server.resourcemanager.rmcontainer.RMContainerImpl: container_1376143950665_0010_01_000028 Container Transitioned from ACQUIRED to RUNNING
2013-08-10 14:29:09,849 INFO org.apache.hadoop.yarn.server.resourcemanager.rmcontainer.RMContainerImpl: container_1376143950665_0010_01_000029 Container Transitioned from ACQUIRED to RUNNING
2013-08-10 14:29:30,630 INFO org.apache.hadoop.yarn.server.resourcemanager.rmcontainer.RMContainerImpl: container_1376143950665_0010_01_000012 Container Transitioned from RUNNING to COMPLETED
2013-08-10 14:29:30,631 INFO org.apache.hadoop.yarn.server.resourcemanager.scheduler.common.fica.FiCaSchedulerApp: Completed container: container_1376143950665_0010_01_000012 in state: COMPLETED event:FINISHED
2013-08-10 14:29:30,631 INFO org.apache.hadoop.yarn.server.resourcemanager.RMAuditLogger: USER=ubuntu	OPERATION=AM Released Container	TARGET=SchedulerApp	RESULT=SUCCESS	APPID=application_1376143950665_0010	CONTAINERID=container_1376143950665_0010_01_000012
2013-08-10 14:29:30,631 INFO org.apache.hadoop.yarn.server.resourcemanager.scheduler.common.fica.FiCaSchedulerNode: Released container container_1376143950665_0010_01_000012 of capacity <memory:1024, vCores:1> on host hadoop-221-4:43548, which currently has 6 containers, <memory:7168, vCores:6> used and <memory:1024, vCores:10> available, release resources=true
2013-08-10 14:29:30,631 INFO org.apache.hadoop.yarn.server.resourcemanager.scheduler.capacity.LeafQueue: default used=<memory:48128, vCores:42> numContainers=42 user=ubuntu user-resources=<memory:48128, vCores:42>
2013-08-10 14:29:30,634 INFO org.apache.hadoop.yarn.server.resourcemanager.scheduler.capacity.LeafQueue: completedContainer container=Container: [ContainerId: container_1376143950665_0010_01_000012, NodeId: hadoop-221-4:43548, NodeHttpAddress: hadoop-221-4:8042, Resource: <memory:1024, vCores:1>, Priority: 20, State: NEW, Token: null, Status: container_id {, app_attempt_id {, application_id {, id: 10, cluster_timestamp: 1376143950665, }, attemptId: 1, }, id: 12, }, state: C_COMPLETE, diagnostics: "", exit_status: 0, ] resource=<memory:1024, vCores:1> queue=default: capacity=1.0, absoluteCapacity=1.0, usedResources=<memory:48128, vCores:42>usedCapacity=0.9791667, absoluteUsedCapacity=0.9791667, numApps=5, numContainers=42 usedCapacity=0.9791667 absoluteUsedCapacity=0.9791667 used=<memory:48128, vCores:42> cluster=<memory:49152, vCores:96>
2013-08-10 14:29:30,634 INFO org.apache.hadoop.yarn.server.resourcemanager.scheduler.capacity.ParentQueue: completedContainer queue=root usedCapacity=0.9791667 absoluteUsedCapacity=0.9791667 used=<memory:48128, vCores:42> cluster=<memory:49152, vCores:96>
2013-08-10 14:29:30,634 INFO org.apache.hadoop.yarn.server.resourcemanager.scheduler.capacity.CapacityScheduler: Application appattempt_1376143950665_0010_000001 released container container_1376143950665_0010_01_000012 on node: host: hadoop-221-4:43548 #containers=6 available=1024 used=7168 with event: FINISHED
2013-08-10 14:29:30,634 INFO org.apache.hadoop.yarn.server.resourcemanager.rmcontainer.RMContainerImpl: container_1376143950665_0006_01_000002 Container Transitioned from NEW to ALLOCATED
2013-08-10 14:29:30,635 INFO org.apache.hadoop.yarn.server.resourcemanager.RMAuditLogger: USER=ubuntu	OPERATION=AM Allocated Container	TARGET=SchedulerApp	RESULT=SUCCESS	APPID=application_1376143950665_0006	CONTAINERID=container_1376143950665_0006_01_000002
2013-08-10 14:29:30,635 INFO org.apache.hadoop.yarn.server.resourcemanager.scheduler.common.fica.FiCaSchedulerNode: Assigned container container_1376143950665_0006_01_000002 of capacity <memory:1024, vCores:1> on host hadoop-221-4:43548, which currently has 7 containers, <memory:8192, vCores:7> used and <memory:0, vCores:9> available
2013-08-10 14:29:30,636 INFO org.apache.hadoop.yarn.server.resourcemanager.scheduler.capacity.LeafQueue: assignedContainer application=application_1376143950665_0006 container=Container: [ContainerId: container_1376143950665_0006_01_000002, NodeId: hadoop-221-4:43548, NodeHttpAddress: hadoop-221-4:8042, Resource: <memory:1024, vCores:1>, Priority: 20, State: NEW, Token: null, Status: container_id {, app_attempt_id {, application_id {, id: 6, cluster_timestamp: 1376143950665, }, attemptId: 1, }, id: 2, }, state: C_NEW, ] containerId=container_1376143950665_0006_01_000002 queue=default: capacity=1.0, absoluteCapacity=1.0, usedResources=<memory:48128, vCores:42>usedCapacity=0.9791667, absoluteUsedCapacity=0.9791667, numApps=5, numContainers=42 usedCapacity=0.9791667 absoluteUsedCapacity=0.9791667 used=<memory:48128, vCores:42> cluster=<memory:49152, vCores:96>
2013-08-10 14:29:30,636 INFO org.apache.hadoop.yarn.server.resourcemanager.scheduler.capacity.ParentQueue: Re-sorting queues since queue: root.default stats: default: capacity=1.0, absoluteCapacity=1.0, usedResources=<memory:49152, vCores:43>usedCapacity=1.0, absoluteUsedCapacity=1.0, numApps=5, numContainers=43
2013-08-10 14:29:30,636 INFO org.apache.hadoop.yarn.server.resourcemanager.scheduler.capacity.ParentQueue: assignedContainer queue=root usedCapacity=1.0 absoluteUsedCapacity=1.0 used=<memory:49152, vCores:43> cluster=<memory:49152, vCores:96>
2013-08-10 14:29:31,385 INFO org.apache.hadoop.yarn.server.resourcemanager.rmcontainer.RMContainerImpl: container_1376143950665_0006_01_000002 Container Transitioned from ALLOCATED to ACQUIRED
2013-08-10 14:29:32,660 INFO org.apache.hadoop.yarn.server.resourcemanager.rmcontainer.RMContainerImpl: container_1376143950665_0006_01_000002 Container Transitioned from ACQUIRED to RUNNING
2013-08-10 14:29:33,467 INFO org.apache.hadoop.yarn.server.resourcemanager.rmcontainer.RMContainerImpl: container_1376143950665_0010_01_000037 Container Transitioned from RUNNING to COMPLETED
2013-08-10 14:29:33,467 INFO org.apache.hadoop.yarn.server.resourcemanager.scheduler.common.fica.FiCaSchedulerApp: Completed container: container_1376143950665_0010_01_000037 in state: COMPLETED event:FINISHED
2013-08-10 14:29:33,467 INFO org.apache.hadoop.yarn.server.resourcemanager.RMAuditLogger: USER=ubuntu	OPERATION=AM Released Container	TARGET=SchedulerApp	RESULT=SUCCESS	APPID=application_1376143950665_0010	CONTAINERID=container_1376143950665_0010_01_000037
2013-08-10 14:29:33,467 INFO org.apache.hadoop.yarn.server.resourcemanager.scheduler.common.fica.FiCaSchedulerNode: Released container container_1376143950665_0010_01_000037 of capacity <memory:1024, vCores:1> on host hadoop-221-7:43558, which currently has 6 containers, <memory:7168, vCores:6> used and <memory:1024, vCores:10> available, release resources=true
2013-08-10 14:29:33,467 INFO org.apache.hadoop.yarn.server.resourcemanager.scheduler.capacity.LeafQueue: default used=<memory:48128, vCores:42> numContainers=42 user=ubuntu user-resources=<memory:48128, vCores:42>
2013-08-10 14:29:33,469 INFO org.apache.hadoop.yarn.server.resourcemanager.scheduler.capacity.LeafQueue: completedContainer container=Container: [ContainerId: container_1376143950665_0010_01_000037, NodeId: hadoop-221-7:43558, NodeHttpAddress: hadoop-221-7:8042, Resource: <memory:1024, vCores:1>, Priority: 20, State: NEW, Token: null, Status: container_id {, app_attempt_id {, application_id {, id: 10, cluster_timestamp: 1376143950665, }, attemptId: 1, }, id: 37, }, state: C_COMPLETE, diagnostics: "Container killed by the ApplicationMaster.\n\n", exit_status: 143, ] resource=<memory:1024, vCores:1> queue=default: capacity=1.0, absoluteCapacity=1.0, usedResources=<memory:48128, vCores:42>usedCapacity=0.9791667, absoluteUsedCapacity=0.9791667, numApps=5, numContainers=42 usedCapacity=0.9791667 absoluteUsedCapacity=0.9791667 used=<memory:48128, vCores:42> cluster=<memory:49152, vCores:96>
2013-08-10 14:29:33,469 INFO org.apache.hadoop.yarn.server.resourcemanager.scheduler.capacity.ParentQueue: completedContainer queue=root usedCapacity=0.9791667 absoluteUsedCapacity=0.9791667 used=<memory:48128, vCores:42> cluster=<memory:49152, vCores:96>
2013-08-10 14:29:33,469 INFO org.apache.hadoop.yarn.server.resourcemanager.scheduler.capacity.CapacityScheduler: Application appattempt_1376143950665_0010_000001 released container container_1376143950665_0010_01_000037 on node: host: hadoop-221-7:43558 #containers=6 available=1024 used=7168 with event: FINISHED
2013-08-10 14:29:33,470 INFO org.apache.hadoop.yarn.server.resourcemanager.rmcontainer.RMContainerImpl: container_1376143950665_0006_01_000003 Container Transitioned from NEW to ALLOCATED
2013-08-10 14:29:33,470 INFO org.apache.hadoop.yarn.server.resourcemanager.RMAuditLogger: USER=ubuntu	OPERATION=AM Allocated Container	TARGET=SchedulerApp	RESULT=SUCCESS	APPID=application_1376143950665_0006	CONTAINERID=container_1376143950665_0006_01_000003
2013-08-10 14:29:33,470 INFO org.apache.hadoop.yarn.server.resourcemanager.scheduler.common.fica.FiCaSchedulerNode: Assigned container container_1376143950665_0006_01_000003 of capacity <memory:1024, vCores:1> on host hadoop-221-7:43558, which currently has 7 containers, <memory:8192, vCores:7> used and <memory:0, vCores:9> available
2013-08-10 14:29:33,471 INFO org.apache.hadoop.yarn.server.resourcemanager.scheduler.capacity.LeafQueue: assignedContainer application=application_1376143950665_0006 container=Container: [ContainerId: container_1376143950665_0006_01_000003, NodeId: hadoop-221-7:43558, NodeHttpAddress: hadoop-221-7:8042, Resource: <memory:1024, vCores:1>, Priority: 20, State: NEW, Token: null, Status: container_id {, app_attempt_id {, application_id {, id: 6, cluster_timestamp: 1376143950665, }, attemptId: 1, }, id: 3, }, state: C_NEW, ] containerId=container_1376143950665_0006_01_000003 queue=default: capacity=1.0, absoluteCapacity=1.0, usedResources=<memory:48128, vCores:42>usedCapacity=0.9791667, absoluteUsedCapacity=0.9791667, numApps=5, numContainers=42 usedCapacity=0.9791667 absoluteUsedCapacity=0.9791667 used=<memory:48128, vCores:42> cluster=<memory:49152, vCores:96>
2013-08-10 14:29:33,471 INFO org.apache.hadoop.yarn.server.resourcemanager.scheduler.capacity.ParentQueue: Re-sorting queues since queue: root.default stats: default: capacity=1.0, absoluteCapacity=1.0, usedResources=<memory:49152, vCores:43>usedCapacity=1.0, absoluteUsedCapacity=1.0, numApps=5, numContainers=43
2013-08-10 14:29:33,471 INFO org.apache.hadoop.yarn.server.resourcemanager.scheduler.capacity.ParentQueue: assignedContainer queue=root usedCapacity=1.0 absoluteUsedCapacity=1.0 used=<memory:49152, vCores:43> cluster=<memory:49152, vCores:96>
2013-08-10 14:29:34,428 INFO org.apache.hadoop.yarn.server.resourcemanager.rmcontainer.RMContainerImpl: container_1376143950665_0006_01_000003 Container Transitioned from ALLOCATED to ACQUIRED
2013-08-10 14:29:34,989 INFO org.apache.hadoop.yarn.server.resourcemanager.rmcontainer.RMContainerImpl: container_1376143950665_0006_01_000003 Container Transitioned from ACQUIRED to RUNNING
2013-08-10 14:29:34,989 INFO org.apache.hadoop.yarn.server.resourcemanager.rmcontainer.RMContainerImpl: container_1376143950665_0010_01_000035 Container Transitioned from RUNNING to COMPLETED
2013-08-10 14:29:34,989 INFO org.apache.hadoop.yarn.server.resourcemanager.scheduler.common.fica.FiCaSchedulerApp: Completed container: container_1376143950665_0010_01_000035 in state: COMPLETED event:FINISHED
2013-08-10 14:29:34,989 INFO org.apache.hadoop.yarn.server.resourcemanager.RMAuditLogger: USER=ubuntu	OPERATION=AM Released Container	TARGET=SchedulerApp	RESULT=SUCCESS	APPID=application_1376143950665_0010	CONTAINERID=container_1376143950665_0010_01_000035
2013-08-10 14:29:34,989 INFO org.apache.hadoop.yarn.server.resourcemanager.scheduler.common.fica.FiCaSchedulerNode: Released container container_1376143950665_0010_01_000035 of capacity <memory:1024, vCores:1> on host hadoop-221-7:43558, which currently has 6 containers, <memory:7168, vCores:6> used and <memory:1024, vCores:10> available, release resources=true
2013-08-10 14:29:34,990 INFO org.apache.hadoop.yarn.server.resourcemanager.scheduler.capacity.LeafQueue: default used=<memory:48128, vCores:42> numContainers=42 user=ubuntu user-resources=<memory:48128, vCores:42>
2013-08-10 14:29:34,991 INFO org.apache.hadoop.yarn.server.resourcemanager.scheduler.capacity.LeafQueue: completedContainer container=Container: [ContainerId: container_1376143950665_0010_01_000035, NodeId: hadoop-221-7:43558, NodeHttpAddress: hadoop-221-7:8042, Resource: <memory:1024, vCores:1>, Priority: 20, State: NEW, Token: null, Status: container_id {, app_attempt_id {, application_id {, id: 10, cluster_timestamp: 1376143950665, }, attemptId: 1, }, id: 35, }, state: C_COMPLETE, diagnostics: "Container killed by the ApplicationMaster.\n\n", exit_status: 143, ] resource=<memory:1024, vCores:1> queue=default: capacity=1.0, absoluteCapacity=1.0, usedResources=<memory:48128, vCores:42>usedCapacity=0.9791667, absoluteUsedCapacity=0.9791667, numApps=5, numContainers=42 usedCapacity=0.9791667 absoluteUsedCapacity=0.9791667 used=<memory:48128, vCores:42> cluster=<memory:49152, vCores:96>
2013-08-10 14:29:34,991 INFO org.apache.hadoop.yarn.server.resourcemanager.scheduler.capacity.ParentQueue: completedContainer queue=root usedCapacity=0.9791667 absoluteUsedCapacity=0.9791667 used=<memory:48128, vCores:42> cluster=<memory:49152, vCores:96>
2013-08-10 14:29:34,991 INFO org.apache.hadoop.yarn.server.resourcemanager.scheduler.capacity.CapacityScheduler: Application appattempt_1376143950665_0010_000001 released container container_1376143950665_0010_01_000035 on node: host: hadoop-221-7:43558 #containers=6 available=1024 used=7168 with event: FINISHED
2013-08-10 14:29:34,992 INFO org.apache.hadoop.yarn.server.resourcemanager.rmcontainer.RMContainerImpl: container_1376143950665_0006_01_000004 Container Transitioned from NEW to ALLOCATED
2013-08-10 14:29:34,992 INFO org.apache.hadoop.yarn.server.resourcemanager.RMAuditLogger: USER=ubuntu	OPERATION=AM Allocated Container	TARGET=SchedulerApp	RESULT=SUCCESS	APPID=application_1376143950665_0006	CONTAINERID=container_1376143950665_0006_01_000004
2013-08-10 14:29:34,992 INFO org.apache.hadoop.yarn.server.resourcemanager.scheduler.common.fica.FiCaSchedulerNode: Assigned container container_1376143950665_0006_01_000004 of capacity <memory:1024, vCores:1> on host hadoop-221-7:43558, which currently has 7 containers, <memory:8192, vCores:7> used and <memory:0, vCores:9> available
2013-08-10 14:29:34,993 INFO org.apache.hadoop.yarn.server.resourcemanager.scheduler.capacity.LeafQueue: assignedContainer application=application_1376143950665_0006 container=Container: [ContainerId: container_1376143950665_0006_01_000004, NodeId: hadoop-221-7:43558, NodeHttpAddress: hadoop-221-7:8042, Resource: <memory:1024, vCores:1>, Priority: 20, State: NEW, Token: null, Status: container_id {, app_attempt_id {, application_id {, id: 6, cluster_timestamp: 1376143950665, }, attemptId: 1, }, id: 4, }, state: C_NEW, ] containerId=container_1376143950665_0006_01_000004 queue=default: capacity=1.0, absoluteCapacity=1.0, usedResources=<memory:48128, vCores:42>usedCapacity=0.9791667, absoluteUsedCapacity=0.9791667, numApps=5, numContainers=42 usedCapacity=0.9791667 absoluteUsedCapacity=0.9791667 used=<memory:48128, vCores:42> cluster=<memory:49152, vCores:96>
2013-08-10 14:29:34,993 INFO org.apache.hadoop.yarn.server.resourcemanager.scheduler.capacity.ParentQueue: Re-sorting queues since queue: root.default stats: default: capacity=1.0, absoluteCapacity=1.0, usedResources=<memory:49152, vCores:43>usedCapacity=1.0, absoluteUsedCapacity=1.0, numApps=5, numContainers=43
2013-08-10 14:29:34,993 INFO org.apache.hadoop.yarn.server.resourcemanager.scheduler.capacity.ParentQueue: assignedContainer queue=root usedCapacity=1.0 absoluteUsedCapacity=1.0 used=<memory:49152, vCores:43> cluster=<memory:49152, vCores:96>
2013-08-10 14:29:35,437 INFO org.apache.hadoop.yarn.server.resourcemanager.rmcontainer.RMContainerImpl: container_1376143950665_0006_01_000004 Container Transitioned from ALLOCATED to ACQUIRED
2013-08-10 14:29:36,011 INFO org.apache.hadoop.yarn.server.resourcemanager.rmcontainer.RMContainerImpl: container_1376143950665_0006_01_000004 Container Transitioned from ACQUIRED to RUNNING
2013-08-10 14:29:36,033 INFO org.apache.hadoop.yarn.server.resourcemanager.rmcontainer.RMContainerImpl: container_1376143950665_0010_01_000025 Container Transitioned from RUNNING to COMPLETED
2013-08-10 14:29:36,033 INFO org.apache.hadoop.yarn.server.resourcemanager.scheduler.common.fica.FiCaSchedulerApp: Completed container: container_1376143950665_0010_01_000025 in state: COMPLETED event:FINISHED
2013-08-10 14:29:36,034 INFO org.apache.hadoop.yarn.server.resourcemanager.RMAuditLogger: USER=ubuntu	OPERATION=AM Released Container	TARGET=SchedulerApp	RESULT=SUCCESS	APPID=application_1376143950665_0010	CONTAINERID=container_1376143950665_0010_01_000025
2013-08-10 14:29:36,034 INFO org.apache.hadoop.yarn.server.resourcemanager.scheduler.common.fica.FiCaSchedulerNode: Released container container_1376143950665_0010_01_000025 of capacity <memory:1024, vCores:1> on host hadoop-221-6:51695, which currently has 6 containers, <memory:7168, vCores:6> used and <memory:1024, vCores:10> available, release resources=true
2013-08-10 14:29:36,034 INFO org.apache.hadoop.yarn.server.resourcemanager.scheduler.capacity.LeafQueue: default used=<memory:48128, vCores:42> numContainers=42 user=ubuntu user-resources=<memory:48128, vCores:42>
2013-08-10 14:29:36,035 INFO org.apache.hadoop.yarn.server.resourcemanager.scheduler.capacity.LeafQueue: completedContainer container=Container: [ContainerId: container_1376143950665_0010_01_000025, NodeId: hadoop-221-6:51695, NodeHttpAddress: hadoop-221-6:8042, Resource: <memory:1024, vCores:1>, Priority: 20, State: NEW, Token: null, Status: container_id {, app_attempt_id {, application_id {, id: 10, cluster_timestamp: 1376143950665, }, attemptId: 1, }, id: 25, }, state: C_COMPLETE, diagnostics: "Container killed by the ApplicationMaster.\n\n", exit_status: 143, ] resource=<memory:1024, vCores:1> queue=default: capacity=1.0, absoluteCapacity=1.0, usedResources=<memory:48128, vCores:42>usedCapacity=0.9791667, absoluteUsedCapacity=0.9791667, numApps=5, numContainers=42 usedCapacity=0.9791667 absoluteUsedCapacity=0.9791667 used=<memory:48128, vCores:42> cluster=<memory:49152, vCores:96>
2013-08-10 14:29:36,035 INFO org.apache.hadoop.yarn.server.resourcemanager.scheduler.capacity.ParentQueue: completedContainer queue=root usedCapacity=0.9791667 absoluteUsedCapacity=0.9791667 used=<memory:48128, vCores:42> cluster=<memory:49152, vCores:96>
2013-08-10 14:29:36,035 INFO org.apache.hadoop.yarn.server.resourcemanager.scheduler.capacity.CapacityScheduler: Application appattempt_1376143950665_0010_000001 released container container_1376143950665_0010_01_000025 on node: host: hadoop-221-6:51695 #containers=6 available=1024 used=7168 with event: FINISHED
2013-08-10 14:29:36,036 INFO org.apache.hadoop.yarn.server.resourcemanager.rmcontainer.RMContainerImpl: container_1376143950665_0006_01_000005 Container Transitioned from NEW to ALLOCATED
2013-08-10 14:29:36,036 INFO org.apache.hadoop.yarn.server.resourcemanager.RMAuditLogger: USER=ubuntu	OPERATION=AM Allocated Container	TARGET=SchedulerApp	RESULT=SUCCESS	APPID=application_1376143950665_0006	CONTAINERID=container_1376143950665_0006_01_000005
2013-08-10 14:29:36,036 INFO org.apache.hadoop.yarn.server.resourcemanager.scheduler.common.fica.FiCaSchedulerNode: Assigned container container_1376143950665_0006_01_000005 of capacity <memory:1024, vCores:1> on host hadoop-221-6:51695, which currently has 7 containers, <memory:8192, vCores:7> used and <memory:0, vCores:9> available
2013-08-10 14:29:36,037 INFO org.apache.hadoop.yarn.server.resourcemanager.scheduler.capacity.LeafQueue: assignedContainer application=application_1376143950665_0006 container=Container: [ContainerId: container_1376143950665_0006_01_000005, NodeId: hadoop-221-6:51695, NodeHttpAddress: hadoop-221-6:8042, Resource: <memory:1024, vCores:1>, Priority: 20, State: NEW, Token: null, Status: container_id {, app_attempt_id {, application_id {, id: 6, cluster_timestamp: 1376143950665, }, attemptId: 1, }, id: 5, }, state: C_NEW, ] containerId=container_1376143950665_0006_01_000005 queue=default: capacity=1.0, absoluteCapacity=1.0, usedResources=<memory:48128, vCores:42>usedCapacity=0.9791667, absoluteUsedCapacity=0.9791667, numApps=5, numContainers=42 usedCapacity=0.9791667 absoluteUsedCapacity=0.9791667 used=<memory:48128, vCores:42> cluster=<memory:49152, vCores:96>
2013-08-10 14:29:36,037 INFO org.apache.hadoop.yarn.server.resourcemanager.scheduler.capacity.ParentQueue: Re-sorting queues since queue: root.default stats: default: capacity=1.0, absoluteCapacity=1.0, usedResources=<memory:49152, vCores:43>usedCapacity=1.0, absoluteUsedCapacity=1.0, numApps=5, numContainers=43
2013-08-10 14:29:36,038 INFO org.apache.hadoop.yarn.server.resourcemanager.scheduler.capacity.ParentQueue: assignedContainer queue=root usedCapacity=1.0 absoluteUsedCapacity=1.0 used=<memory:49152, vCores:43> cluster=<memory:49152, vCores:96>
2013-08-10 14:29:36,126 INFO org.apache.hadoop.yarn.server.resourcemanager.rmcontainer.RMContainerImpl: container_1376143950665_0010_01_000023 Container Transitioned from RUNNING to COMPLETED
2013-08-10 14:29:36,126 INFO org.apache.hadoop.yarn.server.resourcemanager.scheduler.common.fica.FiCaSchedulerApp: Completed container: container_1376143950665_0010_01_000023 in state: COMPLETED event:FINISHED
2013-08-10 14:29:36,126 INFO org.apache.hadoop.yarn.server.resourcemanager.RMAuditLogger: USER=ubuntu	OPERATION=AM Released Container	TARGET=SchedulerApp	RESULT=SUCCESS	APPID=application_1376143950665_0010	CONTAINERID=container_1376143950665_0010_01_000023
2013-08-10 14:29:36,126 INFO org.apache.hadoop.yarn.server.resourcemanager.scheduler.common.fica.FiCaSchedulerNode: Released container container_1376143950665_0010_01_000023 of capacity <memory:1024, vCores:1> on host hadoop-221-6:51695, which currently has 6 containers, <memory:7168, vCores:6> used and <memory:1024, vCores:10> available, release resources=true
2013-08-10 14:29:36,126 INFO org.apache.hadoop.yarn.server.resourcemanager.scheduler.capacity.LeafQueue: default used=<memory:48128, vCores:42> numContainers=42 user=ubuntu user-resources=<memory:48128, vCores:42>
2013-08-10 14:29:36,127 INFO org.apache.hadoop.yarn.server.resourcemanager.scheduler.capacity.LeafQueue: completedContainer container=Container: [ContainerId: container_1376143950665_0010_01_000023, NodeId: hadoop-221-6:51695, NodeHttpAddress: hadoop-221-6:8042, Resource: <memory:1024, vCores:1>, Priority: 20, State: NEW, Token: null, Status: container_id {, app_attempt_id {, application_id {, id: 10, cluster_timestamp: 1376143950665, }, attemptId: 1, }, id: 23, }, state: C_COMPLETE, diagnostics: "Container killed by the ApplicationMaster.\n\n", exit_status: 143, ] resource=<memory:1024, vCores:1> queue=default: capacity=1.0, absoluteCapacity=1.0, usedResources=<memory:48128, vCores:42>usedCapacity=0.9791667, absoluteUsedCapacity=0.9791667, numApps=5, numContainers=42 usedCapacity=0.9791667 absoluteUsedCapacity=0.9791667 used=<memory:48128, vCores:42> cluster=<memory:49152, vCores:96>
2013-08-10 14:29:36,128 INFO org.apache.hadoop.yarn.server.resourcemanager.scheduler.capacity.ParentQueue: completedContainer queue=root usedCapacity=0.9791667 absoluteUsedCapacity=0.9791667 used=<memory:48128, vCores:42> cluster=<memory:49152, vCores:96>
2013-08-10 14:29:36,128 INFO org.apache.hadoop.yarn.server.resourcemanager.scheduler.capacity.CapacityScheduler: Application appattempt_1376143950665_0010_000001 released container container_1376143950665_0010_01_000023 on node: host: hadoop-221-6:51695 #containers=6 available=1024 used=7168 with event: FINISHED
2013-08-10 14:29:36,128 INFO org.apache.hadoop.yarn.server.resourcemanager.rmcontainer.RMContainerImpl: container_1376143950665_0006_01_000006 Container Transitioned from NEW to ALLOCATED
2013-08-10 14:29:36,128 INFO org.apache.hadoop.yarn.server.resourcemanager.RMAuditLogger: USER=ubuntu	OPERATION=AM Allocated Container	TARGET=SchedulerApp	RESULT=SUCCESS	APPID=application_1376143950665_0006	CONTAINERID=container_1376143950665_0006_01_000006
2013-08-10 14:29:36,129 INFO org.apache.hadoop.yarn.server.resourcemanager.scheduler.common.fica.FiCaSchedulerNode: Assigned container container_1376143950665_0006_01_000006 of capacity <memory:1024, vCores:1> on host hadoop-221-6:51695, which currently has 7 containers, <memory:8192, vCores:7> used and <memory:0, vCores:9> available
2013-08-10 14:29:36,129 INFO org.apache.hadoop.yarn.server.resourcemanager.scheduler.capacity.LeafQueue: assignedContainer application=application_1376143950665_0006 container=Container: [ContainerId: container_1376143950665_0006_01_000006, NodeId: hadoop-221-6:51695, NodeHttpAddress: hadoop-221-6:8042, Resource: <memory:1024, vCores:1>, Priority: 20, State: NEW, Token: null, Status: container_id {, app_attempt_id {, application_id {, id: 6, cluster_timestamp: 1376143950665, }, attemptId: 1, }, id: 6, }, state: C_NEW, ] containerId=container_1376143950665_0006_01_000006 queue=default: capacity=1.0, absoluteCapacity=1.0, usedResources=<memory:48128, vCores:42>usedCapacity=0.9791667, absoluteUsedCapacity=0.9791667, numApps=5, numContainers=42 usedCapacity=0.9791667 absoluteUsedCapacity=0.9791667 used=<memory:48128, vCores:42> cluster=<memory:49152, vCores:96>
2013-08-10 14:29:36,130 INFO org.apache.hadoop.yarn.server.resourcemanager.scheduler.capacity.ParentQueue: Re-sorting queues since queue: root.default stats: default: capacity=1.0, absoluteCapacity=1.0, usedResources=<memory:49152, vCores:43>usedCapacity=1.0, absoluteUsedCapacity=1.0, numApps=5, numContainers=43
2013-08-10 14:29:36,130 INFO org.apache.hadoop.yarn.server.resourcemanager.scheduler.capacity.ParentQueue: assignedContainer queue=root usedCapacity=1.0 absoluteUsedCapacity=1.0 used=<memory:49152, vCores:43> cluster=<memory:49152, vCores:96>
2013-08-10 14:29:36,450 INFO org.apache.hadoop.yarn.server.resourcemanager.rmcontainer.RMContainerImpl: container_1376143950665_0006_01_000005 Container Transitioned from ALLOCATED to ACQUIRED
2013-08-10 14:29:36,451 INFO org.apache.hadoop.yarn.server.resourcemanager.rmcontainer.RMContainerImpl: container_1376143950665_0006_01_000006 Container Transitioned from ALLOCATED to ACQUIRED
2013-08-10 14:29:37,132 INFO org.apache.hadoop.yarn.server.resourcemanager.rmcontainer.RMContainerImpl: container_1376143950665_0006_01_000005 Container Transitioned from ACQUIRED to RUNNING
2013-08-10 14:29:37,132 INFO org.apache.hadoop.yarn.server.resourcemanager.rmcontainer.RMContainerImpl: container_1376143950665_0006_01_000006 Container Transitioned from ACQUIRED to RUNNING
2013-08-10 14:29:37,132 INFO org.apache.hadoop.yarn.server.resourcemanager.rmcontainer.RMContainerImpl: container_1376143950665_0010_01_000024 Container Transitioned from RUNNING to COMPLETED
2013-08-10 14:29:37,132 INFO org.apache.hadoop.yarn.server.resourcemanager.scheduler.common.fica.FiCaSchedulerApp: Completed container: container_1376143950665_0010_01_000024 in state: COMPLETED event:FINISHED
2013-08-10 14:29:37,133 INFO org.apache.hadoop.yarn.server.resourcemanager.RMAuditLogger: USER=ubuntu	OPERATION=AM Released Container	TARGET=SchedulerApp	RESULT=SUCCESS	APPID=application_1376143950665_0010	CONTAINERID=container_1376143950665_0010_01_000024
2013-08-10 14:29:37,133 INFO org.apache.hadoop.yarn.server.resourcemanager.scheduler.common.fica.FiCaSchedulerNode: Released container container_1376143950665_0010_01_000024 of capacity <memory:1024, vCores:1> on host hadoop-221-6:51695, which currently has 6 containers, <memory:7168, vCores:6> used and <memory:1024, vCores:10> available, release resources=true
2013-08-10 14:29:37,133 INFO org.apache.hadoop.yarn.server.resourcemanager.scheduler.capacity.LeafQueue: default used=<memory:48128, vCores:42> numContainers=42 user=ubuntu user-resources=<memory:48128, vCores:42>
2013-08-10 14:29:37,134 INFO org.apache.hadoop.yarn.server.resourcemanager.scheduler.capacity.LeafQueue: completedContainer container=Container: [ContainerId: container_1376143950665_0010_01_000024, NodeId: hadoop-221-6:51695, NodeHttpAddress: hadoop-221-6:8042, Resource: <memory:1024, vCores:1>, Priority: 20, State: NEW, Token: null, Status: container_id {, app_attempt_id {, application_id {, id: 10, cluster_timestamp: 1376143950665, }, attemptId: 1, }, id: 24, }, state: C_COMPLETE, diagnostics: "Container killed by the ApplicationMaster.\n\n", exit_status: 143, ] resource=<memory:1024, vCores:1> queue=default: capacity=1.0, absoluteCapacity=1.0, usedResources=<memory:48128, vCores:42>usedCapacity=0.9791667, absoluteUsedCapacity=0.9791667, numApps=5, numContainers=42 usedCapacity=0.9791667 absoluteUsedCapacity=0.9791667 used=<memory:48128, vCores:42> cluster=<memory:49152, vCores:96>
2013-08-10 14:29:37,134 INFO org.apache.hadoop.yarn.server.resourcemanager.scheduler.capacity.ParentQueue: completedContainer queue=root usedCapacity=0.9791667 absoluteUsedCapacity=0.9791667 used=<memory:48128, vCores:42> cluster=<memory:49152, vCores:96>
2013-08-10 14:29:37,134 INFO org.apache.hadoop.yarn.server.resourcemanager.scheduler.capacity.CapacityScheduler: Application appattempt_1376143950665_0010_000001 released container container_1376143950665_0010_01_000024 on node: host: hadoop-221-6:51695 #containers=6 available=1024 used=7168 with event: FINISHED
2013-08-10 14:29:37,135 INFO org.apache.hadoop.yarn.server.resourcemanager.rmcontainer.RMContainerImpl: container_1376143950665_0006_01_000007 Container Transitioned from NEW to ALLOCATED
2013-08-10 14:29:37,135 INFO org.apache.hadoop.yarn.server.resourcemanager.RMAuditLogger: USER=ubuntu	OPERATION=AM Allocated Container	TARGET=SchedulerApp	RESULT=SUCCESS	APPID=application_1376143950665_0006	CONTAINERID=container_1376143950665_0006_01_000007
2013-08-10 14:29:37,135 INFO org.apache.hadoop.yarn.server.resourcemanager.scheduler.common.fica.FiCaSchedulerNode: Assigned container container_1376143950665_0006_01_000007 of capacity <memory:1024, vCores:1> on host hadoop-221-6:51695, which currently has 7 containers, <memory:8192, vCores:7> used and <memory:0, vCores:9> available
2013-08-10 14:29:37,136 INFO org.apache.hadoop.yarn.server.resourcemanager.scheduler.capacity.LeafQueue: assignedContainer application=application_1376143950665_0006 container=Container: [ContainerId: container_1376143950665_0006_01_000007, NodeId: hadoop-221-6:51695, NodeHttpAddress: hadoop-221-6:8042, Resource: <memory:1024, vCores:1>, Priority: 20, State: NEW, Token: null, Status: container_id {, app_attempt_id {, application_id {, id: 6, cluster_timestamp: 1376143950665, }, attemptId: 1, }, id: 7, }, state: C_NEW, ] containerId=container_1376143950665_0006_01_000007 queue=default: capacity=1.0, absoluteCapacity=1.0, usedResources=<memory:48128, vCores:42>usedCapacity=0.9791667, absoluteUsedCapacity=0.9791667, numApps=5, numContainers=42 usedCapacity=0.9791667 absoluteUsedCapacity=0.9791667 used=<memory:48128, vCores:42> cluster=<memory:49152, vCores:96>
2013-08-10 14:29:37,136 INFO org.apache.hadoop.yarn.server.resourcemanager.scheduler.capacity.ParentQueue: Re-sorting queues since queue: root.default stats: default: capacity=1.0, absoluteCapacity=1.0, usedResources=<memory:49152, vCores:43>usedCapacity=1.0, absoluteUsedCapacity=1.0, numApps=5, numContainers=43
2013-08-10 14:29:37,136 INFO org.apache.hadoop.yarn.server.resourcemanager.scheduler.capacity.ParentQueue: assignedContainer queue=root usedCapacity=1.0 absoluteUsedCapacity=1.0 used=<memory:49152, vCores:43> cluster=<memory:49152, vCores:96>
2013-08-10 14:29:37,463 INFO org.apache.hadoop.yarn.server.resourcemanager.rmcontainer.RMContainerImpl: container_1376143950665_0006_01_000007 Container Transitioned from ALLOCATED to ACQUIRED
2013-08-10 14:29:38,139 INFO org.apache.hadoop.yarn.server.resourcemanager.rmcontainer.RMContainerImpl: container_1376143950665_0006_01_000007 Container Transitioned from ACQUIRED to RUNNING
2013-08-10 14:29:38,281 INFO org.apache.hadoop.yarn.server.resourcemanager.rmcontainer.RMContainerImpl: container_1376143950665_0010_01_000039 Container Transitioned from RUNNING to COMPLETED
2013-08-10 14:29:38,281 INFO org.apache.hadoop.yarn.server.resourcemanager.scheduler.common.fica.FiCaSchedulerApp: Completed container: container_1376143950665_0010_01_000039 in state: COMPLETED event:FINISHED
2013-08-10 14:29:38,281 INFO org.apache.hadoop.yarn.server.resourcemanager.RMAuditLogger: USER=ubuntu	OPERATION=AM Released Container	TARGET=SchedulerApp	RESULT=SUCCESS	APPID=application_1376143950665_0010	CONTAINERID=container_1376143950665_0010_01_000039
2013-08-10 14:29:38,281 INFO org.apache.hadoop.yarn.server.resourcemanager.scheduler.common.fica.FiCaSchedulerNode: Released container container_1376143950665_0010_01_000039 of capacity <memory:1024, vCores:1> on host hadoop-221-7:43558, which currently has 6 containers, <memory:7168, vCores:6> used and <memory:1024, vCores:10> available, release resources=true
2013-08-10 14:29:38,281 INFO org.apache.hadoop.yarn.server.resourcemanager.scheduler.capacity.LeafQueue: default used=<memory:48128, vCores:42> numContainers=42 user=ubuntu user-resources=<memory:48128, vCores:42>
2013-08-10 14:29:38,282 INFO org.apache.hadoop.yarn.server.resourcemanager.scheduler.capacity.LeafQueue: completedContainer container=Container: [ContainerId: container_1376143950665_0010_01_000039, NodeId: hadoop-221-7:43558, NodeHttpAddress: hadoop-221-7:8042, Resource: <memory:1024, vCores:1>, Priority: 20, State: NEW, Token: null, Status: container_id {, app_attempt_id {, application_id {, id: 10, cluster_timestamp: 1376143950665, }, attemptId: 1, }, id: 39, }, state: C_COMPLETE, diagnostics: "Container killed by the ApplicationMaster.\n\n", exit_status: 143, ] resource=<memory:1024, vCores:1> queue=default: capacity=1.0, absoluteCapacity=1.0, usedResources=<memory:48128, vCores:42>usedCapacity=0.9791667, absoluteUsedCapacity=0.9791667, numApps=5, numContainers=42 usedCapacity=0.9791667 absoluteUsedCapacity=0.9791667 used=<memory:48128, vCores:42> cluster=<memory:49152, vCores:96>
2013-08-10 14:29:38,283 INFO org.apache.hadoop.yarn.server.resourcemanager.scheduler.capacity.ParentQueue: completedContainer queue=root usedCapacity=0.9791667 absoluteUsedCapacity=0.9791667 used=<memory:48128, vCores:42> cluster=<memory:49152, vCores:96>
2013-08-10 14:29:38,283 INFO org.apache.hadoop.yarn.server.resourcemanager.scheduler.capacity.CapacityScheduler: Application appattempt_1376143950665_0010_000001 released container container_1376143950665_0010_01_000039 on node: host: hadoop-221-7:43558 #containers=6 available=1024 used=7168 with event: FINISHED
2013-08-10 14:29:38,283 INFO org.apache.hadoop.yarn.server.resourcemanager.rmcontainer.RMContainerImpl: container_1376143950665_0006_01_000008 Container Transitioned from NEW to ALLOCATED
2013-08-10 14:29:38,283 INFO org.apache.hadoop.yarn.server.resourcemanager.RMAuditLogger: USER=ubuntu	OPERATION=AM Allocated Container	TARGET=SchedulerApp	RESULT=SUCCESS	APPID=application_1376143950665_0006	CONTAINERID=container_1376143950665_0006_01_000008
2013-08-10 14:29:38,284 INFO org.apache.hadoop.yarn.server.resourcemanager.scheduler.common.fica.FiCaSchedulerNode: Assigned container container_1376143950665_0006_01_000008 of capacity <memory:1024, vCores:1> on host hadoop-221-7:43558, which currently has 7 containers, <memory:8192, vCores:7> used and <memory:0, vCores:9> available
2013-08-10 14:29:38,284 INFO org.apache.hadoop.yarn.server.resourcemanager.scheduler.capacity.LeafQueue: assignedContainer application=application_1376143950665_0006 container=Container: [ContainerId: container_1376143950665_0006_01_000008, NodeId: hadoop-221-7:43558, NodeHttpAddress: hadoop-221-7:8042, Resource: <memory:1024, vCores:1>, Priority: 20, State: NEW, Token: null, Status: container_id {, app_attempt_id {, application_id {, id: 6, cluster_timestamp: 1376143950665, }, attemptId: 1, }, id: 8, }, state: C_NEW, ] containerId=container_1376143950665_0006_01_000008 queue=default: capacity=1.0, absoluteCapacity=1.0, usedResources=<memory:48128, vCores:42>usedCapacity=0.9791667, absoluteUsedCapacity=0.9791667, numApps=5, numContainers=42 usedCapacity=0.9791667 absoluteUsedCapacity=0.9791667 used=<memory:48128, vCores:42> cluster=<memory:49152, vCores:96>
2013-08-10 14:29:38,285 INFO org.apache.hadoop.yarn.server.resourcemanager.scheduler.capacity.ParentQueue: Re-sorting queues since queue: root.default stats: default: capacity=1.0, absoluteCapacity=1.0, usedResources=<memory:49152, vCores:43>usedCapacity=1.0, absoluteUsedCapacity=1.0, numApps=5, numContainers=43
2013-08-10 14:29:38,285 INFO org.apache.hadoop.yarn.server.resourcemanager.scheduler.capacity.ParentQueue: assignedContainer queue=root usedCapacity=1.0 absoluteUsedCapacity=1.0 used=<memory:49152, vCores:43> cluster=<memory:49152, vCores:96>
2013-08-10 14:29:38,471 INFO org.apache.hadoop.yarn.server.resourcemanager.rmcontainer.RMContainerImpl: container_1376143950665_0006_01_000008 Container Transitioned from ALLOCATED to ACQUIRED
2013-08-10 14:29:39,291 INFO org.apache.hadoop.yarn.server.resourcemanager.rmcontainer.RMContainerImpl: container_1376143950665_0006_01_000008 Container Transitioned from ACQUIRED to RUNNING
2013-08-10 14:29:41,207 INFO org.apache.hadoop.yarn.server.resourcemanager.rmcontainer.RMContainerImpl: container_1376143950665_0010_01_000031 Container Transitioned from RUNNING to COMPLETED
2013-08-10 14:29:41,207 INFO org.apache.hadoop.yarn.server.resourcemanager.scheduler.common.fica.FiCaSchedulerApp: Completed container: container_1376143950665_0010_01_000031 in state: COMPLETED event:FINISHED
2013-08-10 14:29:41,207 INFO org.apache.hadoop.yarn.server.resourcemanager.RMAuditLogger: USER=ubuntu	OPERATION=AM Released Container	TARGET=SchedulerApp	RESULT=SUCCESS	APPID=application_1376143950665_0010	CONTAINERID=container_1376143950665_0010_01_000031
2013-08-10 14:29:41,207 INFO org.apache.hadoop.yarn.server.resourcemanager.scheduler.common.fica.FiCaSchedulerNode: Released container container_1376143950665_0010_01_000031 of capacity <memory:1024, vCores:1> on host hadoop-221-3:48808, which currently has 7 containers, <memory:7168, vCores:7> used and <memory:1024, vCores:9> available, release resources=true
2013-08-10 14:29:41,207 INFO org.apache.hadoop.yarn.server.resourcemanager.scheduler.capacity.LeafQueue: default used=<memory:48128, vCores:42> numContainers=42 user=ubuntu user-resources=<memory:48128, vCores:42>
2013-08-10 14:29:41,209 INFO org.apache.hadoop.yarn.server.resourcemanager.scheduler.capacity.LeafQueue: completedContainer container=Container: [ContainerId: container_1376143950665_0010_01_000031, NodeId: hadoop-221-3:48808, NodeHttpAddress: hadoop-221-3:8042, Resource: <memory:1024, vCores:1>, Priority: 20, State: NEW, Token: null, Status: container_id {, app_attempt_id {, application_id {, id: 10, cluster_timestamp: 1376143950665, }, attemptId: 1, }, id: 31, }, state: C_COMPLETE, diagnostics: "Container killed by the ApplicationMaster.\n\n", exit_status: 143, ] resource=<memory:1024, vCores:1> queue=default: capacity=1.0, absoluteCapacity=1.0, usedResources=<memory:48128, vCores:42>usedCapacity=0.9791667, absoluteUsedCapacity=0.9791667, numApps=5, numContainers=42 usedCapacity=0.9791667 absoluteUsedCapacity=0.9791667 used=<memory:48128, vCores:42> cluster=<memory:49152, vCores:96>
2013-08-10 14:29:41,209 INFO org.apache.hadoop.yarn.server.resourcemanager.scheduler.capacity.ParentQueue: completedContainer queue=root usedCapacity=0.9791667 absoluteUsedCapacity=0.9791667 used=<memory:48128, vCores:42> cluster=<memory:49152, vCores:96>
2013-08-10 14:29:41,209 INFO org.apache.hadoop.yarn.server.resourcemanager.scheduler.capacity.CapacityScheduler: Application appattempt_1376143950665_0010_000001 released container container_1376143950665_0010_01_000031 on node: host: hadoop-221-3:48808 #containers=7 available=1024 used=7168 with event: FINISHED
2013-08-10 14:29:41,210 INFO org.apache.hadoop.yarn.server.resourcemanager.rmcontainer.RMContainerImpl: container_1376143950665_0006_01_000009 Container Transitioned from NEW to ALLOCATED
2013-08-10 14:29:41,210 INFO org.apache.hadoop.yarn.server.resourcemanager.RMAuditLogger: USER=ubuntu	OPERATION=AM Allocated Container	TARGET=SchedulerApp	RESULT=SUCCESS	APPID=application_1376143950665_0006	CONTAINERID=container_1376143950665_0006_01_000009
2013-08-10 14:29:41,210 INFO org.apache.hadoop.yarn.server.resourcemanager.scheduler.common.fica.FiCaSchedulerNode: Assigned container container_1376143950665_0006_01_000009 of capacity <memory:1024, vCores:1> on host hadoop-221-3:48808, which currently has 8 containers, <memory:8192, vCores:8> used and <memory:0, vCores:8> available
2013-08-10 14:29:41,211 INFO org.apache.hadoop.yarn.server.resourcemanager.scheduler.capacity.LeafQueue: assignedContainer application=application_1376143950665_0006 container=Container: [ContainerId: container_1376143950665_0006_01_000009, NodeId: hadoop-221-3:48808, NodeHttpAddress: hadoop-221-3:8042, Resource: <memory:1024, vCores:1>, Priority: 20, State: NEW, Token: null, Status: container_id {, app_attempt_id {, application_id {, id: 6, cluster_timestamp: 1376143950665, }, attemptId: 1, }, id: 9, }, state: C_NEW, ] containerId=container_1376143950665_0006_01_000009 queue=default: capacity=1.0, absoluteCapacity=1.0, usedResources=<memory:48128, vCores:42>usedCapacity=0.9791667, absoluteUsedCapacity=0.9791667, numApps=5, numContainers=42 usedCapacity=0.9791667 absoluteUsedCapacity=0.9791667 used=<memory:48128, vCores:42> cluster=<memory:49152, vCores:96>
2013-08-10 14:29:41,211 INFO org.apache.hadoop.yarn.server.resourcemanager.scheduler.capacity.ParentQueue: Re-sorting queues since queue: root.default stats: default: capacity=1.0, absoluteCapacity=1.0, usedResources=<memory:49152, vCores:43>usedCapacity=1.0, absoluteUsedCapacity=1.0, numApps=5, numContainers=43
2013-08-10 14:29:41,211 INFO org.apache.hadoop.yarn.server.resourcemanager.scheduler.capacity.ParentQueue: assignedContainer queue=root usedCapacity=1.0 absoluteUsedCapacity=1.0 used=<memory:49152, vCores:43> cluster=<memory:49152, vCores:96>
2013-08-10 14:29:41,882 INFO org.apache.hadoop.yarn.server.resourcemanager.rmcontainer.RMContainerImpl: container_1376143950665_0006_01_000009 Container Transitioned from ALLOCATED to ACQUIRED
2013-08-10 14:29:42,226 INFO org.apache.hadoop.yarn.server.resourcemanager.rmcontainer.RMContainerImpl: container_1376143950665_0006_01_000009 Container Transitioned from ACQUIRED to RUNNING
2013-08-10 14:29:42,226 INFO org.apache.hadoop.yarn.server.resourcemanager.rmcontainer.RMContainerImpl: container_1376143950665_0010_01_000030 Container Transitioned from RUNNING to COMPLETED
2013-08-10 14:29:42,226 INFO org.apache.hadoop.yarn.server.resourcemanager.scheduler.common.fica.FiCaSchedulerApp: Completed container: container_1376143950665_0010_01_000030 in state: COMPLETED event:FINISHED
2013-08-10 14:29:42,226 INFO org.apache.hadoop.yarn.server.resourcemanager.RMAuditLogger: USER=ubuntu	OPERATION=AM Released Container	TARGET=SchedulerApp	RESULT=SUCCESS	APPID=application_1376143950665_0010	CONTAINERID=container_1376143950665_0010_01_000030
2013-08-10 14:29:42,226 INFO org.apache.hadoop.yarn.server.resourcemanager.scheduler.common.fica.FiCaSchedulerNode: Released container container_1376143950665_0010_01_000030 of capacity <memory:1024, vCores:1> on host hadoop-221-3:48808, which currently has 7 containers, <memory:7168, vCores:7> used and <memory:1024, vCores:9> available, release resources=true
2013-08-10 14:29:42,227 INFO org.apache.hadoop.yarn.server.resourcemanager.scheduler.capacity.LeafQueue: default used=<memory:48128, vCores:42> numContainers=42 user=ubuntu user-resources=<memory:48128, vCores:42>
2013-08-10 14:29:42,228 INFO org.apache.hadoop.yarn.server.resourcemanager.scheduler.capacity.LeafQueue: completedContainer container=Container: [ContainerId: container_1376143950665_0010_01_000030, NodeId: hadoop-221-3:48808, NodeHttpAddress: hadoop-221-3:8042, Resource: <memory:1024, vCores:1>, Priority: 20, State: NEW, Token: null, Status: container_id {, app_attempt_id {, application_id {, id: 10, cluster_timestamp: 1376143950665, }, attemptId: 1, }, id: 30, }, state: C_COMPLETE, diagnostics: "Container killed by the ApplicationMaster.\n\n", exit_status: 143, ] resource=<memory:1024, vCores:1> queue=default: capacity=1.0, absoluteCapacity=1.0, usedResources=<memory:48128, vCores:42>usedCapacity=0.9791667, absoluteUsedCapacity=0.9791667, numApps=5, numContainers=42 usedCapacity=0.9791667 absoluteUsedCapacity=0.9791667 used=<memory:48128, vCores:42> cluster=<memory:49152, vCores:96>
2013-08-10 14:29:42,228 INFO org.apache.hadoop.yarn.server.resourcemanager.scheduler.capacity.ParentQueue: completedContainer queue=root usedCapacity=0.9791667 absoluteUsedCapacity=0.9791667 used=<memory:48128, vCores:42> cluster=<memory:49152, vCores:96>
2013-08-10 14:29:42,228 INFO org.apache.hadoop.yarn.server.resourcemanager.scheduler.capacity.CapacityScheduler: Application appattempt_1376143950665_0010_000001 released container container_1376143950665_0010_01_000030 on node: host: hadoop-221-3:48808 #containers=7 available=1024 used=7168 with event: FINISHED
2013-08-10 14:29:42,229 INFO org.apache.hadoop.yarn.server.resourcemanager.rmcontainer.RMContainerImpl: container_1376143950665_0006_01_000010 Container Transitioned from NEW to ALLOCATED
2013-08-10 14:29:42,229 INFO org.apache.hadoop.yarn.server.resourcemanager.RMAuditLogger: USER=ubuntu	OPERATION=AM Allocated Container	TARGET=SchedulerApp	RESULT=SUCCESS	APPID=application_1376143950665_0006	CONTAINERID=container_1376143950665_0006_01_000010
2013-08-10 14:29:42,229 INFO org.apache.hadoop.yarn.server.resourcemanager.scheduler.common.fica.FiCaSchedulerNode: Assigned container container_1376143950665_0006_01_000010 of capacity <memory:1024, vCores:1> on host hadoop-221-3:48808, which currently has 8 containers, <memory:8192, vCores:8> used and <memory:0, vCores:8> available
2013-08-10 14:29:42,230 INFO org.apache.hadoop.yarn.server.resourcemanager.scheduler.capacity.LeafQueue: assignedContainer application=application_1376143950665_0006 container=Container: [ContainerId: container_1376143950665_0006_01_000010, NodeId: hadoop-221-3:48808, NodeHttpAddress: hadoop-221-3:8042, Resource: <memory:1024, vCores:1>, Priority: 20, State: NEW, Token: null, Status: container_id {, app_attempt_id {, application_id {, id: 6, cluster_timestamp: 1376143950665, }, attemptId: 1, }, id: 10, }, state: C_NEW, ] containerId=container_1376143950665_0006_01_000010 queue=default: capacity=1.0, absoluteCapacity=1.0, usedResources=<memory:48128, vCores:42>usedCapacity=0.9791667, absoluteUsedCapacity=0.9791667, numApps=5, numContainers=42 usedCapacity=0.9791667 absoluteUsedCapacity=0.9791667 used=<memory:48128, vCores:42> cluster=<memory:49152, vCores:96>
2013-08-10 14:29:42,230 INFO org.apache.hadoop.yarn.server.resourcemanager.scheduler.capacity.ParentQueue: Re-sorting queues since queue: root.default stats: default: capacity=1.0, absoluteCapacity=1.0, usedResources=<memory:49152, vCores:43>usedCapacity=1.0, absoluteUsedCapacity=1.0, numApps=5, numContainers=43
2013-08-10 14:29:42,230 INFO org.apache.hadoop.yarn.server.resourcemanager.scheduler.capacity.ParentQueue: assignedContainer queue=root usedCapacity=1.0 absoluteUsedCapacity=1.0 used=<memory:49152, vCores:43> cluster=<memory:49152, vCores:96>
2013-08-10 14:29:42,903 INFO org.apache.hadoop.yarn.server.resourcemanager.rmcontainer.RMContainerImpl: container_1376143950665_0006_01_000010 Container Transitioned from ALLOCATED to ACQUIRED
2013-08-10 14:29:43,244 INFO org.apache.hadoop.yarn.server.resourcemanager.rmcontainer.RMContainerImpl: container_1376143950665_0006_01_000010 Container Transitioned from ACQUIRED to RUNNING
2013-08-10 14:29:45,185 INFO org.apache.hadoop.yarn.server.resourcemanager.rmcontainer.RMContainerImpl: container_1376143950665_0010_01_000026 Container Transitioned from RUNNING to COMPLETED
2013-08-10 14:29:45,185 INFO org.apache.hadoop.yarn.server.resourcemanager.scheduler.common.fica.FiCaSchedulerApp: Completed container: container_1376143950665_0010_01_000026 in state: COMPLETED event:FINISHED
2013-08-10 14:29:45,185 INFO org.apache.hadoop.yarn.server.resourcemanager.RMAuditLogger: USER=ubuntu	OPERATION=AM Released Container	TARGET=SchedulerApp	RESULT=SUCCESS	APPID=application_1376143950665_0010	CONTAINERID=container_1376143950665_0010_01_000026
2013-08-10 14:29:45,186 INFO org.apache.hadoop.yarn.server.resourcemanager.scheduler.common.fica.FiCaSchedulerNode: Released container container_1376143950665_0010_01_000026 of capacity <memory:1024, vCores:1> on host hadoop-221-3:48808, which currently has 7 containers, <memory:7168, vCores:7> used and <memory:1024, vCores:9> available, release resources=true
2013-08-10 14:29:45,186 INFO org.apache.hadoop.yarn.server.resourcemanager.scheduler.capacity.LeafQueue: default used=<memory:48128, vCores:42> numContainers=42 user=ubuntu user-resources=<memory:48128, vCores:42>
2013-08-10 14:29:45,187 INFO org.apache.hadoop.yarn.server.resourcemanager.scheduler.capacity.LeafQueue: completedContainer container=Container: [ContainerId: container_1376143950665_0010_01_000026, NodeId: hadoop-221-3:48808, NodeHttpAddress: hadoop-221-3:8042, Resource: <memory:1024, vCores:1>, Priority: 20, State: NEW, Token: null, Status: container_id {, app_attempt_id {, application_id {, id: 10, cluster_timestamp: 1376143950665, }, attemptId: 1, }, id: 26, }, state: C_COMPLETE, diagnostics: "", exit_status: 0, ] resource=<memory:1024, vCores:1> queue=default: capacity=1.0, absoluteCapacity=1.0, usedResources=<memory:48128, vCores:42>usedCapacity=0.9791667, absoluteUsedCapacity=0.9791667, numApps=5, numContainers=42 usedCapacity=0.9791667 absoluteUsedCapacity=0.9791667 used=<memory:48128, vCores:42> cluster=<memory:49152, vCores:96>
2013-08-10 14:29:45,187 INFO org.apache.hadoop.yarn.server.resourcemanager.scheduler.capacity.ParentQueue: completedContainer queue=root usedCapacity=0.9791667 absoluteUsedCapacity=0.9791667 used=<memory:48128, vCores:42> cluster=<memory:49152, vCores:96>
2013-08-10 14:29:45,187 INFO org.apache.hadoop.yarn.server.resourcemanager.scheduler.capacity.CapacityScheduler: Application appattempt_1376143950665_0010_000001 released container container_1376143950665_0010_01_000026 on node: host: hadoop-221-3:48808 #containers=7 available=1024 used=7168 with event: FINISHED
2013-08-10 14:29:45,187 INFO org.apache.hadoop.yarn.server.resourcemanager.rmcontainer.RMContainerImpl: container_1376143950665_0010_01_000029 Container Transitioned from RUNNING to COMPLETED
2013-08-10 14:29:45,187 INFO org.apache.hadoop.yarn.server.resourcemanager.scheduler.common.fica.FiCaSchedulerApp: Completed container: container_1376143950665_0010_01_000029 in state: COMPLETED event:FINISHED
2013-08-10 14:29:45,187 INFO org.apache.hadoop.yarn.server.resourcemanager.RMAuditLogger: USER=ubuntu	OPERATION=AM Released Container	TARGET=SchedulerApp	RESULT=SUCCESS	APPID=application_1376143950665_0010	CONTAINERID=container_1376143950665_0010_01_000029
2013-08-10 14:29:45,188 INFO org.apache.hadoop.yarn.server.resourcemanager.scheduler.common.fica.FiCaSchedulerNode: Released container container_1376143950665_0010_01_000029 of capacity <memory:1024, vCores:1> on host hadoop-221-3:48808, which currently has 6 containers, <memory:6144, vCores:6> used and <memory:2048, vCores:10> available, release resources=true
2013-08-10 14:29:45,188 INFO org.apache.hadoop.yarn.server.resourcemanager.scheduler.capacity.LeafQueue: default used=<memory:47104, vCores:41> numContainers=41 user=ubuntu user-resources=<memory:47104, vCores:41>
2013-08-10 14:29:45,192 INFO org.apache.hadoop.yarn.server.resourcemanager.scheduler.capacity.LeafQueue: completedContainer container=Container: [ContainerId: container_1376143950665_0010_01_000029, NodeId: hadoop-221-3:48808, NodeHttpAddress: hadoop-221-3:8042, Resource: <memory:1024, vCores:1>, Priority: 20, State: NEW, Token: null, Status: container_id {, app_attempt_id {, application_id {, id: 10, cluster_timestamp: 1376143950665, }, attemptId: 1, }, id: 29, }, state: C_COMPLETE, diagnostics: "Container killed by the ApplicationMaster.\n\n", exit_status: 143, ] resource=<memory:1024, vCores:1> queue=default: capacity=1.0, absoluteCapacity=1.0, usedResources=<memory:47104, vCores:41>usedCapacity=0.9583333, absoluteUsedCapacity=0.9583333, numApps=5, numContainers=41 usedCapacity=0.9583333 absoluteUsedCapacity=0.9583333 used=<memory:47104, vCores:41> cluster=<memory:49152, vCores:96>
2013-08-10 14:29:45,193 INFO org.apache.hadoop.yarn.server.resourcemanager.scheduler.capacity.ParentQueue: completedContainer queue=root usedCapacity=0.9583333 absoluteUsedCapacity=0.9583333 used=<memory:47104, vCores:41> cluster=<memory:49152, vCores:96>
2013-08-10 14:29:45,193 INFO org.apache.hadoop.yarn.server.resourcemanager.scheduler.capacity.CapacityScheduler: Application appattempt_1376143950665_0010_000001 released container container_1376143950665_0010_01_000029 on node: host: hadoop-221-3:48808 #containers=6 available=2048 used=6144 with event: FINISHED
2013-08-10 14:29:45,193 INFO org.apache.hadoop.yarn.server.resourcemanager.rmcontainer.RMContainerImpl: container_1376143950665_0006_01_000011 Container Transitioned from NEW to ALLOCATED
2013-08-10 14:29:45,193 INFO org.apache.hadoop.yarn.server.resourcemanager.RMAuditLogger: USER=ubuntu	OPERATION=AM Allocated Container	TARGET=SchedulerApp	RESULT=SUCCESS	APPID=application_1376143950665_0006	CONTAINERID=container_1376143950665_0006_01_000011
2013-08-10 14:29:45,193 INFO org.apache.hadoop.yarn.server.resourcemanager.scheduler.common.fica.FiCaSchedulerNode: Assigned container container_1376143950665_0006_01_000011 of capacity <memory:1024, vCores:1> on host hadoop-221-3:48808, which currently has 7 containers, <memory:7168, vCores:7> used and <memory:1024, vCores:9> available
2013-08-10 14:29:45,194 INFO org.apache.hadoop.yarn.server.resourcemanager.scheduler.capacity.LeafQueue: assignedContainer application=application_1376143950665_0006 container=Container: [ContainerId: container_1376143950665_0006_01_000011, NodeId: hadoop-221-3:48808, NodeHttpAddress: hadoop-221-3:8042, Resource: <memory:1024, vCores:1>, Priority: 20, State: NEW, Token: null, Status: container_id {, app_attempt_id {, application_id {, id: 6, cluster_timestamp: 1376143950665, }, attemptId: 1, }, id: 11, }, state: C_NEW, ] containerId=container_1376143950665_0006_01_000011 queue=default: capacity=1.0, absoluteCapacity=1.0, usedResources=<memory:47104, vCores:41>usedCapacity=0.9583333, absoluteUsedCapacity=0.9583333, numApps=5, numContainers=41 usedCapacity=0.9583333 absoluteUsedCapacity=0.9583333 used=<memory:47104, vCores:41> cluster=<memory:49152, vCores:96>
2013-08-10 14:29:45,194 INFO org.apache.hadoop.yarn.server.resourcemanager.scheduler.capacity.ParentQueue: Re-sorting queues since queue: root.default stats: default: capacity=1.0, absoluteCapacity=1.0, usedResources=<memory:48128, vCores:42>usedCapacity=0.9791667, absoluteUsedCapacity=0.9791667, numApps=5, numContainers=42
2013-08-10 14:29:45,195 INFO org.apache.hadoop.yarn.server.resourcemanager.scheduler.capacity.ParentQueue: assignedContainer queue=root usedCapacity=0.9791667 absoluteUsedCapacity=0.9791667 used=<memory:48128, vCores:42> cluster=<memory:49152, vCores:96>
2013-08-10 14:29:45,195 INFO org.apache.hadoop.yarn.server.resourcemanager.rmcontainer.RMContainerImpl: container_1376143950665_0006_01_000012 Container Transitioned from NEW to ALLOCATED
2013-08-10 14:29:45,195 INFO org.apache.hadoop.yarn.server.resourcemanager.RMAuditLogger: USER=ubuntu	OPERATION=AM Allocated Container	TARGET=SchedulerApp	RESULT=SUCCESS	APPID=application_1376143950665_0006	CONTAINERID=container_1376143950665_0006_01_000012
2013-08-10 14:29:45,195 INFO org.apache.hadoop.yarn.server.resourcemanager.scheduler.common.fica.FiCaSchedulerNode: Assigned container container_1376143950665_0006_01_000012 of capacity <memory:1024, vCores:1> on host hadoop-221-3:48808, which currently has 8 containers, <memory:8192, vCores:8> used and <memory:0, vCores:8> available
2013-08-10 14:29:45,196 INFO org.apache.hadoop.yarn.server.resourcemanager.scheduler.capacity.LeafQueue: assignedContainer application=application_1376143950665_0006 container=Container: [ContainerId: container_1376143950665_0006_01_000012, NodeId: hadoop-221-3:48808, NodeHttpAddress: hadoop-221-3:8042, Resource: <memory:1024, vCores:1>, Priority: 20, State: NEW, Token: null, Status: container_id {, app_attempt_id {, application_id {, id: 6, cluster_timestamp: 1376143950665, }, attemptId: 1, }, id: 12, }, state: C_NEW, ] containerId=container_1376143950665_0006_01_000012 queue=default: capacity=1.0, absoluteCapacity=1.0, usedResources=<memory:48128, vCores:42>usedCapacity=0.9791667, absoluteUsedCapacity=0.9791667, numApps=5, numContainers=42 usedCapacity=0.9791667 absoluteUsedCapacity=0.9791667 used=<memory:48128, vCores:42> cluster=<memory:49152, vCores:96>
2013-08-10 14:29:45,196 INFO org.apache.hadoop.yarn.server.resourcemanager.scheduler.capacity.ParentQueue: Re-sorting queues since queue: root.default stats: default: capacity=1.0, absoluteCapacity=1.0, usedResources=<memory:49152, vCores:43>usedCapacity=1.0, absoluteUsedCapacity=1.0, numApps=5, numContainers=43
2013-08-10 14:29:45,197 INFO org.apache.hadoop.yarn.server.resourcemanager.scheduler.capacity.ParentQueue: assignedContainer queue=root usedCapacity=1.0 absoluteUsedCapacity=1.0 used=<memory:49152, vCores:43> cluster=<memory:49152, vCores:96>
2013-08-10 14:29:45,931 INFO org.apache.hadoop.yarn.server.resourcemanager.rmcontainer.RMContainerImpl: container_1376143950665_0006_01_000011 Container Transitioned from ALLOCATED to ACQUIRED
2013-08-10 14:29:45,932 INFO org.apache.hadoop.yarn.server.resourcemanager.rmcontainer.RMContainerImpl: container_1376143950665_0006_01_000012 Container Transitioned from ALLOCATED to ACQUIRED
2013-08-10 14:29:46,205 INFO org.apache.hadoop.yarn.server.resourcemanager.rmcontainer.RMContainerImpl: container_1376143950665_0006_01_000011 Container Transitioned from ACQUIRED to RUNNING
2013-08-10 14:29:46,205 INFO org.apache.hadoop.yarn.server.resourcemanager.rmcontainer.RMContainerImpl: container_1376143950665_0006_01_000012 Container Transitioned from ACQUIRED to RUNNING
2013-08-10 14:29:46,734 INFO org.apache.hadoop.yarn.server.resourcemanager.rmcontainer.RMContainerImpl: container_1376143950665_0010_01_000002 Container Transitioned from RUNNING to COMPLETED
2013-08-10 14:29:46,735 INFO org.apache.hadoop.yarn.server.resourcemanager.scheduler.common.fica.FiCaSchedulerApp: Completed container: container_1376143950665_0010_01_000002 in state: COMPLETED event:FINISHED
2013-08-10 14:29:46,735 INFO org.apache.hadoop.yarn.server.resourcemanager.RMAuditLogger: USER=ubuntu	OPERATION=AM Released Container	TARGET=SchedulerApp	RESULT=SUCCESS	APPID=application_1376143950665_0010	CONTAINERID=container_1376143950665_0010_01_000002
2013-08-10 14:29:46,735 INFO org.apache.hadoop.yarn.server.resourcemanager.scheduler.common.fica.FiCaSchedulerNode: Released container container_1376143950665_0010_01_000002 of capacity <memory:1024, vCores:1> on host hadoop-221-2:53277, which currently has 6 containers, <memory:7168, vCores:6> used and <memory:1024, vCores:10> available, release resources=true
2013-08-10 14:29:46,735 INFO org.apache.hadoop.yarn.server.resourcemanager.scheduler.capacity.LeafQueue: default used=<memory:48128, vCores:42> numContainers=42 user=ubuntu user-resources=<memory:48128, vCores:42>
2013-08-10 14:29:46,736 INFO org.apache.hadoop.yarn.server.resourcemanager.scheduler.capacity.LeafQueue: completedContainer container=Container: [ContainerId: container_1376143950665_0010_01_000002, NodeId: hadoop-221-2:53277, NodeHttpAddress: hadoop-221-2:8042, Resource: <memory:1024, vCores:1>, Priority: 20, State: NEW, Token: null, Status: container_id {, app_attempt_id {, application_id {, id: 10, cluster_timestamp: 1376143950665, }, attemptId: 1, }, id: 2, }, state: C_COMPLETE, diagnostics: "Container killed by the ApplicationMaster.\n\n", exit_status: 143, ] resource=<memory:1024, vCores:1> queue=default: capacity=1.0, absoluteCapacity=1.0, usedResources=<memory:48128, vCores:42>usedCapacity=0.9791667, absoluteUsedCapacity=0.9791667, numApps=5, numContainers=42 usedCapacity=0.9791667 absoluteUsedCapacity=0.9791667 used=<memory:48128, vCores:42> cluster=<memory:49152, vCores:96>
2013-08-10 14:29:46,736 INFO org.apache.hadoop.yarn.server.resourcemanager.scheduler.capacity.ParentQueue: completedContainer queue=root usedCapacity=0.9791667 absoluteUsedCapacity=0.9791667 used=<memory:48128, vCores:42> cluster=<memory:49152, vCores:96>
2013-08-10 14:29:46,736 INFO org.apache.hadoop.yarn.server.resourcemanager.scheduler.capacity.CapacityScheduler: Application appattempt_1376143950665_0010_000001 released container container_1376143950665_0010_01_000002 on node: host: hadoop-221-2:53277 #containers=6 available=1024 used=7168 with event: FINISHED
2013-08-10 14:29:46,737 INFO org.apache.hadoop.yarn.server.resourcemanager.rmcontainer.RMContainerImpl: container_1376143950665_0006_01_000013 Container Transitioned from NEW to ALLOCATED
2013-08-10 14:29:46,737 INFO org.apache.hadoop.yarn.server.resourcemanager.RMAuditLogger: USER=ubuntu	OPERATION=AM Allocated Container	TARGET=SchedulerApp	RESULT=SUCCESS	APPID=application_1376143950665_0006	CONTAINERID=container_1376143950665_0006_01_000013
2013-08-10 14:29:46,737 INFO org.apache.hadoop.yarn.server.resourcemanager.scheduler.common.fica.FiCaSchedulerNode: Assigned container container_1376143950665_0006_01_000013 of capacity <memory:1024, vCores:1> on host hadoop-221-2:53277, which currently has 7 containers, <memory:8192, vCores:7> used and <memory:0, vCores:9> available
2013-08-10 14:29:46,738 INFO org.apache.hadoop.yarn.server.resourcemanager.scheduler.capacity.LeafQueue: assignedContainer application=application_1376143950665_0006 container=Container: [ContainerId: container_1376143950665_0006_01_000013, NodeId: hadoop-221-2:53277, NodeHttpAddress: hadoop-221-2:8042, Resource: <memory:1024, vCores:1>, Priority: 20, State: NEW, Token: null, Status: container_id {, app_attempt_id {, application_id {, id: 6, cluster_timestamp: 1376143950665, }, attemptId: 1, }, id: 13, }, state: C_NEW, ] containerId=container_1376143950665_0006_01_000013 queue=default: capacity=1.0, absoluteCapacity=1.0, usedResources=<memory:48128, vCores:42>usedCapacity=0.9791667, absoluteUsedCapacity=0.9791667, numApps=5, numContainers=42 usedCapacity=0.9791667 absoluteUsedCapacity=0.9791667 used=<memory:48128, vCores:42> cluster=<memory:49152, vCores:96>
2013-08-10 14:29:46,738 INFO org.apache.hadoop.yarn.server.resourcemanager.scheduler.capacity.ParentQueue: Re-sorting queues since queue: root.default stats: default: capacity=1.0, absoluteCapacity=1.0, usedResources=<memory:49152, vCores:43>usedCapacity=1.0, absoluteUsedCapacity=1.0, numApps=5, numContainers=43
2013-08-10 14:29:46,738 INFO org.apache.hadoop.yarn.server.resourcemanager.scheduler.capacity.ParentQueue: assignedContainer queue=root usedCapacity=1.0 absoluteUsedCapacity=1.0 used=<memory:49152, vCores:43> cluster=<memory:49152, vCores:96>
2013-08-10 14:29:46,944 INFO org.apache.hadoop.yarn.server.resourcemanager.rmcontainer.RMContainerImpl: container_1376143950665_0006_01_000013 Container Transitioned from ALLOCATED to ACQUIRED
2013-08-10 14:29:47,019 INFO org.apache.hadoop.yarn.server.resourcemanager.rmcontainer.RMContainerImpl: container_1376143950665_0010_01_000020 Container Transitioned from RUNNING to COMPLETED
2013-08-10 14:29:47,019 INFO org.apache.hadoop.yarn.server.resourcemanager.scheduler.common.fica.FiCaSchedulerApp: Completed container: container_1376143950665_0010_01_000020 in state: COMPLETED event:FINISHED
2013-08-10 14:29:47,020 INFO org.apache.hadoop.yarn.server.resourcemanager.RMAuditLogger: USER=ubuntu	OPERATION=AM Released Container	TARGET=SchedulerApp	RESULT=SUCCESS	APPID=application_1376143950665_0010	CONTAINERID=container_1376143950665_0010_01_000020
2013-08-10 14:29:47,020 INFO org.apache.hadoop.yarn.server.resourcemanager.scheduler.common.fica.FiCaSchedulerNode: Released container container_1376143950665_0010_01_000020 of capacity <memory:1024, vCores:1> on host hadoop-221-6:51695, which currently has 6 containers, <memory:7168, vCores:6> used and <memory:1024, vCores:10> available, release resources=true
2013-08-10 14:29:47,020 INFO org.apache.hadoop.yarn.server.resourcemanager.scheduler.capacity.LeafQueue: default used=<memory:48128, vCores:42> numContainers=42 user=ubuntu user-resources=<memory:48128, vCores:42>
2013-08-10 14:29:47,021 INFO org.apache.hadoop.yarn.server.resourcemanager.scheduler.capacity.LeafQueue: completedContainer container=Container: [ContainerId: container_1376143950665_0010_01_000020, NodeId: hadoop-221-6:51695, NodeHttpAddress: hadoop-221-6:8042, Resource: <memory:1024, vCores:1>, Priority: 20, State: NEW, Token: null, Status: container_id {, app_attempt_id {, application_id {, id: 10, cluster_timestamp: 1376143950665, }, attemptId: 1, }, id: 20, }, state: C_COMPLETE, diagnostics: "Container killed by the ApplicationMaster.\n\n", exit_status: 143, ] resource=<memory:1024, vCores:1> queue=default: capacity=1.0, absoluteCapacity=1.0, usedResources=<memory:48128, vCores:42>usedCapacity=0.9791667, absoluteUsedCapacity=0.9791667, numApps=5, numContainers=42 usedCapacity=0.9791667 absoluteUsedCapacity=0.9791667 used=<memory:48128, vCores:42> cluster=<memory:49152, vCores:96>
2013-08-10 14:29:47,021 INFO org.apache.hadoop.yarn.server.resourcemanager.scheduler.capacity.ParentQueue: completedContainer queue=root usedCapacity=0.9791667 absoluteUsedCapacity=0.9791667 used=<memory:48128, vCores:42> cluster=<memory:49152, vCores:96>
2013-08-10 14:29:47,021 INFO org.apache.hadoop.yarn.server.resourcemanager.scheduler.capacity.CapacityScheduler: Application appattempt_1376143950665_0010_000001 released container container_1376143950665_0010_01_000020 on node: host: hadoop-221-6:51695 #containers=6 available=1024 used=7168 with event: FINISHED
2013-08-10 14:29:47,022 INFO org.apache.hadoop.yarn.server.resourcemanager.rmcontainer.RMContainerImpl: container_1376143950665_0006_01_000014 Container Transitioned from NEW to ALLOCATED
2013-08-10 14:29:47,022 INFO org.apache.hadoop.yarn.server.resourcemanager.RMAuditLogger: USER=ubuntu	OPERATION=AM Allocated Container	TARGET=SchedulerApp	RESULT=SUCCESS	APPID=application_1376143950665_0006	CONTAINERID=container_1376143950665_0006_01_000014
2013-08-10 14:29:47,022 INFO org.apache.hadoop.yarn.server.resourcemanager.scheduler.common.fica.FiCaSchedulerNode: Assigned container container_1376143950665_0006_01_000014 of capacity <memory:1024, vCores:1> on host hadoop-221-6:51695, which currently has 7 containers, <memory:8192, vCores:7> used and <memory:0, vCores:9> available
2013-08-10 14:29:47,023 INFO org.apache.hadoop.yarn.server.resourcemanager.scheduler.capacity.LeafQueue: assignedContainer application=application_1376143950665_0006 container=Container: [ContainerId: container_1376143950665_0006_01_000014, NodeId: hadoop-221-6:51695, NodeHttpAddress: hadoop-221-6:8042, Resource: <memory:1024, vCores:1>, Priority: 20, State: NEW, Token: null, Status: container_id {, app_attempt_id {, application_id {, id: 6, cluster_timestamp: 1376143950665, }, attemptId: 1, }, id: 14, }, state: C_NEW, ] containerId=container_1376143950665_0006_01_000014 queue=default: capacity=1.0, absoluteCapacity=1.0, usedResources=<memory:48128, vCores:42>usedCapacity=0.9791667, absoluteUsedCapacity=0.9791667, numApps=5, numContainers=42 usedCapacity=0.9791667 absoluteUsedCapacity=0.9791667 used=<memory:48128, vCores:42> cluster=<memory:49152, vCores:96>
2013-08-10 14:29:47,023 INFO org.apache.hadoop.yarn.server.resourcemanager.scheduler.capacity.ParentQueue: Re-sorting queues since queue: root.default stats: default: capacity=1.0, absoluteCapacity=1.0, usedResources=<memory:49152, vCores:43>usedCapacity=1.0, absoluteUsedCapacity=1.0, numApps=5, numContainers=43
2013-08-10 14:29:47,023 INFO org.apache.hadoop.yarn.server.resourcemanager.scheduler.capacity.ParentQueue: assignedContainer queue=root usedCapacity=1.0 absoluteUsedCapacity=1.0 used=<memory:49152, vCores:43> cluster=<memory:49152, vCores:96>
2013-08-10 14:29:47,630 INFO org.apache.hadoop.yarn.server.resourcemanager.rmcontainer.RMContainerImpl: container_1376143950665_0010_01_000021 Container Transitioned from RUNNING to COMPLETED
2013-08-10 14:29:47,631 INFO org.apache.hadoop.yarn.server.resourcemanager.scheduler.common.fica.FiCaSchedulerApp: Completed container: container_1376143950665_0010_01_000021 in state: COMPLETED event:FINISHED
2013-08-10 14:29:47,631 INFO org.apache.hadoop.yarn.server.resourcemanager.RMAuditLogger: USER=ubuntu	OPERATION=AM Released Container	TARGET=SchedulerApp	RESULT=SUCCESS	APPID=application_1376143950665_0010	CONTAINERID=container_1376143950665_0010_01_000021
2013-08-10 14:29:47,631 INFO org.apache.hadoop.yarn.server.resourcemanager.scheduler.common.fica.FiCaSchedulerNode: Released container container_1376143950665_0010_01_000021 of capacity <memory:1024, vCores:1> on host hadoop-221-6:51695, which currently has 6 containers, <memory:7168, vCores:6> used and <memory:1024, vCores:10> available, release resources=true
2013-08-10 14:29:47,631 INFO org.apache.hadoop.yarn.server.resourcemanager.scheduler.capacity.LeafQueue: default used=<memory:48128, vCores:42> numContainers=42 user=ubuntu user-resources=<memory:48128, vCores:42>
2013-08-10 14:29:47,632 INFO org.apache.hadoop.yarn.server.resourcemanager.scheduler.capacity.LeafQueue: completedContainer container=Container: [ContainerId: container_1376143950665_0010_01_000021, NodeId: hadoop-221-6:51695, NodeHttpAddress: hadoop-221-6:8042, Resource: <memory:1024, vCores:1>, Priority: 20, State: NEW, Token: null, Status: container_id {, app_attempt_id {, application_id {, id: 10, cluster_timestamp: 1376143950665, }, attemptId: 1, }, id: 21, }, state: C_COMPLETE, diagnostics: "Container killed by the ApplicationMaster.\n\n", exit_status: 143, ] resource=<memory:1024, vCores:1> queue=default: capacity=1.0, absoluteCapacity=1.0, usedResources=<memory:48128, vCores:42>usedCapacity=0.9791667, absoluteUsedCapacity=0.9791667, numApps=5, numContainers=42 usedCapacity=0.9791667 absoluteUsedCapacity=0.9791667 used=<memory:48128, vCores:42> cluster=<memory:49152, vCores:96>
2013-08-10 14:29:47,632 INFO org.apache.hadoop.yarn.server.resourcemanager.scheduler.capacity.ParentQueue: completedContainer queue=root usedCapacity=0.9791667 absoluteUsedCapacity=0.9791667 used=<memory:48128, vCores:42> cluster=<memory:49152, vCores:96>
2013-08-10 14:29:47,632 INFO org.apache.hadoop.yarn.server.resourcemanager.scheduler.capacity.CapacityScheduler: Application appattempt_1376143950665_0010_000001 released container container_1376143950665_0010_01_000021 on node: host: hadoop-221-6:51695 #containers=6 available=1024 used=7168 with event: FINISHED
2013-08-10 14:29:47,633 INFO org.apache.hadoop.yarn.server.resourcemanager.rmcontainer.RMContainerImpl: container_1376143950665_0006_01_000015 Container Transitioned from NEW to ALLOCATED
2013-08-10 14:29:47,633 INFO org.apache.hadoop.yarn.server.resourcemanager.RMAuditLogger: USER=ubuntu	OPERATION=AM Allocated Container	TARGET=SchedulerApp	RESULT=SUCCESS	APPID=application_1376143950665_0006	CONTAINERID=container_1376143950665_0006_01_000015
2013-08-10 14:29:47,633 INFO org.apache.hadoop.yarn.server.resourcemanager.scheduler.common.fica.FiCaSchedulerNode: Assigned container container_1376143950665_0006_01_000015 of capacity <memory:1024, vCores:1> on host hadoop-221-6:51695, which currently has 7 containers, <memory:8192, vCores:7> used and <memory:0, vCores:9> available
2013-08-10 14:29:47,634 INFO org.apache.hadoop.yarn.server.resourcemanager.scheduler.capacity.LeafQueue: assignedContainer application=application_1376143950665_0006 container=Container: [ContainerId: container_1376143950665_0006_01_000015, NodeId: hadoop-221-6:51695, NodeHttpAddress: hadoop-221-6:8042, Resource: <memory:1024, vCores:1>, Priority: 20, State: NEW, Token: null, Status: container_id {, app_attempt_id {, application_id {, id: 6, cluster_timestamp: 1376143950665, }, attemptId: 1, }, id: 15, }, state: C_NEW, ] containerId=container_1376143950665_0006_01_000015 queue=default: capacity=1.0, absoluteCapacity=1.0, usedResources=<memory:48128, vCores:42>usedCapacity=0.9791667, absoluteUsedCapacity=0.9791667, numApps=5, numContainers=42 usedCapacity=0.9791667 absoluteUsedCapacity=0.9791667 used=<memory:48128, vCores:42> cluster=<memory:49152, vCores:96>
2013-08-10 14:29:47,634 INFO org.apache.hadoop.yarn.server.resourcemanager.scheduler.capacity.ParentQueue: Re-sorting queues since queue: root.default stats: default: capacity=1.0, absoluteCapacity=1.0, usedResources=<memory:49152, vCores:43>usedCapacity=1.0, absoluteUsedCapacity=1.0, numApps=5, numContainers=43
2013-08-10 14:29:47,634 INFO org.apache.hadoop.yarn.server.resourcemanager.scheduler.capacity.ParentQueue: assignedContainer queue=root usedCapacity=1.0 absoluteUsedCapacity=1.0 used=<memory:49152, vCores:43> cluster=<memory:49152, vCores:96>
2013-08-10 14:29:47,924 INFO org.apache.hadoop.yarn.server.resourcemanager.rmcontainer.RMContainerImpl: container_1376143950665_0006_01_000013 Container Transitioned from ACQUIRED to RUNNING
2013-08-10 14:29:47,924 INFO org.apache.hadoop.yarn.server.resourcemanager.rmcontainer.RMContainerImpl: container_1376143950665_0010_01_000006 Container Transitioned from RUNNING to COMPLETED
2013-08-10 14:29:47,924 INFO org.apache.hadoop.yarn.server.resourcemanager.scheduler.common.fica.FiCaSchedulerApp: Completed container: container_1376143950665_0010_01_000006 in state: COMPLETED event:FINISHED
2013-08-10 14:29:47,925 INFO org.apache.hadoop.yarn.server.resourcemanager.RMAuditLogger: USER=ubuntu	OPERATION=AM Released Container	TARGET=SchedulerApp	RESULT=SUCCESS	APPID=application_1376143950665_0010	CONTAINERID=container_1376143950665_0010_01_000006
2013-08-10 14:29:47,925 INFO org.apache.hadoop.yarn.server.resourcemanager.scheduler.common.fica.FiCaSchedulerNode: Released container container_1376143950665_0010_01_000006 of capacity <memory:1024, vCores:1> on host hadoop-221-2:53277, which currently has 6 containers, <memory:7168, vCores:6> used and <memory:1024, vCores:10> available, release resources=true
2013-08-10 14:29:47,925 INFO org.apache.hadoop.yarn.server.resourcemanager.scheduler.capacity.LeafQueue: default used=<memory:48128, vCores:42> numContainers=42 user=ubuntu user-resources=<memory:48128, vCores:42>
2013-08-10 14:29:47,926 INFO org.apache.hadoop.yarn.server.resourcemanager.scheduler.capacity.LeafQueue: completedContainer container=Container: [ContainerId: container_1376143950665_0010_01_000006, NodeId: hadoop-221-2:53277, NodeHttpAddress: hadoop-221-2:8042, Resource: <memory:1024, vCores:1>, Priority: 20, State: NEW, Token: null, Status: container_id {, app_attempt_id {, application_id {, id: 10, cluster_timestamp: 1376143950665, }, attemptId: 1, }, id: 6, }, state: C_COMPLETE, diagnostics: "Container killed by the ApplicationMaster.\n\n", exit_status: 143, ] resource=<memory:1024, vCores:1> queue=default: capacity=1.0, absoluteCapacity=1.0, usedResources=<memory:48128, vCores:42>usedCapacity=0.9791667, absoluteUsedCapacity=0.9791667, numApps=5, numContainers=42 usedCapacity=0.9791667 absoluteUsedCapacity=0.9791667 used=<memory:48128, vCores:42> cluster=<memory:49152, vCores:96>
2013-08-10 14:29:47,926 INFO org.apache.hadoop.yarn.server.resourcemanager.scheduler.capacity.ParentQueue: completedContainer queue=root usedCapacity=0.9791667 absoluteUsedCapacity=0.9791667 used=<memory:48128, vCores:42> cluster=<memory:49152, vCores:96>
2013-08-10 14:29:47,926 INFO org.apache.hadoop.yarn.server.resourcemanager.scheduler.capacity.CapacityScheduler: Application appattempt_1376143950665_0010_000001 released container container_1376143950665_0010_01_000006 on node: host: hadoop-221-2:53277 #containers=6 available=1024 used=7168 with event: FINISHED
2013-08-10 14:29:47,927 INFO org.apache.hadoop.yarn.server.resourcemanager.rmcontainer.RMContainerImpl: container_1376143950665_0006_01_000016 Container Transitioned from NEW to ALLOCATED
2013-08-10 14:29:47,927 INFO org.apache.hadoop.yarn.server.resourcemanager.RMAuditLogger: USER=ubuntu	OPERATION=AM Allocated Container	TARGET=SchedulerApp	RESULT=SUCCESS	APPID=application_1376143950665_0006	CONTAINERID=container_1376143950665_0006_01_000016
2013-08-10 14:29:47,927 INFO org.apache.hadoop.yarn.server.resourcemanager.scheduler.common.fica.FiCaSchedulerNode: Assigned container container_1376143950665_0006_01_000016 of capacity <memory:1024, vCores:1> on host hadoop-221-2:53277, which currently has 7 containers, <memory:8192, vCores:7> used and <memory:0, vCores:9> available
2013-08-10 14:29:47,928 INFO org.apache.hadoop.yarn.server.resourcemanager.scheduler.capacity.LeafQueue: assignedContainer application=application_1376143950665_0006 container=Container: [ContainerId: container_1376143950665_0006_01_000016, NodeId: hadoop-221-2:53277, NodeHttpAddress: hadoop-221-2:8042, Resource: <memory:1024, vCores:1>, Priority: 20, State: NEW, Token: null, Status: container_id {, app_attempt_id {, application_id {, id: 6, cluster_timestamp: 1376143950665, }, attemptId: 1, }, id: 16, }, state: C_NEW, ] containerId=container_1376143950665_0006_01_000016 queue=default: capacity=1.0, absoluteCapacity=1.0, usedResources=<memory:48128, vCores:42>usedCapacity=0.9791667, absoluteUsedCapacity=0.9791667, numApps=5, numContainers=42 usedCapacity=0.9791667 absoluteUsedCapacity=0.9791667 used=<memory:48128, vCores:42> cluster=<memory:49152, vCores:96>
2013-08-10 14:29:47,928 INFO org.apache.hadoop.yarn.server.resourcemanager.scheduler.capacity.ParentQueue: Re-sorting queues since queue: root.default stats: default: capacity=1.0, absoluteCapacity=1.0, usedResources=<memory:49152, vCores:43>usedCapacity=1.0, absoluteUsedCapacity=1.0, numApps=5, numContainers=43
2013-08-10 14:29:47,928 INFO org.apache.hadoop.yarn.server.resourcemanager.scheduler.capacity.ParentQueue: assignedContainer queue=root usedCapacity=1.0 absoluteUsedCapacity=1.0 used=<memory:49152, vCores:43> cluster=<memory:49152, vCores:96>
2013-08-10 14:29:47,962 INFO org.apache.hadoop.yarn.server.resourcemanager.rmcontainer.RMContainerImpl: container_1376143950665_0006_01_000014 Container Transitioned from ALLOCATED to ACQUIRED
2013-08-10 14:29:47,964 INFO org.apache.hadoop.yarn.server.resourcemanager.rmcontainer.RMContainerImpl: container_1376143950665_0006_01_000015 Container Transitioned from ALLOCATED to ACQUIRED
2013-08-10 14:29:47,964 INFO org.apache.hadoop.yarn.server.resourcemanager.rmcontainer.RMContainerImpl: container_1376143950665_0006_01_000016 Container Transitioned from ALLOCATED to ACQUIRED
2013-08-10 14:29:48,641 INFO org.apache.hadoop.yarn.server.resourcemanager.rmcontainer.RMContainerImpl: container_1376143950665_0006_01_000014 Container Transitioned from ACQUIRED to RUNNING
2013-08-10 14:29:48,642 INFO org.apache.hadoop.yarn.server.resourcemanager.rmcontainer.RMContainerImpl: container_1376143950665_0006_01_000015 Container Transitioned from ACQUIRED to RUNNING
2013-08-10 14:29:48,642 INFO org.apache.hadoop.yarn.server.resourcemanager.rmcontainer.RMContainerImpl: container_1376143950665_0010_01_000022 Container Transitioned from RUNNING to COMPLETED
2013-08-10 14:29:48,642 INFO org.apache.hadoop.yarn.server.resourcemanager.scheduler.common.fica.FiCaSchedulerApp: Completed container: container_1376143950665_0010_01_000022 in state: COMPLETED event:FINISHED
2013-08-10 14:29:48,642 INFO org.apache.hadoop.yarn.server.resourcemanager.RMAuditLogger: USER=ubuntu	OPERATION=AM Released Container	TARGET=SchedulerApp	RESULT=SUCCESS	APPID=application_1376143950665_0010	CONTAINERID=container_1376143950665_0010_01_000022
2013-08-10 14:29:48,642 INFO org.apache.hadoop.yarn.server.resourcemanager.scheduler.common.fica.FiCaSchedulerNode: Released container container_1376143950665_0010_01_000022 of capacity <memory:1024, vCores:1> on host hadoop-221-6:51695, which currently has 6 containers, <memory:7168, vCores:6> used and <memory:1024, vCores:10> available, release resources=true
2013-08-10 14:29:48,642 INFO org.apache.hadoop.yarn.server.resourcemanager.scheduler.capacity.LeafQueue: default used=<memory:48128, vCores:42> numContainers=42 user=ubuntu user-resources=<memory:48128, vCores:42>
2013-08-10 14:29:48,644 INFO org.apache.hadoop.yarn.server.resourcemanager.scheduler.capacity.LeafQueue: completedContainer container=Container: [ContainerId: container_1376143950665_0010_01_000022, NodeId: hadoop-221-6:51695, NodeHttpAddress: hadoop-221-6:8042, Resource: <memory:1024, vCores:1>, Priority: 20, State: NEW, Token: null, Status: container_id {, app_attempt_id {, application_id {, id: 10, cluster_timestamp: 1376143950665, }, attemptId: 1, }, id: 22, }, state: C_COMPLETE, diagnostics: "Container killed by the ApplicationMaster.\n\n", exit_status: 143, ] resource=<memory:1024, vCores:1> queue=default: capacity=1.0, absoluteCapacity=1.0, usedResources=<memory:48128, vCores:42>usedCapacity=0.9791667, absoluteUsedCapacity=0.9791667, numApps=5, numContainers=42 usedCapacity=0.9791667 absoluteUsedCapacity=0.9791667 used=<memory:48128, vCores:42> cluster=<memory:49152, vCores:96>
2013-08-10 14:29:48,644 INFO org.apache.hadoop.yarn.server.resourcemanager.scheduler.capacity.ParentQueue: completedContainer queue=root usedCapacity=0.9791667 absoluteUsedCapacity=0.9791667 used=<memory:48128, vCores:42> cluster=<memory:49152, vCores:96>
2013-08-10 14:29:48,644 INFO org.apache.hadoop.yarn.server.resourcemanager.scheduler.capacity.CapacityScheduler: Application appattempt_1376143950665_0010_000001 released container container_1376143950665_0010_01_000022 on node: host: hadoop-221-6:51695 #containers=6 available=1024 used=7168 with event: FINISHED
2013-08-10 14:29:48,644 INFO org.apache.hadoop.yarn.server.resourcemanager.rmcontainer.RMContainerImpl: container_1376143950665_0006_01_000017 Container Transitioned from NEW to ALLOCATED
2013-08-10 14:29:48,644 INFO org.apache.hadoop.yarn.server.resourcemanager.RMAuditLogger: USER=ubuntu	OPERATION=AM Allocated Container	TARGET=SchedulerApp	RESULT=SUCCESS	APPID=application_1376143950665_0006	CONTAINERID=container_1376143950665_0006_01_000017
2013-08-10 14:29:48,645 INFO org.apache.hadoop.yarn.server.resourcemanager.scheduler.common.fica.FiCaSchedulerNode: Assigned container container_1376143950665_0006_01_000017 of capacity <memory:1024, vCores:1> on host hadoop-221-6:51695, which currently has 7 containers, <memory:8192, vCores:7> used and <memory:0, vCores:9> available
2013-08-10 14:29:48,645 INFO org.apache.hadoop.yarn.server.resourcemanager.scheduler.capacity.LeafQueue: assignedContainer application=application_1376143950665_0006 container=Container: [ContainerId: container_1376143950665_0006_01_000017, NodeId: hadoop-221-6:51695, NodeHttpAddress: hadoop-221-6:8042, Resource: <memory:1024, vCores:1>, Priority: 20, State: NEW, Token: null, Status: container_id {, app_attempt_id {, application_id {, id: 6, cluster_timestamp: 1376143950665, }, attemptId: 1, }, id: 17, }, state: C_NEW, ] containerId=container_1376143950665_0006_01_000017 queue=default: capacity=1.0, absoluteCapacity=1.0, usedResources=<memory:48128, vCores:42>usedCapacity=0.9791667, absoluteUsedCapacity=0.9791667, numApps=5, numContainers=42 usedCapacity=0.9791667 absoluteUsedCapacity=0.9791667 used=<memory:48128, vCores:42> cluster=<memory:49152, vCores:96>
2013-08-10 14:29:48,646 INFO org.apache.hadoop.yarn.server.resourcemanager.scheduler.capacity.ParentQueue: Re-sorting queues since queue: root.default stats: default: capacity=1.0, absoluteCapacity=1.0, usedResources=<memory:49152, vCores:43>usedCapacity=1.0, absoluteUsedCapacity=1.0, numApps=5, numContainers=43
2013-08-10 14:29:48,646 INFO org.apache.hadoop.yarn.server.resourcemanager.scheduler.capacity.ParentQueue: assignedContainer queue=root usedCapacity=1.0 absoluteUsedCapacity=1.0 used=<memory:49152, vCores:43> cluster=<memory:49152, vCores:96>
2013-08-10 14:29:48,931 INFO org.apache.hadoop.yarn.server.resourcemanager.rmcontainer.RMContainerImpl: container_1376143950665_0006_01_000016 Container Transitioned from ACQUIRED to RUNNING
2013-08-10 14:29:48,975 INFO org.apache.hadoop.yarn.server.resourcemanager.rmcontainer.RMContainerImpl: container_1376143950665_0006_01_000017 Container Transitioned from ALLOCATED to ACQUIRED
2013-08-10 14:29:49,662 INFO org.apache.hadoop.yarn.server.resourcemanager.rmcontainer.RMContainerImpl: container_1376143950665_0006_01_000017 Container Transitioned from ACQUIRED to RUNNING
2013-08-10 14:29:50,391 INFO org.apache.hadoop.yarn.server.resourcemanager.rmcontainer.RMContainerImpl: container_1376143950665_0010_01_000034 Container Transitioned from RUNNING to COMPLETED
2013-08-10 14:29:50,392 INFO org.apache.hadoop.yarn.server.resourcemanager.scheduler.common.fica.FiCaSchedulerApp: Completed container: container_1376143950665_0010_01_000034 in state: COMPLETED event:FINISHED
2013-08-10 14:29:50,392 INFO org.apache.hadoop.yarn.server.resourcemanager.RMAuditLogger: USER=ubuntu	OPERATION=AM Released Container	TARGET=SchedulerApp	RESULT=SUCCESS	APPID=application_1376143950665_0010	CONTAINERID=container_1376143950665_0010_01_000034
2013-08-10 14:29:50,392 INFO org.apache.hadoop.yarn.server.resourcemanager.scheduler.common.fica.FiCaSchedulerNode: Released container container_1376143950665_0010_01_000034 of capacity <memory:1024, vCores:1> on host hadoop-221-7:43558, which currently has 6 containers, <memory:7168, vCores:6> used and <memory:1024, vCores:10> available, release resources=true
2013-08-10 14:29:50,392 INFO org.apache.hadoop.yarn.server.resourcemanager.scheduler.capacity.LeafQueue: default used=<memory:48128, vCores:42> numContainers=42 user=ubuntu user-resources=<memory:48128, vCores:42>
2013-08-10 14:29:50,393 INFO org.apache.hadoop.yarn.server.resourcemanager.scheduler.capacity.LeafQueue: completedContainer container=Container: [ContainerId: container_1376143950665_0010_01_000034, NodeId: hadoop-221-7:43558, NodeHttpAddress: hadoop-221-7:8042, Resource: <memory:1024, vCores:1>, Priority: 20, State: NEW, Token: null, Status: container_id {, app_attempt_id {, application_id {, id: 10, cluster_timestamp: 1376143950665, }, attemptId: 1, }, id: 34, }, state: C_COMPLETE, diagnostics: "Container killed by the ApplicationMaster.\n\n", exit_status: 143, ] resource=<memory:1024, vCores:1> queue=default: capacity=1.0, absoluteCapacity=1.0, usedResources=<memory:48128, vCores:42>usedCapacity=0.9791667, absoluteUsedCapacity=0.9791667, numApps=5, numContainers=42 usedCapacity=0.9791667 absoluteUsedCapacity=0.9791667 used=<memory:48128, vCores:42> cluster=<memory:49152, vCores:96>
2013-08-10 14:29:50,393 INFO org.apache.hadoop.yarn.server.resourcemanager.scheduler.capacity.ParentQueue: completedContainer queue=root usedCapacity=0.9791667 absoluteUsedCapacity=0.9791667 used=<memory:48128, vCores:42> cluster=<memory:49152, vCores:96>
2013-08-10 14:29:50,393 INFO org.apache.hadoop.yarn.server.resourcemanager.scheduler.capacity.CapacityScheduler: Application appattempt_1376143950665_0010_000001 released container container_1376143950665_0010_01_000034 on node: host: hadoop-221-7:43558 #containers=6 available=1024 used=7168 with event: FINISHED
2013-08-10 14:29:50,394 INFO org.apache.hadoop.yarn.server.resourcemanager.rmcontainer.RMContainerImpl: container_1376143950665_0006_01_000018 Container Transitioned from NEW to ALLOCATED
2013-08-10 14:29:50,394 INFO org.apache.hadoop.yarn.server.resourcemanager.RMAuditLogger: USER=ubuntu	OPERATION=AM Allocated Container	TARGET=SchedulerApp	RESULT=SUCCESS	APPID=application_1376143950665_0006	CONTAINERID=container_1376143950665_0006_01_000018
2013-08-10 14:29:50,394 INFO org.apache.hadoop.yarn.server.resourcemanager.scheduler.common.fica.FiCaSchedulerNode: Assigned container container_1376143950665_0006_01_000018 of capacity <memory:1024, vCores:1> on host hadoop-221-7:43558, which currently has 7 containers, <memory:8192, vCores:7> used and <memory:0, vCores:9> available
2013-08-10 14:29:50,395 INFO org.apache.hadoop.yarn.server.resourcemanager.scheduler.capacity.LeafQueue: assignedContainer application=application_1376143950665_0006 container=Container: [ContainerId: container_1376143950665_0006_01_000018, NodeId: hadoop-221-7:43558, NodeHttpAddress: hadoop-221-7:8042, Resource: <memory:1024, vCores:1>, Priority: 20, State: NEW, Token: null, Status: container_id {, app_attempt_id {, application_id {, id: 6, cluster_timestamp: 1376143950665, }, attemptId: 1, }, id: 18, }, state: C_NEW, ] containerId=container_1376143950665_0006_01_000018 queue=default: capacity=1.0, absoluteCapacity=1.0, usedResources=<memory:48128, vCores:42>usedCapacity=0.9791667, absoluteUsedCapacity=0.9791667, numApps=5, numContainers=42 usedCapacity=0.9791667 absoluteUsedCapacity=0.9791667 used=<memory:48128, vCores:42> cluster=<memory:49152, vCores:96>
2013-08-10 14:29:50,395 INFO org.apache.hadoop.yarn.server.resourcemanager.scheduler.capacity.ParentQueue: Re-sorting queues since queue: root.default stats: default: capacity=1.0, absoluteCapacity=1.0, usedResources=<memory:49152, vCores:43>usedCapacity=1.0, absoluteUsedCapacity=1.0, numApps=5, numContainers=43
2013-08-10 14:29:50,395 INFO org.apache.hadoop.yarn.server.resourcemanager.scheduler.capacity.ParentQueue: assignedContainer queue=root usedCapacity=1.0 absoluteUsedCapacity=1.0 used=<memory:49152, vCores:43> cluster=<memory:49152, vCores:96>
2013-08-10 14:29:50,996 INFO org.apache.hadoop.yarn.server.resourcemanager.rmcontainer.RMContainerImpl: container_1376143950665_0006_01_000018 Container Transitioned from ALLOCATED to ACQUIRED
2013-08-10 14:29:51,411 INFO org.apache.hadoop.yarn.server.resourcemanager.rmcontainer.RMContainerImpl: container_1376143950665_0006_01_000018 Container Transitioned from ACQUIRED to RUNNING
2013-08-10 14:29:55,022 INFO org.apache.hadoop.yarn.server.resourcemanager.rmcontainer.RMContainerImpl: container_1376143950665_0010_01_000019 Container Transitioned from RUNNING to COMPLETED
2013-08-10 14:29:55,022 INFO org.apache.hadoop.yarn.server.resourcemanager.scheduler.common.fica.FiCaSchedulerApp: Completed container: container_1376143950665_0010_01_000019 in state: COMPLETED event:FINISHED
2013-08-10 14:29:55,022 INFO org.apache.hadoop.yarn.server.resourcemanager.RMAuditLogger: USER=ubuntu	OPERATION=AM Released Container	TARGET=SchedulerApp	RESULT=SUCCESS	APPID=application_1376143950665_0010	CONTAINERID=container_1376143950665_0010_01_000019
2013-08-10 14:29:55,022 INFO org.apache.hadoop.yarn.server.resourcemanager.scheduler.common.fica.FiCaSchedulerNode: Released container container_1376143950665_0010_01_000019 of capacity <memory:1024, vCores:1> on host hadoop-221-5:53998, which currently has 6 containers, <memory:7168, vCores:6> used and <memory:1024, vCores:10> available, release resources=true
2013-08-10 14:29:55,023 INFO org.apache.hadoop.yarn.server.resourcemanager.scheduler.capacity.LeafQueue: default used=<memory:48128, vCores:42> numContainers=42 user=ubuntu user-resources=<memory:48128, vCores:42>
2013-08-10 14:29:55,024 INFO org.apache.hadoop.yarn.server.resourcemanager.scheduler.capacity.LeafQueue: completedContainer container=Container: [ContainerId: container_1376143950665_0010_01_000019, NodeId: hadoop-221-5:53998, NodeHttpAddress: hadoop-221-5:8042, Resource: <memory:1024, vCores:1>, Priority: 20, State: NEW, Token: null, Status: container_id {, app_attempt_id {, application_id {, id: 10, cluster_timestamp: 1376143950665, }, attemptId: 1, }, id: 19, }, state: C_COMPLETE, diagnostics: "Container killed by the ApplicationMaster.\n\n", exit_status: 143, ] resource=<memory:1024, vCores:1> queue=default: capacity=1.0, absoluteCapacity=1.0, usedResources=<memory:48128, vCores:42>usedCapacity=0.9791667, absoluteUsedCapacity=0.9791667, numApps=5, numContainers=42 usedCapacity=0.9791667 absoluteUsedCapacity=0.9791667 used=<memory:48128, vCores:42> cluster=<memory:49152, vCores:96>
2013-08-10 14:29:55,024 INFO org.apache.hadoop.yarn.server.resourcemanager.scheduler.capacity.ParentQueue: completedContainer queue=root usedCapacity=0.9791667 absoluteUsedCapacity=0.9791667 used=<memory:48128, vCores:42> cluster=<memory:49152, vCores:96>
2013-08-10 14:29:55,024 INFO org.apache.hadoop.yarn.server.resourcemanager.scheduler.capacity.CapacityScheduler: Application appattempt_1376143950665_0010_000001 released container container_1376143950665_0010_01_000019 on node: host: hadoop-221-5:53998 #containers=6 available=1024 used=7168 with event: FINISHED
2013-08-10 14:29:55,024 INFO org.apache.hadoop.yarn.server.resourcemanager.rmcontainer.RMContainerImpl: container_1376143950665_0006_01_000019 Container Transitioned from NEW to ALLOCATED
2013-08-10 14:29:55,025 INFO org.apache.hadoop.yarn.server.resourcemanager.RMAuditLogger: USER=ubuntu	OPERATION=AM Allocated Container	TARGET=SchedulerApp	RESULT=SUCCESS	APPID=application_1376143950665_0006	CONTAINERID=container_1376143950665_0006_01_000019
2013-08-10 14:29:55,025 INFO org.apache.hadoop.yarn.server.resourcemanager.scheduler.common.fica.FiCaSchedulerNode: Assigned container container_1376143950665_0006_01_000019 of capacity <memory:1024, vCores:1> on host hadoop-221-5:53998, which currently has 7 containers, <memory:8192, vCores:7> used and <memory:0, vCores:9> available
2013-08-10 14:29:55,026 INFO org.apache.hadoop.yarn.server.resourcemanager.scheduler.capacity.LeafQueue: assignedContainer application=application_1376143950665_0006 container=Container: [ContainerId: container_1376143950665_0006_01_000019, NodeId: hadoop-221-5:53998, NodeHttpAddress: hadoop-221-5:8042, Resource: <memory:1024, vCores:1>, Priority: 20, State: NEW, Token: null, Status: container_id {, app_attempt_id {, application_id {, id: 6, cluster_timestamp: 1376143950665, }, attemptId: 1, }, id: 19, }, state: C_NEW, ] containerId=container_1376143950665_0006_01_000019 queue=default: capacity=1.0, absoluteCapacity=1.0, usedResources=<memory:48128, vCores:42>usedCapacity=0.9791667, absoluteUsedCapacity=0.9791667, numApps=5, numContainers=42 usedCapacity=0.9791667 absoluteUsedCapacity=0.9791667 used=<memory:48128, vCores:42> cluster=<memory:49152, vCores:96>
2013-08-10 14:29:55,026 INFO org.apache.hadoop.yarn.server.resourcemanager.scheduler.capacity.ParentQueue: Re-sorting queues since queue: root.default stats: default: capacity=1.0, absoluteCapacity=1.0, usedResources=<memory:49152, vCores:43>usedCapacity=1.0, absoluteUsedCapacity=1.0, numApps=5, numContainers=43
2013-08-10 14:29:55,026 INFO org.apache.hadoop.yarn.server.resourcemanager.scheduler.capacity.ParentQueue: assignedContainer queue=root usedCapacity=1.0 absoluteUsedCapacity=1.0 used=<memory:49152, vCores:43> cluster=<memory:49152, vCores:96>
2013-08-10 14:29:55,422 INFO org.apache.hadoop.yarn.server.resourcemanager.rmcontainer.RMContainerImpl: container_1376143950665_0006_01_000002 Container Transitioned from RUNNING to COMPLETED
2013-08-10 14:29:55,422 INFO org.apache.hadoop.yarn.server.resourcemanager.scheduler.common.fica.FiCaSchedulerApp: Completed container: container_1376143950665_0006_01_000002 in state: COMPLETED event:FINISHED
2013-08-10 14:29:55,422 INFO org.apache.hadoop.yarn.server.resourcemanager.RMAuditLogger: USER=ubuntu	OPERATION=AM Released Container	TARGET=SchedulerApp	RESULT=SUCCESS	APPID=application_1376143950665_0006	CONTAINERID=container_1376143950665_0006_01_000002
2013-08-10 14:29:55,422 INFO org.apache.hadoop.yarn.server.resourcemanager.scheduler.common.fica.FiCaSchedulerNode: Released container container_1376143950665_0006_01_000002 of capacity <memory:1024, vCores:1> on host hadoop-221-4:43548, which currently has 6 containers, <memory:7168, vCores:6> used and <memory:1024, vCores:10> available, release resources=true
2013-08-10 14:29:55,422 INFO org.apache.hadoop.yarn.server.resourcemanager.scheduler.capacity.LeafQueue: default used=<memory:48128, vCores:42> numContainers=42 user=ubuntu user-resources=<memory:48128, vCores:42>
2013-08-10 14:29:55,424 INFO org.apache.hadoop.yarn.server.resourcemanager.scheduler.capacity.LeafQueue: completedContainer container=Container: [ContainerId: container_1376143950665_0006_01_000002, NodeId: hadoop-221-4:43548, NodeHttpAddress: hadoop-221-4:8042, Resource: <memory:1024, vCores:1>, Priority: 20, State: NEW, Token: null, Status: container_id {, app_attempt_id {, application_id {, id: 6, cluster_timestamp: 1376143950665, }, attemptId: 1, }, id: 2, }, state: C_COMPLETE, diagnostics: "Container killed by the ApplicationMaster.\n\n", exit_status: 143, ] resource=<memory:1024, vCores:1> queue=default: capacity=1.0, absoluteCapacity=1.0, usedResources=<memory:48128, vCores:42>usedCapacity=0.9791667, absoluteUsedCapacity=0.9791667, numApps=5, numContainers=42 usedCapacity=0.9791667 absoluteUsedCapacity=0.9791667 used=<memory:48128, vCores:42> cluster=<memory:49152, vCores:96>
2013-08-10 14:29:55,424 INFO org.apache.hadoop.yarn.server.resourcemanager.scheduler.capacity.ParentQueue: completedContainer queue=root usedCapacity=0.9791667 absoluteUsedCapacity=0.9791667 used=<memory:48128, vCores:42> cluster=<memory:49152, vCores:96>
2013-08-10 14:29:55,424 INFO org.apache.hadoop.yarn.server.resourcemanager.scheduler.capacity.CapacityScheduler: Application appattempt_1376143950665_0006_000001 released container container_1376143950665_0006_01_000002 on node: host: hadoop-221-4:43548 #containers=6 available=1024 used=7168 with event: FINISHED
2013-08-10 14:29:55,424 INFO org.apache.hadoop.yarn.server.resourcemanager.rmcontainer.RMContainerImpl: container_1376143950665_0006_01_000020 Container Transitioned from NEW to ALLOCATED
2013-08-10 14:29:55,425 INFO org.apache.hadoop.yarn.server.resourcemanager.RMAuditLogger: USER=ubuntu	OPERATION=AM Allocated Container	TARGET=SchedulerApp	RESULT=SUCCESS	APPID=application_1376143950665_0006	CONTAINERID=container_1376143950665_0006_01_000020
2013-08-10 14:29:55,425 INFO org.apache.hadoop.yarn.server.resourcemanager.scheduler.common.fica.FiCaSchedulerNode: Assigned container container_1376143950665_0006_01_000020 of capacity <memory:1024, vCores:1> on host hadoop-221-4:43548, which currently has 7 containers, <memory:8192, vCores:7> used and <memory:0, vCores:9> available
2013-08-10 14:29:55,429 INFO org.apache.hadoop.yarn.server.resourcemanager.scheduler.capacity.LeafQueue: assignedContainer application=application_1376143950665_0006 container=Container: [ContainerId: container_1376143950665_0006_01_000020, NodeId: hadoop-221-4:43548, NodeHttpAddress: hadoop-221-4:8042, Resource: <memory:1024, vCores:1>, Priority: 20, State: NEW, Token: null, Status: container_id {, app_attempt_id {, application_id {, id: 6, cluster_timestamp: 1376143950665, }, attemptId: 1, }, id: 20, }, state: C_NEW, ] containerId=container_1376143950665_0006_01_000020 queue=default: capacity=1.0, absoluteCapacity=1.0, usedResources=<memory:48128, vCores:42>usedCapacity=0.9791667, absoluteUsedCapacity=0.9791667, numApps=5, numContainers=42 usedCapacity=0.9791667 absoluteUsedCapacity=0.9791667 used=<memory:48128, vCores:42> cluster=<memory:49152, vCores:96>
2013-08-10 14:29:55,429 INFO org.apache.hadoop.yarn.server.resourcemanager.scheduler.capacity.ParentQueue: Re-sorting queues since queue: root.default stats: default: capacity=1.0, absoluteCapacity=1.0, usedResources=<memory:49152, vCores:43>usedCapacity=1.0, absoluteUsedCapacity=1.0, numApps=5, numContainers=43
2013-08-10 14:29:55,429 INFO org.apache.hadoop.yarn.server.resourcemanager.scheduler.capacity.ParentQueue: assignedContainer queue=root usedCapacity=1.0 absoluteUsedCapacity=1.0 used=<memory:49152, vCores:43> cluster=<memory:49152, vCores:96>
2013-08-10 14:29:55,524 INFO org.apache.hadoop.yarn.server.resourcemanager.rmcontainer.RMContainerImpl: container_1376143950665_0006_01_000019 Container Transitioned from ALLOCATED to ACQUIRED
2013-08-10 14:29:55,525 INFO org.apache.hadoop.yarn.server.resourcemanager.rmcontainer.RMContainerImpl: container_1376143950665_0006_01_000020 Container Transitioned from ALLOCATED to ACQUIRED
2013-08-10 14:29:56,028 INFO org.apache.hadoop.yarn.server.resourcemanager.rmcontainer.RMContainerImpl: container_1376143950665_0006_01_000019 Container Transitioned from ACQUIRED to RUNNING
2013-08-10 14:29:56,433 INFO org.apache.hadoop.yarn.server.resourcemanager.rmcontainer.RMContainerImpl: container_1376143950665_0006_01_000020 Container Transitioned from ACQUIRED to RUNNING
2013-08-10 14:29:58,177 INFO org.apache.hadoop.yarn.server.resourcemanager.rmcontainer.RMContainerImpl: container_1376143950665_0006_01_000003 Container Transitioned from RUNNING to COMPLETED
2013-08-10 14:29:58,177 INFO org.apache.hadoop.yarn.server.resourcemanager.scheduler.common.fica.FiCaSchedulerApp: Completed container: container_1376143950665_0006_01_000003 in state: COMPLETED event:FINISHED
2013-08-10 14:29:58,178 INFO org.apache.hadoop.yarn.server.resourcemanager.RMAuditLogger: USER=ubuntu	OPERATION=AM Released Container	TARGET=SchedulerApp	RESULT=SUCCESS	APPID=application_1376143950665_0006	CONTAINERID=container_1376143950665_0006_01_000003
2013-08-10 14:29:58,178 INFO org.apache.hadoop.yarn.server.resourcemanager.scheduler.common.fica.FiCaSchedulerNode: Released container container_1376143950665_0006_01_000003 of capacity <memory:1024, vCores:1> on host hadoop-221-7:43558, which currently has 6 containers, <memory:7168, vCores:6> used and <memory:1024, vCores:10> available, release resources=true
2013-08-10 14:29:58,178 INFO org.apache.hadoop.yarn.server.resourcemanager.scheduler.capacity.LeafQueue: default used=<memory:48128, vCores:42> numContainers=42 user=ubuntu user-resources=<memory:48128, vCores:42>
2013-08-10 14:29:58,179 INFO org.apache.hadoop.yarn.server.resourcemanager.scheduler.capacity.LeafQueue: completedContainer container=Container: [ContainerId: container_1376143950665_0006_01_000003, NodeId: hadoop-221-7:43558, NodeHttpAddress: hadoop-221-7:8042, Resource: <memory:1024, vCores:1>, Priority: 20, State: NEW, Token: null, Status: container_id {, app_attempt_id {, application_id {, id: 6, cluster_timestamp: 1376143950665, }, attemptId: 1, }, id: 3, }, state: C_COMPLETE, diagnostics: "Container killed by the ApplicationMaster.\n\n", exit_status: 143, ] resource=<memory:1024, vCores:1> queue=default: capacity=1.0, absoluteCapacity=1.0, usedResources=<memory:48128, vCores:42>usedCapacity=0.9791667, absoluteUsedCapacity=0.9791667, numApps=5, numContainers=42 usedCapacity=0.9791667 absoluteUsedCapacity=0.9791667 used=<memory:48128, vCores:42> cluster=<memory:49152, vCores:96>
2013-08-10 14:29:58,179 INFO org.apache.hadoop.yarn.server.resourcemanager.scheduler.capacity.ParentQueue: completedContainer queue=root usedCapacity=0.9791667 absoluteUsedCapacity=0.9791667 used=<memory:48128, vCores:42> cluster=<memory:49152, vCores:96>
2013-08-10 14:29:58,179 INFO org.apache.hadoop.yarn.server.resourcemanager.scheduler.capacity.CapacityScheduler: Application appattempt_1376143950665_0006_000001 released container container_1376143950665_0006_01_000003 on node: host: hadoop-221-7:43558 #containers=6 available=1024 used=7168 with event: FINISHED
2013-08-10 14:29:58,180 INFO org.apache.hadoop.yarn.server.resourcemanager.rmcontainer.RMContainerImpl: container_1376143950665_0006_01_000021 Container Transitioned from NEW to ALLOCATED
2013-08-10 14:29:58,180 INFO org.apache.hadoop.yarn.server.resourcemanager.RMAuditLogger: USER=ubuntu	OPERATION=AM Allocated Container	TARGET=SchedulerApp	RESULT=SUCCESS	APPID=application_1376143950665_0006	CONTAINERID=container_1376143950665_0006_01_000021
2013-08-10 14:29:58,180 INFO org.apache.hadoop.yarn.server.resourcemanager.scheduler.common.fica.FiCaSchedulerNode: Assigned container container_1376143950665_0006_01_000021 of capacity <memory:1024, vCores:1> on host hadoop-221-7:43558, which currently has 7 containers, <memory:8192, vCores:7> used and <memory:0, vCores:9> available
2013-08-10 14:29:58,181 INFO org.apache.hadoop.yarn.server.resourcemanager.scheduler.capacity.LeafQueue: assignedContainer application=application_1376143950665_0006 container=Container: [ContainerId: container_1376143950665_0006_01_000021, NodeId: hadoop-221-7:43558, NodeHttpAddress: hadoop-221-7:8042, Resource: <memory:1024, vCores:1>, Priority: 20, State: NEW, Token: null, Status: container_id {, app_attempt_id {, application_id {, id: 6, cluster_timestamp: 1376143950665, }, attemptId: 1, }, id: 21, }, state: C_NEW, ] containerId=container_1376143950665_0006_01_000021 queue=default: capacity=1.0, absoluteCapacity=1.0, usedResources=<memory:48128, vCores:42>usedCapacity=0.9791667, absoluteUsedCapacity=0.9791667, numApps=5, numContainers=42 usedCapacity=0.9791667 absoluteUsedCapacity=0.9791667 used=<memory:48128, vCores:42> cluster=<memory:49152, vCores:96>
2013-08-10 14:29:58,181 INFO org.apache.hadoop.yarn.server.resourcemanager.scheduler.capacity.ParentQueue: Re-sorting queues since queue: root.default stats: default: capacity=1.0, absoluteCapacity=1.0, usedResources=<memory:49152, vCores:43>usedCapacity=1.0, absoluteUsedCapacity=1.0, numApps=5, numContainers=43
2013-08-10 14:29:58,181 INFO org.apache.hadoop.yarn.server.resourcemanager.scheduler.capacity.ParentQueue: assignedContainer queue=root usedCapacity=1.0 absoluteUsedCapacity=1.0 used=<memory:49152, vCores:43> cluster=<memory:49152, vCores:96>
2013-08-10 14:29:58,827 INFO org.apache.hadoop.yarn.server.resourcemanager.rmcontainer.RMContainerImpl: container_1376143950665_0006_01_000021 Container Transitioned from ALLOCATED to ACQUIRED
2013-08-10 14:29:59,194 INFO org.apache.hadoop.yarn.server.resourcemanager.rmcontainer.RMContainerImpl: container_1376143950665_0006_01_000021 Container Transitioned from ACQUIRED to RUNNING
2013-08-10 14:29:59,231 INFO org.apache.hadoop.yarn.server.resourcemanager.rmcontainer.RMContainerImpl: container_1376143950665_0010_01_000028 Container Transitioned from RUNNING to COMPLETED
2013-08-10 14:29:59,231 INFO org.apache.hadoop.yarn.server.resourcemanager.scheduler.common.fica.FiCaSchedulerApp: Completed container: container_1376143950665_0010_01_000028 in state: COMPLETED event:FINISHED
2013-08-10 14:29:59,231 INFO org.apache.hadoop.yarn.server.resourcemanager.RMAuditLogger: USER=ubuntu	OPERATION=AM Released Container	TARGET=SchedulerApp	RESULT=SUCCESS	APPID=application_1376143950665_0010	CONTAINERID=container_1376143950665_0010_01_000028
2013-08-10 14:29:59,231 INFO org.apache.hadoop.yarn.server.resourcemanager.scheduler.common.fica.FiCaSchedulerNode: Released container container_1376143950665_0010_01_000028 of capacity <memory:1024, vCores:1> on host hadoop-221-3:48808, which currently has 7 containers, <memory:7168, vCores:7> used and <memory:1024, vCores:9> available, release resources=true
2013-08-10 14:29:59,231 INFO org.apache.hadoop.yarn.server.resourcemanager.scheduler.capacity.LeafQueue: default used=<memory:48128, vCores:42> numContainers=42 user=ubuntu user-resources=<memory:48128, vCores:42>
2013-08-10 14:29:59,232 INFO org.apache.hadoop.yarn.server.resourcemanager.scheduler.capacity.LeafQueue: completedContainer container=Container: [ContainerId: container_1376143950665_0010_01_000028, NodeId: hadoop-221-3:48808, NodeHttpAddress: hadoop-221-3:8042, Resource: <memory:1024, vCores:1>, Priority: 20, State: NEW, Token: null, Status: container_id {, app_attempt_id {, application_id {, id: 10, cluster_timestamp: 1376143950665, }, attemptId: 1, }, id: 28, }, state: C_COMPLETE, diagnostics: "Container killed by the ApplicationMaster.\n\n", exit_status: 143, ] resource=<memory:1024, vCores:1> queue=default: capacity=1.0, absoluteCapacity=1.0, usedResources=<memory:48128, vCores:42>usedCapacity=0.9791667, absoluteUsedCapacity=0.9791667, numApps=5, numContainers=42 usedCapacity=0.9791667 absoluteUsedCapacity=0.9791667 used=<memory:48128, vCores:42> cluster=<memory:49152, vCores:96>
2013-08-10 14:29:59,233 INFO org.apache.hadoop.yarn.server.resourcemanager.scheduler.capacity.ParentQueue: completedContainer queue=root usedCapacity=0.9791667 absoluteUsedCapacity=0.9791667 used=<memory:48128, vCores:42> cluster=<memory:49152, vCores:96>
2013-08-10 14:29:59,233 INFO org.apache.hadoop.yarn.server.resourcemanager.scheduler.capacity.CapacityScheduler: Application appattempt_1376143950665_0010_000001 released container container_1376143950665_0010_01_000028 on node: host: hadoop-221-3:48808 #containers=7 available=1024 used=7168 with event: FINISHED
2013-08-10 14:29:59,233 INFO org.apache.hadoop.yarn.server.resourcemanager.rmcontainer.RMContainerImpl: container_1376143950665_0006_01_000022 Container Transitioned from NEW to ALLOCATED
2013-08-10 14:29:59,233 INFO org.apache.hadoop.yarn.server.resourcemanager.RMAuditLogger: USER=ubuntu	OPERATION=AM Allocated Container	TARGET=SchedulerApp	RESULT=SUCCESS	APPID=application_1376143950665_0006	CONTAINERID=container_1376143950665_0006_01_000022
2013-08-10 14:29:59,233 INFO org.apache.hadoop.yarn.server.resourcemanager.scheduler.common.fica.FiCaSchedulerNode: Assigned container container_1376143950665_0006_01_000022 of capacity <memory:1024, vCores:1> on host hadoop-221-3:48808, which currently has 8 containers, <memory:8192, vCores:8> used and <memory:0, vCores:8> available
