2013-08-28 20:17:46,299 INFO org.apache.hadoop.yarn.server.resourcemanager.ResourceManager: STARTUP_MSG: 
/************************************************************
STARTUP_MSG: Starting ResourceManager
STARTUP_MSG:   host = hadoop-17-1/192.168.100.34
STARTUP_MSG:   args = []
STARTUP_MSG:   version = 3.0.0-SNAPSHOT
STARTUP_MSG:   build = https://github.com/lalithsuresh/hadoop-common -r 0cb423bd4868928bb06cd93f882bb0913172fd17; compiled by 'lsuresh' on 2013-04-08T15:47Z
STARTUP_MSG:   java = 1.7.0_17
************************************************************/
2013-08-28 20:17:46,315 INFO org.apache.hadoop.yarn.server.resourcemanager.ResourceManager: registered UNIX signal handlers for [TERM, HUP, INT]
2013-08-28 20:17:47,078 INFO org.apache.hadoop.yarn.server.resourcemanager.security.ApplicationTokenSecretManager: Rolling master-key for application-tokens
2013-08-28 20:17:47,111 INFO org.apache.hadoop.yarn.server.resourcemanager.security.RMContainerTokenSecretManager: ContainerTokenKeyRollingInterval: 86400000ms and ContainerTokenKeyActivationDelay: 900000ms
2013-08-28 20:17:47,116 INFO org.apache.hadoop.yarn.service.AbstractService: Service:Dispatcher is inited.
2013-08-28 20:17:47,119 INFO org.apache.hadoop.yarn.event.AsyncDispatcher: Registering class org.apache.hadoop.yarn.server.resourcemanager.recovery.RMStateStoreEventType for class org.apache.hadoop.yarn.server.resourcemanager.recovery.RMStateStore$ForwardingEventHandler
2013-08-28 20:17:47,119 INFO org.apache.hadoop.yarn.service.AbstractService: Service:Dispatcher is started.
2013-08-28 20:17:47,129 INFO org.apache.hadoop.yarn.event.AsyncDispatcher: Registering class org.apache.hadoop.yarn.server.resourcemanager.NodesListManagerEventType for class org.apache.hadoop.yarn.server.resourcemanager.NodesListManager
2013-08-28 20:17:47,130 INFO org.apache.hadoop.yarn.server.resourcemanager.ResourceManager: Using Scheduler: org.apache.hadoop.yarn.server.resourcemanager.scheduler.capacity.CapacityScheduler
2013-08-28 20:17:47,451 INFO org.apache.hadoop.yarn.event.AsyncDispatcher: Registering class org.apache.hadoop.yarn.server.resourcemanager.scheduler.event.SchedulerEventType for class org.apache.hadoop.yarn.server.resourcemanager.ResourceManager$SchedulerEventDispatcher
2013-08-28 20:17:47,454 INFO org.apache.hadoop.yarn.event.AsyncDispatcher: Registering class org.apache.hadoop.yarn.server.resourcemanager.rmapp.RMAppEventType for class org.apache.hadoop.yarn.server.resourcemanager.ResourceManager$ApplicationEventDispatcher
2013-08-28 20:17:47,457 INFO org.apache.hadoop.yarn.event.AsyncDispatcher: Registering class org.apache.hadoop.yarn.server.resourcemanager.rmapp.attempt.RMAppAttemptEventType for class org.apache.hadoop.yarn.server.resourcemanager.ResourceManager$ApplicationAttemptEventDispatcher
2013-08-28 20:17:47,460 INFO org.apache.hadoop.yarn.event.AsyncDispatcher: Registering class org.apache.hadoop.yarn.server.resourcemanager.rmnode.RMNodeEventType for class org.apache.hadoop.yarn.server.resourcemanager.ResourceManager$NodeEventDispatcher
2013-08-28 20:17:48,225 WARN org.apache.hadoop.util.NativeCodeLoader: Unable to load native-hadoop library for your platform... using builtin-java classes where applicable
2013-08-28 20:17:48,259 INFO org.apache.hadoop.yarn.server.resourcemanager.scheduler.capacity.ParentQueue: root, capacity=1.0, asboluteCapacity=1.0, maxCapacity=1.0, asboluteMaxCapacity=1.0, state=RUNNING, acls=SUBMIT_APPLICATIONS:*ADMINISTER_QUEUE:*
2013-08-28 20:17:48,259 INFO org.apache.hadoop.yarn.server.resourcemanager.scheduler.capacity.ParentQueue: Initialized parent-queue root name=root, fullname=root
2013-08-28 20:17:48,275 INFO org.apache.hadoop.yarn.server.resourcemanager.scheduler.capacity.LeafQueue: Initializing default
capacity = 1.0 [= (float) configuredCapacity / 100 ]
asboluteCapacity = 1.0 [= parentAbsoluteCapacity * capacity ]
maxCapacity = 1.0 [= configuredMaxCapacity ]
absoluteMaxCapacity = 1.0 [= 1.0 maximumCapacity undefined, (parentAbsoluteMaxCapacity * maximumCapacity) / 100 otherwise ]
userLimit = 100 [= configuredUserLimit ]
userLimitFactor = 1.0 [= configuredUserLimitFactor ]
maxApplications = 10000 [= configuredMaximumSystemApplicationsPerQueue or (int)(configuredMaximumSystemApplications * absoluteCapacity)]
maxApplicationsPerUser = 10000 [= (int)(maxApplications * (userLimit / 100.0f) * userLimitFactor) ]
maxActiveApplications = 1 [= max((int)ceil((clusterResourceMemory / minimumAllocation) * maxAMResourcePerQueuePercent * absoluteMaxCapacity),1) ]
maxActiveAppsUsingAbsCap = 1 [= max((int)ceil((clusterResourceMemory / minimumAllocation) *maxAMResourcePercent * absoluteCapacity),1) ]
maxActiveApplicationsPerUser = 1 [= max((int)(maxActiveApplications * (userLimit / 100.0f) * userLimitFactor),1) ]
usedCapacity = 0.0 [= usedResourcesMemory / (clusterResourceMemory * absoluteCapacity)]
absoluteUsedCapacity = 0.0 [= usedResourcesMemory / clusterResourceMemory]
maxAMResourcePerQueuePercent = 0.1 [= configuredMaximumAMResourcePercent ]
minimumAllocationFactor = 0.875 [= (float)(maximumAllocationMemory - minimumAllocationMemory) / maximumAllocationMemory ]
numContainers = 0 [= currentNumContainers ]
state = RUNNING [= configuredState ]
acls = SUBMIT_APPLICATIONS:*ADMINISTER_QUEUE:* [= configuredAcls ]

2013-08-28 20:17:48,276 INFO org.apache.hadoop.yarn.server.resourcemanager.scheduler.capacity.CapacityScheduler: Initialized queue: default: capacity=1.0, absoluteCapacity=1.0, usedResources=<memory:0, vCores:0>usedCapacity=0.0, absoluteUsedCapacity=0.0, numApps=0, numContainers=0
2013-08-28 20:17:48,276 INFO org.apache.hadoop.yarn.server.resourcemanager.scheduler.capacity.CapacityScheduler: Initialized queue: root: numChildQueue= 1, capacity=1.0, absoluteCapacity=1.0, usedResources=<memory:0, vCores:0>usedCapacity=0.0, numApps=0, numContainers=0
2013-08-28 20:17:48,276 INFO org.apache.hadoop.yarn.server.resourcemanager.scheduler.capacity.CapacityScheduler: Initialized root queue root: numChildQueue= 1, capacity=1.0, absoluteCapacity=1.0, usedResources=<memory:0, vCores:0>usedCapacity=0.0, numApps=0, numContainers=0
2013-08-28 20:17:48,276 INFO org.apache.hadoop.yarn.server.resourcemanager.scheduler.capacity.CapacityScheduler: Initialized CapacityScheduler with calculator=class org.apache.hadoop.yarn.server.resourcemanager.resource.DefaultResourceCalculator, minimumAllocation=<<memory:1024, vCores:1>>, maximumAllocation=<<memory:8192, vCores:32>>
2013-08-28 20:17:48,675 INFO org.apache.hadoop.yarn.event.AsyncDispatcher: Registering class org.apache.hadoop.yarn.server.resourcemanager.RMAppManagerEventType for class org.apache.hadoop.yarn.server.resourcemanager.RMAppManager
2013-08-28 20:17:48,699 INFO org.apache.hadoop.yarn.event.AsyncDispatcher: Registering class org.apache.hadoop.yarn.server.resourcemanager.amlauncher.AMLauncherEventType for class org.apache.hadoop.yarn.server.resourcemanager.amlauncher.ApplicationMasterLauncher
2013-08-28 20:17:48,811 INFO org.apache.hadoop.yarn.server.resourcemanager.RMNMInfo: Registered RMNMInfo MBean
2013-08-28 20:17:48,812 INFO org.apache.hadoop.yarn.service.AbstractService: Service:Dispatcher is inited.
2013-08-28 20:17:48,812 INFO org.apache.hadoop.yarn.service.AbstractService: Service:org.apache.hadoop.yarn.server.resourcemanager.rmcontainer.ContainerAllocationExpirer is inited.
2013-08-28 20:17:48,812 INFO org.apache.hadoop.yarn.service.AbstractService: Service:AMLivelinessMonitor is inited.
2013-08-28 20:17:48,812 INFO org.apache.hadoop.yarn.service.AbstractService: Service:AMLivelinessMonitor is inited.
2013-08-28 20:17:48,812 INFO org.apache.hadoop.yarn.service.AbstractService: Service:org.apache.hadoop.yarn.server.resourcemanager.security.DelegationTokenRenewer is inited.
2013-08-28 20:17:48,814 INFO org.apache.hadoop.util.HostsFileReader: Refreshing hosts (include/exclude) list
2013-08-28 20:17:48,814 INFO org.apache.hadoop.yarn.service.AbstractService: Service:org.apache.hadoop.yarn.server.resourcemanager.NodesListManager is inited.
2013-08-28 20:17:48,815 INFO org.apache.hadoop.yarn.service.AbstractService: Service:org.apache.hadoop.yarn.server.resourcemanager.ResourceManager$SchedulerEventDispatcher is inited.
2013-08-28 20:17:48,815 INFO org.apache.hadoop.yarn.service.AbstractService: Service:NMLivelinessMonitor is inited.
2013-08-28 20:17:48,825 INFO org.apache.hadoop.yarn.service.AbstractService: Service:org.apache.hadoop.yarn.server.resourcemanager.ResourceTrackerService is inited.
2013-08-28 20:17:48,825 INFO org.apache.hadoop.yarn.service.AbstractService: Service:org.apache.hadoop.yarn.server.resourcemanager.ApplicationMasterService is inited.
2013-08-28 20:17:48,825 INFO org.apache.hadoop.yarn.service.AbstractService: Service:org.apache.hadoop.yarn.server.resourcemanager.ClientRMService is inited.
2013-08-28 20:17:48,825 INFO org.apache.hadoop.yarn.service.AbstractService: Service:org.apache.hadoop.yarn.server.resourcemanager.AdminService is inited.
2013-08-28 20:17:48,826 INFO org.apache.hadoop.yarn.service.AbstractService: Service:org.apache.hadoop.yarn.server.resourcemanager.amlauncher.ApplicationMasterLauncher is inited.
2013-08-28 20:17:48,826 INFO org.apache.hadoop.yarn.service.AbstractService: Service:ResourceManager is inited.
2013-08-28 20:17:48,826 INFO org.apache.hadoop.yarn.server.resourcemanager.security.ApplicationTokenSecretManager: Rolling master-key for application-tokens
2013-08-28 20:17:48,827 INFO org.apache.hadoop.yarn.server.resourcemanager.security.RMContainerTokenSecretManager: Rolling master-key for container-tokens
2013-08-28 20:17:48,934 INFO org.mortbay.log: Logging to org.slf4j.impl.Log4jLoggerAdapter(org.mortbay.log) via org.mortbay.log.Slf4jLog
2013-08-28 20:17:48,989 INFO org.apache.hadoop.http.HttpServer: Added global filter 'safety' (class=org.apache.hadoop.http.HttpServer$QuotingInputFilter)
2013-08-28 20:17:48,991 INFO org.apache.hadoop.http.HttpServer: Added filter static_user_filter (class=org.apache.hadoop.http.lib.StaticUserWebFilter$StaticUserFilter) to context cluster
2013-08-28 20:17:48,991 INFO org.apache.hadoop.http.HttpServer: Added filter static_user_filter (class=org.apache.hadoop.http.lib.StaticUserWebFilter$StaticUserFilter) to context logs
2013-08-28 20:17:48,991 INFO org.apache.hadoop.http.HttpServer: Added filter static_user_filter (class=org.apache.hadoop.http.lib.StaticUserWebFilter$StaticUserFilter) to context static
2013-08-28 20:17:48,995 INFO org.apache.hadoop.http.HttpServer: adding path spec: /cluster
2013-08-28 20:17:48,996 INFO org.apache.hadoop.http.HttpServer: adding path spec: /cluster/*
2013-08-28 20:17:48,996 INFO org.apache.hadoop.http.HttpServer: adding path spec: /ws
2013-08-28 20:17:48,996 INFO org.apache.hadoop.http.HttpServer: adding path spec: /ws/*
2013-08-28 20:17:48,997 INFO org.apache.hadoop.http.HttpServer: Added global filter 'guice' (class=com.google.inject.servlet.GuiceFilter)
2013-08-28 20:17:49,003 INFO org.apache.hadoop.http.HttpServer: Jetty bound to port 8088
2013-08-28 20:17:49,003 INFO org.mortbay.log: jetty-6.1.26
2013-08-28 20:17:49,031 INFO org.mortbay.log: Extract jar:file:/home/ubuntu/hadoop-3.0.0-SNAPSHOT/share/hadoop/yarn/hadoop-yarn-common-3.0.0-SNAPSHOT.jar!/webapps/cluster to /tmp/Jetty_0_0_0_0_8088_cluster____u0rgz3/webapp
2013-08-28 20:17:49,320 INFO org.mortbay.log: Started SelectChannelConnector@0.0.0.0:8088
2013-08-28 20:17:49,320 INFO org.apache.hadoop.yarn.webapp.WebApps: Web app /cluster started at 8088
2013-08-28 20:17:50,014 INFO org.apache.hadoop.yarn.webapp.WebApps: Registered webapp guice modules
2013-08-28 20:17:50,138 INFO org.apache.hadoop.metrics2.impl.MetricsConfig: loaded properties from hadoop-metrics2.properties
2013-08-28 20:17:50,177 INFO org.apache.hadoop.metrics2.impl.MetricsSystemImpl: Scheduled snapshot period at 10 second(s).
2013-08-28 20:17:50,177 INFO org.apache.hadoop.metrics2.impl.MetricsSystemImpl: ResourceManager metrics system started
2013-08-28 20:17:50,194 INFO org.apache.hadoop.security.token.delegation.AbstractDelegationTokenSecretManager: Updating the current master key for generating delegation tokens
2013-08-28 20:17:50,198 INFO org.apache.hadoop.yarn.service.AbstractService: Service:Dispatcher is started.
2013-08-28 20:17:50,199 INFO org.apache.hadoop.security.token.delegation.AbstractDelegationTokenSecretManager: Starting expired delegation token remover thread, tokenRemoverScanInterval=60 min(s)
2013-08-28 20:17:50,199 INFO org.apache.hadoop.security.token.delegation.AbstractDelegationTokenSecretManager: Updating the current master key for generating delegation tokens
2013-08-28 20:17:50,201 INFO org.apache.hadoop.yarn.service.AbstractService: Service:org.apache.hadoop.yarn.server.resourcemanager.rmcontainer.ContainerAllocationExpirer is started.
2013-08-28 20:17:50,202 INFO org.apache.hadoop.yarn.service.AbstractService: Service:AMLivelinessMonitor is started.
2013-08-28 20:17:50,203 INFO org.apache.hadoop.yarn.service.AbstractService: Service:AMLivelinessMonitor is started.
2013-08-28 20:17:50,203 INFO org.apache.hadoop.yarn.service.AbstractService: Service:org.apache.hadoop.yarn.server.resourcemanager.security.DelegationTokenRenewer is started.
2013-08-28 20:17:50,204 INFO org.apache.hadoop.yarn.service.AbstractService: Service:org.apache.hadoop.yarn.server.resourcemanager.NodesListManager is started.
2013-08-28 20:17:50,205 INFO org.apache.hadoop.yarn.service.AbstractService: Service:org.apache.hadoop.yarn.server.resourcemanager.ResourceManager$SchedulerEventDispatcher is started.
2013-08-28 20:17:50,206 INFO org.apache.hadoop.yarn.service.AbstractService: Service:NMLivelinessMonitor is started.
2013-08-28 20:17:50,206 INFO org.apache.hadoop.yarn.service.AbstractService: Service:org.apache.hadoop.yarn.server.resourcemanager.ResourceTrackerService is started.
2013-08-28 20:17:50,293 INFO org.apache.hadoop.ipc.Server: Starting Socket Reader #1 for port 54110
2013-08-28 20:17:50,342 INFO org.apache.hadoop.yarn.factories.impl.pb.RpcServerFactoryPBImpl: Adding protocol org.apache.hadoop.yarn.server.api.ResourceTrackerPB to the server
2013-08-28 20:17:50,343 INFO org.apache.hadoop.ipc.Server: IPC Server Responder: starting
2013-08-28 20:17:50,346 INFO org.apache.hadoop.ipc.Server: IPC Server listener on 54110: starting
2013-08-28 20:17:50,479 INFO org.apache.hadoop.ipc.Server: Starting Socket Reader #1 for port 54112
2013-08-28 20:17:50,501 INFO org.apache.hadoop.yarn.factories.impl.pb.RpcServerFactoryPBImpl: Adding protocol org.apache.hadoop.yarn.api.AMRMProtocolPB to the server
2013-08-28 20:17:50,503 INFO org.apache.hadoop.ipc.Server: IPC Server Responder: starting
2013-08-28 20:17:50,504 INFO org.apache.hadoop.ipc.Server: IPC Server listener on 54112: starting
2013-08-28 20:17:50,556 INFO org.apache.hadoop.yarn.service.AbstractService: Service:org.apache.hadoop.yarn.server.resourcemanager.ApplicationMasterService is started.
2013-08-28 20:17:50,617 INFO org.apache.hadoop.ipc.Server: Starting Socket Reader #1 for port 54111
2013-08-28 20:17:50,623 INFO org.apache.hadoop.yarn.factories.impl.pb.RpcServerFactoryPBImpl: Adding protocol org.apache.hadoop.yarn.api.ClientRMProtocolPB to the server
2013-08-28 20:17:50,624 INFO org.apache.hadoop.ipc.Server: IPC Server Responder: starting
2013-08-28 20:17:50,627 INFO org.apache.hadoop.ipc.Server: IPC Server listener on 54111: starting
2013-08-28 20:17:50,661 INFO org.apache.hadoop.yarn.service.AbstractService: Service:org.apache.hadoop.yarn.server.resourcemanager.ClientRMService is started.
2013-08-28 20:17:50,704 INFO org.apache.hadoop.ipc.Server: Starting Socket Reader #1 for port 8033
2013-08-28 20:17:50,710 INFO org.apache.hadoop.yarn.factories.impl.pb.RpcServerFactoryPBImpl: Adding protocol org.apache.hadoop.yarn.api.RMAdminProtocolPB to the server
2013-08-28 20:17:50,711 INFO org.apache.hadoop.ipc.Server: IPC Server Responder: starting
2013-08-28 20:17:50,723 INFO org.apache.hadoop.yarn.service.AbstractService: Service:org.apache.hadoop.yarn.server.resourcemanager.AdminService is started.
2013-08-28 20:17:50,723 INFO org.apache.hadoop.ipc.Server: IPC Server listener on 8033: starting
2013-08-28 20:17:50,723 INFO org.apache.hadoop.yarn.service.AbstractService: Service:org.apache.hadoop.yarn.server.resourcemanager.amlauncher.ApplicationMasterLauncher is started.
2013-08-28 20:17:50,724 INFO org.apache.hadoop.yarn.service.AbstractService: Service:ResourceManager is started.
2013-08-28 20:18:00,388 INFO org.apache.hadoop.yarn.util.RackResolver: Resolved hadoop-17-4 to /default-rack
2013-08-28 20:18:00,396 INFO org.apache.hadoop.yarn.server.resourcemanager.ResourceTrackerService: NodeManager from node hadoop-17-4(cmPort: 59779 httpPort: 8042) registered with capability: <memory:8192, vCores:16>, assigned nodeId hadoop-17-4:59779
2013-08-28 20:18:00,401 INFO org.apache.hadoop.yarn.util.RackResolver: Resolved hadoop-17-6 to /default-rack
2013-08-28 20:18:00,401 INFO org.apache.hadoop.yarn.server.resourcemanager.ResourceTrackerService: NodeManager from node hadoop-17-6(cmPort: 32933 httpPort: 8042) registered with capability: <memory:8192, vCores:16>, assigned nodeId hadoop-17-6:32933
2013-08-28 20:18:00,408 INFO org.apache.hadoop.yarn.util.RackResolver: Resolved hadoop-17-2 to /default-rack
2013-08-28 20:18:00,409 INFO org.apache.hadoop.yarn.server.resourcemanager.ResourceTrackerService: NodeManager from node hadoop-17-2(cmPort: 52914 httpPort: 8042) registered with capability: <memory:8192, vCores:16>, assigned nodeId hadoop-17-2:52914
2013-08-28 20:18:00,429 INFO org.apache.hadoop.yarn.server.resourcemanager.rmnode.RMNodeImpl: hadoop-17-4:59779 Node Transitioned from NEW to RUNNING
2013-08-28 20:18:00,437 INFO org.apache.hadoop.yarn.server.resourcemanager.rmnode.RMNodeImpl: hadoop-17-6:32933 Node Transitioned from NEW to RUNNING
2013-08-28 20:18:00,442 INFO org.apache.hadoop.yarn.server.resourcemanager.scheduler.capacity.CapacityScheduler: Added node hadoop-17-4:59779 clusterResource: <memory:8192, vCores:16>
2013-08-28 20:18:00,443 INFO org.apache.hadoop.yarn.server.resourcemanager.rmnode.RMNodeImpl: hadoop-17-2:52914 Node Transitioned from NEW to RUNNING
2013-08-28 20:18:00,443 INFO org.apache.hadoop.yarn.server.resourcemanager.scheduler.capacity.CapacityScheduler: Added node hadoop-17-6:32933 clusterResource: <memory:16384, vCores:32>
2013-08-28 20:18:00,444 INFO org.apache.hadoop.yarn.server.resourcemanager.scheduler.capacity.CapacityScheduler: Added node hadoop-17-2:52914 clusterResource: <memory:24576, vCores:48>
2013-08-28 20:18:00,520 INFO org.apache.hadoop.yarn.util.RackResolver: Resolved hadoop-17-3 to /default-rack
2013-08-28 20:18:00,520 INFO org.apache.hadoop.yarn.server.resourcemanager.ResourceTrackerService: NodeManager from node hadoop-17-3(cmPort: 35481 httpPort: 8042) registered with capability: <memory:8192, vCores:16>, assigned nodeId hadoop-17-3:35481
2013-08-28 20:18:00,521 INFO org.apache.hadoop.yarn.server.resourcemanager.rmnode.RMNodeImpl: hadoop-17-3:35481 Node Transitioned from NEW to RUNNING
2013-08-28 20:18:00,522 INFO org.apache.hadoop.yarn.server.resourcemanager.scheduler.capacity.CapacityScheduler: Added node hadoop-17-3:35481 clusterResource: <memory:32768, vCores:64>
2013-08-28 20:18:00,586 INFO org.apache.hadoop.yarn.util.RackResolver: Resolved hadoop-17-7 to /default-rack
2013-08-28 20:18:00,586 INFO org.apache.hadoop.yarn.server.resourcemanager.ResourceTrackerService: NodeManager from node hadoop-17-7(cmPort: 49112 httpPort: 8042) registered with capability: <memory:8192, vCores:16>, assigned nodeId hadoop-17-7:49112
2013-08-28 20:18:00,587 INFO org.apache.hadoop.yarn.server.resourcemanager.rmnode.RMNodeImpl: hadoop-17-7:49112 Node Transitioned from NEW to RUNNING
2013-08-28 20:18:00,588 INFO org.apache.hadoop.yarn.server.resourcemanager.scheduler.capacity.CapacityScheduler: Added node hadoop-17-7:49112 clusterResource: <memory:40960, vCores:80>
2013-08-28 20:18:00,702 INFO org.apache.hadoop.yarn.util.RackResolver: Resolved hadoop-17-5 to /default-rack
2013-08-28 20:18:00,702 INFO org.apache.hadoop.yarn.server.resourcemanager.ResourceTrackerService: NodeManager from node hadoop-17-5(cmPort: 46576 httpPort: 8042) registered with capability: <memory:8192, vCores:16>, assigned nodeId hadoop-17-5:46576
2013-08-28 20:18:00,703 INFO org.apache.hadoop.yarn.server.resourcemanager.rmnode.RMNodeImpl: hadoop-17-5:46576 Node Transitioned from NEW to RUNNING
2013-08-28 20:18:00,704 INFO org.apache.hadoop.yarn.server.resourcemanager.scheduler.capacity.CapacityScheduler: Added node hadoop-17-5:46576 clusterResource: <memory:49152, vCores:96>
2013-08-28 20:18:27,882 INFO org.apache.hadoop.yarn.server.resourcemanager.ClientRMService: Allocated new applicationId: 1
2013-08-28 20:18:31,317 INFO org.apache.hadoop.yarn.server.resourcemanager.ClientRMService: Storing Application with id application_1377721066246_0001
2013-08-28 20:18:31,323 INFO org.apache.hadoop.yarn.server.resourcemanager.recovery.RMStateStore: Storing info for app: application_1377721066246_0001
2013-08-28 20:18:31,323 INFO org.apache.hadoop.yarn.server.resourcemanager.ClientRMService: Application with id 1 submitted by user ubuntu
2013-08-28 20:18:31,327 INFO org.apache.hadoop.yarn.server.resourcemanager.RMAuditLogger: USER=ubuntu	IP=192.168.100.34	OPERATION=Submit Application Request	TARGET=ClientRMService	RESULT=SUCCESS	APPID=application_1377721066246_0001
2013-08-28 20:18:31,370 INFO org.apache.hadoop.yarn.server.resourcemanager.rmapp.RMAppImpl: application_1377721066246_0001 State change from NEW to SUBMITTED
2013-08-28 20:18:31,370 INFO org.apache.hadoop.yarn.server.resourcemanager.ApplicationMasterService: Registering appattempt_1377721066246_0001_000001
2013-08-28 20:18:31,372 INFO org.apache.hadoop.yarn.server.resourcemanager.rmapp.attempt.RMAppAttemptImpl: appattempt_1377721066246_0001_000001 State change from NEW to SUBMITTED
2013-08-28 20:18:31,404 INFO org.apache.hadoop.yarn.server.resourcemanager.scheduler.capacity.LeafQueue: Application application_1377721066246_0001 from user: ubuntu activated in queue: default
2013-08-28 20:18:31,405 INFO org.apache.hadoop.yarn.server.resourcemanager.scheduler.capacity.LeafQueue: Application added - appId: application_1377721066246_0001 user: org.apache.hadoop.yarn.server.resourcemanager.scheduler.capacity.LeafQueue$User@5f28e5cb, leaf-queue: default #user-pending-applications: 0 #user-active-applications: 1 #queue-pending-applications: 0 #queue-active-applications: 1
2013-08-28 20:18:31,405 INFO org.apache.hadoop.yarn.server.resourcemanager.scheduler.capacity.ParentQueue: Application added - appId: application_1377721066246_0001 user: ubuntu leaf-queue of parent: root #applications: 1
2013-08-28 20:18:31,405 INFO org.apache.hadoop.yarn.server.resourcemanager.scheduler.capacity.CapacityScheduler: Application Submission: appattempt_1377721066246_0001_000001, user: ubuntu queue: default: capacity=1.0, absoluteCapacity=1.0, usedResources=<memory:0, vCores:0>usedCapacity=0.0, absoluteUsedCapacity=0.0, numApps=1, numContainers=0, currently active: 1
2013-08-28 20:18:31,411 INFO org.apache.hadoop.yarn.server.resourcemanager.rmapp.attempt.RMAppAttemptImpl: appattempt_1377721066246_0001_000001 State change from SUBMITTED to SCHEDULED
2013-08-28 20:18:31,411 INFO org.apache.hadoop.yarn.server.resourcemanager.rmapp.RMAppImpl: application_1377721066246_0001 State change from SUBMITTED to ACCEPTED
2013-08-28 20:18:31,677 INFO org.apache.hadoop.yarn.server.resourcemanager.rmcontainer.RMContainerImpl: container_1377721066246_0001_01_000001 Container Transitioned from NEW to ALLOCATED
2013-08-28 20:18:31,677 INFO org.apache.hadoop.yarn.server.resourcemanager.RMAuditLogger: USER=ubuntu	OPERATION=AM Allocated Container	TARGET=SchedulerApp	RESULT=SUCCESS	APPID=application_1377721066246_0001	CONTAINERID=container_1377721066246_0001_01_000001
2013-08-28 20:18:31,678 INFO org.apache.hadoop.yarn.server.resourcemanager.scheduler.common.fica.FiCaSchedulerNode: Assigned container container_1377721066246_0001_01_000001 of capacity <memory:2048, vCores:1> on host hadoop-17-6:32933, which currently has 1 containers, <memory:2048, vCores:1> used and <memory:6144, vCores:15> available
2013-08-28 20:18:31,684 INFO org.apache.hadoop.yarn.server.resourcemanager.scheduler.capacity.LeafQueue: assignedContainer application=application_1377721066246_0001 container=Container: [ContainerId: container_1377721066246_0001_01_000001, NodeId: hadoop-17-6:32933, NodeHttpAddress: hadoop-17-6:8042, Resource: <memory:2048, vCores:1>, Priority: 0, State: NEW, Token: null, Status: container_id {, app_attempt_id {, application_id {, id: 1, cluster_timestamp: 1377721066246, }, attemptId: 1, }, id: 1, }, state: C_NEW, ] containerId=container_1377721066246_0001_01_000001 queue=default: capacity=1.0, absoluteCapacity=1.0, usedResources=<memory:0, vCores:0>usedCapacity=0.0, absoluteUsedCapacity=0.0, numApps=1, numContainers=0 usedCapacity=0.0 absoluteUsedCapacity=0.0 used=<memory:0, vCores:0> cluster=<memory:49152, vCores:96>
2013-08-28 20:18:31,684 INFO org.apache.hadoop.yarn.server.resourcemanager.scheduler.capacity.ParentQueue: Re-sorting queues since queue: root.default stats: default: capacity=1.0, absoluteCapacity=1.0, usedResources=<memory:2048, vCores:1>usedCapacity=0.041666668, absoluteUsedCapacity=0.041666668, numApps=1, numContainers=1
2013-08-28 20:18:31,685 INFO org.apache.hadoop.yarn.server.resourcemanager.scheduler.capacity.ParentQueue: assignedContainer queue=root usedCapacity=0.041666668 absoluteUsedCapacity=0.041666668 used=<memory:2048, vCores:1> cluster=<memory:49152, vCores:96>
2013-08-28 20:18:31,687 INFO org.apache.hadoop.yarn.server.resourcemanager.rmcontainer.RMContainerImpl: container_1377721066246_0001_01_000001 Container Transitioned from ALLOCATED to ACQUIRED
2013-08-28 20:18:31,691 INFO org.apache.hadoop.yarn.server.resourcemanager.rmapp.attempt.RMAppAttemptImpl: Storing attempt: AppId: application_1377721066246_0001 AttemptId: appattempt_1377721066246_0001_000001 MasterContainer: Container: [ContainerId: container_1377721066246_0001_01_000001, NodeId: hadoop-17-6:32933, NodeHttpAddress: hadoop-17-6:8042, Resource: <memory:2048, vCores:1>, Priority: 0, State: NEW, Token: null, Status: container_id {, app_attempt_id {, application_id {, id: 1, cluster_timestamp: 1377721066246, }, attemptId: 1, }, id: 1, }, state: C_NEW, ]
2013-08-28 20:18:31,695 INFO org.apache.hadoop.yarn.server.resourcemanager.rmapp.attempt.RMAppAttemptImpl: appattempt_1377721066246_0001_000001 State change from SCHEDULED to ALLOCATED_SAVING
2013-08-28 20:18:31,699 INFO org.apache.hadoop.yarn.server.resourcemanager.recovery.RMStateStore: Storing info for attempt: appattempt_1377721066246_0001_000001
2013-08-28 20:18:31,702 INFO org.apache.hadoop.yarn.server.resourcemanager.rmapp.attempt.RMAppAttemptImpl: appattempt_1377721066246_0001_000001 State change from ALLOCATED_SAVING to ALLOCATED
2013-08-28 20:18:31,711 INFO org.apache.hadoop.yarn.server.resourcemanager.amlauncher.AMLauncher: Launching masterappattempt_1377721066246_0001_000001
2013-08-28 20:18:31,755 INFO org.apache.hadoop.yarn.server.resourcemanager.amlauncher.AMLauncher: Setting up container Container: [ContainerId: container_1377721066246_0001_01_000001, NodeId: hadoop-17-6:32933, NodeHttpAddress: hadoop-17-6:8042, Resource: <memory:2048, vCores:1>, Priority: 0, State: NEW, Token: null, Status: container_id {, app_attempt_id {, application_id {, id: 1, cluster_timestamp: 1377721066246, }, attemptId: 1, }, id: 1, }, state: C_NEW, ] for AM appattempt_1377721066246_0001_000001
2013-08-28 20:18:31,755 INFO org.apache.hadoop.yarn.server.resourcemanager.amlauncher.AMLauncher: Command to launch container container_1377721066246_0001_01_000001 : $JAVA_HOME/bin/java -Dlog4j.configuration=container-log4j.properties -Dyarn.app.mapreduce.container.log.dir=<LOG_DIR> -Dyarn.app.mapreduce.container.log.filesize=0 -Dhadoop.root.logger=INFO,CLA  -Xmx1024m org.apache.hadoop.mapreduce.v2.app.MRAppMaster 1><LOG_DIR>/stdout 2><LOG_DIR>/stderr 
2013-08-28 20:18:32,706 INFO org.apache.hadoop.yarn.server.resourcemanager.amlauncher.AMLauncher: Done launching container Container: [ContainerId: container_1377721066246_0001_01_000001, NodeId: hadoop-17-6:32933, NodeHttpAddress: hadoop-17-6:8042, Resource: <memory:2048, vCores:1>, Priority: 0, State: NEW, Token: null, Status: container_id {, app_attempt_id {, application_id {, id: 1, cluster_timestamp: 1377721066246, }, attemptId: 1, }, id: 1, }, state: C_NEW, ] for AM appattempt_1377721066246_0001_000001
2013-08-28 20:18:32,707 INFO org.apache.hadoop.yarn.server.resourcemanager.rmapp.attempt.RMAppAttemptImpl: appattempt_1377721066246_0001_000001 State change from ALLOCATED to LAUNCHED
2013-08-28 20:18:33,693 INFO org.apache.hadoop.yarn.server.resourcemanager.rmcontainer.RMContainerImpl: container_1377721066246_0001_01_000001 Container Transitioned from ACQUIRED to RUNNING
2013-08-28 20:18:42,027 INFO org.apache.hadoop.yarn.server.resourcemanager.ApplicationMasterService: AM registration appattempt_1377721066246_0001_000001
2013-08-28 20:18:42,028 INFO org.apache.hadoop.yarn.server.resourcemanager.RMAuditLogger: USER=ubuntu	IP=192.168.100.38	OPERATION=Register App Master	TARGET=ApplicationMasterService	RESULT=SUCCESS	APPID=application_1377721066246_0001	APPATTEMPTID=appattempt_1377721066246_0001_000001
2013-08-28 20:18:42,031 INFO org.apache.hadoop.yarn.server.resourcemanager.rmapp.attempt.RMAppAttemptImpl: appattempt_1377721066246_0001_000001 State change from LAUNCHED to RUNNING
2013-08-28 20:18:42,031 INFO org.apache.hadoop.yarn.server.resourcemanager.rmapp.RMAppImpl: application_1377721066246_0001 State change from ACCEPTED to RUNNING
2013-08-28 20:18:43,696 INFO org.apache.hadoop.yarn.server.resourcemanager.rmcontainer.RMContainerImpl: container_1377721066246_0001_01_000002 Container Transitioned from NEW to ALLOCATED
2013-08-28 20:18:43,696 INFO org.apache.hadoop.yarn.server.resourcemanager.RMAuditLogger: USER=ubuntu	OPERATION=AM Allocated Container	TARGET=SchedulerApp	RESULT=SUCCESS	APPID=application_1377721066246_0001	CONTAINERID=container_1377721066246_0001_01_000002
2013-08-28 20:18:43,697 INFO org.apache.hadoop.yarn.server.resourcemanager.scheduler.common.fica.FiCaSchedulerNode: Assigned container container_1377721066246_0001_01_000002 of capacity <memory:1024, vCores:1> on host hadoop-17-2:52914, which currently has 1 containers, <memory:1024, vCores:1> used and <memory:7168, vCores:15> available
2013-08-28 20:18:43,698 INFO org.apache.hadoop.yarn.server.resourcemanager.scheduler.capacity.LeafQueue: assignedContainer application=application_1377721066246_0001 container=Container: [ContainerId: container_1377721066246_0001_01_000002, NodeId: hadoop-17-2:52914, NodeHttpAddress: hadoop-17-2:8042, Resource: <memory:1024, vCores:1>, Priority: 20, State: NEW, Token: null, Status: container_id {, app_attempt_id {, application_id {, id: 1, cluster_timestamp: 1377721066246, }, attemptId: 1, }, id: 2, }, state: C_NEW, ] containerId=container_1377721066246_0001_01_000002 queue=default: capacity=1.0, absoluteCapacity=1.0, usedResources=<memory:2048, vCores:1>usedCapacity=0.041666668, absoluteUsedCapacity=0.041666668, numApps=1, numContainers=1 usedCapacity=0.041666668 absoluteUsedCapacity=0.041666668 used=<memory:2048, vCores:1> cluster=<memory:49152, vCores:96>
2013-08-28 20:18:43,699 INFO org.apache.hadoop.yarn.server.resourcemanager.scheduler.capacity.ParentQueue: Re-sorting queues since queue: root.default stats: default: capacity=1.0, absoluteCapacity=1.0, usedResources=<memory:3072, vCores:2>usedCapacity=0.0625, absoluteUsedCapacity=0.0625, numApps=1, numContainers=2
2013-08-28 20:18:43,699 INFO org.apache.hadoop.yarn.server.resourcemanager.scheduler.capacity.ParentQueue: assignedContainer queue=root usedCapacity=0.0625 absoluteUsedCapacity=0.0625 used=<memory:3072, vCores:2> cluster=<memory:49152, vCores:96>
2013-08-28 20:18:43,718 INFO org.apache.hadoop.yarn.server.resourcemanager.rmcontainer.RMContainerImpl: container_1377721066246_0001_01_000003 Container Transitioned from NEW to ALLOCATED
2013-08-28 20:18:43,718 INFO org.apache.hadoop.yarn.server.resourcemanager.RMAuditLogger: USER=ubuntu	OPERATION=AM Allocated Container	TARGET=SchedulerApp	RESULT=SUCCESS	APPID=application_1377721066246_0001	CONTAINERID=container_1377721066246_0001_01_000003
2013-08-28 20:18:43,718 INFO org.apache.hadoop.yarn.server.resourcemanager.scheduler.common.fica.FiCaSchedulerNode: Assigned container container_1377721066246_0001_01_000003 of capacity <memory:1024, vCores:1> on host hadoop-17-4:59779, which currently has 1 containers, <memory:1024, vCores:1> used and <memory:7168, vCores:15> available
2013-08-28 20:18:43,720 INFO org.apache.hadoop.yarn.server.resourcemanager.scheduler.capacity.LeafQueue: assignedContainer application=application_1377721066246_0001 container=Container: [ContainerId: container_1377721066246_0001_01_000003, NodeId: hadoop-17-4:59779, NodeHttpAddress: hadoop-17-4:8042, Resource: <memory:1024, vCores:1>, Priority: 20, State: NEW, Token: null, Status: container_id {, app_attempt_id {, application_id {, id: 1, cluster_timestamp: 1377721066246, }, attemptId: 1, }, id: 3, }, state: C_NEW, ] containerId=container_1377721066246_0001_01_000003 queue=default: capacity=1.0, absoluteCapacity=1.0, usedResources=<memory:3072, vCores:2>usedCapacity=0.0625, absoluteUsedCapacity=0.0625, numApps=1, numContainers=2 usedCapacity=0.0625 absoluteUsedCapacity=0.0625 used=<memory:3072, vCores:2> cluster=<memory:49152, vCores:96>
2013-08-28 20:18:43,720 INFO org.apache.hadoop.yarn.server.resourcemanager.scheduler.capacity.ParentQueue: Re-sorting queues since queue: root.default stats: default: capacity=1.0, absoluteCapacity=1.0, usedResources=<memory:4096, vCores:3>usedCapacity=0.083333336, absoluteUsedCapacity=0.083333336, numApps=1, numContainers=3
2013-08-28 20:18:43,721 INFO org.apache.hadoop.yarn.server.resourcemanager.scheduler.capacity.ParentQueue: assignedContainer queue=root usedCapacity=0.083333336 absoluteUsedCapacity=0.083333336 used=<memory:4096, vCores:3> cluster=<memory:49152, vCores:96>
2013-08-28 20:18:44,114 INFO org.apache.hadoop.yarn.server.resourcemanager.rmcontainer.RMContainerImpl: container_1377721066246_0001_01_000002 Container Transitioned from ALLOCATED to ACQUIRED
2013-08-28 20:18:44,115 INFO org.apache.hadoop.yarn.server.resourcemanager.rmcontainer.RMContainerImpl: container_1377721066246_0001_01_000003 Container Transitioned from ALLOCATED to ACQUIRED
2013-08-28 20:18:45,153 INFO org.apache.hadoop.yarn.server.resourcemanager.scheduler.AppSchedulingInfo: checking for deactivate... 
2013-08-28 20:18:45,818 INFO org.apache.hadoop.yarn.server.resourcemanager.rmcontainer.RMContainerImpl: container_1377721066246_0001_01_000002 Container Transitioned from ACQUIRED to RUNNING
2013-08-28 20:18:45,824 INFO org.apache.hadoop.yarn.server.resourcemanager.rmcontainer.RMContainerImpl: container_1377721066246_0001_01_000003 Container Transitioned from ACQUIRED to RUNNING
2013-08-28 20:21:47,821 INFO org.apache.hadoop.yarn.server.resourcemanager.rmcontainer.RMContainerImpl: container_1377721066246_0001_01_000002 Container Transitioned from RUNNING to COMPLETED
2013-08-28 20:21:47,821 INFO org.apache.hadoop.yarn.server.resourcemanager.scheduler.common.fica.FiCaSchedulerApp: Completed container: container_1377721066246_0001_01_000002 in state: COMPLETED event:FINISHED
2013-08-28 20:21:47,822 INFO org.apache.hadoop.yarn.server.resourcemanager.RMAuditLogger: USER=ubuntu	OPERATION=AM Released Container	TARGET=SchedulerApp	RESULT=SUCCESS	APPID=application_1377721066246_0001	CONTAINERID=container_1377721066246_0001_01_000002
2013-08-28 20:21:47,822 INFO org.apache.hadoop.yarn.server.resourcemanager.scheduler.common.fica.FiCaSchedulerNode: Released container container_1377721066246_0001_01_000002 of capacity <memory:1024, vCores:1> on host hadoop-17-2:52914, which currently has 0 containers, <memory:0, vCores:0> used and <memory:8192, vCores:16> available, release resources=true
2013-08-28 20:21:47,822 INFO org.apache.hadoop.yarn.server.resourcemanager.scheduler.capacity.LeafQueue: default used=<memory:3072, vCores:2> numContainers=2 user=ubuntu user-resources=<memory:3072, vCores:2>
2013-08-28 20:21:47,824 INFO org.apache.hadoop.yarn.server.resourcemanager.scheduler.capacity.LeafQueue: completedContainer container=Container: [ContainerId: container_1377721066246_0001_01_000002, NodeId: hadoop-17-2:52914, NodeHttpAddress: hadoop-17-2:8042, Resource: <memory:1024, vCores:1>, Priority: 20, State: NEW, Token: null, Status: container_id {, app_attempt_id {, application_id {, id: 1, cluster_timestamp: 1377721066246, }, attemptId: 1, }, id: 2, }, state: C_COMPLETE, diagnostics: "Container killed by the ApplicationMaster.\n\n", exit_status: 143, ] resource=<memory:1024, vCores:1> queue=default: capacity=1.0, absoluteCapacity=1.0, usedResources=<memory:3072, vCores:2>usedCapacity=0.0625, absoluteUsedCapacity=0.0625, numApps=1, numContainers=2 usedCapacity=0.0625 absoluteUsedCapacity=0.0625 used=<memory:3072, vCores:2> cluster=<memory:49152, vCores:96>
2013-08-28 20:21:47,825 INFO org.apache.hadoop.yarn.server.resourcemanager.scheduler.capacity.ParentQueue: completedContainer queue=root usedCapacity=0.0625 absoluteUsedCapacity=0.0625 used=<memory:3072, vCores:2> cluster=<memory:49152, vCores:96>
2013-08-28 20:21:47,825 INFO org.apache.hadoop.yarn.server.resourcemanager.scheduler.capacity.CapacityScheduler: Application appattempt_1377721066246_0001_000001 released container container_1377721066246_0001_01_000002 on node: host: hadoop-17-2:52914 #containers=0 available=8192 used=0 with event: FINISHED
2013-08-28 20:21:56,706 INFO org.apache.hadoop.yarn.server.resourcemanager.rmcontainer.RMContainerImpl: container_1377721066246_0001_01_000003 Container Transitioned from RUNNING to COMPLETED
2013-08-28 20:21:56,706 INFO org.apache.hadoop.yarn.server.resourcemanager.scheduler.common.fica.FiCaSchedulerApp: Completed container: container_1377721066246_0001_01_000003 in state: COMPLETED event:FINISHED
2013-08-28 20:21:56,707 INFO org.apache.hadoop.yarn.server.resourcemanager.RMAuditLogger: USER=ubuntu	OPERATION=AM Released Container	TARGET=SchedulerApp	RESULT=SUCCESS	APPID=application_1377721066246_0001	CONTAINERID=container_1377721066246_0001_01_000003
2013-08-28 20:21:56,707 INFO org.apache.hadoop.yarn.server.resourcemanager.scheduler.common.fica.FiCaSchedulerNode: Released container container_1377721066246_0001_01_000003 of capacity <memory:1024, vCores:1> on host hadoop-17-4:59779, which currently has 0 containers, <memory:0, vCores:0> used and <memory:8192, vCores:16> available, release resources=true
2013-08-28 20:21:56,707 INFO org.apache.hadoop.yarn.server.resourcemanager.scheduler.capacity.LeafQueue: default used=<memory:2048, vCores:1> numContainers=1 user=ubuntu user-resources=<memory:2048, vCores:1>
2013-08-28 20:21:56,709 INFO org.apache.hadoop.yarn.server.resourcemanager.scheduler.capacity.LeafQueue: completedContainer container=Container: [ContainerId: container_1377721066246_0001_01_000003, NodeId: hadoop-17-4:59779, NodeHttpAddress: hadoop-17-4:8042, Resource: <memory:1024, vCores:1>, Priority: 20, State: NEW, Token: null, Status: container_id {, app_attempt_id {, application_id {, id: 1, cluster_timestamp: 1377721066246, }, attemptId: 1, }, id: 3, }, state: C_COMPLETE, diagnostics: "Container killed by the ApplicationMaster.\n\n", exit_status: 143, ] resource=<memory:1024, vCores:1> queue=default: capacity=1.0, absoluteCapacity=1.0, usedResources=<memory:2048, vCores:1>usedCapacity=0.041666668, absoluteUsedCapacity=0.041666668, numApps=1, numContainers=1 usedCapacity=0.041666668 absoluteUsedCapacity=0.041666668 used=<memory:2048, vCores:1> cluster=<memory:49152, vCores:96>
2013-08-28 20:21:56,709 INFO org.apache.hadoop.yarn.server.resourcemanager.scheduler.capacity.ParentQueue: completedContainer queue=root usedCapacity=0.041666668 absoluteUsedCapacity=0.041666668 used=<memory:2048, vCores:1> cluster=<memory:49152, vCores:96>
2013-08-28 20:21:56,710 INFO org.apache.hadoop.yarn.server.resourcemanager.scheduler.capacity.CapacityScheduler: Application appattempt_1377721066246_0001_000001 released container container_1377721066246_0001_01_000003 on node: host: hadoop-17-4:59779 #containers=0 available=8192 used=0 with event: FINISHED
2013-08-28 20:22:00,914 INFO org.apache.hadoop.yarn.server.resourcemanager.rmapp.attempt.RMAppAttemptImpl: appattempt_1377721066246_0001_000001 State change from RUNNING to FINISHING
2013-08-28 20:22:00,916 INFO org.apache.hadoop.yarn.server.resourcemanager.rmapp.RMAppImpl: application_1377721066246_0001 State change from RUNNING to FINISHING
2013-08-28 20:22:01,164 INFO org.apache.hadoop.yarn.server.resourcemanager.rmcontainer.RMContainerImpl: container_1377721066246_0001_01_000001 Container Transitioned from RUNNING to COMPLETED
2013-08-28 20:22:01,165 INFO org.apache.hadoop.yarn.server.resourcemanager.scheduler.common.fica.FiCaSchedulerApp: Completed container: container_1377721066246_0001_01_000001 in state: COMPLETED event:FINISHED
2013-08-28 20:22:01,165 INFO org.apache.hadoop.yarn.server.resourcemanager.RMAuditLogger: USER=ubuntu	OPERATION=AM Released Container	TARGET=SchedulerApp	RESULT=SUCCESS	APPID=application_1377721066246_0001	CONTAINERID=container_1377721066246_0001_01_000001
2013-08-28 20:22:01,165 INFO org.apache.hadoop.yarn.server.resourcemanager.scheduler.common.fica.FiCaSchedulerNode: Released container container_1377721066246_0001_01_000001 of capacity <memory:2048, vCores:1> on host hadoop-17-6:32933, which currently has 0 containers, <memory:0, vCores:0> used and <memory:8192, vCores:16> available, release resources=true
2013-08-28 20:22:01,165 INFO org.apache.hadoop.yarn.server.resourcemanager.scheduler.capacity.LeafQueue: default used=<memory:0, vCores:0> numContainers=0 user=ubuntu user-resources=<memory:0, vCores:0>
2013-08-28 20:22:01,167 INFO org.apache.hadoop.yarn.server.resourcemanager.scheduler.capacity.LeafQueue: completedContainer container=Container: [ContainerId: container_1377721066246_0001_01_000001, NodeId: hadoop-17-6:32933, NodeHttpAddress: hadoop-17-6:8042, Resource: <memory:2048, vCores:1>, Priority: 0, State: NEW, Token: null, Status: container_id {, app_attempt_id {, application_id {, id: 1, cluster_timestamp: 1377721066246, }, attemptId: 1, }, id: 1, }, state: C_COMPLETE, diagnostics: "", exit_status: 0, ] resource=<memory:2048, vCores:1> queue=default: capacity=1.0, absoluteCapacity=1.0, usedResources=<memory:0, vCores:0>usedCapacity=0.0, absoluteUsedCapacity=0.0, numApps=1, numContainers=0 usedCapacity=0.0 absoluteUsedCapacity=0.0 used=<memory:0, vCores:0> cluster=<memory:49152, vCores:96>
2013-08-28 20:22:01,167 INFO org.apache.hadoop.yarn.server.resourcemanager.scheduler.capacity.ParentQueue: completedContainer queue=root usedCapacity=0.0 absoluteUsedCapacity=0.0 used=<memory:0, vCores:0> cluster=<memory:49152, vCores:96>
2013-08-28 20:22:01,168 INFO org.apache.hadoop.yarn.server.resourcemanager.scheduler.capacity.CapacityScheduler: Application appattempt_1377721066246_0001_000001 released container container_1377721066246_0001_01_000001 on node: host: hadoop-17-6:32933 #containers=0 available=8192 used=0 with event: FINISHED
2013-08-28 20:22:01,171 INFO org.apache.hadoop.yarn.server.resourcemanager.rmapp.attempt.RMAppAttemptImpl: appattempt_1377721066246_0001_000001 State change from FINISHING to FINISHED
2013-08-28 20:22:01,173 INFO org.apache.hadoop.yarn.server.resourcemanager.rmapp.RMAppImpl: application_1377721066246_0001 State change from FINISHING to FINISHED
2013-08-28 20:22:01,174 INFO org.apache.hadoop.yarn.server.resourcemanager.scheduler.capacity.CapacityScheduler: Application appattempt_1377721066246_0001_000001 is done. finalState=FINISHED
2013-08-28 20:22:01,175 INFO org.apache.hadoop.yarn.server.resourcemanager.scheduler.AppSchedulingInfo: Application application_1377721066246_0001 requests cleared
2013-08-28 20:22:01,176 INFO org.apache.hadoop.yarn.server.resourcemanager.scheduler.capacity.LeafQueue: Application removed - appId: application_1377721066246_0001 user: ubuntu queue: default #user-pending-applications: 0 #user-active-applications: 0 #queue-pending-applications: 0 #queue-active-applications: 0
2013-08-28 20:22:01,176 INFO org.apache.hadoop.yarn.server.resourcemanager.scheduler.capacity.ParentQueue: Application removed - appId: application_1377721066246_0001 user: ubuntu leaf-queue of parent: root #applications: 0
2013-08-28 20:22:01,176 INFO org.apache.hadoop.yarn.server.resourcemanager.RMAuditLogger: USER=ubuntu	OPERATION=Application Finished - Succeeded	TARGET=RMAppManager	RESULT=SUCCESS	APPID=application_1377721066246_0001
2013-08-28 20:22:01,179 INFO org.apache.hadoop.yarn.server.resourcemanager.recovery.RMStateStore: Removing info for app: application_1377721066246_0001
2013-08-28 20:22:01,181 INFO org.apache.hadoop.yarn.server.resourcemanager.amlauncher.AMLauncher: Cleaning master appattempt_1377721066246_0001_000001
2013-08-28 20:22:01,183 INFO org.apache.hadoop.yarn.server.resourcemanager.RMAppManager$ApplicationSummary: appId=application_1377721066246_0001,name=TeraGen,user=ubuntu,queue=default,state=FINISHED,trackingUrl=hadoop-17-1.novalocal:8088/proxy/application_1377721066246_0001/jobhistory/job/job_1377721066246_0001,appMasterHost=hadoop-17-6,startTime=1377721111310,finishTime=1377721320916
2013-08-28 20:22:13,146 INFO org.apache.hadoop.yarn.server.resourcemanager.ClientRMService: Allocated new applicationId: 2
2013-08-28 20:22:15,149 INFO org.apache.hadoop.yarn.server.resourcemanager.ClientRMService: Storing Application with id application_1377721066246_0002
2013-08-28 20:22:15,149 INFO org.apache.hadoop.yarn.server.resourcemanager.recovery.RMStateStore: Storing info for app: application_1377721066246_0002
2013-08-28 20:22:15,149 INFO org.apache.hadoop.yarn.server.resourcemanager.ClientRMService: Application with id 2 submitted by user ubuntu
2013-08-28 20:22:15,149 INFO org.apache.hadoop.yarn.server.resourcemanager.RMAuditLogger: USER=ubuntu	IP=192.168.100.34	OPERATION=Submit Application Request	TARGET=ClientRMService	RESULT=SUCCESS	APPID=application_1377721066246_0002
2013-08-28 20:22:15,153 INFO org.apache.hadoop.yarn.server.resourcemanager.rmapp.RMAppImpl: application_1377721066246_0002 State change from NEW to SUBMITTED
2013-08-28 20:22:15,153 INFO org.apache.hadoop.yarn.server.resourcemanager.ApplicationMasterService: Registering appattempt_1377721066246_0002_000001
2013-08-28 20:22:15,154 INFO org.apache.hadoop.yarn.server.resourcemanager.rmapp.attempt.RMAppAttemptImpl: appattempt_1377721066246_0002_000001 State change from NEW to SUBMITTED
2013-08-28 20:22:15,154 INFO org.apache.hadoop.yarn.server.resourcemanager.scheduler.capacity.LeafQueue: Application application_1377721066246_0002 from user: ubuntu activated in queue: default
2013-08-28 20:22:15,154 INFO org.apache.hadoop.yarn.server.resourcemanager.scheduler.capacity.LeafQueue: Application added - appId: application_1377721066246_0002 user: org.apache.hadoop.yarn.server.resourcemanager.scheduler.capacity.LeafQueue$User@aca62b1, leaf-queue: default #user-pending-applications: 0 #user-active-applications: 1 #queue-pending-applications: 0 #queue-active-applications: 1
2013-08-28 20:22:15,155 INFO org.apache.hadoop.yarn.server.resourcemanager.scheduler.capacity.ParentQueue: Application added - appId: application_1377721066246_0002 user: ubuntu leaf-queue of parent: root #applications: 1
2013-08-28 20:22:15,155 INFO org.apache.hadoop.yarn.server.resourcemanager.scheduler.capacity.CapacityScheduler: Application Submission: appattempt_1377721066246_0002_000001, user: ubuntu queue: default: capacity=1.0, absoluteCapacity=1.0, usedResources=<memory:0, vCores:0>usedCapacity=0.0, absoluteUsedCapacity=0.0, numApps=1, numContainers=0, currently active: 1
2013-08-28 20:22:15,155 INFO org.apache.hadoop.yarn.server.resourcemanager.rmapp.attempt.RMAppAttemptImpl: appattempt_1377721066246_0002_000001 State change from SUBMITTED to SCHEDULED
2013-08-28 20:22:15,155 INFO org.apache.hadoop.yarn.server.resourcemanager.rmapp.RMAppImpl: application_1377721066246_0002 State change from SUBMITTED to ACCEPTED
2013-08-28 20:22:15,223 INFO org.apache.hadoop.yarn.server.resourcemanager.rmcontainer.RMContainerImpl: container_1377721066246_0002_01_000001 Container Transitioned from NEW to ALLOCATED
2013-08-28 20:22:15,223 INFO org.apache.hadoop.yarn.server.resourcemanager.RMAuditLogger: USER=ubuntu	OPERATION=AM Allocated Container	TARGET=SchedulerApp	RESULT=SUCCESS	APPID=application_1377721066246_0002	CONTAINERID=container_1377721066246_0002_01_000001
2013-08-28 20:22:15,223 INFO org.apache.hadoop.yarn.server.resourcemanager.scheduler.common.fica.FiCaSchedulerNode: Assigned container container_1377721066246_0002_01_000001 of capacity <memory:2048, vCores:1> on host hadoop-17-6:32933, which currently has 1 containers, <memory:2048, vCores:1> used and <memory:6144, vCores:15> available
2013-08-28 20:22:15,225 INFO org.apache.hadoop.yarn.server.resourcemanager.scheduler.capacity.LeafQueue: assignedContainer application=application_1377721066246_0002 container=Container: [ContainerId: container_1377721066246_0002_01_000001, NodeId: hadoop-17-6:32933, NodeHttpAddress: hadoop-17-6:8042, Resource: <memory:2048, vCores:1>, Priority: 0, State: NEW, Token: null, Status: container_id {, app_attempt_id {, application_id {, id: 2, cluster_timestamp: 1377721066246, }, attemptId: 1, }, id: 1, }, state: C_NEW, ] containerId=container_1377721066246_0002_01_000001 queue=default: capacity=1.0, absoluteCapacity=1.0, usedResources=<memory:0, vCores:0>usedCapacity=0.0, absoluteUsedCapacity=0.0, numApps=1, numContainers=0 usedCapacity=0.0 absoluteUsedCapacity=0.0 used=<memory:0, vCores:0> cluster=<memory:49152, vCores:96>
2013-08-28 20:22:15,225 INFO org.apache.hadoop.yarn.server.resourcemanager.scheduler.capacity.ParentQueue: Re-sorting queues since queue: root.default stats: default: capacity=1.0, absoluteCapacity=1.0, usedResources=<memory:2048, vCores:1>usedCapacity=0.041666668, absoluteUsedCapacity=0.041666668, numApps=1, numContainers=1
2013-08-28 20:22:15,227 INFO org.apache.hadoop.yarn.server.resourcemanager.scheduler.capacity.ParentQueue: assignedContainer queue=root usedCapacity=0.041666668 absoluteUsedCapacity=0.041666668 used=<memory:2048, vCores:1> cluster=<memory:49152, vCores:96>
2013-08-28 20:22:15,227 INFO org.apache.hadoop.yarn.server.resourcemanager.rmcontainer.RMContainerImpl: container_1377721066246_0002_01_000001 Container Transitioned from ALLOCATED to ACQUIRED
2013-08-28 20:22:15,230 INFO org.apache.hadoop.yarn.server.resourcemanager.rmapp.attempt.RMAppAttemptImpl: Storing attempt: AppId: application_1377721066246_0002 AttemptId: appattempt_1377721066246_0002_000001 MasterContainer: Container: [ContainerId: container_1377721066246_0002_01_000001, NodeId: hadoop-17-6:32933, NodeHttpAddress: hadoop-17-6:8042, Resource: <memory:2048, vCores:1>, Priority: 0, State: NEW, Token: null, Status: container_id {, app_attempt_id {, application_id {, id: 2, cluster_timestamp: 1377721066246, }, attemptId: 1, }, id: 1, }, state: C_NEW, ]
2013-08-28 20:22:15,230 INFO org.apache.hadoop.yarn.server.resourcemanager.recovery.RMStateStore: Storing info for attempt: appattempt_1377721066246_0002_000001
2013-08-28 20:22:15,230 INFO org.apache.hadoop.yarn.server.resourcemanager.rmapp.attempt.RMAppAttemptImpl: appattempt_1377721066246_0002_000001 State change from SCHEDULED to ALLOCATED_SAVING
2013-08-28 20:22:15,232 INFO org.apache.hadoop.yarn.server.resourcemanager.rmapp.attempt.RMAppAttemptImpl: appattempt_1377721066246_0002_000001 State change from ALLOCATED_SAVING to ALLOCATED
2013-08-28 20:22:15,233 INFO org.apache.hadoop.yarn.server.resourcemanager.amlauncher.AMLauncher: Launching masterappattempt_1377721066246_0002_000001
2013-08-28 20:22:15,236 INFO org.apache.hadoop.yarn.server.resourcemanager.amlauncher.AMLauncher: Setting up container Container: [ContainerId: container_1377721066246_0002_01_000001, NodeId: hadoop-17-6:32933, NodeHttpAddress: hadoop-17-6:8042, Resource: <memory:2048, vCores:1>, Priority: 0, State: NEW, Token: null, Status: container_id {, app_attempt_id {, application_id {, id: 2, cluster_timestamp: 1377721066246, }, attemptId: 1, }, id: 1, }, state: C_NEW, ] for AM appattempt_1377721066246_0002_000001
2013-08-28 20:22:15,236 INFO org.apache.hadoop.yarn.server.resourcemanager.amlauncher.AMLauncher: Command to launch container container_1377721066246_0002_01_000001 : $JAVA_HOME/bin/java -Dlog4j.configuration=container-log4j.properties -Dyarn.app.mapreduce.container.log.dir=<LOG_DIR> -Dyarn.app.mapreduce.container.log.filesize=0 -Dhadoop.root.logger=INFO,CLA  -Xmx1024m org.apache.hadoop.mapreduce.v2.app.MRAppMaster 1><LOG_DIR>/stdout 2><LOG_DIR>/stderr 
2013-08-28 20:22:15,264 INFO org.apache.hadoop.yarn.server.resourcemanager.amlauncher.AMLauncher: Done launching container Container: [ContainerId: container_1377721066246_0002_01_000001, NodeId: hadoop-17-6:32933, NodeHttpAddress: hadoop-17-6:8042, Resource: <memory:2048, vCores:1>, Priority: 0, State: NEW, Token: null, Status: container_id {, app_attempt_id {, application_id {, id: 2, cluster_timestamp: 1377721066246, }, attemptId: 1, }, id: 1, }, state: C_NEW, ] for AM appattempt_1377721066246_0002_000001
2013-08-28 20:22:15,264 INFO org.apache.hadoop.yarn.server.resourcemanager.rmapp.attempt.RMAppAttemptImpl: appattempt_1377721066246_0002_000001 State change from ALLOCATED to LAUNCHED
2013-08-28 20:22:16,231 INFO org.apache.hadoop.yarn.server.resourcemanager.rmcontainer.RMContainerImpl: container_1377721066246_0002_01_000001 Container Transitioned from ACQUIRED to RUNNING
2013-08-28 20:22:20,869 INFO org.apache.hadoop.yarn.server.resourcemanager.ApplicationMasterService: AM registration appattempt_1377721066246_0002_000001
2013-08-28 20:22:20,870 INFO org.apache.hadoop.yarn.server.resourcemanager.RMAuditLogger: USER=ubuntu	IP=192.168.100.38	OPERATION=Register App Master	TARGET=ApplicationMasterService	RESULT=SUCCESS	APPID=application_1377721066246_0002	APPATTEMPTID=appattempt_1377721066246_0002_000001
2013-08-28 20:22:20,877 INFO org.apache.hadoop.yarn.server.resourcemanager.rmapp.attempt.RMAppAttemptImpl: appattempt_1377721066246_0002_000001 State change from LAUNCHED to RUNNING
2013-08-28 20:22:20,878 INFO org.apache.hadoop.yarn.server.resourcemanager.rmapp.RMAppImpl: application_1377721066246_0002 State change from ACCEPTED to RUNNING
2013-08-28 20:22:21,927 INFO org.apache.hadoop.yarn.server.resourcemanager.rmcontainer.RMContainerImpl: container_1377721066246_0002_01_000002 Container Transitioned from NEW to ALLOCATED
2013-08-28 20:22:21,927 INFO org.apache.hadoop.yarn.server.resourcemanager.RMAuditLogger: USER=ubuntu	OPERATION=AM Allocated Container	TARGET=SchedulerApp	RESULT=SUCCESS	APPID=application_1377721066246_0002	CONTAINERID=container_1377721066246_0002_01_000002
2013-08-28 20:22:21,927 INFO org.apache.hadoop.yarn.server.resourcemanager.scheduler.common.fica.FiCaSchedulerNode: Assigned container container_1377721066246_0002_01_000002 of capacity <memory:1024, vCores:1> on host hadoop-17-7:49112, which currently has 1 containers, <memory:1024, vCores:1> used and <memory:7168, vCores:15> available
2013-08-28 20:22:21,929 INFO org.apache.hadoop.yarn.server.resourcemanager.scheduler.capacity.LeafQueue: assignedContainer application=application_1377721066246_0002 container=Container: [ContainerId: container_1377721066246_0002_01_000002, NodeId: hadoop-17-7:49112, NodeHttpAddress: hadoop-17-7:8042, Resource: <memory:1024, vCores:1>, Priority: 20, State: NEW, Token: null, Status: container_id {, app_attempt_id {, application_id {, id: 2, cluster_timestamp: 1377721066246, }, attemptId: 1, }, id: 2, }, state: C_NEW, ] containerId=container_1377721066246_0002_01_000002 queue=default: capacity=1.0, absoluteCapacity=1.0, usedResources=<memory:2048, vCores:1>usedCapacity=0.041666668, absoluteUsedCapacity=0.041666668, numApps=1, numContainers=1 usedCapacity=0.041666668 absoluteUsedCapacity=0.041666668 used=<memory:2048, vCores:1> cluster=<memory:49152, vCores:96>
2013-08-28 20:22:21,929 INFO org.apache.hadoop.yarn.server.resourcemanager.scheduler.capacity.ParentQueue: Re-sorting queues since queue: root.default stats: default: capacity=1.0, absoluteCapacity=1.0, usedResources=<memory:3072, vCores:2>usedCapacity=0.0625, absoluteUsedCapacity=0.0625, numApps=1, numContainers=2
2013-08-28 20:22:21,929 INFO org.apache.hadoop.yarn.server.resourcemanager.scheduler.capacity.ParentQueue: assignedContainer queue=root usedCapacity=0.0625 absoluteUsedCapacity=0.0625 used=<memory:3072, vCores:2> cluster=<memory:49152, vCores:96>
2013-08-28 20:22:21,930 INFO org.apache.hadoop.yarn.server.resourcemanager.rmcontainer.RMContainerImpl: container_1377721066246_0002_01_000003 Container Transitioned from NEW to ALLOCATED
2013-08-28 20:22:21,930 INFO org.apache.hadoop.yarn.server.resourcemanager.RMAuditLogger: USER=ubuntu	OPERATION=AM Allocated Container	TARGET=SchedulerApp	RESULT=SUCCESS	APPID=application_1377721066246_0002	CONTAINERID=container_1377721066246_0002_01_000003
2013-08-28 20:22:21,931 INFO org.apache.hadoop.yarn.server.resourcemanager.scheduler.common.fica.FiCaSchedulerNode: Assigned container container_1377721066246_0002_01_000003 of capacity <memory:1024, vCores:1> on host hadoop-17-5:46576, which currently has 1 containers, <memory:1024, vCores:1> used and <memory:7168, vCores:15> available
2013-08-28 20:22:21,932 INFO org.apache.hadoop.yarn.server.resourcemanager.scheduler.capacity.LeafQueue: assignedContainer application=application_1377721066246_0002 container=Container: [ContainerId: container_1377721066246_0002_01_000003, NodeId: hadoop-17-5:46576, NodeHttpAddress: hadoop-17-5:8042, Resource: <memory:1024, vCores:1>, Priority: 20, State: NEW, Token: null, Status: container_id {, app_attempt_id {, application_id {, id: 2, cluster_timestamp: 1377721066246, }, attemptId: 1, }, id: 3, }, state: C_NEW, ] containerId=container_1377721066246_0002_01_000003 queue=default: capacity=1.0, absoluteCapacity=1.0, usedResources=<memory:3072, vCores:2>usedCapacity=0.0625, absoluteUsedCapacity=0.0625, numApps=1, numContainers=2 usedCapacity=0.0625 absoluteUsedCapacity=0.0625 used=<memory:3072, vCores:2> cluster=<memory:49152, vCores:96>
2013-08-28 20:22:21,932 INFO org.apache.hadoop.yarn.server.resourcemanager.scheduler.capacity.ParentQueue: Re-sorting queues since queue: root.default stats: default: capacity=1.0, absoluteCapacity=1.0, usedResources=<memory:4096, vCores:3>usedCapacity=0.083333336, absoluteUsedCapacity=0.083333336, numApps=1, numContainers=3
2013-08-28 20:22:21,933 INFO org.apache.hadoop.yarn.server.resourcemanager.scheduler.capacity.ParentQueue: assignedContainer queue=root usedCapacity=0.083333336 absoluteUsedCapacity=0.083333336 used=<memory:4096, vCores:3> cluster=<memory:49152, vCores:96>
2013-08-28 20:22:22,935 INFO org.apache.hadoop.yarn.server.resourcemanager.rmcontainer.RMContainerImpl: container_1377721066246_0002_01_000002 Container Transitioned from ALLOCATED to ACQUIRED
2013-08-28 20:22:22,937 INFO org.apache.hadoop.yarn.server.resourcemanager.rmcontainer.RMContainerImpl: container_1377721066246_0002_01_000003 Container Transitioned from ALLOCATED to ACQUIRED
2013-08-28 20:22:23,982 INFO org.apache.hadoop.yarn.server.resourcemanager.scheduler.AppSchedulingInfo: checking for deactivate... 
2013-08-28 20:22:24,963 INFO org.apache.hadoop.yarn.server.resourcemanager.rmcontainer.RMContainerImpl: container_1377721066246_0002_01_000002 Container Transitioned from ACQUIRED to RUNNING
2013-08-28 20:22:24,985 INFO org.apache.hadoop.yarn.server.resourcemanager.rmcontainer.RMContainerImpl: container_1377721066246_0002_01_000003 Container Transitioned from ACQUIRED to RUNNING
2013-08-28 20:24:59,216 INFO org.apache.hadoop.yarn.server.resourcemanager.rmcontainer.RMContainerImpl: container_1377721066246_0002_01_000002 Container Transitioned from RUNNING to COMPLETED
2013-08-28 20:24:59,216 INFO org.apache.hadoop.yarn.server.resourcemanager.scheduler.common.fica.FiCaSchedulerApp: Completed container: container_1377721066246_0002_01_000002 in state: COMPLETED event:FINISHED
2013-08-28 20:24:59,216 INFO org.apache.hadoop.yarn.server.resourcemanager.RMAuditLogger: USER=ubuntu	OPERATION=AM Released Container	TARGET=SchedulerApp	RESULT=SUCCESS	APPID=application_1377721066246_0002	CONTAINERID=container_1377721066246_0002_01_000002
2013-08-28 20:24:59,217 INFO org.apache.hadoop.yarn.server.resourcemanager.scheduler.common.fica.FiCaSchedulerNode: Released container container_1377721066246_0002_01_000002 of capacity <memory:1024, vCores:1> on host hadoop-17-7:49112, which currently has 0 containers, <memory:0, vCores:0> used and <memory:8192, vCores:16> available, release resources=true
2013-08-28 20:24:59,217 INFO org.apache.hadoop.yarn.server.resourcemanager.scheduler.capacity.LeafQueue: default used=<memory:3072, vCores:2> numContainers=2 user=ubuntu user-resources=<memory:3072, vCores:2>
2013-08-28 20:24:59,231 INFO org.apache.hadoop.yarn.server.resourcemanager.scheduler.capacity.LeafQueue: completedContainer container=Container: [ContainerId: container_1377721066246_0002_01_000002, NodeId: hadoop-17-7:49112, NodeHttpAddress: hadoop-17-7:8042, Resource: <memory:1024, vCores:1>, Priority: 20, State: NEW, Token: null, Status: container_id {, app_attempt_id {, application_id {, id: 2, cluster_timestamp: 1377721066246, }, attemptId: 1, }, id: 2, }, state: C_COMPLETE, diagnostics: "Container killed by the ApplicationMaster.\n\n", exit_status: 143, ] resource=<memory:1024, vCores:1> queue=default: capacity=1.0, absoluteCapacity=1.0, usedResources=<memory:3072, vCores:2>usedCapacity=0.0625, absoluteUsedCapacity=0.0625, numApps=1, numContainers=2 usedCapacity=0.0625 absoluteUsedCapacity=0.0625 used=<memory:3072, vCores:2> cluster=<memory:49152, vCores:96>
2013-08-28 20:24:59,231 INFO org.apache.hadoop.yarn.server.resourcemanager.scheduler.capacity.ParentQueue: completedContainer queue=root usedCapacity=0.0625 absoluteUsedCapacity=0.0625 used=<memory:3072, vCores:2> cluster=<memory:49152, vCores:96>
2013-08-28 20:24:59,231 INFO org.apache.hadoop.yarn.server.resourcemanager.scheduler.capacity.CapacityScheduler: Application appattempt_1377721066246_0002_000001 released container container_1377721066246_0002_01_000002 on node: host: hadoop-17-7:49112 #containers=0 available=8192 used=0 with event: FINISHED
2013-08-28 20:25:02,691 INFO org.apache.hadoop.yarn.server.resourcemanager.rmcontainer.RMContainerImpl: container_1377721066246_0002_01_000003 Container Transitioned from RUNNING to COMPLETED
2013-08-28 20:25:02,691 INFO org.apache.hadoop.yarn.server.resourcemanager.scheduler.common.fica.FiCaSchedulerApp: Completed container: container_1377721066246_0002_01_000003 in state: COMPLETED event:FINISHED
2013-08-28 20:25:02,691 INFO org.apache.hadoop.yarn.server.resourcemanager.RMAuditLogger: USER=ubuntu	OPERATION=AM Released Container	TARGET=SchedulerApp	RESULT=SUCCESS	APPID=application_1377721066246_0002	CONTAINERID=container_1377721066246_0002_01_000003
2013-08-28 20:25:02,692 INFO org.apache.hadoop.yarn.server.resourcemanager.scheduler.common.fica.FiCaSchedulerNode: Released container container_1377721066246_0002_01_000003 of capacity <memory:1024, vCores:1> on host hadoop-17-5:46576, which currently has 0 containers, <memory:0, vCores:0> used and <memory:8192, vCores:16> available, release resources=true
2013-08-28 20:25:02,692 INFO org.apache.hadoop.yarn.server.resourcemanager.scheduler.capacity.LeafQueue: default used=<memory:2048, vCores:1> numContainers=1 user=ubuntu user-resources=<memory:2048, vCores:1>
2013-08-28 20:25:02,694 INFO org.apache.hadoop.yarn.server.resourcemanager.scheduler.capacity.LeafQueue: completedContainer container=Container: [ContainerId: container_1377721066246_0002_01_000003, NodeId: hadoop-17-5:46576, NodeHttpAddress: hadoop-17-5:8042, Resource: <memory:1024, vCores:1>, Priority: 20, State: NEW, Token: null, Status: container_id {, app_attempt_id {, application_id {, id: 2, cluster_timestamp: 1377721066246, }, attemptId: 1, }, id: 3, }, state: C_COMPLETE, diagnostics: "Container killed by the ApplicationMaster.\n\n", exit_status: 143, ] resource=<memory:1024, vCores:1> queue=default: capacity=1.0, absoluteCapacity=1.0, usedResources=<memory:2048, vCores:1>usedCapacity=0.041666668, absoluteUsedCapacity=0.041666668, numApps=1, numContainers=1 usedCapacity=0.041666668 absoluteUsedCapacity=0.041666668 used=<memory:2048, vCores:1> cluster=<memory:49152, vCores:96>
2013-08-28 20:25:02,694 INFO org.apache.hadoop.yarn.server.resourcemanager.scheduler.capacity.ParentQueue: completedContainer queue=root usedCapacity=0.041666668 absoluteUsedCapacity=0.041666668 used=<memory:2048, vCores:1> cluster=<memory:49152, vCores:96>
2013-08-28 20:25:02,694 INFO org.apache.hadoop.yarn.server.resourcemanager.scheduler.capacity.CapacityScheduler: Application appattempt_1377721066246_0002_000001 released container container_1377721066246_0002_01_000003 on node: host: hadoop-17-5:46576 #containers=0 available=8192 used=0 with event: FINISHED
2013-08-28 20:25:06,842 INFO org.apache.hadoop.yarn.server.resourcemanager.rmapp.attempt.RMAppAttemptImpl: appattempt_1377721066246_0002_000001 State change from RUNNING to FINISHING
2013-08-28 20:25:06,843 INFO org.apache.hadoop.yarn.server.resourcemanager.rmapp.RMAppImpl: application_1377721066246_0002 State change from RUNNING to FINISHING
2013-08-28 20:25:07,908 INFO org.apache.hadoop.yarn.server.resourcemanager.rmcontainer.RMContainerImpl: container_1377721066246_0002_01_000001 Container Transitioned from RUNNING to COMPLETED
2013-08-28 20:25:07,908 INFO org.apache.hadoop.yarn.server.resourcemanager.scheduler.common.fica.FiCaSchedulerApp: Completed container: container_1377721066246_0002_01_000001 in state: COMPLETED event:FINISHED
2013-08-28 20:25:07,908 INFO org.apache.hadoop.yarn.server.resourcemanager.rmapp.attempt.RMAppAttemptImpl: appattempt_1377721066246_0002_000001 State change from FINISHING to FINISHED
2013-08-28 20:25:07,910 INFO org.apache.hadoop.yarn.server.resourcemanager.RMAuditLogger: USER=ubuntu	OPERATION=AM Released Container	TARGET=SchedulerApp	RESULT=SUCCESS	APPID=application_1377721066246_0002	CONTAINERID=container_1377721066246_0002_01_000001
2013-08-28 20:25:07,910 INFO org.apache.hadoop.yarn.server.resourcemanager.rmapp.RMAppImpl: application_1377721066246_0002 State change from FINISHING to FINISHED
2013-08-28 20:25:07,910 INFO org.apache.hadoop.yarn.server.resourcemanager.scheduler.common.fica.FiCaSchedulerNode: Released container container_1377721066246_0002_01_000001 of capacity <memory:2048, vCores:1> on host hadoop-17-6:32933, which currently has 0 containers, <memory:0, vCores:0> used and <memory:8192, vCores:16> available, release resources=true
2013-08-28 20:25:07,911 INFO org.apache.hadoop.yarn.server.resourcemanager.scheduler.capacity.LeafQueue: default used=<memory:0, vCores:0> numContainers=0 user=ubuntu user-resources=<memory:0, vCores:0>
2013-08-28 20:25:07,911 INFO org.apache.hadoop.yarn.server.resourcemanager.RMAuditLogger: USER=ubuntu	OPERATION=Application Finished - Succeeded	TARGET=RMAppManager	RESULT=SUCCESS	APPID=application_1377721066246_0002
2013-08-28 20:25:07,911 INFO org.apache.hadoop.yarn.server.resourcemanager.recovery.RMStateStore: Removing info for app: application_1377721066246_0002
2013-08-28 20:25:07,911 INFO org.apache.hadoop.yarn.server.resourcemanager.RMAppManager$ApplicationSummary: appId=application_1377721066246_0002,name=TeraGen,user=ubuntu,queue=default,state=FINISHED,trackingUrl=hadoop-17-1.novalocal:8088/proxy/application_1377721066246_0002/jobhistory/job/job_1377721066246_0002,appMasterHost=hadoop-17-6,startTime=1377721335148,finishTime=1377721506843
2013-08-28 20:25:07,912 INFO org.apache.hadoop.yarn.server.resourcemanager.amlauncher.AMLauncher: Cleaning master appattempt_1377721066246_0002_000001
2013-08-28 20:25:07,912 INFO org.apache.hadoop.yarn.server.resourcemanager.scheduler.capacity.LeafQueue: completedContainer container=Container: [ContainerId: container_1377721066246_0002_01_000001, NodeId: hadoop-17-6:32933, NodeHttpAddress: hadoop-17-6:8042, Resource: <memory:2048, vCores:1>, Priority: 0, State: NEW, Token: null, Status: container_id {, app_attempt_id {, application_id {, id: 2, cluster_timestamp: 1377721066246, }, attemptId: 1, }, id: 1, }, state: C_COMPLETE, diagnostics: "", exit_status: 0, ] resource=<memory:2048, vCores:1> queue=default: capacity=1.0, absoluteCapacity=1.0, usedResources=<memory:0, vCores:0>usedCapacity=0.0, absoluteUsedCapacity=0.0, numApps=1, numContainers=0 usedCapacity=0.0 absoluteUsedCapacity=0.0 used=<memory:0, vCores:0> cluster=<memory:49152, vCores:96>
2013-08-28 20:25:07,913 INFO org.apache.hadoop.yarn.server.resourcemanager.scheduler.capacity.ParentQueue: completedContainer queue=root usedCapacity=0.0 absoluteUsedCapacity=0.0 used=<memory:0, vCores:0> cluster=<memory:49152, vCores:96>
2013-08-28 20:25:07,913 INFO org.apache.hadoop.yarn.server.resourcemanager.scheduler.capacity.CapacityScheduler: Application appattempt_1377721066246_0002_000001 released container container_1377721066246_0002_01_000001 on node: host: hadoop-17-6:32933 #containers=0 available=8192 used=0 with event: FINISHED
2013-08-28 20:25:07,913 INFO org.apache.hadoop.yarn.server.resourcemanager.scheduler.capacity.CapacityScheduler: Application appattempt_1377721066246_0002_000001 is done. finalState=FINISHED
2013-08-28 20:25:07,913 INFO org.apache.hadoop.yarn.server.resourcemanager.scheduler.AppSchedulingInfo: Application application_1377721066246_0002 requests cleared
2013-08-28 20:25:07,913 INFO org.apache.hadoop.yarn.server.resourcemanager.scheduler.capacity.LeafQueue: Application removed - appId: application_1377721066246_0002 user: ubuntu queue: default #user-pending-applications: 0 #user-active-applications: 0 #queue-pending-applications: 0 #queue-active-applications: 0
2013-08-28 20:25:07,914 INFO org.apache.hadoop.yarn.server.resourcemanager.scheduler.capacity.ParentQueue: Application removed - appId: application_1377721066246_0002 user: ubuntu leaf-queue of parent: root #applications: 0
2013-08-28 20:25:12,968 INFO org.apache.hadoop.yarn.server.resourcemanager.ClientRMService: Allocated new applicationId: 3
2013-08-28 20:25:14,854 INFO org.apache.hadoop.yarn.server.resourcemanager.ClientRMService: Storing Application with id application_1377721066246_0003
2013-08-28 20:25:14,854 INFO org.apache.hadoop.yarn.server.resourcemanager.recovery.RMStateStore: Storing info for app: application_1377721066246_0003
2013-08-28 20:25:14,854 INFO org.apache.hadoop.yarn.server.resourcemanager.ClientRMService: Application with id 3 submitted by user ubuntu
2013-08-28 20:25:14,854 INFO org.apache.hadoop.yarn.server.resourcemanager.RMAuditLogger: USER=ubuntu	IP=192.168.100.34	OPERATION=Submit Application Request	TARGET=ClientRMService	RESULT=SUCCESS	APPID=application_1377721066246_0003
2013-08-28 20:25:14,856 INFO org.apache.hadoop.yarn.server.resourcemanager.rmapp.RMAppImpl: application_1377721066246_0003 State change from NEW to SUBMITTED
2013-08-28 20:25:14,856 INFO org.apache.hadoop.yarn.server.resourcemanager.ApplicationMasterService: Registering appattempt_1377721066246_0003_000001
2013-08-28 20:25:14,856 INFO org.apache.hadoop.yarn.server.resourcemanager.rmapp.attempt.RMAppAttemptImpl: appattempt_1377721066246_0003_000001 State change from NEW to SUBMITTED
2013-08-28 20:25:14,857 INFO org.apache.hadoop.yarn.server.resourcemanager.scheduler.capacity.LeafQueue: Application application_1377721066246_0003 from user: ubuntu activated in queue: default
2013-08-28 20:25:14,857 INFO org.apache.hadoop.yarn.server.resourcemanager.scheduler.capacity.LeafQueue: Application added - appId: application_1377721066246_0003 user: org.apache.hadoop.yarn.server.resourcemanager.scheduler.capacity.LeafQueue$User@4f0a9c28, leaf-queue: default #user-pending-applications: 0 #user-active-applications: 1 #queue-pending-applications: 0 #queue-active-applications: 1
2013-08-28 20:25:14,857 INFO org.apache.hadoop.yarn.server.resourcemanager.scheduler.capacity.ParentQueue: Application added - appId: application_1377721066246_0003 user: ubuntu leaf-queue of parent: root #applications: 1
2013-08-28 20:25:14,858 INFO org.apache.hadoop.yarn.server.resourcemanager.scheduler.capacity.CapacityScheduler: Application Submission: appattempt_1377721066246_0003_000001, user: ubuntu queue: default: capacity=1.0, absoluteCapacity=1.0, usedResources=<memory:0, vCores:0>usedCapacity=0.0, absoluteUsedCapacity=0.0, numApps=1, numContainers=0, currently active: 1
2013-08-28 20:25:14,858 INFO org.apache.hadoop.yarn.server.resourcemanager.rmapp.attempt.RMAppAttemptImpl: appattempt_1377721066246_0003_000001 State change from SUBMITTED to SCHEDULED
2013-08-28 20:25:14,858 INFO org.apache.hadoop.yarn.server.resourcemanager.rmapp.RMAppImpl: application_1377721066246_0003 State change from SUBMITTED to ACCEPTED
2013-08-28 20:25:14,932 INFO org.apache.hadoop.yarn.server.resourcemanager.rmcontainer.RMContainerImpl: container_1377721066246_0003_01_000001 Container Transitioned from NEW to ALLOCATED
2013-08-28 20:25:14,932 INFO org.apache.hadoop.yarn.server.resourcemanager.RMAuditLogger: USER=ubuntu	OPERATION=AM Allocated Container	TARGET=SchedulerApp	RESULT=SUCCESS	APPID=application_1377721066246_0003	CONTAINERID=container_1377721066246_0003_01_000001
2013-08-28 20:25:14,933 INFO org.apache.hadoop.yarn.server.resourcemanager.scheduler.common.fica.FiCaSchedulerNode: Assigned container container_1377721066246_0003_01_000001 of capacity <memory:2048, vCores:1> on host hadoop-17-6:32933, which currently has 1 containers, <memory:2048, vCores:1> used and <memory:6144, vCores:15> available
2013-08-28 20:25:14,934 INFO org.apache.hadoop.yarn.server.resourcemanager.scheduler.capacity.LeafQueue: assignedContainer application=application_1377721066246_0003 container=Container: [ContainerId: container_1377721066246_0003_01_000001, NodeId: hadoop-17-6:32933, NodeHttpAddress: hadoop-17-6:8042, Resource: <memory:2048, vCores:1>, Priority: 0, State: NEW, Token: null, Status: container_id {, app_attempt_id {, application_id {, id: 3, cluster_timestamp: 1377721066246, }, attemptId: 1, }, id: 1, }, state: C_NEW, ] containerId=container_1377721066246_0003_01_000001 queue=default: capacity=1.0, absoluteCapacity=1.0, usedResources=<memory:0, vCores:0>usedCapacity=0.0, absoluteUsedCapacity=0.0, numApps=1, numContainers=0 usedCapacity=0.0 absoluteUsedCapacity=0.0 used=<memory:0, vCores:0> cluster=<memory:49152, vCores:96>
2013-08-28 20:25:14,934 INFO org.apache.hadoop.yarn.server.resourcemanager.scheduler.capacity.ParentQueue: Re-sorting queues since queue: root.default stats: default: capacity=1.0, absoluteCapacity=1.0, usedResources=<memory:2048, vCores:1>usedCapacity=0.041666668, absoluteUsedCapacity=0.041666668, numApps=1, numContainers=1
2013-08-28 20:25:14,935 INFO org.apache.hadoop.yarn.server.resourcemanager.scheduler.capacity.ParentQueue: assignedContainer queue=root usedCapacity=0.041666668 absoluteUsedCapacity=0.041666668 used=<memory:2048, vCores:1> cluster=<memory:49152, vCores:96>
2013-08-28 20:25:14,937 INFO org.apache.hadoop.yarn.server.resourcemanager.rmcontainer.RMContainerImpl: container_1377721066246_0003_01_000001 Container Transitioned from ALLOCATED to ACQUIRED
2013-08-28 20:25:14,938 INFO org.apache.hadoop.yarn.server.resourcemanager.rmapp.attempt.RMAppAttemptImpl: Storing attempt: AppId: application_1377721066246_0003 AttemptId: appattempt_1377721066246_0003_000001 MasterContainer: Container: [ContainerId: container_1377721066246_0003_01_000001, NodeId: hadoop-17-6:32933, NodeHttpAddress: hadoop-17-6:8042, Resource: <memory:2048, vCores:1>, Priority: 0, State: NEW, Token: null, Status: container_id {, app_attempt_id {, application_id {, id: 3, cluster_timestamp: 1377721066246, }, attemptId: 1, }, id: 1, }, state: C_NEW, ]
2013-08-28 20:25:14,939 INFO org.apache.hadoop.yarn.server.resourcemanager.rmapp.attempt.RMAppAttemptImpl: appattempt_1377721066246_0003_000001 State change from SCHEDULED to ALLOCATED_SAVING
2013-08-28 20:25:14,939 INFO org.apache.hadoop.yarn.server.resourcemanager.recovery.RMStateStore: Storing info for attempt: appattempt_1377721066246_0003_000001
2013-08-28 20:25:14,940 INFO org.apache.hadoop.yarn.server.resourcemanager.rmapp.attempt.RMAppAttemptImpl: appattempt_1377721066246_0003_000001 State change from ALLOCATED_SAVING to ALLOCATED
2013-08-28 20:25:14,942 INFO org.apache.hadoop.yarn.server.resourcemanager.amlauncher.AMLauncher: Launching masterappattempt_1377721066246_0003_000001
2013-08-28 20:25:14,945 INFO org.apache.hadoop.yarn.server.resourcemanager.amlauncher.AMLauncher: Setting up container Container: [ContainerId: container_1377721066246_0003_01_000001, NodeId: hadoop-17-6:32933, NodeHttpAddress: hadoop-17-6:8042, Resource: <memory:2048, vCores:1>, Priority: 0, State: NEW, Token: null, Status: container_id {, app_attempt_id {, application_id {, id: 3, cluster_timestamp: 1377721066246, }, attemptId: 1, }, id: 1, }, state: C_NEW, ] for AM appattempt_1377721066246_0003_000001
2013-08-28 20:25:14,946 INFO org.apache.hadoop.yarn.server.resourcemanager.amlauncher.AMLauncher: Command to launch container container_1377721066246_0003_01_000001 : $JAVA_HOME/bin/java -Dlog4j.configuration=container-log4j.properties -Dyarn.app.mapreduce.container.log.dir=<LOG_DIR> -Dyarn.app.mapreduce.container.log.filesize=0 -Dhadoop.root.logger=INFO,CLA  -Xmx1024m org.apache.hadoop.mapreduce.v2.app.MRAppMaster 1><LOG_DIR>/stdout 2><LOG_DIR>/stderr 
2013-08-28 20:25:14,964 INFO org.apache.hadoop.yarn.server.resourcemanager.amlauncher.AMLauncher: Done launching container Container: [ContainerId: container_1377721066246_0003_01_000001, NodeId: hadoop-17-6:32933, NodeHttpAddress: hadoop-17-6:8042, Resource: <memory:2048, vCores:1>, Priority: 0, State: NEW, Token: null, Status: container_id {, app_attempt_id {, application_id {, id: 3, cluster_timestamp: 1377721066246, }, attemptId: 1, }, id: 1, }, state: C_NEW, ] for AM appattempt_1377721066246_0003_000001
2013-08-28 20:25:14,965 INFO org.apache.hadoop.yarn.server.resourcemanager.rmapp.attempt.RMAppAttemptImpl: appattempt_1377721066246_0003_000001 State change from ALLOCATED to LAUNCHED
2013-08-28 20:25:15,942 INFO org.apache.hadoop.yarn.server.resourcemanager.rmcontainer.RMContainerImpl: container_1377721066246_0003_01_000001 Container Transitioned from ACQUIRED to RUNNING
2013-08-28 20:25:20,369 INFO org.apache.hadoop.yarn.server.resourcemanager.ApplicationMasterService: AM registration appattempt_1377721066246_0003_000001
2013-08-28 20:25:20,370 INFO org.apache.hadoop.yarn.server.resourcemanager.RMAuditLogger: USER=ubuntu	IP=192.168.100.38	OPERATION=Register App Master	TARGET=ApplicationMasterService	RESULT=SUCCESS	APPID=application_1377721066246_0003	APPATTEMPTID=appattempt_1377721066246_0003_000001
2013-08-28 20:25:20,371 INFO org.apache.hadoop.yarn.server.resourcemanager.rmapp.attempt.RMAppAttemptImpl: appattempt_1377721066246_0003_000001 State change from LAUNCHED to RUNNING
2013-08-28 20:25:20,371 INFO org.apache.hadoop.yarn.server.resourcemanager.rmapp.RMAppImpl: application_1377721066246_0003 State change from ACCEPTED to RUNNING
2013-08-28 20:25:21,615 INFO org.apache.hadoop.yarn.server.resourcemanager.rmcontainer.RMContainerImpl: container_1377721066246_0003_01_000002 Container Transitioned from NEW to ALLOCATED
2013-08-28 20:25:21,615 INFO org.apache.hadoop.yarn.server.resourcemanager.RMAuditLogger: USER=ubuntu	OPERATION=AM Allocated Container	TARGET=SchedulerApp	RESULT=SUCCESS	APPID=application_1377721066246_0003	CONTAINERID=container_1377721066246_0003_01_000002
2013-08-28 20:25:21,616 INFO org.apache.hadoop.yarn.server.resourcemanager.scheduler.common.fica.FiCaSchedulerNode: Assigned container container_1377721066246_0003_01_000002 of capacity <memory:1024, vCores:1> on host hadoop-17-2:52914, which currently has 1 containers, <memory:1024, vCores:1> used and <memory:7168, vCores:15> available
2013-08-28 20:25:21,617 INFO org.apache.hadoop.yarn.server.resourcemanager.scheduler.capacity.LeafQueue: assignedContainer application=application_1377721066246_0003 container=Container: [ContainerId: container_1377721066246_0003_01_000002, NodeId: hadoop-17-2:52914, NodeHttpAddress: hadoop-17-2:8042, Resource: <memory:1024, vCores:1>, Priority: 20, State: NEW, Token: null, Status: container_id {, app_attempt_id {, application_id {, id: 3, cluster_timestamp: 1377721066246, }, attemptId: 1, }, id: 2, }, state: C_NEW, ] containerId=container_1377721066246_0003_01_000002 queue=default: capacity=1.0, absoluteCapacity=1.0, usedResources=<memory:2048, vCores:1>usedCapacity=0.041666668, absoluteUsedCapacity=0.041666668, numApps=1, numContainers=1 usedCapacity=0.041666668 absoluteUsedCapacity=0.041666668 used=<memory:2048, vCores:1> cluster=<memory:49152, vCores:96>
2013-08-28 20:25:21,618 INFO org.apache.hadoop.yarn.server.resourcemanager.scheduler.capacity.ParentQueue: Re-sorting queues since queue: root.default stats: default: capacity=1.0, absoluteCapacity=1.0, usedResources=<memory:3072, vCores:2>usedCapacity=0.0625, absoluteUsedCapacity=0.0625, numApps=1, numContainers=2
2013-08-28 20:25:21,618 INFO org.apache.hadoop.yarn.server.resourcemanager.scheduler.capacity.ParentQueue: assignedContainer queue=root usedCapacity=0.0625 absoluteUsedCapacity=0.0625 used=<memory:3072, vCores:2> cluster=<memory:49152, vCores:96>
2013-08-28 20:25:21,713 INFO org.apache.hadoop.yarn.server.resourcemanager.rmcontainer.RMContainerImpl: container_1377721066246_0003_01_000003 Container Transitioned from NEW to ALLOCATED
2013-08-28 20:25:21,713 INFO org.apache.hadoop.yarn.server.resourcemanager.RMAuditLogger: USER=ubuntu	OPERATION=AM Allocated Container	TARGET=SchedulerApp	RESULT=SUCCESS	APPID=application_1377721066246_0003	CONTAINERID=container_1377721066246_0003_01_000003
2013-08-28 20:25:21,713 INFO org.apache.hadoop.yarn.server.resourcemanager.scheduler.common.fica.FiCaSchedulerNode: Assigned container container_1377721066246_0003_01_000003 of capacity <memory:1024, vCores:1> on host hadoop-17-3:35481, which currently has 1 containers, <memory:1024, vCores:1> used and <memory:7168, vCores:15> available
2013-08-28 20:25:21,715 INFO org.apache.hadoop.yarn.server.resourcemanager.scheduler.capacity.LeafQueue: assignedContainer application=application_1377721066246_0003 container=Container: [ContainerId: container_1377721066246_0003_01_000003, NodeId: hadoop-17-3:35481, NodeHttpAddress: hadoop-17-3:8042, Resource: <memory:1024, vCores:1>, Priority: 20, State: NEW, Token: null, Status: container_id {, app_attempt_id {, application_id {, id: 3, cluster_timestamp: 1377721066246, }, attemptId: 1, }, id: 3, }, state: C_NEW, ] containerId=container_1377721066246_0003_01_000003 queue=default: capacity=1.0, absoluteCapacity=1.0, usedResources=<memory:3072, vCores:2>usedCapacity=0.0625, absoluteUsedCapacity=0.0625, numApps=1, numContainers=2 usedCapacity=0.0625 absoluteUsedCapacity=0.0625 used=<memory:3072, vCores:2> cluster=<memory:49152, vCores:96>
2013-08-28 20:25:21,715 INFO org.apache.hadoop.yarn.server.resourcemanager.scheduler.capacity.ParentQueue: Re-sorting queues since queue: root.default stats: default: capacity=1.0, absoluteCapacity=1.0, usedResources=<memory:4096, vCores:3>usedCapacity=0.083333336, absoluteUsedCapacity=0.083333336, numApps=1, numContainers=3
2013-08-28 20:25:21,715 INFO org.apache.hadoop.yarn.server.resourcemanager.scheduler.capacity.ParentQueue: assignedContainer queue=root usedCapacity=0.083333336 absoluteUsedCapacity=0.083333336 used=<memory:4096, vCores:3> cluster=<memory:49152, vCores:96>
2013-08-28 20:25:22,435 INFO org.apache.hadoop.yarn.server.resourcemanager.rmcontainer.RMContainerImpl: container_1377721066246_0003_01_000002 Container Transitioned from ALLOCATED to ACQUIRED
2013-08-28 20:25:22,437 INFO org.apache.hadoop.yarn.server.resourcemanager.rmcontainer.RMContainerImpl: container_1377721066246_0003_01_000003 Container Transitioned from ALLOCATED to ACQUIRED
2013-08-28 20:25:23,466 INFO org.apache.hadoop.yarn.server.resourcemanager.scheduler.AppSchedulingInfo: checking for deactivate... 
2013-08-28 20:25:23,625 INFO org.apache.hadoop.yarn.server.resourcemanager.rmcontainer.RMContainerImpl: container_1377721066246_0003_01_000002 Container Transitioned from ACQUIRED to RUNNING
2013-08-28 20:25:23,842 INFO org.apache.hadoop.yarn.server.resourcemanager.rmcontainer.RMContainerImpl: container_1377721066246_0003_01_000003 Container Transitioned from ACQUIRED to RUNNING
2013-08-28 20:28:11,423 INFO org.apache.hadoop.yarn.server.resourcemanager.rmcontainer.RMContainerImpl: container_1377721066246_0003_01_000002 Container Transitioned from RUNNING to COMPLETED
2013-08-28 20:28:11,423 INFO org.apache.hadoop.yarn.server.resourcemanager.scheduler.common.fica.FiCaSchedulerApp: Completed container: container_1377721066246_0003_01_000002 in state: COMPLETED event:FINISHED
2013-08-28 20:28:11,423 INFO org.apache.hadoop.yarn.server.resourcemanager.RMAuditLogger: USER=ubuntu	OPERATION=AM Released Container	TARGET=SchedulerApp	RESULT=SUCCESS	APPID=application_1377721066246_0003	CONTAINERID=container_1377721066246_0003_01_000002
2013-08-28 20:28:11,424 INFO org.apache.hadoop.yarn.server.resourcemanager.scheduler.common.fica.FiCaSchedulerNode: Released container container_1377721066246_0003_01_000002 of capacity <memory:1024, vCores:1> on host hadoop-17-2:52914, which currently has 0 containers, <memory:0, vCores:0> used and <memory:8192, vCores:16> available, release resources=true
2013-08-28 20:28:11,424 INFO org.apache.hadoop.yarn.server.resourcemanager.scheduler.capacity.LeafQueue: default used=<memory:3072, vCores:2> numContainers=2 user=ubuntu user-resources=<memory:3072, vCores:2>
2013-08-28 20:28:11,426 INFO org.apache.hadoop.yarn.server.resourcemanager.scheduler.capacity.LeafQueue: completedContainer container=Container: [ContainerId: container_1377721066246_0003_01_000002, NodeId: hadoop-17-2:52914, NodeHttpAddress: hadoop-17-2:8042, Resource: <memory:1024, vCores:1>, Priority: 20, State: NEW, Token: null, Status: container_id {, app_attempt_id {, application_id {, id: 3, cluster_timestamp: 1377721066246, }, attemptId: 1, }, id: 2, }, state: C_COMPLETE, diagnostics: "Container killed by the ApplicationMaster.\n", exit_status: 0, ] resource=<memory:1024, vCores:1> queue=default: capacity=1.0, absoluteCapacity=1.0, usedResources=<memory:3072, vCores:2>usedCapacity=0.0625, absoluteUsedCapacity=0.0625, numApps=1, numContainers=2 usedCapacity=0.0625 absoluteUsedCapacity=0.0625 used=<memory:3072, vCores:2> cluster=<memory:49152, vCores:96>
2013-08-28 20:28:11,426 INFO org.apache.hadoop.yarn.server.resourcemanager.scheduler.capacity.ParentQueue: completedContainer queue=root usedCapacity=0.0625 absoluteUsedCapacity=0.0625 used=<memory:3072, vCores:2> cluster=<memory:49152, vCores:96>
2013-08-28 20:28:11,426 INFO org.apache.hadoop.yarn.server.resourcemanager.scheduler.capacity.CapacityScheduler: Application appattempt_1377721066246_0003_000001 released container container_1377721066246_0003_01_000002 on node: host: hadoop-17-2:52914 #containers=0 available=8192 used=0 with event: FINISHED
2013-08-28 20:28:17,170 INFO org.apache.hadoop.yarn.server.resourcemanager.rmcontainer.RMContainerImpl: container_1377721066246_0003_01_000003 Container Transitioned from RUNNING to COMPLETED
2013-08-28 20:28:17,170 INFO org.apache.hadoop.yarn.server.resourcemanager.scheduler.common.fica.FiCaSchedulerApp: Completed container: container_1377721066246_0003_01_000003 in state: COMPLETED event:FINISHED
2013-08-28 20:28:17,172 INFO org.apache.hadoop.yarn.server.resourcemanager.RMAuditLogger: USER=ubuntu	OPERATION=AM Released Container	TARGET=SchedulerApp	RESULT=SUCCESS	APPID=application_1377721066246_0003	CONTAINERID=container_1377721066246_0003_01_000003
2013-08-28 20:28:17,172 INFO org.apache.hadoop.yarn.server.resourcemanager.scheduler.common.fica.FiCaSchedulerNode: Released container container_1377721066246_0003_01_000003 of capacity <memory:1024, vCores:1> on host hadoop-17-3:35481, which currently has 0 containers, <memory:0, vCores:0> used and <memory:8192, vCores:16> available, release resources=true
2013-08-28 20:28:17,172 INFO org.apache.hadoop.yarn.server.resourcemanager.scheduler.capacity.LeafQueue: default used=<memory:2048, vCores:1> numContainers=1 user=ubuntu user-resources=<memory:2048, vCores:1>
2013-08-28 20:28:17,174 INFO org.apache.hadoop.yarn.server.resourcemanager.scheduler.capacity.LeafQueue: completedContainer container=Container: [ContainerId: container_1377721066246_0003_01_000003, NodeId: hadoop-17-3:35481, NodeHttpAddress: hadoop-17-3:8042, Resource: <memory:1024, vCores:1>, Priority: 20, State: NEW, Token: null, Status: container_id {, app_attempt_id {, application_id {, id: 3, cluster_timestamp: 1377721066246, }, attemptId: 1, }, id: 3, }, state: C_COMPLETE, diagnostics: "Container killed by the ApplicationMaster.\n\n", exit_status: 143, ] resource=<memory:1024, vCores:1> queue=default: capacity=1.0, absoluteCapacity=1.0, usedResources=<memory:2048, vCores:1>usedCapacity=0.041666668, absoluteUsedCapacity=0.041666668, numApps=1, numContainers=1 usedCapacity=0.041666668 absoluteUsedCapacity=0.041666668 used=<memory:2048, vCores:1> cluster=<memory:49152, vCores:96>
2013-08-28 20:28:17,174 INFO org.apache.hadoop.yarn.server.resourcemanager.scheduler.capacity.ParentQueue: completedContainer queue=root usedCapacity=0.041666668 absoluteUsedCapacity=0.041666668 used=<memory:2048, vCores:1> cluster=<memory:49152, vCores:96>
2013-08-28 20:28:17,174 INFO org.apache.hadoop.yarn.server.resourcemanager.scheduler.capacity.CapacityScheduler: Application appattempt_1377721066246_0003_000001 released container container_1377721066246_0003_01_000003 on node: host: hadoop-17-3:35481 #containers=0 available=8192 used=0 with event: FINISHED
2013-08-28 20:28:21,333 INFO org.apache.hadoop.yarn.server.resourcemanager.rmapp.attempt.RMAppAttemptImpl: appattempt_1377721066246_0003_000001 State change from RUNNING to FINISHING
2013-08-28 20:28:21,334 INFO org.apache.hadoop.yarn.server.resourcemanager.rmapp.RMAppImpl: application_1377721066246_0003 State change from RUNNING to FINISHING
2013-08-28 20:28:22,121 INFO org.apache.hadoop.yarn.server.resourcemanager.rmcontainer.RMContainerImpl: container_1377721066246_0003_01_000001 Container Transitioned from RUNNING to COMPLETED
2013-08-28 20:28:22,121 INFO org.apache.hadoop.yarn.server.resourcemanager.scheduler.common.fica.FiCaSchedulerApp: Completed container: container_1377721066246_0003_01_000001 in state: COMPLETED event:FINISHED
2013-08-28 20:28:22,121 INFO org.apache.hadoop.yarn.server.resourcemanager.RMAuditLogger: USER=ubuntu	OPERATION=AM Released Container	TARGET=SchedulerApp	RESULT=SUCCESS	APPID=application_1377721066246_0003	CONTAINERID=container_1377721066246_0003_01_000001
2013-08-28 20:28:22,121 INFO org.apache.hadoop.yarn.server.resourcemanager.scheduler.common.fica.FiCaSchedulerNode: Released container container_1377721066246_0003_01_000001 of capacity <memory:2048, vCores:1> on host hadoop-17-6:32933, which currently has 0 containers, <memory:0, vCores:0> used and <memory:8192, vCores:16> available, release resources=true
2013-08-28 20:28:22,121 INFO org.apache.hadoop.yarn.server.resourcemanager.scheduler.capacity.LeafQueue: default used=<memory:0, vCores:0> numContainers=0 user=ubuntu user-resources=<memory:0, vCores:0>
2013-08-28 20:28:22,123 INFO org.apache.hadoop.yarn.server.resourcemanager.scheduler.capacity.LeafQueue: completedContainer container=Container: [ContainerId: container_1377721066246_0003_01_000001, NodeId: hadoop-17-6:32933, NodeHttpAddress: hadoop-17-6:8042, Resource: <memory:2048, vCores:1>, Priority: 0, State: NEW, Token: null, Status: container_id {, app_attempt_id {, application_id {, id: 3, cluster_timestamp: 1377721066246, }, attemptId: 1, }, id: 1, }, state: C_COMPLETE, diagnostics: "", exit_status: 0, ] resource=<memory:2048, vCores:1> queue=default: capacity=1.0, absoluteCapacity=1.0, usedResources=<memory:0, vCores:0>usedCapacity=0.0, absoluteUsedCapacity=0.0, numApps=1, numContainers=0 usedCapacity=0.0 absoluteUsedCapacity=0.0 used=<memory:0, vCores:0> cluster=<memory:49152, vCores:96>
2013-08-28 20:28:22,123 INFO org.apache.hadoop.yarn.server.resourcemanager.scheduler.capacity.ParentQueue: completedContainer queue=root usedCapacity=0.0 absoluteUsedCapacity=0.0 used=<memory:0, vCores:0> cluster=<memory:49152, vCores:96>
2013-08-28 20:28:22,123 INFO org.apache.hadoop.yarn.server.resourcemanager.scheduler.capacity.CapacityScheduler: Application appattempt_1377721066246_0003_000001 released container container_1377721066246_0003_01_000001 on node: host: hadoop-17-6:32933 #containers=0 available=8192 used=0 with event: FINISHED
2013-08-28 20:28:22,124 INFO org.apache.hadoop.yarn.server.resourcemanager.rmapp.attempt.RMAppAttemptImpl: appattempt_1377721066246_0003_000001 State change from FINISHING to FINISHED
2013-08-28 20:28:22,124 INFO org.apache.hadoop.yarn.server.resourcemanager.rmapp.RMAppImpl: application_1377721066246_0003 State change from FINISHING to FINISHED
2013-08-28 20:28:22,125 INFO org.apache.hadoop.yarn.server.resourcemanager.RMAuditLogger: USER=ubuntu	OPERATION=Application Finished - Succeeded	TARGET=RMAppManager	RESULT=SUCCESS	APPID=application_1377721066246_0003
2013-08-28 20:28:22,126 INFO org.apache.hadoop.yarn.server.resourcemanager.recovery.RMStateStore: Removing info for app: application_1377721066246_0003
2013-08-28 20:28:22,126 INFO org.apache.hadoop.yarn.server.resourcemanager.amlauncher.AMLauncher: Cleaning master appattempt_1377721066246_0003_000001
2013-08-28 20:28:22,126 INFO org.apache.hadoop.yarn.server.resourcemanager.RMAppManager$ApplicationSummary: appId=application_1377721066246_0003,name=TeraGen,user=ubuntu,queue=default,state=FINISHED,trackingUrl=hadoop-17-1.novalocal:8088/proxy/application_1377721066246_0003/jobhistory/job/job_1377721066246_0003,appMasterHost=hadoop-17-6,startTime=1377721514853,finishTime=1377721701334
2013-08-28 20:28:22,126 INFO org.apache.hadoop.yarn.server.resourcemanager.scheduler.capacity.CapacityScheduler: Application appattempt_1377721066246_0003_000001 is done. finalState=FINISHED
2013-08-28 20:28:22,126 INFO org.apache.hadoop.yarn.server.resourcemanager.scheduler.AppSchedulingInfo: Application application_1377721066246_0003 requests cleared
2013-08-28 20:28:22,126 INFO org.apache.hadoop.yarn.server.resourcemanager.scheduler.capacity.LeafQueue: Application removed - appId: application_1377721066246_0003 user: ubuntu queue: default #user-pending-applications: 0 #user-active-applications: 0 #queue-pending-applications: 0 #queue-active-applications: 0
2013-08-28 20:28:22,126 INFO org.apache.hadoop.yarn.server.resourcemanager.scheduler.capacity.ParentQueue: Application removed - appId: application_1377721066246_0003 user: ubuntu leaf-queue of parent: root #applications: 0
2013-08-28 20:28:22,673 INFO org.apache.hadoop.yarn.server.resourcemanager.ClientRMService: Allocated new applicationId: 4
2013-08-28 20:28:24,633 INFO org.apache.hadoop.yarn.server.resourcemanager.ClientRMService: Storing Application with id application_1377721066246_0004
2013-08-28 20:28:24,633 INFO org.apache.hadoop.yarn.server.resourcemanager.recovery.RMStateStore: Storing info for app: application_1377721066246_0004
2013-08-28 20:28:24,634 INFO org.apache.hadoop.yarn.server.resourcemanager.ClientRMService: Application with id 4 submitted by user ubuntu
2013-08-28 20:28:24,634 INFO org.apache.hadoop.yarn.server.resourcemanager.RMAuditLogger: USER=ubuntu	IP=192.168.100.34	OPERATION=Submit Application Request	TARGET=ClientRMService	RESULT=SUCCESS	APPID=application_1377721066246_0004
2013-08-28 20:28:24,635 INFO org.apache.hadoop.yarn.server.resourcemanager.rmapp.RMAppImpl: application_1377721066246_0004 State change from NEW to SUBMITTED
2013-08-28 20:28:24,635 INFO org.apache.hadoop.yarn.server.resourcemanager.ApplicationMasterService: Registering appattempt_1377721066246_0004_000001
2013-08-28 20:28:24,636 INFO org.apache.hadoop.yarn.server.resourcemanager.rmapp.attempt.RMAppAttemptImpl: appattempt_1377721066246_0004_000001 State change from NEW to SUBMITTED
2013-08-28 20:28:24,636 INFO org.apache.hadoop.yarn.server.resourcemanager.scheduler.capacity.LeafQueue: Application application_1377721066246_0004 from user: ubuntu activated in queue: default
2013-08-28 20:28:24,636 INFO org.apache.hadoop.yarn.server.resourcemanager.scheduler.capacity.LeafQueue: Application added - appId: application_1377721066246_0004 user: org.apache.hadoop.yarn.server.resourcemanager.scheduler.capacity.LeafQueue$User@785e7845, leaf-queue: default #user-pending-applications: 0 #user-active-applications: 1 #queue-pending-applications: 0 #queue-active-applications: 1
2013-08-28 20:28:24,637 INFO org.apache.hadoop.yarn.server.resourcemanager.scheduler.capacity.ParentQueue: Application added - appId: application_1377721066246_0004 user: ubuntu leaf-queue of parent: root #applications: 1
2013-08-28 20:28:24,637 INFO org.apache.hadoop.yarn.server.resourcemanager.scheduler.capacity.CapacityScheduler: Application Submission: appattempt_1377721066246_0004_000001, user: ubuntu queue: default: capacity=1.0, absoluteCapacity=1.0, usedResources=<memory:0, vCores:0>usedCapacity=0.0, absoluteUsedCapacity=0.0, numApps=1, numContainers=0, currently active: 1
2013-08-28 20:28:24,637 INFO org.apache.hadoop.yarn.server.resourcemanager.rmapp.attempt.RMAppAttemptImpl: appattempt_1377721066246_0004_000001 State change from SUBMITTED to SCHEDULED
2013-08-28 20:28:24,637 INFO org.apache.hadoop.yarn.server.resourcemanager.rmapp.RMAppImpl: application_1377721066246_0004 State change from SUBMITTED to ACCEPTED
2013-08-28 20:28:25,136 INFO org.apache.hadoop.yarn.server.resourcemanager.rmcontainer.RMContainerImpl: container_1377721066246_0004_01_000001 Container Transitioned from NEW to ALLOCATED
2013-08-28 20:28:25,136 INFO org.apache.hadoop.yarn.server.resourcemanager.RMAuditLogger: USER=ubuntu	OPERATION=AM Allocated Container	TARGET=SchedulerApp	RESULT=SUCCESS	APPID=application_1377721066246_0004	CONTAINERID=container_1377721066246_0004_01_000001
2013-08-28 20:28:25,137 INFO org.apache.hadoop.yarn.server.resourcemanager.scheduler.common.fica.FiCaSchedulerNode: Assigned container container_1377721066246_0004_01_000001 of capacity <memory:2048, vCores:1> on host hadoop-17-6:32933, which currently has 1 containers, <memory:2048, vCores:1> used and <memory:6144, vCores:15> available
2013-08-28 20:28:25,138 INFO org.apache.hadoop.yarn.server.resourcemanager.scheduler.capacity.LeafQueue: assignedContainer application=application_1377721066246_0004 container=Container: [ContainerId: container_1377721066246_0004_01_000001, NodeId: hadoop-17-6:32933, NodeHttpAddress: hadoop-17-6:8042, Resource: <memory:2048, vCores:1>, Priority: 0, State: NEW, Token: null, Status: container_id {, app_attempt_id {, application_id {, id: 4, cluster_timestamp: 1377721066246, }, attemptId: 1, }, id: 1, }, state: C_NEW, ] containerId=container_1377721066246_0004_01_000001 queue=default: capacity=1.0, absoluteCapacity=1.0, usedResources=<memory:0, vCores:0>usedCapacity=0.0, absoluteUsedCapacity=0.0, numApps=1, numContainers=0 usedCapacity=0.0 absoluteUsedCapacity=0.0 used=<memory:0, vCores:0> cluster=<memory:49152, vCores:96>
2013-08-28 20:28:25,138 INFO org.apache.hadoop.yarn.server.resourcemanager.scheduler.capacity.ParentQueue: Re-sorting queues since queue: root.default stats: default: capacity=1.0, absoluteCapacity=1.0, usedResources=<memory:2048, vCores:1>usedCapacity=0.041666668, absoluteUsedCapacity=0.041666668, numApps=1, numContainers=1
2013-08-28 20:28:25,138 INFO org.apache.hadoop.yarn.server.resourcemanager.scheduler.capacity.ParentQueue: assignedContainer queue=root usedCapacity=0.041666668 absoluteUsedCapacity=0.041666668 used=<memory:2048, vCores:1> cluster=<memory:49152, vCores:96>
2013-08-28 20:28:25,140 INFO org.apache.hadoop.yarn.server.resourcemanager.rmcontainer.RMContainerImpl: container_1377721066246_0004_01_000001 Container Transitioned from ALLOCATED to ACQUIRED
2013-08-28 20:28:25,141 INFO org.apache.hadoop.yarn.server.resourcemanager.rmapp.attempt.RMAppAttemptImpl: Storing attempt: AppId: application_1377721066246_0004 AttemptId: appattempt_1377721066246_0004_000001 MasterContainer: Container: [ContainerId: container_1377721066246_0004_01_000001, NodeId: hadoop-17-6:32933, NodeHttpAddress: hadoop-17-6:8042, Resource: <memory:2048, vCores:1>, Priority: 0, State: NEW, Token: null, Status: container_id {, app_attempt_id {, application_id {, id: 4, cluster_timestamp: 1377721066246, }, attemptId: 1, }, id: 1, }, state: C_NEW, ]
2013-08-28 20:28:25,142 INFO org.apache.hadoop.yarn.server.resourcemanager.recovery.RMStateStore: Storing info for attempt: appattempt_1377721066246_0004_000001
2013-08-28 20:28:25,142 INFO org.apache.hadoop.yarn.server.resourcemanager.rmapp.attempt.RMAppAttemptImpl: appattempt_1377721066246_0004_000001 State change from SCHEDULED to ALLOCATED_SAVING
2013-08-28 20:28:25,142 INFO org.apache.hadoop.yarn.server.resourcemanager.rmapp.attempt.RMAppAttemptImpl: appattempt_1377721066246_0004_000001 State change from ALLOCATED_SAVING to ALLOCATED
2013-08-28 20:28:25,144 INFO org.apache.hadoop.yarn.server.resourcemanager.amlauncher.AMLauncher: Launching masterappattempt_1377721066246_0004_000001
2013-08-28 20:28:25,146 INFO org.apache.hadoop.yarn.server.resourcemanager.amlauncher.AMLauncher: Setting up container Container: [ContainerId: container_1377721066246_0004_01_000001, NodeId: hadoop-17-6:32933, NodeHttpAddress: hadoop-17-6:8042, Resource: <memory:2048, vCores:1>, Priority: 0, State: NEW, Token: null, Status: container_id {, app_attempt_id {, application_id {, id: 4, cluster_timestamp: 1377721066246, }, attemptId: 1, }, id: 1, }, state: C_NEW, ] for AM appattempt_1377721066246_0004_000001
2013-08-28 20:28:25,147 INFO org.apache.hadoop.yarn.server.resourcemanager.amlauncher.AMLauncher: Command to launch container container_1377721066246_0004_01_000001 : $JAVA_HOME/bin/java -Dlog4j.configuration=container-log4j.properties -Dyarn.app.mapreduce.container.log.dir=<LOG_DIR> -Dyarn.app.mapreduce.container.log.filesize=0 -Dhadoop.root.logger=INFO,CLA  -Xmx1024m org.apache.hadoop.mapreduce.v2.app.MRAppMaster 1><LOG_DIR>/stdout 2><LOG_DIR>/stderr 
2013-08-28 20:28:25,168 INFO org.apache.hadoop.yarn.server.resourcemanager.amlauncher.AMLauncher: Done launching container Container: [ContainerId: container_1377721066246_0004_01_000001, NodeId: hadoop-17-6:32933, NodeHttpAddress: hadoop-17-6:8042, Resource: <memory:2048, vCores:1>, Priority: 0, State: NEW, Token: null, Status: container_id {, app_attempt_id {, application_id {, id: 4, cluster_timestamp: 1377721066246, }, attemptId: 1, }, id: 1, }, state: C_NEW, ] for AM appattempt_1377721066246_0004_000001
2013-08-28 20:28:25,168 INFO org.apache.hadoop.yarn.server.resourcemanager.rmapp.attempt.RMAppAttemptImpl: appattempt_1377721066246_0004_000001 State change from ALLOCATED to LAUNCHED
2013-08-28 20:28:26,143 INFO org.apache.hadoop.yarn.server.resourcemanager.rmcontainer.RMContainerImpl: container_1377721066246_0004_01_000001 Container Transitioned from ACQUIRED to RUNNING
2013-08-28 20:28:31,736 INFO org.apache.hadoop.yarn.server.resourcemanager.ApplicationMasterService: AM registration appattempt_1377721066246_0004_000001
2013-08-28 20:28:31,736 INFO org.apache.hadoop.yarn.server.resourcemanager.RMAuditLogger: USER=ubuntu	IP=192.168.100.38	OPERATION=Register App Master	TARGET=ApplicationMasterService	RESULT=SUCCESS	APPID=application_1377721066246_0004	APPATTEMPTID=appattempt_1377721066246_0004_000001
2013-08-28 20:28:31,737 INFO org.apache.hadoop.yarn.server.resourcemanager.rmapp.attempt.RMAppAttemptImpl: appattempt_1377721066246_0004_000001 State change from LAUNCHED to RUNNING
2013-08-28 20:28:31,737 INFO org.apache.hadoop.yarn.server.resourcemanager.rmapp.RMAppImpl: application_1377721066246_0004 State change from ACCEPTED to RUNNING
2013-08-28 20:28:33,179 INFO org.apache.hadoop.yarn.server.resourcemanager.rmcontainer.RMContainerImpl: container_1377721066246_0004_01_000002 Container Transitioned from NEW to ALLOCATED
2013-08-28 20:28:33,180 INFO org.apache.hadoop.yarn.server.resourcemanager.RMAuditLogger: USER=ubuntu	OPERATION=AM Allocated Container	TARGET=SchedulerApp	RESULT=SUCCESS	APPID=application_1377721066246_0004	CONTAINERID=container_1377721066246_0004_01_000002
2013-08-28 20:28:33,180 INFO org.apache.hadoop.yarn.server.resourcemanager.scheduler.common.fica.FiCaSchedulerNode: Assigned container container_1377721066246_0004_01_000002 of capacity <memory:1024, vCores:1> on host hadoop-17-6:32933, which currently has 2 containers, <memory:3072, vCores:2> used and <memory:5120, vCores:14> available
2013-08-28 20:28:33,181 INFO org.apache.hadoop.yarn.server.resourcemanager.scheduler.capacity.LeafQueue: assignedContainer application=application_1377721066246_0004 container=Container: [ContainerId: container_1377721066246_0004_01_000002, NodeId: hadoop-17-6:32933, NodeHttpAddress: hadoop-17-6:8042, Resource: <memory:1024, vCores:1>, Priority: 20, State: NEW, Token: null, Status: container_id {, app_attempt_id {, application_id {, id: 4, cluster_timestamp: 1377721066246, }, attemptId: 1, }, id: 2, }, state: C_NEW, ] containerId=container_1377721066246_0004_01_000002 queue=default: capacity=1.0, absoluteCapacity=1.0, usedResources=<memory:2048, vCores:1>usedCapacity=0.041666668, absoluteUsedCapacity=0.041666668, numApps=1, numContainers=1 usedCapacity=0.041666668 absoluteUsedCapacity=0.041666668 used=<memory:2048, vCores:1> cluster=<memory:49152, vCores:96>
2013-08-28 20:28:33,182 INFO org.apache.hadoop.yarn.server.resourcemanager.scheduler.capacity.ParentQueue: Re-sorting queues since queue: root.default stats: default: capacity=1.0, absoluteCapacity=1.0, usedResources=<memory:3072, vCores:2>usedCapacity=0.0625, absoluteUsedCapacity=0.0625, numApps=1, numContainers=2
2013-08-28 20:28:33,182 INFO org.apache.hadoop.yarn.server.resourcemanager.scheduler.capacity.ParentQueue: assignedContainer queue=root usedCapacity=0.0625 absoluteUsedCapacity=0.0625 used=<memory:3072, vCores:2> cluster=<memory:49152, vCores:96>
2013-08-28 20:28:33,235 INFO org.apache.hadoop.yarn.server.resourcemanager.rmcontainer.RMContainerImpl: container_1377721066246_0004_01_000003 Container Transitioned from NEW to ALLOCATED
2013-08-28 20:28:33,235 INFO org.apache.hadoop.yarn.server.resourcemanager.RMAuditLogger: USER=ubuntu	OPERATION=AM Allocated Container	TARGET=SchedulerApp	RESULT=SUCCESS	APPID=application_1377721066246_0004	CONTAINERID=container_1377721066246_0004_01_000003
2013-08-28 20:28:33,236 INFO org.apache.hadoop.yarn.server.resourcemanager.scheduler.common.fica.FiCaSchedulerNode: Assigned container container_1377721066246_0004_01_000003 of capacity <memory:1024, vCores:1> on host hadoop-17-3:35481, which currently has 1 containers, <memory:1024, vCores:1> used and <memory:7168, vCores:15> available
2013-08-28 20:28:33,237 INFO org.apache.hadoop.yarn.server.resourcemanager.scheduler.capacity.LeafQueue: assignedContainer application=application_1377721066246_0004 container=Container: [ContainerId: container_1377721066246_0004_01_000003, NodeId: hadoop-17-3:35481, NodeHttpAddress: hadoop-17-3:8042, Resource: <memory:1024, vCores:1>, Priority: 20, State: NEW, Token: null, Status: container_id {, app_attempt_id {, application_id {, id: 4, cluster_timestamp: 1377721066246, }, attemptId: 1, }, id: 3, }, state: C_NEW, ] containerId=container_1377721066246_0004_01_000003 queue=default: capacity=1.0, absoluteCapacity=1.0, usedResources=<memory:3072, vCores:2>usedCapacity=0.0625, absoluteUsedCapacity=0.0625, numApps=1, numContainers=2 usedCapacity=0.0625 absoluteUsedCapacity=0.0625 used=<memory:3072, vCores:2> cluster=<memory:49152, vCores:96>
2013-08-28 20:28:33,237 INFO org.apache.hadoop.yarn.server.resourcemanager.scheduler.capacity.ParentQueue: Re-sorting queues since queue: root.default stats: default: capacity=1.0, absoluteCapacity=1.0, usedResources=<memory:4096, vCores:3>usedCapacity=0.083333336, absoluteUsedCapacity=0.083333336, numApps=1, numContainers=3
2013-08-28 20:28:33,238 INFO org.apache.hadoop.yarn.server.resourcemanager.scheduler.capacity.ParentQueue: assignedContainer queue=root usedCapacity=0.083333336 absoluteUsedCapacity=0.083333336 used=<memory:4096, vCores:3> cluster=<memory:49152, vCores:96>
2013-08-28 20:28:33,782 INFO org.apache.hadoop.yarn.server.resourcemanager.rmcontainer.RMContainerImpl: container_1377721066246_0004_01_000002 Container Transitioned from ALLOCATED to ACQUIRED
2013-08-28 20:28:33,784 INFO org.apache.hadoop.yarn.server.resourcemanager.rmcontainer.RMContainerImpl: container_1377721066246_0004_01_000003 Container Transitioned from ALLOCATED to ACQUIRED
2013-08-28 20:28:34,191 INFO org.apache.hadoop.yarn.server.resourcemanager.rmcontainer.RMContainerImpl: container_1377721066246_0004_01_000002 Container Transitioned from ACQUIRED to RUNNING
2013-08-28 20:28:34,248 INFO org.apache.hadoop.yarn.server.resourcemanager.rmcontainer.RMContainerImpl: container_1377721066246_0004_01_000003 Container Transitioned from ACQUIRED to RUNNING
2013-08-28 20:28:34,811 INFO org.apache.hadoop.yarn.server.resourcemanager.scheduler.AppSchedulingInfo: checking for deactivate... 
2013-08-28 20:31:13,070 INFO org.apache.hadoop.yarn.server.resourcemanager.rmcontainer.RMContainerImpl: container_1377721066246_0004_01_000002 Container Transitioned from RUNNING to COMPLETED
2013-08-28 20:31:13,070 INFO org.apache.hadoop.yarn.server.resourcemanager.scheduler.common.fica.FiCaSchedulerApp: Completed container: container_1377721066246_0004_01_000002 in state: COMPLETED event:FINISHED
2013-08-28 20:31:13,070 INFO org.apache.hadoop.yarn.server.resourcemanager.RMAuditLogger: USER=ubuntu	OPERATION=AM Released Container	TARGET=SchedulerApp	RESULT=SUCCESS	APPID=application_1377721066246_0004	CONTAINERID=container_1377721066246_0004_01_000002
2013-08-28 20:31:13,070 INFO org.apache.hadoop.yarn.server.resourcemanager.scheduler.common.fica.FiCaSchedulerNode: Released container container_1377721066246_0004_01_000002 of capacity <memory:1024, vCores:1> on host hadoop-17-6:32933, which currently has 1 containers, <memory:2048, vCores:1> used and <memory:6144, vCores:15> available, release resources=true
2013-08-28 20:31:13,070 INFO org.apache.hadoop.yarn.server.resourcemanager.scheduler.capacity.LeafQueue: default used=<memory:3072, vCores:2> numContainers=2 user=ubuntu user-resources=<memory:3072, vCores:2>
2013-08-28 20:31:13,072 INFO org.apache.hadoop.yarn.server.resourcemanager.scheduler.capacity.LeafQueue: completedContainer container=Container: [ContainerId: container_1377721066246_0004_01_000002, NodeId: hadoop-17-6:32933, NodeHttpAddress: hadoop-17-6:8042, Resource: <memory:1024, vCores:1>, Priority: 20, State: NEW, Token: null, Status: container_id {, app_attempt_id {, application_id {, id: 4, cluster_timestamp: 1377721066246, }, attemptId: 1, }, id: 2, }, state: C_COMPLETE, diagnostics: "Container killed by the ApplicationMaster.\n\n", exit_status: 143, ] resource=<memory:1024, vCores:1> queue=default: capacity=1.0, absoluteCapacity=1.0, usedResources=<memory:3072, vCores:2>usedCapacity=0.0625, absoluteUsedCapacity=0.0625, numApps=1, numContainers=2 usedCapacity=0.0625 absoluteUsedCapacity=0.0625 used=<memory:3072, vCores:2> cluster=<memory:49152, vCores:96>
2013-08-28 20:31:13,072 INFO org.apache.hadoop.yarn.server.resourcemanager.scheduler.capacity.ParentQueue: completedContainer queue=root usedCapacity=0.0625 absoluteUsedCapacity=0.0625 used=<memory:3072, vCores:2> cluster=<memory:49152, vCores:96>
2013-08-28 20:31:13,072 INFO org.apache.hadoop.yarn.server.resourcemanager.scheduler.capacity.CapacityScheduler: Application appattempt_1377721066246_0004_000001 released container container_1377721066246_0004_01_000002 on node: host: hadoop-17-6:32933 #containers=1 available=6144 used=2048 with event: FINISHED
2013-08-28 20:31:16,839 INFO org.apache.hadoop.yarn.server.resourcemanager.rmcontainer.RMContainerImpl: container_1377721066246_0004_01_000003 Container Transitioned from RUNNING to COMPLETED
2013-08-28 20:31:16,839 INFO org.apache.hadoop.yarn.server.resourcemanager.scheduler.common.fica.FiCaSchedulerApp: Completed container: container_1377721066246_0004_01_000003 in state: COMPLETED event:FINISHED
2013-08-28 20:31:16,839 INFO org.apache.hadoop.yarn.server.resourcemanager.RMAuditLogger: USER=ubuntu	OPERATION=AM Released Container	TARGET=SchedulerApp	RESULT=SUCCESS	APPID=application_1377721066246_0004	CONTAINERID=container_1377721066246_0004_01_000003
2013-08-28 20:31:16,839 INFO org.apache.hadoop.yarn.server.resourcemanager.scheduler.common.fica.FiCaSchedulerNode: Released container container_1377721066246_0004_01_000003 of capacity <memory:1024, vCores:1> on host hadoop-17-3:35481, which currently has 0 containers, <memory:0, vCores:0> used and <memory:8192, vCores:16> available, release resources=true
2013-08-28 20:31:16,839 INFO org.apache.hadoop.yarn.server.resourcemanager.scheduler.capacity.LeafQueue: default used=<memory:2048, vCores:1> numContainers=1 user=ubuntu user-resources=<memory:2048, vCores:1>
2013-08-28 20:31:16,841 INFO org.apache.hadoop.yarn.server.resourcemanager.scheduler.capacity.LeafQueue: completedContainer container=Container: [ContainerId: container_1377721066246_0004_01_000003, NodeId: hadoop-17-3:35481, NodeHttpAddress: hadoop-17-3:8042, Resource: <memory:1024, vCores:1>, Priority: 20, State: NEW, Token: null, Status: container_id {, app_attempt_id {, application_id {, id: 4, cluster_timestamp: 1377721066246, }, attemptId: 1, }, id: 3, }, state: C_COMPLETE, diagnostics: "Container killed by the ApplicationMaster.\n\n", exit_status: 143, ] resource=<memory:1024, vCores:1> queue=default: capacity=1.0, absoluteCapacity=1.0, usedResources=<memory:2048, vCores:1>usedCapacity=0.041666668, absoluteUsedCapacity=0.041666668, numApps=1, numContainers=1 usedCapacity=0.041666668 absoluteUsedCapacity=0.041666668 used=<memory:2048, vCores:1> cluster=<memory:49152, vCores:96>
2013-08-28 20:31:16,841 INFO org.apache.hadoop.yarn.server.resourcemanager.scheduler.capacity.ParentQueue: completedContainer queue=root usedCapacity=0.041666668 absoluteUsedCapacity=0.041666668 used=<memory:2048, vCores:1> cluster=<memory:49152, vCores:96>
2013-08-28 20:31:16,841 INFO org.apache.hadoop.yarn.server.resourcemanager.scheduler.capacity.CapacityScheduler: Application appattempt_1377721066246_0004_000001 released container container_1377721066246_0004_01_000003 on node: host: hadoop-17-3:35481 #containers=0 available=8192 used=0 with event: FINISHED
2013-08-28 20:31:21,000 INFO org.apache.hadoop.yarn.server.resourcemanager.rmapp.attempt.RMAppAttemptImpl: appattempt_1377721066246_0004_000001 State change from RUNNING to FINISHING
2013-08-28 20:31:21,001 INFO org.apache.hadoop.yarn.server.resourcemanager.rmapp.RMAppImpl: application_1377721066246_0004 State change from RUNNING to FINISHING
2013-08-28 20:31:22,110 INFO org.apache.hadoop.yarn.server.resourcemanager.rmcontainer.RMContainerImpl: container_1377721066246_0004_01_000001 Container Transitioned from RUNNING to COMPLETED
2013-08-28 20:31:22,110 INFO org.apache.hadoop.yarn.server.resourcemanager.scheduler.common.fica.FiCaSchedulerApp: Completed container: container_1377721066246_0004_01_000001 in state: COMPLETED event:FINISHED
2013-08-28 20:31:22,110 INFO org.apache.hadoop.yarn.server.resourcemanager.RMAuditLogger: USER=ubuntu	OPERATION=AM Released Container	TARGET=SchedulerApp	RESULT=SUCCESS	APPID=application_1377721066246_0004	CONTAINERID=container_1377721066246_0004_01_000001
2013-08-28 20:31:22,110 INFO org.apache.hadoop.yarn.server.resourcemanager.scheduler.common.fica.FiCaSchedulerNode: Released container container_1377721066246_0004_01_000001 of capacity <memory:2048, vCores:1> on host hadoop-17-6:32933, which currently has 0 containers, <memory:0, vCores:0> used and <memory:8192, vCores:16> available, release resources=true
2013-08-28 20:31:22,110 INFO org.apache.hadoop.yarn.server.resourcemanager.scheduler.capacity.LeafQueue: default used=<memory:0, vCores:0> numContainers=0 user=ubuntu user-resources=<memory:0, vCores:0>
2013-08-28 20:31:22,112 INFO org.apache.hadoop.yarn.server.resourcemanager.scheduler.capacity.LeafQueue: completedContainer container=Container: [ContainerId: container_1377721066246_0004_01_000001, NodeId: hadoop-17-6:32933, NodeHttpAddress: hadoop-17-6:8042, Resource: <memory:2048, vCores:1>, Priority: 0, State: NEW, Token: null, Status: container_id {, app_attempt_id {, application_id {, id: 4, cluster_timestamp: 1377721066246, }, attemptId: 1, }, id: 1, }, state: C_COMPLETE, diagnostics: "", exit_status: 0, ] resource=<memory:2048, vCores:1> queue=default: capacity=1.0, absoluteCapacity=1.0, usedResources=<memory:0, vCores:0>usedCapacity=0.0, absoluteUsedCapacity=0.0, numApps=1, numContainers=0 usedCapacity=0.0 absoluteUsedCapacity=0.0 used=<memory:0, vCores:0> cluster=<memory:49152, vCores:96>
2013-08-28 20:31:22,112 INFO org.apache.hadoop.yarn.server.resourcemanager.scheduler.capacity.ParentQueue: completedContainer queue=root usedCapacity=0.0 absoluteUsedCapacity=0.0 used=<memory:0, vCores:0> cluster=<memory:49152, vCores:96>
2013-08-28 20:31:22,112 INFO org.apache.hadoop.yarn.server.resourcemanager.scheduler.capacity.CapacityScheduler: Application appattempt_1377721066246_0004_000001 released container container_1377721066246_0004_01_000001 on node: host: hadoop-17-6:32933 #containers=0 available=8192 used=0 with event: FINISHED
2013-08-28 20:31:22,112 INFO org.apache.hadoop.yarn.server.resourcemanager.rmapp.attempt.RMAppAttemptImpl: appattempt_1377721066246_0004_000001 State change from FINISHING to FINISHED
2013-08-28 20:31:22,114 INFO org.apache.hadoop.yarn.server.resourcemanager.rmapp.RMAppImpl: application_1377721066246_0004 State change from FINISHING to FINISHED
2013-08-28 20:31:22,115 INFO org.apache.hadoop.yarn.server.resourcemanager.scheduler.capacity.CapacityScheduler: Application appattempt_1377721066246_0004_000001 is done. finalState=FINISHED
2013-08-28 20:31:22,116 INFO org.apache.hadoop.yarn.server.resourcemanager.scheduler.AppSchedulingInfo: Application application_1377721066246_0004 requests cleared
2013-08-28 20:31:22,116 INFO org.apache.hadoop.yarn.server.resourcemanager.scheduler.capacity.LeafQueue: Application removed - appId: application_1377721066246_0004 user: ubuntu queue: default #user-pending-applications: 0 #user-active-applications: 0 #queue-pending-applications: 0 #queue-active-applications: 0
2013-08-28 20:31:22,116 INFO org.apache.hadoop.yarn.server.resourcemanager.scheduler.capacity.ParentQueue: Application removed - appId: application_1377721066246_0004 user: ubuntu leaf-queue of parent: root #applications: 0
2013-08-28 20:31:22,116 INFO org.apache.hadoop.yarn.server.resourcemanager.RMAuditLogger: USER=ubuntu	OPERATION=Application Finished - Succeeded	TARGET=RMAppManager	RESULT=SUCCESS	APPID=application_1377721066246_0004
2013-08-28 20:31:22,117 INFO org.apache.hadoop.yarn.server.resourcemanager.RMAppManager$ApplicationSummary: appId=application_1377721066246_0004,name=TeraGen,user=ubuntu,queue=default,state=FINISHED,trackingUrl=hadoop-17-1.novalocal:8088/proxy/application_1377721066246_0004/jobhistory/job/job_1377721066246_0004,appMasterHost=hadoop-17-6,startTime=1377721704633,finishTime=1377721881001
2013-08-28 20:31:22,117 INFO org.apache.hadoop.yarn.server.resourcemanager.recovery.RMStateStore: Removing info for app: application_1377721066246_0004
2013-08-28 20:31:22,117 INFO org.apache.hadoop.yarn.server.resourcemanager.amlauncher.AMLauncher: Cleaning master appattempt_1377721066246_0004_000001
2013-08-28 20:31:22,867 INFO org.apache.hadoop.yarn.server.resourcemanager.ClientRMService: Allocated new applicationId: 5
2013-08-28 20:31:24,827 INFO org.apache.hadoop.yarn.server.resourcemanager.ClientRMService: Storing Application with id application_1377721066246_0005
2013-08-28 20:31:24,828 INFO org.apache.hadoop.yarn.server.resourcemanager.recovery.RMStateStore: Storing info for app: application_1377721066246_0005
2013-08-28 20:31:24,828 INFO org.apache.hadoop.yarn.server.resourcemanager.ClientRMService: Application with id 5 submitted by user ubuntu
2013-08-28 20:31:24,828 INFO org.apache.hadoop.yarn.server.resourcemanager.RMAuditLogger: USER=ubuntu	IP=192.168.100.34	OPERATION=Submit Application Request	TARGET=ClientRMService	RESULT=SUCCESS	APPID=application_1377721066246_0005
2013-08-28 20:31:24,834 INFO org.apache.hadoop.yarn.server.resourcemanager.rmapp.RMAppImpl: application_1377721066246_0005 State change from NEW to SUBMITTED
2013-08-28 20:31:24,835 INFO org.apache.hadoop.yarn.server.resourcemanager.ApplicationMasterService: Registering appattempt_1377721066246_0005_000001
2013-08-28 20:31:24,835 INFO org.apache.hadoop.yarn.server.resourcemanager.rmapp.attempt.RMAppAttemptImpl: appattempt_1377721066246_0005_000001 State change from NEW to SUBMITTED
2013-08-28 20:31:24,835 INFO org.apache.hadoop.yarn.server.resourcemanager.scheduler.capacity.LeafQueue: Application application_1377721066246_0005 from user: ubuntu activated in queue: default
2013-08-28 20:31:24,835 INFO org.apache.hadoop.yarn.server.resourcemanager.scheduler.capacity.LeafQueue: Application added - appId: application_1377721066246_0005 user: org.apache.hadoop.yarn.server.resourcemanager.scheduler.capacity.LeafQueue$User@5251edb4, leaf-queue: default #user-pending-applications: 0 #user-active-applications: 1 #queue-pending-applications: 0 #queue-active-applications: 1
2013-08-28 20:31:24,836 INFO org.apache.hadoop.yarn.server.resourcemanager.scheduler.capacity.ParentQueue: Application added - appId: application_1377721066246_0005 user: ubuntu leaf-queue of parent: root #applications: 1
2013-08-28 20:31:24,836 INFO org.apache.hadoop.yarn.server.resourcemanager.scheduler.capacity.CapacityScheduler: Application Submission: appattempt_1377721066246_0005_000001, user: ubuntu queue: default: capacity=1.0, absoluteCapacity=1.0, usedResources=<memory:0, vCores:0>usedCapacity=0.0, absoluteUsedCapacity=0.0, numApps=1, numContainers=0, currently active: 1
2013-08-28 20:31:24,836 INFO org.apache.hadoop.yarn.server.resourcemanager.rmapp.attempt.RMAppAttemptImpl: appattempt_1377721066246_0005_000001 State change from SUBMITTED to SCHEDULED
2013-08-28 20:31:24,837 INFO org.apache.hadoop.yarn.server.resourcemanager.rmapp.RMAppImpl: application_1377721066246_0005 State change from SUBMITTED to ACCEPTED
2013-08-28 20:31:24,866 INFO org.apache.hadoop.yarn.server.resourcemanager.rmcontainer.RMContainerImpl: container_1377721066246_0005_01_000001 Container Transitioned from NEW to ALLOCATED
2013-08-28 20:31:24,866 INFO org.apache.hadoop.yarn.server.resourcemanager.RMAuditLogger: USER=ubuntu	OPERATION=AM Allocated Container	TARGET=SchedulerApp	RESULT=SUCCESS	APPID=application_1377721066246_0005	CONTAINERID=container_1377721066246_0005_01_000001
2013-08-28 20:31:24,866 INFO org.apache.hadoop.yarn.server.resourcemanager.scheduler.common.fica.FiCaSchedulerNode: Assigned container container_1377721066246_0005_01_000001 of capacity <memory:2048, vCores:1> on host hadoop-17-3:35481, which currently has 1 containers, <memory:2048, vCores:1> used and <memory:6144, vCores:15> available
2013-08-28 20:31:24,868 INFO org.apache.hadoop.yarn.server.resourcemanager.scheduler.capacity.LeafQueue: assignedContainer application=application_1377721066246_0005 container=Container: [ContainerId: container_1377721066246_0005_01_000001, NodeId: hadoop-17-3:35481, NodeHttpAddress: hadoop-17-3:8042, Resource: <memory:2048, vCores:1>, Priority: 0, State: NEW, Token: null, Status: container_id {, app_attempt_id {, application_id {, id: 5, cluster_timestamp: 1377721066246, }, attemptId: 1, }, id: 1, }, state: C_NEW, ] containerId=container_1377721066246_0005_01_000001 queue=default: capacity=1.0, absoluteCapacity=1.0, usedResources=<memory:0, vCores:0>usedCapacity=0.0, absoluteUsedCapacity=0.0, numApps=1, numContainers=0 usedCapacity=0.0 absoluteUsedCapacity=0.0 used=<memory:0, vCores:0> cluster=<memory:49152, vCores:96>
2013-08-28 20:31:24,868 INFO org.apache.hadoop.yarn.server.resourcemanager.scheduler.capacity.ParentQueue: Re-sorting queues since queue: root.default stats: default: capacity=1.0, absoluteCapacity=1.0, usedResources=<memory:2048, vCores:1>usedCapacity=0.041666668, absoluteUsedCapacity=0.041666668, numApps=1, numContainers=1
2013-08-28 20:31:24,868 INFO org.apache.hadoop.yarn.server.resourcemanager.scheduler.capacity.ParentQueue: assignedContainer queue=root usedCapacity=0.041666668 absoluteUsedCapacity=0.041666668 used=<memory:2048, vCores:1> cluster=<memory:49152, vCores:96>
2013-08-28 20:31:24,870 INFO org.apache.hadoop.yarn.server.resourcemanager.rmcontainer.RMContainerImpl: container_1377721066246_0005_01_000001 Container Transitioned from ALLOCATED to ACQUIRED
2013-08-28 20:31:24,871 INFO org.apache.hadoop.yarn.server.resourcemanager.rmapp.attempt.RMAppAttemptImpl: Storing attempt: AppId: application_1377721066246_0005 AttemptId: appattempt_1377721066246_0005_000001 MasterContainer: Container: [ContainerId: container_1377721066246_0005_01_000001, NodeId: hadoop-17-3:35481, NodeHttpAddress: hadoop-17-3:8042, Resource: <memory:2048, vCores:1>, Priority: 0, State: NEW, Token: null, Status: container_id {, app_attempt_id {, application_id {, id: 5, cluster_timestamp: 1377721066246, }, attemptId: 1, }, id: 1, }, state: C_NEW, ]
2013-08-28 20:31:24,872 INFO org.apache.hadoop.yarn.server.resourcemanager.recovery.RMStateStore: Storing info for attempt: appattempt_1377721066246_0005_000001
2013-08-28 20:31:24,872 INFO org.apache.hadoop.yarn.server.resourcemanager.rmapp.attempt.RMAppAttemptImpl: appattempt_1377721066246_0005_000001 State change from SCHEDULED to ALLOCATED_SAVING
2013-08-28 20:31:24,873 INFO org.apache.hadoop.yarn.server.resourcemanager.rmapp.attempt.RMAppAttemptImpl: appattempt_1377721066246_0005_000001 State change from ALLOCATED_SAVING to ALLOCATED
2013-08-28 20:31:24,874 INFO org.apache.hadoop.yarn.server.resourcemanager.amlauncher.AMLauncher: Launching masterappattempt_1377721066246_0005_000001
2013-08-28 20:31:24,877 INFO org.apache.hadoop.yarn.server.resourcemanager.amlauncher.AMLauncher: Setting up container Container: [ContainerId: container_1377721066246_0005_01_000001, NodeId: hadoop-17-3:35481, NodeHttpAddress: hadoop-17-3:8042, Resource: <memory:2048, vCores:1>, Priority: 0, State: NEW, Token: null, Status: container_id {, app_attempt_id {, application_id {, id: 5, cluster_timestamp: 1377721066246, }, attemptId: 1, }, id: 1, }, state: C_NEW, ] for AM appattempt_1377721066246_0005_000001
2013-08-28 20:31:24,877 INFO org.apache.hadoop.yarn.server.resourcemanager.amlauncher.AMLauncher: Command to launch container container_1377721066246_0005_01_000001 : $JAVA_HOME/bin/java -Dlog4j.configuration=container-log4j.properties -Dyarn.app.mapreduce.container.log.dir=<LOG_DIR> -Dyarn.app.mapreduce.container.log.filesize=0 -Dhadoop.root.logger=INFO,CLA  -Xmx1024m org.apache.hadoop.mapreduce.v2.app.MRAppMaster 1><LOG_DIR>/stdout 2><LOG_DIR>/stderr 
2013-08-28 20:31:24,895 INFO org.apache.hadoop.yarn.server.resourcemanager.amlauncher.AMLauncher: Done launching container Container: [ContainerId: container_1377721066246_0005_01_000001, NodeId: hadoop-17-3:35481, NodeHttpAddress: hadoop-17-3:8042, Resource: <memory:2048, vCores:1>, Priority: 0, State: NEW, Token: null, Status: container_id {, app_attempt_id {, application_id {, id: 5, cluster_timestamp: 1377721066246, }, attemptId: 1, }, id: 1, }, state: C_NEW, ] for AM appattempt_1377721066246_0005_000001
2013-08-28 20:31:24,896 INFO org.apache.hadoop.yarn.server.resourcemanager.rmapp.attempt.RMAppAttemptImpl: appattempt_1377721066246_0005_000001 State change from ALLOCATED to LAUNCHED
2013-08-28 20:31:25,873 INFO org.apache.hadoop.yarn.server.resourcemanager.rmcontainer.RMContainerImpl: container_1377721066246_0005_01_000001 Container Transitioned from ACQUIRED to RUNNING
2013-08-28 20:31:34,284 INFO org.apache.hadoop.yarn.server.resourcemanager.ApplicationMasterService: AM registration appattempt_1377721066246_0005_000001
2013-08-28 20:31:34,285 INFO org.apache.hadoop.yarn.server.resourcemanager.RMAuditLogger: USER=ubuntu	IP=192.168.100.15	OPERATION=Register App Master	TARGET=ApplicationMasterService	RESULT=SUCCESS	APPID=application_1377721066246_0005	APPATTEMPTID=appattempt_1377721066246_0005_000001
2013-08-28 20:31:34,286 INFO org.apache.hadoop.yarn.server.resourcemanager.rmapp.attempt.RMAppAttemptImpl: appattempt_1377721066246_0005_000001 State change from LAUNCHED to RUNNING
2013-08-28 20:31:34,286 INFO org.apache.hadoop.yarn.server.resourcemanager.rmapp.RMAppImpl: application_1377721066246_0005 State change from ACCEPTED to RUNNING
2013-08-28 20:31:35,438 INFO org.apache.hadoop.yarn.server.resourcemanager.rmcontainer.RMContainerImpl: container_1377721066246_0005_01_000002 Container Transitioned from NEW to ALLOCATED
2013-08-28 20:31:35,439 INFO org.apache.hadoop.yarn.server.resourcemanager.RMAuditLogger: USER=ubuntu	OPERATION=AM Allocated Container	TARGET=SchedulerApp	RESULT=SUCCESS	APPID=application_1377721066246_0005	CONTAINERID=container_1377721066246_0005_01_000002
2013-08-28 20:31:35,439 INFO org.apache.hadoop.yarn.server.resourcemanager.scheduler.common.fica.FiCaSchedulerNode: Assigned container container_1377721066246_0005_01_000002 of capacity <memory:1024, vCores:1> on host hadoop-17-5:46576, which currently has 1 containers, <memory:1024, vCores:1> used and <memory:7168, vCores:15> available
2013-08-28 20:31:35,440 INFO org.apache.hadoop.yarn.server.resourcemanager.scheduler.capacity.LeafQueue: assignedContainer application=application_1377721066246_0005 container=Container: [ContainerId: container_1377721066246_0005_01_000002, NodeId: hadoop-17-5:46576, NodeHttpAddress: hadoop-17-5:8042, Resource: <memory:1024, vCores:1>, Priority: 20, State: NEW, Token: null, Status: container_id {, app_attempt_id {, application_id {, id: 5, cluster_timestamp: 1377721066246, }, attemptId: 1, }, id: 2, }, state: C_NEW, ] containerId=container_1377721066246_0005_01_000002 queue=default: capacity=1.0, absoluteCapacity=1.0, usedResources=<memory:2048, vCores:1>usedCapacity=0.041666668, absoluteUsedCapacity=0.041666668, numApps=1, numContainers=1 usedCapacity=0.041666668 absoluteUsedCapacity=0.041666668 used=<memory:2048, vCores:1> cluster=<memory:49152, vCores:96>
2013-08-28 20:31:35,440 INFO org.apache.hadoop.yarn.server.resourcemanager.scheduler.capacity.ParentQueue: Re-sorting queues since queue: root.default stats: default: capacity=1.0, absoluteCapacity=1.0, usedResources=<memory:3072, vCores:2>usedCapacity=0.0625, absoluteUsedCapacity=0.0625, numApps=1, numContainers=2
2013-08-28 20:31:35,441 INFO org.apache.hadoop.yarn.server.resourcemanager.scheduler.capacity.ParentQueue: assignedContainer queue=root usedCapacity=0.0625 absoluteUsedCapacity=0.0625 used=<memory:3072, vCores:2> cluster=<memory:49152, vCores:96>
2013-08-28 20:31:35,487 INFO org.apache.hadoop.yarn.server.resourcemanager.rmcontainer.RMContainerImpl: container_1377721066246_0005_01_000003 Container Transitioned from NEW to ALLOCATED
2013-08-28 20:31:35,487 INFO org.apache.hadoop.yarn.server.resourcemanager.RMAuditLogger: USER=ubuntu	OPERATION=AM Allocated Container	TARGET=SchedulerApp	RESULT=SUCCESS	APPID=application_1377721066246_0005	CONTAINERID=container_1377721066246_0005_01_000003
2013-08-28 20:31:35,487 INFO org.apache.hadoop.yarn.server.resourcemanager.scheduler.common.fica.FiCaSchedulerNode: Assigned container container_1377721066246_0005_01_000003 of capacity <memory:1024, vCores:1> on host hadoop-17-4:59779, which currently has 1 containers, <memory:1024, vCores:1> used and <memory:7168, vCores:15> available
2013-08-28 20:31:35,488 INFO org.apache.hadoop.yarn.server.resourcemanager.scheduler.capacity.LeafQueue: assignedContainer application=application_1377721066246_0005 container=Container: [ContainerId: container_1377721066246_0005_01_000003, NodeId: hadoop-17-4:59779, NodeHttpAddress: hadoop-17-4:8042, Resource: <memory:1024, vCores:1>, Priority: 20, State: NEW, Token: null, Status: container_id {, app_attempt_id {, application_id {, id: 5, cluster_timestamp: 1377721066246, }, attemptId: 1, }, id: 3, }, state: C_NEW, ] containerId=container_1377721066246_0005_01_000003 queue=default: capacity=1.0, absoluteCapacity=1.0, usedResources=<memory:3072, vCores:2>usedCapacity=0.0625, absoluteUsedCapacity=0.0625, numApps=1, numContainers=2 usedCapacity=0.0625 absoluteUsedCapacity=0.0625 used=<memory:3072, vCores:2> cluster=<memory:49152, vCores:96>
2013-08-28 20:31:35,489 INFO org.apache.hadoop.yarn.server.resourcemanager.scheduler.capacity.ParentQueue: Re-sorting queues since queue: root.default stats: default: capacity=1.0, absoluteCapacity=1.0, usedResources=<memory:4096, vCores:3>usedCapacity=0.083333336, absoluteUsedCapacity=0.083333336, numApps=1, numContainers=3
2013-08-28 20:31:35,489 INFO org.apache.hadoop.yarn.server.resourcemanager.scheduler.capacity.ParentQueue: assignedContainer queue=root usedCapacity=0.083333336 absoluteUsedCapacity=0.083333336 used=<memory:4096, vCores:3> cluster=<memory:49152, vCores:96>
2013-08-28 20:31:36,384 INFO org.apache.hadoop.yarn.server.resourcemanager.rmcontainer.RMContainerImpl: container_1377721066246_0005_01_000002 Container Transitioned from ALLOCATED to ACQUIRED
2013-08-28 20:31:36,386 INFO org.apache.hadoop.yarn.server.resourcemanager.rmcontainer.RMContainerImpl: container_1377721066246_0005_01_000003 Container Transitioned from ALLOCATED to ACQUIRED
2013-08-28 20:31:37,422 INFO org.apache.hadoop.yarn.server.resourcemanager.scheduler.AppSchedulingInfo: checking for deactivate... 
2013-08-28 20:31:37,448 INFO org.apache.hadoop.yarn.server.resourcemanager.rmcontainer.RMContainerImpl: container_1377721066246_0005_01_000002 Container Transitioned from ACQUIRED to RUNNING
2013-08-28 20:31:37,496 INFO org.apache.hadoop.yarn.server.resourcemanager.rmcontainer.RMContainerImpl: container_1377721066246_0005_01_000003 Container Transitioned from ACQUIRED to RUNNING
2013-08-28 20:34:14,885 INFO org.apache.hadoop.yarn.server.resourcemanager.rmcontainer.RMContainerImpl: container_1377721066246_0005_01_000003 Container Transitioned from RUNNING to COMPLETED
2013-08-28 20:34:14,885 INFO org.apache.hadoop.yarn.server.resourcemanager.scheduler.common.fica.FiCaSchedulerApp: Completed container: container_1377721066246_0005_01_000003 in state: COMPLETED event:FINISHED
2013-08-28 20:34:14,885 INFO org.apache.hadoop.yarn.server.resourcemanager.RMAuditLogger: USER=ubuntu	OPERATION=AM Released Container	TARGET=SchedulerApp	RESULT=SUCCESS	APPID=application_1377721066246_0005	CONTAINERID=container_1377721066246_0005_01_000003
2013-08-28 20:34:14,886 INFO org.apache.hadoop.yarn.server.resourcemanager.scheduler.common.fica.FiCaSchedulerNode: Released container container_1377721066246_0005_01_000003 of capacity <memory:1024, vCores:1> on host hadoop-17-4:59779, which currently has 0 containers, <memory:0, vCores:0> used and <memory:8192, vCores:16> available, release resources=true
2013-08-28 20:34:14,886 INFO org.apache.hadoop.yarn.server.resourcemanager.scheduler.capacity.LeafQueue: default used=<memory:3072, vCores:2> numContainers=2 user=ubuntu user-resources=<memory:3072, vCores:2>
2013-08-28 20:34:14,887 INFO org.apache.hadoop.yarn.server.resourcemanager.scheduler.capacity.LeafQueue: completedContainer container=Container: [ContainerId: container_1377721066246_0005_01_000003, NodeId: hadoop-17-4:59779, NodeHttpAddress: hadoop-17-4:8042, Resource: <memory:1024, vCores:1>, Priority: 20, State: NEW, Token: null, Status: container_id {, app_attempt_id {, application_id {, id: 5, cluster_timestamp: 1377721066246, }, attemptId: 1, }, id: 3, }, state: C_COMPLETE, diagnostics: "Container killed by the ApplicationMaster.\n\n", exit_status: 143, ] resource=<memory:1024, vCores:1> queue=default: capacity=1.0, absoluteCapacity=1.0, usedResources=<memory:3072, vCores:2>usedCapacity=0.0625, absoluteUsedCapacity=0.0625, numApps=1, numContainers=2 usedCapacity=0.0625 absoluteUsedCapacity=0.0625 used=<memory:3072, vCores:2> cluster=<memory:49152, vCores:96>
2013-08-28 20:34:14,887 INFO org.apache.hadoop.yarn.server.resourcemanager.scheduler.capacity.ParentQueue: completedContainer queue=root usedCapacity=0.0625 absoluteUsedCapacity=0.0625 used=<memory:3072, vCores:2> cluster=<memory:49152, vCores:96>
2013-08-28 20:34:14,888 INFO org.apache.hadoop.yarn.server.resourcemanager.scheduler.capacity.CapacityScheduler: Application appattempt_1377721066246_0005_000001 released container container_1377721066246_0005_01_000003 on node: host: hadoop-17-4:59779 #containers=0 available=8192 used=0 with event: FINISHED
2013-08-28 20:34:17,120 INFO org.apache.hadoop.yarn.server.resourcemanager.rmcontainer.RMContainerImpl: container_1377721066246_0005_01_000002 Container Transitioned from RUNNING to COMPLETED
2013-08-28 20:34:17,120 INFO org.apache.hadoop.yarn.server.resourcemanager.scheduler.common.fica.FiCaSchedulerApp: Completed container: container_1377721066246_0005_01_000002 in state: COMPLETED event:FINISHED
2013-08-28 20:34:17,120 INFO org.apache.hadoop.yarn.server.resourcemanager.RMAuditLogger: USER=ubuntu	OPERATION=AM Released Container	TARGET=SchedulerApp	RESULT=SUCCESS	APPID=application_1377721066246_0005	CONTAINERID=container_1377721066246_0005_01_000002
2013-08-28 20:34:17,121 INFO org.apache.hadoop.yarn.server.resourcemanager.scheduler.common.fica.FiCaSchedulerNode: Released container container_1377721066246_0005_01_000002 of capacity <memory:1024, vCores:1> on host hadoop-17-5:46576, which currently has 0 containers, <memory:0, vCores:0> used and <memory:8192, vCores:16> available, release resources=true
2013-08-28 20:34:17,121 INFO org.apache.hadoop.yarn.server.resourcemanager.scheduler.capacity.LeafQueue: default used=<memory:2048, vCores:1> numContainers=1 user=ubuntu user-resources=<memory:2048, vCores:1>
2013-08-28 20:34:17,122 INFO org.apache.hadoop.yarn.server.resourcemanager.scheduler.capacity.LeafQueue: completedContainer container=Container: [ContainerId: container_1377721066246_0005_01_000002, NodeId: hadoop-17-5:46576, NodeHttpAddress: hadoop-17-5:8042, Resource: <memory:1024, vCores:1>, Priority: 20, State: NEW, Token: null, Status: container_id {, app_attempt_id {, application_id {, id: 5, cluster_timestamp: 1377721066246, }, attemptId: 1, }, id: 2, }, state: C_COMPLETE, diagnostics: "Container killed by the ApplicationMaster.\n\n", exit_status: 143, ] resource=<memory:1024, vCores:1> queue=default: capacity=1.0, absoluteCapacity=1.0, usedResources=<memory:2048, vCores:1>usedCapacity=0.041666668, absoluteUsedCapacity=0.041666668, numApps=1, numContainers=1 usedCapacity=0.041666668 absoluteUsedCapacity=0.041666668 used=<memory:2048, vCores:1> cluster=<memory:49152, vCores:96>
2013-08-28 20:34:17,122 INFO org.apache.hadoop.yarn.server.resourcemanager.scheduler.capacity.ParentQueue: completedContainer queue=root usedCapacity=0.041666668 absoluteUsedCapacity=0.041666668 used=<memory:2048, vCores:1> cluster=<memory:49152, vCores:96>
2013-08-28 20:34:17,123 INFO org.apache.hadoop.yarn.server.resourcemanager.scheduler.capacity.CapacityScheduler: Application appattempt_1377721066246_0005_000001 released container container_1377721066246_0005_01_000002 on node: host: hadoop-17-5:46576 #containers=0 available=8192 used=0 with event: FINISHED
2013-08-28 20:34:21,288 INFO org.apache.hadoop.yarn.server.resourcemanager.rmapp.attempt.RMAppAttemptImpl: appattempt_1377721066246_0005_000001 State change from RUNNING to FINISHING
2013-08-28 20:34:21,289 INFO org.apache.hadoop.yarn.server.resourcemanager.rmapp.RMAppImpl: application_1377721066246_0005 State change from RUNNING to FINISHING
2013-08-28 20:34:22,049 INFO org.apache.hadoop.yarn.server.resourcemanager.rmcontainer.RMContainerImpl: container_1377721066246_0005_01_000001 Container Transitioned from RUNNING to COMPLETED
2013-08-28 20:34:22,049 INFO org.apache.hadoop.yarn.server.resourcemanager.scheduler.common.fica.FiCaSchedulerApp: Completed container: container_1377721066246_0005_01_000001 in state: COMPLETED event:FINISHED
2013-08-28 20:34:22,049 INFO org.apache.hadoop.yarn.server.resourcemanager.rmapp.attempt.RMAppAttemptImpl: appattempt_1377721066246_0005_000001 State change from FINISHING to FINISHED
2013-08-28 20:34:22,049 INFO org.apache.hadoop.yarn.server.resourcemanager.RMAuditLogger: USER=ubuntu	OPERATION=AM Released Container	TARGET=SchedulerApp	RESULT=SUCCESS	APPID=application_1377721066246_0005	CONTAINERID=container_1377721066246_0005_01_000001
2013-08-28 20:34:22,049 INFO org.apache.hadoop.yarn.server.resourcemanager.rmapp.RMAppImpl: application_1377721066246_0005 State change from FINISHING to FINISHED
2013-08-28 20:34:22,049 INFO org.apache.hadoop.yarn.server.resourcemanager.scheduler.common.fica.FiCaSchedulerNode: Released container container_1377721066246_0005_01_000001 of capacity <memory:2048, vCores:1> on host hadoop-17-3:35481, which currently has 0 containers, <memory:0, vCores:0> used and <memory:8192, vCores:16> available, release resources=true
2013-08-28 20:34:22,050 INFO org.apache.hadoop.yarn.server.resourcemanager.scheduler.capacity.LeafQueue: default used=<memory:0, vCores:0> numContainers=0 user=ubuntu user-resources=<memory:0, vCores:0>
2013-08-28 20:34:22,050 INFO org.apache.hadoop.yarn.server.resourcemanager.RMAuditLogger: USER=ubuntu	OPERATION=Application Finished - Succeeded	TARGET=RMAppManager	RESULT=SUCCESS	APPID=application_1377721066246_0005
2013-08-28 20:34:22,050 INFO org.apache.hadoop.yarn.server.resourcemanager.recovery.RMStateStore: Removing info for app: application_1377721066246_0005
2013-08-28 20:34:22,050 INFO org.apache.hadoop.yarn.server.resourcemanager.RMAppManager$ApplicationSummary: appId=application_1377721066246_0005,name=TeraGen,user=ubuntu,queue=default,state=FINISHED,trackingUrl=hadoop-17-1.novalocal:8088/proxy/application_1377721066246_0005/jobhistory/job/job_1377721066246_0005,appMasterHost=hadoop-17-3,startTime=1377721884827,finishTime=1377722061289
2013-08-28 20:34:22,051 INFO org.apache.hadoop.yarn.server.resourcemanager.scheduler.capacity.LeafQueue: completedContainer container=Container: [ContainerId: container_1377721066246_0005_01_000001, NodeId: hadoop-17-3:35481, NodeHttpAddress: hadoop-17-3:8042, Resource: <memory:2048, vCores:1>, Priority: 0, State: NEW, Token: null, Status: container_id {, app_attempt_id {, application_id {, id: 5, cluster_timestamp: 1377721066246, }, attemptId: 1, }, id: 1, }, state: C_COMPLETE, diagnostics: "", exit_status: 0, ] resource=<memory:2048, vCores:1> queue=default: capacity=1.0, absoluteCapacity=1.0, usedResources=<memory:0, vCores:0>usedCapacity=0.0, absoluteUsedCapacity=0.0, numApps=1, numContainers=0 usedCapacity=0.0 absoluteUsedCapacity=0.0 used=<memory:0, vCores:0> cluster=<memory:49152, vCores:96>
2013-08-28 20:34:22,051 INFO org.apache.hadoop.yarn.server.resourcemanager.scheduler.capacity.ParentQueue: completedContainer queue=root usedCapacity=0.0 absoluteUsedCapacity=0.0 used=<memory:0, vCores:0> cluster=<memory:49152, vCores:96>
2013-08-28 20:34:22,051 INFO org.apache.hadoop.yarn.server.resourcemanager.amlauncher.AMLauncher: Cleaning master appattempt_1377721066246_0005_000001
2013-08-28 20:34:22,051 INFO org.apache.hadoop.yarn.server.resourcemanager.scheduler.capacity.CapacityScheduler: Application appattempt_1377721066246_0005_000001 released container container_1377721066246_0005_01_000001 on node: host: hadoop-17-3:35481 #containers=0 available=8192 used=0 with event: FINISHED
2013-08-28 20:34:22,052 INFO org.apache.hadoop.yarn.server.resourcemanager.scheduler.capacity.CapacityScheduler: Application appattempt_1377721066246_0005_000001 is done. finalState=FINISHED
2013-08-28 20:34:22,052 INFO org.apache.hadoop.yarn.server.resourcemanager.scheduler.AppSchedulingInfo: Application application_1377721066246_0005 requests cleared
2013-08-28 20:34:22,053 INFO org.apache.hadoop.yarn.server.resourcemanager.scheduler.capacity.LeafQueue: Application removed - appId: application_1377721066246_0005 user: ubuntu queue: default #user-pending-applications: 0 #user-active-applications: 0 #queue-pending-applications: 0 #queue-active-applications: 0
2013-08-28 20:34:22,053 INFO org.apache.hadoop.yarn.server.resourcemanager.scheduler.capacity.ParentQueue: Application removed - appId: application_1377721066246_0005 user: ubuntu leaf-queue of parent: root #applications: 0
2013-08-28 20:34:36,902 INFO org.apache.hadoop.yarn.server.resourcemanager.ClientRMService: Allocated new applicationId: 6
2013-08-28 20:34:37,616 INFO org.apache.hadoop.yarn.server.resourcemanager.ClientRMService: Allocated new applicationId: 7
2013-08-28 20:34:37,731 INFO org.apache.hadoop.yarn.server.resourcemanager.ClientRMService: Allocated new applicationId: 8
2013-08-28 20:34:38,094 INFO org.apache.hadoop.yarn.server.resourcemanager.ClientRMService: Allocated new applicationId: 9
2013-08-28 20:34:38,362 INFO org.apache.hadoop.yarn.server.resourcemanager.ClientRMService: Allocated new applicationId: 10
2013-08-28 20:34:40,727 INFO org.apache.hadoop.yarn.server.resourcemanager.ClientRMService: Storing Application with id application_1377721066246_0008
2013-08-28 20:34:40,728 INFO org.apache.hadoop.yarn.server.resourcemanager.recovery.RMStateStore: Storing info for app: application_1377721066246_0008
2013-08-28 20:34:40,728 INFO org.apache.hadoop.yarn.server.resourcemanager.ClientRMService: Application with id 8 submitted by user ubuntu
2013-08-28 20:34:40,728 INFO org.apache.hadoop.yarn.server.resourcemanager.RMAuditLogger: USER=ubuntu	IP=192.168.100.34	OPERATION=Submit Application Request	TARGET=ClientRMService	RESULT=SUCCESS	APPID=application_1377721066246_0008
2013-08-28 20:34:40,728 INFO org.apache.hadoop.yarn.server.resourcemanager.rmapp.RMAppImpl: application_1377721066246_0008 State change from NEW to SUBMITTED
2013-08-28 20:34:40,729 INFO org.apache.hadoop.yarn.server.resourcemanager.ApplicationMasterService: Registering appattempt_1377721066246_0008_000001
2013-08-28 20:34:40,729 INFO org.apache.hadoop.yarn.server.resourcemanager.rmapp.attempt.RMAppAttemptImpl: appattempt_1377721066246_0008_000001 State change from NEW to SUBMITTED
2013-08-28 20:34:40,731 INFO org.apache.hadoop.yarn.server.resourcemanager.scheduler.capacity.LeafQueue: Application application_1377721066246_0008 from user: ubuntu activated in queue: default
2013-08-28 20:34:40,731 INFO org.apache.hadoop.yarn.server.resourcemanager.scheduler.capacity.LeafQueue: Application added - appId: application_1377721066246_0008 user: org.apache.hadoop.yarn.server.resourcemanager.scheduler.capacity.LeafQueue$User@33a515d3, leaf-queue: default #user-pending-applications: 0 #user-active-applications: 1 #queue-pending-applications: 0 #queue-active-applications: 1
2013-08-28 20:34:40,731 INFO org.apache.hadoop.yarn.server.resourcemanager.scheduler.capacity.ParentQueue: Application added - appId: application_1377721066246_0008 user: ubuntu leaf-queue of parent: root #applications: 1
2013-08-28 20:34:40,731 INFO org.apache.hadoop.yarn.server.resourcemanager.scheduler.capacity.CapacityScheduler: Application Submission: appattempt_1377721066246_0008_000001, user: ubuntu queue: default: capacity=1.0, absoluteCapacity=1.0, usedResources=<memory:0, vCores:0>usedCapacity=0.0, absoluteUsedCapacity=0.0, numApps=1, numContainers=0, currently active: 1
2013-08-28 20:34:40,737 INFO org.apache.hadoop.yarn.server.resourcemanager.rmapp.attempt.RMAppAttemptImpl: appattempt_1377721066246_0008_000001 State change from SUBMITTED to SCHEDULED
2013-08-28 20:34:40,737 INFO org.apache.hadoop.yarn.server.resourcemanager.rmapp.RMAppImpl: application_1377721066246_0008 State change from SUBMITTED to ACCEPTED
2013-08-28 20:34:40,825 INFO org.apache.hadoop.yarn.server.resourcemanager.ClientRMService: Storing Application with id application_1377721066246_0006
2013-08-28 20:34:40,825 INFO org.apache.hadoop.yarn.server.resourcemanager.recovery.RMStateStore: Storing info for app: application_1377721066246_0006
2013-08-28 20:34:40,825 INFO org.apache.hadoop.yarn.server.resourcemanager.ClientRMService: Application with id 6 submitted by user ubuntu
2013-08-28 20:34:40,825 INFO org.apache.hadoop.yarn.server.resourcemanager.RMAuditLogger: USER=ubuntu	IP=192.168.100.34	OPERATION=Submit Application Request	TARGET=ClientRMService	RESULT=SUCCESS	APPID=application_1377721066246_0006
2013-08-28 20:34:40,827 INFO org.apache.hadoop.yarn.server.resourcemanager.rmapp.RMAppImpl: application_1377721066246_0006 State change from NEW to SUBMITTED
2013-08-28 20:34:40,827 INFO org.apache.hadoop.yarn.server.resourcemanager.ApplicationMasterService: Registering appattempt_1377721066246_0006_000001
2013-08-28 20:34:40,828 INFO org.apache.hadoop.yarn.server.resourcemanager.rmapp.attempt.RMAppAttemptImpl: appattempt_1377721066246_0006_000001 State change from NEW to SUBMITTED
2013-08-28 20:34:40,828 INFO org.apache.hadoop.yarn.server.resourcemanager.scheduler.capacity.LeafQueue: Application application_1377721066246_0006 from user: ubuntu activated in queue: default
2013-08-28 20:34:40,828 INFO org.apache.hadoop.yarn.server.resourcemanager.scheduler.capacity.LeafQueue: Application added - appId: application_1377721066246_0006 user: org.apache.hadoop.yarn.server.resourcemanager.scheduler.capacity.LeafQueue$User@33a515d3, leaf-queue: default #user-pending-applications: 0 #user-active-applications: 2 #queue-pending-applications: 0 #queue-active-applications: 2
2013-08-28 20:34:40,828 INFO org.apache.hadoop.yarn.server.resourcemanager.scheduler.capacity.ParentQueue: Application added - appId: application_1377721066246_0006 user: ubuntu leaf-queue of parent: root #applications: 2
2013-08-28 20:34:40,828 INFO org.apache.hadoop.yarn.server.resourcemanager.scheduler.capacity.CapacityScheduler: Application Submission: appattempt_1377721066246_0006_000001, user: ubuntu queue: default: capacity=1.0, absoluteCapacity=1.0, usedResources=<memory:0, vCores:0>usedCapacity=0.0, absoluteUsedCapacity=0.0, numApps=2, numContainers=0, currently active: 2
2013-08-28 20:34:40,828 INFO org.apache.hadoop.yarn.server.resourcemanager.rmapp.attempt.RMAppAttemptImpl: appattempt_1377721066246_0006_000001 State change from SUBMITTED to SCHEDULED
2013-08-28 20:34:40,829 INFO org.apache.hadoop.yarn.server.resourcemanager.rmapp.RMAppImpl: application_1377721066246_0006 State change from SUBMITTED to ACCEPTED
2013-08-28 20:34:40,973 INFO org.apache.hadoop.yarn.server.resourcemanager.rmcontainer.RMContainerImpl: container_1377721066246_0006_01_000001 Container Transitioned from NEW to ALLOCATED
2013-08-28 20:34:40,973 INFO org.apache.hadoop.yarn.server.resourcemanager.RMAuditLogger: USER=ubuntu	OPERATION=AM Allocated Container	TARGET=SchedulerApp	RESULT=SUCCESS	APPID=application_1377721066246_0006	CONTAINERID=container_1377721066246_0006_01_000001
2013-08-28 20:34:40,973 INFO org.apache.hadoop.yarn.server.resourcemanager.scheduler.common.fica.FiCaSchedulerNode: Assigned container container_1377721066246_0006_01_000001 of capacity <memory:2048, vCores:1> on host hadoop-17-2:52914, which currently has 1 containers, <memory:2048, vCores:1> used and <memory:6144, vCores:15> available
2013-08-28 20:34:40,974 INFO org.apache.hadoop.yarn.server.resourcemanager.scheduler.capacity.LeafQueue: assignedContainer application=application_1377721066246_0006 container=Container: [ContainerId: container_1377721066246_0006_01_000001, NodeId: hadoop-17-2:52914, NodeHttpAddress: hadoop-17-2:8042, Resource: <memory:2048, vCores:1>, Priority: 0, State: NEW, Token: null, Status: container_id {, app_attempt_id {, application_id {, id: 6, cluster_timestamp: 1377721066246, }, attemptId: 1, }, id: 1, }, state: C_NEW, ] containerId=container_1377721066246_0006_01_000001 queue=default: capacity=1.0, absoluteCapacity=1.0, usedResources=<memory:0, vCores:0>usedCapacity=0.0, absoluteUsedCapacity=0.0, numApps=2, numContainers=0 usedCapacity=0.0 absoluteUsedCapacity=0.0 used=<memory:0, vCores:0> cluster=<memory:49152, vCores:96>
2013-08-28 20:34:40,974 INFO org.apache.hadoop.yarn.server.resourcemanager.scheduler.capacity.ParentQueue: Re-sorting queues since queue: root.default stats: default: capacity=1.0, absoluteCapacity=1.0, usedResources=<memory:2048, vCores:1>usedCapacity=0.041666668, absoluteUsedCapacity=0.041666668, numApps=2, numContainers=1
2013-08-28 20:34:40,974 INFO org.apache.hadoop.yarn.server.resourcemanager.scheduler.capacity.ParentQueue: assignedContainer queue=root usedCapacity=0.041666668 absoluteUsedCapacity=0.041666668 used=<memory:2048, vCores:1> cluster=<memory:49152, vCores:96>
2013-08-28 20:34:40,975 INFO org.apache.hadoop.yarn.server.resourcemanager.rmcontainer.RMContainerImpl: container_1377721066246_0006_01_000001 Container Transitioned from ALLOCATED to ACQUIRED
2013-08-28 20:34:40,976 INFO org.apache.hadoop.yarn.server.resourcemanager.rmapp.attempt.RMAppAttemptImpl: Storing attempt: AppId: application_1377721066246_0006 AttemptId: appattempt_1377721066246_0006_000001 MasterContainer: Container: [ContainerId: container_1377721066246_0006_01_000001, NodeId: hadoop-17-2:52914, NodeHttpAddress: hadoop-17-2:8042, Resource: <memory:2048, vCores:1>, Priority: 0, State: NEW, Token: null, Status: container_id {, app_attempt_id {, application_id {, id: 6, cluster_timestamp: 1377721066246, }, attemptId: 1, }, id: 1, }, state: C_NEW, ]
2013-08-28 20:34:40,976 INFO org.apache.hadoop.yarn.server.resourcemanager.rmapp.attempt.RMAppAttemptImpl: appattempt_1377721066246_0006_000001 State change from SCHEDULED to ALLOCATED_SAVING
2013-08-28 20:34:40,976 INFO org.apache.hadoop.yarn.server.resourcemanager.recovery.RMStateStore: Storing info for attempt: appattempt_1377721066246_0006_000001
2013-08-28 20:34:40,976 INFO org.apache.hadoop.yarn.server.resourcemanager.rmapp.attempt.RMAppAttemptImpl: appattempt_1377721066246_0006_000001 State change from ALLOCATED_SAVING to ALLOCATED
2013-08-28 20:34:40,977 INFO org.apache.hadoop.yarn.server.resourcemanager.amlauncher.AMLauncher: Launching masterappattempt_1377721066246_0006_000001
2013-08-28 20:34:40,980 INFO org.apache.hadoop.yarn.server.resourcemanager.amlauncher.AMLauncher: Setting up container Container: [ContainerId: container_1377721066246_0006_01_000001, NodeId: hadoop-17-2:52914, NodeHttpAddress: hadoop-17-2:8042, Resource: <memory:2048, vCores:1>, Priority: 0, State: NEW, Token: null, Status: container_id {, app_attempt_id {, application_id {, id: 6, cluster_timestamp: 1377721066246, }, attemptId: 1, }, id: 1, }, state: C_NEW, ] for AM appattempt_1377721066246_0006_000001
2013-08-28 20:34:40,981 INFO org.apache.hadoop.yarn.server.resourcemanager.amlauncher.AMLauncher: Command to launch container container_1377721066246_0006_01_000001 : $JAVA_HOME/bin/java -Dlog4j.configuration=container-log4j.properties -Dyarn.app.mapreduce.container.log.dir=<LOG_DIR> -Dyarn.app.mapreduce.container.log.filesize=0 -Dhadoop.root.logger=INFO,CLA  -Xmx1024m org.apache.hadoop.mapreduce.v2.app.MRAppMaster 1><LOG_DIR>/stdout 2><LOG_DIR>/stderr 
2013-08-28 20:34:41,006 INFO org.apache.hadoop.yarn.server.resourcemanager.amlauncher.AMLauncher: Done launching container Container: [ContainerId: container_1377721066246_0006_01_000001, NodeId: hadoop-17-2:52914, NodeHttpAddress: hadoop-17-2:8042, Resource: <memory:2048, vCores:1>, Priority: 0, State: NEW, Token: null, Status: container_id {, app_attempt_id {, application_id {, id: 6, cluster_timestamp: 1377721066246, }, attemptId: 1, }, id: 1, }, state: C_NEW, ] for AM appattempt_1377721066246_0006_000001
2013-08-28 20:34:41,007 INFO org.apache.hadoop.yarn.server.resourcemanager.rmapp.attempt.RMAppAttemptImpl: appattempt_1377721066246_0006_000001 State change from ALLOCATED to LAUNCHED
2013-08-28 20:34:41,015 INFO org.apache.hadoop.yarn.server.resourcemanager.rmcontainer.RMContainerImpl: container_1377721066246_0008_01_000001 Container Transitioned from NEW to ALLOCATED
2013-08-28 20:34:41,015 INFO org.apache.hadoop.yarn.server.resourcemanager.RMAuditLogger: USER=ubuntu	OPERATION=AM Allocated Container	TARGET=SchedulerApp	RESULT=SUCCESS	APPID=application_1377721066246_0008	CONTAINERID=container_1377721066246_0008_01_000001
2013-08-28 20:34:41,015 INFO org.apache.hadoop.yarn.server.resourcemanager.scheduler.common.fica.FiCaSchedulerNode: Assigned container container_1377721066246_0008_01_000001 of capacity <memory:2048, vCores:1> on host hadoop-17-4:59779, which currently has 1 containers, <memory:2048, vCores:1> used and <memory:6144, vCores:15> available
2013-08-28 20:34:41,016 INFO org.apache.hadoop.yarn.server.resourcemanager.scheduler.capacity.LeafQueue: assignedContainer application=application_1377721066246_0008 container=Container: [ContainerId: container_1377721066246_0008_01_000001, NodeId: hadoop-17-4:59779, NodeHttpAddress: hadoop-17-4:8042, Resource: <memory:2048, vCores:1>, Priority: 0, State: NEW, Token: null, Status: container_id {, app_attempt_id {, application_id {, id: 8, cluster_timestamp: 1377721066246, }, attemptId: 1, }, id: 1, }, state: C_NEW, ] containerId=container_1377721066246_0008_01_000001 queue=default: capacity=1.0, absoluteCapacity=1.0, usedResources=<memory:2048, vCores:1>usedCapacity=0.041666668, absoluteUsedCapacity=0.041666668, numApps=2, numContainers=1 usedCapacity=0.041666668 absoluteUsedCapacity=0.041666668 used=<memory:2048, vCores:1> cluster=<memory:49152, vCores:96>
2013-08-28 20:34:41,016 INFO org.apache.hadoop.yarn.server.resourcemanager.scheduler.capacity.ParentQueue: Re-sorting queues since queue: root.default stats: default: capacity=1.0, absoluteCapacity=1.0, usedResources=<memory:4096, vCores:2>usedCapacity=0.083333336, absoluteUsedCapacity=0.083333336, numApps=2, numContainers=2
2013-08-28 20:34:41,016 INFO org.apache.hadoop.yarn.server.resourcemanager.scheduler.capacity.ParentQueue: assignedContainer queue=root usedCapacity=0.083333336 absoluteUsedCapacity=0.083333336 used=<memory:4096, vCores:2> cluster=<memory:49152, vCores:96>
2013-08-28 20:34:41,017 INFO org.apache.hadoop.yarn.server.resourcemanager.rmcontainer.RMContainerImpl: container_1377721066246_0008_01_000001 Container Transitioned from ALLOCATED to ACQUIRED
2013-08-28 20:34:41,018 INFO org.apache.hadoop.yarn.server.resourcemanager.rmapp.attempt.RMAppAttemptImpl: Storing attempt: AppId: application_1377721066246_0008 AttemptId: appattempt_1377721066246_0008_000001 MasterContainer: Container: [ContainerId: container_1377721066246_0008_01_000001, NodeId: hadoop-17-4:59779, NodeHttpAddress: hadoop-17-4:8042, Resource: <memory:2048, vCores:1>, Priority: 0, State: NEW, Token: null, Status: container_id {, app_attempt_id {, application_id {, id: 8, cluster_timestamp: 1377721066246, }, attemptId: 1, }, id: 1, }, state: C_NEW, ]
2013-08-28 20:34:41,018 INFO org.apache.hadoop.yarn.server.resourcemanager.rmapp.attempt.RMAppAttemptImpl: appattempt_1377721066246_0008_000001 State change from SCHEDULED to ALLOCATED_SAVING
2013-08-28 20:34:41,018 INFO org.apache.hadoop.yarn.server.resourcemanager.recovery.RMStateStore: Storing info for attempt: appattempt_1377721066246_0008_000001
2013-08-28 20:34:41,019 INFO org.apache.hadoop.yarn.server.resourcemanager.rmapp.attempt.RMAppAttemptImpl: appattempt_1377721066246_0008_000001 State change from ALLOCATED_SAVING to ALLOCATED
2013-08-28 20:34:41,020 INFO org.apache.hadoop.yarn.server.resourcemanager.amlauncher.AMLauncher: Launching masterappattempt_1377721066246_0008_000001
2013-08-28 20:34:41,022 INFO org.apache.hadoop.yarn.server.resourcemanager.amlauncher.AMLauncher: Setting up container Container: [ContainerId: container_1377721066246_0008_01_000001, NodeId: hadoop-17-4:59779, NodeHttpAddress: hadoop-17-4:8042, Resource: <memory:2048, vCores:1>, Priority: 0, State: NEW, Token: null, Status: container_id {, app_attempt_id {, application_id {, id: 8, cluster_timestamp: 1377721066246, }, attemptId: 1, }, id: 1, }, state: C_NEW, ] for AM appattempt_1377721066246_0008_000001
2013-08-28 20:34:41,022 INFO org.apache.hadoop.yarn.server.resourcemanager.amlauncher.AMLauncher: Command to launch container container_1377721066246_0008_01_000001 : $JAVA_HOME/bin/java -Dlog4j.configuration=container-log4j.properties -Dyarn.app.mapreduce.container.log.dir=<LOG_DIR> -Dyarn.app.mapreduce.container.log.filesize=0 -Dhadoop.root.logger=INFO,CLA  -Xmx1024m org.apache.hadoop.mapreduce.v2.app.MRAppMaster 1><LOG_DIR>/stdout 2><LOG_DIR>/stderr 
2013-08-28 20:34:41,036 INFO org.apache.hadoop.yarn.server.resourcemanager.amlauncher.AMLauncher: Done launching container Container: [ContainerId: container_1377721066246_0008_01_000001, NodeId: hadoop-17-4:59779, NodeHttpAddress: hadoop-17-4:8042, Resource: <memory:2048, vCores:1>, Priority: 0, State: NEW, Token: null, Status: container_id {, app_attempt_id {, application_id {, id: 8, cluster_timestamp: 1377721066246, }, attemptId: 1, }, id: 1, }, state: C_NEW, ] for AM appattempt_1377721066246_0008_000001
2013-08-28 20:34:41,037 INFO org.apache.hadoop.yarn.server.resourcemanager.rmapp.attempt.RMAppAttemptImpl: appattempt_1377721066246_0008_000001 State change from ALLOCATED to LAUNCHED
2013-08-28 20:34:41,049 INFO org.apache.hadoop.yarn.server.resourcemanager.ClientRMService: Storing Application with id application_1377721066246_0009
2013-08-28 20:34:41,049 INFO org.apache.hadoop.yarn.server.resourcemanager.recovery.RMStateStore: Storing info for app: application_1377721066246_0009
2013-08-28 20:34:41,049 INFO org.apache.hadoop.yarn.server.resourcemanager.ClientRMService: Application with id 9 submitted by user ubuntu
2013-08-28 20:34:41,049 INFO org.apache.hadoop.yarn.server.resourcemanager.RMAuditLogger: USER=ubuntu	IP=192.168.100.34	OPERATION=Submit Application Request	TARGET=ClientRMService	RESULT=SUCCESS	APPID=application_1377721066246_0009
2013-08-28 20:34:41,050 INFO org.apache.hadoop.yarn.server.resourcemanager.rmapp.RMAppImpl: application_1377721066246_0009 State change from NEW to SUBMITTED
2013-08-28 20:34:41,050 INFO org.apache.hadoop.yarn.server.resourcemanager.ApplicationMasterService: Registering appattempt_1377721066246_0009_000001
2013-08-28 20:34:41,050 INFO org.apache.hadoop.yarn.server.resourcemanager.rmapp.attempt.RMAppAttemptImpl: appattempt_1377721066246_0009_000001 State change from NEW to SUBMITTED
2013-08-28 20:34:41,050 INFO org.apache.hadoop.yarn.server.resourcemanager.scheduler.capacity.LeafQueue: Application application_1377721066246_0009 from user: ubuntu activated in queue: default
2013-08-28 20:34:41,050 INFO org.apache.hadoop.yarn.server.resourcemanager.scheduler.capacity.LeafQueue: Application added - appId: application_1377721066246_0009 user: org.apache.hadoop.yarn.server.resourcemanager.scheduler.capacity.LeafQueue$User@33a515d3, leaf-queue: default #user-pending-applications: 0 #user-active-applications: 3 #queue-pending-applications: 0 #queue-active-applications: 3
2013-08-28 20:34:41,050 INFO org.apache.hadoop.yarn.server.resourcemanager.scheduler.capacity.ParentQueue: Application added - appId: application_1377721066246_0009 user: ubuntu leaf-queue of parent: root #applications: 3
2013-08-28 20:34:41,051 INFO org.apache.hadoop.yarn.server.resourcemanager.scheduler.capacity.CapacityScheduler: Application Submission: appattempt_1377721066246_0009_000001, user: ubuntu queue: default: capacity=1.0, absoluteCapacity=1.0, usedResources=<memory:4096, vCores:2>usedCapacity=0.083333336, absoluteUsedCapacity=0.083333336, numApps=3, numContainers=2, currently active: 3
2013-08-28 20:34:41,051 INFO org.apache.hadoop.yarn.server.resourcemanager.rmapp.attempt.RMAppAttemptImpl: appattempt_1377721066246_0009_000001 State change from SUBMITTED to SCHEDULED
2013-08-28 20:34:41,051 INFO org.apache.hadoop.yarn.server.resourcemanager.rmapp.RMAppImpl: application_1377721066246_0009 State change from SUBMITTED to ACCEPTED
2013-08-28 20:34:41,082 INFO org.apache.hadoop.yarn.server.resourcemanager.rmcontainer.RMContainerImpl: container_1377721066246_0009_01_000001 Container Transitioned from NEW to ALLOCATED
2013-08-28 20:34:41,082 INFO org.apache.hadoop.yarn.server.resourcemanager.RMAuditLogger: USER=ubuntu	OPERATION=AM Allocated Container	TARGET=SchedulerApp	RESULT=SUCCESS	APPID=application_1377721066246_0009	CONTAINERID=container_1377721066246_0009_01_000001
2013-08-28 20:34:41,082 INFO org.apache.hadoop.yarn.server.resourcemanager.scheduler.common.fica.FiCaSchedulerNode: Assigned container container_1377721066246_0009_01_000001 of capacity <memory:2048, vCores:1> on host hadoop-17-7:49112, which currently has 1 containers, <memory:2048, vCores:1> used and <memory:6144, vCores:15> available
2013-08-28 20:34:41,083 INFO org.apache.hadoop.yarn.server.resourcemanager.scheduler.capacity.LeafQueue: assignedContainer application=application_1377721066246_0009 container=Container: [ContainerId: container_1377721066246_0009_01_000001, NodeId: hadoop-17-7:49112, NodeHttpAddress: hadoop-17-7:8042, Resource: <memory:2048, vCores:1>, Priority: 0, State: NEW, Token: null, Status: container_id {, app_attempt_id {, application_id {, id: 9, cluster_timestamp: 1377721066246, }, attemptId: 1, }, id: 1, }, state: C_NEW, ] containerId=container_1377721066246_0009_01_000001 queue=default: capacity=1.0, absoluteCapacity=1.0, usedResources=<memory:4096, vCores:2>usedCapacity=0.083333336, absoluteUsedCapacity=0.083333336, numApps=3, numContainers=2 usedCapacity=0.083333336 absoluteUsedCapacity=0.083333336 used=<memory:4096, vCores:2> cluster=<memory:49152, vCores:96>
2013-08-28 20:34:41,083 INFO org.apache.hadoop.yarn.server.resourcemanager.scheduler.capacity.ParentQueue: Re-sorting queues since queue: root.default stats: default: capacity=1.0, absoluteCapacity=1.0, usedResources=<memory:6144, vCores:3>usedCapacity=0.125, absoluteUsedCapacity=0.125, numApps=3, numContainers=3
2013-08-28 20:34:41,083 INFO org.apache.hadoop.yarn.server.resourcemanager.scheduler.capacity.ParentQueue: assignedContainer queue=root usedCapacity=0.125 absoluteUsedCapacity=0.125 used=<memory:6144, vCores:3> cluster=<memory:49152, vCores:96>
2013-08-28 20:34:41,083 INFO org.apache.hadoop.yarn.server.resourcemanager.rmcontainer.RMContainerImpl: container_1377721066246_0009_01_000001 Container Transitioned from ALLOCATED to ACQUIRED
2013-08-28 20:34:41,084 INFO org.apache.hadoop.yarn.server.resourcemanager.rmapp.attempt.RMAppAttemptImpl: Storing attempt: AppId: application_1377721066246_0009 AttemptId: appattempt_1377721066246_0009_000001 MasterContainer: Container: [ContainerId: container_1377721066246_0009_01_000001, NodeId: hadoop-17-7:49112, NodeHttpAddress: hadoop-17-7:8042, Resource: <memory:2048, vCores:1>, Priority: 0, State: NEW, Token: null, Status: container_id {, app_attempt_id {, application_id {, id: 9, cluster_timestamp: 1377721066246, }, attemptId: 1, }, id: 1, }, state: C_NEW, ]
2013-08-28 20:34:41,084 INFO org.apache.hadoop.yarn.server.resourcemanager.rmapp.attempt.RMAppAttemptImpl: appattempt_1377721066246_0009_000001 State change from SCHEDULED to ALLOCATED_SAVING
2013-08-28 20:34:41,085 INFO org.apache.hadoop.yarn.server.resourcemanager.recovery.RMStateStore: Storing info for attempt: appattempt_1377721066246_0009_000001
2013-08-28 20:34:41,085 INFO org.apache.hadoop.yarn.server.resourcemanager.rmapp.attempt.RMAppAttemptImpl: appattempt_1377721066246_0009_000001 State change from ALLOCATED_SAVING to ALLOCATED
2013-08-28 20:34:41,085 INFO org.apache.hadoop.yarn.server.resourcemanager.amlauncher.AMLauncher: Launching masterappattempt_1377721066246_0009_000001
2013-08-28 20:34:41,086 INFO org.apache.hadoop.yarn.server.resourcemanager.amlauncher.AMLauncher: Setting up container Container: [ContainerId: container_1377721066246_0009_01_000001, NodeId: hadoop-17-7:49112, NodeHttpAddress: hadoop-17-7:8042, Resource: <memory:2048, vCores:1>, Priority: 0, State: NEW, Token: null, Status: container_id {, app_attempt_id {, application_id {, id: 9, cluster_timestamp: 1377721066246, }, attemptId: 1, }, id: 1, }, state: C_NEW, ] for AM appattempt_1377721066246_0009_000001
2013-08-28 20:34:41,087 INFO org.apache.hadoop.yarn.server.resourcemanager.amlauncher.AMLauncher: Command to launch container container_1377721066246_0009_01_000001 : $JAVA_HOME/bin/java -Dlog4j.configuration=container-log4j.properties -Dyarn.app.mapreduce.container.log.dir=<LOG_DIR> -Dyarn.app.mapreduce.container.log.filesize=0 -Dhadoop.root.logger=INFO,CLA  -Xmx1024m org.apache.hadoop.mapreduce.v2.app.MRAppMaster 1><LOG_DIR>/stdout 2><LOG_DIR>/stderr 
2013-08-28 20:34:41,108 INFO org.apache.hadoop.yarn.server.resourcemanager.amlauncher.AMLauncher: Done launching container Container: [ContainerId: container_1377721066246_0009_01_000001, NodeId: hadoop-17-7:49112, NodeHttpAddress: hadoop-17-7:8042, Resource: <memory:2048, vCores:1>, Priority: 0, State: NEW, Token: null, Status: container_id {, app_attempt_id {, application_id {, id: 9, cluster_timestamp: 1377721066246, }, attemptId: 1, }, id: 1, }, state: C_NEW, ] for AM appattempt_1377721066246_0009_000001
2013-08-28 20:34:41,108 INFO org.apache.hadoop.yarn.server.resourcemanager.rmapp.attempt.RMAppAttemptImpl: appattempt_1377721066246_0009_000001 State change from ALLOCATED to LAUNCHED
2013-08-28 20:34:41,132 INFO org.apache.hadoop.yarn.server.resourcemanager.ClientRMService: Storing Application with id application_1377721066246_0010
2013-08-28 20:34:41,132 INFO org.apache.hadoop.yarn.server.resourcemanager.recovery.RMStateStore: Storing info for app: application_1377721066246_0010
2013-08-28 20:34:41,132 INFO org.apache.hadoop.yarn.server.resourcemanager.ClientRMService: Application with id 10 submitted by user ubuntu
2013-08-28 20:34:41,132 INFO org.apache.hadoop.yarn.server.resourcemanager.RMAuditLogger: USER=ubuntu	IP=192.168.100.34	OPERATION=Submit Application Request	TARGET=ClientRMService	RESULT=SUCCESS	APPID=application_1377721066246_0010
2013-08-28 20:34:41,140 INFO org.apache.hadoop.yarn.server.resourcemanager.rmapp.RMAppImpl: application_1377721066246_0010 State change from NEW to SUBMITTED
2013-08-28 20:34:41,140 INFO org.apache.hadoop.yarn.server.resourcemanager.ApplicationMasterService: Registering appattempt_1377721066246_0010_000001
2013-08-28 20:34:41,141 INFO org.apache.hadoop.yarn.server.resourcemanager.rmapp.attempt.RMAppAttemptImpl: appattempt_1377721066246_0010_000001 State change from NEW to SUBMITTED
2013-08-28 20:34:41,141 INFO org.apache.hadoop.yarn.server.resourcemanager.scheduler.capacity.LeafQueue: Application application_1377721066246_0010 from user: ubuntu activated in queue: default
2013-08-28 20:34:41,141 INFO org.apache.hadoop.yarn.server.resourcemanager.scheduler.capacity.LeafQueue: Application added - appId: application_1377721066246_0010 user: org.apache.hadoop.yarn.server.resourcemanager.scheduler.capacity.LeafQueue$User@33a515d3, leaf-queue: default #user-pending-applications: 0 #user-active-applications: 4 #queue-pending-applications: 0 #queue-active-applications: 4
2013-08-28 20:34:41,141 INFO org.apache.hadoop.yarn.server.resourcemanager.scheduler.capacity.ParentQueue: Application added - appId: application_1377721066246_0010 user: ubuntu leaf-queue of parent: root #applications: 4
2013-08-28 20:34:41,142 INFO org.apache.hadoop.yarn.server.resourcemanager.scheduler.capacity.CapacityScheduler: Application Submission: appattempt_1377721066246_0010_000001, user: ubuntu queue: default: capacity=1.0, absoluteCapacity=1.0, usedResources=<memory:6144, vCores:3>usedCapacity=0.125, absoluteUsedCapacity=0.125, numApps=4, numContainers=3, currently active: 4
2013-08-28 20:34:41,142 INFO org.apache.hadoop.yarn.server.resourcemanager.rmapp.attempt.RMAppAttemptImpl: appattempt_1377721066246_0010_000001 State change from SUBMITTED to SCHEDULED
2013-08-28 20:34:41,142 INFO org.apache.hadoop.yarn.server.resourcemanager.rmapp.RMAppImpl: application_1377721066246_0010 State change from SUBMITTED to ACCEPTED
2013-08-28 20:34:41,154 INFO org.apache.hadoop.yarn.server.resourcemanager.rmcontainer.RMContainerImpl: container_1377721066246_0010_01_000001 Container Transitioned from NEW to ALLOCATED
2013-08-28 20:34:41,155 INFO org.apache.hadoop.yarn.server.resourcemanager.RMAuditLogger: USER=ubuntu	OPERATION=AM Allocated Container	TARGET=SchedulerApp	RESULT=SUCCESS	APPID=application_1377721066246_0010	CONTAINERID=container_1377721066246_0010_01_000001
2013-08-28 20:34:41,155 INFO org.apache.hadoop.yarn.server.resourcemanager.scheduler.common.fica.FiCaSchedulerNode: Assigned container container_1377721066246_0010_01_000001 of capacity <memory:2048, vCores:1> on host hadoop-17-3:35481, which currently has 1 containers, <memory:2048, vCores:1> used and <memory:6144, vCores:15> available
2013-08-28 20:34:41,156 INFO org.apache.hadoop.yarn.server.resourcemanager.scheduler.capacity.LeafQueue: assignedContainer application=application_1377721066246_0010 container=Container: [ContainerId: container_1377721066246_0010_01_000001, NodeId: hadoop-17-3:35481, NodeHttpAddress: hadoop-17-3:8042, Resource: <memory:2048, vCores:1>, Priority: 0, State: NEW, Token: null, Status: container_id {, app_attempt_id {, application_id {, id: 10, cluster_timestamp: 1377721066246, }, attemptId: 1, }, id: 1, }, state: C_NEW, ] containerId=container_1377721066246_0010_01_000001 queue=default: capacity=1.0, absoluteCapacity=1.0, usedResources=<memory:6144, vCores:3>usedCapacity=0.125, absoluteUsedCapacity=0.125, numApps=4, numContainers=3 usedCapacity=0.125 absoluteUsedCapacity=0.125 used=<memory:6144, vCores:3> cluster=<memory:49152, vCores:96>
2013-08-28 20:34:41,156 INFO org.apache.hadoop.yarn.server.resourcemanager.scheduler.capacity.ParentQueue: Re-sorting queues since queue: root.default stats: default: capacity=1.0, absoluteCapacity=1.0, usedResources=<memory:8192, vCores:4>usedCapacity=0.16666667, absoluteUsedCapacity=0.16666667, numApps=4, numContainers=4
2013-08-28 20:34:41,156 INFO org.apache.hadoop.yarn.server.resourcemanager.scheduler.capacity.ParentQueue: assignedContainer queue=root usedCapacity=0.16666667 absoluteUsedCapacity=0.16666667 used=<memory:8192, vCores:4> cluster=<memory:49152, vCores:96>
2013-08-28 20:34:41,157 INFO org.apache.hadoop.yarn.server.resourcemanager.rmcontainer.RMContainerImpl: container_1377721066246_0010_01_000001 Container Transitioned from ALLOCATED to ACQUIRED
2013-08-28 20:34:41,157 INFO org.apache.hadoop.yarn.server.resourcemanager.rmapp.attempt.RMAppAttemptImpl: Storing attempt: AppId: application_1377721066246_0010 AttemptId: appattempt_1377721066246_0010_000001 MasterContainer: Container: [ContainerId: container_1377721066246_0010_01_000001, NodeId: hadoop-17-3:35481, NodeHttpAddress: hadoop-17-3:8042, Resource: <memory:2048, vCores:1>, Priority: 0, State: NEW, Token: null, Status: container_id {, app_attempt_id {, application_id {, id: 10, cluster_timestamp: 1377721066246, }, attemptId: 1, }, id: 1, }, state: C_NEW, ]
2013-08-28 20:34:41,158 INFO org.apache.hadoop.yarn.server.resourcemanager.rmapp.attempt.RMAppAttemptImpl: appattempt_1377721066246_0010_000001 State change from SCHEDULED to ALLOCATED_SAVING
2013-08-28 20:34:41,158 INFO org.apache.hadoop.yarn.server.resourcemanager.recovery.RMStateStore: Storing info for attempt: appattempt_1377721066246_0010_000001
2013-08-28 20:34:41,159 INFO org.apache.hadoop.yarn.server.resourcemanager.rmapp.attempt.RMAppAttemptImpl: appattempt_1377721066246_0010_000001 State change from ALLOCATED_SAVING to ALLOCATED
2013-08-28 20:34:41,159 INFO org.apache.hadoop.yarn.server.resourcemanager.amlauncher.AMLauncher: Launching masterappattempt_1377721066246_0010_000001
2013-08-28 20:34:41,160 INFO org.apache.hadoop.yarn.server.resourcemanager.amlauncher.AMLauncher: Setting up container Container: [ContainerId: container_1377721066246_0010_01_000001, NodeId: hadoop-17-3:35481, NodeHttpAddress: hadoop-17-3:8042, Resource: <memory:2048, vCores:1>, Priority: 0, State: NEW, Token: null, Status: container_id {, app_attempt_id {, application_id {, id: 10, cluster_timestamp: 1377721066246, }, attemptId: 1, }, id: 1, }, state: C_NEW, ] for AM appattempt_1377721066246_0010_000001
2013-08-28 20:34:41,160 INFO org.apache.hadoop.yarn.server.resourcemanager.amlauncher.AMLauncher: Command to launch container container_1377721066246_0010_01_000001 : $JAVA_HOME/bin/java -Dlog4j.configuration=container-log4j.properties -Dyarn.app.mapreduce.container.log.dir=<LOG_DIR> -Dyarn.app.mapreduce.container.log.filesize=0 -Dhadoop.root.logger=INFO,CLA  -Xmx1024m org.apache.hadoop.mapreduce.v2.app.MRAppMaster 1><LOG_DIR>/stdout 2><LOG_DIR>/stderr 
2013-08-28 20:34:41,176 INFO org.apache.hadoop.yarn.server.resourcemanager.amlauncher.AMLauncher: Done launching container Container: [ContainerId: container_1377721066246_0010_01_000001, NodeId: hadoop-17-3:35481, NodeHttpAddress: hadoop-17-3:8042, Resource: <memory:2048, vCores:1>, Priority: 0, State: NEW, Token: null, Status: container_id {, app_attempt_id {, application_id {, id: 10, cluster_timestamp: 1377721066246, }, attemptId: 1, }, id: 1, }, state: C_NEW, ] for AM appattempt_1377721066246_0010_000001
2013-08-28 20:34:41,176 INFO org.apache.hadoop.yarn.server.resourcemanager.rmapp.attempt.RMAppAttemptImpl: appattempt_1377721066246_0010_000001 State change from ALLOCATED to LAUNCHED
2013-08-28 20:34:41,198 INFO org.apache.hadoop.yarn.server.resourcemanager.ClientRMService: Storing Application with id application_1377721066246_0007
2013-08-28 20:34:41,198 INFO org.apache.hadoop.yarn.server.resourcemanager.recovery.RMStateStore: Storing info for app: application_1377721066246_0007
2013-08-28 20:34:41,198 INFO org.apache.hadoop.yarn.server.resourcemanager.ClientRMService: Application with id 7 submitted by user ubuntu
2013-08-28 20:34:41,198 INFO org.apache.hadoop.yarn.server.resourcemanager.RMAuditLogger: USER=ubuntu	IP=192.168.100.34	OPERATION=Submit Application Request	TARGET=ClientRMService	RESULT=SUCCESS	APPID=application_1377721066246_0007
2013-08-28 20:34:41,199 INFO org.apache.hadoop.yarn.server.resourcemanager.rmapp.RMAppImpl: application_1377721066246_0007 State change from NEW to SUBMITTED
2013-08-28 20:34:41,199 INFO org.apache.hadoop.yarn.server.resourcemanager.ApplicationMasterService: Registering appattempt_1377721066246_0007_000001
2013-08-28 20:34:41,199 INFO org.apache.hadoop.yarn.server.resourcemanager.rmapp.attempt.RMAppAttemptImpl: appattempt_1377721066246_0007_000001 State change from NEW to SUBMITTED
2013-08-28 20:34:41,199 INFO org.apache.hadoop.yarn.server.resourcemanager.scheduler.capacity.LeafQueue: Application application_1377721066246_0007 from user: ubuntu activated in queue: default
2013-08-28 20:34:41,199 INFO org.apache.hadoop.yarn.server.resourcemanager.scheduler.capacity.LeafQueue: Application added - appId: application_1377721066246_0007 user: org.apache.hadoop.yarn.server.resourcemanager.scheduler.capacity.LeafQueue$User@33a515d3, leaf-queue: default #user-pending-applications: 0 #user-active-applications: 5 #queue-pending-applications: 0 #queue-active-applications: 5
2013-08-28 20:34:41,199 INFO org.apache.hadoop.yarn.server.resourcemanager.scheduler.capacity.ParentQueue: Application added - appId: application_1377721066246_0007 user: ubuntu leaf-queue of parent: root #applications: 5
2013-08-28 20:34:41,200 INFO org.apache.hadoop.yarn.server.resourcemanager.scheduler.capacity.CapacityScheduler: Application Submission: appattempt_1377721066246_0007_000001, user: ubuntu queue: default: capacity=1.0, absoluteCapacity=1.0, usedResources=<memory:8192, vCores:4>usedCapacity=0.16666667, absoluteUsedCapacity=0.16666667, numApps=5, numContainers=4, currently active: 5
2013-08-28 20:34:41,200 INFO org.apache.hadoop.yarn.server.resourcemanager.rmapp.attempt.RMAppAttemptImpl: appattempt_1377721066246_0007_000001 State change from SUBMITTED to SCHEDULED
2013-08-28 20:34:41,200 INFO org.apache.hadoop.yarn.server.resourcemanager.rmapp.RMAppImpl: application_1377721066246_0007 State change from SUBMITTED to ACCEPTED
2013-08-28 20:34:41,233 INFO org.apache.hadoop.yarn.server.resourcemanager.rmcontainer.RMContainerImpl: container_1377721066246_0007_01_000001 Container Transitioned from NEW to ALLOCATED
2013-08-28 20:34:41,233 INFO org.apache.hadoop.yarn.server.resourcemanager.RMAuditLogger: USER=ubuntu	OPERATION=AM Allocated Container	TARGET=SchedulerApp	RESULT=SUCCESS	APPID=application_1377721066246_0007	CONTAINERID=container_1377721066246_0007_01_000001
2013-08-28 20:34:41,233 INFO org.apache.hadoop.yarn.server.resourcemanager.scheduler.common.fica.FiCaSchedulerNode: Assigned container container_1377721066246_0007_01_000001 of capacity <memory:2048, vCores:1> on host hadoop-17-5:46576, which currently has 1 containers, <memory:2048, vCores:1> used and <memory:6144, vCores:15> available
2013-08-28 20:34:41,234 INFO org.apache.hadoop.yarn.server.resourcemanager.scheduler.capacity.LeafQueue: assignedContainer application=application_1377721066246_0007 container=Container: [ContainerId: container_1377721066246_0007_01_000001, NodeId: hadoop-17-5:46576, NodeHttpAddress: hadoop-17-5:8042, Resource: <memory:2048, vCores:1>, Priority: 0, State: NEW, Token: null, Status: container_id {, app_attempt_id {, application_id {, id: 7, cluster_timestamp: 1377721066246, }, attemptId: 1, }, id: 1, }, state: C_NEW, ] containerId=container_1377721066246_0007_01_000001 queue=default: capacity=1.0, absoluteCapacity=1.0, usedResources=<memory:8192, vCores:4>usedCapacity=0.16666667, absoluteUsedCapacity=0.16666667, numApps=5, numContainers=4 usedCapacity=0.16666667 absoluteUsedCapacity=0.16666667 used=<memory:8192, vCores:4> cluster=<memory:49152, vCores:96>
2013-08-28 20:34:41,234 INFO org.apache.hadoop.yarn.server.resourcemanager.scheduler.capacity.ParentQueue: Re-sorting queues since queue: root.default stats: default: capacity=1.0, absoluteCapacity=1.0, usedResources=<memory:10240, vCores:5>usedCapacity=0.20833333, absoluteUsedCapacity=0.20833333, numApps=5, numContainers=5
2013-08-28 20:34:41,234 INFO org.apache.hadoop.yarn.server.resourcemanager.scheduler.capacity.ParentQueue: assignedContainer queue=root usedCapacity=0.20833333 absoluteUsedCapacity=0.20833333 used=<memory:10240, vCores:5> cluster=<memory:49152, vCores:96>
2013-08-28 20:34:41,235 INFO org.apache.hadoop.yarn.server.resourcemanager.rmcontainer.RMContainerImpl: container_1377721066246_0007_01_000001 Container Transitioned from ALLOCATED to ACQUIRED
2013-08-28 20:34:41,236 INFO org.apache.hadoop.yarn.server.resourcemanager.rmapp.attempt.RMAppAttemptImpl: Storing attempt: AppId: application_1377721066246_0007 AttemptId: appattempt_1377721066246_0007_000001 MasterContainer: Container: [ContainerId: container_1377721066246_0007_01_000001, NodeId: hadoop-17-5:46576, NodeHttpAddress: hadoop-17-5:8042, Resource: <memory:2048, vCores:1>, Priority: 0, State: NEW, Token: null, Status: container_id {, app_attempt_id {, application_id {, id: 7, cluster_timestamp: 1377721066246, }, attemptId: 1, }, id: 1, }, state: C_NEW, ]
2013-08-28 20:34:41,237 INFO org.apache.hadoop.yarn.server.resourcemanager.recovery.RMStateStore: Storing info for attempt: appattempt_1377721066246_0007_000001
2013-08-28 20:34:41,237 INFO org.apache.hadoop.yarn.server.resourcemanager.rmapp.attempt.RMAppAttemptImpl: appattempt_1377721066246_0007_000001 State change from SCHEDULED to ALLOCATED_SAVING
2013-08-28 20:34:41,238 INFO org.apache.hadoop.yarn.server.resourcemanager.rmapp.attempt.RMAppAttemptImpl: appattempt_1377721066246_0007_000001 State change from ALLOCATED_SAVING to ALLOCATED
2013-08-28 20:34:41,238 INFO org.apache.hadoop.yarn.server.resourcemanager.amlauncher.AMLauncher: Launching masterappattempt_1377721066246_0007_000001
2013-08-28 20:34:41,239 INFO org.apache.hadoop.yarn.server.resourcemanager.amlauncher.AMLauncher: Setting up container Container: [ContainerId: container_1377721066246_0007_01_000001, NodeId: hadoop-17-5:46576, NodeHttpAddress: hadoop-17-5:8042, Resource: <memory:2048, vCores:1>, Priority: 0, State: NEW, Token: null, Status: container_id {, app_attempt_id {, application_id {, id: 7, cluster_timestamp: 1377721066246, }, attemptId: 1, }, id: 1, }, state: C_NEW, ] for AM appattempt_1377721066246_0007_000001
2013-08-28 20:34:41,239 INFO org.apache.hadoop.yarn.server.resourcemanager.amlauncher.AMLauncher: Command to launch container container_1377721066246_0007_01_000001 : $JAVA_HOME/bin/java -Dlog4j.configuration=container-log4j.properties -Dyarn.app.mapreduce.container.log.dir=<LOG_DIR> -Dyarn.app.mapreduce.container.log.filesize=0 -Dhadoop.root.logger=INFO,CLA  -Xmx1024m org.apache.hadoop.mapreduce.v2.app.MRAppMaster 1><LOG_DIR>/stdout 2><LOG_DIR>/stderr 
2013-08-28 20:34:41,252 INFO org.apache.hadoop.yarn.server.resourcemanager.amlauncher.AMLauncher: Done launching container Container: [ContainerId: container_1377721066246_0007_01_000001, NodeId: hadoop-17-5:46576, NodeHttpAddress: hadoop-17-5:8042, Resource: <memory:2048, vCores:1>, Priority: 0, State: NEW, Token: null, Status: container_id {, app_attempt_id {, application_id {, id: 7, cluster_timestamp: 1377721066246, }, attemptId: 1, }, id: 1, }, state: C_NEW, ] for AM appattempt_1377721066246_0007_000001
2013-08-28 20:34:41,252 INFO org.apache.hadoop.yarn.server.resourcemanager.rmapp.attempt.RMAppAttemptImpl: appattempt_1377721066246_0007_000001 State change from ALLOCATED to LAUNCHED
2013-08-28 20:34:41,977 INFO org.apache.hadoop.yarn.server.resourcemanager.rmcontainer.RMContainerImpl: container_1377721066246_0006_01_000001 Container Transitioned from ACQUIRED to RUNNING
2013-08-28 20:34:42,019 INFO org.apache.hadoop.yarn.server.resourcemanager.rmcontainer.RMContainerImpl: container_1377721066246_0008_01_000001 Container Transitioned from ACQUIRED to RUNNING
2013-08-28 20:34:42,088 INFO org.apache.hadoop.yarn.server.resourcemanager.rmcontainer.RMContainerImpl: container_1377721066246_0009_01_000001 Container Transitioned from ACQUIRED to RUNNING
2013-08-28 20:34:42,161 INFO org.apache.hadoop.yarn.server.resourcemanager.rmcontainer.RMContainerImpl: container_1377721066246_0010_01_000001 Container Transitioned from ACQUIRED to RUNNING
2013-08-28 20:34:42,239 INFO org.apache.hadoop.yarn.server.resourcemanager.rmcontainer.RMContainerImpl: container_1377721066246_0007_01_000001 Container Transitioned from ACQUIRED to RUNNING
2013-08-28 20:34:47,023 INFO org.apache.hadoop.yarn.server.resourcemanager.ApplicationMasterService: AM registration appattempt_1377721066246_0010_000001
2013-08-28 20:34:47,023 INFO org.apache.hadoop.yarn.server.resourcemanager.RMAuditLogger: USER=ubuntu	IP=192.168.100.15	OPERATION=Register App Master	TARGET=ApplicationMasterService	RESULT=SUCCESS	APPID=application_1377721066246_0010	APPATTEMPTID=appattempt_1377721066246_0010_000001
2013-08-28 20:34:47,024 INFO org.apache.hadoop.yarn.server.resourcemanager.rmapp.attempt.RMAppAttemptImpl: appattempt_1377721066246_0010_000001 State change from LAUNCHED to RUNNING
2013-08-28 20:34:47,024 INFO org.apache.hadoop.yarn.server.resourcemanager.rmapp.RMAppImpl: application_1377721066246_0010 State change from ACCEPTED to RUNNING
2013-08-28 20:34:48,121 INFO org.apache.hadoop.yarn.server.resourcemanager.rmcontainer.RMContainerImpl: container_1377721066246_0010_01_000002 Container Transitioned from NEW to ALLOCATED
2013-08-28 20:34:48,122 INFO org.apache.hadoop.yarn.server.resourcemanager.RMAuditLogger: USER=ubuntu	OPERATION=AM Allocated Container	TARGET=SchedulerApp	RESULT=SUCCESS	APPID=application_1377721066246_0010	CONTAINERID=container_1377721066246_0010_01_000002
2013-08-28 20:34:48,122 INFO org.apache.hadoop.yarn.server.resourcemanager.scheduler.common.fica.FiCaSchedulerNode: Assigned container container_1377721066246_0010_01_000002 of capacity <memory:1024, vCores:1> on host hadoop-17-7:49112, which currently has 2 containers, <memory:3072, vCores:2> used and <memory:5120, vCores:14> available
2013-08-28 20:34:48,123 INFO org.apache.hadoop.yarn.server.resourcemanager.scheduler.capacity.LeafQueue: assignedContainer application=application_1377721066246_0010 container=Container: [ContainerId: container_1377721066246_0010_01_000002, NodeId: hadoop-17-7:49112, NodeHttpAddress: hadoop-17-7:8042, Resource: <memory:1024, vCores:1>, Priority: 20, State: NEW, Token: null, Status: container_id {, app_attempt_id {, application_id {, id: 10, cluster_timestamp: 1377721066246, }, attemptId: 1, }, id: 2, }, state: C_NEW, ] containerId=container_1377721066246_0010_01_000002 queue=default: capacity=1.0, absoluteCapacity=1.0, usedResources=<memory:10240, vCores:5>usedCapacity=0.20833333, absoluteUsedCapacity=0.20833333, numApps=5, numContainers=5 usedCapacity=0.20833333 absoluteUsedCapacity=0.20833333 used=<memory:10240, vCores:5> cluster=<memory:49152, vCores:96>
2013-08-28 20:34:48,123 INFO org.apache.hadoop.yarn.server.resourcemanager.scheduler.capacity.ParentQueue: Re-sorting queues since queue: root.default stats: default: capacity=1.0, absoluteCapacity=1.0, usedResources=<memory:11264, vCores:6>usedCapacity=0.22916667, absoluteUsedCapacity=0.22916667, numApps=5, numContainers=6
2013-08-28 20:34:48,124 INFO org.apache.hadoop.yarn.server.resourcemanager.scheduler.capacity.ParentQueue: assignedContainer queue=root usedCapacity=0.22916667 absoluteUsedCapacity=0.22916667 used=<memory:11264, vCores:6> cluster=<memory:49152, vCores:96>
2013-08-28 20:34:48,124 INFO org.apache.hadoop.yarn.server.resourcemanager.rmcontainer.RMContainerImpl: container_1377721066246_0010_01_000003 Container Transitioned from NEW to ALLOCATED
2013-08-28 20:34:48,124 INFO org.apache.hadoop.yarn.server.resourcemanager.RMAuditLogger: USER=ubuntu	OPERATION=AM Allocated Container	TARGET=SchedulerApp	RESULT=SUCCESS	APPID=application_1377721066246_0010	CONTAINERID=container_1377721066246_0010_01_000003
2013-08-28 20:34:48,124 INFO org.apache.hadoop.yarn.server.resourcemanager.scheduler.common.fica.FiCaSchedulerNode: Assigned container container_1377721066246_0010_01_000003 of capacity <memory:1024, vCores:1> on host hadoop-17-7:49112, which currently has 3 containers, <memory:4096, vCores:3> used and <memory:4096, vCores:13> available
2013-08-28 20:34:48,125 INFO org.apache.hadoop.yarn.server.resourcemanager.scheduler.capacity.LeafQueue: assignedContainer application=application_1377721066246_0010 container=Container: [ContainerId: container_1377721066246_0010_01_000003, NodeId: hadoop-17-7:49112, NodeHttpAddress: hadoop-17-7:8042, Resource: <memory:1024, vCores:1>, Priority: 20, State: NEW, Token: null, Status: container_id {, app_attempt_id {, application_id {, id: 10, cluster_timestamp: 1377721066246, }, attemptId: 1, }, id: 3, }, state: C_NEW, ] containerId=container_1377721066246_0010_01_000003 queue=default: capacity=1.0, absoluteCapacity=1.0, usedResources=<memory:11264, vCores:6>usedCapacity=0.22916667, absoluteUsedCapacity=0.22916667, numApps=5, numContainers=6 usedCapacity=0.22916667 absoluteUsedCapacity=0.22916667 used=<memory:11264, vCores:6> cluster=<memory:49152, vCores:96>
2013-08-28 20:34:48,126 INFO org.apache.hadoop.yarn.server.resourcemanager.scheduler.capacity.ParentQueue: Re-sorting queues since queue: root.default stats: default: capacity=1.0, absoluteCapacity=1.0, usedResources=<memory:12288, vCores:7>usedCapacity=0.25, absoluteUsedCapacity=0.25, numApps=5, numContainers=7
2013-08-28 20:34:48,126 INFO org.apache.hadoop.yarn.server.resourcemanager.scheduler.capacity.ParentQueue: assignedContainer queue=root usedCapacity=0.25 absoluteUsedCapacity=0.25 used=<memory:12288, vCores:7> cluster=<memory:49152, vCores:96>
2013-08-28 20:34:48,126 INFO org.apache.hadoop.yarn.server.resourcemanager.rmcontainer.RMContainerImpl: container_1377721066246_0010_01_000004 Container Transitioned from NEW to ALLOCATED
2013-08-28 20:34:48,126 INFO org.apache.hadoop.yarn.server.resourcemanager.RMAuditLogger: USER=ubuntu	OPERATION=AM Allocated Container	TARGET=SchedulerApp	RESULT=SUCCESS	APPID=application_1377721066246_0010	CONTAINERID=container_1377721066246_0010_01_000004
2013-08-28 20:34:48,127 INFO org.apache.hadoop.yarn.server.resourcemanager.scheduler.common.fica.FiCaSchedulerNode: Assigned container container_1377721066246_0010_01_000004 of capacity <memory:1024, vCores:1> on host hadoop-17-7:49112, which currently has 4 containers, <memory:5120, vCores:4> used and <memory:3072, vCores:12> available
2013-08-28 20:34:48,128 INFO org.apache.hadoop.yarn.server.resourcemanager.scheduler.capacity.LeafQueue: assignedContainer application=application_1377721066246_0010 container=Container: [ContainerId: container_1377721066246_0010_01_000004, NodeId: hadoop-17-7:49112, NodeHttpAddress: hadoop-17-7:8042, Resource: <memory:1024, vCores:1>, Priority: 20, State: NEW, Token: null, Status: container_id {, app_attempt_id {, application_id {, id: 10, cluster_timestamp: 1377721066246, }, attemptId: 1, }, id: 4, }, state: C_NEW, ] containerId=container_1377721066246_0010_01_000004 queue=default: capacity=1.0, absoluteCapacity=1.0, usedResources=<memory:12288, vCores:7>usedCapacity=0.25, absoluteUsedCapacity=0.25, numApps=5, numContainers=7 usedCapacity=0.25 absoluteUsedCapacity=0.25 used=<memory:12288, vCores:7> cluster=<memory:49152, vCores:96>
2013-08-28 20:34:48,128 INFO org.apache.hadoop.yarn.server.resourcemanager.scheduler.capacity.ParentQueue: Re-sorting queues since queue: root.default stats: default: capacity=1.0, absoluteCapacity=1.0, usedResources=<memory:13312, vCores:8>usedCapacity=0.27083334, absoluteUsedCapacity=0.27083334, numApps=5, numContainers=8
2013-08-28 20:34:48,128 INFO org.apache.hadoop.yarn.server.resourcemanager.scheduler.capacity.ParentQueue: assignedContainer queue=root usedCapacity=0.27083334 absoluteUsedCapacity=0.27083334 used=<memory:13312, vCores:8> cluster=<memory:49152, vCores:96>
2013-08-28 20:34:48,128 INFO org.apache.hadoop.yarn.server.resourcemanager.rmcontainer.RMContainerImpl: container_1377721066246_0010_01_000005 Container Transitioned from NEW to ALLOCATED
2013-08-28 20:34:48,129 INFO org.apache.hadoop.yarn.server.resourcemanager.RMAuditLogger: USER=ubuntu	OPERATION=AM Allocated Container	TARGET=SchedulerApp	RESULT=SUCCESS	APPID=application_1377721066246_0010	CONTAINERID=container_1377721066246_0010_01_000005
2013-08-28 20:34:48,129 INFO org.apache.hadoop.yarn.server.resourcemanager.scheduler.common.fica.FiCaSchedulerNode: Assigned container container_1377721066246_0010_01_000005 of capacity <memory:1024, vCores:1> on host hadoop-17-7:49112, which currently has 5 containers, <memory:6144, vCores:5> used and <memory:2048, vCores:11> available
2013-08-28 20:34:48,130 INFO org.apache.hadoop.yarn.server.resourcemanager.scheduler.capacity.LeafQueue: assignedContainer application=application_1377721066246_0010 container=Container: [ContainerId: container_1377721066246_0010_01_000005, NodeId: hadoop-17-7:49112, NodeHttpAddress: hadoop-17-7:8042, Resource: <memory:1024, vCores:1>, Priority: 20, State: NEW, Token: null, Status: container_id {, app_attempt_id {, application_id {, id: 10, cluster_timestamp: 1377721066246, }, attemptId: 1, }, id: 5, }, state: C_NEW, ] containerId=container_1377721066246_0010_01_000005 queue=default: capacity=1.0, absoluteCapacity=1.0, usedResources=<memory:13312, vCores:8>usedCapacity=0.27083334, absoluteUsedCapacity=0.27083334, numApps=5, numContainers=8 usedCapacity=0.27083334 absoluteUsedCapacity=0.27083334 used=<memory:13312, vCores:8> cluster=<memory:49152, vCores:96>
2013-08-28 20:34:48,130 INFO org.apache.hadoop.yarn.server.resourcemanager.scheduler.capacity.ParentQueue: Re-sorting queues since queue: root.default stats: default: capacity=1.0, absoluteCapacity=1.0, usedResources=<memory:14336, vCores:9>usedCapacity=0.29166666, absoluteUsedCapacity=0.29166666, numApps=5, numContainers=9
2013-08-28 20:34:48,130 INFO org.apache.hadoop.yarn.server.resourcemanager.scheduler.capacity.ParentQueue: assignedContainer queue=root usedCapacity=0.29166666 absoluteUsedCapacity=0.29166666 used=<memory:14336, vCores:9> cluster=<memory:49152, vCores:96>
2013-08-28 20:34:48,131 INFO org.apache.hadoop.yarn.server.resourcemanager.rmcontainer.RMContainerImpl: container_1377721066246_0010_01_000006 Container Transitioned from NEW to ALLOCATED
2013-08-28 20:34:48,131 INFO org.apache.hadoop.yarn.server.resourcemanager.RMAuditLogger: USER=ubuntu	OPERATION=AM Allocated Container	TARGET=SchedulerApp	RESULT=SUCCESS	APPID=application_1377721066246_0010	CONTAINERID=container_1377721066246_0010_01_000006
2013-08-28 20:34:48,131 INFO org.apache.hadoop.yarn.server.resourcemanager.scheduler.common.fica.FiCaSchedulerNode: Assigned container container_1377721066246_0010_01_000006 of capacity <memory:1024, vCores:1> on host hadoop-17-7:49112, which currently has 6 containers, <memory:7168, vCores:6> used and <memory:1024, vCores:10> available
2013-08-28 20:34:48,132 INFO org.apache.hadoop.yarn.server.resourcemanager.scheduler.capacity.LeafQueue: assignedContainer application=application_1377721066246_0010 container=Container: [ContainerId: container_1377721066246_0010_01_000006, NodeId: hadoop-17-7:49112, NodeHttpAddress: hadoop-17-7:8042, Resource: <memory:1024, vCores:1>, Priority: 20, State: NEW, Token: null, Status: container_id {, app_attempt_id {, application_id {, id: 10, cluster_timestamp: 1377721066246, }, attemptId: 1, }, id: 6, }, state: C_NEW, ] containerId=container_1377721066246_0010_01_000006 queue=default: capacity=1.0, absoluteCapacity=1.0, usedResources=<memory:14336, vCores:9>usedCapacity=0.29166666, absoluteUsedCapacity=0.29166666, numApps=5, numContainers=9 usedCapacity=0.29166666 absoluteUsedCapacity=0.29166666 used=<memory:14336, vCores:9> cluster=<memory:49152, vCores:96>
2013-08-28 20:34:48,132 INFO org.apache.hadoop.yarn.server.resourcemanager.scheduler.capacity.ParentQueue: Re-sorting queues since queue: root.default stats: default: capacity=1.0, absoluteCapacity=1.0, usedResources=<memory:15360, vCores:10>usedCapacity=0.3125, absoluteUsedCapacity=0.3125, numApps=5, numContainers=10
2013-08-28 20:34:48,132 INFO org.apache.hadoop.yarn.server.resourcemanager.scheduler.capacity.ParentQueue: assignedContainer queue=root usedCapacity=0.3125 absoluteUsedCapacity=0.3125 used=<memory:15360, vCores:10> cluster=<memory:49152, vCores:96>
2013-08-28 20:34:48,133 INFO org.apache.hadoop.yarn.server.resourcemanager.rmcontainer.RMContainerImpl: container_1377721066246_0010_01_000007 Container Transitioned from NEW to ALLOCATED
2013-08-28 20:34:48,133 INFO org.apache.hadoop.yarn.server.resourcemanager.RMAuditLogger: USER=ubuntu	OPERATION=AM Allocated Container	TARGET=SchedulerApp	RESULT=SUCCESS	APPID=application_1377721066246_0010	CONTAINERID=container_1377721066246_0010_01_000007
2013-08-28 20:34:48,133 INFO org.apache.hadoop.yarn.server.resourcemanager.scheduler.common.fica.FiCaSchedulerNode: Assigned container container_1377721066246_0010_01_000007 of capacity <memory:1024, vCores:1> on host hadoop-17-7:49112, which currently has 7 containers, <memory:8192, vCores:7> used and <memory:0, vCores:9> available
2013-08-28 20:34:48,134 INFO org.apache.hadoop.yarn.server.resourcemanager.scheduler.capacity.LeafQueue: assignedContainer application=application_1377721066246_0010 container=Container: [ContainerId: container_1377721066246_0010_01_000007, NodeId: hadoop-17-7:49112, NodeHttpAddress: hadoop-17-7:8042, Resource: <memory:1024, vCores:1>, Priority: 20, State: NEW, Token: null, Status: container_id {, app_attempt_id {, application_id {, id: 10, cluster_timestamp: 1377721066246, }, attemptId: 1, }, id: 7, }, state: C_NEW, ] containerId=container_1377721066246_0010_01_000007 queue=default: capacity=1.0, absoluteCapacity=1.0, usedResources=<memory:15360, vCores:10>usedCapacity=0.3125, absoluteUsedCapacity=0.3125, numApps=5, numContainers=10 usedCapacity=0.3125 absoluteUsedCapacity=0.3125 used=<memory:15360, vCores:10> cluster=<memory:49152, vCores:96>
2013-08-28 20:34:48,134 INFO org.apache.hadoop.yarn.server.resourcemanager.scheduler.capacity.ParentQueue: Re-sorting queues since queue: root.default stats: default: capacity=1.0, absoluteCapacity=1.0, usedResources=<memory:16384, vCores:11>usedCapacity=0.33333334, absoluteUsedCapacity=0.33333334, numApps=5, numContainers=11
2013-08-28 20:34:48,134 INFO org.apache.hadoop.yarn.server.resourcemanager.scheduler.capacity.ParentQueue: assignedContainer queue=root usedCapacity=0.33333334 absoluteUsedCapacity=0.33333334 used=<memory:16384, vCores:11> cluster=<memory:49152, vCores:96>
2013-08-28 20:34:48,184 INFO org.apache.hadoop.yarn.server.resourcemanager.rmcontainer.RMContainerImpl: container_1377721066246_0010_01_000008 Container Transitioned from NEW to ALLOCATED
2013-08-28 20:34:48,184 INFO org.apache.hadoop.yarn.server.resourcemanager.RMAuditLogger: USER=ubuntu	OPERATION=AM Allocated Container	TARGET=SchedulerApp	RESULT=SUCCESS	APPID=application_1377721066246_0010	CONTAINERID=container_1377721066246_0010_01_000008
2013-08-28 20:34:48,184 INFO org.apache.hadoop.yarn.server.resourcemanager.scheduler.common.fica.FiCaSchedulerNode: Assigned container container_1377721066246_0010_01_000008 of capacity <memory:1024, vCores:1> on host hadoop-17-3:35481, which currently has 2 containers, <memory:3072, vCores:2> used and <memory:5120, vCores:14> available
2013-08-28 20:34:48,185 INFO org.apache.hadoop.yarn.server.resourcemanager.scheduler.capacity.LeafQueue: assignedContainer application=application_1377721066246_0010 container=Container: [ContainerId: container_1377721066246_0010_01_000008, NodeId: hadoop-17-3:35481, NodeHttpAddress: hadoop-17-3:8042, Resource: <memory:1024, vCores:1>, Priority: 20, State: NEW, Token: null, Status: container_id {, app_attempt_id {, application_id {, id: 10, cluster_timestamp: 1377721066246, }, attemptId: 1, }, id: 8, }, state: C_NEW, ] containerId=container_1377721066246_0010_01_000008 queue=default: capacity=1.0, absoluteCapacity=1.0, usedResources=<memory:16384, vCores:11>usedCapacity=0.33333334, absoluteUsedCapacity=0.33333334, numApps=5, numContainers=11 usedCapacity=0.33333334 absoluteUsedCapacity=0.33333334 used=<memory:16384, vCores:11> cluster=<memory:49152, vCores:96>
2013-08-28 20:34:48,185 INFO org.apache.hadoop.yarn.server.resourcemanager.scheduler.capacity.ParentQueue: Re-sorting queues since queue: root.default stats: default: capacity=1.0, absoluteCapacity=1.0, usedResources=<memory:17408, vCores:12>usedCapacity=0.35416666, absoluteUsedCapacity=0.35416666, numApps=5, numContainers=12
2013-08-28 20:34:48,185 INFO org.apache.hadoop.yarn.server.resourcemanager.scheduler.capacity.ParentQueue: assignedContainer queue=root usedCapacity=0.35416666 absoluteUsedCapacity=0.35416666 used=<memory:17408, vCores:12> cluster=<memory:49152, vCores:96>
2013-08-28 20:34:48,186 INFO org.apache.hadoop.yarn.server.resourcemanager.rmcontainer.RMContainerImpl: container_1377721066246_0010_01_000009 Container Transitioned from NEW to ALLOCATED
2013-08-28 20:34:48,186 INFO org.apache.hadoop.yarn.server.resourcemanager.RMAuditLogger: USER=ubuntu	OPERATION=AM Allocated Container	TARGET=SchedulerApp	RESULT=SUCCESS	APPID=application_1377721066246_0010	CONTAINERID=container_1377721066246_0010_01_000009
2013-08-28 20:34:48,186 INFO org.apache.hadoop.yarn.server.resourcemanager.scheduler.common.fica.FiCaSchedulerNode: Assigned container container_1377721066246_0010_01_000009 of capacity <memory:1024, vCores:1> on host hadoop-17-3:35481, which currently has 3 containers, <memory:4096, vCores:3> used and <memory:4096, vCores:13> available
2013-08-28 20:34:48,187 INFO org.apache.hadoop.yarn.server.resourcemanager.scheduler.capacity.LeafQueue: assignedContainer application=application_1377721066246_0010 container=Container: [ContainerId: container_1377721066246_0010_01_000009, NodeId: hadoop-17-3:35481, NodeHttpAddress: hadoop-17-3:8042, Resource: <memory:1024, vCores:1>, Priority: 20, State: NEW, Token: null, Status: container_id {, app_attempt_id {, application_id {, id: 10, cluster_timestamp: 1377721066246, }, attemptId: 1, }, id: 9, }, state: C_NEW, ] containerId=container_1377721066246_0010_01_000009 queue=default: capacity=1.0, absoluteCapacity=1.0, usedResources=<memory:17408, vCores:12>usedCapacity=0.35416666, absoluteUsedCapacity=0.35416666, numApps=5, numContainers=12 usedCapacity=0.35416666 absoluteUsedCapacity=0.35416666 used=<memory:17408, vCores:12> cluster=<memory:49152, vCores:96>
2013-08-28 20:34:48,187 INFO org.apache.hadoop.yarn.server.resourcemanager.scheduler.capacity.ParentQueue: Re-sorting queues since queue: root.default stats: default: capacity=1.0, absoluteCapacity=1.0, usedResources=<memory:18432, vCores:13>usedCapacity=0.375, absoluteUsedCapacity=0.375, numApps=5, numContainers=13
2013-08-28 20:34:48,187 INFO org.apache.hadoop.yarn.server.resourcemanager.scheduler.capacity.ParentQueue: assignedContainer queue=root usedCapacity=0.375 absoluteUsedCapacity=0.375 used=<memory:18432, vCores:13> cluster=<memory:49152, vCores:96>
2013-08-28 20:34:48,188 INFO org.apache.hadoop.yarn.server.resourcemanager.rmcontainer.RMContainerImpl: container_1377721066246_0010_01_000010 Container Transitioned from NEW to ALLOCATED
2013-08-28 20:34:48,188 INFO org.apache.hadoop.yarn.server.resourcemanager.RMAuditLogger: USER=ubuntu	OPERATION=AM Allocated Container	TARGET=SchedulerApp	RESULT=SUCCESS	APPID=application_1377721066246_0010	CONTAINERID=container_1377721066246_0010_01_000010
2013-08-28 20:34:48,188 INFO org.apache.hadoop.yarn.server.resourcemanager.scheduler.common.fica.FiCaSchedulerNode: Assigned container container_1377721066246_0010_01_000010 of capacity <memory:1024, vCores:1> on host hadoop-17-3:35481, which currently has 4 containers, <memory:5120, vCores:4> used and <memory:3072, vCores:12> available
2013-08-28 20:34:48,189 INFO org.apache.hadoop.yarn.server.resourcemanager.scheduler.capacity.LeafQueue: assignedContainer application=application_1377721066246_0010 container=Container: [ContainerId: container_1377721066246_0010_01_000010, NodeId: hadoop-17-3:35481, NodeHttpAddress: hadoop-17-3:8042, Resource: <memory:1024, vCores:1>, Priority: 20, State: NEW, Token: null, Status: container_id {, app_attempt_id {, application_id {, id: 10, cluster_timestamp: 1377721066246, }, attemptId: 1, }, id: 10, }, state: C_NEW, ] containerId=container_1377721066246_0010_01_000010 queue=default: capacity=1.0, absoluteCapacity=1.0, usedResources=<memory:18432, vCores:13>usedCapacity=0.375, absoluteUsedCapacity=0.375, numApps=5, numContainers=13 usedCapacity=0.375 absoluteUsedCapacity=0.375 used=<memory:18432, vCores:13> cluster=<memory:49152, vCores:96>
2013-08-28 20:34:48,189 INFO org.apache.hadoop.yarn.server.resourcemanager.scheduler.capacity.ParentQueue: Re-sorting queues since queue: root.default stats: default: capacity=1.0, absoluteCapacity=1.0, usedResources=<memory:19456, vCores:14>usedCapacity=0.39583334, absoluteUsedCapacity=0.39583334, numApps=5, numContainers=14
2013-08-28 20:34:48,189 INFO org.apache.hadoop.yarn.server.resourcemanager.scheduler.capacity.ParentQueue: assignedContainer queue=root usedCapacity=0.39583334 absoluteUsedCapacity=0.39583334 used=<memory:19456, vCores:14> cluster=<memory:49152, vCores:96>
2013-08-28 20:34:48,190 INFO org.apache.hadoop.yarn.server.resourcemanager.rmcontainer.RMContainerImpl: container_1377721066246_0010_01_000011 Container Transitioned from NEW to ALLOCATED
2013-08-28 20:34:48,190 INFO org.apache.hadoop.yarn.server.resourcemanager.RMAuditLogger: USER=ubuntu	OPERATION=AM Allocated Container	TARGET=SchedulerApp	RESULT=SUCCESS	APPID=application_1377721066246_0010	CONTAINERID=container_1377721066246_0010_01_000011
2013-08-28 20:34:48,190 INFO org.apache.hadoop.yarn.server.resourcemanager.scheduler.common.fica.FiCaSchedulerNode: Assigned container container_1377721066246_0010_01_000011 of capacity <memory:1024, vCores:1> on host hadoop-17-3:35481, which currently has 5 containers, <memory:6144, vCores:5> used and <memory:2048, vCores:11> available
2013-08-28 20:34:48,191 INFO org.apache.hadoop.yarn.server.resourcemanager.scheduler.capacity.LeafQueue: assignedContainer application=application_1377721066246_0010 container=Container: [ContainerId: container_1377721066246_0010_01_000011, NodeId: hadoop-17-3:35481, NodeHttpAddress: hadoop-17-3:8042, Resource: <memory:1024, vCores:1>, Priority: 20, State: NEW, Token: null, Status: container_id {, app_attempt_id {, application_id {, id: 10, cluster_timestamp: 1377721066246, }, attemptId: 1, }, id: 11, }, state: C_NEW, ] containerId=container_1377721066246_0010_01_000011 queue=default: capacity=1.0, absoluteCapacity=1.0, usedResources=<memory:19456, vCores:14>usedCapacity=0.39583334, absoluteUsedCapacity=0.39583334, numApps=5, numContainers=14 usedCapacity=0.39583334 absoluteUsedCapacity=0.39583334 used=<memory:19456, vCores:14> cluster=<memory:49152, vCores:96>
2013-08-28 20:34:48,191 INFO org.apache.hadoop.yarn.server.resourcemanager.scheduler.capacity.ParentQueue: Re-sorting queues since queue: root.default stats: default: capacity=1.0, absoluteCapacity=1.0, usedResources=<memory:20480, vCores:15>usedCapacity=0.41666666, absoluteUsedCapacity=0.41666666, numApps=5, numContainers=15
2013-08-28 20:34:48,191 INFO org.apache.hadoop.yarn.server.resourcemanager.scheduler.capacity.ParentQueue: assignedContainer queue=root usedCapacity=0.41666666 absoluteUsedCapacity=0.41666666 used=<memory:20480, vCores:15> cluster=<memory:49152, vCores:96>
2013-08-28 20:34:48,192 INFO org.apache.hadoop.yarn.server.resourcemanager.rmcontainer.RMContainerImpl: container_1377721066246_0010_01_000012 Container Transitioned from NEW to ALLOCATED
2013-08-28 20:34:48,192 INFO org.apache.hadoop.yarn.server.resourcemanager.RMAuditLogger: USER=ubuntu	OPERATION=AM Allocated Container	TARGET=SchedulerApp	RESULT=SUCCESS	APPID=application_1377721066246_0010	CONTAINERID=container_1377721066246_0010_01_000012
2013-08-28 20:34:48,192 INFO org.apache.hadoop.yarn.server.resourcemanager.scheduler.common.fica.FiCaSchedulerNode: Assigned container container_1377721066246_0010_01_000012 of capacity <memory:1024, vCores:1> on host hadoop-17-3:35481, which currently has 6 containers, <memory:7168, vCores:6> used and <memory:1024, vCores:10> available
2013-08-28 20:34:48,193 INFO org.apache.hadoop.yarn.server.resourcemanager.scheduler.capacity.LeafQueue: assignedContainer application=application_1377721066246_0010 container=Container: [ContainerId: container_1377721066246_0010_01_000012, NodeId: hadoop-17-3:35481, NodeHttpAddress: hadoop-17-3:8042, Resource: <memory:1024, vCores:1>, Priority: 20, State: NEW, Token: null, Status: container_id {, app_attempt_id {, application_id {, id: 10, cluster_timestamp: 1377721066246, }, attemptId: 1, }, id: 12, }, state: C_NEW, ] containerId=container_1377721066246_0010_01_000012 queue=default: capacity=1.0, absoluteCapacity=1.0, usedResources=<memory:20480, vCores:15>usedCapacity=0.41666666, absoluteUsedCapacity=0.41666666, numApps=5, numContainers=15 usedCapacity=0.41666666 absoluteUsedCapacity=0.41666666 used=<memory:20480, vCores:15> cluster=<memory:49152, vCores:96>
2013-08-28 20:34:48,193 INFO org.apache.hadoop.yarn.server.resourcemanager.scheduler.capacity.ParentQueue: Re-sorting queues since queue: root.default stats: default: capacity=1.0, absoluteCapacity=1.0, usedResources=<memory:21504, vCores:16>usedCapacity=0.4375, absoluteUsedCapacity=0.4375, numApps=5, numContainers=16
2013-08-28 20:34:48,193 INFO org.apache.hadoop.yarn.server.resourcemanager.scheduler.capacity.ParentQueue: assignedContainer queue=root usedCapacity=0.4375 absoluteUsedCapacity=0.4375 used=<memory:21504, vCores:16> cluster=<memory:49152, vCores:96>
2013-08-28 20:34:48,194 INFO org.apache.hadoop.yarn.server.resourcemanager.rmcontainer.RMContainerImpl: container_1377721066246_0010_01_000013 Container Transitioned from NEW to ALLOCATED
2013-08-28 20:34:48,194 INFO org.apache.hadoop.yarn.server.resourcemanager.RMAuditLogger: USER=ubuntu	OPERATION=AM Allocated Container	TARGET=SchedulerApp	RESULT=SUCCESS	APPID=application_1377721066246_0010	CONTAINERID=container_1377721066246_0010_01_000013
2013-08-28 20:34:48,194 INFO org.apache.hadoop.yarn.server.resourcemanager.scheduler.common.fica.FiCaSchedulerNode: Assigned container container_1377721066246_0010_01_000013 of capacity <memory:1024, vCores:1> on host hadoop-17-3:35481, which currently has 7 containers, <memory:8192, vCores:7> used and <memory:0, vCores:9> available
2013-08-28 20:34:48,196 INFO org.apache.hadoop.yarn.server.resourcemanager.scheduler.capacity.LeafQueue: assignedContainer application=application_1377721066246_0010 container=Container: [ContainerId: container_1377721066246_0010_01_000013, NodeId: hadoop-17-3:35481, NodeHttpAddress: hadoop-17-3:8042, Resource: <memory:1024, vCores:1>, Priority: 20, State: NEW, Token: null, Status: container_id {, app_attempt_id {, application_id {, id: 10, cluster_timestamp: 1377721066246, }, attemptId: 1, }, id: 13, }, state: C_NEW, ] containerId=container_1377721066246_0010_01_000013 queue=default: capacity=1.0, absoluteCapacity=1.0, usedResources=<memory:21504, vCores:16>usedCapacity=0.4375, absoluteUsedCapacity=0.4375, numApps=5, numContainers=16 usedCapacity=0.4375 absoluteUsedCapacity=0.4375 used=<memory:21504, vCores:16> cluster=<memory:49152, vCores:96>
2013-08-28 20:34:48,196 INFO org.apache.hadoop.yarn.server.resourcemanager.scheduler.capacity.ParentQueue: Re-sorting queues since queue: root.default stats: default: capacity=1.0, absoluteCapacity=1.0, usedResources=<memory:22528, vCores:17>usedCapacity=0.45833334, absoluteUsedCapacity=0.45833334, numApps=5, numContainers=17
2013-08-28 20:34:48,197 INFO org.apache.hadoop.yarn.server.resourcemanager.scheduler.capacity.ParentQueue: assignedContainer queue=root usedCapacity=0.45833334 absoluteUsedCapacity=0.45833334 used=<memory:22528, vCores:17> cluster=<memory:49152, vCores:96>
2013-08-28 20:34:48,264 INFO org.apache.hadoop.yarn.server.resourcemanager.rmcontainer.RMContainerImpl: container_1377721066246_0010_01_000014 Container Transitioned from NEW to ALLOCATED
2013-08-28 20:34:48,264 INFO org.apache.hadoop.yarn.server.resourcemanager.RMAuditLogger: USER=ubuntu	OPERATION=AM Allocated Container	TARGET=SchedulerApp	RESULT=SUCCESS	APPID=application_1377721066246_0010	CONTAINERID=container_1377721066246_0010_01_000014
2013-08-28 20:34:48,264 INFO org.apache.hadoop.yarn.server.resourcemanager.scheduler.common.fica.FiCaSchedulerNode: Assigned container container_1377721066246_0010_01_000014 of capacity <memory:1024, vCores:1> on host hadoop-17-5:46576, which currently has 2 containers, <memory:3072, vCores:2> used and <memory:5120, vCores:14> available
2013-08-28 20:34:48,265 INFO org.apache.hadoop.yarn.server.resourcemanager.scheduler.capacity.LeafQueue: assignedContainer application=application_1377721066246_0010 container=Container: [ContainerId: container_1377721066246_0010_01_000014, NodeId: hadoop-17-5:46576, NodeHttpAddress: hadoop-17-5:8042, Resource: <memory:1024, vCores:1>, Priority: 20, State: NEW, Token: null, Status: container_id {, app_attempt_id {, application_id {, id: 10, cluster_timestamp: 1377721066246, }, attemptId: 1, }, id: 14, }, state: C_NEW, ] containerId=container_1377721066246_0010_01_000014 queue=default: capacity=1.0, absoluteCapacity=1.0, usedResources=<memory:22528, vCores:17>usedCapacity=0.45833334, absoluteUsedCapacity=0.45833334, numApps=5, numContainers=17 usedCapacity=0.45833334 absoluteUsedCapacity=0.45833334 used=<memory:22528, vCores:17> cluster=<memory:49152, vCores:96>
2013-08-28 20:34:48,266 INFO org.apache.hadoop.yarn.server.resourcemanager.scheduler.capacity.ParentQueue: Re-sorting queues since queue: root.default stats: default: capacity=1.0, absoluteCapacity=1.0, usedResources=<memory:23552, vCores:18>usedCapacity=0.47916666, absoluteUsedCapacity=0.47916666, numApps=5, numContainers=18
2013-08-28 20:34:48,266 INFO org.apache.hadoop.yarn.server.resourcemanager.scheduler.capacity.ParentQueue: assignedContainer queue=root usedCapacity=0.47916666 absoluteUsedCapacity=0.47916666 used=<memory:23552, vCores:18> cluster=<memory:49152, vCores:96>
2013-08-28 20:34:48,266 INFO org.apache.hadoop.yarn.server.resourcemanager.rmcontainer.RMContainerImpl: container_1377721066246_0010_01_000015 Container Transitioned from NEW to ALLOCATED
2013-08-28 20:34:48,266 INFO org.apache.hadoop.yarn.server.resourcemanager.RMAuditLogger: USER=ubuntu	OPERATION=AM Allocated Container	TARGET=SchedulerApp	RESULT=SUCCESS	APPID=application_1377721066246_0010	CONTAINERID=container_1377721066246_0010_01_000015
2013-08-28 20:34:48,267 INFO org.apache.hadoop.yarn.server.resourcemanager.scheduler.common.fica.FiCaSchedulerNode: Assigned container container_1377721066246_0010_01_000015 of capacity <memory:1024, vCores:1> on host hadoop-17-5:46576, which currently has 3 containers, <memory:4096, vCores:3> used and <memory:4096, vCores:13> available
2013-08-28 20:34:48,267 INFO org.apache.hadoop.yarn.server.resourcemanager.scheduler.capacity.LeafQueue: assignedContainer application=application_1377721066246_0010 container=Container: [ContainerId: container_1377721066246_0010_01_000015, NodeId: hadoop-17-5:46576, NodeHttpAddress: hadoop-17-5:8042, Resource: <memory:1024, vCores:1>, Priority: 20, State: NEW, Token: null, Status: container_id {, app_attempt_id {, application_id {, id: 10, cluster_timestamp: 1377721066246, }, attemptId: 1, }, id: 15, }, state: C_NEW, ] containerId=container_1377721066246_0010_01_000015 queue=default: capacity=1.0, absoluteCapacity=1.0, usedResources=<memory:23552, vCores:18>usedCapacity=0.47916666, absoluteUsedCapacity=0.47916666, numApps=5, numContainers=18 usedCapacity=0.47916666 absoluteUsedCapacity=0.47916666 used=<memory:23552, vCores:18> cluster=<memory:49152, vCores:96>
2013-08-28 20:34:48,268 INFO org.apache.hadoop.yarn.server.resourcemanager.scheduler.capacity.ParentQueue: Re-sorting queues since queue: root.default stats: default: capacity=1.0, absoluteCapacity=1.0, usedResources=<memory:24576, vCores:19>usedCapacity=0.5, absoluteUsedCapacity=0.5, numApps=5, numContainers=19
2013-08-28 20:34:48,268 INFO org.apache.hadoop.yarn.server.resourcemanager.scheduler.capacity.ParentQueue: assignedContainer queue=root usedCapacity=0.5 absoluteUsedCapacity=0.5 used=<memory:24576, vCores:19> cluster=<memory:49152, vCores:96>
2013-08-28 20:34:48,268 INFO org.apache.hadoop.yarn.server.resourcemanager.rmcontainer.RMContainerImpl: container_1377721066246_0010_01_000016 Container Transitioned from NEW to ALLOCATED
2013-08-28 20:34:48,268 INFO org.apache.hadoop.yarn.server.resourcemanager.RMAuditLogger: USER=ubuntu	OPERATION=AM Allocated Container	TARGET=SchedulerApp	RESULT=SUCCESS	APPID=application_1377721066246_0010	CONTAINERID=container_1377721066246_0010_01_000016
2013-08-28 20:34:48,269 INFO org.apache.hadoop.yarn.server.resourcemanager.scheduler.common.fica.FiCaSchedulerNode: Assigned container container_1377721066246_0010_01_000016 of capacity <memory:1024, vCores:1> on host hadoop-17-5:46576, which currently has 4 containers, <memory:5120, vCores:4> used and <memory:3072, vCores:12> available
2013-08-28 20:34:48,269 INFO org.apache.hadoop.yarn.server.resourcemanager.scheduler.capacity.LeafQueue: assignedContainer application=application_1377721066246_0010 container=Container: [ContainerId: container_1377721066246_0010_01_000016, NodeId: hadoop-17-5:46576, NodeHttpAddress: hadoop-17-5:8042, Resource: <memory:1024, vCores:1>, Priority: 20, State: NEW, Token: null, Status: container_id {, app_attempt_id {, application_id {, id: 10, cluster_timestamp: 1377721066246, }, attemptId: 1, }, id: 16, }, state: C_NEW, ] containerId=container_1377721066246_0010_01_000016 queue=default: capacity=1.0, absoluteCapacity=1.0, usedResources=<memory:24576, vCores:19>usedCapacity=0.5, absoluteUsedCapacity=0.5, numApps=5, numContainers=19 usedCapacity=0.5 absoluteUsedCapacity=0.5 used=<memory:24576, vCores:19> cluster=<memory:49152, vCores:96>
2013-08-28 20:34:48,270 INFO org.apache.hadoop.yarn.server.resourcemanager.scheduler.capacity.ParentQueue: Re-sorting queues since queue: root.default stats: default: capacity=1.0, absoluteCapacity=1.0, usedResources=<memory:25600, vCores:20>usedCapacity=0.5208333, absoluteUsedCapacity=0.5208333, numApps=5, numContainers=20
2013-08-28 20:34:48,270 INFO org.apache.hadoop.yarn.server.resourcemanager.scheduler.capacity.ParentQueue: assignedContainer queue=root usedCapacity=0.5208333 absoluteUsedCapacity=0.5208333 used=<memory:25600, vCores:20> cluster=<memory:49152, vCores:96>
2013-08-28 20:34:48,270 INFO org.apache.hadoop.yarn.server.resourcemanager.rmcontainer.RMContainerImpl: container_1377721066246_0010_01_000017 Container Transitioned from NEW to ALLOCATED
2013-08-28 20:34:48,270 INFO org.apache.hadoop.yarn.server.resourcemanager.RMAuditLogger: USER=ubuntu	OPERATION=AM Allocated Container	TARGET=SchedulerApp	RESULT=SUCCESS	APPID=application_1377721066246_0010	CONTAINERID=container_1377721066246_0010_01_000017
2013-08-28 20:34:48,271 INFO org.apache.hadoop.yarn.server.resourcemanager.scheduler.common.fica.FiCaSchedulerNode: Assigned container container_1377721066246_0010_01_000017 of capacity <memory:1024, vCores:1> on host hadoop-17-5:46576, which currently has 5 containers, <memory:6144, vCores:5> used and <memory:2048, vCores:11> available
2013-08-28 20:34:48,271 INFO org.apache.hadoop.yarn.server.resourcemanager.scheduler.capacity.LeafQueue: assignedContainer application=application_1377721066246_0010 container=Container: [ContainerId: container_1377721066246_0010_01_000017, NodeId: hadoop-17-5:46576, NodeHttpAddress: hadoop-17-5:8042, Resource: <memory:1024, vCores:1>, Priority: 20, State: NEW, Token: null, Status: container_id {, app_attempt_id {, application_id {, id: 10, cluster_timestamp: 1377721066246, }, attemptId: 1, }, id: 17, }, state: C_NEW, ] containerId=container_1377721066246_0010_01_000017 queue=default: capacity=1.0, absoluteCapacity=1.0, usedResources=<memory:25600, vCores:20>usedCapacity=0.5208333, absoluteUsedCapacity=0.5208333, numApps=5, numContainers=20 usedCapacity=0.5208333 absoluteUsedCapacity=0.5208333 used=<memory:25600, vCores:20> cluster=<memory:49152, vCores:96>
2013-08-28 20:34:48,272 INFO org.apache.hadoop.yarn.server.resourcemanager.scheduler.capacity.ParentQueue: Re-sorting queues since queue: root.default stats: default: capacity=1.0, absoluteCapacity=1.0, usedResources=<memory:26624, vCores:21>usedCapacity=0.5416667, absoluteUsedCapacity=0.5416667, numApps=5, numContainers=21
2013-08-28 20:34:48,272 INFO org.apache.hadoop.yarn.server.resourcemanager.scheduler.capacity.ParentQueue: assignedContainer queue=root usedCapacity=0.5416667 absoluteUsedCapacity=0.5416667 used=<memory:26624, vCores:21> cluster=<memory:49152, vCores:96>
2013-08-28 20:34:48,272 INFO org.apache.hadoop.yarn.server.resourcemanager.rmcontainer.RMContainerImpl: container_1377721066246_0010_01_000018 Container Transitioned from NEW to ALLOCATED
2013-08-28 20:34:48,272 INFO org.apache.hadoop.yarn.server.resourcemanager.RMAuditLogger: USER=ubuntu	OPERATION=AM Allocated Container	TARGET=SchedulerApp	RESULT=SUCCESS	APPID=application_1377721066246_0010	CONTAINERID=container_1377721066246_0010_01_000018
2013-08-28 20:34:48,273 INFO org.apache.hadoop.yarn.server.resourcemanager.scheduler.common.fica.FiCaSchedulerNode: Assigned container container_1377721066246_0010_01_000018 of capacity <memory:1024, vCores:1> on host hadoop-17-5:46576, which currently has 6 containers, <memory:7168, vCores:6> used and <memory:1024, vCores:10> available
2013-08-28 20:34:48,273 INFO org.apache.hadoop.yarn.server.resourcemanager.scheduler.capacity.LeafQueue: assignedContainer application=application_1377721066246_0010 container=Container: [ContainerId: container_1377721066246_0010_01_000018, NodeId: hadoop-17-5:46576, NodeHttpAddress: hadoop-17-5:8042, Resource: <memory:1024, vCores:1>, Priority: 20, State: NEW, Token: null, Status: container_id {, app_attempt_id {, application_id {, id: 10, cluster_timestamp: 1377721066246, }, attemptId: 1, }, id: 18, }, state: C_NEW, ] containerId=container_1377721066246_0010_01_000018 queue=default: capacity=1.0, absoluteCapacity=1.0, usedResources=<memory:26624, vCores:21>usedCapacity=0.5416667, absoluteUsedCapacity=0.5416667, numApps=5, numContainers=21 usedCapacity=0.5416667 absoluteUsedCapacity=0.5416667 used=<memory:26624, vCores:21> cluster=<memory:49152, vCores:96>
2013-08-28 20:34:48,274 INFO org.apache.hadoop.yarn.server.resourcemanager.scheduler.capacity.ParentQueue: Re-sorting queues since queue: root.default stats: default: capacity=1.0, absoluteCapacity=1.0, usedResources=<memory:27648, vCores:22>usedCapacity=0.5625, absoluteUsedCapacity=0.5625, numApps=5, numContainers=22
2013-08-28 20:34:48,274 INFO org.apache.hadoop.yarn.server.resourcemanager.scheduler.capacity.ParentQueue: assignedContainer queue=root usedCapacity=0.5625 absoluteUsedCapacity=0.5625 used=<memory:27648, vCores:22> cluster=<memory:49152, vCores:96>
2013-08-28 20:34:48,274 INFO org.apache.hadoop.yarn.server.resourcemanager.rmcontainer.RMContainerImpl: container_1377721066246_0010_01_000019 Container Transitioned from NEW to ALLOCATED
2013-08-28 20:34:48,274 INFO org.apache.hadoop.yarn.server.resourcemanager.RMAuditLogger: USER=ubuntu	OPERATION=AM Allocated Container	TARGET=SchedulerApp	RESULT=SUCCESS	APPID=application_1377721066246_0010	CONTAINERID=container_1377721066246_0010_01_000019
2013-08-28 20:34:48,275 INFO org.apache.hadoop.yarn.server.resourcemanager.scheduler.common.fica.FiCaSchedulerNode: Assigned container container_1377721066246_0010_01_000019 of capacity <memory:1024, vCores:1> on host hadoop-17-5:46576, which currently has 7 containers, <memory:8192, vCores:7> used and <memory:0, vCores:9> available
2013-08-28 20:34:48,275 INFO org.apache.hadoop.yarn.server.resourcemanager.scheduler.capacity.LeafQueue: assignedContainer application=application_1377721066246_0010 container=Container: [ContainerId: container_1377721066246_0010_01_000019, NodeId: hadoop-17-5:46576, NodeHttpAddress: hadoop-17-5:8042, Resource: <memory:1024, vCores:1>, Priority: 20, State: NEW, Token: null, Status: container_id {, app_attempt_id {, application_id {, id: 10, cluster_timestamp: 1377721066246, }, attemptId: 1, }, id: 19, }, state: C_NEW, ] containerId=container_1377721066246_0010_01_000019 queue=default: capacity=1.0, absoluteCapacity=1.0, usedResources=<memory:27648, vCores:22>usedCapacity=0.5625, absoluteUsedCapacity=0.5625, numApps=5, numContainers=22 usedCapacity=0.5625 absoluteUsedCapacity=0.5625 used=<memory:27648, vCores:22> cluster=<memory:49152, vCores:96>
2013-08-28 20:34:48,276 INFO org.apache.hadoop.yarn.server.resourcemanager.scheduler.capacity.ParentQueue: Re-sorting queues since queue: root.default stats: default: capacity=1.0, absoluteCapacity=1.0, usedResources=<memory:28672, vCores:23>usedCapacity=0.5833333, absoluteUsedCapacity=0.5833333, numApps=5, numContainers=23
2013-08-28 20:34:48,276 INFO org.apache.hadoop.yarn.server.resourcemanager.scheduler.capacity.ParentQueue: assignedContainer queue=root usedCapacity=0.5833333 absoluteUsedCapacity=0.5833333 used=<memory:28672, vCores:23> cluster=<memory:49152, vCores:96>
2013-08-28 20:34:48,531 INFO org.apache.hadoop.yarn.server.resourcemanager.ApplicationMasterService: AM registration appattempt_1377721066246_0008_000001
2013-08-28 20:34:48,532 INFO org.apache.hadoop.yarn.server.resourcemanager.RMAuditLogger: USER=ubuntu	IP=192.168.100.22	OPERATION=Register App Master	TARGET=ApplicationMasterService	RESULT=SUCCESS	APPID=application_1377721066246_0008	APPATTEMPTID=appattempt_1377721066246_0008_000001
2013-08-28 20:34:48,533 INFO org.apache.hadoop.yarn.server.resourcemanager.rmapp.attempt.RMAppAttemptImpl: appattempt_1377721066246_0008_000001 State change from LAUNCHED to RUNNING
2013-08-28 20:34:48,534 INFO org.apache.hadoop.yarn.server.resourcemanager.rmapp.RMAppImpl: application_1377721066246_0008 State change from ACCEPTED to RUNNING
2013-08-28 20:34:48,558 INFO org.apache.hadoop.yarn.server.resourcemanager.ApplicationMasterService: AM registration appattempt_1377721066246_0006_000001
2013-08-28 20:34:48,558 INFO org.apache.hadoop.yarn.server.resourcemanager.RMAuditLogger: USER=ubuntu	IP=192.168.100.33	OPERATION=Register App Master	TARGET=ApplicationMasterService	RESULT=SUCCESS	APPID=application_1377721066246_0006	APPATTEMPTID=appattempt_1377721066246_0006_000001
2013-08-28 20:34:48,559 INFO org.apache.hadoop.yarn.server.resourcemanager.rmapp.attempt.RMAppAttemptImpl: appattempt_1377721066246_0006_000001 State change from LAUNCHED to RUNNING
2013-08-28 20:34:48,559 INFO org.apache.hadoop.yarn.server.resourcemanager.rmapp.RMAppImpl: application_1377721066246_0006 State change from ACCEPTED to RUNNING
2013-08-28 20:34:48,854 INFO org.apache.hadoop.yarn.server.resourcemanager.ApplicationMasterService: AM registration appattempt_1377721066246_0009_000001
2013-08-28 20:34:48,854 INFO org.apache.hadoop.yarn.server.resourcemanager.RMAuditLogger: USER=ubuntu	IP=192.168.100.41	OPERATION=Register App Master	TARGET=ApplicationMasterService	RESULT=SUCCESS	APPID=application_1377721066246_0009	APPATTEMPTID=appattempt_1377721066246_0009_000001
2013-08-28 20:34:48,855 INFO org.apache.hadoop.yarn.server.resourcemanager.rmapp.attempt.RMAppAttemptImpl: appattempt_1377721066246_0009_000001 State change from LAUNCHED to RUNNING
2013-08-28 20:34:48,856 INFO org.apache.hadoop.yarn.server.resourcemanager.rmapp.RMAppImpl: application_1377721066246_0009 State change from ACCEPTED to RUNNING
2013-08-28 20:34:48,969 INFO org.apache.hadoop.yarn.server.resourcemanager.ApplicationMasterService: AM registration appattempt_1377721066246_0007_000001
2013-08-28 20:34:48,969 INFO org.apache.hadoop.yarn.server.resourcemanager.RMAuditLogger: USER=ubuntu	IP=192.168.100.35	OPERATION=Register App Master	TARGET=ApplicationMasterService	RESULT=SUCCESS	APPID=application_1377721066246_0007	APPATTEMPTID=appattempt_1377721066246_0007_000001
2013-08-28 20:34:48,971 INFO org.apache.hadoop.yarn.server.resourcemanager.rmapp.attempt.RMAppAttemptImpl: appattempt_1377721066246_0007_000001 State change from LAUNCHED to RUNNING
2013-08-28 20:34:48,971 INFO org.apache.hadoop.yarn.server.resourcemanager.rmapp.RMAppImpl: application_1377721066246_0007 State change from ACCEPTED to RUNNING
2013-08-28 20:34:49,010 INFO org.apache.hadoop.yarn.server.resourcemanager.rmcontainer.RMContainerImpl: container_1377721066246_0010_01_000020 Container Transitioned from NEW to ALLOCATED
2013-08-28 20:34:49,010 INFO org.apache.hadoop.yarn.server.resourcemanager.RMAuditLogger: USER=ubuntu	OPERATION=AM Allocated Container	TARGET=SchedulerApp	RESULT=SUCCESS	APPID=application_1377721066246_0010	CONTAINERID=container_1377721066246_0010_01_000020
2013-08-28 20:34:49,010 INFO org.apache.hadoop.yarn.server.resourcemanager.scheduler.common.fica.FiCaSchedulerNode: Assigned container container_1377721066246_0010_01_000020 of capacity <memory:1024, vCores:1> on host hadoop-17-2:52914, which currently has 2 containers, <memory:3072, vCores:2> used and <memory:5120, vCores:14> available
2013-08-28 20:34:49,011 INFO org.apache.hadoop.yarn.server.resourcemanager.scheduler.capacity.LeafQueue: assignedContainer application=application_1377721066246_0010 container=Container: [ContainerId: container_1377721066246_0010_01_000020, NodeId: hadoop-17-2:52914, NodeHttpAddress: hadoop-17-2:8042, Resource: <memory:1024, vCores:1>, Priority: 20, State: NEW, Token: null, Status: container_id {, app_attempt_id {, application_id {, id: 10, cluster_timestamp: 1377721066246, }, attemptId: 1, }, id: 20, }, state: C_NEW, ] containerId=container_1377721066246_0010_01_000020 queue=default: capacity=1.0, absoluteCapacity=1.0, usedResources=<memory:28672, vCores:23>usedCapacity=0.5833333, absoluteUsedCapacity=0.5833333, numApps=5, numContainers=23 usedCapacity=0.5833333 absoluteUsedCapacity=0.5833333 used=<memory:28672, vCores:23> cluster=<memory:49152, vCores:96>
2013-08-28 20:34:49,012 INFO org.apache.hadoop.yarn.server.resourcemanager.scheduler.capacity.ParentQueue: Re-sorting queues since queue: root.default stats: default: capacity=1.0, absoluteCapacity=1.0, usedResources=<memory:29696, vCores:24>usedCapacity=0.6041667, absoluteUsedCapacity=0.6041667, numApps=5, numContainers=24
2013-08-28 20:34:49,012 INFO org.apache.hadoop.yarn.server.resourcemanager.scheduler.capacity.ParentQueue: assignedContainer queue=root usedCapacity=0.6041667 absoluteUsedCapacity=0.6041667 used=<memory:29696, vCores:24> cluster=<memory:49152, vCores:96>
2013-08-28 20:34:49,012 INFO org.apache.hadoop.yarn.server.resourcemanager.rmcontainer.RMContainerImpl: container_1377721066246_0010_01_000021 Container Transitioned from NEW to ALLOCATED
2013-08-28 20:34:49,014 INFO org.apache.hadoop.yarn.server.resourcemanager.RMAuditLogger: USER=ubuntu	OPERATION=AM Allocated Container	TARGET=SchedulerApp	RESULT=SUCCESS	APPID=application_1377721066246_0010	CONTAINERID=container_1377721066246_0010_01_000021
2013-08-28 20:34:49,014 INFO org.apache.hadoop.yarn.server.resourcemanager.scheduler.common.fica.FiCaSchedulerNode: Assigned container container_1377721066246_0010_01_000021 of capacity <memory:1024, vCores:1> on host hadoop-17-2:52914, which currently has 3 containers, <memory:4096, vCores:3> used and <memory:4096, vCores:13> available
2013-08-28 20:34:49,016 INFO org.apache.hadoop.yarn.server.resourcemanager.scheduler.capacity.LeafQueue: assignedContainer application=application_1377721066246_0010 container=Container: [ContainerId: container_1377721066246_0010_01_000021, NodeId: hadoop-17-2:52914, NodeHttpAddress: hadoop-17-2:8042, Resource: <memory:1024, vCores:1>, Priority: 20, State: NEW, Token: null, Status: container_id {, app_attempt_id {, application_id {, id: 10, cluster_timestamp: 1377721066246, }, attemptId: 1, }, id: 21, }, state: C_NEW, ] containerId=container_1377721066246_0010_01_000021 queue=default: capacity=1.0, absoluteCapacity=1.0, usedResources=<memory:29696, vCores:24>usedCapacity=0.6041667, absoluteUsedCapacity=0.6041667, numApps=5, numContainers=24 usedCapacity=0.6041667 absoluteUsedCapacity=0.6041667 used=<memory:29696, vCores:24> cluster=<memory:49152, vCores:96>
2013-08-28 20:34:49,016 INFO org.apache.hadoop.yarn.server.resourcemanager.scheduler.capacity.ParentQueue: Re-sorting queues since queue: root.default stats: default: capacity=1.0, absoluteCapacity=1.0, usedResources=<memory:30720, vCores:25>usedCapacity=0.625, absoluteUsedCapacity=0.625, numApps=5, numContainers=25
2013-08-28 20:34:49,016 INFO org.apache.hadoop.yarn.server.resourcemanager.scheduler.capacity.ParentQueue: assignedContainer queue=root usedCapacity=0.625 absoluteUsedCapacity=0.625 used=<memory:30720, vCores:25> cluster=<memory:49152, vCores:96>
2013-08-28 20:34:49,017 INFO org.apache.hadoop.yarn.server.resourcemanager.rmcontainer.RMContainerImpl: container_1377721066246_0010_01_000022 Container Transitioned from NEW to ALLOCATED
2013-08-28 20:34:49,017 INFO org.apache.hadoop.yarn.server.resourcemanager.RMAuditLogger: USER=ubuntu	OPERATION=AM Allocated Container	TARGET=SchedulerApp	RESULT=SUCCESS	APPID=application_1377721066246_0010	CONTAINERID=container_1377721066246_0010_01_000022
2013-08-28 20:34:49,017 INFO org.apache.hadoop.yarn.server.resourcemanager.scheduler.common.fica.FiCaSchedulerNode: Assigned container container_1377721066246_0010_01_000022 of capacity <memory:1024, vCores:1> on host hadoop-17-2:52914, which currently has 4 containers, <memory:5120, vCores:4> used and <memory:3072, vCores:12> available
2013-08-28 20:34:49,018 INFO org.apache.hadoop.yarn.server.resourcemanager.scheduler.capacity.LeafQueue: assignedContainer application=application_1377721066246_0010 container=Container: [ContainerId: container_1377721066246_0010_01_000022, NodeId: hadoop-17-2:52914, NodeHttpAddress: hadoop-17-2:8042, Resource: <memory:1024, vCores:1>, Priority: 20, State: NEW, Token: null, Status: container_id {, app_attempt_id {, application_id {, id: 10, cluster_timestamp: 1377721066246, }, attemptId: 1, }, id: 22, }, state: C_NEW, ] containerId=container_1377721066246_0010_01_000022 queue=default: capacity=1.0, absoluteCapacity=1.0, usedResources=<memory:30720, vCores:25>usedCapacity=0.625, absoluteUsedCapacity=0.625, numApps=5, numContainers=25 usedCapacity=0.625 absoluteUsedCapacity=0.625 used=<memory:30720, vCores:25> cluster=<memory:49152, vCores:96>
2013-08-28 20:34:49,018 INFO org.apache.hadoop.yarn.server.resourcemanager.scheduler.capacity.ParentQueue: Re-sorting queues since queue: root.default stats: default: capacity=1.0, absoluteCapacity=1.0, usedResources=<memory:31744, vCores:26>usedCapacity=0.6458333, absoluteUsedCapacity=0.6458333, numApps=5, numContainers=26
2013-08-28 20:34:49,018 INFO org.apache.hadoop.yarn.server.resourcemanager.scheduler.capacity.ParentQueue: assignedContainer queue=root usedCapacity=0.6458333 absoluteUsedCapacity=0.6458333 used=<memory:31744, vCores:26> cluster=<memory:49152, vCores:96>
2013-08-28 20:34:49,019 INFO org.apache.hadoop.yarn.server.resourcemanager.rmcontainer.RMContainerImpl: container_1377721066246_0010_01_000023 Container Transitioned from NEW to ALLOCATED
2013-08-28 20:34:49,019 INFO org.apache.hadoop.yarn.server.resourcemanager.RMAuditLogger: USER=ubuntu	OPERATION=AM Allocated Container	TARGET=SchedulerApp	RESULT=SUCCESS	APPID=application_1377721066246_0010	CONTAINERID=container_1377721066246_0010_01_000023
2013-08-28 20:34:49,019 INFO org.apache.hadoop.yarn.server.resourcemanager.scheduler.common.fica.FiCaSchedulerNode: Assigned container container_1377721066246_0010_01_000023 of capacity <memory:1024, vCores:1> on host hadoop-17-2:52914, which currently has 5 containers, <memory:6144, vCores:5> used and <memory:2048, vCores:11> available
2013-08-28 20:34:49,020 INFO org.apache.hadoop.yarn.server.resourcemanager.scheduler.capacity.LeafQueue: assignedContainer application=application_1377721066246_0010 container=Container: [ContainerId: container_1377721066246_0010_01_000023, NodeId: hadoop-17-2:52914, NodeHttpAddress: hadoop-17-2:8042, Resource: <memory:1024, vCores:1>, Priority: 20, State: NEW, Token: null, Status: container_id {, app_attempt_id {, application_id {, id: 10, cluster_timestamp: 1377721066246, }, attemptId: 1, }, id: 23, }, state: C_NEW, ] containerId=container_1377721066246_0010_01_000023 queue=default: capacity=1.0, absoluteCapacity=1.0, usedResources=<memory:31744, vCores:26>usedCapacity=0.6458333, absoluteUsedCapacity=0.6458333, numApps=5, numContainers=26 usedCapacity=0.6458333 absoluteUsedCapacity=0.6458333 used=<memory:31744, vCores:26> cluster=<memory:49152, vCores:96>
2013-08-28 20:34:49,020 INFO org.apache.hadoop.yarn.server.resourcemanager.scheduler.capacity.ParentQueue: Re-sorting queues since queue: root.default stats: default: capacity=1.0, absoluteCapacity=1.0, usedResources=<memory:32768, vCores:27>usedCapacity=0.6666667, absoluteUsedCapacity=0.6666667, numApps=5, numContainers=27
2013-08-28 20:34:49,021 INFO org.apache.hadoop.yarn.server.resourcemanager.scheduler.capacity.ParentQueue: assignedContainer queue=root usedCapacity=0.6666667 absoluteUsedCapacity=0.6666667 used=<memory:32768, vCores:27> cluster=<memory:49152, vCores:96>
2013-08-28 20:34:49,022 INFO org.apache.hadoop.yarn.server.resourcemanager.rmcontainer.RMContainerImpl: container_1377721066246_0010_01_000024 Container Transitioned from NEW to ALLOCATED
2013-08-28 20:34:49,022 INFO org.apache.hadoop.yarn.server.resourcemanager.RMAuditLogger: USER=ubuntu	OPERATION=AM Allocated Container	TARGET=SchedulerApp	RESULT=SUCCESS	APPID=application_1377721066246_0010	CONTAINERID=container_1377721066246_0010_01_000024
2013-08-28 20:34:49,023 INFO org.apache.hadoop.yarn.server.resourcemanager.scheduler.common.fica.FiCaSchedulerNode: Assigned container container_1377721066246_0010_01_000024 of capacity <memory:1024, vCores:1> on host hadoop-17-2:52914, which currently has 6 containers, <memory:7168, vCores:6> used and <memory:1024, vCores:10> available
2013-08-28 20:34:49,025 INFO org.apache.hadoop.yarn.server.resourcemanager.scheduler.capacity.LeafQueue: assignedContainer application=application_1377721066246_0010 container=Container: [ContainerId: container_1377721066246_0010_01_000024, NodeId: hadoop-17-2:52914, NodeHttpAddress: hadoop-17-2:8042, Resource: <memory:1024, vCores:1>, Priority: 20, State: NEW, Token: null, Status: container_id {, app_attempt_id {, application_id {, id: 10, cluster_timestamp: 1377721066246, }, attemptId: 1, }, id: 24, }, state: C_NEW, ] containerId=container_1377721066246_0010_01_000024 queue=default: capacity=1.0, absoluteCapacity=1.0, usedResources=<memory:32768, vCores:27>usedCapacity=0.6666667, absoluteUsedCapacity=0.6666667, numApps=5, numContainers=27 usedCapacity=0.6666667 absoluteUsedCapacity=0.6666667 used=<memory:32768, vCores:27> cluster=<memory:49152, vCores:96>
2013-08-28 20:34:49,026 INFO org.apache.hadoop.yarn.server.resourcemanager.scheduler.capacity.ParentQueue: Re-sorting queues since queue: root.default stats: default: capacity=1.0, absoluteCapacity=1.0, usedResources=<memory:33792, vCores:28>usedCapacity=0.6875, absoluteUsedCapacity=0.6875, numApps=5, numContainers=28
2013-08-28 20:34:49,026 INFO org.apache.hadoop.yarn.server.resourcemanager.scheduler.capacity.ParentQueue: assignedContainer queue=root usedCapacity=0.6875 absoluteUsedCapacity=0.6875 used=<memory:33792, vCores:28> cluster=<memory:49152, vCores:96>
2013-08-28 20:34:49,027 INFO org.apache.hadoop.yarn.server.resourcemanager.rmcontainer.RMContainerImpl: container_1377721066246_0010_01_000025 Container Transitioned from NEW to ALLOCATED
2013-08-28 20:34:49,027 INFO org.apache.hadoop.yarn.server.resourcemanager.RMAuditLogger: USER=ubuntu	OPERATION=AM Allocated Container	TARGET=SchedulerApp	RESULT=SUCCESS	APPID=application_1377721066246_0010	CONTAINERID=container_1377721066246_0010_01_000025
2013-08-28 20:34:49,027 INFO org.apache.hadoop.yarn.server.resourcemanager.scheduler.common.fica.FiCaSchedulerNode: Assigned container container_1377721066246_0010_01_000025 of capacity <memory:1024, vCores:1> on host hadoop-17-2:52914, which currently has 7 containers, <memory:8192, vCores:7> used and <memory:0, vCores:9> available
2013-08-28 20:34:49,028 INFO org.apache.hadoop.yarn.server.resourcemanager.scheduler.capacity.LeafQueue: assignedContainer application=application_1377721066246_0010 container=Container: [ContainerId: container_1377721066246_0010_01_000025, NodeId: hadoop-17-2:52914, NodeHttpAddress: hadoop-17-2:8042, Resource: <memory:1024, vCores:1>, Priority: 20, State: NEW, Token: null, Status: container_id {, app_attempt_id {, application_id {, id: 10, cluster_timestamp: 1377721066246, }, attemptId: 1, }, id: 25, }, state: C_NEW, ] containerId=container_1377721066246_0010_01_000025 queue=default: capacity=1.0, absoluteCapacity=1.0, usedResources=<memory:33792, vCores:28>usedCapacity=0.6875, absoluteUsedCapacity=0.6875, numApps=5, numContainers=28 usedCapacity=0.6875 absoluteUsedCapacity=0.6875 used=<memory:33792, vCores:28> cluster=<memory:49152, vCores:96>
2013-08-28 20:34:49,028 INFO org.apache.hadoop.yarn.server.resourcemanager.scheduler.capacity.ParentQueue: Re-sorting queues since queue: root.default stats: default: capacity=1.0, absoluteCapacity=1.0, usedResources=<memory:34816, vCores:29>usedCapacity=0.7083333, absoluteUsedCapacity=0.7083333, numApps=5, numContainers=29
2013-08-28 20:34:49,028 INFO org.apache.hadoop.yarn.server.resourcemanager.scheduler.capacity.ParentQueue: assignedContainer queue=root usedCapacity=0.7083333 absoluteUsedCapacity=0.7083333 used=<memory:34816, vCores:29> cluster=<memory:49152, vCores:96>
2013-08-28 20:34:49,038 INFO org.apache.hadoop.yarn.server.resourcemanager.rmcontainer.RMContainerImpl: container_1377721066246_0010_01_000026 Container Transitioned from NEW to ALLOCATED
2013-08-28 20:34:49,038 INFO org.apache.hadoop.yarn.server.resourcemanager.RMAuditLogger: USER=ubuntu	OPERATION=AM Allocated Container	TARGET=SchedulerApp	RESULT=SUCCESS	APPID=application_1377721066246_0010	CONTAINERID=container_1377721066246_0010_01_000026
2013-08-28 20:34:49,038 INFO org.apache.hadoop.yarn.server.resourcemanager.scheduler.common.fica.FiCaSchedulerNode: Assigned container container_1377721066246_0010_01_000026 of capacity <memory:1024, vCores:1> on host hadoop-17-6:32933, which currently has 1 containers, <memory:1024, vCores:1> used and <memory:7168, vCores:15> available
2013-08-28 20:34:49,039 INFO org.apache.hadoop.yarn.server.resourcemanager.scheduler.capacity.LeafQueue: assignedContainer application=application_1377721066246_0010 container=Container: [ContainerId: container_1377721066246_0010_01_000026, NodeId: hadoop-17-6:32933, NodeHttpAddress: hadoop-17-6:8042, Resource: <memory:1024, vCores:1>, Priority: 20, State: NEW, Token: null, Status: container_id {, app_attempt_id {, application_id {, id: 10, cluster_timestamp: 1377721066246, }, attemptId: 1, }, id: 26, }, state: C_NEW, ] containerId=container_1377721066246_0010_01_000026 queue=default: capacity=1.0, absoluteCapacity=1.0, usedResources=<memory:34816, vCores:29>usedCapacity=0.7083333, absoluteUsedCapacity=0.7083333, numApps=5, numContainers=29 usedCapacity=0.7083333 absoluteUsedCapacity=0.7083333 used=<memory:34816, vCores:29> cluster=<memory:49152, vCores:96>
2013-08-28 20:34:49,040 INFO org.apache.hadoop.yarn.server.resourcemanager.scheduler.capacity.ParentQueue: Re-sorting queues since queue: root.default stats: default: capacity=1.0, absoluteCapacity=1.0, usedResources=<memory:35840, vCores:30>usedCapacity=0.7291667, absoluteUsedCapacity=0.7291667, numApps=5, numContainers=30
2013-08-28 20:34:49,040 INFO org.apache.hadoop.yarn.server.resourcemanager.scheduler.capacity.ParentQueue: assignedContainer queue=root usedCapacity=0.7291667 absoluteUsedCapacity=0.7291667 used=<memory:35840, vCores:30> cluster=<memory:49152, vCores:96>
2013-08-28 20:34:49,040 INFO org.apache.hadoop.yarn.server.resourcemanager.rmcontainer.RMContainerImpl: container_1377721066246_0010_01_000027 Container Transitioned from NEW to ALLOCATED
2013-08-28 20:34:49,040 INFO org.apache.hadoop.yarn.server.resourcemanager.RMAuditLogger: USER=ubuntu	OPERATION=AM Allocated Container	TARGET=SchedulerApp	RESULT=SUCCESS	APPID=application_1377721066246_0010	CONTAINERID=container_1377721066246_0010_01_000027
2013-08-28 20:34:49,041 INFO org.apache.hadoop.yarn.server.resourcemanager.scheduler.common.fica.FiCaSchedulerNode: Assigned container container_1377721066246_0010_01_000027 of capacity <memory:1024, vCores:1> on host hadoop-17-6:32933, which currently has 2 containers, <memory:2048, vCores:2> used and <memory:6144, vCores:14> available
2013-08-28 20:34:49,041 INFO org.apache.hadoop.yarn.server.resourcemanager.scheduler.capacity.LeafQueue: assignedContainer application=application_1377721066246_0010 container=Container: [ContainerId: container_1377721066246_0010_01_000027, NodeId: hadoop-17-6:32933, NodeHttpAddress: hadoop-17-6:8042, Resource: <memory:1024, vCores:1>, Priority: 20, State: NEW, Token: null, Status: container_id {, app_attempt_id {, application_id {, id: 10, cluster_timestamp: 1377721066246, }, attemptId: 1, }, id: 27, }, state: C_NEW, ] containerId=container_1377721066246_0010_01_000027 queue=default: capacity=1.0, absoluteCapacity=1.0, usedResources=<memory:35840, vCores:30>usedCapacity=0.7291667, absoluteUsedCapacity=0.7291667, numApps=5, numContainers=30 usedCapacity=0.7291667 absoluteUsedCapacity=0.7291667 used=<memory:35840, vCores:30> cluster=<memory:49152, vCores:96>
2013-08-28 20:34:49,042 INFO org.apache.hadoop.yarn.server.resourcemanager.scheduler.capacity.ParentQueue: Re-sorting queues since queue: root.default stats: default: capacity=1.0, absoluteCapacity=1.0, usedResources=<memory:36864, vCores:31>usedCapacity=0.75, absoluteUsedCapacity=0.75, numApps=5, numContainers=31
2013-08-28 20:34:49,042 INFO org.apache.hadoop.yarn.server.resourcemanager.scheduler.capacity.ParentQueue: assignedContainer queue=root usedCapacity=0.75 absoluteUsedCapacity=0.75 used=<memory:36864, vCores:31> cluster=<memory:49152, vCores:96>
2013-08-28 20:34:49,042 INFO org.apache.hadoop.yarn.server.resourcemanager.rmcontainer.RMContainerImpl: container_1377721066246_0010_01_000028 Container Transitioned from NEW to ALLOCATED
2013-08-28 20:34:49,042 INFO org.apache.hadoop.yarn.server.resourcemanager.RMAuditLogger: USER=ubuntu	OPERATION=AM Allocated Container	TARGET=SchedulerApp	RESULT=SUCCESS	APPID=application_1377721066246_0010	CONTAINERID=container_1377721066246_0010_01_000028
2013-08-28 20:34:49,043 INFO org.apache.hadoop.yarn.server.resourcemanager.scheduler.common.fica.FiCaSchedulerNode: Assigned container container_1377721066246_0010_01_000028 of capacity <memory:1024, vCores:1> on host hadoop-17-6:32933, which currently has 3 containers, <memory:3072, vCores:3> used and <memory:5120, vCores:13> available
2013-08-28 20:34:49,043 INFO org.apache.hadoop.yarn.server.resourcemanager.scheduler.capacity.LeafQueue: assignedContainer application=application_1377721066246_0010 container=Container: [ContainerId: container_1377721066246_0010_01_000028, NodeId: hadoop-17-6:32933, NodeHttpAddress: hadoop-17-6:8042, Resource: <memory:1024, vCores:1>, Priority: 20, State: NEW, Token: null, Status: container_id {, app_attempt_id {, application_id {, id: 10, cluster_timestamp: 1377721066246, }, attemptId: 1, }, id: 28, }, state: C_NEW, ] containerId=container_1377721066246_0010_01_000028 queue=default: capacity=1.0, absoluteCapacity=1.0, usedResources=<memory:36864, vCores:31>usedCapacity=0.75, absoluteUsedCapacity=0.75, numApps=5, numContainers=31 usedCapacity=0.75 absoluteUsedCapacity=0.75 used=<memory:36864, vCores:31> cluster=<memory:49152, vCores:96>
2013-08-28 20:34:49,044 INFO org.apache.hadoop.yarn.server.resourcemanager.scheduler.capacity.ParentQueue: Re-sorting queues since queue: root.default stats: default: capacity=1.0, absoluteCapacity=1.0, usedResources=<memory:37888, vCores:32>usedCapacity=0.7708333, absoluteUsedCapacity=0.7708333, numApps=5, numContainers=32
2013-08-28 20:34:49,044 INFO org.apache.hadoop.yarn.server.resourcemanager.scheduler.capacity.ParentQueue: assignedContainer queue=root usedCapacity=0.7708333 absoluteUsedCapacity=0.7708333 used=<memory:37888, vCores:32> cluster=<memory:49152, vCores:96>
2013-08-28 20:34:49,044 INFO org.apache.hadoop.yarn.server.resourcemanager.rmcontainer.RMContainerImpl: container_1377721066246_0010_01_000029 Container Transitioned from NEW to ALLOCATED
2013-08-28 20:34:49,044 INFO org.apache.hadoop.yarn.server.resourcemanager.RMAuditLogger: USER=ubuntu	OPERATION=AM Allocated Container	TARGET=SchedulerApp	RESULT=SUCCESS	APPID=application_1377721066246_0010	CONTAINERID=container_1377721066246_0010_01_000029
2013-08-28 20:34:49,045 INFO org.apache.hadoop.yarn.server.resourcemanager.scheduler.common.fica.FiCaSchedulerNode: Assigned container container_1377721066246_0010_01_000029 of capacity <memory:1024, vCores:1> on host hadoop-17-6:32933, which currently has 4 containers, <memory:4096, vCores:4> used and <memory:4096, vCores:12> available
2013-08-28 20:34:49,046 INFO org.apache.hadoop.yarn.server.resourcemanager.scheduler.capacity.LeafQueue: assignedContainer application=application_1377721066246_0010 container=Container: [ContainerId: container_1377721066246_0010_01_000029, NodeId: hadoop-17-6:32933, NodeHttpAddress: hadoop-17-6:8042, Resource: <memory:1024, vCores:1>, Priority: 20, State: NEW, Token: null, Status: container_id {, app_attempt_id {, application_id {, id: 10, cluster_timestamp: 1377721066246, }, attemptId: 1, }, id: 29, }, state: C_NEW, ] containerId=container_1377721066246_0010_01_000029 queue=default: capacity=1.0, absoluteCapacity=1.0, usedResources=<memory:37888, vCores:32>usedCapacity=0.7708333, absoluteUsedCapacity=0.7708333, numApps=5, numContainers=32 usedCapacity=0.7708333 absoluteUsedCapacity=0.7708333 used=<memory:37888, vCores:32> cluster=<memory:49152, vCores:96>
2013-08-28 20:34:49,046 INFO org.apache.hadoop.yarn.server.resourcemanager.scheduler.capacity.ParentQueue: Re-sorting queues since queue: root.default stats: default: capacity=1.0, absoluteCapacity=1.0, usedResources=<memory:38912, vCores:33>usedCapacity=0.7916667, absoluteUsedCapacity=0.7916667, numApps=5, numContainers=33
2013-08-28 20:34:49,046 INFO org.apache.hadoop.yarn.server.resourcemanager.scheduler.capacity.ParentQueue: assignedContainer queue=root usedCapacity=0.7916667 absoluteUsedCapacity=0.7916667 used=<memory:38912, vCores:33> cluster=<memory:49152, vCores:96>
2013-08-28 20:34:49,046 INFO org.apache.hadoop.yarn.server.resourcemanager.rmcontainer.RMContainerImpl: container_1377721066246_0010_01_000030 Container Transitioned from NEW to ALLOCATED
2013-08-28 20:34:49,047 INFO org.apache.hadoop.yarn.server.resourcemanager.RMAuditLogger: USER=ubuntu	OPERATION=AM Allocated Container	TARGET=SchedulerApp	RESULT=SUCCESS	APPID=application_1377721066246_0010	CONTAINERID=container_1377721066246_0010_01_000030
2013-08-28 20:34:49,047 INFO org.apache.hadoop.yarn.server.resourcemanager.scheduler.common.fica.FiCaSchedulerNode: Assigned container container_1377721066246_0010_01_000030 of capacity <memory:1024, vCores:1> on host hadoop-17-6:32933, which currently has 5 containers, <memory:5120, vCores:5> used and <memory:3072, vCores:11> available
2013-08-28 20:34:49,049 INFO org.apache.hadoop.yarn.server.resourcemanager.scheduler.capacity.LeafQueue: assignedContainer application=application_1377721066246_0010 container=Container: [ContainerId: container_1377721066246_0010_01_000030, NodeId: hadoop-17-6:32933, NodeHttpAddress: hadoop-17-6:8042, Resource: <memory:1024, vCores:1>, Priority: 20, State: NEW, Token: null, Status: container_id {, app_attempt_id {, application_id {, id: 10, cluster_timestamp: 1377721066246, }, attemptId: 1, }, id: 30, }, state: C_NEW, ] containerId=container_1377721066246_0010_01_000030 queue=default: capacity=1.0, absoluteCapacity=1.0, usedResources=<memory:38912, vCores:33>usedCapacity=0.7916667, absoluteUsedCapacity=0.7916667, numApps=5, numContainers=33 usedCapacity=0.7916667 absoluteUsedCapacity=0.7916667 used=<memory:38912, vCores:33> cluster=<memory:49152, vCores:96>
2013-08-28 20:34:49,049 INFO org.apache.hadoop.yarn.server.resourcemanager.scheduler.capacity.ParentQueue: Re-sorting queues since queue: root.default stats: default: capacity=1.0, absoluteCapacity=1.0, usedResources=<memory:39936, vCores:34>usedCapacity=0.8125, absoluteUsedCapacity=0.8125, numApps=5, numContainers=34
2013-08-28 20:34:49,050 INFO org.apache.hadoop.yarn.server.resourcemanager.scheduler.capacity.ParentQueue: assignedContainer queue=root usedCapacity=0.8125 absoluteUsedCapacity=0.8125 used=<memory:39936, vCores:34> cluster=<memory:49152, vCores:96>
2013-08-28 20:34:49,050 INFO org.apache.hadoop.yarn.server.resourcemanager.rmcontainer.RMContainerImpl: container_1377721066246_0010_01_000031 Container Transitioned from NEW to ALLOCATED
2013-08-28 20:34:49,050 INFO org.apache.hadoop.yarn.server.resourcemanager.RMAuditLogger: USER=ubuntu	OPERATION=AM Allocated Container	TARGET=SchedulerApp	RESULT=SUCCESS	APPID=application_1377721066246_0010	CONTAINERID=container_1377721066246_0010_01_000031
2013-08-28 20:34:49,050 INFO org.apache.hadoop.yarn.server.resourcemanager.scheduler.common.fica.FiCaSchedulerNode: Assigned container container_1377721066246_0010_01_000031 of capacity <memory:1024, vCores:1> on host hadoop-17-6:32933, which currently has 6 containers, <memory:6144, vCores:6> used and <memory:2048, vCores:10> available
2013-08-28 20:34:49,051 INFO org.apache.hadoop.yarn.server.resourcemanager.scheduler.capacity.LeafQueue: assignedContainer application=application_1377721066246_0010 container=Container: [ContainerId: container_1377721066246_0010_01_000031, NodeId: hadoop-17-6:32933, NodeHttpAddress: hadoop-17-6:8042, Resource: <memory:1024, vCores:1>, Priority: 20, State: NEW, Token: null, Status: container_id {, app_attempt_id {, application_id {, id: 10, cluster_timestamp: 1377721066246, }, attemptId: 1, }, id: 31, }, state: C_NEW, ] containerId=container_1377721066246_0010_01_000031 queue=default: capacity=1.0, absoluteCapacity=1.0, usedResources=<memory:39936, vCores:34>usedCapacity=0.8125, absoluteUsedCapacity=0.8125, numApps=5, numContainers=34 usedCapacity=0.8125 absoluteUsedCapacity=0.8125 used=<memory:39936, vCores:34> cluster=<memory:49152, vCores:96>
2013-08-28 20:34:49,052 INFO org.apache.hadoop.yarn.server.resourcemanager.scheduler.capacity.ParentQueue: Re-sorting queues since queue: root.default stats: default: capacity=1.0, absoluteCapacity=1.0, usedResources=<memory:40960, vCores:35>usedCapacity=0.8333333, absoluteUsedCapacity=0.8333333, numApps=5, numContainers=35
2013-08-28 20:34:49,052 INFO org.apache.hadoop.yarn.server.resourcemanager.scheduler.capacity.ParentQueue: assignedContainer queue=root usedCapacity=0.8333333 absoluteUsedCapacity=0.8333333 used=<memory:40960, vCores:35> cluster=<memory:49152, vCores:96>
2013-08-28 20:34:49,052 INFO org.apache.hadoop.yarn.server.resourcemanager.rmcontainer.RMContainerImpl: container_1377721066246_0010_01_000032 Container Transitioned from NEW to ALLOCATED
2013-08-28 20:34:49,052 INFO org.apache.hadoop.yarn.server.resourcemanager.RMAuditLogger: USER=ubuntu	OPERATION=AM Allocated Container	TARGET=SchedulerApp	RESULT=SUCCESS	APPID=application_1377721066246_0010	CONTAINERID=container_1377721066246_0010_01_000032
2013-08-28 20:34:49,052 INFO org.apache.hadoop.yarn.server.resourcemanager.scheduler.common.fica.FiCaSchedulerNode: Assigned container container_1377721066246_0010_01_000032 of capacity <memory:1024, vCores:1> on host hadoop-17-6:32933, which currently has 7 containers, <memory:7168, vCores:7> used and <memory:1024, vCores:9> available
2013-08-28 20:34:49,053 INFO org.apache.hadoop.yarn.server.resourcemanager.scheduler.capacity.LeafQueue: assignedContainer application=application_1377721066246_0010 container=Container: [ContainerId: container_1377721066246_0010_01_000032, NodeId: hadoop-17-6:32933, NodeHttpAddress: hadoop-17-6:8042, Resource: <memory:1024, vCores:1>, Priority: 20, State: NEW, Token: null, Status: container_id {, app_attempt_id {, application_id {, id: 10, cluster_timestamp: 1377721066246, }, attemptId: 1, }, id: 32, }, state: C_NEW, ] containerId=container_1377721066246_0010_01_000032 queue=default: capacity=1.0, absoluteCapacity=1.0, usedResources=<memory:40960, vCores:35>usedCapacity=0.8333333, absoluteUsedCapacity=0.8333333, numApps=5, numContainers=35 usedCapacity=0.8333333 absoluteUsedCapacity=0.8333333 used=<memory:40960, vCores:35> cluster=<memory:49152, vCores:96>
2013-08-28 20:34:49,054 INFO org.apache.hadoop.yarn.server.resourcemanager.scheduler.capacity.ParentQueue: Re-sorting queues since queue: root.default stats: default: capacity=1.0, absoluteCapacity=1.0, usedResources=<memory:41984, vCores:36>usedCapacity=0.8541667, absoluteUsedCapacity=0.8541667, numApps=5, numContainers=36
2013-08-28 20:34:49,054 INFO org.apache.hadoop.yarn.server.resourcemanager.scheduler.capacity.ParentQueue: assignedContainer queue=root usedCapacity=0.8541667 absoluteUsedCapacity=0.8541667 used=<memory:41984, vCores:36> cluster=<memory:49152, vCores:96>
2013-08-28 20:34:49,054 INFO org.apache.hadoop.yarn.server.resourcemanager.rmcontainer.RMContainerImpl: container_1377721066246_0010_01_000033 Container Transitioned from NEW to ALLOCATED
2013-08-28 20:34:49,054 INFO org.apache.hadoop.yarn.server.resourcemanager.RMAuditLogger: USER=ubuntu	OPERATION=AM Allocated Container	TARGET=SchedulerApp	RESULT=SUCCESS	APPID=application_1377721066246_0010	CONTAINERID=container_1377721066246_0010_01_000033
2013-08-28 20:34:49,054 INFO org.apache.hadoop.yarn.server.resourcemanager.scheduler.common.fica.FiCaSchedulerNode: Assigned container container_1377721066246_0010_01_000033 of capacity <memory:1024, vCores:1> on host hadoop-17-6:32933, which currently has 8 containers, <memory:8192, vCores:8> used and <memory:0, vCores:8> available
2013-08-28 20:34:49,055 INFO org.apache.hadoop.yarn.server.resourcemanager.scheduler.capacity.LeafQueue: assignedContainer application=application_1377721066246_0010 container=Container: [ContainerId: container_1377721066246_0010_01_000033, NodeId: hadoop-17-6:32933, NodeHttpAddress: hadoop-17-6:8042, Resource: <memory:1024, vCores:1>, Priority: 20, State: NEW, Token: null, Status: container_id {, app_attempt_id {, application_id {, id: 10, cluster_timestamp: 1377721066246, }, attemptId: 1, }, id: 33, }, state: C_NEW, ] containerId=container_1377721066246_0010_01_000033 queue=default: capacity=1.0, absoluteCapacity=1.0, usedResources=<memory:41984, vCores:36>usedCapacity=0.8541667, absoluteUsedCapacity=0.8541667, numApps=5, numContainers=36 usedCapacity=0.8541667 absoluteUsedCapacity=0.8541667 used=<memory:41984, vCores:36> cluster=<memory:49152, vCores:96>
2013-08-28 20:34:49,056 INFO org.apache.hadoop.yarn.server.resourcemanager.scheduler.capacity.ParentQueue: Re-sorting queues since queue: root.default stats: default: capacity=1.0, absoluteCapacity=1.0, usedResources=<memory:43008, vCores:37>usedCapacity=0.875, absoluteUsedCapacity=0.875, numApps=5, numContainers=37
2013-08-28 20:34:49,056 INFO org.apache.hadoop.yarn.server.resourcemanager.scheduler.capacity.ParentQueue: assignedContainer queue=root usedCapacity=0.875 absoluteUsedCapacity=0.875 used=<memory:43008, vCores:37> cluster=<memory:49152, vCores:96>
2013-08-28 20:34:49,056 INFO org.apache.hadoop.yarn.server.resourcemanager.rmcontainer.RMContainerImpl: container_1377721066246_0010_01_000034 Container Transitioned from NEW to ALLOCATED
2013-08-28 20:34:49,056 INFO org.apache.hadoop.yarn.server.resourcemanager.RMAuditLogger: USER=ubuntu	OPERATION=AM Allocated Container	TARGET=SchedulerApp	RESULT=SUCCESS	APPID=application_1377721066246_0010	CONTAINERID=container_1377721066246_0010_01_000034
2013-08-28 20:34:49,056 INFO org.apache.hadoop.yarn.server.resourcemanager.scheduler.common.fica.FiCaSchedulerNode: Assigned container container_1377721066246_0010_01_000034 of capacity <memory:1024, vCores:1> on host hadoop-17-4:59779, which currently has 2 containers, <memory:3072, vCores:2> used and <memory:5120, vCores:14> available
2013-08-28 20:34:49,057 INFO org.apache.hadoop.yarn.server.resourcemanager.scheduler.capacity.LeafQueue: assignedContainer application=application_1377721066246_0010 container=Container: [ContainerId: container_1377721066246_0010_01_000034, NodeId: hadoop-17-4:59779, NodeHttpAddress: hadoop-17-4:8042, Resource: <memory:1024, vCores:1>, Priority: 20, State: NEW, Token: null, Status: container_id {, app_attempt_id {, application_id {, id: 10, cluster_timestamp: 1377721066246, }, attemptId: 1, }, id: 34, }, state: C_NEW, ] containerId=container_1377721066246_0010_01_000034 queue=default: capacity=1.0, absoluteCapacity=1.0, usedResources=<memory:43008, vCores:37>usedCapacity=0.875, absoluteUsedCapacity=0.875, numApps=5, numContainers=37 usedCapacity=0.875 absoluteUsedCapacity=0.875 used=<memory:43008, vCores:37> cluster=<memory:49152, vCores:96>
2013-08-28 20:34:49,058 INFO org.apache.hadoop.yarn.server.resourcemanager.scheduler.capacity.ParentQueue: Re-sorting queues since queue: root.default stats: default: capacity=1.0, absoluteCapacity=1.0, usedResources=<memory:44032, vCores:38>usedCapacity=0.8958333, absoluteUsedCapacity=0.8958333, numApps=5, numContainers=38
2013-08-28 20:34:49,058 INFO org.apache.hadoop.yarn.server.resourcemanager.scheduler.capacity.ParentQueue: assignedContainer queue=root usedCapacity=0.8958333 absoluteUsedCapacity=0.8958333 used=<memory:44032, vCores:38> cluster=<memory:49152, vCores:96>
2013-08-28 20:34:49,058 INFO org.apache.hadoop.yarn.server.resourcemanager.rmcontainer.RMContainerImpl: container_1377721066246_0010_01_000035 Container Transitioned from NEW to ALLOCATED
2013-08-28 20:34:49,058 INFO org.apache.hadoop.yarn.server.resourcemanager.RMAuditLogger: USER=ubuntu	OPERATION=AM Allocated Container	TARGET=SchedulerApp	RESULT=SUCCESS	APPID=application_1377721066246_0010	CONTAINERID=container_1377721066246_0010_01_000035
2013-08-28 20:34:49,058 INFO org.apache.hadoop.yarn.server.resourcemanager.scheduler.common.fica.FiCaSchedulerNode: Assigned container container_1377721066246_0010_01_000035 of capacity <memory:1024, vCores:1> on host hadoop-17-4:59779, which currently has 3 containers, <memory:4096, vCores:3> used and <memory:4096, vCores:13> available
2013-08-28 20:34:49,059 INFO org.apache.hadoop.yarn.server.resourcemanager.scheduler.capacity.LeafQueue: assignedContainer application=application_1377721066246_0010 container=Container: [ContainerId: container_1377721066246_0010_01_000035, NodeId: hadoop-17-4:59779, NodeHttpAddress: hadoop-17-4:8042, Resource: <memory:1024, vCores:1>, Priority: 20, State: NEW, Token: null, Status: container_id {, app_attempt_id {, application_id {, id: 10, cluster_timestamp: 1377721066246, }, attemptId: 1, }, id: 35, }, state: C_NEW, ] containerId=container_1377721066246_0010_01_000035 queue=default: capacity=1.0, absoluteCapacity=1.0, usedResources=<memory:44032, vCores:38>usedCapacity=0.8958333, absoluteUsedCapacity=0.8958333, numApps=5, numContainers=38 usedCapacity=0.8958333 absoluteUsedCapacity=0.8958333 used=<memory:44032, vCores:38> cluster=<memory:49152, vCores:96>
2013-08-28 20:34:49,060 INFO org.apache.hadoop.yarn.server.resourcemanager.scheduler.capacity.ParentQueue: Re-sorting queues since queue: root.default stats: default: capacity=1.0, absoluteCapacity=1.0, usedResources=<memory:45056, vCores:39>usedCapacity=0.9166667, absoluteUsedCapacity=0.9166667, numApps=5, numContainers=39
2013-08-28 20:34:49,060 INFO org.apache.hadoop.yarn.server.resourcemanager.scheduler.capacity.ParentQueue: assignedContainer queue=root usedCapacity=0.9166667 absoluteUsedCapacity=0.9166667 used=<memory:45056, vCores:39> cluster=<memory:49152, vCores:96>
2013-08-28 20:34:49,060 INFO org.apache.hadoop.yarn.server.resourcemanager.rmcontainer.RMContainerImpl: container_1377721066246_0010_01_000036 Container Transitioned from NEW to ALLOCATED
2013-08-28 20:34:49,060 INFO org.apache.hadoop.yarn.server.resourcemanager.RMAuditLogger: USER=ubuntu	OPERATION=AM Allocated Container	TARGET=SchedulerApp	RESULT=SUCCESS	APPID=application_1377721066246_0010	CONTAINERID=container_1377721066246_0010_01_000036
2013-08-28 20:34:49,060 INFO org.apache.hadoop.yarn.server.resourcemanager.scheduler.common.fica.FiCaSchedulerNode: Assigned container container_1377721066246_0010_01_000036 of capacity <memory:1024, vCores:1> on host hadoop-17-4:59779, which currently has 4 containers, <memory:5120, vCores:4> used and <memory:3072, vCores:12> available
2013-08-28 20:34:49,061 INFO org.apache.hadoop.yarn.server.resourcemanager.scheduler.capacity.LeafQueue: assignedContainer application=application_1377721066246_0010 container=Container: [ContainerId: container_1377721066246_0010_01_000036, NodeId: hadoop-17-4:59779, NodeHttpAddress: hadoop-17-4:8042, Resource: <memory:1024, vCores:1>, Priority: 20, State: NEW, Token: null, Status: container_id {, app_attempt_id {, application_id {, id: 10, cluster_timestamp: 1377721066246, }, attemptId: 1, }, id: 36, }, state: C_NEW, ] containerId=container_1377721066246_0010_01_000036 queue=default: capacity=1.0, absoluteCapacity=1.0, usedResources=<memory:45056, vCores:39>usedCapacity=0.9166667, absoluteUsedCapacity=0.9166667, numApps=5, numContainers=39 usedCapacity=0.9166667 absoluteUsedCapacity=0.9166667 used=<memory:45056, vCores:39> cluster=<memory:49152, vCores:96>
2013-08-28 20:34:49,062 INFO org.apache.hadoop.yarn.server.resourcemanager.scheduler.capacity.ParentQueue: Re-sorting queues since queue: root.default stats: default: capacity=1.0, absoluteCapacity=1.0, usedResources=<memory:46080, vCores:40>usedCapacity=0.9375, absoluteUsedCapacity=0.9375, numApps=5, numContainers=40
2013-08-28 20:34:49,062 INFO org.apache.hadoop.yarn.server.resourcemanager.scheduler.capacity.ParentQueue: assignedContainer queue=root usedCapacity=0.9375 absoluteUsedCapacity=0.9375 used=<memory:46080, vCores:40> cluster=<memory:49152, vCores:96>
2013-08-28 20:34:49,062 INFO org.apache.hadoop.yarn.server.resourcemanager.rmcontainer.RMContainerImpl: container_1377721066246_0010_01_000037 Container Transitioned from NEW to ALLOCATED
2013-08-28 20:34:49,062 INFO org.apache.hadoop.yarn.server.resourcemanager.RMAuditLogger: USER=ubuntu	OPERATION=AM Allocated Container	TARGET=SchedulerApp	RESULT=SUCCESS	APPID=application_1377721066246_0010	CONTAINERID=container_1377721066246_0010_01_000037
2013-08-28 20:34:49,062 INFO org.apache.hadoop.yarn.server.resourcemanager.scheduler.common.fica.FiCaSchedulerNode: Assigned container container_1377721066246_0010_01_000037 of capacity <memory:1024, vCores:1> on host hadoop-17-4:59779, which currently has 5 containers, <memory:6144, vCores:5> used and <memory:2048, vCores:11> available
2013-08-28 20:34:49,063 INFO org.apache.hadoop.yarn.server.resourcemanager.scheduler.capacity.LeafQueue: assignedContainer application=application_1377721066246_0010 container=Container: [ContainerId: container_1377721066246_0010_01_000037, NodeId: hadoop-17-4:59779, NodeHttpAddress: hadoop-17-4:8042, Resource: <memory:1024, vCores:1>, Priority: 20, State: NEW, Token: null, Status: container_id {, app_attempt_id {, application_id {, id: 10, cluster_timestamp: 1377721066246, }, attemptId: 1, }, id: 37, }, state: C_NEW, ] containerId=container_1377721066246_0010_01_000037 queue=default: capacity=1.0, absoluteCapacity=1.0, usedResources=<memory:46080, vCores:40>usedCapacity=0.9375, absoluteUsedCapacity=0.9375, numApps=5, numContainers=40 usedCapacity=0.9375 absoluteUsedCapacity=0.9375 used=<memory:46080, vCores:40> cluster=<memory:49152, vCores:96>
2013-08-28 20:34:49,064 INFO org.apache.hadoop.yarn.server.resourcemanager.scheduler.capacity.ParentQueue: Re-sorting queues since queue: root.default stats: default: capacity=1.0, absoluteCapacity=1.0, usedResources=<memory:47104, vCores:41>usedCapacity=0.9583333, absoluteUsedCapacity=0.9583333, numApps=5, numContainers=41
2013-08-28 20:34:49,064 INFO org.apache.hadoop.yarn.server.resourcemanager.scheduler.capacity.ParentQueue: assignedContainer queue=root usedCapacity=0.9583333 absoluteUsedCapacity=0.9583333 used=<memory:47104, vCores:41> cluster=<memory:49152, vCores:96>
2013-08-28 20:34:49,064 INFO org.apache.hadoop.yarn.server.resourcemanager.rmcontainer.RMContainerImpl: container_1377721066246_0010_01_000038 Container Transitioned from NEW to ALLOCATED
2013-08-28 20:34:49,064 INFO org.apache.hadoop.yarn.server.resourcemanager.RMAuditLogger: USER=ubuntu	OPERATION=AM Allocated Container	TARGET=SchedulerApp	RESULT=SUCCESS	APPID=application_1377721066246_0010	CONTAINERID=container_1377721066246_0010_01_000038
2013-08-28 20:34:49,064 INFO org.apache.hadoop.yarn.server.resourcemanager.scheduler.common.fica.FiCaSchedulerNode: Assigned container container_1377721066246_0010_01_000038 of capacity <memory:1024, vCores:1> on host hadoop-17-4:59779, which currently has 6 containers, <memory:7168, vCores:6> used and <memory:1024, vCores:10> available
2013-08-28 20:34:49,065 INFO org.apache.hadoop.yarn.server.resourcemanager.scheduler.capacity.LeafQueue: assignedContainer application=application_1377721066246_0010 container=Container: [ContainerId: container_1377721066246_0010_01_000038, NodeId: hadoop-17-4:59779, NodeHttpAddress: hadoop-17-4:8042, Resource: <memory:1024, vCores:1>, Priority: 20, State: NEW, Token: null, Status: container_id {, app_attempt_id {, application_id {, id: 10, cluster_timestamp: 1377721066246, }, attemptId: 1, }, id: 38, }, state: C_NEW, ] containerId=container_1377721066246_0010_01_000038 queue=default: capacity=1.0, absoluteCapacity=1.0, usedResources=<memory:47104, vCores:41>usedCapacity=0.9583333, absoluteUsedCapacity=0.9583333, numApps=5, numContainers=41 usedCapacity=0.9583333 absoluteUsedCapacity=0.9583333 used=<memory:47104, vCores:41> cluster=<memory:49152, vCores:96>
2013-08-28 20:34:49,066 INFO org.apache.hadoop.yarn.server.resourcemanager.scheduler.capacity.ParentQueue: Re-sorting queues since queue: root.default stats: default: capacity=1.0, absoluteCapacity=1.0, usedResources=<memory:48128, vCores:42>usedCapacity=0.9791667, absoluteUsedCapacity=0.9791667, numApps=5, numContainers=42
2013-08-28 20:34:49,066 INFO org.apache.hadoop.yarn.server.resourcemanager.scheduler.capacity.ParentQueue: assignedContainer queue=root usedCapacity=0.9791667 absoluteUsedCapacity=0.9791667 used=<memory:48128, vCores:42> cluster=<memory:49152, vCores:96>
2013-08-28 20:34:49,066 INFO org.apache.hadoop.yarn.server.resourcemanager.rmcontainer.RMContainerImpl: container_1377721066246_0010_01_000039 Container Transitioned from NEW to ALLOCATED
2013-08-28 20:34:49,066 INFO org.apache.hadoop.yarn.server.resourcemanager.RMAuditLogger: USER=ubuntu	OPERATION=AM Allocated Container	TARGET=SchedulerApp	RESULT=SUCCESS	APPID=application_1377721066246_0010	CONTAINERID=container_1377721066246_0010_01_000039
2013-08-28 20:34:49,067 INFO org.apache.hadoop.yarn.server.resourcemanager.scheduler.common.fica.FiCaSchedulerNode: Assigned container container_1377721066246_0010_01_000039 of capacity <memory:1024, vCores:1> on host hadoop-17-4:59779, which currently has 7 containers, <memory:8192, vCores:7> used and <memory:0, vCores:9> available
2013-08-28 20:34:49,067 INFO org.apache.hadoop.yarn.server.resourcemanager.scheduler.capacity.LeafQueue: assignedContainer application=application_1377721066246_0010 container=Container: [ContainerId: container_1377721066246_0010_01_000039, NodeId: hadoop-17-4:59779, NodeHttpAddress: hadoop-17-4:8042, Resource: <memory:1024, vCores:1>, Priority: 20, State: NEW, Token: null, Status: container_id {, app_attempt_id {, application_id {, id: 10, cluster_timestamp: 1377721066246, }, attemptId: 1, }, id: 39, }, state: C_NEW, ] containerId=container_1377721066246_0010_01_000039 queue=default: capacity=1.0, absoluteCapacity=1.0, usedResources=<memory:48128, vCores:42>usedCapacity=0.9791667, absoluteUsedCapacity=0.9791667, numApps=5, numContainers=42 usedCapacity=0.9791667 absoluteUsedCapacity=0.9791667 used=<memory:48128, vCores:42> cluster=<memory:49152, vCores:96>
2013-08-28 20:34:49,068 INFO org.apache.hadoop.yarn.server.resourcemanager.scheduler.capacity.ParentQueue: Re-sorting queues since queue: root.default stats: default: capacity=1.0, absoluteCapacity=1.0, usedResources=<memory:49152, vCores:43>usedCapacity=1.0, absoluteUsedCapacity=1.0, numApps=5, numContainers=43
2013-08-28 20:34:49,068 INFO org.apache.hadoop.yarn.server.resourcemanager.scheduler.capacity.ParentQueue: assignedContainer queue=root usedCapacity=1.0 absoluteUsedCapacity=1.0 used=<memory:49152, vCores:43> cluster=<memory:49152, vCores:96>
2013-08-28 20:34:49,096 INFO org.apache.hadoop.yarn.server.resourcemanager.rmcontainer.RMContainerImpl: container_1377721066246_0010_01_000002 Container Transitioned from ALLOCATED to ACQUIRED
2013-08-28 20:34:49,098 INFO org.apache.hadoop.yarn.server.resourcemanager.rmcontainer.RMContainerImpl: container_1377721066246_0010_01_000003 Container Transitioned from ALLOCATED to ACQUIRED
2013-08-28 20:34:49,099 INFO org.apache.hadoop.yarn.server.resourcemanager.rmcontainer.RMContainerImpl: container_1377721066246_0010_01_000004 Container Transitioned from ALLOCATED to ACQUIRED
2013-08-28 20:34:49,102 INFO org.apache.hadoop.yarn.server.resourcemanager.rmcontainer.RMContainerImpl: container_1377721066246_0010_01_000005 Container Transitioned from ALLOCATED to ACQUIRED
2013-08-28 20:34:49,103 INFO org.apache.hadoop.yarn.server.resourcemanager.rmcontainer.RMContainerImpl: container_1377721066246_0010_01_000006 Container Transitioned from ALLOCATED to ACQUIRED
2013-08-28 20:34:49,104 INFO org.apache.hadoop.yarn.server.resourcemanager.rmcontainer.RMContainerImpl: container_1377721066246_0010_01_000007 Container Transitioned from ALLOCATED to ACQUIRED
2013-08-28 20:34:49,105 INFO org.apache.hadoop.yarn.server.resourcemanager.rmcontainer.RMContainerImpl: container_1377721066246_0010_01_000008 Container Transitioned from ALLOCATED to ACQUIRED
2013-08-28 20:34:49,106 INFO org.apache.hadoop.yarn.server.resourcemanager.rmcontainer.RMContainerImpl: container_1377721066246_0010_01_000009 Container Transitioned from ALLOCATED to ACQUIRED
2013-08-28 20:34:49,107 INFO org.apache.hadoop.yarn.server.resourcemanager.rmcontainer.RMContainerImpl: container_1377721066246_0010_01_000010 Container Transitioned from ALLOCATED to ACQUIRED
2013-08-28 20:34:49,109 INFO org.apache.hadoop.yarn.server.resourcemanager.rmcontainer.RMContainerImpl: container_1377721066246_0010_01_000011 Container Transitioned from ALLOCATED to ACQUIRED
2013-08-28 20:34:49,110 INFO org.apache.hadoop.yarn.server.resourcemanager.rmcontainer.RMContainerImpl: container_1377721066246_0010_01_000012 Container Transitioned from ALLOCATED to ACQUIRED
2013-08-28 20:34:49,110 INFO org.apache.hadoop.yarn.server.resourcemanager.rmcontainer.RMContainerImpl: container_1377721066246_0010_01_000013 Container Transitioned from ALLOCATED to ACQUIRED
2013-08-28 20:34:49,111 INFO org.apache.hadoop.yarn.server.resourcemanager.rmcontainer.RMContainerImpl: container_1377721066246_0010_01_000014 Container Transitioned from ALLOCATED to ACQUIRED
2013-08-28 20:34:49,111 INFO org.apache.hadoop.yarn.server.resourcemanager.rmcontainer.RMContainerImpl: container_1377721066246_0010_01_000015 Container Transitioned from ALLOCATED to ACQUIRED
2013-08-28 20:34:49,112 INFO org.apache.hadoop.yarn.server.resourcemanager.rmcontainer.RMContainerImpl: container_1377721066246_0010_01_000016 Container Transitioned from ALLOCATED to ACQUIRED
2013-08-28 20:34:49,113 INFO org.apache.hadoop.yarn.server.resourcemanager.rmcontainer.RMContainerImpl: container_1377721066246_0010_01_000017 Container Transitioned from ALLOCATED to ACQUIRED
2013-08-28 20:34:49,113 INFO org.apache.hadoop.yarn.server.resourcemanager.rmcontainer.RMContainerImpl: container_1377721066246_0010_01_000018 Container Transitioned from ALLOCATED to ACQUIRED
2013-08-28 20:34:49,114 INFO org.apache.hadoop.yarn.server.resourcemanager.rmcontainer.RMContainerImpl: container_1377721066246_0010_01_000019 Container Transitioned from ALLOCATED to ACQUIRED
2013-08-28 20:34:49,115 INFO org.apache.hadoop.yarn.server.resourcemanager.rmcontainer.RMContainerImpl: container_1377721066246_0010_01_000020 Container Transitioned from ALLOCATED to ACQUIRED
2013-08-28 20:34:49,115 INFO org.apache.hadoop.yarn.server.resourcemanager.rmcontainer.RMContainerImpl: container_1377721066246_0010_01_000021 Container Transitioned from ALLOCATED to ACQUIRED
2013-08-28 20:34:49,115 INFO org.apache.hadoop.yarn.server.resourcemanager.rmcontainer.RMContainerImpl: container_1377721066246_0010_01_000022 Container Transitioned from ALLOCATED to ACQUIRED
2013-08-28 20:34:49,115 INFO org.apache.hadoop.yarn.server.resourcemanager.rmcontainer.RMContainerImpl: container_1377721066246_0010_01_000023 Container Transitioned from ALLOCATED to ACQUIRED
2013-08-28 20:34:49,116 INFO org.apache.hadoop.yarn.server.resourcemanager.rmcontainer.RMContainerImpl: container_1377721066246_0010_01_000024 Container Transitioned from ALLOCATED to ACQUIRED
2013-08-28 20:34:49,116 INFO org.apache.hadoop.yarn.server.resourcemanager.rmcontainer.RMContainerImpl: container_1377721066246_0010_01_000025 Container Transitioned from ALLOCATED to ACQUIRED
2013-08-28 20:34:49,116 INFO org.apache.hadoop.yarn.server.resourcemanager.rmcontainer.RMContainerImpl: container_1377721066246_0010_01_000026 Container Transitioned from ALLOCATED to ACQUIRED
2013-08-28 20:34:49,116 INFO org.apache.hadoop.yarn.server.resourcemanager.rmcontainer.RMContainerImpl: container_1377721066246_0010_01_000027 Container Transitioned from ALLOCATED to ACQUIRED
2013-08-28 20:34:49,116 INFO org.apache.hadoop.yarn.server.resourcemanager.rmcontainer.RMContainerImpl: container_1377721066246_0010_01_000028 Container Transitioned from ALLOCATED to ACQUIRED
2013-08-28 20:34:49,117 INFO org.apache.hadoop.yarn.server.resourcemanager.rmcontainer.RMContainerImpl: container_1377721066246_0010_01_000029 Container Transitioned from ALLOCATED to ACQUIRED
2013-08-28 20:34:49,117 INFO org.apache.hadoop.yarn.server.resourcemanager.rmcontainer.RMContainerImpl: container_1377721066246_0010_01_000030 Container Transitioned from ALLOCATED to ACQUIRED
2013-08-28 20:34:49,117 INFO org.apache.hadoop.yarn.server.resourcemanager.rmcontainer.RMContainerImpl: container_1377721066246_0010_01_000031 Container Transitioned from ALLOCATED to ACQUIRED
2013-08-28 20:34:49,117 INFO org.apache.hadoop.yarn.server.resourcemanager.rmcontainer.RMContainerImpl: container_1377721066246_0010_01_000032 Container Transitioned from ALLOCATED to ACQUIRED
2013-08-28 20:34:49,117 INFO org.apache.hadoop.yarn.server.resourcemanager.rmcontainer.RMContainerImpl: container_1377721066246_0010_01_000033 Container Transitioned from ALLOCATED to ACQUIRED
2013-08-28 20:34:49,118 INFO org.apache.hadoop.yarn.server.resourcemanager.rmcontainer.RMContainerImpl: container_1377721066246_0010_01_000034 Container Transitioned from ALLOCATED to ACQUIRED
2013-08-28 20:34:49,118 INFO org.apache.hadoop.yarn.server.resourcemanager.rmcontainer.RMContainerImpl: container_1377721066246_0010_01_000035 Container Transitioned from ALLOCATED to ACQUIRED
2013-08-28 20:34:49,118 INFO org.apache.hadoop.yarn.server.resourcemanager.rmcontainer.RMContainerImpl: container_1377721066246_0010_01_000036 Container Transitioned from ALLOCATED to ACQUIRED
2013-08-28 20:34:49,118 INFO org.apache.hadoop.yarn.server.resourcemanager.rmcontainer.RMContainerImpl: container_1377721066246_0010_01_000037 Container Transitioned from ALLOCATED to ACQUIRED
2013-08-28 20:34:49,119 INFO org.apache.hadoop.yarn.server.resourcemanager.rmcontainer.RMContainerImpl: container_1377721066246_0010_01_000038 Container Transitioned from ALLOCATED to ACQUIRED
2013-08-28 20:34:49,119 INFO org.apache.hadoop.yarn.server.resourcemanager.rmcontainer.RMContainerImpl: container_1377721066246_0010_01_000039 Container Transitioned from ALLOCATED to ACQUIRED
2013-08-28 20:34:50,032 INFO org.apache.hadoop.yarn.server.resourcemanager.rmcontainer.RMContainerImpl: container_1377721066246_0010_01_000020 Container Transitioned from ACQUIRED to RUNNING
2013-08-28 20:34:50,037 INFO org.apache.hadoop.yarn.server.resourcemanager.rmcontainer.RMContainerImpl: container_1377721066246_0010_01_000021 Container Transitioned from ACQUIRED to RUNNING
2013-08-28 20:34:50,038 INFO org.apache.hadoop.yarn.server.resourcemanager.rmcontainer.RMContainerImpl: container_1377721066246_0010_01_000022 Container Transitioned from ACQUIRED to RUNNING
2013-08-28 20:34:50,039 INFO org.apache.hadoop.yarn.server.resourcemanager.rmcontainer.RMContainerImpl: container_1377721066246_0010_01_000023 Container Transitioned from ACQUIRED to RUNNING
2013-08-28 20:34:50,040 INFO org.apache.hadoop.yarn.server.resourcemanager.rmcontainer.RMContainerImpl: container_1377721066246_0010_01_000024 Container Transitioned from ACQUIRED to RUNNING
2013-08-28 20:34:50,041 INFO org.apache.hadoop.yarn.server.resourcemanager.rmcontainer.RMContainerImpl: container_1377721066246_0010_01_000025 Container Transitioned from ACQUIRED to RUNNING
2013-08-28 20:34:50,055 INFO org.apache.hadoop.yarn.server.resourcemanager.rmcontainer.RMContainerImpl: container_1377721066246_0010_01_000026 Container Transitioned from ACQUIRED to RUNNING
2013-08-28 20:34:50,056 INFO org.apache.hadoop.yarn.server.resourcemanager.rmcontainer.RMContainerImpl: container_1377721066246_0010_01_000027 Container Transitioned from ACQUIRED to RUNNING
2013-08-28 20:34:50,057 INFO org.apache.hadoop.yarn.server.resourcemanager.rmcontainer.RMContainerImpl: container_1377721066246_0010_01_000028 Container Transitioned from ACQUIRED to RUNNING
2013-08-28 20:34:50,059 INFO org.apache.hadoop.yarn.server.resourcemanager.rmcontainer.RMContainerImpl: container_1377721066246_0010_01_000029 Container Transitioned from ACQUIRED to RUNNING
2013-08-28 20:34:50,059 INFO org.apache.hadoop.yarn.server.resourcemanager.rmcontainer.RMContainerImpl: container_1377721066246_0010_01_000030 Container Transitioned from ACQUIRED to RUNNING
2013-08-28 20:34:50,059 INFO org.apache.hadoop.yarn.server.resourcemanager.rmcontainer.RMContainerImpl: container_1377721066246_0010_01_000031 Container Transitioned from ACQUIRED to RUNNING
2013-08-28 20:34:50,060 INFO org.apache.hadoop.yarn.server.resourcemanager.rmcontainer.RMContainerImpl: container_1377721066246_0010_01_000032 Container Transitioned from ACQUIRED to RUNNING
2013-08-28 20:34:50,060 INFO org.apache.hadoop.yarn.server.resourcemanager.rmcontainer.RMContainerImpl: container_1377721066246_0010_01_000033 Container Transitioned from ACQUIRED to RUNNING
2013-08-28 20:34:50,067 INFO org.apache.hadoop.yarn.server.resourcemanager.rmcontainer.RMContainerImpl: container_1377721066246_0010_01_000034 Container Transitioned from ACQUIRED to RUNNING
2013-08-28 20:34:50,067 INFO org.apache.hadoop.yarn.server.resourcemanager.rmcontainer.RMContainerImpl: container_1377721066246_0010_01_000035 Container Transitioned from ACQUIRED to RUNNING
2013-08-28 20:34:50,068 INFO org.apache.hadoop.yarn.server.resourcemanager.rmcontainer.RMContainerImpl: container_1377721066246_0010_01_000036 Container Transitioned from ACQUIRED to RUNNING
2013-08-28 20:34:50,068 INFO org.apache.hadoop.yarn.server.resourcemanager.rmcontainer.RMContainerImpl: container_1377721066246_0010_01_000037 Container Transitioned from ACQUIRED to RUNNING
2013-08-28 20:34:50,069 INFO org.apache.hadoop.yarn.server.resourcemanager.rmcontainer.RMContainerImpl: container_1377721066246_0010_01_000038 Container Transitioned from ACQUIRED to RUNNING
2013-08-28 20:34:50,070 INFO org.apache.hadoop.yarn.server.resourcemanager.rmcontainer.RMContainerImpl: container_1377721066246_0010_01_000039 Container Transitioned from ACQUIRED to RUNNING
2013-08-28 20:34:50,173 INFO org.apache.hadoop.yarn.server.resourcemanager.rmcontainer.RMContainerImpl: container_1377721066246_0010_01_000002 Container Transitioned from ACQUIRED to RUNNING
2013-08-28 20:34:50,173 INFO org.apache.hadoop.yarn.server.resourcemanager.rmcontainer.RMContainerImpl: container_1377721066246_0010_01_000003 Container Transitioned from ACQUIRED to RUNNING
2013-08-28 20:34:50,174 INFO org.apache.hadoop.yarn.server.resourcemanager.rmcontainer.RMContainerImpl: container_1377721066246_0010_01_000004 Container Transitioned from ACQUIRED to RUNNING
2013-08-28 20:34:50,174 INFO org.apache.hadoop.yarn.server.resourcemanager.rmcontainer.RMContainerImpl: container_1377721066246_0010_01_000005 Container Transitioned from ACQUIRED to RUNNING
2013-08-28 20:34:50,174 INFO org.apache.hadoop.yarn.server.resourcemanager.rmcontainer.RMContainerImpl: container_1377721066246_0010_01_000006 Container Transitioned from ACQUIRED to RUNNING
2013-08-28 20:34:50,174 INFO org.apache.hadoop.yarn.server.resourcemanager.rmcontainer.RMContainerImpl: container_1377721066246_0010_01_000007 Container Transitioned from ACQUIRED to RUNNING
2013-08-28 20:34:50,199 INFO org.apache.hadoop.yarn.server.resourcemanager.rmcontainer.RMContainerImpl: container_1377721066246_0010_01_000008 Container Transitioned from ACQUIRED to RUNNING
2013-08-28 20:34:50,199 INFO org.apache.hadoop.yarn.server.resourcemanager.rmcontainer.RMContainerImpl: container_1377721066246_0010_01_000009 Container Transitioned from ACQUIRED to RUNNING
2013-08-28 20:34:50,199 INFO org.apache.hadoop.yarn.server.resourcemanager.rmcontainer.RMContainerImpl: container_1377721066246_0010_01_000010 Container Transitioned from ACQUIRED to RUNNING
2013-08-28 20:34:50,199 INFO org.apache.hadoop.yarn.server.resourcemanager.rmcontainer.RMContainerImpl: container_1377721066246_0010_01_000011 Container Transitioned from ACQUIRED to RUNNING
2013-08-28 20:34:50,199 INFO org.apache.hadoop.yarn.server.resourcemanager.rmcontainer.RMContainerImpl: container_1377721066246_0010_01_000012 Container Transitioned from ACQUIRED to RUNNING
2013-08-28 20:34:50,199 INFO org.apache.hadoop.yarn.server.resourcemanager.rmcontainer.RMContainerImpl: container_1377721066246_0010_01_000013 Container Transitioned from ACQUIRED to RUNNING
2013-08-28 20:34:50,302 INFO org.apache.hadoop.yarn.server.resourcemanager.rmcontainer.RMContainerImpl: container_1377721066246_0010_01_000014 Container Transitioned from ACQUIRED to RUNNING
2013-08-28 20:34:50,302 INFO org.apache.hadoop.yarn.server.resourcemanager.rmcontainer.RMContainerImpl: container_1377721066246_0010_01_000015 Container Transitioned from ACQUIRED to RUNNING
2013-08-28 20:34:50,302 INFO org.apache.hadoop.yarn.server.resourcemanager.rmcontainer.RMContainerImpl: container_1377721066246_0010_01_000016 Container Transitioned from ACQUIRED to RUNNING
2013-08-28 20:34:50,302 INFO org.apache.hadoop.yarn.server.resourcemanager.rmcontainer.RMContainerImpl: container_1377721066246_0010_01_000017 Container Transitioned from ACQUIRED to RUNNING
2013-08-28 20:34:50,302 INFO org.apache.hadoop.yarn.server.resourcemanager.rmcontainer.RMContainerImpl: container_1377721066246_0010_01_000018 Container Transitioned from ACQUIRED to RUNNING
2013-08-28 20:34:50,303 INFO org.apache.hadoop.yarn.server.resourcemanager.rmcontainer.RMContainerImpl: container_1377721066246_0010_01_000019 Container Transitioned from ACQUIRED to RUNNING
2013-08-28 20:35:16,224 INFO org.apache.hadoop.yarn.server.resourcemanager.rmcontainer.RMContainerImpl: container_1377721066246_0010_01_000009 Container Transitioned from RUNNING to COMPLETED
2013-08-28 20:35:16,225 INFO org.apache.hadoop.yarn.server.resourcemanager.scheduler.common.fica.FiCaSchedulerApp: Completed container: container_1377721066246_0010_01_000009 in state: COMPLETED event:FINISHED
2013-08-28 20:35:16,225 INFO org.apache.hadoop.yarn.server.resourcemanager.RMAuditLogger: USER=ubuntu	OPERATION=AM Released Container	TARGET=SchedulerApp	RESULT=SUCCESS	APPID=application_1377721066246_0010	CONTAINERID=container_1377721066246_0010_01_000009
2013-08-28 20:35:16,225 INFO org.apache.hadoop.yarn.server.resourcemanager.scheduler.common.fica.FiCaSchedulerNode: Released container container_1377721066246_0010_01_000009 of capacity <memory:1024, vCores:1> on host hadoop-17-3:35481, which currently has 6 containers, <memory:7168, vCores:6> used and <memory:1024, vCores:10> available, release resources=true
2013-08-28 20:35:16,225 INFO org.apache.hadoop.yarn.server.resourcemanager.scheduler.capacity.LeafQueue: default used=<memory:48128, vCores:42> numContainers=42 user=ubuntu user-resources=<memory:48128, vCores:42>
2013-08-28 20:35:16,228 INFO org.apache.hadoop.yarn.server.resourcemanager.scheduler.capacity.LeafQueue: completedContainer container=Container: [ContainerId: container_1377721066246_0010_01_000009, NodeId: hadoop-17-3:35481, NodeHttpAddress: hadoop-17-3:8042, Resource: <memory:1024, vCores:1>, Priority: 20, State: NEW, Token: null, Status: container_id {, app_attempt_id {, application_id {, id: 10, cluster_timestamp: 1377721066246, }, attemptId: 1, }, id: 9, }, state: C_COMPLETE, diagnostics: "Container killed by the ApplicationMaster.\n", exit_status: 0, ] resource=<memory:1024, vCores:1> queue=default: capacity=1.0, absoluteCapacity=1.0, usedResources=<memory:48128, vCores:42>usedCapacity=0.9791667, absoluteUsedCapacity=0.9791667, numApps=5, numContainers=42 usedCapacity=0.9791667 absoluteUsedCapacity=0.9791667 used=<memory:48128, vCores:42> cluster=<memory:49152, vCores:96>
2013-08-28 20:35:16,228 INFO org.apache.hadoop.yarn.server.resourcemanager.scheduler.capacity.ParentQueue: completedContainer queue=root usedCapacity=0.9791667 absoluteUsedCapacity=0.9791667 used=<memory:48128, vCores:42> cluster=<memory:49152, vCores:96>
2013-08-28 20:35:16,228 INFO org.apache.hadoop.yarn.server.resourcemanager.scheduler.capacity.CapacityScheduler: Application appattempt_1377721066246_0010_000001 released container container_1377721066246_0010_01_000009 on node: host: hadoop-17-3:35481 #containers=6 available=1024 used=7168 with event: FINISHED
2013-08-28 20:35:16,229 INFO org.apache.hadoop.yarn.server.resourcemanager.rmcontainer.RMContainerImpl: container_1377721066246_0006_01_000002 Container Transitioned from NEW to ALLOCATED
2013-08-28 20:35:16,229 INFO org.apache.hadoop.yarn.server.resourcemanager.RMAuditLogger: USER=ubuntu	OPERATION=AM Allocated Container	TARGET=SchedulerApp	RESULT=SUCCESS	APPID=application_1377721066246_0006	CONTAINERID=container_1377721066246_0006_01_000002
2013-08-28 20:35:16,229 INFO org.apache.hadoop.yarn.server.resourcemanager.scheduler.common.fica.FiCaSchedulerNode: Assigned container container_1377721066246_0006_01_000002 of capacity <memory:1024, vCores:1> on host hadoop-17-3:35481, which currently has 7 containers, <memory:8192, vCores:7> used and <memory:0, vCores:9> available
2013-08-28 20:35:16,230 INFO org.apache.hadoop.yarn.server.resourcemanager.scheduler.capacity.LeafQueue: assignedContainer application=application_1377721066246_0006 container=Container: [ContainerId: container_1377721066246_0006_01_000002, NodeId: hadoop-17-3:35481, NodeHttpAddress: hadoop-17-3:8042, Resource: <memory:1024, vCores:1>, Priority: 20, State: NEW, Token: null, Status: container_id {, app_attempt_id {, application_id {, id: 6, cluster_timestamp: 1377721066246, }, attemptId: 1, }, id: 2, }, state: C_NEW, ] containerId=container_1377721066246_0006_01_000002 queue=default: capacity=1.0, absoluteCapacity=1.0, usedResources=<memory:48128, vCores:42>usedCapacity=0.9791667, absoluteUsedCapacity=0.9791667, numApps=5, numContainers=42 usedCapacity=0.9791667 absoluteUsedCapacity=0.9791667 used=<memory:48128, vCores:42> cluster=<memory:49152, vCores:96>
2013-08-28 20:35:16,230 INFO org.apache.hadoop.yarn.server.resourcemanager.scheduler.capacity.ParentQueue: Re-sorting queues since queue: root.default stats: default: capacity=1.0, absoluteCapacity=1.0, usedResources=<memory:49152, vCores:43>usedCapacity=1.0, absoluteUsedCapacity=1.0, numApps=5, numContainers=43
2013-08-28 20:35:16,230 INFO org.apache.hadoop.yarn.server.resourcemanager.scheduler.capacity.ParentQueue: assignedContainer queue=root usedCapacity=1.0 absoluteUsedCapacity=1.0 used=<memory:49152, vCores:43> cluster=<memory:49152, vCores:96>
2013-08-28 20:35:16,793 INFO org.apache.hadoop.yarn.server.resourcemanager.rmcontainer.RMContainerImpl: container_1377721066246_0006_01_000002 Container Transitioned from ALLOCATED to ACQUIRED
2013-08-28 20:35:17,245 INFO org.apache.hadoop.yarn.server.resourcemanager.rmcontainer.RMContainerImpl: container_1377721066246_0010_01_000027 Container Transitioned from RUNNING to COMPLETED
2013-08-28 20:35:17,245 INFO org.apache.hadoop.yarn.server.resourcemanager.scheduler.common.fica.FiCaSchedulerApp: Completed container: container_1377721066246_0010_01_000027 in state: COMPLETED event:FINISHED
2013-08-28 20:35:17,245 INFO org.apache.hadoop.yarn.server.resourcemanager.RMAuditLogger: USER=ubuntu	OPERATION=AM Released Container	TARGET=SchedulerApp	RESULT=SUCCESS	APPID=application_1377721066246_0010	CONTAINERID=container_1377721066246_0010_01_000027
2013-08-28 20:35:17,245 INFO org.apache.hadoop.yarn.server.resourcemanager.scheduler.common.fica.FiCaSchedulerNode: Released container container_1377721066246_0010_01_000027 of capacity <memory:1024, vCores:1> on host hadoop-17-6:32933, which currently has 7 containers, <memory:7168, vCores:7> used and <memory:1024, vCores:9> available, release resources=true
2013-08-28 20:35:17,246 INFO org.apache.hadoop.yarn.server.resourcemanager.scheduler.capacity.LeafQueue: default used=<memory:48128, vCores:42> numContainers=42 user=ubuntu user-resources=<memory:48128, vCores:42>
2013-08-28 20:35:17,247 INFO org.apache.hadoop.yarn.server.resourcemanager.scheduler.capacity.LeafQueue: completedContainer container=Container: [ContainerId: container_1377721066246_0010_01_000027, NodeId: hadoop-17-6:32933, NodeHttpAddress: hadoop-17-6:8042, Resource: <memory:1024, vCores:1>, Priority: 20, State: NEW, Token: null, Status: container_id {, app_attempt_id {, application_id {, id: 10, cluster_timestamp: 1377721066246, }, attemptId: 1, }, id: 27, }, state: C_COMPLETE, diagnostics: "Container killed by the ApplicationMaster.\n\n", exit_status: 143, ] resource=<memory:1024, vCores:1> queue=default: capacity=1.0, absoluteCapacity=1.0, usedResources=<memory:48128, vCores:42>usedCapacity=0.9791667, absoluteUsedCapacity=0.9791667, numApps=5, numContainers=42 usedCapacity=0.9791667 absoluteUsedCapacity=0.9791667 used=<memory:48128, vCores:42> cluster=<memory:49152, vCores:96>
2013-08-28 20:35:17,247 INFO org.apache.hadoop.yarn.server.resourcemanager.scheduler.capacity.ParentQueue: completedContainer queue=root usedCapacity=0.9791667 absoluteUsedCapacity=0.9791667 used=<memory:48128, vCores:42> cluster=<memory:49152, vCores:96>
2013-08-28 20:35:17,247 INFO org.apache.hadoop.yarn.server.resourcemanager.scheduler.capacity.CapacityScheduler: Application appattempt_1377721066246_0010_000001 released container container_1377721066246_0010_01_000027 on node: host: hadoop-17-6:32933 #containers=7 available=1024 used=7168 with event: FINISHED
2013-08-28 20:35:17,248 INFO org.apache.hadoop.yarn.server.resourcemanager.rmcontainer.RMContainerImpl: container_1377721066246_0006_01_000003 Container Transitioned from NEW to ALLOCATED
2013-08-28 20:35:17,248 INFO org.apache.hadoop.yarn.server.resourcemanager.RMAuditLogger: USER=ubuntu	OPERATION=AM Allocated Container	TARGET=SchedulerApp	RESULT=SUCCESS	APPID=application_1377721066246_0006	CONTAINERID=container_1377721066246_0006_01_000003
2013-08-28 20:35:17,248 INFO org.apache.hadoop.yarn.server.resourcemanager.scheduler.common.fica.FiCaSchedulerNode: Assigned container container_1377721066246_0006_01_000003 of capacity <memory:1024, vCores:1> on host hadoop-17-6:32933, which currently has 8 containers, <memory:8192, vCores:8> used and <memory:0, vCores:8> available
2013-08-28 20:35:17,249 INFO org.apache.hadoop.yarn.server.resourcemanager.scheduler.capacity.LeafQueue: assignedContainer application=application_1377721066246_0006 container=Container: [ContainerId: container_1377721066246_0006_01_000003, NodeId: hadoop-17-6:32933, NodeHttpAddress: hadoop-17-6:8042, Resource: <memory:1024, vCores:1>, Priority: 20, State: NEW, Token: null, Status: container_id {, app_attempt_id {, application_id {, id: 6, cluster_timestamp: 1377721066246, }, attemptId: 1, }, id: 3, }, state: C_NEW, ] containerId=container_1377721066246_0006_01_000003 queue=default: capacity=1.0, absoluteCapacity=1.0, usedResources=<memory:48128, vCores:42>usedCapacity=0.9791667, absoluteUsedCapacity=0.9791667, numApps=5, numContainers=42 usedCapacity=0.9791667 absoluteUsedCapacity=0.9791667 used=<memory:48128, vCores:42> cluster=<memory:49152, vCores:96>
2013-08-28 20:35:17,249 INFO org.apache.hadoop.yarn.server.resourcemanager.scheduler.capacity.ParentQueue: Re-sorting queues since queue: root.default stats: default: capacity=1.0, absoluteCapacity=1.0, usedResources=<memory:49152, vCores:43>usedCapacity=1.0, absoluteUsedCapacity=1.0, numApps=5, numContainers=43
2013-08-28 20:35:17,249 INFO org.apache.hadoop.yarn.server.resourcemanager.scheduler.capacity.ParentQueue: assignedContainer queue=root usedCapacity=1.0 absoluteUsedCapacity=1.0 used=<memory:49152, vCores:43> cluster=<memory:49152, vCores:96>
2013-08-28 20:35:17,272 INFO org.apache.hadoop.yarn.server.resourcemanager.rmcontainer.RMContainerImpl: container_1377721066246_0010_01_000013 Container Transitioned from RUNNING to COMPLETED
2013-08-28 20:35:17,272 INFO org.apache.hadoop.yarn.server.resourcemanager.scheduler.common.fica.FiCaSchedulerApp: Completed container: container_1377721066246_0010_01_000013 in state: COMPLETED event:FINISHED
2013-08-28 20:35:17,272 INFO org.apache.hadoop.yarn.server.resourcemanager.RMAuditLogger: USER=ubuntu	OPERATION=AM Released Container	TARGET=SchedulerApp	RESULT=SUCCESS	APPID=application_1377721066246_0010	CONTAINERID=container_1377721066246_0010_01_000013
2013-08-28 20:35:17,272 INFO org.apache.hadoop.yarn.server.resourcemanager.scheduler.common.fica.FiCaSchedulerNode: Released container container_1377721066246_0010_01_000013 of capacity <memory:1024, vCores:1> on host hadoop-17-3:35481, which currently has 6 containers, <memory:7168, vCores:6> used and <memory:1024, vCores:10> available, release resources=true
2013-08-28 20:35:17,272 INFO org.apache.hadoop.yarn.server.resourcemanager.scheduler.capacity.LeafQueue: default used=<memory:48128, vCores:42> numContainers=42 user=ubuntu user-resources=<memory:48128, vCores:42>
2013-08-28 20:35:17,273 INFO org.apache.hadoop.yarn.server.resourcemanager.scheduler.capacity.LeafQueue: completedContainer container=Container: [ContainerId: container_1377721066246_0010_01_000013, NodeId: hadoop-17-3:35481, NodeHttpAddress: hadoop-17-3:8042, Resource: <memory:1024, vCores:1>, Priority: 20, State: NEW, Token: null, Status: container_id {, app_attempt_id {, application_id {, id: 10, cluster_timestamp: 1377721066246, }, attemptId: 1, }, id: 13, }, state: C_COMPLETE, diagnostics: "Container killed by the ApplicationMaster.\n\n", exit_status: 143, ] resource=<memory:1024, vCores:1> queue=default: capacity=1.0, absoluteCapacity=1.0, usedResources=<memory:48128, vCores:42>usedCapacity=0.9791667, absoluteUsedCapacity=0.9791667, numApps=5, numContainers=42 usedCapacity=0.9791667 absoluteUsedCapacity=0.9791667 used=<memory:48128, vCores:42> cluster=<memory:49152, vCores:96>
2013-08-28 20:35:17,274 INFO org.apache.hadoop.yarn.server.resourcemanager.scheduler.capacity.ParentQueue: completedContainer queue=root usedCapacity=0.9791667 absoluteUsedCapacity=0.9791667 used=<memory:48128, vCores:42> cluster=<memory:49152, vCores:96>
2013-08-28 20:35:17,274 INFO org.apache.hadoop.yarn.server.resourcemanager.scheduler.capacity.CapacityScheduler: Application appattempt_1377721066246_0010_000001 released container container_1377721066246_0010_01_000013 on node: host: hadoop-17-3:35481 #containers=6 available=1024 used=7168 with event: FINISHED
2013-08-28 20:35:17,275 INFO org.apache.hadoop.yarn.server.resourcemanager.rmcontainer.RMContainerImpl: container_1377721066246_0006_01_000004 Container Transitioned from NEW to ALLOCATED
2013-08-28 20:35:17,275 INFO org.apache.hadoop.yarn.server.resourcemanager.RMAuditLogger: USER=ubuntu	OPERATION=AM Allocated Container	TARGET=SchedulerApp	RESULT=SUCCESS	APPID=application_1377721066246_0006	CONTAINERID=container_1377721066246_0006_01_000004
2013-08-28 20:35:17,275 INFO org.apache.hadoop.yarn.server.resourcemanager.scheduler.common.fica.FiCaSchedulerNode: Assigned container container_1377721066246_0006_01_000004 of capacity <memory:1024, vCores:1> on host hadoop-17-3:35481, which currently has 7 containers, <memory:8192, vCores:7> used and <memory:0, vCores:9> available
2013-08-28 20:35:17,276 INFO org.apache.hadoop.yarn.server.resourcemanager.scheduler.capacity.LeafQueue: assignedContainer application=application_1377721066246_0006 container=Container: [ContainerId: container_1377721066246_0006_01_000004, NodeId: hadoop-17-3:35481, NodeHttpAddress: hadoop-17-3:8042, Resource: <memory:1024, vCores:1>, Priority: 20, State: NEW, Token: null, Status: container_id {, app_attempt_id {, application_id {, id: 6, cluster_timestamp: 1377721066246, }, attemptId: 1, }, id: 4, }, state: C_NEW, ] containerId=container_1377721066246_0006_01_000004 queue=default: capacity=1.0, absoluteCapacity=1.0, usedResources=<memory:48128, vCores:42>usedCapacity=0.9791667, absoluteUsedCapacity=0.9791667, numApps=5, numContainers=42 usedCapacity=0.9791667 absoluteUsedCapacity=0.9791667 used=<memory:48128, vCores:42> cluster=<memory:49152, vCores:96>
2013-08-28 20:35:17,276 INFO org.apache.hadoop.yarn.server.resourcemanager.scheduler.capacity.ParentQueue: Re-sorting queues since queue: root.default stats: default: capacity=1.0, absoluteCapacity=1.0, usedResources=<memory:49152, vCores:43>usedCapacity=1.0, absoluteUsedCapacity=1.0, numApps=5, numContainers=43
2013-08-28 20:35:17,276 INFO org.apache.hadoop.yarn.server.resourcemanager.scheduler.capacity.ParentQueue: assignedContainer queue=root usedCapacity=1.0 absoluteUsedCapacity=1.0 used=<memory:49152, vCores:43> cluster=<memory:49152, vCores:96>
2013-08-28 20:35:17,832 INFO org.apache.hadoop.yarn.server.resourcemanager.rmcontainer.RMContainerImpl: container_1377721066246_0006_01_000003 Container Transitioned from ALLOCATED to ACQUIRED
2013-08-28 20:35:17,833 INFO org.apache.hadoop.yarn.server.resourcemanager.rmcontainer.RMContainerImpl: container_1377721066246_0006_01_000004 Container Transitioned from ALLOCATED to ACQUIRED
2013-08-28 20:35:18,260 INFO org.apache.hadoop.yarn.server.resourcemanager.rmcontainer.RMContainerImpl: container_1377721066246_0006_01_000003 Container Transitioned from ACQUIRED to RUNNING
2013-08-28 20:35:18,290 INFO org.apache.hadoop.yarn.server.resourcemanager.rmcontainer.RMContainerImpl: container_1377721066246_0006_01_000002 Container Transitioned from ACQUIRED to RUNNING
2013-08-28 20:35:18,290 INFO org.apache.hadoop.yarn.server.resourcemanager.rmcontainer.RMContainerImpl: container_1377721066246_0006_01_000004 Container Transitioned from ACQUIRED to RUNNING
2013-08-28 20:35:22,791 INFO org.apache.hadoop.yarn.server.resourcemanager.rmcontainer.RMContainerImpl: container_1377721066246_0010_01_000017 Container Transitioned from RUNNING to COMPLETED
2013-08-28 20:35:22,792 INFO org.apache.hadoop.yarn.server.resourcemanager.scheduler.common.fica.FiCaSchedulerApp: Completed container: container_1377721066246_0010_01_000017 in state: COMPLETED event:FINISHED
2013-08-28 20:35:22,792 INFO org.apache.hadoop.yarn.server.resourcemanager.RMAuditLogger: USER=ubuntu	OPERATION=AM Released Container	TARGET=SchedulerApp	RESULT=SUCCESS	APPID=application_1377721066246_0010	CONTAINERID=container_1377721066246_0010_01_000017
2013-08-28 20:35:22,792 INFO org.apache.hadoop.yarn.server.resourcemanager.scheduler.common.fica.FiCaSchedulerNode: Released container container_1377721066246_0010_01_000017 of capacity <memory:1024, vCores:1> on host hadoop-17-5:46576, which currently has 6 containers, <memory:7168, vCores:6> used and <memory:1024, vCores:10> available, release resources=true
2013-08-28 20:35:22,792 INFO org.apache.hadoop.yarn.server.resourcemanager.scheduler.capacity.LeafQueue: default used=<memory:48128, vCores:42> numContainers=42 user=ubuntu user-resources=<memory:48128, vCores:42>
2013-08-28 20:35:22,793 INFO org.apache.hadoop.yarn.server.resourcemanager.scheduler.capacity.LeafQueue: completedContainer container=Container: [ContainerId: container_1377721066246_0010_01_000017, NodeId: hadoop-17-5:46576, NodeHttpAddress: hadoop-17-5:8042, Resource: <memory:1024, vCores:1>, Priority: 20, State: NEW, Token: null, Status: container_id {, app_attempt_id {, application_id {, id: 10, cluster_timestamp: 1377721066246, }, attemptId: 1, }, id: 17, }, state: C_COMPLETE, diagnostics: "Container killed by the ApplicationMaster.\n\n", exit_status: 143, ] resource=<memory:1024, vCores:1> queue=default: capacity=1.0, absoluteCapacity=1.0, usedResources=<memory:48128, vCores:42>usedCapacity=0.9791667, absoluteUsedCapacity=0.9791667, numApps=5, numContainers=42 usedCapacity=0.9791667 absoluteUsedCapacity=0.9791667 used=<memory:48128, vCores:42> cluster=<memory:49152, vCores:96>
2013-08-28 20:35:22,794 INFO org.apache.hadoop.yarn.server.resourcemanager.scheduler.capacity.ParentQueue: completedContainer queue=root usedCapacity=0.9791667 absoluteUsedCapacity=0.9791667 used=<memory:48128, vCores:42> cluster=<memory:49152, vCores:96>
2013-08-28 20:35:22,794 INFO org.apache.hadoop.yarn.server.resourcemanager.scheduler.capacity.CapacityScheduler: Application appattempt_1377721066246_0010_000001 released container container_1377721066246_0010_01_000017 on node: host: hadoop-17-5:46576 #containers=6 available=1024 used=7168 with event: FINISHED
2013-08-28 20:35:22,794 INFO org.apache.hadoop.yarn.server.resourcemanager.rmcontainer.RMContainerImpl: container_1377721066246_0006_01_000005 Container Transitioned from NEW to ALLOCATED
2013-08-28 20:35:22,794 INFO org.apache.hadoop.yarn.server.resourcemanager.RMAuditLogger: USER=ubuntu	OPERATION=AM Allocated Container	TARGET=SchedulerApp	RESULT=SUCCESS	APPID=application_1377721066246_0006	CONTAINERID=container_1377721066246_0006_01_000005
2013-08-28 20:35:22,794 INFO org.apache.hadoop.yarn.server.resourcemanager.scheduler.common.fica.FiCaSchedulerNode: Assigned container container_1377721066246_0006_01_000005 of capacity <memory:1024, vCores:1> on host hadoop-17-5:46576, which currently has 7 containers, <memory:8192, vCores:7> used and <memory:0, vCores:9> available
2013-08-28 20:35:22,795 INFO org.apache.hadoop.yarn.server.resourcemanager.scheduler.capacity.LeafQueue: assignedContainer application=application_1377721066246_0006 container=Container: [ContainerId: container_1377721066246_0006_01_000005, NodeId: hadoop-17-5:46576, NodeHttpAddress: hadoop-17-5:8042, Resource: <memory:1024, vCores:1>, Priority: 20, State: NEW, Token: null, Status: container_id {, app_attempt_id {, application_id {, id: 6, cluster_timestamp: 1377721066246, }, attemptId: 1, }, id: 5, }, state: C_NEW, ] containerId=container_1377721066246_0006_01_000005 queue=default: capacity=1.0, absoluteCapacity=1.0, usedResources=<memory:48128, vCores:42>usedCapacity=0.9791667, absoluteUsedCapacity=0.9791667, numApps=5, numContainers=42 usedCapacity=0.9791667 absoluteUsedCapacity=0.9791667 used=<memory:48128, vCores:42> cluster=<memory:49152, vCores:96>
2013-08-28 20:35:22,796 INFO org.apache.hadoop.yarn.server.resourcemanager.scheduler.capacity.ParentQueue: Re-sorting queues since queue: root.default stats: default: capacity=1.0, absoluteCapacity=1.0, usedResources=<memory:49152, vCores:43>usedCapacity=1.0, absoluteUsedCapacity=1.0, numApps=5, numContainers=43
2013-08-28 20:35:22,796 INFO org.apache.hadoop.yarn.server.resourcemanager.scheduler.capacity.ParentQueue: assignedContainer queue=root usedCapacity=1.0 absoluteUsedCapacity=1.0 used=<memory:49152, vCores:43> cluster=<memory:49152, vCores:96>
2013-08-28 20:35:22,860 INFO org.apache.hadoop.yarn.server.resourcemanager.rmcontainer.RMContainerImpl: container_1377721066246_0006_01_000005 Container Transitioned from ALLOCATED to ACQUIRED
2013-08-28 20:35:23,302 INFO org.apache.hadoop.yarn.server.resourcemanager.rmcontainer.RMContainerImpl: container_1377721066246_0010_01_000003 Container Transitioned from RUNNING to COMPLETED
2013-08-28 20:35:23,302 INFO org.apache.hadoop.yarn.server.resourcemanager.scheduler.common.fica.FiCaSchedulerApp: Completed container: container_1377721066246_0010_01_000003 in state: COMPLETED event:FINISHED
2013-08-28 20:35:23,302 INFO org.apache.hadoop.yarn.server.resourcemanager.RMAuditLogger: USER=ubuntu	OPERATION=AM Released Container	TARGET=SchedulerApp	RESULT=SUCCESS	APPID=application_1377721066246_0010	CONTAINERID=container_1377721066246_0010_01_000003
2013-08-28 20:35:23,302 INFO org.apache.hadoop.yarn.server.resourcemanager.scheduler.common.fica.FiCaSchedulerNode: Released container container_1377721066246_0010_01_000003 of capacity <memory:1024, vCores:1> on host hadoop-17-7:49112, which currently has 6 containers, <memory:7168, vCores:6> used and <memory:1024, vCores:10> available, release resources=true
2013-08-28 20:35:23,303 INFO org.apache.hadoop.yarn.server.resourcemanager.scheduler.capacity.LeafQueue: default used=<memory:48128, vCores:42> numContainers=42 user=ubuntu user-resources=<memory:48128, vCores:42>
2013-08-28 20:35:23,304 INFO org.apache.hadoop.yarn.server.resourcemanager.scheduler.capacity.LeafQueue: completedContainer container=Container: [ContainerId: container_1377721066246_0010_01_000003, NodeId: hadoop-17-7:49112, NodeHttpAddress: hadoop-17-7:8042, Resource: <memory:1024, vCores:1>, Priority: 20, State: NEW, Token: null, Status: container_id {, app_attempt_id {, application_id {, id: 10, cluster_timestamp: 1377721066246, }, attemptId: 1, }, id: 3, }, state: C_COMPLETE, diagnostics: "Container killed by the ApplicationMaster.\n", exit_status: 0, ] resource=<memory:1024, vCores:1> queue=default: capacity=1.0, absoluteCapacity=1.0, usedResources=<memory:48128, vCores:42>usedCapacity=0.9791667, absoluteUsedCapacity=0.9791667, numApps=5, numContainers=42 usedCapacity=0.9791667 absoluteUsedCapacity=0.9791667 used=<memory:48128, vCores:42> cluster=<memory:49152, vCores:96>
2013-08-28 20:35:23,304 INFO org.apache.hadoop.yarn.server.resourcemanager.scheduler.capacity.ParentQueue: completedContainer queue=root usedCapacity=0.9791667 absoluteUsedCapacity=0.9791667 used=<memory:48128, vCores:42> cluster=<memory:49152, vCores:96>
2013-08-28 20:35:23,304 INFO org.apache.hadoop.yarn.server.resourcemanager.scheduler.capacity.CapacityScheduler: Application appattempt_1377721066246_0010_000001 released container container_1377721066246_0010_01_000003 on node: host: hadoop-17-7:49112 #containers=6 available=1024 used=7168 with event: FINISHED
2013-08-28 20:35:23,305 INFO org.apache.hadoop.yarn.server.resourcemanager.rmcontainer.RMContainerImpl: container_1377721066246_0006_01_000006 Container Transitioned from NEW to ALLOCATED
2013-08-28 20:35:23,305 INFO org.apache.hadoop.yarn.server.resourcemanager.RMAuditLogger: USER=ubuntu	OPERATION=AM Allocated Container	TARGET=SchedulerApp	RESULT=SUCCESS	APPID=application_1377721066246_0006	CONTAINERID=container_1377721066246_0006_01_000006
2013-08-28 20:35:23,305 INFO org.apache.hadoop.yarn.server.resourcemanager.scheduler.common.fica.FiCaSchedulerNode: Assigned container container_1377721066246_0006_01_000006 of capacity <memory:1024, vCores:1> on host hadoop-17-7:49112, which currently has 7 containers, <memory:8192, vCores:7> used and <memory:0, vCores:9> available
2013-08-28 20:35:23,306 INFO org.apache.hadoop.yarn.server.resourcemanager.scheduler.capacity.LeafQueue: assignedContainer application=application_1377721066246_0006 container=Container: [ContainerId: container_1377721066246_0006_01_000006, NodeId: hadoop-17-7:49112, NodeHttpAddress: hadoop-17-7:8042, Resource: <memory:1024, vCores:1>, Priority: 20, State: NEW, Token: null, Status: container_id {, app_attempt_id {, application_id {, id: 6, cluster_timestamp: 1377721066246, }, attemptId: 1, }, id: 6, }, state: C_NEW, ] containerId=container_1377721066246_0006_01_000006 queue=default: capacity=1.0, absoluteCapacity=1.0, usedResources=<memory:48128, vCores:42>usedCapacity=0.9791667, absoluteUsedCapacity=0.9791667, numApps=5, numContainers=42 usedCapacity=0.9791667 absoluteUsedCapacity=0.9791667 used=<memory:48128, vCores:42> cluster=<memory:49152, vCores:96>
2013-08-28 20:35:23,306 INFO org.apache.hadoop.yarn.server.resourcemanager.scheduler.capacity.ParentQueue: Re-sorting queues since queue: root.default stats: default: capacity=1.0, absoluteCapacity=1.0, usedResources=<memory:49152, vCores:43>usedCapacity=1.0, absoluteUsedCapacity=1.0, numApps=5, numContainers=43
2013-08-28 20:35:23,306 INFO org.apache.hadoop.yarn.server.resourcemanager.scheduler.capacity.ParentQueue: assignedContainer queue=root usedCapacity=1.0 absoluteUsedCapacity=1.0 used=<memory:49152, vCores:43> cluster=<memory:49152, vCores:96>
2013-08-28 20:35:23,803 INFO org.apache.hadoop.yarn.server.resourcemanager.rmcontainer.RMContainerImpl: container_1377721066246_0006_01_000005 Container Transitioned from ACQUIRED to RUNNING
2013-08-28 20:35:23,876 INFO org.apache.hadoop.yarn.server.resourcemanager.rmcontainer.RMContainerImpl: container_1377721066246_0006_01_000006 Container Transitioned from ALLOCATED to ACQUIRED
2013-08-28 20:35:24,310 INFO org.apache.hadoop.yarn.server.resourcemanager.rmcontainer.RMContainerImpl: container_1377721066246_0006_01_000006 Container Transitioned from ACQUIRED to RUNNING
2013-08-28 20:35:25,210 INFO org.apache.hadoop.yarn.server.resourcemanager.rmcontainer.RMContainerImpl: container_1377721066246_0010_01_000026 Container Transitioned from RUNNING to COMPLETED
2013-08-28 20:35:25,210 INFO org.apache.hadoop.yarn.server.resourcemanager.scheduler.common.fica.FiCaSchedulerApp: Completed container: container_1377721066246_0010_01_000026 in state: COMPLETED event:FINISHED
2013-08-28 20:35:25,210 INFO org.apache.hadoop.yarn.server.resourcemanager.RMAuditLogger: USER=ubuntu	OPERATION=AM Released Container	TARGET=SchedulerApp	RESULT=SUCCESS	APPID=application_1377721066246_0010	CONTAINERID=container_1377721066246_0010_01_000026
2013-08-28 20:35:25,210 INFO org.apache.hadoop.yarn.server.resourcemanager.scheduler.common.fica.FiCaSchedulerNode: Released container container_1377721066246_0010_01_000026 of capacity <memory:1024, vCores:1> on host hadoop-17-6:32933, which currently has 7 containers, <memory:7168, vCores:7> used and <memory:1024, vCores:9> available, release resources=true
2013-08-28 20:35:25,211 INFO org.apache.hadoop.yarn.server.resourcemanager.scheduler.capacity.LeafQueue: default used=<memory:48128, vCores:42> numContainers=42 user=ubuntu user-resources=<memory:48128, vCores:42>
2013-08-28 20:35:25,212 INFO org.apache.hadoop.yarn.server.resourcemanager.scheduler.capacity.LeafQueue: completedContainer container=Container: [ContainerId: container_1377721066246_0010_01_000026, NodeId: hadoop-17-6:32933, NodeHttpAddress: hadoop-17-6:8042, Resource: <memory:1024, vCores:1>, Priority: 20, State: NEW, Token: null, Status: container_id {, app_attempt_id {, application_id {, id: 10, cluster_timestamp: 1377721066246, }, attemptId: 1, }, id: 26, }, state: C_COMPLETE, diagnostics: "Container killed by the ApplicationMaster.\n\n", exit_status: 143, ] resource=<memory:1024, vCores:1> queue=default: capacity=1.0, absoluteCapacity=1.0, usedResources=<memory:48128, vCores:42>usedCapacity=0.9791667, absoluteUsedCapacity=0.9791667, numApps=5, numContainers=42 usedCapacity=0.9791667 absoluteUsedCapacity=0.9791667 used=<memory:48128, vCores:42> cluster=<memory:49152, vCores:96>
2013-08-28 20:35:25,212 INFO org.apache.hadoop.yarn.server.resourcemanager.scheduler.capacity.ParentQueue: completedContainer queue=root usedCapacity=0.9791667 absoluteUsedCapacity=0.9791667 used=<memory:48128, vCores:42> cluster=<memory:49152, vCores:96>
2013-08-28 20:35:25,212 INFO org.apache.hadoop.yarn.server.resourcemanager.scheduler.capacity.CapacityScheduler: Application appattempt_1377721066246_0010_000001 released container container_1377721066246_0010_01_000026 on node: host: hadoop-17-6:32933 #containers=7 available=1024 used=7168 with event: FINISHED
2013-08-28 20:35:25,212 INFO org.apache.hadoop.yarn.server.resourcemanager.rmcontainer.RMContainerImpl: container_1377721066246_0010_01_000033 Container Transitioned from RUNNING to COMPLETED
2013-08-28 20:35:25,213 INFO org.apache.hadoop.yarn.server.resourcemanager.scheduler.common.fica.FiCaSchedulerApp: Completed container: container_1377721066246_0010_01_000033 in state: COMPLETED event:FINISHED
2013-08-28 20:35:25,213 INFO org.apache.hadoop.yarn.server.resourcemanager.RMAuditLogger: USER=ubuntu	OPERATION=AM Released Container	TARGET=SchedulerApp	RESULT=SUCCESS	APPID=application_1377721066246_0010	CONTAINERID=container_1377721066246_0010_01_000033
2013-08-28 20:35:25,213 INFO org.apache.hadoop.yarn.server.resourcemanager.scheduler.common.fica.FiCaSchedulerNode: Released container container_1377721066246_0010_01_000033 of capacity <memory:1024, vCores:1> on host hadoop-17-6:32933, which currently has 6 containers, <memory:6144, vCores:6> used and <memory:2048, vCores:10> available, release resources=true
2013-08-28 20:35:25,213 INFO org.apache.hadoop.yarn.server.resourcemanager.scheduler.capacity.LeafQueue: default used=<memory:47104, vCores:41> numContainers=41 user=ubuntu user-resources=<memory:47104, vCores:41>
2013-08-28 20:35:25,214 INFO org.apache.hadoop.yarn.server.resourcemanager.scheduler.capacity.LeafQueue: completedContainer container=Container: [ContainerId: container_1377721066246_0010_01_000033, NodeId: hadoop-17-6:32933, NodeHttpAddress: hadoop-17-6:8042, Resource: <memory:1024, vCores:1>, Priority: 20, State: NEW, Token: null, Status: container_id {, app_attempt_id {, application_id {, id: 10, cluster_timestamp: 1377721066246, }, attemptId: 1, }, id: 33, }, state: C_COMPLETE, diagnostics: "Container killed by the ApplicationMaster.\n\n", exit_status: 143, ] resource=<memory:1024, vCores:1> queue=default: capacity=1.0, absoluteCapacity=1.0, usedResources=<memory:47104, vCores:41>usedCapacity=0.9583333, absoluteUsedCapacity=0.9583333, numApps=5, numContainers=41 usedCapacity=0.9583333 absoluteUsedCapacity=0.9583333 used=<memory:47104, vCores:41> cluster=<memory:49152, vCores:96>
2013-08-28 20:35:25,214 INFO org.apache.hadoop.yarn.server.resourcemanager.scheduler.capacity.ParentQueue: completedContainer queue=root usedCapacity=0.9583333 absoluteUsedCapacity=0.9583333 used=<memory:47104, vCores:41> cluster=<memory:49152, vCores:96>
2013-08-28 20:35:25,214 INFO org.apache.hadoop.yarn.server.resourcemanager.scheduler.capacity.CapacityScheduler: Application appattempt_1377721066246_0010_000001 released container container_1377721066246_0010_01_000033 on node: host: hadoop-17-6:32933 #containers=6 available=2048 used=6144 with event: FINISHED
2013-08-28 20:35:25,215 INFO org.apache.hadoop.yarn.server.resourcemanager.rmcontainer.RMContainerImpl: container_1377721066246_0006_01_000007 Container Transitioned from NEW to ALLOCATED
2013-08-28 20:35:25,215 INFO org.apache.hadoop.yarn.server.resourcemanager.RMAuditLogger: USER=ubuntu	OPERATION=AM Allocated Container	TARGET=SchedulerApp	RESULT=SUCCESS	APPID=application_1377721066246_0006	CONTAINERID=container_1377721066246_0006_01_000007
2013-08-28 20:35:25,215 INFO org.apache.hadoop.yarn.server.resourcemanager.scheduler.common.fica.FiCaSchedulerNode: Assigned container container_1377721066246_0006_01_000007 of capacity <memory:1024, vCores:1> on host hadoop-17-6:32933, which currently has 7 containers, <memory:7168, vCores:7> used and <memory:1024, vCores:9> available
2013-08-28 20:35:25,216 INFO org.apache.hadoop.yarn.server.resourcemanager.scheduler.capacity.LeafQueue: assignedContainer application=application_1377721066246_0006 container=Container: [ContainerId: container_1377721066246_0006_01_000007, NodeId: hadoop-17-6:32933, NodeHttpAddress: hadoop-17-6:8042, Resource: <memory:1024, vCores:1>, Priority: 20, State: NEW, Token: null, Status: container_id {, app_attempt_id {, application_id {, id: 6, cluster_timestamp: 1377721066246, }, attemptId: 1, }, id: 7, }, state: C_NEW, ] containerId=container_1377721066246_0006_01_000007 queue=default: capacity=1.0, absoluteCapacity=1.0, usedResources=<memory:47104, vCores:41>usedCapacity=0.9583333, absoluteUsedCapacity=0.9583333, numApps=5, numContainers=41 usedCapacity=0.9583333 absoluteUsedCapacity=0.9583333 used=<memory:47104, vCores:41> cluster=<memory:49152, vCores:96>
2013-08-28 20:35:25,216 INFO org.apache.hadoop.yarn.server.resourcemanager.scheduler.capacity.ParentQueue: Re-sorting queues since queue: root.default stats: default: capacity=1.0, absoluteCapacity=1.0, usedResources=<memory:48128, vCores:42>usedCapacity=0.9791667, absoluteUsedCapacity=0.9791667, numApps=5, numContainers=42
2013-08-28 20:35:25,216 INFO org.apache.hadoop.yarn.server.resourcemanager.scheduler.capacity.ParentQueue: assignedContainer queue=root usedCapacity=0.9791667 absoluteUsedCapacity=0.9791667 used=<memory:48128, vCores:42> cluster=<memory:49152, vCores:96>
2013-08-28 20:35:25,216 INFO org.apache.hadoop.yarn.server.resourcemanager.rmcontainer.RMContainerImpl: container_1377721066246_0006_01_000008 Container Transitioned from NEW to ALLOCATED
2013-08-28 20:35:25,217 INFO org.apache.hadoop.yarn.server.resourcemanager.RMAuditLogger: USER=ubuntu	OPERATION=AM Allocated Container	TARGET=SchedulerApp	RESULT=SUCCESS	APPID=application_1377721066246_0006	CONTAINERID=container_1377721066246_0006_01_000008
2013-08-28 20:35:25,217 INFO org.apache.hadoop.yarn.server.resourcemanager.scheduler.common.fica.FiCaSchedulerNode: Assigned container container_1377721066246_0006_01_000008 of capacity <memory:1024, vCores:1> on host hadoop-17-6:32933, which currently has 8 containers, <memory:8192, vCores:8> used and <memory:0, vCores:8> available
2013-08-28 20:35:25,217 INFO org.apache.hadoop.yarn.server.resourcemanager.scheduler.capacity.LeafQueue: assignedContainer application=application_1377721066246_0006 container=Container: [ContainerId: container_1377721066246_0006_01_000008, NodeId: hadoop-17-6:32933, NodeHttpAddress: hadoop-17-6:8042, Resource: <memory:1024, vCores:1>, Priority: 20, State: NEW, Token: null, Status: container_id {, app_attempt_id {, application_id {, id: 6, cluster_timestamp: 1377721066246, }, attemptId: 1, }, id: 8, }, state: C_NEW, ] containerId=container_1377721066246_0006_01_000008 queue=default: capacity=1.0, absoluteCapacity=1.0, usedResources=<memory:48128, vCores:42>usedCapacity=0.9791667, absoluteUsedCapacity=0.9791667, numApps=5, numContainers=42 usedCapacity=0.9791667 absoluteUsedCapacity=0.9791667 used=<memory:48128, vCores:42> cluster=<memory:49152, vCores:96>
2013-08-28 20:35:25,218 INFO org.apache.hadoop.yarn.server.resourcemanager.scheduler.capacity.ParentQueue: Re-sorting queues since queue: root.default stats: default: capacity=1.0, absoluteCapacity=1.0, usedResources=<memory:49152, vCores:43>usedCapacity=1.0, absoluteUsedCapacity=1.0, numApps=5, numContainers=43
2013-08-28 20:35:25,218 INFO org.apache.hadoop.yarn.server.resourcemanager.scheduler.capacity.ParentQueue: assignedContainer queue=root usedCapacity=1.0 absoluteUsedCapacity=1.0 used=<memory:49152, vCores:43> cluster=<memory:49152, vCores:96>
2013-08-28 20:35:25,891 INFO org.apache.hadoop.yarn.server.resourcemanager.rmcontainer.RMContainerImpl: container_1377721066246_0006_01_000007 Container Transitioned from ALLOCATED to ACQUIRED
2013-08-28 20:35:25,893 INFO org.apache.hadoop.yarn.server.resourcemanager.rmcontainer.RMContainerImpl: container_1377721066246_0006_01_000008 Container Transitioned from ALLOCATED to ACQUIRED
2013-08-28 20:35:26,234 INFO org.apache.hadoop.yarn.server.resourcemanager.rmcontainer.RMContainerImpl: container_1377721066246_0006_01_000007 Container Transitioned from ACQUIRED to RUNNING
2013-08-28 20:35:26,235 INFO org.apache.hadoop.yarn.server.resourcemanager.rmcontainer.RMContainerImpl: container_1377721066246_0006_01_000008 Container Transitioned from ACQUIRED to RUNNING
2013-08-28 20:35:26,305 INFO org.apache.hadoop.yarn.server.resourcemanager.rmcontainer.RMContainerImpl: container_1377721066246_0010_01_000024 Container Transitioned from RUNNING to COMPLETED
2013-08-28 20:35:26,305 INFO org.apache.hadoop.yarn.server.resourcemanager.scheduler.common.fica.FiCaSchedulerApp: Completed container: container_1377721066246_0010_01_000024 in state: COMPLETED event:FINISHED
2013-08-28 20:35:26,305 INFO org.apache.hadoop.yarn.server.resourcemanager.RMAuditLogger: USER=ubuntu	OPERATION=AM Released Container	TARGET=SchedulerApp	RESULT=SUCCESS	APPID=application_1377721066246_0010	CONTAINERID=container_1377721066246_0010_01_000024
2013-08-28 20:35:26,305 INFO org.apache.hadoop.yarn.server.resourcemanager.scheduler.common.fica.FiCaSchedulerNode: Released container container_1377721066246_0010_01_000024 of capacity <memory:1024, vCores:1> on host hadoop-17-2:52914, which currently has 6 containers, <memory:7168, vCores:6> used and <memory:1024, vCores:10> available, release resources=true
2013-08-28 20:35:26,305 INFO org.apache.hadoop.yarn.server.resourcemanager.scheduler.capacity.LeafQueue: default used=<memory:48128, vCores:42> numContainers=42 user=ubuntu user-resources=<memory:48128, vCores:42>
2013-08-28 20:35:26,307 INFO org.apache.hadoop.yarn.server.resourcemanager.scheduler.capacity.LeafQueue: completedContainer container=Container: [ContainerId: container_1377721066246_0010_01_000024, NodeId: hadoop-17-2:52914, NodeHttpAddress: hadoop-17-2:8042, Resource: <memory:1024, vCores:1>, Priority: 20, State: NEW, Token: null, Status: container_id {, app_attempt_id {, application_id {, id: 10, cluster_timestamp: 1377721066246, }, attemptId: 1, }, id: 24, }, state: C_COMPLETE, diagnostics: "Container killed by the ApplicationMaster.\n\n", exit_status: 143, ] resource=<memory:1024, vCores:1> queue=default: capacity=1.0, absoluteCapacity=1.0, usedResources=<memory:48128, vCores:42>usedCapacity=0.9791667, absoluteUsedCapacity=0.9791667, numApps=5, numContainers=42 usedCapacity=0.9791667 absoluteUsedCapacity=0.9791667 used=<memory:48128, vCores:42> cluster=<memory:49152, vCores:96>
2013-08-28 20:35:26,307 INFO org.apache.hadoop.yarn.server.resourcemanager.scheduler.capacity.ParentQueue: completedContainer queue=root usedCapacity=0.9791667 absoluteUsedCapacity=0.9791667 used=<memory:48128, vCores:42> cluster=<memory:49152, vCores:96>
2013-08-28 20:35:26,307 INFO org.apache.hadoop.yarn.server.resourcemanager.scheduler.capacity.CapacityScheduler: Application appattempt_1377721066246_0010_000001 released container container_1377721066246_0010_01_000024 on node: host: hadoop-17-2:52914 #containers=6 available=1024 used=7168 with event: FINISHED
2013-08-28 20:35:26,307 INFO org.apache.hadoop.yarn.server.resourcemanager.rmcontainer.RMContainerImpl: container_1377721066246_0006_01_000009 Container Transitioned from NEW to ALLOCATED
2013-08-28 20:35:26,307 INFO org.apache.hadoop.yarn.server.resourcemanager.RMAuditLogger: USER=ubuntu	OPERATION=AM Allocated Container	TARGET=SchedulerApp	RESULT=SUCCESS	APPID=application_1377721066246_0006	CONTAINERID=container_1377721066246_0006_01_000009
2013-08-28 20:35:26,308 INFO org.apache.hadoop.yarn.server.resourcemanager.scheduler.common.fica.FiCaSchedulerNode: Assigned container container_1377721066246_0006_01_000009 of capacity <memory:1024, vCores:1> on host hadoop-17-2:52914, which currently has 7 containers, <memory:8192, vCores:7> used and <memory:0, vCores:9> available
2013-08-28 20:35:26,308 INFO org.apache.hadoop.yarn.server.resourcemanager.scheduler.capacity.LeafQueue: assignedContainer application=application_1377721066246_0006 container=Container: [ContainerId: container_1377721066246_0006_01_000009, NodeId: hadoop-17-2:52914, NodeHttpAddress: hadoop-17-2:8042, Resource: <memory:1024, vCores:1>, Priority: 20, State: NEW, Token: null, Status: container_id {, app_attempt_id {, application_id {, id: 6, cluster_timestamp: 1377721066246, }, attemptId: 1, }, id: 9, }, state: C_NEW, ] containerId=container_1377721066246_0006_01_000009 queue=default: capacity=1.0, absoluteCapacity=1.0, usedResources=<memory:48128, vCores:42>usedCapacity=0.9791667, absoluteUsedCapacity=0.9791667, numApps=5, numContainers=42 usedCapacity=0.9791667 absoluteUsedCapacity=0.9791667 used=<memory:48128, vCores:42> cluster=<memory:49152, vCores:96>
2013-08-28 20:35:26,309 INFO org.apache.hadoop.yarn.server.resourcemanager.scheduler.capacity.ParentQueue: Re-sorting queues since queue: root.default stats: default: capacity=1.0, absoluteCapacity=1.0, usedResources=<memory:49152, vCores:43>usedCapacity=1.0, absoluteUsedCapacity=1.0, numApps=5, numContainers=43
2013-08-28 20:35:26,309 INFO org.apache.hadoop.yarn.server.resourcemanager.scheduler.capacity.ParentQueue: assignedContainer queue=root usedCapacity=1.0 absoluteUsedCapacity=1.0 used=<memory:49152, vCores:43> cluster=<memory:49152, vCores:96>
2013-08-28 20:35:26,901 INFO org.apache.hadoop.yarn.server.resourcemanager.rmcontainer.RMContainerImpl: container_1377721066246_0006_01_000009 Container Transitioned from ALLOCATED to ACQUIRED
2013-08-28 20:35:27,837 INFO org.apache.hadoop.yarn.server.resourcemanager.rmcontainer.RMContainerImpl: container_1377721066246_0006_01_000009 Container Transitioned from ACQUIRED to RUNNING
2013-08-28 20:35:27,838 INFO org.apache.hadoop.yarn.server.resourcemanager.rmcontainer.RMContainerImpl: container_1377721066246_0010_01_000025 Container Transitioned from RUNNING to COMPLETED
2013-08-28 20:35:27,838 INFO org.apache.hadoop.yarn.server.resourcemanager.scheduler.common.fica.FiCaSchedulerApp: Completed container: container_1377721066246_0010_01_000025 in state: COMPLETED event:FINISHED
2013-08-28 20:35:27,838 INFO org.apache.hadoop.yarn.server.resourcemanager.RMAuditLogger: USER=ubuntu	OPERATION=AM Released Container	TARGET=SchedulerApp	RESULT=SUCCESS	APPID=application_1377721066246_0010	CONTAINERID=container_1377721066246_0010_01_000025
2013-08-28 20:35:27,838 INFO org.apache.hadoop.yarn.server.resourcemanager.scheduler.common.fica.FiCaSchedulerNode: Released container container_1377721066246_0010_01_000025 of capacity <memory:1024, vCores:1> on host hadoop-17-2:52914, which currently has 6 containers, <memory:7168, vCores:6> used and <memory:1024, vCores:10> available, release resources=true
2013-08-28 20:35:27,838 INFO org.apache.hadoop.yarn.server.resourcemanager.scheduler.capacity.LeafQueue: default used=<memory:48128, vCores:42> numContainers=42 user=ubuntu user-resources=<memory:48128, vCores:42>
2013-08-28 20:35:27,839 INFO org.apache.hadoop.yarn.server.resourcemanager.scheduler.capacity.LeafQueue: completedContainer container=Container: [ContainerId: container_1377721066246_0010_01_000025, NodeId: hadoop-17-2:52914, NodeHttpAddress: hadoop-17-2:8042, Resource: <memory:1024, vCores:1>, Priority: 20, State: NEW, Token: null, Status: container_id {, app_attempt_id {, application_id {, id: 10, cluster_timestamp: 1377721066246, }, attemptId: 1, }, id: 25, }, state: C_COMPLETE, diagnostics: "Container killed by the ApplicationMaster.\n\n", exit_status: 143, ] resource=<memory:1024, vCores:1> queue=default: capacity=1.0, absoluteCapacity=1.0, usedResources=<memory:48128, vCores:42>usedCapacity=0.9791667, absoluteUsedCapacity=0.9791667, numApps=5, numContainers=42 usedCapacity=0.9791667 absoluteUsedCapacity=0.9791667 used=<memory:48128, vCores:42> cluster=<memory:49152, vCores:96>
2013-08-28 20:35:27,840 INFO org.apache.hadoop.yarn.server.resourcemanager.scheduler.capacity.ParentQueue: completedContainer queue=root usedCapacity=0.9791667 absoluteUsedCapacity=0.9791667 used=<memory:48128, vCores:42> cluster=<memory:49152, vCores:96>
2013-08-28 20:35:27,840 INFO org.apache.hadoop.yarn.server.resourcemanager.scheduler.capacity.CapacityScheduler: Application appattempt_1377721066246_0010_000001 released container container_1377721066246_0010_01_000025 on node: host: hadoop-17-2:52914 #containers=6 available=1024 used=7168 with event: FINISHED
2013-08-28 20:35:27,840 INFO org.apache.hadoop.yarn.server.resourcemanager.rmcontainer.RMContainerImpl: container_1377721066246_0006_01_000010 Container Transitioned from NEW to ALLOCATED
2013-08-28 20:35:27,840 INFO org.apache.hadoop.yarn.server.resourcemanager.RMAuditLogger: USER=ubuntu	OPERATION=AM Allocated Container	TARGET=SchedulerApp	RESULT=SUCCESS	APPID=application_1377721066246_0006	CONTAINERID=container_1377721066246_0006_01_000010
2013-08-28 20:35:27,840 INFO org.apache.hadoop.yarn.server.resourcemanager.scheduler.common.fica.FiCaSchedulerNode: Assigned container container_1377721066246_0006_01_000010 of capacity <memory:1024, vCores:1> on host hadoop-17-2:52914, which currently has 7 containers, <memory:8192, vCores:7> used and <memory:0, vCores:9> available
2013-08-28 20:35:27,841 INFO org.apache.hadoop.yarn.server.resourcemanager.scheduler.capacity.LeafQueue: assignedContainer application=application_1377721066246_0006 container=Container: [ContainerId: container_1377721066246_0006_01_000010, NodeId: hadoop-17-2:52914, NodeHttpAddress: hadoop-17-2:8042, Resource: <memory:1024, vCores:1>, Priority: 20, State: NEW, Token: null, Status: container_id {, app_attempt_id {, application_id {, id: 6, cluster_timestamp: 1377721066246, }, attemptId: 1, }, id: 10, }, state: C_NEW, ] containerId=container_1377721066246_0006_01_000010 queue=default: capacity=1.0, absoluteCapacity=1.0, usedResources=<memory:48128, vCores:42>usedCapacity=0.9791667, absoluteUsedCapacity=0.9791667, numApps=5, numContainers=42 usedCapacity=0.9791667 absoluteUsedCapacity=0.9791667 used=<memory:48128, vCores:42> cluster=<memory:49152, vCores:96>
2013-08-28 20:35:27,842 INFO org.apache.hadoop.yarn.server.resourcemanager.scheduler.capacity.ParentQueue: Re-sorting queues since queue: root.default stats: default: capacity=1.0, absoluteCapacity=1.0, usedResources=<memory:49152, vCores:43>usedCapacity=1.0, absoluteUsedCapacity=1.0, numApps=5, numContainers=43
2013-08-28 20:35:27,842 INFO org.apache.hadoop.yarn.server.resourcemanager.scheduler.capacity.ParentQueue: assignedContainer queue=root usedCapacity=1.0 absoluteUsedCapacity=1.0 used=<memory:49152, vCores:43> cluster=<memory:49152, vCores:96>
2013-08-28 20:35:27,913 INFO org.apache.hadoop.yarn.server.resourcemanager.rmcontainer.RMContainerImpl: container_1377721066246_0006_01_000010 Container Transitioned from ALLOCATED to ACQUIRED
2013-08-28 20:35:28,035 INFO org.apache.hadoop.yarn.server.resourcemanager.rmcontainer.RMContainerImpl: container_1377721066246_0006_01_000010 Container Transitioned from ACQUIRED to RUNNING
2013-08-28 20:35:29,047 INFO org.apache.hadoop.yarn.server.resourcemanager.rmcontainer.RMContainerImpl: container_1377721066246_0010_01_000022 Container Transitioned from RUNNING to COMPLETED
2013-08-28 20:35:29,047 INFO org.apache.hadoop.yarn.server.resourcemanager.scheduler.common.fica.FiCaSchedulerApp: Completed container: container_1377721066246_0010_01_000022 in state: COMPLETED event:FINISHED
2013-08-28 20:35:29,047 INFO org.apache.hadoop.yarn.server.resourcemanager.RMAuditLogger: USER=ubuntu	OPERATION=AM Released Container	TARGET=SchedulerApp	RESULT=SUCCESS	APPID=application_1377721066246_0010	CONTAINERID=container_1377721066246_0010_01_000022
2013-08-28 20:35:29,047 INFO org.apache.hadoop.yarn.server.resourcemanager.scheduler.common.fica.FiCaSchedulerNode: Released container container_1377721066246_0010_01_000022 of capacity <memory:1024, vCores:1> on host hadoop-17-2:52914, which currently has 6 containers, <memory:7168, vCores:6> used and <memory:1024, vCores:10> available, release resources=true
2013-08-28 20:35:29,048 INFO org.apache.hadoop.yarn.server.resourcemanager.scheduler.capacity.LeafQueue: default used=<memory:48128, vCores:42> numContainers=42 user=ubuntu user-resources=<memory:48128, vCores:42>
2013-08-28 20:35:29,049 INFO org.apache.hadoop.yarn.server.resourcemanager.scheduler.capacity.LeafQueue: completedContainer container=Container: [ContainerId: container_1377721066246_0010_01_000022, NodeId: hadoop-17-2:52914, NodeHttpAddress: hadoop-17-2:8042, Resource: <memory:1024, vCores:1>, Priority: 20, State: NEW, Token: null, Status: container_id {, app_attempt_id {, application_id {, id: 10, cluster_timestamp: 1377721066246, }, attemptId: 1, }, id: 22, }, state: C_COMPLETE, diagnostics: "Container killed by the ApplicationMaster.\n\n", exit_status: 143, ] resource=<memory:1024, vCores:1> queue=default: capacity=1.0, absoluteCapacity=1.0, usedResources=<memory:48128, vCores:42>usedCapacity=0.9791667, absoluteUsedCapacity=0.9791667, numApps=5, numContainers=42 usedCapacity=0.9791667 absoluteUsedCapacity=0.9791667 used=<memory:48128, vCores:42> cluster=<memory:49152, vCores:96>
2013-08-28 20:35:29,049 INFO org.apache.hadoop.yarn.server.resourcemanager.scheduler.capacity.ParentQueue: completedContainer queue=root usedCapacity=0.9791667 absoluteUsedCapacity=0.9791667 used=<memory:48128, vCores:42> cluster=<memory:49152, vCores:96>
2013-08-28 20:35:29,049 INFO org.apache.hadoop.yarn.server.resourcemanager.scheduler.capacity.CapacityScheduler: Application appattempt_1377721066246_0010_000001 released container container_1377721066246_0010_01_000022 on node: host: hadoop-17-2:52914 #containers=6 available=1024 used=7168 with event: FINISHED
2013-08-28 20:35:29,050 INFO org.apache.hadoop.yarn.server.resourcemanager.rmcontainer.RMContainerImpl: container_1377721066246_0006_01_000011 Container Transitioned from NEW to ALLOCATED
2013-08-28 20:35:29,050 INFO org.apache.hadoop.yarn.server.resourcemanager.RMAuditLogger: USER=ubuntu	OPERATION=AM Allocated Container	TARGET=SchedulerApp	RESULT=SUCCESS	APPID=application_1377721066246_0006	CONTAINERID=container_1377721066246_0006_01_000011
2013-08-28 20:35:29,050 INFO org.apache.hadoop.yarn.server.resourcemanager.scheduler.common.fica.FiCaSchedulerNode: Assigned container container_1377721066246_0006_01_000011 of capacity <memory:1024, vCores:1> on host hadoop-17-2:52914, which currently has 7 containers, <memory:8192, vCores:7> used and <memory:0, vCores:9> available
2013-08-28 20:35:29,051 INFO org.apache.hadoop.yarn.server.resourcemanager.scheduler.capacity.LeafQueue: assignedContainer application=application_1377721066246_0006 container=Container: [ContainerId: container_1377721066246_0006_01_000011, NodeId: hadoop-17-2:52914, NodeHttpAddress: hadoop-17-2:8042, Resource: <memory:1024, vCores:1>, Priority: 20, State: NEW, Token: null, Status: container_id {, app_attempt_id {, application_id {, id: 6, cluster_timestamp: 1377721066246, }, attemptId: 1, }, id: 11, }, state: C_NEW, ] containerId=container_1377721066246_0006_01_000011 queue=default: capacity=1.0, absoluteCapacity=1.0, usedResources=<memory:48128, vCores:42>usedCapacity=0.9791667, absoluteUsedCapacity=0.9791667, numApps=5, numContainers=42 usedCapacity=0.9791667 absoluteUsedCapacity=0.9791667 used=<memory:48128, vCores:42> cluster=<memory:49152, vCores:96>
2013-08-28 20:35:29,051 INFO org.apache.hadoop.yarn.server.resourcemanager.scheduler.capacity.ParentQueue: Re-sorting queues since queue: root.default stats: default: capacity=1.0, absoluteCapacity=1.0, usedResources=<memory:49152, vCores:43>usedCapacity=1.0, absoluteUsedCapacity=1.0, numApps=5, numContainers=43
2013-08-28 20:35:29,051 INFO org.apache.hadoop.yarn.server.resourcemanager.scheduler.capacity.ParentQueue: assignedContainer queue=root usedCapacity=1.0 absoluteUsedCapacity=1.0 used=<memory:49152, vCores:43> cluster=<memory:49152, vCores:96>
2013-08-28 20:35:29,927 INFO org.apache.hadoop.yarn.server.resourcemanager.rmcontainer.RMContainerImpl: container_1377721066246_0006_01_000011 Container Transitioned from ALLOCATED to ACQUIRED
2013-08-28 20:35:30,056 INFO org.apache.hadoop.yarn.server.resourcemanager.rmcontainer.RMContainerImpl: container_1377721066246_0006_01_000011 Container Transitioned from ACQUIRED to RUNNING
2013-08-28 20:35:30,840 INFO org.apache.hadoop.yarn.server.resourcemanager.rmcontainer.RMContainerImpl: container_1377721066246_0010_01_000030 Container Transitioned from RUNNING to COMPLETED
2013-08-28 20:35:30,840 INFO org.apache.hadoop.yarn.server.resourcemanager.scheduler.common.fica.FiCaSchedulerApp: Completed container: container_1377721066246_0010_01_000030 in state: COMPLETED event:FINISHED
2013-08-28 20:35:30,840 INFO org.apache.hadoop.yarn.server.resourcemanager.RMAuditLogger: USER=ubuntu	OPERATION=AM Released Container	TARGET=SchedulerApp	RESULT=SUCCESS	APPID=application_1377721066246_0010	CONTAINERID=container_1377721066246_0010_01_000030
2013-08-28 20:35:30,840 INFO org.apache.hadoop.yarn.server.resourcemanager.scheduler.common.fica.FiCaSchedulerNode: Released container container_1377721066246_0010_01_000030 of capacity <memory:1024, vCores:1> on host hadoop-17-6:32933, which currently has 7 containers, <memory:7168, vCores:7> used and <memory:1024, vCores:9> available, release resources=true
2013-08-28 20:35:30,840 INFO org.apache.hadoop.yarn.server.resourcemanager.scheduler.capacity.LeafQueue: default used=<memory:48128, vCores:42> numContainers=42 user=ubuntu user-resources=<memory:48128, vCores:42>
2013-08-28 20:35:30,842 INFO org.apache.hadoop.yarn.server.resourcemanager.scheduler.capacity.LeafQueue: completedContainer container=Container: [ContainerId: container_1377721066246_0010_01_000030, NodeId: hadoop-17-6:32933, NodeHttpAddress: hadoop-17-6:8042, Resource: <memory:1024, vCores:1>, Priority: 20, State: NEW, Token: null, Status: container_id {, app_attempt_id {, application_id {, id: 10, cluster_timestamp: 1377721066246, }, attemptId: 1, }, id: 30, }, state: C_COMPLETE, diagnostics: "Container killed by the ApplicationMaster.\n\n", exit_status: 143, ] resource=<memory:1024, vCores:1> queue=default: capacity=1.0, absoluteCapacity=1.0, usedResources=<memory:48128, vCores:42>usedCapacity=0.9791667, absoluteUsedCapacity=0.9791667, numApps=5, numContainers=42 usedCapacity=0.9791667 absoluteUsedCapacity=0.9791667 used=<memory:48128, vCores:42> cluster=<memory:49152, vCores:96>
2013-08-28 20:35:30,842 INFO org.apache.hadoop.yarn.server.resourcemanager.scheduler.capacity.ParentQueue: completedContainer queue=root usedCapacity=0.9791667 absoluteUsedCapacity=0.9791667 used=<memory:48128, vCores:42> cluster=<memory:49152, vCores:96>
2013-08-28 20:35:30,842 INFO org.apache.hadoop.yarn.server.resourcemanager.scheduler.capacity.CapacityScheduler: Application appattempt_1377721066246_0010_000001 released container container_1377721066246_0010_01_000030 on node: host: hadoop-17-6:32933 #containers=7 available=1024 used=7168 with event: FINISHED
2013-08-28 20:35:30,842 INFO org.apache.hadoop.yarn.server.resourcemanager.rmcontainer.RMContainerImpl: container_1377721066246_0006_01_000012 Container Transitioned from NEW to ALLOCATED
2013-08-28 20:35:30,842 INFO org.apache.hadoop.yarn.server.resourcemanager.RMAuditLogger: USER=ubuntu	OPERATION=AM Allocated Container	TARGET=SchedulerApp	RESULT=SUCCESS	APPID=application_1377721066246_0006	CONTAINERID=container_1377721066246_0006_01_000012
2013-08-28 20:35:30,843 INFO org.apache.hadoop.yarn.server.resourcemanager.scheduler.common.fica.FiCaSchedulerNode: Assigned container container_1377721066246_0006_01_000012 of capacity <memory:1024, vCores:1> on host hadoop-17-6:32933, which currently has 8 containers, <memory:8192, vCores:8> used and <memory:0, vCores:8> available
2013-08-28 20:35:30,843 INFO org.apache.hadoop.yarn.server.resourcemanager.scheduler.capacity.LeafQueue: assignedContainer application=application_1377721066246_0006 container=Container: [ContainerId: container_1377721066246_0006_01_000012, NodeId: hadoop-17-6:32933, NodeHttpAddress: hadoop-17-6:8042, Resource: <memory:1024, vCores:1>, Priority: 20, State: NEW, Token: null, Status: container_id {, app_attempt_id {, application_id {, id: 6, cluster_timestamp: 1377721066246, }, attemptId: 1, }, id: 12, }, state: C_NEW, ] containerId=container_1377721066246_0006_01_000012 queue=default: capacity=1.0, absoluteCapacity=1.0, usedResources=<memory:48128, vCores:42>usedCapacity=0.9791667, absoluteUsedCapacity=0.9791667, numApps=5, numContainers=42 usedCapacity=0.9791667 absoluteUsedCapacity=0.9791667 used=<memory:48128, vCores:42> cluster=<memory:49152, vCores:96>
2013-08-28 20:35:30,844 INFO org.apache.hadoop.yarn.server.resourcemanager.scheduler.capacity.ParentQueue: Re-sorting queues since queue: root.default stats: default: capacity=1.0, absoluteCapacity=1.0, usedResources=<memory:49152, vCores:43>usedCapacity=1.0, absoluteUsedCapacity=1.0, numApps=5, numContainers=43
2013-08-28 20:35:30,844 INFO org.apache.hadoop.yarn.server.resourcemanager.scheduler.capacity.ParentQueue: assignedContainer queue=root usedCapacity=1.0 absoluteUsedCapacity=1.0 used=<memory:49152, vCores:43> cluster=<memory:49152, vCores:96>
2013-08-28 20:35:30,946 INFO org.apache.hadoop.yarn.server.resourcemanager.rmcontainer.RMContainerImpl: container_1377721066246_0006_01_000012 Container Transitioned from ALLOCATED to ACQUIRED
2013-08-28 20:35:31,418 INFO org.apache.hadoop.yarn.server.resourcemanager.rmcontainer.RMContainerImpl: container_1377721066246_0010_01_000014 Container Transitioned from RUNNING to COMPLETED
2013-08-28 20:35:31,418 INFO org.apache.hadoop.yarn.server.resourcemanager.scheduler.common.fica.FiCaSchedulerApp: Completed container: container_1377721066246_0010_01_000014 in state: COMPLETED event:FINISHED
2013-08-28 20:35:31,418 INFO org.apache.hadoop.yarn.server.resourcemanager.RMAuditLogger: USER=ubuntu	OPERATION=AM Released Container	TARGET=SchedulerApp	RESULT=SUCCESS	APPID=application_1377721066246_0010	CONTAINERID=container_1377721066246_0010_01_000014
2013-08-28 20:35:31,419 INFO org.apache.hadoop.yarn.server.resourcemanager.scheduler.common.fica.FiCaSchedulerNode: Released container container_1377721066246_0010_01_000014 of capacity <memory:1024, vCores:1> on host hadoop-17-5:46576, which currently has 6 containers, <memory:7168, vCores:6> used and <memory:1024, vCores:10> available, release resources=true
2013-08-28 20:35:31,419 INFO org.apache.hadoop.yarn.server.resourcemanager.scheduler.capacity.LeafQueue: default used=<memory:48128, vCores:42> numContainers=42 user=ubuntu user-resources=<memory:48128, vCores:42>
2013-08-28 20:35:31,420 INFO org.apache.hadoop.yarn.server.resourcemanager.scheduler.capacity.LeafQueue: completedContainer container=Container: [ContainerId: container_1377721066246_0010_01_000014, NodeId: hadoop-17-5:46576, NodeHttpAddress: hadoop-17-5:8042, Resource: <memory:1024, vCores:1>, Priority: 20, State: NEW, Token: null, Status: container_id {, app_attempt_id {, application_id {, id: 10, cluster_timestamp: 1377721066246, }, attemptId: 1, }, id: 14, }, state: C_COMPLETE, diagnostics: "Container killed by the ApplicationMaster.\n\n", exit_status: 143, ] resource=<memory:1024, vCores:1> queue=default: capacity=1.0, absoluteCapacity=1.0, usedResources=<memory:48128, vCores:42>usedCapacity=0.9791667, absoluteUsedCapacity=0.9791667, numApps=5, numContainers=42 usedCapacity=0.9791667 absoluteUsedCapacity=0.9791667 used=<memory:48128, vCores:42> cluster=<memory:49152, vCores:96>
2013-08-28 20:35:31,420 INFO org.apache.hadoop.yarn.server.resourcemanager.scheduler.capacity.ParentQueue: completedContainer queue=root usedCapacity=0.9791667 absoluteUsedCapacity=0.9791667 used=<memory:48128, vCores:42> cluster=<memory:49152, vCores:96>
2013-08-28 20:35:31,420 INFO org.apache.hadoop.yarn.server.resourcemanager.scheduler.capacity.CapacityScheduler: Application appattempt_1377721066246_0010_000001 released container container_1377721066246_0010_01_000014 on node: host: hadoop-17-5:46576 #containers=6 available=1024 used=7168 with event: FINISHED
2013-08-28 20:35:31,421 INFO org.apache.hadoop.yarn.server.resourcemanager.rmcontainer.RMContainerImpl: container_1377721066246_0006_01_000013 Container Transitioned from NEW to ALLOCATED
2013-08-28 20:35:31,421 INFO org.apache.hadoop.yarn.server.resourcemanager.RMAuditLogger: USER=ubuntu	OPERATION=AM Allocated Container	TARGET=SchedulerApp	RESULT=SUCCESS	APPID=application_1377721066246_0006	CONTAINERID=container_1377721066246_0006_01_000013
2013-08-28 20:35:31,421 INFO org.apache.hadoop.yarn.server.resourcemanager.scheduler.common.fica.FiCaSchedulerNode: Assigned container container_1377721066246_0006_01_000013 of capacity <memory:1024, vCores:1> on host hadoop-17-5:46576, which currently has 7 containers, <memory:8192, vCores:7> used and <memory:0, vCores:9> available
2013-08-28 20:35:31,422 INFO org.apache.hadoop.yarn.server.resourcemanager.scheduler.capacity.LeafQueue: assignedContainer application=application_1377721066246_0006 container=Container: [ContainerId: container_1377721066246_0006_01_000013, NodeId: hadoop-17-5:46576, NodeHttpAddress: hadoop-17-5:8042, Resource: <memory:1024, vCores:1>, Priority: 20, State: NEW, Token: null, Status: container_id {, app_attempt_id {, application_id {, id: 6, cluster_timestamp: 1377721066246, }, attemptId: 1, }, id: 13, }, state: C_NEW, ] containerId=container_1377721066246_0006_01_000013 queue=default: capacity=1.0, absoluteCapacity=1.0, usedResources=<memory:48128, vCores:42>usedCapacity=0.9791667, absoluteUsedCapacity=0.9791667, numApps=5, numContainers=42 usedCapacity=0.9791667 absoluteUsedCapacity=0.9791667 used=<memory:48128, vCores:42> cluster=<memory:49152, vCores:96>
2013-08-28 20:35:31,422 INFO org.apache.hadoop.yarn.server.resourcemanager.scheduler.capacity.ParentQueue: Re-sorting queues since queue: root.default stats: default: capacity=1.0, absoluteCapacity=1.0, usedResources=<memory:49152, vCores:43>usedCapacity=1.0, absoluteUsedCapacity=1.0, numApps=5, numContainers=43
2013-08-28 20:35:31,422 INFO org.apache.hadoop.yarn.server.resourcemanager.scheduler.capacity.ParentQueue: assignedContainer queue=root usedCapacity=1.0 absoluteUsedCapacity=1.0 used=<memory:49152, vCores:43> cluster=<memory:49152, vCores:96>
2013-08-28 20:35:31,729 INFO org.apache.hadoop.yarn.server.resourcemanager.rmcontainer.RMContainerImpl: container_1377721066246_0010_01_000039 Container Transitioned from RUNNING to COMPLETED
2013-08-28 20:35:31,729 INFO org.apache.hadoop.yarn.server.resourcemanager.scheduler.common.fica.FiCaSchedulerApp: Completed container: container_1377721066246_0010_01_000039 in state: COMPLETED event:FINISHED
2013-08-28 20:35:31,730 INFO org.apache.hadoop.yarn.server.resourcemanager.RMAuditLogger: USER=ubuntu	OPERATION=AM Released Container	TARGET=SchedulerApp	RESULT=SUCCESS	APPID=application_1377721066246_0010	CONTAINERID=container_1377721066246_0010_01_000039
2013-08-28 20:35:31,730 INFO org.apache.hadoop.yarn.server.resourcemanager.scheduler.common.fica.FiCaSchedulerNode: Released container container_1377721066246_0010_01_000039 of capacity <memory:1024, vCores:1> on host hadoop-17-4:59779, which currently has 6 containers, <memory:7168, vCores:6> used and <memory:1024, vCores:10> available, release resources=true
2013-08-28 20:35:31,730 INFO org.apache.hadoop.yarn.server.resourcemanager.scheduler.capacity.LeafQueue: default used=<memory:48128, vCores:42> numContainers=42 user=ubuntu user-resources=<memory:48128, vCores:42>
2013-08-28 20:35:31,731 INFO org.apache.hadoop.yarn.server.resourcemanager.scheduler.capacity.LeafQueue: completedContainer container=Container: [ContainerId: container_1377721066246_0010_01_000039, NodeId: hadoop-17-4:59779, NodeHttpAddress: hadoop-17-4:8042, Resource: <memory:1024, vCores:1>, Priority: 20, State: NEW, Token: null, Status: container_id {, app_attempt_id {, application_id {, id: 10, cluster_timestamp: 1377721066246, }, attemptId: 1, }, id: 39, }, state: C_COMPLETE, diagnostics: "", exit_status: 0, ] resource=<memory:1024, vCores:1> queue=default: capacity=1.0, absoluteCapacity=1.0, usedResources=<memory:48128, vCores:42>usedCapacity=0.9791667, absoluteUsedCapacity=0.9791667, numApps=5, numContainers=42 usedCapacity=0.9791667 absoluteUsedCapacity=0.9791667 used=<memory:48128, vCores:42> cluster=<memory:49152, vCores:96>
2013-08-28 20:35:31,731 INFO org.apache.hadoop.yarn.server.resourcemanager.scheduler.capacity.ParentQueue: completedContainer queue=root usedCapacity=0.9791667 absoluteUsedCapacity=0.9791667 used=<memory:48128, vCores:42> cluster=<memory:49152, vCores:96>
2013-08-28 20:35:31,731 INFO org.apache.hadoop.yarn.server.resourcemanager.scheduler.capacity.CapacityScheduler: Application appattempt_1377721066246_0010_000001 released container container_1377721066246_0010_01_000039 on node: host: hadoop-17-4:59779 #containers=6 available=1024 used=7168 with event: FINISHED
2013-08-28 20:35:31,732 INFO org.apache.hadoop.yarn.server.resourcemanager.rmcontainer.RMContainerImpl: container_1377721066246_0006_01_000014 Container Transitioned from NEW to ALLOCATED
2013-08-28 20:35:31,732 INFO org.apache.hadoop.yarn.server.resourcemanager.RMAuditLogger: USER=ubuntu	OPERATION=AM Allocated Container	TARGET=SchedulerApp	RESULT=SUCCESS	APPID=application_1377721066246_0006	CONTAINERID=container_1377721066246_0006_01_000014
2013-08-28 20:35:31,732 INFO org.apache.hadoop.yarn.server.resourcemanager.scheduler.common.fica.FiCaSchedulerNode: Assigned container container_1377721066246_0006_01_000014 of capacity <memory:1024, vCores:1> on host hadoop-17-4:59779, which currently has 7 containers, <memory:8192, vCores:7> used and <memory:0, vCores:9> available
2013-08-28 20:35:31,733 INFO org.apache.hadoop.yarn.server.resourcemanager.scheduler.capacity.LeafQueue: assignedContainer application=application_1377721066246_0006 container=Container: [ContainerId: container_1377721066246_0006_01_000014, NodeId: hadoop-17-4:59779, NodeHttpAddress: hadoop-17-4:8042, Resource: <memory:1024, vCores:1>, Priority: 20, State: NEW, Token: null, Status: container_id {, app_attempt_id {, application_id {, id: 6, cluster_timestamp: 1377721066246, }, attemptId: 1, }, id: 14, }, state: C_NEW, ] containerId=container_1377721066246_0006_01_000014 queue=default: capacity=1.0, absoluteCapacity=1.0, usedResources=<memory:48128, vCores:42>usedCapacity=0.9791667, absoluteUsedCapacity=0.9791667, numApps=5, numContainers=42 usedCapacity=0.9791667 absoluteUsedCapacity=0.9791667 used=<memory:48128, vCores:42> cluster=<memory:49152, vCores:96>
2013-08-28 20:35:31,733 INFO org.apache.hadoop.yarn.server.resourcemanager.scheduler.capacity.ParentQueue: Re-sorting queues since queue: root.default stats: default: capacity=1.0, absoluteCapacity=1.0, usedResources=<memory:49152, vCores:43>usedCapacity=1.0, absoluteUsedCapacity=1.0, numApps=5, numContainers=43
2013-08-28 20:35:31,733 INFO org.apache.hadoop.yarn.server.resourcemanager.scheduler.capacity.ParentQueue: assignedContainer queue=root usedCapacity=1.0 absoluteUsedCapacity=1.0 used=<memory:49152, vCores:43> cluster=<memory:49152, vCores:96>
2013-08-28 20:35:31,847 INFO org.apache.hadoop.yarn.server.resourcemanager.rmcontainer.RMContainerImpl: container_1377721066246_0006_01_000012 Container Transitioned from ACQUIRED to RUNNING
2013-08-28 20:35:31,952 INFO org.apache.hadoop.yarn.server.resourcemanager.rmcontainer.RMContainerImpl: container_1377721066246_0006_01_000013 Container Transitioned from ALLOCATED to ACQUIRED
2013-08-28 20:35:31,957 INFO org.apache.hadoop.yarn.server.resourcemanager.rmcontainer.RMContainerImpl: container_1377721066246_0006_01_000014 Container Transitioned from ALLOCATED to ACQUIRED
2013-08-28 20:35:32,791 INFO org.apache.hadoop.yarn.server.resourcemanager.rmcontainer.RMContainerImpl: container_1377721066246_0006_01_000014 Container Transitioned from ACQUIRED to RUNNING
2013-08-28 20:35:32,792 INFO org.apache.hadoop.yarn.server.resourcemanager.rmcontainer.RMContainerImpl: container_1377721066246_0010_01_000037 Container Transitioned from RUNNING to COMPLETED
2013-08-28 20:35:32,792 INFO org.apache.hadoop.yarn.server.resourcemanager.scheduler.common.fica.FiCaSchedulerApp: Completed container: container_1377721066246_0010_01_000037 in state: COMPLETED event:FINISHED
2013-08-28 20:35:32,792 INFO org.apache.hadoop.yarn.server.resourcemanager.RMAuditLogger: USER=ubuntu	OPERATION=AM Released Container	TARGET=SchedulerApp	RESULT=SUCCESS	APPID=application_1377721066246_0010	CONTAINERID=container_1377721066246_0010_01_000037
2013-08-28 20:35:32,792 INFO org.apache.hadoop.yarn.server.resourcemanager.scheduler.common.fica.FiCaSchedulerNode: Released container container_1377721066246_0010_01_000037 of capacity <memory:1024, vCores:1> on host hadoop-17-4:59779, which currently has 6 containers, <memory:7168, vCores:6> used and <memory:1024, vCores:10> available, release resources=true
2013-08-28 20:35:32,792 INFO org.apache.hadoop.yarn.server.resourcemanager.scheduler.capacity.LeafQueue: default used=<memory:48128, vCores:42> numContainers=42 user=ubuntu user-resources=<memory:48128, vCores:42>
2013-08-28 20:35:32,794 INFO org.apache.hadoop.yarn.server.resourcemanager.scheduler.capacity.LeafQueue: completedContainer container=Container: [ContainerId: container_1377721066246_0010_01_000037, NodeId: hadoop-17-4:59779, NodeHttpAddress: hadoop-17-4:8042, Resource: <memory:1024, vCores:1>, Priority: 20, State: NEW, Token: null, Status: container_id {, app_attempt_id {, application_id {, id: 10, cluster_timestamp: 1377721066246, }, attemptId: 1, }, id: 37, }, state: C_COMPLETE, diagnostics: "Container killed by the ApplicationMaster.\n\n", exit_status: 143, ] resource=<memory:1024, vCores:1> queue=default: capacity=1.0, absoluteCapacity=1.0, usedResources=<memory:48128, vCores:42>usedCapacity=0.9791667, absoluteUsedCapacity=0.9791667, numApps=5, numContainers=42 usedCapacity=0.9791667 absoluteUsedCapacity=0.9791667 used=<memory:48128, vCores:42> cluster=<memory:49152, vCores:96>
2013-08-28 20:35:32,794 INFO org.apache.hadoop.yarn.server.resourcemanager.scheduler.capacity.ParentQueue: completedContainer queue=root usedCapacity=0.9791667 absoluteUsedCapacity=0.9791667 used=<memory:48128, vCores:42> cluster=<memory:49152, vCores:96>
2013-08-28 20:35:32,794 INFO org.apache.hadoop.yarn.server.resourcemanager.scheduler.capacity.CapacityScheduler: Application appattempt_1377721066246_0010_000001 released container container_1377721066246_0010_01_000037 on node: host: hadoop-17-4:59779 #containers=6 available=1024 used=7168 with event: FINISHED
2013-08-28 20:35:32,794 INFO org.apache.hadoop.yarn.server.resourcemanager.rmcontainer.RMContainerImpl: container_1377721066246_0010_01_000038 Container Transitioned from RUNNING to COMPLETED
2013-08-28 20:35:32,794 INFO org.apache.hadoop.yarn.server.resourcemanager.scheduler.common.fica.FiCaSchedulerApp: Completed container: container_1377721066246_0010_01_000038 in state: COMPLETED event:FINISHED
2013-08-28 20:35:32,794 INFO org.apache.hadoop.yarn.server.resourcemanager.RMAuditLogger: USER=ubuntu	OPERATION=AM Released Container	TARGET=SchedulerApp	RESULT=SUCCESS	APPID=application_1377721066246_0010	CONTAINERID=container_1377721066246_0010_01_000038
2013-08-28 20:35:32,794 INFO org.apache.hadoop.yarn.server.resourcemanager.scheduler.common.fica.FiCaSchedulerNode: Released container container_1377721066246_0010_01_000038 of capacity <memory:1024, vCores:1> on host hadoop-17-4:59779, which currently has 5 containers, <memory:6144, vCores:5> used and <memory:2048, vCores:11> available, release resources=true
2013-08-28 20:35:32,795 INFO org.apache.hadoop.yarn.server.resourcemanager.scheduler.capacity.LeafQueue: default used=<memory:47104, vCores:41> numContainers=41 user=ubuntu user-resources=<memory:47104, vCores:41>
2013-08-28 20:35:32,795 INFO org.apache.hadoop.yarn.server.resourcemanager.scheduler.capacity.LeafQueue: completedContainer container=Container: [ContainerId: container_1377721066246_0010_01_000038, NodeId: hadoop-17-4:59779, NodeHttpAddress: hadoop-17-4:8042, Resource: <memory:1024, vCores:1>, Priority: 20, State: NEW, Token: null, Status: container_id {, app_attempt_id {, application_id {, id: 10, cluster_timestamp: 1377721066246, }, attemptId: 1, }, id: 38, }, state: C_COMPLETE, diagnostics: "Container killed by the ApplicationMaster.\n\n", exit_status: 143, ] resource=<memory:1024, vCores:1> queue=default: capacity=1.0, absoluteCapacity=1.0, usedResources=<memory:47104, vCores:41>usedCapacity=0.9583333, absoluteUsedCapacity=0.9583333, numApps=5, numContainers=41 usedCapacity=0.9583333 absoluteUsedCapacity=0.9583333 used=<memory:47104, vCores:41> cluster=<memory:49152, vCores:96>
2013-08-28 20:35:32,796 INFO org.apache.hadoop.yarn.server.resourcemanager.scheduler.capacity.ParentQueue: completedContainer queue=root usedCapacity=0.9583333 absoluteUsedCapacity=0.9583333 used=<memory:47104, vCores:41> cluster=<memory:49152, vCores:96>
2013-08-28 20:35:32,796 INFO org.apache.hadoop.yarn.server.resourcemanager.scheduler.capacity.CapacityScheduler: Application appattempt_1377721066246_0010_000001 released container container_1377721066246_0010_01_000038 on node: host: hadoop-17-4:59779 #containers=5 available=2048 used=6144 with event: FINISHED
2013-08-28 20:35:32,796 INFO org.apache.hadoop.yarn.server.resourcemanager.rmcontainer.RMContainerImpl: container_1377721066246_0006_01_000015 Container Transitioned from NEW to ALLOCATED
2013-08-28 20:35:32,796 INFO org.apache.hadoop.yarn.server.resourcemanager.RMAuditLogger: USER=ubuntu	OPERATION=AM Allocated Container	TARGET=SchedulerApp	RESULT=SUCCESS	APPID=application_1377721066246_0006	CONTAINERID=container_1377721066246_0006_01_000015
2013-08-28 20:35:32,797 INFO org.apache.hadoop.yarn.server.resourcemanager.scheduler.common.fica.FiCaSchedulerNode: Assigned container container_1377721066246_0006_01_000015 of capacity <memory:1024, vCores:1> on host hadoop-17-4:59779, which currently has 6 containers, <memory:7168, vCores:6> used and <memory:1024, vCores:10> available
2013-08-28 20:35:32,797 INFO org.apache.hadoop.yarn.server.resourcemanager.scheduler.capacity.LeafQueue: assignedContainer application=application_1377721066246_0006 container=Container: [ContainerId: container_1377721066246_0006_01_000015, NodeId: hadoop-17-4:59779, NodeHttpAddress: hadoop-17-4:8042, Resource: <memory:1024, vCores:1>, Priority: 20, State: NEW, Token: null, Status: container_id {, app_attempt_id {, application_id {, id: 6, cluster_timestamp: 1377721066246, }, attemptId: 1, }, id: 15, }, state: C_NEW, ] containerId=container_1377721066246_0006_01_000015 queue=default: capacity=1.0, absoluteCapacity=1.0, usedResources=<memory:47104, vCores:41>usedCapacity=0.9583333, absoluteUsedCapacity=0.9583333, numApps=5, numContainers=41 usedCapacity=0.9583333 absoluteUsedCapacity=0.9583333 used=<memory:47104, vCores:41> cluster=<memory:49152, vCores:96>
2013-08-28 20:35:32,798 INFO org.apache.hadoop.yarn.server.resourcemanager.scheduler.capacity.ParentQueue: Re-sorting queues since queue: root.default stats: default: capacity=1.0, absoluteCapacity=1.0, usedResources=<memory:48128, vCores:42>usedCapacity=0.9791667, absoluteUsedCapacity=0.9791667, numApps=5, numContainers=42
2013-08-28 20:35:32,798 INFO org.apache.hadoop.yarn.server.resourcemanager.scheduler.capacity.ParentQueue: assignedContainer queue=root usedCapacity=0.9791667 absoluteUsedCapacity=0.9791667 used=<memory:48128, vCores:42> cluster=<memory:49152, vCores:96>
2013-08-28 20:35:32,798 INFO org.apache.hadoop.yarn.server.resourcemanager.rmcontainer.RMContainerImpl: container_1377721066246_0006_01_000016 Container Transitioned from NEW to ALLOCATED
2013-08-28 20:35:32,798 INFO org.apache.hadoop.yarn.server.resourcemanager.RMAuditLogger: USER=ubuntu	OPERATION=AM Allocated Container	TARGET=SchedulerApp	RESULT=SUCCESS	APPID=application_1377721066246_0006	CONTAINERID=container_1377721066246_0006_01_000016
2013-08-28 20:35:32,798 INFO org.apache.hadoop.yarn.server.resourcemanager.scheduler.common.fica.FiCaSchedulerNode: Assigned container container_1377721066246_0006_01_000016 of capacity <memory:1024, vCores:1> on host hadoop-17-4:59779, which currently has 7 containers, <memory:8192, vCores:7> used and <memory:0, vCores:9> available
2013-08-28 20:35:32,799 INFO org.apache.hadoop.yarn.server.resourcemanager.scheduler.capacity.LeafQueue: assignedContainer application=application_1377721066246_0006 container=Container: [ContainerId: container_1377721066246_0006_01_000016, NodeId: hadoop-17-4:59779, NodeHttpAddress: hadoop-17-4:8042, Resource: <memory:1024, vCores:1>, Priority: 20, State: NEW, Token: null, Status: container_id {, app_attempt_id {, application_id {, id: 6, cluster_timestamp: 1377721066246, }, attemptId: 1, }, id: 16, }, state: C_NEW, ] containerId=container_1377721066246_0006_01_000016 queue=default: capacity=1.0, absoluteCapacity=1.0, usedResources=<memory:48128, vCores:42>usedCapacity=0.9791667, absoluteUsedCapacity=0.9791667, numApps=5, numContainers=42 usedCapacity=0.9791667 absoluteUsedCapacity=0.9791667 used=<memory:48128, vCores:42> cluster=<memory:49152, vCores:96>
2013-08-28 20:35:32,799 INFO org.apache.hadoop.yarn.server.resourcemanager.scheduler.capacity.ParentQueue: Re-sorting queues since queue: root.default stats: default: capacity=1.0, absoluteCapacity=1.0, usedResources=<memory:49152, vCores:43>usedCapacity=1.0, absoluteUsedCapacity=1.0, numApps=5, numContainers=43
2013-08-28 20:35:32,800 INFO org.apache.hadoop.yarn.server.resourcemanager.scheduler.capacity.ParentQueue: assignedContainer queue=root usedCapacity=1.0 absoluteUsedCapacity=1.0 used=<memory:49152, vCores:43> cluster=<memory:49152, vCores:96>
2013-08-28 20:35:33,084 INFO org.apache.hadoop.yarn.server.resourcemanager.rmcontainer.RMContainerImpl: container_1377721066246_0006_01_000013 Container Transitioned from ACQUIRED to RUNNING
2013-08-28 20:35:33,103 INFO org.apache.hadoop.yarn.server.resourcemanager.rmcontainer.RMContainerImpl: container_1377721066246_0006_01_000015 Container Transitioned from ALLOCATED to ACQUIRED
2013-08-28 20:35:33,104 INFO org.apache.hadoop.yarn.server.resourcemanager.rmcontainer.RMContainerImpl: container_1377721066246_0006_01_000016 Container Transitioned from ALLOCATED to ACQUIRED
2013-08-28 20:35:33,803 INFO org.apache.hadoop.yarn.server.resourcemanager.rmcontainer.RMContainerImpl: container_1377721066246_0006_01_000015 Container Transitioned from ACQUIRED to RUNNING
2013-08-28 20:35:33,803 INFO org.apache.hadoop.yarn.server.resourcemanager.rmcontainer.RMContainerImpl: container_1377721066246_0006_01_000016 Container Transitioned from ACQUIRED to RUNNING
2013-08-28 20:35:34,948 INFO org.apache.hadoop.yarn.server.resourcemanager.rmcontainer.RMContainerImpl: container_1377721066246_0006_01_000014 Container Transitioned from RUNNING to COMPLETED
2013-08-28 20:35:34,948 INFO org.apache.hadoop.yarn.server.resourcemanager.scheduler.common.fica.FiCaSchedulerApp: Completed container: container_1377721066246_0006_01_000014 in state: COMPLETED event:FINISHED
2013-08-28 20:35:34,948 INFO org.apache.hadoop.yarn.server.resourcemanager.RMAuditLogger: USER=ubuntu	OPERATION=AM Released Container	TARGET=SchedulerApp	RESULT=SUCCESS	APPID=application_1377721066246_0006	CONTAINERID=container_1377721066246_0006_01_000014
2013-08-28 20:35:34,948 INFO org.apache.hadoop.yarn.server.resourcemanager.scheduler.common.fica.FiCaSchedulerNode: Released container container_1377721066246_0006_01_000014 of capacity <memory:1024, vCores:1> on host hadoop-17-4:59779, which currently has 6 containers, <memory:7168, vCores:6> used and <memory:1024, vCores:10> available, release resources=true
2013-08-28 20:35:34,949 INFO org.apache.hadoop.yarn.server.resourcemanager.scheduler.capacity.LeafQueue: default used=<memory:48128, vCores:42> numContainers=42 user=ubuntu user-resources=<memory:48128, vCores:42>
2013-08-28 20:35:34,950 INFO org.apache.hadoop.yarn.server.resourcemanager.scheduler.capacity.LeafQueue: completedContainer container=Container: [ContainerId: container_1377721066246_0006_01_000014, NodeId: hadoop-17-4:59779, NodeHttpAddress: hadoop-17-4:8042, Resource: <memory:1024, vCores:1>, Priority: 20, State: NEW, Token: null, Status: container_id {, app_attempt_id {, application_id {, id: 6, cluster_timestamp: 1377721066246, }, attemptId: 1, }, id: 14, }, state: C_COMPLETE, diagnostics: "\n", exit_status: 126, ] resource=<memory:1024, vCores:1> queue=default: capacity=1.0, absoluteCapacity=1.0, usedResources=<memory:48128, vCores:42>usedCapacity=0.9791667, absoluteUsedCapacity=0.9791667, numApps=5, numContainers=42 usedCapacity=0.9791667 absoluteUsedCapacity=0.9791667 used=<memory:48128, vCores:42> cluster=<memory:49152, vCores:96>
2013-08-28 20:35:34,950 INFO org.apache.hadoop.yarn.server.resourcemanager.scheduler.capacity.ParentQueue: completedContainer queue=root usedCapacity=0.9791667 absoluteUsedCapacity=0.9791667 used=<memory:48128, vCores:42> cluster=<memory:49152, vCores:96>
2013-08-28 20:35:34,950 INFO org.apache.hadoop.yarn.server.resourcemanager.scheduler.capacity.CapacityScheduler: Application appattempt_1377721066246_0006_000001 released container container_1377721066246_0006_01_000014 on node: host: hadoop-17-4:59779 #containers=6 available=1024 used=7168 with event: FINISHED
2013-08-28 20:35:34,951 INFO org.apache.hadoop.yarn.server.resourcemanager.rmcontainer.RMContainerImpl: container_1377721066246_0006_01_000017 Container Transitioned from NEW to ALLOCATED
2013-08-28 20:35:34,951 INFO org.apache.hadoop.yarn.server.resourcemanager.RMAuditLogger: USER=ubuntu	OPERATION=AM Allocated Container	TARGET=SchedulerApp	RESULT=SUCCESS	APPID=application_1377721066246_0006	CONTAINERID=container_1377721066246_0006_01_000017
2013-08-28 20:35:34,951 INFO org.apache.hadoop.yarn.server.resourcemanager.scheduler.common.fica.FiCaSchedulerNode: Assigned container container_1377721066246_0006_01_000017 of capacity <memory:1024, vCores:1> on host hadoop-17-4:59779, which currently has 7 containers, <memory:8192, vCores:7> used and <memory:0, vCores:9> available
2013-08-28 20:35:34,952 INFO org.apache.hadoop.yarn.server.resourcemanager.scheduler.capacity.LeafQueue: assignedContainer application=application_1377721066246_0006 container=Container: [ContainerId: container_1377721066246_0006_01_000017, NodeId: hadoop-17-4:59779, NodeHttpAddress: hadoop-17-4:8042, Resource: <memory:1024, vCores:1>, Priority: 20, State: NEW, Token: null, Status: container_id {, app_attempt_id {, application_id {, id: 6, cluster_timestamp: 1377721066246, }, attemptId: 1, }, id: 17, }, state: C_NEW, ] containerId=container_1377721066246_0006_01_000017 queue=default: capacity=1.0, absoluteCapacity=1.0, usedResources=<memory:48128, vCores:42>usedCapacity=0.9791667, absoluteUsedCapacity=0.9791667, numApps=5, numContainers=42 usedCapacity=0.9791667 absoluteUsedCapacity=0.9791667 used=<memory:48128, vCores:42> cluster=<memory:49152, vCores:96>
2013-08-28 20:35:34,952 INFO org.apache.hadoop.yarn.server.resourcemanager.scheduler.capacity.ParentQueue: Re-sorting queues since queue: root.default stats: default: capacity=1.0, absoluteCapacity=1.0, usedResources=<memory:49152, vCores:43>usedCapacity=1.0, absoluteUsedCapacity=1.0, numApps=5, numContainers=43
2013-08-28 20:35:34,952 INFO org.apache.hadoop.yarn.server.resourcemanager.scheduler.capacity.ParentQueue: assignedContainer queue=root usedCapacity=1.0 absoluteUsedCapacity=1.0 used=<memory:49152, vCores:43> cluster=<memory:49152, vCores:96>
2013-08-28 20:35:35,121 INFO org.apache.hadoop.yarn.server.resourcemanager.rmcontainer.RMContainerImpl: container_1377721066246_0006_01_000017 Container Transitioned from ALLOCATED to ACQUIRED
2013-08-28 20:35:35,957 INFO org.apache.hadoop.yarn.server.resourcemanager.rmcontainer.RMContainerImpl: container_1377721066246_0006_01_000017 Container Transitioned from ACQUIRED to RUNNING
2013-08-28 20:35:38,187 INFO org.apache.hadoop.yarn.server.resourcemanager.rmcontainer.RMContainerImpl: container_1377721066246_0010_01_000034 Container Transitioned from RUNNING to COMPLETED
2013-08-28 20:35:38,187 INFO org.apache.hadoop.yarn.server.resourcemanager.scheduler.common.fica.FiCaSchedulerApp: Completed container: container_1377721066246_0010_01_000034 in state: COMPLETED event:FINISHED
2013-08-28 20:35:38,187 INFO org.apache.hadoop.yarn.server.resourcemanager.RMAuditLogger: USER=ubuntu	OPERATION=AM Released Container	TARGET=SchedulerApp	RESULT=SUCCESS	APPID=application_1377721066246_0010	CONTAINERID=container_1377721066246_0010_01_000034
2013-08-28 20:35:38,187 INFO org.apache.hadoop.yarn.server.resourcemanager.scheduler.common.fica.FiCaSchedulerNode: Released container container_1377721066246_0010_01_000034 of capacity <memory:1024, vCores:1> on host hadoop-17-4:59779, which currently has 6 containers, <memory:7168, vCores:6> used and <memory:1024, vCores:10> available, release resources=true
2013-08-28 20:35:38,187 INFO org.apache.hadoop.yarn.server.resourcemanager.scheduler.capacity.LeafQueue: default used=<memory:48128, vCores:42> numContainers=42 user=ubuntu user-resources=<memory:48128, vCores:42>
2013-08-28 20:35:38,189 INFO org.apache.hadoop.yarn.server.resourcemanager.scheduler.capacity.LeafQueue: completedContainer container=Container: [ContainerId: container_1377721066246_0010_01_000034, NodeId: hadoop-17-4:59779, NodeHttpAddress: hadoop-17-4:8042, Resource: <memory:1024, vCores:1>, Priority: 20, State: NEW, Token: null, Status: container_id {, app_attempt_id {, application_id {, id: 10, cluster_timestamp: 1377721066246, }, attemptId: 1, }, id: 34, }, state: C_COMPLETE, diagnostics: "Container killed by the ApplicationMaster.\n\n", exit_status: 143, ] resource=<memory:1024, vCores:1> queue=default: capacity=1.0, absoluteCapacity=1.0, usedResources=<memory:48128, vCores:42>usedCapacity=0.9791667, absoluteUsedCapacity=0.9791667, numApps=5, numContainers=42 usedCapacity=0.9791667 absoluteUsedCapacity=0.9791667 used=<memory:48128, vCores:42> cluster=<memory:49152, vCores:96>
2013-08-28 20:35:38,189 INFO org.apache.hadoop.yarn.server.resourcemanager.scheduler.capacity.ParentQueue: completedContainer queue=root usedCapacity=0.9791667 absoluteUsedCapacity=0.9791667 used=<memory:48128, vCores:42> cluster=<memory:49152, vCores:96>
2013-08-28 20:35:38,189 INFO org.apache.hadoop.yarn.server.resourcemanager.scheduler.capacity.CapacityScheduler: Application appattempt_1377721066246_0010_000001 released container container_1377721066246_0010_01_000034 on node: host: hadoop-17-4:59779 #containers=6 available=1024 used=7168 with event: FINISHED
2013-08-28 20:35:38,189 INFO org.apache.hadoop.yarn.server.resourcemanager.rmcontainer.RMContainerImpl: container_1377721066246_0006_01_000018 Container Transitioned from NEW to ALLOCATED
2013-08-28 20:35:38,190 INFO org.apache.hadoop.yarn.server.resourcemanager.RMAuditLogger: USER=ubuntu	OPERATION=AM Allocated Container	TARGET=SchedulerApp	RESULT=SUCCESS	APPID=application_1377721066246_0006	CONTAINERID=container_1377721066246_0006_01_000018
2013-08-28 20:35:38,190 INFO org.apache.hadoop.yarn.server.resourcemanager.scheduler.common.fica.FiCaSchedulerNode: Assigned container container_1377721066246_0006_01_000018 of capacity <memory:1024, vCores:1> on host hadoop-17-4:59779, which currently has 7 containers, <memory:8192, vCores:7> used and <memory:0, vCores:9> available
2013-08-28 20:35:38,190 INFO org.apache.hadoop.yarn.server.resourcemanager.scheduler.capacity.LeafQueue: assignedContainer application=application_1377721066246_0006 container=Container: [ContainerId: container_1377721066246_0006_01_000018, NodeId: hadoop-17-4:59779, NodeHttpAddress: hadoop-17-4:8042, Resource: <memory:1024, vCores:1>, Priority: 5, State: NEW, Token: null, Status: container_id {, app_attempt_id {, application_id {, id: 6, cluster_timestamp: 1377721066246, }, attemptId: 1, }, id: 18, }, state: C_NEW, ] containerId=container_1377721066246_0006_01_000018 queue=default: capacity=1.0, absoluteCapacity=1.0, usedResources=<memory:48128, vCores:42>usedCapacity=0.9791667, absoluteUsedCapacity=0.9791667, numApps=5, numContainers=42 usedCapacity=0.9791667 absoluteUsedCapacity=0.9791667 used=<memory:48128, vCores:42> cluster=<memory:49152, vCores:96>
2013-08-28 20:35:38,191 INFO org.apache.hadoop.yarn.server.resourcemanager.scheduler.capacity.ParentQueue: Re-sorting queues since queue: root.default stats: default: capacity=1.0, absoluteCapacity=1.0, usedResources=<memory:49152, vCores:43>usedCapacity=1.0, absoluteUsedCapacity=1.0, numApps=5, numContainers=43
2013-08-28 20:35:38,191 INFO org.apache.hadoop.yarn.server.resourcemanager.scheduler.capacity.ParentQueue: assignedContainer queue=root usedCapacity=1.0 absoluteUsedCapacity=1.0 used=<memory:49152, vCores:43> cluster=<memory:49152, vCores:96>
2013-08-28 20:35:38,293 INFO org.apache.hadoop.yarn.server.resourcemanager.rmcontainer.RMContainerImpl: container_1377721066246_0006_01_000018 Container Transitioned from ALLOCATED to ACQUIRED
2013-08-28 20:35:38,646 INFO org.apache.hadoop.yarn.server.resourcemanager.rmcontainer.RMContainerImpl: container_1377721066246_0006_01_000002 Container Transitioned from RUNNING to COMPLETED
2013-08-28 20:35:38,646 INFO org.apache.hadoop.yarn.server.resourcemanager.scheduler.common.fica.FiCaSchedulerApp: Completed container: container_1377721066246_0006_01_000002 in state: COMPLETED event:FINISHED
2013-08-28 20:35:38,646 INFO org.apache.hadoop.yarn.server.resourcemanager.RMAuditLogger: USER=ubuntu	OPERATION=AM Released Container	TARGET=SchedulerApp	RESULT=SUCCESS	APPID=application_1377721066246_0006	CONTAINERID=container_1377721066246_0006_01_000002
2013-08-28 20:35:38,646 INFO org.apache.hadoop.yarn.server.resourcemanager.scheduler.common.fica.FiCaSchedulerNode: Released container container_1377721066246_0006_01_000002 of capacity <memory:1024, vCores:1> on host hadoop-17-3:35481, which currently has 6 containers, <memory:7168, vCores:6> used and <memory:1024, vCores:10> available, release resources=true
2013-08-28 20:35:38,646 INFO org.apache.hadoop.yarn.server.resourcemanager.scheduler.capacity.LeafQueue: default used=<memory:48128, vCores:42> numContainers=42 user=ubuntu user-resources=<memory:48128, vCores:42>
2013-08-28 20:35:38,647 INFO org.apache.hadoop.yarn.server.resourcemanager.scheduler.capacity.LeafQueue: completedContainer container=Container: [ContainerId: container_1377721066246_0006_01_000002, NodeId: hadoop-17-3:35481, NodeHttpAddress: hadoop-17-3:8042, Resource: <memory:1024, vCores:1>, Priority: 20, State: NEW, Token: null, Status: container_id {, app_attempt_id {, application_id {, id: 6, cluster_timestamp: 1377721066246, }, attemptId: 1, }, id: 2, }, state: C_COMPLETE, diagnostics: "Container killed by the ApplicationMaster.\n", exit_status: 0, ] resource=<memory:1024, vCores:1> queue=default: capacity=1.0, absoluteCapacity=1.0, usedResources=<memory:48128, vCores:42>usedCapacity=0.9791667, absoluteUsedCapacity=0.9791667, numApps=5, numContainers=42 usedCapacity=0.9791667 absoluteUsedCapacity=0.9791667 used=<memory:48128, vCores:42> cluster=<memory:49152, vCores:96>
2013-08-28 20:35:38,648 INFO org.apache.hadoop.yarn.server.resourcemanager.scheduler.capacity.ParentQueue: completedContainer queue=root usedCapacity=0.9791667 absoluteUsedCapacity=0.9791667 used=<memory:48128, vCores:42> cluster=<memory:49152, vCores:96>
2013-08-28 20:35:38,648 INFO org.apache.hadoop.yarn.server.resourcemanager.scheduler.capacity.CapacityScheduler: Application appattempt_1377721066246_0006_000001 released container container_1377721066246_0006_01_000002 on node: host: hadoop-17-3:35481 #containers=6 available=1024 used=7168 with event: FINISHED
2013-08-28 20:35:38,648 INFO org.apache.hadoop.yarn.server.resourcemanager.rmcontainer.RMContainerImpl: container_1377721066246_0006_01_000019 Container Transitioned from NEW to ALLOCATED
2013-08-28 20:35:38,648 INFO org.apache.hadoop.yarn.server.resourcemanager.RMAuditLogger: USER=ubuntu	OPERATION=AM Allocated Container	TARGET=SchedulerApp	RESULT=SUCCESS	APPID=application_1377721066246_0006	CONTAINERID=container_1377721066246_0006_01_000019
2013-08-28 20:35:38,648 INFO org.apache.hadoop.yarn.server.resourcemanager.scheduler.common.fica.FiCaSchedulerNode: Assigned container container_1377721066246_0006_01_000019 of capacity <memory:1024, vCores:1> on host hadoop-17-3:35481, which currently has 7 containers, <memory:8192, vCores:7> used and <memory:0, vCores:9> available
2013-08-28 20:35:38,649 INFO org.apache.hadoop.yarn.server.resourcemanager.scheduler.capacity.LeafQueue: assignedContainer application=application_1377721066246_0006 container=Container: [ContainerId: container_1377721066246_0006_01_000019, NodeId: hadoop-17-3:35481, NodeHttpAddress: hadoop-17-3:8042, Resource: <memory:1024, vCores:1>, Priority: 20, State: NEW, Token: null, Status: container_id {, app_attempt_id {, application_id {, id: 6, cluster_timestamp: 1377721066246, }, attemptId: 1, }, id: 19, }, state: C_NEW, ] containerId=container_1377721066246_0006_01_000019 queue=default: capacity=1.0, absoluteCapacity=1.0, usedResources=<memory:48128, vCores:42>usedCapacity=0.9791667, absoluteUsedCapacity=0.9791667, numApps=5, numContainers=42 usedCapacity=0.9791667 absoluteUsedCapacity=0.9791667 used=<memory:48128, vCores:42> cluster=<memory:49152, vCores:96>
2013-08-28 20:35:38,649 INFO org.apache.hadoop.yarn.server.resourcemanager.scheduler.capacity.ParentQueue: Re-sorting queues since queue: root.default stats: default: capacity=1.0, absoluteCapacity=1.0, usedResources=<memory:49152, vCores:43>usedCapacity=1.0, absoluteUsedCapacity=1.0, numApps=5, numContainers=43
2013-08-28 20:35:38,650 INFO org.apache.hadoop.yarn.server.resourcemanager.scheduler.capacity.ParentQueue: assignedContainer queue=root usedCapacity=1.0 absoluteUsedCapacity=1.0 used=<memory:49152, vCores:43> cluster=<memory:49152, vCores:96>
2013-08-28 20:35:39,203 INFO org.apache.hadoop.yarn.server.resourcemanager.rmcontainer.RMContainerImpl: container_1377721066246_0006_01_000018 Container Transitioned from ACQUIRED to RUNNING
2013-08-28 20:35:39,344 INFO org.apache.hadoop.yarn.server.resourcemanager.scheduler.AppSchedulingInfo: checking for deactivate... 
2013-08-28 20:35:39,345 INFO org.apache.hadoop.yarn.server.resourcemanager.rmcontainer.RMContainerImpl: container_1377721066246_0006_01_000019 Container Transitioned from ALLOCATED to ACQUIRED
2013-08-28 20:35:39,653 INFO org.apache.hadoop.yarn.server.resourcemanager.rmcontainer.RMContainerImpl: container_1377721066246_0006_01_000019 Container Transitioned from ACQUIRED to RUNNING
2013-08-28 20:35:41,073 INFO org.apache.hadoop.yarn.server.resourcemanager.rmcontainer.RMContainerImpl: container_1377721066246_0010_01_000036 Container Transitioned from RUNNING to COMPLETED
2013-08-28 20:35:41,073 INFO org.apache.hadoop.yarn.server.resourcemanager.scheduler.common.fica.FiCaSchedulerApp: Completed container: container_1377721066246_0010_01_000036 in state: COMPLETED event:FINISHED
2013-08-28 20:35:41,073 INFO org.apache.hadoop.yarn.server.resourcemanager.RMAuditLogger: USER=ubuntu	OPERATION=AM Released Container	TARGET=SchedulerApp	RESULT=SUCCESS	APPID=application_1377721066246_0010	CONTAINERID=container_1377721066246_0010_01_000036
2013-08-28 20:35:41,073 INFO org.apache.hadoop.yarn.server.resourcemanager.scheduler.common.fica.FiCaSchedulerNode: Released container container_1377721066246_0010_01_000036 of capacity <memory:1024, vCores:1> on host hadoop-17-4:59779, which currently has 6 containers, <memory:7168, vCores:6> used and <memory:1024, vCores:10> available, release resources=true
2013-08-28 20:35:41,073 INFO org.apache.hadoop.yarn.server.resourcemanager.scheduler.capacity.LeafQueue: default used=<memory:48128, vCores:42> numContainers=42 user=ubuntu user-resources=<memory:48128, vCores:42>
2013-08-28 20:35:41,075 INFO org.apache.hadoop.yarn.server.resourcemanager.scheduler.capacity.LeafQueue: completedContainer container=Container: [ContainerId: container_1377721066246_0010_01_000036, NodeId: hadoop-17-4:59779, NodeHttpAddress: hadoop-17-4:8042, Resource: <memory:1024, vCores:1>, Priority: 20, State: NEW, Token: null, Status: container_id {, app_attempt_id {, application_id {, id: 10, cluster_timestamp: 1377721066246, }, attemptId: 1, }, id: 36, }, state: C_COMPLETE, diagnostics: "Container killed by the ApplicationMaster.\n\n", exit_status: 143, ] resource=<memory:1024, vCores:1> queue=default: capacity=1.0, absoluteCapacity=1.0, usedResources=<memory:48128, vCores:42>usedCapacity=0.9791667, absoluteUsedCapacity=0.9791667, numApps=5, numContainers=42 usedCapacity=0.9791667 absoluteUsedCapacity=0.9791667 used=<memory:48128, vCores:42> cluster=<memory:49152, vCores:96>
2013-08-28 20:35:41,075 INFO org.apache.hadoop.yarn.server.resourcemanager.scheduler.capacity.ParentQueue: completedContainer queue=root usedCapacity=0.9791667 absoluteUsedCapacity=0.9791667 used=<memory:48128, vCores:42> cluster=<memory:49152, vCores:96>
2013-08-28 20:35:41,075 INFO org.apache.hadoop.yarn.server.resourcemanager.scheduler.capacity.CapacityScheduler: Application appattempt_1377721066246_0010_000001 released container container_1377721066246_0010_01_000036 on node: host: hadoop-17-4:59779 #containers=6 available=1024 used=7168 with event: FINISHED
2013-08-28 20:35:41,075 INFO org.apache.hadoop.yarn.server.resourcemanager.rmcontainer.RMContainerImpl: container_1377721066246_0006_01_000020 Container Transitioned from NEW to ALLOCATED
2013-08-28 20:35:41,075 INFO org.apache.hadoop.yarn.server.resourcemanager.RMAuditLogger: USER=ubuntu	OPERATION=AM Allocated Container	TARGET=SchedulerApp	RESULT=SUCCESS	APPID=application_1377721066246_0006	CONTAINERID=container_1377721066246_0006_01_000020
2013-08-28 20:35:41,076 INFO org.apache.hadoop.yarn.server.resourcemanager.scheduler.common.fica.FiCaSchedulerNode: Assigned container container_1377721066246_0006_01_000020 of capacity <memory:1024, vCores:1> on host hadoop-17-4:59779, which currently has 7 containers, <memory:8192, vCores:7> used and <memory:0, vCores:9> available
2013-08-28 20:35:41,076 INFO org.apache.hadoop.yarn.server.resourcemanager.scheduler.capacity.LeafQueue: assignedContainer application=application_1377721066246_0006 container=Container: [ContainerId: container_1377721066246_0006_01_000020, NodeId: hadoop-17-4:59779, NodeHttpAddress: hadoop-17-4:8042, Resource: <memory:1024, vCores:1>, Priority: 20, State: NEW, Token: null, Status: container_id {, app_attempt_id {, application_id {, id: 6, cluster_timestamp: 1377721066246, }, attemptId: 1, }, id: 20, }, state: C_NEW, ] containerId=container_1377721066246_0006_01_000020 queue=default: capacity=1.0, absoluteCapacity=1.0, usedResources=<memory:48128, vCores:42>usedCapacity=0.9791667, absoluteUsedCapacity=0.9791667, numApps=5, numContainers=42 usedCapacity=0.9791667 absoluteUsedCapacity=0.9791667 used=<memory:48128, vCores:42> cluster=<memory:49152, vCores:96>
2013-08-28 20:35:41,077 INFO org.apache.hadoop.yarn.server.resourcemanager.scheduler.capacity.ParentQueue: Re-sorting queues since queue: root.default stats: default: capacity=1.0, absoluteCapacity=1.0, usedResources=<memory:49152, vCores:43>usedCapacity=1.0, absoluteUsedCapacity=1.0, numApps=5, numContainers=43
2013-08-28 20:35:41,077 INFO org.apache.hadoop.yarn.server.resourcemanager.scheduler.capacity.ParentQueue: assignedContainer queue=root usedCapacity=1.0 absoluteUsedCapacity=1.0 used=<memory:49152, vCores:43> cluster=<memory:49152, vCores:96>
2013-08-28 20:35:41,356 INFO org.apache.hadoop.yarn.server.resourcemanager.rmcontainer.RMContainerImpl: container_1377721066246_0006_01_000020 Container Transitioned from ALLOCATED to ACQUIRED
2013-08-28 20:35:41,575 INFO org.apache.hadoop.yarn.server.resourcemanager.rmcontainer.RMContainerImpl: container_1377721066246_0010_01_000029 Container Transitioned from RUNNING to COMPLETED
2013-08-28 20:35:41,576 INFO org.apache.hadoop.yarn.server.resourcemanager.scheduler.common.fica.FiCaSchedulerApp: Completed container: container_1377721066246_0010_01_000029 in state: COMPLETED event:FINISHED
2013-08-28 20:35:41,576 INFO org.apache.hadoop.yarn.server.resourcemanager.RMAuditLogger: USER=ubuntu	OPERATION=AM Released Container	TARGET=SchedulerApp	RESULT=SUCCESS	APPID=application_1377721066246_0010	CONTAINERID=container_1377721066246_0010_01_000029
2013-08-28 20:35:41,576 INFO org.apache.hadoop.yarn.server.resourcemanager.scheduler.common.fica.FiCaSchedulerNode: Released container container_1377721066246_0010_01_000029 of capacity <memory:1024, vCores:1> on host hadoop-17-6:32933, which currently has 7 containers, <memory:7168, vCores:7> used and <memory:1024, vCores:9> available, release resources=true
2013-08-28 20:35:41,576 INFO org.apache.hadoop.yarn.server.resourcemanager.scheduler.capacity.LeafQueue: default used=<memory:48128, vCores:42> numContainers=42 user=ubuntu user-resources=<memory:48128, vCores:42>
2013-08-28 20:35:41,577 INFO org.apache.hadoop.yarn.server.resourcemanager.scheduler.capacity.LeafQueue: completedContainer container=Container: [ContainerId: container_1377721066246_0010_01_000029, NodeId: hadoop-17-6:32933, NodeHttpAddress: hadoop-17-6:8042, Resource: <memory:1024, vCores:1>, Priority: 20, State: NEW, Token: null, Status: container_id {, app_attempt_id {, application_id {, id: 10, cluster_timestamp: 1377721066246, }, attemptId: 1, }, id: 29, }, state: C_COMPLETE, diagnostics: "Container killed by the ApplicationMaster.\n\n", exit_status: 143, ] resource=<memory:1024, vCores:1> queue=default: capacity=1.0, absoluteCapacity=1.0, usedResources=<memory:48128, vCores:42>usedCapacity=0.9791667, absoluteUsedCapacity=0.9791667, numApps=5, numContainers=42 usedCapacity=0.9791667 absoluteUsedCapacity=0.9791667 used=<memory:48128, vCores:42> cluster=<memory:49152, vCores:96>
2013-08-28 20:35:41,577 INFO org.apache.hadoop.yarn.server.resourcemanager.scheduler.capacity.ParentQueue: completedContainer queue=root usedCapacity=0.9791667 absoluteUsedCapacity=0.9791667 used=<memory:48128, vCores:42> cluster=<memory:49152, vCores:96>
2013-08-28 20:35:41,578 INFO org.apache.hadoop.yarn.server.resourcemanager.scheduler.capacity.CapacityScheduler: Application appattempt_1377721066246_0010_000001 released container container_1377721066246_0010_01_000029 on node: host: hadoop-17-6:32933 #containers=7 available=1024 used=7168 with event: FINISHED
2013-08-28 20:35:41,578 INFO org.apache.hadoop.yarn.server.resourcemanager.rmcontainer.RMContainerImpl: container_1377721066246_0010_01_000032 Container Transitioned from RUNNING to COMPLETED
2013-08-28 20:35:41,578 INFO org.apache.hadoop.yarn.server.resourcemanager.scheduler.common.fica.FiCaSchedulerApp: Completed container: container_1377721066246_0010_01_000032 in state: COMPLETED event:FINISHED
2013-08-28 20:35:41,578 INFO org.apache.hadoop.yarn.server.resourcemanager.RMAuditLogger: USER=ubuntu	OPERATION=AM Released Container	TARGET=SchedulerApp	RESULT=SUCCESS	APPID=application_1377721066246_0010	CONTAINERID=container_1377721066246_0010_01_000032
2013-08-28 20:35:41,578 INFO org.apache.hadoop.yarn.server.resourcemanager.scheduler.common.fica.FiCaSchedulerNode: Released container container_1377721066246_0010_01_000032 of capacity <memory:1024, vCores:1> on host hadoop-17-6:32933, which currently has 6 containers, <memory:6144, vCores:6> used and <memory:2048, vCores:10> available, release resources=true
2013-08-28 20:35:41,578 INFO org.apache.hadoop.yarn.server.resourcemanager.scheduler.capacity.LeafQueue: default used=<memory:47104, vCores:41> numContainers=41 user=ubuntu user-resources=<memory:47104, vCores:41>
2013-08-28 20:35:41,579 INFO org.apache.hadoop.yarn.server.resourcemanager.scheduler.capacity.LeafQueue: completedContainer container=Container: [ContainerId: container_1377721066246_0010_01_000032, NodeId: hadoop-17-6:32933, NodeHttpAddress: hadoop-17-6:8042, Resource: <memory:1024, vCores:1>, Priority: 20, State: NEW, Token: null, Status: container_id {, app_attempt_id {, application_id {, id: 10, cluster_timestamp: 1377721066246, }, attemptId: 1, }, id: 32, }, state: C_COMPLETE, diagnostics: "Container killed by the ApplicationMaster.\n\n", exit_status: 143, ] resource=<memory:1024, vCores:1> queue=default: capacity=1.0, absoluteCapacity=1.0, usedResources=<memory:47104, vCores:41>usedCapacity=0.9583333, absoluteUsedCapacity=0.9583333, numApps=5, numContainers=41 usedCapacity=0.9583333 absoluteUsedCapacity=0.9583333 used=<memory:47104, vCores:41> cluster=<memory:49152, vCores:96>
2013-08-28 20:35:41,579 INFO org.apache.hadoop.yarn.server.resourcemanager.scheduler.capacity.ParentQueue: completedContainer queue=root usedCapacity=0.9583333 absoluteUsedCapacity=0.9583333 used=<memory:47104, vCores:41> cluster=<memory:49152, vCores:96>
2013-08-28 20:35:41,580 INFO org.apache.hadoop.yarn.server.resourcemanager.scheduler.capacity.CapacityScheduler: Application appattempt_1377721066246_0010_000001 released container container_1377721066246_0010_01_000032 on node: host: hadoop-17-6:32933 #containers=6 available=2048 used=6144 with event: FINISHED
2013-08-28 20:35:41,580 INFO org.apache.hadoop.yarn.server.resourcemanager.rmcontainer.RMContainerImpl: container_1377721066246_0006_01_000021 Container Transitioned from NEW to ALLOCATED
2013-08-28 20:35:41,580 INFO org.apache.hadoop.yarn.server.resourcemanager.RMAuditLogger: USER=ubuntu	OPERATION=AM Allocated Container	TARGET=SchedulerApp	RESULT=SUCCESS	APPID=application_1377721066246_0006	CONTAINERID=container_1377721066246_0006_01_000021
2013-08-28 20:35:41,580 INFO org.apache.hadoop.yarn.server.resourcemanager.scheduler.common.fica.FiCaSchedulerNode: Assigned container container_1377721066246_0006_01_000021 of capacity <memory:1024, vCores:1> on host hadoop-17-6:32933, which currently has 7 containers, <memory:7168, vCores:7> used and <memory:1024, vCores:9> available
2013-08-28 20:35:41,581 INFO org.apache.hadoop.yarn.server.resourcemanager.scheduler.capacity.LeafQueue: assignedContainer application=application_1377721066246_0006 container=Container: [ContainerId: container_1377721066246_0006_01_000021, NodeId: hadoop-17-6:32933, NodeHttpAddress: hadoop-17-6:8042, Resource: <memory:1024, vCores:1>, Priority: 20, State: NEW, Token: null, Status: container_id {, app_attempt_id {, application_id {, id: 6, cluster_timestamp: 1377721066246, }, attemptId: 1, }, id: 21, }, state: C_NEW, ] containerId=container_1377721066246_0006_01_000021 queue=default: capacity=1.0, absoluteCapacity=1.0, usedResources=<memory:47104, vCores:41>usedCapacity=0.9583333, absoluteUsedCapacity=0.9583333, numApps=5, numContainers=41 usedCapacity=0.9583333 absoluteUsedCapacity=0.9583333 used=<memory:47104, vCores:41> cluster=<memory:49152, vCores:96>
2013-08-28 20:35:41,581 INFO org.apache.hadoop.yarn.server.resourcemanager.scheduler.capacity.ParentQueue: Re-sorting queues since queue: root.default stats: default: capacity=1.0, absoluteCapacity=1.0, usedResources=<memory:48128, vCores:42>usedCapacity=0.9791667, absoluteUsedCapacity=0.9791667, numApps=5, numContainers=42
2013-08-28 20:35:41,582 INFO org.apache.hadoop.yarn.server.resourcemanager.scheduler.capacity.ParentQueue: assignedContainer queue=root usedCapacity=0.9791667 absoluteUsedCapacity=0.9791667 used=<memory:48128, vCores:42> cluster=<memory:49152, vCores:96>
2013-08-28 20:35:41,582 INFO org.apache.hadoop.yarn.server.resourcemanager.rmcontainer.RMContainerImpl: container_1377721066246_0006_01_000022 Container Transitioned from NEW to ALLOCATED
2013-08-28 20:35:41,582 INFO org.apache.hadoop.yarn.server.resourcemanager.RMAuditLogger: USER=ubuntu	OPERATION=AM Allocated Container	TARGET=SchedulerApp	RESULT=SUCCESS	APPID=application_1377721066246_0006	CONTAINERID=container_1377721066246_0006_01_000022
2013-08-28 20:35:41,582 INFO org.apache.hadoop.yarn.server.resourcemanager.scheduler.common.fica.FiCaSchedulerNode: Assigned container container_1377721066246_0006_01_000022 of capacity <memory:1024, vCores:1> on host hadoop-17-6:32933, which currently has 8 containers, <memory:8192, vCores:8> used and <memory:0, vCores:8> available
2013-08-28 20:35:41,583 INFO org.apache.hadoop.yarn.server.resourcemanager.scheduler.capacity.LeafQueue: assignedContainer application=application_1377721066246_0006 container=Container: [ContainerId: container_1377721066246_0006_01_000022, NodeId: hadoop-17-6:32933, NodeHttpAddress: hadoop-17-6:8042, Resource: <memory:1024, vCores:1>, Priority: 20, State: NEW, Token: null, Status: container_id {, app_attempt_id {, application_id {, id: 6, cluster_timestamp: 1377721066246, }, attemptId: 1, }, id: 22, }, state: C_NEW, ] containerId=container_1377721066246_0006_01_000022 queue=default: capacity=1.0, absoluteCapacity=1.0, usedResources=<memory:48128, vCores:42>usedCapacity=0.9791667, absoluteUsedCapacity=0.9791667, numApps=5, numContainers=42 usedCapacity=0.9791667 absoluteUsedCapacity=0.9791667 used=<memory:48128, vCores:42> cluster=<memory:49152, vCores:96>
2013-08-28 20:35:41,583 INFO org.apache.hadoop.yarn.server.resourcemanager.scheduler.capacity.ParentQueue: Re-sorting queues since queue: root.default stats: default: capacity=1.0, absoluteCapacity=1.0, usedResources=<memory:49152, vCores:43>usedCapacity=1.0, absoluteUsedCapacity=1.0, numApps=5, numContainers=43
