2013-08-05 22:10:21,398 INFO org.apache.hadoop.yarn.server.resourcemanager.ResourceManager: STARTUP_MSG: 
/************************************************************
STARTUP_MSG: Starting ResourceManager
STARTUP_MSG:   host = hadoop-100-1/192.168.100.3
STARTUP_MSG:   args = []
STARTUP_MSG:   version = 3.0.0-SNAPSHOT
STARTUP_MSG:   build = https://github.com/lalithsuresh/hadoop-common -r 0cb423bd4868928bb06cd93f882bb0913172fd17; compiled by 'lsuresh' on 2013-04-08T15:47Z
STARTUP_MSG:   java = 1.7.0_17
************************************************************/
2013-08-05 22:10:21,412 INFO org.apache.hadoop.yarn.server.resourcemanager.ResourceManager: registered UNIX signal handlers for [TERM, HUP, INT]
2013-08-05 22:10:22,094 INFO org.apache.hadoop.yarn.server.resourcemanager.security.ApplicationTokenSecretManager: Rolling master-key for application-tokens
2013-08-05 22:10:22,159 INFO org.apache.hadoop.yarn.server.resourcemanager.security.RMContainerTokenSecretManager: ContainerTokenKeyRollingInterval: 86400000ms and ContainerTokenKeyActivationDelay: 900000ms
2013-08-05 22:10:22,164 INFO org.apache.hadoop.yarn.service.AbstractService: Service:Dispatcher is inited.
2013-08-05 22:10:22,167 INFO org.apache.hadoop.yarn.event.AsyncDispatcher: Registering class org.apache.hadoop.yarn.server.resourcemanager.recovery.RMStateStoreEventType for class org.apache.hadoop.yarn.server.resourcemanager.recovery.RMStateStore$ForwardingEventHandler
2013-08-05 22:10:22,167 INFO org.apache.hadoop.yarn.service.AbstractService: Service:Dispatcher is started.
2013-08-05 22:10:22,177 INFO org.apache.hadoop.yarn.event.AsyncDispatcher: Registering class org.apache.hadoop.yarn.server.resourcemanager.NodesListManagerEventType for class org.apache.hadoop.yarn.server.resourcemanager.NodesListManager
2013-08-05 22:10:22,177 INFO org.apache.hadoop.yarn.server.resourcemanager.ResourceManager: Using Scheduler: org.apache.hadoop.yarn.server.resourcemanager.scheduler.capacity.CapacityScheduler
2013-08-05 22:10:22,484 INFO org.apache.hadoop.yarn.event.AsyncDispatcher: Registering class org.apache.hadoop.yarn.server.resourcemanager.scheduler.event.SchedulerEventType for class org.apache.hadoop.yarn.server.resourcemanager.ResourceManager$SchedulerEventDispatcher
2013-08-05 22:10:22,487 INFO org.apache.hadoop.yarn.event.AsyncDispatcher: Registering class org.apache.hadoop.yarn.server.resourcemanager.rmapp.RMAppEventType for class org.apache.hadoop.yarn.server.resourcemanager.ResourceManager$ApplicationEventDispatcher
2013-08-05 22:10:22,490 INFO org.apache.hadoop.yarn.event.AsyncDispatcher: Registering class org.apache.hadoop.yarn.server.resourcemanager.rmapp.attempt.RMAppAttemptEventType for class org.apache.hadoop.yarn.server.resourcemanager.ResourceManager$ApplicationAttemptEventDispatcher
2013-08-05 22:10:22,493 INFO org.apache.hadoop.yarn.event.AsyncDispatcher: Registering class org.apache.hadoop.yarn.server.resourcemanager.rmnode.RMNodeEventType for class org.apache.hadoop.yarn.server.resourcemanager.ResourceManager$NodeEventDispatcher
2013-08-05 22:10:23,081 WARN org.apache.hadoop.util.NativeCodeLoader: Unable to load native-hadoop library for your platform... using builtin-java classes where applicable
2013-08-05 22:10:23,142 INFO org.apache.hadoop.yarn.server.resourcemanager.scheduler.capacity.ParentQueue: root, capacity=1.0, asboluteCapacity=1.0, maxCapacity=1.0, asboluteMaxCapacity=1.0, state=RUNNING, acls=ADMINISTER_QUEUE:*SUBMIT_APPLICATIONS:*
2013-08-05 22:10:23,142 INFO org.apache.hadoop.yarn.server.resourcemanager.scheduler.capacity.ParentQueue: Initialized parent-queue root name=root, fullname=root
2013-08-05 22:10:23,155 INFO org.apache.hadoop.yarn.server.resourcemanager.scheduler.capacity.LeafQueue: Initializing default
capacity = 1.0 [= (float) configuredCapacity / 100 ]
asboluteCapacity = 1.0 [= parentAbsoluteCapacity * capacity ]
maxCapacity = 1.0 [= configuredMaxCapacity ]
absoluteMaxCapacity = 1.0 [= 1.0 maximumCapacity undefined, (parentAbsoluteMaxCapacity * maximumCapacity) / 100 otherwise ]
userLimit = 100 [= configuredUserLimit ]
userLimitFactor = 1.0 [= configuredUserLimitFactor ]
maxApplications = 10000 [= configuredMaximumSystemApplicationsPerQueue or (int)(configuredMaximumSystemApplications * absoluteCapacity)]
maxApplicationsPerUser = 10000 [= (int)(maxApplications * (userLimit / 100.0f) * userLimitFactor) ]
maxActiveApplications = 1 [= max((int)ceil((clusterResourceMemory / minimumAllocation) * maxAMResourcePerQueuePercent * absoluteMaxCapacity),1) ]
maxActiveAppsUsingAbsCap = 1 [= max((int)ceil((clusterResourceMemory / minimumAllocation) *maxAMResourcePercent * absoluteCapacity),1) ]
maxActiveApplicationsPerUser = 1 [= max((int)(maxActiveApplications * (userLimit / 100.0f) * userLimitFactor),1) ]
usedCapacity = 0.0 [= usedResourcesMemory / (clusterResourceMemory * absoluteCapacity)]
absoluteUsedCapacity = 0.0 [= usedResourcesMemory / clusterResourceMemory]
maxAMResourcePerQueuePercent = 0.1 [= configuredMaximumAMResourcePercent ]
minimumAllocationFactor = 0.875 [= (float)(maximumAllocationMemory - minimumAllocationMemory) / maximumAllocationMemory ]
numContainers = 0 [= currentNumContainers ]
state = RUNNING [= configuredState ]
acls = ADMINISTER_QUEUE:*SUBMIT_APPLICATIONS:* [= configuredAcls ]

2013-08-05 22:10:23,156 INFO org.apache.hadoop.yarn.server.resourcemanager.scheduler.capacity.CapacityScheduler: Initialized queue: default: capacity=1.0, absoluteCapacity=1.0, usedResources=<memory:0, vCores:0>usedCapacity=0.0, absoluteUsedCapacity=0.0, numApps=0, numContainers=0
2013-08-05 22:10:23,156 INFO org.apache.hadoop.yarn.server.resourcemanager.scheduler.capacity.CapacityScheduler: Initialized queue: root: numChildQueue= 1, capacity=1.0, absoluteCapacity=1.0, usedResources=<memory:0, vCores:0>usedCapacity=0.0, numApps=0, numContainers=0
2013-08-05 22:10:23,156 INFO org.apache.hadoop.yarn.server.resourcemanager.scheduler.capacity.CapacityScheduler: Initialized root queue root: numChildQueue= 1, capacity=1.0, absoluteCapacity=1.0, usedResources=<memory:0, vCores:0>usedCapacity=0.0, numApps=0, numContainers=0
2013-08-05 22:10:23,156 INFO org.apache.hadoop.yarn.server.resourcemanager.scheduler.capacity.CapacityScheduler: Initialized CapacityScheduler with calculator=class org.apache.hadoop.yarn.server.resourcemanager.resource.DefaultResourceCalculator, minimumAllocation=<<memory:1024, vCores:1>>, maximumAllocation=<<memory:8192, vCores:32>>
2013-08-05 22:10:23,624 INFO org.apache.hadoop.yarn.event.AsyncDispatcher: Registering class org.apache.hadoop.yarn.server.resourcemanager.RMAppManagerEventType for class org.apache.hadoop.yarn.server.resourcemanager.RMAppManager
2013-08-05 22:10:23,647 INFO org.apache.hadoop.yarn.event.AsyncDispatcher: Registering class org.apache.hadoop.yarn.server.resourcemanager.amlauncher.AMLauncherEventType for class org.apache.hadoop.yarn.server.resourcemanager.amlauncher.ApplicationMasterLauncher
2013-08-05 22:10:23,752 INFO org.apache.hadoop.yarn.server.resourcemanager.RMNMInfo: Registered RMNMInfo MBean
2013-08-05 22:10:23,753 INFO org.apache.hadoop.yarn.service.AbstractService: Service:Dispatcher is inited.
2013-08-05 22:10:23,753 INFO org.apache.hadoop.yarn.service.AbstractService: Service:org.apache.hadoop.yarn.server.resourcemanager.rmcontainer.ContainerAllocationExpirer is inited.
2013-08-05 22:10:23,753 INFO org.apache.hadoop.yarn.service.AbstractService: Service:AMLivelinessMonitor is inited.
2013-08-05 22:10:23,753 INFO org.apache.hadoop.yarn.service.AbstractService: Service:AMLivelinessMonitor is inited.
2013-08-05 22:10:23,753 INFO org.apache.hadoop.yarn.service.AbstractService: Service:org.apache.hadoop.yarn.server.resourcemanager.security.DelegationTokenRenewer is inited.
2013-08-05 22:10:23,755 INFO org.apache.hadoop.util.HostsFileReader: Refreshing hosts (include/exclude) list
2013-08-05 22:10:23,755 INFO org.apache.hadoop.yarn.service.AbstractService: Service:org.apache.hadoop.yarn.server.resourcemanager.NodesListManager is inited.
2013-08-05 22:10:23,755 INFO org.apache.hadoop.yarn.service.AbstractService: Service:org.apache.hadoop.yarn.server.resourcemanager.ResourceManager$SchedulerEventDispatcher is inited.
2013-08-05 22:10:23,755 INFO org.apache.hadoop.yarn.service.AbstractService: Service:NMLivelinessMonitor is inited.
2013-08-05 22:10:23,764 INFO org.apache.hadoop.yarn.service.AbstractService: Service:org.apache.hadoop.yarn.server.resourcemanager.ResourceTrackerService is inited.
2013-08-05 22:10:23,764 INFO org.apache.hadoop.yarn.service.AbstractService: Service:org.apache.hadoop.yarn.server.resourcemanager.ApplicationMasterService is inited.
2013-08-05 22:10:23,765 INFO org.apache.hadoop.yarn.service.AbstractService: Service:org.apache.hadoop.yarn.server.resourcemanager.ClientRMService is inited.
2013-08-05 22:10:23,765 INFO org.apache.hadoop.yarn.service.AbstractService: Service:org.apache.hadoop.yarn.server.resourcemanager.AdminService is inited.
2013-08-05 22:10:23,765 INFO org.apache.hadoop.yarn.service.AbstractService: Service:org.apache.hadoop.yarn.server.resourcemanager.amlauncher.ApplicationMasterLauncher is inited.
2013-08-05 22:10:23,765 INFO org.apache.hadoop.yarn.service.AbstractService: Service:ResourceManager is inited.
2013-08-05 22:10:23,766 INFO org.apache.hadoop.yarn.server.resourcemanager.security.RMContainerTokenSecretManager: Rolling master-key for container-tokens
2013-08-05 22:10:23,766 INFO org.apache.hadoop.yarn.server.resourcemanager.security.ApplicationTokenSecretManager: Rolling master-key for application-tokens
2013-08-05 22:10:23,943 INFO org.mortbay.log: Logging to org.slf4j.impl.Log4jLoggerAdapter(org.mortbay.log) via org.mortbay.log.Slf4jLog
2013-08-05 22:10:24,009 INFO org.apache.hadoop.http.HttpServer: Added global filter 'safety' (class=org.apache.hadoop.http.HttpServer$QuotingInputFilter)
2013-08-05 22:10:24,012 INFO org.apache.hadoop.http.HttpServer: Added filter static_user_filter (class=org.apache.hadoop.http.lib.StaticUserWebFilter$StaticUserFilter) to context cluster
2013-08-05 22:10:24,012 INFO org.apache.hadoop.http.HttpServer: Added filter static_user_filter (class=org.apache.hadoop.http.lib.StaticUserWebFilter$StaticUserFilter) to context static
2013-08-05 22:10:24,012 INFO org.apache.hadoop.http.HttpServer: Added filter static_user_filter (class=org.apache.hadoop.http.lib.StaticUserWebFilter$StaticUserFilter) to context logs
2013-08-05 22:10:24,016 INFO org.apache.hadoop.http.HttpServer: adding path spec: /cluster
2013-08-05 22:10:24,017 INFO org.apache.hadoop.http.HttpServer: adding path spec: /cluster/*
2013-08-05 22:10:24,017 INFO org.apache.hadoop.http.HttpServer: adding path spec: /ws
2013-08-05 22:10:24,017 INFO org.apache.hadoop.http.HttpServer: adding path spec: /ws/*
2013-08-05 22:10:24,019 INFO org.apache.hadoop.http.HttpServer: Added global filter 'guice' (class=com.google.inject.servlet.GuiceFilter)
2013-08-05 22:10:24,025 INFO org.apache.hadoop.http.HttpServer: Jetty bound to port 8088
2013-08-05 22:10:24,025 INFO org.mortbay.log: jetty-6.1.26
2013-08-05 22:10:24,060 INFO org.mortbay.log: Extract jar:file:/home/ubuntu/hadoop-3.0.0-SNAPSHOT/share/hadoop/yarn/hadoop-yarn-common-3.0.0-SNAPSHOT.jar!/webapps/cluster to /tmp/Jetty_0_0_0_0_8088_cluster____u0rgz3/webapp
2013-08-05 22:10:24,556 INFO org.mortbay.log: Started SelectChannelConnector@0.0.0.0:8088
2013-08-05 22:10:24,556 INFO org.apache.hadoop.yarn.webapp.WebApps: Web app /cluster started at 8088
2013-08-05 22:10:25,382 INFO org.apache.hadoop.yarn.webapp.WebApps: Registered webapp guice modules
2013-08-05 22:10:25,501 INFO org.apache.hadoop.metrics2.impl.MetricsConfig: loaded properties from hadoop-metrics2.properties
2013-08-05 22:10:25,539 INFO org.apache.hadoop.metrics2.impl.MetricsSystemImpl: Scheduled snapshot period at 10 second(s).
2013-08-05 22:10:25,539 INFO org.apache.hadoop.metrics2.impl.MetricsSystemImpl: ResourceManager metrics system started
2013-08-05 22:10:25,556 INFO org.apache.hadoop.security.token.delegation.AbstractDelegationTokenSecretManager: Updating the current master key for generating delegation tokens
2013-08-05 22:10:25,559 INFO org.apache.hadoop.yarn.service.AbstractService: Service:Dispatcher is started.
2013-08-05 22:10:25,560 INFO org.apache.hadoop.security.token.delegation.AbstractDelegationTokenSecretManager: Starting expired delegation token remover thread, tokenRemoverScanInterval=60 min(s)
2013-08-05 22:10:25,560 INFO org.apache.hadoop.security.token.delegation.AbstractDelegationTokenSecretManager: Updating the current master key for generating delegation tokens
2013-08-05 22:10:25,562 INFO org.apache.hadoop.yarn.service.AbstractService: Service:org.apache.hadoop.yarn.server.resourcemanager.rmcontainer.ContainerAllocationExpirer is started.
2013-08-05 22:10:25,563 INFO org.apache.hadoop.yarn.service.AbstractService: Service:AMLivelinessMonitor is started.
2013-08-05 22:10:25,563 INFO org.apache.hadoop.yarn.service.AbstractService: Service:AMLivelinessMonitor is started.
2013-08-05 22:10:25,564 INFO org.apache.hadoop.yarn.service.AbstractService: Service:org.apache.hadoop.yarn.server.resourcemanager.security.DelegationTokenRenewer is started.
2013-08-05 22:10:25,565 INFO org.apache.hadoop.yarn.service.AbstractService: Service:org.apache.hadoop.yarn.server.resourcemanager.NodesListManager is started.
2013-08-05 22:10:25,565 INFO org.apache.hadoop.yarn.service.AbstractService: Service:org.apache.hadoop.yarn.server.resourcemanager.ResourceManager$SchedulerEventDispatcher is started.
2013-08-05 22:10:25,566 INFO org.apache.hadoop.yarn.service.AbstractService: Service:NMLivelinessMonitor is started.
2013-08-05 22:10:25,566 INFO org.apache.hadoop.yarn.service.AbstractService: Service:org.apache.hadoop.yarn.server.resourcemanager.ResourceTrackerService is started.
2013-08-05 22:10:25,647 INFO org.apache.hadoop.ipc.Server: Starting Socket Reader #1 for port 54110
2013-08-05 22:10:25,692 INFO org.apache.hadoop.yarn.factories.impl.pb.RpcServerFactoryPBImpl: Adding protocol org.apache.hadoop.yarn.server.api.ResourceTrackerPB to the server
2013-08-05 22:10:25,693 INFO org.apache.hadoop.ipc.Server: IPC Server Responder: starting
2013-08-05 22:10:25,735 INFO org.apache.hadoop.ipc.Server: IPC Server listener on 54110: starting
2013-08-05 22:10:25,836 INFO org.apache.hadoop.ipc.Server: Starting Socket Reader #1 for port 54112
2013-08-05 22:10:25,858 INFO org.apache.hadoop.yarn.factories.impl.pb.RpcServerFactoryPBImpl: Adding protocol org.apache.hadoop.yarn.api.AMRMProtocolPB to the server
2013-08-05 22:10:25,860 INFO org.apache.hadoop.ipc.Server: IPC Server Responder: starting
2013-08-05 22:10:25,860 INFO org.apache.hadoop.ipc.Server: IPC Server listener on 54112: starting
2013-08-05 22:10:25,884 INFO org.apache.hadoop.yarn.service.AbstractService: Service:org.apache.hadoop.yarn.server.resourcemanager.ApplicationMasterService is started.
2013-08-05 22:10:25,937 INFO org.apache.hadoop.ipc.Server: Starting Socket Reader #1 for port 54111
2013-08-05 22:10:25,943 INFO org.apache.hadoop.yarn.factories.impl.pb.RpcServerFactoryPBImpl: Adding protocol org.apache.hadoop.yarn.api.ClientRMProtocolPB to the server
2013-08-05 22:10:25,944 INFO org.apache.hadoop.ipc.Server: IPC Server Responder: starting
2013-08-05 22:10:25,945 INFO org.apache.hadoop.ipc.Server: IPC Server listener on 54111: starting
2013-08-05 22:10:25,983 INFO org.apache.hadoop.yarn.service.AbstractService: Service:org.apache.hadoop.yarn.server.resourcemanager.ClientRMService is started.
2013-08-05 22:10:26,017 INFO org.apache.hadoop.ipc.Server: Starting Socket Reader #1 for port 8033
2013-08-05 22:10:26,024 INFO org.apache.hadoop.yarn.factories.impl.pb.RpcServerFactoryPBImpl: Adding protocol org.apache.hadoop.yarn.api.RMAdminProtocolPB to the server
2013-08-05 22:10:26,025 INFO org.apache.hadoop.ipc.Server: IPC Server Responder: starting
2013-08-05 22:10:26,030 INFO org.apache.hadoop.ipc.Server: IPC Server listener on 8033: starting
2013-08-05 22:10:26,032 INFO org.apache.hadoop.yarn.service.AbstractService: Service:org.apache.hadoop.yarn.server.resourcemanager.AdminService is started.
2013-08-05 22:10:26,034 INFO org.apache.hadoop.yarn.service.AbstractService: Service:org.apache.hadoop.yarn.server.resourcemanager.amlauncher.ApplicationMasterLauncher is started.
2013-08-05 22:10:26,034 INFO org.apache.hadoop.yarn.service.AbstractService: Service:ResourceManager is started.
2013-08-05 22:10:35,752 INFO org.apache.hadoop.yarn.util.RackResolver: Resolved hadoop-100-5 to /default-rack
2013-08-05 22:10:35,756 INFO org.apache.hadoop.yarn.server.resourcemanager.ResourceTrackerService: NodeManager from node hadoop-100-5(cmPort: 58882 httpPort: 8042) registered with capability: <memory:8192, vCores:16>, assigned nodeId hadoop-100-5:58882
2013-08-05 22:10:35,757 INFO org.apache.hadoop.yarn.util.RackResolver: Resolved hadoop-100-6 to /default-rack
2013-08-05 22:10:35,757 INFO org.apache.hadoop.yarn.server.resourcemanager.ResourceTrackerService: NodeManager from node hadoop-100-6(cmPort: 42294 httpPort: 8042) registered with capability: <memory:8192, vCores:16>, assigned nodeId hadoop-100-6:42294
2013-08-05 22:10:35,757 INFO org.apache.hadoop.yarn.util.RackResolver: Resolved hadoop-100-2 to /default-rack
2013-08-05 22:10:35,757 INFO org.apache.hadoop.yarn.server.resourcemanager.ResourceTrackerService: NodeManager from node hadoop-100-2(cmPort: 37374 httpPort: 8042) registered with capability: <memory:8192, vCores:16>, assigned nodeId hadoop-100-2:37374
2013-08-05 22:10:35,778 INFO org.apache.hadoop.yarn.server.resourcemanager.rmnode.RMNodeImpl: hadoop-100-5:58882 Node Transitioned from NEW to RUNNING
2013-08-05 22:10:35,779 INFO org.apache.hadoop.yarn.server.resourcemanager.rmnode.RMNodeImpl: hadoop-100-6:42294 Node Transitioned from NEW to RUNNING
2013-08-05 22:10:35,779 INFO org.apache.hadoop.yarn.server.resourcemanager.rmnode.RMNodeImpl: hadoop-100-2:37374 Node Transitioned from NEW to RUNNING
2013-08-05 22:10:35,781 INFO org.apache.hadoop.yarn.server.resourcemanager.scheduler.capacity.CapacityScheduler: Added node hadoop-100-5:58882 clusterResource: <memory:8192, vCores:16>
2013-08-05 22:10:35,782 INFO org.apache.hadoop.yarn.server.resourcemanager.scheduler.capacity.CapacityScheduler: Added node hadoop-100-6:42294 clusterResource: <memory:16384, vCores:32>
2013-08-05 22:10:35,782 INFO org.apache.hadoop.yarn.server.resourcemanager.scheduler.capacity.CapacityScheduler: Added node hadoop-100-2:37374 clusterResource: <memory:24576, vCores:48>
2013-08-05 22:10:35,804 INFO org.apache.hadoop.yarn.util.RackResolver: Resolved hadoop-100-3 to /default-rack
2013-08-05 22:10:35,805 INFO org.apache.hadoop.yarn.server.resourcemanager.ResourceTrackerService: NodeManager from node hadoop-100-3(cmPort: 44102 httpPort: 8042) registered with capability: <memory:8192, vCores:16>, assigned nodeId hadoop-100-3:44102
2013-08-05 22:10:35,805 INFO org.apache.hadoop.yarn.server.resourcemanager.rmnode.RMNodeImpl: hadoop-100-3:44102 Node Transitioned from NEW to RUNNING
2013-08-05 22:10:35,806 INFO org.apache.hadoop.yarn.server.resourcemanager.scheduler.capacity.CapacityScheduler: Added node hadoop-100-3:44102 clusterResource: <memory:32768, vCores:64>
2013-08-05 22:10:35,982 INFO org.apache.hadoop.yarn.util.RackResolver: Resolved hadoop-100-4 to /default-rack
2013-08-05 22:10:35,982 INFO org.apache.hadoop.yarn.server.resourcemanager.ResourceTrackerService: NodeManager from node hadoop-100-4(cmPort: 50425 httpPort: 8042) registered with capability: <memory:8192, vCores:16>, assigned nodeId hadoop-100-4:50425
2013-08-05 22:10:35,983 INFO org.apache.hadoop.yarn.server.resourcemanager.rmnode.RMNodeImpl: hadoop-100-4:50425 Node Transitioned from NEW to RUNNING
2013-08-05 22:10:35,983 INFO org.apache.hadoop.yarn.server.resourcemanager.scheduler.capacity.CapacityScheduler: Added node hadoop-100-4:50425 clusterResource: <memory:40960, vCores:80>
2013-08-05 22:10:35,991 INFO org.apache.hadoop.yarn.util.RackResolver: Resolved hadoop-100-7 to /default-rack
2013-08-05 22:10:35,991 INFO org.apache.hadoop.yarn.server.resourcemanager.ResourceTrackerService: NodeManager from node hadoop-100-7(cmPort: 36057 httpPort: 8042) registered with capability: <memory:8192, vCores:16>, assigned nodeId hadoop-100-7:36057
2013-08-05 22:10:35,991 INFO org.apache.hadoop.yarn.server.resourcemanager.rmnode.RMNodeImpl: hadoop-100-7:36057 Node Transitioned from NEW to RUNNING
2013-08-05 22:10:35,992 INFO org.apache.hadoop.yarn.server.resourcemanager.scheduler.capacity.CapacityScheduler: Added node hadoop-100-7:36057 clusterResource: <memory:49152, vCores:96>
2013-08-05 22:10:41,807 INFO org.apache.hadoop.yarn.server.resourcemanager.ClientRMService: Allocated new applicationId: 1
2013-08-05 22:10:45,262 INFO org.apache.hadoop.yarn.server.resourcemanager.ClientRMService: Storing Application with id application_1375740621345_0001
2013-08-05 22:10:45,265 INFO org.apache.hadoop.yarn.server.resourcemanager.recovery.RMStateStore: Storing info for app: application_1375740621345_0001
2013-08-05 22:10:45,265 INFO org.apache.hadoop.yarn.server.resourcemanager.ClientRMService: Application with id 1 submitted by user ubuntu
2013-08-05 22:10:45,269 INFO org.apache.hadoop.yarn.server.resourcemanager.RMAuditLogger: USER=ubuntu	IP=192.168.100.3	OPERATION=Submit Application Request	TARGET=ClientRMService	RESULT=SUCCESS	APPID=application_1375740621345_0001
2013-08-05 22:10:45,312 INFO org.apache.hadoop.yarn.server.resourcemanager.rmapp.RMAppImpl: application_1375740621345_0001 State change from NEW to SUBMITTED
2013-08-05 22:10:45,313 INFO org.apache.hadoop.yarn.server.resourcemanager.ApplicationMasterService: Registering appattempt_1375740621345_0001_000001
2013-08-05 22:10:45,314 INFO org.apache.hadoop.yarn.server.resourcemanager.rmapp.attempt.RMAppAttemptImpl: appattempt_1375740621345_0001_000001 State change from NEW to SUBMITTED
2013-08-05 22:10:45,348 INFO org.apache.hadoop.yarn.server.resourcemanager.scheduler.capacity.LeafQueue: Application application_1375740621345_0001 from user: ubuntu activated in queue: default
2013-08-05 22:10:45,348 INFO org.apache.hadoop.yarn.server.resourcemanager.scheduler.capacity.LeafQueue: Application added - appId: application_1375740621345_0001 user: org.apache.hadoop.yarn.server.resourcemanager.scheduler.capacity.LeafQueue$User@60c209ae, leaf-queue: default #user-pending-applications: 0 #user-active-applications: 1 #queue-pending-applications: 0 #queue-active-applications: 1
2013-08-05 22:10:45,348 INFO org.apache.hadoop.yarn.server.resourcemanager.scheduler.capacity.ParentQueue: Application added - appId: application_1375740621345_0001 user: ubuntu leaf-queue of parent: root #applications: 1
2013-08-05 22:10:45,349 INFO org.apache.hadoop.yarn.server.resourcemanager.scheduler.capacity.CapacityScheduler: Application Submission: appattempt_1375740621345_0001_000001, user: ubuntu queue: default: capacity=1.0, absoluteCapacity=1.0, usedResources=<memory:0, vCores:0>usedCapacity=0.0, absoluteUsedCapacity=0.0, numApps=1, numContainers=0, currently active: 1
2013-08-05 22:10:45,354 INFO org.apache.hadoop.yarn.server.resourcemanager.rmapp.attempt.RMAppAttemptImpl: appattempt_1375740621345_0001_000001 State change from SUBMITTED to SCHEDULED
2013-08-05 22:10:45,355 INFO org.apache.hadoop.yarn.server.resourcemanager.rmapp.RMAppImpl: application_1375740621345_0001 State change from SUBMITTED to ACCEPTED
2013-08-05 22:10:45,926 INFO org.apache.hadoop.yarn.server.resourcemanager.rmcontainer.RMContainerImpl: container_1375740621345_0001_01_000001 Container Transitioned from NEW to ALLOCATED
2013-08-05 22:10:45,927 INFO org.apache.hadoop.yarn.server.resourcemanager.RMAuditLogger: USER=ubuntu	OPERATION=AM Allocated Container	TARGET=SchedulerApp	RESULT=SUCCESS	APPID=application_1375740621345_0001	CONTAINERID=container_1375740621345_0001_01_000001
2013-08-05 22:10:45,928 INFO org.apache.hadoop.yarn.server.resourcemanager.scheduler.common.fica.FiCaSchedulerNode: Assigned container container_1375740621345_0001_01_000001 of capacity <memory:2048, vCores:1> on host hadoop-100-2:37374, which currently has 1 containers, <memory:2048, vCores:1> used and <memory:6144, vCores:15> available
2013-08-05 22:10:45,934 INFO org.apache.hadoop.yarn.server.resourcemanager.scheduler.capacity.LeafQueue: assignedContainer application=application_1375740621345_0001 container=Container: [ContainerId: container_1375740621345_0001_01_000001, NodeId: hadoop-100-2:37374, NodeHttpAddress: hadoop-100-2:8042, Resource: <memory:2048, vCores:1>, Priority: 0, State: NEW, Token: null, Status: container_id {, app_attempt_id {, application_id {, id: 1, cluster_timestamp: 1375740621345, }, attemptId: 1, }, id: 1, }, state: C_NEW, ] containerId=container_1375740621345_0001_01_000001 queue=default: capacity=1.0, absoluteCapacity=1.0, usedResources=<memory:0, vCores:0>usedCapacity=0.0, absoluteUsedCapacity=0.0, numApps=1, numContainers=0 usedCapacity=0.0 absoluteUsedCapacity=0.0 used=<memory:0, vCores:0> cluster=<memory:49152, vCores:96>
2013-08-05 22:10:45,934 INFO org.apache.hadoop.yarn.server.resourcemanager.scheduler.capacity.ParentQueue: Re-sorting queues since queue: root.default stats: default: capacity=1.0, absoluteCapacity=1.0, usedResources=<memory:2048, vCores:1>usedCapacity=0.041666668, absoluteUsedCapacity=0.041666668, numApps=1, numContainers=1
2013-08-05 22:10:45,938 INFO org.apache.hadoop.yarn.server.resourcemanager.scheduler.capacity.ParentQueue: assignedContainer queue=root usedCapacity=0.041666668 absoluteUsedCapacity=0.041666668 used=<memory:2048, vCores:1> cluster=<memory:49152, vCores:96>
2013-08-05 22:10:45,940 INFO org.apache.hadoop.yarn.server.resourcemanager.rmcontainer.RMContainerImpl: container_1375740621345_0001_01_000001 Container Transitioned from ALLOCATED to ACQUIRED
2013-08-05 22:10:45,943 INFO org.apache.hadoop.yarn.server.resourcemanager.rmapp.attempt.RMAppAttemptImpl: Storing attempt: AppId: application_1375740621345_0001 AttemptId: appattempt_1375740621345_0001_000001 MasterContainer: Container: [ContainerId: container_1375740621345_0001_01_000001, NodeId: hadoop-100-2:37374, NodeHttpAddress: hadoop-100-2:8042, Resource: <memory:2048, vCores:1>, Priority: 0, State: NEW, Token: null, Status: container_id {, app_attempt_id {, application_id {, id: 1, cluster_timestamp: 1375740621345, }, attemptId: 1, }, id: 1, }, state: C_NEW, ]
2013-08-05 22:10:45,947 INFO org.apache.hadoop.yarn.server.resourcemanager.rmapp.attempt.RMAppAttemptImpl: appattempt_1375740621345_0001_000001 State change from SCHEDULED to ALLOCATED_SAVING
2013-08-05 22:10:45,951 INFO org.apache.hadoop.yarn.server.resourcemanager.recovery.RMStateStore: Storing info for attempt: appattempt_1375740621345_0001_000001
2013-08-05 22:10:45,956 INFO org.apache.hadoop.yarn.server.resourcemanager.rmapp.attempt.RMAppAttemptImpl: appattempt_1375740621345_0001_000001 State change from ALLOCATED_SAVING to ALLOCATED
2013-08-05 22:10:45,963 INFO org.apache.hadoop.yarn.server.resourcemanager.amlauncher.AMLauncher: Launching masterappattempt_1375740621345_0001_000001
2013-08-05 22:10:46,005 INFO org.apache.hadoop.yarn.server.resourcemanager.amlauncher.AMLauncher: Setting up container Container: [ContainerId: container_1375740621345_0001_01_000001, NodeId: hadoop-100-2:37374, NodeHttpAddress: hadoop-100-2:8042, Resource: <memory:2048, vCores:1>, Priority: 0, State: NEW, Token: null, Status: container_id {, app_attempt_id {, application_id {, id: 1, cluster_timestamp: 1375740621345, }, attemptId: 1, }, id: 1, }, state: C_NEW, ] for AM appattempt_1375740621345_0001_000001
2013-08-05 22:10:46,005 INFO org.apache.hadoop.yarn.server.resourcemanager.amlauncher.AMLauncher: Command to launch container container_1375740621345_0001_01_000001 : $JAVA_HOME/bin/java -Dlog4j.configuration=container-log4j.properties -Dyarn.app.mapreduce.container.log.dir=<LOG_DIR> -Dyarn.app.mapreduce.container.log.filesize=0 -Dhadoop.root.logger=INFO,CLA  -Xmx1024m org.apache.hadoop.mapreduce.v2.app.MRAppMaster 1><LOG_DIR>/stdout 2><LOG_DIR>/stderr 
2013-08-05 22:10:46,906 INFO org.apache.hadoop.yarn.server.resourcemanager.amlauncher.AMLauncher: Done launching container Container: [ContainerId: container_1375740621345_0001_01_000001, NodeId: hadoop-100-2:37374, NodeHttpAddress: hadoop-100-2:8042, Resource: <memory:2048, vCores:1>, Priority: 0, State: NEW, Token: null, Status: container_id {, app_attempt_id {, application_id {, id: 1, cluster_timestamp: 1375740621345, }, attemptId: 1, }, id: 1, }, state: C_NEW, ] for AM appattempt_1375740621345_0001_000001
2013-08-05 22:10:46,907 INFO org.apache.hadoop.yarn.server.resourcemanager.rmapp.attempt.RMAppAttemptImpl: appattempt_1375740621345_0001_000001 State change from ALLOCATED to LAUNCHED
2013-08-05 22:10:46,929 INFO org.apache.hadoop.yarn.server.resourcemanager.rmcontainer.RMContainerImpl: container_1375740621345_0001_01_000001 Container Transitioned from ACQUIRED to RUNNING
2013-08-05 22:10:55,561 INFO org.apache.hadoop.yarn.server.resourcemanager.ApplicationMasterService: AM registration appattempt_1375740621345_0001_000001
2013-08-05 22:10:55,562 INFO org.apache.hadoop.yarn.server.resourcemanager.RMAuditLogger: USER=ubuntu	IP=192.168.100.4	OPERATION=Register App Master	TARGET=ApplicationMasterService	RESULT=SUCCESS	APPID=application_1375740621345_0001	APPATTEMPTID=appattempt_1375740621345_0001_000001
2013-08-05 22:10:55,567 INFO org.apache.hadoop.yarn.server.resourcemanager.rmapp.attempt.RMAppAttemptImpl: appattempt_1375740621345_0001_000001 State change from LAUNCHED to RUNNING
2013-08-05 22:10:55,567 INFO org.apache.hadoop.yarn.server.resourcemanager.rmapp.RMAppImpl: application_1375740621345_0001 State change from ACCEPTED to RUNNING
2013-08-05 22:10:56,949 INFO org.apache.hadoop.yarn.server.resourcemanager.rmcontainer.RMContainerImpl: container_1375740621345_0001_01_000002 Container Transitioned from NEW to ALLOCATED
2013-08-05 22:10:56,949 INFO org.apache.hadoop.yarn.server.resourcemanager.RMAuditLogger: USER=ubuntu	OPERATION=AM Allocated Container	TARGET=SchedulerApp	RESULT=SUCCESS	APPID=application_1375740621345_0001	CONTAINERID=container_1375740621345_0001_01_000002
2013-08-05 22:10:56,949 INFO org.apache.hadoop.yarn.server.resourcemanager.scheduler.common.fica.FiCaSchedulerNode: Assigned container container_1375740621345_0001_01_000002 of capacity <memory:1024, vCores:1> on host hadoop-100-6:42294, which currently has 1 containers, <memory:1024, vCores:1> used and <memory:7168, vCores:15> available
2013-08-05 22:10:56,951 INFO org.apache.hadoop.yarn.server.resourcemanager.scheduler.capacity.LeafQueue: assignedContainer application=application_1375740621345_0001 container=Container: [ContainerId: container_1375740621345_0001_01_000002, NodeId: hadoop-100-6:42294, NodeHttpAddress: hadoop-100-6:8042, Resource: <memory:1024, vCores:1>, Priority: 20, State: NEW, Token: null, Status: container_id {, app_attempt_id {, application_id {, id: 1, cluster_timestamp: 1375740621345, }, attemptId: 1, }, id: 2, }, state: C_NEW, ] containerId=container_1375740621345_0001_01_000002 queue=default: capacity=1.0, absoluteCapacity=1.0, usedResources=<memory:2048, vCores:1>usedCapacity=0.041666668, absoluteUsedCapacity=0.041666668, numApps=1, numContainers=1 usedCapacity=0.041666668 absoluteUsedCapacity=0.041666668 used=<memory:2048, vCores:1> cluster=<memory:49152, vCores:96>
2013-08-05 22:10:56,952 INFO org.apache.hadoop.yarn.server.resourcemanager.scheduler.capacity.ParentQueue: Re-sorting queues since queue: root.default stats: default: capacity=1.0, absoluteCapacity=1.0, usedResources=<memory:3072, vCores:2>usedCapacity=0.0625, absoluteUsedCapacity=0.0625, numApps=1, numContainers=2
2013-08-05 22:10:56,952 INFO org.apache.hadoop.yarn.server.resourcemanager.scheduler.capacity.ParentQueue: assignedContainer queue=root usedCapacity=0.0625 absoluteUsedCapacity=0.0625 used=<memory:3072, vCores:2> cluster=<memory:49152, vCores:96>
2013-08-05 22:10:56,953 INFO org.apache.hadoop.yarn.server.resourcemanager.rmcontainer.RMContainerImpl: container_1375740621345_0001_01_000003 Container Transitioned from NEW to ALLOCATED
2013-08-05 22:10:56,953 INFO org.apache.hadoop.yarn.server.resourcemanager.RMAuditLogger: USER=ubuntu	OPERATION=AM Allocated Container	TARGET=SchedulerApp	RESULT=SUCCESS	APPID=application_1375740621345_0001	CONTAINERID=container_1375740621345_0001_01_000003
2013-08-05 22:10:56,953 INFO org.apache.hadoop.yarn.server.resourcemanager.scheduler.common.fica.FiCaSchedulerNode: Assigned container container_1375740621345_0001_01_000003 of capacity <memory:1024, vCores:1> on host hadoop-100-5:58882, which currently has 1 containers, <memory:1024, vCores:1> used and <memory:7168, vCores:15> available
2013-08-05 22:10:56,955 INFO org.apache.hadoop.yarn.server.resourcemanager.scheduler.capacity.LeafQueue: assignedContainer application=application_1375740621345_0001 container=Container: [ContainerId: container_1375740621345_0001_01_000003, NodeId: hadoop-100-5:58882, NodeHttpAddress: hadoop-100-5:8042, Resource: <memory:1024, vCores:1>, Priority: 20, State: NEW, Token: null, Status: container_id {, app_attempt_id {, application_id {, id: 1, cluster_timestamp: 1375740621345, }, attemptId: 1, }, id: 3, }, state: C_NEW, ] containerId=container_1375740621345_0001_01_000003 queue=default: capacity=1.0, absoluteCapacity=1.0, usedResources=<memory:3072, vCores:2>usedCapacity=0.0625, absoluteUsedCapacity=0.0625, numApps=1, numContainers=2 usedCapacity=0.0625 absoluteUsedCapacity=0.0625 used=<memory:3072, vCores:2> cluster=<memory:49152, vCores:96>
2013-08-05 22:10:56,955 INFO org.apache.hadoop.yarn.server.resourcemanager.scheduler.capacity.ParentQueue: Re-sorting queues since queue: root.default stats: default: capacity=1.0, absoluteCapacity=1.0, usedResources=<memory:4096, vCores:3>usedCapacity=0.083333336, absoluteUsedCapacity=0.083333336, numApps=1, numContainers=3
2013-08-05 22:10:56,955 INFO org.apache.hadoop.yarn.server.resourcemanager.scheduler.capacity.ParentQueue: assignedContainer queue=root usedCapacity=0.083333336 absoluteUsedCapacity=0.083333336 used=<memory:4096, vCores:3> cluster=<memory:49152, vCores:96>
2013-08-05 22:10:57,639 INFO org.apache.hadoop.yarn.server.resourcemanager.rmcontainer.RMContainerImpl: container_1375740621345_0001_01_000002 Container Transitioned from ALLOCATED to ACQUIRED
2013-08-05 22:10:57,641 INFO org.apache.hadoop.yarn.server.resourcemanager.rmcontainer.RMContainerImpl: container_1375740621345_0001_01_000003 Container Transitioned from ALLOCATED to ACQUIRED
2013-08-05 22:10:58,687 INFO org.apache.hadoop.yarn.server.resourcemanager.scheduler.AppSchedulingInfo: checking for deactivate... 
2013-08-05 22:10:59,052 INFO org.apache.hadoop.yarn.server.resourcemanager.rmcontainer.RMContainerImpl: container_1375740621345_0001_01_000002 Container Transitioned from ACQUIRED to RUNNING
2013-08-05 22:10:59,099 INFO org.apache.hadoop.yarn.server.resourcemanager.rmcontainer.RMContainerImpl: container_1375740621345_0001_01_000003 Container Transitioned from ACQUIRED to RUNNING
2013-08-05 22:12:49,641 INFO org.apache.hadoop.yarn.server.resourcemanager.rmcontainer.RMContainerImpl: container_1375740621345_0001_01_000003 Container Transitioned from RUNNING to COMPLETED
2013-08-05 22:12:49,641 INFO org.apache.hadoop.yarn.server.resourcemanager.scheduler.common.fica.FiCaSchedulerApp: Completed container: container_1375740621345_0001_01_000003 in state: COMPLETED event:FINISHED
2013-08-05 22:12:49,641 INFO org.apache.hadoop.yarn.server.resourcemanager.RMAuditLogger: USER=ubuntu	OPERATION=AM Released Container	TARGET=SchedulerApp	RESULT=SUCCESS	APPID=application_1375740621345_0001	CONTAINERID=container_1375740621345_0001_01_000003
2013-08-05 22:12:49,642 INFO org.apache.hadoop.yarn.server.resourcemanager.scheduler.common.fica.FiCaSchedulerNode: Released container container_1375740621345_0001_01_000003 of capacity <memory:1024, vCores:1> on host hadoop-100-5:58882, which currently has 0 containers, <memory:0, vCores:0> used and <memory:8192, vCores:16> available, release resources=true
2013-08-05 22:12:49,642 INFO org.apache.hadoop.yarn.server.resourcemanager.scheduler.capacity.LeafQueue: default used=<memory:3072, vCores:2> numContainers=2 user=ubuntu user-resources=<memory:3072, vCores:2>
2013-08-05 22:12:49,644 INFO org.apache.hadoop.yarn.server.resourcemanager.scheduler.capacity.LeafQueue: completedContainer container=Container: [ContainerId: container_1375740621345_0001_01_000003, NodeId: hadoop-100-5:58882, NodeHttpAddress: hadoop-100-5:8042, Resource: <memory:1024, vCores:1>, Priority: 20, State: NEW, Token: null, Status: container_id {, app_attempt_id {, application_id {, id: 1, cluster_timestamp: 1375740621345, }, attemptId: 1, }, id: 3, }, state: C_COMPLETE, diagnostics: "Container killed by the ApplicationMaster.\n\n", exit_status: 143, ] resource=<memory:1024, vCores:1> queue=default: capacity=1.0, absoluteCapacity=1.0, usedResources=<memory:3072, vCores:2>usedCapacity=0.0625, absoluteUsedCapacity=0.0625, numApps=1, numContainers=2 usedCapacity=0.0625 absoluteUsedCapacity=0.0625 used=<memory:3072, vCores:2> cluster=<memory:49152, vCores:96>
2013-08-05 22:12:49,645 INFO org.apache.hadoop.yarn.server.resourcemanager.scheduler.capacity.ParentQueue: completedContainer queue=root usedCapacity=0.0625 absoluteUsedCapacity=0.0625 used=<memory:3072, vCores:2> cluster=<memory:49152, vCores:96>
2013-08-05 22:12:49,645 INFO org.apache.hadoop.yarn.server.resourcemanager.scheduler.capacity.CapacityScheduler: Application appattempt_1375740621345_0001_000001 released container container_1375740621345_0001_01_000003 on node: host: hadoop-100-5:58882 #containers=0 available=8192 used=0 with event: FINISHED
2013-08-05 22:12:51,867 INFO org.apache.hadoop.yarn.server.resourcemanager.rmcontainer.RMContainerImpl: container_1375740621345_0001_01_000002 Container Transitioned from RUNNING to COMPLETED
2013-08-05 22:12:51,868 INFO org.apache.hadoop.yarn.server.resourcemanager.scheduler.common.fica.FiCaSchedulerApp: Completed container: container_1375740621345_0001_01_000002 in state: COMPLETED event:FINISHED
2013-08-05 22:12:51,868 INFO org.apache.hadoop.yarn.server.resourcemanager.RMAuditLogger: USER=ubuntu	OPERATION=AM Released Container	TARGET=SchedulerApp	RESULT=SUCCESS	APPID=application_1375740621345_0001	CONTAINERID=container_1375740621345_0001_01_000002
2013-08-05 22:12:51,868 INFO org.apache.hadoop.yarn.server.resourcemanager.scheduler.common.fica.FiCaSchedulerNode: Released container container_1375740621345_0001_01_000002 of capacity <memory:1024, vCores:1> on host hadoop-100-6:42294, which currently has 0 containers, <memory:0, vCores:0> used and <memory:8192, vCores:16> available, release resources=true
2013-08-05 22:12:51,868 INFO org.apache.hadoop.yarn.server.resourcemanager.scheduler.capacity.LeafQueue: default used=<memory:2048, vCores:1> numContainers=1 user=ubuntu user-resources=<memory:2048, vCores:1>
2013-08-05 22:12:51,870 INFO org.apache.hadoop.yarn.server.resourcemanager.scheduler.capacity.LeafQueue: completedContainer container=Container: [ContainerId: container_1375740621345_0001_01_000002, NodeId: hadoop-100-6:42294, NodeHttpAddress: hadoop-100-6:8042, Resource: <memory:1024, vCores:1>, Priority: 20, State: NEW, Token: null, Status: container_id {, app_attempt_id {, application_id {, id: 1, cluster_timestamp: 1375740621345, }, attemptId: 1, }, id: 2, }, state: C_COMPLETE, diagnostics: "Container killed by the ApplicationMaster.\n\n", exit_status: 143, ] resource=<memory:1024, vCores:1> queue=default: capacity=1.0, absoluteCapacity=1.0, usedResources=<memory:2048, vCores:1>usedCapacity=0.041666668, absoluteUsedCapacity=0.041666668, numApps=1, numContainers=1 usedCapacity=0.041666668 absoluteUsedCapacity=0.041666668 used=<memory:2048, vCores:1> cluster=<memory:49152, vCores:96>
2013-08-05 22:12:51,870 INFO org.apache.hadoop.yarn.server.resourcemanager.scheduler.capacity.ParentQueue: completedContainer queue=root usedCapacity=0.041666668 absoluteUsedCapacity=0.041666668 used=<memory:2048, vCores:1> cluster=<memory:49152, vCores:96>
2013-08-05 22:12:51,871 INFO org.apache.hadoop.yarn.server.resourcemanager.scheduler.capacity.CapacityScheduler: Application appattempt_1375740621345_0001_000001 released container container_1375740621345_0001_01_000002 on node: host: hadoop-100-6:42294 #containers=0 available=8192 used=0 with event: FINISHED
2013-08-05 22:12:56,021 INFO org.apache.hadoop.yarn.server.resourcemanager.rmapp.attempt.RMAppAttemptImpl: appattempt_1375740621345_0001_000001 State change from RUNNING to FINISHING
2013-08-05 22:12:56,022 INFO org.apache.hadoop.yarn.server.resourcemanager.rmapp.RMAppImpl: application_1375740621345_0001 State change from RUNNING to FINISHING
2013-08-05 22:12:56,683 INFO org.apache.hadoop.yarn.server.resourcemanager.rmcontainer.RMContainerImpl: container_1375740621345_0001_01_000001 Container Transitioned from RUNNING to COMPLETED
2013-08-05 22:12:56,683 INFO org.apache.hadoop.yarn.server.resourcemanager.scheduler.common.fica.FiCaSchedulerApp: Completed container: container_1375740621345_0001_01_000001 in state: COMPLETED event:FINISHED
2013-08-05 22:12:56,683 INFO org.apache.hadoop.yarn.server.resourcemanager.RMAuditLogger: USER=ubuntu	OPERATION=AM Released Container	TARGET=SchedulerApp	RESULT=SUCCESS	APPID=application_1375740621345_0001	CONTAINERID=container_1375740621345_0001_01_000001
2013-08-05 22:12:56,683 INFO org.apache.hadoop.yarn.server.resourcemanager.scheduler.common.fica.FiCaSchedulerNode: Released container container_1375740621345_0001_01_000001 of capacity <memory:2048, vCores:1> on host hadoop-100-2:37374, which currently has 0 containers, <memory:0, vCores:0> used and <memory:8192, vCores:16> available, release resources=true
2013-08-05 22:12:56,684 INFO org.apache.hadoop.yarn.server.resourcemanager.scheduler.capacity.LeafQueue: default used=<memory:0, vCores:0> numContainers=0 user=ubuntu user-resources=<memory:0, vCores:0>
2013-08-05 22:12:56,685 INFO org.apache.hadoop.yarn.server.resourcemanager.scheduler.capacity.LeafQueue: completedContainer container=Container: [ContainerId: container_1375740621345_0001_01_000001, NodeId: hadoop-100-2:37374, NodeHttpAddress: hadoop-100-2:8042, Resource: <memory:2048, vCores:1>, Priority: 0, State: NEW, Token: null, Status: container_id {, app_attempt_id {, application_id {, id: 1, cluster_timestamp: 1375740621345, }, attemptId: 1, }, id: 1, }, state: C_COMPLETE, diagnostics: "", exit_status: 0, ] resource=<memory:2048, vCores:1> queue=default: capacity=1.0, absoluteCapacity=1.0, usedResources=<memory:0, vCores:0>usedCapacity=0.0, absoluteUsedCapacity=0.0, numApps=1, numContainers=0 usedCapacity=0.0 absoluteUsedCapacity=0.0 used=<memory:0, vCores:0> cluster=<memory:49152, vCores:96>
2013-08-05 22:12:56,686 INFO org.apache.hadoop.yarn.server.resourcemanager.scheduler.capacity.ParentQueue: completedContainer queue=root usedCapacity=0.0 absoluteUsedCapacity=0.0 used=<memory:0, vCores:0> cluster=<memory:49152, vCores:96>
2013-08-05 22:12:56,686 INFO org.apache.hadoop.yarn.server.resourcemanager.scheduler.capacity.CapacityScheduler: Application appattempt_1375740621345_0001_000001 released container container_1375740621345_0001_01_000001 on node: host: hadoop-100-2:37374 #containers=0 available=8192 used=0 with event: FINISHED
2013-08-05 22:12:56,689 INFO org.apache.hadoop.yarn.server.resourcemanager.rmapp.attempt.RMAppAttemptImpl: appattempt_1375740621345_0001_000001 State change from FINISHING to FINISHED
2013-08-05 22:12:56,691 INFO org.apache.hadoop.yarn.server.resourcemanager.rmapp.RMAppImpl: application_1375740621345_0001 State change from FINISHING to FINISHED
2013-08-05 22:12:56,691 INFO org.apache.hadoop.yarn.server.resourcemanager.scheduler.capacity.CapacityScheduler: Application appattempt_1375740621345_0001_000001 is done. finalState=FINISHED
2013-08-05 22:12:56,691 INFO org.apache.hadoop.yarn.server.resourcemanager.RMAuditLogger: USER=ubuntu	OPERATION=Application Finished - Succeeded	TARGET=RMAppManager	RESULT=SUCCESS	APPID=application_1375740621345_0001
2013-08-05 22:12:56,692 INFO org.apache.hadoop.yarn.server.resourcemanager.amlauncher.AMLauncher: Cleaning master appattempt_1375740621345_0001_000001
2013-08-05 22:12:56,693 INFO org.apache.hadoop.yarn.server.resourcemanager.scheduler.AppSchedulingInfo: Application application_1375740621345_0001 requests cleared
2013-08-05 22:12:56,701 INFO org.apache.hadoop.yarn.server.resourcemanager.scheduler.capacity.LeafQueue: Application removed - appId: application_1375740621345_0001 user: ubuntu queue: default #user-pending-applications: 0 #user-active-applications: 0 #queue-pending-applications: 0 #queue-active-applications: 0
2013-08-05 22:12:56,701 INFO org.apache.hadoop.yarn.server.resourcemanager.scheduler.capacity.ParentQueue: Application removed - appId: application_1375740621345_0001 user: ubuntu leaf-queue of parent: root #applications: 0
2013-08-05 22:12:56,703 INFO org.apache.hadoop.yarn.server.resourcemanager.recovery.RMStateStore: Removing info for app: application_1375740621345_0001
2013-08-05 22:12:56,708 INFO org.apache.hadoop.yarn.server.resourcemanager.RMAppManager$ApplicationSummary: appId=application_1375740621345_0001,name=TeraGen,user=ubuntu,queue=default,state=FINISHED,trackingUrl=hadoop-100-1.novalocal:8088/proxy/application_1375740621345_0001/jobhistory/job/job_1375740621345_0001,appMasterHost=hadoop-100-2,startTime=1375740645251,finishTime=1375740776022
2013-08-05 22:12:57,435 INFO org.apache.hadoop.yarn.server.resourcemanager.ClientRMService: Allocated new applicationId: 2
2013-08-05 22:12:59,374 INFO org.apache.hadoop.yarn.server.resourcemanager.ClientRMService: Storing Application with id application_1375740621345_0002
2013-08-05 22:12:59,374 INFO org.apache.hadoop.yarn.server.resourcemanager.recovery.RMStateStore: Storing info for app: application_1375740621345_0002
2013-08-05 22:12:59,374 INFO org.apache.hadoop.yarn.server.resourcemanager.ClientRMService: Application with id 2 submitted by user ubuntu
2013-08-05 22:12:59,374 INFO org.apache.hadoop.yarn.server.resourcemanager.RMAuditLogger: USER=ubuntu	IP=192.168.100.3	OPERATION=Submit Application Request	TARGET=ClientRMService	RESULT=SUCCESS	APPID=application_1375740621345_0002
2013-08-05 22:12:59,379 INFO org.apache.hadoop.yarn.server.resourcemanager.rmapp.RMAppImpl: application_1375740621345_0002 State change from NEW to SUBMITTED
2013-08-05 22:12:59,380 INFO org.apache.hadoop.yarn.server.resourcemanager.ApplicationMasterService: Registering appattempt_1375740621345_0002_000001
2013-08-05 22:12:59,380 INFO org.apache.hadoop.yarn.server.resourcemanager.rmapp.attempt.RMAppAttemptImpl: appattempt_1375740621345_0002_000001 State change from NEW to SUBMITTED
2013-08-05 22:12:59,381 INFO org.apache.hadoop.yarn.server.resourcemanager.scheduler.capacity.LeafQueue: Application application_1375740621345_0002 from user: ubuntu activated in queue: default
2013-08-05 22:12:59,381 INFO org.apache.hadoop.yarn.server.resourcemanager.scheduler.capacity.LeafQueue: Application added - appId: application_1375740621345_0002 user: org.apache.hadoop.yarn.server.resourcemanager.scheduler.capacity.LeafQueue$User@1be68d72, leaf-queue: default #user-pending-applications: 0 #user-active-applications: 1 #queue-pending-applications: 0 #queue-active-applications: 1
2013-08-05 22:12:59,381 INFO org.apache.hadoop.yarn.server.resourcemanager.scheduler.capacity.ParentQueue: Application added - appId: application_1375740621345_0002 user: ubuntu leaf-queue of parent: root #applications: 1
2013-08-05 22:12:59,381 INFO org.apache.hadoop.yarn.server.resourcemanager.scheduler.capacity.CapacityScheduler: Application Submission: appattempt_1375740621345_0002_000001, user: ubuntu queue: default: capacity=1.0, absoluteCapacity=1.0, usedResources=<memory:0, vCores:0>usedCapacity=0.0, absoluteUsedCapacity=0.0, numApps=1, numContainers=0, currently active: 1
2013-08-05 22:12:59,382 INFO org.apache.hadoop.yarn.server.resourcemanager.rmapp.attempt.RMAppAttemptImpl: appattempt_1375740621345_0002_000001 State change from SUBMITTED to SCHEDULED
2013-08-05 22:12:59,382 INFO org.apache.hadoop.yarn.server.resourcemanager.rmapp.RMAppImpl: application_1375740621345_0002 State change from SUBMITTED to ACCEPTED
2013-08-05 22:12:59,463 INFO org.apache.hadoop.yarn.server.resourcemanager.rmcontainer.RMContainerImpl: container_1375740621345_0002_01_000001 Container Transitioned from NEW to ALLOCATED
2013-08-05 22:12:59,463 INFO org.apache.hadoop.yarn.server.resourcemanager.RMAuditLogger: USER=ubuntu	OPERATION=AM Allocated Container	TARGET=SchedulerApp	RESULT=SUCCESS	APPID=application_1375740621345_0002	CONTAINERID=container_1375740621345_0002_01_000001
2013-08-05 22:12:59,464 INFO org.apache.hadoop.yarn.server.resourcemanager.scheduler.common.fica.FiCaSchedulerNode: Assigned container container_1375740621345_0002_01_000001 of capacity <memory:2048, vCores:1> on host hadoop-100-3:44102, which currently has 1 containers, <memory:2048, vCores:1> used and <memory:6144, vCores:15> available
2013-08-05 22:12:59,466 INFO org.apache.hadoop.yarn.server.resourcemanager.scheduler.capacity.LeafQueue: assignedContainer application=application_1375740621345_0002 container=Container: [ContainerId: container_1375740621345_0002_01_000001, NodeId: hadoop-100-3:44102, NodeHttpAddress: hadoop-100-3:8042, Resource: <memory:2048, vCores:1>, Priority: 0, State: NEW, Token: null, Status: container_id {, app_attempt_id {, application_id {, id: 2, cluster_timestamp: 1375740621345, }, attemptId: 1, }, id: 1, }, state: C_NEW, ] containerId=container_1375740621345_0002_01_000001 queue=default: capacity=1.0, absoluteCapacity=1.0, usedResources=<memory:0, vCores:0>usedCapacity=0.0, absoluteUsedCapacity=0.0, numApps=1, numContainers=0 usedCapacity=0.0 absoluteUsedCapacity=0.0 used=<memory:0, vCores:0> cluster=<memory:49152, vCores:96>
2013-08-05 22:12:59,466 INFO org.apache.hadoop.yarn.server.resourcemanager.scheduler.capacity.ParentQueue: Re-sorting queues since queue: root.default stats: default: capacity=1.0, absoluteCapacity=1.0, usedResources=<memory:2048, vCores:1>usedCapacity=0.041666668, absoluteUsedCapacity=0.041666668, numApps=1, numContainers=1
2013-08-05 22:12:59,467 INFO org.apache.hadoop.yarn.server.resourcemanager.rmcontainer.RMContainerImpl: container_1375740621345_0002_01_000001 Container Transitioned from ALLOCATED to ACQUIRED
2013-08-05 22:12:59,467 INFO org.apache.hadoop.yarn.server.resourcemanager.scheduler.capacity.ParentQueue: assignedContainer queue=root usedCapacity=0.041666668 absoluteUsedCapacity=0.041666668 used=<memory:2048, vCores:1> cluster=<memory:49152, vCores:96>
2013-08-05 22:12:59,469 INFO org.apache.hadoop.yarn.server.resourcemanager.rmapp.attempt.RMAppAttemptImpl: Storing attempt: AppId: application_1375740621345_0002 AttemptId: appattempt_1375740621345_0002_000001 MasterContainer: Container: [ContainerId: container_1375740621345_0002_01_000001, NodeId: hadoop-100-3:44102, NodeHttpAddress: hadoop-100-3:8042, Resource: <memory:2048, vCores:1>, Priority: 0, State: NEW, Token: null, Status: container_id {, app_attempt_id {, application_id {, id: 2, cluster_timestamp: 1375740621345, }, attemptId: 1, }, id: 1, }, state: C_NEW, ]
2013-08-05 22:12:59,470 INFO org.apache.hadoop.yarn.server.resourcemanager.recovery.RMStateStore: Storing info for attempt: appattempt_1375740621345_0002_000001
2013-08-05 22:12:59,470 INFO org.apache.hadoop.yarn.server.resourcemanager.rmapp.attempt.RMAppAttemptImpl: appattempt_1375740621345_0002_000001 State change from SCHEDULED to ALLOCATED_SAVING
2013-08-05 22:12:59,471 INFO org.apache.hadoop.yarn.server.resourcemanager.rmapp.attempt.RMAppAttemptImpl: appattempt_1375740621345_0002_000001 State change from ALLOCATED_SAVING to ALLOCATED
2013-08-05 22:12:59,472 INFO org.apache.hadoop.yarn.server.resourcemanager.amlauncher.AMLauncher: Launching masterappattempt_1375740621345_0002_000001
2013-08-05 22:12:59,475 INFO org.apache.hadoop.yarn.server.resourcemanager.amlauncher.AMLauncher: Setting up container Container: [ContainerId: container_1375740621345_0002_01_000001, NodeId: hadoop-100-3:44102, NodeHttpAddress: hadoop-100-3:8042, Resource: <memory:2048, vCores:1>, Priority: 0, State: NEW, Token: null, Status: container_id {, app_attempt_id {, application_id {, id: 2, cluster_timestamp: 1375740621345, }, attemptId: 1, }, id: 1, }, state: C_NEW, ] for AM appattempt_1375740621345_0002_000001
2013-08-05 22:12:59,476 INFO org.apache.hadoop.yarn.server.resourcemanager.amlauncher.AMLauncher: Command to launch container container_1375740621345_0002_01_000001 : $JAVA_HOME/bin/java -Dlog4j.configuration=container-log4j.properties -Dyarn.app.mapreduce.container.log.dir=<LOG_DIR> -Dyarn.app.mapreduce.container.log.filesize=0 -Dhadoop.root.logger=INFO,CLA  -Xmx1024m org.apache.hadoop.mapreduce.v2.app.MRAppMaster 1><LOG_DIR>/stdout 2><LOG_DIR>/stderr 
2013-08-05 22:13:00,301 INFO org.apache.hadoop.yarn.server.resourcemanager.amlauncher.AMLauncher: Done launching container Container: [ContainerId: container_1375740621345_0002_01_000001, NodeId: hadoop-100-3:44102, NodeHttpAddress: hadoop-100-3:8042, Resource: <memory:2048, vCores:1>, Priority: 0, State: NEW, Token: null, Status: container_id {, app_attempt_id {, application_id {, id: 2, cluster_timestamp: 1375740621345, }, attemptId: 1, }, id: 1, }, state: C_NEW, ] for AM appattempt_1375740621345_0002_000001
2013-08-05 22:13:00,302 INFO org.apache.hadoop.yarn.server.resourcemanager.rmapp.attempt.RMAppAttemptImpl: appattempt_1375740621345_0002_000001 State change from ALLOCATED to LAUNCHED
2013-08-05 22:13:00,634 INFO org.apache.hadoop.yarn.server.resourcemanager.rmcontainer.RMContainerImpl: container_1375740621345_0002_01_000001 Container Transitioned from ACQUIRED to RUNNING
2013-08-05 22:13:10,554 INFO org.apache.hadoop.yarn.server.resourcemanager.ApplicationMasterService: AM registration appattempt_1375740621345_0002_000001
2013-08-05 22:13:10,554 INFO org.apache.hadoop.yarn.server.resourcemanager.RMAuditLogger: USER=ubuntu	IP=192.168.100.13	OPERATION=Register App Master	TARGET=ApplicationMasterService	RESULT=SUCCESS	APPID=application_1375740621345_0002	APPATTEMPTID=appattempt_1375740621345_0002_000001
2013-08-05 22:13:10,567 INFO org.apache.hadoop.yarn.server.resourcemanager.rmapp.attempt.RMAppAttemptImpl: appattempt_1375740621345_0002_000001 State change from LAUNCHED to RUNNING
2013-08-05 22:13:10,567 INFO org.apache.hadoop.yarn.server.resourcemanager.rmapp.RMAppImpl: application_1375740621345_0002 State change from ACCEPTED to RUNNING
2013-08-05 22:13:11,687 INFO org.apache.hadoop.yarn.server.resourcemanager.rmcontainer.RMContainerImpl: container_1375740621345_0002_01_000002 Container Transitioned from NEW to ALLOCATED
2013-08-05 22:13:11,688 INFO org.apache.hadoop.yarn.server.resourcemanager.RMAuditLogger: USER=ubuntu	OPERATION=AM Allocated Container	TARGET=SchedulerApp	RESULT=SUCCESS	APPID=application_1375740621345_0002	CONTAINERID=container_1375740621345_0002_01_000002
2013-08-05 22:13:11,688 INFO org.apache.hadoop.yarn.server.resourcemanager.scheduler.common.fica.FiCaSchedulerNode: Assigned container container_1375740621345_0002_01_000002 of capacity <memory:1024, vCores:1> on host hadoop-100-4:50425, which currently has 1 containers, <memory:1024, vCores:1> used and <memory:7168, vCores:15> available
2013-08-05 22:13:11,690 INFO org.apache.hadoop.yarn.server.resourcemanager.scheduler.capacity.LeafQueue: assignedContainer application=application_1375740621345_0002 container=Container: [ContainerId: container_1375740621345_0002_01_000002, NodeId: hadoop-100-4:50425, NodeHttpAddress: hadoop-100-4:8042, Resource: <memory:1024, vCores:1>, Priority: 20, State: NEW, Token: null, Status: container_id {, app_attempt_id {, application_id {, id: 2, cluster_timestamp: 1375740621345, }, attemptId: 1, }, id: 2, }, state: C_NEW, ] containerId=container_1375740621345_0002_01_000002 queue=default: capacity=1.0, absoluteCapacity=1.0, usedResources=<memory:2048, vCores:1>usedCapacity=0.041666668, absoluteUsedCapacity=0.041666668, numApps=1, numContainers=1 usedCapacity=0.041666668 absoluteUsedCapacity=0.041666668 used=<memory:2048, vCores:1> cluster=<memory:49152, vCores:96>
2013-08-05 22:13:11,690 INFO org.apache.hadoop.yarn.server.resourcemanager.scheduler.capacity.ParentQueue: Re-sorting queues since queue: root.default stats: default: capacity=1.0, absoluteCapacity=1.0, usedResources=<memory:3072, vCores:2>usedCapacity=0.0625, absoluteUsedCapacity=0.0625, numApps=1, numContainers=2
2013-08-05 22:13:11,690 INFO org.apache.hadoop.yarn.server.resourcemanager.scheduler.capacity.ParentQueue: assignedContainer queue=root usedCapacity=0.0625 absoluteUsedCapacity=0.0625 used=<memory:3072, vCores:2> cluster=<memory:49152, vCores:96>
2013-08-05 22:13:11,692 INFO org.apache.hadoop.yarn.server.resourcemanager.rmcontainer.RMContainerImpl: container_1375740621345_0002_01_000003 Container Transitioned from NEW to ALLOCATED
2013-08-05 22:13:11,692 INFO org.apache.hadoop.yarn.server.resourcemanager.RMAuditLogger: USER=ubuntu	OPERATION=AM Allocated Container	TARGET=SchedulerApp	RESULT=SUCCESS	APPID=application_1375740621345_0002	CONTAINERID=container_1375740621345_0002_01_000003
2013-08-05 22:13:11,692 INFO org.apache.hadoop.yarn.server.resourcemanager.scheduler.common.fica.FiCaSchedulerNode: Assigned container container_1375740621345_0002_01_000003 of capacity <memory:1024, vCores:1> on host hadoop-100-7:36057, which currently has 1 containers, <memory:1024, vCores:1> used and <memory:7168, vCores:15> available
2013-08-05 22:13:11,694 INFO org.apache.hadoop.yarn.server.resourcemanager.scheduler.capacity.LeafQueue: assignedContainer application=application_1375740621345_0002 container=Container: [ContainerId: container_1375740621345_0002_01_000003, NodeId: hadoop-100-7:36057, NodeHttpAddress: hadoop-100-7:8042, Resource: <memory:1024, vCores:1>, Priority: 20, State: NEW, Token: null, Status: container_id {, app_attempt_id {, application_id {, id: 2, cluster_timestamp: 1375740621345, }, attemptId: 1, }, id: 3, }, state: C_NEW, ] containerId=container_1375740621345_0002_01_000003 queue=default: capacity=1.0, absoluteCapacity=1.0, usedResources=<memory:3072, vCores:2>usedCapacity=0.0625, absoluteUsedCapacity=0.0625, numApps=1, numContainers=2 usedCapacity=0.0625 absoluteUsedCapacity=0.0625 used=<memory:3072, vCores:2> cluster=<memory:49152, vCores:96>
2013-08-05 22:13:11,694 INFO org.apache.hadoop.yarn.server.resourcemanager.scheduler.capacity.ParentQueue: Re-sorting queues since queue: root.default stats: default: capacity=1.0, absoluteCapacity=1.0, usedResources=<memory:4096, vCores:3>usedCapacity=0.083333336, absoluteUsedCapacity=0.083333336, numApps=1, numContainers=3
2013-08-05 22:13:11,694 INFO org.apache.hadoop.yarn.server.resourcemanager.scheduler.capacity.ParentQueue: assignedContainer queue=root usedCapacity=0.083333336 absoluteUsedCapacity=0.083333336 used=<memory:4096, vCores:3> cluster=<memory:49152, vCores:96>
2013-08-05 22:13:12,602 INFO org.apache.hadoop.yarn.server.resourcemanager.rmcontainer.RMContainerImpl: container_1375740621345_0002_01_000002 Container Transitioned from ALLOCATED to ACQUIRED
2013-08-05 22:13:12,609 INFO org.apache.hadoop.yarn.server.resourcemanager.rmcontainer.RMContainerImpl: container_1375740621345_0002_01_000003 Container Transitioned from ALLOCATED to ACQUIRED
2013-08-05 22:13:13,649 INFO org.apache.hadoop.yarn.server.resourcemanager.scheduler.AppSchedulingInfo: checking for deactivate... 
2013-08-05 22:13:13,718 INFO org.apache.hadoop.yarn.server.resourcemanager.rmcontainer.RMContainerImpl: container_1375740621345_0002_01_000002 Container Transitioned from ACQUIRED to RUNNING
2013-08-05 22:13:13,736 INFO org.apache.hadoop.yarn.server.resourcemanager.rmcontainer.RMContainerImpl: container_1375740621345_0002_01_000003 Container Transitioned from ACQUIRED to RUNNING
2013-08-05 22:14:58,536 INFO org.apache.hadoop.yarn.server.resourcemanager.rmcontainer.RMContainerImpl: container_1375740621345_0002_01_000003 Container Transitioned from RUNNING to COMPLETED
2013-08-05 22:14:58,537 INFO org.apache.hadoop.yarn.server.resourcemanager.scheduler.common.fica.FiCaSchedulerApp: Completed container: container_1375740621345_0002_01_000003 in state: COMPLETED event:FINISHED
2013-08-05 22:14:58,537 INFO org.apache.hadoop.yarn.server.resourcemanager.RMAuditLogger: USER=ubuntu	OPERATION=AM Released Container	TARGET=SchedulerApp	RESULT=SUCCESS	APPID=application_1375740621345_0002	CONTAINERID=container_1375740621345_0002_01_000003
2013-08-05 22:14:58,537 INFO org.apache.hadoop.yarn.server.resourcemanager.scheduler.common.fica.FiCaSchedulerNode: Released container container_1375740621345_0002_01_000003 of capacity <memory:1024, vCores:1> on host hadoop-100-7:36057, which currently has 0 containers, <memory:0, vCores:0> used and <memory:8192, vCores:16> available, release resources=true
2013-08-05 22:14:58,537 INFO org.apache.hadoop.yarn.server.resourcemanager.scheduler.capacity.LeafQueue: default used=<memory:3072, vCores:2> numContainers=2 user=ubuntu user-resources=<memory:3072, vCores:2>
2013-08-05 22:14:58,551 INFO org.apache.hadoop.yarn.server.resourcemanager.scheduler.capacity.LeafQueue: completedContainer container=Container: [ContainerId: container_1375740621345_0002_01_000003, NodeId: hadoop-100-7:36057, NodeHttpAddress: hadoop-100-7:8042, Resource: <memory:1024, vCores:1>, Priority: 20, State: NEW, Token: null, Status: container_id {, app_attempt_id {, application_id {, id: 2, cluster_timestamp: 1375740621345, }, attemptId: 1, }, id: 3, }, state: C_COMPLETE, diagnostics: "Container killed by the ApplicationMaster.\n\n", exit_status: 143, ] resource=<memory:1024, vCores:1> queue=default: capacity=1.0, absoluteCapacity=1.0, usedResources=<memory:3072, vCores:2>usedCapacity=0.0625, absoluteUsedCapacity=0.0625, numApps=1, numContainers=2 usedCapacity=0.0625 absoluteUsedCapacity=0.0625 used=<memory:3072, vCores:2> cluster=<memory:49152, vCores:96>
2013-08-05 22:14:58,551 INFO org.apache.hadoop.yarn.server.resourcemanager.scheduler.capacity.ParentQueue: completedContainer queue=root usedCapacity=0.0625 absoluteUsedCapacity=0.0625 used=<memory:3072, vCores:2> cluster=<memory:49152, vCores:96>
2013-08-05 22:14:58,551 INFO org.apache.hadoop.yarn.server.resourcemanager.scheduler.capacity.CapacityScheduler: Application appattempt_1375740621345_0002_000001 released container container_1375740621345_0002_01_000003 on node: host: hadoop-100-7:36057 #containers=0 available=8192 used=0 with event: FINISHED
2013-08-05 22:15:01,787 INFO org.apache.hadoop.yarn.server.resourcemanager.rmcontainer.RMContainerImpl: container_1375740621345_0002_01_000002 Container Transitioned from RUNNING to COMPLETED
2013-08-05 22:15:01,787 INFO org.apache.hadoop.yarn.server.resourcemanager.scheduler.common.fica.FiCaSchedulerApp: Completed container: container_1375740621345_0002_01_000002 in state: COMPLETED event:FINISHED
2013-08-05 22:15:01,787 INFO org.apache.hadoop.yarn.server.resourcemanager.RMAuditLogger: USER=ubuntu	OPERATION=AM Released Container	TARGET=SchedulerApp	RESULT=SUCCESS	APPID=application_1375740621345_0002	CONTAINERID=container_1375740621345_0002_01_000002
2013-08-05 22:15:01,788 INFO org.apache.hadoop.yarn.server.resourcemanager.scheduler.common.fica.FiCaSchedulerNode: Released container container_1375740621345_0002_01_000002 of capacity <memory:1024, vCores:1> on host hadoop-100-4:50425, which currently has 0 containers, <memory:0, vCores:0> used and <memory:8192, vCores:16> available, release resources=true
2013-08-05 22:15:01,788 INFO org.apache.hadoop.yarn.server.resourcemanager.scheduler.capacity.LeafQueue: default used=<memory:2048, vCores:1> numContainers=1 user=ubuntu user-resources=<memory:2048, vCores:1>
2013-08-05 22:15:01,790 INFO org.apache.hadoop.yarn.server.resourcemanager.scheduler.capacity.LeafQueue: completedContainer container=Container: [ContainerId: container_1375740621345_0002_01_000002, NodeId: hadoop-100-4:50425, NodeHttpAddress: hadoop-100-4:8042, Resource: <memory:1024, vCores:1>, Priority: 20, State: NEW, Token: null, Status: container_id {, app_attempt_id {, application_id {, id: 2, cluster_timestamp: 1375740621345, }, attemptId: 1, }, id: 2, }, state: C_COMPLETE, diagnostics: "Container killed by the ApplicationMaster.\n\n", exit_status: 143, ] resource=<memory:1024, vCores:1> queue=default: capacity=1.0, absoluteCapacity=1.0, usedResources=<memory:2048, vCores:1>usedCapacity=0.041666668, absoluteUsedCapacity=0.041666668, numApps=1, numContainers=1 usedCapacity=0.041666668 absoluteUsedCapacity=0.041666668 used=<memory:2048, vCores:1> cluster=<memory:49152, vCores:96>
2013-08-05 22:15:01,790 INFO org.apache.hadoop.yarn.server.resourcemanager.scheduler.capacity.ParentQueue: completedContainer queue=root usedCapacity=0.041666668 absoluteUsedCapacity=0.041666668 used=<memory:2048, vCores:1> cluster=<memory:49152, vCores:96>
2013-08-05 22:15:01,790 INFO org.apache.hadoop.yarn.server.resourcemanager.scheduler.capacity.CapacityScheduler: Application appattempt_1375740621345_0002_000001 released container container_1375740621345_0002_01_000002 on node: host: hadoop-100-4:50425 #containers=0 available=8192 used=0 with event: FINISHED
2013-08-05 22:15:05,942 INFO org.apache.hadoop.yarn.server.resourcemanager.rmapp.attempt.RMAppAttemptImpl: appattempt_1375740621345_0002_000001 State change from RUNNING to FINISHING
2013-08-05 22:15:05,943 INFO org.apache.hadoop.yarn.server.resourcemanager.rmapp.RMAppImpl: application_1375740621345_0002 State change from RUNNING to FINISHING
2013-08-05 22:15:06,820 INFO org.apache.hadoop.yarn.server.resourcemanager.rmcontainer.RMContainerImpl: container_1375740621345_0002_01_000001 Container Transitioned from RUNNING to COMPLETED
2013-08-05 22:15:06,820 INFO org.apache.hadoop.yarn.server.resourcemanager.scheduler.common.fica.FiCaSchedulerApp: Completed container: container_1375740621345_0002_01_000001 in state: COMPLETED event:FINISHED
2013-08-05 22:15:06,820 INFO org.apache.hadoop.yarn.server.resourcemanager.rmapp.attempt.RMAppAttemptImpl: appattempt_1375740621345_0002_000001 State change from FINISHING to FINISHED
2013-08-05 22:15:06,820 INFO org.apache.hadoop.yarn.server.resourcemanager.RMAuditLogger: USER=ubuntu	OPERATION=AM Released Container	TARGET=SchedulerApp	RESULT=SUCCESS	APPID=application_1375740621345_0002	CONTAINERID=container_1375740621345_0002_01_000001
2013-08-05 22:15:06,821 INFO org.apache.hadoop.yarn.server.resourcemanager.scheduler.common.fica.FiCaSchedulerNode: Released container container_1375740621345_0002_01_000001 of capacity <memory:2048, vCores:1> on host hadoop-100-3:44102, which currently has 0 containers, <memory:0, vCores:0> used and <memory:8192, vCores:16> available, release resources=true
2013-08-05 22:15:06,821 INFO org.apache.hadoop.yarn.server.resourcemanager.rmapp.RMAppImpl: application_1375740621345_0002 State change from FINISHING to FINISHED
2013-08-05 22:15:06,821 INFO org.apache.hadoop.yarn.server.resourcemanager.scheduler.capacity.LeafQueue: default used=<memory:0, vCores:0> numContainers=0 user=ubuntu user-resources=<memory:0, vCores:0>
2013-08-05 22:15:06,821 INFO org.apache.hadoop.yarn.server.resourcemanager.RMAuditLogger: USER=ubuntu	OPERATION=Application Finished - Succeeded	TARGET=RMAppManager	RESULT=SUCCESS	APPID=application_1375740621345_0002
2013-08-05 22:15:06,822 INFO org.apache.hadoop.yarn.server.resourcemanager.recovery.RMStateStore: Removing info for app: application_1375740621345_0002
2013-08-05 22:15:06,822 INFO org.apache.hadoop.yarn.server.resourcemanager.RMAppManager$ApplicationSummary: appId=application_1375740621345_0002,name=TeraGen,user=ubuntu,queue=default,state=FINISHED,trackingUrl=hadoop-100-1.novalocal:8088/proxy/application_1375740621345_0002/jobhistory/job/job_1375740621345_0002,appMasterHost=hadoop-100-3,startTime=1375740779373,finishTime=1375740905943
2013-08-05 22:15:06,822 INFO org.apache.hadoop.yarn.server.resourcemanager.amlauncher.AMLauncher: Cleaning master appattempt_1375740621345_0002_000001
2013-08-05 22:15:06,823 INFO org.apache.hadoop.yarn.server.resourcemanager.scheduler.capacity.LeafQueue: completedContainer container=Container: [ContainerId: container_1375740621345_0002_01_000001, NodeId: hadoop-100-3:44102, NodeHttpAddress: hadoop-100-3:8042, Resource: <memory:2048, vCores:1>, Priority: 0, State: NEW, Token: null, Status: container_id {, app_attempt_id {, application_id {, id: 2, cluster_timestamp: 1375740621345, }, attemptId: 1, }, id: 1, }, state: C_COMPLETE, diagnostics: "", exit_status: 0, ] resource=<memory:2048, vCores:1> queue=default: capacity=1.0, absoluteCapacity=1.0, usedResources=<memory:0, vCores:0>usedCapacity=0.0, absoluteUsedCapacity=0.0, numApps=1, numContainers=0 usedCapacity=0.0 absoluteUsedCapacity=0.0 used=<memory:0, vCores:0> cluster=<memory:49152, vCores:96>
2013-08-05 22:15:06,823 INFO org.apache.hadoop.yarn.server.resourcemanager.scheduler.capacity.ParentQueue: completedContainer queue=root usedCapacity=0.0 absoluteUsedCapacity=0.0 used=<memory:0, vCores:0> cluster=<memory:49152, vCores:96>
2013-08-05 22:15:06,823 INFO org.apache.hadoop.yarn.server.resourcemanager.scheduler.capacity.CapacityScheduler: Application appattempt_1375740621345_0002_000001 released container container_1375740621345_0002_01_000001 on node: host: hadoop-100-3:44102 #containers=0 available=8192 used=0 with event: FINISHED
2013-08-05 22:15:06,823 INFO org.apache.hadoop.yarn.server.resourcemanager.scheduler.capacity.CapacityScheduler: Application appattempt_1375740621345_0002_000001 is done. finalState=FINISHED
2013-08-05 22:15:06,824 INFO org.apache.hadoop.yarn.server.resourcemanager.scheduler.AppSchedulingInfo: Application application_1375740621345_0002 requests cleared
2013-08-05 22:15:06,824 INFO org.apache.hadoop.yarn.server.resourcemanager.scheduler.capacity.LeafQueue: Application removed - appId: application_1375740621345_0002 user: ubuntu queue: default #user-pending-applications: 0 #user-active-applications: 0 #queue-pending-applications: 0 #queue-active-applications: 0
2013-08-05 22:15:06,824 INFO org.apache.hadoop.yarn.server.resourcemanager.scheduler.capacity.ParentQueue: Application removed - appId: application_1375740621345_0002 user: ubuntu leaf-queue of parent: root #applications: 0
2013-08-05 22:15:07,686 INFO org.apache.hadoop.yarn.server.resourcemanager.ClientRMService: Allocated new applicationId: 3
2013-08-05 22:15:09,646 INFO org.apache.hadoop.yarn.server.resourcemanager.ClientRMService: Storing Application with id application_1375740621345_0003
2013-08-05 22:15:09,646 INFO org.apache.hadoop.yarn.server.resourcemanager.recovery.RMStateStore: Storing info for app: application_1375740621345_0003
2013-08-05 22:15:09,646 INFO org.apache.hadoop.yarn.server.resourcemanager.ClientRMService: Application with id 3 submitted by user ubuntu
2013-08-05 22:15:09,646 INFO org.apache.hadoop.yarn.server.resourcemanager.RMAuditLogger: USER=ubuntu	IP=192.168.100.3	OPERATION=Submit Application Request	TARGET=ClientRMService	RESULT=SUCCESS	APPID=application_1375740621345_0003
2013-08-05 22:15:09,648 INFO org.apache.hadoop.yarn.server.resourcemanager.rmapp.RMAppImpl: application_1375740621345_0003 State change from NEW to SUBMITTED
2013-08-05 22:15:09,649 INFO org.apache.hadoop.yarn.server.resourcemanager.ApplicationMasterService: Registering appattempt_1375740621345_0003_000001
2013-08-05 22:15:09,649 INFO org.apache.hadoop.yarn.server.resourcemanager.rmapp.attempt.RMAppAttemptImpl: appattempt_1375740621345_0003_000001 State change from NEW to SUBMITTED
2013-08-05 22:15:09,650 INFO org.apache.hadoop.yarn.server.resourcemanager.scheduler.capacity.LeafQueue: Application application_1375740621345_0003 from user: ubuntu activated in queue: default
2013-08-05 22:15:09,650 INFO org.apache.hadoop.yarn.server.resourcemanager.scheduler.capacity.LeafQueue: Application added - appId: application_1375740621345_0003 user: org.apache.hadoop.yarn.server.resourcemanager.scheduler.capacity.LeafQueue$User@6e24617a, leaf-queue: default #user-pending-applications: 0 #user-active-applications: 1 #queue-pending-applications: 0 #queue-active-applications: 1
2013-08-05 22:15:09,650 INFO org.apache.hadoop.yarn.server.resourcemanager.scheduler.capacity.ParentQueue: Application added - appId: application_1375740621345_0003 user: ubuntu leaf-queue of parent: root #applications: 1
2013-08-05 22:15:09,650 INFO org.apache.hadoop.yarn.server.resourcemanager.scheduler.capacity.CapacityScheduler: Application Submission: appattempt_1375740621345_0003_000001, user: ubuntu queue: default: capacity=1.0, absoluteCapacity=1.0, usedResources=<memory:0, vCores:0>usedCapacity=0.0, absoluteUsedCapacity=0.0, numApps=1, numContainers=0, currently active: 1
2013-08-05 22:15:09,652 INFO org.apache.hadoop.yarn.server.resourcemanager.rmapp.attempt.RMAppAttemptImpl: appattempt_1375740621345_0003_000001 State change from SUBMITTED to SCHEDULED
2013-08-05 22:15:09,652 INFO org.apache.hadoop.yarn.server.resourcemanager.rmapp.RMAppImpl: application_1375740621345_0003 State change from SUBMITTED to ACCEPTED
2013-08-05 22:15:09,819 INFO org.apache.hadoop.yarn.server.resourcemanager.rmcontainer.RMContainerImpl: container_1375740621345_0003_01_000001 Container Transitioned from NEW to ALLOCATED
2013-08-05 22:15:09,819 INFO org.apache.hadoop.yarn.server.resourcemanager.RMAuditLogger: USER=ubuntu	OPERATION=AM Allocated Container	TARGET=SchedulerApp	RESULT=SUCCESS	APPID=application_1375740621345_0003	CONTAINERID=container_1375740621345_0003_01_000001
2013-08-05 22:15:09,820 INFO org.apache.hadoop.yarn.server.resourcemanager.scheduler.common.fica.FiCaSchedulerNode: Assigned container container_1375740621345_0003_01_000001 of capacity <memory:2048, vCores:1> on host hadoop-100-4:50425, which currently has 1 containers, <memory:2048, vCores:1> used and <memory:6144, vCores:15> available
2013-08-05 22:15:09,821 INFO org.apache.hadoop.yarn.server.resourcemanager.scheduler.capacity.LeafQueue: assignedContainer application=application_1375740621345_0003 container=Container: [ContainerId: container_1375740621345_0003_01_000001, NodeId: hadoop-100-4:50425, NodeHttpAddress: hadoop-100-4:8042, Resource: <memory:2048, vCores:1>, Priority: 0, State: NEW, Token: null, Status: container_id {, app_attempt_id {, application_id {, id: 3, cluster_timestamp: 1375740621345, }, attemptId: 1, }, id: 1, }, state: C_NEW, ] containerId=container_1375740621345_0003_01_000001 queue=default: capacity=1.0, absoluteCapacity=1.0, usedResources=<memory:0, vCores:0>usedCapacity=0.0, absoluteUsedCapacity=0.0, numApps=1, numContainers=0 usedCapacity=0.0 absoluteUsedCapacity=0.0 used=<memory:0, vCores:0> cluster=<memory:49152, vCores:96>
2013-08-05 22:15:09,822 INFO org.apache.hadoop.yarn.server.resourcemanager.scheduler.capacity.ParentQueue: Re-sorting queues since queue: root.default stats: default: capacity=1.0, absoluteCapacity=1.0, usedResources=<memory:2048, vCores:1>usedCapacity=0.041666668, absoluteUsedCapacity=0.041666668, numApps=1, numContainers=1
2013-08-05 22:15:09,823 INFO org.apache.hadoop.yarn.server.resourcemanager.rmcontainer.RMContainerImpl: container_1375740621345_0003_01_000001 Container Transitioned from ALLOCATED to ACQUIRED
2013-08-05 22:15:09,823 INFO org.apache.hadoop.yarn.server.resourcemanager.scheduler.capacity.ParentQueue: assignedContainer queue=root usedCapacity=0.041666668 absoluteUsedCapacity=0.041666668 used=<memory:2048, vCores:1> cluster=<memory:49152, vCores:96>
2013-08-05 22:15:09,824 INFO org.apache.hadoop.yarn.server.resourcemanager.rmapp.attempt.RMAppAttemptImpl: Storing attempt: AppId: application_1375740621345_0003 AttemptId: appattempt_1375740621345_0003_000001 MasterContainer: Container: [ContainerId: container_1375740621345_0003_01_000001, NodeId: hadoop-100-4:50425, NodeHttpAddress: hadoop-100-4:8042, Resource: <memory:2048, vCores:1>, Priority: 0, State: NEW, Token: null, Status: container_id {, app_attempt_id {, application_id {, id: 3, cluster_timestamp: 1375740621345, }, attemptId: 1, }, id: 1, }, state: C_NEW, ]
2013-08-05 22:15:09,825 INFO org.apache.hadoop.yarn.server.resourcemanager.recovery.RMStateStore: Storing info for attempt: appattempt_1375740621345_0003_000001
2013-08-05 22:15:09,825 INFO org.apache.hadoop.yarn.server.resourcemanager.rmapp.attempt.RMAppAttemptImpl: appattempt_1375740621345_0003_000001 State change from SCHEDULED to ALLOCATED_SAVING
2013-08-05 22:15:09,826 INFO org.apache.hadoop.yarn.server.resourcemanager.rmapp.attempt.RMAppAttemptImpl: appattempt_1375740621345_0003_000001 State change from ALLOCATED_SAVING to ALLOCATED
2013-08-05 22:15:09,827 INFO org.apache.hadoop.yarn.server.resourcemanager.amlauncher.AMLauncher: Launching masterappattempt_1375740621345_0003_000001
2013-08-05 22:15:09,830 INFO org.apache.hadoop.yarn.server.resourcemanager.amlauncher.AMLauncher: Setting up container Container: [ContainerId: container_1375740621345_0003_01_000001, NodeId: hadoop-100-4:50425, NodeHttpAddress: hadoop-100-4:8042, Resource: <memory:2048, vCores:1>, Priority: 0, State: NEW, Token: null, Status: container_id {, app_attempt_id {, application_id {, id: 3, cluster_timestamp: 1375740621345, }, attemptId: 1, }, id: 1, }, state: C_NEW, ] for AM appattempt_1375740621345_0003_000001
2013-08-05 22:15:09,830 INFO org.apache.hadoop.yarn.server.resourcemanager.amlauncher.AMLauncher: Command to launch container container_1375740621345_0003_01_000001 : $JAVA_HOME/bin/java -Dlog4j.configuration=container-log4j.properties -Dyarn.app.mapreduce.container.log.dir=<LOG_DIR> -Dyarn.app.mapreduce.container.log.filesize=0 -Dhadoop.root.logger=INFO,CLA  -Xmx1024m org.apache.hadoop.mapreduce.v2.app.MRAppMaster 1><LOG_DIR>/stdout 2><LOG_DIR>/stderr 
2013-08-05 22:15:09,851 INFO org.apache.hadoop.yarn.server.resourcemanager.amlauncher.AMLauncher: Done launching container Container: [ContainerId: container_1375740621345_0003_01_000001, NodeId: hadoop-100-4:50425, NodeHttpAddress: hadoop-100-4:8042, Resource: <memory:2048, vCores:1>, Priority: 0, State: NEW, Token: null, Status: container_id {, app_attempt_id {, application_id {, id: 3, cluster_timestamp: 1375740621345, }, attemptId: 1, }, id: 1, }, state: C_NEW, ] for AM appattempt_1375740621345_0003_000001
2013-08-05 22:15:09,851 INFO org.apache.hadoop.yarn.server.resourcemanager.rmapp.attempt.RMAppAttemptImpl: appattempt_1375740621345_0003_000001 State change from ALLOCATED to LAUNCHED
2013-08-05 22:15:10,825 INFO org.apache.hadoop.yarn.server.resourcemanager.rmcontainer.RMContainerImpl: container_1375740621345_0003_01_000001 Container Transitioned from ACQUIRED to RUNNING
2013-08-05 22:15:17,408 INFO org.apache.hadoop.yarn.server.resourcemanager.ApplicationMasterService: AM registration appattempt_1375740621345_0003_000001
2013-08-05 22:15:17,409 INFO org.apache.hadoop.yarn.server.resourcemanager.RMAuditLogger: USER=ubuntu	IP=192.168.100.14	OPERATION=Register App Master	TARGET=ApplicationMasterService	RESULT=SUCCESS	APPID=application_1375740621345_0003	APPATTEMPTID=appattempt_1375740621345_0003_000001
2013-08-05 22:15:17,410 INFO org.apache.hadoop.yarn.server.resourcemanager.rmapp.attempt.RMAppAttemptImpl: appattempt_1375740621345_0003_000001 State change from LAUNCHED to RUNNING
2013-08-05 22:15:17,410 INFO org.apache.hadoop.yarn.server.resourcemanager.rmapp.RMAppImpl: application_1375740621345_0003 State change from ACCEPTED to RUNNING
2013-08-05 22:15:18,608 INFO org.apache.hadoop.yarn.server.resourcemanager.rmcontainer.RMContainerImpl: container_1375740621345_0003_01_000002 Container Transitioned from NEW to ALLOCATED
2013-08-05 22:15:18,608 INFO org.apache.hadoop.yarn.server.resourcemanager.RMAuditLogger: USER=ubuntu	OPERATION=AM Allocated Container	TARGET=SchedulerApp	RESULT=SUCCESS	APPID=application_1375740621345_0003	CONTAINERID=container_1375740621345_0003_01_000002
2013-08-05 22:15:18,609 INFO org.apache.hadoop.yarn.server.resourcemanager.scheduler.common.fica.FiCaSchedulerNode: Assigned container container_1375740621345_0003_01_000002 of capacity <memory:1024, vCores:1> on host hadoop-100-7:36057, which currently has 1 containers, <memory:1024, vCores:1> used and <memory:7168, vCores:15> available
2013-08-05 22:15:18,610 INFO org.apache.hadoop.yarn.server.resourcemanager.scheduler.capacity.LeafQueue: assignedContainer application=application_1375740621345_0003 container=Container: [ContainerId: container_1375740621345_0003_01_000002, NodeId: hadoop-100-7:36057, NodeHttpAddress: hadoop-100-7:8042, Resource: <memory:1024, vCores:1>, Priority: 20, State: NEW, Token: null, Status: container_id {, app_attempt_id {, application_id {, id: 3, cluster_timestamp: 1375740621345, }, attemptId: 1, }, id: 2, }, state: C_NEW, ] containerId=container_1375740621345_0003_01_000002 queue=default: capacity=1.0, absoluteCapacity=1.0, usedResources=<memory:2048, vCores:1>usedCapacity=0.041666668, absoluteUsedCapacity=0.041666668, numApps=1, numContainers=1 usedCapacity=0.041666668 absoluteUsedCapacity=0.041666668 used=<memory:2048, vCores:1> cluster=<memory:49152, vCores:96>
2013-08-05 22:15:18,611 INFO org.apache.hadoop.yarn.server.resourcemanager.scheduler.capacity.ParentQueue: Re-sorting queues since queue: root.default stats: default: capacity=1.0, absoluteCapacity=1.0, usedResources=<memory:3072, vCores:2>usedCapacity=0.0625, absoluteUsedCapacity=0.0625, numApps=1, numContainers=2
2013-08-05 22:15:18,611 INFO org.apache.hadoop.yarn.server.resourcemanager.scheduler.capacity.ParentQueue: assignedContainer queue=root usedCapacity=0.0625 absoluteUsedCapacity=0.0625 used=<memory:3072, vCores:2> cluster=<memory:49152, vCores:96>
2013-08-05 22:15:18,865 INFO org.apache.hadoop.yarn.server.resourcemanager.rmcontainer.RMContainerImpl: container_1375740621345_0003_01_000003 Container Transitioned from NEW to ALLOCATED
2013-08-05 22:15:18,865 INFO org.apache.hadoop.yarn.server.resourcemanager.RMAuditLogger: USER=ubuntu	OPERATION=AM Allocated Container	TARGET=SchedulerApp	RESULT=SUCCESS	APPID=application_1375740621345_0003	CONTAINERID=container_1375740621345_0003_01_000003
2013-08-05 22:15:18,866 INFO org.apache.hadoop.yarn.server.resourcemanager.scheduler.common.fica.FiCaSchedulerNode: Assigned container container_1375740621345_0003_01_000003 of capacity <memory:1024, vCores:1> on host hadoop-100-4:50425, which currently has 2 containers, <memory:3072, vCores:2> used and <memory:5120, vCores:14> available
2013-08-05 22:15:18,867 INFO org.apache.hadoop.yarn.server.resourcemanager.scheduler.capacity.LeafQueue: assignedContainer application=application_1375740621345_0003 container=Container: [ContainerId: container_1375740621345_0003_01_000003, NodeId: hadoop-100-4:50425, NodeHttpAddress: hadoop-100-4:8042, Resource: <memory:1024, vCores:1>, Priority: 20, State: NEW, Token: null, Status: container_id {, app_attempt_id {, application_id {, id: 3, cluster_timestamp: 1375740621345, }, attemptId: 1, }, id: 3, }, state: C_NEW, ] containerId=container_1375740621345_0003_01_000003 queue=default: capacity=1.0, absoluteCapacity=1.0, usedResources=<memory:3072, vCores:2>usedCapacity=0.0625, absoluteUsedCapacity=0.0625, numApps=1, numContainers=2 usedCapacity=0.0625 absoluteUsedCapacity=0.0625 used=<memory:3072, vCores:2> cluster=<memory:49152, vCores:96>
2013-08-05 22:15:18,868 INFO org.apache.hadoop.yarn.server.resourcemanager.scheduler.capacity.ParentQueue: Re-sorting queues since queue: root.default stats: default: capacity=1.0, absoluteCapacity=1.0, usedResources=<memory:4096, vCores:3>usedCapacity=0.083333336, absoluteUsedCapacity=0.083333336, numApps=1, numContainers=3
2013-08-05 22:15:18,868 INFO org.apache.hadoop.yarn.server.resourcemanager.scheduler.capacity.ParentQueue: assignedContainer queue=root usedCapacity=0.083333336 absoluteUsedCapacity=0.083333336 used=<memory:4096, vCores:3> cluster=<memory:49152, vCores:96>
2013-08-05 22:15:19,474 INFO org.apache.hadoop.yarn.server.resourcemanager.rmcontainer.RMContainerImpl: container_1375740621345_0003_01_000002 Container Transitioned from ALLOCATED to ACQUIRED
2013-08-05 22:15:19,475 INFO org.apache.hadoop.yarn.server.resourcemanager.rmcontainer.RMContainerImpl: container_1375740621345_0003_01_000003 Container Transitioned from ALLOCATED to ACQUIRED
2013-08-05 22:15:19,872 INFO org.apache.hadoop.yarn.server.resourcemanager.rmcontainer.RMContainerImpl: container_1375740621345_0003_01_000003 Container Transitioned from ACQUIRED to RUNNING
2013-08-05 22:15:20,506 INFO org.apache.hadoop.yarn.server.resourcemanager.scheduler.AppSchedulingInfo: checking for deactivate... 
2013-08-05 22:15:20,618 INFO org.apache.hadoop.yarn.server.resourcemanager.rmcontainer.RMContainerImpl: container_1375740621345_0003_01_000002 Container Transitioned from ACQUIRED to RUNNING
2013-08-05 22:17:08,116 INFO org.apache.hadoop.yarn.server.resourcemanager.rmcontainer.RMContainerImpl: container_1375740621345_0003_01_000003 Container Transitioned from RUNNING to COMPLETED
2013-08-05 22:17:08,116 INFO org.apache.hadoop.yarn.server.resourcemanager.scheduler.common.fica.FiCaSchedulerApp: Completed container: container_1375740621345_0003_01_000003 in state: COMPLETED event:FINISHED
2013-08-05 22:17:08,117 INFO org.apache.hadoop.yarn.server.resourcemanager.RMAuditLogger: USER=ubuntu	OPERATION=AM Released Container	TARGET=SchedulerApp	RESULT=SUCCESS	APPID=application_1375740621345_0003	CONTAINERID=container_1375740621345_0003_01_000003
2013-08-05 22:17:08,117 INFO org.apache.hadoop.yarn.server.resourcemanager.scheduler.common.fica.FiCaSchedulerNode: Released container container_1375740621345_0003_01_000003 of capacity <memory:1024, vCores:1> on host hadoop-100-4:50425, which currently has 1 containers, <memory:2048, vCores:1> used and <memory:6144, vCores:15> available, release resources=true
2013-08-05 22:17:08,117 INFO org.apache.hadoop.yarn.server.resourcemanager.scheduler.capacity.LeafQueue: default used=<memory:3072, vCores:2> numContainers=2 user=ubuntu user-resources=<memory:3072, vCores:2>
2013-08-05 22:17:08,119 INFO org.apache.hadoop.yarn.server.resourcemanager.scheduler.capacity.LeafQueue: completedContainer container=Container: [ContainerId: container_1375740621345_0003_01_000003, NodeId: hadoop-100-4:50425, NodeHttpAddress: hadoop-100-4:8042, Resource: <memory:1024, vCores:1>, Priority: 20, State: NEW, Token: null, Status: container_id {, app_attempt_id {, application_id {, id: 3, cluster_timestamp: 1375740621345, }, attemptId: 1, }, id: 3, }, state: C_COMPLETE, diagnostics: "Container killed by the ApplicationMaster.\n\n", exit_status: 143, ] resource=<memory:1024, vCores:1> queue=default: capacity=1.0, absoluteCapacity=1.0, usedResources=<memory:3072, vCores:2>usedCapacity=0.0625, absoluteUsedCapacity=0.0625, numApps=1, numContainers=2 usedCapacity=0.0625 absoluteUsedCapacity=0.0625 used=<memory:3072, vCores:2> cluster=<memory:49152, vCores:96>
2013-08-05 22:17:08,119 INFO org.apache.hadoop.yarn.server.resourcemanager.scheduler.capacity.ParentQueue: completedContainer queue=root usedCapacity=0.0625 absoluteUsedCapacity=0.0625 used=<memory:3072, vCores:2> cluster=<memory:49152, vCores:96>
2013-08-05 22:17:08,119 INFO org.apache.hadoop.yarn.server.resourcemanager.scheduler.capacity.CapacityScheduler: Application appattempt_1375740621345_0003_000001 released container container_1375740621345_0003_01_000003 on node: host: hadoop-100-4:50425 #containers=1 available=6144 used=2048 with event: FINISHED
2013-08-05 22:17:09,070 INFO org.apache.hadoop.yarn.server.resourcemanager.rmcontainer.RMContainerImpl: container_1375740621345_0003_01_000002 Container Transitioned from RUNNING to COMPLETED
2013-08-05 22:17:09,070 INFO org.apache.hadoop.yarn.server.resourcemanager.scheduler.common.fica.FiCaSchedulerApp: Completed container: container_1375740621345_0003_01_000002 in state: COMPLETED event:FINISHED
2013-08-05 22:17:09,070 INFO org.apache.hadoop.yarn.server.resourcemanager.RMAuditLogger: USER=ubuntu	OPERATION=AM Released Container	TARGET=SchedulerApp	RESULT=SUCCESS	APPID=application_1375740621345_0003	CONTAINERID=container_1375740621345_0003_01_000002
2013-08-05 22:17:09,070 INFO org.apache.hadoop.yarn.server.resourcemanager.scheduler.common.fica.FiCaSchedulerNode: Released container container_1375740621345_0003_01_000002 of capacity <memory:1024, vCores:1> on host hadoop-100-7:36057, which currently has 0 containers, <memory:0, vCores:0> used and <memory:8192, vCores:16> available, release resources=true
2013-08-05 22:17:09,070 INFO org.apache.hadoop.yarn.server.resourcemanager.scheduler.capacity.LeafQueue: default used=<memory:2048, vCores:1> numContainers=1 user=ubuntu user-resources=<memory:2048, vCores:1>
2013-08-05 22:17:09,072 INFO org.apache.hadoop.yarn.server.resourcemanager.scheduler.capacity.LeafQueue: completedContainer container=Container: [ContainerId: container_1375740621345_0003_01_000002, NodeId: hadoop-100-7:36057, NodeHttpAddress: hadoop-100-7:8042, Resource: <memory:1024, vCores:1>, Priority: 20, State: NEW, Token: null, Status: container_id {, app_attempt_id {, application_id {, id: 3, cluster_timestamp: 1375740621345, }, attemptId: 1, }, id: 2, }, state: C_COMPLETE, diagnostics: "Container killed by the ApplicationMaster.\n", exit_status: 0, ] resource=<memory:1024, vCores:1> queue=default: capacity=1.0, absoluteCapacity=1.0, usedResources=<memory:2048, vCores:1>usedCapacity=0.041666668, absoluteUsedCapacity=0.041666668, numApps=1, numContainers=1 usedCapacity=0.041666668 absoluteUsedCapacity=0.041666668 used=<memory:2048, vCores:1> cluster=<memory:49152, vCores:96>
2013-08-05 22:17:09,072 INFO org.apache.hadoop.yarn.server.resourcemanager.scheduler.capacity.ParentQueue: completedContainer queue=root usedCapacity=0.041666668 absoluteUsedCapacity=0.041666668 used=<memory:2048, vCores:1> cluster=<memory:49152, vCores:96>
2013-08-05 22:17:09,073 INFO org.apache.hadoop.yarn.server.resourcemanager.scheduler.capacity.CapacityScheduler: Application appattempt_1375740621345_0003_000001 released container container_1375740621345_0003_01_000002 on node: host: hadoop-100-7:36057 #containers=0 available=8192 used=0 with event: FINISHED
2013-08-05 22:17:13,251 INFO org.apache.hadoop.yarn.server.resourcemanager.rmapp.attempt.RMAppAttemptImpl: appattempt_1375740621345_0003_000001 State change from RUNNING to FINISHING
2013-08-05 22:17:13,252 INFO org.apache.hadoop.yarn.server.resourcemanager.rmapp.RMAppImpl: application_1375740621345_0003 State change from RUNNING to FINISHING
2013-08-05 22:17:14,146 INFO org.apache.hadoop.yarn.server.resourcemanager.rmcontainer.RMContainerImpl: container_1375740621345_0003_01_000001 Container Transitioned from RUNNING to COMPLETED
2013-08-05 22:17:14,146 INFO org.apache.hadoop.yarn.server.resourcemanager.scheduler.common.fica.FiCaSchedulerApp: Completed container: container_1375740621345_0003_01_000001 in state: COMPLETED event:FINISHED
2013-08-05 22:17:14,146 INFO org.apache.hadoop.yarn.server.resourcemanager.RMAuditLogger: USER=ubuntu	OPERATION=AM Released Container	TARGET=SchedulerApp	RESULT=SUCCESS	APPID=application_1375740621345_0003	CONTAINERID=container_1375740621345_0003_01_000001
2013-08-05 22:17:14,147 INFO org.apache.hadoop.yarn.server.resourcemanager.scheduler.common.fica.FiCaSchedulerNode: Released container container_1375740621345_0003_01_000001 of capacity <memory:2048, vCores:1> on host hadoop-100-4:50425, which currently has 0 containers, <memory:0, vCores:0> used and <memory:8192, vCores:16> available, release resources=true
2013-08-05 22:17:14,147 INFO org.apache.hadoop.yarn.server.resourcemanager.scheduler.capacity.LeafQueue: default used=<memory:0, vCores:0> numContainers=0 user=ubuntu user-resources=<memory:0, vCores:0>
2013-08-05 22:17:14,148 INFO org.apache.hadoop.yarn.server.resourcemanager.rmapp.attempt.RMAppAttemptImpl: appattempt_1375740621345_0003_000001 State change from FINISHING to FINISHED
2013-08-05 22:17:14,148 INFO org.apache.hadoop.yarn.server.resourcemanager.rmapp.RMAppImpl: application_1375740621345_0003 State change from FINISHING to FINISHED
2013-08-05 22:17:14,148 INFO org.apache.hadoop.yarn.server.resourcemanager.RMAuditLogger: USER=ubuntu	OPERATION=Application Finished - Succeeded	TARGET=RMAppManager	RESULT=SUCCESS	APPID=application_1375740621345_0003
2013-08-05 22:17:14,149 INFO org.apache.hadoop.yarn.server.resourcemanager.recovery.RMStateStore: Removing info for app: application_1375740621345_0003
2013-08-05 22:17:14,149 INFO org.apache.hadoop.yarn.server.resourcemanager.RMAppManager$ApplicationSummary: appId=application_1375740621345_0003,name=TeraGen,user=ubuntu,queue=default,state=FINISHED,trackingUrl=hadoop-100-1.novalocal:8088/proxy/application_1375740621345_0003/jobhistory/job/job_1375740621345_0003,appMasterHost=hadoop-100-4,startTime=1375740909645,finishTime=1375741033252
2013-08-05 22:17:14,149 INFO org.apache.hadoop.yarn.server.resourcemanager.scheduler.capacity.LeafQueue: completedContainer container=Container: [ContainerId: container_1375740621345_0003_01_000001, NodeId: hadoop-100-4:50425, NodeHttpAddress: hadoop-100-4:8042, Resource: <memory:2048, vCores:1>, Priority: 0, State: NEW, Token: null, Status: container_id {, app_attempt_id {, application_id {, id: 3, cluster_timestamp: 1375740621345, }, attemptId: 1, }, id: 1, }, state: C_COMPLETE, diagnostics: "", exit_status: 0, ] resource=<memory:2048, vCores:1> queue=default: capacity=1.0, absoluteCapacity=1.0, usedResources=<memory:0, vCores:0>usedCapacity=0.0, absoluteUsedCapacity=0.0, numApps=1, numContainers=0 usedCapacity=0.0 absoluteUsedCapacity=0.0 used=<memory:0, vCores:0> cluster=<memory:49152, vCores:96>
2013-08-05 22:17:14,149 INFO org.apache.hadoop.yarn.server.resourcemanager.scheduler.capacity.ParentQueue: completedContainer queue=root usedCapacity=0.0 absoluteUsedCapacity=0.0 used=<memory:0, vCores:0> cluster=<memory:49152, vCores:96>
2013-08-05 22:17:14,150 INFO org.apache.hadoop.yarn.server.resourcemanager.scheduler.capacity.CapacityScheduler: Application appattempt_1375740621345_0003_000001 released container container_1375740621345_0003_01_000001 on node: host: hadoop-100-4:50425 #containers=0 available=8192 used=0 with event: FINISHED
2013-08-05 22:17:14,150 INFO org.apache.hadoop.yarn.server.resourcemanager.amlauncher.AMLauncher: Cleaning master appattempt_1375740621345_0003_000001
2013-08-05 22:17:14,162 INFO org.apache.hadoop.yarn.server.resourcemanager.scheduler.capacity.CapacityScheduler: Application appattempt_1375740621345_0003_000001 is done. finalState=FINISHED
2013-08-05 22:17:14,162 INFO org.apache.hadoop.yarn.server.resourcemanager.scheduler.AppSchedulingInfo: Application application_1375740621345_0003 requests cleared
2013-08-05 22:17:14,162 INFO org.apache.hadoop.yarn.server.resourcemanager.scheduler.capacity.LeafQueue: Application removed - appId: application_1375740621345_0003 user: ubuntu queue: default #user-pending-applications: 0 #user-active-applications: 0 #queue-pending-applications: 0 #queue-active-applications: 0
2013-08-05 22:17:14,162 INFO org.apache.hadoop.yarn.server.resourcemanager.scheduler.capacity.ParentQueue: Application removed - appId: application_1375740621345_0003 user: ubuntu leaf-queue of parent: root #applications: 0
2013-08-05 22:17:14,275 INFO org.apache.hadoop.yarn.server.resourcemanager.ClientRMService: Allocated new applicationId: 4
2013-08-05 22:17:16,157 INFO org.apache.hadoop.yarn.server.resourcemanager.ClientRMService: Storing Application with id application_1375740621345_0004
2013-08-05 22:17:16,157 INFO org.apache.hadoop.yarn.server.resourcemanager.recovery.RMStateStore: Storing info for app: application_1375740621345_0004
2013-08-05 22:17:16,158 INFO org.apache.hadoop.yarn.server.resourcemanager.ClientRMService: Application with id 4 submitted by user ubuntu
2013-08-05 22:17:16,158 INFO org.apache.hadoop.yarn.server.resourcemanager.RMAuditLogger: USER=ubuntu	IP=192.168.100.3	OPERATION=Submit Application Request	TARGET=ClientRMService	RESULT=SUCCESS	APPID=application_1375740621345_0004
2013-08-05 22:17:16,159 INFO org.apache.hadoop.yarn.server.resourcemanager.rmapp.RMAppImpl: application_1375740621345_0004 State change from NEW to SUBMITTED
2013-08-05 22:17:16,159 INFO org.apache.hadoop.yarn.server.resourcemanager.ApplicationMasterService: Registering appattempt_1375740621345_0004_000001
2013-08-05 22:17:16,160 INFO org.apache.hadoop.yarn.server.resourcemanager.rmapp.attempt.RMAppAttemptImpl: appattempt_1375740621345_0004_000001 State change from NEW to SUBMITTED
2013-08-05 22:17:16,160 INFO org.apache.hadoop.yarn.server.resourcemanager.scheduler.capacity.LeafQueue: Application application_1375740621345_0004 from user: ubuntu activated in queue: default
2013-08-05 22:17:16,160 INFO org.apache.hadoop.yarn.server.resourcemanager.scheduler.capacity.LeafQueue: Application added - appId: application_1375740621345_0004 user: org.apache.hadoop.yarn.server.resourcemanager.scheduler.capacity.LeafQueue$User@38054f37, leaf-queue: default #user-pending-applications: 0 #user-active-applications: 1 #queue-pending-applications: 0 #queue-active-applications: 1
2013-08-05 22:17:16,160 INFO org.apache.hadoop.yarn.server.resourcemanager.scheduler.capacity.ParentQueue: Application added - appId: application_1375740621345_0004 user: ubuntu leaf-queue of parent: root #applications: 1
2013-08-05 22:17:16,161 INFO org.apache.hadoop.yarn.server.resourcemanager.scheduler.capacity.CapacityScheduler: Application Submission: appattempt_1375740621345_0004_000001, user: ubuntu queue: default: capacity=1.0, absoluteCapacity=1.0, usedResources=<memory:0, vCores:0>usedCapacity=0.0, absoluteUsedCapacity=0.0, numApps=1, numContainers=0, currently active: 1
2013-08-05 22:17:16,161 INFO org.apache.hadoop.yarn.server.resourcemanager.rmapp.attempt.RMAppAttemptImpl: appattempt_1375740621345_0004_000001 State change from SUBMITTED to SCHEDULED
2013-08-05 22:17:16,161 INFO org.apache.hadoop.yarn.server.resourcemanager.rmapp.RMAppImpl: application_1375740621345_0004 State change from SUBMITTED to ACCEPTED
2013-08-05 22:17:16,304 INFO org.apache.hadoop.yarn.server.resourcemanager.rmcontainer.RMContainerImpl: container_1375740621345_0004_01_000001 Container Transitioned from NEW to ALLOCATED
2013-08-05 22:17:16,304 INFO org.apache.hadoop.yarn.server.resourcemanager.RMAuditLogger: USER=ubuntu	OPERATION=AM Allocated Container	TARGET=SchedulerApp	RESULT=SUCCESS	APPID=application_1375740621345_0004	CONTAINERID=container_1375740621345_0004_01_000001
2013-08-05 22:17:16,304 INFO org.apache.hadoop.yarn.server.resourcemanager.scheduler.common.fica.FiCaSchedulerNode: Assigned container container_1375740621345_0004_01_000001 of capacity <memory:2048, vCores:1> on host hadoop-100-3:44102, which currently has 1 containers, <memory:2048, vCores:1> used and <memory:6144, vCores:15> available
2013-08-05 22:17:16,306 INFO org.apache.hadoop.yarn.server.resourcemanager.scheduler.capacity.LeafQueue: assignedContainer application=application_1375740621345_0004 container=Container: [ContainerId: container_1375740621345_0004_01_000001, NodeId: hadoop-100-3:44102, NodeHttpAddress: hadoop-100-3:8042, Resource: <memory:2048, vCores:1>, Priority: 0, State: NEW, Token: null, Status: container_id {, app_attempt_id {, application_id {, id: 4, cluster_timestamp: 1375740621345, }, attemptId: 1, }, id: 1, }, state: C_NEW, ] containerId=container_1375740621345_0004_01_000001 queue=default: capacity=1.0, absoluteCapacity=1.0, usedResources=<memory:0, vCores:0>usedCapacity=0.0, absoluteUsedCapacity=0.0, numApps=1, numContainers=0 usedCapacity=0.0 absoluteUsedCapacity=0.0 used=<memory:0, vCores:0> cluster=<memory:49152, vCores:96>
2013-08-05 22:17:16,306 INFO org.apache.hadoop.yarn.server.resourcemanager.scheduler.capacity.ParentQueue: Re-sorting queues since queue: root.default stats: default: capacity=1.0, absoluteCapacity=1.0, usedResources=<memory:2048, vCores:1>usedCapacity=0.041666668, absoluteUsedCapacity=0.041666668, numApps=1, numContainers=1
2013-08-05 22:17:16,306 INFO org.apache.hadoop.yarn.server.resourcemanager.scheduler.capacity.ParentQueue: assignedContainer queue=root usedCapacity=0.041666668 absoluteUsedCapacity=0.041666668 used=<memory:2048, vCores:1> cluster=<memory:49152, vCores:96>
2013-08-05 22:17:16,309 INFO org.apache.hadoop.yarn.server.resourcemanager.rmcontainer.RMContainerImpl: container_1375740621345_0004_01_000001 Container Transitioned from ALLOCATED to ACQUIRED
2013-08-05 22:17:16,311 INFO org.apache.hadoop.yarn.server.resourcemanager.rmapp.attempt.RMAppAttemptImpl: Storing attempt: AppId: application_1375740621345_0004 AttemptId: appattempt_1375740621345_0004_000001 MasterContainer: Container: [ContainerId: container_1375740621345_0004_01_000001, NodeId: hadoop-100-3:44102, NodeHttpAddress: hadoop-100-3:8042, Resource: <memory:2048, vCores:1>, Priority: 0, State: NEW, Token: null, Status: container_id {, app_attempt_id {, application_id {, id: 4, cluster_timestamp: 1375740621345, }, attemptId: 1, }, id: 1, }, state: C_NEW, ]
2013-08-05 22:17:16,312 INFO org.apache.hadoop.yarn.server.resourcemanager.rmapp.attempt.RMAppAttemptImpl: appattempt_1375740621345_0004_000001 State change from SCHEDULED to ALLOCATED_SAVING
2013-08-05 22:17:16,312 INFO org.apache.hadoop.yarn.server.resourcemanager.recovery.RMStateStore: Storing info for attempt: appattempt_1375740621345_0004_000001
2013-08-05 22:17:16,314 INFO org.apache.hadoop.yarn.server.resourcemanager.rmapp.attempt.RMAppAttemptImpl: appattempt_1375740621345_0004_000001 State change from ALLOCATED_SAVING to ALLOCATED
2013-08-05 22:17:16,316 INFO org.apache.hadoop.yarn.server.resourcemanager.amlauncher.AMLauncher: Launching masterappattempt_1375740621345_0004_000001
2013-08-05 22:17:16,318 INFO org.apache.hadoop.yarn.server.resourcemanager.amlauncher.AMLauncher: Setting up container Container: [ContainerId: container_1375740621345_0004_01_000001, NodeId: hadoop-100-3:44102, NodeHttpAddress: hadoop-100-3:8042, Resource: <memory:2048, vCores:1>, Priority: 0, State: NEW, Token: null, Status: container_id {, app_attempt_id {, application_id {, id: 4, cluster_timestamp: 1375740621345, }, attemptId: 1, }, id: 1, }, state: C_NEW, ] for AM appattempt_1375740621345_0004_000001
2013-08-05 22:17:16,319 INFO org.apache.hadoop.yarn.server.resourcemanager.amlauncher.AMLauncher: Command to launch container container_1375740621345_0004_01_000001 : $JAVA_HOME/bin/java -Dlog4j.configuration=container-log4j.properties -Dyarn.app.mapreduce.container.log.dir=<LOG_DIR> -Dyarn.app.mapreduce.container.log.filesize=0 -Dhadoop.root.logger=INFO,CLA  -Xmx1024m org.apache.hadoop.mapreduce.v2.app.MRAppMaster 1><LOG_DIR>/stdout 2><LOG_DIR>/stderr 
2013-08-05 22:17:16,338 INFO org.apache.hadoop.yarn.server.resourcemanager.amlauncher.AMLauncher: Done launching container Container: [ContainerId: container_1375740621345_0004_01_000001, NodeId: hadoop-100-3:44102, NodeHttpAddress: hadoop-100-3:8042, Resource: <memory:2048, vCores:1>, Priority: 0, State: NEW, Token: null, Status: container_id {, app_attempt_id {, application_id {, id: 4, cluster_timestamp: 1375740621345, }, attemptId: 1, }, id: 1, }, state: C_NEW, ] for AM appattempt_1375740621345_0004_000001
2013-08-05 22:17:16,338 INFO org.apache.hadoop.yarn.server.resourcemanager.rmapp.attempt.RMAppAttemptImpl: appattempt_1375740621345_0004_000001 State change from ALLOCATED to LAUNCHED
2013-08-05 22:17:17,309 INFO org.apache.hadoop.yarn.server.resourcemanager.rmcontainer.RMContainerImpl: container_1375740621345_0004_01_000001 Container Transitioned from ACQUIRED to RUNNING
2013-08-05 22:17:21,850 INFO org.apache.hadoop.yarn.server.resourcemanager.ApplicationMasterService: AM registration appattempt_1375740621345_0004_000001
2013-08-05 22:17:21,850 INFO org.apache.hadoop.yarn.server.resourcemanager.RMAuditLogger: USER=ubuntu	IP=192.168.100.13	OPERATION=Register App Master	TARGET=ApplicationMasterService	RESULT=SUCCESS	APPID=application_1375740621345_0004	APPATTEMPTID=appattempt_1375740621345_0004_000001
2013-08-05 22:17:21,852 INFO org.apache.hadoop.yarn.server.resourcemanager.rmapp.attempt.RMAppAttemptImpl: appattempt_1375740621345_0004_000001 State change from LAUNCHED to RUNNING
2013-08-05 22:17:21,852 INFO org.apache.hadoop.yarn.server.resourcemanager.rmapp.RMAppImpl: application_1375740621345_0004 State change from ACCEPTED to RUNNING
2013-08-05 22:17:22,925 INFO org.apache.hadoop.yarn.server.resourcemanager.rmcontainer.RMContainerImpl: container_1375740621345_0004_01_000002 Container Transitioned from NEW to ALLOCATED
2013-08-05 22:17:22,925 INFO org.apache.hadoop.yarn.server.resourcemanager.RMAuditLogger: USER=ubuntu	OPERATION=AM Allocated Container	TARGET=SchedulerApp	RESULT=SUCCESS	APPID=application_1375740621345_0004	CONTAINERID=container_1375740621345_0004_01_000002
2013-08-05 22:17:22,925 INFO org.apache.hadoop.yarn.server.resourcemanager.scheduler.common.fica.FiCaSchedulerNode: Assigned container container_1375740621345_0004_01_000002 of capacity <memory:1024, vCores:1> on host hadoop-100-6:42294, which currently has 1 containers, <memory:1024, vCores:1> used and <memory:7168, vCores:15> available
2013-08-05 22:17:22,927 INFO org.apache.hadoop.yarn.server.resourcemanager.scheduler.capacity.LeafQueue: assignedContainer application=application_1375740621345_0004 container=Container: [ContainerId: container_1375740621345_0004_01_000002, NodeId: hadoop-100-6:42294, NodeHttpAddress: hadoop-100-6:8042, Resource: <memory:1024, vCores:1>, Priority: 20, State: NEW, Token: null, Status: container_id {, app_attempt_id {, application_id {, id: 4, cluster_timestamp: 1375740621345, }, attemptId: 1, }, id: 2, }, state: C_NEW, ] containerId=container_1375740621345_0004_01_000002 queue=default: capacity=1.0, absoluteCapacity=1.0, usedResources=<memory:2048, vCores:1>usedCapacity=0.041666668, absoluteUsedCapacity=0.041666668, numApps=1, numContainers=1 usedCapacity=0.041666668 absoluteUsedCapacity=0.041666668 used=<memory:2048, vCores:1> cluster=<memory:49152, vCores:96>
2013-08-05 22:17:22,927 INFO org.apache.hadoop.yarn.server.resourcemanager.scheduler.capacity.ParentQueue: Re-sorting queues since queue: root.default stats: default: capacity=1.0, absoluteCapacity=1.0, usedResources=<memory:3072, vCores:2>usedCapacity=0.0625, absoluteUsedCapacity=0.0625, numApps=1, numContainers=2
2013-08-05 22:17:22,927 INFO org.apache.hadoop.yarn.server.resourcemanager.scheduler.capacity.ParentQueue: assignedContainer queue=root usedCapacity=0.0625 absoluteUsedCapacity=0.0625 used=<memory:3072, vCores:2> cluster=<memory:49152, vCores:96>
2013-08-05 22:17:23,114 INFO org.apache.hadoop.yarn.server.resourcemanager.rmcontainer.RMContainerImpl: container_1375740621345_0004_01_000003 Container Transitioned from NEW to ALLOCATED
2013-08-05 22:17:23,114 INFO org.apache.hadoop.yarn.server.resourcemanager.RMAuditLogger: USER=ubuntu	OPERATION=AM Allocated Container	TARGET=SchedulerApp	RESULT=SUCCESS	APPID=application_1375740621345_0004	CONTAINERID=container_1375740621345_0004_01_000003
2013-08-05 22:17:23,114 INFO org.apache.hadoop.yarn.server.resourcemanager.scheduler.common.fica.FiCaSchedulerNode: Assigned container container_1375740621345_0004_01_000003 of capacity <memory:1024, vCores:1> on host hadoop-100-7:36057, which currently has 1 containers, <memory:1024, vCores:1> used and <memory:7168, vCores:15> available
2013-08-05 22:17:23,116 INFO org.apache.hadoop.yarn.server.resourcemanager.scheduler.capacity.LeafQueue: assignedContainer application=application_1375740621345_0004 container=Container: [ContainerId: container_1375740621345_0004_01_000003, NodeId: hadoop-100-7:36057, NodeHttpAddress: hadoop-100-7:8042, Resource: <memory:1024, vCores:1>, Priority: 20, State: NEW, Token: null, Status: container_id {, app_attempt_id {, application_id {, id: 4, cluster_timestamp: 1375740621345, }, attemptId: 1, }, id: 3, }, state: C_NEW, ] containerId=container_1375740621345_0004_01_000003 queue=default: capacity=1.0, absoluteCapacity=1.0, usedResources=<memory:3072, vCores:2>usedCapacity=0.0625, absoluteUsedCapacity=0.0625, numApps=1, numContainers=2 usedCapacity=0.0625 absoluteUsedCapacity=0.0625 used=<memory:3072, vCores:2> cluster=<memory:49152, vCores:96>
2013-08-05 22:17:23,116 INFO org.apache.hadoop.yarn.server.resourcemanager.scheduler.capacity.ParentQueue: Re-sorting queues since queue: root.default stats: default: capacity=1.0, absoluteCapacity=1.0, usedResources=<memory:4096, vCores:3>usedCapacity=0.083333336, absoluteUsedCapacity=0.083333336, numApps=1, numContainers=3
2013-08-05 22:17:23,116 INFO org.apache.hadoop.yarn.server.resourcemanager.scheduler.capacity.ParentQueue: assignedContainer queue=root usedCapacity=0.083333336 absoluteUsedCapacity=0.083333336 used=<memory:4096, vCores:3> cluster=<memory:49152, vCores:96>
2013-08-05 22:17:23,913 INFO org.apache.hadoop.yarn.server.resourcemanager.rmcontainer.RMContainerImpl: container_1375740621345_0004_01_000002 Container Transitioned from ALLOCATED to ACQUIRED
2013-08-05 22:17:23,915 INFO org.apache.hadoop.yarn.server.resourcemanager.rmcontainer.RMContainerImpl: container_1375740621345_0004_01_000003 Container Transitioned from ALLOCATED to ACQUIRED
2013-08-05 22:17:24,934 INFO org.apache.hadoop.yarn.server.resourcemanager.rmcontainer.RMContainerImpl: container_1375740621345_0004_01_000002 Container Transitioned from ACQUIRED to RUNNING
2013-08-05 22:17:24,948 INFO org.apache.hadoop.yarn.server.resourcemanager.scheduler.AppSchedulingInfo: checking for deactivate... 
2013-08-05 22:17:25,122 INFO org.apache.hadoop.yarn.server.resourcemanager.rmcontainer.RMContainerImpl: container_1375740621345_0004_01_000003 Container Transitioned from ACQUIRED to RUNNING
2013-08-05 22:19:14,879 INFO org.apache.hadoop.yarn.server.resourcemanager.rmcontainer.RMContainerImpl: container_1375740621345_0004_01_000002 Container Transitioned from RUNNING to COMPLETED
2013-08-05 22:19:14,879 INFO org.apache.hadoop.yarn.server.resourcemanager.scheduler.common.fica.FiCaSchedulerApp: Completed container: container_1375740621345_0004_01_000002 in state: COMPLETED event:FINISHED
2013-08-05 22:19:14,879 INFO org.apache.hadoop.yarn.server.resourcemanager.RMAuditLogger: USER=ubuntu	OPERATION=AM Released Container	TARGET=SchedulerApp	RESULT=SUCCESS	APPID=application_1375740621345_0004	CONTAINERID=container_1375740621345_0004_01_000002
2013-08-05 22:19:14,879 INFO org.apache.hadoop.yarn.server.resourcemanager.scheduler.common.fica.FiCaSchedulerNode: Released container container_1375740621345_0004_01_000002 of capacity <memory:1024, vCores:1> on host hadoop-100-6:42294, which currently has 0 containers, <memory:0, vCores:0> used and <memory:8192, vCores:16> available, release resources=true
2013-08-05 22:19:14,879 INFO org.apache.hadoop.yarn.server.resourcemanager.scheduler.capacity.LeafQueue: default used=<memory:3072, vCores:2> numContainers=2 user=ubuntu user-resources=<memory:3072, vCores:2>
2013-08-05 22:19:14,881 INFO org.apache.hadoop.yarn.server.resourcemanager.scheduler.capacity.LeafQueue: completedContainer container=Container: [ContainerId: container_1375740621345_0004_01_000002, NodeId: hadoop-100-6:42294, NodeHttpAddress: hadoop-100-6:8042, Resource: <memory:1024, vCores:1>, Priority: 20, State: NEW, Token: null, Status: container_id {, app_attempt_id {, application_id {, id: 4, cluster_timestamp: 1375740621345, }, attemptId: 1, }, id: 2, }, state: C_COMPLETE, diagnostics: "Container killed by the ApplicationMaster.\n\n", exit_status: 143, ] resource=<memory:1024, vCores:1> queue=default: capacity=1.0, absoluteCapacity=1.0, usedResources=<memory:3072, vCores:2>usedCapacity=0.0625, absoluteUsedCapacity=0.0625, numApps=1, numContainers=2 usedCapacity=0.0625 absoluteUsedCapacity=0.0625 used=<memory:3072, vCores:2> cluster=<memory:49152, vCores:96>
2013-08-05 22:19:14,881 INFO org.apache.hadoop.yarn.server.resourcemanager.scheduler.capacity.ParentQueue: completedContainer queue=root usedCapacity=0.0625 absoluteUsedCapacity=0.0625 used=<memory:3072, vCores:2> cluster=<memory:49152, vCores:96>
2013-08-05 22:19:14,881 INFO org.apache.hadoop.yarn.server.resourcemanager.scheduler.capacity.CapacityScheduler: Application appattempt_1375740621345_0004_000001 released container container_1375740621345_0004_01_000002 on node: host: hadoop-100-6:42294 #containers=0 available=8192 used=0 with event: FINISHED
2013-08-05 22:19:15,931 INFO org.apache.hadoop.yarn.server.resourcemanager.rmcontainer.RMContainerImpl: container_1375740621345_0004_01_000003 Container Transitioned from RUNNING to COMPLETED
2013-08-05 22:19:15,932 INFO org.apache.hadoop.yarn.server.resourcemanager.scheduler.common.fica.FiCaSchedulerApp: Completed container: container_1375740621345_0004_01_000003 in state: COMPLETED event:FINISHED
2013-08-05 22:19:15,932 INFO org.apache.hadoop.yarn.server.resourcemanager.RMAuditLogger: USER=ubuntu	OPERATION=AM Released Container	TARGET=SchedulerApp	RESULT=SUCCESS	APPID=application_1375740621345_0004	CONTAINERID=container_1375740621345_0004_01_000003
2013-08-05 22:19:15,932 INFO org.apache.hadoop.yarn.server.resourcemanager.scheduler.common.fica.FiCaSchedulerNode: Released container container_1375740621345_0004_01_000003 of capacity <memory:1024, vCores:1> on host hadoop-100-7:36057, which currently has 0 containers, <memory:0, vCores:0> used and <memory:8192, vCores:16> available, release resources=true
2013-08-05 22:19:15,932 INFO org.apache.hadoop.yarn.server.resourcemanager.scheduler.capacity.LeafQueue: default used=<memory:2048, vCores:1> numContainers=1 user=ubuntu user-resources=<memory:2048, vCores:1>
2013-08-05 22:19:15,934 INFO org.apache.hadoop.yarn.server.resourcemanager.scheduler.capacity.LeafQueue: completedContainer container=Container: [ContainerId: container_1375740621345_0004_01_000003, NodeId: hadoop-100-7:36057, NodeHttpAddress: hadoop-100-7:8042, Resource: <memory:1024, vCores:1>, Priority: 20, State: NEW, Token: null, Status: container_id {, app_attempt_id {, application_id {, id: 4, cluster_timestamp: 1375740621345, }, attemptId: 1, }, id: 3, }, state: C_COMPLETE, diagnostics: "Container killed by the ApplicationMaster.\n\n", exit_status: 143, ] resource=<memory:1024, vCores:1> queue=default: capacity=1.0, absoluteCapacity=1.0, usedResources=<memory:2048, vCores:1>usedCapacity=0.041666668, absoluteUsedCapacity=0.041666668, numApps=1, numContainers=1 usedCapacity=0.041666668 absoluteUsedCapacity=0.041666668 used=<memory:2048, vCores:1> cluster=<memory:49152, vCores:96>
2013-08-05 22:19:15,934 INFO org.apache.hadoop.yarn.server.resourcemanager.scheduler.capacity.ParentQueue: completedContainer queue=root usedCapacity=0.041666668 absoluteUsedCapacity=0.041666668 used=<memory:2048, vCores:1> cluster=<memory:49152, vCores:96>
2013-08-05 22:19:15,934 INFO org.apache.hadoop.yarn.server.resourcemanager.scheduler.capacity.CapacityScheduler: Application appattempt_1375740621345_0004_000001 released container container_1375740621345_0004_01_000003 on node: host: hadoop-100-7:36057 #containers=0 available=8192 used=0 with event: FINISHED
2013-08-05 22:19:20,096 INFO org.apache.hadoop.yarn.server.resourcemanager.rmapp.attempt.RMAppAttemptImpl: appattempt_1375740621345_0004_000001 State change from RUNNING to FINISHING
2013-08-05 22:19:20,097 INFO org.apache.hadoop.yarn.server.resourcemanager.rmapp.RMAppImpl: application_1375740621345_0004 State change from RUNNING to FINISHING
2013-08-05 22:19:21,269 INFO org.apache.hadoop.yarn.server.resourcemanager.rmcontainer.RMContainerImpl: container_1375740621345_0004_01_000001 Container Transitioned from RUNNING to COMPLETED
2013-08-05 22:19:21,269 INFO org.apache.hadoop.yarn.server.resourcemanager.scheduler.common.fica.FiCaSchedulerApp: Completed container: container_1375740621345_0004_01_000001 in state: COMPLETED event:FINISHED
2013-08-05 22:19:21,270 INFO org.apache.hadoop.yarn.server.resourcemanager.RMAuditLogger: USER=ubuntu	OPERATION=AM Released Container	TARGET=SchedulerApp	RESULT=SUCCESS	APPID=application_1375740621345_0004	CONTAINERID=container_1375740621345_0004_01_000001
2013-08-05 22:19:21,270 INFO org.apache.hadoop.yarn.server.resourcemanager.scheduler.common.fica.FiCaSchedulerNode: Released container container_1375740621345_0004_01_000001 of capacity <memory:2048, vCores:1> on host hadoop-100-3:44102, which currently has 0 containers, <memory:0, vCores:0> used and <memory:8192, vCores:16> available, release resources=true
2013-08-05 22:19:21,270 INFO org.apache.hadoop.yarn.server.resourcemanager.rmapp.attempt.RMAppAttemptImpl: appattempt_1375740621345_0004_000001 State change from FINISHING to FINISHED
2013-08-05 22:19:21,270 INFO org.apache.hadoop.yarn.server.resourcemanager.scheduler.capacity.LeafQueue: default used=<memory:0, vCores:0> numContainers=0 user=ubuntu user-resources=<memory:0, vCores:0>
2013-08-05 22:19:21,270 INFO org.apache.hadoop.yarn.server.resourcemanager.rmapp.RMAppImpl: application_1375740621345_0004 State change from FINISHING to FINISHED
2013-08-05 22:19:21,271 INFO org.apache.hadoop.yarn.server.resourcemanager.RMAuditLogger: USER=ubuntu	OPERATION=Application Finished - Succeeded	TARGET=RMAppManager	RESULT=SUCCESS	APPID=application_1375740621345_0004
2013-08-05 22:19:21,271 INFO org.apache.hadoop.yarn.server.resourcemanager.amlauncher.AMLauncher: Cleaning master appattempt_1375740621345_0004_000001
2013-08-05 22:19:21,271 INFO org.apache.hadoop.yarn.server.resourcemanager.scheduler.capacity.LeafQueue: completedContainer container=Container: [ContainerId: container_1375740621345_0004_01_000001, NodeId: hadoop-100-3:44102, NodeHttpAddress: hadoop-100-3:8042, Resource: <memory:2048, vCores:1>, Priority: 0, State: NEW, Token: null, Status: container_id {, app_attempt_id {, application_id {, id: 4, cluster_timestamp: 1375740621345, }, attemptId: 1, }, id: 1, }, state: C_COMPLETE, diagnostics: "", exit_status: 0, ] resource=<memory:2048, vCores:1> queue=default: capacity=1.0, absoluteCapacity=1.0, usedResources=<memory:0, vCores:0>usedCapacity=0.0, absoluteUsedCapacity=0.0, numApps=1, numContainers=0 usedCapacity=0.0 absoluteUsedCapacity=0.0 used=<memory:0, vCores:0> cluster=<memory:49152, vCores:96>
2013-08-05 22:19:21,272 INFO org.apache.hadoop.yarn.server.resourcemanager.recovery.RMStateStore: Removing info for app: application_1375740621345_0004
2013-08-05 22:19:21,272 INFO org.apache.hadoop.yarn.server.resourcemanager.RMAppManager$ApplicationSummary: appId=application_1375740621345_0004,name=TeraGen,user=ubuntu,queue=default,state=FINISHED,trackingUrl=hadoop-100-1.novalocal:8088/proxy/application_1375740621345_0004/jobhistory/job/job_1375740621345_0004,appMasterHost=hadoop-100-3,startTime=1375741036157,finishTime=1375741160097
2013-08-05 22:19:21,272 INFO org.apache.hadoop.yarn.server.resourcemanager.scheduler.capacity.ParentQueue: completedContainer queue=root usedCapacity=0.0 absoluteUsedCapacity=0.0 used=<memory:0, vCores:0> cluster=<memory:49152, vCores:96>
2013-08-05 22:19:21,276 INFO org.apache.hadoop.yarn.server.resourcemanager.scheduler.capacity.CapacityScheduler: Application appattempt_1375740621345_0004_000001 released container container_1375740621345_0004_01_000001 on node: host: hadoop-100-3:44102 #containers=0 available=8192 used=0 with event: FINISHED
2013-08-05 22:19:21,276 INFO org.apache.hadoop.yarn.server.resourcemanager.scheduler.capacity.CapacityScheduler: Application appattempt_1375740621345_0004_000001 is done. finalState=FINISHED
2013-08-05 22:19:21,276 INFO org.apache.hadoop.yarn.server.resourcemanager.scheduler.AppSchedulingInfo: Application application_1375740621345_0004 requests cleared
2013-08-05 22:19:21,276 INFO org.apache.hadoop.yarn.server.resourcemanager.scheduler.capacity.LeafQueue: Application removed - appId: application_1375740621345_0004 user: ubuntu queue: default #user-pending-applications: 0 #user-active-applications: 0 #queue-pending-applications: 0 #queue-active-applications: 0
2013-08-05 22:19:21,277 INFO org.apache.hadoop.yarn.server.resourcemanager.scheduler.capacity.ParentQueue: Application removed - appId: application_1375740621345_0004 user: ubuntu leaf-queue of parent: root #applications: 0
2013-08-05 22:19:21,558 INFO org.apache.hadoop.yarn.server.resourcemanager.ClientRMService: Allocated new applicationId: 5
2013-08-05 22:19:23,389 INFO org.apache.hadoop.yarn.server.resourcemanager.ClientRMService: Storing Application with id application_1375740621345_0005
2013-08-05 22:19:23,390 INFO org.apache.hadoop.yarn.server.resourcemanager.recovery.RMStateStore: Storing info for app: application_1375740621345_0005
2013-08-05 22:19:23,390 INFO org.apache.hadoop.yarn.server.resourcemanager.ClientRMService: Application with id 5 submitted by user ubuntu
2013-08-05 22:19:23,390 INFO org.apache.hadoop.yarn.server.resourcemanager.RMAuditLogger: USER=ubuntu	IP=192.168.100.3	OPERATION=Submit Application Request	TARGET=ClientRMService	RESULT=SUCCESS	APPID=application_1375740621345_0005
2013-08-05 22:19:23,392 INFO org.apache.hadoop.yarn.server.resourcemanager.rmapp.RMAppImpl: application_1375740621345_0005 State change from NEW to SUBMITTED
2013-08-05 22:19:23,392 INFO org.apache.hadoop.yarn.server.resourcemanager.ApplicationMasterService: Registering appattempt_1375740621345_0005_000001
2013-08-05 22:19:23,392 INFO org.apache.hadoop.yarn.server.resourcemanager.rmapp.attempt.RMAppAttemptImpl: appattempt_1375740621345_0005_000001 State change from NEW to SUBMITTED
2013-08-05 22:19:23,393 INFO org.apache.hadoop.yarn.server.resourcemanager.scheduler.capacity.LeafQueue: Application application_1375740621345_0005 from user: ubuntu activated in queue: default
2013-08-05 22:19:23,394 INFO org.apache.hadoop.yarn.server.resourcemanager.scheduler.capacity.LeafQueue: Application added - appId: application_1375740621345_0005 user: org.apache.hadoop.yarn.server.resourcemanager.scheduler.capacity.LeafQueue$User@4183422d, leaf-queue: default #user-pending-applications: 0 #user-active-applications: 1 #queue-pending-applications: 0 #queue-active-applications: 1
2013-08-05 22:19:23,394 INFO org.apache.hadoop.yarn.server.resourcemanager.scheduler.capacity.ParentQueue: Application added - appId: application_1375740621345_0005 user: ubuntu leaf-queue of parent: root #applications: 1
2013-08-05 22:19:23,394 INFO org.apache.hadoop.yarn.server.resourcemanager.scheduler.capacity.CapacityScheduler: Application Submission: appattempt_1375740621345_0005_000001, user: ubuntu queue: default: capacity=1.0, absoluteCapacity=1.0, usedResources=<memory:0, vCores:0>usedCapacity=0.0, absoluteUsedCapacity=0.0, numApps=1, numContainers=0, currently active: 1
2013-08-05 22:19:23,394 INFO org.apache.hadoop.yarn.server.resourcemanager.rmapp.attempt.RMAppAttemptImpl: appattempt_1375740621345_0005_000001 State change from SUBMITTED to SCHEDULED
2013-08-05 22:19:23,394 INFO org.apache.hadoop.yarn.server.resourcemanager.rmapp.RMAppImpl: application_1375740621345_0005 State change from SUBMITTED to ACCEPTED
2013-08-05 22:19:23,648 INFO org.apache.hadoop.yarn.server.resourcemanager.rmcontainer.RMContainerImpl: container_1375740621345_0005_01_000001 Container Transitioned from NEW to ALLOCATED
2013-08-05 22:19:23,648 INFO org.apache.hadoop.yarn.server.resourcemanager.RMAuditLogger: USER=ubuntu	OPERATION=AM Allocated Container	TARGET=SchedulerApp	RESULT=SUCCESS	APPID=application_1375740621345_0005	CONTAINERID=container_1375740621345_0005_01_000001
2013-08-05 22:19:23,648 INFO org.apache.hadoop.yarn.server.resourcemanager.scheduler.common.fica.FiCaSchedulerNode: Assigned container container_1375740621345_0005_01_000001 of capacity <memory:2048, vCores:1> on host hadoop-100-4:50425, which currently has 1 containers, <memory:2048, vCores:1> used and <memory:6144, vCores:15> available
2013-08-05 22:19:23,649 INFO org.apache.hadoop.yarn.server.resourcemanager.scheduler.capacity.LeafQueue: assignedContainer application=application_1375740621345_0005 container=Container: [ContainerId: container_1375740621345_0005_01_000001, NodeId: hadoop-100-4:50425, NodeHttpAddress: hadoop-100-4:8042, Resource: <memory:2048, vCores:1>, Priority: 0, State: NEW, Token: null, Status: container_id {, app_attempt_id {, application_id {, id: 5, cluster_timestamp: 1375740621345, }, attemptId: 1, }, id: 1, }, state: C_NEW, ] containerId=container_1375740621345_0005_01_000001 queue=default: capacity=1.0, absoluteCapacity=1.0, usedResources=<memory:0, vCores:0>usedCapacity=0.0, absoluteUsedCapacity=0.0, numApps=1, numContainers=0 usedCapacity=0.0 absoluteUsedCapacity=0.0 used=<memory:0, vCores:0> cluster=<memory:49152, vCores:96>
2013-08-05 22:19:23,650 INFO org.apache.hadoop.yarn.server.resourcemanager.scheduler.capacity.ParentQueue: Re-sorting queues since queue: root.default stats: default: capacity=1.0, absoluteCapacity=1.0, usedResources=<memory:2048, vCores:1>usedCapacity=0.041666668, absoluteUsedCapacity=0.041666668, numApps=1, numContainers=1
2013-08-05 22:19:23,651 INFO org.apache.hadoop.yarn.server.resourcemanager.rmcontainer.RMContainerImpl: container_1375740621345_0005_01_000001 Container Transitioned from ALLOCATED to ACQUIRED
2013-08-05 22:19:23,651 INFO org.apache.hadoop.yarn.server.resourcemanager.scheduler.capacity.ParentQueue: assignedContainer queue=root usedCapacity=0.041666668 absoluteUsedCapacity=0.041666668 used=<memory:2048, vCores:1> cluster=<memory:49152, vCores:96>
2013-08-05 22:19:23,653 INFO org.apache.hadoop.yarn.server.resourcemanager.rmapp.attempt.RMAppAttemptImpl: Storing attempt: AppId: application_1375740621345_0005 AttemptId: appattempt_1375740621345_0005_000001 MasterContainer: Container: [ContainerId: container_1375740621345_0005_01_000001, NodeId: hadoop-100-4:50425, NodeHttpAddress: hadoop-100-4:8042, Resource: <memory:2048, vCores:1>, Priority: 0, State: NEW, Token: null, Status: container_id {, app_attempt_id {, application_id {, id: 5, cluster_timestamp: 1375740621345, }, attemptId: 1, }, id: 1, }, state: C_NEW, ]
2013-08-05 22:19:23,653 INFO org.apache.hadoop.yarn.server.resourcemanager.recovery.RMStateStore: Storing info for attempt: appattempt_1375740621345_0005_000001
2013-08-05 22:19:23,654 INFO org.apache.hadoop.yarn.server.resourcemanager.rmapp.attempt.RMAppAttemptImpl: appattempt_1375740621345_0005_000001 State change from SCHEDULED to ALLOCATED_SAVING
2013-08-05 22:19:23,654 INFO org.apache.hadoop.yarn.server.resourcemanager.rmapp.attempt.RMAppAttemptImpl: appattempt_1375740621345_0005_000001 State change from ALLOCATED_SAVING to ALLOCATED
2013-08-05 22:19:23,655 INFO org.apache.hadoop.yarn.server.resourcemanager.amlauncher.AMLauncher: Launching masterappattempt_1375740621345_0005_000001
2013-08-05 22:19:23,658 INFO org.apache.hadoop.yarn.server.resourcemanager.amlauncher.AMLauncher: Setting up container Container: [ContainerId: container_1375740621345_0005_01_000001, NodeId: hadoop-100-4:50425, NodeHttpAddress: hadoop-100-4:8042, Resource: <memory:2048, vCores:1>, Priority: 0, State: NEW, Token: null, Status: container_id {, app_attempt_id {, application_id {, id: 5, cluster_timestamp: 1375740621345, }, attemptId: 1, }, id: 1, }, state: C_NEW, ] for AM appattempt_1375740621345_0005_000001
2013-08-05 22:19:23,658 INFO org.apache.hadoop.yarn.server.resourcemanager.amlauncher.AMLauncher: Command to launch container container_1375740621345_0005_01_000001 : $JAVA_HOME/bin/java -Dlog4j.configuration=container-log4j.properties -Dyarn.app.mapreduce.container.log.dir=<LOG_DIR> -Dyarn.app.mapreduce.container.log.filesize=0 -Dhadoop.root.logger=INFO,CLA  -Xmx1024m org.apache.hadoop.mapreduce.v2.app.MRAppMaster 1><LOG_DIR>/stdout 2><LOG_DIR>/stderr 
2013-08-05 22:19:23,716 INFO org.apache.hadoop.yarn.server.resourcemanager.amlauncher.AMLauncher: Done launching container Container: [ContainerId: container_1375740621345_0005_01_000001, NodeId: hadoop-100-4:50425, NodeHttpAddress: hadoop-100-4:8042, Resource: <memory:2048, vCores:1>, Priority: 0, State: NEW, Token: null, Status: container_id {, app_attempt_id {, application_id {, id: 5, cluster_timestamp: 1375740621345, }, attemptId: 1, }, id: 1, }, state: C_NEW, ] for AM appattempt_1375740621345_0005_000001
2013-08-05 22:19:23,716 INFO org.apache.hadoop.yarn.server.resourcemanager.rmapp.attempt.RMAppAttemptImpl: appattempt_1375740621345_0005_000001 State change from ALLOCATED to LAUNCHED
2013-08-05 22:19:24,653 INFO org.apache.hadoop.yarn.server.resourcemanager.rmcontainer.RMContainerImpl: container_1375740621345_0005_01_000001 Container Transitioned from ACQUIRED to RUNNING
2013-08-05 22:19:30,709 INFO org.apache.hadoop.yarn.server.resourcemanager.ApplicationMasterService: AM registration appattempt_1375740621345_0005_000001
2013-08-05 22:19:30,709 INFO org.apache.hadoop.yarn.server.resourcemanager.RMAuditLogger: USER=ubuntu	IP=192.168.100.14	OPERATION=Register App Master	TARGET=ApplicationMasterService	RESULT=SUCCESS	APPID=application_1375740621345_0005	APPATTEMPTID=appattempt_1375740621345_0005_000001
2013-08-05 22:19:30,710 INFO org.apache.hadoop.yarn.server.resourcemanager.rmapp.attempt.RMAppAttemptImpl: appattempt_1375740621345_0005_000001 State change from LAUNCHED to RUNNING
2013-08-05 22:19:30,711 INFO org.apache.hadoop.yarn.server.resourcemanager.rmapp.RMAppImpl: application_1375740621345_0005 State change from ACCEPTED to RUNNING
2013-08-05 22:19:31,939 INFO org.apache.hadoop.yarn.server.resourcemanager.rmcontainer.RMContainerImpl: container_1375740621345_0005_01_000002 Container Transitioned from NEW to ALLOCATED
2013-08-05 22:19:31,939 INFO org.apache.hadoop.yarn.server.resourcemanager.RMAuditLogger: USER=ubuntu	OPERATION=AM Allocated Container	TARGET=SchedulerApp	RESULT=SUCCESS	APPID=application_1375740621345_0005	CONTAINERID=container_1375740621345_0005_01_000002
2013-08-05 22:19:31,939 INFO org.apache.hadoop.yarn.server.resourcemanager.scheduler.common.fica.FiCaSchedulerNode: Assigned container container_1375740621345_0005_01_000002 of capacity <memory:1024, vCores:1> on host hadoop-100-6:42294, which currently has 1 containers, <memory:1024, vCores:1> used and <memory:7168, vCores:15> available
2013-08-05 22:19:31,940 INFO org.apache.hadoop.yarn.server.resourcemanager.scheduler.capacity.LeafQueue: assignedContainer application=application_1375740621345_0005 container=Container: [ContainerId: container_1375740621345_0005_01_000002, NodeId: hadoop-100-6:42294, NodeHttpAddress: hadoop-100-6:8042, Resource: <memory:1024, vCores:1>, Priority: 20, State: NEW, Token: null, Status: container_id {, app_attempt_id {, application_id {, id: 5, cluster_timestamp: 1375740621345, }, attemptId: 1, }, id: 2, }, state: C_NEW, ] containerId=container_1375740621345_0005_01_000002 queue=default: capacity=1.0, absoluteCapacity=1.0, usedResources=<memory:2048, vCores:1>usedCapacity=0.041666668, absoluteUsedCapacity=0.041666668, numApps=1, numContainers=1 usedCapacity=0.041666668 absoluteUsedCapacity=0.041666668 used=<memory:2048, vCores:1> cluster=<memory:49152, vCores:96>
2013-08-05 22:19:31,941 INFO org.apache.hadoop.yarn.server.resourcemanager.scheduler.capacity.ParentQueue: Re-sorting queues since queue: root.default stats: default: capacity=1.0, absoluteCapacity=1.0, usedResources=<memory:3072, vCores:2>usedCapacity=0.0625, absoluteUsedCapacity=0.0625, numApps=1, numContainers=2
2013-08-05 22:19:31,941 INFO org.apache.hadoop.yarn.server.resourcemanager.scheduler.capacity.ParentQueue: assignedContainer queue=root usedCapacity=0.0625 absoluteUsedCapacity=0.0625 used=<memory:3072, vCores:2> cluster=<memory:49152, vCores:96>
2013-08-05 22:19:31,987 INFO org.apache.hadoop.yarn.server.resourcemanager.rmcontainer.RMContainerImpl: container_1375740621345_0005_01_000003 Container Transitioned from NEW to ALLOCATED
2013-08-05 22:19:31,987 INFO org.apache.hadoop.yarn.server.resourcemanager.RMAuditLogger: USER=ubuntu	OPERATION=AM Allocated Container	TARGET=SchedulerApp	RESULT=SUCCESS	APPID=application_1375740621345_0005	CONTAINERID=container_1375740621345_0005_01_000003
2013-08-05 22:19:31,987 INFO org.apache.hadoop.yarn.server.resourcemanager.scheduler.common.fica.FiCaSchedulerNode: Assigned container container_1375740621345_0005_01_000003 of capacity <memory:1024, vCores:1> on host hadoop-100-7:36057, which currently has 1 containers, <memory:1024, vCores:1> used and <memory:7168, vCores:15> available
2013-08-05 22:19:31,988 INFO org.apache.hadoop.yarn.server.resourcemanager.scheduler.capacity.LeafQueue: assignedContainer application=application_1375740621345_0005 container=Container: [ContainerId: container_1375740621345_0005_01_000003, NodeId: hadoop-100-7:36057, NodeHttpAddress: hadoop-100-7:8042, Resource: <memory:1024, vCores:1>, Priority: 20, State: NEW, Token: null, Status: container_id {, app_attempt_id {, application_id {, id: 5, cluster_timestamp: 1375740621345, }, attemptId: 1, }, id: 3, }, state: C_NEW, ] containerId=container_1375740621345_0005_01_000003 queue=default: capacity=1.0, absoluteCapacity=1.0, usedResources=<memory:3072, vCores:2>usedCapacity=0.0625, absoluteUsedCapacity=0.0625, numApps=1, numContainers=2 usedCapacity=0.0625 absoluteUsedCapacity=0.0625 used=<memory:3072, vCores:2> cluster=<memory:49152, vCores:96>
2013-08-05 22:19:31,988 INFO org.apache.hadoop.yarn.server.resourcemanager.scheduler.capacity.ParentQueue: Re-sorting queues since queue: root.default stats: default: capacity=1.0, absoluteCapacity=1.0, usedResources=<memory:4096, vCores:3>usedCapacity=0.083333336, absoluteUsedCapacity=0.083333336, numApps=1, numContainers=3
2013-08-05 22:19:31,989 INFO org.apache.hadoop.yarn.server.resourcemanager.scheduler.capacity.ParentQueue: assignedContainer queue=root usedCapacity=0.083333336 absoluteUsedCapacity=0.083333336 used=<memory:4096, vCores:3> cluster=<memory:49152, vCores:96>
2013-08-05 22:19:32,793 INFO org.apache.hadoop.yarn.server.resourcemanager.rmcontainer.RMContainerImpl: container_1375740621345_0005_01_000002 Container Transitioned from ALLOCATED to ACQUIRED
2013-08-05 22:19:32,796 INFO org.apache.hadoop.yarn.server.resourcemanager.rmcontainer.RMContainerImpl: container_1375740621345_0005_01_000003 Container Transitioned from ALLOCATED to ACQUIRED
2013-08-05 22:19:33,824 INFO org.apache.hadoop.yarn.server.resourcemanager.scheduler.AppSchedulingInfo: checking for deactivate... 
2013-08-05 22:19:33,949 INFO org.apache.hadoop.yarn.server.resourcemanager.rmcontainer.RMContainerImpl: container_1375740621345_0005_01_000002 Container Transitioned from ACQUIRED to RUNNING
2013-08-05 22:19:33,995 INFO org.apache.hadoop.yarn.server.resourcemanager.rmcontainer.RMContainerImpl: container_1375740621345_0005_01_000003 Container Transitioned from ACQUIRED to RUNNING
2013-08-05 22:21:17,468 INFO org.apache.hadoop.yarn.server.resourcemanager.rmcontainer.RMContainerImpl: container_1375740621345_0005_01_000003 Container Transitioned from RUNNING to COMPLETED
2013-08-05 22:21:17,468 INFO org.apache.hadoop.yarn.server.resourcemanager.scheduler.common.fica.FiCaSchedulerApp: Completed container: container_1375740621345_0005_01_000003 in state: COMPLETED event:FINISHED
2013-08-05 22:21:17,468 INFO org.apache.hadoop.yarn.server.resourcemanager.RMAuditLogger: USER=ubuntu	OPERATION=AM Released Container	TARGET=SchedulerApp	RESULT=SUCCESS	APPID=application_1375740621345_0005	CONTAINERID=container_1375740621345_0005_01_000003
2013-08-05 22:21:17,469 INFO org.apache.hadoop.yarn.server.resourcemanager.scheduler.common.fica.FiCaSchedulerNode: Released container container_1375740621345_0005_01_000003 of capacity <memory:1024, vCores:1> on host hadoop-100-7:36057, which currently has 0 containers, <memory:0, vCores:0> used and <memory:8192, vCores:16> available, release resources=true
2013-08-05 22:21:17,469 INFO org.apache.hadoop.yarn.server.resourcemanager.scheduler.capacity.LeafQueue: default used=<memory:3072, vCores:2> numContainers=2 user=ubuntu user-resources=<memory:3072, vCores:2>
2013-08-05 22:21:17,470 INFO org.apache.hadoop.yarn.server.resourcemanager.scheduler.capacity.LeafQueue: completedContainer container=Container: [ContainerId: container_1375740621345_0005_01_000003, NodeId: hadoop-100-7:36057, NodeHttpAddress: hadoop-100-7:8042, Resource: <memory:1024, vCores:1>, Priority: 20, State: NEW, Token: null, Status: container_id {, app_attempt_id {, application_id {, id: 5, cluster_timestamp: 1375740621345, }, attemptId: 1, }, id: 3, }, state: C_COMPLETE, diagnostics: "Container killed by the ApplicationMaster.\n\n", exit_status: 143, ] resource=<memory:1024, vCores:1> queue=default: capacity=1.0, absoluteCapacity=1.0, usedResources=<memory:3072, vCores:2>usedCapacity=0.0625, absoluteUsedCapacity=0.0625, numApps=1, numContainers=2 usedCapacity=0.0625 absoluteUsedCapacity=0.0625 used=<memory:3072, vCores:2> cluster=<memory:49152, vCores:96>
2013-08-05 22:21:17,471 INFO org.apache.hadoop.yarn.server.resourcemanager.scheduler.capacity.ParentQueue: completedContainer queue=root usedCapacity=0.0625 absoluteUsedCapacity=0.0625 used=<memory:3072, vCores:2> cluster=<memory:49152, vCores:96>
2013-08-05 22:21:17,471 INFO org.apache.hadoop.yarn.server.resourcemanager.scheduler.capacity.CapacityScheduler: Application appattempt_1375740621345_0005_000001 released container container_1375740621345_0005_01_000003 on node: host: hadoop-100-7:36057 #containers=0 available=8192 used=0 with event: FINISHED
2013-08-05 22:21:23,544 INFO org.apache.hadoop.yarn.server.resourcemanager.rmcontainer.RMContainerImpl: container_1375740621345_0005_01_000002 Container Transitioned from RUNNING to COMPLETED
2013-08-05 22:21:23,544 INFO org.apache.hadoop.yarn.server.resourcemanager.scheduler.common.fica.FiCaSchedulerApp: Completed container: container_1375740621345_0005_01_000002 in state: COMPLETED event:FINISHED
2013-08-05 22:21:23,545 INFO org.apache.hadoop.yarn.server.resourcemanager.RMAuditLogger: USER=ubuntu	OPERATION=AM Released Container	TARGET=SchedulerApp	RESULT=SUCCESS	APPID=application_1375740621345_0005	CONTAINERID=container_1375740621345_0005_01_000002
2013-08-05 22:21:23,545 INFO org.apache.hadoop.yarn.server.resourcemanager.scheduler.common.fica.FiCaSchedulerNode: Released container container_1375740621345_0005_01_000002 of capacity <memory:1024, vCores:1> on host hadoop-100-6:42294, which currently has 0 containers, <memory:0, vCores:0> used and <memory:8192, vCores:16> available, release resources=true
2013-08-05 22:21:23,545 INFO org.apache.hadoop.yarn.server.resourcemanager.scheduler.capacity.LeafQueue: default used=<memory:2048, vCores:1> numContainers=1 user=ubuntu user-resources=<memory:2048, vCores:1>
2013-08-05 22:21:23,560 INFO org.apache.hadoop.yarn.server.resourcemanager.scheduler.capacity.LeafQueue: completedContainer container=Container: [ContainerId: container_1375740621345_0005_01_000002, NodeId: hadoop-100-6:42294, NodeHttpAddress: hadoop-100-6:8042, Resource: <memory:1024, vCores:1>, Priority: 20, State: NEW, Token: null, Status: container_id {, app_attempt_id {, application_id {, id: 5, cluster_timestamp: 1375740621345, }, attemptId: 1, }, id: 2, }, state: C_COMPLETE, diagnostics: "Container killed by the ApplicationMaster.\n\n", exit_status: 143, ] resource=<memory:1024, vCores:1> queue=default: capacity=1.0, absoluteCapacity=1.0, usedResources=<memory:2048, vCores:1>usedCapacity=0.041666668, absoluteUsedCapacity=0.041666668, numApps=1, numContainers=1 usedCapacity=0.041666668 absoluteUsedCapacity=0.041666668 used=<memory:2048, vCores:1> cluster=<memory:49152, vCores:96>
2013-08-05 22:21:23,561 INFO org.apache.hadoop.yarn.server.resourcemanager.scheduler.capacity.ParentQueue: completedContainer queue=root usedCapacity=0.041666668 absoluteUsedCapacity=0.041666668 used=<memory:2048, vCores:1> cluster=<memory:49152, vCores:96>
2013-08-05 22:21:23,561 INFO org.apache.hadoop.yarn.server.resourcemanager.scheduler.capacity.CapacityScheduler: Application appattempt_1375740621345_0005_000001 released container container_1375740621345_0005_01_000002 on node: host: hadoop-100-6:42294 #containers=0 available=8192 used=0 with event: FINISHED
2013-08-05 22:21:27,693 INFO org.apache.hadoop.yarn.server.resourcemanager.rmapp.attempt.RMAppAttemptImpl: appattempt_1375740621345_0005_000001 State change from RUNNING to FINISHING
2013-08-05 22:21:27,693 INFO org.apache.hadoop.yarn.server.resourcemanager.rmapp.RMAppImpl: application_1375740621345_0005 State change from RUNNING to FINISHING
2013-08-05 22:21:28,282 INFO org.apache.hadoop.yarn.server.resourcemanager.rmcontainer.RMContainerImpl: container_1375740621345_0005_01_000001 Container Transitioned from RUNNING to COMPLETED
2013-08-05 22:21:28,282 INFO org.apache.hadoop.yarn.server.resourcemanager.scheduler.common.fica.FiCaSchedulerApp: Completed container: container_1375740621345_0005_01_000001 in state: COMPLETED event:FINISHED
2013-08-05 22:21:28,282 INFO org.apache.hadoop.yarn.server.resourcemanager.RMAuditLogger: USER=ubuntu	OPERATION=AM Released Container	TARGET=SchedulerApp	RESULT=SUCCESS	APPID=application_1375740621345_0005	CONTAINERID=container_1375740621345_0005_01_000001
2013-08-05 22:21:28,282 INFO org.apache.hadoop.yarn.server.resourcemanager.scheduler.common.fica.FiCaSchedulerNode: Released container container_1375740621345_0005_01_000001 of capacity <memory:2048, vCores:1> on host hadoop-100-4:50425, which currently has 0 containers, <memory:0, vCores:0> used and <memory:8192, vCores:16> available, release resources=true
2013-08-05 22:21:28,282 INFO org.apache.hadoop.yarn.server.resourcemanager.scheduler.capacity.LeafQueue: default used=<memory:0, vCores:0> numContainers=0 user=ubuntu user-resources=<memory:0, vCores:0>
2013-08-05 22:21:28,283 INFO org.apache.hadoop.yarn.server.resourcemanager.scheduler.capacity.LeafQueue: completedContainer container=Container: [ContainerId: container_1375740621345_0005_01_000001, NodeId: hadoop-100-4:50425, NodeHttpAddress: hadoop-100-4:8042, Resource: <memory:2048, vCores:1>, Priority: 0, State: NEW, Token: null, Status: container_id {, app_attempt_id {, application_id {, id: 5, cluster_timestamp: 1375740621345, }, attemptId: 1, }, id: 1, }, state: C_COMPLETE, diagnostics: "", exit_status: 0, ] resource=<memory:2048, vCores:1> queue=default: capacity=1.0, absoluteCapacity=1.0, usedResources=<memory:0, vCores:0>usedCapacity=0.0, absoluteUsedCapacity=0.0, numApps=1, numContainers=0 usedCapacity=0.0 absoluteUsedCapacity=0.0 used=<memory:0, vCores:0> cluster=<memory:49152, vCores:96>
2013-08-05 22:21:28,283 INFO org.apache.hadoop.yarn.server.resourcemanager.scheduler.capacity.ParentQueue: completedContainer queue=root usedCapacity=0.0 absoluteUsedCapacity=0.0 used=<memory:0, vCores:0> cluster=<memory:49152, vCores:96>
2013-08-05 22:21:28,283 INFO org.apache.hadoop.yarn.server.resourcemanager.scheduler.capacity.CapacityScheduler: Application appattempt_1375740621345_0005_000001 released container container_1375740621345_0005_01_000001 on node: host: hadoop-100-4:50425 #containers=0 available=8192 used=0 with event: FINISHED
2013-08-05 22:21:28,283 INFO org.apache.hadoop.yarn.server.resourcemanager.rmapp.attempt.RMAppAttemptImpl: appattempt_1375740621345_0005_000001 State change from FINISHING to FINISHED
2013-08-05 22:21:28,285 INFO org.apache.hadoop.yarn.server.resourcemanager.rmapp.RMAppImpl: application_1375740621345_0005 State change from FINISHING to FINISHED
2013-08-05 22:21:28,286 INFO org.apache.hadoop.yarn.server.resourcemanager.RMAuditLogger: USER=ubuntu	OPERATION=Application Finished - Succeeded	TARGET=RMAppManager	RESULT=SUCCESS	APPID=application_1375740621345_0005
2013-08-05 22:21:28,286 INFO org.apache.hadoop.yarn.server.resourcemanager.amlauncher.AMLauncher: Cleaning master appattempt_1375740621345_0005_000001
2013-08-05 22:21:28,286 INFO org.apache.hadoop.yarn.server.resourcemanager.recovery.RMStateStore: Removing info for app: application_1375740621345_0005
2013-08-05 22:21:28,286 INFO org.apache.hadoop.yarn.server.resourcemanager.RMAppManager$ApplicationSummary: appId=application_1375740621345_0005,name=TeraGen,user=ubuntu,queue=default,state=FINISHED,trackingUrl=hadoop-100-1.novalocal:8088/proxy/application_1375740621345_0005/jobhistory/job/job_1375740621345_0005,appMasterHost=hadoop-100-4,startTime=1375741163389,finishTime=1375741287693
2013-08-05 22:21:28,286 INFO org.apache.hadoop.yarn.server.resourcemanager.scheduler.capacity.CapacityScheduler: Application appattempt_1375740621345_0005_000001 is done. finalState=FINISHED
2013-08-05 22:21:28,286 INFO org.apache.hadoop.yarn.server.resourcemanager.scheduler.AppSchedulingInfo: Application application_1375740621345_0005 requests cleared
2013-08-05 22:21:28,286 INFO org.apache.hadoop.yarn.server.resourcemanager.scheduler.capacity.LeafQueue: Application removed - appId: application_1375740621345_0005 user: ubuntu queue: default #user-pending-applications: 0 #user-active-applications: 0 #queue-pending-applications: 0 #queue-active-applications: 0
2013-08-05 22:21:28,287 INFO org.apache.hadoop.yarn.server.resourcemanager.scheduler.capacity.ParentQueue: Application removed - appId: application_1375740621345_0005 user: ubuntu leaf-queue of parent: root #applications: 0
2013-08-05 22:21:33,588 INFO org.apache.hadoop.yarn.server.resourcemanager.ClientRMService: Allocated new applicationId: 6
2013-08-05 22:21:33,734 INFO org.apache.hadoop.yarn.server.resourcemanager.ClientRMService: Allocated new applicationId: 7
2013-08-05 22:21:33,891 INFO org.apache.hadoop.yarn.server.resourcemanager.ClientRMService: Allocated new applicationId: 8
2013-08-05 22:21:34,319 INFO org.apache.hadoop.yarn.server.resourcemanager.ClientRMService: Allocated new applicationId: 9
2013-08-05 22:21:34,346 INFO org.apache.hadoop.yarn.server.resourcemanager.ClientRMService: Allocated new applicationId: 10
2013-08-05 22:21:35,202 INFO org.apache.hadoop.yarn.server.resourcemanager.ClientRMService: Storing Application with id application_1375740621345_0006
2013-08-05 22:21:35,202 INFO org.apache.hadoop.yarn.server.resourcemanager.recovery.RMStateStore: Storing info for app: application_1375740621345_0006
2013-08-05 22:21:35,202 INFO org.apache.hadoop.yarn.server.resourcemanager.ClientRMService: Application with id 6 submitted by user ubuntu
2013-08-05 22:21:35,202 INFO org.apache.hadoop.yarn.server.resourcemanager.RMAuditLogger: USER=ubuntu	IP=192.168.100.3	OPERATION=Submit Application Request	TARGET=ClientRMService	RESULT=SUCCESS	APPID=application_1375740621345_0006
2013-08-05 22:21:35,203 INFO org.apache.hadoop.yarn.server.resourcemanager.rmapp.RMAppImpl: application_1375740621345_0006 State change from NEW to SUBMITTED
2013-08-05 22:21:35,203 INFO org.apache.hadoop.yarn.server.resourcemanager.ApplicationMasterService: Registering appattempt_1375740621345_0006_000001
2013-08-05 22:21:35,203 INFO org.apache.hadoop.yarn.server.resourcemanager.rmapp.attempt.RMAppAttemptImpl: appattempt_1375740621345_0006_000001 State change from NEW to SUBMITTED
2013-08-05 22:21:35,205 INFO org.apache.hadoop.yarn.server.resourcemanager.scheduler.capacity.LeafQueue: Application application_1375740621345_0006 from user: ubuntu activated in queue: default
2013-08-05 22:21:35,205 INFO org.apache.hadoop.yarn.server.resourcemanager.scheduler.capacity.LeafQueue: Application added - appId: application_1375740621345_0006 user: org.apache.hadoop.yarn.server.resourcemanager.scheduler.capacity.LeafQueue$User@bc7f85d, leaf-queue: default #user-pending-applications: 0 #user-active-applications: 1 #queue-pending-applications: 0 #queue-active-applications: 1
2013-08-05 22:21:35,205 INFO org.apache.hadoop.yarn.server.resourcemanager.scheduler.capacity.ParentQueue: Application added - appId: application_1375740621345_0006 user: ubuntu leaf-queue of parent: root #applications: 1
2013-08-05 22:21:35,205 INFO org.apache.hadoop.yarn.server.resourcemanager.scheduler.capacity.CapacityScheduler: Application Submission: appattempt_1375740621345_0006_000001, user: ubuntu queue: default: capacity=1.0, absoluteCapacity=1.0, usedResources=<memory:0, vCores:0>usedCapacity=0.0, absoluteUsedCapacity=0.0, numApps=1, numContainers=0, currently active: 1
2013-08-05 22:21:35,205 INFO org.apache.hadoop.yarn.server.resourcemanager.rmapp.attempt.RMAppAttemptImpl: appattempt_1375740621345_0006_000001 State change from SUBMITTED to SCHEDULED
2013-08-05 22:21:35,206 INFO org.apache.hadoop.yarn.server.resourcemanager.rmapp.RMAppImpl: application_1375740621345_0006 State change from SUBMITTED to ACCEPTED
2013-08-05 22:21:35,303 INFO org.apache.hadoop.yarn.server.resourcemanager.rmcontainer.RMContainerImpl: container_1375740621345_0006_01_000001 Container Transitioned from NEW to ALLOCATED
2013-08-05 22:21:35,303 INFO org.apache.hadoop.yarn.server.resourcemanager.RMAuditLogger: USER=ubuntu	OPERATION=AM Allocated Container	TARGET=SchedulerApp	RESULT=SUCCESS	APPID=application_1375740621345_0006	CONTAINERID=container_1375740621345_0006_01_000001
2013-08-05 22:21:35,304 INFO org.apache.hadoop.yarn.server.resourcemanager.scheduler.common.fica.FiCaSchedulerNode: Assigned container container_1375740621345_0006_01_000001 of capacity <memory:2048, vCores:1> on host hadoop-100-4:50425, which currently has 1 containers, <memory:2048, vCores:1> used and <memory:6144, vCores:15> available
2013-08-05 22:21:35,304 INFO org.apache.hadoop.yarn.server.resourcemanager.scheduler.capacity.LeafQueue: assignedContainer application=application_1375740621345_0006 container=Container: [ContainerId: container_1375740621345_0006_01_000001, NodeId: hadoop-100-4:50425, NodeHttpAddress: hadoop-100-4:8042, Resource: <memory:2048, vCores:1>, Priority: 0, State: NEW, Token: null, Status: container_id {, app_attempt_id {, application_id {, id: 6, cluster_timestamp: 1375740621345, }, attemptId: 1, }, id: 1, }, state: C_NEW, ] containerId=container_1375740621345_0006_01_000001 queue=default: capacity=1.0, absoluteCapacity=1.0, usedResources=<memory:0, vCores:0>usedCapacity=0.0, absoluteUsedCapacity=0.0, numApps=1, numContainers=0 usedCapacity=0.0 absoluteUsedCapacity=0.0 used=<memory:0, vCores:0> cluster=<memory:49152, vCores:96>
2013-08-05 22:21:35,304 INFO org.apache.hadoop.yarn.server.resourcemanager.scheduler.capacity.ParentQueue: Re-sorting queues since queue: root.default stats: default: capacity=1.0, absoluteCapacity=1.0, usedResources=<memory:2048, vCores:1>usedCapacity=0.041666668, absoluteUsedCapacity=0.041666668, numApps=1, numContainers=1
2013-08-05 22:21:35,306 INFO org.apache.hadoop.yarn.server.resourcemanager.scheduler.capacity.ParentQueue: assignedContainer queue=root usedCapacity=0.041666668 absoluteUsedCapacity=0.041666668 used=<memory:2048, vCores:1> cluster=<memory:49152, vCores:96>
2013-08-05 22:21:35,307 INFO org.apache.hadoop.yarn.server.resourcemanager.rmcontainer.RMContainerImpl: container_1375740621345_0006_01_000001 Container Transitioned from ALLOCATED to ACQUIRED
2013-08-05 22:21:35,309 INFO org.apache.hadoop.yarn.server.resourcemanager.rmapp.attempt.RMAppAttemptImpl: Storing attempt: AppId: application_1375740621345_0006 AttemptId: appattempt_1375740621345_0006_000001 MasterContainer: Container: [ContainerId: container_1375740621345_0006_01_000001, NodeId: hadoop-100-4:50425, NodeHttpAddress: hadoop-100-4:8042, Resource: <memory:2048, vCores:1>, Priority: 0, State: NEW, Token: null, Status: container_id {, app_attempt_id {, application_id {, id: 6, cluster_timestamp: 1375740621345, }, attemptId: 1, }, id: 1, }, state: C_NEW, ]
2013-08-05 22:21:35,309 INFO org.apache.hadoop.yarn.server.resourcemanager.recovery.RMStateStore: Storing info for attempt: appattempt_1375740621345_0006_000001
2013-08-05 22:21:35,309 INFO org.apache.hadoop.yarn.server.resourcemanager.rmapp.attempt.RMAppAttemptImpl: appattempt_1375740621345_0006_000001 State change from SCHEDULED to ALLOCATED_SAVING
2013-08-05 22:21:35,310 INFO org.apache.hadoop.yarn.server.resourcemanager.rmapp.attempt.RMAppAttemptImpl: appattempt_1375740621345_0006_000001 State change from ALLOCATED_SAVING to ALLOCATED
2013-08-05 22:21:35,311 INFO org.apache.hadoop.yarn.server.resourcemanager.amlauncher.AMLauncher: Launching masterappattempt_1375740621345_0006_000001
2013-08-05 22:21:35,313 INFO org.apache.hadoop.yarn.server.resourcemanager.amlauncher.AMLauncher: Setting up container Container: [ContainerId: container_1375740621345_0006_01_000001, NodeId: hadoop-100-4:50425, NodeHttpAddress: hadoop-100-4:8042, Resource: <memory:2048, vCores:1>, Priority: 0, State: NEW, Token: null, Status: container_id {, app_attempt_id {, application_id {, id: 6, cluster_timestamp: 1375740621345, }, attemptId: 1, }, id: 1, }, state: C_NEW, ] for AM appattempt_1375740621345_0006_000001
2013-08-05 22:21:35,313 INFO org.apache.hadoop.yarn.server.resourcemanager.amlauncher.AMLauncher: Command to launch container container_1375740621345_0006_01_000001 : $JAVA_HOME/bin/java -Dlog4j.configuration=container-log4j.properties -Dyarn.app.mapreduce.container.log.dir=<LOG_DIR> -Dyarn.app.mapreduce.container.log.filesize=0 -Dhadoop.root.logger=INFO,CLA  -Xmx1024m org.apache.hadoop.mapreduce.v2.app.MRAppMaster 1><LOG_DIR>/stdout 2><LOG_DIR>/stderr 
2013-08-05 22:21:35,332 INFO org.apache.hadoop.yarn.server.resourcemanager.amlauncher.AMLauncher: Done launching container Container: [ContainerId: container_1375740621345_0006_01_000001, NodeId: hadoop-100-4:50425, NodeHttpAddress: hadoop-100-4:8042, Resource: <memory:2048, vCores:1>, Priority: 0, State: NEW, Token: null, Status: container_id {, app_attempt_id {, application_id {, id: 6, cluster_timestamp: 1375740621345, }, attemptId: 1, }, id: 1, }, state: C_NEW, ] for AM appattempt_1375740621345_0006_000001
2013-08-05 22:21:35,333 INFO org.apache.hadoop.yarn.server.resourcemanager.rmapp.attempt.RMAppAttemptImpl: appattempt_1375740621345_0006_000001 State change from ALLOCATED to LAUNCHED
2013-08-05 22:21:35,407 INFO org.apache.hadoop.yarn.server.resourcemanager.ClientRMService: Storing Application with id application_1375740621345_0007
2013-08-05 22:21:35,407 INFO org.apache.hadoop.yarn.server.resourcemanager.recovery.RMStateStore: Storing info for app: application_1375740621345_0007
2013-08-05 22:21:35,407 INFO org.apache.hadoop.yarn.server.resourcemanager.ClientRMService: Application with id 7 submitted by user ubuntu
2013-08-05 22:21:35,408 INFO org.apache.hadoop.yarn.server.resourcemanager.RMAuditLogger: USER=ubuntu	IP=192.168.100.3	OPERATION=Submit Application Request	TARGET=ClientRMService	RESULT=SUCCESS	APPID=application_1375740621345_0007
2013-08-05 22:21:35,414 INFO org.apache.hadoop.yarn.server.resourcemanager.rmapp.RMAppImpl: application_1375740621345_0007 State change from NEW to SUBMITTED
2013-08-05 22:21:35,414 INFO org.apache.hadoop.yarn.server.resourcemanager.ApplicationMasterService: Registering appattempt_1375740621345_0007_000001
2013-08-05 22:21:35,414 INFO org.apache.hadoop.yarn.server.resourcemanager.rmapp.attempt.RMAppAttemptImpl: appattempt_1375740621345_0007_000001 State change from NEW to SUBMITTED
2013-08-05 22:21:35,414 INFO org.apache.hadoop.yarn.server.resourcemanager.scheduler.capacity.LeafQueue: Application application_1375740621345_0007 from user: ubuntu activated in queue: default
2013-08-05 22:21:35,414 INFO org.apache.hadoop.yarn.server.resourcemanager.scheduler.capacity.LeafQueue: Application added - appId: application_1375740621345_0007 user: org.apache.hadoop.yarn.server.resourcemanager.scheduler.capacity.LeafQueue$User@bc7f85d, leaf-queue: default #user-pending-applications: 0 #user-active-applications: 2 #queue-pending-applications: 0 #queue-active-applications: 2
2013-08-05 22:21:35,414 INFO org.apache.hadoop.yarn.server.resourcemanager.scheduler.capacity.ParentQueue: Application added - appId: application_1375740621345_0007 user: ubuntu leaf-queue of parent: root #applications: 2
2013-08-05 22:21:35,414 INFO org.apache.hadoop.yarn.server.resourcemanager.scheduler.capacity.CapacityScheduler: Application Submission: appattempt_1375740621345_0007_000001, user: ubuntu queue: default: capacity=1.0, absoluteCapacity=1.0, usedResources=<memory:2048, vCores:1>usedCapacity=0.041666668, absoluteUsedCapacity=0.041666668, numApps=2, numContainers=1, currently active: 2
2013-08-05 22:21:35,415 INFO org.apache.hadoop.yarn.server.resourcemanager.rmapp.attempt.RMAppAttemptImpl: appattempt_1375740621345_0007_000001 State change from SUBMITTED to SCHEDULED
2013-08-05 22:21:35,415 INFO org.apache.hadoop.yarn.server.resourcemanager.rmapp.RMAppImpl: application_1375740621345_0007 State change from SUBMITTED to ACCEPTED
2013-08-05 22:21:35,497 INFO org.apache.hadoop.yarn.server.resourcemanager.rmcontainer.RMContainerImpl: container_1375740621345_0007_01_000001 Container Transitioned from NEW to ALLOCATED
2013-08-05 22:21:35,498 INFO org.apache.hadoop.yarn.server.resourcemanager.RMAuditLogger: USER=ubuntu	OPERATION=AM Allocated Container	TARGET=SchedulerApp	RESULT=SUCCESS	APPID=application_1375740621345_0007	CONTAINERID=container_1375740621345_0007_01_000001
2013-08-05 22:21:35,498 INFO org.apache.hadoop.yarn.server.resourcemanager.scheduler.common.fica.FiCaSchedulerNode: Assigned container container_1375740621345_0007_01_000001 of capacity <memory:2048, vCores:1> on host hadoop-100-2:37374, which currently has 1 containers, <memory:2048, vCores:1> used and <memory:6144, vCores:15> available
2013-08-05 22:21:35,498 INFO org.apache.hadoop.yarn.server.resourcemanager.scheduler.capacity.LeafQueue: assignedContainer application=application_1375740621345_0007 container=Container: [ContainerId: container_1375740621345_0007_01_000001, NodeId: hadoop-100-2:37374, NodeHttpAddress: hadoop-100-2:8042, Resource: <memory:2048, vCores:1>, Priority: 0, State: NEW, Token: null, Status: container_id {, app_attempt_id {, application_id {, id: 7, cluster_timestamp: 1375740621345, }, attemptId: 1, }, id: 1, }, state: C_NEW, ] containerId=container_1375740621345_0007_01_000001 queue=default: capacity=1.0, absoluteCapacity=1.0, usedResources=<memory:2048, vCores:1>usedCapacity=0.041666668, absoluteUsedCapacity=0.041666668, numApps=2, numContainers=1 usedCapacity=0.041666668 absoluteUsedCapacity=0.041666668 used=<memory:2048, vCores:1> cluster=<memory:49152, vCores:96>
2013-08-05 22:21:35,498 INFO org.apache.hadoop.yarn.server.resourcemanager.scheduler.capacity.ParentQueue: Re-sorting queues since queue: root.default stats: default: capacity=1.0, absoluteCapacity=1.0, usedResources=<memory:4096, vCores:2>usedCapacity=0.083333336, absoluteUsedCapacity=0.083333336, numApps=2, numContainers=2
2013-08-05 22:21:35,499 INFO org.apache.hadoop.yarn.server.resourcemanager.scheduler.capacity.ParentQueue: assignedContainer queue=root usedCapacity=0.083333336 absoluteUsedCapacity=0.083333336 used=<memory:4096, vCores:2> cluster=<memory:49152, vCores:96>
2013-08-05 22:21:35,499 INFO org.apache.hadoop.yarn.server.resourcemanager.rmcontainer.RMContainerImpl: container_1375740621345_0007_01_000001 Container Transitioned from ALLOCATED to ACQUIRED
2013-08-05 22:21:35,500 INFO org.apache.hadoop.yarn.server.resourcemanager.rmapp.attempt.RMAppAttemptImpl: Storing attempt: AppId: application_1375740621345_0007 AttemptId: appattempt_1375740621345_0007_000001 MasterContainer: Container: [ContainerId: container_1375740621345_0007_01_000001, NodeId: hadoop-100-2:37374, NodeHttpAddress: hadoop-100-2:8042, Resource: <memory:2048, vCores:1>, Priority: 0, State: NEW, Token: null, Status: container_id {, app_attempt_id {, application_id {, id: 7, cluster_timestamp: 1375740621345, }, attemptId: 1, }, id: 1, }, state: C_NEW, ]
2013-08-05 22:21:35,500 INFO org.apache.hadoop.yarn.server.resourcemanager.rmapp.attempt.RMAppAttemptImpl: appattempt_1375740621345_0007_000001 State change from SCHEDULED to ALLOCATED_SAVING
2013-08-05 22:21:35,500 INFO org.apache.hadoop.yarn.server.resourcemanager.recovery.RMStateStore: Storing info for attempt: appattempt_1375740621345_0007_000001
2013-08-05 22:21:35,502 INFO org.apache.hadoop.yarn.server.resourcemanager.rmapp.attempt.RMAppAttemptImpl: appattempt_1375740621345_0007_000001 State change from ALLOCATED_SAVING to ALLOCATED
2013-08-05 22:21:35,502 INFO org.apache.hadoop.yarn.server.resourcemanager.amlauncher.AMLauncher: Launching masterappattempt_1375740621345_0007_000001
2013-08-05 22:21:35,503 INFO org.apache.hadoop.yarn.server.resourcemanager.amlauncher.AMLauncher: Setting up container Container: [ContainerId: container_1375740621345_0007_01_000001, NodeId: hadoop-100-2:37374, NodeHttpAddress: hadoop-100-2:8042, Resource: <memory:2048, vCores:1>, Priority: 0, State: NEW, Token: null, Status: container_id {, app_attempt_id {, application_id {, id: 7, cluster_timestamp: 1375740621345, }, attemptId: 1, }, id: 1, }, state: C_NEW, ] for AM appattempt_1375740621345_0007_000001
2013-08-05 22:21:35,504 INFO org.apache.hadoop.yarn.server.resourcemanager.amlauncher.AMLauncher: Command to launch container container_1375740621345_0007_01_000001 : $JAVA_HOME/bin/java -Dlog4j.configuration=container-log4j.properties -Dyarn.app.mapreduce.container.log.dir=<LOG_DIR> -Dyarn.app.mapreduce.container.log.filesize=0 -Dhadoop.root.logger=INFO,CLA  -Xmx1024m org.apache.hadoop.mapreduce.v2.app.MRAppMaster 1><LOG_DIR>/stdout 2><LOG_DIR>/stderr 
2013-08-05 22:21:35,524 INFO org.apache.hadoop.yarn.server.resourcemanager.ClientRMService: Storing Application with id application_1375740621345_0008
2013-08-05 22:21:35,524 INFO org.apache.hadoop.yarn.server.resourcemanager.recovery.RMStateStore: Storing info for app: application_1375740621345_0008
2013-08-05 22:21:35,524 INFO org.apache.hadoop.yarn.server.resourcemanager.ClientRMService: Application with id 8 submitted by user ubuntu
2013-08-05 22:21:35,524 INFO org.apache.hadoop.yarn.server.resourcemanager.RMAuditLogger: USER=ubuntu	IP=192.168.100.3	OPERATION=Submit Application Request	TARGET=ClientRMService	RESULT=SUCCESS	APPID=application_1375740621345_0008
2013-08-05 22:21:35,525 INFO org.apache.hadoop.yarn.server.resourcemanager.rmapp.RMAppImpl: application_1375740621345_0008 State change from NEW to SUBMITTED
2013-08-05 22:21:35,525 INFO org.apache.hadoop.yarn.server.resourcemanager.ApplicationMasterService: Registering appattempt_1375740621345_0008_000001
2013-08-05 22:21:35,527 INFO org.apache.hadoop.yarn.server.resourcemanager.rmapp.attempt.RMAppAttemptImpl: appattempt_1375740621345_0008_000001 State change from NEW to SUBMITTED
2013-08-05 22:21:35,530 INFO org.apache.hadoop.yarn.server.resourcemanager.scheduler.capacity.LeafQueue: Application application_1375740621345_0008 from user: ubuntu activated in queue: default
2013-08-05 22:21:35,530 INFO org.apache.hadoop.yarn.server.resourcemanager.scheduler.capacity.LeafQueue: Application added - appId: application_1375740621345_0008 user: org.apache.hadoop.yarn.server.resourcemanager.scheduler.capacity.LeafQueue$User@bc7f85d, leaf-queue: default #user-pending-applications: 0 #user-active-applications: 3 #queue-pending-applications: 0 #queue-active-applications: 3
2013-08-05 22:21:35,530 INFO org.apache.hadoop.yarn.server.resourcemanager.scheduler.capacity.ParentQueue: Application added - appId: application_1375740621345_0008 user: ubuntu leaf-queue of parent: root #applications: 3
2013-08-05 22:21:35,530 INFO org.apache.hadoop.yarn.server.resourcemanager.scheduler.capacity.CapacityScheduler: Application Submission: appattempt_1375740621345_0008_000001, user: ubuntu queue: default: capacity=1.0, absoluteCapacity=1.0, usedResources=<memory:4096, vCores:2>usedCapacity=0.083333336, absoluteUsedCapacity=0.083333336, numApps=3, numContainers=2, currently active: 3
2013-08-05 22:21:35,530 INFO org.apache.hadoop.yarn.server.resourcemanager.rmapp.attempt.RMAppAttemptImpl: appattempt_1375740621345_0008_000001 State change from SUBMITTED to SCHEDULED
2013-08-05 22:21:35,531 INFO org.apache.hadoop.yarn.server.resourcemanager.rmapp.RMAppImpl: application_1375740621345_0008 State change from SUBMITTED to ACCEPTED
2013-08-05 22:21:35,542 INFO org.apache.hadoop.yarn.server.resourcemanager.amlauncher.AMLauncher: Done launching container Container: [ContainerId: container_1375740621345_0007_01_000001, NodeId: hadoop-100-2:37374, NodeHttpAddress: hadoop-100-2:8042, Resource: <memory:2048, vCores:1>, Priority: 0, State: NEW, Token: null, Status: container_id {, app_attempt_id {, application_id {, id: 7, cluster_timestamp: 1375740621345, }, attemptId: 1, }, id: 1, }, state: C_NEW, ] for AM appattempt_1375740621345_0007_000001
2013-08-05 22:21:35,542 INFO org.apache.hadoop.yarn.server.resourcemanager.rmapp.attempt.RMAppAttemptImpl: appattempt_1375740621345_0007_000001 State change from ALLOCATED to LAUNCHED
2013-08-05 22:21:35,582 INFO org.apache.hadoop.yarn.server.resourcemanager.rmcontainer.RMContainerImpl: container_1375740621345_0008_01_000001 Container Transitioned from NEW to ALLOCATED
2013-08-05 22:21:35,583 INFO org.apache.hadoop.yarn.server.resourcemanager.RMAuditLogger: USER=ubuntu	OPERATION=AM Allocated Container	TARGET=SchedulerApp	RESULT=SUCCESS	APPID=application_1375740621345_0008	CONTAINERID=container_1375740621345_0008_01_000001
2013-08-05 22:21:35,583 INFO org.apache.hadoop.yarn.server.resourcemanager.scheduler.common.fica.FiCaSchedulerNode: Assigned container container_1375740621345_0008_01_000001 of capacity <memory:2048, vCores:1> on host hadoop-100-6:42294, which currently has 1 containers, <memory:2048, vCores:1> used and <memory:6144, vCores:15> available
2013-08-05 22:21:35,584 INFO org.apache.hadoop.yarn.server.resourcemanager.scheduler.capacity.LeafQueue: assignedContainer application=application_1375740621345_0008 container=Container: [ContainerId: container_1375740621345_0008_01_000001, NodeId: hadoop-100-6:42294, NodeHttpAddress: hadoop-100-6:8042, Resource: <memory:2048, vCores:1>, Priority: 0, State: NEW, Token: null, Status: container_id {, app_attempt_id {, application_id {, id: 8, cluster_timestamp: 1375740621345, }, attemptId: 1, }, id: 1, }, state: C_NEW, ] containerId=container_1375740621345_0008_01_000001 queue=default: capacity=1.0, absoluteCapacity=1.0, usedResources=<memory:4096, vCores:2>usedCapacity=0.083333336, absoluteUsedCapacity=0.083333336, numApps=3, numContainers=2 usedCapacity=0.083333336 absoluteUsedCapacity=0.083333336 used=<memory:4096, vCores:2> cluster=<memory:49152, vCores:96>
2013-08-05 22:21:35,584 INFO org.apache.hadoop.yarn.server.resourcemanager.scheduler.capacity.ParentQueue: Re-sorting queues since queue: root.default stats: default: capacity=1.0, absoluteCapacity=1.0, usedResources=<memory:6144, vCores:3>usedCapacity=0.125, absoluteUsedCapacity=0.125, numApps=3, numContainers=3
2013-08-05 22:21:35,585 INFO org.apache.hadoop.yarn.server.resourcemanager.scheduler.capacity.ParentQueue: assignedContainer queue=root usedCapacity=0.125 absoluteUsedCapacity=0.125 used=<memory:6144, vCores:3> cluster=<memory:49152, vCores:96>
2013-08-05 22:21:35,585 INFO org.apache.hadoop.yarn.server.resourcemanager.rmcontainer.RMContainerImpl: container_1375740621345_0008_01_000001 Container Transitioned from ALLOCATED to ACQUIRED
2013-08-05 22:21:35,586 INFO org.apache.hadoop.yarn.server.resourcemanager.rmapp.attempt.RMAppAttemptImpl: Storing attempt: AppId: application_1375740621345_0008 AttemptId: appattempt_1375740621345_0008_000001 MasterContainer: Container: [ContainerId: container_1375740621345_0008_01_000001, NodeId: hadoop-100-6:42294, NodeHttpAddress: hadoop-100-6:8042, Resource: <memory:2048, vCores:1>, Priority: 0, State: NEW, Token: null, Status: container_id {, app_attempt_id {, application_id {, id: 8, cluster_timestamp: 1375740621345, }, attemptId: 1, }, id: 1, }, state: C_NEW, ]
2013-08-05 22:21:35,586 INFO org.apache.hadoop.yarn.server.resourcemanager.rmapp.attempt.RMAppAttemptImpl: appattempt_1375740621345_0008_000001 State change from SCHEDULED to ALLOCATED_SAVING
2013-08-05 22:21:35,586 INFO org.apache.hadoop.yarn.server.resourcemanager.recovery.RMStateStore: Storing info for attempt: appattempt_1375740621345_0008_000001
2013-08-05 22:21:35,588 INFO org.apache.hadoop.yarn.server.resourcemanager.rmapp.attempt.RMAppAttemptImpl: appattempt_1375740621345_0008_000001 State change from ALLOCATED_SAVING to ALLOCATED
2013-08-05 22:21:35,588 INFO org.apache.hadoop.yarn.server.resourcemanager.amlauncher.AMLauncher: Launching masterappattempt_1375740621345_0008_000001
2013-08-05 22:21:35,589 INFO org.apache.hadoop.yarn.server.resourcemanager.amlauncher.AMLauncher: Setting up container Container: [ContainerId: container_1375740621345_0008_01_000001, NodeId: hadoop-100-6:42294, NodeHttpAddress: hadoop-100-6:8042, Resource: <memory:2048, vCores:1>, Priority: 0, State: NEW, Token: null, Status: container_id {, app_attempt_id {, application_id {, id: 8, cluster_timestamp: 1375740621345, }, attemptId: 1, }, id: 1, }, state: C_NEW, ] for AM appattempt_1375740621345_0008_000001
2013-08-05 22:21:35,590 INFO org.apache.hadoop.yarn.server.resourcemanager.amlauncher.AMLauncher: Command to launch container container_1375740621345_0008_01_000001 : $JAVA_HOME/bin/java -Dlog4j.configuration=container-log4j.properties -Dyarn.app.mapreduce.container.log.dir=<LOG_DIR> -Dyarn.app.mapreduce.container.log.filesize=0 -Dhadoop.root.logger=INFO,CLA  -Xmx1024m org.apache.hadoop.mapreduce.v2.app.MRAppMaster 1><LOG_DIR>/stdout 2><LOG_DIR>/stderr 
2013-08-05 22:21:35,624 INFO org.apache.hadoop.yarn.server.resourcemanager.amlauncher.AMLauncher: Done launching container Container: [ContainerId: container_1375740621345_0008_01_000001, NodeId: hadoop-100-6:42294, NodeHttpAddress: hadoop-100-6:8042, Resource: <memory:2048, vCores:1>, Priority: 0, State: NEW, Token: null, Status: container_id {, app_attempt_id {, application_id {, id: 8, cluster_timestamp: 1375740621345, }, attemptId: 1, }, id: 1, }, state: C_NEW, ] for AM appattempt_1375740621345_0008_000001
2013-08-05 22:21:35,625 INFO org.apache.hadoop.yarn.server.resourcemanager.rmapp.attempt.RMAppAttemptImpl: appattempt_1375740621345_0008_000001 State change from ALLOCATED to LAUNCHED
2013-08-05 22:21:35,731 INFO org.apache.hadoop.yarn.server.resourcemanager.ClientRMService: Storing Application with id application_1375740621345_0010
2013-08-05 22:21:35,732 INFO org.apache.hadoop.yarn.server.resourcemanager.recovery.RMStateStore: Storing info for app: application_1375740621345_0010
2013-08-05 22:21:35,732 INFO org.apache.hadoop.yarn.server.resourcemanager.ClientRMService: Application with id 10 submitted by user ubuntu
2013-08-05 22:21:35,732 INFO org.apache.hadoop.yarn.server.resourcemanager.RMAuditLogger: USER=ubuntu	IP=192.168.100.3	OPERATION=Submit Application Request	TARGET=ClientRMService	RESULT=SUCCESS	APPID=application_1375740621345_0010
2013-08-05 22:21:35,731 INFO org.apache.hadoop.yarn.server.resourcemanager.rmapp.RMAppImpl: application_1375740621345_0010 State change from NEW to SUBMITTED
2013-08-05 22:21:35,732 INFO org.apache.hadoop.yarn.server.resourcemanager.ApplicationMasterService: Registering appattempt_1375740621345_0010_000001
2013-08-05 22:21:35,732 INFO org.apache.hadoop.yarn.server.resourcemanager.rmapp.attempt.RMAppAttemptImpl: appattempt_1375740621345_0010_000001 State change from NEW to SUBMITTED
2013-08-05 22:21:35,733 INFO org.apache.hadoop.yarn.server.resourcemanager.scheduler.capacity.LeafQueue: Application application_1375740621345_0010 from user: ubuntu activated in queue: default
2013-08-05 22:21:35,733 INFO org.apache.hadoop.yarn.server.resourcemanager.scheduler.capacity.LeafQueue: Application added - appId: application_1375740621345_0010 user: org.apache.hadoop.yarn.server.resourcemanager.scheduler.capacity.LeafQueue$User@bc7f85d, leaf-queue: default #user-pending-applications: 0 #user-active-applications: 4 #queue-pending-applications: 0 #queue-active-applications: 4
2013-08-05 22:21:35,733 INFO org.apache.hadoop.yarn.server.resourcemanager.scheduler.capacity.ParentQueue: Application added - appId: application_1375740621345_0010 user: ubuntu leaf-queue of parent: root #applications: 4
2013-08-05 22:21:35,733 INFO org.apache.hadoop.yarn.server.resourcemanager.scheduler.capacity.CapacityScheduler: Application Submission: appattempt_1375740621345_0010_000001, user: ubuntu queue: default: capacity=1.0, absoluteCapacity=1.0, usedResources=<memory:6144, vCores:3>usedCapacity=0.125, absoluteUsedCapacity=0.125, numApps=4, numContainers=3, currently active: 4
2013-08-05 22:21:35,733 INFO org.apache.hadoop.yarn.server.resourcemanager.rmapp.attempt.RMAppAttemptImpl: appattempt_1375740621345_0010_000001 State change from SUBMITTED to SCHEDULED
2013-08-05 22:21:35,733 INFO org.apache.hadoop.yarn.server.resourcemanager.rmapp.RMAppImpl: application_1375740621345_0010 State change from SUBMITTED to ACCEPTED
2013-08-05 22:21:35,937 INFO org.apache.hadoop.yarn.server.resourcemanager.ClientRMService: Storing Application with id application_1375740621345_0009
2013-08-05 22:21:35,937 INFO org.apache.hadoop.yarn.server.resourcemanager.recovery.RMStateStore: Storing info for app: application_1375740621345_0009
2013-08-05 22:21:35,937 INFO org.apache.hadoop.yarn.server.resourcemanager.ClientRMService: Application with id 9 submitted by user ubuntu
2013-08-05 22:21:35,937 INFO org.apache.hadoop.yarn.server.resourcemanager.RMAuditLogger: USER=ubuntu	IP=192.168.100.3	OPERATION=Submit Application Request	TARGET=ClientRMService	RESULT=SUCCESS	APPID=application_1375740621345_0009
2013-08-05 22:21:35,938 INFO org.apache.hadoop.yarn.server.resourcemanager.rmapp.RMAppImpl: application_1375740621345_0009 State change from NEW to SUBMITTED
2013-08-05 22:21:35,939 INFO org.apache.hadoop.yarn.server.resourcemanager.ApplicationMasterService: Registering appattempt_1375740621345_0009_000001
2013-08-05 22:21:35,939 INFO org.apache.hadoop.yarn.server.resourcemanager.rmapp.attempt.RMAppAttemptImpl: appattempt_1375740621345_0009_000001 State change from NEW to SUBMITTED
2013-08-05 22:21:35,939 INFO org.apache.hadoop.yarn.server.resourcemanager.scheduler.capacity.LeafQueue: Application application_1375740621345_0009 from user: ubuntu activated in queue: default
2013-08-05 22:21:35,939 INFO org.apache.hadoop.yarn.server.resourcemanager.scheduler.capacity.LeafQueue: Application added - appId: application_1375740621345_0009 user: org.apache.hadoop.yarn.server.resourcemanager.scheduler.capacity.LeafQueue$User@bc7f85d, leaf-queue: default #user-pending-applications: 0 #user-active-applications: 5 #queue-pending-applications: 0 #queue-active-applications: 5
2013-08-05 22:21:35,939 INFO org.apache.hadoop.yarn.server.resourcemanager.scheduler.capacity.ParentQueue: Application added - appId: application_1375740621345_0009 user: ubuntu leaf-queue of parent: root #applications: 5
2013-08-05 22:21:35,939 INFO org.apache.hadoop.yarn.server.resourcemanager.scheduler.capacity.CapacityScheduler: Application Submission: appattempt_1375740621345_0009_000001, user: ubuntu queue: default: capacity=1.0, absoluteCapacity=1.0, usedResources=<memory:6144, vCores:3>usedCapacity=0.125, absoluteUsedCapacity=0.125, numApps=5, numContainers=3, currently active: 5
2013-08-05 22:21:35,939 INFO org.apache.hadoop.yarn.server.resourcemanager.rmapp.attempt.RMAppAttemptImpl: appattempt_1375740621345_0009_000001 State change from SUBMITTED to SCHEDULED
2013-08-05 22:21:35,940 INFO org.apache.hadoop.yarn.server.resourcemanager.rmapp.RMAppImpl: application_1375740621345_0009 State change from SUBMITTED to ACCEPTED
2013-08-05 22:21:36,308 INFO org.apache.hadoop.yarn.server.resourcemanager.rmcontainer.RMContainerImpl: container_1375740621345_0006_01_000001 Container Transitioned from ACQUIRED to RUNNING
2013-08-05 22:21:36,308 INFO org.apache.hadoop.yarn.server.resourcemanager.rmcontainer.RMContainerImpl: container_1375740621345_0009_01_000001 Container Transitioned from NEW to ALLOCATED
2013-08-05 22:21:36,309 INFO org.apache.hadoop.yarn.server.resourcemanager.RMAuditLogger: USER=ubuntu	OPERATION=AM Allocated Container	TARGET=SchedulerApp	RESULT=SUCCESS	APPID=application_1375740621345_0009	CONTAINERID=container_1375740621345_0009_01_000001
2013-08-05 22:21:36,309 INFO org.apache.hadoop.yarn.server.resourcemanager.scheduler.common.fica.FiCaSchedulerNode: Assigned container container_1375740621345_0009_01_000001 of capacity <memory:2048, vCores:1> on host hadoop-100-4:50425, which currently has 2 containers, <memory:4096, vCores:2> used and <memory:4096, vCores:14> available
2013-08-05 22:21:36,310 INFO org.apache.hadoop.yarn.server.resourcemanager.scheduler.capacity.LeafQueue: assignedContainer application=application_1375740621345_0009 container=Container: [ContainerId: container_1375740621345_0009_01_000001, NodeId: hadoop-100-4:50425, NodeHttpAddress: hadoop-100-4:8042, Resource: <memory:2048, vCores:1>, Priority: 0, State: NEW, Token: null, Status: container_id {, app_attempt_id {, application_id {, id: 9, cluster_timestamp: 1375740621345, }, attemptId: 1, }, id: 1, }, state: C_NEW, ] containerId=container_1375740621345_0009_01_000001 queue=default: capacity=1.0, absoluteCapacity=1.0, usedResources=<memory:6144, vCores:3>usedCapacity=0.125, absoluteUsedCapacity=0.125, numApps=5, numContainers=3 usedCapacity=0.125 absoluteUsedCapacity=0.125 used=<memory:6144, vCores:3> cluster=<memory:49152, vCores:96>
2013-08-05 22:21:36,310 INFO org.apache.hadoop.yarn.server.resourcemanager.scheduler.capacity.ParentQueue: Re-sorting queues since queue: root.default stats: default: capacity=1.0, absoluteCapacity=1.0, usedResources=<memory:8192, vCores:4>usedCapacity=0.16666667, absoluteUsedCapacity=0.16666667, numApps=5, numContainers=4
2013-08-05 22:21:36,311 INFO org.apache.hadoop.yarn.server.resourcemanager.scheduler.capacity.ParentQueue: assignedContainer queue=root usedCapacity=0.16666667 absoluteUsedCapacity=0.16666667 used=<memory:8192, vCores:4> cluster=<memory:49152, vCores:96>
2013-08-05 22:21:36,312 INFO org.apache.hadoop.yarn.server.resourcemanager.rmcontainer.RMContainerImpl: container_1375740621345_0009_01_000001 Container Transitioned from ALLOCATED to ACQUIRED
2013-08-05 22:21:36,314 INFO org.apache.hadoop.yarn.server.resourcemanager.rmapp.attempt.RMAppAttemptImpl: Storing attempt: AppId: application_1375740621345_0009 AttemptId: appattempt_1375740621345_0009_000001 MasterContainer: Container: [ContainerId: container_1375740621345_0009_01_000001, NodeId: hadoop-100-4:50425, NodeHttpAddress: hadoop-100-4:8042, Resource: <memory:2048, vCores:1>, Priority: 0, State: NEW, Token: null, Status: container_id {, app_attempt_id {, application_id {, id: 9, cluster_timestamp: 1375740621345, }, attemptId: 1, }, id: 1, }, state: C_NEW, ]
2013-08-05 22:21:36,315 INFO org.apache.hadoop.yarn.server.resourcemanager.recovery.RMStateStore: Storing info for attempt: appattempt_1375740621345_0009_000001
2013-08-05 22:21:36,315 INFO org.apache.hadoop.yarn.server.resourcemanager.rmapp.attempt.RMAppAttemptImpl: appattempt_1375740621345_0009_000001 State change from SCHEDULED to ALLOCATED_SAVING
2013-08-05 22:21:36,316 INFO org.apache.hadoop.yarn.server.resourcemanager.rmapp.attempt.RMAppAttemptImpl: appattempt_1375740621345_0009_000001 State change from ALLOCATED_SAVING to ALLOCATED
2013-08-05 22:21:36,316 INFO org.apache.hadoop.yarn.server.resourcemanager.amlauncher.AMLauncher: Launching masterappattempt_1375740621345_0009_000001
2013-08-05 22:21:36,318 INFO org.apache.hadoop.yarn.server.resourcemanager.amlauncher.AMLauncher: Setting up container Container: [ContainerId: container_1375740621345_0009_01_000001, NodeId: hadoop-100-4:50425, NodeHttpAddress: hadoop-100-4:8042, Resource: <memory:2048, vCores:1>, Priority: 0, State: NEW, Token: null, Status: container_id {, app_attempt_id {, application_id {, id: 9, cluster_timestamp: 1375740621345, }, attemptId: 1, }, id: 1, }, state: C_NEW, ] for AM appattempt_1375740621345_0009_000001
2013-08-05 22:21:36,319 INFO org.apache.hadoop.yarn.server.resourcemanager.amlauncher.AMLauncher: Command to launch container container_1375740621345_0009_01_000001 : $JAVA_HOME/bin/java -Dlog4j.configuration=container-log4j.properties -Dyarn.app.mapreduce.container.log.dir=<LOG_DIR> -Dyarn.app.mapreduce.container.log.filesize=0 -Dhadoop.root.logger=INFO,CLA  -Xmx1024m org.apache.hadoop.mapreduce.v2.app.MRAppMaster 1><LOG_DIR>/stdout 2><LOG_DIR>/stderr 
2013-08-05 22:21:36,332 INFO org.apache.hadoop.yarn.server.resourcemanager.amlauncher.AMLauncher: Done launching container Container: [ContainerId: container_1375740621345_0009_01_000001, NodeId: hadoop-100-4:50425, NodeHttpAddress: hadoop-100-4:8042, Resource: <memory:2048, vCores:1>, Priority: 0, State: NEW, Token: null, Status: container_id {, app_attempt_id {, application_id {, id: 9, cluster_timestamp: 1375740621345, }, attemptId: 1, }, id: 1, }, state: C_NEW, ] for AM appattempt_1375740621345_0009_000001
2013-08-05 22:21:36,333 INFO org.apache.hadoop.yarn.server.resourcemanager.rmapp.attempt.RMAppAttemptImpl: appattempt_1375740621345_0009_000001 State change from ALLOCATED to LAUNCHED
2013-08-05 22:21:36,503 INFO org.apache.hadoop.yarn.server.resourcemanager.rmcontainer.RMContainerImpl: container_1375740621345_0007_01_000001 Container Transitioned from ACQUIRED to RUNNING
2013-08-05 22:21:36,505 INFO org.apache.hadoop.yarn.server.resourcemanager.rmcontainer.RMContainerImpl: container_1375740621345_0010_01_000001 Container Transitioned from NEW to ALLOCATED
2013-08-05 22:21:36,505 INFO org.apache.hadoop.yarn.server.resourcemanager.RMAuditLogger: USER=ubuntu	OPERATION=AM Allocated Container	TARGET=SchedulerApp	RESULT=SUCCESS	APPID=application_1375740621345_0010	CONTAINERID=container_1375740621345_0010_01_000001
2013-08-05 22:21:36,506 INFO org.apache.hadoop.yarn.server.resourcemanager.scheduler.common.fica.FiCaSchedulerNode: Assigned container container_1375740621345_0010_01_000001 of capacity <memory:2048, vCores:1> on host hadoop-100-2:37374, which currently has 2 containers, <memory:4096, vCores:2> used and <memory:4096, vCores:14> available
2013-08-05 22:21:36,507 INFO org.apache.hadoop.yarn.server.resourcemanager.scheduler.capacity.LeafQueue: assignedContainer application=application_1375740621345_0010 container=Container: [ContainerId: container_1375740621345_0010_01_000001, NodeId: hadoop-100-2:37374, NodeHttpAddress: hadoop-100-2:8042, Resource: <memory:2048, vCores:1>, Priority: 0, State: NEW, Token: null, Status: container_id {, app_attempt_id {, application_id {, id: 10, cluster_timestamp: 1375740621345, }, attemptId: 1, }, id: 1, }, state: C_NEW, ] containerId=container_1375740621345_0010_01_000001 queue=default: capacity=1.0, absoluteCapacity=1.0, usedResources=<memory:8192, vCores:4>usedCapacity=0.16666667, absoluteUsedCapacity=0.16666667, numApps=5, numContainers=4 usedCapacity=0.16666667 absoluteUsedCapacity=0.16666667 used=<memory:8192, vCores:4> cluster=<memory:49152, vCores:96>
2013-08-05 22:21:36,507 INFO org.apache.hadoop.yarn.server.resourcemanager.scheduler.capacity.ParentQueue: Re-sorting queues since queue: root.default stats: default: capacity=1.0, absoluteCapacity=1.0, usedResources=<memory:10240, vCores:5>usedCapacity=0.20833333, absoluteUsedCapacity=0.20833333, numApps=5, numContainers=5
2013-08-05 22:21:36,508 INFO org.apache.hadoop.yarn.server.resourcemanager.rmcontainer.RMContainerImpl: container_1375740621345_0010_01_000001 Container Transitioned from ALLOCATED to ACQUIRED
2013-08-05 22:21:36,509 INFO org.apache.hadoop.yarn.server.resourcemanager.scheduler.capacity.ParentQueue: assignedContainer queue=root usedCapacity=0.20833333 absoluteUsedCapacity=0.20833333 used=<memory:10240, vCores:5> cluster=<memory:49152, vCores:96>
2013-08-05 22:21:36,509 INFO org.apache.hadoop.yarn.server.resourcemanager.rmapp.attempt.RMAppAttemptImpl: Storing attempt: AppId: application_1375740621345_0010 AttemptId: appattempt_1375740621345_0010_000001 MasterContainer: Container: [ContainerId: container_1375740621345_0010_01_000001, NodeId: hadoop-100-2:37374, NodeHttpAddress: hadoop-100-2:8042, Resource: <memory:2048, vCores:1>, Priority: 0, State: NEW, Token: null, Status: container_id {, app_attempt_id {, application_id {, id: 10, cluster_timestamp: 1375740621345, }, attemptId: 1, }, id: 1, }, state: C_NEW, ]
2013-08-05 22:21:36,510 INFO org.apache.hadoop.yarn.server.resourcemanager.rmapp.attempt.RMAppAttemptImpl: appattempt_1375740621345_0010_000001 State change from SCHEDULED to ALLOCATED_SAVING
2013-08-05 22:21:36,510 INFO org.apache.hadoop.yarn.server.resourcemanager.recovery.RMStateStore: Storing info for attempt: appattempt_1375740621345_0010_000001
2013-08-05 22:21:36,511 INFO org.apache.hadoop.yarn.server.resourcemanager.rmapp.attempt.RMAppAttemptImpl: appattempt_1375740621345_0010_000001 State change from ALLOCATED_SAVING to ALLOCATED
2013-08-05 22:21:36,511 INFO org.apache.hadoop.yarn.server.resourcemanager.amlauncher.AMLauncher: Launching masterappattempt_1375740621345_0010_000001
2013-08-05 22:21:36,513 INFO org.apache.hadoop.yarn.server.resourcemanager.amlauncher.AMLauncher: Setting up container Container: [ContainerId: container_1375740621345_0010_01_000001, NodeId: hadoop-100-2:37374, NodeHttpAddress: hadoop-100-2:8042, Resource: <memory:2048, vCores:1>, Priority: 0, State: NEW, Token: null, Status: container_id {, app_attempt_id {, application_id {, id: 10, cluster_timestamp: 1375740621345, }, attemptId: 1, }, id: 1, }, state: C_NEW, ] for AM appattempt_1375740621345_0010_000001
2013-08-05 22:21:36,513 INFO org.apache.hadoop.yarn.server.resourcemanager.amlauncher.AMLauncher: Command to launch container container_1375740621345_0010_01_000001 : $JAVA_HOME/bin/java -Dlog4j.configuration=container-log4j.properties -Dyarn.app.mapreduce.container.log.dir=<LOG_DIR> -Dyarn.app.mapreduce.container.log.filesize=0 -Dhadoop.root.logger=INFO,CLA  -Xmx1024m org.apache.hadoop.mapreduce.v2.app.MRAppMaster 1><LOG_DIR>/stdout 2><LOG_DIR>/stderr 
2013-08-05 22:21:36,530 INFO org.apache.hadoop.yarn.server.resourcemanager.amlauncher.AMLauncher: Done launching container Container: [ContainerId: container_1375740621345_0010_01_000001, NodeId: hadoop-100-2:37374, NodeHttpAddress: hadoop-100-2:8042, Resource: <memory:2048, vCores:1>, Priority: 0, State: NEW, Token: null, Status: container_id {, app_attempt_id {, application_id {, id: 10, cluster_timestamp: 1375740621345, }, attemptId: 1, }, id: 1, }, state: C_NEW, ] for AM appattempt_1375740621345_0010_000001
2013-08-05 22:21:36,530 INFO org.apache.hadoop.yarn.server.resourcemanager.rmapp.attempt.RMAppAttemptImpl: appattempt_1375740621345_0010_000001 State change from ALLOCATED to LAUNCHED
2013-08-05 22:21:36,588 INFO org.apache.hadoop.yarn.server.resourcemanager.rmcontainer.RMContainerImpl: container_1375740621345_0008_01_000001 Container Transitioned from ACQUIRED to RUNNING
2013-08-05 22:21:37,318 INFO org.apache.hadoop.yarn.server.resourcemanager.rmcontainer.RMContainerImpl: container_1375740621345_0009_01_000001 Container Transitioned from ACQUIRED to RUNNING
2013-08-05 22:21:37,512 INFO org.apache.hadoop.yarn.server.resourcemanager.rmcontainer.RMContainerImpl: container_1375740621345_0010_01_000001 Container Transitioned from ACQUIRED to RUNNING
2013-08-05 22:21:40,637 INFO org.apache.hadoop.yarn.server.resourcemanager.ApplicationMasterService: AM registration appattempt_1375740621345_0006_000001
2013-08-05 22:21:40,637 INFO org.apache.hadoop.yarn.server.resourcemanager.RMAuditLogger: USER=ubuntu	IP=192.168.100.14	OPERATION=Register App Master	TARGET=ApplicationMasterService	RESULT=SUCCESS	APPID=application_1375740621345_0006	APPATTEMPTID=appattempt_1375740621345_0006_000001
2013-08-05 22:21:40,638 INFO org.apache.hadoop.yarn.server.resourcemanager.rmapp.attempt.RMAppAttemptImpl: appattempt_1375740621345_0006_000001 State change from LAUNCHED to RUNNING
2013-08-05 22:21:40,638 INFO org.apache.hadoop.yarn.server.resourcemanager.rmapp.RMAppImpl: application_1375740621345_0006 State change from ACCEPTED to RUNNING
2013-08-05 22:21:41,439 INFO org.apache.hadoop.yarn.server.resourcemanager.ApplicationMasterService: AM registration appattempt_1375740621345_0007_000001
2013-08-05 22:21:41,439 INFO org.apache.hadoop.yarn.server.resourcemanager.RMAuditLogger: USER=ubuntu	IP=192.168.100.4	OPERATION=Register App Master	TARGET=ApplicationMasterService	RESULT=SUCCESS	APPID=application_1375740621345_0007	APPATTEMPTID=appattempt_1375740621345_0007_000001
2013-08-05 22:21:41,440 INFO org.apache.hadoop.yarn.server.resourcemanager.rmapp.attempt.RMAppAttemptImpl: appattempt_1375740621345_0007_000001 State change from LAUNCHED to RUNNING
2013-08-05 22:21:41,440 INFO org.apache.hadoop.yarn.server.resourcemanager.rmapp.RMAppImpl: application_1375740621345_0007 State change from ACCEPTED to RUNNING
2013-08-05 22:21:41,712 INFO org.apache.hadoop.yarn.server.resourcemanager.rmcontainer.RMContainerImpl: container_1375740621345_0006_01_000002 Container Transitioned from NEW to ALLOCATED
2013-08-05 22:21:41,712 INFO org.apache.hadoop.yarn.server.resourcemanager.RMAuditLogger: USER=ubuntu	OPERATION=AM Allocated Container	TARGET=SchedulerApp	RESULT=SUCCESS	APPID=application_1375740621345_0006	CONTAINERID=container_1375740621345_0006_01_000002
2013-08-05 22:21:41,712 INFO org.apache.hadoop.yarn.server.resourcemanager.scheduler.common.fica.FiCaSchedulerNode: Assigned container container_1375740621345_0006_01_000002 of capacity <memory:1024, vCores:1> on host hadoop-100-3:44102, which currently has 1 containers, <memory:1024, vCores:1> used and <memory:7168, vCores:15> available
2013-08-05 22:21:41,713 INFO org.apache.hadoop.yarn.server.resourcemanager.scheduler.capacity.LeafQueue: assignedContainer application=application_1375740621345_0006 container=Container: [ContainerId: container_1375740621345_0006_01_000002, NodeId: hadoop-100-3:44102, NodeHttpAddress: hadoop-100-3:8042, Resource: <memory:1024, vCores:1>, Priority: 20, State: NEW, Token: null, Status: container_id {, app_attempt_id {, application_id {, id: 6, cluster_timestamp: 1375740621345, }, attemptId: 1, }, id: 2, }, state: C_NEW, ] containerId=container_1375740621345_0006_01_000002 queue=default: capacity=1.0, absoluteCapacity=1.0, usedResources=<memory:10240, vCores:5>usedCapacity=0.20833333, absoluteUsedCapacity=0.20833333, numApps=5, numContainers=5 usedCapacity=0.20833333 absoluteUsedCapacity=0.20833333 used=<memory:10240, vCores:5> cluster=<memory:49152, vCores:96>
2013-08-05 22:21:41,713 INFO org.apache.hadoop.yarn.server.resourcemanager.scheduler.capacity.ParentQueue: Re-sorting queues since queue: root.default stats: default: capacity=1.0, absoluteCapacity=1.0, usedResources=<memory:11264, vCores:6>usedCapacity=0.22916667, absoluteUsedCapacity=0.22916667, numApps=5, numContainers=6
2013-08-05 22:21:41,714 INFO org.apache.hadoop.yarn.server.resourcemanager.scheduler.capacity.ParentQueue: assignedContainer queue=root usedCapacity=0.22916667 absoluteUsedCapacity=0.22916667 used=<memory:11264, vCores:6> cluster=<memory:49152, vCores:96>
2013-08-05 22:21:41,714 INFO org.apache.hadoop.yarn.server.resourcemanager.rmcontainer.RMContainerImpl: container_1375740621345_0006_01_000003 Container Transitioned from NEW to ALLOCATED
2013-08-05 22:21:41,714 INFO org.apache.hadoop.yarn.server.resourcemanager.RMAuditLogger: USER=ubuntu	OPERATION=AM Allocated Container	TARGET=SchedulerApp	RESULT=SUCCESS	APPID=application_1375740621345_0006	CONTAINERID=container_1375740621345_0006_01_000003
2013-08-05 22:21:41,714 INFO org.apache.hadoop.yarn.server.resourcemanager.scheduler.common.fica.FiCaSchedulerNode: Assigned container container_1375740621345_0006_01_000003 of capacity <memory:1024, vCores:1> on host hadoop-100-3:44102, which currently has 2 containers, <memory:2048, vCores:2> used and <memory:6144, vCores:14> available
2013-08-05 22:21:41,715 INFO org.apache.hadoop.yarn.server.resourcemanager.scheduler.capacity.LeafQueue: assignedContainer application=application_1375740621345_0006 container=Container: [ContainerId: container_1375740621345_0006_01_000003, NodeId: hadoop-100-3:44102, NodeHttpAddress: hadoop-100-3:8042, Resource: <memory:1024, vCores:1>, Priority: 20, State: NEW, Token: null, Status: container_id {, app_attempt_id {, application_id {, id: 6, cluster_timestamp: 1375740621345, }, attemptId: 1, }, id: 3, }, state: C_NEW, ] containerId=container_1375740621345_0006_01_000003 queue=default: capacity=1.0, absoluteCapacity=1.0, usedResources=<memory:11264, vCores:6>usedCapacity=0.22916667, absoluteUsedCapacity=0.22916667, numApps=5, numContainers=6 usedCapacity=0.22916667 absoluteUsedCapacity=0.22916667 used=<memory:11264, vCores:6> cluster=<memory:49152, vCores:96>
2013-08-05 22:21:41,716 INFO org.apache.hadoop.yarn.server.resourcemanager.scheduler.capacity.ParentQueue: Re-sorting queues since queue: root.default stats: default: capacity=1.0, absoluteCapacity=1.0, usedResources=<memory:12288, vCores:7>usedCapacity=0.25, absoluteUsedCapacity=0.25, numApps=5, numContainers=7
2013-08-05 22:21:41,716 INFO org.apache.hadoop.yarn.server.resourcemanager.scheduler.capacity.ParentQueue: assignedContainer queue=root usedCapacity=0.25 absoluteUsedCapacity=0.25 used=<memory:12288, vCores:7> cluster=<memory:49152, vCores:96>
2013-08-05 22:21:41,716 INFO org.apache.hadoop.yarn.server.resourcemanager.rmcontainer.RMContainerImpl: container_1375740621345_0006_01_000004 Container Transitioned from NEW to ALLOCATED
2013-08-05 22:21:41,717 INFO org.apache.hadoop.yarn.server.resourcemanager.RMAuditLogger: USER=ubuntu	OPERATION=AM Allocated Container	TARGET=SchedulerApp	RESULT=SUCCESS	APPID=application_1375740621345_0006	CONTAINERID=container_1375740621345_0006_01_000004
2013-08-05 22:21:41,717 INFO org.apache.hadoop.yarn.server.resourcemanager.scheduler.common.fica.FiCaSchedulerNode: Assigned container container_1375740621345_0006_01_000004 of capacity <memory:1024, vCores:1> on host hadoop-100-3:44102, which currently has 3 containers, <memory:3072, vCores:3> used and <memory:5120, vCores:13> available
2013-08-05 22:21:41,718 INFO org.apache.hadoop.yarn.server.resourcemanager.scheduler.capacity.LeafQueue: assignedContainer application=application_1375740621345_0006 container=Container: [ContainerId: container_1375740621345_0006_01_000004, NodeId: hadoop-100-3:44102, NodeHttpAddress: hadoop-100-3:8042, Resource: <memory:1024, vCores:1>, Priority: 20, State: NEW, Token: null, Status: container_id {, app_attempt_id {, application_id {, id: 6, cluster_timestamp: 1375740621345, }, attemptId: 1, }, id: 4, }, state: C_NEW, ] containerId=container_1375740621345_0006_01_000004 queue=default: capacity=1.0, absoluteCapacity=1.0, usedResources=<memory:12288, vCores:7>usedCapacity=0.25, absoluteUsedCapacity=0.25, numApps=5, numContainers=7 usedCapacity=0.25 absoluteUsedCapacity=0.25 used=<memory:12288, vCores:7> cluster=<memory:49152, vCores:96>
2013-08-05 22:21:41,718 INFO org.apache.hadoop.yarn.server.resourcemanager.scheduler.capacity.ParentQueue: Re-sorting queues since queue: root.default stats: default: capacity=1.0, absoluteCapacity=1.0, usedResources=<memory:13312, vCores:8>usedCapacity=0.27083334, absoluteUsedCapacity=0.27083334, numApps=5, numContainers=8
2013-08-05 22:21:41,718 INFO org.apache.hadoop.yarn.server.resourcemanager.scheduler.capacity.ParentQueue: assignedContainer queue=root usedCapacity=0.27083334 absoluteUsedCapacity=0.27083334 used=<memory:13312, vCores:8> cluster=<memory:49152, vCores:96>
2013-08-05 22:21:41,719 INFO org.apache.hadoop.yarn.server.resourcemanager.rmcontainer.RMContainerImpl: container_1375740621345_0006_01_000005 Container Transitioned from NEW to ALLOCATED
2013-08-05 22:21:41,719 INFO org.apache.hadoop.yarn.server.resourcemanager.RMAuditLogger: USER=ubuntu	OPERATION=AM Allocated Container	TARGET=SchedulerApp	RESULT=SUCCESS	APPID=application_1375740621345_0006	CONTAINERID=container_1375740621345_0006_01_000005
2013-08-05 22:21:41,719 INFO org.apache.hadoop.yarn.server.resourcemanager.scheduler.common.fica.FiCaSchedulerNode: Assigned container container_1375740621345_0006_01_000005 of capacity <memory:1024, vCores:1> on host hadoop-100-3:44102, which currently has 4 containers, <memory:4096, vCores:4> used and <memory:4096, vCores:12> available
2013-08-05 22:21:41,720 INFO org.apache.hadoop.yarn.server.resourcemanager.scheduler.capacity.LeafQueue: assignedContainer application=application_1375740621345_0006 container=Container: [ContainerId: container_1375740621345_0006_01_000005, NodeId: hadoop-100-3:44102, NodeHttpAddress: hadoop-100-3:8042, Resource: <memory:1024, vCores:1>, Priority: 20, State: NEW, Token: null, Status: container_id {, app_attempt_id {, application_id {, id: 6, cluster_timestamp: 1375740621345, }, attemptId: 1, }, id: 5, }, state: C_NEW, ] containerId=container_1375740621345_0006_01_000005 queue=default: capacity=1.0, absoluteCapacity=1.0, usedResources=<memory:13312, vCores:8>usedCapacity=0.27083334, absoluteUsedCapacity=0.27083334, numApps=5, numContainers=8 usedCapacity=0.27083334 absoluteUsedCapacity=0.27083334 used=<memory:13312, vCores:8> cluster=<memory:49152, vCores:96>
2013-08-05 22:21:41,720 INFO org.apache.hadoop.yarn.server.resourcemanager.scheduler.capacity.ParentQueue: Re-sorting queues since queue: root.default stats: default: capacity=1.0, absoluteCapacity=1.0, usedResources=<memory:14336, vCores:9>usedCapacity=0.29166666, absoluteUsedCapacity=0.29166666, numApps=5, numContainers=9
2013-08-05 22:21:41,721 INFO org.apache.hadoop.yarn.server.resourcemanager.scheduler.capacity.ParentQueue: assignedContainer queue=root usedCapacity=0.29166666 absoluteUsedCapacity=0.29166666 used=<memory:14336, vCores:9> cluster=<memory:49152, vCores:96>
2013-08-05 22:21:41,721 INFO org.apache.hadoop.yarn.server.resourcemanager.rmcontainer.RMContainerImpl: container_1375740621345_0006_01_000006 Container Transitioned from NEW to ALLOCATED
2013-08-05 22:21:41,721 INFO org.apache.hadoop.yarn.server.resourcemanager.RMAuditLogger: USER=ubuntu	OPERATION=AM Allocated Container	TARGET=SchedulerApp	RESULT=SUCCESS	APPID=application_1375740621345_0006	CONTAINERID=container_1375740621345_0006_01_000006
2013-08-05 22:21:41,721 INFO org.apache.hadoop.yarn.server.resourcemanager.scheduler.common.fica.FiCaSchedulerNode: Assigned container container_1375740621345_0006_01_000006 of capacity <memory:1024, vCores:1> on host hadoop-100-3:44102, which currently has 5 containers, <memory:5120, vCores:5> used and <memory:3072, vCores:11> available
2013-08-05 22:21:41,723 INFO org.apache.hadoop.yarn.server.resourcemanager.scheduler.capacity.LeafQueue: assignedContainer application=application_1375740621345_0006 container=Container: [ContainerId: container_1375740621345_0006_01_000006, NodeId: hadoop-100-3:44102, NodeHttpAddress: hadoop-100-3:8042, Resource: <memory:1024, vCores:1>, Priority: 20, State: NEW, Token: null, Status: container_id {, app_attempt_id {, application_id {, id: 6, cluster_timestamp: 1375740621345, }, attemptId: 1, }, id: 6, }, state: C_NEW, ] containerId=container_1375740621345_0006_01_000006 queue=default: capacity=1.0, absoluteCapacity=1.0, usedResources=<memory:14336, vCores:9>usedCapacity=0.29166666, absoluteUsedCapacity=0.29166666, numApps=5, numContainers=9 usedCapacity=0.29166666 absoluteUsedCapacity=0.29166666 used=<memory:14336, vCores:9> cluster=<memory:49152, vCores:96>
2013-08-05 22:21:41,723 INFO org.apache.hadoop.yarn.server.resourcemanager.scheduler.capacity.ParentQueue: Re-sorting queues since queue: root.default stats: default: capacity=1.0, absoluteCapacity=1.0, usedResources=<memory:15360, vCores:10>usedCapacity=0.3125, absoluteUsedCapacity=0.3125, numApps=5, numContainers=10
2013-08-05 22:21:41,723 INFO org.apache.hadoop.yarn.server.resourcemanager.scheduler.capacity.ParentQueue: assignedContainer queue=root usedCapacity=0.3125 absoluteUsedCapacity=0.3125 used=<memory:15360, vCores:10> cluster=<memory:49152, vCores:96>
2013-08-05 22:21:41,723 INFO org.apache.hadoop.yarn.server.resourcemanager.rmcontainer.RMContainerImpl: container_1375740621345_0006_01_000007 Container Transitioned from NEW to ALLOCATED
2013-08-05 22:21:41,724 INFO org.apache.hadoop.yarn.server.resourcemanager.RMAuditLogger: USER=ubuntu	OPERATION=AM Allocated Container	TARGET=SchedulerApp	RESULT=SUCCESS	APPID=application_1375740621345_0006	CONTAINERID=container_1375740621345_0006_01_000007
2013-08-05 22:21:41,724 INFO org.apache.hadoop.yarn.server.resourcemanager.scheduler.common.fica.FiCaSchedulerNode: Assigned container container_1375740621345_0006_01_000007 of capacity <memory:1024, vCores:1> on host hadoop-100-3:44102, which currently has 6 containers, <memory:6144, vCores:6> used and <memory:2048, vCores:10> available
2013-08-05 22:21:41,725 INFO org.apache.hadoop.yarn.server.resourcemanager.scheduler.capacity.LeafQueue: assignedContainer application=application_1375740621345_0006 container=Container: [ContainerId: container_1375740621345_0006_01_000007, NodeId: hadoop-100-3:44102, NodeHttpAddress: hadoop-100-3:8042, Resource: <memory:1024, vCores:1>, Priority: 20, State: NEW, Token: null, Status: container_id {, app_attempt_id {, application_id {, id: 6, cluster_timestamp: 1375740621345, }, attemptId: 1, }, id: 7, }, state: C_NEW, ] containerId=container_1375740621345_0006_01_000007 queue=default: capacity=1.0, absoluteCapacity=1.0, usedResources=<memory:15360, vCores:10>usedCapacity=0.3125, absoluteUsedCapacity=0.3125, numApps=5, numContainers=10 usedCapacity=0.3125 absoluteUsedCapacity=0.3125 used=<memory:15360, vCores:10> cluster=<memory:49152, vCores:96>
2013-08-05 22:21:41,725 INFO org.apache.hadoop.yarn.server.resourcemanager.scheduler.capacity.ParentQueue: Re-sorting queues since queue: root.default stats: default: capacity=1.0, absoluteCapacity=1.0, usedResources=<memory:16384, vCores:11>usedCapacity=0.33333334, absoluteUsedCapacity=0.33333334, numApps=5, numContainers=11
2013-08-05 22:21:41,725 INFO org.apache.hadoop.yarn.server.resourcemanager.scheduler.capacity.ParentQueue: assignedContainer queue=root usedCapacity=0.33333334 absoluteUsedCapacity=0.33333334 used=<memory:16384, vCores:11> cluster=<memory:49152, vCores:96>
2013-08-05 22:21:41,726 INFO org.apache.hadoop.yarn.server.resourcemanager.rmcontainer.RMContainerImpl: container_1375740621345_0006_01_000008 Container Transitioned from NEW to ALLOCATED
2013-08-05 22:21:41,726 INFO org.apache.hadoop.yarn.server.resourcemanager.RMAuditLogger: USER=ubuntu	OPERATION=AM Allocated Container	TARGET=SchedulerApp	RESULT=SUCCESS	APPID=application_1375740621345_0006	CONTAINERID=container_1375740621345_0006_01_000008
2013-08-05 22:21:41,726 INFO org.apache.hadoop.yarn.server.resourcemanager.scheduler.common.fica.FiCaSchedulerNode: Assigned container container_1375740621345_0006_01_000008 of capacity <memory:1024, vCores:1> on host hadoop-100-3:44102, which currently has 7 containers, <memory:7168, vCores:7> used and <memory:1024, vCores:9> available
2013-08-05 22:21:41,727 INFO org.apache.hadoop.yarn.server.resourcemanager.scheduler.capacity.LeafQueue: assignedContainer application=application_1375740621345_0006 container=Container: [ContainerId: container_1375740621345_0006_01_000008, NodeId: hadoop-100-3:44102, NodeHttpAddress: hadoop-100-3:8042, Resource: <memory:1024, vCores:1>, Priority: 20, State: NEW, Token: null, Status: container_id {, app_attempt_id {, application_id {, id: 6, cluster_timestamp: 1375740621345, }, attemptId: 1, }, id: 8, }, state: C_NEW, ] containerId=container_1375740621345_0006_01_000008 queue=default: capacity=1.0, absoluteCapacity=1.0, usedResources=<memory:16384, vCores:11>usedCapacity=0.33333334, absoluteUsedCapacity=0.33333334, numApps=5, numContainers=11 usedCapacity=0.33333334 absoluteUsedCapacity=0.33333334 used=<memory:16384, vCores:11> cluster=<memory:49152, vCores:96>
2013-08-05 22:21:41,727 INFO org.apache.hadoop.yarn.server.resourcemanager.scheduler.capacity.ParentQueue: Re-sorting queues since queue: root.default stats: default: capacity=1.0, absoluteCapacity=1.0, usedResources=<memory:17408, vCores:12>usedCapacity=0.35416666, absoluteUsedCapacity=0.35416666, numApps=5, numContainers=12
2013-08-05 22:21:41,727 INFO org.apache.hadoop.yarn.server.resourcemanager.scheduler.capacity.ParentQueue: assignedContainer queue=root usedCapacity=0.35416666 absoluteUsedCapacity=0.35416666 used=<memory:17408, vCores:12> cluster=<memory:49152, vCores:96>
2013-08-05 22:21:41,728 INFO org.apache.hadoop.yarn.server.resourcemanager.rmcontainer.RMContainerImpl: container_1375740621345_0006_01_000009 Container Transitioned from NEW to ALLOCATED
2013-08-05 22:21:41,728 INFO org.apache.hadoop.yarn.server.resourcemanager.RMAuditLogger: USER=ubuntu	OPERATION=AM Allocated Container	TARGET=SchedulerApp	RESULT=SUCCESS	APPID=application_1375740621345_0006	CONTAINERID=container_1375740621345_0006_01_000009
2013-08-05 22:21:41,728 INFO org.apache.hadoop.yarn.server.resourcemanager.scheduler.common.fica.FiCaSchedulerNode: Assigned container container_1375740621345_0006_01_000009 of capacity <memory:1024, vCores:1> on host hadoop-100-3:44102, which currently has 8 containers, <memory:8192, vCores:8> used and <memory:0, vCores:8> available
2013-08-05 22:21:41,729 INFO org.apache.hadoop.yarn.server.resourcemanager.scheduler.capacity.LeafQueue: assignedContainer application=application_1375740621345_0006 container=Container: [ContainerId: container_1375740621345_0006_01_000009, NodeId: hadoop-100-3:44102, NodeHttpAddress: hadoop-100-3:8042, Resource: <memory:1024, vCores:1>, Priority: 20, State: NEW, Token: null, Status: container_id {, app_attempt_id {, application_id {, id: 6, cluster_timestamp: 1375740621345, }, attemptId: 1, }, id: 9, }, state: C_NEW, ] containerId=container_1375740621345_0006_01_000009 queue=default: capacity=1.0, absoluteCapacity=1.0, usedResources=<memory:17408, vCores:12>usedCapacity=0.35416666, absoluteUsedCapacity=0.35416666, numApps=5, numContainers=12 usedCapacity=0.35416666 absoluteUsedCapacity=0.35416666 used=<memory:17408, vCores:12> cluster=<memory:49152, vCores:96>
2013-08-05 22:21:41,729 INFO org.apache.hadoop.yarn.server.resourcemanager.scheduler.capacity.ParentQueue: Re-sorting queues since queue: root.default stats: default: capacity=1.0, absoluteCapacity=1.0, usedResources=<memory:18432, vCores:13>usedCapacity=0.375, absoluteUsedCapacity=0.375, numApps=5, numContainers=13
2013-08-05 22:21:41,729 INFO org.apache.hadoop.yarn.server.resourcemanager.scheduler.capacity.ParentQueue: assignedContainer queue=root usedCapacity=0.375 absoluteUsedCapacity=0.375 used=<memory:18432, vCores:13> cluster=<memory:49152, vCores:96>
2013-08-05 22:21:41,751 INFO org.apache.hadoop.yarn.server.resourcemanager.ApplicationMasterService: AM registration appattempt_1375740621345_0009_000001
2013-08-05 22:21:41,752 INFO org.apache.hadoop.yarn.server.resourcemanager.RMAuditLogger: USER=ubuntu	IP=192.168.100.14	OPERATION=Register App Master	TARGET=ApplicationMasterService	RESULT=SUCCESS	APPID=application_1375740621345_0009	APPATTEMPTID=appattempt_1375740621345_0009_000001
2013-08-05 22:21:41,752 INFO org.apache.hadoop.yarn.server.resourcemanager.rmapp.attempt.RMAppAttemptImpl: appattempt_1375740621345_0009_000001 State change from LAUNCHED to RUNNING
2013-08-05 22:21:41,752 INFO org.apache.hadoop.yarn.server.resourcemanager.rmapp.RMAppImpl: application_1375740621345_0009 State change from ACCEPTED to RUNNING
2013-08-05 22:21:41,783 INFO org.apache.hadoop.yarn.server.resourcemanager.ApplicationMasterService: AM registration appattempt_1375740621345_0010_000001
2013-08-05 22:21:41,783 INFO org.apache.hadoop.yarn.server.resourcemanager.RMAuditLogger: USER=ubuntu	IP=192.168.100.4	OPERATION=Register App Master	TARGET=ApplicationMasterService	RESULT=SUCCESS	APPID=application_1375740621345_0010	APPATTEMPTID=appattempt_1375740621345_0010_000001
2013-08-05 22:21:41,784 INFO org.apache.hadoop.yarn.server.resourcemanager.rmapp.attempt.RMAppAttemptImpl: appattempt_1375740621345_0010_000001 State change from LAUNCHED to RUNNING
2013-08-05 22:21:41,784 INFO org.apache.hadoop.yarn.server.resourcemanager.rmapp.RMAppImpl: application_1375740621345_0010 State change from ACCEPTED to RUNNING
2013-08-05 22:21:42,348 INFO org.apache.hadoop.yarn.server.resourcemanager.rmcontainer.RMContainerImpl: container_1375740621345_0006_01_000010 Container Transitioned from NEW to ALLOCATED
2013-08-05 22:21:42,349 INFO org.apache.hadoop.yarn.server.resourcemanager.RMAuditLogger: USER=ubuntu	OPERATION=AM Allocated Container	TARGET=SchedulerApp	RESULT=SUCCESS	APPID=application_1375740621345_0006	CONTAINERID=container_1375740621345_0006_01_000010
2013-08-05 22:21:42,349 INFO org.apache.hadoop.yarn.server.resourcemanager.scheduler.common.fica.FiCaSchedulerNode: Assigned container container_1375740621345_0006_01_000010 of capacity <memory:1024, vCores:1> on host hadoop-100-4:50425, which currently has 3 containers, <memory:5120, vCores:3> used and <memory:3072, vCores:13> available
2013-08-05 22:21:42,350 INFO org.apache.hadoop.yarn.server.resourcemanager.scheduler.capacity.LeafQueue: assignedContainer application=application_1375740621345_0006 container=Container: [ContainerId: container_1375740621345_0006_01_000010, NodeId: hadoop-100-4:50425, NodeHttpAddress: hadoop-100-4:8042, Resource: <memory:1024, vCores:1>, Priority: 20, State: NEW, Token: null, Status: container_id {, app_attempt_id {, application_id {, id: 6, cluster_timestamp: 1375740621345, }, attemptId: 1, }, id: 10, }, state: C_NEW, ] containerId=container_1375740621345_0006_01_000010 queue=default: capacity=1.0, absoluteCapacity=1.0, usedResources=<memory:18432, vCores:13>usedCapacity=0.375, absoluteUsedCapacity=0.375, numApps=5, numContainers=13 usedCapacity=0.375 absoluteUsedCapacity=0.375 used=<memory:18432, vCores:13> cluster=<memory:49152, vCores:96>
2013-08-05 22:21:42,350 INFO org.apache.hadoop.yarn.server.resourcemanager.scheduler.capacity.ParentQueue: Re-sorting queues since queue: root.default stats: default: capacity=1.0, absoluteCapacity=1.0, usedResources=<memory:19456, vCores:14>usedCapacity=0.39583334, absoluteUsedCapacity=0.39583334, numApps=5, numContainers=14
2013-08-05 22:21:42,350 INFO org.apache.hadoop.yarn.server.resourcemanager.scheduler.capacity.ParentQueue: assignedContainer queue=root usedCapacity=0.39583334 absoluteUsedCapacity=0.39583334 used=<memory:19456, vCores:14> cluster=<memory:49152, vCores:96>
2013-08-05 22:21:42,351 INFO org.apache.hadoop.yarn.server.resourcemanager.rmcontainer.RMContainerImpl: container_1375740621345_0006_01_000011 Container Transitioned from NEW to ALLOCATED
2013-08-05 22:21:42,351 INFO org.apache.hadoop.yarn.server.resourcemanager.RMAuditLogger: USER=ubuntu	OPERATION=AM Allocated Container	TARGET=SchedulerApp	RESULT=SUCCESS	APPID=application_1375740621345_0006	CONTAINERID=container_1375740621345_0006_01_000011
2013-08-05 22:21:42,351 INFO org.apache.hadoop.yarn.server.resourcemanager.scheduler.common.fica.FiCaSchedulerNode: Assigned container container_1375740621345_0006_01_000011 of capacity <memory:1024, vCores:1> on host hadoop-100-4:50425, which currently has 4 containers, <memory:6144, vCores:4> used and <memory:2048, vCores:12> available
2013-08-05 22:21:42,352 INFO org.apache.hadoop.yarn.server.resourcemanager.scheduler.capacity.LeafQueue: assignedContainer application=application_1375740621345_0006 container=Container: [ContainerId: container_1375740621345_0006_01_000011, NodeId: hadoop-100-4:50425, NodeHttpAddress: hadoop-100-4:8042, Resource: <memory:1024, vCores:1>, Priority: 20, State: NEW, Token: null, Status: container_id {, app_attempt_id {, application_id {, id: 6, cluster_timestamp: 1375740621345, }, attemptId: 1, }, id: 11, }, state: C_NEW, ] containerId=container_1375740621345_0006_01_000011 queue=default: capacity=1.0, absoluteCapacity=1.0, usedResources=<memory:19456, vCores:14>usedCapacity=0.39583334, absoluteUsedCapacity=0.39583334, numApps=5, numContainers=14 usedCapacity=0.39583334 absoluteUsedCapacity=0.39583334 used=<memory:19456, vCores:14> cluster=<memory:49152, vCores:96>
2013-08-05 22:21:42,352 INFO org.apache.hadoop.yarn.server.resourcemanager.scheduler.capacity.ParentQueue: Re-sorting queues since queue: root.default stats: default: capacity=1.0, absoluteCapacity=1.0, usedResources=<memory:20480, vCores:15>usedCapacity=0.41666666, absoluteUsedCapacity=0.41666666, numApps=5, numContainers=15
2013-08-05 22:21:42,353 INFO org.apache.hadoop.yarn.server.resourcemanager.scheduler.capacity.ParentQueue: assignedContainer queue=root usedCapacity=0.41666666 absoluteUsedCapacity=0.41666666 used=<memory:20480, vCores:15> cluster=<memory:49152, vCores:96>
2013-08-05 22:21:42,353 INFO org.apache.hadoop.yarn.server.resourcemanager.rmcontainer.RMContainerImpl: container_1375740621345_0006_01_000012 Container Transitioned from NEW to ALLOCATED
2013-08-05 22:21:42,353 INFO org.apache.hadoop.yarn.server.resourcemanager.RMAuditLogger: USER=ubuntu	OPERATION=AM Allocated Container	TARGET=SchedulerApp	RESULT=SUCCESS	APPID=application_1375740621345_0006	CONTAINERID=container_1375740621345_0006_01_000012
2013-08-05 22:21:42,353 INFO org.apache.hadoop.yarn.server.resourcemanager.scheduler.common.fica.FiCaSchedulerNode: Assigned container container_1375740621345_0006_01_000012 of capacity <memory:1024, vCores:1> on host hadoop-100-4:50425, which currently has 5 containers, <memory:7168, vCores:5> used and <memory:1024, vCores:11> available
2013-08-05 22:21:42,354 INFO org.apache.hadoop.yarn.server.resourcemanager.scheduler.capacity.LeafQueue: assignedContainer application=application_1375740621345_0006 container=Container: [ContainerId: container_1375740621345_0006_01_000012, NodeId: hadoop-100-4:50425, NodeHttpAddress: hadoop-100-4:8042, Resource: <memory:1024, vCores:1>, Priority: 20, State: NEW, Token: null, Status: container_id {, app_attempt_id {, application_id {, id: 6, cluster_timestamp: 1375740621345, }, attemptId: 1, }, id: 12, }, state: C_NEW, ] containerId=container_1375740621345_0006_01_000012 queue=default: capacity=1.0, absoluteCapacity=1.0, usedResources=<memory:20480, vCores:15>usedCapacity=0.41666666, absoluteUsedCapacity=0.41666666, numApps=5, numContainers=15 usedCapacity=0.41666666 absoluteUsedCapacity=0.41666666 used=<memory:20480, vCores:15> cluster=<memory:49152, vCores:96>
2013-08-05 22:21:42,354 INFO org.apache.hadoop.yarn.server.resourcemanager.scheduler.capacity.ParentQueue: Re-sorting queues since queue: root.default stats: default: capacity=1.0, absoluteCapacity=1.0, usedResources=<memory:21504, vCores:16>usedCapacity=0.4375, absoluteUsedCapacity=0.4375, numApps=5, numContainers=16
2013-08-05 22:21:42,355 INFO org.apache.hadoop.yarn.server.resourcemanager.scheduler.capacity.ParentQueue: assignedContainer queue=root usedCapacity=0.4375 absoluteUsedCapacity=0.4375 used=<memory:21504, vCores:16> cluster=<memory:49152, vCores:96>
2013-08-05 22:21:42,355 INFO org.apache.hadoop.yarn.server.resourcemanager.rmcontainer.RMContainerImpl: container_1375740621345_0006_01_000013 Container Transitioned from NEW to ALLOCATED
2013-08-05 22:21:42,355 INFO org.apache.hadoop.yarn.server.resourcemanager.RMAuditLogger: USER=ubuntu	OPERATION=AM Allocated Container	TARGET=SchedulerApp	RESULT=SUCCESS	APPID=application_1375740621345_0006	CONTAINERID=container_1375740621345_0006_01_000013
2013-08-05 22:21:42,355 INFO org.apache.hadoop.yarn.server.resourcemanager.scheduler.common.fica.FiCaSchedulerNode: Assigned container container_1375740621345_0006_01_000013 of capacity <memory:1024, vCores:1> on host hadoop-100-4:50425, which currently has 6 containers, <memory:8192, vCores:6> used and <memory:0, vCores:10> available
2013-08-05 22:21:42,356 INFO org.apache.hadoop.yarn.server.resourcemanager.scheduler.capacity.LeafQueue: assignedContainer application=application_1375740621345_0006 container=Container: [ContainerId: container_1375740621345_0006_01_000013, NodeId: hadoop-100-4:50425, NodeHttpAddress: hadoop-100-4:8042, Resource: <memory:1024, vCores:1>, Priority: 20, State: NEW, Token: null, Status: container_id {, app_attempt_id {, application_id {, id: 6, cluster_timestamp: 1375740621345, }, attemptId: 1, }, id: 13, }, state: C_NEW, ] containerId=container_1375740621345_0006_01_000013 queue=default: capacity=1.0, absoluteCapacity=1.0, usedResources=<memory:21504, vCores:16>usedCapacity=0.4375, absoluteUsedCapacity=0.4375, numApps=5, numContainers=16 usedCapacity=0.4375 absoluteUsedCapacity=0.4375 used=<memory:21504, vCores:16> cluster=<memory:49152, vCores:96>
2013-08-05 22:21:42,357 INFO org.apache.hadoop.yarn.server.resourcemanager.scheduler.capacity.ParentQueue: Re-sorting queues since queue: root.default stats: default: capacity=1.0, absoluteCapacity=1.0, usedResources=<memory:22528, vCores:17>usedCapacity=0.45833334, absoluteUsedCapacity=0.45833334, numApps=5, numContainers=17
2013-08-05 22:21:42,357 INFO org.apache.hadoop.yarn.server.resourcemanager.scheduler.capacity.ParentQueue: assignedContainer queue=root usedCapacity=0.45833334 absoluteUsedCapacity=0.45833334 used=<memory:22528, vCores:17> cluster=<memory:49152, vCores:96>
2013-08-05 22:21:42,534 INFO org.apache.hadoop.yarn.server.resourcemanager.rmcontainer.RMContainerImpl: container_1375740621345_0006_01_000014 Container Transitioned from NEW to ALLOCATED
2013-08-05 22:21:42,534 INFO org.apache.hadoop.yarn.server.resourcemanager.RMAuditLogger: USER=ubuntu	OPERATION=AM Allocated Container	TARGET=SchedulerApp	RESULT=SUCCESS	APPID=application_1375740621345_0006	CONTAINERID=container_1375740621345_0006_01_000014
2013-08-05 22:21:42,534 INFO org.apache.hadoop.yarn.server.resourcemanager.scheduler.common.fica.FiCaSchedulerNode: Assigned container container_1375740621345_0006_01_000014 of capacity <memory:1024, vCores:1> on host hadoop-100-2:37374, which currently has 3 containers, <memory:5120, vCores:3> used and <memory:3072, vCores:13> available
2013-08-05 22:21:42,535 INFO org.apache.hadoop.yarn.server.resourcemanager.scheduler.capacity.LeafQueue: assignedContainer application=application_1375740621345_0006 container=Container: [ContainerId: container_1375740621345_0006_01_000014, NodeId: hadoop-100-2:37374, NodeHttpAddress: hadoop-100-2:8042, Resource: <memory:1024, vCores:1>, Priority: 20, State: NEW, Token: null, Status: container_id {, app_attempt_id {, application_id {, id: 6, cluster_timestamp: 1375740621345, }, attemptId: 1, }, id: 14, }, state: C_NEW, ] containerId=container_1375740621345_0006_01_000014 queue=default: capacity=1.0, absoluteCapacity=1.0, usedResources=<memory:22528, vCores:17>usedCapacity=0.45833334, absoluteUsedCapacity=0.45833334, numApps=5, numContainers=17 usedCapacity=0.45833334 absoluteUsedCapacity=0.45833334 used=<memory:22528, vCores:17> cluster=<memory:49152, vCores:96>
2013-08-05 22:21:42,536 INFO org.apache.hadoop.yarn.server.resourcemanager.scheduler.capacity.ParentQueue: Re-sorting queues since queue: root.default stats: default: capacity=1.0, absoluteCapacity=1.0, usedResources=<memory:23552, vCores:18>usedCapacity=0.47916666, absoluteUsedCapacity=0.47916666, numApps=5, numContainers=18
2013-08-05 22:21:42,536 INFO org.apache.hadoop.yarn.server.resourcemanager.scheduler.capacity.ParentQueue: assignedContainer queue=root usedCapacity=0.47916666 absoluteUsedCapacity=0.47916666 used=<memory:23552, vCores:18> cluster=<memory:49152, vCores:96>
2013-08-05 22:21:42,536 INFO org.apache.hadoop.yarn.server.resourcemanager.rmcontainer.RMContainerImpl: container_1375740621345_0006_01_000015 Container Transitioned from NEW to ALLOCATED
2013-08-05 22:21:42,537 INFO org.apache.hadoop.yarn.server.resourcemanager.RMAuditLogger: USER=ubuntu	OPERATION=AM Allocated Container	TARGET=SchedulerApp	RESULT=SUCCESS	APPID=application_1375740621345_0006	CONTAINERID=container_1375740621345_0006_01_000015
2013-08-05 22:21:42,537 INFO org.apache.hadoop.yarn.server.resourcemanager.scheduler.common.fica.FiCaSchedulerNode: Assigned container container_1375740621345_0006_01_000015 of capacity <memory:1024, vCores:1> on host hadoop-100-2:37374, which currently has 4 containers, <memory:6144, vCores:4> used and <memory:2048, vCores:12> available
2013-08-05 22:21:42,538 INFO org.apache.hadoop.yarn.server.resourcemanager.scheduler.capacity.LeafQueue: assignedContainer application=application_1375740621345_0006 container=Container: [ContainerId: container_1375740621345_0006_01_000015, NodeId: hadoop-100-2:37374, NodeHttpAddress: hadoop-100-2:8042, Resource: <memory:1024, vCores:1>, Priority: 20, State: NEW, Token: null, Status: container_id {, app_attempt_id {, application_id {, id: 6, cluster_timestamp: 1375740621345, }, attemptId: 1, }, id: 15, }, state: C_NEW, ] containerId=container_1375740621345_0006_01_000015 queue=default: capacity=1.0, absoluteCapacity=1.0, usedResources=<memory:23552, vCores:18>usedCapacity=0.47916666, absoluteUsedCapacity=0.47916666, numApps=5, numContainers=18 usedCapacity=0.47916666 absoluteUsedCapacity=0.47916666 used=<memory:23552, vCores:18> cluster=<memory:49152, vCores:96>
2013-08-05 22:21:42,538 INFO org.apache.hadoop.yarn.server.resourcemanager.scheduler.capacity.ParentQueue: Re-sorting queues since queue: root.default stats: default: capacity=1.0, absoluteCapacity=1.0, usedResources=<memory:24576, vCores:19>usedCapacity=0.5, absoluteUsedCapacity=0.5, numApps=5, numContainers=19
2013-08-05 22:21:42,538 INFO org.apache.hadoop.yarn.server.resourcemanager.scheduler.capacity.ParentQueue: assignedContainer queue=root usedCapacity=0.5 absoluteUsedCapacity=0.5 used=<memory:24576, vCores:19> cluster=<memory:49152, vCores:96>
2013-08-05 22:21:42,539 INFO org.apache.hadoop.yarn.server.resourcemanager.rmcontainer.RMContainerImpl: container_1375740621345_0006_01_000016 Container Transitioned from NEW to ALLOCATED
2013-08-05 22:21:42,539 INFO org.apache.hadoop.yarn.server.resourcemanager.RMAuditLogger: USER=ubuntu	OPERATION=AM Allocated Container	TARGET=SchedulerApp	RESULT=SUCCESS	APPID=application_1375740621345_0006	CONTAINERID=container_1375740621345_0006_01_000016
2013-08-05 22:21:42,539 INFO org.apache.hadoop.yarn.server.resourcemanager.scheduler.common.fica.FiCaSchedulerNode: Assigned container container_1375740621345_0006_01_000016 of capacity <memory:1024, vCores:1> on host hadoop-100-2:37374, which currently has 5 containers, <memory:7168, vCores:5> used and <memory:1024, vCores:11> available
2013-08-05 22:21:42,540 INFO org.apache.hadoop.yarn.server.resourcemanager.scheduler.capacity.LeafQueue: assignedContainer application=application_1375740621345_0006 container=Container: [ContainerId: container_1375740621345_0006_01_000016, NodeId: hadoop-100-2:37374, NodeHttpAddress: hadoop-100-2:8042, Resource: <memory:1024, vCores:1>, Priority: 20, State: NEW, Token: null, Status: container_id {, app_attempt_id {, application_id {, id: 6, cluster_timestamp: 1375740621345, }, attemptId: 1, }, id: 16, }, state: C_NEW, ] containerId=container_1375740621345_0006_01_000016 queue=default: capacity=1.0, absoluteCapacity=1.0, usedResources=<memory:24576, vCores:19>usedCapacity=0.5, absoluteUsedCapacity=0.5, numApps=5, numContainers=19 usedCapacity=0.5 absoluteUsedCapacity=0.5 used=<memory:24576, vCores:19> cluster=<memory:49152, vCores:96>
2013-08-05 22:21:42,540 INFO org.apache.hadoop.yarn.server.resourcemanager.scheduler.capacity.ParentQueue: Re-sorting queues since queue: root.default stats: default: capacity=1.0, absoluteCapacity=1.0, usedResources=<memory:25600, vCores:20>usedCapacity=0.5208333, absoluteUsedCapacity=0.5208333, numApps=5, numContainers=20
2013-08-05 22:21:42,540 INFO org.apache.hadoop.yarn.server.resourcemanager.scheduler.capacity.ParentQueue: assignedContainer queue=root usedCapacity=0.5208333 absoluteUsedCapacity=0.5208333 used=<memory:25600, vCores:20> cluster=<memory:49152, vCores:96>
2013-08-05 22:21:42,541 INFO org.apache.hadoop.yarn.server.resourcemanager.rmcontainer.RMContainerImpl: container_1375740621345_0006_01_000017 Container Transitioned from NEW to ALLOCATED
2013-08-05 22:21:42,541 INFO org.apache.hadoop.yarn.server.resourcemanager.RMAuditLogger: USER=ubuntu	OPERATION=AM Allocated Container	TARGET=SchedulerApp	RESULT=SUCCESS	APPID=application_1375740621345_0006	CONTAINERID=container_1375740621345_0006_01_000017
2013-08-05 22:21:42,541 INFO org.apache.hadoop.yarn.server.resourcemanager.scheduler.common.fica.FiCaSchedulerNode: Assigned container container_1375740621345_0006_01_000017 of capacity <memory:1024, vCores:1> on host hadoop-100-2:37374, which currently has 6 containers, <memory:8192, vCores:6> used and <memory:0, vCores:10> available
2013-08-05 22:21:42,542 INFO org.apache.hadoop.yarn.server.resourcemanager.scheduler.capacity.LeafQueue: assignedContainer application=application_1375740621345_0006 container=Container: [ContainerId: container_1375740621345_0006_01_000017, NodeId: hadoop-100-2:37374, NodeHttpAddress: hadoop-100-2:8042, Resource: <memory:1024, vCores:1>, Priority: 20, State: NEW, Token: null, Status: container_id {, app_attempt_id {, application_id {, id: 6, cluster_timestamp: 1375740621345, }, attemptId: 1, }, id: 17, }, state: C_NEW, ] containerId=container_1375740621345_0006_01_000017 queue=default: capacity=1.0, absoluteCapacity=1.0, usedResources=<memory:25600, vCores:20>usedCapacity=0.5208333, absoluteUsedCapacity=0.5208333, numApps=5, numContainers=20 usedCapacity=0.5208333 absoluteUsedCapacity=0.5208333 used=<memory:25600, vCores:20> cluster=<memory:49152, vCores:96>
2013-08-05 22:21:42,542 INFO org.apache.hadoop.yarn.server.resourcemanager.scheduler.capacity.ParentQueue: Re-sorting queues since queue: root.default stats: default: capacity=1.0, absoluteCapacity=1.0, usedResources=<memory:26624, vCores:21>usedCapacity=0.5416667, absoluteUsedCapacity=0.5416667, numApps=5, numContainers=21
2013-08-05 22:21:42,542 INFO org.apache.hadoop.yarn.server.resourcemanager.scheduler.capacity.ParentQueue: assignedContainer queue=root usedCapacity=0.5416667 absoluteUsedCapacity=0.5416667 used=<memory:26624, vCores:21> cluster=<memory:49152, vCores:96>
2013-08-05 22:21:42,544 INFO org.apache.hadoop.yarn.server.resourcemanager.rmcontainer.RMContainerImpl: container_1375740621345_0006_01_000018 Container Transitioned from NEW to ALLOCATED
2013-08-05 22:21:42,544 INFO org.apache.hadoop.yarn.server.resourcemanager.RMAuditLogger: USER=ubuntu	OPERATION=AM Allocated Container	TARGET=SchedulerApp	RESULT=SUCCESS	APPID=application_1375740621345_0006	CONTAINERID=container_1375740621345_0006_01_000018
2013-08-05 22:21:42,544 INFO org.apache.hadoop.yarn.server.resourcemanager.scheduler.common.fica.FiCaSchedulerNode: Assigned container container_1375740621345_0006_01_000018 of capacity <memory:1024, vCores:1> on host hadoop-100-7:36057, which currently has 1 containers, <memory:1024, vCores:1> used and <memory:7168, vCores:15> available
2013-08-05 22:21:42,545 INFO org.apache.hadoop.yarn.server.resourcemanager.scheduler.capacity.LeafQueue: assignedContainer application=application_1375740621345_0006 container=Container: [ContainerId: container_1375740621345_0006_01_000018, NodeId: hadoop-100-7:36057, NodeHttpAddress: hadoop-100-7:8042, Resource: <memory:1024, vCores:1>, Priority: 20, State: NEW, Token: null, Status: container_id {, app_attempt_id {, application_id {, id: 6, cluster_timestamp: 1375740621345, }, attemptId: 1, }, id: 18, }, state: C_NEW, ] containerId=container_1375740621345_0006_01_000018 queue=default: capacity=1.0, absoluteCapacity=1.0, usedResources=<memory:26624, vCores:21>usedCapacity=0.5416667, absoluteUsedCapacity=0.5416667, numApps=5, numContainers=21 usedCapacity=0.5416667 absoluteUsedCapacity=0.5416667 used=<memory:26624, vCores:21> cluster=<memory:49152, vCores:96>
2013-08-05 22:21:42,545 INFO org.apache.hadoop.yarn.server.resourcemanager.scheduler.capacity.ParentQueue: Re-sorting queues since queue: root.default stats: default: capacity=1.0, absoluteCapacity=1.0, usedResources=<memory:27648, vCores:22>usedCapacity=0.5625, absoluteUsedCapacity=0.5625, numApps=5, numContainers=22
2013-08-05 22:21:42,546 INFO org.apache.hadoop.yarn.server.resourcemanager.scheduler.capacity.ParentQueue: assignedContainer queue=root usedCapacity=0.5625 absoluteUsedCapacity=0.5625 used=<memory:27648, vCores:22> cluster=<memory:49152, vCores:96>
2013-08-05 22:21:42,546 INFO org.apache.hadoop.yarn.server.resourcemanager.rmcontainer.RMContainerImpl: container_1375740621345_0006_01_000019 Container Transitioned from NEW to ALLOCATED
2013-08-05 22:21:42,546 INFO org.apache.hadoop.yarn.server.resourcemanager.RMAuditLogger: USER=ubuntu	OPERATION=AM Allocated Container	TARGET=SchedulerApp	RESULT=SUCCESS	APPID=application_1375740621345_0006	CONTAINERID=container_1375740621345_0006_01_000019
2013-08-05 22:21:42,546 INFO org.apache.hadoop.yarn.server.resourcemanager.scheduler.common.fica.FiCaSchedulerNode: Assigned container container_1375740621345_0006_01_000019 of capacity <memory:1024, vCores:1> on host hadoop-100-7:36057, which currently has 2 containers, <memory:2048, vCores:2> used and <memory:6144, vCores:14> available
2013-08-05 22:21:42,547 INFO org.apache.hadoop.yarn.server.resourcemanager.scheduler.capacity.LeafQueue: assignedContainer application=application_1375740621345_0006 container=Container: [ContainerId: container_1375740621345_0006_01_000019, NodeId: hadoop-100-7:36057, NodeHttpAddress: hadoop-100-7:8042, Resource: <memory:1024, vCores:1>, Priority: 20, State: NEW, Token: null, Status: container_id {, app_attempt_id {, application_id {, id: 6, cluster_timestamp: 1375740621345, }, attemptId: 1, }, id: 19, }, state: C_NEW, ] containerId=container_1375740621345_0006_01_000019 queue=default: capacity=1.0, absoluteCapacity=1.0, usedResources=<memory:27648, vCores:22>usedCapacity=0.5625, absoluteUsedCapacity=0.5625, numApps=5, numContainers=22 usedCapacity=0.5625 absoluteUsedCapacity=0.5625 used=<memory:27648, vCores:22> cluster=<memory:49152, vCores:96>
2013-08-05 22:21:42,547 INFO org.apache.hadoop.yarn.server.resourcemanager.scheduler.capacity.ParentQueue: Re-sorting queues since queue: root.default stats: default: capacity=1.0, absoluteCapacity=1.0, usedResources=<memory:28672, vCores:23>usedCapacity=0.5833333, absoluteUsedCapacity=0.5833333, numApps=5, numContainers=23
2013-08-05 22:21:42,548 INFO org.apache.hadoop.yarn.server.resourcemanager.scheduler.capacity.ParentQueue: assignedContainer queue=root usedCapacity=0.5833333 absoluteUsedCapacity=0.5833333 used=<memory:28672, vCores:23> cluster=<memory:49152, vCores:96>
2013-08-05 22:21:42,548 INFO org.apache.hadoop.yarn.server.resourcemanager.rmcontainer.RMContainerImpl: container_1375740621345_0006_01_000020 Container Transitioned from NEW to ALLOCATED
2013-08-05 22:21:42,548 INFO org.apache.hadoop.yarn.server.resourcemanager.RMAuditLogger: USER=ubuntu	OPERATION=AM Allocated Container	TARGET=SchedulerApp	RESULT=SUCCESS	APPID=application_1375740621345_0006	CONTAINERID=container_1375740621345_0006_01_000020
2013-08-05 22:21:42,548 INFO org.apache.hadoop.yarn.server.resourcemanager.scheduler.common.fica.FiCaSchedulerNode: Assigned container container_1375740621345_0006_01_000020 of capacity <memory:1024, vCores:1> on host hadoop-100-7:36057, which currently has 3 containers, <memory:3072, vCores:3> used and <memory:5120, vCores:13> available
2013-08-05 22:21:42,549 INFO org.apache.hadoop.yarn.server.resourcemanager.scheduler.capacity.LeafQueue: assignedContainer application=application_1375740621345_0006 container=Container: [ContainerId: container_1375740621345_0006_01_000020, NodeId: hadoop-100-7:36057, NodeHttpAddress: hadoop-100-7:8042, Resource: <memory:1024, vCores:1>, Priority: 20, State: NEW, Token: null, Status: container_id {, app_attempt_id {, application_id {, id: 6, cluster_timestamp: 1375740621345, }, attemptId: 1, }, id: 20, }, state: C_NEW, ] containerId=container_1375740621345_0006_01_000020 queue=default: capacity=1.0, absoluteCapacity=1.0, usedResources=<memory:28672, vCores:23>usedCapacity=0.5833333, absoluteUsedCapacity=0.5833333, numApps=5, numContainers=23 usedCapacity=0.5833333 absoluteUsedCapacity=0.5833333 used=<memory:28672, vCores:23> cluster=<memory:49152, vCores:96>
2013-08-05 22:21:42,550 INFO org.apache.hadoop.yarn.server.resourcemanager.scheduler.capacity.ParentQueue: Re-sorting queues since queue: root.default stats: default: capacity=1.0, absoluteCapacity=1.0, usedResources=<memory:29696, vCores:24>usedCapacity=0.6041667, absoluteUsedCapacity=0.6041667, numApps=5, numContainers=24
2013-08-05 22:21:42,550 INFO org.apache.hadoop.yarn.server.resourcemanager.scheduler.capacity.ParentQueue: assignedContainer queue=root usedCapacity=0.6041667 absoluteUsedCapacity=0.6041667 used=<memory:29696, vCores:24> cluster=<memory:49152, vCores:96>
2013-08-05 22:21:42,550 INFO org.apache.hadoop.yarn.server.resourcemanager.rmcontainer.RMContainerImpl: container_1375740621345_0006_01_000021 Container Transitioned from NEW to ALLOCATED
2013-08-05 22:21:42,550 INFO org.apache.hadoop.yarn.server.resourcemanager.RMAuditLogger: USER=ubuntu	OPERATION=AM Allocated Container	TARGET=SchedulerApp	RESULT=SUCCESS	APPID=application_1375740621345_0006	CONTAINERID=container_1375740621345_0006_01_000021
2013-08-05 22:21:42,550 INFO org.apache.hadoop.yarn.server.resourcemanager.scheduler.common.fica.FiCaSchedulerNode: Assigned container container_1375740621345_0006_01_000021 of capacity <memory:1024, vCores:1> on host hadoop-100-7:36057, which currently has 4 containers, <memory:4096, vCores:4> used and <memory:4096, vCores:12> available
2013-08-05 22:21:42,551 INFO org.apache.hadoop.yarn.server.resourcemanager.scheduler.capacity.LeafQueue: assignedContainer application=application_1375740621345_0006 container=Container: [ContainerId: container_1375740621345_0006_01_000021, NodeId: hadoop-100-7:36057, NodeHttpAddress: hadoop-100-7:8042, Resource: <memory:1024, vCores:1>, Priority: 20, State: NEW, Token: null, Status: container_id {, app_attempt_id {, application_id {, id: 6, cluster_timestamp: 1375740621345, }, attemptId: 1, }, id: 21, }, state: C_NEW, ] containerId=container_1375740621345_0006_01_000021 queue=default: capacity=1.0, absoluteCapacity=1.0, usedResources=<memory:29696, vCores:24>usedCapacity=0.6041667, absoluteUsedCapacity=0.6041667, numApps=5, numContainers=24 usedCapacity=0.6041667 absoluteUsedCapacity=0.6041667 used=<memory:29696, vCores:24> cluster=<memory:49152, vCores:96>
2013-08-05 22:21:42,552 INFO org.apache.hadoop.yarn.server.resourcemanager.scheduler.capacity.ParentQueue: Re-sorting queues since queue: root.default stats: default: capacity=1.0, absoluteCapacity=1.0, usedResources=<memory:30720, vCores:25>usedCapacity=0.625, absoluteUsedCapacity=0.625, numApps=5, numContainers=25
2013-08-05 22:21:42,552 INFO org.apache.hadoop.yarn.server.resourcemanager.scheduler.capacity.ParentQueue: assignedContainer queue=root usedCapacity=0.625 absoluteUsedCapacity=0.625 used=<memory:30720, vCores:25> cluster=<memory:49152, vCores:96>
2013-08-05 22:21:42,552 INFO org.apache.hadoop.yarn.server.resourcemanager.rmcontainer.RMContainerImpl: container_1375740621345_0006_01_000022 Container Transitioned from NEW to ALLOCATED
2013-08-05 22:21:42,552 INFO org.apache.hadoop.yarn.server.resourcemanager.RMAuditLogger: USER=ubuntu	OPERATION=AM Allocated Container	TARGET=SchedulerApp	RESULT=SUCCESS	APPID=application_1375740621345_0006	CONTAINERID=container_1375740621345_0006_01_000022
2013-08-05 22:21:42,553 INFO org.apache.hadoop.yarn.server.resourcemanager.scheduler.common.fica.FiCaSchedulerNode: Assigned container container_1375740621345_0006_01_000022 of capacity <memory:1024, vCores:1> on host hadoop-100-7:36057, which currently has 5 containers, <memory:5120, vCores:5> used and <memory:3072, vCores:11> available
2013-08-05 22:21:42,553 INFO org.apache.hadoop.yarn.server.resourcemanager.scheduler.capacity.LeafQueue: assignedContainer application=application_1375740621345_0006 container=Container: [ContainerId: container_1375740621345_0006_01_000022, NodeId: hadoop-100-7:36057, NodeHttpAddress: hadoop-100-7:8042, Resource: <memory:1024, vCores:1>, Priority: 20, State: NEW, Token: null, Status: container_id {, app_attempt_id {, application_id {, id: 6, cluster_timestamp: 1375740621345, }, attemptId: 1, }, id: 22, }, state: C_NEW, ] containerId=container_1375740621345_0006_01_000022 queue=default: capacity=1.0, absoluteCapacity=1.0, usedResources=<memory:30720, vCores:25>usedCapacity=0.625, absoluteUsedCapacity=0.625, numApps=5, numContainers=25 usedCapacity=0.625 absoluteUsedCapacity=0.625 used=<memory:30720, vCores:25> cluster=<memory:49152, vCores:96>
2013-08-05 22:21:42,554 INFO org.apache.hadoop.yarn.server.resourcemanager.scheduler.capacity.ParentQueue: Re-sorting queues since queue: root.default stats: default: capacity=1.0, absoluteCapacity=1.0, usedResources=<memory:31744, vCores:26>usedCapacity=0.6458333, absoluteUsedCapacity=0.6458333, numApps=5, numContainers=26
2013-08-05 22:21:42,554 INFO org.apache.hadoop.yarn.server.resourcemanager.scheduler.capacity.ParentQueue: assignedContainer queue=root usedCapacity=0.6458333 absoluteUsedCapacity=0.6458333 used=<memory:31744, vCores:26> cluster=<memory:49152, vCores:96>
2013-08-05 22:21:42,554 INFO org.apache.hadoop.yarn.server.resourcemanager.rmcontainer.RMContainerImpl: container_1375740621345_0006_01_000023 Container Transitioned from NEW to ALLOCATED
2013-08-05 22:21:42,555 INFO org.apache.hadoop.yarn.server.resourcemanager.RMAuditLogger: USER=ubuntu	OPERATION=AM Allocated Container	TARGET=SchedulerApp	RESULT=SUCCESS	APPID=application_1375740621345_0006	CONTAINERID=container_1375740621345_0006_01_000023
2013-08-05 22:21:42,555 INFO org.apache.hadoop.yarn.server.resourcemanager.scheduler.common.fica.FiCaSchedulerNode: Assigned container container_1375740621345_0006_01_000023 of capacity <memory:1024, vCores:1> on host hadoop-100-7:36057, which currently has 6 containers, <memory:6144, vCores:6> used and <memory:2048, vCores:10> available
2013-08-05 22:21:42,556 INFO org.apache.hadoop.yarn.server.resourcemanager.scheduler.capacity.LeafQueue: assignedContainer application=application_1375740621345_0006 container=Container: [ContainerId: container_1375740621345_0006_01_000023, NodeId: hadoop-100-7:36057, NodeHttpAddress: hadoop-100-7:8042, Resource: <memory:1024, vCores:1>, Priority: 20, State: NEW, Token: null, Status: container_id {, app_attempt_id {, application_id {, id: 6, cluster_timestamp: 1375740621345, }, attemptId: 1, }, id: 23, }, state: C_NEW, ] containerId=container_1375740621345_0006_01_000023 queue=default: capacity=1.0, absoluteCapacity=1.0, usedResources=<memory:31744, vCores:26>usedCapacity=0.6458333, absoluteUsedCapacity=0.6458333, numApps=5, numContainers=26 usedCapacity=0.6458333 absoluteUsedCapacity=0.6458333 used=<memory:31744, vCores:26> cluster=<memory:49152, vCores:96>
2013-08-05 22:21:42,556 INFO org.apache.hadoop.yarn.server.resourcemanager.scheduler.capacity.ParentQueue: Re-sorting queues since queue: root.default stats: default: capacity=1.0, absoluteCapacity=1.0, usedResources=<memory:32768, vCores:27>usedCapacity=0.6666667, absoluteUsedCapacity=0.6666667, numApps=5, numContainers=27
2013-08-05 22:21:42,556 INFO org.apache.hadoop.yarn.server.resourcemanager.scheduler.capacity.ParentQueue: assignedContainer queue=root usedCapacity=0.6666667 absoluteUsedCapacity=0.6666667 used=<memory:32768, vCores:27> cluster=<memory:49152, vCores:96>
2013-08-05 22:21:42,556 INFO org.apache.hadoop.yarn.server.resourcemanager.rmcontainer.RMContainerImpl: container_1375740621345_0006_01_000024 Container Transitioned from NEW to ALLOCATED
2013-08-05 22:21:42,557 INFO org.apache.hadoop.yarn.server.resourcemanager.RMAuditLogger: USER=ubuntu	OPERATION=AM Allocated Container	TARGET=SchedulerApp	RESULT=SUCCESS	APPID=application_1375740621345_0006	CONTAINERID=container_1375740621345_0006_01_000024
2013-08-05 22:21:42,557 INFO org.apache.hadoop.yarn.server.resourcemanager.scheduler.common.fica.FiCaSchedulerNode: Assigned container container_1375740621345_0006_01_000024 of capacity <memory:1024, vCores:1> on host hadoop-100-7:36057, which currently has 7 containers, <memory:7168, vCores:7> used and <memory:1024, vCores:9> available
2013-08-05 22:21:42,558 INFO org.apache.hadoop.yarn.server.resourcemanager.scheduler.capacity.LeafQueue: assignedContainer application=application_1375740621345_0006 container=Container: [ContainerId: container_1375740621345_0006_01_000024, NodeId: hadoop-100-7:36057, NodeHttpAddress: hadoop-100-7:8042, Resource: <memory:1024, vCores:1>, Priority: 20, State: NEW, Token: null, Status: container_id {, app_attempt_id {, application_id {, id: 6, cluster_timestamp: 1375740621345, }, attemptId: 1, }, id: 24, }, state: C_NEW, ] containerId=container_1375740621345_0006_01_000024 queue=default: capacity=1.0, absoluteCapacity=1.0, usedResources=<memory:32768, vCores:27>usedCapacity=0.6666667, absoluteUsedCapacity=0.6666667, numApps=5, numContainers=27 usedCapacity=0.6666667 absoluteUsedCapacity=0.6666667 used=<memory:32768, vCores:27> cluster=<memory:49152, vCores:96>
2013-08-05 22:21:42,558 INFO org.apache.hadoop.yarn.server.resourcemanager.scheduler.capacity.ParentQueue: Re-sorting queues since queue: root.default stats: default: capacity=1.0, absoluteCapacity=1.0, usedResources=<memory:33792, vCores:28>usedCapacity=0.6875, absoluteUsedCapacity=0.6875, numApps=5, numContainers=28
2013-08-05 22:21:42,558 INFO org.apache.hadoop.yarn.server.resourcemanager.scheduler.capacity.ParentQueue: assignedContainer queue=root usedCapacity=0.6875 absoluteUsedCapacity=0.6875 used=<memory:33792, vCores:28> cluster=<memory:49152, vCores:96>
2013-08-05 22:21:42,559 INFO org.apache.hadoop.yarn.server.resourcemanager.rmcontainer.RMContainerImpl: container_1375740621345_0006_01_000025 Container Transitioned from NEW to ALLOCATED
2013-08-05 22:21:42,559 INFO org.apache.hadoop.yarn.server.resourcemanager.RMAuditLogger: USER=ubuntu	OPERATION=AM Allocated Container	TARGET=SchedulerApp	RESULT=SUCCESS	APPID=application_1375740621345_0006	CONTAINERID=container_1375740621345_0006_01_000025
2013-08-05 22:21:42,559 INFO org.apache.hadoop.yarn.server.resourcemanager.scheduler.common.fica.FiCaSchedulerNode: Assigned container container_1375740621345_0006_01_000025 of capacity <memory:1024, vCores:1> on host hadoop-100-7:36057, which currently has 8 containers, <memory:8192, vCores:8> used and <memory:0, vCores:8> available
2013-08-05 22:21:42,560 INFO org.apache.hadoop.yarn.server.resourcemanager.scheduler.capacity.LeafQueue: assignedContainer application=application_1375740621345_0006 container=Container: [ContainerId: container_1375740621345_0006_01_000025, NodeId: hadoop-100-7:36057, NodeHttpAddress: hadoop-100-7:8042, Resource: <memory:1024, vCores:1>, Priority: 20, State: NEW, Token: null, Status: container_id {, app_attempt_id {, application_id {, id: 6, cluster_timestamp: 1375740621345, }, attemptId: 1, }, id: 25, }, state: C_NEW, ] containerId=container_1375740621345_0006_01_000025 queue=default: capacity=1.0, absoluteCapacity=1.0, usedResources=<memory:33792, vCores:28>usedCapacity=0.6875, absoluteUsedCapacity=0.6875, numApps=5, numContainers=28 usedCapacity=0.6875 absoluteUsedCapacity=0.6875 used=<memory:33792, vCores:28> cluster=<memory:49152, vCores:96>
2013-08-05 22:21:42,560 INFO org.apache.hadoop.yarn.server.resourcemanager.scheduler.capacity.ParentQueue: Re-sorting queues since queue: root.default stats: default: capacity=1.0, absoluteCapacity=1.0, usedResources=<memory:34816, vCores:29>usedCapacity=0.7083333, absoluteUsedCapacity=0.7083333, numApps=5, numContainers=29
2013-08-05 22:21:42,560 INFO org.apache.hadoop.yarn.server.resourcemanager.scheduler.capacity.ParentQueue: assignedContainer queue=root usedCapacity=0.7083333 absoluteUsedCapacity=0.7083333 used=<memory:34816, vCores:29> cluster=<memory:49152, vCores:96>
2013-08-05 22:21:42,620 INFO org.apache.hadoop.yarn.server.resourcemanager.rmcontainer.RMContainerImpl: container_1375740621345_0006_01_000026 Container Transitioned from NEW to ALLOCATED
2013-08-05 22:21:42,620 INFO org.apache.hadoop.yarn.server.resourcemanager.RMAuditLogger: USER=ubuntu	OPERATION=AM Allocated Container	TARGET=SchedulerApp	RESULT=SUCCESS	APPID=application_1375740621345_0006	CONTAINERID=container_1375740621345_0006_01_000026
2013-08-05 22:21:42,621 INFO org.apache.hadoop.yarn.server.resourcemanager.scheduler.common.fica.FiCaSchedulerNode: Assigned container container_1375740621345_0006_01_000026 of capacity <memory:1024, vCores:1> on host hadoop-100-6:42294, which currently has 2 containers, <memory:3072, vCores:2> used and <memory:5120, vCores:14> available
2013-08-05 22:21:42,622 INFO org.apache.hadoop.yarn.server.resourcemanager.scheduler.capacity.LeafQueue: assignedContainer application=application_1375740621345_0006 container=Container: [ContainerId: container_1375740621345_0006_01_000026, NodeId: hadoop-100-6:42294, NodeHttpAddress: hadoop-100-6:8042, Resource: <memory:1024, vCores:1>, Priority: 20, State: NEW, Token: null, Status: container_id {, app_attempt_id {, application_id {, id: 6, cluster_timestamp: 1375740621345, }, attemptId: 1, }, id: 26, }, state: C_NEW, ] containerId=container_1375740621345_0006_01_000026 queue=default: capacity=1.0, absoluteCapacity=1.0, usedResources=<memory:34816, vCores:29>usedCapacity=0.7083333, absoluteUsedCapacity=0.7083333, numApps=5, numContainers=29 usedCapacity=0.7083333 absoluteUsedCapacity=0.7083333 used=<memory:34816, vCores:29> cluster=<memory:49152, vCores:96>
2013-08-05 22:21:42,622 INFO org.apache.hadoop.yarn.server.resourcemanager.scheduler.capacity.ParentQueue: Re-sorting queues since queue: root.default stats: default: capacity=1.0, absoluteCapacity=1.0, usedResources=<memory:35840, vCores:30>usedCapacity=0.7291667, absoluteUsedCapacity=0.7291667, numApps=5, numContainers=30
2013-08-05 22:21:42,622 INFO org.apache.hadoop.yarn.server.resourcemanager.scheduler.capacity.ParentQueue: assignedContainer queue=root usedCapacity=0.7291667 absoluteUsedCapacity=0.7291667 used=<memory:35840, vCores:30> cluster=<memory:49152, vCores:96>
2013-08-05 22:21:42,623 INFO org.apache.hadoop.yarn.server.resourcemanager.rmcontainer.RMContainerImpl: container_1375740621345_0006_01_000027 Container Transitioned from NEW to ALLOCATED
2013-08-05 22:21:42,623 INFO org.apache.hadoop.yarn.server.resourcemanager.RMAuditLogger: USER=ubuntu	OPERATION=AM Allocated Container	TARGET=SchedulerApp	RESULT=SUCCESS	APPID=application_1375740621345_0006	CONTAINERID=container_1375740621345_0006_01_000027
2013-08-05 22:21:42,623 INFO org.apache.hadoop.yarn.server.resourcemanager.scheduler.common.fica.FiCaSchedulerNode: Assigned container container_1375740621345_0006_01_000027 of capacity <memory:1024, vCores:1> on host hadoop-100-6:42294, which currently has 3 containers, <memory:4096, vCores:3> used and <memory:4096, vCores:13> available
2013-08-05 22:21:42,624 INFO org.apache.hadoop.yarn.server.resourcemanager.scheduler.capacity.LeafQueue: assignedContainer application=application_1375740621345_0006 container=Container: [ContainerId: container_1375740621345_0006_01_000027, NodeId: hadoop-100-6:42294, NodeHttpAddress: hadoop-100-6:8042, Resource: <memory:1024, vCores:1>, Priority: 20, State: NEW, Token: null, Status: container_id {, app_attempt_id {, application_id {, id: 6, cluster_timestamp: 1375740621345, }, attemptId: 1, }, id: 27, }, state: C_NEW, ] containerId=container_1375740621345_0006_01_000027 queue=default: capacity=1.0, absoluteCapacity=1.0, usedResources=<memory:35840, vCores:30>usedCapacity=0.7291667, absoluteUsedCapacity=0.7291667, numApps=5, numContainers=30 usedCapacity=0.7291667 absoluteUsedCapacity=0.7291667 used=<memory:35840, vCores:30> cluster=<memory:49152, vCores:96>
2013-08-05 22:21:42,624 INFO org.apache.hadoop.yarn.server.resourcemanager.scheduler.capacity.ParentQueue: Re-sorting queues since queue: root.default stats: default: capacity=1.0, absoluteCapacity=1.0, usedResources=<memory:36864, vCores:31>usedCapacity=0.75, absoluteUsedCapacity=0.75, numApps=5, numContainers=31
2013-08-05 22:21:42,624 INFO org.apache.hadoop.yarn.server.resourcemanager.scheduler.capacity.ParentQueue: assignedContainer queue=root usedCapacity=0.75 absoluteUsedCapacity=0.75 used=<memory:36864, vCores:31> cluster=<memory:49152, vCores:96>
2013-08-05 22:21:42,625 INFO org.apache.hadoop.yarn.server.resourcemanager.rmcontainer.RMContainerImpl: container_1375740621345_0006_01_000028 Container Transitioned from NEW to ALLOCATED
2013-08-05 22:21:42,625 INFO org.apache.hadoop.yarn.server.resourcemanager.RMAuditLogger: USER=ubuntu	OPERATION=AM Allocated Container	TARGET=SchedulerApp	RESULT=SUCCESS	APPID=application_1375740621345_0006	CONTAINERID=container_1375740621345_0006_01_000028
2013-08-05 22:21:42,625 INFO org.apache.hadoop.yarn.server.resourcemanager.scheduler.common.fica.FiCaSchedulerNode: Assigned container container_1375740621345_0006_01_000028 of capacity <memory:1024, vCores:1> on host hadoop-100-6:42294, which currently has 4 containers, <memory:5120, vCores:4> used and <memory:3072, vCores:12> available
2013-08-05 22:21:42,626 INFO org.apache.hadoop.yarn.server.resourcemanager.scheduler.capacity.LeafQueue: assignedContainer application=application_1375740621345_0006 container=Container: [ContainerId: container_1375740621345_0006_01_000028, NodeId: hadoop-100-6:42294, NodeHttpAddress: hadoop-100-6:8042, Resource: <memory:1024, vCores:1>, Priority: 20, State: NEW, Token: null, Status: container_id {, app_attempt_id {, application_id {, id: 6, cluster_timestamp: 1375740621345, }, attemptId: 1, }, id: 28, }, state: C_NEW, ] containerId=container_1375740621345_0006_01_000028 queue=default: capacity=1.0, absoluteCapacity=1.0, usedResources=<memory:36864, vCores:31>usedCapacity=0.75, absoluteUsedCapacity=0.75, numApps=5, numContainers=31 usedCapacity=0.75 absoluteUsedCapacity=0.75 used=<memory:36864, vCores:31> cluster=<memory:49152, vCores:96>
2013-08-05 22:21:42,626 INFO org.apache.hadoop.yarn.server.resourcemanager.scheduler.capacity.ParentQueue: Re-sorting queues since queue: root.default stats: default: capacity=1.0, absoluteCapacity=1.0, usedResources=<memory:37888, vCores:32>usedCapacity=0.7708333, absoluteUsedCapacity=0.7708333, numApps=5, numContainers=32
2013-08-05 22:21:42,626 INFO org.apache.hadoop.yarn.server.resourcemanager.scheduler.capacity.ParentQueue: assignedContainer queue=root usedCapacity=0.7708333 absoluteUsedCapacity=0.7708333 used=<memory:37888, vCores:32> cluster=<memory:49152, vCores:96>
2013-08-05 22:21:42,627 INFO org.apache.hadoop.yarn.server.resourcemanager.rmcontainer.RMContainerImpl: container_1375740621345_0006_01_000029 Container Transitioned from NEW to ALLOCATED
2013-08-05 22:21:42,627 INFO org.apache.hadoop.yarn.server.resourcemanager.RMAuditLogger: USER=ubuntu	OPERATION=AM Allocated Container	TARGET=SchedulerApp	RESULT=SUCCESS	APPID=application_1375740621345_0006	CONTAINERID=container_1375740621345_0006_01_000029
2013-08-05 22:21:42,627 INFO org.apache.hadoop.yarn.server.resourcemanager.scheduler.common.fica.FiCaSchedulerNode: Assigned container container_1375740621345_0006_01_000029 of capacity <memory:1024, vCores:1> on host hadoop-100-6:42294, which currently has 5 containers, <memory:6144, vCores:5> used and <memory:2048, vCores:11> available
2013-08-05 22:21:42,628 INFO org.apache.hadoop.yarn.server.resourcemanager.scheduler.capacity.LeafQueue: assignedContainer application=application_1375740621345_0006 container=Container: [ContainerId: container_1375740621345_0006_01_000029, NodeId: hadoop-100-6:42294, NodeHttpAddress: hadoop-100-6:8042, Resource: <memory:1024, vCores:1>, Priority: 20, State: NEW, Token: null, Status: container_id {, app_attempt_id {, application_id {, id: 6, cluster_timestamp: 1375740621345, }, attemptId: 1, }, id: 29, }, state: C_NEW, ] containerId=container_1375740621345_0006_01_000029 queue=default: capacity=1.0, absoluteCapacity=1.0, usedResources=<memory:37888, vCores:32>usedCapacity=0.7708333, absoluteUsedCapacity=0.7708333, numApps=5, numContainers=32 usedCapacity=0.7708333 absoluteUsedCapacity=0.7708333 used=<memory:37888, vCores:32> cluster=<memory:49152, vCores:96>
2013-08-05 22:21:42,628 INFO org.apache.hadoop.yarn.server.resourcemanager.scheduler.capacity.ParentQueue: Re-sorting queues since queue: root.default stats: default: capacity=1.0, absoluteCapacity=1.0, usedResources=<memory:38912, vCores:33>usedCapacity=0.7916667, absoluteUsedCapacity=0.7916667, numApps=5, numContainers=33
2013-08-05 22:21:42,628 INFO org.apache.hadoop.yarn.server.resourcemanager.scheduler.capacity.ParentQueue: assignedContainer queue=root usedCapacity=0.7916667 absoluteUsedCapacity=0.7916667 used=<memory:38912, vCores:33> cluster=<memory:49152, vCores:96>
2013-08-05 22:21:42,629 INFO org.apache.hadoop.yarn.server.resourcemanager.rmcontainer.RMContainerImpl: container_1375740621345_0006_01_000030 Container Transitioned from NEW to ALLOCATED
2013-08-05 22:21:42,629 INFO org.apache.hadoop.yarn.server.resourcemanager.RMAuditLogger: USER=ubuntu	OPERATION=AM Allocated Container	TARGET=SchedulerApp	RESULT=SUCCESS	APPID=application_1375740621345_0006	CONTAINERID=container_1375740621345_0006_01_000030
2013-08-05 22:21:42,629 INFO org.apache.hadoop.yarn.server.resourcemanager.scheduler.common.fica.FiCaSchedulerNode: Assigned container container_1375740621345_0006_01_000030 of capacity <memory:1024, vCores:1> on host hadoop-100-6:42294, which currently has 6 containers, <memory:7168, vCores:6> used and <memory:1024, vCores:10> available
2013-08-05 22:21:42,630 INFO org.apache.hadoop.yarn.server.resourcemanager.scheduler.capacity.LeafQueue: assignedContainer application=application_1375740621345_0006 container=Container: [ContainerId: container_1375740621345_0006_01_000030, NodeId: hadoop-100-6:42294, NodeHttpAddress: hadoop-100-6:8042, Resource: <memory:1024, vCores:1>, Priority: 20, State: NEW, Token: null, Status: container_id {, app_attempt_id {, application_id {, id: 6, cluster_timestamp: 1375740621345, }, attemptId: 1, }, id: 30, }, state: C_NEW, ] containerId=container_1375740621345_0006_01_000030 queue=default: capacity=1.0, absoluteCapacity=1.0, usedResources=<memory:38912, vCores:33>usedCapacity=0.7916667, absoluteUsedCapacity=0.7916667, numApps=5, numContainers=33 usedCapacity=0.7916667 absoluteUsedCapacity=0.7916667 used=<memory:38912, vCores:33> cluster=<memory:49152, vCores:96>
2013-08-05 22:21:42,630 INFO org.apache.hadoop.yarn.server.resourcemanager.scheduler.capacity.ParentQueue: Re-sorting queues since queue: root.default stats: default: capacity=1.0, absoluteCapacity=1.0, usedResources=<memory:39936, vCores:34>usedCapacity=0.8125, absoluteUsedCapacity=0.8125, numApps=5, numContainers=34
2013-08-05 22:21:42,630 INFO org.apache.hadoop.yarn.server.resourcemanager.scheduler.capacity.ParentQueue: assignedContainer queue=root usedCapacity=0.8125 absoluteUsedCapacity=0.8125 used=<memory:39936, vCores:34> cluster=<memory:49152, vCores:96>
2013-08-05 22:21:42,631 INFO org.apache.hadoop.yarn.server.resourcemanager.rmcontainer.RMContainerImpl: container_1375740621345_0006_01_000031 Container Transitioned from NEW to ALLOCATED
2013-08-05 22:21:42,631 INFO org.apache.hadoop.yarn.server.resourcemanager.RMAuditLogger: USER=ubuntu	OPERATION=AM Allocated Container	TARGET=SchedulerApp	RESULT=SUCCESS	APPID=application_1375740621345_0006	CONTAINERID=container_1375740621345_0006_01_000031
2013-08-05 22:21:42,631 INFO org.apache.hadoop.yarn.server.resourcemanager.scheduler.common.fica.FiCaSchedulerNode: Assigned container container_1375740621345_0006_01_000031 of capacity <memory:1024, vCores:1> on host hadoop-100-6:42294, which currently has 7 containers, <memory:8192, vCores:7> used and <memory:0, vCores:9> available
2013-08-05 22:21:42,632 INFO org.apache.hadoop.yarn.server.resourcemanager.scheduler.capacity.LeafQueue: assignedContainer application=application_1375740621345_0006 container=Container: [ContainerId: container_1375740621345_0006_01_000031, NodeId: hadoop-100-6:42294, NodeHttpAddress: hadoop-100-6:8042, Resource: <memory:1024, vCores:1>, Priority: 20, State: NEW, Token: null, Status: container_id {, app_attempt_id {, application_id {, id: 6, cluster_timestamp: 1375740621345, }, attemptId: 1, }, id: 31, }, state: C_NEW, ] containerId=container_1375740621345_0006_01_000031 queue=default: capacity=1.0, absoluteCapacity=1.0, usedResources=<memory:39936, vCores:34>usedCapacity=0.8125, absoluteUsedCapacity=0.8125, numApps=5, numContainers=34 usedCapacity=0.8125 absoluteUsedCapacity=0.8125 used=<memory:39936, vCores:34> cluster=<memory:49152, vCores:96>
2013-08-05 22:21:42,632 INFO org.apache.hadoop.yarn.server.resourcemanager.scheduler.capacity.ParentQueue: Re-sorting queues since queue: root.default stats: default: capacity=1.0, absoluteCapacity=1.0, usedResources=<memory:40960, vCores:35>usedCapacity=0.8333333, absoluteUsedCapacity=0.8333333, numApps=5, numContainers=35
2013-08-05 22:21:42,633 INFO org.apache.hadoop.yarn.server.resourcemanager.scheduler.capacity.ParentQueue: assignedContainer queue=root usedCapacity=0.8333333 absoluteUsedCapacity=0.8333333 used=<memory:40960, vCores:35> cluster=<memory:49152, vCores:96>
2013-08-05 22:21:42,680 INFO org.apache.hadoop.yarn.server.resourcemanager.rmcontainer.RMContainerImpl: container_1375740621345_0006_01_000032 Container Transitioned from NEW to ALLOCATED
2013-08-05 22:21:42,680 INFO org.apache.hadoop.yarn.server.resourcemanager.RMAuditLogger: USER=ubuntu	OPERATION=AM Allocated Container	TARGET=SchedulerApp	RESULT=SUCCESS	APPID=application_1375740621345_0006	CONTAINERID=container_1375740621345_0006_01_000032
2013-08-05 22:21:42,680 INFO org.apache.hadoop.yarn.server.resourcemanager.scheduler.common.fica.FiCaSchedulerNode: Assigned container container_1375740621345_0006_01_000032 of capacity <memory:1024, vCores:1> on host hadoop-100-5:58882, which currently has 1 containers, <memory:1024, vCores:1> used and <memory:7168, vCores:15> available
2013-08-05 22:21:42,681 INFO org.apache.hadoop.yarn.server.resourcemanager.scheduler.capacity.LeafQueue: assignedContainer application=application_1375740621345_0006 container=Container: [ContainerId: container_1375740621345_0006_01_000032, NodeId: hadoop-100-5:58882, NodeHttpAddress: hadoop-100-5:8042, Resource: <memory:1024, vCores:1>, Priority: 20, State: NEW, Token: null, Status: container_id {, app_attempt_id {, application_id {, id: 6, cluster_timestamp: 1375740621345, }, attemptId: 1, }, id: 32, }, state: C_NEW, ] containerId=container_1375740621345_0006_01_000032 queue=default: capacity=1.0, absoluteCapacity=1.0, usedResources=<memory:40960, vCores:35>usedCapacity=0.8333333, absoluteUsedCapacity=0.8333333, numApps=5, numContainers=35 usedCapacity=0.8333333 absoluteUsedCapacity=0.8333333 used=<memory:40960, vCores:35> cluster=<memory:49152, vCores:96>
2013-08-05 22:21:42,682 INFO org.apache.hadoop.yarn.server.resourcemanager.scheduler.capacity.ParentQueue: Re-sorting queues since queue: root.default stats: default: capacity=1.0, absoluteCapacity=1.0, usedResources=<memory:41984, vCores:36>usedCapacity=0.8541667, absoluteUsedCapacity=0.8541667, numApps=5, numContainers=36
2013-08-05 22:21:42,682 INFO org.apache.hadoop.yarn.server.resourcemanager.scheduler.capacity.ParentQueue: assignedContainer queue=root usedCapacity=0.8541667 absoluteUsedCapacity=0.8541667 used=<memory:41984, vCores:36> cluster=<memory:49152, vCores:96>
2013-08-05 22:21:42,682 INFO org.apache.hadoop.yarn.server.resourcemanager.rmcontainer.RMContainerImpl: container_1375740621345_0006_01_000033 Container Transitioned from NEW to ALLOCATED
2013-08-05 22:21:42,682 INFO org.apache.hadoop.yarn.server.resourcemanager.RMAuditLogger: USER=ubuntu	OPERATION=AM Allocated Container	TARGET=SchedulerApp	RESULT=SUCCESS	APPID=application_1375740621345_0006	CONTAINERID=container_1375740621345_0006_01_000033
2013-08-05 22:21:42,682 INFO org.apache.hadoop.yarn.server.resourcemanager.scheduler.common.fica.FiCaSchedulerNode: Assigned container container_1375740621345_0006_01_000033 of capacity <memory:1024, vCores:1> on host hadoop-100-5:58882, which currently has 2 containers, <memory:2048, vCores:2> used and <memory:6144, vCores:14> available
2013-08-05 22:21:42,683 INFO org.apache.hadoop.yarn.server.resourcemanager.scheduler.capacity.LeafQueue: assignedContainer application=application_1375740621345_0006 container=Container: [ContainerId: container_1375740621345_0006_01_000033, NodeId: hadoop-100-5:58882, NodeHttpAddress: hadoop-100-5:8042, Resource: <memory:1024, vCores:1>, Priority: 20, State: NEW, Token: null, Status: container_id {, app_attempt_id {, application_id {, id: 6, cluster_timestamp: 1375740621345, }, attemptId: 1, }, id: 33, }, state: C_NEW, ] containerId=container_1375740621345_0006_01_000033 queue=default: capacity=1.0, absoluteCapacity=1.0, usedResources=<memory:41984, vCores:36>usedCapacity=0.8541667, absoluteUsedCapacity=0.8541667, numApps=5, numContainers=36 usedCapacity=0.8541667 absoluteUsedCapacity=0.8541667 used=<memory:41984, vCores:36> cluster=<memory:49152, vCores:96>
2013-08-05 22:21:42,684 INFO org.apache.hadoop.yarn.server.resourcemanager.scheduler.capacity.ParentQueue: Re-sorting queues since queue: root.default stats: default: capacity=1.0, absoluteCapacity=1.0, usedResources=<memory:43008, vCores:37>usedCapacity=0.875, absoluteUsedCapacity=0.875, numApps=5, numContainers=37
2013-08-05 22:21:42,684 INFO org.apache.hadoop.yarn.server.resourcemanager.scheduler.capacity.ParentQueue: assignedContainer queue=root usedCapacity=0.875 absoluteUsedCapacity=0.875 used=<memory:43008, vCores:37> cluster=<memory:49152, vCores:96>
2013-08-05 22:21:42,684 INFO org.apache.hadoop.yarn.server.resourcemanager.rmcontainer.RMContainerImpl: container_1375740621345_0006_01_000034 Container Transitioned from NEW to ALLOCATED
2013-08-05 22:21:42,684 INFO org.apache.hadoop.yarn.server.resourcemanager.RMAuditLogger: USER=ubuntu	OPERATION=AM Allocated Container	TARGET=SchedulerApp	RESULT=SUCCESS	APPID=application_1375740621345_0006	CONTAINERID=container_1375740621345_0006_01_000034
2013-08-05 22:21:42,685 INFO org.apache.hadoop.yarn.server.resourcemanager.scheduler.common.fica.FiCaSchedulerNode: Assigned container container_1375740621345_0006_01_000034 of capacity <memory:1024, vCores:1> on host hadoop-100-5:58882, which currently has 3 containers, <memory:3072, vCores:3> used and <memory:5120, vCores:13> available
2013-08-05 22:21:42,685 INFO org.apache.hadoop.yarn.server.resourcemanager.scheduler.capacity.LeafQueue: assignedContainer application=application_1375740621345_0006 container=Container: [ContainerId: container_1375740621345_0006_01_000034, NodeId: hadoop-100-5:58882, NodeHttpAddress: hadoop-100-5:8042, Resource: <memory:1024, vCores:1>, Priority: 20, State: NEW, Token: null, Status: container_id {, app_attempt_id {, application_id {, id: 6, cluster_timestamp: 1375740621345, }, attemptId: 1, }, id: 34, }, state: C_NEW, ] containerId=container_1375740621345_0006_01_000034 queue=default: capacity=1.0, absoluteCapacity=1.0, usedResources=<memory:43008, vCores:37>usedCapacity=0.875, absoluteUsedCapacity=0.875, numApps=5, numContainers=37 usedCapacity=0.875 absoluteUsedCapacity=0.875 used=<memory:43008, vCores:37> cluster=<memory:49152, vCores:96>
2013-08-05 22:21:42,686 INFO org.apache.hadoop.yarn.server.resourcemanager.scheduler.capacity.ParentQueue: Re-sorting queues since queue: root.default stats: default: capacity=1.0, absoluteCapacity=1.0, usedResources=<memory:44032, vCores:38>usedCapacity=0.8958333, absoluteUsedCapacity=0.8958333, numApps=5, numContainers=38
2013-08-05 22:21:42,686 INFO org.apache.hadoop.yarn.server.resourcemanager.scheduler.capacity.ParentQueue: assignedContainer queue=root usedCapacity=0.8958333 absoluteUsedCapacity=0.8958333 used=<memory:44032, vCores:38> cluster=<memory:49152, vCores:96>
2013-08-05 22:21:42,686 INFO org.apache.hadoop.yarn.server.resourcemanager.rmcontainer.RMContainerImpl: container_1375740621345_0006_01_000035 Container Transitioned from NEW to ALLOCATED
2013-08-05 22:21:42,687 INFO org.apache.hadoop.yarn.server.resourcemanager.RMAuditLogger: USER=ubuntu	OPERATION=AM Allocated Container	TARGET=SchedulerApp	RESULT=SUCCESS	APPID=application_1375740621345_0006	CONTAINERID=container_1375740621345_0006_01_000035
2013-08-05 22:21:42,687 INFO org.apache.hadoop.yarn.server.resourcemanager.scheduler.common.fica.FiCaSchedulerNode: Assigned container container_1375740621345_0006_01_000035 of capacity <memory:1024, vCores:1> on host hadoop-100-5:58882, which currently has 4 containers, <memory:4096, vCores:4> used and <memory:4096, vCores:12> available
2013-08-05 22:21:42,688 INFO org.apache.hadoop.yarn.server.resourcemanager.scheduler.capacity.LeafQueue: assignedContainer application=application_1375740621345_0006 container=Container: [ContainerId: container_1375740621345_0006_01_000035, NodeId: hadoop-100-5:58882, NodeHttpAddress: hadoop-100-5:8042, Resource: <memory:1024, vCores:1>, Priority: 20, State: NEW, Token: null, Status: container_id {, app_attempt_id {, application_id {, id: 6, cluster_timestamp: 1375740621345, }, attemptId: 1, }, id: 35, }, state: C_NEW, ] containerId=container_1375740621345_0006_01_000035 queue=default: capacity=1.0, absoluteCapacity=1.0, usedResources=<memory:44032, vCores:38>usedCapacity=0.8958333, absoluteUsedCapacity=0.8958333, numApps=5, numContainers=38 usedCapacity=0.8958333 absoluteUsedCapacity=0.8958333 used=<memory:44032, vCores:38> cluster=<memory:49152, vCores:96>
2013-08-05 22:21:42,688 INFO org.apache.hadoop.yarn.server.resourcemanager.scheduler.capacity.ParentQueue: Re-sorting queues since queue: root.default stats: default: capacity=1.0, absoluteCapacity=1.0, usedResources=<memory:45056, vCores:39>usedCapacity=0.9166667, absoluteUsedCapacity=0.9166667, numApps=5, numContainers=39
2013-08-05 22:21:42,688 INFO org.apache.hadoop.yarn.server.resourcemanager.scheduler.capacity.ParentQueue: assignedContainer queue=root usedCapacity=0.9166667 absoluteUsedCapacity=0.9166667 used=<memory:45056, vCores:39> cluster=<memory:49152, vCores:96>
2013-08-05 22:21:42,688 INFO org.apache.hadoop.yarn.server.resourcemanager.rmcontainer.RMContainerImpl: container_1375740621345_0006_01_000036 Container Transitioned from NEW to ALLOCATED
2013-08-05 22:21:42,689 INFO org.apache.hadoop.yarn.server.resourcemanager.RMAuditLogger: USER=ubuntu	OPERATION=AM Allocated Container	TARGET=SchedulerApp	RESULT=SUCCESS	APPID=application_1375740621345_0006	CONTAINERID=container_1375740621345_0006_01_000036
2013-08-05 22:21:42,689 INFO org.apache.hadoop.yarn.server.resourcemanager.scheduler.common.fica.FiCaSchedulerNode: Assigned container container_1375740621345_0006_01_000036 of capacity <memory:1024, vCores:1> on host hadoop-100-5:58882, which currently has 5 containers, <memory:5120, vCores:5> used and <memory:3072, vCores:11> available
2013-08-05 22:21:42,690 INFO org.apache.hadoop.yarn.server.resourcemanager.scheduler.capacity.LeafQueue: assignedContainer application=application_1375740621345_0006 container=Container: [ContainerId: container_1375740621345_0006_01_000036, NodeId: hadoop-100-5:58882, NodeHttpAddress: hadoop-100-5:8042, Resource: <memory:1024, vCores:1>, Priority: 20, State: NEW, Token: null, Status: container_id {, app_attempt_id {, application_id {, id: 6, cluster_timestamp: 1375740621345, }, attemptId: 1, }, id: 36, }, state: C_NEW, ] containerId=container_1375740621345_0006_01_000036 queue=default: capacity=1.0, absoluteCapacity=1.0, usedResources=<memory:45056, vCores:39>usedCapacity=0.9166667, absoluteUsedCapacity=0.9166667, numApps=5, numContainers=39 usedCapacity=0.9166667 absoluteUsedCapacity=0.9166667 used=<memory:45056, vCores:39> cluster=<memory:49152, vCores:96>
2013-08-05 22:21:42,690 INFO org.apache.hadoop.yarn.server.resourcemanager.scheduler.capacity.ParentQueue: Re-sorting queues since queue: root.default stats: default: capacity=1.0, absoluteCapacity=1.0, usedResources=<memory:46080, vCores:40>usedCapacity=0.9375, absoluteUsedCapacity=0.9375, numApps=5, numContainers=40
2013-08-05 22:21:42,690 INFO org.apache.hadoop.yarn.server.resourcemanager.scheduler.capacity.ParentQueue: assignedContainer queue=root usedCapacity=0.9375 absoluteUsedCapacity=0.9375 used=<memory:46080, vCores:40> cluster=<memory:49152, vCores:96>
2013-08-05 22:21:42,691 INFO org.apache.hadoop.yarn.server.resourcemanager.rmcontainer.RMContainerImpl: container_1375740621345_0006_01_000037 Container Transitioned from NEW to ALLOCATED
2013-08-05 22:21:42,691 INFO org.apache.hadoop.yarn.server.resourcemanager.RMAuditLogger: USER=ubuntu	OPERATION=AM Allocated Container	TARGET=SchedulerApp	RESULT=SUCCESS	APPID=application_1375740621345_0006	CONTAINERID=container_1375740621345_0006_01_000037
2013-08-05 22:21:42,691 INFO org.apache.hadoop.yarn.server.resourcemanager.scheduler.common.fica.FiCaSchedulerNode: Assigned container container_1375740621345_0006_01_000037 of capacity <memory:1024, vCores:1> on host hadoop-100-5:58882, which currently has 6 containers, <memory:6144, vCores:6> used and <memory:2048, vCores:10> available
2013-08-05 22:21:42,692 INFO org.apache.hadoop.yarn.server.resourcemanager.scheduler.capacity.LeafQueue: assignedContainer application=application_1375740621345_0006 container=Container: [ContainerId: container_1375740621345_0006_01_000037, NodeId: hadoop-100-5:58882, NodeHttpAddress: hadoop-100-5:8042, Resource: <memory:1024, vCores:1>, Priority: 20, State: NEW, Token: null, Status: container_id {, app_attempt_id {, application_id {, id: 6, cluster_timestamp: 1375740621345, }, attemptId: 1, }, id: 37, }, state: C_NEW, ] containerId=container_1375740621345_0006_01_000037 queue=default: capacity=1.0, absoluteCapacity=1.0, usedResources=<memory:46080, vCores:40>usedCapacity=0.9375, absoluteUsedCapacity=0.9375, numApps=5, numContainers=40 usedCapacity=0.9375 absoluteUsedCapacity=0.9375 used=<memory:46080, vCores:40> cluster=<memory:49152, vCores:96>
2013-08-05 22:21:42,692 INFO org.apache.hadoop.yarn.server.resourcemanager.scheduler.capacity.ParentQueue: Re-sorting queues since queue: root.default stats: default: capacity=1.0, absoluteCapacity=1.0, usedResources=<memory:47104, vCores:41>usedCapacity=0.9583333, absoluteUsedCapacity=0.9583333, numApps=5, numContainers=41
2013-08-05 22:21:42,692 INFO org.apache.hadoop.yarn.server.resourcemanager.scheduler.capacity.ParentQueue: assignedContainer queue=root usedCapacity=0.9583333 absoluteUsedCapacity=0.9583333 used=<memory:47104, vCores:41> cluster=<memory:49152, vCores:96>
2013-08-05 22:21:42,693 INFO org.apache.hadoop.yarn.server.resourcemanager.rmcontainer.RMContainerImpl: container_1375740621345_0006_01_000038 Container Transitioned from NEW to ALLOCATED
2013-08-05 22:21:42,693 INFO org.apache.hadoop.yarn.server.resourcemanager.RMAuditLogger: USER=ubuntu	OPERATION=AM Allocated Container	TARGET=SchedulerApp	RESULT=SUCCESS	APPID=application_1375740621345_0006	CONTAINERID=container_1375740621345_0006_01_000038
2013-08-05 22:21:42,693 INFO org.apache.hadoop.yarn.server.resourcemanager.scheduler.common.fica.FiCaSchedulerNode: Assigned container container_1375740621345_0006_01_000038 of capacity <memory:1024, vCores:1> on host hadoop-100-5:58882, which currently has 7 containers, <memory:7168, vCores:7> used and <memory:1024, vCores:9> available
2013-08-05 22:21:42,694 INFO org.apache.hadoop.yarn.server.resourcemanager.scheduler.capacity.LeafQueue: assignedContainer application=application_1375740621345_0006 container=Container: [ContainerId: container_1375740621345_0006_01_000038, NodeId: hadoop-100-5:58882, NodeHttpAddress: hadoop-100-5:8042, Resource: <memory:1024, vCores:1>, Priority: 20, State: NEW, Token: null, Status: container_id {, app_attempt_id {, application_id {, id: 6, cluster_timestamp: 1375740621345, }, attemptId: 1, }, id: 38, }, state: C_NEW, ] containerId=container_1375740621345_0006_01_000038 queue=default: capacity=1.0, absoluteCapacity=1.0, usedResources=<memory:47104, vCores:41>usedCapacity=0.9583333, absoluteUsedCapacity=0.9583333, numApps=5, numContainers=41 usedCapacity=0.9583333 absoluteUsedCapacity=0.9583333 used=<memory:47104, vCores:41> cluster=<memory:49152, vCores:96>
2013-08-05 22:21:42,694 INFO org.apache.hadoop.yarn.server.resourcemanager.scheduler.capacity.ParentQueue: Re-sorting queues since queue: root.default stats: default: capacity=1.0, absoluteCapacity=1.0, usedResources=<memory:48128, vCores:42>usedCapacity=0.9791667, absoluteUsedCapacity=0.9791667, numApps=5, numContainers=42
2013-08-05 22:21:42,694 INFO org.apache.hadoop.yarn.server.resourcemanager.scheduler.capacity.ParentQueue: assignedContainer queue=root usedCapacity=0.9791667 absoluteUsedCapacity=0.9791667 used=<memory:48128, vCores:42> cluster=<memory:49152, vCores:96>
2013-08-05 22:21:42,695 INFO org.apache.hadoop.yarn.server.resourcemanager.rmcontainer.RMContainerImpl: container_1375740621345_0006_01_000039 Container Transitioned from NEW to ALLOCATED
2013-08-05 22:21:42,695 INFO org.apache.hadoop.yarn.server.resourcemanager.RMAuditLogger: USER=ubuntu	OPERATION=AM Allocated Container	TARGET=SchedulerApp	RESULT=SUCCESS	APPID=application_1375740621345_0006	CONTAINERID=container_1375740621345_0006_01_000039
2013-08-05 22:21:42,695 INFO org.apache.hadoop.yarn.server.resourcemanager.scheduler.common.fica.FiCaSchedulerNode: Assigned container container_1375740621345_0006_01_000039 of capacity <memory:1024, vCores:1> on host hadoop-100-5:58882, which currently has 8 containers, <memory:8192, vCores:8> used and <memory:0, vCores:8> available
2013-08-05 22:21:42,696 INFO org.apache.hadoop.yarn.server.resourcemanager.scheduler.capacity.LeafQueue: assignedContainer application=application_1375740621345_0006 container=Container: [ContainerId: container_1375740621345_0006_01_000039, NodeId: hadoop-100-5:58882, NodeHttpAddress: hadoop-100-5:8042, Resource: <memory:1024, vCores:1>, Priority: 20, State: NEW, Token: null, Status: container_id {, app_attempt_id {, application_id {, id: 6, cluster_timestamp: 1375740621345, }, attemptId: 1, }, id: 39, }, state: C_NEW, ] containerId=container_1375740621345_0006_01_000039 queue=default: capacity=1.0, absoluteCapacity=1.0, usedResources=<memory:48128, vCores:42>usedCapacity=0.9791667, absoluteUsedCapacity=0.9791667, numApps=5, numContainers=42 usedCapacity=0.9791667 absoluteUsedCapacity=0.9791667 used=<memory:48128, vCores:42> cluster=<memory:49152, vCores:96>
2013-08-05 22:21:42,696 INFO org.apache.hadoop.yarn.server.resourcemanager.scheduler.capacity.ParentQueue: Re-sorting queues since queue: root.default stats: default: capacity=1.0, absoluteCapacity=1.0, usedResources=<memory:49152, vCores:43>usedCapacity=1.0, absoluteUsedCapacity=1.0, numApps=5, numContainers=43
2013-08-05 22:21:42,696 INFO org.apache.hadoop.yarn.server.resourcemanager.scheduler.capacity.ParentQueue: assignedContainer queue=root usedCapacity=1.0 absoluteUsedCapacity=1.0 used=<memory:49152, vCores:43> cluster=<memory:49152, vCores:96>
2013-08-05 22:21:42,704 INFO org.apache.hadoop.yarn.server.resourcemanager.rmcontainer.RMContainerImpl: container_1375740621345_0006_01_000002 Container Transitioned from ALLOCATED to ACQUIRED
2013-08-05 22:21:42,705 INFO org.apache.hadoop.yarn.server.resourcemanager.rmcontainer.RMContainerImpl: container_1375740621345_0006_01_000003 Container Transitioned from ALLOCATED to ACQUIRED
2013-08-05 22:21:42,706 INFO org.apache.hadoop.yarn.server.resourcemanager.rmcontainer.RMContainerImpl: container_1375740621345_0006_01_000004 Container Transitioned from ALLOCATED to ACQUIRED
2013-08-05 22:21:42,710 INFO org.apache.hadoop.yarn.server.resourcemanager.rmcontainer.RMContainerImpl: container_1375740621345_0006_01_000005 Container Transitioned from ALLOCATED to ACQUIRED
2013-08-05 22:21:42,711 INFO org.apache.hadoop.yarn.server.resourcemanager.rmcontainer.RMContainerImpl: container_1375740621345_0006_01_000006 Container Transitioned from ALLOCATED to ACQUIRED
2013-08-05 22:21:42,712 INFO org.apache.hadoop.yarn.server.resourcemanager.rmcontainer.RMContainerImpl: container_1375740621345_0006_01_000007 Container Transitioned from ALLOCATED to ACQUIRED
2013-08-05 22:21:42,713 INFO org.apache.hadoop.yarn.server.resourcemanager.rmcontainer.RMContainerImpl: container_1375740621345_0006_01_000008 Container Transitioned from ALLOCATED to ACQUIRED
2013-08-05 22:21:42,717 INFO org.apache.hadoop.yarn.server.resourcemanager.rmcontainer.RMContainerImpl: container_1375740621345_0006_01_000009 Container Transitioned from ALLOCATED to ACQUIRED
2013-08-05 22:21:42,718 INFO org.apache.hadoop.yarn.server.resourcemanager.rmcontainer.RMContainerImpl: container_1375740621345_0006_01_000010 Container Transitioned from ALLOCATED to ACQUIRED
2013-08-05 22:21:42,719 INFO org.apache.hadoop.yarn.server.resourcemanager.rmcontainer.RMContainerImpl: container_1375740621345_0006_01_000011 Container Transitioned from ALLOCATED to ACQUIRED
2013-08-05 22:21:42,719 INFO org.apache.hadoop.yarn.server.resourcemanager.rmcontainer.RMContainerImpl: container_1375740621345_0006_01_000012 Container Transitioned from ALLOCATED to ACQUIRED
2013-08-05 22:21:42,720 INFO org.apache.hadoop.yarn.server.resourcemanager.rmcontainer.RMContainerImpl: container_1375740621345_0006_01_000013 Container Transitioned from ALLOCATED to ACQUIRED
2013-08-05 22:21:42,720 INFO org.apache.hadoop.yarn.server.resourcemanager.rmcontainer.RMContainerImpl: container_1375740621345_0006_01_000014 Container Transitioned from ALLOCATED to ACQUIRED
2013-08-05 22:21:42,720 INFO org.apache.hadoop.yarn.server.resourcemanager.rmcontainer.RMContainerImpl: container_1375740621345_0006_01_000015 Container Transitioned from ALLOCATED to ACQUIRED
2013-08-05 22:21:42,720 INFO org.apache.hadoop.yarn.server.resourcemanager.rmcontainer.RMContainerImpl: container_1375740621345_0006_01_000016 Container Transitioned from ALLOCATED to ACQUIRED
2013-08-05 22:21:42,720 INFO org.apache.hadoop.yarn.server.resourcemanager.rmcontainer.RMContainerImpl: container_1375740621345_0006_01_000017 Container Transitioned from ALLOCATED to ACQUIRED
2013-08-05 22:21:42,720 INFO org.apache.hadoop.yarn.server.resourcemanager.rmcontainer.RMContainerImpl: container_1375740621345_0006_01_000018 Container Transitioned from ALLOCATED to ACQUIRED
2013-08-05 22:21:42,721 INFO org.apache.hadoop.yarn.server.resourcemanager.rmcontainer.RMContainerImpl: container_1375740621345_0006_01_000019 Container Transitioned from ALLOCATED to ACQUIRED
2013-08-05 22:21:42,721 INFO org.apache.hadoop.yarn.server.resourcemanager.rmcontainer.RMContainerImpl: container_1375740621345_0006_01_000020 Container Transitioned from ALLOCATED to ACQUIRED
2013-08-05 22:21:42,721 INFO org.apache.hadoop.yarn.server.resourcemanager.rmcontainer.RMContainerImpl: container_1375740621345_0006_01_000021 Container Transitioned from ALLOCATED to ACQUIRED
2013-08-05 22:21:42,721 INFO org.apache.hadoop.yarn.server.resourcemanager.rmcontainer.RMContainerImpl: container_1375740621345_0006_01_000022 Container Transitioned from ALLOCATED to ACQUIRED
2013-08-05 22:21:42,721 INFO org.apache.hadoop.yarn.server.resourcemanager.rmcontainer.RMContainerImpl: container_1375740621345_0006_01_000023 Container Transitioned from ALLOCATED to ACQUIRED
2013-08-05 22:21:42,721 INFO org.apache.hadoop.yarn.server.resourcemanager.rmcontainer.RMContainerImpl: container_1375740621345_0006_01_000024 Container Transitioned from ALLOCATED to ACQUIRED
2013-08-05 22:21:42,722 INFO org.apache.hadoop.yarn.server.resourcemanager.rmcontainer.RMContainerImpl: container_1375740621345_0006_01_000025 Container Transitioned from ALLOCATED to ACQUIRED
2013-08-05 22:21:42,722 INFO org.apache.hadoop.yarn.server.resourcemanager.rmcontainer.RMContainerImpl: container_1375740621345_0006_01_000026 Container Transitioned from ALLOCATED to ACQUIRED
2013-08-05 22:21:42,722 INFO org.apache.hadoop.yarn.server.resourcemanager.rmcontainer.RMContainerImpl: container_1375740621345_0006_01_000027 Container Transitioned from ALLOCATED to ACQUIRED
2013-08-05 22:21:42,722 INFO org.apache.hadoop.yarn.server.resourcemanager.rmcontainer.RMContainerImpl: container_1375740621345_0006_01_000028 Container Transitioned from ALLOCATED to ACQUIRED
2013-08-05 22:21:42,722 INFO org.apache.hadoop.yarn.server.resourcemanager.rmcontainer.RMContainerImpl: container_1375740621345_0006_01_000029 Container Transitioned from ALLOCATED to ACQUIRED
2013-08-05 22:21:42,722 INFO org.apache.hadoop.yarn.server.resourcemanager.rmcontainer.RMContainerImpl: container_1375740621345_0006_01_000030 Container Transitioned from ALLOCATED to ACQUIRED
2013-08-05 22:21:42,723 INFO org.apache.hadoop.yarn.server.resourcemanager.rmcontainer.RMContainerImpl: container_1375740621345_0006_01_000031 Container Transitioned from ALLOCATED to ACQUIRED
2013-08-05 22:21:42,723 INFO org.apache.hadoop.yarn.server.resourcemanager.rmcontainer.RMContainerImpl: container_1375740621345_0006_01_000032 Container Transitioned from ALLOCATED to ACQUIRED
2013-08-05 22:21:42,723 INFO org.apache.hadoop.yarn.server.resourcemanager.rmcontainer.RMContainerImpl: container_1375740621345_0006_01_000033 Container Transitioned from ALLOCATED to ACQUIRED
2013-08-05 22:21:42,723 INFO org.apache.hadoop.yarn.server.resourcemanager.rmcontainer.RMContainerImpl: container_1375740621345_0006_01_000034 Container Transitioned from ALLOCATED to ACQUIRED
2013-08-05 22:21:42,723 INFO org.apache.hadoop.yarn.server.resourcemanager.rmcontainer.RMContainerImpl: container_1375740621345_0006_01_000035 Container Transitioned from ALLOCATED to ACQUIRED
2013-08-05 22:21:42,724 INFO org.apache.hadoop.yarn.server.resourcemanager.rmcontainer.RMContainerImpl: container_1375740621345_0006_01_000036 Container Transitioned from ALLOCATED to ACQUIRED
2013-08-05 22:21:42,724 INFO org.apache.hadoop.yarn.server.resourcemanager.rmcontainer.RMContainerImpl: container_1375740621345_0006_01_000037 Container Transitioned from ALLOCATED to ACQUIRED
2013-08-05 22:21:42,724 INFO org.apache.hadoop.yarn.server.resourcemanager.rmcontainer.RMContainerImpl: container_1375740621345_0006_01_000038 Container Transitioned from ALLOCATED to ACQUIRED
2013-08-05 22:21:42,724 INFO org.apache.hadoop.yarn.server.resourcemanager.rmcontainer.RMContainerImpl: container_1375740621345_0006_01_000039 Container Transitioned from ALLOCATED to ACQUIRED
2013-08-05 22:21:43,379 INFO org.apache.hadoop.yarn.server.resourcemanager.rmcontainer.RMContainerImpl: container_1375740621345_0006_01_000010 Container Transitioned from ACQUIRED to RUNNING
2013-08-05 22:21:43,380 INFO org.apache.hadoop.yarn.server.resourcemanager.rmcontainer.RMContainerImpl: container_1375740621345_0006_01_000011 Container Transitioned from ACQUIRED to RUNNING
2013-08-05 22:21:43,381 INFO org.apache.hadoop.yarn.server.resourcemanager.rmcontainer.RMContainerImpl: container_1375740621345_0006_01_000012 Container Transitioned from ACQUIRED to RUNNING
2013-08-05 22:21:43,381 INFO org.apache.hadoop.yarn.server.resourcemanager.rmcontainer.RMContainerImpl: container_1375740621345_0006_01_000013 Container Transitioned from ACQUIRED to RUNNING
2013-08-05 22:21:43,547 INFO org.apache.hadoop.yarn.server.resourcemanager.rmcontainer.RMContainerImpl: container_1375740621345_0006_01_000014 Container Transitioned from ACQUIRED to RUNNING
2013-08-05 22:21:43,548 INFO org.apache.hadoop.yarn.server.resourcemanager.rmcontainer.RMContainerImpl: container_1375740621345_0006_01_000015 Container Transitioned from ACQUIRED to RUNNING
2013-08-05 22:21:43,549 INFO org.apache.hadoop.yarn.server.resourcemanager.rmcontainer.RMContainerImpl: container_1375740621345_0006_01_000016 Container Transitioned from ACQUIRED to RUNNING
2013-08-05 22:21:43,549 INFO org.apache.hadoop.yarn.server.resourcemanager.rmcontainer.RMContainerImpl: container_1375740621345_0006_01_000017 Container Transitioned from ACQUIRED to RUNNING
2013-08-05 22:21:43,559 INFO org.apache.hadoop.yarn.server.resourcemanager.rmcontainer.RMContainerImpl: container_1375740621345_0006_01_000018 Container Transitioned from ACQUIRED to RUNNING
2013-08-05 22:21:43,560 INFO org.apache.hadoop.yarn.server.resourcemanager.rmcontainer.RMContainerImpl: container_1375740621345_0006_01_000019 Container Transitioned from ACQUIRED to RUNNING
2013-08-05 22:21:43,560 INFO org.apache.hadoop.yarn.server.resourcemanager.rmcontainer.RMContainerImpl: container_1375740621345_0006_01_000020 Container Transitioned from ACQUIRED to RUNNING
2013-08-05 22:21:43,561 INFO org.apache.hadoop.yarn.server.resourcemanager.rmcontainer.RMContainerImpl: container_1375740621345_0006_01_000021 Container Transitioned from ACQUIRED to RUNNING
2013-08-05 22:21:43,561 INFO org.apache.hadoop.yarn.server.resourcemanager.rmcontainer.RMContainerImpl: container_1375740621345_0006_01_000022 Container Transitioned from ACQUIRED to RUNNING
2013-08-05 22:21:43,561 INFO org.apache.hadoop.yarn.server.resourcemanager.rmcontainer.RMContainerImpl: container_1375740621345_0006_01_000023 Container Transitioned from ACQUIRED to RUNNING
2013-08-05 22:21:43,562 INFO org.apache.hadoop.yarn.server.resourcemanager.rmcontainer.RMContainerImpl: container_1375740621345_0006_01_000024 Container Transitioned from ACQUIRED to RUNNING
2013-08-05 22:21:43,562 INFO org.apache.hadoop.yarn.server.resourcemanager.rmcontainer.RMContainerImpl: container_1375740621345_0006_01_000025 Container Transitioned from ACQUIRED to RUNNING
2013-08-05 22:21:43,632 INFO org.apache.hadoop.yarn.server.resourcemanager.rmcontainer.RMContainerImpl: container_1375740621345_0006_01_000026 Container Transitioned from ACQUIRED to RUNNING
2013-08-05 22:21:43,632 INFO org.apache.hadoop.yarn.server.resourcemanager.rmcontainer.RMContainerImpl: container_1375740621345_0006_01_000027 Container Transitioned from ACQUIRED to RUNNING
2013-08-05 22:21:43,632 INFO org.apache.hadoop.yarn.server.resourcemanager.rmcontainer.RMContainerImpl: container_1375740621345_0006_01_000028 Container Transitioned from ACQUIRED to RUNNING
2013-08-05 22:21:43,633 INFO org.apache.hadoop.yarn.server.resourcemanager.rmcontainer.RMContainerImpl: container_1375740621345_0006_01_000029 Container Transitioned from ACQUIRED to RUNNING
2013-08-05 22:21:43,634 INFO org.apache.hadoop.yarn.server.resourcemanager.rmcontainer.RMContainerImpl: container_1375740621345_0006_01_000030 Container Transitioned from ACQUIRED to RUNNING
2013-08-05 22:21:43,634 INFO org.apache.hadoop.yarn.server.resourcemanager.rmcontainer.RMContainerImpl: container_1375740621345_0006_01_000031 Container Transitioned from ACQUIRED to RUNNING
2013-08-05 22:21:43,701 INFO org.apache.hadoop.yarn.server.resourcemanager.rmcontainer.RMContainerImpl: container_1375740621345_0006_01_000032 Container Transitioned from ACQUIRED to RUNNING
2013-08-05 22:21:43,701 INFO org.apache.hadoop.yarn.server.resourcemanager.rmcontainer.RMContainerImpl: container_1375740621345_0006_01_000033 Container Transitioned from ACQUIRED to RUNNING
2013-08-05 22:21:43,701 INFO org.apache.hadoop.yarn.server.resourcemanager.rmcontainer.RMContainerImpl: container_1375740621345_0006_01_000034 Container Transitioned from ACQUIRED to RUNNING
2013-08-05 22:21:43,701 INFO org.apache.hadoop.yarn.server.resourcemanager.rmcontainer.RMContainerImpl: container_1375740621345_0006_01_000035 Container Transitioned from ACQUIRED to RUNNING
2013-08-05 22:21:43,702 INFO org.apache.hadoop.yarn.server.resourcemanager.rmcontainer.RMContainerImpl: container_1375740621345_0006_01_000036 Container Transitioned from ACQUIRED to RUNNING
2013-08-05 22:21:43,702 INFO org.apache.hadoop.yarn.server.resourcemanager.rmcontainer.RMContainerImpl: container_1375740621345_0006_01_000037 Container Transitioned from ACQUIRED to RUNNING
2013-08-05 22:21:43,702 INFO org.apache.hadoop.yarn.server.resourcemanager.rmcontainer.RMContainerImpl: container_1375740621345_0006_01_000038 Container Transitioned from ACQUIRED to RUNNING
2013-08-05 22:21:43,702 INFO org.apache.hadoop.yarn.server.resourcemanager.rmcontainer.RMContainerImpl: container_1375740621345_0006_01_000039 Container Transitioned from ACQUIRED to RUNNING
2013-08-05 22:21:43,750 INFO org.apache.hadoop.yarn.server.resourcemanager.rmcontainer.RMContainerImpl: container_1375740621345_0006_01_000002 Container Transitioned from ACQUIRED to RUNNING
2013-08-05 22:21:43,751 INFO org.apache.hadoop.yarn.server.resourcemanager.rmcontainer.RMContainerImpl: container_1375740621345_0006_01_000003 Container Transitioned from ACQUIRED to RUNNING
2013-08-05 22:21:43,751 INFO org.apache.hadoop.yarn.server.resourcemanager.rmcontainer.RMContainerImpl: container_1375740621345_0006_01_000004 Container Transitioned from ACQUIRED to RUNNING
2013-08-05 22:21:43,751 INFO org.apache.hadoop.yarn.server.resourcemanager.rmcontainer.RMContainerImpl: container_1375740621345_0006_01_000005 Container Transitioned from ACQUIRED to RUNNING
2013-08-05 22:21:43,751 INFO org.apache.hadoop.yarn.server.resourcemanager.rmcontainer.RMContainerImpl: container_1375740621345_0006_01_000006 Container Transitioned from ACQUIRED to RUNNING
2013-08-05 22:21:43,751 INFO org.apache.hadoop.yarn.server.resourcemanager.rmcontainer.RMContainerImpl: container_1375740621345_0006_01_000007 Container Transitioned from ACQUIRED to RUNNING
2013-08-05 22:21:43,752 INFO org.apache.hadoop.yarn.server.resourcemanager.rmcontainer.RMContainerImpl: container_1375740621345_0006_01_000008 Container Transitioned from ACQUIRED to RUNNING
2013-08-05 22:21:43,752 INFO org.apache.hadoop.yarn.server.resourcemanager.rmcontainer.RMContainerImpl: container_1375740621345_0006_01_000009 Container Transitioned from ACQUIRED to RUNNING
2013-08-05 22:21:44,925 INFO org.apache.hadoop.yarn.server.resourcemanager.ApplicationMasterService: AM registration appattempt_1375740621345_0008_000001
2013-08-05 22:21:44,925 INFO org.apache.hadoop.yarn.server.resourcemanager.RMAuditLogger: USER=ubuntu	IP=192.168.100.18	OPERATION=Register App Master	TARGET=ApplicationMasterService	RESULT=SUCCESS	APPID=application_1375740621345_0008	APPATTEMPTID=appattempt_1375740621345_0008_000001
2013-08-05 22:21:44,926 INFO org.apache.hadoop.yarn.server.resourcemanager.rmapp.attempt.RMAppAttemptImpl: appattempt_1375740621345_0008_000001 State change from LAUNCHED to RUNNING
2013-08-05 22:21:44,926 INFO org.apache.hadoop.yarn.server.resourcemanager.rmapp.RMAppImpl: application_1375740621345_0008 State change from ACCEPTED to RUNNING
2013-08-05 22:22:00,811 INFO org.apache.hadoop.yarn.server.resourcemanager.rmcontainer.RMContainerImpl: container_1375740621345_0006_01_000017 Container Transitioned from RUNNING to COMPLETED
2013-08-05 22:22:00,811 INFO org.apache.hadoop.yarn.server.resourcemanager.scheduler.common.fica.FiCaSchedulerApp: Completed container: container_1375740621345_0006_01_000017 in state: COMPLETED event:FINISHED
2013-08-05 22:22:00,812 INFO org.apache.hadoop.yarn.server.resourcemanager.RMAuditLogger: USER=ubuntu	OPERATION=AM Released Container	TARGET=SchedulerApp	RESULT=SUCCESS	APPID=application_1375740621345_0006	CONTAINERID=container_1375740621345_0006_01_000017
2013-08-05 22:22:00,812 INFO org.apache.hadoop.yarn.server.resourcemanager.scheduler.common.fica.FiCaSchedulerNode: Released container container_1375740621345_0006_01_000017 of capacity <memory:1024, vCores:1> on host hadoop-100-2:37374, which currently has 5 containers, <memory:7168, vCores:5> used and <memory:1024, vCores:11> available, release resources=true
2013-08-05 22:22:00,812 INFO org.apache.hadoop.yarn.server.resourcemanager.scheduler.capacity.LeafQueue: default used=<memory:48128, vCores:42> numContainers=42 user=ubuntu user-resources=<memory:48128, vCores:42>
2013-08-05 22:22:00,815 INFO org.apache.hadoop.yarn.server.resourcemanager.scheduler.capacity.LeafQueue: completedContainer container=Container: [ContainerId: container_1375740621345_0006_01_000017, NodeId: hadoop-100-2:37374, NodeHttpAddress: hadoop-100-2:8042, Resource: <memory:1024, vCores:1>, Priority: 20, State: NEW, Token: null, Status: container_id {, app_attempt_id {, application_id {, id: 6, cluster_timestamp: 1375740621345, }, attemptId: 1, }, id: 17, }, state: C_COMPLETE, diagnostics: "Container killed by the ApplicationMaster.\n\n", exit_status: 143, ] resource=<memory:1024, vCores:1> queue=default: capacity=1.0, absoluteCapacity=1.0, usedResources=<memory:48128, vCores:42>usedCapacity=0.9791667, absoluteUsedCapacity=0.9791667, numApps=5, numContainers=42 usedCapacity=0.9791667 absoluteUsedCapacity=0.9791667 used=<memory:48128, vCores:42> cluster=<memory:49152, vCores:96>
2013-08-05 22:22:00,815 INFO org.apache.hadoop.yarn.server.resourcemanager.scheduler.capacity.ParentQueue: completedContainer queue=root usedCapacity=0.9791667 absoluteUsedCapacity=0.9791667 used=<memory:48128, vCores:42> cluster=<memory:49152, vCores:96>
2013-08-05 22:22:00,815 INFO org.apache.hadoop.yarn.server.resourcemanager.scheduler.capacity.CapacityScheduler: Application appattempt_1375740621345_0006_000001 released container container_1375740621345_0006_01_000017 on node: host: hadoop-100-2:37374 #containers=5 available=1024 used=7168 with event: FINISHED
2013-08-05 22:22:00,816 INFO org.apache.hadoop.yarn.server.resourcemanager.rmcontainer.RMContainerImpl: container_1375740621345_0006_01_000040 Container Transitioned from NEW to ALLOCATED
2013-08-05 22:22:00,816 INFO org.apache.hadoop.yarn.server.resourcemanager.RMAuditLogger: USER=ubuntu	OPERATION=AM Allocated Container	TARGET=SchedulerApp	RESULT=SUCCESS	APPID=application_1375740621345_0006	CONTAINERID=container_1375740621345_0006_01_000040
2013-08-05 22:22:00,816 INFO org.apache.hadoop.yarn.server.resourcemanager.scheduler.common.fica.FiCaSchedulerNode: Assigned container container_1375740621345_0006_01_000040 of capacity <memory:1024, vCores:1> on host hadoop-100-2:37374, which currently has 6 containers, <memory:8192, vCores:6> used and <memory:0, vCores:10> available
2013-08-05 22:22:00,817 INFO org.apache.hadoop.yarn.server.resourcemanager.scheduler.capacity.LeafQueue: assignedContainer application=application_1375740621345_0006 container=Container: [ContainerId: container_1375740621345_0006_01_000040, NodeId: hadoop-100-2:37374, NodeHttpAddress: hadoop-100-2:8042, Resource: <memory:1024, vCores:1>, Priority: 20, State: NEW, Token: null, Status: container_id {, app_attempt_id {, application_id {, id: 6, cluster_timestamp: 1375740621345, }, attemptId: 1, }, id: 40, }, state: C_NEW, ] containerId=container_1375740621345_0006_01_000040 queue=default: capacity=1.0, absoluteCapacity=1.0, usedResources=<memory:48128, vCores:42>usedCapacity=0.9791667, absoluteUsedCapacity=0.9791667, numApps=5, numContainers=42 usedCapacity=0.9791667 absoluteUsedCapacity=0.9791667 used=<memory:48128, vCores:42> cluster=<memory:49152, vCores:96>
2013-08-05 22:22:00,817 INFO org.apache.hadoop.yarn.server.resourcemanager.scheduler.capacity.ParentQueue: Re-sorting queues since queue: root.default stats: default: capacity=1.0, absoluteCapacity=1.0, usedResources=<memory:49152, vCores:43>usedCapacity=1.0, absoluteUsedCapacity=1.0, numApps=5, numContainers=43
2013-08-05 22:22:00,817 INFO org.apache.hadoop.yarn.server.resourcemanager.scheduler.capacity.ParentQueue: assignedContainer queue=root usedCapacity=1.0 absoluteUsedCapacity=1.0 used=<memory:49152, vCores:43> cluster=<memory:49152, vCores:96>
2013-08-05 22:22:00,924 INFO org.apache.hadoop.yarn.server.resourcemanager.rmcontainer.RMContainerImpl: container_1375740621345_0006_01_000040 Container Transitioned from ALLOCATED to ACQUIRED
2013-08-05 22:22:00,996 INFO org.apache.hadoop.yarn.server.resourcemanager.rmcontainer.RMContainerImpl: container_1375740621345_0006_01_000013 Container Transitioned from RUNNING to COMPLETED
2013-08-05 22:22:00,997 INFO org.apache.hadoop.yarn.server.resourcemanager.scheduler.common.fica.FiCaSchedulerApp: Completed container: container_1375740621345_0006_01_000013 in state: COMPLETED event:FINISHED
2013-08-05 22:22:00,997 INFO org.apache.hadoop.yarn.server.resourcemanager.RMAuditLogger: USER=ubuntu	OPERATION=AM Released Container	TARGET=SchedulerApp	RESULT=SUCCESS	APPID=application_1375740621345_0006	CONTAINERID=container_1375740621345_0006_01_000013
2013-08-05 22:22:00,997 INFO org.apache.hadoop.yarn.server.resourcemanager.scheduler.common.fica.FiCaSchedulerNode: Released container container_1375740621345_0006_01_000013 of capacity <memory:1024, vCores:1> on host hadoop-100-4:50425, which currently has 5 containers, <memory:7168, vCores:5> used and <memory:1024, vCores:11> available, release resources=true
2013-08-05 22:22:00,997 INFO org.apache.hadoop.yarn.server.resourcemanager.scheduler.capacity.LeafQueue: default used=<memory:48128, vCores:42> numContainers=42 user=ubuntu user-resources=<memory:48128, vCores:42>
2013-08-05 22:22:00,998 INFO org.apache.hadoop.yarn.server.resourcemanager.scheduler.capacity.LeafQueue: completedContainer container=Container: [ContainerId: container_1375740621345_0006_01_000013, NodeId: hadoop-100-4:50425, NodeHttpAddress: hadoop-100-4:8042, Resource: <memory:1024, vCores:1>, Priority: 20, State: NEW, Token: null, Status: container_id {, app_attempt_id {, application_id {, id: 6, cluster_timestamp: 1375740621345, }, attemptId: 1, }, id: 13, }, state: C_COMPLETE, diagnostics: "Container killed by the ApplicationMaster.\n\n", exit_status: 143, ] resource=<memory:1024, vCores:1> queue=default: capacity=1.0, absoluteCapacity=1.0, usedResources=<memory:48128, vCores:42>usedCapacity=0.9791667, absoluteUsedCapacity=0.9791667, numApps=5, numContainers=42 usedCapacity=0.9791667 absoluteUsedCapacity=0.9791667 used=<memory:48128, vCores:42> cluster=<memory:49152, vCores:96>
2013-08-05 22:22:00,998 INFO org.apache.hadoop.yarn.server.resourcemanager.scheduler.capacity.ParentQueue: completedContainer queue=root usedCapacity=0.9791667 absoluteUsedCapacity=0.9791667 used=<memory:48128, vCores:42> cluster=<memory:49152, vCores:96>
2013-08-05 22:22:00,998 INFO org.apache.hadoop.yarn.server.resourcemanager.scheduler.capacity.CapacityScheduler: Application appattempt_1375740621345_0006_000001 released container container_1375740621345_0006_01_000013 on node: host: hadoop-100-4:50425 #containers=5 available=1024 used=7168 with event: FINISHED
2013-08-05 22:22:00,999 INFO org.apache.hadoop.yarn.server.resourcemanager.rmcontainer.RMContainerImpl: container_1375740621345_0006_01_000041 Container Transitioned from NEW to ALLOCATED
2013-08-05 22:22:00,999 INFO org.apache.hadoop.yarn.server.resourcemanager.RMAuditLogger: USER=ubuntu	OPERATION=AM Allocated Container	TARGET=SchedulerApp	RESULT=SUCCESS	APPID=application_1375740621345_0006	CONTAINERID=container_1375740621345_0006_01_000041
2013-08-05 22:22:00,999 INFO org.apache.hadoop.yarn.server.resourcemanager.scheduler.common.fica.FiCaSchedulerNode: Assigned container container_1375740621345_0006_01_000041 of capacity <memory:1024, vCores:1> on host hadoop-100-4:50425, which currently has 6 containers, <memory:8192, vCores:6> used and <memory:0, vCores:10> available
2013-08-05 22:22:01,000 INFO org.apache.hadoop.yarn.server.resourcemanager.scheduler.capacity.LeafQueue: assignedContainer application=application_1375740621345_0006 container=Container: [ContainerId: container_1375740621345_0006_01_000041, NodeId: hadoop-100-4:50425, NodeHttpAddress: hadoop-100-4:8042, Resource: <memory:1024, vCores:1>, Priority: 20, State: NEW, Token: null, Status: container_id {, app_attempt_id {, application_id {, id: 6, cluster_timestamp: 1375740621345, }, attemptId: 1, }, id: 41, }, state: C_NEW, ] containerId=container_1375740621345_0006_01_000041 queue=default: capacity=1.0, absoluteCapacity=1.0, usedResources=<memory:48128, vCores:42>usedCapacity=0.9791667, absoluteUsedCapacity=0.9791667, numApps=5, numContainers=42 usedCapacity=0.9791667 absoluteUsedCapacity=0.9791667 used=<memory:48128, vCores:42> cluster=<memory:49152, vCores:96>
2013-08-05 22:22:01,001 INFO org.apache.hadoop.yarn.server.resourcemanager.scheduler.capacity.ParentQueue: Re-sorting queues since queue: root.default stats: default: capacity=1.0, absoluteCapacity=1.0, usedResources=<memory:49152, vCores:43>usedCapacity=1.0, absoluteUsedCapacity=1.0, numApps=5, numContainers=43
2013-08-05 22:22:01,001 INFO org.apache.hadoop.yarn.server.resourcemanager.scheduler.capacity.ParentQueue: assignedContainer queue=root usedCapacity=1.0 absoluteUsedCapacity=1.0 used=<memory:49152, vCores:43> cluster=<memory:49152, vCores:96>
2013-08-05 22:22:01,080 INFO org.apache.hadoop.yarn.server.resourcemanager.rmcontainer.RMContainerImpl: container_1375740621345_0006_01_000011 Container Transitioned from RUNNING to COMPLETED
2013-08-05 22:22:01,080 INFO org.apache.hadoop.yarn.server.resourcemanager.scheduler.common.fica.FiCaSchedulerApp: Completed container: container_1375740621345_0006_01_000011 in state: COMPLETED event:FINISHED
2013-08-05 22:22:01,080 INFO org.apache.hadoop.yarn.server.resourcemanager.RMAuditLogger: USER=ubuntu	OPERATION=AM Released Container	TARGET=SchedulerApp	RESULT=SUCCESS	APPID=application_1375740621345_0006	CONTAINERID=container_1375740621345_0006_01_000011
2013-08-05 22:22:01,080 INFO org.apache.hadoop.yarn.server.resourcemanager.scheduler.common.fica.FiCaSchedulerNode: Released container container_1375740621345_0006_01_000011 of capacity <memory:1024, vCores:1> on host hadoop-100-4:50425, which currently has 5 containers, <memory:7168, vCores:5> used and <memory:1024, vCores:11> available, release resources=true
2013-08-05 22:22:01,080 INFO org.apache.hadoop.yarn.server.resourcemanager.scheduler.capacity.LeafQueue: default used=<memory:48128, vCores:42> numContainers=42 user=ubuntu user-resources=<memory:48128, vCores:42>
2013-08-05 22:22:01,081 INFO org.apache.hadoop.yarn.server.resourcemanager.scheduler.capacity.LeafQueue: completedContainer container=Container: [ContainerId: container_1375740621345_0006_01_000011, NodeId: hadoop-100-4:50425, NodeHttpAddress: hadoop-100-4:8042, Resource: <memory:1024, vCores:1>, Priority: 20, State: NEW, Token: null, Status: container_id {, app_attempt_id {, application_id {, id: 6, cluster_timestamp: 1375740621345, }, attemptId: 1, }, id: 11, }, state: C_COMPLETE, diagnostics: "Container killed by the ApplicationMaster.\n\n", exit_status: 143, ] resource=<memory:1024, vCores:1> queue=default: capacity=1.0, absoluteCapacity=1.0, usedResources=<memory:48128, vCores:42>usedCapacity=0.9791667, absoluteUsedCapacity=0.9791667, numApps=5, numContainers=42 usedCapacity=0.9791667 absoluteUsedCapacity=0.9791667 used=<memory:48128, vCores:42> cluster=<memory:49152, vCores:96>
2013-08-05 22:22:01,081 INFO org.apache.hadoop.yarn.server.resourcemanager.scheduler.capacity.ParentQueue: completedContainer queue=root usedCapacity=0.9791667 absoluteUsedCapacity=0.9791667 used=<memory:48128, vCores:42> cluster=<memory:49152, vCores:96>
2013-08-05 22:22:01,082 INFO org.apache.hadoop.yarn.server.resourcemanager.scheduler.capacity.CapacityScheduler: Application appattempt_1375740621345_0006_000001 released container container_1375740621345_0006_01_000011 on node: host: hadoop-100-4:50425 #containers=5 available=1024 used=7168 with event: FINISHED
2013-08-05 22:22:01,082 INFO org.apache.hadoop.yarn.server.resourcemanager.rmcontainer.RMContainerImpl: container_1375740621345_0007_01_000002 Container Transitioned from NEW to ALLOCATED
2013-08-05 22:22:01,082 INFO org.apache.hadoop.yarn.server.resourcemanager.RMAuditLogger: USER=ubuntu	OPERATION=AM Allocated Container	TARGET=SchedulerApp	RESULT=SUCCESS	APPID=application_1375740621345_0007	CONTAINERID=container_1375740621345_0007_01_000002
2013-08-05 22:22:01,082 INFO org.apache.hadoop.yarn.server.resourcemanager.scheduler.common.fica.FiCaSchedulerNode: Assigned container container_1375740621345_0007_01_000002 of capacity <memory:1024, vCores:1> on host hadoop-100-4:50425, which currently has 6 containers, <memory:8192, vCores:6> used and <memory:0, vCores:10> available
2013-08-05 22:22:01,083 INFO org.apache.hadoop.yarn.server.resourcemanager.scheduler.capacity.LeafQueue: assignedContainer application=application_1375740621345_0007 container=Container: [ContainerId: container_1375740621345_0007_01_000002, NodeId: hadoop-100-4:50425, NodeHttpAddress: hadoop-100-4:8042, Resource: <memory:1024, vCores:1>, Priority: 20, State: NEW, Token: null, Status: container_id {, app_attempt_id {, application_id {, id: 7, cluster_timestamp: 1375740621345, }, attemptId: 1, }, id: 2, }, state: C_NEW, ] containerId=container_1375740621345_0007_01_000002 queue=default: capacity=1.0, absoluteCapacity=1.0, usedResources=<memory:48128, vCores:42>usedCapacity=0.9791667, absoluteUsedCapacity=0.9791667, numApps=5, numContainers=42 usedCapacity=0.9791667 absoluteUsedCapacity=0.9791667 used=<memory:48128, vCores:42> cluster=<memory:49152, vCores:96>
2013-08-05 22:22:01,084 INFO org.apache.hadoop.yarn.server.resourcemanager.scheduler.capacity.ParentQueue: Re-sorting queues since queue: root.default stats: default: capacity=1.0, absoluteCapacity=1.0, usedResources=<memory:49152, vCores:43>usedCapacity=1.0, absoluteUsedCapacity=1.0, numApps=5, numContainers=43
2013-08-05 22:22:01,084 INFO org.apache.hadoop.yarn.server.resourcemanager.scheduler.capacity.ParentQueue: assignedContainer queue=root usedCapacity=1.0 absoluteUsedCapacity=1.0 used=<memory:49152, vCores:43> cluster=<memory:49152, vCores:96>
2013-08-05 22:22:01,560 INFO org.apache.hadoop.yarn.server.resourcemanager.rmcontainer.RMContainerImpl: container_1375740621345_0007_01_000002 Container Transitioned from ALLOCATED to ACQUIRED
2013-08-05 22:22:01,820 INFO org.apache.hadoop.yarn.server.resourcemanager.rmcontainer.RMContainerImpl: container_1375740621345_0006_01_000040 Container Transitioned from ACQUIRED to RUNNING
2013-08-05 22:22:01,821 INFO org.apache.hadoop.yarn.server.resourcemanager.rmcontainer.RMContainerImpl: container_1375740621345_0006_01_000015 Container Transitioned from RUNNING to COMPLETED
2013-08-05 22:22:01,821 INFO org.apache.hadoop.yarn.server.resourcemanager.scheduler.common.fica.FiCaSchedulerApp: Completed container: container_1375740621345_0006_01_000015 in state: COMPLETED event:FINISHED
2013-08-05 22:22:01,821 INFO org.apache.hadoop.yarn.server.resourcemanager.RMAuditLogger: USER=ubuntu	OPERATION=AM Released Container	TARGET=SchedulerApp	RESULT=SUCCESS	APPID=application_1375740621345_0006	CONTAINERID=container_1375740621345_0006_01_000015
2013-08-05 22:22:01,821 INFO org.apache.hadoop.yarn.server.resourcemanager.scheduler.common.fica.FiCaSchedulerNode: Released container container_1375740621345_0006_01_000015 of capacity <memory:1024, vCores:1> on host hadoop-100-2:37374, which currently has 5 containers, <memory:7168, vCores:5> used and <memory:1024, vCores:11> available, release resources=true
2013-08-05 22:22:01,821 INFO org.apache.hadoop.yarn.server.resourcemanager.scheduler.capacity.LeafQueue: default used=<memory:48128, vCores:42> numContainers=42 user=ubuntu user-resources=<memory:48128, vCores:42>
2013-08-05 22:22:01,823 INFO org.apache.hadoop.yarn.server.resourcemanager.scheduler.capacity.LeafQueue: completedContainer container=Container: [ContainerId: container_1375740621345_0006_01_000015, NodeId: hadoop-100-2:37374, NodeHttpAddress: hadoop-100-2:8042, Resource: <memory:1024, vCores:1>, Priority: 20, State: NEW, Token: null, Status: container_id {, app_attempt_id {, application_id {, id: 6, cluster_timestamp: 1375740621345, }, attemptId: 1, }, id: 15, }, state: C_COMPLETE, diagnostics: "Container killed by the ApplicationMaster.\n\n", exit_status: 143, ] resource=<memory:1024, vCores:1> queue=default: capacity=1.0, absoluteCapacity=1.0, usedResources=<memory:48128, vCores:42>usedCapacity=0.9791667, absoluteUsedCapacity=0.9791667, numApps=5, numContainers=42 usedCapacity=0.9791667 absoluteUsedCapacity=0.9791667 used=<memory:48128, vCores:42> cluster=<memory:49152, vCores:96>
2013-08-05 22:22:01,823 INFO org.apache.hadoop.yarn.server.resourcemanager.scheduler.capacity.ParentQueue: completedContainer queue=root usedCapacity=0.9791667 absoluteUsedCapacity=0.9791667 used=<memory:48128, vCores:42> cluster=<memory:49152, vCores:96>
2013-08-05 22:22:01,823 INFO org.apache.hadoop.yarn.server.resourcemanager.scheduler.capacity.CapacityScheduler: Application appattempt_1375740621345_0006_000001 released container container_1375740621345_0006_01_000015 on node: host: hadoop-100-2:37374 #containers=5 available=1024 used=7168 with event: FINISHED
2013-08-05 22:22:01,824 INFO org.apache.hadoop.yarn.server.resourcemanager.rmcontainer.RMContainerImpl: container_1375740621345_0007_01_000003 Container Transitioned from NEW to ALLOCATED
2013-08-05 22:22:01,824 INFO org.apache.hadoop.yarn.server.resourcemanager.RMAuditLogger: USER=ubuntu	OPERATION=AM Allocated Container	TARGET=SchedulerApp	RESULT=SUCCESS	APPID=application_1375740621345_0007	CONTAINERID=container_1375740621345_0007_01_000003
2013-08-05 22:22:01,824 INFO org.apache.hadoop.yarn.server.resourcemanager.scheduler.common.fica.FiCaSchedulerNode: Assigned container container_1375740621345_0007_01_000003 of capacity <memory:1024, vCores:1> on host hadoop-100-2:37374, which currently has 6 containers, <memory:8192, vCores:6> used and <memory:0, vCores:10> available
2013-08-05 22:22:01,825 INFO org.apache.hadoop.yarn.server.resourcemanager.scheduler.capacity.LeafQueue: assignedContainer application=application_1375740621345_0007 container=Container: [ContainerId: container_1375740621345_0007_01_000003, NodeId: hadoop-100-2:37374, NodeHttpAddress: hadoop-100-2:8042, Resource: <memory:1024, vCores:1>, Priority: 20, State: NEW, Token: null, Status: container_id {, app_attempt_id {, application_id {, id: 7, cluster_timestamp: 1375740621345, }, attemptId: 1, }, id: 3, }, state: C_NEW, ] containerId=container_1375740621345_0007_01_000003 queue=default: capacity=1.0, absoluteCapacity=1.0, usedResources=<memory:48128, vCores:42>usedCapacity=0.9791667, absoluteUsedCapacity=0.9791667, numApps=5, numContainers=42 usedCapacity=0.9791667 absoluteUsedCapacity=0.9791667 used=<memory:48128, vCores:42> cluster=<memory:49152, vCores:96>
2013-08-05 22:22:01,825 INFO org.apache.hadoop.yarn.server.resourcemanager.scheduler.capacity.ParentQueue: Re-sorting queues since queue: root.default stats: default: capacity=1.0, absoluteCapacity=1.0, usedResources=<memory:49152, vCores:43>usedCapacity=1.0, absoluteUsedCapacity=1.0, numApps=5, numContainers=43
2013-08-05 22:22:01,825 INFO org.apache.hadoop.yarn.server.resourcemanager.scheduler.capacity.ParentQueue: assignedContainer queue=root usedCapacity=1.0 absoluteUsedCapacity=1.0 used=<memory:49152, vCores:43> cluster=<memory:49152, vCores:96>
2013-08-05 22:22:01,940 INFO org.apache.hadoop.yarn.server.resourcemanager.rmcontainer.RMContainerImpl: container_1375740621345_0006_01_000041 Container Transitioned from ALLOCATED to ACQUIRED
2013-08-05 22:22:02,090 INFO org.apache.hadoop.yarn.server.resourcemanager.rmcontainer.RMContainerImpl: container_1375740621345_0006_01_000041 Container Transitioned from ACQUIRED to RUNNING
2013-08-05 22:22:02,091 INFO org.apache.hadoop.yarn.server.resourcemanager.rmcontainer.RMContainerImpl: container_1375740621345_0007_01_000002 Container Transitioned from ACQUIRED to RUNNING
2013-08-05 22:22:02,091 INFO org.apache.hadoop.yarn.server.resourcemanager.rmcontainer.RMContainerImpl: container_1375740621345_0006_01_000010 Container Transitioned from RUNNING to COMPLETED
2013-08-05 22:22:02,091 INFO org.apache.hadoop.yarn.server.resourcemanager.scheduler.common.fica.FiCaSchedulerApp: Completed container: container_1375740621345_0006_01_000010 in state: COMPLETED event:FINISHED
2013-08-05 22:22:02,091 INFO org.apache.hadoop.yarn.server.resourcemanager.RMAuditLogger: USER=ubuntu	OPERATION=AM Released Container	TARGET=SchedulerApp	RESULT=SUCCESS	APPID=application_1375740621345_0006	CONTAINERID=container_1375740621345_0006_01_000010
2013-08-05 22:22:02,091 INFO org.apache.hadoop.yarn.server.resourcemanager.scheduler.common.fica.FiCaSchedulerNode: Released container container_1375740621345_0006_01_000010 of capacity <memory:1024, vCores:1> on host hadoop-100-4:50425, which currently has 5 containers, <memory:7168, vCores:5> used and <memory:1024, vCores:11> available, release resources=true
2013-08-05 22:22:02,092 INFO org.apache.hadoop.yarn.server.resourcemanager.scheduler.capacity.LeafQueue: default used=<memory:48128, vCores:42> numContainers=42 user=ubuntu user-resources=<memory:48128, vCores:42>
2013-08-05 22:22:02,093 INFO org.apache.hadoop.yarn.server.resourcemanager.scheduler.capacity.LeafQueue: completedContainer container=Container: [ContainerId: container_1375740621345_0006_01_000010, NodeId: hadoop-100-4:50425, NodeHttpAddress: hadoop-100-4:8042, Resource: <memory:1024, vCores:1>, Priority: 20, State: NEW, Token: null, Status: container_id {, app_attempt_id {, application_id {, id: 6, cluster_timestamp: 1375740621345, }, attemptId: 1, }, id: 10, }, state: C_COMPLETE, diagnostics: "Container killed by the ApplicationMaster.\n\n", exit_status: 143, ] resource=<memory:1024, vCores:1> queue=default: capacity=1.0, absoluteCapacity=1.0, usedResources=<memory:48128, vCores:42>usedCapacity=0.9791667, absoluteUsedCapacity=0.9791667, numApps=5, numContainers=42 usedCapacity=0.9791667 absoluteUsedCapacity=0.9791667 used=<memory:48128, vCores:42> cluster=<memory:49152, vCores:96>
2013-08-05 22:22:02,093 INFO org.apache.hadoop.yarn.server.resourcemanager.scheduler.capacity.ParentQueue: completedContainer queue=root usedCapacity=0.9791667 absoluteUsedCapacity=0.9791667 used=<memory:48128, vCores:42> cluster=<memory:49152, vCores:96>
2013-08-05 22:22:02,093 INFO org.apache.hadoop.yarn.server.resourcemanager.scheduler.capacity.CapacityScheduler: Application appattempt_1375740621345_0006_000001 released container container_1375740621345_0006_01_000010 on node: host: hadoop-100-4:50425 #containers=5 available=1024 used=7168 with event: FINISHED
2013-08-05 22:22:02,094 INFO org.apache.hadoop.yarn.server.resourcemanager.rmcontainer.RMContainerImpl: container_1375740621345_0006_01_000042 Container Transitioned from NEW to ALLOCATED
2013-08-05 22:22:02,094 INFO org.apache.hadoop.yarn.server.resourcemanager.RMAuditLogger: USER=ubuntu	OPERATION=AM Allocated Container	TARGET=SchedulerApp	RESULT=SUCCESS	APPID=application_1375740621345_0006	CONTAINERID=container_1375740621345_0006_01_000042
2013-08-05 22:22:02,094 INFO org.apache.hadoop.yarn.server.resourcemanager.scheduler.common.fica.FiCaSchedulerNode: Assigned container container_1375740621345_0006_01_000042 of capacity <memory:1024, vCores:1> on host hadoop-100-4:50425, which currently has 6 containers, <memory:8192, vCores:6> used and <memory:0, vCores:10> available
2013-08-05 22:22:02,095 INFO org.apache.hadoop.yarn.server.resourcemanager.scheduler.capacity.LeafQueue: assignedContainer application=application_1375740621345_0006 container=Container: [ContainerId: container_1375740621345_0006_01_000042, NodeId: hadoop-100-4:50425, NodeHttpAddress: hadoop-100-4:8042, Resource: <memory:1024, vCores:1>, Priority: 10, State: NEW, Token: null, Status: container_id {, app_attempt_id {, application_id {, id: 6, cluster_timestamp: 1375740621345, }, attemptId: 1, }, id: 42, }, state: C_NEW, ] containerId=container_1375740621345_0006_01_000042 queue=default: capacity=1.0, absoluteCapacity=1.0, usedResources=<memory:48128, vCores:42>usedCapacity=0.9791667, absoluteUsedCapacity=0.9791667, numApps=5, numContainers=42 usedCapacity=0.9791667 absoluteUsedCapacity=0.9791667 used=<memory:48128, vCores:42> cluster=<memory:49152, vCores:96>
2013-08-05 22:22:02,095 INFO org.apache.hadoop.yarn.server.resourcemanager.scheduler.capacity.ParentQueue: Re-sorting queues since queue: root.default stats: default: capacity=1.0, absoluteCapacity=1.0, usedResources=<memory:49152, vCores:43>usedCapacity=1.0, absoluteUsedCapacity=1.0, numApps=5, numContainers=43
2013-08-05 22:22:02,095 INFO org.apache.hadoop.yarn.server.resourcemanager.scheduler.capacity.ParentQueue: assignedContainer queue=root usedCapacity=1.0 absoluteUsedCapacity=1.0 used=<memory:49152, vCores:43> cluster=<memory:49152, vCores:96>
2013-08-05 22:22:02,591 INFO org.apache.hadoop.yarn.server.resourcemanager.rmcontainer.RMContainerImpl: container_1375740621345_0007_01_000003 Container Transitioned from ALLOCATED to ACQUIRED
2013-08-05 22:22:02,834 INFO org.apache.hadoop.yarn.server.resourcemanager.rmcontainer.RMContainerImpl: container_1375740621345_0007_01_000003 Container Transitioned from ACQUIRED to RUNNING
2013-08-05 22:22:02,950 INFO org.apache.hadoop.yarn.server.resourcemanager.scheduler.AppSchedulingInfo: checking for deactivate... 
2013-08-05 22:22:02,950 INFO org.apache.hadoop.yarn.server.resourcemanager.rmcontainer.RMContainerImpl: container_1375740621345_0006_01_000042 Container Transitioned from ALLOCATED to ACQUIRED
2013-08-05 22:22:03,963 INFO org.apache.hadoop.yarn.server.resourcemanager.scheduler.AppSchedulingInfo: checking for deactivate... 
2013-08-05 22:22:04,125 INFO org.apache.hadoop.yarn.server.resourcemanager.rmcontainer.RMContainerImpl: container_1375740621345_0006_01_000042 Container Transitioned from ACQUIRED to RUNNING
2013-08-05 22:22:06,517 INFO org.apache.hadoop.yarn.server.resourcemanager.rmcontainer.RMContainerImpl: container_1375740621345_0006_01_000026 Container Transitioned from RUNNING to COMPLETED
2013-08-05 22:22:06,517 INFO org.apache.hadoop.yarn.server.resourcemanager.scheduler.common.fica.FiCaSchedulerApp: Completed container: container_1375740621345_0006_01_000026 in state: COMPLETED event:FINISHED
2013-08-05 22:22:06,517 INFO org.apache.hadoop.yarn.server.resourcemanager.RMAuditLogger: USER=ubuntu	OPERATION=AM Released Container	TARGET=SchedulerApp	RESULT=SUCCESS	APPID=application_1375740621345_0006	CONTAINERID=container_1375740621345_0006_01_000026
2013-08-05 22:22:06,518 INFO org.apache.hadoop.yarn.server.resourcemanager.scheduler.common.fica.FiCaSchedulerNode: Released container container_1375740621345_0006_01_000026 of capacity <memory:1024, vCores:1> on host hadoop-100-6:42294, which currently has 6 containers, <memory:7168, vCores:6> used and <memory:1024, vCores:10> available, release resources=true
2013-08-05 22:22:06,518 INFO org.apache.hadoop.yarn.server.resourcemanager.scheduler.capacity.LeafQueue: default used=<memory:48128, vCores:42> numContainers=42 user=ubuntu user-resources=<memory:48128, vCores:42>
2013-08-05 22:22:06,519 INFO org.apache.hadoop.yarn.server.resourcemanager.scheduler.capacity.LeafQueue: completedContainer container=Container: [ContainerId: container_1375740621345_0006_01_000026, NodeId: hadoop-100-6:42294, NodeHttpAddress: hadoop-100-6:8042, Resource: <memory:1024, vCores:1>, Priority: 20, State: NEW, Token: null, Status: container_id {, app_attempt_id {, application_id {, id: 6, cluster_timestamp: 1375740621345, }, attemptId: 1, }, id: 26, }, state: C_COMPLETE, diagnostics: "", exit_status: 0, ] resource=<memory:1024, vCores:1> queue=default: capacity=1.0, absoluteCapacity=1.0, usedResources=<memory:48128, vCores:42>usedCapacity=0.9791667, absoluteUsedCapacity=0.9791667, numApps=5, numContainers=42 usedCapacity=0.9791667 absoluteUsedCapacity=0.9791667 used=<memory:48128, vCores:42> cluster=<memory:49152, vCores:96>
2013-08-05 22:22:06,519 INFO org.apache.hadoop.yarn.server.resourcemanager.scheduler.capacity.ParentQueue: completedContainer queue=root usedCapacity=0.9791667 absoluteUsedCapacity=0.9791667 used=<memory:48128, vCores:42> cluster=<memory:49152, vCores:96>
2013-08-05 22:22:06,519 INFO org.apache.hadoop.yarn.server.resourcemanager.scheduler.capacity.CapacityScheduler: Application appattempt_1375740621345_0006_000001 released container container_1375740621345_0006_01_000026 on node: host: hadoop-100-6:42294 #containers=6 available=1024 used=7168 with event: FINISHED
2013-08-05 22:22:06,520 INFO org.apache.hadoop.yarn.server.resourcemanager.rmcontainer.RMContainerImpl: container_1375740621345_0007_01_000004 Container Transitioned from NEW to ALLOCATED
2013-08-05 22:22:06,520 INFO org.apache.hadoop.yarn.server.resourcemanager.RMAuditLogger: USER=ubuntu	OPERATION=AM Allocated Container	TARGET=SchedulerApp	RESULT=SUCCESS	APPID=application_1375740621345_0007	CONTAINERID=container_1375740621345_0007_01_000004
2013-08-05 22:22:06,520 INFO org.apache.hadoop.yarn.server.resourcemanager.scheduler.common.fica.FiCaSchedulerNode: Assigned container container_1375740621345_0007_01_000004 of capacity <memory:1024, vCores:1> on host hadoop-100-6:42294, which currently has 7 containers, <memory:8192, vCores:7> used and <memory:0, vCores:9> available
2013-08-05 22:22:06,521 INFO org.apache.hadoop.yarn.server.resourcemanager.scheduler.capacity.LeafQueue: assignedContainer application=application_1375740621345_0007 container=Container: [ContainerId: container_1375740621345_0007_01_000004, NodeId: hadoop-100-6:42294, NodeHttpAddress: hadoop-100-6:8042, Resource: <memory:1024, vCores:1>, Priority: 20, State: NEW, Token: null, Status: container_id {, app_attempt_id {, application_id {, id: 7, cluster_timestamp: 1375740621345, }, attemptId: 1, }, id: 4, }, state: C_NEW, ] containerId=container_1375740621345_0007_01_000004 queue=default: capacity=1.0, absoluteCapacity=1.0, usedResources=<memory:48128, vCores:42>usedCapacity=0.9791667, absoluteUsedCapacity=0.9791667, numApps=5, numContainers=42 usedCapacity=0.9791667 absoluteUsedCapacity=0.9791667 used=<memory:48128, vCores:42> cluster=<memory:49152, vCores:96>
2013-08-05 22:22:06,521 INFO org.apache.hadoop.yarn.server.resourcemanager.scheduler.capacity.ParentQueue: Re-sorting queues since queue: root.default stats: default: capacity=1.0, absoluteCapacity=1.0, usedResources=<memory:49152, vCores:43>usedCapacity=1.0, absoluteUsedCapacity=1.0, numApps=5, numContainers=43
2013-08-05 22:22:06,521 INFO org.apache.hadoop.yarn.server.resourcemanager.scheduler.capacity.ParentQueue: assignedContainer queue=root usedCapacity=1.0 absoluteUsedCapacity=1.0 used=<memory:49152, vCores:43> cluster=<memory:49152, vCores:96>
2013-08-05 22:22:06,609 INFO org.apache.hadoop.yarn.server.resourcemanager.rmcontainer.RMContainerImpl: container_1375740621345_0007_01_000004 Container Transitioned from ALLOCATED to ACQUIRED
2013-08-05 22:22:07,545 INFO org.apache.hadoop.yarn.server.resourcemanager.rmcontainer.RMContainerImpl: container_1375740621345_0007_01_000004 Container Transitioned from ACQUIRED to RUNNING
2013-08-05 22:22:09,706 INFO org.apache.hadoop.yarn.server.resourcemanager.rmcontainer.RMContainerImpl: container_1375740621345_0006_01_000005 Container Transitioned from RUNNING to COMPLETED
2013-08-05 22:22:09,706 INFO org.apache.hadoop.yarn.server.resourcemanager.scheduler.common.fica.FiCaSchedulerApp: Completed container: container_1375740621345_0006_01_000005 in state: COMPLETED event:FINISHED
2013-08-05 22:22:09,706 INFO org.apache.hadoop.yarn.server.resourcemanager.RMAuditLogger: USER=ubuntu	OPERATION=AM Released Container	TARGET=SchedulerApp	RESULT=SUCCESS	APPID=application_1375740621345_0006	CONTAINERID=container_1375740621345_0006_01_000005
2013-08-05 22:22:09,706 INFO org.apache.hadoop.yarn.server.resourcemanager.scheduler.common.fica.FiCaSchedulerNode: Released container container_1375740621345_0006_01_000005 of capacity <memory:1024, vCores:1> on host hadoop-100-3:44102, which currently has 7 containers, <memory:7168, vCores:7> used and <memory:1024, vCores:9> available, release resources=true
2013-08-05 22:22:09,707 INFO org.apache.hadoop.yarn.server.resourcemanager.scheduler.capacity.LeafQueue: default used=<memory:48128, vCores:42> numContainers=42 user=ubuntu user-resources=<memory:48128, vCores:42>
2013-08-05 22:22:09,708 INFO org.apache.hadoop.yarn.server.resourcemanager.scheduler.capacity.LeafQueue: completedContainer container=Container: [ContainerId: container_1375740621345_0006_01_000005, NodeId: hadoop-100-3:44102, NodeHttpAddress: hadoop-100-3:8042, Resource: <memory:1024, vCores:1>, Priority: 20, State: NEW, Token: null, Status: container_id {, app_attempt_id {, application_id {, id: 6, cluster_timestamp: 1375740621345, }, attemptId: 1, }, id: 5, }, state: C_COMPLETE, diagnostics: "Container killed by the ApplicationMaster.\n\n", exit_status: 143, ] resource=<memory:1024, vCores:1> queue=default: capacity=1.0, absoluteCapacity=1.0, usedResources=<memory:48128, vCores:42>usedCapacity=0.9791667, absoluteUsedCapacity=0.9791667, numApps=5, numContainers=42 usedCapacity=0.9791667 absoluteUsedCapacity=0.9791667 used=<memory:48128, vCores:42> cluster=<memory:49152, vCores:96>
2013-08-05 22:22:09,708 INFO org.apache.hadoop.yarn.server.resourcemanager.scheduler.capacity.ParentQueue: completedContainer queue=root usedCapacity=0.9791667 absoluteUsedCapacity=0.9791667 used=<memory:48128, vCores:42> cluster=<memory:49152, vCores:96>
2013-08-05 22:22:09,708 INFO org.apache.hadoop.yarn.server.resourcemanager.scheduler.capacity.CapacityScheduler: Application appattempt_1375740621345_0006_000001 released container container_1375740621345_0006_01_000005 on node: host: hadoop-100-3:44102 #containers=7 available=1024 used=7168 with event: FINISHED
2013-08-05 22:22:09,709 INFO org.apache.hadoop.yarn.server.resourcemanager.rmcontainer.RMContainerImpl: container_1375740621345_0007_01_000005 Container Transitioned from NEW to ALLOCATED
2013-08-05 22:22:09,709 INFO org.apache.hadoop.yarn.server.resourcemanager.RMAuditLogger: USER=ubuntu	OPERATION=AM Allocated Container	TARGET=SchedulerApp	RESULT=SUCCESS	APPID=application_1375740621345_0007	CONTAINERID=container_1375740621345_0007_01_000005
2013-08-05 22:22:09,709 INFO org.apache.hadoop.yarn.server.resourcemanager.scheduler.common.fica.FiCaSchedulerNode: Assigned container container_1375740621345_0007_01_000005 of capacity <memory:1024, vCores:1> on host hadoop-100-3:44102, which currently has 8 containers, <memory:8192, vCores:8> used and <memory:0, vCores:8> available
2013-08-05 22:22:09,710 INFO org.apache.hadoop.yarn.server.resourcemanager.scheduler.capacity.LeafQueue: assignedContainer application=application_1375740621345_0007 container=Container: [ContainerId: container_1375740621345_0007_01_000005, NodeId: hadoop-100-3:44102, NodeHttpAddress: hadoop-100-3:8042, Resource: <memory:1024, vCores:1>, Priority: 20, State: NEW, Token: null, Status: container_id {, app_attempt_id {, application_id {, id: 7, cluster_timestamp: 1375740621345, }, attemptId: 1, }, id: 5, }, state: C_NEW, ] containerId=container_1375740621345_0007_01_000005 queue=default: capacity=1.0, absoluteCapacity=1.0, usedResources=<memory:48128, vCores:42>usedCapacity=0.9791667, absoluteUsedCapacity=0.9791667, numApps=5, numContainers=42 usedCapacity=0.9791667 absoluteUsedCapacity=0.9791667 used=<memory:48128, vCores:42> cluster=<memory:49152, vCores:96>
2013-08-05 22:22:09,710 INFO org.apache.hadoop.yarn.server.resourcemanager.scheduler.capacity.ParentQueue: Re-sorting queues since queue: root.default stats: default: capacity=1.0, absoluteCapacity=1.0, usedResources=<memory:49152, vCores:43>usedCapacity=1.0, absoluteUsedCapacity=1.0, numApps=5, numContainers=43
2013-08-05 22:22:09,710 INFO org.apache.hadoop.yarn.server.resourcemanager.scheduler.capacity.ParentQueue: assignedContainer queue=root usedCapacity=1.0 absoluteUsedCapacity=1.0 used=<memory:49152, vCores:43> cluster=<memory:49152, vCores:96>
2013-08-05 22:22:09,767 INFO org.apache.hadoop.yarn.server.resourcemanager.rmcontainer.RMContainerImpl: container_1375740621345_0006_01_000012 Container Transitioned from RUNNING to COMPLETED
2013-08-05 22:22:09,767 INFO org.apache.hadoop.yarn.server.resourcemanager.scheduler.common.fica.FiCaSchedulerApp: Completed container: container_1375740621345_0006_01_000012 in state: COMPLETED event:FINISHED
2013-08-05 22:22:09,767 INFO org.apache.hadoop.yarn.server.resourcemanager.RMAuditLogger: USER=ubuntu	OPERATION=AM Released Container	TARGET=SchedulerApp	RESULT=SUCCESS	APPID=application_1375740621345_0006	CONTAINERID=container_1375740621345_0006_01_000012
2013-08-05 22:22:09,767 INFO org.apache.hadoop.yarn.server.resourcemanager.scheduler.common.fica.FiCaSchedulerNode: Released container container_1375740621345_0006_01_000012 of capacity <memory:1024, vCores:1> on host hadoop-100-4:50425, which currently has 5 containers, <memory:7168, vCores:5> used and <memory:1024, vCores:11> available, release resources=true
2013-08-05 22:22:09,767 INFO org.apache.hadoop.yarn.server.resourcemanager.scheduler.capacity.LeafQueue: default used=<memory:48128, vCores:42> numContainers=42 user=ubuntu user-resources=<memory:48128, vCores:42>
2013-08-05 22:22:09,768 INFO org.apache.hadoop.yarn.server.resourcemanager.scheduler.capacity.LeafQueue: completedContainer container=Container: [ContainerId: container_1375740621345_0006_01_000012, NodeId: hadoop-100-4:50425, NodeHttpAddress: hadoop-100-4:8042, Resource: <memory:1024, vCores:1>, Priority: 20, State: NEW, Token: null, Status: container_id {, app_attempt_id {, application_id {, id: 6, cluster_timestamp: 1375740621345, }, attemptId: 1, }, id: 12, }, state: C_COMPLETE, diagnostics: "Container killed by the ApplicationMaster.\n\n", exit_status: 143, ] resource=<memory:1024, vCores:1> queue=default: capacity=1.0, absoluteCapacity=1.0, usedResources=<memory:48128, vCores:42>usedCapacity=0.9791667, absoluteUsedCapacity=0.9791667, numApps=5, numContainers=42 usedCapacity=0.9791667 absoluteUsedCapacity=0.9791667 used=<memory:48128, vCores:42> cluster=<memory:49152, vCores:96>
2013-08-05 22:22:09,769 INFO org.apache.hadoop.yarn.server.resourcemanager.scheduler.capacity.ParentQueue: completedContainer queue=root usedCapacity=0.9791667 absoluteUsedCapacity=0.9791667 used=<memory:48128, vCores:42> cluster=<memory:49152, vCores:96>
2013-08-05 22:22:09,769 INFO org.apache.hadoop.yarn.server.resourcemanager.scheduler.capacity.CapacityScheduler: Application appattempt_1375740621345_0006_000001 released container container_1375740621345_0006_01_000012 on node: host: hadoop-100-4:50425 #containers=5 available=1024 used=7168 with event: FINISHED
2013-08-05 22:22:09,769 INFO org.apache.hadoop.yarn.server.resourcemanager.rmcontainer.RMContainerImpl: container_1375740621345_0007_01_000006 Container Transitioned from NEW to ALLOCATED
2013-08-05 22:22:09,769 INFO org.apache.hadoop.yarn.server.resourcemanager.RMAuditLogger: USER=ubuntu	OPERATION=AM Allocated Container	TARGET=SchedulerApp	RESULT=SUCCESS	APPID=application_1375740621345_0007	CONTAINERID=container_1375740621345_0007_01_000006
2013-08-05 22:22:09,770 INFO org.apache.hadoop.yarn.server.resourcemanager.scheduler.common.fica.FiCaSchedulerNode: Assigned container container_1375740621345_0007_01_000006 of capacity <memory:1024, vCores:1> on host hadoop-100-4:50425, which currently has 6 containers, <memory:8192, vCores:6> used and <memory:0, vCores:10> available
2013-08-05 22:22:09,770 INFO org.apache.hadoop.yarn.server.resourcemanager.scheduler.capacity.LeafQueue: assignedContainer application=application_1375740621345_0007 container=Container: [ContainerId: container_1375740621345_0007_01_000006, NodeId: hadoop-100-4:50425, NodeHttpAddress: hadoop-100-4:8042, Resource: <memory:1024, vCores:1>, Priority: 20, State: NEW, Token: null, Status: container_id {, app_attempt_id {, application_id {, id: 7, cluster_timestamp: 1375740621345, }, attemptId: 1, }, id: 6, }, state: C_NEW, ] containerId=container_1375740621345_0007_01_000006 queue=default: capacity=1.0, absoluteCapacity=1.0, usedResources=<memory:48128, vCores:42>usedCapacity=0.9791667, absoluteUsedCapacity=0.9791667, numApps=5, numContainers=42 usedCapacity=0.9791667 absoluteUsedCapacity=0.9791667 used=<memory:48128, vCores:42> cluster=<memory:49152, vCores:96>
2013-08-05 22:22:09,771 INFO org.apache.hadoop.yarn.server.resourcemanager.scheduler.capacity.ParentQueue: Re-sorting queues since queue: root.default stats: default: capacity=1.0, absoluteCapacity=1.0, usedResources=<memory:49152, vCores:43>usedCapacity=1.0, absoluteUsedCapacity=1.0, numApps=5, numContainers=43
2013-08-05 22:22:09,771 INFO org.apache.hadoop.yarn.server.resourcemanager.scheduler.capacity.ParentQueue: assignedContainer queue=root usedCapacity=1.0 absoluteUsedCapacity=1.0 used=<memory:49152, vCores:43> cluster=<memory:49152, vCores:96>
2013-08-05 22:22:09,905 INFO org.apache.hadoop.yarn.server.resourcemanager.rmcontainer.RMContainerImpl: container_1375740621345_0006_01_000029 Container Transitioned from RUNNING to COMPLETED
2013-08-05 22:22:09,905 INFO org.apache.hadoop.yarn.server.resourcemanager.scheduler.common.fica.FiCaSchedulerApp: Completed container: container_1375740621345_0006_01_000029 in state: COMPLETED event:FINISHED
2013-08-05 22:22:09,905 INFO org.apache.hadoop.yarn.server.resourcemanager.RMAuditLogger: USER=ubuntu	OPERATION=AM Released Container	TARGET=SchedulerApp	RESULT=SUCCESS	APPID=application_1375740621345_0006	CONTAINERID=container_1375740621345_0006_01_000029
2013-08-05 22:22:09,905 INFO org.apache.hadoop.yarn.server.resourcemanager.scheduler.common.fica.FiCaSchedulerNode: Released container container_1375740621345_0006_01_000029 of capacity <memory:1024, vCores:1> on host hadoop-100-6:42294, which currently has 6 containers, <memory:7168, vCores:6> used and <memory:1024, vCores:10> available, release resources=true
2013-08-05 22:22:09,906 INFO org.apache.hadoop.yarn.server.resourcemanager.scheduler.capacity.LeafQueue: default used=<memory:48128, vCores:42> numContainers=42 user=ubuntu user-resources=<memory:48128, vCores:42>
2013-08-05 22:22:09,907 INFO org.apache.hadoop.yarn.server.resourcemanager.scheduler.capacity.LeafQueue: completedContainer container=Container: [ContainerId: container_1375740621345_0006_01_000029, NodeId: hadoop-100-6:42294, NodeHttpAddress: hadoop-100-6:8042, Resource: <memory:1024, vCores:1>, Priority: 20, State: NEW, Token: null, Status: container_id {, app_attempt_id {, application_id {, id: 6, cluster_timestamp: 1375740621345, }, attemptId: 1, }, id: 29, }, state: C_COMPLETE, diagnostics: "Container killed by the ApplicationMaster.\n", exit_status: 0, ] resource=<memory:1024, vCores:1> queue=default: capacity=1.0, absoluteCapacity=1.0, usedResources=<memory:48128, vCores:42>usedCapacity=0.9791667, absoluteUsedCapacity=0.9791667, numApps=5, numContainers=42 usedCapacity=0.9791667 absoluteUsedCapacity=0.9791667 used=<memory:48128, vCores:42> cluster=<memory:49152, vCores:96>
2013-08-05 22:22:09,907 INFO org.apache.hadoop.yarn.server.resourcemanager.scheduler.capacity.ParentQueue: completedContainer queue=root usedCapacity=0.9791667 absoluteUsedCapacity=0.9791667 used=<memory:48128, vCores:42> cluster=<memory:49152, vCores:96>
2013-08-05 22:22:09,907 INFO org.apache.hadoop.yarn.server.resourcemanager.scheduler.capacity.CapacityScheduler: Application appattempt_1375740621345_0006_000001 released container container_1375740621345_0006_01_000029 on node: host: hadoop-100-6:42294 #containers=6 available=1024 used=7168 with event: FINISHED
2013-08-05 22:22:09,908 INFO org.apache.hadoop.yarn.server.resourcemanager.rmcontainer.RMContainerImpl: container_1375740621345_0007_01_000007 Container Transitioned from NEW to ALLOCATED
2013-08-05 22:22:09,908 INFO org.apache.hadoop.yarn.server.resourcemanager.RMAuditLogger: USER=ubuntu	OPERATION=AM Allocated Container	TARGET=SchedulerApp	RESULT=SUCCESS	APPID=application_1375740621345_0007	CONTAINERID=container_1375740621345_0007_01_000007
2013-08-05 22:22:09,908 INFO org.apache.hadoop.yarn.server.resourcemanager.scheduler.common.fica.FiCaSchedulerNode: Assigned container container_1375740621345_0007_01_000007 of capacity <memory:1024, vCores:1> on host hadoop-100-6:42294, which currently has 7 containers, <memory:8192, vCores:7> used and <memory:0, vCores:9> available
2013-08-05 22:22:09,909 INFO org.apache.hadoop.yarn.server.resourcemanager.scheduler.capacity.LeafQueue: assignedContainer application=application_1375740621345_0007 container=Container: [ContainerId: container_1375740621345_0007_01_000007, NodeId: hadoop-100-6:42294, NodeHttpAddress: hadoop-100-6:8042, Resource: <memory:1024, vCores:1>, Priority: 20, State: NEW, Token: null, Status: container_id {, app_attempt_id {, application_id {, id: 7, cluster_timestamp: 1375740621345, }, attemptId: 1, }, id: 7, }, state: C_NEW, ] containerId=container_1375740621345_0007_01_000007 queue=default: capacity=1.0, absoluteCapacity=1.0, usedResources=<memory:48128, vCores:42>usedCapacity=0.9791667, absoluteUsedCapacity=0.9791667, numApps=5, numContainers=42 usedCapacity=0.9791667 absoluteUsedCapacity=0.9791667 used=<memory:48128, vCores:42> cluster=<memory:49152, vCores:96>
2013-08-05 22:22:09,909 INFO org.apache.hadoop.yarn.server.resourcemanager.scheduler.capacity.ParentQueue: Re-sorting queues since queue: root.default stats: default: capacity=1.0, absoluteCapacity=1.0, usedResources=<memory:49152, vCores:43>usedCapacity=1.0, absoluteUsedCapacity=1.0, numApps=5, numContainers=43
2013-08-05 22:22:09,909 INFO org.apache.hadoop.yarn.server.resourcemanager.scheduler.capacity.ParentQueue: assignedContainer queue=root usedCapacity=1.0 absoluteUsedCapacity=1.0 used=<memory:49152, vCores:43> cluster=<memory:49152, vCores:96>
2013-08-05 22:22:10,626 INFO org.apache.hadoop.yarn.server.resourcemanager.rmcontainer.RMContainerImpl: container_1375740621345_0007_01_000005 Container Transitioned from ALLOCATED to ACQUIRED
2013-08-05 22:22:10,631 INFO org.apache.hadoop.yarn.server.resourcemanager.rmcontainer.RMContainerImpl: container_1375740621345_0007_01_000006 Container Transitioned from ALLOCATED to ACQUIRED
2013-08-05 22:22:10,631 INFO org.apache.hadoop.yarn.server.resourcemanager.rmcontainer.RMContainerImpl: container_1375740621345_0007_01_000007 Container Transitioned from ALLOCATED to ACQUIRED
2013-08-05 22:22:10,736 INFO org.apache.hadoop.yarn.server.resourcemanager.rmcontainer.RMContainerImpl: container_1375740621345_0007_01_000005 Container Transitioned from ACQUIRED to RUNNING
2013-08-05 22:22:10,913 INFO org.apache.hadoop.yarn.server.resourcemanager.rmcontainer.RMContainerImpl: container_1375740621345_0006_01_000014 Container Transitioned from RUNNING to COMPLETED
2013-08-05 22:22:10,913 INFO org.apache.hadoop.yarn.server.resourcemanager.scheduler.common.fica.FiCaSchedulerApp: Completed container: container_1375740621345_0006_01_000014 in state: COMPLETED event:FINISHED
2013-08-05 22:22:10,913 INFO org.apache.hadoop.yarn.server.resourcemanager.RMAuditLogger: USER=ubuntu	OPERATION=AM Released Container	TARGET=SchedulerApp	RESULT=SUCCESS	APPID=application_1375740621345_0006	CONTAINERID=container_1375740621345_0006_01_000014
2013-08-05 22:22:10,913 INFO org.apache.hadoop.yarn.server.resourcemanager.scheduler.common.fica.FiCaSchedulerNode: Released container container_1375740621345_0006_01_000014 of capacity <memory:1024, vCores:1> on host hadoop-100-2:37374, which currently has 5 containers, <memory:7168, vCores:5> used and <memory:1024, vCores:11> available, release resources=true
2013-08-05 22:22:10,913 INFO org.apache.hadoop.yarn.server.resourcemanager.scheduler.capacity.LeafQueue: default used=<memory:48128, vCores:42> numContainers=42 user=ubuntu user-resources=<memory:48128, vCores:42>
2013-08-05 22:22:10,914 INFO org.apache.hadoop.yarn.server.resourcemanager.scheduler.capacity.LeafQueue: completedContainer container=Container: [ContainerId: container_1375740621345_0006_01_000014, NodeId: hadoop-100-2:37374, NodeHttpAddress: hadoop-100-2:8042, Resource: <memory:1024, vCores:1>, Priority: 20, State: NEW, Token: null, Status: container_id {, app_attempt_id {, application_id {, id: 6, cluster_timestamp: 1375740621345, }, attemptId: 1, }, id: 14, }, state: C_COMPLETE, diagnostics: "", exit_status: 0, ] resource=<memory:1024, vCores:1> queue=default: capacity=1.0, absoluteCapacity=1.0, usedResources=<memory:48128, vCores:42>usedCapacity=0.9791667, absoluteUsedCapacity=0.9791667, numApps=5, numContainers=42 usedCapacity=0.9791667 absoluteUsedCapacity=0.9791667 used=<memory:48128, vCores:42> cluster=<memory:49152, vCores:96>
2013-08-05 22:22:10,914 INFO org.apache.hadoop.yarn.server.resourcemanager.scheduler.capacity.ParentQueue: completedContainer queue=root usedCapacity=0.9791667 absoluteUsedCapacity=0.9791667 used=<memory:48128, vCores:42> cluster=<memory:49152, vCores:96>
2013-08-05 22:22:10,915 INFO org.apache.hadoop.yarn.server.resourcemanager.scheduler.capacity.CapacityScheduler: Application appattempt_1375740621345_0006_000001 released container container_1375740621345_0006_01_000014 on node: host: hadoop-100-2:37374 #containers=5 available=1024 used=7168 with event: FINISHED
2013-08-05 22:22:10,915 INFO org.apache.hadoop.yarn.server.resourcemanager.rmcontainer.RMContainerImpl: container_1375740621345_0007_01_000008 Container Transitioned from NEW to ALLOCATED
2013-08-05 22:22:10,915 INFO org.apache.hadoop.yarn.server.resourcemanager.RMAuditLogger: USER=ubuntu	OPERATION=AM Allocated Container	TARGET=SchedulerApp	RESULT=SUCCESS	APPID=application_1375740621345_0007	CONTAINERID=container_1375740621345_0007_01_000008
2013-08-05 22:22:10,915 INFO org.apache.hadoop.yarn.server.resourcemanager.scheduler.common.fica.FiCaSchedulerNode: Assigned container container_1375740621345_0007_01_000008 of capacity <memory:1024, vCores:1> on host hadoop-100-2:37374, which currently has 6 containers, <memory:8192, vCores:6> used and <memory:0, vCores:10> available
2013-08-05 22:22:10,916 INFO org.apache.hadoop.yarn.server.resourcemanager.scheduler.capacity.LeafQueue: assignedContainer application=application_1375740621345_0007 container=Container: [ContainerId: container_1375740621345_0007_01_000008, NodeId: hadoop-100-2:37374, NodeHttpAddress: hadoop-100-2:8042, Resource: <memory:1024, vCores:1>, Priority: 20, State: NEW, Token: null, Status: container_id {, app_attempt_id {, application_id {, id: 7, cluster_timestamp: 1375740621345, }, attemptId: 1, }, id: 8, }, state: C_NEW, ] containerId=container_1375740621345_0007_01_000008 queue=default: capacity=1.0, absoluteCapacity=1.0, usedResources=<memory:48128, vCores:42>usedCapacity=0.9791667, absoluteUsedCapacity=0.9791667, numApps=5, numContainers=42 usedCapacity=0.9791667 absoluteUsedCapacity=0.9791667 used=<memory:48128, vCores:42> cluster=<memory:49152, vCores:96>
2013-08-05 22:22:10,917 INFO org.apache.hadoop.yarn.server.resourcemanager.scheduler.capacity.ParentQueue: Re-sorting queues since queue: root.default stats: default: capacity=1.0, absoluteCapacity=1.0, usedResources=<memory:49152, vCores:43>usedCapacity=1.0, absoluteUsedCapacity=1.0, numApps=5, numContainers=43
2013-08-05 22:22:10,917 INFO org.apache.hadoop.yarn.server.resourcemanager.scheduler.capacity.ParentQueue: assignedContainer queue=root usedCapacity=1.0 absoluteUsedCapacity=1.0 used=<memory:49152, vCores:43> cluster=<memory:49152, vCores:96>
2013-08-05 22:22:10,928 INFO org.apache.hadoop.yarn.server.resourcemanager.rmcontainer.RMContainerImpl: container_1375740621345_0007_01_000007 Container Transitioned from ACQUIRED to RUNNING
2013-08-05 22:22:11,643 INFO org.apache.hadoop.yarn.server.resourcemanager.rmcontainer.RMContainerImpl: container_1375740621345_0007_01_000008 Container Transitioned from ALLOCATED to ACQUIRED
2013-08-05 22:22:11,835 INFO org.apache.hadoop.yarn.server.resourcemanager.rmcontainer.RMContainerImpl: container_1375740621345_0007_01_000006 Container Transitioned from ACQUIRED to RUNNING
2013-08-05 22:22:11,899 INFO org.apache.hadoop.yarn.server.resourcemanager.rmcontainer.RMContainerImpl: container_1375740621345_0006_01_000006 Container Transitioned from RUNNING to COMPLETED
2013-08-05 22:22:11,899 INFO org.apache.hadoop.yarn.server.resourcemanager.scheduler.common.fica.FiCaSchedulerApp: Completed container: container_1375740621345_0006_01_000006 in state: COMPLETED event:FINISHED
2013-08-05 22:22:11,899 INFO org.apache.hadoop.yarn.server.resourcemanager.RMAuditLogger: USER=ubuntu	OPERATION=AM Released Container	TARGET=SchedulerApp	RESULT=SUCCESS	APPID=application_1375740621345_0006	CONTAINERID=container_1375740621345_0006_01_000006
2013-08-05 22:22:11,899 INFO org.apache.hadoop.yarn.server.resourcemanager.scheduler.common.fica.FiCaSchedulerNode: Released container container_1375740621345_0006_01_000006 of capacity <memory:1024, vCores:1> on host hadoop-100-3:44102, which currently has 7 containers, <memory:7168, vCores:7> used and <memory:1024, vCores:9> available, release resources=true
2013-08-05 22:22:11,899 INFO org.apache.hadoop.yarn.server.resourcemanager.scheduler.capacity.LeafQueue: default used=<memory:48128, vCores:42> numContainers=42 user=ubuntu user-resources=<memory:48128, vCores:42>
2013-08-05 22:22:11,900 INFO org.apache.hadoop.yarn.server.resourcemanager.scheduler.capacity.LeafQueue: completedContainer container=Container: [ContainerId: container_1375740621345_0006_01_000006, NodeId: hadoop-100-3:44102, NodeHttpAddress: hadoop-100-3:8042, Resource: <memory:1024, vCores:1>, Priority: 20, State: NEW, Token: null, Status: container_id {, app_attempt_id {, application_id {, id: 6, cluster_timestamp: 1375740621345, }, attemptId: 1, }, id: 6, }, state: C_COMPLETE, diagnostics: "Container killed by the ApplicationMaster.\n\n", exit_status: 143, ] resource=<memory:1024, vCores:1> queue=default: capacity=1.0, absoluteCapacity=1.0, usedResources=<memory:48128, vCores:42>usedCapacity=0.9791667, absoluteUsedCapacity=0.9791667, numApps=5, numContainers=42 usedCapacity=0.9791667 absoluteUsedCapacity=0.9791667 used=<memory:48128, vCores:42> cluster=<memory:49152, vCores:96>
2013-08-05 22:22:11,901 INFO org.apache.hadoop.yarn.server.resourcemanager.scheduler.capacity.ParentQueue: completedContainer queue=root usedCapacity=0.9791667 absoluteUsedCapacity=0.9791667 used=<memory:48128, vCores:42> cluster=<memory:49152, vCores:96>
2013-08-05 22:22:11,901 INFO org.apache.hadoop.yarn.server.resourcemanager.scheduler.capacity.CapacityScheduler: Application appattempt_1375740621345_0006_000001 released container container_1375740621345_0006_01_000006 on node: host: hadoop-100-3:44102 #containers=7 available=1024 used=7168 with event: FINISHED
2013-08-05 22:22:11,901 INFO org.apache.hadoop.yarn.server.resourcemanager.rmcontainer.RMContainerImpl: container_1375740621345_0007_01_000009 Container Transitioned from NEW to ALLOCATED
2013-08-05 22:22:11,902 INFO org.apache.hadoop.yarn.server.resourcemanager.RMAuditLogger: USER=ubuntu	OPERATION=AM Allocated Container	TARGET=SchedulerApp	RESULT=SUCCESS	APPID=application_1375740621345_0007	CONTAINERID=container_1375740621345_0007_01_000009
2013-08-05 22:22:11,902 INFO org.apache.hadoop.yarn.server.resourcemanager.scheduler.common.fica.FiCaSchedulerNode: Assigned container container_1375740621345_0007_01_000009 of capacity <memory:1024, vCores:1> on host hadoop-100-3:44102, which currently has 8 containers, <memory:8192, vCores:8> used and <memory:0, vCores:8> available
2013-08-05 22:22:11,903 INFO org.apache.hadoop.yarn.server.resourcemanager.scheduler.capacity.LeafQueue: assignedContainer application=application_1375740621345_0007 container=Container: [ContainerId: container_1375740621345_0007_01_000009, NodeId: hadoop-100-3:44102, NodeHttpAddress: hadoop-100-3:8042, Resource: <memory:1024, vCores:1>, Priority: 20, State: NEW, Token: null, Status: container_id {, app_attempt_id {, application_id {, id: 7, cluster_timestamp: 1375740621345, }, attemptId: 1, }, id: 9, }, state: C_NEW, ] containerId=container_1375740621345_0007_01_000009 queue=default: capacity=1.0, absoluteCapacity=1.0, usedResources=<memory:48128, vCores:42>usedCapacity=0.9791667, absoluteUsedCapacity=0.9791667, numApps=5, numContainers=42 usedCapacity=0.9791667 absoluteUsedCapacity=0.9791667 used=<memory:48128, vCores:42> cluster=<memory:49152, vCores:96>
2013-08-05 22:22:11,903 INFO org.apache.hadoop.yarn.server.resourcemanager.scheduler.capacity.ParentQueue: Re-sorting queues since queue: root.default stats: default: capacity=1.0, absoluteCapacity=1.0, usedResources=<memory:49152, vCores:43>usedCapacity=1.0, absoluteUsedCapacity=1.0, numApps=5, numContainers=43
2013-08-05 22:22:11,903 INFO org.apache.hadoop.yarn.server.resourcemanager.scheduler.capacity.ParentQueue: assignedContainer queue=root usedCapacity=1.0 absoluteUsedCapacity=1.0 used=<memory:49152, vCores:43> cluster=<memory:49152, vCores:96>
2013-08-05 22:22:12,163 INFO org.apache.hadoop.yarn.server.resourcemanager.rmcontainer.RMContainerImpl: container_1375740621345_0007_01_000008 Container Transitioned from ACQUIRED to RUNNING
2013-08-05 22:22:12,164 INFO org.apache.hadoop.yarn.server.resourcemanager.rmcontainer.RMContainerImpl: container_1375740621345_0006_01_000016 Container Transitioned from RUNNING to COMPLETED
2013-08-05 22:22:12,164 INFO org.apache.hadoop.yarn.server.resourcemanager.scheduler.common.fica.FiCaSchedulerApp: Completed container: container_1375740621345_0006_01_000016 in state: COMPLETED event:FINISHED
2013-08-05 22:22:12,164 INFO org.apache.hadoop.yarn.server.resourcemanager.RMAuditLogger: USER=ubuntu	OPERATION=AM Released Container	TARGET=SchedulerApp	RESULT=SUCCESS	APPID=application_1375740621345_0006	CONTAINERID=container_1375740621345_0006_01_000016
2013-08-05 22:22:12,164 INFO org.apache.hadoop.yarn.server.resourcemanager.scheduler.common.fica.FiCaSchedulerNode: Released container container_1375740621345_0006_01_000016 of capacity <memory:1024, vCores:1> on host hadoop-100-2:37374, which currently has 5 containers, <memory:7168, vCores:5> used and <memory:1024, vCores:11> available, release resources=true
2013-08-05 22:22:12,164 INFO org.apache.hadoop.yarn.server.resourcemanager.scheduler.capacity.LeafQueue: default used=<memory:48128, vCores:42> numContainers=42 user=ubuntu user-resources=<memory:48128, vCores:42>
2013-08-05 22:22:12,165 INFO org.apache.hadoop.yarn.server.resourcemanager.scheduler.capacity.LeafQueue: completedContainer container=Container: [ContainerId: container_1375740621345_0006_01_000016, NodeId: hadoop-100-2:37374, NodeHttpAddress: hadoop-100-2:8042, Resource: <memory:1024, vCores:1>, Priority: 20, State: NEW, Token: null, Status: container_id {, app_attempt_id {, application_id {, id: 6, cluster_timestamp: 1375740621345, }, attemptId: 1, }, id: 16, }, state: C_COMPLETE, diagnostics: "Container killed by the ApplicationMaster.\n\n", exit_status: 143, ] resource=<memory:1024, vCores:1> queue=default: capacity=1.0, absoluteCapacity=1.0, usedResources=<memory:48128, vCores:42>usedCapacity=0.9791667, absoluteUsedCapacity=0.9791667, numApps=5, numContainers=42 usedCapacity=0.9791667 absoluteUsedCapacity=0.9791667 used=<memory:48128, vCores:42> cluster=<memory:49152, vCores:96>
2013-08-05 22:22:12,165 INFO org.apache.hadoop.yarn.server.resourcemanager.scheduler.capacity.ParentQueue: completedContainer queue=root usedCapacity=0.9791667 absoluteUsedCapacity=0.9791667 used=<memory:48128, vCores:42> cluster=<memory:49152, vCores:96>
2013-08-05 22:22:12,166 INFO org.apache.hadoop.yarn.server.resourcemanager.scheduler.capacity.CapacityScheduler: Application appattempt_1375740621345_0006_000001 released container container_1375740621345_0006_01_000016 on node: host: hadoop-100-2:37374 #containers=5 available=1024 used=7168 with event: FINISHED
2013-08-05 22:22:12,166 INFO org.apache.hadoop.yarn.server.resourcemanager.rmcontainer.RMContainerImpl: container_1375740621345_0007_01_000010 Container Transitioned from NEW to ALLOCATED
2013-08-05 22:22:12,166 INFO org.apache.hadoop.yarn.server.resourcemanager.RMAuditLogger: USER=ubuntu	OPERATION=AM Allocated Container	TARGET=SchedulerApp	RESULT=SUCCESS	APPID=application_1375740621345_0007	CONTAINERID=container_1375740621345_0007_01_000010
2013-08-05 22:22:12,166 INFO org.apache.hadoop.yarn.server.resourcemanager.scheduler.common.fica.FiCaSchedulerNode: Assigned container container_1375740621345_0007_01_000010 of capacity <memory:1024, vCores:1> on host hadoop-100-2:37374, which currently has 6 containers, <memory:8192, vCores:6> used and <memory:0, vCores:10> available
2013-08-05 22:22:12,167 INFO org.apache.hadoop.yarn.server.resourcemanager.scheduler.capacity.LeafQueue: assignedContainer application=application_1375740621345_0007 container=Container: [ContainerId: container_1375740621345_0007_01_000010, NodeId: hadoop-100-2:37374, NodeHttpAddress: hadoop-100-2:8042, Resource: <memory:1024, vCores:1>, Priority: 20, State: NEW, Token: null, Status: container_id {, app_attempt_id {, application_id {, id: 7, cluster_timestamp: 1375740621345, }, attemptId: 1, }, id: 10, }, state: C_NEW, ] containerId=container_1375740621345_0007_01_000010 queue=default: capacity=1.0, absoluteCapacity=1.0, usedResources=<memory:48128, vCores:42>usedCapacity=0.9791667, absoluteUsedCapacity=0.9791667, numApps=5, numContainers=42 usedCapacity=0.9791667 absoluteUsedCapacity=0.9791667 used=<memory:48128, vCores:42> cluster=<memory:49152, vCores:96>
2013-08-05 22:22:12,167 INFO org.apache.hadoop.yarn.server.resourcemanager.scheduler.capacity.ParentQueue: Re-sorting queues since queue: root.default stats: default: capacity=1.0, absoluteCapacity=1.0, usedResources=<memory:49152, vCores:43>usedCapacity=1.0, absoluteUsedCapacity=1.0, numApps=5, numContainers=43
2013-08-05 22:22:12,168 INFO org.apache.hadoop.yarn.server.resourcemanager.scheduler.capacity.ParentQueue: assignedContainer queue=root usedCapacity=1.0 absoluteUsedCapacity=1.0 used=<memory:49152, vCores:43> cluster=<memory:49152, vCores:96>
2013-08-05 22:22:12,650 INFO org.apache.hadoop.yarn.server.resourcemanager.rmcontainer.RMContainerImpl: container_1375740621345_0007_01_000009 Container Transitioned from ALLOCATED to ACQUIRED
2013-08-05 22:22:12,652 INFO org.apache.hadoop.yarn.server.resourcemanager.rmcontainer.RMContainerImpl: container_1375740621345_0007_01_000010 Container Transitioned from ALLOCATED to ACQUIRED
2013-08-05 22:22:12,918 INFO org.apache.hadoop.yarn.server.resourcemanager.rmcontainer.RMContainerImpl: container_1375740621345_0007_01_000009 Container Transitioned from ACQUIRED to RUNNING
2013-08-05 22:22:13,169 INFO org.apache.hadoop.yarn.server.resourcemanager.rmcontainer.RMContainerImpl: container_1375740621345_0007_01_000010 Container Transitioned from ACQUIRED to RUNNING
2013-08-05 22:22:14,539 INFO org.apache.hadoop.yarn.server.resourcemanager.rmcontainer.RMContainerImpl: container_1375740621345_0006_01_000034 Container Transitioned from RUNNING to COMPLETED
2013-08-05 22:22:14,539 INFO org.apache.hadoop.yarn.server.resourcemanager.scheduler.common.fica.FiCaSchedulerApp: Completed container: container_1375740621345_0006_01_000034 in state: COMPLETED event:FINISHED
2013-08-05 22:22:14,539 INFO org.apache.hadoop.yarn.server.resourcemanager.RMAuditLogger: USER=ubuntu	OPERATION=AM Released Container	TARGET=SchedulerApp	RESULT=SUCCESS	APPID=application_1375740621345_0006	CONTAINERID=container_1375740621345_0006_01_000034
2013-08-05 22:22:14,540 INFO org.apache.hadoop.yarn.server.resourcemanager.scheduler.common.fica.FiCaSchedulerNode: Released container container_1375740621345_0006_01_000034 of capacity <memory:1024, vCores:1> on host hadoop-100-5:58882, which currently has 7 containers, <memory:7168, vCores:7> used and <memory:1024, vCores:9> available, release resources=true
2013-08-05 22:22:14,540 INFO org.apache.hadoop.yarn.server.resourcemanager.scheduler.capacity.LeafQueue: default used=<memory:48128, vCores:42> numContainers=42 user=ubuntu user-resources=<memory:48128, vCores:42>
2013-08-05 22:22:14,541 INFO org.apache.hadoop.yarn.server.resourcemanager.scheduler.capacity.LeafQueue: completedContainer container=Container: [ContainerId: container_1375740621345_0006_01_000034, NodeId: hadoop-100-5:58882, NodeHttpAddress: hadoop-100-5:8042, Resource: <memory:1024, vCores:1>, Priority: 20, State: NEW, Token: null, Status: container_id {, app_attempt_id {, application_id {, id: 6, cluster_timestamp: 1375740621345, }, attemptId: 1, }, id: 34, }, state: C_COMPLETE, diagnostics: "Container killed by the ApplicationMaster.\n\n", exit_status: 143, ] resource=<memory:1024, vCores:1> queue=default: capacity=1.0, absoluteCapacity=1.0, usedResources=<memory:48128, vCores:42>usedCapacity=0.9791667, absoluteUsedCapacity=0.9791667, numApps=5, numContainers=42 usedCapacity=0.9791667 absoluteUsedCapacity=0.9791667 used=<memory:48128, vCores:42> cluster=<memory:49152, vCores:96>
2013-08-05 22:22:14,541 INFO org.apache.hadoop.yarn.server.resourcemanager.scheduler.capacity.ParentQueue: completedContainer queue=root usedCapacity=0.9791667 absoluteUsedCapacity=0.9791667 used=<memory:48128, vCores:42> cluster=<memory:49152, vCores:96>
2013-08-05 22:22:14,541 INFO org.apache.hadoop.yarn.server.resourcemanager.scheduler.capacity.CapacityScheduler: Application appattempt_1375740621345_0006_000001 released container container_1375740621345_0006_01_000034 on node: host: hadoop-100-5:58882 #containers=7 available=1024 used=7168 with event: FINISHED
2013-08-05 22:22:14,542 INFO org.apache.hadoop.yarn.server.resourcemanager.rmcontainer.RMContainerImpl: container_1375740621345_0007_01_000011 Container Transitioned from NEW to ALLOCATED
2013-08-05 22:22:14,542 INFO org.apache.hadoop.yarn.server.resourcemanager.RMAuditLogger: USER=ubuntu	OPERATION=AM Allocated Container	TARGET=SchedulerApp	RESULT=SUCCESS	APPID=application_1375740621345_0007	CONTAINERID=container_1375740621345_0007_01_000011
2013-08-05 22:22:14,542 INFO org.apache.hadoop.yarn.server.resourcemanager.scheduler.common.fica.FiCaSchedulerNode: Assigned container container_1375740621345_0007_01_000011 of capacity <memory:1024, vCores:1> on host hadoop-100-5:58882, which currently has 8 containers, <memory:8192, vCores:8> used and <memory:0, vCores:8> available
2013-08-05 22:22:14,543 INFO org.apache.hadoop.yarn.server.resourcemanager.scheduler.capacity.LeafQueue: assignedContainer application=application_1375740621345_0007 container=Container: [ContainerId: container_1375740621345_0007_01_000011, NodeId: hadoop-100-5:58882, NodeHttpAddress: hadoop-100-5:8042, Resource: <memory:1024, vCores:1>, Priority: 20, State: NEW, Token: null, Status: container_id {, app_attempt_id {, application_id {, id: 7, cluster_timestamp: 1375740621345, }, attemptId: 1, }, id: 11, }, state: C_NEW, ] containerId=container_1375740621345_0007_01_000011 queue=default: capacity=1.0, absoluteCapacity=1.0, usedResources=<memory:48128, vCores:42>usedCapacity=0.9791667, absoluteUsedCapacity=0.9791667, numApps=5, numContainers=42 usedCapacity=0.9791667 absoluteUsedCapacity=0.9791667 used=<memory:48128, vCores:42> cluster=<memory:49152, vCores:96>
2013-08-05 22:22:14,543 INFO org.apache.hadoop.yarn.server.resourcemanager.scheduler.capacity.ParentQueue: Re-sorting queues since queue: root.default stats: default: capacity=1.0, absoluteCapacity=1.0, usedResources=<memory:49152, vCores:43>usedCapacity=1.0, absoluteUsedCapacity=1.0, numApps=5, numContainers=43
2013-08-05 22:22:14,544 INFO org.apache.hadoop.yarn.server.resourcemanager.scheduler.capacity.ParentQueue: assignedContainer queue=root usedCapacity=1.0 absoluteUsedCapacity=1.0 used=<memory:49152, vCores:43> cluster=<memory:49152, vCores:96>
2013-08-05 22:22:14,994 INFO org.apache.hadoop.yarn.server.resourcemanager.rmcontainer.RMContainerImpl: container_1375740621345_0006_01_000033 Container Transitioned from RUNNING to COMPLETED
2013-08-05 22:22:14,995 INFO org.apache.hadoop.yarn.server.resourcemanager.scheduler.common.fica.FiCaSchedulerApp: Completed container: container_1375740621345_0006_01_000033 in state: COMPLETED event:FINISHED
2013-08-05 22:22:14,996 INFO org.apache.hadoop.yarn.server.resourcemanager.RMAuditLogger: USER=ubuntu	OPERATION=AM Released Container	TARGET=SchedulerApp	RESULT=SUCCESS	APPID=application_1375740621345_0006	CONTAINERID=container_1375740621345_0006_01_000033
2013-08-05 22:22:14,996 INFO org.apache.hadoop.yarn.server.resourcemanager.scheduler.common.fica.FiCaSchedulerNode: Released container container_1375740621345_0006_01_000033 of capacity <memory:1024, vCores:1> on host hadoop-100-5:58882, which currently has 7 containers, <memory:7168, vCores:7> used and <memory:1024, vCores:9> available, release resources=true
2013-08-05 22:22:14,996 INFO org.apache.hadoop.yarn.server.resourcemanager.scheduler.capacity.LeafQueue: default used=<memory:48128, vCores:42> numContainers=42 user=ubuntu user-resources=<memory:48128, vCores:42>
2013-08-05 22:22:14,997 INFO org.apache.hadoop.yarn.server.resourcemanager.scheduler.capacity.LeafQueue: completedContainer container=Container: [ContainerId: container_1375740621345_0006_01_000033, NodeId: hadoop-100-5:58882, NodeHttpAddress: hadoop-100-5:8042, Resource: <memory:1024, vCores:1>, Priority: 20, State: NEW, Token: null, Status: container_id {, app_attempt_id {, application_id {, id: 6, cluster_timestamp: 1375740621345, }, attemptId: 1, }, id: 33, }, state: C_COMPLETE, diagnostics: "Container killed by the ApplicationMaster.\n\n", exit_status: 143, ] resource=<memory:1024, vCores:1> queue=default: capacity=1.0, absoluteCapacity=1.0, usedResources=<memory:48128, vCores:42>usedCapacity=0.9791667, absoluteUsedCapacity=0.9791667, numApps=5, numContainers=42 usedCapacity=0.9791667 absoluteUsedCapacity=0.9791667 used=<memory:48128, vCores:42> cluster=<memory:49152, vCores:96>
2013-08-05 22:22:14,998 INFO org.apache.hadoop.yarn.server.resourcemanager.scheduler.capacity.ParentQueue: completedContainer queue=root usedCapacity=0.9791667 absoluteUsedCapacity=0.9791667 used=<memory:48128, vCores:42> cluster=<memory:49152, vCores:96>
2013-08-05 22:22:14,998 INFO org.apache.hadoop.yarn.server.resourcemanager.scheduler.capacity.CapacityScheduler: Application appattempt_1375740621345_0006_000001 released container container_1375740621345_0006_01_000033 on node: host: hadoop-100-5:58882 #containers=7 available=1024 used=7168 with event: FINISHED
2013-08-05 22:22:14,998 INFO org.apache.hadoop.yarn.server.resourcemanager.rmcontainer.RMContainerImpl: container_1375740621345_0007_01_000012 Container Transitioned from NEW to ALLOCATED
2013-08-05 22:22:14,998 INFO org.apache.hadoop.yarn.server.resourcemanager.RMAuditLogger: USER=ubuntu	OPERATION=AM Allocated Container	TARGET=SchedulerApp	RESULT=SUCCESS	APPID=application_1375740621345_0007	CONTAINERID=container_1375740621345_0007_01_000012
2013-08-05 22:22:14,999 INFO org.apache.hadoop.yarn.server.resourcemanager.scheduler.common.fica.FiCaSchedulerNode: Assigned container container_1375740621345_0007_01_000012 of capacity <memory:1024, vCores:1> on host hadoop-100-5:58882, which currently has 8 containers, <memory:8192, vCores:8> used and <memory:0, vCores:8> available
2013-08-05 22:22:14,999 INFO org.apache.hadoop.yarn.server.resourcemanager.scheduler.capacity.LeafQueue: assignedContainer application=application_1375740621345_0007 container=Container: [ContainerId: container_1375740621345_0007_01_000012, NodeId: hadoop-100-5:58882, NodeHttpAddress: hadoop-100-5:8042, Resource: <memory:1024, vCores:1>, Priority: 20, State: NEW, Token: null, Status: container_id {, app_attempt_id {, application_id {, id: 7, cluster_timestamp: 1375740621345, }, attemptId: 1, }, id: 12, }, state: C_NEW, ] containerId=container_1375740621345_0007_01_000012 queue=default: capacity=1.0, absoluteCapacity=1.0, usedResources=<memory:48128, vCores:42>usedCapacity=0.9791667, absoluteUsedCapacity=0.9791667, numApps=5, numContainers=42 usedCapacity=0.9791667 absoluteUsedCapacity=0.9791667 used=<memory:48128, vCores:42> cluster=<memory:49152, vCores:96>
2013-08-05 22:22:15,000 INFO org.apache.hadoop.yarn.server.resourcemanager.scheduler.capacity.ParentQueue: Re-sorting queues since queue: root.default stats: default: capacity=1.0, absoluteCapacity=1.0, usedResources=<memory:49152, vCores:43>usedCapacity=1.0, absoluteUsedCapacity=1.0, numApps=5, numContainers=43
2013-08-05 22:22:15,000 INFO org.apache.hadoop.yarn.server.resourcemanager.scheduler.capacity.ParentQueue: assignedContainer queue=root usedCapacity=1.0 absoluteUsedCapacity=1.0 used=<memory:49152, vCores:43> cluster=<memory:49152, vCores:96>
2013-08-05 22:22:15,478 INFO org.apache.hadoop.yarn.server.resourcemanager.rmcontainer.RMContainerImpl: container_1375740621345_0007_01_000011 Container Transitioned from ALLOCATED to ACQUIRED
2013-08-05 22:22:15,479 INFO org.apache.hadoop.yarn.server.resourcemanager.rmcontainer.RMContainerImpl: container_1375740621345_0007_01_000012 Container Transitioned from ALLOCATED to ACQUIRED
2013-08-05 22:22:15,683 INFO org.apache.hadoop.yarn.server.resourcemanager.rmcontainer.RMContainerImpl: container_1375740621345_0006_01_000028 Container Transitioned from RUNNING to COMPLETED
2013-08-05 22:22:15,684 INFO org.apache.hadoop.yarn.server.resourcemanager.scheduler.common.fica.FiCaSchedulerApp: Completed container: container_1375740621345_0006_01_000028 in state: COMPLETED event:FINISHED
2013-08-05 22:22:15,684 INFO org.apache.hadoop.yarn.server.resourcemanager.RMAuditLogger: USER=ubuntu	OPERATION=AM Released Container	TARGET=SchedulerApp	RESULT=SUCCESS	APPID=application_1375740621345_0006	CONTAINERID=container_1375740621345_0006_01_000028
2013-08-05 22:22:15,684 INFO org.apache.hadoop.yarn.server.resourcemanager.scheduler.common.fica.FiCaSchedulerNode: Released container container_1375740621345_0006_01_000028 of capacity <memory:1024, vCores:1> on host hadoop-100-6:42294, which currently has 6 containers, <memory:7168, vCores:6> used and <memory:1024, vCores:10> available, release resources=true
2013-08-05 22:22:15,684 INFO org.apache.hadoop.yarn.server.resourcemanager.scheduler.capacity.LeafQueue: default used=<memory:48128, vCores:42> numContainers=42 user=ubuntu user-resources=<memory:48128, vCores:42>
2013-08-05 22:22:15,685 INFO org.apache.hadoop.yarn.server.resourcemanager.scheduler.capacity.LeafQueue: completedContainer container=Container: [ContainerId: container_1375740621345_0006_01_000028, NodeId: hadoop-100-6:42294, NodeHttpAddress: hadoop-100-6:8042, Resource: <memory:1024, vCores:1>, Priority: 20, State: NEW, Token: null, Status: container_id {, app_attempt_id {, application_id {, id: 6, cluster_timestamp: 1375740621345, }, attemptId: 1, }, id: 28, }, state: C_COMPLETE, diagnostics: "Container killed by the ApplicationMaster.\n\n", exit_status: 143, ] resource=<memory:1024, vCores:1> queue=default: capacity=1.0, absoluteCapacity=1.0, usedResources=<memory:48128, vCores:42>usedCapacity=0.9791667, absoluteUsedCapacity=0.9791667, numApps=5, numContainers=42 usedCapacity=0.9791667 absoluteUsedCapacity=0.9791667 used=<memory:48128, vCores:42> cluster=<memory:49152, vCores:96>
2013-08-05 22:22:15,685 INFO org.apache.hadoop.yarn.server.resourcemanager.scheduler.capacity.ParentQueue: completedContainer queue=root usedCapacity=0.9791667 absoluteUsedCapacity=0.9791667 used=<memory:48128, vCores:42> cluster=<memory:49152, vCores:96>
2013-08-05 22:22:15,685 INFO org.apache.hadoop.yarn.server.resourcemanager.scheduler.capacity.CapacityScheduler: Application appattempt_1375740621345_0006_000001 released container container_1375740621345_0006_01_000028 on node: host: hadoop-100-6:42294 #containers=6 available=1024 used=7168 with event: FINISHED
2013-08-05 22:22:15,686 INFO org.apache.hadoop.yarn.server.resourcemanager.rmcontainer.RMContainerImpl: container_1375740621345_0007_01_000013 Container Transitioned from NEW to ALLOCATED
2013-08-05 22:22:15,686 INFO org.apache.hadoop.yarn.server.resourcemanager.RMAuditLogger: USER=ubuntu	OPERATION=AM Allocated Container	TARGET=SchedulerApp	RESULT=SUCCESS	APPID=application_1375740621345_0007	CONTAINERID=container_1375740621345_0007_01_000013
2013-08-05 22:22:15,686 INFO org.apache.hadoop.yarn.server.resourcemanager.scheduler.common.fica.FiCaSchedulerNode: Assigned container container_1375740621345_0007_01_000013 of capacity <memory:1024, vCores:1> on host hadoop-100-6:42294, which currently has 7 containers, <memory:8192, vCores:7> used and <memory:0, vCores:9> available
2013-08-05 22:22:15,687 INFO org.apache.hadoop.yarn.server.resourcemanager.scheduler.capacity.LeafQueue: assignedContainer application=application_1375740621345_0007 container=Container: [ContainerId: container_1375740621345_0007_01_000013, NodeId: hadoop-100-6:42294, NodeHttpAddress: hadoop-100-6:8042, Resource: <memory:1024, vCores:1>, Priority: 20, State: NEW, Token: null, Status: container_id {, app_attempt_id {, application_id {, id: 7, cluster_timestamp: 1375740621345, }, attemptId: 1, }, id: 13, }, state: C_NEW, ] containerId=container_1375740621345_0007_01_000013 queue=default: capacity=1.0, absoluteCapacity=1.0, usedResources=<memory:48128, vCores:42>usedCapacity=0.9791667, absoluteUsedCapacity=0.9791667, numApps=5, numContainers=42 usedCapacity=0.9791667 absoluteUsedCapacity=0.9791667 used=<memory:48128, vCores:42> cluster=<memory:49152, vCores:96>
2013-08-05 22:22:15,687 INFO org.apache.hadoop.yarn.server.resourcemanager.scheduler.capacity.ParentQueue: Re-sorting queues since queue: root.default stats: default: capacity=1.0, absoluteCapacity=1.0, usedResources=<memory:49152, vCores:43>usedCapacity=1.0, absoluteUsedCapacity=1.0, numApps=5, numContainers=43
2013-08-05 22:22:15,688 INFO org.apache.hadoop.yarn.server.resourcemanager.scheduler.capacity.ParentQueue: assignedContainer queue=root usedCapacity=1.0 absoluteUsedCapacity=1.0 used=<memory:49152, vCores:43> cluster=<memory:49152, vCores:96>
2013-08-05 22:22:16,002 INFO org.apache.hadoop.yarn.server.resourcemanager.rmcontainer.RMContainerImpl: container_1375740621345_0007_01_000011 Container Transitioned from ACQUIRED to RUNNING
2013-08-05 22:22:16,003 INFO org.apache.hadoop.yarn.server.resourcemanager.rmcontainer.RMContainerImpl: container_1375740621345_0007_01_000012 Container Transitioned from ACQUIRED to RUNNING
2013-08-05 22:22:16,003 INFO org.apache.hadoop.yarn.server.resourcemanager.rmcontainer.RMContainerImpl: container_1375740621345_0006_01_000036 Container Transitioned from RUNNING to COMPLETED
2013-08-05 22:22:16,003 INFO org.apache.hadoop.yarn.server.resourcemanager.scheduler.common.fica.FiCaSchedulerApp: Completed container: container_1375740621345_0006_01_000036 in state: COMPLETED event:FINISHED
2013-08-05 22:22:16,003 INFO org.apache.hadoop.yarn.server.resourcemanager.RMAuditLogger: USER=ubuntu	OPERATION=AM Released Container	TARGET=SchedulerApp	RESULT=SUCCESS	APPID=application_1375740621345_0006	CONTAINERID=container_1375740621345_0006_01_000036
2013-08-05 22:22:16,003 INFO org.apache.hadoop.yarn.server.resourcemanager.scheduler.common.fica.FiCaSchedulerNode: Released container container_1375740621345_0006_01_000036 of capacity <memory:1024, vCores:1> on host hadoop-100-5:58882, which currently has 7 containers, <memory:7168, vCores:7> used and <memory:1024, vCores:9> available, release resources=true
2013-08-05 22:22:16,003 INFO org.apache.hadoop.yarn.server.resourcemanager.scheduler.capacity.LeafQueue: default used=<memory:48128, vCores:42> numContainers=42 user=ubuntu user-resources=<memory:48128, vCores:42>
2013-08-05 22:22:16,004 INFO org.apache.hadoop.yarn.server.resourcemanager.scheduler.capacity.LeafQueue: completedContainer container=Container: [ContainerId: container_1375740621345_0006_01_000036, NodeId: hadoop-100-5:58882, NodeHttpAddress: hadoop-100-5:8042, Resource: <memory:1024, vCores:1>, Priority: 20, State: NEW, Token: null, Status: container_id {, app_attempt_id {, application_id {, id: 6, cluster_timestamp: 1375740621345, }, attemptId: 1, }, id: 36, }, state: C_COMPLETE, diagnostics: "Container killed by the ApplicationMaster.\n\n", exit_status: 143, ] resource=<memory:1024, vCores:1> queue=default: capacity=1.0, absoluteCapacity=1.0, usedResources=<memory:48128, vCores:42>usedCapacity=0.9791667, absoluteUsedCapacity=0.9791667, numApps=5, numContainers=42 usedCapacity=0.9791667 absoluteUsedCapacity=0.9791667 used=<memory:48128, vCores:42> cluster=<memory:49152, vCores:96>
2013-08-05 22:22:16,005 INFO org.apache.hadoop.yarn.server.resourcemanager.scheduler.capacity.ParentQueue: completedContainer queue=root usedCapacity=0.9791667 absoluteUsedCapacity=0.9791667 used=<memory:48128, vCores:42> cluster=<memory:49152, vCores:96>
2013-08-05 22:22:16,005 INFO org.apache.hadoop.yarn.server.resourcemanager.scheduler.capacity.CapacityScheduler: Application appattempt_1375740621345_0006_000001 released container container_1375740621345_0006_01_000036 on node: host: hadoop-100-5:58882 #containers=7 available=1024 used=7168 with event: FINISHED
2013-08-05 22:22:16,005 INFO org.apache.hadoop.yarn.server.resourcemanager.rmcontainer.RMContainerImpl: container_1375740621345_0007_01_000014 Container Transitioned from NEW to ALLOCATED
2013-08-05 22:22:16,006 INFO org.apache.hadoop.yarn.server.resourcemanager.RMAuditLogger: USER=ubuntu	OPERATION=AM Allocated Container	TARGET=SchedulerApp	RESULT=SUCCESS	APPID=application_1375740621345_0007	CONTAINERID=container_1375740621345_0007_01_000014
2013-08-05 22:22:16,006 INFO org.apache.hadoop.yarn.server.resourcemanager.scheduler.common.fica.FiCaSchedulerNode: Assigned container container_1375740621345_0007_01_000014 of capacity <memory:1024, vCores:1> on host hadoop-100-5:58882, which currently has 8 containers, <memory:8192, vCores:8> used and <memory:0, vCores:8> available
2013-08-05 22:22:16,007 INFO org.apache.hadoop.yarn.server.resourcemanager.scheduler.capacity.LeafQueue: assignedContainer application=application_1375740621345_0007 container=Container: [ContainerId: container_1375740621345_0007_01_000014, NodeId: hadoop-100-5:58882, NodeHttpAddress: hadoop-100-5:8042, Resource: <memory:1024, vCores:1>, Priority: 20, State: NEW, Token: null, Status: container_id {, app_attempt_id {, application_id {, id: 7, cluster_timestamp: 1375740621345, }, attemptId: 1, }, id: 14, }, state: C_NEW, ] containerId=container_1375740621345_0007_01_000014 queue=default: capacity=1.0, absoluteCapacity=1.0, usedResources=<memory:48128, vCores:42>usedCapacity=0.9791667, absoluteUsedCapacity=0.9791667, numApps=5, numContainers=42 usedCapacity=0.9791667 absoluteUsedCapacity=0.9791667 used=<memory:48128, vCores:42> cluster=<memory:49152, vCores:96>
2013-08-05 22:22:16,007 INFO org.apache.hadoop.yarn.server.resourcemanager.scheduler.capacity.ParentQueue: Re-sorting queues since queue: root.default stats: default: capacity=1.0, absoluteCapacity=1.0, usedResources=<memory:49152, vCores:43>usedCapacity=1.0, absoluteUsedCapacity=1.0, numApps=5, numContainers=43
2013-08-05 22:22:16,007 INFO org.apache.hadoop.yarn.server.resourcemanager.scheduler.capacity.ParentQueue: assignedContainer queue=root usedCapacity=1.0 absoluteUsedCapacity=1.0 used=<memory:49152, vCores:43> cluster=<memory:49152, vCores:96>
2013-08-05 22:22:16,449 INFO org.apache.hadoop.yarn.server.resourcemanager.rmcontainer.RMContainerImpl: container_1375740621345_0006_01_000008 Container Transitioned from RUNNING to COMPLETED
2013-08-05 22:22:16,449 INFO org.apache.hadoop.yarn.server.resourcemanager.scheduler.common.fica.FiCaSchedulerApp: Completed container: container_1375740621345_0006_01_000008 in state: COMPLETED event:FINISHED
2013-08-05 22:22:16,449 INFO org.apache.hadoop.yarn.server.resourcemanager.RMAuditLogger: USER=ubuntu	OPERATION=AM Released Container	TARGET=SchedulerApp	RESULT=SUCCESS	APPID=application_1375740621345_0006	CONTAINERID=container_1375740621345_0006_01_000008
2013-08-05 22:22:16,449 INFO org.apache.hadoop.yarn.server.resourcemanager.scheduler.common.fica.FiCaSchedulerNode: Released container container_1375740621345_0006_01_000008 of capacity <memory:1024, vCores:1> on host hadoop-100-3:44102, which currently has 7 containers, <memory:7168, vCores:7> used and <memory:1024, vCores:9> available, release resources=true
2013-08-05 22:22:16,450 INFO org.apache.hadoop.yarn.server.resourcemanager.scheduler.capacity.LeafQueue: default used=<memory:48128, vCores:42> numContainers=42 user=ubuntu user-resources=<memory:48128, vCores:42>
2013-08-05 22:22:16,451 INFO org.apache.hadoop.yarn.server.resourcemanager.scheduler.capacity.LeafQueue: completedContainer container=Container: [ContainerId: container_1375740621345_0006_01_000008, NodeId: hadoop-100-3:44102, NodeHttpAddress: hadoop-100-3:8042, Resource: <memory:1024, vCores:1>, Priority: 20, State: NEW, Token: null, Status: container_id {, app_attempt_id {, application_id {, id: 6, cluster_timestamp: 1375740621345, }, attemptId: 1, }, id: 8, }, state: C_COMPLETE, diagnostics: "Container killed by the ApplicationMaster.\n", exit_status: 0, ] resource=<memory:1024, vCores:1> queue=default: capacity=1.0, absoluteCapacity=1.0, usedResources=<memory:48128, vCores:42>usedCapacity=0.9791667, absoluteUsedCapacity=0.9791667, numApps=5, numContainers=42 usedCapacity=0.9791667 absoluteUsedCapacity=0.9791667 used=<memory:48128, vCores:42> cluster=<memory:49152, vCores:96>
2013-08-05 22:22:16,451 INFO org.apache.hadoop.yarn.server.resourcemanager.scheduler.capacity.ParentQueue: completedContainer queue=root usedCapacity=0.9791667 absoluteUsedCapacity=0.9791667 used=<memory:48128, vCores:42> cluster=<memory:49152, vCores:96>
2013-08-05 22:22:16,451 INFO org.apache.hadoop.yarn.server.resourcemanager.scheduler.capacity.CapacityScheduler: Application appattempt_1375740621345_0006_000001 released container container_1375740621345_0006_01_000008 on node: host: hadoop-100-3:44102 #containers=7 available=1024 used=7168 with event: FINISHED
2013-08-05 22:22:16,452 INFO org.apache.hadoop.yarn.server.resourcemanager.rmcontainer.RMContainerImpl: container_1375740621345_0007_01_000015 Container Transitioned from NEW to ALLOCATED
2013-08-05 22:22:16,452 INFO org.apache.hadoop.yarn.server.resourcemanager.RMAuditLogger: USER=ubuntu	OPERATION=AM Allocated Container	TARGET=SchedulerApp	RESULT=SUCCESS	APPID=application_1375740621345_0007	CONTAINERID=container_1375740621345_0007_01_000015
2013-08-05 22:22:16,452 INFO org.apache.hadoop.yarn.server.resourcemanager.scheduler.common.fica.FiCaSchedulerNode: Assigned container container_1375740621345_0007_01_000015 of capacity <memory:1024, vCores:1> on host hadoop-100-3:44102, which currently has 8 containers, <memory:8192, vCores:8> used and <memory:0, vCores:8> available
2013-08-05 22:22:16,453 INFO org.apache.hadoop.yarn.server.resourcemanager.scheduler.capacity.LeafQueue: assignedContainer application=application_1375740621345_0007 container=Container: [ContainerId: container_1375740621345_0007_01_000015, NodeId: hadoop-100-3:44102, NodeHttpAddress: hadoop-100-3:8042, Resource: <memory:1024, vCores:1>, Priority: 20, State: NEW, Token: null, Status: container_id {, app_attempt_id {, application_id {, id: 7, cluster_timestamp: 1375740621345, }, attemptId: 1, }, id: 15, }, state: C_NEW, ] containerId=container_1375740621345_0007_01_000015 queue=default: capacity=1.0, absoluteCapacity=1.0, usedResources=<memory:48128, vCores:42>usedCapacity=0.9791667, absoluteUsedCapacity=0.9791667, numApps=5, numContainers=42 usedCapacity=0.9791667 absoluteUsedCapacity=0.9791667 used=<memory:48128, vCores:42> cluster=<memory:49152, vCores:96>
2013-08-05 22:22:16,453 INFO org.apache.hadoop.yarn.server.resourcemanager.scheduler.capacity.ParentQueue: Re-sorting queues since queue: root.default stats: default: capacity=1.0, absoluteCapacity=1.0, usedResources=<memory:49152, vCores:43>usedCapacity=1.0, absoluteUsedCapacity=1.0, numApps=5, numContainers=43
2013-08-05 22:22:16,453 INFO org.apache.hadoop.yarn.server.resourcemanager.scheduler.capacity.ParentQueue: assignedContainer queue=root usedCapacity=1.0 absoluteUsedCapacity=1.0 used=<memory:49152, vCores:43> cluster=<memory:49152, vCores:96>
2013-08-05 22:22:16,488 INFO org.apache.hadoop.yarn.server.resourcemanager.rmcontainer.RMContainerImpl: container_1375740621345_0007_01_000013 Container Transitioned from ALLOCATED to ACQUIRED
2013-08-05 22:22:16,489 INFO org.apache.hadoop.yarn.server.resourcemanager.rmcontainer.RMContainerImpl: container_1375740621345_0007_01_000014 Container Transitioned from ALLOCATED to ACQUIRED
2013-08-05 22:22:16,489 INFO org.apache.hadoop.yarn.server.resourcemanager.rmcontainer.RMContainerImpl: container_1375740621345_0007_01_000015 Container Transitioned from ALLOCATED to ACQUIRED
2013-08-05 22:22:16,689 INFO org.apache.hadoop.yarn.server.resourcemanager.rmcontainer.RMContainerImpl: container_1375740621345_0007_01_000013 Container Transitioned from ACQUIRED to RUNNING
2013-08-05 22:22:16,690 INFO org.apache.hadoop.yarn.server.resourcemanager.rmcontainer.RMContainerImpl: container_1375740621345_0006_01_000030 Container Transitioned from RUNNING to COMPLETED
2013-08-05 22:22:16,690 INFO org.apache.hadoop.yarn.server.resourcemanager.scheduler.common.fica.FiCaSchedulerApp: Completed container: container_1375740621345_0006_01_000030 in state: COMPLETED event:FINISHED
2013-08-05 22:22:16,690 INFO org.apache.hadoop.yarn.server.resourcemanager.RMAuditLogger: USER=ubuntu	OPERATION=AM Released Container	TARGET=SchedulerApp	RESULT=SUCCESS	APPID=application_1375740621345_0006	CONTAINERID=container_1375740621345_0006_01_000030
2013-08-05 22:22:16,690 INFO org.apache.hadoop.yarn.server.resourcemanager.scheduler.common.fica.FiCaSchedulerNode: Released container container_1375740621345_0006_01_000030 of capacity <memory:1024, vCores:1> on host hadoop-100-6:42294, which currently has 6 containers, <memory:7168, vCores:6> used and <memory:1024, vCores:10> available, release resources=true
2013-08-05 22:22:16,690 INFO org.apache.hadoop.yarn.server.resourcemanager.scheduler.capacity.LeafQueue: default used=<memory:48128, vCores:42> numContainers=42 user=ubuntu user-resources=<memory:48128, vCores:42>
2013-08-05 22:22:16,691 INFO org.apache.hadoop.yarn.server.resourcemanager.scheduler.capacity.LeafQueue: completedContainer container=Container: [ContainerId: container_1375740621345_0006_01_000030, NodeId: hadoop-100-6:42294, NodeHttpAddress: hadoop-100-6:8042, Resource: <memory:1024, vCores:1>, Priority: 20, State: NEW, Token: null, Status: container_id {, app_attempt_id {, application_id {, id: 6, cluster_timestamp: 1375740621345, }, attemptId: 1, }, id: 30, }, state: C_COMPLETE, diagnostics: "Container killed by the ApplicationMaster.\n\n", exit_status: 143, ] resource=<memory:1024, vCores:1> queue=default: capacity=1.0, absoluteCapacity=1.0, usedResources=<memory:48128, vCores:42>usedCapacity=0.9791667, absoluteUsedCapacity=0.9791667, numApps=5, numContainers=42 usedCapacity=0.9791667 absoluteUsedCapacity=0.9791667 used=<memory:48128, vCores:42> cluster=<memory:49152, vCores:96>
2013-08-05 22:22:16,691 INFO org.apache.hadoop.yarn.server.resourcemanager.scheduler.capacity.ParentQueue: completedContainer queue=root usedCapacity=0.9791667 absoluteUsedCapacity=0.9791667 used=<memory:48128, vCores:42> cluster=<memory:49152, vCores:96>
2013-08-05 22:22:16,692 INFO org.apache.hadoop.yarn.server.resourcemanager.scheduler.capacity.CapacityScheduler: Application appattempt_1375740621345_0006_000001 released container container_1375740621345_0006_01_000030 on node: host: hadoop-100-6:42294 #containers=6 available=1024 used=7168 with event: FINISHED
2013-08-05 22:22:16,692 INFO org.apache.hadoop.yarn.server.resourcemanager.rmcontainer.RMContainerImpl: container_1375740621345_0007_01_000016 Container Transitioned from NEW to ALLOCATED
2013-08-05 22:22:16,692 INFO org.apache.hadoop.yarn.server.resourcemanager.RMAuditLogger: USER=ubuntu	OPERATION=AM Allocated Container	TARGET=SchedulerApp	RESULT=SUCCESS	APPID=application_1375740621345_0007	CONTAINERID=container_1375740621345_0007_01_000016
2013-08-05 22:22:16,692 INFO org.apache.hadoop.yarn.server.resourcemanager.scheduler.common.fica.FiCaSchedulerNode: Assigned container container_1375740621345_0007_01_000016 of capacity <memory:1024, vCores:1> on host hadoop-100-6:42294, which currently has 7 containers, <memory:8192, vCores:7> used and <memory:0, vCores:9> available
2013-08-05 22:22:16,693 INFO org.apache.hadoop.yarn.server.resourcemanager.scheduler.capacity.LeafQueue: assignedContainer application=application_1375740621345_0007 container=Container: [ContainerId: container_1375740621345_0007_01_000016, NodeId: hadoop-100-6:42294, NodeHttpAddress: hadoop-100-6:8042, Resource: <memory:1024, vCores:1>, Priority: 20, State: NEW, Token: null, Status: container_id {, app_attempt_id {, application_id {, id: 7, cluster_timestamp: 1375740621345, }, attemptId: 1, }, id: 16, }, state: C_NEW, ] containerId=container_1375740621345_0007_01_000016 queue=default: capacity=1.0, absoluteCapacity=1.0, usedResources=<memory:48128, vCores:42>usedCapacity=0.9791667, absoluteUsedCapacity=0.9791667, numApps=5, numContainers=42 usedCapacity=0.9791667 absoluteUsedCapacity=0.9791667 used=<memory:48128, vCores:42> cluster=<memory:49152, vCores:96>
2013-08-05 22:22:16,693 INFO org.apache.hadoop.yarn.server.resourcemanager.scheduler.capacity.ParentQueue: Re-sorting queues since queue: root.default stats: default: capacity=1.0, absoluteCapacity=1.0, usedResources=<memory:49152, vCores:43>usedCapacity=1.0, absoluteUsedCapacity=1.0, numApps=5, numContainers=43
2013-08-05 22:22:16,694 INFO org.apache.hadoop.yarn.server.resourcemanager.scheduler.capacity.ParentQueue: assignedContainer queue=root usedCapacity=1.0 absoluteUsedCapacity=1.0 used=<memory:49152, vCores:43> cluster=<memory:49152, vCores:96>
2013-08-05 22:22:17,041 INFO org.apache.hadoop.yarn.server.resourcemanager.rmcontainer.RMContainerImpl: container_1375740621345_0007_01_000014 Container Transitioned from ACQUIRED to RUNNING
2013-08-05 22:22:17,233 INFO org.apache.hadoop.yarn.server.resourcemanager.rmcontainer.RMContainerImpl: container_1375740621345_0006_01_000022 Container Transitioned from RUNNING to COMPLETED
2013-08-05 22:22:17,233 INFO org.apache.hadoop.yarn.server.resourcemanager.scheduler.common.fica.FiCaSchedulerApp: Completed container: container_1375740621345_0006_01_000022 in state: COMPLETED event:FINISHED
2013-08-05 22:22:17,233 INFO org.apache.hadoop.yarn.server.resourcemanager.RMAuditLogger: USER=ubuntu	OPERATION=AM Released Container	TARGET=SchedulerApp	RESULT=SUCCESS	APPID=application_1375740621345_0006	CONTAINERID=container_1375740621345_0006_01_000022
2013-08-05 22:22:17,233 INFO org.apache.hadoop.yarn.server.resourcemanager.scheduler.common.fica.FiCaSchedulerNode: Released container container_1375740621345_0006_01_000022 of capacity <memory:1024, vCores:1> on host hadoop-100-7:36057, which currently has 7 containers, <memory:7168, vCores:7> used and <memory:1024, vCores:9> available, release resources=true
2013-08-05 22:22:17,233 INFO org.apache.hadoop.yarn.server.resourcemanager.scheduler.capacity.LeafQueue: default used=<memory:48128, vCores:42> numContainers=42 user=ubuntu user-resources=<memory:48128, vCores:42>
2013-08-05 22:22:17,234 INFO org.apache.hadoop.yarn.server.resourcemanager.scheduler.capacity.LeafQueue: completedContainer container=Container: [ContainerId: container_1375740621345_0006_01_000022, NodeId: hadoop-100-7:36057, NodeHttpAddress: hadoop-100-7:8042, Resource: <memory:1024, vCores:1>, Priority: 20, State: NEW, Token: null, Status: container_id {, app_attempt_id {, application_id {, id: 6, cluster_timestamp: 1375740621345, }, attemptId: 1, }, id: 22, }, state: C_COMPLETE, diagnostics: "Container killed by the ApplicationMaster.\n\n", exit_status: 143, ] resource=<memory:1024, vCores:1> queue=default: capacity=1.0, absoluteCapacity=1.0, usedResources=<memory:48128, vCores:42>usedCapacity=0.9791667, absoluteUsedCapacity=0.9791667, numApps=5, numContainers=42 usedCapacity=0.9791667 absoluteUsedCapacity=0.9791667 used=<memory:48128, vCores:42> cluster=<memory:49152, vCores:96>
2013-08-05 22:22:17,234 INFO org.apache.hadoop.yarn.server.resourcemanager.scheduler.capacity.ParentQueue: completedContainer queue=root usedCapacity=0.9791667 absoluteUsedCapacity=0.9791667 used=<memory:48128, vCores:42> cluster=<memory:49152, vCores:96>
2013-08-05 22:22:17,235 INFO org.apache.hadoop.yarn.server.resourcemanager.scheduler.capacity.CapacityScheduler: Application appattempt_1375740621345_0006_000001 released container container_1375740621345_0006_01_000022 on node: host: hadoop-100-7:36057 #containers=7 available=1024 used=7168 with event: FINISHED
2013-08-05 22:22:17,235 INFO org.apache.hadoop.yarn.server.resourcemanager.rmcontainer.RMContainerImpl: container_1375740621345_0007_01_000017 Container Transitioned from NEW to ALLOCATED
2013-08-05 22:22:17,235 INFO org.apache.hadoop.yarn.server.resourcemanager.RMAuditLogger: USER=ubuntu	OPERATION=AM Allocated Container	TARGET=SchedulerApp	RESULT=SUCCESS	APPID=application_1375740621345_0007	CONTAINERID=container_1375740621345_0007_01_000017
2013-08-05 22:22:17,235 INFO org.apache.hadoop.yarn.server.resourcemanager.scheduler.common.fica.FiCaSchedulerNode: Assigned container container_1375740621345_0007_01_000017 of capacity <memory:1024, vCores:1> on host hadoop-100-7:36057, which currently has 8 containers, <memory:8192, vCores:8> used and <memory:0, vCores:8> available
2013-08-05 22:22:17,236 INFO org.apache.hadoop.yarn.server.resourcemanager.scheduler.capacity.LeafQueue: assignedContainer application=application_1375740621345_0007 container=Container: [ContainerId: container_1375740621345_0007_01_000017, NodeId: hadoop-100-7:36057, NodeHttpAddress: hadoop-100-7:8042, Resource: <memory:1024, vCores:1>, Priority: 20, State: NEW, Token: null, Status: container_id {, app_attempt_id {, application_id {, id: 7, cluster_timestamp: 1375740621345, }, attemptId: 1, }, id: 17, }, state: C_NEW, ] containerId=container_1375740621345_0007_01_000017 queue=default: capacity=1.0, absoluteCapacity=1.0, usedResources=<memory:48128, vCores:42>usedCapacity=0.9791667, absoluteUsedCapacity=0.9791667, numApps=5, numContainers=42 usedCapacity=0.9791667 absoluteUsedCapacity=0.9791667 used=<memory:48128, vCores:42> cluster=<memory:49152, vCores:96>
2013-08-05 22:22:17,237 INFO org.apache.hadoop.yarn.server.resourcemanager.scheduler.capacity.ParentQueue: Re-sorting queues since queue: root.default stats: default: capacity=1.0, absoluteCapacity=1.0, usedResources=<memory:49152, vCores:43>usedCapacity=1.0, absoluteUsedCapacity=1.0, numApps=5, numContainers=43
2013-08-05 22:22:17,237 INFO org.apache.hadoop.yarn.server.resourcemanager.scheduler.capacity.ParentQueue: assignedContainer queue=root usedCapacity=1.0 absoluteUsedCapacity=1.0 used=<memory:49152, vCores:43> cluster=<memory:49152, vCores:96>
2013-08-05 22:22:17,455 INFO org.apache.hadoop.yarn.server.resourcemanager.rmcontainer.RMContainerImpl: container_1375740621345_0007_01_000015 Container Transitioned from ACQUIRED to RUNNING
2013-08-05 22:22:17,496 INFO org.apache.hadoop.yarn.server.resourcemanager.rmcontainer.RMContainerImpl: container_1375740621345_0007_01_000016 Container Transitioned from ALLOCATED to ACQUIRED
2013-08-05 22:22:17,497 INFO org.apache.hadoop.yarn.server.resourcemanager.rmcontainer.RMContainerImpl: container_1375740621345_0007_01_000017 Container Transitioned from ALLOCATED to ACQUIRED
2013-08-05 22:22:17,705 INFO org.apache.hadoop.yarn.server.resourcemanager.rmcontainer.RMContainerImpl: container_1375740621345_0007_01_000016 Container Transitioned from ACQUIRED to RUNNING
2013-08-05 22:22:17,719 INFO org.apache.hadoop.yarn.server.resourcemanager.rmcontainer.RMContainerImpl: container_1375740621345_0007_01_000017 Container Transitioned from ACQUIRED to RUNNING
2013-08-05 22:22:18,339 INFO org.apache.hadoop.yarn.server.resourcemanager.rmcontainer.RMContainerImpl: container_1375740621345_0006_01_000018 Container Transitioned from RUNNING to COMPLETED
2013-08-05 22:22:18,340 INFO org.apache.hadoop.yarn.server.resourcemanager.scheduler.common.fica.FiCaSchedulerApp: Completed container: container_1375740621345_0006_01_000018 in state: COMPLETED event:FINISHED
2013-08-05 22:22:18,340 INFO org.apache.hadoop.yarn.server.resourcemanager.RMAuditLogger: USER=ubuntu	OPERATION=AM Released Container	TARGET=SchedulerApp	RESULT=SUCCESS	APPID=application_1375740621345_0006	CONTAINERID=container_1375740621345_0006_01_000018
2013-08-05 22:22:18,340 INFO org.apache.hadoop.yarn.server.resourcemanager.scheduler.common.fica.FiCaSchedulerNode: Released container container_1375740621345_0006_01_000018 of capacity <memory:1024, vCores:1> on host hadoop-100-7:36057, which currently has 7 containers, <memory:7168, vCores:7> used and <memory:1024, vCores:9> available, release resources=true
2013-08-05 22:22:18,340 INFO org.apache.hadoop.yarn.server.resourcemanager.scheduler.capacity.LeafQueue: default used=<memory:48128, vCores:42> numContainers=42 user=ubuntu user-resources=<memory:48128, vCores:42>
2013-08-05 22:22:18,341 INFO org.apache.hadoop.yarn.server.resourcemanager.scheduler.capacity.LeafQueue: completedContainer container=Container: [ContainerId: container_1375740621345_0006_01_000018, NodeId: hadoop-100-7:36057, NodeHttpAddress: hadoop-100-7:8042, Resource: <memory:1024, vCores:1>, Priority: 20, State: NEW, Token: null, Status: container_id {, app_attempt_id {, application_id {, id: 6, cluster_timestamp: 1375740621345, }, attemptId: 1, }, id: 18, }, state: C_COMPLETE, diagnostics: "Container killed by the ApplicationMaster.\n\n", exit_status: 143, ] resource=<memory:1024, vCores:1> queue=default: capacity=1.0, absoluteCapacity=1.0, usedResources=<memory:48128, vCores:42>usedCapacity=0.9791667, absoluteUsedCapacity=0.9791667, numApps=5, numContainers=42 usedCapacity=0.9791667 absoluteUsedCapacity=0.9791667 used=<memory:48128, vCores:42> cluster=<memory:49152, vCores:96>
2013-08-05 22:22:18,341 INFO org.apache.hadoop.yarn.server.resourcemanager.scheduler.capacity.ParentQueue: completedContainer queue=root usedCapacity=0.9791667 absoluteUsedCapacity=0.9791667 used=<memory:48128, vCores:42> cluster=<memory:49152, vCores:96>
2013-08-05 22:22:18,342 INFO org.apache.hadoop.yarn.server.resourcemanager.scheduler.capacity.CapacityScheduler: Application appattempt_1375740621345_0006_000001 released container container_1375740621345_0006_01_000018 on node: host: hadoop-100-7:36057 #containers=7 available=1024 used=7168 with event: FINISHED
2013-08-05 22:22:18,342 INFO org.apache.hadoop.yarn.server.resourcemanager.rmcontainer.RMContainerImpl: container_1375740621345_0007_01_000018 Container Transitioned from NEW to ALLOCATED
2013-08-05 22:22:18,342 INFO org.apache.hadoop.yarn.server.resourcemanager.RMAuditLogger: USER=ubuntu	OPERATION=AM Allocated Container	TARGET=SchedulerApp	RESULT=SUCCESS	APPID=application_1375740621345_0007	CONTAINERID=container_1375740621345_0007_01_000018
2013-08-05 22:22:18,342 INFO org.apache.hadoop.yarn.server.resourcemanager.scheduler.common.fica.FiCaSchedulerNode: Assigned container container_1375740621345_0007_01_000018 of capacity <memory:1024, vCores:1> on host hadoop-100-7:36057, which currently has 8 containers, <memory:8192, vCores:8> used and <memory:0, vCores:8> available
2013-08-05 22:22:18,343 INFO org.apache.hadoop.yarn.server.resourcemanager.scheduler.capacity.LeafQueue: assignedContainer application=application_1375740621345_0007 container=Container: [ContainerId: container_1375740621345_0007_01_000018, NodeId: hadoop-100-7:36057, NodeHttpAddress: hadoop-100-7:8042, Resource: <memory:1024, vCores:1>, Priority: 20, State: NEW, Token: null, Status: container_id {, app_attempt_id {, application_id {, id: 7, cluster_timestamp: 1375740621345, }, attemptId: 1, }, id: 18, }, state: C_NEW, ] containerId=container_1375740621345_0007_01_000018 queue=default: capacity=1.0, absoluteCapacity=1.0, usedResources=<memory:48128, vCores:42>usedCapacity=0.9791667, absoluteUsedCapacity=0.9791667, numApps=5, numContainers=42 usedCapacity=0.9791667 absoluteUsedCapacity=0.9791667 used=<memory:48128, vCores:42> cluster=<memory:49152, vCores:96>
2013-08-05 22:22:18,343 INFO org.apache.hadoop.yarn.server.resourcemanager.scheduler.capacity.ParentQueue: Re-sorting queues since queue: root.default stats: default: capacity=1.0, absoluteCapacity=1.0, usedResources=<memory:49152, vCores:43>usedCapacity=1.0, absoluteUsedCapacity=1.0, numApps=5, numContainers=43
2013-08-05 22:22:18,344 INFO org.apache.hadoop.yarn.server.resourcemanager.scheduler.capacity.ParentQueue: assignedContainer queue=root usedCapacity=1.0 absoluteUsedCapacity=1.0 used=<memory:49152, vCores:43> cluster=<memory:49152, vCores:96>
2013-08-05 22:22:18,442 INFO org.apache.hadoop.yarn.server.resourcemanager.rmcontainer.RMContainerImpl: container_1375740621345_0006_01_000031 Container Transitioned from RUNNING to COMPLETED
2013-08-05 22:22:18,442 INFO org.apache.hadoop.yarn.server.resourcemanager.scheduler.common.fica.FiCaSchedulerApp: Completed container: container_1375740621345_0006_01_000031 in state: COMPLETED event:FINISHED
2013-08-05 22:22:18,442 INFO org.apache.hadoop.yarn.server.resourcemanager.RMAuditLogger: USER=ubuntu	OPERATION=AM Released Container	TARGET=SchedulerApp	RESULT=SUCCESS	APPID=application_1375740621345_0006	CONTAINERID=container_1375740621345_0006_01_000031
2013-08-05 22:22:18,442 INFO org.apache.hadoop.yarn.server.resourcemanager.scheduler.common.fica.FiCaSchedulerNode: Released container container_1375740621345_0006_01_000031 of capacity <memory:1024, vCores:1> on host hadoop-100-6:42294, which currently has 6 containers, <memory:7168, vCores:6> used and <memory:1024, vCores:10> available, release resources=true
2013-08-05 22:22:18,442 INFO org.apache.hadoop.yarn.server.resourcemanager.scheduler.capacity.LeafQueue: default used=<memory:48128, vCores:42> numContainers=42 user=ubuntu user-resources=<memory:48128, vCores:42>
2013-08-05 22:22:18,443 INFO org.apache.hadoop.yarn.server.resourcemanager.scheduler.capacity.LeafQueue: completedContainer container=Container: [ContainerId: container_1375740621345_0006_01_000031, NodeId: hadoop-100-6:42294, NodeHttpAddress: hadoop-100-6:8042, Resource: <memory:1024, vCores:1>, Priority: 20, State: NEW, Token: null, Status: container_id {, app_attempt_id {, application_id {, id: 6, cluster_timestamp: 1375740621345, }, attemptId: 1, }, id: 31, }, state: C_COMPLETE, diagnostics: "Container killed by the ApplicationMaster.\n\n", exit_status: 143, ] resource=<memory:1024, vCores:1> queue=default: capacity=1.0, absoluteCapacity=1.0, usedResources=<memory:48128, vCores:42>usedCapacity=0.9791667, absoluteUsedCapacity=0.9791667, numApps=5, numContainers=42 usedCapacity=0.9791667 absoluteUsedCapacity=0.9791667 used=<memory:48128, vCores:42> cluster=<memory:49152, vCores:96>
2013-08-05 22:22:18,443 INFO org.apache.hadoop.yarn.server.resourcemanager.scheduler.capacity.ParentQueue: completedContainer queue=root usedCapacity=0.9791667 absoluteUsedCapacity=0.9791667 used=<memory:48128, vCores:42> cluster=<memory:49152, vCores:96>
2013-08-05 22:22:18,444 INFO org.apache.hadoop.yarn.server.resourcemanager.scheduler.capacity.CapacityScheduler: Application appattempt_1375740621345_0006_000001 released container container_1375740621345_0006_01_000031 on node: host: hadoop-100-6:42294 #containers=6 available=1024 used=7168 with event: FINISHED
2013-08-05 22:22:18,444 INFO org.apache.hadoop.yarn.server.resourcemanager.rmcontainer.RMContainerImpl: container_1375740621345_0007_01_000019 Container Transitioned from NEW to ALLOCATED
2013-08-05 22:22:18,444 INFO org.apache.hadoop.yarn.server.resourcemanager.RMAuditLogger: USER=ubuntu	OPERATION=AM Allocated Container	TARGET=SchedulerApp	RESULT=SUCCESS	APPID=application_1375740621345_0007	CONTAINERID=container_1375740621345_0007_01_000019
2013-08-05 22:22:18,444 INFO org.apache.hadoop.yarn.server.resourcemanager.scheduler.common.fica.FiCaSchedulerNode: Assigned container container_1375740621345_0007_01_000019 of capacity <memory:1024, vCores:1> on host hadoop-100-6:42294, which currently has 7 containers, <memory:8192, vCores:7> used and <memory:0, vCores:9> available
