2013-08-11 09:15:03,426 INFO org.apache.hadoop.yarn.server.resourcemanager.ResourceManager: STARTUP_MSG: 
/************************************************************
STARTUP_MSG: Starting ResourceManager
STARTUP_MSG:   host = hadoop-320-1/192.168.100.4
STARTUP_MSG:   args = []
STARTUP_MSG:   version = 3.0.0-SNAPSHOT
STARTUP_MSG:   build = https://github.com/lalithsuresh/hadoop-common -r 0cb423bd4868928bb06cd93f882bb0913172fd17; compiled by 'lsuresh' on 2013-04-08T15:47Z
STARTUP_MSG:   java = 1.7.0_17
************************************************************/
2013-08-11 09:15:03,441 INFO org.apache.hadoop.yarn.server.resourcemanager.ResourceManager: registered UNIX signal handlers for [TERM, HUP, INT]
2013-08-11 09:15:04,153 INFO org.apache.hadoop.yarn.server.resourcemanager.security.ApplicationTokenSecretManager: Rolling master-key for application-tokens
2013-08-11 09:15:04,181 INFO org.apache.hadoop.yarn.server.resourcemanager.security.RMContainerTokenSecretManager: ContainerTokenKeyRollingInterval: 86400000ms and ContainerTokenKeyActivationDelay: 900000ms
2013-08-11 09:15:04,183 INFO org.apache.hadoop.yarn.service.AbstractService: Service:Dispatcher is inited.
2013-08-11 09:15:04,185 INFO org.apache.hadoop.yarn.event.AsyncDispatcher: Registering class org.apache.hadoop.yarn.server.resourcemanager.recovery.RMStateStoreEventType for class org.apache.hadoop.yarn.server.resourcemanager.recovery.RMStateStore$ForwardingEventHandler
2013-08-11 09:15:04,185 INFO org.apache.hadoop.yarn.service.AbstractService: Service:Dispatcher is started.
2013-08-11 09:15:04,190 INFO org.apache.hadoop.yarn.event.AsyncDispatcher: Registering class org.apache.hadoop.yarn.server.resourcemanager.NodesListManagerEventType for class org.apache.hadoop.yarn.server.resourcemanager.NodesListManager
2013-08-11 09:15:04,190 INFO org.apache.hadoop.yarn.server.resourcemanager.ResourceManager: Using Scheduler: org.apache.hadoop.yarn.server.resourcemanager.scheduler.capacity.CapacityScheduler
2013-08-11 09:15:04,342 INFO org.apache.hadoop.yarn.event.AsyncDispatcher: Registering class org.apache.hadoop.yarn.server.resourcemanager.scheduler.event.SchedulerEventType for class org.apache.hadoop.yarn.server.resourcemanager.ResourceManager$SchedulerEventDispatcher
2013-08-11 09:15:04,343 INFO org.apache.hadoop.yarn.event.AsyncDispatcher: Registering class org.apache.hadoop.yarn.server.resourcemanager.rmapp.RMAppEventType for class org.apache.hadoop.yarn.server.resourcemanager.ResourceManager$ApplicationEventDispatcher
2013-08-11 09:15:04,345 INFO org.apache.hadoop.yarn.event.AsyncDispatcher: Registering class org.apache.hadoop.yarn.server.resourcemanager.rmapp.attempt.RMAppAttemptEventType for class org.apache.hadoop.yarn.server.resourcemanager.ResourceManager$ApplicationAttemptEventDispatcher
2013-08-11 09:15:04,347 INFO org.apache.hadoop.yarn.event.AsyncDispatcher: Registering class org.apache.hadoop.yarn.server.resourcemanager.rmnode.RMNodeEventType for class org.apache.hadoop.yarn.server.resourcemanager.ResourceManager$NodeEventDispatcher
2013-08-11 09:15:04,836 WARN org.apache.hadoop.util.NativeCodeLoader: Unable to load native-hadoop library for your platform... using builtin-java classes where applicable
2013-08-11 09:15:04,883 INFO org.apache.hadoop.yarn.server.resourcemanager.scheduler.capacity.ParentQueue: root, capacity=1.0, asboluteCapacity=1.0, maxCapacity=1.0, asboluteMaxCapacity=1.0, state=RUNNING, acls=ADMINISTER_QUEUE:*SUBMIT_APPLICATIONS:*
2013-08-11 09:15:04,883 INFO org.apache.hadoop.yarn.server.resourcemanager.scheduler.capacity.ParentQueue: Initialized parent-queue root name=root, fullname=root
2013-08-11 09:15:04,900 INFO org.apache.hadoop.yarn.server.resourcemanager.scheduler.capacity.LeafQueue: Initializing default
capacity = 1.0 [= (float) configuredCapacity / 100 ]
asboluteCapacity = 1.0 [= parentAbsoluteCapacity * capacity ]
maxCapacity = 1.0 [= configuredMaxCapacity ]
absoluteMaxCapacity = 1.0 [= 1.0 maximumCapacity undefined, (parentAbsoluteMaxCapacity * maximumCapacity) / 100 otherwise ]
userLimit = 100 [= configuredUserLimit ]
userLimitFactor = 1.0 [= configuredUserLimitFactor ]
maxApplications = 10000 [= configuredMaximumSystemApplicationsPerQueue or (int)(configuredMaximumSystemApplications * absoluteCapacity)]
maxApplicationsPerUser = 10000 [= (int)(maxApplications * (userLimit / 100.0f) * userLimitFactor) ]
maxActiveApplications = 1 [= max((int)ceil((clusterResourceMemory / minimumAllocation) * maxAMResourcePerQueuePercent * absoluteMaxCapacity),1) ]
maxActiveAppsUsingAbsCap = 1 [= max((int)ceil((clusterResourceMemory / minimumAllocation) *maxAMResourcePercent * absoluteCapacity),1) ]
maxActiveApplicationsPerUser = 1 [= max((int)(maxActiveApplications * (userLimit / 100.0f) * userLimitFactor),1) ]
usedCapacity = 0.0 [= usedResourcesMemory / (clusterResourceMemory * absoluteCapacity)]
absoluteUsedCapacity = 0.0 [= usedResourcesMemory / clusterResourceMemory]
maxAMResourcePerQueuePercent = 0.1 [= configuredMaximumAMResourcePercent ]
minimumAllocationFactor = 0.875 [= (float)(maximumAllocationMemory - minimumAllocationMemory) / maximumAllocationMemory ]
numContainers = 0 [= currentNumContainers ]
state = RUNNING [= configuredState ]
acls = ADMINISTER_QUEUE:*SUBMIT_APPLICATIONS:* [= configuredAcls ]

2013-08-11 09:15:04,900 INFO org.apache.hadoop.yarn.server.resourcemanager.scheduler.capacity.CapacityScheduler: Initialized queue: default: capacity=1.0, absoluteCapacity=1.0, usedResources=<memory:0, vCores:0>usedCapacity=0.0, absoluteUsedCapacity=0.0, numApps=0, numContainers=0
2013-08-11 09:15:04,900 INFO org.apache.hadoop.yarn.server.resourcemanager.scheduler.capacity.CapacityScheduler: Initialized queue: root: numChildQueue= 1, capacity=1.0, absoluteCapacity=1.0, usedResources=<memory:0, vCores:0>usedCapacity=0.0, numApps=0, numContainers=0
2013-08-11 09:15:04,901 INFO org.apache.hadoop.yarn.server.resourcemanager.scheduler.capacity.CapacityScheduler: Initialized root queue root: numChildQueue= 1, capacity=1.0, absoluteCapacity=1.0, usedResources=<memory:0, vCores:0>usedCapacity=0.0, numApps=0, numContainers=0
2013-08-11 09:15:04,901 INFO org.apache.hadoop.yarn.server.resourcemanager.scheduler.capacity.CapacityScheduler: Initialized CapacityScheduler with calculator=class org.apache.hadoop.yarn.server.resourcemanager.resource.DefaultResourceCalculator, minimumAllocation=<<memory:1024, vCores:1>>, maximumAllocation=<<memory:8192, vCores:32>>
2013-08-11 09:15:05,347 INFO org.apache.hadoop.yarn.event.AsyncDispatcher: Registering class org.apache.hadoop.yarn.server.resourcemanager.RMAppManagerEventType for class org.apache.hadoop.yarn.server.resourcemanager.RMAppManager
2013-08-11 09:15:05,368 INFO org.apache.hadoop.yarn.event.AsyncDispatcher: Registering class org.apache.hadoop.yarn.server.resourcemanager.amlauncher.AMLauncherEventType for class org.apache.hadoop.yarn.server.resourcemanager.amlauncher.ApplicationMasterLauncher
2013-08-11 09:15:05,440 INFO org.apache.hadoop.yarn.server.resourcemanager.RMNMInfo: Registered RMNMInfo MBean
2013-08-11 09:15:05,440 INFO org.apache.hadoop.yarn.service.AbstractService: Service:Dispatcher is inited.
2013-08-11 09:15:05,440 INFO org.apache.hadoop.yarn.service.AbstractService: Service:org.apache.hadoop.yarn.server.resourcemanager.rmcontainer.ContainerAllocationExpirer is inited.
2013-08-11 09:15:05,440 INFO org.apache.hadoop.yarn.service.AbstractService: Service:AMLivelinessMonitor is inited.
2013-08-11 09:15:05,440 INFO org.apache.hadoop.yarn.service.AbstractService: Service:AMLivelinessMonitor is inited.
2013-08-11 09:15:05,440 INFO org.apache.hadoop.yarn.service.AbstractService: Service:org.apache.hadoop.yarn.server.resourcemanager.security.DelegationTokenRenewer is inited.
2013-08-11 09:15:05,442 INFO org.apache.hadoop.util.HostsFileReader: Refreshing hosts (include/exclude) list
2013-08-11 09:15:05,442 INFO org.apache.hadoop.yarn.service.AbstractService: Service:org.apache.hadoop.yarn.server.resourcemanager.NodesListManager is inited.
2013-08-11 09:15:05,442 INFO org.apache.hadoop.yarn.service.AbstractService: Service:org.apache.hadoop.yarn.server.resourcemanager.ResourceManager$SchedulerEventDispatcher is inited.
2013-08-11 09:15:05,442 INFO org.apache.hadoop.yarn.service.AbstractService: Service:NMLivelinessMonitor is inited.
2013-08-11 09:15:05,448 INFO org.apache.hadoop.yarn.service.AbstractService: Service:org.apache.hadoop.yarn.server.resourcemanager.ResourceTrackerService is inited.
2013-08-11 09:15:05,448 INFO org.apache.hadoop.yarn.service.AbstractService: Service:org.apache.hadoop.yarn.server.resourcemanager.ApplicationMasterService is inited.
2013-08-11 09:15:05,448 INFO org.apache.hadoop.yarn.service.AbstractService: Service:org.apache.hadoop.yarn.server.resourcemanager.ClientRMService is inited.
2013-08-11 09:15:05,448 INFO org.apache.hadoop.yarn.service.AbstractService: Service:org.apache.hadoop.yarn.server.resourcemanager.AdminService is inited.
2013-08-11 09:15:05,448 INFO org.apache.hadoop.yarn.service.AbstractService: Service:org.apache.hadoop.yarn.server.resourcemanager.amlauncher.ApplicationMasterLauncher is inited.
2013-08-11 09:15:05,448 INFO org.apache.hadoop.yarn.service.AbstractService: Service:ResourceManager is inited.
2013-08-11 09:15:05,449 INFO org.apache.hadoop.yarn.server.resourcemanager.security.RMContainerTokenSecretManager: Rolling master-key for container-tokens
2013-08-11 09:15:05,449 INFO org.apache.hadoop.yarn.server.resourcemanager.security.ApplicationTokenSecretManager: Rolling master-key for application-tokens
2013-08-11 09:15:05,590 INFO org.mortbay.log: Logging to org.slf4j.impl.Log4jLoggerAdapter(org.mortbay.log) via org.mortbay.log.Slf4jLog
2013-08-11 09:15:05,694 INFO org.apache.hadoop.http.HttpServer: Added global filter 'safety' (class=org.apache.hadoop.http.HttpServer$QuotingInputFilter)
2013-08-11 09:15:05,698 INFO org.apache.hadoop.http.HttpServer: Added filter static_user_filter (class=org.apache.hadoop.http.lib.StaticUserWebFilter$StaticUserFilter) to context cluster
2013-08-11 09:15:05,699 INFO org.apache.hadoop.http.HttpServer: Added filter static_user_filter (class=org.apache.hadoop.http.lib.StaticUserWebFilter$StaticUserFilter) to context static
2013-08-11 09:15:05,699 INFO org.apache.hadoop.http.HttpServer: Added filter static_user_filter (class=org.apache.hadoop.http.lib.StaticUserWebFilter$StaticUserFilter) to context logs
2013-08-11 09:15:05,706 INFO org.apache.hadoop.http.HttpServer: adding path spec: /cluster
2013-08-11 09:15:05,707 INFO org.apache.hadoop.http.HttpServer: adding path spec: /cluster/*
2013-08-11 09:15:05,707 INFO org.apache.hadoop.http.HttpServer: adding path spec: /ws
2013-08-11 09:15:05,707 INFO org.apache.hadoop.http.HttpServer: adding path spec: /ws/*
2013-08-11 09:15:05,710 INFO org.apache.hadoop.http.HttpServer: Added global filter 'guice' (class=com.google.inject.servlet.GuiceFilter)
2013-08-11 09:15:05,721 INFO org.apache.hadoop.http.HttpServer: Jetty bound to port 8088
2013-08-11 09:15:05,721 INFO org.mortbay.log: jetty-6.1.26
2013-08-11 09:15:05,779 INFO org.mortbay.log: Extract jar:file:/home/ubuntu/hadoop-3.0.0-SNAPSHOT/share/hadoop/yarn/hadoop-yarn-common-3.0.0-SNAPSHOT.jar!/webapps/cluster to /tmp/Jetty_0_0_0_0_8088_cluster____u0rgz3/webapp
2013-08-11 09:15:06,290 INFO org.mortbay.log: Started SelectChannelConnector@0.0.0.0:8088
2013-08-11 09:15:06,290 INFO org.apache.hadoop.yarn.webapp.WebApps: Web app /cluster started at 8088
2013-08-11 09:15:07,246 INFO org.apache.hadoop.yarn.webapp.WebApps: Registered webapp guice modules
2013-08-11 09:15:07,368 INFO org.apache.hadoop.metrics2.impl.MetricsConfig: loaded properties from hadoop-metrics2.properties
2013-08-11 09:15:07,407 INFO org.apache.hadoop.metrics2.impl.MetricsSystemImpl: Scheduled snapshot period at 10 second(s).
2013-08-11 09:15:07,407 INFO org.apache.hadoop.metrics2.impl.MetricsSystemImpl: ResourceManager metrics system started
2013-08-11 09:15:07,424 INFO org.apache.hadoop.security.token.delegation.AbstractDelegationTokenSecretManager: Updating the current master key for generating delegation tokens
2013-08-11 09:15:07,428 INFO org.apache.hadoop.yarn.service.AbstractService: Service:Dispatcher is started.
2013-08-11 09:15:07,428 INFO org.apache.hadoop.security.token.delegation.AbstractDelegationTokenSecretManager: Starting expired delegation token remover thread, tokenRemoverScanInterval=60 min(s)
2013-08-11 09:15:07,428 INFO org.apache.hadoop.security.token.delegation.AbstractDelegationTokenSecretManager: Updating the current master key for generating delegation tokens
2013-08-11 09:15:07,431 INFO org.apache.hadoop.yarn.service.AbstractService: Service:org.apache.hadoop.yarn.server.resourcemanager.rmcontainer.ContainerAllocationExpirer is started.
2013-08-11 09:15:07,431 INFO org.apache.hadoop.yarn.service.AbstractService: Service:AMLivelinessMonitor is started.
2013-08-11 09:15:07,432 INFO org.apache.hadoop.yarn.service.AbstractService: Service:AMLivelinessMonitor is started.
2013-08-11 09:15:07,432 INFO org.apache.hadoop.yarn.service.AbstractService: Service:org.apache.hadoop.yarn.server.resourcemanager.security.DelegationTokenRenewer is started.
2013-08-11 09:15:07,433 INFO org.apache.hadoop.yarn.service.AbstractService: Service:org.apache.hadoop.yarn.server.resourcemanager.NodesListManager is started.
2013-08-11 09:15:07,434 INFO org.apache.hadoop.yarn.service.AbstractService: Service:org.apache.hadoop.yarn.server.resourcemanager.ResourceManager$SchedulerEventDispatcher is started.
2013-08-11 09:15:07,434 INFO org.apache.hadoop.yarn.service.AbstractService: Service:NMLivelinessMonitor is started.
2013-08-11 09:15:07,435 INFO org.apache.hadoop.yarn.service.AbstractService: Service:org.apache.hadoop.yarn.server.resourcemanager.ResourceTrackerService is started.
2013-08-11 09:15:07,518 INFO org.apache.hadoop.ipc.Server: Starting Socket Reader #1 for port 54110
2013-08-11 09:15:07,565 INFO org.apache.hadoop.yarn.factories.impl.pb.RpcServerFactoryPBImpl: Adding protocol org.apache.hadoop.yarn.server.api.ResourceTrackerPB to the server
2013-08-11 09:15:07,567 INFO org.apache.hadoop.ipc.Server: IPC Server Responder: starting
2013-08-11 09:15:07,571 INFO org.apache.hadoop.ipc.Server: IPC Server listener on 54110: starting
2013-08-11 09:15:07,689 INFO org.apache.hadoop.ipc.Server: Starting Socket Reader #1 for port 54112
2013-08-11 09:15:07,704 INFO org.apache.hadoop.yarn.factories.impl.pb.RpcServerFactoryPBImpl: Adding protocol org.apache.hadoop.yarn.api.AMRMProtocolPB to the server
2013-08-11 09:15:07,706 INFO org.apache.hadoop.ipc.Server: IPC Server Responder: starting
2013-08-11 09:15:07,707 INFO org.apache.hadoop.ipc.Server: IPC Server listener on 54112: starting
2013-08-11 09:15:07,752 INFO org.apache.hadoop.yarn.service.AbstractService: Service:org.apache.hadoop.yarn.server.resourcemanager.ApplicationMasterService is started.
2013-08-11 09:15:07,810 INFO org.apache.hadoop.ipc.Server: Starting Socket Reader #1 for port 54111
2013-08-11 09:15:07,816 INFO org.apache.hadoop.yarn.factories.impl.pb.RpcServerFactoryPBImpl: Adding protocol org.apache.hadoop.yarn.api.ClientRMProtocolPB to the server
2013-08-11 09:15:07,817 INFO org.apache.hadoop.ipc.Server: IPC Server Responder: starting
2013-08-11 09:15:07,817 INFO org.apache.hadoop.ipc.Server: IPC Server listener on 54111: starting
2013-08-11 09:15:07,843 INFO org.apache.hadoop.yarn.service.AbstractService: Service:org.apache.hadoop.yarn.server.resourcemanager.ClientRMService is started.
2013-08-11 09:15:07,878 INFO org.apache.hadoop.ipc.Server: Starting Socket Reader #1 for port 8033
2013-08-11 09:15:07,884 INFO org.apache.hadoop.yarn.factories.impl.pb.RpcServerFactoryPBImpl: Adding protocol org.apache.hadoop.yarn.api.RMAdminProtocolPB to the server
2013-08-11 09:15:07,886 INFO org.apache.hadoop.ipc.Server: IPC Server Responder: starting
2013-08-11 09:15:07,887 INFO org.apache.hadoop.yarn.service.AbstractService: Service:org.apache.hadoop.yarn.server.resourcemanager.AdminService is started.
2013-08-11 09:15:07,887 INFO org.apache.hadoop.yarn.service.AbstractService: Service:org.apache.hadoop.yarn.server.resourcemanager.amlauncher.ApplicationMasterLauncher is started.
2013-08-11 09:15:07,886 INFO org.apache.hadoop.ipc.Server: IPC Server listener on 8033: starting
2013-08-11 09:15:07,887 INFO org.apache.hadoop.yarn.service.AbstractService: Service:ResourceManager is started.
2013-08-11 09:15:18,011 INFO org.apache.hadoop.yarn.util.RackResolver: Resolved hadoop-320-4 to /default-rack
2013-08-11 09:15:18,011 INFO org.apache.hadoop.yarn.util.RackResolver: Resolved hadoop-320-3 to /default-rack
2013-08-11 09:15:18,013 INFO org.apache.hadoop.yarn.util.RackResolver: Resolved hadoop-320-2 to /default-rack
2013-08-11 09:15:18,036 INFO org.apache.hadoop.yarn.util.RackResolver: Resolved hadoop-320-5 to /default-rack
2013-08-11 09:15:18,037 INFO org.apache.hadoop.yarn.server.resourcemanager.ResourceTrackerService: NodeManager from node hadoop-320-3(cmPort: 47015 httpPort: 8042) registered with capability: <memory:8192, vCores:16>, assigned nodeId hadoop-320-3:47015
2013-08-11 09:15:18,037 INFO org.apache.hadoop.yarn.server.resourcemanager.ResourceTrackerService: NodeManager from node hadoop-320-5(cmPort: 36272 httpPort: 8042) registered with capability: <memory:8192, vCores:16>, assigned nodeId hadoop-320-5:36272
2013-08-11 09:15:18,037 INFO org.apache.hadoop.yarn.server.resourcemanager.ResourceTrackerService: NodeManager from node hadoop-320-2(cmPort: 53179 httpPort: 8042) registered with capability: <memory:8192, vCores:16>, assigned nodeId hadoop-320-2:53179
2013-08-11 09:15:18,041 INFO org.apache.hadoop.yarn.server.resourcemanager.ResourceTrackerService: NodeManager from node hadoop-320-4(cmPort: 39920 httpPort: 8042) registered with capability: <memory:8192, vCores:16>, assigned nodeId hadoop-320-4:39920
2013-08-11 09:15:18,054 INFO org.apache.hadoop.yarn.server.resourcemanager.rmnode.RMNodeImpl: hadoop-320-4:39920 Node Transitioned from NEW to RUNNING
2013-08-11 09:15:18,056 INFO org.apache.hadoop.yarn.server.resourcemanager.rmnode.RMNodeImpl: hadoop-320-3:47015 Node Transitioned from NEW to RUNNING
2013-08-11 09:15:18,057 INFO org.apache.hadoop.yarn.server.resourcemanager.rmnode.RMNodeImpl: hadoop-320-5:36272 Node Transitioned from NEW to RUNNING
2013-08-11 09:15:18,058 INFO org.apache.hadoop.yarn.server.resourcemanager.rmnode.RMNodeImpl: hadoop-320-2:53179 Node Transitioned from NEW to RUNNING
2013-08-11 09:15:18,064 INFO org.apache.hadoop.yarn.server.resourcemanager.scheduler.capacity.CapacityScheduler: Added node hadoop-320-4:39920 clusterResource: <memory:8192, vCores:16>
2013-08-11 09:15:18,065 INFO org.apache.hadoop.yarn.server.resourcemanager.scheduler.capacity.CapacityScheduler: Added node hadoop-320-3:47015 clusterResource: <memory:16384, vCores:32>
2013-08-11 09:15:18,065 INFO org.apache.hadoop.yarn.server.resourcemanager.scheduler.capacity.CapacityScheduler: Added node hadoop-320-5:36272 clusterResource: <memory:24576, vCores:48>
2013-08-11 09:15:18,066 INFO org.apache.hadoop.yarn.server.resourcemanager.scheduler.capacity.CapacityScheduler: Added node hadoop-320-2:53179 clusterResource: <memory:32768, vCores:64>
2013-08-11 09:15:18,096 INFO org.apache.hadoop.yarn.util.RackResolver: Resolved hadoop-320-6 to /default-rack
2013-08-11 09:15:18,096 INFO org.apache.hadoop.yarn.server.resourcemanager.ResourceTrackerService: NodeManager from node hadoop-320-6(cmPort: 38980 httpPort: 8042) registered with capability: <memory:8192, vCores:16>, assigned nodeId hadoop-320-6:38980
2013-08-11 09:15:18,097 INFO org.apache.hadoop.yarn.server.resourcemanager.rmnode.RMNodeImpl: hadoop-320-6:38980 Node Transitioned from NEW to RUNNING
2013-08-11 09:15:18,098 INFO org.apache.hadoop.yarn.server.resourcemanager.scheduler.capacity.CapacityScheduler: Added node hadoop-320-6:38980 clusterResource: <memory:40960, vCores:80>
2013-08-11 09:15:23,920 INFO org.apache.hadoop.yarn.server.resourcemanager.ClientRMService: Allocated new applicationId: 1
2013-08-11 09:15:27,361 INFO org.apache.hadoop.yarn.server.resourcemanager.ClientRMService: Storing Application with id application_1376212503271_0001
2013-08-11 09:15:27,365 INFO org.apache.hadoop.yarn.server.resourcemanager.recovery.RMStateStore: Storing info for app: application_1376212503271_0001
2013-08-11 09:15:27,365 INFO org.apache.hadoop.yarn.server.resourcemanager.ClientRMService: Application with id 1 submitted by user ubuntu
2013-08-11 09:15:27,369 INFO org.apache.hadoop.yarn.server.resourcemanager.RMAuditLogger: USER=ubuntu	IP=192.168.100.4	OPERATION=Submit Application Request	TARGET=ClientRMService	RESULT=SUCCESS	APPID=application_1376212503271_0001
2013-08-11 09:15:27,419 INFO org.apache.hadoop.yarn.server.resourcemanager.rmapp.RMAppImpl: application_1376212503271_0001 State change from NEW to SUBMITTED
2013-08-11 09:15:27,420 INFO org.apache.hadoop.yarn.server.resourcemanager.ApplicationMasterService: Registering appattempt_1376212503271_0001_000001
2013-08-11 09:15:27,421 INFO org.apache.hadoop.yarn.server.resourcemanager.rmapp.attempt.RMAppAttemptImpl: appattempt_1376212503271_0001_000001 State change from NEW to SUBMITTED
2013-08-11 09:15:27,457 INFO org.apache.hadoop.yarn.server.resourcemanager.scheduler.capacity.LeafQueue: Application application_1376212503271_0001 from user: ubuntu activated in queue: default
2013-08-11 09:15:27,458 INFO org.apache.hadoop.yarn.server.resourcemanager.scheduler.capacity.LeafQueue: Application added - appId: application_1376212503271_0001 user: org.apache.hadoop.yarn.server.resourcemanager.scheduler.capacity.LeafQueue$User@eaca568, leaf-queue: default #user-pending-applications: 0 #user-active-applications: 1 #queue-pending-applications: 0 #queue-active-applications: 1
2013-08-11 09:15:27,458 INFO org.apache.hadoop.yarn.server.resourcemanager.scheduler.capacity.ParentQueue: Application added - appId: application_1376212503271_0001 user: ubuntu leaf-queue of parent: root #applications: 1
2013-08-11 09:15:27,458 INFO org.apache.hadoop.yarn.server.resourcemanager.scheduler.capacity.CapacityScheduler: Application Submission: appattempt_1376212503271_0001_000001, user: ubuntu queue: default: capacity=1.0, absoluteCapacity=1.0, usedResources=<memory:0, vCores:0>usedCapacity=0.0, absoluteUsedCapacity=0.0, numApps=1, numContainers=0, currently active: 1
2013-08-11 09:15:27,464 INFO org.apache.hadoop.yarn.server.resourcemanager.rmapp.attempt.RMAppAttemptImpl: appattempt_1376212503271_0001_000001 State change from SUBMITTED to SCHEDULED
2013-08-11 09:15:27,465 INFO org.apache.hadoop.yarn.server.resourcemanager.rmapp.RMAppImpl: application_1376212503271_0001 State change from SUBMITTED to ACCEPTED
2013-08-11 09:15:27,921 INFO org.apache.hadoop.yarn.util.RackResolver: Resolved hadoop-320-7 to /default-rack
2013-08-11 09:15:27,921 INFO org.apache.hadoop.yarn.server.resourcemanager.ResourceTrackerService: NodeManager from node hadoop-320-7(cmPort: 48037 httpPort: 8042) registered with capability: <memory:8192, vCores:16>, assigned nodeId hadoop-320-7:48037
2013-08-11 09:15:27,921 INFO org.apache.hadoop.yarn.server.resourcemanager.rmnode.RMNodeImpl: hadoop-320-7:48037 Node Transitioned from NEW to RUNNING
2013-08-11 09:15:27,923 INFO org.apache.hadoop.yarn.server.resourcemanager.scheduler.capacity.CapacityScheduler: Added node hadoop-320-7:48037 clusterResource: <memory:49152, vCores:96>
2013-08-11 09:15:28,023 INFO org.apache.hadoop.yarn.server.resourcemanager.rmcontainer.RMContainerImpl: container_1376212503271_0001_01_000001 Container Transitioned from NEW to ALLOCATED
2013-08-11 09:15:28,024 INFO org.apache.hadoop.yarn.server.resourcemanager.RMAuditLogger: USER=ubuntu	OPERATION=AM Allocated Container	TARGET=SchedulerApp	RESULT=SUCCESS	APPID=application_1376212503271_0001	CONTAINERID=container_1376212503271_0001_01_000001
2013-08-11 09:15:28,025 INFO org.apache.hadoop.yarn.server.resourcemanager.scheduler.common.fica.FiCaSchedulerNode: Assigned container container_1376212503271_0001_01_000001 of capacity <memory:2048, vCores:1> on host hadoop-320-7:48037, which currently has 1 containers, <memory:2048, vCores:1> used and <memory:6144, vCores:15> available
2013-08-11 09:15:28,035 INFO org.apache.hadoop.yarn.server.resourcemanager.scheduler.capacity.LeafQueue: assignedContainer application=application_1376212503271_0001 container=Container: [ContainerId: container_1376212503271_0001_01_000001, NodeId: hadoop-320-7:48037, NodeHttpAddress: hadoop-320-7:8042, Resource: <memory:2048, vCores:1>, Priority: 0, State: NEW, Token: null, Status: container_id {, app_attempt_id {, application_id {, id: 1, cluster_timestamp: 1376212503271, }, attemptId: 1, }, id: 1, }, state: C_NEW, ] containerId=container_1376212503271_0001_01_000001 queue=default: capacity=1.0, absoluteCapacity=1.0, usedResources=<memory:0, vCores:0>usedCapacity=0.0, absoluteUsedCapacity=0.0, numApps=1, numContainers=0 usedCapacity=0.0 absoluteUsedCapacity=0.0 used=<memory:0, vCores:0> cluster=<memory:49152, vCores:96>
2013-08-11 09:15:28,036 INFO org.apache.hadoop.yarn.server.resourcemanager.scheduler.capacity.ParentQueue: Re-sorting queues since queue: root.default stats: default: capacity=1.0, absoluteCapacity=1.0, usedResources=<memory:2048, vCores:1>usedCapacity=0.041666668, absoluteUsedCapacity=0.041666668, numApps=1, numContainers=1
2013-08-11 09:15:28,038 INFO org.apache.hadoop.yarn.server.resourcemanager.scheduler.capacity.ParentQueue: assignedContainer queue=root usedCapacity=0.041666668 absoluteUsedCapacity=0.041666668 used=<memory:2048, vCores:1> cluster=<memory:49152, vCores:96>
2013-08-11 09:15:28,040 INFO org.apache.hadoop.yarn.server.resourcemanager.rmcontainer.RMContainerImpl: container_1376212503271_0001_01_000001 Container Transitioned from ALLOCATED to ACQUIRED
2013-08-11 09:15:28,043 INFO org.apache.hadoop.yarn.server.resourcemanager.rmapp.attempt.RMAppAttemptImpl: Storing attempt: AppId: application_1376212503271_0001 AttemptId: appattempt_1376212503271_0001_000001 MasterContainer: Container: [ContainerId: container_1376212503271_0001_01_000001, NodeId: hadoop-320-7:48037, NodeHttpAddress: hadoop-320-7:8042, Resource: <memory:2048, vCores:1>, Priority: 0, State: NEW, Token: null, Status: container_id {, app_attempt_id {, application_id {, id: 1, cluster_timestamp: 1376212503271, }, attemptId: 1, }, id: 1, }, state: C_NEW, ]
2013-08-11 09:15:28,046 INFO org.apache.hadoop.yarn.server.resourcemanager.rmapp.attempt.RMAppAttemptImpl: appattempt_1376212503271_0001_000001 State change from SCHEDULED to ALLOCATED_SAVING
2013-08-11 09:15:28,050 INFO org.apache.hadoop.yarn.server.resourcemanager.recovery.RMStateStore: Storing info for attempt: appattempt_1376212503271_0001_000001
2013-08-11 09:15:28,054 INFO org.apache.hadoop.yarn.server.resourcemanager.rmapp.attempt.RMAppAttemptImpl: appattempt_1376212503271_0001_000001 State change from ALLOCATED_SAVING to ALLOCATED
2013-08-11 09:15:28,061 INFO org.apache.hadoop.yarn.server.resourcemanager.amlauncher.AMLauncher: Launching masterappattempt_1376212503271_0001_000001
2013-08-11 09:15:28,106 INFO org.apache.hadoop.yarn.server.resourcemanager.amlauncher.AMLauncher: Setting up container Container: [ContainerId: container_1376212503271_0001_01_000001, NodeId: hadoop-320-7:48037, NodeHttpAddress: hadoop-320-7:8042, Resource: <memory:2048, vCores:1>, Priority: 0, State: NEW, Token: null, Status: container_id {, app_attempt_id {, application_id {, id: 1, cluster_timestamp: 1376212503271, }, attemptId: 1, }, id: 1, }, state: C_NEW, ] for AM appattempt_1376212503271_0001_000001
2013-08-11 09:15:28,107 INFO org.apache.hadoop.yarn.server.resourcemanager.amlauncher.AMLauncher: Command to launch container container_1376212503271_0001_01_000001 : $JAVA_HOME/bin/java -Dlog4j.configuration=container-log4j.properties -Dyarn.app.mapreduce.container.log.dir=<LOG_DIR> -Dyarn.app.mapreduce.container.log.filesize=0 -Dhadoop.root.logger=INFO,CLA  -Xmx1024m org.apache.hadoop.mapreduce.v2.app.MRAppMaster 1><LOG_DIR>/stdout 2><LOG_DIR>/stderr 
2013-08-11 09:15:29,041 INFO org.apache.hadoop.yarn.server.resourcemanager.amlauncher.AMLauncher: Done launching container Container: [ContainerId: container_1376212503271_0001_01_000001, NodeId: hadoop-320-7:48037, NodeHttpAddress: hadoop-320-7:8042, Resource: <memory:2048, vCores:1>, Priority: 0, State: NEW, Token: null, Status: container_id {, app_attempt_id {, application_id {, id: 1, cluster_timestamp: 1376212503271, }, attemptId: 1, }, id: 1, }, state: C_NEW, ] for AM appattempt_1376212503271_0001_000001
2013-08-11 09:15:29,042 INFO org.apache.hadoop.yarn.server.resourcemanager.rmapp.attempt.RMAppAttemptImpl: appattempt_1376212503271_0001_000001 State change from ALLOCATED to LAUNCHED
2013-08-11 09:15:29,048 INFO org.apache.hadoop.yarn.server.resourcemanager.rmcontainer.RMContainerImpl: container_1376212503271_0001_01_000001 Container Transitioned from ACQUIRED to RUNNING
2013-08-11 09:15:37,851 INFO org.apache.hadoop.yarn.server.resourcemanager.ApplicationMasterService: AM registration appattempt_1376212503271_0001_000001
2013-08-11 09:15:37,855 INFO org.apache.hadoop.yarn.server.resourcemanager.RMAuditLogger: USER=ubuntu	IP=192.168.100.22	OPERATION=Register App Master	TARGET=ApplicationMasterService	RESULT=SUCCESS	APPID=application_1376212503271_0001	APPATTEMPTID=appattempt_1376212503271_0001_000001
2013-08-11 09:15:37,858 INFO org.apache.hadoop.yarn.server.resourcemanager.rmapp.attempt.RMAppAttemptImpl: appattempt_1376212503271_0001_000001 State change from LAUNCHED to RUNNING
2013-08-11 09:15:37,859 INFO org.apache.hadoop.yarn.server.resourcemanager.rmapp.RMAppImpl: application_1376212503271_0001 State change from ACCEPTED to RUNNING
2013-08-11 09:15:39,107 INFO org.apache.hadoop.yarn.server.resourcemanager.rmcontainer.RMContainerImpl: container_1376212503271_0001_01_000002 Container Transitioned from NEW to ALLOCATED
2013-08-11 09:15:39,108 INFO org.apache.hadoop.yarn.server.resourcemanager.RMAuditLogger: USER=ubuntu	OPERATION=AM Allocated Container	TARGET=SchedulerApp	RESULT=SUCCESS	APPID=application_1376212503271_0001	CONTAINERID=container_1376212503271_0001_01_000002
2013-08-11 09:15:39,108 INFO org.apache.hadoop.yarn.server.resourcemanager.scheduler.common.fica.FiCaSchedulerNode: Assigned container container_1376212503271_0001_01_000002 of capacity <memory:1024, vCores:1> on host hadoop-320-7:48037, which currently has 2 containers, <memory:3072, vCores:2> used and <memory:5120, vCores:14> available
2013-08-11 09:15:39,110 INFO org.apache.hadoop.yarn.server.resourcemanager.scheduler.capacity.LeafQueue: assignedContainer application=application_1376212503271_0001 container=Container: [ContainerId: container_1376212503271_0001_01_000002, NodeId: hadoop-320-7:48037, NodeHttpAddress: hadoop-320-7:8042, Resource: <memory:1024, vCores:1>, Priority: 20, State: NEW, Token: null, Status: container_id {, app_attempt_id {, application_id {, id: 1, cluster_timestamp: 1376212503271, }, attemptId: 1, }, id: 2, }, state: C_NEW, ] containerId=container_1376212503271_0001_01_000002 queue=default: capacity=1.0, absoluteCapacity=1.0, usedResources=<memory:2048, vCores:1>usedCapacity=0.041666668, absoluteUsedCapacity=0.041666668, numApps=1, numContainers=1 usedCapacity=0.041666668 absoluteUsedCapacity=0.041666668 used=<memory:2048, vCores:1> cluster=<memory:49152, vCores:96>
2013-08-11 09:15:39,110 INFO org.apache.hadoop.yarn.server.resourcemanager.scheduler.capacity.ParentQueue: Re-sorting queues since queue: root.default stats: default: capacity=1.0, absoluteCapacity=1.0, usedResources=<memory:3072, vCores:2>usedCapacity=0.0625, absoluteUsedCapacity=0.0625, numApps=1, numContainers=2
2013-08-11 09:15:39,110 INFO org.apache.hadoop.yarn.server.resourcemanager.scheduler.capacity.ParentQueue: assignedContainer queue=root usedCapacity=0.0625 absoluteUsedCapacity=0.0625 used=<memory:3072, vCores:2> cluster=<memory:49152, vCores:96>
2013-08-11 09:15:39,243 INFO org.apache.hadoop.yarn.server.resourcemanager.rmcontainer.RMContainerImpl: container_1376212503271_0001_01_000003 Container Transitioned from NEW to ALLOCATED
2013-08-11 09:15:39,243 INFO org.apache.hadoop.yarn.server.resourcemanager.RMAuditLogger: USER=ubuntu	OPERATION=AM Allocated Container	TARGET=SchedulerApp	RESULT=SUCCESS	APPID=application_1376212503271_0001	CONTAINERID=container_1376212503271_0001_01_000003
2013-08-11 09:15:39,243 INFO org.apache.hadoop.yarn.server.resourcemanager.scheduler.common.fica.FiCaSchedulerNode: Assigned container container_1376212503271_0001_01_000003 of capacity <memory:1024, vCores:1> on host hadoop-320-3:47015, which currently has 1 containers, <memory:1024, vCores:1> used and <memory:7168, vCores:15> available
2013-08-11 09:15:39,245 INFO org.apache.hadoop.yarn.server.resourcemanager.scheduler.capacity.LeafQueue: assignedContainer application=application_1376212503271_0001 container=Container: [ContainerId: container_1376212503271_0001_01_000003, NodeId: hadoop-320-3:47015, NodeHttpAddress: hadoop-320-3:8042, Resource: <memory:1024, vCores:1>, Priority: 20, State: NEW, Token: null, Status: container_id {, app_attempt_id {, application_id {, id: 1, cluster_timestamp: 1376212503271, }, attemptId: 1, }, id: 3, }, state: C_NEW, ] containerId=container_1376212503271_0001_01_000003 queue=default: capacity=1.0, absoluteCapacity=1.0, usedResources=<memory:3072, vCores:2>usedCapacity=0.0625, absoluteUsedCapacity=0.0625, numApps=1, numContainers=2 usedCapacity=0.0625 absoluteUsedCapacity=0.0625 used=<memory:3072, vCores:2> cluster=<memory:49152, vCores:96>
2013-08-11 09:15:39,245 INFO org.apache.hadoop.yarn.server.resourcemanager.scheduler.capacity.ParentQueue: Re-sorting queues since queue: root.default stats: default: capacity=1.0, absoluteCapacity=1.0, usedResources=<memory:4096, vCores:3>usedCapacity=0.083333336, absoluteUsedCapacity=0.083333336, numApps=1, numContainers=3
2013-08-11 09:15:39,245 INFO org.apache.hadoop.yarn.server.resourcemanager.scheduler.capacity.ParentQueue: assignedContainer queue=root usedCapacity=0.083333336 absoluteUsedCapacity=0.083333336 used=<memory:4096, vCores:3> cluster=<memory:49152, vCores:96>
2013-08-11 09:15:39,938 INFO org.apache.hadoop.yarn.server.resourcemanager.rmcontainer.RMContainerImpl: container_1376212503271_0001_01_000002 Container Transitioned from ALLOCATED to ACQUIRED
2013-08-11 09:15:39,941 INFO org.apache.hadoop.yarn.server.resourcemanager.rmcontainer.RMContainerImpl: container_1376212503271_0001_01_000003 Container Transitioned from ALLOCATED to ACQUIRED
2013-08-11 09:15:40,985 INFO org.apache.hadoop.yarn.server.resourcemanager.scheduler.AppSchedulingInfo: checking for deactivate... 
2013-08-11 09:15:41,121 INFO org.apache.hadoop.yarn.server.resourcemanager.rmcontainer.RMContainerImpl: container_1376212503271_0001_01_000002 Container Transitioned from ACQUIRED to RUNNING
2013-08-11 09:15:41,409 INFO org.apache.hadoop.yarn.server.resourcemanager.rmcontainer.RMContainerImpl: container_1376212503271_0001_01_000003 Container Transitioned from ACQUIRED to RUNNING
2013-08-11 09:18:25,359 INFO org.apache.hadoop.yarn.server.resourcemanager.rmcontainer.RMContainerImpl: container_1376212503271_0001_01_000002 Container Transitioned from RUNNING to COMPLETED
2013-08-11 09:18:25,360 INFO org.apache.hadoop.yarn.server.resourcemanager.scheduler.common.fica.FiCaSchedulerApp: Completed container: container_1376212503271_0001_01_000002 in state: COMPLETED event:FINISHED
2013-08-11 09:18:25,362 INFO org.apache.hadoop.yarn.server.resourcemanager.RMAuditLogger: USER=ubuntu	OPERATION=AM Released Container	TARGET=SchedulerApp	RESULT=SUCCESS	APPID=application_1376212503271_0001	CONTAINERID=container_1376212503271_0001_01_000002
2013-08-11 09:18:25,362 INFO org.apache.hadoop.yarn.server.resourcemanager.scheduler.common.fica.FiCaSchedulerNode: Released container container_1376212503271_0001_01_000002 of capacity <memory:1024, vCores:1> on host hadoop-320-7:48037, which currently has 1 containers, <memory:2048, vCores:1> used and <memory:6144, vCores:15> available, release resources=true
2013-08-11 09:18:25,363 INFO org.apache.hadoop.yarn.server.resourcemanager.scheduler.capacity.LeafQueue: default used=<memory:3072, vCores:2> numContainers=2 user=ubuntu user-resources=<memory:3072, vCores:2>
2013-08-11 09:18:25,365 INFO org.apache.hadoop.yarn.server.resourcemanager.scheduler.capacity.LeafQueue: completedContainer container=Container: [ContainerId: container_1376212503271_0001_01_000002, NodeId: hadoop-320-7:48037, NodeHttpAddress: hadoop-320-7:8042, Resource: <memory:1024, vCores:1>, Priority: 20, State: NEW, Token: null, Status: container_id {, app_attempt_id {, application_id {, id: 1, cluster_timestamp: 1376212503271, }, attemptId: 1, }, id: 2, }, state: C_COMPLETE, diagnostics: "Container killed by the ApplicationMaster.\n\n", exit_status: 143, ] resource=<memory:1024, vCores:1> queue=default: capacity=1.0, absoluteCapacity=1.0, usedResources=<memory:3072, vCores:2>usedCapacity=0.0625, absoluteUsedCapacity=0.0625, numApps=1, numContainers=2 usedCapacity=0.0625 absoluteUsedCapacity=0.0625 used=<memory:3072, vCores:2> cluster=<memory:49152, vCores:96>
2013-08-11 09:18:25,365 INFO org.apache.hadoop.yarn.server.resourcemanager.scheduler.capacity.ParentQueue: completedContainer queue=root usedCapacity=0.0625 absoluteUsedCapacity=0.0625 used=<memory:3072, vCores:2> cluster=<memory:49152, vCores:96>
2013-08-11 09:18:25,365 INFO org.apache.hadoop.yarn.server.resourcemanager.scheduler.capacity.CapacityScheduler: Application appattempt_1376212503271_0001_000001 released container container_1376212503271_0001_01_000002 on node: host: hadoop-320-7:48037 #containers=1 available=6144 used=2048 with event: FINISHED
2013-08-11 09:18:27,007 INFO org.apache.hadoop.yarn.server.resourcemanager.rmcontainer.RMContainerImpl: container_1376212503271_0001_01_000003 Container Transitioned from RUNNING to COMPLETED
2013-08-11 09:18:27,007 INFO org.apache.hadoop.yarn.server.resourcemanager.scheduler.common.fica.FiCaSchedulerApp: Completed container: container_1376212503271_0001_01_000003 in state: COMPLETED event:FINISHED
2013-08-11 09:18:27,007 INFO org.apache.hadoop.yarn.server.resourcemanager.RMAuditLogger: USER=ubuntu	OPERATION=AM Released Container	TARGET=SchedulerApp	RESULT=SUCCESS	APPID=application_1376212503271_0001	CONTAINERID=container_1376212503271_0001_01_000003
2013-08-11 09:18:27,007 INFO org.apache.hadoop.yarn.server.resourcemanager.scheduler.common.fica.FiCaSchedulerNode: Released container container_1376212503271_0001_01_000003 of capacity <memory:1024, vCores:1> on host hadoop-320-3:47015, which currently has 0 containers, <memory:0, vCores:0> used and <memory:8192, vCores:16> available, release resources=true
2013-08-11 09:18:27,007 INFO org.apache.hadoop.yarn.server.resourcemanager.scheduler.capacity.LeafQueue: default used=<memory:2048, vCores:1> numContainers=1 user=ubuntu user-resources=<memory:2048, vCores:1>
2013-08-11 09:18:27,009 INFO org.apache.hadoop.yarn.server.resourcemanager.scheduler.capacity.LeafQueue: completedContainer container=Container: [ContainerId: container_1376212503271_0001_01_000003, NodeId: hadoop-320-3:47015, NodeHttpAddress: hadoop-320-3:8042, Resource: <memory:1024, vCores:1>, Priority: 20, State: NEW, Token: null, Status: container_id {, app_attempt_id {, application_id {, id: 1, cluster_timestamp: 1376212503271, }, attemptId: 1, }, id: 3, }, state: C_COMPLETE, diagnostics: "Container killed by the ApplicationMaster.\n\n", exit_status: 143, ] resource=<memory:1024, vCores:1> queue=default: capacity=1.0, absoluteCapacity=1.0, usedResources=<memory:2048, vCores:1>usedCapacity=0.041666668, absoluteUsedCapacity=0.041666668, numApps=1, numContainers=1 usedCapacity=0.041666668 absoluteUsedCapacity=0.041666668 used=<memory:2048, vCores:1> cluster=<memory:49152, vCores:96>
2013-08-11 09:18:27,010 INFO org.apache.hadoop.yarn.server.resourcemanager.scheduler.capacity.ParentQueue: completedContainer queue=root usedCapacity=0.041666668 absoluteUsedCapacity=0.041666668 used=<memory:2048, vCores:1> cluster=<memory:49152, vCores:96>
2013-08-11 09:18:27,010 INFO org.apache.hadoop.yarn.server.resourcemanager.scheduler.capacity.CapacityScheduler: Application appattempt_1376212503271_0001_000001 released container container_1376212503271_0001_01_000003 on node: host: hadoop-320-3:47015 #containers=0 available=8192 used=0 with event: FINISHED
2013-08-11 09:18:31,232 INFO org.apache.hadoop.yarn.server.resourcemanager.rmapp.attempt.RMAppAttemptImpl: appattempt_1376212503271_0001_000001 State change from RUNNING to FINISHING
2013-08-11 09:18:31,233 INFO org.apache.hadoop.yarn.server.resourcemanager.rmapp.RMAppImpl: application_1376212503271_0001 State change from RUNNING to FINISHING
2013-08-11 09:18:31,658 INFO org.apache.hadoop.yarn.server.resourcemanager.rmcontainer.RMContainerImpl: container_1376212503271_0001_01_000001 Container Transitioned from RUNNING to COMPLETED
2013-08-11 09:18:31,658 INFO org.apache.hadoop.yarn.server.resourcemanager.scheduler.common.fica.FiCaSchedulerApp: Completed container: container_1376212503271_0001_01_000001 in state: COMPLETED event:FINISHED
2013-08-11 09:18:31,658 INFO org.apache.hadoop.yarn.server.resourcemanager.RMAuditLogger: USER=ubuntu	OPERATION=AM Released Container	TARGET=SchedulerApp	RESULT=SUCCESS	APPID=application_1376212503271_0001	CONTAINERID=container_1376212503271_0001_01_000001
2013-08-11 09:18:31,659 INFO org.apache.hadoop.yarn.server.resourcemanager.scheduler.common.fica.FiCaSchedulerNode: Released container container_1376212503271_0001_01_000001 of capacity <memory:2048, vCores:1> on host hadoop-320-7:48037, which currently has 0 containers, <memory:0, vCores:0> used and <memory:8192, vCores:16> available, release resources=true
2013-08-11 09:18:31,659 INFO org.apache.hadoop.yarn.server.resourcemanager.scheduler.capacity.LeafQueue: default used=<memory:0, vCores:0> numContainers=0 user=ubuntu user-resources=<memory:0, vCores:0>
2013-08-11 09:18:31,661 INFO org.apache.hadoop.yarn.server.resourcemanager.scheduler.capacity.LeafQueue: completedContainer container=Container: [ContainerId: container_1376212503271_0001_01_000001, NodeId: hadoop-320-7:48037, NodeHttpAddress: hadoop-320-7:8042, Resource: <memory:2048, vCores:1>, Priority: 0, State: NEW, Token: null, Status: container_id {, app_attempt_id {, application_id {, id: 1, cluster_timestamp: 1376212503271, }, attemptId: 1, }, id: 1, }, state: C_COMPLETE, diagnostics: "", exit_status: 0, ] resource=<memory:2048, vCores:1> queue=default: capacity=1.0, absoluteCapacity=1.0, usedResources=<memory:0, vCores:0>usedCapacity=0.0, absoluteUsedCapacity=0.0, numApps=1, numContainers=0 usedCapacity=0.0 absoluteUsedCapacity=0.0 used=<memory:0, vCores:0> cluster=<memory:49152, vCores:96>
2013-08-11 09:18:31,661 INFO org.apache.hadoop.yarn.server.resourcemanager.scheduler.capacity.ParentQueue: completedContainer queue=root usedCapacity=0.0 absoluteUsedCapacity=0.0 used=<memory:0, vCores:0> cluster=<memory:49152, vCores:96>
2013-08-11 09:18:31,661 INFO org.apache.hadoop.yarn.server.resourcemanager.scheduler.capacity.CapacityScheduler: Application appattempt_1376212503271_0001_000001 released container container_1376212503271_0001_01_000001 on node: host: hadoop-320-7:48037 #containers=0 available=8192 used=0 with event: FINISHED
2013-08-11 09:18:31,661 INFO org.apache.hadoop.yarn.server.resourcemanager.rmapp.attempt.RMAppAttemptImpl: appattempt_1376212503271_0001_000001 State change from FINISHING to FINISHED
2013-08-11 09:18:31,664 INFO org.apache.hadoop.yarn.server.resourcemanager.rmapp.RMAppImpl: application_1376212503271_0001 State change from FINISHING to FINISHED
2013-08-11 09:18:31,664 INFO org.apache.hadoop.yarn.server.resourcemanager.scheduler.capacity.CapacityScheduler: Application appattempt_1376212503271_0001_000001 is done. finalState=FINISHED
2013-08-11 09:18:31,664 INFO org.apache.hadoop.yarn.server.resourcemanager.RMAuditLogger: USER=ubuntu	OPERATION=Application Finished - Succeeded	TARGET=RMAppManager	RESULT=SUCCESS	APPID=application_1376212503271_0001
2013-08-11 09:18:31,676 INFO org.apache.hadoop.yarn.server.resourcemanager.recovery.RMStateStore: Removing info for app: application_1376212503271_0001
2013-08-11 09:18:31,666 INFO org.apache.hadoop.yarn.server.resourcemanager.scheduler.AppSchedulingInfo: Application application_1376212503271_0001 requests cleared
2013-08-11 09:18:31,678 INFO org.apache.hadoop.yarn.server.resourcemanager.scheduler.capacity.LeafQueue: Application removed - appId: application_1376212503271_0001 user: ubuntu queue: default #user-pending-applications: 0 #user-active-applications: 0 #queue-pending-applications: 0 #queue-active-applications: 0
2013-08-11 09:18:31,678 INFO org.apache.hadoop.yarn.server.resourcemanager.scheduler.capacity.ParentQueue: Application removed - appId: application_1376212503271_0001 user: ubuntu leaf-queue of parent: root #applications: 0
2013-08-11 09:18:31,680 INFO org.apache.hadoop.yarn.server.resourcemanager.RMAppManager$ApplicationSummary: appId=application_1376212503271_0001,name=TeraGen,user=ubuntu,queue=default,state=FINISHED,trackingUrl=hadoop-320-1.novalocal:8088/proxy/application_1376212503271_0001/jobhistory/job/job_1376212503271_0001,appMasterHost=hadoop-320-7,startTime=1376212527353,finishTime=1376212711233
2013-08-11 09:18:31,674 INFO org.apache.hadoop.yarn.server.resourcemanager.amlauncher.AMLauncher: Cleaning master appattempt_1376212503271_0001_000001
2013-08-11 09:18:31,961 INFO org.apache.hadoop.yarn.server.resourcemanager.ClientRMService: Allocated new applicationId: 2
2013-08-11 09:18:33,978 INFO org.apache.hadoop.yarn.server.resourcemanager.ClientRMService: Storing Application with id application_1376212503271_0002
2013-08-11 09:18:33,978 INFO org.apache.hadoop.yarn.server.resourcemanager.recovery.RMStateStore: Storing info for app: application_1376212503271_0002
2013-08-11 09:18:33,978 INFO org.apache.hadoop.yarn.server.resourcemanager.ClientRMService: Application with id 2 submitted by user ubuntu
2013-08-11 09:18:33,978 INFO org.apache.hadoop.yarn.server.resourcemanager.RMAuditLogger: USER=ubuntu	IP=192.168.100.4	OPERATION=Submit Application Request	TARGET=ClientRMService	RESULT=SUCCESS	APPID=application_1376212503271_0002
2013-08-11 09:18:33,980 INFO org.apache.hadoop.yarn.server.resourcemanager.rmapp.RMAppImpl: application_1376212503271_0002 State change from NEW to SUBMITTED
2013-08-11 09:18:33,981 INFO org.apache.hadoop.yarn.server.resourcemanager.ApplicationMasterService: Registering appattempt_1376212503271_0002_000001
2013-08-11 09:18:33,981 INFO org.apache.hadoop.yarn.server.resourcemanager.rmapp.attempt.RMAppAttemptImpl: appattempt_1376212503271_0002_000001 State change from NEW to SUBMITTED
2013-08-11 09:18:33,982 INFO org.apache.hadoop.yarn.server.resourcemanager.scheduler.capacity.LeafQueue: Application application_1376212503271_0002 from user: ubuntu activated in queue: default
2013-08-11 09:18:33,982 INFO org.apache.hadoop.yarn.server.resourcemanager.scheduler.capacity.LeafQueue: Application added - appId: application_1376212503271_0002 user: org.apache.hadoop.yarn.server.resourcemanager.scheduler.capacity.LeafQueue$User@38e1ea47, leaf-queue: default #user-pending-applications: 0 #user-active-applications: 1 #queue-pending-applications: 0 #queue-active-applications: 1
2013-08-11 09:18:33,982 INFO org.apache.hadoop.yarn.server.resourcemanager.scheduler.capacity.ParentQueue: Application added - appId: application_1376212503271_0002 user: ubuntu leaf-queue of parent: root #applications: 1
2013-08-11 09:18:33,983 INFO org.apache.hadoop.yarn.server.resourcemanager.scheduler.capacity.CapacityScheduler: Application Submission: appattempt_1376212503271_0002_000001, user: ubuntu queue: default: capacity=1.0, absoluteCapacity=1.0, usedResources=<memory:0, vCores:0>usedCapacity=0.0, absoluteUsedCapacity=0.0, numApps=1, numContainers=0, currently active: 1
2013-08-11 09:18:33,983 INFO org.apache.hadoop.yarn.server.resourcemanager.rmapp.attempt.RMAppAttemptImpl: appattempt_1376212503271_0002_000001 State change from SUBMITTED to SCHEDULED
2013-08-11 09:18:33,984 INFO org.apache.hadoop.yarn.server.resourcemanager.rmapp.RMAppImpl: application_1376212503271_0002 State change from SUBMITTED to ACCEPTED
2013-08-11 09:18:34,035 INFO org.apache.hadoop.yarn.server.resourcemanager.rmcontainer.RMContainerImpl: container_1376212503271_0002_01_000001 Container Transitioned from NEW to ALLOCATED
2013-08-11 09:18:34,035 INFO org.apache.hadoop.yarn.server.resourcemanager.RMAuditLogger: USER=ubuntu	OPERATION=AM Allocated Container	TARGET=SchedulerApp	RESULT=SUCCESS	APPID=application_1376212503271_0002	CONTAINERID=container_1376212503271_0002_01_000001
2013-08-11 09:18:34,036 INFO org.apache.hadoop.yarn.server.resourcemanager.scheduler.common.fica.FiCaSchedulerNode: Assigned container container_1376212503271_0002_01_000001 of capacity <memory:2048, vCores:1> on host hadoop-320-3:47015, which currently has 1 containers, <memory:2048, vCores:1> used and <memory:6144, vCores:15> available
2013-08-11 09:18:34,037 INFO org.apache.hadoop.yarn.server.resourcemanager.scheduler.capacity.LeafQueue: assignedContainer application=application_1376212503271_0002 container=Container: [ContainerId: container_1376212503271_0002_01_000001, NodeId: hadoop-320-3:47015, NodeHttpAddress: hadoop-320-3:8042, Resource: <memory:2048, vCores:1>, Priority: 0, State: NEW, Token: null, Status: container_id {, app_attempt_id {, application_id {, id: 2, cluster_timestamp: 1376212503271, }, attemptId: 1, }, id: 1, }, state: C_NEW, ] containerId=container_1376212503271_0002_01_000001 queue=default: capacity=1.0, absoluteCapacity=1.0, usedResources=<memory:0, vCores:0>usedCapacity=0.0, absoluteUsedCapacity=0.0, numApps=1, numContainers=0 usedCapacity=0.0 absoluteUsedCapacity=0.0 used=<memory:0, vCores:0> cluster=<memory:49152, vCores:96>
2013-08-11 09:18:34,038 INFO org.apache.hadoop.yarn.server.resourcemanager.scheduler.capacity.ParentQueue: Re-sorting queues since queue: root.default stats: default: capacity=1.0, absoluteCapacity=1.0, usedResources=<memory:2048, vCores:1>usedCapacity=0.041666668, absoluteUsedCapacity=0.041666668, numApps=1, numContainers=1
2013-08-11 09:18:34,038 INFO org.apache.hadoop.yarn.server.resourcemanager.scheduler.capacity.ParentQueue: assignedContainer queue=root usedCapacity=0.041666668 absoluteUsedCapacity=0.041666668 used=<memory:2048, vCores:1> cluster=<memory:49152, vCores:96>
2013-08-11 09:18:34,040 INFO org.apache.hadoop.yarn.server.resourcemanager.rmcontainer.RMContainerImpl: container_1376212503271_0002_01_000001 Container Transitioned from ALLOCATED to ACQUIRED
2013-08-11 09:18:34,042 INFO org.apache.hadoop.yarn.server.resourcemanager.rmapp.attempt.RMAppAttemptImpl: Storing attempt: AppId: application_1376212503271_0002 AttemptId: appattempt_1376212503271_0002_000001 MasterContainer: Container: [ContainerId: container_1376212503271_0002_01_000001, NodeId: hadoop-320-3:47015, NodeHttpAddress: hadoop-320-3:8042, Resource: <memory:2048, vCores:1>, Priority: 0, State: NEW, Token: null, Status: container_id {, app_attempt_id {, application_id {, id: 2, cluster_timestamp: 1376212503271, }, attemptId: 1, }, id: 1, }, state: C_NEW, ]
2013-08-11 09:18:34,042 INFO org.apache.hadoop.yarn.server.resourcemanager.rmapp.attempt.RMAppAttemptImpl: appattempt_1376212503271_0002_000001 State change from SCHEDULED to ALLOCATED_SAVING
2013-08-11 09:18:34,042 INFO org.apache.hadoop.yarn.server.resourcemanager.recovery.RMStateStore: Storing info for attempt: appattempt_1376212503271_0002_000001
2013-08-11 09:18:34,043 INFO org.apache.hadoop.yarn.server.resourcemanager.rmapp.attempt.RMAppAttemptImpl: appattempt_1376212503271_0002_000001 State change from ALLOCATED_SAVING to ALLOCATED
2013-08-11 09:18:34,045 INFO org.apache.hadoop.yarn.server.resourcemanager.amlauncher.AMLauncher: Launching masterappattempt_1376212503271_0002_000001
2013-08-11 09:18:34,048 INFO org.apache.hadoop.yarn.server.resourcemanager.amlauncher.AMLauncher: Setting up container Container: [ContainerId: container_1376212503271_0002_01_000001, NodeId: hadoop-320-3:47015, NodeHttpAddress: hadoop-320-3:8042, Resource: <memory:2048, vCores:1>, Priority: 0, State: NEW, Token: null, Status: container_id {, app_attempt_id {, application_id {, id: 2, cluster_timestamp: 1376212503271, }, attemptId: 1, }, id: 1, }, state: C_NEW, ] for AM appattempt_1376212503271_0002_000001
2013-08-11 09:18:34,048 INFO org.apache.hadoop.yarn.server.resourcemanager.amlauncher.AMLauncher: Command to launch container container_1376212503271_0002_01_000001 : $JAVA_HOME/bin/java -Dlog4j.configuration=container-log4j.properties -Dyarn.app.mapreduce.container.log.dir=<LOG_DIR> -Dyarn.app.mapreduce.container.log.filesize=0 -Dhadoop.root.logger=INFO,CLA  -Xmx1024m org.apache.hadoop.mapreduce.v2.app.MRAppMaster 1><LOG_DIR>/stdout 2><LOG_DIR>/stderr 
2013-08-11 09:18:34,076 INFO org.apache.hadoop.yarn.server.resourcemanager.amlauncher.AMLauncher: Done launching container Container: [ContainerId: container_1376212503271_0002_01_000001, NodeId: hadoop-320-3:47015, NodeHttpAddress: hadoop-320-3:8042, Resource: <memory:2048, vCores:1>, Priority: 0, State: NEW, Token: null, Status: container_id {, app_attempt_id {, application_id {, id: 2, cluster_timestamp: 1376212503271, }, attemptId: 1, }, id: 1, }, state: C_NEW, ] for AM appattempt_1376212503271_0002_000001
2013-08-11 09:18:34,076 INFO org.apache.hadoop.yarn.server.resourcemanager.rmapp.attempt.RMAppAttemptImpl: appattempt_1376212503271_0002_000001 State change from ALLOCATED to LAUNCHED
2013-08-11 09:18:35,041 INFO org.apache.hadoop.yarn.server.resourcemanager.rmcontainer.RMContainerImpl: container_1376212503271_0002_01_000001 Container Transitioned from ACQUIRED to RUNNING
2013-08-11 09:18:42,603 INFO org.apache.hadoop.yarn.server.resourcemanager.ApplicationMasterService: AM registration appattempt_1376212503271_0002_000001
2013-08-11 09:18:42,603 INFO org.apache.hadoop.yarn.server.resourcemanager.RMAuditLogger: USER=ubuntu	IP=192.168.100.13	OPERATION=Register App Master	TARGET=ApplicationMasterService	RESULT=SUCCESS	APPID=application_1376212503271_0002	APPATTEMPTID=appattempt_1376212503271_0002_000001
2013-08-11 09:18:42,613 INFO org.apache.hadoop.yarn.server.resourcemanager.rmapp.attempt.RMAppAttemptImpl: appattempt_1376212503271_0002_000001 State change from LAUNCHED to RUNNING
2013-08-11 09:18:42,613 INFO org.apache.hadoop.yarn.server.resourcemanager.rmapp.RMAppImpl: application_1376212503271_0002 State change from ACCEPTED to RUNNING
2013-08-11 09:18:43,709 INFO org.apache.hadoop.yarn.server.resourcemanager.rmcontainer.RMContainerImpl: container_1376212503271_0002_01_000002 Container Transitioned from NEW to ALLOCATED
2013-08-11 09:18:43,709 INFO org.apache.hadoop.yarn.server.resourcemanager.RMAuditLogger: USER=ubuntu	OPERATION=AM Allocated Container	TARGET=SchedulerApp	RESULT=SUCCESS	APPID=application_1376212503271_0002	CONTAINERID=container_1376212503271_0002_01_000002
2013-08-11 09:18:43,709 INFO org.apache.hadoop.yarn.server.resourcemanager.scheduler.common.fica.FiCaSchedulerNode: Assigned container container_1376212503271_0002_01_000002 of capacity <memory:1024, vCores:1> on host hadoop-320-7:48037, which currently has 1 containers, <memory:1024, vCores:1> used and <memory:7168, vCores:15> available
2013-08-11 09:18:43,714 INFO org.apache.hadoop.yarn.server.resourcemanager.scheduler.capacity.LeafQueue: assignedContainer application=application_1376212503271_0002 container=Container: [ContainerId: container_1376212503271_0002_01_000002, NodeId: hadoop-320-7:48037, NodeHttpAddress: hadoop-320-7:8042, Resource: <memory:1024, vCores:1>, Priority: 20, State: NEW, Token: null, Status: container_id {, app_attempt_id {, application_id {, id: 2, cluster_timestamp: 1376212503271, }, attemptId: 1, }, id: 2, }, state: C_NEW, ] containerId=container_1376212503271_0002_01_000002 queue=default: capacity=1.0, absoluteCapacity=1.0, usedResources=<memory:2048, vCores:1>usedCapacity=0.041666668, absoluteUsedCapacity=0.041666668, numApps=1, numContainers=1 usedCapacity=0.041666668 absoluteUsedCapacity=0.041666668 used=<memory:2048, vCores:1> cluster=<memory:49152, vCores:96>
2013-08-11 09:18:43,715 INFO org.apache.hadoop.yarn.server.resourcemanager.scheduler.capacity.ParentQueue: Re-sorting queues since queue: root.default stats: default: capacity=1.0, absoluteCapacity=1.0, usedResources=<memory:3072, vCores:2>usedCapacity=0.0625, absoluteUsedCapacity=0.0625, numApps=1, numContainers=2
2013-08-11 09:18:43,715 INFO org.apache.hadoop.yarn.server.resourcemanager.scheduler.capacity.ParentQueue: assignedContainer queue=root usedCapacity=0.0625 absoluteUsedCapacity=0.0625 used=<memory:3072, vCores:2> cluster=<memory:49152, vCores:96>
2013-08-11 09:18:44,018 INFO org.apache.hadoop.yarn.server.resourcemanager.rmcontainer.RMContainerImpl: container_1376212503271_0002_01_000003 Container Transitioned from NEW to ALLOCATED
2013-08-11 09:18:44,019 INFO org.apache.hadoop.yarn.server.resourcemanager.RMAuditLogger: USER=ubuntu	OPERATION=AM Allocated Container	TARGET=SchedulerApp	RESULT=SUCCESS	APPID=application_1376212503271_0002	CONTAINERID=container_1376212503271_0002_01_000003
2013-08-11 09:18:44,019 INFO org.apache.hadoop.yarn.server.resourcemanager.scheduler.common.fica.FiCaSchedulerNode: Assigned container container_1376212503271_0002_01_000003 of capacity <memory:1024, vCores:1> on host hadoop-320-2:53179, which currently has 1 containers, <memory:1024, vCores:1> used and <memory:7168, vCores:15> available
2013-08-11 09:18:44,020 INFO org.apache.hadoop.yarn.server.resourcemanager.scheduler.capacity.LeafQueue: assignedContainer application=application_1376212503271_0002 container=Container: [ContainerId: container_1376212503271_0002_01_000003, NodeId: hadoop-320-2:53179, NodeHttpAddress: hadoop-320-2:8042, Resource: <memory:1024, vCores:1>, Priority: 20, State: NEW, Token: null, Status: container_id {, app_attempt_id {, application_id {, id: 2, cluster_timestamp: 1376212503271, }, attemptId: 1, }, id: 3, }, state: C_NEW, ] containerId=container_1376212503271_0002_01_000003 queue=default: capacity=1.0, absoluteCapacity=1.0, usedResources=<memory:3072, vCores:2>usedCapacity=0.0625, absoluteUsedCapacity=0.0625, numApps=1, numContainers=2 usedCapacity=0.0625 absoluteUsedCapacity=0.0625 used=<memory:3072, vCores:2> cluster=<memory:49152, vCores:96>
2013-08-11 09:18:44,020 INFO org.apache.hadoop.yarn.server.resourcemanager.scheduler.capacity.ParentQueue: Re-sorting queues since queue: root.default stats: default: capacity=1.0, absoluteCapacity=1.0, usedResources=<memory:4096, vCores:3>usedCapacity=0.083333336, absoluteUsedCapacity=0.083333336, numApps=1, numContainers=3
2013-08-11 09:18:44,020 INFO org.apache.hadoop.yarn.server.resourcemanager.scheduler.capacity.ParentQueue: assignedContainer queue=root usedCapacity=0.083333336 absoluteUsedCapacity=0.083333336 used=<memory:4096, vCores:3> cluster=<memory:49152, vCores:96>
2013-08-11 09:18:44,679 INFO org.apache.hadoop.yarn.server.resourcemanager.rmcontainer.RMContainerImpl: container_1376212503271_0002_01_000002 Container Transitioned from ALLOCATED to ACQUIRED
2013-08-11 09:18:44,684 INFO org.apache.hadoop.yarn.server.resourcemanager.rmcontainer.RMContainerImpl: container_1376212503271_0002_01_000003 Container Transitioned from ALLOCATED to ACQUIRED
2013-08-11 09:18:45,714 INFO org.apache.hadoop.yarn.server.resourcemanager.scheduler.AppSchedulingInfo: checking for deactivate... 
2013-08-11 09:18:45,719 INFO org.apache.hadoop.yarn.server.resourcemanager.rmcontainer.RMContainerImpl: container_1376212503271_0002_01_000002 Container Transitioned from ACQUIRED to RUNNING
2013-08-11 09:18:46,138 INFO org.apache.hadoop.yarn.server.resourcemanager.rmcontainer.RMContainerImpl: container_1376212503271_0002_01_000003 Container Transitioned from ACQUIRED to RUNNING
2013-08-11 09:21:26,889 INFO org.apache.hadoop.yarn.server.resourcemanager.rmcontainer.RMContainerImpl: container_1376212503271_0002_01_000002 Container Transitioned from RUNNING to COMPLETED
2013-08-11 09:21:26,889 INFO org.apache.hadoop.yarn.server.resourcemanager.scheduler.common.fica.FiCaSchedulerApp: Completed container: container_1376212503271_0002_01_000002 in state: COMPLETED event:FINISHED
2013-08-11 09:21:26,889 INFO org.apache.hadoop.yarn.server.resourcemanager.RMAuditLogger: USER=ubuntu	OPERATION=AM Released Container	TARGET=SchedulerApp	RESULT=SUCCESS	APPID=application_1376212503271_0002	CONTAINERID=container_1376212503271_0002_01_000002
2013-08-11 09:21:26,889 INFO org.apache.hadoop.yarn.server.resourcemanager.scheduler.common.fica.FiCaSchedulerNode: Released container container_1376212503271_0002_01_000002 of capacity <memory:1024, vCores:1> on host hadoop-320-7:48037, which currently has 0 containers, <memory:0, vCores:0> used and <memory:8192, vCores:16> available, release resources=true
2013-08-11 09:21:26,889 INFO org.apache.hadoop.yarn.server.resourcemanager.scheduler.capacity.LeafQueue: default used=<memory:3072, vCores:2> numContainers=2 user=ubuntu user-resources=<memory:3072, vCores:2>
2013-08-11 09:21:26,903 INFO org.apache.hadoop.yarn.server.resourcemanager.scheduler.capacity.LeafQueue: completedContainer container=Container: [ContainerId: container_1376212503271_0002_01_000002, NodeId: hadoop-320-7:48037, NodeHttpAddress: hadoop-320-7:8042, Resource: <memory:1024, vCores:1>, Priority: 20, State: NEW, Token: null, Status: container_id {, app_attempt_id {, application_id {, id: 2, cluster_timestamp: 1376212503271, }, attemptId: 1, }, id: 2, }, state: C_COMPLETE, diagnostics: "Container killed by the ApplicationMaster.\n\n", exit_status: 143, ] resource=<memory:1024, vCores:1> queue=default: capacity=1.0, absoluteCapacity=1.0, usedResources=<memory:3072, vCores:2>usedCapacity=0.0625, absoluteUsedCapacity=0.0625, numApps=1, numContainers=2 usedCapacity=0.0625 absoluteUsedCapacity=0.0625 used=<memory:3072, vCores:2> cluster=<memory:49152, vCores:96>
2013-08-11 09:21:26,903 INFO org.apache.hadoop.yarn.server.resourcemanager.scheduler.capacity.ParentQueue: completedContainer queue=root usedCapacity=0.0625 absoluteUsedCapacity=0.0625 used=<memory:3072, vCores:2> cluster=<memory:49152, vCores:96>
2013-08-11 09:21:26,903 INFO org.apache.hadoop.yarn.server.resourcemanager.scheduler.capacity.CapacityScheduler: Application appattempt_1376212503271_0002_000001 released container container_1376212503271_0002_01_000002 on node: host: hadoop-320-7:48037 #containers=0 available=8192 used=0 with event: FINISHED
2013-08-11 09:21:42,589 INFO org.apache.hadoop.yarn.server.resourcemanager.rmcontainer.RMContainerImpl: container_1376212503271_0002_01_000003 Container Transitioned from RUNNING to COMPLETED
2013-08-11 09:21:42,590 INFO org.apache.hadoop.yarn.server.resourcemanager.scheduler.common.fica.FiCaSchedulerApp: Completed container: container_1376212503271_0002_01_000003 in state: COMPLETED event:FINISHED
2013-08-11 09:21:42,590 INFO org.apache.hadoop.yarn.server.resourcemanager.RMAuditLogger: USER=ubuntu	OPERATION=AM Released Container	TARGET=SchedulerApp	RESULT=SUCCESS	APPID=application_1376212503271_0002	CONTAINERID=container_1376212503271_0002_01_000003
2013-08-11 09:21:42,590 INFO org.apache.hadoop.yarn.server.resourcemanager.scheduler.common.fica.FiCaSchedulerNode: Released container container_1376212503271_0002_01_000003 of capacity <memory:1024, vCores:1> on host hadoop-320-2:53179, which currently has 0 containers, <memory:0, vCores:0> used and <memory:8192, vCores:16> available, release resources=true
2013-08-11 09:21:42,590 INFO org.apache.hadoop.yarn.server.resourcemanager.scheduler.capacity.LeafQueue: default used=<memory:2048, vCores:1> numContainers=1 user=ubuntu user-resources=<memory:2048, vCores:1>
2013-08-11 09:21:42,592 INFO org.apache.hadoop.yarn.server.resourcemanager.scheduler.capacity.LeafQueue: completedContainer container=Container: [ContainerId: container_1376212503271_0002_01_000003, NodeId: hadoop-320-2:53179, NodeHttpAddress: hadoop-320-2:8042, Resource: <memory:1024, vCores:1>, Priority: 20, State: NEW, Token: null, Status: container_id {, app_attempt_id {, application_id {, id: 2, cluster_timestamp: 1376212503271, }, attemptId: 1, }, id: 3, }, state: C_COMPLETE, diagnostics: "Container killed by the ApplicationMaster.\n\n", exit_status: 143, ] resource=<memory:1024, vCores:1> queue=default: capacity=1.0, absoluteCapacity=1.0, usedResources=<memory:2048, vCores:1>usedCapacity=0.041666668, absoluteUsedCapacity=0.041666668, numApps=1, numContainers=1 usedCapacity=0.041666668 absoluteUsedCapacity=0.041666668 used=<memory:2048, vCores:1> cluster=<memory:49152, vCores:96>
2013-08-11 09:21:42,593 INFO org.apache.hadoop.yarn.server.resourcemanager.scheduler.capacity.ParentQueue: completedContainer queue=root usedCapacity=0.041666668 absoluteUsedCapacity=0.041666668 used=<memory:2048, vCores:1> cluster=<memory:49152, vCores:96>
2013-08-11 09:21:42,593 INFO org.apache.hadoop.yarn.server.resourcemanager.scheduler.capacity.CapacityScheduler: Application appattempt_1376212503271_0002_000001 released container container_1376212503271_0002_01_000003 on node: host: hadoop-320-2:53179 #containers=0 available=8192 used=0 with event: FINISHED
2013-08-11 09:21:46,776 INFO org.apache.hadoop.yarn.server.resourcemanager.rmapp.attempt.RMAppAttemptImpl: appattempt_1376212503271_0002_000001 State change from RUNNING to FINISHING
2013-08-11 09:21:46,777 INFO org.apache.hadoop.yarn.server.resourcemanager.rmapp.RMAppImpl: application_1376212503271_0002 State change from RUNNING to FINISHING
2013-08-11 09:21:47,034 INFO org.apache.hadoop.yarn.server.resourcemanager.rmcontainer.RMContainerImpl: container_1376212503271_0002_01_000001 Container Transitioned from RUNNING to COMPLETED
2013-08-11 09:21:47,034 INFO org.apache.hadoop.yarn.server.resourcemanager.scheduler.common.fica.FiCaSchedulerApp: Completed container: container_1376212503271_0002_01_000001 in state: COMPLETED event:FINISHED
2013-08-11 09:21:47,034 INFO org.apache.hadoop.yarn.server.resourcemanager.rmapp.attempt.RMAppAttemptImpl: appattempt_1376212503271_0002_000001 State change from FINISHING to FINISHED
2013-08-11 09:21:47,034 INFO org.apache.hadoop.yarn.server.resourcemanager.RMAuditLogger: USER=ubuntu	OPERATION=AM Released Container	TARGET=SchedulerApp	RESULT=SUCCESS	APPID=application_1376212503271_0002	CONTAINERID=container_1376212503271_0002_01_000001
2013-08-11 09:21:47,035 INFO org.apache.hadoop.yarn.server.resourcemanager.rmapp.RMAppImpl: application_1376212503271_0002 State change from FINISHING to FINISHED
2013-08-11 09:21:47,035 INFO org.apache.hadoop.yarn.server.resourcemanager.scheduler.common.fica.FiCaSchedulerNode: Released container container_1376212503271_0002_01_000001 of capacity <memory:2048, vCores:1> on host hadoop-320-3:47015, which currently has 0 containers, <memory:0, vCores:0> used and <memory:8192, vCores:16> available, release resources=true
2013-08-11 09:21:47,035 INFO org.apache.hadoop.yarn.server.resourcemanager.scheduler.capacity.LeafQueue: default used=<memory:0, vCores:0> numContainers=0 user=ubuntu user-resources=<memory:0, vCores:0>
2013-08-11 09:21:47,036 INFO org.apache.hadoop.yarn.server.resourcemanager.RMAuditLogger: USER=ubuntu	OPERATION=Application Finished - Succeeded	TARGET=RMAppManager	RESULT=SUCCESS	APPID=application_1376212503271_0002
2013-08-11 09:21:47,036 INFO org.apache.hadoop.yarn.server.resourcemanager.scheduler.capacity.LeafQueue: completedContainer container=Container: [ContainerId: container_1376212503271_0002_01_000001, NodeId: hadoop-320-3:47015, NodeHttpAddress: hadoop-320-3:8042, Resource: <memory:2048, vCores:1>, Priority: 0, State: NEW, Token: null, Status: container_id {, app_attempt_id {, application_id {, id: 2, cluster_timestamp: 1376212503271, }, attemptId: 1, }, id: 1, }, state: C_COMPLETE, diagnostics: "", exit_status: 0, ] resource=<memory:2048, vCores:1> queue=default: capacity=1.0, absoluteCapacity=1.0, usedResources=<memory:0, vCores:0>usedCapacity=0.0, absoluteUsedCapacity=0.0, numApps=1, numContainers=0 usedCapacity=0.0 absoluteUsedCapacity=0.0 used=<memory:0, vCores:0> cluster=<memory:49152, vCores:96>
2013-08-11 09:21:47,037 INFO org.apache.hadoop.yarn.server.resourcemanager.amlauncher.AMLauncher: Cleaning master appattempt_1376212503271_0002_000001
2013-08-11 09:21:47,037 INFO org.apache.hadoop.yarn.server.resourcemanager.RMAppManager$ApplicationSummary: appId=application_1376212503271_0002,name=TeraGen,user=ubuntu,queue=default,state=FINISHED,trackingUrl=hadoop-320-1.novalocal:8088/proxy/application_1376212503271_0002/jobhistory/job/job_1376212503271_0002,appMasterHost=hadoop-320-3,startTime=1376212713977,finishTime=1376212906777
2013-08-11 09:21:47,037 INFO org.apache.hadoop.yarn.server.resourcemanager.recovery.RMStateStore: Removing info for app: application_1376212503271_0002
2013-08-11 09:21:47,037 INFO org.apache.hadoop.yarn.server.resourcemanager.scheduler.capacity.ParentQueue: completedContainer queue=root usedCapacity=0.0 absoluteUsedCapacity=0.0 used=<memory:0, vCores:0> cluster=<memory:49152, vCores:96>
2013-08-11 09:21:47,040 INFO org.apache.hadoop.yarn.server.resourcemanager.scheduler.capacity.CapacityScheduler: Application appattempt_1376212503271_0002_000001 released container container_1376212503271_0002_01_000001 on node: host: hadoop-320-3:47015 #containers=0 available=8192 used=0 with event: FINISHED
2013-08-11 09:21:47,040 INFO org.apache.hadoop.yarn.server.resourcemanager.scheduler.capacity.CapacityScheduler: Application appattempt_1376212503271_0002_000001 is done. finalState=FINISHED
2013-08-11 09:21:47,040 INFO org.apache.hadoop.yarn.server.resourcemanager.scheduler.AppSchedulingInfo: Application application_1376212503271_0002 requests cleared
2013-08-11 09:21:47,040 INFO org.apache.hadoop.yarn.server.resourcemanager.scheduler.capacity.LeafQueue: Application removed - appId: application_1376212503271_0002 user: ubuntu queue: default #user-pending-applications: 0 #user-active-applications: 0 #queue-pending-applications: 0 #queue-active-applications: 0
2013-08-11 09:21:47,040 INFO org.apache.hadoop.yarn.server.resourcemanager.scheduler.capacity.ParentQueue: Application removed - appId: application_1376212503271_0002 user: ubuntu leaf-queue of parent: root #applications: 0
2013-08-11 09:21:48,414 INFO org.apache.hadoop.yarn.server.resourcemanager.ClientRMService: Allocated new applicationId: 3
2013-08-11 09:21:50,194 INFO org.apache.hadoop.yarn.server.resourcemanager.ClientRMService: Storing Application with id application_1376212503271_0003
2013-08-11 09:21:50,195 INFO org.apache.hadoop.yarn.server.resourcemanager.recovery.RMStateStore: Storing info for app: application_1376212503271_0003
2013-08-11 09:21:50,195 INFO org.apache.hadoop.yarn.server.resourcemanager.ClientRMService: Application with id 3 submitted by user ubuntu
2013-08-11 09:21:50,195 INFO org.apache.hadoop.yarn.server.resourcemanager.RMAuditLogger: USER=ubuntu	IP=192.168.100.4	OPERATION=Submit Application Request	TARGET=ClientRMService	RESULT=SUCCESS	APPID=application_1376212503271_0003
2013-08-11 09:21:50,195 INFO org.apache.hadoop.yarn.server.resourcemanager.rmapp.RMAppImpl: application_1376212503271_0003 State change from NEW to SUBMITTED
2013-08-11 09:21:50,196 INFO org.apache.hadoop.yarn.server.resourcemanager.ApplicationMasterService: Registering appattempt_1376212503271_0003_000001
2013-08-11 09:21:50,196 INFO org.apache.hadoop.yarn.server.resourcemanager.rmapp.attempt.RMAppAttemptImpl: appattempt_1376212503271_0003_000001 State change from NEW to SUBMITTED
2013-08-11 09:21:50,196 INFO org.apache.hadoop.yarn.server.resourcemanager.scheduler.capacity.LeafQueue: Application application_1376212503271_0003 from user: ubuntu activated in queue: default
2013-08-11 09:21:50,197 INFO org.apache.hadoop.yarn.server.resourcemanager.scheduler.capacity.LeafQueue: Application added - appId: application_1376212503271_0003 user: org.apache.hadoop.yarn.server.resourcemanager.scheduler.capacity.LeafQueue$User@38359154, leaf-queue: default #user-pending-applications: 0 #user-active-applications: 1 #queue-pending-applications: 0 #queue-active-applications: 1
2013-08-11 09:21:50,197 INFO org.apache.hadoop.yarn.server.resourcemanager.scheduler.capacity.ParentQueue: Application added - appId: application_1376212503271_0003 user: ubuntu leaf-queue of parent: root #applications: 1
2013-08-11 09:21:50,197 INFO org.apache.hadoop.yarn.server.resourcemanager.scheduler.capacity.CapacityScheduler: Application Submission: appattempt_1376212503271_0003_000001, user: ubuntu queue: default: capacity=1.0, absoluteCapacity=1.0, usedResources=<memory:0, vCores:0>usedCapacity=0.0, absoluteUsedCapacity=0.0, numApps=1, numContainers=0, currently active: 1
2013-08-11 09:21:50,198 INFO org.apache.hadoop.yarn.server.resourcemanager.rmapp.attempt.RMAppAttemptImpl: appattempt_1376212503271_0003_000001 State change from SUBMITTED to SCHEDULED
2013-08-11 09:21:50,198 INFO org.apache.hadoop.yarn.server.resourcemanager.rmapp.RMAppImpl: application_1376212503271_0003 State change from SUBMITTED to ACCEPTED
2013-08-11 09:21:50,626 INFO org.apache.hadoop.yarn.server.resourcemanager.rmcontainer.RMContainerImpl: container_1376212503271_0003_01_000001 Container Transitioned from NEW to ALLOCATED
2013-08-11 09:21:50,626 INFO org.apache.hadoop.yarn.server.resourcemanager.RMAuditLogger: USER=ubuntu	OPERATION=AM Allocated Container	TARGET=SchedulerApp	RESULT=SUCCESS	APPID=application_1376212503271_0003	CONTAINERID=container_1376212503271_0003_01_000001
2013-08-11 09:21:50,626 INFO org.apache.hadoop.yarn.server.resourcemanager.scheduler.common.fica.FiCaSchedulerNode: Assigned container container_1376212503271_0003_01_000001 of capacity <memory:2048, vCores:1> on host hadoop-320-2:53179, which currently has 1 containers, <memory:2048, vCores:1> used and <memory:6144, vCores:15> available
2013-08-11 09:21:50,628 INFO org.apache.hadoop.yarn.server.resourcemanager.scheduler.capacity.LeafQueue: assignedContainer application=application_1376212503271_0003 container=Container: [ContainerId: container_1376212503271_0003_01_000001, NodeId: hadoop-320-2:53179, NodeHttpAddress: hadoop-320-2:8042, Resource: <memory:2048, vCores:1>, Priority: 0, State: NEW, Token: null, Status: container_id {, app_attempt_id {, application_id {, id: 3, cluster_timestamp: 1376212503271, }, attemptId: 1, }, id: 1, }, state: C_NEW, ] containerId=container_1376212503271_0003_01_000001 queue=default: capacity=1.0, absoluteCapacity=1.0, usedResources=<memory:0, vCores:0>usedCapacity=0.0, absoluteUsedCapacity=0.0, numApps=1, numContainers=0 usedCapacity=0.0 absoluteUsedCapacity=0.0 used=<memory:0, vCores:0> cluster=<memory:49152, vCores:96>
2013-08-11 09:21:50,628 INFO org.apache.hadoop.yarn.server.resourcemanager.scheduler.capacity.ParentQueue: Re-sorting queues since queue: root.default stats: default: capacity=1.0, absoluteCapacity=1.0, usedResources=<memory:2048, vCores:1>usedCapacity=0.041666668, absoluteUsedCapacity=0.041666668, numApps=1, numContainers=1
2013-08-11 09:21:50,628 INFO org.apache.hadoop.yarn.server.resourcemanager.scheduler.capacity.ParentQueue: assignedContainer queue=root usedCapacity=0.041666668 absoluteUsedCapacity=0.041666668 used=<memory:2048, vCores:1> cluster=<memory:49152, vCores:96>
2013-08-11 09:21:50,630 INFO org.apache.hadoop.yarn.server.resourcemanager.rmcontainer.RMContainerImpl: container_1376212503271_0003_01_000001 Container Transitioned from ALLOCATED to ACQUIRED
2013-08-11 09:21:50,632 INFO org.apache.hadoop.yarn.server.resourcemanager.rmapp.attempt.RMAppAttemptImpl: Storing attempt: AppId: application_1376212503271_0003 AttemptId: appattempt_1376212503271_0003_000001 MasterContainer: Container: [ContainerId: container_1376212503271_0003_01_000001, NodeId: hadoop-320-2:53179, NodeHttpAddress: hadoop-320-2:8042, Resource: <memory:2048, vCores:1>, Priority: 0, State: NEW, Token: null, Status: container_id {, app_attempt_id {, application_id {, id: 3, cluster_timestamp: 1376212503271, }, attemptId: 1, }, id: 1, }, state: C_NEW, ]
2013-08-11 09:21:50,632 INFO org.apache.hadoop.yarn.server.resourcemanager.rmapp.attempt.RMAppAttemptImpl: appattempt_1376212503271_0003_000001 State change from SCHEDULED to ALLOCATED_SAVING
2013-08-11 09:21:50,632 INFO org.apache.hadoop.yarn.server.resourcemanager.recovery.RMStateStore: Storing info for attempt: appattempt_1376212503271_0003_000001
2013-08-11 09:21:50,633 INFO org.apache.hadoop.yarn.server.resourcemanager.rmapp.attempt.RMAppAttemptImpl: appattempt_1376212503271_0003_000001 State change from ALLOCATED_SAVING to ALLOCATED
2013-08-11 09:21:50,634 INFO org.apache.hadoop.yarn.server.resourcemanager.amlauncher.AMLauncher: Launching masterappattempt_1376212503271_0003_000001
2013-08-11 09:21:50,637 INFO org.apache.hadoop.yarn.server.resourcemanager.amlauncher.AMLauncher: Setting up container Container: [ContainerId: container_1376212503271_0003_01_000001, NodeId: hadoop-320-2:53179, NodeHttpAddress: hadoop-320-2:8042, Resource: <memory:2048, vCores:1>, Priority: 0, State: NEW, Token: null, Status: container_id {, app_attempt_id {, application_id {, id: 3, cluster_timestamp: 1376212503271, }, attemptId: 1, }, id: 1, }, state: C_NEW, ] for AM appattempt_1376212503271_0003_000001
2013-08-11 09:21:50,637 INFO org.apache.hadoop.yarn.server.resourcemanager.amlauncher.AMLauncher: Command to launch container container_1376212503271_0003_01_000001 : $JAVA_HOME/bin/java -Dlog4j.configuration=container-log4j.properties -Dyarn.app.mapreduce.container.log.dir=<LOG_DIR> -Dyarn.app.mapreduce.container.log.filesize=0 -Dhadoop.root.logger=INFO,CLA  -Xmx1024m org.apache.hadoop.mapreduce.v2.app.MRAppMaster 1><LOG_DIR>/stdout 2><LOG_DIR>/stderr 
2013-08-11 09:21:50,653 INFO org.apache.hadoop.yarn.server.resourcemanager.amlauncher.AMLauncher: Done launching container Container: [ContainerId: container_1376212503271_0003_01_000001, NodeId: hadoop-320-2:53179, NodeHttpAddress: hadoop-320-2:8042, Resource: <memory:2048, vCores:1>, Priority: 0, State: NEW, Token: null, Status: container_id {, app_attempt_id {, application_id {, id: 3, cluster_timestamp: 1376212503271, }, attemptId: 1, }, id: 1, }, state: C_NEW, ] for AM appattempt_1376212503271_0003_000001
2013-08-11 09:21:50,653 INFO org.apache.hadoop.yarn.server.resourcemanager.rmapp.attempt.RMAppAttemptImpl: appattempt_1376212503271_0003_000001 State change from ALLOCATED to LAUNCHED
2013-08-11 09:21:51,633 INFO org.apache.hadoop.yarn.server.resourcemanager.rmcontainer.RMContainerImpl: container_1376212503271_0003_01_000001 Container Transitioned from ACQUIRED to RUNNING
2013-08-11 09:21:59,426 INFO org.apache.hadoop.yarn.server.resourcemanager.ApplicationMasterService: AM registration appattempt_1376212503271_0003_000001
2013-08-11 09:21:59,427 INFO org.apache.hadoop.yarn.server.resourcemanager.RMAuditLogger: USER=ubuntu	IP=192.168.100.11	OPERATION=Register App Master	TARGET=ApplicationMasterService	RESULT=SUCCESS	APPID=application_1376212503271_0003	APPATTEMPTID=appattempt_1376212503271_0003_000001
2013-08-11 09:21:59,428 INFO org.apache.hadoop.yarn.server.resourcemanager.rmapp.attempt.RMAppAttemptImpl: appattempt_1376212503271_0003_000001 State change from LAUNCHED to RUNNING
2013-08-11 09:21:59,428 INFO org.apache.hadoop.yarn.server.resourcemanager.rmapp.RMAppImpl: application_1376212503271_0003 State change from ACCEPTED to RUNNING
2013-08-11 09:22:00,678 INFO org.apache.hadoop.yarn.server.resourcemanager.rmcontainer.RMContainerImpl: container_1376212503271_0003_01_000002 Container Transitioned from NEW to ALLOCATED
2013-08-11 09:22:00,678 INFO org.apache.hadoop.yarn.server.resourcemanager.RMAuditLogger: USER=ubuntu	OPERATION=AM Allocated Container	TARGET=SchedulerApp	RESULT=SUCCESS	APPID=application_1376212503271_0003	CONTAINERID=container_1376212503271_0003_01_000002
2013-08-11 09:22:00,678 INFO org.apache.hadoop.yarn.server.resourcemanager.scheduler.common.fica.FiCaSchedulerNode: Assigned container container_1376212503271_0003_01_000002 of capacity <memory:1024, vCores:1> on host hadoop-320-2:53179, which currently has 2 containers, <memory:3072, vCores:2> used and <memory:5120, vCores:14> available
2013-08-11 09:22:00,680 INFO org.apache.hadoop.yarn.server.resourcemanager.scheduler.capacity.LeafQueue: assignedContainer application=application_1376212503271_0003 container=Container: [ContainerId: container_1376212503271_0003_01_000002, NodeId: hadoop-320-2:53179, NodeHttpAddress: hadoop-320-2:8042, Resource: <memory:1024, vCores:1>, Priority: 20, State: NEW, Token: null, Status: container_id {, app_attempt_id {, application_id {, id: 3, cluster_timestamp: 1376212503271, }, attemptId: 1, }, id: 2, }, state: C_NEW, ] containerId=container_1376212503271_0003_01_000002 queue=default: capacity=1.0, absoluteCapacity=1.0, usedResources=<memory:2048, vCores:1>usedCapacity=0.041666668, absoluteUsedCapacity=0.041666668, numApps=1, numContainers=1 usedCapacity=0.041666668 absoluteUsedCapacity=0.041666668 used=<memory:2048, vCores:1> cluster=<memory:49152, vCores:96>
2013-08-11 09:22:00,680 INFO org.apache.hadoop.yarn.server.resourcemanager.scheduler.capacity.ParentQueue: Re-sorting queues since queue: root.default stats: default: capacity=1.0, absoluteCapacity=1.0, usedResources=<memory:3072, vCores:2>usedCapacity=0.0625, absoluteUsedCapacity=0.0625, numApps=1, numContainers=2
2013-08-11 09:22:00,680 INFO org.apache.hadoop.yarn.server.resourcemanager.scheduler.capacity.ParentQueue: assignedContainer queue=root usedCapacity=0.0625 absoluteUsedCapacity=0.0625 used=<memory:3072, vCores:2> cluster=<memory:49152, vCores:96>
2013-08-11 09:22:01,036 INFO org.apache.hadoop.yarn.server.resourcemanager.rmcontainer.RMContainerImpl: container_1376212503271_0003_01_000003 Container Transitioned from NEW to ALLOCATED
2013-08-11 09:22:01,037 INFO org.apache.hadoop.yarn.server.resourcemanager.RMAuditLogger: USER=ubuntu	OPERATION=AM Allocated Container	TARGET=SchedulerApp	RESULT=SUCCESS	APPID=application_1376212503271_0003	CONTAINERID=container_1376212503271_0003_01_000003
2013-08-11 09:22:01,037 INFO org.apache.hadoop.yarn.server.resourcemanager.scheduler.common.fica.FiCaSchedulerNode: Assigned container container_1376212503271_0003_01_000003 of capacity <memory:1024, vCores:1> on host hadoop-320-7:48037, which currently has 1 containers, <memory:1024, vCores:1> used and <memory:7168, vCores:15> available
2013-08-11 09:22:01,038 INFO org.apache.hadoop.yarn.server.resourcemanager.scheduler.capacity.LeafQueue: assignedContainer application=application_1376212503271_0003 container=Container: [ContainerId: container_1376212503271_0003_01_000003, NodeId: hadoop-320-7:48037, NodeHttpAddress: hadoop-320-7:8042, Resource: <memory:1024, vCores:1>, Priority: 20, State: NEW, Token: null, Status: container_id {, app_attempt_id {, application_id {, id: 3, cluster_timestamp: 1376212503271, }, attemptId: 1, }, id: 3, }, state: C_NEW, ] containerId=container_1376212503271_0003_01_000003 queue=default: capacity=1.0, absoluteCapacity=1.0, usedResources=<memory:3072, vCores:2>usedCapacity=0.0625, absoluteUsedCapacity=0.0625, numApps=1, numContainers=2 usedCapacity=0.0625 absoluteUsedCapacity=0.0625 used=<memory:3072, vCores:2> cluster=<memory:49152, vCores:96>
2013-08-11 09:22:01,039 INFO org.apache.hadoop.yarn.server.resourcemanager.scheduler.capacity.ParentQueue: Re-sorting queues since queue: root.default stats: default: capacity=1.0, absoluteCapacity=1.0, usedResources=<memory:4096, vCores:3>usedCapacity=0.083333336, absoluteUsedCapacity=0.083333336, numApps=1, numContainers=3
2013-08-11 09:22:01,039 INFO org.apache.hadoop.yarn.server.resourcemanager.scheduler.capacity.ParentQueue: assignedContainer queue=root usedCapacity=0.083333336 absoluteUsedCapacity=0.083333336 used=<memory:4096, vCores:3> cluster=<memory:49152, vCores:96>
2013-08-11 09:22:01,501 INFO org.apache.hadoop.yarn.server.resourcemanager.rmcontainer.RMContainerImpl: container_1376212503271_0003_01_000002 Container Transitioned from ALLOCATED to ACQUIRED
2013-08-11 09:22:01,502 INFO org.apache.hadoop.yarn.server.resourcemanager.rmcontainer.RMContainerImpl: container_1376212503271_0003_01_000003 Container Transitioned from ALLOCATED to ACQUIRED
2013-08-11 09:22:02,045 INFO org.apache.hadoop.yarn.server.resourcemanager.rmcontainer.RMContainerImpl: container_1376212503271_0003_01_000003 Container Transitioned from ACQUIRED to RUNNING
2013-08-11 09:22:02,530 INFO org.apache.hadoop.yarn.server.resourcemanager.scheduler.AppSchedulingInfo: checking for deactivate... 
2013-08-11 09:22:02,689 INFO org.apache.hadoop.yarn.server.resourcemanager.rmcontainer.RMContainerImpl: container_1376212503271_0003_01_000002 Container Transitioned from ACQUIRED to RUNNING
2013-08-11 09:24:43,618 INFO org.apache.hadoop.yarn.server.resourcemanager.rmcontainer.RMContainerImpl: container_1376212503271_0003_01_000002 Container Transitioned from RUNNING to COMPLETED
2013-08-11 09:24:43,618 INFO org.apache.hadoop.yarn.server.resourcemanager.scheduler.common.fica.FiCaSchedulerApp: Completed container: container_1376212503271_0003_01_000002 in state: COMPLETED event:FINISHED
2013-08-11 09:24:43,618 INFO org.apache.hadoop.yarn.server.resourcemanager.RMAuditLogger: USER=ubuntu	OPERATION=AM Released Container	TARGET=SchedulerApp	RESULT=SUCCESS	APPID=application_1376212503271_0003	CONTAINERID=container_1376212503271_0003_01_000002
2013-08-11 09:24:43,618 INFO org.apache.hadoop.yarn.server.resourcemanager.scheduler.common.fica.FiCaSchedulerNode: Released container container_1376212503271_0003_01_000002 of capacity <memory:1024, vCores:1> on host hadoop-320-2:53179, which currently has 1 containers, <memory:2048, vCores:1> used and <memory:6144, vCores:15> available, release resources=true
2013-08-11 09:24:43,619 INFO org.apache.hadoop.yarn.server.resourcemanager.scheduler.capacity.LeafQueue: default used=<memory:3072, vCores:2> numContainers=2 user=ubuntu user-resources=<memory:3072, vCores:2>
2013-08-11 09:24:43,620 INFO org.apache.hadoop.yarn.server.resourcemanager.scheduler.capacity.LeafQueue: completedContainer container=Container: [ContainerId: container_1376212503271_0003_01_000002, NodeId: hadoop-320-2:53179, NodeHttpAddress: hadoop-320-2:8042, Resource: <memory:1024, vCores:1>, Priority: 20, State: NEW, Token: null, Status: container_id {, app_attempt_id {, application_id {, id: 3, cluster_timestamp: 1376212503271, }, attemptId: 1, }, id: 2, }, state: C_COMPLETE, diagnostics: "Container killed by the ApplicationMaster.\n\n", exit_status: 143, ] resource=<memory:1024, vCores:1> queue=default: capacity=1.0, absoluteCapacity=1.0, usedResources=<memory:3072, vCores:2>usedCapacity=0.0625, absoluteUsedCapacity=0.0625, numApps=1, numContainers=2 usedCapacity=0.0625 absoluteUsedCapacity=0.0625 used=<memory:3072, vCores:2> cluster=<memory:49152, vCores:96>
2013-08-11 09:24:43,621 INFO org.apache.hadoop.yarn.server.resourcemanager.scheduler.capacity.ParentQueue: completedContainer queue=root usedCapacity=0.0625 absoluteUsedCapacity=0.0625 used=<memory:3072, vCores:2> cluster=<memory:49152, vCores:96>
2013-08-11 09:24:43,621 INFO org.apache.hadoop.yarn.server.resourcemanager.scheduler.capacity.CapacityScheduler: Application appattempt_1376212503271_0003_000001 released container container_1376212503271_0003_01_000002 on node: host: hadoop-320-2:53179 #containers=1 available=6144 used=2048 with event: FINISHED
2013-08-11 09:24:52,506 INFO org.apache.hadoop.yarn.server.resourcemanager.rmcontainer.RMContainerImpl: container_1376212503271_0003_01_000003 Container Transitioned from RUNNING to COMPLETED
2013-08-11 09:24:52,506 INFO org.apache.hadoop.yarn.server.resourcemanager.scheduler.common.fica.FiCaSchedulerApp: Completed container: container_1376212503271_0003_01_000003 in state: COMPLETED event:FINISHED
2013-08-11 09:24:52,506 INFO org.apache.hadoop.yarn.server.resourcemanager.RMAuditLogger: USER=ubuntu	OPERATION=AM Released Container	TARGET=SchedulerApp	RESULT=SUCCESS	APPID=application_1376212503271_0003	CONTAINERID=container_1376212503271_0003_01_000003
2013-08-11 09:24:52,507 INFO org.apache.hadoop.yarn.server.resourcemanager.scheduler.common.fica.FiCaSchedulerNode: Released container container_1376212503271_0003_01_000003 of capacity <memory:1024, vCores:1> on host hadoop-320-7:48037, which currently has 0 containers, <memory:0, vCores:0> used and <memory:8192, vCores:16> available, release resources=true
2013-08-11 09:24:52,507 INFO org.apache.hadoop.yarn.server.resourcemanager.scheduler.capacity.LeafQueue: default used=<memory:2048, vCores:1> numContainers=1 user=ubuntu user-resources=<memory:2048, vCores:1>
2013-08-11 09:24:52,509 INFO org.apache.hadoop.yarn.server.resourcemanager.scheduler.capacity.LeafQueue: completedContainer container=Container: [ContainerId: container_1376212503271_0003_01_000003, NodeId: hadoop-320-7:48037, NodeHttpAddress: hadoop-320-7:8042, Resource: <memory:1024, vCores:1>, Priority: 20, State: NEW, Token: null, Status: container_id {, app_attempt_id {, application_id {, id: 3, cluster_timestamp: 1376212503271, }, attemptId: 1, }, id: 3, }, state: C_COMPLETE, diagnostics: "Container killed by the ApplicationMaster.\n\n", exit_status: 143, ] resource=<memory:1024, vCores:1> queue=default: capacity=1.0, absoluteCapacity=1.0, usedResources=<memory:2048, vCores:1>usedCapacity=0.041666668, absoluteUsedCapacity=0.041666668, numApps=1, numContainers=1 usedCapacity=0.041666668 absoluteUsedCapacity=0.041666668 used=<memory:2048, vCores:1> cluster=<memory:49152, vCores:96>
2013-08-11 09:24:52,509 INFO org.apache.hadoop.yarn.server.resourcemanager.scheduler.capacity.ParentQueue: completedContainer queue=root usedCapacity=0.041666668 absoluteUsedCapacity=0.041666668 used=<memory:2048, vCores:1> cluster=<memory:49152, vCores:96>
2013-08-11 09:24:52,509 INFO org.apache.hadoop.yarn.server.resourcemanager.scheduler.capacity.CapacityScheduler: Application appattempt_1376212503271_0003_000001 released container container_1376212503271_0003_01_000003 on node: host: hadoop-320-7:48037 #containers=0 available=8192 used=0 with event: FINISHED
2013-08-11 09:24:56,680 INFO org.apache.hadoop.yarn.server.resourcemanager.rmapp.attempt.RMAppAttemptImpl: appattempt_1376212503271_0003_000001 State change from RUNNING to FINISHING
2013-08-11 09:24:56,680 INFO org.apache.hadoop.yarn.server.resourcemanager.rmapp.RMAppImpl: application_1376212503271_0003 State change from RUNNING to FINISHING
2013-08-11 09:24:57,688 INFO org.apache.hadoop.yarn.server.resourcemanager.rmcontainer.RMContainerImpl: container_1376212503271_0003_01_000001 Container Transitioned from RUNNING to COMPLETED
2013-08-11 09:24:57,688 INFO org.apache.hadoop.yarn.server.resourcemanager.scheduler.common.fica.FiCaSchedulerApp: Completed container: container_1376212503271_0003_01_000001 in state: COMPLETED event:FINISHED
2013-08-11 09:24:57,688 INFO org.apache.hadoop.yarn.server.resourcemanager.rmapp.attempt.RMAppAttemptImpl: appattempt_1376212503271_0003_000001 State change from FINISHING to FINISHED
2013-08-11 09:24:57,688 INFO org.apache.hadoop.yarn.server.resourcemanager.RMAuditLogger: USER=ubuntu	OPERATION=AM Released Container	TARGET=SchedulerApp	RESULT=SUCCESS	APPID=application_1376212503271_0003	CONTAINERID=container_1376212503271_0003_01_000001
2013-08-11 09:24:57,689 INFO org.apache.hadoop.yarn.server.resourcemanager.rmapp.RMAppImpl: application_1376212503271_0003 State change from FINISHING to FINISHED
2013-08-11 09:24:57,689 INFO org.apache.hadoop.yarn.server.resourcemanager.scheduler.common.fica.FiCaSchedulerNode: Released container container_1376212503271_0003_01_000001 of capacity <memory:2048, vCores:1> on host hadoop-320-2:53179, which currently has 0 containers, <memory:0, vCores:0> used and <memory:8192, vCores:16> available, release resources=true
2013-08-11 09:24:57,689 INFO org.apache.hadoop.yarn.server.resourcemanager.scheduler.capacity.LeafQueue: default used=<memory:0, vCores:0> numContainers=0 user=ubuntu user-resources=<memory:0, vCores:0>
2013-08-11 09:24:57,689 INFO org.apache.hadoop.yarn.server.resourcemanager.RMAuditLogger: USER=ubuntu	OPERATION=Application Finished - Succeeded	TARGET=RMAppManager	RESULT=SUCCESS	APPID=application_1376212503271_0003
2013-08-11 09:24:57,690 INFO org.apache.hadoop.yarn.server.resourcemanager.amlauncher.AMLauncher: Cleaning master appattempt_1376212503271_0003_000001
2013-08-11 09:24:57,690 INFO org.apache.hadoop.yarn.server.resourcemanager.recovery.RMStateStore: Removing info for app: application_1376212503271_0003
2013-08-11 09:24:57,690 INFO org.apache.hadoop.yarn.server.resourcemanager.RMAppManager$ApplicationSummary: appId=application_1376212503271_0003,name=TeraGen,user=ubuntu,queue=default,state=FINISHED,trackingUrl=hadoop-320-1.novalocal:8088/proxy/application_1376212503271_0003/jobhistory/job/job_1376212503271_0003,appMasterHost=hadoop-320-2,startTime=1376212910194,finishTime=1376213096680
2013-08-11 09:24:57,691 INFO org.apache.hadoop.yarn.server.resourcemanager.scheduler.capacity.LeafQueue: completedContainer container=Container: [ContainerId: container_1376212503271_0003_01_000001, NodeId: hadoop-320-2:53179, NodeHttpAddress: hadoop-320-2:8042, Resource: <memory:2048, vCores:1>, Priority: 0, State: NEW, Token: null, Status: container_id {, app_attempt_id {, application_id {, id: 3, cluster_timestamp: 1376212503271, }, attemptId: 1, }, id: 1, }, state: C_COMPLETE, diagnostics: "", exit_status: 0, ] resource=<memory:2048, vCores:1> queue=default: capacity=1.0, absoluteCapacity=1.0, usedResources=<memory:0, vCores:0>usedCapacity=0.0, absoluteUsedCapacity=0.0, numApps=1, numContainers=0 usedCapacity=0.0 absoluteUsedCapacity=0.0 used=<memory:0, vCores:0> cluster=<memory:49152, vCores:96>
2013-08-11 09:24:57,691 INFO org.apache.hadoop.yarn.server.resourcemanager.scheduler.capacity.ParentQueue: completedContainer queue=root usedCapacity=0.0 absoluteUsedCapacity=0.0 used=<memory:0, vCores:0> cluster=<memory:49152, vCores:96>
2013-08-11 09:24:57,691 INFO org.apache.hadoop.yarn.server.resourcemanager.scheduler.capacity.CapacityScheduler: Application appattempt_1376212503271_0003_000001 released container container_1376212503271_0003_01_000001 on node: host: hadoop-320-2:53179 #containers=0 available=8192 used=0 with event: FINISHED
2013-08-11 09:24:57,691 INFO org.apache.hadoop.yarn.server.resourcemanager.scheduler.capacity.CapacityScheduler: Application appattempt_1376212503271_0003_000001 is done. finalState=FINISHED
2013-08-11 09:24:57,691 INFO org.apache.hadoop.yarn.server.resourcemanager.scheduler.AppSchedulingInfo: Application application_1376212503271_0003 requests cleared
2013-08-11 09:24:57,691 INFO org.apache.hadoop.yarn.server.resourcemanager.scheduler.capacity.LeafQueue: Application removed - appId: application_1376212503271_0003 user: ubuntu queue: default #user-pending-applications: 0 #user-active-applications: 0 #queue-pending-applications: 0 #queue-active-applications: 0
2013-08-11 09:24:57,692 INFO org.apache.hadoop.yarn.server.resourcemanager.scheduler.capacity.ParentQueue: Application removed - appId: application_1376212503271_0003 user: ubuntu leaf-queue of parent: root #applications: 0
2013-08-11 09:24:57,717 INFO org.apache.hadoop.yarn.server.resourcemanager.ClientRMService: Allocated new applicationId: 4
2013-08-11 09:24:59,741 INFO org.apache.hadoop.yarn.server.resourcemanager.ClientRMService: Storing Application with id application_1376212503271_0004
2013-08-11 09:24:59,741 INFO org.apache.hadoop.yarn.server.resourcemanager.recovery.RMStateStore: Storing info for app: application_1376212503271_0004
2013-08-11 09:24:59,741 INFO org.apache.hadoop.yarn.server.resourcemanager.ClientRMService: Application with id 4 submitted by user ubuntu
2013-08-11 09:24:59,741 INFO org.apache.hadoop.yarn.server.resourcemanager.RMAuditLogger: USER=ubuntu	IP=192.168.100.4	OPERATION=Submit Application Request	TARGET=ClientRMService	RESULT=SUCCESS	APPID=application_1376212503271_0004
2013-08-11 09:24:59,743 INFO org.apache.hadoop.yarn.server.resourcemanager.rmapp.RMAppImpl: application_1376212503271_0004 State change from NEW to SUBMITTED
2013-08-11 09:24:59,743 INFO org.apache.hadoop.yarn.server.resourcemanager.ApplicationMasterService: Registering appattempt_1376212503271_0004_000001
2013-08-11 09:24:59,743 INFO org.apache.hadoop.yarn.server.resourcemanager.rmapp.attempt.RMAppAttemptImpl: appattempt_1376212503271_0004_000001 State change from NEW to SUBMITTED
2013-08-11 09:24:59,744 INFO org.apache.hadoop.yarn.server.resourcemanager.scheduler.capacity.LeafQueue: Application application_1376212503271_0004 from user: ubuntu activated in queue: default
2013-08-11 09:24:59,744 INFO org.apache.hadoop.yarn.server.resourcemanager.scheduler.capacity.LeafQueue: Application added - appId: application_1376212503271_0004 user: org.apache.hadoop.yarn.server.resourcemanager.scheduler.capacity.LeafQueue$User@3bead2d, leaf-queue: default #user-pending-applications: 0 #user-active-applications: 1 #queue-pending-applications: 0 #queue-active-applications: 1
2013-08-11 09:24:59,744 INFO org.apache.hadoop.yarn.server.resourcemanager.scheduler.capacity.ParentQueue: Application added - appId: application_1376212503271_0004 user: ubuntu leaf-queue of parent: root #applications: 1
2013-08-11 09:24:59,744 INFO org.apache.hadoop.yarn.server.resourcemanager.scheduler.capacity.CapacityScheduler: Application Submission: appattempt_1376212503271_0004_000001, user: ubuntu queue: default: capacity=1.0, absoluteCapacity=1.0, usedResources=<memory:0, vCores:0>usedCapacity=0.0, absoluteUsedCapacity=0.0, numApps=1, numContainers=0, currently active: 1
2013-08-11 09:24:59,745 INFO org.apache.hadoop.yarn.server.resourcemanager.rmapp.attempt.RMAppAttemptImpl: appattempt_1376212503271_0004_000001 State change from SUBMITTED to SCHEDULED
2013-08-11 09:24:59,745 INFO org.apache.hadoop.yarn.server.resourcemanager.rmapp.RMAppImpl: application_1376212503271_0004 State change from SUBMITTED to ACCEPTED
2013-08-11 09:24:59,893 INFO org.apache.hadoop.yarn.server.resourcemanager.rmcontainer.RMContainerImpl: container_1376212503271_0004_01_000001 Container Transitioned from NEW to ALLOCATED
2013-08-11 09:24:59,894 INFO org.apache.hadoop.yarn.server.resourcemanager.RMAuditLogger: USER=ubuntu	OPERATION=AM Allocated Container	TARGET=SchedulerApp	RESULT=SUCCESS	APPID=application_1376212503271_0004	CONTAINERID=container_1376212503271_0004_01_000001
2013-08-11 09:24:59,894 INFO org.apache.hadoop.yarn.server.resourcemanager.scheduler.common.fica.FiCaSchedulerNode: Assigned container container_1376212503271_0004_01_000001 of capacity <memory:2048, vCores:1> on host hadoop-320-3:47015, which currently has 1 containers, <memory:2048, vCores:1> used and <memory:6144, vCores:15> available
2013-08-11 09:24:59,895 INFO org.apache.hadoop.yarn.server.resourcemanager.scheduler.capacity.LeafQueue: assignedContainer application=application_1376212503271_0004 container=Container: [ContainerId: container_1376212503271_0004_01_000001, NodeId: hadoop-320-3:47015, NodeHttpAddress: hadoop-320-3:8042, Resource: <memory:2048, vCores:1>, Priority: 0, State: NEW, Token: null, Status: container_id {, app_attempt_id {, application_id {, id: 4, cluster_timestamp: 1376212503271, }, attemptId: 1, }, id: 1, }, state: C_NEW, ] containerId=container_1376212503271_0004_01_000001 queue=default: capacity=1.0, absoluteCapacity=1.0, usedResources=<memory:0, vCores:0>usedCapacity=0.0, absoluteUsedCapacity=0.0, numApps=1, numContainers=0 usedCapacity=0.0 absoluteUsedCapacity=0.0 used=<memory:0, vCores:0> cluster=<memory:49152, vCores:96>
2013-08-11 09:24:59,895 INFO org.apache.hadoop.yarn.server.resourcemanager.scheduler.capacity.ParentQueue: Re-sorting queues since queue: root.default stats: default: capacity=1.0, absoluteCapacity=1.0, usedResources=<memory:2048, vCores:1>usedCapacity=0.041666668, absoluteUsedCapacity=0.041666668, numApps=1, numContainers=1
2013-08-11 09:24:59,896 INFO org.apache.hadoop.yarn.server.resourcemanager.scheduler.capacity.ParentQueue: assignedContainer queue=root usedCapacity=0.041666668 absoluteUsedCapacity=0.041666668 used=<memory:2048, vCores:1> cluster=<memory:49152, vCores:96>
2013-08-11 09:24:59,897 INFO org.apache.hadoop.yarn.server.resourcemanager.rmcontainer.RMContainerImpl: container_1376212503271_0004_01_000001 Container Transitioned from ALLOCATED to ACQUIRED
2013-08-11 09:24:59,899 INFO org.apache.hadoop.yarn.server.resourcemanager.rmapp.attempt.RMAppAttemptImpl: Storing attempt: AppId: application_1376212503271_0004 AttemptId: appattempt_1376212503271_0004_000001 MasterContainer: Container: [ContainerId: container_1376212503271_0004_01_000001, NodeId: hadoop-320-3:47015, NodeHttpAddress: hadoop-320-3:8042, Resource: <memory:2048, vCores:1>, Priority: 0, State: NEW, Token: null, Status: container_id {, app_attempt_id {, application_id {, id: 4, cluster_timestamp: 1376212503271, }, attemptId: 1, }, id: 1, }, state: C_NEW, ]
2013-08-11 09:24:59,900 INFO org.apache.hadoop.yarn.server.resourcemanager.recovery.RMStateStore: Storing info for attempt: appattempt_1376212503271_0004_000001
2013-08-11 09:24:59,900 INFO org.apache.hadoop.yarn.server.resourcemanager.rmapp.attempt.RMAppAttemptImpl: appattempt_1376212503271_0004_000001 State change from SCHEDULED to ALLOCATED_SAVING
2013-08-11 09:24:59,903 INFO org.apache.hadoop.yarn.server.resourcemanager.rmapp.attempt.RMAppAttemptImpl: appattempt_1376212503271_0004_000001 State change from ALLOCATED_SAVING to ALLOCATED
2013-08-11 09:24:59,904 INFO org.apache.hadoop.yarn.server.resourcemanager.amlauncher.AMLauncher: Launching masterappattempt_1376212503271_0004_000001
2013-08-11 09:24:59,907 INFO org.apache.hadoop.yarn.server.resourcemanager.amlauncher.AMLauncher: Setting up container Container: [ContainerId: container_1376212503271_0004_01_000001, NodeId: hadoop-320-3:47015, NodeHttpAddress: hadoop-320-3:8042, Resource: <memory:2048, vCores:1>, Priority: 0, State: NEW, Token: null, Status: container_id {, app_attempt_id {, application_id {, id: 4, cluster_timestamp: 1376212503271, }, attemptId: 1, }, id: 1, }, state: C_NEW, ] for AM appattempt_1376212503271_0004_000001
2013-08-11 09:24:59,907 INFO org.apache.hadoop.yarn.server.resourcemanager.amlauncher.AMLauncher: Command to launch container container_1376212503271_0004_01_000001 : $JAVA_HOME/bin/java -Dlog4j.configuration=container-log4j.properties -Dyarn.app.mapreduce.container.log.dir=<LOG_DIR> -Dyarn.app.mapreduce.container.log.filesize=0 -Dhadoop.root.logger=INFO,CLA  -Xmx1024m org.apache.hadoop.mapreduce.v2.app.MRAppMaster 1><LOG_DIR>/stdout 2><LOG_DIR>/stderr 
2013-08-11 09:24:59,924 INFO org.apache.hadoop.yarn.server.resourcemanager.amlauncher.AMLauncher: Done launching container Container: [ContainerId: container_1376212503271_0004_01_000001, NodeId: hadoop-320-3:47015, NodeHttpAddress: hadoop-320-3:8042, Resource: <memory:2048, vCores:1>, Priority: 0, State: NEW, Token: null, Status: container_id {, app_attempt_id {, application_id {, id: 4, cluster_timestamp: 1376212503271, }, attemptId: 1, }, id: 1, }, state: C_NEW, ] for AM appattempt_1376212503271_0004_000001
2013-08-11 09:24:59,925 INFO org.apache.hadoop.yarn.server.resourcemanager.rmapp.attempt.RMAppAttemptImpl: appattempt_1376212503271_0004_000001 State change from ALLOCATED to LAUNCHED
2013-08-11 09:25:00,899 INFO org.apache.hadoop.yarn.server.resourcemanager.rmcontainer.RMContainerImpl: container_1376212503271_0004_01_000001 Container Transitioned from ACQUIRED to RUNNING
2013-08-11 09:25:06,221 INFO org.apache.hadoop.yarn.server.resourcemanager.ApplicationMasterService: AM registration appattempt_1376212503271_0004_000001
2013-08-11 09:25:06,221 INFO org.apache.hadoop.yarn.server.resourcemanager.RMAuditLogger: USER=ubuntu	IP=192.168.100.13	OPERATION=Register App Master	TARGET=ApplicationMasterService	RESULT=SUCCESS	APPID=application_1376212503271_0004	APPATTEMPTID=appattempt_1376212503271_0004_000001
2013-08-11 09:25:06,222 INFO org.apache.hadoop.yarn.server.resourcemanager.rmapp.attempt.RMAppAttemptImpl: appattempt_1376212503271_0004_000001 State change from LAUNCHED to RUNNING
2013-08-11 09:25:06,222 INFO org.apache.hadoop.yarn.server.resourcemanager.rmapp.RMAppImpl: application_1376212503271_0004 State change from ACCEPTED to RUNNING
2013-08-11 09:25:07,560 INFO org.apache.hadoop.yarn.server.resourcemanager.rmcontainer.RMContainerImpl: container_1376212503271_0004_01_000002 Container Transitioned from NEW to ALLOCATED
2013-08-11 09:25:07,560 INFO org.apache.hadoop.yarn.server.resourcemanager.RMAuditLogger: USER=ubuntu	OPERATION=AM Allocated Container	TARGET=SchedulerApp	RESULT=SUCCESS	APPID=application_1376212503271_0004	CONTAINERID=container_1376212503271_0004_01_000002
2013-08-11 09:25:07,560 INFO org.apache.hadoop.yarn.server.resourcemanager.scheduler.common.fica.FiCaSchedulerNode: Assigned container container_1376212503271_0004_01_000002 of capacity <memory:1024, vCores:1> on host hadoop-320-7:48037, which currently has 1 containers, <memory:1024, vCores:1> used and <memory:7168, vCores:15> available
2013-08-11 09:25:07,562 INFO org.apache.hadoop.yarn.server.resourcemanager.scheduler.capacity.LeafQueue: assignedContainer application=application_1376212503271_0004 container=Container: [ContainerId: container_1376212503271_0004_01_000002, NodeId: hadoop-320-7:48037, NodeHttpAddress: hadoop-320-7:8042, Resource: <memory:1024, vCores:1>, Priority: 20, State: NEW, Token: null, Status: container_id {, app_attempt_id {, application_id {, id: 4, cluster_timestamp: 1376212503271, }, attemptId: 1, }, id: 2, }, state: C_NEW, ] containerId=container_1376212503271_0004_01_000002 queue=default: capacity=1.0, absoluteCapacity=1.0, usedResources=<memory:2048, vCores:1>usedCapacity=0.041666668, absoluteUsedCapacity=0.041666668, numApps=1, numContainers=1 usedCapacity=0.041666668 absoluteUsedCapacity=0.041666668 used=<memory:2048, vCores:1> cluster=<memory:49152, vCores:96>
2013-08-11 09:25:07,562 INFO org.apache.hadoop.yarn.server.resourcemanager.scheduler.capacity.ParentQueue: Re-sorting queues since queue: root.default stats: default: capacity=1.0, absoluteCapacity=1.0, usedResources=<memory:3072, vCores:2>usedCapacity=0.0625, absoluteUsedCapacity=0.0625, numApps=1, numContainers=2
2013-08-11 09:25:07,562 INFO org.apache.hadoop.yarn.server.resourcemanager.scheduler.capacity.ParentQueue: assignedContainer queue=root usedCapacity=0.0625 absoluteUsedCapacity=0.0625 used=<memory:3072, vCores:2> cluster=<memory:49152, vCores:96>
2013-08-11 09:25:07,722 INFO org.apache.hadoop.yarn.server.resourcemanager.rmcontainer.RMContainerImpl: container_1376212503271_0004_01_000003 Container Transitioned from NEW to ALLOCATED
2013-08-11 09:25:07,722 INFO org.apache.hadoop.yarn.server.resourcemanager.RMAuditLogger: USER=ubuntu	OPERATION=AM Allocated Container	TARGET=SchedulerApp	RESULT=SUCCESS	APPID=application_1376212503271_0004	CONTAINERID=container_1376212503271_0004_01_000003
2013-08-11 09:25:07,722 INFO org.apache.hadoop.yarn.server.resourcemanager.scheduler.common.fica.FiCaSchedulerNode: Assigned container container_1376212503271_0004_01_000003 of capacity <memory:1024, vCores:1> on host hadoop-320-2:53179, which currently has 1 containers, <memory:1024, vCores:1> used and <memory:7168, vCores:15> available
2013-08-11 09:25:07,723 INFO org.apache.hadoop.yarn.server.resourcemanager.scheduler.capacity.LeafQueue: assignedContainer application=application_1376212503271_0004 container=Container: [ContainerId: container_1376212503271_0004_01_000003, NodeId: hadoop-320-2:53179, NodeHttpAddress: hadoop-320-2:8042, Resource: <memory:1024, vCores:1>, Priority: 20, State: NEW, Token: null, Status: container_id {, app_attempt_id {, application_id {, id: 4, cluster_timestamp: 1376212503271, }, attemptId: 1, }, id: 3, }, state: C_NEW, ] containerId=container_1376212503271_0004_01_000003 queue=default: capacity=1.0, absoluteCapacity=1.0, usedResources=<memory:3072, vCores:2>usedCapacity=0.0625, absoluteUsedCapacity=0.0625, numApps=1, numContainers=2 usedCapacity=0.0625 absoluteUsedCapacity=0.0625 used=<memory:3072, vCores:2> cluster=<memory:49152, vCores:96>
2013-08-11 09:25:07,724 INFO org.apache.hadoop.yarn.server.resourcemanager.scheduler.capacity.ParentQueue: Re-sorting queues since queue: root.default stats: default: capacity=1.0, absoluteCapacity=1.0, usedResources=<memory:4096, vCores:3>usedCapacity=0.083333336, absoluteUsedCapacity=0.083333336, numApps=1, numContainers=3
2013-08-11 09:25:07,724 INFO org.apache.hadoop.yarn.server.resourcemanager.scheduler.capacity.ParentQueue: assignedContainer queue=root usedCapacity=0.083333336 absoluteUsedCapacity=0.083333336 used=<memory:4096, vCores:3> cluster=<memory:49152, vCores:96>
2013-08-11 09:25:08,270 INFO org.apache.hadoop.yarn.server.resourcemanager.rmcontainer.RMContainerImpl: container_1376212503271_0004_01_000002 Container Transitioned from ALLOCATED to ACQUIRED
2013-08-11 09:25:08,271 INFO org.apache.hadoop.yarn.server.resourcemanager.rmcontainer.RMContainerImpl: container_1376212503271_0004_01_000003 Container Transitioned from ALLOCATED to ACQUIRED
2013-08-11 09:25:08,565 INFO org.apache.hadoop.yarn.server.resourcemanager.rmcontainer.RMContainerImpl: container_1376212503271_0004_01_000002 Container Transitioned from ACQUIRED to RUNNING
2013-08-11 09:25:08,728 INFO org.apache.hadoop.yarn.server.resourcemanager.rmcontainer.RMContainerImpl: container_1376212503271_0004_01_000003 Container Transitioned from ACQUIRED to RUNNING
2013-08-11 09:25:09,300 INFO org.apache.hadoop.yarn.server.resourcemanager.scheduler.AppSchedulingInfo: checking for deactivate... 
2013-08-11 09:27:51,640 INFO org.apache.hadoop.yarn.server.resourcemanager.rmcontainer.RMContainerImpl: container_1376212503271_0004_01_000002 Container Transitioned from RUNNING to COMPLETED
2013-08-11 09:27:51,641 INFO org.apache.hadoop.yarn.server.resourcemanager.scheduler.common.fica.FiCaSchedulerApp: Completed container: container_1376212503271_0004_01_000002 in state: COMPLETED event:FINISHED
2013-08-11 09:27:51,641 INFO org.apache.hadoop.yarn.server.resourcemanager.RMAuditLogger: USER=ubuntu	OPERATION=AM Released Container	TARGET=SchedulerApp	RESULT=SUCCESS	APPID=application_1376212503271_0004	CONTAINERID=container_1376212503271_0004_01_000002
2013-08-11 09:27:51,641 INFO org.apache.hadoop.yarn.server.resourcemanager.scheduler.common.fica.FiCaSchedulerNode: Released container container_1376212503271_0004_01_000002 of capacity <memory:1024, vCores:1> on host hadoop-320-7:48037, which currently has 0 containers, <memory:0, vCores:0> used and <memory:8192, vCores:16> available, release resources=true
2013-08-11 09:27:51,641 INFO org.apache.hadoop.yarn.server.resourcemanager.scheduler.capacity.LeafQueue: default used=<memory:3072, vCores:2> numContainers=2 user=ubuntu user-resources=<memory:3072, vCores:2>
2013-08-11 09:27:51,643 INFO org.apache.hadoop.yarn.server.resourcemanager.scheduler.capacity.LeafQueue: completedContainer container=Container: [ContainerId: container_1376212503271_0004_01_000002, NodeId: hadoop-320-7:48037, NodeHttpAddress: hadoop-320-7:8042, Resource: <memory:1024, vCores:1>, Priority: 20, State: NEW, Token: null, Status: container_id {, app_attempt_id {, application_id {, id: 4, cluster_timestamp: 1376212503271, }, attemptId: 1, }, id: 2, }, state: C_COMPLETE, diagnostics: "Container killed by the ApplicationMaster.\n\n", exit_status: 143, ] resource=<memory:1024, vCores:1> queue=default: capacity=1.0, absoluteCapacity=1.0, usedResources=<memory:3072, vCores:2>usedCapacity=0.0625, absoluteUsedCapacity=0.0625, numApps=1, numContainers=2 usedCapacity=0.0625 absoluteUsedCapacity=0.0625 used=<memory:3072, vCores:2> cluster=<memory:49152, vCores:96>
2013-08-11 09:27:51,643 INFO org.apache.hadoop.yarn.server.resourcemanager.scheduler.capacity.ParentQueue: completedContainer queue=root usedCapacity=0.0625 absoluteUsedCapacity=0.0625 used=<memory:3072, vCores:2> cluster=<memory:49152, vCores:96>
2013-08-11 09:27:51,643 INFO org.apache.hadoop.yarn.server.resourcemanager.scheduler.capacity.CapacityScheduler: Application appattempt_1376212503271_0004_000001 released container container_1376212503271_0004_01_000002 on node: host: hadoop-320-7:48037 #containers=0 available=8192 used=0 with event: FINISHED
2013-08-11 09:27:54,479 INFO org.apache.hadoop.yarn.server.resourcemanager.rmcontainer.RMContainerImpl: container_1376212503271_0004_01_000003 Container Transitioned from RUNNING to COMPLETED
2013-08-11 09:27:54,479 INFO org.apache.hadoop.yarn.server.resourcemanager.scheduler.common.fica.FiCaSchedulerApp: Completed container: container_1376212503271_0004_01_000003 in state: COMPLETED event:FINISHED
2013-08-11 09:27:54,479 INFO org.apache.hadoop.yarn.server.resourcemanager.RMAuditLogger: USER=ubuntu	OPERATION=AM Released Container	TARGET=SchedulerApp	RESULT=SUCCESS	APPID=application_1376212503271_0004	CONTAINERID=container_1376212503271_0004_01_000003
2013-08-11 09:27:54,479 INFO org.apache.hadoop.yarn.server.resourcemanager.scheduler.common.fica.FiCaSchedulerNode: Released container container_1376212503271_0004_01_000003 of capacity <memory:1024, vCores:1> on host hadoop-320-2:53179, which currently has 0 containers, <memory:0, vCores:0> used and <memory:8192, vCores:16> available, release resources=true
2013-08-11 09:27:54,479 INFO org.apache.hadoop.yarn.server.resourcemanager.scheduler.capacity.LeafQueue: default used=<memory:2048, vCores:1> numContainers=1 user=ubuntu user-resources=<memory:2048, vCores:1>
2013-08-11 09:27:54,481 INFO org.apache.hadoop.yarn.server.resourcemanager.scheduler.capacity.LeafQueue: completedContainer container=Container: [ContainerId: container_1376212503271_0004_01_000003, NodeId: hadoop-320-2:53179, NodeHttpAddress: hadoop-320-2:8042, Resource: <memory:1024, vCores:1>, Priority: 20, State: NEW, Token: null, Status: container_id {, app_attempt_id {, application_id {, id: 4, cluster_timestamp: 1376212503271, }, attemptId: 1, }, id: 3, }, state: C_COMPLETE, diagnostics: "Container killed by the ApplicationMaster.\n\n", exit_status: 143, ] resource=<memory:1024, vCores:1> queue=default: capacity=1.0, absoluteCapacity=1.0, usedResources=<memory:2048, vCores:1>usedCapacity=0.041666668, absoluteUsedCapacity=0.041666668, numApps=1, numContainers=1 usedCapacity=0.041666668 absoluteUsedCapacity=0.041666668 used=<memory:2048, vCores:1> cluster=<memory:49152, vCores:96>
2013-08-11 09:27:54,481 INFO org.apache.hadoop.yarn.server.resourcemanager.scheduler.capacity.ParentQueue: completedContainer queue=root usedCapacity=0.041666668 absoluteUsedCapacity=0.041666668 used=<memory:2048, vCores:1> cluster=<memory:49152, vCores:96>
2013-08-11 09:27:54,481 INFO org.apache.hadoop.yarn.server.resourcemanager.scheduler.capacity.CapacityScheduler: Application appattempt_1376212503271_0004_000001 released container container_1376212503271_0004_01_000003 on node: host: hadoop-320-2:53179 #containers=0 available=8192 used=0 with event: FINISHED
2013-08-11 09:27:58,698 INFO org.apache.hadoop.yarn.server.resourcemanager.rmapp.attempt.RMAppAttemptImpl: appattempt_1376212503271_0004_000001 State change from RUNNING to FINISHING
2013-08-11 09:27:58,699 INFO org.apache.hadoop.yarn.server.resourcemanager.rmapp.RMAppImpl: application_1376212503271_0004 State change from RUNNING to FINISHING
2013-08-11 09:27:59,365 INFO org.apache.hadoop.yarn.server.resourcemanager.rmcontainer.RMContainerImpl: container_1376212503271_0004_01_000001 Container Transitioned from RUNNING to COMPLETED
2013-08-11 09:27:59,366 INFO org.apache.hadoop.yarn.server.resourcemanager.scheduler.common.fica.FiCaSchedulerApp: Completed container: container_1376212503271_0004_01_000001 in state: COMPLETED event:FINISHED
2013-08-11 09:27:59,366 INFO org.apache.hadoop.yarn.server.resourcemanager.RMAuditLogger: USER=ubuntu	OPERATION=AM Released Container	TARGET=SchedulerApp	RESULT=SUCCESS	APPID=application_1376212503271_0004	CONTAINERID=container_1376212503271_0004_01_000001
2013-08-11 09:27:59,366 INFO org.apache.hadoop.yarn.server.resourcemanager.rmapp.attempt.RMAppAttemptImpl: appattempt_1376212503271_0004_000001 State change from FINISHING to FINISHED
2013-08-11 09:27:59,366 INFO org.apache.hadoop.yarn.server.resourcemanager.scheduler.common.fica.FiCaSchedulerNode: Released container container_1376212503271_0004_01_000001 of capacity <memory:2048, vCores:1> on host hadoop-320-3:47015, which currently has 0 containers, <memory:0, vCores:0> used and <memory:8192, vCores:16> available, release resources=true
2013-08-11 09:27:59,366 INFO org.apache.hadoop.yarn.server.resourcemanager.rmapp.RMAppImpl: application_1376212503271_0004 State change from FINISHING to FINISHED
2013-08-11 09:27:59,366 INFO org.apache.hadoop.yarn.server.resourcemanager.scheduler.capacity.LeafQueue: default used=<memory:0, vCores:0> numContainers=0 user=ubuntu user-resources=<memory:0, vCores:0>
2013-08-11 09:27:59,367 INFO org.apache.hadoop.yarn.server.resourcemanager.RMAuditLogger: USER=ubuntu	OPERATION=Application Finished - Succeeded	TARGET=RMAppManager	RESULT=SUCCESS	APPID=application_1376212503271_0004
2013-08-11 09:27:59,367 INFO org.apache.hadoop.yarn.server.resourcemanager.RMAppManager$ApplicationSummary: appId=application_1376212503271_0004,name=TeraGen,user=ubuntu,queue=default,state=FINISHED,trackingUrl=hadoop-320-1.novalocal:8088/proxy/application_1376212503271_0004/jobhistory/job/job_1376212503271_0004,appMasterHost=hadoop-320-3,startTime=1376213099740,finishTime=1376213278699
2013-08-11 09:27:59,367 INFO org.apache.hadoop.yarn.server.resourcemanager.recovery.RMStateStore: Removing info for app: application_1376212503271_0004
2013-08-11 09:27:59,368 INFO org.apache.hadoop.yarn.server.resourcemanager.amlauncher.AMLauncher: Cleaning master appattempt_1376212503271_0004_000001
2013-08-11 09:27:59,368 INFO org.apache.hadoop.yarn.server.resourcemanager.scheduler.capacity.LeafQueue: completedContainer container=Container: [ContainerId: container_1376212503271_0004_01_000001, NodeId: hadoop-320-3:47015, NodeHttpAddress: hadoop-320-3:8042, Resource: <memory:2048, vCores:1>, Priority: 0, State: NEW, Token: null, Status: container_id {, app_attempt_id {, application_id {, id: 4, cluster_timestamp: 1376212503271, }, attemptId: 1, }, id: 1, }, state: C_COMPLETE, diagnostics: "", exit_status: 0, ] resource=<memory:2048, vCores:1> queue=default: capacity=1.0, absoluteCapacity=1.0, usedResources=<memory:0, vCores:0>usedCapacity=0.0, absoluteUsedCapacity=0.0, numApps=1, numContainers=0 usedCapacity=0.0 absoluteUsedCapacity=0.0 used=<memory:0, vCores:0> cluster=<memory:49152, vCores:96>
2013-08-11 09:27:59,368 INFO org.apache.hadoop.yarn.server.resourcemanager.scheduler.capacity.ParentQueue: completedContainer queue=root usedCapacity=0.0 absoluteUsedCapacity=0.0 used=<memory:0, vCores:0> cluster=<memory:49152, vCores:96>
2013-08-11 09:27:59,368 INFO org.apache.hadoop.yarn.server.resourcemanager.scheduler.capacity.CapacityScheduler: Application appattempt_1376212503271_0004_000001 released container container_1376212503271_0004_01_000001 on node: host: hadoop-320-3:47015 #containers=0 available=8192 used=0 with event: FINISHED
2013-08-11 09:27:59,368 INFO org.apache.hadoop.yarn.server.resourcemanager.scheduler.capacity.CapacityScheduler: Application appattempt_1376212503271_0004_000001 is done. finalState=FINISHED
2013-08-11 09:27:59,369 INFO org.apache.hadoop.yarn.server.resourcemanager.scheduler.AppSchedulingInfo: Application application_1376212503271_0004 requests cleared
2013-08-11 09:27:59,369 INFO org.apache.hadoop.yarn.server.resourcemanager.scheduler.capacity.LeafQueue: Application removed - appId: application_1376212503271_0004 user: ubuntu queue: default #user-pending-applications: 0 #user-active-applications: 0 #queue-pending-applications: 0 #queue-active-applications: 0
2013-08-11 09:27:59,369 INFO org.apache.hadoop.yarn.server.resourcemanager.scheduler.capacity.ParentQueue: Application removed - appId: application_1376212503271_0004 user: ubuntu leaf-queue of parent: root #applications: 0
2013-08-11 09:27:59,911 INFO org.apache.hadoop.yarn.server.resourcemanager.ClientRMService: Allocated new applicationId: 5
2013-08-11 09:28:01,798 INFO org.apache.hadoop.yarn.server.resourcemanager.ClientRMService: Storing Application with id application_1376212503271_0005
2013-08-11 09:28:01,799 INFO org.apache.hadoop.yarn.server.resourcemanager.recovery.RMStateStore: Storing info for app: application_1376212503271_0005
2013-08-11 09:28:01,799 INFO org.apache.hadoop.yarn.server.resourcemanager.ClientRMService: Application with id 5 submitted by user ubuntu
2013-08-11 09:28:01,799 INFO org.apache.hadoop.yarn.server.resourcemanager.RMAuditLogger: USER=ubuntu	IP=192.168.100.4	OPERATION=Submit Application Request	TARGET=ClientRMService	RESULT=SUCCESS	APPID=application_1376212503271_0005
2013-08-11 09:28:01,806 INFO org.apache.hadoop.yarn.server.resourcemanager.rmapp.RMAppImpl: application_1376212503271_0005 State change from NEW to SUBMITTED
2013-08-11 09:28:01,807 INFO org.apache.hadoop.yarn.server.resourcemanager.ApplicationMasterService: Registering appattempt_1376212503271_0005_000001
2013-08-11 09:28:01,807 INFO org.apache.hadoop.yarn.server.resourcemanager.rmapp.attempt.RMAppAttemptImpl: appattempt_1376212503271_0005_000001 State change from NEW to SUBMITTED
2013-08-11 09:28:01,808 INFO org.apache.hadoop.yarn.server.resourcemanager.scheduler.capacity.LeafQueue: Application application_1376212503271_0005 from user: ubuntu activated in queue: default
2013-08-11 09:28:01,808 INFO org.apache.hadoop.yarn.server.resourcemanager.scheduler.capacity.LeafQueue: Application added - appId: application_1376212503271_0005 user: org.apache.hadoop.yarn.server.resourcemanager.scheduler.capacity.LeafQueue$User@a151d3, leaf-queue: default #user-pending-applications: 0 #user-active-applications: 1 #queue-pending-applications: 0 #queue-active-applications: 1
2013-08-11 09:28:01,808 INFO org.apache.hadoop.yarn.server.resourcemanager.scheduler.capacity.ParentQueue: Application added - appId: application_1376212503271_0005 user: ubuntu leaf-queue of parent: root #applications: 1
2013-08-11 09:28:01,808 INFO org.apache.hadoop.yarn.server.resourcemanager.scheduler.capacity.CapacityScheduler: Application Submission: appattempt_1376212503271_0005_000001, user: ubuntu queue: default: capacity=1.0, absoluteCapacity=1.0, usedResources=<memory:0, vCores:0>usedCapacity=0.0, absoluteUsedCapacity=0.0, numApps=1, numContainers=0, currently active: 1
2013-08-11 09:28:01,808 INFO org.apache.hadoop.yarn.server.resourcemanager.rmapp.attempt.RMAppAttemptImpl: appattempt_1376212503271_0005_000001 State change from SUBMITTED to SCHEDULED
2013-08-11 09:28:01,809 INFO org.apache.hadoop.yarn.server.resourcemanager.rmapp.RMAppImpl: application_1376212503271_0005 State change from SUBMITTED to ACCEPTED
2013-08-11 09:28:01,836 INFO org.apache.hadoop.yarn.server.resourcemanager.rmcontainer.RMContainerImpl: container_1376212503271_0005_01_000001 Container Transitioned from NEW to ALLOCATED
2013-08-11 09:28:01,836 INFO org.apache.hadoop.yarn.server.resourcemanager.RMAuditLogger: USER=ubuntu	OPERATION=AM Allocated Container	TARGET=SchedulerApp	RESULT=SUCCESS	APPID=application_1376212503271_0005	CONTAINERID=container_1376212503271_0005_01_000001
2013-08-11 09:28:01,836 INFO org.apache.hadoop.yarn.server.resourcemanager.scheduler.common.fica.FiCaSchedulerNode: Assigned container container_1376212503271_0005_01_000001 of capacity <memory:2048, vCores:1> on host hadoop-320-6:38980, which currently has 1 containers, <memory:2048, vCores:1> used and <memory:6144, vCores:15> available
2013-08-11 09:28:01,838 INFO org.apache.hadoop.yarn.server.resourcemanager.scheduler.capacity.LeafQueue: assignedContainer application=application_1376212503271_0005 container=Container: [ContainerId: container_1376212503271_0005_01_000001, NodeId: hadoop-320-6:38980, NodeHttpAddress: hadoop-320-6:8042, Resource: <memory:2048, vCores:1>, Priority: 0, State: NEW, Token: null, Status: container_id {, app_attempt_id {, application_id {, id: 5, cluster_timestamp: 1376212503271, }, attemptId: 1, }, id: 1, }, state: C_NEW, ] containerId=container_1376212503271_0005_01_000001 queue=default: capacity=1.0, absoluteCapacity=1.0, usedResources=<memory:0, vCores:0>usedCapacity=0.0, absoluteUsedCapacity=0.0, numApps=1, numContainers=0 usedCapacity=0.0 absoluteUsedCapacity=0.0 used=<memory:0, vCores:0> cluster=<memory:49152, vCores:96>
2013-08-11 09:28:01,838 INFO org.apache.hadoop.yarn.server.resourcemanager.scheduler.capacity.ParentQueue: Re-sorting queues since queue: root.default stats: default: capacity=1.0, absoluteCapacity=1.0, usedResources=<memory:2048, vCores:1>usedCapacity=0.041666668, absoluteUsedCapacity=0.041666668, numApps=1, numContainers=1
2013-08-11 09:28:01,838 INFO org.apache.hadoop.yarn.server.resourcemanager.scheduler.capacity.ParentQueue: assignedContainer queue=root usedCapacity=0.041666668 absoluteUsedCapacity=0.041666668 used=<memory:2048, vCores:1> cluster=<memory:49152, vCores:96>
2013-08-11 09:28:01,840 INFO org.apache.hadoop.yarn.server.resourcemanager.rmcontainer.RMContainerImpl: container_1376212503271_0005_01_000001 Container Transitioned from ALLOCATED to ACQUIRED
2013-08-11 09:28:01,841 INFO org.apache.hadoop.yarn.server.resourcemanager.rmapp.attempt.RMAppAttemptImpl: Storing attempt: AppId: application_1376212503271_0005 AttemptId: appattempt_1376212503271_0005_000001 MasterContainer: Container: [ContainerId: container_1376212503271_0005_01_000001, NodeId: hadoop-320-6:38980, NodeHttpAddress: hadoop-320-6:8042, Resource: <memory:2048, vCores:1>, Priority: 0, State: NEW, Token: null, Status: container_id {, app_attempt_id {, application_id {, id: 5, cluster_timestamp: 1376212503271, }, attemptId: 1, }, id: 1, }, state: C_NEW, ]
2013-08-11 09:28:01,842 INFO org.apache.hadoop.yarn.server.resourcemanager.recovery.RMStateStore: Storing info for attempt: appattempt_1376212503271_0005_000001
2013-08-11 09:28:01,842 INFO org.apache.hadoop.yarn.server.resourcemanager.rmapp.attempt.RMAppAttemptImpl: appattempt_1376212503271_0005_000001 State change from SCHEDULED to ALLOCATED_SAVING
2013-08-11 09:28:01,843 INFO org.apache.hadoop.yarn.server.resourcemanager.rmapp.attempt.RMAppAttemptImpl: appattempt_1376212503271_0005_000001 State change from ALLOCATED_SAVING to ALLOCATED
2013-08-11 09:28:01,844 INFO org.apache.hadoop.yarn.server.resourcemanager.amlauncher.AMLauncher: Launching masterappattempt_1376212503271_0005_000001
2013-08-11 09:28:01,847 INFO org.apache.hadoop.yarn.server.resourcemanager.amlauncher.AMLauncher: Setting up container Container: [ContainerId: container_1376212503271_0005_01_000001, NodeId: hadoop-320-6:38980, NodeHttpAddress: hadoop-320-6:8042, Resource: <memory:2048, vCores:1>, Priority: 0, State: NEW, Token: null, Status: container_id {, app_attempt_id {, application_id {, id: 5, cluster_timestamp: 1376212503271, }, attemptId: 1, }, id: 1, }, state: C_NEW, ] for AM appattempt_1376212503271_0005_000001
2013-08-11 09:28:01,847 INFO org.apache.hadoop.yarn.server.resourcemanager.amlauncher.AMLauncher: Command to launch container container_1376212503271_0005_01_000001 : $JAVA_HOME/bin/java -Dlog4j.configuration=container-log4j.properties -Dyarn.app.mapreduce.container.log.dir=<LOG_DIR> -Dyarn.app.mapreduce.container.log.filesize=0 -Dhadoop.root.logger=INFO,CLA  -Xmx1024m org.apache.hadoop.mapreduce.v2.app.MRAppMaster 1><LOG_DIR>/stdout 2><LOG_DIR>/stderr 
2013-08-11 09:28:02,741 INFO org.apache.hadoop.yarn.server.resourcemanager.amlauncher.AMLauncher: Done launching container Container: [ContainerId: container_1376212503271_0005_01_000001, NodeId: hadoop-320-6:38980, NodeHttpAddress: hadoop-320-6:8042, Resource: <memory:2048, vCores:1>, Priority: 0, State: NEW, Token: null, Status: container_id {, app_attempt_id {, application_id {, id: 5, cluster_timestamp: 1376212503271, }, attemptId: 1, }, id: 1, }, state: C_NEW, ] for AM appattempt_1376212503271_0005_000001
2013-08-11 09:28:02,741 INFO org.apache.hadoop.yarn.server.resourcemanager.rmapp.attempt.RMAppAttemptImpl: appattempt_1376212503271_0005_000001 State change from ALLOCATED to LAUNCHED
2013-08-11 09:28:02,858 INFO org.apache.hadoop.yarn.server.resourcemanager.rmcontainer.RMContainerImpl: container_1376212503271_0005_01_000001 Container Transitioned from ACQUIRED to RUNNING
2013-08-11 09:28:13,404 INFO org.apache.hadoop.yarn.server.resourcemanager.ApplicationMasterService: AM registration appattempt_1376212503271_0005_000001
2013-08-11 09:28:13,404 INFO org.apache.hadoop.yarn.server.resourcemanager.RMAuditLogger: USER=ubuntu	IP=192.168.100.18	OPERATION=Register App Master	TARGET=ApplicationMasterService	RESULT=SUCCESS	APPID=application_1376212503271_0005	APPATTEMPTID=appattempt_1376212503271_0005_000001
2013-08-11 09:28:13,405 INFO org.apache.hadoop.yarn.server.resourcemanager.rmapp.attempt.RMAppAttemptImpl: appattempt_1376212503271_0005_000001 State change from LAUNCHED to RUNNING
2013-08-11 09:28:13,405 INFO org.apache.hadoop.yarn.server.resourcemanager.rmapp.RMAppImpl: application_1376212503271_0005 State change from ACCEPTED to RUNNING
2013-08-11 09:28:14,544 INFO org.apache.hadoop.yarn.server.resourcemanager.rmcontainer.RMContainerImpl: container_1376212503271_0005_01_000002 Container Transitioned from NEW to ALLOCATED
2013-08-11 09:28:14,544 INFO org.apache.hadoop.yarn.server.resourcemanager.RMAuditLogger: USER=ubuntu	OPERATION=AM Allocated Container	TARGET=SchedulerApp	RESULT=SUCCESS	APPID=application_1376212503271_0005	CONTAINERID=container_1376212503271_0005_01_000002
2013-08-11 09:28:14,544 INFO org.apache.hadoop.yarn.server.resourcemanager.scheduler.common.fica.FiCaSchedulerNode: Assigned container container_1376212503271_0005_01_000002 of capacity <memory:1024, vCores:1> on host hadoop-320-2:53179, which currently has 1 containers, <memory:1024, vCores:1> used and <memory:7168, vCores:15> available
2013-08-11 09:28:14,546 INFO org.apache.hadoop.yarn.server.resourcemanager.scheduler.capacity.LeafQueue: assignedContainer application=application_1376212503271_0005 container=Container: [ContainerId: container_1376212503271_0005_01_000002, NodeId: hadoop-320-2:53179, NodeHttpAddress: hadoop-320-2:8042, Resource: <memory:1024, vCores:1>, Priority: 20, State: NEW, Token: null, Status: container_id {, app_attempt_id {, application_id {, id: 5, cluster_timestamp: 1376212503271, }, attemptId: 1, }, id: 2, }, state: C_NEW, ] containerId=container_1376212503271_0005_01_000002 queue=default: capacity=1.0, absoluteCapacity=1.0, usedResources=<memory:2048, vCores:1>usedCapacity=0.041666668, absoluteUsedCapacity=0.041666668, numApps=1, numContainers=1 usedCapacity=0.041666668 absoluteUsedCapacity=0.041666668 used=<memory:2048, vCores:1> cluster=<memory:49152, vCores:96>
2013-08-11 09:28:14,546 INFO org.apache.hadoop.yarn.server.resourcemanager.scheduler.capacity.ParentQueue: Re-sorting queues since queue: root.default stats: default: capacity=1.0, absoluteCapacity=1.0, usedResources=<memory:3072, vCores:2>usedCapacity=0.0625, absoluteUsedCapacity=0.0625, numApps=1, numContainers=2
2013-08-11 09:28:14,546 INFO org.apache.hadoop.yarn.server.resourcemanager.scheduler.capacity.ParentQueue: assignedContainer queue=root usedCapacity=0.0625 absoluteUsedCapacity=0.0625 used=<memory:3072, vCores:2> cluster=<memory:49152, vCores:96>
2013-08-11 09:28:14,715 INFO org.apache.hadoop.yarn.server.resourcemanager.rmcontainer.RMContainerImpl: container_1376212503271_0005_01_000003 Container Transitioned from NEW to ALLOCATED
2013-08-11 09:28:14,716 INFO org.apache.hadoop.yarn.server.resourcemanager.RMAuditLogger: USER=ubuntu	OPERATION=AM Allocated Container	TARGET=SchedulerApp	RESULT=SUCCESS	APPID=application_1376212503271_0005	CONTAINERID=container_1376212503271_0005_01_000003
2013-08-11 09:28:14,716 INFO org.apache.hadoop.yarn.server.resourcemanager.scheduler.common.fica.FiCaSchedulerNode: Assigned container container_1376212503271_0005_01_000003 of capacity <memory:1024, vCores:1> on host hadoop-320-7:48037, which currently has 1 containers, <memory:1024, vCores:1> used and <memory:7168, vCores:15> available
2013-08-11 09:28:14,717 INFO org.apache.hadoop.yarn.server.resourcemanager.scheduler.capacity.LeafQueue: assignedContainer application=application_1376212503271_0005 container=Container: [ContainerId: container_1376212503271_0005_01_000003, NodeId: hadoop-320-7:48037, NodeHttpAddress: hadoop-320-7:8042, Resource: <memory:1024, vCores:1>, Priority: 20, State: NEW, Token: null, Status: container_id {, app_attempt_id {, application_id {, id: 5, cluster_timestamp: 1376212503271, }, attemptId: 1, }, id: 3, }, state: C_NEW, ] containerId=container_1376212503271_0005_01_000003 queue=default: capacity=1.0, absoluteCapacity=1.0, usedResources=<memory:3072, vCores:2>usedCapacity=0.0625, absoluteUsedCapacity=0.0625, numApps=1, numContainers=2 usedCapacity=0.0625 absoluteUsedCapacity=0.0625 used=<memory:3072, vCores:2> cluster=<memory:49152, vCores:96>
2013-08-11 09:28:14,717 INFO org.apache.hadoop.yarn.server.resourcemanager.scheduler.capacity.ParentQueue: Re-sorting queues since queue: root.default stats: default: capacity=1.0, absoluteCapacity=1.0, usedResources=<memory:4096, vCores:3>usedCapacity=0.083333336, absoluteUsedCapacity=0.083333336, numApps=1, numContainers=3
2013-08-11 09:28:14,717 INFO org.apache.hadoop.yarn.server.resourcemanager.scheduler.capacity.ParentQueue: assignedContainer queue=root usedCapacity=0.083333336 absoluteUsedCapacity=0.083333336 used=<memory:4096, vCores:3> cluster=<memory:49152, vCores:96>
2013-08-11 09:28:15,464 INFO org.apache.hadoop.yarn.server.resourcemanager.rmcontainer.RMContainerImpl: container_1376212503271_0005_01_000002 Container Transitioned from ALLOCATED to ACQUIRED
2013-08-11 09:28:15,468 INFO org.apache.hadoop.yarn.server.resourcemanager.rmcontainer.RMContainerImpl: container_1376212503271_0005_01_000003 Container Transitioned from ALLOCATED to ACQUIRED
2013-08-11 09:28:16,494 INFO org.apache.hadoop.yarn.server.resourcemanager.scheduler.AppSchedulingInfo: checking for deactivate... 
2013-08-11 09:28:16,552 INFO org.apache.hadoop.yarn.server.resourcemanager.rmcontainer.RMContainerImpl: container_1376212503271_0005_01_000002 Container Transitioned from ACQUIRED to RUNNING
2013-08-11 09:28:16,724 INFO org.apache.hadoop.yarn.server.resourcemanager.rmcontainer.RMContainerImpl: container_1376212503271_0005_01_000003 Container Transitioned from ACQUIRED to RUNNING
2013-08-11 09:31:04,268 INFO org.apache.hadoop.yarn.server.resourcemanager.rmcontainer.RMContainerImpl: container_1376212503271_0005_01_000003 Container Transitioned from RUNNING to COMPLETED
2013-08-11 09:31:04,268 INFO org.apache.hadoop.yarn.server.resourcemanager.scheduler.common.fica.FiCaSchedulerApp: Completed container: container_1376212503271_0005_01_000003 in state: COMPLETED event:FINISHED
2013-08-11 09:31:04,268 INFO org.apache.hadoop.yarn.server.resourcemanager.RMAuditLogger: USER=ubuntu	OPERATION=AM Released Container	TARGET=SchedulerApp	RESULT=SUCCESS	APPID=application_1376212503271_0005	CONTAINERID=container_1376212503271_0005_01_000003
2013-08-11 09:31:04,268 INFO org.apache.hadoop.yarn.server.resourcemanager.scheduler.common.fica.FiCaSchedulerNode: Released container container_1376212503271_0005_01_000003 of capacity <memory:1024, vCores:1> on host hadoop-320-7:48037, which currently has 0 containers, <memory:0, vCores:0> used and <memory:8192, vCores:16> available, release resources=true
2013-08-11 09:31:04,268 INFO org.apache.hadoop.yarn.server.resourcemanager.scheduler.capacity.LeafQueue: default used=<memory:3072, vCores:2> numContainers=2 user=ubuntu user-resources=<memory:3072, vCores:2>
2013-08-11 09:31:04,270 INFO org.apache.hadoop.yarn.server.resourcemanager.scheduler.capacity.LeafQueue: completedContainer container=Container: [ContainerId: container_1376212503271_0005_01_000003, NodeId: hadoop-320-7:48037, NodeHttpAddress: hadoop-320-7:8042, Resource: <memory:1024, vCores:1>, Priority: 20, State: NEW, Token: null, Status: container_id {, app_attempt_id {, application_id {, id: 5, cluster_timestamp: 1376212503271, }, attemptId: 1, }, id: 3, }, state: C_COMPLETE, diagnostics: "Container killed by the ApplicationMaster.\n\n", exit_status: 143, ] resource=<memory:1024, vCores:1> queue=default: capacity=1.0, absoluteCapacity=1.0, usedResources=<memory:3072, vCores:2>usedCapacity=0.0625, absoluteUsedCapacity=0.0625, numApps=1, numContainers=2 usedCapacity=0.0625 absoluteUsedCapacity=0.0625 used=<memory:3072, vCores:2> cluster=<memory:49152, vCores:96>
2013-08-11 09:31:04,270 INFO org.apache.hadoop.yarn.server.resourcemanager.scheduler.capacity.ParentQueue: completedContainer queue=root usedCapacity=0.0625 absoluteUsedCapacity=0.0625 used=<memory:3072, vCores:2> cluster=<memory:49152, vCores:96>
2013-08-11 09:31:04,270 INFO org.apache.hadoop.yarn.server.resourcemanager.scheduler.capacity.CapacityScheduler: Application appattempt_1376212503271_0005_000001 released container container_1376212503271_0005_01_000003 on node: host: hadoop-320-7:48037 #containers=0 available=8192 used=0 with event: FINISHED
2013-08-11 09:31:07,405 INFO org.apache.hadoop.yarn.server.resourcemanager.rmcontainer.RMContainerImpl: container_1376212503271_0005_01_000002 Container Transitioned from RUNNING to COMPLETED
2013-08-11 09:31:07,406 INFO org.apache.hadoop.yarn.server.resourcemanager.scheduler.common.fica.FiCaSchedulerApp: Completed container: container_1376212503271_0005_01_000002 in state: COMPLETED event:FINISHED
2013-08-11 09:31:07,406 INFO org.apache.hadoop.yarn.server.resourcemanager.RMAuditLogger: USER=ubuntu	OPERATION=AM Released Container	TARGET=SchedulerApp	RESULT=SUCCESS	APPID=application_1376212503271_0005	CONTAINERID=container_1376212503271_0005_01_000002
2013-08-11 09:31:07,406 INFO org.apache.hadoop.yarn.server.resourcemanager.scheduler.common.fica.FiCaSchedulerNode: Released container container_1376212503271_0005_01_000002 of capacity <memory:1024, vCores:1> on host hadoop-320-2:53179, which currently has 0 containers, <memory:0, vCores:0> used and <memory:8192, vCores:16> available, release resources=true
2013-08-11 09:31:07,406 INFO org.apache.hadoop.yarn.server.resourcemanager.scheduler.capacity.LeafQueue: default used=<memory:2048, vCores:1> numContainers=1 user=ubuntu user-resources=<memory:2048, vCores:1>
2013-08-11 09:31:07,408 INFO org.apache.hadoop.yarn.server.resourcemanager.scheduler.capacity.LeafQueue: completedContainer container=Container: [ContainerId: container_1376212503271_0005_01_000002, NodeId: hadoop-320-2:53179, NodeHttpAddress: hadoop-320-2:8042, Resource: <memory:1024, vCores:1>, Priority: 20, State: NEW, Token: null, Status: container_id {, app_attempt_id {, application_id {, id: 5, cluster_timestamp: 1376212503271, }, attemptId: 1, }, id: 2, }, state: C_COMPLETE, diagnostics: "Container killed by the ApplicationMaster.\n\n", exit_status: 143, ] resource=<memory:1024, vCores:1> queue=default: capacity=1.0, absoluteCapacity=1.0, usedResources=<memory:2048, vCores:1>usedCapacity=0.041666668, absoluteUsedCapacity=0.041666668, numApps=1, numContainers=1 usedCapacity=0.041666668 absoluteUsedCapacity=0.041666668 used=<memory:2048, vCores:1> cluster=<memory:49152, vCores:96>
2013-08-11 09:31:07,408 INFO org.apache.hadoop.yarn.server.resourcemanager.scheduler.capacity.ParentQueue: completedContainer queue=root usedCapacity=0.041666668 absoluteUsedCapacity=0.041666668 used=<memory:2048, vCores:1> cluster=<memory:49152, vCores:96>
2013-08-11 09:31:07,408 INFO org.apache.hadoop.yarn.server.resourcemanager.scheduler.capacity.CapacityScheduler: Application appattempt_1376212503271_0005_000001 released container container_1376212503271_0005_01_000002 on node: host: hadoop-320-2:53179 #containers=0 available=8192 used=0 with event: FINISHED
2013-08-11 09:31:11,552 INFO org.apache.hadoop.yarn.server.resourcemanager.rmapp.attempt.RMAppAttemptImpl: appattempt_1376212503271_0005_000001 State change from RUNNING to FINISHING
2013-08-11 09:31:11,554 INFO org.apache.hadoop.yarn.server.resourcemanager.rmapp.RMAppImpl: application_1376212503271_0005 State change from RUNNING to FINISHING
2013-08-11 09:31:12,209 INFO org.apache.hadoop.yarn.server.resourcemanager.rmcontainer.RMContainerImpl: container_1376212503271_0005_01_000001 Container Transitioned from RUNNING to COMPLETED
2013-08-11 09:31:12,209 INFO org.apache.hadoop.yarn.server.resourcemanager.scheduler.common.fica.FiCaSchedulerApp: Completed container: container_1376212503271_0005_01_000001 in state: COMPLETED event:FINISHED
2013-08-11 09:31:12,210 INFO org.apache.hadoop.yarn.server.resourcemanager.RMAuditLogger: USER=ubuntu	OPERATION=AM Released Container	TARGET=SchedulerApp	RESULT=SUCCESS	APPID=application_1376212503271_0005	CONTAINERID=container_1376212503271_0005_01_000001
2013-08-11 09:31:12,210 INFO org.apache.hadoop.yarn.server.resourcemanager.rmapp.attempt.RMAppAttemptImpl: appattempt_1376212503271_0005_000001 State change from FINISHING to FINISHED
2013-08-11 09:31:12,210 INFO org.apache.hadoop.yarn.server.resourcemanager.scheduler.common.fica.FiCaSchedulerNode: Released container container_1376212503271_0005_01_000001 of capacity <memory:2048, vCores:1> on host hadoop-320-6:38980, which currently has 0 containers, <memory:0, vCores:0> used and <memory:8192, vCores:16> available, release resources=true
2013-08-11 09:31:12,210 INFO org.apache.hadoop.yarn.server.resourcemanager.rmapp.RMAppImpl: application_1376212503271_0005 State change from FINISHING to FINISHED
2013-08-11 09:31:12,210 INFO org.apache.hadoop.yarn.server.resourcemanager.scheduler.capacity.LeafQueue: default used=<memory:0, vCores:0> numContainers=0 user=ubuntu user-resources=<memory:0, vCores:0>
2013-08-11 09:31:12,211 INFO org.apache.hadoop.yarn.server.resourcemanager.RMAuditLogger: USER=ubuntu	OPERATION=Application Finished - Succeeded	TARGET=RMAppManager	RESULT=SUCCESS	APPID=application_1376212503271_0005
2013-08-11 09:31:12,211 INFO org.apache.hadoop.yarn.server.resourcemanager.recovery.RMStateStore: Removing info for app: application_1376212503271_0005
2013-08-11 09:31:12,211 INFO org.apache.hadoop.yarn.server.resourcemanager.RMAppManager$ApplicationSummary: appId=application_1376212503271_0005,name=TeraGen,user=ubuntu,queue=default,state=FINISHED,trackingUrl=hadoop-320-1.novalocal:8088/proxy/application_1376212503271_0005/jobhistory/job/job_1376212503271_0005,appMasterHost=hadoop-320-6,startTime=1376213281798,finishTime=1376213471554
2013-08-11 09:31:12,212 INFO org.apache.hadoop.yarn.server.resourcemanager.amlauncher.AMLauncher: Cleaning master appattempt_1376212503271_0005_000001
2013-08-11 09:31:12,212 INFO org.apache.hadoop.yarn.server.resourcemanager.scheduler.capacity.LeafQueue: completedContainer container=Container: [ContainerId: container_1376212503271_0005_01_000001, NodeId: hadoop-320-6:38980, NodeHttpAddress: hadoop-320-6:8042, Resource: <memory:2048, vCores:1>, Priority: 0, State: NEW, Token: null, Status: container_id {, app_attempt_id {, application_id {, id: 5, cluster_timestamp: 1376212503271, }, attemptId: 1, }, id: 1, }, state: C_COMPLETE, diagnostics: "", exit_status: 0, ] resource=<memory:2048, vCores:1> queue=default: capacity=1.0, absoluteCapacity=1.0, usedResources=<memory:0, vCores:0>usedCapacity=0.0, absoluteUsedCapacity=0.0, numApps=1, numContainers=0 usedCapacity=0.0 absoluteUsedCapacity=0.0 used=<memory:0, vCores:0> cluster=<memory:49152, vCores:96>
2013-08-11 09:31:12,212 INFO org.apache.hadoop.yarn.server.resourcemanager.scheduler.capacity.ParentQueue: completedContainer queue=root usedCapacity=0.0 absoluteUsedCapacity=0.0 used=<memory:0, vCores:0> cluster=<memory:49152, vCores:96>
2013-08-11 09:31:12,212 INFO org.apache.hadoop.yarn.server.resourcemanager.scheduler.capacity.CapacityScheduler: Application appattempt_1376212503271_0005_000001 released container container_1376212503271_0005_01_000001 on node: host: hadoop-320-6:38980 #containers=0 available=8192 used=0 with event: FINISHED
2013-08-11 09:31:12,213 INFO org.apache.hadoop.yarn.server.resourcemanager.scheduler.capacity.CapacityScheduler: Application appattempt_1376212503271_0005_000001 is done. finalState=FINISHED
2013-08-11 09:31:12,213 INFO org.apache.hadoop.yarn.server.resourcemanager.scheduler.AppSchedulingInfo: Application application_1376212503271_0005 requests cleared
2013-08-11 09:31:12,213 INFO org.apache.hadoop.yarn.server.resourcemanager.scheduler.capacity.LeafQueue: Application removed - appId: application_1376212503271_0005 user: ubuntu queue: default #user-pending-applications: 0 #user-active-applications: 0 #queue-pending-applications: 0 #queue-active-applications: 0
2013-08-11 09:31:12,213 INFO org.apache.hadoop.yarn.server.resourcemanager.scheduler.capacity.ParentQueue: Application removed - appId: application_1376212503271_0005 user: ubuntu leaf-queue of parent: root #applications: 0
2013-08-11 09:31:27,439 INFO org.apache.hadoop.yarn.server.resourcemanager.ClientRMService: Allocated new applicationId: 6
2013-08-11 09:31:27,547 INFO org.apache.hadoop.yarn.server.resourcemanager.ClientRMService: Allocated new applicationId: 7
2013-08-11 09:31:27,662 INFO org.apache.hadoop.yarn.server.resourcemanager.ClientRMService: Allocated new applicationId: 8
2013-08-11 09:31:28,272 INFO org.apache.hadoop.yarn.server.resourcemanager.ClientRMService: Allocated new applicationId: 9
2013-08-11 09:31:28,436 INFO org.apache.hadoop.yarn.server.resourcemanager.ClientRMService: Allocated new applicationId: 10
2013-08-11 09:31:29,286 INFO org.apache.hadoop.yarn.server.resourcemanager.ClientRMService: Storing Application with id application_1376212503271_0006
2013-08-11 09:31:29,286 INFO org.apache.hadoop.yarn.server.resourcemanager.recovery.RMStateStore: Storing info for app: application_1376212503271_0006
2013-08-11 09:31:29,286 INFO org.apache.hadoop.yarn.server.resourcemanager.ClientRMService: Application with id 6 submitted by user ubuntu
2013-08-11 09:31:29,286 INFO org.apache.hadoop.yarn.server.resourcemanager.RMAuditLogger: USER=ubuntu	IP=192.168.100.4	OPERATION=Submit Application Request	TARGET=ClientRMService	RESULT=SUCCESS	APPID=application_1376212503271_0006
2013-08-11 09:31:29,287 INFO org.apache.hadoop.yarn.server.resourcemanager.rmapp.RMAppImpl: application_1376212503271_0006 State change from NEW to SUBMITTED
2013-08-11 09:31:29,287 INFO org.apache.hadoop.yarn.server.resourcemanager.ApplicationMasterService: Registering appattempt_1376212503271_0006_000001
2013-08-11 09:31:29,287 INFO org.apache.hadoop.yarn.server.resourcemanager.rmapp.attempt.RMAppAttemptImpl: appattempt_1376212503271_0006_000001 State change from NEW to SUBMITTED
2013-08-11 09:31:29,287 INFO org.apache.hadoop.yarn.server.resourcemanager.scheduler.capacity.LeafQueue: Application application_1376212503271_0006 from user: ubuntu activated in queue: default
2013-08-11 09:31:29,287 INFO org.apache.hadoop.yarn.server.resourcemanager.scheduler.capacity.LeafQueue: Application added - appId: application_1376212503271_0006 user: org.apache.hadoop.yarn.server.resourcemanager.scheduler.capacity.LeafQueue$User@7a886c25, leaf-queue: default #user-pending-applications: 0 #user-active-applications: 1 #queue-pending-applications: 0 #queue-active-applications: 1
2013-08-11 09:31:29,287 INFO org.apache.hadoop.yarn.server.resourcemanager.scheduler.capacity.ParentQueue: Application added - appId: application_1376212503271_0006 user: ubuntu leaf-queue of parent: root #applications: 1
2013-08-11 09:31:29,287 INFO org.apache.hadoop.yarn.server.resourcemanager.scheduler.capacity.CapacityScheduler: Application Submission: appattempt_1376212503271_0006_000001, user: ubuntu queue: default: capacity=1.0, absoluteCapacity=1.0, usedResources=<memory:0, vCores:0>usedCapacity=0.0, absoluteUsedCapacity=0.0, numApps=1, numContainers=0, currently active: 1
2013-08-11 09:31:29,287 INFO org.apache.hadoop.yarn.server.resourcemanager.rmapp.attempt.RMAppAttemptImpl: appattempt_1376212503271_0006_000001 State change from SUBMITTED to SCHEDULED
2013-08-11 09:31:29,288 INFO org.apache.hadoop.yarn.server.resourcemanager.rmapp.RMAppImpl: application_1376212503271_0006 State change from SUBMITTED to ACCEPTED
2013-08-11 09:31:29,361 INFO org.apache.hadoop.yarn.server.resourcemanager.ClientRMService: Storing Application with id application_1376212503271_0007
2013-08-11 09:31:29,361 INFO org.apache.hadoop.yarn.server.resourcemanager.recovery.RMStateStore: Storing info for app: application_1376212503271_0007
2013-08-11 09:31:29,361 INFO org.apache.hadoop.yarn.server.resourcemanager.ClientRMService: Application with id 7 submitted by user ubuntu
2013-08-11 09:31:29,361 INFO org.apache.hadoop.yarn.server.resourcemanager.RMAuditLogger: USER=ubuntu	IP=192.168.100.4	OPERATION=Submit Application Request	TARGET=ClientRMService	RESULT=SUCCESS	APPID=application_1376212503271_0007
2013-08-11 09:31:29,362 INFO org.apache.hadoop.yarn.server.resourcemanager.rmapp.RMAppImpl: application_1376212503271_0007 State change from NEW to SUBMITTED
2013-08-11 09:31:29,362 INFO org.apache.hadoop.yarn.server.resourcemanager.ApplicationMasterService: Registering appattempt_1376212503271_0007_000001
2013-08-11 09:31:29,362 INFO org.apache.hadoop.yarn.server.resourcemanager.rmapp.attempt.RMAppAttemptImpl: appattempt_1376212503271_0007_000001 State change from NEW to SUBMITTED
2013-08-11 09:31:29,362 INFO org.apache.hadoop.yarn.server.resourcemanager.scheduler.capacity.LeafQueue: Application application_1376212503271_0007 from user: ubuntu activated in queue: default
2013-08-11 09:31:29,362 INFO org.apache.hadoop.yarn.server.resourcemanager.scheduler.capacity.LeafQueue: Application added - appId: application_1376212503271_0007 user: org.apache.hadoop.yarn.server.resourcemanager.scheduler.capacity.LeafQueue$User@7a886c25, leaf-queue: default #user-pending-applications: 0 #user-active-applications: 2 #queue-pending-applications: 0 #queue-active-applications: 2
2013-08-11 09:31:29,362 INFO org.apache.hadoop.yarn.server.resourcemanager.scheduler.capacity.ParentQueue: Application added - appId: application_1376212503271_0007 user: ubuntu leaf-queue of parent: root #applications: 2
2013-08-11 09:31:29,363 INFO org.apache.hadoop.yarn.server.resourcemanager.scheduler.capacity.CapacityScheduler: Application Submission: appattempt_1376212503271_0007_000001, user: ubuntu queue: default: capacity=1.0, absoluteCapacity=1.0, usedResources=<memory:0, vCores:0>usedCapacity=0.0, absoluteUsedCapacity=0.0, numApps=2, numContainers=0, currently active: 2
2013-08-11 09:31:29,363 INFO org.apache.hadoop.yarn.server.resourcemanager.rmapp.attempt.RMAppAttemptImpl: appattempt_1376212503271_0007_000001 State change from SUBMITTED to SCHEDULED
2013-08-11 09:31:29,363 INFO org.apache.hadoop.yarn.server.resourcemanager.rmapp.RMAppImpl: application_1376212503271_0007 State change from SUBMITTED to ACCEPTED
2013-08-11 09:31:29,375 INFO org.apache.hadoop.yarn.server.resourcemanager.ClientRMService: Storing Application with id application_1376212503271_0008
2013-08-11 09:31:29,375 INFO org.apache.hadoop.yarn.server.resourcemanager.recovery.RMStateStore: Storing info for app: application_1376212503271_0008
2013-08-11 09:31:29,375 INFO org.apache.hadoop.yarn.server.resourcemanager.ClientRMService: Application with id 8 submitted by user ubuntu
2013-08-11 09:31:29,375 INFO org.apache.hadoop.yarn.server.resourcemanager.RMAuditLogger: USER=ubuntu	IP=192.168.100.4	OPERATION=Submit Application Request	TARGET=ClientRMService	RESULT=SUCCESS	APPID=application_1376212503271_0008
2013-08-11 09:31:29,376 INFO org.apache.hadoop.yarn.server.resourcemanager.rmapp.RMAppImpl: application_1376212503271_0008 State change from NEW to SUBMITTED
2013-08-11 09:31:29,377 INFO org.apache.hadoop.yarn.server.resourcemanager.ApplicationMasterService: Registering appattempt_1376212503271_0008_000001
2013-08-11 09:31:29,377 INFO org.apache.hadoop.yarn.server.resourcemanager.rmapp.attempt.RMAppAttemptImpl: appattempt_1376212503271_0008_000001 State change from NEW to SUBMITTED
2013-08-11 09:31:29,378 INFO org.apache.hadoop.yarn.server.resourcemanager.rmcontainer.RMContainerImpl: container_1376212503271_0006_01_000001 Container Transitioned from NEW to ALLOCATED
2013-08-11 09:31:29,378 INFO org.apache.hadoop.yarn.server.resourcemanager.RMAuditLogger: USER=ubuntu	OPERATION=AM Allocated Container	TARGET=SchedulerApp	RESULT=SUCCESS	APPID=application_1376212503271_0006	CONTAINERID=container_1376212503271_0006_01_000001
2013-08-11 09:31:29,378 INFO org.apache.hadoop.yarn.server.resourcemanager.scheduler.common.fica.FiCaSchedulerNode: Assigned container container_1376212503271_0006_01_000001 of capacity <memory:2048, vCores:1> on host hadoop-320-7:48037, which currently has 1 containers, <memory:2048, vCores:1> used and <memory:6144, vCores:15> available
2013-08-11 09:31:29,380 INFO org.apache.hadoop.yarn.server.resourcemanager.scheduler.capacity.LeafQueue: assignedContainer application=application_1376212503271_0006 container=Container: [ContainerId: container_1376212503271_0006_01_000001, NodeId: hadoop-320-7:48037, NodeHttpAddress: hadoop-320-7:8042, Resource: <memory:2048, vCores:1>, Priority: 0, State: NEW, Token: null, Status: container_id {, app_attempt_id {, application_id {, id: 6, cluster_timestamp: 1376212503271, }, attemptId: 1, }, id: 1, }, state: C_NEW, ] containerId=container_1376212503271_0006_01_000001 queue=default: capacity=1.0, absoluteCapacity=1.0, usedResources=<memory:0, vCores:0>usedCapacity=0.0, absoluteUsedCapacity=0.0, numApps=2, numContainers=0 usedCapacity=0.0 absoluteUsedCapacity=0.0 used=<memory:0, vCores:0> cluster=<memory:49152, vCores:96>
2013-08-11 09:31:29,381 INFO org.apache.hadoop.yarn.server.resourcemanager.scheduler.capacity.ParentQueue: Re-sorting queues since queue: root.default stats: default: capacity=1.0, absoluteCapacity=1.0, usedResources=<memory:2048, vCores:1>usedCapacity=0.041666668, absoluteUsedCapacity=0.041666668, numApps=2, numContainers=1
2013-08-11 09:31:29,381 INFO org.apache.hadoop.yarn.server.resourcemanager.scheduler.capacity.ParentQueue: assignedContainer queue=root usedCapacity=0.041666668 absoluteUsedCapacity=0.041666668 used=<memory:2048, vCores:1> cluster=<memory:49152, vCores:96>
2013-08-11 09:31:29,381 INFO org.apache.hadoop.yarn.server.resourcemanager.rmcontainer.RMContainerImpl: container_1376212503271_0006_01_000001 Container Transitioned from ALLOCATED to ACQUIRED
2013-08-11 09:31:29,384 INFO org.apache.hadoop.yarn.server.resourcemanager.rmapp.attempt.RMAppAttemptImpl: Storing attempt: AppId: application_1376212503271_0006 AttemptId: appattempt_1376212503271_0006_000001 MasterContainer: Container: [ContainerId: container_1376212503271_0006_01_000001, NodeId: hadoop-320-7:48037, NodeHttpAddress: hadoop-320-7:8042, Resource: <memory:2048, vCores:1>, Priority: 0, State: NEW, Token: null, Status: container_id {, app_attempt_id {, application_id {, id: 6, cluster_timestamp: 1376212503271, }, attemptId: 1, }, id: 1, }, state: C_NEW, ]
2013-08-11 09:31:29,384 INFO org.apache.hadoop.yarn.server.resourcemanager.rmapp.attempt.RMAppAttemptImpl: appattempt_1376212503271_0006_000001 State change from SCHEDULED to ALLOCATED_SAVING
2013-08-11 09:31:29,384 INFO org.apache.hadoop.yarn.server.resourcemanager.recovery.RMStateStore: Storing info for attempt: appattempt_1376212503271_0006_000001
2013-08-11 09:31:29,386 INFO org.apache.hadoop.yarn.server.resourcemanager.rmapp.attempt.RMAppAttemptImpl: appattempt_1376212503271_0006_000001 State change from ALLOCATED_SAVING to ALLOCATED
2013-08-11 09:31:29,383 INFO org.apache.hadoop.yarn.server.resourcemanager.scheduler.capacity.LeafQueue: Application application_1376212503271_0008 from user: ubuntu activated in queue: default
2013-08-11 09:31:29,388 INFO org.apache.hadoop.yarn.server.resourcemanager.scheduler.capacity.LeafQueue: Application added - appId: application_1376212503271_0008 user: org.apache.hadoop.yarn.server.resourcemanager.scheduler.capacity.LeafQueue$User@7a886c25, leaf-queue: default #user-pending-applications: 0 #user-active-applications: 3 #queue-pending-applications: 0 #queue-active-applications: 3
2013-08-11 09:31:29,388 INFO org.apache.hadoop.yarn.server.resourcemanager.scheduler.capacity.ParentQueue: Application added - appId: application_1376212503271_0008 user: ubuntu leaf-queue of parent: root #applications: 3
2013-08-11 09:31:29,388 INFO org.apache.hadoop.yarn.server.resourcemanager.scheduler.capacity.CapacityScheduler: Application Submission: appattempt_1376212503271_0008_000001, user: ubuntu queue: default: capacity=1.0, absoluteCapacity=1.0, usedResources=<memory:2048, vCores:1>usedCapacity=0.041666668, absoluteUsedCapacity=0.041666668, numApps=3, numContainers=1, currently active: 3
2013-08-11 09:31:29,388 INFO org.apache.hadoop.yarn.server.resourcemanager.rmapp.attempt.RMAppAttemptImpl: appattempt_1376212503271_0008_000001 State change from SUBMITTED to SCHEDULED
2013-08-11 09:31:29,389 INFO org.apache.hadoop.yarn.server.resourcemanager.amlauncher.AMLauncher: Launching masterappattempt_1376212503271_0006_000001
2013-08-11 09:31:29,395 INFO org.apache.hadoop.yarn.server.resourcemanager.amlauncher.AMLauncher: Setting up container Container: [ContainerId: container_1376212503271_0006_01_000001, NodeId: hadoop-320-7:48037, NodeHttpAddress: hadoop-320-7:8042, Resource: <memory:2048, vCores:1>, Priority: 0, State: NEW, Token: null, Status: container_id {, app_attempt_id {, application_id {, id: 6, cluster_timestamp: 1376212503271, }, attemptId: 1, }, id: 1, }, state: C_NEW, ] for AM appattempt_1376212503271_0006_000001
2013-08-11 09:31:29,395 INFO org.apache.hadoop.yarn.server.resourcemanager.amlauncher.AMLauncher: Command to launch container container_1376212503271_0006_01_000001 : $JAVA_HOME/bin/java -Dlog4j.configuration=container-log4j.properties -Dyarn.app.mapreduce.container.log.dir=<LOG_DIR> -Dyarn.app.mapreduce.container.log.filesize=0 -Dhadoop.root.logger=INFO,CLA  -Xmx1024m org.apache.hadoop.mapreduce.v2.app.MRAppMaster 1><LOG_DIR>/stdout 2><LOG_DIR>/stderr 
2013-08-11 09:31:29,396 INFO org.apache.hadoop.yarn.server.resourcemanager.rmapp.RMAppImpl: application_1376212503271_0008 State change from SUBMITTED to ACCEPTED
2013-08-11 09:31:29,411 INFO org.apache.hadoop.yarn.server.resourcemanager.amlauncher.AMLauncher: Done launching container Container: [ContainerId: container_1376212503271_0006_01_000001, NodeId: hadoop-320-7:48037, NodeHttpAddress: hadoop-320-7:8042, Resource: <memory:2048, vCores:1>, Priority: 0, State: NEW, Token: null, Status: container_id {, app_attempt_id {, application_id {, id: 6, cluster_timestamp: 1376212503271, }, attemptId: 1, }, id: 1, }, state: C_NEW, ] for AM appattempt_1376212503271_0006_000001
2013-08-11 09:31:29,411 INFO org.apache.hadoop.yarn.server.resourcemanager.rmapp.attempt.RMAppAttemptImpl: appattempt_1376212503271_0006_000001 State change from ALLOCATED to LAUNCHED
2013-08-11 09:31:29,519 INFO org.apache.hadoop.yarn.server.resourcemanager.rmcontainer.RMContainerImpl: container_1376212503271_0007_01_000001 Container Transitioned from NEW to ALLOCATED
2013-08-11 09:31:29,521 INFO org.apache.hadoop.yarn.server.resourcemanager.RMAuditLogger: USER=ubuntu	OPERATION=AM Allocated Container	TARGET=SchedulerApp	RESULT=SUCCESS	APPID=application_1376212503271_0007	CONTAINERID=container_1376212503271_0007_01_000001
2013-08-11 09:31:29,521 INFO org.apache.hadoop.yarn.server.resourcemanager.scheduler.common.fica.FiCaSchedulerNode: Assigned container container_1376212503271_0007_01_000001 of capacity <memory:2048, vCores:1> on host hadoop-320-2:53179, which currently has 1 containers, <memory:2048, vCores:1> used and <memory:6144, vCores:15> available
2013-08-11 09:31:29,522 INFO org.apache.hadoop.yarn.server.resourcemanager.scheduler.capacity.LeafQueue: assignedContainer application=application_1376212503271_0007 container=Container: [ContainerId: container_1376212503271_0007_01_000001, NodeId: hadoop-320-2:53179, NodeHttpAddress: hadoop-320-2:8042, Resource: <memory:2048, vCores:1>, Priority: 0, State: NEW, Token: null, Status: container_id {, app_attempt_id {, application_id {, id: 7, cluster_timestamp: 1376212503271, }, attemptId: 1, }, id: 1, }, state: C_NEW, ] containerId=container_1376212503271_0007_01_000001 queue=default: capacity=1.0, absoluteCapacity=1.0, usedResources=<memory:2048, vCores:1>usedCapacity=0.041666668, absoluteUsedCapacity=0.041666668, numApps=3, numContainers=1 usedCapacity=0.041666668 absoluteUsedCapacity=0.041666668 used=<memory:2048, vCores:1> cluster=<memory:49152, vCores:96>
2013-08-11 09:31:29,522 INFO org.apache.hadoop.yarn.server.resourcemanager.scheduler.capacity.ParentQueue: Re-sorting queues since queue: root.default stats: default: capacity=1.0, absoluteCapacity=1.0, usedResources=<memory:4096, vCores:2>usedCapacity=0.083333336, absoluteUsedCapacity=0.083333336, numApps=3, numContainers=2
2013-08-11 09:31:29,522 INFO org.apache.hadoop.yarn.server.resourcemanager.scheduler.capacity.ParentQueue: assignedContainer queue=root usedCapacity=0.083333336 absoluteUsedCapacity=0.083333336 used=<memory:4096, vCores:2> cluster=<memory:49152, vCores:96>
2013-08-11 09:31:29,522 INFO org.apache.hadoop.yarn.server.resourcemanager.rmcontainer.RMContainerImpl: container_1376212503271_0007_01_000001 Container Transitioned from ALLOCATED to ACQUIRED
2013-08-11 09:31:29,523 INFO org.apache.hadoop.yarn.server.resourcemanager.rmapp.attempt.RMAppAttemptImpl: Storing attempt: AppId: application_1376212503271_0007 AttemptId: appattempt_1376212503271_0007_000001 MasterContainer: Container: [ContainerId: container_1376212503271_0007_01_000001, NodeId: hadoop-320-2:53179, NodeHttpAddress: hadoop-320-2:8042, Resource: <memory:2048, vCores:1>, Priority: 0, State: NEW, Token: null, Status: container_id {, app_attempt_id {, application_id {, id: 7, cluster_timestamp: 1376212503271, }, attemptId: 1, }, id: 1, }, state: C_NEW, ]
2013-08-11 09:31:29,523 INFO org.apache.hadoop.yarn.server.resourcemanager.rmapp.attempt.RMAppAttemptImpl: appattempt_1376212503271_0007_000001 State change from SCHEDULED to ALLOCATED_SAVING
2013-08-11 09:31:29,523 INFO org.apache.hadoop.yarn.server.resourcemanager.recovery.RMStateStore: Storing info for attempt: appattempt_1376212503271_0007_000001
2013-08-11 09:31:29,526 INFO org.apache.hadoop.yarn.server.resourcemanager.rmapp.attempt.RMAppAttemptImpl: appattempt_1376212503271_0007_000001 State change from ALLOCATED_SAVING to ALLOCATED
2013-08-11 09:31:29,527 INFO org.apache.hadoop.yarn.server.resourcemanager.amlauncher.AMLauncher: Launching masterappattempt_1376212503271_0007_000001
2013-08-11 09:31:29,529 INFO org.apache.hadoop.yarn.server.resourcemanager.amlauncher.AMLauncher: Setting up container Container: [ContainerId: container_1376212503271_0007_01_000001, NodeId: hadoop-320-2:53179, NodeHttpAddress: hadoop-320-2:8042, Resource: <memory:2048, vCores:1>, Priority: 0, State: NEW, Token: null, Status: container_id {, app_attempt_id {, application_id {, id: 7, cluster_timestamp: 1376212503271, }, attemptId: 1, }, id: 1, }, state: C_NEW, ] for AM appattempt_1376212503271_0007_000001
2013-08-11 09:31:29,529 INFO org.apache.hadoop.yarn.server.resourcemanager.amlauncher.AMLauncher: Command to launch container container_1376212503271_0007_01_000001 : $JAVA_HOME/bin/java -Dlog4j.configuration=container-log4j.properties -Dyarn.app.mapreduce.container.log.dir=<LOG_DIR> -Dyarn.app.mapreduce.container.log.filesize=0 -Dhadoop.root.logger=INFO,CLA  -Xmx1024m org.apache.hadoop.mapreduce.v2.app.MRAppMaster 1><LOG_DIR>/stdout 2><LOG_DIR>/stderr 
2013-08-11 09:31:29,541 INFO org.apache.hadoop.yarn.server.resourcemanager.amlauncher.AMLauncher: Done launching container Container: [ContainerId: container_1376212503271_0007_01_000001, NodeId: hadoop-320-2:53179, NodeHttpAddress: hadoop-320-2:8042, Resource: <memory:2048, vCores:1>, Priority: 0, State: NEW, Token: null, Status: container_id {, app_attempt_id {, application_id {, id: 7, cluster_timestamp: 1376212503271, }, attemptId: 1, }, id: 1, }, state: C_NEW, ] for AM appattempt_1376212503271_0007_000001
2013-08-11 09:31:29,541 INFO org.apache.hadoop.yarn.server.resourcemanager.rmapp.attempt.RMAppAttemptImpl: appattempt_1376212503271_0007_000001 State change from ALLOCATED to LAUNCHED
2013-08-11 09:31:29,682 INFO org.apache.hadoop.yarn.server.resourcemanager.ClientRMService: Storing Application with id application_1376212503271_0009
2013-08-11 09:31:29,682 INFO org.apache.hadoop.yarn.server.resourcemanager.recovery.RMStateStore: Storing info for app: application_1376212503271_0009
2013-08-11 09:31:29,682 INFO org.apache.hadoop.yarn.server.resourcemanager.ClientRMService: Application with id 9 submitted by user ubuntu
2013-08-11 09:31:29,683 INFO org.apache.hadoop.yarn.server.resourcemanager.RMAuditLogger: USER=ubuntu	IP=192.168.100.4	OPERATION=Submit Application Request	TARGET=ClientRMService	RESULT=SUCCESS	APPID=application_1376212503271_0009
2013-08-11 09:31:29,683 INFO org.apache.hadoop.yarn.server.resourcemanager.rmapp.RMAppImpl: application_1376212503271_0009 State change from NEW to SUBMITTED
2013-08-11 09:31:29,684 INFO org.apache.hadoop.yarn.server.resourcemanager.ApplicationMasterService: Registering appattempt_1376212503271_0009_000001
2013-08-11 09:31:29,684 INFO org.apache.hadoop.yarn.server.resourcemanager.rmapp.attempt.RMAppAttemptImpl: appattempt_1376212503271_0009_000001 State change from NEW to SUBMITTED
2013-08-11 09:31:29,684 INFO org.apache.hadoop.yarn.server.resourcemanager.scheduler.capacity.LeafQueue: Application application_1376212503271_0009 from user: ubuntu activated in queue: default
2013-08-11 09:31:29,684 INFO org.apache.hadoop.yarn.server.resourcemanager.scheduler.capacity.LeafQueue: Application added - appId: application_1376212503271_0009 user: org.apache.hadoop.yarn.server.resourcemanager.scheduler.capacity.LeafQueue$User@7a886c25, leaf-queue: default #user-pending-applications: 0 #user-active-applications: 4 #queue-pending-applications: 0 #queue-active-applications: 4
2013-08-11 09:31:29,685 INFO org.apache.hadoop.yarn.server.resourcemanager.scheduler.capacity.ParentQueue: Application added - appId: application_1376212503271_0009 user: ubuntu leaf-queue of parent: root #applications: 4
2013-08-11 09:31:29,685 INFO org.apache.hadoop.yarn.server.resourcemanager.scheduler.capacity.CapacityScheduler: Application Submission: appattempt_1376212503271_0009_000001, user: ubuntu queue: default: capacity=1.0, absoluteCapacity=1.0, usedResources=<memory:4096, vCores:2>usedCapacity=0.083333336, absoluteUsedCapacity=0.083333336, numApps=4, numContainers=2, currently active: 4
2013-08-11 09:31:29,685 INFO org.apache.hadoop.yarn.server.resourcemanager.rmapp.attempt.RMAppAttemptImpl: appattempt_1376212503271_0009_000001 State change from SUBMITTED to SCHEDULED
2013-08-11 09:31:29,685 INFO org.apache.hadoop.yarn.server.resourcemanager.rmapp.RMAppImpl: application_1376212503271_0009 State change from SUBMITTED to ACCEPTED
2013-08-11 09:31:29,694 INFO org.apache.hadoop.yarn.server.resourcemanager.rmcontainer.RMContainerImpl: container_1376212503271_0008_01_000001 Container Transitioned from NEW to ALLOCATED
2013-08-11 09:31:29,695 INFO org.apache.hadoop.yarn.server.resourcemanager.RMAuditLogger: USER=ubuntu	OPERATION=AM Allocated Container	TARGET=SchedulerApp	RESULT=SUCCESS	APPID=application_1376212503271_0008	CONTAINERID=container_1376212503271_0008_01_000001
2013-08-11 09:31:29,695 INFO org.apache.hadoop.yarn.server.resourcemanager.scheduler.common.fica.FiCaSchedulerNode: Assigned container container_1376212503271_0008_01_000001 of capacity <memory:2048, vCores:1> on host hadoop-320-4:39920, which currently has 1 containers, <memory:2048, vCores:1> used and <memory:6144, vCores:15> available
2013-08-11 09:31:29,696 INFO org.apache.hadoop.yarn.server.resourcemanager.scheduler.capacity.LeafQueue: assignedContainer application=application_1376212503271_0008 container=Container: [ContainerId: container_1376212503271_0008_01_000001, NodeId: hadoop-320-4:39920, NodeHttpAddress: hadoop-320-4:8042, Resource: <memory:2048, vCores:1>, Priority: 0, State: NEW, Token: null, Status: container_id {, app_attempt_id {, application_id {, id: 8, cluster_timestamp: 1376212503271, }, attemptId: 1, }, id: 1, }, state: C_NEW, ] containerId=container_1376212503271_0008_01_000001 queue=default: capacity=1.0, absoluteCapacity=1.0, usedResources=<memory:4096, vCores:2>usedCapacity=0.083333336, absoluteUsedCapacity=0.083333336, numApps=4, numContainers=2 usedCapacity=0.083333336 absoluteUsedCapacity=0.083333336 used=<memory:4096, vCores:2> cluster=<memory:49152, vCores:96>
2013-08-11 09:31:29,696 INFO org.apache.hadoop.yarn.server.resourcemanager.scheduler.capacity.ParentQueue: Re-sorting queues since queue: root.default stats: default: capacity=1.0, absoluteCapacity=1.0, usedResources=<memory:6144, vCores:3>usedCapacity=0.125, absoluteUsedCapacity=0.125, numApps=4, numContainers=3
2013-08-11 09:31:29,696 INFO org.apache.hadoop.yarn.server.resourcemanager.scheduler.capacity.ParentQueue: assignedContainer queue=root usedCapacity=0.125 absoluteUsedCapacity=0.125 used=<memory:6144, vCores:3> cluster=<memory:49152, vCores:96>
2013-08-11 09:31:29,697 INFO org.apache.hadoop.yarn.server.resourcemanager.rmcontainer.RMContainerImpl: container_1376212503271_0008_01_000001 Container Transitioned from ALLOCATED to ACQUIRED
2013-08-11 09:31:29,698 INFO org.apache.hadoop.yarn.server.resourcemanager.rmapp.attempt.RMAppAttemptImpl: Storing attempt: AppId: application_1376212503271_0008 AttemptId: appattempt_1376212503271_0008_000001 MasterContainer: Container: [ContainerId: container_1376212503271_0008_01_000001, NodeId: hadoop-320-4:39920, NodeHttpAddress: hadoop-320-4:8042, Resource: <memory:2048, vCores:1>, Priority: 0, State: NEW, Token: null, Status: container_id {, app_attempt_id {, application_id {, id: 8, cluster_timestamp: 1376212503271, }, attemptId: 1, }, id: 1, }, state: C_NEW, ]
2013-08-11 09:31:29,699 INFO org.apache.hadoop.yarn.server.resourcemanager.recovery.RMStateStore: Storing info for attempt: appattempt_1376212503271_0008_000001
2013-08-11 09:31:29,699 INFO org.apache.hadoop.yarn.server.resourcemanager.rmapp.attempt.RMAppAttemptImpl: appattempt_1376212503271_0008_000001 State change from SCHEDULED to ALLOCATED_SAVING
2013-08-11 09:31:29,699 INFO org.apache.hadoop.yarn.server.resourcemanager.rmapp.attempt.RMAppAttemptImpl: appattempt_1376212503271_0008_000001 State change from ALLOCATED_SAVING to ALLOCATED
2013-08-11 09:31:29,700 INFO org.apache.hadoop.yarn.server.resourcemanager.amlauncher.AMLauncher: Launching masterappattempt_1376212503271_0008_000001
2013-08-11 09:31:29,701 INFO org.apache.hadoop.yarn.server.resourcemanager.amlauncher.AMLauncher: Setting up container Container: [ContainerId: container_1376212503271_0008_01_000001, NodeId: hadoop-320-4:39920, NodeHttpAddress: hadoop-320-4:8042, Resource: <memory:2048, vCores:1>, Priority: 0, State: NEW, Token: null, Status: container_id {, app_attempt_id {, application_id {, id: 8, cluster_timestamp: 1376212503271, }, attemptId: 1, }, id: 1, }, state: C_NEW, ] for AM appattempt_1376212503271_0008_000001
2013-08-11 09:31:29,702 INFO org.apache.hadoop.yarn.server.resourcemanager.amlauncher.AMLauncher: Command to launch container container_1376212503271_0008_01_000001 : $JAVA_HOME/bin/java -Dlog4j.configuration=container-log4j.properties -Dyarn.app.mapreduce.container.log.dir=<LOG_DIR> -Dyarn.app.mapreduce.container.log.filesize=0 -Dhadoop.root.logger=INFO,CLA  -Xmx1024m org.apache.hadoop.mapreduce.v2.app.MRAppMaster 1><LOG_DIR>/stdout 2><LOG_DIR>/stderr 
2013-08-11 09:31:29,722 INFO org.apache.hadoop.yarn.server.resourcemanager.rmcontainer.RMContainerImpl: container_1376212503271_0009_01_000001 Container Transitioned from NEW to ALLOCATED
2013-08-11 09:31:29,723 INFO org.apache.hadoop.yarn.server.resourcemanager.RMAuditLogger: USER=ubuntu	OPERATION=AM Allocated Container	TARGET=SchedulerApp	RESULT=SUCCESS	APPID=application_1376212503271_0009	CONTAINERID=container_1376212503271_0009_01_000001
2013-08-11 09:31:29,723 INFO org.apache.hadoop.yarn.server.resourcemanager.scheduler.common.fica.FiCaSchedulerNode: Assigned container container_1376212503271_0009_01_000001 of capacity <memory:2048, vCores:1> on host hadoop-320-5:36272, which currently has 1 containers, <memory:2048, vCores:1> used and <memory:6144, vCores:15> available
2013-08-11 09:31:29,723 INFO org.apache.hadoop.yarn.server.resourcemanager.scheduler.capacity.LeafQueue: assignedContainer application=application_1376212503271_0009 container=Container: [ContainerId: container_1376212503271_0009_01_000001, NodeId: hadoop-320-5:36272, NodeHttpAddress: hadoop-320-5:8042, Resource: <memory:2048, vCores:1>, Priority: 0, State: NEW, Token: null, Status: container_id {, app_attempt_id {, application_id {, id: 9, cluster_timestamp: 1376212503271, }, attemptId: 1, }, id: 1, }, state: C_NEW, ] containerId=container_1376212503271_0009_01_000001 queue=default: capacity=1.0, absoluteCapacity=1.0, usedResources=<memory:6144, vCores:3>usedCapacity=0.125, absoluteUsedCapacity=0.125, numApps=4, numContainers=3 usedCapacity=0.125 absoluteUsedCapacity=0.125 used=<memory:6144, vCores:3> cluster=<memory:49152, vCores:96>
2013-08-11 09:31:29,724 INFO org.apache.hadoop.yarn.server.resourcemanager.scheduler.capacity.ParentQueue: Re-sorting queues since queue: root.default stats: default: capacity=1.0, absoluteCapacity=1.0, usedResources=<memory:8192, vCores:4>usedCapacity=0.16666667, absoluteUsedCapacity=0.16666667, numApps=4, numContainers=4
2013-08-11 09:31:29,724 INFO org.apache.hadoop.yarn.server.resourcemanager.scheduler.capacity.ParentQueue: assignedContainer queue=root usedCapacity=0.16666667 absoluteUsedCapacity=0.16666667 used=<memory:8192, vCores:4> cluster=<memory:49152, vCores:96>
2013-08-11 09:31:29,730 INFO org.apache.hadoop.yarn.server.resourcemanager.rmcontainer.RMContainerImpl: container_1376212503271_0009_01_000001 Container Transitioned from ALLOCATED to ACQUIRED
2013-08-11 09:31:29,731 INFO org.apache.hadoop.yarn.server.resourcemanager.rmapp.attempt.RMAppAttemptImpl: Storing attempt: AppId: application_1376212503271_0009 AttemptId: appattempt_1376212503271_0009_000001 MasterContainer: Container: [ContainerId: container_1376212503271_0009_01_000001, NodeId: hadoop-320-5:36272, NodeHttpAddress: hadoop-320-5:8042, Resource: <memory:2048, vCores:1>, Priority: 0, State: NEW, Token: null, Status: container_id {, app_attempt_id {, application_id {, id: 9, cluster_timestamp: 1376212503271, }, attemptId: 1, }, id: 1, }, state: C_NEW, ]
2013-08-11 09:31:29,731 INFO org.apache.hadoop.yarn.server.resourcemanager.rmapp.attempt.RMAppAttemptImpl: appattempt_1376212503271_0009_000001 State change from SCHEDULED to ALLOCATED_SAVING
2013-08-11 09:31:29,731 INFO org.apache.hadoop.yarn.server.resourcemanager.recovery.RMStateStore: Storing info for attempt: appattempt_1376212503271_0009_000001
2013-08-11 09:31:29,732 INFO org.apache.hadoop.yarn.server.resourcemanager.rmapp.attempt.RMAppAttemptImpl: appattempt_1376212503271_0009_000001 State change from ALLOCATED_SAVING to ALLOCATED
2013-08-11 09:31:29,732 INFO org.apache.hadoop.yarn.server.resourcemanager.amlauncher.AMLauncher: Launching masterappattempt_1376212503271_0009_000001
2013-08-11 09:31:29,733 INFO org.apache.hadoop.yarn.server.resourcemanager.amlauncher.AMLauncher: Setting up container Container: [ContainerId: container_1376212503271_0009_01_000001, NodeId: hadoop-320-5:36272, NodeHttpAddress: hadoop-320-5:8042, Resource: <memory:2048, vCores:1>, Priority: 0, State: NEW, Token: null, Status: container_id {, app_attempt_id {, application_id {, id: 9, cluster_timestamp: 1376212503271, }, attemptId: 1, }, id: 1, }, state: C_NEW, ] for AM appattempt_1376212503271_0009_000001
2013-08-11 09:31:29,733 INFO org.apache.hadoop.yarn.server.resourcemanager.amlauncher.AMLauncher: Command to launch container container_1376212503271_0009_01_000001 : $JAVA_HOME/bin/java -Dlog4j.configuration=container-log4j.properties -Dyarn.app.mapreduce.container.log.dir=<LOG_DIR> -Dyarn.app.mapreduce.container.log.filesize=0 -Dhadoop.root.logger=INFO,CLA  -Xmx1024m org.apache.hadoop.mapreduce.v2.app.MRAppMaster 1><LOG_DIR>/stdout 2><LOG_DIR>/stderr 
2013-08-11 09:31:29,825 INFO org.apache.hadoop.yarn.server.resourcemanager.ClientRMService: Storing Application with id application_1376212503271_0010
2013-08-11 09:31:29,825 INFO org.apache.hadoop.yarn.server.resourcemanager.recovery.RMStateStore: Storing info for app: application_1376212503271_0010
2013-08-11 09:31:29,825 INFO org.apache.hadoop.yarn.server.resourcemanager.ClientRMService: Application with id 10 submitted by user ubuntu
2013-08-11 09:31:29,825 INFO org.apache.hadoop.yarn.server.resourcemanager.RMAuditLogger: USER=ubuntu	IP=192.168.100.4	OPERATION=Submit Application Request	TARGET=ClientRMService	RESULT=SUCCESS	APPID=application_1376212503271_0010
2013-08-11 09:31:29,826 INFO org.apache.hadoop.yarn.server.resourcemanager.rmapp.RMAppImpl: application_1376212503271_0010 State change from NEW to SUBMITTED
2013-08-11 09:31:29,826 INFO org.apache.hadoop.yarn.server.resourcemanager.ApplicationMasterService: Registering appattempt_1376212503271_0010_000001
2013-08-11 09:31:29,826 INFO org.apache.hadoop.yarn.server.resourcemanager.rmapp.attempt.RMAppAttemptImpl: appattempt_1376212503271_0010_000001 State change from NEW to SUBMITTED
2013-08-11 09:31:29,826 INFO org.apache.hadoop.yarn.server.resourcemanager.scheduler.capacity.LeafQueue: Application application_1376212503271_0010 from user: ubuntu activated in queue: default
2013-08-11 09:31:29,826 INFO org.apache.hadoop.yarn.server.resourcemanager.scheduler.capacity.LeafQueue: Application added - appId: application_1376212503271_0010 user: org.apache.hadoop.yarn.server.resourcemanager.scheduler.capacity.LeafQueue$User@7a886c25, leaf-queue: default #user-pending-applications: 0 #user-active-applications: 5 #queue-pending-applications: 0 #queue-active-applications: 5
2013-08-11 09:31:29,827 INFO org.apache.hadoop.yarn.server.resourcemanager.scheduler.capacity.ParentQueue: Application added - appId: application_1376212503271_0010 user: ubuntu leaf-queue of parent: root #applications: 5
2013-08-11 09:31:29,827 INFO org.apache.hadoop.yarn.server.resourcemanager.scheduler.capacity.CapacityScheduler: Application Submission: appattempt_1376212503271_0010_000001, user: ubuntu queue: default: capacity=1.0, absoluteCapacity=1.0, usedResources=<memory:8192, vCores:4>usedCapacity=0.16666667, absoluteUsedCapacity=0.16666667, numApps=5, numContainers=4, currently active: 5
2013-08-11 09:31:29,827 INFO org.apache.hadoop.yarn.server.resourcemanager.rmapp.attempt.RMAppAttemptImpl: appattempt_1376212503271_0010_000001 State change from SUBMITTED to SCHEDULED
2013-08-11 09:31:29,827 INFO org.apache.hadoop.yarn.server.resourcemanager.rmapp.RMAppImpl: application_1376212503271_0010 State change from SUBMITTED to ACCEPTED
2013-08-11 09:31:30,278 INFO org.apache.hadoop.yarn.server.resourcemanager.rmcontainer.RMContainerImpl: container_1376212503271_0010_01_000001 Container Transitioned from NEW to ALLOCATED
2013-08-11 09:31:30,279 INFO org.apache.hadoop.yarn.server.resourcemanager.RMAuditLogger: USER=ubuntu	OPERATION=AM Allocated Container	TARGET=SchedulerApp	RESULT=SUCCESS	APPID=application_1376212503271_0010	CONTAINERID=container_1376212503271_0010_01_000001
2013-08-11 09:31:30,279 INFO org.apache.hadoop.yarn.server.resourcemanager.scheduler.common.fica.FiCaSchedulerNode: Assigned container container_1376212503271_0010_01_000001 of capacity <memory:2048, vCores:1> on host hadoop-320-3:47015, which currently has 1 containers, <memory:2048, vCores:1> used and <memory:6144, vCores:15> available
2013-08-11 09:31:30,280 INFO org.apache.hadoop.yarn.server.resourcemanager.scheduler.capacity.LeafQueue: assignedContainer application=application_1376212503271_0010 container=Container: [ContainerId: container_1376212503271_0010_01_000001, NodeId: hadoop-320-3:47015, NodeHttpAddress: hadoop-320-3:8042, Resource: <memory:2048, vCores:1>, Priority: 0, State: NEW, Token: null, Status: container_id {, app_attempt_id {, application_id {, id: 10, cluster_timestamp: 1376212503271, }, attemptId: 1, }, id: 1, }, state: C_NEW, ] containerId=container_1376212503271_0010_01_000001 queue=default: capacity=1.0, absoluteCapacity=1.0, usedResources=<memory:8192, vCores:4>usedCapacity=0.16666667, absoluteUsedCapacity=0.16666667, numApps=5, numContainers=4 usedCapacity=0.16666667 absoluteUsedCapacity=0.16666667 used=<memory:8192, vCores:4> cluster=<memory:49152, vCores:96>
2013-08-11 09:31:30,280 INFO org.apache.hadoop.yarn.server.resourcemanager.scheduler.capacity.ParentQueue: Re-sorting queues since queue: root.default stats: default: capacity=1.0, absoluteCapacity=1.0, usedResources=<memory:10240, vCores:5>usedCapacity=0.20833333, absoluteUsedCapacity=0.20833333, numApps=5, numContainers=5
2013-08-11 09:31:30,281 INFO org.apache.hadoop.yarn.server.resourcemanager.scheduler.capacity.ParentQueue: assignedContainer queue=root usedCapacity=0.20833333 absoluteUsedCapacity=0.20833333 used=<memory:10240, vCores:5> cluster=<memory:49152, vCores:96>
2013-08-11 09:31:30,283 INFO org.apache.hadoop.yarn.server.resourcemanager.rmcontainer.RMContainerImpl: container_1376212503271_0010_01_000001 Container Transitioned from ALLOCATED to ACQUIRED
2013-08-11 09:31:30,285 INFO org.apache.hadoop.yarn.server.resourcemanager.rmapp.attempt.RMAppAttemptImpl: Storing attempt: AppId: application_1376212503271_0010 AttemptId: appattempt_1376212503271_0010_000001 MasterContainer: Container: [ContainerId: container_1376212503271_0010_01_000001, NodeId: hadoop-320-3:47015, NodeHttpAddress: hadoop-320-3:8042, Resource: <memory:2048, vCores:1>, Priority: 0, State: NEW, Token: null, Status: container_id {, app_attempt_id {, application_id {, id: 10, cluster_timestamp: 1376212503271, }, attemptId: 1, }, id: 1, }, state: C_NEW, ]
2013-08-11 09:31:30,285 INFO org.apache.hadoop.yarn.server.resourcemanager.rmapp.attempt.RMAppAttemptImpl: appattempt_1376212503271_0010_000001 State change from SCHEDULED to ALLOCATED_SAVING
2013-08-11 09:31:30,285 INFO org.apache.hadoop.yarn.server.resourcemanager.recovery.RMStateStore: Storing info for attempt: appattempt_1376212503271_0010_000001
2013-08-11 09:31:30,288 INFO org.apache.hadoop.yarn.server.resourcemanager.rmapp.attempt.RMAppAttemptImpl: appattempt_1376212503271_0010_000001 State change from ALLOCATED_SAVING to ALLOCATED
2013-08-11 09:31:30,289 INFO org.apache.hadoop.yarn.server.resourcemanager.amlauncher.AMLauncher: Launching masterappattempt_1376212503271_0010_000001
2013-08-11 09:31:30,291 INFO org.apache.hadoop.yarn.server.resourcemanager.amlauncher.AMLauncher: Setting up container Container: [ContainerId: container_1376212503271_0010_01_000001, NodeId: hadoop-320-3:47015, NodeHttpAddress: hadoop-320-3:8042, Resource: <memory:2048, vCores:1>, Priority: 0, State: NEW, Token: null, Status: container_id {, app_attempt_id {, application_id {, id: 10, cluster_timestamp: 1376212503271, }, attemptId: 1, }, id: 1, }, state: C_NEW, ] for AM appattempt_1376212503271_0010_000001
2013-08-11 09:31:30,291 INFO org.apache.hadoop.yarn.server.resourcemanager.amlauncher.AMLauncher: Command to launch container container_1376212503271_0010_01_000001 : $JAVA_HOME/bin/java -Dlog4j.configuration=container-log4j.properties -Dyarn.app.mapreduce.container.log.dir=<LOG_DIR> -Dyarn.app.mapreduce.container.log.filesize=0 -Dhadoop.root.logger=INFO,CLA  -Xmx1024m org.apache.hadoop.mapreduce.v2.app.MRAppMaster 1><LOG_DIR>/stdout 2><LOG_DIR>/stderr 
2013-08-11 09:31:30,309 INFO org.apache.hadoop.yarn.server.resourcemanager.amlauncher.AMLauncher: Done launching container Container: [ContainerId: container_1376212503271_0010_01_000001, NodeId: hadoop-320-3:47015, NodeHttpAddress: hadoop-320-3:8042, Resource: <memory:2048, vCores:1>, Priority: 0, State: NEW, Token: null, Status: container_id {, app_attempt_id {, application_id {, id: 10, cluster_timestamp: 1376212503271, }, attemptId: 1, }, id: 1, }, state: C_NEW, ] for AM appattempt_1376212503271_0010_000001
2013-08-11 09:31:30,310 INFO org.apache.hadoop.yarn.server.resourcemanager.rmapp.attempt.RMAppAttemptImpl: appattempt_1376212503271_0010_000001 State change from ALLOCATED to LAUNCHED
2013-08-11 09:31:30,380 INFO org.apache.hadoop.yarn.server.resourcemanager.rmcontainer.RMContainerImpl: container_1376212503271_0006_01_000001 Container Transitioned from ACQUIRED to RUNNING
2013-08-11 09:31:30,524 INFO org.apache.hadoop.yarn.server.resourcemanager.rmcontainer.RMContainerImpl: container_1376212503271_0007_01_000001 Container Transitioned from ACQUIRED to RUNNING
2013-08-11 09:31:30,692 INFO org.apache.hadoop.yarn.server.resourcemanager.amlauncher.AMLauncher: Done launching container Container: [ContainerId: container_1376212503271_0008_01_000001, NodeId: hadoop-320-4:39920, NodeHttpAddress: hadoop-320-4:8042, Resource: <memory:2048, vCores:1>, Priority: 0, State: NEW, Token: null, Status: container_id {, app_attempt_id {, application_id {, id: 8, cluster_timestamp: 1376212503271, }, attemptId: 1, }, id: 1, }, state: C_NEW, ] for AM appattempt_1376212503271_0008_000001
2013-08-11 09:31:30,692 INFO org.apache.hadoop.yarn.server.resourcemanager.rmapp.attempt.RMAppAttemptImpl: appattempt_1376212503271_0008_000001 State change from ALLOCATED to LAUNCHED
2013-08-11 09:31:30,709 INFO org.apache.hadoop.yarn.server.resourcemanager.amlauncher.AMLauncher: Done launching container Container: [ContainerId: container_1376212503271_0009_01_000001, NodeId: hadoop-320-5:36272, NodeHttpAddress: hadoop-320-5:8042, Resource: <memory:2048, vCores:1>, Priority: 0, State: NEW, Token: null, Status: container_id {, app_attempt_id {, application_id {, id: 9, cluster_timestamp: 1376212503271, }, attemptId: 1, }, id: 1, }, state: C_NEW, ] for AM appattempt_1376212503271_0009_000001
2013-08-11 09:31:30,709 INFO org.apache.hadoop.yarn.server.resourcemanager.rmapp.attempt.RMAppAttemptImpl: appattempt_1376212503271_0009_000001 State change from ALLOCATED to LAUNCHED
2013-08-11 09:31:30,721 INFO org.apache.hadoop.yarn.server.resourcemanager.rmcontainer.RMContainerImpl: container_1376212503271_0008_01_000001 Container Transitioned from ACQUIRED to RUNNING
2013-08-11 09:31:30,745 INFO org.apache.hadoop.yarn.server.resourcemanager.rmcontainer.RMContainerImpl: container_1376212503271_0009_01_000001 Container Transitioned from ACQUIRED to RUNNING
2013-08-11 09:31:31,284 INFO org.apache.hadoop.yarn.server.resourcemanager.rmcontainer.RMContainerImpl: container_1376212503271_0010_01_000001 Container Transitioned from ACQUIRED to RUNNING
2013-08-11 09:31:36,045 INFO org.apache.hadoop.yarn.server.resourcemanager.ApplicationMasterService: AM registration appattempt_1376212503271_0007_000001
2013-08-11 09:31:36,045 INFO org.apache.hadoop.yarn.server.resourcemanager.RMAuditLogger: USER=ubuntu	IP=192.168.100.11	OPERATION=Register App Master	TARGET=ApplicationMasterService	RESULT=SUCCESS	APPID=application_1376212503271_0007	APPATTEMPTID=appattempt_1376212503271_0007_000001
2013-08-11 09:31:36,046 INFO org.apache.hadoop.yarn.server.resourcemanager.rmapp.attempt.RMAppAttemptImpl: appattempt_1376212503271_0007_000001 State change from LAUNCHED to RUNNING
2013-08-11 09:31:36,047 INFO org.apache.hadoop.yarn.server.resourcemanager.rmapp.RMAppImpl: application_1376212503271_0007 State change from ACCEPTED to RUNNING
2013-08-11 09:31:36,803 INFO org.apache.hadoop.yarn.server.resourcemanager.ApplicationMasterService: AM registration appattempt_1376212503271_0006_000001
2013-08-11 09:31:36,803 INFO org.apache.hadoop.yarn.server.resourcemanager.RMAuditLogger: USER=ubuntu	IP=192.168.100.22	OPERATION=Register App Master	TARGET=ApplicationMasterService	RESULT=SUCCESS	APPID=application_1376212503271_0006	APPATTEMPTID=appattempt_1376212503271_0006_000001
2013-08-11 09:31:36,804 INFO org.apache.hadoop.yarn.server.resourcemanager.rmapp.attempt.RMAppAttemptImpl: appattempt_1376212503271_0006_000001 State change from LAUNCHED to RUNNING
2013-08-11 09:31:36,804 INFO org.apache.hadoop.yarn.server.resourcemanager.rmapp.RMAppImpl: application_1376212503271_0006 State change from ACCEPTED to RUNNING
2013-08-11 09:31:37,066 INFO org.apache.hadoop.yarn.server.resourcemanager.ApplicationMasterService: AM registration appattempt_1376212503271_0010_000001
2013-08-11 09:31:37,067 INFO org.apache.hadoop.yarn.server.resourcemanager.RMAuditLogger: USER=ubuntu	IP=192.168.100.13	OPERATION=Register App Master	TARGET=ApplicationMasterService	RESULT=SUCCESS	APPID=application_1376212503271_0010	APPATTEMPTID=appattempt_1376212503271_0010_000001
2013-08-11 09:31:37,068 INFO org.apache.hadoop.yarn.server.resourcemanager.rmapp.attempt.RMAppAttemptImpl: appattempt_1376212503271_0010_000001 State change from LAUNCHED to RUNNING
2013-08-11 09:31:37,068 INFO org.apache.hadoop.yarn.server.resourcemanager.rmapp.RMAppImpl: application_1376212503271_0010 State change from ACCEPTED to RUNNING
2013-08-11 09:31:37,306 INFO org.apache.hadoop.yarn.server.resourcemanager.rmcontainer.RMContainerImpl: container_1376212503271_0007_01_000002 Container Transitioned from NEW to ALLOCATED
2013-08-11 09:31:37,306 INFO org.apache.hadoop.yarn.server.resourcemanager.RMAuditLogger: USER=ubuntu	OPERATION=AM Allocated Container	TARGET=SchedulerApp	RESULT=SUCCESS	APPID=application_1376212503271_0007	CONTAINERID=container_1376212503271_0007_01_000002
2013-08-11 09:31:37,306 INFO org.apache.hadoop.yarn.server.resourcemanager.scheduler.common.fica.FiCaSchedulerNode: Assigned container container_1376212503271_0007_01_000002 of capacity <memory:1024, vCores:1> on host hadoop-320-3:47015, which currently has 2 containers, <memory:3072, vCores:2> used and <memory:5120, vCores:14> available
2013-08-11 09:31:37,308 INFO org.apache.hadoop.yarn.server.resourcemanager.scheduler.capacity.LeafQueue: assignedContainer application=application_1376212503271_0007 container=Container: [ContainerId: container_1376212503271_0007_01_000002, NodeId: hadoop-320-3:47015, NodeHttpAddress: hadoop-320-3:8042, Resource: <memory:1024, vCores:1>, Priority: 20, State: NEW, Token: null, Status: container_id {, app_attempt_id {, application_id {, id: 7, cluster_timestamp: 1376212503271, }, attemptId: 1, }, id: 2, }, state: C_NEW, ] containerId=container_1376212503271_0007_01_000002 queue=default: capacity=1.0, absoluteCapacity=1.0, usedResources=<memory:10240, vCores:5>usedCapacity=0.20833333, absoluteUsedCapacity=0.20833333, numApps=5, numContainers=5 usedCapacity=0.20833333 absoluteUsedCapacity=0.20833333 used=<memory:10240, vCores:5> cluster=<memory:49152, vCores:96>
2013-08-11 09:31:37,308 INFO org.apache.hadoop.yarn.server.resourcemanager.scheduler.capacity.ParentQueue: Re-sorting queues since queue: root.default stats: default: capacity=1.0, absoluteCapacity=1.0, usedResources=<memory:11264, vCores:6>usedCapacity=0.22916667, absoluteUsedCapacity=0.22916667, numApps=5, numContainers=6
2013-08-11 09:31:37,308 INFO org.apache.hadoop.yarn.server.resourcemanager.scheduler.capacity.ParentQueue: assignedContainer queue=root usedCapacity=0.22916667 absoluteUsedCapacity=0.22916667 used=<memory:11264, vCores:6> cluster=<memory:49152, vCores:96>
2013-08-11 09:31:37,308 INFO org.apache.hadoop.yarn.server.resourcemanager.rmcontainer.RMContainerImpl: container_1376212503271_0007_01_000003 Container Transitioned from NEW to ALLOCATED
2013-08-11 09:31:37,309 INFO org.apache.hadoop.yarn.server.resourcemanager.RMAuditLogger: USER=ubuntu	OPERATION=AM Allocated Container	TARGET=SchedulerApp	RESULT=SUCCESS	APPID=application_1376212503271_0007	CONTAINERID=container_1376212503271_0007_01_000003
2013-08-11 09:31:37,309 INFO org.apache.hadoop.yarn.server.resourcemanager.scheduler.common.fica.FiCaSchedulerNode: Assigned container container_1376212503271_0007_01_000003 of capacity <memory:1024, vCores:1> on host hadoop-320-3:47015, which currently has 3 containers, <memory:4096, vCores:3> used and <memory:4096, vCores:13> available
2013-08-11 09:31:37,310 INFO org.apache.hadoop.yarn.server.resourcemanager.scheduler.capacity.LeafQueue: assignedContainer application=application_1376212503271_0007 container=Container: [ContainerId: container_1376212503271_0007_01_000003, NodeId: hadoop-320-3:47015, NodeHttpAddress: hadoop-320-3:8042, Resource: <memory:1024, vCores:1>, Priority: 20, State: NEW, Token: null, Status: container_id {, app_attempt_id {, application_id {, id: 7, cluster_timestamp: 1376212503271, }, attemptId: 1, }, id: 3, }, state: C_NEW, ] containerId=container_1376212503271_0007_01_000003 queue=default: capacity=1.0, absoluteCapacity=1.0, usedResources=<memory:11264, vCores:6>usedCapacity=0.22916667, absoluteUsedCapacity=0.22916667, numApps=5, numContainers=6 usedCapacity=0.22916667 absoluteUsedCapacity=0.22916667 used=<memory:11264, vCores:6> cluster=<memory:49152, vCores:96>
2013-08-11 09:31:37,310 INFO org.apache.hadoop.yarn.server.resourcemanager.scheduler.capacity.ParentQueue: Re-sorting queues since queue: root.default stats: default: capacity=1.0, absoluteCapacity=1.0, usedResources=<memory:12288, vCores:7>usedCapacity=0.25, absoluteUsedCapacity=0.25, numApps=5, numContainers=7
2013-08-11 09:31:37,310 INFO org.apache.hadoop.yarn.server.resourcemanager.scheduler.capacity.ParentQueue: assignedContainer queue=root usedCapacity=0.25 absoluteUsedCapacity=0.25 used=<memory:12288, vCores:7> cluster=<memory:49152, vCores:96>
2013-08-11 09:31:37,310 INFO org.apache.hadoop.yarn.server.resourcemanager.rmcontainer.RMContainerImpl: container_1376212503271_0007_01_000004 Container Transitioned from NEW to ALLOCATED
2013-08-11 09:31:37,311 INFO org.apache.hadoop.yarn.server.resourcemanager.RMAuditLogger: USER=ubuntu	OPERATION=AM Allocated Container	TARGET=SchedulerApp	RESULT=SUCCESS	APPID=application_1376212503271_0007	CONTAINERID=container_1376212503271_0007_01_000004
2013-08-11 09:31:37,311 INFO org.apache.hadoop.yarn.server.resourcemanager.scheduler.common.fica.FiCaSchedulerNode: Assigned container container_1376212503271_0007_01_000004 of capacity <memory:1024, vCores:1> on host hadoop-320-3:47015, which currently has 4 containers, <memory:5120, vCores:4> used and <memory:3072, vCores:12> available
2013-08-11 09:31:37,314 INFO org.apache.hadoop.yarn.server.resourcemanager.scheduler.capacity.LeafQueue: assignedContainer application=application_1376212503271_0007 container=Container: [ContainerId: container_1376212503271_0007_01_000004, NodeId: hadoop-320-3:47015, NodeHttpAddress: hadoop-320-3:8042, Resource: <memory:1024, vCores:1>, Priority: 20, State: NEW, Token: null, Status: container_id {, app_attempt_id {, application_id {, id: 7, cluster_timestamp: 1376212503271, }, attemptId: 1, }, id: 4, }, state: C_NEW, ] containerId=container_1376212503271_0007_01_000004 queue=default: capacity=1.0, absoluteCapacity=1.0, usedResources=<memory:12288, vCores:7>usedCapacity=0.25, absoluteUsedCapacity=0.25, numApps=5, numContainers=7 usedCapacity=0.25 absoluteUsedCapacity=0.25 used=<memory:12288, vCores:7> cluster=<memory:49152, vCores:96>
2013-08-11 09:31:37,314 INFO org.apache.hadoop.yarn.server.resourcemanager.scheduler.capacity.ParentQueue: Re-sorting queues since queue: root.default stats: default: capacity=1.0, absoluteCapacity=1.0, usedResources=<memory:13312, vCores:8>usedCapacity=0.27083334, absoluteUsedCapacity=0.27083334, numApps=5, numContainers=8
2013-08-11 09:31:37,314 INFO org.apache.hadoop.yarn.server.resourcemanager.scheduler.capacity.ParentQueue: assignedContainer queue=root usedCapacity=0.27083334 absoluteUsedCapacity=0.27083334 used=<memory:13312, vCores:8> cluster=<memory:49152, vCores:96>
2013-08-11 09:31:37,314 INFO org.apache.hadoop.yarn.server.resourcemanager.rmcontainer.RMContainerImpl: container_1376212503271_0007_01_000005 Container Transitioned from NEW to ALLOCATED
2013-08-11 09:31:37,315 INFO org.apache.hadoop.yarn.server.resourcemanager.RMAuditLogger: USER=ubuntu	OPERATION=AM Allocated Container	TARGET=SchedulerApp	RESULT=SUCCESS	APPID=application_1376212503271_0007	CONTAINERID=container_1376212503271_0007_01_000005
2013-08-11 09:31:37,315 INFO org.apache.hadoop.yarn.server.resourcemanager.scheduler.common.fica.FiCaSchedulerNode: Assigned container container_1376212503271_0007_01_000005 of capacity <memory:1024, vCores:1> on host hadoop-320-3:47015, which currently has 5 containers, <memory:6144, vCores:5> used and <memory:2048, vCores:11> available
2013-08-11 09:31:37,316 INFO org.apache.hadoop.yarn.server.resourcemanager.scheduler.capacity.LeafQueue: assignedContainer application=application_1376212503271_0007 container=Container: [ContainerId: container_1376212503271_0007_01_000005, NodeId: hadoop-320-3:47015, NodeHttpAddress: hadoop-320-3:8042, Resource: <memory:1024, vCores:1>, Priority: 20, State: NEW, Token: null, Status: container_id {, app_attempt_id {, application_id {, id: 7, cluster_timestamp: 1376212503271, }, attemptId: 1, }, id: 5, }, state: C_NEW, ] containerId=container_1376212503271_0007_01_000005 queue=default: capacity=1.0, absoluteCapacity=1.0, usedResources=<memory:13312, vCores:8>usedCapacity=0.27083334, absoluteUsedCapacity=0.27083334, numApps=5, numContainers=8 usedCapacity=0.27083334 absoluteUsedCapacity=0.27083334 used=<memory:13312, vCores:8> cluster=<memory:49152, vCores:96>
2013-08-11 09:31:37,316 INFO org.apache.hadoop.yarn.server.resourcemanager.scheduler.capacity.ParentQueue: Re-sorting queues since queue: root.default stats: default: capacity=1.0, absoluteCapacity=1.0, usedResources=<memory:14336, vCores:9>usedCapacity=0.29166666, absoluteUsedCapacity=0.29166666, numApps=5, numContainers=9
2013-08-11 09:31:37,316 INFO org.apache.hadoop.yarn.server.resourcemanager.scheduler.capacity.ParentQueue: assignedContainer queue=root usedCapacity=0.29166666 absoluteUsedCapacity=0.29166666 used=<memory:14336, vCores:9> cluster=<memory:49152, vCores:96>
2013-08-11 09:31:37,317 INFO org.apache.hadoop.yarn.server.resourcemanager.rmcontainer.RMContainerImpl: container_1376212503271_0007_01_000006 Container Transitioned from NEW to ALLOCATED
2013-08-11 09:31:37,317 INFO org.apache.hadoop.yarn.server.resourcemanager.RMAuditLogger: USER=ubuntu	OPERATION=AM Allocated Container	TARGET=SchedulerApp	RESULT=SUCCESS	APPID=application_1376212503271_0007	CONTAINERID=container_1376212503271_0007_01_000006
2013-08-11 09:31:37,317 INFO org.apache.hadoop.yarn.server.resourcemanager.scheduler.common.fica.FiCaSchedulerNode: Assigned container container_1376212503271_0007_01_000006 of capacity <memory:1024, vCores:1> on host hadoop-320-3:47015, which currently has 6 containers, <memory:7168, vCores:6> used and <memory:1024, vCores:10> available
2013-08-11 09:31:37,318 INFO org.apache.hadoop.yarn.server.resourcemanager.scheduler.capacity.LeafQueue: assignedContainer application=application_1376212503271_0007 container=Container: [ContainerId: container_1376212503271_0007_01_000006, NodeId: hadoop-320-3:47015, NodeHttpAddress: hadoop-320-3:8042, Resource: <memory:1024, vCores:1>, Priority: 20, State: NEW, Token: null, Status: container_id {, app_attempt_id {, application_id {, id: 7, cluster_timestamp: 1376212503271, }, attemptId: 1, }, id: 6, }, state: C_NEW, ] containerId=container_1376212503271_0007_01_000006 queue=default: capacity=1.0, absoluteCapacity=1.0, usedResources=<memory:14336, vCores:9>usedCapacity=0.29166666, absoluteUsedCapacity=0.29166666, numApps=5, numContainers=9 usedCapacity=0.29166666 absoluteUsedCapacity=0.29166666 used=<memory:14336, vCores:9> cluster=<memory:49152, vCores:96>
2013-08-11 09:31:37,318 INFO org.apache.hadoop.yarn.server.resourcemanager.scheduler.capacity.ParentQueue: Re-sorting queues since queue: root.default stats: default: capacity=1.0, absoluteCapacity=1.0, usedResources=<memory:15360, vCores:10>usedCapacity=0.3125, absoluteUsedCapacity=0.3125, numApps=5, numContainers=10
2013-08-11 09:31:37,318 INFO org.apache.hadoop.yarn.server.resourcemanager.scheduler.capacity.ParentQueue: assignedContainer queue=root usedCapacity=0.3125 absoluteUsedCapacity=0.3125 used=<memory:15360, vCores:10> cluster=<memory:49152, vCores:96>
2013-08-11 09:31:37,319 INFO org.apache.hadoop.yarn.server.resourcemanager.rmcontainer.RMContainerImpl: container_1376212503271_0007_01_000007 Container Transitioned from NEW to ALLOCATED
2013-08-11 09:31:37,319 INFO org.apache.hadoop.yarn.server.resourcemanager.RMAuditLogger: USER=ubuntu	OPERATION=AM Allocated Container	TARGET=SchedulerApp	RESULT=SUCCESS	APPID=application_1376212503271_0007	CONTAINERID=container_1376212503271_0007_01_000007
2013-08-11 09:31:37,319 INFO org.apache.hadoop.yarn.server.resourcemanager.scheduler.common.fica.FiCaSchedulerNode: Assigned container container_1376212503271_0007_01_000007 of capacity <memory:1024, vCores:1> on host hadoop-320-3:47015, which currently has 7 containers, <memory:8192, vCores:7> used and <memory:0, vCores:9> available
2013-08-11 09:31:37,320 INFO org.apache.hadoop.yarn.server.resourcemanager.scheduler.capacity.LeafQueue: assignedContainer application=application_1376212503271_0007 container=Container: [ContainerId: container_1376212503271_0007_01_000007, NodeId: hadoop-320-3:47015, NodeHttpAddress: hadoop-320-3:8042, Resource: <memory:1024, vCores:1>, Priority: 20, State: NEW, Token: null, Status: container_id {, app_attempt_id {, application_id {, id: 7, cluster_timestamp: 1376212503271, }, attemptId: 1, }, id: 7, }, state: C_NEW, ] containerId=container_1376212503271_0007_01_000007 queue=default: capacity=1.0, absoluteCapacity=1.0, usedResources=<memory:15360, vCores:10>usedCapacity=0.3125, absoluteUsedCapacity=0.3125, numApps=5, numContainers=10 usedCapacity=0.3125 absoluteUsedCapacity=0.3125 used=<memory:15360, vCores:10> cluster=<memory:49152, vCores:96>
2013-08-11 09:31:37,320 INFO org.apache.hadoop.yarn.server.resourcemanager.scheduler.capacity.ParentQueue: Re-sorting queues since queue: root.default stats: default: capacity=1.0, absoluteCapacity=1.0, usedResources=<memory:16384, vCores:11>usedCapacity=0.33333334, absoluteUsedCapacity=0.33333334, numApps=5, numContainers=11
2013-08-11 09:31:37,320 INFO org.apache.hadoop.yarn.server.resourcemanager.scheduler.capacity.ParentQueue: assignedContainer queue=root usedCapacity=0.33333334 absoluteUsedCapacity=0.33333334 used=<memory:16384, vCores:11> cluster=<memory:49152, vCores:96>
2013-08-11 09:31:37,321 INFO org.apache.hadoop.yarn.server.resourcemanager.rmcontainer.RMContainerImpl: container_1376212503271_0007_01_000008 Container Transitioned from NEW to ALLOCATED
2013-08-11 09:31:37,321 INFO org.apache.hadoop.yarn.server.resourcemanager.RMAuditLogger: USER=ubuntu	OPERATION=AM Allocated Container	TARGET=SchedulerApp	RESULT=SUCCESS	APPID=application_1376212503271_0007	CONTAINERID=container_1376212503271_0007_01_000008
2013-08-11 09:31:37,321 INFO org.apache.hadoop.yarn.server.resourcemanager.scheduler.common.fica.FiCaSchedulerNode: Assigned container container_1376212503271_0007_01_000008 of capacity <memory:1024, vCores:1> on host hadoop-320-6:38980, which currently has 1 containers, <memory:1024, vCores:1> used and <memory:7168, vCores:15> available
2013-08-11 09:31:37,322 INFO org.apache.hadoop.yarn.server.resourcemanager.scheduler.capacity.LeafQueue: assignedContainer application=application_1376212503271_0007 container=Container: [ContainerId: container_1376212503271_0007_01_000008, NodeId: hadoop-320-6:38980, NodeHttpAddress: hadoop-320-6:8042, Resource: <memory:1024, vCores:1>, Priority: 20, State: NEW, Token: null, Status: container_id {, app_attempt_id {, application_id {, id: 7, cluster_timestamp: 1376212503271, }, attemptId: 1, }, id: 8, }, state: C_NEW, ] containerId=container_1376212503271_0007_01_000008 queue=default: capacity=1.0, absoluteCapacity=1.0, usedResources=<memory:16384, vCores:11>usedCapacity=0.33333334, absoluteUsedCapacity=0.33333334, numApps=5, numContainers=11 usedCapacity=0.33333334 absoluteUsedCapacity=0.33333334 used=<memory:16384, vCores:11> cluster=<memory:49152, vCores:96>
2013-08-11 09:31:37,322 INFO org.apache.hadoop.yarn.server.resourcemanager.scheduler.capacity.ParentQueue: Re-sorting queues since queue: root.default stats: default: capacity=1.0, absoluteCapacity=1.0, usedResources=<memory:17408, vCores:12>usedCapacity=0.35416666, absoluteUsedCapacity=0.35416666, numApps=5, numContainers=12
2013-08-11 09:31:37,323 INFO org.apache.hadoop.yarn.server.resourcemanager.scheduler.capacity.ParentQueue: assignedContainer queue=root usedCapacity=0.35416666 absoluteUsedCapacity=0.35416666 used=<memory:17408, vCores:12> cluster=<memory:49152, vCores:96>
2013-08-11 09:31:37,323 INFO org.apache.hadoop.yarn.server.resourcemanager.rmcontainer.RMContainerImpl: container_1376212503271_0007_01_000009 Container Transitioned from NEW to ALLOCATED
2013-08-11 09:31:37,323 INFO org.apache.hadoop.yarn.server.resourcemanager.RMAuditLogger: USER=ubuntu	OPERATION=AM Allocated Container	TARGET=SchedulerApp	RESULT=SUCCESS	APPID=application_1376212503271_0007	CONTAINERID=container_1376212503271_0007_01_000009
2013-08-11 09:31:37,323 INFO org.apache.hadoop.yarn.server.resourcemanager.scheduler.common.fica.FiCaSchedulerNode: Assigned container container_1376212503271_0007_01_000009 of capacity <memory:1024, vCores:1> on host hadoop-320-6:38980, which currently has 2 containers, <memory:2048, vCores:2> used and <memory:6144, vCores:14> available
2013-08-11 09:31:37,324 INFO org.apache.hadoop.yarn.server.resourcemanager.scheduler.capacity.LeafQueue: assignedContainer application=application_1376212503271_0007 container=Container: [ContainerId: container_1376212503271_0007_01_000009, NodeId: hadoop-320-6:38980, NodeHttpAddress: hadoop-320-6:8042, Resource: <memory:1024, vCores:1>, Priority: 20, State: NEW, Token: null, Status: container_id {, app_attempt_id {, application_id {, id: 7, cluster_timestamp: 1376212503271, }, attemptId: 1, }, id: 9, }, state: C_NEW, ] containerId=container_1376212503271_0007_01_000009 queue=default: capacity=1.0, absoluteCapacity=1.0, usedResources=<memory:17408, vCores:12>usedCapacity=0.35416666, absoluteUsedCapacity=0.35416666, numApps=5, numContainers=12 usedCapacity=0.35416666 absoluteUsedCapacity=0.35416666 used=<memory:17408, vCores:12> cluster=<memory:49152, vCores:96>
2013-08-11 09:31:37,325 INFO org.apache.hadoop.yarn.server.resourcemanager.scheduler.capacity.ParentQueue: Re-sorting queues since queue: root.default stats: default: capacity=1.0, absoluteCapacity=1.0, usedResources=<memory:18432, vCores:13>usedCapacity=0.375, absoluteUsedCapacity=0.375, numApps=5, numContainers=13
2013-08-11 09:31:37,325 INFO org.apache.hadoop.yarn.server.resourcemanager.scheduler.capacity.ParentQueue: assignedContainer queue=root usedCapacity=0.375 absoluteUsedCapacity=0.375 used=<memory:18432, vCores:13> cluster=<memory:49152, vCores:96>
2013-08-11 09:31:37,325 INFO org.apache.hadoop.yarn.server.resourcemanager.rmcontainer.RMContainerImpl: container_1376212503271_0007_01_000010 Container Transitioned from NEW to ALLOCATED
2013-08-11 09:31:37,325 INFO org.apache.hadoop.yarn.server.resourcemanager.RMAuditLogger: USER=ubuntu	OPERATION=AM Allocated Container	TARGET=SchedulerApp	RESULT=SUCCESS	APPID=application_1376212503271_0007	CONTAINERID=container_1376212503271_0007_01_000010
2013-08-11 09:31:37,326 INFO org.apache.hadoop.yarn.server.resourcemanager.scheduler.common.fica.FiCaSchedulerNode: Assigned container container_1376212503271_0007_01_000010 of capacity <memory:1024, vCores:1> on host hadoop-320-6:38980, which currently has 3 containers, <memory:3072, vCores:3> used and <memory:5120, vCores:13> available
2013-08-11 09:31:37,327 INFO org.apache.hadoop.yarn.server.resourcemanager.scheduler.capacity.LeafQueue: assignedContainer application=application_1376212503271_0007 container=Container: [ContainerId: container_1376212503271_0007_01_000010, NodeId: hadoop-320-6:38980, NodeHttpAddress: hadoop-320-6:8042, Resource: <memory:1024, vCores:1>, Priority: 20, State: NEW, Token: null, Status: container_id {, app_attempt_id {, application_id {, id: 7, cluster_timestamp: 1376212503271, }, attemptId: 1, }, id: 10, }, state: C_NEW, ] containerId=container_1376212503271_0007_01_000010 queue=default: capacity=1.0, absoluteCapacity=1.0, usedResources=<memory:18432, vCores:13>usedCapacity=0.375, absoluteUsedCapacity=0.375, numApps=5, numContainers=13 usedCapacity=0.375 absoluteUsedCapacity=0.375 used=<memory:18432, vCores:13> cluster=<memory:49152, vCores:96>
2013-08-11 09:31:37,327 INFO org.apache.hadoop.yarn.server.resourcemanager.scheduler.capacity.ParentQueue: Re-sorting queues since queue: root.default stats: default: capacity=1.0, absoluteCapacity=1.0, usedResources=<memory:19456, vCores:14>usedCapacity=0.39583334, absoluteUsedCapacity=0.39583334, numApps=5, numContainers=14
2013-08-11 09:31:37,327 INFO org.apache.hadoop.yarn.server.resourcemanager.scheduler.capacity.ParentQueue: assignedContainer queue=root usedCapacity=0.39583334 absoluteUsedCapacity=0.39583334 used=<memory:19456, vCores:14> cluster=<memory:49152, vCores:96>
2013-08-11 09:31:37,327 INFO org.apache.hadoop.yarn.server.resourcemanager.rmcontainer.RMContainerImpl: container_1376212503271_0007_01_000011 Container Transitioned from NEW to ALLOCATED
2013-08-11 09:31:37,327 INFO org.apache.hadoop.yarn.server.resourcemanager.RMAuditLogger: USER=ubuntu	OPERATION=AM Allocated Container	TARGET=SchedulerApp	RESULT=SUCCESS	APPID=application_1376212503271_0007	CONTAINERID=container_1376212503271_0007_01_000011
2013-08-11 09:31:37,328 INFO org.apache.hadoop.yarn.server.resourcemanager.scheduler.common.fica.FiCaSchedulerNode: Assigned container container_1376212503271_0007_01_000011 of capacity <memory:1024, vCores:1> on host hadoop-320-6:38980, which currently has 4 containers, <memory:4096, vCores:4> used and <memory:4096, vCores:12> available
2013-08-11 09:31:37,331 INFO org.apache.hadoop.yarn.server.resourcemanager.scheduler.capacity.LeafQueue: assignedContainer application=application_1376212503271_0007 container=Container: [ContainerId: container_1376212503271_0007_01_000011, NodeId: hadoop-320-6:38980, NodeHttpAddress: hadoop-320-6:8042, Resource: <memory:1024, vCores:1>, Priority: 20, State: NEW, Token: null, Status: container_id {, app_attempt_id {, application_id {, id: 7, cluster_timestamp: 1376212503271, }, attemptId: 1, }, id: 11, }, state: C_NEW, ] containerId=container_1376212503271_0007_01_000011 queue=default: capacity=1.0, absoluteCapacity=1.0, usedResources=<memory:19456, vCores:14>usedCapacity=0.39583334, absoluteUsedCapacity=0.39583334, numApps=5, numContainers=14 usedCapacity=0.39583334 absoluteUsedCapacity=0.39583334 used=<memory:19456, vCores:14> cluster=<memory:49152, vCores:96>
2013-08-11 09:31:37,331 INFO org.apache.hadoop.yarn.server.resourcemanager.scheduler.capacity.ParentQueue: Re-sorting queues since queue: root.default stats: default: capacity=1.0, absoluteCapacity=1.0, usedResources=<memory:20480, vCores:15>usedCapacity=0.41666666, absoluteUsedCapacity=0.41666666, numApps=5, numContainers=15
2013-08-11 09:31:37,331 INFO org.apache.hadoop.yarn.server.resourcemanager.scheduler.capacity.ParentQueue: assignedContainer queue=root usedCapacity=0.41666666 absoluteUsedCapacity=0.41666666 used=<memory:20480, vCores:15> cluster=<memory:49152, vCores:96>
2013-08-11 09:31:37,332 INFO org.apache.hadoop.yarn.server.resourcemanager.rmcontainer.RMContainerImpl: container_1376212503271_0007_01_000012 Container Transitioned from NEW to ALLOCATED
2013-08-11 09:31:37,332 INFO org.apache.hadoop.yarn.server.resourcemanager.RMAuditLogger: USER=ubuntu	OPERATION=AM Allocated Container	TARGET=SchedulerApp	RESULT=SUCCESS	APPID=application_1376212503271_0007	CONTAINERID=container_1376212503271_0007_01_000012
2013-08-11 09:31:37,332 INFO org.apache.hadoop.yarn.server.resourcemanager.scheduler.common.fica.FiCaSchedulerNode: Assigned container container_1376212503271_0007_01_000012 of capacity <memory:1024, vCores:1> on host hadoop-320-6:38980, which currently has 5 containers, <memory:5120, vCores:5> used and <memory:3072, vCores:11> available
2013-08-11 09:31:37,333 INFO org.apache.hadoop.yarn.server.resourcemanager.scheduler.capacity.LeafQueue: assignedContainer application=application_1376212503271_0007 container=Container: [ContainerId: container_1376212503271_0007_01_000012, NodeId: hadoop-320-6:38980, NodeHttpAddress: hadoop-320-6:8042, Resource: <memory:1024, vCores:1>, Priority: 20, State: NEW, Token: null, Status: container_id {, app_attempt_id {, application_id {, id: 7, cluster_timestamp: 1376212503271, }, attemptId: 1, }, id: 12, }, state: C_NEW, ] containerId=container_1376212503271_0007_01_000012 queue=default: capacity=1.0, absoluteCapacity=1.0, usedResources=<memory:20480, vCores:15>usedCapacity=0.41666666, absoluteUsedCapacity=0.41666666, numApps=5, numContainers=15 usedCapacity=0.41666666 absoluteUsedCapacity=0.41666666 used=<memory:20480, vCores:15> cluster=<memory:49152, vCores:96>
2013-08-11 09:31:37,333 INFO org.apache.hadoop.yarn.server.resourcemanager.scheduler.capacity.ParentQueue: Re-sorting queues since queue: root.default stats: default: capacity=1.0, absoluteCapacity=1.0, usedResources=<memory:21504, vCores:16>usedCapacity=0.4375, absoluteUsedCapacity=0.4375, numApps=5, numContainers=16
2013-08-11 09:31:37,333 INFO org.apache.hadoop.yarn.server.resourcemanager.scheduler.capacity.ParentQueue: assignedContainer queue=root usedCapacity=0.4375 absoluteUsedCapacity=0.4375 used=<memory:21504, vCores:16> cluster=<memory:49152, vCores:96>
2013-08-11 09:31:37,334 INFO org.apache.hadoop.yarn.server.resourcemanager.rmcontainer.RMContainerImpl: container_1376212503271_0007_01_000013 Container Transitioned from NEW to ALLOCATED
2013-08-11 09:31:37,334 INFO org.apache.hadoop.yarn.server.resourcemanager.RMAuditLogger: USER=ubuntu	OPERATION=AM Allocated Container	TARGET=SchedulerApp	RESULT=SUCCESS	APPID=application_1376212503271_0007	CONTAINERID=container_1376212503271_0007_01_000013
2013-08-11 09:31:37,334 INFO org.apache.hadoop.yarn.server.resourcemanager.scheduler.common.fica.FiCaSchedulerNode: Assigned container container_1376212503271_0007_01_000013 of capacity <memory:1024, vCores:1> on host hadoop-320-6:38980, which currently has 6 containers, <memory:6144, vCores:6> used and <memory:2048, vCores:10> available
2013-08-11 09:31:37,335 INFO org.apache.hadoop.yarn.server.resourcemanager.scheduler.capacity.LeafQueue: assignedContainer application=application_1376212503271_0007 container=Container: [ContainerId: container_1376212503271_0007_01_000013, NodeId: hadoop-320-6:38980, NodeHttpAddress: hadoop-320-6:8042, Resource: <memory:1024, vCores:1>, Priority: 20, State: NEW, Token: null, Status: container_id {, app_attempt_id {, application_id {, id: 7, cluster_timestamp: 1376212503271, }, attemptId: 1, }, id: 13, }, state: C_NEW, ] containerId=container_1376212503271_0007_01_000013 queue=default: capacity=1.0, absoluteCapacity=1.0, usedResources=<memory:21504, vCores:16>usedCapacity=0.4375, absoluteUsedCapacity=0.4375, numApps=5, numContainers=16 usedCapacity=0.4375 absoluteUsedCapacity=0.4375 used=<memory:21504, vCores:16> cluster=<memory:49152, vCores:96>
2013-08-11 09:31:37,335 INFO org.apache.hadoop.yarn.server.resourcemanager.scheduler.capacity.ParentQueue: Re-sorting queues since queue: root.default stats: default: capacity=1.0, absoluteCapacity=1.0, usedResources=<memory:22528, vCores:17>usedCapacity=0.45833334, absoluteUsedCapacity=0.45833334, numApps=5, numContainers=17
2013-08-11 09:31:37,335 INFO org.apache.hadoop.yarn.server.resourcemanager.scheduler.capacity.ParentQueue: assignedContainer queue=root usedCapacity=0.45833334 absoluteUsedCapacity=0.45833334 used=<memory:22528, vCores:17> cluster=<memory:49152, vCores:96>
2013-08-11 09:31:37,336 INFO org.apache.hadoop.yarn.server.resourcemanager.rmcontainer.RMContainerImpl: container_1376212503271_0007_01_000014 Container Transitioned from NEW to ALLOCATED
2013-08-11 09:31:37,336 INFO org.apache.hadoop.yarn.server.resourcemanager.RMAuditLogger: USER=ubuntu	OPERATION=AM Allocated Container	TARGET=SchedulerApp	RESULT=SUCCESS	APPID=application_1376212503271_0007	CONTAINERID=container_1376212503271_0007_01_000014
2013-08-11 09:31:37,336 INFO org.apache.hadoop.yarn.server.resourcemanager.scheduler.common.fica.FiCaSchedulerNode: Assigned container container_1376212503271_0007_01_000014 of capacity <memory:1024, vCores:1> on host hadoop-320-6:38980, which currently has 7 containers, <memory:7168, vCores:7> used and <memory:1024, vCores:9> available
2013-08-11 09:31:37,337 INFO org.apache.hadoop.yarn.server.resourcemanager.scheduler.capacity.LeafQueue: assignedContainer application=application_1376212503271_0007 container=Container: [ContainerId: container_1376212503271_0007_01_000014, NodeId: hadoop-320-6:38980, NodeHttpAddress: hadoop-320-6:8042, Resource: <memory:1024, vCores:1>, Priority: 20, State: NEW, Token: null, Status: container_id {, app_attempt_id {, application_id {, id: 7, cluster_timestamp: 1376212503271, }, attemptId: 1, }, id: 14, }, state: C_NEW, ] containerId=container_1376212503271_0007_01_000014 queue=default: capacity=1.0, absoluteCapacity=1.0, usedResources=<memory:22528, vCores:17>usedCapacity=0.45833334, absoluteUsedCapacity=0.45833334, numApps=5, numContainers=17 usedCapacity=0.45833334 absoluteUsedCapacity=0.45833334 used=<memory:22528, vCores:17> cluster=<memory:49152, vCores:96>
2013-08-11 09:31:37,337 INFO org.apache.hadoop.yarn.server.resourcemanager.scheduler.capacity.ParentQueue: Re-sorting queues since queue: root.default stats: default: capacity=1.0, absoluteCapacity=1.0, usedResources=<memory:23552, vCores:18>usedCapacity=0.47916666, absoluteUsedCapacity=0.47916666, numApps=5, numContainers=18
2013-08-11 09:31:37,337 INFO org.apache.hadoop.yarn.server.resourcemanager.scheduler.capacity.ParentQueue: assignedContainer queue=root usedCapacity=0.47916666 absoluteUsedCapacity=0.47916666 used=<memory:23552, vCores:18> cluster=<memory:49152, vCores:96>
2013-08-11 09:31:37,338 INFO org.apache.hadoop.yarn.server.resourcemanager.rmcontainer.RMContainerImpl: container_1376212503271_0007_01_000015 Container Transitioned from NEW to ALLOCATED
2013-08-11 09:31:37,338 INFO org.apache.hadoop.yarn.server.resourcemanager.RMAuditLogger: USER=ubuntu	OPERATION=AM Allocated Container	TARGET=SchedulerApp	RESULT=SUCCESS	APPID=application_1376212503271_0007	CONTAINERID=container_1376212503271_0007_01_000015
2013-08-11 09:31:37,338 INFO org.apache.hadoop.yarn.server.resourcemanager.scheduler.common.fica.FiCaSchedulerNode: Assigned container container_1376212503271_0007_01_000015 of capacity <memory:1024, vCores:1> on host hadoop-320-6:38980, which currently has 8 containers, <memory:8192, vCores:8> used and <memory:0, vCores:8> available
2013-08-11 09:31:37,339 INFO org.apache.hadoop.yarn.server.resourcemanager.scheduler.capacity.LeafQueue: assignedContainer application=application_1376212503271_0007 container=Container: [ContainerId: container_1376212503271_0007_01_000015, NodeId: hadoop-320-6:38980, NodeHttpAddress: hadoop-320-6:8042, Resource: <memory:1024, vCores:1>, Priority: 20, State: NEW, Token: null, Status: container_id {, app_attempt_id {, application_id {, id: 7, cluster_timestamp: 1376212503271, }, attemptId: 1, }, id: 15, }, state: C_NEW, ] containerId=container_1376212503271_0007_01_000015 queue=default: capacity=1.0, absoluteCapacity=1.0, usedResources=<memory:23552, vCores:18>usedCapacity=0.47916666, absoluteUsedCapacity=0.47916666, numApps=5, numContainers=18 usedCapacity=0.47916666 absoluteUsedCapacity=0.47916666 used=<memory:23552, vCores:18> cluster=<memory:49152, vCores:96>
2013-08-11 09:31:37,339 INFO org.apache.hadoop.yarn.server.resourcemanager.scheduler.capacity.ParentQueue: Re-sorting queues since queue: root.default stats: default: capacity=1.0, absoluteCapacity=1.0, usedResources=<memory:24576, vCores:19>usedCapacity=0.5, absoluteUsedCapacity=0.5, numApps=5, numContainers=19
2013-08-11 09:31:37,340 INFO org.apache.hadoop.yarn.server.resourcemanager.scheduler.capacity.ParentQueue: assignedContainer queue=root usedCapacity=0.5 absoluteUsedCapacity=0.5 used=<memory:24576, vCores:19> cluster=<memory:49152, vCores:96>
2013-08-11 09:31:37,414 INFO org.apache.hadoop.yarn.server.resourcemanager.rmcontainer.RMContainerImpl: container_1376212503271_0007_01_000016 Container Transitioned from NEW to ALLOCATED
2013-08-11 09:31:37,414 INFO org.apache.hadoop.yarn.server.resourcemanager.RMAuditLogger: USER=ubuntu	OPERATION=AM Allocated Container	TARGET=SchedulerApp	RESULT=SUCCESS	APPID=application_1376212503271_0007	CONTAINERID=container_1376212503271_0007_01_000016
2013-08-11 09:31:37,414 INFO org.apache.hadoop.yarn.server.resourcemanager.scheduler.common.fica.FiCaSchedulerNode: Assigned container container_1376212503271_0007_01_000016 of capacity <memory:1024, vCores:1> on host hadoop-320-7:48037, which currently has 2 containers, <memory:3072, vCores:2> used and <memory:5120, vCores:14> available
2013-08-11 09:31:37,416 INFO org.apache.hadoop.yarn.server.resourcemanager.scheduler.capacity.LeafQueue: assignedContainer application=application_1376212503271_0007 container=Container: [ContainerId: container_1376212503271_0007_01_000016, NodeId: hadoop-320-7:48037, NodeHttpAddress: hadoop-320-7:8042, Resource: <memory:1024, vCores:1>, Priority: 20, State: NEW, Token: null, Status: container_id {, app_attempt_id {, application_id {, id: 7, cluster_timestamp: 1376212503271, }, attemptId: 1, }, id: 16, }, state: C_NEW, ] containerId=container_1376212503271_0007_01_000016 queue=default: capacity=1.0, absoluteCapacity=1.0, usedResources=<memory:24576, vCores:19>usedCapacity=0.5, absoluteUsedCapacity=0.5, numApps=5, numContainers=19 usedCapacity=0.5 absoluteUsedCapacity=0.5 used=<memory:24576, vCores:19> cluster=<memory:49152, vCores:96>
2013-08-11 09:31:37,416 INFO org.apache.hadoop.yarn.server.resourcemanager.scheduler.capacity.ParentQueue: Re-sorting queues since queue: root.default stats: default: capacity=1.0, absoluteCapacity=1.0, usedResources=<memory:25600, vCores:20>usedCapacity=0.5208333, absoluteUsedCapacity=0.5208333, numApps=5, numContainers=20
2013-08-11 09:31:37,416 INFO org.apache.hadoop.yarn.server.resourcemanager.scheduler.capacity.ParentQueue: assignedContainer queue=root usedCapacity=0.5208333 absoluteUsedCapacity=0.5208333 used=<memory:25600, vCores:20> cluster=<memory:49152, vCores:96>
2013-08-11 09:31:37,416 INFO org.apache.hadoop.yarn.server.resourcemanager.rmcontainer.RMContainerImpl: container_1376212503271_0007_01_000017 Container Transitioned from NEW to ALLOCATED
2013-08-11 09:31:37,417 INFO org.apache.hadoop.yarn.server.resourcemanager.RMAuditLogger: USER=ubuntu	OPERATION=AM Allocated Container	TARGET=SchedulerApp	RESULT=SUCCESS	APPID=application_1376212503271_0007	CONTAINERID=container_1376212503271_0007_01_000017
2013-08-11 09:31:37,417 INFO org.apache.hadoop.yarn.server.resourcemanager.scheduler.common.fica.FiCaSchedulerNode: Assigned container container_1376212503271_0007_01_000017 of capacity <memory:1024, vCores:1> on host hadoop-320-7:48037, which currently has 3 containers, <memory:4096, vCores:3> used and <memory:4096, vCores:13> available
2013-08-11 09:31:37,418 INFO org.apache.hadoop.yarn.server.resourcemanager.scheduler.capacity.LeafQueue: assignedContainer application=application_1376212503271_0007 container=Container: [ContainerId: container_1376212503271_0007_01_000017, NodeId: hadoop-320-7:48037, NodeHttpAddress: hadoop-320-7:8042, Resource: <memory:1024, vCores:1>, Priority: 20, State: NEW, Token: null, Status: container_id {, app_attempt_id {, application_id {, id: 7, cluster_timestamp: 1376212503271, }, attemptId: 1, }, id: 17, }, state: C_NEW, ] containerId=container_1376212503271_0007_01_000017 queue=default: capacity=1.0, absoluteCapacity=1.0, usedResources=<memory:25600, vCores:20>usedCapacity=0.5208333, absoluteUsedCapacity=0.5208333, numApps=5, numContainers=20 usedCapacity=0.5208333 absoluteUsedCapacity=0.5208333 used=<memory:25600, vCores:20> cluster=<memory:49152, vCores:96>
2013-08-11 09:31:37,418 INFO org.apache.hadoop.yarn.server.resourcemanager.scheduler.capacity.ParentQueue: Re-sorting queues since queue: root.default stats: default: capacity=1.0, absoluteCapacity=1.0, usedResources=<memory:26624, vCores:21>usedCapacity=0.5416667, absoluteUsedCapacity=0.5416667, numApps=5, numContainers=21
2013-08-11 09:31:37,418 INFO org.apache.hadoop.yarn.server.resourcemanager.scheduler.capacity.ParentQueue: assignedContainer queue=root usedCapacity=0.5416667 absoluteUsedCapacity=0.5416667 used=<memory:26624, vCores:21> cluster=<memory:49152, vCores:96>
2013-08-11 09:31:37,418 INFO org.apache.hadoop.yarn.server.resourcemanager.rmcontainer.RMContainerImpl: container_1376212503271_0007_01_000018 Container Transitioned from NEW to ALLOCATED
2013-08-11 09:31:37,419 INFO org.apache.hadoop.yarn.server.resourcemanager.RMAuditLogger: USER=ubuntu	OPERATION=AM Allocated Container	TARGET=SchedulerApp	RESULT=SUCCESS	APPID=application_1376212503271_0007	CONTAINERID=container_1376212503271_0007_01_000018
2013-08-11 09:31:37,419 INFO org.apache.hadoop.yarn.server.resourcemanager.scheduler.common.fica.FiCaSchedulerNode: Assigned container container_1376212503271_0007_01_000018 of capacity <memory:1024, vCores:1> on host hadoop-320-7:48037, which currently has 4 containers, <memory:5120, vCores:4> used and <memory:3072, vCores:12> available
2013-08-11 09:31:37,420 INFO org.apache.hadoop.yarn.server.resourcemanager.scheduler.capacity.LeafQueue: assignedContainer application=application_1376212503271_0007 container=Container: [ContainerId: container_1376212503271_0007_01_000018, NodeId: hadoop-320-7:48037, NodeHttpAddress: hadoop-320-7:8042, Resource: <memory:1024, vCores:1>, Priority: 20, State: NEW, Token: null, Status: container_id {, app_attempt_id {, application_id {, id: 7, cluster_timestamp: 1376212503271, }, attemptId: 1, }, id: 18, }, state: C_NEW, ] containerId=container_1376212503271_0007_01_000018 queue=default: capacity=1.0, absoluteCapacity=1.0, usedResources=<memory:26624, vCores:21>usedCapacity=0.5416667, absoluteUsedCapacity=0.5416667, numApps=5, numContainers=21 usedCapacity=0.5416667 absoluteUsedCapacity=0.5416667 used=<memory:26624, vCores:21> cluster=<memory:49152, vCores:96>
2013-08-11 09:31:37,420 INFO org.apache.hadoop.yarn.server.resourcemanager.scheduler.capacity.ParentQueue: Re-sorting queues since queue: root.default stats: default: capacity=1.0, absoluteCapacity=1.0, usedResources=<memory:27648, vCores:22>usedCapacity=0.5625, absoluteUsedCapacity=0.5625, numApps=5, numContainers=22
2013-08-11 09:31:37,420 INFO org.apache.hadoop.yarn.server.resourcemanager.scheduler.capacity.ParentQueue: assignedContainer queue=root usedCapacity=0.5625 absoluteUsedCapacity=0.5625 used=<memory:27648, vCores:22> cluster=<memory:49152, vCores:96>
2013-08-11 09:31:37,420 INFO org.apache.hadoop.yarn.server.resourcemanager.rmcontainer.RMContainerImpl: container_1376212503271_0007_01_000019 Container Transitioned from NEW to ALLOCATED
2013-08-11 09:31:37,421 INFO org.apache.hadoop.yarn.server.resourcemanager.RMAuditLogger: USER=ubuntu	OPERATION=AM Allocated Container	TARGET=SchedulerApp	RESULT=SUCCESS	APPID=application_1376212503271_0007	CONTAINERID=container_1376212503271_0007_01_000019
2013-08-11 09:31:37,421 INFO org.apache.hadoop.yarn.server.resourcemanager.scheduler.common.fica.FiCaSchedulerNode: Assigned container container_1376212503271_0007_01_000019 of capacity <memory:1024, vCores:1> on host hadoop-320-7:48037, which currently has 5 containers, <memory:6144, vCores:5> used and <memory:2048, vCores:11> available
2013-08-11 09:31:37,422 INFO org.apache.hadoop.yarn.server.resourcemanager.scheduler.capacity.LeafQueue: assignedContainer application=application_1376212503271_0007 container=Container: [ContainerId: container_1376212503271_0007_01_000019, NodeId: hadoop-320-7:48037, NodeHttpAddress: hadoop-320-7:8042, Resource: <memory:1024, vCores:1>, Priority: 20, State: NEW, Token: null, Status: container_id {, app_attempt_id {, application_id {, id: 7, cluster_timestamp: 1376212503271, }, attemptId: 1, }, id: 19, }, state: C_NEW, ] containerId=container_1376212503271_0007_01_000019 queue=default: capacity=1.0, absoluteCapacity=1.0, usedResources=<memory:27648, vCores:22>usedCapacity=0.5625, absoluteUsedCapacity=0.5625, numApps=5, numContainers=22 usedCapacity=0.5625 absoluteUsedCapacity=0.5625 used=<memory:27648, vCores:22> cluster=<memory:49152, vCores:96>
2013-08-11 09:31:37,422 INFO org.apache.hadoop.yarn.server.resourcemanager.scheduler.capacity.ParentQueue: Re-sorting queues since queue: root.default stats: default: capacity=1.0, absoluteCapacity=1.0, usedResources=<memory:28672, vCores:23>usedCapacity=0.5833333, absoluteUsedCapacity=0.5833333, numApps=5, numContainers=23
2013-08-11 09:31:37,422 INFO org.apache.hadoop.yarn.server.resourcemanager.scheduler.capacity.ParentQueue: assignedContainer queue=root usedCapacity=0.5833333 absoluteUsedCapacity=0.5833333 used=<memory:28672, vCores:23> cluster=<memory:49152, vCores:96>
2013-08-11 09:31:37,423 INFO org.apache.hadoop.yarn.server.resourcemanager.rmcontainer.RMContainerImpl: container_1376212503271_0007_01_000020 Container Transitioned from NEW to ALLOCATED
2013-08-11 09:31:37,423 INFO org.apache.hadoop.yarn.server.resourcemanager.RMAuditLogger: USER=ubuntu	OPERATION=AM Allocated Container	TARGET=SchedulerApp	RESULT=SUCCESS	APPID=application_1376212503271_0007	CONTAINERID=container_1376212503271_0007_01_000020
2013-08-11 09:31:37,423 INFO org.apache.hadoop.yarn.server.resourcemanager.scheduler.common.fica.FiCaSchedulerNode: Assigned container container_1376212503271_0007_01_000020 of capacity <memory:1024, vCores:1> on host hadoop-320-7:48037, which currently has 6 containers, <memory:7168, vCores:6> used and <memory:1024, vCores:10> available
2013-08-11 09:31:37,424 INFO org.apache.hadoop.yarn.server.resourcemanager.scheduler.capacity.LeafQueue: assignedContainer application=application_1376212503271_0007 container=Container: [ContainerId: container_1376212503271_0007_01_000020, NodeId: hadoop-320-7:48037, NodeHttpAddress: hadoop-320-7:8042, Resource: <memory:1024, vCores:1>, Priority: 20, State: NEW, Token: null, Status: container_id {, app_attempt_id {, application_id {, id: 7, cluster_timestamp: 1376212503271, }, attemptId: 1, }, id: 20, }, state: C_NEW, ] containerId=container_1376212503271_0007_01_000020 queue=default: capacity=1.0, absoluteCapacity=1.0, usedResources=<memory:28672, vCores:23>usedCapacity=0.5833333, absoluteUsedCapacity=0.5833333, numApps=5, numContainers=23 usedCapacity=0.5833333 absoluteUsedCapacity=0.5833333 used=<memory:28672, vCores:23> cluster=<memory:49152, vCores:96>
2013-08-11 09:31:37,424 INFO org.apache.hadoop.yarn.server.resourcemanager.scheduler.capacity.ParentQueue: Re-sorting queues since queue: root.default stats: default: capacity=1.0, absoluteCapacity=1.0, usedResources=<memory:29696, vCores:24>usedCapacity=0.6041667, absoluteUsedCapacity=0.6041667, numApps=5, numContainers=24
2013-08-11 09:31:37,424 INFO org.apache.hadoop.yarn.server.resourcemanager.scheduler.capacity.ParentQueue: assignedContainer queue=root usedCapacity=0.6041667 absoluteUsedCapacity=0.6041667 used=<memory:29696, vCores:24> cluster=<memory:49152, vCores:96>
2013-08-11 09:31:37,425 INFO org.apache.hadoop.yarn.server.resourcemanager.rmcontainer.RMContainerImpl: container_1376212503271_0007_01_000021 Container Transitioned from NEW to ALLOCATED
2013-08-11 09:31:37,425 INFO org.apache.hadoop.yarn.server.resourcemanager.RMAuditLogger: USER=ubuntu	OPERATION=AM Allocated Container	TARGET=SchedulerApp	RESULT=SUCCESS	APPID=application_1376212503271_0007	CONTAINERID=container_1376212503271_0007_01_000021
2013-08-11 09:31:37,425 INFO org.apache.hadoop.yarn.server.resourcemanager.scheduler.common.fica.FiCaSchedulerNode: Assigned container container_1376212503271_0007_01_000021 of capacity <memory:1024, vCores:1> on host hadoop-320-7:48037, which currently has 7 containers, <memory:8192, vCores:7> used and <memory:0, vCores:9> available
2013-08-11 09:31:37,426 INFO org.apache.hadoop.yarn.server.resourcemanager.scheduler.capacity.LeafQueue: assignedContainer application=application_1376212503271_0007 container=Container: [ContainerId: container_1376212503271_0007_01_000021, NodeId: hadoop-320-7:48037, NodeHttpAddress: hadoop-320-7:8042, Resource: <memory:1024, vCores:1>, Priority: 20, State: NEW, Token: null, Status: container_id {, app_attempt_id {, application_id {, id: 7, cluster_timestamp: 1376212503271, }, attemptId: 1, }, id: 21, }, state: C_NEW, ] containerId=container_1376212503271_0007_01_000021 queue=default: capacity=1.0, absoluteCapacity=1.0, usedResources=<memory:29696, vCores:24>usedCapacity=0.6041667, absoluteUsedCapacity=0.6041667, numApps=5, numContainers=24 usedCapacity=0.6041667 absoluteUsedCapacity=0.6041667 used=<memory:29696, vCores:24> cluster=<memory:49152, vCores:96>
2013-08-11 09:31:37,426 INFO org.apache.hadoop.yarn.server.resourcemanager.scheduler.capacity.ParentQueue: Re-sorting queues since queue: root.default stats: default: capacity=1.0, absoluteCapacity=1.0, usedResources=<memory:30720, vCores:25>usedCapacity=0.625, absoluteUsedCapacity=0.625, numApps=5, numContainers=25
2013-08-11 09:31:37,426 INFO org.apache.hadoop.yarn.server.resourcemanager.scheduler.capacity.ParentQueue: assignedContainer queue=root usedCapacity=0.625 absoluteUsedCapacity=0.625 used=<memory:30720, vCores:25> cluster=<memory:49152, vCores:96>
2013-08-11 09:31:37,558 INFO org.apache.hadoop.yarn.server.resourcemanager.rmcontainer.RMContainerImpl: container_1376212503271_0007_01_000022 Container Transitioned from NEW to ALLOCATED
2013-08-11 09:31:37,558 INFO org.apache.hadoop.yarn.server.resourcemanager.RMAuditLogger: USER=ubuntu	OPERATION=AM Allocated Container	TARGET=SchedulerApp	RESULT=SUCCESS	APPID=application_1376212503271_0007	CONTAINERID=container_1376212503271_0007_01_000022
2013-08-11 09:31:37,559 INFO org.apache.hadoop.yarn.server.resourcemanager.scheduler.common.fica.FiCaSchedulerNode: Assigned container container_1376212503271_0007_01_000022 of capacity <memory:1024, vCores:1> on host hadoop-320-2:53179, which currently has 2 containers, <memory:3072, vCores:2> used and <memory:5120, vCores:14> available
2013-08-11 09:31:37,560 INFO org.apache.hadoop.yarn.server.resourcemanager.scheduler.capacity.LeafQueue: assignedContainer application=application_1376212503271_0007 container=Container: [ContainerId: container_1376212503271_0007_01_000022, NodeId: hadoop-320-2:53179, NodeHttpAddress: hadoop-320-2:8042, Resource: <memory:1024, vCores:1>, Priority: 20, State: NEW, Token: null, Status: container_id {, app_attempt_id {, application_id {, id: 7, cluster_timestamp: 1376212503271, }, attemptId: 1, }, id: 22, }, state: C_NEW, ] containerId=container_1376212503271_0007_01_000022 queue=default: capacity=1.0, absoluteCapacity=1.0, usedResources=<memory:30720, vCores:25>usedCapacity=0.625, absoluteUsedCapacity=0.625, numApps=5, numContainers=25 usedCapacity=0.625 absoluteUsedCapacity=0.625 used=<memory:30720, vCores:25> cluster=<memory:49152, vCores:96>
2013-08-11 09:31:37,560 INFO org.apache.hadoop.yarn.server.resourcemanager.scheduler.capacity.ParentQueue: Re-sorting queues since queue: root.default stats: default: capacity=1.0, absoluteCapacity=1.0, usedResources=<memory:31744, vCores:26>usedCapacity=0.6458333, absoluteUsedCapacity=0.6458333, numApps=5, numContainers=26
2013-08-11 09:31:37,560 INFO org.apache.hadoop.yarn.server.resourcemanager.scheduler.capacity.ParentQueue: assignedContainer queue=root usedCapacity=0.6458333 absoluteUsedCapacity=0.6458333 used=<memory:31744, vCores:26> cluster=<memory:49152, vCores:96>
2013-08-11 09:31:37,561 INFO org.apache.hadoop.yarn.server.resourcemanager.rmcontainer.RMContainerImpl: container_1376212503271_0007_01_000023 Container Transitioned from NEW to ALLOCATED
2013-08-11 09:31:37,561 INFO org.apache.hadoop.yarn.server.resourcemanager.RMAuditLogger: USER=ubuntu	OPERATION=AM Allocated Container	TARGET=SchedulerApp	RESULT=SUCCESS	APPID=application_1376212503271_0007	CONTAINERID=container_1376212503271_0007_01_000023
2013-08-11 09:31:37,561 INFO org.apache.hadoop.yarn.server.resourcemanager.scheduler.common.fica.FiCaSchedulerNode: Assigned container container_1376212503271_0007_01_000023 of capacity <memory:1024, vCores:1> on host hadoop-320-2:53179, which currently has 3 containers, <memory:4096, vCores:3> used and <memory:4096, vCores:13> available
2013-08-11 09:31:37,562 INFO org.apache.hadoop.yarn.server.resourcemanager.scheduler.capacity.LeafQueue: assignedContainer application=application_1376212503271_0007 container=Container: [ContainerId: container_1376212503271_0007_01_000023, NodeId: hadoop-320-2:53179, NodeHttpAddress: hadoop-320-2:8042, Resource: <memory:1024, vCores:1>, Priority: 20, State: NEW, Token: null, Status: container_id {, app_attempt_id {, application_id {, id: 7, cluster_timestamp: 1376212503271, }, attemptId: 1, }, id: 23, }, state: C_NEW, ] containerId=container_1376212503271_0007_01_000023 queue=default: capacity=1.0, absoluteCapacity=1.0, usedResources=<memory:31744, vCores:26>usedCapacity=0.6458333, absoluteUsedCapacity=0.6458333, numApps=5, numContainers=26 usedCapacity=0.6458333 absoluteUsedCapacity=0.6458333 used=<memory:31744, vCores:26> cluster=<memory:49152, vCores:96>
2013-08-11 09:31:37,562 INFO org.apache.hadoop.yarn.server.resourcemanager.scheduler.capacity.ParentQueue: Re-sorting queues since queue: root.default stats: default: capacity=1.0, absoluteCapacity=1.0, usedResources=<memory:32768, vCores:27>usedCapacity=0.6666667, absoluteUsedCapacity=0.6666667, numApps=5, numContainers=27
2013-08-11 09:31:37,562 INFO org.apache.hadoop.yarn.server.resourcemanager.scheduler.capacity.ParentQueue: assignedContainer queue=root usedCapacity=0.6666667 absoluteUsedCapacity=0.6666667 used=<memory:32768, vCores:27> cluster=<memory:49152, vCores:96>
2013-08-11 09:31:37,563 INFO org.apache.hadoop.yarn.server.resourcemanager.rmcontainer.RMContainerImpl: container_1376212503271_0007_01_000024 Container Transitioned from NEW to ALLOCATED
2013-08-11 09:31:37,563 INFO org.apache.hadoop.yarn.server.resourcemanager.RMAuditLogger: USER=ubuntu	OPERATION=AM Allocated Container	TARGET=SchedulerApp	RESULT=SUCCESS	APPID=application_1376212503271_0007	CONTAINERID=container_1376212503271_0007_01_000024
2013-08-11 09:31:37,563 INFO org.apache.hadoop.yarn.server.resourcemanager.scheduler.common.fica.FiCaSchedulerNode: Assigned container container_1376212503271_0007_01_000024 of capacity <memory:1024, vCores:1> on host hadoop-320-2:53179, which currently has 4 containers, <memory:5120, vCores:4> used and <memory:3072, vCores:12> available
2013-08-11 09:31:37,564 INFO org.apache.hadoop.yarn.server.resourcemanager.scheduler.capacity.LeafQueue: assignedContainer application=application_1376212503271_0007 container=Container: [ContainerId: container_1376212503271_0007_01_000024, NodeId: hadoop-320-2:53179, NodeHttpAddress: hadoop-320-2:8042, Resource: <memory:1024, vCores:1>, Priority: 20, State: NEW, Token: null, Status: container_id {, app_attempt_id {, application_id {, id: 7, cluster_timestamp: 1376212503271, }, attemptId: 1, }, id: 24, }, state: C_NEW, ] containerId=container_1376212503271_0007_01_000024 queue=default: capacity=1.0, absoluteCapacity=1.0, usedResources=<memory:32768, vCores:27>usedCapacity=0.6666667, absoluteUsedCapacity=0.6666667, numApps=5, numContainers=27 usedCapacity=0.6666667 absoluteUsedCapacity=0.6666667 used=<memory:32768, vCores:27> cluster=<memory:49152, vCores:96>
2013-08-11 09:31:37,564 INFO org.apache.hadoop.yarn.server.resourcemanager.scheduler.capacity.ParentQueue: Re-sorting queues since queue: root.default stats: default: capacity=1.0, absoluteCapacity=1.0, usedResources=<memory:33792, vCores:28>usedCapacity=0.6875, absoluteUsedCapacity=0.6875, numApps=5, numContainers=28
2013-08-11 09:31:37,564 INFO org.apache.hadoop.yarn.server.resourcemanager.scheduler.capacity.ParentQueue: assignedContainer queue=root usedCapacity=0.6875 absoluteUsedCapacity=0.6875 used=<memory:33792, vCores:28> cluster=<memory:49152, vCores:96>
2013-08-11 09:31:37,565 INFO org.apache.hadoop.yarn.server.resourcemanager.rmcontainer.RMContainerImpl: container_1376212503271_0007_01_000025 Container Transitioned from NEW to ALLOCATED
2013-08-11 09:31:37,565 INFO org.apache.hadoop.yarn.server.resourcemanager.RMAuditLogger: USER=ubuntu	OPERATION=AM Allocated Container	TARGET=SchedulerApp	RESULT=SUCCESS	APPID=application_1376212503271_0007	CONTAINERID=container_1376212503271_0007_01_000025
2013-08-11 09:31:37,565 INFO org.apache.hadoop.yarn.server.resourcemanager.scheduler.common.fica.FiCaSchedulerNode: Assigned container container_1376212503271_0007_01_000025 of capacity <memory:1024, vCores:1> on host hadoop-320-2:53179, which currently has 5 containers, <memory:6144, vCores:5> used and <memory:2048, vCores:11> available
2013-08-11 09:31:37,566 INFO org.apache.hadoop.yarn.server.resourcemanager.scheduler.capacity.LeafQueue: assignedContainer application=application_1376212503271_0007 container=Container: [ContainerId: container_1376212503271_0007_01_000025, NodeId: hadoop-320-2:53179, NodeHttpAddress: hadoop-320-2:8042, Resource: <memory:1024, vCores:1>, Priority: 20, State: NEW, Token: null, Status: container_id {, app_attempt_id {, application_id {, id: 7, cluster_timestamp: 1376212503271, }, attemptId: 1, }, id: 25, }, state: C_NEW, ] containerId=container_1376212503271_0007_01_000025 queue=default: capacity=1.0, absoluteCapacity=1.0, usedResources=<memory:33792, vCores:28>usedCapacity=0.6875, absoluteUsedCapacity=0.6875, numApps=5, numContainers=28 usedCapacity=0.6875 absoluteUsedCapacity=0.6875 used=<memory:33792, vCores:28> cluster=<memory:49152, vCores:96>
2013-08-11 09:31:37,566 INFO org.apache.hadoop.yarn.server.resourcemanager.scheduler.capacity.ParentQueue: Re-sorting queues since queue: root.default stats: default: capacity=1.0, absoluteCapacity=1.0, usedResources=<memory:34816, vCores:29>usedCapacity=0.7083333, absoluteUsedCapacity=0.7083333, numApps=5, numContainers=29
2013-08-11 09:31:37,566 INFO org.apache.hadoop.yarn.server.resourcemanager.scheduler.capacity.ParentQueue: assignedContainer queue=root usedCapacity=0.7083333 absoluteUsedCapacity=0.7083333 used=<memory:34816, vCores:29> cluster=<memory:49152, vCores:96>
2013-08-11 09:31:37,566 INFO org.apache.hadoop.yarn.server.resourcemanager.rmcontainer.RMContainerImpl: container_1376212503271_0007_01_000026 Container Transitioned from NEW to ALLOCATED
2013-08-11 09:31:37,567 INFO org.apache.hadoop.yarn.server.resourcemanager.RMAuditLogger: USER=ubuntu	OPERATION=AM Allocated Container	TARGET=SchedulerApp	RESULT=SUCCESS	APPID=application_1376212503271_0007	CONTAINERID=container_1376212503271_0007_01_000026
2013-08-11 09:31:37,567 INFO org.apache.hadoop.yarn.server.resourcemanager.scheduler.common.fica.FiCaSchedulerNode: Assigned container container_1376212503271_0007_01_000026 of capacity <memory:1024, vCores:1> on host hadoop-320-2:53179, which currently has 6 containers, <memory:7168, vCores:6> used and <memory:1024, vCores:10> available
2013-08-11 09:31:37,568 INFO org.apache.hadoop.yarn.server.resourcemanager.scheduler.capacity.LeafQueue: assignedContainer application=application_1376212503271_0007 container=Container: [ContainerId: container_1376212503271_0007_01_000026, NodeId: hadoop-320-2:53179, NodeHttpAddress: hadoop-320-2:8042, Resource: <memory:1024, vCores:1>, Priority: 20, State: NEW, Token: null, Status: container_id {, app_attempt_id {, application_id {, id: 7, cluster_timestamp: 1376212503271, }, attemptId: 1, }, id: 26, }, state: C_NEW, ] containerId=container_1376212503271_0007_01_000026 queue=default: capacity=1.0, absoluteCapacity=1.0, usedResources=<memory:34816, vCores:29>usedCapacity=0.7083333, absoluteUsedCapacity=0.7083333, numApps=5, numContainers=29 usedCapacity=0.7083333 absoluteUsedCapacity=0.7083333 used=<memory:34816, vCores:29> cluster=<memory:49152, vCores:96>
2013-08-11 09:31:37,568 INFO org.apache.hadoop.yarn.server.resourcemanager.scheduler.capacity.ParentQueue: Re-sorting queues since queue: root.default stats: default: capacity=1.0, absoluteCapacity=1.0, usedResources=<memory:35840, vCores:30>usedCapacity=0.7291667, absoluteUsedCapacity=0.7291667, numApps=5, numContainers=30
2013-08-11 09:31:37,568 INFO org.apache.hadoop.yarn.server.resourcemanager.scheduler.capacity.ParentQueue: assignedContainer queue=root usedCapacity=0.7291667 absoluteUsedCapacity=0.7291667 used=<memory:35840, vCores:30> cluster=<memory:49152, vCores:96>
2013-08-11 09:31:37,568 INFO org.apache.hadoop.yarn.server.resourcemanager.rmcontainer.RMContainerImpl: container_1376212503271_0007_01_000027 Container Transitioned from NEW to ALLOCATED
2013-08-11 09:31:37,569 INFO org.apache.hadoop.yarn.server.resourcemanager.RMAuditLogger: USER=ubuntu	OPERATION=AM Allocated Container	TARGET=SchedulerApp	RESULT=SUCCESS	APPID=application_1376212503271_0007	CONTAINERID=container_1376212503271_0007_01_000027
2013-08-11 09:31:37,569 INFO org.apache.hadoop.yarn.server.resourcemanager.scheduler.common.fica.FiCaSchedulerNode: Assigned container container_1376212503271_0007_01_000027 of capacity <memory:1024, vCores:1> on host hadoop-320-2:53179, which currently has 7 containers, <memory:8192, vCores:7> used and <memory:0, vCores:9> available
2013-08-11 09:31:37,570 INFO org.apache.hadoop.yarn.server.resourcemanager.scheduler.capacity.LeafQueue: assignedContainer application=application_1376212503271_0007 container=Container: [ContainerId: container_1376212503271_0007_01_000027, NodeId: hadoop-320-2:53179, NodeHttpAddress: hadoop-320-2:8042, Resource: <memory:1024, vCores:1>, Priority: 20, State: NEW, Token: null, Status: container_id {, app_attempt_id {, application_id {, id: 7, cluster_timestamp: 1376212503271, }, attemptId: 1, }, id: 27, }, state: C_NEW, ] containerId=container_1376212503271_0007_01_000027 queue=default: capacity=1.0, absoluteCapacity=1.0, usedResources=<memory:35840, vCores:30>usedCapacity=0.7291667, absoluteUsedCapacity=0.7291667, numApps=5, numContainers=30 usedCapacity=0.7291667 absoluteUsedCapacity=0.7291667 used=<memory:35840, vCores:30> cluster=<memory:49152, vCores:96>
2013-08-11 09:31:37,570 INFO org.apache.hadoop.yarn.server.resourcemanager.scheduler.capacity.ParentQueue: Re-sorting queues since queue: root.default stats: default: capacity=1.0, absoluteCapacity=1.0, usedResources=<memory:36864, vCores:31>usedCapacity=0.75, absoluteUsedCapacity=0.75, numApps=5, numContainers=31
2013-08-11 09:31:37,570 INFO org.apache.hadoop.yarn.server.resourcemanager.scheduler.capacity.ParentQueue: assignedContainer queue=root usedCapacity=0.75 absoluteUsedCapacity=0.75 used=<memory:36864, vCores:31> cluster=<memory:49152, vCores:96>
2013-08-11 09:31:37,763 INFO org.apache.hadoop.yarn.server.resourcemanager.rmcontainer.RMContainerImpl: container_1376212503271_0007_01_000028 Container Transitioned from NEW to ALLOCATED
2013-08-11 09:31:37,763 INFO org.apache.hadoop.yarn.server.resourcemanager.RMAuditLogger: USER=ubuntu	OPERATION=AM Allocated Container	TARGET=SchedulerApp	RESULT=SUCCESS	APPID=application_1376212503271_0007	CONTAINERID=container_1376212503271_0007_01_000028
2013-08-11 09:31:37,763 INFO org.apache.hadoop.yarn.server.resourcemanager.scheduler.common.fica.FiCaSchedulerNode: Assigned container container_1376212503271_0007_01_000028 of capacity <memory:1024, vCores:1> on host hadoop-320-4:39920, which currently has 2 containers, <memory:3072, vCores:2> used and <memory:5120, vCores:14> available
2013-08-11 09:31:37,764 INFO org.apache.hadoop.yarn.server.resourcemanager.scheduler.capacity.LeafQueue: assignedContainer application=application_1376212503271_0007 container=Container: [ContainerId: container_1376212503271_0007_01_000028, NodeId: hadoop-320-4:39920, NodeHttpAddress: hadoop-320-4:8042, Resource: <memory:1024, vCores:1>, Priority: 20, State: NEW, Token: null, Status: container_id {, app_attempt_id {, application_id {, id: 7, cluster_timestamp: 1376212503271, }, attemptId: 1, }, id: 28, }, state: C_NEW, ] containerId=container_1376212503271_0007_01_000028 queue=default: capacity=1.0, absoluteCapacity=1.0, usedResources=<memory:36864, vCores:31>usedCapacity=0.75, absoluteUsedCapacity=0.75, numApps=5, numContainers=31 usedCapacity=0.75 absoluteUsedCapacity=0.75 used=<memory:36864, vCores:31> cluster=<memory:49152, vCores:96>
2013-08-11 09:31:37,764 INFO org.apache.hadoop.yarn.server.resourcemanager.scheduler.capacity.ParentQueue: Re-sorting queues since queue: root.default stats: default: capacity=1.0, absoluteCapacity=1.0, usedResources=<memory:37888, vCores:32>usedCapacity=0.7708333, absoluteUsedCapacity=0.7708333, numApps=5, numContainers=32
2013-08-11 09:31:37,764 INFO org.apache.hadoop.yarn.server.resourcemanager.scheduler.capacity.ParentQueue: assignedContainer queue=root usedCapacity=0.7708333 absoluteUsedCapacity=0.7708333 used=<memory:37888, vCores:32> cluster=<memory:49152, vCores:96>
2013-08-11 09:31:37,765 INFO org.apache.hadoop.yarn.server.resourcemanager.rmcontainer.RMContainerImpl: container_1376212503271_0007_01_000029 Container Transitioned from NEW to ALLOCATED
2013-08-11 09:31:37,765 INFO org.apache.hadoop.yarn.server.resourcemanager.RMAuditLogger: USER=ubuntu	OPERATION=AM Allocated Container	TARGET=SchedulerApp	RESULT=SUCCESS	APPID=application_1376212503271_0007	CONTAINERID=container_1376212503271_0007_01_000029
2013-08-11 09:31:37,765 INFO org.apache.hadoop.yarn.server.resourcemanager.scheduler.common.fica.FiCaSchedulerNode: Assigned container container_1376212503271_0007_01_000029 of capacity <memory:1024, vCores:1> on host hadoop-320-4:39920, which currently has 3 containers, <memory:4096, vCores:3> used and <memory:4096, vCores:13> available
2013-08-11 09:31:37,766 INFO org.apache.hadoop.yarn.server.resourcemanager.scheduler.capacity.LeafQueue: assignedContainer application=application_1376212503271_0007 container=Container: [ContainerId: container_1376212503271_0007_01_000029, NodeId: hadoop-320-4:39920, NodeHttpAddress: hadoop-320-4:8042, Resource: <memory:1024, vCores:1>, Priority: 20, State: NEW, Token: null, Status: container_id {, app_attempt_id {, application_id {, id: 7, cluster_timestamp: 1376212503271, }, attemptId: 1, }, id: 29, }, state: C_NEW, ] containerId=container_1376212503271_0007_01_000029 queue=default: capacity=1.0, absoluteCapacity=1.0, usedResources=<memory:37888, vCores:32>usedCapacity=0.7708333, absoluteUsedCapacity=0.7708333, numApps=5, numContainers=32 usedCapacity=0.7708333 absoluteUsedCapacity=0.7708333 used=<memory:37888, vCores:32> cluster=<memory:49152, vCores:96>
2013-08-11 09:31:37,766 INFO org.apache.hadoop.yarn.server.resourcemanager.scheduler.capacity.ParentQueue: Re-sorting queues since queue: root.default stats: default: capacity=1.0, absoluteCapacity=1.0, usedResources=<memory:38912, vCores:33>usedCapacity=0.7916667, absoluteUsedCapacity=0.7916667, numApps=5, numContainers=33
2013-08-11 09:31:37,766 INFO org.apache.hadoop.yarn.server.resourcemanager.scheduler.capacity.ParentQueue: assignedContainer queue=root usedCapacity=0.7916667 absoluteUsedCapacity=0.7916667 used=<memory:38912, vCores:33> cluster=<memory:49152, vCores:96>
2013-08-11 09:31:37,767 INFO org.apache.hadoop.yarn.server.resourcemanager.rmcontainer.RMContainerImpl: container_1376212503271_0007_01_000030 Container Transitioned from NEW to ALLOCATED
2013-08-11 09:31:37,767 INFO org.apache.hadoop.yarn.server.resourcemanager.RMAuditLogger: USER=ubuntu	OPERATION=AM Allocated Container	TARGET=SchedulerApp	RESULT=SUCCESS	APPID=application_1376212503271_0007	CONTAINERID=container_1376212503271_0007_01_000030
2013-08-11 09:31:37,767 INFO org.apache.hadoop.yarn.server.resourcemanager.scheduler.common.fica.FiCaSchedulerNode: Assigned container container_1376212503271_0007_01_000030 of capacity <memory:1024, vCores:1> on host hadoop-320-4:39920, which currently has 4 containers, <memory:5120, vCores:4> used and <memory:3072, vCores:12> available
2013-08-11 09:31:37,768 INFO org.apache.hadoop.yarn.server.resourcemanager.scheduler.capacity.LeafQueue: assignedContainer application=application_1376212503271_0007 container=Container: [ContainerId: container_1376212503271_0007_01_000030, NodeId: hadoop-320-4:39920, NodeHttpAddress: hadoop-320-4:8042, Resource: <memory:1024, vCores:1>, Priority: 20, State: NEW, Token: null, Status: container_id {, app_attempt_id {, application_id {, id: 7, cluster_timestamp: 1376212503271, }, attemptId: 1, }, id: 30, }, state: C_NEW, ] containerId=container_1376212503271_0007_01_000030 queue=default: capacity=1.0, absoluteCapacity=1.0, usedResources=<memory:38912, vCores:33>usedCapacity=0.7916667, absoluteUsedCapacity=0.7916667, numApps=5, numContainers=33 usedCapacity=0.7916667 absoluteUsedCapacity=0.7916667 used=<memory:38912, vCores:33> cluster=<memory:49152, vCores:96>
2013-08-11 09:31:37,768 INFO org.apache.hadoop.yarn.server.resourcemanager.scheduler.capacity.ParentQueue: Re-sorting queues since queue: root.default stats: default: capacity=1.0, absoluteCapacity=1.0, usedResources=<memory:39936, vCores:34>usedCapacity=0.8125, absoluteUsedCapacity=0.8125, numApps=5, numContainers=34
2013-08-11 09:31:37,768 INFO org.apache.hadoop.yarn.server.resourcemanager.scheduler.capacity.ParentQueue: assignedContainer queue=root usedCapacity=0.8125 absoluteUsedCapacity=0.8125 used=<memory:39936, vCores:34> cluster=<memory:49152, vCores:96>
2013-08-11 09:31:37,769 INFO org.apache.hadoop.yarn.server.resourcemanager.rmcontainer.RMContainerImpl: container_1376212503271_0007_01_000031 Container Transitioned from NEW to ALLOCATED
2013-08-11 09:31:37,769 INFO org.apache.hadoop.yarn.server.resourcemanager.RMAuditLogger: USER=ubuntu	OPERATION=AM Allocated Container	TARGET=SchedulerApp	RESULT=SUCCESS	APPID=application_1376212503271_0007	CONTAINERID=container_1376212503271_0007_01_000031
2013-08-11 09:31:37,769 INFO org.apache.hadoop.yarn.server.resourcemanager.scheduler.common.fica.FiCaSchedulerNode: Assigned container container_1376212503271_0007_01_000031 of capacity <memory:1024, vCores:1> on host hadoop-320-4:39920, which currently has 5 containers, <memory:6144, vCores:5> used and <memory:2048, vCores:11> available
2013-08-11 09:31:37,770 INFO org.apache.hadoop.yarn.server.resourcemanager.scheduler.capacity.LeafQueue: assignedContainer application=application_1376212503271_0007 container=Container: [ContainerId: container_1376212503271_0007_01_000031, NodeId: hadoop-320-4:39920, NodeHttpAddress: hadoop-320-4:8042, Resource: <memory:1024, vCores:1>, Priority: 20, State: NEW, Token: null, Status: container_id {, app_attempt_id {, application_id {, id: 7, cluster_timestamp: 1376212503271, }, attemptId: 1, }, id: 31, }, state: C_NEW, ] containerId=container_1376212503271_0007_01_000031 queue=default: capacity=1.0, absoluteCapacity=1.0, usedResources=<memory:39936, vCores:34>usedCapacity=0.8125, absoluteUsedCapacity=0.8125, numApps=5, numContainers=34 usedCapacity=0.8125 absoluteUsedCapacity=0.8125 used=<memory:39936, vCores:34> cluster=<memory:49152, vCores:96>
2013-08-11 09:31:37,770 INFO org.apache.hadoop.yarn.server.resourcemanager.scheduler.capacity.ParentQueue: Re-sorting queues since queue: root.default stats: default: capacity=1.0, absoluteCapacity=1.0, usedResources=<memory:40960, vCores:35>usedCapacity=0.8333333, absoluteUsedCapacity=0.8333333, numApps=5, numContainers=35
2013-08-11 09:31:37,770 INFO org.apache.hadoop.yarn.server.resourcemanager.scheduler.capacity.ParentQueue: assignedContainer queue=root usedCapacity=0.8333333 absoluteUsedCapacity=0.8333333 used=<memory:40960, vCores:35> cluster=<memory:49152, vCores:96>
2013-08-11 09:31:37,771 INFO org.apache.hadoop.yarn.server.resourcemanager.rmcontainer.RMContainerImpl: container_1376212503271_0007_01_000032 Container Transitioned from NEW to ALLOCATED
2013-08-11 09:31:37,771 INFO org.apache.hadoop.yarn.server.resourcemanager.RMAuditLogger: USER=ubuntu	OPERATION=AM Allocated Container	TARGET=SchedulerApp	RESULT=SUCCESS	APPID=application_1376212503271_0007	CONTAINERID=container_1376212503271_0007_01_000032
2013-08-11 09:31:37,771 INFO org.apache.hadoop.yarn.server.resourcemanager.scheduler.common.fica.FiCaSchedulerNode: Assigned container container_1376212503271_0007_01_000032 of capacity <memory:1024, vCores:1> on host hadoop-320-4:39920, which currently has 6 containers, <memory:7168, vCores:6> used and <memory:1024, vCores:10> available
2013-08-11 09:31:37,772 INFO org.apache.hadoop.yarn.server.resourcemanager.scheduler.capacity.LeafQueue: assignedContainer application=application_1376212503271_0007 container=Container: [ContainerId: container_1376212503271_0007_01_000032, NodeId: hadoop-320-4:39920, NodeHttpAddress: hadoop-320-4:8042, Resource: <memory:1024, vCores:1>, Priority: 20, State: NEW, Token: null, Status: container_id {, app_attempt_id {, application_id {, id: 7, cluster_timestamp: 1376212503271, }, attemptId: 1, }, id: 32, }, state: C_NEW, ] containerId=container_1376212503271_0007_01_000032 queue=default: capacity=1.0, absoluteCapacity=1.0, usedResources=<memory:40960, vCores:35>usedCapacity=0.8333333, absoluteUsedCapacity=0.8333333, numApps=5, numContainers=35 usedCapacity=0.8333333 absoluteUsedCapacity=0.8333333 used=<memory:40960, vCores:35> cluster=<memory:49152, vCores:96>
2013-08-11 09:31:37,772 INFO org.apache.hadoop.yarn.server.resourcemanager.scheduler.capacity.ParentQueue: Re-sorting queues since queue: root.default stats: default: capacity=1.0, absoluteCapacity=1.0, usedResources=<memory:41984, vCores:36>usedCapacity=0.8541667, absoluteUsedCapacity=0.8541667, numApps=5, numContainers=36
2013-08-11 09:31:37,772 INFO org.apache.hadoop.yarn.server.resourcemanager.scheduler.capacity.ParentQueue: assignedContainer queue=root usedCapacity=0.8541667 absoluteUsedCapacity=0.8541667 used=<memory:41984, vCores:36> cluster=<memory:49152, vCores:96>
2013-08-11 09:31:37,773 INFO org.apache.hadoop.yarn.server.resourcemanager.rmcontainer.RMContainerImpl: container_1376212503271_0007_01_000033 Container Transitioned from NEW to ALLOCATED
2013-08-11 09:31:37,773 INFO org.apache.hadoop.yarn.server.resourcemanager.RMAuditLogger: USER=ubuntu	OPERATION=AM Allocated Container	TARGET=SchedulerApp	RESULT=SUCCESS	APPID=application_1376212503271_0007	CONTAINERID=container_1376212503271_0007_01_000033
2013-08-11 09:31:37,773 INFO org.apache.hadoop.yarn.server.resourcemanager.scheduler.common.fica.FiCaSchedulerNode: Assigned container container_1376212503271_0007_01_000033 of capacity <memory:1024, vCores:1> on host hadoop-320-4:39920, which currently has 7 containers, <memory:8192, vCores:7> used and <memory:0, vCores:9> available
2013-08-11 09:31:37,774 INFO org.apache.hadoop.yarn.server.resourcemanager.scheduler.capacity.LeafQueue: assignedContainer application=application_1376212503271_0007 container=Container: [ContainerId: container_1376212503271_0007_01_000033, NodeId: hadoop-320-4:39920, NodeHttpAddress: hadoop-320-4:8042, Resource: <memory:1024, vCores:1>, Priority: 20, State: NEW, Token: null, Status: container_id {, app_attempt_id {, application_id {, id: 7, cluster_timestamp: 1376212503271, }, attemptId: 1, }, id: 33, }, state: C_NEW, ] containerId=container_1376212503271_0007_01_000033 queue=default: capacity=1.0, absoluteCapacity=1.0, usedResources=<memory:41984, vCores:36>usedCapacity=0.8541667, absoluteUsedCapacity=0.8541667, numApps=5, numContainers=36 usedCapacity=0.8541667 absoluteUsedCapacity=0.8541667 used=<memory:41984, vCores:36> cluster=<memory:49152, vCores:96>
2013-08-11 09:31:37,774 INFO org.apache.hadoop.yarn.server.resourcemanager.scheduler.capacity.ParentQueue: Re-sorting queues since queue: root.default stats: default: capacity=1.0, absoluteCapacity=1.0, usedResources=<memory:43008, vCores:37>usedCapacity=0.875, absoluteUsedCapacity=0.875, numApps=5, numContainers=37
2013-08-11 09:31:37,774 INFO org.apache.hadoop.yarn.server.resourcemanager.scheduler.capacity.ParentQueue: assignedContainer queue=root usedCapacity=0.875 absoluteUsedCapacity=0.875 used=<memory:43008, vCores:37> cluster=<memory:49152, vCores:96>
2013-08-11 09:31:37,780 INFO org.apache.hadoop.yarn.server.resourcemanager.rmcontainer.RMContainerImpl: container_1376212503271_0007_01_000034 Container Transitioned from NEW to ALLOCATED
2013-08-11 09:31:37,781 INFO org.apache.hadoop.yarn.server.resourcemanager.RMAuditLogger: USER=ubuntu	OPERATION=AM Allocated Container	TARGET=SchedulerApp	RESULT=SUCCESS	APPID=application_1376212503271_0007	CONTAINERID=container_1376212503271_0007_01_000034
2013-08-11 09:31:37,781 INFO org.apache.hadoop.yarn.server.resourcemanager.scheduler.common.fica.FiCaSchedulerNode: Assigned container container_1376212503271_0007_01_000034 of capacity <memory:1024, vCores:1> on host hadoop-320-5:36272, which currently has 2 containers, <memory:3072, vCores:2> used and <memory:5120, vCores:14> available
2013-08-11 09:31:37,782 INFO org.apache.hadoop.yarn.server.resourcemanager.scheduler.capacity.LeafQueue: assignedContainer application=application_1376212503271_0007 container=Container: [ContainerId: container_1376212503271_0007_01_000034, NodeId: hadoop-320-5:36272, NodeHttpAddress: hadoop-320-5:8042, Resource: <memory:1024, vCores:1>, Priority: 20, State: NEW, Token: null, Status: container_id {, app_attempt_id {, application_id {, id: 7, cluster_timestamp: 1376212503271, }, attemptId: 1, }, id: 34, }, state: C_NEW, ] containerId=container_1376212503271_0007_01_000034 queue=default: capacity=1.0, absoluteCapacity=1.0, usedResources=<memory:43008, vCores:37>usedCapacity=0.875, absoluteUsedCapacity=0.875, numApps=5, numContainers=37 usedCapacity=0.875 absoluteUsedCapacity=0.875 used=<memory:43008, vCores:37> cluster=<memory:49152, vCores:96>
2013-08-11 09:31:37,782 INFO org.apache.hadoop.yarn.server.resourcemanager.scheduler.capacity.ParentQueue: Re-sorting queues since queue: root.default stats: default: capacity=1.0, absoluteCapacity=1.0, usedResources=<memory:44032, vCores:38>usedCapacity=0.8958333, absoluteUsedCapacity=0.8958333, numApps=5, numContainers=38
2013-08-11 09:31:37,782 INFO org.apache.hadoop.yarn.server.resourcemanager.scheduler.capacity.ParentQueue: assignedContainer queue=root usedCapacity=0.8958333 absoluteUsedCapacity=0.8958333 used=<memory:44032, vCores:38> cluster=<memory:49152, vCores:96>
2013-08-11 09:31:37,783 INFO org.apache.hadoop.yarn.server.resourcemanager.rmcontainer.RMContainerImpl: container_1376212503271_0007_01_000035 Container Transitioned from NEW to ALLOCATED
2013-08-11 09:31:37,783 INFO org.apache.hadoop.yarn.server.resourcemanager.RMAuditLogger: USER=ubuntu	OPERATION=AM Allocated Container	TARGET=SchedulerApp	RESULT=SUCCESS	APPID=application_1376212503271_0007	CONTAINERID=container_1376212503271_0007_01_000035
2013-08-11 09:31:37,783 INFO org.apache.hadoop.yarn.server.resourcemanager.scheduler.common.fica.FiCaSchedulerNode: Assigned container container_1376212503271_0007_01_000035 of capacity <memory:1024, vCores:1> on host hadoop-320-5:36272, which currently has 3 containers, <memory:4096, vCores:3> used and <memory:4096, vCores:13> available
2013-08-11 09:31:37,784 INFO org.apache.hadoop.yarn.server.resourcemanager.scheduler.capacity.LeafQueue: assignedContainer application=application_1376212503271_0007 container=Container: [ContainerId: container_1376212503271_0007_01_000035, NodeId: hadoop-320-5:36272, NodeHttpAddress: hadoop-320-5:8042, Resource: <memory:1024, vCores:1>, Priority: 20, State: NEW, Token: null, Status: container_id {, app_attempt_id {, application_id {, id: 7, cluster_timestamp: 1376212503271, }, attemptId: 1, }, id: 35, }, state: C_NEW, ] containerId=container_1376212503271_0007_01_000035 queue=default: capacity=1.0, absoluteCapacity=1.0, usedResources=<memory:44032, vCores:38>usedCapacity=0.8958333, absoluteUsedCapacity=0.8958333, numApps=5, numContainers=38 usedCapacity=0.8958333 absoluteUsedCapacity=0.8958333 used=<memory:44032, vCores:38> cluster=<memory:49152, vCores:96>
2013-08-11 09:31:37,784 INFO org.apache.hadoop.yarn.server.resourcemanager.scheduler.capacity.ParentQueue: Re-sorting queues since queue: root.default stats: default: capacity=1.0, absoluteCapacity=1.0, usedResources=<memory:45056, vCores:39>usedCapacity=0.9166667, absoluteUsedCapacity=0.9166667, numApps=5, numContainers=39
2013-08-11 09:31:37,784 INFO org.apache.hadoop.yarn.server.resourcemanager.scheduler.capacity.ParentQueue: assignedContainer queue=root usedCapacity=0.9166667 absoluteUsedCapacity=0.9166667 used=<memory:45056, vCores:39> cluster=<memory:49152, vCores:96>
2013-08-11 09:31:37,785 INFO org.apache.hadoop.yarn.server.resourcemanager.rmcontainer.RMContainerImpl: container_1376212503271_0007_01_000036 Container Transitioned from NEW to ALLOCATED
2013-08-11 09:31:37,785 INFO org.apache.hadoop.yarn.server.resourcemanager.RMAuditLogger: USER=ubuntu	OPERATION=AM Allocated Container	TARGET=SchedulerApp	RESULT=SUCCESS	APPID=application_1376212503271_0007	CONTAINERID=container_1376212503271_0007_01_000036
2013-08-11 09:31:37,785 INFO org.apache.hadoop.yarn.server.resourcemanager.scheduler.common.fica.FiCaSchedulerNode: Assigned container container_1376212503271_0007_01_000036 of capacity <memory:1024, vCores:1> on host hadoop-320-5:36272, which currently has 4 containers, <memory:5120, vCores:4> used and <memory:3072, vCores:12> available
2013-08-11 09:31:37,786 INFO org.apache.hadoop.yarn.server.resourcemanager.scheduler.capacity.LeafQueue: assignedContainer application=application_1376212503271_0007 container=Container: [ContainerId: container_1376212503271_0007_01_000036, NodeId: hadoop-320-5:36272, NodeHttpAddress: hadoop-320-5:8042, Resource: <memory:1024, vCores:1>, Priority: 20, State: NEW, Token: null, Status: container_id {, app_attempt_id {, application_id {, id: 7, cluster_timestamp: 1376212503271, }, attemptId: 1, }, id: 36, }, state: C_NEW, ] containerId=container_1376212503271_0007_01_000036 queue=default: capacity=1.0, absoluteCapacity=1.0, usedResources=<memory:45056, vCores:39>usedCapacity=0.9166667, absoluteUsedCapacity=0.9166667, numApps=5, numContainers=39 usedCapacity=0.9166667 absoluteUsedCapacity=0.9166667 used=<memory:45056, vCores:39> cluster=<memory:49152, vCores:96>
2013-08-11 09:31:37,786 INFO org.apache.hadoop.yarn.server.resourcemanager.scheduler.capacity.ParentQueue: Re-sorting queues since queue: root.default stats: default: capacity=1.0, absoluteCapacity=1.0, usedResources=<memory:46080, vCores:40>usedCapacity=0.9375, absoluteUsedCapacity=0.9375, numApps=5, numContainers=40
2013-08-11 09:31:37,786 INFO org.apache.hadoop.yarn.server.resourcemanager.scheduler.capacity.ParentQueue: assignedContainer queue=root usedCapacity=0.9375 absoluteUsedCapacity=0.9375 used=<memory:46080, vCores:40> cluster=<memory:49152, vCores:96>
2013-08-11 09:31:37,787 INFO org.apache.hadoop.yarn.server.resourcemanager.rmcontainer.RMContainerImpl: container_1376212503271_0007_01_000037 Container Transitioned from NEW to ALLOCATED
2013-08-11 09:31:37,787 INFO org.apache.hadoop.yarn.server.resourcemanager.RMAuditLogger: USER=ubuntu	OPERATION=AM Allocated Container	TARGET=SchedulerApp	RESULT=SUCCESS	APPID=application_1376212503271_0007	CONTAINERID=container_1376212503271_0007_01_000037
2013-08-11 09:31:37,787 INFO org.apache.hadoop.yarn.server.resourcemanager.scheduler.common.fica.FiCaSchedulerNode: Assigned container container_1376212503271_0007_01_000037 of capacity <memory:1024, vCores:1> on host hadoop-320-5:36272, which currently has 5 containers, <memory:6144, vCores:5> used and <memory:2048, vCores:11> available
2013-08-11 09:31:37,788 INFO org.apache.hadoop.yarn.server.resourcemanager.scheduler.capacity.LeafQueue: assignedContainer application=application_1376212503271_0007 container=Container: [ContainerId: container_1376212503271_0007_01_000037, NodeId: hadoop-320-5:36272, NodeHttpAddress: hadoop-320-5:8042, Resource: <memory:1024, vCores:1>, Priority: 20, State: NEW, Token: null, Status: container_id {, app_attempt_id {, application_id {, id: 7, cluster_timestamp: 1376212503271, }, attemptId: 1, }, id: 37, }, state: C_NEW, ] containerId=container_1376212503271_0007_01_000037 queue=default: capacity=1.0, absoluteCapacity=1.0, usedResources=<memory:46080, vCores:40>usedCapacity=0.9375, absoluteUsedCapacity=0.9375, numApps=5, numContainers=40 usedCapacity=0.9375 absoluteUsedCapacity=0.9375 used=<memory:46080, vCores:40> cluster=<memory:49152, vCores:96>
2013-08-11 09:31:37,788 INFO org.apache.hadoop.yarn.server.resourcemanager.scheduler.capacity.ParentQueue: Re-sorting queues since queue: root.default stats: default: capacity=1.0, absoluteCapacity=1.0, usedResources=<memory:47104, vCores:41>usedCapacity=0.9583333, absoluteUsedCapacity=0.9583333, numApps=5, numContainers=41
2013-08-11 09:31:37,788 INFO org.apache.hadoop.yarn.server.resourcemanager.scheduler.capacity.ParentQueue: assignedContainer queue=root usedCapacity=0.9583333 absoluteUsedCapacity=0.9583333 used=<memory:47104, vCores:41> cluster=<memory:49152, vCores:96>
2013-08-11 09:31:37,789 INFO org.apache.hadoop.yarn.server.resourcemanager.rmcontainer.RMContainerImpl: container_1376212503271_0007_01_000038 Container Transitioned from NEW to ALLOCATED
2013-08-11 09:31:37,789 INFO org.apache.hadoop.yarn.server.resourcemanager.RMAuditLogger: USER=ubuntu	OPERATION=AM Allocated Container	TARGET=SchedulerApp	RESULT=SUCCESS	APPID=application_1376212503271_0007	CONTAINERID=container_1376212503271_0007_01_000038
2013-08-11 09:31:37,789 INFO org.apache.hadoop.yarn.server.resourcemanager.scheduler.common.fica.FiCaSchedulerNode: Assigned container container_1376212503271_0007_01_000038 of capacity <memory:1024, vCores:1> on host hadoop-320-5:36272, which currently has 6 containers, <memory:7168, vCores:6> used and <memory:1024, vCores:10> available
2013-08-11 09:31:37,790 INFO org.apache.hadoop.yarn.server.resourcemanager.scheduler.capacity.LeafQueue: assignedContainer application=application_1376212503271_0007 container=Container: [ContainerId: container_1376212503271_0007_01_000038, NodeId: hadoop-320-5:36272, NodeHttpAddress: hadoop-320-5:8042, Resource: <memory:1024, vCores:1>, Priority: 20, State: NEW, Token: null, Status: container_id {, app_attempt_id {, application_id {, id: 7, cluster_timestamp: 1376212503271, }, attemptId: 1, }, id: 38, }, state: C_NEW, ] containerId=container_1376212503271_0007_01_000038 queue=default: capacity=1.0, absoluteCapacity=1.0, usedResources=<memory:47104, vCores:41>usedCapacity=0.9583333, absoluteUsedCapacity=0.9583333, numApps=5, numContainers=41 usedCapacity=0.9583333 absoluteUsedCapacity=0.9583333 used=<memory:47104, vCores:41> cluster=<memory:49152, vCores:96>
2013-08-11 09:31:37,790 INFO org.apache.hadoop.yarn.server.resourcemanager.scheduler.capacity.ParentQueue: Re-sorting queues since queue: root.default stats: default: capacity=1.0, absoluteCapacity=1.0, usedResources=<memory:48128, vCores:42>usedCapacity=0.9791667, absoluteUsedCapacity=0.9791667, numApps=5, numContainers=42
2013-08-11 09:31:37,790 INFO org.apache.hadoop.yarn.server.resourcemanager.scheduler.capacity.ParentQueue: assignedContainer queue=root usedCapacity=0.9791667 absoluteUsedCapacity=0.9791667 used=<memory:48128, vCores:42> cluster=<memory:49152, vCores:96>
2013-08-11 09:31:37,791 INFO org.apache.hadoop.yarn.server.resourcemanager.rmcontainer.RMContainerImpl: container_1376212503271_0007_01_000039 Container Transitioned from NEW to ALLOCATED
2013-08-11 09:31:37,791 INFO org.apache.hadoop.yarn.server.resourcemanager.RMAuditLogger: USER=ubuntu	OPERATION=AM Allocated Container	TARGET=SchedulerApp	RESULT=SUCCESS	APPID=application_1376212503271_0007	CONTAINERID=container_1376212503271_0007_01_000039
2013-08-11 09:31:37,791 INFO org.apache.hadoop.yarn.server.resourcemanager.scheduler.common.fica.FiCaSchedulerNode: Assigned container container_1376212503271_0007_01_000039 of capacity <memory:1024, vCores:1> on host hadoop-320-5:36272, which currently has 7 containers, <memory:8192, vCores:7> used and <memory:0, vCores:9> available
2013-08-11 09:31:37,792 INFO org.apache.hadoop.yarn.server.resourcemanager.scheduler.capacity.LeafQueue: assignedContainer application=application_1376212503271_0007 container=Container: [ContainerId: container_1376212503271_0007_01_000039, NodeId: hadoop-320-5:36272, NodeHttpAddress: hadoop-320-5:8042, Resource: <memory:1024, vCores:1>, Priority: 20, State: NEW, Token: null, Status: container_id {, app_attempt_id {, application_id {, id: 7, cluster_timestamp: 1376212503271, }, attemptId: 1, }, id: 39, }, state: C_NEW, ] containerId=container_1376212503271_0007_01_000039 queue=default: capacity=1.0, absoluteCapacity=1.0, usedResources=<memory:48128, vCores:42>usedCapacity=0.9791667, absoluteUsedCapacity=0.9791667, numApps=5, numContainers=42 usedCapacity=0.9791667 absoluteUsedCapacity=0.9791667 used=<memory:48128, vCores:42> cluster=<memory:49152, vCores:96>
2013-08-11 09:31:37,792 INFO org.apache.hadoop.yarn.server.resourcemanager.scheduler.capacity.ParentQueue: Re-sorting queues since queue: root.default stats: default: capacity=1.0, absoluteCapacity=1.0, usedResources=<memory:49152, vCores:43>usedCapacity=1.0, absoluteUsedCapacity=1.0, numApps=5, numContainers=43
2013-08-11 09:31:37,793 INFO org.apache.hadoop.yarn.server.resourcemanager.scheduler.capacity.ParentQueue: assignedContainer queue=root usedCapacity=1.0 absoluteUsedCapacity=1.0 used=<memory:49152, vCores:43> cluster=<memory:49152, vCores:96>
2013-08-11 09:31:38,113 INFO org.apache.hadoop.yarn.server.resourcemanager.rmcontainer.RMContainerImpl: container_1376212503271_0007_01_000002 Container Transitioned from ALLOCATED to ACQUIRED
2013-08-11 09:31:38,114 INFO org.apache.hadoop.yarn.server.resourcemanager.rmcontainer.RMContainerImpl: container_1376212503271_0007_01_000003 Container Transitioned from ALLOCATED to ACQUIRED
2013-08-11 09:31:38,115 INFO org.apache.hadoop.yarn.server.resourcemanager.rmcontainer.RMContainerImpl: container_1376212503271_0007_01_000004 Container Transitioned from ALLOCATED to ACQUIRED
2013-08-11 09:31:38,116 INFO org.apache.hadoop.yarn.server.resourcemanager.rmcontainer.RMContainerImpl: container_1376212503271_0007_01_000005 Container Transitioned from ALLOCATED to ACQUIRED
2013-08-11 09:31:38,117 INFO org.apache.hadoop.yarn.server.resourcemanager.rmcontainer.RMContainerImpl: container_1376212503271_0007_01_000006 Container Transitioned from ALLOCATED to ACQUIRED
2013-08-11 09:31:38,118 INFO org.apache.hadoop.yarn.server.resourcemanager.rmcontainer.RMContainerImpl: container_1376212503271_0007_01_000007 Container Transitioned from ALLOCATED to ACQUIRED
2013-08-11 09:31:38,118 INFO org.apache.hadoop.yarn.server.resourcemanager.rmcontainer.RMContainerImpl: container_1376212503271_0007_01_000008 Container Transitioned from ALLOCATED to ACQUIRED
2013-08-11 09:31:38,119 INFO org.apache.hadoop.yarn.server.resourcemanager.rmcontainer.RMContainerImpl: container_1376212503271_0007_01_000009 Container Transitioned from ALLOCATED to ACQUIRED
2013-08-11 09:31:38,120 INFO org.apache.hadoop.yarn.server.resourcemanager.rmcontainer.RMContainerImpl: container_1376212503271_0007_01_000010 Container Transitioned from ALLOCATED to ACQUIRED
2013-08-11 09:31:38,121 INFO org.apache.hadoop.yarn.server.resourcemanager.rmcontainer.RMContainerImpl: container_1376212503271_0007_01_000011 Container Transitioned from ALLOCATED to ACQUIRED
2013-08-11 09:31:38,122 INFO org.apache.hadoop.yarn.server.resourcemanager.rmcontainer.RMContainerImpl: container_1376212503271_0007_01_000012 Container Transitioned from ALLOCATED to ACQUIRED
2013-08-11 09:31:38,122 INFO org.apache.hadoop.yarn.server.resourcemanager.rmcontainer.RMContainerImpl: container_1376212503271_0007_01_000013 Container Transitioned from ALLOCATED to ACQUIRED
2013-08-11 09:31:38,123 INFO org.apache.hadoop.yarn.server.resourcemanager.rmcontainer.RMContainerImpl: container_1376212503271_0007_01_000014 Container Transitioned from ALLOCATED to ACQUIRED
2013-08-11 09:31:38,123 INFO org.apache.hadoop.yarn.server.resourcemanager.rmcontainer.RMContainerImpl: container_1376212503271_0007_01_000015 Container Transitioned from ALLOCATED to ACQUIRED
2013-08-11 09:31:38,124 INFO org.apache.hadoop.yarn.server.resourcemanager.rmcontainer.RMContainerImpl: container_1376212503271_0007_01_000016 Container Transitioned from ALLOCATED to ACQUIRED
2013-08-11 09:31:38,124 INFO org.apache.hadoop.yarn.server.resourcemanager.rmcontainer.RMContainerImpl: container_1376212503271_0007_01_000017 Container Transitioned from ALLOCATED to ACQUIRED
2013-08-11 09:31:38,125 INFO org.apache.hadoop.yarn.server.resourcemanager.rmcontainer.RMContainerImpl: container_1376212503271_0007_01_000018 Container Transitioned from ALLOCATED to ACQUIRED
2013-08-11 09:31:38,125 INFO org.apache.hadoop.yarn.server.resourcemanager.rmcontainer.RMContainerImpl: container_1376212503271_0007_01_000019 Container Transitioned from ALLOCATED to ACQUIRED
2013-08-11 09:31:38,126 INFO org.apache.hadoop.yarn.server.resourcemanager.rmcontainer.RMContainerImpl: container_1376212503271_0007_01_000020 Container Transitioned from ALLOCATED to ACQUIRED
2013-08-11 09:31:38,127 INFO org.apache.hadoop.yarn.server.resourcemanager.rmcontainer.RMContainerImpl: container_1376212503271_0007_01_000021 Container Transitioned from ALLOCATED to ACQUIRED
2013-08-11 09:31:38,127 INFO org.apache.hadoop.yarn.server.resourcemanager.rmcontainer.RMContainerImpl: container_1376212503271_0007_01_000022 Container Transitioned from ALLOCATED to ACQUIRED
2013-08-11 09:31:38,127 INFO org.apache.hadoop.yarn.server.resourcemanager.rmcontainer.RMContainerImpl: container_1376212503271_0007_01_000023 Container Transitioned from ALLOCATED to ACQUIRED
2013-08-11 09:31:38,128 INFO org.apache.hadoop.yarn.server.resourcemanager.rmcontainer.RMContainerImpl: container_1376212503271_0007_01_000024 Container Transitioned from ALLOCATED to ACQUIRED
2013-08-11 09:31:38,128 INFO org.apache.hadoop.yarn.server.resourcemanager.rmcontainer.RMContainerImpl: container_1376212503271_0007_01_000025 Container Transitioned from ALLOCATED to ACQUIRED
2013-08-11 09:31:38,128 INFO org.apache.hadoop.yarn.server.resourcemanager.rmcontainer.RMContainerImpl: container_1376212503271_0007_01_000026 Container Transitioned from ALLOCATED to ACQUIRED
2013-08-11 09:31:38,128 INFO org.apache.hadoop.yarn.server.resourcemanager.rmcontainer.RMContainerImpl: container_1376212503271_0007_01_000027 Container Transitioned from ALLOCATED to ACQUIRED
2013-08-11 09:31:38,128 INFO org.apache.hadoop.yarn.server.resourcemanager.rmcontainer.RMContainerImpl: container_1376212503271_0007_01_000028 Container Transitioned from ALLOCATED to ACQUIRED
2013-08-11 09:31:38,128 INFO org.apache.hadoop.yarn.server.resourcemanager.rmcontainer.RMContainerImpl: container_1376212503271_0007_01_000029 Container Transitioned from ALLOCATED to ACQUIRED
2013-08-11 09:31:38,129 INFO org.apache.hadoop.yarn.server.resourcemanager.rmcontainer.RMContainerImpl: container_1376212503271_0007_01_000030 Container Transitioned from ALLOCATED to ACQUIRED
2013-08-11 09:31:38,129 INFO org.apache.hadoop.yarn.server.resourcemanager.rmcontainer.RMContainerImpl: container_1376212503271_0007_01_000031 Container Transitioned from ALLOCATED to ACQUIRED
2013-08-11 09:31:38,129 INFO org.apache.hadoop.yarn.server.resourcemanager.rmcontainer.RMContainerImpl: container_1376212503271_0007_01_000032 Container Transitioned from ALLOCATED to ACQUIRED
2013-08-11 09:31:38,129 INFO org.apache.hadoop.yarn.server.resourcemanager.rmcontainer.RMContainerImpl: container_1376212503271_0007_01_000033 Container Transitioned from ALLOCATED to ACQUIRED
2013-08-11 09:31:38,129 INFO org.apache.hadoop.yarn.server.resourcemanager.rmcontainer.RMContainerImpl: container_1376212503271_0007_01_000034 Container Transitioned from ALLOCATED to ACQUIRED
2013-08-11 09:31:38,130 INFO org.apache.hadoop.yarn.server.resourcemanager.rmcontainer.RMContainerImpl: container_1376212503271_0007_01_000035 Container Transitioned from ALLOCATED to ACQUIRED
2013-08-11 09:31:38,130 INFO org.apache.hadoop.yarn.server.resourcemanager.rmcontainer.RMContainerImpl: container_1376212503271_0007_01_000036 Container Transitioned from ALLOCATED to ACQUIRED
2013-08-11 09:31:38,130 INFO org.apache.hadoop.yarn.server.resourcemanager.rmcontainer.RMContainerImpl: container_1376212503271_0007_01_000037 Container Transitioned from ALLOCATED to ACQUIRED
2013-08-11 09:31:38,130 INFO org.apache.hadoop.yarn.server.resourcemanager.rmcontainer.RMContainerImpl: container_1376212503271_0007_01_000038 Container Transitioned from ALLOCATED to ACQUIRED
2013-08-11 09:31:38,130 INFO org.apache.hadoop.yarn.server.resourcemanager.rmcontainer.RMContainerImpl: container_1376212503271_0007_01_000039 Container Transitioned from ALLOCATED to ACQUIRED
2013-08-11 09:31:38,567 INFO org.apache.hadoop.yarn.server.resourcemanager.rmcontainer.RMContainerImpl: container_1376212503271_0007_01_000022 Container Transitioned from ACQUIRED to RUNNING
2013-08-11 09:31:38,568 INFO org.apache.hadoop.yarn.server.resourcemanager.rmcontainer.RMContainerImpl: container_1376212503271_0007_01_000023 Container Transitioned from ACQUIRED to RUNNING
2013-08-11 09:31:38,568 INFO org.apache.hadoop.yarn.server.resourcemanager.rmcontainer.RMContainerImpl: container_1376212503271_0007_01_000024 Container Transitioned from ACQUIRED to RUNNING
2013-08-11 09:31:38,569 INFO org.apache.hadoop.yarn.server.resourcemanager.rmcontainer.RMContainerImpl: container_1376212503271_0007_01_000025 Container Transitioned from ACQUIRED to RUNNING
2013-08-11 09:31:38,570 INFO org.apache.hadoop.yarn.server.resourcemanager.rmcontainer.RMContainerImpl: container_1376212503271_0007_01_000026 Container Transitioned from ACQUIRED to RUNNING
2013-08-11 09:31:38,571 INFO org.apache.hadoop.yarn.server.resourcemanager.rmcontainer.RMContainerImpl: container_1376212503271_0007_01_000027 Container Transitioned from ACQUIRED to RUNNING
2013-08-11 09:31:38,824 INFO org.apache.hadoop.yarn.server.resourcemanager.rmcontainer.RMContainerImpl: container_1376212503271_0007_01_000028 Container Transitioned from ACQUIRED to RUNNING
2013-08-11 09:31:38,825 INFO org.apache.hadoop.yarn.server.resourcemanager.rmcontainer.RMContainerImpl: container_1376212503271_0007_01_000029 Container Transitioned from ACQUIRED to RUNNING
2013-08-11 09:31:38,826 INFO org.apache.hadoop.yarn.server.resourcemanager.rmcontainer.RMContainerImpl: container_1376212503271_0007_01_000030 Container Transitioned from ACQUIRED to RUNNING
2013-08-11 09:31:38,828 INFO org.apache.hadoop.yarn.server.resourcemanager.rmcontainer.RMContainerImpl: container_1376212503271_0007_01_000031 Container Transitioned from ACQUIRED to RUNNING
2013-08-11 09:31:38,830 INFO org.apache.hadoop.yarn.server.resourcemanager.rmcontainer.RMContainerImpl: container_1376212503271_0007_01_000032 Container Transitioned from ACQUIRED to RUNNING
2013-08-11 09:31:38,832 INFO org.apache.hadoop.yarn.server.resourcemanager.rmcontainer.RMContainerImpl: container_1376212503271_0007_01_000033 Container Transitioned from ACQUIRED to RUNNING
2013-08-11 09:31:38,832 INFO org.apache.hadoop.yarn.server.resourcemanager.rmcontainer.RMContainerImpl: container_1376212503271_0007_01_000034 Container Transitioned from ACQUIRED to RUNNING
2013-08-11 09:31:38,833 INFO org.apache.hadoop.yarn.server.resourcemanager.rmcontainer.RMContainerImpl: container_1376212503271_0007_01_000035 Container Transitioned from ACQUIRED to RUNNING
2013-08-11 09:31:38,833 INFO org.apache.hadoop.yarn.server.resourcemanager.rmcontainer.RMContainerImpl: container_1376212503271_0007_01_000036 Container Transitioned from ACQUIRED to RUNNING
2013-08-11 09:31:38,834 INFO org.apache.hadoop.yarn.server.resourcemanager.rmcontainer.RMContainerImpl: container_1376212503271_0007_01_000037 Container Transitioned from ACQUIRED to RUNNING
2013-08-11 09:31:38,835 INFO org.apache.hadoop.yarn.server.resourcemanager.rmcontainer.RMContainerImpl: container_1376212503271_0007_01_000038 Container Transitioned from ACQUIRED to RUNNING
2013-08-11 09:31:38,836 INFO org.apache.hadoop.yarn.server.resourcemanager.rmcontainer.RMContainerImpl: container_1376212503271_0007_01_000039 Container Transitioned from ACQUIRED to RUNNING
2013-08-11 09:31:38,836 INFO org.apache.hadoop.yarn.server.resourcemanager.ApplicationMasterService: AM registration appattempt_1376212503271_0009_000001
2013-08-11 09:31:38,836 INFO org.apache.hadoop.yarn.server.resourcemanager.RMAuditLogger: USER=ubuntu	IP=192.168.100.14	OPERATION=Register App Master	TARGET=ApplicationMasterService	RESULT=SUCCESS	APPID=application_1376212503271_0009	APPATTEMPTID=appattempt_1376212503271_0009_000001
2013-08-11 09:31:38,838 INFO org.apache.hadoop.yarn.server.resourcemanager.rmapp.attempt.RMAppAttemptImpl: appattempt_1376212503271_0009_000001 State change from LAUNCHED to RUNNING
2013-08-11 09:31:38,838 INFO org.apache.hadoop.yarn.server.resourcemanager.rmapp.RMAppImpl: application_1376212503271_0009 State change from ACCEPTED to RUNNING
2013-08-11 09:31:39,322 INFO org.apache.hadoop.yarn.server.resourcemanager.rmcontainer.RMContainerImpl: container_1376212503271_0007_01_000002 Container Transitioned from ACQUIRED to RUNNING
2013-08-11 09:31:39,322 INFO org.apache.hadoop.yarn.server.resourcemanager.rmcontainer.RMContainerImpl: container_1376212503271_0007_01_000003 Container Transitioned from ACQUIRED to RUNNING
2013-08-11 09:31:39,322 INFO org.apache.hadoop.yarn.server.resourcemanager.rmcontainer.RMContainerImpl: container_1376212503271_0007_01_000004 Container Transitioned from ACQUIRED to RUNNING
2013-08-11 09:31:39,322 INFO org.apache.hadoop.yarn.server.resourcemanager.rmcontainer.RMContainerImpl: container_1376212503271_0007_01_000005 Container Transitioned from ACQUIRED to RUNNING
2013-08-11 09:31:39,323 INFO org.apache.hadoop.yarn.server.resourcemanager.rmcontainer.RMContainerImpl: container_1376212503271_0007_01_000006 Container Transitioned from ACQUIRED to RUNNING
2013-08-11 09:31:39,323 INFO org.apache.hadoop.yarn.server.resourcemanager.rmcontainer.RMContainerImpl: container_1376212503271_0007_01_000007 Container Transitioned from ACQUIRED to RUNNING
2013-08-11 09:31:39,408 INFO org.apache.hadoop.yarn.server.resourcemanager.rmcontainer.RMContainerImpl: container_1376212503271_0007_01_000008 Container Transitioned from ACQUIRED to RUNNING
2013-08-11 09:31:39,409 INFO org.apache.hadoop.yarn.server.resourcemanager.rmcontainer.RMContainerImpl: container_1376212503271_0007_01_000009 Container Transitioned from ACQUIRED to RUNNING
2013-08-11 09:31:39,409 INFO org.apache.hadoop.yarn.server.resourcemanager.rmcontainer.RMContainerImpl: container_1376212503271_0007_01_000010 Container Transitioned from ACQUIRED to RUNNING
2013-08-11 09:31:39,414 INFO org.apache.hadoop.yarn.server.resourcemanager.rmcontainer.RMContainerImpl: container_1376212503271_0007_01_000011 Container Transitioned from ACQUIRED to RUNNING
2013-08-11 09:31:39,416 INFO org.apache.hadoop.yarn.server.resourcemanager.rmcontainer.RMContainerImpl: container_1376212503271_0007_01_000012 Container Transitioned from ACQUIRED to RUNNING
2013-08-11 09:31:39,417 INFO org.apache.hadoop.yarn.server.resourcemanager.rmcontainer.RMContainerImpl: container_1376212503271_0007_01_000013 Container Transitioned from ACQUIRED to RUNNING
2013-08-11 09:31:39,417 INFO org.apache.hadoop.yarn.server.resourcemanager.rmcontainer.RMContainerImpl: container_1376212503271_0007_01_000014 Container Transitioned from ACQUIRED to RUNNING
2013-08-11 09:31:39,418 INFO org.apache.hadoop.yarn.server.resourcemanager.rmcontainer.RMContainerImpl: container_1376212503271_0007_01_000015 Container Transitioned from ACQUIRED to RUNNING
2013-08-11 09:31:39,431 INFO org.apache.hadoop.yarn.server.resourcemanager.rmcontainer.RMContainerImpl: container_1376212503271_0007_01_000016 Container Transitioned from ACQUIRED to RUNNING
2013-08-11 09:31:39,431 INFO org.apache.hadoop.yarn.server.resourcemanager.rmcontainer.RMContainerImpl: container_1376212503271_0007_01_000017 Container Transitioned from ACQUIRED to RUNNING
2013-08-11 09:31:39,432 INFO org.apache.hadoop.yarn.server.resourcemanager.rmcontainer.RMContainerImpl: container_1376212503271_0007_01_000018 Container Transitioned from ACQUIRED to RUNNING
2013-08-11 09:31:39,432 INFO org.apache.hadoop.yarn.server.resourcemanager.rmcontainer.RMContainerImpl: container_1376212503271_0007_01_000019 Container Transitioned from ACQUIRED to RUNNING
2013-08-11 09:31:39,432 INFO org.apache.hadoop.yarn.server.resourcemanager.rmcontainer.RMContainerImpl: container_1376212503271_0007_01_000020 Container Transitioned from ACQUIRED to RUNNING
2013-08-11 09:31:39,432 INFO org.apache.hadoop.yarn.server.resourcemanager.rmcontainer.RMContainerImpl: container_1376212503271_0007_01_000021 Container Transitioned from ACQUIRED to RUNNING
2013-08-11 09:31:40,361 INFO org.apache.hadoop.yarn.server.resourcemanager.ApplicationMasterService: AM registration appattempt_1376212503271_0008_000001
2013-08-11 09:31:40,361 INFO org.apache.hadoop.yarn.server.resourcemanager.RMAuditLogger: USER=ubuntu	IP=192.168.100.15	OPERATION=Register App Master	TARGET=ApplicationMasterService	RESULT=SUCCESS	APPID=application_1376212503271_0008	APPATTEMPTID=appattempt_1376212503271_0008_000001
2013-08-11 09:31:40,362 INFO org.apache.hadoop.yarn.server.resourcemanager.rmapp.attempt.RMAppAttemptImpl: appattempt_1376212503271_0008_000001 State change from LAUNCHED to RUNNING
2013-08-11 09:31:40,362 INFO org.apache.hadoop.yarn.server.resourcemanager.rmapp.RMAppImpl: application_1376212503271_0008 State change from ACCEPTED to RUNNING
2013-08-11 09:32:01,949 INFO org.apache.hadoop.yarn.server.resourcemanager.rmcontainer.RMContainerImpl: container_1376212503271_0007_01_000018 Container Transitioned from RUNNING to COMPLETED
2013-08-11 09:32:01,949 INFO org.apache.hadoop.yarn.server.resourcemanager.scheduler.common.fica.FiCaSchedulerApp: Completed container: container_1376212503271_0007_01_000018 in state: COMPLETED event:FINISHED
2013-08-11 09:32:01,949 INFO org.apache.hadoop.yarn.server.resourcemanager.RMAuditLogger: USER=ubuntu	OPERATION=AM Released Container	TARGET=SchedulerApp	RESULT=SUCCESS	APPID=application_1376212503271_0007	CONTAINERID=container_1376212503271_0007_01_000018
2013-08-11 09:32:01,950 INFO org.apache.hadoop.yarn.server.resourcemanager.scheduler.common.fica.FiCaSchedulerNode: Released container container_1376212503271_0007_01_000018 of capacity <memory:1024, vCores:1> on host hadoop-320-7:48037, which currently has 6 containers, <memory:7168, vCores:6> used and <memory:1024, vCores:10> available, release resources=true
2013-08-11 09:32:01,950 INFO org.apache.hadoop.yarn.server.resourcemanager.scheduler.capacity.LeafQueue: default used=<memory:48128, vCores:42> numContainers=42 user=ubuntu user-resources=<memory:48128, vCores:42>
2013-08-11 09:32:01,953 INFO org.apache.hadoop.yarn.server.resourcemanager.scheduler.capacity.LeafQueue: completedContainer container=Container: [ContainerId: container_1376212503271_0007_01_000018, NodeId: hadoop-320-7:48037, NodeHttpAddress: hadoop-320-7:8042, Resource: <memory:1024, vCores:1>, Priority: 20, State: NEW, Token: null, Status: container_id {, app_attempt_id {, application_id {, id: 7, cluster_timestamp: 1376212503271, }, attemptId: 1, }, id: 18, }, state: C_COMPLETE, diagnostics: "Container killed by the ApplicationMaster.\n", exit_status: 0, ] resource=<memory:1024, vCores:1> queue=default: capacity=1.0, absoluteCapacity=1.0, usedResources=<memory:48128, vCores:42>usedCapacity=0.9791667, absoluteUsedCapacity=0.9791667, numApps=5, numContainers=42 usedCapacity=0.9791667 absoluteUsedCapacity=0.9791667 used=<memory:48128, vCores:42> cluster=<memory:49152, vCores:96>
2013-08-11 09:32:01,953 INFO org.apache.hadoop.yarn.server.resourcemanager.scheduler.capacity.ParentQueue: completedContainer queue=root usedCapacity=0.9791667 absoluteUsedCapacity=0.9791667 used=<memory:48128, vCores:42> cluster=<memory:49152, vCores:96>
2013-08-11 09:32:01,953 INFO org.apache.hadoop.yarn.server.resourcemanager.scheduler.capacity.CapacityScheduler: Application appattempt_1376212503271_0007_000001 released container container_1376212503271_0007_01_000018 on node: host: hadoop-320-7:48037 #containers=6 available=1024 used=7168 with event: FINISHED
2013-08-11 09:32:01,953 INFO org.apache.hadoop.yarn.server.resourcemanager.rmcontainer.RMContainerImpl: container_1376212503271_0006_01_000002 Container Transitioned from NEW to ALLOCATED
2013-08-11 09:32:01,954 INFO org.apache.hadoop.yarn.server.resourcemanager.RMAuditLogger: USER=ubuntu	OPERATION=AM Allocated Container	TARGET=SchedulerApp	RESULT=SUCCESS	APPID=application_1376212503271_0006	CONTAINERID=container_1376212503271_0006_01_000002
2013-08-11 09:32:01,954 INFO org.apache.hadoop.yarn.server.resourcemanager.scheduler.common.fica.FiCaSchedulerNode: Assigned container container_1376212503271_0006_01_000002 of capacity <memory:1024, vCores:1> on host hadoop-320-7:48037, which currently has 7 containers, <memory:8192, vCores:7> used and <memory:0, vCores:9> available
2013-08-11 09:32:01,955 INFO org.apache.hadoop.yarn.server.resourcemanager.scheduler.capacity.LeafQueue: assignedContainer application=application_1376212503271_0006 container=Container: [ContainerId: container_1376212503271_0006_01_000002, NodeId: hadoop-320-7:48037, NodeHttpAddress: hadoop-320-7:8042, Resource: <memory:1024, vCores:1>, Priority: 20, State: NEW, Token: null, Status: container_id {, app_attempt_id {, application_id {, id: 6, cluster_timestamp: 1376212503271, }, attemptId: 1, }, id: 2, }, state: C_NEW, ] containerId=container_1376212503271_0006_01_000002 queue=default: capacity=1.0, absoluteCapacity=1.0, usedResources=<memory:48128, vCores:42>usedCapacity=0.9791667, absoluteUsedCapacity=0.9791667, numApps=5, numContainers=42 usedCapacity=0.9791667 absoluteUsedCapacity=0.9791667 used=<memory:48128, vCores:42> cluster=<memory:49152, vCores:96>
2013-08-11 09:32:01,955 INFO org.apache.hadoop.yarn.server.resourcemanager.scheduler.capacity.ParentQueue: Re-sorting queues since queue: root.default stats: default: capacity=1.0, absoluteCapacity=1.0, usedResources=<memory:49152, vCores:43>usedCapacity=1.0, absoluteUsedCapacity=1.0, numApps=5, numContainers=43
2013-08-11 09:32:01,955 INFO org.apache.hadoop.yarn.server.resourcemanager.scheduler.capacity.ParentQueue: assignedContainer queue=root usedCapacity=1.0 absoluteUsedCapacity=1.0 used=<memory:49152, vCores:43> cluster=<memory:49152, vCores:96>
2013-08-11 09:32:02,201 INFO org.apache.hadoop.yarn.server.resourcemanager.rmcontainer.RMContainerImpl: container_1376212503271_0007_01_000031 Container Transitioned from RUNNING to COMPLETED
2013-08-11 09:32:02,201 INFO org.apache.hadoop.yarn.server.resourcemanager.scheduler.common.fica.FiCaSchedulerApp: Completed container: container_1376212503271_0007_01_000031 in state: COMPLETED event:FINISHED
2013-08-11 09:32:02,201 INFO org.apache.hadoop.yarn.server.resourcemanager.RMAuditLogger: USER=ubuntu	OPERATION=AM Released Container	TARGET=SchedulerApp	RESULT=SUCCESS	APPID=application_1376212503271_0007	CONTAINERID=container_1376212503271_0007_01_000031
2013-08-11 09:32:02,201 INFO org.apache.hadoop.yarn.server.resourcemanager.scheduler.common.fica.FiCaSchedulerNode: Released container container_1376212503271_0007_01_000031 of capacity <memory:1024, vCores:1> on host hadoop-320-4:39920, which currently has 6 containers, <memory:7168, vCores:6> used and <memory:1024, vCores:10> available, release resources=true
2013-08-11 09:32:02,201 INFO org.apache.hadoop.yarn.server.resourcemanager.scheduler.capacity.LeafQueue: default used=<memory:48128, vCores:42> numContainers=42 user=ubuntu user-resources=<memory:48128, vCores:42>
2013-08-11 09:32:02,203 INFO org.apache.hadoop.yarn.server.resourcemanager.scheduler.capacity.LeafQueue: completedContainer container=Container: [ContainerId: container_1376212503271_0007_01_000031, NodeId: hadoop-320-4:39920, NodeHttpAddress: hadoop-320-4:8042, Resource: <memory:1024, vCores:1>, Priority: 20, State: NEW, Token: null, Status: container_id {, app_attempt_id {, application_id {, id: 7, cluster_timestamp: 1376212503271, }, attemptId: 1, }, id: 31, }, state: C_COMPLETE, diagnostics: "Container killed by the ApplicationMaster.\n\n", exit_status: 143, ] resource=<memory:1024, vCores:1> queue=default: capacity=1.0, absoluteCapacity=1.0, usedResources=<memory:48128, vCores:42>usedCapacity=0.9791667, absoluteUsedCapacity=0.9791667, numApps=5, numContainers=42 usedCapacity=0.9791667 absoluteUsedCapacity=0.9791667 used=<memory:48128, vCores:42> cluster=<memory:49152, vCores:96>
2013-08-11 09:32:02,203 INFO org.apache.hadoop.yarn.server.resourcemanager.scheduler.capacity.ParentQueue: completedContainer queue=root usedCapacity=0.9791667 absoluteUsedCapacity=0.9791667 used=<memory:48128, vCores:42> cluster=<memory:49152, vCores:96>
2013-08-11 09:32:02,203 INFO org.apache.hadoop.yarn.server.resourcemanager.scheduler.capacity.CapacityScheduler: Application appattempt_1376212503271_0007_000001 released container container_1376212503271_0007_01_000031 on node: host: hadoop-320-4:39920 #containers=6 available=1024 used=7168 with event: FINISHED
2013-08-11 09:32:02,204 INFO org.apache.hadoop.yarn.server.resourcemanager.rmcontainer.RMContainerImpl: container_1376212503271_0006_01_000003 Container Transitioned from NEW to ALLOCATED
2013-08-11 09:32:02,204 INFO org.apache.hadoop.yarn.server.resourcemanager.RMAuditLogger: USER=ubuntu	OPERATION=AM Allocated Container	TARGET=SchedulerApp	RESULT=SUCCESS	APPID=application_1376212503271_0006	CONTAINERID=container_1376212503271_0006_01_000003
2013-08-11 09:32:02,204 INFO org.apache.hadoop.yarn.server.resourcemanager.scheduler.common.fica.FiCaSchedulerNode: Assigned container container_1376212503271_0006_01_000003 of capacity <memory:1024, vCores:1> on host hadoop-320-4:39920, which currently has 7 containers, <memory:8192, vCores:7> used and <memory:0, vCores:9> available
2013-08-11 09:32:02,205 INFO org.apache.hadoop.yarn.server.resourcemanager.scheduler.capacity.LeafQueue: assignedContainer application=application_1376212503271_0006 container=Container: [ContainerId: container_1376212503271_0006_01_000003, NodeId: hadoop-320-4:39920, NodeHttpAddress: hadoop-320-4:8042, Resource: <memory:1024, vCores:1>, Priority: 20, State: NEW, Token: null, Status: container_id {, app_attempt_id {, application_id {, id: 6, cluster_timestamp: 1376212503271, }, attemptId: 1, }, id: 3, }, state: C_NEW, ] containerId=container_1376212503271_0006_01_000003 queue=default: capacity=1.0, absoluteCapacity=1.0, usedResources=<memory:48128, vCores:42>usedCapacity=0.9791667, absoluteUsedCapacity=0.9791667, numApps=5, numContainers=42 usedCapacity=0.9791667 absoluteUsedCapacity=0.9791667 used=<memory:48128, vCores:42> cluster=<memory:49152, vCores:96>
2013-08-11 09:32:02,205 INFO org.apache.hadoop.yarn.server.resourcemanager.scheduler.capacity.ParentQueue: Re-sorting queues since queue: root.default stats: default: capacity=1.0, absoluteCapacity=1.0, usedResources=<memory:49152, vCores:43>usedCapacity=1.0, absoluteUsedCapacity=1.0, numApps=5, numContainers=43
2013-08-11 09:32:02,205 INFO org.apache.hadoop.yarn.server.resourcemanager.scheduler.capacity.ParentQueue: assignedContainer queue=root usedCapacity=1.0 absoluteUsedCapacity=1.0 used=<memory:49152, vCores:43> cluster=<memory:49152, vCores:96>
2013-08-11 09:32:02,295 INFO org.apache.hadoop.yarn.server.resourcemanager.rmcontainer.RMContainerImpl: container_1376212503271_0006_01_000002 Container Transitioned from ALLOCATED to ACQUIRED
2013-08-11 09:32:02,297 INFO org.apache.hadoop.yarn.server.resourcemanager.rmcontainer.RMContainerImpl: container_1376212503271_0006_01_000003 Container Transitioned from ALLOCATED to ACQUIRED
2013-08-11 09:32:02,961 INFO org.apache.hadoop.yarn.server.resourcemanager.rmcontainer.RMContainerImpl: container_1376212503271_0006_01_000002 Container Transitioned from ACQUIRED to RUNNING
2013-08-11 09:32:03,283 INFO org.apache.hadoop.yarn.server.resourcemanager.rmcontainer.RMContainerImpl: container_1376212503271_0006_01_000003 Container Transitioned from ACQUIRED to RUNNING
2013-08-11 09:32:06,337 INFO org.apache.hadoop.yarn.server.resourcemanager.rmcontainer.RMContainerImpl: container_1376212503271_0007_01_000011 Container Transitioned from RUNNING to COMPLETED
2013-08-11 09:32:06,337 INFO org.apache.hadoop.yarn.server.resourcemanager.scheduler.common.fica.FiCaSchedulerApp: Completed container: container_1376212503271_0007_01_000011 in state: COMPLETED event:FINISHED
2013-08-11 09:32:06,337 INFO org.apache.hadoop.yarn.server.resourcemanager.RMAuditLogger: USER=ubuntu	OPERATION=AM Released Container	TARGET=SchedulerApp	RESULT=SUCCESS	APPID=application_1376212503271_0007	CONTAINERID=container_1376212503271_0007_01_000011
2013-08-11 09:32:06,338 INFO org.apache.hadoop.yarn.server.resourcemanager.scheduler.common.fica.FiCaSchedulerNode: Released container container_1376212503271_0007_01_000011 of capacity <memory:1024, vCores:1> on host hadoop-320-6:38980, which currently has 7 containers, <memory:7168, vCores:7> used and <memory:1024, vCores:9> available, release resources=true
2013-08-11 09:32:06,338 INFO org.apache.hadoop.yarn.server.resourcemanager.scheduler.capacity.LeafQueue: default used=<memory:48128, vCores:42> numContainers=42 user=ubuntu user-resources=<memory:48128, vCores:42>
2013-08-11 09:32:06,339 INFO org.apache.hadoop.yarn.server.resourcemanager.scheduler.capacity.LeafQueue: completedContainer container=Container: [ContainerId: container_1376212503271_0007_01_000011, NodeId: hadoop-320-6:38980, NodeHttpAddress: hadoop-320-6:8042, Resource: <memory:1024, vCores:1>, Priority: 20, State: NEW, Token: null, Status: container_id {, app_attempt_id {, application_id {, id: 7, cluster_timestamp: 1376212503271, }, attemptId: 1, }, id: 11, }, state: C_COMPLETE, diagnostics: "Container killed by the ApplicationMaster.\n\n", exit_status: 143, ] resource=<memory:1024, vCores:1> queue=default: capacity=1.0, absoluteCapacity=1.0, usedResources=<memory:48128, vCores:42>usedCapacity=0.9791667, absoluteUsedCapacity=0.9791667, numApps=5, numContainers=42 usedCapacity=0.9791667 absoluteUsedCapacity=0.9791667 used=<memory:48128, vCores:42> cluster=<memory:49152, vCores:96>
2013-08-11 09:32:06,339 INFO org.apache.hadoop.yarn.server.resourcemanager.scheduler.capacity.ParentQueue: completedContainer queue=root usedCapacity=0.9791667 absoluteUsedCapacity=0.9791667 used=<memory:48128, vCores:42> cluster=<memory:49152, vCores:96>
2013-08-11 09:32:06,340 INFO org.apache.hadoop.yarn.server.resourcemanager.scheduler.capacity.CapacityScheduler: Application appattempt_1376212503271_0007_000001 released container container_1376212503271_0007_01_000011 on node: host: hadoop-320-6:38980 #containers=7 available=1024 used=7168 with event: FINISHED
2013-08-11 09:32:06,340 INFO org.apache.hadoop.yarn.server.resourcemanager.rmcontainer.RMContainerImpl: container_1376212503271_0006_01_000004 Container Transitioned from NEW to ALLOCATED
2013-08-11 09:32:06,340 INFO org.apache.hadoop.yarn.server.resourcemanager.RMAuditLogger: USER=ubuntu	OPERATION=AM Allocated Container	TARGET=SchedulerApp	RESULT=SUCCESS	APPID=application_1376212503271_0006	CONTAINERID=container_1376212503271_0006_01_000004
2013-08-11 09:32:06,340 INFO org.apache.hadoop.yarn.server.resourcemanager.scheduler.common.fica.FiCaSchedulerNode: Assigned container container_1376212503271_0006_01_000004 of capacity <memory:1024, vCores:1> on host hadoop-320-6:38980, which currently has 8 containers, <memory:8192, vCores:8> used and <memory:0, vCores:8> available
2013-08-11 09:32:06,341 INFO org.apache.hadoop.yarn.server.resourcemanager.scheduler.capacity.LeafQueue: assignedContainer application=application_1376212503271_0006 container=Container: [ContainerId: container_1376212503271_0006_01_000004, NodeId: hadoop-320-6:38980, NodeHttpAddress: hadoop-320-6:8042, Resource: <memory:1024, vCores:1>, Priority: 20, State: NEW, Token: null, Status: container_id {, app_attempt_id {, application_id {, id: 6, cluster_timestamp: 1376212503271, }, attemptId: 1, }, id: 4, }, state: C_NEW, ] containerId=container_1376212503271_0006_01_000004 queue=default: capacity=1.0, absoluteCapacity=1.0, usedResources=<memory:48128, vCores:42>usedCapacity=0.9791667, absoluteUsedCapacity=0.9791667, numApps=5, numContainers=42 usedCapacity=0.9791667 absoluteUsedCapacity=0.9791667 used=<memory:48128, vCores:42> cluster=<memory:49152, vCores:96>
2013-08-11 09:32:06,342 INFO org.apache.hadoop.yarn.server.resourcemanager.scheduler.capacity.ParentQueue: Re-sorting queues since queue: root.default stats: default: capacity=1.0, absoluteCapacity=1.0, usedResources=<memory:49152, vCores:43>usedCapacity=1.0, absoluteUsedCapacity=1.0, numApps=5, numContainers=43
2013-08-11 09:32:06,342 INFO org.apache.hadoop.yarn.server.resourcemanager.scheduler.capacity.ParentQueue: assignedContainer queue=root usedCapacity=1.0 absoluteUsedCapacity=1.0 used=<memory:49152, vCores:43> cluster=<memory:49152, vCores:96>
2013-08-11 09:32:06,610 INFO org.apache.hadoop.yarn.server.resourcemanager.rmcontainer.RMContainerImpl: container_1376212503271_0006_01_000004 Container Transitioned from ALLOCATED to ACQUIRED
2013-08-11 09:32:07,109 INFO org.apache.hadoop.yarn.server.resourcemanager.rmcontainer.RMContainerImpl: container_1376212503271_0007_01_000029 Container Transitioned from RUNNING to COMPLETED
2013-08-11 09:32:07,109 INFO org.apache.hadoop.yarn.server.resourcemanager.scheduler.common.fica.FiCaSchedulerApp: Completed container: container_1376212503271_0007_01_000029 in state: COMPLETED event:FINISHED
2013-08-11 09:32:07,110 INFO org.apache.hadoop.yarn.server.resourcemanager.RMAuditLogger: USER=ubuntu	OPERATION=AM Released Container	TARGET=SchedulerApp	RESULT=SUCCESS	APPID=application_1376212503271_0007	CONTAINERID=container_1376212503271_0007_01_000029
2013-08-11 09:32:07,110 INFO org.apache.hadoop.yarn.server.resourcemanager.scheduler.common.fica.FiCaSchedulerNode: Released container container_1376212503271_0007_01_000029 of capacity <memory:1024, vCores:1> on host hadoop-320-4:39920, which currently has 6 containers, <memory:7168, vCores:6> used and <memory:1024, vCores:10> available, release resources=true
2013-08-11 09:32:07,110 INFO org.apache.hadoop.yarn.server.resourcemanager.scheduler.capacity.LeafQueue: default used=<memory:48128, vCores:42> numContainers=42 user=ubuntu user-resources=<memory:48128, vCores:42>
2013-08-11 09:32:07,111 INFO org.apache.hadoop.yarn.server.resourcemanager.scheduler.capacity.LeafQueue: completedContainer container=Container: [ContainerId: container_1376212503271_0007_01_000029, NodeId: hadoop-320-4:39920, NodeHttpAddress: hadoop-320-4:8042, Resource: <memory:1024, vCores:1>, Priority: 20, State: NEW, Token: null, Status: container_id {, app_attempt_id {, application_id {, id: 7, cluster_timestamp: 1376212503271, }, attemptId: 1, }, id: 29, }, state: C_COMPLETE, diagnostics: "Container killed by the ApplicationMaster.\n\n", exit_status: 143, ] resource=<memory:1024, vCores:1> queue=default: capacity=1.0, absoluteCapacity=1.0, usedResources=<memory:48128, vCores:42>usedCapacity=0.9791667, absoluteUsedCapacity=0.9791667, numApps=5, numContainers=42 usedCapacity=0.9791667 absoluteUsedCapacity=0.9791667 used=<memory:48128, vCores:42> cluster=<memory:49152, vCores:96>
2013-08-11 09:32:07,112 INFO org.apache.hadoop.yarn.server.resourcemanager.scheduler.capacity.ParentQueue: completedContainer queue=root usedCapacity=0.9791667 absoluteUsedCapacity=0.9791667 used=<memory:48128, vCores:42> cluster=<memory:49152, vCores:96>
2013-08-11 09:32:07,112 INFO org.apache.hadoop.yarn.server.resourcemanager.scheduler.capacity.CapacityScheduler: Application appattempt_1376212503271_0007_000001 released container container_1376212503271_0007_01_000029 on node: host: hadoop-320-4:39920 #containers=6 available=1024 used=7168 with event: FINISHED
2013-08-11 09:32:07,112 INFO org.apache.hadoop.yarn.server.resourcemanager.rmcontainer.RMContainerImpl: container_1376212503271_0006_01_000005 Container Transitioned from NEW to ALLOCATED
2013-08-11 09:32:07,113 INFO org.apache.hadoop.yarn.server.resourcemanager.RMAuditLogger: USER=ubuntu	OPERATION=AM Allocated Container	TARGET=SchedulerApp	RESULT=SUCCESS	APPID=application_1376212503271_0006	CONTAINERID=container_1376212503271_0006_01_000005
2013-08-11 09:32:07,113 INFO org.apache.hadoop.yarn.server.resourcemanager.scheduler.common.fica.FiCaSchedulerNode: Assigned container container_1376212503271_0006_01_000005 of capacity <memory:1024, vCores:1> on host hadoop-320-4:39920, which currently has 7 containers, <memory:8192, vCores:7> used and <memory:0, vCores:9> available
2013-08-11 09:32:07,114 INFO org.apache.hadoop.yarn.server.resourcemanager.scheduler.capacity.LeafQueue: assignedContainer application=application_1376212503271_0006 container=Container: [ContainerId: container_1376212503271_0006_01_000005, NodeId: hadoop-320-4:39920, NodeHttpAddress: hadoop-320-4:8042, Resource: <memory:1024, vCores:1>, Priority: 20, State: NEW, Token: null, Status: container_id {, app_attempt_id {, application_id {, id: 6, cluster_timestamp: 1376212503271, }, attemptId: 1, }, id: 5, }, state: C_NEW, ] containerId=container_1376212503271_0006_01_000005 queue=default: capacity=1.0, absoluteCapacity=1.0, usedResources=<memory:48128, vCores:42>usedCapacity=0.9791667, absoluteUsedCapacity=0.9791667, numApps=5, numContainers=42 usedCapacity=0.9791667 absoluteUsedCapacity=0.9791667 used=<memory:48128, vCores:42> cluster=<memory:49152, vCores:96>
2013-08-11 09:32:07,114 INFO org.apache.hadoop.yarn.server.resourcemanager.scheduler.capacity.ParentQueue: Re-sorting queues since queue: root.default stats: default: capacity=1.0, absoluteCapacity=1.0, usedResources=<memory:49152, vCores:43>usedCapacity=1.0, absoluteUsedCapacity=1.0, numApps=5, numContainers=43
2013-08-11 09:32:07,114 INFO org.apache.hadoop.yarn.server.resourcemanager.scheduler.capacity.ParentQueue: assignedContainer queue=root usedCapacity=1.0 absoluteUsedCapacity=1.0 used=<memory:49152, vCores:43> cluster=<memory:49152, vCores:96>
2013-08-11 09:32:07,348 INFO org.apache.hadoop.yarn.server.resourcemanager.rmcontainer.RMContainerImpl: container_1376212503271_0007_01_000032 Container Transitioned from RUNNING to COMPLETED
2013-08-11 09:32:07,348 INFO org.apache.hadoop.yarn.server.resourcemanager.scheduler.common.fica.FiCaSchedulerApp: Completed container: container_1376212503271_0007_01_000032 in state: COMPLETED event:FINISHED
2013-08-11 09:32:07,348 INFO org.apache.hadoop.yarn.server.resourcemanager.RMAuditLogger: USER=ubuntu	OPERATION=AM Released Container	TARGET=SchedulerApp	RESULT=SUCCESS	APPID=application_1376212503271_0007	CONTAINERID=container_1376212503271_0007_01_000032
2013-08-11 09:32:07,349 INFO org.apache.hadoop.yarn.server.resourcemanager.scheduler.common.fica.FiCaSchedulerNode: Released container container_1376212503271_0007_01_000032 of capacity <memory:1024, vCores:1> on host hadoop-320-4:39920, which currently has 6 containers, <memory:7168, vCores:6> used and <memory:1024, vCores:10> available, release resources=true
2013-08-11 09:32:07,349 INFO org.apache.hadoop.yarn.server.resourcemanager.scheduler.capacity.LeafQueue: default used=<memory:48128, vCores:42> numContainers=42 user=ubuntu user-resources=<memory:48128, vCores:42>
2013-08-11 09:32:07,350 INFO org.apache.hadoop.yarn.server.resourcemanager.scheduler.capacity.LeafQueue: completedContainer container=Container: [ContainerId: container_1376212503271_0007_01_000032, NodeId: hadoop-320-4:39920, NodeHttpAddress: hadoop-320-4:8042, Resource: <memory:1024, vCores:1>, Priority: 20, State: NEW, Token: null, Status: container_id {, app_attempt_id {, application_id {, id: 7, cluster_timestamp: 1376212503271, }, attemptId: 1, }, id: 32, }, state: C_COMPLETE, diagnostics: "Container killed by the ApplicationMaster.\n\n", exit_status: 143, ] resource=<memory:1024, vCores:1> queue=default: capacity=1.0, absoluteCapacity=1.0, usedResources=<memory:48128, vCores:42>usedCapacity=0.9791667, absoluteUsedCapacity=0.9791667, numApps=5, numContainers=42 usedCapacity=0.9791667 absoluteUsedCapacity=0.9791667 used=<memory:48128, vCores:42> cluster=<memory:49152, vCores:96>
2013-08-11 09:32:07,350 INFO org.apache.hadoop.yarn.server.resourcemanager.scheduler.capacity.ParentQueue: completedContainer queue=root usedCapacity=0.9791667 absoluteUsedCapacity=0.9791667 used=<memory:48128, vCores:42> cluster=<memory:49152, vCores:96>
2013-08-11 09:32:07,350 INFO org.apache.hadoop.yarn.server.resourcemanager.scheduler.capacity.CapacityScheduler: Application appattempt_1376212503271_0007_000001 released container container_1376212503271_0007_01_000032 on node: host: hadoop-320-4:39920 #containers=6 available=1024 used=7168 with event: FINISHED
2013-08-11 09:32:07,351 INFO org.apache.hadoop.yarn.server.resourcemanager.rmcontainer.RMContainerImpl: container_1376212503271_0006_01_000006 Container Transitioned from NEW to ALLOCATED
2013-08-11 09:32:07,351 INFO org.apache.hadoop.yarn.server.resourcemanager.RMAuditLogger: USER=ubuntu	OPERATION=AM Allocated Container	TARGET=SchedulerApp	RESULT=SUCCESS	APPID=application_1376212503271_0006	CONTAINERID=container_1376212503271_0006_01_000006
2013-08-11 09:32:07,351 INFO org.apache.hadoop.yarn.server.resourcemanager.scheduler.common.fica.FiCaSchedulerNode: Assigned container container_1376212503271_0006_01_000006 of capacity <memory:1024, vCores:1> on host hadoop-320-4:39920, which currently has 7 containers, <memory:8192, vCores:7> used and <memory:0, vCores:9> available
2013-08-11 09:32:07,352 INFO org.apache.hadoop.yarn.server.resourcemanager.scheduler.capacity.LeafQueue: assignedContainer application=application_1376212503271_0006 container=Container: [ContainerId: container_1376212503271_0006_01_000006, NodeId: hadoop-320-4:39920, NodeHttpAddress: hadoop-320-4:8042, Resource: <memory:1024, vCores:1>, Priority: 20, State: NEW, Token: null, Status: container_id {, app_attempt_id {, application_id {, id: 6, cluster_timestamp: 1376212503271, }, attemptId: 1, }, id: 6, }, state: C_NEW, ] containerId=container_1376212503271_0006_01_000006 queue=default: capacity=1.0, absoluteCapacity=1.0, usedResources=<memory:48128, vCores:42>usedCapacity=0.9791667, absoluteUsedCapacity=0.9791667, numApps=5, numContainers=42 usedCapacity=0.9791667 absoluteUsedCapacity=0.9791667 used=<memory:48128, vCores:42> cluster=<memory:49152, vCores:96>
2013-08-11 09:32:07,352 INFO org.apache.hadoop.yarn.server.resourcemanager.scheduler.capacity.ParentQueue: Re-sorting queues since queue: root.default stats: default: capacity=1.0, absoluteCapacity=1.0, usedResources=<memory:49152, vCores:43>usedCapacity=1.0, absoluteUsedCapacity=1.0, numApps=5, numContainers=43
2013-08-11 09:32:07,352 INFO org.apache.hadoop.yarn.server.resourcemanager.scheduler.capacity.ParentQueue: assignedContainer queue=root usedCapacity=1.0 absoluteUsedCapacity=1.0 used=<memory:49152, vCores:43> cluster=<memory:49152, vCores:96>
2013-08-11 09:32:07,365 INFO org.apache.hadoop.yarn.server.resourcemanager.rmcontainer.RMContainerImpl: container_1376212503271_0006_01_000004 Container Transitioned from ACQUIRED to RUNNING
2013-08-11 09:32:07,634 INFO org.apache.hadoop.yarn.server.resourcemanager.rmcontainer.RMContainerImpl: container_1376212503271_0006_01_000005 Container Transitioned from ALLOCATED to ACQUIRED
2013-08-11 09:32:07,635 INFO org.apache.hadoop.yarn.server.resourcemanager.rmcontainer.RMContainerImpl: container_1376212503271_0006_01_000006 Container Transitioned from ALLOCATED to ACQUIRED
2013-08-11 09:32:08,358 INFO org.apache.hadoop.yarn.server.resourcemanager.rmcontainer.RMContainerImpl: container_1376212503271_0006_01_000005 Container Transitioned from ACQUIRED to RUNNING
2013-08-11 09:32:08,358 INFO org.apache.hadoop.yarn.server.resourcemanager.rmcontainer.RMContainerImpl: container_1376212503271_0006_01_000006 Container Transitioned from ACQUIRED to RUNNING
2013-08-11 09:32:08,358 INFO org.apache.hadoop.yarn.server.resourcemanager.rmcontainer.RMContainerImpl: container_1376212503271_0007_01_000028 Container Transitioned from RUNNING to COMPLETED
2013-08-11 09:32:08,358 INFO org.apache.hadoop.yarn.server.resourcemanager.scheduler.common.fica.FiCaSchedulerApp: Completed container: container_1376212503271_0007_01_000028 in state: COMPLETED event:FINISHED
2013-08-11 09:32:08,358 INFO org.apache.hadoop.yarn.server.resourcemanager.RMAuditLogger: USER=ubuntu	OPERATION=AM Released Container	TARGET=SchedulerApp	RESULT=SUCCESS	APPID=application_1376212503271_0007	CONTAINERID=container_1376212503271_0007_01_000028
2013-08-11 09:32:08,359 INFO org.apache.hadoop.yarn.server.resourcemanager.scheduler.common.fica.FiCaSchedulerNode: Released container container_1376212503271_0007_01_000028 of capacity <memory:1024, vCores:1> on host hadoop-320-4:39920, which currently has 6 containers, <memory:7168, vCores:6> used and <memory:1024, vCores:10> available, release resources=true
2013-08-11 09:32:08,359 INFO org.apache.hadoop.yarn.server.resourcemanager.scheduler.capacity.LeafQueue: default used=<memory:48128, vCores:42> numContainers=42 user=ubuntu user-resources=<memory:48128, vCores:42>
2013-08-11 09:32:08,360 INFO org.apache.hadoop.yarn.server.resourcemanager.scheduler.capacity.LeafQueue: completedContainer container=Container: [ContainerId: container_1376212503271_0007_01_000028, NodeId: hadoop-320-4:39920, NodeHttpAddress: hadoop-320-4:8042, Resource: <memory:1024, vCores:1>, Priority: 20, State: NEW, Token: null, Status: container_id {, app_attempt_id {, application_id {, id: 7, cluster_timestamp: 1376212503271, }, attemptId: 1, }, id: 28, }, state: C_COMPLETE, diagnostics: "Container killed by the ApplicationMaster.\n\n", exit_status: 143, ] resource=<memory:1024, vCores:1> queue=default: capacity=1.0, absoluteCapacity=1.0, usedResources=<memory:48128, vCores:42>usedCapacity=0.9791667, absoluteUsedCapacity=0.9791667, numApps=5, numContainers=42 usedCapacity=0.9791667 absoluteUsedCapacity=0.9791667 used=<memory:48128, vCores:42> cluster=<memory:49152, vCores:96>
2013-08-11 09:32:08,360 INFO org.apache.hadoop.yarn.server.resourcemanager.scheduler.capacity.ParentQueue: completedContainer queue=root usedCapacity=0.9791667 absoluteUsedCapacity=0.9791667 used=<memory:48128, vCores:42> cluster=<memory:49152, vCores:96>
2013-08-11 09:32:08,360 INFO org.apache.hadoop.yarn.server.resourcemanager.scheduler.capacity.CapacityScheduler: Application appattempt_1376212503271_0007_000001 released container container_1376212503271_0007_01_000028 on node: host: hadoop-320-4:39920 #containers=6 available=1024 used=7168 with event: FINISHED
2013-08-11 09:32:08,361 INFO org.apache.hadoop.yarn.server.resourcemanager.rmcontainer.RMContainerImpl: container_1376212503271_0006_01_000007 Container Transitioned from NEW to ALLOCATED
2013-08-11 09:32:08,361 INFO org.apache.hadoop.yarn.server.resourcemanager.RMAuditLogger: USER=ubuntu	OPERATION=AM Allocated Container	TARGET=SchedulerApp	RESULT=SUCCESS	APPID=application_1376212503271_0006	CONTAINERID=container_1376212503271_0006_01_000007
2013-08-11 09:32:08,361 INFO org.apache.hadoop.yarn.server.resourcemanager.scheduler.common.fica.FiCaSchedulerNode: Assigned container container_1376212503271_0006_01_000007 of capacity <memory:1024, vCores:1> on host hadoop-320-4:39920, which currently has 7 containers, <memory:8192, vCores:7> used and <memory:0, vCores:9> available
2013-08-11 09:32:08,362 INFO org.apache.hadoop.yarn.server.resourcemanager.scheduler.capacity.LeafQueue: assignedContainer application=application_1376212503271_0006 container=Container: [ContainerId: container_1376212503271_0006_01_000007, NodeId: hadoop-320-4:39920, NodeHttpAddress: hadoop-320-4:8042, Resource: <memory:1024, vCores:1>, Priority: 20, State: NEW, Token: null, Status: container_id {, app_attempt_id {, application_id {, id: 6, cluster_timestamp: 1376212503271, }, attemptId: 1, }, id: 7, }, state: C_NEW, ] containerId=container_1376212503271_0006_01_000007 queue=default: capacity=1.0, absoluteCapacity=1.0, usedResources=<memory:48128, vCores:42>usedCapacity=0.9791667, absoluteUsedCapacity=0.9791667, numApps=5, numContainers=42 usedCapacity=0.9791667 absoluteUsedCapacity=0.9791667 used=<memory:48128, vCores:42> cluster=<memory:49152, vCores:96>
2013-08-11 09:32:08,362 INFO org.apache.hadoop.yarn.server.resourcemanager.scheduler.capacity.ParentQueue: Re-sorting queues since queue: root.default stats: default: capacity=1.0, absoluteCapacity=1.0, usedResources=<memory:49152, vCores:43>usedCapacity=1.0, absoluteUsedCapacity=1.0, numApps=5, numContainers=43
2013-08-11 09:32:08,362 INFO org.apache.hadoop.yarn.server.resourcemanager.scheduler.capacity.ParentQueue: assignedContainer queue=root usedCapacity=1.0 absoluteUsedCapacity=1.0 used=<memory:49152, vCores:43> cluster=<memory:49152, vCores:96>
2013-08-11 09:32:08,650 INFO org.apache.hadoop.yarn.server.resourcemanager.rmcontainer.RMContainerImpl: container_1376212503271_0006_01_000007 Container Transitioned from ALLOCATED to ACQUIRED
2013-08-11 09:32:08,656 INFO org.apache.hadoop.yarn.server.resourcemanager.rmcontainer.RMContainerImpl: container_1376212503271_0007_01_000004 Container Transitioned from RUNNING to COMPLETED
2013-08-11 09:32:08,656 INFO org.apache.hadoop.yarn.server.resourcemanager.scheduler.common.fica.FiCaSchedulerApp: Completed container: container_1376212503271_0007_01_000004 in state: COMPLETED event:FINISHED
2013-08-11 09:32:08,656 INFO org.apache.hadoop.yarn.server.resourcemanager.RMAuditLogger: USER=ubuntu	OPERATION=AM Released Container	TARGET=SchedulerApp	RESULT=SUCCESS	APPID=application_1376212503271_0007	CONTAINERID=container_1376212503271_0007_01_000004
2013-08-11 09:32:08,656 INFO org.apache.hadoop.yarn.server.resourcemanager.scheduler.common.fica.FiCaSchedulerNode: Released container container_1376212503271_0007_01_000004 of capacity <memory:1024, vCores:1> on host hadoop-320-3:47015, which currently has 6 containers, <memory:7168, vCores:6> used and <memory:1024, vCores:10> available, release resources=true
2013-08-11 09:32:08,656 INFO org.apache.hadoop.yarn.server.resourcemanager.scheduler.capacity.LeafQueue: default used=<memory:48128, vCores:42> numContainers=42 user=ubuntu user-resources=<memory:48128, vCores:42>
2013-08-11 09:32:08,657 INFO org.apache.hadoop.yarn.server.resourcemanager.scheduler.capacity.LeafQueue: completedContainer container=Container: [ContainerId: container_1376212503271_0007_01_000004, NodeId: hadoop-320-3:47015, NodeHttpAddress: hadoop-320-3:8042, Resource: <memory:1024, vCores:1>, Priority: 20, State: NEW, Token: null, Status: container_id {, app_attempt_id {, application_id {, id: 7, cluster_timestamp: 1376212503271, }, attemptId: 1, }, id: 4, }, state: C_COMPLETE, diagnostics: "Container killed by the ApplicationMaster.\n", exit_status: 0, ] resource=<memory:1024, vCores:1> queue=default: capacity=1.0, absoluteCapacity=1.0, usedResources=<memory:48128, vCores:42>usedCapacity=0.9791667, absoluteUsedCapacity=0.9791667, numApps=5, numContainers=42 usedCapacity=0.9791667 absoluteUsedCapacity=0.9791667 used=<memory:48128, vCores:42> cluster=<memory:49152, vCores:96>
2013-08-11 09:32:08,658 INFO org.apache.hadoop.yarn.server.resourcemanager.scheduler.capacity.ParentQueue: completedContainer queue=root usedCapacity=0.9791667 absoluteUsedCapacity=0.9791667 used=<memory:48128, vCores:42> cluster=<memory:49152, vCores:96>
2013-08-11 09:32:08,658 INFO org.apache.hadoop.yarn.server.resourcemanager.scheduler.capacity.CapacityScheduler: Application appattempt_1376212503271_0007_000001 released container container_1376212503271_0007_01_000004 on node: host: hadoop-320-3:47015 #containers=6 available=1024 used=7168 with event: FINISHED
2013-08-11 09:32:08,658 INFO org.apache.hadoop.yarn.server.resourcemanager.rmcontainer.RMContainerImpl: container_1376212503271_0006_01_000008 Container Transitioned from NEW to ALLOCATED
2013-08-11 09:32:08,659 INFO org.apache.hadoop.yarn.server.resourcemanager.RMAuditLogger: USER=ubuntu	OPERATION=AM Allocated Container	TARGET=SchedulerApp	RESULT=SUCCESS	APPID=application_1376212503271_0006	CONTAINERID=container_1376212503271_0006_01_000008
2013-08-11 09:32:08,659 INFO org.apache.hadoop.yarn.server.resourcemanager.scheduler.common.fica.FiCaSchedulerNode: Assigned container container_1376212503271_0006_01_000008 of capacity <memory:1024, vCores:1> on host hadoop-320-3:47015, which currently has 7 containers, <memory:8192, vCores:7> used and <memory:0, vCores:9> available
2013-08-11 09:32:08,660 INFO org.apache.hadoop.yarn.server.resourcemanager.scheduler.capacity.LeafQueue: assignedContainer application=application_1376212503271_0006 container=Container: [ContainerId: container_1376212503271_0006_01_000008, NodeId: hadoop-320-3:47015, NodeHttpAddress: hadoop-320-3:8042, Resource: <memory:1024, vCores:1>, Priority: 20, State: NEW, Token: null, Status: container_id {, app_attempt_id {, application_id {, id: 6, cluster_timestamp: 1376212503271, }, attemptId: 1, }, id: 8, }, state: C_NEW, ] containerId=container_1376212503271_0006_01_000008 queue=default: capacity=1.0, absoluteCapacity=1.0, usedResources=<memory:48128, vCores:42>usedCapacity=0.9791667, absoluteUsedCapacity=0.9791667, numApps=5, numContainers=42 usedCapacity=0.9791667 absoluteUsedCapacity=0.9791667 used=<memory:48128, vCores:42> cluster=<memory:49152, vCores:96>
2013-08-11 09:32:08,660 INFO org.apache.hadoop.yarn.server.resourcemanager.scheduler.capacity.ParentQueue: Re-sorting queues since queue: root.default stats: default: capacity=1.0, absoluteCapacity=1.0, usedResources=<memory:49152, vCores:43>usedCapacity=1.0, absoluteUsedCapacity=1.0, numApps=5, numContainers=43
2013-08-11 09:32:08,660 INFO org.apache.hadoop.yarn.server.resourcemanager.scheduler.capacity.ParentQueue: assignedContainer queue=root usedCapacity=1.0 absoluteUsedCapacity=1.0 used=<memory:49152, vCores:43> cluster=<memory:49152, vCores:96>
2013-08-11 09:32:09,365 INFO org.apache.hadoop.yarn.server.resourcemanager.rmcontainer.RMContainerImpl: container_1376212503271_0006_01_000007 Container Transitioned from ACQUIRED to RUNNING
2013-08-11 09:32:09,660 INFO org.apache.hadoop.yarn.server.resourcemanager.rmcontainer.RMContainerImpl: container_1376212503271_0006_01_000008 Container Transitioned from ALLOCATED to ACQUIRED
2013-08-11 09:32:09,731 INFO org.apache.hadoop.yarn.server.resourcemanager.rmcontainer.RMContainerImpl: container_1376212503271_0006_01_000008 Container Transitioned from ACQUIRED to RUNNING
2013-08-11 09:32:09,731 INFO org.apache.hadoop.yarn.server.resourcemanager.rmcontainer.RMContainerImpl: container_1376212503271_0007_01_000003 Container Transitioned from RUNNING to COMPLETED
2013-08-11 09:32:09,732 INFO org.apache.hadoop.yarn.server.resourcemanager.scheduler.common.fica.FiCaSchedulerApp: Completed container: container_1376212503271_0007_01_000003 in state: COMPLETED event:FINISHED
2013-08-11 09:32:09,732 INFO org.apache.hadoop.yarn.server.resourcemanager.RMAuditLogger: USER=ubuntu	OPERATION=AM Released Container	TARGET=SchedulerApp	RESULT=SUCCESS	APPID=application_1376212503271_0007	CONTAINERID=container_1376212503271_0007_01_000003
2013-08-11 09:32:09,732 INFO org.apache.hadoop.yarn.server.resourcemanager.scheduler.common.fica.FiCaSchedulerNode: Released container container_1376212503271_0007_01_000003 of capacity <memory:1024, vCores:1> on host hadoop-320-3:47015, which currently has 6 containers, <memory:7168, vCores:6> used and <memory:1024, vCores:10> available, release resources=true
2013-08-11 09:32:09,732 INFO org.apache.hadoop.yarn.server.resourcemanager.scheduler.capacity.LeafQueue: default used=<memory:48128, vCores:42> numContainers=42 user=ubuntu user-resources=<memory:48128, vCores:42>
2013-08-11 09:32:09,733 INFO org.apache.hadoop.yarn.server.resourcemanager.scheduler.capacity.LeafQueue: completedContainer container=Container: [ContainerId: container_1376212503271_0007_01_000003, NodeId: hadoop-320-3:47015, NodeHttpAddress: hadoop-320-3:8042, Resource: <memory:1024, vCores:1>, Priority: 20, State: NEW, Token: null, Status: container_id {, app_attempt_id {, application_id {, id: 7, cluster_timestamp: 1376212503271, }, attemptId: 1, }, id: 3, }, state: C_COMPLETE, diagnostics: "Container killed by the ApplicationMaster.\n", exit_status: 0, ] resource=<memory:1024, vCores:1> queue=default: capacity=1.0, absoluteCapacity=1.0, usedResources=<memory:48128, vCores:42>usedCapacity=0.9791667, absoluteUsedCapacity=0.9791667, numApps=5, numContainers=42 usedCapacity=0.9791667 absoluteUsedCapacity=0.9791667 used=<memory:48128, vCores:42> cluster=<memory:49152, vCores:96>
2013-08-11 09:32:09,733 INFO org.apache.hadoop.yarn.server.resourcemanager.scheduler.capacity.ParentQueue: completedContainer queue=root usedCapacity=0.9791667 absoluteUsedCapacity=0.9791667 used=<memory:48128, vCores:42> cluster=<memory:49152, vCores:96>
2013-08-11 09:32:09,733 INFO org.apache.hadoop.yarn.server.resourcemanager.scheduler.capacity.CapacityScheduler: Application appattempt_1376212503271_0007_000001 released container container_1376212503271_0007_01_000003 on node: host: hadoop-320-3:47015 #containers=6 available=1024 used=7168 with event: FINISHED
2013-08-11 09:32:09,734 INFO org.apache.hadoop.yarn.server.resourcemanager.rmcontainer.RMContainerImpl: container_1376212503271_0007_01_000007 Container Transitioned from RUNNING to COMPLETED
2013-08-11 09:32:09,734 INFO org.apache.hadoop.yarn.server.resourcemanager.scheduler.common.fica.FiCaSchedulerApp: Completed container: container_1376212503271_0007_01_000007 in state: COMPLETED event:FINISHED
2013-08-11 09:32:09,734 INFO org.apache.hadoop.yarn.server.resourcemanager.RMAuditLogger: USER=ubuntu	OPERATION=AM Released Container	TARGET=SchedulerApp	RESULT=SUCCESS	APPID=application_1376212503271_0007	CONTAINERID=container_1376212503271_0007_01_000007
2013-08-11 09:32:09,734 INFO org.apache.hadoop.yarn.server.resourcemanager.scheduler.common.fica.FiCaSchedulerNode: Released container container_1376212503271_0007_01_000007 of capacity <memory:1024, vCores:1> on host hadoop-320-3:47015, which currently has 5 containers, <memory:6144, vCores:5> used and <memory:2048, vCores:11> available, release resources=true
2013-08-11 09:32:09,734 INFO org.apache.hadoop.yarn.server.resourcemanager.scheduler.capacity.LeafQueue: default used=<memory:47104, vCores:41> numContainers=41 user=ubuntu user-resources=<memory:47104, vCores:41>
2013-08-11 09:32:09,738 INFO org.apache.hadoop.yarn.server.resourcemanager.scheduler.capacity.LeafQueue: completedContainer container=Container: [ContainerId: container_1376212503271_0007_01_000007, NodeId: hadoop-320-3:47015, NodeHttpAddress: hadoop-320-3:8042, Resource: <memory:1024, vCores:1>, Priority: 20, State: NEW, Token: null, Status: container_id {, app_attempt_id {, application_id {, id: 7, cluster_timestamp: 1376212503271, }, attemptId: 1, }, id: 7, }, state: C_COMPLETE, diagnostics: "Container killed by the ApplicationMaster.\n\n", exit_status: 143, ] resource=<memory:1024, vCores:1> queue=default: capacity=1.0, absoluteCapacity=1.0, usedResources=<memory:47104, vCores:41>usedCapacity=0.9583333, absoluteUsedCapacity=0.9583333, numApps=5, numContainers=41 usedCapacity=0.9583333 absoluteUsedCapacity=0.9583333 used=<memory:47104, vCores:41> cluster=<memory:49152, vCores:96>
2013-08-11 09:32:09,738 INFO org.apache.hadoop.yarn.server.resourcemanager.scheduler.capacity.ParentQueue: completedContainer queue=root usedCapacity=0.9583333 absoluteUsedCapacity=0.9583333 used=<memory:47104, vCores:41> cluster=<memory:49152, vCores:96>
2013-08-11 09:32:09,738 INFO org.apache.hadoop.yarn.server.resourcemanager.scheduler.capacity.CapacityScheduler: Application appattempt_1376212503271_0007_000001 released container container_1376212503271_0007_01_000007 on node: host: hadoop-320-3:47015 #containers=5 available=2048 used=6144 with event: FINISHED
2013-08-11 09:32:09,740 INFO org.apache.hadoop.yarn.server.resourcemanager.rmcontainer.RMContainerImpl: container_1376212503271_0006_01_000009 Container Transitioned from NEW to ALLOCATED
2013-08-11 09:32:09,740 INFO org.apache.hadoop.yarn.server.resourcemanager.RMAuditLogger: USER=ubuntu	OPERATION=AM Allocated Container	TARGET=SchedulerApp	RESULT=SUCCESS	APPID=application_1376212503271_0006	CONTAINERID=container_1376212503271_0006_01_000009
2013-08-11 09:32:09,740 INFO org.apache.hadoop.yarn.server.resourcemanager.scheduler.common.fica.FiCaSchedulerNode: Assigned container container_1376212503271_0006_01_000009 of capacity <memory:1024, vCores:1> on host hadoop-320-3:47015, which currently has 6 containers, <memory:7168, vCores:6> used and <memory:1024, vCores:10> available
2013-08-11 09:32:09,741 INFO org.apache.hadoop.yarn.server.resourcemanager.scheduler.capacity.LeafQueue: assignedContainer application=application_1376212503271_0006 container=Container: [ContainerId: container_1376212503271_0006_01_000009, NodeId: hadoop-320-3:47015, NodeHttpAddress: hadoop-320-3:8042, Resource: <memory:1024, vCores:1>, Priority: 20, State: NEW, Token: null, Status: container_id {, app_attempt_id {, application_id {, id: 6, cluster_timestamp: 1376212503271, }, attemptId: 1, }, id: 9, }, state: C_NEW, ] containerId=container_1376212503271_0006_01_000009 queue=default: capacity=1.0, absoluteCapacity=1.0, usedResources=<memory:47104, vCores:41>usedCapacity=0.9583333, absoluteUsedCapacity=0.9583333, numApps=5, numContainers=41 usedCapacity=0.9583333 absoluteUsedCapacity=0.9583333 used=<memory:47104, vCores:41> cluster=<memory:49152, vCores:96>
2013-08-11 09:32:09,741 INFO org.apache.hadoop.yarn.server.resourcemanager.scheduler.capacity.ParentQueue: Re-sorting queues since queue: root.default stats: default: capacity=1.0, absoluteCapacity=1.0, usedResources=<memory:48128, vCores:42>usedCapacity=0.9791667, absoluteUsedCapacity=0.9791667, numApps=5, numContainers=42
2013-08-11 09:32:09,742 INFO org.apache.hadoop.yarn.server.resourcemanager.scheduler.capacity.ParentQueue: assignedContainer queue=root usedCapacity=0.9791667 absoluteUsedCapacity=0.9791667 used=<memory:48128, vCores:42> cluster=<memory:49152, vCores:96>
2013-08-11 09:32:09,742 INFO org.apache.hadoop.yarn.server.resourcemanager.rmcontainer.RMContainerImpl: container_1376212503271_0006_01_000010 Container Transitioned from NEW to ALLOCATED
2013-08-11 09:32:09,742 INFO org.apache.hadoop.yarn.server.resourcemanager.RMAuditLogger: USER=ubuntu	OPERATION=AM Allocated Container	TARGET=SchedulerApp	RESULT=SUCCESS	APPID=application_1376212503271_0006	CONTAINERID=container_1376212503271_0006_01_000010
2013-08-11 09:32:09,742 INFO org.apache.hadoop.yarn.server.resourcemanager.scheduler.common.fica.FiCaSchedulerNode: Assigned container container_1376212503271_0006_01_000010 of capacity <memory:1024, vCores:1> on host hadoop-320-3:47015, which currently has 7 containers, <memory:8192, vCores:7> used and <memory:0, vCores:9> available
2013-08-11 09:32:09,743 INFO org.apache.hadoop.yarn.server.resourcemanager.scheduler.capacity.LeafQueue: assignedContainer application=application_1376212503271_0006 container=Container: [ContainerId: container_1376212503271_0006_01_000010, NodeId: hadoop-320-3:47015, NodeHttpAddress: hadoop-320-3:8042, Resource: <memory:1024, vCores:1>, Priority: 20, State: NEW, Token: null, Status: container_id {, app_attempt_id {, application_id {, id: 6, cluster_timestamp: 1376212503271, }, attemptId: 1, }, id: 10, }, state: C_NEW, ] containerId=container_1376212503271_0006_01_000010 queue=default: capacity=1.0, absoluteCapacity=1.0, usedResources=<memory:48128, vCores:42>usedCapacity=0.9791667, absoluteUsedCapacity=0.9791667, numApps=5, numContainers=42 usedCapacity=0.9791667 absoluteUsedCapacity=0.9791667 used=<memory:48128, vCores:42> cluster=<memory:49152, vCores:96>
2013-08-11 09:32:09,744 INFO org.apache.hadoop.yarn.server.resourcemanager.scheduler.capacity.ParentQueue: Re-sorting queues since queue: root.default stats: default: capacity=1.0, absoluteCapacity=1.0, usedResources=<memory:49152, vCores:43>usedCapacity=1.0, absoluteUsedCapacity=1.0, numApps=5, numContainers=43
2013-08-11 09:32:09,744 INFO org.apache.hadoop.yarn.server.resourcemanager.scheduler.capacity.ParentQueue: assignedContainer queue=root usedCapacity=1.0 absoluteUsedCapacity=1.0 used=<memory:49152, vCores:43> cluster=<memory:49152, vCores:96>
2013-08-11 09:32:10,284 INFO org.apache.hadoop.yarn.server.resourcemanager.rmcontainer.RMContainerImpl: container_1376212503271_0007_01_000034 Container Transitioned from RUNNING to COMPLETED
2013-08-11 09:32:10,284 INFO org.apache.hadoop.yarn.server.resourcemanager.scheduler.common.fica.FiCaSchedulerApp: Completed container: container_1376212503271_0007_01_000034 in state: COMPLETED event:FINISHED
2013-08-11 09:32:10,284 INFO org.apache.hadoop.yarn.server.resourcemanager.RMAuditLogger: USER=ubuntu	OPERATION=AM Released Container	TARGET=SchedulerApp	RESULT=SUCCESS	APPID=application_1376212503271_0007	CONTAINERID=container_1376212503271_0007_01_000034
2013-08-11 09:32:10,284 INFO org.apache.hadoop.yarn.server.resourcemanager.scheduler.common.fica.FiCaSchedulerNode: Released container container_1376212503271_0007_01_000034 of capacity <memory:1024, vCores:1> on host hadoop-320-5:36272, which currently has 6 containers, <memory:7168, vCores:6> used and <memory:1024, vCores:10> available, release resources=true
2013-08-11 09:32:10,285 INFO org.apache.hadoop.yarn.server.resourcemanager.scheduler.capacity.LeafQueue: default used=<memory:48128, vCores:42> numContainers=42 user=ubuntu user-resources=<memory:48128, vCores:42>
2013-08-11 09:32:10,286 INFO org.apache.hadoop.yarn.server.resourcemanager.scheduler.capacity.LeafQueue: completedContainer container=Container: [ContainerId: container_1376212503271_0007_01_000034, NodeId: hadoop-320-5:36272, NodeHttpAddress: hadoop-320-5:8042, Resource: <memory:1024, vCores:1>, Priority: 20, State: NEW, Token: null, Status: container_id {, app_attempt_id {, application_id {, id: 7, cluster_timestamp: 1376212503271, }, attemptId: 1, }, id: 34, }, state: C_COMPLETE, diagnostics: "Container killed by the ApplicationMaster.\n\n", exit_status: 143, ] resource=<memory:1024, vCores:1> queue=default: capacity=1.0, absoluteCapacity=1.0, usedResources=<memory:48128, vCores:42>usedCapacity=0.9791667, absoluteUsedCapacity=0.9791667, numApps=5, numContainers=42 usedCapacity=0.9791667 absoluteUsedCapacity=0.9791667 used=<memory:48128, vCores:42> cluster=<memory:49152, vCores:96>
2013-08-11 09:32:10,286 INFO org.apache.hadoop.yarn.server.resourcemanager.scheduler.capacity.ParentQueue: completedContainer queue=root usedCapacity=0.9791667 absoluteUsedCapacity=0.9791667 used=<memory:48128, vCores:42> cluster=<memory:49152, vCores:96>
2013-08-11 09:32:10,286 INFO org.apache.hadoop.yarn.server.resourcemanager.scheduler.capacity.CapacityScheduler: Application appattempt_1376212503271_0007_000001 released container container_1376212503271_0007_01_000034 on node: host: hadoop-320-5:36272 #containers=6 available=1024 used=7168 with event: FINISHED
2013-08-11 09:32:10,287 INFO org.apache.hadoop.yarn.server.resourcemanager.rmcontainer.RMContainerImpl: container_1376212503271_0006_01_000011 Container Transitioned from NEW to ALLOCATED
2013-08-11 09:32:10,287 INFO org.apache.hadoop.yarn.server.resourcemanager.RMAuditLogger: USER=ubuntu	OPERATION=AM Allocated Container	TARGET=SchedulerApp	RESULT=SUCCESS	APPID=application_1376212503271_0006	CONTAINERID=container_1376212503271_0006_01_000011
2013-08-11 09:32:10,287 INFO org.apache.hadoop.yarn.server.resourcemanager.scheduler.common.fica.FiCaSchedulerNode: Assigned container container_1376212503271_0006_01_000011 of capacity <memory:1024, vCores:1> on host hadoop-320-5:36272, which currently has 7 containers, <memory:8192, vCores:7> used and <memory:0, vCores:9> available
2013-08-11 09:32:10,288 INFO org.apache.hadoop.yarn.server.resourcemanager.scheduler.capacity.LeafQueue: assignedContainer application=application_1376212503271_0006 container=Container: [ContainerId: container_1376212503271_0006_01_000011, NodeId: hadoop-320-5:36272, NodeHttpAddress: hadoop-320-5:8042, Resource: <memory:1024, vCores:1>, Priority: 20, State: NEW, Token: null, Status: container_id {, app_attempt_id {, application_id {, id: 6, cluster_timestamp: 1376212503271, }, attemptId: 1, }, id: 11, }, state: C_NEW, ] containerId=container_1376212503271_0006_01_000011 queue=default: capacity=1.0, absoluteCapacity=1.0, usedResources=<memory:48128, vCores:42>usedCapacity=0.9791667, absoluteUsedCapacity=0.9791667, numApps=5, numContainers=42 usedCapacity=0.9791667 absoluteUsedCapacity=0.9791667 used=<memory:48128, vCores:42> cluster=<memory:49152, vCores:96>
2013-08-11 09:32:10,288 INFO org.apache.hadoop.yarn.server.resourcemanager.scheduler.capacity.ParentQueue: Re-sorting queues since queue: root.default stats: default: capacity=1.0, absoluteCapacity=1.0, usedResources=<memory:49152, vCores:43>usedCapacity=1.0, absoluteUsedCapacity=1.0, numApps=5, numContainers=43
2013-08-11 09:32:10,289 INFO org.apache.hadoop.yarn.server.resourcemanager.scheduler.capacity.ParentQueue: assignedContainer queue=root usedCapacity=1.0 absoluteUsedCapacity=1.0 used=<memory:49152, vCores:43> cluster=<memory:49152, vCores:96>
2013-08-11 09:32:10,400 INFO org.apache.hadoop.yarn.server.resourcemanager.rmcontainer.RMContainerImpl: container_1376212503271_0007_01_000036 Container Transitioned from RUNNING to COMPLETED
2013-08-11 09:32:10,400 INFO org.apache.hadoop.yarn.server.resourcemanager.scheduler.common.fica.FiCaSchedulerApp: Completed container: container_1376212503271_0007_01_000036 in state: COMPLETED event:FINISHED
2013-08-11 09:32:10,401 INFO org.apache.hadoop.yarn.server.resourcemanager.RMAuditLogger: USER=ubuntu	OPERATION=AM Released Container	TARGET=SchedulerApp	RESULT=SUCCESS	APPID=application_1376212503271_0007	CONTAINERID=container_1376212503271_0007_01_000036
2013-08-11 09:32:10,401 INFO org.apache.hadoop.yarn.server.resourcemanager.scheduler.common.fica.FiCaSchedulerNode: Released container container_1376212503271_0007_01_000036 of capacity <memory:1024, vCores:1> on host hadoop-320-5:36272, which currently has 6 containers, <memory:7168, vCores:6> used and <memory:1024, vCores:10> available, release resources=true
2013-08-11 09:32:10,401 INFO org.apache.hadoop.yarn.server.resourcemanager.scheduler.capacity.LeafQueue: default used=<memory:48128, vCores:42> numContainers=42 user=ubuntu user-resources=<memory:48128, vCores:42>
2013-08-11 09:32:10,402 INFO org.apache.hadoop.yarn.server.resourcemanager.scheduler.capacity.LeafQueue: completedContainer container=Container: [ContainerId: container_1376212503271_0007_01_000036, NodeId: hadoop-320-5:36272, NodeHttpAddress: hadoop-320-5:8042, Resource: <memory:1024, vCores:1>, Priority: 20, State: NEW, Token: null, Status: container_id {, app_attempt_id {, application_id {, id: 7, cluster_timestamp: 1376212503271, }, attemptId: 1, }, id: 36, }, state: C_COMPLETE, diagnostics: "Container killed by the ApplicationMaster.\n\n", exit_status: 143, ] resource=<memory:1024, vCores:1> queue=default: capacity=1.0, absoluteCapacity=1.0, usedResources=<memory:48128, vCores:42>usedCapacity=0.9791667, absoluteUsedCapacity=0.9791667, numApps=5, numContainers=42 usedCapacity=0.9791667 absoluteUsedCapacity=0.9791667 used=<memory:48128, vCores:42> cluster=<memory:49152, vCores:96>
2013-08-11 09:32:10,402 INFO org.apache.hadoop.yarn.server.resourcemanager.scheduler.capacity.ParentQueue: completedContainer queue=root usedCapacity=0.9791667 absoluteUsedCapacity=0.9791667 used=<memory:48128, vCores:42> cluster=<memory:49152, vCores:96>
2013-08-11 09:32:10,402 INFO org.apache.hadoop.yarn.server.resourcemanager.scheduler.capacity.CapacityScheduler: Application appattempt_1376212503271_0007_000001 released container container_1376212503271_0007_01_000036 on node: host: hadoop-320-5:36272 #containers=6 available=1024 used=7168 with event: FINISHED
2013-08-11 09:32:10,403 INFO org.apache.hadoop.yarn.server.resourcemanager.rmcontainer.RMContainerImpl: container_1376212503271_0006_01_000012 Container Transitioned from NEW to ALLOCATED
2013-08-11 09:32:10,403 INFO org.apache.hadoop.yarn.server.resourcemanager.RMAuditLogger: USER=ubuntu	OPERATION=AM Allocated Container	TARGET=SchedulerApp	RESULT=SUCCESS	APPID=application_1376212503271_0006	CONTAINERID=container_1376212503271_0006_01_000012
2013-08-11 09:32:10,403 INFO org.apache.hadoop.yarn.server.resourcemanager.scheduler.common.fica.FiCaSchedulerNode: Assigned container container_1376212503271_0006_01_000012 of capacity <memory:1024, vCores:1> on host hadoop-320-5:36272, which currently has 7 containers, <memory:8192, vCores:7> used and <memory:0, vCores:9> available
2013-08-11 09:32:10,404 INFO org.apache.hadoop.yarn.server.resourcemanager.scheduler.capacity.LeafQueue: assignedContainer application=application_1376212503271_0006 container=Container: [ContainerId: container_1376212503271_0006_01_000012, NodeId: hadoop-320-5:36272, NodeHttpAddress: hadoop-320-5:8042, Resource: <memory:1024, vCores:1>, Priority: 20, State: NEW, Token: null, Status: container_id {, app_attempt_id {, application_id {, id: 6, cluster_timestamp: 1376212503271, }, attemptId: 1, }, id: 12, }, state: C_NEW, ] containerId=container_1376212503271_0006_01_000012 queue=default: capacity=1.0, absoluteCapacity=1.0, usedResources=<memory:48128, vCores:42>usedCapacity=0.9791667, absoluteUsedCapacity=0.9791667, numApps=5, numContainers=42 usedCapacity=0.9791667 absoluteUsedCapacity=0.9791667 used=<memory:48128, vCores:42> cluster=<memory:49152, vCores:96>
2013-08-11 09:32:10,405 INFO org.apache.hadoop.yarn.server.resourcemanager.scheduler.capacity.ParentQueue: Re-sorting queues since queue: root.default stats: default: capacity=1.0, absoluteCapacity=1.0, usedResources=<memory:49152, vCores:43>usedCapacity=1.0, absoluteUsedCapacity=1.0, numApps=5, numContainers=43
2013-08-11 09:32:10,405 INFO org.apache.hadoop.yarn.server.resourcemanager.scheduler.capacity.ParentQueue: assignedContainer queue=root usedCapacity=1.0 absoluteUsedCapacity=1.0 used=<memory:49152, vCores:43> cluster=<memory:49152, vCores:96>
2013-08-11 09:32:10,675 INFO org.apache.hadoop.yarn.server.resourcemanager.rmcontainer.RMContainerImpl: container_1376212503271_0006_01_000009 Container Transitioned from ALLOCATED to ACQUIRED
2013-08-11 09:32:10,676 INFO org.apache.hadoop.yarn.server.resourcemanager.rmcontainer.RMContainerImpl: container_1376212503271_0006_01_000010 Container Transitioned from ALLOCATED to ACQUIRED
2013-08-11 09:32:10,676 INFO org.apache.hadoop.yarn.server.resourcemanager.rmcontainer.RMContainerImpl: container_1376212503271_0006_01_000011 Container Transitioned from ALLOCATED to ACQUIRED
2013-08-11 09:32:10,676 INFO org.apache.hadoop.yarn.server.resourcemanager.rmcontainer.RMContainerImpl: container_1376212503271_0006_01_000012 Container Transitioned from ALLOCATED to ACQUIRED
2013-08-11 09:32:10,744 INFO org.apache.hadoop.yarn.server.resourcemanager.rmcontainer.RMContainerImpl: container_1376212503271_0006_01_000009 Container Transitioned from ACQUIRED to RUNNING
2013-08-11 09:32:10,745 INFO org.apache.hadoop.yarn.server.resourcemanager.rmcontainer.RMContainerImpl: container_1376212503271_0006_01_000010 Container Transitioned from ACQUIRED to RUNNING
2013-08-11 09:32:10,813 INFO org.apache.hadoop.yarn.server.resourcemanager.rmcontainer.RMContainerImpl: container_1376212503271_0006_01_000011 Container Transitioned from ACQUIRED to RUNNING
2013-08-11 09:32:10,813 INFO org.apache.hadoop.yarn.server.resourcemanager.rmcontainer.RMContainerImpl: container_1376212503271_0006_01_000012 Container Transitioned from ACQUIRED to RUNNING
2013-08-11 09:32:10,813 INFO org.apache.hadoop.yarn.server.resourcemanager.rmcontainer.RMContainerImpl: container_1376212503271_0007_01_000039 Container Transitioned from RUNNING to COMPLETED
2013-08-11 09:32:10,813 INFO org.apache.hadoop.yarn.server.resourcemanager.scheduler.common.fica.FiCaSchedulerApp: Completed container: container_1376212503271_0007_01_000039 in state: COMPLETED event:FINISHED
2013-08-11 09:32:10,814 INFO org.apache.hadoop.yarn.server.resourcemanager.RMAuditLogger: USER=ubuntu	OPERATION=AM Released Container	TARGET=SchedulerApp	RESULT=SUCCESS	APPID=application_1376212503271_0007	CONTAINERID=container_1376212503271_0007_01_000039
2013-08-11 09:32:10,814 INFO org.apache.hadoop.yarn.server.resourcemanager.scheduler.common.fica.FiCaSchedulerNode: Released container container_1376212503271_0007_01_000039 of capacity <memory:1024, vCores:1> on host hadoop-320-5:36272, which currently has 6 containers, <memory:7168, vCores:6> used and <memory:1024, vCores:10> available, release resources=true
2013-08-11 09:32:10,814 INFO org.apache.hadoop.yarn.server.resourcemanager.scheduler.capacity.LeafQueue: default used=<memory:48128, vCores:42> numContainers=42 user=ubuntu user-resources=<memory:48128, vCores:42>
2013-08-11 09:32:10,815 INFO org.apache.hadoop.yarn.server.resourcemanager.scheduler.capacity.LeafQueue: completedContainer container=Container: [ContainerId: container_1376212503271_0007_01_000039, NodeId: hadoop-320-5:36272, NodeHttpAddress: hadoop-320-5:8042, Resource: <memory:1024, vCores:1>, Priority: 20, State: NEW, Token: null, Status: container_id {, app_attempt_id {, application_id {, id: 7, cluster_timestamp: 1376212503271, }, attemptId: 1, }, id: 39, }, state: C_COMPLETE, diagnostics: "Container killed by the ApplicationMaster.\n\n", exit_status: 143, ] resource=<memory:1024, vCores:1> queue=default: capacity=1.0, absoluteCapacity=1.0, usedResources=<memory:48128, vCores:42>usedCapacity=0.9791667, absoluteUsedCapacity=0.9791667, numApps=5, numContainers=42 usedCapacity=0.9791667 absoluteUsedCapacity=0.9791667 used=<memory:48128, vCores:42> cluster=<memory:49152, vCores:96>
2013-08-11 09:32:10,815 INFO org.apache.hadoop.yarn.server.resourcemanager.scheduler.capacity.ParentQueue: completedContainer queue=root usedCapacity=0.9791667 absoluteUsedCapacity=0.9791667 used=<memory:48128, vCores:42> cluster=<memory:49152, vCores:96>
2013-08-11 09:32:10,816 INFO org.apache.hadoop.yarn.server.resourcemanager.scheduler.capacity.CapacityScheduler: Application appattempt_1376212503271_0007_000001 released container container_1376212503271_0007_01_000039 on node: host: hadoop-320-5:36272 #containers=6 available=1024 used=7168 with event: FINISHED
2013-08-11 09:32:10,816 INFO org.apache.hadoop.yarn.server.resourcemanager.rmcontainer.RMContainerImpl: container_1376212503271_0006_01_000013 Container Transitioned from NEW to ALLOCATED
2013-08-11 09:32:10,816 INFO org.apache.hadoop.yarn.server.resourcemanager.RMAuditLogger: USER=ubuntu	OPERATION=AM Allocated Container	TARGET=SchedulerApp	RESULT=SUCCESS	APPID=application_1376212503271_0006	CONTAINERID=container_1376212503271_0006_01_000013
2013-08-11 09:32:10,817 INFO org.apache.hadoop.yarn.server.resourcemanager.scheduler.common.fica.FiCaSchedulerNode: Assigned container container_1376212503271_0006_01_000013 of capacity <memory:1024, vCores:1> on host hadoop-320-5:36272, which currently has 7 containers, <memory:8192, vCores:7> used and <memory:0, vCores:9> available
2013-08-11 09:32:10,817 INFO org.apache.hadoop.yarn.server.resourcemanager.scheduler.capacity.LeafQueue: assignedContainer application=application_1376212503271_0006 container=Container: [ContainerId: container_1376212503271_0006_01_000013, NodeId: hadoop-320-5:36272, NodeHttpAddress: hadoop-320-5:8042, Resource: <memory:1024, vCores:1>, Priority: 20, State: NEW, Token: null, Status: container_id {, app_attempt_id {, application_id {, id: 6, cluster_timestamp: 1376212503271, }, attemptId: 1, }, id: 13, }, state: C_NEW, ] containerId=container_1376212503271_0006_01_000013 queue=default: capacity=1.0, absoluteCapacity=1.0, usedResources=<memory:48128, vCores:42>usedCapacity=0.9791667, absoluteUsedCapacity=0.9791667, numApps=5, numContainers=42 usedCapacity=0.9791667 absoluteUsedCapacity=0.9791667 used=<memory:48128, vCores:42> cluster=<memory:49152, vCores:96>
2013-08-11 09:32:10,819 INFO org.apache.hadoop.yarn.server.resourcemanager.scheduler.capacity.ParentQueue: Re-sorting queues since queue: root.default stats: default: capacity=1.0, absoluteCapacity=1.0, usedResources=<memory:49152, vCores:43>usedCapacity=1.0, absoluteUsedCapacity=1.0, numApps=5, numContainers=43
2013-08-11 09:32:10,819 INFO org.apache.hadoop.yarn.server.resourcemanager.scheduler.capacity.ParentQueue: assignedContainer queue=root usedCapacity=1.0 absoluteUsedCapacity=1.0 used=<memory:49152, vCores:43> cluster=<memory:49152, vCores:96>
2013-08-11 09:32:11,705 INFO org.apache.hadoop.yarn.server.resourcemanager.rmcontainer.RMContainerImpl: container_1376212503271_0006_01_000013 Container Transitioned from ALLOCATED to ACQUIRED
2013-08-11 09:32:11,828 INFO org.apache.hadoop.yarn.server.resourcemanager.rmcontainer.RMContainerImpl: container_1376212503271_0006_01_000013 Container Transitioned from ACQUIRED to RUNNING
2013-08-11 09:32:11,829 INFO org.apache.hadoop.yarn.server.resourcemanager.rmcontainer.RMContainerImpl: container_1376212503271_0007_01_000038 Container Transitioned from RUNNING to COMPLETED
2013-08-11 09:32:11,829 INFO org.apache.hadoop.yarn.server.resourcemanager.scheduler.common.fica.FiCaSchedulerApp: Completed container: container_1376212503271_0007_01_000038 in state: COMPLETED event:FINISHED
2013-08-11 09:32:11,829 INFO org.apache.hadoop.yarn.server.resourcemanager.RMAuditLogger: USER=ubuntu	OPERATION=AM Released Container	TARGET=SchedulerApp	RESULT=SUCCESS	APPID=application_1376212503271_0007	CONTAINERID=container_1376212503271_0007_01_000038
2013-08-11 09:32:11,829 INFO org.apache.hadoop.yarn.server.resourcemanager.scheduler.common.fica.FiCaSchedulerNode: Released container container_1376212503271_0007_01_000038 of capacity <memory:1024, vCores:1> on host hadoop-320-5:36272, which currently has 6 containers, <memory:7168, vCores:6> used and <memory:1024, vCores:10> available, release resources=true
2013-08-11 09:32:11,829 INFO org.apache.hadoop.yarn.server.resourcemanager.scheduler.capacity.LeafQueue: default used=<memory:48128, vCores:42> numContainers=42 user=ubuntu user-resources=<memory:48128, vCores:42>
2013-08-11 09:32:11,831 INFO org.apache.hadoop.yarn.server.resourcemanager.scheduler.capacity.LeafQueue: completedContainer container=Container: [ContainerId: container_1376212503271_0007_01_000038, NodeId: hadoop-320-5:36272, NodeHttpAddress: hadoop-320-5:8042, Resource: <memory:1024, vCores:1>, Priority: 20, State: NEW, Token: null, Status: container_id {, app_attempt_id {, application_id {, id: 7, cluster_timestamp: 1376212503271, }, attemptId: 1, }, id: 38, }, state: C_COMPLETE, diagnostics: "Container killed by the ApplicationMaster.\n\n", exit_status: 143, ] resource=<memory:1024, vCores:1> queue=default: capacity=1.0, absoluteCapacity=1.0, usedResources=<memory:48128, vCores:42>usedCapacity=0.9791667, absoluteUsedCapacity=0.9791667, numApps=5, numContainers=42 usedCapacity=0.9791667 absoluteUsedCapacity=0.9791667 used=<memory:48128, vCores:42> cluster=<memory:49152, vCores:96>
2013-08-11 09:32:11,831 INFO org.apache.hadoop.yarn.server.resourcemanager.scheduler.capacity.ParentQueue: completedContainer queue=root usedCapacity=0.9791667 absoluteUsedCapacity=0.9791667 used=<memory:48128, vCores:42> cluster=<memory:49152, vCores:96>
2013-08-11 09:32:11,831 INFO org.apache.hadoop.yarn.server.resourcemanager.scheduler.capacity.CapacityScheduler: Application appattempt_1376212503271_0007_000001 released container container_1376212503271_0007_01_000038 on node: host: hadoop-320-5:36272 #containers=6 available=1024 used=7168 with event: FINISHED
2013-08-11 09:32:11,831 INFO org.apache.hadoop.yarn.server.resourcemanager.rmcontainer.RMContainerImpl: container_1376212503271_0006_01_000014 Container Transitioned from NEW to ALLOCATED
2013-08-11 09:32:11,832 INFO org.apache.hadoop.yarn.server.resourcemanager.RMAuditLogger: USER=ubuntu	OPERATION=AM Allocated Container	TARGET=SchedulerApp	RESULT=SUCCESS	APPID=application_1376212503271_0006	CONTAINERID=container_1376212503271_0006_01_000014
2013-08-11 09:32:11,832 INFO org.apache.hadoop.yarn.server.resourcemanager.scheduler.common.fica.FiCaSchedulerNode: Assigned container container_1376212503271_0006_01_000014 of capacity <memory:1024, vCores:1> on host hadoop-320-5:36272, which currently has 7 containers, <memory:8192, vCores:7> used and <memory:0, vCores:9> available
2013-08-11 09:32:11,833 INFO org.apache.hadoop.yarn.server.resourcemanager.scheduler.capacity.LeafQueue: assignedContainer application=application_1376212503271_0006 container=Container: [ContainerId: container_1376212503271_0006_01_000014, NodeId: hadoop-320-5:36272, NodeHttpAddress: hadoop-320-5:8042, Resource: <memory:1024, vCores:1>, Priority: 20, State: NEW, Token: null, Status: container_id {, app_attempt_id {, application_id {, id: 6, cluster_timestamp: 1376212503271, }, attemptId: 1, }, id: 14, }, state: C_NEW, ] containerId=container_1376212503271_0006_01_000014 queue=default: capacity=1.0, absoluteCapacity=1.0, usedResources=<memory:48128, vCores:42>usedCapacity=0.9791667, absoluteUsedCapacity=0.9791667, numApps=5, numContainers=42 usedCapacity=0.9791667 absoluteUsedCapacity=0.9791667 used=<memory:48128, vCores:42> cluster=<memory:49152, vCores:96>
2013-08-11 09:32:11,833 INFO org.apache.hadoop.yarn.server.resourcemanager.scheduler.capacity.ParentQueue: Re-sorting queues since queue: root.default stats: default: capacity=1.0, absoluteCapacity=1.0, usedResources=<memory:49152, vCores:43>usedCapacity=1.0, absoluteUsedCapacity=1.0, numApps=5, numContainers=43
2013-08-11 09:32:11,833 INFO org.apache.hadoop.yarn.server.resourcemanager.scheduler.capacity.ParentQueue: assignedContainer queue=root usedCapacity=1.0 absoluteUsedCapacity=1.0 used=<memory:49152, vCores:43> cluster=<memory:49152, vCores:96>
2013-08-11 09:32:12,715 INFO org.apache.hadoop.yarn.server.resourcemanager.rmcontainer.RMContainerImpl: container_1376212503271_0006_01_000014 Container Transitioned from ALLOCATED to ACQUIRED
2013-08-11 09:32:12,892 INFO org.apache.hadoop.yarn.server.resourcemanager.rmcontainer.RMContainerImpl: container_1376212503271_0006_01_000014 Container Transitioned from ACQUIRED to RUNNING
2013-08-11 09:32:13,261 INFO org.apache.hadoop.yarn.server.resourcemanager.rmcontainer.RMContainerImpl: container_1376212503271_0007_01_000027 Container Transitioned from RUNNING to COMPLETED
2013-08-11 09:32:13,262 INFO org.apache.hadoop.yarn.server.resourcemanager.scheduler.common.fica.FiCaSchedulerApp: Completed container: container_1376212503271_0007_01_000027 in state: COMPLETED event:FINISHED
2013-08-11 09:32:13,262 INFO org.apache.hadoop.yarn.server.resourcemanager.RMAuditLogger: USER=ubuntu	OPERATION=AM Released Container	TARGET=SchedulerApp	RESULT=SUCCESS	APPID=application_1376212503271_0007	CONTAINERID=container_1376212503271_0007_01_000027
2013-08-11 09:32:13,262 INFO org.apache.hadoop.yarn.server.resourcemanager.scheduler.common.fica.FiCaSchedulerNode: Released container container_1376212503271_0007_01_000027 of capacity <memory:1024, vCores:1> on host hadoop-320-2:53179, which currently has 6 containers, <memory:7168, vCores:6> used and <memory:1024, vCores:10> available, release resources=true
2013-08-11 09:32:13,262 INFO org.apache.hadoop.yarn.server.resourcemanager.scheduler.capacity.LeafQueue: default used=<memory:48128, vCores:42> numContainers=42 user=ubuntu user-resources=<memory:48128, vCores:42>
2013-08-11 09:32:13,264 INFO org.apache.hadoop.yarn.server.resourcemanager.scheduler.capacity.LeafQueue: completedContainer container=Container: [ContainerId: container_1376212503271_0007_01_000027, NodeId: hadoop-320-2:53179, NodeHttpAddress: hadoop-320-2:8042, Resource: <memory:1024, vCores:1>, Priority: 20, State: NEW, Token: null, Status: container_id {, app_attempt_id {, application_id {, id: 7, cluster_timestamp: 1376212503271, }, attemptId: 1, }, id: 27, }, state: C_COMPLETE, diagnostics: "Container killed by the ApplicationMaster.\n", exit_status: 0, ] resource=<memory:1024, vCores:1> queue=default: capacity=1.0, absoluteCapacity=1.0, usedResources=<memory:48128, vCores:42>usedCapacity=0.9791667, absoluteUsedCapacity=0.9791667, numApps=5, numContainers=42 usedCapacity=0.9791667 absoluteUsedCapacity=0.9791667 used=<memory:48128, vCores:42> cluster=<memory:49152, vCores:96>
2013-08-11 09:32:13,264 INFO org.apache.hadoop.yarn.server.resourcemanager.scheduler.capacity.ParentQueue: completedContainer queue=root usedCapacity=0.9791667 absoluteUsedCapacity=0.9791667 used=<memory:48128, vCores:42> cluster=<memory:49152, vCores:96>
2013-08-11 09:32:13,264 INFO org.apache.hadoop.yarn.server.resourcemanager.scheduler.capacity.CapacityScheduler: Application appattempt_1376212503271_0007_000001 released container container_1376212503271_0007_01_000027 on node: host: hadoop-320-2:53179 #containers=6 available=1024 used=7168 with event: FINISHED
2013-08-11 09:32:13,264 INFO org.apache.hadoop.yarn.server.resourcemanager.rmcontainer.RMContainerImpl: container_1376212503271_0006_01_000015 Container Transitioned from NEW to ALLOCATED
2013-08-11 09:32:13,265 INFO org.apache.hadoop.yarn.server.resourcemanager.RMAuditLogger: USER=ubuntu	OPERATION=AM Allocated Container	TARGET=SchedulerApp	RESULT=SUCCESS	APPID=application_1376212503271_0006	CONTAINERID=container_1376212503271_0006_01_000015
2013-08-11 09:32:13,265 INFO org.apache.hadoop.yarn.server.resourcemanager.scheduler.common.fica.FiCaSchedulerNode: Assigned container container_1376212503271_0006_01_000015 of capacity <memory:1024, vCores:1> on host hadoop-320-2:53179, which currently has 7 containers, <memory:8192, vCores:7> used and <memory:0, vCores:9> available
2013-08-11 09:32:13,266 INFO org.apache.hadoop.yarn.server.resourcemanager.scheduler.capacity.LeafQueue: assignedContainer application=application_1376212503271_0006 container=Container: [ContainerId: container_1376212503271_0006_01_000015, NodeId: hadoop-320-2:53179, NodeHttpAddress: hadoop-320-2:8042, Resource: <memory:1024, vCores:1>, Priority: 20, State: NEW, Token: null, Status: container_id {, app_attempt_id {, application_id {, id: 6, cluster_timestamp: 1376212503271, }, attemptId: 1, }, id: 15, }, state: C_NEW, ] containerId=container_1376212503271_0006_01_000015 queue=default: capacity=1.0, absoluteCapacity=1.0, usedResources=<memory:48128, vCores:42>usedCapacity=0.9791667, absoluteUsedCapacity=0.9791667, numApps=5, numContainers=42 usedCapacity=0.9791667 absoluteUsedCapacity=0.9791667 used=<memory:48128, vCores:42> cluster=<memory:49152, vCores:96>
2013-08-11 09:32:13,266 INFO org.apache.hadoop.yarn.server.resourcemanager.scheduler.capacity.ParentQueue: Re-sorting queues since queue: root.default stats: default: capacity=1.0, absoluteCapacity=1.0, usedResources=<memory:49152, vCores:43>usedCapacity=1.0, absoluteUsedCapacity=1.0, numApps=5, numContainers=43
2013-08-11 09:32:13,266 INFO org.apache.hadoop.yarn.server.resourcemanager.scheduler.capacity.ParentQueue: assignedContainer queue=root usedCapacity=1.0 absoluteUsedCapacity=1.0 used=<memory:49152, vCores:43> cluster=<memory:49152, vCores:96>
2013-08-11 09:32:13,726 INFO org.apache.hadoop.yarn.server.resourcemanager.rmcontainer.RMContainerImpl: container_1376212503271_0006_01_000015 Container Transitioned from ALLOCATED to ACQUIRED
2013-08-11 09:32:14,271 INFO org.apache.hadoop.yarn.server.resourcemanager.rmcontainer.RMContainerImpl: container_1376212503271_0006_01_000015 Container Transitioned from ACQUIRED to RUNNING
2013-08-11 09:32:15,397 INFO org.apache.hadoop.yarn.server.resourcemanager.rmcontainer.RMContainerImpl: container_1376212503271_0007_01_000002 Container Transitioned from RUNNING to COMPLETED
2013-08-11 09:32:15,397 INFO org.apache.hadoop.yarn.server.resourcemanager.scheduler.common.fica.FiCaSchedulerApp: Completed container: container_1376212503271_0007_01_000002 in state: COMPLETED event:FINISHED
2013-08-11 09:32:15,398 INFO org.apache.hadoop.yarn.server.resourcemanager.RMAuditLogger: USER=ubuntu	OPERATION=AM Released Container	TARGET=SchedulerApp	RESULT=SUCCESS	APPID=application_1376212503271_0007	CONTAINERID=container_1376212503271_0007_01_000002
2013-08-11 09:32:15,398 INFO org.apache.hadoop.yarn.server.resourcemanager.scheduler.common.fica.FiCaSchedulerNode: Released container container_1376212503271_0007_01_000002 of capacity <memory:1024, vCores:1> on host hadoop-320-3:47015, which currently has 6 containers, <memory:7168, vCores:6> used and <memory:1024, vCores:10> available, release resources=true
2013-08-11 09:32:15,398 INFO org.apache.hadoop.yarn.server.resourcemanager.scheduler.capacity.LeafQueue: default used=<memory:48128, vCores:42> numContainers=42 user=ubuntu user-resources=<memory:48128, vCores:42>
2013-08-11 09:32:15,399 INFO org.apache.hadoop.yarn.server.resourcemanager.scheduler.capacity.LeafQueue: completedContainer container=Container: [ContainerId: container_1376212503271_0007_01_000002, NodeId: hadoop-320-3:47015, NodeHttpAddress: hadoop-320-3:8042, Resource: <memory:1024, vCores:1>, Priority: 20, State: NEW, Token: null, Status: container_id {, app_attempt_id {, application_id {, id: 7, cluster_timestamp: 1376212503271, }, attemptId: 1, }, id: 2, }, state: C_COMPLETE, diagnostics: "Container killed by the ApplicationMaster.\n\n", exit_status: 143, ] resource=<memory:1024, vCores:1> queue=default: capacity=1.0, absoluteCapacity=1.0, usedResources=<memory:48128, vCores:42>usedCapacity=0.9791667, absoluteUsedCapacity=0.9791667, numApps=5, numContainers=42 usedCapacity=0.9791667 absoluteUsedCapacity=0.9791667 used=<memory:48128, vCores:42> cluster=<memory:49152, vCores:96>
2013-08-11 09:32:15,399 INFO org.apache.hadoop.yarn.server.resourcemanager.scheduler.capacity.ParentQueue: completedContainer queue=root usedCapacity=0.9791667 absoluteUsedCapacity=0.9791667 used=<memory:48128, vCores:42> cluster=<memory:49152, vCores:96>
2013-08-11 09:32:15,399 INFO org.apache.hadoop.yarn.server.resourcemanager.scheduler.capacity.CapacityScheduler: Application appattempt_1376212503271_0007_000001 released container container_1376212503271_0007_01_000002 on node: host: hadoop-320-3:47015 #containers=6 available=1024 used=7168 with event: FINISHED
2013-08-11 09:32:15,400 INFO org.apache.hadoop.yarn.server.resourcemanager.rmcontainer.RMContainerImpl: container_1376212503271_0006_01_000016 Container Transitioned from NEW to ALLOCATED
2013-08-11 09:32:15,400 INFO org.apache.hadoop.yarn.server.resourcemanager.RMAuditLogger: USER=ubuntu	OPERATION=AM Allocated Container	TARGET=SchedulerApp	RESULT=SUCCESS	APPID=application_1376212503271_0006	CONTAINERID=container_1376212503271_0006_01_000016
2013-08-11 09:32:15,400 INFO org.apache.hadoop.yarn.server.resourcemanager.scheduler.common.fica.FiCaSchedulerNode: Assigned container container_1376212503271_0006_01_000016 of capacity <memory:1024, vCores:1> on host hadoop-320-3:47015, which currently has 7 containers, <memory:8192, vCores:7> used and <memory:0, vCores:9> available
2013-08-11 09:32:15,401 INFO org.apache.hadoop.yarn.server.resourcemanager.scheduler.capacity.LeafQueue: assignedContainer application=application_1376212503271_0006 container=Container: [ContainerId: container_1376212503271_0006_01_000016, NodeId: hadoop-320-3:47015, NodeHttpAddress: hadoop-320-3:8042, Resource: <memory:1024, vCores:1>, Priority: 20, State: NEW, Token: null, Status: container_id {, app_attempt_id {, application_id {, id: 6, cluster_timestamp: 1376212503271, }, attemptId: 1, }, id: 16, }, state: C_NEW, ] containerId=container_1376212503271_0006_01_000016 queue=default: capacity=1.0, absoluteCapacity=1.0, usedResources=<memory:48128, vCores:42>usedCapacity=0.9791667, absoluteUsedCapacity=0.9791667, numApps=5, numContainers=42 usedCapacity=0.9791667 absoluteUsedCapacity=0.9791667 used=<memory:48128, vCores:42> cluster=<memory:49152, vCores:96>
2013-08-11 09:32:15,401 INFO org.apache.hadoop.yarn.server.resourcemanager.scheduler.capacity.ParentQueue: Re-sorting queues since queue: root.default stats: default: capacity=1.0, absoluteCapacity=1.0, usedResources=<memory:49152, vCores:43>usedCapacity=1.0, absoluteUsedCapacity=1.0, numApps=5, numContainers=43
2013-08-11 09:32:15,401 INFO org.apache.hadoop.yarn.server.resourcemanager.scheduler.capacity.ParentQueue: assignedContainer queue=root usedCapacity=1.0 absoluteUsedCapacity=1.0 used=<memory:49152, vCores:43> cluster=<memory:49152, vCores:96>
2013-08-11 09:32:15,782 INFO org.apache.hadoop.yarn.server.resourcemanager.rmcontainer.RMContainerImpl: container_1376212503271_0006_01_000016 Container Transitioned from ALLOCATED to ACQUIRED
2013-08-11 09:32:16,404 INFO org.apache.hadoop.yarn.server.resourcemanager.rmcontainer.RMContainerImpl: container_1376212503271_0006_01_000016 Container Transitioned from ACQUIRED to RUNNING
2013-08-11 09:32:20,484 INFO org.apache.hadoop.yarn.server.resourcemanager.rmcontainer.RMContainerImpl: container_1376212503271_0007_01_000030 Container Transitioned from RUNNING to COMPLETED
2013-08-11 09:32:20,484 INFO org.apache.hadoop.yarn.server.resourcemanager.scheduler.common.fica.FiCaSchedulerApp: Completed container: container_1376212503271_0007_01_000030 in state: COMPLETED event:FINISHED
2013-08-11 09:32:20,485 INFO org.apache.hadoop.yarn.server.resourcemanager.RMAuditLogger: USER=ubuntu	OPERATION=AM Released Container	TARGET=SchedulerApp	RESULT=SUCCESS	APPID=application_1376212503271_0007	CONTAINERID=container_1376212503271_0007_01_000030
2013-08-11 09:32:20,485 INFO org.apache.hadoop.yarn.server.resourcemanager.scheduler.common.fica.FiCaSchedulerNode: Released container container_1376212503271_0007_01_000030 of capacity <memory:1024, vCores:1> on host hadoop-320-4:39920, which currently has 6 containers, <memory:7168, vCores:6> used and <memory:1024, vCores:10> available, release resources=true
2013-08-11 09:32:20,485 INFO org.apache.hadoop.yarn.server.resourcemanager.scheduler.capacity.LeafQueue: default used=<memory:48128, vCores:42> numContainers=42 user=ubuntu user-resources=<memory:48128, vCores:42>
2013-08-11 09:32:20,486 INFO org.apache.hadoop.yarn.server.resourcemanager.scheduler.capacity.LeafQueue: completedContainer container=Container: [ContainerId: container_1376212503271_0007_01_000030, NodeId: hadoop-320-4:39920, NodeHttpAddress: hadoop-320-4:8042, Resource: <memory:1024, vCores:1>, Priority: 20, State: NEW, Token: null, Status: container_id {, app_attempt_id {, application_id {, id: 7, cluster_timestamp: 1376212503271, }, attemptId: 1, }, id: 30, }, state: C_COMPLETE, diagnostics: "Container killed by the ApplicationMaster.\n", exit_status: 0, ] resource=<memory:1024, vCores:1> queue=default: capacity=1.0, absoluteCapacity=1.0, usedResources=<memory:48128, vCores:42>usedCapacity=0.9791667, absoluteUsedCapacity=0.9791667, numApps=5, numContainers=42 usedCapacity=0.9791667 absoluteUsedCapacity=0.9791667 used=<memory:48128, vCores:42> cluster=<memory:49152, vCores:96>
2013-08-11 09:32:20,486 INFO org.apache.hadoop.yarn.server.resourcemanager.scheduler.capacity.ParentQueue: completedContainer queue=root usedCapacity=0.9791667 absoluteUsedCapacity=0.9791667 used=<memory:48128, vCores:42> cluster=<memory:49152, vCores:96>
2013-08-11 09:32:20,486 INFO org.apache.hadoop.yarn.server.resourcemanager.scheduler.capacity.CapacityScheduler: Application appattempt_1376212503271_0007_000001 released container container_1376212503271_0007_01_000030 on node: host: hadoop-320-4:39920 #containers=6 available=1024 used=7168 with event: FINISHED
2013-08-11 09:32:20,487 INFO org.apache.hadoop.yarn.server.resourcemanager.rmcontainer.RMContainerImpl: container_1376212503271_0006_01_000017 Container Transitioned from NEW to ALLOCATED
2013-08-11 09:32:20,487 INFO org.apache.hadoop.yarn.server.resourcemanager.RMAuditLogger: USER=ubuntu	OPERATION=AM Allocated Container	TARGET=SchedulerApp	RESULT=SUCCESS	APPID=application_1376212503271_0006	CONTAINERID=container_1376212503271_0006_01_000017
2013-08-11 09:32:20,487 INFO org.apache.hadoop.yarn.server.resourcemanager.scheduler.common.fica.FiCaSchedulerNode: Assigned container container_1376212503271_0006_01_000017 of capacity <memory:1024, vCores:1> on host hadoop-320-4:39920, which currently has 7 containers, <memory:8192, vCores:7> used and <memory:0, vCores:9> available
2013-08-11 09:32:20,488 INFO org.apache.hadoop.yarn.server.resourcemanager.scheduler.capacity.LeafQueue: assignedContainer application=application_1376212503271_0006 container=Container: [ContainerId: container_1376212503271_0006_01_000017, NodeId: hadoop-320-4:39920, NodeHttpAddress: hadoop-320-4:8042, Resource: <memory:1024, vCores:1>, Priority: 20, State: NEW, Token: null, Status: container_id {, app_attempt_id {, application_id {, id: 6, cluster_timestamp: 1376212503271, }, attemptId: 1, }, id: 17, }, state: C_NEW, ] containerId=container_1376212503271_0006_01_000017 queue=default: capacity=1.0, absoluteCapacity=1.0, usedResources=<memory:48128, vCores:42>usedCapacity=0.9791667, absoluteUsedCapacity=0.9791667, numApps=5, numContainers=42 usedCapacity=0.9791667 absoluteUsedCapacity=0.9791667 used=<memory:48128, vCores:42> cluster=<memory:49152, vCores:96>
2013-08-11 09:32:20,488 INFO org.apache.hadoop.yarn.server.resourcemanager.scheduler.capacity.ParentQueue: Re-sorting queues since queue: root.default stats: default: capacity=1.0, absoluteCapacity=1.0, usedResources=<memory:49152, vCores:43>usedCapacity=1.0, absoluteUsedCapacity=1.0, numApps=5, numContainers=43
2013-08-11 09:32:20,488 INFO org.apache.hadoop.yarn.server.resourcemanager.scheduler.capacity.ParentQueue: assignedContainer queue=root usedCapacity=1.0 absoluteUsedCapacity=1.0 used=<memory:49152, vCores:43> cluster=<memory:49152, vCores:96>
2013-08-11 09:32:20,815 INFO org.apache.hadoop.yarn.server.resourcemanager.rmcontainer.RMContainerImpl: container_1376212503271_0006_01_000017 Container Transitioned from ALLOCATED to ACQUIRED
2013-08-11 09:32:21,492 INFO org.apache.hadoop.yarn.server.resourcemanager.rmcontainer.RMContainerImpl: container_1376212503271_0006_01_000017 Container Transitioned from ACQUIRED to RUNNING
2013-08-11 09:32:22,102 INFO org.apache.hadoop.yarn.server.resourcemanager.rmcontainer.RMContainerImpl: container_1376212503271_0007_01_000037 Container Transitioned from RUNNING to COMPLETED
2013-08-11 09:32:22,102 INFO org.apache.hadoop.yarn.server.resourcemanager.scheduler.common.fica.FiCaSchedulerApp: Completed container: container_1376212503271_0007_01_000037 in state: COMPLETED event:FINISHED
2013-08-11 09:32:22,103 INFO org.apache.hadoop.yarn.server.resourcemanager.RMAuditLogger: USER=ubuntu	OPERATION=AM Released Container	TARGET=SchedulerApp	RESULT=SUCCESS	APPID=application_1376212503271_0007	CONTAINERID=container_1376212503271_0007_01_000037
2013-08-11 09:32:22,103 INFO org.apache.hadoop.yarn.server.resourcemanager.scheduler.common.fica.FiCaSchedulerNode: Released container container_1376212503271_0007_01_000037 of capacity <memory:1024, vCores:1> on host hadoop-320-5:36272, which currently has 6 containers, <memory:7168, vCores:6> used and <memory:1024, vCores:10> available, release resources=true
2013-08-11 09:32:22,103 INFO org.apache.hadoop.yarn.server.resourcemanager.scheduler.capacity.LeafQueue: default used=<memory:48128, vCores:42> numContainers=42 user=ubuntu user-resources=<memory:48128, vCores:42>
2013-08-11 09:32:22,104 INFO org.apache.hadoop.yarn.server.resourcemanager.scheduler.capacity.LeafQueue: completedContainer container=Container: [ContainerId: container_1376212503271_0007_01_000037, NodeId: hadoop-320-5:36272, NodeHttpAddress: hadoop-320-5:8042, Resource: <memory:1024, vCores:1>, Priority: 20, State: NEW, Token: null, Status: container_id {, app_attempt_id {, application_id {, id: 7, cluster_timestamp: 1376212503271, }, attemptId: 1, }, id: 37, }, state: C_COMPLETE, diagnostics: "Container killed by the ApplicationMaster.\n\n", exit_status: 143, ] resource=<memory:1024, vCores:1> queue=default: capacity=1.0, absoluteCapacity=1.0, usedResources=<memory:48128, vCores:42>usedCapacity=0.9791667, absoluteUsedCapacity=0.9791667, numApps=5, numContainers=42 usedCapacity=0.9791667 absoluteUsedCapacity=0.9791667 used=<memory:48128, vCores:42> cluster=<memory:49152, vCores:96>
2013-08-11 09:32:22,104 INFO org.apache.hadoop.yarn.server.resourcemanager.scheduler.capacity.ParentQueue: completedContainer queue=root usedCapacity=0.9791667 absoluteUsedCapacity=0.9791667 used=<memory:48128, vCores:42> cluster=<memory:49152, vCores:96>
2013-08-11 09:32:22,105 INFO org.apache.hadoop.yarn.server.resourcemanager.scheduler.capacity.CapacityScheduler: Application appattempt_1376212503271_0007_000001 released container container_1376212503271_0007_01_000037 on node: host: hadoop-320-5:36272 #containers=6 available=1024 used=7168 with event: FINISHED
2013-08-11 09:32:22,105 INFO org.apache.hadoop.yarn.server.resourcemanager.rmcontainer.RMContainerImpl: container_1376212503271_0006_01_000018 Container Transitioned from NEW to ALLOCATED
2013-08-11 09:32:22,105 INFO org.apache.hadoop.yarn.server.resourcemanager.RMAuditLogger: USER=ubuntu	OPERATION=AM Allocated Container	TARGET=SchedulerApp	RESULT=SUCCESS	APPID=application_1376212503271_0006	CONTAINERID=container_1376212503271_0006_01_000018
2013-08-11 09:32:22,105 INFO org.apache.hadoop.yarn.server.resourcemanager.scheduler.common.fica.FiCaSchedulerNode: Assigned container container_1376212503271_0006_01_000018 of capacity <memory:1024, vCores:1> on host hadoop-320-5:36272, which currently has 7 containers, <memory:8192, vCores:7> used and <memory:0, vCores:9> available
2013-08-11 09:32:22,106 INFO org.apache.hadoop.yarn.server.resourcemanager.scheduler.capacity.LeafQueue: assignedContainer application=application_1376212503271_0006 container=Container: [ContainerId: container_1376212503271_0006_01_000018, NodeId: hadoop-320-5:36272, NodeHttpAddress: hadoop-320-5:8042, Resource: <memory:1024, vCores:1>, Priority: 20, State: NEW, Token: null, Status: container_id {, app_attempt_id {, application_id {, id: 6, cluster_timestamp: 1376212503271, }, attemptId: 1, }, id: 18, }, state: C_NEW, ] containerId=container_1376212503271_0006_01_000018 queue=default: capacity=1.0, absoluteCapacity=1.0, usedResources=<memory:48128, vCores:42>usedCapacity=0.9791667, absoluteUsedCapacity=0.9791667, numApps=5, numContainers=42 usedCapacity=0.9791667 absoluteUsedCapacity=0.9791667 used=<memory:48128, vCores:42> cluster=<memory:49152, vCores:96>
2013-08-11 09:32:22,106 INFO org.apache.hadoop.yarn.server.resourcemanager.scheduler.capacity.ParentQueue: Re-sorting queues since queue: root.default stats: default: capacity=1.0, absoluteCapacity=1.0, usedResources=<memory:49152, vCores:43>usedCapacity=1.0, absoluteUsedCapacity=1.0, numApps=5, numContainers=43
2013-08-11 09:32:22,106 INFO org.apache.hadoop.yarn.server.resourcemanager.scheduler.capacity.ParentQueue: assignedContainer queue=root usedCapacity=1.0 absoluteUsedCapacity=1.0 used=<memory:49152, vCores:43> cluster=<memory:49152, vCores:96>
2013-08-11 09:32:22,374 INFO org.apache.hadoop.yarn.server.resourcemanager.rmcontainer.RMContainerImpl: container_1376212503271_0007_01_000017 Container Transitioned from RUNNING to COMPLETED
2013-08-11 09:32:22,374 INFO org.apache.hadoop.yarn.server.resourcemanager.scheduler.common.fica.FiCaSchedulerApp: Completed container: container_1376212503271_0007_01_000017 in state: COMPLETED event:FINISHED
2013-08-11 09:32:22,374 INFO org.apache.hadoop.yarn.server.resourcemanager.RMAuditLogger: USER=ubuntu	OPERATION=AM Released Container	TARGET=SchedulerApp	RESULT=SUCCESS	APPID=application_1376212503271_0007	CONTAINERID=container_1376212503271_0007_01_000017
2013-08-11 09:32:22,375 INFO org.apache.hadoop.yarn.server.resourcemanager.scheduler.common.fica.FiCaSchedulerNode: Released container container_1376212503271_0007_01_000017 of capacity <memory:1024, vCores:1> on host hadoop-320-7:48037, which currently has 6 containers, <memory:7168, vCores:6> used and <memory:1024, vCores:10> available, release resources=true
2013-08-11 09:32:22,375 INFO org.apache.hadoop.yarn.server.resourcemanager.scheduler.capacity.LeafQueue: default used=<memory:48128, vCores:42> numContainers=42 user=ubuntu user-resources=<memory:48128, vCores:42>
2013-08-11 09:32:22,376 INFO org.apache.hadoop.yarn.server.resourcemanager.scheduler.capacity.LeafQueue: completedContainer container=Container: [ContainerId: container_1376212503271_0007_01_000017, NodeId: hadoop-320-7:48037, NodeHttpAddress: hadoop-320-7:8042, Resource: <memory:1024, vCores:1>, Priority: 20, State: NEW, Token: null, Status: container_id {, app_attempt_id {, application_id {, id: 7, cluster_timestamp: 1376212503271, }, attemptId: 1, }, id: 17, }, state: C_COMPLETE, diagnostics: "Container killed by the ApplicationMaster.\n\n", exit_status: 143, ] resource=<memory:1024, vCores:1> queue=default: capacity=1.0, absoluteCapacity=1.0, usedResources=<memory:48128, vCores:42>usedCapacity=0.9791667, absoluteUsedCapacity=0.9791667, numApps=5, numContainers=42 usedCapacity=0.9791667 absoluteUsedCapacity=0.9791667 used=<memory:48128, vCores:42> cluster=<memory:49152, vCores:96>
2013-08-11 09:32:22,376 INFO org.apache.hadoop.yarn.server.resourcemanager.scheduler.capacity.ParentQueue: completedContainer queue=root usedCapacity=0.9791667 absoluteUsedCapacity=0.9791667 used=<memory:48128, vCores:42> cluster=<memory:49152, vCores:96>
2013-08-11 09:32:22,376 INFO org.apache.hadoop.yarn.server.resourcemanager.scheduler.capacity.CapacityScheduler: Application appattempt_1376212503271_0007_000001 released container container_1376212503271_0007_01_000017 on node: host: hadoop-320-7:48037 #containers=6 available=1024 used=7168 with event: FINISHED
2013-08-11 09:32:22,377 INFO org.apache.hadoop.yarn.server.resourcemanager.rmcontainer.RMContainerImpl: container_1376212503271_0006_01_000019 Container Transitioned from NEW to ALLOCATED
2013-08-11 09:32:22,377 INFO org.apache.hadoop.yarn.server.resourcemanager.RMAuditLogger: USER=ubuntu	OPERATION=AM Allocated Container	TARGET=SchedulerApp	RESULT=SUCCESS	APPID=application_1376212503271_0006	CONTAINERID=container_1376212503271_0006_01_000019
2013-08-11 09:32:22,377 INFO org.apache.hadoop.yarn.server.resourcemanager.scheduler.common.fica.FiCaSchedulerNode: Assigned container container_1376212503271_0006_01_000019 of capacity <memory:1024, vCores:1> on host hadoop-320-7:48037, which currently has 7 containers, <memory:8192, vCores:7> used and <memory:0, vCores:9> available
2013-08-11 09:32:22,378 INFO org.apache.hadoop.yarn.server.resourcemanager.scheduler.capacity.LeafQueue: assignedContainer application=application_1376212503271_0006 container=Container: [ContainerId: container_1376212503271_0006_01_000019, NodeId: hadoop-320-7:48037, NodeHttpAddress: hadoop-320-7:8042, Resource: <memory:1024, vCores:1>, Priority: 20, State: NEW, Token: null, Status: container_id {, app_attempt_id {, application_id {, id: 6, cluster_timestamp: 1376212503271, }, attemptId: 1, }, id: 19, }, state: C_NEW, ] containerId=container_1376212503271_0006_01_000019 queue=default: capacity=1.0, absoluteCapacity=1.0, usedResources=<memory:48128, vCores:42>usedCapacity=0.9791667, absoluteUsedCapacity=0.9791667, numApps=5, numContainers=42 usedCapacity=0.9791667 absoluteUsedCapacity=0.9791667 used=<memory:48128, vCores:42> cluster=<memory:49152, vCores:96>
2013-08-11 09:32:22,378 INFO org.apache.hadoop.yarn.server.resourcemanager.scheduler.capacity.ParentQueue: Re-sorting queues since queue: root.default stats: default: capacity=1.0, absoluteCapacity=1.0, usedResources=<memory:49152, vCores:43>usedCapacity=1.0, absoluteUsedCapacity=1.0, numApps=5, numContainers=43
2013-08-11 09:32:22,378 INFO org.apache.hadoop.yarn.server.resourcemanager.scheduler.capacity.ParentQueue: assignedContainer queue=root usedCapacity=1.0 absoluteUsedCapacity=1.0 used=<memory:49152, vCores:43> cluster=<memory:49152, vCores:96>
2013-08-11 09:32:22,826 INFO org.apache.hadoop.yarn.server.resourcemanager.rmcontainer.RMContainerImpl: container_1376212503271_0006_01_000018 Container Transitioned from ALLOCATED to ACQUIRED
2013-08-11 09:32:22,827 INFO org.apache.hadoop.yarn.server.resourcemanager.rmcontainer.RMContainerImpl: container_1376212503271_0006_01_000019 Container Transitioned from ALLOCATED to ACQUIRED
2013-08-11 09:32:23,114 INFO org.apache.hadoop.yarn.server.resourcemanager.rmcontainer.RMContainerImpl: container_1376212503271_0006_01_000018 Container Transitioned from ACQUIRED to RUNNING
2013-08-11 09:32:23,115 INFO org.apache.hadoop.yarn.server.resourcemanager.rmcontainer.RMContainerImpl: container_1376212503271_0007_01_000035 Container Transitioned from RUNNING to COMPLETED
2013-08-11 09:32:23,115 INFO org.apache.hadoop.yarn.server.resourcemanager.scheduler.common.fica.FiCaSchedulerApp: Completed container: container_1376212503271_0007_01_000035 in state: COMPLETED event:FINISHED
2013-08-11 09:32:23,115 INFO org.apache.hadoop.yarn.server.resourcemanager.RMAuditLogger: USER=ubuntu	OPERATION=AM Released Container	TARGET=SchedulerApp	RESULT=SUCCESS	APPID=application_1376212503271_0007	CONTAINERID=container_1376212503271_0007_01_000035
2013-08-11 09:32:23,115 INFO org.apache.hadoop.yarn.server.resourcemanager.scheduler.common.fica.FiCaSchedulerNode: Released container container_1376212503271_0007_01_000035 of capacity <memory:1024, vCores:1> on host hadoop-320-5:36272, which currently has 6 containers, <memory:7168, vCores:6> used and <memory:1024, vCores:10> available, release resources=true
2013-08-11 09:32:23,115 INFO org.apache.hadoop.yarn.server.resourcemanager.scheduler.capacity.LeafQueue: default used=<memory:48128, vCores:42> numContainers=42 user=ubuntu user-resources=<memory:48128, vCores:42>
2013-08-11 09:32:23,116 INFO org.apache.hadoop.yarn.server.resourcemanager.scheduler.capacity.LeafQueue: completedContainer container=Container: [ContainerId: container_1376212503271_0007_01_000035, NodeId: hadoop-320-5:36272, NodeHttpAddress: hadoop-320-5:8042, Resource: <memory:1024, vCores:1>, Priority: 20, State: NEW, Token: null, Status: container_id {, app_attempt_id {, application_id {, id: 7, cluster_timestamp: 1376212503271, }, attemptId: 1, }, id: 35, }, state: C_COMPLETE, diagnostics: "Container killed by the ApplicationMaster.\n\n", exit_status: 143, ] resource=<memory:1024, vCores:1> queue=default: capacity=1.0, absoluteCapacity=1.0, usedResources=<memory:48128, vCores:42>usedCapacity=0.9791667, absoluteUsedCapacity=0.9791667, numApps=5, numContainers=42 usedCapacity=0.9791667 absoluteUsedCapacity=0.9791667 used=<memory:48128, vCores:42> cluster=<memory:49152, vCores:96>
2013-08-11 09:32:23,117 INFO org.apache.hadoop.yarn.server.resourcemanager.scheduler.capacity.ParentQueue: completedContainer queue=root usedCapacity=0.9791667 absoluteUsedCapacity=0.9791667 used=<memory:48128, vCores:42> cluster=<memory:49152, vCores:96>
2013-08-11 09:32:23,117 INFO org.apache.hadoop.yarn.server.resourcemanager.scheduler.capacity.CapacityScheduler: Application appattempt_1376212503271_0007_000001 released container container_1376212503271_0007_01_000035 on node: host: hadoop-320-5:36272 #containers=6 available=1024 used=7168 with event: FINISHED
2013-08-11 09:32:23,117 INFO org.apache.hadoop.yarn.server.resourcemanager.rmcontainer.RMContainerImpl: container_1376212503271_0006_01_000020 Container Transitioned from NEW to ALLOCATED
2013-08-11 09:32:23,118 INFO org.apache.hadoop.yarn.server.resourcemanager.RMAuditLogger: USER=ubuntu	OPERATION=AM Allocated Container	TARGET=SchedulerApp	RESULT=SUCCESS	APPID=application_1376212503271_0006	CONTAINERID=container_1376212503271_0006_01_000020
2013-08-11 09:32:23,118 INFO org.apache.hadoop.yarn.server.resourcemanager.scheduler.common.fica.FiCaSchedulerNode: Assigned container container_1376212503271_0006_01_000020 of capacity <memory:1024, vCores:1> on host hadoop-320-5:36272, which currently has 7 containers, <memory:8192, vCores:7> used and <memory:0, vCores:9> available
2013-08-11 09:32:23,119 INFO org.apache.hadoop.yarn.server.resourcemanager.scheduler.capacity.LeafQueue: assignedContainer application=application_1376212503271_0006 container=Container: [ContainerId: container_1376212503271_0006_01_000020, NodeId: hadoop-320-5:36272, NodeHttpAddress: hadoop-320-5:8042, Resource: <memory:1024, vCores:1>, Priority: 20, State: NEW, Token: null, Status: container_id {, app_attempt_id {, application_id {, id: 6, cluster_timestamp: 1376212503271, }, attemptId: 1, }, id: 20, }, state: C_NEW, ] containerId=container_1376212503271_0006_01_000020 queue=default: capacity=1.0, absoluteCapacity=1.0, usedResources=<memory:48128, vCores:42>usedCapacity=0.9791667, absoluteUsedCapacity=0.9791667, numApps=5, numContainers=42 usedCapacity=0.9791667 absoluteUsedCapacity=0.9791667 used=<memory:48128, vCores:42> cluster=<memory:49152, vCores:96>
2013-08-11 09:32:23,119 INFO org.apache.hadoop.yarn.server.resourcemanager.scheduler.capacity.ParentQueue: Re-sorting queues since queue: root.default stats: default: capacity=1.0, absoluteCapacity=1.0, usedResources=<memory:49152, vCores:43>usedCapacity=1.0, absoluteUsedCapacity=1.0, numApps=5, numContainers=43
2013-08-11 09:32:23,119 INFO org.apache.hadoop.yarn.server.resourcemanager.scheduler.capacity.ParentQueue: assignedContainer queue=root usedCapacity=1.0 absoluteUsedCapacity=1.0 used=<memory:49152, vCores:43> cluster=<memory:49152, vCores:96>
2013-08-11 09:32:23,379 INFO org.apache.hadoop.yarn.server.resourcemanager.rmcontainer.RMContainerImpl: container_1376212503271_0006_01_000019 Container Transitioned from ACQUIRED to RUNNING
2013-08-11 09:32:23,845 INFO org.apache.hadoop.yarn.server.resourcemanager.rmcontainer.RMContainerImpl: container_1376212503271_0006_01_000020 Container Transitioned from ALLOCATED to ACQUIRED
2013-08-11 09:32:24,123 INFO org.apache.hadoop.yarn.server.resourcemanager.rmcontainer.RMContainerImpl: container_1376212503271_0006_01_000020 Container Transitioned from ACQUIRED to RUNNING
2013-08-11 09:32:24,175 INFO org.apache.hadoop.yarn.server.resourcemanager.rmcontainer.RMContainerImpl: container_1376212503271_0007_01_000022 Container Transitioned from RUNNING to COMPLETED
2013-08-11 09:32:24,175 INFO org.apache.hadoop.yarn.server.resourcemanager.scheduler.common.fica.FiCaSchedulerApp: Completed container: container_1376212503271_0007_01_000022 in state: COMPLETED event:FINISHED
2013-08-11 09:32:24,175 INFO org.apache.hadoop.yarn.server.resourcemanager.RMAuditLogger: USER=ubuntu	OPERATION=AM Released Container	TARGET=SchedulerApp	RESULT=SUCCESS	APPID=application_1376212503271_0007	CONTAINERID=container_1376212503271_0007_01_000022
2013-08-11 09:32:24,176 INFO org.apache.hadoop.yarn.server.resourcemanager.scheduler.common.fica.FiCaSchedulerNode: Released container container_1376212503271_0007_01_000022 of capacity <memory:1024, vCores:1> on host hadoop-320-2:53179, which currently has 6 containers, <memory:7168, vCores:6> used and <memory:1024, vCores:10> available, release resources=true
2013-08-11 09:32:24,176 INFO org.apache.hadoop.yarn.server.resourcemanager.scheduler.capacity.LeafQueue: default used=<memory:48128, vCores:42> numContainers=42 user=ubuntu user-resources=<memory:48128, vCores:42>
2013-08-11 09:32:24,177 INFO org.apache.hadoop.yarn.server.resourcemanager.scheduler.capacity.LeafQueue: completedContainer container=Container: [ContainerId: container_1376212503271_0007_01_000022, NodeId: hadoop-320-2:53179, NodeHttpAddress: hadoop-320-2:8042, Resource: <memory:1024, vCores:1>, Priority: 20, State: NEW, Token: null, Status: container_id {, app_attempt_id {, application_id {, id: 7, cluster_timestamp: 1376212503271, }, attemptId: 1, }, id: 22, }, state: C_COMPLETE, diagnostics: "Container killed by the ApplicationMaster.\n\n", exit_status: 143, ] resource=<memory:1024, vCores:1> queue=default: capacity=1.0, absoluteCapacity=1.0, usedResources=<memory:48128, vCores:42>usedCapacity=0.9791667, absoluteUsedCapacity=0.9791667, numApps=5, numContainers=42 usedCapacity=0.9791667 absoluteUsedCapacity=0.9791667 used=<memory:48128, vCores:42> cluster=<memory:49152, vCores:96>
2013-08-11 09:32:24,177 INFO org.apache.hadoop.yarn.server.resourcemanager.scheduler.capacity.ParentQueue: completedContainer queue=root usedCapacity=0.9791667 absoluteUsedCapacity=0.9791667 used=<memory:48128, vCores:42> cluster=<memory:49152, vCores:96>
2013-08-11 09:32:24,177 INFO org.apache.hadoop.yarn.server.resourcemanager.scheduler.capacity.CapacityScheduler: Application appattempt_1376212503271_0007_000001 released container container_1376212503271_0007_01_000022 on node: host: hadoop-320-2:53179 #containers=6 available=1024 used=7168 with event: FINISHED
2013-08-11 09:32:24,178 INFO org.apache.hadoop.yarn.server.resourcemanager.rmcontainer.RMContainerImpl: container_1376212503271_0007_01_000023 Container Transitioned from RUNNING to COMPLETED
2013-08-11 09:32:24,178 INFO org.apache.hadoop.yarn.server.resourcemanager.scheduler.common.fica.FiCaSchedulerApp: Completed container: container_1376212503271_0007_01_000023 in state: COMPLETED event:FINISHED
2013-08-11 09:32:24,178 INFO org.apache.hadoop.yarn.server.resourcemanager.RMAuditLogger: USER=ubuntu	OPERATION=AM Released Container	TARGET=SchedulerApp	RESULT=SUCCESS	APPID=application_1376212503271_0007	CONTAINERID=container_1376212503271_0007_01_000023
2013-08-11 09:32:24,178 INFO org.apache.hadoop.yarn.server.resourcemanager.scheduler.common.fica.FiCaSchedulerNode: Released container container_1376212503271_0007_01_000023 of capacity <memory:1024, vCores:1> on host hadoop-320-2:53179, which currently has 5 containers, <memory:6144, vCores:5> used and <memory:2048, vCores:11> available, release resources=true
2013-08-11 09:32:24,178 INFO org.apache.hadoop.yarn.server.resourcemanager.scheduler.capacity.LeafQueue: default used=<memory:47104, vCores:41> numContainers=41 user=ubuntu user-resources=<memory:47104, vCores:41>
2013-08-11 09:32:24,179 INFO org.apache.hadoop.yarn.server.resourcemanager.scheduler.capacity.LeafQueue: completedContainer container=Container: [ContainerId: container_1376212503271_0007_01_000023, NodeId: hadoop-320-2:53179, NodeHttpAddress: hadoop-320-2:8042, Resource: <memory:1024, vCores:1>, Priority: 20, State: NEW, Token: null, Status: container_id {, app_attempt_id {, application_id {, id: 7, cluster_timestamp: 1376212503271, }, attemptId: 1, }, id: 23, }, state: C_COMPLETE, diagnostics: "Container killed by the ApplicationMaster.\n", exit_status: 0, ] resource=<memory:1024, vCores:1> queue=default: capacity=1.0, absoluteCapacity=1.0, usedResources=<memory:47104, vCores:41>usedCapacity=0.9583333, absoluteUsedCapacity=0.9583333, numApps=5, numContainers=41 usedCapacity=0.9583333 absoluteUsedCapacity=0.9583333 used=<memory:47104, vCores:41> cluster=<memory:49152, vCores:96>
2013-08-11 09:32:24,179 INFO org.apache.hadoop.yarn.server.resourcemanager.scheduler.capacity.ParentQueue: completedContainer queue=root usedCapacity=0.9583333 absoluteUsedCapacity=0.9583333 used=<memory:47104, vCores:41> cluster=<memory:49152, vCores:96>
2013-08-11 09:32:24,180 INFO org.apache.hadoop.yarn.server.resourcemanager.scheduler.capacity.CapacityScheduler: Application appattempt_1376212503271_0007_000001 released container container_1376212503271_0007_01_000023 on node: host: hadoop-320-2:53179 #containers=5 available=2048 used=6144 with event: FINISHED
2013-08-11 09:32:24,180 INFO org.apache.hadoop.yarn.server.resourcemanager.rmcontainer.RMContainerImpl: container_1376212503271_0007_01_000024 Container Transitioned from RUNNING to COMPLETED
2013-08-11 09:32:24,180 INFO org.apache.hadoop.yarn.server.resourcemanager.scheduler.common.fica.FiCaSchedulerApp: Completed container: container_1376212503271_0007_01_000024 in state: COMPLETED event:FINISHED
2013-08-11 09:32:24,180 INFO org.apache.hadoop.yarn.server.resourcemanager.RMAuditLogger: USER=ubuntu	OPERATION=AM Released Container	TARGET=SchedulerApp	RESULT=SUCCESS	APPID=application_1376212503271_0007	CONTAINERID=container_1376212503271_0007_01_000024
2013-08-11 09:32:24,180 INFO org.apache.hadoop.yarn.server.resourcemanager.scheduler.common.fica.FiCaSchedulerNode: Released container container_1376212503271_0007_01_000024 of capacity <memory:1024, vCores:1> on host hadoop-320-2:53179, which currently has 4 containers, <memory:5120, vCores:4> used and <memory:3072, vCores:12> available, release resources=true
2013-08-11 09:32:24,180 INFO org.apache.hadoop.yarn.server.resourcemanager.scheduler.capacity.LeafQueue: default used=<memory:46080, vCores:40> numContainers=40 user=ubuntu user-resources=<memory:46080, vCores:40>
2013-08-11 09:32:24,181 INFO org.apache.hadoop.yarn.server.resourcemanager.scheduler.capacity.LeafQueue: completedContainer container=Container: [ContainerId: container_1376212503271_0007_01_000024, NodeId: hadoop-320-2:53179, NodeHttpAddress: hadoop-320-2:8042, Resource: <memory:1024, vCores:1>, Priority: 20, State: NEW, Token: null, Status: container_id {, app_attempt_id {, application_id {, id: 7, cluster_timestamp: 1376212503271, }, attemptId: 1, }, id: 24, }, state: C_COMPLETE, diagnostics: "Container killed by the ApplicationMaster.\n", exit_status: 0, ] resource=<memory:1024, vCores:1> queue=default: capacity=1.0, absoluteCapacity=1.0, usedResources=<memory:46080, vCores:40>usedCapacity=0.9375, absoluteUsedCapacity=0.9375, numApps=5, numContainers=40 usedCapacity=0.9375 absoluteUsedCapacity=0.9375 used=<memory:46080, vCores:40> cluster=<memory:49152, vCores:96>
2013-08-11 09:32:24,181 INFO org.apache.hadoop.yarn.server.resourcemanager.scheduler.capacity.ParentQueue: completedContainer queue=root usedCapacity=0.9375 absoluteUsedCapacity=0.9375 used=<memory:46080, vCores:40> cluster=<memory:49152, vCores:96>
2013-08-11 09:32:24,182 INFO org.apache.hadoop.yarn.server.resourcemanager.scheduler.capacity.CapacityScheduler: Application appattempt_1376212503271_0007_000001 released container container_1376212503271_0007_01_000024 on node: host: hadoop-320-2:53179 #containers=4 available=3072 used=5120 with event: FINISHED
2013-08-11 09:32:24,182 INFO org.apache.hadoop.yarn.server.resourcemanager.rmcontainer.RMContainerImpl: container_1376212503271_0007_01_000025 Container Transitioned from RUNNING to COMPLETED
2013-08-11 09:32:24,182 INFO org.apache.hadoop.yarn.server.resourcemanager.scheduler.common.fica.FiCaSchedulerApp: Completed container: container_1376212503271_0007_01_000025 in state: COMPLETED event:FINISHED
2013-08-11 09:32:24,182 INFO org.apache.hadoop.yarn.server.resourcemanager.RMAuditLogger: USER=ubuntu	OPERATION=AM Released Container	TARGET=SchedulerApp	RESULT=SUCCESS	APPID=application_1376212503271_0007	CONTAINERID=container_1376212503271_0007_01_000025
2013-08-11 09:32:24,182 INFO org.apache.hadoop.yarn.server.resourcemanager.scheduler.common.fica.FiCaSchedulerNode: Released container container_1376212503271_0007_01_000025 of capacity <memory:1024, vCores:1> on host hadoop-320-2:53179, which currently has 3 containers, <memory:4096, vCores:3> used and <memory:4096, vCores:13> available, release resources=true
