2013-08-10 17:07:23,143 INFO org.apache.hadoop.yarn.server.resourcemanager.ResourceManager: STARTUP_MSG: 
/************************************************************
STARTUP_MSG: Starting ResourceManager
STARTUP_MSG:   host = hadoop-220-1/192.168.100.9
STARTUP_MSG:   args = []
STARTUP_MSG:   version = 3.0.0-SNAPSHOT
STARTUP_MSG:   build = https://github.com/lalithsuresh/hadoop-common -r 0cb423bd4868928bb06cd93f882bb0913172fd17; compiled by 'lsuresh' on 2013-04-08T15:47Z
STARTUP_MSG:   java = 1.7.0_17
************************************************************/
2013-08-10 17:07:23,157 INFO org.apache.hadoop.yarn.server.resourcemanager.ResourceManager: registered UNIX signal handlers for [TERM, HUP, INT]
2013-08-10 17:07:23,840 INFO org.apache.hadoop.yarn.server.resourcemanager.security.ApplicationTokenSecretManager: Rolling master-key for application-tokens
2013-08-10 17:07:23,894 INFO org.apache.hadoop.yarn.server.resourcemanager.security.RMContainerTokenSecretManager: ContainerTokenKeyRollingInterval: 86400000ms and ContainerTokenKeyActivationDelay: 900000ms
2013-08-10 17:07:23,899 INFO org.apache.hadoop.yarn.service.AbstractService: Service:Dispatcher is inited.
2013-08-10 17:07:23,902 INFO org.apache.hadoop.yarn.event.AsyncDispatcher: Registering class org.apache.hadoop.yarn.server.resourcemanager.recovery.RMStateStoreEventType for class org.apache.hadoop.yarn.server.resourcemanager.recovery.RMStateStore$ForwardingEventHandler
2013-08-10 17:07:23,902 INFO org.apache.hadoop.yarn.service.AbstractService: Service:Dispatcher is started.
2013-08-10 17:07:23,911 INFO org.apache.hadoop.yarn.event.AsyncDispatcher: Registering class org.apache.hadoop.yarn.server.resourcemanager.NodesListManagerEventType for class org.apache.hadoop.yarn.server.resourcemanager.NodesListManager
2013-08-10 17:07:23,912 INFO org.apache.hadoop.yarn.server.resourcemanager.ResourceManager: Using Scheduler: org.apache.hadoop.yarn.server.resourcemanager.scheduler.capacity.CapacityScheduler
2013-08-10 17:07:24,208 INFO org.apache.hadoop.yarn.event.AsyncDispatcher: Registering class org.apache.hadoop.yarn.server.resourcemanager.scheduler.event.SchedulerEventType for class org.apache.hadoop.yarn.server.resourcemanager.ResourceManager$SchedulerEventDispatcher
2013-08-10 17:07:24,211 INFO org.apache.hadoop.yarn.event.AsyncDispatcher: Registering class org.apache.hadoop.yarn.server.resourcemanager.rmapp.RMAppEventType for class org.apache.hadoop.yarn.server.resourcemanager.ResourceManager$ApplicationEventDispatcher
2013-08-10 17:07:24,214 INFO org.apache.hadoop.yarn.event.AsyncDispatcher: Registering class org.apache.hadoop.yarn.server.resourcemanager.rmapp.attempt.RMAppAttemptEventType for class org.apache.hadoop.yarn.server.resourcemanager.ResourceManager$ApplicationAttemptEventDispatcher
2013-08-10 17:07:24,217 INFO org.apache.hadoop.yarn.event.AsyncDispatcher: Registering class org.apache.hadoop.yarn.server.resourcemanager.rmnode.RMNodeEventType for class org.apache.hadoop.yarn.server.resourcemanager.ResourceManager$NodeEventDispatcher
2013-08-10 17:07:24,936 WARN org.apache.hadoop.util.NativeCodeLoader: Unable to load native-hadoop library for your platform... using builtin-java classes where applicable
2013-08-10 17:07:24,966 INFO org.apache.hadoop.yarn.server.resourcemanager.scheduler.capacity.ParentQueue: root, capacity=1.0, asboluteCapacity=1.0, maxCapacity=1.0, asboluteMaxCapacity=1.0, state=RUNNING, acls=SUBMIT_APPLICATIONS:*ADMINISTER_QUEUE:*
2013-08-10 17:07:24,966 INFO org.apache.hadoop.yarn.server.resourcemanager.scheduler.capacity.ParentQueue: Initialized parent-queue root name=root, fullname=root
2013-08-10 17:07:24,984 INFO org.apache.hadoop.yarn.server.resourcemanager.scheduler.capacity.LeafQueue: Initializing default
capacity = 1.0 [= (float) configuredCapacity / 100 ]
asboluteCapacity = 1.0 [= parentAbsoluteCapacity * capacity ]
maxCapacity = 1.0 [= configuredMaxCapacity ]
absoluteMaxCapacity = 1.0 [= 1.0 maximumCapacity undefined, (parentAbsoluteMaxCapacity * maximumCapacity) / 100 otherwise ]
userLimit = 100 [= configuredUserLimit ]
userLimitFactor = 1.0 [= configuredUserLimitFactor ]
maxApplications = 10000 [= configuredMaximumSystemApplicationsPerQueue or (int)(configuredMaximumSystemApplications * absoluteCapacity)]
maxApplicationsPerUser = 10000 [= (int)(maxApplications * (userLimit / 100.0f) * userLimitFactor) ]
maxActiveApplications = 1 [= max((int)ceil((clusterResourceMemory / minimumAllocation) * maxAMResourcePerQueuePercent * absoluteMaxCapacity),1) ]
maxActiveAppsUsingAbsCap = 1 [= max((int)ceil((clusterResourceMemory / minimumAllocation) *maxAMResourcePercent * absoluteCapacity),1) ]
maxActiveApplicationsPerUser = 1 [= max((int)(maxActiveApplications * (userLimit / 100.0f) * userLimitFactor),1) ]
usedCapacity = 0.0 [= usedResourcesMemory / (clusterResourceMemory * absoluteCapacity)]
absoluteUsedCapacity = 0.0 [= usedResourcesMemory / clusterResourceMemory]
maxAMResourcePerQueuePercent = 0.1 [= configuredMaximumAMResourcePercent ]
minimumAllocationFactor = 0.875 [= (float)(maximumAllocationMemory - minimumAllocationMemory) / maximumAllocationMemory ]
numContainers = 0 [= currentNumContainers ]
state = RUNNING [= configuredState ]
acls = SUBMIT_APPLICATIONS:*ADMINISTER_QUEUE:* [= configuredAcls ]

2013-08-10 17:07:24,984 INFO org.apache.hadoop.yarn.server.resourcemanager.scheduler.capacity.CapacityScheduler: Initialized queue: default: capacity=1.0, absoluteCapacity=1.0, usedResources=<memory:0, vCores:0>usedCapacity=0.0, absoluteUsedCapacity=0.0, numApps=0, numContainers=0
2013-08-10 17:07:24,985 INFO org.apache.hadoop.yarn.server.resourcemanager.scheduler.capacity.CapacityScheduler: Initialized queue: root: numChildQueue= 1, capacity=1.0, absoluteCapacity=1.0, usedResources=<memory:0, vCores:0>usedCapacity=0.0, numApps=0, numContainers=0
2013-08-10 17:07:24,985 INFO org.apache.hadoop.yarn.server.resourcemanager.scheduler.capacity.CapacityScheduler: Initialized root queue root: numChildQueue= 1, capacity=1.0, absoluteCapacity=1.0, usedResources=<memory:0, vCores:0>usedCapacity=0.0, numApps=0, numContainers=0
2013-08-10 17:07:24,985 INFO org.apache.hadoop.yarn.server.resourcemanager.scheduler.capacity.CapacityScheduler: Initialized CapacityScheduler with calculator=class org.apache.hadoop.yarn.server.resourcemanager.resource.DefaultResourceCalculator, minimumAllocation=<<memory:1024, vCores:1>>, maximumAllocation=<<memory:8192, vCores:32>>
2013-08-10 17:07:25,353 INFO org.apache.hadoop.yarn.event.AsyncDispatcher: Registering class org.apache.hadoop.yarn.server.resourcemanager.RMAppManagerEventType for class org.apache.hadoop.yarn.server.resourcemanager.RMAppManager
2013-08-10 17:07:25,381 INFO org.apache.hadoop.yarn.event.AsyncDispatcher: Registering class org.apache.hadoop.yarn.server.resourcemanager.amlauncher.AMLauncherEventType for class org.apache.hadoop.yarn.server.resourcemanager.amlauncher.ApplicationMasterLauncher
2013-08-10 17:07:25,476 INFO org.apache.hadoop.yarn.server.resourcemanager.RMNMInfo: Registered RMNMInfo MBean
2013-08-10 17:07:25,477 INFO org.apache.hadoop.yarn.service.AbstractService: Service:Dispatcher is inited.
2013-08-10 17:07:25,477 INFO org.apache.hadoop.yarn.service.AbstractService: Service:org.apache.hadoop.yarn.server.resourcemanager.rmcontainer.ContainerAllocationExpirer is inited.
2013-08-10 17:07:25,477 INFO org.apache.hadoop.yarn.service.AbstractService: Service:AMLivelinessMonitor is inited.
2013-08-10 17:07:25,477 INFO org.apache.hadoop.yarn.service.AbstractService: Service:AMLivelinessMonitor is inited.
2013-08-10 17:07:25,477 INFO org.apache.hadoop.yarn.service.AbstractService: Service:org.apache.hadoop.yarn.server.resourcemanager.security.DelegationTokenRenewer is inited.
2013-08-10 17:07:25,479 INFO org.apache.hadoop.util.HostsFileReader: Refreshing hosts (include/exclude) list
2013-08-10 17:07:25,479 INFO org.apache.hadoop.yarn.service.AbstractService: Service:org.apache.hadoop.yarn.server.resourcemanager.NodesListManager is inited.
2013-08-10 17:07:25,479 INFO org.apache.hadoop.yarn.service.AbstractService: Service:org.apache.hadoop.yarn.server.resourcemanager.ResourceManager$SchedulerEventDispatcher is inited.
2013-08-10 17:07:25,479 INFO org.apache.hadoop.yarn.service.AbstractService: Service:NMLivelinessMonitor is inited.
2013-08-10 17:07:25,487 INFO org.apache.hadoop.yarn.service.AbstractService: Service:org.apache.hadoop.yarn.server.resourcemanager.ResourceTrackerService is inited.
2013-08-10 17:07:25,487 INFO org.apache.hadoop.yarn.service.AbstractService: Service:org.apache.hadoop.yarn.server.resourcemanager.ApplicationMasterService is inited.
2013-08-10 17:07:25,487 INFO org.apache.hadoop.yarn.service.AbstractService: Service:org.apache.hadoop.yarn.server.resourcemanager.ClientRMService is inited.
2013-08-10 17:07:25,487 INFO org.apache.hadoop.yarn.service.AbstractService: Service:org.apache.hadoop.yarn.server.resourcemanager.AdminService is inited.
2013-08-10 17:07:25,488 INFO org.apache.hadoop.yarn.service.AbstractService: Service:org.apache.hadoop.yarn.server.resourcemanager.amlauncher.ApplicationMasterLauncher is inited.
2013-08-10 17:07:25,488 INFO org.apache.hadoop.yarn.service.AbstractService: Service:ResourceManager is inited.
2013-08-10 17:07:25,488 INFO org.apache.hadoop.yarn.server.resourcemanager.security.RMContainerTokenSecretManager: Rolling master-key for container-tokens
2013-08-10 17:07:25,488 INFO org.apache.hadoop.yarn.server.resourcemanager.security.ApplicationTokenSecretManager: Rolling master-key for application-tokens
2013-08-10 17:07:25,642 INFO org.mortbay.log: Logging to org.slf4j.impl.Log4jLoggerAdapter(org.mortbay.log) via org.mortbay.log.Slf4jLog
2013-08-10 17:07:25,736 INFO org.apache.hadoop.http.HttpServer: Added global filter 'safety' (class=org.apache.hadoop.http.HttpServer$QuotingInputFilter)
2013-08-10 17:07:25,740 INFO org.apache.hadoop.http.HttpServer: Added filter static_user_filter (class=org.apache.hadoop.http.lib.StaticUserWebFilter$StaticUserFilter) to context cluster
2013-08-10 17:07:25,740 INFO org.apache.hadoop.http.HttpServer: Added filter static_user_filter (class=org.apache.hadoop.http.lib.StaticUserWebFilter$StaticUserFilter) to context static
2013-08-10 17:07:25,740 INFO org.apache.hadoop.http.HttpServer: Added filter static_user_filter (class=org.apache.hadoop.http.lib.StaticUserWebFilter$StaticUserFilter) to context logs
2013-08-10 17:07:25,747 INFO org.apache.hadoop.http.HttpServer: adding path spec: /cluster
2013-08-10 17:07:25,747 INFO org.apache.hadoop.http.HttpServer: adding path spec: /cluster/*
2013-08-10 17:07:25,748 INFO org.apache.hadoop.http.HttpServer: adding path spec: /ws
2013-08-10 17:07:25,748 INFO org.apache.hadoop.http.HttpServer: adding path spec: /ws/*
2013-08-10 17:07:25,750 INFO org.apache.hadoop.http.HttpServer: Added global filter 'guice' (class=com.google.inject.servlet.GuiceFilter)
2013-08-10 17:07:25,758 INFO org.apache.hadoop.http.HttpServer: Jetty bound to port 8088
2013-08-10 17:07:25,759 INFO org.mortbay.log: jetty-6.1.26
2013-08-10 17:07:25,801 INFO org.mortbay.log: Extract jar:file:/home/ubuntu/hadoop-3.0.0-SNAPSHOT/share/hadoop/yarn/hadoop-yarn-common-3.0.0-SNAPSHOT.jar!/webapps/cluster to /tmp/Jetty_0_0_0_0_8088_cluster____u0rgz3/webapp
2013-08-10 17:07:26,288 INFO org.mortbay.log: Started SelectChannelConnector@0.0.0.0:8088
2013-08-10 17:07:26,288 INFO org.apache.hadoop.yarn.webapp.WebApps: Web app /cluster started at 8088
2013-08-10 17:07:27,224 INFO org.apache.hadoop.yarn.webapp.WebApps: Registered webapp guice modules
2013-08-10 17:07:27,331 INFO org.apache.hadoop.metrics2.impl.MetricsConfig: loaded properties from hadoop-metrics2.properties
2013-08-10 17:07:27,363 INFO org.apache.hadoop.metrics2.impl.MetricsSystemImpl: Scheduled snapshot period at 10 second(s).
2013-08-10 17:07:27,363 INFO org.apache.hadoop.metrics2.impl.MetricsSystemImpl: ResourceManager metrics system started
2013-08-10 17:07:27,376 INFO org.apache.hadoop.security.token.delegation.AbstractDelegationTokenSecretManager: Updating the current master key for generating delegation tokens
2013-08-10 17:07:27,379 INFO org.apache.hadoop.yarn.service.AbstractService: Service:Dispatcher is started.
2013-08-10 17:07:27,380 INFO org.apache.hadoop.security.token.delegation.AbstractDelegationTokenSecretManager: Starting expired delegation token remover thread, tokenRemoverScanInterval=60 min(s)
2013-08-10 17:07:27,380 INFO org.apache.hadoop.security.token.delegation.AbstractDelegationTokenSecretManager: Updating the current master key for generating delegation tokens
2013-08-10 17:07:27,381 INFO org.apache.hadoop.yarn.service.AbstractService: Service:org.apache.hadoop.yarn.server.resourcemanager.rmcontainer.ContainerAllocationExpirer is started.
2013-08-10 17:07:27,382 INFO org.apache.hadoop.yarn.service.AbstractService: Service:AMLivelinessMonitor is started.
2013-08-10 17:07:27,382 INFO org.apache.hadoop.yarn.service.AbstractService: Service:AMLivelinessMonitor is started.
2013-08-10 17:07:27,382 INFO org.apache.hadoop.yarn.service.AbstractService: Service:org.apache.hadoop.yarn.server.resourcemanager.security.DelegationTokenRenewer is started.
2013-08-10 17:07:27,384 INFO org.apache.hadoop.yarn.service.AbstractService: Service:org.apache.hadoop.yarn.server.resourcemanager.NodesListManager is started.
2013-08-10 17:07:27,384 INFO org.apache.hadoop.yarn.service.AbstractService: Service:org.apache.hadoop.yarn.server.resourcemanager.ResourceManager$SchedulerEventDispatcher is started.
2013-08-10 17:07:27,385 INFO org.apache.hadoop.yarn.service.AbstractService: Service:NMLivelinessMonitor is started.
2013-08-10 17:07:27,385 INFO org.apache.hadoop.yarn.service.AbstractService: Service:org.apache.hadoop.yarn.server.resourcemanager.ResourceTrackerService is started.
2013-08-10 17:07:27,442 INFO org.apache.hadoop.ipc.Server: Starting Socket Reader #1 for port 54110
2013-08-10 17:07:27,474 INFO org.apache.hadoop.yarn.factories.impl.pb.RpcServerFactoryPBImpl: Adding protocol org.apache.hadoop.yarn.server.api.ResourceTrackerPB to the server
2013-08-10 17:07:27,475 INFO org.apache.hadoop.ipc.Server: IPC Server listener on 54110: starting
2013-08-10 17:07:27,475 INFO org.apache.hadoop.ipc.Server: IPC Server Responder: starting
2013-08-10 17:07:27,619 INFO org.apache.hadoop.ipc.Server: Starting Socket Reader #1 for port 54112
2013-08-10 17:07:27,631 INFO org.apache.hadoop.yarn.factories.impl.pb.RpcServerFactoryPBImpl: Adding protocol org.apache.hadoop.yarn.api.AMRMProtocolPB to the server
2013-08-10 17:07:27,633 INFO org.apache.hadoop.ipc.Server: IPC Server Responder: starting
2013-08-10 17:07:27,633 INFO org.apache.hadoop.ipc.Server: IPC Server listener on 54112: starting
2013-08-10 17:07:27,656 INFO org.apache.hadoop.yarn.service.AbstractService: Service:org.apache.hadoop.yarn.server.resourcemanager.ApplicationMasterService is started.
2013-08-10 17:07:27,701 INFO org.apache.hadoop.ipc.Server: Starting Socket Reader #1 for port 54111
2013-08-10 17:07:27,706 INFO org.apache.hadoop.yarn.factories.impl.pb.RpcServerFactoryPBImpl: Adding protocol org.apache.hadoop.yarn.api.ClientRMProtocolPB to the server
2013-08-10 17:07:27,707 INFO org.apache.hadoop.ipc.Server: IPC Server Responder: starting
2013-08-10 17:07:27,715 INFO org.apache.hadoop.ipc.Server: IPC Server listener on 54111: starting
2013-08-10 17:07:27,750 INFO org.apache.hadoop.yarn.service.AbstractService: Service:org.apache.hadoop.yarn.server.resourcemanager.ClientRMService is started.
2013-08-10 17:07:27,784 INFO org.apache.hadoop.ipc.Server: Starting Socket Reader #1 for port 8033
2013-08-10 17:07:27,800 INFO org.apache.hadoop.yarn.factories.impl.pb.RpcServerFactoryPBImpl: Adding protocol org.apache.hadoop.yarn.api.RMAdminProtocolPB to the server
2013-08-10 17:07:27,801 INFO org.apache.hadoop.ipc.Server: IPC Server Responder: starting
2013-08-10 17:07:27,802 INFO org.apache.hadoop.ipc.Server: IPC Server listener on 8033: starting
2013-08-10 17:07:27,815 INFO org.apache.hadoop.yarn.service.AbstractService: Service:org.apache.hadoop.yarn.server.resourcemanager.AdminService is started.
2013-08-10 17:07:27,816 INFO org.apache.hadoop.yarn.service.AbstractService: Service:org.apache.hadoop.yarn.server.resourcemanager.amlauncher.ApplicationMasterLauncher is started.
2013-08-10 17:07:27,816 INFO org.apache.hadoop.yarn.service.AbstractService: Service:ResourceManager is started.
2013-08-10 17:07:37,162 INFO org.apache.hadoop.yarn.util.RackResolver: Resolved hadoop-220-2 to /default-rack
2013-08-10 17:07:37,169 INFO org.apache.hadoop.yarn.server.resourcemanager.ResourceTrackerService: NodeManager from node hadoop-220-2(cmPort: 50762 httpPort: 8042) registered with capability: <memory:8192, vCores:16>, assigned nodeId hadoop-220-2:50762
2013-08-10 17:07:37,192 INFO org.apache.hadoop.yarn.server.resourcemanager.rmnode.RMNodeImpl: hadoop-220-2:50762 Node Transitioned from NEW to RUNNING
2013-08-10 17:07:37,196 INFO org.apache.hadoop.yarn.server.resourcemanager.scheduler.capacity.CapacityScheduler: Added node hadoop-220-2:50762 clusterResource: <memory:8192, vCores:16>
2013-08-10 17:07:37,360 INFO org.apache.hadoop.yarn.util.RackResolver: Resolved hadoop-220-4 to /default-rack
2013-08-10 17:07:37,360 INFO org.apache.hadoop.yarn.server.resourcemanager.ResourceTrackerService: NodeManager from node hadoop-220-4(cmPort: 35716 httpPort: 8042) registered with capability: <memory:8192, vCores:16>, assigned nodeId hadoop-220-4:35716
2013-08-10 17:07:37,361 INFO org.apache.hadoop.yarn.server.resourcemanager.rmnode.RMNodeImpl: hadoop-220-4:35716 Node Transitioned from NEW to RUNNING
2013-08-10 17:07:37,361 INFO org.apache.hadoop.yarn.server.resourcemanager.scheduler.capacity.CapacityScheduler: Added node hadoop-220-4:35716 clusterResource: <memory:16384, vCores:32>
2013-08-10 17:07:37,374 INFO org.apache.hadoop.yarn.util.RackResolver: Resolved hadoop-220-3 to /default-rack
2013-08-10 17:07:37,374 INFO org.apache.hadoop.yarn.server.resourcemanager.ResourceTrackerService: NodeManager from node hadoop-220-3(cmPort: 58548 httpPort: 8042) registered with capability: <memory:8192, vCores:16>, assigned nodeId hadoop-220-3:58548
2013-08-10 17:07:37,375 INFO org.apache.hadoop.yarn.server.resourcemanager.rmnode.RMNodeImpl: hadoop-220-3:58548 Node Transitioned from NEW to RUNNING
2013-08-10 17:07:37,376 INFO org.apache.hadoop.yarn.server.resourcemanager.scheduler.capacity.CapacityScheduler: Added node hadoop-220-3:58548 clusterResource: <memory:24576, vCores:48>
2013-08-10 17:07:37,383 INFO org.apache.hadoop.yarn.util.RackResolver: Resolved hadoop-220-5 to /default-rack
2013-08-10 17:07:37,383 INFO org.apache.hadoop.yarn.server.resourcemanager.ResourceTrackerService: NodeManager from node hadoop-220-5(cmPort: 59721 httpPort: 8042) registered with capability: <memory:8192, vCores:16>, assigned nodeId hadoop-220-5:59721
2013-08-10 17:07:37,384 INFO org.apache.hadoop.yarn.server.resourcemanager.rmnode.RMNodeImpl: hadoop-220-5:59721 Node Transitioned from NEW to RUNNING
2013-08-10 17:07:37,384 INFO org.apache.hadoop.yarn.server.resourcemanager.scheduler.capacity.CapacityScheduler: Added node hadoop-220-5:59721 clusterResource: <memory:32768, vCores:64>
2013-08-10 17:07:37,549 INFO org.apache.hadoop.yarn.util.RackResolver: Resolved hadoop-220-6 to /default-rack
2013-08-10 17:07:37,550 INFO org.apache.hadoop.yarn.server.resourcemanager.ResourceTrackerService: NodeManager from node hadoop-220-6(cmPort: 56687 httpPort: 8042) registered with capability: <memory:8192, vCores:16>, assigned nodeId hadoop-220-6:56687
2013-08-10 17:07:37,551 INFO org.apache.hadoop.yarn.server.resourcemanager.rmnode.RMNodeImpl: hadoop-220-6:56687 Node Transitioned from NEW to RUNNING
2013-08-10 17:07:37,551 INFO org.apache.hadoop.yarn.server.resourcemanager.scheduler.capacity.CapacityScheduler: Added node hadoop-220-6:56687 clusterResource: <memory:40960, vCores:80>
2013-08-10 17:07:37,680 INFO org.apache.hadoop.yarn.util.RackResolver: Resolved hadoop-220-7 to /default-rack
2013-08-10 17:07:37,680 INFO org.apache.hadoop.yarn.server.resourcemanager.ResourceTrackerService: NodeManager from node hadoop-220-7(cmPort: 42517 httpPort: 8042) registered with capability: <memory:8192, vCores:16>, assigned nodeId hadoop-220-7:42517
2013-08-10 17:07:37,681 INFO org.apache.hadoop.yarn.server.resourcemanager.rmnode.RMNodeImpl: hadoop-220-7:42517 Node Transitioned from NEW to RUNNING
2013-08-10 17:07:37,683 INFO org.apache.hadoop.yarn.server.resourcemanager.scheduler.capacity.CapacityScheduler: Added node hadoop-220-7:42517 clusterResource: <memory:49152, vCores:96>
2013-08-10 17:07:45,514 INFO org.apache.hadoop.yarn.server.resourcemanager.ClientRMService: Allocated new applicationId: 1
2013-08-10 17:07:48,792 INFO org.apache.hadoop.yarn.server.resourcemanager.ClientRMService: Storing Application with id application_1376154442901_0001
2013-08-10 17:07:48,797 INFO org.apache.hadoop.yarn.server.resourcemanager.recovery.RMStateStore: Storing info for app: application_1376154442901_0001
2013-08-10 17:07:48,797 INFO org.apache.hadoop.yarn.server.resourcemanager.ClientRMService: Application with id 1 submitted by user ubuntu
2013-08-10 17:07:48,800 INFO org.apache.hadoop.yarn.server.resourcemanager.RMAuditLogger: USER=ubuntu	IP=192.168.100.9	OPERATION=Submit Application Request	TARGET=ClientRMService	RESULT=SUCCESS	APPID=application_1376154442901_0001
2013-08-10 17:07:48,840 INFO org.apache.hadoop.yarn.server.resourcemanager.rmapp.RMAppImpl: application_1376154442901_0001 State change from NEW to SUBMITTED
2013-08-10 17:07:48,842 INFO org.apache.hadoop.yarn.server.resourcemanager.ApplicationMasterService: Registering appattempt_1376154442901_0001_000001
2013-08-10 17:07:48,843 INFO org.apache.hadoop.yarn.server.resourcemanager.rmapp.attempt.RMAppAttemptImpl: appattempt_1376154442901_0001_000001 State change from NEW to SUBMITTED
2013-08-10 17:07:48,877 INFO org.apache.hadoop.yarn.server.resourcemanager.scheduler.capacity.LeafQueue: Application application_1376154442901_0001 from user: ubuntu activated in queue: default
2013-08-10 17:07:48,877 INFO org.apache.hadoop.yarn.server.resourcemanager.scheduler.capacity.LeafQueue: Application added - appId: application_1376154442901_0001 user: org.apache.hadoop.yarn.server.resourcemanager.scheduler.capacity.LeafQueue$User@34f04b34, leaf-queue: default #user-pending-applications: 0 #user-active-applications: 1 #queue-pending-applications: 0 #queue-active-applications: 1
2013-08-10 17:07:48,877 INFO org.apache.hadoop.yarn.server.resourcemanager.scheduler.capacity.ParentQueue: Application added - appId: application_1376154442901_0001 user: ubuntu leaf-queue of parent: root #applications: 1
2013-08-10 17:07:48,878 INFO org.apache.hadoop.yarn.server.resourcemanager.scheduler.capacity.CapacityScheduler: Application Submission: appattempt_1376154442901_0001_000001, user: ubuntu queue: default: capacity=1.0, absoluteCapacity=1.0, usedResources=<memory:0, vCores:0>usedCapacity=0.0, absoluteUsedCapacity=0.0, numApps=1, numContainers=0, currently active: 1
2013-08-10 17:07:48,884 INFO org.apache.hadoop.yarn.server.resourcemanager.rmapp.attempt.RMAppAttemptImpl: appattempt_1376154442901_0001_000001 State change from SUBMITTED to SCHEDULED
2013-08-10 17:07:48,884 INFO org.apache.hadoop.yarn.server.resourcemanager.rmapp.RMAppImpl: application_1376154442901_0001 State change from SUBMITTED to ACCEPTED
2013-08-10 17:07:49,370 INFO org.apache.hadoop.yarn.server.resourcemanager.rmcontainer.RMContainerImpl: container_1376154442901_0001_01_000001 Container Transitioned from NEW to ALLOCATED
2013-08-10 17:07:49,371 INFO org.apache.hadoop.yarn.server.resourcemanager.RMAuditLogger: USER=ubuntu	OPERATION=AM Allocated Container	TARGET=SchedulerApp	RESULT=SUCCESS	APPID=application_1376154442901_0001	CONTAINERID=container_1376154442901_0001_01_000001
2013-08-10 17:07:49,372 INFO org.apache.hadoop.yarn.server.resourcemanager.scheduler.common.fica.FiCaSchedulerNode: Assigned container container_1376154442901_0001_01_000001 of capacity <memory:2048, vCores:1> on host hadoop-220-2:50762, which currently has 1 containers, <memory:2048, vCores:1> used and <memory:6144, vCores:15> available
2013-08-10 17:07:49,378 INFO org.apache.hadoop.yarn.server.resourcemanager.scheduler.capacity.LeafQueue: assignedContainer application=application_1376154442901_0001 container=Container: [ContainerId: container_1376154442901_0001_01_000001, NodeId: hadoop-220-2:50762, NodeHttpAddress: hadoop-220-2:8042, Resource: <memory:2048, vCores:1>, Priority: 0, State: NEW, Token: null, Status: container_id {, app_attempt_id {, application_id {, id: 1, cluster_timestamp: 1376154442901, }, attemptId: 1, }, id: 1, }, state: C_NEW, ] containerId=container_1376154442901_0001_01_000001 queue=default: capacity=1.0, absoluteCapacity=1.0, usedResources=<memory:0, vCores:0>usedCapacity=0.0, absoluteUsedCapacity=0.0, numApps=1, numContainers=0 usedCapacity=0.0 absoluteUsedCapacity=0.0 used=<memory:0, vCores:0> cluster=<memory:49152, vCores:96>
2013-08-10 17:07:49,378 INFO org.apache.hadoop.yarn.server.resourcemanager.scheduler.capacity.ParentQueue: Re-sorting queues since queue: root.default stats: default: capacity=1.0, absoluteCapacity=1.0, usedResources=<memory:2048, vCores:1>usedCapacity=0.041666668, absoluteUsedCapacity=0.041666668, numApps=1, numContainers=1
2013-08-10 17:07:49,380 INFO org.apache.hadoop.yarn.server.resourcemanager.scheduler.capacity.ParentQueue: assignedContainer queue=root usedCapacity=0.041666668 absoluteUsedCapacity=0.041666668 used=<memory:2048, vCores:1> cluster=<memory:49152, vCores:96>
2013-08-10 17:07:49,382 INFO org.apache.hadoop.yarn.server.resourcemanager.rmcontainer.RMContainerImpl: container_1376154442901_0001_01_000001 Container Transitioned from ALLOCATED to ACQUIRED
2013-08-10 17:07:49,385 INFO org.apache.hadoop.yarn.server.resourcemanager.rmapp.attempt.RMAppAttemptImpl: Storing attempt: AppId: application_1376154442901_0001 AttemptId: appattempt_1376154442901_0001_000001 MasterContainer: Container: [ContainerId: container_1376154442901_0001_01_000001, NodeId: hadoop-220-2:50762, NodeHttpAddress: hadoop-220-2:8042, Resource: <memory:2048, vCores:1>, Priority: 0, State: NEW, Token: null, Status: container_id {, app_attempt_id {, application_id {, id: 1, cluster_timestamp: 1376154442901, }, attemptId: 1, }, id: 1, }, state: C_NEW, ]
2013-08-10 17:07:49,388 INFO org.apache.hadoop.yarn.server.resourcemanager.rmapp.attempt.RMAppAttemptImpl: appattempt_1376154442901_0001_000001 State change from SCHEDULED to ALLOCATED_SAVING
2013-08-10 17:07:49,393 INFO org.apache.hadoop.yarn.server.resourcemanager.recovery.RMStateStore: Storing info for attempt: appattempt_1376154442901_0001_000001
2013-08-10 17:07:49,398 INFO org.apache.hadoop.yarn.server.resourcemanager.rmapp.attempt.RMAppAttemptImpl: appattempt_1376154442901_0001_000001 State change from ALLOCATED_SAVING to ALLOCATED
2013-08-10 17:07:49,406 INFO org.apache.hadoop.yarn.server.resourcemanager.amlauncher.AMLauncher: Launching masterappattempt_1376154442901_0001_000001
2013-08-10 17:07:49,449 INFO org.apache.hadoop.yarn.server.resourcemanager.amlauncher.AMLauncher: Setting up container Container: [ContainerId: container_1376154442901_0001_01_000001, NodeId: hadoop-220-2:50762, NodeHttpAddress: hadoop-220-2:8042, Resource: <memory:2048, vCores:1>, Priority: 0, State: NEW, Token: null, Status: container_id {, app_attempt_id {, application_id {, id: 1, cluster_timestamp: 1376154442901, }, attemptId: 1, }, id: 1, }, state: C_NEW, ] for AM appattempt_1376154442901_0001_000001
2013-08-10 17:07:49,449 INFO org.apache.hadoop.yarn.server.resourcemanager.amlauncher.AMLauncher: Command to launch container container_1376154442901_0001_01_000001 : $JAVA_HOME/bin/java -Dlog4j.configuration=container-log4j.properties -Dyarn.app.mapreduce.container.log.dir=<LOG_DIR> -Dyarn.app.mapreduce.container.log.filesize=0 -Dhadoop.root.logger=INFO,CLA  -Xmx1024m org.apache.hadoop.mapreduce.v2.app.MRAppMaster 1><LOG_DIR>/stdout 2><LOG_DIR>/stderr 
2013-08-10 17:07:50,350 INFO org.apache.hadoop.yarn.server.resourcemanager.amlauncher.AMLauncher: Done launching container Container: [ContainerId: container_1376154442901_0001_01_000001, NodeId: hadoop-220-2:50762, NodeHttpAddress: hadoop-220-2:8042, Resource: <memory:2048, vCores:1>, Priority: 0, State: NEW, Token: null, Status: container_id {, app_attempt_id {, application_id {, id: 1, cluster_timestamp: 1376154442901, }, attemptId: 1, }, id: 1, }, state: C_NEW, ] for AM appattempt_1376154442901_0001_000001
2013-08-10 17:07:50,351 INFO org.apache.hadoop.yarn.server.resourcemanager.rmapp.attempt.RMAppAttemptImpl: appattempt_1376154442901_0001_000001 State change from ALLOCATED to LAUNCHED
2013-08-10 17:07:50,376 INFO org.apache.hadoop.yarn.server.resourcemanager.rmcontainer.RMContainerImpl: container_1376154442901_0001_01_000001 Container Transitioned from ACQUIRED to RUNNING
2013-08-10 17:07:58,780 INFO org.apache.hadoop.yarn.server.resourcemanager.ApplicationMasterService: AM registration appattempt_1376154442901_0001_000001
2013-08-10 17:07:58,788 INFO org.apache.hadoop.yarn.server.resourcemanager.RMAuditLogger: USER=ubuntu	IP=192.168.100.15	OPERATION=Register App Master	TARGET=ApplicationMasterService	RESULT=SUCCESS	APPID=application_1376154442901_0001	APPATTEMPTID=appattempt_1376154442901_0001_000001
2013-08-10 17:07:58,796 INFO org.apache.hadoop.yarn.server.resourcemanager.rmapp.attempt.RMAppAttemptImpl: appattempt_1376154442901_0001_000001 State change from LAUNCHED to RUNNING
2013-08-10 17:07:58,797 INFO org.apache.hadoop.yarn.server.resourcemanager.rmapp.RMAppImpl: application_1376154442901_0001 State change from ACCEPTED to RUNNING
2013-08-10 17:08:00,436 INFO org.apache.hadoop.yarn.server.resourcemanager.rmcontainer.RMContainerImpl: container_1376154442901_0001_01_000002 Container Transitioned from NEW to ALLOCATED
2013-08-10 17:08:00,436 INFO org.apache.hadoop.yarn.server.resourcemanager.RMAuditLogger: USER=ubuntu	OPERATION=AM Allocated Container	TARGET=SchedulerApp	RESULT=SUCCESS	APPID=application_1376154442901_0001	CONTAINERID=container_1376154442901_0001_01_000002
2013-08-10 17:08:00,436 INFO org.apache.hadoop.yarn.server.resourcemanager.scheduler.common.fica.FiCaSchedulerNode: Assigned container container_1376154442901_0001_01_000002 of capacity <memory:1024, vCores:1> on host hadoop-220-2:50762, which currently has 2 containers, <memory:3072, vCores:2> used and <memory:5120, vCores:14> available
2013-08-10 17:08:00,438 INFO org.apache.hadoop.yarn.server.resourcemanager.scheduler.capacity.LeafQueue: assignedContainer application=application_1376154442901_0001 container=Container: [ContainerId: container_1376154442901_0001_01_000002, NodeId: hadoop-220-2:50762, NodeHttpAddress: hadoop-220-2:8042, Resource: <memory:1024, vCores:1>, Priority: 20, State: NEW, Token: null, Status: container_id {, app_attempt_id {, application_id {, id: 1, cluster_timestamp: 1376154442901, }, attemptId: 1, }, id: 2, }, state: C_NEW, ] containerId=container_1376154442901_0001_01_000002 queue=default: capacity=1.0, absoluteCapacity=1.0, usedResources=<memory:2048, vCores:1>usedCapacity=0.041666668, absoluteUsedCapacity=0.041666668, numApps=1, numContainers=1 usedCapacity=0.041666668 absoluteUsedCapacity=0.041666668 used=<memory:2048, vCores:1> cluster=<memory:49152, vCores:96>
2013-08-10 17:08:00,438 INFO org.apache.hadoop.yarn.server.resourcemanager.scheduler.capacity.ParentQueue: Re-sorting queues since queue: root.default stats: default: capacity=1.0, absoluteCapacity=1.0, usedResources=<memory:3072, vCores:2>usedCapacity=0.0625, absoluteUsedCapacity=0.0625, numApps=1, numContainers=2
2013-08-10 17:08:00,439 INFO org.apache.hadoop.yarn.server.resourcemanager.scheduler.capacity.ParentQueue: assignedContainer queue=root usedCapacity=0.0625 absoluteUsedCapacity=0.0625 used=<memory:3072, vCores:2> cluster=<memory:49152, vCores:96>
2013-08-10 17:08:00,527 INFO org.apache.hadoop.yarn.server.resourcemanager.rmcontainer.RMContainerImpl: container_1376154442901_0001_01_000003 Container Transitioned from NEW to ALLOCATED
2013-08-10 17:08:00,527 INFO org.apache.hadoop.yarn.server.resourcemanager.RMAuditLogger: USER=ubuntu	OPERATION=AM Allocated Container	TARGET=SchedulerApp	RESULT=SUCCESS	APPID=application_1376154442901_0001	CONTAINERID=container_1376154442901_0001_01_000003
2013-08-10 17:08:00,527 INFO org.apache.hadoop.yarn.server.resourcemanager.scheduler.common.fica.FiCaSchedulerNode: Assigned container container_1376154442901_0001_01_000003 of capacity <memory:1024, vCores:1> on host hadoop-220-4:35716, which currently has 1 containers, <memory:1024, vCores:1> used and <memory:7168, vCores:15> available
2013-08-10 17:08:00,529 INFO org.apache.hadoop.yarn.server.resourcemanager.scheduler.capacity.LeafQueue: assignedContainer application=application_1376154442901_0001 container=Container: [ContainerId: container_1376154442901_0001_01_000003, NodeId: hadoop-220-4:35716, NodeHttpAddress: hadoop-220-4:8042, Resource: <memory:1024, vCores:1>, Priority: 20, State: NEW, Token: null, Status: container_id {, app_attempt_id {, application_id {, id: 1, cluster_timestamp: 1376154442901, }, attemptId: 1, }, id: 3, }, state: C_NEW, ] containerId=container_1376154442901_0001_01_000003 queue=default: capacity=1.0, absoluteCapacity=1.0, usedResources=<memory:3072, vCores:2>usedCapacity=0.0625, absoluteUsedCapacity=0.0625, numApps=1, numContainers=2 usedCapacity=0.0625 absoluteUsedCapacity=0.0625 used=<memory:3072, vCores:2> cluster=<memory:49152, vCores:96>
2013-08-10 17:08:00,529 INFO org.apache.hadoop.yarn.server.resourcemanager.scheduler.capacity.ParentQueue: Re-sorting queues since queue: root.default stats: default: capacity=1.0, absoluteCapacity=1.0, usedResources=<memory:4096, vCores:3>usedCapacity=0.083333336, absoluteUsedCapacity=0.083333336, numApps=1, numContainers=3
2013-08-10 17:08:00,529 INFO org.apache.hadoop.yarn.server.resourcemanager.scheduler.capacity.ParentQueue: assignedContainer queue=root usedCapacity=0.083333336 absoluteUsedCapacity=0.083333336 used=<memory:4096, vCores:3> cluster=<memory:49152, vCores:96>
2013-08-10 17:08:00,865 INFO org.apache.hadoop.yarn.server.resourcemanager.rmcontainer.RMContainerImpl: container_1376154442901_0001_01_000002 Container Transitioned from ALLOCATED to ACQUIRED
2013-08-10 17:08:00,867 INFO org.apache.hadoop.yarn.server.resourcemanager.rmcontainer.RMContainerImpl: container_1376154442901_0001_01_000003 Container Transitioned from ALLOCATED to ACQUIRED
2013-08-10 17:08:01,447 INFO org.apache.hadoop.yarn.server.resourcemanager.rmcontainer.RMContainerImpl: container_1376154442901_0001_01_000002 Container Transitioned from ACQUIRED to RUNNING
2013-08-10 17:08:01,892 INFO org.apache.hadoop.yarn.server.resourcemanager.scheduler.AppSchedulingInfo: checking for deactivate... 
2013-08-10 17:08:02,621 INFO org.apache.hadoop.yarn.server.resourcemanager.rmcontainer.RMContainerImpl: container_1376154442901_0001_01_000003 Container Transitioned from ACQUIRED to RUNNING
2013-08-10 17:10:47,233 INFO org.apache.hadoop.yarn.server.resourcemanager.rmcontainer.RMContainerImpl: container_1376154442901_0001_01_000002 Container Transitioned from RUNNING to COMPLETED
2013-08-10 17:10:47,234 INFO org.apache.hadoop.yarn.server.resourcemanager.scheduler.common.fica.FiCaSchedulerApp: Completed container: container_1376154442901_0001_01_000002 in state: COMPLETED event:FINISHED
2013-08-10 17:10:47,234 INFO org.apache.hadoop.yarn.server.resourcemanager.RMAuditLogger: USER=ubuntu	OPERATION=AM Released Container	TARGET=SchedulerApp	RESULT=SUCCESS	APPID=application_1376154442901_0001	CONTAINERID=container_1376154442901_0001_01_000002
2013-08-10 17:10:47,234 INFO org.apache.hadoop.yarn.server.resourcemanager.scheduler.common.fica.FiCaSchedulerNode: Released container container_1376154442901_0001_01_000002 of capacity <memory:1024, vCores:1> on host hadoop-220-2:50762, which currently has 1 containers, <memory:2048, vCores:1> used and <memory:6144, vCores:15> available, release resources=true
2013-08-10 17:10:47,234 INFO org.apache.hadoop.yarn.server.resourcemanager.scheduler.capacity.LeafQueue: default used=<memory:3072, vCores:2> numContainers=2 user=ubuntu user-resources=<memory:3072, vCores:2>
2013-08-10 17:10:47,237 INFO org.apache.hadoop.yarn.server.resourcemanager.scheduler.capacity.LeafQueue: completedContainer container=Container: [ContainerId: container_1376154442901_0001_01_000002, NodeId: hadoop-220-2:50762, NodeHttpAddress: hadoop-220-2:8042, Resource: <memory:1024, vCores:1>, Priority: 20, State: NEW, Token: null, Status: container_id {, app_attempt_id {, application_id {, id: 1, cluster_timestamp: 1376154442901, }, attemptId: 1, }, id: 2, }, state: C_COMPLETE, diagnostics: "Container killed by the ApplicationMaster.\n\n", exit_status: 143, ] resource=<memory:1024, vCores:1> queue=default: capacity=1.0, absoluteCapacity=1.0, usedResources=<memory:3072, vCores:2>usedCapacity=0.0625, absoluteUsedCapacity=0.0625, numApps=1, numContainers=2 usedCapacity=0.0625 absoluteUsedCapacity=0.0625 used=<memory:3072, vCores:2> cluster=<memory:49152, vCores:96>
2013-08-10 17:10:47,237 INFO org.apache.hadoop.yarn.server.resourcemanager.scheduler.capacity.ParentQueue: completedContainer queue=root usedCapacity=0.0625 absoluteUsedCapacity=0.0625 used=<memory:3072, vCores:2> cluster=<memory:49152, vCores:96>
2013-08-10 17:10:47,237 INFO org.apache.hadoop.yarn.server.resourcemanager.scheduler.capacity.CapacityScheduler: Application appattempt_1376154442901_0001_000001 released container container_1376154442901_0001_01_000002 on node: host: hadoop-220-2:50762 #containers=1 available=6144 used=2048 with event: FINISHED
2013-08-10 17:10:50,596 INFO org.apache.hadoop.yarn.server.resourcemanager.rmcontainer.RMContainerImpl: container_1376154442901_0001_01_000003 Container Transitioned from RUNNING to COMPLETED
2013-08-10 17:10:50,596 INFO org.apache.hadoop.yarn.server.resourcemanager.scheduler.common.fica.FiCaSchedulerApp: Completed container: container_1376154442901_0001_01_000003 in state: COMPLETED event:FINISHED
2013-08-10 17:10:50,597 INFO org.apache.hadoop.yarn.server.resourcemanager.RMAuditLogger: USER=ubuntu	OPERATION=AM Released Container	TARGET=SchedulerApp	RESULT=SUCCESS	APPID=application_1376154442901_0001	CONTAINERID=container_1376154442901_0001_01_000003
2013-08-10 17:10:50,597 INFO org.apache.hadoop.yarn.server.resourcemanager.scheduler.common.fica.FiCaSchedulerNode: Released container container_1376154442901_0001_01_000003 of capacity <memory:1024, vCores:1> on host hadoop-220-4:35716, which currently has 0 containers, <memory:0, vCores:0> used and <memory:8192, vCores:16> available, release resources=true
2013-08-10 17:10:50,597 INFO org.apache.hadoop.yarn.server.resourcemanager.scheduler.capacity.LeafQueue: default used=<memory:2048, vCores:1> numContainers=1 user=ubuntu user-resources=<memory:2048, vCores:1>
2013-08-10 17:10:50,599 INFO org.apache.hadoop.yarn.server.resourcemanager.scheduler.capacity.LeafQueue: completedContainer container=Container: [ContainerId: container_1376154442901_0001_01_000003, NodeId: hadoop-220-4:35716, NodeHttpAddress: hadoop-220-4:8042, Resource: <memory:1024, vCores:1>, Priority: 20, State: NEW, Token: null, Status: container_id {, app_attempt_id {, application_id {, id: 1, cluster_timestamp: 1376154442901, }, attemptId: 1, }, id: 3, }, state: C_COMPLETE, diagnostics: "Container killed by the ApplicationMaster.\n\n", exit_status: 143, ] resource=<memory:1024, vCores:1> queue=default: capacity=1.0, absoluteCapacity=1.0, usedResources=<memory:2048, vCores:1>usedCapacity=0.041666668, absoluteUsedCapacity=0.041666668, numApps=1, numContainers=1 usedCapacity=0.041666668 absoluteUsedCapacity=0.041666668 used=<memory:2048, vCores:1> cluster=<memory:49152, vCores:96>
2013-08-10 17:10:50,599 INFO org.apache.hadoop.yarn.server.resourcemanager.scheduler.capacity.ParentQueue: completedContainer queue=root usedCapacity=0.041666668 absoluteUsedCapacity=0.041666668 used=<memory:2048, vCores:1> cluster=<memory:49152, vCores:96>
2013-08-10 17:10:50,599 INFO org.apache.hadoop.yarn.server.resourcemanager.scheduler.capacity.CapacityScheduler: Application appattempt_1376154442901_0001_000001 released container container_1376154442901_0001_01_000003 on node: host: hadoop-220-4:35716 #containers=0 available=8192 used=0 with event: FINISHED
2013-08-10 17:10:54,748 INFO org.apache.hadoop.yarn.server.resourcemanager.rmapp.attempt.RMAppAttemptImpl: appattempt_1376154442901_0001_000001 State change from RUNNING to FINISHING
2013-08-10 17:10:54,749 INFO org.apache.hadoop.yarn.server.resourcemanager.rmapp.RMAppImpl: application_1376154442901_0001 State change from RUNNING to FINISHING
2013-08-10 17:10:55,167 INFO org.apache.hadoop.yarn.server.resourcemanager.ClientRMService: Allocated new applicationId: 2
2013-08-10 17:10:55,453 INFO org.apache.hadoop.yarn.server.resourcemanager.rmcontainer.RMContainerImpl: container_1376154442901_0001_01_000001 Container Transitioned from RUNNING to COMPLETED
2013-08-10 17:10:55,453 INFO org.apache.hadoop.yarn.server.resourcemanager.scheduler.common.fica.FiCaSchedulerApp: Completed container: container_1376154442901_0001_01_000001 in state: COMPLETED event:FINISHED
2013-08-10 17:10:55,453 INFO org.apache.hadoop.yarn.server.resourcemanager.RMAuditLogger: USER=ubuntu	OPERATION=AM Released Container	TARGET=SchedulerApp	RESULT=SUCCESS	APPID=application_1376154442901_0001	CONTAINERID=container_1376154442901_0001_01_000001
2013-08-10 17:10:55,454 INFO org.apache.hadoop.yarn.server.resourcemanager.scheduler.common.fica.FiCaSchedulerNode: Released container container_1376154442901_0001_01_000001 of capacity <memory:2048, vCores:1> on host hadoop-220-2:50762, which currently has 0 containers, <memory:0, vCores:0> used and <memory:8192, vCores:16> available, release resources=true
2013-08-10 17:10:55,454 INFO org.apache.hadoop.yarn.server.resourcemanager.scheduler.capacity.LeafQueue: default used=<memory:0, vCores:0> numContainers=0 user=ubuntu user-resources=<memory:0, vCores:0>
2013-08-10 17:10:55,456 INFO org.apache.hadoop.yarn.server.resourcemanager.rmapp.attempt.RMAppAttemptImpl: appattempt_1376154442901_0001_000001 State change from FINISHING to FINISHED
2013-08-10 17:10:55,456 INFO org.apache.hadoop.yarn.server.resourcemanager.scheduler.capacity.LeafQueue: completedContainer container=Container: [ContainerId: container_1376154442901_0001_01_000001, NodeId: hadoop-220-2:50762, NodeHttpAddress: hadoop-220-2:8042, Resource: <memory:2048, vCores:1>, Priority: 0, State: NEW, Token: null, Status: container_id {, app_attempt_id {, application_id {, id: 1, cluster_timestamp: 1376154442901, }, attemptId: 1, }, id: 1, }, state: C_COMPLETE, diagnostics: "", exit_status: 0, ] resource=<memory:2048, vCores:1> queue=default: capacity=1.0, absoluteCapacity=1.0, usedResources=<memory:0, vCores:0>usedCapacity=0.0, absoluteUsedCapacity=0.0, numApps=1, numContainers=0 usedCapacity=0.0 absoluteUsedCapacity=0.0 used=<memory:0, vCores:0> cluster=<memory:49152, vCores:96>
2013-08-10 17:10:55,457 INFO org.apache.hadoop.yarn.server.resourcemanager.scheduler.capacity.ParentQueue: completedContainer queue=root usedCapacity=0.0 absoluteUsedCapacity=0.0 used=<memory:0, vCores:0> cluster=<memory:49152, vCores:96>
2013-08-10 17:10:55,457 INFO org.apache.hadoop.yarn.server.resourcemanager.scheduler.capacity.CapacityScheduler: Application appattempt_1376154442901_0001_000001 released container container_1376154442901_0001_01_000001 on node: host: hadoop-220-2:50762 #containers=0 available=8192 used=0 with event: FINISHED
2013-08-10 17:10:55,458 INFO org.apache.hadoop.yarn.server.resourcemanager.rmapp.RMAppImpl: application_1376154442901_0001 State change from FINISHING to FINISHED
2013-08-10 17:10:55,459 INFO org.apache.hadoop.yarn.server.resourcemanager.scheduler.capacity.CapacityScheduler: Application appattempt_1376154442901_0001_000001 is done. finalState=FINISHED
2013-08-10 17:10:55,460 INFO org.apache.hadoop.yarn.server.resourcemanager.RMAuditLogger: USER=ubuntu	OPERATION=Application Finished - Succeeded	TARGET=RMAppManager	RESULT=SUCCESS	APPID=application_1376154442901_0001
2013-08-10 17:10:55,460 INFO org.apache.hadoop.yarn.server.resourcemanager.amlauncher.AMLauncher: Cleaning master appattempt_1376154442901_0001_000001
2013-08-10 17:10:55,465 INFO org.apache.hadoop.yarn.server.resourcemanager.scheduler.AppSchedulingInfo: Application application_1376154442901_0001 requests cleared
2013-08-10 17:10:55,466 INFO org.apache.hadoop.yarn.server.resourcemanager.scheduler.capacity.LeafQueue: Application removed - appId: application_1376154442901_0001 user: ubuntu queue: default #user-pending-applications: 0 #user-active-applications: 0 #queue-pending-applications: 0 #queue-active-applications: 0
2013-08-10 17:10:55,466 INFO org.apache.hadoop.yarn.server.resourcemanager.scheduler.capacity.ParentQueue: Application removed - appId: application_1376154442901_0001 user: ubuntu leaf-queue of parent: root #applications: 0
2013-08-10 17:10:55,469 INFO org.apache.hadoop.yarn.server.resourcemanager.recovery.RMStateStore: Removing info for app: application_1376154442901_0001
2013-08-10 17:10:55,473 INFO org.apache.hadoop.yarn.server.resourcemanager.RMAppManager$ApplicationSummary: appId=application_1376154442901_0001,name=TeraGen,user=ubuntu,queue=default,state=FINISHED,trackingUrl=hadoop-220-1.novalocal:8088/proxy/application_1376154442901_0001/jobhistory/job/job_1376154442901_0001,appMasterHost=hadoop-220-2,startTime=1376154468785,finishTime=1376154654749
2013-08-10 17:10:57,126 INFO org.apache.hadoop.yarn.server.resourcemanager.ClientRMService: Storing Application with id application_1376154442901_0002
2013-08-10 17:10:57,126 INFO org.apache.hadoop.yarn.server.resourcemanager.recovery.RMStateStore: Storing info for app: application_1376154442901_0002
2013-08-10 17:10:57,126 INFO org.apache.hadoop.yarn.server.resourcemanager.ClientRMService: Application with id 2 submitted by user ubuntu
2013-08-10 17:10:57,126 INFO org.apache.hadoop.yarn.server.resourcemanager.RMAuditLogger: USER=ubuntu	IP=192.168.100.9	OPERATION=Submit Application Request	TARGET=ClientRMService	RESULT=SUCCESS	APPID=application_1376154442901_0002
2013-08-10 17:10:57,128 INFO org.apache.hadoop.yarn.server.resourcemanager.rmapp.RMAppImpl: application_1376154442901_0002 State change from NEW to SUBMITTED
2013-08-10 17:10:57,129 INFO org.apache.hadoop.yarn.server.resourcemanager.ApplicationMasterService: Registering appattempt_1376154442901_0002_000001
2013-08-10 17:10:57,129 INFO org.apache.hadoop.yarn.server.resourcemanager.rmapp.attempt.RMAppAttemptImpl: appattempt_1376154442901_0002_000001 State change from NEW to SUBMITTED
2013-08-10 17:10:57,131 INFO org.apache.hadoop.yarn.server.resourcemanager.scheduler.capacity.LeafQueue: Application application_1376154442901_0002 from user: ubuntu activated in queue: default
2013-08-10 17:10:57,131 INFO org.apache.hadoop.yarn.server.resourcemanager.scheduler.capacity.LeafQueue: Application added - appId: application_1376154442901_0002 user: org.apache.hadoop.yarn.server.resourcemanager.scheduler.capacity.LeafQueue$User@3e5cff19, leaf-queue: default #user-pending-applications: 0 #user-active-applications: 1 #queue-pending-applications: 0 #queue-active-applications: 1
2013-08-10 17:10:57,131 INFO org.apache.hadoop.yarn.server.resourcemanager.scheduler.capacity.ParentQueue: Application added - appId: application_1376154442901_0002 user: ubuntu leaf-queue of parent: root #applications: 1
2013-08-10 17:10:57,131 INFO org.apache.hadoop.yarn.server.resourcemanager.scheduler.capacity.CapacityScheduler: Application Submission: appattempt_1376154442901_0002_000001, user: ubuntu queue: default: capacity=1.0, absoluteCapacity=1.0, usedResources=<memory:0, vCores:0>usedCapacity=0.0, absoluteUsedCapacity=0.0, numApps=1, numContainers=0, currently active: 1
2013-08-10 17:10:57,132 INFO org.apache.hadoop.yarn.server.resourcemanager.rmapp.attempt.RMAppAttemptImpl: appattempt_1376154442901_0002_000001 State change from SUBMITTED to SCHEDULED
2013-08-10 17:10:57,132 INFO org.apache.hadoop.yarn.server.resourcemanager.rmapp.RMAppImpl: application_1376154442901_0002 State change from SUBMITTED to ACCEPTED
2013-08-10 17:10:57,464 INFO org.apache.hadoop.yarn.server.resourcemanager.rmcontainer.RMContainerImpl: container_1376154442901_0002_01_000001 Container Transitioned from NEW to ALLOCATED
2013-08-10 17:10:57,465 INFO org.apache.hadoop.yarn.server.resourcemanager.RMAuditLogger: USER=ubuntu	OPERATION=AM Allocated Container	TARGET=SchedulerApp	RESULT=SUCCESS	APPID=application_1376154442901_0002	CONTAINERID=container_1376154442901_0002_01_000001
2013-08-10 17:10:57,465 INFO org.apache.hadoop.yarn.server.resourcemanager.scheduler.common.fica.FiCaSchedulerNode: Assigned container container_1376154442901_0002_01_000001 of capacity <memory:2048, vCores:1> on host hadoop-220-2:50762, which currently has 1 containers, <memory:2048, vCores:1> used and <memory:6144, vCores:15> available
2013-08-10 17:10:57,467 INFO org.apache.hadoop.yarn.server.resourcemanager.scheduler.capacity.LeafQueue: assignedContainer application=application_1376154442901_0002 container=Container: [ContainerId: container_1376154442901_0002_01_000001, NodeId: hadoop-220-2:50762, NodeHttpAddress: hadoop-220-2:8042, Resource: <memory:2048, vCores:1>, Priority: 0, State: NEW, Token: null, Status: container_id {, app_attempt_id {, application_id {, id: 2, cluster_timestamp: 1376154442901, }, attemptId: 1, }, id: 1, }, state: C_NEW, ] containerId=container_1376154442901_0002_01_000001 queue=default: capacity=1.0, absoluteCapacity=1.0, usedResources=<memory:0, vCores:0>usedCapacity=0.0, absoluteUsedCapacity=0.0, numApps=1, numContainers=0 usedCapacity=0.0 absoluteUsedCapacity=0.0 used=<memory:0, vCores:0> cluster=<memory:49152, vCores:96>
2013-08-10 17:10:57,468 INFO org.apache.hadoop.yarn.server.resourcemanager.scheduler.capacity.ParentQueue: Re-sorting queues since queue: root.default stats: default: capacity=1.0, absoluteCapacity=1.0, usedResources=<memory:2048, vCores:1>usedCapacity=0.041666668, absoluteUsedCapacity=0.041666668, numApps=1, numContainers=1
2013-08-10 17:10:57,469 INFO org.apache.hadoop.yarn.server.resourcemanager.rmcontainer.RMContainerImpl: container_1376154442901_0002_01_000001 Container Transitioned from ALLOCATED to ACQUIRED
2013-08-10 17:10:57,471 INFO org.apache.hadoop.yarn.server.resourcemanager.rmapp.attempt.RMAppAttemptImpl: Storing attempt: AppId: application_1376154442901_0002 AttemptId: appattempt_1376154442901_0002_000001 MasterContainer: Container: [ContainerId: container_1376154442901_0002_01_000001, NodeId: hadoop-220-2:50762, NodeHttpAddress: hadoop-220-2:8042, Resource: <memory:2048, vCores:1>, Priority: 0, State: NEW, Token: null, Status: container_id {, app_attempt_id {, application_id {, id: 2, cluster_timestamp: 1376154442901, }, attemptId: 1, }, id: 1, }, state: C_NEW, ]
2013-08-10 17:10:57,471 INFO org.apache.hadoop.yarn.server.resourcemanager.rmapp.attempt.RMAppAttemptImpl: appattempt_1376154442901_0002_000001 State change from SCHEDULED to ALLOCATED_SAVING
2013-08-10 17:10:57,472 INFO org.apache.hadoop.yarn.server.resourcemanager.recovery.RMStateStore: Storing info for attempt: appattempt_1376154442901_0002_000001
2013-08-10 17:10:57,472 INFO org.apache.hadoop.yarn.server.resourcemanager.scheduler.capacity.ParentQueue: assignedContainer queue=root usedCapacity=0.041666668 absoluteUsedCapacity=0.041666668 used=<memory:2048, vCores:1> cluster=<memory:49152, vCores:96>
2013-08-10 17:10:57,473 INFO org.apache.hadoop.yarn.server.resourcemanager.rmapp.attempt.RMAppAttemptImpl: appattempt_1376154442901_0002_000001 State change from ALLOCATED_SAVING to ALLOCATED
2013-08-10 17:10:57,475 INFO org.apache.hadoop.yarn.server.resourcemanager.amlauncher.AMLauncher: Launching masterappattempt_1376154442901_0002_000001
2013-08-10 17:10:57,478 INFO org.apache.hadoop.yarn.server.resourcemanager.amlauncher.AMLauncher: Setting up container Container: [ContainerId: container_1376154442901_0002_01_000001, NodeId: hadoop-220-2:50762, NodeHttpAddress: hadoop-220-2:8042, Resource: <memory:2048, vCores:1>, Priority: 0, State: NEW, Token: null, Status: container_id {, app_attempt_id {, application_id {, id: 2, cluster_timestamp: 1376154442901, }, attemptId: 1, }, id: 1, }, state: C_NEW, ] for AM appattempt_1376154442901_0002_000001
2013-08-10 17:10:57,478 INFO org.apache.hadoop.yarn.server.resourcemanager.amlauncher.AMLauncher: Command to launch container container_1376154442901_0002_01_000001 : $JAVA_HOME/bin/java -Dlog4j.configuration=container-log4j.properties -Dyarn.app.mapreduce.container.log.dir=<LOG_DIR> -Dyarn.app.mapreduce.container.log.filesize=0 -Dhadoop.root.logger=INFO,CLA  -Xmx1024m org.apache.hadoop.mapreduce.v2.app.MRAppMaster 1><LOG_DIR>/stdout 2><LOG_DIR>/stderr 
2013-08-10 17:10:57,497 INFO org.apache.hadoop.yarn.server.resourcemanager.amlauncher.AMLauncher: Done launching container Container: [ContainerId: container_1376154442901_0002_01_000001, NodeId: hadoop-220-2:50762, NodeHttpAddress: hadoop-220-2:8042, Resource: <memory:2048, vCores:1>, Priority: 0, State: NEW, Token: null, Status: container_id {, app_attempt_id {, application_id {, id: 2, cluster_timestamp: 1376154442901, }, attemptId: 1, }, id: 1, }, state: C_NEW, ] for AM appattempt_1376154442901_0002_000001
2013-08-10 17:10:57,497 INFO org.apache.hadoop.yarn.server.resourcemanager.rmapp.attempt.RMAppAttemptImpl: appattempt_1376154442901_0002_000001 State change from ALLOCATED to LAUNCHED
2013-08-10 17:10:58,471 INFO org.apache.hadoop.yarn.server.resourcemanager.rmcontainer.RMContainerImpl: container_1376154442901_0002_01_000001 Container Transitioned from ACQUIRED to RUNNING
2013-08-10 17:11:03,597 INFO org.apache.hadoop.yarn.server.resourcemanager.ApplicationMasterService: AM registration appattempt_1376154442901_0002_000001
2013-08-10 17:11:03,597 INFO org.apache.hadoop.yarn.server.resourcemanager.RMAuditLogger: USER=ubuntu	IP=192.168.100.15	OPERATION=Register App Master	TARGET=ApplicationMasterService	RESULT=SUCCESS	APPID=application_1376154442901_0002	APPATTEMPTID=appattempt_1376154442901_0002_000001
2013-08-10 17:11:03,599 INFO org.apache.hadoop.yarn.server.resourcemanager.rmapp.attempt.RMAppAttemptImpl: appattempt_1376154442901_0002_000001 State change from LAUNCHED to RUNNING
2013-08-10 17:11:03,599 INFO org.apache.hadoop.yarn.server.resourcemanager.rmapp.RMAppImpl: application_1376154442901_0002 State change from ACCEPTED to RUNNING
2013-08-10 17:11:04,653 INFO org.apache.hadoop.yarn.server.resourcemanager.rmcontainer.RMContainerImpl: container_1376154442901_0002_01_000002 Container Transitioned from NEW to ALLOCATED
2013-08-10 17:11:04,653 INFO org.apache.hadoop.yarn.server.resourcemanager.RMAuditLogger: USER=ubuntu	OPERATION=AM Allocated Container	TARGET=SchedulerApp	RESULT=SUCCESS	APPID=application_1376154442901_0002	CONTAINERID=container_1376154442901_0002_01_000002
2013-08-10 17:11:04,653 INFO org.apache.hadoop.yarn.server.resourcemanager.scheduler.common.fica.FiCaSchedulerNode: Assigned container container_1376154442901_0002_01_000002 of capacity <memory:1024, vCores:1> on host hadoop-220-4:35716, which currently has 1 containers, <memory:1024, vCores:1> used and <memory:7168, vCores:15> available
2013-08-10 17:11:04,655 INFO org.apache.hadoop.yarn.server.resourcemanager.scheduler.capacity.LeafQueue: assignedContainer application=application_1376154442901_0002 container=Container: [ContainerId: container_1376154442901_0002_01_000002, NodeId: hadoop-220-4:35716, NodeHttpAddress: hadoop-220-4:8042, Resource: <memory:1024, vCores:1>, Priority: 20, State: NEW, Token: null, Status: container_id {, app_attempt_id {, application_id {, id: 2, cluster_timestamp: 1376154442901, }, attemptId: 1, }, id: 2, }, state: C_NEW, ] containerId=container_1376154442901_0002_01_000002 queue=default: capacity=1.0, absoluteCapacity=1.0, usedResources=<memory:2048, vCores:1>usedCapacity=0.041666668, absoluteUsedCapacity=0.041666668, numApps=1, numContainers=1 usedCapacity=0.041666668 absoluteUsedCapacity=0.041666668 used=<memory:2048, vCores:1> cluster=<memory:49152, vCores:96>
2013-08-10 17:11:04,655 INFO org.apache.hadoop.yarn.server.resourcemanager.scheduler.capacity.ParentQueue: Re-sorting queues since queue: root.default stats: default: capacity=1.0, absoluteCapacity=1.0, usedResources=<memory:3072, vCores:2>usedCapacity=0.0625, absoluteUsedCapacity=0.0625, numApps=1, numContainers=2
2013-08-10 17:11:04,655 INFO org.apache.hadoop.yarn.server.resourcemanager.scheduler.capacity.ParentQueue: assignedContainer queue=root usedCapacity=0.0625 absoluteUsedCapacity=0.0625 used=<memory:3072, vCores:2> cluster=<memory:49152, vCores:96>
2013-08-10 17:11:04,722 INFO org.apache.hadoop.yarn.server.resourcemanager.rmcontainer.RMContainerImpl: container_1376154442901_0002_01_000003 Container Transitioned from NEW to ALLOCATED
2013-08-10 17:11:04,722 INFO org.apache.hadoop.yarn.server.resourcemanager.RMAuditLogger: USER=ubuntu	OPERATION=AM Allocated Container	TARGET=SchedulerApp	RESULT=SUCCESS	APPID=application_1376154442901_0002	CONTAINERID=container_1376154442901_0002_01_000003
2013-08-10 17:11:04,723 INFO org.apache.hadoop.yarn.server.resourcemanager.scheduler.common.fica.FiCaSchedulerNode: Assigned container container_1376154442901_0002_01_000003 of capacity <memory:1024, vCores:1> on host hadoop-220-7:42517, which currently has 1 containers, <memory:1024, vCores:1> used and <memory:7168, vCores:15> available
2013-08-10 17:11:04,724 INFO org.apache.hadoop.yarn.server.resourcemanager.scheduler.capacity.LeafQueue: assignedContainer application=application_1376154442901_0002 container=Container: [ContainerId: container_1376154442901_0002_01_000003, NodeId: hadoop-220-7:42517, NodeHttpAddress: hadoop-220-7:8042, Resource: <memory:1024, vCores:1>, Priority: 20, State: NEW, Token: null, Status: container_id {, app_attempt_id {, application_id {, id: 2, cluster_timestamp: 1376154442901, }, attemptId: 1, }, id: 3, }, state: C_NEW, ] containerId=container_1376154442901_0002_01_000003 queue=default: capacity=1.0, absoluteCapacity=1.0, usedResources=<memory:3072, vCores:2>usedCapacity=0.0625, absoluteUsedCapacity=0.0625, numApps=1, numContainers=2 usedCapacity=0.0625 absoluteUsedCapacity=0.0625 used=<memory:3072, vCores:2> cluster=<memory:49152, vCores:96>
2013-08-10 17:11:04,724 INFO org.apache.hadoop.yarn.server.resourcemanager.scheduler.capacity.ParentQueue: Re-sorting queues since queue: root.default stats: default: capacity=1.0, absoluteCapacity=1.0, usedResources=<memory:4096, vCores:3>usedCapacity=0.083333336, absoluteUsedCapacity=0.083333336, numApps=1, numContainers=3
2013-08-10 17:11:04,725 INFO org.apache.hadoop.yarn.server.resourcemanager.scheduler.capacity.ParentQueue: assignedContainer queue=root usedCapacity=0.083333336 absoluteUsedCapacity=0.083333336 used=<memory:4096, vCores:3> cluster=<memory:49152, vCores:96>
2013-08-10 17:11:05,660 INFO org.apache.hadoop.yarn.server.resourcemanager.rmcontainer.RMContainerImpl: container_1376154442901_0002_01_000002 Container Transitioned from ALLOCATED to ACQUIRED
2013-08-10 17:11:05,662 INFO org.apache.hadoop.yarn.server.resourcemanager.rmcontainer.RMContainerImpl: container_1376154442901_0002_01_000003 Container Transitioned from ALLOCATED to ACQUIRED
2013-08-10 17:11:06,662 INFO org.apache.hadoop.yarn.server.resourcemanager.rmcontainer.RMContainerImpl: container_1376154442901_0002_01_000002 Container Transitioned from ACQUIRED to RUNNING
2013-08-10 17:11:06,689 INFO org.apache.hadoop.yarn.server.resourcemanager.scheduler.AppSchedulingInfo: checking for deactivate... 
2013-08-10 17:11:06,746 INFO org.apache.hadoop.yarn.server.resourcemanager.rmcontainer.RMContainerImpl: container_1376154442901_0002_01_000003 Container Transitioned from ACQUIRED to RUNNING
2013-08-10 17:13:45,857 INFO org.apache.hadoop.yarn.server.resourcemanager.rmcontainer.RMContainerImpl: container_1376154442901_0002_01_000002 Container Transitioned from RUNNING to COMPLETED
2013-08-10 17:13:45,857 INFO org.apache.hadoop.yarn.server.resourcemanager.scheduler.common.fica.FiCaSchedulerApp: Completed container: container_1376154442901_0002_01_000002 in state: COMPLETED event:FINISHED
2013-08-10 17:13:45,857 INFO org.apache.hadoop.yarn.server.resourcemanager.RMAuditLogger: USER=ubuntu	OPERATION=AM Released Container	TARGET=SchedulerApp	RESULT=SUCCESS	APPID=application_1376154442901_0002	CONTAINERID=container_1376154442901_0002_01_000002
2013-08-10 17:13:45,858 INFO org.apache.hadoop.yarn.server.resourcemanager.scheduler.common.fica.FiCaSchedulerNode: Released container container_1376154442901_0002_01_000002 of capacity <memory:1024, vCores:1> on host hadoop-220-4:35716, which currently has 0 containers, <memory:0, vCores:0> used and <memory:8192, vCores:16> available, release resources=true
2013-08-10 17:13:45,858 INFO org.apache.hadoop.yarn.server.resourcemanager.scheduler.capacity.LeafQueue: default used=<memory:3072, vCores:2> numContainers=2 user=ubuntu user-resources=<memory:3072, vCores:2>
2013-08-10 17:13:45,871 INFO org.apache.hadoop.yarn.server.resourcemanager.scheduler.capacity.LeafQueue: completedContainer container=Container: [ContainerId: container_1376154442901_0002_01_000002, NodeId: hadoop-220-4:35716, NodeHttpAddress: hadoop-220-4:8042, Resource: <memory:1024, vCores:1>, Priority: 20, State: NEW, Token: null, Status: container_id {, app_attempt_id {, application_id {, id: 2, cluster_timestamp: 1376154442901, }, attemptId: 1, }, id: 2, }, state: C_COMPLETE, diagnostics: "Container killed by the ApplicationMaster.\n", exit_status: 0, ] resource=<memory:1024, vCores:1> queue=default: capacity=1.0, absoluteCapacity=1.0, usedResources=<memory:3072, vCores:2>usedCapacity=0.0625, absoluteUsedCapacity=0.0625, numApps=1, numContainers=2 usedCapacity=0.0625 absoluteUsedCapacity=0.0625 used=<memory:3072, vCores:2> cluster=<memory:49152, vCores:96>
2013-08-10 17:13:45,872 INFO org.apache.hadoop.yarn.server.resourcemanager.scheduler.capacity.ParentQueue: completedContainer queue=root usedCapacity=0.0625 absoluteUsedCapacity=0.0625 used=<memory:3072, vCores:2> cluster=<memory:49152, vCores:96>
2013-08-10 17:13:45,872 INFO org.apache.hadoop.yarn.server.resourcemanager.scheduler.capacity.CapacityScheduler: Application appattempt_1376154442901_0002_000001 released container container_1376154442901_0002_01_000002 on node: host: hadoop-220-4:35716 #containers=0 available=8192 used=0 with event: FINISHED
2013-08-10 17:13:56,529 INFO org.apache.hadoop.yarn.server.resourcemanager.rmcontainer.RMContainerImpl: container_1376154442901_0002_01_000003 Container Transitioned from RUNNING to COMPLETED
2013-08-10 17:13:56,529 INFO org.apache.hadoop.yarn.server.resourcemanager.scheduler.common.fica.FiCaSchedulerApp: Completed container: container_1376154442901_0002_01_000003 in state: COMPLETED event:FINISHED
2013-08-10 17:13:56,530 INFO org.apache.hadoop.yarn.server.resourcemanager.RMAuditLogger: USER=ubuntu	OPERATION=AM Released Container	TARGET=SchedulerApp	RESULT=SUCCESS	APPID=application_1376154442901_0002	CONTAINERID=container_1376154442901_0002_01_000003
2013-08-10 17:13:56,530 INFO org.apache.hadoop.yarn.server.resourcemanager.scheduler.common.fica.FiCaSchedulerNode: Released container container_1376154442901_0002_01_000003 of capacity <memory:1024, vCores:1> on host hadoop-220-7:42517, which currently has 0 containers, <memory:0, vCores:0> used and <memory:8192, vCores:16> available, release resources=true
2013-08-10 17:13:56,530 INFO org.apache.hadoop.yarn.server.resourcemanager.scheduler.capacity.LeafQueue: default used=<memory:2048, vCores:1> numContainers=1 user=ubuntu user-resources=<memory:2048, vCores:1>
2013-08-10 17:13:56,532 INFO org.apache.hadoop.yarn.server.resourcemanager.scheduler.capacity.LeafQueue: completedContainer container=Container: [ContainerId: container_1376154442901_0002_01_000003, NodeId: hadoop-220-7:42517, NodeHttpAddress: hadoop-220-7:8042, Resource: <memory:1024, vCores:1>, Priority: 20, State: NEW, Token: null, Status: container_id {, app_attempt_id {, application_id {, id: 2, cluster_timestamp: 1376154442901, }, attemptId: 1, }, id: 3, }, state: C_COMPLETE, diagnostics: "Container killed by the ApplicationMaster.\n\n", exit_status: 143, ] resource=<memory:1024, vCores:1> queue=default: capacity=1.0, absoluteCapacity=1.0, usedResources=<memory:2048, vCores:1>usedCapacity=0.041666668, absoluteUsedCapacity=0.041666668, numApps=1, numContainers=1 usedCapacity=0.041666668 absoluteUsedCapacity=0.041666668 used=<memory:2048, vCores:1> cluster=<memory:49152, vCores:96>
2013-08-10 17:13:56,532 INFO org.apache.hadoop.yarn.server.resourcemanager.scheduler.capacity.ParentQueue: completedContainer queue=root usedCapacity=0.041666668 absoluteUsedCapacity=0.041666668 used=<memory:2048, vCores:1> cluster=<memory:49152, vCores:96>
2013-08-10 17:13:56,533 INFO org.apache.hadoop.yarn.server.resourcemanager.scheduler.capacity.CapacityScheduler: Application appattempt_1376154442901_0002_000001 released container container_1376154442901_0002_01_000003 on node: host: hadoop-220-7:42517 #containers=0 available=8192 used=0 with event: FINISHED
2013-08-10 17:14:00,703 INFO org.apache.hadoop.yarn.server.resourcemanager.rmapp.attempt.RMAppAttemptImpl: appattempt_1376154442901_0002_000001 State change from RUNNING to FINISHING
2013-08-10 17:14:00,704 INFO org.apache.hadoop.yarn.server.resourcemanager.rmapp.RMAppImpl: application_1376154442901_0002 State change from RUNNING to FINISHING
2013-08-10 17:14:01,377 INFO org.apache.hadoop.yarn.server.resourcemanager.rmcontainer.RMContainerImpl: container_1376154442901_0002_01_000001 Container Transitioned from RUNNING to COMPLETED
2013-08-10 17:14:01,377 INFO org.apache.hadoop.yarn.server.resourcemanager.scheduler.common.fica.FiCaSchedulerApp: Completed container: container_1376154442901_0002_01_000001 in state: COMPLETED event:FINISHED
2013-08-10 17:14:01,377 INFO org.apache.hadoop.yarn.server.resourcemanager.rmapp.attempt.RMAppAttemptImpl: appattempt_1376154442901_0002_000001 State change from FINISHING to FINISHED
2013-08-10 17:14:01,377 INFO org.apache.hadoop.yarn.server.resourcemanager.RMAuditLogger: USER=ubuntu	OPERATION=AM Released Container	TARGET=SchedulerApp	RESULT=SUCCESS	APPID=application_1376154442901_0002	CONTAINERID=container_1376154442901_0002_01_000001
2013-08-10 17:14:01,378 INFO org.apache.hadoop.yarn.server.resourcemanager.rmapp.RMAppImpl: application_1376154442901_0002 State change from FINISHING to FINISHED
2013-08-10 17:14:01,378 INFO org.apache.hadoop.yarn.server.resourcemanager.scheduler.common.fica.FiCaSchedulerNode: Released container container_1376154442901_0002_01_000001 of capacity <memory:2048, vCores:1> on host hadoop-220-2:50762, which currently has 0 containers, <memory:0, vCores:0> used and <memory:8192, vCores:16> available, release resources=true
2013-08-10 17:14:01,378 INFO org.apache.hadoop.yarn.server.resourcemanager.scheduler.capacity.LeafQueue: default used=<memory:0, vCores:0> numContainers=0 user=ubuntu user-resources=<memory:0, vCores:0>
2013-08-10 17:14:01,378 INFO org.apache.hadoop.yarn.server.resourcemanager.RMAuditLogger: USER=ubuntu	OPERATION=Application Finished - Succeeded	TARGET=RMAppManager	RESULT=SUCCESS	APPID=application_1376154442901_0002
2013-08-10 17:14:01,379 INFO org.apache.hadoop.yarn.server.resourcemanager.recovery.RMStateStore: Removing info for app: application_1376154442901_0002
2013-08-10 17:14:01,379 INFO org.apache.hadoop.yarn.server.resourcemanager.RMAppManager$ApplicationSummary: appId=application_1376154442901_0002,name=TeraGen,user=ubuntu,queue=default,state=FINISHED,trackingUrl=hadoop-220-1.novalocal:8088/proxy/application_1376154442901_0002/jobhistory/job/job_1376154442901_0002,appMasterHost=hadoop-220-2,startTime=1376154657125,finishTime=1376154840704
2013-08-10 17:14:01,379 INFO org.apache.hadoop.yarn.server.resourcemanager.amlauncher.AMLauncher: Cleaning master appattempt_1376154442901_0002_000001
2013-08-10 17:14:01,380 INFO org.apache.hadoop.yarn.server.resourcemanager.scheduler.capacity.LeafQueue: completedContainer container=Container: [ContainerId: container_1376154442901_0002_01_000001, NodeId: hadoop-220-2:50762, NodeHttpAddress: hadoop-220-2:8042, Resource: <memory:2048, vCores:1>, Priority: 0, State: NEW, Token: null, Status: container_id {, app_attempt_id {, application_id {, id: 2, cluster_timestamp: 1376154442901, }, attemptId: 1, }, id: 1, }, state: C_COMPLETE, diagnostics: "", exit_status: 0, ] resource=<memory:2048, vCores:1> queue=default: capacity=1.0, absoluteCapacity=1.0, usedResources=<memory:0, vCores:0>usedCapacity=0.0, absoluteUsedCapacity=0.0, numApps=1, numContainers=0 usedCapacity=0.0 absoluteUsedCapacity=0.0 used=<memory:0, vCores:0> cluster=<memory:49152, vCores:96>
2013-08-10 17:14:01,380 INFO org.apache.hadoop.yarn.server.resourcemanager.scheduler.capacity.ParentQueue: completedContainer queue=root usedCapacity=0.0 absoluteUsedCapacity=0.0 used=<memory:0, vCores:0> cluster=<memory:49152, vCores:96>
2013-08-10 17:14:01,380 INFO org.apache.hadoop.yarn.server.resourcemanager.scheduler.capacity.CapacityScheduler: Application appattempt_1376154442901_0002_000001 released container container_1376154442901_0002_01_000001 on node: host: hadoop-220-2:50762 #containers=0 available=8192 used=0 with event: FINISHED
2013-08-10 17:14:01,381 INFO org.apache.hadoop.yarn.server.resourcemanager.scheduler.capacity.CapacityScheduler: Application appattempt_1376154442901_0002_000001 is done. finalState=FINISHED
2013-08-10 17:14:01,381 INFO org.apache.hadoop.yarn.server.resourcemanager.scheduler.AppSchedulingInfo: Application application_1376154442901_0002 requests cleared
2013-08-10 17:14:01,381 INFO org.apache.hadoop.yarn.server.resourcemanager.scheduler.capacity.LeafQueue: Application removed - appId: application_1376154442901_0002 user: ubuntu queue: default #user-pending-applications: 0 #user-active-applications: 0 #queue-pending-applications: 0 #queue-active-applications: 0
2013-08-10 17:14:01,381 INFO org.apache.hadoop.yarn.server.resourcemanager.scheduler.capacity.ParentQueue: Application removed - appId: application_1376154442901_0002 user: ubuntu leaf-queue of parent: root #applications: 0
2013-08-10 17:14:01,988 INFO org.apache.hadoop.yarn.server.resourcemanager.ClientRMService: Allocated new applicationId: 3
2013-08-10 17:14:03,966 INFO org.apache.hadoop.yarn.server.resourcemanager.ClientRMService: Storing Application with id application_1376154442901_0003
2013-08-10 17:14:03,966 INFO org.apache.hadoop.yarn.server.resourcemanager.recovery.RMStateStore: Storing info for app: application_1376154442901_0003
2013-08-10 17:14:03,966 INFO org.apache.hadoop.yarn.server.resourcemanager.ClientRMService: Application with id 3 submitted by user ubuntu
2013-08-10 17:14:03,967 INFO org.apache.hadoop.yarn.server.resourcemanager.RMAuditLogger: USER=ubuntu	IP=192.168.100.9	OPERATION=Submit Application Request	TARGET=ClientRMService	RESULT=SUCCESS	APPID=application_1376154442901_0003
2013-08-10 17:14:03,968 INFO org.apache.hadoop.yarn.server.resourcemanager.rmapp.RMAppImpl: application_1376154442901_0003 State change from NEW to SUBMITTED
2013-08-10 17:14:03,969 INFO org.apache.hadoop.yarn.server.resourcemanager.ApplicationMasterService: Registering appattempt_1376154442901_0003_000001
2013-08-10 17:14:03,970 INFO org.apache.hadoop.yarn.server.resourcemanager.rmapp.attempt.RMAppAttemptImpl: appattempt_1376154442901_0003_000001 State change from NEW to SUBMITTED
2013-08-10 17:14:03,970 INFO org.apache.hadoop.yarn.server.resourcemanager.scheduler.capacity.LeafQueue: Application application_1376154442901_0003 from user: ubuntu activated in queue: default
2013-08-10 17:14:03,970 INFO org.apache.hadoop.yarn.server.resourcemanager.scheduler.capacity.LeafQueue: Application added - appId: application_1376154442901_0003 user: org.apache.hadoop.yarn.server.resourcemanager.scheduler.capacity.LeafQueue$User@1df9adb4, leaf-queue: default #user-pending-applications: 0 #user-active-applications: 1 #queue-pending-applications: 0 #queue-active-applications: 1
2013-08-10 17:14:03,970 INFO org.apache.hadoop.yarn.server.resourcemanager.scheduler.capacity.ParentQueue: Application added - appId: application_1376154442901_0003 user: ubuntu leaf-queue of parent: root #applications: 1
2013-08-10 17:14:03,971 INFO org.apache.hadoop.yarn.server.resourcemanager.scheduler.capacity.CapacityScheduler: Application Submission: appattempt_1376154442901_0003_000001, user: ubuntu queue: default: capacity=1.0, absoluteCapacity=1.0, usedResources=<memory:0, vCores:0>usedCapacity=0.0, absoluteUsedCapacity=0.0, numApps=1, numContainers=0, currently active: 1
2013-08-10 17:14:03,971 INFO org.apache.hadoop.yarn.server.resourcemanager.rmapp.attempt.RMAppAttemptImpl: appattempt_1376154442901_0003_000001 State change from SUBMITTED to SCHEDULED
2013-08-10 17:14:03,971 INFO org.apache.hadoop.yarn.server.resourcemanager.rmapp.RMAppImpl: application_1376154442901_0003 State change from SUBMITTED to ACCEPTED
2013-08-10 17:14:04,388 INFO org.apache.hadoop.yarn.server.resourcemanager.rmcontainer.RMContainerImpl: container_1376154442901_0003_01_000001 Container Transitioned from NEW to ALLOCATED
2013-08-10 17:14:04,388 INFO org.apache.hadoop.yarn.server.resourcemanager.RMAuditLogger: USER=ubuntu	OPERATION=AM Allocated Container	TARGET=SchedulerApp	RESULT=SUCCESS	APPID=application_1376154442901_0003	CONTAINERID=container_1376154442901_0003_01_000001
2013-08-10 17:14:04,389 INFO org.apache.hadoop.yarn.server.resourcemanager.scheduler.common.fica.FiCaSchedulerNode: Assigned container container_1376154442901_0003_01_000001 of capacity <memory:2048, vCores:1> on host hadoop-220-2:50762, which currently has 1 containers, <memory:2048, vCores:1> used and <memory:6144, vCores:15> available
2013-08-10 17:14:04,390 INFO org.apache.hadoop.yarn.server.resourcemanager.scheduler.capacity.LeafQueue: assignedContainer application=application_1376154442901_0003 container=Container: [ContainerId: container_1376154442901_0003_01_000001, NodeId: hadoop-220-2:50762, NodeHttpAddress: hadoop-220-2:8042, Resource: <memory:2048, vCores:1>, Priority: 0, State: NEW, Token: null, Status: container_id {, app_attempt_id {, application_id {, id: 3, cluster_timestamp: 1376154442901, }, attemptId: 1, }, id: 1, }, state: C_NEW, ] containerId=container_1376154442901_0003_01_000001 queue=default: capacity=1.0, absoluteCapacity=1.0, usedResources=<memory:0, vCores:0>usedCapacity=0.0, absoluteUsedCapacity=0.0, numApps=1, numContainers=0 usedCapacity=0.0 absoluteUsedCapacity=0.0 used=<memory:0, vCores:0> cluster=<memory:49152, vCores:96>
2013-08-10 17:14:04,391 INFO org.apache.hadoop.yarn.server.resourcemanager.scheduler.capacity.ParentQueue: Re-sorting queues since queue: root.default stats: default: capacity=1.0, absoluteCapacity=1.0, usedResources=<memory:2048, vCores:1>usedCapacity=0.041666668, absoluteUsedCapacity=0.041666668, numApps=1, numContainers=1
2013-08-10 17:14:04,391 INFO org.apache.hadoop.yarn.server.resourcemanager.scheduler.capacity.ParentQueue: assignedContainer queue=root usedCapacity=0.041666668 absoluteUsedCapacity=0.041666668 used=<memory:2048, vCores:1> cluster=<memory:49152, vCores:96>
2013-08-10 17:14:04,392 INFO org.apache.hadoop.yarn.server.resourcemanager.rmcontainer.RMContainerImpl: container_1376154442901_0003_01_000001 Container Transitioned from ALLOCATED to ACQUIRED
2013-08-10 17:14:04,394 INFO org.apache.hadoop.yarn.server.resourcemanager.rmapp.attempt.RMAppAttemptImpl: Storing attempt: AppId: application_1376154442901_0003 AttemptId: appattempt_1376154442901_0003_000001 MasterContainer: Container: [ContainerId: container_1376154442901_0003_01_000001, NodeId: hadoop-220-2:50762, NodeHttpAddress: hadoop-220-2:8042, Resource: <memory:2048, vCores:1>, Priority: 0, State: NEW, Token: null, Status: container_id {, app_attempt_id {, application_id {, id: 3, cluster_timestamp: 1376154442901, }, attemptId: 1, }, id: 1, }, state: C_NEW, ]
2013-08-10 17:14:04,395 INFO org.apache.hadoop.yarn.server.resourcemanager.rmapp.attempt.RMAppAttemptImpl: appattempt_1376154442901_0003_000001 State change from SCHEDULED to ALLOCATED_SAVING
2013-08-10 17:14:04,395 INFO org.apache.hadoop.yarn.server.resourcemanager.recovery.RMStateStore: Storing info for attempt: appattempt_1376154442901_0003_000001
2013-08-10 17:14:04,396 INFO org.apache.hadoop.yarn.server.resourcemanager.rmapp.attempt.RMAppAttemptImpl: appattempt_1376154442901_0003_000001 State change from ALLOCATED_SAVING to ALLOCATED
2013-08-10 17:14:04,397 INFO org.apache.hadoop.yarn.server.resourcemanager.amlauncher.AMLauncher: Launching masterappattempt_1376154442901_0003_000001
2013-08-10 17:14:04,400 INFO org.apache.hadoop.yarn.server.resourcemanager.amlauncher.AMLauncher: Setting up container Container: [ContainerId: container_1376154442901_0003_01_000001, NodeId: hadoop-220-2:50762, NodeHttpAddress: hadoop-220-2:8042, Resource: <memory:2048, vCores:1>, Priority: 0, State: NEW, Token: null, Status: container_id {, app_attempt_id {, application_id {, id: 3, cluster_timestamp: 1376154442901, }, attemptId: 1, }, id: 1, }, state: C_NEW, ] for AM appattempt_1376154442901_0003_000001
2013-08-10 17:14:04,400 INFO org.apache.hadoop.yarn.server.resourcemanager.amlauncher.AMLauncher: Command to launch container container_1376154442901_0003_01_000001 : $JAVA_HOME/bin/java -Dlog4j.configuration=container-log4j.properties -Dyarn.app.mapreduce.container.log.dir=<LOG_DIR> -Dyarn.app.mapreduce.container.log.filesize=0 -Dhadoop.root.logger=INFO,CLA  -Xmx1024m org.apache.hadoop.mapreduce.v2.app.MRAppMaster 1><LOG_DIR>/stdout 2><LOG_DIR>/stderr 
2013-08-10 17:14:04,418 INFO org.apache.hadoop.yarn.server.resourcemanager.amlauncher.AMLauncher: Done launching container Container: [ContainerId: container_1376154442901_0003_01_000001, NodeId: hadoop-220-2:50762, NodeHttpAddress: hadoop-220-2:8042, Resource: <memory:2048, vCores:1>, Priority: 0, State: NEW, Token: null, Status: container_id {, app_attempt_id {, application_id {, id: 3, cluster_timestamp: 1376154442901, }, attemptId: 1, }, id: 1, }, state: C_NEW, ] for AM appattempt_1376154442901_0003_000001
2013-08-10 17:14:04,419 INFO org.apache.hadoop.yarn.server.resourcemanager.rmapp.attempt.RMAppAttemptImpl: appattempt_1376154442901_0003_000001 State change from ALLOCATED to LAUNCHED
2013-08-10 17:14:05,396 INFO org.apache.hadoop.yarn.server.resourcemanager.rmcontainer.RMContainerImpl: container_1376154442901_0003_01_000001 Container Transitioned from ACQUIRED to RUNNING
2013-08-10 17:14:10,816 INFO org.apache.hadoop.yarn.server.resourcemanager.ApplicationMasterService: AM registration appattempt_1376154442901_0003_000001
2013-08-10 17:14:10,816 INFO org.apache.hadoop.yarn.server.resourcemanager.RMAuditLogger: USER=ubuntu	IP=192.168.100.15	OPERATION=Register App Master	TARGET=ApplicationMasterService	RESULT=SUCCESS	APPID=application_1376154442901_0003	APPATTEMPTID=appattempt_1376154442901_0003_000001
2013-08-10 17:14:10,817 INFO org.apache.hadoop.yarn.server.resourcemanager.rmapp.attempt.RMAppAttemptImpl: appattempt_1376154442901_0003_000001 State change from LAUNCHED to RUNNING
2013-08-10 17:14:10,817 INFO org.apache.hadoop.yarn.server.resourcemanager.rmapp.RMAppImpl: application_1376154442901_0003 State change from ACCEPTED to RUNNING
2013-08-10 17:14:11,934 INFO org.apache.hadoop.yarn.server.resourcemanager.rmcontainer.RMContainerImpl: container_1376154442901_0003_01_000002 Container Transitioned from NEW to ALLOCATED
2013-08-10 17:14:11,935 INFO org.apache.hadoop.yarn.server.resourcemanager.RMAuditLogger: USER=ubuntu	OPERATION=AM Allocated Container	TARGET=SchedulerApp	RESULT=SUCCESS	APPID=application_1376154442901_0003	CONTAINERID=container_1376154442901_0003_01_000002
2013-08-10 17:14:11,935 INFO org.apache.hadoop.yarn.server.resourcemanager.scheduler.common.fica.FiCaSchedulerNode: Assigned container container_1376154442901_0003_01_000002 of capacity <memory:1024, vCores:1> on host hadoop-220-6:56687, which currently has 1 containers, <memory:1024, vCores:1> used and <memory:7168, vCores:15> available
2013-08-10 17:14:11,937 INFO org.apache.hadoop.yarn.server.resourcemanager.scheduler.capacity.LeafQueue: assignedContainer application=application_1376154442901_0003 container=Container: [ContainerId: container_1376154442901_0003_01_000002, NodeId: hadoop-220-6:56687, NodeHttpAddress: hadoop-220-6:8042, Resource: <memory:1024, vCores:1>, Priority: 20, State: NEW, Token: null, Status: container_id {, app_attempt_id {, application_id {, id: 3, cluster_timestamp: 1376154442901, }, attemptId: 1, }, id: 2, }, state: C_NEW, ] containerId=container_1376154442901_0003_01_000002 queue=default: capacity=1.0, absoluteCapacity=1.0, usedResources=<memory:2048, vCores:1>usedCapacity=0.041666668, absoluteUsedCapacity=0.041666668, numApps=1, numContainers=1 usedCapacity=0.041666668 absoluteUsedCapacity=0.041666668 used=<memory:2048, vCores:1> cluster=<memory:49152, vCores:96>
2013-08-10 17:14:11,937 INFO org.apache.hadoop.yarn.server.resourcemanager.scheduler.capacity.ParentQueue: Re-sorting queues since queue: root.default stats: default: capacity=1.0, absoluteCapacity=1.0, usedResources=<memory:3072, vCores:2>usedCapacity=0.0625, absoluteUsedCapacity=0.0625, numApps=1, numContainers=2
2013-08-10 17:14:11,937 INFO org.apache.hadoop.yarn.server.resourcemanager.scheduler.capacity.ParentQueue: assignedContainer queue=root usedCapacity=0.0625 absoluteUsedCapacity=0.0625 used=<memory:3072, vCores:2> cluster=<memory:49152, vCores:96>
2013-08-10 17:14:11,952 INFO org.apache.hadoop.yarn.server.resourcemanager.rmcontainer.RMContainerImpl: container_1376154442901_0003_01_000003 Container Transitioned from NEW to ALLOCATED
2013-08-10 17:14:11,952 INFO org.apache.hadoop.yarn.server.resourcemanager.RMAuditLogger: USER=ubuntu	OPERATION=AM Allocated Container	TARGET=SchedulerApp	RESULT=SUCCESS	APPID=application_1376154442901_0003	CONTAINERID=container_1376154442901_0003_01_000003
2013-08-10 17:14:11,952 INFO org.apache.hadoop.yarn.server.resourcemanager.scheduler.common.fica.FiCaSchedulerNode: Assigned container container_1376154442901_0003_01_000003 of capacity <memory:1024, vCores:1> on host hadoop-220-4:35716, which currently has 1 containers, <memory:1024, vCores:1> used and <memory:7168, vCores:15> available
2013-08-10 17:14:11,953 INFO org.apache.hadoop.yarn.server.resourcemanager.scheduler.capacity.LeafQueue: assignedContainer application=application_1376154442901_0003 container=Container: [ContainerId: container_1376154442901_0003_01_000003, NodeId: hadoop-220-4:35716, NodeHttpAddress: hadoop-220-4:8042, Resource: <memory:1024, vCores:1>, Priority: 20, State: NEW, Token: null, Status: container_id {, app_attempt_id {, application_id {, id: 3, cluster_timestamp: 1376154442901, }, attemptId: 1, }, id: 3, }, state: C_NEW, ] containerId=container_1376154442901_0003_01_000003 queue=default: capacity=1.0, absoluteCapacity=1.0, usedResources=<memory:3072, vCores:2>usedCapacity=0.0625, absoluteUsedCapacity=0.0625, numApps=1, numContainers=2 usedCapacity=0.0625 absoluteUsedCapacity=0.0625 used=<memory:3072, vCores:2> cluster=<memory:49152, vCores:96>
2013-08-10 17:14:11,954 INFO org.apache.hadoop.yarn.server.resourcemanager.scheduler.capacity.ParentQueue: Re-sorting queues since queue: root.default stats: default: capacity=1.0, absoluteCapacity=1.0, usedResources=<memory:4096, vCores:3>usedCapacity=0.083333336, absoluteUsedCapacity=0.083333336, numApps=1, numContainers=3
2013-08-10 17:14:11,954 INFO org.apache.hadoop.yarn.server.resourcemanager.scheduler.capacity.ParentQueue: assignedContainer queue=root usedCapacity=0.083333336 absoluteUsedCapacity=0.083333336 used=<memory:4096, vCores:3> cluster=<memory:49152, vCores:96>
2013-08-10 17:14:12,869 INFO org.apache.hadoop.yarn.server.resourcemanager.rmcontainer.RMContainerImpl: container_1376154442901_0003_01_000002 Container Transitioned from ALLOCATED to ACQUIRED
2013-08-10 17:14:12,870 INFO org.apache.hadoop.yarn.server.resourcemanager.rmcontainer.RMContainerImpl: container_1376154442901_0003_01_000003 Container Transitioned from ALLOCATED to ACQUIRED
2013-08-10 17:14:13,900 INFO org.apache.hadoop.yarn.server.resourcemanager.scheduler.AppSchedulingInfo: checking for deactivate... 
2013-08-10 17:14:13,961 INFO org.apache.hadoop.yarn.server.resourcemanager.rmcontainer.RMContainerImpl: container_1376154442901_0003_01_000003 Container Transitioned from ACQUIRED to RUNNING
2013-08-10 17:14:14,968 INFO org.apache.hadoop.yarn.server.resourcemanager.rmcontainer.RMContainerImpl: container_1376154442901_0003_01_000002 Container Transitioned from ACQUIRED to RUNNING
2013-08-10 17:17:07,006 INFO org.apache.hadoop.yarn.server.resourcemanager.rmcontainer.RMContainerImpl: container_1376154442901_0003_01_000003 Container Transitioned from RUNNING to COMPLETED
2013-08-10 17:17:07,007 INFO org.apache.hadoop.yarn.server.resourcemanager.scheduler.common.fica.FiCaSchedulerApp: Completed container: container_1376154442901_0003_01_000003 in state: COMPLETED event:FINISHED
2013-08-10 17:17:07,007 INFO org.apache.hadoop.yarn.server.resourcemanager.RMAuditLogger: USER=ubuntu	OPERATION=AM Released Container	TARGET=SchedulerApp	RESULT=SUCCESS	APPID=application_1376154442901_0003	CONTAINERID=container_1376154442901_0003_01_000003
2013-08-10 17:17:07,007 INFO org.apache.hadoop.yarn.server.resourcemanager.scheduler.common.fica.FiCaSchedulerNode: Released container container_1376154442901_0003_01_000003 of capacity <memory:1024, vCores:1> on host hadoop-220-4:35716, which currently has 0 containers, <memory:0, vCores:0> used and <memory:8192, vCores:16> available, release resources=true
2013-08-10 17:17:07,007 INFO org.apache.hadoop.yarn.server.resourcemanager.scheduler.capacity.LeafQueue: default used=<memory:3072, vCores:2> numContainers=2 user=ubuntu user-resources=<memory:3072, vCores:2>
2013-08-10 17:17:07,009 INFO org.apache.hadoop.yarn.server.resourcemanager.scheduler.capacity.LeafQueue: completedContainer container=Container: [ContainerId: container_1376154442901_0003_01_000003, NodeId: hadoop-220-4:35716, NodeHttpAddress: hadoop-220-4:8042, Resource: <memory:1024, vCores:1>, Priority: 20, State: NEW, Token: null, Status: container_id {, app_attempt_id {, application_id {, id: 3, cluster_timestamp: 1376154442901, }, attemptId: 1, }, id: 3, }, state: C_COMPLETE, diagnostics: "Container killed by the ApplicationMaster.\n\n", exit_status: 143, ] resource=<memory:1024, vCores:1> queue=default: capacity=1.0, absoluteCapacity=1.0, usedResources=<memory:3072, vCores:2>usedCapacity=0.0625, absoluteUsedCapacity=0.0625, numApps=1, numContainers=2 usedCapacity=0.0625 absoluteUsedCapacity=0.0625 used=<memory:3072, vCores:2> cluster=<memory:49152, vCores:96>
2013-08-10 17:17:07,009 INFO org.apache.hadoop.yarn.server.resourcemanager.scheduler.capacity.ParentQueue: completedContainer queue=root usedCapacity=0.0625 absoluteUsedCapacity=0.0625 used=<memory:3072, vCores:2> cluster=<memory:49152, vCores:96>
2013-08-10 17:17:07,010 INFO org.apache.hadoop.yarn.server.resourcemanager.scheduler.capacity.CapacityScheduler: Application appattempt_1376154442901_0003_000001 released container container_1376154442901_0003_01_000003 on node: host: hadoop-220-4:35716 #containers=0 available=8192 used=0 with event: FINISHED
2013-08-10 17:17:09,871 INFO org.apache.hadoop.yarn.server.resourcemanager.rmcontainer.RMContainerImpl: container_1376154442901_0003_01_000002 Container Transitioned from RUNNING to COMPLETED
2013-08-10 17:17:09,871 INFO org.apache.hadoop.yarn.server.resourcemanager.scheduler.common.fica.FiCaSchedulerApp: Completed container: container_1376154442901_0003_01_000002 in state: COMPLETED event:FINISHED
2013-08-10 17:17:09,871 INFO org.apache.hadoop.yarn.server.resourcemanager.RMAuditLogger: USER=ubuntu	OPERATION=AM Released Container	TARGET=SchedulerApp	RESULT=SUCCESS	APPID=application_1376154442901_0003	CONTAINERID=container_1376154442901_0003_01_000002
2013-08-10 17:17:09,871 INFO org.apache.hadoop.yarn.server.resourcemanager.scheduler.common.fica.FiCaSchedulerNode: Released container container_1376154442901_0003_01_000002 of capacity <memory:1024, vCores:1> on host hadoop-220-6:56687, which currently has 0 containers, <memory:0, vCores:0> used and <memory:8192, vCores:16> available, release resources=true
2013-08-10 17:17:09,871 INFO org.apache.hadoop.yarn.server.resourcemanager.scheduler.capacity.LeafQueue: default used=<memory:2048, vCores:1> numContainers=1 user=ubuntu user-resources=<memory:2048, vCores:1>
2013-08-10 17:17:09,873 INFO org.apache.hadoop.yarn.server.resourcemanager.scheduler.capacity.LeafQueue: completedContainer container=Container: [ContainerId: container_1376154442901_0003_01_000002, NodeId: hadoop-220-6:56687, NodeHttpAddress: hadoop-220-6:8042, Resource: <memory:1024, vCores:1>, Priority: 20, State: NEW, Token: null, Status: container_id {, app_attempt_id {, application_id {, id: 3, cluster_timestamp: 1376154442901, }, attemptId: 1, }, id: 2, }, state: C_COMPLETE, diagnostics: "Container killed by the ApplicationMaster.\n", exit_status: 0, ] resource=<memory:1024, vCores:1> queue=default: capacity=1.0, absoluteCapacity=1.0, usedResources=<memory:2048, vCores:1>usedCapacity=0.041666668, absoluteUsedCapacity=0.041666668, numApps=1, numContainers=1 usedCapacity=0.041666668 absoluteUsedCapacity=0.041666668 used=<memory:2048, vCores:1> cluster=<memory:49152, vCores:96>
2013-08-10 17:17:09,874 INFO org.apache.hadoop.yarn.server.resourcemanager.scheduler.capacity.ParentQueue: completedContainer queue=root usedCapacity=0.041666668 absoluteUsedCapacity=0.041666668 used=<memory:2048, vCores:1> cluster=<memory:49152, vCores:96>
2013-08-10 17:17:09,874 INFO org.apache.hadoop.yarn.server.resourcemanager.scheduler.capacity.CapacityScheduler: Application appattempt_1376154442901_0003_000001 released container container_1376154442901_0003_01_000002 on node: host: hadoop-220-6:56687 #containers=0 available=8192 used=0 with event: FINISHED
2013-08-10 17:17:14,018 INFO org.apache.hadoop.yarn.server.resourcemanager.rmapp.attempt.RMAppAttemptImpl: appattempt_1376154442901_0003_000001 State change from RUNNING to FINISHING
2013-08-10 17:17:14,019 INFO org.apache.hadoop.yarn.server.resourcemanager.rmapp.RMAppImpl: application_1376154442901_0003 State change from RUNNING to FINISHING
2013-08-10 17:17:14,907 INFO org.apache.hadoop.yarn.server.resourcemanager.ClientRMService: Allocated new applicationId: 4
2013-08-10 17:17:14,952 INFO org.apache.hadoop.yarn.server.resourcemanager.rmcontainer.RMContainerImpl: container_1376154442901_0003_01_000001 Container Transitioned from RUNNING to COMPLETED
2013-08-10 17:17:14,952 INFO org.apache.hadoop.yarn.server.resourcemanager.rmapp.attempt.RMAppAttemptImpl: appattempt_1376154442901_0003_000001 State change from FINISHING to FINISHED
2013-08-10 17:17:14,952 INFO org.apache.hadoop.yarn.server.resourcemanager.scheduler.common.fica.FiCaSchedulerApp: Completed container: container_1376154442901_0003_01_000001 in state: COMPLETED event:FINISHED
2013-08-10 17:17:14,952 INFO org.apache.hadoop.yarn.server.resourcemanager.rmapp.RMAppImpl: application_1376154442901_0003 State change from FINISHING to FINISHED
2013-08-10 17:17:14,952 INFO org.apache.hadoop.yarn.server.resourcemanager.RMAuditLogger: USER=ubuntu	OPERATION=AM Released Container	TARGET=SchedulerApp	RESULT=SUCCESS	APPID=application_1376154442901_0003	CONTAINERID=container_1376154442901_0003_01_000001
2013-08-10 17:17:14,952 INFO org.apache.hadoop.yarn.server.resourcemanager.scheduler.common.fica.FiCaSchedulerNode: Released container container_1376154442901_0003_01_000001 of capacity <memory:2048, vCores:1> on host hadoop-220-2:50762, which currently has 0 containers, <memory:0, vCores:0> used and <memory:8192, vCores:16> available, release resources=true
2013-08-10 17:17:14,952 INFO org.apache.hadoop.yarn.server.resourcemanager.RMAuditLogger: USER=ubuntu	OPERATION=Application Finished - Succeeded	TARGET=RMAppManager	RESULT=SUCCESS	APPID=application_1376154442901_0003
2013-08-10 17:17:14,953 INFO org.apache.hadoop.yarn.server.resourcemanager.scheduler.capacity.LeafQueue: default used=<memory:0, vCores:0> numContainers=0 user=ubuntu user-resources=<memory:0, vCores:0>
2013-08-10 17:17:14,953 INFO org.apache.hadoop.yarn.server.resourcemanager.recovery.RMStateStore: Removing info for app: application_1376154442901_0003
2013-08-10 17:17:14,953 INFO org.apache.hadoop.yarn.server.resourcemanager.RMAppManager$ApplicationSummary: appId=application_1376154442901_0003,name=TeraGen,user=ubuntu,queue=default,state=FINISHED,trackingUrl=hadoop-220-1.novalocal:8088/proxy/application_1376154442901_0003/jobhistory/job/job_1376154442901_0003,appMasterHost=hadoop-220-2,startTime=1376154843965,finishTime=1376155034019
2013-08-10 17:17:14,954 INFO org.apache.hadoop.yarn.server.resourcemanager.scheduler.capacity.LeafQueue: completedContainer container=Container: [ContainerId: container_1376154442901_0003_01_000001, NodeId: hadoop-220-2:50762, NodeHttpAddress: hadoop-220-2:8042, Resource: <memory:2048, vCores:1>, Priority: 0, State: NEW, Token: null, Status: container_id {, app_attempt_id {, application_id {, id: 3, cluster_timestamp: 1376154442901, }, attemptId: 1, }, id: 1, }, state: C_COMPLETE, diagnostics: "", exit_status: 0, ] resource=<memory:2048, vCores:1> queue=default: capacity=1.0, absoluteCapacity=1.0, usedResources=<memory:0, vCores:0>usedCapacity=0.0, absoluteUsedCapacity=0.0, numApps=1, numContainers=0 usedCapacity=0.0 absoluteUsedCapacity=0.0 used=<memory:0, vCores:0> cluster=<memory:49152, vCores:96>
2013-08-10 17:17:14,954 INFO org.apache.hadoop.yarn.server.resourcemanager.scheduler.capacity.ParentQueue: completedContainer queue=root usedCapacity=0.0 absoluteUsedCapacity=0.0 used=<memory:0, vCores:0> cluster=<memory:49152, vCores:96>
2013-08-10 17:17:14,955 INFO org.apache.hadoop.yarn.server.resourcemanager.scheduler.capacity.CapacityScheduler: Application appattempt_1376154442901_0003_000001 released container container_1376154442901_0003_01_000001 on node: host: hadoop-220-2:50762 #containers=0 available=8192 used=0 with event: FINISHED
2013-08-10 17:17:14,955 INFO org.apache.hadoop.yarn.server.resourcemanager.scheduler.capacity.CapacityScheduler: Application appattempt_1376154442901_0003_000001 is done. finalState=FINISHED
2013-08-10 17:17:14,955 INFO org.apache.hadoop.yarn.server.resourcemanager.amlauncher.AMLauncher: Cleaning master appattempt_1376154442901_0003_000001
2013-08-10 17:17:14,955 INFO org.apache.hadoop.yarn.server.resourcemanager.scheduler.AppSchedulingInfo: Application application_1376154442901_0003 requests cleared
2013-08-10 17:17:14,956 INFO org.apache.hadoop.yarn.server.resourcemanager.scheduler.capacity.LeafQueue: Application removed - appId: application_1376154442901_0003 user: ubuntu queue: default #user-pending-applications: 0 #user-active-applications: 0 #queue-pending-applications: 0 #queue-active-applications: 0
2013-08-10 17:17:14,956 INFO org.apache.hadoop.yarn.server.resourcemanager.scheduler.capacity.ParentQueue: Application removed - appId: application_1376154442901_0003 user: ubuntu leaf-queue of parent: root #applications: 0
2013-08-10 17:17:16,754 INFO org.apache.hadoop.yarn.server.resourcemanager.ClientRMService: Storing Application with id application_1376154442901_0004
2013-08-10 17:17:16,755 INFO org.apache.hadoop.yarn.server.resourcemanager.recovery.RMStateStore: Storing info for app: application_1376154442901_0004
2013-08-10 17:17:16,755 INFO org.apache.hadoop.yarn.server.resourcemanager.ClientRMService: Application with id 4 submitted by user ubuntu
2013-08-10 17:17:16,755 INFO org.apache.hadoop.yarn.server.resourcemanager.RMAuditLogger: USER=ubuntu	IP=192.168.100.9	OPERATION=Submit Application Request	TARGET=ClientRMService	RESULT=SUCCESS	APPID=application_1376154442901_0004
2013-08-10 17:17:16,757 INFO org.apache.hadoop.yarn.server.resourcemanager.rmapp.RMAppImpl: application_1376154442901_0004 State change from NEW to SUBMITTED
2013-08-10 17:17:16,758 INFO org.apache.hadoop.yarn.server.resourcemanager.ApplicationMasterService: Registering appattempt_1376154442901_0004_000001
2013-08-10 17:17:16,758 INFO org.apache.hadoop.yarn.server.resourcemanager.rmapp.attempt.RMAppAttemptImpl: appattempt_1376154442901_0004_000001 State change from NEW to SUBMITTED
2013-08-10 17:17:16,759 INFO org.apache.hadoop.yarn.server.resourcemanager.scheduler.capacity.LeafQueue: Application application_1376154442901_0004 from user: ubuntu activated in queue: default
2013-08-10 17:17:16,759 INFO org.apache.hadoop.yarn.server.resourcemanager.scheduler.capacity.LeafQueue: Application added - appId: application_1376154442901_0004 user: org.apache.hadoop.yarn.server.resourcemanager.scheduler.capacity.LeafQueue$User@2aec4bcb, leaf-queue: default #user-pending-applications: 0 #user-active-applications: 1 #queue-pending-applications: 0 #queue-active-applications: 1
2013-08-10 17:17:16,759 INFO org.apache.hadoop.yarn.server.resourcemanager.scheduler.capacity.ParentQueue: Application added - appId: application_1376154442901_0004 user: ubuntu leaf-queue of parent: root #applications: 1
2013-08-10 17:17:16,759 INFO org.apache.hadoop.yarn.server.resourcemanager.scheduler.capacity.CapacityScheduler: Application Submission: appattempt_1376154442901_0004_000001, user: ubuntu queue: default: capacity=1.0, absoluteCapacity=1.0, usedResources=<memory:0, vCores:0>usedCapacity=0.0, absoluteUsedCapacity=0.0, numApps=1, numContainers=0, currently active: 1
2013-08-10 17:17:16,760 INFO org.apache.hadoop.yarn.server.resourcemanager.rmapp.attempt.RMAppAttemptImpl: appattempt_1376154442901_0004_000001 State change from SUBMITTED to SCHEDULED
2013-08-10 17:17:16,760 INFO org.apache.hadoop.yarn.server.resourcemanager.rmapp.RMAppImpl: application_1376154442901_0004 State change from SUBMITTED to ACCEPTED
2013-08-10 17:17:16,906 INFO org.apache.hadoop.yarn.server.resourcemanager.rmcontainer.RMContainerImpl: container_1376154442901_0004_01_000001 Container Transitioned from NEW to ALLOCATED
2013-08-10 17:17:16,907 INFO org.apache.hadoop.yarn.server.resourcemanager.RMAuditLogger: USER=ubuntu	OPERATION=AM Allocated Container	TARGET=SchedulerApp	RESULT=SUCCESS	APPID=application_1376154442901_0004	CONTAINERID=container_1376154442901_0004_01_000001
2013-08-10 17:17:16,907 INFO org.apache.hadoop.yarn.server.resourcemanager.scheduler.common.fica.FiCaSchedulerNode: Assigned container container_1376154442901_0004_01_000001 of capacity <memory:2048, vCores:1> on host hadoop-220-6:56687, which currently has 1 containers, <memory:2048, vCores:1> used and <memory:6144, vCores:15> available
2013-08-10 17:17:16,908 INFO org.apache.hadoop.yarn.server.resourcemanager.scheduler.capacity.LeafQueue: assignedContainer application=application_1376154442901_0004 container=Container: [ContainerId: container_1376154442901_0004_01_000001, NodeId: hadoop-220-6:56687, NodeHttpAddress: hadoop-220-6:8042, Resource: <memory:2048, vCores:1>, Priority: 0, State: NEW, Token: null, Status: container_id {, app_attempt_id {, application_id {, id: 4, cluster_timestamp: 1376154442901, }, attemptId: 1, }, id: 1, }, state: C_NEW, ] containerId=container_1376154442901_0004_01_000001 queue=default: capacity=1.0, absoluteCapacity=1.0, usedResources=<memory:0, vCores:0>usedCapacity=0.0, absoluteUsedCapacity=0.0, numApps=1, numContainers=0 usedCapacity=0.0 absoluteUsedCapacity=0.0 used=<memory:0, vCores:0> cluster=<memory:49152, vCores:96>
2013-08-10 17:17:16,909 INFO org.apache.hadoop.yarn.server.resourcemanager.scheduler.capacity.ParentQueue: Re-sorting queues since queue: root.default stats: default: capacity=1.0, absoluteCapacity=1.0, usedResources=<memory:2048, vCores:1>usedCapacity=0.041666668, absoluteUsedCapacity=0.041666668, numApps=1, numContainers=1
2013-08-10 17:17:16,910 INFO org.apache.hadoop.yarn.server.resourcemanager.rmcontainer.RMContainerImpl: container_1376154442901_0004_01_000001 Container Transitioned from ALLOCATED to ACQUIRED
2013-08-10 17:17:16,910 INFO org.apache.hadoop.yarn.server.resourcemanager.scheduler.capacity.ParentQueue: assignedContainer queue=root usedCapacity=0.041666668 absoluteUsedCapacity=0.041666668 used=<memory:2048, vCores:1> cluster=<memory:49152, vCores:96>
2013-08-10 17:17:16,912 INFO org.apache.hadoop.yarn.server.resourcemanager.rmapp.attempt.RMAppAttemptImpl: Storing attempt: AppId: application_1376154442901_0004 AttemptId: appattempt_1376154442901_0004_000001 MasterContainer: Container: [ContainerId: container_1376154442901_0004_01_000001, NodeId: hadoop-220-6:56687, NodeHttpAddress: hadoop-220-6:8042, Resource: <memory:2048, vCores:1>, Priority: 0, State: NEW, Token: null, Status: container_id {, app_attempt_id {, application_id {, id: 4, cluster_timestamp: 1376154442901, }, attemptId: 1, }, id: 1, }, state: C_NEW, ]
2013-08-10 17:17:16,912 INFO org.apache.hadoop.yarn.server.resourcemanager.rmapp.attempt.RMAppAttemptImpl: appattempt_1376154442901_0004_000001 State change from SCHEDULED to ALLOCATED_SAVING
2013-08-10 17:17:16,912 INFO org.apache.hadoop.yarn.server.resourcemanager.recovery.RMStateStore: Storing info for attempt: appattempt_1376154442901_0004_000001
2013-08-10 17:17:16,915 INFO org.apache.hadoop.yarn.server.resourcemanager.rmapp.attempt.RMAppAttemptImpl: appattempt_1376154442901_0004_000001 State change from ALLOCATED_SAVING to ALLOCATED
2013-08-10 17:17:16,917 INFO org.apache.hadoop.yarn.server.resourcemanager.amlauncher.AMLauncher: Launching masterappattempt_1376154442901_0004_000001
2013-08-10 17:17:16,919 INFO org.apache.hadoop.yarn.server.resourcemanager.amlauncher.AMLauncher: Setting up container Container: [ContainerId: container_1376154442901_0004_01_000001, NodeId: hadoop-220-6:56687, NodeHttpAddress: hadoop-220-6:8042, Resource: <memory:2048, vCores:1>, Priority: 0, State: NEW, Token: null, Status: container_id {, app_attempt_id {, application_id {, id: 4, cluster_timestamp: 1376154442901, }, attemptId: 1, }, id: 1, }, state: C_NEW, ] for AM appattempt_1376154442901_0004_000001
2013-08-10 17:17:16,920 INFO org.apache.hadoop.yarn.server.resourcemanager.amlauncher.AMLauncher: Command to launch container container_1376154442901_0004_01_000001 : $JAVA_HOME/bin/java -Dlog4j.configuration=container-log4j.properties -Dyarn.app.mapreduce.container.log.dir=<LOG_DIR> -Dyarn.app.mapreduce.container.log.filesize=0 -Dhadoop.root.logger=INFO,CLA  -Xmx1024m org.apache.hadoop.mapreduce.v2.app.MRAppMaster 1><LOG_DIR>/stdout 2><LOG_DIR>/stderr 
2013-08-10 17:17:16,936 INFO org.apache.hadoop.yarn.server.resourcemanager.amlauncher.AMLauncher: Done launching container Container: [ContainerId: container_1376154442901_0004_01_000001, NodeId: hadoop-220-6:56687, NodeHttpAddress: hadoop-220-6:8042, Resource: <memory:2048, vCores:1>, Priority: 0, State: NEW, Token: null, Status: container_id {, app_attempt_id {, application_id {, id: 4, cluster_timestamp: 1376154442901, }, attemptId: 1, }, id: 1, }, state: C_NEW, ] for AM appattempt_1376154442901_0004_000001
2013-08-10 17:17:16,937 INFO org.apache.hadoop.yarn.server.resourcemanager.rmapp.attempt.RMAppAttemptImpl: appattempt_1376154442901_0004_000001 State change from ALLOCATED to LAUNCHED
2013-08-10 17:17:17,913 INFO org.apache.hadoop.yarn.server.resourcemanager.rmcontainer.RMContainerImpl: container_1376154442901_0004_01_000001 Container Transitioned from ACQUIRED to RUNNING
2013-08-10 17:17:26,113 INFO org.apache.hadoop.yarn.server.resourcemanager.ApplicationMasterService: AM registration appattempt_1376154442901_0004_000001
2013-08-10 17:17:26,113 INFO org.apache.hadoop.yarn.server.resourcemanager.RMAuditLogger: USER=ubuntu	IP=192.168.100.34	OPERATION=Register App Master	TARGET=ApplicationMasterService	RESULT=SUCCESS	APPID=application_1376154442901_0004	APPATTEMPTID=appattempt_1376154442901_0004_000001
2013-08-10 17:17:26,114 INFO org.apache.hadoop.yarn.server.resourcemanager.rmapp.attempt.RMAppAttemptImpl: appattempt_1376154442901_0004_000001 State change from LAUNCHED to RUNNING
2013-08-10 17:17:26,115 INFO org.apache.hadoop.yarn.server.resourcemanager.rmapp.RMAppImpl: application_1376154442901_0004 State change from ACCEPTED to RUNNING
2013-08-10 17:17:27,300 INFO org.apache.hadoop.yarn.server.resourcemanager.rmcontainer.RMContainerImpl: container_1376154442901_0004_01_000002 Container Transitioned from NEW to ALLOCATED
2013-08-10 17:17:27,300 INFO org.apache.hadoop.yarn.server.resourcemanager.RMAuditLogger: USER=ubuntu	OPERATION=AM Allocated Container	TARGET=SchedulerApp	RESULT=SUCCESS	APPID=application_1376154442901_0004	CONTAINERID=container_1376154442901_0004_01_000002
2013-08-10 17:17:27,300 INFO org.apache.hadoop.yarn.server.resourcemanager.scheduler.common.fica.FiCaSchedulerNode: Assigned container container_1376154442901_0004_01_000002 of capacity <memory:1024, vCores:1> on host hadoop-220-5:59721, which currently has 1 containers, <memory:1024, vCores:1> used and <memory:7168, vCores:15> available
2013-08-10 17:17:27,302 INFO org.apache.hadoop.yarn.server.resourcemanager.scheduler.capacity.LeafQueue: assignedContainer application=application_1376154442901_0004 container=Container: [ContainerId: container_1376154442901_0004_01_000002, NodeId: hadoop-220-5:59721, NodeHttpAddress: hadoop-220-5:8042, Resource: <memory:1024, vCores:1>, Priority: 20, State: NEW, Token: null, Status: container_id {, app_attempt_id {, application_id {, id: 4, cluster_timestamp: 1376154442901, }, attemptId: 1, }, id: 2, }, state: C_NEW, ] containerId=container_1376154442901_0004_01_000002 queue=default: capacity=1.0, absoluteCapacity=1.0, usedResources=<memory:2048, vCores:1>usedCapacity=0.041666668, absoluteUsedCapacity=0.041666668, numApps=1, numContainers=1 usedCapacity=0.041666668 absoluteUsedCapacity=0.041666668 used=<memory:2048, vCores:1> cluster=<memory:49152, vCores:96>
2013-08-10 17:17:27,302 INFO org.apache.hadoop.yarn.server.resourcemanager.scheduler.capacity.ParentQueue: Re-sorting queues since queue: root.default stats: default: capacity=1.0, absoluteCapacity=1.0, usedResources=<memory:3072, vCores:2>usedCapacity=0.0625, absoluteUsedCapacity=0.0625, numApps=1, numContainers=2
2013-08-10 17:17:27,302 INFO org.apache.hadoop.yarn.server.resourcemanager.scheduler.capacity.ParentQueue: assignedContainer queue=root usedCapacity=0.0625 absoluteUsedCapacity=0.0625 used=<memory:3072, vCores:2> cluster=<memory:49152, vCores:96>
2013-08-10 17:17:27,487 INFO org.apache.hadoop.yarn.server.resourcemanager.rmcontainer.RMContainerImpl: container_1376154442901_0004_01_000003 Container Transitioned from NEW to ALLOCATED
2013-08-10 17:17:27,487 INFO org.apache.hadoop.yarn.server.resourcemanager.RMAuditLogger: USER=ubuntu	OPERATION=AM Allocated Container	TARGET=SchedulerApp	RESULT=SUCCESS	APPID=application_1376154442901_0004	CONTAINERID=container_1376154442901_0004_01_000003
2013-08-10 17:17:27,488 INFO org.apache.hadoop.yarn.server.resourcemanager.scheduler.common.fica.FiCaSchedulerNode: Assigned container container_1376154442901_0004_01_000003 of capacity <memory:1024, vCores:1> on host hadoop-220-7:42517, which currently has 1 containers, <memory:1024, vCores:1> used and <memory:7168, vCores:15> available
2013-08-10 17:17:27,489 INFO org.apache.hadoop.yarn.server.resourcemanager.scheduler.capacity.LeafQueue: assignedContainer application=application_1376154442901_0004 container=Container: [ContainerId: container_1376154442901_0004_01_000003, NodeId: hadoop-220-7:42517, NodeHttpAddress: hadoop-220-7:8042, Resource: <memory:1024, vCores:1>, Priority: 20, State: NEW, Token: null, Status: container_id {, app_attempt_id {, application_id {, id: 4, cluster_timestamp: 1376154442901, }, attemptId: 1, }, id: 3, }, state: C_NEW, ] containerId=container_1376154442901_0004_01_000003 queue=default: capacity=1.0, absoluteCapacity=1.0, usedResources=<memory:3072, vCores:2>usedCapacity=0.0625, absoluteUsedCapacity=0.0625, numApps=1, numContainers=2 usedCapacity=0.0625 absoluteUsedCapacity=0.0625 used=<memory:3072, vCores:2> cluster=<memory:49152, vCores:96>
2013-08-10 17:17:27,489 INFO org.apache.hadoop.yarn.server.resourcemanager.scheduler.capacity.ParentQueue: Re-sorting queues since queue: root.default stats: default: capacity=1.0, absoluteCapacity=1.0, usedResources=<memory:4096, vCores:3>usedCapacity=0.083333336, absoluteUsedCapacity=0.083333336, numApps=1, numContainers=3
2013-08-10 17:17:27,489 INFO org.apache.hadoop.yarn.server.resourcemanager.scheduler.capacity.ParentQueue: assignedContainer queue=root usedCapacity=0.083333336 absoluteUsedCapacity=0.083333336 used=<memory:4096, vCores:3> cluster=<memory:49152, vCores:96>
2013-08-10 17:17:28,189 INFO org.apache.hadoop.yarn.server.resourcemanager.rmcontainer.RMContainerImpl: container_1376154442901_0004_01_000002 Container Transitioned from ALLOCATED to ACQUIRED
2013-08-10 17:17:28,191 INFO org.apache.hadoop.yarn.server.resourcemanager.rmcontainer.RMContainerImpl: container_1376154442901_0004_01_000003 Container Transitioned from ALLOCATED to ACQUIRED
2013-08-10 17:17:28,493 INFO org.apache.hadoop.yarn.server.resourcemanager.rmcontainer.RMContainerImpl: container_1376154442901_0004_01_000003 Container Transitioned from ACQUIRED to RUNNING
2013-08-10 17:17:29,218 INFO org.apache.hadoop.yarn.server.resourcemanager.scheduler.AppSchedulingInfo: checking for deactivate... 
2013-08-10 17:17:30,336 INFO org.apache.hadoop.yarn.server.resourcemanager.rmcontainer.RMContainerImpl: container_1376154442901_0004_01_000002 Container Transitioned from ACQUIRED to RUNNING
2013-08-10 17:20:10,746 INFO org.apache.hadoop.yarn.server.resourcemanager.rmcontainer.RMContainerImpl: container_1376154442901_0004_01_000003 Container Transitioned from RUNNING to COMPLETED
2013-08-10 17:20:10,746 INFO org.apache.hadoop.yarn.server.resourcemanager.scheduler.common.fica.FiCaSchedulerApp: Completed container: container_1376154442901_0004_01_000003 in state: COMPLETED event:FINISHED
2013-08-10 17:20:10,746 INFO org.apache.hadoop.yarn.server.resourcemanager.RMAuditLogger: USER=ubuntu	OPERATION=AM Released Container	TARGET=SchedulerApp	RESULT=SUCCESS	APPID=application_1376154442901_0004	CONTAINERID=container_1376154442901_0004_01_000003
2013-08-10 17:20:10,746 INFO org.apache.hadoop.yarn.server.resourcemanager.scheduler.common.fica.FiCaSchedulerNode: Released container container_1376154442901_0004_01_000003 of capacity <memory:1024, vCores:1> on host hadoop-220-7:42517, which currently has 0 containers, <memory:0, vCores:0> used and <memory:8192, vCores:16> available, release resources=true
2013-08-10 17:20:10,746 INFO org.apache.hadoop.yarn.server.resourcemanager.scheduler.capacity.LeafQueue: default used=<memory:3072, vCores:2> numContainers=2 user=ubuntu user-resources=<memory:3072, vCores:2>
2013-08-10 17:20:10,748 INFO org.apache.hadoop.yarn.server.resourcemanager.scheduler.capacity.LeafQueue: completedContainer container=Container: [ContainerId: container_1376154442901_0004_01_000003, NodeId: hadoop-220-7:42517, NodeHttpAddress: hadoop-220-7:8042, Resource: <memory:1024, vCores:1>, Priority: 20, State: NEW, Token: null, Status: container_id {, app_attempt_id {, application_id {, id: 4, cluster_timestamp: 1376154442901, }, attemptId: 1, }, id: 3, }, state: C_COMPLETE, diagnostics: "Container killed by the ApplicationMaster.\n", exit_status: 0, ] resource=<memory:1024, vCores:1> queue=default: capacity=1.0, absoluteCapacity=1.0, usedResources=<memory:3072, vCores:2>usedCapacity=0.0625, absoluteUsedCapacity=0.0625, numApps=1, numContainers=2 usedCapacity=0.0625 absoluteUsedCapacity=0.0625 used=<memory:3072, vCores:2> cluster=<memory:49152, vCores:96>
2013-08-10 17:20:10,748 INFO org.apache.hadoop.yarn.server.resourcemanager.scheduler.capacity.ParentQueue: completedContainer queue=root usedCapacity=0.0625 absoluteUsedCapacity=0.0625 used=<memory:3072, vCores:2> cluster=<memory:49152, vCores:96>
2013-08-10 17:20:10,748 INFO org.apache.hadoop.yarn.server.resourcemanager.scheduler.capacity.CapacityScheduler: Application appattempt_1376154442901_0004_000001 released container container_1376154442901_0004_01_000003 on node: host: hadoop-220-7:42517 #containers=0 available=8192 used=0 with event: FINISHED
2013-08-10 17:20:23,872 INFO org.apache.hadoop.yarn.server.resourcemanager.rmcontainer.RMContainerImpl: container_1376154442901_0004_01_000002 Container Transitioned from RUNNING to COMPLETED
2013-08-10 17:20:23,873 INFO org.apache.hadoop.yarn.server.resourcemanager.scheduler.common.fica.FiCaSchedulerApp: Completed container: container_1376154442901_0004_01_000002 in state: COMPLETED event:FINISHED
2013-08-10 17:20:23,873 INFO org.apache.hadoop.yarn.server.resourcemanager.RMAuditLogger: USER=ubuntu	OPERATION=AM Released Container	TARGET=SchedulerApp	RESULT=SUCCESS	APPID=application_1376154442901_0004	CONTAINERID=container_1376154442901_0004_01_000002
2013-08-10 17:20:23,873 INFO org.apache.hadoop.yarn.server.resourcemanager.scheduler.common.fica.FiCaSchedulerNode: Released container container_1376154442901_0004_01_000002 of capacity <memory:1024, vCores:1> on host hadoop-220-5:59721, which currently has 0 containers, <memory:0, vCores:0> used and <memory:8192, vCores:16> available, release resources=true
2013-08-10 17:20:23,873 INFO org.apache.hadoop.yarn.server.resourcemanager.scheduler.capacity.LeafQueue: default used=<memory:2048, vCores:1> numContainers=1 user=ubuntu user-resources=<memory:2048, vCores:1>
2013-08-10 17:20:23,875 INFO org.apache.hadoop.yarn.server.resourcemanager.scheduler.capacity.LeafQueue: completedContainer container=Container: [ContainerId: container_1376154442901_0004_01_000002, NodeId: hadoop-220-5:59721, NodeHttpAddress: hadoop-220-5:8042, Resource: <memory:1024, vCores:1>, Priority: 20, State: NEW, Token: null, Status: container_id {, app_attempt_id {, application_id {, id: 4, cluster_timestamp: 1376154442901, }, attemptId: 1, }, id: 2, }, state: C_COMPLETE, diagnostics: "Container killed by the ApplicationMaster.\n\n", exit_status: 143, ] resource=<memory:1024, vCores:1> queue=default: capacity=1.0, absoluteCapacity=1.0, usedResources=<memory:2048, vCores:1>usedCapacity=0.041666668, absoluteUsedCapacity=0.041666668, numApps=1, numContainers=1 usedCapacity=0.041666668 absoluteUsedCapacity=0.041666668 used=<memory:2048, vCores:1> cluster=<memory:49152, vCores:96>
2013-08-10 17:20:23,875 INFO org.apache.hadoop.yarn.server.resourcemanager.scheduler.capacity.ParentQueue: completedContainer queue=root usedCapacity=0.041666668 absoluteUsedCapacity=0.041666668 used=<memory:2048, vCores:1> cluster=<memory:49152, vCores:96>
2013-08-10 17:20:23,875 INFO org.apache.hadoop.yarn.server.resourcemanager.scheduler.capacity.CapacityScheduler: Application appattempt_1376154442901_0004_000001 released container container_1376154442901_0004_01_000002 on node: host: hadoop-220-5:59721 #containers=0 available=8192 used=0 with event: FINISHED
2013-08-10 17:20:28,090 INFO org.apache.hadoop.yarn.server.resourcemanager.rmapp.attempt.RMAppAttemptImpl: appattempt_1376154442901_0004_000001 State change from RUNNING to FINISHING
2013-08-10 17:20:28,090 INFO org.apache.hadoop.yarn.server.resourcemanager.rmapp.RMAppImpl: application_1376154442901_0004 State change from RUNNING to FINISHING
2013-08-10 17:20:28,533 INFO org.apache.hadoop.yarn.server.resourcemanager.rmcontainer.RMContainerImpl: container_1376154442901_0004_01_000001 Container Transitioned from RUNNING to COMPLETED
2013-08-10 17:20:28,533 INFO org.apache.hadoop.yarn.server.resourcemanager.scheduler.common.fica.FiCaSchedulerApp: Completed container: container_1376154442901_0004_01_000001 in state: COMPLETED event:FINISHED
2013-08-10 17:20:28,533 INFO org.apache.hadoop.yarn.server.resourcemanager.RMAuditLogger: USER=ubuntu	OPERATION=AM Released Container	TARGET=SchedulerApp	RESULT=SUCCESS	APPID=application_1376154442901_0004	CONTAINERID=container_1376154442901_0004_01_000001
2013-08-10 17:20:28,533 INFO org.apache.hadoop.yarn.server.resourcemanager.scheduler.common.fica.FiCaSchedulerNode: Released container container_1376154442901_0004_01_000001 of capacity <memory:2048, vCores:1> on host hadoop-220-6:56687, which currently has 0 containers, <memory:0, vCores:0> used and <memory:8192, vCores:16> available, release resources=true
2013-08-10 17:20:28,533 INFO org.apache.hadoop.yarn.server.resourcemanager.scheduler.capacity.LeafQueue: default used=<memory:0, vCores:0> numContainers=0 user=ubuntu user-resources=<memory:0, vCores:0>
2013-08-10 17:20:28,535 INFO org.apache.hadoop.yarn.server.resourcemanager.scheduler.capacity.LeafQueue: completedContainer container=Container: [ContainerId: container_1376154442901_0004_01_000001, NodeId: hadoop-220-6:56687, NodeHttpAddress: hadoop-220-6:8042, Resource: <memory:2048, vCores:1>, Priority: 0, State: NEW, Token: null, Status: container_id {, app_attempt_id {, application_id {, id: 4, cluster_timestamp: 1376154442901, }, attemptId: 1, }, id: 1, }, state: C_COMPLETE, diagnostics: "", exit_status: 0, ] resource=<memory:2048, vCores:1> queue=default: capacity=1.0, absoluteCapacity=1.0, usedResources=<memory:0, vCores:0>usedCapacity=0.0, absoluteUsedCapacity=0.0, numApps=1, numContainers=0 usedCapacity=0.0 absoluteUsedCapacity=0.0 used=<memory:0, vCores:0> cluster=<memory:49152, vCores:96>
2013-08-10 17:20:28,535 INFO org.apache.hadoop.yarn.server.resourcemanager.scheduler.capacity.ParentQueue: completedContainer queue=root usedCapacity=0.0 absoluteUsedCapacity=0.0 used=<memory:0, vCores:0> cluster=<memory:49152, vCores:96>
2013-08-10 17:20:28,535 INFO org.apache.hadoop.yarn.server.resourcemanager.scheduler.capacity.CapacityScheduler: Application appattempt_1376154442901_0004_000001 released container container_1376154442901_0004_01_000001 on node: host: hadoop-220-6:56687 #containers=0 available=8192 used=0 with event: FINISHED
2013-08-10 17:20:28,535 INFO org.apache.hadoop.yarn.server.resourcemanager.rmapp.attempt.RMAppAttemptImpl: appattempt_1376154442901_0004_000001 State change from FINISHING to FINISHED
2013-08-10 17:20:28,536 INFO org.apache.hadoop.yarn.server.resourcemanager.rmapp.RMAppImpl: application_1376154442901_0004 State change from FINISHING to FINISHED
2013-08-10 17:20:28,536 INFO org.apache.hadoop.yarn.server.resourcemanager.scheduler.capacity.CapacityScheduler: Application appattempt_1376154442901_0004_000001 is done. finalState=FINISHED
2013-08-10 17:20:28,537 INFO org.apache.hadoop.yarn.server.resourcemanager.scheduler.AppSchedulingInfo: Application application_1376154442901_0004 requests cleared
2013-08-10 17:20:28,537 INFO org.apache.hadoop.yarn.server.resourcemanager.scheduler.capacity.LeafQueue: Application removed - appId: application_1376154442901_0004 user: ubuntu queue: default #user-pending-applications: 0 #user-active-applications: 0 #queue-pending-applications: 0 #queue-active-applications: 0
2013-08-10 17:20:28,537 INFO org.apache.hadoop.yarn.server.resourcemanager.scheduler.capacity.ParentQueue: Application removed - appId: application_1376154442901_0004 user: ubuntu leaf-queue of parent: root #applications: 0
2013-08-10 17:20:28,537 INFO org.apache.hadoop.yarn.server.resourcemanager.RMAuditLogger: USER=ubuntu	OPERATION=Application Finished - Succeeded	TARGET=RMAppManager	RESULT=SUCCESS	APPID=application_1376154442901_0004
2013-08-10 17:20:28,538 INFO org.apache.hadoop.yarn.server.resourcemanager.RMAppManager$ApplicationSummary: appId=application_1376154442901_0004,name=TeraGen,user=ubuntu,queue=default,state=FINISHED,trackingUrl=hadoop-220-1.novalocal:8088/proxy/application_1376154442901_0004/jobhistory/job/job_1376154442901_0004,appMasterHost=hadoop-220-6,startTime=1376155036754,finishTime=1376155228090
2013-08-10 17:20:28,538 INFO org.apache.hadoop.yarn.server.resourcemanager.recovery.RMStateStore: Removing info for app: application_1376154442901_0004
2013-08-10 17:20:28,539 INFO org.apache.hadoop.yarn.server.resourcemanager.amlauncher.AMLauncher: Cleaning master appattempt_1376154442901_0004_000001
2013-08-10 17:20:29,388 INFO org.apache.hadoop.yarn.server.resourcemanager.ClientRMService: Allocated new applicationId: 5
2013-08-10 17:20:31,322 INFO org.apache.hadoop.yarn.server.resourcemanager.ClientRMService: Storing Application with id application_1376154442901_0005
2013-08-10 17:20:31,323 INFO org.apache.hadoop.yarn.server.resourcemanager.recovery.RMStateStore: Storing info for app: application_1376154442901_0005
2013-08-10 17:20:31,323 INFO org.apache.hadoop.yarn.server.resourcemanager.ClientRMService: Application with id 5 submitted by user ubuntu
2013-08-10 17:20:31,323 INFO org.apache.hadoop.yarn.server.resourcemanager.RMAuditLogger: USER=ubuntu	IP=192.168.100.9	OPERATION=Submit Application Request	TARGET=ClientRMService	RESULT=SUCCESS	APPID=application_1376154442901_0005
2013-08-10 17:20:31,324 INFO org.apache.hadoop.yarn.server.resourcemanager.rmapp.RMAppImpl: application_1376154442901_0005 State change from NEW to SUBMITTED
2013-08-10 17:20:31,325 INFO org.apache.hadoop.yarn.server.resourcemanager.ApplicationMasterService: Registering appattempt_1376154442901_0005_000001
2013-08-10 17:20:31,325 INFO org.apache.hadoop.yarn.server.resourcemanager.rmapp.attempt.RMAppAttemptImpl: appattempt_1376154442901_0005_000001 State change from NEW to SUBMITTED
2013-08-10 17:20:31,326 INFO org.apache.hadoop.yarn.server.resourcemanager.scheduler.capacity.LeafQueue: Application application_1376154442901_0005 from user: ubuntu activated in queue: default
2013-08-10 17:20:31,326 INFO org.apache.hadoop.yarn.server.resourcemanager.scheduler.capacity.LeafQueue: Application added - appId: application_1376154442901_0005 user: org.apache.hadoop.yarn.server.resourcemanager.scheduler.capacity.LeafQueue$User@3bead2d, leaf-queue: default #user-pending-applications: 0 #user-active-applications: 1 #queue-pending-applications: 0 #queue-active-applications: 1
2013-08-10 17:20:31,326 INFO org.apache.hadoop.yarn.server.resourcemanager.scheduler.capacity.ParentQueue: Application added - appId: application_1376154442901_0005 user: ubuntu leaf-queue of parent: root #applications: 1
2013-08-10 17:20:31,326 INFO org.apache.hadoop.yarn.server.resourcemanager.scheduler.capacity.CapacityScheduler: Application Submission: appattempt_1376154442901_0005_000001, user: ubuntu queue: default: capacity=1.0, absoluteCapacity=1.0, usedResources=<memory:0, vCores:0>usedCapacity=0.0, absoluteUsedCapacity=0.0, numApps=1, numContainers=0, currently active: 1
2013-08-10 17:20:31,326 INFO org.apache.hadoop.yarn.server.resourcemanager.rmapp.attempt.RMAppAttemptImpl: appattempt_1376154442901_0005_000001 State change from SUBMITTED to SCHEDULED
2013-08-10 17:20:31,327 INFO org.apache.hadoop.yarn.server.resourcemanager.rmapp.RMAppImpl: application_1376154442901_0005 State change from SUBMITTED to ACCEPTED
2013-08-10 17:20:31,542 INFO org.apache.hadoop.yarn.server.resourcemanager.rmcontainer.RMContainerImpl: container_1376154442901_0005_01_000001 Container Transitioned from NEW to ALLOCATED
2013-08-10 17:20:31,542 INFO org.apache.hadoop.yarn.server.resourcemanager.RMAuditLogger: USER=ubuntu	OPERATION=AM Allocated Container	TARGET=SchedulerApp	RESULT=SUCCESS	APPID=application_1376154442901_0005	CONTAINERID=container_1376154442901_0005_01_000001
2013-08-10 17:20:31,542 INFO org.apache.hadoop.yarn.server.resourcemanager.scheduler.common.fica.FiCaSchedulerNode: Assigned container container_1376154442901_0005_01_000001 of capacity <memory:2048, vCores:1> on host hadoop-220-6:56687, which currently has 1 containers, <memory:2048, vCores:1> used and <memory:6144, vCores:15> available
2013-08-10 17:20:31,544 INFO org.apache.hadoop.yarn.server.resourcemanager.scheduler.capacity.LeafQueue: assignedContainer application=application_1376154442901_0005 container=Container: [ContainerId: container_1376154442901_0005_01_000001, NodeId: hadoop-220-6:56687, NodeHttpAddress: hadoop-220-6:8042, Resource: <memory:2048, vCores:1>, Priority: 0, State: NEW, Token: null, Status: container_id {, app_attempt_id {, application_id {, id: 5, cluster_timestamp: 1376154442901, }, attemptId: 1, }, id: 1, }, state: C_NEW, ] containerId=container_1376154442901_0005_01_000001 queue=default: capacity=1.0, absoluteCapacity=1.0, usedResources=<memory:0, vCores:0>usedCapacity=0.0, absoluteUsedCapacity=0.0, numApps=1, numContainers=0 usedCapacity=0.0 absoluteUsedCapacity=0.0 used=<memory:0, vCores:0> cluster=<memory:49152, vCores:96>
2013-08-10 17:20:31,544 INFO org.apache.hadoop.yarn.server.resourcemanager.scheduler.capacity.ParentQueue: Re-sorting queues since queue: root.default stats: default: capacity=1.0, absoluteCapacity=1.0, usedResources=<memory:2048, vCores:1>usedCapacity=0.041666668, absoluteUsedCapacity=0.041666668, numApps=1, numContainers=1
2013-08-10 17:20:31,545 INFO org.apache.hadoop.yarn.server.resourcemanager.rmcontainer.RMContainerImpl: container_1376154442901_0005_01_000001 Container Transitioned from ALLOCATED to ACQUIRED
2013-08-10 17:20:31,545 INFO org.apache.hadoop.yarn.server.resourcemanager.scheduler.capacity.ParentQueue: assignedContainer queue=root usedCapacity=0.041666668 absoluteUsedCapacity=0.041666668 used=<memory:2048, vCores:1> cluster=<memory:49152, vCores:96>
2013-08-10 17:20:31,546 INFO org.apache.hadoop.yarn.server.resourcemanager.rmapp.attempt.RMAppAttemptImpl: Storing attempt: AppId: application_1376154442901_0005 AttemptId: appattempt_1376154442901_0005_000001 MasterContainer: Container: [ContainerId: container_1376154442901_0005_01_000001, NodeId: hadoop-220-6:56687, NodeHttpAddress: hadoop-220-6:8042, Resource: <memory:2048, vCores:1>, Priority: 0, State: NEW, Token: null, Status: container_id {, app_attempt_id {, application_id {, id: 5, cluster_timestamp: 1376154442901, }, attemptId: 1, }, id: 1, }, state: C_NEW, ]
2013-08-10 17:20:31,547 INFO org.apache.hadoop.yarn.server.resourcemanager.recovery.RMStateStore: Storing info for attempt: appattempt_1376154442901_0005_000001
2013-08-10 17:20:31,547 INFO org.apache.hadoop.yarn.server.resourcemanager.rmapp.attempt.RMAppAttemptImpl: appattempt_1376154442901_0005_000001 State change from SCHEDULED to ALLOCATED_SAVING
2013-08-10 17:20:31,548 INFO org.apache.hadoop.yarn.server.resourcemanager.rmapp.attempt.RMAppAttemptImpl: appattempt_1376154442901_0005_000001 State change from ALLOCATED_SAVING to ALLOCATED
2013-08-10 17:20:31,549 INFO org.apache.hadoop.yarn.server.resourcemanager.amlauncher.AMLauncher: Launching masterappattempt_1376154442901_0005_000001
2013-08-10 17:20:31,551 INFO org.apache.hadoop.yarn.server.resourcemanager.amlauncher.AMLauncher: Setting up container Container: [ContainerId: container_1376154442901_0005_01_000001, NodeId: hadoop-220-6:56687, NodeHttpAddress: hadoop-220-6:8042, Resource: <memory:2048, vCores:1>, Priority: 0, State: NEW, Token: null, Status: container_id {, app_attempt_id {, application_id {, id: 5, cluster_timestamp: 1376154442901, }, attemptId: 1, }, id: 1, }, state: C_NEW, ] for AM appattempt_1376154442901_0005_000001
2013-08-10 17:20:31,551 INFO org.apache.hadoop.yarn.server.resourcemanager.amlauncher.AMLauncher: Command to launch container container_1376154442901_0005_01_000001 : $JAVA_HOME/bin/java -Dlog4j.configuration=container-log4j.properties -Dyarn.app.mapreduce.container.log.dir=<LOG_DIR> -Dyarn.app.mapreduce.container.log.filesize=0 -Dhadoop.root.logger=INFO,CLA  -Xmx1024m org.apache.hadoop.mapreduce.v2.app.MRAppMaster 1><LOG_DIR>/stdout 2><LOG_DIR>/stderr 
2013-08-10 17:20:31,566 INFO org.apache.hadoop.yarn.server.resourcemanager.amlauncher.AMLauncher: Done launching container Container: [ContainerId: container_1376154442901_0005_01_000001, NodeId: hadoop-220-6:56687, NodeHttpAddress: hadoop-220-6:8042, Resource: <memory:2048, vCores:1>, Priority: 0, State: NEW, Token: null, Status: container_id {, app_attempt_id {, application_id {, id: 5, cluster_timestamp: 1376154442901, }, attemptId: 1, }, id: 1, }, state: C_NEW, ] for AM appattempt_1376154442901_0005_000001
2013-08-10 17:20:31,567 INFO org.apache.hadoop.yarn.server.resourcemanager.rmapp.attempt.RMAppAttemptImpl: appattempt_1376154442901_0005_000001 State change from ALLOCATED to LAUNCHED
2013-08-10 17:20:32,548 INFO org.apache.hadoop.yarn.server.resourcemanager.rmcontainer.RMContainerImpl: container_1376154442901_0005_01_000001 Container Transitioned from ACQUIRED to RUNNING
2013-08-10 17:20:37,624 INFO org.apache.hadoop.yarn.server.resourcemanager.ApplicationMasterService: AM registration appattempt_1376154442901_0005_000001
2013-08-10 17:20:37,625 INFO org.apache.hadoop.yarn.server.resourcemanager.RMAuditLogger: USER=ubuntu	IP=192.168.100.34	OPERATION=Register App Master	TARGET=ApplicationMasterService	RESULT=SUCCESS	APPID=application_1376154442901_0005	APPATTEMPTID=appattempt_1376154442901_0005_000001
2013-08-10 17:20:37,626 INFO org.apache.hadoop.yarn.server.resourcemanager.rmapp.attempt.RMAppAttemptImpl: appattempt_1376154442901_0005_000001 State change from LAUNCHED to RUNNING
2013-08-10 17:20:37,626 INFO org.apache.hadoop.yarn.server.resourcemanager.rmapp.RMAppImpl: application_1376154442901_0005 State change from ACCEPTED to RUNNING
2013-08-10 17:20:38,734 INFO org.apache.hadoop.yarn.server.resourcemanager.rmcontainer.RMContainerImpl: container_1376154442901_0005_01_000002 Container Transitioned from NEW to ALLOCATED
2013-08-10 17:20:38,735 INFO org.apache.hadoop.yarn.server.resourcemanager.RMAuditLogger: USER=ubuntu	OPERATION=AM Allocated Container	TARGET=SchedulerApp	RESULT=SUCCESS	APPID=application_1376154442901_0005	CONTAINERID=container_1376154442901_0005_01_000002
2013-08-10 17:20:38,736 INFO org.apache.hadoop.yarn.server.resourcemanager.scheduler.common.fica.FiCaSchedulerNode: Assigned container container_1376154442901_0005_01_000002 of capacity <memory:1024, vCores:1> on host hadoop-220-3:58548, which currently has 1 containers, <memory:1024, vCores:1> used and <memory:7168, vCores:15> available
2013-08-10 17:20:38,737 INFO org.apache.hadoop.yarn.server.resourcemanager.scheduler.capacity.LeafQueue: assignedContainer application=application_1376154442901_0005 container=Container: [ContainerId: container_1376154442901_0005_01_000002, NodeId: hadoop-220-3:58548, NodeHttpAddress: hadoop-220-3:8042, Resource: <memory:1024, vCores:1>, Priority: 20, State: NEW, Token: null, Status: container_id {, app_attempt_id {, application_id {, id: 5, cluster_timestamp: 1376154442901, }, attemptId: 1, }, id: 2, }, state: C_NEW, ] containerId=container_1376154442901_0005_01_000002 queue=default: capacity=1.0, absoluteCapacity=1.0, usedResources=<memory:2048, vCores:1>usedCapacity=0.041666668, absoluteUsedCapacity=0.041666668, numApps=1, numContainers=1 usedCapacity=0.041666668 absoluteUsedCapacity=0.041666668 used=<memory:2048, vCores:1> cluster=<memory:49152, vCores:96>
2013-08-10 17:20:38,737 INFO org.apache.hadoop.yarn.server.resourcemanager.scheduler.capacity.ParentQueue: Re-sorting queues since queue: root.default stats: default: capacity=1.0, absoluteCapacity=1.0, usedResources=<memory:3072, vCores:2>usedCapacity=0.0625, absoluteUsedCapacity=0.0625, numApps=1, numContainers=2
2013-08-10 17:20:38,737 INFO org.apache.hadoop.yarn.server.resourcemanager.scheduler.capacity.ParentQueue: assignedContainer queue=root usedCapacity=0.0625 absoluteUsedCapacity=0.0625 used=<memory:3072, vCores:2> cluster=<memory:49152, vCores:96>
2013-08-10 17:20:38,866 INFO org.apache.hadoop.yarn.server.resourcemanager.rmcontainer.RMContainerImpl: container_1376154442901_0005_01_000003 Container Transitioned from NEW to ALLOCATED
2013-08-10 17:20:38,866 INFO org.apache.hadoop.yarn.server.resourcemanager.RMAuditLogger: USER=ubuntu	OPERATION=AM Allocated Container	TARGET=SchedulerApp	RESULT=SUCCESS	APPID=application_1376154442901_0005	CONTAINERID=container_1376154442901_0005_01_000003
2013-08-10 17:20:38,866 INFO org.apache.hadoop.yarn.server.resourcemanager.scheduler.common.fica.FiCaSchedulerNode: Assigned container container_1376154442901_0005_01_000003 of capacity <memory:1024, vCores:1> on host hadoop-220-7:42517, which currently has 1 containers, <memory:1024, vCores:1> used and <memory:7168, vCores:15> available
2013-08-10 17:20:38,867 INFO org.apache.hadoop.yarn.server.resourcemanager.scheduler.capacity.LeafQueue: assignedContainer application=application_1376154442901_0005 container=Container: [ContainerId: container_1376154442901_0005_01_000003, NodeId: hadoop-220-7:42517, NodeHttpAddress: hadoop-220-7:8042, Resource: <memory:1024, vCores:1>, Priority: 20, State: NEW, Token: null, Status: container_id {, app_attempt_id {, application_id {, id: 5, cluster_timestamp: 1376154442901, }, attemptId: 1, }, id: 3, }, state: C_NEW, ] containerId=container_1376154442901_0005_01_000003 queue=default: capacity=1.0, absoluteCapacity=1.0, usedResources=<memory:3072, vCores:2>usedCapacity=0.0625, absoluteUsedCapacity=0.0625, numApps=1, numContainers=2 usedCapacity=0.0625 absoluteUsedCapacity=0.0625 used=<memory:3072, vCores:2> cluster=<memory:49152, vCores:96>
2013-08-10 17:20:38,867 INFO org.apache.hadoop.yarn.server.resourcemanager.scheduler.capacity.ParentQueue: Re-sorting queues since queue: root.default stats: default: capacity=1.0, absoluteCapacity=1.0, usedResources=<memory:4096, vCores:3>usedCapacity=0.083333336, absoluteUsedCapacity=0.083333336, numApps=1, numContainers=3
2013-08-10 17:20:38,868 INFO org.apache.hadoop.yarn.server.resourcemanager.scheduler.capacity.ParentQueue: assignedContainer queue=root usedCapacity=0.083333336 absoluteUsedCapacity=0.083333336 used=<memory:4096, vCores:3> cluster=<memory:49152, vCores:96>
2013-08-10 17:20:39,683 INFO org.apache.hadoop.yarn.server.resourcemanager.rmcontainer.RMContainerImpl: container_1376154442901_0005_01_000002 Container Transitioned from ALLOCATED to ACQUIRED
2013-08-10 17:20:39,686 INFO org.apache.hadoop.yarn.server.resourcemanager.rmcontainer.RMContainerImpl: container_1376154442901_0005_01_000003 Container Transitioned from ALLOCATED to ACQUIRED
2013-08-10 17:20:40,713 INFO org.apache.hadoop.yarn.server.resourcemanager.scheduler.AppSchedulingInfo: checking for deactivate... 
2013-08-10 17:20:40,884 INFO org.apache.hadoop.yarn.server.resourcemanager.rmcontainer.RMContainerImpl: container_1376154442901_0005_01_000003 Container Transitioned from ACQUIRED to RUNNING
2013-08-10 17:20:41,794 INFO org.apache.hadoop.yarn.server.resourcemanager.rmcontainer.RMContainerImpl: container_1376154442901_0005_01_000002 Container Transitioned from ACQUIRED to RUNNING
2013-08-10 17:23:28,041 INFO org.apache.hadoop.yarn.server.resourcemanager.rmcontainer.RMContainerImpl: container_1376154442901_0005_01_000002 Container Transitioned from RUNNING to COMPLETED
2013-08-10 17:23:28,041 INFO org.apache.hadoop.yarn.server.resourcemanager.scheduler.common.fica.FiCaSchedulerApp: Completed container: container_1376154442901_0005_01_000002 in state: COMPLETED event:FINISHED
2013-08-10 17:23:28,041 INFO org.apache.hadoop.yarn.server.resourcemanager.RMAuditLogger: USER=ubuntu	OPERATION=AM Released Container	TARGET=SchedulerApp	RESULT=SUCCESS	APPID=application_1376154442901_0005	CONTAINERID=container_1376154442901_0005_01_000002
2013-08-10 17:23:28,041 INFO org.apache.hadoop.yarn.server.resourcemanager.scheduler.common.fica.FiCaSchedulerNode: Released container container_1376154442901_0005_01_000002 of capacity <memory:1024, vCores:1> on host hadoop-220-3:58548, which currently has 0 containers, <memory:0, vCores:0> used and <memory:8192, vCores:16> available, release resources=true
2013-08-10 17:23:28,042 INFO org.apache.hadoop.yarn.server.resourcemanager.scheduler.capacity.LeafQueue: default used=<memory:3072, vCores:2> numContainers=2 user=ubuntu user-resources=<memory:3072, vCores:2>
2013-08-10 17:23:28,043 INFO org.apache.hadoop.yarn.server.resourcemanager.scheduler.capacity.LeafQueue: completedContainer container=Container: [ContainerId: container_1376154442901_0005_01_000002, NodeId: hadoop-220-3:58548, NodeHttpAddress: hadoop-220-3:8042, Resource: <memory:1024, vCores:1>, Priority: 20, State: NEW, Token: null, Status: container_id {, app_attempt_id {, application_id {, id: 5, cluster_timestamp: 1376154442901, }, attemptId: 1, }, id: 2, }, state: C_COMPLETE, diagnostics: "Container killed by the ApplicationMaster.\n\n", exit_status: 143, ] resource=<memory:1024, vCores:1> queue=default: capacity=1.0, absoluteCapacity=1.0, usedResources=<memory:3072, vCores:2>usedCapacity=0.0625, absoluteUsedCapacity=0.0625, numApps=1, numContainers=2 usedCapacity=0.0625 absoluteUsedCapacity=0.0625 used=<memory:3072, vCores:2> cluster=<memory:49152, vCores:96>
2013-08-10 17:23:28,043 INFO org.apache.hadoop.yarn.server.resourcemanager.scheduler.capacity.ParentQueue: completedContainer queue=root usedCapacity=0.0625 absoluteUsedCapacity=0.0625 used=<memory:3072, vCores:2> cluster=<memory:49152, vCores:96>
2013-08-10 17:23:28,044 INFO org.apache.hadoop.yarn.server.resourcemanager.scheduler.capacity.CapacityScheduler: Application appattempt_1376154442901_0005_000001 released container container_1376154442901_0005_01_000002 on node: host: hadoop-220-3:58548 #containers=0 available=8192 used=0 with event: FINISHED
2013-08-10 17:23:37,716 INFO org.apache.hadoop.yarn.server.resourcemanager.rmcontainer.RMContainerImpl: container_1376154442901_0005_01_000003 Container Transitioned from RUNNING to COMPLETED
2013-08-10 17:23:37,717 INFO org.apache.hadoop.yarn.server.resourcemanager.scheduler.common.fica.FiCaSchedulerApp: Completed container: container_1376154442901_0005_01_000003 in state: COMPLETED event:FINISHED
2013-08-10 17:23:37,717 INFO org.apache.hadoop.yarn.server.resourcemanager.RMAuditLogger: USER=ubuntu	OPERATION=AM Released Container	TARGET=SchedulerApp	RESULT=SUCCESS	APPID=application_1376154442901_0005	CONTAINERID=container_1376154442901_0005_01_000003
2013-08-10 17:23:37,717 INFO org.apache.hadoop.yarn.server.resourcemanager.scheduler.common.fica.FiCaSchedulerNode: Released container container_1376154442901_0005_01_000003 of capacity <memory:1024, vCores:1> on host hadoop-220-7:42517, which currently has 0 containers, <memory:0, vCores:0> used and <memory:8192, vCores:16> available, release resources=true
2013-08-10 17:23:37,717 INFO org.apache.hadoop.yarn.server.resourcemanager.scheduler.capacity.LeafQueue: default used=<memory:2048, vCores:1> numContainers=1 user=ubuntu user-resources=<memory:2048, vCores:1>
2013-08-10 17:23:37,719 INFO org.apache.hadoop.yarn.server.resourcemanager.scheduler.capacity.LeafQueue: completedContainer container=Container: [ContainerId: container_1376154442901_0005_01_000003, NodeId: hadoop-220-7:42517, NodeHttpAddress: hadoop-220-7:8042, Resource: <memory:1024, vCores:1>, Priority: 20, State: NEW, Token: null, Status: container_id {, app_attempt_id {, application_id {, id: 5, cluster_timestamp: 1376154442901, }, attemptId: 1, }, id: 3, }, state: C_COMPLETE, diagnostics: "Container killed by the ApplicationMaster.\n\n", exit_status: 143, ] resource=<memory:1024, vCores:1> queue=default: capacity=1.0, absoluteCapacity=1.0, usedResources=<memory:2048, vCores:1>usedCapacity=0.041666668, absoluteUsedCapacity=0.041666668, numApps=1, numContainers=1 usedCapacity=0.041666668 absoluteUsedCapacity=0.041666668 used=<memory:2048, vCores:1> cluster=<memory:49152, vCores:96>
2013-08-10 17:23:37,720 INFO org.apache.hadoop.yarn.server.resourcemanager.scheduler.capacity.ParentQueue: completedContainer queue=root usedCapacity=0.041666668 absoluteUsedCapacity=0.041666668 used=<memory:2048, vCores:1> cluster=<memory:49152, vCores:96>
2013-08-10 17:23:37,720 INFO org.apache.hadoop.yarn.server.resourcemanager.scheduler.capacity.CapacityScheduler: Application appattempt_1376154442901_0005_000001 released container container_1376154442901_0005_01_000003 on node: host: hadoop-220-7:42517 #containers=0 available=8192 used=0 with event: FINISHED
2013-08-10 17:23:42,258 INFO org.apache.hadoop.yarn.server.resourcemanager.rmapp.attempt.RMAppAttemptImpl: appattempt_1376154442901_0005_000001 State change from RUNNING to FINISHING
2013-08-10 17:23:42,259 INFO org.apache.hadoop.yarn.server.resourcemanager.rmapp.RMAppImpl: application_1376154442901_0005 State change from RUNNING to FINISHING
2013-08-10 17:23:43,233 INFO org.apache.hadoop.yarn.server.resourcemanager.rmcontainer.RMContainerImpl: container_1376154442901_0005_01_000001 Container Transitioned from RUNNING to COMPLETED
2013-08-10 17:23:43,233 INFO org.apache.hadoop.yarn.server.resourcemanager.scheduler.common.fica.FiCaSchedulerApp: Completed container: container_1376154442901_0005_01_000001 in state: COMPLETED event:FINISHED
2013-08-10 17:23:43,233 INFO org.apache.hadoop.yarn.server.resourcemanager.rmapp.attempt.RMAppAttemptImpl: appattempt_1376154442901_0005_000001 State change from FINISHING to FINISHED
2013-08-10 17:23:43,233 INFO org.apache.hadoop.yarn.server.resourcemanager.RMAuditLogger: USER=ubuntu	OPERATION=AM Released Container	TARGET=SchedulerApp	RESULT=SUCCESS	APPID=application_1376154442901_0005	CONTAINERID=container_1376154442901_0005_01_000001
2013-08-10 17:23:43,234 INFO org.apache.hadoop.yarn.server.resourcemanager.rmapp.RMAppImpl: application_1376154442901_0005 State change from FINISHING to FINISHED
2013-08-10 17:23:43,234 INFO org.apache.hadoop.yarn.server.resourcemanager.scheduler.common.fica.FiCaSchedulerNode: Released container container_1376154442901_0005_01_000001 of capacity <memory:2048, vCores:1> on host hadoop-220-6:56687, which currently has 0 containers, <memory:0, vCores:0> used and <memory:8192, vCores:16> available, release resources=true
2013-08-10 17:23:43,234 INFO org.apache.hadoop.yarn.server.resourcemanager.scheduler.capacity.LeafQueue: default used=<memory:0, vCores:0> numContainers=0 user=ubuntu user-resources=<memory:0, vCores:0>
2013-08-10 17:23:43,235 INFO org.apache.hadoop.yarn.server.resourcemanager.RMAuditLogger: USER=ubuntu	OPERATION=Application Finished - Succeeded	TARGET=RMAppManager	RESULT=SUCCESS	APPID=application_1376154442901_0005
2013-08-10 17:23:43,235 INFO org.apache.hadoop.yarn.server.resourcemanager.amlauncher.AMLauncher: Cleaning master appattempt_1376154442901_0005_000001
2013-08-10 17:23:43,236 INFO org.apache.hadoop.yarn.server.resourcemanager.recovery.RMStateStore: Removing info for app: application_1376154442901_0005
2013-08-10 17:23:43,236 INFO org.apache.hadoop.yarn.server.resourcemanager.scheduler.capacity.LeafQueue: completedContainer container=Container: [ContainerId: container_1376154442901_0005_01_000001, NodeId: hadoop-220-6:56687, NodeHttpAddress: hadoop-220-6:8042, Resource: <memory:2048, vCores:1>, Priority: 0, State: NEW, Token: null, Status: container_id {, app_attempt_id {, application_id {, id: 5, cluster_timestamp: 1376154442901, }, attemptId: 1, }, id: 1, }, state: C_COMPLETE, diagnostics: "", exit_status: 0, ] resource=<memory:2048, vCores:1> queue=default: capacity=1.0, absoluteCapacity=1.0, usedResources=<memory:0, vCores:0>usedCapacity=0.0, absoluteUsedCapacity=0.0, numApps=1, numContainers=0 usedCapacity=0.0 absoluteUsedCapacity=0.0 used=<memory:0, vCores:0> cluster=<memory:49152, vCores:96>
2013-08-10 17:23:43,236 INFO org.apache.hadoop.yarn.server.resourcemanager.RMAppManager$ApplicationSummary: appId=application_1376154442901_0005,name=TeraGen,user=ubuntu,queue=default,state=FINISHED,trackingUrl=hadoop-220-1.novalocal:8088/proxy/application_1376154442901_0005/jobhistory/job/job_1376154442901_0005,appMasterHost=hadoop-220-6,startTime=1376155231322,finishTime=1376155422259
2013-08-10 17:23:43,236 INFO org.apache.hadoop.yarn.server.resourcemanager.scheduler.capacity.ParentQueue: completedContainer queue=root usedCapacity=0.0 absoluteUsedCapacity=0.0 used=<memory:0, vCores:0> cluster=<memory:49152, vCores:96>
2013-08-10 17:23:43,239 INFO org.apache.hadoop.yarn.server.resourcemanager.scheduler.capacity.CapacityScheduler: Application appattempt_1376154442901_0005_000001 released container container_1376154442901_0005_01_000001 on node: host: hadoop-220-6:56687 #containers=0 available=8192 used=0 with event: FINISHED
2013-08-10 17:23:43,240 INFO org.apache.hadoop.yarn.server.resourcemanager.scheduler.capacity.CapacityScheduler: Application appattempt_1376154442901_0005_000001 is done. finalState=FINISHED
2013-08-10 17:23:43,240 INFO org.apache.hadoop.yarn.server.resourcemanager.scheduler.AppSchedulingInfo: Application application_1376154442901_0005 requests cleared
2013-08-10 17:23:43,240 INFO org.apache.hadoop.yarn.server.resourcemanager.scheduler.capacity.LeafQueue: Application removed - appId: application_1376154442901_0005 user: ubuntu queue: default #user-pending-applications: 0 #user-active-applications: 0 #queue-pending-applications: 0 #queue-active-applications: 0
2013-08-10 17:23:43,240 INFO org.apache.hadoop.yarn.server.resourcemanager.scheduler.capacity.ParentQueue: Application removed - appId: application_1376154442901_0005 user: ubuntu leaf-queue of parent: root #applications: 0
2013-08-10 17:23:56,487 INFO org.apache.hadoop.yarn.server.resourcemanager.ClientRMService: Allocated new applicationId: 6
2013-08-10 17:23:56,857 INFO org.apache.hadoop.yarn.server.resourcemanager.ClientRMService: Allocated new applicationId: 7
2013-08-10 17:23:56,980 INFO org.apache.hadoop.yarn.server.resourcemanager.ClientRMService: Allocated new applicationId: 8
2013-08-10 17:23:57,315 INFO org.apache.hadoop.yarn.server.resourcemanager.ClientRMService: Allocated new applicationId: 9
2013-08-10 17:23:57,472 INFO org.apache.hadoop.yarn.server.resourcemanager.ClientRMService: Allocated new applicationId: 10
2013-08-10 17:23:58,341 INFO org.apache.hadoop.yarn.server.resourcemanager.ClientRMService: Storing Application with id application_1376154442901_0006
2013-08-10 17:23:58,341 INFO org.apache.hadoop.yarn.server.resourcemanager.recovery.RMStateStore: Storing info for app: application_1376154442901_0006
2013-08-10 17:23:58,342 INFO org.apache.hadoop.yarn.server.resourcemanager.ClientRMService: Application with id 6 submitted by user ubuntu
2013-08-10 17:23:58,342 INFO org.apache.hadoop.yarn.server.resourcemanager.RMAuditLogger: USER=ubuntu	IP=192.168.100.9	OPERATION=Submit Application Request	TARGET=ClientRMService	RESULT=SUCCESS	APPID=application_1376154442901_0006
2013-08-10 17:23:58,347 INFO org.apache.hadoop.yarn.server.resourcemanager.rmapp.RMAppImpl: application_1376154442901_0006 State change from NEW to SUBMITTED
2013-08-10 17:23:58,347 INFO org.apache.hadoop.yarn.server.resourcemanager.ApplicationMasterService: Registering appattempt_1376154442901_0006_000001
2013-08-10 17:23:58,347 INFO org.apache.hadoop.yarn.server.resourcemanager.rmapp.attempt.RMAppAttemptImpl: appattempt_1376154442901_0006_000001 State change from NEW to SUBMITTED
2013-08-10 17:23:58,348 INFO org.apache.hadoop.yarn.server.resourcemanager.scheduler.capacity.LeafQueue: Application application_1376154442901_0006 from user: ubuntu activated in queue: default
2013-08-10 17:23:58,348 INFO org.apache.hadoop.yarn.server.resourcemanager.scheduler.capacity.LeafQueue: Application added - appId: application_1376154442901_0006 user: org.apache.hadoop.yarn.server.resourcemanager.scheduler.capacity.LeafQueue$User@7e14d761, leaf-queue: default #user-pending-applications: 0 #user-active-applications: 1 #queue-pending-applications: 0 #queue-active-applications: 1
2013-08-10 17:23:58,348 INFO org.apache.hadoop.yarn.server.resourcemanager.scheduler.capacity.ParentQueue: Application added - appId: application_1376154442901_0006 user: ubuntu leaf-queue of parent: root #applications: 1
2013-08-10 17:23:58,348 INFO org.apache.hadoop.yarn.server.resourcemanager.scheduler.capacity.CapacityScheduler: Application Submission: appattempt_1376154442901_0006_000001, user: ubuntu queue: default: capacity=1.0, absoluteCapacity=1.0, usedResources=<memory:0, vCores:0>usedCapacity=0.0, absoluteUsedCapacity=0.0, numApps=1, numContainers=0, currently active: 1
2013-08-10 17:23:58,348 INFO org.apache.hadoop.yarn.server.resourcemanager.rmapp.attempt.RMAppAttemptImpl: appattempt_1376154442901_0006_000001 State change from SUBMITTED to SCHEDULED
2013-08-10 17:23:58,348 INFO org.apache.hadoop.yarn.server.resourcemanager.rmapp.RMAppImpl: application_1376154442901_0006 State change from SUBMITTED to ACCEPTED
2013-08-10 17:23:58,532 INFO org.apache.hadoop.yarn.server.resourcemanager.ClientRMService: Storing Application with id application_1376154442901_0007
2013-08-10 17:23:58,532 INFO org.apache.hadoop.yarn.server.resourcemanager.recovery.RMStateStore: Storing info for app: application_1376154442901_0007
2013-08-10 17:23:58,532 INFO org.apache.hadoop.yarn.server.resourcemanager.ClientRMService: Application with id 7 submitted by user ubuntu
2013-08-10 17:23:58,532 INFO org.apache.hadoop.yarn.server.resourcemanager.RMAuditLogger: USER=ubuntu	IP=192.168.100.9	OPERATION=Submit Application Request	TARGET=ClientRMService	RESULT=SUCCESS	APPID=application_1376154442901_0007
2013-08-10 17:23:58,533 INFO org.apache.hadoop.yarn.server.resourcemanager.rmapp.RMAppImpl: application_1376154442901_0007 State change from NEW to SUBMITTED
2013-08-10 17:23:58,533 INFO org.apache.hadoop.yarn.server.resourcemanager.ApplicationMasterService: Registering appattempt_1376154442901_0007_000001
2013-08-10 17:23:58,533 INFO org.apache.hadoop.yarn.server.resourcemanager.rmapp.attempt.RMAppAttemptImpl: appattempt_1376154442901_0007_000001 State change from NEW to SUBMITTED
2013-08-10 17:23:58,533 INFO org.apache.hadoop.yarn.server.resourcemanager.scheduler.capacity.LeafQueue: Application application_1376154442901_0007 from user: ubuntu activated in queue: default
2013-08-10 17:23:58,533 INFO org.apache.hadoop.yarn.server.resourcemanager.scheduler.capacity.LeafQueue: Application added - appId: application_1376154442901_0007 user: org.apache.hadoop.yarn.server.resourcemanager.scheduler.capacity.LeafQueue$User@7e14d761, leaf-queue: default #user-pending-applications: 0 #user-active-applications: 2 #queue-pending-applications: 0 #queue-active-applications: 2
2013-08-10 17:23:58,533 INFO org.apache.hadoop.yarn.server.resourcemanager.scheduler.capacity.ParentQueue: Application added - appId: application_1376154442901_0007 user: ubuntu leaf-queue of parent: root #applications: 2
2013-08-10 17:23:58,533 INFO org.apache.hadoop.yarn.server.resourcemanager.scheduler.capacity.CapacityScheduler: Application Submission: appattempt_1376154442901_0007_000001, user: ubuntu queue: default: capacity=1.0, absoluteCapacity=1.0, usedResources=<memory:0, vCores:0>usedCapacity=0.0, absoluteUsedCapacity=0.0, numApps=2, numContainers=0, currently active: 2
2013-08-10 17:23:58,534 INFO org.apache.hadoop.yarn.server.resourcemanager.rmapp.attempt.RMAppAttemptImpl: appattempt_1376154442901_0007_000001 State change from SUBMITTED to SCHEDULED
2013-08-10 17:23:58,534 INFO org.apache.hadoop.yarn.server.resourcemanager.rmapp.RMAppImpl: application_1376154442901_0007 State change from SUBMITTED to ACCEPTED
2013-08-10 17:23:58,550 INFO org.apache.hadoop.yarn.server.resourcemanager.ClientRMService: Storing Application with id application_1376154442901_0008
2013-08-10 17:23:58,550 INFO org.apache.hadoop.yarn.server.resourcemanager.recovery.RMStateStore: Storing info for app: application_1376154442901_0008
2013-08-10 17:23:58,550 INFO org.apache.hadoop.yarn.server.resourcemanager.ClientRMService: Application with id 8 submitted by user ubuntu
2013-08-10 17:23:58,550 INFO org.apache.hadoop.yarn.server.resourcemanager.RMAuditLogger: USER=ubuntu	IP=192.168.100.9	OPERATION=Submit Application Request	TARGET=ClientRMService	RESULT=SUCCESS	APPID=application_1376154442901_0008
2013-08-10 17:23:58,551 INFO org.apache.hadoop.yarn.server.resourcemanager.rmapp.RMAppImpl: application_1376154442901_0008 State change from NEW to SUBMITTED
2013-08-10 17:23:58,551 INFO org.apache.hadoop.yarn.server.resourcemanager.ApplicationMasterService: Registering appattempt_1376154442901_0008_000001
2013-08-10 17:23:58,551 INFO org.apache.hadoop.yarn.server.resourcemanager.rmapp.attempt.RMAppAttemptImpl: appattempt_1376154442901_0008_000001 State change from NEW to SUBMITTED
2013-08-10 17:23:58,551 INFO org.apache.hadoop.yarn.server.resourcemanager.scheduler.capacity.LeafQueue: Application application_1376154442901_0008 from user: ubuntu activated in queue: default
2013-08-10 17:23:58,551 INFO org.apache.hadoop.yarn.server.resourcemanager.scheduler.capacity.LeafQueue: Application added - appId: application_1376154442901_0008 user: org.apache.hadoop.yarn.server.resourcemanager.scheduler.capacity.LeafQueue$User@7e14d761, leaf-queue: default #user-pending-applications: 0 #user-active-applications: 3 #queue-pending-applications: 0 #queue-active-applications: 3
2013-08-10 17:23:58,551 INFO org.apache.hadoop.yarn.server.resourcemanager.scheduler.capacity.ParentQueue: Application added - appId: application_1376154442901_0008 user: ubuntu leaf-queue of parent: root #applications: 3
2013-08-10 17:23:58,552 INFO org.apache.hadoop.yarn.server.resourcemanager.scheduler.capacity.CapacityScheduler: Application Submission: appattempt_1376154442901_0008_000001, user: ubuntu queue: default: capacity=1.0, absoluteCapacity=1.0, usedResources=<memory:0, vCores:0>usedCapacity=0.0, absoluteUsedCapacity=0.0, numApps=3, numContainers=0, currently active: 3
2013-08-10 17:23:58,552 INFO org.apache.hadoop.yarn.server.resourcemanager.rmapp.attempt.RMAppAttemptImpl: appattempt_1376154442901_0008_000001 State change from SUBMITTED to SCHEDULED
2013-08-10 17:23:58,552 INFO org.apache.hadoop.yarn.server.resourcemanager.rmapp.RMAppImpl: application_1376154442901_0008 State change from SUBMITTED to ACCEPTED
2013-08-10 17:23:58,811 INFO org.apache.hadoop.yarn.server.resourcemanager.rmcontainer.RMContainerImpl: container_1376154442901_0006_01_000001 Container Transitioned from NEW to ALLOCATED
2013-08-10 17:23:58,811 INFO org.apache.hadoop.yarn.server.resourcemanager.RMAuditLogger: USER=ubuntu	OPERATION=AM Allocated Container	TARGET=SchedulerApp	RESULT=SUCCESS	APPID=application_1376154442901_0006	CONTAINERID=container_1376154442901_0006_01_000001
2013-08-10 17:23:58,811 INFO org.apache.hadoop.yarn.server.resourcemanager.scheduler.common.fica.FiCaSchedulerNode: Assigned container container_1376154442901_0006_01_000001 of capacity <memory:2048, vCores:1> on host hadoop-220-7:42517, which currently has 1 containers, <memory:2048, vCores:1> used and <memory:6144, vCores:15> available
2013-08-10 17:23:58,812 INFO org.apache.hadoop.yarn.server.resourcemanager.scheduler.capacity.LeafQueue: assignedContainer application=application_1376154442901_0006 container=Container: [ContainerId: container_1376154442901_0006_01_000001, NodeId: hadoop-220-7:42517, NodeHttpAddress: hadoop-220-7:8042, Resource: <memory:2048, vCores:1>, Priority: 0, State: NEW, Token: null, Status: container_id {, app_attempt_id {, application_id {, id: 6, cluster_timestamp: 1376154442901, }, attemptId: 1, }, id: 1, }, state: C_NEW, ] containerId=container_1376154442901_0006_01_000001 queue=default: capacity=1.0, absoluteCapacity=1.0, usedResources=<memory:0, vCores:0>usedCapacity=0.0, absoluteUsedCapacity=0.0, numApps=3, numContainers=0 usedCapacity=0.0 absoluteUsedCapacity=0.0 used=<memory:0, vCores:0> cluster=<memory:49152, vCores:96>
2013-08-10 17:23:58,812 INFO org.apache.hadoop.yarn.server.resourcemanager.scheduler.capacity.ParentQueue: Re-sorting queues since queue: root.default stats: default: capacity=1.0, absoluteCapacity=1.0, usedResources=<memory:2048, vCores:1>usedCapacity=0.041666668, absoluteUsedCapacity=0.041666668, numApps=3, numContainers=1
2013-08-10 17:23:58,812 INFO org.apache.hadoop.yarn.server.resourcemanager.scheduler.capacity.ParentQueue: assignedContainer queue=root usedCapacity=0.041666668 absoluteUsedCapacity=0.041666668 used=<memory:2048, vCores:1> cluster=<memory:49152, vCores:96>
2013-08-10 17:23:58,812 INFO org.apache.hadoop.yarn.server.resourcemanager.rmcontainer.RMContainerImpl: container_1376154442901_0006_01_000001 Container Transitioned from ALLOCATED to ACQUIRED
2013-08-10 17:23:58,813 INFO org.apache.hadoop.yarn.server.resourcemanager.rmapp.attempt.RMAppAttemptImpl: Storing attempt: AppId: application_1376154442901_0006 AttemptId: appattempt_1376154442901_0006_000001 MasterContainer: Container: [ContainerId: container_1376154442901_0006_01_000001, NodeId: hadoop-220-7:42517, NodeHttpAddress: hadoop-220-7:8042, Resource: <memory:2048, vCores:1>, Priority: 0, State: NEW, Token: null, Status: container_id {, app_attempt_id {, application_id {, id: 6, cluster_timestamp: 1376154442901, }, attemptId: 1, }, id: 1, }, state: C_NEW, ]
2013-08-10 17:23:58,813 INFO org.apache.hadoop.yarn.server.resourcemanager.recovery.RMStateStore: Storing info for attempt: appattempt_1376154442901_0006_000001
2013-08-10 17:23:58,813 INFO org.apache.hadoop.yarn.server.resourcemanager.rmapp.attempt.RMAppAttemptImpl: appattempt_1376154442901_0006_000001 State change from SCHEDULED to ALLOCATED_SAVING
2013-08-10 17:23:58,814 INFO org.apache.hadoop.yarn.server.resourcemanager.rmapp.attempt.RMAppAttemptImpl: appattempt_1376154442901_0006_000001 State change from ALLOCATED_SAVING to ALLOCATED
2013-08-10 17:23:58,814 INFO org.apache.hadoop.yarn.server.resourcemanager.amlauncher.AMLauncher: Launching masterappattempt_1376154442901_0006_000001
2013-08-10 17:23:58,815 INFO org.apache.hadoop.yarn.server.resourcemanager.amlauncher.AMLauncher: Setting up container Container: [ContainerId: container_1376154442901_0006_01_000001, NodeId: hadoop-220-7:42517, NodeHttpAddress: hadoop-220-7:8042, Resource: <memory:2048, vCores:1>, Priority: 0, State: NEW, Token: null, Status: container_id {, app_attempt_id {, application_id {, id: 6, cluster_timestamp: 1376154442901, }, attemptId: 1, }, id: 1, }, state: C_NEW, ] for AM appattempt_1376154442901_0006_000001
2013-08-10 17:23:58,815 INFO org.apache.hadoop.yarn.server.resourcemanager.amlauncher.AMLauncher: Command to launch container container_1376154442901_0006_01_000001 : $JAVA_HOME/bin/java -Dlog4j.configuration=container-log4j.properties -Dyarn.app.mapreduce.container.log.dir=<LOG_DIR> -Dyarn.app.mapreduce.container.log.filesize=0 -Dhadoop.root.logger=INFO,CLA  -Xmx1024m org.apache.hadoop.mapreduce.v2.app.MRAppMaster 1><LOG_DIR>/stdout 2><LOG_DIR>/stderr 
2013-08-10 17:23:58,818 INFO org.apache.hadoop.yarn.server.resourcemanager.rmcontainer.RMContainerImpl: container_1376154442901_0007_01_000001 Container Transitioned from NEW to ALLOCATED
2013-08-10 17:23:58,818 INFO org.apache.hadoop.yarn.server.resourcemanager.RMAuditLogger: USER=ubuntu	OPERATION=AM Allocated Container	TARGET=SchedulerApp	RESULT=SUCCESS	APPID=application_1376154442901_0007	CONTAINERID=container_1376154442901_0007_01_000001
2013-08-10 17:23:58,818 INFO org.apache.hadoop.yarn.server.resourcemanager.scheduler.common.fica.FiCaSchedulerNode: Assigned container container_1376154442901_0007_01_000001 of capacity <memory:2048, vCores:1> on host hadoop-220-4:35716, which currently has 1 containers, <memory:2048, vCores:1> used and <memory:6144, vCores:15> available
2013-08-10 17:23:58,819 INFO org.apache.hadoop.yarn.server.resourcemanager.scheduler.capacity.LeafQueue: assignedContainer application=application_1376154442901_0007 container=Container: [ContainerId: container_1376154442901_0007_01_000001, NodeId: hadoop-220-4:35716, NodeHttpAddress: hadoop-220-4:8042, Resource: <memory:2048, vCores:1>, Priority: 0, State: NEW, Token: null, Status: container_id {, app_attempt_id {, application_id {, id: 7, cluster_timestamp: 1376154442901, }, attemptId: 1, }, id: 1, }, state: C_NEW, ] containerId=container_1376154442901_0007_01_000001 queue=default: capacity=1.0, absoluteCapacity=1.0, usedResources=<memory:2048, vCores:1>usedCapacity=0.041666668, absoluteUsedCapacity=0.041666668, numApps=3, numContainers=1 usedCapacity=0.041666668 absoluteUsedCapacity=0.041666668 used=<memory:2048, vCores:1> cluster=<memory:49152, vCores:96>
2013-08-10 17:23:58,819 INFO org.apache.hadoop.yarn.server.resourcemanager.scheduler.capacity.ParentQueue: Re-sorting queues since queue: root.default stats: default: capacity=1.0, absoluteCapacity=1.0, usedResources=<memory:4096, vCores:2>usedCapacity=0.083333336, absoluteUsedCapacity=0.083333336, numApps=3, numContainers=2
2013-08-10 17:23:58,819 INFO org.apache.hadoop.yarn.server.resourcemanager.scheduler.capacity.ParentQueue: assignedContainer queue=root usedCapacity=0.083333336 absoluteUsedCapacity=0.083333336 used=<memory:4096, vCores:2> cluster=<memory:49152, vCores:96>
2013-08-10 17:23:58,828 INFO org.apache.hadoop.yarn.server.resourcemanager.rmcontainer.RMContainerImpl: container_1376154442901_0007_01_000001 Container Transitioned from ALLOCATED to ACQUIRED
2013-08-10 17:23:58,829 INFO org.apache.hadoop.yarn.server.resourcemanager.rmapp.attempt.RMAppAttemptImpl: Storing attempt: AppId: application_1376154442901_0007 AttemptId: appattempt_1376154442901_0007_000001 MasterContainer: Container: [ContainerId: container_1376154442901_0007_01_000001, NodeId: hadoop-220-4:35716, NodeHttpAddress: hadoop-220-4:8042, Resource: <memory:2048, vCores:1>, Priority: 0, State: NEW, Token: null, Status: container_id {, app_attempt_id {, application_id {, id: 7, cluster_timestamp: 1376154442901, }, attemptId: 1, }, id: 1, }, state: C_NEW, ]
2013-08-10 17:23:58,830 INFO org.apache.hadoop.yarn.server.resourcemanager.recovery.RMStateStore: Storing info for attempt: appattempt_1376154442901_0007_000001
2013-08-10 17:23:58,830 INFO org.apache.hadoop.yarn.server.resourcemanager.rmapp.attempt.RMAppAttemptImpl: appattempt_1376154442901_0007_000001 State change from SCHEDULED to ALLOCATED_SAVING
2013-08-10 17:23:58,832 INFO org.apache.hadoop.yarn.server.resourcemanager.rmapp.attempt.RMAppAttemptImpl: appattempt_1376154442901_0007_000001 State change from ALLOCATED_SAVING to ALLOCATED
2013-08-10 17:23:58,832 INFO org.apache.hadoop.yarn.server.resourcemanager.amlauncher.AMLauncher: Launching masterappattempt_1376154442901_0007_000001
2013-08-10 17:23:58,834 INFO org.apache.hadoop.yarn.server.resourcemanager.amlauncher.AMLauncher: Setting up container Container: [ContainerId: container_1376154442901_0007_01_000001, NodeId: hadoop-220-4:35716, NodeHttpAddress: hadoop-220-4:8042, Resource: <memory:2048, vCores:1>, Priority: 0, State: NEW, Token: null, Status: container_id {, app_attempt_id {, application_id {, id: 7, cluster_timestamp: 1376154442901, }, attemptId: 1, }, id: 1, }, state: C_NEW, ] for AM appattempt_1376154442901_0007_000001
2013-08-10 17:23:58,834 INFO org.apache.hadoop.yarn.server.resourcemanager.amlauncher.AMLauncher: Command to launch container container_1376154442901_0007_01_000001 : $JAVA_HOME/bin/java -Dlog4j.configuration=container-log4j.properties -Dyarn.app.mapreduce.container.log.dir=<LOG_DIR> -Dyarn.app.mapreduce.container.log.filesize=0 -Dhadoop.root.logger=INFO,CLA  -Xmx1024m org.apache.hadoop.mapreduce.v2.app.MRAppMaster 1><LOG_DIR>/stdout 2><LOG_DIR>/stderr 
2013-08-10 17:23:58,841 INFO org.apache.hadoop.yarn.server.resourcemanager.amlauncher.AMLauncher: Done launching container Container: [ContainerId: container_1376154442901_0006_01_000001, NodeId: hadoop-220-7:42517, NodeHttpAddress: hadoop-220-7:8042, Resource: <memory:2048, vCores:1>, Priority: 0, State: NEW, Token: null, Status: container_id {, app_attempt_id {, application_id {, id: 6, cluster_timestamp: 1376154442901, }, attemptId: 1, }, id: 1, }, state: C_NEW, ] for AM appattempt_1376154442901_0006_000001
2013-08-10 17:23:58,842 INFO org.apache.hadoop.yarn.server.resourcemanager.rmapp.attempt.RMAppAttemptImpl: appattempt_1376154442901_0006_000001 State change from ALLOCATED to LAUNCHED
2013-08-10 17:23:58,845 INFO org.apache.hadoop.yarn.server.resourcemanager.amlauncher.AMLauncher: Done launching container Container: [ContainerId: container_1376154442901_0007_01_000001, NodeId: hadoop-220-4:35716, NodeHttpAddress: hadoop-220-4:8042, Resource: <memory:2048, vCores:1>, Priority: 0, State: NEW, Token: null, Status: container_id {, app_attempt_id {, application_id {, id: 7, cluster_timestamp: 1376154442901, }, attemptId: 1, }, id: 1, }, state: C_NEW, ] for AM appattempt_1376154442901_0007_000001
2013-08-10 17:23:58,845 INFO org.apache.hadoop.yarn.server.resourcemanager.rmapp.attempt.RMAppAttemptImpl: appattempt_1376154442901_0007_000001 State change from ALLOCATED to LAUNCHED
2013-08-10 17:23:58,859 INFO org.apache.hadoop.yarn.server.resourcemanager.rmcontainer.RMContainerImpl: container_1376154442901_0008_01_000001 Container Transitioned from NEW to ALLOCATED
2013-08-10 17:23:58,860 INFO org.apache.hadoop.yarn.server.resourcemanager.RMAuditLogger: USER=ubuntu	OPERATION=AM Allocated Container	TARGET=SchedulerApp	RESULT=SUCCESS	APPID=application_1376154442901_0008	CONTAINERID=container_1376154442901_0008_01_000001
2013-08-10 17:23:58,860 INFO org.apache.hadoop.yarn.server.resourcemanager.scheduler.common.fica.FiCaSchedulerNode: Assigned container container_1376154442901_0008_01_000001 of capacity <memory:2048, vCores:1> on host hadoop-220-5:59721, which currently has 1 containers, <memory:2048, vCores:1> used and <memory:6144, vCores:15> available
2013-08-10 17:23:58,861 INFO org.apache.hadoop.yarn.server.resourcemanager.scheduler.capacity.LeafQueue: assignedContainer application=application_1376154442901_0008 container=Container: [ContainerId: container_1376154442901_0008_01_000001, NodeId: hadoop-220-5:59721, NodeHttpAddress: hadoop-220-5:8042, Resource: <memory:2048, vCores:1>, Priority: 0, State: NEW, Token: null, Status: container_id {, app_attempt_id {, application_id {, id: 8, cluster_timestamp: 1376154442901, }, attemptId: 1, }, id: 1, }, state: C_NEW, ] containerId=container_1376154442901_0008_01_000001 queue=default: capacity=1.0, absoluteCapacity=1.0, usedResources=<memory:4096, vCores:2>usedCapacity=0.083333336, absoluteUsedCapacity=0.083333336, numApps=3, numContainers=2 usedCapacity=0.083333336 absoluteUsedCapacity=0.083333336 used=<memory:4096, vCores:2> cluster=<memory:49152, vCores:96>
2013-08-10 17:23:58,861 INFO org.apache.hadoop.yarn.server.resourcemanager.scheduler.capacity.ParentQueue: Re-sorting queues since queue: root.default stats: default: capacity=1.0, absoluteCapacity=1.0, usedResources=<memory:6144, vCores:3>usedCapacity=0.125, absoluteUsedCapacity=0.125, numApps=3, numContainers=3
2013-08-10 17:23:58,861 INFO org.apache.hadoop.yarn.server.resourcemanager.scheduler.capacity.ParentQueue: assignedContainer queue=root usedCapacity=0.125 absoluteUsedCapacity=0.125 used=<memory:6144, vCores:3> cluster=<memory:49152, vCores:96>
2013-08-10 17:23:58,862 INFO org.apache.hadoop.yarn.server.resourcemanager.rmcontainer.RMContainerImpl: container_1376154442901_0008_01_000001 Container Transitioned from ALLOCATED to ACQUIRED
2013-08-10 17:23:58,872 INFO org.apache.hadoop.yarn.server.resourcemanager.rmapp.attempt.RMAppAttemptImpl: Storing attempt: AppId: application_1376154442901_0008 AttemptId: appattempt_1376154442901_0008_000001 MasterContainer: Container: [ContainerId: container_1376154442901_0008_01_000001, NodeId: hadoop-220-5:59721, NodeHttpAddress: hadoop-220-5:8042, Resource: <memory:2048, vCores:1>, Priority: 0, State: NEW, Token: null, Status: container_id {, app_attempt_id {, application_id {, id: 8, cluster_timestamp: 1376154442901, }, attemptId: 1, }, id: 1, }, state: C_NEW, ]
2013-08-10 17:23:58,872 INFO org.apache.hadoop.yarn.server.resourcemanager.rmapp.attempt.RMAppAttemptImpl: appattempt_1376154442901_0008_000001 State change from SCHEDULED to ALLOCATED_SAVING
2013-08-10 17:23:58,873 INFO org.apache.hadoop.yarn.server.resourcemanager.recovery.RMStateStore: Storing info for attempt: appattempt_1376154442901_0008_000001
2013-08-10 17:23:58,873 INFO org.apache.hadoop.yarn.server.resourcemanager.rmapp.attempt.RMAppAttemptImpl: appattempt_1376154442901_0008_000001 State change from ALLOCATED_SAVING to ALLOCATED
2013-08-10 17:23:58,874 INFO org.apache.hadoop.yarn.server.resourcemanager.ClientRMService: Storing Application with id application_1376154442901_0009
2013-08-10 17:23:58,874 INFO org.apache.hadoop.yarn.server.resourcemanager.amlauncher.AMLauncher: Launching masterappattempt_1376154442901_0008_000001
2013-08-10 17:23:58,874 INFO org.apache.hadoop.yarn.server.resourcemanager.rmapp.RMAppImpl: application_1376154442901_0009 State change from NEW to SUBMITTED
2013-08-10 17:23:58,874 INFO org.apache.hadoop.yarn.server.resourcemanager.ApplicationMasterService: Registering appattempt_1376154442901_0009_000001
2013-08-10 17:23:58,874 INFO org.apache.hadoop.yarn.server.resourcemanager.rmapp.attempt.RMAppAttemptImpl: appattempt_1376154442901_0009_000001 State change from NEW to SUBMITTED
2013-08-10 17:23:58,874 INFO org.apache.hadoop.yarn.server.resourcemanager.recovery.RMStateStore: Storing info for app: application_1376154442901_0009
2013-08-10 17:23:58,875 INFO org.apache.hadoop.yarn.server.resourcemanager.ClientRMService: Application with id 9 submitted by user ubuntu
2013-08-10 17:23:58,875 INFO org.apache.hadoop.yarn.server.resourcemanager.RMAuditLogger: USER=ubuntu	IP=192.168.100.9	OPERATION=Submit Application Request	TARGET=ClientRMService	RESULT=SUCCESS	APPID=application_1376154442901_0009
2013-08-10 17:23:58,876 INFO org.apache.hadoop.yarn.server.resourcemanager.scheduler.capacity.LeafQueue: Application application_1376154442901_0009 from user: ubuntu activated in queue: default
2013-08-10 17:23:58,876 INFO org.apache.hadoop.yarn.server.resourcemanager.scheduler.capacity.LeafQueue: Application added - appId: application_1376154442901_0009 user: org.apache.hadoop.yarn.server.resourcemanager.scheduler.capacity.LeafQueue$User@7e14d761, leaf-queue: default #user-pending-applications: 0 #user-active-applications: 4 #queue-pending-applications: 0 #queue-active-applications: 4
2013-08-10 17:23:58,876 INFO org.apache.hadoop.yarn.server.resourcemanager.scheduler.capacity.ParentQueue: Application added - appId: application_1376154442901_0009 user: ubuntu leaf-queue of parent: root #applications: 4
2013-08-10 17:23:58,876 INFO org.apache.hadoop.yarn.server.resourcemanager.amlauncher.AMLauncher: Setting up container Container: [ContainerId: container_1376154442901_0008_01_000001, NodeId: hadoop-220-5:59721, NodeHttpAddress: hadoop-220-5:8042, Resource: <memory:2048, vCores:1>, Priority: 0, State: NEW, Token: null, Status: container_id {, app_attempt_id {, application_id {, id: 8, cluster_timestamp: 1376154442901, }, attemptId: 1, }, id: 1, }, state: C_NEW, ] for AM appattempt_1376154442901_0008_000001
2013-08-10 17:23:58,876 INFO org.apache.hadoop.yarn.server.resourcemanager.amlauncher.AMLauncher: Command to launch container container_1376154442901_0008_01_000001 : $JAVA_HOME/bin/java -Dlog4j.configuration=container-log4j.properties -Dyarn.app.mapreduce.container.log.dir=<LOG_DIR> -Dyarn.app.mapreduce.container.log.filesize=0 -Dhadoop.root.logger=INFO,CLA  -Xmx1024m org.apache.hadoop.mapreduce.v2.app.MRAppMaster 1><LOG_DIR>/stdout 2><LOG_DIR>/stderr 
2013-08-10 17:23:58,885 INFO org.apache.hadoop.yarn.server.resourcemanager.scheduler.capacity.CapacityScheduler: Application Submission: appattempt_1376154442901_0009_000001, user: ubuntu queue: default: capacity=1.0, absoluteCapacity=1.0, usedResources=<memory:6144, vCores:3>usedCapacity=0.125, absoluteUsedCapacity=0.125, numApps=4, numContainers=3, currently active: 4
2013-08-10 17:23:58,885 INFO org.apache.hadoop.yarn.server.resourcemanager.rmapp.attempt.RMAppAttemptImpl: appattempt_1376154442901_0009_000001 State change from SUBMITTED to SCHEDULED
2013-08-10 17:23:58,887 INFO org.apache.hadoop.yarn.server.resourcemanager.rmapp.RMAppImpl: application_1376154442901_0009 State change from SUBMITTED to ACCEPTED
2013-08-10 17:23:58,899 INFO org.apache.hadoop.yarn.server.resourcemanager.amlauncher.AMLauncher: Done launching container Container: [ContainerId: container_1376154442901_0008_01_000001, NodeId: hadoop-220-5:59721, NodeHttpAddress: hadoop-220-5:8042, Resource: <memory:2048, vCores:1>, Priority: 0, State: NEW, Token: null, Status: container_id {, app_attempt_id {, application_id {, id: 8, cluster_timestamp: 1376154442901, }, attemptId: 1, }, id: 1, }, state: C_NEW, ] for AM appattempt_1376154442901_0008_000001
2013-08-10 17:23:58,900 INFO org.apache.hadoop.yarn.server.resourcemanager.rmapp.attempt.RMAppAttemptImpl: appattempt_1376154442901_0008_000001 State change from ALLOCATED to LAUNCHED
2013-08-10 17:23:58,997 INFO org.apache.hadoop.yarn.server.resourcemanager.ClientRMService: Storing Application with id application_1376154442901_0010
2013-08-10 17:23:58,998 INFO org.apache.hadoop.yarn.server.resourcemanager.recovery.RMStateStore: Storing info for app: application_1376154442901_0010
2013-08-10 17:23:58,998 INFO org.apache.hadoop.yarn.server.resourcemanager.ClientRMService: Application with id 10 submitted by user ubuntu
2013-08-10 17:23:58,998 INFO org.apache.hadoop.yarn.server.resourcemanager.RMAuditLogger: USER=ubuntu	IP=192.168.100.9	OPERATION=Submit Application Request	TARGET=ClientRMService	RESULT=SUCCESS	APPID=application_1376154442901_0010
2013-08-10 17:23:58,999 INFO org.apache.hadoop.yarn.server.resourcemanager.rmapp.RMAppImpl: application_1376154442901_0010 State change from NEW to SUBMITTED
2013-08-10 17:23:58,999 INFO org.apache.hadoop.yarn.server.resourcemanager.ApplicationMasterService: Registering appattempt_1376154442901_0010_000001
2013-08-10 17:23:58,999 INFO org.apache.hadoop.yarn.server.resourcemanager.rmapp.attempt.RMAppAttemptImpl: appattempt_1376154442901_0010_000001 State change from NEW to SUBMITTED
2013-08-10 17:23:58,999 INFO org.apache.hadoop.yarn.server.resourcemanager.scheduler.capacity.LeafQueue: Application application_1376154442901_0010 from user: ubuntu activated in queue: default
2013-08-10 17:23:58,999 INFO org.apache.hadoop.yarn.server.resourcemanager.scheduler.capacity.LeafQueue: Application added - appId: application_1376154442901_0010 user: org.apache.hadoop.yarn.server.resourcemanager.scheduler.capacity.LeafQueue$User@7e14d761, leaf-queue: default #user-pending-applications: 0 #user-active-applications: 5 #queue-pending-applications: 0 #queue-active-applications: 5
2013-08-10 17:23:58,999 INFO org.apache.hadoop.yarn.server.resourcemanager.scheduler.capacity.ParentQueue: Application added - appId: application_1376154442901_0010 user: ubuntu leaf-queue of parent: root #applications: 5
2013-08-10 17:23:58,999 INFO org.apache.hadoop.yarn.server.resourcemanager.scheduler.capacity.CapacityScheduler: Application Submission: appattempt_1376154442901_0010_000001, user: ubuntu queue: default: capacity=1.0, absoluteCapacity=1.0, usedResources=<memory:6144, vCores:3>usedCapacity=0.125, absoluteUsedCapacity=0.125, numApps=5, numContainers=3, currently active: 5
2013-08-10 17:23:59,000 INFO org.apache.hadoop.yarn.server.resourcemanager.rmapp.attempt.RMAppAttemptImpl: appattempt_1376154442901_0010_000001 State change from SUBMITTED to SCHEDULED
2013-08-10 17:23:59,000 INFO org.apache.hadoop.yarn.server.resourcemanager.rmapp.RMAppImpl: application_1376154442901_0010 State change from SUBMITTED to ACCEPTED
2013-08-10 17:23:59,171 INFO org.apache.hadoop.yarn.server.resourcemanager.rmcontainer.RMContainerImpl: container_1376154442901_0009_01_000001 Container Transitioned from NEW to ALLOCATED
2013-08-10 17:23:59,171 INFO org.apache.hadoop.yarn.server.resourcemanager.RMAuditLogger: USER=ubuntu	OPERATION=AM Allocated Container	TARGET=SchedulerApp	RESULT=SUCCESS	APPID=application_1376154442901_0009	CONTAINERID=container_1376154442901_0009_01_000001
2013-08-10 17:23:59,171 INFO org.apache.hadoop.yarn.server.resourcemanager.scheduler.common.fica.FiCaSchedulerNode: Assigned container container_1376154442901_0009_01_000001 of capacity <memory:2048, vCores:1> on host hadoop-220-3:58548, which currently has 1 containers, <memory:2048, vCores:1> used and <memory:6144, vCores:15> available
2013-08-10 17:23:59,172 INFO org.apache.hadoop.yarn.server.resourcemanager.scheduler.capacity.LeafQueue: assignedContainer application=application_1376154442901_0009 container=Container: [ContainerId: container_1376154442901_0009_01_000001, NodeId: hadoop-220-3:58548, NodeHttpAddress: hadoop-220-3:8042, Resource: <memory:2048, vCores:1>, Priority: 0, State: NEW, Token: null, Status: container_id {, app_attempt_id {, application_id {, id: 9, cluster_timestamp: 1376154442901, }, attemptId: 1, }, id: 1, }, state: C_NEW, ] containerId=container_1376154442901_0009_01_000001 queue=default: capacity=1.0, absoluteCapacity=1.0, usedResources=<memory:6144, vCores:3>usedCapacity=0.125, absoluteUsedCapacity=0.125, numApps=5, numContainers=3 usedCapacity=0.125 absoluteUsedCapacity=0.125 used=<memory:6144, vCores:3> cluster=<memory:49152, vCores:96>
2013-08-10 17:23:59,172 INFO org.apache.hadoop.yarn.server.resourcemanager.scheduler.capacity.ParentQueue: Re-sorting queues since queue: root.default stats: default: capacity=1.0, absoluteCapacity=1.0, usedResources=<memory:8192, vCores:4>usedCapacity=0.16666667, absoluteUsedCapacity=0.16666667, numApps=5, numContainers=4
2013-08-10 17:23:59,172 INFO org.apache.hadoop.yarn.server.resourcemanager.scheduler.capacity.ParentQueue: assignedContainer queue=root usedCapacity=0.16666667 absoluteUsedCapacity=0.16666667 used=<memory:8192, vCores:4> cluster=<memory:49152, vCores:96>
2013-08-10 17:23:59,173 INFO org.apache.hadoop.yarn.server.resourcemanager.rmcontainer.RMContainerImpl: container_1376154442901_0009_01_000001 Container Transitioned from ALLOCATED to ACQUIRED
2013-08-10 17:23:59,174 INFO org.apache.hadoop.yarn.server.resourcemanager.rmapp.attempt.RMAppAttemptImpl: Storing attempt: AppId: application_1376154442901_0009 AttemptId: appattempt_1376154442901_0009_000001 MasterContainer: Container: [ContainerId: container_1376154442901_0009_01_000001, NodeId: hadoop-220-3:58548, NodeHttpAddress: hadoop-220-3:8042, Resource: <memory:2048, vCores:1>, Priority: 0, State: NEW, Token: null, Status: container_id {, app_attempt_id {, application_id {, id: 9, cluster_timestamp: 1376154442901, }, attemptId: 1, }, id: 1, }, state: C_NEW, ]
2013-08-10 17:23:59,174 INFO org.apache.hadoop.yarn.server.resourcemanager.rmapp.attempt.RMAppAttemptImpl: appattempt_1376154442901_0009_000001 State change from SCHEDULED to ALLOCATED_SAVING
2013-08-10 17:23:59,174 INFO org.apache.hadoop.yarn.server.resourcemanager.recovery.RMStateStore: Storing info for attempt: appattempt_1376154442901_0009_000001
2013-08-10 17:23:59,174 INFO org.apache.hadoop.yarn.server.resourcemanager.rmapp.attempt.RMAppAttemptImpl: appattempt_1376154442901_0009_000001 State change from ALLOCATED_SAVING to ALLOCATED
2013-08-10 17:23:59,174 INFO org.apache.hadoop.yarn.server.resourcemanager.amlauncher.AMLauncher: Launching masterappattempt_1376154442901_0009_000001
2013-08-10 17:23:59,176 INFO org.apache.hadoop.yarn.server.resourcemanager.amlauncher.AMLauncher: Setting up container Container: [ContainerId: container_1376154442901_0009_01_000001, NodeId: hadoop-220-3:58548, NodeHttpAddress: hadoop-220-3:8042, Resource: <memory:2048, vCores:1>, Priority: 0, State: NEW, Token: null, Status: container_id {, app_attempt_id {, application_id {, id: 9, cluster_timestamp: 1376154442901, }, attemptId: 1, }, id: 1, }, state: C_NEW, ] for AM appattempt_1376154442901_0009_000001
2013-08-10 17:23:59,176 INFO org.apache.hadoop.yarn.server.resourcemanager.amlauncher.AMLauncher: Command to launch container container_1376154442901_0009_01_000001 : $JAVA_HOME/bin/java -Dlog4j.configuration=container-log4j.properties -Dyarn.app.mapreduce.container.log.dir=<LOG_DIR> -Dyarn.app.mapreduce.container.log.filesize=0 -Dhadoop.root.logger=INFO,CLA  -Xmx1024m org.apache.hadoop.mapreduce.v2.app.MRAppMaster 1><LOG_DIR>/stdout 2><LOG_DIR>/stderr 
2013-08-10 17:23:59,189 INFO org.apache.hadoop.yarn.server.resourcemanager.amlauncher.AMLauncher: Done launching container Container: [ContainerId: container_1376154442901_0009_01_000001, NodeId: hadoop-220-3:58548, NodeHttpAddress: hadoop-220-3:8042, Resource: <memory:2048, vCores:1>, Priority: 0, State: NEW, Token: null, Status: container_id {, app_attempt_id {, application_id {, id: 9, cluster_timestamp: 1376154442901, }, attemptId: 1, }, id: 1, }, state: C_NEW, ] for AM appattempt_1376154442901_0009_000001
2013-08-10 17:23:59,189 INFO org.apache.hadoop.yarn.server.resourcemanager.rmapp.attempt.RMAppAttemptImpl: appattempt_1376154442901_0009_000001 State change from ALLOCATED to LAUNCHED
2013-08-10 17:23:59,304 INFO org.apache.hadoop.yarn.server.resourcemanager.rmcontainer.RMContainerImpl: container_1376154442901_0010_01_000001 Container Transitioned from NEW to ALLOCATED
2013-08-10 17:23:59,306 INFO org.apache.hadoop.yarn.server.resourcemanager.RMAuditLogger: USER=ubuntu	OPERATION=AM Allocated Container	TARGET=SchedulerApp	RESULT=SUCCESS	APPID=application_1376154442901_0010	CONTAINERID=container_1376154442901_0010_01_000001
2013-08-10 17:23:59,306 INFO org.apache.hadoop.yarn.server.resourcemanager.scheduler.common.fica.FiCaSchedulerNode: Assigned container container_1376154442901_0010_01_000001 of capacity <memory:2048, vCores:1> on host hadoop-220-6:56687, which currently has 1 containers, <memory:2048, vCores:1> used and <memory:6144, vCores:15> available
2013-08-10 17:23:59,308 INFO org.apache.hadoop.yarn.server.resourcemanager.scheduler.capacity.LeafQueue: assignedContainer application=application_1376154442901_0010 container=Container: [ContainerId: container_1376154442901_0010_01_000001, NodeId: hadoop-220-6:56687, NodeHttpAddress: hadoop-220-6:8042, Resource: <memory:2048, vCores:1>, Priority: 0, State: NEW, Token: null, Status: container_id {, app_attempt_id {, application_id {, id: 10, cluster_timestamp: 1376154442901, }, attemptId: 1, }, id: 1, }, state: C_NEW, ] containerId=container_1376154442901_0010_01_000001 queue=default: capacity=1.0, absoluteCapacity=1.0, usedResources=<memory:8192, vCores:4>usedCapacity=0.16666667, absoluteUsedCapacity=0.16666667, numApps=5, numContainers=4 usedCapacity=0.16666667 absoluteUsedCapacity=0.16666667 used=<memory:8192, vCores:4> cluster=<memory:49152, vCores:96>
2013-08-10 17:23:59,308 INFO org.apache.hadoop.yarn.server.resourcemanager.scheduler.capacity.ParentQueue: Re-sorting queues since queue: root.default stats: default: capacity=1.0, absoluteCapacity=1.0, usedResources=<memory:10240, vCores:5>usedCapacity=0.20833333, absoluteUsedCapacity=0.20833333, numApps=5, numContainers=5
2013-08-10 17:23:59,309 INFO org.apache.hadoop.yarn.server.resourcemanager.rmcontainer.RMContainerImpl: container_1376154442901_0010_01_000001 Container Transitioned from ALLOCATED to ACQUIRED
2013-08-10 17:23:59,311 INFO org.apache.hadoop.yarn.server.resourcemanager.rmapp.attempt.RMAppAttemptImpl: Storing attempt: AppId: application_1376154442901_0010 AttemptId: appattempt_1376154442901_0010_000001 MasterContainer: Container: [ContainerId: container_1376154442901_0010_01_000001, NodeId: hadoop-220-6:56687, NodeHttpAddress: hadoop-220-6:8042, Resource: <memory:2048, vCores:1>, Priority: 0, State: NEW, Token: null, Status: container_id {, app_attempt_id {, application_id {, id: 10, cluster_timestamp: 1376154442901, }, attemptId: 1, }, id: 1, }, state: C_NEW, ]
2013-08-10 17:23:59,311 INFO org.apache.hadoop.yarn.server.resourcemanager.recovery.RMStateStore: Storing info for attempt: appattempt_1376154442901_0010_000001
2013-08-10 17:23:59,311 INFO org.apache.hadoop.yarn.server.resourcemanager.rmapp.attempt.RMAppAttemptImpl: appattempt_1376154442901_0010_000001 State change from SCHEDULED to ALLOCATED_SAVING
2013-08-10 17:23:59,312 INFO org.apache.hadoop.yarn.server.resourcemanager.rmapp.attempt.RMAppAttemptImpl: appattempt_1376154442901_0010_000001 State change from ALLOCATED_SAVING to ALLOCATED
2013-08-10 17:23:59,312 INFO org.apache.hadoop.yarn.server.resourcemanager.scheduler.capacity.ParentQueue: assignedContainer queue=root usedCapacity=0.20833333 absoluteUsedCapacity=0.20833333 used=<memory:10240, vCores:5> cluster=<memory:49152, vCores:96>
2013-08-10 17:23:59,313 INFO org.apache.hadoop.yarn.server.resourcemanager.amlauncher.AMLauncher: Launching masterappattempt_1376154442901_0010_000001
2013-08-10 17:23:59,315 INFO org.apache.hadoop.yarn.server.resourcemanager.amlauncher.AMLauncher: Setting up container Container: [ContainerId: container_1376154442901_0010_01_000001, NodeId: hadoop-220-6:56687, NodeHttpAddress: hadoop-220-6:8042, Resource: <memory:2048, vCores:1>, Priority: 0, State: NEW, Token: null, Status: container_id {, app_attempt_id {, application_id {, id: 10, cluster_timestamp: 1376154442901, }, attemptId: 1, }, id: 1, }, state: C_NEW, ] for AM appattempt_1376154442901_0010_000001
2013-08-10 17:23:59,315 INFO org.apache.hadoop.yarn.server.resourcemanager.amlauncher.AMLauncher: Command to launch container container_1376154442901_0010_01_000001 : $JAVA_HOME/bin/java -Dlog4j.configuration=container-log4j.properties -Dyarn.app.mapreduce.container.log.dir=<LOG_DIR> -Dyarn.app.mapreduce.container.log.filesize=0 -Dhadoop.root.logger=INFO,CLA  -Xmx1024m org.apache.hadoop.mapreduce.v2.app.MRAppMaster 1><LOG_DIR>/stdout 2><LOG_DIR>/stderr 
2013-08-10 17:23:59,334 INFO org.apache.hadoop.yarn.server.resourcemanager.amlauncher.AMLauncher: Done launching container Container: [ContainerId: container_1376154442901_0010_01_000001, NodeId: hadoop-220-6:56687, NodeHttpAddress: hadoop-220-6:8042, Resource: <memory:2048, vCores:1>, Priority: 0, State: NEW, Token: null, Status: container_id {, app_attempt_id {, application_id {, id: 10, cluster_timestamp: 1376154442901, }, attemptId: 1, }, id: 1, }, state: C_NEW, ] for AM appattempt_1376154442901_0010_000001
2013-08-10 17:23:59,334 INFO org.apache.hadoop.yarn.server.resourcemanager.rmapp.attempt.RMAppAttemptImpl: appattempt_1376154442901_0010_000001 State change from ALLOCATED to LAUNCHED
2013-08-10 17:23:59,816 INFO org.apache.hadoop.yarn.server.resourcemanager.rmcontainer.RMContainerImpl: container_1376154442901_0006_01_000001 Container Transitioned from ACQUIRED to RUNNING
2013-08-10 17:23:59,824 INFO org.apache.hadoop.yarn.server.resourcemanager.rmcontainer.RMContainerImpl: container_1376154442901_0007_01_000001 Container Transitioned from ACQUIRED to RUNNING
2013-08-10 17:23:59,865 INFO org.apache.hadoop.yarn.server.resourcemanager.rmcontainer.RMContainerImpl: container_1376154442901_0008_01_000001 Container Transitioned from ACQUIRED to RUNNING
2013-08-10 17:24:00,180 INFO org.apache.hadoop.yarn.server.resourcemanager.rmcontainer.RMContainerImpl: container_1376154442901_0009_01_000001 Container Transitioned from ACQUIRED to RUNNING
2013-08-10 17:24:00,310 INFO org.apache.hadoop.yarn.server.resourcemanager.rmcontainer.RMContainerImpl: container_1376154442901_0010_01_000001 Container Transitioned from ACQUIRED to RUNNING
2013-08-10 17:24:03,949 INFO org.apache.hadoop.yarn.server.resourcemanager.ApplicationMasterService: AM registration appattempt_1376154442901_0010_000001
2013-08-10 17:24:03,950 INFO org.apache.hadoop.yarn.server.resourcemanager.RMAuditLogger: USER=ubuntu	IP=192.168.100.34	OPERATION=Register App Master	TARGET=ApplicationMasterService	RESULT=SUCCESS	APPID=application_1376154442901_0010	APPATTEMPTID=appattempt_1376154442901_0010_000001
2013-08-10 17:24:03,951 INFO org.apache.hadoop.yarn.server.resourcemanager.rmapp.attempt.RMAppAttemptImpl: appattempt_1376154442901_0010_000001 State change from LAUNCHED to RUNNING
2013-08-10 17:24:03,951 INFO org.apache.hadoop.yarn.server.resourcemanager.rmapp.RMAppImpl: application_1376154442901_0010 State change from ACCEPTED to RUNNING
2013-08-10 17:24:05,207 INFO org.apache.hadoop.yarn.server.resourcemanager.rmcontainer.RMContainerImpl: container_1376154442901_0010_01_000002 Container Transitioned from NEW to ALLOCATED
2013-08-10 17:24:05,207 INFO org.apache.hadoop.yarn.server.resourcemanager.RMAuditLogger: USER=ubuntu	OPERATION=AM Allocated Container	TARGET=SchedulerApp	RESULT=SUCCESS	APPID=application_1376154442901_0010	CONTAINERID=container_1376154442901_0010_01_000002
2013-08-10 17:24:05,208 INFO org.apache.hadoop.yarn.server.resourcemanager.scheduler.common.fica.FiCaSchedulerNode: Assigned container container_1376154442901_0010_01_000002 of capacity <memory:1024, vCores:1> on host hadoop-220-3:58548, which currently has 2 containers, <memory:3072, vCores:2> used and <memory:5120, vCores:14> available
2013-08-10 17:24:05,209 INFO org.apache.hadoop.yarn.server.resourcemanager.scheduler.capacity.LeafQueue: assignedContainer application=application_1376154442901_0010 container=Container: [ContainerId: container_1376154442901_0010_01_000002, NodeId: hadoop-220-3:58548, NodeHttpAddress: hadoop-220-3:8042, Resource: <memory:1024, vCores:1>, Priority: 20, State: NEW, Token: null, Status: container_id {, app_attempt_id {, application_id {, id: 10, cluster_timestamp: 1376154442901, }, attemptId: 1, }, id: 2, }, state: C_NEW, ] containerId=container_1376154442901_0010_01_000002 queue=default: capacity=1.0, absoluteCapacity=1.0, usedResources=<memory:10240, vCores:5>usedCapacity=0.20833333, absoluteUsedCapacity=0.20833333, numApps=5, numContainers=5 usedCapacity=0.20833333 absoluteUsedCapacity=0.20833333 used=<memory:10240, vCores:5> cluster=<memory:49152, vCores:96>
2013-08-10 17:24:05,209 INFO org.apache.hadoop.yarn.server.resourcemanager.scheduler.capacity.ParentQueue: Re-sorting queues since queue: root.default stats: default: capacity=1.0, absoluteCapacity=1.0, usedResources=<memory:11264, vCores:6>usedCapacity=0.22916667, absoluteUsedCapacity=0.22916667, numApps=5, numContainers=6
2013-08-10 17:24:05,209 INFO org.apache.hadoop.yarn.server.resourcemanager.scheduler.capacity.ParentQueue: assignedContainer queue=root usedCapacity=0.22916667 absoluteUsedCapacity=0.22916667 used=<memory:11264, vCores:6> cluster=<memory:49152, vCores:96>
2013-08-10 17:24:05,210 INFO org.apache.hadoop.yarn.server.resourcemanager.rmcontainer.RMContainerImpl: container_1376154442901_0010_01_000003 Container Transitioned from NEW to ALLOCATED
2013-08-10 17:24:05,210 INFO org.apache.hadoop.yarn.server.resourcemanager.RMAuditLogger: USER=ubuntu	OPERATION=AM Allocated Container	TARGET=SchedulerApp	RESULT=SUCCESS	APPID=application_1376154442901_0010	CONTAINERID=container_1376154442901_0010_01_000003
2013-08-10 17:24:05,210 INFO org.apache.hadoop.yarn.server.resourcemanager.scheduler.common.fica.FiCaSchedulerNode: Assigned container container_1376154442901_0010_01_000003 of capacity <memory:1024, vCores:1> on host hadoop-220-3:58548, which currently has 3 containers, <memory:4096, vCores:3> used and <memory:4096, vCores:13> available
2013-08-10 17:24:05,211 INFO org.apache.hadoop.yarn.server.resourcemanager.scheduler.capacity.LeafQueue: assignedContainer application=application_1376154442901_0010 container=Container: [ContainerId: container_1376154442901_0010_01_000003, NodeId: hadoop-220-3:58548, NodeHttpAddress: hadoop-220-3:8042, Resource: <memory:1024, vCores:1>, Priority: 20, State: NEW, Token: null, Status: container_id {, app_attempt_id {, application_id {, id: 10, cluster_timestamp: 1376154442901, }, attemptId: 1, }, id: 3, }, state: C_NEW, ] containerId=container_1376154442901_0010_01_000003 queue=default: capacity=1.0, absoluteCapacity=1.0, usedResources=<memory:11264, vCores:6>usedCapacity=0.22916667, absoluteUsedCapacity=0.22916667, numApps=5, numContainers=6 usedCapacity=0.22916667 absoluteUsedCapacity=0.22916667 used=<memory:11264, vCores:6> cluster=<memory:49152, vCores:96>
2013-08-10 17:24:05,211 INFO org.apache.hadoop.yarn.server.resourcemanager.scheduler.capacity.ParentQueue: Re-sorting queues since queue: root.default stats: default: capacity=1.0, absoluteCapacity=1.0, usedResources=<memory:12288, vCores:7>usedCapacity=0.25, absoluteUsedCapacity=0.25, numApps=5, numContainers=7
2013-08-10 17:24:05,212 INFO org.apache.hadoop.yarn.server.resourcemanager.scheduler.capacity.ParentQueue: assignedContainer queue=root usedCapacity=0.25 absoluteUsedCapacity=0.25 used=<memory:12288, vCores:7> cluster=<memory:49152, vCores:96>
2013-08-10 17:24:05,212 INFO org.apache.hadoop.yarn.server.resourcemanager.rmcontainer.RMContainerImpl: container_1376154442901_0010_01_000004 Container Transitioned from NEW to ALLOCATED
2013-08-10 17:24:05,212 INFO org.apache.hadoop.yarn.server.resourcemanager.RMAuditLogger: USER=ubuntu	OPERATION=AM Allocated Container	TARGET=SchedulerApp	RESULT=SUCCESS	APPID=application_1376154442901_0010	CONTAINERID=container_1376154442901_0010_01_000004
2013-08-10 17:24:05,212 INFO org.apache.hadoop.yarn.server.resourcemanager.scheduler.common.fica.FiCaSchedulerNode: Assigned container container_1376154442901_0010_01_000004 of capacity <memory:1024, vCores:1> on host hadoop-220-3:58548, which currently has 4 containers, <memory:5120, vCores:4> used and <memory:3072, vCores:12> available
2013-08-10 17:24:05,213 INFO org.apache.hadoop.yarn.server.resourcemanager.scheduler.capacity.LeafQueue: assignedContainer application=application_1376154442901_0010 container=Container: [ContainerId: container_1376154442901_0010_01_000004, NodeId: hadoop-220-3:58548, NodeHttpAddress: hadoop-220-3:8042, Resource: <memory:1024, vCores:1>, Priority: 20, State: NEW, Token: null, Status: container_id {, app_attempt_id {, application_id {, id: 10, cluster_timestamp: 1376154442901, }, attemptId: 1, }, id: 4, }, state: C_NEW, ] containerId=container_1376154442901_0010_01_000004 queue=default: capacity=1.0, absoluteCapacity=1.0, usedResources=<memory:12288, vCores:7>usedCapacity=0.25, absoluteUsedCapacity=0.25, numApps=5, numContainers=7 usedCapacity=0.25 absoluteUsedCapacity=0.25 used=<memory:12288, vCores:7> cluster=<memory:49152, vCores:96>
2013-08-10 17:24:05,213 INFO org.apache.hadoop.yarn.server.resourcemanager.scheduler.capacity.ParentQueue: Re-sorting queues since queue: root.default stats: default: capacity=1.0, absoluteCapacity=1.0, usedResources=<memory:13312, vCores:8>usedCapacity=0.27083334, absoluteUsedCapacity=0.27083334, numApps=5, numContainers=8
2013-08-10 17:24:05,214 INFO org.apache.hadoop.yarn.server.resourcemanager.scheduler.capacity.ParentQueue: assignedContainer queue=root usedCapacity=0.27083334 absoluteUsedCapacity=0.27083334 used=<memory:13312, vCores:8> cluster=<memory:49152, vCores:96>
2013-08-10 17:24:05,214 INFO org.apache.hadoop.yarn.server.resourcemanager.rmcontainer.RMContainerImpl: container_1376154442901_0010_01_000005 Container Transitioned from NEW to ALLOCATED
2013-08-10 17:24:05,214 INFO org.apache.hadoop.yarn.server.resourcemanager.RMAuditLogger: USER=ubuntu	OPERATION=AM Allocated Container	TARGET=SchedulerApp	RESULT=SUCCESS	APPID=application_1376154442901_0010	CONTAINERID=container_1376154442901_0010_01_000005
2013-08-10 17:24:05,214 INFO org.apache.hadoop.yarn.server.resourcemanager.scheduler.common.fica.FiCaSchedulerNode: Assigned container container_1376154442901_0010_01_000005 of capacity <memory:1024, vCores:1> on host hadoop-220-3:58548, which currently has 5 containers, <memory:6144, vCores:5> used and <memory:2048, vCores:11> available
2013-08-10 17:24:05,215 INFO org.apache.hadoop.yarn.server.resourcemanager.scheduler.capacity.LeafQueue: assignedContainer application=application_1376154442901_0010 container=Container: [ContainerId: container_1376154442901_0010_01_000005, NodeId: hadoop-220-3:58548, NodeHttpAddress: hadoop-220-3:8042, Resource: <memory:1024, vCores:1>, Priority: 20, State: NEW, Token: null, Status: container_id {, app_attempt_id {, application_id {, id: 10, cluster_timestamp: 1376154442901, }, attemptId: 1, }, id: 5, }, state: C_NEW, ] containerId=container_1376154442901_0010_01_000005 queue=default: capacity=1.0, absoluteCapacity=1.0, usedResources=<memory:13312, vCores:8>usedCapacity=0.27083334, absoluteUsedCapacity=0.27083334, numApps=5, numContainers=8 usedCapacity=0.27083334 absoluteUsedCapacity=0.27083334 used=<memory:13312, vCores:8> cluster=<memory:49152, vCores:96>
2013-08-10 17:24:05,216 INFO org.apache.hadoop.yarn.server.resourcemanager.scheduler.capacity.ParentQueue: Re-sorting queues since queue: root.default stats: default: capacity=1.0, absoluteCapacity=1.0, usedResources=<memory:14336, vCores:9>usedCapacity=0.29166666, absoluteUsedCapacity=0.29166666, numApps=5, numContainers=9
2013-08-10 17:24:05,216 INFO org.apache.hadoop.yarn.server.resourcemanager.scheduler.capacity.ParentQueue: assignedContainer queue=root usedCapacity=0.29166666 absoluteUsedCapacity=0.29166666 used=<memory:14336, vCores:9> cluster=<memory:49152, vCores:96>
2013-08-10 17:24:05,216 INFO org.apache.hadoop.yarn.server.resourcemanager.rmcontainer.RMContainerImpl: container_1376154442901_0010_01_000006 Container Transitioned from NEW to ALLOCATED
2013-08-10 17:24:05,216 INFO org.apache.hadoop.yarn.server.resourcemanager.RMAuditLogger: USER=ubuntu	OPERATION=AM Allocated Container	TARGET=SchedulerApp	RESULT=SUCCESS	APPID=application_1376154442901_0010	CONTAINERID=container_1376154442901_0010_01_000006
2013-08-10 17:24:05,217 INFO org.apache.hadoop.yarn.server.resourcemanager.scheduler.common.fica.FiCaSchedulerNode: Assigned container container_1376154442901_0010_01_000006 of capacity <memory:1024, vCores:1> on host hadoop-220-3:58548, which currently has 6 containers, <memory:7168, vCores:6> used and <memory:1024, vCores:10> available
2013-08-10 17:24:05,218 INFO org.apache.hadoop.yarn.server.resourcemanager.scheduler.capacity.LeafQueue: assignedContainer application=application_1376154442901_0010 container=Container: [ContainerId: container_1376154442901_0010_01_000006, NodeId: hadoop-220-3:58548, NodeHttpAddress: hadoop-220-3:8042, Resource: <memory:1024, vCores:1>, Priority: 20, State: NEW, Token: null, Status: container_id {, app_attempt_id {, application_id {, id: 10, cluster_timestamp: 1376154442901, }, attemptId: 1, }, id: 6, }, state: C_NEW, ] containerId=container_1376154442901_0010_01_000006 queue=default: capacity=1.0, absoluteCapacity=1.0, usedResources=<memory:14336, vCores:9>usedCapacity=0.29166666, absoluteUsedCapacity=0.29166666, numApps=5, numContainers=9 usedCapacity=0.29166666 absoluteUsedCapacity=0.29166666 used=<memory:14336, vCores:9> cluster=<memory:49152, vCores:96>
2013-08-10 17:24:05,218 INFO org.apache.hadoop.yarn.server.resourcemanager.scheduler.capacity.ParentQueue: Re-sorting queues since queue: root.default stats: default: capacity=1.0, absoluteCapacity=1.0, usedResources=<memory:15360, vCores:10>usedCapacity=0.3125, absoluteUsedCapacity=0.3125, numApps=5, numContainers=10
2013-08-10 17:24:05,218 INFO org.apache.hadoop.yarn.server.resourcemanager.scheduler.capacity.ParentQueue: assignedContainer queue=root usedCapacity=0.3125 absoluteUsedCapacity=0.3125 used=<memory:15360, vCores:10> cluster=<memory:49152, vCores:96>
2013-08-10 17:24:05,219 INFO org.apache.hadoop.yarn.server.resourcemanager.rmcontainer.RMContainerImpl: container_1376154442901_0010_01_000007 Container Transitioned from NEW to ALLOCATED
2013-08-10 17:24:05,219 INFO org.apache.hadoop.yarn.server.resourcemanager.RMAuditLogger: USER=ubuntu	OPERATION=AM Allocated Container	TARGET=SchedulerApp	RESULT=SUCCESS	APPID=application_1376154442901_0010	CONTAINERID=container_1376154442901_0010_01_000007
2013-08-10 17:24:05,219 INFO org.apache.hadoop.yarn.server.resourcemanager.scheduler.common.fica.FiCaSchedulerNode: Assigned container container_1376154442901_0010_01_000007 of capacity <memory:1024, vCores:1> on host hadoop-220-3:58548, which currently has 7 containers, <memory:8192, vCores:7> used and <memory:0, vCores:9> available
2013-08-10 17:24:05,220 INFO org.apache.hadoop.yarn.server.resourcemanager.scheduler.capacity.LeafQueue: assignedContainer application=application_1376154442901_0010 container=Container: [ContainerId: container_1376154442901_0010_01_000007, NodeId: hadoop-220-3:58548, NodeHttpAddress: hadoop-220-3:8042, Resource: <memory:1024, vCores:1>, Priority: 20, State: NEW, Token: null, Status: container_id {, app_attempt_id {, application_id {, id: 10, cluster_timestamp: 1376154442901, }, attemptId: 1, }, id: 7, }, state: C_NEW, ] containerId=container_1376154442901_0010_01_000007 queue=default: capacity=1.0, absoluteCapacity=1.0, usedResources=<memory:15360, vCores:10>usedCapacity=0.3125, absoluteUsedCapacity=0.3125, numApps=5, numContainers=10 usedCapacity=0.3125 absoluteUsedCapacity=0.3125 used=<memory:15360, vCores:10> cluster=<memory:49152, vCores:96>
2013-08-10 17:24:05,220 INFO org.apache.hadoop.yarn.server.resourcemanager.scheduler.capacity.ParentQueue: Re-sorting queues since queue: root.default stats: default: capacity=1.0, absoluteCapacity=1.0, usedResources=<memory:16384, vCores:11>usedCapacity=0.33333334, absoluteUsedCapacity=0.33333334, numApps=5, numContainers=11
2013-08-10 17:24:05,220 INFO org.apache.hadoop.yarn.server.resourcemanager.scheduler.capacity.ParentQueue: assignedContainer queue=root usedCapacity=0.33333334 absoluteUsedCapacity=0.33333334 used=<memory:16384, vCores:11> cluster=<memory:49152, vCores:96>
2013-08-10 17:24:05,326 INFO org.apache.hadoop.yarn.server.resourcemanager.rmcontainer.RMContainerImpl: container_1376154442901_0010_01_000008 Container Transitioned from NEW to ALLOCATED
2013-08-10 17:24:05,327 INFO org.apache.hadoop.yarn.server.resourcemanager.RMAuditLogger: USER=ubuntu	OPERATION=AM Allocated Container	TARGET=SchedulerApp	RESULT=SUCCESS	APPID=application_1376154442901_0010	CONTAINERID=container_1376154442901_0010_01_000008
2013-08-10 17:24:05,327 INFO org.apache.hadoop.yarn.server.resourcemanager.scheduler.common.fica.FiCaSchedulerNode: Assigned container container_1376154442901_0010_01_000008 of capacity <memory:1024, vCores:1> on host hadoop-220-2:50762, which currently has 1 containers, <memory:1024, vCores:1> used and <memory:7168, vCores:15> available
2013-08-10 17:24:05,328 INFO org.apache.hadoop.yarn.server.resourcemanager.scheduler.capacity.LeafQueue: assignedContainer application=application_1376154442901_0010 container=Container: [ContainerId: container_1376154442901_0010_01_000008, NodeId: hadoop-220-2:50762, NodeHttpAddress: hadoop-220-2:8042, Resource: <memory:1024, vCores:1>, Priority: 20, State: NEW, Token: null, Status: container_id {, app_attempt_id {, application_id {, id: 10, cluster_timestamp: 1376154442901, }, attemptId: 1, }, id: 8, }, state: C_NEW, ] containerId=container_1376154442901_0010_01_000008 queue=default: capacity=1.0, absoluteCapacity=1.0, usedResources=<memory:16384, vCores:11>usedCapacity=0.33333334, absoluteUsedCapacity=0.33333334, numApps=5, numContainers=11 usedCapacity=0.33333334 absoluteUsedCapacity=0.33333334 used=<memory:16384, vCores:11> cluster=<memory:49152, vCores:96>
2013-08-10 17:24:05,328 INFO org.apache.hadoop.yarn.server.resourcemanager.scheduler.capacity.ParentQueue: Re-sorting queues since queue: root.default stats: default: capacity=1.0, absoluteCapacity=1.0, usedResources=<memory:17408, vCores:12>usedCapacity=0.35416666, absoluteUsedCapacity=0.35416666, numApps=5, numContainers=12
2013-08-10 17:24:05,328 INFO org.apache.hadoop.yarn.server.resourcemanager.scheduler.capacity.ParentQueue: assignedContainer queue=root usedCapacity=0.35416666 absoluteUsedCapacity=0.35416666 used=<memory:17408, vCores:12> cluster=<memory:49152, vCores:96>
2013-08-10 17:24:05,329 INFO org.apache.hadoop.yarn.server.resourcemanager.rmcontainer.RMContainerImpl: container_1376154442901_0010_01_000009 Container Transitioned from NEW to ALLOCATED
2013-08-10 17:24:05,329 INFO org.apache.hadoop.yarn.server.resourcemanager.RMAuditLogger: USER=ubuntu	OPERATION=AM Allocated Container	TARGET=SchedulerApp	RESULT=SUCCESS	APPID=application_1376154442901_0010	CONTAINERID=container_1376154442901_0010_01_000009
2013-08-10 17:24:05,329 INFO org.apache.hadoop.yarn.server.resourcemanager.scheduler.common.fica.FiCaSchedulerNode: Assigned container container_1376154442901_0010_01_000009 of capacity <memory:1024, vCores:1> on host hadoop-220-2:50762, which currently has 2 containers, <memory:2048, vCores:2> used and <memory:6144, vCores:14> available
2013-08-10 17:24:05,330 INFO org.apache.hadoop.yarn.server.resourcemanager.scheduler.capacity.LeafQueue: assignedContainer application=application_1376154442901_0010 container=Container: [ContainerId: container_1376154442901_0010_01_000009, NodeId: hadoop-220-2:50762, NodeHttpAddress: hadoop-220-2:8042, Resource: <memory:1024, vCores:1>, Priority: 20, State: NEW, Token: null, Status: container_id {, app_attempt_id {, application_id {, id: 10, cluster_timestamp: 1376154442901, }, attemptId: 1, }, id: 9, }, state: C_NEW, ] containerId=container_1376154442901_0010_01_000009 queue=default: capacity=1.0, absoluteCapacity=1.0, usedResources=<memory:17408, vCores:12>usedCapacity=0.35416666, absoluteUsedCapacity=0.35416666, numApps=5, numContainers=12 usedCapacity=0.35416666 absoluteUsedCapacity=0.35416666 used=<memory:17408, vCores:12> cluster=<memory:49152, vCores:96>
2013-08-10 17:24:05,330 INFO org.apache.hadoop.yarn.server.resourcemanager.scheduler.capacity.ParentQueue: Re-sorting queues since queue: root.default stats: default: capacity=1.0, absoluteCapacity=1.0, usedResources=<memory:18432, vCores:13>usedCapacity=0.375, absoluteUsedCapacity=0.375, numApps=5, numContainers=13
2013-08-10 17:24:05,331 INFO org.apache.hadoop.yarn.server.resourcemanager.scheduler.capacity.ParentQueue: assignedContainer queue=root usedCapacity=0.375 absoluteUsedCapacity=0.375 used=<memory:18432, vCores:13> cluster=<memory:49152, vCores:96>
2013-08-10 17:24:05,331 INFO org.apache.hadoop.yarn.server.resourcemanager.rmcontainer.RMContainerImpl: container_1376154442901_0010_01_000010 Container Transitioned from NEW to ALLOCATED
2013-08-10 17:24:05,331 INFO org.apache.hadoop.yarn.server.resourcemanager.RMAuditLogger: USER=ubuntu	OPERATION=AM Allocated Container	TARGET=SchedulerApp	RESULT=SUCCESS	APPID=application_1376154442901_0010	CONTAINERID=container_1376154442901_0010_01_000010
2013-08-10 17:24:05,331 INFO org.apache.hadoop.yarn.server.resourcemanager.scheduler.common.fica.FiCaSchedulerNode: Assigned container container_1376154442901_0010_01_000010 of capacity <memory:1024, vCores:1> on host hadoop-220-2:50762, which currently has 3 containers, <memory:3072, vCores:3> used and <memory:5120, vCores:13> available
2013-08-10 17:24:05,332 INFO org.apache.hadoop.yarn.server.resourcemanager.scheduler.capacity.LeafQueue: assignedContainer application=application_1376154442901_0010 container=Container: [ContainerId: container_1376154442901_0010_01_000010, NodeId: hadoop-220-2:50762, NodeHttpAddress: hadoop-220-2:8042, Resource: <memory:1024, vCores:1>, Priority: 20, State: NEW, Token: null, Status: container_id {, app_attempt_id {, application_id {, id: 10, cluster_timestamp: 1376154442901, }, attemptId: 1, }, id: 10, }, state: C_NEW, ] containerId=container_1376154442901_0010_01_000010 queue=default: capacity=1.0, absoluteCapacity=1.0, usedResources=<memory:18432, vCores:13>usedCapacity=0.375, absoluteUsedCapacity=0.375, numApps=5, numContainers=13 usedCapacity=0.375 absoluteUsedCapacity=0.375 used=<memory:18432, vCores:13> cluster=<memory:49152, vCores:96>
2013-08-10 17:24:05,332 INFO org.apache.hadoop.yarn.server.resourcemanager.scheduler.capacity.ParentQueue: Re-sorting queues since queue: root.default stats: default: capacity=1.0, absoluteCapacity=1.0, usedResources=<memory:19456, vCores:14>usedCapacity=0.39583334, absoluteUsedCapacity=0.39583334, numApps=5, numContainers=14
2013-08-10 17:24:05,333 INFO org.apache.hadoop.yarn.server.resourcemanager.scheduler.capacity.ParentQueue: assignedContainer queue=root usedCapacity=0.39583334 absoluteUsedCapacity=0.39583334 used=<memory:19456, vCores:14> cluster=<memory:49152, vCores:96>
2013-08-10 17:24:05,333 INFO org.apache.hadoop.yarn.server.resourcemanager.rmcontainer.RMContainerImpl: container_1376154442901_0010_01_000011 Container Transitioned from NEW to ALLOCATED
2013-08-10 17:24:05,333 INFO org.apache.hadoop.yarn.server.resourcemanager.RMAuditLogger: USER=ubuntu	OPERATION=AM Allocated Container	TARGET=SchedulerApp	RESULT=SUCCESS	APPID=application_1376154442901_0010	CONTAINERID=container_1376154442901_0010_01_000011
2013-08-10 17:24:05,333 INFO org.apache.hadoop.yarn.server.resourcemanager.scheduler.common.fica.FiCaSchedulerNode: Assigned container container_1376154442901_0010_01_000011 of capacity <memory:1024, vCores:1> on host hadoop-220-2:50762, which currently has 4 containers, <memory:4096, vCores:4> used and <memory:4096, vCores:12> available
2013-08-10 17:24:05,334 INFO org.apache.hadoop.yarn.server.resourcemanager.scheduler.capacity.LeafQueue: assignedContainer application=application_1376154442901_0010 container=Container: [ContainerId: container_1376154442901_0010_01_000011, NodeId: hadoop-220-2:50762, NodeHttpAddress: hadoop-220-2:8042, Resource: <memory:1024, vCores:1>, Priority: 20, State: NEW, Token: null, Status: container_id {, app_attempt_id {, application_id {, id: 10, cluster_timestamp: 1376154442901, }, attemptId: 1, }, id: 11, }, state: C_NEW, ] containerId=container_1376154442901_0010_01_000011 queue=default: capacity=1.0, absoluteCapacity=1.0, usedResources=<memory:19456, vCores:14>usedCapacity=0.39583334, absoluteUsedCapacity=0.39583334, numApps=5, numContainers=14 usedCapacity=0.39583334 absoluteUsedCapacity=0.39583334 used=<memory:19456, vCores:14> cluster=<memory:49152, vCores:96>
2013-08-10 17:24:05,335 INFO org.apache.hadoop.yarn.server.resourcemanager.scheduler.capacity.ParentQueue: Re-sorting queues since queue: root.default stats: default: capacity=1.0, absoluteCapacity=1.0, usedResources=<memory:20480, vCores:15>usedCapacity=0.41666666, absoluteUsedCapacity=0.41666666, numApps=5, numContainers=15
2013-08-10 17:24:05,335 INFO org.apache.hadoop.yarn.server.resourcemanager.scheduler.capacity.ParentQueue: assignedContainer queue=root usedCapacity=0.41666666 absoluteUsedCapacity=0.41666666 used=<memory:20480, vCores:15> cluster=<memory:49152, vCores:96>
2013-08-10 17:24:05,335 INFO org.apache.hadoop.yarn.server.resourcemanager.rmcontainer.RMContainerImpl: container_1376154442901_0010_01_000012 Container Transitioned from NEW to ALLOCATED
2013-08-10 17:24:05,335 INFO org.apache.hadoop.yarn.server.resourcemanager.RMAuditLogger: USER=ubuntu	OPERATION=AM Allocated Container	TARGET=SchedulerApp	RESULT=SUCCESS	APPID=application_1376154442901_0010	CONTAINERID=container_1376154442901_0010_01_000012
2013-08-10 17:24:05,336 INFO org.apache.hadoop.yarn.server.resourcemanager.scheduler.common.fica.FiCaSchedulerNode: Assigned container container_1376154442901_0010_01_000012 of capacity <memory:1024, vCores:1> on host hadoop-220-2:50762, which currently has 5 containers, <memory:5120, vCores:5> used and <memory:3072, vCores:11> available
2013-08-10 17:24:05,337 INFO org.apache.hadoop.yarn.server.resourcemanager.scheduler.capacity.LeafQueue: assignedContainer application=application_1376154442901_0010 container=Container: [ContainerId: container_1376154442901_0010_01_000012, NodeId: hadoop-220-2:50762, NodeHttpAddress: hadoop-220-2:8042, Resource: <memory:1024, vCores:1>, Priority: 20, State: NEW, Token: null, Status: container_id {, app_attempt_id {, application_id {, id: 10, cluster_timestamp: 1376154442901, }, attemptId: 1, }, id: 12, }, state: C_NEW, ] containerId=container_1376154442901_0010_01_000012 queue=default: capacity=1.0, absoluteCapacity=1.0, usedResources=<memory:20480, vCores:15>usedCapacity=0.41666666, absoluteUsedCapacity=0.41666666, numApps=5, numContainers=15 usedCapacity=0.41666666 absoluteUsedCapacity=0.41666666 used=<memory:20480, vCores:15> cluster=<memory:49152, vCores:96>
2013-08-10 17:24:05,337 INFO org.apache.hadoop.yarn.server.resourcemanager.scheduler.capacity.ParentQueue: Re-sorting queues since queue: root.default stats: default: capacity=1.0, absoluteCapacity=1.0, usedResources=<memory:21504, vCores:16>usedCapacity=0.4375, absoluteUsedCapacity=0.4375, numApps=5, numContainers=16
2013-08-10 17:24:05,337 INFO org.apache.hadoop.yarn.server.resourcemanager.scheduler.capacity.ParentQueue: assignedContainer queue=root usedCapacity=0.4375 absoluteUsedCapacity=0.4375 used=<memory:21504, vCores:16> cluster=<memory:49152, vCores:96>
2013-08-10 17:24:05,337 INFO org.apache.hadoop.yarn.server.resourcemanager.rmcontainer.RMContainerImpl: container_1376154442901_0010_01_000013 Container Transitioned from NEW to ALLOCATED
2013-08-10 17:24:05,338 INFO org.apache.hadoop.yarn.server.resourcemanager.RMAuditLogger: USER=ubuntu	OPERATION=AM Allocated Container	TARGET=SchedulerApp	RESULT=SUCCESS	APPID=application_1376154442901_0010	CONTAINERID=container_1376154442901_0010_01_000013
2013-08-10 17:24:05,338 INFO org.apache.hadoop.yarn.server.resourcemanager.scheduler.common.fica.FiCaSchedulerNode: Assigned container container_1376154442901_0010_01_000013 of capacity <memory:1024, vCores:1> on host hadoop-220-2:50762, which currently has 6 containers, <memory:6144, vCores:6> used and <memory:2048, vCores:10> available
2013-08-10 17:24:05,339 INFO org.apache.hadoop.yarn.server.resourcemanager.scheduler.capacity.LeafQueue: assignedContainer application=application_1376154442901_0010 container=Container: [ContainerId: container_1376154442901_0010_01_000013, NodeId: hadoop-220-2:50762, NodeHttpAddress: hadoop-220-2:8042, Resource: <memory:1024, vCores:1>, Priority: 20, State: NEW, Token: null, Status: container_id {, app_attempt_id {, application_id {, id: 10, cluster_timestamp: 1376154442901, }, attemptId: 1, }, id: 13, }, state: C_NEW, ] containerId=container_1376154442901_0010_01_000013 queue=default: capacity=1.0, absoluteCapacity=1.0, usedResources=<memory:21504, vCores:16>usedCapacity=0.4375, absoluteUsedCapacity=0.4375, numApps=5, numContainers=16 usedCapacity=0.4375 absoluteUsedCapacity=0.4375 used=<memory:21504, vCores:16> cluster=<memory:49152, vCores:96>
2013-08-10 17:24:05,339 INFO org.apache.hadoop.yarn.server.resourcemanager.scheduler.capacity.ParentQueue: Re-sorting queues since queue: root.default stats: default: capacity=1.0, absoluteCapacity=1.0, usedResources=<memory:22528, vCores:17>usedCapacity=0.45833334, absoluteUsedCapacity=0.45833334, numApps=5, numContainers=17
2013-08-10 17:24:05,339 INFO org.apache.hadoop.yarn.server.resourcemanager.scheduler.capacity.ParentQueue: assignedContainer queue=root usedCapacity=0.45833334 absoluteUsedCapacity=0.45833334 used=<memory:22528, vCores:17> cluster=<memory:49152, vCores:96>
2013-08-10 17:24:05,340 INFO org.apache.hadoop.yarn.server.resourcemanager.rmcontainer.RMContainerImpl: container_1376154442901_0010_01_000014 Container Transitioned from NEW to ALLOCATED
2013-08-10 17:24:05,340 INFO org.apache.hadoop.yarn.server.resourcemanager.RMAuditLogger: USER=ubuntu	OPERATION=AM Allocated Container	TARGET=SchedulerApp	RESULT=SUCCESS	APPID=application_1376154442901_0010	CONTAINERID=container_1376154442901_0010_01_000014
2013-08-10 17:24:05,340 INFO org.apache.hadoop.yarn.server.resourcemanager.scheduler.common.fica.FiCaSchedulerNode: Assigned container container_1376154442901_0010_01_000014 of capacity <memory:1024, vCores:1> on host hadoop-220-2:50762, which currently has 7 containers, <memory:7168, vCores:7> used and <memory:1024, vCores:9> available
2013-08-10 17:24:05,341 INFO org.apache.hadoop.yarn.server.resourcemanager.scheduler.capacity.LeafQueue: assignedContainer application=application_1376154442901_0010 container=Container: [ContainerId: container_1376154442901_0010_01_000014, NodeId: hadoop-220-2:50762, NodeHttpAddress: hadoop-220-2:8042, Resource: <memory:1024, vCores:1>, Priority: 20, State: NEW, Token: null, Status: container_id {, app_attempt_id {, application_id {, id: 10, cluster_timestamp: 1376154442901, }, attemptId: 1, }, id: 14, }, state: C_NEW, ] containerId=container_1376154442901_0010_01_000014 queue=default: capacity=1.0, absoluteCapacity=1.0, usedResources=<memory:22528, vCores:17>usedCapacity=0.45833334, absoluteUsedCapacity=0.45833334, numApps=5, numContainers=17 usedCapacity=0.45833334 absoluteUsedCapacity=0.45833334 used=<memory:22528, vCores:17> cluster=<memory:49152, vCores:96>
2013-08-10 17:24:05,341 INFO org.apache.hadoop.yarn.server.resourcemanager.scheduler.capacity.ParentQueue: Re-sorting queues since queue: root.default stats: default: capacity=1.0, absoluteCapacity=1.0, usedResources=<memory:23552, vCores:18>usedCapacity=0.47916666, absoluteUsedCapacity=0.47916666, numApps=5, numContainers=18
2013-08-10 17:24:05,341 INFO org.apache.hadoop.yarn.server.resourcemanager.scheduler.capacity.ParentQueue: assignedContainer queue=root usedCapacity=0.47916666 absoluteUsedCapacity=0.47916666 used=<memory:23552, vCores:18> cluster=<memory:49152, vCores:96>
2013-08-10 17:24:05,342 INFO org.apache.hadoop.yarn.server.resourcemanager.rmcontainer.RMContainerImpl: container_1376154442901_0010_01_000015 Container Transitioned from NEW to ALLOCATED
2013-08-10 17:24:05,342 INFO org.apache.hadoop.yarn.server.resourcemanager.RMAuditLogger: USER=ubuntu	OPERATION=AM Allocated Container	TARGET=SchedulerApp	RESULT=SUCCESS	APPID=application_1376154442901_0010	CONTAINERID=container_1376154442901_0010_01_000015
2013-08-10 17:24:05,342 INFO org.apache.hadoop.yarn.server.resourcemanager.scheduler.common.fica.FiCaSchedulerNode: Assigned container container_1376154442901_0010_01_000015 of capacity <memory:1024, vCores:1> on host hadoop-220-2:50762, which currently has 8 containers, <memory:8192, vCores:8> used and <memory:0, vCores:8> available
2013-08-10 17:24:05,343 INFO org.apache.hadoop.yarn.server.resourcemanager.scheduler.capacity.LeafQueue: assignedContainer application=application_1376154442901_0010 container=Container: [ContainerId: container_1376154442901_0010_01_000015, NodeId: hadoop-220-2:50762, NodeHttpAddress: hadoop-220-2:8042, Resource: <memory:1024, vCores:1>, Priority: 20, State: NEW, Token: null, Status: container_id {, app_attempt_id {, application_id {, id: 10, cluster_timestamp: 1376154442901, }, attemptId: 1, }, id: 15, }, state: C_NEW, ] containerId=container_1376154442901_0010_01_000015 queue=default: capacity=1.0, absoluteCapacity=1.0, usedResources=<memory:23552, vCores:18>usedCapacity=0.47916666, absoluteUsedCapacity=0.47916666, numApps=5, numContainers=18 usedCapacity=0.47916666 absoluteUsedCapacity=0.47916666 used=<memory:23552, vCores:18> cluster=<memory:49152, vCores:96>
2013-08-10 17:24:05,343 INFO org.apache.hadoop.yarn.server.resourcemanager.scheduler.capacity.ParentQueue: Re-sorting queues since queue: root.default stats: default: capacity=1.0, absoluteCapacity=1.0, usedResources=<memory:24576, vCores:19>usedCapacity=0.5, absoluteUsedCapacity=0.5, numApps=5, numContainers=19
2013-08-10 17:24:05,343 INFO org.apache.hadoop.yarn.server.resourcemanager.scheduler.capacity.ParentQueue: assignedContainer queue=root usedCapacity=0.5 absoluteUsedCapacity=0.5 used=<memory:24576, vCores:19> cluster=<memory:49152, vCores:96>
2013-08-10 17:24:05,344 INFO org.apache.hadoop.yarn.server.resourcemanager.rmcontainer.RMContainerImpl: container_1376154442901_0010_01_000016 Container Transitioned from NEW to ALLOCATED
2013-08-10 17:24:05,344 INFO org.apache.hadoop.yarn.server.resourcemanager.RMAuditLogger: USER=ubuntu	OPERATION=AM Allocated Container	TARGET=SchedulerApp	RESULT=SUCCESS	APPID=application_1376154442901_0010	CONTAINERID=container_1376154442901_0010_01_000016
2013-08-10 17:24:05,344 INFO org.apache.hadoop.yarn.server.resourcemanager.scheduler.common.fica.FiCaSchedulerNode: Assigned container container_1376154442901_0010_01_000016 of capacity <memory:1024, vCores:1> on host hadoop-220-6:56687, which currently has 2 containers, <memory:3072, vCores:2> used and <memory:5120, vCores:14> available
2013-08-10 17:24:05,345 INFO org.apache.hadoop.yarn.server.resourcemanager.scheduler.capacity.LeafQueue: assignedContainer application=application_1376154442901_0010 container=Container: [ContainerId: container_1376154442901_0010_01_000016, NodeId: hadoop-220-6:56687, NodeHttpAddress: hadoop-220-6:8042, Resource: <memory:1024, vCores:1>, Priority: 20, State: NEW, Token: null, Status: container_id {, app_attempt_id {, application_id {, id: 10, cluster_timestamp: 1376154442901, }, attemptId: 1, }, id: 16, }, state: C_NEW, ] containerId=container_1376154442901_0010_01_000016 queue=default: capacity=1.0, absoluteCapacity=1.0, usedResources=<memory:24576, vCores:19>usedCapacity=0.5, absoluteUsedCapacity=0.5, numApps=5, numContainers=19 usedCapacity=0.5 absoluteUsedCapacity=0.5 used=<memory:24576, vCores:19> cluster=<memory:49152, vCores:96>
2013-08-10 17:24:05,346 INFO org.apache.hadoop.yarn.server.resourcemanager.scheduler.capacity.ParentQueue: Re-sorting queues since queue: root.default stats: default: capacity=1.0, absoluteCapacity=1.0, usedResources=<memory:25600, vCores:20>usedCapacity=0.5208333, absoluteUsedCapacity=0.5208333, numApps=5, numContainers=20
2013-08-10 17:24:05,346 INFO org.apache.hadoop.yarn.server.resourcemanager.scheduler.capacity.ParentQueue: assignedContainer queue=root usedCapacity=0.5208333 absoluteUsedCapacity=0.5208333 used=<memory:25600, vCores:20> cluster=<memory:49152, vCores:96>
2013-08-10 17:24:05,346 INFO org.apache.hadoop.yarn.server.resourcemanager.rmcontainer.RMContainerImpl: container_1376154442901_0010_01_000017 Container Transitioned from NEW to ALLOCATED
2013-08-10 17:24:05,347 INFO org.apache.hadoop.yarn.server.resourcemanager.RMAuditLogger: USER=ubuntu	OPERATION=AM Allocated Container	TARGET=SchedulerApp	RESULT=SUCCESS	APPID=application_1376154442901_0010	CONTAINERID=container_1376154442901_0010_01_000017
2013-08-10 17:24:05,347 INFO org.apache.hadoop.yarn.server.resourcemanager.scheduler.common.fica.FiCaSchedulerNode: Assigned container container_1376154442901_0010_01_000017 of capacity <memory:1024, vCores:1> on host hadoop-220-6:56687, which currently has 3 containers, <memory:4096, vCores:3> used and <memory:4096, vCores:13> available
2013-08-10 17:24:05,348 INFO org.apache.hadoop.yarn.server.resourcemanager.scheduler.capacity.LeafQueue: assignedContainer application=application_1376154442901_0010 container=Container: [ContainerId: container_1376154442901_0010_01_000017, NodeId: hadoop-220-6:56687, NodeHttpAddress: hadoop-220-6:8042, Resource: <memory:1024, vCores:1>, Priority: 20, State: NEW, Token: null, Status: container_id {, app_attempt_id {, application_id {, id: 10, cluster_timestamp: 1376154442901, }, attemptId: 1, }, id: 17, }, state: C_NEW, ] containerId=container_1376154442901_0010_01_000017 queue=default: capacity=1.0, absoluteCapacity=1.0, usedResources=<memory:25600, vCores:20>usedCapacity=0.5208333, absoluteUsedCapacity=0.5208333, numApps=5, numContainers=20 usedCapacity=0.5208333 absoluteUsedCapacity=0.5208333 used=<memory:25600, vCores:20> cluster=<memory:49152, vCores:96>
2013-08-10 17:24:05,348 INFO org.apache.hadoop.yarn.server.resourcemanager.scheduler.capacity.ParentQueue: Re-sorting queues since queue: root.default stats: default: capacity=1.0, absoluteCapacity=1.0, usedResources=<memory:26624, vCores:21>usedCapacity=0.5416667, absoluteUsedCapacity=0.5416667, numApps=5, numContainers=21
2013-08-10 17:24:05,348 INFO org.apache.hadoop.yarn.server.resourcemanager.scheduler.capacity.ParentQueue: assignedContainer queue=root usedCapacity=0.5416667 absoluteUsedCapacity=0.5416667 used=<memory:26624, vCores:21> cluster=<memory:49152, vCores:96>
2013-08-10 17:24:05,349 INFO org.apache.hadoop.yarn.server.resourcemanager.rmcontainer.RMContainerImpl: container_1376154442901_0010_01_000018 Container Transitioned from NEW to ALLOCATED
2013-08-10 17:24:05,349 INFO org.apache.hadoop.yarn.server.resourcemanager.RMAuditLogger: USER=ubuntu	OPERATION=AM Allocated Container	TARGET=SchedulerApp	RESULT=SUCCESS	APPID=application_1376154442901_0010	CONTAINERID=container_1376154442901_0010_01_000018
2013-08-10 17:24:05,349 INFO org.apache.hadoop.yarn.server.resourcemanager.scheduler.common.fica.FiCaSchedulerNode: Assigned container container_1376154442901_0010_01_000018 of capacity <memory:1024, vCores:1> on host hadoop-220-6:56687, which currently has 4 containers, <memory:5120, vCores:4> used and <memory:3072, vCores:12> available
2013-08-10 17:24:05,350 INFO org.apache.hadoop.yarn.server.resourcemanager.scheduler.capacity.LeafQueue: assignedContainer application=application_1376154442901_0010 container=Container: [ContainerId: container_1376154442901_0010_01_000018, NodeId: hadoop-220-6:56687, NodeHttpAddress: hadoop-220-6:8042, Resource: <memory:1024, vCores:1>, Priority: 20, State: NEW, Token: null, Status: container_id {, app_attempt_id {, application_id {, id: 10, cluster_timestamp: 1376154442901, }, attemptId: 1, }, id: 18, }, state: C_NEW, ] containerId=container_1376154442901_0010_01_000018 queue=default: capacity=1.0, absoluteCapacity=1.0, usedResources=<memory:26624, vCores:21>usedCapacity=0.5416667, absoluteUsedCapacity=0.5416667, numApps=5, numContainers=21 usedCapacity=0.5416667 absoluteUsedCapacity=0.5416667 used=<memory:26624, vCores:21> cluster=<memory:49152, vCores:96>
2013-08-10 17:24:05,350 INFO org.apache.hadoop.yarn.server.resourcemanager.scheduler.capacity.ParentQueue: Re-sorting queues since queue: root.default stats: default: capacity=1.0, absoluteCapacity=1.0, usedResources=<memory:27648, vCores:22>usedCapacity=0.5625, absoluteUsedCapacity=0.5625, numApps=5, numContainers=22
2013-08-10 17:24:05,350 INFO org.apache.hadoop.yarn.server.resourcemanager.scheduler.capacity.ParentQueue: assignedContainer queue=root usedCapacity=0.5625 absoluteUsedCapacity=0.5625 used=<memory:27648, vCores:22> cluster=<memory:49152, vCores:96>
2013-08-10 17:24:05,351 INFO org.apache.hadoop.yarn.server.resourcemanager.rmcontainer.RMContainerImpl: container_1376154442901_0010_01_000019 Container Transitioned from NEW to ALLOCATED
2013-08-10 17:24:05,351 INFO org.apache.hadoop.yarn.server.resourcemanager.RMAuditLogger: USER=ubuntu	OPERATION=AM Allocated Container	TARGET=SchedulerApp	RESULT=SUCCESS	APPID=application_1376154442901_0010	CONTAINERID=container_1376154442901_0010_01_000019
2013-08-10 17:24:05,351 INFO org.apache.hadoop.yarn.server.resourcemanager.scheduler.common.fica.FiCaSchedulerNode: Assigned container container_1376154442901_0010_01_000019 of capacity <memory:1024, vCores:1> on host hadoop-220-6:56687, which currently has 5 containers, <memory:6144, vCores:5> used and <memory:2048, vCores:11> available
2013-08-10 17:24:05,352 INFO org.apache.hadoop.yarn.server.resourcemanager.scheduler.capacity.LeafQueue: assignedContainer application=application_1376154442901_0010 container=Container: [ContainerId: container_1376154442901_0010_01_000019, NodeId: hadoop-220-6:56687, NodeHttpAddress: hadoop-220-6:8042, Resource: <memory:1024, vCores:1>, Priority: 20, State: NEW, Token: null, Status: container_id {, app_attempt_id {, application_id {, id: 10, cluster_timestamp: 1376154442901, }, attemptId: 1, }, id: 19, }, state: C_NEW, ] containerId=container_1376154442901_0010_01_000019 queue=default: capacity=1.0, absoluteCapacity=1.0, usedResources=<memory:27648, vCores:22>usedCapacity=0.5625, absoluteUsedCapacity=0.5625, numApps=5, numContainers=22 usedCapacity=0.5625 absoluteUsedCapacity=0.5625 used=<memory:27648, vCores:22> cluster=<memory:49152, vCores:96>
2013-08-10 17:24:05,352 INFO org.apache.hadoop.yarn.server.resourcemanager.scheduler.capacity.ParentQueue: Re-sorting queues since queue: root.default stats: default: capacity=1.0, absoluteCapacity=1.0, usedResources=<memory:28672, vCores:23>usedCapacity=0.5833333, absoluteUsedCapacity=0.5833333, numApps=5, numContainers=23
2013-08-10 17:24:05,352 INFO org.apache.hadoop.yarn.server.resourcemanager.scheduler.capacity.ParentQueue: assignedContainer queue=root usedCapacity=0.5833333 absoluteUsedCapacity=0.5833333 used=<memory:28672, vCores:23> cluster=<memory:49152, vCores:96>
2013-08-10 17:24:05,355 INFO org.apache.hadoop.yarn.server.resourcemanager.rmcontainer.RMContainerImpl: container_1376154442901_0010_01_000020 Container Transitioned from NEW to ALLOCATED
2013-08-10 17:24:05,355 INFO org.apache.hadoop.yarn.server.resourcemanager.RMAuditLogger: USER=ubuntu	OPERATION=AM Allocated Container	TARGET=SchedulerApp	RESULT=SUCCESS	APPID=application_1376154442901_0010	CONTAINERID=container_1376154442901_0010_01_000020
2013-08-10 17:24:05,355 INFO org.apache.hadoop.yarn.server.resourcemanager.scheduler.common.fica.FiCaSchedulerNode: Assigned container container_1376154442901_0010_01_000020 of capacity <memory:1024, vCores:1> on host hadoop-220-6:56687, which currently has 6 containers, <memory:7168, vCores:6> used and <memory:1024, vCores:10> available
2013-08-10 17:24:05,356 INFO org.apache.hadoop.yarn.server.resourcemanager.scheduler.capacity.LeafQueue: assignedContainer application=application_1376154442901_0010 container=Container: [ContainerId: container_1376154442901_0010_01_000020, NodeId: hadoop-220-6:56687, NodeHttpAddress: hadoop-220-6:8042, Resource: <memory:1024, vCores:1>, Priority: 20, State: NEW, Token: null, Status: container_id {, app_attempt_id {, application_id {, id: 10, cluster_timestamp: 1376154442901, }, attemptId: 1, }, id: 20, }, state: C_NEW, ] containerId=container_1376154442901_0010_01_000020 queue=default: capacity=1.0, absoluteCapacity=1.0, usedResources=<memory:28672, vCores:23>usedCapacity=0.5833333, absoluteUsedCapacity=0.5833333, numApps=5, numContainers=23 usedCapacity=0.5833333 absoluteUsedCapacity=0.5833333 used=<memory:28672, vCores:23> cluster=<memory:49152, vCores:96>
2013-08-10 17:24:05,356 INFO org.apache.hadoop.yarn.server.resourcemanager.scheduler.capacity.ParentQueue: Re-sorting queues since queue: root.default stats: default: capacity=1.0, absoluteCapacity=1.0, usedResources=<memory:29696, vCores:24>usedCapacity=0.6041667, absoluteUsedCapacity=0.6041667, numApps=5, numContainers=24
2013-08-10 17:24:05,356 INFO org.apache.hadoop.yarn.server.resourcemanager.scheduler.capacity.ParentQueue: assignedContainer queue=root usedCapacity=0.6041667 absoluteUsedCapacity=0.6041667 used=<memory:29696, vCores:24> cluster=<memory:49152, vCores:96>
2013-08-10 17:24:05,357 INFO org.apache.hadoop.yarn.server.resourcemanager.rmcontainer.RMContainerImpl: container_1376154442901_0010_01_000021 Container Transitioned from NEW to ALLOCATED
2013-08-10 17:24:05,357 INFO org.apache.hadoop.yarn.server.resourcemanager.RMAuditLogger: USER=ubuntu	OPERATION=AM Allocated Container	TARGET=SchedulerApp	RESULT=SUCCESS	APPID=application_1376154442901_0010	CONTAINERID=container_1376154442901_0010_01_000021
2013-08-10 17:24:05,357 INFO org.apache.hadoop.yarn.server.resourcemanager.scheduler.common.fica.FiCaSchedulerNode: Assigned container container_1376154442901_0010_01_000021 of capacity <memory:1024, vCores:1> on host hadoop-220-6:56687, which currently has 7 containers, <memory:8192, vCores:7> used and <memory:0, vCores:9> available
2013-08-10 17:24:05,358 INFO org.apache.hadoop.yarn.server.resourcemanager.scheduler.capacity.LeafQueue: assignedContainer application=application_1376154442901_0010 container=Container: [ContainerId: container_1376154442901_0010_01_000021, NodeId: hadoop-220-6:56687, NodeHttpAddress: hadoop-220-6:8042, Resource: <memory:1024, vCores:1>, Priority: 20, State: NEW, Token: null, Status: container_id {, app_attempt_id {, application_id {, id: 10, cluster_timestamp: 1376154442901, }, attemptId: 1, }, id: 21, }, state: C_NEW, ] containerId=container_1376154442901_0010_01_000021 queue=default: capacity=1.0, absoluteCapacity=1.0, usedResources=<memory:29696, vCores:24>usedCapacity=0.6041667, absoluteUsedCapacity=0.6041667, numApps=5, numContainers=24 usedCapacity=0.6041667 absoluteUsedCapacity=0.6041667 used=<memory:29696, vCores:24> cluster=<memory:49152, vCores:96>
2013-08-10 17:24:05,359 INFO org.apache.hadoop.yarn.server.resourcemanager.scheduler.capacity.ParentQueue: Re-sorting queues since queue: root.default stats: default: capacity=1.0, absoluteCapacity=1.0, usedResources=<memory:30720, vCores:25>usedCapacity=0.625, absoluteUsedCapacity=0.625, numApps=5, numContainers=25
2013-08-10 17:24:05,359 INFO org.apache.hadoop.yarn.server.resourcemanager.scheduler.capacity.ParentQueue: assignedContainer queue=root usedCapacity=0.625 absoluteUsedCapacity=0.625 used=<memory:30720, vCores:25> cluster=<memory:49152, vCores:96>
2013-08-10 17:24:05,842 INFO org.apache.hadoop.yarn.server.resourcemanager.rmcontainer.RMContainerImpl: container_1376154442901_0010_01_000022 Container Transitioned from NEW to ALLOCATED
2013-08-10 17:24:05,843 INFO org.apache.hadoop.yarn.server.resourcemanager.RMAuditLogger: USER=ubuntu	OPERATION=AM Allocated Container	TARGET=SchedulerApp	RESULT=SUCCESS	APPID=application_1376154442901_0010	CONTAINERID=container_1376154442901_0010_01_000022
2013-08-10 17:24:05,843 INFO org.apache.hadoop.yarn.server.resourcemanager.scheduler.common.fica.FiCaSchedulerNode: Assigned container container_1376154442901_0010_01_000022 of capacity <memory:1024, vCores:1> on host hadoop-220-7:42517, which currently has 2 containers, <memory:3072, vCores:2> used and <memory:5120, vCores:14> available
2013-08-10 17:24:05,844 INFO org.apache.hadoop.yarn.server.resourcemanager.scheduler.capacity.LeafQueue: assignedContainer application=application_1376154442901_0010 container=Container: [ContainerId: container_1376154442901_0010_01_000022, NodeId: hadoop-220-7:42517, NodeHttpAddress: hadoop-220-7:8042, Resource: <memory:1024, vCores:1>, Priority: 20, State: NEW, Token: null, Status: container_id {, app_attempt_id {, application_id {, id: 10, cluster_timestamp: 1376154442901, }, attemptId: 1, }, id: 22, }, state: C_NEW, ] containerId=container_1376154442901_0010_01_000022 queue=default: capacity=1.0, absoluteCapacity=1.0, usedResources=<memory:30720, vCores:25>usedCapacity=0.625, absoluteUsedCapacity=0.625, numApps=5, numContainers=25 usedCapacity=0.625 absoluteUsedCapacity=0.625 used=<memory:30720, vCores:25> cluster=<memory:49152, vCores:96>
2013-08-10 17:24:05,844 INFO org.apache.hadoop.yarn.server.resourcemanager.scheduler.capacity.ParentQueue: Re-sorting queues since queue: root.default stats: default: capacity=1.0, absoluteCapacity=1.0, usedResources=<memory:31744, vCores:26>usedCapacity=0.6458333, absoluteUsedCapacity=0.6458333, numApps=5, numContainers=26
2013-08-10 17:24:05,844 INFO org.apache.hadoop.yarn.server.resourcemanager.scheduler.capacity.ParentQueue: assignedContainer queue=root usedCapacity=0.6458333 absoluteUsedCapacity=0.6458333 used=<memory:31744, vCores:26> cluster=<memory:49152, vCores:96>
2013-08-10 17:24:05,845 INFO org.apache.hadoop.yarn.server.resourcemanager.rmcontainer.RMContainerImpl: container_1376154442901_0010_01_000023 Container Transitioned from NEW to ALLOCATED
2013-08-10 17:24:05,845 INFO org.apache.hadoop.yarn.server.resourcemanager.RMAuditLogger: USER=ubuntu	OPERATION=AM Allocated Container	TARGET=SchedulerApp	RESULT=SUCCESS	APPID=application_1376154442901_0010	CONTAINERID=container_1376154442901_0010_01_000023
2013-08-10 17:24:05,845 INFO org.apache.hadoop.yarn.server.resourcemanager.scheduler.common.fica.FiCaSchedulerNode: Assigned container container_1376154442901_0010_01_000023 of capacity <memory:1024, vCores:1> on host hadoop-220-7:42517, which currently has 3 containers, <memory:4096, vCores:3> used and <memory:4096, vCores:13> available
2013-08-10 17:24:05,846 INFO org.apache.hadoop.yarn.server.resourcemanager.scheduler.capacity.LeafQueue: assignedContainer application=application_1376154442901_0010 container=Container: [ContainerId: container_1376154442901_0010_01_000023, NodeId: hadoop-220-7:42517, NodeHttpAddress: hadoop-220-7:8042, Resource: <memory:1024, vCores:1>, Priority: 20, State: NEW, Token: null, Status: container_id {, app_attempt_id {, application_id {, id: 10, cluster_timestamp: 1376154442901, }, attemptId: 1, }, id: 23, }, state: C_NEW, ] containerId=container_1376154442901_0010_01_000023 queue=default: capacity=1.0, absoluteCapacity=1.0, usedResources=<memory:31744, vCores:26>usedCapacity=0.6458333, absoluteUsedCapacity=0.6458333, numApps=5, numContainers=26 usedCapacity=0.6458333 absoluteUsedCapacity=0.6458333 used=<memory:31744, vCores:26> cluster=<memory:49152, vCores:96>
2013-08-10 17:24:05,846 INFO org.apache.hadoop.yarn.server.resourcemanager.scheduler.capacity.ParentQueue: Re-sorting queues since queue: root.default stats: default: capacity=1.0, absoluteCapacity=1.0, usedResources=<memory:32768, vCores:27>usedCapacity=0.6666667, absoluteUsedCapacity=0.6666667, numApps=5, numContainers=27
2013-08-10 17:24:05,847 INFO org.apache.hadoop.yarn.server.resourcemanager.scheduler.capacity.ParentQueue: assignedContainer queue=root usedCapacity=0.6666667 absoluteUsedCapacity=0.6666667 used=<memory:32768, vCores:27> cluster=<memory:49152, vCores:96>
2013-08-10 17:24:05,847 INFO org.apache.hadoop.yarn.server.resourcemanager.rmcontainer.RMContainerImpl: container_1376154442901_0010_01_000024 Container Transitioned from NEW to ALLOCATED
2013-08-10 17:24:05,847 INFO org.apache.hadoop.yarn.server.resourcemanager.RMAuditLogger: USER=ubuntu	OPERATION=AM Allocated Container	TARGET=SchedulerApp	RESULT=SUCCESS	APPID=application_1376154442901_0010	CONTAINERID=container_1376154442901_0010_01_000024
2013-08-10 17:24:05,847 INFO org.apache.hadoop.yarn.server.resourcemanager.scheduler.common.fica.FiCaSchedulerNode: Assigned container container_1376154442901_0010_01_000024 of capacity <memory:1024, vCores:1> on host hadoop-220-7:42517, which currently has 4 containers, <memory:5120, vCores:4> used and <memory:3072, vCores:12> available
2013-08-10 17:24:05,848 INFO org.apache.hadoop.yarn.server.resourcemanager.scheduler.capacity.LeafQueue: assignedContainer application=application_1376154442901_0010 container=Container: [ContainerId: container_1376154442901_0010_01_000024, NodeId: hadoop-220-7:42517, NodeHttpAddress: hadoop-220-7:8042, Resource: <memory:1024, vCores:1>, Priority: 20, State: NEW, Token: null, Status: container_id {, app_attempt_id {, application_id {, id: 10, cluster_timestamp: 1376154442901, }, attemptId: 1, }, id: 24, }, state: C_NEW, ] containerId=container_1376154442901_0010_01_000024 queue=default: capacity=1.0, absoluteCapacity=1.0, usedResources=<memory:32768, vCores:27>usedCapacity=0.6666667, absoluteUsedCapacity=0.6666667, numApps=5, numContainers=27 usedCapacity=0.6666667 absoluteUsedCapacity=0.6666667 used=<memory:32768, vCores:27> cluster=<memory:49152, vCores:96>
2013-08-10 17:24:05,848 INFO org.apache.hadoop.yarn.server.resourcemanager.scheduler.capacity.ParentQueue: Re-sorting queues since queue: root.default stats: default: capacity=1.0, absoluteCapacity=1.0, usedResources=<memory:33792, vCores:28>usedCapacity=0.6875, absoluteUsedCapacity=0.6875, numApps=5, numContainers=28
2013-08-10 17:24:05,849 INFO org.apache.hadoop.yarn.server.resourcemanager.scheduler.capacity.ParentQueue: assignedContainer queue=root usedCapacity=0.6875 absoluteUsedCapacity=0.6875 used=<memory:33792, vCores:28> cluster=<memory:49152, vCores:96>
2013-08-10 17:24:05,849 INFO org.apache.hadoop.yarn.server.resourcemanager.rmcontainer.RMContainerImpl: container_1376154442901_0010_01_000025 Container Transitioned from NEW to ALLOCATED
2013-08-10 17:24:05,849 INFO org.apache.hadoop.yarn.server.resourcemanager.RMAuditLogger: USER=ubuntu	OPERATION=AM Allocated Container	TARGET=SchedulerApp	RESULT=SUCCESS	APPID=application_1376154442901_0010	CONTAINERID=container_1376154442901_0010_01_000025
2013-08-10 17:24:05,849 INFO org.apache.hadoop.yarn.server.resourcemanager.scheduler.common.fica.FiCaSchedulerNode: Assigned container container_1376154442901_0010_01_000025 of capacity <memory:1024, vCores:1> on host hadoop-220-7:42517, which currently has 5 containers, <memory:6144, vCores:5> used and <memory:2048, vCores:11> available
2013-08-10 17:24:05,850 INFO org.apache.hadoop.yarn.server.resourcemanager.scheduler.capacity.LeafQueue: assignedContainer application=application_1376154442901_0010 container=Container: [ContainerId: container_1376154442901_0010_01_000025, NodeId: hadoop-220-7:42517, NodeHttpAddress: hadoop-220-7:8042, Resource: <memory:1024, vCores:1>, Priority: 20, State: NEW, Token: null, Status: container_id {, app_attempt_id {, application_id {, id: 10, cluster_timestamp: 1376154442901, }, attemptId: 1, }, id: 25, }, state: C_NEW, ] containerId=container_1376154442901_0010_01_000025 queue=default: capacity=1.0, absoluteCapacity=1.0, usedResources=<memory:33792, vCores:28>usedCapacity=0.6875, absoluteUsedCapacity=0.6875, numApps=5, numContainers=28 usedCapacity=0.6875 absoluteUsedCapacity=0.6875 used=<memory:33792, vCores:28> cluster=<memory:49152, vCores:96>
2013-08-10 17:24:05,851 INFO org.apache.hadoop.yarn.server.resourcemanager.scheduler.capacity.ParentQueue: Re-sorting queues since queue: root.default stats: default: capacity=1.0, absoluteCapacity=1.0, usedResources=<memory:34816, vCores:29>usedCapacity=0.7083333, absoluteUsedCapacity=0.7083333, numApps=5, numContainers=29
2013-08-10 17:24:05,851 INFO org.apache.hadoop.yarn.server.resourcemanager.scheduler.capacity.ParentQueue: assignedContainer queue=root usedCapacity=0.7083333 absoluteUsedCapacity=0.7083333 used=<memory:34816, vCores:29> cluster=<memory:49152, vCores:96>
2013-08-10 17:24:05,851 INFO org.apache.hadoop.yarn.server.resourcemanager.rmcontainer.RMContainerImpl: container_1376154442901_0010_01_000026 Container Transitioned from NEW to ALLOCATED
2013-08-10 17:24:05,851 INFO org.apache.hadoop.yarn.server.resourcemanager.RMAuditLogger: USER=ubuntu	OPERATION=AM Allocated Container	TARGET=SchedulerApp	RESULT=SUCCESS	APPID=application_1376154442901_0010	CONTAINERID=container_1376154442901_0010_01_000026
2013-08-10 17:24:05,851 INFO org.apache.hadoop.yarn.server.resourcemanager.scheduler.common.fica.FiCaSchedulerNode: Assigned container container_1376154442901_0010_01_000026 of capacity <memory:1024, vCores:1> on host hadoop-220-7:42517, which currently has 6 containers, <memory:7168, vCores:6> used and <memory:1024, vCores:10> available
2013-08-10 17:24:05,852 INFO org.apache.hadoop.yarn.server.resourcemanager.scheduler.capacity.LeafQueue: assignedContainer application=application_1376154442901_0010 container=Container: [ContainerId: container_1376154442901_0010_01_000026, NodeId: hadoop-220-7:42517, NodeHttpAddress: hadoop-220-7:8042, Resource: <memory:1024, vCores:1>, Priority: 20, State: NEW, Token: null, Status: container_id {, app_attempt_id {, application_id {, id: 10, cluster_timestamp: 1376154442901, }, attemptId: 1, }, id: 26, }, state: C_NEW, ] containerId=container_1376154442901_0010_01_000026 queue=default: capacity=1.0, absoluteCapacity=1.0, usedResources=<memory:34816, vCores:29>usedCapacity=0.7083333, absoluteUsedCapacity=0.7083333, numApps=5, numContainers=29 usedCapacity=0.7083333 absoluteUsedCapacity=0.7083333 used=<memory:34816, vCores:29> cluster=<memory:49152, vCores:96>
2013-08-10 17:24:05,853 INFO org.apache.hadoop.yarn.server.resourcemanager.scheduler.capacity.ParentQueue: Re-sorting queues since queue: root.default stats: default: capacity=1.0, absoluteCapacity=1.0, usedResources=<memory:35840, vCores:30>usedCapacity=0.7291667, absoluteUsedCapacity=0.7291667, numApps=5, numContainers=30
2013-08-10 17:24:05,853 INFO org.apache.hadoop.yarn.server.resourcemanager.scheduler.capacity.ParentQueue: assignedContainer queue=root usedCapacity=0.7291667 absoluteUsedCapacity=0.7291667 used=<memory:35840, vCores:30> cluster=<memory:49152, vCores:96>
2013-08-10 17:24:05,853 INFO org.apache.hadoop.yarn.server.resourcemanager.rmcontainer.RMContainerImpl: container_1376154442901_0010_01_000027 Container Transitioned from NEW to ALLOCATED
2013-08-10 17:24:05,853 INFO org.apache.hadoop.yarn.server.resourcemanager.RMAuditLogger: USER=ubuntu	OPERATION=AM Allocated Container	TARGET=SchedulerApp	RESULT=SUCCESS	APPID=application_1376154442901_0010	CONTAINERID=container_1376154442901_0010_01_000027
2013-08-10 17:24:05,853 INFO org.apache.hadoop.yarn.server.resourcemanager.scheduler.common.fica.FiCaSchedulerNode: Assigned container container_1376154442901_0010_01_000027 of capacity <memory:1024, vCores:1> on host hadoop-220-7:42517, which currently has 7 containers, <memory:8192, vCores:7> used and <memory:0, vCores:9> available
2013-08-10 17:24:05,854 INFO org.apache.hadoop.yarn.server.resourcemanager.scheduler.capacity.LeafQueue: assignedContainer application=application_1376154442901_0010 container=Container: [ContainerId: container_1376154442901_0010_01_000027, NodeId: hadoop-220-7:42517, NodeHttpAddress: hadoop-220-7:8042, Resource: <memory:1024, vCores:1>, Priority: 20, State: NEW, Token: null, Status: container_id {, app_attempt_id {, application_id {, id: 10, cluster_timestamp: 1376154442901, }, attemptId: 1, }, id: 27, }, state: C_NEW, ] containerId=container_1376154442901_0010_01_000027 queue=default: capacity=1.0, absoluteCapacity=1.0, usedResources=<memory:35840, vCores:30>usedCapacity=0.7291667, absoluteUsedCapacity=0.7291667, numApps=5, numContainers=30 usedCapacity=0.7291667 absoluteUsedCapacity=0.7291667 used=<memory:35840, vCores:30> cluster=<memory:49152, vCores:96>
2013-08-10 17:24:05,855 INFO org.apache.hadoop.yarn.server.resourcemanager.scheduler.capacity.ParentQueue: Re-sorting queues since queue: root.default stats: default: capacity=1.0, absoluteCapacity=1.0, usedResources=<memory:36864, vCores:31>usedCapacity=0.75, absoluteUsedCapacity=0.75, numApps=5, numContainers=31
2013-08-10 17:24:05,855 INFO org.apache.hadoop.yarn.server.resourcemanager.scheduler.capacity.ParentQueue: assignedContainer queue=root usedCapacity=0.75 absoluteUsedCapacity=0.75 used=<memory:36864, vCores:31> cluster=<memory:49152, vCores:96>
2013-08-10 17:24:05,855 INFO org.apache.hadoop.yarn.server.resourcemanager.rmcontainer.RMContainerImpl: container_1376154442901_0010_01_000028 Container Transitioned from NEW to ALLOCATED
2013-08-10 17:24:05,855 INFO org.apache.hadoop.yarn.server.resourcemanager.RMAuditLogger: USER=ubuntu	OPERATION=AM Allocated Container	TARGET=SchedulerApp	RESULT=SUCCESS	APPID=application_1376154442901_0010	CONTAINERID=container_1376154442901_0010_01_000028
2013-08-10 17:24:05,855 INFO org.apache.hadoop.yarn.server.resourcemanager.scheduler.common.fica.FiCaSchedulerNode: Assigned container container_1376154442901_0010_01_000028 of capacity <memory:1024, vCores:1> on host hadoop-220-4:35716, which currently has 2 containers, <memory:3072, vCores:2> used and <memory:5120, vCores:14> available
2013-08-10 17:24:05,856 INFO org.apache.hadoop.yarn.server.resourcemanager.scheduler.capacity.LeafQueue: assignedContainer application=application_1376154442901_0010 container=Container: [ContainerId: container_1376154442901_0010_01_000028, NodeId: hadoop-220-4:35716, NodeHttpAddress: hadoop-220-4:8042, Resource: <memory:1024, vCores:1>, Priority: 20, State: NEW, Token: null, Status: container_id {, app_attempt_id {, application_id {, id: 10, cluster_timestamp: 1376154442901, }, attemptId: 1, }, id: 28, }, state: C_NEW, ] containerId=container_1376154442901_0010_01_000028 queue=default: capacity=1.0, absoluteCapacity=1.0, usedResources=<memory:36864, vCores:31>usedCapacity=0.75, absoluteUsedCapacity=0.75, numApps=5, numContainers=31 usedCapacity=0.75 absoluteUsedCapacity=0.75 used=<memory:36864, vCores:31> cluster=<memory:49152, vCores:96>
2013-08-10 17:24:05,857 INFO org.apache.hadoop.yarn.server.resourcemanager.scheduler.capacity.ParentQueue: Re-sorting queues since queue: root.default stats: default: capacity=1.0, absoluteCapacity=1.0, usedResources=<memory:37888, vCores:32>usedCapacity=0.7708333, absoluteUsedCapacity=0.7708333, numApps=5, numContainers=32
2013-08-10 17:24:05,857 INFO org.apache.hadoop.yarn.server.resourcemanager.scheduler.capacity.ParentQueue: assignedContainer queue=root usedCapacity=0.7708333 absoluteUsedCapacity=0.7708333 used=<memory:37888, vCores:32> cluster=<memory:49152, vCores:96>
2013-08-10 17:24:05,857 INFO org.apache.hadoop.yarn.server.resourcemanager.rmcontainer.RMContainerImpl: container_1376154442901_0010_01_000029 Container Transitioned from NEW to ALLOCATED
2013-08-10 17:24:05,857 INFO org.apache.hadoop.yarn.server.resourcemanager.RMAuditLogger: USER=ubuntu	OPERATION=AM Allocated Container	TARGET=SchedulerApp	RESULT=SUCCESS	APPID=application_1376154442901_0010	CONTAINERID=container_1376154442901_0010_01_000029
2013-08-10 17:24:05,858 INFO org.apache.hadoop.yarn.server.resourcemanager.scheduler.common.fica.FiCaSchedulerNode: Assigned container container_1376154442901_0010_01_000029 of capacity <memory:1024, vCores:1> on host hadoop-220-4:35716, which currently has 3 containers, <memory:4096, vCores:3> used and <memory:4096, vCores:13> available
2013-08-10 17:24:05,858 INFO org.apache.hadoop.yarn.server.resourcemanager.scheduler.capacity.LeafQueue: assignedContainer application=application_1376154442901_0010 container=Container: [ContainerId: container_1376154442901_0010_01_000029, NodeId: hadoop-220-4:35716, NodeHttpAddress: hadoop-220-4:8042, Resource: <memory:1024, vCores:1>, Priority: 20, State: NEW, Token: null, Status: container_id {, app_attempt_id {, application_id {, id: 10, cluster_timestamp: 1376154442901, }, attemptId: 1, }, id: 29, }, state: C_NEW, ] containerId=container_1376154442901_0010_01_000029 queue=default: capacity=1.0, absoluteCapacity=1.0, usedResources=<memory:37888, vCores:32>usedCapacity=0.7708333, absoluteUsedCapacity=0.7708333, numApps=5, numContainers=32 usedCapacity=0.7708333 absoluteUsedCapacity=0.7708333 used=<memory:37888, vCores:32> cluster=<memory:49152, vCores:96>
2013-08-10 17:24:05,859 INFO org.apache.hadoop.yarn.server.resourcemanager.scheduler.capacity.ParentQueue: Re-sorting queues since queue: root.default stats: default: capacity=1.0, absoluteCapacity=1.0, usedResources=<memory:38912, vCores:33>usedCapacity=0.7916667, absoluteUsedCapacity=0.7916667, numApps=5, numContainers=33
2013-08-10 17:24:05,859 INFO org.apache.hadoop.yarn.server.resourcemanager.scheduler.capacity.ParentQueue: assignedContainer queue=root usedCapacity=0.7916667 absoluteUsedCapacity=0.7916667 used=<memory:38912, vCores:33> cluster=<memory:49152, vCores:96>
2013-08-10 17:24:05,859 INFO org.apache.hadoop.yarn.server.resourcemanager.rmcontainer.RMContainerImpl: container_1376154442901_0010_01_000030 Container Transitioned from NEW to ALLOCATED
2013-08-10 17:24:05,859 INFO org.apache.hadoop.yarn.server.resourcemanager.RMAuditLogger: USER=ubuntu	OPERATION=AM Allocated Container	TARGET=SchedulerApp	RESULT=SUCCESS	APPID=application_1376154442901_0010	CONTAINERID=container_1376154442901_0010_01_000030
2013-08-10 17:24:05,860 INFO org.apache.hadoop.yarn.server.resourcemanager.scheduler.common.fica.FiCaSchedulerNode: Assigned container container_1376154442901_0010_01_000030 of capacity <memory:1024, vCores:1> on host hadoop-220-4:35716, which currently has 4 containers, <memory:5120, vCores:4> used and <memory:3072, vCores:12> available
2013-08-10 17:24:05,861 INFO org.apache.hadoop.yarn.server.resourcemanager.scheduler.capacity.LeafQueue: assignedContainer application=application_1376154442901_0010 container=Container: [ContainerId: container_1376154442901_0010_01_000030, NodeId: hadoop-220-4:35716, NodeHttpAddress: hadoop-220-4:8042, Resource: <memory:1024, vCores:1>, Priority: 20, State: NEW, Token: null, Status: container_id {, app_attempt_id {, application_id {, id: 10, cluster_timestamp: 1376154442901, }, attemptId: 1, }, id: 30, }, state: C_NEW, ] containerId=container_1376154442901_0010_01_000030 queue=default: capacity=1.0, absoluteCapacity=1.0, usedResources=<memory:38912, vCores:33>usedCapacity=0.7916667, absoluteUsedCapacity=0.7916667, numApps=5, numContainers=33 usedCapacity=0.7916667 absoluteUsedCapacity=0.7916667 used=<memory:38912, vCores:33> cluster=<memory:49152, vCores:96>
2013-08-10 17:24:05,861 INFO org.apache.hadoop.yarn.server.resourcemanager.scheduler.capacity.ParentQueue: Re-sorting queues since queue: root.default stats: default: capacity=1.0, absoluteCapacity=1.0, usedResources=<memory:39936, vCores:34>usedCapacity=0.8125, absoluteUsedCapacity=0.8125, numApps=5, numContainers=34
2013-08-10 17:24:05,861 INFO org.apache.hadoop.yarn.server.resourcemanager.scheduler.capacity.ParentQueue: assignedContainer queue=root usedCapacity=0.8125 absoluteUsedCapacity=0.8125 used=<memory:39936, vCores:34> cluster=<memory:49152, vCores:96>
2013-08-10 17:24:05,861 INFO org.apache.hadoop.yarn.server.resourcemanager.rmcontainer.RMContainerImpl: container_1376154442901_0010_01_000031 Container Transitioned from NEW to ALLOCATED
2013-08-10 17:24:05,862 INFO org.apache.hadoop.yarn.server.resourcemanager.RMAuditLogger: USER=ubuntu	OPERATION=AM Allocated Container	TARGET=SchedulerApp	RESULT=SUCCESS	APPID=application_1376154442901_0010	CONTAINERID=container_1376154442901_0010_01_000031
2013-08-10 17:24:05,862 INFO org.apache.hadoop.yarn.server.resourcemanager.scheduler.common.fica.FiCaSchedulerNode: Assigned container container_1376154442901_0010_01_000031 of capacity <memory:1024, vCores:1> on host hadoop-220-4:35716, which currently has 5 containers, <memory:6144, vCores:5> used and <memory:2048, vCores:11> available
2013-08-10 17:24:05,863 INFO org.apache.hadoop.yarn.server.resourcemanager.scheduler.capacity.LeafQueue: assignedContainer application=application_1376154442901_0010 container=Container: [ContainerId: container_1376154442901_0010_01_000031, NodeId: hadoop-220-4:35716, NodeHttpAddress: hadoop-220-4:8042, Resource: <memory:1024, vCores:1>, Priority: 20, State: NEW, Token: null, Status: container_id {, app_attempt_id {, application_id {, id: 10, cluster_timestamp: 1376154442901, }, attemptId: 1, }, id: 31, }, state: C_NEW, ] containerId=container_1376154442901_0010_01_000031 queue=default: capacity=1.0, absoluteCapacity=1.0, usedResources=<memory:39936, vCores:34>usedCapacity=0.8125, absoluteUsedCapacity=0.8125, numApps=5, numContainers=34 usedCapacity=0.8125 absoluteUsedCapacity=0.8125 used=<memory:39936, vCores:34> cluster=<memory:49152, vCores:96>
2013-08-10 17:24:05,863 INFO org.apache.hadoop.yarn.server.resourcemanager.scheduler.capacity.ParentQueue: Re-sorting queues since queue: root.default stats: default: capacity=1.0, absoluteCapacity=1.0, usedResources=<memory:40960, vCores:35>usedCapacity=0.8333333, absoluteUsedCapacity=0.8333333, numApps=5, numContainers=35
2013-08-10 17:24:05,863 INFO org.apache.hadoop.yarn.server.resourcemanager.scheduler.capacity.ParentQueue: assignedContainer queue=root usedCapacity=0.8333333 absoluteUsedCapacity=0.8333333 used=<memory:40960, vCores:35> cluster=<memory:49152, vCores:96>
2013-08-10 17:24:05,863 INFO org.apache.hadoop.yarn.server.resourcemanager.rmcontainer.RMContainerImpl: container_1376154442901_0010_01_000032 Container Transitioned from NEW to ALLOCATED
2013-08-10 17:24:05,864 INFO org.apache.hadoop.yarn.server.resourcemanager.RMAuditLogger: USER=ubuntu	OPERATION=AM Allocated Container	TARGET=SchedulerApp	RESULT=SUCCESS	APPID=application_1376154442901_0010	CONTAINERID=container_1376154442901_0010_01_000032
2013-08-10 17:24:05,864 INFO org.apache.hadoop.yarn.server.resourcemanager.scheduler.common.fica.FiCaSchedulerNode: Assigned container container_1376154442901_0010_01_000032 of capacity <memory:1024, vCores:1> on host hadoop-220-4:35716, which currently has 6 containers, <memory:7168, vCores:6> used and <memory:1024, vCores:10> available
2013-08-10 17:24:05,865 INFO org.apache.hadoop.yarn.server.resourcemanager.scheduler.capacity.LeafQueue: assignedContainer application=application_1376154442901_0010 container=Container: [ContainerId: container_1376154442901_0010_01_000032, NodeId: hadoop-220-4:35716, NodeHttpAddress: hadoop-220-4:8042, Resource: <memory:1024, vCores:1>, Priority: 20, State: NEW, Token: null, Status: container_id {, app_attempt_id {, application_id {, id: 10, cluster_timestamp: 1376154442901, }, attemptId: 1, }, id: 32, }, state: C_NEW, ] containerId=container_1376154442901_0010_01_000032 queue=default: capacity=1.0, absoluteCapacity=1.0, usedResources=<memory:40960, vCores:35>usedCapacity=0.8333333, absoluteUsedCapacity=0.8333333, numApps=5, numContainers=35 usedCapacity=0.8333333 absoluteUsedCapacity=0.8333333 used=<memory:40960, vCores:35> cluster=<memory:49152, vCores:96>
2013-08-10 17:24:05,865 INFO org.apache.hadoop.yarn.server.resourcemanager.scheduler.capacity.ParentQueue: Re-sorting queues since queue: root.default stats: default: capacity=1.0, absoluteCapacity=1.0, usedResources=<memory:41984, vCores:36>usedCapacity=0.8541667, absoluteUsedCapacity=0.8541667, numApps=5, numContainers=36
2013-08-10 17:24:05,865 INFO org.apache.hadoop.yarn.server.resourcemanager.scheduler.capacity.ParentQueue: assignedContainer queue=root usedCapacity=0.8541667 absoluteUsedCapacity=0.8541667 used=<memory:41984, vCores:36> cluster=<memory:49152, vCores:96>
2013-08-10 17:24:05,866 INFO org.apache.hadoop.yarn.server.resourcemanager.rmcontainer.RMContainerImpl: container_1376154442901_0010_01_000033 Container Transitioned from NEW to ALLOCATED
2013-08-10 17:24:05,866 INFO org.apache.hadoop.yarn.server.resourcemanager.RMAuditLogger: USER=ubuntu	OPERATION=AM Allocated Container	TARGET=SchedulerApp	RESULT=SUCCESS	APPID=application_1376154442901_0010	CONTAINERID=container_1376154442901_0010_01_000033
2013-08-10 17:24:05,866 INFO org.apache.hadoop.yarn.server.resourcemanager.scheduler.common.fica.FiCaSchedulerNode: Assigned container container_1376154442901_0010_01_000033 of capacity <memory:1024, vCores:1> on host hadoop-220-4:35716, which currently has 7 containers, <memory:8192, vCores:7> used and <memory:0, vCores:9> available
2013-08-10 17:24:05,867 INFO org.apache.hadoop.yarn.server.resourcemanager.scheduler.capacity.LeafQueue: assignedContainer application=application_1376154442901_0010 container=Container: [ContainerId: container_1376154442901_0010_01_000033, NodeId: hadoop-220-4:35716, NodeHttpAddress: hadoop-220-4:8042, Resource: <memory:1024, vCores:1>, Priority: 20, State: NEW, Token: null, Status: container_id {, app_attempt_id {, application_id {, id: 10, cluster_timestamp: 1376154442901, }, attemptId: 1, }, id: 33, }, state: C_NEW, ] containerId=container_1376154442901_0010_01_000033 queue=default: capacity=1.0, absoluteCapacity=1.0, usedResources=<memory:41984, vCores:36>usedCapacity=0.8541667, absoluteUsedCapacity=0.8541667, numApps=5, numContainers=36 usedCapacity=0.8541667 absoluteUsedCapacity=0.8541667 used=<memory:41984, vCores:36> cluster=<memory:49152, vCores:96>
2013-08-10 17:24:05,867 INFO org.apache.hadoop.yarn.server.resourcemanager.scheduler.capacity.ParentQueue: Re-sorting queues since queue: root.default stats: default: capacity=1.0, absoluteCapacity=1.0, usedResources=<memory:43008, vCores:37>usedCapacity=0.875, absoluteUsedCapacity=0.875, numApps=5, numContainers=37
2013-08-10 17:24:05,867 INFO org.apache.hadoop.yarn.server.resourcemanager.scheduler.capacity.ParentQueue: assignedContainer queue=root usedCapacity=0.875 absoluteUsedCapacity=0.875 used=<memory:43008, vCores:37> cluster=<memory:49152, vCores:96>
2013-08-10 17:24:05,892 INFO org.apache.hadoop.yarn.server.resourcemanager.rmcontainer.RMContainerImpl: container_1376154442901_0010_01_000034 Container Transitioned from NEW to ALLOCATED
2013-08-10 17:24:05,892 INFO org.apache.hadoop.yarn.server.resourcemanager.RMAuditLogger: USER=ubuntu	OPERATION=AM Allocated Container	TARGET=SchedulerApp	RESULT=SUCCESS	APPID=application_1376154442901_0010	CONTAINERID=container_1376154442901_0010_01_000034
2013-08-10 17:24:05,892 INFO org.apache.hadoop.yarn.server.resourcemanager.scheduler.common.fica.FiCaSchedulerNode: Assigned container container_1376154442901_0010_01_000034 of capacity <memory:1024, vCores:1> on host hadoop-220-5:59721, which currently has 2 containers, <memory:3072, vCores:2> used and <memory:5120, vCores:14> available
2013-08-10 17:24:05,893 INFO org.apache.hadoop.yarn.server.resourcemanager.scheduler.capacity.LeafQueue: assignedContainer application=application_1376154442901_0010 container=Container: [ContainerId: container_1376154442901_0010_01_000034, NodeId: hadoop-220-5:59721, NodeHttpAddress: hadoop-220-5:8042, Resource: <memory:1024, vCores:1>, Priority: 20, State: NEW, Token: null, Status: container_id {, app_attempt_id {, application_id {, id: 10, cluster_timestamp: 1376154442901, }, attemptId: 1, }, id: 34, }, state: C_NEW, ] containerId=container_1376154442901_0010_01_000034 queue=default: capacity=1.0, absoluteCapacity=1.0, usedResources=<memory:43008, vCores:37>usedCapacity=0.875, absoluteUsedCapacity=0.875, numApps=5, numContainers=37 usedCapacity=0.875 absoluteUsedCapacity=0.875 used=<memory:43008, vCores:37> cluster=<memory:49152, vCores:96>
2013-08-10 17:24:05,893 INFO org.apache.hadoop.yarn.server.resourcemanager.scheduler.capacity.ParentQueue: Re-sorting queues since queue: root.default stats: default: capacity=1.0, absoluteCapacity=1.0, usedResources=<memory:44032, vCores:38>usedCapacity=0.8958333, absoluteUsedCapacity=0.8958333, numApps=5, numContainers=38
2013-08-10 17:24:05,893 INFO org.apache.hadoop.yarn.server.resourcemanager.scheduler.capacity.ParentQueue: assignedContainer queue=root usedCapacity=0.8958333 absoluteUsedCapacity=0.8958333 used=<memory:44032, vCores:38> cluster=<memory:49152, vCores:96>
2013-08-10 17:24:05,894 INFO org.apache.hadoop.yarn.server.resourcemanager.rmcontainer.RMContainerImpl: container_1376154442901_0010_01_000035 Container Transitioned from NEW to ALLOCATED
2013-08-10 17:24:05,894 INFO org.apache.hadoop.yarn.server.resourcemanager.RMAuditLogger: USER=ubuntu	OPERATION=AM Allocated Container	TARGET=SchedulerApp	RESULT=SUCCESS	APPID=application_1376154442901_0010	CONTAINERID=container_1376154442901_0010_01_000035
2013-08-10 17:24:05,894 INFO org.apache.hadoop.yarn.server.resourcemanager.scheduler.common.fica.FiCaSchedulerNode: Assigned container container_1376154442901_0010_01_000035 of capacity <memory:1024, vCores:1> on host hadoop-220-5:59721, which currently has 3 containers, <memory:4096, vCores:3> used and <memory:4096, vCores:13> available
2013-08-10 17:24:05,895 INFO org.apache.hadoop.yarn.server.resourcemanager.scheduler.capacity.LeafQueue: assignedContainer application=application_1376154442901_0010 container=Container: [ContainerId: container_1376154442901_0010_01_000035, NodeId: hadoop-220-5:59721, NodeHttpAddress: hadoop-220-5:8042, Resource: <memory:1024, vCores:1>, Priority: 20, State: NEW, Token: null, Status: container_id {, app_attempt_id {, application_id {, id: 10, cluster_timestamp: 1376154442901, }, attemptId: 1, }, id: 35, }, state: C_NEW, ] containerId=container_1376154442901_0010_01_000035 queue=default: capacity=1.0, absoluteCapacity=1.0, usedResources=<memory:44032, vCores:38>usedCapacity=0.8958333, absoluteUsedCapacity=0.8958333, numApps=5, numContainers=38 usedCapacity=0.8958333 absoluteUsedCapacity=0.8958333 used=<memory:44032, vCores:38> cluster=<memory:49152, vCores:96>
2013-08-10 17:24:05,895 INFO org.apache.hadoop.yarn.server.resourcemanager.scheduler.capacity.ParentQueue: Re-sorting queues since queue: root.default stats: default: capacity=1.0, absoluteCapacity=1.0, usedResources=<memory:45056, vCores:39>usedCapacity=0.9166667, absoluteUsedCapacity=0.9166667, numApps=5, numContainers=39
2013-08-10 17:24:05,895 INFO org.apache.hadoop.yarn.server.resourcemanager.scheduler.capacity.ParentQueue: assignedContainer queue=root usedCapacity=0.9166667 absoluteUsedCapacity=0.9166667 used=<memory:45056, vCores:39> cluster=<memory:49152, vCores:96>
2013-08-10 17:24:05,896 INFO org.apache.hadoop.yarn.server.resourcemanager.rmcontainer.RMContainerImpl: container_1376154442901_0010_01_000036 Container Transitioned from NEW to ALLOCATED
2013-08-10 17:24:05,896 INFO org.apache.hadoop.yarn.server.resourcemanager.RMAuditLogger: USER=ubuntu	OPERATION=AM Allocated Container	TARGET=SchedulerApp	RESULT=SUCCESS	APPID=application_1376154442901_0010	CONTAINERID=container_1376154442901_0010_01_000036
2013-08-10 17:24:05,896 INFO org.apache.hadoop.yarn.server.resourcemanager.scheduler.common.fica.FiCaSchedulerNode: Assigned container container_1376154442901_0010_01_000036 of capacity <memory:1024, vCores:1> on host hadoop-220-5:59721, which currently has 4 containers, <memory:5120, vCores:4> used and <memory:3072, vCores:12> available
2013-08-10 17:24:05,897 INFO org.apache.hadoop.yarn.server.resourcemanager.scheduler.capacity.LeafQueue: assignedContainer application=application_1376154442901_0010 container=Container: [ContainerId: container_1376154442901_0010_01_000036, NodeId: hadoop-220-5:59721, NodeHttpAddress: hadoop-220-5:8042, Resource: <memory:1024, vCores:1>, Priority: 20, State: NEW, Token: null, Status: container_id {, app_attempt_id {, application_id {, id: 10, cluster_timestamp: 1376154442901, }, attemptId: 1, }, id: 36, }, state: C_NEW, ] containerId=container_1376154442901_0010_01_000036 queue=default: capacity=1.0, absoluteCapacity=1.0, usedResources=<memory:45056, vCores:39>usedCapacity=0.9166667, absoluteUsedCapacity=0.9166667, numApps=5, numContainers=39 usedCapacity=0.9166667 absoluteUsedCapacity=0.9166667 used=<memory:45056, vCores:39> cluster=<memory:49152, vCores:96>
2013-08-10 17:24:05,897 INFO org.apache.hadoop.yarn.server.resourcemanager.scheduler.capacity.ParentQueue: Re-sorting queues since queue: root.default stats: default: capacity=1.0, absoluteCapacity=1.0, usedResources=<memory:46080, vCores:40>usedCapacity=0.9375, absoluteUsedCapacity=0.9375, numApps=5, numContainers=40
2013-08-10 17:24:05,898 INFO org.apache.hadoop.yarn.server.resourcemanager.scheduler.capacity.ParentQueue: assignedContainer queue=root usedCapacity=0.9375 absoluteUsedCapacity=0.9375 used=<memory:46080, vCores:40> cluster=<memory:49152, vCores:96>
2013-08-10 17:24:05,898 INFO org.apache.hadoop.yarn.server.resourcemanager.rmcontainer.RMContainerImpl: container_1376154442901_0010_01_000037 Container Transitioned from NEW to ALLOCATED
2013-08-10 17:24:05,898 INFO org.apache.hadoop.yarn.server.resourcemanager.RMAuditLogger: USER=ubuntu	OPERATION=AM Allocated Container	TARGET=SchedulerApp	RESULT=SUCCESS	APPID=application_1376154442901_0010	CONTAINERID=container_1376154442901_0010_01_000037
2013-08-10 17:24:05,898 INFO org.apache.hadoop.yarn.server.resourcemanager.scheduler.common.fica.FiCaSchedulerNode: Assigned container container_1376154442901_0010_01_000037 of capacity <memory:1024, vCores:1> on host hadoop-220-5:59721, which currently has 5 containers, <memory:6144, vCores:5> used and <memory:2048, vCores:11> available
2013-08-10 17:24:05,899 INFO org.apache.hadoop.yarn.server.resourcemanager.scheduler.capacity.LeafQueue: assignedContainer application=application_1376154442901_0010 container=Container: [ContainerId: container_1376154442901_0010_01_000037, NodeId: hadoop-220-5:59721, NodeHttpAddress: hadoop-220-5:8042, Resource: <memory:1024, vCores:1>, Priority: 20, State: NEW, Token: null, Status: container_id {, app_attempt_id {, application_id {, id: 10, cluster_timestamp: 1376154442901, }, attemptId: 1, }, id: 37, }, state: C_NEW, ] containerId=container_1376154442901_0010_01_000037 queue=default: capacity=1.0, absoluteCapacity=1.0, usedResources=<memory:46080, vCores:40>usedCapacity=0.9375, absoluteUsedCapacity=0.9375, numApps=5, numContainers=40 usedCapacity=0.9375 absoluteUsedCapacity=0.9375 used=<memory:46080, vCores:40> cluster=<memory:49152, vCores:96>
2013-08-10 17:24:05,899 INFO org.apache.hadoop.yarn.server.resourcemanager.scheduler.capacity.ParentQueue: Re-sorting queues since queue: root.default stats: default: capacity=1.0, absoluteCapacity=1.0, usedResources=<memory:47104, vCores:41>usedCapacity=0.9583333, absoluteUsedCapacity=0.9583333, numApps=5, numContainers=41
2013-08-10 17:24:05,900 INFO org.apache.hadoop.yarn.server.resourcemanager.scheduler.capacity.ParentQueue: assignedContainer queue=root usedCapacity=0.9583333 absoluteUsedCapacity=0.9583333 used=<memory:47104, vCores:41> cluster=<memory:49152, vCores:96>
2013-08-10 17:24:05,900 INFO org.apache.hadoop.yarn.server.resourcemanager.rmcontainer.RMContainerImpl: container_1376154442901_0010_01_000038 Container Transitioned from NEW to ALLOCATED
2013-08-10 17:24:05,900 INFO org.apache.hadoop.yarn.server.resourcemanager.RMAuditLogger: USER=ubuntu	OPERATION=AM Allocated Container	TARGET=SchedulerApp	RESULT=SUCCESS	APPID=application_1376154442901_0010	CONTAINERID=container_1376154442901_0010_01_000038
2013-08-10 17:24:05,900 INFO org.apache.hadoop.yarn.server.resourcemanager.scheduler.common.fica.FiCaSchedulerNode: Assigned container container_1376154442901_0010_01_000038 of capacity <memory:1024, vCores:1> on host hadoop-220-5:59721, which currently has 6 containers, <memory:7168, vCores:6> used and <memory:1024, vCores:10> available
2013-08-10 17:24:05,901 INFO org.apache.hadoop.yarn.server.resourcemanager.scheduler.capacity.LeafQueue: assignedContainer application=application_1376154442901_0010 container=Container: [ContainerId: container_1376154442901_0010_01_000038, NodeId: hadoop-220-5:59721, NodeHttpAddress: hadoop-220-5:8042, Resource: <memory:1024, vCores:1>, Priority: 20, State: NEW, Token: null, Status: container_id {, app_attempt_id {, application_id {, id: 10, cluster_timestamp: 1376154442901, }, attemptId: 1, }, id: 38, }, state: C_NEW, ] containerId=container_1376154442901_0010_01_000038 queue=default: capacity=1.0, absoluteCapacity=1.0, usedResources=<memory:47104, vCores:41>usedCapacity=0.9583333, absoluteUsedCapacity=0.9583333, numApps=5, numContainers=41 usedCapacity=0.9583333 absoluteUsedCapacity=0.9583333 used=<memory:47104, vCores:41> cluster=<memory:49152, vCores:96>
2013-08-10 17:24:05,901 INFO org.apache.hadoop.yarn.server.resourcemanager.scheduler.capacity.ParentQueue: Re-sorting queues since queue: root.default stats: default: capacity=1.0, absoluteCapacity=1.0, usedResources=<memory:48128, vCores:42>usedCapacity=0.9791667, absoluteUsedCapacity=0.9791667, numApps=5, numContainers=42
2013-08-10 17:24:05,902 INFO org.apache.hadoop.yarn.server.resourcemanager.scheduler.capacity.ParentQueue: assignedContainer queue=root usedCapacity=0.9791667 absoluteUsedCapacity=0.9791667 used=<memory:48128, vCores:42> cluster=<memory:49152, vCores:96>
2013-08-10 17:24:05,902 INFO org.apache.hadoop.yarn.server.resourcemanager.rmcontainer.RMContainerImpl: container_1376154442901_0010_01_000039 Container Transitioned from NEW to ALLOCATED
2013-08-10 17:24:05,902 INFO org.apache.hadoop.yarn.server.resourcemanager.RMAuditLogger: USER=ubuntu	OPERATION=AM Allocated Container	TARGET=SchedulerApp	RESULT=SUCCESS	APPID=application_1376154442901_0010	CONTAINERID=container_1376154442901_0010_01_000039
2013-08-10 17:24:05,902 INFO org.apache.hadoop.yarn.server.resourcemanager.scheduler.common.fica.FiCaSchedulerNode: Assigned container container_1376154442901_0010_01_000039 of capacity <memory:1024, vCores:1> on host hadoop-220-5:59721, which currently has 7 containers, <memory:8192, vCores:7> used and <memory:0, vCores:9> available
2013-08-10 17:24:05,903 INFO org.apache.hadoop.yarn.server.resourcemanager.scheduler.capacity.LeafQueue: assignedContainer application=application_1376154442901_0010 container=Container: [ContainerId: container_1376154442901_0010_01_000039, NodeId: hadoop-220-5:59721, NodeHttpAddress: hadoop-220-5:8042, Resource: <memory:1024, vCores:1>, Priority: 20, State: NEW, Token: null, Status: container_id {, app_attempt_id {, application_id {, id: 10, cluster_timestamp: 1376154442901, }, attemptId: 1, }, id: 39, }, state: C_NEW, ] containerId=container_1376154442901_0010_01_000039 queue=default: capacity=1.0, absoluteCapacity=1.0, usedResources=<memory:48128, vCores:42>usedCapacity=0.9791667, absoluteUsedCapacity=0.9791667, numApps=5, numContainers=42 usedCapacity=0.9791667 absoluteUsedCapacity=0.9791667 used=<memory:48128, vCores:42> cluster=<memory:49152, vCores:96>
2013-08-10 17:24:05,904 INFO org.apache.hadoop.yarn.server.resourcemanager.scheduler.capacity.ParentQueue: Re-sorting queues since queue: root.default stats: default: capacity=1.0, absoluteCapacity=1.0, usedResources=<memory:49152, vCores:43>usedCapacity=1.0, absoluteUsedCapacity=1.0, numApps=5, numContainers=43
2013-08-10 17:24:05,904 INFO org.apache.hadoop.yarn.server.resourcemanager.scheduler.capacity.ParentQueue: assignedContainer queue=root usedCapacity=1.0 absoluteUsedCapacity=1.0 used=<memory:49152, vCores:43> cluster=<memory:49152, vCores:96>
2013-08-10 17:24:05,997 INFO org.apache.hadoop.yarn.server.resourcemanager.rmcontainer.RMContainerImpl: container_1376154442901_0010_01_000002 Container Transitioned from ALLOCATED to ACQUIRED
2013-08-10 17:24:05,999 INFO org.apache.hadoop.yarn.server.resourcemanager.rmcontainer.RMContainerImpl: container_1376154442901_0010_01_000003 Container Transitioned from ALLOCATED to ACQUIRED
2013-08-10 17:24:06,000 INFO org.apache.hadoop.yarn.server.resourcemanager.rmcontainer.RMContainerImpl: container_1376154442901_0010_01_000004 Container Transitioned from ALLOCATED to ACQUIRED
2013-08-10 17:24:06,001 INFO org.apache.hadoop.yarn.server.resourcemanager.rmcontainer.RMContainerImpl: container_1376154442901_0010_01_000005 Container Transitioned from ALLOCATED to ACQUIRED
2013-08-10 17:24:06,002 INFO org.apache.hadoop.yarn.server.resourcemanager.rmcontainer.RMContainerImpl: container_1376154442901_0010_01_000006 Container Transitioned from ALLOCATED to ACQUIRED
2013-08-10 17:24:06,003 INFO org.apache.hadoop.yarn.server.resourcemanager.rmcontainer.RMContainerImpl: container_1376154442901_0010_01_000007 Container Transitioned from ALLOCATED to ACQUIRED
2013-08-10 17:24:06,004 INFO org.apache.hadoop.yarn.server.resourcemanager.rmcontainer.RMContainerImpl: container_1376154442901_0010_01_000008 Container Transitioned from ALLOCATED to ACQUIRED
2013-08-10 17:24:06,006 INFO org.apache.hadoop.yarn.server.resourcemanager.rmcontainer.RMContainerImpl: container_1376154442901_0010_01_000009 Container Transitioned from ALLOCATED to ACQUIRED
2013-08-10 17:24:06,007 INFO org.apache.hadoop.yarn.server.resourcemanager.rmcontainer.RMContainerImpl: container_1376154442901_0010_01_000010 Container Transitioned from ALLOCATED to ACQUIRED
2013-08-10 17:24:06,009 INFO org.apache.hadoop.yarn.server.resourcemanager.rmcontainer.RMContainerImpl: container_1376154442901_0010_01_000011 Container Transitioned from ALLOCATED to ACQUIRED
2013-08-10 17:24:06,011 INFO org.apache.hadoop.yarn.server.resourcemanager.rmcontainer.RMContainerImpl: container_1376154442901_0010_01_000012 Container Transitioned from ALLOCATED to ACQUIRED
2013-08-10 17:24:06,011 INFO org.apache.hadoop.yarn.server.resourcemanager.rmcontainer.RMContainerImpl: container_1376154442901_0010_01_000013 Container Transitioned from ALLOCATED to ACQUIRED
2013-08-10 17:24:06,012 INFO org.apache.hadoop.yarn.server.resourcemanager.rmcontainer.RMContainerImpl: container_1376154442901_0010_01_000014 Container Transitioned from ALLOCATED to ACQUIRED
2013-08-10 17:24:06,012 INFO org.apache.hadoop.yarn.server.resourcemanager.rmcontainer.RMContainerImpl: container_1376154442901_0010_01_000015 Container Transitioned from ALLOCATED to ACQUIRED
2013-08-10 17:24:06,013 INFO org.apache.hadoop.yarn.server.resourcemanager.rmcontainer.RMContainerImpl: container_1376154442901_0010_01_000016 Container Transitioned from ALLOCATED to ACQUIRED
2013-08-10 17:24:06,014 INFO org.apache.hadoop.yarn.server.resourcemanager.rmcontainer.RMContainerImpl: container_1376154442901_0010_01_000017 Container Transitioned from ALLOCATED to ACQUIRED
2013-08-10 17:24:06,014 INFO org.apache.hadoop.yarn.server.resourcemanager.rmcontainer.RMContainerImpl: container_1376154442901_0010_01_000018 Container Transitioned from ALLOCATED to ACQUIRED
2013-08-10 17:24:06,015 INFO org.apache.hadoop.yarn.server.resourcemanager.rmcontainer.RMContainerImpl: container_1376154442901_0010_01_000019 Container Transitioned from ALLOCATED to ACQUIRED
2013-08-10 17:24:06,015 INFO org.apache.hadoop.yarn.server.resourcemanager.rmcontainer.RMContainerImpl: container_1376154442901_0010_01_000020 Container Transitioned from ALLOCATED to ACQUIRED
2013-08-10 17:24:06,017 INFO org.apache.hadoop.yarn.server.resourcemanager.rmcontainer.RMContainerImpl: container_1376154442901_0010_01_000021 Container Transitioned from ALLOCATED to ACQUIRED
2013-08-10 17:24:06,018 INFO org.apache.hadoop.yarn.server.resourcemanager.rmcontainer.RMContainerImpl: container_1376154442901_0010_01_000022 Container Transitioned from ALLOCATED to ACQUIRED
2013-08-10 17:24:06,018 INFO org.apache.hadoop.yarn.server.resourcemanager.rmcontainer.RMContainerImpl: container_1376154442901_0010_01_000023 Container Transitioned from ALLOCATED to ACQUIRED
2013-08-10 17:24:06,018 INFO org.apache.hadoop.yarn.server.resourcemanager.rmcontainer.RMContainerImpl: container_1376154442901_0010_01_000024 Container Transitioned from ALLOCATED to ACQUIRED
2013-08-10 17:24:06,018 INFO org.apache.hadoop.yarn.server.resourcemanager.rmcontainer.RMContainerImpl: container_1376154442901_0010_01_000025 Container Transitioned from ALLOCATED to ACQUIRED
2013-08-10 17:24:06,018 INFO org.apache.hadoop.yarn.server.resourcemanager.rmcontainer.RMContainerImpl: container_1376154442901_0010_01_000026 Container Transitioned from ALLOCATED to ACQUIRED
2013-08-10 17:24:06,018 INFO org.apache.hadoop.yarn.server.resourcemanager.rmcontainer.RMContainerImpl: container_1376154442901_0010_01_000027 Container Transitioned from ALLOCATED to ACQUIRED
2013-08-10 17:24:06,019 INFO org.apache.hadoop.yarn.server.resourcemanager.rmcontainer.RMContainerImpl: container_1376154442901_0010_01_000028 Container Transitioned from ALLOCATED to ACQUIRED
2013-08-10 17:24:06,019 INFO org.apache.hadoop.yarn.server.resourcemanager.rmcontainer.RMContainerImpl: container_1376154442901_0010_01_000029 Container Transitioned from ALLOCATED to ACQUIRED
2013-08-10 17:24:06,019 INFO org.apache.hadoop.yarn.server.resourcemanager.rmcontainer.RMContainerImpl: container_1376154442901_0010_01_000030 Container Transitioned from ALLOCATED to ACQUIRED
2013-08-10 17:24:06,019 INFO org.apache.hadoop.yarn.server.resourcemanager.rmcontainer.RMContainerImpl: container_1376154442901_0010_01_000031 Container Transitioned from ALLOCATED to ACQUIRED
2013-08-10 17:24:06,019 INFO org.apache.hadoop.yarn.server.resourcemanager.rmcontainer.RMContainerImpl: container_1376154442901_0010_01_000032 Container Transitioned from ALLOCATED to ACQUIRED
2013-08-10 17:24:06,019 INFO org.apache.hadoop.yarn.server.resourcemanager.rmcontainer.RMContainerImpl: container_1376154442901_0010_01_000033 Container Transitioned from ALLOCATED to ACQUIRED
2013-08-10 17:24:06,020 INFO org.apache.hadoop.yarn.server.resourcemanager.rmcontainer.RMContainerImpl: container_1376154442901_0010_01_000034 Container Transitioned from ALLOCATED to ACQUIRED
2013-08-10 17:24:06,020 INFO org.apache.hadoop.yarn.server.resourcemanager.rmcontainer.RMContainerImpl: container_1376154442901_0010_01_000035 Container Transitioned from ALLOCATED to ACQUIRED
2013-08-10 17:24:06,020 INFO org.apache.hadoop.yarn.server.resourcemanager.rmcontainer.RMContainerImpl: container_1376154442901_0010_01_000036 Container Transitioned from ALLOCATED to ACQUIRED
2013-08-10 17:24:06,020 INFO org.apache.hadoop.yarn.server.resourcemanager.rmcontainer.RMContainerImpl: container_1376154442901_0010_01_000037 Container Transitioned from ALLOCATED to ACQUIRED
2013-08-10 17:24:06,020 INFO org.apache.hadoop.yarn.server.resourcemanager.rmcontainer.RMContainerImpl: container_1376154442901_0010_01_000038 Container Transitioned from ALLOCATED to ACQUIRED
2013-08-10 17:24:06,021 INFO org.apache.hadoop.yarn.server.resourcemanager.rmcontainer.RMContainerImpl: container_1376154442901_0010_01_000039 Container Transitioned from ALLOCATED to ACQUIRED
2013-08-10 17:24:06,146 INFO org.apache.hadoop.yarn.server.resourcemanager.ApplicationMasterService: AM registration appattempt_1376154442901_0007_000001
2013-08-10 17:24:06,147 INFO org.apache.hadoop.yarn.server.resourcemanager.RMAuditLogger: USER=ubuntu	IP=192.168.100.32	OPERATION=Register App Master	TARGET=ApplicationMasterService	RESULT=SUCCESS	APPID=application_1376154442901_0007	APPATTEMPTID=appattempt_1376154442901_0007_000001
2013-08-10 17:24:06,147 INFO org.apache.hadoop.yarn.server.resourcemanager.rmapp.attempt.RMAppAttemptImpl: appattempt_1376154442901_0007_000001 State change from LAUNCHED to RUNNING
2013-08-10 17:24:06,148 INFO org.apache.hadoop.yarn.server.resourcemanager.rmapp.RMAppImpl: application_1376154442901_0007 State change from ACCEPTED to RUNNING
2013-08-10 17:24:06,202 INFO org.apache.hadoop.yarn.server.resourcemanager.ApplicationMasterService: AM registration appattempt_1376154442901_0009_000001
2013-08-10 17:24:06,202 INFO org.apache.hadoop.yarn.server.resourcemanager.RMAuditLogger: USER=ubuntu	IP=192.168.100.19	OPERATION=Register App Master	TARGET=ApplicationMasterService	RESULT=SUCCESS	APPID=application_1376154442901_0009	APPATTEMPTID=appattempt_1376154442901_0009_000001
2013-08-10 17:24:06,204 INFO org.apache.hadoop.yarn.server.resourcemanager.rmapp.attempt.RMAppAttemptImpl: appattempt_1376154442901_0009_000001 State change from LAUNCHED to RUNNING
2013-08-10 17:24:06,204 INFO org.apache.hadoop.yarn.server.resourcemanager.rmapp.RMAppImpl: application_1376154442901_0009 State change from ACCEPTED to RUNNING
2013-08-10 17:24:06,834 INFO org.apache.hadoop.yarn.server.resourcemanager.ApplicationMasterService: AM registration appattempt_1376154442901_0006_000001
2013-08-10 17:24:06,834 INFO org.apache.hadoop.yarn.server.resourcemanager.RMAuditLogger: USER=ubuntu	IP=192.168.100.35	OPERATION=Register App Master	TARGET=ApplicationMasterService	RESULT=SUCCESS	APPID=application_1376154442901_0006	APPATTEMPTID=appattempt_1376154442901_0006_000001
2013-08-10 17:24:06,835 INFO org.apache.hadoop.yarn.server.resourcemanager.rmapp.attempt.RMAppAttemptImpl: appattempt_1376154442901_0006_000001 State change from LAUNCHED to RUNNING
2013-08-10 17:24:06,835 INFO org.apache.hadoop.yarn.server.resourcemanager.rmapp.RMAppImpl: application_1376154442901_0006 State change from ACCEPTED to RUNNING
2013-08-10 17:24:06,856 INFO org.apache.hadoop.yarn.server.resourcemanager.rmcontainer.RMContainerImpl: container_1376154442901_0010_01_000022 Container Transitioned from ACQUIRED to RUNNING
2013-08-10 17:24:06,857 INFO org.apache.hadoop.yarn.server.resourcemanager.rmcontainer.RMContainerImpl: container_1376154442901_0010_01_000023 Container Transitioned from ACQUIRED to RUNNING
2013-08-10 17:24:06,858 INFO org.apache.hadoop.yarn.server.resourcemanager.rmcontainer.RMContainerImpl: container_1376154442901_0010_01_000024 Container Transitioned from ACQUIRED to RUNNING
2013-08-10 17:24:06,858 INFO org.apache.hadoop.yarn.server.resourcemanager.rmcontainer.RMContainerImpl: container_1376154442901_0010_01_000025 Container Transitioned from ACQUIRED to RUNNING
2013-08-10 17:24:06,859 INFO org.apache.hadoop.yarn.server.resourcemanager.rmcontainer.RMContainerImpl: container_1376154442901_0010_01_000026 Container Transitioned from ACQUIRED to RUNNING
2013-08-10 17:24:06,860 INFO org.apache.hadoop.yarn.server.resourcemanager.rmcontainer.RMContainerImpl: container_1376154442901_0010_01_000027 Container Transitioned from ACQUIRED to RUNNING
2013-08-10 17:24:06,870 INFO org.apache.hadoop.yarn.server.resourcemanager.rmcontainer.RMContainerImpl: container_1376154442901_0010_01_000028 Container Transitioned from ACQUIRED to RUNNING
2013-08-10 17:24:06,871 INFO org.apache.hadoop.yarn.server.resourcemanager.rmcontainer.RMContainerImpl: container_1376154442901_0010_01_000029 Container Transitioned from ACQUIRED to RUNNING
2013-08-10 17:24:06,872 INFO org.apache.hadoop.yarn.server.resourcemanager.rmcontainer.RMContainerImpl: container_1376154442901_0010_01_000030 Container Transitioned from ACQUIRED to RUNNING
2013-08-10 17:24:06,874 INFO org.apache.hadoop.yarn.server.resourcemanager.rmcontainer.RMContainerImpl: container_1376154442901_0010_01_000031 Container Transitioned from ACQUIRED to RUNNING
2013-08-10 17:24:06,874 INFO org.apache.hadoop.yarn.server.resourcemanager.rmcontainer.RMContainerImpl: container_1376154442901_0010_01_000032 Container Transitioned from ACQUIRED to RUNNING
2013-08-10 17:24:06,875 INFO org.apache.hadoop.yarn.server.resourcemanager.rmcontainer.RMContainerImpl: container_1376154442901_0010_01_000033 Container Transitioned from ACQUIRED to RUNNING
2013-08-10 17:24:06,922 INFO org.apache.hadoop.yarn.server.resourcemanager.rmcontainer.RMContainerImpl: container_1376154442901_0010_01_000034 Container Transitioned from ACQUIRED to RUNNING
2013-08-10 17:24:06,922 INFO org.apache.hadoop.yarn.server.resourcemanager.rmcontainer.RMContainerImpl: container_1376154442901_0010_01_000035 Container Transitioned from ACQUIRED to RUNNING
2013-08-10 17:24:06,923 INFO org.apache.hadoop.yarn.server.resourcemanager.rmcontainer.RMContainerImpl: container_1376154442901_0010_01_000036 Container Transitioned from ACQUIRED to RUNNING
2013-08-10 17:24:06,923 INFO org.apache.hadoop.yarn.server.resourcemanager.rmcontainer.RMContainerImpl: container_1376154442901_0010_01_000037 Container Transitioned from ACQUIRED to RUNNING
2013-08-10 17:24:06,924 INFO org.apache.hadoop.yarn.server.resourcemanager.rmcontainer.RMContainerImpl: container_1376154442901_0010_01_000038 Container Transitioned from ACQUIRED to RUNNING
2013-08-10 17:24:06,924 INFO org.apache.hadoop.yarn.server.resourcemanager.rmcontainer.RMContainerImpl: container_1376154442901_0010_01_000039 Container Transitioned from ACQUIRED to RUNNING
2013-08-10 17:24:06,971 INFO org.apache.hadoop.yarn.server.resourcemanager.ApplicationMasterService: AM registration appattempt_1376154442901_0008_000001
2013-08-10 17:24:06,972 INFO org.apache.hadoop.yarn.server.resourcemanager.RMAuditLogger: USER=ubuntu	IP=192.168.100.33	OPERATION=Register App Master	TARGET=ApplicationMasterService	RESULT=SUCCESS	APPID=application_1376154442901_0008	APPATTEMPTID=appattempt_1376154442901_0008_000001
2013-08-10 17:24:06,973 INFO org.apache.hadoop.yarn.server.resourcemanager.rmapp.attempt.RMAppAttemptImpl: appattempt_1376154442901_0008_000001 State change from LAUNCHED to RUNNING
2013-08-10 17:24:06,973 INFO org.apache.hadoop.yarn.server.resourcemanager.rmapp.RMAppImpl: application_1376154442901_0008 State change from ACCEPTED to RUNNING
2013-08-10 17:24:07,324 INFO org.apache.hadoop.yarn.server.resourcemanager.rmcontainer.RMContainerImpl: container_1376154442901_0010_01_000002 Container Transitioned from ACQUIRED to RUNNING
2013-08-10 17:24:07,325 INFO org.apache.hadoop.yarn.server.resourcemanager.rmcontainer.RMContainerImpl: container_1376154442901_0010_01_000003 Container Transitioned from ACQUIRED to RUNNING
2013-08-10 17:24:07,325 INFO org.apache.hadoop.yarn.server.resourcemanager.rmcontainer.RMContainerImpl: container_1376154442901_0010_01_000004 Container Transitioned from ACQUIRED to RUNNING
2013-08-10 17:24:07,325 INFO org.apache.hadoop.yarn.server.resourcemanager.rmcontainer.RMContainerImpl: container_1376154442901_0010_01_000005 Container Transitioned from ACQUIRED to RUNNING
2013-08-10 17:24:07,325 INFO org.apache.hadoop.yarn.server.resourcemanager.rmcontainer.RMContainerImpl: container_1376154442901_0010_01_000006 Container Transitioned from ACQUIRED to RUNNING
2013-08-10 17:24:07,325 INFO org.apache.hadoop.yarn.server.resourcemanager.rmcontainer.RMContainerImpl: container_1376154442901_0010_01_000007 Container Transitioned from ACQUIRED to RUNNING
2013-08-10 17:24:07,348 INFO org.apache.hadoop.yarn.server.resourcemanager.rmcontainer.RMContainerImpl: container_1376154442901_0010_01_000008 Container Transitioned from ACQUIRED to RUNNING
2013-08-10 17:24:07,348 INFO org.apache.hadoop.yarn.server.resourcemanager.rmcontainer.RMContainerImpl: container_1376154442901_0010_01_000009 Container Transitioned from ACQUIRED to RUNNING
2013-08-10 17:24:07,348 INFO org.apache.hadoop.yarn.server.resourcemanager.rmcontainer.RMContainerImpl: container_1376154442901_0010_01_000010 Container Transitioned from ACQUIRED to RUNNING
2013-08-10 17:24:07,349 INFO org.apache.hadoop.yarn.server.resourcemanager.rmcontainer.RMContainerImpl: container_1376154442901_0010_01_000011 Container Transitioned from ACQUIRED to RUNNING
2013-08-10 17:24:07,351 INFO org.apache.hadoop.yarn.server.resourcemanager.rmcontainer.RMContainerImpl: container_1376154442901_0010_01_000012 Container Transitioned from ACQUIRED to RUNNING
2013-08-10 17:24:07,352 INFO org.apache.hadoop.yarn.server.resourcemanager.rmcontainer.RMContainerImpl: container_1376154442901_0010_01_000013 Container Transitioned from ACQUIRED to RUNNING
2013-08-10 17:24:07,352 INFO org.apache.hadoop.yarn.server.resourcemanager.rmcontainer.RMContainerImpl: container_1376154442901_0010_01_000014 Container Transitioned from ACQUIRED to RUNNING
2013-08-10 17:24:07,352 INFO org.apache.hadoop.yarn.server.resourcemanager.rmcontainer.RMContainerImpl: container_1376154442901_0010_01_000015 Container Transitioned from ACQUIRED to RUNNING
2013-08-10 17:24:07,352 INFO org.apache.hadoop.yarn.server.resourcemanager.rmcontainer.RMContainerImpl: container_1376154442901_0010_01_000016 Container Transitioned from ACQUIRED to RUNNING
2013-08-10 17:24:07,352 INFO org.apache.hadoop.yarn.server.resourcemanager.rmcontainer.RMContainerImpl: container_1376154442901_0010_01_000017 Container Transitioned from ACQUIRED to RUNNING
2013-08-10 17:24:07,353 INFO org.apache.hadoop.yarn.server.resourcemanager.rmcontainer.RMContainerImpl: container_1376154442901_0010_01_000018 Container Transitioned from ACQUIRED to RUNNING
2013-08-10 17:24:07,353 INFO org.apache.hadoop.yarn.server.resourcemanager.rmcontainer.RMContainerImpl: container_1376154442901_0010_01_000019 Container Transitioned from ACQUIRED to RUNNING
2013-08-10 17:24:07,353 INFO org.apache.hadoop.yarn.server.resourcemanager.rmcontainer.RMContainerImpl: container_1376154442901_0010_01_000020 Container Transitioned from ACQUIRED to RUNNING
2013-08-10 17:24:07,353 INFO org.apache.hadoop.yarn.server.resourcemanager.rmcontainer.RMContainerImpl: container_1376154442901_0010_01_000021 Container Transitioned from ACQUIRED to RUNNING
2013-08-10 17:24:29,599 INFO org.apache.hadoop.yarn.server.resourcemanager.rmcontainer.RMContainerImpl: container_1376154442901_0010_01_000029 Container Transitioned from RUNNING to COMPLETED
2013-08-10 17:24:29,599 INFO org.apache.hadoop.yarn.server.resourcemanager.scheduler.common.fica.FiCaSchedulerApp: Completed container: container_1376154442901_0010_01_000029 in state: COMPLETED event:FINISHED
2013-08-10 17:24:29,599 INFO org.apache.hadoop.yarn.server.resourcemanager.RMAuditLogger: USER=ubuntu	OPERATION=AM Released Container	TARGET=SchedulerApp	RESULT=SUCCESS	APPID=application_1376154442901_0010	CONTAINERID=container_1376154442901_0010_01_000029
2013-08-10 17:24:29,600 INFO org.apache.hadoop.yarn.server.resourcemanager.scheduler.common.fica.FiCaSchedulerNode: Released container container_1376154442901_0010_01_000029 of capacity <memory:1024, vCores:1> on host hadoop-220-4:35716, which currently has 6 containers, <memory:7168, vCores:6> used and <memory:1024, vCores:10> available, release resources=true
2013-08-10 17:24:29,600 INFO org.apache.hadoop.yarn.server.resourcemanager.scheduler.capacity.LeafQueue: default used=<memory:48128, vCores:42> numContainers=42 user=ubuntu user-resources=<memory:48128, vCores:42>
2013-08-10 17:24:29,603 INFO org.apache.hadoop.yarn.server.resourcemanager.scheduler.capacity.LeafQueue: completedContainer container=Container: [ContainerId: container_1376154442901_0010_01_000029, NodeId: hadoop-220-4:35716, NodeHttpAddress: hadoop-220-4:8042, Resource: <memory:1024, vCores:1>, Priority: 20, State: NEW, Token: null, Status: container_id {, app_attempt_id {, application_id {, id: 10, cluster_timestamp: 1376154442901, }, attemptId: 1, }, id: 29, }, state: C_COMPLETE, diagnostics: "Container killed by the ApplicationMaster.\n", exit_status: 0, ] resource=<memory:1024, vCores:1> queue=default: capacity=1.0, absoluteCapacity=1.0, usedResources=<memory:48128, vCores:42>usedCapacity=0.9791667, absoluteUsedCapacity=0.9791667, numApps=5, numContainers=42 usedCapacity=0.9791667 absoluteUsedCapacity=0.9791667 used=<memory:48128, vCores:42> cluster=<memory:49152, vCores:96>
2013-08-10 17:24:29,603 INFO org.apache.hadoop.yarn.server.resourcemanager.scheduler.capacity.ParentQueue: completedContainer queue=root usedCapacity=0.9791667 absoluteUsedCapacity=0.9791667 used=<memory:48128, vCores:42> cluster=<memory:49152, vCores:96>
2013-08-10 17:24:29,603 INFO org.apache.hadoop.yarn.server.resourcemanager.scheduler.capacity.CapacityScheduler: Application appattempt_1376154442901_0010_000001 released container container_1376154442901_0010_01_000029 on node: host: hadoop-220-4:35716 #containers=6 available=1024 used=7168 with event: FINISHED
2013-08-10 17:24:29,604 INFO org.apache.hadoop.yarn.server.resourcemanager.rmcontainer.RMContainerImpl: container_1376154442901_0006_01_000002 Container Transitioned from NEW to ALLOCATED
2013-08-10 17:24:29,604 INFO org.apache.hadoop.yarn.server.resourcemanager.RMAuditLogger: USER=ubuntu	OPERATION=AM Allocated Container	TARGET=SchedulerApp	RESULT=SUCCESS	APPID=application_1376154442901_0006	CONTAINERID=container_1376154442901_0006_01_000002
2013-08-10 17:24:29,604 INFO org.apache.hadoop.yarn.server.resourcemanager.scheduler.common.fica.FiCaSchedulerNode: Assigned container container_1376154442901_0006_01_000002 of capacity <memory:1024, vCores:1> on host hadoop-220-4:35716, which currently has 7 containers, <memory:8192, vCores:7> used and <memory:0, vCores:9> available
2013-08-10 17:24:29,605 INFO org.apache.hadoop.yarn.server.resourcemanager.scheduler.capacity.LeafQueue: assignedContainer application=application_1376154442901_0006 container=Container: [ContainerId: container_1376154442901_0006_01_000002, NodeId: hadoop-220-4:35716, NodeHttpAddress: hadoop-220-4:8042, Resource: <memory:1024, vCores:1>, Priority: 20, State: NEW, Token: null, Status: container_id {, app_attempt_id {, application_id {, id: 6, cluster_timestamp: 1376154442901, }, attemptId: 1, }, id: 2, }, state: C_NEW, ] containerId=container_1376154442901_0006_01_000002 queue=default: capacity=1.0, absoluteCapacity=1.0, usedResources=<memory:48128, vCores:42>usedCapacity=0.9791667, absoluteUsedCapacity=0.9791667, numApps=5, numContainers=42 usedCapacity=0.9791667 absoluteUsedCapacity=0.9791667 used=<memory:48128, vCores:42> cluster=<memory:49152, vCores:96>
2013-08-10 17:24:29,605 INFO org.apache.hadoop.yarn.server.resourcemanager.scheduler.capacity.ParentQueue: Re-sorting queues since queue: root.default stats: default: capacity=1.0, absoluteCapacity=1.0, usedResources=<memory:49152, vCores:43>usedCapacity=1.0, absoluteUsedCapacity=1.0, numApps=5, numContainers=43
2013-08-10 17:24:29,605 INFO org.apache.hadoop.yarn.server.resourcemanager.scheduler.capacity.ParentQueue: assignedContainer queue=root usedCapacity=1.0 absoluteUsedCapacity=1.0 used=<memory:49152, vCores:43> cluster=<memory:49152, vCores:96>
2013-08-10 17:24:29,889 INFO org.apache.hadoop.yarn.server.resourcemanager.rmcontainer.RMContainerImpl: container_1376154442901_0006_01_000002 Container Transitioned from ALLOCATED to ACQUIRED
2013-08-10 17:24:31,419 INFO org.apache.hadoop.yarn.server.resourcemanager.rmcontainer.RMContainerImpl: container_1376154442901_0010_01_000039 Container Transitioned from RUNNING to COMPLETED
2013-08-10 17:24:31,419 INFO org.apache.hadoop.yarn.server.resourcemanager.scheduler.common.fica.FiCaSchedulerApp: Completed container: container_1376154442901_0010_01_000039 in state: COMPLETED event:FINISHED
2013-08-10 17:24:31,419 INFO org.apache.hadoop.yarn.server.resourcemanager.RMAuditLogger: USER=ubuntu	OPERATION=AM Released Container	TARGET=SchedulerApp	RESULT=SUCCESS	APPID=application_1376154442901_0010	CONTAINERID=container_1376154442901_0010_01_000039
2013-08-10 17:24:31,420 INFO org.apache.hadoop.yarn.server.resourcemanager.scheduler.common.fica.FiCaSchedulerNode: Released container container_1376154442901_0010_01_000039 of capacity <memory:1024, vCores:1> on host hadoop-220-5:59721, which currently has 6 containers, <memory:7168, vCores:6> used and <memory:1024, vCores:10> available, release resources=true
2013-08-10 17:24:31,420 INFO org.apache.hadoop.yarn.server.resourcemanager.scheduler.capacity.LeafQueue: default used=<memory:48128, vCores:42> numContainers=42 user=ubuntu user-resources=<memory:48128, vCores:42>
2013-08-10 17:24:31,421 INFO org.apache.hadoop.yarn.server.resourcemanager.scheduler.capacity.LeafQueue: completedContainer container=Container: [ContainerId: container_1376154442901_0010_01_000039, NodeId: hadoop-220-5:59721, NodeHttpAddress: hadoop-220-5:8042, Resource: <memory:1024, vCores:1>, Priority: 20, State: NEW, Token: null, Status: container_id {, app_attempt_id {, application_id {, id: 10, cluster_timestamp: 1376154442901, }, attemptId: 1, }, id: 39, }, state: C_COMPLETE, diagnostics: "", exit_status: 0, ] resource=<memory:1024, vCores:1> queue=default: capacity=1.0, absoluteCapacity=1.0, usedResources=<memory:48128, vCores:42>usedCapacity=0.9791667, absoluteUsedCapacity=0.9791667, numApps=5, numContainers=42 usedCapacity=0.9791667 absoluteUsedCapacity=0.9791667 used=<memory:48128, vCores:42> cluster=<memory:49152, vCores:96>
2013-08-10 17:24:31,421 INFO org.apache.hadoop.yarn.server.resourcemanager.scheduler.capacity.ParentQueue: completedContainer queue=root usedCapacity=0.9791667 absoluteUsedCapacity=0.9791667 used=<memory:48128, vCores:42> cluster=<memory:49152, vCores:96>
2013-08-10 17:24:31,421 INFO org.apache.hadoop.yarn.server.resourcemanager.scheduler.capacity.CapacityScheduler: Application appattempt_1376154442901_0010_000001 released container container_1376154442901_0010_01_000039 on node: host: hadoop-220-5:59721 #containers=6 available=1024 used=7168 with event: FINISHED
2013-08-10 17:24:31,422 INFO org.apache.hadoop.yarn.server.resourcemanager.rmcontainer.RMContainerImpl: container_1376154442901_0006_01_000003 Container Transitioned from NEW to ALLOCATED
2013-08-10 17:24:31,422 INFO org.apache.hadoop.yarn.server.resourcemanager.RMAuditLogger: USER=ubuntu	OPERATION=AM Allocated Container	TARGET=SchedulerApp	RESULT=SUCCESS	APPID=application_1376154442901_0006	CONTAINERID=container_1376154442901_0006_01_000003
2013-08-10 17:24:31,422 INFO org.apache.hadoop.yarn.server.resourcemanager.scheduler.common.fica.FiCaSchedulerNode: Assigned container container_1376154442901_0006_01_000003 of capacity <memory:1024, vCores:1> on host hadoop-220-5:59721, which currently has 7 containers, <memory:8192, vCores:7> used and <memory:0, vCores:9> available
2013-08-10 17:24:31,423 INFO org.apache.hadoop.yarn.server.resourcemanager.scheduler.capacity.LeafQueue: assignedContainer application=application_1376154442901_0006 container=Container: [ContainerId: container_1376154442901_0006_01_000003, NodeId: hadoop-220-5:59721, NodeHttpAddress: hadoop-220-5:8042, Resource: <memory:1024, vCores:1>, Priority: 20, State: NEW, Token: null, Status: container_id {, app_attempt_id {, application_id {, id: 6, cluster_timestamp: 1376154442901, }, attemptId: 1, }, id: 3, }, state: C_NEW, ] containerId=container_1376154442901_0006_01_000003 queue=default: capacity=1.0, absoluteCapacity=1.0, usedResources=<memory:48128, vCores:42>usedCapacity=0.9791667, absoluteUsedCapacity=0.9791667, numApps=5, numContainers=42 usedCapacity=0.9791667 absoluteUsedCapacity=0.9791667 used=<memory:48128, vCores:42> cluster=<memory:49152, vCores:96>
2013-08-10 17:24:31,423 INFO org.apache.hadoop.yarn.server.resourcemanager.scheduler.capacity.ParentQueue: Re-sorting queues since queue: root.default stats: default: capacity=1.0, absoluteCapacity=1.0, usedResources=<memory:49152, vCores:43>usedCapacity=1.0, absoluteUsedCapacity=1.0, numApps=5, numContainers=43
2013-08-10 17:24:31,423 INFO org.apache.hadoop.yarn.server.resourcemanager.scheduler.capacity.ParentQueue: assignedContainer queue=root usedCapacity=1.0 absoluteUsedCapacity=1.0 used=<memory:49152, vCores:43> cluster=<memory:49152, vCores:96>
2013-08-10 17:24:32,103 INFO org.apache.hadoop.yarn.server.resourcemanager.rmcontainer.RMContainerImpl: container_1376154442901_0010_01_000012 Container Transitioned from RUNNING to COMPLETED
2013-08-10 17:24:32,103 INFO org.apache.hadoop.yarn.server.resourcemanager.scheduler.common.fica.FiCaSchedulerApp: Completed container: container_1376154442901_0010_01_000012 in state: COMPLETED event:FINISHED
2013-08-10 17:24:32,103 INFO org.apache.hadoop.yarn.server.resourcemanager.RMAuditLogger: USER=ubuntu	OPERATION=AM Released Container	TARGET=SchedulerApp	RESULT=SUCCESS	APPID=application_1376154442901_0010	CONTAINERID=container_1376154442901_0010_01_000012
2013-08-10 17:24:32,103 INFO org.apache.hadoop.yarn.server.resourcemanager.scheduler.common.fica.FiCaSchedulerNode: Released container container_1376154442901_0010_01_000012 of capacity <memory:1024, vCores:1> on host hadoop-220-2:50762, which currently has 7 containers, <memory:7168, vCores:7> used and <memory:1024, vCores:9> available, release resources=true
2013-08-10 17:24:32,104 INFO org.apache.hadoop.yarn.server.resourcemanager.scheduler.capacity.LeafQueue: default used=<memory:48128, vCores:42> numContainers=42 user=ubuntu user-resources=<memory:48128, vCores:42>
2013-08-10 17:24:32,105 INFO org.apache.hadoop.yarn.server.resourcemanager.scheduler.capacity.LeafQueue: completedContainer container=Container: [ContainerId: container_1376154442901_0010_01_000012, NodeId: hadoop-220-2:50762, NodeHttpAddress: hadoop-220-2:8042, Resource: <memory:1024, vCores:1>, Priority: 20, State: NEW, Token: null, Status: container_id {, app_attempt_id {, application_id {, id: 10, cluster_timestamp: 1376154442901, }, attemptId: 1, }, id: 12, }, state: C_COMPLETE, diagnostics: "Container killed by the ApplicationMaster.\n\n", exit_status: 143, ] resource=<memory:1024, vCores:1> queue=default: capacity=1.0, absoluteCapacity=1.0, usedResources=<memory:48128, vCores:42>usedCapacity=0.9791667, absoluteUsedCapacity=0.9791667, numApps=5, numContainers=42 usedCapacity=0.9791667 absoluteUsedCapacity=0.9791667 used=<memory:48128, vCores:42> cluster=<memory:49152, vCores:96>
2013-08-10 17:24:32,105 INFO org.apache.hadoop.yarn.server.resourcemanager.scheduler.capacity.ParentQueue: completedContainer queue=root usedCapacity=0.9791667 absoluteUsedCapacity=0.9791667 used=<memory:48128, vCores:42> cluster=<memory:49152, vCores:96>
2013-08-10 17:24:32,105 INFO org.apache.hadoop.yarn.server.resourcemanager.scheduler.capacity.CapacityScheduler: Application appattempt_1376154442901_0010_000001 released container container_1376154442901_0010_01_000012 on node: host: hadoop-220-2:50762 #containers=7 available=1024 used=7168 with event: FINISHED
2013-08-10 17:24:32,106 INFO org.apache.hadoop.yarn.server.resourcemanager.rmcontainer.RMContainerImpl: container_1376154442901_0006_01_000004 Container Transitioned from NEW to ALLOCATED
2013-08-10 17:24:32,106 INFO org.apache.hadoop.yarn.server.resourcemanager.RMAuditLogger: USER=ubuntu	OPERATION=AM Allocated Container	TARGET=SchedulerApp	RESULT=SUCCESS	APPID=application_1376154442901_0006	CONTAINERID=container_1376154442901_0006_01_000004
2013-08-10 17:24:32,106 INFO org.apache.hadoop.yarn.server.resourcemanager.scheduler.common.fica.FiCaSchedulerNode: Assigned container container_1376154442901_0006_01_000004 of capacity <memory:1024, vCores:1> on host hadoop-220-2:50762, which currently has 8 containers, <memory:8192, vCores:8> used and <memory:0, vCores:8> available
2013-08-10 17:24:32,107 INFO org.apache.hadoop.yarn.server.resourcemanager.scheduler.capacity.LeafQueue: assignedContainer application=application_1376154442901_0006 container=Container: [ContainerId: container_1376154442901_0006_01_000004, NodeId: hadoop-220-2:50762, NodeHttpAddress: hadoop-220-2:8042, Resource: <memory:1024, vCores:1>, Priority: 20, State: NEW, Token: null, Status: container_id {, app_attempt_id {, application_id {, id: 6, cluster_timestamp: 1376154442901, }, attemptId: 1, }, id: 4, }, state: C_NEW, ] containerId=container_1376154442901_0006_01_000004 queue=default: capacity=1.0, absoluteCapacity=1.0, usedResources=<memory:48128, vCores:42>usedCapacity=0.9791667, absoluteUsedCapacity=0.9791667, numApps=5, numContainers=42 usedCapacity=0.9791667 absoluteUsedCapacity=0.9791667 used=<memory:48128, vCores:42> cluster=<memory:49152, vCores:96>
2013-08-10 17:24:32,107 INFO org.apache.hadoop.yarn.server.resourcemanager.scheduler.capacity.ParentQueue: Re-sorting queues since queue: root.default stats: default: capacity=1.0, absoluteCapacity=1.0, usedResources=<memory:49152, vCores:43>usedCapacity=1.0, absoluteUsedCapacity=1.0, numApps=5, numContainers=43
2013-08-10 17:24:32,107 INFO org.apache.hadoop.yarn.server.resourcemanager.scheduler.capacity.ParentQueue: assignedContainer queue=root usedCapacity=1.0 absoluteUsedCapacity=1.0 used=<memory:49152, vCores:43> cluster=<memory:49152, vCores:96>
2013-08-10 17:24:32,973 INFO org.apache.hadoop.yarn.server.resourcemanager.rmcontainer.RMContainerImpl: container_1376154442901_0010_01_000007 Container Transitioned from RUNNING to COMPLETED
2013-08-10 17:24:32,973 INFO org.apache.hadoop.yarn.server.resourcemanager.scheduler.common.fica.FiCaSchedulerApp: Completed container: container_1376154442901_0010_01_000007 in state: COMPLETED event:FINISHED
2013-08-10 17:24:32,974 INFO org.apache.hadoop.yarn.server.resourcemanager.RMAuditLogger: USER=ubuntu	OPERATION=AM Released Container	TARGET=SchedulerApp	RESULT=SUCCESS	APPID=application_1376154442901_0010	CONTAINERID=container_1376154442901_0010_01_000007
2013-08-10 17:24:32,974 INFO org.apache.hadoop.yarn.server.resourcemanager.scheduler.common.fica.FiCaSchedulerNode: Released container container_1376154442901_0010_01_000007 of capacity <memory:1024, vCores:1> on host hadoop-220-3:58548, which currently has 6 containers, <memory:7168, vCores:6> used and <memory:1024, vCores:10> available, release resources=true
2013-08-10 17:24:32,974 INFO org.apache.hadoop.yarn.server.resourcemanager.scheduler.capacity.LeafQueue: default used=<memory:48128, vCores:42> numContainers=42 user=ubuntu user-resources=<memory:48128, vCores:42>
2013-08-10 17:24:32,975 INFO org.apache.hadoop.yarn.server.resourcemanager.scheduler.capacity.LeafQueue: completedContainer container=Container: [ContainerId: container_1376154442901_0010_01_000007, NodeId: hadoop-220-3:58548, NodeHttpAddress: hadoop-220-3:8042, Resource: <memory:1024, vCores:1>, Priority: 20, State: NEW, Token: null, Status: container_id {, app_attempt_id {, application_id {, id: 10, cluster_timestamp: 1376154442901, }, attemptId: 1, }, id: 7, }, state: C_COMPLETE, diagnostics: "Container killed by the ApplicationMaster.\n", exit_status: 0, ] resource=<memory:1024, vCores:1> queue=default: capacity=1.0, absoluteCapacity=1.0, usedResources=<memory:48128, vCores:42>usedCapacity=0.9791667, absoluteUsedCapacity=0.9791667, numApps=5, numContainers=42 usedCapacity=0.9791667 absoluteUsedCapacity=0.9791667 used=<memory:48128, vCores:42> cluster=<memory:49152, vCores:96>
2013-08-10 17:24:32,975 INFO org.apache.hadoop.yarn.server.resourcemanager.scheduler.capacity.ParentQueue: completedContainer queue=root usedCapacity=0.9791667 absoluteUsedCapacity=0.9791667 used=<memory:48128, vCores:42> cluster=<memory:49152, vCores:96>
2013-08-10 17:24:32,975 INFO org.apache.hadoop.yarn.server.resourcemanager.scheduler.capacity.CapacityScheduler: Application appattempt_1376154442901_0010_000001 released container container_1376154442901_0010_01_000007 on node: host: hadoop-220-3:58548 #containers=6 available=1024 used=7168 with event: FINISHED
2013-08-10 17:24:32,976 INFO org.apache.hadoop.yarn.server.resourcemanager.rmcontainer.RMContainerImpl: container_1376154442901_0006_01_000005 Container Transitioned from NEW to ALLOCATED
2013-08-10 17:24:32,976 INFO org.apache.hadoop.yarn.server.resourcemanager.RMAuditLogger: USER=ubuntu	OPERATION=AM Allocated Container	TARGET=SchedulerApp	RESULT=SUCCESS	APPID=application_1376154442901_0006	CONTAINERID=container_1376154442901_0006_01_000005
2013-08-10 17:24:32,976 INFO org.apache.hadoop.yarn.server.resourcemanager.scheduler.common.fica.FiCaSchedulerNode: Assigned container container_1376154442901_0006_01_000005 of capacity <memory:1024, vCores:1> on host hadoop-220-3:58548, which currently has 7 containers, <memory:8192, vCores:7> used and <memory:0, vCores:9> available
2013-08-10 17:24:32,977 INFO org.apache.hadoop.yarn.server.resourcemanager.scheduler.capacity.LeafQueue: assignedContainer application=application_1376154442901_0006 container=Container: [ContainerId: container_1376154442901_0006_01_000005, NodeId: hadoop-220-3:58548, NodeHttpAddress: hadoop-220-3:8042, Resource: <memory:1024, vCores:1>, Priority: 20, State: NEW, Token: null, Status: container_id {, app_attempt_id {, application_id {, id: 6, cluster_timestamp: 1376154442901, }, attemptId: 1, }, id: 5, }, state: C_NEW, ] containerId=container_1376154442901_0006_01_000005 queue=default: capacity=1.0, absoluteCapacity=1.0, usedResources=<memory:48128, vCores:42>usedCapacity=0.9791667, absoluteUsedCapacity=0.9791667, numApps=5, numContainers=42 usedCapacity=0.9791667 absoluteUsedCapacity=0.9791667 used=<memory:48128, vCores:42> cluster=<memory:49152, vCores:96>
2013-08-10 17:24:32,977 INFO org.apache.hadoop.yarn.server.resourcemanager.scheduler.capacity.ParentQueue: Re-sorting queues since queue: root.default stats: default: capacity=1.0, absoluteCapacity=1.0, usedResources=<memory:49152, vCores:43>usedCapacity=1.0, absoluteUsedCapacity=1.0, numApps=5, numContainers=43
2013-08-10 17:24:32,977 INFO org.apache.hadoop.yarn.server.resourcemanager.scheduler.capacity.ParentQueue: assignedContainer queue=root usedCapacity=1.0 absoluteUsedCapacity=1.0 used=<memory:49152, vCores:43> cluster=<memory:49152, vCores:96>
2013-08-10 17:24:33,029 INFO org.apache.hadoop.yarn.server.resourcemanager.rmcontainer.RMContainerImpl: container_1376154442901_0010_01_000030 Container Transitioned from RUNNING to COMPLETED
2013-08-10 17:24:33,030 INFO org.apache.hadoop.yarn.server.resourcemanager.scheduler.common.fica.FiCaSchedulerApp: Completed container: container_1376154442901_0010_01_000030 in state: COMPLETED event:FINISHED
2013-08-10 17:24:33,030 INFO org.apache.hadoop.yarn.server.resourcemanager.RMAuditLogger: USER=ubuntu	OPERATION=AM Released Container	TARGET=SchedulerApp	RESULT=SUCCESS	APPID=application_1376154442901_0010	CONTAINERID=container_1376154442901_0010_01_000030
2013-08-10 17:24:33,030 INFO org.apache.hadoop.yarn.server.resourcemanager.scheduler.common.fica.FiCaSchedulerNode: Released container container_1376154442901_0010_01_000030 of capacity <memory:1024, vCores:1> on host hadoop-220-4:35716, which currently has 6 containers, <memory:7168, vCores:6> used and <memory:1024, vCores:10> available, release resources=true
2013-08-10 17:24:33,030 INFO org.apache.hadoop.yarn.server.resourcemanager.scheduler.capacity.LeafQueue: default used=<memory:48128, vCores:42> numContainers=42 user=ubuntu user-resources=<memory:48128, vCores:42>
2013-08-10 17:24:33,031 INFO org.apache.hadoop.yarn.server.resourcemanager.scheduler.capacity.LeafQueue: completedContainer container=Container: [ContainerId: container_1376154442901_0010_01_000030, NodeId: hadoop-220-4:35716, NodeHttpAddress: hadoop-220-4:8042, Resource: <memory:1024, vCores:1>, Priority: 20, State: NEW, Token: null, Status: container_id {, app_attempt_id {, application_id {, id: 10, cluster_timestamp: 1376154442901, }, attemptId: 1, }, id: 30, }, state: C_COMPLETE, diagnostics: "Container killed by the ApplicationMaster.\n\n", exit_status: 143, ] resource=<memory:1024, vCores:1> queue=default: capacity=1.0, absoluteCapacity=1.0, usedResources=<memory:48128, vCores:42>usedCapacity=0.9791667, absoluteUsedCapacity=0.9791667, numApps=5, numContainers=42 usedCapacity=0.9791667 absoluteUsedCapacity=0.9791667 used=<memory:48128, vCores:42> cluster=<memory:49152, vCores:96>
2013-08-10 17:24:33,031 INFO org.apache.hadoop.yarn.server.resourcemanager.scheduler.capacity.ParentQueue: completedContainer queue=root usedCapacity=0.9791667 absoluteUsedCapacity=0.9791667 used=<memory:48128, vCores:42> cluster=<memory:49152, vCores:96>
2013-08-10 17:24:33,031 INFO org.apache.hadoop.yarn.server.resourcemanager.scheduler.capacity.CapacityScheduler: Application appattempt_1376154442901_0010_000001 released container container_1376154442901_0010_01_000030 on node: host: hadoop-220-4:35716 #containers=6 available=1024 used=7168 with event: FINISHED
2013-08-10 17:24:33,032 INFO org.apache.hadoop.yarn.server.resourcemanager.rmcontainer.RMContainerImpl: container_1376154442901_0006_01_000006 Container Transitioned from NEW to ALLOCATED
2013-08-10 17:24:33,032 INFO org.apache.hadoop.yarn.server.resourcemanager.RMAuditLogger: USER=ubuntu	OPERATION=AM Allocated Container	TARGET=SchedulerApp	RESULT=SUCCESS	APPID=application_1376154442901_0006	CONTAINERID=container_1376154442901_0006_01_000006
2013-08-10 17:24:33,032 INFO org.apache.hadoop.yarn.server.resourcemanager.scheduler.common.fica.FiCaSchedulerNode: Assigned container container_1376154442901_0006_01_000006 of capacity <memory:1024, vCores:1> on host hadoop-220-4:35716, which currently has 7 containers, <memory:8192, vCores:7> used and <memory:0, vCores:9> available
2013-08-10 17:24:33,033 INFO org.apache.hadoop.yarn.server.resourcemanager.scheduler.capacity.LeafQueue: assignedContainer application=application_1376154442901_0006 container=Container: [ContainerId: container_1376154442901_0006_01_000006, NodeId: hadoop-220-4:35716, NodeHttpAddress: hadoop-220-4:8042, Resource: <memory:1024, vCores:1>, Priority: 20, State: NEW, Token: null, Status: container_id {, app_attempt_id {, application_id {, id: 6, cluster_timestamp: 1376154442901, }, attemptId: 1, }, id: 6, }, state: C_NEW, ] containerId=container_1376154442901_0006_01_000006 queue=default: capacity=1.0, absoluteCapacity=1.0, usedResources=<memory:48128, vCores:42>usedCapacity=0.9791667, absoluteUsedCapacity=0.9791667, numApps=5, numContainers=42 usedCapacity=0.9791667 absoluteUsedCapacity=0.9791667 used=<memory:48128, vCores:42> cluster=<memory:49152, vCores:96>
2013-08-10 17:24:33,033 INFO org.apache.hadoop.yarn.server.resourcemanager.scheduler.capacity.ParentQueue: Re-sorting queues since queue: root.default stats: default: capacity=1.0, absoluteCapacity=1.0, usedResources=<memory:49152, vCores:43>usedCapacity=1.0, absoluteUsedCapacity=1.0, numApps=5, numContainers=43
2013-08-10 17:24:33,033 INFO org.apache.hadoop.yarn.server.resourcemanager.scheduler.capacity.ParentQueue: assignedContainer queue=root usedCapacity=1.0 absoluteUsedCapacity=1.0 used=<memory:49152, vCores:43> cluster=<memory:49152, vCores:96>
2013-08-10 17:24:33,931 INFO org.apache.hadoop.yarn.server.resourcemanager.rmcontainer.RMContainerImpl: container_1376154442901_0006_01_000003 Container Transitioned from ALLOCATED to ACQUIRED
2013-08-10 17:24:33,932 INFO org.apache.hadoop.yarn.server.resourcemanager.rmcontainer.RMContainerImpl: container_1376154442901_0006_01_000004 Container Transitioned from ALLOCATED to ACQUIRED
2013-08-10 17:24:33,933 INFO org.apache.hadoop.yarn.server.resourcemanager.rmcontainer.RMContainerImpl: container_1376154442901_0006_01_000005 Container Transitioned from ALLOCATED to ACQUIRED
2013-08-10 17:24:33,933 INFO org.apache.hadoop.yarn.server.resourcemanager.rmcontainer.RMContainerImpl: container_1376154442901_0006_01_000006 Container Transitioned from ALLOCATED to ACQUIRED
2013-08-10 17:24:34,480 INFO org.apache.hadoop.yarn.server.resourcemanager.rmcontainer.RMContainerImpl: container_1376154442901_0010_01_000038 Container Transitioned from RUNNING to COMPLETED
2013-08-10 17:24:34,480 INFO org.apache.hadoop.yarn.server.resourcemanager.scheduler.common.fica.FiCaSchedulerApp: Completed container: container_1376154442901_0010_01_000038 in state: COMPLETED event:FINISHED
2013-08-10 17:24:34,480 INFO org.apache.hadoop.yarn.server.resourcemanager.RMAuditLogger: USER=ubuntu	OPERATION=AM Released Container	TARGET=SchedulerApp	RESULT=SUCCESS	APPID=application_1376154442901_0010	CONTAINERID=container_1376154442901_0010_01_000038
2013-08-10 17:24:34,481 INFO org.apache.hadoop.yarn.server.resourcemanager.scheduler.common.fica.FiCaSchedulerNode: Released container container_1376154442901_0010_01_000038 of capacity <memory:1024, vCores:1> on host hadoop-220-5:59721, which currently has 6 containers, <memory:7168, vCores:6> used and <memory:1024, vCores:10> available, release resources=true
2013-08-10 17:24:34,481 INFO org.apache.hadoop.yarn.server.resourcemanager.scheduler.capacity.LeafQueue: default used=<memory:48128, vCores:42> numContainers=42 user=ubuntu user-resources=<memory:48128, vCores:42>
2013-08-10 17:24:34,482 INFO org.apache.hadoop.yarn.server.resourcemanager.scheduler.capacity.LeafQueue: completedContainer container=Container: [ContainerId: container_1376154442901_0010_01_000038, NodeId: hadoop-220-5:59721, NodeHttpAddress: hadoop-220-5:8042, Resource: <memory:1024, vCores:1>, Priority: 20, State: NEW, Token: null, Status: container_id {, app_attempt_id {, application_id {, id: 10, cluster_timestamp: 1376154442901, }, attemptId: 1, }, id: 38, }, state: C_COMPLETE, diagnostics: "Container killed by the ApplicationMaster.\n\n", exit_status: 143, ] resource=<memory:1024, vCores:1> queue=default: capacity=1.0, absoluteCapacity=1.0, usedResources=<memory:48128, vCores:42>usedCapacity=0.9791667, absoluteUsedCapacity=0.9791667, numApps=5, numContainers=42 usedCapacity=0.9791667 absoluteUsedCapacity=0.9791667 used=<memory:48128, vCores:42> cluster=<memory:49152, vCores:96>
2013-08-10 17:24:34,482 INFO org.apache.hadoop.yarn.server.resourcemanager.scheduler.capacity.ParentQueue: completedContainer queue=root usedCapacity=0.9791667 absoluteUsedCapacity=0.9791667 used=<memory:48128, vCores:42> cluster=<memory:49152, vCores:96>
2013-08-10 17:24:34,482 INFO org.apache.hadoop.yarn.server.resourcemanager.scheduler.capacity.CapacityScheduler: Application appattempt_1376154442901_0010_000001 released container container_1376154442901_0010_01_000038 on node: host: hadoop-220-5:59721 #containers=6 available=1024 used=7168 with event: FINISHED
2013-08-10 17:24:34,483 INFO org.apache.hadoop.yarn.server.resourcemanager.rmcontainer.RMContainerImpl: container_1376154442901_0006_01_000007 Container Transitioned from NEW to ALLOCATED
2013-08-10 17:24:34,483 INFO org.apache.hadoop.yarn.server.resourcemanager.RMAuditLogger: USER=ubuntu	OPERATION=AM Allocated Container	TARGET=SchedulerApp	RESULT=SUCCESS	APPID=application_1376154442901_0006	CONTAINERID=container_1376154442901_0006_01_000007
2013-08-10 17:24:34,483 INFO org.apache.hadoop.yarn.server.resourcemanager.scheduler.common.fica.FiCaSchedulerNode: Assigned container container_1376154442901_0006_01_000007 of capacity <memory:1024, vCores:1> on host hadoop-220-5:59721, which currently has 7 containers, <memory:8192, vCores:7> used and <memory:0, vCores:9> available
2013-08-10 17:24:34,484 INFO org.apache.hadoop.yarn.server.resourcemanager.scheduler.capacity.LeafQueue: assignedContainer application=application_1376154442901_0006 container=Container: [ContainerId: container_1376154442901_0006_01_000007, NodeId: hadoop-220-5:59721, NodeHttpAddress: hadoop-220-5:8042, Resource: <memory:1024, vCores:1>, Priority: 20, State: NEW, Token: null, Status: container_id {, app_attempt_id {, application_id {, id: 6, cluster_timestamp: 1376154442901, }, attemptId: 1, }, id: 7, }, state: C_NEW, ] containerId=container_1376154442901_0006_01_000007 queue=default: capacity=1.0, absoluteCapacity=1.0, usedResources=<memory:48128, vCores:42>usedCapacity=0.9791667, absoluteUsedCapacity=0.9791667, numApps=5, numContainers=42 usedCapacity=0.9791667 absoluteUsedCapacity=0.9791667 used=<memory:48128, vCores:42> cluster=<memory:49152, vCores:96>
2013-08-10 17:24:34,484 INFO org.apache.hadoop.yarn.server.resourcemanager.scheduler.capacity.ParentQueue: Re-sorting queues since queue: root.default stats: default: capacity=1.0, absoluteCapacity=1.0, usedResources=<memory:49152, vCores:43>usedCapacity=1.0, absoluteUsedCapacity=1.0, numApps=5, numContainers=43
2013-08-10 17:24:34,484 INFO org.apache.hadoop.yarn.server.resourcemanager.scheduler.capacity.ParentQueue: assignedContainer queue=root usedCapacity=1.0 absoluteUsedCapacity=1.0 used=<memory:49152, vCores:43> cluster=<memory:49152, vCores:96>
2013-08-10 17:24:35,185 INFO org.apache.hadoop.yarn.server.resourcemanager.rmcontainer.RMContainerImpl: container_1376154442901_0006_01_000004 Container Transitioned from ACQUIRED to RUNNING
2013-08-10 17:24:35,386 INFO org.apache.hadoop.yarn.server.resourcemanager.rmcontainer.RMContainerImpl: container_1376154442901_0010_01_000013 Container Transitioned from RUNNING to COMPLETED
2013-08-10 17:24:35,386 INFO org.apache.hadoop.yarn.server.resourcemanager.scheduler.common.fica.FiCaSchedulerApp: Completed container: container_1376154442901_0010_01_000013 in state: COMPLETED event:FINISHED
2013-08-10 17:24:35,386 INFO org.apache.hadoop.yarn.server.resourcemanager.RMAuditLogger: USER=ubuntu	OPERATION=AM Released Container	TARGET=SchedulerApp	RESULT=SUCCESS	APPID=application_1376154442901_0010	CONTAINERID=container_1376154442901_0010_01_000013
2013-08-10 17:24:35,386 INFO org.apache.hadoop.yarn.server.resourcemanager.scheduler.common.fica.FiCaSchedulerNode: Released container container_1376154442901_0010_01_000013 of capacity <memory:1024, vCores:1> on host hadoop-220-2:50762, which currently has 7 containers, <memory:7168, vCores:7> used and <memory:1024, vCores:9> available, release resources=true
2013-08-10 17:24:35,386 INFO org.apache.hadoop.yarn.server.resourcemanager.scheduler.capacity.LeafQueue: default used=<memory:48128, vCores:42> numContainers=42 user=ubuntu user-resources=<memory:48128, vCores:42>
2013-08-10 17:24:35,388 INFO org.apache.hadoop.yarn.server.resourcemanager.scheduler.capacity.LeafQueue: completedContainer container=Container: [ContainerId: container_1376154442901_0010_01_000013, NodeId: hadoop-220-2:50762, NodeHttpAddress: hadoop-220-2:8042, Resource: <memory:1024, vCores:1>, Priority: 20, State: NEW, Token: null, Status: container_id {, app_attempt_id {, application_id {, id: 10, cluster_timestamp: 1376154442901, }, attemptId: 1, }, id: 13, }, state: C_COMPLETE, diagnostics: "Container killed by the ApplicationMaster.\n\n", exit_status: 143, ] resource=<memory:1024, vCores:1> queue=default: capacity=1.0, absoluteCapacity=1.0, usedResources=<memory:48128, vCores:42>usedCapacity=0.9791667, absoluteUsedCapacity=0.9791667, numApps=5, numContainers=42 usedCapacity=0.9791667 absoluteUsedCapacity=0.9791667 used=<memory:48128, vCores:42> cluster=<memory:49152, vCores:96>
2013-08-10 17:24:35,388 INFO org.apache.hadoop.yarn.server.resourcemanager.scheduler.capacity.ParentQueue: completedContainer queue=root usedCapacity=0.9791667 absoluteUsedCapacity=0.9791667 used=<memory:48128, vCores:42> cluster=<memory:49152, vCores:96>
2013-08-10 17:24:35,388 INFO org.apache.hadoop.yarn.server.resourcemanager.scheduler.capacity.CapacityScheduler: Application appattempt_1376154442901_0010_000001 released container container_1376154442901_0010_01_000013 on node: host: hadoop-220-2:50762 #containers=7 available=1024 used=7168 with event: FINISHED
2013-08-10 17:24:35,388 INFO org.apache.hadoop.yarn.server.resourcemanager.rmcontainer.RMContainerImpl: container_1376154442901_0006_01_000008 Container Transitioned from NEW to ALLOCATED
2013-08-10 17:24:35,388 INFO org.apache.hadoop.yarn.server.resourcemanager.RMAuditLogger: USER=ubuntu	OPERATION=AM Allocated Container	TARGET=SchedulerApp	RESULT=SUCCESS	APPID=application_1376154442901_0006	CONTAINERID=container_1376154442901_0006_01_000008
2013-08-10 17:24:35,389 INFO org.apache.hadoop.yarn.server.resourcemanager.scheduler.common.fica.FiCaSchedulerNode: Assigned container container_1376154442901_0006_01_000008 of capacity <memory:1024, vCores:1> on host hadoop-220-2:50762, which currently has 8 containers, <memory:8192, vCores:8> used and <memory:0, vCores:8> available
2013-08-10 17:24:35,391 INFO org.apache.hadoop.yarn.server.resourcemanager.scheduler.capacity.LeafQueue: assignedContainer application=application_1376154442901_0006 container=Container: [ContainerId: container_1376154442901_0006_01_000008, NodeId: hadoop-220-2:50762, NodeHttpAddress: hadoop-220-2:8042, Resource: <memory:1024, vCores:1>, Priority: 20, State: NEW, Token: null, Status: container_id {, app_attempt_id {, application_id {, id: 6, cluster_timestamp: 1376154442901, }, attemptId: 1, }, id: 8, }, state: C_NEW, ] containerId=container_1376154442901_0006_01_000008 queue=default: capacity=1.0, absoluteCapacity=1.0, usedResources=<memory:48128, vCores:42>usedCapacity=0.9791667, absoluteUsedCapacity=0.9791667, numApps=5, numContainers=42 usedCapacity=0.9791667 absoluteUsedCapacity=0.9791667 used=<memory:48128, vCores:42> cluster=<memory:49152, vCores:96>
2013-08-10 17:24:35,391 INFO org.apache.hadoop.yarn.server.resourcemanager.scheduler.capacity.ParentQueue: Re-sorting queues since queue: root.default stats: default: capacity=1.0, absoluteCapacity=1.0, usedResources=<memory:49152, vCores:43>usedCapacity=1.0, absoluteUsedCapacity=1.0, numApps=5, numContainers=43
2013-08-10 17:24:35,391 INFO org.apache.hadoop.yarn.server.resourcemanager.scheduler.capacity.ParentQueue: assignedContainer queue=root usedCapacity=1.0 absoluteUsedCapacity=1.0 used=<memory:49152, vCores:43> cluster=<memory:49152, vCores:96>
2013-08-10 17:24:35,507 INFO org.apache.hadoop.yarn.server.resourcemanager.rmcontainer.RMContainerImpl: container_1376154442901_0006_01_000003 Container Transitioned from ACQUIRED to RUNNING
2013-08-10 17:24:35,610 INFO org.apache.hadoop.yarn.server.resourcemanager.rmcontainer.RMContainerImpl: container_1376154442901_0006_01_000002 Container Transitioned from ACQUIRED to RUNNING
2013-08-10 17:24:36,040 INFO org.apache.hadoop.yarn.server.resourcemanager.rmcontainer.RMContainerImpl: container_1376154442901_0006_01_000005 Container Transitioned from ACQUIRED to RUNNING
2013-08-10 17:24:36,166 INFO org.apache.hadoop.yarn.server.resourcemanager.rmcontainer.RMContainerImpl: container_1376154442901_0006_01_000007 Container Transitioned from ALLOCATED to ACQUIRED
2013-08-10 17:24:36,167 INFO org.apache.hadoop.yarn.server.resourcemanager.rmcontainer.RMContainerImpl: container_1376154442901_0006_01_000008 Container Transitioned from ALLOCATED to ACQUIRED
2013-08-10 17:24:36,402 INFO org.apache.hadoop.yarn.server.resourcemanager.rmcontainer.RMContainerImpl: container_1376154442901_0010_01_000015 Container Transitioned from RUNNING to COMPLETED
2013-08-10 17:24:36,402 INFO org.apache.hadoop.yarn.server.resourcemanager.scheduler.common.fica.FiCaSchedulerApp: Completed container: container_1376154442901_0010_01_000015 in state: COMPLETED event:FINISHED
2013-08-10 17:24:36,402 INFO org.apache.hadoop.yarn.server.resourcemanager.RMAuditLogger: USER=ubuntu	OPERATION=AM Released Container	TARGET=SchedulerApp	RESULT=SUCCESS	APPID=application_1376154442901_0010	CONTAINERID=container_1376154442901_0010_01_000015
2013-08-10 17:24:36,402 INFO org.apache.hadoop.yarn.server.resourcemanager.scheduler.common.fica.FiCaSchedulerNode: Released container container_1376154442901_0010_01_000015 of capacity <memory:1024, vCores:1> on host hadoop-220-2:50762, which currently has 7 containers, <memory:7168, vCores:7> used and <memory:1024, vCores:9> available, release resources=true
2013-08-10 17:24:36,403 INFO org.apache.hadoop.yarn.server.resourcemanager.scheduler.capacity.LeafQueue: default used=<memory:48128, vCores:42> numContainers=42 user=ubuntu user-resources=<memory:48128, vCores:42>
2013-08-10 17:24:36,404 INFO org.apache.hadoop.yarn.server.resourcemanager.scheduler.capacity.LeafQueue: completedContainer container=Container: [ContainerId: container_1376154442901_0010_01_000015, NodeId: hadoop-220-2:50762, NodeHttpAddress: hadoop-220-2:8042, Resource: <memory:1024, vCores:1>, Priority: 20, State: NEW, Token: null, Status: container_id {, app_attempt_id {, application_id {, id: 10, cluster_timestamp: 1376154442901, }, attemptId: 1, }, id: 15, }, state: C_COMPLETE, diagnostics: "Container killed by the ApplicationMaster.\n\n", exit_status: 143, ] resource=<memory:1024, vCores:1> queue=default: capacity=1.0, absoluteCapacity=1.0, usedResources=<memory:48128, vCores:42>usedCapacity=0.9791667, absoluteUsedCapacity=0.9791667, numApps=5, numContainers=42 usedCapacity=0.9791667 absoluteUsedCapacity=0.9791667 used=<memory:48128, vCores:42> cluster=<memory:49152, vCores:96>
2013-08-10 17:24:36,404 INFO org.apache.hadoop.yarn.server.resourcemanager.scheduler.capacity.ParentQueue: completedContainer queue=root usedCapacity=0.9791667 absoluteUsedCapacity=0.9791667 used=<memory:48128, vCores:42> cluster=<memory:49152, vCores:96>
2013-08-10 17:24:36,404 INFO org.apache.hadoop.yarn.server.resourcemanager.scheduler.capacity.CapacityScheduler: Application appattempt_1376154442901_0010_000001 released container container_1376154442901_0010_01_000015 on node: host: hadoop-220-2:50762 #containers=7 available=1024 used=7168 with event: FINISHED
2013-08-10 17:24:36,405 INFO org.apache.hadoop.yarn.server.resourcemanager.rmcontainer.RMContainerImpl: container_1376154442901_0006_01_000009 Container Transitioned from NEW to ALLOCATED
2013-08-10 17:24:36,405 INFO org.apache.hadoop.yarn.server.resourcemanager.RMAuditLogger: USER=ubuntu	OPERATION=AM Allocated Container	TARGET=SchedulerApp	RESULT=SUCCESS	APPID=application_1376154442901_0006	CONTAINERID=container_1376154442901_0006_01_000009
2013-08-10 17:24:36,405 INFO org.apache.hadoop.yarn.server.resourcemanager.scheduler.common.fica.FiCaSchedulerNode: Assigned container container_1376154442901_0006_01_000009 of capacity <memory:1024, vCores:1> on host hadoop-220-2:50762, which currently has 8 containers, <memory:8192, vCores:8> used and <memory:0, vCores:8> available
2013-08-10 17:24:36,406 INFO org.apache.hadoop.yarn.server.resourcemanager.scheduler.capacity.LeafQueue: assignedContainer application=application_1376154442901_0006 container=Container: [ContainerId: container_1376154442901_0006_01_000009, NodeId: hadoop-220-2:50762, NodeHttpAddress: hadoop-220-2:8042, Resource: <memory:1024, vCores:1>, Priority: 20, State: NEW, Token: null, Status: container_id {, app_attempt_id {, application_id {, id: 6, cluster_timestamp: 1376154442901, }, attemptId: 1, }, id: 9, }, state: C_NEW, ] containerId=container_1376154442901_0006_01_000009 queue=default: capacity=1.0, absoluteCapacity=1.0, usedResources=<memory:48128, vCores:42>usedCapacity=0.9791667, absoluteUsedCapacity=0.9791667, numApps=5, numContainers=42 usedCapacity=0.9791667 absoluteUsedCapacity=0.9791667 used=<memory:48128, vCores:42> cluster=<memory:49152, vCores:96>
2013-08-10 17:24:36,406 INFO org.apache.hadoop.yarn.server.resourcemanager.scheduler.capacity.ParentQueue: Re-sorting queues since queue: root.default stats: default: capacity=1.0, absoluteCapacity=1.0, usedResources=<memory:49152, vCores:43>usedCapacity=1.0, absoluteUsedCapacity=1.0, numApps=5, numContainers=43
2013-08-10 17:24:36,406 INFO org.apache.hadoop.yarn.server.resourcemanager.scheduler.capacity.ParentQueue: assignedContainer queue=root usedCapacity=1.0 absoluteUsedCapacity=1.0 used=<memory:49152, vCores:43> cluster=<memory:49152, vCores:96>
2013-08-10 17:24:36,599 INFO org.apache.hadoop.yarn.server.resourcemanager.rmcontainer.RMContainerImpl: container_1376154442901_0006_01_000007 Container Transitioned from ACQUIRED to RUNNING
2013-08-10 17:24:36,623 INFO org.apache.hadoop.yarn.server.resourcemanager.rmcontainer.RMContainerImpl: container_1376154442901_0006_01_000006 Container Transitioned from ACQUIRED to RUNNING
2013-08-10 17:24:37,178 INFO org.apache.hadoop.yarn.server.resourcemanager.rmcontainer.RMContainerImpl: container_1376154442901_0006_01_000009 Container Transitioned from ALLOCATED to ACQUIRED
2013-08-10 17:24:37,413 INFO org.apache.hadoop.yarn.server.resourcemanager.rmcontainer.RMContainerImpl: container_1376154442901_0006_01_000008 Container Transitioned from ACQUIRED to RUNNING
2013-08-10 17:24:37,414 INFO org.apache.hadoop.yarn.server.resourcemanager.rmcontainer.RMContainerImpl: container_1376154442901_0006_01_000009 Container Transitioned from ACQUIRED to RUNNING
2013-08-10 17:24:38,613 INFO org.apache.hadoop.yarn.server.resourcemanager.rmcontainer.RMContainerImpl: container_1376154442901_0010_01_000018 Container Transitioned from RUNNING to COMPLETED
2013-08-10 17:24:38,613 INFO org.apache.hadoop.yarn.server.resourcemanager.scheduler.common.fica.FiCaSchedulerApp: Completed container: container_1376154442901_0010_01_000018 in state: COMPLETED event:FINISHED
2013-08-10 17:24:38,613 INFO org.apache.hadoop.yarn.server.resourcemanager.RMAuditLogger: USER=ubuntu	OPERATION=AM Released Container	TARGET=SchedulerApp	RESULT=SUCCESS	APPID=application_1376154442901_0010	CONTAINERID=container_1376154442901_0010_01_000018
2013-08-10 17:24:38,613 INFO org.apache.hadoop.yarn.server.resourcemanager.scheduler.common.fica.FiCaSchedulerNode: Released container container_1376154442901_0010_01_000018 of capacity <memory:1024, vCores:1> on host hadoop-220-6:56687, which currently has 6 containers, <memory:7168, vCores:6> used and <memory:1024, vCores:10> available, release resources=true
2013-08-10 17:24:38,613 INFO org.apache.hadoop.yarn.server.resourcemanager.scheduler.capacity.LeafQueue: default used=<memory:48128, vCores:42> numContainers=42 user=ubuntu user-resources=<memory:48128, vCores:42>
2013-08-10 17:24:38,614 INFO org.apache.hadoop.yarn.server.resourcemanager.scheduler.capacity.LeafQueue: completedContainer container=Container: [ContainerId: container_1376154442901_0010_01_000018, NodeId: hadoop-220-6:56687, NodeHttpAddress: hadoop-220-6:8042, Resource: <memory:1024, vCores:1>, Priority: 20, State: NEW, Token: null, Status: container_id {, app_attempt_id {, application_id {, id: 10, cluster_timestamp: 1376154442901, }, attemptId: 1, }, id: 18, }, state: C_COMPLETE, diagnostics: "Container killed by the ApplicationMaster.\n\n", exit_status: 143, ] resource=<memory:1024, vCores:1> queue=default: capacity=1.0, absoluteCapacity=1.0, usedResources=<memory:48128, vCores:42>usedCapacity=0.9791667, absoluteUsedCapacity=0.9791667, numApps=5, numContainers=42 usedCapacity=0.9791667 absoluteUsedCapacity=0.9791667 used=<memory:48128, vCores:42> cluster=<memory:49152, vCores:96>
2013-08-10 17:24:38,615 INFO org.apache.hadoop.yarn.server.resourcemanager.scheduler.capacity.ParentQueue: completedContainer queue=root usedCapacity=0.9791667 absoluteUsedCapacity=0.9791667 used=<memory:48128, vCores:42> cluster=<memory:49152, vCores:96>
2013-08-10 17:24:38,616 INFO org.apache.hadoop.yarn.server.resourcemanager.scheduler.capacity.CapacityScheduler: Application appattempt_1376154442901_0010_000001 released container container_1376154442901_0010_01_000018 on node: host: hadoop-220-6:56687 #containers=6 available=1024 used=7168 with event: FINISHED
2013-08-10 17:24:38,616 INFO org.apache.hadoop.yarn.server.resourcemanager.rmcontainer.RMContainerImpl: container_1376154442901_0006_01_000010 Container Transitioned from NEW to ALLOCATED
2013-08-10 17:24:38,616 INFO org.apache.hadoop.yarn.server.resourcemanager.RMAuditLogger: USER=ubuntu	OPERATION=AM Allocated Container	TARGET=SchedulerApp	RESULT=SUCCESS	APPID=application_1376154442901_0006	CONTAINERID=container_1376154442901_0006_01_000010
2013-08-10 17:24:38,617 INFO org.apache.hadoop.yarn.server.resourcemanager.scheduler.common.fica.FiCaSchedulerNode: Assigned container container_1376154442901_0006_01_000010 of capacity <memory:1024, vCores:1> on host hadoop-220-6:56687, which currently has 7 containers, <memory:8192, vCores:7> used and <memory:0, vCores:9> available
2013-08-10 17:24:38,618 INFO org.apache.hadoop.yarn.server.resourcemanager.scheduler.capacity.LeafQueue: assignedContainer application=application_1376154442901_0006 container=Container: [ContainerId: container_1376154442901_0006_01_000010, NodeId: hadoop-220-6:56687, NodeHttpAddress: hadoop-220-6:8042, Resource: <memory:1024, vCores:1>, Priority: 20, State: NEW, Token: null, Status: container_id {, app_attempt_id {, application_id {, id: 6, cluster_timestamp: 1376154442901, }, attemptId: 1, }, id: 10, }, state: C_NEW, ] containerId=container_1376154442901_0006_01_000010 queue=default: capacity=1.0, absoluteCapacity=1.0, usedResources=<memory:48128, vCores:42>usedCapacity=0.9791667, absoluteUsedCapacity=0.9791667, numApps=5, numContainers=42 usedCapacity=0.9791667 absoluteUsedCapacity=0.9791667 used=<memory:48128, vCores:42> cluster=<memory:49152, vCores:96>
2013-08-10 17:24:38,618 INFO org.apache.hadoop.yarn.server.resourcemanager.scheduler.capacity.ParentQueue: Re-sorting queues since queue: root.default stats: default: capacity=1.0, absoluteCapacity=1.0, usedResources=<memory:49152, vCores:43>usedCapacity=1.0, absoluteUsedCapacity=1.0, numApps=5, numContainers=43
2013-08-10 17:24:38,618 INFO org.apache.hadoop.yarn.server.resourcemanager.scheduler.capacity.ParentQueue: assignedContainer queue=root usedCapacity=1.0 absoluteUsedCapacity=1.0 used=<memory:49152, vCores:43> cluster=<memory:49152, vCores:96>
2013-08-10 17:24:39,193 INFO org.apache.hadoop.yarn.server.resourcemanager.rmcontainer.RMContainerImpl: container_1376154442901_0006_01_000010 Container Transitioned from ALLOCATED to ACQUIRED
2013-08-10 17:24:39,684 INFO org.apache.hadoop.yarn.server.resourcemanager.rmcontainer.RMContainerImpl: container_1376154442901_0006_01_000010 Container Transitioned from ACQUIRED to RUNNING
2013-08-10 17:24:39,684 INFO org.apache.hadoop.yarn.server.resourcemanager.rmcontainer.RMContainerImpl: container_1376154442901_0010_01_000016 Container Transitioned from RUNNING to COMPLETED
2013-08-10 17:24:39,685 INFO org.apache.hadoop.yarn.server.resourcemanager.scheduler.common.fica.FiCaSchedulerApp: Completed container: container_1376154442901_0010_01_000016 in state: COMPLETED event:FINISHED
2013-08-10 17:24:39,685 INFO org.apache.hadoop.yarn.server.resourcemanager.RMAuditLogger: USER=ubuntu	OPERATION=AM Released Container	TARGET=SchedulerApp	RESULT=SUCCESS	APPID=application_1376154442901_0010	CONTAINERID=container_1376154442901_0010_01_000016
2013-08-10 17:24:39,685 INFO org.apache.hadoop.yarn.server.resourcemanager.scheduler.common.fica.FiCaSchedulerNode: Released container container_1376154442901_0010_01_000016 of capacity <memory:1024, vCores:1> on host hadoop-220-6:56687, which currently has 6 containers, <memory:7168, vCores:6> used and <memory:1024, vCores:10> available, release resources=true
2013-08-10 17:24:39,685 INFO org.apache.hadoop.yarn.server.resourcemanager.scheduler.capacity.LeafQueue: default used=<memory:48128, vCores:42> numContainers=42 user=ubuntu user-resources=<memory:48128, vCores:42>
2013-08-10 17:24:39,686 INFO org.apache.hadoop.yarn.server.resourcemanager.scheduler.capacity.LeafQueue: completedContainer container=Container: [ContainerId: container_1376154442901_0010_01_000016, NodeId: hadoop-220-6:56687, NodeHttpAddress: hadoop-220-6:8042, Resource: <memory:1024, vCores:1>, Priority: 20, State: NEW, Token: null, Status: container_id {, app_attempt_id {, application_id {, id: 10, cluster_timestamp: 1376154442901, }, attemptId: 1, }, id: 16, }, state: C_COMPLETE, diagnostics: "Container killed by the ApplicationMaster.\n", exit_status: 0, ] resource=<memory:1024, vCores:1> queue=default: capacity=1.0, absoluteCapacity=1.0, usedResources=<memory:48128, vCores:42>usedCapacity=0.9791667, absoluteUsedCapacity=0.9791667, numApps=5, numContainers=42 usedCapacity=0.9791667 absoluteUsedCapacity=0.9791667 used=<memory:48128, vCores:42> cluster=<memory:49152, vCores:96>
2013-08-10 17:24:39,686 INFO org.apache.hadoop.yarn.server.resourcemanager.scheduler.capacity.ParentQueue: completedContainer queue=root usedCapacity=0.9791667 absoluteUsedCapacity=0.9791667 used=<memory:48128, vCores:42> cluster=<memory:49152, vCores:96>
2013-08-10 17:24:39,686 INFO org.apache.hadoop.yarn.server.resourcemanager.scheduler.capacity.CapacityScheduler: Application appattempt_1376154442901_0010_000001 released container container_1376154442901_0010_01_000016 on node: host: hadoop-220-6:56687 #containers=6 available=1024 used=7168 with event: FINISHED
2013-08-10 17:24:39,687 INFO org.apache.hadoop.yarn.server.resourcemanager.rmcontainer.RMContainerImpl: container_1376154442901_0010_01_000017 Container Transitioned from RUNNING to COMPLETED
2013-08-10 17:24:39,687 INFO org.apache.hadoop.yarn.server.resourcemanager.scheduler.common.fica.FiCaSchedulerApp: Completed container: container_1376154442901_0010_01_000017 in state: COMPLETED event:FINISHED
2013-08-10 17:24:39,687 INFO org.apache.hadoop.yarn.server.resourcemanager.RMAuditLogger: USER=ubuntu	OPERATION=AM Released Container	TARGET=SchedulerApp	RESULT=SUCCESS	APPID=application_1376154442901_0010	CONTAINERID=container_1376154442901_0010_01_000017
2013-08-10 17:24:39,687 INFO org.apache.hadoop.yarn.server.resourcemanager.scheduler.common.fica.FiCaSchedulerNode: Released container container_1376154442901_0010_01_000017 of capacity <memory:1024, vCores:1> on host hadoop-220-6:56687, which currently has 5 containers, <memory:6144, vCores:5> used and <memory:2048, vCores:11> available, release resources=true
2013-08-10 17:24:39,687 INFO org.apache.hadoop.yarn.server.resourcemanager.scheduler.capacity.LeafQueue: default used=<memory:47104, vCores:41> numContainers=41 user=ubuntu user-resources=<memory:47104, vCores:41>
2013-08-10 17:24:39,688 INFO org.apache.hadoop.yarn.server.resourcemanager.scheduler.capacity.LeafQueue: completedContainer container=Container: [ContainerId: container_1376154442901_0010_01_000017, NodeId: hadoop-220-6:56687, NodeHttpAddress: hadoop-220-6:8042, Resource: <memory:1024, vCores:1>, Priority: 20, State: NEW, Token: null, Status: container_id {, app_attempt_id {, application_id {, id: 10, cluster_timestamp: 1376154442901, }, attemptId: 1, }, id: 17, }, state: C_COMPLETE, diagnostics: "Container killed by the ApplicationMaster.\n", exit_status: 0, ] resource=<memory:1024, vCores:1> queue=default: capacity=1.0, absoluteCapacity=1.0, usedResources=<memory:47104, vCores:41>usedCapacity=0.9583333, absoluteUsedCapacity=0.9583333, numApps=5, numContainers=41 usedCapacity=0.9583333 absoluteUsedCapacity=0.9583333 used=<memory:47104, vCores:41> cluster=<memory:49152, vCores:96>
2013-08-10 17:24:39,691 INFO org.apache.hadoop.yarn.server.resourcemanager.scheduler.capacity.ParentQueue: completedContainer queue=root usedCapacity=0.9583333 absoluteUsedCapacity=0.9583333 used=<memory:47104, vCores:41> cluster=<memory:49152, vCores:96>
2013-08-10 17:24:39,691 INFO org.apache.hadoop.yarn.server.resourcemanager.scheduler.capacity.CapacityScheduler: Application appattempt_1376154442901_0010_000001 released container container_1376154442901_0010_01_000017 on node: host: hadoop-220-6:56687 #containers=5 available=2048 used=6144 with event: FINISHED
2013-08-10 17:24:39,691 INFO org.apache.hadoop.yarn.server.resourcemanager.rmcontainer.RMContainerImpl: container_1376154442901_0010_01_000020 Container Transitioned from RUNNING to COMPLETED
2013-08-10 17:24:39,691 INFO org.apache.hadoop.yarn.server.resourcemanager.scheduler.common.fica.FiCaSchedulerApp: Completed container: container_1376154442901_0010_01_000020 in state: COMPLETED event:FINISHED
2013-08-10 17:24:39,692 INFO org.apache.hadoop.yarn.server.resourcemanager.RMAuditLogger: USER=ubuntu	OPERATION=AM Released Container	TARGET=SchedulerApp	RESULT=SUCCESS	APPID=application_1376154442901_0010	CONTAINERID=container_1376154442901_0010_01_000020
2013-08-10 17:24:39,692 INFO org.apache.hadoop.yarn.server.resourcemanager.scheduler.common.fica.FiCaSchedulerNode: Released container container_1376154442901_0010_01_000020 of capacity <memory:1024, vCores:1> on host hadoop-220-6:56687, which currently has 4 containers, <memory:5120, vCores:4> used and <memory:3072, vCores:12> available, release resources=true
2013-08-10 17:24:39,692 INFO org.apache.hadoop.yarn.server.resourcemanager.scheduler.capacity.LeafQueue: default used=<memory:46080, vCores:40> numContainers=40 user=ubuntu user-resources=<memory:46080, vCores:40>
2013-08-10 17:24:39,693 INFO org.apache.hadoop.yarn.server.resourcemanager.scheduler.capacity.LeafQueue: completedContainer container=Container: [ContainerId: container_1376154442901_0010_01_000020, NodeId: hadoop-220-6:56687, NodeHttpAddress: hadoop-220-6:8042, Resource: <memory:1024, vCores:1>, Priority: 20, State: NEW, Token: null, Status: container_id {, app_attempt_id {, application_id {, id: 10, cluster_timestamp: 1376154442901, }, attemptId: 1, }, id: 20, }, state: C_COMPLETE, diagnostics: "Container killed by the ApplicationMaster.\n\n", exit_status: 143, ] resource=<memory:1024, vCores:1> queue=default: capacity=1.0, absoluteCapacity=1.0, usedResources=<memory:46080, vCores:40>usedCapacity=0.9375, absoluteUsedCapacity=0.9375, numApps=5, numContainers=40 usedCapacity=0.9375 absoluteUsedCapacity=0.9375 used=<memory:46080, vCores:40> cluster=<memory:49152, vCores:96>
2013-08-10 17:24:39,693 INFO org.apache.hadoop.yarn.server.resourcemanager.scheduler.capacity.ParentQueue: completedContainer queue=root usedCapacity=0.9375 absoluteUsedCapacity=0.9375 used=<memory:46080, vCores:40> cluster=<memory:49152, vCores:96>
2013-08-10 17:24:39,693 INFO org.apache.hadoop.yarn.server.resourcemanager.scheduler.capacity.CapacityScheduler: Application appattempt_1376154442901_0010_000001 released container container_1376154442901_0010_01_000020 on node: host: hadoop-220-6:56687 #containers=4 available=3072 used=5120 with event: FINISHED
2013-08-10 17:24:39,694 INFO org.apache.hadoop.yarn.server.resourcemanager.rmcontainer.RMContainerImpl: container_1376154442901_0006_01_000011 Container Transitioned from NEW to ALLOCATED
2013-08-10 17:24:39,694 INFO org.apache.hadoop.yarn.server.resourcemanager.RMAuditLogger: USER=ubuntu	OPERATION=AM Allocated Container	TARGET=SchedulerApp	RESULT=SUCCESS	APPID=application_1376154442901_0006	CONTAINERID=container_1376154442901_0006_01_000011
2013-08-10 17:24:39,694 INFO org.apache.hadoop.yarn.server.resourcemanager.scheduler.common.fica.FiCaSchedulerNode: Assigned container container_1376154442901_0006_01_000011 of capacity <memory:1024, vCores:1> on host hadoop-220-6:56687, which currently has 5 containers, <memory:6144, vCores:5> used and <memory:2048, vCores:11> available
2013-08-10 17:24:39,695 INFO org.apache.hadoop.yarn.server.resourcemanager.scheduler.capacity.LeafQueue: assignedContainer application=application_1376154442901_0006 container=Container: [ContainerId: container_1376154442901_0006_01_000011, NodeId: hadoop-220-6:56687, NodeHttpAddress: hadoop-220-6:8042, Resource: <memory:1024, vCores:1>, Priority: 20, State: NEW, Token: null, Status: container_id {, app_attempt_id {, application_id {, id: 6, cluster_timestamp: 1376154442901, }, attemptId: 1, }, id: 11, }, state: C_NEW, ] containerId=container_1376154442901_0006_01_000011 queue=default: capacity=1.0, absoluteCapacity=1.0, usedResources=<memory:46080, vCores:40>usedCapacity=0.9375, absoluteUsedCapacity=0.9375, numApps=5, numContainers=40 usedCapacity=0.9375 absoluteUsedCapacity=0.9375 used=<memory:46080, vCores:40> cluster=<memory:49152, vCores:96>
2013-08-10 17:24:39,695 INFO org.apache.hadoop.yarn.server.resourcemanager.scheduler.capacity.ParentQueue: Re-sorting queues since queue: root.default stats: default: capacity=1.0, absoluteCapacity=1.0, usedResources=<memory:47104, vCores:41>usedCapacity=0.9583333, absoluteUsedCapacity=0.9583333, numApps=5, numContainers=41
2013-08-10 17:24:39,695 INFO org.apache.hadoop.yarn.server.resourcemanager.scheduler.capacity.ParentQueue: assignedContainer queue=root usedCapacity=0.9583333 absoluteUsedCapacity=0.9583333 used=<memory:47104, vCores:41> cluster=<memory:49152, vCores:96>
2013-08-10 17:24:39,696 INFO org.apache.hadoop.yarn.server.resourcemanager.rmcontainer.RMContainerImpl: container_1376154442901_0006_01_000012 Container Transitioned from NEW to ALLOCATED
2013-08-10 17:24:39,696 INFO org.apache.hadoop.yarn.server.resourcemanager.RMAuditLogger: USER=ubuntu	OPERATION=AM Allocated Container	TARGET=SchedulerApp	RESULT=SUCCESS	APPID=application_1376154442901_0006	CONTAINERID=container_1376154442901_0006_01_000012
2013-08-10 17:24:39,696 INFO org.apache.hadoop.yarn.server.resourcemanager.scheduler.common.fica.FiCaSchedulerNode: Assigned container container_1376154442901_0006_01_000012 of capacity <memory:1024, vCores:1> on host hadoop-220-6:56687, which currently has 6 containers, <memory:7168, vCores:6> used and <memory:1024, vCores:10> available
2013-08-10 17:24:39,697 INFO org.apache.hadoop.yarn.server.resourcemanager.scheduler.capacity.LeafQueue: assignedContainer application=application_1376154442901_0006 container=Container: [ContainerId: container_1376154442901_0006_01_000012, NodeId: hadoop-220-6:56687, NodeHttpAddress: hadoop-220-6:8042, Resource: <memory:1024, vCores:1>, Priority: 20, State: NEW, Token: null, Status: container_id {, app_attempt_id {, application_id {, id: 6, cluster_timestamp: 1376154442901, }, attemptId: 1, }, id: 12, }, state: C_NEW, ] containerId=container_1376154442901_0006_01_000012 queue=default: capacity=1.0, absoluteCapacity=1.0, usedResources=<memory:47104, vCores:41>usedCapacity=0.9583333, absoluteUsedCapacity=0.9583333, numApps=5, numContainers=41 usedCapacity=0.9583333 absoluteUsedCapacity=0.9583333 used=<memory:47104, vCores:41> cluster=<memory:49152, vCores:96>
2013-08-10 17:24:39,697 INFO org.apache.hadoop.yarn.server.resourcemanager.scheduler.capacity.ParentQueue: Re-sorting queues since queue: root.default stats: default: capacity=1.0, absoluteCapacity=1.0, usedResources=<memory:48128, vCores:42>usedCapacity=0.9791667, absoluteUsedCapacity=0.9791667, numApps=5, numContainers=42
2013-08-10 17:24:39,697 INFO org.apache.hadoop.yarn.server.resourcemanager.scheduler.capacity.ParentQueue: assignedContainer queue=root usedCapacity=0.9791667 absoluteUsedCapacity=0.9791667 used=<memory:48128, vCores:42> cluster=<memory:49152, vCores:96>
2013-08-10 17:24:39,698 INFO org.apache.hadoop.yarn.server.resourcemanager.rmcontainer.RMContainerImpl: container_1376154442901_0006_01_000013 Container Transitioned from NEW to ALLOCATED
2013-08-10 17:24:39,698 INFO org.apache.hadoop.yarn.server.resourcemanager.RMAuditLogger: USER=ubuntu	OPERATION=AM Allocated Container	TARGET=SchedulerApp	RESULT=SUCCESS	APPID=application_1376154442901_0006	CONTAINERID=container_1376154442901_0006_01_000013
2013-08-10 17:24:39,698 INFO org.apache.hadoop.yarn.server.resourcemanager.scheduler.common.fica.FiCaSchedulerNode: Assigned container container_1376154442901_0006_01_000013 of capacity <memory:1024, vCores:1> on host hadoop-220-6:56687, which currently has 7 containers, <memory:8192, vCores:7> used and <memory:0, vCores:9> available
2013-08-10 17:24:39,699 INFO org.apache.hadoop.yarn.server.resourcemanager.scheduler.capacity.LeafQueue: assignedContainer application=application_1376154442901_0006 container=Container: [ContainerId: container_1376154442901_0006_01_000013, NodeId: hadoop-220-6:56687, NodeHttpAddress: hadoop-220-6:8042, Resource: <memory:1024, vCores:1>, Priority: 20, State: NEW, Token: null, Status: container_id {, app_attempt_id {, application_id {, id: 6, cluster_timestamp: 1376154442901, }, attemptId: 1, }, id: 13, }, state: C_NEW, ] containerId=container_1376154442901_0006_01_000013 queue=default: capacity=1.0, absoluteCapacity=1.0, usedResources=<memory:48128, vCores:42>usedCapacity=0.9791667, absoluteUsedCapacity=0.9791667, numApps=5, numContainers=42 usedCapacity=0.9791667 absoluteUsedCapacity=0.9791667 used=<memory:48128, vCores:42> cluster=<memory:49152, vCores:96>
2013-08-10 17:24:39,699 INFO org.apache.hadoop.yarn.server.resourcemanager.scheduler.capacity.ParentQueue: Re-sorting queues since queue: root.default stats: default: capacity=1.0, absoluteCapacity=1.0, usedResources=<memory:49152, vCores:43>usedCapacity=1.0, absoluteUsedCapacity=1.0, numApps=5, numContainers=43
2013-08-10 17:24:39,699 INFO org.apache.hadoop.yarn.server.resourcemanager.scheduler.capacity.ParentQueue: assignedContainer queue=root usedCapacity=1.0 absoluteUsedCapacity=1.0 used=<memory:49152, vCores:43> cluster=<memory:49152, vCores:96>
2013-08-10 17:24:40,206 INFO org.apache.hadoop.yarn.server.resourcemanager.rmcontainer.RMContainerImpl: container_1376154442901_0006_01_000011 Container Transitioned from ALLOCATED to ACQUIRED
2013-08-10 17:24:40,208 INFO org.apache.hadoop.yarn.server.resourcemanager.rmcontainer.RMContainerImpl: container_1376154442901_0006_01_000012 Container Transitioned from ALLOCATED to ACQUIRED
2013-08-10 17:24:40,208 INFO org.apache.hadoop.yarn.server.resourcemanager.rmcontainer.RMContainerImpl: container_1376154442901_0006_01_000013 Container Transitioned from ALLOCATED to ACQUIRED
2013-08-10 17:24:40,692 INFO org.apache.hadoop.yarn.server.resourcemanager.rmcontainer.RMContainerImpl: container_1376154442901_0006_01_000011 Container Transitioned from ACQUIRED to RUNNING
2013-08-10 17:24:40,692 INFO org.apache.hadoop.yarn.server.resourcemanager.rmcontainer.RMContainerImpl: container_1376154442901_0006_01_000012 Container Transitioned from ACQUIRED to RUNNING
2013-08-10 17:24:40,692 INFO org.apache.hadoop.yarn.server.resourcemanager.rmcontainer.RMContainerImpl: container_1376154442901_0006_01_000013 Container Transitioned from ACQUIRED to RUNNING
2013-08-10 17:24:42,252 INFO org.apache.hadoop.yarn.server.resourcemanager.rmcontainer.RMContainerImpl: container_1376154442901_0010_01_000003 Container Transitioned from RUNNING to COMPLETED
2013-08-10 17:24:42,252 INFO org.apache.hadoop.yarn.server.resourcemanager.scheduler.common.fica.FiCaSchedulerApp: Completed container: container_1376154442901_0010_01_000003 in state: COMPLETED event:FINISHED
2013-08-10 17:24:42,252 INFO org.apache.hadoop.yarn.server.resourcemanager.RMAuditLogger: USER=ubuntu	OPERATION=AM Released Container	TARGET=SchedulerApp	RESULT=SUCCESS	APPID=application_1376154442901_0010	CONTAINERID=container_1376154442901_0010_01_000003
2013-08-10 17:24:42,253 INFO org.apache.hadoop.yarn.server.resourcemanager.scheduler.common.fica.FiCaSchedulerNode: Released container container_1376154442901_0010_01_000003 of capacity <memory:1024, vCores:1> on host hadoop-220-3:58548, which currently has 6 containers, <memory:7168, vCores:6> used and <memory:1024, vCores:10> available, release resources=true
2013-08-10 17:24:42,253 INFO org.apache.hadoop.yarn.server.resourcemanager.scheduler.capacity.LeafQueue: default used=<memory:48128, vCores:42> numContainers=42 user=ubuntu user-resources=<memory:48128, vCores:42>
2013-08-10 17:24:42,254 INFO org.apache.hadoop.yarn.server.resourcemanager.scheduler.capacity.LeafQueue: completedContainer container=Container: [ContainerId: container_1376154442901_0010_01_000003, NodeId: hadoop-220-3:58548, NodeHttpAddress: hadoop-220-3:8042, Resource: <memory:1024, vCores:1>, Priority: 20, State: NEW, Token: null, Status: container_id {, app_attempt_id {, application_id {, id: 10, cluster_timestamp: 1376154442901, }, attemptId: 1, }, id: 3, }, state: C_COMPLETE, diagnostics: "Container killed by the ApplicationMaster.\n\n", exit_status: 143, ] resource=<memory:1024, vCores:1> queue=default: capacity=1.0, absoluteCapacity=1.0, usedResources=<memory:48128, vCores:42>usedCapacity=0.9791667, absoluteUsedCapacity=0.9791667, numApps=5, numContainers=42 usedCapacity=0.9791667 absoluteUsedCapacity=0.9791667 used=<memory:48128, vCores:42> cluster=<memory:49152, vCores:96>
2013-08-10 17:24:42,254 INFO org.apache.hadoop.yarn.server.resourcemanager.scheduler.capacity.ParentQueue: completedContainer queue=root usedCapacity=0.9791667 absoluteUsedCapacity=0.9791667 used=<memory:48128, vCores:42> cluster=<memory:49152, vCores:96>
2013-08-10 17:24:42,254 INFO org.apache.hadoop.yarn.server.resourcemanager.scheduler.capacity.CapacityScheduler: Application appattempt_1376154442901_0010_000001 released container container_1376154442901_0010_01_000003 on node: host: hadoop-220-3:58548 #containers=6 available=1024 used=7168 with event: FINISHED
2013-08-10 17:24:42,255 INFO org.apache.hadoop.yarn.server.resourcemanager.rmcontainer.RMContainerImpl: container_1376154442901_0006_01_000014 Container Transitioned from NEW to ALLOCATED
2013-08-10 17:24:42,255 INFO org.apache.hadoop.yarn.server.resourcemanager.RMAuditLogger: USER=ubuntu	OPERATION=AM Allocated Container	TARGET=SchedulerApp	RESULT=SUCCESS	APPID=application_1376154442901_0006	CONTAINERID=container_1376154442901_0006_01_000014
2013-08-10 17:24:42,255 INFO org.apache.hadoop.yarn.server.resourcemanager.scheduler.common.fica.FiCaSchedulerNode: Assigned container container_1376154442901_0006_01_000014 of capacity <memory:1024, vCores:1> on host hadoop-220-3:58548, which currently has 7 containers, <memory:8192, vCores:7> used and <memory:0, vCores:9> available
2013-08-10 17:24:42,256 INFO org.apache.hadoop.yarn.server.resourcemanager.scheduler.capacity.LeafQueue: assignedContainer application=application_1376154442901_0006 container=Container: [ContainerId: container_1376154442901_0006_01_000014, NodeId: hadoop-220-3:58548, NodeHttpAddress: hadoop-220-3:8042, Resource: <memory:1024, vCores:1>, Priority: 20, State: NEW, Token: null, Status: container_id {, app_attempt_id {, application_id {, id: 6, cluster_timestamp: 1376154442901, }, attemptId: 1, }, id: 14, }, state: C_NEW, ] containerId=container_1376154442901_0006_01_000014 queue=default: capacity=1.0, absoluteCapacity=1.0, usedResources=<memory:48128, vCores:42>usedCapacity=0.9791667, absoluteUsedCapacity=0.9791667, numApps=5, numContainers=42 usedCapacity=0.9791667 absoluteUsedCapacity=0.9791667 used=<memory:48128, vCores:42> cluster=<memory:49152, vCores:96>
2013-08-10 17:24:42,256 INFO org.apache.hadoop.yarn.server.resourcemanager.scheduler.capacity.ParentQueue: Re-sorting queues since queue: root.default stats: default: capacity=1.0, absoluteCapacity=1.0, usedResources=<memory:49152, vCores:43>usedCapacity=1.0, absoluteUsedCapacity=1.0, numApps=5, numContainers=43
2013-08-10 17:24:42,256 INFO org.apache.hadoop.yarn.server.resourcemanager.scheduler.capacity.ParentQueue: assignedContainer queue=root usedCapacity=1.0 absoluteUsedCapacity=1.0 used=<memory:49152, vCores:43> cluster=<memory:49152, vCores:96>
2013-08-10 17:24:42,641 INFO org.apache.hadoop.yarn.server.resourcemanager.rmcontainer.RMContainerImpl: container_1376154442901_0010_01_000028 Container Transitioned from RUNNING to COMPLETED
2013-08-10 17:24:42,641 INFO org.apache.hadoop.yarn.server.resourcemanager.scheduler.common.fica.FiCaSchedulerApp: Completed container: container_1376154442901_0010_01_000028 in state: COMPLETED event:FINISHED
2013-08-10 17:24:42,641 INFO org.apache.hadoop.yarn.server.resourcemanager.RMAuditLogger: USER=ubuntu	OPERATION=AM Released Container	TARGET=SchedulerApp	RESULT=SUCCESS	APPID=application_1376154442901_0010	CONTAINERID=container_1376154442901_0010_01_000028
2013-08-10 17:24:42,641 INFO org.apache.hadoop.yarn.server.resourcemanager.scheduler.common.fica.FiCaSchedulerNode: Released container container_1376154442901_0010_01_000028 of capacity <memory:1024, vCores:1> on host hadoop-220-4:35716, which currently has 6 containers, <memory:7168, vCores:6> used and <memory:1024, vCores:10> available, release resources=true
2013-08-10 17:24:42,641 INFO org.apache.hadoop.yarn.server.resourcemanager.scheduler.capacity.LeafQueue: default used=<memory:48128, vCores:42> numContainers=42 user=ubuntu user-resources=<memory:48128, vCores:42>
2013-08-10 17:24:42,642 INFO org.apache.hadoop.yarn.server.resourcemanager.scheduler.capacity.LeafQueue: completedContainer container=Container: [ContainerId: container_1376154442901_0010_01_000028, NodeId: hadoop-220-4:35716, NodeHttpAddress: hadoop-220-4:8042, Resource: <memory:1024, vCores:1>, Priority: 20, State: NEW, Token: null, Status: container_id {, app_attempt_id {, application_id {, id: 10, cluster_timestamp: 1376154442901, }, attemptId: 1, }, id: 28, }, state: C_COMPLETE, diagnostics: "Container killed by the ApplicationMaster.\n\n", exit_status: 143, ] resource=<memory:1024, vCores:1> queue=default: capacity=1.0, absoluteCapacity=1.0, usedResources=<memory:48128, vCores:42>usedCapacity=0.9791667, absoluteUsedCapacity=0.9791667, numApps=5, numContainers=42 usedCapacity=0.9791667 absoluteUsedCapacity=0.9791667 used=<memory:48128, vCores:42> cluster=<memory:49152, vCores:96>
2013-08-10 17:24:42,643 INFO org.apache.hadoop.yarn.server.resourcemanager.scheduler.capacity.ParentQueue: completedContainer queue=root usedCapacity=0.9791667 absoluteUsedCapacity=0.9791667 used=<memory:48128, vCores:42> cluster=<memory:49152, vCores:96>
2013-08-10 17:24:42,643 INFO org.apache.hadoop.yarn.server.resourcemanager.scheduler.capacity.CapacityScheduler: Application appattempt_1376154442901_0010_000001 released container container_1376154442901_0010_01_000028 on node: host: hadoop-220-4:35716 #containers=6 available=1024 used=7168 with event: FINISHED
2013-08-10 17:24:42,643 INFO org.apache.hadoop.yarn.server.resourcemanager.rmcontainer.RMContainerImpl: container_1376154442901_0006_01_000015 Container Transitioned from NEW to ALLOCATED
2013-08-10 17:24:42,643 INFO org.apache.hadoop.yarn.server.resourcemanager.RMAuditLogger: USER=ubuntu	OPERATION=AM Allocated Container	TARGET=SchedulerApp	RESULT=SUCCESS	APPID=application_1376154442901_0006	CONTAINERID=container_1376154442901_0006_01_000015
2013-08-10 17:24:42,644 INFO org.apache.hadoop.yarn.server.resourcemanager.scheduler.common.fica.FiCaSchedulerNode: Assigned container container_1376154442901_0006_01_000015 of capacity <memory:1024, vCores:1> on host hadoop-220-4:35716, which currently has 7 containers, <memory:8192, vCores:7> used and <memory:0, vCores:9> available
2013-08-10 17:24:42,644 INFO org.apache.hadoop.yarn.server.resourcemanager.scheduler.capacity.LeafQueue: assignedContainer application=application_1376154442901_0006 container=Container: [ContainerId: container_1376154442901_0006_01_000015, NodeId: hadoop-220-4:35716, NodeHttpAddress: hadoop-220-4:8042, Resource: <memory:1024, vCores:1>, Priority: 20, State: NEW, Token: null, Status: container_id {, app_attempt_id {, application_id {, id: 6, cluster_timestamp: 1376154442901, }, attemptId: 1, }, id: 15, }, state: C_NEW, ] containerId=container_1376154442901_0006_01_000015 queue=default: capacity=1.0, absoluteCapacity=1.0, usedResources=<memory:48128, vCores:42>usedCapacity=0.9791667, absoluteUsedCapacity=0.9791667, numApps=5, numContainers=42 usedCapacity=0.9791667 absoluteUsedCapacity=0.9791667 used=<memory:48128, vCores:42> cluster=<memory:49152, vCores:96>
2013-08-10 17:24:42,645 INFO org.apache.hadoop.yarn.server.resourcemanager.scheduler.capacity.ParentQueue: Re-sorting queues since queue: root.default stats: default: capacity=1.0, absoluteCapacity=1.0, usedResources=<memory:49152, vCores:43>usedCapacity=1.0, absoluteUsedCapacity=1.0, numApps=5, numContainers=43
2013-08-10 17:24:42,645 INFO org.apache.hadoop.yarn.server.resourcemanager.scheduler.capacity.ParentQueue: assignedContainer queue=root usedCapacity=1.0 absoluteUsedCapacity=1.0 used=<memory:49152, vCores:43> cluster=<memory:49152, vCores:96>
2013-08-10 17:24:43,244 INFO org.apache.hadoop.yarn.server.resourcemanager.rmcontainer.RMContainerImpl: container_1376154442901_0006_01_000014 Container Transitioned from ALLOCATED to ACQUIRED
2013-08-10 17:24:43,245 INFO org.apache.hadoop.yarn.server.resourcemanager.rmcontainer.RMContainerImpl: container_1376154442901_0006_01_000015 Container Transitioned from ALLOCATED to ACQUIRED
2013-08-10 17:24:43,656 INFO org.apache.hadoop.yarn.server.resourcemanager.rmcontainer.RMContainerImpl: container_1376154442901_0006_01_000015 Container Transitioned from ACQUIRED to RUNNING
2013-08-10 17:24:43,995 INFO org.apache.hadoop.yarn.server.resourcemanager.rmcontainer.RMContainerImpl: container_1376154442901_0006_01_000014 Container Transitioned from ACQUIRED to RUNNING
2013-08-10 17:24:45,022 INFO org.apache.hadoop.yarn.server.resourcemanager.rmcontainer.RMContainerImpl: container_1376154442901_0010_01_000004 Container Transitioned from RUNNING to COMPLETED
2013-08-10 17:24:45,022 INFO org.apache.hadoop.yarn.server.resourcemanager.scheduler.common.fica.FiCaSchedulerApp: Completed container: container_1376154442901_0010_01_000004 in state: COMPLETED event:FINISHED
2013-08-10 17:24:45,023 INFO org.apache.hadoop.yarn.server.resourcemanager.RMAuditLogger: USER=ubuntu	OPERATION=AM Released Container	TARGET=SchedulerApp	RESULT=SUCCESS	APPID=application_1376154442901_0010	CONTAINERID=container_1376154442901_0010_01_000004
2013-08-10 17:24:45,023 INFO org.apache.hadoop.yarn.server.resourcemanager.scheduler.common.fica.FiCaSchedulerNode: Released container container_1376154442901_0010_01_000004 of capacity <memory:1024, vCores:1> on host hadoop-220-3:58548, which currently has 6 containers, <memory:7168, vCores:6> used and <memory:1024, vCores:10> available, release resources=true
2013-08-10 17:24:45,023 INFO org.apache.hadoop.yarn.server.resourcemanager.scheduler.capacity.LeafQueue: default used=<memory:48128, vCores:42> numContainers=42 user=ubuntu user-resources=<memory:48128, vCores:42>
2013-08-10 17:24:45,024 INFO org.apache.hadoop.yarn.server.resourcemanager.scheduler.capacity.LeafQueue: completedContainer container=Container: [ContainerId: container_1376154442901_0010_01_000004, NodeId: hadoop-220-3:58548, NodeHttpAddress: hadoop-220-3:8042, Resource: <memory:1024, vCores:1>, Priority: 20, State: NEW, Token: null, Status: container_id {, app_attempt_id {, application_id {, id: 10, cluster_timestamp: 1376154442901, }, attemptId: 1, }, id: 4, }, state: C_COMPLETE, diagnostics: "Container killed by the ApplicationMaster.\n\n", exit_status: 143, ] resource=<memory:1024, vCores:1> queue=default: capacity=1.0, absoluteCapacity=1.0, usedResources=<memory:48128, vCores:42>usedCapacity=0.9791667, absoluteUsedCapacity=0.9791667, numApps=5, numContainers=42 usedCapacity=0.9791667 absoluteUsedCapacity=0.9791667 used=<memory:48128, vCores:42> cluster=<memory:49152, vCores:96>
2013-08-10 17:24:45,024 INFO org.apache.hadoop.yarn.server.resourcemanager.scheduler.capacity.ParentQueue: completedContainer queue=root usedCapacity=0.9791667 absoluteUsedCapacity=0.9791667 used=<memory:48128, vCores:42> cluster=<memory:49152, vCores:96>
2013-08-10 17:24:45,024 INFO org.apache.hadoop.yarn.server.resourcemanager.scheduler.capacity.CapacityScheduler: Application appattempt_1376154442901_0010_000001 released container container_1376154442901_0010_01_000004 on node: host: hadoop-220-3:58548 #containers=6 available=1024 used=7168 with event: FINISHED
2013-08-10 17:24:45,025 INFO org.apache.hadoop.yarn.server.resourcemanager.rmcontainer.RMContainerImpl: container_1376154442901_0006_01_000016 Container Transitioned from NEW to ALLOCATED
2013-08-10 17:24:45,025 INFO org.apache.hadoop.yarn.server.resourcemanager.RMAuditLogger: USER=ubuntu	OPERATION=AM Allocated Container	TARGET=SchedulerApp	RESULT=SUCCESS	APPID=application_1376154442901_0006	CONTAINERID=container_1376154442901_0006_01_000016
2013-08-10 17:24:45,025 INFO org.apache.hadoop.yarn.server.resourcemanager.scheduler.common.fica.FiCaSchedulerNode: Assigned container container_1376154442901_0006_01_000016 of capacity <memory:1024, vCores:1> on host hadoop-220-3:58548, which currently has 7 containers, <memory:8192, vCores:7> used and <memory:0, vCores:9> available
2013-08-10 17:24:45,026 INFO org.apache.hadoop.yarn.server.resourcemanager.scheduler.capacity.LeafQueue: assignedContainer application=application_1376154442901_0006 container=Container: [ContainerId: container_1376154442901_0006_01_000016, NodeId: hadoop-220-3:58548, NodeHttpAddress: hadoop-220-3:8042, Resource: <memory:1024, vCores:1>, Priority: 20, State: NEW, Token: null, Status: container_id {, app_attempt_id {, application_id {, id: 6, cluster_timestamp: 1376154442901, }, attemptId: 1, }, id: 16, }, state: C_NEW, ] containerId=container_1376154442901_0006_01_000016 queue=default: capacity=1.0, absoluteCapacity=1.0, usedResources=<memory:48128, vCores:42>usedCapacity=0.9791667, absoluteUsedCapacity=0.9791667, numApps=5, numContainers=42 usedCapacity=0.9791667 absoluteUsedCapacity=0.9791667 used=<memory:48128, vCores:42> cluster=<memory:49152, vCores:96>
2013-08-10 17:24:45,026 INFO org.apache.hadoop.yarn.server.resourcemanager.scheduler.capacity.ParentQueue: Re-sorting queues since queue: root.default stats: default: capacity=1.0, absoluteCapacity=1.0, usedResources=<memory:49152, vCores:43>usedCapacity=1.0, absoluteUsedCapacity=1.0, numApps=5, numContainers=43
2013-08-10 17:24:45,026 INFO org.apache.hadoop.yarn.server.resourcemanager.scheduler.capacity.ParentQueue: assignedContainer queue=root usedCapacity=1.0 absoluteUsedCapacity=1.0 used=<memory:49152, vCores:43> cluster=<memory:49152, vCores:96>
2013-08-10 17:24:45,357 INFO org.apache.hadoop.yarn.server.resourcemanager.rmcontainer.RMContainerImpl: container_1376154442901_0006_01_000016 Container Transitioned from ALLOCATED to ACQUIRED
2013-08-10 17:24:46,031 INFO org.apache.hadoop.yarn.server.resourcemanager.rmcontainer.RMContainerImpl: container_1376154442901_0006_01_000016 Container Transitioned from ACQUIRED to RUNNING
2013-08-10 17:24:47,242 INFO org.apache.hadoop.yarn.server.resourcemanager.rmcontainer.RMContainerImpl: container_1376154442901_0010_01_000002 Container Transitioned from RUNNING to COMPLETED
2013-08-10 17:24:47,243 INFO org.apache.hadoop.yarn.server.resourcemanager.scheduler.common.fica.FiCaSchedulerApp: Completed container: container_1376154442901_0010_01_000002 in state: COMPLETED event:FINISHED
2013-08-10 17:24:47,243 INFO org.apache.hadoop.yarn.server.resourcemanager.RMAuditLogger: USER=ubuntu	OPERATION=AM Released Container	TARGET=SchedulerApp	RESULT=SUCCESS	APPID=application_1376154442901_0010	CONTAINERID=container_1376154442901_0010_01_000002
2013-08-10 17:24:47,243 INFO org.apache.hadoop.yarn.server.resourcemanager.scheduler.common.fica.FiCaSchedulerNode: Released container container_1376154442901_0010_01_000002 of capacity <memory:1024, vCores:1> on host hadoop-220-3:58548, which currently has 6 containers, <memory:7168, vCores:6> used and <memory:1024, vCores:10> available, release resources=true
2013-08-10 17:24:47,243 INFO org.apache.hadoop.yarn.server.resourcemanager.scheduler.capacity.LeafQueue: default used=<memory:48128, vCores:42> numContainers=42 user=ubuntu user-resources=<memory:48128, vCores:42>
2013-08-10 17:24:47,244 INFO org.apache.hadoop.yarn.server.resourcemanager.scheduler.capacity.LeafQueue: completedContainer container=Container: [ContainerId: container_1376154442901_0010_01_000002, NodeId: hadoop-220-3:58548, NodeHttpAddress: hadoop-220-3:8042, Resource: <memory:1024, vCores:1>, Priority: 20, State: NEW, Token: null, Status: container_id {, app_attempt_id {, application_id {, id: 10, cluster_timestamp: 1376154442901, }, attemptId: 1, }, id: 2, }, state: C_COMPLETE, diagnostics: "Container killed by the ApplicationMaster.\n\n", exit_status: 143, ] resource=<memory:1024, vCores:1> queue=default: capacity=1.0, absoluteCapacity=1.0, usedResources=<memory:48128, vCores:42>usedCapacity=0.9791667, absoluteUsedCapacity=0.9791667, numApps=5, numContainers=42 usedCapacity=0.9791667 absoluteUsedCapacity=0.9791667 used=<memory:48128, vCores:42> cluster=<memory:49152, vCores:96>
2013-08-10 17:24:47,244 INFO org.apache.hadoop.yarn.server.resourcemanager.scheduler.capacity.ParentQueue: completedContainer queue=root usedCapacity=0.9791667 absoluteUsedCapacity=0.9791667 used=<memory:48128, vCores:42> cluster=<memory:49152, vCores:96>
2013-08-10 17:24:47,244 INFO org.apache.hadoop.yarn.server.resourcemanager.scheduler.capacity.CapacityScheduler: Application appattempt_1376154442901_0010_000001 released container container_1376154442901_0010_01_000002 on node: host: hadoop-220-3:58548 #containers=6 available=1024 used=7168 with event: FINISHED
2013-08-10 17:24:47,245 INFO org.apache.hadoop.yarn.server.resourcemanager.rmcontainer.RMContainerImpl: container_1376154442901_0006_01_000017 Container Transitioned from NEW to ALLOCATED
2013-08-10 17:24:47,245 INFO org.apache.hadoop.yarn.server.resourcemanager.RMAuditLogger: USER=ubuntu	OPERATION=AM Allocated Container	TARGET=SchedulerApp	RESULT=SUCCESS	APPID=application_1376154442901_0006	CONTAINERID=container_1376154442901_0006_01_000017
2013-08-10 17:24:47,245 INFO org.apache.hadoop.yarn.server.resourcemanager.scheduler.common.fica.FiCaSchedulerNode: Assigned container container_1376154442901_0006_01_000017 of capacity <memory:1024, vCores:1> on host hadoop-220-3:58548, which currently has 7 containers, <memory:8192, vCores:7> used and <memory:0, vCores:9> available
2013-08-10 17:24:47,246 INFO org.apache.hadoop.yarn.server.resourcemanager.scheduler.capacity.LeafQueue: assignedContainer application=application_1376154442901_0006 container=Container: [ContainerId: container_1376154442901_0006_01_000017, NodeId: hadoop-220-3:58548, NodeHttpAddress: hadoop-220-3:8042, Resource: <memory:1024, vCores:1>, Priority: 20, State: NEW, Token: null, Status: container_id {, app_attempt_id {, application_id {, id: 6, cluster_timestamp: 1376154442901, }, attemptId: 1, }, id: 17, }, state: C_NEW, ] containerId=container_1376154442901_0006_01_000017 queue=default: capacity=1.0, absoluteCapacity=1.0, usedResources=<memory:48128, vCores:42>usedCapacity=0.9791667, absoluteUsedCapacity=0.9791667, numApps=5, numContainers=42 usedCapacity=0.9791667 absoluteUsedCapacity=0.9791667 used=<memory:48128, vCores:42> cluster=<memory:49152, vCores:96>
2013-08-10 17:24:47,246 INFO org.apache.hadoop.yarn.server.resourcemanager.scheduler.capacity.ParentQueue: Re-sorting queues since queue: root.default stats: default: capacity=1.0, absoluteCapacity=1.0, usedResources=<memory:49152, vCores:43>usedCapacity=1.0, absoluteUsedCapacity=1.0, numApps=5, numContainers=43
2013-08-10 17:24:47,246 INFO org.apache.hadoop.yarn.server.resourcemanager.scheduler.capacity.ParentQueue: assignedContainer queue=root usedCapacity=1.0 absoluteUsedCapacity=1.0 used=<memory:49152, vCores:43> cluster=<memory:49152, vCores:96>
2013-08-10 17:24:48,136 INFO org.apache.hadoop.yarn.server.resourcemanager.rmcontainer.RMContainerImpl: container_1376154442901_0006_01_000017 Container Transitioned from ALLOCATED to ACQUIRED
2013-08-10 17:24:49,201 INFO org.apache.hadoop.yarn.server.resourcemanager.rmcontainer.RMContainerImpl: container_1376154442901_0010_01_000019 Container Transitioned from RUNNING to COMPLETED
2013-08-10 17:24:49,201 INFO org.apache.hadoop.yarn.server.resourcemanager.scheduler.common.fica.FiCaSchedulerApp: Completed container: container_1376154442901_0010_01_000019 in state: COMPLETED event:FINISHED
2013-08-10 17:24:49,201 INFO org.apache.hadoop.yarn.server.resourcemanager.RMAuditLogger: USER=ubuntu	OPERATION=AM Released Container	TARGET=SchedulerApp	RESULT=SUCCESS	APPID=application_1376154442901_0010	CONTAINERID=container_1376154442901_0010_01_000019
2013-08-10 17:24:49,201 INFO org.apache.hadoop.yarn.server.resourcemanager.scheduler.common.fica.FiCaSchedulerNode: Released container container_1376154442901_0010_01_000019 of capacity <memory:1024, vCores:1> on host hadoop-220-6:56687, which currently has 6 containers, <memory:7168, vCores:6> used and <memory:1024, vCores:10> available, release resources=true
2013-08-10 17:24:49,201 INFO org.apache.hadoop.yarn.server.resourcemanager.scheduler.capacity.LeafQueue: default used=<memory:48128, vCores:42> numContainers=42 user=ubuntu user-resources=<memory:48128, vCores:42>
2013-08-10 17:24:49,203 INFO org.apache.hadoop.yarn.server.resourcemanager.scheduler.capacity.LeafQueue: completedContainer container=Container: [ContainerId: container_1376154442901_0010_01_000019, NodeId: hadoop-220-6:56687, NodeHttpAddress: hadoop-220-6:8042, Resource: <memory:1024, vCores:1>, Priority: 20, State: NEW, Token: null, Status: container_id {, app_attempt_id {, application_id {, id: 10, cluster_timestamp: 1376154442901, }, attemptId: 1, }, id: 19, }, state: C_COMPLETE, diagnostics: "Container killed by the ApplicationMaster.\n\n", exit_status: 143, ] resource=<memory:1024, vCores:1> queue=default: capacity=1.0, absoluteCapacity=1.0, usedResources=<memory:48128, vCores:42>usedCapacity=0.9791667, absoluteUsedCapacity=0.9791667, numApps=5, numContainers=42 usedCapacity=0.9791667 absoluteUsedCapacity=0.9791667 used=<memory:48128, vCores:42> cluster=<memory:49152, vCores:96>
2013-08-10 17:24:49,203 INFO org.apache.hadoop.yarn.server.resourcemanager.scheduler.capacity.ParentQueue: completedContainer queue=root usedCapacity=0.9791667 absoluteUsedCapacity=0.9791667 used=<memory:48128, vCores:42> cluster=<memory:49152, vCores:96>
2013-08-10 17:24:49,203 INFO org.apache.hadoop.yarn.server.resourcemanager.scheduler.capacity.CapacityScheduler: Application appattempt_1376154442901_0010_000001 released container container_1376154442901_0010_01_000019 on node: host: hadoop-220-6:56687 #containers=6 available=1024 used=7168 with event: FINISHED
2013-08-10 17:24:49,203 INFO org.apache.hadoop.yarn.server.resourcemanager.rmcontainer.RMContainerImpl: container_1376154442901_0006_01_000018 Container Transitioned from NEW to ALLOCATED
2013-08-10 17:24:49,204 INFO org.apache.hadoop.yarn.server.resourcemanager.RMAuditLogger: USER=ubuntu	OPERATION=AM Allocated Container	TARGET=SchedulerApp	RESULT=SUCCESS	APPID=application_1376154442901_0006	CONTAINERID=container_1376154442901_0006_01_000018
2013-08-10 17:24:49,204 INFO org.apache.hadoop.yarn.server.resourcemanager.scheduler.common.fica.FiCaSchedulerNode: Assigned container container_1376154442901_0006_01_000018 of capacity <memory:1024, vCores:1> on host hadoop-220-6:56687, which currently has 7 containers, <memory:8192, vCores:7> used and <memory:0, vCores:9> available
2013-08-10 17:24:49,204 INFO org.apache.hadoop.yarn.server.resourcemanager.scheduler.capacity.LeafQueue: assignedContainer application=application_1376154442901_0006 container=Container: [ContainerId: container_1376154442901_0006_01_000018, NodeId: hadoop-220-6:56687, NodeHttpAddress: hadoop-220-6:8042, Resource: <memory:1024, vCores:1>, Priority: 20, State: NEW, Token: null, Status: container_id {, app_attempt_id {, application_id {, id: 6, cluster_timestamp: 1376154442901, }, attemptId: 1, }, id: 18, }, state: C_NEW, ] containerId=container_1376154442901_0006_01_000018 queue=default: capacity=1.0, absoluteCapacity=1.0, usedResources=<memory:48128, vCores:42>usedCapacity=0.9791667, absoluteUsedCapacity=0.9791667, numApps=5, numContainers=42 usedCapacity=0.9791667 absoluteUsedCapacity=0.9791667 used=<memory:48128, vCores:42> cluster=<memory:49152, vCores:96>
2013-08-10 17:24:49,205 INFO org.apache.hadoop.yarn.server.resourcemanager.scheduler.capacity.ParentQueue: Re-sorting queues since queue: root.default stats: default: capacity=1.0, absoluteCapacity=1.0, usedResources=<memory:49152, vCores:43>usedCapacity=1.0, absoluteUsedCapacity=1.0, numApps=5, numContainers=43
2013-08-10 17:24:49,205 INFO org.apache.hadoop.yarn.server.resourcemanager.scheduler.capacity.ParentQueue: assignedContainer queue=root usedCapacity=1.0 absoluteUsedCapacity=1.0 used=<memory:49152, vCores:43> cluster=<memory:49152, vCores:96>
2013-08-10 17:24:49,227 INFO org.apache.hadoop.yarn.server.resourcemanager.rmcontainer.RMContainerImpl: container_1376154442901_0010_01_000008 Container Transitioned from RUNNING to COMPLETED
2013-08-10 17:24:49,227 INFO org.apache.hadoop.yarn.server.resourcemanager.scheduler.common.fica.FiCaSchedulerApp: Completed container: container_1376154442901_0010_01_000008 in state: COMPLETED event:FINISHED
2013-08-10 17:24:49,227 INFO org.apache.hadoop.yarn.server.resourcemanager.RMAuditLogger: USER=ubuntu	OPERATION=AM Released Container	TARGET=SchedulerApp	RESULT=SUCCESS	APPID=application_1376154442901_0010	CONTAINERID=container_1376154442901_0010_01_000008
2013-08-10 17:24:49,227 INFO org.apache.hadoop.yarn.server.resourcemanager.scheduler.common.fica.FiCaSchedulerNode: Released container container_1376154442901_0010_01_000008 of capacity <memory:1024, vCores:1> on host hadoop-220-2:50762, which currently has 7 containers, <memory:7168, vCores:7> used and <memory:1024, vCores:9> available, release resources=true
2013-08-10 17:24:49,227 INFO org.apache.hadoop.yarn.server.resourcemanager.scheduler.capacity.LeafQueue: default used=<memory:48128, vCores:42> numContainers=42 user=ubuntu user-resources=<memory:48128, vCores:42>
2013-08-10 17:24:49,228 INFO org.apache.hadoop.yarn.server.resourcemanager.scheduler.capacity.LeafQueue: completedContainer container=Container: [ContainerId: container_1376154442901_0010_01_000008, NodeId: hadoop-220-2:50762, NodeHttpAddress: hadoop-220-2:8042, Resource: <memory:1024, vCores:1>, Priority: 20, State: NEW, Token: null, Status: container_id {, app_attempt_id {, application_id {, id: 10, cluster_timestamp: 1376154442901, }, attemptId: 1, }, id: 8, }, state: C_COMPLETE, diagnostics: "Container killed by the ApplicationMaster.\n\n", exit_status: 143, ] resource=<memory:1024, vCores:1> queue=default: capacity=1.0, absoluteCapacity=1.0, usedResources=<memory:48128, vCores:42>usedCapacity=0.9791667, absoluteUsedCapacity=0.9791667, numApps=5, numContainers=42 usedCapacity=0.9791667 absoluteUsedCapacity=0.9791667 used=<memory:48128, vCores:42> cluster=<memory:49152, vCores:96>
2013-08-10 17:24:49,228 INFO org.apache.hadoop.yarn.server.resourcemanager.scheduler.capacity.ParentQueue: completedContainer queue=root usedCapacity=0.9791667 absoluteUsedCapacity=0.9791667 used=<memory:48128, vCores:42> cluster=<memory:49152, vCores:96>
2013-08-10 17:24:49,228 INFO org.apache.hadoop.yarn.server.resourcemanager.scheduler.capacity.CapacityScheduler: Application appattempt_1376154442901_0010_000001 released container container_1376154442901_0010_01_000008 on node: host: hadoop-220-2:50762 #containers=7 available=1024 used=7168 with event: FINISHED
2013-08-10 17:24:49,229 INFO org.apache.hadoop.yarn.server.resourcemanager.rmcontainer.RMContainerImpl: container_1376154442901_0006_01_000019 Container Transitioned from NEW to ALLOCATED
2013-08-10 17:24:49,229 INFO org.apache.hadoop.yarn.server.resourcemanager.RMAuditLogger: USER=ubuntu	OPERATION=AM Allocated Container	TARGET=SchedulerApp	RESULT=SUCCESS	APPID=application_1376154442901_0006	CONTAINERID=container_1376154442901_0006_01_000019
2013-08-10 17:24:49,229 INFO org.apache.hadoop.yarn.server.resourcemanager.scheduler.common.fica.FiCaSchedulerNode: Assigned container container_1376154442901_0006_01_000019 of capacity <memory:1024, vCores:1> on host hadoop-220-2:50762, which currently has 8 containers, <memory:8192, vCores:8> used and <memory:0, vCores:8> available
2013-08-10 17:24:49,231 INFO org.apache.hadoop.yarn.server.resourcemanager.scheduler.capacity.LeafQueue: assignedContainer application=application_1376154442901_0006 container=Container: [ContainerId: container_1376154442901_0006_01_000019, NodeId: hadoop-220-2:50762, NodeHttpAddress: hadoop-220-2:8042, Resource: <memory:1024, vCores:1>, Priority: 20, State: NEW, Token: null, Status: container_id {, app_attempt_id {, application_id {, id: 6, cluster_timestamp: 1376154442901, }, attemptId: 1, }, id: 19, }, state: C_NEW, ] containerId=container_1376154442901_0006_01_000019 queue=default: capacity=1.0, absoluteCapacity=1.0, usedResources=<memory:48128, vCores:42>usedCapacity=0.9791667, absoluteUsedCapacity=0.9791667, numApps=5, numContainers=42 usedCapacity=0.9791667 absoluteUsedCapacity=0.9791667 used=<memory:48128, vCores:42> cluster=<memory:49152, vCores:96>
2013-08-10 17:24:49,231 INFO org.apache.hadoop.yarn.server.resourcemanager.scheduler.capacity.ParentQueue: Re-sorting queues since queue: root.default stats: default: capacity=1.0, absoluteCapacity=1.0, usedResources=<memory:49152, vCores:43>usedCapacity=1.0, absoluteUsedCapacity=1.0, numApps=5, numContainers=43
2013-08-10 17:24:49,231 INFO org.apache.hadoop.yarn.server.resourcemanager.scheduler.capacity.ParentQueue: assignedContainer queue=root usedCapacity=1.0 absoluteUsedCapacity=1.0 used=<memory:49152, vCores:43> cluster=<memory:49152, vCores:96>
2013-08-10 17:24:49,589 INFO org.apache.hadoop.yarn.server.resourcemanager.rmcontainer.RMContainerImpl: container_1376154442901_0006_01_000018 Container Transitioned from ALLOCATED to ACQUIRED
2013-08-10 17:24:49,591 INFO org.apache.hadoop.yarn.server.resourcemanager.rmcontainer.RMContainerImpl: container_1376154442901_0006_01_000019 Container Transitioned from ALLOCATED to ACQUIRED
2013-08-10 17:24:50,303 INFO org.apache.hadoop.yarn.server.resourcemanager.rmcontainer.RMContainerImpl: container_1376154442901_0006_01_000017 Container Transitioned from ACQUIRED to RUNNING
2013-08-10 17:24:51,254 INFO org.apache.hadoop.yarn.server.resourcemanager.rmcontainer.RMContainerImpl: container_1376154442901_0006_01_000019 Container Transitioned from ACQUIRED to RUNNING
2013-08-10 17:24:52,217 INFO org.apache.hadoop.yarn.server.resourcemanager.rmcontainer.RMContainerImpl: container_1376154442901_0006_01_000018 Container Transitioned from ACQUIRED to RUNNING
2013-08-10 17:24:52,611 INFO org.apache.hadoop.yarn.server.resourcemanager.rmcontainer.RMContainerImpl: container_1376154442901_0010_01_000005 Container Transitioned from RUNNING to COMPLETED
2013-08-10 17:24:52,611 INFO org.apache.hadoop.yarn.server.resourcemanager.scheduler.common.fica.FiCaSchedulerApp: Completed container: container_1376154442901_0010_01_000005 in state: COMPLETED event:FINISHED
2013-08-10 17:24:52,611 INFO org.apache.hadoop.yarn.server.resourcemanager.RMAuditLogger: USER=ubuntu	OPERATION=AM Released Container	TARGET=SchedulerApp	RESULT=SUCCESS	APPID=application_1376154442901_0010	CONTAINERID=container_1376154442901_0010_01_000005
2013-08-10 17:24:52,611 INFO org.apache.hadoop.yarn.server.resourcemanager.scheduler.common.fica.FiCaSchedulerNode: Released container container_1376154442901_0010_01_000005 of capacity <memory:1024, vCores:1> on host hadoop-220-3:58548, which currently has 6 containers, <memory:7168, vCores:6> used and <memory:1024, vCores:10> available, release resources=true
2013-08-10 17:24:52,611 INFO org.apache.hadoop.yarn.server.resourcemanager.scheduler.capacity.LeafQueue: default used=<memory:48128, vCores:42> numContainers=42 user=ubuntu user-resources=<memory:48128, vCores:42>
2013-08-10 17:24:52,612 INFO org.apache.hadoop.yarn.server.resourcemanager.scheduler.capacity.LeafQueue: completedContainer container=Container: [ContainerId: container_1376154442901_0010_01_000005, NodeId: hadoop-220-3:58548, NodeHttpAddress: hadoop-220-3:8042, Resource: <memory:1024, vCores:1>, Priority: 20, State: NEW, Token: null, Status: container_id {, app_attempt_id {, application_id {, id: 10, cluster_timestamp: 1376154442901, }, attemptId: 1, }, id: 5, }, state: C_COMPLETE, diagnostics: "Container killed by the ApplicationMaster.\n\n", exit_status: 143, ] resource=<memory:1024, vCores:1> queue=default: capacity=1.0, absoluteCapacity=1.0, usedResources=<memory:48128, vCores:42>usedCapacity=0.9791667, absoluteUsedCapacity=0.9791667, numApps=5, numContainers=42 usedCapacity=0.9791667 absoluteUsedCapacity=0.9791667 used=<memory:48128, vCores:42> cluster=<memory:49152, vCores:96>
2013-08-10 17:24:52,613 INFO org.apache.hadoop.yarn.server.resourcemanager.scheduler.capacity.ParentQueue: completedContainer queue=root usedCapacity=0.9791667 absoluteUsedCapacity=0.9791667 used=<memory:48128, vCores:42> cluster=<memory:49152, vCores:96>
2013-08-10 17:24:52,613 INFO org.apache.hadoop.yarn.server.resourcemanager.scheduler.capacity.CapacityScheduler: Application appattempt_1376154442901_0010_000001 released container container_1376154442901_0010_01_000005 on node: host: hadoop-220-3:58548 #containers=6 available=1024 used=7168 with event: FINISHED
2013-08-10 17:24:52,613 INFO org.apache.hadoop.yarn.server.resourcemanager.rmcontainer.RMContainerImpl: container_1376154442901_0010_01_000006 Container Transitioned from RUNNING to COMPLETED
2013-08-10 17:24:52,613 INFO org.apache.hadoop.yarn.server.resourcemanager.scheduler.common.fica.FiCaSchedulerApp: Completed container: container_1376154442901_0010_01_000006 in state: COMPLETED event:FINISHED
2013-08-10 17:24:52,613 INFO org.apache.hadoop.yarn.server.resourcemanager.RMAuditLogger: USER=ubuntu	OPERATION=AM Released Container	TARGET=SchedulerApp	RESULT=SUCCESS	APPID=application_1376154442901_0010	CONTAINERID=container_1376154442901_0010_01_000006
2013-08-10 17:24:52,613 INFO org.apache.hadoop.yarn.server.resourcemanager.scheduler.common.fica.FiCaSchedulerNode: Released container container_1376154442901_0010_01_000006 of capacity <memory:1024, vCores:1> on host hadoop-220-3:58548, which currently has 5 containers, <memory:6144, vCores:5> used and <memory:2048, vCores:11> available, release resources=true
2013-08-10 17:24:52,613 INFO org.apache.hadoop.yarn.server.resourcemanager.scheduler.capacity.LeafQueue: default used=<memory:47104, vCores:41> numContainers=41 user=ubuntu user-resources=<memory:47104, vCores:41>
2013-08-10 17:24:52,614 INFO org.apache.hadoop.yarn.server.resourcemanager.scheduler.capacity.LeafQueue: completedContainer container=Container: [ContainerId: container_1376154442901_0010_01_000006, NodeId: hadoop-220-3:58548, NodeHttpAddress: hadoop-220-3:8042, Resource: <memory:1024, vCores:1>, Priority: 20, State: NEW, Token: null, Status: container_id {, app_attempt_id {, application_id {, id: 10, cluster_timestamp: 1376154442901, }, attemptId: 1, }, id: 6, }, state: C_COMPLETE, diagnostics: "Container killed by the ApplicationMaster.\n\n", exit_status: 143, ] resource=<memory:1024, vCores:1> queue=default: capacity=1.0, absoluteCapacity=1.0, usedResources=<memory:47104, vCores:41>usedCapacity=0.9583333, absoluteUsedCapacity=0.9583333, numApps=5, numContainers=41 usedCapacity=0.9583333 absoluteUsedCapacity=0.9583333 used=<memory:47104, vCores:41> cluster=<memory:49152, vCores:96>
2013-08-10 17:24:52,614 INFO org.apache.hadoop.yarn.server.resourcemanager.scheduler.capacity.ParentQueue: completedContainer queue=root usedCapacity=0.9583333 absoluteUsedCapacity=0.9583333 used=<memory:47104, vCores:41> cluster=<memory:49152, vCores:96>
2013-08-10 17:24:52,615 INFO org.apache.hadoop.yarn.server.resourcemanager.scheduler.capacity.CapacityScheduler: Application appattempt_1376154442901_0010_000001 released container container_1376154442901_0010_01_000006 on node: host: hadoop-220-3:58548 #containers=5 available=2048 used=6144 with event: FINISHED
2013-08-10 17:24:52,615 INFO org.apache.hadoop.yarn.server.resourcemanager.rmcontainer.RMContainerImpl: container_1376154442901_0006_01_000020 Container Transitioned from NEW to ALLOCATED
2013-08-10 17:24:52,615 INFO org.apache.hadoop.yarn.server.resourcemanager.RMAuditLogger: USER=ubuntu	OPERATION=AM Allocated Container	TARGET=SchedulerApp	RESULT=SUCCESS	APPID=application_1376154442901_0006	CONTAINERID=container_1376154442901_0006_01_000020
2013-08-10 17:24:52,615 INFO org.apache.hadoop.yarn.server.resourcemanager.scheduler.common.fica.FiCaSchedulerNode: Assigned container container_1376154442901_0006_01_000020 of capacity <memory:1024, vCores:1> on host hadoop-220-3:58548, which currently has 6 containers, <memory:7168, vCores:6> used and <memory:1024, vCores:10> available
2013-08-10 17:24:52,619 INFO org.apache.hadoop.yarn.server.resourcemanager.scheduler.capacity.LeafQueue: assignedContainer application=application_1376154442901_0006 container=Container: [ContainerId: container_1376154442901_0006_01_000020, NodeId: hadoop-220-3:58548, NodeHttpAddress: hadoop-220-3:8042, Resource: <memory:1024, vCores:1>, Priority: 20, State: NEW, Token: null, Status: container_id {, app_attempt_id {, application_id {, id: 6, cluster_timestamp: 1376154442901, }, attemptId: 1, }, id: 20, }, state: C_NEW, ] containerId=container_1376154442901_0006_01_000020 queue=default: capacity=1.0, absoluteCapacity=1.0, usedResources=<memory:47104, vCores:41>usedCapacity=0.9583333, absoluteUsedCapacity=0.9583333, numApps=5, numContainers=41 usedCapacity=0.9583333 absoluteUsedCapacity=0.9583333 used=<memory:47104, vCores:41> cluster=<memory:49152, vCores:96>
2013-08-10 17:24:52,619 INFO org.apache.hadoop.yarn.server.resourcemanager.scheduler.capacity.ParentQueue: Re-sorting queues since queue: root.default stats: default: capacity=1.0, absoluteCapacity=1.0, usedResources=<memory:48128, vCores:42>usedCapacity=0.9791667, absoluteUsedCapacity=0.9791667, numApps=5, numContainers=42
2013-08-10 17:24:52,620 INFO org.apache.hadoop.yarn.server.resourcemanager.scheduler.capacity.ParentQueue: assignedContainer queue=root usedCapacity=0.9791667 absoluteUsedCapacity=0.9791667 used=<memory:48128, vCores:42> cluster=<memory:49152, vCores:96>
2013-08-10 17:24:52,620 INFO org.apache.hadoop.yarn.server.resourcemanager.rmcontainer.RMContainerImpl: container_1376154442901_0006_01_000021 Container Transitioned from NEW to ALLOCATED
2013-08-10 17:24:52,620 INFO org.apache.hadoop.yarn.server.resourcemanager.RMAuditLogger: USER=ubuntu	OPERATION=AM Allocated Container	TARGET=SchedulerApp	RESULT=SUCCESS	APPID=application_1376154442901_0006	CONTAINERID=container_1376154442901_0006_01_000021
2013-08-10 17:24:52,620 INFO org.apache.hadoop.yarn.server.resourcemanager.scheduler.common.fica.FiCaSchedulerNode: Assigned container container_1376154442901_0006_01_000021 of capacity <memory:1024, vCores:1> on host hadoop-220-3:58548, which currently has 7 containers, <memory:8192, vCores:7> used and <memory:0, vCores:9> available
2013-08-10 17:24:52,621 INFO org.apache.hadoop.yarn.server.resourcemanager.scheduler.capacity.LeafQueue: assignedContainer application=application_1376154442901_0006 container=Container: [ContainerId: container_1376154442901_0006_01_000021, NodeId: hadoop-220-3:58548, NodeHttpAddress: hadoop-220-3:8042, Resource: <memory:1024, vCores:1>, Priority: 20, State: NEW, Token: null, Status: container_id {, app_attempt_id {, application_id {, id: 6, cluster_timestamp: 1376154442901, }, attemptId: 1, }, id: 21, }, state: C_NEW, ] containerId=container_1376154442901_0006_01_000021 queue=default: capacity=1.0, absoluteCapacity=1.0, usedResources=<memory:48128, vCores:42>usedCapacity=0.9791667, absoluteUsedCapacity=0.9791667, numApps=5, numContainers=42 usedCapacity=0.9791667 absoluteUsedCapacity=0.9791667 used=<memory:48128, vCores:42> cluster=<memory:49152, vCores:96>
2013-08-10 17:24:52,622 INFO org.apache.hadoop.yarn.server.resourcemanager.scheduler.capacity.ParentQueue: Re-sorting queues since queue: root.default stats: default: capacity=1.0, absoluteCapacity=1.0, usedResources=<memory:49152, vCores:43>usedCapacity=1.0, absoluteUsedCapacity=1.0, numApps=5, numContainers=43
2013-08-10 17:24:52,622 INFO org.apache.hadoop.yarn.server.resourcemanager.scheduler.capacity.ParentQueue: assignedContainer queue=root usedCapacity=1.0 absoluteUsedCapacity=1.0 used=<memory:49152, vCores:43> cluster=<memory:49152, vCores:96>
2013-08-10 17:24:53,280 INFO org.apache.hadoop.yarn.server.resourcemanager.rmcontainer.RMContainerImpl: container_1376154442901_0010_01_000031 Container Transitioned from RUNNING to COMPLETED
2013-08-10 17:24:53,280 INFO org.apache.hadoop.yarn.server.resourcemanager.scheduler.common.fica.FiCaSchedulerApp: Completed container: container_1376154442901_0010_01_000031 in state: COMPLETED event:FINISHED
2013-08-10 17:24:53,280 INFO org.apache.hadoop.yarn.server.resourcemanager.RMAuditLogger: USER=ubuntu	OPERATION=AM Released Container	TARGET=SchedulerApp	RESULT=SUCCESS	APPID=application_1376154442901_0010	CONTAINERID=container_1376154442901_0010_01_000031
2013-08-10 17:24:53,281 INFO org.apache.hadoop.yarn.server.resourcemanager.scheduler.common.fica.FiCaSchedulerNode: Released container container_1376154442901_0010_01_000031 of capacity <memory:1024, vCores:1> on host hadoop-220-4:35716, which currently has 6 containers, <memory:7168, vCores:6> used and <memory:1024, vCores:10> available, release resources=true
2013-08-10 17:24:53,281 INFO org.apache.hadoop.yarn.server.resourcemanager.scheduler.capacity.LeafQueue: default used=<memory:48128, vCores:42> numContainers=42 user=ubuntu user-resources=<memory:48128, vCores:42>
2013-08-10 17:24:53,282 INFO org.apache.hadoop.yarn.server.resourcemanager.scheduler.capacity.LeafQueue: completedContainer container=Container: [ContainerId: container_1376154442901_0010_01_000031, NodeId: hadoop-220-4:35716, NodeHttpAddress: hadoop-220-4:8042, Resource: <memory:1024, vCores:1>, Priority: 20, State: NEW, Token: null, Status: container_id {, app_attempt_id {, application_id {, id: 10, cluster_timestamp: 1376154442901, }, attemptId: 1, }, id: 31, }, state: C_COMPLETE, diagnostics: "Container killed by the ApplicationMaster.\n", exit_status: 0, ] resource=<memory:1024, vCores:1> queue=default: capacity=1.0, absoluteCapacity=1.0, usedResources=<memory:48128, vCores:42>usedCapacity=0.9791667, absoluteUsedCapacity=0.9791667, numApps=5, numContainers=42 usedCapacity=0.9791667 absoluteUsedCapacity=0.9791667 used=<memory:48128, vCores:42> cluster=<memory:49152, vCores:96>
2013-08-10 17:24:53,282 INFO org.apache.hadoop.yarn.server.resourcemanager.scheduler.capacity.ParentQueue: completedContainer queue=root usedCapacity=0.9791667 absoluteUsedCapacity=0.9791667 used=<memory:48128, vCores:42> cluster=<memory:49152, vCores:96>
2013-08-10 17:24:53,282 INFO org.apache.hadoop.yarn.server.resourcemanager.scheduler.capacity.CapacityScheduler: Application appattempt_1376154442901_0010_000001 released container container_1376154442901_0010_01_000031 on node: host: hadoop-220-4:35716 #containers=6 available=1024 used=7168 with event: FINISHED
2013-08-10 17:24:53,283 INFO org.apache.hadoop.yarn.server.resourcemanager.rmcontainer.RMContainerImpl: container_1376154442901_0006_01_000022 Container Transitioned from NEW to ALLOCATED
2013-08-10 17:24:53,283 INFO org.apache.hadoop.yarn.server.resourcemanager.RMAuditLogger: USER=ubuntu	OPERATION=AM Allocated Container	TARGET=SchedulerApp	RESULT=SUCCESS	APPID=application_1376154442901_0006	CONTAINERID=container_1376154442901_0006_01_000022
2013-08-10 17:24:53,283 INFO org.apache.hadoop.yarn.server.resourcemanager.scheduler.common.fica.FiCaSchedulerNode: Assigned container container_1376154442901_0006_01_000022 of capacity <memory:1024, vCores:1> on host hadoop-220-4:35716, which currently has 7 containers, <memory:8192, vCores:7> used and <memory:0, vCores:9> available
2013-08-10 17:24:53,284 INFO org.apache.hadoop.yarn.server.resourcemanager.scheduler.capacity.LeafQueue: assignedContainer application=application_1376154442901_0006 container=Container: [ContainerId: container_1376154442901_0006_01_000022, NodeId: hadoop-220-4:35716, NodeHttpAddress: hadoop-220-4:8042, Resource: <memory:1024, vCores:1>, Priority: 20, State: NEW, Token: null, Status: container_id {, app_attempt_id {, application_id {, id: 6, cluster_timestamp: 1376154442901, }, attemptId: 1, }, id: 22, }, state: C_NEW, ] containerId=container_1376154442901_0006_01_000022 queue=default: capacity=1.0, absoluteCapacity=1.0, usedResources=<memory:48128, vCores:42>usedCapacity=0.9791667, absoluteUsedCapacity=0.9791667, numApps=5, numContainers=42 usedCapacity=0.9791667 absoluteUsedCapacity=0.9791667 used=<memory:48128, vCores:42> cluster=<memory:49152, vCores:96>
