2013-08-09 12:09:08,995 INFO org.apache.hadoop.yarn.server.resourcemanager.ResourceManager: STARTUP_MSG: 
/************************************************************
STARTUP_MSG: Starting ResourceManager
STARTUP_MSG:   host = hadoop-210-1/192.168.100.4
STARTUP_MSG:   args = []
STARTUP_MSG:   version = 3.0.0-SNAPSHOT
STARTUP_MSG:   build = https://github.com/lalithsuresh/hadoop-common -r 0cb423bd4868928bb06cd93f882bb0913172fd17; compiled by 'lsuresh' on 2013-04-08T15:47Z
STARTUP_MSG:   java = 1.7.0_17
************************************************************/
2013-08-09 12:09:09,009 INFO org.apache.hadoop.yarn.server.resourcemanager.ResourceManager: registered UNIX signal handlers for [TERM, HUP, INT]
2013-08-09 12:09:09,735 INFO org.apache.hadoop.yarn.server.resourcemanager.security.ApplicationTokenSecretManager: Rolling master-key for application-tokens
2013-08-09 12:09:09,796 INFO org.apache.hadoop.yarn.server.resourcemanager.security.RMContainerTokenSecretManager: ContainerTokenKeyRollingInterval: 86400000ms and ContainerTokenKeyActivationDelay: 900000ms
2013-08-09 12:09:09,801 INFO org.apache.hadoop.yarn.service.AbstractService: Service:Dispatcher is inited.
2013-08-09 12:09:09,804 INFO org.apache.hadoop.yarn.event.AsyncDispatcher: Registering class org.apache.hadoop.yarn.server.resourcemanager.recovery.RMStateStoreEventType for class org.apache.hadoop.yarn.server.resourcemanager.recovery.RMStateStore$ForwardingEventHandler
2013-08-09 12:09:09,804 INFO org.apache.hadoop.yarn.service.AbstractService: Service:Dispatcher is started.
2013-08-09 12:09:09,814 INFO org.apache.hadoop.yarn.event.AsyncDispatcher: Registering class org.apache.hadoop.yarn.server.resourcemanager.NodesListManagerEventType for class org.apache.hadoop.yarn.server.resourcemanager.NodesListManager
2013-08-09 12:09:09,814 INFO org.apache.hadoop.yarn.server.resourcemanager.ResourceManager: Using Scheduler: org.apache.hadoop.yarn.server.resourcemanager.scheduler.capacity.CapacityScheduler
2013-08-09 12:09:10,115 INFO org.apache.hadoop.yarn.event.AsyncDispatcher: Registering class org.apache.hadoop.yarn.server.resourcemanager.scheduler.event.SchedulerEventType for class org.apache.hadoop.yarn.server.resourcemanager.ResourceManager$SchedulerEventDispatcher
2013-08-09 12:09:10,118 INFO org.apache.hadoop.yarn.event.AsyncDispatcher: Registering class org.apache.hadoop.yarn.server.resourcemanager.rmapp.RMAppEventType for class org.apache.hadoop.yarn.server.resourcemanager.ResourceManager$ApplicationEventDispatcher
2013-08-09 12:09:10,121 INFO org.apache.hadoop.yarn.event.AsyncDispatcher: Registering class org.apache.hadoop.yarn.server.resourcemanager.rmapp.attempt.RMAppAttemptEventType for class org.apache.hadoop.yarn.server.resourcemanager.ResourceManager$ApplicationAttemptEventDispatcher
2013-08-09 12:09:10,124 INFO org.apache.hadoop.yarn.event.AsyncDispatcher: Registering class org.apache.hadoop.yarn.server.resourcemanager.rmnode.RMNodeEventType for class org.apache.hadoop.yarn.server.resourcemanager.ResourceManager$NodeEventDispatcher
2013-08-09 12:09:10,825 WARN org.apache.hadoop.util.NativeCodeLoader: Unable to load native-hadoop library for your platform... using builtin-java classes where applicable
2013-08-09 12:09:10,884 INFO org.apache.hadoop.yarn.server.resourcemanager.scheduler.capacity.ParentQueue: root, capacity=1.0, asboluteCapacity=1.0, maxCapacity=1.0, asboluteMaxCapacity=1.0, state=RUNNING, acls=ADMINISTER_QUEUE:*SUBMIT_APPLICATIONS:*
2013-08-09 12:09:10,885 INFO org.apache.hadoop.yarn.server.resourcemanager.scheduler.capacity.ParentQueue: Initialized parent-queue root name=root, fullname=root
2013-08-09 12:09:10,903 INFO org.apache.hadoop.yarn.server.resourcemanager.scheduler.capacity.LeafQueue: Initializing default
capacity = 1.0 [= (float) configuredCapacity / 100 ]
asboluteCapacity = 1.0 [= parentAbsoluteCapacity * capacity ]
maxCapacity = 1.0 [= configuredMaxCapacity ]
absoluteMaxCapacity = 1.0 [= 1.0 maximumCapacity undefined, (parentAbsoluteMaxCapacity * maximumCapacity) / 100 otherwise ]
userLimit = 100 [= configuredUserLimit ]
userLimitFactor = 1.0 [= configuredUserLimitFactor ]
maxApplications = 10000 [= configuredMaximumSystemApplicationsPerQueue or (int)(configuredMaximumSystemApplications * absoluteCapacity)]
maxApplicationsPerUser = 10000 [= (int)(maxApplications * (userLimit / 100.0f) * userLimitFactor) ]
maxActiveApplications = 1 [= max((int)ceil((clusterResourceMemory / minimumAllocation) * maxAMResourcePerQueuePercent * absoluteMaxCapacity),1) ]
maxActiveAppsUsingAbsCap = 1 [= max((int)ceil((clusterResourceMemory / minimumAllocation) *maxAMResourcePercent * absoluteCapacity),1) ]
maxActiveApplicationsPerUser = 1 [= max((int)(maxActiveApplications * (userLimit / 100.0f) * userLimitFactor),1) ]
usedCapacity = 0.0 [= usedResourcesMemory / (clusterResourceMemory * absoluteCapacity)]
absoluteUsedCapacity = 0.0 [= usedResourcesMemory / clusterResourceMemory]
maxAMResourcePerQueuePercent = 0.1 [= configuredMaximumAMResourcePercent ]
minimumAllocationFactor = 0.875 [= (float)(maximumAllocationMemory - minimumAllocationMemory) / maximumAllocationMemory ]
numContainers = 0 [= currentNumContainers ]
state = RUNNING [= configuredState ]
acls = ADMINISTER_QUEUE:*SUBMIT_APPLICATIONS:* [= configuredAcls ]

2013-08-09 12:09:10,903 INFO org.apache.hadoop.yarn.server.resourcemanager.scheduler.capacity.CapacityScheduler: Initialized queue: default: capacity=1.0, absoluteCapacity=1.0, usedResources=<memory:0, vCores:0>usedCapacity=0.0, absoluteUsedCapacity=0.0, numApps=0, numContainers=0
2013-08-09 12:09:10,903 INFO org.apache.hadoop.yarn.server.resourcemanager.scheduler.capacity.CapacityScheduler: Initialized queue: root: numChildQueue= 1, capacity=1.0, absoluteCapacity=1.0, usedResources=<memory:0, vCores:0>usedCapacity=0.0, numApps=0, numContainers=0
2013-08-09 12:09:10,903 INFO org.apache.hadoop.yarn.server.resourcemanager.scheduler.capacity.CapacityScheduler: Initialized root queue root: numChildQueue= 1, capacity=1.0, absoluteCapacity=1.0, usedResources=<memory:0, vCores:0>usedCapacity=0.0, numApps=0, numContainers=0
2013-08-09 12:09:10,903 INFO org.apache.hadoop.yarn.server.resourcemanager.scheduler.capacity.CapacityScheduler: Initialized CapacityScheduler with calculator=class org.apache.hadoop.yarn.server.resourcemanager.resource.DefaultResourceCalculator, minimumAllocation=<<memory:1024, vCores:1>>, maximumAllocation=<<memory:8192, vCores:32>>
2013-08-09 12:09:11,370 INFO org.apache.hadoop.yarn.event.AsyncDispatcher: Registering class org.apache.hadoop.yarn.server.resourcemanager.RMAppManagerEventType for class org.apache.hadoop.yarn.server.resourcemanager.RMAppManager
2013-08-09 12:09:11,388 INFO org.apache.hadoop.yarn.event.AsyncDispatcher: Registering class org.apache.hadoop.yarn.server.resourcemanager.amlauncher.AMLauncherEventType for class org.apache.hadoop.yarn.server.resourcemanager.amlauncher.ApplicationMasterLauncher
2013-08-09 12:09:11,467 INFO org.apache.hadoop.yarn.server.resourcemanager.RMNMInfo: Registered RMNMInfo MBean
2013-08-09 12:09:11,468 INFO org.apache.hadoop.yarn.service.AbstractService: Service:Dispatcher is inited.
2013-08-09 12:09:11,468 INFO org.apache.hadoop.yarn.service.AbstractService: Service:org.apache.hadoop.yarn.server.resourcemanager.rmcontainer.ContainerAllocationExpirer is inited.
2013-08-09 12:09:11,468 INFO org.apache.hadoop.yarn.service.AbstractService: Service:AMLivelinessMonitor is inited.
2013-08-09 12:09:11,468 INFO org.apache.hadoop.yarn.service.AbstractService: Service:AMLivelinessMonitor is inited.
2013-08-09 12:09:11,468 INFO org.apache.hadoop.yarn.service.AbstractService: Service:org.apache.hadoop.yarn.server.resourcemanager.security.DelegationTokenRenewer is inited.
2013-08-09 12:09:11,469 INFO org.apache.hadoop.util.HostsFileReader: Refreshing hosts (include/exclude) list
2013-08-09 12:09:11,470 INFO org.apache.hadoop.yarn.service.AbstractService: Service:org.apache.hadoop.yarn.server.resourcemanager.NodesListManager is inited.
2013-08-09 12:09:11,470 INFO org.apache.hadoop.yarn.service.AbstractService: Service:org.apache.hadoop.yarn.server.resourcemanager.ResourceManager$SchedulerEventDispatcher is inited.
2013-08-09 12:09:11,470 INFO org.apache.hadoop.yarn.service.AbstractService: Service:NMLivelinessMonitor is inited.
2013-08-09 12:09:11,476 INFO org.apache.hadoop.yarn.service.AbstractService: Service:org.apache.hadoop.yarn.server.resourcemanager.ResourceTrackerService is inited.
2013-08-09 12:09:11,476 INFO org.apache.hadoop.yarn.service.AbstractService: Service:org.apache.hadoop.yarn.server.resourcemanager.ApplicationMasterService is inited.
2013-08-09 12:09:11,476 INFO org.apache.hadoop.yarn.service.AbstractService: Service:org.apache.hadoop.yarn.server.resourcemanager.ClientRMService is inited.
2013-08-09 12:09:11,476 INFO org.apache.hadoop.yarn.service.AbstractService: Service:org.apache.hadoop.yarn.server.resourcemanager.AdminService is inited.
2013-08-09 12:09:11,477 INFO org.apache.hadoop.yarn.service.AbstractService: Service:org.apache.hadoop.yarn.server.resourcemanager.amlauncher.ApplicationMasterLauncher is inited.
2013-08-09 12:09:11,477 INFO org.apache.hadoop.yarn.service.AbstractService: Service:ResourceManager is inited.
2013-08-09 12:09:11,477 INFO org.apache.hadoop.yarn.server.resourcemanager.security.RMContainerTokenSecretManager: Rolling master-key for container-tokens
2013-08-09 12:09:11,477 INFO org.apache.hadoop.yarn.server.resourcemanager.security.ApplicationTokenSecretManager: Rolling master-key for application-tokens
2013-08-09 12:09:11,604 INFO org.mortbay.log: Logging to org.slf4j.impl.Log4jLoggerAdapter(org.mortbay.log) via org.mortbay.log.Slf4jLog
2013-08-09 12:09:11,671 INFO org.apache.hadoop.http.HttpServer: Added global filter 'safety' (class=org.apache.hadoop.http.HttpServer$QuotingInputFilter)
2013-08-09 12:09:11,674 INFO org.apache.hadoop.http.HttpServer: Added filter static_user_filter (class=org.apache.hadoop.http.lib.StaticUserWebFilter$StaticUserFilter) to context cluster
2013-08-09 12:09:11,674 INFO org.apache.hadoop.http.HttpServer: Added filter static_user_filter (class=org.apache.hadoop.http.lib.StaticUserWebFilter$StaticUserFilter) to context static
2013-08-09 12:09:11,674 INFO org.apache.hadoop.http.HttpServer: Added filter static_user_filter (class=org.apache.hadoop.http.lib.StaticUserWebFilter$StaticUserFilter) to context logs
2013-08-09 12:09:11,679 INFO org.apache.hadoop.http.HttpServer: adding path spec: /cluster
2013-08-09 12:09:11,679 INFO org.apache.hadoop.http.HttpServer: adding path spec: /cluster/*
2013-08-09 12:09:11,679 INFO org.apache.hadoop.http.HttpServer: adding path spec: /ws
2013-08-09 12:09:11,679 INFO org.apache.hadoop.http.HttpServer: adding path spec: /ws/*
2013-08-09 12:09:11,681 INFO org.apache.hadoop.http.HttpServer: Added global filter 'guice' (class=com.google.inject.servlet.GuiceFilter)
2013-08-09 12:09:11,688 INFO org.apache.hadoop.http.HttpServer: Jetty bound to port 8088
2013-08-09 12:09:11,688 INFO org.mortbay.log: jetty-6.1.26
2013-08-09 12:09:11,723 INFO org.mortbay.log: Extract jar:file:/home/ubuntu/hadoop-3.0.0-SNAPSHOT/share/hadoop/yarn/hadoop-yarn-common-3.0.0-SNAPSHOT.jar!/webapps/cluster to /tmp/Jetty_0_0_0_0_8088_cluster____u0rgz3/webapp
2013-08-09 12:09:12,049 INFO org.mortbay.log: Started SelectChannelConnector@0.0.0.0:8088
2013-08-09 12:09:12,049 INFO org.apache.hadoop.yarn.webapp.WebApps: Web app /cluster started at 8088
2013-08-09 12:09:12,550 INFO org.apache.hadoop.yarn.webapp.WebApps: Registered webapp guice modules
2013-08-09 12:09:12,612 INFO org.apache.hadoop.metrics2.impl.MetricsConfig: loaded properties from hadoop-metrics2.properties
2013-08-09 12:09:12,631 INFO org.apache.hadoop.metrics2.impl.MetricsSystemImpl: Scheduled snapshot period at 10 second(s).
2013-08-09 12:09:12,631 INFO org.apache.hadoop.metrics2.impl.MetricsSystemImpl: ResourceManager metrics system started
2013-08-09 12:09:12,640 INFO org.apache.hadoop.security.token.delegation.AbstractDelegationTokenSecretManager: Updating the current master key for generating delegation tokens
2013-08-09 12:09:12,642 INFO org.apache.hadoop.yarn.service.AbstractService: Service:Dispatcher is started.
2013-08-09 12:09:12,642 INFO org.apache.hadoop.security.token.delegation.AbstractDelegationTokenSecretManager: Starting expired delegation token remover thread, tokenRemoverScanInterval=60 min(s)
2013-08-09 12:09:12,642 INFO org.apache.hadoop.security.token.delegation.AbstractDelegationTokenSecretManager: Updating the current master key for generating delegation tokens
2013-08-09 12:09:12,643 INFO org.apache.hadoop.yarn.service.AbstractService: Service:org.apache.hadoop.yarn.server.resourcemanager.rmcontainer.ContainerAllocationExpirer is started.
2013-08-09 12:09:12,644 INFO org.apache.hadoop.yarn.service.AbstractService: Service:AMLivelinessMonitor is started.
2013-08-09 12:09:12,644 INFO org.apache.hadoop.yarn.service.AbstractService: Service:AMLivelinessMonitor is started.
2013-08-09 12:09:12,644 INFO org.apache.hadoop.yarn.service.AbstractService: Service:org.apache.hadoop.yarn.server.resourcemanager.security.DelegationTokenRenewer is started.
2013-08-09 12:09:12,645 INFO org.apache.hadoop.yarn.service.AbstractService: Service:org.apache.hadoop.yarn.server.resourcemanager.NodesListManager is started.
2013-08-09 12:09:12,646 INFO org.apache.hadoop.yarn.service.AbstractService: Service:org.apache.hadoop.yarn.server.resourcemanager.ResourceManager$SchedulerEventDispatcher is started.
2013-08-09 12:09:12,646 INFO org.apache.hadoop.yarn.service.AbstractService: Service:NMLivelinessMonitor is started.
2013-08-09 12:09:12,646 INFO org.apache.hadoop.yarn.service.AbstractService: Service:org.apache.hadoop.yarn.server.resourcemanager.ResourceTrackerService is started.
2013-08-09 12:09:12,688 INFO org.apache.hadoop.ipc.Server: Starting Socket Reader #1 for port 54110
2013-08-09 12:09:12,710 INFO org.apache.hadoop.yarn.factories.impl.pb.RpcServerFactoryPBImpl: Adding protocol org.apache.hadoop.yarn.server.api.ResourceTrackerPB to the server
2013-08-09 12:09:12,711 INFO org.apache.hadoop.ipc.Server: IPC Server Responder: starting
2013-08-09 12:09:12,712 INFO org.apache.hadoop.ipc.Server: IPC Server listener on 54110: starting
2013-08-09 12:09:12,820 INFO org.apache.hadoop.ipc.Server: Starting Socket Reader #1 for port 54112
2013-08-09 12:09:12,841 INFO org.apache.hadoop.yarn.factories.impl.pb.RpcServerFactoryPBImpl: Adding protocol org.apache.hadoop.yarn.api.AMRMProtocolPB to the server
2013-08-09 12:09:12,842 INFO org.apache.hadoop.ipc.Server: IPC Server Responder: starting
2013-08-09 12:09:12,844 INFO org.apache.hadoop.ipc.Server: IPC Server listener on 54112: starting
2013-08-09 12:09:12,877 INFO org.apache.hadoop.yarn.service.AbstractService: Service:org.apache.hadoop.yarn.server.resourcemanager.ApplicationMasterService is started.
2013-08-09 12:09:12,905 INFO org.apache.hadoop.ipc.Server: Starting Socket Reader #1 for port 54111
2013-08-09 12:09:12,915 INFO org.apache.hadoop.yarn.factories.impl.pb.RpcServerFactoryPBImpl: Adding protocol org.apache.hadoop.yarn.api.ClientRMProtocolPB to the server
2013-08-09 12:09:12,916 INFO org.apache.hadoop.ipc.Server: IPC Server Responder: starting
2013-08-09 12:09:12,916 INFO org.apache.hadoop.ipc.Server: IPC Server listener on 54111: starting
2013-08-09 12:09:12,959 INFO org.apache.hadoop.yarn.service.AbstractService: Service:org.apache.hadoop.yarn.server.resourcemanager.ClientRMService is started.
2013-08-09 12:09:12,977 INFO org.apache.hadoop.ipc.Server: Starting Socket Reader #1 for port 8033
2013-08-09 12:09:12,980 INFO org.apache.hadoop.yarn.factories.impl.pb.RpcServerFactoryPBImpl: Adding protocol org.apache.hadoop.yarn.api.RMAdminProtocolPB to the server
2013-08-09 12:09:12,981 INFO org.apache.hadoop.ipc.Server: IPC Server Responder: starting
2013-08-09 12:09:12,982 INFO org.apache.hadoop.yarn.service.AbstractService: Service:org.apache.hadoop.yarn.server.resourcemanager.AdminService is started.
2013-08-09 12:09:12,983 INFO org.apache.hadoop.ipc.Server: IPC Server listener on 8033: starting
2013-08-09 12:09:12,983 INFO org.apache.hadoop.yarn.service.AbstractService: Service:org.apache.hadoop.yarn.server.resourcemanager.amlauncher.ApplicationMasterLauncher is started.
2013-08-09 12:09:12,983 INFO org.apache.hadoop.yarn.service.AbstractService: Service:ResourceManager is started.
2013-08-09 12:09:23,522 INFO org.apache.hadoop.yarn.util.RackResolver: Resolved hadoop-210-6 to /default-rack
2013-08-09 12:09:23,522 INFO org.apache.hadoop.yarn.util.RackResolver: Resolved hadoop-210-7 to /default-rack
2013-08-09 12:09:23,522 INFO org.apache.hadoop.yarn.util.RackResolver: Resolved hadoop-210-5 to /default-rack
2013-08-09 12:09:23,525 INFO org.apache.hadoop.yarn.util.RackResolver: Resolved hadoop-210-3 to /default-rack
2013-08-09 12:09:23,533 INFO org.apache.hadoop.yarn.server.resourcemanager.ResourceTrackerService: NodeManager from node hadoop-210-6(cmPort: 38267 httpPort: 8042) registered with capability: <memory:8192, vCores:16>, assigned nodeId hadoop-210-6:38267
2013-08-09 12:09:23,533 INFO org.apache.hadoop.yarn.server.resourcemanager.ResourceTrackerService: NodeManager from node hadoop-210-7(cmPort: 41457 httpPort: 8042) registered with capability: <memory:8192, vCores:16>, assigned nodeId hadoop-210-7:41457
2013-08-09 12:09:23,534 INFO org.apache.hadoop.yarn.util.RackResolver: Resolved hadoop-210-4 to /default-rack
2013-08-09 12:09:23,533 INFO org.apache.hadoop.yarn.server.resourcemanager.ResourceTrackerService: NodeManager from node hadoop-210-3(cmPort: 36255 httpPort: 8042) registered with capability: <memory:8192, vCores:16>, assigned nodeId hadoop-210-3:36255
2013-08-09 12:09:23,534 INFO org.apache.hadoop.yarn.util.RackResolver: Resolved hadoop-210-2 to /default-rack
2013-08-09 12:09:23,534 INFO org.apache.hadoop.yarn.server.resourcemanager.ResourceTrackerService: NodeManager from node hadoop-210-5(cmPort: 60822 httpPort: 8042) registered with capability: <memory:8192, vCores:16>, assigned nodeId hadoop-210-5:60822
2013-08-09 12:09:23,535 INFO org.apache.hadoop.yarn.server.resourcemanager.ResourceTrackerService: NodeManager from node hadoop-210-2(cmPort: 40150 httpPort: 8042) registered with capability: <memory:8192, vCores:16>, assigned nodeId hadoop-210-2:40150
2013-08-09 12:09:23,536 INFO org.apache.hadoop.yarn.server.resourcemanager.ResourceTrackerService: NodeManager from node hadoop-210-4(cmPort: 57908 httpPort: 8042) registered with capability: <memory:8192, vCores:16>, assigned nodeId hadoop-210-4:57908
2013-08-09 12:09:23,552 INFO org.apache.hadoop.yarn.server.resourcemanager.rmnode.RMNodeImpl: hadoop-210-6:38267 Node Transitioned from NEW to RUNNING
2013-08-09 12:09:23,553 INFO org.apache.hadoop.yarn.server.resourcemanager.rmnode.RMNodeImpl: hadoop-210-3:36255 Node Transitioned from NEW to RUNNING
2013-08-09 12:09:23,553 INFO org.apache.hadoop.yarn.server.resourcemanager.rmnode.RMNodeImpl: hadoop-210-7:41457 Node Transitioned from NEW to RUNNING
2013-08-09 12:09:23,560 INFO org.apache.hadoop.yarn.server.resourcemanager.rmnode.RMNodeImpl: hadoop-210-5:60822 Node Transitioned from NEW to RUNNING
2013-08-09 12:09:23,560 INFO org.apache.hadoop.yarn.server.resourcemanager.rmnode.RMNodeImpl: hadoop-210-2:40150 Node Transitioned from NEW to RUNNING
2013-08-09 12:09:23,561 INFO org.apache.hadoop.yarn.server.resourcemanager.rmnode.RMNodeImpl: hadoop-210-4:57908 Node Transitioned from NEW to RUNNING
2013-08-09 12:09:23,565 INFO org.apache.hadoop.yarn.server.resourcemanager.scheduler.capacity.CapacityScheduler: Added node hadoop-210-6:38267 clusterResource: <memory:8192, vCores:16>
2013-08-09 12:09:23,566 INFO org.apache.hadoop.yarn.server.resourcemanager.scheduler.capacity.CapacityScheduler: Added node hadoop-210-3:36255 clusterResource: <memory:16384, vCores:32>
2013-08-09 12:09:23,566 INFO org.apache.hadoop.yarn.server.resourcemanager.scheduler.capacity.CapacityScheduler: Added node hadoop-210-7:41457 clusterResource: <memory:24576, vCores:48>
2013-08-09 12:09:23,566 INFO org.apache.hadoop.yarn.server.resourcemanager.scheduler.capacity.CapacityScheduler: Added node hadoop-210-5:60822 clusterResource: <memory:32768, vCores:64>
2013-08-09 12:09:23,566 INFO org.apache.hadoop.yarn.server.resourcemanager.scheduler.capacity.CapacityScheduler: Added node hadoop-210-2:40150 clusterResource: <memory:40960, vCores:80>
2013-08-09 12:09:23,567 INFO org.apache.hadoop.yarn.server.resourcemanager.scheduler.capacity.CapacityScheduler: Added node hadoop-210-4:57908 clusterResource: <memory:49152, vCores:96>
2013-08-09 12:11:28,809 INFO org.apache.hadoop.yarn.server.resourcemanager.ClientRMService: Allocated new applicationId: 1
2013-08-09 12:11:32,158 INFO org.apache.hadoop.yarn.server.resourcemanager.ClientRMService: Storing Application with id application_1376050148932_0001
2013-08-09 12:11:32,161 INFO org.apache.hadoop.yarn.server.resourcemanager.recovery.RMStateStore: Storing info for app: application_1376050148932_0001
2013-08-09 12:11:32,161 INFO org.apache.hadoop.yarn.server.resourcemanager.ClientRMService: Application with id 1 submitted by user ubuntu
2013-08-09 12:11:32,165 INFO org.apache.hadoop.yarn.server.resourcemanager.RMAuditLogger: USER=ubuntu	IP=192.168.100.4	OPERATION=Submit Application Request	TARGET=ClientRMService	RESULT=SUCCESS	APPID=application_1376050148932_0001
2013-08-09 12:11:32,212 INFO org.apache.hadoop.yarn.server.resourcemanager.rmapp.RMAppImpl: application_1376050148932_0001 State change from NEW to SUBMITTED
2013-08-09 12:11:32,213 INFO org.apache.hadoop.yarn.server.resourcemanager.ApplicationMasterService: Registering appattempt_1376050148932_0001_000001
2013-08-09 12:11:32,214 INFO org.apache.hadoop.yarn.server.resourcemanager.rmapp.attempt.RMAppAttemptImpl: appattempt_1376050148932_0001_000001 State change from NEW to SUBMITTED
2013-08-09 12:11:32,248 INFO org.apache.hadoop.yarn.server.resourcemanager.scheduler.capacity.LeafQueue: Application application_1376050148932_0001 from user: ubuntu activated in queue: default
2013-08-09 12:11:32,249 INFO org.apache.hadoop.yarn.server.resourcemanager.scheduler.capacity.LeafQueue: Application added - appId: application_1376050148932_0001 user: org.apache.hadoop.yarn.server.resourcemanager.scheduler.capacity.LeafQueue$User@5d791d43, leaf-queue: default #user-pending-applications: 0 #user-active-applications: 1 #queue-pending-applications: 0 #queue-active-applications: 1
2013-08-09 12:11:32,249 INFO org.apache.hadoop.yarn.server.resourcemanager.scheduler.capacity.ParentQueue: Application added - appId: application_1376050148932_0001 user: ubuntu leaf-queue of parent: root #applications: 1
2013-08-09 12:11:32,249 INFO org.apache.hadoop.yarn.server.resourcemanager.scheduler.capacity.CapacityScheduler: Application Submission: appattempt_1376050148932_0001_000001, user: ubuntu queue: default: capacity=1.0, absoluteCapacity=1.0, usedResources=<memory:0, vCores:0>usedCapacity=0.0, absoluteUsedCapacity=0.0, numApps=1, numContainers=0, currently active: 1
2013-08-09 12:11:32,255 INFO org.apache.hadoop.yarn.server.resourcemanager.rmapp.attempt.RMAppAttemptImpl: appattempt_1376050148932_0001_000001 State change from SUBMITTED to SCHEDULED
2013-08-09 12:11:32,255 INFO org.apache.hadoop.yarn.server.resourcemanager.rmapp.RMAppImpl: application_1376050148932_0001 State change from SUBMITTED to ACCEPTED
2013-08-09 12:11:33,163 INFO org.apache.hadoop.yarn.server.resourcemanager.rmcontainer.RMContainerImpl: container_1376050148932_0001_01_000001 Container Transitioned from NEW to ALLOCATED
2013-08-09 12:11:33,163 INFO org.apache.hadoop.yarn.server.resourcemanager.RMAuditLogger: USER=ubuntu	OPERATION=AM Allocated Container	TARGET=SchedulerApp	RESULT=SUCCESS	APPID=application_1376050148932_0001	CONTAINERID=container_1376050148932_0001_01_000001
2013-08-09 12:11:33,165 INFO org.apache.hadoop.yarn.server.resourcemanager.scheduler.common.fica.FiCaSchedulerNode: Assigned container container_1376050148932_0001_01_000001 of capacity <memory:2048, vCores:1> on host hadoop-210-5:60822, which currently has 1 containers, <memory:2048, vCores:1> used and <memory:6144, vCores:15> available
2013-08-09 12:11:33,171 INFO org.apache.hadoop.yarn.server.resourcemanager.scheduler.capacity.LeafQueue: assignedContainer application=application_1376050148932_0001 container=Container: [ContainerId: container_1376050148932_0001_01_000001, NodeId: hadoop-210-5:60822, NodeHttpAddress: hadoop-210-5:8042, Resource: <memory:2048, vCores:1>, Priority: 0, State: NEW, Token: null, Status: container_id {, app_attempt_id {, application_id {, id: 1, cluster_timestamp: 1376050148932, }, attemptId: 1, }, id: 1, }, state: C_NEW, ] containerId=container_1376050148932_0001_01_000001 queue=default: capacity=1.0, absoluteCapacity=1.0, usedResources=<memory:0, vCores:0>usedCapacity=0.0, absoluteUsedCapacity=0.0, numApps=1, numContainers=0 usedCapacity=0.0 absoluteUsedCapacity=0.0 used=<memory:0, vCores:0> cluster=<memory:49152, vCores:96>
2013-08-09 12:11:33,172 INFO org.apache.hadoop.yarn.server.resourcemanager.scheduler.capacity.ParentQueue: Re-sorting queues since queue: root.default stats: default: capacity=1.0, absoluteCapacity=1.0, usedResources=<memory:2048, vCores:1>usedCapacity=0.041666668, absoluteUsedCapacity=0.041666668, numApps=1, numContainers=1
2013-08-09 12:11:33,174 INFO org.apache.hadoop.yarn.server.resourcemanager.rmcontainer.RMContainerImpl: container_1376050148932_0001_01_000001 Container Transitioned from ALLOCATED to ACQUIRED
2013-08-09 12:11:33,178 INFO org.apache.hadoop.yarn.server.resourcemanager.rmapp.attempt.RMAppAttemptImpl: Storing attempt: AppId: application_1376050148932_0001 AttemptId: appattempt_1376050148932_0001_000001 MasterContainer: Container: [ContainerId: container_1376050148932_0001_01_000001, NodeId: hadoop-210-5:60822, NodeHttpAddress: hadoop-210-5:8042, Resource: <memory:2048, vCores:1>, Priority: 0, State: NEW, Token: null, Status: container_id {, app_attempt_id {, application_id {, id: 1, cluster_timestamp: 1376050148932, }, attemptId: 1, }, id: 1, }, state: C_NEW, ]
2013-08-09 12:11:33,180 INFO org.apache.hadoop.yarn.server.resourcemanager.scheduler.capacity.ParentQueue: assignedContainer queue=root usedCapacity=0.041666668 absoluteUsedCapacity=0.041666668 used=<memory:2048, vCores:1> cluster=<memory:49152, vCores:96>
2013-08-09 12:11:33,181 INFO org.apache.hadoop.yarn.server.resourcemanager.rmapp.attempt.RMAppAttemptImpl: appattempt_1376050148932_0001_000001 State change from SCHEDULED to ALLOCATED_SAVING
2013-08-09 12:11:33,185 INFO org.apache.hadoop.yarn.server.resourcemanager.recovery.RMStateStore: Storing info for attempt: appattempt_1376050148932_0001_000001
2013-08-09 12:11:33,188 INFO org.apache.hadoop.yarn.server.resourcemanager.rmapp.attempt.RMAppAttemptImpl: appattempt_1376050148932_0001_000001 State change from ALLOCATED_SAVING to ALLOCATED
2013-08-09 12:11:33,195 INFO org.apache.hadoop.yarn.server.resourcemanager.amlauncher.AMLauncher: Launching masterappattempt_1376050148932_0001_000001
2013-08-09 12:11:33,236 INFO org.apache.hadoop.yarn.server.resourcemanager.amlauncher.AMLauncher: Setting up container Container: [ContainerId: container_1376050148932_0001_01_000001, NodeId: hadoop-210-5:60822, NodeHttpAddress: hadoop-210-5:8042, Resource: <memory:2048, vCores:1>, Priority: 0, State: NEW, Token: null, Status: container_id {, app_attempt_id {, application_id {, id: 1, cluster_timestamp: 1376050148932, }, attemptId: 1, }, id: 1, }, state: C_NEW, ] for AM appattempt_1376050148932_0001_000001
2013-08-09 12:11:33,236 INFO org.apache.hadoop.yarn.server.resourcemanager.amlauncher.AMLauncher: Command to launch container container_1376050148932_0001_01_000001 : $JAVA_HOME/bin/java -Dlog4j.configuration=container-log4j.properties -Dyarn.app.mapreduce.container.log.dir=<LOG_DIR> -Dyarn.app.mapreduce.container.log.filesize=0 -Dhadoop.root.logger=INFO,CLA  -Xmx1024m org.apache.hadoop.mapreduce.v2.app.MRAppMaster 1><LOG_DIR>/stdout 2><LOG_DIR>/stderr 
2013-08-09 12:11:34,183 INFO org.apache.hadoop.yarn.server.resourcemanager.amlauncher.AMLauncher: Done launching container Container: [ContainerId: container_1376050148932_0001_01_000001, NodeId: hadoop-210-5:60822, NodeHttpAddress: hadoop-210-5:8042, Resource: <memory:2048, vCores:1>, Priority: 0, State: NEW, Token: null, Status: container_id {, app_attempt_id {, application_id {, id: 1, cluster_timestamp: 1376050148932, }, attemptId: 1, }, id: 1, }, state: C_NEW, ] for AM appattempt_1376050148932_0001_000001
2013-08-09 12:11:34,184 INFO org.apache.hadoop.yarn.server.resourcemanager.rmapp.attempt.RMAppAttemptImpl: appattempt_1376050148932_0001_000001 State change from ALLOCATED to LAUNCHED
2013-08-09 12:11:35,168 INFO org.apache.hadoop.yarn.server.resourcemanager.rmcontainer.RMContainerImpl: container_1376050148932_0001_01_000001 Container Transitioned from ACQUIRED to RUNNING
2013-08-09 12:11:43,574 INFO org.apache.hadoop.yarn.server.resourcemanager.ApplicationMasterService: AM registration appattempt_1376050148932_0001_000001
2013-08-09 12:11:43,580 INFO org.apache.hadoop.yarn.server.resourcemanager.RMAuditLogger: USER=ubuntu	IP=192.168.100.11	OPERATION=Register App Master	TARGET=ApplicationMasterService	RESULT=SUCCESS	APPID=application_1376050148932_0001	APPATTEMPTID=appattempt_1376050148932_0001_000001
2013-08-09 12:11:43,582 INFO org.apache.hadoop.yarn.server.resourcemanager.rmapp.attempt.RMAppAttemptImpl: appattempt_1376050148932_0001_000001 State change from LAUNCHED to RUNNING
2013-08-09 12:11:43,587 INFO org.apache.hadoop.yarn.server.resourcemanager.rmapp.RMAppImpl: application_1376050148932_0001 State change from ACCEPTED to RUNNING
2013-08-09 12:11:45,176 INFO org.apache.hadoop.yarn.server.resourcemanager.rmcontainer.RMContainerImpl: container_1376050148932_0001_01_000002 Container Transitioned from NEW to ALLOCATED
2013-08-09 12:11:45,177 INFO org.apache.hadoop.yarn.server.resourcemanager.RMAuditLogger: USER=ubuntu	OPERATION=AM Allocated Container	TARGET=SchedulerApp	RESULT=SUCCESS	APPID=application_1376050148932_0001	CONTAINERID=container_1376050148932_0001_01_000002
2013-08-09 12:11:45,177 INFO org.apache.hadoop.yarn.server.resourcemanager.scheduler.common.fica.FiCaSchedulerNode: Assigned container container_1376050148932_0001_01_000002 of capacity <memory:1024, vCores:1> on host hadoop-210-6:38267, which currently has 1 containers, <memory:1024, vCores:1> used and <memory:7168, vCores:15> available
2013-08-09 12:11:45,179 INFO org.apache.hadoop.yarn.server.resourcemanager.scheduler.capacity.LeafQueue: assignedContainer application=application_1376050148932_0001 container=Container: [ContainerId: container_1376050148932_0001_01_000002, NodeId: hadoop-210-6:38267, NodeHttpAddress: hadoop-210-6:8042, Resource: <memory:1024, vCores:1>, Priority: 20, State: NEW, Token: null, Status: container_id {, app_attempt_id {, application_id {, id: 1, cluster_timestamp: 1376050148932, }, attemptId: 1, }, id: 2, }, state: C_NEW, ] containerId=container_1376050148932_0001_01_000002 queue=default: capacity=1.0, absoluteCapacity=1.0, usedResources=<memory:2048, vCores:1>usedCapacity=0.041666668, absoluteUsedCapacity=0.041666668, numApps=1, numContainers=1 usedCapacity=0.041666668 absoluteUsedCapacity=0.041666668 used=<memory:2048, vCores:1> cluster=<memory:49152, vCores:96>
2013-08-09 12:11:45,179 INFO org.apache.hadoop.yarn.server.resourcemanager.scheduler.capacity.ParentQueue: Re-sorting queues since queue: root.default stats: default: capacity=1.0, absoluteCapacity=1.0, usedResources=<memory:3072, vCores:2>usedCapacity=0.0625, absoluteUsedCapacity=0.0625, numApps=1, numContainers=2
2013-08-09 12:11:45,179 INFO org.apache.hadoop.yarn.server.resourcemanager.scheduler.capacity.ParentQueue: assignedContainer queue=root usedCapacity=0.0625 absoluteUsedCapacity=0.0625 used=<memory:3072, vCores:2> cluster=<memory:49152, vCores:96>
2013-08-09 12:11:45,180 INFO org.apache.hadoop.yarn.server.resourcemanager.rmcontainer.RMContainerImpl: container_1376050148932_0001_01_000003 Container Transitioned from NEW to ALLOCATED
2013-08-09 12:11:45,180 INFO org.apache.hadoop.yarn.server.resourcemanager.RMAuditLogger: USER=ubuntu	OPERATION=AM Allocated Container	TARGET=SchedulerApp	RESULT=SUCCESS	APPID=application_1376050148932_0001	CONTAINERID=container_1376050148932_0001_01_000003
2013-08-09 12:11:45,180 INFO org.apache.hadoop.yarn.server.resourcemanager.scheduler.common.fica.FiCaSchedulerNode: Assigned container container_1376050148932_0001_01_000003 of capacity <memory:1024, vCores:1> on host hadoop-210-7:41457, which currently has 1 containers, <memory:1024, vCores:1> used and <memory:7168, vCores:15> available
2013-08-09 12:11:45,182 INFO org.apache.hadoop.yarn.server.resourcemanager.scheduler.capacity.LeafQueue: assignedContainer application=application_1376050148932_0001 container=Container: [ContainerId: container_1376050148932_0001_01_000003, NodeId: hadoop-210-7:41457, NodeHttpAddress: hadoop-210-7:8042, Resource: <memory:1024, vCores:1>, Priority: 20, State: NEW, Token: null, Status: container_id {, app_attempt_id {, application_id {, id: 1, cluster_timestamp: 1376050148932, }, attemptId: 1, }, id: 3, }, state: C_NEW, ] containerId=container_1376050148932_0001_01_000003 queue=default: capacity=1.0, absoluteCapacity=1.0, usedResources=<memory:3072, vCores:2>usedCapacity=0.0625, absoluteUsedCapacity=0.0625, numApps=1, numContainers=2 usedCapacity=0.0625 absoluteUsedCapacity=0.0625 used=<memory:3072, vCores:2> cluster=<memory:49152, vCores:96>
2013-08-09 12:11:45,182 INFO org.apache.hadoop.yarn.server.resourcemanager.scheduler.capacity.ParentQueue: Re-sorting queues since queue: root.default stats: default: capacity=1.0, absoluteCapacity=1.0, usedResources=<memory:4096, vCores:3>usedCapacity=0.083333336, absoluteUsedCapacity=0.083333336, numApps=1, numContainers=3
2013-08-09 12:11:45,183 INFO org.apache.hadoop.yarn.server.resourcemanager.scheduler.capacity.ParentQueue: assignedContainer queue=root usedCapacity=0.083333336 absoluteUsedCapacity=0.083333336 used=<memory:4096, vCores:3> cluster=<memory:49152, vCores:96>
2013-08-09 12:11:45,668 INFO org.apache.hadoop.yarn.server.resourcemanager.rmcontainer.RMContainerImpl: container_1376050148932_0001_01_000002 Container Transitioned from ALLOCATED to ACQUIRED
2013-08-09 12:11:45,670 INFO org.apache.hadoop.yarn.server.resourcemanager.rmcontainer.RMContainerImpl: container_1376050148932_0001_01_000003 Container Transitioned from ALLOCATED to ACQUIRED
2013-08-09 12:11:46,701 INFO org.apache.hadoop.yarn.server.resourcemanager.scheduler.AppSchedulingInfo: checking for deactivate... 
2013-08-09 12:11:47,312 INFO org.apache.hadoop.yarn.server.resourcemanager.rmcontainer.RMContainerImpl: container_1376050148932_0001_01_000002 Container Transitioned from ACQUIRED to RUNNING
2013-08-09 12:11:47,315 INFO org.apache.hadoop.yarn.server.resourcemanager.rmcontainer.RMContainerImpl: container_1376050148932_0001_01_000003 Container Transitioned from ACQUIRED to RUNNING
2013-08-09 12:14:13,647 INFO org.apache.hadoop.yarn.server.resourcemanager.rmcontainer.RMContainerImpl: container_1376050148932_0001_01_000003 Container Transitioned from RUNNING to COMPLETED
2013-08-09 12:14:13,648 INFO org.apache.hadoop.yarn.server.resourcemanager.scheduler.common.fica.FiCaSchedulerApp: Completed container: container_1376050148932_0001_01_000003 in state: COMPLETED event:FINISHED
2013-08-09 12:14:13,648 INFO org.apache.hadoop.yarn.server.resourcemanager.RMAuditLogger: USER=ubuntu	OPERATION=AM Released Container	TARGET=SchedulerApp	RESULT=SUCCESS	APPID=application_1376050148932_0001	CONTAINERID=container_1376050148932_0001_01_000003
2013-08-09 12:14:13,648 INFO org.apache.hadoop.yarn.server.resourcemanager.scheduler.common.fica.FiCaSchedulerNode: Released container container_1376050148932_0001_01_000003 of capacity <memory:1024, vCores:1> on host hadoop-210-7:41457, which currently has 0 containers, <memory:0, vCores:0> used and <memory:8192, vCores:16> available, release resources=true
2013-08-09 12:14:13,649 INFO org.apache.hadoop.yarn.server.resourcemanager.scheduler.capacity.LeafQueue: default used=<memory:3072, vCores:2> numContainers=2 user=ubuntu user-resources=<memory:3072, vCores:2>
2013-08-09 12:14:13,651 INFO org.apache.hadoop.yarn.server.resourcemanager.scheduler.capacity.LeafQueue: completedContainer container=Container: [ContainerId: container_1376050148932_0001_01_000003, NodeId: hadoop-210-7:41457, NodeHttpAddress: hadoop-210-7:8042, Resource: <memory:1024, vCores:1>, Priority: 20, State: NEW, Token: null, Status: container_id {, app_attempt_id {, application_id {, id: 1, cluster_timestamp: 1376050148932, }, attemptId: 1, }, id: 3, }, state: C_COMPLETE, diagnostics: "Container killed by the ApplicationMaster.\n\n", exit_status: 143, ] resource=<memory:1024, vCores:1> queue=default: capacity=1.0, absoluteCapacity=1.0, usedResources=<memory:3072, vCores:2>usedCapacity=0.0625, absoluteUsedCapacity=0.0625, numApps=1, numContainers=2 usedCapacity=0.0625 absoluteUsedCapacity=0.0625 used=<memory:3072, vCores:2> cluster=<memory:49152, vCores:96>
2013-08-09 12:14:13,651 INFO org.apache.hadoop.yarn.server.resourcemanager.scheduler.capacity.ParentQueue: completedContainer queue=root usedCapacity=0.0625 absoluteUsedCapacity=0.0625 used=<memory:3072, vCores:2> cluster=<memory:49152, vCores:96>
2013-08-09 12:14:13,651 INFO org.apache.hadoop.yarn.server.resourcemanager.scheduler.capacity.CapacityScheduler: Application appattempt_1376050148932_0001_000001 released container container_1376050148932_0001_01_000003 on node: host: hadoop-210-7:41457 #containers=0 available=8192 used=0 with event: FINISHED
2013-08-09 12:14:14,494 INFO org.apache.hadoop.yarn.server.resourcemanager.rmcontainer.RMContainerImpl: container_1376050148932_0001_01_000002 Container Transitioned from RUNNING to COMPLETED
2013-08-09 12:14:14,495 INFO org.apache.hadoop.yarn.server.resourcemanager.scheduler.common.fica.FiCaSchedulerApp: Completed container: container_1376050148932_0001_01_000002 in state: COMPLETED event:FINISHED
2013-08-09 12:14:14,495 INFO org.apache.hadoop.yarn.server.resourcemanager.RMAuditLogger: USER=ubuntu	OPERATION=AM Released Container	TARGET=SchedulerApp	RESULT=SUCCESS	APPID=application_1376050148932_0001	CONTAINERID=container_1376050148932_0001_01_000002
2013-08-09 12:14:14,495 INFO org.apache.hadoop.yarn.server.resourcemanager.scheduler.common.fica.FiCaSchedulerNode: Released container container_1376050148932_0001_01_000002 of capacity <memory:1024, vCores:1> on host hadoop-210-6:38267, which currently has 0 containers, <memory:0, vCores:0> used and <memory:8192, vCores:16> available, release resources=true
2013-08-09 12:14:14,495 INFO org.apache.hadoop.yarn.server.resourcemanager.scheduler.capacity.LeafQueue: default used=<memory:2048, vCores:1> numContainers=1 user=ubuntu user-resources=<memory:2048, vCores:1>
2013-08-09 12:14:14,497 INFO org.apache.hadoop.yarn.server.resourcemanager.scheduler.capacity.LeafQueue: completedContainer container=Container: [ContainerId: container_1376050148932_0001_01_000002, NodeId: hadoop-210-6:38267, NodeHttpAddress: hadoop-210-6:8042, Resource: <memory:1024, vCores:1>, Priority: 20, State: NEW, Token: null, Status: container_id {, app_attempt_id {, application_id {, id: 1, cluster_timestamp: 1376050148932, }, attemptId: 1, }, id: 2, }, state: C_COMPLETE, diagnostics: "Container killed by the ApplicationMaster.\n\n", exit_status: 143, ] resource=<memory:1024, vCores:1> queue=default: capacity=1.0, absoluteCapacity=1.0, usedResources=<memory:2048, vCores:1>usedCapacity=0.041666668, absoluteUsedCapacity=0.041666668, numApps=1, numContainers=1 usedCapacity=0.041666668 absoluteUsedCapacity=0.041666668 used=<memory:2048, vCores:1> cluster=<memory:49152, vCores:96>
2013-08-09 12:14:14,498 INFO org.apache.hadoop.yarn.server.resourcemanager.scheduler.capacity.ParentQueue: completedContainer queue=root usedCapacity=0.041666668 absoluteUsedCapacity=0.041666668 used=<memory:2048, vCores:1> cluster=<memory:49152, vCores:96>
2013-08-09 12:14:14,498 INFO org.apache.hadoop.yarn.server.resourcemanager.scheduler.capacity.CapacityScheduler: Application appattempt_1376050148932_0001_000001 released container container_1376050148932_0001_01_000002 on node: host: hadoop-210-6:38267 #containers=0 available=8192 used=0 with event: FINISHED
2013-08-09 12:14:18,657 INFO org.apache.hadoop.yarn.server.resourcemanager.rmapp.attempt.RMAppAttemptImpl: appattempt_1376050148932_0001_000001 State change from RUNNING to FINISHING
2013-08-09 12:14:18,657 INFO org.apache.hadoop.yarn.server.resourcemanager.rmapp.RMAppImpl: application_1376050148932_0001 State change from RUNNING to FINISHING
2013-08-09 12:14:19,514 INFO org.apache.hadoop.yarn.server.resourcemanager.rmcontainer.RMContainerImpl: container_1376050148932_0001_01_000001 Container Transitioned from RUNNING to COMPLETED
2013-08-09 12:14:19,514 INFO org.apache.hadoop.yarn.server.resourcemanager.scheduler.common.fica.FiCaSchedulerApp: Completed container: container_1376050148932_0001_01_000001 in state: COMPLETED event:FINISHED
2013-08-09 12:14:19,515 INFO org.apache.hadoop.yarn.server.resourcemanager.RMAuditLogger: USER=ubuntu	OPERATION=AM Released Container	TARGET=SchedulerApp	RESULT=SUCCESS	APPID=application_1376050148932_0001	CONTAINERID=container_1376050148932_0001_01_000001
2013-08-09 12:14:19,515 INFO org.apache.hadoop.yarn.server.resourcemanager.scheduler.common.fica.FiCaSchedulerNode: Released container container_1376050148932_0001_01_000001 of capacity <memory:2048, vCores:1> on host hadoop-210-5:60822, which currently has 0 containers, <memory:0, vCores:0> used and <memory:8192, vCores:16> available, release resources=true
2013-08-09 12:14:19,515 INFO org.apache.hadoop.yarn.server.resourcemanager.scheduler.capacity.LeafQueue: default used=<memory:0, vCores:0> numContainers=0 user=ubuntu user-resources=<memory:0, vCores:0>
2013-08-09 12:14:19,517 INFO org.apache.hadoop.yarn.server.resourcemanager.scheduler.capacity.LeafQueue: completedContainer container=Container: [ContainerId: container_1376050148932_0001_01_000001, NodeId: hadoop-210-5:60822, NodeHttpAddress: hadoop-210-5:8042, Resource: <memory:2048, vCores:1>, Priority: 0, State: NEW, Token: null, Status: container_id {, app_attempt_id {, application_id {, id: 1, cluster_timestamp: 1376050148932, }, attemptId: 1, }, id: 1, }, state: C_COMPLETE, diagnostics: "", exit_status: 0, ] resource=<memory:2048, vCores:1> queue=default: capacity=1.0, absoluteCapacity=1.0, usedResources=<memory:0, vCores:0>usedCapacity=0.0, absoluteUsedCapacity=0.0, numApps=1, numContainers=0 usedCapacity=0.0 absoluteUsedCapacity=0.0 used=<memory:0, vCores:0> cluster=<memory:49152, vCores:96>
2013-08-09 12:14:19,517 INFO org.apache.hadoop.yarn.server.resourcemanager.scheduler.capacity.ParentQueue: completedContainer queue=root usedCapacity=0.0 absoluteUsedCapacity=0.0 used=<memory:0, vCores:0> cluster=<memory:49152, vCores:96>
2013-08-09 12:14:19,517 INFO org.apache.hadoop.yarn.server.resourcemanager.scheduler.capacity.CapacityScheduler: Application appattempt_1376050148932_0001_000001 released container container_1376050148932_0001_01_000001 on node: host: hadoop-210-5:60822 #containers=0 available=8192 used=0 with event: FINISHED
2013-08-09 12:14:19,519 INFO org.apache.hadoop.yarn.server.resourcemanager.rmapp.attempt.RMAppAttemptImpl: appattempt_1376050148932_0001_000001 State change from FINISHING to FINISHED
2013-08-09 12:14:19,521 INFO org.apache.hadoop.yarn.server.resourcemanager.rmapp.RMAppImpl: application_1376050148932_0001 State change from FINISHING to FINISHED
2013-08-09 12:14:19,521 INFO org.apache.hadoop.yarn.server.resourcemanager.scheduler.capacity.CapacityScheduler: Application appattempt_1376050148932_0001_000001 is done. finalState=FINISHED
2013-08-09 12:14:19,522 INFO org.apache.hadoop.yarn.server.resourcemanager.RMAuditLogger: USER=ubuntu	OPERATION=Application Finished - Succeeded	TARGET=RMAppManager	RESULT=SUCCESS	APPID=application_1376050148932_0001
2013-08-09 12:14:19,524 INFO org.apache.hadoop.yarn.server.resourcemanager.scheduler.AppSchedulingInfo: Application application_1376050148932_0001 requests cleared
2013-08-09 12:14:19,525 INFO org.apache.hadoop.yarn.server.resourcemanager.scheduler.capacity.LeafQueue: Application removed - appId: application_1376050148932_0001 user: ubuntu queue: default #user-pending-applications: 0 #user-active-applications: 0 #queue-pending-applications: 0 #queue-active-applications: 0
2013-08-09 12:14:19,525 INFO org.apache.hadoop.yarn.server.resourcemanager.scheduler.capacity.ParentQueue: Application removed - appId: application_1376050148932_0001 user: ubuntu leaf-queue of parent: root #applications: 0
2013-08-09 12:14:19,525 INFO org.apache.hadoop.yarn.server.resourcemanager.recovery.RMStateStore: Removing info for app: application_1376050148932_0001
2013-08-09 12:14:19,522 INFO org.apache.hadoop.yarn.server.resourcemanager.amlauncher.AMLauncher: Cleaning master appattempt_1376050148932_0001_000001
2013-08-09 12:14:19,528 INFO org.apache.hadoop.yarn.server.resourcemanager.RMAppManager$ApplicationSummary: appId=application_1376050148932_0001,name=TeraGen,user=ubuntu,queue=default,state=FINISHED,trackingUrl=hadoop-210-1.novalocal:8088/proxy/application_1376050148932_0001/jobhistory/job/job_1376050148932_0001,appMasterHost=hadoop-210-5,startTime=1376050292151,finishTime=1376050458657
2013-08-09 12:14:20,287 INFO org.apache.hadoop.yarn.server.resourcemanager.ClientRMService: Allocated new applicationId: 2
2013-08-09 12:14:22,311 INFO org.apache.hadoop.yarn.server.resourcemanager.ClientRMService: Storing Application with id application_1376050148932_0002
2013-08-09 12:14:22,311 INFO org.apache.hadoop.yarn.server.resourcemanager.recovery.RMStateStore: Storing info for app: application_1376050148932_0002
2013-08-09 12:14:22,311 INFO org.apache.hadoop.yarn.server.resourcemanager.ClientRMService: Application with id 2 submitted by user ubuntu
2013-08-09 12:14:22,312 INFO org.apache.hadoop.yarn.server.resourcemanager.RMAuditLogger: USER=ubuntu	IP=192.168.100.4	OPERATION=Submit Application Request	TARGET=ClientRMService	RESULT=SUCCESS	APPID=application_1376050148932_0002
2013-08-09 12:14:22,314 INFO org.apache.hadoop.yarn.server.resourcemanager.rmapp.RMAppImpl: application_1376050148932_0002 State change from NEW to SUBMITTED
2013-08-09 12:14:22,315 INFO org.apache.hadoop.yarn.server.resourcemanager.ApplicationMasterService: Registering appattempt_1376050148932_0002_000001
2013-08-09 12:14:22,315 INFO org.apache.hadoop.yarn.server.resourcemanager.rmapp.attempt.RMAppAttemptImpl: appattempt_1376050148932_0002_000001 State change from NEW to SUBMITTED
2013-08-09 12:14:22,315 INFO org.apache.hadoop.yarn.server.resourcemanager.scheduler.capacity.LeafQueue: Application application_1376050148932_0002 from user: ubuntu activated in queue: default
2013-08-09 12:14:22,316 INFO org.apache.hadoop.yarn.server.resourcemanager.scheduler.capacity.LeafQueue: Application added - appId: application_1376050148932_0002 user: org.apache.hadoop.yarn.server.resourcemanager.scheduler.capacity.LeafQueue$User@54cd55ce, leaf-queue: default #user-pending-applications: 0 #user-active-applications: 1 #queue-pending-applications: 0 #queue-active-applications: 1
2013-08-09 12:14:22,316 INFO org.apache.hadoop.yarn.server.resourcemanager.scheduler.capacity.ParentQueue: Application added - appId: application_1376050148932_0002 user: ubuntu leaf-queue of parent: root #applications: 1
2013-08-09 12:14:22,316 INFO org.apache.hadoop.yarn.server.resourcemanager.scheduler.capacity.CapacityScheduler: Application Submission: appattempt_1376050148932_0002_000001, user: ubuntu queue: default: capacity=1.0, absoluteCapacity=1.0, usedResources=<memory:0, vCores:0>usedCapacity=0.0, absoluteUsedCapacity=0.0, numApps=1, numContainers=0, currently active: 1
2013-08-09 12:14:22,317 INFO org.apache.hadoop.yarn.server.resourcemanager.rmapp.attempt.RMAppAttemptImpl: appattempt_1376050148932_0002_000001 State change from SUBMITTED to SCHEDULED
2013-08-09 12:14:22,317 INFO org.apache.hadoop.yarn.server.resourcemanager.rmapp.RMAppImpl: application_1376050148932_0002 State change from SUBMITTED to ACCEPTED
2013-08-09 12:14:22,526 INFO org.apache.hadoop.yarn.server.resourcemanager.rmcontainer.RMContainerImpl: container_1376050148932_0002_01_000001 Container Transitioned from NEW to ALLOCATED
2013-08-09 12:14:22,526 INFO org.apache.hadoop.yarn.server.resourcemanager.RMAuditLogger: USER=ubuntu	OPERATION=AM Allocated Container	TARGET=SchedulerApp	RESULT=SUCCESS	APPID=application_1376050148932_0002	CONTAINERID=container_1376050148932_0002_01_000001
2013-08-09 12:14:22,527 INFO org.apache.hadoop.yarn.server.resourcemanager.scheduler.common.fica.FiCaSchedulerNode: Assigned container container_1376050148932_0002_01_000001 of capacity <memory:2048, vCores:1> on host hadoop-210-6:38267, which currently has 1 containers, <memory:2048, vCores:1> used and <memory:6144, vCores:15> available
2013-08-09 12:14:22,529 INFO org.apache.hadoop.yarn.server.resourcemanager.scheduler.capacity.LeafQueue: assignedContainer application=application_1376050148932_0002 container=Container: [ContainerId: container_1376050148932_0002_01_000001, NodeId: hadoop-210-6:38267, NodeHttpAddress: hadoop-210-6:8042, Resource: <memory:2048, vCores:1>, Priority: 0, State: NEW, Token: null, Status: container_id {, app_attempt_id {, application_id {, id: 2, cluster_timestamp: 1376050148932, }, attemptId: 1, }, id: 1, }, state: C_NEW, ] containerId=container_1376050148932_0002_01_000001 queue=default: capacity=1.0, absoluteCapacity=1.0, usedResources=<memory:0, vCores:0>usedCapacity=0.0, absoluteUsedCapacity=0.0, numApps=1, numContainers=0 usedCapacity=0.0 absoluteUsedCapacity=0.0 used=<memory:0, vCores:0> cluster=<memory:49152, vCores:96>
2013-08-09 12:14:22,529 INFO org.apache.hadoop.yarn.server.resourcemanager.scheduler.capacity.ParentQueue: Re-sorting queues since queue: root.default stats: default: capacity=1.0, absoluteCapacity=1.0, usedResources=<memory:2048, vCores:1>usedCapacity=0.041666668, absoluteUsedCapacity=0.041666668, numApps=1, numContainers=1
2013-08-09 12:14:22,529 INFO org.apache.hadoop.yarn.server.resourcemanager.scheduler.capacity.ParentQueue: assignedContainer queue=root usedCapacity=0.041666668 absoluteUsedCapacity=0.041666668 used=<memory:2048, vCores:1> cluster=<memory:49152, vCores:96>
2013-08-09 12:14:22,531 INFO org.apache.hadoop.yarn.server.resourcemanager.rmcontainer.RMContainerImpl: container_1376050148932_0002_01_000001 Container Transitioned from ALLOCATED to ACQUIRED
2013-08-09 12:14:22,533 INFO org.apache.hadoop.yarn.server.resourcemanager.rmapp.attempt.RMAppAttemptImpl: Storing attempt: AppId: application_1376050148932_0002 AttemptId: appattempt_1376050148932_0002_000001 MasterContainer: Container: [ContainerId: container_1376050148932_0002_01_000001, NodeId: hadoop-210-6:38267, NodeHttpAddress: hadoop-210-6:8042, Resource: <memory:2048, vCores:1>, Priority: 0, State: NEW, Token: null, Status: container_id {, app_attempt_id {, application_id {, id: 2, cluster_timestamp: 1376050148932, }, attemptId: 1, }, id: 1, }, state: C_NEW, ]
2013-08-09 12:14:22,533 INFO org.apache.hadoop.yarn.server.resourcemanager.rmapp.attempt.RMAppAttemptImpl: appattempt_1376050148932_0002_000001 State change from SCHEDULED to ALLOCATED_SAVING
2013-08-09 12:14:22,534 INFO org.apache.hadoop.yarn.server.resourcemanager.recovery.RMStateStore: Storing info for attempt: appattempt_1376050148932_0002_000001
2013-08-09 12:14:22,535 INFO org.apache.hadoop.yarn.server.resourcemanager.rmapp.attempt.RMAppAttemptImpl: appattempt_1376050148932_0002_000001 State change from ALLOCATED_SAVING to ALLOCATED
2013-08-09 12:14:22,537 INFO org.apache.hadoop.yarn.server.resourcemanager.amlauncher.AMLauncher: Launching masterappattempt_1376050148932_0002_000001
2013-08-09 12:14:22,540 INFO org.apache.hadoop.yarn.server.resourcemanager.amlauncher.AMLauncher: Setting up container Container: [ContainerId: container_1376050148932_0002_01_000001, NodeId: hadoop-210-6:38267, NodeHttpAddress: hadoop-210-6:8042, Resource: <memory:2048, vCores:1>, Priority: 0, State: NEW, Token: null, Status: container_id {, app_attempt_id {, application_id {, id: 2, cluster_timestamp: 1376050148932, }, attemptId: 1, }, id: 1, }, state: C_NEW, ] for AM appattempt_1376050148932_0002_000001
2013-08-09 12:14:22,540 INFO org.apache.hadoop.yarn.server.resourcemanager.amlauncher.AMLauncher: Command to launch container container_1376050148932_0002_01_000001 : $JAVA_HOME/bin/java -Dlog4j.configuration=container-log4j.properties -Dyarn.app.mapreduce.container.log.dir=<LOG_DIR> -Dyarn.app.mapreduce.container.log.filesize=0 -Dhadoop.root.logger=INFO,CLA  -Xmx1024m org.apache.hadoop.mapreduce.v2.app.MRAppMaster 1><LOG_DIR>/stdout 2><LOG_DIR>/stderr 
2013-08-09 12:14:22,557 INFO org.apache.hadoop.yarn.server.resourcemanager.amlauncher.AMLauncher: Done launching container Container: [ContainerId: container_1376050148932_0002_01_000001, NodeId: hadoop-210-6:38267, NodeHttpAddress: hadoop-210-6:8042, Resource: <memory:2048, vCores:1>, Priority: 0, State: NEW, Token: null, Status: container_id {, app_attempt_id {, application_id {, id: 2, cluster_timestamp: 1376050148932, }, attemptId: 1, }, id: 1, }, state: C_NEW, ] for AM appattempt_1376050148932_0002_000001
2013-08-09 12:14:22,557 INFO org.apache.hadoop.yarn.server.resourcemanager.rmapp.attempt.RMAppAttemptImpl: appattempt_1376050148932_0002_000001 State change from ALLOCATED to LAUNCHED
2013-08-09 12:14:23,533 INFO org.apache.hadoop.yarn.server.resourcemanager.rmcontainer.RMContainerImpl: container_1376050148932_0002_01_000001 Container Transitioned from ACQUIRED to RUNNING
2013-08-09 12:14:30,834 INFO org.apache.hadoop.yarn.server.resourcemanager.ApplicationMasterService: AM registration appattempt_1376050148932_0002_000001
2013-08-09 12:14:30,834 INFO org.apache.hadoop.yarn.server.resourcemanager.RMAuditLogger: USER=ubuntu	IP=192.168.100.13	OPERATION=Register App Master	TARGET=ApplicationMasterService	RESULT=SUCCESS	APPID=application_1376050148932_0002	APPATTEMPTID=appattempt_1376050148932_0002_000001
2013-08-09 12:14:30,849 INFO org.apache.hadoop.yarn.server.resourcemanager.rmapp.attempt.RMAppAttemptImpl: appattempt_1376050148932_0002_000001 State change from LAUNCHED to RUNNING
2013-08-09 12:14:30,849 INFO org.apache.hadoop.yarn.server.resourcemanager.rmapp.RMAppImpl: application_1376050148932_0002 State change from ACCEPTED to RUNNING
2013-08-09 12:14:31,961 INFO org.apache.hadoop.yarn.server.resourcemanager.rmcontainer.RMContainerImpl: container_1376050148932_0002_01_000002 Container Transitioned from NEW to ALLOCATED
2013-08-09 12:14:31,962 INFO org.apache.hadoop.yarn.server.resourcemanager.RMAuditLogger: USER=ubuntu	OPERATION=AM Allocated Container	TARGET=SchedulerApp	RESULT=SUCCESS	APPID=application_1376050148932_0002	CONTAINERID=container_1376050148932_0002_01_000002
2013-08-09 12:14:31,962 INFO org.apache.hadoop.yarn.server.resourcemanager.scheduler.common.fica.FiCaSchedulerNode: Assigned container container_1376050148932_0002_01_000002 of capacity <memory:1024, vCores:1> on host hadoop-210-4:57908, which currently has 1 containers, <memory:1024, vCores:1> used and <memory:7168, vCores:15> available
2013-08-09 12:14:31,964 INFO org.apache.hadoop.yarn.server.resourcemanager.scheduler.capacity.LeafQueue: assignedContainer application=application_1376050148932_0002 container=Container: [ContainerId: container_1376050148932_0002_01_000002, NodeId: hadoop-210-4:57908, NodeHttpAddress: hadoop-210-4:8042, Resource: <memory:1024, vCores:1>, Priority: 20, State: NEW, Token: null, Status: container_id {, app_attempt_id {, application_id {, id: 2, cluster_timestamp: 1376050148932, }, attemptId: 1, }, id: 2, }, state: C_NEW, ] containerId=container_1376050148932_0002_01_000002 queue=default: capacity=1.0, absoluteCapacity=1.0, usedResources=<memory:2048, vCores:1>usedCapacity=0.041666668, absoluteUsedCapacity=0.041666668, numApps=1, numContainers=1 usedCapacity=0.041666668 absoluteUsedCapacity=0.041666668 used=<memory:2048, vCores:1> cluster=<memory:49152, vCores:96>
2013-08-09 12:14:31,964 INFO org.apache.hadoop.yarn.server.resourcemanager.scheduler.capacity.ParentQueue: Re-sorting queues since queue: root.default stats: default: capacity=1.0, absoluteCapacity=1.0, usedResources=<memory:3072, vCores:2>usedCapacity=0.0625, absoluteUsedCapacity=0.0625, numApps=1, numContainers=2
2013-08-09 12:14:31,964 INFO org.apache.hadoop.yarn.server.resourcemanager.scheduler.capacity.ParentQueue: assignedContainer queue=root usedCapacity=0.0625 absoluteUsedCapacity=0.0625 used=<memory:3072, vCores:2> cluster=<memory:49152, vCores:96>
2013-08-09 12:14:32,563 INFO org.apache.hadoop.yarn.server.resourcemanager.rmcontainer.RMContainerImpl: container_1376050148932_0002_01_000003 Container Transitioned from NEW to ALLOCATED
2013-08-09 12:14:32,564 INFO org.apache.hadoop.yarn.server.resourcemanager.RMAuditLogger: USER=ubuntu	OPERATION=AM Allocated Container	TARGET=SchedulerApp	RESULT=SUCCESS	APPID=application_1376050148932_0002	CONTAINERID=container_1376050148932_0002_01_000003
2013-08-09 12:14:32,564 INFO org.apache.hadoop.yarn.server.resourcemanager.scheduler.common.fica.FiCaSchedulerNode: Assigned container container_1376050148932_0002_01_000003 of capacity <memory:1024, vCores:1> on host hadoop-210-5:60822, which currently has 1 containers, <memory:1024, vCores:1> used and <memory:7168, vCores:15> available
2013-08-09 12:14:32,565 INFO org.apache.hadoop.yarn.server.resourcemanager.scheduler.capacity.LeafQueue: assignedContainer application=application_1376050148932_0002 container=Container: [ContainerId: container_1376050148932_0002_01_000003, NodeId: hadoop-210-5:60822, NodeHttpAddress: hadoop-210-5:8042, Resource: <memory:1024, vCores:1>, Priority: 20, State: NEW, Token: null, Status: container_id {, app_attempt_id {, application_id {, id: 2, cluster_timestamp: 1376050148932, }, attemptId: 1, }, id: 3, }, state: C_NEW, ] containerId=container_1376050148932_0002_01_000003 queue=default: capacity=1.0, absoluteCapacity=1.0, usedResources=<memory:3072, vCores:2>usedCapacity=0.0625, absoluteUsedCapacity=0.0625, numApps=1, numContainers=2 usedCapacity=0.0625 absoluteUsedCapacity=0.0625 used=<memory:3072, vCores:2> cluster=<memory:49152, vCores:96>
2013-08-09 12:14:32,566 INFO org.apache.hadoop.yarn.server.resourcemanager.scheduler.capacity.ParentQueue: Re-sorting queues since queue: root.default stats: default: capacity=1.0, absoluteCapacity=1.0, usedResources=<memory:4096, vCores:3>usedCapacity=0.083333336, absoluteUsedCapacity=0.083333336, numApps=1, numContainers=3
2013-08-09 12:14:32,566 INFO org.apache.hadoop.yarn.server.resourcemanager.scheduler.capacity.ParentQueue: assignedContainer queue=root usedCapacity=0.083333336 absoluteUsedCapacity=0.083333336 used=<memory:4096, vCores:3> cluster=<memory:49152, vCores:96>
2013-08-09 12:14:32,907 INFO org.apache.hadoop.yarn.server.resourcemanager.rmcontainer.RMContainerImpl: container_1376050148932_0002_01_000002 Container Transitioned from ALLOCATED to ACQUIRED
2013-08-09 12:14:32,909 INFO org.apache.hadoop.yarn.server.resourcemanager.rmcontainer.RMContainerImpl: container_1376050148932_0002_01_000003 Container Transitioned from ALLOCATED to ACQUIRED
2013-08-09 12:14:33,569 INFO org.apache.hadoop.yarn.server.resourcemanager.rmcontainer.RMContainerImpl: container_1376050148932_0002_01_000003 Container Transitioned from ACQUIRED to RUNNING
2013-08-09 12:14:33,937 INFO org.apache.hadoop.yarn.server.resourcemanager.scheduler.AppSchedulingInfo: checking for deactivate... 
2013-08-09 12:14:35,996 INFO org.apache.hadoop.yarn.server.resourcemanager.rmcontainer.RMContainerImpl: container_1376050148932_0002_01_000002 Container Transitioned from ACQUIRED to RUNNING
2013-08-09 12:16:18,822 INFO org.apache.hadoop.yarn.server.resourcemanager.rmcontainer.RMContainerImpl: container_1376050148932_0002_01_000003 Container Transitioned from RUNNING to COMPLETED
2013-08-09 12:16:18,822 INFO org.apache.hadoop.yarn.server.resourcemanager.scheduler.common.fica.FiCaSchedulerApp: Completed container: container_1376050148932_0002_01_000003 in state: COMPLETED event:FINISHED
2013-08-09 12:16:18,822 INFO org.apache.hadoop.yarn.server.resourcemanager.RMAuditLogger: USER=ubuntu	OPERATION=AM Released Container	TARGET=SchedulerApp	RESULT=SUCCESS	APPID=application_1376050148932_0002	CONTAINERID=container_1376050148932_0002_01_000003
2013-08-09 12:16:18,823 INFO org.apache.hadoop.yarn.server.resourcemanager.scheduler.common.fica.FiCaSchedulerNode: Released container container_1376050148932_0002_01_000003 of capacity <memory:1024, vCores:1> on host hadoop-210-5:60822, which currently has 0 containers, <memory:0, vCores:0> used and <memory:8192, vCores:16> available, release resources=true
2013-08-09 12:16:18,823 INFO org.apache.hadoop.yarn.server.resourcemanager.scheduler.capacity.LeafQueue: default used=<memory:3072, vCores:2> numContainers=2 user=ubuntu user-resources=<memory:3072, vCores:2>
2013-08-09 12:16:18,837 INFO org.apache.hadoop.yarn.server.resourcemanager.scheduler.capacity.LeafQueue: completedContainer container=Container: [ContainerId: container_1376050148932_0002_01_000003, NodeId: hadoop-210-5:60822, NodeHttpAddress: hadoop-210-5:8042, Resource: <memory:1024, vCores:1>, Priority: 20, State: NEW, Token: null, Status: container_id {, app_attempt_id {, application_id {, id: 2, cluster_timestamp: 1376050148932, }, attemptId: 1, }, id: 3, }, state: C_COMPLETE, diagnostics: "Container killed by the ApplicationMaster.\n\n", exit_status: 143, ] resource=<memory:1024, vCores:1> queue=default: capacity=1.0, absoluteCapacity=1.0, usedResources=<memory:3072, vCores:2>usedCapacity=0.0625, absoluteUsedCapacity=0.0625, numApps=1, numContainers=2 usedCapacity=0.0625 absoluteUsedCapacity=0.0625 used=<memory:3072, vCores:2> cluster=<memory:49152, vCores:96>
2013-08-09 12:16:18,837 INFO org.apache.hadoop.yarn.server.resourcemanager.scheduler.capacity.ParentQueue: completedContainer queue=root usedCapacity=0.0625 absoluteUsedCapacity=0.0625 used=<memory:3072, vCores:2> cluster=<memory:49152, vCores:96>
2013-08-09 12:16:18,837 INFO org.apache.hadoop.yarn.server.resourcemanager.scheduler.capacity.CapacityScheduler: Application appattempt_1376050148932_0002_000001 released container container_1376050148932_0002_01_000003 on node: host: hadoop-210-5:60822 #containers=0 available=8192 used=0 with event: FINISHED
2013-08-09 12:16:20,528 INFO org.apache.hadoop.yarn.server.resourcemanager.rmcontainer.RMContainerImpl: container_1376050148932_0002_01_000002 Container Transitioned from RUNNING to COMPLETED
2013-08-09 12:16:20,528 INFO org.apache.hadoop.yarn.server.resourcemanager.scheduler.common.fica.FiCaSchedulerApp: Completed container: container_1376050148932_0002_01_000002 in state: COMPLETED event:FINISHED
2013-08-09 12:16:20,528 INFO org.apache.hadoop.yarn.server.resourcemanager.RMAuditLogger: USER=ubuntu	OPERATION=AM Released Container	TARGET=SchedulerApp	RESULT=SUCCESS	APPID=application_1376050148932_0002	CONTAINERID=container_1376050148932_0002_01_000002
2013-08-09 12:16:20,529 INFO org.apache.hadoop.yarn.server.resourcemanager.scheduler.common.fica.FiCaSchedulerNode: Released container container_1376050148932_0002_01_000002 of capacity <memory:1024, vCores:1> on host hadoop-210-4:57908, which currently has 0 containers, <memory:0, vCores:0> used and <memory:8192, vCores:16> available, release resources=true
2013-08-09 12:16:20,529 INFO org.apache.hadoop.yarn.server.resourcemanager.scheduler.capacity.LeafQueue: default used=<memory:2048, vCores:1> numContainers=1 user=ubuntu user-resources=<memory:2048, vCores:1>
2013-08-09 12:16:20,531 INFO org.apache.hadoop.yarn.server.resourcemanager.scheduler.capacity.LeafQueue: completedContainer container=Container: [ContainerId: container_1376050148932_0002_01_000002, NodeId: hadoop-210-4:57908, NodeHttpAddress: hadoop-210-4:8042, Resource: <memory:1024, vCores:1>, Priority: 20, State: NEW, Token: null, Status: container_id {, app_attempt_id {, application_id {, id: 2, cluster_timestamp: 1376050148932, }, attemptId: 1, }, id: 2, }, state: C_COMPLETE, diagnostics: "Container killed by the ApplicationMaster.\n\n", exit_status: 143, ] resource=<memory:1024, vCores:1> queue=default: capacity=1.0, absoluteCapacity=1.0, usedResources=<memory:2048, vCores:1>usedCapacity=0.041666668, absoluteUsedCapacity=0.041666668, numApps=1, numContainers=1 usedCapacity=0.041666668 absoluteUsedCapacity=0.041666668 used=<memory:2048, vCores:1> cluster=<memory:49152, vCores:96>
2013-08-09 12:16:20,531 INFO org.apache.hadoop.yarn.server.resourcemanager.scheduler.capacity.ParentQueue: completedContainer queue=root usedCapacity=0.041666668 absoluteUsedCapacity=0.041666668 used=<memory:2048, vCores:1> cluster=<memory:49152, vCores:96>
2013-08-09 12:16:20,531 INFO org.apache.hadoop.yarn.server.resourcemanager.scheduler.capacity.CapacityScheduler: Application appattempt_1376050148932_0002_000001 released container container_1376050148932_0002_01_000002 on node: host: hadoop-210-4:57908 #containers=0 available=8192 used=0 with event: FINISHED
2013-08-09 12:16:24,686 INFO org.apache.hadoop.yarn.server.resourcemanager.rmapp.attempt.RMAppAttemptImpl: appattempt_1376050148932_0002_000001 State change from RUNNING to FINISHING
2013-08-09 12:16:24,687 INFO org.apache.hadoop.yarn.server.resourcemanager.rmapp.RMAppImpl: application_1376050148932_0002 State change from RUNNING to FINISHING
2013-08-09 12:16:25,166 INFO org.apache.hadoop.yarn.server.resourcemanager.rmcontainer.RMContainerImpl: container_1376050148932_0002_01_000001 Container Transitioned from RUNNING to COMPLETED
2013-08-09 12:16:25,166 INFO org.apache.hadoop.yarn.server.resourcemanager.rmapp.attempt.RMAppAttemptImpl: appattempt_1376050148932_0002_000001 State change from FINISHING to FINISHED
2013-08-09 12:16:25,167 INFO org.apache.hadoop.yarn.server.resourcemanager.scheduler.common.fica.FiCaSchedulerApp: Completed container: container_1376050148932_0002_01_000001 in state: COMPLETED event:FINISHED
2013-08-09 12:16:25,167 INFO org.apache.hadoop.yarn.server.resourcemanager.RMAuditLogger: USER=ubuntu	OPERATION=AM Released Container	TARGET=SchedulerApp	RESULT=SUCCESS	APPID=application_1376050148932_0002	CONTAINERID=container_1376050148932_0002_01_000001
2013-08-09 12:16:25,167 INFO org.apache.hadoop.yarn.server.resourcemanager.rmapp.RMAppImpl: application_1376050148932_0002 State change from FINISHING to FINISHED
2013-08-09 12:16:25,167 INFO org.apache.hadoop.yarn.server.resourcemanager.scheduler.common.fica.FiCaSchedulerNode: Released container container_1376050148932_0002_01_000001 of capacity <memory:2048, vCores:1> on host hadoop-210-6:38267, which currently has 0 containers, <memory:0, vCores:0> used and <memory:8192, vCores:16> available, release resources=true
2013-08-09 12:16:25,167 INFO org.apache.hadoop.yarn.server.resourcemanager.scheduler.capacity.LeafQueue: default used=<memory:0, vCores:0> numContainers=0 user=ubuntu user-resources=<memory:0, vCores:0>
2013-08-09 12:16:25,167 INFO org.apache.hadoop.yarn.server.resourcemanager.RMAuditLogger: USER=ubuntu	OPERATION=Application Finished - Succeeded	TARGET=RMAppManager	RESULT=SUCCESS	APPID=application_1376050148932_0002
2013-08-09 12:16:25,168 INFO org.apache.hadoop.yarn.server.resourcemanager.recovery.RMStateStore: Removing info for app: application_1376050148932_0002
2013-08-09 12:16:25,168 INFO org.apache.hadoop.yarn.server.resourcemanager.RMAppManager$ApplicationSummary: appId=application_1376050148932_0002,name=TeraGen,user=ubuntu,queue=default,state=FINISHED,trackingUrl=hadoop-210-1.novalocal:8088/proxy/application_1376050148932_0002/jobhistory/job/job_1376050148932_0002,appMasterHost=hadoop-210-6,startTime=1376050462310,finishTime=1376050584687
2013-08-09 12:16:25,169 INFO org.apache.hadoop.yarn.server.resourcemanager.scheduler.capacity.LeafQueue: completedContainer container=Container: [ContainerId: container_1376050148932_0002_01_000001, NodeId: hadoop-210-6:38267, NodeHttpAddress: hadoop-210-6:8042, Resource: <memory:2048, vCores:1>, Priority: 0, State: NEW, Token: null, Status: container_id {, app_attempt_id {, application_id {, id: 2, cluster_timestamp: 1376050148932, }, attemptId: 1, }, id: 1, }, state: C_COMPLETE, diagnostics: "", exit_status: 0, ] resource=<memory:2048, vCores:1> queue=default: capacity=1.0, absoluteCapacity=1.0, usedResources=<memory:0, vCores:0>usedCapacity=0.0, absoluteUsedCapacity=0.0, numApps=1, numContainers=0 usedCapacity=0.0 absoluteUsedCapacity=0.0 used=<memory:0, vCores:0> cluster=<memory:49152, vCores:96>
2013-08-09 12:16:25,169 INFO org.apache.hadoop.yarn.server.resourcemanager.scheduler.capacity.ParentQueue: completedContainer queue=root usedCapacity=0.0 absoluteUsedCapacity=0.0 used=<memory:0, vCores:0> cluster=<memory:49152, vCores:96>
2013-08-09 12:16:25,169 INFO org.apache.hadoop.yarn.server.resourcemanager.scheduler.capacity.CapacityScheduler: Application appattempt_1376050148932_0002_000001 released container container_1376050148932_0002_01_000001 on node: host: hadoop-210-6:38267 #containers=0 available=8192 used=0 with event: FINISHED
2013-08-09 12:16:25,169 INFO org.apache.hadoop.yarn.server.resourcemanager.scheduler.capacity.CapacityScheduler: Application appattempt_1376050148932_0002_000001 is done. finalState=FINISHED
2013-08-09 12:16:25,170 INFO org.apache.hadoop.yarn.server.resourcemanager.scheduler.AppSchedulingInfo: Application application_1376050148932_0002 requests cleared
2013-08-09 12:16:25,170 INFO org.apache.hadoop.yarn.server.resourcemanager.scheduler.capacity.LeafQueue: Application removed - appId: application_1376050148932_0002 user: ubuntu queue: default #user-pending-applications: 0 #user-active-applications: 0 #queue-pending-applications: 0 #queue-active-applications: 0
2013-08-09 12:16:25,170 INFO org.apache.hadoop.yarn.server.resourcemanager.scheduler.capacity.ParentQueue: Application removed - appId: application_1376050148932_0002 user: ubuntu leaf-queue of parent: root #applications: 0
2013-08-09 12:16:25,170 INFO org.apache.hadoop.yarn.server.resourcemanager.amlauncher.AMLauncher: Cleaning master appattempt_1376050148932_0002_000001
2013-08-09 12:16:26,557 INFO org.apache.hadoop.yarn.server.resourcemanager.ClientRMService: Allocated new applicationId: 3
2013-08-09 12:16:28,453 INFO org.apache.hadoop.yarn.server.resourcemanager.ClientRMService: Storing Application with id application_1376050148932_0003
2013-08-09 12:16:28,454 INFO org.apache.hadoop.yarn.server.resourcemanager.recovery.RMStateStore: Storing info for app: application_1376050148932_0003
2013-08-09 12:16:28,454 INFO org.apache.hadoop.yarn.server.resourcemanager.ClientRMService: Application with id 3 submitted by user ubuntu
2013-08-09 12:16:28,454 INFO org.apache.hadoop.yarn.server.resourcemanager.RMAuditLogger: USER=ubuntu	IP=192.168.100.4	OPERATION=Submit Application Request	TARGET=ClientRMService	RESULT=SUCCESS	APPID=application_1376050148932_0003
2013-08-09 12:16:28,455 INFO org.apache.hadoop.yarn.server.resourcemanager.rmapp.RMAppImpl: application_1376050148932_0003 State change from NEW to SUBMITTED
2013-08-09 12:16:28,455 INFO org.apache.hadoop.yarn.server.resourcemanager.ApplicationMasterService: Registering appattempt_1376050148932_0003_000001
2013-08-09 12:16:28,456 INFO org.apache.hadoop.yarn.server.resourcemanager.rmapp.attempt.RMAppAttemptImpl: appattempt_1376050148932_0003_000001 State change from NEW to SUBMITTED
2013-08-09 12:16:28,456 INFO org.apache.hadoop.yarn.server.resourcemanager.scheduler.capacity.LeafQueue: Application application_1376050148932_0003 from user: ubuntu activated in queue: default
2013-08-09 12:16:28,457 INFO org.apache.hadoop.yarn.server.resourcemanager.scheduler.capacity.LeafQueue: Application added - appId: application_1376050148932_0003 user: org.apache.hadoop.yarn.server.resourcemanager.scheduler.capacity.LeafQueue$User@17a51abe, leaf-queue: default #user-pending-applications: 0 #user-active-applications: 1 #queue-pending-applications: 0 #queue-active-applications: 1
2013-08-09 12:16:28,457 INFO org.apache.hadoop.yarn.server.resourcemanager.scheduler.capacity.ParentQueue: Application added - appId: application_1376050148932_0003 user: ubuntu leaf-queue of parent: root #applications: 1
2013-08-09 12:16:28,457 INFO org.apache.hadoop.yarn.server.resourcemanager.scheduler.capacity.CapacityScheduler: Application Submission: appattempt_1376050148932_0003_000001, user: ubuntu queue: default: capacity=1.0, absoluteCapacity=1.0, usedResources=<memory:0, vCores:0>usedCapacity=0.0, absoluteUsedCapacity=0.0, numApps=1, numContainers=0, currently active: 1
2013-08-09 12:16:28,458 INFO org.apache.hadoop.yarn.server.resourcemanager.rmapp.attempt.RMAppAttemptImpl: appattempt_1376050148932_0003_000001 State change from SUBMITTED to SCHEDULED
2013-08-09 12:16:28,458 INFO org.apache.hadoop.yarn.server.resourcemanager.rmapp.RMAppImpl: application_1376050148932_0003 State change from SUBMITTED to ACCEPTED
2013-08-09 12:16:28,562 INFO org.apache.hadoop.yarn.server.resourcemanager.rmcontainer.RMContainerImpl: container_1376050148932_0003_01_000001 Container Transitioned from NEW to ALLOCATED
2013-08-09 12:16:28,563 INFO org.apache.hadoop.yarn.server.resourcemanager.RMAuditLogger: USER=ubuntu	OPERATION=AM Allocated Container	TARGET=SchedulerApp	RESULT=SUCCESS	APPID=application_1376050148932_0003	CONTAINERID=container_1376050148932_0003_01_000001
2013-08-09 12:16:28,563 INFO org.apache.hadoop.yarn.server.resourcemanager.scheduler.common.fica.FiCaSchedulerNode: Assigned container container_1376050148932_0003_01_000001 of capacity <memory:2048, vCores:1> on host hadoop-210-4:57908, which currently has 1 containers, <memory:2048, vCores:1> used and <memory:6144, vCores:15> available
2013-08-09 12:16:28,564 INFO org.apache.hadoop.yarn.server.resourcemanager.scheduler.capacity.LeafQueue: assignedContainer application=application_1376050148932_0003 container=Container: [ContainerId: container_1376050148932_0003_01_000001, NodeId: hadoop-210-4:57908, NodeHttpAddress: hadoop-210-4:8042, Resource: <memory:2048, vCores:1>, Priority: 0, State: NEW, Token: null, Status: container_id {, app_attempt_id {, application_id {, id: 3, cluster_timestamp: 1376050148932, }, attemptId: 1, }, id: 1, }, state: C_NEW, ] containerId=container_1376050148932_0003_01_000001 queue=default: capacity=1.0, absoluteCapacity=1.0, usedResources=<memory:0, vCores:0>usedCapacity=0.0, absoluteUsedCapacity=0.0, numApps=1, numContainers=0 usedCapacity=0.0 absoluteUsedCapacity=0.0 used=<memory:0, vCores:0> cluster=<memory:49152, vCores:96>
2013-08-09 12:16:28,565 INFO org.apache.hadoop.yarn.server.resourcemanager.scheduler.capacity.ParentQueue: Re-sorting queues since queue: root.default stats: default: capacity=1.0, absoluteCapacity=1.0, usedResources=<memory:2048, vCores:1>usedCapacity=0.041666668, absoluteUsedCapacity=0.041666668, numApps=1, numContainers=1
2013-08-09 12:16:28,565 INFO org.apache.hadoop.yarn.server.resourcemanager.scheduler.capacity.ParentQueue: assignedContainer queue=root usedCapacity=0.041666668 absoluteUsedCapacity=0.041666668 used=<memory:2048, vCores:1> cluster=<memory:49152, vCores:96>
2013-08-09 12:16:28,572 INFO org.apache.hadoop.yarn.server.resourcemanager.rmcontainer.RMContainerImpl: container_1376050148932_0003_01_000001 Container Transitioned from ALLOCATED to ACQUIRED
2013-08-09 12:16:28,574 INFO org.apache.hadoop.yarn.server.resourcemanager.rmapp.attempt.RMAppAttemptImpl: Storing attempt: AppId: application_1376050148932_0003 AttemptId: appattempt_1376050148932_0003_000001 MasterContainer: Container: [ContainerId: container_1376050148932_0003_01_000001, NodeId: hadoop-210-4:57908, NodeHttpAddress: hadoop-210-4:8042, Resource: <memory:2048, vCores:1>, Priority: 0, State: NEW, Token: null, Status: container_id {, app_attempt_id {, application_id {, id: 3, cluster_timestamp: 1376050148932, }, attemptId: 1, }, id: 1, }, state: C_NEW, ]
2013-08-09 12:16:28,574 INFO org.apache.hadoop.yarn.server.resourcemanager.rmapp.attempt.RMAppAttemptImpl: appattempt_1376050148932_0003_000001 State change from SCHEDULED to ALLOCATED_SAVING
2013-08-09 12:16:28,575 INFO org.apache.hadoop.yarn.server.resourcemanager.recovery.RMStateStore: Storing info for attempt: appattempt_1376050148932_0003_000001
2013-08-09 12:16:28,576 INFO org.apache.hadoop.yarn.server.resourcemanager.rmapp.attempt.RMAppAttemptImpl: appattempt_1376050148932_0003_000001 State change from ALLOCATED_SAVING to ALLOCATED
2013-08-09 12:16:28,578 INFO org.apache.hadoop.yarn.server.resourcemanager.amlauncher.AMLauncher: Launching masterappattempt_1376050148932_0003_000001
2013-08-09 12:16:28,581 INFO org.apache.hadoop.yarn.server.resourcemanager.amlauncher.AMLauncher: Setting up container Container: [ContainerId: container_1376050148932_0003_01_000001, NodeId: hadoop-210-4:57908, NodeHttpAddress: hadoop-210-4:8042, Resource: <memory:2048, vCores:1>, Priority: 0, State: NEW, Token: null, Status: container_id {, app_attempt_id {, application_id {, id: 3, cluster_timestamp: 1376050148932, }, attemptId: 1, }, id: 1, }, state: C_NEW, ] for AM appattempt_1376050148932_0003_000001
2013-08-09 12:16:28,581 INFO org.apache.hadoop.yarn.server.resourcemanager.amlauncher.AMLauncher: Command to launch container container_1376050148932_0003_01_000001 : $JAVA_HOME/bin/java -Dlog4j.configuration=container-log4j.properties -Dyarn.app.mapreduce.container.log.dir=<LOG_DIR> -Dyarn.app.mapreduce.container.log.filesize=0 -Dhadoop.root.logger=INFO,CLA  -Xmx1024m org.apache.hadoop.mapreduce.v2.app.MRAppMaster 1><LOG_DIR>/stdout 2><LOG_DIR>/stderr 
2013-08-09 12:16:28,598 INFO org.apache.hadoop.yarn.server.resourcemanager.amlauncher.AMLauncher: Done launching container Container: [ContainerId: container_1376050148932_0003_01_000001, NodeId: hadoop-210-4:57908, NodeHttpAddress: hadoop-210-4:8042, Resource: <memory:2048, vCores:1>, Priority: 0, State: NEW, Token: null, Status: container_id {, app_attempt_id {, application_id {, id: 3, cluster_timestamp: 1376050148932, }, attemptId: 1, }, id: 1, }, state: C_NEW, ] for AM appattempt_1376050148932_0003_000001
2013-08-09 12:16:28,598 INFO org.apache.hadoop.yarn.server.resourcemanager.rmapp.attempt.RMAppAttemptImpl: appattempt_1376050148932_0003_000001 State change from ALLOCATED to LAUNCHED
2013-08-09 12:16:29,569 INFO org.apache.hadoop.yarn.server.resourcemanager.rmcontainer.RMContainerImpl: container_1376050148932_0003_01_000001 Container Transitioned from ACQUIRED to RUNNING
2013-08-09 12:16:36,513 INFO org.apache.hadoop.yarn.server.resourcemanager.ApplicationMasterService: AM registration appattempt_1376050148932_0003_000001
2013-08-09 12:16:36,514 INFO org.apache.hadoop.yarn.server.resourcemanager.RMAuditLogger: USER=ubuntu	IP=192.168.100.10	OPERATION=Register App Master	TARGET=ApplicationMasterService	RESULT=SUCCESS	APPID=application_1376050148932_0003	APPATTEMPTID=appattempt_1376050148932_0003_000001
2013-08-09 12:16:36,515 INFO org.apache.hadoop.yarn.server.resourcemanager.rmapp.attempt.RMAppAttemptImpl: appattempt_1376050148932_0003_000001 State change from LAUNCHED to RUNNING
2013-08-09 12:16:36,515 INFO org.apache.hadoop.yarn.server.resourcemanager.rmapp.RMAppImpl: application_1376050148932_0003 State change from ACCEPTED to RUNNING
2013-08-09 12:16:37,607 INFO org.apache.hadoop.yarn.server.resourcemanager.rmcontainer.RMContainerImpl: container_1376050148932_0003_01_000002 Container Transitioned from NEW to ALLOCATED
2013-08-09 12:16:37,607 INFO org.apache.hadoop.yarn.server.resourcemanager.RMAuditLogger: USER=ubuntu	OPERATION=AM Allocated Container	TARGET=SchedulerApp	RESULT=SUCCESS	APPID=application_1376050148932_0003	CONTAINERID=container_1376050148932_0003_01_000002
2013-08-09 12:16:37,607 INFO org.apache.hadoop.yarn.server.resourcemanager.scheduler.common.fica.FiCaSchedulerNode: Assigned container container_1376050148932_0003_01_000002 of capacity <memory:1024, vCores:1> on host hadoop-210-4:57908, which currently has 2 containers, <memory:3072, vCores:2> used and <memory:5120, vCores:14> available
2013-08-09 12:16:37,609 INFO org.apache.hadoop.yarn.server.resourcemanager.scheduler.capacity.LeafQueue: assignedContainer application=application_1376050148932_0003 container=Container: [ContainerId: container_1376050148932_0003_01_000002, NodeId: hadoop-210-4:57908, NodeHttpAddress: hadoop-210-4:8042, Resource: <memory:1024, vCores:1>, Priority: 20, State: NEW, Token: null, Status: container_id {, app_attempt_id {, application_id {, id: 3, cluster_timestamp: 1376050148932, }, attemptId: 1, }, id: 2, }, state: C_NEW, ] containerId=container_1376050148932_0003_01_000002 queue=default: capacity=1.0, absoluteCapacity=1.0, usedResources=<memory:2048, vCores:1>usedCapacity=0.041666668, absoluteUsedCapacity=0.041666668, numApps=1, numContainers=1 usedCapacity=0.041666668 absoluteUsedCapacity=0.041666668 used=<memory:2048, vCores:1> cluster=<memory:49152, vCores:96>
2013-08-09 12:16:37,609 INFO org.apache.hadoop.yarn.server.resourcemanager.scheduler.capacity.ParentQueue: Re-sorting queues since queue: root.default stats: default: capacity=1.0, absoluteCapacity=1.0, usedResources=<memory:3072, vCores:2>usedCapacity=0.0625, absoluteUsedCapacity=0.0625, numApps=1, numContainers=2
2013-08-09 12:16:37,609 INFO org.apache.hadoop.yarn.server.resourcemanager.scheduler.capacity.ParentQueue: assignedContainer queue=root usedCapacity=0.0625 absoluteUsedCapacity=0.0625 used=<memory:3072, vCores:2> cluster=<memory:49152, vCores:96>
2013-08-09 12:16:37,890 INFO org.apache.hadoop.yarn.server.resourcemanager.rmcontainer.RMContainerImpl: container_1376050148932_0003_01_000003 Container Transitioned from NEW to ALLOCATED
2013-08-09 12:16:37,891 INFO org.apache.hadoop.yarn.server.resourcemanager.RMAuditLogger: USER=ubuntu	OPERATION=AM Allocated Container	TARGET=SchedulerApp	RESULT=SUCCESS	APPID=application_1376050148932_0003	CONTAINERID=container_1376050148932_0003_01_000003
2013-08-09 12:16:37,891 INFO org.apache.hadoop.yarn.server.resourcemanager.scheduler.common.fica.FiCaSchedulerNode: Assigned container container_1376050148932_0003_01_000003 of capacity <memory:1024, vCores:1> on host hadoop-210-5:60822, which currently has 1 containers, <memory:1024, vCores:1> used and <memory:7168, vCores:15> available
2013-08-09 12:16:37,892 INFO org.apache.hadoop.yarn.server.resourcemanager.scheduler.capacity.LeafQueue: assignedContainer application=application_1376050148932_0003 container=Container: [ContainerId: container_1376050148932_0003_01_000003, NodeId: hadoop-210-5:60822, NodeHttpAddress: hadoop-210-5:8042, Resource: <memory:1024, vCores:1>, Priority: 20, State: NEW, Token: null, Status: container_id {, app_attempt_id {, application_id {, id: 3, cluster_timestamp: 1376050148932, }, attemptId: 1, }, id: 3, }, state: C_NEW, ] containerId=container_1376050148932_0003_01_000003 queue=default: capacity=1.0, absoluteCapacity=1.0, usedResources=<memory:3072, vCores:2>usedCapacity=0.0625, absoluteUsedCapacity=0.0625, numApps=1, numContainers=2 usedCapacity=0.0625 absoluteUsedCapacity=0.0625 used=<memory:3072, vCores:2> cluster=<memory:49152, vCores:96>
2013-08-09 12:16:37,892 INFO org.apache.hadoop.yarn.server.resourcemanager.scheduler.capacity.ParentQueue: Re-sorting queues since queue: root.default stats: default: capacity=1.0, absoluteCapacity=1.0, usedResources=<memory:4096, vCores:3>usedCapacity=0.083333336, absoluteUsedCapacity=0.083333336, numApps=1, numContainers=3
2013-08-09 12:16:37,893 INFO org.apache.hadoop.yarn.server.resourcemanager.scheduler.capacity.ParentQueue: assignedContainer queue=root usedCapacity=0.083333336 absoluteUsedCapacity=0.083333336 used=<memory:4096, vCores:3> cluster=<memory:49152, vCores:96>
2013-08-09 12:16:38,570 INFO org.apache.hadoop.yarn.server.resourcemanager.rmcontainer.RMContainerImpl: container_1376050148932_0003_01_000002 Container Transitioned from ALLOCATED to ACQUIRED
2013-08-09 12:16:38,572 INFO org.apache.hadoop.yarn.server.resourcemanager.rmcontainer.RMContainerImpl: container_1376050148932_0003_01_000003 Container Transitioned from ALLOCATED to ACQUIRED
2013-08-09 12:16:38,896 INFO org.apache.hadoop.yarn.server.resourcemanager.rmcontainer.RMContainerImpl: container_1376050148932_0003_01_000003 Container Transitioned from ACQUIRED to RUNNING
2013-08-09 12:16:39,599 INFO org.apache.hadoop.yarn.server.resourcemanager.scheduler.AppSchedulingInfo: checking for deactivate... 
2013-08-09 12:16:39,619 INFO org.apache.hadoop.yarn.server.resourcemanager.rmcontainer.RMContainerImpl: container_1376050148932_0003_01_000002 Container Transitioned from ACQUIRED to RUNNING
2013-08-09 12:18:41,627 INFO org.apache.hadoop.yarn.server.resourcemanager.rmcontainer.RMContainerImpl: container_1376050148932_0003_01_000003 Container Transitioned from RUNNING to COMPLETED
2013-08-09 12:18:41,627 INFO org.apache.hadoop.yarn.server.resourcemanager.scheduler.common.fica.FiCaSchedulerApp: Completed container: container_1376050148932_0003_01_000003 in state: COMPLETED event:FINISHED
2013-08-09 12:18:41,628 INFO org.apache.hadoop.yarn.server.resourcemanager.RMAuditLogger: USER=ubuntu	OPERATION=AM Released Container	TARGET=SchedulerApp	RESULT=SUCCESS	APPID=application_1376050148932_0003	CONTAINERID=container_1376050148932_0003_01_000003
2013-08-09 12:18:41,628 INFO org.apache.hadoop.yarn.server.resourcemanager.scheduler.common.fica.FiCaSchedulerNode: Released container container_1376050148932_0003_01_000003 of capacity <memory:1024, vCores:1> on host hadoop-210-5:60822, which currently has 0 containers, <memory:0, vCores:0> used and <memory:8192, vCores:16> available, release resources=true
2013-08-09 12:18:41,628 INFO org.apache.hadoop.yarn.server.resourcemanager.scheduler.capacity.LeafQueue: default used=<memory:3072, vCores:2> numContainers=2 user=ubuntu user-resources=<memory:3072, vCores:2>
2013-08-09 12:18:41,630 INFO org.apache.hadoop.yarn.server.resourcemanager.scheduler.capacity.LeafQueue: completedContainer container=Container: [ContainerId: container_1376050148932_0003_01_000003, NodeId: hadoop-210-5:60822, NodeHttpAddress: hadoop-210-5:8042, Resource: <memory:1024, vCores:1>, Priority: 20, State: NEW, Token: null, Status: container_id {, app_attempt_id {, application_id {, id: 3, cluster_timestamp: 1376050148932, }, attemptId: 1, }, id: 3, }, state: C_COMPLETE, diagnostics: "Container killed by the ApplicationMaster.\n\n", exit_status: 143, ] resource=<memory:1024, vCores:1> queue=default: capacity=1.0, absoluteCapacity=1.0, usedResources=<memory:3072, vCores:2>usedCapacity=0.0625, absoluteUsedCapacity=0.0625, numApps=1, numContainers=2 usedCapacity=0.0625 absoluteUsedCapacity=0.0625 used=<memory:3072, vCores:2> cluster=<memory:49152, vCores:96>
2013-08-09 12:18:41,630 INFO org.apache.hadoop.yarn.server.resourcemanager.scheduler.capacity.ParentQueue: completedContainer queue=root usedCapacity=0.0625 absoluteUsedCapacity=0.0625 used=<memory:3072, vCores:2> cluster=<memory:49152, vCores:96>
2013-08-09 12:18:41,630 INFO org.apache.hadoop.yarn.server.resourcemanager.scheduler.capacity.CapacityScheduler: Application appattempt_1376050148932_0003_000001 released container container_1376050148932_0003_01_000003 on node: host: hadoop-210-5:60822 #containers=0 available=8192 used=0 with event: FINISHED
2013-08-09 12:18:41,889 INFO org.apache.hadoop.yarn.server.resourcemanager.rmcontainer.RMContainerImpl: container_1376050148932_0003_01_000002 Container Transitioned from RUNNING to COMPLETED
2013-08-09 12:18:41,890 INFO org.apache.hadoop.yarn.server.resourcemanager.scheduler.common.fica.FiCaSchedulerApp: Completed container: container_1376050148932_0003_01_000002 in state: COMPLETED event:FINISHED
2013-08-09 12:18:41,890 INFO org.apache.hadoop.yarn.server.resourcemanager.RMAuditLogger: USER=ubuntu	OPERATION=AM Released Container	TARGET=SchedulerApp	RESULT=SUCCESS	APPID=application_1376050148932_0003	CONTAINERID=container_1376050148932_0003_01_000002
2013-08-09 12:18:41,890 INFO org.apache.hadoop.yarn.server.resourcemanager.scheduler.common.fica.FiCaSchedulerNode: Released container container_1376050148932_0003_01_000002 of capacity <memory:1024, vCores:1> on host hadoop-210-4:57908, which currently has 1 containers, <memory:2048, vCores:1> used and <memory:6144, vCores:15> available, release resources=true
2013-08-09 12:18:41,890 INFO org.apache.hadoop.yarn.server.resourcemanager.scheduler.capacity.LeafQueue: default used=<memory:2048, vCores:1> numContainers=1 user=ubuntu user-resources=<memory:2048, vCores:1>
2013-08-09 12:18:41,892 INFO org.apache.hadoop.yarn.server.resourcemanager.scheduler.capacity.LeafQueue: completedContainer container=Container: [ContainerId: container_1376050148932_0003_01_000002, NodeId: hadoop-210-4:57908, NodeHttpAddress: hadoop-210-4:8042, Resource: <memory:1024, vCores:1>, Priority: 20, State: NEW, Token: null, Status: container_id {, app_attempt_id {, application_id {, id: 3, cluster_timestamp: 1376050148932, }, attemptId: 1, }, id: 2, }, state: C_COMPLETE, diagnostics: "Container killed by the ApplicationMaster.\n", exit_status: 0, ] resource=<memory:1024, vCores:1> queue=default: capacity=1.0, absoluteCapacity=1.0, usedResources=<memory:2048, vCores:1>usedCapacity=0.041666668, absoluteUsedCapacity=0.041666668, numApps=1, numContainers=1 usedCapacity=0.041666668 absoluteUsedCapacity=0.041666668 used=<memory:2048, vCores:1> cluster=<memory:49152, vCores:96>
2013-08-09 12:18:41,892 INFO org.apache.hadoop.yarn.server.resourcemanager.scheduler.capacity.ParentQueue: completedContainer queue=root usedCapacity=0.041666668 absoluteUsedCapacity=0.041666668 used=<memory:2048, vCores:1> cluster=<memory:49152, vCores:96>
2013-08-09 12:18:41,892 INFO org.apache.hadoop.yarn.server.resourcemanager.scheduler.capacity.CapacityScheduler: Application appattempt_1376050148932_0003_000001 released container container_1376050148932_0003_01_000002 on node: host: hadoop-210-4:57908 #containers=1 available=6144 used=2048 with event: FINISHED
2013-08-09 12:18:46,069 INFO org.apache.hadoop.yarn.server.resourcemanager.rmapp.attempt.RMAppAttemptImpl: appattempt_1376050148932_0003_000001 State change from RUNNING to FINISHING
2013-08-09 12:18:46,070 INFO org.apache.hadoop.yarn.server.resourcemanager.rmapp.RMAppImpl: application_1376050148932_0003 State change from RUNNING to FINISHING
2013-08-09 12:18:46,914 INFO org.apache.hadoop.yarn.server.resourcemanager.rmcontainer.RMContainerImpl: container_1376050148932_0003_01_000001 Container Transitioned from RUNNING to COMPLETED
2013-08-09 12:18:46,914 INFO org.apache.hadoop.yarn.server.resourcemanager.scheduler.common.fica.FiCaSchedulerApp: Completed container: container_1376050148932_0003_01_000001 in state: COMPLETED event:FINISHED
2013-08-09 12:18:46,914 INFO org.apache.hadoop.yarn.server.resourcemanager.RMAuditLogger: USER=ubuntu	OPERATION=AM Released Container	TARGET=SchedulerApp	RESULT=SUCCESS	APPID=application_1376050148932_0003	CONTAINERID=container_1376050148932_0003_01_000001
2013-08-09 12:18:46,914 INFO org.apache.hadoop.yarn.server.resourcemanager.scheduler.common.fica.FiCaSchedulerNode: Released container container_1376050148932_0003_01_000001 of capacity <memory:2048, vCores:1> on host hadoop-210-4:57908, which currently has 0 containers, <memory:0, vCores:0> used and <memory:8192, vCores:16> available, release resources=true
2013-08-09 12:18:46,915 INFO org.apache.hadoop.yarn.server.resourcemanager.scheduler.capacity.LeafQueue: default used=<memory:0, vCores:0> numContainers=0 user=ubuntu user-resources=<memory:0, vCores:0>
2013-08-09 12:18:46,915 INFO org.apache.hadoop.yarn.server.resourcemanager.scheduler.capacity.LeafQueue: completedContainer container=Container: [ContainerId: container_1376050148932_0003_01_000001, NodeId: hadoop-210-4:57908, NodeHttpAddress: hadoop-210-4:8042, Resource: <memory:2048, vCores:1>, Priority: 0, State: NEW, Token: null, Status: container_id {, app_attempt_id {, application_id {, id: 3, cluster_timestamp: 1376050148932, }, attemptId: 1, }, id: 1, }, state: C_COMPLETE, diagnostics: "", exit_status: 0, ] resource=<memory:2048, vCores:1> queue=default: capacity=1.0, absoluteCapacity=1.0, usedResources=<memory:0, vCores:0>usedCapacity=0.0, absoluteUsedCapacity=0.0, numApps=1, numContainers=0 usedCapacity=0.0 absoluteUsedCapacity=0.0 used=<memory:0, vCores:0> cluster=<memory:49152, vCores:96>
2013-08-09 12:18:46,915 INFO org.apache.hadoop.yarn.server.resourcemanager.scheduler.capacity.ParentQueue: completedContainer queue=root usedCapacity=0.0 absoluteUsedCapacity=0.0 used=<memory:0, vCores:0> cluster=<memory:49152, vCores:96>
2013-08-09 12:18:46,916 INFO org.apache.hadoop.yarn.server.resourcemanager.scheduler.capacity.CapacityScheduler: Application appattempt_1376050148932_0003_000001 released container container_1376050148932_0003_01_000001 on node: host: hadoop-210-4:57908 #containers=0 available=8192 used=0 with event: FINISHED
2013-08-09 12:18:46,916 INFO org.apache.hadoop.yarn.server.resourcemanager.rmapp.attempt.RMAppAttemptImpl: appattempt_1376050148932_0003_000001 State change from FINISHING to FINISHED
2013-08-09 12:18:46,916 INFO org.apache.hadoop.yarn.server.resourcemanager.rmapp.RMAppImpl: application_1376050148932_0003 State change from FINISHING to FINISHED
2013-08-09 12:18:46,917 INFO org.apache.hadoop.yarn.server.resourcemanager.scheduler.capacity.CapacityScheduler: Application appattempt_1376050148932_0003_000001 is done. finalState=FINISHED
2013-08-09 12:18:46,917 INFO org.apache.hadoop.yarn.server.resourcemanager.scheduler.AppSchedulingInfo: Application application_1376050148932_0003 requests cleared
2013-08-09 12:18:46,917 INFO org.apache.hadoop.yarn.server.resourcemanager.scheduler.capacity.LeafQueue: Application removed - appId: application_1376050148932_0003 user: ubuntu queue: default #user-pending-applications: 0 #user-active-applications: 0 #queue-pending-applications: 0 #queue-active-applications: 0
2013-08-09 12:18:46,917 INFO org.apache.hadoop.yarn.server.resourcemanager.scheduler.capacity.ParentQueue: Application removed - appId: application_1376050148932_0003 user: ubuntu leaf-queue of parent: root #applications: 0
2013-08-09 12:18:46,917 INFO org.apache.hadoop.yarn.server.resourcemanager.RMAuditLogger: USER=ubuntu	OPERATION=Application Finished - Succeeded	TARGET=RMAppManager	RESULT=SUCCESS	APPID=application_1376050148932_0003
2013-08-09 12:18:46,917 INFO org.apache.hadoop.yarn.server.resourcemanager.amlauncher.AMLauncher: Cleaning master appattempt_1376050148932_0003_000001
2013-08-09 12:18:46,917 INFO org.apache.hadoop.yarn.server.resourcemanager.RMAppManager$ApplicationSummary: appId=application_1376050148932_0003,name=TeraGen,user=ubuntu,queue=default,state=FINISHED,trackingUrl=hadoop-210-1.novalocal:8088/proxy/application_1376050148932_0003/jobhistory/job/job_1376050148932_0003,appMasterHost=hadoop-210-4,startTime=1376050588453,finishTime=1376050726070
2013-08-09 12:18:46,918 INFO org.apache.hadoop.yarn.server.resourcemanager.recovery.RMStateStore: Removing info for app: application_1376050148932_0003
2013-08-09 12:18:47,161 INFO org.apache.hadoop.yarn.server.resourcemanager.ClientRMService: Allocated new applicationId: 4
2013-08-09 12:18:49,026 INFO org.apache.hadoop.yarn.server.resourcemanager.ClientRMService: Storing Application with id application_1376050148932_0004
2013-08-09 12:18:49,026 INFO org.apache.hadoop.yarn.server.resourcemanager.recovery.RMStateStore: Storing info for app: application_1376050148932_0004
2013-08-09 12:18:49,026 INFO org.apache.hadoop.yarn.server.resourcemanager.ClientRMService: Application with id 4 submitted by user ubuntu
2013-08-09 12:18:49,026 INFO org.apache.hadoop.yarn.server.resourcemanager.RMAuditLogger: USER=ubuntu	IP=192.168.100.4	OPERATION=Submit Application Request	TARGET=ClientRMService	RESULT=SUCCESS	APPID=application_1376050148932_0004
2013-08-09 12:18:49,028 INFO org.apache.hadoop.yarn.server.resourcemanager.rmapp.RMAppImpl: application_1376050148932_0004 State change from NEW to SUBMITTED
2013-08-09 12:18:49,028 INFO org.apache.hadoop.yarn.server.resourcemanager.ApplicationMasterService: Registering appattempt_1376050148932_0004_000001
2013-08-09 12:18:49,028 INFO org.apache.hadoop.yarn.server.resourcemanager.rmapp.attempt.RMAppAttemptImpl: appattempt_1376050148932_0004_000001 State change from NEW to SUBMITTED
2013-08-09 12:18:49,029 INFO org.apache.hadoop.yarn.server.resourcemanager.scheduler.capacity.LeafQueue: Application application_1376050148932_0004 from user: ubuntu activated in queue: default
2013-08-09 12:18:49,029 INFO org.apache.hadoop.yarn.server.resourcemanager.scheduler.capacity.LeafQueue: Application added - appId: application_1376050148932_0004 user: org.apache.hadoop.yarn.server.resourcemanager.scheduler.capacity.LeafQueue$User@7025c45b, leaf-queue: default #user-pending-applications: 0 #user-active-applications: 1 #queue-pending-applications: 0 #queue-active-applications: 1
2013-08-09 12:18:49,029 INFO org.apache.hadoop.yarn.server.resourcemanager.scheduler.capacity.ParentQueue: Application added - appId: application_1376050148932_0004 user: ubuntu leaf-queue of parent: root #applications: 1
2013-08-09 12:18:49,029 INFO org.apache.hadoop.yarn.server.resourcemanager.scheduler.capacity.CapacityScheduler: Application Submission: appattempt_1376050148932_0004_000001, user: ubuntu queue: default: capacity=1.0, absoluteCapacity=1.0, usedResources=<memory:0, vCores:0>usedCapacity=0.0, absoluteUsedCapacity=0.0, numApps=1, numContainers=0, currently active: 1
2013-08-09 12:18:49,030 INFO org.apache.hadoop.yarn.server.resourcemanager.rmapp.attempt.RMAppAttemptImpl: appattempt_1376050148932_0004_000001 State change from SUBMITTED to SCHEDULED
2013-08-09 12:18:49,030 INFO org.apache.hadoop.yarn.server.resourcemanager.rmapp.RMAppImpl: application_1376050148932_0004 State change from SUBMITTED to ACCEPTED
2013-08-09 12:18:49,657 INFO org.apache.hadoop.yarn.server.resourcemanager.rmcontainer.RMContainerImpl: container_1376050148932_0004_01_000001 Container Transitioned from NEW to ALLOCATED
2013-08-09 12:18:49,657 INFO org.apache.hadoop.yarn.server.resourcemanager.RMAuditLogger: USER=ubuntu	OPERATION=AM Allocated Container	TARGET=SchedulerApp	RESULT=SUCCESS	APPID=application_1376050148932_0004	CONTAINERID=container_1376050148932_0004_01_000001
2013-08-09 12:18:49,657 INFO org.apache.hadoop.yarn.server.resourcemanager.scheduler.common.fica.FiCaSchedulerNode: Assigned container container_1376050148932_0004_01_000001 of capacity <memory:2048, vCores:1> on host hadoop-210-5:60822, which currently has 1 containers, <memory:2048, vCores:1> used and <memory:6144, vCores:15> available
2013-08-09 12:18:49,659 INFO org.apache.hadoop.yarn.server.resourcemanager.scheduler.capacity.LeafQueue: assignedContainer application=application_1376050148932_0004 container=Container: [ContainerId: container_1376050148932_0004_01_000001, NodeId: hadoop-210-5:60822, NodeHttpAddress: hadoop-210-5:8042, Resource: <memory:2048, vCores:1>, Priority: 0, State: NEW, Token: null, Status: container_id {, app_attempt_id {, application_id {, id: 4, cluster_timestamp: 1376050148932, }, attemptId: 1, }, id: 1, }, state: C_NEW, ] containerId=container_1376050148932_0004_01_000001 queue=default: capacity=1.0, absoluteCapacity=1.0, usedResources=<memory:0, vCores:0>usedCapacity=0.0, absoluteUsedCapacity=0.0, numApps=1, numContainers=0 usedCapacity=0.0 absoluteUsedCapacity=0.0 used=<memory:0, vCores:0> cluster=<memory:49152, vCores:96>
2013-08-09 12:18:49,659 INFO org.apache.hadoop.yarn.server.resourcemanager.scheduler.capacity.ParentQueue: Re-sorting queues since queue: root.default stats: default: capacity=1.0, absoluteCapacity=1.0, usedResources=<memory:2048, vCores:1>usedCapacity=0.041666668, absoluteUsedCapacity=0.041666668, numApps=1, numContainers=1
2013-08-09 12:18:49,659 INFO org.apache.hadoop.yarn.server.resourcemanager.scheduler.capacity.ParentQueue: assignedContainer queue=root usedCapacity=0.041666668 absoluteUsedCapacity=0.041666668 used=<memory:2048, vCores:1> cluster=<memory:49152, vCores:96>
2013-08-09 12:18:49,661 INFO org.apache.hadoop.yarn.server.resourcemanager.rmcontainer.RMContainerImpl: container_1376050148932_0004_01_000001 Container Transitioned from ALLOCATED to ACQUIRED
2013-08-09 12:18:49,662 INFO org.apache.hadoop.yarn.server.resourcemanager.rmapp.attempt.RMAppAttemptImpl: Storing attempt: AppId: application_1376050148932_0004 AttemptId: appattempt_1376050148932_0004_000001 MasterContainer: Container: [ContainerId: container_1376050148932_0004_01_000001, NodeId: hadoop-210-5:60822, NodeHttpAddress: hadoop-210-5:8042, Resource: <memory:2048, vCores:1>, Priority: 0, State: NEW, Token: null, Status: container_id {, app_attempt_id {, application_id {, id: 4, cluster_timestamp: 1376050148932, }, attemptId: 1, }, id: 1, }, state: C_NEW, ]
2013-08-09 12:18:49,663 INFO org.apache.hadoop.yarn.server.resourcemanager.rmapp.attempt.RMAppAttemptImpl: appattempt_1376050148932_0004_000001 State change from SCHEDULED to ALLOCATED_SAVING
2013-08-09 12:18:49,663 INFO org.apache.hadoop.yarn.server.resourcemanager.recovery.RMStateStore: Storing info for attempt: appattempt_1376050148932_0004_000001
2013-08-09 12:18:49,665 INFO org.apache.hadoop.yarn.server.resourcemanager.rmapp.attempt.RMAppAttemptImpl: appattempt_1376050148932_0004_000001 State change from ALLOCATED_SAVING to ALLOCATED
2013-08-09 12:18:49,667 INFO org.apache.hadoop.yarn.server.resourcemanager.amlauncher.AMLauncher: Launching masterappattempt_1376050148932_0004_000001
2013-08-09 12:18:49,670 INFO org.apache.hadoop.yarn.server.resourcemanager.amlauncher.AMLauncher: Setting up container Container: [ContainerId: container_1376050148932_0004_01_000001, NodeId: hadoop-210-5:60822, NodeHttpAddress: hadoop-210-5:8042, Resource: <memory:2048, vCores:1>, Priority: 0, State: NEW, Token: null, Status: container_id {, app_attempt_id {, application_id {, id: 4, cluster_timestamp: 1376050148932, }, attemptId: 1, }, id: 1, }, state: C_NEW, ] for AM appattempt_1376050148932_0004_000001
2013-08-09 12:18:49,670 INFO org.apache.hadoop.yarn.server.resourcemanager.amlauncher.AMLauncher: Command to launch container container_1376050148932_0004_01_000001 : $JAVA_HOME/bin/java -Dlog4j.configuration=container-log4j.properties -Dyarn.app.mapreduce.container.log.dir=<LOG_DIR> -Dyarn.app.mapreduce.container.log.filesize=0 -Dhadoop.root.logger=INFO,CLA  -Xmx1024m org.apache.hadoop.mapreduce.v2.app.MRAppMaster 1><LOG_DIR>/stdout 2><LOG_DIR>/stderr 
2013-08-09 12:18:49,684 INFO org.apache.hadoop.yarn.server.resourcemanager.amlauncher.AMLauncher: Done launching container Container: [ContainerId: container_1376050148932_0004_01_000001, NodeId: hadoop-210-5:60822, NodeHttpAddress: hadoop-210-5:8042, Resource: <memory:2048, vCores:1>, Priority: 0, State: NEW, Token: null, Status: container_id {, app_attempt_id {, application_id {, id: 4, cluster_timestamp: 1376050148932, }, attemptId: 1, }, id: 1, }, state: C_NEW, ] for AM appattempt_1376050148932_0004_000001
2013-08-09 12:18:49,685 INFO org.apache.hadoop.yarn.server.resourcemanager.rmapp.attempt.RMAppAttemptImpl: appattempt_1376050148932_0004_000001 State change from ALLOCATED to LAUNCHED
2013-08-09 12:18:50,665 INFO org.apache.hadoop.yarn.server.resourcemanager.rmcontainer.RMContainerImpl: container_1376050148932_0004_01_000001 Container Transitioned from ACQUIRED to RUNNING
2013-08-09 12:18:56,459 INFO org.apache.hadoop.yarn.server.resourcemanager.ApplicationMasterService: AM registration appattempt_1376050148932_0004_000001
2013-08-09 12:18:56,460 INFO org.apache.hadoop.yarn.server.resourcemanager.RMAuditLogger: USER=ubuntu	IP=192.168.100.11	OPERATION=Register App Master	TARGET=ApplicationMasterService	RESULT=SUCCESS	APPID=application_1376050148932_0004	APPATTEMPTID=appattempt_1376050148932_0004_000001
2013-08-09 12:18:56,461 INFO org.apache.hadoop.yarn.server.resourcemanager.rmapp.attempt.RMAppAttemptImpl: appattempt_1376050148932_0004_000001 State change from LAUNCHED to RUNNING
2013-08-09 12:18:56,461 INFO org.apache.hadoop.yarn.server.resourcemanager.rmapp.RMAppImpl: application_1376050148932_0004 State change from ACCEPTED to RUNNING
2013-08-09 12:18:57,698 INFO org.apache.hadoop.yarn.server.resourcemanager.rmcontainer.RMContainerImpl: container_1376050148932_0004_01_000002 Container Transitioned from NEW to ALLOCATED
2013-08-09 12:18:57,698 INFO org.apache.hadoop.yarn.server.resourcemanager.RMAuditLogger: USER=ubuntu	OPERATION=AM Allocated Container	TARGET=SchedulerApp	RESULT=SUCCESS	APPID=application_1376050148932_0004	CONTAINERID=container_1376050148932_0004_01_000002
2013-08-09 12:18:57,699 INFO org.apache.hadoop.yarn.server.resourcemanager.scheduler.common.fica.FiCaSchedulerNode: Assigned container container_1376050148932_0004_01_000002 of capacity <memory:1024, vCores:1> on host hadoop-210-5:60822, which currently has 2 containers, <memory:3072, vCores:2> used and <memory:5120, vCores:14> available
2013-08-09 12:18:57,700 INFO org.apache.hadoop.yarn.server.resourcemanager.scheduler.capacity.LeafQueue: assignedContainer application=application_1376050148932_0004 container=Container: [ContainerId: container_1376050148932_0004_01_000002, NodeId: hadoop-210-5:60822, NodeHttpAddress: hadoop-210-5:8042, Resource: <memory:1024, vCores:1>, Priority: 20, State: NEW, Token: null, Status: container_id {, app_attempt_id {, application_id {, id: 4, cluster_timestamp: 1376050148932, }, attemptId: 1, }, id: 2, }, state: C_NEW, ] containerId=container_1376050148932_0004_01_000002 queue=default: capacity=1.0, absoluteCapacity=1.0, usedResources=<memory:2048, vCores:1>usedCapacity=0.041666668, absoluteUsedCapacity=0.041666668, numApps=1, numContainers=1 usedCapacity=0.041666668 absoluteUsedCapacity=0.041666668 used=<memory:2048, vCores:1> cluster=<memory:49152, vCores:96>
2013-08-09 12:18:57,700 INFO org.apache.hadoop.yarn.server.resourcemanager.scheduler.capacity.ParentQueue: Re-sorting queues since queue: root.default stats: default: capacity=1.0, absoluteCapacity=1.0, usedResources=<memory:3072, vCores:2>usedCapacity=0.0625, absoluteUsedCapacity=0.0625, numApps=1, numContainers=2
2013-08-09 12:18:57,701 INFO org.apache.hadoop.yarn.server.resourcemanager.scheduler.capacity.ParentQueue: assignedContainer queue=root usedCapacity=0.0625 absoluteUsedCapacity=0.0625 used=<memory:3072, vCores:2> cluster=<memory:49152, vCores:96>
2013-08-09 12:18:57,741 INFO org.apache.hadoop.yarn.server.resourcemanager.rmcontainer.RMContainerImpl: container_1376050148932_0004_01_000003 Container Transitioned from NEW to ALLOCATED
2013-08-09 12:18:57,742 INFO org.apache.hadoop.yarn.server.resourcemanager.RMAuditLogger: USER=ubuntu	OPERATION=AM Allocated Container	TARGET=SchedulerApp	RESULT=SUCCESS	APPID=application_1376050148932_0004	CONTAINERID=container_1376050148932_0004_01_000003
2013-08-09 12:18:57,742 INFO org.apache.hadoop.yarn.server.resourcemanager.scheduler.common.fica.FiCaSchedulerNode: Assigned container container_1376050148932_0004_01_000003 of capacity <memory:1024, vCores:1> on host hadoop-210-6:38267, which currently has 1 containers, <memory:1024, vCores:1> used and <memory:7168, vCores:15> available
2013-08-09 12:18:57,743 INFO org.apache.hadoop.yarn.server.resourcemanager.scheduler.capacity.LeafQueue: assignedContainer application=application_1376050148932_0004 container=Container: [ContainerId: container_1376050148932_0004_01_000003, NodeId: hadoop-210-6:38267, NodeHttpAddress: hadoop-210-6:8042, Resource: <memory:1024, vCores:1>, Priority: 20, State: NEW, Token: null, Status: container_id {, app_attempt_id {, application_id {, id: 4, cluster_timestamp: 1376050148932, }, attemptId: 1, }, id: 3, }, state: C_NEW, ] containerId=container_1376050148932_0004_01_000003 queue=default: capacity=1.0, absoluteCapacity=1.0, usedResources=<memory:3072, vCores:2>usedCapacity=0.0625, absoluteUsedCapacity=0.0625, numApps=1, numContainers=2 usedCapacity=0.0625 absoluteUsedCapacity=0.0625 used=<memory:3072, vCores:2> cluster=<memory:49152, vCores:96>
2013-08-09 12:18:57,744 INFO org.apache.hadoop.yarn.server.resourcemanager.scheduler.capacity.ParentQueue: Re-sorting queues since queue: root.default stats: default: capacity=1.0, absoluteCapacity=1.0, usedResources=<memory:4096, vCores:3>usedCapacity=0.083333336, absoluteUsedCapacity=0.083333336, numApps=1, numContainers=3
2013-08-09 12:18:57,744 INFO org.apache.hadoop.yarn.server.resourcemanager.scheduler.capacity.ParentQueue: assignedContainer queue=root usedCapacity=0.083333336 absoluteUsedCapacity=0.083333336 used=<memory:4096, vCores:3> cluster=<memory:49152, vCores:96>
2013-08-09 12:18:58,533 INFO org.apache.hadoop.yarn.server.resourcemanager.rmcontainer.RMContainerImpl: container_1376050148932_0004_01_000002 Container Transitioned from ALLOCATED to ACQUIRED
2013-08-09 12:18:58,535 INFO org.apache.hadoop.yarn.server.resourcemanager.rmcontainer.RMContainerImpl: container_1376050148932_0004_01_000003 Container Transitioned from ALLOCATED to ACQUIRED
2013-08-09 12:18:59,573 INFO org.apache.hadoop.yarn.server.resourcemanager.scheduler.AppSchedulingInfo: checking for deactivate... 
2013-08-09 12:18:59,711 INFO org.apache.hadoop.yarn.server.resourcemanager.rmcontainer.RMContainerImpl: container_1376050148932_0004_01_000002 Container Transitioned from ACQUIRED to RUNNING
2013-08-09 12:18:59,750 INFO org.apache.hadoop.yarn.server.resourcemanager.rmcontainer.RMContainerImpl: container_1376050148932_0004_01_000003 Container Transitioned from ACQUIRED to RUNNING
2013-08-09 12:20:50,417 INFO org.apache.hadoop.yarn.server.resourcemanager.rmcontainer.RMContainerImpl: container_1376050148932_0004_01_000002 Container Transitioned from RUNNING to COMPLETED
2013-08-09 12:20:50,417 INFO org.apache.hadoop.yarn.server.resourcemanager.scheduler.common.fica.FiCaSchedulerApp: Completed container: container_1376050148932_0004_01_000002 in state: COMPLETED event:FINISHED
2013-08-09 12:20:50,417 INFO org.apache.hadoop.yarn.server.resourcemanager.RMAuditLogger: USER=ubuntu	OPERATION=AM Released Container	TARGET=SchedulerApp	RESULT=SUCCESS	APPID=application_1376050148932_0004	CONTAINERID=container_1376050148932_0004_01_000002
2013-08-09 12:20:50,418 INFO org.apache.hadoop.yarn.server.resourcemanager.scheduler.common.fica.FiCaSchedulerNode: Released container container_1376050148932_0004_01_000002 of capacity <memory:1024, vCores:1> on host hadoop-210-5:60822, which currently has 1 containers, <memory:2048, vCores:1> used and <memory:6144, vCores:15> available, release resources=true
2013-08-09 12:20:50,418 INFO org.apache.hadoop.yarn.server.resourcemanager.scheduler.capacity.LeafQueue: default used=<memory:3072, vCores:2> numContainers=2 user=ubuntu user-resources=<memory:3072, vCores:2>
2013-08-09 12:20:50,419 INFO org.apache.hadoop.yarn.server.resourcemanager.scheduler.capacity.LeafQueue: completedContainer container=Container: [ContainerId: container_1376050148932_0004_01_000002, NodeId: hadoop-210-5:60822, NodeHttpAddress: hadoop-210-5:8042, Resource: <memory:1024, vCores:1>, Priority: 20, State: NEW, Token: null, Status: container_id {, app_attempt_id {, application_id {, id: 4, cluster_timestamp: 1376050148932, }, attemptId: 1, }, id: 2, }, state: C_COMPLETE, diagnostics: "Container killed by the ApplicationMaster.\n\n", exit_status: 143, ] resource=<memory:1024, vCores:1> queue=default: capacity=1.0, absoluteCapacity=1.0, usedResources=<memory:3072, vCores:2>usedCapacity=0.0625, absoluteUsedCapacity=0.0625, numApps=1, numContainers=2 usedCapacity=0.0625 absoluteUsedCapacity=0.0625 used=<memory:3072, vCores:2> cluster=<memory:49152, vCores:96>
2013-08-09 12:20:50,420 INFO org.apache.hadoop.yarn.server.resourcemanager.scheduler.capacity.ParentQueue: completedContainer queue=root usedCapacity=0.0625 absoluteUsedCapacity=0.0625 used=<memory:3072, vCores:2> cluster=<memory:49152, vCores:96>
2013-08-09 12:20:50,420 INFO org.apache.hadoop.yarn.server.resourcemanager.scheduler.capacity.CapacityScheduler: Application appattempt_1376050148932_0004_000001 released container container_1376050148932_0004_01_000002 on node: host: hadoop-210-5:60822 #containers=1 available=6144 used=2048 with event: FINISHED
2013-08-09 12:20:55,187 INFO org.apache.hadoop.yarn.server.resourcemanager.rmcontainer.RMContainerImpl: container_1376050148932_0004_01_000003 Container Transitioned from RUNNING to COMPLETED
2013-08-09 12:20:55,188 INFO org.apache.hadoop.yarn.server.resourcemanager.scheduler.common.fica.FiCaSchedulerApp: Completed container: container_1376050148932_0004_01_000003 in state: COMPLETED event:FINISHED
2013-08-09 12:20:55,188 INFO org.apache.hadoop.yarn.server.resourcemanager.RMAuditLogger: USER=ubuntu	OPERATION=AM Released Container	TARGET=SchedulerApp	RESULT=SUCCESS	APPID=application_1376050148932_0004	CONTAINERID=container_1376050148932_0004_01_000003
2013-08-09 12:20:55,188 INFO org.apache.hadoop.yarn.server.resourcemanager.scheduler.common.fica.FiCaSchedulerNode: Released container container_1376050148932_0004_01_000003 of capacity <memory:1024, vCores:1> on host hadoop-210-6:38267, which currently has 0 containers, <memory:0, vCores:0> used and <memory:8192, vCores:16> available, release resources=true
2013-08-09 12:20:55,188 INFO org.apache.hadoop.yarn.server.resourcemanager.scheduler.capacity.LeafQueue: default used=<memory:2048, vCores:1> numContainers=1 user=ubuntu user-resources=<memory:2048, vCores:1>
2013-08-09 12:20:55,190 INFO org.apache.hadoop.yarn.server.resourcemanager.scheduler.capacity.LeafQueue: completedContainer container=Container: [ContainerId: container_1376050148932_0004_01_000003, NodeId: hadoop-210-6:38267, NodeHttpAddress: hadoop-210-6:8042, Resource: <memory:1024, vCores:1>, Priority: 20, State: NEW, Token: null, Status: container_id {, app_attempt_id {, application_id {, id: 4, cluster_timestamp: 1376050148932, }, attemptId: 1, }, id: 3, }, state: C_COMPLETE, diagnostics: "Container killed by the ApplicationMaster.\n\n", exit_status: 143, ] resource=<memory:1024, vCores:1> queue=default: capacity=1.0, absoluteCapacity=1.0, usedResources=<memory:2048, vCores:1>usedCapacity=0.041666668, absoluteUsedCapacity=0.041666668, numApps=1, numContainers=1 usedCapacity=0.041666668 absoluteUsedCapacity=0.041666668 used=<memory:2048, vCores:1> cluster=<memory:49152, vCores:96>
2013-08-09 12:20:55,190 INFO org.apache.hadoop.yarn.server.resourcemanager.scheduler.capacity.ParentQueue: completedContainer queue=root usedCapacity=0.041666668 absoluteUsedCapacity=0.041666668 used=<memory:2048, vCores:1> cluster=<memory:49152, vCores:96>
2013-08-09 12:20:55,190 INFO org.apache.hadoop.yarn.server.resourcemanager.scheduler.capacity.CapacityScheduler: Application appattempt_1376050148932_0004_000001 released container container_1376050148932_0004_01_000003 on node: host: hadoop-210-6:38267 #containers=0 available=8192 used=0 with event: FINISHED
2013-08-09 12:20:59,739 INFO org.apache.hadoop.yarn.server.resourcemanager.rmapp.attempt.RMAppAttemptImpl: appattempt_1376050148932_0004_000001 State change from RUNNING to FINISHING
2013-08-09 12:20:59,740 INFO org.apache.hadoop.yarn.server.resourcemanager.rmapp.RMAppImpl: application_1376050148932_0004 State change from RUNNING to FINISHING
2013-08-09 12:21:00,448 INFO org.apache.hadoop.yarn.server.resourcemanager.rmcontainer.RMContainerImpl: container_1376050148932_0004_01_000001 Container Transitioned from RUNNING to COMPLETED
2013-08-09 12:21:00,449 INFO org.apache.hadoop.yarn.server.resourcemanager.scheduler.common.fica.FiCaSchedulerApp: Completed container: container_1376050148932_0004_01_000001 in state: COMPLETED event:FINISHED
2013-08-09 12:21:00,449 INFO org.apache.hadoop.yarn.server.resourcemanager.rmapp.attempt.RMAppAttemptImpl: appattempt_1376050148932_0004_000001 State change from FINISHING to FINISHED
2013-08-09 12:21:00,449 INFO org.apache.hadoop.yarn.server.resourcemanager.RMAuditLogger: USER=ubuntu	OPERATION=AM Released Container	TARGET=SchedulerApp	RESULT=SUCCESS	APPID=application_1376050148932_0004	CONTAINERID=container_1376050148932_0004_01_000001
2013-08-09 12:21:00,449 INFO org.apache.hadoop.yarn.server.resourcemanager.rmapp.RMAppImpl: application_1376050148932_0004 State change from FINISHING to FINISHED
2013-08-09 12:21:00,449 INFO org.apache.hadoop.yarn.server.resourcemanager.scheduler.common.fica.FiCaSchedulerNode: Released container container_1376050148932_0004_01_000001 of capacity <memory:2048, vCores:1> on host hadoop-210-5:60822, which currently has 0 containers, <memory:0, vCores:0> used and <memory:8192, vCores:16> available, release resources=true
2013-08-09 12:21:00,449 INFO org.apache.hadoop.yarn.server.resourcemanager.scheduler.capacity.LeafQueue: default used=<memory:0, vCores:0> numContainers=0 user=ubuntu user-resources=<memory:0, vCores:0>
2013-08-09 12:21:00,449 INFO org.apache.hadoop.yarn.server.resourcemanager.RMAuditLogger: USER=ubuntu	OPERATION=Application Finished - Succeeded	TARGET=RMAppManager	RESULT=SUCCESS	APPID=application_1376050148932_0004
2013-08-09 12:21:00,450 INFO org.apache.hadoop.yarn.server.resourcemanager.RMAppManager$ApplicationSummary: appId=application_1376050148932_0004,name=TeraGen,user=ubuntu,queue=default,state=FINISHED,trackingUrl=hadoop-210-1.novalocal:8088/proxy/application_1376050148932_0004/jobhistory/job/job_1376050148932_0004,appMasterHost=hadoop-210-5,startTime=1376050729025,finishTime=1376050859740
2013-08-09 12:21:00,450 INFO org.apache.hadoop.yarn.server.resourcemanager.recovery.RMStateStore: Removing info for app: application_1376050148932_0004
2013-08-09 12:21:00,451 INFO org.apache.hadoop.yarn.server.resourcemanager.amlauncher.AMLauncher: Cleaning master appattempt_1376050148932_0004_000001
2013-08-09 12:21:00,451 INFO org.apache.hadoop.yarn.server.resourcemanager.scheduler.capacity.LeafQueue: completedContainer container=Container: [ContainerId: container_1376050148932_0004_01_000001, NodeId: hadoop-210-5:60822, NodeHttpAddress: hadoop-210-5:8042, Resource: <memory:2048, vCores:1>, Priority: 0, State: NEW, Token: null, Status: container_id {, app_attempt_id {, application_id {, id: 4, cluster_timestamp: 1376050148932, }, attemptId: 1, }, id: 1, }, state: C_COMPLETE, diagnostics: "", exit_status: 0, ] resource=<memory:2048, vCores:1> queue=default: capacity=1.0, absoluteCapacity=1.0, usedResources=<memory:0, vCores:0>usedCapacity=0.0, absoluteUsedCapacity=0.0, numApps=1, numContainers=0 usedCapacity=0.0 absoluteUsedCapacity=0.0 used=<memory:0, vCores:0> cluster=<memory:49152, vCores:96>
2013-08-09 12:21:00,451 INFO org.apache.hadoop.yarn.server.resourcemanager.scheduler.capacity.ParentQueue: completedContainer queue=root usedCapacity=0.0 absoluteUsedCapacity=0.0 used=<memory:0, vCores:0> cluster=<memory:49152, vCores:96>
2013-08-09 12:21:00,451 INFO org.apache.hadoop.yarn.server.resourcemanager.scheduler.capacity.CapacityScheduler: Application appattempt_1376050148932_0004_000001 released container container_1376050148932_0004_01_000001 on node: host: hadoop-210-5:60822 #containers=0 available=8192 used=0 with event: FINISHED
2013-08-09 12:21:00,451 INFO org.apache.hadoop.yarn.server.resourcemanager.scheduler.capacity.CapacityScheduler: Application appattempt_1376050148932_0004_000001 is done. finalState=FINISHED
2013-08-09 12:21:00,451 INFO org.apache.hadoop.yarn.server.resourcemanager.scheduler.AppSchedulingInfo: Application application_1376050148932_0004 requests cleared
2013-08-09 12:21:00,452 INFO org.apache.hadoop.yarn.server.resourcemanager.scheduler.capacity.LeafQueue: Application removed - appId: application_1376050148932_0004 user: ubuntu queue: default #user-pending-applications: 0 #user-active-applications: 0 #queue-pending-applications: 0 #queue-active-applications: 0
2013-08-09 12:21:00,452 INFO org.apache.hadoop.yarn.server.resourcemanager.scheduler.capacity.ParentQueue: Application removed - appId: application_1376050148932_0004 user: ubuntu leaf-queue of parent: root #applications: 0
2013-08-09 12:21:00,988 INFO org.apache.hadoop.yarn.server.resourcemanager.ClientRMService: Allocated new applicationId: 5
2013-08-09 12:21:02,883 INFO org.apache.hadoop.yarn.server.resourcemanager.ClientRMService: Storing Application with id application_1376050148932_0005
2013-08-09 12:21:02,884 INFO org.apache.hadoop.yarn.server.resourcemanager.recovery.RMStateStore: Storing info for app: application_1376050148932_0005
2013-08-09 12:21:02,884 INFO org.apache.hadoop.yarn.server.resourcemanager.ClientRMService: Application with id 5 submitted by user ubuntu
2013-08-09 12:21:02,884 INFO org.apache.hadoop.yarn.server.resourcemanager.RMAuditLogger: USER=ubuntu	IP=192.168.100.4	OPERATION=Submit Application Request	TARGET=ClientRMService	RESULT=SUCCESS	APPID=application_1376050148932_0005
2013-08-09 12:21:02,886 INFO org.apache.hadoop.yarn.server.resourcemanager.rmapp.RMAppImpl: application_1376050148932_0005 State change from NEW to SUBMITTED
2013-08-09 12:21:02,886 INFO org.apache.hadoop.yarn.server.resourcemanager.ApplicationMasterService: Registering appattempt_1376050148932_0005_000001
2013-08-09 12:21:02,887 INFO org.apache.hadoop.yarn.server.resourcemanager.rmapp.attempt.RMAppAttemptImpl: appattempt_1376050148932_0005_000001 State change from NEW to SUBMITTED
2013-08-09 12:21:02,887 INFO org.apache.hadoop.yarn.server.resourcemanager.scheduler.capacity.LeafQueue: Application application_1376050148932_0005 from user: ubuntu activated in queue: default
2013-08-09 12:21:02,887 INFO org.apache.hadoop.yarn.server.resourcemanager.scheduler.capacity.LeafQueue: Application added - appId: application_1376050148932_0005 user: org.apache.hadoop.yarn.server.resourcemanager.scheduler.capacity.LeafQueue$User@7138b045, leaf-queue: default #user-pending-applications: 0 #user-active-applications: 1 #queue-pending-applications: 0 #queue-active-applications: 1
2013-08-09 12:21:02,887 INFO org.apache.hadoop.yarn.server.resourcemanager.scheduler.capacity.ParentQueue: Application added - appId: application_1376050148932_0005 user: ubuntu leaf-queue of parent: root #applications: 1
2013-08-09 12:21:02,888 INFO org.apache.hadoop.yarn.server.resourcemanager.scheduler.capacity.CapacityScheduler: Application Submission: appattempt_1376050148932_0005_000001, user: ubuntu queue: default: capacity=1.0, absoluteCapacity=1.0, usedResources=<memory:0, vCores:0>usedCapacity=0.0, absoluteUsedCapacity=0.0, numApps=1, numContainers=0, currently active: 1
2013-08-09 12:21:02,888 INFO org.apache.hadoop.yarn.server.resourcemanager.rmapp.attempt.RMAppAttemptImpl: appattempt_1376050148932_0005_000001 State change from SUBMITTED to SCHEDULED
2013-08-09 12:21:02,888 INFO org.apache.hadoop.yarn.server.resourcemanager.rmapp.RMAppImpl: application_1376050148932_0005 State change from SUBMITTED to ACCEPTED
2013-08-09 12:21:03,216 INFO org.apache.hadoop.yarn.server.resourcemanager.rmcontainer.RMContainerImpl: container_1376050148932_0005_01_000001 Container Transitioned from NEW to ALLOCATED
2013-08-09 12:21:03,217 INFO org.apache.hadoop.yarn.server.resourcemanager.RMAuditLogger: USER=ubuntu	OPERATION=AM Allocated Container	TARGET=SchedulerApp	RESULT=SUCCESS	APPID=application_1376050148932_0005	CONTAINERID=container_1376050148932_0005_01_000001
2013-08-09 12:21:03,217 INFO org.apache.hadoop.yarn.server.resourcemanager.scheduler.common.fica.FiCaSchedulerNode: Assigned container container_1376050148932_0005_01_000001 of capacity <memory:2048, vCores:1> on host hadoop-210-6:38267, which currently has 1 containers, <memory:2048, vCores:1> used and <memory:6144, vCores:15> available
2013-08-09 12:21:03,218 INFO org.apache.hadoop.yarn.server.resourcemanager.scheduler.capacity.LeafQueue: assignedContainer application=application_1376050148932_0005 container=Container: [ContainerId: container_1376050148932_0005_01_000001, NodeId: hadoop-210-6:38267, NodeHttpAddress: hadoop-210-6:8042, Resource: <memory:2048, vCores:1>, Priority: 0, State: NEW, Token: null, Status: container_id {, app_attempt_id {, application_id {, id: 5, cluster_timestamp: 1376050148932, }, attemptId: 1, }, id: 1, }, state: C_NEW, ] containerId=container_1376050148932_0005_01_000001 queue=default: capacity=1.0, absoluteCapacity=1.0, usedResources=<memory:0, vCores:0>usedCapacity=0.0, absoluteUsedCapacity=0.0, numApps=1, numContainers=0 usedCapacity=0.0 absoluteUsedCapacity=0.0 used=<memory:0, vCores:0> cluster=<memory:49152, vCores:96>
2013-08-09 12:21:03,218 INFO org.apache.hadoop.yarn.server.resourcemanager.scheduler.capacity.ParentQueue: Re-sorting queues since queue: root.default stats: default: capacity=1.0, absoluteCapacity=1.0, usedResources=<memory:2048, vCores:1>usedCapacity=0.041666668, absoluteUsedCapacity=0.041666668, numApps=1, numContainers=1
2013-08-09 12:21:03,218 INFO org.apache.hadoop.yarn.server.resourcemanager.scheduler.capacity.ParentQueue: assignedContainer queue=root usedCapacity=0.041666668 absoluteUsedCapacity=0.041666668 used=<memory:2048, vCores:1> cluster=<memory:49152, vCores:96>
2013-08-09 12:21:03,220 INFO org.apache.hadoop.yarn.server.resourcemanager.rmcontainer.RMContainerImpl: container_1376050148932_0005_01_000001 Container Transitioned from ALLOCATED to ACQUIRED
2013-08-09 12:21:03,222 INFO org.apache.hadoop.yarn.server.resourcemanager.rmapp.attempt.RMAppAttemptImpl: Storing attempt: AppId: application_1376050148932_0005 AttemptId: appattempt_1376050148932_0005_000001 MasterContainer: Container: [ContainerId: container_1376050148932_0005_01_000001, NodeId: hadoop-210-6:38267, NodeHttpAddress: hadoop-210-6:8042, Resource: <memory:2048, vCores:1>, Priority: 0, State: NEW, Token: null, Status: container_id {, app_attempt_id {, application_id {, id: 5, cluster_timestamp: 1376050148932, }, attemptId: 1, }, id: 1, }, state: C_NEW, ]
2013-08-09 12:21:03,222 INFO org.apache.hadoop.yarn.server.resourcemanager.rmapp.attempt.RMAppAttemptImpl: appattempt_1376050148932_0005_000001 State change from SCHEDULED to ALLOCATED_SAVING
2013-08-09 12:21:03,222 INFO org.apache.hadoop.yarn.server.resourcemanager.recovery.RMStateStore: Storing info for attempt: appattempt_1376050148932_0005_000001
2013-08-09 12:21:03,223 INFO org.apache.hadoop.yarn.server.resourcemanager.rmapp.attempt.RMAppAttemptImpl: appattempt_1376050148932_0005_000001 State change from ALLOCATED_SAVING to ALLOCATED
2013-08-09 12:21:03,224 INFO org.apache.hadoop.yarn.server.resourcemanager.amlauncher.AMLauncher: Launching masterappattempt_1376050148932_0005_000001
2013-08-09 12:21:03,227 INFO org.apache.hadoop.yarn.server.resourcemanager.amlauncher.AMLauncher: Setting up container Container: [ContainerId: container_1376050148932_0005_01_000001, NodeId: hadoop-210-6:38267, NodeHttpAddress: hadoop-210-6:8042, Resource: <memory:2048, vCores:1>, Priority: 0, State: NEW, Token: null, Status: container_id {, app_attempt_id {, application_id {, id: 5, cluster_timestamp: 1376050148932, }, attemptId: 1, }, id: 1, }, state: C_NEW, ] for AM appattempt_1376050148932_0005_000001
2013-08-09 12:21:03,227 INFO org.apache.hadoop.yarn.server.resourcemanager.amlauncher.AMLauncher: Command to launch container container_1376050148932_0005_01_000001 : $JAVA_HOME/bin/java -Dlog4j.configuration=container-log4j.properties -Dyarn.app.mapreduce.container.log.dir=<LOG_DIR> -Dyarn.app.mapreduce.container.log.filesize=0 -Dhadoop.root.logger=INFO,CLA  -Xmx1024m org.apache.hadoop.mapreduce.v2.app.MRAppMaster 1><LOG_DIR>/stdout 2><LOG_DIR>/stderr 
2013-08-09 12:21:03,243 INFO org.apache.hadoop.yarn.server.resourcemanager.amlauncher.AMLauncher: Done launching container Container: [ContainerId: container_1376050148932_0005_01_000001, NodeId: hadoop-210-6:38267, NodeHttpAddress: hadoop-210-6:8042, Resource: <memory:2048, vCores:1>, Priority: 0, State: NEW, Token: null, Status: container_id {, app_attempt_id {, application_id {, id: 5, cluster_timestamp: 1376050148932, }, attemptId: 1, }, id: 1, }, state: C_NEW, ] for AM appattempt_1376050148932_0005_000001
2013-08-09 12:21:03,243 INFO org.apache.hadoop.yarn.server.resourcemanager.rmapp.attempt.RMAppAttemptImpl: appattempt_1376050148932_0005_000001 State change from ALLOCATED to LAUNCHED
2013-08-09 12:21:04,222 INFO org.apache.hadoop.yarn.server.resourcemanager.rmcontainer.RMContainerImpl: container_1376050148932_0005_01_000001 Container Transitioned from ACQUIRED to RUNNING
2013-08-09 12:21:10,333 INFO org.apache.hadoop.yarn.server.resourcemanager.ApplicationMasterService: AM registration appattempt_1376050148932_0005_000001
2013-08-09 12:21:10,334 INFO org.apache.hadoop.yarn.server.resourcemanager.RMAuditLogger: USER=ubuntu	IP=192.168.100.13	OPERATION=Register App Master	TARGET=ApplicationMasterService	RESULT=SUCCESS	APPID=application_1376050148932_0005	APPATTEMPTID=appattempt_1376050148932_0005_000001
2013-08-09 12:21:10,335 INFO org.apache.hadoop.yarn.server.resourcemanager.rmapp.attempt.RMAppAttemptImpl: appattempt_1376050148932_0005_000001 State change from LAUNCHED to RUNNING
2013-08-09 12:21:10,335 INFO org.apache.hadoop.yarn.server.resourcemanager.rmapp.RMAppImpl: application_1376050148932_0005 State change from ACCEPTED to RUNNING
2013-08-09 12:21:11,483 INFO org.apache.hadoop.yarn.server.resourcemanager.rmcontainer.RMContainerImpl: container_1376050148932_0005_01_000002 Container Transitioned from NEW to ALLOCATED
2013-08-09 12:21:11,483 INFO org.apache.hadoop.yarn.server.resourcemanager.RMAuditLogger: USER=ubuntu	OPERATION=AM Allocated Container	TARGET=SchedulerApp	RESULT=SUCCESS	APPID=application_1376050148932_0005	CONTAINERID=container_1376050148932_0005_01_000002
2013-08-09 12:21:11,483 INFO org.apache.hadoop.yarn.server.resourcemanager.scheduler.common.fica.FiCaSchedulerNode: Assigned container container_1376050148932_0005_01_000002 of capacity <memory:1024, vCores:1> on host hadoop-210-5:60822, which currently has 1 containers, <memory:1024, vCores:1> used and <memory:7168, vCores:15> available
2013-08-09 12:21:11,485 INFO org.apache.hadoop.yarn.server.resourcemanager.scheduler.capacity.LeafQueue: assignedContainer application=application_1376050148932_0005 container=Container: [ContainerId: container_1376050148932_0005_01_000002, NodeId: hadoop-210-5:60822, NodeHttpAddress: hadoop-210-5:8042, Resource: <memory:1024, vCores:1>, Priority: 20, State: NEW, Token: null, Status: container_id {, app_attempt_id {, application_id {, id: 5, cluster_timestamp: 1376050148932, }, attemptId: 1, }, id: 2, }, state: C_NEW, ] containerId=container_1376050148932_0005_01_000002 queue=default: capacity=1.0, absoluteCapacity=1.0, usedResources=<memory:2048, vCores:1>usedCapacity=0.041666668, absoluteUsedCapacity=0.041666668, numApps=1, numContainers=1 usedCapacity=0.041666668 absoluteUsedCapacity=0.041666668 used=<memory:2048, vCores:1> cluster=<memory:49152, vCores:96>
2013-08-09 12:21:11,485 INFO org.apache.hadoop.yarn.server.resourcemanager.scheduler.capacity.ParentQueue: Re-sorting queues since queue: root.default stats: default: capacity=1.0, absoluteCapacity=1.0, usedResources=<memory:3072, vCores:2>usedCapacity=0.0625, absoluteUsedCapacity=0.0625, numApps=1, numContainers=2
2013-08-09 12:21:11,485 INFO org.apache.hadoop.yarn.server.resourcemanager.scheduler.capacity.ParentQueue: assignedContainer queue=root usedCapacity=0.0625 absoluteUsedCapacity=0.0625 used=<memory:3072, vCores:2> cluster=<memory:49152, vCores:96>
2013-08-09 12:21:11,502 INFO org.apache.hadoop.yarn.server.resourcemanager.rmcontainer.RMContainerImpl: container_1376050148932_0005_01_000003 Container Transitioned from NEW to ALLOCATED
2013-08-09 12:21:11,502 INFO org.apache.hadoop.yarn.server.resourcemanager.RMAuditLogger: USER=ubuntu	OPERATION=AM Allocated Container	TARGET=SchedulerApp	RESULT=SUCCESS	APPID=application_1376050148932_0005	CONTAINERID=container_1376050148932_0005_01_000003
2013-08-09 12:21:11,503 INFO org.apache.hadoop.yarn.server.resourcemanager.scheduler.common.fica.FiCaSchedulerNode: Assigned container container_1376050148932_0005_01_000003 of capacity <memory:1024, vCores:1> on host hadoop-210-4:57908, which currently has 1 containers, <memory:1024, vCores:1> used and <memory:7168, vCores:15> available
2013-08-09 12:21:11,504 INFO org.apache.hadoop.yarn.server.resourcemanager.scheduler.capacity.LeafQueue: assignedContainer application=application_1376050148932_0005 container=Container: [ContainerId: container_1376050148932_0005_01_000003, NodeId: hadoop-210-4:57908, NodeHttpAddress: hadoop-210-4:8042, Resource: <memory:1024, vCores:1>, Priority: 20, State: NEW, Token: null, Status: container_id {, app_attempt_id {, application_id {, id: 5, cluster_timestamp: 1376050148932, }, attemptId: 1, }, id: 3, }, state: C_NEW, ] containerId=container_1376050148932_0005_01_000003 queue=default: capacity=1.0, absoluteCapacity=1.0, usedResources=<memory:3072, vCores:2>usedCapacity=0.0625, absoluteUsedCapacity=0.0625, numApps=1, numContainers=2 usedCapacity=0.0625 absoluteUsedCapacity=0.0625 used=<memory:3072, vCores:2> cluster=<memory:49152, vCores:96>
2013-08-09 12:21:11,504 INFO org.apache.hadoop.yarn.server.resourcemanager.scheduler.capacity.ParentQueue: Re-sorting queues since queue: root.default stats: default: capacity=1.0, absoluteCapacity=1.0, usedResources=<memory:4096, vCores:3>usedCapacity=0.083333336, absoluteUsedCapacity=0.083333336, numApps=1, numContainers=3
2013-08-09 12:21:11,504 INFO org.apache.hadoop.yarn.server.resourcemanager.scheduler.capacity.ParentQueue: assignedContainer queue=root usedCapacity=0.083333336 absoluteUsedCapacity=0.083333336 used=<memory:4096, vCores:3> cluster=<memory:49152, vCores:96>
2013-08-09 12:21:12,413 INFO org.apache.hadoop.yarn.server.resourcemanager.rmcontainer.RMContainerImpl: container_1376050148932_0005_01_000002 Container Transitioned from ALLOCATED to ACQUIRED
2013-08-09 12:21:12,417 INFO org.apache.hadoop.yarn.server.resourcemanager.rmcontainer.RMContainerImpl: container_1376050148932_0005_01_000003 Container Transitioned from ALLOCATED to ACQUIRED
2013-08-09 12:21:13,445 INFO org.apache.hadoop.yarn.server.resourcemanager.scheduler.AppSchedulingInfo: checking for deactivate... 
2013-08-09 12:21:13,492 INFO org.apache.hadoop.yarn.server.resourcemanager.rmcontainer.RMContainerImpl: container_1376050148932_0005_01_000002 Container Transitioned from ACQUIRED to RUNNING
2013-08-09 12:21:13,513 INFO org.apache.hadoop.yarn.server.resourcemanager.rmcontainer.RMContainerImpl: container_1376050148932_0005_01_000003 Container Transitioned from ACQUIRED to RUNNING
2013-08-09 12:23:00,911 INFO org.apache.hadoop.yarn.server.resourcemanager.rmcontainer.RMContainerImpl: container_1376050148932_0005_01_000003 Container Transitioned from RUNNING to COMPLETED
2013-08-09 12:23:00,911 INFO org.apache.hadoop.yarn.server.resourcemanager.scheduler.common.fica.FiCaSchedulerApp: Completed container: container_1376050148932_0005_01_000003 in state: COMPLETED event:FINISHED
2013-08-09 12:23:00,911 INFO org.apache.hadoop.yarn.server.resourcemanager.RMAuditLogger: USER=ubuntu	OPERATION=AM Released Container	TARGET=SchedulerApp	RESULT=SUCCESS	APPID=application_1376050148932_0005	CONTAINERID=container_1376050148932_0005_01_000003
2013-08-09 12:23:00,912 INFO org.apache.hadoop.yarn.server.resourcemanager.scheduler.common.fica.FiCaSchedulerNode: Released container container_1376050148932_0005_01_000003 of capacity <memory:1024, vCores:1> on host hadoop-210-4:57908, which currently has 0 containers, <memory:0, vCores:0> used and <memory:8192, vCores:16> available, release resources=true
2013-08-09 12:23:00,912 INFO org.apache.hadoop.yarn.server.resourcemanager.scheduler.capacity.LeafQueue: default used=<memory:3072, vCores:2> numContainers=2 user=ubuntu user-resources=<memory:3072, vCores:2>
2013-08-09 12:23:00,913 INFO org.apache.hadoop.yarn.server.resourcemanager.scheduler.capacity.LeafQueue: completedContainer container=Container: [ContainerId: container_1376050148932_0005_01_000003, NodeId: hadoop-210-4:57908, NodeHttpAddress: hadoop-210-4:8042, Resource: <memory:1024, vCores:1>, Priority: 20, State: NEW, Token: null, Status: container_id {, app_attempt_id {, application_id {, id: 5, cluster_timestamp: 1376050148932, }, attemptId: 1, }, id: 3, }, state: C_COMPLETE, diagnostics: "Container killed by the ApplicationMaster.\n\n", exit_status: 143, ] resource=<memory:1024, vCores:1> queue=default: capacity=1.0, absoluteCapacity=1.0, usedResources=<memory:3072, vCores:2>usedCapacity=0.0625, absoluteUsedCapacity=0.0625, numApps=1, numContainers=2 usedCapacity=0.0625 absoluteUsedCapacity=0.0625 used=<memory:3072, vCores:2> cluster=<memory:49152, vCores:96>
2013-08-09 12:23:00,914 INFO org.apache.hadoop.yarn.server.resourcemanager.scheduler.capacity.ParentQueue: completedContainer queue=root usedCapacity=0.0625 absoluteUsedCapacity=0.0625 used=<memory:3072, vCores:2> cluster=<memory:49152, vCores:96>
2013-08-09 12:23:00,914 INFO org.apache.hadoop.yarn.server.resourcemanager.scheduler.capacity.CapacityScheduler: Application appattempt_1376050148932_0005_000001 released container container_1376050148932_0005_01_000003 on node: host: hadoop-210-4:57908 #containers=0 available=8192 used=0 with event: FINISHED
2013-08-09 12:23:12,305 INFO org.apache.hadoop.yarn.server.resourcemanager.rmcontainer.RMContainerImpl: container_1376050148932_0005_01_000002 Container Transitioned from RUNNING to COMPLETED
2013-08-09 12:23:12,305 INFO org.apache.hadoop.yarn.server.resourcemanager.scheduler.common.fica.FiCaSchedulerApp: Completed container: container_1376050148932_0005_01_000002 in state: COMPLETED event:FINISHED
2013-08-09 12:23:12,305 INFO org.apache.hadoop.yarn.server.resourcemanager.RMAuditLogger: USER=ubuntu	OPERATION=AM Released Container	TARGET=SchedulerApp	RESULT=SUCCESS	APPID=application_1376050148932_0005	CONTAINERID=container_1376050148932_0005_01_000002
2013-08-09 12:23:12,305 INFO org.apache.hadoop.yarn.server.resourcemanager.scheduler.common.fica.FiCaSchedulerNode: Released container container_1376050148932_0005_01_000002 of capacity <memory:1024, vCores:1> on host hadoop-210-5:60822, which currently has 0 containers, <memory:0, vCores:0> used and <memory:8192, vCores:16> available, release resources=true
2013-08-09 12:23:12,305 INFO org.apache.hadoop.yarn.server.resourcemanager.scheduler.capacity.LeafQueue: default used=<memory:2048, vCores:1> numContainers=1 user=ubuntu user-resources=<memory:2048, vCores:1>
2013-08-09 12:23:12,307 INFO org.apache.hadoop.yarn.server.resourcemanager.scheduler.capacity.LeafQueue: completedContainer container=Container: [ContainerId: container_1376050148932_0005_01_000002, NodeId: hadoop-210-5:60822, NodeHttpAddress: hadoop-210-5:8042, Resource: <memory:1024, vCores:1>, Priority: 20, State: NEW, Token: null, Status: container_id {, app_attempt_id {, application_id {, id: 5, cluster_timestamp: 1376050148932, }, attemptId: 1, }, id: 2, }, state: C_COMPLETE, diagnostics: "Container killed by the ApplicationMaster.\n\n", exit_status: 143, ] resource=<memory:1024, vCores:1> queue=default: capacity=1.0, absoluteCapacity=1.0, usedResources=<memory:2048, vCores:1>usedCapacity=0.041666668, absoluteUsedCapacity=0.041666668, numApps=1, numContainers=1 usedCapacity=0.041666668 absoluteUsedCapacity=0.041666668 used=<memory:2048, vCores:1> cluster=<memory:49152, vCores:96>
2013-08-09 12:23:12,307 INFO org.apache.hadoop.yarn.server.resourcemanager.scheduler.capacity.ParentQueue: completedContainer queue=root usedCapacity=0.041666668 absoluteUsedCapacity=0.041666668 used=<memory:2048, vCores:1> cluster=<memory:49152, vCores:96>
2013-08-09 12:23:12,307 INFO org.apache.hadoop.yarn.server.resourcemanager.scheduler.capacity.CapacityScheduler: Application appattempt_1376050148932_0005_000001 released container container_1376050148932_0005_01_000002 on node: host: hadoop-210-5:60822 #containers=0 available=8192 used=0 with event: FINISHED
2013-08-09 12:23:16,458 INFO org.apache.hadoop.yarn.server.resourcemanager.rmapp.attempt.RMAppAttemptImpl: appattempt_1376050148932_0005_000001 State change from RUNNING to FINISHING
2013-08-09 12:23:16,459 INFO org.apache.hadoop.yarn.server.resourcemanager.rmapp.RMAppImpl: application_1376050148932_0005 State change from RUNNING to FINISHING
2013-08-09 12:23:16,866 INFO org.apache.hadoop.yarn.server.resourcemanager.rmcontainer.RMContainerImpl: container_1376050148932_0005_01_000001 Container Transitioned from RUNNING to COMPLETED
2013-08-09 12:23:16,866 INFO org.apache.hadoop.yarn.server.resourcemanager.scheduler.common.fica.FiCaSchedulerApp: Completed container: container_1376050148932_0005_01_000001 in state: COMPLETED event:FINISHED
2013-08-09 12:23:16,867 INFO org.apache.hadoop.yarn.server.resourcemanager.RMAuditLogger: USER=ubuntu	OPERATION=AM Released Container	TARGET=SchedulerApp	RESULT=SUCCESS	APPID=application_1376050148932_0005	CONTAINERID=container_1376050148932_0005_01_000001
2013-08-09 12:23:16,867 INFO org.apache.hadoop.yarn.server.resourcemanager.rmapp.attempt.RMAppAttemptImpl: appattempt_1376050148932_0005_000001 State change from FINISHING to FINISHED
2013-08-09 12:23:16,867 INFO org.apache.hadoop.yarn.server.resourcemanager.scheduler.common.fica.FiCaSchedulerNode: Released container container_1376050148932_0005_01_000001 of capacity <memory:2048, vCores:1> on host hadoop-210-6:38267, which currently has 0 containers, <memory:0, vCores:0> used and <memory:8192, vCores:16> available, release resources=true
2013-08-09 12:23:16,867 INFO org.apache.hadoop.yarn.server.resourcemanager.rmapp.RMAppImpl: application_1376050148932_0005 State change from FINISHING to FINISHED
2013-08-09 12:23:16,867 INFO org.apache.hadoop.yarn.server.resourcemanager.scheduler.capacity.LeafQueue: default used=<memory:0, vCores:0> numContainers=0 user=ubuntu user-resources=<memory:0, vCores:0>
2013-08-09 12:23:16,867 INFO org.apache.hadoop.yarn.server.resourcemanager.RMAuditLogger: USER=ubuntu	OPERATION=Application Finished - Succeeded	TARGET=RMAppManager	RESULT=SUCCESS	APPID=application_1376050148932_0005
2013-08-09 12:23:16,868 INFO org.apache.hadoop.yarn.server.resourcemanager.recovery.RMStateStore: Removing info for app: application_1376050148932_0005
2013-08-09 12:23:16,868 INFO org.apache.hadoop.yarn.server.resourcemanager.RMAppManager$ApplicationSummary: appId=application_1376050148932_0005,name=TeraGen,user=ubuntu,queue=default,state=FINISHED,trackingUrl=hadoop-210-1.novalocal:8088/proxy/application_1376050148932_0005/jobhistory/job/job_1376050148932_0005,appMasterHost=hadoop-210-6,startTime=1376050862883,finishTime=1376050996459
2013-08-09 12:23:16,869 INFO org.apache.hadoop.yarn.server.resourcemanager.amlauncher.AMLauncher: Cleaning master appattempt_1376050148932_0005_000001
2013-08-09 12:23:16,869 INFO org.apache.hadoop.yarn.server.resourcemanager.scheduler.capacity.LeafQueue: completedContainer container=Container: [ContainerId: container_1376050148932_0005_01_000001, NodeId: hadoop-210-6:38267, NodeHttpAddress: hadoop-210-6:8042, Resource: <memory:2048, vCores:1>, Priority: 0, State: NEW, Token: null, Status: container_id {, app_attempt_id {, application_id {, id: 5, cluster_timestamp: 1376050148932, }, attemptId: 1, }, id: 1, }, state: C_COMPLETE, diagnostics: "", exit_status: 0, ] resource=<memory:2048, vCores:1> queue=default: capacity=1.0, absoluteCapacity=1.0, usedResources=<memory:0, vCores:0>usedCapacity=0.0, absoluteUsedCapacity=0.0, numApps=1, numContainers=0 usedCapacity=0.0 absoluteUsedCapacity=0.0 used=<memory:0, vCores:0> cluster=<memory:49152, vCores:96>
2013-08-09 12:23:16,869 INFO org.apache.hadoop.yarn.server.resourcemanager.scheduler.capacity.ParentQueue: completedContainer queue=root usedCapacity=0.0 absoluteUsedCapacity=0.0 used=<memory:0, vCores:0> cluster=<memory:49152, vCores:96>
2013-08-09 12:23:16,869 INFO org.apache.hadoop.yarn.server.resourcemanager.scheduler.capacity.CapacityScheduler: Application appattempt_1376050148932_0005_000001 released container container_1376050148932_0005_01_000001 on node: host: hadoop-210-6:38267 #containers=0 available=8192 used=0 with event: FINISHED
2013-08-09 12:23:16,869 INFO org.apache.hadoop.yarn.server.resourcemanager.scheduler.capacity.CapacityScheduler: Application appattempt_1376050148932_0005_000001 is done. finalState=FINISHED
2013-08-09 12:23:16,869 INFO org.apache.hadoop.yarn.server.resourcemanager.scheduler.AppSchedulingInfo: Application application_1376050148932_0005 requests cleared
2013-08-09 12:23:16,870 INFO org.apache.hadoop.yarn.server.resourcemanager.scheduler.capacity.LeafQueue: Application removed - appId: application_1376050148932_0005 user: ubuntu queue: default #user-pending-applications: 0 #user-active-applications: 0 #queue-pending-applications: 0 #queue-active-applications: 0
2013-08-09 12:23:16,870 INFO org.apache.hadoop.yarn.server.resourcemanager.scheduler.capacity.ParentQueue: Application removed - appId: application_1376050148932_0005 user: ubuntu leaf-queue of parent: root #applications: 0
2013-08-09 12:24:31,553 INFO org.apache.hadoop.yarn.server.resourcemanager.ClientRMService: Allocated new applicationId: 6
2013-08-09 12:24:31,784 INFO org.apache.hadoop.yarn.server.resourcemanager.ClientRMService: Allocated new applicationId: 7
2013-08-09 12:24:32,370 INFO org.apache.hadoop.yarn.server.resourcemanager.ClientRMService: Allocated new applicationId: 8
2013-08-09 12:24:32,396 INFO org.apache.hadoop.yarn.server.resourcemanager.ClientRMService: Allocated new applicationId: 9
2013-08-09 12:24:32,649 INFO org.apache.hadoop.yarn.server.resourcemanager.ClientRMService: Allocated new applicationId: 10
2013-08-09 12:24:33,105 INFO org.apache.hadoop.yarn.server.resourcemanager.ClientRMService: Storing Application with id application_1376050148932_0006
2013-08-09 12:24:33,105 INFO org.apache.hadoop.yarn.server.resourcemanager.recovery.RMStateStore: Storing info for app: application_1376050148932_0006
2013-08-09 12:24:33,105 INFO org.apache.hadoop.yarn.server.resourcemanager.ClientRMService: Application with id 6 submitted by user ubuntu
2013-08-09 12:24:33,105 INFO org.apache.hadoop.yarn.server.resourcemanager.RMAuditLogger: USER=ubuntu	IP=192.168.100.4	OPERATION=Submit Application Request	TARGET=ClientRMService	RESULT=SUCCESS	APPID=application_1376050148932_0006
2013-08-09 12:24:33,115 INFO org.apache.hadoop.yarn.server.resourcemanager.rmapp.RMAppImpl: application_1376050148932_0006 State change from NEW to SUBMITTED
2013-08-09 12:24:33,116 INFO org.apache.hadoop.yarn.server.resourcemanager.ApplicationMasterService: Registering appattempt_1376050148932_0006_000001
2013-08-09 12:24:33,116 INFO org.apache.hadoop.yarn.server.resourcemanager.rmapp.attempt.RMAppAttemptImpl: appattempt_1376050148932_0006_000001 State change from NEW to SUBMITTED
2013-08-09 12:24:33,124 INFO org.apache.hadoop.yarn.server.resourcemanager.scheduler.capacity.LeafQueue: Application application_1376050148932_0006 from user: ubuntu activated in queue: default
2013-08-09 12:24:33,125 INFO org.apache.hadoop.yarn.server.resourcemanager.scheduler.capacity.LeafQueue: Application added - appId: application_1376050148932_0006 user: org.apache.hadoop.yarn.server.resourcemanager.scheduler.capacity.LeafQueue$User@4c16cfa, leaf-queue: default #user-pending-applications: 0 #user-active-applications: 1 #queue-pending-applications: 0 #queue-active-applications: 1
2013-08-09 12:24:33,125 INFO org.apache.hadoop.yarn.server.resourcemanager.scheduler.capacity.ParentQueue: Application added - appId: application_1376050148932_0006 user: ubuntu leaf-queue of parent: root #applications: 1
2013-08-09 12:24:33,125 INFO org.apache.hadoop.yarn.server.resourcemanager.scheduler.capacity.CapacityScheduler: Application Submission: appattempt_1376050148932_0006_000001, user: ubuntu queue: default: capacity=1.0, absoluteCapacity=1.0, usedResources=<memory:0, vCores:0>usedCapacity=0.0, absoluteUsedCapacity=0.0, numApps=1, numContainers=0, currently active: 1
2013-08-09 12:24:33,125 INFO org.apache.hadoop.yarn.server.resourcemanager.rmapp.attempt.RMAppAttemptImpl: appattempt_1376050148932_0006_000001 State change from SUBMITTED to SCHEDULED
2013-08-09 12:24:33,125 INFO org.apache.hadoop.yarn.server.resourcemanager.rmapp.RMAppImpl: application_1376050148932_0006 State change from SUBMITTED to ACCEPTED
2013-08-09 12:24:33,210 INFO org.apache.hadoop.yarn.server.resourcemanager.rmcontainer.RMContainerImpl: container_1376050148932_0006_01_000001 Container Transitioned from NEW to ALLOCATED
2013-08-09 12:24:33,210 INFO org.apache.hadoop.yarn.server.resourcemanager.RMAuditLogger: USER=ubuntu	OPERATION=AM Allocated Container	TARGET=SchedulerApp	RESULT=SUCCESS	APPID=application_1376050148932_0006	CONTAINERID=container_1376050148932_0006_01_000001
2013-08-09 12:24:33,210 INFO org.apache.hadoop.yarn.server.resourcemanager.scheduler.common.fica.FiCaSchedulerNode: Assigned container container_1376050148932_0006_01_000001 of capacity <memory:2048, vCores:1> on host hadoop-210-4:57908, which currently has 1 containers, <memory:2048, vCores:1> used and <memory:6144, vCores:15> available
2013-08-09 12:24:33,211 INFO org.apache.hadoop.yarn.server.resourcemanager.scheduler.capacity.LeafQueue: assignedContainer application=application_1376050148932_0006 container=Container: [ContainerId: container_1376050148932_0006_01_000001, NodeId: hadoop-210-4:57908, NodeHttpAddress: hadoop-210-4:8042, Resource: <memory:2048, vCores:1>, Priority: 0, State: NEW, Token: null, Status: container_id {, app_attempt_id {, application_id {, id: 6, cluster_timestamp: 1376050148932, }, attemptId: 1, }, id: 1, }, state: C_NEW, ] containerId=container_1376050148932_0006_01_000001 queue=default: capacity=1.0, absoluteCapacity=1.0, usedResources=<memory:0, vCores:0>usedCapacity=0.0, absoluteUsedCapacity=0.0, numApps=1, numContainers=0 usedCapacity=0.0 absoluteUsedCapacity=0.0 used=<memory:0, vCores:0> cluster=<memory:49152, vCores:96>
2013-08-09 12:24:33,211 INFO org.apache.hadoop.yarn.server.resourcemanager.scheduler.capacity.ParentQueue: Re-sorting queues since queue: root.default stats: default: capacity=1.0, absoluteCapacity=1.0, usedResources=<memory:2048, vCores:1>usedCapacity=0.041666668, absoluteUsedCapacity=0.041666668, numApps=1, numContainers=1
2013-08-09 12:24:33,211 INFO org.apache.hadoop.yarn.server.resourcemanager.scheduler.capacity.ParentQueue: assignedContainer queue=root usedCapacity=0.041666668 absoluteUsedCapacity=0.041666668 used=<memory:2048, vCores:1> cluster=<memory:49152, vCores:96>
2013-08-09 12:24:33,212 INFO org.apache.hadoop.yarn.server.resourcemanager.rmcontainer.RMContainerImpl: container_1376050148932_0006_01_000001 Container Transitioned from ALLOCATED to ACQUIRED
2013-08-09 12:24:33,212 INFO org.apache.hadoop.yarn.server.resourcemanager.rmapp.attempt.RMAppAttemptImpl: Storing attempt: AppId: application_1376050148932_0006 AttemptId: appattempt_1376050148932_0006_000001 MasterContainer: Container: [ContainerId: container_1376050148932_0006_01_000001, NodeId: hadoop-210-4:57908, NodeHttpAddress: hadoop-210-4:8042, Resource: <memory:2048, vCores:1>, Priority: 0, State: NEW, Token: null, Status: container_id {, app_attempt_id {, application_id {, id: 6, cluster_timestamp: 1376050148932, }, attemptId: 1, }, id: 1, }, state: C_NEW, ]
2013-08-09 12:24:33,213 INFO org.apache.hadoop.yarn.server.resourcemanager.recovery.RMStateStore: Storing info for attempt: appattempt_1376050148932_0006_000001
2013-08-09 12:24:33,213 INFO org.apache.hadoop.yarn.server.resourcemanager.rmapp.attempt.RMAppAttemptImpl: appattempt_1376050148932_0006_000001 State change from SCHEDULED to ALLOCATED_SAVING
2013-08-09 12:24:33,213 INFO org.apache.hadoop.yarn.server.resourcemanager.rmapp.attempt.RMAppAttemptImpl: appattempt_1376050148932_0006_000001 State change from ALLOCATED_SAVING to ALLOCATED
2013-08-09 12:24:33,215 INFO org.apache.hadoop.yarn.server.resourcemanager.amlauncher.AMLauncher: Launching masterappattempt_1376050148932_0006_000001
2013-08-09 12:24:33,216 INFO org.apache.hadoop.yarn.server.resourcemanager.amlauncher.AMLauncher: Setting up container Container: [ContainerId: container_1376050148932_0006_01_000001, NodeId: hadoop-210-4:57908, NodeHttpAddress: hadoop-210-4:8042, Resource: <memory:2048, vCores:1>, Priority: 0, State: NEW, Token: null, Status: container_id {, app_attempt_id {, application_id {, id: 6, cluster_timestamp: 1376050148932, }, attemptId: 1, }, id: 1, }, state: C_NEW, ] for AM appattempt_1376050148932_0006_000001
2013-08-09 12:24:33,216 INFO org.apache.hadoop.yarn.server.resourcemanager.amlauncher.AMLauncher: Command to launch container container_1376050148932_0006_01_000001 : $JAVA_HOME/bin/java -Dlog4j.configuration=container-log4j.properties -Dyarn.app.mapreduce.container.log.dir=<LOG_DIR> -Dyarn.app.mapreduce.container.log.filesize=0 -Dhadoop.root.logger=INFO,CLA  -Xmx1024m org.apache.hadoop.mapreduce.v2.app.MRAppMaster 1><LOG_DIR>/stdout 2><LOG_DIR>/stderr 
2013-08-09 12:24:33,246 INFO org.apache.hadoop.yarn.server.resourcemanager.amlauncher.AMLauncher: Done launching container Container: [ContainerId: container_1376050148932_0006_01_000001, NodeId: hadoop-210-4:57908, NodeHttpAddress: hadoop-210-4:8042, Resource: <memory:2048, vCores:1>, Priority: 0, State: NEW, Token: null, Status: container_id {, app_attempt_id {, application_id {, id: 6, cluster_timestamp: 1376050148932, }, attemptId: 1, }, id: 1, }, state: C_NEW, ] for AM appattempt_1376050148932_0006_000001
2013-08-09 12:24:33,246 INFO org.apache.hadoop.yarn.server.resourcemanager.rmapp.attempt.RMAppAttemptImpl: appattempt_1376050148932_0006_000001 State change from ALLOCATED to LAUNCHED
2013-08-09 12:24:33,288 INFO org.apache.hadoop.yarn.server.resourcemanager.ClientRMService: Storing Application with id application_1376050148932_0007
2013-08-09 12:24:33,288 INFO org.apache.hadoop.yarn.server.resourcemanager.recovery.RMStateStore: Storing info for app: application_1376050148932_0007
2013-08-09 12:24:33,288 INFO org.apache.hadoop.yarn.server.resourcemanager.ClientRMService: Application with id 7 submitted by user ubuntu
2013-08-09 12:24:33,288 INFO org.apache.hadoop.yarn.server.resourcemanager.RMAuditLogger: USER=ubuntu	IP=192.168.100.4	OPERATION=Submit Application Request	TARGET=ClientRMService	RESULT=SUCCESS	APPID=application_1376050148932_0007
2013-08-09 12:24:33,288 INFO org.apache.hadoop.yarn.server.resourcemanager.rmapp.RMAppImpl: application_1376050148932_0007 State change from NEW to SUBMITTED
2013-08-09 12:24:33,289 INFO org.apache.hadoop.yarn.server.resourcemanager.ApplicationMasterService: Registering appattempt_1376050148932_0007_000001
2013-08-09 12:24:33,289 INFO org.apache.hadoop.yarn.server.resourcemanager.rmapp.attempt.RMAppAttemptImpl: appattempt_1376050148932_0007_000001 State change from NEW to SUBMITTED
2013-08-09 12:24:33,289 INFO org.apache.hadoop.yarn.server.resourcemanager.scheduler.capacity.LeafQueue: Application application_1376050148932_0007 from user: ubuntu activated in queue: default
2013-08-09 12:24:33,289 INFO org.apache.hadoop.yarn.server.resourcemanager.scheduler.capacity.LeafQueue: Application added - appId: application_1376050148932_0007 user: org.apache.hadoop.yarn.server.resourcemanager.scheduler.capacity.LeafQueue$User@4c16cfa, leaf-queue: default #user-pending-applications: 0 #user-active-applications: 2 #queue-pending-applications: 0 #queue-active-applications: 2
2013-08-09 12:24:33,289 INFO org.apache.hadoop.yarn.server.resourcemanager.scheduler.capacity.ParentQueue: Application added - appId: application_1376050148932_0007 user: ubuntu leaf-queue of parent: root #applications: 2
2013-08-09 12:24:33,289 INFO org.apache.hadoop.yarn.server.resourcemanager.scheduler.capacity.CapacityScheduler: Application Submission: appattempt_1376050148932_0007_000001, user: ubuntu queue: default: capacity=1.0, absoluteCapacity=1.0, usedResources=<memory:2048, vCores:1>usedCapacity=0.041666668, absoluteUsedCapacity=0.041666668, numApps=2, numContainers=1, currently active: 2
2013-08-09 12:24:33,290 INFO org.apache.hadoop.yarn.server.resourcemanager.rmapp.attempt.RMAppAttemptImpl: appattempt_1376050148932_0007_000001 State change from SUBMITTED to SCHEDULED
2013-08-09 12:24:33,290 INFO org.apache.hadoop.yarn.server.resourcemanager.rmapp.RMAppImpl: application_1376050148932_0007 State change from SUBMITTED to ACCEPTED
2013-08-09 12:24:33,586 INFO org.apache.hadoop.yarn.server.resourcemanager.rmcontainer.RMContainerImpl: container_1376050148932_0007_01_000001 Container Transitioned from NEW to ALLOCATED
2013-08-09 12:24:33,586 INFO org.apache.hadoop.yarn.server.resourcemanager.RMAuditLogger: USER=ubuntu	OPERATION=AM Allocated Container	TARGET=SchedulerApp	RESULT=SUCCESS	APPID=application_1376050148932_0007	CONTAINERID=container_1376050148932_0007_01_000001
2013-08-09 12:24:33,586 INFO org.apache.hadoop.yarn.server.resourcemanager.scheduler.common.fica.FiCaSchedulerNode: Assigned container container_1376050148932_0007_01_000001 of capacity <memory:2048, vCores:1> on host hadoop-210-5:60822, which currently has 1 containers, <memory:2048, vCores:1> used and <memory:6144, vCores:15> available
2013-08-09 12:24:33,587 INFO org.apache.hadoop.yarn.server.resourcemanager.scheduler.capacity.LeafQueue: assignedContainer application=application_1376050148932_0007 container=Container: [ContainerId: container_1376050148932_0007_01_000001, NodeId: hadoop-210-5:60822, NodeHttpAddress: hadoop-210-5:8042, Resource: <memory:2048, vCores:1>, Priority: 0, State: NEW, Token: null, Status: container_id {, app_attempt_id {, application_id {, id: 7, cluster_timestamp: 1376050148932, }, attemptId: 1, }, id: 1, }, state: C_NEW, ] containerId=container_1376050148932_0007_01_000001 queue=default: capacity=1.0, absoluteCapacity=1.0, usedResources=<memory:2048, vCores:1>usedCapacity=0.041666668, absoluteUsedCapacity=0.041666668, numApps=2, numContainers=1 usedCapacity=0.041666668 absoluteUsedCapacity=0.041666668 used=<memory:2048, vCores:1> cluster=<memory:49152, vCores:96>
2013-08-09 12:24:33,587 INFO org.apache.hadoop.yarn.server.resourcemanager.scheduler.capacity.ParentQueue: Re-sorting queues since queue: root.default stats: default: capacity=1.0, absoluteCapacity=1.0, usedResources=<memory:4096, vCores:2>usedCapacity=0.083333336, absoluteUsedCapacity=0.083333336, numApps=2, numContainers=2
2013-08-09 12:24:33,587 INFO org.apache.hadoop.yarn.server.resourcemanager.scheduler.capacity.ParentQueue: assignedContainer queue=root usedCapacity=0.083333336 absoluteUsedCapacity=0.083333336 used=<memory:4096, vCores:2> cluster=<memory:49152, vCores:96>
2013-08-09 12:24:33,588 INFO org.apache.hadoop.yarn.server.resourcemanager.rmcontainer.RMContainerImpl: container_1376050148932_0007_01_000001 Container Transitioned from ALLOCATED to ACQUIRED
2013-08-09 12:24:33,589 INFO org.apache.hadoop.yarn.server.resourcemanager.rmapp.attempt.RMAppAttemptImpl: Storing attempt: AppId: application_1376050148932_0007 AttemptId: appattempt_1376050148932_0007_000001 MasterContainer: Container: [ContainerId: container_1376050148932_0007_01_000001, NodeId: hadoop-210-5:60822, NodeHttpAddress: hadoop-210-5:8042, Resource: <memory:2048, vCores:1>, Priority: 0, State: NEW, Token: null, Status: container_id {, app_attempt_id {, application_id {, id: 7, cluster_timestamp: 1376050148932, }, attemptId: 1, }, id: 1, }, state: C_NEW, ]
2013-08-09 12:24:33,589 INFO org.apache.hadoop.yarn.server.resourcemanager.recovery.RMStateStore: Storing info for attempt: appattempt_1376050148932_0007_000001
2013-08-09 12:24:33,589 INFO org.apache.hadoop.yarn.server.resourcemanager.rmapp.attempt.RMAppAttemptImpl: appattempt_1376050148932_0007_000001 State change from SCHEDULED to ALLOCATED_SAVING
2013-08-09 12:24:33,590 INFO org.apache.hadoop.yarn.server.resourcemanager.rmapp.attempt.RMAppAttemptImpl: appattempt_1376050148932_0007_000001 State change from ALLOCATED_SAVING to ALLOCATED
2013-08-09 12:24:33,590 INFO org.apache.hadoop.yarn.server.resourcemanager.amlauncher.AMLauncher: Launching masterappattempt_1376050148932_0007_000001
2013-08-09 12:24:33,591 INFO org.apache.hadoop.yarn.server.resourcemanager.amlauncher.AMLauncher: Setting up container Container: [ContainerId: container_1376050148932_0007_01_000001, NodeId: hadoop-210-5:60822, NodeHttpAddress: hadoop-210-5:8042, Resource: <memory:2048, vCores:1>, Priority: 0, State: NEW, Token: null, Status: container_id {, app_attempt_id {, application_id {, id: 7, cluster_timestamp: 1376050148932, }, attemptId: 1, }, id: 1, }, state: C_NEW, ] for AM appattempt_1376050148932_0007_000001
2013-08-09 12:24:33,592 INFO org.apache.hadoop.yarn.server.resourcemanager.amlauncher.AMLauncher: Command to launch container container_1376050148932_0007_01_000001 : $JAVA_HOME/bin/java -Dlog4j.configuration=container-log4j.properties -Dyarn.app.mapreduce.container.log.dir=<LOG_DIR> -Dyarn.app.mapreduce.container.log.filesize=0 -Dhadoop.root.logger=INFO,CLA  -Xmx1024m org.apache.hadoop.mapreduce.v2.app.MRAppMaster 1><LOG_DIR>/stdout 2><LOG_DIR>/stderr 
2013-08-09 12:24:33,601 INFO org.apache.hadoop.yarn.server.resourcemanager.amlauncher.AMLauncher: Done launching container Container: [ContainerId: container_1376050148932_0007_01_000001, NodeId: hadoop-210-5:60822, NodeHttpAddress: hadoop-210-5:8042, Resource: <memory:2048, vCores:1>, Priority: 0, State: NEW, Token: null, Status: container_id {, app_attempt_id {, application_id {, id: 7, cluster_timestamp: 1376050148932, }, attemptId: 1, }, id: 1, }, state: C_NEW, ] for AM appattempt_1376050148932_0007_000001
2013-08-09 12:24:33,601 INFO org.apache.hadoop.yarn.server.resourcemanager.rmapp.attempt.RMAppAttemptImpl: appattempt_1376050148932_0007_000001 State change from ALLOCATED to LAUNCHED
2013-08-09 12:24:33,686 INFO org.apache.hadoop.yarn.server.resourcemanager.ClientRMService: Storing Application with id application_1376050148932_0008
2013-08-09 12:24:33,687 INFO org.apache.hadoop.yarn.server.resourcemanager.recovery.RMStateStore: Storing info for app: application_1376050148932_0008
2013-08-09 12:24:33,687 INFO org.apache.hadoop.yarn.server.resourcemanager.ClientRMService: Application with id 8 submitted by user ubuntu
2013-08-09 12:24:33,687 INFO org.apache.hadoop.yarn.server.resourcemanager.RMAuditLogger: USER=ubuntu	IP=192.168.100.4	OPERATION=Submit Application Request	TARGET=ClientRMService	RESULT=SUCCESS	APPID=application_1376050148932_0008
2013-08-09 12:24:33,689 INFO org.apache.hadoop.yarn.server.resourcemanager.rmapp.RMAppImpl: application_1376050148932_0008 State change from NEW to SUBMITTED
2013-08-09 12:24:33,689 INFO org.apache.hadoop.yarn.server.resourcemanager.ApplicationMasterService: Registering appattempt_1376050148932_0008_000001
2013-08-09 12:24:33,689 INFO org.apache.hadoop.yarn.server.resourcemanager.rmapp.attempt.RMAppAttemptImpl: appattempt_1376050148932_0008_000001 State change from NEW to SUBMITTED
2013-08-09 12:24:33,690 INFO org.apache.hadoop.yarn.server.resourcemanager.scheduler.capacity.LeafQueue: Application application_1376050148932_0008 from user: ubuntu activated in queue: default
2013-08-09 12:24:33,690 INFO org.apache.hadoop.yarn.server.resourcemanager.scheduler.capacity.LeafQueue: Application added - appId: application_1376050148932_0008 user: org.apache.hadoop.yarn.server.resourcemanager.scheduler.capacity.LeafQueue$User@4c16cfa, leaf-queue: default #user-pending-applications: 0 #user-active-applications: 3 #queue-pending-applications: 0 #queue-active-applications: 3
2013-08-09 12:24:33,690 INFO org.apache.hadoop.yarn.server.resourcemanager.scheduler.capacity.ParentQueue: Application added - appId: application_1376050148932_0008 user: ubuntu leaf-queue of parent: root #applications: 3
2013-08-09 12:24:33,690 INFO org.apache.hadoop.yarn.server.resourcemanager.scheduler.capacity.CapacityScheduler: Application Submission: appattempt_1376050148932_0008_000001, user: ubuntu queue: default: capacity=1.0, absoluteCapacity=1.0, usedResources=<memory:4096, vCores:2>usedCapacity=0.083333336, absoluteUsedCapacity=0.083333336, numApps=3, numContainers=2, currently active: 3
2013-08-09 12:24:33,690 INFO org.apache.hadoop.yarn.server.resourcemanager.rmapp.attempt.RMAppAttemptImpl: appattempt_1376050148932_0008_000001 State change from SUBMITTED to SCHEDULED
2013-08-09 12:24:33,690 INFO org.apache.hadoop.yarn.server.resourcemanager.rmapp.RMAppImpl: application_1376050148932_0008 State change from SUBMITTED to ACCEPTED
2013-08-09 12:24:33,734 INFO org.apache.hadoop.yarn.server.resourcemanager.ClientRMService: Storing Application with id application_1376050148932_0009
2013-08-09 12:24:33,735 INFO org.apache.hadoop.yarn.server.resourcemanager.recovery.RMStateStore: Storing info for app: application_1376050148932_0009
2013-08-09 12:24:33,735 INFO org.apache.hadoop.yarn.server.resourcemanager.ClientRMService: Application with id 9 submitted by user ubuntu
2013-08-09 12:24:33,735 INFO org.apache.hadoop.yarn.server.resourcemanager.RMAuditLogger: USER=ubuntu	IP=192.168.100.4	OPERATION=Submit Application Request	TARGET=ClientRMService	RESULT=SUCCESS	APPID=application_1376050148932_0009
2013-08-09 12:24:33,735 INFO org.apache.hadoop.yarn.server.resourcemanager.rmapp.RMAppImpl: application_1376050148932_0009 State change from NEW to SUBMITTED
2013-08-09 12:24:33,735 INFO org.apache.hadoop.yarn.server.resourcemanager.ApplicationMasterService: Registering appattempt_1376050148932_0009_000001
2013-08-09 12:24:33,736 INFO org.apache.hadoop.yarn.server.resourcemanager.rmapp.attempt.RMAppAttemptImpl: appattempt_1376050148932_0009_000001 State change from NEW to SUBMITTED
2013-08-09 12:24:33,736 INFO org.apache.hadoop.yarn.server.resourcemanager.scheduler.capacity.LeafQueue: Application application_1376050148932_0009 from user: ubuntu activated in queue: default
2013-08-09 12:24:33,736 INFO org.apache.hadoop.yarn.server.resourcemanager.scheduler.capacity.LeafQueue: Application added - appId: application_1376050148932_0009 user: org.apache.hadoop.yarn.server.resourcemanager.scheduler.capacity.LeafQueue$User@4c16cfa, leaf-queue: default #user-pending-applications: 0 #user-active-applications: 4 #queue-pending-applications: 0 #queue-active-applications: 4
2013-08-09 12:24:33,736 INFO org.apache.hadoop.yarn.server.resourcemanager.scheduler.capacity.ParentQueue: Application added - appId: application_1376050148932_0009 user: ubuntu leaf-queue of parent: root #applications: 4
2013-08-09 12:24:33,736 INFO org.apache.hadoop.yarn.server.resourcemanager.scheduler.capacity.CapacityScheduler: Application Submission: appattempt_1376050148932_0009_000001, user: ubuntu queue: default: capacity=1.0, absoluteCapacity=1.0, usedResources=<memory:4096, vCores:2>usedCapacity=0.083333336, absoluteUsedCapacity=0.083333336, numApps=4, numContainers=2, currently active: 4
2013-08-09 12:24:33,736 INFO org.apache.hadoop.yarn.server.resourcemanager.rmapp.attempt.RMAppAttemptImpl: appattempt_1376050148932_0009_000001 State change from SUBMITTED to SCHEDULED
2013-08-09 12:24:33,736 INFO org.apache.hadoop.yarn.server.resourcemanager.rmapp.RMAppImpl: application_1376050148932_0009 State change from SUBMITTED to ACCEPTED
2013-08-09 12:24:33,855 INFO org.apache.hadoop.yarn.server.resourcemanager.ClientRMService: Storing Application with id application_1376050148932_0010
2013-08-09 12:24:33,855 INFO org.apache.hadoop.yarn.server.resourcemanager.recovery.RMStateStore: Storing info for app: application_1376050148932_0010
2013-08-09 12:24:33,855 INFO org.apache.hadoop.yarn.server.resourcemanager.ClientRMService: Application with id 10 submitted by user ubuntu
2013-08-09 12:24:33,855 INFO org.apache.hadoop.yarn.server.resourcemanager.RMAuditLogger: USER=ubuntu	IP=192.168.100.4	OPERATION=Submit Application Request	TARGET=ClientRMService	RESULT=SUCCESS	APPID=application_1376050148932_0010
2013-08-09 12:24:33,856 INFO org.apache.hadoop.yarn.server.resourcemanager.rmapp.RMAppImpl: application_1376050148932_0010 State change from NEW to SUBMITTED
2013-08-09 12:24:33,856 INFO org.apache.hadoop.yarn.server.resourcemanager.ApplicationMasterService: Registering appattempt_1376050148932_0010_000001
2013-08-09 12:24:33,856 INFO org.apache.hadoop.yarn.server.resourcemanager.rmapp.attempt.RMAppAttemptImpl: appattempt_1376050148932_0010_000001 State change from NEW to SUBMITTED
2013-08-09 12:24:33,857 INFO org.apache.hadoop.yarn.server.resourcemanager.scheduler.capacity.LeafQueue: Application application_1376050148932_0010 from user: ubuntu activated in queue: default
2013-08-09 12:24:33,857 INFO org.apache.hadoop.yarn.server.resourcemanager.scheduler.capacity.LeafQueue: Application added - appId: application_1376050148932_0010 user: org.apache.hadoop.yarn.server.resourcemanager.scheduler.capacity.LeafQueue$User@4c16cfa, leaf-queue: default #user-pending-applications: 0 #user-active-applications: 5 #queue-pending-applications: 0 #queue-active-applications: 5
2013-08-09 12:24:33,857 INFO org.apache.hadoop.yarn.server.resourcemanager.scheduler.capacity.ParentQueue: Application added - appId: application_1376050148932_0010 user: ubuntu leaf-queue of parent: root #applications: 5
2013-08-09 12:24:33,857 INFO org.apache.hadoop.yarn.server.resourcemanager.scheduler.capacity.CapacityScheduler: Application Submission: appattempt_1376050148932_0010_000001, user: ubuntu queue: default: capacity=1.0, absoluteCapacity=1.0, usedResources=<memory:4096, vCores:2>usedCapacity=0.083333336, absoluteUsedCapacity=0.083333336, numApps=5, numContainers=2, currently active: 5
2013-08-09 12:24:33,857 INFO org.apache.hadoop.yarn.server.resourcemanager.rmapp.attempt.RMAppAttemptImpl: appattempt_1376050148932_0010_000001 State change from SUBMITTED to SCHEDULED
2013-08-09 12:24:33,857 INFO org.apache.hadoop.yarn.server.resourcemanager.rmapp.RMAppImpl: application_1376050148932_0010 State change from SUBMITTED to ACCEPTED
2013-08-09 12:24:33,947 INFO org.apache.hadoop.yarn.server.resourcemanager.rmcontainer.RMContainerImpl: container_1376050148932_0008_01_000001 Container Transitioned from NEW to ALLOCATED
2013-08-09 12:24:33,947 INFO org.apache.hadoop.yarn.server.resourcemanager.RMAuditLogger: USER=ubuntu	OPERATION=AM Allocated Container	TARGET=SchedulerApp	RESULT=SUCCESS	APPID=application_1376050148932_0008	CONTAINERID=container_1376050148932_0008_01_000001
2013-08-09 12:24:33,947 INFO org.apache.hadoop.yarn.server.resourcemanager.scheduler.common.fica.FiCaSchedulerNode: Assigned container container_1376050148932_0008_01_000001 of capacity <memory:2048, vCores:1> on host hadoop-210-3:36255, which currently has 1 containers, <memory:2048, vCores:1> used and <memory:6144, vCores:15> available
2013-08-09 12:24:33,948 INFO org.apache.hadoop.yarn.server.resourcemanager.scheduler.capacity.LeafQueue: assignedContainer application=application_1376050148932_0008 container=Container: [ContainerId: container_1376050148932_0008_01_000001, NodeId: hadoop-210-3:36255, NodeHttpAddress: hadoop-210-3:8042, Resource: <memory:2048, vCores:1>, Priority: 0, State: NEW, Token: null, Status: container_id {, app_attempt_id {, application_id {, id: 8, cluster_timestamp: 1376050148932, }, attemptId: 1, }, id: 1, }, state: C_NEW, ] containerId=container_1376050148932_0008_01_000001 queue=default: capacity=1.0, absoluteCapacity=1.0, usedResources=<memory:4096, vCores:2>usedCapacity=0.083333336, absoluteUsedCapacity=0.083333336, numApps=5, numContainers=2 usedCapacity=0.083333336 absoluteUsedCapacity=0.083333336 used=<memory:4096, vCores:2> cluster=<memory:49152, vCores:96>
2013-08-09 12:24:33,948 INFO org.apache.hadoop.yarn.server.resourcemanager.scheduler.capacity.ParentQueue: Re-sorting queues since queue: root.default stats: default: capacity=1.0, absoluteCapacity=1.0, usedResources=<memory:6144, vCores:3>usedCapacity=0.125, absoluteUsedCapacity=0.125, numApps=5, numContainers=3
2013-08-09 12:24:33,948 INFO org.apache.hadoop.yarn.server.resourcemanager.scheduler.capacity.ParentQueue: assignedContainer queue=root usedCapacity=0.125 absoluteUsedCapacity=0.125 used=<memory:6144, vCores:3> cluster=<memory:49152, vCores:96>
2013-08-09 12:24:33,950 INFO org.apache.hadoop.yarn.server.resourcemanager.rmcontainer.RMContainerImpl: container_1376050148932_0008_01_000001 Container Transitioned from ALLOCATED to ACQUIRED
2013-08-09 12:24:33,951 INFO org.apache.hadoop.yarn.server.resourcemanager.rmcontainer.RMContainerImpl: container_1376050148932_0009_01_000001 Container Transitioned from NEW to ALLOCATED
2013-08-09 12:24:33,951 INFO org.apache.hadoop.yarn.server.resourcemanager.RMAuditLogger: USER=ubuntu	OPERATION=AM Allocated Container	TARGET=SchedulerApp	RESULT=SUCCESS	APPID=application_1376050148932_0009	CONTAINERID=container_1376050148932_0009_01_000001
2013-08-09 12:24:33,951 INFO org.apache.hadoop.yarn.server.resourcemanager.scheduler.common.fica.FiCaSchedulerNode: Assigned container container_1376050148932_0009_01_000001 of capacity <memory:2048, vCores:1> on host hadoop-210-2:40150, which currently has 1 containers, <memory:2048, vCores:1> used and <memory:6144, vCores:15> available
2013-08-09 12:24:33,951 INFO org.apache.hadoop.yarn.server.resourcemanager.rmapp.attempt.RMAppAttemptImpl: Storing attempt: AppId: application_1376050148932_0008 AttemptId: appattempt_1376050148932_0008_000001 MasterContainer: Container: [ContainerId: container_1376050148932_0008_01_000001, NodeId: hadoop-210-3:36255, NodeHttpAddress: hadoop-210-3:8042, Resource: <memory:2048, vCores:1>, Priority: 0, State: NEW, Token: null, Status: container_id {, app_attempt_id {, application_id {, id: 8, cluster_timestamp: 1376050148932, }, attemptId: 1, }, id: 1, }, state: C_NEW, ]
2013-08-09 12:24:33,951 INFO org.apache.hadoop.yarn.server.resourcemanager.rmapp.attempt.RMAppAttemptImpl: appattempt_1376050148932_0008_000001 State change from SCHEDULED to ALLOCATED_SAVING
2013-08-09 12:24:33,951 INFO org.apache.hadoop.yarn.server.resourcemanager.recovery.RMStateStore: Storing info for attempt: appattempt_1376050148932_0008_000001
2013-08-09 12:24:33,952 INFO org.apache.hadoop.yarn.server.resourcemanager.scheduler.capacity.LeafQueue: assignedContainer application=application_1376050148932_0009 container=Container: [ContainerId: container_1376050148932_0009_01_000001, NodeId: hadoop-210-2:40150, NodeHttpAddress: hadoop-210-2:8042, Resource: <memory:2048, vCores:1>, Priority: 0, State: NEW, Token: null, Status: container_id {, app_attempt_id {, application_id {, id: 9, cluster_timestamp: 1376050148932, }, attemptId: 1, }, id: 1, }, state: C_NEW, ] containerId=container_1376050148932_0009_01_000001 queue=default: capacity=1.0, absoluteCapacity=1.0, usedResources=<memory:6144, vCores:3>usedCapacity=0.125, absoluteUsedCapacity=0.125, numApps=5, numContainers=3 usedCapacity=0.125 absoluteUsedCapacity=0.125 used=<memory:6144, vCores:3> cluster=<memory:49152, vCores:96>
2013-08-09 12:24:33,952 INFO org.apache.hadoop.yarn.server.resourcemanager.scheduler.capacity.ParentQueue: Re-sorting queues since queue: root.default stats: default: capacity=1.0, absoluteCapacity=1.0, usedResources=<memory:8192, vCores:4>usedCapacity=0.16666667, absoluteUsedCapacity=0.16666667, numApps=5, numContainers=4
2013-08-09 12:24:33,953 INFO org.apache.hadoop.yarn.server.resourcemanager.scheduler.capacity.ParentQueue: assignedContainer queue=root usedCapacity=0.16666667 absoluteUsedCapacity=0.16666667 used=<memory:8192, vCores:4> cluster=<memory:49152, vCores:96>
2013-08-09 12:24:33,954 INFO org.apache.hadoop.yarn.server.resourcemanager.rmcontainer.RMContainerImpl: container_1376050148932_0009_01_000001 Container Transitioned from ALLOCATED to ACQUIRED
2013-08-09 12:24:33,954 INFO org.apache.hadoop.yarn.server.resourcemanager.rmapp.attempt.RMAppAttemptImpl: Storing attempt: AppId: application_1376050148932_0009 AttemptId: appattempt_1376050148932_0009_000001 MasterContainer: Container: [ContainerId: container_1376050148932_0009_01_000001, NodeId: hadoop-210-2:40150, NodeHttpAddress: hadoop-210-2:8042, Resource: <memory:2048, vCores:1>, Priority: 0, State: NEW, Token: null, Status: container_id {, app_attempt_id {, application_id {, id: 9, cluster_timestamp: 1376050148932, }, attemptId: 1, }, id: 1, }, state: C_NEW, ]
2013-08-09 12:24:33,954 INFO org.apache.hadoop.yarn.server.resourcemanager.rmapp.attempt.RMAppAttemptImpl: appattempt_1376050148932_0009_000001 State change from SCHEDULED to ALLOCATED_SAVING
2013-08-09 12:24:33,955 INFO org.apache.hadoop.yarn.server.resourcemanager.recovery.RMStateStore: Storing info for attempt: appattempt_1376050148932_0009_000001
2013-08-09 12:24:33,955 INFO org.apache.hadoop.yarn.server.resourcemanager.rmapp.attempt.RMAppAttemptImpl: appattempt_1376050148932_0008_000001 State change from ALLOCATED_SAVING to ALLOCATED
2013-08-09 12:24:33,955 INFO org.apache.hadoop.yarn.server.resourcemanager.rmapp.attempt.RMAppAttemptImpl: appattempt_1376050148932_0009_000001 State change from ALLOCATED_SAVING to ALLOCATED
2013-08-09 12:24:33,955 INFO org.apache.hadoop.yarn.server.resourcemanager.amlauncher.AMLauncher: Launching masterappattempt_1376050148932_0008_000001
2013-08-09 12:24:33,956 INFO org.apache.hadoop.yarn.server.resourcemanager.rmcontainer.RMContainerImpl: container_1376050148932_0010_01_000001 Container Transitioned from NEW to ALLOCATED
2013-08-09 12:24:33,956 INFO org.apache.hadoop.yarn.server.resourcemanager.RMAuditLogger: USER=ubuntu	OPERATION=AM Allocated Container	TARGET=SchedulerApp	RESULT=SUCCESS	APPID=application_1376050148932_0010	CONTAINERID=container_1376050148932_0010_01_000001
2013-08-09 12:24:33,956 INFO org.apache.hadoop.yarn.server.resourcemanager.scheduler.common.fica.FiCaSchedulerNode: Assigned container container_1376050148932_0010_01_000001 of capacity <memory:2048, vCores:1> on host hadoop-210-7:41457, which currently has 1 containers, <memory:2048, vCores:1> used and <memory:6144, vCores:15> available
2013-08-09 12:24:33,957 INFO org.apache.hadoop.yarn.server.resourcemanager.scheduler.capacity.LeafQueue: assignedContainer application=application_1376050148932_0010 container=Container: [ContainerId: container_1376050148932_0010_01_000001, NodeId: hadoop-210-7:41457, NodeHttpAddress: hadoop-210-7:8042, Resource: <memory:2048, vCores:1>, Priority: 0, State: NEW, Token: null, Status: container_id {, app_attempt_id {, application_id {, id: 10, cluster_timestamp: 1376050148932, }, attemptId: 1, }, id: 1, }, state: C_NEW, ] containerId=container_1376050148932_0010_01_000001 queue=default: capacity=1.0, absoluteCapacity=1.0, usedResources=<memory:8192, vCores:4>usedCapacity=0.16666667, absoluteUsedCapacity=0.16666667, numApps=5, numContainers=4 usedCapacity=0.16666667 absoluteUsedCapacity=0.16666667 used=<memory:8192, vCores:4> cluster=<memory:49152, vCores:96>
2013-08-09 12:24:33,957 INFO org.apache.hadoop.yarn.server.resourcemanager.amlauncher.AMLauncher: Setting up container Container: [ContainerId: container_1376050148932_0008_01_000001, NodeId: hadoop-210-3:36255, NodeHttpAddress: hadoop-210-3:8042, Resource: <memory:2048, vCores:1>, Priority: 0, State: NEW, Token: null, Status: container_id {, app_attempt_id {, application_id {, id: 8, cluster_timestamp: 1376050148932, }, attemptId: 1, }, id: 1, }, state: C_NEW, ] for AM appattempt_1376050148932_0008_000001
2013-08-09 12:24:33,957 INFO org.apache.hadoop.yarn.server.resourcemanager.scheduler.capacity.ParentQueue: Re-sorting queues since queue: root.default stats: default: capacity=1.0, absoluteCapacity=1.0, usedResources=<memory:10240, vCores:5>usedCapacity=0.20833333, absoluteUsedCapacity=0.20833333, numApps=5, numContainers=5
2013-08-09 12:24:33,957 INFO org.apache.hadoop.yarn.server.resourcemanager.amlauncher.AMLauncher: Command to launch container container_1376050148932_0008_01_000001 : $JAVA_HOME/bin/java -Dlog4j.configuration=container-log4j.properties -Dyarn.app.mapreduce.container.log.dir=<LOG_DIR> -Dyarn.app.mapreduce.container.log.filesize=0 -Dhadoop.root.logger=INFO,CLA  -Xmx1024m org.apache.hadoop.mapreduce.v2.app.MRAppMaster 1><LOG_DIR>/stdout 2><LOG_DIR>/stderr 
2013-08-09 12:24:33,957 INFO org.apache.hadoop.yarn.server.resourcemanager.amlauncher.AMLauncher: Launching masterappattempt_1376050148932_0009_000001
2013-08-09 12:24:33,957 INFO org.apache.hadoop.yarn.server.resourcemanager.scheduler.capacity.ParentQueue: assignedContainer queue=root usedCapacity=0.20833333 absoluteUsedCapacity=0.20833333 used=<memory:10240, vCores:5> cluster=<memory:49152, vCores:96>
2013-08-09 12:24:33,958 INFO org.apache.hadoop.yarn.server.resourcemanager.rmcontainer.RMContainerImpl: container_1376050148932_0010_01_000001 Container Transitioned from ALLOCATED to ACQUIRED
2013-08-09 12:24:33,959 INFO org.apache.hadoop.yarn.server.resourcemanager.amlauncher.AMLauncher: Setting up container Container: [ContainerId: container_1376050148932_0009_01_000001, NodeId: hadoop-210-2:40150, NodeHttpAddress: hadoop-210-2:8042, Resource: <memory:2048, vCores:1>, Priority: 0, State: NEW, Token: null, Status: container_id {, app_attempt_id {, application_id {, id: 9, cluster_timestamp: 1376050148932, }, attemptId: 1, }, id: 1, }, state: C_NEW, ] for AM appattempt_1376050148932_0009_000001
2013-08-09 12:24:33,959 INFO org.apache.hadoop.yarn.server.resourcemanager.amlauncher.AMLauncher: Command to launch container container_1376050148932_0009_01_000001 : $JAVA_HOME/bin/java -Dlog4j.configuration=container-log4j.properties -Dyarn.app.mapreduce.container.log.dir=<LOG_DIR> -Dyarn.app.mapreduce.container.log.filesize=0 -Dhadoop.root.logger=INFO,CLA  -Xmx1024m org.apache.hadoop.mapreduce.v2.app.MRAppMaster 1><LOG_DIR>/stdout 2><LOG_DIR>/stderr 
2013-08-09 12:24:33,960 INFO org.apache.hadoop.yarn.server.resourcemanager.rmapp.attempt.RMAppAttemptImpl: Storing attempt: AppId: application_1376050148932_0010 AttemptId: appattempt_1376050148932_0010_000001 MasterContainer: Container: [ContainerId: container_1376050148932_0010_01_000001, NodeId: hadoop-210-7:41457, NodeHttpAddress: hadoop-210-7:8042, Resource: <memory:2048, vCores:1>, Priority: 0, State: NEW, Token: null, Status: container_id {, app_attempt_id {, application_id {, id: 10, cluster_timestamp: 1376050148932, }, attemptId: 1, }, id: 1, }, state: C_NEW, ]
2013-08-09 12:24:33,960 INFO org.apache.hadoop.yarn.server.resourcemanager.rmapp.attempt.RMAppAttemptImpl: appattempt_1376050148932_0010_000001 State change from SCHEDULED to ALLOCATED_SAVING
2013-08-09 12:24:33,965 INFO org.apache.hadoop.yarn.server.resourcemanager.recovery.RMStateStore: Storing info for attempt: appattempt_1376050148932_0010_000001
2013-08-09 12:24:33,970 INFO org.apache.hadoop.yarn.server.resourcemanager.rmapp.attempt.RMAppAttemptImpl: appattempt_1376050148932_0010_000001 State change from ALLOCATED_SAVING to ALLOCATED
2013-08-09 12:24:33,975 INFO org.apache.hadoop.yarn.server.resourcemanager.amlauncher.AMLauncher: Launching masterappattempt_1376050148932_0010_000001
2013-08-09 12:24:33,976 INFO org.apache.hadoop.yarn.server.resourcemanager.amlauncher.AMLauncher: Setting up container Container: [ContainerId: container_1376050148932_0010_01_000001, NodeId: hadoop-210-7:41457, NodeHttpAddress: hadoop-210-7:8042, Resource: <memory:2048, vCores:1>, Priority: 0, State: NEW, Token: null, Status: container_id {, app_attempt_id {, application_id {, id: 10, cluster_timestamp: 1376050148932, }, attemptId: 1, }, id: 1, }, state: C_NEW, ] for AM appattempt_1376050148932_0010_000001
2013-08-09 12:24:33,976 INFO org.apache.hadoop.yarn.server.resourcemanager.amlauncher.AMLauncher: Command to launch container container_1376050148932_0010_01_000001 : $JAVA_HOME/bin/java -Dlog4j.configuration=container-log4j.properties -Dyarn.app.mapreduce.container.log.dir=<LOG_DIR> -Dyarn.app.mapreduce.container.log.filesize=0 -Dhadoop.root.logger=INFO,CLA  -Xmx1024m org.apache.hadoop.mapreduce.v2.app.MRAppMaster 1><LOG_DIR>/stdout 2><LOG_DIR>/stderr 
2013-08-09 12:24:33,988 INFO org.apache.hadoop.yarn.server.resourcemanager.amlauncher.AMLauncher: Done launching container Container: [ContainerId: container_1376050148932_0010_01_000001, NodeId: hadoop-210-7:41457, NodeHttpAddress: hadoop-210-7:8042, Resource: <memory:2048, vCores:1>, Priority: 0, State: NEW, Token: null, Status: container_id {, app_attempt_id {, application_id {, id: 10, cluster_timestamp: 1376050148932, }, attemptId: 1, }, id: 1, }, state: C_NEW, ] for AM appattempt_1376050148932_0010_000001
2013-08-09 12:24:33,989 INFO org.apache.hadoop.yarn.server.resourcemanager.rmapp.attempt.RMAppAttemptImpl: appattempt_1376050148932_0010_000001 State change from ALLOCATED to LAUNCHED
2013-08-09 12:24:34,216 INFO org.apache.hadoop.yarn.server.resourcemanager.rmcontainer.RMContainerImpl: container_1376050148932_0006_01_000001 Container Transitioned from ACQUIRED to RUNNING
2013-08-09 12:24:34,593 INFO org.apache.hadoop.yarn.server.resourcemanager.rmcontainer.RMContainerImpl: container_1376050148932_0007_01_000001 Container Transitioned from ACQUIRED to RUNNING
2013-08-09 12:24:34,959 INFO org.apache.hadoop.yarn.server.resourcemanager.rmcontainer.RMContainerImpl: container_1376050148932_0010_01_000001 Container Transitioned from ACQUIRED to RUNNING
2013-08-09 12:24:35,099 INFO org.apache.hadoop.yarn.server.resourcemanager.amlauncher.AMLauncher: Done launching container Container: [ContainerId: container_1376050148932_0008_01_000001, NodeId: hadoop-210-3:36255, NodeHttpAddress: hadoop-210-3:8042, Resource: <memory:2048, vCores:1>, Priority: 0, State: NEW, Token: null, Status: container_id {, app_attempt_id {, application_id {, id: 8, cluster_timestamp: 1376050148932, }, attemptId: 1, }, id: 1, }, state: C_NEW, ] for AM appattempt_1376050148932_0008_000001
2013-08-09 12:24:35,100 INFO org.apache.hadoop.yarn.server.resourcemanager.rmapp.attempt.RMAppAttemptImpl: appattempt_1376050148932_0008_000001 State change from ALLOCATED to LAUNCHED
2013-08-09 12:24:35,105 INFO org.apache.hadoop.yarn.server.resourcemanager.amlauncher.AMLauncher: Done launching container Container: [ContainerId: container_1376050148932_0009_01_000001, NodeId: hadoop-210-2:40150, NodeHttpAddress: hadoop-210-2:8042, Resource: <memory:2048, vCores:1>, Priority: 0, State: NEW, Token: null, Status: container_id {, app_attempt_id {, application_id {, id: 9, cluster_timestamp: 1376050148932, }, attemptId: 1, }, id: 1, }, state: C_NEW, ] for AM appattempt_1376050148932_0009_000001
2013-08-09 12:24:35,106 INFO org.apache.hadoop.yarn.server.resourcemanager.rmapp.attempt.RMAppAttemptImpl: appattempt_1376050148932_0009_000001 State change from ALLOCATED to LAUNCHED
2013-08-09 12:24:36,003 INFO org.apache.hadoop.yarn.server.resourcemanager.rmcontainer.RMContainerImpl: container_1376050148932_0008_01_000001 Container Transitioned from ACQUIRED to RUNNING
2013-08-09 12:24:36,023 INFO org.apache.hadoop.yarn.server.resourcemanager.rmcontainer.RMContainerImpl: container_1376050148932_0009_01_000001 Container Transitioned from ACQUIRED to RUNNING
2013-08-09 12:24:40,029 INFO org.apache.hadoop.yarn.server.resourcemanager.ApplicationMasterService: AM registration appattempt_1376050148932_0007_000001
2013-08-09 12:24:40,029 INFO org.apache.hadoop.yarn.server.resourcemanager.RMAuditLogger: USER=ubuntu	IP=192.168.100.11	OPERATION=Register App Master	TARGET=ApplicationMasterService	RESULT=SUCCESS	APPID=application_1376050148932_0007	APPATTEMPTID=appattempt_1376050148932_0007_000001
2013-08-09 12:24:40,030 INFO org.apache.hadoop.yarn.server.resourcemanager.rmapp.attempt.RMAppAttemptImpl: appattempt_1376050148932_0007_000001 State change from LAUNCHED to RUNNING
2013-08-09 12:24:40,030 INFO org.apache.hadoop.yarn.server.resourcemanager.rmapp.RMAppImpl: application_1376050148932_0007 State change from ACCEPTED to RUNNING
2013-08-09 12:24:40,274 INFO org.apache.hadoop.yarn.server.resourcemanager.ApplicationMasterService: AM registration appattempt_1376050148932_0006_000001
2013-08-09 12:24:40,275 INFO org.apache.hadoop.yarn.server.resourcemanager.RMAuditLogger: USER=ubuntu	IP=192.168.100.10	OPERATION=Register App Master	TARGET=ApplicationMasterService	RESULT=SUCCESS	APPID=application_1376050148932_0006	APPATTEMPTID=appattempt_1376050148932_0006_000001
2013-08-09 12:24:40,276 INFO org.apache.hadoop.yarn.server.resourcemanager.rmapp.attempt.RMAppAttemptImpl: appattempt_1376050148932_0006_000001 State change from LAUNCHED to RUNNING
2013-08-09 12:24:40,277 INFO org.apache.hadoop.yarn.server.resourcemanager.rmapp.RMAppImpl: application_1376050148932_0006 State change from ACCEPTED to RUNNING
2013-08-09 12:24:41,130 INFO org.apache.hadoop.yarn.server.resourcemanager.rmcontainer.RMContainerImpl: container_1376050148932_0007_01_000002 Container Transitioned from NEW to ALLOCATED
2013-08-09 12:24:41,131 INFO org.apache.hadoop.yarn.server.resourcemanager.RMAuditLogger: USER=ubuntu	OPERATION=AM Allocated Container	TARGET=SchedulerApp	RESULT=SUCCESS	APPID=application_1376050148932_0007	CONTAINERID=container_1376050148932_0007_01_000002
2013-08-09 12:24:41,131 INFO org.apache.hadoop.yarn.server.resourcemanager.scheduler.common.fica.FiCaSchedulerNode: Assigned container container_1376050148932_0007_01_000002 of capacity <memory:1024, vCores:1> on host hadoop-210-6:38267, which currently has 1 containers, <memory:1024, vCores:1> used and <memory:7168, vCores:15> available
2013-08-09 12:24:41,133 INFO org.apache.hadoop.yarn.server.resourcemanager.scheduler.capacity.LeafQueue: assignedContainer application=application_1376050148932_0007 container=Container: [ContainerId: container_1376050148932_0007_01_000002, NodeId: hadoop-210-6:38267, NodeHttpAddress: hadoop-210-6:8042, Resource: <memory:1024, vCores:1>, Priority: 20, State: NEW, Token: null, Status: container_id {, app_attempt_id {, application_id {, id: 7, cluster_timestamp: 1376050148932, }, attemptId: 1, }, id: 2, }, state: C_NEW, ] containerId=container_1376050148932_0007_01_000002 queue=default: capacity=1.0, absoluteCapacity=1.0, usedResources=<memory:10240, vCores:5>usedCapacity=0.20833333, absoluteUsedCapacity=0.20833333, numApps=5, numContainers=5 usedCapacity=0.20833333 absoluteUsedCapacity=0.20833333 used=<memory:10240, vCores:5> cluster=<memory:49152, vCores:96>
2013-08-09 12:24:41,133 INFO org.apache.hadoop.yarn.server.resourcemanager.scheduler.capacity.ParentQueue: Re-sorting queues since queue: root.default stats: default: capacity=1.0, absoluteCapacity=1.0, usedResources=<memory:11264, vCores:6>usedCapacity=0.22916667, absoluteUsedCapacity=0.22916667, numApps=5, numContainers=6
2013-08-09 12:24:41,133 INFO org.apache.hadoop.yarn.server.resourcemanager.scheduler.capacity.ParentQueue: assignedContainer queue=root usedCapacity=0.22916667 absoluteUsedCapacity=0.22916667 used=<memory:11264, vCores:6> cluster=<memory:49152, vCores:96>
2013-08-09 12:24:41,134 INFO org.apache.hadoop.yarn.server.resourcemanager.rmcontainer.RMContainerImpl: container_1376050148932_0007_01_000003 Container Transitioned from NEW to ALLOCATED
2013-08-09 12:24:41,134 INFO org.apache.hadoop.yarn.server.resourcemanager.RMAuditLogger: USER=ubuntu	OPERATION=AM Allocated Container	TARGET=SchedulerApp	RESULT=SUCCESS	APPID=application_1376050148932_0007	CONTAINERID=container_1376050148932_0007_01_000003
2013-08-09 12:24:41,134 INFO org.apache.hadoop.yarn.server.resourcemanager.scheduler.common.fica.FiCaSchedulerNode: Assigned container container_1376050148932_0007_01_000003 of capacity <memory:1024, vCores:1> on host hadoop-210-6:38267, which currently has 2 containers, <memory:2048, vCores:2> used and <memory:6144, vCores:14> available
2013-08-09 12:24:41,135 INFO org.apache.hadoop.yarn.server.resourcemanager.scheduler.capacity.LeafQueue: assignedContainer application=application_1376050148932_0007 container=Container: [ContainerId: container_1376050148932_0007_01_000003, NodeId: hadoop-210-6:38267, NodeHttpAddress: hadoop-210-6:8042, Resource: <memory:1024, vCores:1>, Priority: 20, State: NEW, Token: null, Status: container_id {, app_attempt_id {, application_id {, id: 7, cluster_timestamp: 1376050148932, }, attemptId: 1, }, id: 3, }, state: C_NEW, ] containerId=container_1376050148932_0007_01_000003 queue=default: capacity=1.0, absoluteCapacity=1.0, usedResources=<memory:11264, vCores:6>usedCapacity=0.22916667, absoluteUsedCapacity=0.22916667, numApps=5, numContainers=6 usedCapacity=0.22916667 absoluteUsedCapacity=0.22916667 used=<memory:11264, vCores:6> cluster=<memory:49152, vCores:96>
2013-08-09 12:24:41,135 INFO org.apache.hadoop.yarn.server.resourcemanager.scheduler.capacity.ParentQueue: Re-sorting queues since queue: root.default stats: default: capacity=1.0, absoluteCapacity=1.0, usedResources=<memory:12288, vCores:7>usedCapacity=0.25, absoluteUsedCapacity=0.25, numApps=5, numContainers=7
2013-08-09 12:24:41,135 INFO org.apache.hadoop.yarn.server.resourcemanager.scheduler.capacity.ParentQueue: assignedContainer queue=root usedCapacity=0.25 absoluteUsedCapacity=0.25 used=<memory:12288, vCores:7> cluster=<memory:49152, vCores:96>
2013-08-09 12:24:41,136 INFO org.apache.hadoop.yarn.server.resourcemanager.rmcontainer.RMContainerImpl: container_1376050148932_0007_01_000004 Container Transitioned from NEW to ALLOCATED
2013-08-09 12:24:41,136 INFO org.apache.hadoop.yarn.server.resourcemanager.RMAuditLogger: USER=ubuntu	OPERATION=AM Allocated Container	TARGET=SchedulerApp	RESULT=SUCCESS	APPID=application_1376050148932_0007	CONTAINERID=container_1376050148932_0007_01_000004
2013-08-09 12:24:41,136 INFO org.apache.hadoop.yarn.server.resourcemanager.scheduler.common.fica.FiCaSchedulerNode: Assigned container container_1376050148932_0007_01_000004 of capacity <memory:1024, vCores:1> on host hadoop-210-6:38267, which currently has 3 containers, <memory:3072, vCores:3> used and <memory:5120, vCores:13> available
2013-08-09 12:24:41,137 INFO org.apache.hadoop.yarn.server.resourcemanager.scheduler.capacity.LeafQueue: assignedContainer application=application_1376050148932_0007 container=Container: [ContainerId: container_1376050148932_0007_01_000004, NodeId: hadoop-210-6:38267, NodeHttpAddress: hadoop-210-6:8042, Resource: <memory:1024, vCores:1>, Priority: 20, State: NEW, Token: null, Status: container_id {, app_attempt_id {, application_id {, id: 7, cluster_timestamp: 1376050148932, }, attemptId: 1, }, id: 4, }, state: C_NEW, ] containerId=container_1376050148932_0007_01_000004 queue=default: capacity=1.0, absoluteCapacity=1.0, usedResources=<memory:12288, vCores:7>usedCapacity=0.25, absoluteUsedCapacity=0.25, numApps=5, numContainers=7 usedCapacity=0.25 absoluteUsedCapacity=0.25 used=<memory:12288, vCores:7> cluster=<memory:49152, vCores:96>
2013-08-09 12:24:41,137 INFO org.apache.hadoop.yarn.server.resourcemanager.scheduler.capacity.ParentQueue: Re-sorting queues since queue: root.default stats: default: capacity=1.0, absoluteCapacity=1.0, usedResources=<memory:13312, vCores:8>usedCapacity=0.27083334, absoluteUsedCapacity=0.27083334, numApps=5, numContainers=8
2013-08-09 12:24:41,138 INFO org.apache.hadoop.yarn.server.resourcemanager.scheduler.capacity.ParentQueue: assignedContainer queue=root usedCapacity=0.27083334 absoluteUsedCapacity=0.27083334 used=<memory:13312, vCores:8> cluster=<memory:49152, vCores:96>
2013-08-09 12:24:41,138 INFO org.apache.hadoop.yarn.server.resourcemanager.rmcontainer.RMContainerImpl: container_1376050148932_0007_01_000005 Container Transitioned from NEW to ALLOCATED
2013-08-09 12:24:41,138 INFO org.apache.hadoop.yarn.server.resourcemanager.RMAuditLogger: USER=ubuntu	OPERATION=AM Allocated Container	TARGET=SchedulerApp	RESULT=SUCCESS	APPID=application_1376050148932_0007	CONTAINERID=container_1376050148932_0007_01_000005
2013-08-09 12:24:41,138 INFO org.apache.hadoop.yarn.server.resourcemanager.scheduler.common.fica.FiCaSchedulerNode: Assigned container container_1376050148932_0007_01_000005 of capacity <memory:1024, vCores:1> on host hadoop-210-6:38267, which currently has 4 containers, <memory:4096, vCores:4> used and <memory:4096, vCores:12> available
2013-08-09 12:24:41,139 INFO org.apache.hadoop.yarn.server.resourcemanager.scheduler.capacity.LeafQueue: assignedContainer application=application_1376050148932_0007 container=Container: [ContainerId: container_1376050148932_0007_01_000005, NodeId: hadoop-210-6:38267, NodeHttpAddress: hadoop-210-6:8042, Resource: <memory:1024, vCores:1>, Priority: 20, State: NEW, Token: null, Status: container_id {, app_attempt_id {, application_id {, id: 7, cluster_timestamp: 1376050148932, }, attemptId: 1, }, id: 5, }, state: C_NEW, ] containerId=container_1376050148932_0007_01_000005 queue=default: capacity=1.0, absoluteCapacity=1.0, usedResources=<memory:13312, vCores:8>usedCapacity=0.27083334, absoluteUsedCapacity=0.27083334, numApps=5, numContainers=8 usedCapacity=0.27083334 absoluteUsedCapacity=0.27083334 used=<memory:13312, vCores:8> cluster=<memory:49152, vCores:96>
2013-08-09 12:24:41,140 INFO org.apache.hadoop.yarn.server.resourcemanager.scheduler.capacity.ParentQueue: Re-sorting queues since queue: root.default stats: default: capacity=1.0, absoluteCapacity=1.0, usedResources=<memory:14336, vCores:9>usedCapacity=0.29166666, absoluteUsedCapacity=0.29166666, numApps=5, numContainers=9
2013-08-09 12:24:41,140 INFO org.apache.hadoop.yarn.server.resourcemanager.scheduler.capacity.ParentQueue: assignedContainer queue=root usedCapacity=0.29166666 absoluteUsedCapacity=0.29166666 used=<memory:14336, vCores:9> cluster=<memory:49152, vCores:96>
2013-08-09 12:24:41,141 INFO org.apache.hadoop.yarn.server.resourcemanager.rmcontainer.RMContainerImpl: container_1376050148932_0007_01_000006 Container Transitioned from NEW to ALLOCATED
2013-08-09 12:24:41,144 INFO org.apache.hadoop.yarn.server.resourcemanager.RMAuditLogger: USER=ubuntu	OPERATION=AM Allocated Container	TARGET=SchedulerApp	RESULT=SUCCESS	APPID=application_1376050148932_0007	CONTAINERID=container_1376050148932_0007_01_000006
2013-08-09 12:24:41,144 INFO org.apache.hadoop.yarn.server.resourcemanager.scheduler.common.fica.FiCaSchedulerNode: Assigned container container_1376050148932_0007_01_000006 of capacity <memory:1024, vCores:1> on host hadoop-210-6:38267, which currently has 5 containers, <memory:5120, vCores:5> used and <memory:3072, vCores:11> available
2013-08-09 12:24:41,147 INFO org.apache.hadoop.yarn.server.resourcemanager.scheduler.capacity.LeafQueue: assignedContainer application=application_1376050148932_0007 container=Container: [ContainerId: container_1376050148932_0007_01_000006, NodeId: hadoop-210-6:38267, NodeHttpAddress: hadoop-210-6:8042, Resource: <memory:1024, vCores:1>, Priority: 20, State: NEW, Token: null, Status: container_id {, app_attempt_id {, application_id {, id: 7, cluster_timestamp: 1376050148932, }, attemptId: 1, }, id: 6, }, state: C_NEW, ] containerId=container_1376050148932_0007_01_000006 queue=default: capacity=1.0, absoluteCapacity=1.0, usedResources=<memory:14336, vCores:9>usedCapacity=0.29166666, absoluteUsedCapacity=0.29166666, numApps=5, numContainers=9 usedCapacity=0.29166666 absoluteUsedCapacity=0.29166666 used=<memory:14336, vCores:9> cluster=<memory:49152, vCores:96>
2013-08-09 12:24:41,147 INFO org.apache.hadoop.yarn.server.resourcemanager.scheduler.capacity.ParentQueue: Re-sorting queues since queue: root.default stats: default: capacity=1.0, absoluteCapacity=1.0, usedResources=<memory:15360, vCores:10>usedCapacity=0.3125, absoluteUsedCapacity=0.3125, numApps=5, numContainers=10
2013-08-09 12:24:41,147 INFO org.apache.hadoop.yarn.server.resourcemanager.scheduler.capacity.ParentQueue: assignedContainer queue=root usedCapacity=0.3125 absoluteUsedCapacity=0.3125 used=<memory:15360, vCores:10> cluster=<memory:49152, vCores:96>
2013-08-09 12:24:41,148 INFO org.apache.hadoop.yarn.server.resourcemanager.rmcontainer.RMContainerImpl: container_1376050148932_0007_01_000007 Container Transitioned from NEW to ALLOCATED
2013-08-09 12:24:41,148 INFO org.apache.hadoop.yarn.server.resourcemanager.RMAuditLogger: USER=ubuntu	OPERATION=AM Allocated Container	TARGET=SchedulerApp	RESULT=SUCCESS	APPID=application_1376050148932_0007	CONTAINERID=container_1376050148932_0007_01_000007
2013-08-09 12:24:41,149 INFO org.apache.hadoop.yarn.server.resourcemanager.scheduler.common.fica.FiCaSchedulerNode: Assigned container container_1376050148932_0007_01_000007 of capacity <memory:1024, vCores:1> on host hadoop-210-6:38267, which currently has 6 containers, <memory:6144, vCores:6> used and <memory:2048, vCores:10> available
2013-08-09 12:24:41,152 INFO org.apache.hadoop.yarn.server.resourcemanager.scheduler.capacity.LeafQueue: assignedContainer application=application_1376050148932_0007 container=Container: [ContainerId: container_1376050148932_0007_01_000007, NodeId: hadoop-210-6:38267, NodeHttpAddress: hadoop-210-6:8042, Resource: <memory:1024, vCores:1>, Priority: 20, State: NEW, Token: null, Status: container_id {, app_attempt_id {, application_id {, id: 7, cluster_timestamp: 1376050148932, }, attemptId: 1, }, id: 7, }, state: C_NEW, ] containerId=container_1376050148932_0007_01_000007 queue=default: capacity=1.0, absoluteCapacity=1.0, usedResources=<memory:15360, vCores:10>usedCapacity=0.3125, absoluteUsedCapacity=0.3125, numApps=5, numContainers=10 usedCapacity=0.3125 absoluteUsedCapacity=0.3125 used=<memory:15360, vCores:10> cluster=<memory:49152, vCores:96>
2013-08-09 12:24:41,152 INFO org.apache.hadoop.yarn.server.resourcemanager.scheduler.capacity.ParentQueue: Re-sorting queues since queue: root.default stats: default: capacity=1.0, absoluteCapacity=1.0, usedResources=<memory:16384, vCores:11>usedCapacity=0.33333334, absoluteUsedCapacity=0.33333334, numApps=5, numContainers=11
2013-08-09 12:24:41,153 INFO org.apache.hadoop.yarn.server.resourcemanager.scheduler.capacity.ParentQueue: assignedContainer queue=root usedCapacity=0.33333334 absoluteUsedCapacity=0.33333334 used=<memory:16384, vCores:11> cluster=<memory:49152, vCores:96>
2013-08-09 12:24:41,153 INFO org.apache.hadoop.yarn.server.resourcemanager.rmcontainer.RMContainerImpl: container_1376050148932_0007_01_000008 Container Transitioned from NEW to ALLOCATED
2013-08-09 12:24:41,153 INFO org.apache.hadoop.yarn.server.resourcemanager.RMAuditLogger: USER=ubuntu	OPERATION=AM Allocated Container	TARGET=SchedulerApp	RESULT=SUCCESS	APPID=application_1376050148932_0007	CONTAINERID=container_1376050148932_0007_01_000008
2013-08-09 12:24:41,154 INFO org.apache.hadoop.yarn.server.resourcemanager.scheduler.common.fica.FiCaSchedulerNode: Assigned container container_1376050148932_0007_01_000008 of capacity <memory:1024, vCores:1> on host hadoop-210-6:38267, which currently has 7 containers, <memory:7168, vCores:7> used and <memory:1024, vCores:9> available
2013-08-09 12:24:41,155 INFO org.apache.hadoop.yarn.server.resourcemanager.scheduler.capacity.LeafQueue: assignedContainer application=application_1376050148932_0007 container=Container: [ContainerId: container_1376050148932_0007_01_000008, NodeId: hadoop-210-6:38267, NodeHttpAddress: hadoop-210-6:8042, Resource: <memory:1024, vCores:1>, Priority: 20, State: NEW, Token: null, Status: container_id {, app_attempt_id {, application_id {, id: 7, cluster_timestamp: 1376050148932, }, attemptId: 1, }, id: 8, }, state: C_NEW, ] containerId=container_1376050148932_0007_01_000008 queue=default: capacity=1.0, absoluteCapacity=1.0, usedResources=<memory:16384, vCores:11>usedCapacity=0.33333334, absoluteUsedCapacity=0.33333334, numApps=5, numContainers=11 usedCapacity=0.33333334 absoluteUsedCapacity=0.33333334 used=<memory:16384, vCores:11> cluster=<memory:49152, vCores:96>
2013-08-09 12:24:41,155 INFO org.apache.hadoop.yarn.server.resourcemanager.scheduler.capacity.ParentQueue: Re-sorting queues since queue: root.default stats: default: capacity=1.0, absoluteCapacity=1.0, usedResources=<memory:17408, vCores:12>usedCapacity=0.35416666, absoluteUsedCapacity=0.35416666, numApps=5, numContainers=12
2013-08-09 12:24:41,155 INFO org.apache.hadoop.yarn.server.resourcemanager.scheduler.capacity.ParentQueue: assignedContainer queue=root usedCapacity=0.35416666 absoluteUsedCapacity=0.35416666 used=<memory:17408, vCores:12> cluster=<memory:49152, vCores:96>
2013-08-09 12:24:41,156 INFO org.apache.hadoop.yarn.server.resourcemanager.rmcontainer.RMContainerImpl: container_1376050148932_0007_01_000009 Container Transitioned from NEW to ALLOCATED
2013-08-09 12:24:41,156 INFO org.apache.hadoop.yarn.server.resourcemanager.RMAuditLogger: USER=ubuntu	OPERATION=AM Allocated Container	TARGET=SchedulerApp	RESULT=SUCCESS	APPID=application_1376050148932_0007	CONTAINERID=container_1376050148932_0007_01_000009
2013-08-09 12:24:41,156 INFO org.apache.hadoop.yarn.server.resourcemanager.scheduler.common.fica.FiCaSchedulerNode: Assigned container container_1376050148932_0007_01_000009 of capacity <memory:1024, vCores:1> on host hadoop-210-6:38267, which currently has 8 containers, <memory:8192, vCores:8> used and <memory:0, vCores:8> available
2013-08-09 12:24:41,157 INFO org.apache.hadoop.yarn.server.resourcemanager.scheduler.capacity.LeafQueue: assignedContainer application=application_1376050148932_0007 container=Container: [ContainerId: container_1376050148932_0007_01_000009, NodeId: hadoop-210-6:38267, NodeHttpAddress: hadoop-210-6:8042, Resource: <memory:1024, vCores:1>, Priority: 20, State: NEW, Token: null, Status: container_id {, app_attempt_id {, application_id {, id: 7, cluster_timestamp: 1376050148932, }, attemptId: 1, }, id: 9, }, state: C_NEW, ] containerId=container_1376050148932_0007_01_000009 queue=default: capacity=1.0, absoluteCapacity=1.0, usedResources=<memory:17408, vCores:12>usedCapacity=0.35416666, absoluteUsedCapacity=0.35416666, numApps=5, numContainers=12 usedCapacity=0.35416666 absoluteUsedCapacity=0.35416666 used=<memory:17408, vCores:12> cluster=<memory:49152, vCores:96>
2013-08-09 12:24:41,157 INFO org.apache.hadoop.yarn.server.resourcemanager.scheduler.capacity.ParentQueue: Re-sorting queues since queue: root.default stats: default: capacity=1.0, absoluteCapacity=1.0, usedResources=<memory:18432, vCores:13>usedCapacity=0.375, absoluteUsedCapacity=0.375, numApps=5, numContainers=13
2013-08-09 12:24:41,157 INFO org.apache.hadoop.yarn.server.resourcemanager.scheduler.capacity.ParentQueue: assignedContainer queue=root usedCapacity=0.375 absoluteUsedCapacity=0.375 used=<memory:18432, vCores:13> cluster=<memory:49152, vCores:96>
2013-08-09 12:24:41,246 INFO org.apache.hadoop.yarn.server.resourcemanager.rmcontainer.RMContainerImpl: container_1376050148932_0007_01_000010 Container Transitioned from NEW to ALLOCATED
2013-08-09 12:24:41,246 INFO org.apache.hadoop.yarn.server.resourcemanager.RMAuditLogger: USER=ubuntu	OPERATION=AM Allocated Container	TARGET=SchedulerApp	RESULT=SUCCESS	APPID=application_1376050148932_0007	CONTAINERID=container_1376050148932_0007_01_000010
2013-08-09 12:24:41,246 INFO org.apache.hadoop.yarn.server.resourcemanager.scheduler.common.fica.FiCaSchedulerNode: Assigned container container_1376050148932_0007_01_000010 of capacity <memory:1024, vCores:1> on host hadoop-210-4:57908, which currently has 2 containers, <memory:3072, vCores:2> used and <memory:5120, vCores:14> available
2013-08-09 12:24:41,247 INFO org.apache.hadoop.yarn.server.resourcemanager.scheduler.capacity.LeafQueue: assignedContainer application=application_1376050148932_0007 container=Container: [ContainerId: container_1376050148932_0007_01_000010, NodeId: hadoop-210-4:57908, NodeHttpAddress: hadoop-210-4:8042, Resource: <memory:1024, vCores:1>, Priority: 20, State: NEW, Token: null, Status: container_id {, app_attempt_id {, application_id {, id: 7, cluster_timestamp: 1376050148932, }, attemptId: 1, }, id: 10, }, state: C_NEW, ] containerId=container_1376050148932_0007_01_000010 queue=default: capacity=1.0, absoluteCapacity=1.0, usedResources=<memory:18432, vCores:13>usedCapacity=0.375, absoluteUsedCapacity=0.375, numApps=5, numContainers=13 usedCapacity=0.375 absoluteUsedCapacity=0.375 used=<memory:18432, vCores:13> cluster=<memory:49152, vCores:96>
2013-08-09 12:24:41,247 INFO org.apache.hadoop.yarn.server.resourcemanager.scheduler.capacity.ParentQueue: Re-sorting queues since queue: root.default stats: default: capacity=1.0, absoluteCapacity=1.0, usedResources=<memory:19456, vCores:14>usedCapacity=0.39583334, absoluteUsedCapacity=0.39583334, numApps=5, numContainers=14
2013-08-09 12:24:41,248 INFO org.apache.hadoop.yarn.server.resourcemanager.scheduler.capacity.ParentQueue: assignedContainer queue=root usedCapacity=0.39583334 absoluteUsedCapacity=0.39583334 used=<memory:19456, vCores:14> cluster=<memory:49152, vCores:96>
2013-08-09 12:24:41,248 INFO org.apache.hadoop.yarn.server.resourcemanager.rmcontainer.RMContainerImpl: container_1376050148932_0007_01_000011 Container Transitioned from NEW to ALLOCATED
2013-08-09 12:24:41,248 INFO org.apache.hadoop.yarn.server.resourcemanager.RMAuditLogger: USER=ubuntu	OPERATION=AM Allocated Container	TARGET=SchedulerApp	RESULT=SUCCESS	APPID=application_1376050148932_0007	CONTAINERID=container_1376050148932_0007_01_000011
2013-08-09 12:24:41,248 INFO org.apache.hadoop.yarn.server.resourcemanager.scheduler.common.fica.FiCaSchedulerNode: Assigned container container_1376050148932_0007_01_000011 of capacity <memory:1024, vCores:1> on host hadoop-210-4:57908, which currently has 3 containers, <memory:4096, vCores:3> used and <memory:4096, vCores:13> available
2013-08-09 12:24:41,249 INFO org.apache.hadoop.yarn.server.resourcemanager.scheduler.capacity.LeafQueue: assignedContainer application=application_1376050148932_0007 container=Container: [ContainerId: container_1376050148932_0007_01_000011, NodeId: hadoop-210-4:57908, NodeHttpAddress: hadoop-210-4:8042, Resource: <memory:1024, vCores:1>, Priority: 20, State: NEW, Token: null, Status: container_id {, app_attempt_id {, application_id {, id: 7, cluster_timestamp: 1376050148932, }, attemptId: 1, }, id: 11, }, state: C_NEW, ] containerId=container_1376050148932_0007_01_000011 queue=default: capacity=1.0, absoluteCapacity=1.0, usedResources=<memory:19456, vCores:14>usedCapacity=0.39583334, absoluteUsedCapacity=0.39583334, numApps=5, numContainers=14 usedCapacity=0.39583334 absoluteUsedCapacity=0.39583334 used=<memory:19456, vCores:14> cluster=<memory:49152, vCores:96>
2013-08-09 12:24:41,250 INFO org.apache.hadoop.yarn.server.resourcemanager.scheduler.capacity.ParentQueue: Re-sorting queues since queue: root.default stats: default: capacity=1.0, absoluteCapacity=1.0, usedResources=<memory:20480, vCores:15>usedCapacity=0.41666666, absoluteUsedCapacity=0.41666666, numApps=5, numContainers=15
2013-08-09 12:24:41,250 INFO org.apache.hadoop.yarn.server.resourcemanager.scheduler.capacity.ParentQueue: assignedContainer queue=root usedCapacity=0.41666666 absoluteUsedCapacity=0.41666666 used=<memory:20480, vCores:15> cluster=<memory:49152, vCores:96>
2013-08-09 12:24:41,250 INFO org.apache.hadoop.yarn.server.resourcemanager.rmcontainer.RMContainerImpl: container_1376050148932_0007_01_000012 Container Transitioned from NEW to ALLOCATED
2013-08-09 12:24:41,250 INFO org.apache.hadoop.yarn.server.resourcemanager.RMAuditLogger: USER=ubuntu	OPERATION=AM Allocated Container	TARGET=SchedulerApp	RESULT=SUCCESS	APPID=application_1376050148932_0007	CONTAINERID=container_1376050148932_0007_01_000012
2013-08-09 12:24:41,251 INFO org.apache.hadoop.yarn.server.resourcemanager.scheduler.common.fica.FiCaSchedulerNode: Assigned container container_1376050148932_0007_01_000012 of capacity <memory:1024, vCores:1> on host hadoop-210-4:57908, which currently has 4 containers, <memory:5120, vCores:4> used and <memory:3072, vCores:12> available
2013-08-09 12:24:41,251 INFO org.apache.hadoop.yarn.server.resourcemanager.scheduler.capacity.LeafQueue: assignedContainer application=application_1376050148932_0007 container=Container: [ContainerId: container_1376050148932_0007_01_000012, NodeId: hadoop-210-4:57908, NodeHttpAddress: hadoop-210-4:8042, Resource: <memory:1024, vCores:1>, Priority: 20, State: NEW, Token: null, Status: container_id {, app_attempt_id {, application_id {, id: 7, cluster_timestamp: 1376050148932, }, attemptId: 1, }, id: 12, }, state: C_NEW, ] containerId=container_1376050148932_0007_01_000012 queue=default: capacity=1.0, absoluteCapacity=1.0, usedResources=<memory:20480, vCores:15>usedCapacity=0.41666666, absoluteUsedCapacity=0.41666666, numApps=5, numContainers=15 usedCapacity=0.41666666 absoluteUsedCapacity=0.41666666 used=<memory:20480, vCores:15> cluster=<memory:49152, vCores:96>
2013-08-09 12:24:41,252 INFO org.apache.hadoop.yarn.server.resourcemanager.scheduler.capacity.ParentQueue: Re-sorting queues since queue: root.default stats: default: capacity=1.0, absoluteCapacity=1.0, usedResources=<memory:21504, vCores:16>usedCapacity=0.4375, absoluteUsedCapacity=0.4375, numApps=5, numContainers=16
2013-08-09 12:24:41,252 INFO org.apache.hadoop.yarn.server.resourcemanager.scheduler.capacity.ParentQueue: assignedContainer queue=root usedCapacity=0.4375 absoluteUsedCapacity=0.4375 used=<memory:21504, vCores:16> cluster=<memory:49152, vCores:96>
2013-08-09 12:24:41,252 INFO org.apache.hadoop.yarn.server.resourcemanager.rmcontainer.RMContainerImpl: container_1376050148932_0007_01_000013 Container Transitioned from NEW to ALLOCATED
2013-08-09 12:24:41,253 INFO org.apache.hadoop.yarn.server.resourcemanager.RMAuditLogger: USER=ubuntu	OPERATION=AM Allocated Container	TARGET=SchedulerApp	RESULT=SUCCESS	APPID=application_1376050148932_0007	CONTAINERID=container_1376050148932_0007_01_000013
2013-08-09 12:24:41,253 INFO org.apache.hadoop.yarn.server.resourcemanager.scheduler.common.fica.FiCaSchedulerNode: Assigned container container_1376050148932_0007_01_000013 of capacity <memory:1024, vCores:1> on host hadoop-210-4:57908, which currently has 5 containers, <memory:6144, vCores:5> used and <memory:2048, vCores:11> available
2013-08-09 12:24:41,254 INFO org.apache.hadoop.yarn.server.resourcemanager.scheduler.capacity.LeafQueue: assignedContainer application=application_1376050148932_0007 container=Container: [ContainerId: container_1376050148932_0007_01_000013, NodeId: hadoop-210-4:57908, NodeHttpAddress: hadoop-210-4:8042, Resource: <memory:1024, vCores:1>, Priority: 20, State: NEW, Token: null, Status: container_id {, app_attempt_id {, application_id {, id: 7, cluster_timestamp: 1376050148932, }, attemptId: 1, }, id: 13, }, state: C_NEW, ] containerId=container_1376050148932_0007_01_000013 queue=default: capacity=1.0, absoluteCapacity=1.0, usedResources=<memory:21504, vCores:16>usedCapacity=0.4375, absoluteUsedCapacity=0.4375, numApps=5, numContainers=16 usedCapacity=0.4375 absoluteUsedCapacity=0.4375 used=<memory:21504, vCores:16> cluster=<memory:49152, vCores:96>
2013-08-09 12:24:41,254 INFO org.apache.hadoop.yarn.server.resourcemanager.scheduler.capacity.ParentQueue: Re-sorting queues since queue: root.default stats: default: capacity=1.0, absoluteCapacity=1.0, usedResources=<memory:22528, vCores:17>usedCapacity=0.45833334, absoluteUsedCapacity=0.45833334, numApps=5, numContainers=17
2013-08-09 12:24:41,254 INFO org.apache.hadoop.yarn.server.resourcemanager.scheduler.capacity.ParentQueue: assignedContainer queue=root usedCapacity=0.45833334 absoluteUsedCapacity=0.45833334 used=<memory:22528, vCores:17> cluster=<memory:49152, vCores:96>
2013-08-09 12:24:41,255 INFO org.apache.hadoop.yarn.server.resourcemanager.rmcontainer.RMContainerImpl: container_1376050148932_0007_01_000014 Container Transitioned from NEW to ALLOCATED
2013-08-09 12:24:41,255 INFO org.apache.hadoop.yarn.server.resourcemanager.RMAuditLogger: USER=ubuntu	OPERATION=AM Allocated Container	TARGET=SchedulerApp	RESULT=SUCCESS	APPID=application_1376050148932_0007	CONTAINERID=container_1376050148932_0007_01_000014
2013-08-09 12:24:41,255 INFO org.apache.hadoop.yarn.server.resourcemanager.scheduler.common.fica.FiCaSchedulerNode: Assigned container container_1376050148932_0007_01_000014 of capacity <memory:1024, vCores:1> on host hadoop-210-4:57908, which currently has 6 containers, <memory:7168, vCores:6> used and <memory:1024, vCores:10> available
2013-08-09 12:24:41,256 INFO org.apache.hadoop.yarn.server.resourcemanager.scheduler.capacity.LeafQueue: assignedContainer application=application_1376050148932_0007 container=Container: [ContainerId: container_1376050148932_0007_01_000014, NodeId: hadoop-210-4:57908, NodeHttpAddress: hadoop-210-4:8042, Resource: <memory:1024, vCores:1>, Priority: 20, State: NEW, Token: null, Status: container_id {, app_attempt_id {, application_id {, id: 7, cluster_timestamp: 1376050148932, }, attemptId: 1, }, id: 14, }, state: C_NEW, ] containerId=container_1376050148932_0007_01_000014 queue=default: capacity=1.0, absoluteCapacity=1.0, usedResources=<memory:22528, vCores:17>usedCapacity=0.45833334, absoluteUsedCapacity=0.45833334, numApps=5, numContainers=17 usedCapacity=0.45833334 absoluteUsedCapacity=0.45833334 used=<memory:22528, vCores:17> cluster=<memory:49152, vCores:96>
2013-08-09 12:24:41,256 INFO org.apache.hadoop.yarn.server.resourcemanager.scheduler.capacity.ParentQueue: Re-sorting queues since queue: root.default stats: default: capacity=1.0, absoluteCapacity=1.0, usedResources=<memory:23552, vCores:18>usedCapacity=0.47916666, absoluteUsedCapacity=0.47916666, numApps=5, numContainers=18
2013-08-09 12:24:41,256 INFO org.apache.hadoop.yarn.server.resourcemanager.scheduler.capacity.ParentQueue: assignedContainer queue=root usedCapacity=0.47916666 absoluteUsedCapacity=0.47916666 used=<memory:23552, vCores:18> cluster=<memory:49152, vCores:96>
2013-08-09 12:24:41,257 INFO org.apache.hadoop.yarn.server.resourcemanager.rmcontainer.RMContainerImpl: container_1376050148932_0007_01_000015 Container Transitioned from NEW to ALLOCATED
2013-08-09 12:24:41,257 INFO org.apache.hadoop.yarn.server.resourcemanager.RMAuditLogger: USER=ubuntu	OPERATION=AM Allocated Container	TARGET=SchedulerApp	RESULT=SUCCESS	APPID=application_1376050148932_0007	CONTAINERID=container_1376050148932_0007_01_000015
2013-08-09 12:24:41,257 INFO org.apache.hadoop.yarn.server.resourcemanager.scheduler.common.fica.FiCaSchedulerNode: Assigned container container_1376050148932_0007_01_000015 of capacity <memory:1024, vCores:1> on host hadoop-210-4:57908, which currently has 7 containers, <memory:8192, vCores:7> used and <memory:0, vCores:9> available
2013-08-09 12:24:41,258 INFO org.apache.hadoop.yarn.server.resourcemanager.scheduler.capacity.LeafQueue: assignedContainer application=application_1376050148932_0007 container=Container: [ContainerId: container_1376050148932_0007_01_000015, NodeId: hadoop-210-4:57908, NodeHttpAddress: hadoop-210-4:8042, Resource: <memory:1024, vCores:1>, Priority: 20, State: NEW, Token: null, Status: container_id {, app_attempt_id {, application_id {, id: 7, cluster_timestamp: 1376050148932, }, attemptId: 1, }, id: 15, }, state: C_NEW, ] containerId=container_1376050148932_0007_01_000015 queue=default: capacity=1.0, absoluteCapacity=1.0, usedResources=<memory:23552, vCores:18>usedCapacity=0.47916666, absoluteUsedCapacity=0.47916666, numApps=5, numContainers=18 usedCapacity=0.47916666 absoluteUsedCapacity=0.47916666 used=<memory:23552, vCores:18> cluster=<memory:49152, vCores:96>
2013-08-09 12:24:41,258 INFO org.apache.hadoop.yarn.server.resourcemanager.scheduler.capacity.ParentQueue: Re-sorting queues since queue: root.default stats: default: capacity=1.0, absoluteCapacity=1.0, usedResources=<memory:24576, vCores:19>usedCapacity=0.5, absoluteUsedCapacity=0.5, numApps=5, numContainers=19
2013-08-09 12:24:41,258 INFO org.apache.hadoop.yarn.server.resourcemanager.scheduler.capacity.ParentQueue: assignedContainer queue=root usedCapacity=0.5 absoluteUsedCapacity=0.5 used=<memory:24576, vCores:19> cluster=<memory:49152, vCores:96>
2013-08-09 12:24:41,378 INFO org.apache.hadoop.yarn.server.resourcemanager.ApplicationMasterService: AM registration appattempt_1376050148932_0010_000001
2013-08-09 12:24:41,379 INFO org.apache.hadoop.yarn.server.resourcemanager.RMAuditLogger: USER=ubuntu	IP=192.168.100.14	OPERATION=Register App Master	TARGET=ApplicationMasterService	RESULT=SUCCESS	APPID=application_1376050148932_0010	APPATTEMPTID=appattempt_1376050148932_0010_000001
2013-08-09 12:24:41,380 INFO org.apache.hadoop.yarn.server.resourcemanager.rmapp.attempt.RMAppAttemptImpl: appattempt_1376050148932_0010_000001 State change from LAUNCHED to RUNNING
2013-08-09 12:24:41,380 INFO org.apache.hadoop.yarn.server.resourcemanager.rmapp.RMAppImpl: application_1376050148932_0010 State change from ACCEPTED to RUNNING
2013-08-09 12:24:41,619 INFO org.apache.hadoop.yarn.server.resourcemanager.rmcontainer.RMContainerImpl: container_1376050148932_0006_01_000002 Container Transitioned from NEW to ALLOCATED
2013-08-09 12:24:41,619 INFO org.apache.hadoop.yarn.server.resourcemanager.RMAuditLogger: USER=ubuntu	OPERATION=AM Allocated Container	TARGET=SchedulerApp	RESULT=SUCCESS	APPID=application_1376050148932_0006	CONTAINERID=container_1376050148932_0006_01_000002
2013-08-09 12:24:41,619 INFO org.apache.hadoop.yarn.server.resourcemanager.scheduler.common.fica.FiCaSchedulerNode: Assigned container container_1376050148932_0006_01_000002 of capacity <memory:1024, vCores:1> on host hadoop-210-5:60822, which currently has 2 containers, <memory:3072, vCores:2> used and <memory:5120, vCores:14> available
2013-08-09 12:24:41,620 INFO org.apache.hadoop.yarn.server.resourcemanager.scheduler.capacity.LeafQueue: assignedContainer application=application_1376050148932_0006 container=Container: [ContainerId: container_1376050148932_0006_01_000002, NodeId: hadoop-210-5:60822, NodeHttpAddress: hadoop-210-5:8042, Resource: <memory:1024, vCores:1>, Priority: 20, State: NEW, Token: null, Status: container_id {, app_attempt_id {, application_id {, id: 6, cluster_timestamp: 1376050148932, }, attemptId: 1, }, id: 2, }, state: C_NEW, ] containerId=container_1376050148932_0006_01_000002 queue=default: capacity=1.0, absoluteCapacity=1.0, usedResources=<memory:24576, vCores:19>usedCapacity=0.5, absoluteUsedCapacity=0.5, numApps=5, numContainers=19 usedCapacity=0.5 absoluteUsedCapacity=0.5 used=<memory:24576, vCores:19> cluster=<memory:49152, vCores:96>
2013-08-09 12:24:41,621 INFO org.apache.hadoop.yarn.server.resourcemanager.scheduler.capacity.ParentQueue: Re-sorting queues since queue: root.default stats: default: capacity=1.0, absoluteCapacity=1.0, usedResources=<memory:25600, vCores:20>usedCapacity=0.5208333, absoluteUsedCapacity=0.5208333, numApps=5, numContainers=20
2013-08-09 12:24:41,621 INFO org.apache.hadoop.yarn.server.resourcemanager.scheduler.capacity.ParentQueue: assignedContainer queue=root usedCapacity=0.5208333 absoluteUsedCapacity=0.5208333 used=<memory:25600, vCores:20> cluster=<memory:49152, vCores:96>
2013-08-09 12:24:41,621 INFO org.apache.hadoop.yarn.server.resourcemanager.rmcontainer.RMContainerImpl: container_1376050148932_0006_01_000003 Container Transitioned from NEW to ALLOCATED
2013-08-09 12:24:41,622 INFO org.apache.hadoop.yarn.server.resourcemanager.RMAuditLogger: USER=ubuntu	OPERATION=AM Allocated Container	TARGET=SchedulerApp	RESULT=SUCCESS	APPID=application_1376050148932_0006	CONTAINERID=container_1376050148932_0006_01_000003
2013-08-09 12:24:41,622 INFO org.apache.hadoop.yarn.server.resourcemanager.scheduler.common.fica.FiCaSchedulerNode: Assigned container container_1376050148932_0006_01_000003 of capacity <memory:1024, vCores:1> on host hadoop-210-5:60822, which currently has 3 containers, <memory:4096, vCores:3> used and <memory:4096, vCores:13> available
2013-08-09 12:24:41,623 INFO org.apache.hadoop.yarn.server.resourcemanager.scheduler.capacity.LeafQueue: assignedContainer application=application_1376050148932_0006 container=Container: [ContainerId: container_1376050148932_0006_01_000003, NodeId: hadoop-210-5:60822, NodeHttpAddress: hadoop-210-5:8042, Resource: <memory:1024, vCores:1>, Priority: 20, State: NEW, Token: null, Status: container_id {, app_attempt_id {, application_id {, id: 6, cluster_timestamp: 1376050148932, }, attemptId: 1, }, id: 3, }, state: C_NEW, ] containerId=container_1376050148932_0006_01_000003 queue=default: capacity=1.0, absoluteCapacity=1.0, usedResources=<memory:25600, vCores:20>usedCapacity=0.5208333, absoluteUsedCapacity=0.5208333, numApps=5, numContainers=20 usedCapacity=0.5208333 absoluteUsedCapacity=0.5208333 used=<memory:25600, vCores:20> cluster=<memory:49152, vCores:96>
2013-08-09 12:24:41,623 INFO org.apache.hadoop.yarn.server.resourcemanager.scheduler.capacity.ParentQueue: Re-sorting queues since queue: root.default stats: default: capacity=1.0, absoluteCapacity=1.0, usedResources=<memory:26624, vCores:21>usedCapacity=0.5416667, absoluteUsedCapacity=0.5416667, numApps=5, numContainers=21
2013-08-09 12:24:41,623 INFO org.apache.hadoop.yarn.server.resourcemanager.scheduler.capacity.ParentQueue: assignedContainer queue=root usedCapacity=0.5416667 absoluteUsedCapacity=0.5416667 used=<memory:26624, vCores:21> cluster=<memory:49152, vCores:96>
2013-08-09 12:24:41,624 INFO org.apache.hadoop.yarn.server.resourcemanager.rmcontainer.RMContainerImpl: container_1376050148932_0006_01_000004 Container Transitioned from NEW to ALLOCATED
2013-08-09 12:24:41,624 INFO org.apache.hadoop.yarn.server.resourcemanager.RMAuditLogger: USER=ubuntu	OPERATION=AM Allocated Container	TARGET=SchedulerApp	RESULT=SUCCESS	APPID=application_1376050148932_0006	CONTAINERID=container_1376050148932_0006_01_000004
2013-08-09 12:24:41,624 INFO org.apache.hadoop.yarn.server.resourcemanager.scheduler.common.fica.FiCaSchedulerNode: Assigned container container_1376050148932_0006_01_000004 of capacity <memory:1024, vCores:1> on host hadoop-210-5:60822, which currently has 4 containers, <memory:5120, vCores:4> used and <memory:3072, vCores:12> available
2013-08-09 12:24:41,625 INFO org.apache.hadoop.yarn.server.resourcemanager.scheduler.capacity.LeafQueue: assignedContainer application=application_1376050148932_0006 container=Container: [ContainerId: container_1376050148932_0006_01_000004, NodeId: hadoop-210-5:60822, NodeHttpAddress: hadoop-210-5:8042, Resource: <memory:1024, vCores:1>, Priority: 20, State: NEW, Token: null, Status: container_id {, app_attempt_id {, application_id {, id: 6, cluster_timestamp: 1376050148932, }, attemptId: 1, }, id: 4, }, state: C_NEW, ] containerId=container_1376050148932_0006_01_000004 queue=default: capacity=1.0, absoluteCapacity=1.0, usedResources=<memory:26624, vCores:21>usedCapacity=0.5416667, absoluteUsedCapacity=0.5416667, numApps=5, numContainers=21 usedCapacity=0.5416667 absoluteUsedCapacity=0.5416667 used=<memory:26624, vCores:21> cluster=<memory:49152, vCores:96>
2013-08-09 12:24:41,625 INFO org.apache.hadoop.yarn.server.resourcemanager.scheduler.capacity.ParentQueue: Re-sorting queues since queue: root.default stats: default: capacity=1.0, absoluteCapacity=1.0, usedResources=<memory:27648, vCores:22>usedCapacity=0.5625, absoluteUsedCapacity=0.5625, numApps=5, numContainers=22
2013-08-09 12:24:41,625 INFO org.apache.hadoop.yarn.server.resourcemanager.scheduler.capacity.ParentQueue: assignedContainer queue=root usedCapacity=0.5625 absoluteUsedCapacity=0.5625 used=<memory:27648, vCores:22> cluster=<memory:49152, vCores:96>
2013-08-09 12:24:41,626 INFO org.apache.hadoop.yarn.server.resourcemanager.rmcontainer.RMContainerImpl: container_1376050148932_0006_01_000005 Container Transitioned from NEW to ALLOCATED
2013-08-09 12:24:41,626 INFO org.apache.hadoop.yarn.server.resourcemanager.RMAuditLogger: USER=ubuntu	OPERATION=AM Allocated Container	TARGET=SchedulerApp	RESULT=SUCCESS	APPID=application_1376050148932_0006	CONTAINERID=container_1376050148932_0006_01_000005
2013-08-09 12:24:41,626 INFO org.apache.hadoop.yarn.server.resourcemanager.scheduler.common.fica.FiCaSchedulerNode: Assigned container container_1376050148932_0006_01_000005 of capacity <memory:1024, vCores:1> on host hadoop-210-5:60822, which currently has 5 containers, <memory:6144, vCores:5> used and <memory:2048, vCores:11> available
2013-08-09 12:24:41,627 INFO org.apache.hadoop.yarn.server.resourcemanager.scheduler.capacity.LeafQueue: assignedContainer application=application_1376050148932_0006 container=Container: [ContainerId: container_1376050148932_0006_01_000005, NodeId: hadoop-210-5:60822, NodeHttpAddress: hadoop-210-5:8042, Resource: <memory:1024, vCores:1>, Priority: 20, State: NEW, Token: null, Status: container_id {, app_attempt_id {, application_id {, id: 6, cluster_timestamp: 1376050148932, }, attemptId: 1, }, id: 5, }, state: C_NEW, ] containerId=container_1376050148932_0006_01_000005 queue=default: capacity=1.0, absoluteCapacity=1.0, usedResources=<memory:27648, vCores:22>usedCapacity=0.5625, absoluteUsedCapacity=0.5625, numApps=5, numContainers=22 usedCapacity=0.5625 absoluteUsedCapacity=0.5625 used=<memory:27648, vCores:22> cluster=<memory:49152, vCores:96>
2013-08-09 12:24:41,627 INFO org.apache.hadoop.yarn.server.resourcemanager.scheduler.capacity.ParentQueue: Re-sorting queues since queue: root.default stats: default: capacity=1.0, absoluteCapacity=1.0, usedResources=<memory:28672, vCores:23>usedCapacity=0.5833333, absoluteUsedCapacity=0.5833333, numApps=5, numContainers=23
2013-08-09 12:24:41,627 INFO org.apache.hadoop.yarn.server.resourcemanager.scheduler.capacity.ParentQueue: assignedContainer queue=root usedCapacity=0.5833333 absoluteUsedCapacity=0.5833333 used=<memory:28672, vCores:23> cluster=<memory:49152, vCores:96>
2013-08-09 12:24:41,628 INFO org.apache.hadoop.yarn.server.resourcemanager.rmcontainer.RMContainerImpl: container_1376050148932_0006_01_000006 Container Transitioned from NEW to ALLOCATED
2013-08-09 12:24:41,628 INFO org.apache.hadoop.yarn.server.resourcemanager.RMAuditLogger: USER=ubuntu	OPERATION=AM Allocated Container	TARGET=SchedulerApp	RESULT=SUCCESS	APPID=application_1376050148932_0006	CONTAINERID=container_1376050148932_0006_01_000006
2013-08-09 12:24:41,628 INFO org.apache.hadoop.yarn.server.resourcemanager.scheduler.common.fica.FiCaSchedulerNode: Assigned container container_1376050148932_0006_01_000006 of capacity <memory:1024, vCores:1> on host hadoop-210-5:60822, which currently has 6 containers, <memory:7168, vCores:6> used and <memory:1024, vCores:10> available
2013-08-09 12:24:41,629 INFO org.apache.hadoop.yarn.server.resourcemanager.scheduler.capacity.LeafQueue: assignedContainer application=application_1376050148932_0006 container=Container: [ContainerId: container_1376050148932_0006_01_000006, NodeId: hadoop-210-5:60822, NodeHttpAddress: hadoop-210-5:8042, Resource: <memory:1024, vCores:1>, Priority: 20, State: NEW, Token: null, Status: container_id {, app_attempt_id {, application_id {, id: 6, cluster_timestamp: 1376050148932, }, attemptId: 1, }, id: 6, }, state: C_NEW, ] containerId=container_1376050148932_0006_01_000006 queue=default: capacity=1.0, absoluteCapacity=1.0, usedResources=<memory:28672, vCores:23>usedCapacity=0.5833333, absoluteUsedCapacity=0.5833333, numApps=5, numContainers=23 usedCapacity=0.5833333 absoluteUsedCapacity=0.5833333 used=<memory:28672, vCores:23> cluster=<memory:49152, vCores:96>
2013-08-09 12:24:41,629 INFO org.apache.hadoop.yarn.server.resourcemanager.scheduler.capacity.ParentQueue: Re-sorting queues since queue: root.default stats: default: capacity=1.0, absoluteCapacity=1.0, usedResources=<memory:29696, vCores:24>usedCapacity=0.6041667, absoluteUsedCapacity=0.6041667, numApps=5, numContainers=24
2013-08-09 12:24:41,630 INFO org.apache.hadoop.yarn.server.resourcemanager.scheduler.capacity.ParentQueue: assignedContainer queue=root usedCapacity=0.6041667 absoluteUsedCapacity=0.6041667 used=<memory:29696, vCores:24> cluster=<memory:49152, vCores:96>
2013-08-09 12:24:41,630 INFO org.apache.hadoop.yarn.server.resourcemanager.rmcontainer.RMContainerImpl: container_1376050148932_0006_01_000007 Container Transitioned from NEW to ALLOCATED
2013-08-09 12:24:41,630 INFO org.apache.hadoop.yarn.server.resourcemanager.RMAuditLogger: USER=ubuntu	OPERATION=AM Allocated Container	TARGET=SchedulerApp	RESULT=SUCCESS	APPID=application_1376050148932_0006	CONTAINERID=container_1376050148932_0006_01_000007
2013-08-09 12:24:41,630 INFO org.apache.hadoop.yarn.server.resourcemanager.scheduler.common.fica.FiCaSchedulerNode: Assigned container container_1376050148932_0006_01_000007 of capacity <memory:1024, vCores:1> on host hadoop-210-5:60822, which currently has 7 containers, <memory:8192, vCores:7> used and <memory:0, vCores:9> available
2013-08-09 12:24:41,631 INFO org.apache.hadoop.yarn.server.resourcemanager.scheduler.capacity.LeafQueue: assignedContainer application=application_1376050148932_0006 container=Container: [ContainerId: container_1376050148932_0006_01_000007, NodeId: hadoop-210-5:60822, NodeHttpAddress: hadoop-210-5:8042, Resource: <memory:1024, vCores:1>, Priority: 20, State: NEW, Token: null, Status: container_id {, app_attempt_id {, application_id {, id: 6, cluster_timestamp: 1376050148932, }, attemptId: 1, }, id: 7, }, state: C_NEW, ] containerId=container_1376050148932_0006_01_000007 queue=default: capacity=1.0, absoluteCapacity=1.0, usedResources=<memory:29696, vCores:24>usedCapacity=0.6041667, absoluteUsedCapacity=0.6041667, numApps=5, numContainers=24 usedCapacity=0.6041667 absoluteUsedCapacity=0.6041667 used=<memory:29696, vCores:24> cluster=<memory:49152, vCores:96>
2013-08-09 12:24:41,631 INFO org.apache.hadoop.yarn.server.resourcemanager.scheduler.capacity.ParentQueue: Re-sorting queues since queue: root.default stats: default: capacity=1.0, absoluteCapacity=1.0, usedResources=<memory:30720, vCores:25>usedCapacity=0.625, absoluteUsedCapacity=0.625, numApps=5, numContainers=25
2013-08-09 12:24:41,632 INFO org.apache.hadoop.yarn.server.resourcemanager.scheduler.capacity.ParentQueue: assignedContainer queue=root usedCapacity=0.625 absoluteUsedCapacity=0.625 used=<memory:30720, vCores:25> cluster=<memory:49152, vCores:96>
2013-08-09 12:24:41,994 INFO org.apache.hadoop.yarn.server.resourcemanager.rmcontainer.RMContainerImpl: container_1376050148932_0006_01_000008 Container Transitioned from NEW to ALLOCATED
2013-08-09 12:24:41,994 INFO org.apache.hadoop.yarn.server.resourcemanager.RMAuditLogger: USER=ubuntu	OPERATION=AM Allocated Container	TARGET=SchedulerApp	RESULT=SUCCESS	APPID=application_1376050148932_0006	CONTAINERID=container_1376050148932_0006_01_000008
2013-08-09 12:24:41,994 INFO org.apache.hadoop.yarn.server.resourcemanager.scheduler.common.fica.FiCaSchedulerNode: Assigned container container_1376050148932_0006_01_000008 of capacity <memory:1024, vCores:1> on host hadoop-210-7:41457, which currently has 2 containers, <memory:3072, vCores:2> used and <memory:5120, vCores:14> available
2013-08-09 12:24:41,996 INFO org.apache.hadoop.yarn.server.resourcemanager.scheduler.capacity.LeafQueue: assignedContainer application=application_1376050148932_0006 container=Container: [ContainerId: container_1376050148932_0006_01_000008, NodeId: hadoop-210-7:41457, NodeHttpAddress: hadoop-210-7:8042, Resource: <memory:1024, vCores:1>, Priority: 20, State: NEW, Token: null, Status: container_id {, app_attempt_id {, application_id {, id: 6, cluster_timestamp: 1376050148932, }, attemptId: 1, }, id: 8, }, state: C_NEW, ] containerId=container_1376050148932_0006_01_000008 queue=default: capacity=1.0, absoluteCapacity=1.0, usedResources=<memory:30720, vCores:25>usedCapacity=0.625, absoluteUsedCapacity=0.625, numApps=5, numContainers=25 usedCapacity=0.625 absoluteUsedCapacity=0.625 used=<memory:30720, vCores:25> cluster=<memory:49152, vCores:96>
2013-08-09 12:24:41,996 INFO org.apache.hadoop.yarn.server.resourcemanager.scheduler.capacity.ParentQueue: Re-sorting queues since queue: root.default stats: default: capacity=1.0, absoluteCapacity=1.0, usedResources=<memory:31744, vCores:26>usedCapacity=0.6458333, absoluteUsedCapacity=0.6458333, numApps=5, numContainers=26
2013-08-09 12:24:41,996 INFO org.apache.hadoop.yarn.server.resourcemanager.scheduler.capacity.ParentQueue: assignedContainer queue=root usedCapacity=0.6458333 absoluteUsedCapacity=0.6458333 used=<memory:31744, vCores:26> cluster=<memory:49152, vCores:96>
2013-08-09 12:24:41,996 INFO org.apache.hadoop.yarn.server.resourcemanager.rmcontainer.RMContainerImpl: container_1376050148932_0006_01_000009 Container Transitioned from NEW to ALLOCATED
2013-08-09 12:24:41,997 INFO org.apache.hadoop.yarn.server.resourcemanager.RMAuditLogger: USER=ubuntu	OPERATION=AM Allocated Container	TARGET=SchedulerApp	RESULT=SUCCESS	APPID=application_1376050148932_0006	CONTAINERID=container_1376050148932_0006_01_000009
2013-08-09 12:24:41,997 INFO org.apache.hadoop.yarn.server.resourcemanager.scheduler.common.fica.FiCaSchedulerNode: Assigned container container_1376050148932_0006_01_000009 of capacity <memory:1024, vCores:1> on host hadoop-210-7:41457, which currently has 3 containers, <memory:4096, vCores:3> used and <memory:4096, vCores:13> available
2013-08-09 12:24:41,998 INFO org.apache.hadoop.yarn.server.resourcemanager.scheduler.capacity.LeafQueue: assignedContainer application=application_1376050148932_0006 container=Container: [ContainerId: container_1376050148932_0006_01_000009, NodeId: hadoop-210-7:41457, NodeHttpAddress: hadoop-210-7:8042, Resource: <memory:1024, vCores:1>, Priority: 20, State: NEW, Token: null, Status: container_id {, app_attempt_id {, application_id {, id: 6, cluster_timestamp: 1376050148932, }, attemptId: 1, }, id: 9, }, state: C_NEW, ] containerId=container_1376050148932_0006_01_000009 queue=default: capacity=1.0, absoluteCapacity=1.0, usedResources=<memory:31744, vCores:26>usedCapacity=0.6458333, absoluteUsedCapacity=0.6458333, numApps=5, numContainers=26 usedCapacity=0.6458333 absoluteUsedCapacity=0.6458333 used=<memory:31744, vCores:26> cluster=<memory:49152, vCores:96>
2013-08-09 12:24:41,998 INFO org.apache.hadoop.yarn.server.resourcemanager.scheduler.capacity.ParentQueue: Re-sorting queues since queue: root.default stats: default: capacity=1.0, absoluteCapacity=1.0, usedResources=<memory:32768, vCores:27>usedCapacity=0.6666667, absoluteUsedCapacity=0.6666667, numApps=5, numContainers=27
2013-08-09 12:24:41,998 INFO org.apache.hadoop.yarn.server.resourcemanager.scheduler.capacity.ParentQueue: assignedContainer queue=root usedCapacity=0.6666667 absoluteUsedCapacity=0.6666667 used=<memory:32768, vCores:27> cluster=<memory:49152, vCores:96>
2013-08-09 12:24:41,999 INFO org.apache.hadoop.yarn.server.resourcemanager.rmcontainer.RMContainerImpl: container_1376050148932_0006_01_000010 Container Transitioned from NEW to ALLOCATED
2013-08-09 12:24:41,999 INFO org.apache.hadoop.yarn.server.resourcemanager.RMAuditLogger: USER=ubuntu	OPERATION=AM Allocated Container	TARGET=SchedulerApp	RESULT=SUCCESS	APPID=application_1376050148932_0006	CONTAINERID=container_1376050148932_0006_01_000010
2013-08-09 12:24:41,999 INFO org.apache.hadoop.yarn.server.resourcemanager.scheduler.common.fica.FiCaSchedulerNode: Assigned container container_1376050148932_0006_01_000010 of capacity <memory:1024, vCores:1> on host hadoop-210-7:41457, which currently has 4 containers, <memory:5120, vCores:4> used and <memory:3072, vCores:12> available
2013-08-09 12:24:42,000 INFO org.apache.hadoop.yarn.server.resourcemanager.scheduler.capacity.LeafQueue: assignedContainer application=application_1376050148932_0006 container=Container: [ContainerId: container_1376050148932_0006_01_000010, NodeId: hadoop-210-7:41457, NodeHttpAddress: hadoop-210-7:8042, Resource: <memory:1024, vCores:1>, Priority: 20, State: NEW, Token: null, Status: container_id {, app_attempt_id {, application_id {, id: 6, cluster_timestamp: 1376050148932, }, attemptId: 1, }, id: 10, }, state: C_NEW, ] containerId=container_1376050148932_0006_01_000010 queue=default: capacity=1.0, absoluteCapacity=1.0, usedResources=<memory:32768, vCores:27>usedCapacity=0.6666667, absoluteUsedCapacity=0.6666667, numApps=5, numContainers=27 usedCapacity=0.6666667 absoluteUsedCapacity=0.6666667 used=<memory:32768, vCores:27> cluster=<memory:49152, vCores:96>
2013-08-09 12:24:42,000 INFO org.apache.hadoop.yarn.server.resourcemanager.scheduler.capacity.ParentQueue: Re-sorting queues since queue: root.default stats: default: capacity=1.0, absoluteCapacity=1.0, usedResources=<memory:33792, vCores:28>usedCapacity=0.6875, absoluteUsedCapacity=0.6875, numApps=5, numContainers=28
2013-08-09 12:24:42,001 INFO org.apache.hadoop.yarn.server.resourcemanager.scheduler.capacity.ParentQueue: assignedContainer queue=root usedCapacity=0.6875 absoluteUsedCapacity=0.6875 used=<memory:33792, vCores:28> cluster=<memory:49152, vCores:96>
2013-08-09 12:24:42,001 INFO org.apache.hadoop.yarn.server.resourcemanager.rmcontainer.RMContainerImpl: container_1376050148932_0006_01_000011 Container Transitioned from NEW to ALLOCATED
2013-08-09 12:24:42,001 INFO org.apache.hadoop.yarn.server.resourcemanager.RMAuditLogger: USER=ubuntu	OPERATION=AM Allocated Container	TARGET=SchedulerApp	RESULT=SUCCESS	APPID=application_1376050148932_0006	CONTAINERID=container_1376050148932_0006_01_000011
2013-08-09 12:24:42,004 INFO org.apache.hadoop.yarn.server.resourcemanager.scheduler.common.fica.FiCaSchedulerNode: Assigned container container_1376050148932_0006_01_000011 of capacity <memory:1024, vCores:1> on host hadoop-210-7:41457, which currently has 5 containers, <memory:6144, vCores:5> used and <memory:2048, vCores:11> available
2013-08-09 12:24:42,005 INFO org.apache.hadoop.yarn.server.resourcemanager.scheduler.capacity.LeafQueue: assignedContainer application=application_1376050148932_0006 container=Container: [ContainerId: container_1376050148932_0006_01_000011, NodeId: hadoop-210-7:41457, NodeHttpAddress: hadoop-210-7:8042, Resource: <memory:1024, vCores:1>, Priority: 20, State: NEW, Token: null, Status: container_id {, app_attempt_id {, application_id {, id: 6, cluster_timestamp: 1376050148932, }, attemptId: 1, }, id: 11, }, state: C_NEW, ] containerId=container_1376050148932_0006_01_000011 queue=default: capacity=1.0, absoluteCapacity=1.0, usedResources=<memory:33792, vCores:28>usedCapacity=0.6875, absoluteUsedCapacity=0.6875, numApps=5, numContainers=28 usedCapacity=0.6875 absoluteUsedCapacity=0.6875 used=<memory:33792, vCores:28> cluster=<memory:49152, vCores:96>
2013-08-09 12:24:42,005 INFO org.apache.hadoop.yarn.server.resourcemanager.scheduler.capacity.ParentQueue: Re-sorting queues since queue: root.default stats: default: capacity=1.0, absoluteCapacity=1.0, usedResources=<memory:34816, vCores:29>usedCapacity=0.7083333, absoluteUsedCapacity=0.7083333, numApps=5, numContainers=29
2013-08-09 12:24:42,005 INFO org.apache.hadoop.yarn.server.resourcemanager.scheduler.capacity.ParentQueue: assignedContainer queue=root usedCapacity=0.7083333 absoluteUsedCapacity=0.7083333 used=<memory:34816, vCores:29> cluster=<memory:49152, vCores:96>
2013-08-09 12:24:42,006 INFO org.apache.hadoop.yarn.server.resourcemanager.rmcontainer.RMContainerImpl: container_1376050148932_0006_01_000012 Container Transitioned from NEW to ALLOCATED
2013-08-09 12:24:42,006 INFO org.apache.hadoop.yarn.server.resourcemanager.RMAuditLogger: USER=ubuntu	OPERATION=AM Allocated Container	TARGET=SchedulerApp	RESULT=SUCCESS	APPID=application_1376050148932_0006	CONTAINERID=container_1376050148932_0006_01_000012
2013-08-09 12:24:42,006 INFO org.apache.hadoop.yarn.server.resourcemanager.scheduler.common.fica.FiCaSchedulerNode: Assigned container container_1376050148932_0006_01_000012 of capacity <memory:1024, vCores:1> on host hadoop-210-7:41457, which currently has 6 containers, <memory:7168, vCores:6> used and <memory:1024, vCores:10> available
2013-08-09 12:24:42,007 INFO org.apache.hadoop.yarn.server.resourcemanager.scheduler.capacity.LeafQueue: assignedContainer application=application_1376050148932_0006 container=Container: [ContainerId: container_1376050148932_0006_01_000012, NodeId: hadoop-210-7:41457, NodeHttpAddress: hadoop-210-7:8042, Resource: <memory:1024, vCores:1>, Priority: 20, State: NEW, Token: null, Status: container_id {, app_attempt_id {, application_id {, id: 6, cluster_timestamp: 1376050148932, }, attemptId: 1, }, id: 12, }, state: C_NEW, ] containerId=container_1376050148932_0006_01_000012 queue=default: capacity=1.0, absoluteCapacity=1.0, usedResources=<memory:34816, vCores:29>usedCapacity=0.7083333, absoluteUsedCapacity=0.7083333, numApps=5, numContainers=29 usedCapacity=0.7083333 absoluteUsedCapacity=0.7083333 used=<memory:34816, vCores:29> cluster=<memory:49152, vCores:96>
2013-08-09 12:24:42,007 INFO org.apache.hadoop.yarn.server.resourcemanager.scheduler.capacity.ParentQueue: Re-sorting queues since queue: root.default stats: default: capacity=1.0, absoluteCapacity=1.0, usedResources=<memory:35840, vCores:30>usedCapacity=0.7291667, absoluteUsedCapacity=0.7291667, numApps=5, numContainers=30
2013-08-09 12:24:42,011 INFO org.apache.hadoop.yarn.server.resourcemanager.scheduler.capacity.ParentQueue: assignedContainer queue=root usedCapacity=0.7291667 absoluteUsedCapacity=0.7291667 used=<memory:35840, vCores:30> cluster=<memory:49152, vCores:96>
2013-08-09 12:24:42,012 INFO org.apache.hadoop.yarn.server.resourcemanager.rmcontainer.RMContainerImpl: container_1376050148932_0006_01_000013 Container Transitioned from NEW to ALLOCATED
2013-08-09 12:24:42,012 INFO org.apache.hadoop.yarn.server.resourcemanager.RMAuditLogger: USER=ubuntu	OPERATION=AM Allocated Container	TARGET=SchedulerApp	RESULT=SUCCESS	APPID=application_1376050148932_0006	CONTAINERID=container_1376050148932_0006_01_000013
2013-08-09 12:24:42,012 INFO org.apache.hadoop.yarn.server.resourcemanager.scheduler.common.fica.FiCaSchedulerNode: Assigned container container_1376050148932_0006_01_000013 of capacity <memory:1024, vCores:1> on host hadoop-210-7:41457, which currently has 7 containers, <memory:8192, vCores:7> used and <memory:0, vCores:9> available
2013-08-09 12:24:42,013 INFO org.apache.hadoop.yarn.server.resourcemanager.scheduler.capacity.LeafQueue: assignedContainer application=application_1376050148932_0006 container=Container: [ContainerId: container_1376050148932_0006_01_000013, NodeId: hadoop-210-7:41457, NodeHttpAddress: hadoop-210-7:8042, Resource: <memory:1024, vCores:1>, Priority: 20, State: NEW, Token: null, Status: container_id {, app_attempt_id {, application_id {, id: 6, cluster_timestamp: 1376050148932, }, attemptId: 1, }, id: 13, }, state: C_NEW, ] containerId=container_1376050148932_0006_01_000013 queue=default: capacity=1.0, absoluteCapacity=1.0, usedResources=<memory:35840, vCores:30>usedCapacity=0.7291667, absoluteUsedCapacity=0.7291667, numApps=5, numContainers=30 usedCapacity=0.7291667 absoluteUsedCapacity=0.7291667 used=<memory:35840, vCores:30> cluster=<memory:49152, vCores:96>
2013-08-09 12:24:42,013 INFO org.apache.hadoop.yarn.server.resourcemanager.scheduler.capacity.ParentQueue: Re-sorting queues since queue: root.default stats: default: capacity=1.0, absoluteCapacity=1.0, usedResources=<memory:36864, vCores:31>usedCapacity=0.75, absoluteUsedCapacity=0.75, numApps=5, numContainers=31
2013-08-09 12:24:42,013 INFO org.apache.hadoop.yarn.server.resourcemanager.scheduler.capacity.ParentQueue: assignedContainer queue=root usedCapacity=0.75 absoluteUsedCapacity=0.75 used=<memory:36864, vCores:31> cluster=<memory:49152, vCores:96>
2013-08-09 12:24:42,036 INFO org.apache.hadoop.yarn.server.resourcemanager.rmcontainer.RMContainerImpl: container_1376050148932_0006_01_000014 Container Transitioned from NEW to ALLOCATED
2013-08-09 12:24:42,037 INFO org.apache.hadoop.yarn.server.resourcemanager.RMAuditLogger: USER=ubuntu	OPERATION=AM Allocated Container	TARGET=SchedulerApp	RESULT=SUCCESS	APPID=application_1376050148932_0006	CONTAINERID=container_1376050148932_0006_01_000014
2013-08-09 12:24:42,037 INFO org.apache.hadoop.yarn.server.resourcemanager.scheduler.common.fica.FiCaSchedulerNode: Assigned container container_1376050148932_0006_01_000014 of capacity <memory:1024, vCores:1> on host hadoop-210-3:36255, which currently has 2 containers, <memory:3072, vCores:2> used and <memory:5120, vCores:14> available
2013-08-09 12:24:42,038 INFO org.apache.hadoop.yarn.server.resourcemanager.scheduler.capacity.LeafQueue: assignedContainer application=application_1376050148932_0006 container=Container: [ContainerId: container_1376050148932_0006_01_000014, NodeId: hadoop-210-3:36255, NodeHttpAddress: hadoop-210-3:8042, Resource: <memory:1024, vCores:1>, Priority: 20, State: NEW, Token: null, Status: container_id {, app_attempt_id {, application_id {, id: 6, cluster_timestamp: 1376050148932, }, attemptId: 1, }, id: 14, }, state: C_NEW, ] containerId=container_1376050148932_0006_01_000014 queue=default: capacity=1.0, absoluteCapacity=1.0, usedResources=<memory:36864, vCores:31>usedCapacity=0.75, absoluteUsedCapacity=0.75, numApps=5, numContainers=31 usedCapacity=0.75 absoluteUsedCapacity=0.75 used=<memory:36864, vCores:31> cluster=<memory:49152, vCores:96>
2013-08-09 12:24:42,038 INFO org.apache.hadoop.yarn.server.resourcemanager.scheduler.capacity.ParentQueue: Re-sorting queues since queue: root.default stats: default: capacity=1.0, absoluteCapacity=1.0, usedResources=<memory:37888, vCores:32>usedCapacity=0.7708333, absoluteUsedCapacity=0.7708333, numApps=5, numContainers=32
2013-08-09 12:24:42,038 INFO org.apache.hadoop.yarn.server.resourcemanager.scheduler.capacity.ParentQueue: assignedContainer queue=root usedCapacity=0.7708333 absoluteUsedCapacity=0.7708333 used=<memory:37888, vCores:32> cluster=<memory:49152, vCores:96>
2013-08-09 12:24:42,039 INFO org.apache.hadoop.yarn.server.resourcemanager.rmcontainer.RMContainerImpl: container_1376050148932_0006_01_000015 Container Transitioned from NEW to ALLOCATED
2013-08-09 12:24:42,039 INFO org.apache.hadoop.yarn.server.resourcemanager.RMAuditLogger: USER=ubuntu	OPERATION=AM Allocated Container	TARGET=SchedulerApp	RESULT=SUCCESS	APPID=application_1376050148932_0006	CONTAINERID=container_1376050148932_0006_01_000015
2013-08-09 12:24:42,039 INFO org.apache.hadoop.yarn.server.resourcemanager.scheduler.common.fica.FiCaSchedulerNode: Assigned container container_1376050148932_0006_01_000015 of capacity <memory:1024, vCores:1> on host hadoop-210-3:36255, which currently has 3 containers, <memory:4096, vCores:3> used and <memory:4096, vCores:13> available
2013-08-09 12:24:42,040 INFO org.apache.hadoop.yarn.server.resourcemanager.scheduler.capacity.LeafQueue: assignedContainer application=application_1376050148932_0006 container=Container: [ContainerId: container_1376050148932_0006_01_000015, NodeId: hadoop-210-3:36255, NodeHttpAddress: hadoop-210-3:8042, Resource: <memory:1024, vCores:1>, Priority: 20, State: NEW, Token: null, Status: container_id {, app_attempt_id {, application_id {, id: 6, cluster_timestamp: 1376050148932, }, attemptId: 1, }, id: 15, }, state: C_NEW, ] containerId=container_1376050148932_0006_01_000015 queue=default: capacity=1.0, absoluteCapacity=1.0, usedResources=<memory:37888, vCores:32>usedCapacity=0.7708333, absoluteUsedCapacity=0.7708333, numApps=5, numContainers=32 usedCapacity=0.7708333 absoluteUsedCapacity=0.7708333 used=<memory:37888, vCores:32> cluster=<memory:49152, vCores:96>
2013-08-09 12:24:42,040 INFO org.apache.hadoop.yarn.server.resourcemanager.scheduler.capacity.ParentQueue: Re-sorting queues since queue: root.default stats: default: capacity=1.0, absoluteCapacity=1.0, usedResources=<memory:38912, vCores:33>usedCapacity=0.7916667, absoluteUsedCapacity=0.7916667, numApps=5, numContainers=33
2013-08-09 12:24:42,040 INFO org.apache.hadoop.yarn.server.resourcemanager.scheduler.capacity.ParentQueue: assignedContainer queue=root usedCapacity=0.7916667 absoluteUsedCapacity=0.7916667 used=<memory:38912, vCores:33> cluster=<memory:49152, vCores:96>
2013-08-09 12:24:42,041 INFO org.apache.hadoop.yarn.server.resourcemanager.rmcontainer.RMContainerImpl: container_1376050148932_0006_01_000016 Container Transitioned from NEW to ALLOCATED
2013-08-09 12:24:42,041 INFO org.apache.hadoop.yarn.server.resourcemanager.RMAuditLogger: USER=ubuntu	OPERATION=AM Allocated Container	TARGET=SchedulerApp	RESULT=SUCCESS	APPID=application_1376050148932_0006	CONTAINERID=container_1376050148932_0006_01_000016
2013-08-09 12:24:42,041 INFO org.apache.hadoop.yarn.server.resourcemanager.scheduler.common.fica.FiCaSchedulerNode: Assigned container container_1376050148932_0006_01_000016 of capacity <memory:1024, vCores:1> on host hadoop-210-3:36255, which currently has 4 containers, <memory:5120, vCores:4> used and <memory:3072, vCores:12> available
2013-08-09 12:24:42,042 INFO org.apache.hadoop.yarn.server.resourcemanager.scheduler.capacity.LeafQueue: assignedContainer application=application_1376050148932_0006 container=Container: [ContainerId: container_1376050148932_0006_01_000016, NodeId: hadoop-210-3:36255, NodeHttpAddress: hadoop-210-3:8042, Resource: <memory:1024, vCores:1>, Priority: 20, State: NEW, Token: null, Status: container_id {, app_attempt_id {, application_id {, id: 6, cluster_timestamp: 1376050148932, }, attemptId: 1, }, id: 16, }, state: C_NEW, ] containerId=container_1376050148932_0006_01_000016 queue=default: capacity=1.0, absoluteCapacity=1.0, usedResources=<memory:38912, vCores:33>usedCapacity=0.7916667, absoluteUsedCapacity=0.7916667, numApps=5, numContainers=33 usedCapacity=0.7916667 absoluteUsedCapacity=0.7916667 used=<memory:38912, vCores:33> cluster=<memory:49152, vCores:96>
2013-08-09 12:24:42,042 INFO org.apache.hadoop.yarn.server.resourcemanager.scheduler.capacity.ParentQueue: Re-sorting queues since queue: root.default stats: default: capacity=1.0, absoluteCapacity=1.0, usedResources=<memory:39936, vCores:34>usedCapacity=0.8125, absoluteUsedCapacity=0.8125, numApps=5, numContainers=34
2013-08-09 12:24:42,042 INFO org.apache.hadoop.yarn.server.resourcemanager.scheduler.capacity.ParentQueue: assignedContainer queue=root usedCapacity=0.8125 absoluteUsedCapacity=0.8125 used=<memory:39936, vCores:34> cluster=<memory:49152, vCores:96>
2013-08-09 12:24:42,043 INFO org.apache.hadoop.yarn.server.resourcemanager.rmcontainer.RMContainerImpl: container_1376050148932_0006_01_000017 Container Transitioned from NEW to ALLOCATED
2013-08-09 12:24:42,043 INFO org.apache.hadoop.yarn.server.resourcemanager.RMAuditLogger: USER=ubuntu	OPERATION=AM Allocated Container	TARGET=SchedulerApp	RESULT=SUCCESS	APPID=application_1376050148932_0006	CONTAINERID=container_1376050148932_0006_01_000017
2013-08-09 12:24:42,043 INFO org.apache.hadoop.yarn.server.resourcemanager.scheduler.common.fica.FiCaSchedulerNode: Assigned container container_1376050148932_0006_01_000017 of capacity <memory:1024, vCores:1> on host hadoop-210-3:36255, which currently has 5 containers, <memory:6144, vCores:5> used and <memory:2048, vCores:11> available
2013-08-09 12:24:42,044 INFO org.apache.hadoop.yarn.server.resourcemanager.scheduler.capacity.LeafQueue: assignedContainer application=application_1376050148932_0006 container=Container: [ContainerId: container_1376050148932_0006_01_000017, NodeId: hadoop-210-3:36255, NodeHttpAddress: hadoop-210-3:8042, Resource: <memory:1024, vCores:1>, Priority: 20, State: NEW, Token: null, Status: container_id {, app_attempt_id {, application_id {, id: 6, cluster_timestamp: 1376050148932, }, attemptId: 1, }, id: 17, }, state: C_NEW, ] containerId=container_1376050148932_0006_01_000017 queue=default: capacity=1.0, absoluteCapacity=1.0, usedResources=<memory:39936, vCores:34>usedCapacity=0.8125, absoluteUsedCapacity=0.8125, numApps=5, numContainers=34 usedCapacity=0.8125 absoluteUsedCapacity=0.8125 used=<memory:39936, vCores:34> cluster=<memory:49152, vCores:96>
2013-08-09 12:24:42,044 INFO org.apache.hadoop.yarn.server.resourcemanager.scheduler.capacity.ParentQueue: Re-sorting queues since queue: root.default stats: default: capacity=1.0, absoluteCapacity=1.0, usedResources=<memory:40960, vCores:35>usedCapacity=0.8333333, absoluteUsedCapacity=0.8333333, numApps=5, numContainers=35
2013-08-09 12:24:42,044 INFO org.apache.hadoop.yarn.server.resourcemanager.scheduler.capacity.ParentQueue: assignedContainer queue=root usedCapacity=0.8333333 absoluteUsedCapacity=0.8333333 used=<memory:40960, vCores:35> cluster=<memory:49152, vCores:96>
2013-08-09 12:24:42,045 INFO org.apache.hadoop.yarn.server.resourcemanager.rmcontainer.RMContainerImpl: container_1376050148932_0006_01_000018 Container Transitioned from NEW to ALLOCATED
2013-08-09 12:24:42,045 INFO org.apache.hadoop.yarn.server.resourcemanager.RMAuditLogger: USER=ubuntu	OPERATION=AM Allocated Container	TARGET=SchedulerApp	RESULT=SUCCESS	APPID=application_1376050148932_0006	CONTAINERID=container_1376050148932_0006_01_000018
2013-08-09 12:24:42,045 INFO org.apache.hadoop.yarn.server.resourcemanager.scheduler.common.fica.FiCaSchedulerNode: Assigned container container_1376050148932_0006_01_000018 of capacity <memory:1024, vCores:1> on host hadoop-210-3:36255, which currently has 6 containers, <memory:7168, vCores:6> used and <memory:1024, vCores:10> available
2013-08-09 12:24:42,046 INFO org.apache.hadoop.yarn.server.resourcemanager.scheduler.capacity.LeafQueue: assignedContainer application=application_1376050148932_0006 container=Container: [ContainerId: container_1376050148932_0006_01_000018, NodeId: hadoop-210-3:36255, NodeHttpAddress: hadoop-210-3:8042, Resource: <memory:1024, vCores:1>, Priority: 20, State: NEW, Token: null, Status: container_id {, app_attempt_id {, application_id {, id: 6, cluster_timestamp: 1376050148932, }, attemptId: 1, }, id: 18, }, state: C_NEW, ] containerId=container_1376050148932_0006_01_000018 queue=default: capacity=1.0, absoluteCapacity=1.0, usedResources=<memory:40960, vCores:35>usedCapacity=0.8333333, absoluteUsedCapacity=0.8333333, numApps=5, numContainers=35 usedCapacity=0.8333333 absoluteUsedCapacity=0.8333333 used=<memory:40960, vCores:35> cluster=<memory:49152, vCores:96>
2013-08-09 12:24:42,046 INFO org.apache.hadoop.yarn.server.resourcemanager.scheduler.capacity.ParentQueue: Re-sorting queues since queue: root.default stats: default: capacity=1.0, absoluteCapacity=1.0, usedResources=<memory:41984, vCores:36>usedCapacity=0.8541667, absoluteUsedCapacity=0.8541667, numApps=5, numContainers=36
2013-08-09 12:24:42,046 INFO org.apache.hadoop.yarn.server.resourcemanager.scheduler.capacity.ParentQueue: assignedContainer queue=root usedCapacity=0.8541667 absoluteUsedCapacity=0.8541667 used=<memory:41984, vCores:36> cluster=<memory:49152, vCores:96>
2013-08-09 12:24:42,047 INFO org.apache.hadoop.yarn.server.resourcemanager.rmcontainer.RMContainerImpl: container_1376050148932_0006_01_000019 Container Transitioned from NEW to ALLOCATED
2013-08-09 12:24:42,047 INFO org.apache.hadoop.yarn.server.resourcemanager.RMAuditLogger: USER=ubuntu	OPERATION=AM Allocated Container	TARGET=SchedulerApp	RESULT=SUCCESS	APPID=application_1376050148932_0006	CONTAINERID=container_1376050148932_0006_01_000019
2013-08-09 12:24:42,047 INFO org.apache.hadoop.yarn.server.resourcemanager.scheduler.common.fica.FiCaSchedulerNode: Assigned container container_1376050148932_0006_01_000019 of capacity <memory:1024, vCores:1> on host hadoop-210-3:36255, which currently has 7 containers, <memory:8192, vCores:7> used and <memory:0, vCores:9> available
2013-08-09 12:24:42,048 INFO org.apache.hadoop.yarn.server.resourcemanager.scheduler.capacity.LeafQueue: assignedContainer application=application_1376050148932_0006 container=Container: [ContainerId: container_1376050148932_0006_01_000019, NodeId: hadoop-210-3:36255, NodeHttpAddress: hadoop-210-3:8042, Resource: <memory:1024, vCores:1>, Priority: 20, State: NEW, Token: null, Status: container_id {, app_attempt_id {, application_id {, id: 6, cluster_timestamp: 1376050148932, }, attemptId: 1, }, id: 19, }, state: C_NEW, ] containerId=container_1376050148932_0006_01_000019 queue=default: capacity=1.0, absoluteCapacity=1.0, usedResources=<memory:41984, vCores:36>usedCapacity=0.8541667, absoluteUsedCapacity=0.8541667, numApps=5, numContainers=36 usedCapacity=0.8541667 absoluteUsedCapacity=0.8541667 used=<memory:41984, vCores:36> cluster=<memory:49152, vCores:96>
2013-08-09 12:24:42,048 INFO org.apache.hadoop.yarn.server.resourcemanager.scheduler.capacity.ParentQueue: Re-sorting queues since queue: root.default stats: default: capacity=1.0, absoluteCapacity=1.0, usedResources=<memory:43008, vCores:37>usedCapacity=0.875, absoluteUsedCapacity=0.875, numApps=5, numContainers=37
2013-08-09 12:24:42,049 INFO org.apache.hadoop.yarn.server.resourcemanager.scheduler.capacity.ParentQueue: assignedContainer queue=root usedCapacity=0.875 absoluteUsedCapacity=0.875 used=<memory:43008, vCores:37> cluster=<memory:49152, vCores:96>
2013-08-09 12:24:42,052 INFO org.apache.hadoop.yarn.server.resourcemanager.rmcontainer.RMContainerImpl: container_1376050148932_0006_01_000020 Container Transitioned from NEW to ALLOCATED
2013-08-09 12:24:42,052 INFO org.apache.hadoop.yarn.server.resourcemanager.RMAuditLogger: USER=ubuntu	OPERATION=AM Allocated Container	TARGET=SchedulerApp	RESULT=SUCCESS	APPID=application_1376050148932_0006	CONTAINERID=container_1376050148932_0006_01_000020
2013-08-09 12:24:42,052 INFO org.apache.hadoop.yarn.server.resourcemanager.scheduler.common.fica.FiCaSchedulerNode: Assigned container container_1376050148932_0006_01_000020 of capacity <memory:1024, vCores:1> on host hadoop-210-2:40150, which currently has 2 containers, <memory:3072, vCores:2> used and <memory:5120, vCores:14> available
2013-08-09 12:24:42,053 INFO org.apache.hadoop.yarn.server.resourcemanager.scheduler.capacity.LeafQueue: assignedContainer application=application_1376050148932_0006 container=Container: [ContainerId: container_1376050148932_0006_01_000020, NodeId: hadoop-210-2:40150, NodeHttpAddress: hadoop-210-2:8042, Resource: <memory:1024, vCores:1>, Priority: 20, State: NEW, Token: null, Status: container_id {, app_attempt_id {, application_id {, id: 6, cluster_timestamp: 1376050148932, }, attemptId: 1, }, id: 20, }, state: C_NEW, ] containerId=container_1376050148932_0006_01_000020 queue=default: capacity=1.0, absoluteCapacity=1.0, usedResources=<memory:43008, vCores:37>usedCapacity=0.875, absoluteUsedCapacity=0.875, numApps=5, numContainers=37 usedCapacity=0.875 absoluteUsedCapacity=0.875 used=<memory:43008, vCores:37> cluster=<memory:49152, vCores:96>
2013-08-09 12:24:42,054 INFO org.apache.hadoop.yarn.server.resourcemanager.scheduler.capacity.ParentQueue: Re-sorting queues since queue: root.default stats: default: capacity=1.0, absoluteCapacity=1.0, usedResources=<memory:44032, vCores:38>usedCapacity=0.8958333, absoluteUsedCapacity=0.8958333, numApps=5, numContainers=38
2013-08-09 12:24:42,054 INFO org.apache.hadoop.yarn.server.resourcemanager.scheduler.capacity.ParentQueue: assignedContainer queue=root usedCapacity=0.8958333 absoluteUsedCapacity=0.8958333 used=<memory:44032, vCores:38> cluster=<memory:49152, vCores:96>
2013-08-09 12:24:42,054 INFO org.apache.hadoop.yarn.server.resourcemanager.rmcontainer.RMContainerImpl: container_1376050148932_0006_01_000021 Container Transitioned from NEW to ALLOCATED
2013-08-09 12:24:42,054 INFO org.apache.hadoop.yarn.server.resourcemanager.RMAuditLogger: USER=ubuntu	OPERATION=AM Allocated Container	TARGET=SchedulerApp	RESULT=SUCCESS	APPID=application_1376050148932_0006	CONTAINERID=container_1376050148932_0006_01_000021
2013-08-09 12:24:42,055 INFO org.apache.hadoop.yarn.server.resourcemanager.scheduler.common.fica.FiCaSchedulerNode: Assigned container container_1376050148932_0006_01_000021 of capacity <memory:1024, vCores:1> on host hadoop-210-2:40150, which currently has 3 containers, <memory:4096, vCores:3> used and <memory:4096, vCores:13> available
2013-08-09 12:24:42,056 INFO org.apache.hadoop.yarn.server.resourcemanager.scheduler.capacity.LeafQueue: assignedContainer application=application_1376050148932_0006 container=Container: [ContainerId: container_1376050148932_0006_01_000021, NodeId: hadoop-210-2:40150, NodeHttpAddress: hadoop-210-2:8042, Resource: <memory:1024, vCores:1>, Priority: 20, State: NEW, Token: null, Status: container_id {, app_attempt_id {, application_id {, id: 6, cluster_timestamp: 1376050148932, }, attemptId: 1, }, id: 21, }, state: C_NEW, ] containerId=container_1376050148932_0006_01_000021 queue=default: capacity=1.0, absoluteCapacity=1.0, usedResources=<memory:44032, vCores:38>usedCapacity=0.8958333, absoluteUsedCapacity=0.8958333, numApps=5, numContainers=38 usedCapacity=0.8958333 absoluteUsedCapacity=0.8958333 used=<memory:44032, vCores:38> cluster=<memory:49152, vCores:96>
2013-08-09 12:24:42,056 INFO org.apache.hadoop.yarn.server.resourcemanager.scheduler.capacity.ParentQueue: Re-sorting queues since queue: root.default stats: default: capacity=1.0, absoluteCapacity=1.0, usedResources=<memory:45056, vCores:39>usedCapacity=0.9166667, absoluteUsedCapacity=0.9166667, numApps=5, numContainers=39
2013-08-09 12:24:42,056 INFO org.apache.hadoop.yarn.server.resourcemanager.scheduler.capacity.ParentQueue: assignedContainer queue=root usedCapacity=0.9166667 absoluteUsedCapacity=0.9166667 used=<memory:45056, vCores:39> cluster=<memory:49152, vCores:96>
2013-08-09 12:24:42,060 INFO org.apache.hadoop.yarn.server.resourcemanager.rmcontainer.RMContainerImpl: container_1376050148932_0006_01_000022 Container Transitioned from NEW to ALLOCATED
2013-08-09 12:24:42,060 INFO org.apache.hadoop.yarn.server.resourcemanager.RMAuditLogger: USER=ubuntu	OPERATION=AM Allocated Container	TARGET=SchedulerApp	RESULT=SUCCESS	APPID=application_1376050148932_0006	CONTAINERID=container_1376050148932_0006_01_000022
2013-08-09 12:24:42,060 INFO org.apache.hadoop.yarn.server.resourcemanager.scheduler.common.fica.FiCaSchedulerNode: Assigned container container_1376050148932_0006_01_000022 of capacity <memory:1024, vCores:1> on host hadoop-210-2:40150, which currently has 4 containers, <memory:5120, vCores:4> used and <memory:3072, vCores:12> available
2013-08-09 12:24:42,061 INFO org.apache.hadoop.yarn.server.resourcemanager.scheduler.capacity.LeafQueue: assignedContainer application=application_1376050148932_0006 container=Container: [ContainerId: container_1376050148932_0006_01_000022, NodeId: hadoop-210-2:40150, NodeHttpAddress: hadoop-210-2:8042, Resource: <memory:1024, vCores:1>, Priority: 20, State: NEW, Token: null, Status: container_id {, app_attempt_id {, application_id {, id: 6, cluster_timestamp: 1376050148932, }, attemptId: 1, }, id: 22, }, state: C_NEW, ] containerId=container_1376050148932_0006_01_000022 queue=default: capacity=1.0, absoluteCapacity=1.0, usedResources=<memory:45056, vCores:39>usedCapacity=0.9166667, absoluteUsedCapacity=0.9166667, numApps=5, numContainers=39 usedCapacity=0.9166667 absoluteUsedCapacity=0.9166667 used=<memory:45056, vCores:39> cluster=<memory:49152, vCores:96>
2013-08-09 12:24:42,061 INFO org.apache.hadoop.yarn.server.resourcemanager.scheduler.capacity.ParentQueue: Re-sorting queues since queue: root.default stats: default: capacity=1.0, absoluteCapacity=1.0, usedResources=<memory:46080, vCores:40>usedCapacity=0.9375, absoluteUsedCapacity=0.9375, numApps=5, numContainers=40
2013-08-09 12:24:42,061 INFO org.apache.hadoop.yarn.server.resourcemanager.scheduler.capacity.ParentQueue: assignedContainer queue=root usedCapacity=0.9375 absoluteUsedCapacity=0.9375 used=<memory:46080, vCores:40> cluster=<memory:49152, vCores:96>
2013-08-09 12:24:42,062 INFO org.apache.hadoop.yarn.server.resourcemanager.rmcontainer.RMContainerImpl: container_1376050148932_0006_01_000023 Container Transitioned from NEW to ALLOCATED
2013-08-09 12:24:42,062 INFO org.apache.hadoop.yarn.server.resourcemanager.RMAuditLogger: USER=ubuntu	OPERATION=AM Allocated Container	TARGET=SchedulerApp	RESULT=SUCCESS	APPID=application_1376050148932_0006	CONTAINERID=container_1376050148932_0006_01_000023
2013-08-09 12:24:42,062 INFO org.apache.hadoop.yarn.server.resourcemanager.scheduler.common.fica.FiCaSchedulerNode: Assigned container container_1376050148932_0006_01_000023 of capacity <memory:1024, vCores:1> on host hadoop-210-2:40150, which currently has 5 containers, <memory:6144, vCores:5> used and <memory:2048, vCores:11> available
2013-08-09 12:24:42,063 INFO org.apache.hadoop.yarn.server.resourcemanager.scheduler.capacity.LeafQueue: assignedContainer application=application_1376050148932_0006 container=Container: [ContainerId: container_1376050148932_0006_01_000023, NodeId: hadoop-210-2:40150, NodeHttpAddress: hadoop-210-2:8042, Resource: <memory:1024, vCores:1>, Priority: 20, State: NEW, Token: null, Status: container_id {, app_attempt_id {, application_id {, id: 6, cluster_timestamp: 1376050148932, }, attemptId: 1, }, id: 23, }, state: C_NEW, ] containerId=container_1376050148932_0006_01_000023 queue=default: capacity=1.0, absoluteCapacity=1.0, usedResources=<memory:46080, vCores:40>usedCapacity=0.9375, absoluteUsedCapacity=0.9375, numApps=5, numContainers=40 usedCapacity=0.9375 absoluteUsedCapacity=0.9375 used=<memory:46080, vCores:40> cluster=<memory:49152, vCores:96>
2013-08-09 12:24:42,063 INFO org.apache.hadoop.yarn.server.resourcemanager.scheduler.capacity.ParentQueue: Re-sorting queues since queue: root.default stats: default: capacity=1.0, absoluteCapacity=1.0, usedResources=<memory:47104, vCores:41>usedCapacity=0.9583333, absoluteUsedCapacity=0.9583333, numApps=5, numContainers=41
2013-08-09 12:24:42,064 INFO org.apache.hadoop.yarn.server.resourcemanager.scheduler.capacity.ParentQueue: assignedContainer queue=root usedCapacity=0.9583333 absoluteUsedCapacity=0.9583333 used=<memory:47104, vCores:41> cluster=<memory:49152, vCores:96>
2013-08-09 12:24:42,064 INFO org.apache.hadoop.yarn.server.resourcemanager.rmcontainer.RMContainerImpl: container_1376050148932_0006_01_000024 Container Transitioned from NEW to ALLOCATED
2013-08-09 12:24:42,064 INFO org.apache.hadoop.yarn.server.resourcemanager.RMAuditLogger: USER=ubuntu	OPERATION=AM Allocated Container	TARGET=SchedulerApp	RESULT=SUCCESS	APPID=application_1376050148932_0006	CONTAINERID=container_1376050148932_0006_01_000024
2013-08-09 12:24:42,064 INFO org.apache.hadoop.yarn.server.resourcemanager.scheduler.common.fica.FiCaSchedulerNode: Assigned container container_1376050148932_0006_01_000024 of capacity <memory:1024, vCores:1> on host hadoop-210-2:40150, which currently has 6 containers, <memory:7168, vCores:6> used and <memory:1024, vCores:10> available
2013-08-09 12:24:42,065 INFO org.apache.hadoop.yarn.server.resourcemanager.scheduler.capacity.LeafQueue: assignedContainer application=application_1376050148932_0006 container=Container: [ContainerId: container_1376050148932_0006_01_000024, NodeId: hadoop-210-2:40150, NodeHttpAddress: hadoop-210-2:8042, Resource: <memory:1024, vCores:1>, Priority: 20, State: NEW, Token: null, Status: container_id {, app_attempt_id {, application_id {, id: 6, cluster_timestamp: 1376050148932, }, attemptId: 1, }, id: 24, }, state: C_NEW, ] containerId=container_1376050148932_0006_01_000024 queue=default: capacity=1.0, absoluteCapacity=1.0, usedResources=<memory:47104, vCores:41>usedCapacity=0.9583333, absoluteUsedCapacity=0.9583333, numApps=5, numContainers=41 usedCapacity=0.9583333 absoluteUsedCapacity=0.9583333 used=<memory:47104, vCores:41> cluster=<memory:49152, vCores:96>
2013-08-09 12:24:42,065 INFO org.apache.hadoop.yarn.server.resourcemanager.scheduler.capacity.ParentQueue: Re-sorting queues since queue: root.default stats: default: capacity=1.0, absoluteCapacity=1.0, usedResources=<memory:48128, vCores:42>usedCapacity=0.9791667, absoluteUsedCapacity=0.9791667, numApps=5, numContainers=42
2013-08-09 12:24:42,066 INFO org.apache.hadoop.yarn.server.resourcemanager.scheduler.capacity.ParentQueue: assignedContainer queue=root usedCapacity=0.9791667 absoluteUsedCapacity=0.9791667 used=<memory:48128, vCores:42> cluster=<memory:49152, vCores:96>
2013-08-09 12:24:42,066 INFO org.apache.hadoop.yarn.server.resourcemanager.rmcontainer.RMContainerImpl: container_1376050148932_0006_01_000025 Container Transitioned from NEW to ALLOCATED
2013-08-09 12:24:42,066 INFO org.apache.hadoop.yarn.server.resourcemanager.RMAuditLogger: USER=ubuntu	OPERATION=AM Allocated Container	TARGET=SchedulerApp	RESULT=SUCCESS	APPID=application_1376050148932_0006	CONTAINERID=container_1376050148932_0006_01_000025
2013-08-09 12:24:42,066 INFO org.apache.hadoop.yarn.server.resourcemanager.scheduler.common.fica.FiCaSchedulerNode: Assigned container container_1376050148932_0006_01_000025 of capacity <memory:1024, vCores:1> on host hadoop-210-2:40150, which currently has 7 containers, <memory:8192, vCores:7> used and <memory:0, vCores:9> available
2013-08-09 12:24:42,068 INFO org.apache.hadoop.yarn.server.resourcemanager.scheduler.capacity.LeafQueue: assignedContainer application=application_1376050148932_0006 container=Container: [ContainerId: container_1376050148932_0006_01_000025, NodeId: hadoop-210-2:40150, NodeHttpAddress: hadoop-210-2:8042, Resource: <memory:1024, vCores:1>, Priority: 20, State: NEW, Token: null, Status: container_id {, app_attempt_id {, application_id {, id: 6, cluster_timestamp: 1376050148932, }, attemptId: 1, }, id: 25, }, state: C_NEW, ] containerId=container_1376050148932_0006_01_000025 queue=default: capacity=1.0, absoluteCapacity=1.0, usedResources=<memory:48128, vCores:42>usedCapacity=0.9791667, absoluteUsedCapacity=0.9791667, numApps=5, numContainers=42 usedCapacity=0.9791667 absoluteUsedCapacity=0.9791667 used=<memory:48128, vCores:42> cluster=<memory:49152, vCores:96>
2013-08-09 12:24:42,068 INFO org.apache.hadoop.yarn.server.resourcemanager.scheduler.capacity.ParentQueue: Re-sorting queues since queue: root.default stats: default: capacity=1.0, absoluteCapacity=1.0, usedResources=<memory:49152, vCores:43>usedCapacity=1.0, absoluteUsedCapacity=1.0, numApps=5, numContainers=43
2013-08-09 12:24:42,068 INFO org.apache.hadoop.yarn.server.resourcemanager.scheduler.capacity.ParentQueue: assignedContainer queue=root usedCapacity=1.0 absoluteUsedCapacity=1.0 used=<memory:49152, vCores:43> cluster=<memory:49152, vCores:96>
2013-08-09 12:24:42,103 INFO org.apache.hadoop.yarn.server.resourcemanager.rmcontainer.RMContainerImpl: container_1376050148932_0007_01_000002 Container Transitioned from ALLOCATED to ACQUIRED
2013-08-09 12:24:42,105 INFO org.apache.hadoop.yarn.server.resourcemanager.rmcontainer.RMContainerImpl: container_1376050148932_0007_01_000003 Container Transitioned from ALLOCATED to ACQUIRED
2013-08-09 12:24:42,107 INFO org.apache.hadoop.yarn.server.resourcemanager.rmcontainer.RMContainerImpl: container_1376050148932_0007_01_000004 Container Transitioned from ALLOCATED to ACQUIRED
2013-08-09 12:24:42,108 INFO org.apache.hadoop.yarn.server.resourcemanager.rmcontainer.RMContainerImpl: container_1376050148932_0007_01_000005 Container Transitioned from ALLOCATED to ACQUIRED
2013-08-09 12:24:42,109 INFO org.apache.hadoop.yarn.server.resourcemanager.rmcontainer.RMContainerImpl: container_1376050148932_0007_01_000006 Container Transitioned from ALLOCATED to ACQUIRED
2013-08-09 12:24:42,110 INFO org.apache.hadoop.yarn.server.resourcemanager.rmcontainer.RMContainerImpl: container_1376050148932_0007_01_000007 Container Transitioned from ALLOCATED to ACQUIRED
2013-08-09 12:24:42,111 INFO org.apache.hadoop.yarn.server.resourcemanager.rmcontainer.RMContainerImpl: container_1376050148932_0007_01_000008 Container Transitioned from ALLOCATED to ACQUIRED
2013-08-09 12:24:42,112 INFO org.apache.hadoop.yarn.server.resourcemanager.rmcontainer.RMContainerImpl: container_1376050148932_0007_01_000009 Container Transitioned from ALLOCATED to ACQUIRED
2013-08-09 12:24:42,113 INFO org.apache.hadoop.yarn.server.resourcemanager.rmcontainer.RMContainerImpl: container_1376050148932_0007_01_000010 Container Transitioned from ALLOCATED to ACQUIRED
2013-08-09 12:24:42,115 INFO org.apache.hadoop.yarn.server.resourcemanager.rmcontainer.RMContainerImpl: container_1376050148932_0007_01_000011 Container Transitioned from ALLOCATED to ACQUIRED
2013-08-09 12:24:42,116 INFO org.apache.hadoop.yarn.server.resourcemanager.rmcontainer.RMContainerImpl: container_1376050148932_0007_01_000012 Container Transitioned from ALLOCATED to ACQUIRED
2013-08-09 12:24:42,116 INFO org.apache.hadoop.yarn.server.resourcemanager.rmcontainer.RMContainerImpl: container_1376050148932_0007_01_000013 Container Transitioned from ALLOCATED to ACQUIRED
2013-08-09 12:24:42,116 INFO org.apache.hadoop.yarn.server.resourcemanager.rmcontainer.RMContainerImpl: container_1376050148932_0007_01_000014 Container Transitioned from ALLOCATED to ACQUIRED
2013-08-09 12:24:42,116 INFO org.apache.hadoop.yarn.server.resourcemanager.rmcontainer.RMContainerImpl: container_1376050148932_0007_01_000015 Container Transitioned from ALLOCATED to ACQUIRED
2013-08-09 12:24:42,361 INFO org.apache.hadoop.yarn.server.resourcemanager.rmcontainer.RMContainerImpl: container_1376050148932_0006_01_000002 Container Transitioned from ALLOCATED to ACQUIRED
2013-08-09 12:24:42,361 INFO org.apache.hadoop.yarn.server.resourcemanager.rmcontainer.RMContainerImpl: container_1376050148932_0006_01_000003 Container Transitioned from ALLOCATED to ACQUIRED
2013-08-09 12:24:42,361 INFO org.apache.hadoop.yarn.server.resourcemanager.rmcontainer.RMContainerImpl: container_1376050148932_0006_01_000004 Container Transitioned from ALLOCATED to ACQUIRED
2013-08-09 12:24:42,361 INFO org.apache.hadoop.yarn.server.resourcemanager.rmcontainer.RMContainerImpl: container_1376050148932_0006_01_000005 Container Transitioned from ALLOCATED to ACQUIRED
2013-08-09 12:24:42,361 INFO org.apache.hadoop.yarn.server.resourcemanager.rmcontainer.RMContainerImpl: container_1376050148932_0006_01_000006 Container Transitioned from ALLOCATED to ACQUIRED
2013-08-09 12:24:42,362 INFO org.apache.hadoop.yarn.server.resourcemanager.rmcontainer.RMContainerImpl: container_1376050148932_0006_01_000007 Container Transitioned from ALLOCATED to ACQUIRED
2013-08-09 12:24:42,362 INFO org.apache.hadoop.yarn.server.resourcemanager.rmcontainer.RMContainerImpl: container_1376050148932_0006_01_000008 Container Transitioned from ALLOCATED to ACQUIRED
2013-08-09 12:24:42,362 INFO org.apache.hadoop.yarn.server.resourcemanager.rmcontainer.RMContainerImpl: container_1376050148932_0006_01_000009 Container Transitioned from ALLOCATED to ACQUIRED
2013-08-09 12:24:42,362 INFO org.apache.hadoop.yarn.server.resourcemanager.rmcontainer.RMContainerImpl: container_1376050148932_0006_01_000010 Container Transitioned from ALLOCATED to ACQUIRED
2013-08-09 12:24:42,362 INFO org.apache.hadoop.yarn.server.resourcemanager.rmcontainer.RMContainerImpl: container_1376050148932_0006_01_000011 Container Transitioned from ALLOCATED to ACQUIRED
2013-08-09 12:24:42,363 INFO org.apache.hadoop.yarn.server.resourcemanager.rmcontainer.RMContainerImpl: container_1376050148932_0006_01_000012 Container Transitioned from ALLOCATED to ACQUIRED
2013-08-09 12:24:42,363 INFO org.apache.hadoop.yarn.server.resourcemanager.rmcontainer.RMContainerImpl: container_1376050148932_0006_01_000013 Container Transitioned from ALLOCATED to ACQUIRED
2013-08-09 12:24:42,363 INFO org.apache.hadoop.yarn.server.resourcemanager.rmcontainer.RMContainerImpl: container_1376050148932_0006_01_000014 Container Transitioned from ALLOCATED to ACQUIRED
2013-08-09 12:24:42,363 INFO org.apache.hadoop.yarn.server.resourcemanager.rmcontainer.RMContainerImpl: container_1376050148932_0006_01_000015 Container Transitioned from ALLOCATED to ACQUIRED
2013-08-09 12:24:42,363 INFO org.apache.hadoop.yarn.server.resourcemanager.rmcontainer.RMContainerImpl: container_1376050148932_0006_01_000016 Container Transitioned from ALLOCATED to ACQUIRED
2013-08-09 12:24:42,364 INFO org.apache.hadoop.yarn.server.resourcemanager.rmcontainer.RMContainerImpl: container_1376050148932_0006_01_000017 Container Transitioned from ALLOCATED to ACQUIRED
2013-08-09 12:24:42,364 INFO org.apache.hadoop.yarn.server.resourcemanager.rmcontainer.RMContainerImpl: container_1376050148932_0006_01_000018 Container Transitioned from ALLOCATED to ACQUIRED
2013-08-09 12:24:42,364 INFO org.apache.hadoop.yarn.server.resourcemanager.rmcontainer.RMContainerImpl: container_1376050148932_0006_01_000019 Container Transitioned from ALLOCATED to ACQUIRED
2013-08-09 12:24:42,364 INFO org.apache.hadoop.yarn.server.resourcemanager.rmcontainer.RMContainerImpl: container_1376050148932_0006_01_000020 Container Transitioned from ALLOCATED to ACQUIRED
2013-08-09 12:24:42,364 INFO org.apache.hadoop.yarn.server.resourcemanager.rmcontainer.RMContainerImpl: container_1376050148932_0006_01_000021 Container Transitioned from ALLOCATED to ACQUIRED
2013-08-09 12:24:42,365 INFO org.apache.hadoop.yarn.server.resourcemanager.rmcontainer.RMContainerImpl: container_1376050148932_0006_01_000022 Container Transitioned from ALLOCATED to ACQUIRED
2013-08-09 12:24:42,365 INFO org.apache.hadoop.yarn.server.resourcemanager.rmcontainer.RMContainerImpl: container_1376050148932_0006_01_000023 Container Transitioned from ALLOCATED to ACQUIRED
2013-08-09 12:24:42,365 INFO org.apache.hadoop.yarn.server.resourcemanager.rmcontainer.RMContainerImpl: container_1376050148932_0006_01_000024 Container Transitioned from ALLOCATED to ACQUIRED
2013-08-09 12:24:42,365 INFO org.apache.hadoop.yarn.server.resourcemanager.rmcontainer.RMContainerImpl: container_1376050148932_0006_01_000025 Container Transitioned from ALLOCATED to ACQUIRED
2013-08-09 12:24:43,011 INFO org.apache.hadoop.yarn.server.resourcemanager.rmcontainer.RMContainerImpl: container_1376050148932_0006_01_000008 Container Transitioned from ACQUIRED to RUNNING
2013-08-09 12:24:43,012 INFO org.apache.hadoop.yarn.server.resourcemanager.rmcontainer.RMContainerImpl: container_1376050148932_0006_01_000009 Container Transitioned from ACQUIRED to RUNNING
2013-08-09 12:24:43,013 INFO org.apache.hadoop.yarn.server.resourcemanager.rmcontainer.RMContainerImpl: container_1376050148932_0006_01_000010 Container Transitioned from ACQUIRED to RUNNING
2013-08-09 12:24:43,014 INFO org.apache.hadoop.yarn.server.resourcemanager.rmcontainer.RMContainerImpl: container_1376050148932_0006_01_000011 Container Transitioned from ACQUIRED to RUNNING
2013-08-09 12:24:43,015 INFO org.apache.hadoop.yarn.server.resourcemanager.rmcontainer.RMContainerImpl: container_1376050148932_0006_01_000012 Container Transitioned from ACQUIRED to RUNNING
2013-08-09 12:24:43,016 INFO org.apache.hadoop.yarn.server.resourcemanager.rmcontainer.RMContainerImpl: container_1376050148932_0006_01_000013 Container Transitioned from ACQUIRED to RUNNING
2013-08-09 12:24:43,060 INFO org.apache.hadoop.yarn.server.resourcemanager.rmcontainer.RMContainerImpl: container_1376050148932_0006_01_000014 Container Transitioned from ACQUIRED to RUNNING
2013-08-09 12:24:43,061 INFO org.apache.hadoop.yarn.server.resourcemanager.rmcontainer.RMContainerImpl: container_1376050148932_0006_01_000015 Container Transitioned from ACQUIRED to RUNNING
2013-08-09 12:24:43,062 INFO org.apache.hadoop.yarn.server.resourcemanager.rmcontainer.RMContainerImpl: container_1376050148932_0006_01_000016 Container Transitioned from ACQUIRED to RUNNING
2013-08-09 12:24:43,064 INFO org.apache.hadoop.yarn.server.resourcemanager.rmcontainer.RMContainerImpl: container_1376050148932_0006_01_000017 Container Transitioned from ACQUIRED to RUNNING
2013-08-09 12:24:43,064 INFO org.apache.hadoop.yarn.server.resourcemanager.rmcontainer.RMContainerImpl: container_1376050148932_0006_01_000018 Container Transitioned from ACQUIRED to RUNNING
2013-08-09 12:24:43,065 INFO org.apache.hadoop.yarn.server.resourcemanager.rmcontainer.RMContainerImpl: container_1376050148932_0006_01_000019 Container Transitioned from ACQUIRED to RUNNING
2013-08-09 12:24:43,078 INFO org.apache.hadoop.yarn.server.resourcemanager.rmcontainer.RMContainerImpl: container_1376050148932_0006_01_000020 Container Transitioned from ACQUIRED to RUNNING
2013-08-09 12:24:43,078 INFO org.apache.hadoop.yarn.server.resourcemanager.rmcontainer.RMContainerImpl: container_1376050148932_0006_01_000021 Container Transitioned from ACQUIRED to RUNNING
2013-08-09 12:24:43,079 INFO org.apache.hadoop.yarn.server.resourcemanager.rmcontainer.RMContainerImpl: container_1376050148932_0006_01_000022 Container Transitioned from ACQUIRED to RUNNING
2013-08-09 12:24:43,079 INFO org.apache.hadoop.yarn.server.resourcemanager.rmcontainer.RMContainerImpl: container_1376050148932_0006_01_000023 Container Transitioned from ACQUIRED to RUNNING
2013-08-09 12:24:43,079 INFO org.apache.hadoop.yarn.server.resourcemanager.rmcontainer.RMContainerImpl: container_1376050148932_0006_01_000024 Container Transitioned from ACQUIRED to RUNNING
2013-08-09 12:24:43,080 INFO org.apache.hadoop.yarn.server.resourcemanager.rmcontainer.RMContainerImpl: container_1376050148932_0006_01_000025 Container Transitioned from ACQUIRED to RUNNING
2013-08-09 12:24:43,226 INFO org.apache.hadoop.yarn.server.resourcemanager.rmcontainer.RMContainerImpl: container_1376050148932_0007_01_000002 Container Transitioned from ACQUIRED to RUNNING
2013-08-09 12:24:43,227 INFO org.apache.hadoop.yarn.server.resourcemanager.rmcontainer.RMContainerImpl: container_1376050148932_0007_01_000003 Container Transitioned from ACQUIRED to RUNNING
2013-08-09 12:24:43,227 INFO org.apache.hadoop.yarn.server.resourcemanager.rmcontainer.RMContainerImpl: container_1376050148932_0007_01_000004 Container Transitioned from ACQUIRED to RUNNING
2013-08-09 12:24:43,227 INFO org.apache.hadoop.yarn.server.resourcemanager.rmcontainer.RMContainerImpl: container_1376050148932_0007_01_000005 Container Transitioned from ACQUIRED to RUNNING
2013-08-09 12:24:43,227 INFO org.apache.hadoop.yarn.server.resourcemanager.rmcontainer.RMContainerImpl: container_1376050148932_0007_01_000006 Container Transitioned from ACQUIRED to RUNNING
2013-08-09 12:24:43,227 INFO org.apache.hadoop.yarn.server.resourcemanager.rmcontainer.RMContainerImpl: container_1376050148932_0007_01_000007 Container Transitioned from ACQUIRED to RUNNING
2013-08-09 12:24:43,227 INFO org.apache.hadoop.yarn.server.resourcemanager.rmcontainer.RMContainerImpl: container_1376050148932_0007_01_000008 Container Transitioned from ACQUIRED to RUNNING
2013-08-09 12:24:43,228 INFO org.apache.hadoop.yarn.server.resourcemanager.rmcontainer.RMContainerImpl: container_1376050148932_0007_01_000009 Container Transitioned from ACQUIRED to RUNNING
2013-08-09 12:24:43,272 INFO org.apache.hadoop.yarn.server.resourcemanager.rmcontainer.RMContainerImpl: container_1376050148932_0007_01_000010 Container Transitioned from ACQUIRED to RUNNING
2013-08-09 12:24:43,272 INFO org.apache.hadoop.yarn.server.resourcemanager.rmcontainer.RMContainerImpl: container_1376050148932_0007_01_000011 Container Transitioned from ACQUIRED to RUNNING
2013-08-09 12:24:43,274 INFO org.apache.hadoop.yarn.server.resourcemanager.rmcontainer.RMContainerImpl: container_1376050148932_0007_01_000012 Container Transitioned from ACQUIRED to RUNNING
2013-08-09 12:24:43,274 INFO org.apache.hadoop.yarn.server.resourcemanager.rmcontainer.RMContainerImpl: container_1376050148932_0007_01_000013 Container Transitioned from ACQUIRED to RUNNING
2013-08-09 12:24:43,274 INFO org.apache.hadoop.yarn.server.resourcemanager.rmcontainer.RMContainerImpl: container_1376050148932_0007_01_000014 Container Transitioned from ACQUIRED to RUNNING
2013-08-09 12:24:43,275 INFO org.apache.hadoop.yarn.server.resourcemanager.rmcontainer.RMContainerImpl: container_1376050148932_0007_01_000015 Container Transitioned from ACQUIRED to RUNNING
2013-08-09 12:24:43,631 INFO org.apache.hadoop.yarn.server.resourcemanager.rmcontainer.RMContainerImpl: container_1376050148932_0006_01_000002 Container Transitioned from ACQUIRED to RUNNING
2013-08-09 12:24:43,632 INFO org.apache.hadoop.yarn.server.resourcemanager.rmcontainer.RMContainerImpl: container_1376050148932_0006_01_000003 Container Transitioned from ACQUIRED to RUNNING
2013-08-09 12:24:43,632 INFO org.apache.hadoop.yarn.server.resourcemanager.rmcontainer.RMContainerImpl: container_1376050148932_0006_01_000004 Container Transitioned from ACQUIRED to RUNNING
2013-08-09 12:24:43,632 INFO org.apache.hadoop.yarn.server.resourcemanager.rmcontainer.RMContainerImpl: container_1376050148932_0006_01_000005 Container Transitioned from ACQUIRED to RUNNING
2013-08-09 12:24:43,632 INFO org.apache.hadoop.yarn.server.resourcemanager.rmcontainer.RMContainerImpl: container_1376050148932_0006_01_000006 Container Transitioned from ACQUIRED to RUNNING
2013-08-09 12:24:43,632 INFO org.apache.hadoop.yarn.server.resourcemanager.rmcontainer.RMContainerImpl: container_1376050148932_0006_01_000007 Container Transitioned from ACQUIRED to RUNNING
2013-08-09 12:24:44,244 INFO org.apache.hadoop.yarn.server.resourcemanager.ApplicationMasterService: AM registration appattempt_1376050148932_0009_000001
2013-08-09 12:24:44,244 INFO org.apache.hadoop.yarn.server.resourcemanager.RMAuditLogger: USER=ubuntu	IP=192.168.100.6	OPERATION=Register App Master	TARGET=ApplicationMasterService	RESULT=SUCCESS	APPID=application_1376050148932_0009	APPATTEMPTID=appattempt_1376050148932_0009_000001
2013-08-09 12:24:44,245 INFO org.apache.hadoop.yarn.server.resourcemanager.rmapp.attempt.RMAppAttemptImpl: appattempt_1376050148932_0009_000001 State change from LAUNCHED to RUNNING
2013-08-09 12:24:44,245 INFO org.apache.hadoop.yarn.server.resourcemanager.rmapp.RMAppImpl: application_1376050148932_0009 State change from ACCEPTED to RUNNING
2013-08-09 12:24:45,499 INFO org.apache.hadoop.yarn.server.resourcemanager.ApplicationMasterService: AM registration appattempt_1376050148932_0008_000001
2013-08-09 12:24:45,499 INFO org.apache.hadoop.yarn.server.resourcemanager.RMAuditLogger: USER=ubuntu	IP=192.168.100.9	OPERATION=Register App Master	TARGET=ApplicationMasterService	RESULT=SUCCESS	APPID=application_1376050148932_0008	APPATTEMPTID=appattempt_1376050148932_0008_000001
2013-08-09 12:24:45,500 INFO org.apache.hadoop.yarn.server.resourcemanager.rmapp.attempt.RMAppAttemptImpl: appattempt_1376050148932_0008_000001 State change from LAUNCHED to RUNNING
2013-08-09 12:24:45,500 INFO org.apache.hadoop.yarn.server.resourcemanager.rmapp.RMAppImpl: application_1376050148932_0008 State change from ACCEPTED to RUNNING
2013-08-09 12:25:07,479 INFO org.apache.hadoop.yarn.server.resourcemanager.rmcontainer.RMContainerImpl: container_1376050148932_0006_01_000007 Container Transitioned from RUNNING to COMPLETED
2013-08-09 12:25:07,479 INFO org.apache.hadoop.yarn.server.resourcemanager.scheduler.common.fica.FiCaSchedulerApp: Completed container: container_1376050148932_0006_01_000007 in state: COMPLETED event:FINISHED
2013-08-09 12:25:07,479 INFO org.apache.hadoop.yarn.server.resourcemanager.RMAuditLogger: USER=ubuntu	OPERATION=AM Released Container	TARGET=SchedulerApp	RESULT=SUCCESS	APPID=application_1376050148932_0006	CONTAINERID=container_1376050148932_0006_01_000007
2013-08-09 12:25:07,479 INFO org.apache.hadoop.yarn.server.resourcemanager.scheduler.common.fica.FiCaSchedulerNode: Released container container_1376050148932_0006_01_000007 of capacity <memory:1024, vCores:1> on host hadoop-210-5:60822, which currently has 6 containers, <memory:7168, vCores:6> used and <memory:1024, vCores:10> available, release resources=true
2013-08-09 12:25:07,479 INFO org.apache.hadoop.yarn.server.resourcemanager.scheduler.capacity.LeafQueue: default used=<memory:48128, vCores:42> numContainers=42 user=ubuntu user-resources=<memory:48128, vCores:42>
2013-08-09 12:25:07,482 INFO org.apache.hadoop.yarn.server.resourcemanager.scheduler.capacity.LeafQueue: completedContainer container=Container: [ContainerId: container_1376050148932_0006_01_000007, NodeId: hadoop-210-5:60822, NodeHttpAddress: hadoop-210-5:8042, Resource: <memory:1024, vCores:1>, Priority: 20, State: NEW, Token: null, Status: container_id {, app_attempt_id {, application_id {, id: 6, cluster_timestamp: 1376050148932, }, attemptId: 1, }, id: 7, }, state: C_COMPLETE, diagnostics: "Container killed by the ApplicationMaster.\n", exit_status: 0, ] resource=<memory:1024, vCores:1> queue=default: capacity=1.0, absoluteCapacity=1.0, usedResources=<memory:48128, vCores:42>usedCapacity=0.9791667, absoluteUsedCapacity=0.9791667, numApps=5, numContainers=42 usedCapacity=0.9791667 absoluteUsedCapacity=0.9791667 used=<memory:48128, vCores:42> cluster=<memory:49152, vCores:96>
2013-08-09 12:25:07,482 INFO org.apache.hadoop.yarn.server.resourcemanager.scheduler.capacity.ParentQueue: completedContainer queue=root usedCapacity=0.9791667 absoluteUsedCapacity=0.9791667 used=<memory:48128, vCores:42> cluster=<memory:49152, vCores:96>
2013-08-09 12:25:07,483 INFO org.apache.hadoop.yarn.server.resourcemanager.scheduler.capacity.CapacityScheduler: Application appattempt_1376050148932_0006_000001 released container container_1376050148932_0006_01_000007 on node: host: hadoop-210-5:60822 #containers=6 available=1024 used=7168 with event: FINISHED
2013-08-09 12:25:07,483 INFO org.apache.hadoop.yarn.server.resourcemanager.rmcontainer.RMContainerImpl: container_1376050148932_0006_01_000026 Container Transitioned from NEW to ALLOCATED
2013-08-09 12:25:07,483 INFO org.apache.hadoop.yarn.server.resourcemanager.RMAuditLogger: USER=ubuntu	OPERATION=AM Allocated Container	TARGET=SchedulerApp	RESULT=SUCCESS	APPID=application_1376050148932_0006	CONTAINERID=container_1376050148932_0006_01_000026
2013-08-09 12:25:07,483 INFO org.apache.hadoop.yarn.server.resourcemanager.scheduler.common.fica.FiCaSchedulerNode: Assigned container container_1376050148932_0006_01_000026 of capacity <memory:1024, vCores:1> on host hadoop-210-5:60822, which currently has 7 containers, <memory:8192, vCores:7> used and <memory:0, vCores:9> available
2013-08-09 12:25:07,484 INFO org.apache.hadoop.yarn.server.resourcemanager.scheduler.capacity.LeafQueue: assignedContainer application=application_1376050148932_0006 container=Container: [ContainerId: container_1376050148932_0006_01_000026, NodeId: hadoop-210-5:60822, NodeHttpAddress: hadoop-210-5:8042, Resource: <memory:1024, vCores:1>, Priority: 20, State: NEW, Token: null, Status: container_id {, app_attempt_id {, application_id {, id: 6, cluster_timestamp: 1376050148932, }, attemptId: 1, }, id: 26, }, state: C_NEW, ] containerId=container_1376050148932_0006_01_000026 queue=default: capacity=1.0, absoluteCapacity=1.0, usedResources=<memory:48128, vCores:42>usedCapacity=0.9791667, absoluteUsedCapacity=0.9791667, numApps=5, numContainers=42 usedCapacity=0.9791667 absoluteUsedCapacity=0.9791667 used=<memory:48128, vCores:42> cluster=<memory:49152, vCores:96>
2013-08-09 12:25:07,485 INFO org.apache.hadoop.yarn.server.resourcemanager.scheduler.capacity.ParentQueue: Re-sorting queues since queue: root.default stats: default: capacity=1.0, absoluteCapacity=1.0, usedResources=<memory:49152, vCores:43>usedCapacity=1.0, absoluteUsedCapacity=1.0, numApps=5, numContainers=43
2013-08-09 12:25:07,485 INFO org.apache.hadoop.yarn.server.resourcemanager.scheduler.capacity.ParentQueue: assignedContainer queue=root usedCapacity=1.0 absoluteUsedCapacity=1.0 used=<memory:49152, vCores:43> cluster=<memory:49152, vCores:96>
2013-08-09 12:25:08,271 INFO org.apache.hadoop.yarn.server.resourcemanager.rmcontainer.RMContainerImpl: container_1376050148932_0006_01_000026 Container Transitioned from ALLOCATED to ACQUIRED
2013-08-09 12:25:08,417 INFO org.apache.hadoop.yarn.server.resourcemanager.rmcontainer.RMContainerImpl: container_1376050148932_0006_01_000022 Container Transitioned from RUNNING to COMPLETED
2013-08-09 12:25:08,418 INFO org.apache.hadoop.yarn.server.resourcemanager.scheduler.common.fica.FiCaSchedulerApp: Completed container: container_1376050148932_0006_01_000022 in state: COMPLETED event:FINISHED
2013-08-09 12:25:08,418 INFO org.apache.hadoop.yarn.server.resourcemanager.RMAuditLogger: USER=ubuntu	OPERATION=AM Released Container	TARGET=SchedulerApp	RESULT=SUCCESS	APPID=application_1376050148932_0006	CONTAINERID=container_1376050148932_0006_01_000022
2013-08-09 12:25:08,418 INFO org.apache.hadoop.yarn.server.resourcemanager.scheduler.common.fica.FiCaSchedulerNode: Released container container_1376050148932_0006_01_000022 of capacity <memory:1024, vCores:1> on host hadoop-210-2:40150, which currently has 6 containers, <memory:7168, vCores:6> used and <memory:1024, vCores:10> available, release resources=true
2013-08-09 12:25:08,418 INFO org.apache.hadoop.yarn.server.resourcemanager.scheduler.capacity.LeafQueue: default used=<memory:48128, vCores:42> numContainers=42 user=ubuntu user-resources=<memory:48128, vCores:42>
2013-08-09 12:25:08,419 INFO org.apache.hadoop.yarn.server.resourcemanager.scheduler.capacity.LeafQueue: completedContainer container=Container: [ContainerId: container_1376050148932_0006_01_000022, NodeId: hadoop-210-2:40150, NodeHttpAddress: hadoop-210-2:8042, Resource: <memory:1024, vCores:1>, Priority: 20, State: NEW, Token: null, Status: container_id {, app_attempt_id {, application_id {, id: 6, cluster_timestamp: 1376050148932, }, attemptId: 1, }, id: 22, }, state: C_COMPLETE, diagnostics: "Container killed by the ApplicationMaster.\n\n", exit_status: 143, ] resource=<memory:1024, vCores:1> queue=default: capacity=1.0, absoluteCapacity=1.0, usedResources=<memory:48128, vCores:42>usedCapacity=0.9791667, absoluteUsedCapacity=0.9791667, numApps=5, numContainers=42 usedCapacity=0.9791667 absoluteUsedCapacity=0.9791667 used=<memory:48128, vCores:42> cluster=<memory:49152, vCores:96>
2013-08-09 12:25:08,420 INFO org.apache.hadoop.yarn.server.resourcemanager.scheduler.capacity.ParentQueue: completedContainer queue=root usedCapacity=0.9791667 absoluteUsedCapacity=0.9791667 used=<memory:48128, vCores:42> cluster=<memory:49152, vCores:96>
2013-08-09 12:25:08,420 INFO org.apache.hadoop.yarn.server.resourcemanager.scheduler.capacity.CapacityScheduler: Application appattempt_1376050148932_0006_000001 released container container_1376050148932_0006_01_000022 on node: host: hadoop-210-2:40150 #containers=6 available=1024 used=7168 with event: FINISHED
2013-08-09 12:25:08,420 INFO org.apache.hadoop.yarn.server.resourcemanager.rmcontainer.RMContainerImpl: container_1376050148932_0006_01_000027 Container Transitioned from NEW to ALLOCATED
2013-08-09 12:25:08,421 INFO org.apache.hadoop.yarn.server.resourcemanager.RMAuditLogger: USER=ubuntu	OPERATION=AM Allocated Container	TARGET=SchedulerApp	RESULT=SUCCESS	APPID=application_1376050148932_0006	CONTAINERID=container_1376050148932_0006_01_000027
2013-08-09 12:25:08,421 INFO org.apache.hadoop.yarn.server.resourcemanager.scheduler.common.fica.FiCaSchedulerNode: Assigned container container_1376050148932_0006_01_000027 of capacity <memory:1024, vCores:1> on host hadoop-210-2:40150, which currently has 7 containers, <memory:8192, vCores:7> used and <memory:0, vCores:9> available
2013-08-09 12:25:08,422 INFO org.apache.hadoop.yarn.server.resourcemanager.scheduler.capacity.LeafQueue: assignedContainer application=application_1376050148932_0006 container=Container: [ContainerId: container_1376050148932_0006_01_000027, NodeId: hadoop-210-2:40150, NodeHttpAddress: hadoop-210-2:8042, Resource: <memory:1024, vCores:1>, Priority: 20, State: NEW, Token: null, Status: container_id {, app_attempt_id {, application_id {, id: 6, cluster_timestamp: 1376050148932, }, attemptId: 1, }, id: 27, }, state: C_NEW, ] containerId=container_1376050148932_0006_01_000027 queue=default: capacity=1.0, absoluteCapacity=1.0, usedResources=<memory:48128, vCores:42>usedCapacity=0.9791667, absoluteUsedCapacity=0.9791667, numApps=5, numContainers=42 usedCapacity=0.9791667 absoluteUsedCapacity=0.9791667 used=<memory:48128, vCores:42> cluster=<memory:49152, vCores:96>
2013-08-09 12:25:08,422 INFO org.apache.hadoop.yarn.server.resourcemanager.scheduler.capacity.ParentQueue: Re-sorting queues since queue: root.default stats: default: capacity=1.0, absoluteCapacity=1.0, usedResources=<memory:49152, vCores:43>usedCapacity=1.0, absoluteUsedCapacity=1.0, numApps=5, numContainers=43
2013-08-09 12:25:08,422 INFO org.apache.hadoop.yarn.server.resourcemanager.scheduler.capacity.ParentQueue: assignedContainer queue=root usedCapacity=1.0 absoluteUsedCapacity=1.0 used=<memory:49152, vCores:43> cluster=<memory:49152, vCores:96>
2013-08-09 12:25:08,895 INFO org.apache.hadoop.yarn.server.resourcemanager.rmcontainer.RMContainerImpl: container_1376050148932_0006_01_000026 Container Transitioned from ACQUIRED to RUNNING
2013-08-09 12:25:08,895 INFO org.apache.hadoop.yarn.server.resourcemanager.rmcontainer.RMContainerImpl: container_1376050148932_0006_01_000003 Container Transitioned from RUNNING to COMPLETED
2013-08-09 12:25:08,895 INFO org.apache.hadoop.yarn.server.resourcemanager.scheduler.common.fica.FiCaSchedulerApp: Completed container: container_1376050148932_0006_01_000003 in state: COMPLETED event:FINISHED
2013-08-09 12:25:08,896 INFO org.apache.hadoop.yarn.server.resourcemanager.RMAuditLogger: USER=ubuntu	OPERATION=AM Released Container	TARGET=SchedulerApp	RESULT=SUCCESS	APPID=application_1376050148932_0006	CONTAINERID=container_1376050148932_0006_01_000003
2013-08-09 12:25:08,896 INFO org.apache.hadoop.yarn.server.resourcemanager.scheduler.common.fica.FiCaSchedulerNode: Released container container_1376050148932_0006_01_000003 of capacity <memory:1024, vCores:1> on host hadoop-210-5:60822, which currently has 6 containers, <memory:7168, vCores:6> used and <memory:1024, vCores:10> available, release resources=true
2013-08-09 12:25:08,896 INFO org.apache.hadoop.yarn.server.resourcemanager.scheduler.capacity.LeafQueue: default used=<memory:48128, vCores:42> numContainers=42 user=ubuntu user-resources=<memory:48128, vCores:42>
2013-08-09 12:25:08,897 INFO org.apache.hadoop.yarn.server.resourcemanager.scheduler.capacity.LeafQueue: completedContainer container=Container: [ContainerId: container_1376050148932_0006_01_000003, NodeId: hadoop-210-5:60822, NodeHttpAddress: hadoop-210-5:8042, Resource: <memory:1024, vCores:1>, Priority: 20, State: NEW, Token: null, Status: container_id {, app_attempt_id {, application_id {, id: 6, cluster_timestamp: 1376050148932, }, attemptId: 1, }, id: 3, }, state: C_COMPLETE, diagnostics: "Container killed by the ApplicationMaster.\n\n", exit_status: 143, ] resource=<memory:1024, vCores:1> queue=default: capacity=1.0, absoluteCapacity=1.0, usedResources=<memory:48128, vCores:42>usedCapacity=0.9791667, absoluteUsedCapacity=0.9791667, numApps=5, numContainers=42 usedCapacity=0.9791667 absoluteUsedCapacity=0.9791667 used=<memory:48128, vCores:42> cluster=<memory:49152, vCores:96>
2013-08-09 12:25:08,897 INFO org.apache.hadoop.yarn.server.resourcemanager.scheduler.capacity.ParentQueue: completedContainer queue=root usedCapacity=0.9791667 absoluteUsedCapacity=0.9791667 used=<memory:48128, vCores:42> cluster=<memory:49152, vCores:96>
2013-08-09 12:25:08,897 INFO org.apache.hadoop.yarn.server.resourcemanager.scheduler.capacity.CapacityScheduler: Application appattempt_1376050148932_0006_000001 released container container_1376050148932_0006_01_000003 on node: host: hadoop-210-5:60822 #containers=6 available=1024 used=7168 with event: FINISHED
2013-08-09 12:25:08,898 INFO org.apache.hadoop.yarn.server.resourcemanager.rmcontainer.RMContainerImpl: container_1376050148932_0006_01_000028 Container Transitioned from NEW to ALLOCATED
2013-08-09 12:25:08,898 INFO org.apache.hadoop.yarn.server.resourcemanager.RMAuditLogger: USER=ubuntu	OPERATION=AM Allocated Container	TARGET=SchedulerApp	RESULT=SUCCESS	APPID=application_1376050148932_0006	CONTAINERID=container_1376050148932_0006_01_000028
2013-08-09 12:25:08,898 INFO org.apache.hadoop.yarn.server.resourcemanager.scheduler.common.fica.FiCaSchedulerNode: Assigned container container_1376050148932_0006_01_000028 of capacity <memory:1024, vCores:1> on host hadoop-210-5:60822, which currently has 7 containers, <memory:8192, vCores:7> used and <memory:0, vCores:9> available
2013-08-09 12:25:08,899 INFO org.apache.hadoop.yarn.server.resourcemanager.scheduler.capacity.LeafQueue: assignedContainer application=application_1376050148932_0006 container=Container: [ContainerId: container_1376050148932_0006_01_000028, NodeId: hadoop-210-5:60822, NodeHttpAddress: hadoop-210-5:8042, Resource: <memory:1024, vCores:1>, Priority: 20, State: NEW, Token: null, Status: container_id {, app_attempt_id {, application_id {, id: 6, cluster_timestamp: 1376050148932, }, attemptId: 1, }, id: 28, }, state: C_NEW, ] containerId=container_1376050148932_0006_01_000028 queue=default: capacity=1.0, absoluteCapacity=1.0, usedResources=<memory:48128, vCores:42>usedCapacity=0.9791667, absoluteUsedCapacity=0.9791667, numApps=5, numContainers=42 usedCapacity=0.9791667 absoluteUsedCapacity=0.9791667 used=<memory:48128, vCores:42> cluster=<memory:49152, vCores:96>
2013-08-09 12:25:08,899 INFO org.apache.hadoop.yarn.server.resourcemanager.scheduler.capacity.ParentQueue: Re-sorting queues since queue: root.default stats: default: capacity=1.0, absoluteCapacity=1.0, usedResources=<memory:49152, vCores:43>usedCapacity=1.0, absoluteUsedCapacity=1.0, numApps=5, numContainers=43
2013-08-09 12:25:08,899 INFO org.apache.hadoop.yarn.server.resourcemanager.scheduler.capacity.ParentQueue: assignedContainer queue=root usedCapacity=1.0 absoluteUsedCapacity=1.0 used=<memory:49152, vCores:43> cluster=<memory:49152, vCores:96>
2013-08-09 12:25:09,285 INFO org.apache.hadoop.yarn.server.resourcemanager.rmcontainer.RMContainerImpl: container_1376050148932_0006_01_000027 Container Transitioned from ALLOCATED to ACQUIRED
2013-08-09 12:25:09,286 INFO org.apache.hadoop.yarn.server.resourcemanager.rmcontainer.RMContainerImpl: container_1376050148932_0006_01_000028 Container Transitioned from ALLOCATED to ACQUIRED
2013-08-09 12:25:09,353 INFO org.apache.hadoop.yarn.server.resourcemanager.rmcontainer.RMContainerImpl: container_1376050148932_0006_01_000027 Container Transitioned from ACQUIRED to RUNNING
2013-08-09 12:25:09,471 INFO org.apache.hadoop.yarn.server.resourcemanager.rmcontainer.RMContainerImpl: container_1376050148932_0006_01_000014 Container Transitioned from RUNNING to COMPLETED
2013-08-09 12:25:09,471 INFO org.apache.hadoop.yarn.server.resourcemanager.scheduler.common.fica.FiCaSchedulerApp: Completed container: container_1376050148932_0006_01_000014 in state: COMPLETED event:FINISHED
2013-08-09 12:25:09,472 INFO org.apache.hadoop.yarn.server.resourcemanager.RMAuditLogger: USER=ubuntu	OPERATION=AM Released Container	TARGET=SchedulerApp	RESULT=SUCCESS	APPID=application_1376050148932_0006	CONTAINERID=container_1376050148932_0006_01_000014
2013-08-09 12:25:09,472 INFO org.apache.hadoop.yarn.server.resourcemanager.scheduler.common.fica.FiCaSchedulerNode: Released container container_1376050148932_0006_01_000014 of capacity <memory:1024, vCores:1> on host hadoop-210-3:36255, which currently has 6 containers, <memory:7168, vCores:6> used and <memory:1024, vCores:10> available, release resources=true
2013-08-09 12:25:09,472 INFO org.apache.hadoop.yarn.server.resourcemanager.scheduler.capacity.LeafQueue: default used=<memory:48128, vCores:42> numContainers=42 user=ubuntu user-resources=<memory:48128, vCores:42>
2013-08-09 12:25:09,473 INFO org.apache.hadoop.yarn.server.resourcemanager.scheduler.capacity.LeafQueue: completedContainer container=Container: [ContainerId: container_1376050148932_0006_01_000014, NodeId: hadoop-210-3:36255, NodeHttpAddress: hadoop-210-3:8042, Resource: <memory:1024, vCores:1>, Priority: 20, State: NEW, Token: null, Status: container_id {, app_attempt_id {, application_id {, id: 6, cluster_timestamp: 1376050148932, }, attemptId: 1, }, id: 14, }, state: C_COMPLETE, diagnostics: "Container killed by the ApplicationMaster.\n\n", exit_status: 143, ] resource=<memory:1024, vCores:1> queue=default: capacity=1.0, absoluteCapacity=1.0, usedResources=<memory:48128, vCores:42>usedCapacity=0.9791667, absoluteUsedCapacity=0.9791667, numApps=5, numContainers=42 usedCapacity=0.9791667 absoluteUsedCapacity=0.9791667 used=<memory:48128, vCores:42> cluster=<memory:49152, vCores:96>
2013-08-09 12:25:09,473 INFO org.apache.hadoop.yarn.server.resourcemanager.scheduler.capacity.ParentQueue: completedContainer queue=root usedCapacity=0.9791667 absoluteUsedCapacity=0.9791667 used=<memory:48128, vCores:42> cluster=<memory:49152, vCores:96>
2013-08-09 12:25:09,473 INFO org.apache.hadoop.yarn.server.resourcemanager.scheduler.capacity.CapacityScheduler: Application appattempt_1376050148932_0006_000001 released container container_1376050148932_0006_01_000014 on node: host: hadoop-210-3:36255 #containers=6 available=1024 used=7168 with event: FINISHED
2013-08-09 12:25:09,474 INFO org.apache.hadoop.yarn.server.resourcemanager.rmcontainer.RMContainerImpl: container_1376050148932_0006_01_000029 Container Transitioned from NEW to ALLOCATED
2013-08-09 12:25:09,474 INFO org.apache.hadoop.yarn.server.resourcemanager.RMAuditLogger: USER=ubuntu	OPERATION=AM Allocated Container	TARGET=SchedulerApp	RESULT=SUCCESS	APPID=application_1376050148932_0006	CONTAINERID=container_1376050148932_0006_01_000029
2013-08-09 12:25:09,474 INFO org.apache.hadoop.yarn.server.resourcemanager.scheduler.common.fica.FiCaSchedulerNode: Assigned container container_1376050148932_0006_01_000029 of capacity <memory:1024, vCores:1> on host hadoop-210-3:36255, which currently has 7 containers, <memory:8192, vCores:7> used and <memory:0, vCores:9> available
2013-08-09 12:25:09,475 INFO org.apache.hadoop.yarn.server.resourcemanager.scheduler.capacity.LeafQueue: assignedContainer application=application_1376050148932_0006 container=Container: [ContainerId: container_1376050148932_0006_01_000029, NodeId: hadoop-210-3:36255, NodeHttpAddress: hadoop-210-3:8042, Resource: <memory:1024, vCores:1>, Priority: 10, State: NEW, Token: null, Status: container_id {, app_attempt_id {, application_id {, id: 6, cluster_timestamp: 1376050148932, }, attemptId: 1, }, id: 29, }, state: C_NEW, ] containerId=container_1376050148932_0006_01_000029 queue=default: capacity=1.0, absoluteCapacity=1.0, usedResources=<memory:48128, vCores:42>usedCapacity=0.9791667, absoluteUsedCapacity=0.9791667, numApps=5, numContainers=42 usedCapacity=0.9791667 absoluteUsedCapacity=0.9791667 used=<memory:48128, vCores:42> cluster=<memory:49152, vCores:96>
2013-08-09 12:25:09,475 INFO org.apache.hadoop.yarn.server.resourcemanager.scheduler.capacity.ParentQueue: Re-sorting queues since queue: root.default stats: default: capacity=1.0, absoluteCapacity=1.0, usedResources=<memory:49152, vCores:43>usedCapacity=1.0, absoluteUsedCapacity=1.0, numApps=5, numContainers=43
2013-08-09 12:25:09,476 INFO org.apache.hadoop.yarn.server.resourcemanager.scheduler.capacity.ParentQueue: assignedContainer queue=root usedCapacity=1.0 absoluteUsedCapacity=1.0 used=<memory:49152, vCores:43> cluster=<memory:49152, vCores:96>
2013-08-09 12:25:09,902 INFO org.apache.hadoop.yarn.server.resourcemanager.rmcontainer.RMContainerImpl: container_1376050148932_0006_01_000028 Container Transitioned from ACQUIRED to RUNNING
2013-08-09 12:25:10,297 INFO org.apache.hadoop.yarn.server.resourcemanager.rmcontainer.RMContainerImpl: container_1376050148932_0006_01_000029 Container Transitioned from ALLOCATED to ACQUIRED
2013-08-09 12:25:10,363 INFO org.apache.hadoop.yarn.server.resourcemanager.rmcontainer.RMContainerImpl: container_1376050148932_0006_01_000021 Container Transitioned from RUNNING to COMPLETED
2013-08-09 12:25:10,363 INFO org.apache.hadoop.yarn.server.resourcemanager.scheduler.common.fica.FiCaSchedulerApp: Completed container: container_1376050148932_0006_01_000021 in state: COMPLETED event:FINISHED
2013-08-09 12:25:10,363 INFO org.apache.hadoop.yarn.server.resourcemanager.RMAuditLogger: USER=ubuntu	OPERATION=AM Released Container	TARGET=SchedulerApp	RESULT=SUCCESS	APPID=application_1376050148932_0006	CONTAINERID=container_1376050148932_0006_01_000021
2013-08-09 12:25:10,363 INFO org.apache.hadoop.yarn.server.resourcemanager.scheduler.common.fica.FiCaSchedulerNode: Released container container_1376050148932_0006_01_000021 of capacity <memory:1024, vCores:1> on host hadoop-210-2:40150, which currently has 6 containers, <memory:7168, vCores:6> used and <memory:1024, vCores:10> available, release resources=true
2013-08-09 12:25:10,363 INFO org.apache.hadoop.yarn.server.resourcemanager.scheduler.capacity.LeafQueue: default used=<memory:48128, vCores:42> numContainers=42 user=ubuntu user-resources=<memory:48128, vCores:42>
2013-08-09 12:25:10,364 INFO org.apache.hadoop.yarn.server.resourcemanager.scheduler.capacity.LeafQueue: completedContainer container=Container: [ContainerId: container_1376050148932_0006_01_000021, NodeId: hadoop-210-2:40150, NodeHttpAddress: hadoop-210-2:8042, Resource: <memory:1024, vCores:1>, Priority: 20, State: NEW, Token: null, Status: container_id {, app_attempt_id {, application_id {, id: 6, cluster_timestamp: 1376050148932, }, attemptId: 1, }, id: 21, }, state: C_COMPLETE, diagnostics: "Container killed by the ApplicationMaster.\n\n", exit_status: 143, ] resource=<memory:1024, vCores:1> queue=default: capacity=1.0, absoluteCapacity=1.0, usedResources=<memory:48128, vCores:42>usedCapacity=0.9791667, absoluteUsedCapacity=0.9791667, numApps=5, numContainers=42 usedCapacity=0.9791667 absoluteUsedCapacity=0.9791667 used=<memory:48128, vCores:42> cluster=<memory:49152, vCores:96>
2013-08-09 12:25:10,365 INFO org.apache.hadoop.yarn.server.resourcemanager.scheduler.capacity.ParentQueue: completedContainer queue=root usedCapacity=0.9791667 absoluteUsedCapacity=0.9791667 used=<memory:48128, vCores:42> cluster=<memory:49152, vCores:96>
2013-08-09 12:25:10,365 INFO org.apache.hadoop.yarn.server.resourcemanager.scheduler.capacity.CapacityScheduler: Application appattempt_1376050148932_0006_000001 released container container_1376050148932_0006_01_000021 on node: host: hadoop-210-2:40150 #containers=6 available=1024 used=7168 with event: FINISHED
2013-08-09 12:25:10,365 INFO org.apache.hadoop.yarn.server.resourcemanager.rmcontainer.RMContainerImpl: container_1376050148932_0006_01_000030 Container Transitioned from NEW to ALLOCATED
2013-08-09 12:25:10,365 INFO org.apache.hadoop.yarn.server.resourcemanager.RMAuditLogger: USER=ubuntu	OPERATION=AM Allocated Container	TARGET=SchedulerApp	RESULT=SUCCESS	APPID=application_1376050148932_0006	CONTAINERID=container_1376050148932_0006_01_000030
2013-08-09 12:25:10,365 INFO org.apache.hadoop.yarn.server.resourcemanager.scheduler.common.fica.FiCaSchedulerNode: Assigned container container_1376050148932_0006_01_000030 of capacity <memory:1024, vCores:1> on host hadoop-210-2:40150, which currently has 7 containers, <memory:8192, vCores:7> used and <memory:0, vCores:9> available
2013-08-09 12:25:10,366 INFO org.apache.hadoop.yarn.server.resourcemanager.scheduler.capacity.LeafQueue: assignedContainer application=application_1376050148932_0006 container=Container: [ContainerId: container_1376050148932_0006_01_000030, NodeId: hadoop-210-2:40150, NodeHttpAddress: hadoop-210-2:8042, Resource: <memory:1024, vCores:1>, Priority: 10, State: NEW, Token: null, Status: container_id {, app_attempt_id {, application_id {, id: 6, cluster_timestamp: 1376050148932, }, attemptId: 1, }, id: 30, }, state: C_NEW, ] containerId=container_1376050148932_0006_01_000030 queue=default: capacity=1.0, absoluteCapacity=1.0, usedResources=<memory:48128, vCores:42>usedCapacity=0.9791667, absoluteUsedCapacity=0.9791667, numApps=5, numContainers=42 usedCapacity=0.9791667 absoluteUsedCapacity=0.9791667 used=<memory:48128, vCores:42> cluster=<memory:49152, vCores:96>
2013-08-09 12:25:10,367 INFO org.apache.hadoop.yarn.server.resourcemanager.scheduler.capacity.ParentQueue: Re-sorting queues since queue: root.default stats: default: capacity=1.0, absoluteCapacity=1.0, usedResources=<memory:49152, vCores:43>usedCapacity=1.0, absoluteUsedCapacity=1.0, numApps=5, numContainers=43
2013-08-09 12:25:10,367 INFO org.apache.hadoop.yarn.server.resourcemanager.scheduler.capacity.ParentQueue: assignedContainer queue=root usedCapacity=1.0 absoluteUsedCapacity=1.0 used=<memory:49152, vCores:43> cluster=<memory:49152, vCores:96>
2013-08-09 12:25:10,482 INFO org.apache.hadoop.yarn.server.resourcemanager.rmcontainer.RMContainerImpl: container_1376050148932_0006_01_000029 Container Transitioned from ACQUIRED to RUNNING
2013-08-09 12:25:11,100 INFO org.apache.hadoop.yarn.server.resourcemanager.rmcontainer.RMContainerImpl: container_1376050148932_0006_01_000011 Container Transitioned from RUNNING to COMPLETED
2013-08-09 12:25:11,100 INFO org.apache.hadoop.yarn.server.resourcemanager.scheduler.common.fica.FiCaSchedulerApp: Completed container: container_1376050148932_0006_01_000011 in state: COMPLETED event:FINISHED
2013-08-09 12:25:11,101 INFO org.apache.hadoop.yarn.server.resourcemanager.RMAuditLogger: USER=ubuntu	OPERATION=AM Released Container	TARGET=SchedulerApp	RESULT=SUCCESS	APPID=application_1376050148932_0006	CONTAINERID=container_1376050148932_0006_01_000011
2013-08-09 12:25:11,101 INFO org.apache.hadoop.yarn.server.resourcemanager.scheduler.common.fica.FiCaSchedulerNode: Released container container_1376050148932_0006_01_000011 of capacity <memory:1024, vCores:1> on host hadoop-210-7:41457, which currently has 6 containers, <memory:7168, vCores:6> used and <memory:1024, vCores:10> available, release resources=true
2013-08-09 12:25:11,101 INFO org.apache.hadoop.yarn.server.resourcemanager.scheduler.capacity.LeafQueue: default used=<memory:48128, vCores:42> numContainers=42 user=ubuntu user-resources=<memory:48128, vCores:42>
2013-08-09 12:25:11,102 INFO org.apache.hadoop.yarn.server.resourcemanager.scheduler.capacity.LeafQueue: completedContainer container=Container: [ContainerId: container_1376050148932_0006_01_000011, NodeId: hadoop-210-7:41457, NodeHttpAddress: hadoop-210-7:8042, Resource: <memory:1024, vCores:1>, Priority: 20, State: NEW, Token: null, Status: container_id {, app_attempt_id {, application_id {, id: 6, cluster_timestamp: 1376050148932, }, attemptId: 1, }, id: 11, }, state: C_COMPLETE, diagnostics: "Container killed by the ApplicationMaster.\n\n", exit_status: 143, ] resource=<memory:1024, vCores:1> queue=default: capacity=1.0, absoluteCapacity=1.0, usedResources=<memory:48128, vCores:42>usedCapacity=0.9791667, absoluteUsedCapacity=0.9791667, numApps=5, numContainers=42 usedCapacity=0.9791667 absoluteUsedCapacity=0.9791667 used=<memory:48128, vCores:42> cluster=<memory:49152, vCores:96>
2013-08-09 12:25:11,103 INFO org.apache.hadoop.yarn.server.resourcemanager.scheduler.capacity.ParentQueue: completedContainer queue=root usedCapacity=0.9791667 absoluteUsedCapacity=0.9791667 used=<memory:48128, vCores:42> cluster=<memory:49152, vCores:96>
2013-08-09 12:25:11,103 INFO org.apache.hadoop.yarn.server.resourcemanager.scheduler.capacity.CapacityScheduler: Application appattempt_1376050148932_0006_000001 released container container_1376050148932_0006_01_000011 on node: host: hadoop-210-7:41457 #containers=6 available=1024 used=7168 with event: FINISHED
2013-08-09 12:25:11,103 INFO org.apache.hadoop.yarn.server.resourcemanager.rmcontainer.RMContainerImpl: container_1376050148932_0006_01_000031 Container Transitioned from NEW to ALLOCATED
2013-08-09 12:25:11,103 INFO org.apache.hadoop.yarn.server.resourcemanager.RMAuditLogger: USER=ubuntu	OPERATION=AM Allocated Container	TARGET=SchedulerApp	RESULT=SUCCESS	APPID=application_1376050148932_0006	CONTAINERID=container_1376050148932_0006_01_000031
2013-08-09 12:25:11,103 INFO org.apache.hadoop.yarn.server.resourcemanager.scheduler.common.fica.FiCaSchedulerNode: Assigned container container_1376050148932_0006_01_000031 of capacity <memory:1024, vCores:1> on host hadoop-210-7:41457, which currently has 7 containers, <memory:8192, vCores:7> used and <memory:0, vCores:9> available
2013-08-09 12:25:11,104 INFO org.apache.hadoop.yarn.server.resourcemanager.scheduler.capacity.LeafQueue: assignedContainer application=application_1376050148932_0006 container=Container: [ContainerId: container_1376050148932_0006_01_000031, NodeId: hadoop-210-7:41457, NodeHttpAddress: hadoop-210-7:8042, Resource: <memory:1024, vCores:1>, Priority: 10, State: NEW, Token: null, Status: container_id {, app_attempt_id {, application_id {, id: 6, cluster_timestamp: 1376050148932, }, attemptId: 1, }, id: 31, }, state: C_NEW, ] containerId=container_1376050148932_0006_01_000031 queue=default: capacity=1.0, absoluteCapacity=1.0, usedResources=<memory:48128, vCores:42>usedCapacity=0.9791667, absoluteUsedCapacity=0.9791667, numApps=5, numContainers=42 usedCapacity=0.9791667 absoluteUsedCapacity=0.9791667 used=<memory:48128, vCores:42> cluster=<memory:49152, vCores:96>
2013-08-09 12:25:11,105 INFO org.apache.hadoop.yarn.server.resourcemanager.scheduler.capacity.ParentQueue: Re-sorting queues since queue: root.default stats: default: capacity=1.0, absoluteCapacity=1.0, usedResources=<memory:49152, vCores:43>usedCapacity=1.0, absoluteUsedCapacity=1.0, numApps=5, numContainers=43
2013-08-09 12:25:11,105 INFO org.apache.hadoop.yarn.server.resourcemanager.scheduler.capacity.ParentQueue: assignedContainer queue=root usedCapacity=1.0 absoluteUsedCapacity=1.0 used=<memory:49152, vCores:43> cluster=<memory:49152, vCores:96>
2013-08-09 12:25:11,305 INFO org.apache.hadoop.yarn.server.resourcemanager.rmcontainer.RMContainerImpl: container_1376050148932_0006_01_000030 Container Transitioned from ALLOCATED to ACQUIRED
2013-08-09 12:25:11,306 INFO org.apache.hadoop.yarn.server.resourcemanager.rmcontainer.RMContainerImpl: container_1376050148932_0006_01_000031 Container Transitioned from ALLOCATED to ACQUIRED
2013-08-09 12:25:11,391 INFO org.apache.hadoop.yarn.server.resourcemanager.rmcontainer.RMContainerImpl: container_1376050148932_0006_01_000030 Container Transitioned from ACQUIRED to RUNNING
2013-08-09 12:25:12,110 INFO org.apache.hadoop.yarn.server.resourcemanager.rmcontainer.RMContainerImpl: container_1376050148932_0006_01_000031 Container Transitioned from ACQUIRED to RUNNING
2013-08-09 12:25:12,314 INFO org.apache.hadoop.yarn.server.resourcemanager.scheduler.AppSchedulingInfo: checking for deactivate... 
2013-08-09 12:25:17,069 INFO org.apache.hadoop.yarn.server.resourcemanager.rmcontainer.RMContainerImpl: container_1376050148932_0006_01_000002 Container Transitioned from RUNNING to COMPLETED
2013-08-09 12:25:17,069 INFO org.apache.hadoop.yarn.server.resourcemanager.scheduler.common.fica.FiCaSchedulerApp: Completed container: container_1376050148932_0006_01_000002 in state: COMPLETED event:FINISHED
2013-08-09 12:25:17,069 INFO org.apache.hadoop.yarn.server.resourcemanager.RMAuditLogger: USER=ubuntu	OPERATION=AM Released Container	TARGET=SchedulerApp	RESULT=SUCCESS	APPID=application_1376050148932_0006	CONTAINERID=container_1376050148932_0006_01_000002
2013-08-09 12:25:17,070 INFO org.apache.hadoop.yarn.server.resourcemanager.scheduler.common.fica.FiCaSchedulerNode: Released container container_1376050148932_0006_01_000002 of capacity <memory:1024, vCores:1> on host hadoop-210-5:60822, which currently has 6 containers, <memory:7168, vCores:6> used and <memory:1024, vCores:10> available, release resources=true
2013-08-09 12:25:17,070 INFO org.apache.hadoop.yarn.server.resourcemanager.scheduler.capacity.LeafQueue: default used=<memory:48128, vCores:42> numContainers=42 user=ubuntu user-resources=<memory:48128, vCores:42>
2013-08-09 12:25:17,071 INFO org.apache.hadoop.yarn.server.resourcemanager.scheduler.capacity.LeafQueue: completedContainer container=Container: [ContainerId: container_1376050148932_0006_01_000002, NodeId: hadoop-210-5:60822, NodeHttpAddress: hadoop-210-5:8042, Resource: <memory:1024, vCores:1>, Priority: 20, State: NEW, Token: null, Status: container_id {, app_attempt_id {, application_id {, id: 6, cluster_timestamp: 1376050148932, }, attemptId: 1, }, id: 2, }, state: C_COMPLETE, diagnostics: "Container killed by the ApplicationMaster.\n\n", exit_status: 143, ] resource=<memory:1024, vCores:1> queue=default: capacity=1.0, absoluteCapacity=1.0, usedResources=<memory:48128, vCores:42>usedCapacity=0.9791667, absoluteUsedCapacity=0.9791667, numApps=5, numContainers=42 usedCapacity=0.9791667 absoluteUsedCapacity=0.9791667 used=<memory:48128, vCores:42> cluster=<memory:49152, vCores:96>
2013-08-09 12:25:17,071 INFO org.apache.hadoop.yarn.server.resourcemanager.scheduler.capacity.ParentQueue: completedContainer queue=root usedCapacity=0.9791667 absoluteUsedCapacity=0.9791667 used=<memory:48128, vCores:42> cluster=<memory:49152, vCores:96>
2013-08-09 12:25:17,071 INFO org.apache.hadoop.yarn.server.resourcemanager.scheduler.capacity.CapacityScheduler: Application appattempt_1376050148932_0006_000001 released container container_1376050148932_0006_01_000002 on node: host: hadoop-210-5:60822 #containers=6 available=1024 used=7168 with event: FINISHED
2013-08-09 12:25:17,072 INFO org.apache.hadoop.yarn.server.resourcemanager.rmcontainer.RMContainerImpl: container_1376050148932_0006_01_000032 Container Transitioned from NEW to ALLOCATED
2013-08-09 12:25:17,072 INFO org.apache.hadoop.yarn.server.resourcemanager.RMAuditLogger: USER=ubuntu	OPERATION=AM Allocated Container	TARGET=SchedulerApp	RESULT=SUCCESS	APPID=application_1376050148932_0006	CONTAINERID=container_1376050148932_0006_01_000032
2013-08-09 12:25:17,072 INFO org.apache.hadoop.yarn.server.resourcemanager.scheduler.common.fica.FiCaSchedulerNode: Assigned container container_1376050148932_0006_01_000032 of capacity <memory:1024, vCores:1> on host hadoop-210-5:60822, which currently has 7 containers, <memory:8192, vCores:7> used and <memory:0, vCores:9> available
2013-08-09 12:25:17,073 INFO org.apache.hadoop.yarn.server.resourcemanager.scheduler.capacity.LeafQueue: assignedContainer application=application_1376050148932_0006 container=Container: [ContainerId: container_1376050148932_0006_01_000032, NodeId: hadoop-210-5:60822, NodeHttpAddress: hadoop-210-5:8042, Resource: <memory:1024, vCores:1>, Priority: 20, State: NEW, Token: null, Status: container_id {, app_attempt_id {, application_id {, id: 6, cluster_timestamp: 1376050148932, }, attemptId: 1, }, id: 32, }, state: C_NEW, ] containerId=container_1376050148932_0006_01_000032 queue=default: capacity=1.0, absoluteCapacity=1.0, usedResources=<memory:48128, vCores:42>usedCapacity=0.9791667, absoluteUsedCapacity=0.9791667, numApps=5, numContainers=42 usedCapacity=0.9791667 absoluteUsedCapacity=0.9791667 used=<memory:48128, vCores:42> cluster=<memory:49152, vCores:96>
2013-08-09 12:25:17,074 INFO org.apache.hadoop.yarn.server.resourcemanager.scheduler.capacity.ParentQueue: Re-sorting queues since queue: root.default stats: default: capacity=1.0, absoluteCapacity=1.0, usedResources=<memory:49152, vCores:43>usedCapacity=1.0, absoluteUsedCapacity=1.0, numApps=5, numContainers=43
2013-08-09 12:25:17,074 INFO org.apache.hadoop.yarn.server.resourcemanager.scheduler.capacity.ParentQueue: assignedContainer queue=root usedCapacity=1.0 absoluteUsedCapacity=1.0 used=<memory:49152, vCores:43> cluster=<memory:49152, vCores:96>
2013-08-09 12:25:17,346 INFO org.apache.hadoop.yarn.server.resourcemanager.rmcontainer.RMContainerImpl: container_1376050148932_0006_01_000032 Container Transitioned from ALLOCATED to ACQUIRED
2013-08-09 12:25:17,739 INFO org.apache.hadoop.yarn.server.resourcemanager.rmcontainer.RMContainerImpl: container_1376050148932_0006_01_000016 Container Transitioned from RUNNING to COMPLETED
2013-08-09 12:25:17,739 INFO org.apache.hadoop.yarn.server.resourcemanager.scheduler.common.fica.FiCaSchedulerApp: Completed container: container_1376050148932_0006_01_000016 in state: COMPLETED event:FINISHED
2013-08-09 12:25:17,739 INFO org.apache.hadoop.yarn.server.resourcemanager.RMAuditLogger: USER=ubuntu	OPERATION=AM Released Container	TARGET=SchedulerApp	RESULT=SUCCESS	APPID=application_1376050148932_0006	CONTAINERID=container_1376050148932_0006_01_000016
2013-08-09 12:25:17,740 INFO org.apache.hadoop.yarn.server.resourcemanager.scheduler.common.fica.FiCaSchedulerNode: Released container container_1376050148932_0006_01_000016 of capacity <memory:1024, vCores:1> on host hadoop-210-3:36255, which currently has 6 containers, <memory:7168, vCores:6> used and <memory:1024, vCores:10> available, release resources=true
2013-08-09 12:25:17,740 INFO org.apache.hadoop.yarn.server.resourcemanager.scheduler.capacity.LeafQueue: default used=<memory:48128, vCores:42> numContainers=42 user=ubuntu user-resources=<memory:48128, vCores:42>
2013-08-09 12:25:17,741 INFO org.apache.hadoop.yarn.server.resourcemanager.scheduler.capacity.LeafQueue: completedContainer container=Container: [ContainerId: container_1376050148932_0006_01_000016, NodeId: hadoop-210-3:36255, NodeHttpAddress: hadoop-210-3:8042, Resource: <memory:1024, vCores:1>, Priority: 20, State: NEW, Token: null, Status: container_id {, app_attempt_id {, application_id {, id: 6, cluster_timestamp: 1376050148932, }, attemptId: 1, }, id: 16, }, state: C_COMPLETE, diagnostics: "Container killed by the ApplicationMaster.\n\n", exit_status: 143, ] resource=<memory:1024, vCores:1> queue=default: capacity=1.0, absoluteCapacity=1.0, usedResources=<memory:48128, vCores:42>usedCapacity=0.9791667, absoluteUsedCapacity=0.9791667, numApps=5, numContainers=42 usedCapacity=0.9791667 absoluteUsedCapacity=0.9791667 used=<memory:48128, vCores:42> cluster=<memory:49152, vCores:96>
2013-08-09 12:25:17,741 INFO org.apache.hadoop.yarn.server.resourcemanager.scheduler.capacity.ParentQueue: completedContainer queue=root usedCapacity=0.9791667 absoluteUsedCapacity=0.9791667 used=<memory:48128, vCores:42> cluster=<memory:49152, vCores:96>
2013-08-09 12:25:17,741 INFO org.apache.hadoop.yarn.server.resourcemanager.scheduler.capacity.CapacityScheduler: Application appattempt_1376050148932_0006_000001 released container container_1376050148932_0006_01_000016 on node: host: hadoop-210-3:36255 #containers=6 available=1024 used=7168 with event: FINISHED
2013-08-09 12:25:17,742 INFO org.apache.hadoop.yarn.server.resourcemanager.rmcontainer.RMContainerImpl: container_1376050148932_0006_01_000033 Container Transitioned from NEW to ALLOCATED
2013-08-09 12:25:17,742 INFO org.apache.hadoop.yarn.server.resourcemanager.RMAuditLogger: USER=ubuntu	OPERATION=AM Allocated Container	TARGET=SchedulerApp	RESULT=SUCCESS	APPID=application_1376050148932_0006	CONTAINERID=container_1376050148932_0006_01_000033
2013-08-09 12:25:17,742 INFO org.apache.hadoop.yarn.server.resourcemanager.scheduler.common.fica.FiCaSchedulerNode: Assigned container container_1376050148932_0006_01_000033 of capacity <memory:1024, vCores:1> on host hadoop-210-3:36255, which currently has 7 containers, <memory:8192, vCores:7> used and <memory:0, vCores:9> available
2013-08-09 12:25:17,743 INFO org.apache.hadoop.yarn.server.resourcemanager.scheduler.capacity.LeafQueue: assignedContainer application=application_1376050148932_0006 container=Container: [ContainerId: container_1376050148932_0006_01_000033, NodeId: hadoop-210-3:36255, NodeHttpAddress: hadoop-210-3:8042, Resource: <memory:1024, vCores:1>, Priority: 10, State: NEW, Token: null, Status: container_id {, app_attempt_id {, application_id {, id: 6, cluster_timestamp: 1376050148932, }, attemptId: 1, }, id: 33, }, state: C_NEW, ] containerId=container_1376050148932_0006_01_000033 queue=default: capacity=1.0, absoluteCapacity=1.0, usedResources=<memory:48128, vCores:42>usedCapacity=0.9791667, absoluteUsedCapacity=0.9791667, numApps=5, numContainers=42 usedCapacity=0.9791667 absoluteUsedCapacity=0.9791667 used=<memory:48128, vCores:42> cluster=<memory:49152, vCores:96>
2013-08-09 12:25:17,743 INFO org.apache.hadoop.yarn.server.resourcemanager.scheduler.capacity.ParentQueue: Re-sorting queues since queue: root.default stats: default: capacity=1.0, absoluteCapacity=1.0, usedResources=<memory:49152, vCores:43>usedCapacity=1.0, absoluteUsedCapacity=1.0, numApps=5, numContainers=43
2013-08-09 12:25:17,743 INFO org.apache.hadoop.yarn.server.resourcemanager.scheduler.capacity.ParentQueue: assignedContainer queue=root usedCapacity=1.0 absoluteUsedCapacity=1.0 used=<memory:49152, vCores:43> cluster=<memory:49152, vCores:96>
2013-08-09 12:25:18,075 INFO org.apache.hadoop.yarn.server.resourcemanager.rmcontainer.RMContainerImpl: container_1376050148932_0006_01_000032 Container Transitioned from ACQUIRED to RUNNING
2013-08-09 12:25:18,172 INFO org.apache.hadoop.yarn.server.resourcemanager.rmcontainer.RMContainerImpl: container_1376050148932_0007_01_000009 Container Transitioned from RUNNING to COMPLETED
2013-08-09 12:25:18,172 INFO org.apache.hadoop.yarn.server.resourcemanager.scheduler.common.fica.FiCaSchedulerApp: Completed container: container_1376050148932_0007_01_000009 in state: COMPLETED event:FINISHED
2013-08-09 12:25:18,172 INFO org.apache.hadoop.yarn.server.resourcemanager.RMAuditLogger: USER=ubuntu	OPERATION=AM Released Container	TARGET=SchedulerApp	RESULT=SUCCESS	APPID=application_1376050148932_0007	CONTAINERID=container_1376050148932_0007_01_000009
2013-08-09 12:25:18,173 INFO org.apache.hadoop.yarn.server.resourcemanager.scheduler.common.fica.FiCaSchedulerNode: Released container container_1376050148932_0007_01_000009 of capacity <memory:1024, vCores:1> on host hadoop-210-6:38267, which currently has 7 containers, <memory:7168, vCores:7> used and <memory:1024, vCores:9> available, release resources=true
2013-08-09 12:25:18,173 INFO org.apache.hadoop.yarn.server.resourcemanager.scheduler.capacity.LeafQueue: default used=<memory:48128, vCores:42> numContainers=42 user=ubuntu user-resources=<memory:48128, vCores:42>
2013-08-09 12:25:18,174 INFO org.apache.hadoop.yarn.server.resourcemanager.scheduler.capacity.LeafQueue: completedContainer container=Container: [ContainerId: container_1376050148932_0007_01_000009, NodeId: hadoop-210-6:38267, NodeHttpAddress: hadoop-210-6:8042, Resource: <memory:1024, vCores:1>, Priority: 20, State: NEW, Token: null, Status: container_id {, app_attempt_id {, application_id {, id: 7, cluster_timestamp: 1376050148932, }, attemptId: 1, }, id: 9, }, state: C_COMPLETE, diagnostics: "Container killed by the ApplicationMaster.\n\n", exit_status: 143, ] resource=<memory:1024, vCores:1> queue=default: capacity=1.0, absoluteCapacity=1.0, usedResources=<memory:48128, vCores:42>usedCapacity=0.9791667, absoluteUsedCapacity=0.9791667, numApps=5, numContainers=42 usedCapacity=0.9791667 absoluteUsedCapacity=0.9791667 used=<memory:48128, vCores:42> cluster=<memory:49152, vCores:96>
2013-08-09 12:25:18,174 INFO org.apache.hadoop.yarn.server.resourcemanager.scheduler.capacity.ParentQueue: completedContainer queue=root usedCapacity=0.9791667 absoluteUsedCapacity=0.9791667 used=<memory:48128, vCores:42> cluster=<memory:49152, vCores:96>
2013-08-09 12:25:18,174 INFO org.apache.hadoop.yarn.server.resourcemanager.scheduler.capacity.CapacityScheduler: Application appattempt_1376050148932_0007_000001 released container container_1376050148932_0007_01_000009 on node: host: hadoop-210-6:38267 #containers=7 available=1024 used=7168 with event: FINISHED
2013-08-09 12:25:18,175 INFO org.apache.hadoop.yarn.server.resourcemanager.rmcontainer.RMContainerImpl: container_1376050148932_0006_01_000034 Container Transitioned from NEW to ALLOCATED
2013-08-09 12:25:18,175 INFO org.apache.hadoop.yarn.server.resourcemanager.RMAuditLogger: USER=ubuntu	OPERATION=AM Allocated Container	TARGET=SchedulerApp	RESULT=SUCCESS	APPID=application_1376050148932_0006	CONTAINERID=container_1376050148932_0006_01_000034
2013-08-09 12:25:18,175 INFO org.apache.hadoop.yarn.server.resourcemanager.scheduler.common.fica.FiCaSchedulerNode: Assigned container container_1376050148932_0006_01_000034 of capacity <memory:1024, vCores:1> on host hadoop-210-6:38267, which currently has 8 containers, <memory:8192, vCores:8> used and <memory:0, vCores:8> available
2013-08-09 12:25:18,176 INFO org.apache.hadoop.yarn.server.resourcemanager.scheduler.capacity.LeafQueue: assignedContainer application=application_1376050148932_0006 container=Container: [ContainerId: container_1376050148932_0006_01_000034, NodeId: hadoop-210-6:38267, NodeHttpAddress: hadoop-210-6:8042, Resource: <memory:1024, vCores:1>, Priority: 20, State: NEW, Token: null, Status: container_id {, app_attempt_id {, application_id {, id: 6, cluster_timestamp: 1376050148932, }, attemptId: 1, }, id: 34, }, state: C_NEW, ] containerId=container_1376050148932_0006_01_000034 queue=default: capacity=1.0, absoluteCapacity=1.0, usedResources=<memory:48128, vCores:42>usedCapacity=0.9791667, absoluteUsedCapacity=0.9791667, numApps=5, numContainers=42 usedCapacity=0.9791667 absoluteUsedCapacity=0.9791667 used=<memory:48128, vCores:42> cluster=<memory:49152, vCores:96>
2013-08-09 12:25:18,176 INFO org.apache.hadoop.yarn.server.resourcemanager.scheduler.capacity.ParentQueue: Re-sorting queues since queue: root.default stats: default: capacity=1.0, absoluteCapacity=1.0, usedResources=<memory:49152, vCores:43>usedCapacity=1.0, absoluteUsedCapacity=1.0, numApps=5, numContainers=43
2013-08-09 12:25:18,176 INFO org.apache.hadoop.yarn.server.resourcemanager.scheduler.capacity.ParentQueue: assignedContainer queue=root usedCapacity=1.0 absoluteUsedCapacity=1.0 used=<memory:49152, vCores:43> cluster=<memory:49152, vCores:96>
2013-08-09 12:25:18,353 INFO org.apache.hadoop.yarn.server.resourcemanager.rmcontainer.RMContainerImpl: container_1376050148932_0006_01_000033 Container Transitioned from ALLOCATED to ACQUIRED
2013-08-09 12:25:18,354 INFO org.apache.hadoop.yarn.server.resourcemanager.rmcontainer.RMContainerImpl: container_1376050148932_0006_01_000034 Container Transitioned from ALLOCATED to ACQUIRED
2013-08-09 12:25:18,747 INFO org.apache.hadoop.yarn.server.resourcemanager.rmcontainer.RMContainerImpl: container_1376050148932_0006_01_000033 Container Transitioned from ACQUIRED to RUNNING
2013-08-09 12:25:19,179 INFO org.apache.hadoop.yarn.server.resourcemanager.rmcontainer.RMContainerImpl: container_1376050148932_0006_01_000034 Container Transitioned from ACQUIRED to RUNNING
2013-08-09 12:25:24,138 INFO org.apache.hadoop.yarn.server.resourcemanager.rmcontainer.RMContainerImpl: container_1376050148932_0006_01_000006 Container Transitioned from RUNNING to COMPLETED
2013-08-09 12:25:24,138 INFO org.apache.hadoop.yarn.server.resourcemanager.scheduler.common.fica.FiCaSchedulerApp: Completed container: container_1376050148932_0006_01_000006 in state: COMPLETED event:FINISHED
2013-08-09 12:25:24,138 INFO org.apache.hadoop.yarn.server.resourcemanager.RMAuditLogger: USER=ubuntu	OPERATION=AM Released Container	TARGET=SchedulerApp	RESULT=SUCCESS	APPID=application_1376050148932_0006	CONTAINERID=container_1376050148932_0006_01_000006
2013-08-09 12:25:24,138 INFO org.apache.hadoop.yarn.server.resourcemanager.scheduler.common.fica.FiCaSchedulerNode: Released container container_1376050148932_0006_01_000006 of capacity <memory:1024, vCores:1> on host hadoop-210-5:60822, which currently has 6 containers, <memory:7168, vCores:6> used and <memory:1024, vCores:10> available, release resources=true
2013-08-09 12:25:24,139 INFO org.apache.hadoop.yarn.server.resourcemanager.scheduler.capacity.LeafQueue: default used=<memory:48128, vCores:42> numContainers=42 user=ubuntu user-resources=<memory:48128, vCores:42>
2013-08-09 12:25:24,140 INFO org.apache.hadoop.yarn.server.resourcemanager.scheduler.capacity.LeafQueue: completedContainer container=Container: [ContainerId: container_1376050148932_0006_01_000006, NodeId: hadoop-210-5:60822, NodeHttpAddress: hadoop-210-5:8042, Resource: <memory:1024, vCores:1>, Priority: 20, State: NEW, Token: null, Status: container_id {, app_attempt_id {, application_id {, id: 6, cluster_timestamp: 1376050148932, }, attemptId: 1, }, id: 6, }, state: C_COMPLETE, diagnostics: "Container killed by the ApplicationMaster.\n\n", exit_status: 143, ] resource=<memory:1024, vCores:1> queue=default: capacity=1.0, absoluteCapacity=1.0, usedResources=<memory:48128, vCores:42>usedCapacity=0.9791667, absoluteUsedCapacity=0.9791667, numApps=5, numContainers=42 usedCapacity=0.9791667 absoluteUsedCapacity=0.9791667 used=<memory:48128, vCores:42> cluster=<memory:49152, vCores:96>
2013-08-09 12:25:24,140 INFO org.apache.hadoop.yarn.server.resourcemanager.scheduler.capacity.ParentQueue: completedContainer queue=root usedCapacity=0.9791667 absoluteUsedCapacity=0.9791667 used=<memory:48128, vCores:42> cluster=<memory:49152, vCores:96>
2013-08-09 12:25:24,140 INFO org.apache.hadoop.yarn.server.resourcemanager.scheduler.capacity.CapacityScheduler: Application appattempt_1376050148932_0006_000001 released container container_1376050148932_0006_01_000006 on node: host: hadoop-210-5:60822 #containers=6 available=1024 used=7168 with event: FINISHED
2013-08-09 12:25:24,141 INFO org.apache.hadoop.yarn.server.resourcemanager.rmcontainer.RMContainerImpl: container_1376050148932_0006_01_000035 Container Transitioned from NEW to ALLOCATED
2013-08-09 12:25:24,141 INFO org.apache.hadoop.yarn.server.resourcemanager.RMAuditLogger: USER=ubuntu	OPERATION=AM Allocated Container	TARGET=SchedulerApp	RESULT=SUCCESS	APPID=application_1376050148932_0006	CONTAINERID=container_1376050148932_0006_01_000035
2013-08-09 12:25:24,141 INFO org.apache.hadoop.yarn.server.resourcemanager.scheduler.common.fica.FiCaSchedulerNode: Assigned container container_1376050148932_0006_01_000035 of capacity <memory:1024, vCores:1> on host hadoop-210-5:60822, which currently has 7 containers, <memory:8192, vCores:7> used and <memory:0, vCores:9> available
2013-08-09 12:25:24,142 INFO org.apache.hadoop.yarn.server.resourcemanager.scheduler.capacity.LeafQueue: assignedContainer application=application_1376050148932_0006 container=Container: [ContainerId: container_1376050148932_0006_01_000035, NodeId: hadoop-210-5:60822, NodeHttpAddress: hadoop-210-5:8042, Resource: <memory:1024, vCores:1>, Priority: 10, State: NEW, Token: null, Status: container_id {, app_attempt_id {, application_id {, id: 6, cluster_timestamp: 1376050148932, }, attemptId: 1, }, id: 35, }, state: C_NEW, ] containerId=container_1376050148932_0006_01_000035 queue=default: capacity=1.0, absoluteCapacity=1.0, usedResources=<memory:48128, vCores:42>usedCapacity=0.9791667, absoluteUsedCapacity=0.9791667, numApps=5, numContainers=42 usedCapacity=0.9791667 absoluteUsedCapacity=0.9791667 used=<memory:48128, vCores:42> cluster=<memory:49152, vCores:96>
2013-08-09 12:25:24,142 INFO org.apache.hadoop.yarn.server.resourcemanager.scheduler.capacity.ParentQueue: Re-sorting queues since queue: root.default stats: default: capacity=1.0, absoluteCapacity=1.0, usedResources=<memory:49152, vCores:43>usedCapacity=1.0, absoluteUsedCapacity=1.0, numApps=5, numContainers=43
2013-08-09 12:25:24,142 INFO org.apache.hadoop.yarn.server.resourcemanager.scheduler.capacity.ParentQueue: assignedContainer queue=root usedCapacity=1.0 absoluteUsedCapacity=1.0 used=<memory:49152, vCores:43> cluster=<memory:49152, vCores:96>
2013-08-09 12:25:24,409 INFO org.apache.hadoop.yarn.server.resourcemanager.rmcontainer.RMContainerImpl: container_1376050148932_0006_01_000035 Container Transitioned from ALLOCATED to ACQUIRED
2013-08-09 12:25:25,153 INFO org.apache.hadoop.yarn.server.resourcemanager.rmcontainer.RMContainerImpl: container_1376050148932_0006_01_000035 Container Transitioned from ACQUIRED to RUNNING
2013-08-09 12:25:25,429 INFO org.apache.hadoop.yarn.server.resourcemanager.scheduler.AppSchedulingInfo: checking for deactivate... 
2013-08-09 12:25:25,451 INFO org.apache.hadoop.yarn.server.resourcemanager.rmcontainer.RMContainerImpl: container_1376050148932_0007_01_000015 Container Transitioned from RUNNING to COMPLETED
2013-08-09 12:25:25,451 INFO org.apache.hadoop.yarn.server.resourcemanager.scheduler.common.fica.FiCaSchedulerApp: Completed container: container_1376050148932_0007_01_000015 in state: COMPLETED event:FINISHED
2013-08-09 12:25:25,452 INFO org.apache.hadoop.yarn.server.resourcemanager.RMAuditLogger: USER=ubuntu	OPERATION=AM Released Container	TARGET=SchedulerApp	RESULT=SUCCESS	APPID=application_1376050148932_0007	CONTAINERID=container_1376050148932_0007_01_000015
2013-08-09 12:25:25,452 INFO org.apache.hadoop.yarn.server.resourcemanager.scheduler.common.fica.FiCaSchedulerNode: Released container container_1376050148932_0007_01_000015 of capacity <memory:1024, vCores:1> on host hadoop-210-4:57908, which currently has 6 containers, <memory:7168, vCores:6> used and <memory:1024, vCores:10> available, release resources=true
2013-08-09 12:25:25,452 INFO org.apache.hadoop.yarn.server.resourcemanager.scheduler.capacity.LeafQueue: default used=<memory:48128, vCores:42> numContainers=42 user=ubuntu user-resources=<memory:48128, vCores:42>
2013-08-09 12:25:25,453 INFO org.apache.hadoop.yarn.server.resourcemanager.scheduler.capacity.LeafQueue: completedContainer container=Container: [ContainerId: container_1376050148932_0007_01_000015, NodeId: hadoop-210-4:57908, NodeHttpAddress: hadoop-210-4:8042, Resource: <memory:1024, vCores:1>, Priority: 20, State: NEW, Token: null, Status: container_id {, app_attempt_id {, application_id {, id: 7, cluster_timestamp: 1376050148932, }, attemptId: 1, }, id: 15, }, state: C_COMPLETE, diagnostics: "Container killed by the ApplicationMaster.\n", exit_status: 0, ] resource=<memory:1024, vCores:1> queue=default: capacity=1.0, absoluteCapacity=1.0, usedResources=<memory:48128, vCores:42>usedCapacity=0.9791667, absoluteUsedCapacity=0.9791667, numApps=5, numContainers=42 usedCapacity=0.9791667 absoluteUsedCapacity=0.9791667 used=<memory:48128, vCores:42> cluster=<memory:49152, vCores:96>
2013-08-09 12:25:25,453 INFO org.apache.hadoop.yarn.server.resourcemanager.scheduler.capacity.ParentQueue: completedContainer queue=root usedCapacity=0.9791667 absoluteUsedCapacity=0.9791667 used=<memory:48128, vCores:42> cluster=<memory:49152, vCores:96>
2013-08-09 12:25:25,453 INFO org.apache.hadoop.yarn.server.resourcemanager.scheduler.capacity.CapacityScheduler: Application appattempt_1376050148932_0007_000001 released container container_1376050148932_0007_01_000015 on node: host: hadoop-210-4:57908 #containers=6 available=1024 used=7168 with event: FINISHED
2013-08-09 12:25:25,454 INFO org.apache.hadoop.yarn.server.resourcemanager.rmcontainer.RMContainerImpl: container_1376050148932_0006_01_000036 Container Transitioned from NEW to ALLOCATED
2013-08-09 12:25:25,454 INFO org.apache.hadoop.yarn.server.resourcemanager.RMAuditLogger: USER=ubuntu	OPERATION=AM Allocated Container	TARGET=SchedulerApp	RESULT=SUCCESS	APPID=application_1376050148932_0006	CONTAINERID=container_1376050148932_0006_01_000036
2013-08-09 12:25:25,454 INFO org.apache.hadoop.yarn.server.resourcemanager.scheduler.common.fica.FiCaSchedulerNode: Assigned container container_1376050148932_0006_01_000036 of capacity <memory:1024, vCores:1> on host hadoop-210-4:57908, which currently has 7 containers, <memory:8192, vCores:7> used and <memory:0, vCores:9> available
2013-08-09 12:25:25,455 INFO org.apache.hadoop.yarn.server.resourcemanager.scheduler.capacity.LeafQueue: assignedContainer application=application_1376050148932_0006 container=Container: [ContainerId: container_1376050148932_0006_01_000036, NodeId: hadoop-210-4:57908, NodeHttpAddress: hadoop-210-4:8042, Resource: <memory:1024, vCores:1>, Priority: 20, State: NEW, Token: null, Status: container_id {, app_attempt_id {, application_id {, id: 6, cluster_timestamp: 1376050148932, }, attemptId: 1, }, id: 36, }, state: C_NEW, ] containerId=container_1376050148932_0006_01_000036 queue=default: capacity=1.0, absoluteCapacity=1.0, usedResources=<memory:48128, vCores:42>usedCapacity=0.9791667, absoluteUsedCapacity=0.9791667, numApps=5, numContainers=42 usedCapacity=0.9791667 absoluteUsedCapacity=0.9791667 used=<memory:48128, vCores:42> cluster=<memory:49152, vCores:96>
2013-08-09 12:25:25,456 INFO org.apache.hadoop.yarn.server.resourcemanager.scheduler.capacity.ParentQueue: Re-sorting queues since queue: root.default stats: default: capacity=1.0, absoluteCapacity=1.0, usedResources=<memory:49152, vCores:43>usedCapacity=1.0, absoluteUsedCapacity=1.0, numApps=5, numContainers=43
2013-08-09 12:25:25,456 INFO org.apache.hadoop.yarn.server.resourcemanager.scheduler.capacity.ParentQueue: assignedContainer queue=root usedCapacity=1.0 absoluteUsedCapacity=1.0 used=<memory:49152, vCores:43> cluster=<memory:49152, vCores:96>
2013-08-09 12:25:26,435 INFO org.apache.hadoop.yarn.server.resourcemanager.rmcontainer.RMContainerImpl: container_1376050148932_0006_01_000036 Container Transitioned from ALLOCATED to ACQUIRED
2013-08-09 12:25:27,466 INFO org.apache.hadoop.yarn.server.resourcemanager.rmcontainer.RMContainerImpl: container_1376050148932_0006_01_000036 Container Transitioned from ACQUIRED to RUNNING
2013-08-09 12:25:30,773 INFO org.apache.hadoop.yarn.server.resourcemanager.rmcontainer.RMContainerImpl: container_1376050148932_0007_01_000010 Container Transitioned from RUNNING to COMPLETED
2013-08-09 12:25:30,773 INFO org.apache.hadoop.yarn.server.resourcemanager.scheduler.common.fica.FiCaSchedulerApp: Completed container: container_1376050148932_0007_01_000010 in state: COMPLETED event:FINISHED
2013-08-09 12:25:30,773 INFO org.apache.hadoop.yarn.server.resourcemanager.RMAuditLogger: USER=ubuntu	OPERATION=AM Released Container	TARGET=SchedulerApp	RESULT=SUCCESS	APPID=application_1376050148932_0007	CONTAINERID=container_1376050148932_0007_01_000010
2013-08-09 12:25:30,773 INFO org.apache.hadoop.yarn.server.resourcemanager.scheduler.common.fica.FiCaSchedulerNode: Released container container_1376050148932_0007_01_000010 of capacity <memory:1024, vCores:1> on host hadoop-210-4:57908, which currently has 6 containers, <memory:7168, vCores:6> used and <memory:1024, vCores:10> available, release resources=true
2013-08-09 12:25:30,774 INFO org.apache.hadoop.yarn.server.resourcemanager.scheduler.capacity.LeafQueue: default used=<memory:48128, vCores:42> numContainers=42 user=ubuntu user-resources=<memory:48128, vCores:42>
2013-08-09 12:25:30,775 INFO org.apache.hadoop.yarn.server.resourcemanager.scheduler.capacity.LeafQueue: completedContainer container=Container: [ContainerId: container_1376050148932_0007_01_000010, NodeId: hadoop-210-4:57908, NodeHttpAddress: hadoop-210-4:8042, Resource: <memory:1024, vCores:1>, Priority: 20, State: NEW, Token: null, Status: container_id {, app_attempt_id {, application_id {, id: 7, cluster_timestamp: 1376050148932, }, attemptId: 1, }, id: 10, }, state: C_COMPLETE, diagnostics: "Container killed by the ApplicationMaster.\n\n", exit_status: 143, ] resource=<memory:1024, vCores:1> queue=default: capacity=1.0, absoluteCapacity=1.0, usedResources=<memory:48128, vCores:42>usedCapacity=0.9791667, absoluteUsedCapacity=0.9791667, numApps=5, numContainers=42 usedCapacity=0.9791667 absoluteUsedCapacity=0.9791667 used=<memory:48128, vCores:42> cluster=<memory:49152, vCores:96>
2013-08-09 12:25:30,775 INFO org.apache.hadoop.yarn.server.resourcemanager.scheduler.capacity.ParentQueue: completedContainer queue=root usedCapacity=0.9791667 absoluteUsedCapacity=0.9791667 used=<memory:48128, vCores:42> cluster=<memory:49152, vCores:96>
2013-08-09 12:25:30,775 INFO org.apache.hadoop.yarn.server.resourcemanager.scheduler.capacity.CapacityScheduler: Application appattempt_1376050148932_0007_000001 released container container_1376050148932_0007_01_000010 on node: host: hadoop-210-4:57908 #containers=6 available=1024 used=7168 with event: FINISHED
2013-08-09 12:25:30,775 INFO org.apache.hadoop.yarn.server.resourcemanager.rmcontainer.RMContainerImpl: container_1376050148932_0007_01_000012 Container Transitioned from RUNNING to COMPLETED
2013-08-09 12:25:30,775 INFO org.apache.hadoop.yarn.server.resourcemanager.scheduler.common.fica.FiCaSchedulerApp: Completed container: container_1376050148932_0007_01_000012 in state: COMPLETED event:FINISHED
2013-08-09 12:25:30,776 INFO org.apache.hadoop.yarn.server.resourcemanager.RMAuditLogger: USER=ubuntu	OPERATION=AM Released Container	TARGET=SchedulerApp	RESULT=SUCCESS	APPID=application_1376050148932_0007	CONTAINERID=container_1376050148932_0007_01_000012
2013-08-09 12:25:30,776 INFO org.apache.hadoop.yarn.server.resourcemanager.scheduler.common.fica.FiCaSchedulerNode: Released container container_1376050148932_0007_01_000012 of capacity <memory:1024, vCores:1> on host hadoop-210-4:57908, which currently has 5 containers, <memory:6144, vCores:5> used and <memory:2048, vCores:11> available, release resources=true
2013-08-09 12:25:30,776 INFO org.apache.hadoop.yarn.server.resourcemanager.scheduler.capacity.LeafQueue: default used=<memory:47104, vCores:41> numContainers=41 user=ubuntu user-resources=<memory:47104, vCores:41>
2013-08-09 12:25:30,777 INFO org.apache.hadoop.yarn.server.resourcemanager.scheduler.capacity.LeafQueue: completedContainer container=Container: [ContainerId: container_1376050148932_0007_01_000012, NodeId: hadoop-210-4:57908, NodeHttpAddress: hadoop-210-4:8042, Resource: <memory:1024, vCores:1>, Priority: 20, State: NEW, Token: null, Status: container_id {, app_attempt_id {, application_id {, id: 7, cluster_timestamp: 1376050148932, }, attemptId: 1, }, id: 12, }, state: C_COMPLETE, diagnostics: "Container killed by the ApplicationMaster.\n\n", exit_status: 143, ] resource=<memory:1024, vCores:1> queue=default: capacity=1.0, absoluteCapacity=1.0, usedResources=<memory:47104, vCores:41>usedCapacity=0.9583333, absoluteUsedCapacity=0.9583333, numApps=5, numContainers=41 usedCapacity=0.9583333 absoluteUsedCapacity=0.9583333 used=<memory:47104, vCores:41> cluster=<memory:49152, vCores:96>
2013-08-09 12:25:30,777 INFO org.apache.hadoop.yarn.server.resourcemanager.scheduler.capacity.ParentQueue: completedContainer queue=root usedCapacity=0.9583333 absoluteUsedCapacity=0.9583333 used=<memory:47104, vCores:41> cluster=<memory:49152, vCores:96>
2013-08-09 12:25:30,777 INFO org.apache.hadoop.yarn.server.resourcemanager.scheduler.capacity.CapacityScheduler: Application appattempt_1376050148932_0007_000001 released container container_1376050148932_0007_01_000012 on node: host: hadoop-210-4:57908 #containers=5 available=2048 used=6144 with event: FINISHED
2013-08-09 12:25:30,778 INFO org.apache.hadoop.yarn.server.resourcemanager.rmcontainer.RMContainerImpl: container_1376050148932_0006_01_000037 Container Transitioned from NEW to ALLOCATED
2013-08-09 12:25:30,778 INFO org.apache.hadoop.yarn.server.resourcemanager.RMAuditLogger: USER=ubuntu	OPERATION=AM Allocated Container	TARGET=SchedulerApp	RESULT=SUCCESS	APPID=application_1376050148932_0006	CONTAINERID=container_1376050148932_0006_01_000037
2013-08-09 12:25:30,778 INFO org.apache.hadoop.yarn.server.resourcemanager.scheduler.common.fica.FiCaSchedulerNode: Assigned container container_1376050148932_0006_01_000037 of capacity <memory:1024, vCores:1> on host hadoop-210-4:57908, which currently has 6 containers, <memory:7168, vCores:6> used and <memory:1024, vCores:10> available
2013-08-09 12:25:30,779 INFO org.apache.hadoop.yarn.server.resourcemanager.scheduler.capacity.LeafQueue: assignedContainer application=application_1376050148932_0006 container=Container: [ContainerId: container_1376050148932_0006_01_000037, NodeId: hadoop-210-4:57908, NodeHttpAddress: hadoop-210-4:8042, Resource: <memory:1024, vCores:1>, Priority: 20, State: NEW, Token: null, Status: container_id {, app_attempt_id {, application_id {, id: 6, cluster_timestamp: 1376050148932, }, attemptId: 1, }, id: 37, }, state: C_NEW, ] containerId=container_1376050148932_0006_01_000037 queue=default: capacity=1.0, absoluteCapacity=1.0, usedResources=<memory:47104, vCores:41>usedCapacity=0.9583333, absoluteUsedCapacity=0.9583333, numApps=5, numContainers=41 usedCapacity=0.9583333 absoluteUsedCapacity=0.9583333 used=<memory:47104, vCores:41> cluster=<memory:49152, vCores:96>
2013-08-09 12:25:30,779 INFO org.apache.hadoop.yarn.server.resourcemanager.scheduler.capacity.ParentQueue: Re-sorting queues since queue: root.default stats: default: capacity=1.0, absoluteCapacity=1.0, usedResources=<memory:48128, vCores:42>usedCapacity=0.9791667, absoluteUsedCapacity=0.9791667, numApps=5, numContainers=42
2013-08-09 12:25:30,779 INFO org.apache.hadoop.yarn.server.resourcemanager.scheduler.capacity.ParentQueue: assignedContainer queue=root usedCapacity=0.9791667 absoluteUsedCapacity=0.9791667 used=<memory:48128, vCores:42> cluster=<memory:49152, vCores:96>
2013-08-09 12:25:30,779 INFO org.apache.hadoop.yarn.server.resourcemanager.rmcontainer.RMContainerImpl: container_1376050148932_0006_01_000038 Container Transitioned from NEW to ALLOCATED
2013-08-09 12:25:30,780 INFO org.apache.hadoop.yarn.server.resourcemanager.RMAuditLogger: USER=ubuntu	OPERATION=AM Allocated Container	TARGET=SchedulerApp	RESULT=SUCCESS	APPID=application_1376050148932_0006	CONTAINERID=container_1376050148932_0006_01_000038
2013-08-09 12:25:30,780 INFO org.apache.hadoop.yarn.server.resourcemanager.scheduler.common.fica.FiCaSchedulerNode: Assigned container container_1376050148932_0006_01_000038 of capacity <memory:1024, vCores:1> on host hadoop-210-4:57908, which currently has 7 containers, <memory:8192, vCores:7> used and <memory:0, vCores:9> available
2013-08-09 12:25:30,781 INFO org.apache.hadoop.yarn.server.resourcemanager.scheduler.capacity.LeafQueue: assignedContainer application=application_1376050148932_0006 container=Container: [ContainerId: container_1376050148932_0006_01_000038, NodeId: hadoop-210-4:57908, NodeHttpAddress: hadoop-210-4:8042, Resource: <memory:1024, vCores:1>, Priority: 20, State: NEW, Token: null, Status: container_id {, app_attempt_id {, application_id {, id: 6, cluster_timestamp: 1376050148932, }, attemptId: 1, }, id: 38, }, state: C_NEW, ] containerId=container_1376050148932_0006_01_000038 queue=default: capacity=1.0, absoluteCapacity=1.0, usedResources=<memory:48128, vCores:42>usedCapacity=0.9791667, absoluteUsedCapacity=0.9791667, numApps=5, numContainers=42 usedCapacity=0.9791667 absoluteUsedCapacity=0.9791667 used=<memory:48128, vCores:42> cluster=<memory:49152, vCores:96>
2013-08-09 12:25:30,781 INFO org.apache.hadoop.yarn.server.resourcemanager.scheduler.capacity.ParentQueue: Re-sorting queues since queue: root.default stats: default: capacity=1.0, absoluteCapacity=1.0, usedResources=<memory:49152, vCores:43>usedCapacity=1.0, absoluteUsedCapacity=1.0, numApps=5, numContainers=43
2013-08-09 12:25:30,781 INFO org.apache.hadoop.yarn.server.resourcemanager.scheduler.capacity.ParentQueue: assignedContainer queue=root usedCapacity=1.0 absoluteUsedCapacity=1.0 used=<memory:49152, vCores:43> cluster=<memory:49152, vCores:96>
2013-08-09 12:25:31,485 INFO org.apache.hadoop.yarn.server.resourcemanager.rmcontainer.RMContainerImpl: container_1376050148932_0006_01_000037 Container Transitioned from ALLOCATED to ACQUIRED
2013-08-09 12:25:31,486 INFO org.apache.hadoop.yarn.server.resourcemanager.rmcontainer.RMContainerImpl: container_1376050148932_0006_01_000038 Container Transitioned from ALLOCATED to ACQUIRED
2013-08-09 12:25:31,819 INFO org.apache.hadoop.yarn.server.resourcemanager.rmcontainer.RMContainerImpl: container_1376050148932_0006_01_000037 Container Transitioned from ACQUIRED to RUNNING
2013-08-09 12:25:31,819 INFO org.apache.hadoop.yarn.server.resourcemanager.rmcontainer.RMContainerImpl: container_1376050148932_0006_01_000038 Container Transitioned from ACQUIRED to RUNNING
2013-08-09 12:25:33,086 INFO org.apache.hadoop.yarn.server.resourcemanager.rmcontainer.RMContainerImpl: container_1376050148932_0007_01_000002 Container Transitioned from RUNNING to COMPLETED
2013-08-09 12:25:33,087 INFO org.apache.hadoop.yarn.server.resourcemanager.scheduler.common.fica.FiCaSchedulerApp: Completed container: container_1376050148932_0007_01_000002 in state: COMPLETED event:FINISHED
2013-08-09 12:25:33,087 INFO org.apache.hadoop.yarn.server.resourcemanager.RMAuditLogger: USER=ubuntu	OPERATION=AM Released Container	TARGET=SchedulerApp	RESULT=SUCCESS	APPID=application_1376050148932_0007	CONTAINERID=container_1376050148932_0007_01_000002
2013-08-09 12:25:33,087 INFO org.apache.hadoop.yarn.server.resourcemanager.scheduler.common.fica.FiCaSchedulerNode: Released container container_1376050148932_0007_01_000002 of capacity <memory:1024, vCores:1> on host hadoop-210-6:38267, which currently has 7 containers, <memory:7168, vCores:7> used and <memory:1024, vCores:9> available, release resources=true
2013-08-09 12:25:33,087 INFO org.apache.hadoop.yarn.server.resourcemanager.scheduler.capacity.LeafQueue: default used=<memory:48128, vCores:42> numContainers=42 user=ubuntu user-resources=<memory:48128, vCores:42>
2013-08-09 12:25:33,088 INFO org.apache.hadoop.yarn.server.resourcemanager.scheduler.capacity.LeafQueue: completedContainer container=Container: [ContainerId: container_1376050148932_0007_01_000002, NodeId: hadoop-210-6:38267, NodeHttpAddress: hadoop-210-6:8042, Resource: <memory:1024, vCores:1>, Priority: 20, State: NEW, Token: null, Status: container_id {, app_attempt_id {, application_id {, id: 7, cluster_timestamp: 1376050148932, }, attemptId: 1, }, id: 2, }, state: C_COMPLETE, diagnostics: "Container killed by the ApplicationMaster.\n\n", exit_status: 143, ] resource=<memory:1024, vCores:1> queue=default: capacity=1.0, absoluteCapacity=1.0, usedResources=<memory:48128, vCores:42>usedCapacity=0.9791667, absoluteUsedCapacity=0.9791667, numApps=5, numContainers=42 usedCapacity=0.9791667 absoluteUsedCapacity=0.9791667 used=<memory:48128, vCores:42> cluster=<memory:49152, vCores:96>
2013-08-09 12:25:33,088 INFO org.apache.hadoop.yarn.server.resourcemanager.scheduler.capacity.ParentQueue: completedContainer queue=root usedCapacity=0.9791667 absoluteUsedCapacity=0.9791667 used=<memory:48128, vCores:42> cluster=<memory:49152, vCores:96>
2013-08-09 12:25:33,088 INFO org.apache.hadoop.yarn.server.resourcemanager.scheduler.capacity.CapacityScheduler: Application appattempt_1376050148932_0007_000001 released container container_1376050148932_0007_01_000002 on node: host: hadoop-210-6:38267 #containers=7 available=1024 used=7168 with event: FINISHED
2013-08-09 12:25:33,089 INFO org.apache.hadoop.yarn.server.resourcemanager.rmcontainer.RMContainerImpl: container_1376050148932_0006_01_000039 Container Transitioned from NEW to ALLOCATED
2013-08-09 12:25:33,089 INFO org.apache.hadoop.yarn.server.resourcemanager.RMAuditLogger: USER=ubuntu	OPERATION=AM Allocated Container	TARGET=SchedulerApp	RESULT=SUCCESS	APPID=application_1376050148932_0006	CONTAINERID=container_1376050148932_0006_01_000039
2013-08-09 12:25:33,089 INFO org.apache.hadoop.yarn.server.resourcemanager.scheduler.common.fica.FiCaSchedulerNode: Assigned container container_1376050148932_0006_01_000039 of capacity <memory:1024, vCores:1> on host hadoop-210-6:38267, which currently has 8 containers, <memory:8192, vCores:8> used and <memory:0, vCores:8> available
2013-08-09 12:25:33,090 INFO org.apache.hadoop.yarn.server.resourcemanager.scheduler.capacity.LeafQueue: assignedContainer application=application_1376050148932_0006 container=Container: [ContainerId: container_1376050148932_0006_01_000039, NodeId: hadoop-210-6:38267, NodeHttpAddress: hadoop-210-6:8042, Resource: <memory:1024, vCores:1>, Priority: 20, State: NEW, Token: null, Status: container_id {, app_attempt_id {, application_id {, id: 6, cluster_timestamp: 1376050148932, }, attemptId: 1, }, id: 39, }, state: C_NEW, ] containerId=container_1376050148932_0006_01_000039 queue=default: capacity=1.0, absoluteCapacity=1.0, usedResources=<memory:48128, vCores:42>usedCapacity=0.9791667, absoluteUsedCapacity=0.9791667, numApps=5, numContainers=42 usedCapacity=0.9791667 absoluteUsedCapacity=0.9791667 used=<memory:48128, vCores:42> cluster=<memory:49152, vCores:96>
2013-08-09 12:25:33,090 INFO org.apache.hadoop.yarn.server.resourcemanager.scheduler.capacity.ParentQueue: Re-sorting queues since queue: root.default stats: default: capacity=1.0, absoluteCapacity=1.0, usedResources=<memory:49152, vCores:43>usedCapacity=1.0, absoluteUsedCapacity=1.0, numApps=5, numContainers=43
2013-08-09 12:25:33,090 INFO org.apache.hadoop.yarn.server.resourcemanager.scheduler.capacity.ParentQueue: assignedContainer queue=root usedCapacity=1.0 absoluteUsedCapacity=1.0 used=<memory:49152, vCores:43> cluster=<memory:49152, vCores:96>
2013-08-09 12:25:33,498 INFO org.apache.hadoop.yarn.server.resourcemanager.rmcontainer.RMContainerImpl: container_1376050148932_0006_01_000039 Container Transitioned from ALLOCATED to ACQUIRED
2013-08-09 12:25:34,094 INFO org.apache.hadoop.yarn.server.resourcemanager.rmcontainer.RMContainerImpl: container_1376050148932_0006_01_000039 Container Transitioned from ACQUIRED to RUNNING
2013-08-09 12:25:34,647 INFO org.apache.hadoop.yarn.server.resourcemanager.rmcontainer.RMContainerImpl: container_1376050148932_0007_01_000014 Container Transitioned from RUNNING to COMPLETED
2013-08-09 12:25:34,647 INFO org.apache.hadoop.yarn.server.resourcemanager.scheduler.common.fica.FiCaSchedulerApp: Completed container: container_1376050148932_0007_01_000014 in state: COMPLETED event:FINISHED
2013-08-09 12:25:34,647 INFO org.apache.hadoop.yarn.server.resourcemanager.RMAuditLogger: USER=ubuntu	OPERATION=AM Released Container	TARGET=SchedulerApp	RESULT=SUCCESS	APPID=application_1376050148932_0007	CONTAINERID=container_1376050148932_0007_01_000014
2013-08-09 12:25:34,647 INFO org.apache.hadoop.yarn.server.resourcemanager.scheduler.common.fica.FiCaSchedulerNode: Released container container_1376050148932_0007_01_000014 of capacity <memory:1024, vCores:1> on host hadoop-210-4:57908, which currently has 6 containers, <memory:7168, vCores:6> used and <memory:1024, vCores:10> available, release resources=true
2013-08-09 12:25:34,647 INFO org.apache.hadoop.yarn.server.resourcemanager.scheduler.capacity.LeafQueue: default used=<memory:48128, vCores:42> numContainers=42 user=ubuntu user-resources=<memory:48128, vCores:42>
2013-08-09 12:25:34,649 INFO org.apache.hadoop.yarn.server.resourcemanager.scheduler.capacity.LeafQueue: completedContainer container=Container: [ContainerId: container_1376050148932_0007_01_000014, NodeId: hadoop-210-4:57908, NodeHttpAddress: hadoop-210-4:8042, Resource: <memory:1024, vCores:1>, Priority: 20, State: NEW, Token: null, Status: container_id {, app_attempt_id {, application_id {, id: 7, cluster_timestamp: 1376050148932, }, attemptId: 1, }, id: 14, }, state: C_COMPLETE, diagnostics: "Container killed by the ApplicationMaster.\n\n", exit_status: 143, ] resource=<memory:1024, vCores:1> queue=default: capacity=1.0, absoluteCapacity=1.0, usedResources=<memory:48128, vCores:42>usedCapacity=0.9791667, absoluteUsedCapacity=0.9791667, numApps=5, numContainers=42 usedCapacity=0.9791667 absoluteUsedCapacity=0.9791667 used=<memory:48128, vCores:42> cluster=<memory:49152, vCores:96>
2013-08-09 12:25:34,649 INFO org.apache.hadoop.yarn.server.resourcemanager.scheduler.capacity.ParentQueue: completedContainer queue=root usedCapacity=0.9791667 absoluteUsedCapacity=0.9791667 used=<memory:48128, vCores:42> cluster=<memory:49152, vCores:96>
2013-08-09 12:25:34,649 INFO org.apache.hadoop.yarn.server.resourcemanager.scheduler.capacity.CapacityScheduler: Application appattempt_1376050148932_0007_000001 released container container_1376050148932_0007_01_000014 on node: host: hadoop-210-4:57908 #containers=6 available=1024 used=7168 with event: FINISHED
2013-08-09 12:25:34,649 INFO org.apache.hadoop.yarn.server.resourcemanager.rmcontainer.RMContainerImpl: container_1376050148932_0006_01_000040 Container Transitioned from NEW to ALLOCATED
2013-08-09 12:25:34,649 INFO org.apache.hadoop.yarn.server.resourcemanager.RMAuditLogger: USER=ubuntu	OPERATION=AM Allocated Container	TARGET=SchedulerApp	RESULT=SUCCESS	APPID=application_1376050148932_0006	CONTAINERID=container_1376050148932_0006_01_000040
2013-08-09 12:25:34,650 INFO org.apache.hadoop.yarn.server.resourcemanager.scheduler.common.fica.FiCaSchedulerNode: Assigned container container_1376050148932_0006_01_000040 of capacity <memory:1024, vCores:1> on host hadoop-210-4:57908, which currently has 7 containers, <memory:8192, vCores:7> used and <memory:0, vCores:9> available
2013-08-09 12:25:34,650 INFO org.apache.hadoop.yarn.server.resourcemanager.scheduler.capacity.LeafQueue: assignedContainer application=application_1376050148932_0006 container=Container: [ContainerId: container_1376050148932_0006_01_000040, NodeId: hadoop-210-4:57908, NodeHttpAddress: hadoop-210-4:8042, Resource: <memory:1024, vCores:1>, Priority: 20, State: NEW, Token: null, Status: container_id {, app_attempt_id {, application_id {, id: 6, cluster_timestamp: 1376050148932, }, attemptId: 1, }, id: 40, }, state: C_NEW, ] containerId=container_1376050148932_0006_01_000040 queue=default: capacity=1.0, absoluteCapacity=1.0, usedResources=<memory:48128, vCores:42>usedCapacity=0.9791667, absoluteUsedCapacity=0.9791667, numApps=5, numContainers=42 usedCapacity=0.9791667 absoluteUsedCapacity=0.9791667 used=<memory:48128, vCores:42> cluster=<memory:49152, vCores:96>
2013-08-09 12:25:34,651 INFO org.apache.hadoop.yarn.server.resourcemanager.scheduler.capacity.ParentQueue: Re-sorting queues since queue: root.default stats: default: capacity=1.0, absoluteCapacity=1.0, usedResources=<memory:49152, vCores:43>usedCapacity=1.0, absoluteUsedCapacity=1.0, numApps=5, numContainers=43
2013-08-09 12:25:34,651 INFO org.apache.hadoop.yarn.server.resourcemanager.scheduler.capacity.ParentQueue: assignedContainer queue=root usedCapacity=1.0 absoluteUsedCapacity=1.0 used=<memory:49152, vCores:43> cluster=<memory:49152, vCores:96>
2013-08-09 12:25:35,013 INFO org.apache.hadoop.yarn.server.resourcemanager.rmcontainer.RMContainerImpl: container_1376050148932_0007_01_000011 Container Transitioned from RUNNING to COMPLETED
2013-08-09 12:25:35,013 INFO org.apache.hadoop.yarn.server.resourcemanager.scheduler.common.fica.FiCaSchedulerApp: Completed container: container_1376050148932_0007_01_000011 in state: COMPLETED event:FINISHED
2013-08-09 12:25:35,013 INFO org.apache.hadoop.yarn.server.resourcemanager.RMAuditLogger: USER=ubuntu	OPERATION=AM Released Container	TARGET=SchedulerApp	RESULT=SUCCESS	APPID=application_1376050148932_0007	CONTAINERID=container_1376050148932_0007_01_000011
2013-08-09 12:25:35,013 INFO org.apache.hadoop.yarn.server.resourcemanager.scheduler.common.fica.FiCaSchedulerNode: Released container container_1376050148932_0007_01_000011 of capacity <memory:1024, vCores:1> on host hadoop-210-4:57908, which currently has 6 containers, <memory:7168, vCores:6> used and <memory:1024, vCores:10> available, release resources=true
2013-08-09 12:25:35,013 INFO org.apache.hadoop.yarn.server.resourcemanager.scheduler.capacity.LeafQueue: default used=<memory:48128, vCores:42> numContainers=42 user=ubuntu user-resources=<memory:48128, vCores:42>
2013-08-09 12:25:35,014 INFO org.apache.hadoop.yarn.server.resourcemanager.scheduler.capacity.LeafQueue: completedContainer container=Container: [ContainerId: container_1376050148932_0007_01_000011, NodeId: hadoop-210-4:57908, NodeHttpAddress: hadoop-210-4:8042, Resource: <memory:1024, vCores:1>, Priority: 20, State: NEW, Token: null, Status: container_id {, app_attempt_id {, application_id {, id: 7, cluster_timestamp: 1376050148932, }, attemptId: 1, }, id: 11, }, state: C_COMPLETE, diagnostics: "Container killed by the ApplicationMaster.\n\n", exit_status: 143, ] resource=<memory:1024, vCores:1> queue=default: capacity=1.0, absoluteCapacity=1.0, usedResources=<memory:48128, vCores:42>usedCapacity=0.9791667, absoluteUsedCapacity=0.9791667, numApps=5, numContainers=42 usedCapacity=0.9791667 absoluteUsedCapacity=0.9791667 used=<memory:48128, vCores:42> cluster=<memory:49152, vCores:96>
2013-08-09 12:25:35,014 INFO org.apache.hadoop.yarn.server.resourcemanager.scheduler.capacity.ParentQueue: completedContainer queue=root usedCapacity=0.9791667 absoluteUsedCapacity=0.9791667 used=<memory:48128, vCores:42> cluster=<memory:49152, vCores:96>
2013-08-09 12:25:35,014 INFO org.apache.hadoop.yarn.server.resourcemanager.scheduler.capacity.CapacityScheduler: Application appattempt_1376050148932_0007_000001 released container container_1376050148932_0007_01_000011 on node: host: hadoop-210-4:57908 #containers=6 available=1024 used=7168 with event: FINISHED
2013-08-09 12:25:35,015 INFO org.apache.hadoop.yarn.server.resourcemanager.rmcontainer.RMContainerImpl: container_1376050148932_0006_01_000041 Container Transitioned from NEW to ALLOCATED
2013-08-09 12:25:35,015 INFO org.apache.hadoop.yarn.server.resourcemanager.RMAuditLogger: USER=ubuntu	OPERATION=AM Allocated Container	TARGET=SchedulerApp	RESULT=SUCCESS	APPID=application_1376050148932_0006	CONTAINERID=container_1376050148932_0006_01_000041
2013-08-09 12:25:35,015 INFO org.apache.hadoop.yarn.server.resourcemanager.scheduler.common.fica.FiCaSchedulerNode: Assigned container container_1376050148932_0006_01_000041 of capacity <memory:1024, vCores:1> on host hadoop-210-4:57908, which currently has 7 containers, <memory:8192, vCores:7> used and <memory:0, vCores:9> available
2013-08-09 12:25:35,016 INFO org.apache.hadoop.yarn.server.resourcemanager.scheduler.capacity.LeafQueue: assignedContainer application=application_1376050148932_0006 container=Container: [ContainerId: container_1376050148932_0006_01_000041, NodeId: hadoop-210-4:57908, NodeHttpAddress: hadoop-210-4:8042, Resource: <memory:1024, vCores:1>, Priority: 20, State: NEW, Token: null, Status: container_id {, app_attempt_id {, application_id {, id: 6, cluster_timestamp: 1376050148932, }, attemptId: 1, }, id: 41, }, state: C_NEW, ] containerId=container_1376050148932_0006_01_000041 queue=default: capacity=1.0, absoluteCapacity=1.0, usedResources=<memory:48128, vCores:42>usedCapacity=0.9791667, absoluteUsedCapacity=0.9791667, numApps=5, numContainers=42 usedCapacity=0.9791667 absoluteUsedCapacity=0.9791667 used=<memory:48128, vCores:42> cluster=<memory:49152, vCores:96>
2013-08-09 12:25:35,016 INFO org.apache.hadoop.yarn.server.resourcemanager.scheduler.capacity.ParentQueue: Re-sorting queues since queue: root.default stats: default: capacity=1.0, absoluteCapacity=1.0, usedResources=<memory:49152, vCores:43>usedCapacity=1.0, absoluteUsedCapacity=1.0, numApps=5, numContainers=43
2013-08-09 12:25:35,016 INFO org.apache.hadoop.yarn.server.resourcemanager.scheduler.capacity.ParentQueue: assignedContainer queue=root usedCapacity=1.0 absoluteUsedCapacity=1.0 used=<memory:49152, vCores:43> cluster=<memory:49152, vCores:96>
2013-08-09 12:25:35,512 INFO org.apache.hadoop.yarn.server.resourcemanager.rmcontainer.RMContainerImpl: container_1376050148932_0006_01_000040 Container Transitioned from ALLOCATED to ACQUIRED
2013-08-09 12:25:35,513 INFO org.apache.hadoop.yarn.server.resourcemanager.rmcontainer.RMContainerImpl: container_1376050148932_0006_01_000041 Container Transitioned from ALLOCATED to ACQUIRED
2013-08-09 12:25:36,018 INFO org.apache.hadoop.yarn.server.resourcemanager.rmcontainer.RMContainerImpl: container_1376050148932_0006_01_000040 Container Transitioned from ACQUIRED to RUNNING
2013-08-09 12:25:36,018 INFO org.apache.hadoop.yarn.server.resourcemanager.rmcontainer.RMContainerImpl: container_1376050148932_0006_01_000041 Container Transitioned from ACQUIRED to RUNNING
2013-08-09 12:25:36,018 INFO org.apache.hadoop.yarn.server.resourcemanager.rmcontainer.RMContainerImpl: container_1376050148932_0007_01_000013 Container Transitioned from RUNNING to COMPLETED
2013-08-09 12:25:36,018 INFO org.apache.hadoop.yarn.server.resourcemanager.scheduler.common.fica.FiCaSchedulerApp: Completed container: container_1376050148932_0007_01_000013 in state: COMPLETED event:FINISHED
2013-08-09 12:25:36,018 INFO org.apache.hadoop.yarn.server.resourcemanager.RMAuditLogger: USER=ubuntu	OPERATION=AM Released Container	TARGET=SchedulerApp	RESULT=SUCCESS	APPID=application_1376050148932_0007	CONTAINERID=container_1376050148932_0007_01_000013
2013-08-09 12:25:36,018 INFO org.apache.hadoop.yarn.server.resourcemanager.scheduler.common.fica.FiCaSchedulerNode: Released container container_1376050148932_0007_01_000013 of capacity <memory:1024, vCores:1> on host hadoop-210-4:57908, which currently has 6 containers, <memory:7168, vCores:6> used and <memory:1024, vCores:10> available, release resources=true
2013-08-09 12:25:36,019 INFO org.apache.hadoop.yarn.server.resourcemanager.scheduler.capacity.LeafQueue: default used=<memory:48128, vCores:42> numContainers=42 user=ubuntu user-resources=<memory:48128, vCores:42>
2013-08-09 12:25:36,020 INFO org.apache.hadoop.yarn.server.resourcemanager.scheduler.capacity.LeafQueue: completedContainer container=Container: [ContainerId: container_1376050148932_0007_01_000013, NodeId: hadoop-210-4:57908, NodeHttpAddress: hadoop-210-4:8042, Resource: <memory:1024, vCores:1>, Priority: 20, State: NEW, Token: null, Status: container_id {, app_attempt_id {, application_id {, id: 7, cluster_timestamp: 1376050148932, }, attemptId: 1, }, id: 13, }, state: C_COMPLETE, diagnostics: "Container killed by the ApplicationMaster.\n\n", exit_status: 143, ] resource=<memory:1024, vCores:1> queue=default: capacity=1.0, absoluteCapacity=1.0, usedResources=<memory:48128, vCores:42>usedCapacity=0.9791667, absoluteUsedCapacity=0.9791667, numApps=5, numContainers=42 usedCapacity=0.9791667 absoluteUsedCapacity=0.9791667 used=<memory:48128, vCores:42> cluster=<memory:49152, vCores:96>
2013-08-09 12:25:36,020 INFO org.apache.hadoop.yarn.server.resourcemanager.scheduler.capacity.ParentQueue: completedContainer queue=root usedCapacity=0.9791667 absoluteUsedCapacity=0.9791667 used=<memory:48128, vCores:42> cluster=<memory:49152, vCores:96>
2013-08-09 12:25:36,020 INFO org.apache.hadoop.yarn.server.resourcemanager.scheduler.capacity.CapacityScheduler: Application appattempt_1376050148932_0007_000001 released container container_1376050148932_0007_01_000013 on node: host: hadoop-210-4:57908 #containers=6 available=1024 used=7168 with event: FINISHED
2013-08-09 12:25:36,020 INFO org.apache.hadoop.yarn.server.resourcemanager.rmcontainer.RMContainerImpl: container_1376050148932_0006_01_000042 Container Transitioned from NEW to ALLOCATED
2013-08-09 12:25:36,021 INFO org.apache.hadoop.yarn.server.resourcemanager.RMAuditLogger: USER=ubuntu	OPERATION=AM Allocated Container	TARGET=SchedulerApp	RESULT=SUCCESS	APPID=application_1376050148932_0006	CONTAINERID=container_1376050148932_0006_01_000042
2013-08-09 12:25:36,021 INFO org.apache.hadoop.yarn.server.resourcemanager.scheduler.common.fica.FiCaSchedulerNode: Assigned container container_1376050148932_0006_01_000042 of capacity <memory:1024, vCores:1> on host hadoop-210-4:57908, which currently has 7 containers, <memory:8192, vCores:7> used and <memory:0, vCores:9> available
2013-08-09 12:25:36,022 INFO org.apache.hadoop.yarn.server.resourcemanager.scheduler.capacity.LeafQueue: assignedContainer application=application_1376050148932_0006 container=Container: [ContainerId: container_1376050148932_0006_01_000042, NodeId: hadoop-210-4:57908, NodeHttpAddress: hadoop-210-4:8042, Resource: <memory:1024, vCores:1>, Priority: 20, State: NEW, Token: null, Status: container_id {, app_attempt_id {, application_id {, id: 6, cluster_timestamp: 1376050148932, }, attemptId: 1, }, id: 42, }, state: C_NEW, ] containerId=container_1376050148932_0006_01_000042 queue=default: capacity=1.0, absoluteCapacity=1.0, usedResources=<memory:48128, vCores:42>usedCapacity=0.9791667, absoluteUsedCapacity=0.9791667, numApps=5, numContainers=42 usedCapacity=0.9791667 absoluteUsedCapacity=0.9791667 used=<memory:48128, vCores:42> cluster=<memory:49152, vCores:96>
2013-08-09 12:25:36,022 INFO org.apache.hadoop.yarn.server.resourcemanager.scheduler.capacity.ParentQueue: Re-sorting queues since queue: root.default stats: default: capacity=1.0, absoluteCapacity=1.0, usedResources=<memory:49152, vCores:43>usedCapacity=1.0, absoluteUsedCapacity=1.0, numApps=5, numContainers=43
2013-08-09 12:25:36,022 INFO org.apache.hadoop.yarn.server.resourcemanager.scheduler.capacity.ParentQueue: assignedContainer queue=root usedCapacity=1.0 absoluteUsedCapacity=1.0 used=<memory:49152, vCores:43> cluster=<memory:49152, vCores:96>
2013-08-09 12:25:36,521 INFO org.apache.hadoop.yarn.server.resourcemanager.rmcontainer.RMContainerImpl: container_1376050148932_0006_01_000042 Container Transitioned from ALLOCATED to ACQUIRED
2013-08-09 12:25:36,676 INFO org.apache.hadoop.yarn.server.resourcemanager.rmcontainer.RMContainerImpl: container_1376050148932_0006_01_000008 Container Transitioned from RUNNING to COMPLETED
2013-08-09 12:25:36,676 INFO org.apache.hadoop.yarn.server.resourcemanager.scheduler.common.fica.FiCaSchedulerApp: Completed container: container_1376050148932_0006_01_000008 in state: COMPLETED event:FINISHED
2013-08-09 12:25:36,676 INFO org.apache.hadoop.yarn.server.resourcemanager.RMAuditLogger: USER=ubuntu	OPERATION=AM Released Container	TARGET=SchedulerApp	RESULT=SUCCESS	APPID=application_1376050148932_0006	CONTAINERID=container_1376050148932_0006_01_000008
2013-08-09 12:25:36,676 INFO org.apache.hadoop.yarn.server.resourcemanager.scheduler.common.fica.FiCaSchedulerNode: Released container container_1376050148932_0006_01_000008 of capacity <memory:1024, vCores:1> on host hadoop-210-7:41457, which currently has 6 containers, <memory:7168, vCores:6> used and <memory:1024, vCores:10> available, release resources=true
2013-08-09 12:25:36,677 INFO org.apache.hadoop.yarn.server.resourcemanager.scheduler.capacity.LeafQueue: default used=<memory:48128, vCores:42> numContainers=42 user=ubuntu user-resources=<memory:48128, vCores:42>
2013-08-09 12:25:36,678 INFO org.apache.hadoop.yarn.server.resourcemanager.scheduler.capacity.LeafQueue: completedContainer container=Container: [ContainerId: container_1376050148932_0006_01_000008, NodeId: hadoop-210-7:41457, NodeHttpAddress: hadoop-210-7:8042, Resource: <memory:1024, vCores:1>, Priority: 20, State: NEW, Token: null, Status: container_id {, app_attempt_id {, application_id {, id: 6, cluster_timestamp: 1376050148932, }, attemptId: 1, }, id: 8, }, state: C_COMPLETE, diagnostics: "Container killed by the ApplicationMaster.\n\n", exit_status: 143, ] resource=<memory:1024, vCores:1> queue=default: capacity=1.0, absoluteCapacity=1.0, usedResources=<memory:48128, vCores:42>usedCapacity=0.9791667, absoluteUsedCapacity=0.9791667, numApps=5, numContainers=42 usedCapacity=0.9791667 absoluteUsedCapacity=0.9791667 used=<memory:48128, vCores:42> cluster=<memory:49152, vCores:96>
2013-08-09 12:25:36,678 INFO org.apache.hadoop.yarn.server.resourcemanager.scheduler.capacity.ParentQueue: completedContainer queue=root usedCapacity=0.9791667 absoluteUsedCapacity=0.9791667 used=<memory:48128, vCores:42> cluster=<memory:49152, vCores:96>
2013-08-09 12:25:36,678 INFO org.apache.hadoop.yarn.server.resourcemanager.scheduler.capacity.CapacityScheduler: Application appattempt_1376050148932_0006_000001 released container container_1376050148932_0006_01_000008 on node: host: hadoop-210-7:41457 #containers=6 available=1024 used=7168 with event: FINISHED
2013-08-09 12:25:36,679 INFO org.apache.hadoop.yarn.server.resourcemanager.rmcontainer.RMContainerImpl: container_1376050148932_0006_01_000043 Container Transitioned from NEW to ALLOCATED
2013-08-09 12:25:36,679 INFO org.apache.hadoop.yarn.server.resourcemanager.RMAuditLogger: USER=ubuntu	OPERATION=AM Allocated Container	TARGET=SchedulerApp	RESULT=SUCCESS	APPID=application_1376050148932_0006	CONTAINERID=container_1376050148932_0006_01_000043
2013-08-09 12:25:36,679 INFO org.apache.hadoop.yarn.server.resourcemanager.scheduler.common.fica.FiCaSchedulerNode: Assigned container container_1376050148932_0006_01_000043 of capacity <memory:1024, vCores:1> on host hadoop-210-7:41457, which currently has 7 containers, <memory:8192, vCores:7> used and <memory:0, vCores:9> available
2013-08-09 12:25:36,680 INFO org.apache.hadoop.yarn.server.resourcemanager.scheduler.capacity.LeafQueue: assignedContainer application=application_1376050148932_0006 container=Container: [ContainerId: container_1376050148932_0006_01_000043, NodeId: hadoop-210-7:41457, NodeHttpAddress: hadoop-210-7:8042, Resource: <memory:1024, vCores:1>, Priority: 20, State: NEW, Token: null, Status: container_id {, app_attempt_id {, application_id {, id: 6, cluster_timestamp: 1376050148932, }, attemptId: 1, }, id: 43, }, state: C_NEW, ] containerId=container_1376050148932_0006_01_000043 queue=default: capacity=1.0, absoluteCapacity=1.0, usedResources=<memory:48128, vCores:42>usedCapacity=0.9791667, absoluteUsedCapacity=0.9791667, numApps=5, numContainers=42 usedCapacity=0.9791667 absoluteUsedCapacity=0.9791667 used=<memory:48128, vCores:42> cluster=<memory:49152, vCores:96>
2013-08-09 12:25:36,680 INFO org.apache.hadoop.yarn.server.resourcemanager.scheduler.capacity.ParentQueue: Re-sorting queues since queue: root.default stats: default: capacity=1.0, absoluteCapacity=1.0, usedResources=<memory:49152, vCores:43>usedCapacity=1.0, absoluteUsedCapacity=1.0, numApps=5, numContainers=43
2013-08-09 12:25:36,680 INFO org.apache.hadoop.yarn.server.resourcemanager.scheduler.capacity.ParentQueue: assignedContainer queue=root usedCapacity=1.0 absoluteUsedCapacity=1.0 used=<memory:49152, vCores:43> cluster=<memory:49152, vCores:96>
2013-08-09 12:25:37,023 INFO org.apache.hadoop.yarn.server.resourcemanager.rmcontainer.RMContainerImpl: container_1376050148932_0006_01_000042 Container Transitioned from ACQUIRED to RUNNING
2013-08-09 12:25:37,527 INFO org.apache.hadoop.yarn.server.resourcemanager.rmcontainer.RMContainerImpl: container_1376050148932_0006_01_000043 Container Transitioned from ALLOCATED to ACQUIRED
2013-08-09 12:25:37,696 INFO org.apache.hadoop.yarn.server.resourcemanager.rmcontainer.RMContainerImpl: container_1376050148932_0006_01_000043 Container Transitioned from ACQUIRED to RUNNING
2013-08-09 12:25:37,696 INFO org.apache.hadoop.yarn.server.resourcemanager.rmcontainer.RMContainerImpl: container_1376050148932_0006_01_000009 Container Transitioned from RUNNING to COMPLETED
2013-08-09 12:25:37,696 INFO org.apache.hadoop.yarn.server.resourcemanager.scheduler.common.fica.FiCaSchedulerApp: Completed container: container_1376050148932_0006_01_000009 in state: COMPLETED event:FINISHED
2013-08-09 12:25:37,696 INFO org.apache.hadoop.yarn.server.resourcemanager.RMAuditLogger: USER=ubuntu	OPERATION=AM Released Container	TARGET=SchedulerApp	RESULT=SUCCESS	APPID=application_1376050148932_0006	CONTAINERID=container_1376050148932_0006_01_000009
2013-08-09 12:25:37,696 INFO org.apache.hadoop.yarn.server.resourcemanager.scheduler.common.fica.FiCaSchedulerNode: Released container container_1376050148932_0006_01_000009 of capacity <memory:1024, vCores:1> on host hadoop-210-7:41457, which currently has 6 containers, <memory:7168, vCores:6> used and <memory:1024, vCores:10> available, release resources=true
2013-08-09 12:25:37,696 INFO org.apache.hadoop.yarn.server.resourcemanager.scheduler.capacity.LeafQueue: default used=<memory:48128, vCores:42> numContainers=42 user=ubuntu user-resources=<memory:48128, vCores:42>
2013-08-09 12:25:37,698 INFO org.apache.hadoop.yarn.server.resourcemanager.scheduler.capacity.LeafQueue: completedContainer container=Container: [ContainerId: container_1376050148932_0006_01_000009, NodeId: hadoop-210-7:41457, NodeHttpAddress: hadoop-210-7:8042, Resource: <memory:1024, vCores:1>, Priority: 20, State: NEW, Token: null, Status: container_id {, app_attempt_id {, application_id {, id: 6, cluster_timestamp: 1376050148932, }, attemptId: 1, }, id: 9, }, state: C_COMPLETE, diagnostics: "Container killed by the ApplicationMaster.\n\n", exit_status: 143, ] resource=<memory:1024, vCores:1> queue=default: capacity=1.0, absoluteCapacity=1.0, usedResources=<memory:48128, vCores:42>usedCapacity=0.9791667, absoluteUsedCapacity=0.9791667, numApps=5, numContainers=42 usedCapacity=0.9791667 absoluteUsedCapacity=0.9791667 used=<memory:48128, vCores:42> cluster=<memory:49152, vCores:96>
2013-08-09 12:25:37,698 INFO org.apache.hadoop.yarn.server.resourcemanager.scheduler.capacity.ParentQueue: completedContainer queue=root usedCapacity=0.9791667 absoluteUsedCapacity=0.9791667 used=<memory:48128, vCores:42> cluster=<memory:49152, vCores:96>
2013-08-09 12:25:37,698 INFO org.apache.hadoop.yarn.server.resourcemanager.scheduler.capacity.CapacityScheduler: Application appattempt_1376050148932_0006_000001 released container container_1376050148932_0006_01_000009 on node: host: hadoop-210-7:41457 #containers=6 available=1024 used=7168 with event: FINISHED
2013-08-09 12:25:37,698 INFO org.apache.hadoop.yarn.server.resourcemanager.rmcontainer.RMContainerImpl: container_1376050148932_0006_01_000044 Container Transitioned from NEW to ALLOCATED
2013-08-09 12:25:37,699 INFO org.apache.hadoop.yarn.server.resourcemanager.RMAuditLogger: USER=ubuntu	OPERATION=AM Allocated Container	TARGET=SchedulerApp	RESULT=SUCCESS	APPID=application_1376050148932_0006	CONTAINERID=container_1376050148932_0006_01_000044
2013-08-09 12:25:37,699 INFO org.apache.hadoop.yarn.server.resourcemanager.scheduler.common.fica.FiCaSchedulerNode: Assigned container container_1376050148932_0006_01_000044 of capacity <memory:1024, vCores:1> on host hadoop-210-7:41457, which currently has 7 containers, <memory:8192, vCores:7> used and <memory:0, vCores:9> available
2013-08-09 12:25:37,699 INFO org.apache.hadoop.yarn.server.resourcemanager.scheduler.capacity.LeafQueue: assignedContainer application=application_1376050148932_0006 container=Container: [ContainerId: container_1376050148932_0006_01_000044, NodeId: hadoop-210-7:41457, NodeHttpAddress: hadoop-210-7:8042, Resource: <memory:1024, vCores:1>, Priority: 20, State: NEW, Token: null, Status: container_id {, app_attempt_id {, application_id {, id: 6, cluster_timestamp: 1376050148932, }, attemptId: 1, }, id: 44, }, state: C_NEW, ] containerId=container_1376050148932_0006_01_000044 queue=default: capacity=1.0, absoluteCapacity=1.0, usedResources=<memory:48128, vCores:42>usedCapacity=0.9791667, absoluteUsedCapacity=0.9791667, numApps=5, numContainers=42 usedCapacity=0.9791667 absoluteUsedCapacity=0.9791667 used=<memory:48128, vCores:42> cluster=<memory:49152, vCores:96>
2013-08-09 12:25:37,700 INFO org.apache.hadoop.yarn.server.resourcemanager.scheduler.capacity.ParentQueue: Re-sorting queues since queue: root.default stats: default: capacity=1.0, absoluteCapacity=1.0, usedResources=<memory:49152, vCores:43>usedCapacity=1.0, absoluteUsedCapacity=1.0, numApps=5, numContainers=43
2013-08-09 12:25:37,700 INFO org.apache.hadoop.yarn.server.resourcemanager.scheduler.capacity.ParentQueue: assignedContainer queue=root usedCapacity=1.0 absoluteUsedCapacity=1.0 used=<memory:49152, vCores:43> cluster=<memory:49152, vCores:96>
2013-08-09 12:25:38,340 INFO org.apache.hadoop.yarn.server.resourcemanager.rmcontainer.RMContainerImpl: container_1376050148932_0006_01_000023 Container Transitioned from RUNNING to COMPLETED
2013-08-09 12:25:38,340 INFO org.apache.hadoop.yarn.server.resourcemanager.scheduler.common.fica.FiCaSchedulerApp: Completed container: container_1376050148932_0006_01_000023 in state: COMPLETED event:FINISHED
2013-08-09 12:25:38,340 INFO org.apache.hadoop.yarn.server.resourcemanager.RMAuditLogger: USER=ubuntu	OPERATION=AM Released Container	TARGET=SchedulerApp	RESULT=SUCCESS	APPID=application_1376050148932_0006	CONTAINERID=container_1376050148932_0006_01_000023
2013-08-09 12:25:38,340 INFO org.apache.hadoop.yarn.server.resourcemanager.scheduler.common.fica.FiCaSchedulerNode: Released container container_1376050148932_0006_01_000023 of capacity <memory:1024, vCores:1> on host hadoop-210-2:40150, which currently has 6 containers, <memory:7168, vCores:6> used and <memory:1024, vCores:10> available, release resources=true
2013-08-09 12:25:38,340 INFO org.apache.hadoop.yarn.server.resourcemanager.scheduler.capacity.LeafQueue: default used=<memory:48128, vCores:42> numContainers=42 user=ubuntu user-resources=<memory:48128, vCores:42>
2013-08-09 12:25:38,341 INFO org.apache.hadoop.yarn.server.resourcemanager.scheduler.capacity.LeafQueue: completedContainer container=Container: [ContainerId: container_1376050148932_0006_01_000023, NodeId: hadoop-210-2:40150, NodeHttpAddress: hadoop-210-2:8042, Resource: <memory:1024, vCores:1>, Priority: 20, State: NEW, Token: null, Status: container_id {, app_attempt_id {, application_id {, id: 6, cluster_timestamp: 1376050148932, }, attemptId: 1, }, id: 23, }, state: C_COMPLETE, diagnostics: "", exit_status: 0, ] resource=<memory:1024, vCores:1> queue=default: capacity=1.0, absoluteCapacity=1.0, usedResources=<memory:48128, vCores:42>usedCapacity=0.9791667, absoluteUsedCapacity=0.9791667, numApps=5, numContainers=42 usedCapacity=0.9791667 absoluteUsedCapacity=0.9791667 used=<memory:48128, vCores:42> cluster=<memory:49152, vCores:96>
2013-08-09 12:25:38,342 INFO org.apache.hadoop.yarn.server.resourcemanager.scheduler.capacity.ParentQueue: completedContainer queue=root usedCapacity=0.9791667 absoluteUsedCapacity=0.9791667 used=<memory:48128, vCores:42> cluster=<memory:49152, vCores:96>
2013-08-09 12:25:38,342 INFO org.apache.hadoop.yarn.server.resourcemanager.scheduler.capacity.CapacityScheduler: Application appattempt_1376050148932_0006_000001 released container container_1376050148932_0006_01_000023 on node: host: hadoop-210-2:40150 #containers=6 available=1024 used=7168 with event: FINISHED
2013-08-09 12:25:38,342 INFO org.apache.hadoop.yarn.server.resourcemanager.rmcontainer.RMContainerImpl: container_1376050148932_0006_01_000045 Container Transitioned from NEW to ALLOCATED
2013-08-09 12:25:38,343 INFO org.apache.hadoop.yarn.server.resourcemanager.RMAuditLogger: USER=ubuntu	OPERATION=AM Allocated Container	TARGET=SchedulerApp	RESULT=SUCCESS	APPID=application_1376050148932_0006	CONTAINERID=container_1376050148932_0006_01_000045
2013-08-09 12:25:38,343 INFO org.apache.hadoop.yarn.server.resourcemanager.scheduler.common.fica.FiCaSchedulerNode: Assigned container container_1376050148932_0006_01_000045 of capacity <memory:1024, vCores:1> on host hadoop-210-2:40150, which currently has 7 containers, <memory:8192, vCores:7> used and <memory:0, vCores:9> available
2013-08-09 12:25:38,343 INFO org.apache.hadoop.yarn.server.resourcemanager.scheduler.capacity.LeafQueue: assignedContainer application=application_1376050148932_0006 container=Container: [ContainerId: container_1376050148932_0006_01_000045, NodeId: hadoop-210-2:40150, NodeHttpAddress: hadoop-210-2:8042, Resource: <memory:1024, vCores:1>, Priority: 20, State: NEW, Token: null, Status: container_id {, app_attempt_id {, application_id {, id: 6, cluster_timestamp: 1376050148932, }, attemptId: 1, }, id: 45, }, state: C_NEW, ] containerId=container_1376050148932_0006_01_000045 queue=default: capacity=1.0, absoluteCapacity=1.0, usedResources=<memory:48128, vCores:42>usedCapacity=0.9791667, absoluteUsedCapacity=0.9791667, numApps=5, numContainers=42 usedCapacity=0.9791667 absoluteUsedCapacity=0.9791667 used=<memory:48128, vCores:42> cluster=<memory:49152, vCores:96>
2013-08-09 12:25:38,344 INFO org.apache.hadoop.yarn.server.resourcemanager.scheduler.capacity.ParentQueue: Re-sorting queues since queue: root.default stats: default: capacity=1.0, absoluteCapacity=1.0, usedResources=<memory:49152, vCores:43>usedCapacity=1.0, absoluteUsedCapacity=1.0, numApps=5, numContainers=43
2013-08-09 12:25:38,344 INFO org.apache.hadoop.yarn.server.resourcemanager.scheduler.capacity.ParentQueue: assignedContainer queue=root usedCapacity=1.0 absoluteUsedCapacity=1.0 used=<memory:49152, vCores:43> cluster=<memory:49152, vCores:96>
2013-08-09 12:25:38,536 INFO org.apache.hadoop.yarn.server.resourcemanager.rmcontainer.RMContainerImpl: container_1376050148932_0006_01_000044 Container Transitioned from ALLOCATED to ACQUIRED
2013-08-09 12:25:38,537 INFO org.apache.hadoop.yarn.server.resourcemanager.rmcontainer.RMContainerImpl: container_1376050148932_0006_01_000045 Container Transitioned from ALLOCATED to ACQUIRED
2013-08-09 12:25:38,723 INFO org.apache.hadoop.yarn.server.resourcemanager.rmcontainer.RMContainerImpl: container_1376050148932_0006_01_000044 Container Transitioned from ACQUIRED to RUNNING
2013-08-09 12:25:38,932 INFO org.apache.hadoop.yarn.server.resourcemanager.rmcontainer.RMContainerImpl: container_1376050148932_0006_01_000045 Container Transitioned from ACQUIRED to RUNNING
2013-08-09 12:25:38,932 INFO org.apache.hadoop.yarn.server.resourcemanager.rmcontainer.RMContainerImpl: container_1376050148932_0006_01_000025 Container Transitioned from RUNNING to COMPLETED
2013-08-09 12:25:38,933 INFO org.apache.hadoop.yarn.server.resourcemanager.scheduler.common.fica.FiCaSchedulerApp: Completed container: container_1376050148932_0006_01_000025 in state: COMPLETED event:FINISHED
2013-08-09 12:25:38,933 INFO org.apache.hadoop.yarn.server.resourcemanager.RMAuditLogger: USER=ubuntu	OPERATION=AM Released Container	TARGET=SchedulerApp	RESULT=SUCCESS	APPID=application_1376050148932_0006	CONTAINERID=container_1376050148932_0006_01_000025
2013-08-09 12:25:38,933 INFO org.apache.hadoop.yarn.server.resourcemanager.scheduler.common.fica.FiCaSchedulerNode: Released container container_1376050148932_0006_01_000025 of capacity <memory:1024, vCores:1> on host hadoop-210-2:40150, which currently has 6 containers, <memory:7168, vCores:6> used and <memory:1024, vCores:10> available, release resources=true
2013-08-09 12:25:38,933 INFO org.apache.hadoop.yarn.server.resourcemanager.scheduler.capacity.LeafQueue: default used=<memory:48128, vCores:42> numContainers=42 user=ubuntu user-resources=<memory:48128, vCores:42>
2013-08-09 12:25:38,934 INFO org.apache.hadoop.yarn.server.resourcemanager.scheduler.capacity.LeafQueue: completedContainer container=Container: [ContainerId: container_1376050148932_0006_01_000025, NodeId: hadoop-210-2:40150, NodeHttpAddress: hadoop-210-2:8042, Resource: <memory:1024, vCores:1>, Priority: 20, State: NEW, Token: null, Status: container_id {, app_attempt_id {, application_id {, id: 6, cluster_timestamp: 1376050148932, }, attemptId: 1, }, id: 25, }, state: C_COMPLETE, diagnostics: "Container killed by the ApplicationMaster.\n\n", exit_status: 143, ] resource=<memory:1024, vCores:1> queue=default: capacity=1.0, absoluteCapacity=1.0, usedResources=<memory:48128, vCores:42>usedCapacity=0.9791667, absoluteUsedCapacity=0.9791667, numApps=5, numContainers=42 usedCapacity=0.9791667 absoluteUsedCapacity=0.9791667 used=<memory:48128, vCores:42> cluster=<memory:49152, vCores:96>
2013-08-09 12:25:38,934 INFO org.apache.hadoop.yarn.server.resourcemanager.scheduler.capacity.ParentQueue: completedContainer queue=root usedCapacity=0.9791667 absoluteUsedCapacity=0.9791667 used=<memory:48128, vCores:42> cluster=<memory:49152, vCores:96>
2013-08-09 12:25:38,934 INFO org.apache.hadoop.yarn.server.resourcemanager.scheduler.capacity.CapacityScheduler: Application appattempt_1376050148932_0006_000001 released container container_1376050148932_0006_01_000025 on node: host: hadoop-210-2:40150 #containers=6 available=1024 used=7168 with event: FINISHED
2013-08-09 12:25:38,935 INFO org.apache.hadoop.yarn.server.resourcemanager.rmcontainer.RMContainerImpl: container_1376050148932_0006_01_000027 Container Transitioned from RUNNING to COMPLETED
2013-08-09 12:25:38,935 INFO org.apache.hadoop.yarn.server.resourcemanager.scheduler.common.fica.FiCaSchedulerApp: Completed container: container_1376050148932_0006_01_000027 in state: COMPLETED event:FINISHED
2013-08-09 12:25:38,935 INFO org.apache.hadoop.yarn.server.resourcemanager.RMAuditLogger: USER=ubuntu	OPERATION=AM Released Container	TARGET=SchedulerApp	RESULT=SUCCESS	APPID=application_1376050148932_0006	CONTAINERID=container_1376050148932_0006_01_000027
