2013-08-07 08:59:02,093 INFO org.apache.hadoop.yarn.server.resourcemanager.ResourceManager: STARTUP_MSG: 
/************************************************************
STARTUP_MSG: Starting ResourceManager
STARTUP_MSG:   host = hadoop-200-1/192.168.100.2
STARTUP_MSG:   args = []
STARTUP_MSG:   version = 3.0.0-SNAPSHOT
STARTUP_MSG:   build = https://github.com/lalithsuresh/hadoop-common -r 0cb423bd4868928bb06cd93f882bb0913172fd17; compiled by 'lsuresh' on 2013-04-08T15:47Z
STARTUP_MSG:   java = 1.7.0_17
************************************************************/
2013-08-07 08:59:02,107 INFO org.apache.hadoop.yarn.server.resourcemanager.ResourceManager: registered UNIX signal handlers for [TERM, HUP, INT]
2013-08-07 08:59:02,879 INFO org.apache.hadoop.yarn.server.resourcemanager.security.ApplicationTokenSecretManager: Rolling master-key for application-tokens
2013-08-07 08:59:02,905 INFO org.apache.hadoop.yarn.server.resourcemanager.security.RMContainerTokenSecretManager: ContainerTokenKeyRollingInterval: 86400000ms and ContainerTokenKeyActivationDelay: 900000ms
2013-08-07 08:59:02,907 INFO org.apache.hadoop.yarn.service.AbstractService: Service:Dispatcher is inited.
2013-08-07 08:59:02,909 INFO org.apache.hadoop.yarn.event.AsyncDispatcher: Registering class org.apache.hadoop.yarn.server.resourcemanager.recovery.RMStateStoreEventType for class org.apache.hadoop.yarn.server.resourcemanager.recovery.RMStateStore$ForwardingEventHandler
2013-08-07 08:59:02,909 INFO org.apache.hadoop.yarn.service.AbstractService: Service:Dispatcher is started.
2013-08-07 08:59:02,914 INFO org.apache.hadoop.yarn.event.AsyncDispatcher: Registering class org.apache.hadoop.yarn.server.resourcemanager.NodesListManagerEventType for class org.apache.hadoop.yarn.server.resourcemanager.NodesListManager
2013-08-07 08:59:02,915 INFO org.apache.hadoop.yarn.server.resourcemanager.ResourceManager: Using Scheduler: org.apache.hadoop.yarn.server.resourcemanager.scheduler.capacity.CapacityScheduler
2013-08-07 08:59:03,068 INFO org.apache.hadoop.yarn.event.AsyncDispatcher: Registering class org.apache.hadoop.yarn.server.resourcemanager.scheduler.event.SchedulerEventType for class org.apache.hadoop.yarn.server.resourcemanager.ResourceManager$SchedulerEventDispatcher
2013-08-07 08:59:03,069 INFO org.apache.hadoop.yarn.event.AsyncDispatcher: Registering class org.apache.hadoop.yarn.server.resourcemanager.rmapp.RMAppEventType for class org.apache.hadoop.yarn.server.resourcemanager.ResourceManager$ApplicationEventDispatcher
2013-08-07 08:59:03,074 INFO org.apache.hadoop.yarn.event.AsyncDispatcher: Registering class org.apache.hadoop.yarn.server.resourcemanager.rmapp.attempt.RMAppAttemptEventType for class org.apache.hadoop.yarn.server.resourcemanager.ResourceManager$ApplicationAttemptEventDispatcher
2013-08-07 08:59:03,076 INFO org.apache.hadoop.yarn.event.AsyncDispatcher: Registering class org.apache.hadoop.yarn.server.resourcemanager.rmnode.RMNodeEventType for class org.apache.hadoop.yarn.server.resourcemanager.ResourceManager$NodeEventDispatcher
2013-08-07 08:59:03,735 WARN org.apache.hadoop.util.NativeCodeLoader: Unable to load native-hadoop library for your platform... using builtin-java classes where applicable
2013-08-07 08:59:03,801 INFO org.apache.hadoop.yarn.server.resourcemanager.scheduler.capacity.ParentQueue: root, capacity=1.0, asboluteCapacity=1.0, maxCapacity=1.0, asboluteMaxCapacity=1.0, state=RUNNING, acls=SUBMIT_APPLICATIONS:*ADMINISTER_QUEUE:*
2013-08-07 08:59:03,801 INFO org.apache.hadoop.yarn.server.resourcemanager.scheduler.capacity.ParentQueue: Initialized parent-queue root name=root, fullname=root
2013-08-07 08:59:03,823 INFO org.apache.hadoop.yarn.server.resourcemanager.scheduler.capacity.LeafQueue: Initializing default
capacity = 1.0 [= (float) configuredCapacity / 100 ]
asboluteCapacity = 1.0 [= parentAbsoluteCapacity * capacity ]
maxCapacity = 1.0 [= configuredMaxCapacity ]
absoluteMaxCapacity = 1.0 [= 1.0 maximumCapacity undefined, (parentAbsoluteMaxCapacity * maximumCapacity) / 100 otherwise ]
userLimit = 100 [= configuredUserLimit ]
userLimitFactor = 1.0 [= configuredUserLimitFactor ]
maxApplications = 10000 [= configuredMaximumSystemApplicationsPerQueue or (int)(configuredMaximumSystemApplications * absoluteCapacity)]
maxApplicationsPerUser = 10000 [= (int)(maxApplications * (userLimit / 100.0f) * userLimitFactor) ]
maxActiveApplications = 1 [= max((int)ceil((clusterResourceMemory / minimumAllocation) * maxAMResourcePerQueuePercent * absoluteMaxCapacity),1) ]
maxActiveAppsUsingAbsCap = 1 [= max((int)ceil((clusterResourceMemory / minimumAllocation) *maxAMResourcePercent * absoluteCapacity),1) ]
maxActiveApplicationsPerUser = 1 [= max((int)(maxActiveApplications * (userLimit / 100.0f) * userLimitFactor),1) ]
usedCapacity = 0.0 [= usedResourcesMemory / (clusterResourceMemory * absoluteCapacity)]
absoluteUsedCapacity = 0.0 [= usedResourcesMemory / clusterResourceMemory]
maxAMResourcePerQueuePercent = 0.1 [= configuredMaximumAMResourcePercent ]
minimumAllocationFactor = 0.875 [= (float)(maximumAllocationMemory - minimumAllocationMemory) / maximumAllocationMemory ]
numContainers = 0 [= currentNumContainers ]
state = RUNNING [= configuredState ]
acls = SUBMIT_APPLICATIONS:*ADMINISTER_QUEUE:* [= configuredAcls ]

2013-08-07 08:59:03,823 INFO org.apache.hadoop.yarn.server.resourcemanager.scheduler.capacity.CapacityScheduler: Initialized queue: default: capacity=1.0, absoluteCapacity=1.0, usedResources=<memory:0, vCores:0>usedCapacity=0.0, absoluteUsedCapacity=0.0, numApps=0, numContainers=0
2013-08-07 08:59:03,823 INFO org.apache.hadoop.yarn.server.resourcemanager.scheduler.capacity.CapacityScheduler: Initialized queue: root: numChildQueue= 1, capacity=1.0, absoluteCapacity=1.0, usedResources=<memory:0, vCores:0>usedCapacity=0.0, numApps=0, numContainers=0
2013-08-07 08:59:03,824 INFO org.apache.hadoop.yarn.server.resourcemanager.scheduler.capacity.CapacityScheduler: Initialized root queue root: numChildQueue= 1, capacity=1.0, absoluteCapacity=1.0, usedResources=<memory:0, vCores:0>usedCapacity=0.0, numApps=0, numContainers=0
2013-08-07 08:59:03,824 INFO org.apache.hadoop.yarn.server.resourcemanager.scheduler.capacity.CapacityScheduler: Initialized CapacityScheduler with calculator=class org.apache.hadoop.yarn.server.resourcemanager.resource.DefaultResourceCalculator, minimumAllocation=<<memory:1024, vCores:1>>, maximumAllocation=<<memory:8192, vCores:32>>
2013-08-07 08:59:04,259 INFO org.apache.hadoop.yarn.event.AsyncDispatcher: Registering class org.apache.hadoop.yarn.server.resourcemanager.RMAppManagerEventType for class org.apache.hadoop.yarn.server.resourcemanager.RMAppManager
2013-08-07 08:59:04,276 INFO org.apache.hadoop.yarn.event.AsyncDispatcher: Registering class org.apache.hadoop.yarn.server.resourcemanager.amlauncher.AMLauncherEventType for class org.apache.hadoop.yarn.server.resourcemanager.amlauncher.ApplicationMasterLauncher
2013-08-07 08:59:04,362 INFO org.apache.hadoop.yarn.server.resourcemanager.RMNMInfo: Registered RMNMInfo MBean
2013-08-07 08:59:04,363 INFO org.apache.hadoop.yarn.service.AbstractService: Service:Dispatcher is inited.
2013-08-07 08:59:04,363 INFO org.apache.hadoop.yarn.service.AbstractService: Service:org.apache.hadoop.yarn.server.resourcemanager.rmcontainer.ContainerAllocationExpirer is inited.
2013-08-07 08:59:04,363 INFO org.apache.hadoop.yarn.service.AbstractService: Service:AMLivelinessMonitor is inited.
2013-08-07 08:59:04,363 INFO org.apache.hadoop.yarn.service.AbstractService: Service:AMLivelinessMonitor is inited.
2013-08-07 08:59:04,363 INFO org.apache.hadoop.yarn.service.AbstractService: Service:org.apache.hadoop.yarn.server.resourcemanager.security.DelegationTokenRenewer is inited.
2013-08-07 08:59:04,365 INFO org.apache.hadoop.util.HostsFileReader: Refreshing hosts (include/exclude) list
2013-08-07 08:59:04,365 INFO org.apache.hadoop.yarn.service.AbstractService: Service:org.apache.hadoop.yarn.server.resourcemanager.NodesListManager is inited.
2013-08-07 08:59:04,365 INFO org.apache.hadoop.yarn.service.AbstractService: Service:org.apache.hadoop.yarn.server.resourcemanager.ResourceManager$SchedulerEventDispatcher is inited.
2013-08-07 08:59:04,365 INFO org.apache.hadoop.yarn.service.AbstractService: Service:NMLivelinessMonitor is inited.
2013-08-07 08:59:04,372 INFO org.apache.hadoop.yarn.service.AbstractService: Service:org.apache.hadoop.yarn.server.resourcemanager.ResourceTrackerService is inited.
2013-08-07 08:59:04,372 INFO org.apache.hadoop.yarn.service.AbstractService: Service:org.apache.hadoop.yarn.server.resourcemanager.ApplicationMasterService is inited.
2013-08-07 08:59:04,372 INFO org.apache.hadoop.yarn.service.AbstractService: Service:org.apache.hadoop.yarn.server.resourcemanager.ClientRMService is inited.
2013-08-07 08:59:04,372 INFO org.apache.hadoop.yarn.service.AbstractService: Service:org.apache.hadoop.yarn.server.resourcemanager.AdminService is inited.
2013-08-07 08:59:04,373 INFO org.apache.hadoop.yarn.service.AbstractService: Service:org.apache.hadoop.yarn.server.resourcemanager.amlauncher.ApplicationMasterLauncher is inited.
2013-08-07 08:59:04,373 INFO org.apache.hadoop.yarn.service.AbstractService: Service:ResourceManager is inited.
2013-08-07 08:59:04,373 INFO org.apache.hadoop.yarn.server.resourcemanager.security.RMContainerTokenSecretManager: Rolling master-key for container-tokens
2013-08-07 08:59:04,373 INFO org.apache.hadoop.yarn.server.resourcemanager.security.ApplicationTokenSecretManager: Rolling master-key for application-tokens
2013-08-07 08:59:04,530 INFO org.mortbay.log: Logging to org.slf4j.impl.Log4jLoggerAdapter(org.mortbay.log) via org.mortbay.log.Slf4jLog
2013-08-07 08:59:04,627 INFO org.apache.hadoop.http.HttpServer: Added global filter 'safety' (class=org.apache.hadoop.http.HttpServer$QuotingInputFilter)
2013-08-07 08:59:04,632 INFO org.apache.hadoop.http.HttpServer: Added filter static_user_filter (class=org.apache.hadoop.http.lib.StaticUserWebFilter$StaticUserFilter) to context cluster
2013-08-07 08:59:04,632 INFO org.apache.hadoop.http.HttpServer: Added filter static_user_filter (class=org.apache.hadoop.http.lib.StaticUserWebFilter$StaticUserFilter) to context static
2013-08-07 08:59:04,632 INFO org.apache.hadoop.http.HttpServer: Added filter static_user_filter (class=org.apache.hadoop.http.lib.StaticUserWebFilter$StaticUserFilter) to context logs
2013-08-07 08:59:04,639 INFO org.apache.hadoop.http.HttpServer: adding path spec: /cluster
2013-08-07 08:59:04,639 INFO org.apache.hadoop.http.HttpServer: adding path spec: /cluster/*
2013-08-07 08:59:04,640 INFO org.apache.hadoop.http.HttpServer: adding path spec: /ws
2013-08-07 08:59:04,640 INFO org.apache.hadoop.http.HttpServer: adding path spec: /ws/*
2013-08-07 08:59:04,643 INFO org.apache.hadoop.http.HttpServer: Added global filter 'guice' (class=com.google.inject.servlet.GuiceFilter)
2013-08-07 08:59:04,652 INFO org.apache.hadoop.http.HttpServer: Jetty bound to port 8088
2013-08-07 08:59:04,652 INFO org.mortbay.log: jetty-6.1.26
2013-08-07 08:59:04,702 INFO org.mortbay.log: Extract jar:file:/home/ubuntu/hadoop-3.0.0-SNAPSHOT/share/hadoop/yarn/hadoop-yarn-common-3.0.0-SNAPSHOT.jar!/webapps/cluster to /tmp/Jetty_0_0_0_0_8088_cluster____u0rgz3/webapp
2013-08-07 08:59:05,150 INFO org.mortbay.log: Started SelectChannelConnector@0.0.0.0:8088
2013-08-07 08:59:05,151 INFO org.apache.hadoop.yarn.webapp.WebApps: Web app /cluster started at 8088
2013-08-07 08:59:06,023 INFO org.apache.hadoop.yarn.webapp.WebApps: Registered webapp guice modules
2013-08-07 08:59:06,126 INFO org.apache.hadoop.metrics2.impl.MetricsConfig: loaded properties from hadoop-metrics2.properties
2013-08-07 08:59:06,158 INFO org.apache.hadoop.metrics2.impl.MetricsSystemImpl: Scheduled snapshot period at 10 second(s).
2013-08-07 08:59:06,158 INFO org.apache.hadoop.metrics2.impl.MetricsSystemImpl: ResourceManager metrics system started
2013-08-07 08:59:06,172 INFO org.apache.hadoop.security.token.delegation.AbstractDelegationTokenSecretManager: Updating the current master key for generating delegation tokens
2013-08-07 08:59:06,175 INFO org.apache.hadoop.yarn.service.AbstractService: Service:Dispatcher is started.
2013-08-07 08:59:06,176 INFO org.apache.hadoop.security.token.delegation.AbstractDelegationTokenSecretManager: Starting expired delegation token remover thread, tokenRemoverScanInterval=60 min(s)
2013-08-07 08:59:06,176 INFO org.apache.hadoop.security.token.delegation.AbstractDelegationTokenSecretManager: Updating the current master key for generating delegation tokens
2013-08-07 08:59:06,178 INFO org.apache.hadoop.yarn.service.AbstractService: Service:org.apache.hadoop.yarn.server.resourcemanager.rmcontainer.ContainerAllocationExpirer is started.
2013-08-07 08:59:06,178 INFO org.apache.hadoop.yarn.service.AbstractService: Service:AMLivelinessMonitor is started.
2013-08-07 08:59:06,178 INFO org.apache.hadoop.yarn.service.AbstractService: Service:AMLivelinessMonitor is started.
2013-08-07 08:59:06,179 INFO org.apache.hadoop.yarn.service.AbstractService: Service:org.apache.hadoop.yarn.server.resourcemanager.security.DelegationTokenRenewer is started.
2013-08-07 08:59:06,180 INFO org.apache.hadoop.yarn.service.AbstractService: Service:org.apache.hadoop.yarn.server.resourcemanager.NodesListManager is started.
2013-08-07 08:59:06,180 INFO org.apache.hadoop.yarn.service.AbstractService: Service:org.apache.hadoop.yarn.server.resourcemanager.ResourceManager$SchedulerEventDispatcher is started.
2013-08-07 08:59:06,181 INFO org.apache.hadoop.yarn.service.AbstractService: Service:NMLivelinessMonitor is started.
2013-08-07 08:59:06,181 INFO org.apache.hadoop.yarn.service.AbstractService: Service:org.apache.hadoop.yarn.server.resourcemanager.ResourceTrackerService is started.
2013-08-07 08:59:06,250 INFO org.apache.hadoop.ipc.Server: Starting Socket Reader #1 for port 54110
2013-08-07 08:59:06,288 INFO org.apache.hadoop.yarn.factories.impl.pb.RpcServerFactoryPBImpl: Adding protocol org.apache.hadoop.yarn.server.api.ResourceTrackerPB to the server
2013-08-07 08:59:06,290 INFO org.apache.hadoop.ipc.Server: IPC Server listener on 54110: starting
2013-08-07 08:59:06,290 INFO org.apache.hadoop.ipc.Server: IPC Server Responder: starting
2013-08-07 08:59:06,436 INFO org.apache.hadoop.ipc.Server: Starting Socket Reader #1 for port 54112
2013-08-07 08:59:06,447 INFO org.apache.hadoop.yarn.factories.impl.pb.RpcServerFactoryPBImpl: Adding protocol org.apache.hadoop.yarn.api.AMRMProtocolPB to the server
2013-08-07 08:59:06,448 INFO org.apache.hadoop.ipc.Server: IPC Server Responder: starting
2013-08-07 08:59:06,457 INFO org.apache.hadoop.ipc.Server: IPC Server listener on 54112: starting
2013-08-07 08:59:06,493 INFO org.apache.hadoop.yarn.service.AbstractService: Service:org.apache.hadoop.yarn.server.resourcemanager.ApplicationMasterService is started.
2013-08-07 08:59:06,533 INFO org.apache.hadoop.ipc.Server: Starting Socket Reader #1 for port 54111
2013-08-07 08:59:06,538 INFO org.apache.hadoop.yarn.factories.impl.pb.RpcServerFactoryPBImpl: Adding protocol org.apache.hadoop.yarn.api.ClientRMProtocolPB to the server
2013-08-07 08:59:06,539 INFO org.apache.hadoop.ipc.Server: IPC Server Responder: starting
2013-08-07 08:59:06,539 INFO org.apache.hadoop.ipc.Server: IPC Server listener on 54111: starting
2013-08-07 08:59:06,566 INFO org.apache.hadoop.yarn.service.AbstractService: Service:org.apache.hadoop.yarn.server.resourcemanager.ClientRMService is started.
2013-08-07 08:59:06,592 INFO org.apache.hadoop.ipc.Server: Starting Socket Reader #1 for port 8033
2013-08-07 08:59:06,596 INFO org.apache.hadoop.yarn.factories.impl.pb.RpcServerFactoryPBImpl: Adding protocol org.apache.hadoop.yarn.api.RMAdminProtocolPB to the server
2013-08-07 08:59:06,597 INFO org.apache.hadoop.ipc.Server: IPC Server Responder: starting
2013-08-07 08:59:06,598 INFO org.apache.hadoop.ipc.Server: IPC Server listener on 8033: starting
2013-08-07 08:59:06,610 INFO org.apache.hadoop.yarn.service.AbstractService: Service:org.apache.hadoop.yarn.server.resourcemanager.AdminService is started.
2013-08-07 08:59:06,610 INFO org.apache.hadoop.yarn.service.AbstractService: Service:org.apache.hadoop.yarn.server.resourcemanager.amlauncher.ApplicationMasterLauncher is started.
2013-08-07 08:59:06,610 INFO org.apache.hadoop.yarn.service.AbstractService: Service:ResourceManager is started.
2013-08-07 08:59:16,401 INFO org.apache.hadoop.yarn.util.RackResolver: Resolved hadoop-200-6 to /default-rack
2013-08-07 08:59:16,401 INFO org.apache.hadoop.yarn.util.RackResolver: Resolved hadoop-200-7 to /default-rack
2013-08-07 08:59:16,401 INFO org.apache.hadoop.yarn.util.RackResolver: Resolved hadoop-200-3 to /default-rack
2013-08-07 08:59:16,421 INFO org.apache.hadoop.yarn.server.resourcemanager.ResourceTrackerService: NodeManager from node hadoop-200-6(cmPort: 52835 httpPort: 8042) registered with capability: <memory:8192, vCores:16>, assigned nodeId hadoop-200-6:52835
2013-08-07 08:59:16,422 INFO org.apache.hadoop.yarn.server.resourcemanager.ResourceTrackerService: NodeManager from node hadoop-200-7(cmPort: 54925 httpPort: 8042) registered with capability: <memory:8192, vCores:16>, assigned nodeId hadoop-200-7:54925
2013-08-07 08:59:16,423 INFO org.apache.hadoop.yarn.server.resourcemanager.ResourceTrackerService: NodeManager from node hadoop-200-3(cmPort: 58063 httpPort: 8042) registered with capability: <memory:8192, vCores:16>, assigned nodeId hadoop-200-3:58063
2013-08-07 08:59:16,442 INFO org.apache.hadoop.yarn.util.RackResolver: Resolved hadoop-200-4 to /default-rack
2013-08-07 08:59:16,442 INFO org.apache.hadoop.yarn.server.resourcemanager.ResourceTrackerService: NodeManager from node hadoop-200-4(cmPort: 57320 httpPort: 8042) registered with capability: <memory:8192, vCores:16>, assigned nodeId hadoop-200-4:57320
2013-08-07 08:59:16,448 INFO org.apache.hadoop.yarn.server.resourcemanager.rmnode.RMNodeImpl: hadoop-200-6:52835 Node Transitioned from NEW to RUNNING
2013-08-07 08:59:16,449 INFO org.apache.hadoop.yarn.server.resourcemanager.rmnode.RMNodeImpl: hadoop-200-7:54925 Node Transitioned from NEW to RUNNING
2013-08-07 08:59:16,449 INFO org.apache.hadoop.yarn.server.resourcemanager.rmnode.RMNodeImpl: hadoop-200-3:58063 Node Transitioned from NEW to RUNNING
2013-08-07 08:59:16,450 INFO org.apache.hadoop.yarn.server.resourcemanager.rmnode.RMNodeImpl: hadoop-200-4:57320 Node Transitioned from NEW to RUNNING
2013-08-07 08:59:16,453 INFO org.apache.hadoop.yarn.server.resourcemanager.scheduler.capacity.CapacityScheduler: Added node hadoop-200-6:52835 clusterResource: <memory:8192, vCores:16>
2013-08-07 08:59:16,454 INFO org.apache.hadoop.yarn.server.resourcemanager.scheduler.capacity.CapacityScheduler: Added node hadoop-200-7:54925 clusterResource: <memory:16384, vCores:32>
2013-08-07 08:59:16,454 INFO org.apache.hadoop.yarn.server.resourcemanager.scheduler.capacity.CapacityScheduler: Added node hadoop-200-3:58063 clusterResource: <memory:24576, vCores:48>
2013-08-07 08:59:16,454 INFO org.apache.hadoop.yarn.server.resourcemanager.scheduler.capacity.CapacityScheduler: Added node hadoop-200-4:57320 clusterResource: <memory:32768, vCores:64>
2013-08-07 08:59:16,585 INFO org.apache.hadoop.yarn.util.RackResolver: Resolved hadoop-200-2 to /default-rack
2013-08-07 08:59:16,586 INFO org.apache.hadoop.yarn.server.resourcemanager.ResourceTrackerService: NodeManager from node hadoop-200-2(cmPort: 58832 httpPort: 8042) registered with capability: <memory:8192, vCores:16>, assigned nodeId hadoop-200-2:58832
2013-08-07 08:59:16,589 INFO org.apache.hadoop.yarn.server.resourcemanager.rmnode.RMNodeImpl: hadoop-200-2:58832 Node Transitioned from NEW to RUNNING
2013-08-07 08:59:16,590 INFO org.apache.hadoop.yarn.server.resourcemanager.scheduler.capacity.CapacityScheduler: Added node hadoop-200-2:58832 clusterResource: <memory:40960, vCores:80>
2013-08-07 08:59:22,832 INFO org.apache.hadoop.yarn.server.resourcemanager.ClientRMService: Allocated new applicationId: 1
2013-08-07 08:59:26,323 INFO org.apache.hadoop.yarn.server.resourcemanager.ClientRMService: Storing Application with id application_1375865942038_0001
2013-08-07 08:59:26,328 INFO org.apache.hadoop.yarn.server.resourcemanager.recovery.RMStateStore: Storing info for app: application_1375865942038_0001
2013-08-07 08:59:26,328 INFO org.apache.hadoop.yarn.server.resourcemanager.ClientRMService: Application with id 1 submitted by user ubuntu
2013-08-07 08:59:26,331 INFO org.apache.hadoop.yarn.server.resourcemanager.RMAuditLogger: USER=ubuntu	IP=192.168.100.2	OPERATION=Submit Application Request	TARGET=ClientRMService	RESULT=SUCCESS	APPID=application_1375865942038_0001
2013-08-07 08:59:26,373 INFO org.apache.hadoop.yarn.server.resourcemanager.rmapp.RMAppImpl: application_1375865942038_0001 State change from NEW to SUBMITTED
2013-08-07 08:59:26,374 INFO org.apache.hadoop.yarn.server.resourcemanager.ApplicationMasterService: Registering appattempt_1375865942038_0001_000001
2013-08-07 08:59:26,375 INFO org.apache.hadoop.yarn.server.resourcemanager.rmapp.attempt.RMAppAttemptImpl: appattempt_1375865942038_0001_000001 State change from NEW to SUBMITTED
2013-08-07 08:59:26,383 INFO org.apache.hadoop.yarn.util.RackResolver: Resolved hadoop-200-5 to /default-rack
2013-08-07 08:59:26,384 INFO org.apache.hadoop.yarn.server.resourcemanager.ResourceTrackerService: NodeManager from node hadoop-200-5(cmPort: 55554 httpPort: 8042) registered with capability: <memory:8192, vCores:16>, assigned nodeId hadoop-200-5:55554
2013-08-07 08:59:26,384 INFO org.apache.hadoop.yarn.server.resourcemanager.rmnode.RMNodeImpl: hadoop-200-5:55554 Node Transitioned from NEW to RUNNING
2013-08-07 08:59:26,411 INFO org.apache.hadoop.yarn.server.resourcemanager.scheduler.capacity.LeafQueue: Application application_1375865942038_0001 from user: ubuntu activated in queue: default
2013-08-07 08:59:26,411 INFO org.apache.hadoop.yarn.server.resourcemanager.scheduler.capacity.LeafQueue: Application added - appId: application_1375865942038_0001 user: org.apache.hadoop.yarn.server.resourcemanager.scheduler.capacity.LeafQueue$User@5f28e5cb, leaf-queue: default #user-pending-applications: 0 #user-active-applications: 1 #queue-pending-applications: 0 #queue-active-applications: 1
2013-08-07 08:59:26,412 INFO org.apache.hadoop.yarn.server.resourcemanager.scheduler.capacity.ParentQueue: Application added - appId: application_1375865942038_0001 user: ubuntu leaf-queue of parent: root #applications: 1
2013-08-07 08:59:26,412 INFO org.apache.hadoop.yarn.server.resourcemanager.scheduler.capacity.CapacityScheduler: Application Submission: appattempt_1375865942038_0001_000001, user: ubuntu queue: default: capacity=1.0, absoluteCapacity=1.0, usedResources=<memory:0, vCores:0>usedCapacity=0.0, absoluteUsedCapacity=0.0, numApps=1, numContainers=0, currently active: 1
2013-08-07 08:59:26,412 INFO org.apache.hadoop.yarn.server.resourcemanager.resource.ResourceCalculator: divideAndCeil called with a=49152 b=0
2013-08-07 08:59:26,413 INFO org.apache.hadoop.yarn.server.resourcemanager.scheduler.capacity.CapacityScheduler: Added node hadoop-200-5:55554 clusterResource: <memory:49152, vCores:96>
2013-08-07 08:59:26,422 INFO org.apache.hadoop.yarn.server.resourcemanager.rmapp.attempt.RMAppAttemptImpl: appattempt_1375865942038_0001_000001 State change from SUBMITTED to SCHEDULED
2013-08-07 08:59:26,422 INFO org.apache.hadoop.yarn.server.resourcemanager.rmapp.RMAppImpl: application_1375865942038_0001 State change from SUBMITTED to ACCEPTED
2013-08-07 08:59:26,485 INFO org.apache.hadoop.yarn.server.resourcemanager.rmcontainer.RMContainerImpl: container_1375865942038_0001_01_000001 Container Transitioned from NEW to ALLOCATED
2013-08-07 08:59:26,486 INFO org.apache.hadoop.yarn.server.resourcemanager.RMAuditLogger: USER=ubuntu	OPERATION=AM Allocated Container	TARGET=SchedulerApp	RESULT=SUCCESS	APPID=application_1375865942038_0001	CONTAINERID=container_1375865942038_0001_01_000001
2013-08-07 08:59:26,487 INFO org.apache.hadoop.yarn.server.resourcemanager.scheduler.common.fica.FiCaSchedulerNode: Assigned container container_1375865942038_0001_01_000001 of capacity <memory:2048, vCores:1> on host hadoop-200-5:55554, which currently has 1 containers, <memory:2048, vCores:1> used and <memory:6144, vCores:15> available
2013-08-07 08:59:26,493 INFO org.apache.hadoop.yarn.server.resourcemanager.scheduler.capacity.LeafQueue: assignedContainer application=application_1375865942038_0001 container=Container: [ContainerId: container_1375865942038_0001_01_000001, NodeId: hadoop-200-5:55554, NodeHttpAddress: hadoop-200-5:8042, Resource: <memory:2048, vCores:1>, Priority: 0, State: NEW, Token: null, Status: container_id {, app_attempt_id {, application_id {, id: 1, cluster_timestamp: 1375865942038, }, attemptId: 1, }, id: 1, }, state: C_NEW, ] containerId=container_1375865942038_0001_01_000001 queue=default: capacity=1.0, absoluteCapacity=1.0, usedResources=<memory:0, vCores:0>usedCapacity=0.0, absoluteUsedCapacity=0.0, numApps=1, numContainers=0 usedCapacity=0.0 absoluteUsedCapacity=0.0 used=<memory:0, vCores:0> cluster=<memory:49152, vCores:96>
2013-08-07 08:59:26,494 INFO org.apache.hadoop.yarn.server.resourcemanager.scheduler.capacity.ParentQueue: Re-sorting queues since queue: root.default stats: default: capacity=1.0, absoluteCapacity=1.0, usedResources=<memory:2048, vCores:1>usedCapacity=0.041666668, absoluteUsedCapacity=0.041666668, numApps=1, numContainers=1
2013-08-07 08:59:26,495 INFO org.apache.hadoop.yarn.server.resourcemanager.scheduler.capacity.ParentQueue: assignedContainer queue=root usedCapacity=0.041666668 absoluteUsedCapacity=0.041666668 used=<memory:2048, vCores:1> cluster=<memory:49152, vCores:96>
2013-08-07 08:59:26,497 INFO org.apache.hadoop.yarn.server.resourcemanager.rmcontainer.RMContainerImpl: container_1375865942038_0001_01_000001 Container Transitioned from ALLOCATED to ACQUIRED
2013-08-07 08:59:26,500 INFO org.apache.hadoop.yarn.server.resourcemanager.rmapp.attempt.RMAppAttemptImpl: Storing attempt: AppId: application_1375865942038_0001 AttemptId: appattempt_1375865942038_0001_000001 MasterContainer: Container: [ContainerId: container_1375865942038_0001_01_000001, NodeId: hadoop-200-5:55554, NodeHttpAddress: hadoop-200-5:8042, Resource: <memory:2048, vCores:1>, Priority: 0, State: NEW, Token: null, Status: container_id {, app_attempt_id {, application_id {, id: 1, cluster_timestamp: 1375865942038, }, attemptId: 1, }, id: 1, }, state: C_NEW, ]
2013-08-07 08:59:26,507 INFO org.apache.hadoop.yarn.server.resourcemanager.recovery.RMStateStore: Storing info for attempt: appattempt_1375865942038_0001_000001
2013-08-07 08:59:26,508 INFO org.apache.hadoop.yarn.server.resourcemanager.rmapp.attempt.RMAppAttemptImpl: appattempt_1375865942038_0001_000001 State change from SCHEDULED to ALLOCATED_SAVING
2013-08-07 08:59:26,511 INFO org.apache.hadoop.yarn.server.resourcemanager.rmapp.attempt.RMAppAttemptImpl: appattempt_1375865942038_0001_000001 State change from ALLOCATED_SAVING to ALLOCATED
2013-08-07 08:59:26,518 INFO org.apache.hadoop.yarn.server.resourcemanager.amlauncher.AMLauncher: Launching masterappattempt_1375865942038_0001_000001
2013-08-07 08:59:26,566 INFO org.apache.hadoop.yarn.server.resourcemanager.amlauncher.AMLauncher: Setting up container Container: [ContainerId: container_1375865942038_0001_01_000001, NodeId: hadoop-200-5:55554, NodeHttpAddress: hadoop-200-5:8042, Resource: <memory:2048, vCores:1>, Priority: 0, State: NEW, Token: null, Status: container_id {, app_attempt_id {, application_id {, id: 1, cluster_timestamp: 1375865942038, }, attemptId: 1, }, id: 1, }, state: C_NEW, ] for AM appattempt_1375865942038_0001_000001
2013-08-07 08:59:26,566 INFO org.apache.hadoop.yarn.server.resourcemanager.amlauncher.AMLauncher: Command to launch container container_1375865942038_0001_01_000001 : $JAVA_HOME/bin/java -Dlog4j.configuration=container-log4j.properties -Dyarn.app.mapreduce.container.log.dir=<LOG_DIR> -Dyarn.app.mapreduce.container.log.filesize=0 -Dhadoop.root.logger=INFO,CLA  -Xmx1024m org.apache.hadoop.mapreduce.v2.app.MRAppMaster 1><LOG_DIR>/stdout 2><LOG_DIR>/stderr 
2013-08-07 08:59:27,455 INFO org.apache.hadoop.yarn.server.resourcemanager.amlauncher.AMLauncher: Done launching container Container: [ContainerId: container_1375865942038_0001_01_000001, NodeId: hadoop-200-5:55554, NodeHttpAddress: hadoop-200-5:8042, Resource: <memory:2048, vCores:1>, Priority: 0, State: NEW, Token: null, Status: container_id {, app_attempt_id {, application_id {, id: 1, cluster_timestamp: 1375865942038, }, attemptId: 1, }, id: 1, }, state: C_NEW, ] for AM appattempt_1375865942038_0001_000001
2013-08-07 08:59:27,456 INFO org.apache.hadoop.yarn.server.resourcemanager.rmapp.attempt.RMAppAttemptImpl: appattempt_1375865942038_0001_000001 State change from ALLOCATED to LAUNCHED
2013-08-07 08:59:27,512 INFO org.apache.hadoop.yarn.server.resourcemanager.rmcontainer.RMContainerImpl: container_1375865942038_0001_01_000001 Container Transitioned from ACQUIRED to RUNNING
2013-08-07 08:59:36,326 INFO org.apache.hadoop.yarn.server.resourcemanager.ApplicationMasterService: AM registration appattempt_1375865942038_0001_000001
2013-08-07 08:59:36,327 INFO org.apache.hadoop.yarn.server.resourcemanager.RMAuditLogger: USER=ubuntu	IP=192.168.100.8	OPERATION=Register App Master	TARGET=ApplicationMasterService	RESULT=SUCCESS	APPID=application_1375865942038_0001	APPATTEMPTID=appattempt_1375865942038_0001_000001
2013-08-07 08:59:36,337 INFO org.apache.hadoop.yarn.server.resourcemanager.rmapp.attempt.RMAppAttemptImpl: appattempt_1375865942038_0001_000001 State change from LAUNCHED to RUNNING
2013-08-07 08:59:36,337 INFO org.apache.hadoop.yarn.server.resourcemanager.rmapp.RMAppImpl: application_1375865942038_0001 State change from ACCEPTED to RUNNING
2013-08-07 08:59:37,575 INFO org.apache.hadoop.yarn.server.resourcemanager.rmcontainer.RMContainerImpl: container_1375865942038_0001_01_000002 Container Transitioned from NEW to ALLOCATED
2013-08-07 08:59:37,575 INFO org.apache.hadoop.yarn.server.resourcemanager.RMAuditLogger: USER=ubuntu	OPERATION=AM Allocated Container	TARGET=SchedulerApp	RESULT=SUCCESS	APPID=application_1375865942038_0001	CONTAINERID=container_1375865942038_0001_01_000002
2013-08-07 08:59:37,576 INFO org.apache.hadoop.yarn.server.resourcemanager.scheduler.common.fica.FiCaSchedulerNode: Assigned container container_1375865942038_0001_01_000002 of capacity <memory:1024, vCores:1> on host hadoop-200-5:55554, which currently has 2 containers, <memory:3072, vCores:2> used and <memory:5120, vCores:14> available
2013-08-07 08:59:37,577 INFO org.apache.hadoop.yarn.server.resourcemanager.scheduler.capacity.LeafQueue: assignedContainer application=application_1375865942038_0001 container=Container: [ContainerId: container_1375865942038_0001_01_000002, NodeId: hadoop-200-5:55554, NodeHttpAddress: hadoop-200-5:8042, Resource: <memory:1024, vCores:1>, Priority: 20, State: NEW, Token: null, Status: container_id {, app_attempt_id {, application_id {, id: 1, cluster_timestamp: 1375865942038, }, attemptId: 1, }, id: 2, }, state: C_NEW, ] containerId=container_1375865942038_0001_01_000002 queue=default: capacity=1.0, absoluteCapacity=1.0, usedResources=<memory:2048, vCores:1>usedCapacity=0.041666668, absoluteUsedCapacity=0.041666668, numApps=1, numContainers=1 usedCapacity=0.041666668 absoluteUsedCapacity=0.041666668 used=<memory:2048, vCores:1> cluster=<memory:49152, vCores:96>
2013-08-07 08:59:37,578 INFO org.apache.hadoop.yarn.server.resourcemanager.scheduler.capacity.ParentQueue: Re-sorting queues since queue: root.default stats: default: capacity=1.0, absoluteCapacity=1.0, usedResources=<memory:3072, vCores:2>usedCapacity=0.0625, absoluteUsedCapacity=0.0625, numApps=1, numContainers=2
2013-08-07 08:59:37,578 INFO org.apache.hadoop.yarn.server.resourcemanager.scheduler.capacity.ParentQueue: assignedContainer queue=root usedCapacity=0.0625 absoluteUsedCapacity=0.0625 used=<memory:3072, vCores:2> cluster=<memory:49152, vCores:96>
2013-08-07 08:59:37,637 INFO org.apache.hadoop.yarn.server.resourcemanager.rmcontainer.RMContainerImpl: container_1375865942038_0001_01_000003 Container Transitioned from NEW to ALLOCATED
2013-08-07 08:59:37,637 INFO org.apache.hadoop.yarn.server.resourcemanager.RMAuditLogger: USER=ubuntu	OPERATION=AM Allocated Container	TARGET=SchedulerApp	RESULT=SUCCESS	APPID=application_1375865942038_0001	CONTAINERID=container_1375865942038_0001_01_000003
2013-08-07 08:59:37,637 INFO org.apache.hadoop.yarn.server.resourcemanager.scheduler.common.fica.FiCaSchedulerNode: Assigned container container_1375865942038_0001_01_000003 of capacity <memory:1024, vCores:1> on host hadoop-200-6:52835, which currently has 1 containers, <memory:1024, vCores:1> used and <memory:7168, vCores:15> available
2013-08-07 08:59:37,639 INFO org.apache.hadoop.yarn.server.resourcemanager.scheduler.capacity.LeafQueue: assignedContainer application=application_1375865942038_0001 container=Container: [ContainerId: container_1375865942038_0001_01_000003, NodeId: hadoop-200-6:52835, NodeHttpAddress: hadoop-200-6:8042, Resource: <memory:1024, vCores:1>, Priority: 20, State: NEW, Token: null, Status: container_id {, app_attempt_id {, application_id {, id: 1, cluster_timestamp: 1375865942038, }, attemptId: 1, }, id: 3, }, state: C_NEW, ] containerId=container_1375865942038_0001_01_000003 queue=default: capacity=1.0, absoluteCapacity=1.0, usedResources=<memory:3072, vCores:2>usedCapacity=0.0625, absoluteUsedCapacity=0.0625, numApps=1, numContainers=2 usedCapacity=0.0625 absoluteUsedCapacity=0.0625 used=<memory:3072, vCores:2> cluster=<memory:49152, vCores:96>
2013-08-07 08:59:37,639 INFO org.apache.hadoop.yarn.server.resourcemanager.scheduler.capacity.ParentQueue: Re-sorting queues since queue: root.default stats: default: capacity=1.0, absoluteCapacity=1.0, usedResources=<memory:4096, vCores:3>usedCapacity=0.083333336, absoluteUsedCapacity=0.083333336, numApps=1, numContainers=3
2013-08-07 08:59:37,640 INFO org.apache.hadoop.yarn.server.resourcemanager.scheduler.capacity.ParentQueue: assignedContainer queue=root usedCapacity=0.083333336 absoluteUsedCapacity=0.083333336 used=<memory:4096, vCores:3> cluster=<memory:49152, vCores:96>
2013-08-07 08:59:38,397 INFO org.apache.hadoop.yarn.server.resourcemanager.rmcontainer.RMContainerImpl: container_1375865942038_0001_01_000002 Container Transitioned from ALLOCATED to ACQUIRED
2013-08-07 08:59:38,398 INFO org.apache.hadoop.yarn.server.resourcemanager.rmcontainer.RMContainerImpl: container_1375865942038_0001_01_000003 Container Transitioned from ALLOCATED to ACQUIRED
2013-08-07 08:59:39,437 INFO org.apache.hadoop.yarn.server.resourcemanager.scheduler.AppSchedulingInfo: checking for deactivate... 
2013-08-07 08:59:39,590 INFO org.apache.hadoop.yarn.server.resourcemanager.rmcontainer.RMContainerImpl: container_1375865942038_0001_01_000002 Container Transitioned from ACQUIRED to RUNNING
2013-08-07 08:59:39,840 INFO org.apache.hadoop.yarn.server.resourcemanager.rmcontainer.RMContainerImpl: container_1375865942038_0001_01_000003 Container Transitioned from ACQUIRED to RUNNING
2013-08-07 09:01:22,794 INFO org.apache.hadoop.yarn.server.resourcemanager.rmcontainer.RMContainerImpl: container_1375865942038_0001_01_000002 Container Transitioned from RUNNING to COMPLETED
2013-08-07 09:01:22,794 INFO org.apache.hadoop.yarn.server.resourcemanager.scheduler.common.fica.FiCaSchedulerApp: Completed container: container_1375865942038_0001_01_000002 in state: COMPLETED event:FINISHED
2013-08-07 09:01:22,794 INFO org.apache.hadoop.yarn.server.resourcemanager.RMAuditLogger: USER=ubuntu	OPERATION=AM Released Container	TARGET=SchedulerApp	RESULT=SUCCESS	APPID=application_1375865942038_0001	CONTAINERID=container_1375865942038_0001_01_000002
2013-08-07 09:01:22,795 INFO org.apache.hadoop.yarn.server.resourcemanager.scheduler.common.fica.FiCaSchedulerNode: Released container container_1375865942038_0001_01_000002 of capacity <memory:1024, vCores:1> on host hadoop-200-5:55554, which currently has 1 containers, <memory:2048, vCores:1> used and <memory:6144, vCores:15> available, release resources=true
2013-08-07 09:01:22,795 INFO org.apache.hadoop.yarn.server.resourcemanager.scheduler.capacity.LeafQueue: default used=<memory:3072, vCores:2> numContainers=2 user=ubuntu user-resources=<memory:3072, vCores:2>
2013-08-07 09:01:22,797 INFO org.apache.hadoop.yarn.server.resourcemanager.scheduler.capacity.LeafQueue: completedContainer container=Container: [ContainerId: container_1375865942038_0001_01_000002, NodeId: hadoop-200-5:55554, NodeHttpAddress: hadoop-200-5:8042, Resource: <memory:1024, vCores:1>, Priority: 20, State: NEW, Token: null, Status: container_id {, app_attempt_id {, application_id {, id: 1, cluster_timestamp: 1375865942038, }, attemptId: 1, }, id: 2, }, state: C_COMPLETE, diagnostics: "Container killed by the ApplicationMaster.\n\n", exit_status: 143, ] resource=<memory:1024, vCores:1> queue=default: capacity=1.0, absoluteCapacity=1.0, usedResources=<memory:3072, vCores:2>usedCapacity=0.0625, absoluteUsedCapacity=0.0625, numApps=1, numContainers=2 usedCapacity=0.0625 absoluteUsedCapacity=0.0625 used=<memory:3072, vCores:2> cluster=<memory:49152, vCores:96>
2013-08-07 09:01:22,797 INFO org.apache.hadoop.yarn.server.resourcemanager.scheduler.capacity.ParentQueue: completedContainer queue=root usedCapacity=0.0625 absoluteUsedCapacity=0.0625 used=<memory:3072, vCores:2> cluster=<memory:49152, vCores:96>
2013-08-07 09:01:22,797 INFO org.apache.hadoop.yarn.server.resourcemanager.scheduler.capacity.CapacityScheduler: Application appattempt_1375865942038_0001_000001 released container container_1375865942038_0001_01_000002 on node: host: hadoop-200-5:55554 #containers=1 available=6144 used=2048 with event: FINISHED
2013-08-07 09:01:24,021 INFO org.apache.hadoop.yarn.server.resourcemanager.rmcontainer.RMContainerImpl: container_1375865942038_0001_01_000003 Container Transitioned from RUNNING to COMPLETED
2013-08-07 09:01:24,022 INFO org.apache.hadoop.yarn.server.resourcemanager.scheduler.common.fica.FiCaSchedulerApp: Completed container: container_1375865942038_0001_01_000003 in state: COMPLETED event:FINISHED
2013-08-07 09:01:24,027 INFO org.apache.hadoop.yarn.server.resourcemanager.RMAuditLogger: USER=ubuntu	OPERATION=AM Released Container	TARGET=SchedulerApp	RESULT=SUCCESS	APPID=application_1375865942038_0001	CONTAINERID=container_1375865942038_0001_01_000003
2013-08-07 09:01:24,027 INFO org.apache.hadoop.yarn.server.resourcemanager.scheduler.common.fica.FiCaSchedulerNode: Released container container_1375865942038_0001_01_000003 of capacity <memory:1024, vCores:1> on host hadoop-200-6:52835, which currently has 0 containers, <memory:0, vCores:0> used and <memory:8192, vCores:16> available, release resources=true
2013-08-07 09:01:24,027 INFO org.apache.hadoop.yarn.server.resourcemanager.scheduler.capacity.LeafQueue: default used=<memory:2048, vCores:1> numContainers=1 user=ubuntu user-resources=<memory:2048, vCores:1>
2013-08-07 09:01:24,030 INFO org.apache.hadoop.yarn.server.resourcemanager.scheduler.capacity.LeafQueue: completedContainer container=Container: [ContainerId: container_1375865942038_0001_01_000003, NodeId: hadoop-200-6:52835, NodeHttpAddress: hadoop-200-6:8042, Resource: <memory:1024, vCores:1>, Priority: 20, State: NEW, Token: null, Status: container_id {, app_attempt_id {, application_id {, id: 1, cluster_timestamp: 1375865942038, }, attemptId: 1, }, id: 3, }, state: C_COMPLETE, diagnostics: "Container killed by the ApplicationMaster.\n\n", exit_status: 143, ] resource=<memory:1024, vCores:1> queue=default: capacity=1.0, absoluteCapacity=1.0, usedResources=<memory:2048, vCores:1>usedCapacity=0.041666668, absoluteUsedCapacity=0.041666668, numApps=1, numContainers=1 usedCapacity=0.041666668 absoluteUsedCapacity=0.041666668 used=<memory:2048, vCores:1> cluster=<memory:49152, vCores:96>
2013-08-07 09:01:24,030 INFO org.apache.hadoop.yarn.server.resourcemanager.scheduler.capacity.ParentQueue: completedContainer queue=root usedCapacity=0.041666668 absoluteUsedCapacity=0.041666668 used=<memory:2048, vCores:1> cluster=<memory:49152, vCores:96>
2013-08-07 09:01:24,030 INFO org.apache.hadoop.yarn.server.resourcemanager.scheduler.capacity.CapacityScheduler: Application appattempt_1375865942038_0001_000001 released container container_1375865942038_0001_01_000003 on node: host: hadoop-200-6:52835 #containers=0 available=8192 used=0 with event: FINISHED
2013-08-07 09:01:28,177 INFO org.apache.hadoop.yarn.server.resourcemanager.rmapp.attempt.RMAppAttemptImpl: appattempt_1375865942038_0001_000001 State change from RUNNING to FINISHING
2013-08-07 09:01:28,178 INFO org.apache.hadoop.yarn.server.resourcemanager.rmapp.RMAppImpl: application_1375865942038_0001 State change from RUNNING to FINISHING
2013-08-07 09:01:28,827 INFO org.apache.hadoop.yarn.server.resourcemanager.rmcontainer.RMContainerImpl: container_1375865942038_0001_01_000001 Container Transitioned from RUNNING to COMPLETED
2013-08-07 09:01:28,828 INFO org.apache.hadoop.yarn.server.resourcemanager.scheduler.common.fica.FiCaSchedulerApp: Completed container: container_1375865942038_0001_01_000001 in state: COMPLETED event:FINISHED
2013-08-07 09:01:28,828 INFO org.apache.hadoop.yarn.server.resourcemanager.RMAuditLogger: USER=ubuntu	OPERATION=AM Released Container	TARGET=SchedulerApp	RESULT=SUCCESS	APPID=application_1375865942038_0001	CONTAINERID=container_1375865942038_0001_01_000001
2013-08-07 09:01:28,828 INFO org.apache.hadoop.yarn.server.resourcemanager.scheduler.common.fica.FiCaSchedulerNode: Released container container_1375865942038_0001_01_000001 of capacity <memory:2048, vCores:1> on host hadoop-200-5:55554, which currently has 0 containers, <memory:0, vCores:0> used and <memory:8192, vCores:16> available, release resources=true
2013-08-07 09:01:28,828 INFO org.apache.hadoop.yarn.server.resourcemanager.scheduler.capacity.LeafQueue: default used=<memory:0, vCores:0> numContainers=0 user=ubuntu user-resources=<memory:0, vCores:0>
2013-08-07 09:01:28,830 INFO org.apache.hadoop.yarn.server.resourcemanager.scheduler.capacity.LeafQueue: completedContainer container=Container: [ContainerId: container_1375865942038_0001_01_000001, NodeId: hadoop-200-5:55554, NodeHttpAddress: hadoop-200-5:8042, Resource: <memory:2048, vCores:1>, Priority: 0, State: NEW, Token: null, Status: container_id {, app_attempt_id {, application_id {, id: 1, cluster_timestamp: 1375865942038, }, attemptId: 1, }, id: 1, }, state: C_COMPLETE, diagnostics: "", exit_status: 0, ] resource=<memory:2048, vCores:1> queue=default: capacity=1.0, absoluteCapacity=1.0, usedResources=<memory:0, vCores:0>usedCapacity=0.0, absoluteUsedCapacity=0.0, numApps=1, numContainers=0 usedCapacity=0.0 absoluteUsedCapacity=0.0 used=<memory:0, vCores:0> cluster=<memory:49152, vCores:96>
2013-08-07 09:01:28,830 INFO org.apache.hadoop.yarn.server.resourcemanager.rmapp.attempt.RMAppAttemptImpl: appattempt_1375865942038_0001_000001 State change from FINISHING to FINISHED
2013-08-07 09:01:28,832 INFO org.apache.hadoop.yarn.server.resourcemanager.rmapp.RMAppImpl: application_1375865942038_0001 State change from FINISHING to FINISHED
2013-08-07 09:01:28,832 INFO org.apache.hadoop.yarn.server.resourcemanager.RMAuditLogger: USER=ubuntu	OPERATION=Application Finished - Succeeded	TARGET=RMAppManager	RESULT=SUCCESS	APPID=application_1375865942038_0001
2013-08-07 09:01:28,848 INFO org.apache.hadoop.yarn.server.resourcemanager.recovery.RMStateStore: Removing info for app: application_1375865942038_0001
2013-08-07 09:01:28,830 INFO org.apache.hadoop.yarn.server.resourcemanager.scheduler.capacity.ParentQueue: completedContainer queue=root usedCapacity=0.0 absoluteUsedCapacity=0.0 used=<memory:0, vCores:0> cluster=<memory:49152, vCores:96>
2013-08-07 09:01:28,833 INFO org.apache.hadoop.yarn.server.resourcemanager.amlauncher.AMLauncher: Cleaning master appattempt_1375865942038_0001_000001
2013-08-07 09:01:28,850 INFO org.apache.hadoop.yarn.server.resourcemanager.RMAppManager$ApplicationSummary: appId=application_1375865942038_0001,name=TeraGen,user=ubuntu,queue=default,state=FINISHED,trackingUrl=hadoop-200-1.novalocal:8088/proxy/application_1375865942038_0001/jobhistory/job/job_1375865942038_0001,appMasterHost=hadoop-200-5,startTime=1375865966316,finishTime=1375866088178
2013-08-07 09:01:28,851 INFO org.apache.hadoop.yarn.server.resourcemanager.scheduler.capacity.CapacityScheduler: Application appattempt_1375865942038_0001_000001 released container container_1375865942038_0001_01_000001 on node: host: hadoop-200-5:55554 #containers=0 available=8192 used=0 with event: FINISHED
2013-08-07 09:01:28,858 INFO org.apache.hadoop.yarn.server.resourcemanager.scheduler.capacity.CapacityScheduler: Application appattempt_1375865942038_0001_000001 is done. finalState=FINISHED
2013-08-07 09:01:28,859 INFO org.apache.hadoop.yarn.server.resourcemanager.scheduler.AppSchedulingInfo: Application application_1375865942038_0001 requests cleared
2013-08-07 09:01:28,863 INFO org.apache.hadoop.yarn.server.resourcemanager.scheduler.capacity.LeafQueue: Application removed - appId: application_1375865942038_0001 user: ubuntu queue: default #user-pending-applications: 0 #user-active-applications: 0 #queue-pending-applications: 0 #queue-active-applications: 0
2013-08-07 09:01:28,863 INFO org.apache.hadoop.yarn.server.resourcemanager.scheduler.capacity.ParentQueue: Application removed - appId: application_1375865942038_0001 user: ubuntu leaf-queue of parent: root #applications: 0
2013-08-07 09:01:29,909 INFO org.apache.hadoop.yarn.server.resourcemanager.ClientRMService: Allocated new applicationId: 2
2013-08-07 09:01:31,979 INFO org.apache.hadoop.yarn.server.resourcemanager.ClientRMService: Storing Application with id application_1375865942038_0002
2013-08-07 09:01:31,979 INFO org.apache.hadoop.yarn.server.resourcemanager.recovery.RMStateStore: Storing info for app: application_1375865942038_0002
2013-08-07 09:01:31,979 INFO org.apache.hadoop.yarn.server.resourcemanager.ClientRMService: Application with id 2 submitted by user ubuntu
2013-08-07 09:01:31,979 INFO org.apache.hadoop.yarn.server.resourcemanager.RMAuditLogger: USER=ubuntu	IP=192.168.100.2	OPERATION=Submit Application Request	TARGET=ClientRMService	RESULT=SUCCESS	APPID=application_1375865942038_0002
2013-08-07 09:01:31,981 INFO org.apache.hadoop.yarn.server.resourcemanager.rmapp.RMAppImpl: application_1375865942038_0002 State change from NEW to SUBMITTED
2013-08-07 09:01:31,981 INFO org.apache.hadoop.yarn.server.resourcemanager.ApplicationMasterService: Registering appattempt_1375865942038_0002_000001
2013-08-07 09:01:31,981 INFO org.apache.hadoop.yarn.server.resourcemanager.rmapp.attempt.RMAppAttemptImpl: appattempt_1375865942038_0002_000001 State change from NEW to SUBMITTED
2013-08-07 09:01:31,982 INFO org.apache.hadoop.yarn.server.resourcemanager.scheduler.capacity.LeafQueue: Application application_1375865942038_0002 from user: ubuntu activated in queue: default
2013-08-07 09:01:31,982 INFO org.apache.hadoop.yarn.server.resourcemanager.scheduler.capacity.LeafQueue: Application added - appId: application_1375865942038_0002 user: org.apache.hadoop.yarn.server.resourcemanager.scheduler.capacity.LeafQueue$User@2ee9390f, leaf-queue: default #user-pending-applications: 0 #user-active-applications: 1 #queue-pending-applications: 0 #queue-active-applications: 1
2013-08-07 09:01:31,982 INFO org.apache.hadoop.yarn.server.resourcemanager.scheduler.capacity.ParentQueue: Application added - appId: application_1375865942038_0002 user: ubuntu leaf-queue of parent: root #applications: 1
2013-08-07 09:01:31,982 INFO org.apache.hadoop.yarn.server.resourcemanager.scheduler.capacity.CapacityScheduler: Application Submission: appattempt_1375865942038_0002_000001, user: ubuntu queue: default: capacity=1.0, absoluteCapacity=1.0, usedResources=<memory:0, vCores:0>usedCapacity=0.0, absoluteUsedCapacity=0.0, numApps=1, numContainers=0, currently active: 1
2013-08-07 09:01:31,983 INFO org.apache.hadoop.yarn.server.resourcemanager.rmapp.attempt.RMAppAttemptImpl: appattempt_1375865942038_0002_000001 State change from SUBMITTED to SCHEDULED
2013-08-07 09:01:31,983 INFO org.apache.hadoop.yarn.server.resourcemanager.rmapp.RMAppImpl: application_1375865942038_0002 State change from SUBMITTED to ACCEPTED
2013-08-07 09:01:32,058 INFO org.apache.hadoop.yarn.server.resourcemanager.rmcontainer.RMContainerImpl: container_1375865942038_0002_01_000001 Container Transitioned from NEW to ALLOCATED
2013-08-07 09:01:32,058 INFO org.apache.hadoop.yarn.server.resourcemanager.RMAuditLogger: USER=ubuntu	OPERATION=AM Allocated Container	TARGET=SchedulerApp	RESULT=SUCCESS	APPID=application_1375865942038_0002	CONTAINERID=container_1375865942038_0002_01_000001
2013-08-07 09:01:32,058 INFO org.apache.hadoop.yarn.server.resourcemanager.scheduler.common.fica.FiCaSchedulerNode: Assigned container container_1375865942038_0002_01_000001 of capacity <memory:2048, vCores:1> on host hadoop-200-6:52835, which currently has 1 containers, <memory:2048, vCores:1> used and <memory:6144, vCores:15> available
2013-08-07 09:01:32,060 INFO org.apache.hadoop.yarn.server.resourcemanager.scheduler.capacity.LeafQueue: assignedContainer application=application_1375865942038_0002 container=Container: [ContainerId: container_1375865942038_0002_01_000001, NodeId: hadoop-200-6:52835, NodeHttpAddress: hadoop-200-6:8042, Resource: <memory:2048, vCores:1>, Priority: 0, State: NEW, Token: null, Status: container_id {, app_attempt_id {, application_id {, id: 2, cluster_timestamp: 1375865942038, }, attemptId: 1, }, id: 1, }, state: C_NEW, ] containerId=container_1375865942038_0002_01_000001 queue=default: capacity=1.0, absoluteCapacity=1.0, usedResources=<memory:0, vCores:0>usedCapacity=0.0, absoluteUsedCapacity=0.0, numApps=1, numContainers=0 usedCapacity=0.0 absoluteUsedCapacity=0.0 used=<memory:0, vCores:0> cluster=<memory:49152, vCores:96>
2013-08-07 09:01:32,060 INFO org.apache.hadoop.yarn.server.resourcemanager.scheduler.capacity.ParentQueue: Re-sorting queues since queue: root.default stats: default: capacity=1.0, absoluteCapacity=1.0, usedResources=<memory:2048, vCores:1>usedCapacity=0.041666668, absoluteUsedCapacity=0.041666668, numApps=1, numContainers=1
2013-08-07 09:01:32,062 INFO org.apache.hadoop.yarn.server.resourcemanager.rmcontainer.RMContainerImpl: container_1375865942038_0002_01_000001 Container Transitioned from ALLOCATED to ACQUIRED
2013-08-07 09:01:32,064 INFO org.apache.hadoop.yarn.server.resourcemanager.rmapp.attempt.RMAppAttemptImpl: Storing attempt: AppId: application_1375865942038_0002 AttemptId: appattempt_1375865942038_0002_000001 MasterContainer: Container: [ContainerId: container_1375865942038_0002_01_000001, NodeId: hadoop-200-6:52835, NodeHttpAddress: hadoop-200-6:8042, Resource: <memory:2048, vCores:1>, Priority: 0, State: NEW, Token: null, Status: container_id {, app_attempt_id {, application_id {, id: 2, cluster_timestamp: 1375865942038, }, attemptId: 1, }, id: 1, }, state: C_NEW, ]
2013-08-07 09:01:32,064 INFO org.apache.hadoop.yarn.server.resourcemanager.rmapp.attempt.RMAppAttemptImpl: appattempt_1375865942038_0002_000001 State change from SCHEDULED to ALLOCATED_SAVING
2013-08-07 09:01:32,064 INFO org.apache.hadoop.yarn.server.resourcemanager.recovery.RMStateStore: Storing info for attempt: appattempt_1375865942038_0002_000001
2013-08-07 09:01:32,064 INFO org.apache.hadoop.yarn.server.resourcemanager.scheduler.capacity.ParentQueue: assignedContainer queue=root usedCapacity=0.041666668 absoluteUsedCapacity=0.041666668 used=<memory:2048, vCores:1> cluster=<memory:49152, vCores:96>
2013-08-07 09:01:32,066 INFO org.apache.hadoop.yarn.server.resourcemanager.rmapp.attempt.RMAppAttemptImpl: appattempt_1375865942038_0002_000001 State change from ALLOCATED_SAVING to ALLOCATED
2013-08-07 09:01:32,067 INFO org.apache.hadoop.yarn.server.resourcemanager.amlauncher.AMLauncher: Launching masterappattempt_1375865942038_0002_000001
2013-08-07 09:01:32,071 INFO org.apache.hadoop.yarn.server.resourcemanager.amlauncher.AMLauncher: Setting up container Container: [ContainerId: container_1375865942038_0002_01_000001, NodeId: hadoop-200-6:52835, NodeHttpAddress: hadoop-200-6:8042, Resource: <memory:2048, vCores:1>, Priority: 0, State: NEW, Token: null, Status: container_id {, app_attempt_id {, application_id {, id: 2, cluster_timestamp: 1375865942038, }, attemptId: 1, }, id: 1, }, state: C_NEW, ] for AM appattempt_1375865942038_0002_000001
2013-08-07 09:01:32,071 INFO org.apache.hadoop.yarn.server.resourcemanager.amlauncher.AMLauncher: Command to launch container container_1375865942038_0002_01_000001 : $JAVA_HOME/bin/java -Dlog4j.configuration=container-log4j.properties -Dyarn.app.mapreduce.container.log.dir=<LOG_DIR> -Dyarn.app.mapreduce.container.log.filesize=0 -Dhadoop.root.logger=INFO,CLA  -Xmx1024m org.apache.hadoop.mapreduce.v2.app.MRAppMaster 1><LOG_DIR>/stdout 2><LOG_DIR>/stderr 
2013-08-07 09:01:32,103 INFO org.apache.hadoop.yarn.server.resourcemanager.amlauncher.AMLauncher: Done launching container Container: [ContainerId: container_1375865942038_0002_01_000001, NodeId: hadoop-200-6:52835, NodeHttpAddress: hadoop-200-6:8042, Resource: <memory:2048, vCores:1>, Priority: 0, State: NEW, Token: null, Status: container_id {, app_attempt_id {, application_id {, id: 2, cluster_timestamp: 1375865942038, }, attemptId: 1, }, id: 1, }, state: C_NEW, ] for AM appattempt_1375865942038_0002_000001
2013-08-07 09:01:32,104 INFO org.apache.hadoop.yarn.server.resourcemanager.rmapp.attempt.RMAppAttemptImpl: appattempt_1375865942038_0002_000001 State change from ALLOCATED to LAUNCHED
2013-08-07 09:01:33,063 INFO org.apache.hadoop.yarn.server.resourcemanager.rmcontainer.RMContainerImpl: container_1375865942038_0002_01_000001 Container Transitioned from ACQUIRED to RUNNING
2013-08-07 09:01:52,357 INFO org.apache.hadoop.yarn.server.resourcemanager.ApplicationMasterService: AM registration appattempt_1375865942038_0002_000001
2013-08-07 09:01:52,358 INFO org.apache.hadoop.yarn.server.resourcemanager.RMAuditLogger: USER=ubuntu	IP=192.168.100.10	OPERATION=Register App Master	TARGET=ApplicationMasterService	RESULT=SUCCESS	APPID=application_1375865942038_0002	APPATTEMPTID=appattempt_1375865942038_0002_000001
2013-08-07 09:01:52,366 INFO org.apache.hadoop.yarn.server.resourcemanager.rmapp.attempt.RMAppAttemptImpl: appattempt_1375865942038_0002_000001 State change from LAUNCHED to RUNNING
2013-08-07 09:01:52,367 INFO org.apache.hadoop.yarn.server.resourcemanager.rmapp.RMAppImpl: application_1375865942038_0002 State change from ACCEPTED to RUNNING
2013-08-07 09:01:53,917 INFO org.apache.hadoop.yarn.server.resourcemanager.rmcontainer.RMContainerImpl: container_1375865942038_0002_01_000002 Container Transitioned from NEW to ALLOCATED
2013-08-07 09:01:53,917 INFO org.apache.hadoop.yarn.server.resourcemanager.RMAuditLogger: USER=ubuntu	OPERATION=AM Allocated Container	TARGET=SchedulerApp	RESULT=SUCCESS	APPID=application_1375865942038_0002	CONTAINERID=container_1375865942038_0002_01_000002
2013-08-07 09:01:53,918 INFO org.apache.hadoop.yarn.server.resourcemanager.scheduler.common.fica.FiCaSchedulerNode: Assigned container container_1375865942038_0002_01_000002 of capacity <memory:1024, vCores:1> on host hadoop-200-5:55554, which currently has 1 containers, <memory:1024, vCores:1> used and <memory:7168, vCores:15> available
2013-08-07 09:01:53,919 INFO org.apache.hadoop.yarn.server.resourcemanager.scheduler.capacity.LeafQueue: assignedContainer application=application_1375865942038_0002 container=Container: [ContainerId: container_1375865942038_0002_01_000002, NodeId: hadoop-200-5:55554, NodeHttpAddress: hadoop-200-5:8042, Resource: <memory:1024, vCores:1>, Priority: 20, State: NEW, Token: null, Status: container_id {, app_attempt_id {, application_id {, id: 2, cluster_timestamp: 1375865942038, }, attemptId: 1, }, id: 2, }, state: C_NEW, ] containerId=container_1375865942038_0002_01_000002 queue=default: capacity=1.0, absoluteCapacity=1.0, usedResources=<memory:2048, vCores:1>usedCapacity=0.041666668, absoluteUsedCapacity=0.041666668, numApps=1, numContainers=1 usedCapacity=0.041666668 absoluteUsedCapacity=0.041666668 used=<memory:2048, vCores:1> cluster=<memory:49152, vCores:96>
2013-08-07 09:01:53,920 INFO org.apache.hadoop.yarn.server.resourcemanager.scheduler.capacity.ParentQueue: Re-sorting queues since queue: root.default stats: default: capacity=1.0, absoluteCapacity=1.0, usedResources=<memory:3072, vCores:2>usedCapacity=0.0625, absoluteUsedCapacity=0.0625, numApps=1, numContainers=2
2013-08-07 09:01:53,920 INFO org.apache.hadoop.yarn.server.resourcemanager.scheduler.capacity.ParentQueue: assignedContainer queue=root usedCapacity=0.0625 absoluteUsedCapacity=0.0625 used=<memory:3072, vCores:2> cluster=<memory:49152, vCores:96>
2013-08-07 09:01:54,166 INFO org.apache.hadoop.yarn.server.resourcemanager.rmcontainer.RMContainerImpl: container_1375865942038_0002_01_000003 Container Transitioned from NEW to ALLOCATED
2013-08-07 09:01:54,167 INFO org.apache.hadoop.yarn.server.resourcemanager.RMAuditLogger: USER=ubuntu	OPERATION=AM Allocated Container	TARGET=SchedulerApp	RESULT=SUCCESS	APPID=application_1375865942038_0002	CONTAINERID=container_1375865942038_0002_01_000003
2013-08-07 09:01:54,167 INFO org.apache.hadoop.yarn.server.resourcemanager.scheduler.common.fica.FiCaSchedulerNode: Assigned container container_1375865942038_0002_01_000003 of capacity <memory:1024, vCores:1> on host hadoop-200-6:52835, which currently has 2 containers, <memory:3072, vCores:2> used and <memory:5120, vCores:14> available
2013-08-07 09:01:54,168 INFO org.apache.hadoop.yarn.server.resourcemanager.scheduler.capacity.LeafQueue: assignedContainer application=application_1375865942038_0002 container=Container: [ContainerId: container_1375865942038_0002_01_000003, NodeId: hadoop-200-6:52835, NodeHttpAddress: hadoop-200-6:8042, Resource: <memory:1024, vCores:1>, Priority: 20, State: NEW, Token: null, Status: container_id {, app_attempt_id {, application_id {, id: 2, cluster_timestamp: 1375865942038, }, attemptId: 1, }, id: 3, }, state: C_NEW, ] containerId=container_1375865942038_0002_01_000003 queue=default: capacity=1.0, absoluteCapacity=1.0, usedResources=<memory:3072, vCores:2>usedCapacity=0.0625, absoluteUsedCapacity=0.0625, numApps=1, numContainers=2 usedCapacity=0.0625 absoluteUsedCapacity=0.0625 used=<memory:3072, vCores:2> cluster=<memory:49152, vCores:96>
2013-08-07 09:01:54,169 INFO org.apache.hadoop.yarn.server.resourcemanager.scheduler.capacity.ParentQueue: Re-sorting queues since queue: root.default stats: default: capacity=1.0, absoluteCapacity=1.0, usedResources=<memory:4096, vCores:3>usedCapacity=0.083333336, absoluteUsedCapacity=0.083333336, numApps=1, numContainers=3
2013-08-07 09:01:54,169 INFO org.apache.hadoop.yarn.server.resourcemanager.scheduler.capacity.ParentQueue: assignedContainer queue=root usedCapacity=0.083333336 absoluteUsedCapacity=0.083333336 used=<memory:4096, vCores:3> cluster=<memory:49152, vCores:96>
2013-08-07 09:01:54,424 INFO org.apache.hadoop.yarn.server.resourcemanager.rmcontainer.RMContainerImpl: container_1375865942038_0002_01_000002 Container Transitioned from ALLOCATED to ACQUIRED
2013-08-07 09:01:54,425 INFO org.apache.hadoop.yarn.server.resourcemanager.rmcontainer.RMContainerImpl: container_1375865942038_0002_01_000003 Container Transitioned from ALLOCATED to ACQUIRED
2013-08-07 09:01:54,922 INFO org.apache.hadoop.yarn.server.resourcemanager.rmcontainer.RMContainerImpl: container_1375865942038_0002_01_000002 Container Transitioned from ACQUIRED to RUNNING
2013-08-07 09:01:55,174 INFO org.apache.hadoop.yarn.server.resourcemanager.rmcontainer.RMContainerImpl: container_1375865942038_0002_01_000003 Container Transitioned from ACQUIRED to RUNNING
2013-08-07 09:01:55,454 INFO org.apache.hadoop.yarn.server.resourcemanager.scheduler.AppSchedulingInfo: checking for deactivate... 
2013-08-07 09:03:42,317 INFO org.apache.hadoop.yarn.server.resourcemanager.rmcontainer.RMContainerImpl: container_1375865942038_0002_01_000003 Container Transitioned from RUNNING to COMPLETED
2013-08-07 09:03:42,317 INFO org.apache.hadoop.yarn.server.resourcemanager.scheduler.common.fica.FiCaSchedulerApp: Completed container: container_1375865942038_0002_01_000003 in state: COMPLETED event:FINISHED
2013-08-07 09:03:42,318 INFO org.apache.hadoop.yarn.server.resourcemanager.RMAuditLogger: USER=ubuntu	OPERATION=AM Released Container	TARGET=SchedulerApp	RESULT=SUCCESS	APPID=application_1375865942038_0002	CONTAINERID=container_1375865942038_0002_01_000003
2013-08-07 09:03:42,318 INFO org.apache.hadoop.yarn.server.resourcemanager.scheduler.common.fica.FiCaSchedulerNode: Released container container_1375865942038_0002_01_000003 of capacity <memory:1024, vCores:1> on host hadoop-200-6:52835, which currently has 1 containers, <memory:2048, vCores:1> used and <memory:6144, vCores:15> available, release resources=true
2013-08-07 09:03:42,318 INFO org.apache.hadoop.yarn.server.resourcemanager.scheduler.capacity.LeafQueue: default used=<memory:3072, vCores:2> numContainers=2 user=ubuntu user-resources=<memory:3072, vCores:2>
2013-08-07 09:03:42,332 INFO org.apache.hadoop.yarn.server.resourcemanager.scheduler.capacity.LeafQueue: completedContainer container=Container: [ContainerId: container_1375865942038_0002_01_000003, NodeId: hadoop-200-6:52835, NodeHttpAddress: hadoop-200-6:8042, Resource: <memory:1024, vCores:1>, Priority: 20, State: NEW, Token: null, Status: container_id {, app_attempt_id {, application_id {, id: 2, cluster_timestamp: 1375865942038, }, attemptId: 1, }, id: 3, }, state: C_COMPLETE, diagnostics: "Container killed by the ApplicationMaster.\n\n", exit_status: 143, ] resource=<memory:1024, vCores:1> queue=default: capacity=1.0, absoluteCapacity=1.0, usedResources=<memory:3072, vCores:2>usedCapacity=0.0625, absoluteUsedCapacity=0.0625, numApps=1, numContainers=2 usedCapacity=0.0625 absoluteUsedCapacity=0.0625 used=<memory:3072, vCores:2> cluster=<memory:49152, vCores:96>
2013-08-07 09:03:42,332 INFO org.apache.hadoop.yarn.server.resourcemanager.scheduler.capacity.ParentQueue: completedContainer queue=root usedCapacity=0.0625 absoluteUsedCapacity=0.0625 used=<memory:3072, vCores:2> cluster=<memory:49152, vCores:96>
2013-08-07 09:03:42,332 INFO org.apache.hadoop.yarn.server.resourcemanager.scheduler.capacity.CapacityScheduler: Application appattempt_1375865942038_0002_000001 released container container_1375865942038_0002_01_000003 on node: host: hadoop-200-6:52835 #containers=1 available=6144 used=2048 with event: FINISHED
2013-08-07 09:03:43,736 INFO org.apache.hadoop.yarn.server.resourcemanager.rmcontainer.RMContainerImpl: container_1375865942038_0002_01_000002 Container Transitioned from RUNNING to COMPLETED
2013-08-07 09:03:43,736 INFO org.apache.hadoop.yarn.server.resourcemanager.scheduler.common.fica.FiCaSchedulerApp: Completed container: container_1375865942038_0002_01_000002 in state: COMPLETED event:FINISHED
2013-08-07 09:03:43,737 INFO org.apache.hadoop.yarn.server.resourcemanager.RMAuditLogger: USER=ubuntu	OPERATION=AM Released Container	TARGET=SchedulerApp	RESULT=SUCCESS	APPID=application_1375865942038_0002	CONTAINERID=container_1375865942038_0002_01_000002
2013-08-07 09:03:43,737 INFO org.apache.hadoop.yarn.server.resourcemanager.scheduler.common.fica.FiCaSchedulerNode: Released container container_1375865942038_0002_01_000002 of capacity <memory:1024, vCores:1> on host hadoop-200-5:55554, which currently has 0 containers, <memory:0, vCores:0> used and <memory:8192, vCores:16> available, release resources=true
2013-08-07 09:03:43,738 INFO org.apache.hadoop.yarn.server.resourcemanager.scheduler.capacity.LeafQueue: default used=<memory:2048, vCores:1> numContainers=1 user=ubuntu user-resources=<memory:2048, vCores:1>
2013-08-07 09:03:43,740 INFO org.apache.hadoop.yarn.server.resourcemanager.scheduler.capacity.LeafQueue: completedContainer container=Container: [ContainerId: container_1375865942038_0002_01_000002, NodeId: hadoop-200-5:55554, NodeHttpAddress: hadoop-200-5:8042, Resource: <memory:1024, vCores:1>, Priority: 20, State: NEW, Token: null, Status: container_id {, app_attempt_id {, application_id {, id: 2, cluster_timestamp: 1375865942038, }, attemptId: 1, }, id: 2, }, state: C_COMPLETE, diagnostics: "Container killed by the ApplicationMaster.\n\n", exit_status: 143, ] resource=<memory:1024, vCores:1> queue=default: capacity=1.0, absoluteCapacity=1.0, usedResources=<memory:2048, vCores:1>usedCapacity=0.041666668, absoluteUsedCapacity=0.041666668, numApps=1, numContainers=1 usedCapacity=0.041666668 absoluteUsedCapacity=0.041666668 used=<memory:2048, vCores:1> cluster=<memory:49152, vCores:96>
2013-08-07 09:03:43,740 INFO org.apache.hadoop.yarn.server.resourcemanager.scheduler.capacity.ParentQueue: completedContainer queue=root usedCapacity=0.041666668 absoluteUsedCapacity=0.041666668 used=<memory:2048, vCores:1> cluster=<memory:49152, vCores:96>
2013-08-07 09:03:43,741 INFO org.apache.hadoop.yarn.server.resourcemanager.scheduler.capacity.CapacityScheduler: Application appattempt_1375865942038_0002_000001 released container container_1375865942038_0002_01_000002 on node: host: hadoop-200-5:55554 #containers=0 available=8192 used=0 with event: FINISHED
2013-08-07 09:03:47,918 INFO org.apache.hadoop.yarn.server.resourcemanager.rmapp.attempt.RMAppAttemptImpl: appattempt_1375865942038_0002_000001 State change from RUNNING to FINISHING
2013-08-07 09:03:47,919 INFO org.apache.hadoop.yarn.server.resourcemanager.rmapp.RMAppImpl: application_1375865942038_0002 State change from RUNNING to FINISHING
2013-08-07 09:03:48,349 INFO org.apache.hadoop.yarn.server.resourcemanager.rmcontainer.RMContainerImpl: container_1375865942038_0002_01_000001 Container Transitioned from RUNNING to COMPLETED
2013-08-07 09:03:48,349 INFO org.apache.hadoop.yarn.server.resourcemanager.scheduler.common.fica.FiCaSchedulerApp: Completed container: container_1375865942038_0002_01_000001 in state: COMPLETED event:FINISHED
2013-08-07 09:03:48,349 INFO org.apache.hadoop.yarn.server.resourcemanager.RMAuditLogger: USER=ubuntu	OPERATION=AM Released Container	TARGET=SchedulerApp	RESULT=SUCCESS	APPID=application_1375865942038_0002	CONTAINERID=container_1375865942038_0002_01_000001
2013-08-07 09:03:48,350 INFO org.apache.hadoop.yarn.server.resourcemanager.rmapp.attempt.RMAppAttemptImpl: appattempt_1375865942038_0002_000001 State change from FINISHING to FINISHED
2013-08-07 09:03:48,350 INFO org.apache.hadoop.yarn.server.resourcemanager.scheduler.common.fica.FiCaSchedulerNode: Released container container_1375865942038_0002_01_000001 of capacity <memory:2048, vCores:1> on host hadoop-200-6:52835, which currently has 0 containers, <memory:0, vCores:0> used and <memory:8192, vCores:16> available, release resources=true
2013-08-07 09:03:48,350 INFO org.apache.hadoop.yarn.server.resourcemanager.scheduler.capacity.LeafQueue: default used=<memory:0, vCores:0> numContainers=0 user=ubuntu user-resources=<memory:0, vCores:0>
2013-08-07 09:03:48,350 INFO org.apache.hadoop.yarn.server.resourcemanager.rmapp.RMAppImpl: application_1375865942038_0002 State change from FINISHING to FINISHED
2013-08-07 09:03:48,351 INFO org.apache.hadoop.yarn.server.resourcemanager.RMAuditLogger: USER=ubuntu	OPERATION=Application Finished - Succeeded	TARGET=RMAppManager	RESULT=SUCCESS	APPID=application_1375865942038_0002
2013-08-07 09:03:48,351 INFO org.apache.hadoop.yarn.server.resourcemanager.recovery.RMStateStore: Removing info for app: application_1375865942038_0002
2013-08-07 09:03:48,352 INFO org.apache.hadoop.yarn.server.resourcemanager.RMAppManager$ApplicationSummary: appId=application_1375865942038_0002,name=TeraGen,user=ubuntu,queue=default,state=FINISHED,trackingUrl=hadoop-200-1.novalocal:8088/proxy/application_1375865942038_0002/jobhistory/job/job_1375865942038_0002,appMasterHost=hadoop-200-6,startTime=1375866091978,finishTime=1375866227919
2013-08-07 09:03:48,352 INFO org.apache.hadoop.yarn.server.resourcemanager.scheduler.capacity.LeafQueue: completedContainer container=Container: [ContainerId: container_1375865942038_0002_01_000001, NodeId: hadoop-200-6:52835, NodeHttpAddress: hadoop-200-6:8042, Resource: <memory:2048, vCores:1>, Priority: 0, State: NEW, Token: null, Status: container_id {, app_attempt_id {, application_id {, id: 2, cluster_timestamp: 1375865942038, }, attemptId: 1, }, id: 1, }, state: C_COMPLETE, diagnostics: "", exit_status: 0, ] resource=<memory:2048, vCores:1> queue=default: capacity=1.0, absoluteCapacity=1.0, usedResources=<memory:0, vCores:0>usedCapacity=0.0, absoluteUsedCapacity=0.0, numApps=1, numContainers=0 usedCapacity=0.0 absoluteUsedCapacity=0.0 used=<memory:0, vCores:0> cluster=<memory:49152, vCores:96>
2013-08-07 09:03:48,353 INFO org.apache.hadoop.yarn.server.resourcemanager.scheduler.capacity.ParentQueue: completedContainer queue=root usedCapacity=0.0 absoluteUsedCapacity=0.0 used=<memory:0, vCores:0> cluster=<memory:49152, vCores:96>
2013-08-07 09:03:48,354 INFO org.apache.hadoop.yarn.server.resourcemanager.scheduler.capacity.CapacityScheduler: Application appattempt_1375865942038_0002_000001 released container container_1375865942038_0002_01_000001 on node: host: hadoop-200-6:52835 #containers=0 available=8192 used=0 with event: FINISHED
2013-08-07 09:03:48,354 INFO org.apache.hadoop.yarn.server.resourcemanager.scheduler.capacity.CapacityScheduler: Application appattempt_1375865942038_0002_000001 is done. finalState=FINISHED
2013-08-07 09:03:48,354 INFO org.apache.hadoop.yarn.server.resourcemanager.scheduler.AppSchedulingInfo: Application application_1375865942038_0002 requests cleared
2013-08-07 09:03:48,354 INFO org.apache.hadoop.yarn.server.resourcemanager.scheduler.capacity.LeafQueue: Application removed - appId: application_1375865942038_0002 user: ubuntu queue: default #user-pending-applications: 0 #user-active-applications: 0 #queue-pending-applications: 0 #queue-active-applications: 0
2013-08-07 09:03:48,354 INFO org.apache.hadoop.yarn.server.resourcemanager.scheduler.capacity.ParentQueue: Application removed - appId: application_1375865942038_0002 user: ubuntu leaf-queue of parent: root #applications: 0
2013-08-07 09:03:48,358 INFO org.apache.hadoop.yarn.server.resourcemanager.amlauncher.AMLauncher: Cleaning master appattempt_1375865942038_0002_000001
2013-08-07 09:03:50,195 INFO org.apache.hadoop.yarn.server.resourcemanager.ClientRMService: Allocated new applicationId: 3
2013-08-07 09:03:52,174 INFO org.apache.hadoop.yarn.server.resourcemanager.ClientRMService: Storing Application with id application_1375865942038_0003
2013-08-07 09:03:52,175 INFO org.apache.hadoop.yarn.server.resourcemanager.recovery.RMStateStore: Storing info for app: application_1375865942038_0003
2013-08-07 09:03:52,175 INFO org.apache.hadoop.yarn.server.resourcemanager.ClientRMService: Application with id 3 submitted by user ubuntu
2013-08-07 09:03:52,175 INFO org.apache.hadoop.yarn.server.resourcemanager.RMAuditLogger: USER=ubuntu	IP=192.168.100.2	OPERATION=Submit Application Request	TARGET=ClientRMService	RESULT=SUCCESS	APPID=application_1375865942038_0003
2013-08-07 09:03:52,176 INFO org.apache.hadoop.yarn.server.resourcemanager.rmapp.RMAppImpl: application_1375865942038_0003 State change from NEW to SUBMITTED
2013-08-07 09:03:52,176 INFO org.apache.hadoop.yarn.server.resourcemanager.ApplicationMasterService: Registering appattempt_1375865942038_0003_000001
2013-08-07 09:03:52,177 INFO org.apache.hadoop.yarn.server.resourcemanager.rmapp.attempt.RMAppAttemptImpl: appattempt_1375865942038_0003_000001 State change from NEW to SUBMITTED
2013-08-07 09:03:52,177 INFO org.apache.hadoop.yarn.server.resourcemanager.scheduler.capacity.LeafQueue: Application application_1375865942038_0003 from user: ubuntu activated in queue: default
2013-08-07 09:03:52,177 INFO org.apache.hadoop.yarn.server.resourcemanager.scheduler.capacity.LeafQueue: Application added - appId: application_1375865942038_0003 user: org.apache.hadoop.yarn.server.resourcemanager.scheduler.capacity.LeafQueue$User@704adcff, leaf-queue: default #user-pending-applications: 0 #user-active-applications: 1 #queue-pending-applications: 0 #queue-active-applications: 1
2013-08-07 09:03:52,177 INFO org.apache.hadoop.yarn.server.resourcemanager.scheduler.capacity.ParentQueue: Application added - appId: application_1375865942038_0003 user: ubuntu leaf-queue of parent: root #applications: 1
2013-08-07 09:03:52,178 INFO org.apache.hadoop.yarn.server.resourcemanager.scheduler.capacity.CapacityScheduler: Application Submission: appattempt_1375865942038_0003_000001, user: ubuntu queue: default: capacity=1.0, absoluteCapacity=1.0, usedResources=<memory:0, vCores:0>usedCapacity=0.0, absoluteUsedCapacity=0.0, numApps=1, numContainers=0, currently active: 1
2013-08-07 09:03:52,178 INFO org.apache.hadoop.yarn.server.resourcemanager.rmapp.attempt.RMAppAttemptImpl: appattempt_1375865942038_0003_000001 State change from SUBMITTED to SCHEDULED
2013-08-07 09:03:52,178 INFO org.apache.hadoop.yarn.server.resourcemanager.rmapp.RMAppImpl: application_1375865942038_0003 State change from SUBMITTED to ACCEPTED
2013-08-07 09:03:52,366 INFO org.apache.hadoop.yarn.server.resourcemanager.rmcontainer.RMContainerImpl: container_1375865942038_0003_01_000001 Container Transitioned from NEW to ALLOCATED
2013-08-07 09:03:52,366 INFO org.apache.hadoop.yarn.server.resourcemanager.RMAuditLogger: USER=ubuntu	OPERATION=AM Allocated Container	TARGET=SchedulerApp	RESULT=SUCCESS	APPID=application_1375865942038_0003	CONTAINERID=container_1375865942038_0003_01_000001
2013-08-07 09:03:52,367 INFO org.apache.hadoop.yarn.server.resourcemanager.scheduler.common.fica.FiCaSchedulerNode: Assigned container container_1375865942038_0003_01_000001 of capacity <memory:2048, vCores:1> on host hadoop-200-6:52835, which currently has 1 containers, <memory:2048, vCores:1> used and <memory:6144, vCores:15> available
2013-08-07 09:03:52,368 INFO org.apache.hadoop.yarn.server.resourcemanager.scheduler.capacity.LeafQueue: assignedContainer application=application_1375865942038_0003 container=Container: [ContainerId: container_1375865942038_0003_01_000001, NodeId: hadoop-200-6:52835, NodeHttpAddress: hadoop-200-6:8042, Resource: <memory:2048, vCores:1>, Priority: 0, State: NEW, Token: null, Status: container_id {, app_attempt_id {, application_id {, id: 3, cluster_timestamp: 1375865942038, }, attemptId: 1, }, id: 1, }, state: C_NEW, ] containerId=container_1375865942038_0003_01_000001 queue=default: capacity=1.0, absoluteCapacity=1.0, usedResources=<memory:0, vCores:0>usedCapacity=0.0, absoluteUsedCapacity=0.0, numApps=1, numContainers=0 usedCapacity=0.0 absoluteUsedCapacity=0.0 used=<memory:0, vCores:0> cluster=<memory:49152, vCores:96>
2013-08-07 09:03:52,368 INFO org.apache.hadoop.yarn.server.resourcemanager.scheduler.capacity.ParentQueue: Re-sorting queues since queue: root.default stats: default: capacity=1.0, absoluteCapacity=1.0, usedResources=<memory:2048, vCores:1>usedCapacity=0.041666668, absoluteUsedCapacity=0.041666668, numApps=1, numContainers=1
2013-08-07 09:03:52,369 INFO org.apache.hadoop.yarn.server.resourcemanager.scheduler.capacity.ParentQueue: assignedContainer queue=root usedCapacity=0.041666668 absoluteUsedCapacity=0.041666668 used=<memory:2048, vCores:1> cluster=<memory:49152, vCores:96>
2013-08-07 09:03:52,371 INFO org.apache.hadoop.yarn.server.resourcemanager.rmcontainer.RMContainerImpl: container_1375865942038_0003_01_000001 Container Transitioned from ALLOCATED to ACQUIRED
2013-08-07 09:03:52,373 INFO org.apache.hadoop.yarn.server.resourcemanager.rmapp.attempt.RMAppAttemptImpl: Storing attempt: AppId: application_1375865942038_0003 AttemptId: appattempt_1375865942038_0003_000001 MasterContainer: Container: [ContainerId: container_1375865942038_0003_01_000001, NodeId: hadoop-200-6:52835, NodeHttpAddress: hadoop-200-6:8042, Resource: <memory:2048, vCores:1>, Priority: 0, State: NEW, Token: null, Status: container_id {, app_attempt_id {, application_id {, id: 3, cluster_timestamp: 1375865942038, }, attemptId: 1, }, id: 1, }, state: C_NEW, ]
2013-08-07 09:03:52,373 INFO org.apache.hadoop.yarn.server.resourcemanager.rmapp.attempt.RMAppAttemptImpl: appattempt_1375865942038_0003_000001 State change from SCHEDULED to ALLOCATED_SAVING
2013-08-07 09:03:52,373 INFO org.apache.hadoop.yarn.server.resourcemanager.recovery.RMStateStore: Storing info for attempt: appattempt_1375865942038_0003_000001
2013-08-07 09:03:52,374 INFO org.apache.hadoop.yarn.server.resourcemanager.rmapp.attempt.RMAppAttemptImpl: appattempt_1375865942038_0003_000001 State change from ALLOCATED_SAVING to ALLOCATED
2013-08-07 09:03:52,375 INFO org.apache.hadoop.yarn.server.resourcemanager.amlauncher.AMLauncher: Launching masterappattempt_1375865942038_0003_000001
2013-08-07 09:03:52,378 INFO org.apache.hadoop.yarn.server.resourcemanager.amlauncher.AMLauncher: Setting up container Container: [ContainerId: container_1375865942038_0003_01_000001, NodeId: hadoop-200-6:52835, NodeHttpAddress: hadoop-200-6:8042, Resource: <memory:2048, vCores:1>, Priority: 0, State: NEW, Token: null, Status: container_id {, app_attempt_id {, application_id {, id: 3, cluster_timestamp: 1375865942038, }, attemptId: 1, }, id: 1, }, state: C_NEW, ] for AM appattempt_1375865942038_0003_000001
2013-08-07 09:03:52,378 INFO org.apache.hadoop.yarn.server.resourcemanager.amlauncher.AMLauncher: Command to launch container container_1375865942038_0003_01_000001 : $JAVA_HOME/bin/java -Dlog4j.configuration=container-log4j.properties -Dyarn.app.mapreduce.container.log.dir=<LOG_DIR> -Dyarn.app.mapreduce.container.log.filesize=0 -Dhadoop.root.logger=INFO,CLA  -Xmx1024m org.apache.hadoop.mapreduce.v2.app.MRAppMaster 1><LOG_DIR>/stdout 2><LOG_DIR>/stderr 
2013-08-07 09:03:52,392 INFO org.apache.hadoop.yarn.server.resourcemanager.amlauncher.AMLauncher: Done launching container Container: [ContainerId: container_1375865942038_0003_01_000001, NodeId: hadoop-200-6:52835, NodeHttpAddress: hadoop-200-6:8042, Resource: <memory:2048, vCores:1>, Priority: 0, State: NEW, Token: null, Status: container_id {, app_attempt_id {, application_id {, id: 3, cluster_timestamp: 1375865942038, }, attemptId: 1, }, id: 1, }, state: C_NEW, ] for AM appattempt_1375865942038_0003_000001
2013-08-07 09:03:52,393 INFO org.apache.hadoop.yarn.server.resourcemanager.rmapp.attempt.RMAppAttemptImpl: appattempt_1375865942038_0003_000001 State change from ALLOCATED to LAUNCHED
2013-08-07 09:03:53,373 INFO org.apache.hadoop.yarn.server.resourcemanager.rmcontainer.RMContainerImpl: container_1375865942038_0003_01_000001 Container Transitioned from ACQUIRED to RUNNING
2013-08-07 09:03:58,857 INFO org.apache.hadoop.yarn.server.resourcemanager.ApplicationMasterService: AM registration appattempt_1375865942038_0003_000001
2013-08-07 09:03:58,858 INFO org.apache.hadoop.yarn.server.resourcemanager.RMAuditLogger: USER=ubuntu	IP=192.168.100.10	OPERATION=Register App Master	TARGET=ApplicationMasterService	RESULT=SUCCESS	APPID=application_1375865942038_0003	APPATTEMPTID=appattempt_1375865942038_0003_000001
2013-08-07 09:03:58,859 INFO org.apache.hadoop.yarn.server.resourcemanager.rmapp.attempt.RMAppAttemptImpl: appattempt_1375865942038_0003_000001 State change from LAUNCHED to RUNNING
2013-08-07 09:03:58,859 INFO org.apache.hadoop.yarn.server.resourcemanager.rmapp.RMAppImpl: application_1375865942038_0003 State change from ACCEPTED to RUNNING
2013-08-07 09:04:00,405 INFO org.apache.hadoop.yarn.server.resourcemanager.rmcontainer.RMContainerImpl: container_1375865942038_0003_01_000002 Container Transitioned from NEW to ALLOCATED
2013-08-07 09:04:00,406 INFO org.apache.hadoop.yarn.server.resourcemanager.RMAuditLogger: USER=ubuntu	OPERATION=AM Allocated Container	TARGET=SchedulerApp	RESULT=SUCCESS	APPID=application_1375865942038_0003	CONTAINERID=container_1375865942038_0003_01_000002
2013-08-07 09:04:00,406 INFO org.apache.hadoop.yarn.server.resourcemanager.scheduler.common.fica.FiCaSchedulerNode: Assigned container container_1375865942038_0003_01_000002 of capacity <memory:1024, vCores:1> on host hadoop-200-6:52835, which currently has 2 containers, <memory:3072, vCores:2> used and <memory:5120, vCores:14> available
2013-08-07 09:04:00,408 INFO org.apache.hadoop.yarn.server.resourcemanager.scheduler.capacity.LeafQueue: assignedContainer application=application_1375865942038_0003 container=Container: [ContainerId: container_1375865942038_0003_01_000002, NodeId: hadoop-200-6:52835, NodeHttpAddress: hadoop-200-6:8042, Resource: <memory:1024, vCores:1>, Priority: 20, State: NEW, Token: null, Status: container_id {, app_attempt_id {, application_id {, id: 3, cluster_timestamp: 1375865942038, }, attemptId: 1, }, id: 2, }, state: C_NEW, ] containerId=container_1375865942038_0003_01_000002 queue=default: capacity=1.0, absoluteCapacity=1.0, usedResources=<memory:2048, vCores:1>usedCapacity=0.041666668, absoluteUsedCapacity=0.041666668, numApps=1, numContainers=1 usedCapacity=0.041666668 absoluteUsedCapacity=0.041666668 used=<memory:2048, vCores:1> cluster=<memory:49152, vCores:96>
2013-08-07 09:04:00,408 INFO org.apache.hadoop.yarn.server.resourcemanager.scheduler.capacity.ParentQueue: Re-sorting queues since queue: root.default stats: default: capacity=1.0, absoluteCapacity=1.0, usedResources=<memory:3072, vCores:2>usedCapacity=0.0625, absoluteUsedCapacity=0.0625, numApps=1, numContainers=2
2013-08-07 09:04:00,409 INFO org.apache.hadoop.yarn.server.resourcemanager.scheduler.capacity.ParentQueue: assignedContainer queue=root usedCapacity=0.0625 absoluteUsedCapacity=0.0625 used=<memory:3072, vCores:2> cluster=<memory:49152, vCores:96>
2013-08-07 09:04:00,678 INFO org.apache.hadoop.yarn.server.resourcemanager.rmcontainer.RMContainerImpl: container_1375865942038_0003_01_000003 Container Transitioned from NEW to ALLOCATED
2013-08-07 09:04:00,678 INFO org.apache.hadoop.yarn.server.resourcemanager.RMAuditLogger: USER=ubuntu	OPERATION=AM Allocated Container	TARGET=SchedulerApp	RESULT=SUCCESS	APPID=application_1375865942038_0003	CONTAINERID=container_1375865942038_0003_01_000003
2013-08-07 09:04:00,679 INFO org.apache.hadoop.yarn.server.resourcemanager.scheduler.common.fica.FiCaSchedulerNode: Assigned container container_1375865942038_0003_01_000003 of capacity <memory:1024, vCores:1> on host hadoop-200-4:57320, which currently has 1 containers, <memory:1024, vCores:1> used and <memory:7168, vCores:15> available
2013-08-07 09:04:00,680 INFO org.apache.hadoop.yarn.server.resourcemanager.scheduler.capacity.LeafQueue: assignedContainer application=application_1375865942038_0003 container=Container: [ContainerId: container_1375865942038_0003_01_000003, NodeId: hadoop-200-4:57320, NodeHttpAddress: hadoop-200-4:8042, Resource: <memory:1024, vCores:1>, Priority: 20, State: NEW, Token: null, Status: container_id {, app_attempt_id {, application_id {, id: 3, cluster_timestamp: 1375865942038, }, attemptId: 1, }, id: 3, }, state: C_NEW, ] containerId=container_1375865942038_0003_01_000003 queue=default: capacity=1.0, absoluteCapacity=1.0, usedResources=<memory:3072, vCores:2>usedCapacity=0.0625, absoluteUsedCapacity=0.0625, numApps=1, numContainers=2 usedCapacity=0.0625 absoluteUsedCapacity=0.0625 used=<memory:3072, vCores:2> cluster=<memory:49152, vCores:96>
2013-08-07 09:04:00,680 INFO org.apache.hadoop.yarn.server.resourcemanager.scheduler.capacity.ParentQueue: Re-sorting queues since queue: root.default stats: default: capacity=1.0, absoluteCapacity=1.0, usedResources=<memory:4096, vCores:3>usedCapacity=0.083333336, absoluteUsedCapacity=0.083333336, numApps=1, numContainers=3
2013-08-07 09:04:00,681 INFO org.apache.hadoop.yarn.server.resourcemanager.scheduler.capacity.ParentQueue: assignedContainer queue=root usedCapacity=0.083333336 absoluteUsedCapacity=0.083333336 used=<memory:4096, vCores:3> cluster=<memory:49152, vCores:96>
2013-08-07 09:04:00,944 INFO org.apache.hadoop.yarn.server.resourcemanager.rmcontainer.RMContainerImpl: container_1375865942038_0003_01_000002 Container Transitioned from ALLOCATED to ACQUIRED
2013-08-07 09:04:00,946 INFO org.apache.hadoop.yarn.server.resourcemanager.rmcontainer.RMContainerImpl: container_1375865942038_0003_01_000003 Container Transitioned from ALLOCATED to ACQUIRED
2013-08-07 09:04:01,412 INFO org.apache.hadoop.yarn.server.resourcemanager.rmcontainer.RMContainerImpl: container_1375865942038_0003_01_000002 Container Transitioned from ACQUIRED to RUNNING
2013-08-07 09:04:01,973 INFO org.apache.hadoop.yarn.server.resourcemanager.scheduler.AppSchedulingInfo: checking for deactivate... 
2013-08-07 09:04:02,760 INFO org.apache.hadoop.yarn.server.resourcemanager.rmcontainer.RMContainerImpl: container_1375865942038_0003_01_000003 Container Transitioned from ACQUIRED to RUNNING
2013-08-07 09:05:45,546 INFO org.apache.hadoop.yarn.server.resourcemanager.rmcontainer.RMContainerImpl: container_1375865942038_0003_01_000003 Container Transitioned from RUNNING to COMPLETED
2013-08-07 09:05:45,547 INFO org.apache.hadoop.yarn.server.resourcemanager.scheduler.common.fica.FiCaSchedulerApp: Completed container: container_1375865942038_0003_01_000003 in state: COMPLETED event:FINISHED
2013-08-07 09:05:45,547 INFO org.apache.hadoop.yarn.server.resourcemanager.RMAuditLogger: USER=ubuntu	OPERATION=AM Released Container	TARGET=SchedulerApp	RESULT=SUCCESS	APPID=application_1375865942038_0003	CONTAINERID=container_1375865942038_0003_01_000003
2013-08-07 09:05:45,547 INFO org.apache.hadoop.yarn.server.resourcemanager.scheduler.common.fica.FiCaSchedulerNode: Released container container_1375865942038_0003_01_000003 of capacity <memory:1024, vCores:1> on host hadoop-200-4:57320, which currently has 0 containers, <memory:0, vCores:0> used and <memory:8192, vCores:16> available, release resources=true
2013-08-07 09:05:45,547 INFO org.apache.hadoop.yarn.server.resourcemanager.scheduler.capacity.LeafQueue: default used=<memory:3072, vCores:2> numContainers=2 user=ubuntu user-resources=<memory:3072, vCores:2>
2013-08-07 09:05:45,549 INFO org.apache.hadoop.yarn.server.resourcemanager.scheduler.capacity.LeafQueue: completedContainer container=Container: [ContainerId: container_1375865942038_0003_01_000003, NodeId: hadoop-200-4:57320, NodeHttpAddress: hadoop-200-4:8042, Resource: <memory:1024, vCores:1>, Priority: 20, State: NEW, Token: null, Status: container_id {, app_attempt_id {, application_id {, id: 3, cluster_timestamp: 1375865942038, }, attemptId: 1, }, id: 3, }, state: C_COMPLETE, diagnostics: "Container killed by the ApplicationMaster.\n\n", exit_status: 143, ] resource=<memory:1024, vCores:1> queue=default: capacity=1.0, absoluteCapacity=1.0, usedResources=<memory:3072, vCores:2>usedCapacity=0.0625, absoluteUsedCapacity=0.0625, numApps=1, numContainers=2 usedCapacity=0.0625 absoluteUsedCapacity=0.0625 used=<memory:3072, vCores:2> cluster=<memory:49152, vCores:96>
2013-08-07 09:05:45,549 INFO org.apache.hadoop.yarn.server.resourcemanager.scheduler.capacity.ParentQueue: completedContainer queue=root usedCapacity=0.0625 absoluteUsedCapacity=0.0625 used=<memory:3072, vCores:2> cluster=<memory:49152, vCores:96>
2013-08-07 09:05:45,550 INFO org.apache.hadoop.yarn.server.resourcemanager.scheduler.capacity.CapacityScheduler: Application appattempt_1375865942038_0003_000001 released container container_1375865942038_0003_01_000003 on node: host: hadoop-200-4:57320 #containers=0 available=8192 used=0 with event: FINISHED
2013-08-07 09:05:51,161 INFO org.apache.hadoop.yarn.server.resourcemanager.rmcontainer.RMContainerImpl: container_1375865942038_0003_01_000002 Container Transitioned from RUNNING to COMPLETED
2013-08-07 09:05:51,162 INFO org.apache.hadoop.yarn.server.resourcemanager.scheduler.common.fica.FiCaSchedulerApp: Completed container: container_1375865942038_0003_01_000002 in state: COMPLETED event:FINISHED
2013-08-07 09:05:51,162 INFO org.apache.hadoop.yarn.server.resourcemanager.RMAuditLogger: USER=ubuntu	OPERATION=AM Released Container	TARGET=SchedulerApp	RESULT=SUCCESS	APPID=application_1375865942038_0003	CONTAINERID=container_1375865942038_0003_01_000002
2013-08-07 09:05:51,162 INFO org.apache.hadoop.yarn.server.resourcemanager.scheduler.common.fica.FiCaSchedulerNode: Released container container_1375865942038_0003_01_000002 of capacity <memory:1024, vCores:1> on host hadoop-200-6:52835, which currently has 1 containers, <memory:2048, vCores:1> used and <memory:6144, vCores:15> available, release resources=true
2013-08-07 09:05:51,162 INFO org.apache.hadoop.yarn.server.resourcemanager.scheduler.capacity.LeafQueue: default used=<memory:2048, vCores:1> numContainers=1 user=ubuntu user-resources=<memory:2048, vCores:1>
2013-08-07 09:05:51,164 INFO org.apache.hadoop.yarn.server.resourcemanager.scheduler.capacity.LeafQueue: completedContainer container=Container: [ContainerId: container_1375865942038_0003_01_000002, NodeId: hadoop-200-6:52835, NodeHttpAddress: hadoop-200-6:8042, Resource: <memory:1024, vCores:1>, Priority: 20, State: NEW, Token: null, Status: container_id {, app_attempt_id {, application_id {, id: 3, cluster_timestamp: 1375865942038, }, attemptId: 1, }, id: 2, }, state: C_COMPLETE, diagnostics: "Container killed by the ApplicationMaster.\n\n", exit_status: 143, ] resource=<memory:1024, vCores:1> queue=default: capacity=1.0, absoluteCapacity=1.0, usedResources=<memory:2048, vCores:1>usedCapacity=0.041666668, absoluteUsedCapacity=0.041666668, numApps=1, numContainers=1 usedCapacity=0.041666668 absoluteUsedCapacity=0.041666668 used=<memory:2048, vCores:1> cluster=<memory:49152, vCores:96>
2013-08-07 09:05:51,164 INFO org.apache.hadoop.yarn.server.resourcemanager.scheduler.capacity.ParentQueue: completedContainer queue=root usedCapacity=0.041666668 absoluteUsedCapacity=0.041666668 used=<memory:2048, vCores:1> cluster=<memory:49152, vCores:96>
2013-08-07 09:05:51,165 INFO org.apache.hadoop.yarn.server.resourcemanager.scheduler.capacity.CapacityScheduler: Application appattempt_1375865942038_0003_000001 released container container_1375865942038_0003_01_000002 on node: host: hadoop-200-6:52835 #containers=1 available=6144 used=2048 with event: FINISHED
2013-08-07 09:05:55,310 INFO org.apache.hadoop.yarn.server.resourcemanager.rmapp.attempt.RMAppAttemptImpl: appattempt_1375865942038_0003_000001 State change from RUNNING to FINISHING
2013-08-07 09:05:55,311 INFO org.apache.hadoop.yarn.server.resourcemanager.rmapp.RMAppImpl: application_1375865942038_0003 State change from RUNNING to FINISHING
2013-08-07 09:05:56,181 INFO org.apache.hadoop.yarn.server.resourcemanager.rmcontainer.RMContainerImpl: container_1375865942038_0003_01_000001 Container Transitioned from RUNNING to COMPLETED
2013-08-07 09:05:56,182 INFO org.apache.hadoop.yarn.server.resourcemanager.rmapp.attempt.RMAppAttemptImpl: appattempt_1375865942038_0003_000001 State change from FINISHING to FINISHED
2013-08-07 09:05:56,182 INFO org.apache.hadoop.yarn.server.resourcemanager.scheduler.common.fica.FiCaSchedulerApp: Completed container: container_1375865942038_0003_01_000001 in state: COMPLETED event:FINISHED
2013-08-07 09:05:56,182 INFO org.apache.hadoop.yarn.server.resourcemanager.RMAuditLogger: USER=ubuntu	OPERATION=AM Released Container	TARGET=SchedulerApp	RESULT=SUCCESS	APPID=application_1375865942038_0003	CONTAINERID=container_1375865942038_0003_01_000001
2013-08-07 09:05:56,182 INFO org.apache.hadoop.yarn.server.resourcemanager.scheduler.common.fica.FiCaSchedulerNode: Released container container_1375865942038_0003_01_000001 of capacity <memory:2048, vCores:1> on host hadoop-200-6:52835, which currently has 0 containers, <memory:0, vCores:0> used and <memory:8192, vCores:16> available, release resources=true
2013-08-07 09:05:56,182 INFO org.apache.hadoop.yarn.server.resourcemanager.rmapp.RMAppImpl: application_1375865942038_0003 State change from FINISHING to FINISHED
2013-08-07 09:05:56,182 INFO org.apache.hadoop.yarn.server.resourcemanager.scheduler.capacity.LeafQueue: default used=<memory:0, vCores:0> numContainers=0 user=ubuntu user-resources=<memory:0, vCores:0>
2013-08-07 09:05:56,183 INFO org.apache.hadoop.yarn.server.resourcemanager.RMAuditLogger: USER=ubuntu	OPERATION=Application Finished - Succeeded	TARGET=RMAppManager	RESULT=SUCCESS	APPID=application_1375865942038_0003
2013-08-07 09:05:56,183 INFO org.apache.hadoop.yarn.server.resourcemanager.recovery.RMStateStore: Removing info for app: application_1375865942038_0003
2013-08-07 09:05:56,183 INFO org.apache.hadoop.yarn.server.resourcemanager.RMAppManager$ApplicationSummary: appId=application_1375865942038_0003,name=TeraGen,user=ubuntu,queue=default,state=FINISHED,trackingUrl=hadoop-200-1.novalocal:8088/proxy/application_1375865942038_0003/jobhistory/job/job_1375865942038_0003,appMasterHost=hadoop-200-6,startTime=1375866232174,finishTime=1375866355311
2013-08-07 09:05:56,186 INFO org.apache.hadoop.yarn.server.resourcemanager.scheduler.capacity.LeafQueue: completedContainer container=Container: [ContainerId: container_1375865942038_0003_01_000001, NodeId: hadoop-200-6:52835, NodeHttpAddress: hadoop-200-6:8042, Resource: <memory:2048, vCores:1>, Priority: 0, State: NEW, Token: null, Status: container_id {, app_attempt_id {, application_id {, id: 3, cluster_timestamp: 1375865942038, }, attemptId: 1, }, id: 1, }, state: C_COMPLETE, diagnostics: "", exit_status: 0, ] resource=<memory:2048, vCores:1> queue=default: capacity=1.0, absoluteCapacity=1.0, usedResources=<memory:0, vCores:0>usedCapacity=0.0, absoluteUsedCapacity=0.0, numApps=1, numContainers=0 usedCapacity=0.0 absoluteUsedCapacity=0.0 used=<memory:0, vCores:0> cluster=<memory:49152, vCores:96>
2013-08-07 09:05:56,186 INFO org.apache.hadoop.yarn.server.resourcemanager.scheduler.capacity.ParentQueue: completedContainer queue=root usedCapacity=0.0 absoluteUsedCapacity=0.0 used=<memory:0, vCores:0> cluster=<memory:49152, vCores:96>
2013-08-07 09:05:56,186 INFO org.apache.hadoop.yarn.server.resourcemanager.scheduler.capacity.CapacityScheduler: Application appattempt_1375865942038_0003_000001 released container container_1375865942038_0003_01_000001 on node: host: hadoop-200-6:52835 #containers=0 available=8192 used=0 with event: FINISHED
2013-08-07 09:05:56,187 INFO org.apache.hadoop.yarn.server.resourcemanager.scheduler.capacity.CapacityScheduler: Application appattempt_1375865942038_0003_000001 is done. finalState=FINISHED
2013-08-07 09:05:56,187 INFO org.apache.hadoop.yarn.server.resourcemanager.scheduler.AppSchedulingInfo: Application application_1375865942038_0003 requests cleared
2013-08-07 09:05:56,187 INFO org.apache.hadoop.yarn.server.resourcemanager.scheduler.capacity.LeafQueue: Application removed - appId: application_1375865942038_0003 user: ubuntu queue: default #user-pending-applications: 0 #user-active-applications: 0 #queue-pending-applications: 0 #queue-active-applications: 0
2013-08-07 09:05:56,187 INFO org.apache.hadoop.yarn.server.resourcemanager.scheduler.capacity.ParentQueue: Application removed - appId: application_1375865942038_0003 user: ubuntu leaf-queue of parent: root #applications: 0
2013-08-07 09:05:56,188 INFO org.apache.hadoop.yarn.server.resourcemanager.amlauncher.AMLauncher: Cleaning master appattempt_1375865942038_0003_000001
2013-08-07 09:05:56,344 INFO org.apache.hadoop.yarn.server.resourcemanager.ClientRMService: Allocated new applicationId: 4
2013-08-07 09:05:58,273 INFO org.apache.hadoop.yarn.server.resourcemanager.ClientRMService: Storing Application with id application_1375865942038_0004
2013-08-07 09:05:58,274 INFO org.apache.hadoop.yarn.server.resourcemanager.recovery.RMStateStore: Storing info for app: application_1375865942038_0004
2013-08-07 09:05:58,274 INFO org.apache.hadoop.yarn.server.resourcemanager.ClientRMService: Application with id 4 submitted by user ubuntu
2013-08-07 09:05:58,274 INFO org.apache.hadoop.yarn.server.resourcemanager.RMAuditLogger: USER=ubuntu	IP=192.168.100.2	OPERATION=Submit Application Request	TARGET=ClientRMService	RESULT=SUCCESS	APPID=application_1375865942038_0004
2013-08-07 09:05:58,275 INFO org.apache.hadoop.yarn.server.resourcemanager.rmapp.RMAppImpl: application_1375865942038_0004 State change from NEW to SUBMITTED
2013-08-07 09:05:58,276 INFO org.apache.hadoop.yarn.server.resourcemanager.ApplicationMasterService: Registering appattempt_1375865942038_0004_000001
2013-08-07 09:05:58,276 INFO org.apache.hadoop.yarn.server.resourcemanager.rmapp.attempt.RMAppAttemptImpl: appattempt_1375865942038_0004_000001 State change from NEW to SUBMITTED
2013-08-07 09:05:58,277 INFO org.apache.hadoop.yarn.server.resourcemanager.scheduler.capacity.LeafQueue: Application application_1375865942038_0004 from user: ubuntu activated in queue: default
2013-08-07 09:05:58,277 INFO org.apache.hadoop.yarn.server.resourcemanager.scheduler.capacity.LeafQueue: Application added - appId: application_1375865942038_0004 user: org.apache.hadoop.yarn.server.resourcemanager.scheduler.capacity.LeafQueue$User@3df9b7f7, leaf-queue: default #user-pending-applications: 0 #user-active-applications: 1 #queue-pending-applications: 0 #queue-active-applications: 1
2013-08-07 09:05:58,277 INFO org.apache.hadoop.yarn.server.resourcemanager.scheduler.capacity.ParentQueue: Application added - appId: application_1375865942038_0004 user: ubuntu leaf-queue of parent: root #applications: 1
2013-08-07 09:05:58,277 INFO org.apache.hadoop.yarn.server.resourcemanager.scheduler.capacity.CapacityScheduler: Application Submission: appattempt_1375865942038_0004_000001, user: ubuntu queue: default: capacity=1.0, absoluteCapacity=1.0, usedResources=<memory:0, vCores:0>usedCapacity=0.0, absoluteUsedCapacity=0.0, numApps=1, numContainers=0, currently active: 1
2013-08-07 09:05:58,278 INFO org.apache.hadoop.yarn.server.resourcemanager.rmapp.attempt.RMAppAttemptImpl: appattempt_1375865942038_0004_000001 State change from SUBMITTED to SCHEDULED
2013-08-07 09:05:58,278 INFO org.apache.hadoop.yarn.server.resourcemanager.rmapp.RMAppImpl: application_1375865942038_0004 State change from SUBMITTED to ACCEPTED
2013-08-07 09:05:58,600 INFO org.apache.hadoop.yarn.server.resourcemanager.rmcontainer.RMContainerImpl: container_1375865942038_0004_01_000001 Container Transitioned from NEW to ALLOCATED
2013-08-07 09:05:58,601 INFO org.apache.hadoop.yarn.server.resourcemanager.RMAuditLogger: USER=ubuntu	OPERATION=AM Allocated Container	TARGET=SchedulerApp	RESULT=SUCCESS	APPID=application_1375865942038_0004	CONTAINERID=container_1375865942038_0004_01_000001
2013-08-07 09:05:58,601 INFO org.apache.hadoop.yarn.server.resourcemanager.scheduler.common.fica.FiCaSchedulerNode: Assigned container container_1375865942038_0004_01_000001 of capacity <memory:2048, vCores:1> on host hadoop-200-4:57320, which currently has 1 containers, <memory:2048, vCores:1> used and <memory:6144, vCores:15> available
2013-08-07 09:05:58,602 INFO org.apache.hadoop.yarn.server.resourcemanager.scheduler.capacity.LeafQueue: assignedContainer application=application_1375865942038_0004 container=Container: [ContainerId: container_1375865942038_0004_01_000001, NodeId: hadoop-200-4:57320, NodeHttpAddress: hadoop-200-4:8042, Resource: <memory:2048, vCores:1>, Priority: 0, State: NEW, Token: null, Status: container_id {, app_attempt_id {, application_id {, id: 4, cluster_timestamp: 1375865942038, }, attemptId: 1, }, id: 1, }, state: C_NEW, ] containerId=container_1375865942038_0004_01_000001 queue=default: capacity=1.0, absoluteCapacity=1.0, usedResources=<memory:0, vCores:0>usedCapacity=0.0, absoluteUsedCapacity=0.0, numApps=1, numContainers=0 usedCapacity=0.0 absoluteUsedCapacity=0.0 used=<memory:0, vCores:0> cluster=<memory:49152, vCores:96>
2013-08-07 09:05:58,606 INFO org.apache.hadoop.yarn.server.resourcemanager.scheduler.capacity.ParentQueue: Re-sorting queues since queue: root.default stats: default: capacity=1.0, absoluteCapacity=1.0, usedResources=<memory:2048, vCores:1>usedCapacity=0.041666668, absoluteUsedCapacity=0.041666668, numApps=1, numContainers=1
2013-08-07 09:05:58,606 INFO org.apache.hadoop.yarn.server.resourcemanager.scheduler.capacity.ParentQueue: assignedContainer queue=root usedCapacity=0.041666668 absoluteUsedCapacity=0.041666668 used=<memory:2048, vCores:1> cluster=<memory:49152, vCores:96>
2013-08-07 09:05:58,607 INFO org.apache.hadoop.yarn.server.resourcemanager.rmcontainer.RMContainerImpl: container_1375865942038_0004_01_000001 Container Transitioned from ALLOCATED to ACQUIRED
2013-08-07 09:05:58,609 INFO org.apache.hadoop.yarn.server.resourcemanager.rmapp.attempt.RMAppAttemptImpl: Storing attempt: AppId: application_1375865942038_0004 AttemptId: appattempt_1375865942038_0004_000001 MasterContainer: Container: [ContainerId: container_1375865942038_0004_01_000001, NodeId: hadoop-200-4:57320, NodeHttpAddress: hadoop-200-4:8042, Resource: <memory:2048, vCores:1>, Priority: 0, State: NEW, Token: null, Status: container_id {, app_attempt_id {, application_id {, id: 4, cluster_timestamp: 1375865942038, }, attemptId: 1, }, id: 1, }, state: C_NEW, ]
2013-08-07 09:05:58,609 INFO org.apache.hadoop.yarn.server.resourcemanager.rmapp.attempt.RMAppAttemptImpl: appattempt_1375865942038_0004_000001 State change from SCHEDULED to ALLOCATED_SAVING
2013-08-07 09:05:58,609 INFO org.apache.hadoop.yarn.server.resourcemanager.recovery.RMStateStore: Storing info for attempt: appattempt_1375865942038_0004_000001
2013-08-07 09:05:58,611 INFO org.apache.hadoop.yarn.server.resourcemanager.rmapp.attempt.RMAppAttemptImpl: appattempt_1375865942038_0004_000001 State change from ALLOCATED_SAVING to ALLOCATED
2013-08-07 09:05:58,613 INFO org.apache.hadoop.yarn.server.resourcemanager.amlauncher.AMLauncher: Launching masterappattempt_1375865942038_0004_000001
2013-08-07 09:05:58,616 INFO org.apache.hadoop.yarn.server.resourcemanager.amlauncher.AMLauncher: Setting up container Container: [ContainerId: container_1375865942038_0004_01_000001, NodeId: hadoop-200-4:57320, NodeHttpAddress: hadoop-200-4:8042, Resource: <memory:2048, vCores:1>, Priority: 0, State: NEW, Token: null, Status: container_id {, app_attempt_id {, application_id {, id: 4, cluster_timestamp: 1375865942038, }, attemptId: 1, }, id: 1, }, state: C_NEW, ] for AM appattempt_1375865942038_0004_000001
2013-08-07 09:05:58,616 INFO org.apache.hadoop.yarn.server.resourcemanager.amlauncher.AMLauncher: Command to launch container container_1375865942038_0004_01_000001 : $JAVA_HOME/bin/java -Dlog4j.configuration=container-log4j.properties -Dyarn.app.mapreduce.container.log.dir=<LOG_DIR> -Dyarn.app.mapreduce.container.log.filesize=0 -Dhadoop.root.logger=INFO,CLA  -Xmx1024m org.apache.hadoop.mapreduce.v2.app.MRAppMaster 1><LOG_DIR>/stdout 2><LOG_DIR>/stderr 
2013-08-07 09:05:58,633 INFO org.apache.hadoop.yarn.server.resourcemanager.amlauncher.AMLauncher: Done launching container Container: [ContainerId: container_1375865942038_0004_01_000001, NodeId: hadoop-200-4:57320, NodeHttpAddress: hadoop-200-4:8042, Resource: <memory:2048, vCores:1>, Priority: 0, State: NEW, Token: null, Status: container_id {, app_attempt_id {, application_id {, id: 4, cluster_timestamp: 1375865942038, }, attemptId: 1, }, id: 1, }, state: C_NEW, ] for AM appattempt_1375865942038_0004_000001
2013-08-07 09:05:58,634 INFO org.apache.hadoop.yarn.server.resourcemanager.rmapp.attempt.RMAppAttemptImpl: appattempt_1375865942038_0004_000001 State change from ALLOCATED to LAUNCHED
2013-08-07 09:05:59,606 INFO org.apache.hadoop.yarn.server.resourcemanager.rmcontainer.RMContainerImpl: container_1375865942038_0004_01_000001 Container Transitioned from ACQUIRED to RUNNING
2013-08-07 09:06:07,979 INFO org.apache.hadoop.yarn.server.resourcemanager.ApplicationMasterService: AM registration appattempt_1375865942038_0004_000001
2013-08-07 09:06:07,980 INFO org.apache.hadoop.yarn.server.resourcemanager.RMAuditLogger: USER=ubuntu	IP=192.168.100.6	OPERATION=Register App Master	TARGET=ApplicationMasterService	RESULT=SUCCESS	APPID=application_1375865942038_0004	APPATTEMPTID=appattempt_1375865942038_0004_000001
2013-08-07 09:06:07,981 INFO org.apache.hadoop.yarn.server.resourcemanager.rmapp.attempt.RMAppAttemptImpl: appattempt_1375865942038_0004_000001 State change from LAUNCHED to RUNNING
2013-08-07 09:06:07,981 INFO org.apache.hadoop.yarn.server.resourcemanager.rmapp.RMAppImpl: application_1375865942038_0004 State change from ACCEPTED to RUNNING
2013-08-07 09:06:09,126 INFO org.apache.hadoop.yarn.server.resourcemanager.rmcontainer.RMContainerImpl: container_1375865942038_0004_01_000002 Container Transitioned from NEW to ALLOCATED
2013-08-07 09:06:09,126 INFO org.apache.hadoop.yarn.server.resourcemanager.RMAuditLogger: USER=ubuntu	OPERATION=AM Allocated Container	TARGET=SchedulerApp	RESULT=SUCCESS	APPID=application_1375865942038_0004	CONTAINERID=container_1375865942038_0004_01_000002
2013-08-07 09:06:09,128 INFO org.apache.hadoop.yarn.server.resourcemanager.scheduler.common.fica.FiCaSchedulerNode: Assigned container container_1375865942038_0004_01_000002 of capacity <memory:1024, vCores:1> on host hadoop-200-2:58832, which currently has 1 containers, <memory:1024, vCores:1> used and <memory:7168, vCores:15> available
2013-08-07 09:06:09,130 INFO org.apache.hadoop.yarn.server.resourcemanager.scheduler.capacity.LeafQueue: assignedContainer application=application_1375865942038_0004 container=Container: [ContainerId: container_1375865942038_0004_01_000002, NodeId: hadoop-200-2:58832, NodeHttpAddress: hadoop-200-2:8042, Resource: <memory:1024, vCores:1>, Priority: 20, State: NEW, Token: null, Status: container_id {, app_attempt_id {, application_id {, id: 4, cluster_timestamp: 1375865942038, }, attemptId: 1, }, id: 2, }, state: C_NEW, ] containerId=container_1375865942038_0004_01_000002 queue=default: capacity=1.0, absoluteCapacity=1.0, usedResources=<memory:2048, vCores:1>usedCapacity=0.041666668, absoluteUsedCapacity=0.041666668, numApps=1, numContainers=1 usedCapacity=0.041666668 absoluteUsedCapacity=0.041666668 used=<memory:2048, vCores:1> cluster=<memory:49152, vCores:96>
2013-08-07 09:06:09,130 INFO org.apache.hadoop.yarn.server.resourcemanager.scheduler.capacity.ParentQueue: Re-sorting queues since queue: root.default stats: default: capacity=1.0, absoluteCapacity=1.0, usedResources=<memory:3072, vCores:2>usedCapacity=0.0625, absoluteUsedCapacity=0.0625, numApps=1, numContainers=2
2013-08-07 09:06:09,130 INFO org.apache.hadoop.yarn.server.resourcemanager.scheduler.capacity.ParentQueue: assignedContainer queue=root usedCapacity=0.0625 absoluteUsedCapacity=0.0625 used=<memory:3072, vCores:2> cluster=<memory:49152, vCores:96>
2013-08-07 09:06:09,131 INFO org.apache.hadoop.yarn.server.resourcemanager.rmcontainer.RMContainerImpl: container_1375865942038_0004_01_000003 Container Transitioned from NEW to ALLOCATED
2013-08-07 09:06:09,131 INFO org.apache.hadoop.yarn.server.resourcemanager.RMAuditLogger: USER=ubuntu	OPERATION=AM Allocated Container	TARGET=SchedulerApp	RESULT=SUCCESS	APPID=application_1375865942038_0004	CONTAINERID=container_1375865942038_0004_01_000003
2013-08-07 09:06:09,131 INFO org.apache.hadoop.yarn.server.resourcemanager.scheduler.common.fica.FiCaSchedulerNode: Assigned container container_1375865942038_0004_01_000003 of capacity <memory:1024, vCores:1> on host hadoop-200-5:55554, which currently has 1 containers, <memory:1024, vCores:1> used and <memory:7168, vCores:15> available
2013-08-07 09:06:09,133 INFO org.apache.hadoop.yarn.server.resourcemanager.scheduler.capacity.LeafQueue: assignedContainer application=application_1375865942038_0004 container=Container: [ContainerId: container_1375865942038_0004_01_000003, NodeId: hadoop-200-5:55554, NodeHttpAddress: hadoop-200-5:8042, Resource: <memory:1024, vCores:1>, Priority: 20, State: NEW, Token: null, Status: container_id {, app_attempt_id {, application_id {, id: 4, cluster_timestamp: 1375865942038, }, attemptId: 1, }, id: 3, }, state: C_NEW, ] containerId=container_1375865942038_0004_01_000003 queue=default: capacity=1.0, absoluteCapacity=1.0, usedResources=<memory:3072, vCores:2>usedCapacity=0.0625, absoluteUsedCapacity=0.0625, numApps=1, numContainers=2 usedCapacity=0.0625 absoluteUsedCapacity=0.0625 used=<memory:3072, vCores:2> cluster=<memory:49152, vCores:96>
2013-08-07 09:06:09,133 INFO org.apache.hadoop.yarn.server.resourcemanager.scheduler.capacity.ParentQueue: Re-sorting queues since queue: root.default stats: default: capacity=1.0, absoluteCapacity=1.0, usedResources=<memory:4096, vCores:3>usedCapacity=0.083333336, absoluteUsedCapacity=0.083333336, numApps=1, numContainers=3
2013-08-07 09:06:09,133 INFO org.apache.hadoop.yarn.server.resourcemanager.scheduler.capacity.ParentQueue: assignedContainer queue=root usedCapacity=0.083333336 absoluteUsedCapacity=0.083333336 used=<memory:4096, vCores:3> cluster=<memory:49152, vCores:96>
2013-08-07 09:06:10,046 INFO org.apache.hadoop.yarn.server.resourcemanager.rmcontainer.RMContainerImpl: container_1375865942038_0004_01_000002 Container Transitioned from ALLOCATED to ACQUIRED
2013-08-07 09:06:10,048 INFO org.apache.hadoop.yarn.server.resourcemanager.rmcontainer.RMContainerImpl: container_1375865942038_0004_01_000003 Container Transitioned from ALLOCATED to ACQUIRED
2013-08-07 09:06:11,083 INFO org.apache.hadoop.yarn.server.resourcemanager.scheduler.AppSchedulingInfo: checking for deactivate... 
2013-08-07 09:06:11,139 INFO org.apache.hadoop.yarn.server.resourcemanager.rmcontainer.RMContainerImpl: container_1375865942038_0004_01_000003 Container Transitioned from ACQUIRED to RUNNING
2013-08-07 09:06:12,160 INFO org.apache.hadoop.yarn.server.resourcemanager.rmcontainer.RMContainerImpl: container_1375865942038_0004_01_000002 Container Transitioned from ACQUIRED to RUNNING
2013-08-07 09:07:45,270 INFO org.apache.hadoop.yarn.server.resourcemanager.rmcontainer.RMContainerImpl: container_1375865942038_0004_01_000003 Container Transitioned from RUNNING to COMPLETED
2013-08-07 09:07:45,270 INFO org.apache.hadoop.yarn.server.resourcemanager.scheduler.common.fica.FiCaSchedulerApp: Completed container: container_1375865942038_0004_01_000003 in state: COMPLETED event:FINISHED
2013-08-07 09:07:45,271 INFO org.apache.hadoop.yarn.server.resourcemanager.RMAuditLogger: USER=ubuntu	OPERATION=AM Released Container	TARGET=SchedulerApp	RESULT=SUCCESS	APPID=application_1375865942038_0004	CONTAINERID=container_1375865942038_0004_01_000003
2013-08-07 09:07:45,271 INFO org.apache.hadoop.yarn.server.resourcemanager.scheduler.common.fica.FiCaSchedulerNode: Released container container_1375865942038_0004_01_000003 of capacity <memory:1024, vCores:1> on host hadoop-200-5:55554, which currently has 0 containers, <memory:0, vCores:0> used and <memory:8192, vCores:16> available, release resources=true
2013-08-07 09:07:45,271 INFO org.apache.hadoop.yarn.server.resourcemanager.scheduler.capacity.LeafQueue: default used=<memory:3072, vCores:2> numContainers=2 user=ubuntu user-resources=<memory:3072, vCores:2>
2013-08-07 09:07:45,273 INFO org.apache.hadoop.yarn.server.resourcemanager.scheduler.capacity.LeafQueue: completedContainer container=Container: [ContainerId: container_1375865942038_0004_01_000003, NodeId: hadoop-200-5:55554, NodeHttpAddress: hadoop-200-5:8042, Resource: <memory:1024, vCores:1>, Priority: 20, State: NEW, Token: null, Status: container_id {, app_attempt_id {, application_id {, id: 4, cluster_timestamp: 1375865942038, }, attemptId: 1, }, id: 3, }, state: C_COMPLETE, diagnostics: "Container killed by the ApplicationMaster.\n\n", exit_status: 143, ] resource=<memory:1024, vCores:1> queue=default: capacity=1.0, absoluteCapacity=1.0, usedResources=<memory:3072, vCores:2>usedCapacity=0.0625, absoluteUsedCapacity=0.0625, numApps=1, numContainers=2 usedCapacity=0.0625 absoluteUsedCapacity=0.0625 used=<memory:3072, vCores:2> cluster=<memory:49152, vCores:96>
2013-08-07 09:07:45,273 INFO org.apache.hadoop.yarn.server.resourcemanager.scheduler.capacity.ParentQueue: completedContainer queue=root usedCapacity=0.0625 absoluteUsedCapacity=0.0625 used=<memory:3072, vCores:2> cluster=<memory:49152, vCores:96>
2013-08-07 09:07:45,273 INFO org.apache.hadoop.yarn.server.resourcemanager.scheduler.capacity.CapacityScheduler: Application appattempt_1375865942038_0004_000001 released container container_1375865942038_0004_01_000003 on node: host: hadoop-200-5:55554 #containers=0 available=8192 used=0 with event: FINISHED
2013-08-07 09:08:00,449 INFO org.apache.hadoop.yarn.server.resourcemanager.rmcontainer.RMContainerImpl: container_1375865942038_0004_01_000002 Container Transitioned from RUNNING to COMPLETED
2013-08-07 09:08:00,450 INFO org.apache.hadoop.yarn.server.resourcemanager.scheduler.common.fica.FiCaSchedulerApp: Completed container: container_1375865942038_0004_01_000002 in state: COMPLETED event:FINISHED
2013-08-07 09:08:00,450 INFO org.apache.hadoop.yarn.server.resourcemanager.RMAuditLogger: USER=ubuntu	OPERATION=AM Released Container	TARGET=SchedulerApp	RESULT=SUCCESS	APPID=application_1375865942038_0004	CONTAINERID=container_1375865942038_0004_01_000002
2013-08-07 09:08:00,450 INFO org.apache.hadoop.yarn.server.resourcemanager.scheduler.common.fica.FiCaSchedulerNode: Released container container_1375865942038_0004_01_000002 of capacity <memory:1024, vCores:1> on host hadoop-200-2:58832, which currently has 0 containers, <memory:0, vCores:0> used and <memory:8192, vCores:16> available, release resources=true
2013-08-07 09:08:00,450 INFO org.apache.hadoop.yarn.server.resourcemanager.scheduler.capacity.LeafQueue: default used=<memory:2048, vCores:1> numContainers=1 user=ubuntu user-resources=<memory:2048, vCores:1>
2013-08-07 09:08:00,452 INFO org.apache.hadoop.yarn.server.resourcemanager.scheduler.capacity.LeafQueue: completedContainer container=Container: [ContainerId: container_1375865942038_0004_01_000002, NodeId: hadoop-200-2:58832, NodeHttpAddress: hadoop-200-2:8042, Resource: <memory:1024, vCores:1>, Priority: 20, State: NEW, Token: null, Status: container_id {, app_attempt_id {, application_id {, id: 4, cluster_timestamp: 1375865942038, }, attemptId: 1, }, id: 2, }, state: C_COMPLETE, diagnostics: "Container killed by the ApplicationMaster.\n\n", exit_status: 143, ] resource=<memory:1024, vCores:1> queue=default: capacity=1.0, absoluteCapacity=1.0, usedResources=<memory:2048, vCores:1>usedCapacity=0.041666668, absoluteUsedCapacity=0.041666668, numApps=1, numContainers=1 usedCapacity=0.041666668 absoluteUsedCapacity=0.041666668 used=<memory:2048, vCores:1> cluster=<memory:49152, vCores:96>
2013-08-07 09:08:00,452 INFO org.apache.hadoop.yarn.server.resourcemanager.scheduler.capacity.ParentQueue: completedContainer queue=root usedCapacity=0.041666668 absoluteUsedCapacity=0.041666668 used=<memory:2048, vCores:1> cluster=<memory:49152, vCores:96>
2013-08-07 09:08:00,452 INFO org.apache.hadoop.yarn.server.resourcemanager.scheduler.capacity.CapacityScheduler: Application appattempt_1375865942038_0004_000001 released container container_1375865942038_0004_01_000002 on node: host: hadoop-200-2:58832 #containers=0 available=8192 used=0 with event: FINISHED
2013-08-07 09:08:05,102 INFO org.apache.hadoop.yarn.server.resourcemanager.rmapp.attempt.RMAppAttemptImpl: appattempt_1375865942038_0004_000001 State change from RUNNING to FINISHING
2013-08-07 09:08:05,102 INFO org.apache.hadoop.yarn.server.resourcemanager.rmapp.RMAppImpl: application_1375865942038_0004 State change from RUNNING to FINISHING
2013-08-07 09:08:06,092 INFO org.apache.hadoop.yarn.server.resourcemanager.rmcontainer.RMContainerImpl: container_1375865942038_0004_01_000001 Container Transitioned from RUNNING to COMPLETED
2013-08-07 09:08:06,092 INFO org.apache.hadoop.yarn.server.resourcemanager.scheduler.common.fica.FiCaSchedulerApp: Completed container: container_1375865942038_0004_01_000001 in state: COMPLETED event:FINISHED
2013-08-07 09:08:06,092 INFO org.apache.hadoop.yarn.server.resourcemanager.rmapp.attempt.RMAppAttemptImpl: appattempt_1375865942038_0004_000001 State change from FINISHING to FINISHED
2013-08-07 09:08:06,093 INFO org.apache.hadoop.yarn.server.resourcemanager.RMAuditLogger: USER=ubuntu	OPERATION=AM Released Container	TARGET=SchedulerApp	RESULT=SUCCESS	APPID=application_1375865942038_0004	CONTAINERID=container_1375865942038_0004_01_000001
2013-08-07 09:08:06,093 INFO org.apache.hadoop.yarn.server.resourcemanager.rmapp.RMAppImpl: application_1375865942038_0004 State change from FINISHING to FINISHED
2013-08-07 09:08:06,094 INFO org.apache.hadoop.yarn.server.resourcemanager.scheduler.common.fica.FiCaSchedulerNode: Released container container_1375865942038_0004_01_000001 of capacity <memory:2048, vCores:1> on host hadoop-200-4:57320, which currently has 0 containers, <memory:0, vCores:0> used and <memory:8192, vCores:16> available, release resources=true
2013-08-07 09:08:06,094 INFO org.apache.hadoop.yarn.server.resourcemanager.scheduler.capacity.LeafQueue: default used=<memory:0, vCores:0> numContainers=0 user=ubuntu user-resources=<memory:0, vCores:0>
2013-08-07 09:08:06,094 INFO org.apache.hadoop.yarn.server.resourcemanager.RMAuditLogger: USER=ubuntu	OPERATION=Application Finished - Succeeded	TARGET=RMAppManager	RESULT=SUCCESS	APPID=application_1375865942038_0004
2013-08-07 09:08:06,094 INFO org.apache.hadoop.yarn.server.resourcemanager.recovery.RMStateStore: Removing info for app: application_1375865942038_0004
2013-08-07 09:08:06,094 INFO org.apache.hadoop.yarn.server.resourcemanager.RMAppManager$ApplicationSummary: appId=application_1375865942038_0004,name=TeraGen,user=ubuntu,queue=default,state=FINISHED,trackingUrl=hadoop-200-1.novalocal:8088/proxy/application_1375865942038_0004/jobhistory/job/job_1375865942038_0004,appMasterHost=hadoop-200-4,startTime=1375866358273,finishTime=1375866485102
2013-08-07 09:08:06,095 INFO org.apache.hadoop.yarn.server.resourcemanager.amlauncher.AMLauncher: Cleaning master appattempt_1375865942038_0004_000001
2013-08-07 09:08:06,096 INFO org.apache.hadoop.yarn.server.resourcemanager.scheduler.capacity.LeafQueue: completedContainer container=Container: [ContainerId: container_1375865942038_0004_01_000001, NodeId: hadoop-200-4:57320, NodeHttpAddress: hadoop-200-4:8042, Resource: <memory:2048, vCores:1>, Priority: 0, State: NEW, Token: null, Status: container_id {, app_attempt_id {, application_id {, id: 4, cluster_timestamp: 1375865942038, }, attemptId: 1, }, id: 1, }, state: C_COMPLETE, diagnostics: "", exit_status: 0, ] resource=<memory:2048, vCores:1> queue=default: capacity=1.0, absoluteCapacity=1.0, usedResources=<memory:0, vCores:0>usedCapacity=0.0, absoluteUsedCapacity=0.0, numApps=1, numContainers=0 usedCapacity=0.0 absoluteUsedCapacity=0.0 used=<memory:0, vCores:0> cluster=<memory:49152, vCores:96>
2013-08-07 09:08:06,096 INFO org.apache.hadoop.yarn.server.resourcemanager.scheduler.capacity.ParentQueue: completedContainer queue=root usedCapacity=0.0 absoluteUsedCapacity=0.0 used=<memory:0, vCores:0> cluster=<memory:49152, vCores:96>
2013-08-07 09:08:06,096 INFO org.apache.hadoop.yarn.server.resourcemanager.scheduler.capacity.CapacityScheduler: Application appattempt_1375865942038_0004_000001 released container container_1375865942038_0004_01_000001 on node: host: hadoop-200-4:57320 #containers=0 available=8192 used=0 with event: FINISHED
2013-08-07 09:08:06,096 INFO org.apache.hadoop.yarn.server.resourcemanager.scheduler.capacity.CapacityScheduler: Application appattempt_1375865942038_0004_000001 is done. finalState=FINISHED
2013-08-07 09:08:06,096 INFO org.apache.hadoop.yarn.server.resourcemanager.scheduler.AppSchedulingInfo: Application application_1375865942038_0004 requests cleared
2013-08-07 09:08:06,096 INFO org.apache.hadoop.yarn.server.resourcemanager.scheduler.capacity.LeafQueue: Application removed - appId: application_1375865942038_0004 user: ubuntu queue: default #user-pending-applications: 0 #user-active-applications: 0 #queue-pending-applications: 0 #queue-active-applications: 0
2013-08-07 09:08:06,097 INFO org.apache.hadoop.yarn.server.resourcemanager.scheduler.capacity.ParentQueue: Application removed - appId: application_1375865942038_0004 user: ubuntu leaf-queue of parent: root #applications: 0
2013-08-07 09:08:06,242 INFO org.apache.hadoop.yarn.server.resourcemanager.ClientRMService: Allocated new applicationId: 5
2013-08-07 09:08:08,155 INFO org.apache.hadoop.yarn.server.resourcemanager.ClientRMService: Storing Application with id application_1375865942038_0005
2013-08-07 09:08:08,155 INFO org.apache.hadoop.yarn.server.resourcemanager.recovery.RMStateStore: Storing info for app: application_1375865942038_0005
2013-08-07 09:08:08,156 INFO org.apache.hadoop.yarn.server.resourcemanager.ClientRMService: Application with id 5 submitted by user ubuntu
2013-08-07 09:08:08,156 INFO org.apache.hadoop.yarn.server.resourcemanager.RMAuditLogger: USER=ubuntu	IP=192.168.100.2	OPERATION=Submit Application Request	TARGET=ClientRMService	RESULT=SUCCESS	APPID=application_1375865942038_0005
2013-08-07 09:08:08,157 INFO org.apache.hadoop.yarn.server.resourcemanager.rmapp.RMAppImpl: application_1375865942038_0005 State change from NEW to SUBMITTED
2013-08-07 09:08:08,157 INFO org.apache.hadoop.yarn.server.resourcemanager.ApplicationMasterService: Registering appattempt_1375865942038_0005_000001
2013-08-07 09:08:08,158 INFO org.apache.hadoop.yarn.server.resourcemanager.rmapp.attempt.RMAppAttemptImpl: appattempt_1375865942038_0005_000001 State change from NEW to SUBMITTED
2013-08-07 09:08:08,158 INFO org.apache.hadoop.yarn.server.resourcemanager.scheduler.capacity.LeafQueue: Application application_1375865942038_0005 from user: ubuntu activated in queue: default
2013-08-07 09:08:08,158 INFO org.apache.hadoop.yarn.server.resourcemanager.scheduler.capacity.LeafQueue: Application added - appId: application_1375865942038_0005 user: org.apache.hadoop.yarn.server.resourcemanager.scheduler.capacity.LeafQueue$User@3b37d2b6, leaf-queue: default #user-pending-applications: 0 #user-active-applications: 1 #queue-pending-applications: 0 #queue-active-applications: 1
2013-08-07 09:08:08,159 INFO org.apache.hadoop.yarn.server.resourcemanager.scheduler.capacity.ParentQueue: Application added - appId: application_1375865942038_0005 user: ubuntu leaf-queue of parent: root #applications: 1
2013-08-07 09:08:08,159 INFO org.apache.hadoop.yarn.server.resourcemanager.scheduler.capacity.CapacityScheduler: Application Submission: appattempt_1375865942038_0005_000001, user: ubuntu queue: default: capacity=1.0, absoluteCapacity=1.0, usedResources=<memory:0, vCores:0>usedCapacity=0.0, absoluteUsedCapacity=0.0, numApps=1, numContainers=0, currently active: 1
2013-08-07 09:08:08,159 INFO org.apache.hadoop.yarn.server.resourcemanager.rmapp.attempt.RMAppAttemptImpl: appattempt_1375865942038_0005_000001 State change from SUBMITTED to SCHEDULED
2013-08-07 09:08:08,159 INFO org.apache.hadoop.yarn.server.resourcemanager.rmapp.RMAppImpl: application_1375865942038_0005 State change from SUBMITTED to ACCEPTED
2013-08-07 09:08:08,350 INFO org.apache.hadoop.yarn.server.resourcemanager.rmcontainer.RMContainerImpl: container_1375865942038_0005_01_000001 Container Transitioned from NEW to ALLOCATED
2013-08-07 09:08:08,350 INFO org.apache.hadoop.yarn.server.resourcemanager.RMAuditLogger: USER=ubuntu	OPERATION=AM Allocated Container	TARGET=SchedulerApp	RESULT=SUCCESS	APPID=application_1375865942038_0005	CONTAINERID=container_1375865942038_0005_01_000001
2013-08-07 09:08:08,350 INFO org.apache.hadoop.yarn.server.resourcemanager.scheduler.common.fica.FiCaSchedulerNode: Assigned container container_1375865942038_0005_01_000001 of capacity <memory:2048, vCores:1> on host hadoop-200-5:55554, which currently has 1 containers, <memory:2048, vCores:1> used and <memory:6144, vCores:15> available
2013-08-07 09:08:08,352 INFO org.apache.hadoop.yarn.server.resourcemanager.scheduler.capacity.LeafQueue: assignedContainer application=application_1375865942038_0005 container=Container: [ContainerId: container_1375865942038_0005_01_000001, NodeId: hadoop-200-5:55554, NodeHttpAddress: hadoop-200-5:8042, Resource: <memory:2048, vCores:1>, Priority: 0, State: NEW, Token: null, Status: container_id {, app_attempt_id {, application_id {, id: 5, cluster_timestamp: 1375865942038, }, attemptId: 1, }, id: 1, }, state: C_NEW, ] containerId=container_1375865942038_0005_01_000001 queue=default: capacity=1.0, absoluteCapacity=1.0, usedResources=<memory:0, vCores:0>usedCapacity=0.0, absoluteUsedCapacity=0.0, numApps=1, numContainers=0 usedCapacity=0.0 absoluteUsedCapacity=0.0 used=<memory:0, vCores:0> cluster=<memory:49152, vCores:96>
2013-08-07 09:08:08,352 INFO org.apache.hadoop.yarn.server.resourcemanager.scheduler.capacity.ParentQueue: Re-sorting queues since queue: root.default stats: default: capacity=1.0, absoluteCapacity=1.0, usedResources=<memory:2048, vCores:1>usedCapacity=0.041666668, absoluteUsedCapacity=0.041666668, numApps=1, numContainers=1
2013-08-07 09:08:08,352 INFO org.apache.hadoop.yarn.server.resourcemanager.scheduler.capacity.ParentQueue: assignedContainer queue=root usedCapacity=0.041666668 absoluteUsedCapacity=0.041666668 used=<memory:2048, vCores:1> cluster=<memory:49152, vCores:96>
2013-08-07 09:08:08,354 INFO org.apache.hadoop.yarn.server.resourcemanager.rmcontainer.RMContainerImpl: container_1375865942038_0005_01_000001 Container Transitioned from ALLOCATED to ACQUIRED
2013-08-07 09:08:08,356 INFO org.apache.hadoop.yarn.server.resourcemanager.rmapp.attempt.RMAppAttemptImpl: Storing attempt: AppId: application_1375865942038_0005 AttemptId: appattempt_1375865942038_0005_000001 MasterContainer: Container: [ContainerId: container_1375865942038_0005_01_000001, NodeId: hadoop-200-5:55554, NodeHttpAddress: hadoop-200-5:8042, Resource: <memory:2048, vCores:1>, Priority: 0, State: NEW, Token: null, Status: container_id {, app_attempt_id {, application_id {, id: 5, cluster_timestamp: 1375865942038, }, attemptId: 1, }, id: 1, }, state: C_NEW, ]
2013-08-07 09:08:08,356 INFO org.apache.hadoop.yarn.server.resourcemanager.rmapp.attempt.RMAppAttemptImpl: appattempt_1375865942038_0005_000001 State change from SCHEDULED to ALLOCATED_SAVING
2013-08-07 09:08:08,356 INFO org.apache.hadoop.yarn.server.resourcemanager.recovery.RMStateStore: Storing info for attempt: appattempt_1375865942038_0005_000001
2013-08-07 09:08:08,357 INFO org.apache.hadoop.yarn.server.resourcemanager.rmapp.attempt.RMAppAttemptImpl: appattempt_1375865942038_0005_000001 State change from ALLOCATED_SAVING to ALLOCATED
2013-08-07 09:08:08,359 INFO org.apache.hadoop.yarn.server.resourcemanager.amlauncher.AMLauncher: Launching masterappattempt_1375865942038_0005_000001
2013-08-07 09:08:08,362 INFO org.apache.hadoop.yarn.server.resourcemanager.amlauncher.AMLauncher: Setting up container Container: [ContainerId: container_1375865942038_0005_01_000001, NodeId: hadoop-200-5:55554, NodeHttpAddress: hadoop-200-5:8042, Resource: <memory:2048, vCores:1>, Priority: 0, State: NEW, Token: null, Status: container_id {, app_attempt_id {, application_id {, id: 5, cluster_timestamp: 1375865942038, }, attemptId: 1, }, id: 1, }, state: C_NEW, ] for AM appattempt_1375865942038_0005_000001
2013-08-07 09:08:08,362 INFO org.apache.hadoop.yarn.server.resourcemanager.amlauncher.AMLauncher: Command to launch container container_1375865942038_0005_01_000001 : $JAVA_HOME/bin/java -Dlog4j.configuration=container-log4j.properties -Dyarn.app.mapreduce.container.log.dir=<LOG_DIR> -Dyarn.app.mapreduce.container.log.filesize=0 -Dhadoop.root.logger=INFO,CLA  -Xmx1024m org.apache.hadoop.mapreduce.v2.app.MRAppMaster 1><LOG_DIR>/stdout 2><LOG_DIR>/stderr 
2013-08-07 09:08:08,377 INFO org.apache.hadoop.yarn.server.resourcemanager.amlauncher.AMLauncher: Done launching container Container: [ContainerId: container_1375865942038_0005_01_000001, NodeId: hadoop-200-5:55554, NodeHttpAddress: hadoop-200-5:8042, Resource: <memory:2048, vCores:1>, Priority: 0, State: NEW, Token: null, Status: container_id {, app_attempt_id {, application_id {, id: 5, cluster_timestamp: 1375865942038, }, attemptId: 1, }, id: 1, }, state: C_NEW, ] for AM appattempt_1375865942038_0005_000001
2013-08-07 09:08:08,377 INFO org.apache.hadoop.yarn.server.resourcemanager.rmapp.attempt.RMAppAttemptImpl: appattempt_1375865942038_0005_000001 State change from ALLOCATED to LAUNCHED
2013-08-07 09:08:09,355 INFO org.apache.hadoop.yarn.server.resourcemanager.rmcontainer.RMContainerImpl: container_1375865942038_0005_01_000001 Container Transitioned from ACQUIRED to RUNNING
2013-08-07 09:08:14,518 INFO org.apache.hadoop.yarn.server.resourcemanager.ApplicationMasterService: AM registration appattempt_1375865942038_0005_000001
2013-08-07 09:08:14,518 INFO org.apache.hadoop.yarn.server.resourcemanager.RMAuditLogger: USER=ubuntu	IP=192.168.100.8	OPERATION=Register App Master	TARGET=ApplicationMasterService	RESULT=SUCCESS	APPID=application_1375865942038_0005	APPATTEMPTID=appattempt_1375865942038_0005_000001
2013-08-07 09:08:14,519 INFO org.apache.hadoop.yarn.server.resourcemanager.rmapp.attempt.RMAppAttemptImpl: appattempt_1375865942038_0005_000001 State change from LAUNCHED to RUNNING
2013-08-07 09:08:14,519 INFO org.apache.hadoop.yarn.server.resourcemanager.rmapp.RMAppImpl: application_1375865942038_0005 State change from ACCEPTED to RUNNING
2013-08-07 09:08:15,642 INFO org.apache.hadoop.yarn.server.resourcemanager.rmcontainer.RMContainerImpl: container_1375865942038_0005_01_000002 Container Transitioned from NEW to ALLOCATED
2013-08-07 09:08:15,642 INFO org.apache.hadoop.yarn.server.resourcemanager.RMAuditLogger: USER=ubuntu	OPERATION=AM Allocated Container	TARGET=SchedulerApp	RESULT=SUCCESS	APPID=application_1375865942038_0005	CONTAINERID=container_1375865942038_0005_01_000002
2013-08-07 09:08:15,642 INFO org.apache.hadoop.yarn.server.resourcemanager.scheduler.common.fica.FiCaSchedulerNode: Assigned container container_1375865942038_0005_01_000002 of capacity <memory:1024, vCores:1> on host hadoop-200-7:54925, which currently has 1 containers, <memory:1024, vCores:1> used and <memory:7168, vCores:15> available
2013-08-07 09:08:15,644 INFO org.apache.hadoop.yarn.server.resourcemanager.scheduler.capacity.LeafQueue: assignedContainer application=application_1375865942038_0005 container=Container: [ContainerId: container_1375865942038_0005_01_000002, NodeId: hadoop-200-7:54925, NodeHttpAddress: hadoop-200-7:8042, Resource: <memory:1024, vCores:1>, Priority: 20, State: NEW, Token: null, Status: container_id {, app_attempt_id {, application_id {, id: 5, cluster_timestamp: 1375865942038, }, attemptId: 1, }, id: 2, }, state: C_NEW, ] containerId=container_1375865942038_0005_01_000002 queue=default: capacity=1.0, absoluteCapacity=1.0, usedResources=<memory:2048, vCores:1>usedCapacity=0.041666668, absoluteUsedCapacity=0.041666668, numApps=1, numContainers=1 usedCapacity=0.041666668 absoluteUsedCapacity=0.041666668 used=<memory:2048, vCores:1> cluster=<memory:49152, vCores:96>
2013-08-07 09:08:15,644 INFO org.apache.hadoop.yarn.server.resourcemanager.scheduler.capacity.ParentQueue: Re-sorting queues since queue: root.default stats: default: capacity=1.0, absoluteCapacity=1.0, usedResources=<memory:3072, vCores:2>usedCapacity=0.0625, absoluteUsedCapacity=0.0625, numApps=1, numContainers=2
2013-08-07 09:08:15,644 INFO org.apache.hadoop.yarn.server.resourcemanager.scheduler.capacity.ParentQueue: assignedContainer queue=root usedCapacity=0.0625 absoluteUsedCapacity=0.0625 used=<memory:3072, vCores:2> cluster=<memory:49152, vCores:96>
2013-08-07 09:08:15,660 INFO org.apache.hadoop.yarn.server.resourcemanager.rmcontainer.RMContainerImpl: container_1375865942038_0005_01_000003 Container Transitioned from NEW to ALLOCATED
2013-08-07 09:08:15,660 INFO org.apache.hadoop.yarn.server.resourcemanager.RMAuditLogger: USER=ubuntu	OPERATION=AM Allocated Container	TARGET=SchedulerApp	RESULT=SUCCESS	APPID=application_1375865942038_0005	CONTAINERID=container_1375865942038_0005_01_000003
2013-08-07 09:08:15,660 INFO org.apache.hadoop.yarn.server.resourcemanager.scheduler.common.fica.FiCaSchedulerNode: Assigned container container_1375865942038_0005_01_000003 of capacity <memory:1024, vCores:1> on host hadoop-200-3:58063, which currently has 1 containers, <memory:1024, vCores:1> used and <memory:7168, vCores:15> available
2013-08-07 09:08:15,662 INFO org.apache.hadoop.yarn.server.resourcemanager.scheduler.capacity.LeafQueue: assignedContainer application=application_1375865942038_0005 container=Container: [ContainerId: container_1375865942038_0005_01_000003, NodeId: hadoop-200-3:58063, NodeHttpAddress: hadoop-200-3:8042, Resource: <memory:1024, vCores:1>, Priority: 20, State: NEW, Token: null, Status: container_id {, app_attempt_id {, application_id {, id: 5, cluster_timestamp: 1375865942038, }, attemptId: 1, }, id: 3, }, state: C_NEW, ] containerId=container_1375865942038_0005_01_000003 queue=default: capacity=1.0, absoluteCapacity=1.0, usedResources=<memory:3072, vCores:2>usedCapacity=0.0625, absoluteUsedCapacity=0.0625, numApps=1, numContainers=2 usedCapacity=0.0625 absoluteUsedCapacity=0.0625 used=<memory:3072, vCores:2> cluster=<memory:49152, vCores:96>
2013-08-07 09:08:15,662 INFO org.apache.hadoop.yarn.server.resourcemanager.scheduler.capacity.ParentQueue: Re-sorting queues since queue: root.default stats: default: capacity=1.0, absoluteCapacity=1.0, usedResources=<memory:4096, vCores:3>usedCapacity=0.083333336, absoluteUsedCapacity=0.083333336, numApps=1, numContainers=3
2013-08-07 09:08:15,662 INFO org.apache.hadoop.yarn.server.resourcemanager.scheduler.capacity.ParentQueue: assignedContainer queue=root usedCapacity=0.083333336 absoluteUsedCapacity=0.083333336 used=<memory:4096, vCores:3> cluster=<memory:49152, vCores:96>
2013-08-07 09:08:16,588 INFO org.apache.hadoop.yarn.server.resourcemanager.rmcontainer.RMContainerImpl: container_1375865942038_0005_01_000002 Container Transitioned from ALLOCATED to ACQUIRED
2013-08-07 09:08:16,591 INFO org.apache.hadoop.yarn.server.resourcemanager.rmcontainer.RMContainerImpl: container_1375865942038_0005_01_000003 Container Transitioned from ALLOCATED to ACQUIRED
2013-08-07 09:08:17,618 INFO org.apache.hadoop.yarn.server.resourcemanager.scheduler.AppSchedulingInfo: checking for deactivate... 
2013-08-07 09:08:18,686 INFO org.apache.hadoop.yarn.server.resourcemanager.rmcontainer.RMContainerImpl: container_1375865942038_0005_01_000002 Container Transitioned from ACQUIRED to RUNNING
2013-08-07 09:08:18,701 INFO org.apache.hadoop.yarn.server.resourcemanager.rmcontainer.RMContainerImpl: container_1375865942038_0005_01_000003 Container Transitioned from ACQUIRED to RUNNING
2013-08-07 09:10:02,232 INFO org.apache.hadoop.yarn.server.resourcemanager.rmcontainer.RMContainerImpl: container_1375865942038_0005_01_000002 Container Transitioned from RUNNING to COMPLETED
2013-08-07 09:10:02,232 INFO org.apache.hadoop.yarn.server.resourcemanager.scheduler.common.fica.FiCaSchedulerApp: Completed container: container_1375865942038_0005_01_000002 in state: COMPLETED event:FINISHED
2013-08-07 09:10:02,232 INFO org.apache.hadoop.yarn.server.resourcemanager.RMAuditLogger: USER=ubuntu	OPERATION=AM Released Container	TARGET=SchedulerApp	RESULT=SUCCESS	APPID=application_1375865942038_0005	CONTAINERID=container_1375865942038_0005_01_000002
2013-08-07 09:10:02,232 INFO org.apache.hadoop.yarn.server.resourcemanager.scheduler.common.fica.FiCaSchedulerNode: Released container container_1375865942038_0005_01_000002 of capacity <memory:1024, vCores:1> on host hadoop-200-7:54925, which currently has 0 containers, <memory:0, vCores:0> used and <memory:8192, vCores:16> available, release resources=true
2013-08-07 09:10:02,232 INFO org.apache.hadoop.yarn.server.resourcemanager.scheduler.capacity.LeafQueue: default used=<memory:3072, vCores:2> numContainers=2 user=ubuntu user-resources=<memory:3072, vCores:2>
2013-08-07 09:10:02,234 INFO org.apache.hadoop.yarn.server.resourcemanager.scheduler.capacity.LeafQueue: completedContainer container=Container: [ContainerId: container_1375865942038_0005_01_000002, NodeId: hadoop-200-7:54925, NodeHttpAddress: hadoop-200-7:8042, Resource: <memory:1024, vCores:1>, Priority: 20, State: NEW, Token: null, Status: container_id {, app_attempt_id {, application_id {, id: 5, cluster_timestamp: 1375865942038, }, attemptId: 1, }, id: 2, }, state: C_COMPLETE, diagnostics: "Container killed by the ApplicationMaster.\n\n", exit_status: 143, ] resource=<memory:1024, vCores:1> queue=default: capacity=1.0, absoluteCapacity=1.0, usedResources=<memory:3072, vCores:2>usedCapacity=0.0625, absoluteUsedCapacity=0.0625, numApps=1, numContainers=2 usedCapacity=0.0625 absoluteUsedCapacity=0.0625 used=<memory:3072, vCores:2> cluster=<memory:49152, vCores:96>
2013-08-07 09:10:02,234 INFO org.apache.hadoop.yarn.server.resourcemanager.scheduler.capacity.ParentQueue: completedContainer queue=root usedCapacity=0.0625 absoluteUsedCapacity=0.0625 used=<memory:3072, vCores:2> cluster=<memory:49152, vCores:96>
2013-08-07 09:10:02,234 INFO org.apache.hadoop.yarn.server.resourcemanager.scheduler.capacity.CapacityScheduler: Application appattempt_1375865942038_0005_000001 released container container_1375865942038_0005_01_000002 on node: host: hadoop-200-7:54925 #containers=0 available=8192 used=0 with event: FINISHED
2013-08-07 09:10:05,279 INFO org.apache.hadoop.yarn.server.resourcemanager.rmcontainer.RMContainerImpl: container_1375865942038_0005_01_000003 Container Transitioned from RUNNING to COMPLETED
2013-08-07 09:10:05,280 INFO org.apache.hadoop.yarn.server.resourcemanager.scheduler.common.fica.FiCaSchedulerApp: Completed container: container_1375865942038_0005_01_000003 in state: COMPLETED event:FINISHED
2013-08-07 09:10:05,280 INFO org.apache.hadoop.yarn.server.resourcemanager.RMAuditLogger: USER=ubuntu	OPERATION=AM Released Container	TARGET=SchedulerApp	RESULT=SUCCESS	APPID=application_1375865942038_0005	CONTAINERID=container_1375865942038_0005_01_000003
2013-08-07 09:10:05,280 INFO org.apache.hadoop.yarn.server.resourcemanager.scheduler.common.fica.FiCaSchedulerNode: Released container container_1375865942038_0005_01_000003 of capacity <memory:1024, vCores:1> on host hadoop-200-3:58063, which currently has 0 containers, <memory:0, vCores:0> used and <memory:8192, vCores:16> available, release resources=true
2013-08-07 09:10:05,280 INFO org.apache.hadoop.yarn.server.resourcemanager.scheduler.capacity.LeafQueue: default used=<memory:2048, vCores:1> numContainers=1 user=ubuntu user-resources=<memory:2048, vCores:1>
2013-08-07 09:10:05,282 INFO org.apache.hadoop.yarn.server.resourcemanager.scheduler.capacity.LeafQueue: completedContainer container=Container: [ContainerId: container_1375865942038_0005_01_000003, NodeId: hadoop-200-3:58063, NodeHttpAddress: hadoop-200-3:8042, Resource: <memory:1024, vCores:1>, Priority: 20, State: NEW, Token: null, Status: container_id {, app_attempt_id {, application_id {, id: 5, cluster_timestamp: 1375865942038, }, attemptId: 1, }, id: 3, }, state: C_COMPLETE, diagnostics: "Container killed by the ApplicationMaster.\n\n", exit_status: 143, ] resource=<memory:1024, vCores:1> queue=default: capacity=1.0, absoluteCapacity=1.0, usedResources=<memory:2048, vCores:1>usedCapacity=0.041666668, absoluteUsedCapacity=0.041666668, numApps=1, numContainers=1 usedCapacity=0.041666668 absoluteUsedCapacity=0.041666668 used=<memory:2048, vCores:1> cluster=<memory:49152, vCores:96>
2013-08-07 09:10:05,282 INFO org.apache.hadoop.yarn.server.resourcemanager.scheduler.capacity.ParentQueue: completedContainer queue=root usedCapacity=0.041666668 absoluteUsedCapacity=0.041666668 used=<memory:2048, vCores:1> cluster=<memory:49152, vCores:96>
2013-08-07 09:10:05,283 INFO org.apache.hadoop.yarn.server.resourcemanager.scheduler.capacity.CapacityScheduler: Application appattempt_1375865942038_0005_000001 released container container_1375865942038_0005_01_000003 on node: host: hadoop-200-3:58063 #containers=0 available=8192 used=0 with event: FINISHED
2013-08-07 09:10:09,435 INFO org.apache.hadoop.yarn.server.resourcemanager.rmapp.attempt.RMAppAttemptImpl: appattempt_1375865942038_0005_000001 State change from RUNNING to FINISHING
2013-08-07 09:10:09,436 INFO org.apache.hadoop.yarn.server.resourcemanager.rmapp.RMAppImpl: application_1375865942038_0005 State change from RUNNING to FINISHING
2013-08-07 09:10:09,973 INFO org.apache.hadoop.yarn.server.resourcemanager.rmcontainer.RMContainerImpl: container_1375865942038_0005_01_000001 Container Transitioned from RUNNING to COMPLETED
2013-08-07 09:10:09,974 INFO org.apache.hadoop.yarn.server.resourcemanager.scheduler.common.fica.FiCaSchedulerApp: Completed container: container_1375865942038_0005_01_000001 in state: COMPLETED event:FINISHED
2013-08-07 09:10:09,974 INFO org.apache.hadoop.yarn.server.resourcemanager.RMAuditLogger: USER=ubuntu	OPERATION=AM Released Container	TARGET=SchedulerApp	RESULT=SUCCESS	APPID=application_1375865942038_0005	CONTAINERID=container_1375865942038_0005_01_000001
2013-08-07 09:10:09,974 INFO org.apache.hadoop.yarn.server.resourcemanager.scheduler.common.fica.FiCaSchedulerNode: Released container container_1375865942038_0005_01_000001 of capacity <memory:2048, vCores:1> on host hadoop-200-5:55554, which currently has 0 containers, <memory:0, vCores:0> used and <memory:8192, vCores:16> available, release resources=true
2013-08-07 09:10:09,974 INFO org.apache.hadoop.yarn.server.resourcemanager.scheduler.capacity.LeafQueue: default used=<memory:0, vCores:0> numContainers=0 user=ubuntu user-resources=<memory:0, vCores:0>
2013-08-07 09:10:09,974 INFO org.apache.hadoop.yarn.server.resourcemanager.rmapp.attempt.RMAppAttemptImpl: appattempt_1375865942038_0005_000001 State change from FINISHING to FINISHED
2013-08-07 09:10:09,974 INFO org.apache.hadoop.yarn.server.resourcemanager.rmapp.RMAppImpl: application_1375865942038_0005 State change from FINISHING to FINISHED
2013-08-07 09:10:09,975 INFO org.apache.hadoop.yarn.server.resourcemanager.RMAuditLogger: USER=ubuntu	OPERATION=Application Finished - Succeeded	TARGET=RMAppManager	RESULT=SUCCESS	APPID=application_1375865942038_0005
2013-08-07 09:10:09,975 INFO org.apache.hadoop.yarn.server.resourcemanager.recovery.RMStateStore: Removing info for app: application_1375865942038_0005
2013-08-07 09:10:09,975 INFO org.apache.hadoop.yarn.server.resourcemanager.RMAppManager$ApplicationSummary: appId=application_1375865942038_0005,name=TeraGen,user=ubuntu,queue=default,state=FINISHED,trackingUrl=hadoop-200-1.novalocal:8088/proxy/application_1375865942038_0005/jobhistory/job/job_1375865942038_0005,appMasterHost=hadoop-200-5,startTime=1375866488155,finishTime=1375866609436
2013-08-07 09:10:09,976 INFO org.apache.hadoop.yarn.server.resourcemanager.scheduler.capacity.LeafQueue: completedContainer container=Container: [ContainerId: container_1375865942038_0005_01_000001, NodeId: hadoop-200-5:55554, NodeHttpAddress: hadoop-200-5:8042, Resource: <memory:2048, vCores:1>, Priority: 0, State: NEW, Token: null, Status: container_id {, app_attempt_id {, application_id {, id: 5, cluster_timestamp: 1375865942038, }, attemptId: 1, }, id: 1, }, state: C_COMPLETE, diagnostics: "", exit_status: 0, ] resource=<memory:2048, vCores:1> queue=default: capacity=1.0, absoluteCapacity=1.0, usedResources=<memory:0, vCores:0>usedCapacity=0.0, absoluteUsedCapacity=0.0, numApps=1, numContainers=0 usedCapacity=0.0 absoluteUsedCapacity=0.0 used=<memory:0, vCores:0> cluster=<memory:49152, vCores:96>
2013-08-07 09:10:09,976 INFO org.apache.hadoop.yarn.server.resourcemanager.scheduler.capacity.ParentQueue: completedContainer queue=root usedCapacity=0.0 absoluteUsedCapacity=0.0 used=<memory:0, vCores:0> cluster=<memory:49152, vCores:96>
2013-08-07 09:10:09,976 INFO org.apache.hadoop.yarn.server.resourcemanager.scheduler.capacity.CapacityScheduler: Application appattempt_1375865942038_0005_000001 released container container_1375865942038_0005_01_000001 on node: host: hadoop-200-5:55554 #containers=0 available=8192 used=0 with event: FINISHED
2013-08-07 09:10:09,976 INFO org.apache.hadoop.yarn.server.resourcemanager.amlauncher.AMLauncher: Cleaning master appattempt_1375865942038_0005_000001
2013-08-07 09:10:10,005 INFO org.apache.hadoop.yarn.server.resourcemanager.scheduler.capacity.CapacityScheduler: Application appattempt_1375865942038_0005_000001 is done. finalState=FINISHED
2013-08-07 09:10:10,006 INFO org.apache.hadoop.yarn.server.resourcemanager.scheduler.AppSchedulingInfo: Application application_1375865942038_0005 requests cleared
2013-08-07 09:10:10,006 INFO org.apache.hadoop.yarn.server.resourcemanager.scheduler.capacity.LeafQueue: Application removed - appId: application_1375865942038_0005 user: ubuntu queue: default #user-pending-applications: 0 #user-active-applications: 0 #queue-pending-applications: 0 #queue-active-applications: 0
2013-08-07 09:10:10,006 INFO org.apache.hadoop.yarn.server.resourcemanager.scheduler.capacity.ParentQueue: Application removed - appId: application_1375865942038_0005 user: ubuntu leaf-queue of parent: root #applications: 0
2013-08-07 09:10:14,386 INFO org.apache.hadoop.yarn.server.resourcemanager.ClientRMService: Allocated new applicationId: 6
2013-08-07 09:10:14,478 INFO org.apache.hadoop.yarn.server.resourcemanager.ClientRMService: Allocated new applicationId: 7
2013-08-07 09:10:15,339 INFO org.apache.hadoop.yarn.server.resourcemanager.ClientRMService: Allocated new applicationId: 8
2013-08-07 09:10:15,537 INFO org.apache.hadoop.yarn.server.resourcemanager.ClientRMService: Allocated new applicationId: 9
2013-08-07 09:10:16,098 INFO org.apache.hadoop.yarn.server.resourcemanager.ClientRMService: Storing Application with id application_1375865942038_0006
2013-08-07 09:10:16,098 INFO org.apache.hadoop.yarn.server.resourcemanager.recovery.RMStateStore: Storing info for app: application_1375865942038_0006
2013-08-07 09:10:16,098 INFO org.apache.hadoop.yarn.server.resourcemanager.ClientRMService: Application with id 6 submitted by user ubuntu
2013-08-07 09:10:16,098 INFO org.apache.hadoop.yarn.server.resourcemanager.RMAuditLogger: USER=ubuntu	IP=192.168.100.2	OPERATION=Submit Application Request	TARGET=ClientRMService	RESULT=SUCCESS	APPID=application_1375865942038_0006
2013-08-07 09:10:16,099 INFO org.apache.hadoop.yarn.server.resourcemanager.rmapp.RMAppImpl: application_1375865942038_0006 State change from NEW to SUBMITTED
2013-08-07 09:10:16,099 INFO org.apache.hadoop.yarn.server.resourcemanager.ApplicationMasterService: Registering appattempt_1375865942038_0006_000001
2013-08-07 09:10:16,099 INFO org.apache.hadoop.yarn.server.resourcemanager.rmapp.attempt.RMAppAttemptImpl: appattempt_1375865942038_0006_000001 State change from NEW to SUBMITTED
2013-08-07 09:10:16,099 INFO org.apache.hadoop.yarn.server.resourcemanager.scheduler.capacity.LeafQueue: Application application_1375865942038_0006 from user: ubuntu activated in queue: default
2013-08-07 09:10:16,100 INFO org.apache.hadoop.yarn.server.resourcemanager.scheduler.capacity.LeafQueue: Application added - appId: application_1375865942038_0006 user: org.apache.hadoop.yarn.server.resourcemanager.scheduler.capacity.LeafQueue$User@3b8c8ad2, leaf-queue: default #user-pending-applications: 0 #user-active-applications: 1 #queue-pending-applications: 0 #queue-active-applications: 1
2013-08-07 09:10:16,100 INFO org.apache.hadoop.yarn.server.resourcemanager.scheduler.capacity.ParentQueue: Application added - appId: application_1375865942038_0006 user: ubuntu leaf-queue of parent: root #applications: 1
2013-08-07 09:10:16,100 INFO org.apache.hadoop.yarn.server.resourcemanager.scheduler.capacity.CapacityScheduler: Application Submission: appattempt_1375865942038_0006_000001, user: ubuntu queue: default: capacity=1.0, absoluteCapacity=1.0, usedResources=<memory:0, vCores:0>usedCapacity=0.0, absoluteUsedCapacity=0.0, numApps=1, numContainers=0, currently active: 1
2013-08-07 09:10:16,100 INFO org.apache.hadoop.yarn.server.resourcemanager.rmapp.attempt.RMAppAttemptImpl: appattempt_1375865942038_0006_000001 State change from SUBMITTED to SCHEDULED
2013-08-07 09:10:16,100 INFO org.apache.hadoop.yarn.server.resourcemanager.rmapp.RMAppImpl: application_1375865942038_0006 State change from SUBMITTED to ACCEPTED
2013-08-07 09:10:16,132 INFO org.apache.hadoop.yarn.server.resourcemanager.rmcontainer.RMContainerImpl: container_1375865942038_0006_01_000001 Container Transitioned from NEW to ALLOCATED
2013-08-07 09:10:16,132 INFO org.apache.hadoop.yarn.server.resourcemanager.RMAuditLogger: USER=ubuntu	OPERATION=AM Allocated Container	TARGET=SchedulerApp	RESULT=SUCCESS	APPID=application_1375865942038_0006	CONTAINERID=container_1375865942038_0006_01_000001
2013-08-07 09:10:16,132 INFO org.apache.hadoop.yarn.server.resourcemanager.scheduler.common.fica.FiCaSchedulerNode: Assigned container container_1375865942038_0006_01_000001 of capacity <memory:2048, vCores:1> on host hadoop-200-6:52835, which currently has 1 containers, <memory:2048, vCores:1> used and <memory:6144, vCores:15> available
2013-08-07 09:10:16,133 INFO org.apache.hadoop.yarn.server.resourcemanager.scheduler.capacity.LeafQueue: assignedContainer application=application_1375865942038_0006 container=Container: [ContainerId: container_1375865942038_0006_01_000001, NodeId: hadoop-200-6:52835, NodeHttpAddress: hadoop-200-6:8042, Resource: <memory:2048, vCores:1>, Priority: 0, State: NEW, Token: null, Status: container_id {, app_attempt_id {, application_id {, id: 6, cluster_timestamp: 1375865942038, }, attemptId: 1, }, id: 1, }, state: C_NEW, ] containerId=container_1375865942038_0006_01_000001 queue=default: capacity=1.0, absoluteCapacity=1.0, usedResources=<memory:0, vCores:0>usedCapacity=0.0, absoluteUsedCapacity=0.0, numApps=1, numContainers=0 usedCapacity=0.0 absoluteUsedCapacity=0.0 used=<memory:0, vCores:0> cluster=<memory:49152, vCores:96>
2013-08-07 09:10:16,134 INFO org.apache.hadoop.yarn.server.resourcemanager.scheduler.capacity.ParentQueue: Re-sorting queues since queue: root.default stats: default: capacity=1.0, absoluteCapacity=1.0, usedResources=<memory:2048, vCores:1>usedCapacity=0.041666668, absoluteUsedCapacity=0.041666668, numApps=1, numContainers=1
2013-08-07 09:10:16,134 INFO org.apache.hadoop.yarn.server.resourcemanager.scheduler.capacity.ParentQueue: assignedContainer queue=root usedCapacity=0.041666668 absoluteUsedCapacity=0.041666668 used=<memory:2048, vCores:1> cluster=<memory:49152, vCores:96>
2013-08-07 09:10:16,134 INFO org.apache.hadoop.yarn.server.resourcemanager.rmcontainer.RMContainerImpl: container_1375865942038_0006_01_000001 Container Transitioned from ALLOCATED to ACQUIRED
2013-08-07 09:10:16,135 INFO org.apache.hadoop.yarn.server.resourcemanager.rmapp.attempt.RMAppAttemptImpl: Storing attempt: AppId: application_1375865942038_0006 AttemptId: appattempt_1375865942038_0006_000001 MasterContainer: Container: [ContainerId: container_1375865942038_0006_01_000001, NodeId: hadoop-200-6:52835, NodeHttpAddress: hadoop-200-6:8042, Resource: <memory:2048, vCores:1>, Priority: 0, State: NEW, Token: null, Status: container_id {, app_attempt_id {, application_id {, id: 6, cluster_timestamp: 1375865942038, }, attemptId: 1, }, id: 1, }, state: C_NEW, ]
2013-08-07 09:10:16,135 INFO org.apache.hadoop.yarn.server.resourcemanager.recovery.RMStateStore: Storing info for attempt: appattempt_1375865942038_0006_000001
2013-08-07 09:10:16,135 INFO org.apache.hadoop.yarn.server.resourcemanager.rmapp.attempt.RMAppAttemptImpl: appattempt_1375865942038_0006_000001 State change from SCHEDULED to ALLOCATED_SAVING
2013-08-07 09:10:16,135 INFO org.apache.hadoop.yarn.server.resourcemanager.rmapp.attempt.RMAppAttemptImpl: appattempt_1375865942038_0006_000001 State change from ALLOCATED_SAVING to ALLOCATED
2013-08-07 09:10:16,136 INFO org.apache.hadoop.yarn.server.resourcemanager.amlauncher.AMLauncher: Launching masterappattempt_1375865942038_0006_000001
2013-08-07 09:10:16,137 INFO org.apache.hadoop.yarn.server.resourcemanager.amlauncher.AMLauncher: Setting up container Container: [ContainerId: container_1375865942038_0006_01_000001, NodeId: hadoop-200-6:52835, NodeHttpAddress: hadoop-200-6:8042, Resource: <memory:2048, vCores:1>, Priority: 0, State: NEW, Token: null, Status: container_id {, app_attempt_id {, application_id {, id: 6, cluster_timestamp: 1375865942038, }, attemptId: 1, }, id: 1, }, state: C_NEW, ] for AM appattempt_1375865942038_0006_000001
2013-08-07 09:10:16,138 INFO org.apache.hadoop.yarn.server.resourcemanager.amlauncher.AMLauncher: Command to launch container container_1375865942038_0006_01_000001 : $JAVA_HOME/bin/java -Dlog4j.configuration=container-log4j.properties -Dyarn.app.mapreduce.container.log.dir=<LOG_DIR> -Dyarn.app.mapreduce.container.log.filesize=0 -Dhadoop.root.logger=INFO,CLA  -Xmx1024m org.apache.hadoop.mapreduce.v2.app.MRAppMaster 1><LOG_DIR>/stdout 2><LOG_DIR>/stderr 
2013-08-07 09:10:16,147 INFO org.apache.hadoop.yarn.server.resourcemanager.ClientRMService: Storing Application with id application_1375865942038_0007
2013-08-07 09:10:16,147 INFO org.apache.hadoop.yarn.server.resourcemanager.recovery.RMStateStore: Storing info for app: application_1375865942038_0007
2013-08-07 09:10:16,147 INFO org.apache.hadoop.yarn.server.resourcemanager.ClientRMService: Application with id 7 submitted by user ubuntu
2013-08-07 09:10:16,147 INFO org.apache.hadoop.yarn.server.resourcemanager.RMAuditLogger: USER=ubuntu	IP=192.168.100.2	OPERATION=Submit Application Request	TARGET=ClientRMService	RESULT=SUCCESS	APPID=application_1375865942038_0007
2013-08-07 09:10:16,147 INFO org.apache.hadoop.yarn.server.resourcemanager.rmapp.RMAppImpl: application_1375865942038_0007 State change from NEW to SUBMITTED
2013-08-07 09:10:16,148 INFO org.apache.hadoop.yarn.server.resourcemanager.ApplicationMasterService: Registering appattempt_1375865942038_0007_000001
2013-08-07 09:10:16,148 INFO org.apache.hadoop.yarn.server.resourcemanager.rmapp.attempt.RMAppAttemptImpl: appattempt_1375865942038_0007_000001 State change from NEW to SUBMITTED
2013-08-07 09:10:16,149 INFO org.apache.hadoop.yarn.server.resourcemanager.scheduler.capacity.LeafQueue: Application application_1375865942038_0007 from user: ubuntu activated in queue: default
2013-08-07 09:10:16,149 INFO org.apache.hadoop.yarn.server.resourcemanager.scheduler.capacity.LeafQueue: Application added - appId: application_1375865942038_0007 user: org.apache.hadoop.yarn.server.resourcemanager.scheduler.capacity.LeafQueue$User@3b8c8ad2, leaf-queue: default #user-pending-applications: 0 #user-active-applications: 2 #queue-pending-applications: 0 #queue-active-applications: 2
2013-08-07 09:10:16,149 INFO org.apache.hadoop.yarn.server.resourcemanager.scheduler.capacity.ParentQueue: Application added - appId: application_1375865942038_0007 user: ubuntu leaf-queue of parent: root #applications: 2
2013-08-07 09:10:16,149 INFO org.apache.hadoop.yarn.server.resourcemanager.scheduler.capacity.CapacityScheduler: Application Submission: appattempt_1375865942038_0007_000001, user: ubuntu queue: default: capacity=1.0, absoluteCapacity=1.0, usedResources=<memory:2048, vCores:1>usedCapacity=0.041666668, absoluteUsedCapacity=0.041666668, numApps=2, numContainers=1, currently active: 2
2013-08-07 09:10:16,149 INFO org.apache.hadoop.yarn.server.resourcemanager.rmapp.attempt.RMAppAttemptImpl: appattempt_1375865942038_0007_000001 State change from SUBMITTED to SCHEDULED
2013-08-07 09:10:16,149 INFO org.apache.hadoop.yarn.server.resourcemanager.rmapp.RMAppImpl: application_1375865942038_0007 State change from SUBMITTED to ACCEPTED
2013-08-07 09:10:16,151 INFO org.apache.hadoop.yarn.server.resourcemanager.amlauncher.AMLauncher: Done launching container Container: [ContainerId: container_1375865942038_0006_01_000001, NodeId: hadoop-200-6:52835, NodeHttpAddress: hadoop-200-6:8042, Resource: <memory:2048, vCores:1>, Priority: 0, State: NEW, Token: null, Status: container_id {, app_attempt_id {, application_id {, id: 6, cluster_timestamp: 1375865942038, }, attemptId: 1, }, id: 1, }, state: C_NEW, ] for AM appattempt_1375865942038_0006_000001
2013-08-07 09:10:16,151 INFO org.apache.hadoop.yarn.server.resourcemanager.rmapp.attempt.RMAppAttemptImpl: appattempt_1375865942038_0006_000001 State change from ALLOCATED to LAUNCHED
2013-08-07 09:10:16,286 INFO org.apache.hadoop.yarn.server.resourcemanager.rmcontainer.RMContainerImpl: container_1375865942038_0007_01_000001 Container Transitioned from NEW to ALLOCATED
2013-08-07 09:10:16,286 INFO org.apache.hadoop.yarn.server.resourcemanager.RMAuditLogger: USER=ubuntu	OPERATION=AM Allocated Container	TARGET=SchedulerApp	RESULT=SUCCESS	APPID=application_1375865942038_0007	CONTAINERID=container_1375865942038_0007_01_000001
2013-08-07 09:10:16,286 INFO org.apache.hadoop.yarn.server.resourcemanager.scheduler.common.fica.FiCaSchedulerNode: Assigned container container_1375865942038_0007_01_000001 of capacity <memory:2048, vCores:1> on host hadoop-200-7:54925, which currently has 1 containers, <memory:2048, vCores:1> used and <memory:6144, vCores:15> available
2013-08-07 09:10:16,287 INFO org.apache.hadoop.yarn.server.resourcemanager.scheduler.capacity.LeafQueue: assignedContainer application=application_1375865942038_0007 container=Container: [ContainerId: container_1375865942038_0007_01_000001, NodeId: hadoop-200-7:54925, NodeHttpAddress: hadoop-200-7:8042, Resource: <memory:2048, vCores:1>, Priority: 0, State: NEW, Token: null, Status: container_id {, app_attempt_id {, application_id {, id: 7, cluster_timestamp: 1375865942038, }, attemptId: 1, }, id: 1, }, state: C_NEW, ] containerId=container_1375865942038_0007_01_000001 queue=default: capacity=1.0, absoluteCapacity=1.0, usedResources=<memory:2048, vCores:1>usedCapacity=0.041666668, absoluteUsedCapacity=0.041666668, numApps=2, numContainers=1 usedCapacity=0.041666668 absoluteUsedCapacity=0.041666668 used=<memory:2048, vCores:1> cluster=<memory:49152, vCores:96>
2013-08-07 09:10:16,287 INFO org.apache.hadoop.yarn.server.resourcemanager.scheduler.capacity.ParentQueue: Re-sorting queues since queue: root.default stats: default: capacity=1.0, absoluteCapacity=1.0, usedResources=<memory:4096, vCores:2>usedCapacity=0.083333336, absoluteUsedCapacity=0.083333336, numApps=2, numContainers=2
2013-08-07 09:10:16,287 INFO org.apache.hadoop.yarn.server.resourcemanager.scheduler.capacity.ParentQueue: assignedContainer queue=root usedCapacity=0.083333336 absoluteUsedCapacity=0.083333336 used=<memory:4096, vCores:2> cluster=<memory:49152, vCores:96>
2013-08-07 09:10:16,288 INFO org.apache.hadoop.yarn.server.resourcemanager.rmcontainer.RMContainerImpl: container_1375865942038_0007_01_000001 Container Transitioned from ALLOCATED to ACQUIRED
2013-08-07 09:10:16,288 INFO org.apache.hadoop.yarn.server.resourcemanager.rmapp.attempt.RMAppAttemptImpl: Storing attempt: AppId: application_1375865942038_0007 AttemptId: appattempt_1375865942038_0007_000001 MasterContainer: Container: [ContainerId: container_1375865942038_0007_01_000001, NodeId: hadoop-200-7:54925, NodeHttpAddress: hadoop-200-7:8042, Resource: <memory:2048, vCores:1>, Priority: 0, State: NEW, Token: null, Status: container_id {, app_attempt_id {, application_id {, id: 7, cluster_timestamp: 1375865942038, }, attemptId: 1, }, id: 1, }, state: C_NEW, ]
2013-08-07 09:10:16,289 INFO org.apache.hadoop.yarn.server.resourcemanager.recovery.RMStateStore: Storing info for attempt: appattempt_1375865942038_0007_000001
2013-08-07 09:10:16,289 INFO org.apache.hadoop.yarn.server.resourcemanager.rmapp.attempt.RMAppAttemptImpl: appattempt_1375865942038_0007_000001 State change from SCHEDULED to ALLOCATED_SAVING
2013-08-07 09:10:16,289 INFO org.apache.hadoop.yarn.server.resourcemanager.rmapp.attempt.RMAppAttemptImpl: appattempt_1375865942038_0007_000001 State change from ALLOCATED_SAVING to ALLOCATED
2013-08-07 09:10:16,289 INFO org.apache.hadoop.yarn.server.resourcemanager.amlauncher.AMLauncher: Launching masterappattempt_1375865942038_0007_000001
2013-08-07 09:10:16,291 INFO org.apache.hadoop.yarn.server.resourcemanager.amlauncher.AMLauncher: Setting up container Container: [ContainerId: container_1375865942038_0007_01_000001, NodeId: hadoop-200-7:54925, NodeHttpAddress: hadoop-200-7:8042, Resource: <memory:2048, vCores:1>, Priority: 0, State: NEW, Token: null, Status: container_id {, app_attempt_id {, application_id {, id: 7, cluster_timestamp: 1375865942038, }, attemptId: 1, }, id: 1, }, state: C_NEW, ] for AM appattempt_1375865942038_0007_000001
2013-08-07 09:10:16,291 INFO org.apache.hadoop.yarn.server.resourcemanager.amlauncher.AMLauncher: Command to launch container container_1375865942038_0007_01_000001 : $JAVA_HOME/bin/java -Dlog4j.configuration=container-log4j.properties -Dyarn.app.mapreduce.container.log.dir=<LOG_DIR> -Dyarn.app.mapreduce.container.log.filesize=0 -Dhadoop.root.logger=INFO,CLA  -Xmx1024m org.apache.hadoop.mapreduce.v2.app.MRAppMaster 1><LOG_DIR>/stdout 2><LOG_DIR>/stderr 
2013-08-07 09:10:16,308 INFO org.apache.hadoop.yarn.server.resourcemanager.amlauncher.AMLauncher: Done launching container Container: [ContainerId: container_1375865942038_0007_01_000001, NodeId: hadoop-200-7:54925, NodeHttpAddress: hadoop-200-7:8042, Resource: <memory:2048, vCores:1>, Priority: 0, State: NEW, Token: null, Status: container_id {, app_attempt_id {, application_id {, id: 7, cluster_timestamp: 1375865942038, }, attemptId: 1, }, id: 1, }, state: C_NEW, ] for AM appattempt_1375865942038_0007_000001
2013-08-07 09:10:16,308 INFO org.apache.hadoop.yarn.server.resourcemanager.rmapp.attempt.RMAppAttemptImpl: appattempt_1375865942038_0007_000001 State change from ALLOCATED to LAUNCHED
2013-08-07 09:10:16,320 INFO org.apache.hadoop.yarn.server.resourcemanager.ClientRMService: Allocated new applicationId: 10
2013-08-07 09:10:16,803 INFO org.apache.hadoop.yarn.server.resourcemanager.ClientRMService: Storing Application with id application_1375865942038_0008
2013-08-07 09:10:16,803 INFO org.apache.hadoop.yarn.server.resourcemanager.recovery.RMStateStore: Storing info for app: application_1375865942038_0008
2013-08-07 09:10:16,803 INFO org.apache.hadoop.yarn.server.resourcemanager.ClientRMService: Application with id 8 submitted by user ubuntu
2013-08-07 09:10:16,803 INFO org.apache.hadoop.yarn.server.resourcemanager.RMAuditLogger: USER=ubuntu	IP=192.168.100.2	OPERATION=Submit Application Request	TARGET=ClientRMService	RESULT=SUCCESS	APPID=application_1375865942038_0008
2013-08-07 09:10:16,803 INFO org.apache.hadoop.yarn.server.resourcemanager.rmapp.RMAppImpl: application_1375865942038_0008 State change from NEW to SUBMITTED
2013-08-07 09:10:16,804 INFO org.apache.hadoop.yarn.server.resourcemanager.ApplicationMasterService: Registering appattempt_1375865942038_0008_000001
2013-08-07 09:10:16,804 INFO org.apache.hadoop.yarn.server.resourcemanager.rmapp.attempt.RMAppAttemptImpl: appattempt_1375865942038_0008_000001 State change from NEW to SUBMITTED
2013-08-07 09:10:16,804 INFO org.apache.hadoop.yarn.server.resourcemanager.scheduler.capacity.LeafQueue: Application application_1375865942038_0008 from user: ubuntu activated in queue: default
2013-08-07 09:10:16,804 INFO org.apache.hadoop.yarn.server.resourcemanager.scheduler.capacity.LeafQueue: Application added - appId: application_1375865942038_0008 user: org.apache.hadoop.yarn.server.resourcemanager.scheduler.capacity.LeafQueue$User@3b8c8ad2, leaf-queue: default #user-pending-applications: 0 #user-active-applications: 3 #queue-pending-applications: 0 #queue-active-applications: 3
2013-08-07 09:10:16,804 INFO org.apache.hadoop.yarn.server.resourcemanager.scheduler.capacity.ParentQueue: Application added - appId: application_1375865942038_0008 user: ubuntu leaf-queue of parent: root #applications: 3
2013-08-07 09:10:16,805 INFO org.apache.hadoop.yarn.server.resourcemanager.scheduler.capacity.CapacityScheduler: Application Submission: appattempt_1375865942038_0008_000001, user: ubuntu queue: default: capacity=1.0, absoluteCapacity=1.0, usedResources=<memory:4096, vCores:2>usedCapacity=0.083333336, absoluteUsedCapacity=0.083333336, numApps=3, numContainers=2, currently active: 3
2013-08-07 09:10:16,805 INFO org.apache.hadoop.yarn.server.resourcemanager.rmapp.attempt.RMAppAttemptImpl: appattempt_1375865942038_0008_000001 State change from SUBMITTED to SCHEDULED
2013-08-07 09:10:16,805 INFO org.apache.hadoop.yarn.server.resourcemanager.rmapp.RMAppImpl: application_1375865942038_0008 State change from SUBMITTED to ACCEPTED
2013-08-07 09:10:16,909 INFO org.apache.hadoop.yarn.server.resourcemanager.rmcontainer.RMContainerImpl: container_1375865942038_0008_01_000001 Container Transitioned from NEW to ALLOCATED
2013-08-07 09:10:16,909 INFO org.apache.hadoop.yarn.server.resourcemanager.RMAuditLogger: USER=ubuntu	OPERATION=AM Allocated Container	TARGET=SchedulerApp	RESULT=SUCCESS	APPID=application_1375865942038_0008	CONTAINERID=container_1375865942038_0008_01_000001
2013-08-07 09:10:16,909 INFO org.apache.hadoop.yarn.server.resourcemanager.scheduler.common.fica.FiCaSchedulerNode: Assigned container container_1375865942038_0008_01_000001 of capacity <memory:2048, vCores:1> on host hadoop-200-2:58832, which currently has 1 containers, <memory:2048, vCores:1> used and <memory:6144, vCores:15> available
2013-08-07 09:10:16,910 INFO org.apache.hadoop.yarn.server.resourcemanager.scheduler.capacity.LeafQueue: assignedContainer application=application_1375865942038_0008 container=Container: [ContainerId: container_1375865942038_0008_01_000001, NodeId: hadoop-200-2:58832, NodeHttpAddress: hadoop-200-2:8042, Resource: <memory:2048, vCores:1>, Priority: 0, State: NEW, Token: null, Status: container_id {, app_attempt_id {, application_id {, id: 8, cluster_timestamp: 1375865942038, }, attemptId: 1, }, id: 1, }, state: C_NEW, ] containerId=container_1375865942038_0008_01_000001 queue=default: capacity=1.0, absoluteCapacity=1.0, usedResources=<memory:4096, vCores:2>usedCapacity=0.083333336, absoluteUsedCapacity=0.083333336, numApps=3, numContainers=2 usedCapacity=0.083333336 absoluteUsedCapacity=0.083333336 used=<memory:4096, vCores:2> cluster=<memory:49152, vCores:96>
2013-08-07 09:10:16,910 INFO org.apache.hadoop.yarn.server.resourcemanager.scheduler.capacity.ParentQueue: Re-sorting queues since queue: root.default stats: default: capacity=1.0, absoluteCapacity=1.0, usedResources=<memory:6144, vCores:3>usedCapacity=0.125, absoluteUsedCapacity=0.125, numApps=3, numContainers=3
2013-08-07 09:10:16,910 INFO org.apache.hadoop.yarn.server.resourcemanager.scheduler.capacity.ParentQueue: assignedContainer queue=root usedCapacity=0.125 absoluteUsedCapacity=0.125 used=<memory:6144, vCores:3> cluster=<memory:49152, vCores:96>
2013-08-07 09:10:16,910 INFO org.apache.hadoop.yarn.server.resourcemanager.rmcontainer.RMContainerImpl: container_1375865942038_0008_01_000001 Container Transitioned from ALLOCATED to ACQUIRED
2013-08-07 09:10:16,912 INFO org.apache.hadoop.yarn.server.resourcemanager.rmapp.attempt.RMAppAttemptImpl: Storing attempt: AppId: application_1375865942038_0008 AttemptId: appattempt_1375865942038_0008_000001 MasterContainer: Container: [ContainerId: container_1375865942038_0008_01_000001, NodeId: hadoop-200-2:58832, NodeHttpAddress: hadoop-200-2:8042, Resource: <memory:2048, vCores:1>, Priority: 0, State: NEW, Token: null, Status: container_id {, app_attempt_id {, application_id {, id: 8, cluster_timestamp: 1375865942038, }, attemptId: 1, }, id: 1, }, state: C_NEW, ]
2013-08-07 09:10:16,912 INFO org.apache.hadoop.yarn.server.resourcemanager.recovery.RMStateStore: Storing info for attempt: appattempt_1375865942038_0008_000001
2013-08-07 09:10:16,912 INFO org.apache.hadoop.yarn.server.resourcemanager.rmapp.attempt.RMAppAttemptImpl: appattempt_1375865942038_0008_000001 State change from SCHEDULED to ALLOCATED_SAVING
2013-08-07 09:10:16,917 INFO org.apache.hadoop.yarn.server.resourcemanager.rmapp.attempt.RMAppAttemptImpl: appattempt_1375865942038_0008_000001 State change from ALLOCATED_SAVING to ALLOCATED
2013-08-07 09:10:16,917 INFO org.apache.hadoop.yarn.server.resourcemanager.amlauncher.AMLauncher: Launching masterappattempt_1375865942038_0008_000001
2013-08-07 09:10:16,919 INFO org.apache.hadoop.yarn.server.resourcemanager.amlauncher.AMLauncher: Setting up container Container: [ContainerId: container_1375865942038_0008_01_000001, NodeId: hadoop-200-2:58832, NodeHttpAddress: hadoop-200-2:8042, Resource: <memory:2048, vCores:1>, Priority: 0, State: NEW, Token: null, Status: container_id {, app_attempt_id {, application_id {, id: 8, cluster_timestamp: 1375865942038, }, attemptId: 1, }, id: 1, }, state: C_NEW, ] for AM appattempt_1375865942038_0008_000001
2013-08-07 09:10:16,919 INFO org.apache.hadoop.yarn.server.resourcemanager.amlauncher.AMLauncher: Command to launch container container_1375865942038_0008_01_000001 : $JAVA_HOME/bin/java -Dlog4j.configuration=container-log4j.properties -Dyarn.app.mapreduce.container.log.dir=<LOG_DIR> -Dyarn.app.mapreduce.container.log.filesize=0 -Dhadoop.root.logger=INFO,CLA  -Xmx1024m org.apache.hadoop.mapreduce.v2.app.MRAppMaster 1><LOG_DIR>/stdout 2><LOG_DIR>/stderr 
2013-08-07 09:10:16,931 INFO org.apache.hadoop.yarn.server.resourcemanager.amlauncher.AMLauncher: Done launching container Container: [ContainerId: container_1375865942038_0008_01_000001, NodeId: hadoop-200-2:58832, NodeHttpAddress: hadoop-200-2:8042, Resource: <memory:2048, vCores:1>, Priority: 0, State: NEW, Token: null, Status: container_id {, app_attempt_id {, application_id {, id: 8, cluster_timestamp: 1375865942038, }, attemptId: 1, }, id: 1, }, state: C_NEW, ] for AM appattempt_1375865942038_0008_000001
2013-08-07 09:10:16,931 INFO org.apache.hadoop.yarn.server.resourcemanager.rmapp.attempt.RMAppAttemptImpl: appattempt_1375865942038_0008_000001 State change from ALLOCATED to LAUNCHED
2013-08-07 09:10:16,989 INFO org.apache.hadoop.yarn.server.resourcemanager.ClientRMService: Storing Application with id application_1375865942038_0009
2013-08-07 09:10:16,989 INFO org.apache.hadoop.yarn.server.resourcemanager.recovery.RMStateStore: Storing info for app: application_1375865942038_0009
2013-08-07 09:10:16,989 INFO org.apache.hadoop.yarn.server.resourcemanager.ClientRMService: Application with id 9 submitted by user ubuntu
2013-08-07 09:10:16,989 INFO org.apache.hadoop.yarn.server.resourcemanager.RMAuditLogger: USER=ubuntu	IP=192.168.100.2	OPERATION=Submit Application Request	TARGET=ClientRMService	RESULT=SUCCESS	APPID=application_1375865942038_0009
2013-08-07 09:10:16,989 INFO org.apache.hadoop.yarn.server.resourcemanager.rmapp.RMAppImpl: application_1375865942038_0009 State change from NEW to SUBMITTED
2013-08-07 09:10:16,990 INFO org.apache.hadoop.yarn.server.resourcemanager.ApplicationMasterService: Registering appattempt_1375865942038_0009_000001
2013-08-07 09:10:16,990 INFO org.apache.hadoop.yarn.server.resourcemanager.rmapp.attempt.RMAppAttemptImpl: appattempt_1375865942038_0009_000001 State change from NEW to SUBMITTED
2013-08-07 09:10:16,990 INFO org.apache.hadoop.yarn.server.resourcemanager.scheduler.capacity.LeafQueue: Application application_1375865942038_0009 from user: ubuntu activated in queue: default
2013-08-07 09:10:16,990 INFO org.apache.hadoop.yarn.server.resourcemanager.scheduler.capacity.LeafQueue: Application added - appId: application_1375865942038_0009 user: org.apache.hadoop.yarn.server.resourcemanager.scheduler.capacity.LeafQueue$User@3b8c8ad2, leaf-queue: default #user-pending-applications: 0 #user-active-applications: 4 #queue-pending-applications: 0 #queue-active-applications: 4
2013-08-07 09:10:16,990 INFO org.apache.hadoop.yarn.server.resourcemanager.scheduler.capacity.ParentQueue: Application added - appId: application_1375865942038_0009 user: ubuntu leaf-queue of parent: root #applications: 4
2013-08-07 09:10:16,990 INFO org.apache.hadoop.yarn.server.resourcemanager.scheduler.capacity.CapacityScheduler: Application Submission: appattempt_1375865942038_0009_000001, user: ubuntu queue: default: capacity=1.0, absoluteCapacity=1.0, usedResources=<memory:6144, vCores:3>usedCapacity=0.125, absoluteUsedCapacity=0.125, numApps=4, numContainers=3, currently active: 4
2013-08-07 09:10:16,991 INFO org.apache.hadoop.yarn.server.resourcemanager.rmapp.attempt.RMAppAttemptImpl: appattempt_1375865942038_0009_000001 State change from SUBMITTED to SCHEDULED
2013-08-07 09:10:16,991 INFO org.apache.hadoop.yarn.server.resourcemanager.rmapp.RMAppImpl: application_1375865942038_0009 State change from SUBMITTED to ACCEPTED
2013-08-07 09:10:17,000 INFO org.apache.hadoop.yarn.server.resourcemanager.rmcontainer.RMContainerImpl: container_1375865942038_0009_01_000001 Container Transitioned from NEW to ALLOCATED
2013-08-07 09:10:17,001 INFO org.apache.hadoop.yarn.server.resourcemanager.RMAuditLogger: USER=ubuntu	OPERATION=AM Allocated Container	TARGET=SchedulerApp	RESULT=SUCCESS	APPID=application_1375865942038_0009	CONTAINERID=container_1375865942038_0009_01_000001
2013-08-07 09:10:17,001 INFO org.apache.hadoop.yarn.server.resourcemanager.scheduler.common.fica.FiCaSchedulerNode: Assigned container container_1375865942038_0009_01_000001 of capacity <memory:2048, vCores:1> on host hadoop-200-5:55554, which currently has 1 containers, <memory:2048, vCores:1> used and <memory:6144, vCores:15> available
2013-08-07 09:10:17,001 INFO org.apache.hadoop.yarn.server.resourcemanager.scheduler.capacity.LeafQueue: assignedContainer application=application_1375865942038_0009 container=Container: [ContainerId: container_1375865942038_0009_01_000001, NodeId: hadoop-200-5:55554, NodeHttpAddress: hadoop-200-5:8042, Resource: <memory:2048, vCores:1>, Priority: 0, State: NEW, Token: null, Status: container_id {, app_attempt_id {, application_id {, id: 9, cluster_timestamp: 1375865942038, }, attemptId: 1, }, id: 1, }, state: C_NEW, ] containerId=container_1375865942038_0009_01_000001 queue=default: capacity=1.0, absoluteCapacity=1.0, usedResources=<memory:6144, vCores:3>usedCapacity=0.125, absoluteUsedCapacity=0.125, numApps=4, numContainers=3 usedCapacity=0.125 absoluteUsedCapacity=0.125 used=<memory:6144, vCores:3> cluster=<memory:49152, vCores:96>
2013-08-07 09:10:17,002 INFO org.apache.hadoop.yarn.server.resourcemanager.scheduler.capacity.ParentQueue: Re-sorting queues since queue: root.default stats: default: capacity=1.0, absoluteCapacity=1.0, usedResources=<memory:8192, vCores:4>usedCapacity=0.16666667, absoluteUsedCapacity=0.16666667, numApps=4, numContainers=4
2013-08-07 09:10:17,006 INFO org.apache.hadoop.yarn.server.resourcemanager.rmcontainer.RMContainerImpl: container_1375865942038_0009_01_000001 Container Transitioned from ALLOCATED to ACQUIRED
2013-08-07 09:10:17,006 INFO org.apache.hadoop.yarn.server.resourcemanager.scheduler.capacity.ParentQueue: assignedContainer queue=root usedCapacity=0.16666667 absoluteUsedCapacity=0.16666667 used=<memory:8192, vCores:4> cluster=<memory:49152, vCores:96>
2013-08-07 09:10:17,007 INFO org.apache.hadoop.yarn.server.resourcemanager.rmapp.attempt.RMAppAttemptImpl: Storing attempt: AppId: application_1375865942038_0009 AttemptId: appattempt_1375865942038_0009_000001 MasterContainer: Container: [ContainerId: container_1375865942038_0009_01_000001, NodeId: hadoop-200-5:55554, NodeHttpAddress: hadoop-200-5:8042, Resource: <memory:2048, vCores:1>, Priority: 0, State: NEW, Token: null, Status: container_id {, app_attempt_id {, application_id {, id: 9, cluster_timestamp: 1375865942038, }, attemptId: 1, }, id: 1, }, state: C_NEW, ]
2013-08-07 09:10:17,007 INFO org.apache.hadoop.yarn.server.resourcemanager.recovery.RMStateStore: Storing info for attempt: appattempt_1375865942038_0009_000001
2013-08-07 09:10:17,007 INFO org.apache.hadoop.yarn.server.resourcemanager.rmapp.attempt.RMAppAttemptImpl: appattempt_1375865942038_0009_000001 State change from SCHEDULED to ALLOCATED_SAVING
2013-08-07 09:10:17,008 INFO org.apache.hadoop.yarn.server.resourcemanager.rmapp.attempt.RMAppAttemptImpl: appattempt_1375865942038_0009_000001 State change from ALLOCATED_SAVING to ALLOCATED
2013-08-07 09:10:17,008 INFO org.apache.hadoop.yarn.server.resourcemanager.amlauncher.AMLauncher: Launching masterappattempt_1375865942038_0009_000001
2013-08-07 09:10:17,009 INFO org.apache.hadoop.yarn.server.resourcemanager.amlauncher.AMLauncher: Setting up container Container: [ContainerId: container_1375865942038_0009_01_000001, NodeId: hadoop-200-5:55554, NodeHttpAddress: hadoop-200-5:8042, Resource: <memory:2048, vCores:1>, Priority: 0, State: NEW, Token: null, Status: container_id {, app_attempt_id {, application_id {, id: 9, cluster_timestamp: 1375865942038, }, attemptId: 1, }, id: 1, }, state: C_NEW, ] for AM appattempt_1375865942038_0009_000001
2013-08-07 09:10:17,009 INFO org.apache.hadoop.yarn.server.resourcemanager.amlauncher.AMLauncher: Command to launch container container_1375865942038_0009_01_000001 : $JAVA_HOME/bin/java -Dlog4j.configuration=container-log4j.properties -Dyarn.app.mapreduce.container.log.dir=<LOG_DIR> -Dyarn.app.mapreduce.container.log.filesize=0 -Dhadoop.root.logger=INFO,CLA  -Xmx1024m org.apache.hadoop.mapreduce.v2.app.MRAppMaster 1><LOG_DIR>/stdout 2><LOG_DIR>/stderr 
2013-08-07 09:10:17,020 INFO org.apache.hadoop.yarn.server.resourcemanager.amlauncher.AMLauncher: Done launching container Container: [ContainerId: container_1375865942038_0009_01_000001, NodeId: hadoop-200-5:55554, NodeHttpAddress: hadoop-200-5:8042, Resource: <memory:2048, vCores:1>, Priority: 0, State: NEW, Token: null, Status: container_id {, app_attempt_id {, application_id {, id: 9, cluster_timestamp: 1375865942038, }, attemptId: 1, }, id: 1, }, state: C_NEW, ] for AM appattempt_1375865942038_0009_000001
2013-08-07 09:10:17,020 INFO org.apache.hadoop.yarn.server.resourcemanager.rmapp.attempt.RMAppAttemptImpl: appattempt_1375865942038_0009_000001 State change from ALLOCATED to LAUNCHED
2013-08-07 09:10:17,136 INFO org.apache.hadoop.yarn.server.resourcemanager.rmcontainer.RMContainerImpl: container_1375865942038_0006_01_000001 Container Transitioned from ACQUIRED to RUNNING
2013-08-07 09:10:17,290 INFO org.apache.hadoop.yarn.server.resourcemanager.rmcontainer.RMContainerImpl: container_1375865942038_0007_01_000001 Container Transitioned from ACQUIRED to RUNNING
2013-08-07 09:10:17,332 INFO org.apache.hadoop.yarn.server.resourcemanager.ClientRMService: Storing Application with id application_1375865942038_0010
2013-08-07 09:10:17,333 INFO org.apache.hadoop.yarn.server.resourcemanager.recovery.RMStateStore: Storing info for app: application_1375865942038_0010
2013-08-07 09:10:17,333 INFO org.apache.hadoop.yarn.server.resourcemanager.ClientRMService: Application with id 10 submitted by user ubuntu
2013-08-07 09:10:17,333 INFO org.apache.hadoop.yarn.server.resourcemanager.RMAuditLogger: USER=ubuntu	IP=192.168.100.2	OPERATION=Submit Application Request	TARGET=ClientRMService	RESULT=SUCCESS	APPID=application_1375865942038_0010
2013-08-07 09:10:17,332 INFO org.apache.hadoop.yarn.server.resourcemanager.rmapp.RMAppImpl: application_1375865942038_0010 State change from NEW to SUBMITTED
2013-08-07 09:10:17,333 INFO org.apache.hadoop.yarn.server.resourcemanager.ApplicationMasterService: Registering appattempt_1375865942038_0010_000001
2013-08-07 09:10:17,333 INFO org.apache.hadoop.yarn.server.resourcemanager.rmapp.attempt.RMAppAttemptImpl: appattempt_1375865942038_0010_000001 State change from NEW to SUBMITTED
2013-08-07 09:10:17,333 INFO org.apache.hadoop.yarn.server.resourcemanager.scheduler.capacity.LeafQueue: Application application_1375865942038_0010 from user: ubuntu activated in queue: default
2013-08-07 09:10:17,334 INFO org.apache.hadoop.yarn.server.resourcemanager.scheduler.capacity.LeafQueue: Application added - appId: application_1375865942038_0010 user: org.apache.hadoop.yarn.server.resourcemanager.scheduler.capacity.LeafQueue$User@3b8c8ad2, leaf-queue: default #user-pending-applications: 0 #user-active-applications: 5 #queue-pending-applications: 0 #queue-active-applications: 5
2013-08-07 09:10:17,334 INFO org.apache.hadoop.yarn.server.resourcemanager.scheduler.capacity.ParentQueue: Application added - appId: application_1375865942038_0010 user: ubuntu leaf-queue of parent: root #applications: 5
2013-08-07 09:10:17,334 INFO org.apache.hadoop.yarn.server.resourcemanager.scheduler.capacity.CapacityScheduler: Application Submission: appattempt_1375865942038_0010_000001, user: ubuntu queue: default: capacity=1.0, absoluteCapacity=1.0, usedResources=<memory:8192, vCores:4>usedCapacity=0.16666667, absoluteUsedCapacity=0.16666667, numApps=5, numContainers=4, currently active: 5
2013-08-07 09:10:17,334 INFO org.apache.hadoop.yarn.server.resourcemanager.rmapp.attempt.RMAppAttemptImpl: appattempt_1375865942038_0010_000001 State change from SUBMITTED to SCHEDULED
2013-08-07 09:10:17,334 INFO org.apache.hadoop.yarn.server.resourcemanager.rmapp.RMAppImpl: application_1375865942038_0010 State change from SUBMITTED to ACCEPTED
2013-08-07 09:10:17,570 INFO org.apache.hadoop.yarn.server.resourcemanager.rmcontainer.RMContainerImpl: container_1375865942038_0010_01_000001 Container Transitioned from NEW to ALLOCATED
2013-08-07 09:10:17,570 INFO org.apache.hadoop.yarn.server.resourcemanager.RMAuditLogger: USER=ubuntu	OPERATION=AM Allocated Container	TARGET=SchedulerApp	RESULT=SUCCESS	APPID=application_1375865942038_0010	CONTAINERID=container_1375865942038_0010_01_000001
2013-08-07 09:10:17,570 INFO org.apache.hadoop.yarn.server.resourcemanager.scheduler.common.fica.FiCaSchedulerNode: Assigned container container_1375865942038_0010_01_000001 of capacity <memory:2048, vCores:1> on host hadoop-200-4:57320, which currently has 1 containers, <memory:2048, vCores:1> used and <memory:6144, vCores:15> available
2013-08-07 09:10:17,571 INFO org.apache.hadoop.yarn.server.resourcemanager.scheduler.capacity.LeafQueue: assignedContainer application=application_1375865942038_0010 container=Container: [ContainerId: container_1375865942038_0010_01_000001, NodeId: hadoop-200-4:57320, NodeHttpAddress: hadoop-200-4:8042, Resource: <memory:2048, vCores:1>, Priority: 0, State: NEW, Token: null, Status: container_id {, app_attempt_id {, application_id {, id: 10, cluster_timestamp: 1375865942038, }, attemptId: 1, }, id: 1, }, state: C_NEW, ] containerId=container_1375865942038_0010_01_000001 queue=default: capacity=1.0, absoluteCapacity=1.0, usedResources=<memory:8192, vCores:4>usedCapacity=0.16666667, absoluteUsedCapacity=0.16666667, numApps=5, numContainers=4 usedCapacity=0.16666667 absoluteUsedCapacity=0.16666667 used=<memory:8192, vCores:4> cluster=<memory:49152, vCores:96>
2013-08-07 09:10:17,571 INFO org.apache.hadoop.yarn.server.resourcemanager.scheduler.capacity.ParentQueue: Re-sorting queues since queue: root.default stats: default: capacity=1.0, absoluteCapacity=1.0, usedResources=<memory:10240, vCores:5>usedCapacity=0.20833333, absoluteUsedCapacity=0.20833333, numApps=5, numContainers=5
2013-08-07 09:10:17,571 INFO org.apache.hadoop.yarn.server.resourcemanager.scheduler.capacity.ParentQueue: assignedContainer queue=root usedCapacity=0.20833333 absoluteUsedCapacity=0.20833333 used=<memory:10240, vCores:5> cluster=<memory:49152, vCores:96>
2013-08-07 09:10:17,572 INFO org.apache.hadoop.yarn.server.resourcemanager.rmcontainer.RMContainerImpl: container_1375865942038_0010_01_000001 Container Transitioned from ALLOCATED to ACQUIRED
2013-08-07 09:10:17,573 INFO org.apache.hadoop.yarn.server.resourcemanager.rmapp.attempt.RMAppAttemptImpl: Storing attempt: AppId: application_1375865942038_0010 AttemptId: appattempt_1375865942038_0010_000001 MasterContainer: Container: [ContainerId: container_1375865942038_0010_01_000001, NodeId: hadoop-200-4:57320, NodeHttpAddress: hadoop-200-4:8042, Resource: <memory:2048, vCores:1>, Priority: 0, State: NEW, Token: null, Status: container_id {, app_attempt_id {, application_id {, id: 10, cluster_timestamp: 1375865942038, }, attemptId: 1, }, id: 1, }, state: C_NEW, ]
2013-08-07 09:10:17,573 INFO org.apache.hadoop.yarn.server.resourcemanager.recovery.RMStateStore: Storing info for attempt: appattempt_1375865942038_0010_000001
2013-08-07 09:10:17,573 INFO org.apache.hadoop.yarn.server.resourcemanager.rmapp.attempt.RMAppAttemptImpl: appattempt_1375865942038_0010_000001 State change from SCHEDULED to ALLOCATED_SAVING
2013-08-07 09:10:17,574 INFO org.apache.hadoop.yarn.server.resourcemanager.rmapp.attempt.RMAppAttemptImpl: appattempt_1375865942038_0010_000001 State change from ALLOCATED_SAVING to ALLOCATED
2013-08-07 09:10:17,574 INFO org.apache.hadoop.yarn.server.resourcemanager.amlauncher.AMLauncher: Launching masterappattempt_1375865942038_0010_000001
2013-08-07 09:10:17,576 INFO org.apache.hadoop.yarn.server.resourcemanager.amlauncher.AMLauncher: Setting up container Container: [ContainerId: container_1375865942038_0010_01_000001, NodeId: hadoop-200-4:57320, NodeHttpAddress: hadoop-200-4:8042, Resource: <memory:2048, vCores:1>, Priority: 0, State: NEW, Token: null, Status: container_id {, app_attempt_id {, application_id {, id: 10, cluster_timestamp: 1375865942038, }, attemptId: 1, }, id: 1, }, state: C_NEW, ] for AM appattempt_1375865942038_0010_000001
2013-08-07 09:10:17,576 INFO org.apache.hadoop.yarn.server.resourcemanager.amlauncher.AMLauncher: Command to launch container container_1375865942038_0010_01_000001 : $JAVA_HOME/bin/java -Dlog4j.configuration=container-log4j.properties -Dyarn.app.mapreduce.container.log.dir=<LOG_DIR> -Dyarn.app.mapreduce.container.log.filesize=0 -Dhadoop.root.logger=INFO,CLA  -Xmx1024m org.apache.hadoop.mapreduce.v2.app.MRAppMaster 1><LOG_DIR>/stdout 2><LOG_DIR>/stderr 
2013-08-07 09:10:17,590 INFO org.apache.hadoop.yarn.server.resourcemanager.amlauncher.AMLauncher: Done launching container Container: [ContainerId: container_1375865942038_0010_01_000001, NodeId: hadoop-200-4:57320, NodeHttpAddress: hadoop-200-4:8042, Resource: <memory:2048, vCores:1>, Priority: 0, State: NEW, Token: null, Status: container_id {, app_attempt_id {, application_id {, id: 10, cluster_timestamp: 1375865942038, }, attemptId: 1, }, id: 1, }, state: C_NEW, ] for AM appattempt_1375865942038_0010_000001
2013-08-07 09:10:17,591 INFO org.apache.hadoop.yarn.server.resourcemanager.rmapp.attempt.RMAppAttemptImpl: appattempt_1375865942038_0010_000001 State change from ALLOCATED to LAUNCHED
2013-08-07 09:10:17,914 INFO org.apache.hadoop.yarn.server.resourcemanager.rmcontainer.RMContainerImpl: container_1375865942038_0008_01_000001 Container Transitioned from ACQUIRED to RUNNING
2013-08-07 09:10:18,001 INFO org.apache.hadoop.yarn.server.resourcemanager.rmcontainer.RMContainerImpl: container_1375865942038_0009_01_000001 Container Transitioned from ACQUIRED to RUNNING
2013-08-07 09:10:18,575 INFO org.apache.hadoop.yarn.server.resourcemanager.rmcontainer.RMContainerImpl: container_1375865942038_0010_01_000001 Container Transitioned from ACQUIRED to RUNNING
2013-08-07 09:10:22,232 INFO org.apache.hadoop.yarn.server.resourcemanager.ApplicationMasterService: AM registration appattempt_1375865942038_0006_000001
2013-08-07 09:10:22,232 INFO org.apache.hadoop.yarn.server.resourcemanager.RMAuditLogger: USER=ubuntu	IP=192.168.100.10	OPERATION=Register App Master	TARGET=ApplicationMasterService	RESULT=SUCCESS	APPID=application_1375865942038_0006	APPATTEMPTID=appattempt_1375865942038_0006_000001
2013-08-07 09:10:22,233 INFO org.apache.hadoop.yarn.server.resourcemanager.rmapp.attempt.RMAppAttemptImpl: appattempt_1375865942038_0006_000001 State change from LAUNCHED to RUNNING
2013-08-07 09:10:22,233 INFO org.apache.hadoop.yarn.server.resourcemanager.rmapp.RMAppImpl: application_1375865942038_0006 State change from ACCEPTED to RUNNING
2013-08-07 09:10:22,633 INFO org.apache.hadoop.yarn.server.resourcemanager.ApplicationMasterService: AM registration appattempt_1375865942038_0010_000001
2013-08-07 09:10:22,634 INFO org.apache.hadoop.yarn.server.resourcemanager.RMAuditLogger: USER=ubuntu	IP=192.168.100.6	OPERATION=Register App Master	TARGET=ApplicationMasterService	RESULT=SUCCESS	APPID=application_1375865942038_0010	APPATTEMPTID=appattempt_1375865942038_0010_000001
2013-08-07 09:10:22,634 INFO org.apache.hadoop.yarn.server.resourcemanager.rmapp.attempt.RMAppAttemptImpl: appattempt_1375865942038_0010_000001 State change from LAUNCHED to RUNNING
2013-08-07 09:10:22,635 INFO org.apache.hadoop.yarn.server.resourcemanager.rmapp.RMAppImpl: application_1375865942038_0010 State change from ACCEPTED to RUNNING
2013-08-07 09:10:23,320 INFO org.apache.hadoop.yarn.server.resourcemanager.rmcontainer.RMContainerImpl: container_1375865942038_0006_01_000002 Container Transitioned from NEW to ALLOCATED
2013-08-07 09:10:23,320 INFO org.apache.hadoop.yarn.server.resourcemanager.RMAuditLogger: USER=ubuntu	OPERATION=AM Allocated Container	TARGET=SchedulerApp	RESULT=SUCCESS	APPID=application_1375865942038_0006	CONTAINERID=container_1375865942038_0006_01_000002
2013-08-07 09:10:23,320 INFO org.apache.hadoop.yarn.server.resourcemanager.scheduler.common.fica.FiCaSchedulerNode: Assigned container container_1375865942038_0006_01_000002 of capacity <memory:1024, vCores:1> on host hadoop-200-7:54925, which currently has 2 containers, <memory:3072, vCores:2> used and <memory:5120, vCores:14> available
2013-08-07 09:10:23,321 INFO org.apache.hadoop.yarn.server.resourcemanager.scheduler.capacity.LeafQueue: assignedContainer application=application_1375865942038_0006 container=Container: [ContainerId: container_1375865942038_0006_01_000002, NodeId: hadoop-200-7:54925, NodeHttpAddress: hadoop-200-7:8042, Resource: <memory:1024, vCores:1>, Priority: 20, State: NEW, Token: null, Status: container_id {, app_attempt_id {, application_id {, id: 6, cluster_timestamp: 1375865942038, }, attemptId: 1, }, id: 2, }, state: C_NEW, ] containerId=container_1375865942038_0006_01_000002 queue=default: capacity=1.0, absoluteCapacity=1.0, usedResources=<memory:10240, vCores:5>usedCapacity=0.20833333, absoluteUsedCapacity=0.20833333, numApps=5, numContainers=5 usedCapacity=0.20833333 absoluteUsedCapacity=0.20833333 used=<memory:10240, vCores:5> cluster=<memory:49152, vCores:96>
2013-08-07 09:10:23,322 INFO org.apache.hadoop.yarn.server.resourcemanager.scheduler.capacity.ParentQueue: Re-sorting queues since queue: root.default stats: default: capacity=1.0, absoluteCapacity=1.0, usedResources=<memory:11264, vCores:6>usedCapacity=0.22916667, absoluteUsedCapacity=0.22916667, numApps=5, numContainers=6
2013-08-07 09:10:23,322 INFO org.apache.hadoop.yarn.server.resourcemanager.scheduler.capacity.ParentQueue: assignedContainer queue=root usedCapacity=0.22916667 absoluteUsedCapacity=0.22916667 used=<memory:11264, vCores:6> cluster=<memory:49152, vCores:96>
2013-08-07 09:10:23,322 INFO org.apache.hadoop.yarn.server.resourcemanager.rmcontainer.RMContainerImpl: container_1375865942038_0006_01_000003 Container Transitioned from NEW to ALLOCATED
2013-08-07 09:10:23,323 INFO org.apache.hadoop.yarn.server.resourcemanager.RMAuditLogger: USER=ubuntu	OPERATION=AM Allocated Container	TARGET=SchedulerApp	RESULT=SUCCESS	APPID=application_1375865942038_0006	CONTAINERID=container_1375865942038_0006_01_000003
2013-08-07 09:10:23,323 INFO org.apache.hadoop.yarn.server.resourcemanager.scheduler.common.fica.FiCaSchedulerNode: Assigned container container_1375865942038_0006_01_000003 of capacity <memory:1024, vCores:1> on host hadoop-200-7:54925, which currently has 3 containers, <memory:4096, vCores:3> used and <memory:4096, vCores:13> available
2013-08-07 09:10:23,324 INFO org.apache.hadoop.yarn.server.resourcemanager.scheduler.capacity.LeafQueue: assignedContainer application=application_1375865942038_0006 container=Container: [ContainerId: container_1375865942038_0006_01_000003, NodeId: hadoop-200-7:54925, NodeHttpAddress: hadoop-200-7:8042, Resource: <memory:1024, vCores:1>, Priority: 20, State: NEW, Token: null, Status: container_id {, app_attempt_id {, application_id {, id: 6, cluster_timestamp: 1375865942038, }, attemptId: 1, }, id: 3, }, state: C_NEW, ] containerId=container_1375865942038_0006_01_000003 queue=default: capacity=1.0, absoluteCapacity=1.0, usedResources=<memory:11264, vCores:6>usedCapacity=0.22916667, absoluteUsedCapacity=0.22916667, numApps=5, numContainers=6 usedCapacity=0.22916667 absoluteUsedCapacity=0.22916667 used=<memory:11264, vCores:6> cluster=<memory:49152, vCores:96>
2013-08-07 09:10:23,324 INFO org.apache.hadoop.yarn.server.resourcemanager.scheduler.capacity.ParentQueue: Re-sorting queues since queue: root.default stats: default: capacity=1.0, absoluteCapacity=1.0, usedResources=<memory:12288, vCores:7>usedCapacity=0.25, absoluteUsedCapacity=0.25, numApps=5, numContainers=7
2013-08-07 09:10:23,324 INFO org.apache.hadoop.yarn.server.resourcemanager.scheduler.capacity.ParentQueue: assignedContainer queue=root usedCapacity=0.25 absoluteUsedCapacity=0.25 used=<memory:12288, vCores:7> cluster=<memory:49152, vCores:96>
2013-08-07 09:10:23,325 INFO org.apache.hadoop.yarn.server.resourcemanager.rmcontainer.RMContainerImpl: container_1375865942038_0006_01_000004 Container Transitioned from NEW to ALLOCATED
2013-08-07 09:10:23,325 INFO org.apache.hadoop.yarn.server.resourcemanager.RMAuditLogger: USER=ubuntu	OPERATION=AM Allocated Container	TARGET=SchedulerApp	RESULT=SUCCESS	APPID=application_1375865942038_0006	CONTAINERID=container_1375865942038_0006_01_000004
2013-08-07 09:10:23,325 INFO org.apache.hadoop.yarn.server.resourcemanager.scheduler.common.fica.FiCaSchedulerNode: Assigned container container_1375865942038_0006_01_000004 of capacity <memory:1024, vCores:1> on host hadoop-200-7:54925, which currently has 4 containers, <memory:5120, vCores:4> used and <memory:3072, vCores:12> available
2013-08-07 09:10:23,326 INFO org.apache.hadoop.yarn.server.resourcemanager.scheduler.capacity.LeafQueue: assignedContainer application=application_1375865942038_0006 container=Container: [ContainerId: container_1375865942038_0006_01_000004, NodeId: hadoop-200-7:54925, NodeHttpAddress: hadoop-200-7:8042, Resource: <memory:1024, vCores:1>, Priority: 20, State: NEW, Token: null, Status: container_id {, app_attempt_id {, application_id {, id: 6, cluster_timestamp: 1375865942038, }, attemptId: 1, }, id: 4, }, state: C_NEW, ] containerId=container_1375865942038_0006_01_000004 queue=default: capacity=1.0, absoluteCapacity=1.0, usedResources=<memory:12288, vCores:7>usedCapacity=0.25, absoluteUsedCapacity=0.25, numApps=5, numContainers=7 usedCapacity=0.25 absoluteUsedCapacity=0.25 used=<memory:12288, vCores:7> cluster=<memory:49152, vCores:96>
2013-08-07 09:10:23,326 INFO org.apache.hadoop.yarn.server.resourcemanager.scheduler.capacity.ParentQueue: Re-sorting queues since queue: root.default stats: default: capacity=1.0, absoluteCapacity=1.0, usedResources=<memory:13312, vCores:8>usedCapacity=0.27083334, absoluteUsedCapacity=0.27083334, numApps=5, numContainers=8
2013-08-07 09:10:23,326 INFO org.apache.hadoop.yarn.server.resourcemanager.scheduler.capacity.ParentQueue: assignedContainer queue=root usedCapacity=0.27083334 absoluteUsedCapacity=0.27083334 used=<memory:13312, vCores:8> cluster=<memory:49152, vCores:96>
2013-08-07 09:10:23,327 INFO org.apache.hadoop.yarn.server.resourcemanager.rmcontainer.RMContainerImpl: container_1375865942038_0006_01_000005 Container Transitioned from NEW to ALLOCATED
2013-08-07 09:10:23,327 INFO org.apache.hadoop.yarn.server.resourcemanager.RMAuditLogger: USER=ubuntu	OPERATION=AM Allocated Container	TARGET=SchedulerApp	RESULT=SUCCESS	APPID=application_1375865942038_0006	CONTAINERID=container_1375865942038_0006_01_000005
2013-08-07 09:10:23,327 INFO org.apache.hadoop.yarn.server.resourcemanager.scheduler.common.fica.FiCaSchedulerNode: Assigned container container_1375865942038_0006_01_000005 of capacity <memory:1024, vCores:1> on host hadoop-200-7:54925, which currently has 5 containers, <memory:6144, vCores:5> used and <memory:2048, vCores:11> available
2013-08-07 09:10:23,328 INFO org.apache.hadoop.yarn.server.resourcemanager.scheduler.capacity.LeafQueue: assignedContainer application=application_1375865942038_0006 container=Container: [ContainerId: container_1375865942038_0006_01_000005, NodeId: hadoop-200-7:54925, NodeHttpAddress: hadoop-200-7:8042, Resource: <memory:1024, vCores:1>, Priority: 20, State: NEW, Token: null, Status: container_id {, app_attempt_id {, application_id {, id: 6, cluster_timestamp: 1375865942038, }, attemptId: 1, }, id: 5, }, state: C_NEW, ] containerId=container_1375865942038_0006_01_000005 queue=default: capacity=1.0, absoluteCapacity=1.0, usedResources=<memory:13312, vCores:8>usedCapacity=0.27083334, absoluteUsedCapacity=0.27083334, numApps=5, numContainers=8 usedCapacity=0.27083334 absoluteUsedCapacity=0.27083334 used=<memory:13312, vCores:8> cluster=<memory:49152, vCores:96>
2013-08-07 09:10:23,328 INFO org.apache.hadoop.yarn.server.resourcemanager.scheduler.capacity.ParentQueue: Re-sorting queues since queue: root.default stats: default: capacity=1.0, absoluteCapacity=1.0, usedResources=<memory:14336, vCores:9>usedCapacity=0.29166666, absoluteUsedCapacity=0.29166666, numApps=5, numContainers=9
2013-08-07 09:10:23,329 INFO org.apache.hadoop.yarn.server.resourcemanager.scheduler.capacity.ParentQueue: assignedContainer queue=root usedCapacity=0.29166666 absoluteUsedCapacity=0.29166666 used=<memory:14336, vCores:9> cluster=<memory:49152, vCores:96>
2013-08-07 09:10:23,329 INFO org.apache.hadoop.yarn.server.resourcemanager.rmcontainer.RMContainerImpl: container_1375865942038_0006_01_000006 Container Transitioned from NEW to ALLOCATED
2013-08-07 09:10:23,329 INFO org.apache.hadoop.yarn.server.resourcemanager.RMAuditLogger: USER=ubuntu	OPERATION=AM Allocated Container	TARGET=SchedulerApp	RESULT=SUCCESS	APPID=application_1375865942038_0006	CONTAINERID=container_1375865942038_0006_01_000006
2013-08-07 09:10:23,329 INFO org.apache.hadoop.yarn.server.resourcemanager.scheduler.common.fica.FiCaSchedulerNode: Assigned container container_1375865942038_0006_01_000006 of capacity <memory:1024, vCores:1> on host hadoop-200-7:54925, which currently has 6 containers, <memory:7168, vCores:6> used and <memory:1024, vCores:10> available
2013-08-07 09:10:23,331 INFO org.apache.hadoop.yarn.server.resourcemanager.scheduler.capacity.LeafQueue: assignedContainer application=application_1375865942038_0006 container=Container: [ContainerId: container_1375865942038_0006_01_000006, NodeId: hadoop-200-7:54925, NodeHttpAddress: hadoop-200-7:8042, Resource: <memory:1024, vCores:1>, Priority: 20, State: NEW, Token: null, Status: container_id {, app_attempt_id {, application_id {, id: 6, cluster_timestamp: 1375865942038, }, attemptId: 1, }, id: 6, }, state: C_NEW, ] containerId=container_1375865942038_0006_01_000006 queue=default: capacity=1.0, absoluteCapacity=1.0, usedResources=<memory:14336, vCores:9>usedCapacity=0.29166666, absoluteUsedCapacity=0.29166666, numApps=5, numContainers=9 usedCapacity=0.29166666 absoluteUsedCapacity=0.29166666 used=<memory:14336, vCores:9> cluster=<memory:49152, vCores:96>
2013-08-07 09:10:23,331 INFO org.apache.hadoop.yarn.server.resourcemanager.scheduler.capacity.ParentQueue: Re-sorting queues since queue: root.default stats: default: capacity=1.0, absoluteCapacity=1.0, usedResources=<memory:15360, vCores:10>usedCapacity=0.3125, absoluteUsedCapacity=0.3125, numApps=5, numContainers=10
2013-08-07 09:10:23,331 INFO org.apache.hadoop.yarn.server.resourcemanager.scheduler.capacity.ParentQueue: assignedContainer queue=root usedCapacity=0.3125 absoluteUsedCapacity=0.3125 used=<memory:15360, vCores:10> cluster=<memory:49152, vCores:96>
2013-08-07 09:10:23,331 INFO org.apache.hadoop.yarn.server.resourcemanager.rmcontainer.RMContainerImpl: container_1375865942038_0006_01_000007 Container Transitioned from NEW to ALLOCATED
2013-08-07 09:10:23,332 INFO org.apache.hadoop.yarn.server.resourcemanager.RMAuditLogger: USER=ubuntu	OPERATION=AM Allocated Container	TARGET=SchedulerApp	RESULT=SUCCESS	APPID=application_1375865942038_0006	CONTAINERID=container_1375865942038_0006_01_000007
2013-08-07 09:10:23,332 INFO org.apache.hadoop.yarn.server.resourcemanager.scheduler.common.fica.FiCaSchedulerNode: Assigned container container_1375865942038_0006_01_000007 of capacity <memory:1024, vCores:1> on host hadoop-200-7:54925, which currently has 7 containers, <memory:8192, vCores:7> used and <memory:0, vCores:9> available
2013-08-07 09:10:23,333 INFO org.apache.hadoop.yarn.server.resourcemanager.scheduler.capacity.LeafQueue: assignedContainer application=application_1375865942038_0006 container=Container: [ContainerId: container_1375865942038_0006_01_000007, NodeId: hadoop-200-7:54925, NodeHttpAddress: hadoop-200-7:8042, Resource: <memory:1024, vCores:1>, Priority: 20, State: NEW, Token: null, Status: container_id {, app_attempt_id {, application_id {, id: 6, cluster_timestamp: 1375865942038, }, attemptId: 1, }, id: 7, }, state: C_NEW, ] containerId=container_1375865942038_0006_01_000007 queue=default: capacity=1.0, absoluteCapacity=1.0, usedResources=<memory:15360, vCores:10>usedCapacity=0.3125, absoluteUsedCapacity=0.3125, numApps=5, numContainers=10 usedCapacity=0.3125 absoluteUsedCapacity=0.3125 used=<memory:15360, vCores:10> cluster=<memory:49152, vCores:96>
2013-08-07 09:10:23,333 INFO org.apache.hadoop.yarn.server.resourcemanager.scheduler.capacity.ParentQueue: Re-sorting queues since queue: root.default stats: default: capacity=1.0, absoluteCapacity=1.0, usedResources=<memory:16384, vCores:11>usedCapacity=0.33333334, absoluteUsedCapacity=0.33333334, numApps=5, numContainers=11
2013-08-07 09:10:23,333 INFO org.apache.hadoop.yarn.server.resourcemanager.scheduler.capacity.ParentQueue: assignedContainer queue=root usedCapacity=0.33333334 absoluteUsedCapacity=0.33333334 used=<memory:16384, vCores:11> cluster=<memory:49152, vCores:96>
2013-08-07 09:10:23,338 INFO org.apache.hadoop.yarn.server.resourcemanager.rmcontainer.RMContainerImpl: container_1375865942038_0006_01_000008 Container Transitioned from NEW to ALLOCATED
2013-08-07 09:10:23,338 INFO org.apache.hadoop.yarn.server.resourcemanager.RMAuditLogger: USER=ubuntu	OPERATION=AM Allocated Container	TARGET=SchedulerApp	RESULT=SUCCESS	APPID=application_1375865942038_0006	CONTAINERID=container_1375865942038_0006_01_000008
2013-08-07 09:10:23,338 INFO org.apache.hadoop.yarn.server.resourcemanager.scheduler.common.fica.FiCaSchedulerNode: Assigned container container_1375865942038_0006_01_000008 of capacity <memory:1024, vCores:1> on host hadoop-200-3:58063, which currently has 1 containers, <memory:1024, vCores:1> used and <memory:7168, vCores:15> available
2013-08-07 09:10:23,339 INFO org.apache.hadoop.yarn.server.resourcemanager.scheduler.capacity.LeafQueue: assignedContainer application=application_1375865942038_0006 container=Container: [ContainerId: container_1375865942038_0006_01_000008, NodeId: hadoop-200-3:58063, NodeHttpAddress: hadoop-200-3:8042, Resource: <memory:1024, vCores:1>, Priority: 20, State: NEW, Token: null, Status: container_id {, app_attempt_id {, application_id {, id: 6, cluster_timestamp: 1375865942038, }, attemptId: 1, }, id: 8, }, state: C_NEW, ] containerId=container_1375865942038_0006_01_000008 queue=default: capacity=1.0, absoluteCapacity=1.0, usedResources=<memory:16384, vCores:11>usedCapacity=0.33333334, absoluteUsedCapacity=0.33333334, numApps=5, numContainers=11 usedCapacity=0.33333334 absoluteUsedCapacity=0.33333334 used=<memory:16384, vCores:11> cluster=<memory:49152, vCores:96>
2013-08-07 09:10:23,339 INFO org.apache.hadoop.yarn.server.resourcemanager.scheduler.capacity.ParentQueue: Re-sorting queues since queue: root.default stats: default: capacity=1.0, absoluteCapacity=1.0, usedResources=<memory:17408, vCores:12>usedCapacity=0.35416666, absoluteUsedCapacity=0.35416666, numApps=5, numContainers=12
2013-08-07 09:10:23,339 INFO org.apache.hadoop.yarn.server.resourcemanager.scheduler.capacity.ParentQueue: assignedContainer queue=root usedCapacity=0.35416666 absoluteUsedCapacity=0.35416666 used=<memory:17408, vCores:12> cluster=<memory:49152, vCores:96>
2013-08-07 09:10:23,340 INFO org.apache.hadoop.yarn.server.resourcemanager.rmcontainer.RMContainerImpl: container_1375865942038_0006_01_000009 Container Transitioned from NEW to ALLOCATED
2013-08-07 09:10:23,340 INFO org.apache.hadoop.yarn.server.resourcemanager.RMAuditLogger: USER=ubuntu	OPERATION=AM Allocated Container	TARGET=SchedulerApp	RESULT=SUCCESS	APPID=application_1375865942038_0006	CONTAINERID=container_1375865942038_0006_01_000009
2013-08-07 09:10:23,340 INFO org.apache.hadoop.yarn.server.resourcemanager.scheduler.common.fica.FiCaSchedulerNode: Assigned container container_1375865942038_0006_01_000009 of capacity <memory:1024, vCores:1> on host hadoop-200-3:58063, which currently has 2 containers, <memory:2048, vCores:2> used and <memory:6144, vCores:14> available
2013-08-07 09:10:23,341 INFO org.apache.hadoop.yarn.server.resourcemanager.scheduler.capacity.LeafQueue: assignedContainer application=application_1375865942038_0006 container=Container: [ContainerId: container_1375865942038_0006_01_000009, NodeId: hadoop-200-3:58063, NodeHttpAddress: hadoop-200-3:8042, Resource: <memory:1024, vCores:1>, Priority: 20, State: NEW, Token: null, Status: container_id {, app_attempt_id {, application_id {, id: 6, cluster_timestamp: 1375865942038, }, attemptId: 1, }, id: 9, }, state: C_NEW, ] containerId=container_1375865942038_0006_01_000009 queue=default: capacity=1.0, absoluteCapacity=1.0, usedResources=<memory:17408, vCores:12>usedCapacity=0.35416666, absoluteUsedCapacity=0.35416666, numApps=5, numContainers=12 usedCapacity=0.35416666 absoluteUsedCapacity=0.35416666 used=<memory:17408, vCores:12> cluster=<memory:49152, vCores:96>
2013-08-07 09:10:23,341 INFO org.apache.hadoop.yarn.server.resourcemanager.scheduler.capacity.ParentQueue: Re-sorting queues since queue: root.default stats: default: capacity=1.0, absoluteCapacity=1.0, usedResources=<memory:18432, vCores:13>usedCapacity=0.375, absoluteUsedCapacity=0.375, numApps=5, numContainers=13
2013-08-07 09:10:23,341 INFO org.apache.hadoop.yarn.server.resourcemanager.scheduler.capacity.ParentQueue: assignedContainer queue=root usedCapacity=0.375 absoluteUsedCapacity=0.375 used=<memory:18432, vCores:13> cluster=<memory:49152, vCores:96>
2013-08-07 09:10:23,342 INFO org.apache.hadoop.yarn.server.resourcemanager.rmcontainer.RMContainerImpl: container_1375865942038_0006_01_000010 Container Transitioned from NEW to ALLOCATED
2013-08-07 09:10:23,342 INFO org.apache.hadoop.yarn.server.resourcemanager.RMAuditLogger: USER=ubuntu	OPERATION=AM Allocated Container	TARGET=SchedulerApp	RESULT=SUCCESS	APPID=application_1375865942038_0006	CONTAINERID=container_1375865942038_0006_01_000010
2013-08-07 09:10:23,342 INFO org.apache.hadoop.yarn.server.resourcemanager.scheduler.common.fica.FiCaSchedulerNode: Assigned container container_1375865942038_0006_01_000010 of capacity <memory:1024, vCores:1> on host hadoop-200-3:58063, which currently has 3 containers, <memory:3072, vCores:3> used and <memory:5120, vCores:13> available
2013-08-07 09:10:23,343 INFO org.apache.hadoop.yarn.server.resourcemanager.scheduler.capacity.LeafQueue: assignedContainer application=application_1375865942038_0006 container=Container: [ContainerId: container_1375865942038_0006_01_000010, NodeId: hadoop-200-3:58063, NodeHttpAddress: hadoop-200-3:8042, Resource: <memory:1024, vCores:1>, Priority: 20, State: NEW, Token: null, Status: container_id {, app_attempt_id {, application_id {, id: 6, cluster_timestamp: 1375865942038, }, attemptId: 1, }, id: 10, }, state: C_NEW, ] containerId=container_1375865942038_0006_01_000010 queue=default: capacity=1.0, absoluteCapacity=1.0, usedResources=<memory:18432, vCores:13>usedCapacity=0.375, absoluteUsedCapacity=0.375, numApps=5, numContainers=13 usedCapacity=0.375 absoluteUsedCapacity=0.375 used=<memory:18432, vCores:13> cluster=<memory:49152, vCores:96>
2013-08-07 09:10:23,344 INFO org.apache.hadoop.yarn.server.resourcemanager.scheduler.capacity.ParentQueue: Re-sorting queues since queue: root.default stats: default: capacity=1.0, absoluteCapacity=1.0, usedResources=<memory:19456, vCores:14>usedCapacity=0.39583334, absoluteUsedCapacity=0.39583334, numApps=5, numContainers=14
2013-08-07 09:10:23,344 INFO org.apache.hadoop.yarn.server.resourcemanager.scheduler.capacity.ParentQueue: assignedContainer queue=root usedCapacity=0.39583334 absoluteUsedCapacity=0.39583334 used=<memory:19456, vCores:14> cluster=<memory:49152, vCores:96>
2013-08-07 09:10:23,344 INFO org.apache.hadoop.yarn.server.resourcemanager.rmcontainer.RMContainerImpl: container_1375865942038_0006_01_000011 Container Transitioned from NEW to ALLOCATED
2013-08-07 09:10:23,344 INFO org.apache.hadoop.yarn.server.resourcemanager.RMAuditLogger: USER=ubuntu	OPERATION=AM Allocated Container	TARGET=SchedulerApp	RESULT=SUCCESS	APPID=application_1375865942038_0006	CONTAINERID=container_1375865942038_0006_01_000011
2013-08-07 09:10:23,344 INFO org.apache.hadoop.yarn.server.resourcemanager.scheduler.common.fica.FiCaSchedulerNode: Assigned container container_1375865942038_0006_01_000011 of capacity <memory:1024, vCores:1> on host hadoop-200-3:58063, which currently has 4 containers, <memory:4096, vCores:4> used and <memory:4096, vCores:12> available
2013-08-07 09:10:23,345 INFO org.apache.hadoop.yarn.server.resourcemanager.scheduler.capacity.LeafQueue: assignedContainer application=application_1375865942038_0006 container=Container: [ContainerId: container_1375865942038_0006_01_000011, NodeId: hadoop-200-3:58063, NodeHttpAddress: hadoop-200-3:8042, Resource: <memory:1024, vCores:1>, Priority: 20, State: NEW, Token: null, Status: container_id {, app_attempt_id {, application_id {, id: 6, cluster_timestamp: 1375865942038, }, attemptId: 1, }, id: 11, }, state: C_NEW, ] containerId=container_1375865942038_0006_01_000011 queue=default: capacity=1.0, absoluteCapacity=1.0, usedResources=<memory:19456, vCores:14>usedCapacity=0.39583334, absoluteUsedCapacity=0.39583334, numApps=5, numContainers=14 usedCapacity=0.39583334 absoluteUsedCapacity=0.39583334 used=<memory:19456, vCores:14> cluster=<memory:49152, vCores:96>
2013-08-07 09:10:23,346 INFO org.apache.hadoop.yarn.server.resourcemanager.scheduler.capacity.ParentQueue: Re-sorting queues since queue: root.default stats: default: capacity=1.0, absoluteCapacity=1.0, usedResources=<memory:20480, vCores:15>usedCapacity=0.41666666, absoluteUsedCapacity=0.41666666, numApps=5, numContainers=15
2013-08-07 09:10:23,346 INFO org.apache.hadoop.yarn.server.resourcemanager.scheduler.capacity.ParentQueue: assignedContainer queue=root usedCapacity=0.41666666 absoluteUsedCapacity=0.41666666 used=<memory:20480, vCores:15> cluster=<memory:49152, vCores:96>
2013-08-07 09:10:23,346 INFO org.apache.hadoop.yarn.server.resourcemanager.rmcontainer.RMContainerImpl: container_1375865942038_0006_01_000012 Container Transitioned from NEW to ALLOCATED
2013-08-07 09:10:23,347 INFO org.apache.hadoop.yarn.server.resourcemanager.RMAuditLogger: USER=ubuntu	OPERATION=AM Allocated Container	TARGET=SchedulerApp	RESULT=SUCCESS	APPID=application_1375865942038_0006	CONTAINERID=container_1375865942038_0006_01_000012
2013-08-07 09:10:23,347 INFO org.apache.hadoop.yarn.server.resourcemanager.scheduler.common.fica.FiCaSchedulerNode: Assigned container container_1375865942038_0006_01_000012 of capacity <memory:1024, vCores:1> on host hadoop-200-3:58063, which currently has 5 containers, <memory:5120, vCores:5> used and <memory:3072, vCores:11> available
2013-08-07 09:10:23,348 INFO org.apache.hadoop.yarn.server.resourcemanager.scheduler.capacity.LeafQueue: assignedContainer application=application_1375865942038_0006 container=Container: [ContainerId: container_1375865942038_0006_01_000012, NodeId: hadoop-200-3:58063, NodeHttpAddress: hadoop-200-3:8042, Resource: <memory:1024, vCores:1>, Priority: 20, State: NEW, Token: null, Status: container_id {, app_attempt_id {, application_id {, id: 6, cluster_timestamp: 1375865942038, }, attemptId: 1, }, id: 12, }, state: C_NEW, ] containerId=container_1375865942038_0006_01_000012 queue=default: capacity=1.0, absoluteCapacity=1.0, usedResources=<memory:20480, vCores:15>usedCapacity=0.41666666, absoluteUsedCapacity=0.41666666, numApps=5, numContainers=15 usedCapacity=0.41666666 absoluteUsedCapacity=0.41666666 used=<memory:20480, vCores:15> cluster=<memory:49152, vCores:96>
2013-08-07 09:10:23,348 INFO org.apache.hadoop.yarn.server.resourcemanager.scheduler.capacity.ParentQueue: Re-sorting queues since queue: root.default stats: default: capacity=1.0, absoluteCapacity=1.0, usedResources=<memory:21504, vCores:16>usedCapacity=0.4375, absoluteUsedCapacity=0.4375, numApps=5, numContainers=16
2013-08-07 09:10:23,348 INFO org.apache.hadoop.yarn.server.resourcemanager.scheduler.capacity.ParentQueue: assignedContainer queue=root usedCapacity=0.4375 absoluteUsedCapacity=0.4375 used=<memory:21504, vCores:16> cluster=<memory:49152, vCores:96>
2013-08-07 09:10:23,349 INFO org.apache.hadoop.yarn.server.resourcemanager.rmcontainer.RMContainerImpl: container_1375865942038_0006_01_000013 Container Transitioned from NEW to ALLOCATED
2013-08-07 09:10:23,349 INFO org.apache.hadoop.yarn.server.resourcemanager.RMAuditLogger: USER=ubuntu	OPERATION=AM Allocated Container	TARGET=SchedulerApp	RESULT=SUCCESS	APPID=application_1375865942038_0006	CONTAINERID=container_1375865942038_0006_01_000013
2013-08-07 09:10:23,349 INFO org.apache.hadoop.yarn.server.resourcemanager.scheduler.common.fica.FiCaSchedulerNode: Assigned container container_1375865942038_0006_01_000013 of capacity <memory:1024, vCores:1> on host hadoop-200-3:58063, which currently has 6 containers, <memory:6144, vCores:6> used and <memory:2048, vCores:10> available
2013-08-07 09:10:23,350 INFO org.apache.hadoop.yarn.server.resourcemanager.scheduler.capacity.LeafQueue: assignedContainer application=application_1375865942038_0006 container=Container: [ContainerId: container_1375865942038_0006_01_000013, NodeId: hadoop-200-3:58063, NodeHttpAddress: hadoop-200-3:8042, Resource: <memory:1024, vCores:1>, Priority: 20, State: NEW, Token: null, Status: container_id {, app_attempt_id {, application_id {, id: 6, cluster_timestamp: 1375865942038, }, attemptId: 1, }, id: 13, }, state: C_NEW, ] containerId=container_1375865942038_0006_01_000013 queue=default: capacity=1.0, absoluteCapacity=1.0, usedResources=<memory:21504, vCores:16>usedCapacity=0.4375, absoluteUsedCapacity=0.4375, numApps=5, numContainers=16 usedCapacity=0.4375 absoluteUsedCapacity=0.4375 used=<memory:21504, vCores:16> cluster=<memory:49152, vCores:96>
2013-08-07 09:10:23,350 INFO org.apache.hadoop.yarn.server.resourcemanager.scheduler.capacity.ParentQueue: Re-sorting queues since queue: root.default stats: default: capacity=1.0, absoluteCapacity=1.0, usedResources=<memory:22528, vCores:17>usedCapacity=0.45833334, absoluteUsedCapacity=0.45833334, numApps=5, numContainers=17
2013-08-07 09:10:23,351 INFO org.apache.hadoop.yarn.server.resourcemanager.scheduler.capacity.ParentQueue: assignedContainer queue=root usedCapacity=0.45833334 absoluteUsedCapacity=0.45833334 used=<memory:22528, vCores:17> cluster=<memory:49152, vCores:96>
2013-08-07 09:10:23,351 INFO org.apache.hadoop.yarn.server.resourcemanager.rmcontainer.RMContainerImpl: container_1375865942038_0006_01_000014 Container Transitioned from NEW to ALLOCATED
2013-08-07 09:10:23,351 INFO org.apache.hadoop.yarn.server.resourcemanager.RMAuditLogger: USER=ubuntu	OPERATION=AM Allocated Container	TARGET=SchedulerApp	RESULT=SUCCESS	APPID=application_1375865942038_0006	CONTAINERID=container_1375865942038_0006_01_000014
2013-08-07 09:10:23,351 INFO org.apache.hadoop.yarn.server.resourcemanager.scheduler.common.fica.FiCaSchedulerNode: Assigned container container_1375865942038_0006_01_000014 of capacity <memory:1024, vCores:1> on host hadoop-200-3:58063, which currently has 7 containers, <memory:7168, vCores:7> used and <memory:1024, vCores:9> available
2013-08-07 09:10:23,352 INFO org.apache.hadoop.yarn.server.resourcemanager.scheduler.capacity.LeafQueue: assignedContainer application=application_1375865942038_0006 container=Container: [ContainerId: container_1375865942038_0006_01_000014, NodeId: hadoop-200-3:58063, NodeHttpAddress: hadoop-200-3:8042, Resource: <memory:1024, vCores:1>, Priority: 20, State: NEW, Token: null, Status: container_id {, app_attempt_id {, application_id {, id: 6, cluster_timestamp: 1375865942038, }, attemptId: 1, }, id: 14, }, state: C_NEW, ] containerId=container_1375865942038_0006_01_000014 queue=default: capacity=1.0, absoluteCapacity=1.0, usedResources=<memory:22528, vCores:17>usedCapacity=0.45833334, absoluteUsedCapacity=0.45833334, numApps=5, numContainers=17 usedCapacity=0.45833334 absoluteUsedCapacity=0.45833334 used=<memory:22528, vCores:17> cluster=<memory:49152, vCores:96>
2013-08-07 09:10:23,353 INFO org.apache.hadoop.yarn.server.resourcemanager.scheduler.capacity.ParentQueue: Re-sorting queues since queue: root.default stats: default: capacity=1.0, absoluteCapacity=1.0, usedResources=<memory:23552, vCores:18>usedCapacity=0.47916666, absoluteUsedCapacity=0.47916666, numApps=5, numContainers=18
2013-08-07 09:10:23,353 INFO org.apache.hadoop.yarn.server.resourcemanager.scheduler.capacity.ParentQueue: assignedContainer queue=root usedCapacity=0.47916666 absoluteUsedCapacity=0.47916666 used=<memory:23552, vCores:18> cluster=<memory:49152, vCores:96>
2013-08-07 09:10:23,353 INFO org.apache.hadoop.yarn.server.resourcemanager.rmcontainer.RMContainerImpl: container_1375865942038_0006_01_000015 Container Transitioned from NEW to ALLOCATED
2013-08-07 09:10:23,353 INFO org.apache.hadoop.yarn.server.resourcemanager.RMAuditLogger: USER=ubuntu	OPERATION=AM Allocated Container	TARGET=SchedulerApp	RESULT=SUCCESS	APPID=application_1375865942038_0006	CONTAINERID=container_1375865942038_0006_01_000015
2013-08-07 09:10:23,354 INFO org.apache.hadoop.yarn.server.resourcemanager.scheduler.common.fica.FiCaSchedulerNode: Assigned container container_1375865942038_0006_01_000015 of capacity <memory:1024, vCores:1> on host hadoop-200-3:58063, which currently has 8 containers, <memory:8192, vCores:8> used and <memory:0, vCores:8> available
2013-08-07 09:10:23,355 INFO org.apache.hadoop.yarn.server.resourcemanager.scheduler.capacity.LeafQueue: assignedContainer application=application_1375865942038_0006 container=Container: [ContainerId: container_1375865942038_0006_01_000015, NodeId: hadoop-200-3:58063, NodeHttpAddress: hadoop-200-3:8042, Resource: <memory:1024, vCores:1>, Priority: 20, State: NEW, Token: null, Status: container_id {, app_attempt_id {, application_id {, id: 6, cluster_timestamp: 1375865942038, }, attemptId: 1, }, id: 15, }, state: C_NEW, ] containerId=container_1375865942038_0006_01_000015 queue=default: capacity=1.0, absoluteCapacity=1.0, usedResources=<memory:23552, vCores:18>usedCapacity=0.47916666, absoluteUsedCapacity=0.47916666, numApps=5, numContainers=18 usedCapacity=0.47916666 absoluteUsedCapacity=0.47916666 used=<memory:23552, vCores:18> cluster=<memory:49152, vCores:96>
2013-08-07 09:10:23,355 INFO org.apache.hadoop.yarn.server.resourcemanager.scheduler.capacity.ParentQueue: Re-sorting queues since queue: root.default stats: default: capacity=1.0, absoluteCapacity=1.0, usedResources=<memory:24576, vCores:19>usedCapacity=0.5, absoluteUsedCapacity=0.5, numApps=5, numContainers=19
2013-08-07 09:10:23,355 INFO org.apache.hadoop.yarn.server.resourcemanager.scheduler.capacity.ParentQueue: assignedContainer queue=root usedCapacity=0.5 absoluteUsedCapacity=0.5 used=<memory:24576, vCores:19> cluster=<memory:49152, vCores:96>
2013-08-07 09:10:23,597 INFO org.apache.hadoop.yarn.server.resourcemanager.rmcontainer.RMContainerImpl: container_1375865942038_0006_01_000016 Container Transitioned from NEW to ALLOCATED
2013-08-07 09:10:23,598 INFO org.apache.hadoop.yarn.server.resourcemanager.RMAuditLogger: USER=ubuntu	OPERATION=AM Allocated Container	TARGET=SchedulerApp	RESULT=SUCCESS	APPID=application_1375865942038_0006	CONTAINERID=container_1375865942038_0006_01_000016
2013-08-07 09:10:23,598 INFO org.apache.hadoop.yarn.server.resourcemanager.scheduler.common.fica.FiCaSchedulerNode: Assigned container container_1375865942038_0006_01_000016 of capacity <memory:1024, vCores:1> on host hadoop-200-4:57320, which currently has 2 containers, <memory:3072, vCores:2> used and <memory:5120, vCores:14> available
2013-08-07 09:10:23,599 INFO org.apache.hadoop.yarn.server.resourcemanager.scheduler.capacity.LeafQueue: assignedContainer application=application_1375865942038_0006 container=Container: [ContainerId: container_1375865942038_0006_01_000016, NodeId: hadoop-200-4:57320, NodeHttpAddress: hadoop-200-4:8042, Resource: <memory:1024, vCores:1>, Priority: 20, State: NEW, Token: null, Status: container_id {, app_attempt_id {, application_id {, id: 6, cluster_timestamp: 1375865942038, }, attemptId: 1, }, id: 16, }, state: C_NEW, ] containerId=container_1375865942038_0006_01_000016 queue=default: capacity=1.0, absoluteCapacity=1.0, usedResources=<memory:24576, vCores:19>usedCapacity=0.5, absoluteUsedCapacity=0.5, numApps=5, numContainers=19 usedCapacity=0.5 absoluteUsedCapacity=0.5 used=<memory:24576, vCores:19> cluster=<memory:49152, vCores:96>
2013-08-07 09:10:23,599 INFO org.apache.hadoop.yarn.server.resourcemanager.scheduler.capacity.ParentQueue: Re-sorting queues since queue: root.default stats: default: capacity=1.0, absoluteCapacity=1.0, usedResources=<memory:25600, vCores:20>usedCapacity=0.5208333, absoluteUsedCapacity=0.5208333, numApps=5, numContainers=20
2013-08-07 09:10:23,599 INFO org.apache.hadoop.yarn.server.resourcemanager.scheduler.capacity.ParentQueue: assignedContainer queue=root usedCapacity=0.5208333 absoluteUsedCapacity=0.5208333 used=<memory:25600, vCores:20> cluster=<memory:49152, vCores:96>
2013-08-07 09:10:23,600 INFO org.apache.hadoop.yarn.server.resourcemanager.rmcontainer.RMContainerImpl: container_1375865942038_0006_01_000017 Container Transitioned from NEW to ALLOCATED
2013-08-07 09:10:23,600 INFO org.apache.hadoop.yarn.server.resourcemanager.RMAuditLogger: USER=ubuntu	OPERATION=AM Allocated Container	TARGET=SchedulerApp	RESULT=SUCCESS	APPID=application_1375865942038_0006	CONTAINERID=container_1375865942038_0006_01_000017
2013-08-07 09:10:23,600 INFO org.apache.hadoop.yarn.server.resourcemanager.scheduler.common.fica.FiCaSchedulerNode: Assigned container container_1375865942038_0006_01_000017 of capacity <memory:1024, vCores:1> on host hadoop-200-4:57320, which currently has 3 containers, <memory:4096, vCores:3> used and <memory:4096, vCores:13> available
2013-08-07 09:10:23,601 INFO org.apache.hadoop.yarn.server.resourcemanager.scheduler.capacity.LeafQueue: assignedContainer application=application_1375865942038_0006 container=Container: [ContainerId: container_1375865942038_0006_01_000017, NodeId: hadoop-200-4:57320, NodeHttpAddress: hadoop-200-4:8042, Resource: <memory:1024, vCores:1>, Priority: 20, State: NEW, Token: null, Status: container_id {, app_attempt_id {, application_id {, id: 6, cluster_timestamp: 1375865942038, }, attemptId: 1, }, id: 17, }, state: C_NEW, ] containerId=container_1375865942038_0006_01_000017 queue=default: capacity=1.0, absoluteCapacity=1.0, usedResources=<memory:25600, vCores:20>usedCapacity=0.5208333, absoluteUsedCapacity=0.5208333, numApps=5, numContainers=20 usedCapacity=0.5208333 absoluteUsedCapacity=0.5208333 used=<memory:25600, vCores:20> cluster=<memory:49152, vCores:96>
2013-08-07 09:10:23,602 INFO org.apache.hadoop.yarn.server.resourcemanager.scheduler.capacity.ParentQueue: Re-sorting queues since queue: root.default stats: default: capacity=1.0, absoluteCapacity=1.0, usedResources=<memory:26624, vCores:21>usedCapacity=0.5416667, absoluteUsedCapacity=0.5416667, numApps=5, numContainers=21
2013-08-07 09:10:23,602 INFO org.apache.hadoop.yarn.server.resourcemanager.scheduler.capacity.ParentQueue: assignedContainer queue=root usedCapacity=0.5416667 absoluteUsedCapacity=0.5416667 used=<memory:26624, vCores:21> cluster=<memory:49152, vCores:96>
2013-08-07 09:10:23,602 INFO org.apache.hadoop.yarn.server.resourcemanager.rmcontainer.RMContainerImpl: container_1375865942038_0006_01_000018 Container Transitioned from NEW to ALLOCATED
2013-08-07 09:10:23,602 INFO org.apache.hadoop.yarn.server.resourcemanager.RMAuditLogger: USER=ubuntu	OPERATION=AM Allocated Container	TARGET=SchedulerApp	RESULT=SUCCESS	APPID=application_1375865942038_0006	CONTAINERID=container_1375865942038_0006_01_000018
2013-08-07 09:10:23,603 INFO org.apache.hadoop.yarn.server.resourcemanager.scheduler.common.fica.FiCaSchedulerNode: Assigned container container_1375865942038_0006_01_000018 of capacity <memory:1024, vCores:1> on host hadoop-200-4:57320, which currently has 4 containers, <memory:5120, vCores:4> used and <memory:3072, vCores:12> available
2013-08-07 09:10:23,604 INFO org.apache.hadoop.yarn.server.resourcemanager.scheduler.capacity.LeafQueue: assignedContainer application=application_1375865942038_0006 container=Container: [ContainerId: container_1375865942038_0006_01_000018, NodeId: hadoop-200-4:57320, NodeHttpAddress: hadoop-200-4:8042, Resource: <memory:1024, vCores:1>, Priority: 20, State: NEW, Token: null, Status: container_id {, app_attempt_id {, application_id {, id: 6, cluster_timestamp: 1375865942038, }, attemptId: 1, }, id: 18, }, state: C_NEW, ] containerId=container_1375865942038_0006_01_000018 queue=default: capacity=1.0, absoluteCapacity=1.0, usedResources=<memory:26624, vCores:21>usedCapacity=0.5416667, absoluteUsedCapacity=0.5416667, numApps=5, numContainers=21 usedCapacity=0.5416667 absoluteUsedCapacity=0.5416667 used=<memory:26624, vCores:21> cluster=<memory:49152, vCores:96>
2013-08-07 09:10:23,604 INFO org.apache.hadoop.yarn.server.resourcemanager.scheduler.capacity.ParentQueue: Re-sorting queues since queue: root.default stats: default: capacity=1.0, absoluteCapacity=1.0, usedResources=<memory:27648, vCores:22>usedCapacity=0.5625, absoluteUsedCapacity=0.5625, numApps=5, numContainers=22
2013-08-07 09:10:23,604 INFO org.apache.hadoop.yarn.server.resourcemanager.scheduler.capacity.ParentQueue: assignedContainer queue=root usedCapacity=0.5625 absoluteUsedCapacity=0.5625 used=<memory:27648, vCores:22> cluster=<memory:49152, vCores:96>
2013-08-07 09:10:23,604 INFO org.apache.hadoop.yarn.server.resourcemanager.rmcontainer.RMContainerImpl: container_1375865942038_0006_01_000019 Container Transitioned from NEW to ALLOCATED
2013-08-07 09:10:23,605 INFO org.apache.hadoop.yarn.server.resourcemanager.RMAuditLogger: USER=ubuntu	OPERATION=AM Allocated Container	TARGET=SchedulerApp	RESULT=SUCCESS	APPID=application_1375865942038_0006	CONTAINERID=container_1375865942038_0006_01_000019
2013-08-07 09:10:23,605 INFO org.apache.hadoop.yarn.server.resourcemanager.scheduler.common.fica.FiCaSchedulerNode: Assigned container container_1375865942038_0006_01_000019 of capacity <memory:1024, vCores:1> on host hadoop-200-4:57320, which currently has 5 containers, <memory:6144, vCores:5> used and <memory:2048, vCores:11> available
2013-08-07 09:10:23,606 INFO org.apache.hadoop.yarn.server.resourcemanager.scheduler.capacity.LeafQueue: assignedContainer application=application_1375865942038_0006 container=Container: [ContainerId: container_1375865942038_0006_01_000019, NodeId: hadoop-200-4:57320, NodeHttpAddress: hadoop-200-4:8042, Resource: <memory:1024, vCores:1>, Priority: 20, State: NEW, Token: null, Status: container_id {, app_attempt_id {, application_id {, id: 6, cluster_timestamp: 1375865942038, }, attemptId: 1, }, id: 19, }, state: C_NEW, ] containerId=container_1375865942038_0006_01_000019 queue=default: capacity=1.0, absoluteCapacity=1.0, usedResources=<memory:27648, vCores:22>usedCapacity=0.5625, absoluteUsedCapacity=0.5625, numApps=5, numContainers=22 usedCapacity=0.5625 absoluteUsedCapacity=0.5625 used=<memory:27648, vCores:22> cluster=<memory:49152, vCores:96>
2013-08-07 09:10:23,606 INFO org.apache.hadoop.yarn.server.resourcemanager.scheduler.capacity.ParentQueue: Re-sorting queues since queue: root.default stats: default: capacity=1.0, absoluteCapacity=1.0, usedResources=<memory:28672, vCores:23>usedCapacity=0.5833333, absoluteUsedCapacity=0.5833333, numApps=5, numContainers=23
2013-08-07 09:10:23,606 INFO org.apache.hadoop.yarn.server.resourcemanager.scheduler.capacity.ParentQueue: assignedContainer queue=root usedCapacity=0.5833333 absoluteUsedCapacity=0.5833333 used=<memory:28672, vCores:23> cluster=<memory:49152, vCores:96>
2013-08-07 09:10:23,607 INFO org.apache.hadoop.yarn.server.resourcemanager.rmcontainer.RMContainerImpl: container_1375865942038_0006_01_000020 Container Transitioned from NEW to ALLOCATED
2013-08-07 09:10:23,607 INFO org.apache.hadoop.yarn.server.resourcemanager.RMAuditLogger: USER=ubuntu	OPERATION=AM Allocated Container	TARGET=SchedulerApp	RESULT=SUCCESS	APPID=application_1375865942038_0006	CONTAINERID=container_1375865942038_0006_01_000020
2013-08-07 09:10:23,607 INFO org.apache.hadoop.yarn.server.resourcemanager.scheduler.common.fica.FiCaSchedulerNode: Assigned container container_1375865942038_0006_01_000020 of capacity <memory:1024, vCores:1> on host hadoop-200-4:57320, which currently has 6 containers, <memory:7168, vCores:6> used and <memory:1024, vCores:10> available
2013-08-07 09:10:23,608 INFO org.apache.hadoop.yarn.server.resourcemanager.scheduler.capacity.LeafQueue: assignedContainer application=application_1375865942038_0006 container=Container: [ContainerId: container_1375865942038_0006_01_000020, NodeId: hadoop-200-4:57320, NodeHttpAddress: hadoop-200-4:8042, Resource: <memory:1024, vCores:1>, Priority: 20, State: NEW, Token: null, Status: container_id {, app_attempt_id {, application_id {, id: 6, cluster_timestamp: 1375865942038, }, attemptId: 1, }, id: 20, }, state: C_NEW, ] containerId=container_1375865942038_0006_01_000020 queue=default: capacity=1.0, absoluteCapacity=1.0, usedResources=<memory:28672, vCores:23>usedCapacity=0.5833333, absoluteUsedCapacity=0.5833333, numApps=5, numContainers=23 usedCapacity=0.5833333 absoluteUsedCapacity=0.5833333 used=<memory:28672, vCores:23> cluster=<memory:49152, vCores:96>
2013-08-07 09:10:23,608 INFO org.apache.hadoop.yarn.server.resourcemanager.scheduler.capacity.ParentQueue: Re-sorting queues since queue: root.default stats: default: capacity=1.0, absoluteCapacity=1.0, usedResources=<memory:29696, vCores:24>usedCapacity=0.6041667, absoluteUsedCapacity=0.6041667, numApps=5, numContainers=24
2013-08-07 09:10:23,608 INFO org.apache.hadoop.yarn.server.resourcemanager.scheduler.capacity.ParentQueue: assignedContainer queue=root usedCapacity=0.6041667 absoluteUsedCapacity=0.6041667 used=<memory:29696, vCores:24> cluster=<memory:49152, vCores:96>
2013-08-07 09:10:23,609 INFO org.apache.hadoop.yarn.server.resourcemanager.rmcontainer.RMContainerImpl: container_1375865942038_0006_01_000021 Container Transitioned from NEW to ALLOCATED
2013-08-07 09:10:23,609 INFO org.apache.hadoop.yarn.server.resourcemanager.RMAuditLogger: USER=ubuntu	OPERATION=AM Allocated Container	TARGET=SchedulerApp	RESULT=SUCCESS	APPID=application_1375865942038_0006	CONTAINERID=container_1375865942038_0006_01_000021
2013-08-07 09:10:23,609 INFO org.apache.hadoop.yarn.server.resourcemanager.scheduler.common.fica.FiCaSchedulerNode: Assigned container container_1375865942038_0006_01_000021 of capacity <memory:1024, vCores:1> on host hadoop-200-4:57320, which currently has 7 containers, <memory:8192, vCores:7> used and <memory:0, vCores:9> available
2013-08-07 09:10:23,610 INFO org.apache.hadoop.yarn.server.resourcemanager.scheduler.capacity.LeafQueue: assignedContainer application=application_1375865942038_0006 container=Container: [ContainerId: container_1375865942038_0006_01_000021, NodeId: hadoop-200-4:57320, NodeHttpAddress: hadoop-200-4:8042, Resource: <memory:1024, vCores:1>, Priority: 20, State: NEW, Token: null, Status: container_id {, app_attempt_id {, application_id {, id: 6, cluster_timestamp: 1375865942038, }, attemptId: 1, }, id: 21, }, state: C_NEW, ] containerId=container_1375865942038_0006_01_000021 queue=default: capacity=1.0, absoluteCapacity=1.0, usedResources=<memory:29696, vCores:24>usedCapacity=0.6041667, absoluteUsedCapacity=0.6041667, numApps=5, numContainers=24 usedCapacity=0.6041667 absoluteUsedCapacity=0.6041667 used=<memory:29696, vCores:24> cluster=<memory:49152, vCores:96>
2013-08-07 09:10:23,610 INFO org.apache.hadoop.yarn.server.resourcemanager.scheduler.capacity.ParentQueue: Re-sorting queues since queue: root.default stats: default: capacity=1.0, absoluteCapacity=1.0, usedResources=<memory:30720, vCores:25>usedCapacity=0.625, absoluteUsedCapacity=0.625, numApps=5, numContainers=25
2013-08-07 09:10:23,611 INFO org.apache.hadoop.yarn.server.resourcemanager.scheduler.capacity.ParentQueue: assignedContainer queue=root usedCapacity=0.625 absoluteUsedCapacity=0.625 used=<memory:30720, vCores:25> cluster=<memory:49152, vCores:96>
2013-08-07 09:10:23,867 INFO org.apache.hadoop.yarn.server.resourcemanager.ApplicationMasterService: AM registration appattempt_1375865942038_0007_000001
2013-08-07 09:10:23,868 INFO org.apache.hadoop.yarn.server.resourcemanager.RMAuditLogger: USER=ubuntu	IP=192.168.100.11	OPERATION=Register App Master	TARGET=ApplicationMasterService	RESULT=SUCCESS	APPID=application_1375865942038_0007	APPATTEMPTID=appattempt_1375865942038_0007_000001
2013-08-07 09:10:23,868 INFO org.apache.hadoop.yarn.server.resourcemanager.rmapp.attempt.RMAppAttemptImpl: appattempt_1375865942038_0007_000001 State change from LAUNCHED to RUNNING
2013-08-07 09:10:23,869 INFO org.apache.hadoop.yarn.server.resourcemanager.rmapp.RMAppImpl: application_1375865942038_0007 State change from ACCEPTED to RUNNING
2013-08-07 09:10:23,945 INFO org.apache.hadoop.yarn.server.resourcemanager.rmcontainer.RMContainerImpl: container_1375865942038_0006_01_000022 Container Transitioned from NEW to ALLOCATED
2013-08-07 09:10:23,945 INFO org.apache.hadoop.yarn.server.resourcemanager.RMAuditLogger: USER=ubuntu	OPERATION=AM Allocated Container	TARGET=SchedulerApp	RESULT=SUCCESS	APPID=application_1375865942038_0006	CONTAINERID=container_1375865942038_0006_01_000022
2013-08-07 09:10:23,946 INFO org.apache.hadoop.yarn.server.resourcemanager.scheduler.common.fica.FiCaSchedulerNode: Assigned container container_1375865942038_0006_01_000022 of capacity <memory:1024, vCores:1> on host hadoop-200-2:58832, which currently has 2 containers, <memory:3072, vCores:2> used and <memory:5120, vCores:14> available
2013-08-07 09:10:23,947 INFO org.apache.hadoop.yarn.server.resourcemanager.scheduler.capacity.LeafQueue: assignedContainer application=application_1375865942038_0006 container=Container: [ContainerId: container_1375865942038_0006_01_000022, NodeId: hadoop-200-2:58832, NodeHttpAddress: hadoop-200-2:8042, Resource: <memory:1024, vCores:1>, Priority: 20, State: NEW, Token: null, Status: container_id {, app_attempt_id {, application_id {, id: 6, cluster_timestamp: 1375865942038, }, attemptId: 1, }, id: 22, }, state: C_NEW, ] containerId=container_1375865942038_0006_01_000022 queue=default: capacity=1.0, absoluteCapacity=1.0, usedResources=<memory:30720, vCores:25>usedCapacity=0.625, absoluteUsedCapacity=0.625, numApps=5, numContainers=25 usedCapacity=0.625 absoluteUsedCapacity=0.625 used=<memory:30720, vCores:25> cluster=<memory:49152, vCores:96>
2013-08-07 09:10:23,947 INFO org.apache.hadoop.yarn.server.resourcemanager.scheduler.capacity.ParentQueue: Re-sorting queues since queue: root.default stats: default: capacity=1.0, absoluteCapacity=1.0, usedResources=<memory:31744, vCores:26>usedCapacity=0.6458333, absoluteUsedCapacity=0.6458333, numApps=5, numContainers=26
2013-08-07 09:10:23,947 INFO org.apache.hadoop.yarn.server.resourcemanager.scheduler.capacity.ParentQueue: assignedContainer queue=root usedCapacity=0.6458333 absoluteUsedCapacity=0.6458333 used=<memory:31744, vCores:26> cluster=<memory:49152, vCores:96>
2013-08-07 09:10:23,948 INFO org.apache.hadoop.yarn.server.resourcemanager.rmcontainer.RMContainerImpl: container_1375865942038_0006_01_000023 Container Transitioned from NEW to ALLOCATED
2013-08-07 09:10:23,948 INFO org.apache.hadoop.yarn.server.resourcemanager.RMAuditLogger: USER=ubuntu	OPERATION=AM Allocated Container	TARGET=SchedulerApp	RESULT=SUCCESS	APPID=application_1375865942038_0006	CONTAINERID=container_1375865942038_0006_01_000023
2013-08-07 09:10:23,948 INFO org.apache.hadoop.yarn.server.resourcemanager.scheduler.common.fica.FiCaSchedulerNode: Assigned container container_1375865942038_0006_01_000023 of capacity <memory:1024, vCores:1> on host hadoop-200-2:58832, which currently has 3 containers, <memory:4096, vCores:3> used and <memory:4096, vCores:13> available
2013-08-07 09:10:23,949 INFO org.apache.hadoop.yarn.server.resourcemanager.scheduler.capacity.LeafQueue: assignedContainer application=application_1375865942038_0006 container=Container: [ContainerId: container_1375865942038_0006_01_000023, NodeId: hadoop-200-2:58832, NodeHttpAddress: hadoop-200-2:8042, Resource: <memory:1024, vCores:1>, Priority: 20, State: NEW, Token: null, Status: container_id {, app_attempt_id {, application_id {, id: 6, cluster_timestamp: 1375865942038, }, attemptId: 1, }, id: 23, }, state: C_NEW, ] containerId=container_1375865942038_0006_01_000023 queue=default: capacity=1.0, absoluteCapacity=1.0, usedResources=<memory:31744, vCores:26>usedCapacity=0.6458333, absoluteUsedCapacity=0.6458333, numApps=5, numContainers=26 usedCapacity=0.6458333 absoluteUsedCapacity=0.6458333 used=<memory:31744, vCores:26> cluster=<memory:49152, vCores:96>
2013-08-07 09:10:23,949 INFO org.apache.hadoop.yarn.server.resourcemanager.scheduler.capacity.ParentQueue: Re-sorting queues since queue: root.default stats: default: capacity=1.0, absoluteCapacity=1.0, usedResources=<memory:32768, vCores:27>usedCapacity=0.6666667, absoluteUsedCapacity=0.6666667, numApps=5, numContainers=27
2013-08-07 09:10:23,949 INFO org.apache.hadoop.yarn.server.resourcemanager.scheduler.capacity.ParentQueue: assignedContainer queue=root usedCapacity=0.6666667 absoluteUsedCapacity=0.6666667 used=<memory:32768, vCores:27> cluster=<memory:49152, vCores:96>
2013-08-07 09:10:23,950 INFO org.apache.hadoop.yarn.server.resourcemanager.rmcontainer.RMContainerImpl: container_1375865942038_0006_01_000024 Container Transitioned from NEW to ALLOCATED
2013-08-07 09:10:23,950 INFO org.apache.hadoop.yarn.server.resourcemanager.RMAuditLogger: USER=ubuntu	OPERATION=AM Allocated Container	TARGET=SchedulerApp	RESULT=SUCCESS	APPID=application_1375865942038_0006	CONTAINERID=container_1375865942038_0006_01_000024
2013-08-07 09:10:23,950 INFO org.apache.hadoop.yarn.server.resourcemanager.scheduler.common.fica.FiCaSchedulerNode: Assigned container container_1375865942038_0006_01_000024 of capacity <memory:1024, vCores:1> on host hadoop-200-2:58832, which currently has 4 containers, <memory:5120, vCores:4> used and <memory:3072, vCores:12> available
2013-08-07 09:10:23,951 INFO org.apache.hadoop.yarn.server.resourcemanager.scheduler.capacity.LeafQueue: assignedContainer application=application_1375865942038_0006 container=Container: [ContainerId: container_1375865942038_0006_01_000024, NodeId: hadoop-200-2:58832, NodeHttpAddress: hadoop-200-2:8042, Resource: <memory:1024, vCores:1>, Priority: 20, State: NEW, Token: null, Status: container_id {, app_attempt_id {, application_id {, id: 6, cluster_timestamp: 1375865942038, }, attemptId: 1, }, id: 24, }, state: C_NEW, ] containerId=container_1375865942038_0006_01_000024 queue=default: capacity=1.0, absoluteCapacity=1.0, usedResources=<memory:32768, vCores:27>usedCapacity=0.6666667, absoluteUsedCapacity=0.6666667, numApps=5, numContainers=27 usedCapacity=0.6666667 absoluteUsedCapacity=0.6666667 used=<memory:32768, vCores:27> cluster=<memory:49152, vCores:96>
2013-08-07 09:10:23,951 INFO org.apache.hadoop.yarn.server.resourcemanager.scheduler.capacity.ParentQueue: Re-sorting queues since queue: root.default stats: default: capacity=1.0, absoluteCapacity=1.0, usedResources=<memory:33792, vCores:28>usedCapacity=0.6875, absoluteUsedCapacity=0.6875, numApps=5, numContainers=28
2013-08-07 09:10:23,952 INFO org.apache.hadoop.yarn.server.resourcemanager.scheduler.capacity.ParentQueue: assignedContainer queue=root usedCapacity=0.6875 absoluteUsedCapacity=0.6875 used=<memory:33792, vCores:28> cluster=<memory:49152, vCores:96>
2013-08-07 09:10:23,952 INFO org.apache.hadoop.yarn.server.resourcemanager.rmcontainer.RMContainerImpl: container_1375865942038_0006_01_000025 Container Transitioned from NEW to ALLOCATED
2013-08-07 09:10:23,952 INFO org.apache.hadoop.yarn.server.resourcemanager.RMAuditLogger: USER=ubuntu	OPERATION=AM Allocated Container	TARGET=SchedulerApp	RESULT=SUCCESS	APPID=application_1375865942038_0006	CONTAINERID=container_1375865942038_0006_01_000025
2013-08-07 09:10:23,952 INFO org.apache.hadoop.yarn.server.resourcemanager.scheduler.common.fica.FiCaSchedulerNode: Assigned container container_1375865942038_0006_01_000025 of capacity <memory:1024, vCores:1> on host hadoop-200-2:58832, which currently has 5 containers, <memory:6144, vCores:5> used and <memory:2048, vCores:11> available
2013-08-07 09:10:23,953 INFO org.apache.hadoop.yarn.server.resourcemanager.scheduler.capacity.LeafQueue: assignedContainer application=application_1375865942038_0006 container=Container: [ContainerId: container_1375865942038_0006_01_000025, NodeId: hadoop-200-2:58832, NodeHttpAddress: hadoop-200-2:8042, Resource: <memory:1024, vCores:1>, Priority: 20, State: NEW, Token: null, Status: container_id {, app_attempt_id {, application_id {, id: 6, cluster_timestamp: 1375865942038, }, attemptId: 1, }, id: 25, }, state: C_NEW, ] containerId=container_1375865942038_0006_01_000025 queue=default: capacity=1.0, absoluteCapacity=1.0, usedResources=<memory:33792, vCores:28>usedCapacity=0.6875, absoluteUsedCapacity=0.6875, numApps=5, numContainers=28 usedCapacity=0.6875 absoluteUsedCapacity=0.6875 used=<memory:33792, vCores:28> cluster=<memory:49152, vCores:96>
2013-08-07 09:10:23,953 INFO org.apache.hadoop.yarn.server.resourcemanager.scheduler.capacity.ParentQueue: Re-sorting queues since queue: root.default stats: default: capacity=1.0, absoluteCapacity=1.0, usedResources=<memory:34816, vCores:29>usedCapacity=0.7083333, absoluteUsedCapacity=0.7083333, numApps=5, numContainers=29
2013-08-07 09:10:23,954 INFO org.apache.hadoop.yarn.server.resourcemanager.scheduler.capacity.ParentQueue: assignedContainer queue=root usedCapacity=0.7083333 absoluteUsedCapacity=0.7083333 used=<memory:34816, vCores:29> cluster=<memory:49152, vCores:96>
2013-08-07 09:10:23,954 INFO org.apache.hadoop.yarn.server.resourcemanager.rmcontainer.RMContainerImpl: container_1375865942038_0006_01_000026 Container Transitioned from NEW to ALLOCATED
2013-08-07 09:10:23,954 INFO org.apache.hadoop.yarn.server.resourcemanager.RMAuditLogger: USER=ubuntu	OPERATION=AM Allocated Container	TARGET=SchedulerApp	RESULT=SUCCESS	APPID=application_1375865942038_0006	CONTAINERID=container_1375865942038_0006_01_000026
2013-08-07 09:10:23,954 INFO org.apache.hadoop.yarn.server.resourcemanager.scheduler.common.fica.FiCaSchedulerNode: Assigned container container_1375865942038_0006_01_000026 of capacity <memory:1024, vCores:1> on host hadoop-200-2:58832, which currently has 6 containers, <memory:7168, vCores:6> used and <memory:1024, vCores:10> available
2013-08-07 09:10:23,955 INFO org.apache.hadoop.yarn.server.resourcemanager.scheduler.capacity.LeafQueue: assignedContainer application=application_1375865942038_0006 container=Container: [ContainerId: container_1375865942038_0006_01_000026, NodeId: hadoop-200-2:58832, NodeHttpAddress: hadoop-200-2:8042, Resource: <memory:1024, vCores:1>, Priority: 20, State: NEW, Token: null, Status: container_id {, app_attempt_id {, application_id {, id: 6, cluster_timestamp: 1375865942038, }, attemptId: 1, }, id: 26, }, state: C_NEW, ] containerId=container_1375865942038_0006_01_000026 queue=default: capacity=1.0, absoluteCapacity=1.0, usedResources=<memory:34816, vCores:29>usedCapacity=0.7083333, absoluteUsedCapacity=0.7083333, numApps=5, numContainers=29 usedCapacity=0.7083333 absoluteUsedCapacity=0.7083333 used=<memory:34816, vCores:29> cluster=<memory:49152, vCores:96>
2013-08-07 09:10:23,956 INFO org.apache.hadoop.yarn.server.resourcemanager.scheduler.capacity.ParentQueue: Re-sorting queues since queue: root.default stats: default: capacity=1.0, absoluteCapacity=1.0, usedResources=<memory:35840, vCores:30>usedCapacity=0.7291667, absoluteUsedCapacity=0.7291667, numApps=5, numContainers=30
2013-08-07 09:10:23,956 INFO org.apache.hadoop.yarn.server.resourcemanager.scheduler.capacity.ParentQueue: assignedContainer queue=root usedCapacity=0.7291667 absoluteUsedCapacity=0.7291667 used=<memory:35840, vCores:30> cluster=<memory:49152, vCores:96>
2013-08-07 09:10:23,956 INFO org.apache.hadoop.yarn.server.resourcemanager.rmcontainer.RMContainerImpl: container_1375865942038_0006_01_000027 Container Transitioned from NEW to ALLOCATED
2013-08-07 09:10:23,957 INFO org.apache.hadoop.yarn.server.resourcemanager.RMAuditLogger: USER=ubuntu	OPERATION=AM Allocated Container	TARGET=SchedulerApp	RESULT=SUCCESS	APPID=application_1375865942038_0006	CONTAINERID=container_1375865942038_0006_01_000027
2013-08-07 09:10:23,957 INFO org.apache.hadoop.yarn.server.resourcemanager.scheduler.common.fica.FiCaSchedulerNode: Assigned container container_1375865942038_0006_01_000027 of capacity <memory:1024, vCores:1> on host hadoop-200-2:58832, which currently has 7 containers, <memory:8192, vCores:7> used and <memory:0, vCores:9> available
2013-08-07 09:10:23,958 INFO org.apache.hadoop.yarn.server.resourcemanager.scheduler.capacity.LeafQueue: assignedContainer application=application_1375865942038_0006 container=Container: [ContainerId: container_1375865942038_0006_01_000027, NodeId: hadoop-200-2:58832, NodeHttpAddress: hadoop-200-2:8042, Resource: <memory:1024, vCores:1>, Priority: 20, State: NEW, Token: null, Status: container_id {, app_attempt_id {, application_id {, id: 6, cluster_timestamp: 1375865942038, }, attemptId: 1, }, id: 27, }, state: C_NEW, ] containerId=container_1375865942038_0006_01_000027 queue=default: capacity=1.0, absoluteCapacity=1.0, usedResources=<memory:35840, vCores:30>usedCapacity=0.7291667, absoluteUsedCapacity=0.7291667, numApps=5, numContainers=30 usedCapacity=0.7291667 absoluteUsedCapacity=0.7291667 used=<memory:35840, vCores:30> cluster=<memory:49152, vCores:96>
2013-08-07 09:10:23,958 INFO org.apache.hadoop.yarn.server.resourcemanager.scheduler.capacity.ParentQueue: Re-sorting queues since queue: root.default stats: default: capacity=1.0, absoluteCapacity=1.0, usedResources=<memory:36864, vCores:31>usedCapacity=0.75, absoluteUsedCapacity=0.75, numApps=5, numContainers=31
2013-08-07 09:10:23,958 INFO org.apache.hadoop.yarn.server.resourcemanager.scheduler.capacity.ParentQueue: assignedContainer queue=root usedCapacity=0.75 absoluteUsedCapacity=0.75 used=<memory:36864, vCores:31> cluster=<memory:49152, vCores:96>
2013-08-07 09:10:23,974 INFO org.apache.hadoop.yarn.server.resourcemanager.ApplicationMasterService: AM registration appattempt_1375865942038_0009_000001
2013-08-07 09:10:23,975 INFO org.apache.hadoop.yarn.server.resourcemanager.RMAuditLogger: USER=ubuntu	IP=192.168.100.8	OPERATION=Register App Master	TARGET=ApplicationMasterService	RESULT=SUCCESS	APPID=application_1375865942038_0009	APPATTEMPTID=appattempt_1375865942038_0009_000001
2013-08-07 09:10:23,976 INFO org.apache.hadoop.yarn.server.resourcemanager.rmapp.attempt.RMAppAttemptImpl: appattempt_1375865942038_0009_000001 State change from LAUNCHED to RUNNING
2013-08-07 09:10:23,976 INFO org.apache.hadoop.yarn.server.resourcemanager.rmapp.RMAppImpl: application_1375865942038_0009 State change from ACCEPTED to RUNNING
2013-08-07 09:10:24,026 INFO org.apache.hadoop.yarn.server.resourcemanager.rmcontainer.RMContainerImpl: container_1375865942038_0006_01_000028 Container Transitioned from NEW to ALLOCATED
2013-08-07 09:10:24,026 INFO org.apache.hadoop.yarn.server.resourcemanager.RMAuditLogger: USER=ubuntu	OPERATION=AM Allocated Container	TARGET=SchedulerApp	RESULT=SUCCESS	APPID=application_1375865942038_0006	CONTAINERID=container_1375865942038_0006_01_000028
2013-08-07 09:10:24,026 INFO org.apache.hadoop.yarn.server.resourcemanager.scheduler.common.fica.FiCaSchedulerNode: Assigned container container_1375865942038_0006_01_000028 of capacity <memory:1024, vCores:1> on host hadoop-200-5:55554, which currently has 2 containers, <memory:3072, vCores:2> used and <memory:5120, vCores:14> available
2013-08-07 09:10:24,027 INFO org.apache.hadoop.yarn.server.resourcemanager.scheduler.capacity.LeafQueue: assignedContainer application=application_1375865942038_0006 container=Container: [ContainerId: container_1375865942038_0006_01_000028, NodeId: hadoop-200-5:55554, NodeHttpAddress: hadoop-200-5:8042, Resource: <memory:1024, vCores:1>, Priority: 20, State: NEW, Token: null, Status: container_id {, app_attempt_id {, application_id {, id: 6, cluster_timestamp: 1375865942038, }, attemptId: 1, }, id: 28, }, state: C_NEW, ] containerId=container_1375865942038_0006_01_000028 queue=default: capacity=1.0, absoluteCapacity=1.0, usedResources=<memory:36864, vCores:31>usedCapacity=0.75, absoluteUsedCapacity=0.75, numApps=5, numContainers=31 usedCapacity=0.75 absoluteUsedCapacity=0.75 used=<memory:36864, vCores:31> cluster=<memory:49152, vCores:96>
2013-08-07 09:10:24,028 INFO org.apache.hadoop.yarn.server.resourcemanager.scheduler.capacity.ParentQueue: Re-sorting queues since queue: root.default stats: default: capacity=1.0, absoluteCapacity=1.0, usedResources=<memory:37888, vCores:32>usedCapacity=0.7708333, absoluteUsedCapacity=0.7708333, numApps=5, numContainers=32
2013-08-07 09:10:24,028 INFO org.apache.hadoop.yarn.server.resourcemanager.scheduler.capacity.ParentQueue: assignedContainer queue=root usedCapacity=0.7708333 absoluteUsedCapacity=0.7708333 used=<memory:37888, vCores:32> cluster=<memory:49152, vCores:96>
2013-08-07 09:10:24,029 INFO org.apache.hadoop.yarn.server.resourcemanager.rmcontainer.RMContainerImpl: container_1375865942038_0006_01_000029 Container Transitioned from NEW to ALLOCATED
2013-08-07 09:10:24,030 INFO org.apache.hadoop.yarn.server.resourcemanager.RMAuditLogger: USER=ubuntu	OPERATION=AM Allocated Container	TARGET=SchedulerApp	RESULT=SUCCESS	APPID=application_1375865942038_0006	CONTAINERID=container_1375865942038_0006_01_000029
2013-08-07 09:10:24,030 INFO org.apache.hadoop.yarn.server.resourcemanager.scheduler.common.fica.FiCaSchedulerNode: Assigned container container_1375865942038_0006_01_000029 of capacity <memory:1024, vCores:1> on host hadoop-200-5:55554, which currently has 3 containers, <memory:4096, vCores:3> used and <memory:4096, vCores:13> available
2013-08-07 09:10:24,031 INFO org.apache.hadoop.yarn.server.resourcemanager.scheduler.capacity.LeafQueue: assignedContainer application=application_1375865942038_0006 container=Container: [ContainerId: container_1375865942038_0006_01_000029, NodeId: hadoop-200-5:55554, NodeHttpAddress: hadoop-200-5:8042, Resource: <memory:1024, vCores:1>, Priority: 20, State: NEW, Token: null, Status: container_id {, app_attempt_id {, application_id {, id: 6, cluster_timestamp: 1375865942038, }, attemptId: 1, }, id: 29, }, state: C_NEW, ] containerId=container_1375865942038_0006_01_000029 queue=default: capacity=1.0, absoluteCapacity=1.0, usedResources=<memory:37888, vCores:32>usedCapacity=0.7708333, absoluteUsedCapacity=0.7708333, numApps=5, numContainers=32 usedCapacity=0.7708333 absoluteUsedCapacity=0.7708333 used=<memory:37888, vCores:32> cluster=<memory:49152, vCores:96>
2013-08-07 09:10:24,031 INFO org.apache.hadoop.yarn.server.resourcemanager.scheduler.capacity.ParentQueue: Re-sorting queues since queue: root.default stats: default: capacity=1.0, absoluteCapacity=1.0, usedResources=<memory:38912, vCores:33>usedCapacity=0.7916667, absoluteUsedCapacity=0.7916667, numApps=5, numContainers=33
2013-08-07 09:10:24,031 INFO org.apache.hadoop.yarn.server.resourcemanager.scheduler.capacity.ParentQueue: assignedContainer queue=root usedCapacity=0.7916667 absoluteUsedCapacity=0.7916667 used=<memory:38912, vCores:33> cluster=<memory:49152, vCores:96>
2013-08-07 09:10:24,032 INFO org.apache.hadoop.yarn.server.resourcemanager.rmcontainer.RMContainerImpl: container_1375865942038_0006_01_000030 Container Transitioned from NEW to ALLOCATED
2013-08-07 09:10:24,032 INFO org.apache.hadoop.yarn.server.resourcemanager.RMAuditLogger: USER=ubuntu	OPERATION=AM Allocated Container	TARGET=SchedulerApp	RESULT=SUCCESS	APPID=application_1375865942038_0006	CONTAINERID=container_1375865942038_0006_01_000030
2013-08-07 09:10:24,032 INFO org.apache.hadoop.yarn.server.resourcemanager.scheduler.common.fica.FiCaSchedulerNode: Assigned container container_1375865942038_0006_01_000030 of capacity <memory:1024, vCores:1> on host hadoop-200-5:55554, which currently has 4 containers, <memory:5120, vCores:4> used and <memory:3072, vCores:12> available
2013-08-07 09:10:24,033 INFO org.apache.hadoop.yarn.server.resourcemanager.scheduler.capacity.LeafQueue: assignedContainer application=application_1375865942038_0006 container=Container: [ContainerId: container_1375865942038_0006_01_000030, NodeId: hadoop-200-5:55554, NodeHttpAddress: hadoop-200-5:8042, Resource: <memory:1024, vCores:1>, Priority: 20, State: NEW, Token: null, Status: container_id {, app_attempt_id {, application_id {, id: 6, cluster_timestamp: 1375865942038, }, attemptId: 1, }, id: 30, }, state: C_NEW, ] containerId=container_1375865942038_0006_01_000030 queue=default: capacity=1.0, absoluteCapacity=1.0, usedResources=<memory:38912, vCores:33>usedCapacity=0.7916667, absoluteUsedCapacity=0.7916667, numApps=5, numContainers=33 usedCapacity=0.7916667 absoluteUsedCapacity=0.7916667 used=<memory:38912, vCores:33> cluster=<memory:49152, vCores:96>
2013-08-07 09:10:24,033 INFO org.apache.hadoop.yarn.server.resourcemanager.scheduler.capacity.ParentQueue: Re-sorting queues since queue: root.default stats: default: capacity=1.0, absoluteCapacity=1.0, usedResources=<memory:39936, vCores:34>usedCapacity=0.8125, absoluteUsedCapacity=0.8125, numApps=5, numContainers=34
2013-08-07 09:10:24,033 INFO org.apache.hadoop.yarn.server.resourcemanager.scheduler.capacity.ParentQueue: assignedContainer queue=root usedCapacity=0.8125 absoluteUsedCapacity=0.8125 used=<memory:39936, vCores:34> cluster=<memory:49152, vCores:96>
2013-08-07 09:10:24,034 INFO org.apache.hadoop.yarn.server.resourcemanager.rmcontainer.RMContainerImpl: container_1375865942038_0006_01_000031 Container Transitioned from NEW to ALLOCATED
2013-08-07 09:10:24,034 INFO org.apache.hadoop.yarn.server.resourcemanager.RMAuditLogger: USER=ubuntu	OPERATION=AM Allocated Container	TARGET=SchedulerApp	RESULT=SUCCESS	APPID=application_1375865942038_0006	CONTAINERID=container_1375865942038_0006_01_000031
2013-08-07 09:10:24,034 INFO org.apache.hadoop.yarn.server.resourcemanager.scheduler.common.fica.FiCaSchedulerNode: Assigned container container_1375865942038_0006_01_000031 of capacity <memory:1024, vCores:1> on host hadoop-200-5:55554, which currently has 5 containers, <memory:6144, vCores:5> used and <memory:2048, vCores:11> available
2013-08-07 09:10:24,035 INFO org.apache.hadoop.yarn.server.resourcemanager.scheduler.capacity.LeafQueue: assignedContainer application=application_1375865942038_0006 container=Container: [ContainerId: container_1375865942038_0006_01_000031, NodeId: hadoop-200-5:55554, NodeHttpAddress: hadoop-200-5:8042, Resource: <memory:1024, vCores:1>, Priority: 20, State: NEW, Token: null, Status: container_id {, app_attempt_id {, application_id {, id: 6, cluster_timestamp: 1375865942038, }, attemptId: 1, }, id: 31, }, state: C_NEW, ] containerId=container_1375865942038_0006_01_000031 queue=default: capacity=1.0, absoluteCapacity=1.0, usedResources=<memory:39936, vCores:34>usedCapacity=0.8125, absoluteUsedCapacity=0.8125, numApps=5, numContainers=34 usedCapacity=0.8125 absoluteUsedCapacity=0.8125 used=<memory:39936, vCores:34> cluster=<memory:49152, vCores:96>
2013-08-07 09:10:24,035 INFO org.apache.hadoop.yarn.server.resourcemanager.scheduler.capacity.ParentQueue: Re-sorting queues since queue: root.default stats: default: capacity=1.0, absoluteCapacity=1.0, usedResources=<memory:40960, vCores:35>usedCapacity=0.8333333, absoluteUsedCapacity=0.8333333, numApps=5, numContainers=35
2013-08-07 09:10:24,035 INFO org.apache.hadoop.yarn.server.resourcemanager.scheduler.capacity.ParentQueue: assignedContainer queue=root usedCapacity=0.8333333 absoluteUsedCapacity=0.8333333 used=<memory:40960, vCores:35> cluster=<memory:49152, vCores:96>
2013-08-07 09:10:24,036 INFO org.apache.hadoop.yarn.server.resourcemanager.rmcontainer.RMContainerImpl: container_1375865942038_0006_01_000032 Container Transitioned from NEW to ALLOCATED
2013-08-07 09:10:24,036 INFO org.apache.hadoop.yarn.server.resourcemanager.RMAuditLogger: USER=ubuntu	OPERATION=AM Allocated Container	TARGET=SchedulerApp	RESULT=SUCCESS	APPID=application_1375865942038_0006	CONTAINERID=container_1375865942038_0006_01_000032
2013-08-07 09:10:24,036 INFO org.apache.hadoop.yarn.server.resourcemanager.scheduler.common.fica.FiCaSchedulerNode: Assigned container container_1375865942038_0006_01_000032 of capacity <memory:1024, vCores:1> on host hadoop-200-5:55554, which currently has 6 containers, <memory:7168, vCores:6> used and <memory:1024, vCores:10> available
2013-08-07 09:10:24,037 INFO org.apache.hadoop.yarn.server.resourcemanager.scheduler.capacity.LeafQueue: assignedContainer application=application_1375865942038_0006 container=Container: [ContainerId: container_1375865942038_0006_01_000032, NodeId: hadoop-200-5:55554, NodeHttpAddress: hadoop-200-5:8042, Resource: <memory:1024, vCores:1>, Priority: 20, State: NEW, Token: null, Status: container_id {, app_attempt_id {, application_id {, id: 6, cluster_timestamp: 1375865942038, }, attemptId: 1, }, id: 32, }, state: C_NEW, ] containerId=container_1375865942038_0006_01_000032 queue=default: capacity=1.0, absoluteCapacity=1.0, usedResources=<memory:40960, vCores:35>usedCapacity=0.8333333, absoluteUsedCapacity=0.8333333, numApps=5, numContainers=35 usedCapacity=0.8333333 absoluteUsedCapacity=0.8333333 used=<memory:40960, vCores:35> cluster=<memory:49152, vCores:96>
2013-08-07 09:10:24,038 INFO org.apache.hadoop.yarn.server.resourcemanager.scheduler.capacity.ParentQueue: Re-sorting queues since queue: root.default stats: default: capacity=1.0, absoluteCapacity=1.0, usedResources=<memory:41984, vCores:36>usedCapacity=0.8541667, absoluteUsedCapacity=0.8541667, numApps=5, numContainers=36
2013-08-07 09:10:24,038 INFO org.apache.hadoop.yarn.server.resourcemanager.scheduler.capacity.ParentQueue: assignedContainer queue=root usedCapacity=0.8541667 absoluteUsedCapacity=0.8541667 used=<memory:41984, vCores:36> cluster=<memory:49152, vCores:96>
2013-08-07 09:10:24,038 INFO org.apache.hadoop.yarn.server.resourcemanager.rmcontainer.RMContainerImpl: container_1375865942038_0006_01_000033 Container Transitioned from NEW to ALLOCATED
2013-08-07 09:10:24,038 INFO org.apache.hadoop.yarn.server.resourcemanager.RMAuditLogger: USER=ubuntu	OPERATION=AM Allocated Container	TARGET=SchedulerApp	RESULT=SUCCESS	APPID=application_1375865942038_0006	CONTAINERID=container_1375865942038_0006_01_000033
2013-08-07 09:10:24,038 INFO org.apache.hadoop.yarn.server.resourcemanager.scheduler.common.fica.FiCaSchedulerNode: Assigned container container_1375865942038_0006_01_000033 of capacity <memory:1024, vCores:1> on host hadoop-200-5:55554, which currently has 7 containers, <memory:8192, vCores:7> used and <memory:0, vCores:9> available
2013-08-07 09:10:24,039 INFO org.apache.hadoop.yarn.server.resourcemanager.scheduler.capacity.LeafQueue: assignedContainer application=application_1375865942038_0006 container=Container: [ContainerId: container_1375865942038_0006_01_000033, NodeId: hadoop-200-5:55554, NodeHttpAddress: hadoop-200-5:8042, Resource: <memory:1024, vCores:1>, Priority: 20, State: NEW, Token: null, Status: container_id {, app_attempt_id {, application_id {, id: 6, cluster_timestamp: 1375865942038, }, attemptId: 1, }, id: 33, }, state: C_NEW, ] containerId=container_1375865942038_0006_01_000033 queue=default: capacity=1.0, absoluteCapacity=1.0, usedResources=<memory:41984, vCores:36>usedCapacity=0.8541667, absoluteUsedCapacity=0.8541667, numApps=5, numContainers=36 usedCapacity=0.8541667 absoluteUsedCapacity=0.8541667 used=<memory:41984, vCores:36> cluster=<memory:49152, vCores:96>
2013-08-07 09:10:24,040 INFO org.apache.hadoop.yarn.server.resourcemanager.scheduler.capacity.ParentQueue: Re-sorting queues since queue: root.default stats: default: capacity=1.0, absoluteCapacity=1.0, usedResources=<memory:43008, vCores:37>usedCapacity=0.875, absoluteUsedCapacity=0.875, numApps=5, numContainers=37
2013-08-07 09:10:24,040 INFO org.apache.hadoop.yarn.server.resourcemanager.scheduler.capacity.ParentQueue: assignedContainer queue=root usedCapacity=0.875 absoluteUsedCapacity=0.875 used=<memory:43008, vCores:37> cluster=<memory:49152, vCores:96>
2013-08-07 09:10:24,166 INFO org.apache.hadoop.yarn.server.resourcemanager.rmcontainer.RMContainerImpl: container_1375865942038_0006_01_000034 Container Transitioned from NEW to ALLOCATED
2013-08-07 09:10:24,167 INFO org.apache.hadoop.yarn.server.resourcemanager.RMAuditLogger: USER=ubuntu	OPERATION=AM Allocated Container	TARGET=SchedulerApp	RESULT=SUCCESS	APPID=application_1375865942038_0006	CONTAINERID=container_1375865942038_0006_01_000034
2013-08-07 09:10:24,167 INFO org.apache.hadoop.yarn.server.resourcemanager.scheduler.common.fica.FiCaSchedulerNode: Assigned container container_1375865942038_0006_01_000034 of capacity <memory:1024, vCores:1> on host hadoop-200-6:52835, which currently has 2 containers, <memory:3072, vCores:2> used and <memory:5120, vCores:14> available
2013-08-07 09:10:24,168 INFO org.apache.hadoop.yarn.server.resourcemanager.scheduler.capacity.LeafQueue: assignedContainer application=application_1375865942038_0006 container=Container: [ContainerId: container_1375865942038_0006_01_000034, NodeId: hadoop-200-6:52835, NodeHttpAddress: hadoop-200-6:8042, Resource: <memory:1024, vCores:1>, Priority: 20, State: NEW, Token: null, Status: container_id {, app_attempt_id {, application_id {, id: 6, cluster_timestamp: 1375865942038, }, attemptId: 1, }, id: 34, }, state: C_NEW, ] containerId=container_1375865942038_0006_01_000034 queue=default: capacity=1.0, absoluteCapacity=1.0, usedResources=<memory:43008, vCores:37>usedCapacity=0.875, absoluteUsedCapacity=0.875, numApps=5, numContainers=37 usedCapacity=0.875 absoluteUsedCapacity=0.875 used=<memory:43008, vCores:37> cluster=<memory:49152, vCores:96>
2013-08-07 09:10:24,168 INFO org.apache.hadoop.yarn.server.resourcemanager.scheduler.capacity.ParentQueue: Re-sorting queues since queue: root.default stats: default: capacity=1.0, absoluteCapacity=1.0, usedResources=<memory:44032, vCores:38>usedCapacity=0.8958333, absoluteUsedCapacity=0.8958333, numApps=5, numContainers=38
2013-08-07 09:10:24,168 INFO org.apache.hadoop.yarn.server.resourcemanager.scheduler.capacity.ParentQueue: assignedContainer queue=root usedCapacity=0.8958333 absoluteUsedCapacity=0.8958333 used=<memory:44032, vCores:38> cluster=<memory:49152, vCores:96>
2013-08-07 09:10:24,169 INFO org.apache.hadoop.yarn.server.resourcemanager.rmcontainer.RMContainerImpl: container_1375865942038_0006_01_000035 Container Transitioned from NEW to ALLOCATED
2013-08-07 09:10:24,169 INFO org.apache.hadoop.yarn.server.resourcemanager.RMAuditLogger: USER=ubuntu	OPERATION=AM Allocated Container	TARGET=SchedulerApp	RESULT=SUCCESS	APPID=application_1375865942038_0006	CONTAINERID=container_1375865942038_0006_01_000035
2013-08-07 09:10:24,169 INFO org.apache.hadoop.yarn.server.resourcemanager.scheduler.common.fica.FiCaSchedulerNode: Assigned container container_1375865942038_0006_01_000035 of capacity <memory:1024, vCores:1> on host hadoop-200-6:52835, which currently has 3 containers, <memory:4096, vCores:3> used and <memory:4096, vCores:13> available
2013-08-07 09:10:24,170 INFO org.apache.hadoop.yarn.server.resourcemanager.scheduler.capacity.LeafQueue: assignedContainer application=application_1375865942038_0006 container=Container: [ContainerId: container_1375865942038_0006_01_000035, NodeId: hadoop-200-6:52835, NodeHttpAddress: hadoop-200-6:8042, Resource: <memory:1024, vCores:1>, Priority: 20, State: NEW, Token: null, Status: container_id {, app_attempt_id {, application_id {, id: 6, cluster_timestamp: 1375865942038, }, attemptId: 1, }, id: 35, }, state: C_NEW, ] containerId=container_1375865942038_0006_01_000035 queue=default: capacity=1.0, absoluteCapacity=1.0, usedResources=<memory:44032, vCores:38>usedCapacity=0.8958333, absoluteUsedCapacity=0.8958333, numApps=5, numContainers=38 usedCapacity=0.8958333 absoluteUsedCapacity=0.8958333 used=<memory:44032, vCores:38> cluster=<memory:49152, vCores:96>
2013-08-07 09:10:24,170 INFO org.apache.hadoop.yarn.server.resourcemanager.scheduler.capacity.ParentQueue: Re-sorting queues since queue: root.default stats: default: capacity=1.0, absoluteCapacity=1.0, usedResources=<memory:45056, vCores:39>usedCapacity=0.9166667, absoluteUsedCapacity=0.9166667, numApps=5, numContainers=39
2013-08-07 09:10:24,170 INFO org.apache.hadoop.yarn.server.resourcemanager.scheduler.capacity.ParentQueue: assignedContainer queue=root usedCapacity=0.9166667 absoluteUsedCapacity=0.9166667 used=<memory:45056, vCores:39> cluster=<memory:49152, vCores:96>
2013-08-07 09:10:24,171 INFO org.apache.hadoop.yarn.server.resourcemanager.rmcontainer.RMContainerImpl: container_1375865942038_0006_01_000036 Container Transitioned from NEW to ALLOCATED
2013-08-07 09:10:24,171 INFO org.apache.hadoop.yarn.server.resourcemanager.RMAuditLogger: USER=ubuntu	OPERATION=AM Allocated Container	TARGET=SchedulerApp	RESULT=SUCCESS	APPID=application_1375865942038_0006	CONTAINERID=container_1375865942038_0006_01_000036
2013-08-07 09:10:24,171 INFO org.apache.hadoop.yarn.server.resourcemanager.scheduler.common.fica.FiCaSchedulerNode: Assigned container container_1375865942038_0006_01_000036 of capacity <memory:1024, vCores:1> on host hadoop-200-6:52835, which currently has 4 containers, <memory:5120, vCores:4> used and <memory:3072, vCores:12> available
2013-08-07 09:10:24,172 INFO org.apache.hadoop.yarn.server.resourcemanager.scheduler.capacity.LeafQueue: assignedContainer application=application_1375865942038_0006 container=Container: [ContainerId: container_1375865942038_0006_01_000036, NodeId: hadoop-200-6:52835, NodeHttpAddress: hadoop-200-6:8042, Resource: <memory:1024, vCores:1>, Priority: 20, State: NEW, Token: null, Status: container_id {, app_attempt_id {, application_id {, id: 6, cluster_timestamp: 1375865942038, }, attemptId: 1, }, id: 36, }, state: C_NEW, ] containerId=container_1375865942038_0006_01_000036 queue=default: capacity=1.0, absoluteCapacity=1.0, usedResources=<memory:45056, vCores:39>usedCapacity=0.9166667, absoluteUsedCapacity=0.9166667, numApps=5, numContainers=39 usedCapacity=0.9166667 absoluteUsedCapacity=0.9166667 used=<memory:45056, vCores:39> cluster=<memory:49152, vCores:96>
2013-08-07 09:10:24,172 INFO org.apache.hadoop.yarn.server.resourcemanager.scheduler.capacity.ParentQueue: Re-sorting queues since queue: root.default stats: default: capacity=1.0, absoluteCapacity=1.0, usedResources=<memory:46080, vCores:40>usedCapacity=0.9375, absoluteUsedCapacity=0.9375, numApps=5, numContainers=40
2013-08-07 09:10:24,173 INFO org.apache.hadoop.yarn.server.resourcemanager.scheduler.capacity.ParentQueue: assignedContainer queue=root usedCapacity=0.9375 absoluteUsedCapacity=0.9375 used=<memory:46080, vCores:40> cluster=<memory:49152, vCores:96>
2013-08-07 09:10:24,173 INFO org.apache.hadoop.yarn.server.resourcemanager.rmcontainer.RMContainerImpl: container_1375865942038_0006_01_000037 Container Transitioned from NEW to ALLOCATED
2013-08-07 09:10:24,173 INFO org.apache.hadoop.yarn.server.resourcemanager.RMAuditLogger: USER=ubuntu	OPERATION=AM Allocated Container	TARGET=SchedulerApp	RESULT=SUCCESS	APPID=application_1375865942038_0006	CONTAINERID=container_1375865942038_0006_01_000037
2013-08-07 09:10:24,173 INFO org.apache.hadoop.yarn.server.resourcemanager.scheduler.common.fica.FiCaSchedulerNode: Assigned container container_1375865942038_0006_01_000037 of capacity <memory:1024, vCores:1> on host hadoop-200-6:52835, which currently has 5 containers, <memory:6144, vCores:5> used and <memory:2048, vCores:11> available
2013-08-07 09:10:24,174 INFO org.apache.hadoop.yarn.server.resourcemanager.scheduler.capacity.LeafQueue: assignedContainer application=application_1375865942038_0006 container=Container: [ContainerId: container_1375865942038_0006_01_000037, NodeId: hadoop-200-6:52835, NodeHttpAddress: hadoop-200-6:8042, Resource: <memory:1024, vCores:1>, Priority: 20, State: NEW, Token: null, Status: container_id {, app_attempt_id {, application_id {, id: 6, cluster_timestamp: 1375865942038, }, attemptId: 1, }, id: 37, }, state: C_NEW, ] containerId=container_1375865942038_0006_01_000037 queue=default: capacity=1.0, absoluteCapacity=1.0, usedResources=<memory:46080, vCores:40>usedCapacity=0.9375, absoluteUsedCapacity=0.9375, numApps=5, numContainers=40 usedCapacity=0.9375 absoluteUsedCapacity=0.9375 used=<memory:46080, vCores:40> cluster=<memory:49152, vCores:96>
2013-08-07 09:10:24,174 INFO org.apache.hadoop.yarn.server.resourcemanager.scheduler.capacity.ParentQueue: Re-sorting queues since queue: root.default stats: default: capacity=1.0, absoluteCapacity=1.0, usedResources=<memory:47104, vCores:41>usedCapacity=0.9583333, absoluteUsedCapacity=0.9583333, numApps=5, numContainers=41
2013-08-07 09:10:24,175 INFO org.apache.hadoop.yarn.server.resourcemanager.scheduler.capacity.ParentQueue: assignedContainer queue=root usedCapacity=0.9583333 absoluteUsedCapacity=0.9583333 used=<memory:47104, vCores:41> cluster=<memory:49152, vCores:96>
2013-08-07 09:10:24,175 INFO org.apache.hadoop.yarn.server.resourcemanager.rmcontainer.RMContainerImpl: container_1375865942038_0006_01_000038 Container Transitioned from NEW to ALLOCATED
2013-08-07 09:10:24,175 INFO org.apache.hadoop.yarn.server.resourcemanager.RMAuditLogger: USER=ubuntu	OPERATION=AM Allocated Container	TARGET=SchedulerApp	RESULT=SUCCESS	APPID=application_1375865942038_0006	CONTAINERID=container_1375865942038_0006_01_000038
2013-08-07 09:10:24,175 INFO org.apache.hadoop.yarn.server.resourcemanager.scheduler.common.fica.FiCaSchedulerNode: Assigned container container_1375865942038_0006_01_000038 of capacity <memory:1024, vCores:1> on host hadoop-200-6:52835, which currently has 6 containers, <memory:7168, vCores:6> used and <memory:1024, vCores:10> available
2013-08-07 09:10:24,176 INFO org.apache.hadoop.yarn.server.resourcemanager.scheduler.capacity.LeafQueue: assignedContainer application=application_1375865942038_0006 container=Container: [ContainerId: container_1375865942038_0006_01_000038, NodeId: hadoop-200-6:52835, NodeHttpAddress: hadoop-200-6:8042, Resource: <memory:1024, vCores:1>, Priority: 20, State: NEW, Token: null, Status: container_id {, app_attempt_id {, application_id {, id: 6, cluster_timestamp: 1375865942038, }, attemptId: 1, }, id: 38, }, state: C_NEW, ] containerId=container_1375865942038_0006_01_000038 queue=default: capacity=1.0, absoluteCapacity=1.0, usedResources=<memory:47104, vCores:41>usedCapacity=0.9583333, absoluteUsedCapacity=0.9583333, numApps=5, numContainers=41 usedCapacity=0.9583333 absoluteUsedCapacity=0.9583333 used=<memory:47104, vCores:41> cluster=<memory:49152, vCores:96>
2013-08-07 09:10:24,177 INFO org.apache.hadoop.yarn.server.resourcemanager.scheduler.capacity.ParentQueue: Re-sorting queues since queue: root.default stats: default: capacity=1.0, absoluteCapacity=1.0, usedResources=<memory:48128, vCores:42>usedCapacity=0.9791667, absoluteUsedCapacity=0.9791667, numApps=5, numContainers=42
2013-08-07 09:10:24,177 INFO org.apache.hadoop.yarn.server.resourcemanager.scheduler.capacity.ParentQueue: assignedContainer queue=root usedCapacity=0.9791667 absoluteUsedCapacity=0.9791667 used=<memory:48128, vCores:42> cluster=<memory:49152, vCores:96>
2013-08-07 09:10:24,177 INFO org.apache.hadoop.yarn.server.resourcemanager.rmcontainer.RMContainerImpl: container_1375865942038_0006_01_000039 Container Transitioned from NEW to ALLOCATED
2013-08-07 09:10:24,177 INFO org.apache.hadoop.yarn.server.resourcemanager.RMAuditLogger: USER=ubuntu	OPERATION=AM Allocated Container	TARGET=SchedulerApp	RESULT=SUCCESS	APPID=application_1375865942038_0006	CONTAINERID=container_1375865942038_0006_01_000039
2013-08-07 09:10:24,178 INFO org.apache.hadoop.yarn.server.resourcemanager.scheduler.common.fica.FiCaSchedulerNode: Assigned container container_1375865942038_0006_01_000039 of capacity <memory:1024, vCores:1> on host hadoop-200-6:52835, which currently has 7 containers, <memory:8192, vCores:7> used and <memory:0, vCores:9> available
2013-08-07 09:10:24,179 INFO org.apache.hadoop.yarn.server.resourcemanager.scheduler.capacity.LeafQueue: assignedContainer application=application_1375865942038_0006 container=Container: [ContainerId: container_1375865942038_0006_01_000039, NodeId: hadoop-200-6:52835, NodeHttpAddress: hadoop-200-6:8042, Resource: <memory:1024, vCores:1>, Priority: 20, State: NEW, Token: null, Status: container_id {, app_attempt_id {, application_id {, id: 6, cluster_timestamp: 1375865942038, }, attemptId: 1, }, id: 39, }, state: C_NEW, ] containerId=container_1375865942038_0006_01_000039 queue=default: capacity=1.0, absoluteCapacity=1.0, usedResources=<memory:48128, vCores:42>usedCapacity=0.9791667, absoluteUsedCapacity=0.9791667, numApps=5, numContainers=42 usedCapacity=0.9791667 absoluteUsedCapacity=0.9791667 used=<memory:48128, vCores:42> cluster=<memory:49152, vCores:96>
2013-08-07 09:10:24,179 INFO org.apache.hadoop.yarn.server.resourcemanager.scheduler.capacity.ParentQueue: Re-sorting queues since queue: root.default stats: default: capacity=1.0, absoluteCapacity=1.0, usedResources=<memory:49152, vCores:43>usedCapacity=1.0, absoluteUsedCapacity=1.0, numApps=5, numContainers=43
2013-08-07 09:10:24,179 INFO org.apache.hadoop.yarn.server.resourcemanager.scheduler.capacity.ParentQueue: assignedContainer queue=root usedCapacity=1.0 absoluteUsedCapacity=1.0 used=<memory:49152, vCores:43> cluster=<memory:49152, vCores:96>
2013-08-07 09:10:24,309 INFO org.apache.hadoop.yarn.server.resourcemanager.rmcontainer.RMContainerImpl: container_1375865942038_0006_01_000002 Container Transitioned from ALLOCATED to ACQUIRED
2013-08-07 09:10:24,311 INFO org.apache.hadoop.yarn.server.resourcemanager.rmcontainer.RMContainerImpl: container_1375865942038_0006_01_000003 Container Transitioned from ALLOCATED to ACQUIRED
2013-08-07 09:10:24,312 INFO org.apache.hadoop.yarn.server.resourcemanager.rmcontainer.RMContainerImpl: container_1375865942038_0006_01_000004 Container Transitioned from ALLOCATED to ACQUIRED
2013-08-07 09:10:24,313 INFO org.apache.hadoop.yarn.server.resourcemanager.rmcontainer.RMContainerImpl: container_1375865942038_0006_01_000005 Container Transitioned from ALLOCATED to ACQUIRED
2013-08-07 09:10:24,314 INFO org.apache.hadoop.yarn.server.resourcemanager.rmcontainer.RMContainerImpl: container_1375865942038_0006_01_000006 Container Transitioned from ALLOCATED to ACQUIRED
2013-08-07 09:10:24,315 INFO org.apache.hadoop.yarn.server.resourcemanager.rmcontainer.RMContainerImpl: container_1375865942038_0006_01_000007 Container Transitioned from ALLOCATED to ACQUIRED
2013-08-07 09:10:24,316 INFO org.apache.hadoop.yarn.server.resourcemanager.rmcontainer.RMContainerImpl: container_1375865942038_0006_01_000008 Container Transitioned from ALLOCATED to ACQUIRED
2013-08-07 09:10:24,318 INFO org.apache.hadoop.yarn.server.resourcemanager.rmcontainer.RMContainerImpl: container_1375865942038_0006_01_000009 Container Transitioned from ALLOCATED to ACQUIRED
2013-08-07 09:10:24,319 INFO org.apache.hadoop.yarn.server.resourcemanager.rmcontainer.RMContainerImpl: container_1375865942038_0006_01_000010 Container Transitioned from ALLOCATED to ACQUIRED
2013-08-07 09:10:24,320 INFO org.apache.hadoop.yarn.server.resourcemanager.rmcontainer.RMContainerImpl: container_1375865942038_0006_01_000011 Container Transitioned from ALLOCATED to ACQUIRED
2013-08-07 09:10:24,320 INFO org.apache.hadoop.yarn.server.resourcemanager.rmcontainer.RMContainerImpl: container_1375865942038_0006_01_000012 Container Transitioned from ALLOCATED to ACQUIRED
2013-08-07 09:10:24,320 INFO org.apache.hadoop.yarn.server.resourcemanager.rmcontainer.RMContainerImpl: container_1375865942038_0006_01_000013 Container Transitioned from ALLOCATED to ACQUIRED
2013-08-07 09:10:24,321 INFO org.apache.hadoop.yarn.server.resourcemanager.rmcontainer.RMContainerImpl: container_1375865942038_0006_01_000014 Container Transitioned from ALLOCATED to ACQUIRED
2013-08-07 09:10:24,321 INFO org.apache.hadoop.yarn.server.resourcemanager.rmcontainer.RMContainerImpl: container_1375865942038_0006_01_000015 Container Transitioned from ALLOCATED to ACQUIRED
2013-08-07 09:10:24,321 INFO org.apache.hadoop.yarn.server.resourcemanager.rmcontainer.RMContainerImpl: container_1375865942038_0006_01_000016 Container Transitioned from ALLOCATED to ACQUIRED
2013-08-07 09:10:24,321 INFO org.apache.hadoop.yarn.server.resourcemanager.rmcontainer.RMContainerImpl: container_1375865942038_0006_01_000017 Container Transitioned from ALLOCATED to ACQUIRED
2013-08-07 09:10:24,321 INFO org.apache.hadoop.yarn.server.resourcemanager.rmcontainer.RMContainerImpl: container_1375865942038_0006_01_000018 Container Transitioned from ALLOCATED to ACQUIRED
2013-08-07 09:10:24,322 INFO org.apache.hadoop.yarn.server.resourcemanager.rmcontainer.RMContainerImpl: container_1375865942038_0006_01_000019 Container Transitioned from ALLOCATED to ACQUIRED
2013-08-07 09:10:24,322 INFO org.apache.hadoop.yarn.server.resourcemanager.rmcontainer.RMContainerImpl: container_1375865942038_0006_01_000020 Container Transitioned from ALLOCATED to ACQUIRED
2013-08-07 09:10:24,322 INFO org.apache.hadoop.yarn.server.resourcemanager.rmcontainer.RMContainerImpl: container_1375865942038_0006_01_000021 Container Transitioned from ALLOCATED to ACQUIRED
2013-08-07 09:10:24,322 INFO org.apache.hadoop.yarn.server.resourcemanager.rmcontainer.RMContainerImpl: container_1375865942038_0006_01_000022 Container Transitioned from ALLOCATED to ACQUIRED
2013-08-07 09:10:24,322 INFO org.apache.hadoop.yarn.server.resourcemanager.rmcontainer.RMContainerImpl: container_1375865942038_0006_01_000023 Container Transitioned from ALLOCATED to ACQUIRED
2013-08-07 09:10:24,322 INFO org.apache.hadoop.yarn.server.resourcemanager.rmcontainer.RMContainerImpl: container_1375865942038_0006_01_000024 Container Transitioned from ALLOCATED to ACQUIRED
2013-08-07 09:10:24,323 INFO org.apache.hadoop.yarn.server.resourcemanager.rmcontainer.RMContainerImpl: container_1375865942038_0006_01_000025 Container Transitioned from ALLOCATED to ACQUIRED
2013-08-07 09:10:24,323 INFO org.apache.hadoop.yarn.server.resourcemanager.rmcontainer.RMContainerImpl: container_1375865942038_0006_01_000026 Container Transitioned from ALLOCATED to ACQUIRED
2013-08-07 09:10:24,323 INFO org.apache.hadoop.yarn.server.resourcemanager.rmcontainer.RMContainerImpl: container_1375865942038_0006_01_000027 Container Transitioned from ALLOCATED to ACQUIRED
2013-08-07 09:10:24,323 INFO org.apache.hadoop.yarn.server.resourcemanager.rmcontainer.RMContainerImpl: container_1375865942038_0006_01_000028 Container Transitioned from ALLOCATED to ACQUIRED
2013-08-07 09:10:24,323 INFO org.apache.hadoop.yarn.server.resourcemanager.rmcontainer.RMContainerImpl: container_1375865942038_0006_01_000029 Container Transitioned from ALLOCATED to ACQUIRED
2013-08-07 09:10:24,324 INFO org.apache.hadoop.yarn.server.resourcemanager.rmcontainer.RMContainerImpl: container_1375865942038_0006_01_000030 Container Transitioned from ALLOCATED to ACQUIRED
2013-08-07 09:10:24,324 INFO org.apache.hadoop.yarn.server.resourcemanager.rmcontainer.RMContainerImpl: container_1375865942038_0006_01_000031 Container Transitioned from ALLOCATED to ACQUIRED
2013-08-07 09:10:24,324 INFO org.apache.hadoop.yarn.server.resourcemanager.rmcontainer.RMContainerImpl: container_1375865942038_0006_01_000032 Container Transitioned from ALLOCATED to ACQUIRED
2013-08-07 09:10:24,324 INFO org.apache.hadoop.yarn.server.resourcemanager.rmcontainer.RMContainerImpl: container_1375865942038_0006_01_000033 Container Transitioned from ALLOCATED to ACQUIRED
2013-08-07 09:10:24,324 INFO org.apache.hadoop.yarn.server.resourcemanager.rmcontainer.RMContainerImpl: container_1375865942038_0006_01_000034 Container Transitioned from ALLOCATED to ACQUIRED
2013-08-07 09:10:24,324 INFO org.apache.hadoop.yarn.server.resourcemanager.rmcontainer.RMContainerImpl: container_1375865942038_0006_01_000035 Container Transitioned from ALLOCATED to ACQUIRED
2013-08-07 09:10:24,325 INFO org.apache.hadoop.yarn.server.resourcemanager.rmcontainer.RMContainerImpl: container_1375865942038_0006_01_000036 Container Transitioned from ALLOCATED to ACQUIRED
2013-08-07 09:10:24,325 INFO org.apache.hadoop.yarn.server.resourcemanager.rmcontainer.RMContainerImpl: container_1375865942038_0006_01_000037 Container Transitioned from ALLOCATED to ACQUIRED
2013-08-07 09:10:24,325 INFO org.apache.hadoop.yarn.server.resourcemanager.rmcontainer.RMContainerImpl: container_1375865942038_0006_01_000038 Container Transitioned from ALLOCATED to ACQUIRED
2013-08-07 09:10:24,325 INFO org.apache.hadoop.yarn.server.resourcemanager.rmcontainer.RMContainerImpl: container_1375865942038_0006_01_000039 Container Transitioned from ALLOCATED to ACQUIRED
2013-08-07 09:10:24,714 INFO org.apache.hadoop.yarn.server.resourcemanager.ApplicationMasterService: AM registration appattempt_1375865942038_0008_000001
2013-08-07 09:10:24,714 INFO org.apache.hadoop.yarn.server.resourcemanager.RMAuditLogger: USER=ubuntu	IP=192.168.100.3	OPERATION=Register App Master	TARGET=ApplicationMasterService	RESULT=SUCCESS	APPID=application_1375865942038_0008	APPATTEMPTID=appattempt_1375865942038_0008_000001
2013-08-07 09:10:24,715 INFO org.apache.hadoop.yarn.server.resourcemanager.rmapp.attempt.RMAppAttemptImpl: appattempt_1375865942038_0008_000001 State change from LAUNCHED to RUNNING
2013-08-07 09:10:24,715 INFO org.apache.hadoop.yarn.server.resourcemanager.rmapp.RMAppImpl: application_1375865942038_0008 State change from ACCEPTED to RUNNING
2013-08-07 09:10:24,990 INFO org.apache.hadoop.yarn.server.resourcemanager.rmcontainer.RMContainerImpl: container_1375865942038_0006_01_000022 Container Transitioned from ACQUIRED to RUNNING
2013-08-07 09:10:24,991 INFO org.apache.hadoop.yarn.server.resourcemanager.rmcontainer.RMContainerImpl: container_1375865942038_0006_01_000023 Container Transitioned from ACQUIRED to RUNNING
2013-08-07 09:10:24,992 INFO org.apache.hadoop.yarn.server.resourcemanager.rmcontainer.RMContainerImpl: container_1375865942038_0006_01_000024 Container Transitioned from ACQUIRED to RUNNING
2013-08-07 09:10:24,993 INFO org.apache.hadoop.yarn.server.resourcemanager.rmcontainer.RMContainerImpl: container_1375865942038_0006_01_000025 Container Transitioned from ACQUIRED to RUNNING
2013-08-07 09:10:24,994 INFO org.apache.hadoop.yarn.server.resourcemanager.rmcontainer.RMContainerImpl: container_1375865942038_0006_01_000026 Container Transitioned from ACQUIRED to RUNNING
2013-08-07 09:10:24,995 INFO org.apache.hadoop.yarn.server.resourcemanager.rmcontainer.RMContainerImpl: container_1375865942038_0006_01_000027 Container Transitioned from ACQUIRED to RUNNING
2013-08-07 09:10:25,042 INFO org.apache.hadoop.yarn.server.resourcemanager.rmcontainer.RMContainerImpl: container_1375865942038_0006_01_000028 Container Transitioned from ACQUIRED to RUNNING
2013-08-07 09:10:25,043 INFO org.apache.hadoop.yarn.server.resourcemanager.rmcontainer.RMContainerImpl: container_1375865942038_0006_01_000029 Container Transitioned from ACQUIRED to RUNNING
2013-08-07 09:10:25,043 INFO org.apache.hadoop.yarn.server.resourcemanager.rmcontainer.RMContainerImpl: container_1375865942038_0006_01_000030 Container Transitioned from ACQUIRED to RUNNING
2013-08-07 09:10:25,043 INFO org.apache.hadoop.yarn.server.resourcemanager.rmcontainer.RMContainerImpl: container_1375865942038_0006_01_000031 Container Transitioned from ACQUIRED to RUNNING
2013-08-07 09:10:25,044 INFO org.apache.hadoop.yarn.server.resourcemanager.rmcontainer.RMContainerImpl: container_1375865942038_0006_01_000032 Container Transitioned from ACQUIRED to RUNNING
2013-08-07 09:10:25,044 INFO org.apache.hadoop.yarn.server.resourcemanager.rmcontainer.RMContainerImpl: container_1375865942038_0006_01_000033 Container Transitioned from ACQUIRED to RUNNING
2013-08-07 09:10:25,194 INFO org.apache.hadoop.yarn.server.resourcemanager.rmcontainer.RMContainerImpl: container_1375865942038_0006_01_000034 Container Transitioned from ACQUIRED to RUNNING
2013-08-07 09:10:25,195 INFO org.apache.hadoop.yarn.server.resourcemanager.rmcontainer.RMContainerImpl: container_1375865942038_0006_01_000035 Container Transitioned from ACQUIRED to RUNNING
2013-08-07 09:10:25,195 INFO org.apache.hadoop.yarn.server.resourcemanager.rmcontainer.RMContainerImpl: container_1375865942038_0006_01_000036 Container Transitioned from ACQUIRED to RUNNING
2013-08-07 09:10:25,195 INFO org.apache.hadoop.yarn.server.resourcemanager.rmcontainer.RMContainerImpl: container_1375865942038_0006_01_000037 Container Transitioned from ACQUIRED to RUNNING
2013-08-07 09:10:25,196 INFO org.apache.hadoop.yarn.server.resourcemanager.rmcontainer.RMContainerImpl: container_1375865942038_0006_01_000038 Container Transitioned from ACQUIRED to RUNNING
2013-08-07 09:10:25,196 INFO org.apache.hadoop.yarn.server.resourcemanager.rmcontainer.RMContainerImpl: container_1375865942038_0006_01_000039 Container Transitioned from ACQUIRED to RUNNING
2013-08-07 09:10:25,362 INFO org.apache.hadoop.yarn.server.resourcemanager.rmcontainer.RMContainerImpl: container_1375865942038_0006_01_000002 Container Transitioned from ACQUIRED to RUNNING
2013-08-07 09:10:25,362 INFO org.apache.hadoop.yarn.server.resourcemanager.rmcontainer.RMContainerImpl: container_1375865942038_0006_01_000003 Container Transitioned from ACQUIRED to RUNNING
2013-08-07 09:10:25,362 INFO org.apache.hadoop.yarn.server.resourcemanager.rmcontainer.RMContainerImpl: container_1375865942038_0006_01_000004 Container Transitioned from ACQUIRED to RUNNING
2013-08-07 09:10:25,362 INFO org.apache.hadoop.yarn.server.resourcemanager.rmcontainer.RMContainerImpl: container_1375865942038_0006_01_000005 Container Transitioned from ACQUIRED to RUNNING
2013-08-07 09:10:25,362 INFO org.apache.hadoop.yarn.server.resourcemanager.rmcontainer.RMContainerImpl: container_1375865942038_0006_01_000006 Container Transitioned from ACQUIRED to RUNNING
2013-08-07 09:10:25,363 INFO org.apache.hadoop.yarn.server.resourcemanager.rmcontainer.RMContainerImpl: container_1375865942038_0006_01_000007 Container Transitioned from ACQUIRED to RUNNING
2013-08-07 09:10:25,417 INFO org.apache.hadoop.yarn.server.resourcemanager.rmcontainer.RMContainerImpl: container_1375865942038_0006_01_000008 Container Transitioned from ACQUIRED to RUNNING
2013-08-07 09:10:25,417 INFO org.apache.hadoop.yarn.server.resourcemanager.rmcontainer.RMContainerImpl: container_1375865942038_0006_01_000009 Container Transitioned from ACQUIRED to RUNNING
2013-08-07 09:10:25,417 INFO org.apache.hadoop.yarn.server.resourcemanager.rmcontainer.RMContainerImpl: container_1375865942038_0006_01_000010 Container Transitioned from ACQUIRED to RUNNING
2013-08-07 09:10:25,418 INFO org.apache.hadoop.yarn.server.resourcemanager.rmcontainer.RMContainerImpl: container_1375865942038_0006_01_000011 Container Transitioned from ACQUIRED to RUNNING
2013-08-07 09:10:25,419 INFO org.apache.hadoop.yarn.server.resourcemanager.rmcontainer.RMContainerImpl: container_1375865942038_0006_01_000012 Container Transitioned from ACQUIRED to RUNNING
2013-08-07 09:10:25,420 INFO org.apache.hadoop.yarn.server.resourcemanager.rmcontainer.RMContainerImpl: container_1375865942038_0006_01_000013 Container Transitioned from ACQUIRED to RUNNING
2013-08-07 09:10:25,420 INFO org.apache.hadoop.yarn.server.resourcemanager.rmcontainer.RMContainerImpl: container_1375865942038_0006_01_000014 Container Transitioned from ACQUIRED to RUNNING
2013-08-07 09:10:25,420 INFO org.apache.hadoop.yarn.server.resourcemanager.rmcontainer.RMContainerImpl: container_1375865942038_0006_01_000015 Container Transitioned from ACQUIRED to RUNNING
2013-08-07 09:10:25,628 INFO org.apache.hadoop.yarn.server.resourcemanager.rmcontainer.RMContainerImpl: container_1375865942038_0006_01_000016 Container Transitioned from ACQUIRED to RUNNING
2013-08-07 09:10:25,629 INFO org.apache.hadoop.yarn.server.resourcemanager.rmcontainer.RMContainerImpl: container_1375865942038_0006_01_000017 Container Transitioned from ACQUIRED to RUNNING
2013-08-07 09:10:25,629 INFO org.apache.hadoop.yarn.server.resourcemanager.rmcontainer.RMContainerImpl: container_1375865942038_0006_01_000018 Container Transitioned from ACQUIRED to RUNNING
2013-08-07 09:10:25,629 INFO org.apache.hadoop.yarn.server.resourcemanager.rmcontainer.RMContainerImpl: container_1375865942038_0006_01_000019 Container Transitioned from ACQUIRED to RUNNING
2013-08-07 09:10:25,629 INFO org.apache.hadoop.yarn.server.resourcemanager.rmcontainer.RMContainerImpl: container_1375865942038_0006_01_000020 Container Transitioned from ACQUIRED to RUNNING
2013-08-07 09:10:25,629 INFO org.apache.hadoop.yarn.server.resourcemanager.rmcontainer.RMContainerImpl: container_1375865942038_0006_01_000021 Container Transitioned from ACQUIRED to RUNNING
2013-08-07 09:10:48,699 INFO org.apache.hadoop.yarn.server.resourcemanager.rmcontainer.RMContainerImpl: container_1375865942038_0006_01_000003 Container Transitioned from RUNNING to COMPLETED
2013-08-07 09:10:48,700 INFO org.apache.hadoop.yarn.server.resourcemanager.scheduler.common.fica.FiCaSchedulerApp: Completed container: container_1375865942038_0006_01_000003 in state: COMPLETED event:FINISHED
2013-08-07 09:10:48,700 INFO org.apache.hadoop.yarn.server.resourcemanager.RMAuditLogger: USER=ubuntu	OPERATION=AM Released Container	TARGET=SchedulerApp	RESULT=SUCCESS	APPID=application_1375865942038_0006	CONTAINERID=container_1375865942038_0006_01_000003
2013-08-07 09:10:48,700 INFO org.apache.hadoop.yarn.server.resourcemanager.scheduler.common.fica.FiCaSchedulerNode: Released container container_1375865942038_0006_01_000003 of capacity <memory:1024, vCores:1> on host hadoop-200-7:54925, which currently has 6 containers, <memory:7168, vCores:6> used and <memory:1024, vCores:10> available, release resources=true
2013-08-07 09:10:48,700 INFO org.apache.hadoop.yarn.server.resourcemanager.scheduler.capacity.LeafQueue: default used=<memory:48128, vCores:42> numContainers=42 user=ubuntu user-resources=<memory:48128, vCores:42>
2013-08-07 09:10:48,703 INFO org.apache.hadoop.yarn.server.resourcemanager.scheduler.capacity.LeafQueue: completedContainer container=Container: [ContainerId: container_1375865942038_0006_01_000003, NodeId: hadoop-200-7:54925, NodeHttpAddress: hadoop-200-7:8042, Resource: <memory:1024, vCores:1>, Priority: 20, State: NEW, Token: null, Status: container_id {, app_attempt_id {, application_id {, id: 6, cluster_timestamp: 1375865942038, }, attemptId: 1, }, id: 3, }, state: C_COMPLETE, diagnostics: "Container killed by the ApplicationMaster.\n\n", exit_status: 143, ] resource=<memory:1024, vCores:1> queue=default: capacity=1.0, absoluteCapacity=1.0, usedResources=<memory:48128, vCores:42>usedCapacity=0.9791667, absoluteUsedCapacity=0.9791667, numApps=5, numContainers=42 usedCapacity=0.9791667 absoluteUsedCapacity=0.9791667 used=<memory:48128, vCores:42> cluster=<memory:49152, vCores:96>
2013-08-07 09:10:48,703 INFO org.apache.hadoop.yarn.server.resourcemanager.scheduler.capacity.ParentQueue: completedContainer queue=root usedCapacity=0.9791667 absoluteUsedCapacity=0.9791667 used=<memory:48128, vCores:42> cluster=<memory:49152, vCores:96>
2013-08-07 09:10:48,703 INFO org.apache.hadoop.yarn.server.resourcemanager.scheduler.capacity.CapacityScheduler: Application appattempt_1375865942038_0006_000001 released container container_1375865942038_0006_01_000003 on node: host: hadoop-200-7:54925 #containers=6 available=1024 used=7168 with event: FINISHED
2013-08-07 09:10:48,704 INFO org.apache.hadoop.yarn.server.resourcemanager.rmcontainer.RMContainerImpl: container_1375865942038_0006_01_000040 Container Transitioned from NEW to ALLOCATED
2013-08-07 09:10:48,704 INFO org.apache.hadoop.yarn.server.resourcemanager.RMAuditLogger: USER=ubuntu	OPERATION=AM Allocated Container	TARGET=SchedulerApp	RESULT=SUCCESS	APPID=application_1375865942038_0006	CONTAINERID=container_1375865942038_0006_01_000040
2013-08-07 09:10:48,704 INFO org.apache.hadoop.yarn.server.resourcemanager.scheduler.common.fica.FiCaSchedulerNode: Assigned container container_1375865942038_0006_01_000040 of capacity <memory:1024, vCores:1> on host hadoop-200-7:54925, which currently has 7 containers, <memory:8192, vCores:7> used and <memory:0, vCores:9> available
2013-08-07 09:10:48,705 INFO org.apache.hadoop.yarn.server.resourcemanager.scheduler.capacity.LeafQueue: assignedContainer application=application_1375865942038_0006 container=Container: [ContainerId: container_1375865942038_0006_01_000040, NodeId: hadoop-200-7:54925, NodeHttpAddress: hadoop-200-7:8042, Resource: <memory:1024, vCores:1>, Priority: 20, State: NEW, Token: null, Status: container_id {, app_attempt_id {, application_id {, id: 6, cluster_timestamp: 1375865942038, }, attemptId: 1, }, id: 40, }, state: C_NEW, ] containerId=container_1375865942038_0006_01_000040 queue=default: capacity=1.0, absoluteCapacity=1.0, usedResources=<memory:48128, vCores:42>usedCapacity=0.9791667, absoluteUsedCapacity=0.9791667, numApps=5, numContainers=42 usedCapacity=0.9791667 absoluteUsedCapacity=0.9791667 used=<memory:48128, vCores:42> cluster=<memory:49152, vCores:96>
2013-08-07 09:10:48,705 INFO org.apache.hadoop.yarn.server.resourcemanager.scheduler.capacity.ParentQueue: Re-sorting queues since queue: root.default stats: default: capacity=1.0, absoluteCapacity=1.0, usedResources=<memory:49152, vCores:43>usedCapacity=1.0, absoluteUsedCapacity=1.0, numApps=5, numContainers=43
2013-08-07 09:10:48,705 INFO org.apache.hadoop.yarn.server.resourcemanager.scheduler.capacity.ParentQueue: assignedContainer queue=root usedCapacity=1.0 absoluteUsedCapacity=1.0 used=<memory:49152, vCores:43> cluster=<memory:49152, vCores:96>
2013-08-07 09:10:49,538 INFO org.apache.hadoop.yarn.server.resourcemanager.rmcontainer.RMContainerImpl: container_1375865942038_0006_01_000040 Container Transitioned from ALLOCATED to ACQUIRED
2013-08-07 09:10:49,576 INFO org.apache.hadoop.yarn.server.resourcemanager.rmcontainer.RMContainerImpl: container_1375865942038_0006_01_000018 Container Transitioned from RUNNING to COMPLETED
2013-08-07 09:10:49,576 INFO org.apache.hadoop.yarn.server.resourcemanager.scheduler.common.fica.FiCaSchedulerApp: Completed container: container_1375865942038_0006_01_000018 in state: COMPLETED event:FINISHED
2013-08-07 09:10:49,576 INFO org.apache.hadoop.yarn.server.resourcemanager.RMAuditLogger: USER=ubuntu	OPERATION=AM Released Container	TARGET=SchedulerApp	RESULT=SUCCESS	APPID=application_1375865942038_0006	CONTAINERID=container_1375865942038_0006_01_000018
2013-08-07 09:10:49,576 INFO org.apache.hadoop.yarn.server.resourcemanager.scheduler.common.fica.FiCaSchedulerNode: Released container container_1375865942038_0006_01_000018 of capacity <memory:1024, vCores:1> on host hadoop-200-4:57320, which currently has 6 containers, <memory:7168, vCores:6> used and <memory:1024, vCores:10> available, release resources=true
2013-08-07 09:10:49,576 INFO org.apache.hadoop.yarn.server.resourcemanager.scheduler.capacity.LeafQueue: default used=<memory:48128, vCores:42> numContainers=42 user=ubuntu user-resources=<memory:48128, vCores:42>
2013-08-07 09:10:49,578 INFO org.apache.hadoop.yarn.server.resourcemanager.scheduler.capacity.LeafQueue: completedContainer container=Container: [ContainerId: container_1375865942038_0006_01_000018, NodeId: hadoop-200-4:57320, NodeHttpAddress: hadoop-200-4:8042, Resource: <memory:1024, vCores:1>, Priority: 20, State: NEW, Token: null, Status: container_id {, app_attempt_id {, application_id {, id: 6, cluster_timestamp: 1375865942038, }, attemptId: 1, }, id: 18, }, state: C_COMPLETE, diagnostics: "Container killed by the ApplicationMaster.\n\n", exit_status: 143, ] resource=<memory:1024, vCores:1> queue=default: capacity=1.0, absoluteCapacity=1.0, usedResources=<memory:48128, vCores:42>usedCapacity=0.9791667, absoluteUsedCapacity=0.9791667, numApps=5, numContainers=42 usedCapacity=0.9791667 absoluteUsedCapacity=0.9791667 used=<memory:48128, vCores:42> cluster=<memory:49152, vCores:96>
2013-08-07 09:10:49,578 INFO org.apache.hadoop.yarn.server.resourcemanager.scheduler.capacity.ParentQueue: completedContainer queue=root usedCapacity=0.9791667 absoluteUsedCapacity=0.9791667 used=<memory:48128, vCores:42> cluster=<memory:49152, vCores:96>
2013-08-07 09:10:49,578 INFO org.apache.hadoop.yarn.server.resourcemanager.scheduler.capacity.CapacityScheduler: Application appattempt_1375865942038_0006_000001 released container container_1375865942038_0006_01_000018 on node: host: hadoop-200-4:57320 #containers=6 available=1024 used=7168 with event: FINISHED
2013-08-07 09:10:49,578 INFO org.apache.hadoop.yarn.server.resourcemanager.rmcontainer.RMContainerImpl: container_1375865942038_0006_01_000019 Container Transitioned from RUNNING to COMPLETED
2013-08-07 09:10:49,578 INFO org.apache.hadoop.yarn.server.resourcemanager.scheduler.common.fica.FiCaSchedulerApp: Completed container: container_1375865942038_0006_01_000019 in state: COMPLETED event:FINISHED
2013-08-07 09:10:49,578 INFO org.apache.hadoop.yarn.server.resourcemanager.RMAuditLogger: USER=ubuntu	OPERATION=AM Released Container	TARGET=SchedulerApp	RESULT=SUCCESS	APPID=application_1375865942038_0006	CONTAINERID=container_1375865942038_0006_01_000019
2013-08-07 09:10:49,579 INFO org.apache.hadoop.yarn.server.resourcemanager.scheduler.common.fica.FiCaSchedulerNode: Released container container_1375865942038_0006_01_000019 of capacity <memory:1024, vCores:1> on host hadoop-200-4:57320, which currently has 5 containers, <memory:6144, vCores:5> used and <memory:2048, vCores:11> available, release resources=true
2013-08-07 09:10:49,579 INFO org.apache.hadoop.yarn.server.resourcemanager.scheduler.capacity.LeafQueue: default used=<memory:47104, vCores:41> numContainers=41 user=ubuntu user-resources=<memory:47104, vCores:41>
2013-08-07 09:10:49,580 INFO org.apache.hadoop.yarn.server.resourcemanager.scheduler.capacity.LeafQueue: completedContainer container=Container: [ContainerId: container_1375865942038_0006_01_000019, NodeId: hadoop-200-4:57320, NodeHttpAddress: hadoop-200-4:8042, Resource: <memory:1024, vCores:1>, Priority: 20, State: NEW, Token: null, Status: container_id {, app_attempt_id {, application_id {, id: 6, cluster_timestamp: 1375865942038, }, attemptId: 1, }, id: 19, }, state: C_COMPLETE, diagnostics: "Container killed by the ApplicationMaster.\n\n", exit_status: 143, ] resource=<memory:1024, vCores:1> queue=default: capacity=1.0, absoluteCapacity=1.0, usedResources=<memory:47104, vCores:41>usedCapacity=0.9583333, absoluteUsedCapacity=0.9583333, numApps=5, numContainers=41 usedCapacity=0.9583333 absoluteUsedCapacity=0.9583333 used=<memory:47104, vCores:41> cluster=<memory:49152, vCores:96>
2013-08-07 09:10:49,580 INFO org.apache.hadoop.yarn.server.resourcemanager.scheduler.capacity.ParentQueue: completedContainer queue=root usedCapacity=0.9583333 absoluteUsedCapacity=0.9583333 used=<memory:47104, vCores:41> cluster=<memory:49152, vCores:96>
2013-08-07 09:10:49,580 INFO org.apache.hadoop.yarn.server.resourcemanager.scheduler.capacity.CapacityScheduler: Application appattempt_1375865942038_0006_000001 released container container_1375865942038_0006_01_000019 on node: host: hadoop-200-4:57320 #containers=5 available=2048 used=6144 with event: FINISHED
2013-08-07 09:10:49,581 INFO org.apache.hadoop.yarn.server.resourcemanager.rmcontainer.RMContainerImpl: container_1375865942038_0006_01_000041 Container Transitioned from NEW to ALLOCATED
2013-08-07 09:10:49,581 INFO org.apache.hadoop.yarn.server.resourcemanager.RMAuditLogger: USER=ubuntu	OPERATION=AM Allocated Container	TARGET=SchedulerApp	RESULT=SUCCESS	APPID=application_1375865942038_0006	CONTAINERID=container_1375865942038_0006_01_000041
2013-08-07 09:10:49,581 INFO org.apache.hadoop.yarn.server.resourcemanager.scheduler.common.fica.FiCaSchedulerNode: Assigned container container_1375865942038_0006_01_000041 of capacity <memory:1024, vCores:1> on host hadoop-200-4:57320, which currently has 6 containers, <memory:7168, vCores:6> used and <memory:1024, vCores:10> available
2013-08-07 09:10:49,582 INFO org.apache.hadoop.yarn.server.resourcemanager.scheduler.capacity.LeafQueue: assignedContainer application=application_1375865942038_0006 container=Container: [ContainerId: container_1375865942038_0006_01_000041, NodeId: hadoop-200-4:57320, NodeHttpAddress: hadoop-200-4:8042, Resource: <memory:1024, vCores:1>, Priority: 20, State: NEW, Token: null, Status: container_id {, app_attempt_id {, application_id {, id: 6, cluster_timestamp: 1375865942038, }, attemptId: 1, }, id: 41, }, state: C_NEW, ] containerId=container_1375865942038_0006_01_000041 queue=default: capacity=1.0, absoluteCapacity=1.0, usedResources=<memory:47104, vCores:41>usedCapacity=0.9583333, absoluteUsedCapacity=0.9583333, numApps=5, numContainers=41 usedCapacity=0.9583333 absoluteUsedCapacity=0.9583333 used=<memory:47104, vCores:41> cluster=<memory:49152, vCores:96>
2013-08-07 09:10:49,582 INFO org.apache.hadoop.yarn.server.resourcemanager.scheduler.capacity.ParentQueue: Re-sorting queues since queue: root.default stats: default: capacity=1.0, absoluteCapacity=1.0, usedResources=<memory:48128, vCores:42>usedCapacity=0.9791667, absoluteUsedCapacity=0.9791667, numApps=5, numContainers=42
2013-08-07 09:10:49,582 INFO org.apache.hadoop.yarn.server.resourcemanager.scheduler.capacity.ParentQueue: assignedContainer queue=root usedCapacity=0.9791667 absoluteUsedCapacity=0.9791667 used=<memory:48128, vCores:42> cluster=<memory:49152, vCores:96>
2013-08-07 09:10:49,583 INFO org.apache.hadoop.yarn.server.resourcemanager.rmcontainer.RMContainerImpl: container_1375865942038_0007_01_000002 Container Transitioned from NEW to ALLOCATED
2013-08-07 09:10:49,583 INFO org.apache.hadoop.yarn.server.resourcemanager.RMAuditLogger: USER=ubuntu	OPERATION=AM Allocated Container	TARGET=SchedulerApp	RESULT=SUCCESS	APPID=application_1375865942038_0007	CONTAINERID=container_1375865942038_0007_01_000002
2013-08-07 09:10:49,583 INFO org.apache.hadoop.yarn.server.resourcemanager.scheduler.common.fica.FiCaSchedulerNode: Assigned container container_1375865942038_0007_01_000002 of capacity <memory:1024, vCores:1> on host hadoop-200-4:57320, which currently has 7 containers, <memory:8192, vCores:7> used and <memory:0, vCores:9> available
2013-08-07 09:10:49,584 INFO org.apache.hadoop.yarn.server.resourcemanager.scheduler.capacity.LeafQueue: assignedContainer application=application_1375865942038_0007 container=Container: [ContainerId: container_1375865942038_0007_01_000002, NodeId: hadoop-200-4:57320, NodeHttpAddress: hadoop-200-4:8042, Resource: <memory:1024, vCores:1>, Priority: 20, State: NEW, Token: null, Status: container_id {, app_attempt_id {, application_id {, id: 7, cluster_timestamp: 1375865942038, }, attemptId: 1, }, id: 2, }, state: C_NEW, ] containerId=container_1375865942038_0007_01_000002 queue=default: capacity=1.0, absoluteCapacity=1.0, usedResources=<memory:48128, vCores:42>usedCapacity=0.9791667, absoluteUsedCapacity=0.9791667, numApps=5, numContainers=42 usedCapacity=0.9791667 absoluteUsedCapacity=0.9791667 used=<memory:48128, vCores:42> cluster=<memory:49152, vCores:96>
2013-08-07 09:10:49,584 INFO org.apache.hadoop.yarn.server.resourcemanager.scheduler.capacity.ParentQueue: Re-sorting queues since queue: root.default stats: default: capacity=1.0, absoluteCapacity=1.0, usedResources=<memory:49152, vCores:43>usedCapacity=1.0, absoluteUsedCapacity=1.0, numApps=5, numContainers=43
2013-08-07 09:10:49,584 INFO org.apache.hadoop.yarn.server.resourcemanager.scheduler.capacity.ParentQueue: assignedContainer queue=root usedCapacity=1.0 absoluteUsedCapacity=1.0 used=<memory:49152, vCores:43> cluster=<memory:49152, vCores:96>
2013-08-07 09:10:49,715 INFO org.apache.hadoop.yarn.server.resourcemanager.rmcontainer.RMContainerImpl: container_1375865942038_0006_01_000040 Container Transitioned from ACQUIRED to RUNNING
2013-08-07 09:10:50,051 INFO org.apache.hadoop.yarn.server.resourcemanager.rmcontainer.RMContainerImpl: container_1375865942038_0007_01_000002 Container Transitioned from ALLOCATED to ACQUIRED
2013-08-07 09:10:50,547 INFO org.apache.hadoop.yarn.server.resourcemanager.rmcontainer.RMContainerImpl: container_1375865942038_0006_01_000041 Container Transitioned from ALLOCATED to ACQUIRED
2013-08-07 09:10:50,584 INFO org.apache.hadoop.yarn.server.resourcemanager.rmcontainer.RMContainerImpl: container_1375865942038_0006_01_000041 Container Transitioned from ACQUIRED to RUNNING
2013-08-07 09:10:51,482 INFO org.apache.hadoop.yarn.server.resourcemanager.rmcontainer.RMContainerImpl: container_1375865942038_0006_01_000005 Container Transitioned from RUNNING to COMPLETED
2013-08-07 09:10:51,483 INFO org.apache.hadoop.yarn.server.resourcemanager.scheduler.common.fica.FiCaSchedulerApp: Completed container: container_1375865942038_0006_01_000005 in state: COMPLETED event:FINISHED
2013-08-07 09:10:51,483 INFO org.apache.hadoop.yarn.server.resourcemanager.RMAuditLogger: USER=ubuntu	OPERATION=AM Released Container	TARGET=SchedulerApp	RESULT=SUCCESS	APPID=application_1375865942038_0006	CONTAINERID=container_1375865942038_0006_01_000005
2013-08-07 09:10:51,483 INFO org.apache.hadoop.yarn.server.resourcemanager.scheduler.common.fica.FiCaSchedulerNode: Released container container_1375865942038_0006_01_000005 of capacity <memory:1024, vCores:1> on host hadoop-200-7:54925, which currently has 6 containers, <memory:7168, vCores:6> used and <memory:1024, vCores:10> available, release resources=true
2013-08-07 09:10:51,483 INFO org.apache.hadoop.yarn.server.resourcemanager.scheduler.capacity.LeafQueue: default used=<memory:48128, vCores:42> numContainers=42 user=ubuntu user-resources=<memory:48128, vCores:42>
2013-08-07 09:10:51,484 INFO org.apache.hadoop.yarn.server.resourcemanager.scheduler.capacity.LeafQueue: completedContainer container=Container: [ContainerId: container_1375865942038_0006_01_000005, NodeId: hadoop-200-7:54925, NodeHttpAddress: hadoop-200-7:8042, Resource: <memory:1024, vCores:1>, Priority: 20, State: NEW, Token: null, Status: container_id {, app_attempt_id {, application_id {, id: 6, cluster_timestamp: 1375865942038, }, attemptId: 1, }, id: 5, }, state: C_COMPLETE, diagnostics: "Container killed by the ApplicationMaster.\n", exit_status: 0, ] resource=<memory:1024, vCores:1> queue=default: capacity=1.0, absoluteCapacity=1.0, usedResources=<memory:48128, vCores:42>usedCapacity=0.9791667, absoluteUsedCapacity=0.9791667, numApps=5, numContainers=42 usedCapacity=0.9791667 absoluteUsedCapacity=0.9791667 used=<memory:48128, vCores:42> cluster=<memory:49152, vCores:96>
2013-08-07 09:10:51,484 INFO org.apache.hadoop.yarn.server.resourcemanager.scheduler.capacity.ParentQueue: completedContainer queue=root usedCapacity=0.9791667 absoluteUsedCapacity=0.9791667 used=<memory:48128, vCores:42> cluster=<memory:49152, vCores:96>
2013-08-07 09:10:51,485 INFO org.apache.hadoop.yarn.server.resourcemanager.scheduler.capacity.CapacityScheduler: Application appattempt_1375865942038_0006_000001 released container container_1375865942038_0006_01_000005 on node: host: hadoop-200-7:54925 #containers=6 available=1024 used=7168 with event: FINISHED
2013-08-07 09:10:51,485 INFO org.apache.hadoop.yarn.server.resourcemanager.rmcontainer.RMContainerImpl: container_1375865942038_0006_01_000042 Container Transitioned from NEW to ALLOCATED
2013-08-07 09:10:51,485 INFO org.apache.hadoop.yarn.server.resourcemanager.RMAuditLogger: USER=ubuntu	OPERATION=AM Allocated Container	TARGET=SchedulerApp	RESULT=SUCCESS	APPID=application_1375865942038_0006	CONTAINERID=container_1375865942038_0006_01_000042
2013-08-07 09:10:51,485 INFO org.apache.hadoop.yarn.server.resourcemanager.scheduler.common.fica.FiCaSchedulerNode: Assigned container container_1375865942038_0006_01_000042 of capacity <memory:1024, vCores:1> on host hadoop-200-7:54925, which currently has 7 containers, <memory:8192, vCores:7> used and <memory:0, vCores:9> available
2013-08-07 09:10:51,486 INFO org.apache.hadoop.yarn.server.resourcemanager.scheduler.capacity.LeafQueue: assignedContainer application=application_1375865942038_0006 container=Container: [ContainerId: container_1375865942038_0006_01_000042, NodeId: hadoop-200-7:54925, NodeHttpAddress: hadoop-200-7:8042, Resource: <memory:1024, vCores:1>, Priority: 10, State: NEW, Token: null, Status: container_id {, app_attempt_id {, application_id {, id: 6, cluster_timestamp: 1375865942038, }, attemptId: 1, }, id: 42, }, state: C_NEW, ] containerId=container_1375865942038_0006_01_000042 queue=default: capacity=1.0, absoluteCapacity=1.0, usedResources=<memory:48128, vCores:42>usedCapacity=0.9791667, absoluteUsedCapacity=0.9791667, numApps=5, numContainers=42 usedCapacity=0.9791667 absoluteUsedCapacity=0.9791667 used=<memory:48128, vCores:42> cluster=<memory:49152, vCores:96>
2013-08-07 09:10:51,487 INFO org.apache.hadoop.yarn.server.resourcemanager.scheduler.capacity.ParentQueue: Re-sorting queues since queue: root.default stats: default: capacity=1.0, absoluteCapacity=1.0, usedResources=<memory:49152, vCores:43>usedCapacity=1.0, absoluteUsedCapacity=1.0, numApps=5, numContainers=43
2013-08-07 09:10:51,487 INFO org.apache.hadoop.yarn.server.resourcemanager.scheduler.capacity.ParentQueue: assignedContainer queue=root usedCapacity=1.0 absoluteUsedCapacity=1.0 used=<memory:49152, vCores:43> cluster=<memory:49152, vCores:96>
2013-08-07 09:10:51,555 INFO org.apache.hadoop.yarn.server.resourcemanager.scheduler.AppSchedulingInfo: checking for deactivate... 
2013-08-07 09:10:51,556 INFO org.apache.hadoop.yarn.server.resourcemanager.rmcontainer.RMContainerImpl: container_1375865942038_0006_01_000042 Container Transitioned from ALLOCATED to ACQUIRED
2013-08-07 09:10:51,599 INFO org.apache.hadoop.yarn.server.resourcemanager.rmcontainer.RMContainerImpl: container_1375865942038_0007_01_000002 Container Transitioned from ACQUIRED to RUNNING
2013-08-07 09:10:52,506 INFO org.apache.hadoop.yarn.server.resourcemanager.rmcontainer.RMContainerImpl: container_1375865942038_0006_01_000042 Container Transitioned from ACQUIRED to RUNNING
2013-08-07 09:10:53,437 INFO org.apache.hadoop.yarn.server.resourcemanager.rmcontainer.RMContainerImpl: container_1375865942038_0006_01_000020 Container Transitioned from RUNNING to COMPLETED
2013-08-07 09:10:53,437 INFO org.apache.hadoop.yarn.server.resourcemanager.scheduler.common.fica.FiCaSchedulerApp: Completed container: container_1375865942038_0006_01_000020 in state: COMPLETED event:FINISHED
2013-08-07 09:10:53,437 INFO org.apache.hadoop.yarn.server.resourcemanager.RMAuditLogger: USER=ubuntu	OPERATION=AM Released Container	TARGET=SchedulerApp	RESULT=SUCCESS	APPID=application_1375865942038_0006	CONTAINERID=container_1375865942038_0006_01_000020
2013-08-07 09:10:53,437 INFO org.apache.hadoop.yarn.server.resourcemanager.scheduler.common.fica.FiCaSchedulerNode: Released container container_1375865942038_0006_01_000020 of capacity <memory:1024, vCores:1> on host hadoop-200-4:57320, which currently has 6 containers, <memory:7168, vCores:6> used and <memory:1024, vCores:10> available, release resources=true
2013-08-07 09:10:53,437 INFO org.apache.hadoop.yarn.server.resourcemanager.scheduler.capacity.LeafQueue: default used=<memory:48128, vCores:42> numContainers=42 user=ubuntu user-resources=<memory:48128, vCores:42>
2013-08-07 09:10:53,439 INFO org.apache.hadoop.yarn.server.resourcemanager.scheduler.capacity.LeafQueue: completedContainer container=Container: [ContainerId: container_1375865942038_0006_01_000020, NodeId: hadoop-200-4:57320, NodeHttpAddress: hadoop-200-4:8042, Resource: <memory:1024, vCores:1>, Priority: 20, State: NEW, Token: null, Status: container_id {, app_attempt_id {, application_id {, id: 6, cluster_timestamp: 1375865942038, }, attemptId: 1, }, id: 20, }, state: C_COMPLETE, diagnostics: "Container killed by the ApplicationMaster.\n", exit_status: 0, ] resource=<memory:1024, vCores:1> queue=default: capacity=1.0, absoluteCapacity=1.0, usedResources=<memory:48128, vCores:42>usedCapacity=0.9791667, absoluteUsedCapacity=0.9791667, numApps=5, numContainers=42 usedCapacity=0.9791667 absoluteUsedCapacity=0.9791667 used=<memory:48128, vCores:42> cluster=<memory:49152, vCores:96>
2013-08-07 09:10:53,439 INFO org.apache.hadoop.yarn.server.resourcemanager.scheduler.capacity.ParentQueue: completedContainer queue=root usedCapacity=0.9791667 absoluteUsedCapacity=0.9791667 used=<memory:48128, vCores:42> cluster=<memory:49152, vCores:96>
2013-08-07 09:10:53,439 INFO org.apache.hadoop.yarn.server.resourcemanager.scheduler.capacity.CapacityScheduler: Application appattempt_1375865942038_0006_000001 released container container_1375865942038_0006_01_000020 on node: host: hadoop-200-4:57320 #containers=6 available=1024 used=7168 with event: FINISHED
2013-08-07 09:10:53,439 INFO org.apache.hadoop.yarn.server.resourcemanager.rmcontainer.RMContainerImpl: container_1375865942038_0006_01_000043 Container Transitioned from NEW to ALLOCATED
2013-08-07 09:10:53,440 INFO org.apache.hadoop.yarn.server.resourcemanager.RMAuditLogger: USER=ubuntu	OPERATION=AM Allocated Container	TARGET=SchedulerApp	RESULT=SUCCESS	APPID=application_1375865942038_0006	CONTAINERID=container_1375865942038_0006_01_000043
2013-08-07 09:10:53,440 INFO org.apache.hadoop.yarn.server.resourcemanager.scheduler.common.fica.FiCaSchedulerNode: Assigned container container_1375865942038_0006_01_000043 of capacity <memory:1024, vCores:1> on host hadoop-200-4:57320, which currently has 7 containers, <memory:8192, vCores:7> used and <memory:0, vCores:9> available
2013-08-07 09:10:53,441 INFO org.apache.hadoop.yarn.server.resourcemanager.scheduler.capacity.LeafQueue: assignedContainer application=application_1375865942038_0006 container=Container: [ContainerId: container_1375865942038_0006_01_000043, NodeId: hadoop-200-4:57320, NodeHttpAddress: hadoop-200-4:8042, Resource: <memory:1024, vCores:1>, Priority: 10, State: NEW, Token: null, Status: container_id {, app_attempt_id {, application_id {, id: 6, cluster_timestamp: 1375865942038, }, attemptId: 1, }, id: 43, }, state: C_NEW, ] containerId=container_1375865942038_0006_01_000043 queue=default: capacity=1.0, absoluteCapacity=1.0, usedResources=<memory:48128, vCores:42>usedCapacity=0.9791667, absoluteUsedCapacity=0.9791667, numApps=5, numContainers=42 usedCapacity=0.9791667 absoluteUsedCapacity=0.9791667 used=<memory:48128, vCores:42> cluster=<memory:49152, vCores:96>
2013-08-07 09:10:53,441 INFO org.apache.hadoop.yarn.server.resourcemanager.scheduler.capacity.ParentQueue: Re-sorting queues since queue: root.default stats: default: capacity=1.0, absoluteCapacity=1.0, usedResources=<memory:49152, vCores:43>usedCapacity=1.0, absoluteUsedCapacity=1.0, numApps=5, numContainers=43
2013-08-07 09:10:53,441 INFO org.apache.hadoop.yarn.server.resourcemanager.scheduler.capacity.ParentQueue: assignedContainer queue=root usedCapacity=1.0 absoluteUsedCapacity=1.0 used=<memory:49152, vCores:43> cluster=<memory:49152, vCores:96>
2013-08-07 09:10:53,460 INFO org.apache.hadoop.yarn.server.resourcemanager.rmcontainer.RMContainerImpl: container_1375865942038_0006_01_000022 Container Transitioned from RUNNING to COMPLETED
2013-08-07 09:10:53,460 INFO org.apache.hadoop.yarn.server.resourcemanager.scheduler.common.fica.FiCaSchedulerApp: Completed container: container_1375865942038_0006_01_000022 in state: COMPLETED event:FINISHED
2013-08-07 09:10:53,461 INFO org.apache.hadoop.yarn.server.resourcemanager.RMAuditLogger: USER=ubuntu	OPERATION=AM Released Container	TARGET=SchedulerApp	RESULT=SUCCESS	APPID=application_1375865942038_0006	CONTAINERID=container_1375865942038_0006_01_000022
2013-08-07 09:10:53,461 INFO org.apache.hadoop.yarn.server.resourcemanager.scheduler.common.fica.FiCaSchedulerNode: Released container container_1375865942038_0006_01_000022 of capacity <memory:1024, vCores:1> on host hadoop-200-2:58832, which currently has 6 containers, <memory:7168, vCores:6> used and <memory:1024, vCores:10> available, release resources=true
2013-08-07 09:10:53,461 INFO org.apache.hadoop.yarn.server.resourcemanager.scheduler.capacity.LeafQueue: default used=<memory:48128, vCores:42> numContainers=42 user=ubuntu user-resources=<memory:48128, vCores:42>
2013-08-07 09:10:53,462 INFO org.apache.hadoop.yarn.server.resourcemanager.scheduler.capacity.LeafQueue: completedContainer container=Container: [ContainerId: container_1375865942038_0006_01_000022, NodeId: hadoop-200-2:58832, NodeHttpAddress: hadoop-200-2:8042, Resource: <memory:1024, vCores:1>, Priority: 20, State: NEW, Token: null, Status: container_id {, app_attempt_id {, application_id {, id: 6, cluster_timestamp: 1375865942038, }, attemptId: 1, }, id: 22, }, state: C_COMPLETE, diagnostics: "", exit_status: 0, ] resource=<memory:1024, vCores:1> queue=default: capacity=1.0, absoluteCapacity=1.0, usedResources=<memory:48128, vCores:42>usedCapacity=0.9791667, absoluteUsedCapacity=0.9791667, numApps=5, numContainers=42 usedCapacity=0.9791667 absoluteUsedCapacity=0.9791667 used=<memory:48128, vCores:42> cluster=<memory:49152, vCores:96>
2013-08-07 09:10:53,462 INFO org.apache.hadoop.yarn.server.resourcemanager.scheduler.capacity.ParentQueue: completedContainer queue=root usedCapacity=0.9791667 absoluteUsedCapacity=0.9791667 used=<memory:48128, vCores:42> cluster=<memory:49152, vCores:96>
2013-08-07 09:10:53,462 INFO org.apache.hadoop.yarn.server.resourcemanager.scheduler.capacity.CapacityScheduler: Application appattempt_1375865942038_0006_000001 released container container_1375865942038_0006_01_000022 on node: host: hadoop-200-2:58832 #containers=6 available=1024 used=7168 with event: FINISHED
2013-08-07 09:10:53,462 INFO org.apache.hadoop.yarn.server.resourcemanager.rmcontainer.RMContainerImpl: container_1375865942038_0006_01_000024 Container Transitioned from RUNNING to COMPLETED
2013-08-07 09:10:53,463 INFO org.apache.hadoop.yarn.server.resourcemanager.scheduler.common.fica.FiCaSchedulerApp: Completed container: container_1375865942038_0006_01_000024 in state: COMPLETED event:FINISHED
2013-08-07 09:10:53,463 INFO org.apache.hadoop.yarn.server.resourcemanager.RMAuditLogger: USER=ubuntu	OPERATION=AM Released Container	TARGET=SchedulerApp	RESULT=SUCCESS	APPID=application_1375865942038_0006	CONTAINERID=container_1375865942038_0006_01_000024
2013-08-07 09:10:53,463 INFO org.apache.hadoop.yarn.server.resourcemanager.scheduler.common.fica.FiCaSchedulerNode: Released container container_1375865942038_0006_01_000024 of capacity <memory:1024, vCores:1> on host hadoop-200-2:58832, which currently has 5 containers, <memory:6144, vCores:5> used and <memory:2048, vCores:11> available, release resources=true
2013-08-07 09:10:53,463 INFO org.apache.hadoop.yarn.server.resourcemanager.scheduler.capacity.LeafQueue: default used=<memory:47104, vCores:41> numContainers=41 user=ubuntu user-resources=<memory:47104, vCores:41>
2013-08-07 09:10:53,464 INFO org.apache.hadoop.yarn.server.resourcemanager.scheduler.capacity.LeafQueue: completedContainer container=Container: [ContainerId: container_1375865942038_0006_01_000024, NodeId: hadoop-200-2:58832, NodeHttpAddress: hadoop-200-2:8042, Resource: <memory:1024, vCores:1>, Priority: 20, State: NEW, Token: null, Status: container_id {, app_attempt_id {, application_id {, id: 6, cluster_timestamp: 1375865942038, }, attemptId: 1, }, id: 24, }, state: C_COMPLETE, diagnostics: "Container killed by the ApplicationMaster.\n", exit_status: 0, ] resource=<memory:1024, vCores:1> queue=default: capacity=1.0, absoluteCapacity=1.0, usedResources=<memory:47104, vCores:41>usedCapacity=0.9583333, absoluteUsedCapacity=0.9583333, numApps=5, numContainers=41 usedCapacity=0.9583333 absoluteUsedCapacity=0.9583333 used=<memory:47104, vCores:41> cluster=<memory:49152, vCores:96>
2013-08-07 09:10:53,464 INFO org.apache.hadoop.yarn.server.resourcemanager.scheduler.capacity.ParentQueue: completedContainer queue=root usedCapacity=0.9583333 absoluteUsedCapacity=0.9583333 used=<memory:47104, vCores:41> cluster=<memory:49152, vCores:96>
2013-08-07 09:10:53,464 INFO org.apache.hadoop.yarn.server.resourcemanager.scheduler.capacity.CapacityScheduler: Application appattempt_1375865942038_0006_000001 released container container_1375865942038_0006_01_000024 on node: host: hadoop-200-2:58832 #containers=5 available=2048 used=6144 with event: FINISHED
2013-08-07 09:10:53,464 INFO org.apache.hadoop.yarn.server.resourcemanager.rmcontainer.RMContainerImpl: container_1375865942038_0006_01_000027 Container Transitioned from RUNNING to COMPLETED
2013-08-07 09:10:53,465 INFO org.apache.hadoop.yarn.server.resourcemanager.scheduler.common.fica.FiCaSchedulerApp: Completed container: container_1375865942038_0006_01_000027 in state: COMPLETED event:FINISHED
2013-08-07 09:10:53,465 INFO org.apache.hadoop.yarn.server.resourcemanager.RMAuditLogger: USER=ubuntu	OPERATION=AM Released Container	TARGET=SchedulerApp	RESULT=SUCCESS	APPID=application_1375865942038_0006	CONTAINERID=container_1375865942038_0006_01_000027
2013-08-07 09:10:53,465 INFO org.apache.hadoop.yarn.server.resourcemanager.scheduler.common.fica.FiCaSchedulerNode: Released container container_1375865942038_0006_01_000027 of capacity <memory:1024, vCores:1> on host hadoop-200-2:58832, which currently has 4 containers, <memory:5120, vCores:4> used and <memory:3072, vCores:12> available, release resources=true
2013-08-07 09:10:53,465 INFO org.apache.hadoop.yarn.server.resourcemanager.scheduler.capacity.LeafQueue: default used=<memory:46080, vCores:40> numContainers=40 user=ubuntu user-resources=<memory:46080, vCores:40>
2013-08-07 09:10:53,466 INFO org.apache.hadoop.yarn.server.resourcemanager.scheduler.capacity.LeafQueue: completedContainer container=Container: [ContainerId: container_1375865942038_0006_01_000027, NodeId: hadoop-200-2:58832, NodeHttpAddress: hadoop-200-2:8042, Resource: <memory:1024, vCores:1>, Priority: 20, State: NEW, Token: null, Status: container_id {, app_attempt_id {, application_id {, id: 6, cluster_timestamp: 1375865942038, }, attemptId: 1, }, id: 27, }, state: C_COMPLETE, diagnostics: "Container killed by the ApplicationMaster.\n", exit_status: 0, ] resource=<memory:1024, vCores:1> queue=default: capacity=1.0, absoluteCapacity=1.0, usedResources=<memory:46080, vCores:40>usedCapacity=0.9375, absoluteUsedCapacity=0.9375, numApps=5, numContainers=40 usedCapacity=0.9375 absoluteUsedCapacity=0.9375 used=<memory:46080, vCores:40> cluster=<memory:49152, vCores:96>
2013-08-07 09:10:53,466 INFO org.apache.hadoop.yarn.server.resourcemanager.scheduler.capacity.ParentQueue: completedContainer queue=root usedCapacity=0.9375 absoluteUsedCapacity=0.9375 used=<memory:46080, vCores:40> cluster=<memory:49152, vCores:96>
2013-08-07 09:10:53,466 INFO org.apache.hadoop.yarn.server.resourcemanager.scheduler.capacity.CapacityScheduler: Application appattempt_1375865942038_0006_000001 released container container_1375865942038_0006_01_000027 on node: host: hadoop-200-2:58832 #containers=4 available=3072 used=5120 with event: FINISHED
2013-08-07 09:10:53,467 INFO org.apache.hadoop.yarn.server.resourcemanager.rmcontainer.RMContainerImpl: container_1375865942038_0006_01_000044 Container Transitioned from NEW to ALLOCATED
2013-08-07 09:10:53,467 INFO org.apache.hadoop.yarn.server.resourcemanager.RMAuditLogger: USER=ubuntu	OPERATION=AM Allocated Container	TARGET=SchedulerApp	RESULT=SUCCESS	APPID=application_1375865942038_0006	CONTAINERID=container_1375865942038_0006_01_000044
2013-08-07 09:10:53,467 INFO org.apache.hadoop.yarn.server.resourcemanager.scheduler.common.fica.FiCaSchedulerNode: Assigned container container_1375865942038_0006_01_000044 of capacity <memory:1024, vCores:1> on host hadoop-200-2:58832, which currently has 5 containers, <memory:6144, vCores:5> used and <memory:2048, vCores:11> available
2013-08-07 09:10:53,468 INFO org.apache.hadoop.yarn.server.resourcemanager.scheduler.capacity.LeafQueue: assignedContainer application=application_1375865942038_0006 container=Container: [ContainerId: container_1375865942038_0006_01_000044, NodeId: hadoop-200-2:58832, NodeHttpAddress: hadoop-200-2:8042, Resource: <memory:1024, vCores:1>, Priority: 10, State: NEW, Token: null, Status: container_id {, app_attempt_id {, application_id {, id: 6, cluster_timestamp: 1375865942038, }, attemptId: 1, }, id: 44, }, state: C_NEW, ] containerId=container_1375865942038_0006_01_000044 queue=default: capacity=1.0, absoluteCapacity=1.0, usedResources=<memory:46080, vCores:40>usedCapacity=0.9375, absoluteUsedCapacity=0.9375, numApps=5, numContainers=40 usedCapacity=0.9375 absoluteUsedCapacity=0.9375 used=<memory:46080, vCores:40> cluster=<memory:49152, vCores:96>
2013-08-07 09:10:53,468 INFO org.apache.hadoop.yarn.server.resourcemanager.scheduler.capacity.ParentQueue: Re-sorting queues since queue: root.default stats: default: capacity=1.0, absoluteCapacity=1.0, usedResources=<memory:47104, vCores:41>usedCapacity=0.9583333, absoluteUsedCapacity=0.9583333, numApps=5, numContainers=41
2013-08-07 09:10:53,468 INFO org.apache.hadoop.yarn.server.resourcemanager.scheduler.capacity.ParentQueue: assignedContainer queue=root usedCapacity=0.9583333 absoluteUsedCapacity=0.9583333 used=<memory:47104, vCores:41> cluster=<memory:49152, vCores:96>
2013-08-07 09:10:53,680 INFO org.apache.hadoop.yarn.server.resourcemanager.rmcontainer.RMContainerImpl: container_1375865942038_0006_01_000037 Container Transitioned from RUNNING to COMPLETED
2013-08-07 09:10:53,680 INFO org.apache.hadoop.yarn.server.resourcemanager.scheduler.common.fica.FiCaSchedulerApp: Completed container: container_1375865942038_0006_01_000037 in state: COMPLETED event:FINISHED
2013-08-07 09:10:53,680 INFO org.apache.hadoop.yarn.server.resourcemanager.RMAuditLogger: USER=ubuntu	OPERATION=AM Released Container	TARGET=SchedulerApp	RESULT=SUCCESS	APPID=application_1375865942038_0006	CONTAINERID=container_1375865942038_0006_01_000037
2013-08-07 09:10:53,680 INFO org.apache.hadoop.yarn.server.resourcemanager.scheduler.common.fica.FiCaSchedulerNode: Released container container_1375865942038_0006_01_000037 of capacity <memory:1024, vCores:1> on host hadoop-200-6:52835, which currently has 6 containers, <memory:7168, vCores:6> used and <memory:1024, vCores:10> available, release resources=true
2013-08-07 09:10:53,680 INFO org.apache.hadoop.yarn.server.resourcemanager.scheduler.capacity.LeafQueue: default used=<memory:46080, vCores:40> numContainers=40 user=ubuntu user-resources=<memory:46080, vCores:40>
2013-08-07 09:10:53,682 INFO org.apache.hadoop.yarn.server.resourcemanager.scheduler.capacity.LeafQueue: completedContainer container=Container: [ContainerId: container_1375865942038_0006_01_000037, NodeId: hadoop-200-6:52835, NodeHttpAddress: hadoop-200-6:8042, Resource: <memory:1024, vCores:1>, Priority: 20, State: NEW, Token: null, Status: container_id {, app_attempt_id {, application_id {, id: 6, cluster_timestamp: 1375865942038, }, attemptId: 1, }, id: 37, }, state: C_COMPLETE, diagnostics: "Container killed by the ApplicationMaster.\n\n", exit_status: 143, ] resource=<memory:1024, vCores:1> queue=default: capacity=1.0, absoluteCapacity=1.0, usedResources=<memory:46080, vCores:40>usedCapacity=0.9375, absoluteUsedCapacity=0.9375, numApps=5, numContainers=40 usedCapacity=0.9375 absoluteUsedCapacity=0.9375 used=<memory:46080, vCores:40> cluster=<memory:49152, vCores:96>
2013-08-07 09:10:53,682 INFO org.apache.hadoop.yarn.server.resourcemanager.scheduler.capacity.ParentQueue: completedContainer queue=root usedCapacity=0.9375 absoluteUsedCapacity=0.9375 used=<memory:46080, vCores:40> cluster=<memory:49152, vCores:96>
2013-08-07 09:10:53,682 INFO org.apache.hadoop.yarn.server.resourcemanager.scheduler.capacity.CapacityScheduler: Application appattempt_1375865942038_0006_000001 released container container_1375865942038_0006_01_000037 on node: host: hadoop-200-6:52835 #containers=6 available=1024 used=7168 with event: FINISHED
2013-08-07 09:10:53,682 INFO org.apache.hadoop.yarn.server.resourcemanager.rmcontainer.RMContainerImpl: container_1375865942038_0006_01_000045 Container Transitioned from NEW to ALLOCATED
2013-08-07 09:10:53,683 INFO org.apache.hadoop.yarn.server.resourcemanager.RMAuditLogger: USER=ubuntu	OPERATION=AM Allocated Container	TARGET=SchedulerApp	RESULT=SUCCESS	APPID=application_1375865942038_0006	CONTAINERID=container_1375865942038_0006_01_000045
2013-08-07 09:10:53,683 INFO org.apache.hadoop.yarn.server.resourcemanager.scheduler.common.fica.FiCaSchedulerNode: Assigned container container_1375865942038_0006_01_000045 of capacity <memory:1024, vCores:1> on host hadoop-200-6:52835, which currently has 7 containers, <memory:8192, vCores:7> used and <memory:0, vCores:9> available
2013-08-07 09:10:53,684 INFO org.apache.hadoop.yarn.server.resourcemanager.scheduler.capacity.LeafQueue: assignedContainer application=application_1375865942038_0006 container=Container: [ContainerId: container_1375865942038_0006_01_000045, NodeId: hadoop-200-6:52835, NodeHttpAddress: hadoop-200-6:8042, Resource: <memory:1024, vCores:1>, Priority: 10, State: NEW, Token: null, Status: container_id {, app_attempt_id {, application_id {, id: 6, cluster_timestamp: 1375865942038, }, attemptId: 1, }, id: 45, }, state: C_NEW, ] containerId=container_1375865942038_0006_01_000045 queue=default: capacity=1.0, absoluteCapacity=1.0, usedResources=<memory:46080, vCores:40>usedCapacity=0.9375, absoluteUsedCapacity=0.9375, numApps=5, numContainers=40 usedCapacity=0.9375 absoluteUsedCapacity=0.9375 used=<memory:46080, vCores:40> cluster=<memory:49152, vCores:96>
2013-08-07 09:10:53,684 INFO org.apache.hadoop.yarn.server.resourcemanager.scheduler.capacity.ParentQueue: Re-sorting queues since queue: root.default stats: default: capacity=1.0, absoluteCapacity=1.0, usedResources=<memory:47104, vCores:41>usedCapacity=0.9583333, absoluteUsedCapacity=0.9583333, numApps=5, numContainers=41
2013-08-07 09:10:53,684 INFO org.apache.hadoop.yarn.server.resourcemanager.scheduler.capacity.ParentQueue: assignedContainer queue=root usedCapacity=0.9583333 absoluteUsedCapacity=0.9583333 used=<memory:47104, vCores:41> cluster=<memory:49152, vCores:96>
2013-08-07 09:10:53,816 INFO org.apache.hadoop.yarn.server.resourcemanager.rmcontainer.RMContainerImpl: container_1375865942038_0006_01_000002 Container Transitioned from RUNNING to COMPLETED
2013-08-07 09:10:53,817 INFO org.apache.hadoop.yarn.server.resourcemanager.scheduler.common.fica.FiCaSchedulerApp: Completed container: container_1375865942038_0006_01_000002 in state: COMPLETED event:FINISHED
2013-08-07 09:10:53,817 INFO org.apache.hadoop.yarn.server.resourcemanager.RMAuditLogger: USER=ubuntu	OPERATION=AM Released Container	TARGET=SchedulerApp	RESULT=SUCCESS	APPID=application_1375865942038_0006	CONTAINERID=container_1375865942038_0006_01_000002
2013-08-07 09:10:53,817 INFO org.apache.hadoop.yarn.server.resourcemanager.scheduler.common.fica.FiCaSchedulerNode: Released container container_1375865942038_0006_01_000002 of capacity <memory:1024, vCores:1> on host hadoop-200-7:54925, which currently has 6 containers, <memory:7168, vCores:6> used and <memory:1024, vCores:10> available, release resources=true
2013-08-07 09:10:53,817 INFO org.apache.hadoop.yarn.server.resourcemanager.scheduler.capacity.LeafQueue: default used=<memory:46080, vCores:40> numContainers=40 user=ubuntu user-resources=<memory:46080, vCores:40>
2013-08-07 09:10:53,818 INFO org.apache.hadoop.yarn.server.resourcemanager.scheduler.capacity.LeafQueue: completedContainer container=Container: [ContainerId: container_1375865942038_0006_01_000002, NodeId: hadoop-200-7:54925, NodeHttpAddress: hadoop-200-7:8042, Resource: <memory:1024, vCores:1>, Priority: 20, State: NEW, Token: null, Status: container_id {, app_attempt_id {, application_id {, id: 6, cluster_timestamp: 1375865942038, }, attemptId: 1, }, id: 2, }, state: C_COMPLETE, diagnostics: "Container killed by the ApplicationMaster.\n\n", exit_status: 143, ] resource=<memory:1024, vCores:1> queue=default: capacity=1.0, absoluteCapacity=1.0, usedResources=<memory:46080, vCores:40>usedCapacity=0.9375, absoluteUsedCapacity=0.9375, numApps=5, numContainers=40 usedCapacity=0.9375 absoluteUsedCapacity=0.9375 used=<memory:46080, vCores:40> cluster=<memory:49152, vCores:96>
2013-08-07 09:10:53,818 INFO org.apache.hadoop.yarn.server.resourcemanager.scheduler.capacity.ParentQueue: completedContainer queue=root usedCapacity=0.9375 absoluteUsedCapacity=0.9375 used=<memory:46080, vCores:40> cluster=<memory:49152, vCores:96>
2013-08-07 09:10:53,818 INFO org.apache.hadoop.yarn.server.resourcemanager.scheduler.capacity.CapacityScheduler: Application appattempt_1375865942038_0006_000001 released container container_1375865942038_0006_01_000002 on node: host: hadoop-200-7:54925 #containers=6 available=1024 used=7168 with event: FINISHED
2013-08-07 09:10:53,819 INFO org.apache.hadoop.yarn.server.resourcemanager.rmcontainer.RMContainerImpl: container_1375865942038_0006_01_000046 Container Transitioned from NEW to ALLOCATED
2013-08-07 09:10:53,819 INFO org.apache.hadoop.yarn.server.resourcemanager.RMAuditLogger: USER=ubuntu	OPERATION=AM Allocated Container	TARGET=SchedulerApp	RESULT=SUCCESS	APPID=application_1375865942038_0006	CONTAINERID=container_1375865942038_0006_01_000046
2013-08-07 09:10:53,819 INFO org.apache.hadoop.yarn.server.resourcemanager.scheduler.common.fica.FiCaSchedulerNode: Assigned container container_1375865942038_0006_01_000046 of capacity <memory:1024, vCores:1> on host hadoop-200-7:54925, which currently has 7 containers, <memory:8192, vCores:7> used and <memory:0, vCores:9> available
2013-08-07 09:10:53,820 INFO org.apache.hadoop.yarn.server.resourcemanager.scheduler.capacity.LeafQueue: assignedContainer application=application_1375865942038_0006 container=Container: [ContainerId: container_1375865942038_0006_01_000046, NodeId: hadoop-200-7:54925, NodeHttpAddress: hadoop-200-7:8042, Resource: <memory:1024, vCores:1>, Priority: 10, State: NEW, Token: null, Status: container_id {, app_attempt_id {, application_id {, id: 6, cluster_timestamp: 1375865942038, }, attemptId: 1, }, id: 46, }, state: C_NEW, ] containerId=container_1375865942038_0006_01_000046 queue=default: capacity=1.0, absoluteCapacity=1.0, usedResources=<memory:46080, vCores:40>usedCapacity=0.9375, absoluteUsedCapacity=0.9375, numApps=5, numContainers=40 usedCapacity=0.9375 absoluteUsedCapacity=0.9375 used=<memory:46080, vCores:40> cluster=<memory:49152, vCores:96>
2013-08-07 09:10:53,820 INFO org.apache.hadoop.yarn.server.resourcemanager.scheduler.capacity.ParentQueue: Re-sorting queues since queue: root.default stats: default: capacity=1.0, absoluteCapacity=1.0, usedResources=<memory:47104, vCores:41>usedCapacity=0.9583333, absoluteUsedCapacity=0.9583333, numApps=5, numContainers=41
2013-08-07 09:10:53,820 INFO org.apache.hadoop.yarn.server.resourcemanager.scheduler.capacity.ParentQueue: assignedContainer queue=root usedCapacity=0.9583333 absoluteUsedCapacity=0.9583333 used=<memory:47104, vCores:41> cluster=<memory:49152, vCores:96>
2013-08-07 09:10:54,297 INFO org.apache.hadoop.yarn.server.resourcemanager.rmcontainer.RMContainerImpl: container_1375865942038_0006_01_000043 Container Transitioned from ALLOCATED to ACQUIRED
2013-08-07 09:10:54,298 INFO org.apache.hadoop.yarn.server.resourcemanager.rmcontainer.RMContainerImpl: container_1375865942038_0006_01_000044 Container Transitioned from ALLOCATED to ACQUIRED
2013-08-07 09:10:54,298 INFO org.apache.hadoop.yarn.server.resourcemanager.rmcontainer.RMContainerImpl: container_1375865942038_0006_01_000045 Container Transitioned from ALLOCATED to ACQUIRED
2013-08-07 09:10:54,299 INFO org.apache.hadoop.yarn.server.resourcemanager.rmcontainer.RMContainerImpl: container_1375865942038_0006_01_000046 Container Transitioned from ALLOCATED to ACQUIRED
2013-08-07 09:10:54,446 INFO org.apache.hadoop.yarn.server.resourcemanager.rmcontainer.RMContainerImpl: container_1375865942038_0006_01_000043 Container Transitioned from ACQUIRED to RUNNING
2013-08-07 09:10:54,469 INFO org.apache.hadoop.yarn.server.resourcemanager.rmcontainer.RMContainerImpl: container_1375865942038_0006_01_000044 Container Transitioned from ACQUIRED to RUNNING
2013-08-07 09:10:54,470 INFO org.apache.hadoop.yarn.server.resourcemanager.rmcontainer.RMContainerImpl: container_1375865942038_0007_01_000003 Container Transitioned from NEW to ALLOCATED
2013-08-07 09:10:54,470 INFO org.apache.hadoop.yarn.server.resourcemanager.RMAuditLogger: USER=ubuntu	OPERATION=AM Allocated Container	TARGET=SchedulerApp	RESULT=SUCCESS	APPID=application_1375865942038_0007	CONTAINERID=container_1375865942038_0007_01_000003
2013-08-07 09:10:54,470 INFO org.apache.hadoop.yarn.server.resourcemanager.scheduler.common.fica.FiCaSchedulerNode: Assigned container container_1375865942038_0007_01_000003 of capacity <memory:1024, vCores:1> on host hadoop-200-2:58832, which currently has 6 containers, <memory:7168, vCores:6> used and <memory:1024, vCores:10> available
2013-08-07 09:10:54,471 INFO org.apache.hadoop.yarn.server.resourcemanager.scheduler.capacity.LeafQueue: assignedContainer application=application_1375865942038_0007 container=Container: [ContainerId: container_1375865942038_0007_01_000003, NodeId: hadoop-200-2:58832, NodeHttpAddress: hadoop-200-2:8042, Resource: <memory:1024, vCores:1>, Priority: 20, State: NEW, Token: null, Status: container_id {, app_attempt_id {, application_id {, id: 7, cluster_timestamp: 1375865942038, }, attemptId: 1, }, id: 3, }, state: C_NEW, ] containerId=container_1375865942038_0007_01_000003 queue=default: capacity=1.0, absoluteCapacity=1.0, usedResources=<memory:47104, vCores:41>usedCapacity=0.9583333, absoluteUsedCapacity=0.9583333, numApps=5, numContainers=41 usedCapacity=0.9583333 absoluteUsedCapacity=0.9583333 used=<memory:47104, vCores:41> cluster=<memory:49152, vCores:96>
2013-08-07 09:10:54,471 INFO org.apache.hadoop.yarn.server.resourcemanager.scheduler.capacity.ParentQueue: Re-sorting queues since queue: root.default stats: default: capacity=1.0, absoluteCapacity=1.0, usedResources=<memory:48128, vCores:42>usedCapacity=0.9791667, absoluteUsedCapacity=0.9791667, numApps=5, numContainers=42
2013-08-07 09:10:54,471 INFO org.apache.hadoop.yarn.server.resourcemanager.scheduler.capacity.ParentQueue: assignedContainer queue=root usedCapacity=0.9791667 absoluteUsedCapacity=0.9791667 used=<memory:48128, vCores:42> cluster=<memory:49152, vCores:96>
2013-08-07 09:10:54,472 INFO org.apache.hadoop.yarn.server.resourcemanager.rmcontainer.RMContainerImpl: container_1375865942038_0007_01_000004 Container Transitioned from NEW to ALLOCATED
2013-08-07 09:10:54,472 INFO org.apache.hadoop.yarn.server.resourcemanager.RMAuditLogger: USER=ubuntu	OPERATION=AM Allocated Container	TARGET=SchedulerApp	RESULT=SUCCESS	APPID=application_1375865942038_0007	CONTAINERID=container_1375865942038_0007_01_000004
2013-08-07 09:10:54,472 INFO org.apache.hadoop.yarn.server.resourcemanager.scheduler.common.fica.FiCaSchedulerNode: Assigned container container_1375865942038_0007_01_000004 of capacity <memory:1024, vCores:1> on host hadoop-200-2:58832, which currently has 7 containers, <memory:8192, vCores:7> used and <memory:0, vCores:9> available
2013-08-07 09:10:54,473 INFO org.apache.hadoop.yarn.server.resourcemanager.scheduler.capacity.LeafQueue: assignedContainer application=application_1375865942038_0007 container=Container: [ContainerId: container_1375865942038_0007_01_000004, NodeId: hadoop-200-2:58832, NodeHttpAddress: hadoop-200-2:8042, Resource: <memory:1024, vCores:1>, Priority: 20, State: NEW, Token: null, Status: container_id {, app_attempt_id {, application_id {, id: 7, cluster_timestamp: 1375865942038, }, attemptId: 1, }, id: 4, }, state: C_NEW, ] containerId=container_1375865942038_0007_01_000004 queue=default: capacity=1.0, absoluteCapacity=1.0, usedResources=<memory:48128, vCores:42>usedCapacity=0.9791667, absoluteUsedCapacity=0.9791667, numApps=5, numContainers=42 usedCapacity=0.9791667 absoluteUsedCapacity=0.9791667 used=<memory:48128, vCores:42> cluster=<memory:49152, vCores:96>
2013-08-07 09:10:54,473 INFO org.apache.hadoop.yarn.server.resourcemanager.scheduler.capacity.ParentQueue: Re-sorting queues since queue: root.default stats: default: capacity=1.0, absoluteCapacity=1.0, usedResources=<memory:49152, vCores:43>usedCapacity=1.0, absoluteUsedCapacity=1.0, numApps=5, numContainers=43
2013-08-07 09:10:54,473 INFO org.apache.hadoop.yarn.server.resourcemanager.scheduler.capacity.ParentQueue: assignedContainer queue=root usedCapacity=1.0 absoluteUsedCapacity=1.0 used=<memory:49152, vCores:43> cluster=<memory:49152, vCores:96>
2013-08-07 09:10:54,712 INFO org.apache.hadoop.yarn.server.resourcemanager.rmcontainer.RMContainerImpl: container_1375865942038_0006_01_000045 Container Transitioned from ACQUIRED to RUNNING
2013-08-07 09:10:54,828 INFO org.apache.hadoop.yarn.server.resourcemanager.rmcontainer.RMContainerImpl: container_1375865942038_0006_01_000046 Container Transitioned from ACQUIRED to RUNNING
2013-08-07 09:10:54,828 INFO org.apache.hadoop.yarn.server.resourcemanager.rmcontainer.RMContainerImpl: container_1375865942038_0006_01_000006 Container Transitioned from RUNNING to COMPLETED
2013-08-07 09:10:54,828 INFO org.apache.hadoop.yarn.server.resourcemanager.scheduler.common.fica.FiCaSchedulerApp: Completed container: container_1375865942038_0006_01_000006 in state: COMPLETED event:FINISHED
2013-08-07 09:10:54,828 INFO org.apache.hadoop.yarn.server.resourcemanager.RMAuditLogger: USER=ubuntu	OPERATION=AM Released Container	TARGET=SchedulerApp	RESULT=SUCCESS	APPID=application_1375865942038_0006	CONTAINERID=container_1375865942038_0006_01_000006
2013-08-07 09:10:54,828 INFO org.apache.hadoop.yarn.server.resourcemanager.scheduler.common.fica.FiCaSchedulerNode: Released container container_1375865942038_0006_01_000006 of capacity <memory:1024, vCores:1> on host hadoop-200-7:54925, which currently has 6 containers, <memory:7168, vCores:6> used and <memory:1024, vCores:10> available, release resources=true
2013-08-07 09:10:54,829 INFO org.apache.hadoop.yarn.server.resourcemanager.scheduler.capacity.LeafQueue: default used=<memory:48128, vCores:42> numContainers=42 user=ubuntu user-resources=<memory:48128, vCores:42>
2013-08-07 09:10:54,830 INFO org.apache.hadoop.yarn.server.resourcemanager.scheduler.capacity.LeafQueue: completedContainer container=Container: [ContainerId: container_1375865942038_0006_01_000006, NodeId: hadoop-200-7:54925, NodeHttpAddress: hadoop-200-7:8042, Resource: <memory:1024, vCores:1>, Priority: 20, State: NEW, Token: null, Status: container_id {, app_attempt_id {, application_id {, id: 6, cluster_timestamp: 1375865942038, }, attemptId: 1, }, id: 6, }, state: C_COMPLETE, diagnostics: "Container killed by the ApplicationMaster.\n\n", exit_status: 143, ] resource=<memory:1024, vCores:1> queue=default: capacity=1.0, absoluteCapacity=1.0, usedResources=<memory:48128, vCores:42>usedCapacity=0.9791667, absoluteUsedCapacity=0.9791667, numApps=5, numContainers=42 usedCapacity=0.9791667 absoluteUsedCapacity=0.9791667 used=<memory:48128, vCores:42> cluster=<memory:49152, vCores:96>
2013-08-07 09:10:54,830 INFO org.apache.hadoop.yarn.server.resourcemanager.scheduler.capacity.ParentQueue: completedContainer queue=root usedCapacity=0.9791667 absoluteUsedCapacity=0.9791667 used=<memory:48128, vCores:42> cluster=<memory:49152, vCores:96>
2013-08-07 09:10:54,830 INFO org.apache.hadoop.yarn.server.resourcemanager.scheduler.capacity.CapacityScheduler: Application appattempt_1375865942038_0006_000001 released container container_1375865942038_0006_01_000006 on node: host: hadoop-200-7:54925 #containers=6 available=1024 used=7168 with event: FINISHED
2013-08-07 09:10:54,830 INFO org.apache.hadoop.yarn.server.resourcemanager.rmcontainer.RMContainerImpl: container_1375865942038_0007_01_000005 Container Transitioned from NEW to ALLOCATED
2013-08-07 09:10:54,831 INFO org.apache.hadoop.yarn.server.resourcemanager.RMAuditLogger: USER=ubuntu	OPERATION=AM Allocated Container	TARGET=SchedulerApp	RESULT=SUCCESS	APPID=application_1375865942038_0007	CONTAINERID=container_1375865942038_0007_01_000005
2013-08-07 09:10:54,831 INFO org.apache.hadoop.yarn.server.resourcemanager.scheduler.common.fica.FiCaSchedulerNode: Assigned container container_1375865942038_0007_01_000005 of capacity <memory:1024, vCores:1> on host hadoop-200-7:54925, which currently has 7 containers, <memory:8192, vCores:7> used and <memory:0, vCores:9> available
2013-08-07 09:10:54,832 INFO org.apache.hadoop.yarn.server.resourcemanager.scheduler.capacity.LeafQueue: assignedContainer application=application_1375865942038_0007 container=Container: [ContainerId: container_1375865942038_0007_01_000005, NodeId: hadoop-200-7:54925, NodeHttpAddress: hadoop-200-7:8042, Resource: <memory:1024, vCores:1>, Priority: 20, State: NEW, Token: null, Status: container_id {, app_attempt_id {, application_id {, id: 7, cluster_timestamp: 1375865942038, }, attemptId: 1, }, id: 5, }, state: C_NEW, ] containerId=container_1375865942038_0007_01_000005 queue=default: capacity=1.0, absoluteCapacity=1.0, usedResources=<memory:48128, vCores:42>usedCapacity=0.9791667, absoluteUsedCapacity=0.9791667, numApps=5, numContainers=42 usedCapacity=0.9791667 absoluteUsedCapacity=0.9791667 used=<memory:48128, vCores:42> cluster=<memory:49152, vCores:96>
2013-08-07 09:10:54,832 INFO org.apache.hadoop.yarn.server.resourcemanager.scheduler.capacity.ParentQueue: Re-sorting queues since queue: root.default stats: default: capacity=1.0, absoluteCapacity=1.0, usedResources=<memory:49152, vCores:43>usedCapacity=1.0, absoluteUsedCapacity=1.0, numApps=5, numContainers=43
2013-08-07 09:10:54,832 INFO org.apache.hadoop.yarn.server.resourcemanager.scheduler.capacity.ParentQueue: assignedContainer queue=root usedCapacity=1.0 absoluteUsedCapacity=1.0 used=<memory:49152, vCores:43> cluster=<memory:49152, vCores:96>
2013-08-07 09:10:55,308 INFO org.apache.hadoop.yarn.server.resourcemanager.scheduler.AppSchedulingInfo: checking for deactivate... 
2013-08-07 09:10:55,328 INFO org.apache.hadoop.yarn.server.resourcemanager.rmcontainer.RMContainerImpl: container_1375865942038_0007_01_000003 Container Transitioned from ALLOCATED to ACQUIRED
2013-08-07 09:10:55,328 INFO org.apache.hadoop.yarn.server.resourcemanager.rmcontainer.RMContainerImpl: container_1375865942038_0007_01_000004 Container Transitioned from ALLOCATED to ACQUIRED
2013-08-07 09:10:55,328 INFO org.apache.hadoop.yarn.server.resourcemanager.rmcontainer.RMContainerImpl: container_1375865942038_0007_01_000005 Container Transitioned from ALLOCATED to ACQUIRED
2013-08-07 09:10:55,479 INFO org.apache.hadoop.yarn.server.resourcemanager.rmcontainer.RMContainerImpl: container_1375865942038_0007_01_000003 Container Transitioned from ACQUIRED to RUNNING
2013-08-07 09:10:55,479 INFO org.apache.hadoop.yarn.server.resourcemanager.rmcontainer.RMContainerImpl: container_1375865942038_0007_01_000004 Container Transitioned from ACQUIRED to RUNNING
2013-08-07 09:10:55,835 INFO org.apache.hadoop.yarn.server.resourcemanager.rmcontainer.RMContainerImpl: container_1375865942038_0007_01_000005 Container Transitioned from ACQUIRED to RUNNING
2013-08-07 09:10:55,878 INFO org.apache.hadoop.yarn.server.resourcemanager.rmcontainer.RMContainerImpl: container_1375865942038_0006_01_000029 Container Transitioned from RUNNING to COMPLETED
2013-08-07 09:10:55,878 INFO org.apache.hadoop.yarn.server.resourcemanager.scheduler.common.fica.FiCaSchedulerApp: Completed container: container_1375865942038_0006_01_000029 in state: COMPLETED event:FINISHED
2013-08-07 09:10:55,879 INFO org.apache.hadoop.yarn.server.resourcemanager.RMAuditLogger: USER=ubuntu	OPERATION=AM Released Container	TARGET=SchedulerApp	RESULT=SUCCESS	APPID=application_1375865942038_0006	CONTAINERID=container_1375865942038_0006_01_000029
2013-08-07 09:10:55,879 INFO org.apache.hadoop.yarn.server.resourcemanager.scheduler.common.fica.FiCaSchedulerNode: Released container container_1375865942038_0006_01_000029 of capacity <memory:1024, vCores:1> on host hadoop-200-5:55554, which currently has 6 containers, <memory:7168, vCores:6> used and <memory:1024, vCores:10> available, release resources=true
2013-08-07 09:10:55,879 INFO org.apache.hadoop.yarn.server.resourcemanager.scheduler.capacity.LeafQueue: default used=<memory:48128, vCores:42> numContainers=42 user=ubuntu user-resources=<memory:48128, vCores:42>
2013-08-07 09:10:55,880 INFO org.apache.hadoop.yarn.server.resourcemanager.scheduler.capacity.LeafQueue: completedContainer container=Container: [ContainerId: container_1375865942038_0006_01_000029, NodeId: hadoop-200-5:55554, NodeHttpAddress: hadoop-200-5:8042, Resource: <memory:1024, vCores:1>, Priority: 20, State: NEW, Token: null, Status: container_id {, app_attempt_id {, application_id {, id: 6, cluster_timestamp: 1375865942038, }, attemptId: 1, }, id: 29, }, state: C_COMPLETE, diagnostics: "Container killed by the ApplicationMaster.\n", exit_status: 0, ] resource=<memory:1024, vCores:1> queue=default: capacity=1.0, absoluteCapacity=1.0, usedResources=<memory:48128, vCores:42>usedCapacity=0.9791667, absoluteUsedCapacity=0.9791667, numApps=5, numContainers=42 usedCapacity=0.9791667 absoluteUsedCapacity=0.9791667 used=<memory:48128, vCores:42> cluster=<memory:49152, vCores:96>
2013-08-07 09:10:55,880 INFO org.apache.hadoop.yarn.server.resourcemanager.scheduler.capacity.ParentQueue: completedContainer queue=root usedCapacity=0.9791667 absoluteUsedCapacity=0.9791667 used=<memory:48128, vCores:42> cluster=<memory:49152, vCores:96>
2013-08-07 09:10:55,880 INFO org.apache.hadoop.yarn.server.resourcemanager.scheduler.capacity.CapacityScheduler: Application appattempt_1375865942038_0006_000001 released container container_1375865942038_0006_01_000029 on node: host: hadoop-200-5:55554 #containers=6 available=1024 used=7168 with event: FINISHED
2013-08-07 09:10:55,881 INFO org.apache.hadoop.yarn.server.resourcemanager.rmcontainer.RMContainerImpl: container_1375865942038_0006_01_000032 Container Transitioned from RUNNING to COMPLETED
2013-08-07 09:10:55,881 INFO org.apache.hadoop.yarn.server.resourcemanager.scheduler.common.fica.FiCaSchedulerApp: Completed container: container_1375865942038_0006_01_000032 in state: COMPLETED event:FINISHED
2013-08-07 09:10:55,881 INFO org.apache.hadoop.yarn.server.resourcemanager.RMAuditLogger: USER=ubuntu	OPERATION=AM Released Container	TARGET=SchedulerApp	RESULT=SUCCESS	APPID=application_1375865942038_0006	CONTAINERID=container_1375865942038_0006_01_000032
2013-08-07 09:10:55,881 INFO org.apache.hadoop.yarn.server.resourcemanager.scheduler.common.fica.FiCaSchedulerNode: Released container container_1375865942038_0006_01_000032 of capacity <memory:1024, vCores:1> on host hadoop-200-5:55554, which currently has 5 containers, <memory:6144, vCores:5> used and <memory:2048, vCores:11> available, release resources=true
2013-08-07 09:10:55,881 INFO org.apache.hadoop.yarn.server.resourcemanager.scheduler.capacity.LeafQueue: default used=<memory:47104, vCores:41> numContainers=41 user=ubuntu user-resources=<memory:47104, vCores:41>
2013-08-07 09:10:55,882 INFO org.apache.hadoop.yarn.server.resourcemanager.scheduler.capacity.LeafQueue: completedContainer container=Container: [ContainerId: container_1375865942038_0006_01_000032, NodeId: hadoop-200-5:55554, NodeHttpAddress: hadoop-200-5:8042, Resource: <memory:1024, vCores:1>, Priority: 20, State: NEW, Token: null, Status: container_id {, app_attempt_id {, application_id {, id: 6, cluster_timestamp: 1375865942038, }, attemptId: 1, }, id: 32, }, state: C_COMPLETE, diagnostics: "Container killed by the ApplicationMaster.\n", exit_status: 0, ] resource=<memory:1024, vCores:1> queue=default: capacity=1.0, absoluteCapacity=1.0, usedResources=<memory:47104, vCores:41>usedCapacity=0.9583333, absoluteUsedCapacity=0.9583333, numApps=5, numContainers=41 usedCapacity=0.9583333 absoluteUsedCapacity=0.9583333 used=<memory:47104, vCores:41> cluster=<memory:49152, vCores:96>
2013-08-07 09:10:55,882 INFO org.apache.hadoop.yarn.server.resourcemanager.scheduler.capacity.ParentQueue: completedContainer queue=root usedCapacity=0.9583333 absoluteUsedCapacity=0.9583333 used=<memory:47104, vCores:41> cluster=<memory:49152, vCores:96>
2013-08-07 09:10:55,882 INFO org.apache.hadoop.yarn.server.resourcemanager.scheduler.capacity.CapacityScheduler: Application appattempt_1375865942038_0006_000001 released container container_1375865942038_0006_01_000032 on node: host: hadoop-200-5:55554 #containers=5 available=2048 used=6144 with event: FINISHED
2013-08-07 09:10:55,883 INFO org.apache.hadoop.yarn.server.resourcemanager.rmcontainer.RMContainerImpl: container_1375865942038_0007_01_000006 Container Transitioned from NEW to ALLOCATED
2013-08-07 09:10:55,883 INFO org.apache.hadoop.yarn.server.resourcemanager.RMAuditLogger: USER=ubuntu	OPERATION=AM Allocated Container	TARGET=SchedulerApp	RESULT=SUCCESS	APPID=application_1375865942038_0007	CONTAINERID=container_1375865942038_0007_01_000006
2013-08-07 09:10:55,883 INFO org.apache.hadoop.yarn.server.resourcemanager.scheduler.common.fica.FiCaSchedulerNode: Assigned container container_1375865942038_0007_01_000006 of capacity <memory:1024, vCores:1> on host hadoop-200-5:55554, which currently has 6 containers, <memory:7168, vCores:6> used and <memory:1024, vCores:10> available
2013-08-07 09:10:55,884 INFO org.apache.hadoop.yarn.server.resourcemanager.scheduler.capacity.LeafQueue: assignedContainer application=application_1375865942038_0007 container=Container: [ContainerId: container_1375865942038_0007_01_000006, NodeId: hadoop-200-5:55554, NodeHttpAddress: hadoop-200-5:8042, Resource: <memory:1024, vCores:1>, Priority: 20, State: NEW, Token: null, Status: container_id {, app_attempt_id {, application_id {, id: 7, cluster_timestamp: 1375865942038, }, attemptId: 1, }, id: 6, }, state: C_NEW, ] containerId=container_1375865942038_0007_01_000006 queue=default: capacity=1.0, absoluteCapacity=1.0, usedResources=<memory:47104, vCores:41>usedCapacity=0.9583333, absoluteUsedCapacity=0.9583333, numApps=5, numContainers=41 usedCapacity=0.9583333 absoluteUsedCapacity=0.9583333 used=<memory:47104, vCores:41> cluster=<memory:49152, vCores:96>
2013-08-07 09:10:55,884 INFO org.apache.hadoop.yarn.server.resourcemanager.scheduler.capacity.ParentQueue: Re-sorting queues since queue: root.default stats: default: capacity=1.0, absoluteCapacity=1.0, usedResources=<memory:48128, vCores:42>usedCapacity=0.9791667, absoluteUsedCapacity=0.9791667, numApps=5, numContainers=42
2013-08-07 09:10:55,884 INFO org.apache.hadoop.yarn.server.resourcemanager.scheduler.capacity.ParentQueue: assignedContainer queue=root usedCapacity=0.9791667 absoluteUsedCapacity=0.9791667 used=<memory:48128, vCores:42> cluster=<memory:49152, vCores:96>
2013-08-07 09:10:55,885 INFO org.apache.hadoop.yarn.server.resourcemanager.rmcontainer.RMContainerImpl: container_1375865942038_0007_01_000007 Container Transitioned from NEW to ALLOCATED
2013-08-07 09:10:55,885 INFO org.apache.hadoop.yarn.server.resourcemanager.RMAuditLogger: USER=ubuntu	OPERATION=AM Allocated Container	TARGET=SchedulerApp	RESULT=SUCCESS	APPID=application_1375865942038_0007	CONTAINERID=container_1375865942038_0007_01_000007
2013-08-07 09:10:55,885 INFO org.apache.hadoop.yarn.server.resourcemanager.scheduler.common.fica.FiCaSchedulerNode: Assigned container container_1375865942038_0007_01_000007 of capacity <memory:1024, vCores:1> on host hadoop-200-5:55554, which currently has 7 containers, <memory:8192, vCores:7> used and <memory:0, vCores:9> available
2013-08-07 09:10:55,886 INFO org.apache.hadoop.yarn.server.resourcemanager.scheduler.capacity.LeafQueue: assignedContainer application=application_1375865942038_0007 container=Container: [ContainerId: container_1375865942038_0007_01_000007, NodeId: hadoop-200-5:55554, NodeHttpAddress: hadoop-200-5:8042, Resource: <memory:1024, vCores:1>, Priority: 20, State: NEW, Token: null, Status: container_id {, app_attempt_id {, application_id {, id: 7, cluster_timestamp: 1375865942038, }, attemptId: 1, }, id: 7, }, state: C_NEW, ] containerId=container_1375865942038_0007_01_000007 queue=default: capacity=1.0, absoluteCapacity=1.0, usedResources=<memory:48128, vCores:42>usedCapacity=0.9791667, absoluteUsedCapacity=0.9791667, numApps=5, numContainers=42 usedCapacity=0.9791667 absoluteUsedCapacity=0.9791667 used=<memory:48128, vCores:42> cluster=<memory:49152, vCores:96>
2013-08-07 09:10:55,886 INFO org.apache.hadoop.yarn.server.resourcemanager.scheduler.capacity.ParentQueue: Re-sorting queues since queue: root.default stats: default: capacity=1.0, absoluteCapacity=1.0, usedResources=<memory:49152, vCores:43>usedCapacity=1.0, absoluteUsedCapacity=1.0, numApps=5, numContainers=43
2013-08-07 09:10:55,886 INFO org.apache.hadoop.yarn.server.resourcemanager.scheduler.capacity.ParentQueue: assignedContainer queue=root usedCapacity=1.0 absoluteUsedCapacity=1.0 used=<memory:49152, vCores:43> cluster=<memory:49152, vCores:96>
2013-08-07 09:10:56,341 INFO org.apache.hadoop.yarn.server.resourcemanager.rmcontainer.RMContainerImpl: container_1375865942038_0007_01_000006 Container Transitioned from ALLOCATED to ACQUIRED
2013-08-07 09:10:56,342 INFO org.apache.hadoop.yarn.server.resourcemanager.rmcontainer.RMContainerImpl: container_1375865942038_0007_01_000007 Container Transitioned from ALLOCATED to ACQUIRED
2013-08-07 09:10:56,371 INFO org.apache.hadoop.yarn.server.resourcemanager.rmcontainer.RMContainerImpl: container_1375865942038_0006_01_000034 Container Transitioned from RUNNING to COMPLETED
2013-08-07 09:10:56,371 INFO org.apache.hadoop.yarn.server.resourcemanager.scheduler.common.fica.FiCaSchedulerApp: Completed container: container_1375865942038_0006_01_000034 in state: COMPLETED event:FINISHED
2013-08-07 09:10:56,372 INFO org.apache.hadoop.yarn.server.resourcemanager.RMAuditLogger: USER=ubuntu	OPERATION=AM Released Container	TARGET=SchedulerApp	RESULT=SUCCESS	APPID=application_1375865942038_0006	CONTAINERID=container_1375865942038_0006_01_000034
2013-08-07 09:10:56,372 INFO org.apache.hadoop.yarn.server.resourcemanager.scheduler.common.fica.FiCaSchedulerNode: Released container container_1375865942038_0006_01_000034 of capacity <memory:1024, vCores:1> on host hadoop-200-6:52835, which currently has 6 containers, <memory:7168, vCores:6> used and <memory:1024, vCores:10> available, release resources=true
2013-08-07 09:10:56,372 INFO org.apache.hadoop.yarn.server.resourcemanager.scheduler.capacity.LeafQueue: default used=<memory:48128, vCores:42> numContainers=42 user=ubuntu user-resources=<memory:48128, vCores:42>
2013-08-07 09:10:56,373 INFO org.apache.hadoop.yarn.server.resourcemanager.scheduler.capacity.LeafQueue: completedContainer container=Container: [ContainerId: container_1375865942038_0006_01_000034, NodeId: hadoop-200-6:52835, NodeHttpAddress: hadoop-200-6:8042, Resource: <memory:1024, vCores:1>, Priority: 20, State: NEW, Token: null, Status: container_id {, app_attempt_id {, application_id {, id: 6, cluster_timestamp: 1375865942038, }, attemptId: 1, }, id: 34, }, state: C_COMPLETE, diagnostics: "Container killed by the ApplicationMaster.\n\n", exit_status: 143, ] resource=<memory:1024, vCores:1> queue=default: capacity=1.0, absoluteCapacity=1.0, usedResources=<memory:48128, vCores:42>usedCapacity=0.9791667, absoluteUsedCapacity=0.9791667, numApps=5, numContainers=42 usedCapacity=0.9791667 absoluteUsedCapacity=0.9791667 used=<memory:48128, vCores:42> cluster=<memory:49152, vCores:96>
2013-08-07 09:10:56,373 INFO org.apache.hadoop.yarn.server.resourcemanager.scheduler.capacity.ParentQueue: completedContainer queue=root usedCapacity=0.9791667 absoluteUsedCapacity=0.9791667 used=<memory:48128, vCores:42> cluster=<memory:49152, vCores:96>
2013-08-07 09:10:56,373 INFO org.apache.hadoop.yarn.server.resourcemanager.scheduler.capacity.CapacityScheduler: Application appattempt_1375865942038_0006_000001 released container container_1375865942038_0006_01_000034 on node: host: hadoop-200-6:52835 #containers=6 available=1024 used=7168 with event: FINISHED
2013-08-07 09:10:56,374 INFO org.apache.hadoop.yarn.server.resourcemanager.rmcontainer.RMContainerImpl: container_1375865942038_0007_01_000008 Container Transitioned from NEW to ALLOCATED
2013-08-07 09:10:56,374 INFO org.apache.hadoop.yarn.server.resourcemanager.RMAuditLogger: USER=ubuntu	OPERATION=AM Allocated Container	TARGET=SchedulerApp	RESULT=SUCCESS	APPID=application_1375865942038_0007	CONTAINERID=container_1375865942038_0007_01_000008
2013-08-07 09:10:56,374 INFO org.apache.hadoop.yarn.server.resourcemanager.scheduler.common.fica.FiCaSchedulerNode: Assigned container container_1375865942038_0007_01_000008 of capacity <memory:1024, vCores:1> on host hadoop-200-6:52835, which currently has 7 containers, <memory:8192, vCores:7> used and <memory:0, vCores:9> available
2013-08-07 09:10:56,375 INFO org.apache.hadoop.yarn.server.resourcemanager.scheduler.capacity.LeafQueue: assignedContainer application=application_1375865942038_0007 container=Container: [ContainerId: container_1375865942038_0007_01_000008, NodeId: hadoop-200-6:52835, NodeHttpAddress: hadoop-200-6:8042, Resource: <memory:1024, vCores:1>, Priority: 20, State: NEW, Token: null, Status: container_id {, app_attempt_id {, application_id {, id: 7, cluster_timestamp: 1375865942038, }, attemptId: 1, }, id: 8, }, state: C_NEW, ] containerId=container_1375865942038_0007_01_000008 queue=default: capacity=1.0, absoluteCapacity=1.0, usedResources=<memory:48128, vCores:42>usedCapacity=0.9791667, absoluteUsedCapacity=0.9791667, numApps=5, numContainers=42 usedCapacity=0.9791667 absoluteUsedCapacity=0.9791667 used=<memory:48128, vCores:42> cluster=<memory:49152, vCores:96>
2013-08-07 09:10:56,375 INFO org.apache.hadoop.yarn.server.resourcemanager.scheduler.capacity.ParentQueue: Re-sorting queues since queue: root.default stats: default: capacity=1.0, absoluteCapacity=1.0, usedResources=<memory:49152, vCores:43>usedCapacity=1.0, absoluteUsedCapacity=1.0, numApps=5, numContainers=43
2013-08-07 09:10:56,375 INFO org.apache.hadoop.yarn.server.resourcemanager.scheduler.capacity.ParentQueue: assignedContainer queue=root usedCapacity=1.0 absoluteUsedCapacity=1.0 used=<memory:49152, vCores:43> cluster=<memory:49152, vCores:96>
2013-08-07 09:10:57,048 INFO org.apache.hadoop.yarn.server.resourcemanager.rmcontainer.RMContainerImpl: container_1375865942038_0007_01_000006 Container Transitioned from ACQUIRED to RUNNING
2013-08-07 09:10:57,048 INFO org.apache.hadoop.yarn.server.resourcemanager.rmcontainer.RMContainerImpl: container_1375865942038_0007_01_000007 Container Transitioned from ACQUIRED to RUNNING
2013-08-07 09:10:57,048 INFO org.apache.hadoop.yarn.server.resourcemanager.rmcontainer.RMContainerImpl: container_1375865942038_0006_01_000031 Container Transitioned from RUNNING to COMPLETED
2013-08-07 09:10:57,049 INFO org.apache.hadoop.yarn.server.resourcemanager.scheduler.common.fica.FiCaSchedulerApp: Completed container: container_1375865942038_0006_01_000031 in state: COMPLETED event:FINISHED
2013-08-07 09:10:57,049 INFO org.apache.hadoop.yarn.server.resourcemanager.RMAuditLogger: USER=ubuntu	OPERATION=AM Released Container	TARGET=SchedulerApp	RESULT=SUCCESS	APPID=application_1375865942038_0006	CONTAINERID=container_1375865942038_0006_01_000031
2013-08-07 09:10:57,049 INFO org.apache.hadoop.yarn.server.resourcemanager.scheduler.common.fica.FiCaSchedulerNode: Released container container_1375865942038_0006_01_000031 of capacity <memory:1024, vCores:1> on host hadoop-200-5:55554, which currently has 6 containers, <memory:7168, vCores:6> used and <memory:1024, vCores:10> available, release resources=true
2013-08-07 09:10:57,049 INFO org.apache.hadoop.yarn.server.resourcemanager.scheduler.capacity.LeafQueue: default used=<memory:48128, vCores:42> numContainers=42 user=ubuntu user-resources=<memory:48128, vCores:42>
2013-08-07 09:10:57,050 INFO org.apache.hadoop.yarn.server.resourcemanager.scheduler.capacity.LeafQueue: completedContainer container=Container: [ContainerId: container_1375865942038_0006_01_000031, NodeId: hadoop-200-5:55554, NodeHttpAddress: hadoop-200-5:8042, Resource: <memory:1024, vCores:1>, Priority: 20, State: NEW, Token: null, Status: container_id {, app_attempt_id {, application_id {, id: 6, cluster_timestamp: 1375865942038, }, attemptId: 1, }, id: 31, }, state: C_COMPLETE, diagnostics: "Container killed by the ApplicationMaster.\n", exit_status: 0, ] resource=<memory:1024, vCores:1> queue=default: capacity=1.0, absoluteCapacity=1.0, usedResources=<memory:48128, vCores:42>usedCapacity=0.9791667, absoluteUsedCapacity=0.9791667, numApps=5, numContainers=42 usedCapacity=0.9791667 absoluteUsedCapacity=0.9791667 used=<memory:48128, vCores:42> cluster=<memory:49152, vCores:96>
2013-08-07 09:10:57,050 INFO org.apache.hadoop.yarn.server.resourcemanager.scheduler.capacity.ParentQueue: completedContainer queue=root usedCapacity=0.9791667 absoluteUsedCapacity=0.9791667 used=<memory:48128, vCores:42> cluster=<memory:49152, vCores:96>
2013-08-07 09:10:57,051 INFO org.apache.hadoop.yarn.server.resourcemanager.scheduler.capacity.CapacityScheduler: Application appattempt_1375865942038_0006_000001 released container container_1375865942038_0006_01_000031 on node: host: hadoop-200-5:55554 #containers=6 available=1024 used=7168 with event: FINISHED
2013-08-07 09:10:57,051 INFO org.apache.hadoop.yarn.server.resourcemanager.rmcontainer.RMContainerImpl: container_1375865942038_0007_01_000009 Container Transitioned from NEW to ALLOCATED
2013-08-07 09:10:57,051 INFO org.apache.hadoop.yarn.server.resourcemanager.RMAuditLogger: USER=ubuntu	OPERATION=AM Allocated Container	TARGET=SchedulerApp	RESULT=SUCCESS	APPID=application_1375865942038_0007	CONTAINERID=container_1375865942038_0007_01_000009
2013-08-07 09:10:57,051 INFO org.apache.hadoop.yarn.server.resourcemanager.scheduler.common.fica.FiCaSchedulerNode: Assigned container container_1375865942038_0007_01_000009 of capacity <memory:1024, vCores:1> on host hadoop-200-5:55554, which currently has 7 containers, <memory:8192, vCores:7> used and <memory:0, vCores:9> available
2013-08-07 09:10:57,052 INFO org.apache.hadoop.yarn.server.resourcemanager.scheduler.capacity.LeafQueue: assignedContainer application=application_1375865942038_0007 container=Container: [ContainerId: container_1375865942038_0007_01_000009, NodeId: hadoop-200-5:55554, NodeHttpAddress: hadoop-200-5:8042, Resource: <memory:1024, vCores:1>, Priority: 20, State: NEW, Token: null, Status: container_id {, app_attempt_id {, application_id {, id: 7, cluster_timestamp: 1375865942038, }, attemptId: 1, }, id: 9, }, state: C_NEW, ] containerId=container_1375865942038_0007_01_000009 queue=default: capacity=1.0, absoluteCapacity=1.0, usedResources=<memory:48128, vCores:42>usedCapacity=0.9791667, absoluteUsedCapacity=0.9791667, numApps=5, numContainers=42 usedCapacity=0.9791667 absoluteUsedCapacity=0.9791667 used=<memory:48128, vCores:42> cluster=<memory:49152, vCores:96>
2013-08-07 09:10:57,052 INFO org.apache.hadoop.yarn.server.resourcemanager.scheduler.capacity.ParentQueue: Re-sorting queues since queue: root.default stats: default: capacity=1.0, absoluteCapacity=1.0, usedResources=<memory:49152, vCores:43>usedCapacity=1.0, absoluteUsedCapacity=1.0, numApps=5, numContainers=43
2013-08-07 09:10:57,053 INFO org.apache.hadoop.yarn.server.resourcemanager.scheduler.capacity.ParentQueue: assignedContainer queue=root usedCapacity=1.0 absoluteUsedCapacity=1.0 used=<memory:49152, vCores:43> cluster=<memory:49152, vCores:96>
2013-08-07 09:10:57,350 INFO org.apache.hadoop.yarn.server.resourcemanager.rmcontainer.RMContainerImpl: container_1375865942038_0007_01_000008 Container Transitioned from ALLOCATED to ACQUIRED
2013-08-07 09:10:57,351 INFO org.apache.hadoop.yarn.server.resourcemanager.rmcontainer.RMContainerImpl: container_1375865942038_0007_01_000009 Container Transitioned from ALLOCATED to ACQUIRED
2013-08-07 09:10:57,379 INFO org.apache.hadoop.yarn.server.resourcemanager.rmcontainer.RMContainerImpl: container_1375865942038_0006_01_000036 Container Transitioned from RUNNING to COMPLETED
2013-08-07 09:10:57,379 INFO org.apache.hadoop.yarn.server.resourcemanager.scheduler.common.fica.FiCaSchedulerApp: Completed container: container_1375865942038_0006_01_000036 in state: COMPLETED event:FINISHED
2013-08-07 09:10:57,379 INFO org.apache.hadoop.yarn.server.resourcemanager.RMAuditLogger: USER=ubuntu	OPERATION=AM Released Container	TARGET=SchedulerApp	RESULT=SUCCESS	APPID=application_1375865942038_0006	CONTAINERID=container_1375865942038_0006_01_000036
2013-08-07 09:10:57,379 INFO org.apache.hadoop.yarn.server.resourcemanager.scheduler.common.fica.FiCaSchedulerNode: Released container container_1375865942038_0006_01_000036 of capacity <memory:1024, vCores:1> on host hadoop-200-6:52835, which currently has 6 containers, <memory:7168, vCores:6> used and <memory:1024, vCores:10> available, release resources=true
2013-08-07 09:10:57,379 INFO org.apache.hadoop.yarn.server.resourcemanager.scheduler.capacity.LeafQueue: default used=<memory:48128, vCores:42> numContainers=42 user=ubuntu user-resources=<memory:48128, vCores:42>
2013-08-07 09:10:57,380 INFO org.apache.hadoop.yarn.server.resourcemanager.scheduler.capacity.LeafQueue: completedContainer container=Container: [ContainerId: container_1375865942038_0006_01_000036, NodeId: hadoop-200-6:52835, NodeHttpAddress: hadoop-200-6:8042, Resource: <memory:1024, vCores:1>, Priority: 20, State: NEW, Token: null, Status: container_id {, app_attempt_id {, application_id {, id: 6, cluster_timestamp: 1375865942038, }, attemptId: 1, }, id: 36, }, state: C_COMPLETE, diagnostics: "Container killed by the ApplicationMaster.\n\n", exit_status: 143, ] resource=<memory:1024, vCores:1> queue=default: capacity=1.0, absoluteCapacity=1.0, usedResources=<memory:48128, vCores:42>usedCapacity=0.9791667, absoluteUsedCapacity=0.9791667, numApps=5, numContainers=42 usedCapacity=0.9791667 absoluteUsedCapacity=0.9791667 used=<memory:48128, vCores:42> cluster=<memory:49152, vCores:96>
2013-08-07 09:10:57,380 INFO org.apache.hadoop.yarn.server.resourcemanager.scheduler.capacity.ParentQueue: completedContainer queue=root usedCapacity=0.9791667 absoluteUsedCapacity=0.9791667 used=<memory:48128, vCores:42> cluster=<memory:49152, vCores:96>
2013-08-07 09:10:57,380 INFO org.apache.hadoop.yarn.server.resourcemanager.scheduler.capacity.CapacityScheduler: Application appattempt_1375865942038_0006_000001 released container container_1375865942038_0006_01_000036 on node: host: hadoop-200-6:52835 #containers=6 available=1024 used=7168 with event: FINISHED
2013-08-07 09:10:57,381 INFO org.apache.hadoop.yarn.server.resourcemanager.rmcontainer.RMContainerImpl: container_1375865942038_0007_01_000010 Container Transitioned from NEW to ALLOCATED
2013-08-07 09:10:57,381 INFO org.apache.hadoop.yarn.server.resourcemanager.RMAuditLogger: USER=ubuntu	OPERATION=AM Allocated Container	TARGET=SchedulerApp	RESULT=SUCCESS	APPID=application_1375865942038_0007	CONTAINERID=container_1375865942038_0007_01_000010
2013-08-07 09:10:57,381 INFO org.apache.hadoop.yarn.server.resourcemanager.scheduler.common.fica.FiCaSchedulerNode: Assigned container container_1375865942038_0007_01_000010 of capacity <memory:1024, vCores:1> on host hadoop-200-6:52835, which currently has 7 containers, <memory:8192, vCores:7> used and <memory:0, vCores:9> available
2013-08-07 09:10:57,382 INFO org.apache.hadoop.yarn.server.resourcemanager.scheduler.capacity.LeafQueue: assignedContainer application=application_1375865942038_0007 container=Container: [ContainerId: container_1375865942038_0007_01_000010, NodeId: hadoop-200-6:52835, NodeHttpAddress: hadoop-200-6:8042, Resource: <memory:1024, vCores:1>, Priority: 20, State: NEW, Token: null, Status: container_id {, app_attempt_id {, application_id {, id: 7, cluster_timestamp: 1375865942038, }, attemptId: 1, }, id: 10, }, state: C_NEW, ] containerId=container_1375865942038_0007_01_000010 queue=default: capacity=1.0, absoluteCapacity=1.0, usedResources=<memory:48128, vCores:42>usedCapacity=0.9791667, absoluteUsedCapacity=0.9791667, numApps=5, numContainers=42 usedCapacity=0.9791667 absoluteUsedCapacity=0.9791667 used=<memory:48128, vCores:42> cluster=<memory:49152, vCores:96>
2013-08-07 09:10:57,382 INFO org.apache.hadoop.yarn.server.resourcemanager.scheduler.capacity.ParentQueue: Re-sorting queues since queue: root.default stats: default: capacity=1.0, absoluteCapacity=1.0, usedResources=<memory:49152, vCores:43>usedCapacity=1.0, absoluteUsedCapacity=1.0, numApps=5, numContainers=43
2013-08-07 09:10:57,383 INFO org.apache.hadoop.yarn.server.resourcemanager.scheduler.capacity.ParentQueue: assignedContainer queue=root usedCapacity=1.0 absoluteUsedCapacity=1.0 used=<memory:49152, vCores:43> cluster=<memory:49152, vCores:96>
2013-08-07 09:10:57,957 INFO org.apache.hadoop.yarn.server.resourcemanager.rmcontainer.RMContainerImpl: container_1375865942038_0006_01_000025 Container Transitioned from RUNNING to COMPLETED
2013-08-07 09:10:57,957 INFO org.apache.hadoop.yarn.server.resourcemanager.scheduler.common.fica.FiCaSchedulerApp: Completed container: container_1375865942038_0006_01_000025 in state: COMPLETED event:FINISHED
2013-08-07 09:10:57,957 INFO org.apache.hadoop.yarn.server.resourcemanager.RMAuditLogger: USER=ubuntu	OPERATION=AM Released Container	TARGET=SchedulerApp	RESULT=SUCCESS	APPID=application_1375865942038_0006	CONTAINERID=container_1375865942038_0006_01_000025
2013-08-07 09:10:57,958 INFO org.apache.hadoop.yarn.server.resourcemanager.scheduler.common.fica.FiCaSchedulerNode: Released container container_1375865942038_0006_01_000025 of capacity <memory:1024, vCores:1> on host hadoop-200-2:58832, which currently has 6 containers, <memory:7168, vCores:6> used and <memory:1024, vCores:10> available, release resources=true
2013-08-07 09:10:57,958 INFO org.apache.hadoop.yarn.server.resourcemanager.scheduler.capacity.LeafQueue: default used=<memory:48128, vCores:42> numContainers=42 user=ubuntu user-resources=<memory:48128, vCores:42>
2013-08-07 09:10:57,961 INFO org.apache.hadoop.yarn.server.resourcemanager.scheduler.capacity.LeafQueue: completedContainer container=Container: [ContainerId: container_1375865942038_0006_01_000025, NodeId: hadoop-200-2:58832, NodeHttpAddress: hadoop-200-2:8042, Resource: <memory:1024, vCores:1>, Priority: 20, State: NEW, Token: null, Status: container_id {, app_attempt_id {, application_id {, id: 6, cluster_timestamp: 1375865942038, }, attemptId: 1, }, id: 25, }, state: C_COMPLETE, diagnostics: "Container killed by the ApplicationMaster.\n\n", exit_status: 143, ] resource=<memory:1024, vCores:1> queue=default: capacity=1.0, absoluteCapacity=1.0, usedResources=<memory:48128, vCores:42>usedCapacity=0.9791667, absoluteUsedCapacity=0.9791667, numApps=5, numContainers=42 usedCapacity=0.9791667 absoluteUsedCapacity=0.9791667 used=<memory:48128, vCores:42> cluster=<memory:49152, vCores:96>
2013-08-07 09:10:57,962 INFO org.apache.hadoop.yarn.server.resourcemanager.scheduler.capacity.ParentQueue: completedContainer queue=root usedCapacity=0.9791667 absoluteUsedCapacity=0.9791667 used=<memory:48128, vCores:42> cluster=<memory:49152, vCores:96>
2013-08-07 09:10:57,962 INFO org.apache.hadoop.yarn.server.resourcemanager.scheduler.capacity.CapacityScheduler: Application appattempt_1375865942038_0006_000001 released container container_1375865942038_0006_01_000025 on node: host: hadoop-200-2:58832 #containers=6 available=1024 used=7168 with event: FINISHED
2013-08-07 09:10:57,962 INFO org.apache.hadoop.yarn.server.resourcemanager.rmcontainer.RMContainerImpl: container_1375865942038_0006_01_000026 Container Transitioned from RUNNING to COMPLETED
2013-08-07 09:10:57,962 INFO org.apache.hadoop.yarn.server.resourcemanager.scheduler.common.fica.FiCaSchedulerApp: Completed container: container_1375865942038_0006_01_000026 in state: COMPLETED event:FINISHED
2013-08-07 09:10:57,962 INFO org.apache.hadoop.yarn.server.resourcemanager.RMAuditLogger: USER=ubuntu	OPERATION=AM Released Container	TARGET=SchedulerApp	RESULT=SUCCESS	APPID=application_1375865942038_0006	CONTAINERID=container_1375865942038_0006_01_000026
2013-08-07 09:10:57,962 INFO org.apache.hadoop.yarn.server.resourcemanager.scheduler.common.fica.FiCaSchedulerNode: Released container container_1375865942038_0006_01_000026 of capacity <memory:1024, vCores:1> on host hadoop-200-2:58832, which currently has 5 containers, <memory:6144, vCores:5> used and <memory:2048, vCores:11> available, release resources=true
2013-08-07 09:10:57,963 INFO org.apache.hadoop.yarn.server.resourcemanager.scheduler.capacity.LeafQueue: default used=<memory:47104, vCores:41> numContainers=41 user=ubuntu user-resources=<memory:47104, vCores:41>
2013-08-07 09:10:57,963 INFO org.apache.hadoop.yarn.server.resourcemanager.scheduler.capacity.LeafQueue: completedContainer container=Container: [ContainerId: container_1375865942038_0006_01_000026, NodeId: hadoop-200-2:58832, NodeHttpAddress: hadoop-200-2:8042, Resource: <memory:1024, vCores:1>, Priority: 20, State: NEW, Token: null, Status: container_id {, app_attempt_id {, application_id {, id: 6, cluster_timestamp: 1375865942038, }, attemptId: 1, }, id: 26, }, state: C_COMPLETE, diagnostics: "Container killed by the ApplicationMaster.\n\n", exit_status: 143, ] resource=<memory:1024, vCores:1> queue=default: capacity=1.0, absoluteCapacity=1.0, usedResources=<memory:47104, vCores:41>usedCapacity=0.9583333, absoluteUsedCapacity=0.9583333, numApps=5, numContainers=41 usedCapacity=0.9583333 absoluteUsedCapacity=0.9583333 used=<memory:47104, vCores:41> cluster=<memory:49152, vCores:96>
2013-08-07 09:10:57,964 INFO org.apache.hadoop.yarn.server.resourcemanager.scheduler.capacity.ParentQueue: completedContainer queue=root usedCapacity=0.9583333 absoluteUsedCapacity=0.9583333 used=<memory:47104, vCores:41> cluster=<memory:49152, vCores:96>
2013-08-07 09:10:57,964 INFO org.apache.hadoop.yarn.server.resourcemanager.scheduler.capacity.CapacityScheduler: Application appattempt_1375865942038_0006_000001 released container container_1375865942038_0006_01_000026 on node: host: hadoop-200-2:58832 #containers=5 available=2048 used=6144 with event: FINISHED
2013-08-07 09:10:57,964 INFO org.apache.hadoop.yarn.server.resourcemanager.rmcontainer.RMContainerImpl: container_1375865942038_0007_01_000011 Container Transitioned from NEW to ALLOCATED
2013-08-07 09:10:57,964 INFO org.apache.hadoop.yarn.server.resourcemanager.RMAuditLogger: USER=ubuntu	OPERATION=AM Allocated Container	TARGET=SchedulerApp	RESULT=SUCCESS	APPID=application_1375865942038_0007	CONTAINERID=container_1375865942038_0007_01_000011
2013-08-07 09:10:57,965 INFO org.apache.hadoop.yarn.server.resourcemanager.scheduler.common.fica.FiCaSchedulerNode: Assigned container container_1375865942038_0007_01_000011 of capacity <memory:1024, vCores:1> on host hadoop-200-2:58832, which currently has 6 containers, <memory:7168, vCores:6> used and <memory:1024, vCores:10> available
2013-08-07 09:10:57,965 INFO org.apache.hadoop.yarn.server.resourcemanager.scheduler.capacity.LeafQueue: assignedContainer application=application_1375865942038_0007 container=Container: [ContainerId: container_1375865942038_0007_01_000011, NodeId: hadoop-200-2:58832, NodeHttpAddress: hadoop-200-2:8042, Resource: <memory:1024, vCores:1>, Priority: 20, State: NEW, Token: null, Status: container_id {, app_attempt_id {, application_id {, id: 7, cluster_timestamp: 1375865942038, }, attemptId: 1, }, id: 11, }, state: C_NEW, ] containerId=container_1375865942038_0007_01_000011 queue=default: capacity=1.0, absoluteCapacity=1.0, usedResources=<memory:47104, vCores:41>usedCapacity=0.9583333, absoluteUsedCapacity=0.9583333, numApps=5, numContainers=41 usedCapacity=0.9583333 absoluteUsedCapacity=0.9583333 used=<memory:47104, vCores:41> cluster=<memory:49152, vCores:96>
2013-08-07 09:10:57,966 INFO org.apache.hadoop.yarn.server.resourcemanager.scheduler.capacity.ParentQueue: Re-sorting queues since queue: root.default stats: default: capacity=1.0, absoluteCapacity=1.0, usedResources=<memory:48128, vCores:42>usedCapacity=0.9791667, absoluteUsedCapacity=0.9791667, numApps=5, numContainers=42
2013-08-07 09:10:57,966 INFO org.apache.hadoop.yarn.server.resourcemanager.scheduler.capacity.ParentQueue: assignedContainer queue=root usedCapacity=0.9791667 absoluteUsedCapacity=0.9791667 used=<memory:48128, vCores:42> cluster=<memory:49152, vCores:96>
2013-08-07 09:10:57,966 INFO org.apache.hadoop.yarn.server.resourcemanager.rmcontainer.RMContainerImpl: container_1375865942038_0007_01_000012 Container Transitioned from NEW to ALLOCATED
2013-08-07 09:10:57,966 INFO org.apache.hadoop.yarn.server.resourcemanager.RMAuditLogger: USER=ubuntu	OPERATION=AM Allocated Container	TARGET=SchedulerApp	RESULT=SUCCESS	APPID=application_1375865942038_0007	CONTAINERID=container_1375865942038_0007_01_000012
2013-08-07 09:10:57,967 INFO org.apache.hadoop.yarn.server.resourcemanager.scheduler.common.fica.FiCaSchedulerNode: Assigned container container_1375865942038_0007_01_000012 of capacity <memory:1024, vCores:1> on host hadoop-200-2:58832, which currently has 7 containers, <memory:8192, vCores:7> used and <memory:0, vCores:9> available
2013-08-07 09:10:57,967 INFO org.apache.hadoop.yarn.server.resourcemanager.scheduler.capacity.LeafQueue: assignedContainer application=application_1375865942038_0007 container=Container: [ContainerId: container_1375865942038_0007_01_000012, NodeId: hadoop-200-2:58832, NodeHttpAddress: hadoop-200-2:8042, Resource: <memory:1024, vCores:1>, Priority: 20, State: NEW, Token: null, Status: container_id {, app_attempt_id {, application_id {, id: 7, cluster_timestamp: 1375865942038, }, attemptId: 1, }, id: 12, }, state: C_NEW, ] containerId=container_1375865942038_0007_01_000012 queue=default: capacity=1.0, absoluteCapacity=1.0, usedResources=<memory:48128, vCores:42>usedCapacity=0.9791667, absoluteUsedCapacity=0.9791667, numApps=5, numContainers=42 usedCapacity=0.9791667 absoluteUsedCapacity=0.9791667 used=<memory:48128, vCores:42> cluster=<memory:49152, vCores:96>
2013-08-07 09:10:57,968 INFO org.apache.hadoop.yarn.server.resourcemanager.scheduler.capacity.ParentQueue: Re-sorting queues since queue: root.default stats: default: capacity=1.0, absoluteCapacity=1.0, usedResources=<memory:49152, vCores:43>usedCapacity=1.0, absoluteUsedCapacity=1.0, numApps=5, numContainers=43
2013-08-07 09:10:57,968 INFO org.apache.hadoop.yarn.server.resourcemanager.scheduler.capacity.ParentQueue: assignedContainer queue=root usedCapacity=1.0 absoluteUsedCapacity=1.0 used=<memory:49152, vCores:43> cluster=<memory:49152, vCores:96>
2013-08-07 09:10:58,303 INFO org.apache.hadoop.yarn.server.resourcemanager.rmcontainer.RMContainerImpl: container_1375865942038_0006_01_000008 Container Transitioned from RUNNING to COMPLETED
2013-08-07 09:10:58,303 INFO org.apache.hadoop.yarn.server.resourcemanager.scheduler.common.fica.FiCaSchedulerApp: Completed container: container_1375865942038_0006_01_000008 in state: COMPLETED event:FINISHED
2013-08-07 09:10:58,303 INFO org.apache.hadoop.yarn.server.resourcemanager.RMAuditLogger: USER=ubuntu	OPERATION=AM Released Container	TARGET=SchedulerApp	RESULT=SUCCESS	APPID=application_1375865942038_0006	CONTAINERID=container_1375865942038_0006_01_000008
2013-08-07 09:10:58,304 INFO org.apache.hadoop.yarn.server.resourcemanager.scheduler.common.fica.FiCaSchedulerNode: Released container container_1375865942038_0006_01_000008 of capacity <memory:1024, vCores:1> on host hadoop-200-3:58063, which currently has 7 containers, <memory:7168, vCores:7> used and <memory:1024, vCores:9> available, release resources=true
2013-08-07 09:10:58,304 INFO org.apache.hadoop.yarn.server.resourcemanager.scheduler.capacity.LeafQueue: default used=<memory:48128, vCores:42> numContainers=42 user=ubuntu user-resources=<memory:48128, vCores:42>
2013-08-07 09:10:58,305 INFO org.apache.hadoop.yarn.server.resourcemanager.scheduler.capacity.LeafQueue: completedContainer container=Container: [ContainerId: container_1375865942038_0006_01_000008, NodeId: hadoop-200-3:58063, NodeHttpAddress: hadoop-200-3:8042, Resource: <memory:1024, vCores:1>, Priority: 20, State: NEW, Token: null, Status: container_id {, app_attempt_id {, application_id {, id: 6, cluster_timestamp: 1375865942038, }, attemptId: 1, }, id: 8, }, state: C_COMPLETE, diagnostics: "Container killed by the ApplicationMaster.\n\n", exit_status: 143, ] resource=<memory:1024, vCores:1> queue=default: capacity=1.0, absoluteCapacity=1.0, usedResources=<memory:48128, vCores:42>usedCapacity=0.9791667, absoluteUsedCapacity=0.9791667, numApps=5, numContainers=42 usedCapacity=0.9791667 absoluteUsedCapacity=0.9791667 used=<memory:48128, vCores:42> cluster=<memory:49152, vCores:96>
2013-08-07 09:10:58,305 INFO org.apache.hadoop.yarn.server.resourcemanager.scheduler.capacity.ParentQueue: completedContainer queue=root usedCapacity=0.9791667 absoluteUsedCapacity=0.9791667 used=<memory:48128, vCores:42> cluster=<memory:49152, vCores:96>
2013-08-07 09:10:58,305 INFO org.apache.hadoop.yarn.server.resourcemanager.scheduler.capacity.CapacityScheduler: Application appattempt_1375865942038_0006_000001 released container container_1375865942038_0006_01_000008 on node: host: hadoop-200-3:58063 #containers=7 available=1024 used=7168 with event: FINISHED
2013-08-07 09:10:58,306 INFO org.apache.hadoop.yarn.server.resourcemanager.rmcontainer.RMContainerImpl: container_1375865942038_0007_01_000013 Container Transitioned from NEW to ALLOCATED
2013-08-07 09:10:58,306 INFO org.apache.hadoop.yarn.server.resourcemanager.RMAuditLogger: USER=ubuntu	OPERATION=AM Allocated Container	TARGET=SchedulerApp	RESULT=SUCCESS	APPID=application_1375865942038_0007	CONTAINERID=container_1375865942038_0007_01_000013
2013-08-07 09:10:58,306 INFO org.apache.hadoop.yarn.server.resourcemanager.scheduler.common.fica.FiCaSchedulerNode: Assigned container container_1375865942038_0007_01_000013 of capacity <memory:1024, vCores:1> on host hadoop-200-3:58063, which currently has 8 containers, <memory:8192, vCores:8> used and <memory:0, vCores:8> available
2013-08-07 09:10:58,307 INFO org.apache.hadoop.yarn.server.resourcemanager.scheduler.capacity.LeafQueue: assignedContainer application=application_1375865942038_0007 container=Container: [ContainerId: container_1375865942038_0007_01_000013, NodeId: hadoop-200-3:58063, NodeHttpAddress: hadoop-200-3:8042, Resource: <memory:1024, vCores:1>, Priority: 20, State: NEW, Token: null, Status: container_id {, app_attempt_id {, application_id {, id: 7, cluster_timestamp: 1375865942038, }, attemptId: 1, }, id: 13, }, state: C_NEW, ] containerId=container_1375865942038_0007_01_000013 queue=default: capacity=1.0, absoluteCapacity=1.0, usedResources=<memory:48128, vCores:42>usedCapacity=0.9791667, absoluteUsedCapacity=0.9791667, numApps=5, numContainers=42 usedCapacity=0.9791667 absoluteUsedCapacity=0.9791667 used=<memory:48128, vCores:42> cluster=<memory:49152, vCores:96>
2013-08-07 09:10:58,307 INFO org.apache.hadoop.yarn.server.resourcemanager.scheduler.capacity.ParentQueue: Re-sorting queues since queue: root.default stats: default: capacity=1.0, absoluteCapacity=1.0, usedResources=<memory:49152, vCores:43>usedCapacity=1.0, absoluteUsedCapacity=1.0, numApps=5, numContainers=43
2013-08-07 09:10:58,307 INFO org.apache.hadoop.yarn.server.resourcemanager.scheduler.capacity.ParentQueue: assignedContainer queue=root usedCapacity=1.0 absoluteUsedCapacity=1.0 used=<memory:49152, vCores:43> cluster=<memory:49152, vCores:96>
2013-08-07 09:10:58,656 INFO org.apache.hadoop.yarn.server.resourcemanager.rmcontainer.RMContainerImpl: container_1375865942038_0006_01_000033 Container Transitioned from RUNNING to COMPLETED
2013-08-07 09:10:58,656 INFO org.apache.hadoop.yarn.server.resourcemanager.scheduler.common.fica.FiCaSchedulerApp: Completed container: container_1375865942038_0006_01_000033 in state: COMPLETED event:FINISHED
2013-08-07 09:10:58,656 INFO org.apache.hadoop.yarn.server.resourcemanager.RMAuditLogger: USER=ubuntu	OPERATION=AM Released Container	TARGET=SchedulerApp	RESULT=SUCCESS	APPID=application_1375865942038_0006	CONTAINERID=container_1375865942038_0006_01_000033
2013-08-07 09:10:58,656 INFO org.apache.hadoop.yarn.server.resourcemanager.scheduler.common.fica.FiCaSchedulerNode: Released container container_1375865942038_0006_01_000033 of capacity <memory:1024, vCores:1> on host hadoop-200-5:55554, which currently has 6 containers, <memory:7168, vCores:6> used and <memory:1024, vCores:10> available, release resources=true
2013-08-07 09:10:58,657 INFO org.apache.hadoop.yarn.server.resourcemanager.scheduler.capacity.LeafQueue: default used=<memory:48128, vCores:42> numContainers=42 user=ubuntu user-resources=<memory:48128, vCores:42>
2013-08-07 09:10:58,658 INFO org.apache.hadoop.yarn.server.resourcemanager.scheduler.capacity.LeafQueue: completedContainer container=Container: [ContainerId: container_1375865942038_0006_01_000033, NodeId: hadoop-200-5:55554, NodeHttpAddress: hadoop-200-5:8042, Resource: <memory:1024, vCores:1>, Priority: 20, State: NEW, Token: null, Status: container_id {, app_attempt_id {, application_id {, id: 6, cluster_timestamp: 1375865942038, }, attemptId: 1, }, id: 33, }, state: C_COMPLETE, diagnostics: "Container killed by the ApplicationMaster.\n\n", exit_status: 143, ] resource=<memory:1024, vCores:1> queue=default: capacity=1.0, absoluteCapacity=1.0, usedResources=<memory:48128, vCores:42>usedCapacity=0.9791667, absoluteUsedCapacity=0.9791667, numApps=5, numContainers=42 usedCapacity=0.9791667 absoluteUsedCapacity=0.9791667 used=<memory:48128, vCores:42> cluster=<memory:49152, vCores:96>
2013-08-07 09:10:58,658 INFO org.apache.hadoop.yarn.server.resourcemanager.scheduler.capacity.ParentQueue: completedContainer queue=root usedCapacity=0.9791667 absoluteUsedCapacity=0.9791667 used=<memory:48128, vCores:42> cluster=<memory:49152, vCores:96>
2013-08-07 09:10:58,658 INFO org.apache.hadoop.yarn.server.resourcemanager.scheduler.capacity.CapacityScheduler: Application appattempt_1375865942038_0006_000001 released container container_1375865942038_0006_01_000033 on node: host: hadoop-200-5:55554 #containers=6 available=1024 used=7168 with event: FINISHED
2013-08-07 09:10:58,659 INFO org.apache.hadoop.yarn.server.resourcemanager.rmcontainer.RMContainerImpl: container_1375865942038_0007_01_000014 Container Transitioned from NEW to ALLOCATED
2013-08-07 09:10:58,659 INFO org.apache.hadoop.yarn.server.resourcemanager.RMAuditLogger: USER=ubuntu	OPERATION=AM Allocated Container	TARGET=SchedulerApp	RESULT=SUCCESS	APPID=application_1375865942038_0007	CONTAINERID=container_1375865942038_0007_01_000014
2013-08-07 09:10:58,659 INFO org.apache.hadoop.yarn.server.resourcemanager.scheduler.common.fica.FiCaSchedulerNode: Assigned container container_1375865942038_0007_01_000014 of capacity <memory:1024, vCores:1> on host hadoop-200-5:55554, which currently has 7 containers, <memory:8192, vCores:7> used and <memory:0, vCores:9> available
2013-08-07 09:10:58,660 INFO org.apache.hadoop.yarn.server.resourcemanager.scheduler.capacity.LeafQueue: assignedContainer application=application_1375865942038_0007 container=Container: [ContainerId: container_1375865942038_0007_01_000014, NodeId: hadoop-200-5:55554, NodeHttpAddress: hadoop-200-5:8042, Resource: <memory:1024, vCores:1>, Priority: 20, State: NEW, Token: null, Status: container_id {, app_attempt_id {, application_id {, id: 7, cluster_timestamp: 1375865942038, }, attemptId: 1, }, id: 14, }, state: C_NEW, ] containerId=container_1375865942038_0007_01_000014 queue=default: capacity=1.0, absoluteCapacity=1.0, usedResources=<memory:48128, vCores:42>usedCapacity=0.9791667, absoluteUsedCapacity=0.9791667, numApps=5, numContainers=42 usedCapacity=0.9791667 absoluteUsedCapacity=0.9791667 used=<memory:48128, vCores:42> cluster=<memory:49152, vCores:96>
2013-08-07 09:10:58,660 INFO org.apache.hadoop.yarn.server.resourcemanager.scheduler.capacity.ParentQueue: Re-sorting queues since queue: root.default stats: default: capacity=1.0, absoluteCapacity=1.0, usedResources=<memory:49152, vCores:43>usedCapacity=1.0, absoluteUsedCapacity=1.0, numApps=5, numContainers=43
2013-08-07 09:10:58,660 INFO org.apache.hadoop.yarn.server.resourcemanager.scheduler.capacity.ParentQueue: assignedContainer queue=root usedCapacity=1.0 absoluteUsedCapacity=1.0 used=<memory:49152, vCores:43> cluster=<memory:49152, vCores:96>
2013-08-07 09:10:58,967 INFO org.apache.hadoop.yarn.server.resourcemanager.rmcontainer.RMContainerImpl: container_1375865942038_0006_01_000023 Container Transitioned from RUNNING to COMPLETED
2013-08-07 09:10:58,967 INFO org.apache.hadoop.yarn.server.resourcemanager.scheduler.common.fica.FiCaSchedulerApp: Completed container: container_1375865942038_0006_01_000023 in state: COMPLETED event:FINISHED
2013-08-07 09:10:58,967 INFO org.apache.hadoop.yarn.server.resourcemanager.RMAuditLogger: USER=ubuntu	OPERATION=AM Released Container	TARGET=SchedulerApp	RESULT=SUCCESS	APPID=application_1375865942038_0006	CONTAINERID=container_1375865942038_0006_01_000023
2013-08-07 09:10:58,967 INFO org.apache.hadoop.yarn.server.resourcemanager.scheduler.common.fica.FiCaSchedulerNode: Released container container_1375865942038_0006_01_000023 of capacity <memory:1024, vCores:1> on host hadoop-200-2:58832, which currently has 6 containers, <memory:7168, vCores:6> used and <memory:1024, vCores:10> available, release resources=true
2013-08-07 09:10:58,967 INFO org.apache.hadoop.yarn.server.resourcemanager.scheduler.capacity.LeafQueue: default used=<memory:48128, vCores:42> numContainers=42 user=ubuntu user-resources=<memory:48128, vCores:42>
2013-08-07 09:10:58,968 INFO org.apache.hadoop.yarn.server.resourcemanager.scheduler.capacity.LeafQueue: completedContainer container=Container: [ContainerId: container_1375865942038_0006_01_000023, NodeId: hadoop-200-2:58832, NodeHttpAddress: hadoop-200-2:8042, Resource: <memory:1024, vCores:1>, Priority: 20, State: NEW, Token: null, Status: container_id {, app_attempt_id {, application_id {, id: 6, cluster_timestamp: 1375865942038, }, attemptId: 1, }, id: 23, }, state: C_COMPLETE, diagnostics: "Container killed by the ApplicationMaster.\n\n", exit_status: 143, ] resource=<memory:1024, vCores:1> queue=default: capacity=1.0, absoluteCapacity=1.0, usedResources=<memory:48128, vCores:42>usedCapacity=0.9791667, absoluteUsedCapacity=0.9791667, numApps=5, numContainers=42 usedCapacity=0.9791667 absoluteUsedCapacity=0.9791667 used=<memory:48128, vCores:42> cluster=<memory:49152, vCores:96>
2013-08-07 09:10:58,968 INFO org.apache.hadoop.yarn.server.resourcemanager.scheduler.capacity.ParentQueue: completedContainer queue=root usedCapacity=0.9791667 absoluteUsedCapacity=0.9791667 used=<memory:48128, vCores:42> cluster=<memory:49152, vCores:96>
2013-08-07 09:10:58,969 INFO org.apache.hadoop.yarn.server.resourcemanager.scheduler.capacity.CapacityScheduler: Application appattempt_1375865942038_0006_000001 released container container_1375865942038_0006_01_000023 on node: host: hadoop-200-2:58832 #containers=6 available=1024 used=7168 with event: FINISHED
2013-08-07 09:10:58,969 INFO org.apache.hadoop.yarn.server.resourcemanager.rmcontainer.RMContainerImpl: container_1375865942038_0007_01_000015 Container Transitioned from NEW to ALLOCATED
2013-08-07 09:10:58,969 INFO org.apache.hadoop.yarn.server.resourcemanager.RMAuditLogger: USER=ubuntu	OPERATION=AM Allocated Container	TARGET=SchedulerApp	RESULT=SUCCESS	APPID=application_1375865942038_0007	CONTAINERID=container_1375865942038_0007_01_000015
2013-08-07 09:10:58,969 INFO org.apache.hadoop.yarn.server.resourcemanager.scheduler.common.fica.FiCaSchedulerNode: Assigned container container_1375865942038_0007_01_000015 of capacity <memory:1024, vCores:1> on host hadoop-200-2:58832, which currently has 7 containers, <memory:8192, vCores:7> used and <memory:0, vCores:9> available
2013-08-07 09:10:58,970 INFO org.apache.hadoop.yarn.server.resourcemanager.scheduler.capacity.LeafQueue: assignedContainer application=application_1375865942038_0007 container=Container: [ContainerId: container_1375865942038_0007_01_000015, NodeId: hadoop-200-2:58832, NodeHttpAddress: hadoop-200-2:8042, Resource: <memory:1024, vCores:1>, Priority: 20, State: NEW, Token: null, Status: container_id {, app_attempt_id {, application_id {, id: 7, cluster_timestamp: 1375865942038, }, attemptId: 1, }, id: 15, }, state: C_NEW, ] containerId=container_1375865942038_0007_01_000015 queue=default: capacity=1.0, absoluteCapacity=1.0, usedResources=<memory:48128, vCores:42>usedCapacity=0.9791667, absoluteUsedCapacity=0.9791667, numApps=5, numContainers=42 usedCapacity=0.9791667 absoluteUsedCapacity=0.9791667 used=<memory:48128, vCores:42> cluster=<memory:49152, vCores:96>
2013-08-07 09:10:58,971 INFO org.apache.hadoop.yarn.server.resourcemanager.scheduler.capacity.ParentQueue: Re-sorting queues since queue: root.default stats: default: capacity=1.0, absoluteCapacity=1.0, usedResources=<memory:49152, vCores:43>usedCapacity=1.0, absoluteUsedCapacity=1.0, numApps=5, numContainers=43
2013-08-07 09:10:58,971 INFO org.apache.hadoop.yarn.server.resourcemanager.scheduler.capacity.ParentQueue: assignedContainer queue=root usedCapacity=1.0 absoluteUsedCapacity=1.0 used=<memory:49152, vCores:43> cluster=<memory:49152, vCores:96>
2013-08-07 09:10:58,971 INFO org.apache.hadoop.yarn.server.resourcemanager.rmcontainer.RMContainerImpl: container_1375865942038_0006_01_000035 Container Transitioned from RUNNING to COMPLETED
2013-08-07 09:10:58,971 INFO org.apache.hadoop.yarn.server.resourcemanager.scheduler.common.fica.FiCaSchedulerApp: Completed container: container_1375865942038_0006_01_000035 in state: COMPLETED event:FINISHED
2013-08-07 09:10:58,971 INFO org.apache.hadoop.yarn.server.resourcemanager.RMAuditLogger: USER=ubuntu	OPERATION=AM Released Container	TARGET=SchedulerApp	RESULT=SUCCESS	APPID=application_1375865942038_0006	CONTAINERID=container_1375865942038_0006_01_000035
