2013-08-22 03:19:13,158 INFO org.apache.hadoop.yarn.server.resourcemanager.ResourceManager: STARTUP_MSG: 
/************************************************************
STARTUP_MSG: Starting ResourceManager
STARTUP_MSG:   host = hadoop-998-1/192.168.100.9
STARTUP_MSG:   args = []
STARTUP_MSG:   version = 3.0.0-SNAPSHOT
STARTUP_MSG:   build = https://github.com/lalithsuresh/hadoop-common -r 0cb423bd4868928bb06cd93f882bb0913172fd17; compiled by 'lsuresh' on 2013-04-08T15:47Z
STARTUP_MSG:   java = 1.7.0_17
************************************************************/
2013-08-22 03:19:13,174 INFO org.apache.hadoop.yarn.server.resourcemanager.ResourceManager: registered UNIX signal handlers for [TERM, HUP, INT]
2013-08-22 03:19:13,835 INFO org.apache.hadoop.yarn.server.resourcemanager.security.ApplicationTokenSecretManager: Rolling master-key for application-tokens
2013-08-22 03:19:13,858 INFO org.apache.hadoop.yarn.server.resourcemanager.security.RMContainerTokenSecretManager: ContainerTokenKeyRollingInterval: 86400000ms and ContainerTokenKeyActivationDelay: 900000ms
2013-08-22 03:19:13,861 INFO org.apache.hadoop.yarn.service.AbstractService: Service:Dispatcher is inited.
2013-08-22 03:19:13,862 INFO org.apache.hadoop.yarn.event.AsyncDispatcher: Registering class org.apache.hadoop.yarn.server.resourcemanager.recovery.RMStateStoreEventType for class org.apache.hadoop.yarn.server.resourcemanager.recovery.RMStateStore$ForwardingEventHandler
2013-08-22 03:19:13,862 INFO org.apache.hadoop.yarn.service.AbstractService: Service:Dispatcher is started.
2013-08-22 03:19:13,868 INFO org.apache.hadoop.yarn.event.AsyncDispatcher: Registering class org.apache.hadoop.yarn.server.resourcemanager.NodesListManagerEventType for class org.apache.hadoop.yarn.server.resourcemanager.NodesListManager
2013-08-22 03:19:13,868 INFO org.apache.hadoop.yarn.server.resourcemanager.ResourceManager: Using Scheduler: org.apache.hadoop.yarn.server.resourcemanager.scheduler.capacity.CapacityScheduler
2013-08-22 03:19:14,021 INFO org.apache.hadoop.yarn.event.AsyncDispatcher: Registering class org.apache.hadoop.yarn.server.resourcemanager.scheduler.event.SchedulerEventType for class org.apache.hadoop.yarn.server.resourcemanager.ResourceManager$SchedulerEventDispatcher
2013-08-22 03:19:14,023 INFO org.apache.hadoop.yarn.event.AsyncDispatcher: Registering class org.apache.hadoop.yarn.server.resourcemanager.rmapp.RMAppEventType for class org.apache.hadoop.yarn.server.resourcemanager.ResourceManager$ApplicationEventDispatcher
2013-08-22 03:19:14,025 INFO org.apache.hadoop.yarn.event.AsyncDispatcher: Registering class org.apache.hadoop.yarn.server.resourcemanager.rmapp.attempt.RMAppAttemptEventType for class org.apache.hadoop.yarn.server.resourcemanager.ResourceManager$ApplicationAttemptEventDispatcher
2013-08-22 03:19:14,027 INFO org.apache.hadoop.yarn.event.AsyncDispatcher: Registering class org.apache.hadoop.yarn.server.resourcemanager.rmnode.RMNodeEventType for class org.apache.hadoop.yarn.server.resourcemanager.ResourceManager$NodeEventDispatcher
2013-08-22 03:19:14,550 WARN org.apache.hadoop.util.NativeCodeLoader: Unable to load native-hadoop library for your platform... using builtin-java classes where applicable
2013-08-22 03:19:14,579 INFO org.apache.hadoop.yarn.server.resourcemanager.scheduler.capacity.ParentQueue: root, capacity=1.0, asboluteCapacity=1.0, maxCapacity=1.0, asboluteMaxCapacity=1.0, state=RUNNING, acls=ADMINISTER_QUEUE:*SUBMIT_APPLICATIONS:*
2013-08-22 03:19:14,579 INFO org.apache.hadoop.yarn.server.resourcemanager.scheduler.capacity.ParentQueue: Initialized parent-queue root name=root, fullname=root
2013-08-22 03:19:14,599 INFO org.apache.hadoop.yarn.server.resourcemanager.scheduler.capacity.LeafQueue: Initializing default
capacity = 1.0 [= (float) configuredCapacity / 100 ]
asboluteCapacity = 1.0 [= parentAbsoluteCapacity * capacity ]
maxCapacity = 1.0 [= configuredMaxCapacity ]
absoluteMaxCapacity = 1.0 [= 1.0 maximumCapacity undefined, (parentAbsoluteMaxCapacity * maximumCapacity) / 100 otherwise ]
userLimit = 100 [= configuredUserLimit ]
userLimitFactor = 1.0 [= configuredUserLimitFactor ]
maxApplications = 10000 [= configuredMaximumSystemApplicationsPerQueue or (int)(configuredMaximumSystemApplications * absoluteCapacity)]
maxApplicationsPerUser = 10000 [= (int)(maxApplications * (userLimit / 100.0f) * userLimitFactor) ]
maxActiveApplications = 1 [= max((int)ceil((clusterResourceMemory / minimumAllocation) * maxAMResourcePerQueuePercent * absoluteMaxCapacity),1) ]
maxActiveAppsUsingAbsCap = 1 [= max((int)ceil((clusterResourceMemory / minimumAllocation) *maxAMResourcePercent * absoluteCapacity),1) ]
maxActiveApplicationsPerUser = 1 [= max((int)(maxActiveApplications * (userLimit / 100.0f) * userLimitFactor),1) ]
usedCapacity = 0.0 [= usedResourcesMemory / (clusterResourceMemory * absoluteCapacity)]
absoluteUsedCapacity = 0.0 [= usedResourcesMemory / clusterResourceMemory]
maxAMResourcePerQueuePercent = 0.1 [= configuredMaximumAMResourcePercent ]
minimumAllocationFactor = 0.875 [= (float)(maximumAllocationMemory - minimumAllocationMemory) / maximumAllocationMemory ]
numContainers = 0 [= currentNumContainers ]
state = RUNNING [= configuredState ]
acls = ADMINISTER_QUEUE:*SUBMIT_APPLICATIONS:* [= configuredAcls ]

2013-08-22 03:19:14,599 INFO org.apache.hadoop.yarn.server.resourcemanager.scheduler.capacity.CapacityScheduler: Initialized queue: default: capacity=1.0, absoluteCapacity=1.0, usedResources=<memory:0, vCores:0>usedCapacity=0.0, absoluteUsedCapacity=0.0, numApps=0, numContainers=0
2013-08-22 03:19:14,600 INFO org.apache.hadoop.yarn.server.resourcemanager.scheduler.capacity.CapacityScheduler: Initialized queue: root: numChildQueue= 1, capacity=1.0, absoluteCapacity=1.0, usedResources=<memory:0, vCores:0>usedCapacity=0.0, numApps=0, numContainers=0
2013-08-22 03:19:14,600 INFO org.apache.hadoop.yarn.server.resourcemanager.scheduler.capacity.CapacityScheduler: Initialized root queue root: numChildQueue= 1, capacity=1.0, absoluteCapacity=1.0, usedResources=<memory:0, vCores:0>usedCapacity=0.0, numApps=0, numContainers=0
2013-08-22 03:19:14,600 INFO org.apache.hadoop.yarn.server.resourcemanager.scheduler.capacity.CapacityScheduler: Initialized CapacityScheduler with calculator=class org.apache.hadoop.yarn.server.resourcemanager.resource.DefaultResourceCalculator, minimumAllocation=<<memory:1024, vCores:1>>, maximumAllocation=<<memory:8192, vCores:32>>
2013-08-22 03:19:14,945 INFO org.apache.hadoop.yarn.event.AsyncDispatcher: Registering class org.apache.hadoop.yarn.server.resourcemanager.RMAppManagerEventType for class org.apache.hadoop.yarn.server.resourcemanager.RMAppManager
2013-08-22 03:19:14,964 INFO org.apache.hadoop.yarn.event.AsyncDispatcher: Registering class org.apache.hadoop.yarn.server.resourcemanager.amlauncher.AMLauncherEventType for class org.apache.hadoop.yarn.server.resourcemanager.amlauncher.ApplicationMasterLauncher
2013-08-22 03:19:15,047 INFO org.apache.hadoop.yarn.server.resourcemanager.RMNMInfo: Registered RMNMInfo MBean
2013-08-22 03:19:15,047 INFO org.apache.hadoop.yarn.service.AbstractService: Service:Dispatcher is inited.
2013-08-22 03:19:15,048 INFO org.apache.hadoop.yarn.service.AbstractService: Service:org.apache.hadoop.yarn.server.resourcemanager.rmcontainer.ContainerAllocationExpirer is inited.
2013-08-22 03:19:15,048 INFO org.apache.hadoop.yarn.service.AbstractService: Service:AMLivelinessMonitor is inited.
2013-08-22 03:19:15,048 INFO org.apache.hadoop.yarn.service.AbstractService: Service:AMLivelinessMonitor is inited.
2013-08-22 03:19:15,048 INFO org.apache.hadoop.yarn.service.AbstractService: Service:org.apache.hadoop.yarn.server.resourcemanager.security.DelegationTokenRenewer is inited.
2013-08-22 03:19:15,049 INFO org.apache.hadoop.util.HostsFileReader: Refreshing hosts (include/exclude) list
2013-08-22 03:19:15,050 INFO org.apache.hadoop.yarn.service.AbstractService: Service:org.apache.hadoop.yarn.server.resourcemanager.NodesListManager is inited.
2013-08-22 03:19:15,050 INFO org.apache.hadoop.yarn.service.AbstractService: Service:org.apache.hadoop.yarn.server.resourcemanager.ResourceManager$SchedulerEventDispatcher is inited.
2013-08-22 03:19:15,050 INFO org.apache.hadoop.yarn.service.AbstractService: Service:NMLivelinessMonitor is inited.
2013-08-22 03:19:15,056 INFO org.apache.hadoop.yarn.service.AbstractService: Service:org.apache.hadoop.yarn.server.resourcemanager.ResourceTrackerService is inited.
2013-08-22 03:19:15,056 INFO org.apache.hadoop.yarn.service.AbstractService: Service:org.apache.hadoop.yarn.server.resourcemanager.ApplicationMasterService is inited.
2013-08-22 03:19:15,057 INFO org.apache.hadoop.yarn.service.AbstractService: Service:org.apache.hadoop.yarn.server.resourcemanager.ClientRMService is inited.
2013-08-22 03:19:15,057 INFO org.apache.hadoop.yarn.service.AbstractService: Service:org.apache.hadoop.yarn.server.resourcemanager.AdminService is inited.
2013-08-22 03:19:15,057 INFO org.apache.hadoop.yarn.service.AbstractService: Service:org.apache.hadoop.yarn.server.resourcemanager.amlauncher.ApplicationMasterLauncher is inited.
2013-08-22 03:19:15,057 INFO org.apache.hadoop.yarn.service.AbstractService: Service:ResourceManager is inited.
2013-08-22 03:19:15,057 INFO org.apache.hadoop.yarn.server.resourcemanager.security.RMContainerTokenSecretManager: Rolling master-key for container-tokens
2013-08-22 03:19:15,057 INFO org.apache.hadoop.yarn.server.resourcemanager.security.ApplicationTokenSecretManager: Rolling master-key for application-tokens
2013-08-22 03:19:15,190 INFO org.mortbay.log: Logging to org.slf4j.impl.Log4jLoggerAdapter(org.mortbay.log) via org.mortbay.log.Slf4jLog
2013-08-22 03:19:15,275 INFO org.apache.hadoop.http.HttpServer: Added global filter 'safety' (class=org.apache.hadoop.http.HttpServer$QuotingInputFilter)
2013-08-22 03:19:15,280 INFO org.apache.hadoop.http.HttpServer: Added filter static_user_filter (class=org.apache.hadoop.http.lib.StaticUserWebFilter$StaticUserFilter) to context cluster
2013-08-22 03:19:15,280 INFO org.apache.hadoop.http.HttpServer: Added filter static_user_filter (class=org.apache.hadoop.http.lib.StaticUserWebFilter$StaticUserFilter) to context static
2013-08-22 03:19:15,280 INFO org.apache.hadoop.http.HttpServer: Added filter static_user_filter (class=org.apache.hadoop.http.lib.StaticUserWebFilter$StaticUserFilter) to context logs
2013-08-22 03:19:15,288 INFO org.apache.hadoop.http.HttpServer: adding path spec: /cluster
2013-08-22 03:19:15,288 INFO org.apache.hadoop.http.HttpServer: adding path spec: /cluster/*
2013-08-22 03:19:15,288 INFO org.apache.hadoop.http.HttpServer: adding path spec: /ws
2013-08-22 03:19:15,289 INFO org.apache.hadoop.http.HttpServer: adding path spec: /ws/*
2013-08-22 03:19:15,291 INFO org.apache.hadoop.http.HttpServer: Added global filter 'guice' (class=com.google.inject.servlet.GuiceFilter)
2013-08-22 03:19:15,301 INFO org.apache.hadoop.http.HttpServer: Jetty bound to port 8088
2013-08-22 03:19:15,301 INFO org.mortbay.log: jetty-6.1.26
2013-08-22 03:19:15,356 INFO org.mortbay.log: Extract jar:file:/home/ubuntu/hadoop-3.0.0-SNAPSHOT/share/hadoop/yarn/hadoop-yarn-common-3.0.0-SNAPSHOT.jar!/webapps/cluster to /tmp/Jetty_0_0_0_0_8088_cluster____u0rgz3/webapp
2013-08-22 03:19:15,817 INFO org.mortbay.log: Started SelectChannelConnector@0.0.0.0:8088
2013-08-22 03:19:15,817 INFO org.apache.hadoop.yarn.webapp.WebApps: Web app /cluster started at 8088
2013-08-22 03:19:16,288 INFO org.apache.hadoop.yarn.webapp.WebApps: Registered webapp guice modules
2013-08-22 03:19:16,376 INFO org.apache.hadoop.metrics2.impl.MetricsConfig: loaded properties from hadoop-metrics2.properties
2013-08-22 03:19:16,403 INFO org.apache.hadoop.metrics2.impl.MetricsSystemImpl: Scheduled snapshot period at 10 second(s).
2013-08-22 03:19:16,403 INFO org.apache.hadoop.metrics2.impl.MetricsSystemImpl: ResourceManager metrics system started
2013-08-22 03:19:16,415 INFO org.apache.hadoop.security.token.delegation.AbstractDelegationTokenSecretManager: Updating the current master key for generating delegation tokens
2013-08-22 03:19:16,417 INFO org.apache.hadoop.yarn.service.AbstractService: Service:Dispatcher is started.
2013-08-22 03:19:16,418 INFO org.apache.hadoop.security.token.delegation.AbstractDelegationTokenSecretManager: Starting expired delegation token remover thread, tokenRemoverScanInterval=60 min(s)
2013-08-22 03:19:16,418 INFO org.apache.hadoop.security.token.delegation.AbstractDelegationTokenSecretManager: Updating the current master key for generating delegation tokens
2013-08-22 03:19:16,419 INFO org.apache.hadoop.yarn.service.AbstractService: Service:org.apache.hadoop.yarn.server.resourcemanager.rmcontainer.ContainerAllocationExpirer is started.
2013-08-22 03:19:16,420 INFO org.apache.hadoop.yarn.service.AbstractService: Service:AMLivelinessMonitor is started.
2013-08-22 03:19:16,420 INFO org.apache.hadoop.yarn.service.AbstractService: Service:AMLivelinessMonitor is started.
2013-08-22 03:19:16,420 INFO org.apache.hadoop.yarn.service.AbstractService: Service:org.apache.hadoop.yarn.server.resourcemanager.security.DelegationTokenRenewer is started.
2013-08-22 03:19:16,421 INFO org.apache.hadoop.yarn.service.AbstractService: Service:org.apache.hadoop.yarn.server.resourcemanager.NodesListManager is started.
2013-08-22 03:19:16,422 INFO org.apache.hadoop.yarn.service.AbstractService: Service:org.apache.hadoop.yarn.server.resourcemanager.ResourceManager$SchedulerEventDispatcher is started.
2013-08-22 03:19:16,422 INFO org.apache.hadoop.yarn.service.AbstractService: Service:NMLivelinessMonitor is started.
2013-08-22 03:19:16,423 INFO org.apache.hadoop.yarn.service.AbstractService: Service:org.apache.hadoop.yarn.server.resourcemanager.ResourceTrackerService is started.
2013-08-22 03:19:16,482 INFO org.apache.hadoop.ipc.Server: Starting Socket Reader #1 for port 54110
2013-08-22 03:19:16,522 INFO org.apache.hadoop.yarn.factories.impl.pb.RpcServerFactoryPBImpl: Adding protocol org.apache.hadoop.yarn.server.api.ResourceTrackerPB to the server
2013-08-22 03:19:16,523 INFO org.apache.hadoop.ipc.Server: IPC Server Responder: starting
2013-08-22 03:19:16,523 INFO org.apache.hadoop.ipc.Server: IPC Server listener on 54110: starting
2013-08-22 03:19:16,599 INFO org.apache.hadoop.ipc.Server: Starting Socket Reader #1 for port 54112
2013-08-22 03:19:16,614 INFO org.apache.hadoop.yarn.factories.impl.pb.RpcServerFactoryPBImpl: Adding protocol org.apache.hadoop.yarn.api.AMRMProtocolPB to the server
2013-08-22 03:19:16,615 INFO org.apache.hadoop.ipc.Server: IPC Server Responder: starting
2013-08-22 03:19:16,616 INFO org.apache.hadoop.ipc.Server: IPC Server listener on 54112: starting
2013-08-22 03:19:16,655 INFO org.apache.hadoop.yarn.service.AbstractService: Service:org.apache.hadoop.yarn.server.resourcemanager.ApplicationMasterService is started.
2013-08-22 03:19:16,707 INFO org.apache.hadoop.ipc.Server: Starting Socket Reader #1 for port 54111
2013-08-22 03:19:16,714 INFO org.apache.hadoop.yarn.factories.impl.pb.RpcServerFactoryPBImpl: Adding protocol org.apache.hadoop.yarn.api.ClientRMProtocolPB to the server
2013-08-22 03:19:16,715 INFO org.apache.hadoop.ipc.Server: IPC Server Responder: starting
2013-08-22 03:19:16,716 INFO org.apache.hadoop.ipc.Server: IPC Server listener on 54111: starting
2013-08-22 03:19:16,749 INFO org.apache.hadoop.yarn.service.AbstractService: Service:org.apache.hadoop.yarn.server.resourcemanager.ClientRMService is started.
2013-08-22 03:19:16,783 INFO org.apache.hadoop.ipc.Server: Starting Socket Reader #1 for port 8033
2013-08-22 03:19:16,792 INFO org.apache.hadoop.yarn.factories.impl.pb.RpcServerFactoryPBImpl: Adding protocol org.apache.hadoop.yarn.api.RMAdminProtocolPB to the server
2013-08-22 03:19:16,793 INFO org.apache.hadoop.ipc.Server: IPC Server Responder: starting
2013-08-22 03:19:16,796 INFO org.apache.hadoop.yarn.service.AbstractService: Service:org.apache.hadoop.yarn.server.resourcemanager.AdminService is started.
2013-08-22 03:19:16,796 INFO org.apache.hadoop.ipc.Server: IPC Server listener on 8033: starting
2013-08-22 03:19:16,797 INFO org.apache.hadoop.yarn.service.AbstractService: Service:org.apache.hadoop.yarn.server.resourcemanager.amlauncher.ApplicationMasterLauncher is started.
2013-08-22 03:19:16,797 INFO org.apache.hadoop.yarn.service.AbstractService: Service:ResourceManager is started.
2013-08-22 03:19:27,483 INFO org.apache.hadoop.yarn.util.RackResolver: Resolved hadoop-998-2 to /default-rack
2013-08-22 03:19:27,483 INFO org.apache.hadoop.yarn.util.RackResolver: Resolved hadoop-998-3 to /default-rack
2013-08-22 03:19:27,489 INFO org.apache.hadoop.yarn.util.RackResolver: Resolved hadoop-998-5 to /default-rack
2013-08-22 03:19:27,500 INFO org.apache.hadoop.yarn.server.resourcemanager.ResourceTrackerService: NodeManager from node hadoop-998-2(cmPort: 35081 httpPort: 8042) registered with capability: <memory:8192, vCores:16>, assigned nodeId hadoop-998-2:35081
2013-08-22 03:19:27,500 INFO org.apache.hadoop.yarn.server.resourcemanager.ResourceTrackerService: NodeManager from node hadoop-998-3(cmPort: 53776 httpPort: 8042) registered with capability: <memory:8192, vCores:16>, assigned nodeId hadoop-998-3:53776
2013-08-22 03:19:27,511 INFO org.apache.hadoop.yarn.server.resourcemanager.ResourceTrackerService: NodeManager from node hadoop-998-5(cmPort: 56087 httpPort: 8042) registered with capability: <memory:8192, vCores:16>, assigned nodeId hadoop-998-5:56087
2013-08-22 03:19:27,514 INFO org.apache.hadoop.yarn.server.resourcemanager.rmnode.RMNodeImpl: hadoop-998-5:56087 Node Transitioned from NEW to RUNNING
2013-08-22 03:19:27,527 INFO org.apache.hadoop.yarn.server.resourcemanager.rmnode.RMNodeImpl: hadoop-998-2:35081 Node Transitioned from NEW to RUNNING
2013-08-22 03:19:27,532 INFO org.apache.hadoop.yarn.server.resourcemanager.rmnode.RMNodeImpl: hadoop-998-3:53776 Node Transitioned from NEW to RUNNING
2013-08-22 03:19:27,536 INFO org.apache.hadoop.yarn.server.resourcemanager.scheduler.capacity.CapacityScheduler: Added node hadoop-998-5:56087 clusterResource: <memory:8192, vCores:16>
2013-08-22 03:19:27,537 INFO org.apache.hadoop.yarn.server.resourcemanager.scheduler.capacity.CapacityScheduler: Added node hadoop-998-2:35081 clusterResource: <memory:16384, vCores:32>
2013-08-22 03:19:27,537 INFO org.apache.hadoop.yarn.server.resourcemanager.scheduler.capacity.CapacityScheduler: Added node hadoop-998-3:53776 clusterResource: <memory:24576, vCores:48>
2013-08-22 03:19:27,586 INFO org.apache.hadoop.yarn.util.RackResolver: Resolved hadoop-998-7 to /default-rack
2013-08-22 03:19:27,586 INFO org.apache.hadoop.yarn.server.resourcemanager.ResourceTrackerService: NodeManager from node hadoop-998-7(cmPort: 60905 httpPort: 8042) registered with capability: <memory:8192, vCores:16>, assigned nodeId hadoop-998-7:60905
2013-08-22 03:19:27,587 INFO org.apache.hadoop.yarn.server.resourcemanager.rmnode.RMNodeImpl: hadoop-998-7:60905 Node Transitioned from NEW to RUNNING
2013-08-22 03:19:27,588 INFO org.apache.hadoop.yarn.server.resourcemanager.scheduler.capacity.CapacityScheduler: Added node hadoop-998-7:60905 clusterResource: <memory:32768, vCores:64>
2013-08-22 03:19:27,737 INFO org.apache.hadoop.yarn.util.RackResolver: Resolved hadoop-998-4 to /default-rack
2013-08-22 03:19:27,738 INFO org.apache.hadoop.yarn.server.resourcemanager.ResourceTrackerService: NodeManager from node hadoop-998-4(cmPort: 35553 httpPort: 8042) registered with capability: <memory:8192, vCores:16>, assigned nodeId hadoop-998-4:35553
2013-08-22 03:19:27,738 INFO org.apache.hadoop.yarn.server.resourcemanager.rmnode.RMNodeImpl: hadoop-998-4:35553 Node Transitioned from NEW to RUNNING
2013-08-22 03:19:27,739 INFO org.apache.hadoop.yarn.server.resourcemanager.scheduler.capacity.CapacityScheduler: Added node hadoop-998-4:35553 clusterResource: <memory:40960, vCores:80>
2013-08-22 03:19:28,180 INFO org.apache.hadoop.yarn.util.RackResolver: Resolved hadoop-998-6 to /default-rack
2013-08-22 03:19:28,180 INFO org.apache.hadoop.yarn.server.resourcemanager.ResourceTrackerService: NodeManager from node hadoop-998-6(cmPort: 58634 httpPort: 8042) registered with capability: <memory:8192, vCores:16>, assigned nodeId hadoop-998-6:58634
2013-08-22 03:19:28,183 INFO org.apache.hadoop.yarn.server.resourcemanager.rmnode.RMNodeImpl: hadoop-998-6:58634 Node Transitioned from NEW to RUNNING
2013-08-22 03:19:28,184 INFO org.apache.hadoop.yarn.server.resourcemanager.scheduler.capacity.CapacityScheduler: Added node hadoop-998-6:58634 clusterResource: <memory:49152, vCores:96>
2013-08-22 03:19:34,640 INFO org.apache.hadoop.yarn.server.resourcemanager.ClientRMService: Allocated new applicationId: 1
2013-08-22 03:19:38,132 INFO org.apache.hadoop.yarn.server.resourcemanager.ClientRMService: Storing Application with id application_1377141553101_0001
2013-08-22 03:19:38,136 INFO org.apache.hadoop.yarn.server.resourcemanager.recovery.RMStateStore: Storing info for app: application_1377141553101_0001
2013-08-22 03:19:38,136 INFO org.apache.hadoop.yarn.server.resourcemanager.ClientRMService: Application with id 1 submitted by user ubuntu
2013-08-22 03:19:38,139 INFO org.apache.hadoop.yarn.server.resourcemanager.RMAuditLogger: USER=ubuntu	IP=192.168.100.9	OPERATION=Submit Application Request	TARGET=ClientRMService	RESULT=SUCCESS	APPID=application_1377141553101_0001
2013-08-22 03:19:38,181 INFO org.apache.hadoop.yarn.server.resourcemanager.rmapp.RMAppImpl: application_1377141553101_0001 State change from NEW to SUBMITTED
2013-08-22 03:19:38,182 INFO org.apache.hadoop.yarn.server.resourcemanager.ApplicationMasterService: Registering appattempt_1377141553101_0001_000001
2013-08-22 03:19:38,184 INFO org.apache.hadoop.yarn.server.resourcemanager.rmapp.attempt.RMAppAttemptImpl: appattempt_1377141553101_0001_000001 State change from NEW to SUBMITTED
2013-08-22 03:19:38,230 INFO org.apache.hadoop.yarn.server.resourcemanager.scheduler.capacity.LeafQueue: Application application_1377141553101_0001 from user: ubuntu activated in queue: default
2013-08-22 03:19:38,230 INFO org.apache.hadoop.yarn.server.resourcemanager.scheduler.capacity.LeafQueue: Application added - appId: application_1377141553101_0001 user: org.apache.hadoop.yarn.server.resourcemanager.scheduler.capacity.LeafQueue$User@110abafa, leaf-queue: default #user-pending-applications: 0 #user-active-applications: 1 #queue-pending-applications: 0 #queue-active-applications: 1
2013-08-22 03:19:38,230 INFO org.apache.hadoop.yarn.server.resourcemanager.scheduler.capacity.ParentQueue: Application added - appId: application_1377141553101_0001 user: ubuntu leaf-queue of parent: root #applications: 1
2013-08-22 03:19:38,231 INFO org.apache.hadoop.yarn.server.resourcemanager.scheduler.capacity.CapacityScheduler: Application Submission: appattempt_1377141553101_0001_000001, user: ubuntu queue: default: capacity=1.0, absoluteCapacity=1.0, usedResources=<memory:0, vCores:0>usedCapacity=0.0, absoluteUsedCapacity=0.0, numApps=1, numContainers=0, currently active: 1
2013-08-22 03:19:38,236 INFO org.apache.hadoop.yarn.server.resourcemanager.rmapp.attempt.RMAppAttemptImpl: appattempt_1377141553101_0001_000001 State change from SUBMITTED to SCHEDULED
2013-08-22 03:19:38,237 INFO org.apache.hadoop.yarn.server.resourcemanager.rmapp.RMAppImpl: application_1377141553101_0001 State change from SUBMITTED to ACCEPTED
2013-08-22 03:19:38,344 INFO org.apache.hadoop.yarn.server.resourcemanager.rmcontainer.RMContainerImpl: container_1377141553101_0001_01_000001 Container Transitioned from NEW to ALLOCATED
2013-08-22 03:19:38,344 INFO org.apache.hadoop.yarn.server.resourcemanager.RMAuditLogger: USER=ubuntu	OPERATION=AM Allocated Container	TARGET=SchedulerApp	RESULT=SUCCESS	APPID=application_1377141553101_0001	CONTAINERID=container_1377141553101_0001_01_000001
2013-08-22 03:19:38,345 INFO org.apache.hadoop.yarn.server.resourcemanager.scheduler.common.fica.FiCaSchedulerNode: Assigned container container_1377141553101_0001_01_000001 of capacity <memory:2048, vCores:1> on host hadoop-998-6:58634, which currently has 1 containers, <memory:2048, vCores:1> used and <memory:6144, vCores:15> available
2013-08-22 03:19:38,351 INFO org.apache.hadoop.yarn.server.resourcemanager.scheduler.capacity.LeafQueue: assignedContainer application=application_1377141553101_0001 container=Container: [ContainerId: container_1377141553101_0001_01_000001, NodeId: hadoop-998-6:58634, NodeHttpAddress: hadoop-998-6:8042, Resource: <memory:2048, vCores:1>, Priority: 0, State: NEW, Token: null, Status: container_id {, app_attempt_id {, application_id {, id: 1, cluster_timestamp: 1377141553101, }, attemptId: 1, }, id: 1, }, state: C_NEW, ] containerId=container_1377141553101_0001_01_000001 queue=default: capacity=1.0, absoluteCapacity=1.0, usedResources=<memory:0, vCores:0>usedCapacity=0.0, absoluteUsedCapacity=0.0, numApps=1, numContainers=0 usedCapacity=0.0 absoluteUsedCapacity=0.0 used=<memory:0, vCores:0> cluster=<memory:49152, vCores:96>
2013-08-22 03:19:38,352 INFO org.apache.hadoop.yarn.server.resourcemanager.scheduler.capacity.ParentQueue: Re-sorting queues since queue: root.default stats: default: capacity=1.0, absoluteCapacity=1.0, usedResources=<memory:2048, vCores:1>usedCapacity=0.041666668, absoluteUsedCapacity=0.041666668, numApps=1, numContainers=1
2013-08-22 03:19:38,352 INFO org.apache.hadoop.yarn.server.resourcemanager.scheduler.capacity.ParentQueue: assignedContainer queue=root usedCapacity=0.041666668 absoluteUsedCapacity=0.041666668 used=<memory:2048, vCores:1> cluster=<memory:49152, vCores:96>
2013-08-22 03:19:38,354 INFO org.apache.hadoop.yarn.server.resourcemanager.rmcontainer.RMContainerImpl: container_1377141553101_0001_01_000001 Container Transitioned from ALLOCATED to ACQUIRED
2013-08-22 03:19:38,357 INFO org.apache.hadoop.yarn.server.resourcemanager.rmapp.attempt.RMAppAttemptImpl: Storing attempt: AppId: application_1377141553101_0001 AttemptId: appattempt_1377141553101_0001_000001 MasterContainer: Container: [ContainerId: container_1377141553101_0001_01_000001, NodeId: hadoop-998-6:58634, NodeHttpAddress: hadoop-998-6:8042, Resource: <memory:2048, vCores:1>, Priority: 0, State: NEW, Token: null, Status: container_id {, app_attempt_id {, application_id {, id: 1, cluster_timestamp: 1377141553101, }, attemptId: 1, }, id: 1, }, state: C_NEW, ]
2013-08-22 03:19:38,363 INFO org.apache.hadoop.yarn.server.resourcemanager.rmapp.attempt.RMAppAttemptImpl: appattempt_1377141553101_0001_000001 State change from SCHEDULED to ALLOCATED_SAVING
2013-08-22 03:19:38,364 INFO org.apache.hadoop.yarn.server.resourcemanager.recovery.RMStateStore: Storing info for attempt: appattempt_1377141553101_0001_000001
2013-08-22 03:19:38,367 INFO org.apache.hadoop.yarn.server.resourcemanager.rmapp.attempt.RMAppAttemptImpl: appattempt_1377141553101_0001_000001 State change from ALLOCATED_SAVING to ALLOCATED
2013-08-22 03:19:38,375 INFO org.apache.hadoop.yarn.server.resourcemanager.amlauncher.AMLauncher: Launching masterappattempt_1377141553101_0001_000001
2013-08-22 03:19:38,415 INFO org.apache.hadoop.yarn.server.resourcemanager.amlauncher.AMLauncher: Setting up container Container: [ContainerId: container_1377141553101_0001_01_000001, NodeId: hadoop-998-6:58634, NodeHttpAddress: hadoop-998-6:8042, Resource: <memory:2048, vCores:1>, Priority: 0, State: NEW, Token: null, Status: container_id {, app_attempt_id {, application_id {, id: 1, cluster_timestamp: 1377141553101, }, attemptId: 1, }, id: 1, }, state: C_NEW, ] for AM appattempt_1377141553101_0001_000001
2013-08-22 03:19:38,416 INFO org.apache.hadoop.yarn.server.resourcemanager.amlauncher.AMLauncher: Command to launch container container_1377141553101_0001_01_000001 : $JAVA_HOME/bin/java -Dlog4j.configuration=container-log4j.properties -Dyarn.app.mapreduce.container.log.dir=<LOG_DIR> -Dyarn.app.mapreduce.container.log.filesize=0 -Dhadoop.root.logger=INFO,CLA  -Xmx1024m org.apache.hadoop.mapreduce.v2.app.MRAppMaster 1><LOG_DIR>/stdout 2><LOG_DIR>/stderr 
2013-08-22 03:19:39,387 INFO org.apache.hadoop.yarn.server.resourcemanager.amlauncher.AMLauncher: Done launching container Container: [ContainerId: container_1377141553101_0001_01_000001, NodeId: hadoop-998-6:58634, NodeHttpAddress: hadoop-998-6:8042, Resource: <memory:2048, vCores:1>, Priority: 0, State: NEW, Token: null, Status: container_id {, app_attempt_id {, application_id {, id: 1, cluster_timestamp: 1377141553101, }, attemptId: 1, }, id: 1, }, state: C_NEW, ] for AM appattempt_1377141553101_0001_000001
2013-08-22 03:19:39,388 INFO org.apache.hadoop.yarn.server.resourcemanager.rmapp.attempt.RMAppAttemptImpl: appattempt_1377141553101_0001_000001 State change from ALLOCATED to LAUNCHED
2013-08-22 03:19:40,331 INFO org.apache.hadoop.yarn.server.resourcemanager.rmcontainer.RMContainerImpl: container_1377141553101_0001_01_000001 Container Transitioned from ACQUIRED to RUNNING
2013-08-22 03:19:46,828 INFO org.apache.hadoop.yarn.server.resourcemanager.ApplicationMasterService: AM registration appattempt_1377141553101_0001_000001
2013-08-22 03:19:46,830 INFO org.apache.hadoop.yarn.server.resourcemanager.RMAuditLogger: USER=ubuntu	IP=192.168.100.10	OPERATION=Register App Master	TARGET=ApplicationMasterService	RESULT=SUCCESS	APPID=application_1377141553101_0001	APPATTEMPTID=appattempt_1377141553101_0001_000001
2013-08-22 03:19:46,834 INFO org.apache.hadoop.yarn.server.resourcemanager.rmapp.attempt.RMAppAttemptImpl: appattempt_1377141553101_0001_000001 State change from LAUNCHED to RUNNING
2013-08-22 03:19:46,835 INFO org.apache.hadoop.yarn.server.resourcemanager.rmapp.RMAppImpl: application_1377141553101_0001 State change from ACCEPTED to RUNNING
2013-08-22 03:19:48,374 INFO org.apache.hadoop.yarn.server.resourcemanager.rmcontainer.RMContainerImpl: container_1377141553101_0001_01_000002 Container Transitioned from NEW to ALLOCATED
2013-08-22 03:19:48,374 INFO org.apache.hadoop.yarn.server.resourcemanager.RMAuditLogger: USER=ubuntu	OPERATION=AM Allocated Container	TARGET=SchedulerApp	RESULT=SUCCESS	APPID=application_1377141553101_0001	CONTAINERID=container_1377141553101_0001_01_000002
2013-08-22 03:19:48,374 INFO org.apache.hadoop.yarn.server.resourcemanager.scheduler.common.fica.FiCaSchedulerNode: Assigned container container_1377141553101_0001_01_000002 of capacity <memory:1024, vCores:1> on host hadoop-998-6:58634, which currently has 2 containers, <memory:3072, vCores:2> used and <memory:5120, vCores:14> available
2013-08-22 03:19:48,376 INFO org.apache.hadoop.yarn.server.resourcemanager.scheduler.capacity.LeafQueue: assignedContainer application=application_1377141553101_0001 container=Container: [ContainerId: container_1377141553101_0001_01_000002, NodeId: hadoop-998-6:58634, NodeHttpAddress: hadoop-998-6:8042, Resource: <memory:1024, vCores:1>, Priority: 20, State: NEW, Token: null, Status: container_id {, app_attempt_id {, application_id {, id: 1, cluster_timestamp: 1377141553101, }, attemptId: 1, }, id: 2, }, state: C_NEW, ] containerId=container_1377141553101_0001_01_000002 queue=default: capacity=1.0, absoluteCapacity=1.0, usedResources=<memory:2048, vCores:1>usedCapacity=0.041666668, absoluteUsedCapacity=0.041666668, numApps=1, numContainers=1 usedCapacity=0.041666668 absoluteUsedCapacity=0.041666668 used=<memory:2048, vCores:1> cluster=<memory:49152, vCores:96>
2013-08-22 03:19:48,376 INFO org.apache.hadoop.yarn.server.resourcemanager.scheduler.capacity.ParentQueue: Re-sorting queues since queue: root.default stats: default: capacity=1.0, absoluteCapacity=1.0, usedResources=<memory:3072, vCores:2>usedCapacity=0.0625, absoluteUsedCapacity=0.0625, numApps=1, numContainers=2
2013-08-22 03:19:48,376 INFO org.apache.hadoop.yarn.server.resourcemanager.scheduler.capacity.ParentQueue: assignedContainer queue=root usedCapacity=0.0625 absoluteUsedCapacity=0.0625 used=<memory:3072, vCores:2> cluster=<memory:49152, vCores:96>
2013-08-22 03:19:48,814 INFO org.apache.hadoop.yarn.server.resourcemanager.rmcontainer.RMContainerImpl: container_1377141553101_0001_01_000003 Container Transitioned from NEW to ALLOCATED
2013-08-22 03:19:48,815 INFO org.apache.hadoop.yarn.server.resourcemanager.RMAuditLogger: USER=ubuntu	OPERATION=AM Allocated Container	TARGET=SchedulerApp	RESULT=SUCCESS	APPID=application_1377141553101_0001	CONTAINERID=container_1377141553101_0001_01_000003
2013-08-22 03:19:48,815 INFO org.apache.hadoop.yarn.server.resourcemanager.scheduler.common.fica.FiCaSchedulerNode: Assigned container container_1377141553101_0001_01_000003 of capacity <memory:1024, vCores:1> on host hadoop-998-7:60905, which currently has 1 containers, <memory:1024, vCores:1> used and <memory:7168, vCores:15> available
2013-08-22 03:19:48,817 INFO org.apache.hadoop.yarn.server.resourcemanager.scheduler.capacity.LeafQueue: assignedContainer application=application_1377141553101_0001 container=Container: [ContainerId: container_1377141553101_0001_01_000003, NodeId: hadoop-998-7:60905, NodeHttpAddress: hadoop-998-7:8042, Resource: <memory:1024, vCores:1>, Priority: 20, State: NEW, Token: null, Status: container_id {, app_attempt_id {, application_id {, id: 1, cluster_timestamp: 1377141553101, }, attemptId: 1, }, id: 3, }, state: C_NEW, ] containerId=container_1377141553101_0001_01_000003 queue=default: capacity=1.0, absoluteCapacity=1.0, usedResources=<memory:3072, vCores:2>usedCapacity=0.0625, absoluteUsedCapacity=0.0625, numApps=1, numContainers=2 usedCapacity=0.0625 absoluteUsedCapacity=0.0625 used=<memory:3072, vCores:2> cluster=<memory:49152, vCores:96>
2013-08-22 03:19:48,817 INFO org.apache.hadoop.yarn.server.resourcemanager.scheduler.capacity.ParentQueue: Re-sorting queues since queue: root.default stats: default: capacity=1.0, absoluteCapacity=1.0, usedResources=<memory:4096, vCores:3>usedCapacity=0.083333336, absoluteUsedCapacity=0.083333336, numApps=1, numContainers=3
2013-08-22 03:19:48,817 INFO org.apache.hadoop.yarn.server.resourcemanager.scheduler.capacity.ParentQueue: assignedContainer queue=root usedCapacity=0.083333336 absoluteUsedCapacity=0.083333336 used=<memory:4096, vCores:3> cluster=<memory:49152, vCores:96>
2013-08-22 03:19:48,912 INFO org.apache.hadoop.yarn.server.resourcemanager.rmcontainer.RMContainerImpl: container_1377141553101_0001_01_000002 Container Transitioned from ALLOCATED to ACQUIRED
2013-08-22 03:19:48,914 INFO org.apache.hadoop.yarn.server.resourcemanager.rmcontainer.RMContainerImpl: container_1377141553101_0001_01_000003 Container Transitioned from ALLOCATED to ACQUIRED
2013-08-22 03:19:49,382 INFO org.apache.hadoop.yarn.server.resourcemanager.rmcontainer.RMContainerImpl: container_1377141553101_0001_01_000002 Container Transitioned from ACQUIRED to RUNNING
2013-08-22 03:19:49,938 INFO org.apache.hadoop.yarn.server.resourcemanager.scheduler.AppSchedulingInfo: checking for deactivate... 
2013-08-22 03:19:50,850 INFO org.apache.hadoop.yarn.server.resourcemanager.rmcontainer.RMContainerImpl: container_1377141553101_0001_01_000003 Container Transitioned from ACQUIRED to RUNNING
2013-08-22 03:22:38,619 INFO org.apache.hadoop.yarn.server.resourcemanager.rmcontainer.RMContainerImpl: container_1377141553101_0001_01_000003 Container Transitioned from RUNNING to COMPLETED
2013-08-22 03:22:38,619 INFO org.apache.hadoop.yarn.server.resourcemanager.scheduler.common.fica.FiCaSchedulerApp: Completed container: container_1377141553101_0001_01_000003 in state: COMPLETED event:FINISHED
2013-08-22 03:22:38,619 INFO org.apache.hadoop.yarn.server.resourcemanager.RMAuditLogger: USER=ubuntu	OPERATION=AM Released Container	TARGET=SchedulerApp	RESULT=SUCCESS	APPID=application_1377141553101_0001	CONTAINERID=container_1377141553101_0001_01_000003
2013-08-22 03:22:38,620 INFO org.apache.hadoop.yarn.server.resourcemanager.scheduler.common.fica.FiCaSchedulerNode: Released container container_1377141553101_0001_01_000003 of capacity <memory:1024, vCores:1> on host hadoop-998-7:60905, which currently has 0 containers, <memory:0, vCores:0> used and <memory:8192, vCores:16> available, release resources=true
2013-08-22 03:22:38,620 INFO org.apache.hadoop.yarn.server.resourcemanager.scheduler.capacity.LeafQueue: default used=<memory:3072, vCores:2> numContainers=2 user=ubuntu user-resources=<memory:3072, vCores:2>
2013-08-22 03:22:38,622 INFO org.apache.hadoop.yarn.server.resourcemanager.scheduler.capacity.LeafQueue: completedContainer container=Container: [ContainerId: container_1377141553101_0001_01_000003, NodeId: hadoop-998-7:60905, NodeHttpAddress: hadoop-998-7:8042, Resource: <memory:1024, vCores:1>, Priority: 20, State: NEW, Token: null, Status: container_id {, app_attempt_id {, application_id {, id: 1, cluster_timestamp: 1377141553101, }, attemptId: 1, }, id: 3, }, state: C_COMPLETE, diagnostics: "Container killed by the ApplicationMaster.\n\n", exit_status: 143, ] resource=<memory:1024, vCores:1> queue=default: capacity=1.0, absoluteCapacity=1.0, usedResources=<memory:3072, vCores:2>usedCapacity=0.0625, absoluteUsedCapacity=0.0625, numApps=1, numContainers=2 usedCapacity=0.0625 absoluteUsedCapacity=0.0625 used=<memory:3072, vCores:2> cluster=<memory:49152, vCores:96>
2013-08-22 03:22:38,623 INFO org.apache.hadoop.yarn.server.resourcemanager.scheduler.capacity.ParentQueue: completedContainer queue=root usedCapacity=0.0625 absoluteUsedCapacity=0.0625 used=<memory:3072, vCores:2> cluster=<memory:49152, vCores:96>
2013-08-22 03:22:38,623 INFO org.apache.hadoop.yarn.server.resourcemanager.scheduler.capacity.CapacityScheduler: Application appattempt_1377141553101_0001_000001 released container container_1377141553101_0001_01_000003 on node: host: hadoop-998-7:60905 #containers=0 available=8192 used=0 with event: FINISHED
2013-08-22 03:22:45,427 INFO org.apache.hadoop.yarn.server.resourcemanager.rmcontainer.RMContainerImpl: container_1377141553101_0001_01_000002 Container Transitioned from RUNNING to COMPLETED
2013-08-22 03:22:45,427 INFO org.apache.hadoop.yarn.server.resourcemanager.scheduler.common.fica.FiCaSchedulerApp: Completed container: container_1377141553101_0001_01_000002 in state: COMPLETED event:FINISHED
2013-08-22 03:22:45,427 INFO org.apache.hadoop.yarn.server.resourcemanager.RMAuditLogger: USER=ubuntu	OPERATION=AM Released Container	TARGET=SchedulerApp	RESULT=SUCCESS	APPID=application_1377141553101_0001	CONTAINERID=container_1377141553101_0001_01_000002
2013-08-22 03:22:45,428 INFO org.apache.hadoop.yarn.server.resourcemanager.scheduler.common.fica.FiCaSchedulerNode: Released container container_1377141553101_0001_01_000002 of capacity <memory:1024, vCores:1> on host hadoop-998-6:58634, which currently has 1 containers, <memory:2048, vCores:1> used and <memory:6144, vCores:15> available, release resources=true
2013-08-22 03:22:45,428 INFO org.apache.hadoop.yarn.server.resourcemanager.scheduler.capacity.LeafQueue: default used=<memory:2048, vCores:1> numContainers=1 user=ubuntu user-resources=<memory:2048, vCores:1>
2013-08-22 03:22:45,430 INFO org.apache.hadoop.yarn.server.resourcemanager.scheduler.capacity.LeafQueue: completedContainer container=Container: [ContainerId: container_1377141553101_0001_01_000002, NodeId: hadoop-998-6:58634, NodeHttpAddress: hadoop-998-6:8042, Resource: <memory:1024, vCores:1>, Priority: 20, State: NEW, Token: null, Status: container_id {, app_attempt_id {, application_id {, id: 1, cluster_timestamp: 1377141553101, }, attemptId: 1, }, id: 2, }, state: C_COMPLETE, diagnostics: "Container killed by the ApplicationMaster.\n\n", exit_status: 143, ] resource=<memory:1024, vCores:1> queue=default: capacity=1.0, absoluteCapacity=1.0, usedResources=<memory:2048, vCores:1>usedCapacity=0.041666668, absoluteUsedCapacity=0.041666668, numApps=1, numContainers=1 usedCapacity=0.041666668 absoluteUsedCapacity=0.041666668 used=<memory:2048, vCores:1> cluster=<memory:49152, vCores:96>
2013-08-22 03:22:45,430 INFO org.apache.hadoop.yarn.server.resourcemanager.scheduler.capacity.ParentQueue: completedContainer queue=root usedCapacity=0.041666668 absoluteUsedCapacity=0.041666668 used=<memory:2048, vCores:1> cluster=<memory:49152, vCores:96>
2013-08-22 03:22:45,430 INFO org.apache.hadoop.yarn.server.resourcemanager.scheduler.capacity.CapacityScheduler: Application appattempt_1377141553101_0001_000001 released container container_1377141553101_0001_01_000002 on node: host: hadoop-998-6:58634 #containers=1 available=6144 used=2048 with event: FINISHED
2013-08-22 03:22:49,573 INFO org.apache.hadoop.yarn.server.resourcemanager.rmapp.attempt.RMAppAttemptImpl: appattempt_1377141553101_0001_000001 State change from RUNNING to FINISHING
2013-08-22 03:22:49,573 INFO org.apache.hadoop.yarn.server.resourcemanager.rmapp.RMAppImpl: application_1377141553101_0001 State change from RUNNING to FINISHING
2013-08-22 03:22:50,454 INFO org.apache.hadoop.yarn.server.resourcemanager.rmcontainer.RMContainerImpl: container_1377141553101_0001_01_000001 Container Transitioned from RUNNING to COMPLETED
2013-08-22 03:22:50,454 INFO org.apache.hadoop.yarn.server.resourcemanager.scheduler.common.fica.FiCaSchedulerApp: Completed container: container_1377141553101_0001_01_000001 in state: COMPLETED event:FINISHED
2013-08-22 03:22:50,454 INFO org.apache.hadoop.yarn.server.resourcemanager.RMAuditLogger: USER=ubuntu	OPERATION=AM Released Container	TARGET=SchedulerApp	RESULT=SUCCESS	APPID=application_1377141553101_0001	CONTAINERID=container_1377141553101_0001_01_000001
2013-08-22 03:22:50,455 INFO org.apache.hadoop.yarn.server.resourcemanager.scheduler.common.fica.FiCaSchedulerNode: Released container container_1377141553101_0001_01_000001 of capacity <memory:2048, vCores:1> on host hadoop-998-6:58634, which currently has 0 containers, <memory:0, vCores:0> used and <memory:8192, vCores:16> available, release resources=true
2013-08-22 03:22:50,455 INFO org.apache.hadoop.yarn.server.resourcemanager.scheduler.capacity.LeafQueue: default used=<memory:0, vCores:0> numContainers=0 user=ubuntu user-resources=<memory:0, vCores:0>
2013-08-22 03:22:50,456 INFO org.apache.hadoop.yarn.server.resourcemanager.scheduler.capacity.LeafQueue: completedContainer container=Container: [ContainerId: container_1377141553101_0001_01_000001, NodeId: hadoop-998-6:58634, NodeHttpAddress: hadoop-998-6:8042, Resource: <memory:2048, vCores:1>, Priority: 0, State: NEW, Token: null, Status: container_id {, app_attempt_id {, application_id {, id: 1, cluster_timestamp: 1377141553101, }, attemptId: 1, }, id: 1, }, state: C_COMPLETE, diagnostics: "", exit_status: 0, ] resource=<memory:2048, vCores:1> queue=default: capacity=1.0, absoluteCapacity=1.0, usedResources=<memory:0, vCores:0>usedCapacity=0.0, absoluteUsedCapacity=0.0, numApps=1, numContainers=0 usedCapacity=0.0 absoluteUsedCapacity=0.0 used=<memory:0, vCores:0> cluster=<memory:49152, vCores:96>
2013-08-22 03:22:50,457 INFO org.apache.hadoop.yarn.server.resourcemanager.scheduler.capacity.ParentQueue: completedContainer queue=root usedCapacity=0.0 absoluteUsedCapacity=0.0 used=<memory:0, vCores:0> cluster=<memory:49152, vCores:96>
2013-08-22 03:22:50,457 INFO org.apache.hadoop.yarn.server.resourcemanager.scheduler.capacity.CapacityScheduler: Application appattempt_1377141553101_0001_000001 released container container_1377141553101_0001_01_000001 on node: host: hadoop-998-6:58634 #containers=0 available=8192 used=0 with event: FINISHED
2013-08-22 03:22:50,457 INFO org.apache.hadoop.yarn.server.resourcemanager.rmapp.attempt.RMAppAttemptImpl: appattempt_1377141553101_0001_000001 State change from FINISHING to FINISHED
2013-08-22 03:22:50,459 INFO org.apache.hadoop.yarn.server.resourcemanager.rmapp.RMAppImpl: application_1377141553101_0001 State change from FINISHING to FINISHED
2013-08-22 03:22:50,459 INFO org.apache.hadoop.yarn.server.resourcemanager.scheduler.capacity.CapacityScheduler: Application appattempt_1377141553101_0001_000001 is done. finalState=FINISHED
2013-08-22 03:22:50,460 INFO org.apache.hadoop.yarn.server.resourcemanager.RMAuditLogger: USER=ubuntu	OPERATION=Application Finished - Succeeded	TARGET=RMAppManager	RESULT=SUCCESS	APPID=application_1377141553101_0001
2013-08-22 03:22:50,460 INFO org.apache.hadoop.yarn.server.resourcemanager.amlauncher.AMLauncher: Cleaning master appattempt_1377141553101_0001_000001
2013-08-22 03:22:50,464 INFO org.apache.hadoop.yarn.server.resourcemanager.scheduler.AppSchedulingInfo: Application application_1377141553101_0001 requests cleared
2013-08-22 03:22:50,465 INFO org.apache.hadoop.yarn.server.resourcemanager.scheduler.capacity.LeafQueue: Application removed - appId: application_1377141553101_0001 user: ubuntu queue: default #user-pending-applications: 0 #user-active-applications: 0 #queue-pending-applications: 0 #queue-active-applications: 0
2013-08-22 03:22:50,465 INFO org.apache.hadoop.yarn.server.resourcemanager.scheduler.capacity.ParentQueue: Application removed - appId: application_1377141553101_0001 user: ubuntu leaf-queue of parent: root #applications: 0
2013-08-22 03:22:50,468 INFO org.apache.hadoop.yarn.server.resourcemanager.recovery.RMStateStore: Removing info for app: application_1377141553101_0001
2013-08-22 03:22:50,471 INFO org.apache.hadoop.yarn.server.resourcemanager.RMAppManager$ApplicationSummary: appId=application_1377141553101_0001,name=TeraGen,user=ubuntu,queue=default,state=FINISHED,trackingUrl=hadoop-998-1.novalocal:8088/proxy/application_1377141553101_0001/jobhistory/job/job_1377141553101_0001,appMasterHost=hadoop-998-6,startTime=1377141578125,finishTime=1377141769573
2013-08-22 03:22:50,929 INFO org.apache.hadoop.yarn.server.resourcemanager.ClientRMService: Allocated new applicationId: 2
2013-08-22 03:22:52,814 INFO org.apache.hadoop.yarn.server.resourcemanager.ClientRMService: Storing Application with id application_1377141553101_0002
2013-08-22 03:22:52,814 INFO org.apache.hadoop.yarn.server.resourcemanager.recovery.RMStateStore: Storing info for app: application_1377141553101_0002
2013-08-22 03:22:52,815 INFO org.apache.hadoop.yarn.server.resourcemanager.ClientRMService: Application with id 2 submitted by user ubuntu
2013-08-22 03:22:52,815 INFO org.apache.hadoop.yarn.server.resourcemanager.RMAuditLogger: USER=ubuntu	IP=192.168.100.9	OPERATION=Submit Application Request	TARGET=ClientRMService	RESULT=SUCCESS	APPID=application_1377141553101_0002
2013-08-22 03:22:52,817 INFO org.apache.hadoop.yarn.server.resourcemanager.rmapp.RMAppImpl: application_1377141553101_0002 State change from NEW to SUBMITTED
2013-08-22 03:22:52,817 INFO org.apache.hadoop.yarn.server.resourcemanager.ApplicationMasterService: Registering appattempt_1377141553101_0002_000001
2013-08-22 03:22:52,817 INFO org.apache.hadoop.yarn.server.resourcemanager.rmapp.attempt.RMAppAttemptImpl: appattempt_1377141553101_0002_000001 State change from NEW to SUBMITTED
2013-08-22 03:22:52,818 INFO org.apache.hadoop.yarn.server.resourcemanager.scheduler.capacity.LeafQueue: Application application_1377141553101_0002 from user: ubuntu activated in queue: default
2013-08-22 03:22:52,818 INFO org.apache.hadoop.yarn.server.resourcemanager.scheduler.capacity.LeafQueue: Application added - appId: application_1377141553101_0002 user: org.apache.hadoop.yarn.server.resourcemanager.scheduler.capacity.LeafQueue$User@2e784443, leaf-queue: default #user-pending-applications: 0 #user-active-applications: 1 #queue-pending-applications: 0 #queue-active-applications: 1
2013-08-22 03:22:52,818 INFO org.apache.hadoop.yarn.server.resourcemanager.scheduler.capacity.ParentQueue: Application added - appId: application_1377141553101_0002 user: ubuntu leaf-queue of parent: root #applications: 1
2013-08-22 03:22:52,819 INFO org.apache.hadoop.yarn.server.resourcemanager.scheduler.capacity.CapacityScheduler: Application Submission: appattempt_1377141553101_0002_000001, user: ubuntu queue: default: capacity=1.0, absoluteCapacity=1.0, usedResources=<memory:0, vCores:0>usedCapacity=0.0, absoluteUsedCapacity=0.0, numApps=1, numContainers=0, currently active: 1
2013-08-22 03:22:52,819 INFO org.apache.hadoop.yarn.server.resourcemanager.rmapp.attempt.RMAppAttemptImpl: appattempt_1377141553101_0002_000001 State change from SUBMITTED to SCHEDULED
2013-08-22 03:22:52,820 INFO org.apache.hadoop.yarn.server.resourcemanager.rmapp.RMAppImpl: application_1377141553101_0002 State change from SUBMITTED to ACCEPTED
2013-08-22 03:22:53,470 INFO org.apache.hadoop.yarn.server.resourcemanager.rmcontainer.RMContainerImpl: container_1377141553101_0002_01_000001 Container Transitioned from NEW to ALLOCATED
2013-08-22 03:22:53,471 INFO org.apache.hadoop.yarn.server.resourcemanager.RMAuditLogger: USER=ubuntu	OPERATION=AM Allocated Container	TARGET=SchedulerApp	RESULT=SUCCESS	APPID=application_1377141553101_0002	CONTAINERID=container_1377141553101_0002_01_000001
2013-08-22 03:22:53,471 INFO org.apache.hadoop.yarn.server.resourcemanager.scheduler.common.fica.FiCaSchedulerNode: Assigned container container_1377141553101_0002_01_000001 of capacity <memory:2048, vCores:1> on host hadoop-998-6:58634, which currently has 1 containers, <memory:2048, vCores:1> used and <memory:6144, vCores:15> available
2013-08-22 03:22:53,472 INFO org.apache.hadoop.yarn.server.resourcemanager.scheduler.capacity.LeafQueue: assignedContainer application=application_1377141553101_0002 container=Container: [ContainerId: container_1377141553101_0002_01_000001, NodeId: hadoop-998-6:58634, NodeHttpAddress: hadoop-998-6:8042, Resource: <memory:2048, vCores:1>, Priority: 0, State: NEW, Token: null, Status: container_id {, app_attempt_id {, application_id {, id: 2, cluster_timestamp: 1377141553101, }, attemptId: 1, }, id: 1, }, state: C_NEW, ] containerId=container_1377141553101_0002_01_000001 queue=default: capacity=1.0, absoluteCapacity=1.0, usedResources=<memory:0, vCores:0>usedCapacity=0.0, absoluteUsedCapacity=0.0, numApps=1, numContainers=0 usedCapacity=0.0 absoluteUsedCapacity=0.0 used=<memory:0, vCores:0> cluster=<memory:49152, vCores:96>
2013-08-22 03:22:53,473 INFO org.apache.hadoop.yarn.server.resourcemanager.scheduler.capacity.ParentQueue: Re-sorting queues since queue: root.default stats: default: capacity=1.0, absoluteCapacity=1.0, usedResources=<memory:2048, vCores:1>usedCapacity=0.041666668, absoluteUsedCapacity=0.041666668, numApps=1, numContainers=1
2013-08-22 03:22:53,474 INFO org.apache.hadoop.yarn.server.resourcemanager.scheduler.capacity.ParentQueue: assignedContainer queue=root usedCapacity=0.041666668 absoluteUsedCapacity=0.041666668 used=<memory:2048, vCores:1> cluster=<memory:49152, vCores:96>
2013-08-22 03:22:53,475 INFO org.apache.hadoop.yarn.server.resourcemanager.rmcontainer.RMContainerImpl: container_1377141553101_0002_01_000001 Container Transitioned from ALLOCATED to ACQUIRED
2013-08-22 03:22:53,477 INFO org.apache.hadoop.yarn.server.resourcemanager.rmapp.attempt.RMAppAttemptImpl: Storing attempt: AppId: application_1377141553101_0002 AttemptId: appattempt_1377141553101_0002_000001 MasterContainer: Container: [ContainerId: container_1377141553101_0002_01_000001, NodeId: hadoop-998-6:58634, NodeHttpAddress: hadoop-998-6:8042, Resource: <memory:2048, vCores:1>, Priority: 0, State: NEW, Token: null, Status: container_id {, app_attempt_id {, application_id {, id: 2, cluster_timestamp: 1377141553101, }, attemptId: 1, }, id: 1, }, state: C_NEW, ]
2013-08-22 03:22:53,477 INFO org.apache.hadoop.yarn.server.resourcemanager.rmapp.attempt.RMAppAttemptImpl: appattempt_1377141553101_0002_000001 State change from SCHEDULED to ALLOCATED_SAVING
2013-08-22 03:22:53,477 INFO org.apache.hadoop.yarn.server.resourcemanager.recovery.RMStateStore: Storing info for attempt: appattempt_1377141553101_0002_000001
2013-08-22 03:22:53,478 INFO org.apache.hadoop.yarn.server.resourcemanager.rmapp.attempt.RMAppAttemptImpl: appattempt_1377141553101_0002_000001 State change from ALLOCATED_SAVING to ALLOCATED
2013-08-22 03:22:53,480 INFO org.apache.hadoop.yarn.server.resourcemanager.amlauncher.AMLauncher: Launching masterappattempt_1377141553101_0002_000001
2013-08-22 03:22:53,483 INFO org.apache.hadoop.yarn.server.resourcemanager.amlauncher.AMLauncher: Setting up container Container: [ContainerId: container_1377141553101_0002_01_000001, NodeId: hadoop-998-6:58634, NodeHttpAddress: hadoop-998-6:8042, Resource: <memory:2048, vCores:1>, Priority: 0, State: NEW, Token: null, Status: container_id {, app_attempt_id {, application_id {, id: 2, cluster_timestamp: 1377141553101, }, attemptId: 1, }, id: 1, }, state: C_NEW, ] for AM appattempt_1377141553101_0002_000001
2013-08-22 03:22:53,483 INFO org.apache.hadoop.yarn.server.resourcemanager.amlauncher.AMLauncher: Command to launch container container_1377141553101_0002_01_000001 : $JAVA_HOME/bin/java -Dlog4j.configuration=container-log4j.properties -Dyarn.app.mapreduce.container.log.dir=<LOG_DIR> -Dyarn.app.mapreduce.container.log.filesize=0 -Dhadoop.root.logger=INFO,CLA  -Xmx1024m org.apache.hadoop.mapreduce.v2.app.MRAppMaster 1><LOG_DIR>/stdout 2><LOG_DIR>/stderr 
2013-08-22 03:22:53,503 INFO org.apache.hadoop.yarn.server.resourcemanager.amlauncher.AMLauncher: Done launching container Container: [ContainerId: container_1377141553101_0002_01_000001, NodeId: hadoop-998-6:58634, NodeHttpAddress: hadoop-998-6:8042, Resource: <memory:2048, vCores:1>, Priority: 0, State: NEW, Token: null, Status: container_id {, app_attempt_id {, application_id {, id: 2, cluster_timestamp: 1377141553101, }, attemptId: 1, }, id: 1, }, state: C_NEW, ] for AM appattempt_1377141553101_0002_000001
2013-08-22 03:22:53,503 INFO org.apache.hadoop.yarn.server.resourcemanager.rmapp.attempt.RMAppAttemptImpl: appattempt_1377141553101_0002_000001 State change from ALLOCATED to LAUNCHED
2013-08-22 03:22:54,478 INFO org.apache.hadoop.yarn.server.resourcemanager.rmcontainer.RMContainerImpl: container_1377141553101_0002_01_000001 Container Transitioned from ACQUIRED to RUNNING
2013-08-22 03:22:58,802 INFO org.apache.hadoop.yarn.server.resourcemanager.ApplicationMasterService: AM registration appattempt_1377141553101_0002_000001
2013-08-22 03:22:58,803 INFO org.apache.hadoop.yarn.server.resourcemanager.RMAuditLogger: USER=ubuntu	IP=192.168.100.10	OPERATION=Register App Master	TARGET=ApplicationMasterService	RESULT=SUCCESS	APPID=application_1377141553101_0002	APPATTEMPTID=appattempt_1377141553101_0002_000001
2013-08-22 03:22:58,805 INFO org.apache.hadoop.yarn.server.resourcemanager.rmapp.attempt.RMAppAttemptImpl: appattempt_1377141553101_0002_000001 State change from LAUNCHED to RUNNING
2013-08-22 03:22:58,805 INFO org.apache.hadoop.yarn.server.resourcemanager.rmapp.RMAppImpl: application_1377141553101_0002 State change from ACCEPTED to RUNNING
2013-08-22 03:23:00,511 INFO org.apache.hadoop.yarn.server.resourcemanager.rmcontainer.RMContainerImpl: container_1377141553101_0002_01_000002 Container Transitioned from NEW to ALLOCATED
2013-08-22 03:23:00,511 INFO org.apache.hadoop.yarn.server.resourcemanager.RMAuditLogger: USER=ubuntu	OPERATION=AM Allocated Container	TARGET=SchedulerApp	RESULT=SUCCESS	APPID=application_1377141553101_0002	CONTAINERID=container_1377141553101_0002_01_000002
2013-08-22 03:23:00,513 INFO org.apache.hadoop.yarn.server.resourcemanager.scheduler.common.fica.FiCaSchedulerNode: Assigned container container_1377141553101_0002_01_000002 of capacity <memory:1024, vCores:1> on host hadoop-998-6:58634, which currently has 2 containers, <memory:3072, vCores:2> used and <memory:5120, vCores:14> available
2013-08-22 03:23:00,515 INFO org.apache.hadoop.yarn.server.resourcemanager.scheduler.capacity.LeafQueue: assignedContainer application=application_1377141553101_0002 container=Container: [ContainerId: container_1377141553101_0002_01_000002, NodeId: hadoop-998-6:58634, NodeHttpAddress: hadoop-998-6:8042, Resource: <memory:1024, vCores:1>, Priority: 20, State: NEW, Token: null, Status: container_id {, app_attempt_id {, application_id {, id: 2, cluster_timestamp: 1377141553101, }, attemptId: 1, }, id: 2, }, state: C_NEW, ] containerId=container_1377141553101_0002_01_000002 queue=default: capacity=1.0, absoluteCapacity=1.0, usedResources=<memory:2048, vCores:1>usedCapacity=0.041666668, absoluteUsedCapacity=0.041666668, numApps=1, numContainers=1 usedCapacity=0.041666668 absoluteUsedCapacity=0.041666668 used=<memory:2048, vCores:1> cluster=<memory:49152, vCores:96>
2013-08-22 03:23:00,515 INFO org.apache.hadoop.yarn.server.resourcemanager.scheduler.capacity.ParentQueue: Re-sorting queues since queue: root.default stats: default: capacity=1.0, absoluteCapacity=1.0, usedResources=<memory:3072, vCores:2>usedCapacity=0.0625, absoluteUsedCapacity=0.0625, numApps=1, numContainers=2
2013-08-22 03:23:00,515 INFO org.apache.hadoop.yarn.server.resourcemanager.scheduler.capacity.ParentQueue: assignedContainer queue=root usedCapacity=0.0625 absoluteUsedCapacity=0.0625 used=<memory:3072, vCores:2> cluster=<memory:49152, vCores:96>
2013-08-22 03:23:00,560 INFO org.apache.hadoop.yarn.server.resourcemanager.rmcontainer.RMContainerImpl: container_1377141553101_0002_01_000003 Container Transitioned from NEW to ALLOCATED
2013-08-22 03:23:00,560 INFO org.apache.hadoop.yarn.server.resourcemanager.RMAuditLogger: USER=ubuntu	OPERATION=AM Allocated Container	TARGET=SchedulerApp	RESULT=SUCCESS	APPID=application_1377141553101_0002	CONTAINERID=container_1377141553101_0002_01_000003
2013-08-22 03:23:00,560 INFO org.apache.hadoop.yarn.server.resourcemanager.scheduler.common.fica.FiCaSchedulerNode: Assigned container container_1377141553101_0002_01_000003 of capacity <memory:1024, vCores:1> on host hadoop-998-2:35081, which currently has 1 containers, <memory:1024, vCores:1> used and <memory:7168, vCores:15> available
2013-08-22 03:23:00,562 INFO org.apache.hadoop.yarn.server.resourcemanager.scheduler.capacity.LeafQueue: assignedContainer application=application_1377141553101_0002 container=Container: [ContainerId: container_1377141553101_0002_01_000003, NodeId: hadoop-998-2:35081, NodeHttpAddress: hadoop-998-2:8042, Resource: <memory:1024, vCores:1>, Priority: 20, State: NEW, Token: null, Status: container_id {, app_attempt_id {, application_id {, id: 2, cluster_timestamp: 1377141553101, }, attemptId: 1, }, id: 3, }, state: C_NEW, ] containerId=container_1377141553101_0002_01_000003 queue=default: capacity=1.0, absoluteCapacity=1.0, usedResources=<memory:3072, vCores:2>usedCapacity=0.0625, absoluteUsedCapacity=0.0625, numApps=1, numContainers=2 usedCapacity=0.0625 absoluteUsedCapacity=0.0625 used=<memory:3072, vCores:2> cluster=<memory:49152, vCores:96>
2013-08-22 03:23:00,562 INFO org.apache.hadoop.yarn.server.resourcemanager.scheduler.capacity.ParentQueue: Re-sorting queues since queue: root.default stats: default: capacity=1.0, absoluteCapacity=1.0, usedResources=<memory:4096, vCores:3>usedCapacity=0.083333336, absoluteUsedCapacity=0.083333336, numApps=1, numContainers=3
2013-08-22 03:23:00,562 INFO org.apache.hadoop.yarn.server.resourcemanager.scheduler.capacity.ParentQueue: assignedContainer queue=root usedCapacity=0.083333336 absoluteUsedCapacity=0.083333336 used=<memory:4096, vCores:3> cluster=<memory:49152, vCores:96>
2013-08-22 03:23:00,851 INFO org.apache.hadoop.yarn.server.resourcemanager.rmcontainer.RMContainerImpl: container_1377141553101_0002_01_000002 Container Transitioned from ALLOCATED to ACQUIRED
2013-08-22 03:23:00,853 INFO org.apache.hadoop.yarn.server.resourcemanager.rmcontainer.RMContainerImpl: container_1377141553101_0002_01_000003 Container Transitioned from ALLOCATED to ACQUIRED
2013-08-22 03:23:01,518 INFO org.apache.hadoop.yarn.server.resourcemanager.rmcontainer.RMContainerImpl: container_1377141553101_0002_01_000002 Container Transitioned from ACQUIRED to RUNNING
2013-08-22 03:23:01,879 INFO org.apache.hadoop.yarn.server.resourcemanager.scheduler.AppSchedulingInfo: checking for deactivate... 
2013-08-22 03:23:02,587 INFO org.apache.hadoop.yarn.server.resourcemanager.rmcontainer.RMContainerImpl: container_1377141553101_0002_01_000003 Container Transitioned from ACQUIRED to RUNNING
2013-08-22 03:25:36,034 INFO org.apache.hadoop.yarn.server.resourcemanager.rmcontainer.RMContainerImpl: container_1377141553101_0002_01_000002 Container Transitioned from RUNNING to COMPLETED
2013-08-22 03:25:36,034 INFO org.apache.hadoop.yarn.server.resourcemanager.scheduler.common.fica.FiCaSchedulerApp: Completed container: container_1377141553101_0002_01_000002 in state: COMPLETED event:FINISHED
2013-08-22 03:25:36,034 INFO org.apache.hadoop.yarn.server.resourcemanager.RMAuditLogger: USER=ubuntu	OPERATION=AM Released Container	TARGET=SchedulerApp	RESULT=SUCCESS	APPID=application_1377141553101_0002	CONTAINERID=container_1377141553101_0002_01_000002
2013-08-22 03:25:36,035 INFO org.apache.hadoop.yarn.server.resourcemanager.scheduler.common.fica.FiCaSchedulerNode: Released container container_1377141553101_0002_01_000002 of capacity <memory:1024, vCores:1> on host hadoop-998-6:58634, which currently has 1 containers, <memory:2048, vCores:1> used and <memory:6144, vCores:15> available, release resources=true
2013-08-22 03:25:36,035 INFO org.apache.hadoop.yarn.server.resourcemanager.scheduler.capacity.LeafQueue: default used=<memory:3072, vCores:2> numContainers=2 user=ubuntu user-resources=<memory:3072, vCores:2>
2013-08-22 03:25:36,048 INFO org.apache.hadoop.yarn.server.resourcemanager.scheduler.capacity.LeafQueue: completedContainer container=Container: [ContainerId: container_1377141553101_0002_01_000002, NodeId: hadoop-998-6:58634, NodeHttpAddress: hadoop-998-6:8042, Resource: <memory:1024, vCores:1>, Priority: 20, State: NEW, Token: null, Status: container_id {, app_attempt_id {, application_id {, id: 2, cluster_timestamp: 1377141553101, }, attemptId: 1, }, id: 2, }, state: C_COMPLETE, diagnostics: "Container killed by the ApplicationMaster.\n\n", exit_status: 143, ] resource=<memory:1024, vCores:1> queue=default: capacity=1.0, absoluteCapacity=1.0, usedResources=<memory:3072, vCores:2>usedCapacity=0.0625, absoluteUsedCapacity=0.0625, numApps=1, numContainers=2 usedCapacity=0.0625 absoluteUsedCapacity=0.0625 used=<memory:3072, vCores:2> cluster=<memory:49152, vCores:96>
2013-08-22 03:25:36,048 INFO org.apache.hadoop.yarn.server.resourcemanager.scheduler.capacity.ParentQueue: completedContainer queue=root usedCapacity=0.0625 absoluteUsedCapacity=0.0625 used=<memory:3072, vCores:2> cluster=<memory:49152, vCores:96>
2013-08-22 03:25:36,048 INFO org.apache.hadoop.yarn.server.resourcemanager.scheduler.capacity.CapacityScheduler: Application appattempt_1377141553101_0002_000001 released container container_1377141553101_0002_01_000002 on node: host: hadoop-998-6:58634 #containers=1 available=6144 used=2048 with event: FINISHED
2013-08-22 03:25:52,044 INFO org.apache.hadoop.yarn.server.resourcemanager.rmcontainer.RMContainerImpl: container_1377141553101_0002_01_000003 Container Transitioned from RUNNING to COMPLETED
2013-08-22 03:25:52,045 INFO org.apache.hadoop.yarn.server.resourcemanager.scheduler.common.fica.FiCaSchedulerApp: Completed container: container_1377141553101_0002_01_000003 in state: COMPLETED event:FINISHED
2013-08-22 03:25:52,045 INFO org.apache.hadoop.yarn.server.resourcemanager.RMAuditLogger: USER=ubuntu	OPERATION=AM Released Container	TARGET=SchedulerApp	RESULT=SUCCESS	APPID=application_1377141553101_0002	CONTAINERID=container_1377141553101_0002_01_000003
2013-08-22 03:25:52,045 INFO org.apache.hadoop.yarn.server.resourcemanager.scheduler.common.fica.FiCaSchedulerNode: Released container container_1377141553101_0002_01_000003 of capacity <memory:1024, vCores:1> on host hadoop-998-2:35081, which currently has 0 containers, <memory:0, vCores:0> used and <memory:8192, vCores:16> available, release resources=true
2013-08-22 03:25:52,045 INFO org.apache.hadoop.yarn.server.resourcemanager.scheduler.capacity.LeafQueue: default used=<memory:2048, vCores:1> numContainers=1 user=ubuntu user-resources=<memory:2048, vCores:1>
2013-08-22 03:25:52,047 INFO org.apache.hadoop.yarn.server.resourcemanager.scheduler.capacity.LeafQueue: completedContainer container=Container: [ContainerId: container_1377141553101_0002_01_000003, NodeId: hadoop-998-2:35081, NodeHttpAddress: hadoop-998-2:8042, Resource: <memory:1024, vCores:1>, Priority: 20, State: NEW, Token: null, Status: container_id {, app_attempt_id {, application_id {, id: 2, cluster_timestamp: 1377141553101, }, attemptId: 1, }, id: 3, }, state: C_COMPLETE, diagnostics: "Container killed by the ApplicationMaster.\n\n", exit_status: 143, ] resource=<memory:1024, vCores:1> queue=default: capacity=1.0, absoluteCapacity=1.0, usedResources=<memory:2048, vCores:1>usedCapacity=0.041666668, absoluteUsedCapacity=0.041666668, numApps=1, numContainers=1 usedCapacity=0.041666668 absoluteUsedCapacity=0.041666668 used=<memory:2048, vCores:1> cluster=<memory:49152, vCores:96>
2013-08-22 03:25:52,048 INFO org.apache.hadoop.yarn.server.resourcemanager.scheduler.capacity.ParentQueue: completedContainer queue=root usedCapacity=0.041666668 absoluteUsedCapacity=0.041666668 used=<memory:2048, vCores:1> cluster=<memory:49152, vCores:96>
2013-08-22 03:25:52,048 INFO org.apache.hadoop.yarn.server.resourcemanager.scheduler.capacity.CapacityScheduler: Application appattempt_1377141553101_0002_000001 released container container_1377141553101_0002_01_000003 on node: host: hadoop-998-2:35081 #containers=0 available=8192 used=0 with event: FINISHED
2013-08-22 03:25:56,228 INFO org.apache.hadoop.yarn.server.resourcemanager.rmapp.attempt.RMAppAttemptImpl: appattempt_1377141553101_0002_000001 State change from RUNNING to FINISHING
2013-08-22 03:25:56,228 INFO org.apache.hadoop.yarn.server.resourcemanager.rmapp.RMAppImpl: application_1377141553101_0002 State change from RUNNING to FINISHING
2013-08-22 03:25:57,163 INFO org.apache.hadoop.yarn.server.resourcemanager.rmcontainer.RMContainerImpl: container_1377141553101_0002_01_000001 Container Transitioned from RUNNING to COMPLETED
2013-08-22 03:25:57,164 INFO org.apache.hadoop.yarn.server.resourcemanager.scheduler.common.fica.FiCaSchedulerApp: Completed container: container_1377141553101_0002_01_000001 in state: COMPLETED event:FINISHED
2013-08-22 03:25:57,164 INFO org.apache.hadoop.yarn.server.resourcemanager.rmapp.attempt.RMAppAttemptImpl: appattempt_1377141553101_0002_000001 State change from FINISHING to FINISHED
2013-08-22 03:25:57,164 INFO org.apache.hadoop.yarn.server.resourcemanager.RMAuditLogger: USER=ubuntu	OPERATION=AM Released Container	TARGET=SchedulerApp	RESULT=SUCCESS	APPID=application_1377141553101_0002	CONTAINERID=container_1377141553101_0002_01_000001
2013-08-22 03:25:57,164 INFO org.apache.hadoop.yarn.server.resourcemanager.rmapp.RMAppImpl: application_1377141553101_0002 State change from FINISHING to FINISHED
2013-08-22 03:25:57,164 INFO org.apache.hadoop.yarn.server.resourcemanager.scheduler.common.fica.FiCaSchedulerNode: Released container container_1377141553101_0002_01_000001 of capacity <memory:2048, vCores:1> on host hadoop-998-6:58634, which currently has 0 containers, <memory:0, vCores:0> used and <memory:8192, vCores:16> available, release resources=true
2013-08-22 03:25:57,165 INFO org.apache.hadoop.yarn.server.resourcemanager.scheduler.capacity.LeafQueue: default used=<memory:0, vCores:0> numContainers=0 user=ubuntu user-resources=<memory:0, vCores:0>
2013-08-22 03:25:57,165 INFO org.apache.hadoop.yarn.server.resourcemanager.RMAuditLogger: USER=ubuntu	OPERATION=Application Finished - Succeeded	TARGET=RMAppManager	RESULT=SUCCESS	APPID=application_1377141553101_0002
2013-08-22 03:25:57,165 INFO org.apache.hadoop.yarn.server.resourcemanager.recovery.RMStateStore: Removing info for app: application_1377141553101_0002
2013-08-22 03:25:57,166 INFO org.apache.hadoop.yarn.server.resourcemanager.RMAppManager$ApplicationSummary: appId=application_1377141553101_0002,name=TeraGen,user=ubuntu,queue=default,state=FINISHED,trackingUrl=hadoop-998-1.novalocal:8088/proxy/application_1377141553101_0002/jobhistory/job/job_1377141553101_0002,appMasterHost=hadoop-998-6,startTime=1377141772813,finishTime=1377141956228
2013-08-22 03:25:57,166 INFO org.apache.hadoop.yarn.server.resourcemanager.scheduler.capacity.LeafQueue: completedContainer container=Container: [ContainerId: container_1377141553101_0002_01_000001, NodeId: hadoop-998-6:58634, NodeHttpAddress: hadoop-998-6:8042, Resource: <memory:2048, vCores:1>, Priority: 0, State: NEW, Token: null, Status: container_id {, app_attempt_id {, application_id {, id: 2, cluster_timestamp: 1377141553101, }, attemptId: 1, }, id: 1, }, state: C_COMPLETE, diagnostics: "", exit_status: 0, ] resource=<memory:2048, vCores:1> queue=default: capacity=1.0, absoluteCapacity=1.0, usedResources=<memory:0, vCores:0>usedCapacity=0.0, absoluteUsedCapacity=0.0, numApps=1, numContainers=0 usedCapacity=0.0 absoluteUsedCapacity=0.0 used=<memory:0, vCores:0> cluster=<memory:49152, vCores:96>
2013-08-22 03:25:57,167 INFO org.apache.hadoop.yarn.server.resourcemanager.scheduler.capacity.ParentQueue: completedContainer queue=root usedCapacity=0.0 absoluteUsedCapacity=0.0 used=<memory:0, vCores:0> cluster=<memory:49152, vCores:96>
2013-08-22 03:25:57,167 INFO org.apache.hadoop.yarn.server.resourcemanager.scheduler.capacity.CapacityScheduler: Application appattempt_1377141553101_0002_000001 released container container_1377141553101_0002_01_000001 on node: host: hadoop-998-6:58634 #containers=0 available=8192 used=0 with event: FINISHED
2013-08-22 03:25:57,167 INFO org.apache.hadoop.yarn.server.resourcemanager.scheduler.capacity.CapacityScheduler: Application appattempt_1377141553101_0002_000001 is done. finalState=FINISHED
2013-08-22 03:25:57,167 INFO org.apache.hadoop.yarn.server.resourcemanager.scheduler.AppSchedulingInfo: Application application_1377141553101_0002 requests cleared
2013-08-22 03:25:57,167 INFO org.apache.hadoop.yarn.server.resourcemanager.scheduler.capacity.LeafQueue: Application removed - appId: application_1377141553101_0002 user: ubuntu queue: default #user-pending-applications: 0 #user-active-applications: 0 #queue-pending-applications: 0 #queue-active-applications: 0
2013-08-22 03:25:57,167 INFO org.apache.hadoop.yarn.server.resourcemanager.scheduler.capacity.ParentQueue: Application removed - appId: application_1377141553101_0002 user: ubuntu leaf-queue of parent: root #applications: 0
2013-08-22 03:25:57,173 INFO org.apache.hadoop.yarn.server.resourcemanager.amlauncher.AMLauncher: Cleaning master appattempt_1377141553101_0002_000001
2013-08-22 03:25:57,517 INFO org.apache.hadoop.yarn.server.resourcemanager.ClientRMService: Allocated new applicationId: 3
2013-08-22 03:25:59,537 INFO org.apache.hadoop.yarn.server.resourcemanager.ClientRMService: Storing Application with id application_1377141553101_0003
2013-08-22 03:25:59,538 INFO org.apache.hadoop.yarn.server.resourcemanager.recovery.RMStateStore: Storing info for app: application_1377141553101_0003
2013-08-22 03:25:59,538 INFO org.apache.hadoop.yarn.server.resourcemanager.ClientRMService: Application with id 3 submitted by user ubuntu
2013-08-22 03:25:59,538 INFO org.apache.hadoop.yarn.server.resourcemanager.RMAuditLogger: USER=ubuntu	IP=192.168.100.9	OPERATION=Submit Application Request	TARGET=ClientRMService	RESULT=SUCCESS	APPID=application_1377141553101_0003
2013-08-22 03:25:59,539 INFO org.apache.hadoop.yarn.server.resourcemanager.rmapp.RMAppImpl: application_1377141553101_0003 State change from NEW to SUBMITTED
2013-08-22 03:25:59,539 INFO org.apache.hadoop.yarn.server.resourcemanager.ApplicationMasterService: Registering appattempt_1377141553101_0003_000001
2013-08-22 03:25:59,539 INFO org.apache.hadoop.yarn.server.resourcemanager.rmapp.attempt.RMAppAttemptImpl: appattempt_1377141553101_0003_000001 State change from NEW to SUBMITTED
2013-08-22 03:25:59,540 INFO org.apache.hadoop.yarn.server.resourcemanager.scheduler.capacity.LeafQueue: Application application_1377141553101_0003 from user: ubuntu activated in queue: default
2013-08-22 03:25:59,540 INFO org.apache.hadoop.yarn.server.resourcemanager.scheduler.capacity.LeafQueue: Application added - appId: application_1377141553101_0003 user: org.apache.hadoop.yarn.server.resourcemanager.scheduler.capacity.LeafQueue$User@8667df7, leaf-queue: default #user-pending-applications: 0 #user-active-applications: 1 #queue-pending-applications: 0 #queue-active-applications: 1
2013-08-22 03:25:59,540 INFO org.apache.hadoop.yarn.server.resourcemanager.scheduler.capacity.ParentQueue: Application added - appId: application_1377141553101_0003 user: ubuntu leaf-queue of parent: root #applications: 1
2013-08-22 03:25:59,540 INFO org.apache.hadoop.yarn.server.resourcemanager.scheduler.capacity.CapacityScheduler: Application Submission: appattempt_1377141553101_0003_000001, user: ubuntu queue: default: capacity=1.0, absoluteCapacity=1.0, usedResources=<memory:0, vCores:0>usedCapacity=0.0, absoluteUsedCapacity=0.0, numApps=1, numContainers=0, currently active: 1
2013-08-22 03:25:59,541 INFO org.apache.hadoop.yarn.server.resourcemanager.rmapp.attempt.RMAppAttemptImpl: appattempt_1377141553101_0003_000001 State change from SUBMITTED to SCHEDULED
2013-08-22 03:25:59,542 INFO org.apache.hadoop.yarn.server.resourcemanager.rmcontainer.RMContainerImpl: container_1377141553101_0003_01_000001 Container Transitioned from NEW to ALLOCATED
2013-08-22 03:25:59,543 INFO org.apache.hadoop.yarn.server.resourcemanager.RMAuditLogger: USER=ubuntu	OPERATION=AM Allocated Container	TARGET=SchedulerApp	RESULT=SUCCESS	APPID=application_1377141553101_0003	CONTAINERID=container_1377141553101_0003_01_000001
2013-08-22 03:25:59,543 INFO org.apache.hadoop.yarn.server.resourcemanager.scheduler.common.fica.FiCaSchedulerNode: Assigned container container_1377141553101_0003_01_000001 of capacity <memory:2048, vCores:1> on host hadoop-998-7:60905, which currently has 1 containers, <memory:2048, vCores:1> used and <memory:6144, vCores:15> available
2013-08-22 03:25:59,544 INFO org.apache.hadoop.yarn.server.resourcemanager.scheduler.capacity.LeafQueue: assignedContainer application=application_1377141553101_0003 container=Container: [ContainerId: container_1377141553101_0003_01_000001, NodeId: hadoop-998-7:60905, NodeHttpAddress: hadoop-998-7:8042, Resource: <memory:2048, vCores:1>, Priority: 0, State: NEW, Token: null, Status: container_id {, app_attempt_id {, application_id {, id: 3, cluster_timestamp: 1377141553101, }, attemptId: 1, }, id: 1, }, state: C_NEW, ] containerId=container_1377141553101_0003_01_000001 queue=default: capacity=1.0, absoluteCapacity=1.0, usedResources=<memory:0, vCores:0>usedCapacity=0.0, absoluteUsedCapacity=0.0, numApps=1, numContainers=0 usedCapacity=0.0 absoluteUsedCapacity=0.0 used=<memory:0, vCores:0> cluster=<memory:49152, vCores:96>
2013-08-22 03:25:59,545 INFO org.apache.hadoop.yarn.server.resourcemanager.scheduler.capacity.ParentQueue: Re-sorting queues since queue: root.default stats: default: capacity=1.0, absoluteCapacity=1.0, usedResources=<memory:2048, vCores:1>usedCapacity=0.041666668, absoluteUsedCapacity=0.041666668, numApps=1, numContainers=1
2013-08-22 03:25:59,545 INFO org.apache.hadoop.yarn.server.resourcemanager.scheduler.capacity.ParentQueue: assignedContainer queue=root usedCapacity=0.041666668 absoluteUsedCapacity=0.041666668 used=<memory:2048, vCores:1> cluster=<memory:49152, vCores:96>
2013-08-22 03:25:59,545 INFO org.apache.hadoop.yarn.server.resourcemanager.rmapp.RMAppImpl: application_1377141553101_0003 State change from SUBMITTED to ACCEPTED
2013-08-22 03:25:59,546 INFO org.apache.hadoop.yarn.server.resourcemanager.rmcontainer.RMContainerImpl: container_1377141553101_0003_01_000001 Container Transitioned from ALLOCATED to ACQUIRED
2013-08-22 03:25:59,548 INFO org.apache.hadoop.yarn.server.resourcemanager.rmapp.attempt.RMAppAttemptImpl: Storing attempt: AppId: application_1377141553101_0003 AttemptId: appattempt_1377141553101_0003_000001 MasterContainer: Container: [ContainerId: container_1377141553101_0003_01_000001, NodeId: hadoop-998-7:60905, NodeHttpAddress: hadoop-998-7:8042, Resource: <memory:2048, vCores:1>, Priority: 0, State: NEW, Token: null, Status: container_id {, app_attempt_id {, application_id {, id: 3, cluster_timestamp: 1377141553101, }, attemptId: 1, }, id: 1, }, state: C_NEW, ]
2013-08-22 03:25:59,548 INFO org.apache.hadoop.yarn.server.resourcemanager.rmapp.attempt.RMAppAttemptImpl: appattempt_1377141553101_0003_000001 State change from SCHEDULED to ALLOCATED_SAVING
2013-08-22 03:25:59,548 INFO org.apache.hadoop.yarn.server.resourcemanager.recovery.RMStateStore: Storing info for attempt: appattempt_1377141553101_0003_000001
2013-08-22 03:25:59,549 INFO org.apache.hadoop.yarn.server.resourcemanager.rmapp.attempt.RMAppAttemptImpl: appattempt_1377141553101_0003_000001 State change from ALLOCATED_SAVING to ALLOCATED
2013-08-22 03:25:59,550 INFO org.apache.hadoop.yarn.server.resourcemanager.amlauncher.AMLauncher: Launching masterappattempt_1377141553101_0003_000001
2013-08-22 03:25:59,553 INFO org.apache.hadoop.yarn.server.resourcemanager.amlauncher.AMLauncher: Setting up container Container: [ContainerId: container_1377141553101_0003_01_000001, NodeId: hadoop-998-7:60905, NodeHttpAddress: hadoop-998-7:8042, Resource: <memory:2048, vCores:1>, Priority: 0, State: NEW, Token: null, Status: container_id {, app_attempt_id {, application_id {, id: 3, cluster_timestamp: 1377141553101, }, attemptId: 1, }, id: 1, }, state: C_NEW, ] for AM appattempt_1377141553101_0003_000001
2013-08-22 03:25:59,554 INFO org.apache.hadoop.yarn.server.resourcemanager.amlauncher.AMLauncher: Command to launch container container_1377141553101_0003_01_000001 : $JAVA_HOME/bin/java -Dlog4j.configuration=container-log4j.properties -Dyarn.app.mapreduce.container.log.dir=<LOG_DIR> -Dyarn.app.mapreduce.container.log.filesize=0 -Dhadoop.root.logger=INFO,CLA  -Xmx1024m org.apache.hadoop.mapreduce.v2.app.MRAppMaster 1><LOG_DIR>/stdout 2><LOG_DIR>/stderr 
2013-08-22 03:25:59,572 INFO org.apache.hadoop.yarn.server.resourcemanager.amlauncher.AMLauncher: Done launching container Container: [ContainerId: container_1377141553101_0003_01_000001, NodeId: hadoop-998-7:60905, NodeHttpAddress: hadoop-998-7:8042, Resource: <memory:2048, vCores:1>, Priority: 0, State: NEW, Token: null, Status: container_id {, app_attempt_id {, application_id {, id: 3, cluster_timestamp: 1377141553101, }, attemptId: 1, }, id: 1, }, state: C_NEW, ] for AM appattempt_1377141553101_0003_000001
2013-08-22 03:25:59,572 INFO org.apache.hadoop.yarn.server.resourcemanager.rmapp.attempt.RMAppAttemptImpl: appattempt_1377141553101_0003_000001 State change from ALLOCATED to LAUNCHED
2013-08-22 03:26:00,550 INFO org.apache.hadoop.yarn.server.resourcemanager.rmcontainer.RMContainerImpl: container_1377141553101_0003_01_000001 Container Transitioned from ACQUIRED to RUNNING
2013-08-22 03:26:07,024 INFO org.apache.hadoop.yarn.server.resourcemanager.ApplicationMasterService: AM registration appattempt_1377141553101_0003_000001
2013-08-22 03:26:07,024 INFO org.apache.hadoop.yarn.server.resourcemanager.RMAuditLogger: USER=ubuntu	IP=192.168.100.13	OPERATION=Register App Master	TARGET=ApplicationMasterService	RESULT=SUCCESS	APPID=application_1377141553101_0003	APPATTEMPTID=appattempt_1377141553101_0003_000001
2013-08-22 03:26:07,025 INFO org.apache.hadoop.yarn.server.resourcemanager.rmapp.attempt.RMAppAttemptImpl: appattempt_1377141553101_0003_000001 State change from LAUNCHED to RUNNING
2013-08-22 03:26:07,026 INFO org.apache.hadoop.yarn.server.resourcemanager.rmapp.RMAppImpl: application_1377141553101_0003 State change from ACCEPTED to RUNNING
2013-08-22 03:26:08,108 INFO org.apache.hadoop.yarn.server.resourcemanager.rmcontainer.RMContainerImpl: container_1377141553101_0003_01_000002 Container Transitioned from NEW to ALLOCATED
2013-08-22 03:26:08,108 INFO org.apache.hadoop.yarn.server.resourcemanager.RMAuditLogger: USER=ubuntu	OPERATION=AM Allocated Container	TARGET=SchedulerApp	RESULT=SUCCESS	APPID=application_1377141553101_0003	CONTAINERID=container_1377141553101_0003_01_000002
2013-08-22 03:26:08,108 INFO org.apache.hadoop.yarn.server.resourcemanager.scheduler.common.fica.FiCaSchedulerNode: Assigned container container_1377141553101_0003_01_000002 of capacity <memory:1024, vCores:1> on host hadoop-998-2:35081, which currently has 1 containers, <memory:1024, vCores:1> used and <memory:7168, vCores:15> available
2013-08-22 03:26:08,110 INFO org.apache.hadoop.yarn.server.resourcemanager.scheduler.capacity.LeafQueue: assignedContainer application=application_1377141553101_0003 container=Container: [ContainerId: container_1377141553101_0003_01_000002, NodeId: hadoop-998-2:35081, NodeHttpAddress: hadoop-998-2:8042, Resource: <memory:1024, vCores:1>, Priority: 20, State: NEW, Token: null, Status: container_id {, app_attempt_id {, application_id {, id: 3, cluster_timestamp: 1377141553101, }, attemptId: 1, }, id: 2, }, state: C_NEW, ] containerId=container_1377141553101_0003_01_000002 queue=default: capacity=1.0, absoluteCapacity=1.0, usedResources=<memory:2048, vCores:1>usedCapacity=0.041666668, absoluteUsedCapacity=0.041666668, numApps=1, numContainers=1 usedCapacity=0.041666668 absoluteUsedCapacity=0.041666668 used=<memory:2048, vCores:1> cluster=<memory:49152, vCores:96>
2013-08-22 03:26:08,110 INFO org.apache.hadoop.yarn.server.resourcemanager.scheduler.capacity.ParentQueue: Re-sorting queues since queue: root.default stats: default: capacity=1.0, absoluteCapacity=1.0, usedResources=<memory:3072, vCores:2>usedCapacity=0.0625, absoluteUsedCapacity=0.0625, numApps=1, numContainers=2
2013-08-22 03:26:08,110 INFO org.apache.hadoop.yarn.server.resourcemanager.scheduler.capacity.ParentQueue: assignedContainer queue=root usedCapacity=0.0625 absoluteUsedCapacity=0.0625 used=<memory:3072, vCores:2> cluster=<memory:49152, vCores:96>
2013-08-22 03:26:08,199 INFO org.apache.hadoop.yarn.server.resourcemanager.rmcontainer.RMContainerImpl: container_1377141553101_0003_01_000003 Container Transitioned from NEW to ALLOCATED
2013-08-22 03:26:08,199 INFO org.apache.hadoop.yarn.server.resourcemanager.RMAuditLogger: USER=ubuntu	OPERATION=AM Allocated Container	TARGET=SchedulerApp	RESULT=SUCCESS	APPID=application_1377141553101_0003	CONTAINERID=container_1377141553101_0003_01_000003
2013-08-22 03:26:08,199 INFO org.apache.hadoop.yarn.server.resourcemanager.scheduler.common.fica.FiCaSchedulerNode: Assigned container container_1377141553101_0003_01_000003 of capacity <memory:1024, vCores:1> on host hadoop-998-6:58634, which currently has 1 containers, <memory:1024, vCores:1> used and <memory:7168, vCores:15> available
2013-08-22 03:26:08,201 INFO org.apache.hadoop.yarn.server.resourcemanager.scheduler.capacity.LeafQueue: assignedContainer application=application_1377141553101_0003 container=Container: [ContainerId: container_1377141553101_0003_01_000003, NodeId: hadoop-998-6:58634, NodeHttpAddress: hadoop-998-6:8042, Resource: <memory:1024, vCores:1>, Priority: 20, State: NEW, Token: null, Status: container_id {, app_attempt_id {, application_id {, id: 3, cluster_timestamp: 1377141553101, }, attemptId: 1, }, id: 3, }, state: C_NEW, ] containerId=container_1377141553101_0003_01_000003 queue=default: capacity=1.0, absoluteCapacity=1.0, usedResources=<memory:3072, vCores:2>usedCapacity=0.0625, absoluteUsedCapacity=0.0625, numApps=1, numContainers=2 usedCapacity=0.0625 absoluteUsedCapacity=0.0625 used=<memory:3072, vCores:2> cluster=<memory:49152, vCores:96>
2013-08-22 03:26:08,201 INFO org.apache.hadoop.yarn.server.resourcemanager.scheduler.capacity.ParentQueue: Re-sorting queues since queue: root.default stats: default: capacity=1.0, absoluteCapacity=1.0, usedResources=<memory:4096, vCores:3>usedCapacity=0.083333336, absoluteUsedCapacity=0.083333336, numApps=1, numContainers=3
2013-08-22 03:26:08,201 INFO org.apache.hadoop.yarn.server.resourcemanager.scheduler.capacity.ParentQueue: assignedContainer queue=root usedCapacity=0.083333336 absoluteUsedCapacity=0.083333336 used=<memory:4096, vCores:3> cluster=<memory:49152, vCores:96>
2013-08-22 03:26:09,094 INFO org.apache.hadoop.yarn.server.resourcemanager.rmcontainer.RMContainerImpl: container_1377141553101_0003_01_000002 Container Transitioned from ALLOCATED to ACQUIRED
2013-08-22 03:26:09,096 INFO org.apache.hadoop.yarn.server.resourcemanager.rmcontainer.RMContainerImpl: container_1377141553101_0003_01_000003 Container Transitioned from ALLOCATED to ACQUIRED
2013-08-22 03:26:10,117 INFO org.apache.hadoop.yarn.server.resourcemanager.rmcontainer.RMContainerImpl: container_1377141553101_0003_01_000002 Container Transitioned from ACQUIRED to RUNNING
2013-08-22 03:26:10,140 INFO org.apache.hadoop.yarn.server.resourcemanager.scheduler.AppSchedulingInfo: checking for deactivate... 
2013-08-22 03:26:10,207 INFO org.apache.hadoop.yarn.server.resourcemanager.rmcontainer.RMContainerImpl: container_1377141553101_0003_01_000003 Container Transitioned from ACQUIRED to RUNNING
2013-08-22 03:28:41,870 INFO org.apache.hadoop.yarn.server.resourcemanager.rmcontainer.RMContainerImpl: container_1377141553101_0003_01_000003 Container Transitioned from RUNNING to COMPLETED
2013-08-22 03:28:41,870 INFO org.apache.hadoop.yarn.server.resourcemanager.scheduler.common.fica.FiCaSchedulerApp: Completed container: container_1377141553101_0003_01_000003 in state: COMPLETED event:FINISHED
2013-08-22 03:28:41,870 INFO org.apache.hadoop.yarn.server.resourcemanager.RMAuditLogger: USER=ubuntu	OPERATION=AM Released Container	TARGET=SchedulerApp	RESULT=SUCCESS	APPID=application_1377141553101_0003	CONTAINERID=container_1377141553101_0003_01_000003
2013-08-22 03:28:41,871 INFO org.apache.hadoop.yarn.server.resourcemanager.scheduler.common.fica.FiCaSchedulerNode: Released container container_1377141553101_0003_01_000003 of capacity <memory:1024, vCores:1> on host hadoop-998-6:58634, which currently has 0 containers, <memory:0, vCores:0> used and <memory:8192, vCores:16> available, release resources=true
2013-08-22 03:28:41,871 INFO org.apache.hadoop.yarn.server.resourcemanager.scheduler.capacity.LeafQueue: default used=<memory:3072, vCores:2> numContainers=2 user=ubuntu user-resources=<memory:3072, vCores:2>
2013-08-22 03:28:41,873 INFO org.apache.hadoop.yarn.server.resourcemanager.scheduler.capacity.LeafQueue: completedContainer container=Container: [ContainerId: container_1377141553101_0003_01_000003, NodeId: hadoop-998-6:58634, NodeHttpAddress: hadoop-998-6:8042, Resource: <memory:1024, vCores:1>, Priority: 20, State: NEW, Token: null, Status: container_id {, app_attempt_id {, application_id {, id: 3, cluster_timestamp: 1377141553101, }, attemptId: 1, }, id: 3, }, state: C_COMPLETE, diagnostics: "Container killed by the ApplicationMaster.\n\n", exit_status: 143, ] resource=<memory:1024, vCores:1> queue=default: capacity=1.0, absoluteCapacity=1.0, usedResources=<memory:3072, vCores:2>usedCapacity=0.0625, absoluteUsedCapacity=0.0625, numApps=1, numContainers=2 usedCapacity=0.0625 absoluteUsedCapacity=0.0625 used=<memory:3072, vCores:2> cluster=<memory:49152, vCores:96>
2013-08-22 03:28:41,873 INFO org.apache.hadoop.yarn.server.resourcemanager.scheduler.capacity.ParentQueue: completedContainer queue=root usedCapacity=0.0625 absoluteUsedCapacity=0.0625 used=<memory:3072, vCores:2> cluster=<memory:49152, vCores:96>
2013-08-22 03:28:41,873 INFO org.apache.hadoop.yarn.server.resourcemanager.scheduler.capacity.CapacityScheduler: Application appattempt_1377141553101_0003_000001 released container container_1377141553101_0003_01_000003 on node: host: hadoop-998-6:58634 #containers=0 available=8192 used=0 with event: FINISHED
2013-08-22 03:28:52,072 INFO org.apache.hadoop.yarn.server.resourcemanager.rmcontainer.RMContainerImpl: container_1377141553101_0003_01_000002 Container Transitioned from RUNNING to COMPLETED
2013-08-22 03:28:52,072 INFO org.apache.hadoop.yarn.server.resourcemanager.scheduler.common.fica.FiCaSchedulerApp: Completed container: container_1377141553101_0003_01_000002 in state: COMPLETED event:FINISHED
2013-08-22 03:28:52,072 INFO org.apache.hadoop.yarn.server.resourcemanager.RMAuditLogger: USER=ubuntu	OPERATION=AM Released Container	TARGET=SchedulerApp	RESULT=SUCCESS	APPID=application_1377141553101_0003	CONTAINERID=container_1377141553101_0003_01_000002
2013-08-22 03:28:52,072 INFO org.apache.hadoop.yarn.server.resourcemanager.scheduler.common.fica.FiCaSchedulerNode: Released container container_1377141553101_0003_01_000002 of capacity <memory:1024, vCores:1> on host hadoop-998-2:35081, which currently has 0 containers, <memory:0, vCores:0> used and <memory:8192, vCores:16> available, release resources=true
2013-08-22 03:28:52,072 INFO org.apache.hadoop.yarn.server.resourcemanager.scheduler.capacity.LeafQueue: default used=<memory:2048, vCores:1> numContainers=1 user=ubuntu user-resources=<memory:2048, vCores:1>
2013-08-22 03:28:52,074 INFO org.apache.hadoop.yarn.server.resourcemanager.scheduler.capacity.LeafQueue: completedContainer container=Container: [ContainerId: container_1377141553101_0003_01_000002, NodeId: hadoop-998-2:35081, NodeHttpAddress: hadoop-998-2:8042, Resource: <memory:1024, vCores:1>, Priority: 20, State: NEW, Token: null, Status: container_id {, app_attempt_id {, application_id {, id: 3, cluster_timestamp: 1377141553101, }, attemptId: 1, }, id: 2, }, state: C_COMPLETE, diagnostics: "Container killed by the ApplicationMaster.\n\n", exit_status: 143, ] resource=<memory:1024, vCores:1> queue=default: capacity=1.0, absoluteCapacity=1.0, usedResources=<memory:2048, vCores:1>usedCapacity=0.041666668, absoluteUsedCapacity=0.041666668, numApps=1, numContainers=1 usedCapacity=0.041666668 absoluteUsedCapacity=0.041666668 used=<memory:2048, vCores:1> cluster=<memory:49152, vCores:96>
2013-08-22 03:28:52,074 INFO org.apache.hadoop.yarn.server.resourcemanager.scheduler.capacity.ParentQueue: completedContainer queue=root usedCapacity=0.041666668 absoluteUsedCapacity=0.041666668 used=<memory:2048, vCores:1> cluster=<memory:49152, vCores:96>
2013-08-22 03:28:52,074 INFO org.apache.hadoop.yarn.server.resourcemanager.scheduler.capacity.CapacityScheduler: Application appattempt_1377141553101_0003_000001 released container container_1377141553101_0003_01_000002 on node: host: hadoop-998-2:35081 #containers=0 available=8192 used=0 with event: FINISHED
2013-08-22 03:28:56,592 INFO org.apache.hadoop.yarn.server.resourcemanager.rmapp.attempt.RMAppAttemptImpl: appattempt_1377141553101_0003_000001 State change from RUNNING to FINISHING
2013-08-22 03:28:56,593 INFO org.apache.hadoop.yarn.server.resourcemanager.rmapp.RMAppImpl: application_1377141553101_0003 State change from RUNNING to FINISHING
2013-08-22 03:28:57,109 INFO org.apache.hadoop.yarn.server.resourcemanager.rmcontainer.RMContainerImpl: container_1377141553101_0003_01_000001 Container Transitioned from RUNNING to COMPLETED
2013-08-22 03:28:57,109 INFO org.apache.hadoop.yarn.server.resourcemanager.scheduler.common.fica.FiCaSchedulerApp: Completed container: container_1377141553101_0003_01_000001 in state: COMPLETED event:FINISHED
2013-08-22 03:28:57,109 INFO org.apache.hadoop.yarn.server.resourcemanager.rmapp.attempt.RMAppAttemptImpl: appattempt_1377141553101_0003_000001 State change from FINISHING to FINISHED
2013-08-22 03:28:57,109 INFO org.apache.hadoop.yarn.server.resourcemanager.RMAuditLogger: USER=ubuntu	OPERATION=AM Released Container	TARGET=SchedulerApp	RESULT=SUCCESS	APPID=application_1377141553101_0003	CONTAINERID=container_1377141553101_0003_01_000001
2013-08-22 03:28:57,109 INFO org.apache.hadoop.yarn.server.resourcemanager.scheduler.common.fica.FiCaSchedulerNode: Released container container_1377141553101_0003_01_000001 of capacity <memory:2048, vCores:1> on host hadoop-998-7:60905, which currently has 0 containers, <memory:0, vCores:0> used and <memory:8192, vCores:16> available, release resources=true
2013-08-22 03:28:57,109 INFO org.apache.hadoop.yarn.server.resourcemanager.rmapp.RMAppImpl: application_1377141553101_0003 State change from FINISHING to FINISHED
2013-08-22 03:28:57,109 INFO org.apache.hadoop.yarn.server.resourcemanager.scheduler.capacity.LeafQueue: default used=<memory:0, vCores:0> numContainers=0 user=ubuntu user-resources=<memory:0, vCores:0>
2013-08-22 03:28:57,110 INFO org.apache.hadoop.yarn.server.resourcemanager.RMAuditLogger: USER=ubuntu	OPERATION=Application Finished - Succeeded	TARGET=RMAppManager	RESULT=SUCCESS	APPID=application_1377141553101_0003
2013-08-22 03:28:57,110 INFO org.apache.hadoop.yarn.server.resourcemanager.RMAppManager$ApplicationSummary: appId=application_1377141553101_0003,name=TeraGen,user=ubuntu,queue=default,state=FINISHED,trackingUrl=hadoop-998-1.novalocal:8088/proxy/application_1377141553101_0003/jobhistory/job/job_1377141553101_0003,appMasterHost=hadoop-998-7,startTime=1377141959537,finishTime=1377142136593
2013-08-22 03:28:57,110 INFO org.apache.hadoop.yarn.server.resourcemanager.recovery.RMStateStore: Removing info for app: application_1377141553101_0003
2013-08-22 03:28:57,110 INFO org.apache.hadoop.yarn.server.resourcemanager.amlauncher.AMLauncher: Cleaning master appattempt_1377141553101_0003_000001
2013-08-22 03:28:57,110 INFO org.apache.hadoop.yarn.server.resourcemanager.scheduler.capacity.LeafQueue: completedContainer container=Container: [ContainerId: container_1377141553101_0003_01_000001, NodeId: hadoop-998-7:60905, NodeHttpAddress: hadoop-998-7:8042, Resource: <memory:2048, vCores:1>, Priority: 0, State: NEW, Token: null, Status: container_id {, app_attempt_id {, application_id {, id: 3, cluster_timestamp: 1377141553101, }, attemptId: 1, }, id: 1, }, state: C_COMPLETE, diagnostics: "", exit_status: 0, ] resource=<memory:2048, vCores:1> queue=default: capacity=1.0, absoluteCapacity=1.0, usedResources=<memory:0, vCores:0>usedCapacity=0.0, absoluteUsedCapacity=0.0, numApps=1, numContainers=0 usedCapacity=0.0 absoluteUsedCapacity=0.0 used=<memory:0, vCores:0> cluster=<memory:49152, vCores:96>
2013-08-22 03:28:57,111 INFO org.apache.hadoop.yarn.server.resourcemanager.scheduler.capacity.ParentQueue: completedContainer queue=root usedCapacity=0.0 absoluteUsedCapacity=0.0 used=<memory:0, vCores:0> cluster=<memory:49152, vCores:96>
2013-08-22 03:28:57,111 INFO org.apache.hadoop.yarn.server.resourcemanager.scheduler.capacity.CapacityScheduler: Application appattempt_1377141553101_0003_000001 released container container_1377141553101_0003_01_000001 on node: host: hadoop-998-7:60905 #containers=0 available=8192 used=0 with event: FINISHED
2013-08-22 03:28:57,111 INFO org.apache.hadoop.yarn.server.resourcemanager.scheduler.capacity.CapacityScheduler: Application appattempt_1377141553101_0003_000001 is done. finalState=FINISHED
2013-08-22 03:28:57,111 INFO org.apache.hadoop.yarn.server.resourcemanager.scheduler.AppSchedulingInfo: Application application_1377141553101_0003 requests cleared
2013-08-22 03:28:57,111 INFO org.apache.hadoop.yarn.server.resourcemanager.scheduler.capacity.LeafQueue: Application removed - appId: application_1377141553101_0003 user: ubuntu queue: default #user-pending-applications: 0 #user-active-applications: 0 #queue-pending-applications: 0 #queue-active-applications: 0
2013-08-22 03:28:57,111 INFO org.apache.hadoop.yarn.server.resourcemanager.scheduler.capacity.ParentQueue: Application removed - appId: application_1377141553101_0003 user: ubuntu leaf-queue of parent: root #applications: 0
2013-08-22 03:28:58,144 INFO org.apache.hadoop.yarn.server.resourcemanager.ClientRMService: Allocated new applicationId: 4
2013-08-22 03:29:00,095 INFO org.apache.hadoop.yarn.server.resourcemanager.ClientRMService: Storing Application with id application_1377141553101_0004
2013-08-22 03:29:00,095 INFO org.apache.hadoop.yarn.server.resourcemanager.recovery.RMStateStore: Storing info for app: application_1377141553101_0004
2013-08-22 03:29:00,095 INFO org.apache.hadoop.yarn.server.resourcemanager.ClientRMService: Application with id 4 submitted by user ubuntu
2013-08-22 03:29:00,095 INFO org.apache.hadoop.yarn.server.resourcemanager.RMAuditLogger: USER=ubuntu	IP=192.168.100.9	OPERATION=Submit Application Request	TARGET=ClientRMService	RESULT=SUCCESS	APPID=application_1377141553101_0004
2013-08-22 03:29:00,096 INFO org.apache.hadoop.yarn.server.resourcemanager.rmapp.RMAppImpl: application_1377141553101_0004 State change from NEW to SUBMITTED
2013-08-22 03:29:00,097 INFO org.apache.hadoop.yarn.server.resourcemanager.ApplicationMasterService: Registering appattempt_1377141553101_0004_000001
2013-08-22 03:29:00,097 INFO org.apache.hadoop.yarn.server.resourcemanager.rmapp.attempt.RMAppAttemptImpl: appattempt_1377141553101_0004_000001 State change from NEW to SUBMITTED
2013-08-22 03:29:00,098 INFO org.apache.hadoop.yarn.server.resourcemanager.scheduler.capacity.LeafQueue: Application application_1377141553101_0004 from user: ubuntu activated in queue: default
2013-08-22 03:29:00,098 INFO org.apache.hadoop.yarn.server.resourcemanager.scheduler.capacity.LeafQueue: Application added - appId: application_1377141553101_0004 user: org.apache.hadoop.yarn.server.resourcemanager.scheduler.capacity.LeafQueue$User@6d672980, leaf-queue: default #user-pending-applications: 0 #user-active-applications: 1 #queue-pending-applications: 0 #queue-active-applications: 1
2013-08-22 03:29:00,098 INFO org.apache.hadoop.yarn.server.resourcemanager.scheduler.capacity.ParentQueue: Application added - appId: application_1377141553101_0004 user: ubuntu leaf-queue of parent: root #applications: 1
2013-08-22 03:29:00,098 INFO org.apache.hadoop.yarn.server.resourcemanager.scheduler.capacity.CapacityScheduler: Application Submission: appattempt_1377141553101_0004_000001, user: ubuntu queue: default: capacity=1.0, absoluteCapacity=1.0, usedResources=<memory:0, vCores:0>usedCapacity=0.0, absoluteUsedCapacity=0.0, numApps=1, numContainers=0, currently active: 1
2013-08-22 03:29:00,099 INFO org.apache.hadoop.yarn.server.resourcemanager.rmapp.attempt.RMAppAttemptImpl: appattempt_1377141553101_0004_000001 State change from SUBMITTED to SCHEDULED
2013-08-22 03:29:00,099 INFO org.apache.hadoop.yarn.server.resourcemanager.rmapp.RMAppImpl: application_1377141553101_0004 State change from SUBMITTED to ACCEPTED
2013-08-22 03:29:00,101 INFO org.apache.hadoop.yarn.server.resourcemanager.rmcontainer.RMContainerImpl: container_1377141553101_0004_01_000001 Container Transitioned from NEW to ALLOCATED
2013-08-22 03:29:00,102 INFO org.apache.hadoop.yarn.server.resourcemanager.RMAuditLogger: USER=ubuntu	OPERATION=AM Allocated Container	TARGET=SchedulerApp	RESULT=SUCCESS	APPID=application_1377141553101_0004	CONTAINERID=container_1377141553101_0004_01_000001
2013-08-22 03:29:00,102 INFO org.apache.hadoop.yarn.server.resourcemanager.scheduler.common.fica.FiCaSchedulerNode: Assigned container container_1377141553101_0004_01_000001 of capacity <memory:2048, vCores:1> on host hadoop-998-2:35081, which currently has 1 containers, <memory:2048, vCores:1> used and <memory:6144, vCores:15> available
2013-08-22 03:29:00,103 INFO org.apache.hadoop.yarn.server.resourcemanager.scheduler.capacity.LeafQueue: assignedContainer application=application_1377141553101_0004 container=Container: [ContainerId: container_1377141553101_0004_01_000001, NodeId: hadoop-998-2:35081, NodeHttpAddress: hadoop-998-2:8042, Resource: <memory:2048, vCores:1>, Priority: 0, State: NEW, Token: null, Status: container_id {, app_attempt_id {, application_id {, id: 4, cluster_timestamp: 1377141553101, }, attemptId: 1, }, id: 1, }, state: C_NEW, ] containerId=container_1377141553101_0004_01_000001 queue=default: capacity=1.0, absoluteCapacity=1.0, usedResources=<memory:0, vCores:0>usedCapacity=0.0, absoluteUsedCapacity=0.0, numApps=1, numContainers=0 usedCapacity=0.0 absoluteUsedCapacity=0.0 used=<memory:0, vCores:0> cluster=<memory:49152, vCores:96>
2013-08-22 03:29:00,103 INFO org.apache.hadoop.yarn.server.resourcemanager.scheduler.capacity.ParentQueue: Re-sorting queues since queue: root.default stats: default: capacity=1.0, absoluteCapacity=1.0, usedResources=<memory:2048, vCores:1>usedCapacity=0.041666668, absoluteUsedCapacity=0.041666668, numApps=1, numContainers=1
2013-08-22 03:29:00,107 INFO org.apache.hadoop.yarn.server.resourcemanager.scheduler.capacity.ParentQueue: assignedContainer queue=root usedCapacity=0.041666668 absoluteUsedCapacity=0.041666668 used=<memory:2048, vCores:1> cluster=<memory:49152, vCores:96>
2013-08-22 03:29:00,108 INFO org.apache.hadoop.yarn.server.resourcemanager.rmcontainer.RMContainerImpl: container_1377141553101_0004_01_000001 Container Transitioned from ALLOCATED to ACQUIRED
2013-08-22 03:29:00,110 INFO org.apache.hadoop.yarn.server.resourcemanager.rmapp.attempt.RMAppAttemptImpl: Storing attempt: AppId: application_1377141553101_0004 AttemptId: appattempt_1377141553101_0004_000001 MasterContainer: Container: [ContainerId: container_1377141553101_0004_01_000001, NodeId: hadoop-998-2:35081, NodeHttpAddress: hadoop-998-2:8042, Resource: <memory:2048, vCores:1>, Priority: 0, State: NEW, Token: null, Status: container_id {, app_attempt_id {, application_id {, id: 4, cluster_timestamp: 1377141553101, }, attemptId: 1, }, id: 1, }, state: C_NEW, ]
2013-08-22 03:29:00,110 INFO org.apache.hadoop.yarn.server.resourcemanager.rmapp.attempt.RMAppAttemptImpl: appattempt_1377141553101_0004_000001 State change from SCHEDULED to ALLOCATED_SAVING
2013-08-22 03:29:00,110 INFO org.apache.hadoop.yarn.server.resourcemanager.recovery.RMStateStore: Storing info for attempt: appattempt_1377141553101_0004_000001
2013-08-22 03:29:00,113 INFO org.apache.hadoop.yarn.server.resourcemanager.rmapp.attempt.RMAppAttemptImpl: appattempt_1377141553101_0004_000001 State change from ALLOCATED_SAVING to ALLOCATED
2013-08-22 03:29:00,115 INFO org.apache.hadoop.yarn.server.resourcemanager.amlauncher.AMLauncher: Launching masterappattempt_1377141553101_0004_000001
2013-08-22 03:29:00,117 INFO org.apache.hadoop.yarn.server.resourcemanager.amlauncher.AMLauncher: Setting up container Container: [ContainerId: container_1377141553101_0004_01_000001, NodeId: hadoop-998-2:35081, NodeHttpAddress: hadoop-998-2:8042, Resource: <memory:2048, vCores:1>, Priority: 0, State: NEW, Token: null, Status: container_id {, app_attempt_id {, application_id {, id: 4, cluster_timestamp: 1377141553101, }, attemptId: 1, }, id: 1, }, state: C_NEW, ] for AM appattempt_1377141553101_0004_000001
2013-08-22 03:29:00,118 INFO org.apache.hadoop.yarn.server.resourcemanager.amlauncher.AMLauncher: Command to launch container container_1377141553101_0004_01_000001 : $JAVA_HOME/bin/java -Dlog4j.configuration=container-log4j.properties -Dyarn.app.mapreduce.container.log.dir=<LOG_DIR> -Dyarn.app.mapreduce.container.log.filesize=0 -Dhadoop.root.logger=INFO,CLA  -Xmx1024m org.apache.hadoop.mapreduce.v2.app.MRAppMaster 1><LOG_DIR>/stdout 2><LOG_DIR>/stderr 
2013-08-22 03:29:00,131 INFO org.apache.hadoop.yarn.server.resourcemanager.amlauncher.AMLauncher: Done launching container Container: [ContainerId: container_1377141553101_0004_01_000001, NodeId: hadoop-998-2:35081, NodeHttpAddress: hadoop-998-2:8042, Resource: <memory:2048, vCores:1>, Priority: 0, State: NEW, Token: null, Status: container_id {, app_attempt_id {, application_id {, id: 4, cluster_timestamp: 1377141553101, }, attemptId: 1, }, id: 1, }, state: C_NEW, ] for AM appattempt_1377141553101_0004_000001
2013-08-22 03:29:00,132 INFO org.apache.hadoop.yarn.server.resourcemanager.rmapp.attempt.RMAppAttemptImpl: appattempt_1377141553101_0004_000001 State change from ALLOCATED to LAUNCHED
2013-08-22 03:29:01,109 INFO org.apache.hadoop.yarn.server.resourcemanager.rmcontainer.RMContainerImpl: container_1377141553101_0004_01_000001 Container Transitioned from ACQUIRED to RUNNING
2013-08-22 03:29:09,741 INFO org.apache.hadoop.yarn.server.resourcemanager.ApplicationMasterService: AM registration appattempt_1377141553101_0004_000001
2013-08-22 03:29:09,741 INFO org.apache.hadoop.yarn.server.resourcemanager.RMAuditLogger: USER=ubuntu	IP=192.168.100.6	OPERATION=Register App Master	TARGET=ApplicationMasterService	RESULT=SUCCESS	APPID=application_1377141553101_0004	APPATTEMPTID=appattempt_1377141553101_0004_000001
2013-08-22 03:29:09,742 INFO org.apache.hadoop.yarn.server.resourcemanager.rmapp.attempt.RMAppAttemptImpl: appattempt_1377141553101_0004_000001 State change from LAUNCHED to RUNNING
2013-08-22 03:29:09,742 INFO org.apache.hadoop.yarn.server.resourcemanager.rmapp.RMAppImpl: application_1377141553101_0004 State change from ACCEPTED to RUNNING
2013-08-22 03:29:10,981 INFO org.apache.hadoop.yarn.server.resourcemanager.rmcontainer.RMContainerImpl: container_1377141553101_0004_01_000002 Container Transitioned from NEW to ALLOCATED
2013-08-22 03:29:10,981 INFO org.apache.hadoop.yarn.server.resourcemanager.RMAuditLogger: USER=ubuntu	OPERATION=AM Allocated Container	TARGET=SchedulerApp	RESULT=SUCCESS	APPID=application_1377141553101_0004	CONTAINERID=container_1377141553101_0004_01_000002
2013-08-22 03:29:10,981 INFO org.apache.hadoop.yarn.server.resourcemanager.scheduler.common.fica.FiCaSchedulerNode: Assigned container container_1377141553101_0004_01_000002 of capacity <memory:1024, vCores:1> on host hadoop-998-6:58634, which currently has 1 containers, <memory:1024, vCores:1> used and <memory:7168, vCores:15> available
2013-08-22 03:29:10,982 INFO org.apache.hadoop.yarn.server.resourcemanager.scheduler.capacity.LeafQueue: assignedContainer application=application_1377141553101_0004 container=Container: [ContainerId: container_1377141553101_0004_01_000002, NodeId: hadoop-998-6:58634, NodeHttpAddress: hadoop-998-6:8042, Resource: <memory:1024, vCores:1>, Priority: 20, State: NEW, Token: null, Status: container_id {, app_attempt_id {, application_id {, id: 4, cluster_timestamp: 1377141553101, }, attemptId: 1, }, id: 2, }, state: C_NEW, ] containerId=container_1377141553101_0004_01_000002 queue=default: capacity=1.0, absoluteCapacity=1.0, usedResources=<memory:2048, vCores:1>usedCapacity=0.041666668, absoluteUsedCapacity=0.041666668, numApps=1, numContainers=1 usedCapacity=0.041666668 absoluteUsedCapacity=0.041666668 used=<memory:2048, vCores:1> cluster=<memory:49152, vCores:96>
2013-08-22 03:29:10,982 INFO org.apache.hadoop.yarn.server.resourcemanager.scheduler.capacity.ParentQueue: Re-sorting queues since queue: root.default stats: default: capacity=1.0, absoluteCapacity=1.0, usedResources=<memory:3072, vCores:2>usedCapacity=0.0625, absoluteUsedCapacity=0.0625, numApps=1, numContainers=2
2013-08-22 03:29:10,982 INFO org.apache.hadoop.yarn.server.resourcemanager.scheduler.capacity.ParentQueue: assignedContainer queue=root usedCapacity=0.0625 absoluteUsedCapacity=0.0625 used=<memory:3072, vCores:2> cluster=<memory:49152, vCores:96>
2013-08-22 03:29:11,159 INFO org.apache.hadoop.yarn.server.resourcemanager.rmcontainer.RMContainerImpl: container_1377141553101_0004_01_000003 Container Transitioned from NEW to ALLOCATED
2013-08-22 03:29:11,159 INFO org.apache.hadoop.yarn.server.resourcemanager.RMAuditLogger: USER=ubuntu	OPERATION=AM Allocated Container	TARGET=SchedulerApp	RESULT=SUCCESS	APPID=application_1377141553101_0004	CONTAINERID=container_1377141553101_0004_01_000003
2013-08-22 03:29:11,159 INFO org.apache.hadoop.yarn.server.resourcemanager.scheduler.common.fica.FiCaSchedulerNode: Assigned container container_1377141553101_0004_01_000003 of capacity <memory:1024, vCores:1> on host hadoop-998-2:35081, which currently has 2 containers, <memory:3072, vCores:2> used and <memory:5120, vCores:14> available
2013-08-22 03:29:11,160 INFO org.apache.hadoop.yarn.server.resourcemanager.scheduler.capacity.LeafQueue: assignedContainer application=application_1377141553101_0004 container=Container: [ContainerId: container_1377141553101_0004_01_000003, NodeId: hadoop-998-2:35081, NodeHttpAddress: hadoop-998-2:8042, Resource: <memory:1024, vCores:1>, Priority: 20, State: NEW, Token: null, Status: container_id {, app_attempt_id {, application_id {, id: 4, cluster_timestamp: 1377141553101, }, attemptId: 1, }, id: 3, }, state: C_NEW, ] containerId=container_1377141553101_0004_01_000003 queue=default: capacity=1.0, absoluteCapacity=1.0, usedResources=<memory:3072, vCores:2>usedCapacity=0.0625, absoluteUsedCapacity=0.0625, numApps=1, numContainers=2 usedCapacity=0.0625 absoluteUsedCapacity=0.0625 used=<memory:3072, vCores:2> cluster=<memory:49152, vCores:96>
2013-08-22 03:29:11,160 INFO org.apache.hadoop.yarn.server.resourcemanager.scheduler.capacity.ParentQueue: Re-sorting queues since queue: root.default stats: default: capacity=1.0, absoluteCapacity=1.0, usedResources=<memory:4096, vCores:3>usedCapacity=0.083333336, absoluteUsedCapacity=0.083333336, numApps=1, numContainers=3
2013-08-22 03:29:11,160 INFO org.apache.hadoop.yarn.server.resourcemanager.scheduler.capacity.ParentQueue: assignedContainer queue=root usedCapacity=0.083333336 absoluteUsedCapacity=0.083333336 used=<memory:4096, vCores:3> cluster=<memory:49152, vCores:96>
2013-08-22 03:29:11,804 INFO org.apache.hadoop.yarn.server.resourcemanager.rmcontainer.RMContainerImpl: container_1377141553101_0004_01_000002 Container Transitioned from ALLOCATED to ACQUIRED
2013-08-22 03:29:11,806 INFO org.apache.hadoop.yarn.server.resourcemanager.rmcontainer.RMContainerImpl: container_1377141553101_0004_01_000003 Container Transitioned from ALLOCATED to ACQUIRED
2013-08-22 03:29:12,165 INFO org.apache.hadoop.yarn.server.resourcemanager.rmcontainer.RMContainerImpl: container_1377141553101_0004_01_000003 Container Transitioned from ACQUIRED to RUNNING
2013-08-22 03:29:12,855 INFO org.apache.hadoop.yarn.server.resourcemanager.scheduler.AppSchedulingInfo: checking for deactivate... 
2013-08-22 03:29:12,989 INFO org.apache.hadoop.yarn.server.resourcemanager.rmcontainer.RMContainerImpl: container_1377141553101_0004_01_000002 Container Transitioned from ACQUIRED to RUNNING
2013-08-22 03:31:46,164 INFO org.apache.hadoop.yarn.server.resourcemanager.rmcontainer.RMContainerImpl: container_1377141553101_0004_01_000003 Container Transitioned from RUNNING to COMPLETED
2013-08-22 03:31:46,169 INFO org.apache.hadoop.yarn.server.resourcemanager.scheduler.common.fica.FiCaSchedulerApp: Completed container: container_1377141553101_0004_01_000003 in state: COMPLETED event:FINISHED
2013-08-22 03:31:46,170 INFO org.apache.hadoop.yarn.server.resourcemanager.RMAuditLogger: USER=ubuntu	OPERATION=AM Released Container	TARGET=SchedulerApp	RESULT=SUCCESS	APPID=application_1377141553101_0004	CONTAINERID=container_1377141553101_0004_01_000003
2013-08-22 03:31:46,170 INFO org.apache.hadoop.yarn.server.resourcemanager.scheduler.common.fica.FiCaSchedulerNode: Released container container_1377141553101_0004_01_000003 of capacity <memory:1024, vCores:1> on host hadoop-998-2:35081, which currently has 1 containers, <memory:2048, vCores:1> used and <memory:6144, vCores:15> available, release resources=true
2013-08-22 03:31:46,170 INFO org.apache.hadoop.yarn.server.resourcemanager.scheduler.capacity.LeafQueue: default used=<memory:3072, vCores:2> numContainers=2 user=ubuntu user-resources=<memory:3072, vCores:2>
2013-08-22 03:31:46,172 INFO org.apache.hadoop.yarn.server.resourcemanager.scheduler.capacity.LeafQueue: completedContainer container=Container: [ContainerId: container_1377141553101_0004_01_000003, NodeId: hadoop-998-2:35081, NodeHttpAddress: hadoop-998-2:8042, Resource: <memory:1024, vCores:1>, Priority: 20, State: NEW, Token: null, Status: container_id {, app_attempt_id {, application_id {, id: 4, cluster_timestamp: 1377141553101, }, attemptId: 1, }, id: 3, }, state: C_COMPLETE, diagnostics: "Container killed by the ApplicationMaster.\n\n", exit_status: 143, ] resource=<memory:1024, vCores:1> queue=default: capacity=1.0, absoluteCapacity=1.0, usedResources=<memory:3072, vCores:2>usedCapacity=0.0625, absoluteUsedCapacity=0.0625, numApps=1, numContainers=2 usedCapacity=0.0625 absoluteUsedCapacity=0.0625 used=<memory:3072, vCores:2> cluster=<memory:49152, vCores:96>
2013-08-22 03:31:46,172 INFO org.apache.hadoop.yarn.server.resourcemanager.scheduler.capacity.ParentQueue: completedContainer queue=root usedCapacity=0.0625 absoluteUsedCapacity=0.0625 used=<memory:3072, vCores:2> cluster=<memory:49152, vCores:96>
2013-08-22 03:31:46,172 INFO org.apache.hadoop.yarn.server.resourcemanager.scheduler.capacity.CapacityScheduler: Application appattempt_1377141553101_0004_000001 released container container_1377141553101_0004_01_000003 on node: host: hadoop-998-2:35081 #containers=1 available=6144 used=2048 with event: FINISHED
2013-08-22 03:31:53,820 INFO org.apache.hadoop.yarn.server.resourcemanager.rmcontainer.RMContainerImpl: container_1377141553101_0004_01_000002 Container Transitioned from RUNNING to COMPLETED
2013-08-22 03:31:53,821 INFO org.apache.hadoop.yarn.server.resourcemanager.scheduler.common.fica.FiCaSchedulerApp: Completed container: container_1377141553101_0004_01_000002 in state: COMPLETED event:FINISHED
2013-08-22 03:31:53,821 INFO org.apache.hadoop.yarn.server.resourcemanager.RMAuditLogger: USER=ubuntu	OPERATION=AM Released Container	TARGET=SchedulerApp	RESULT=SUCCESS	APPID=application_1377141553101_0004	CONTAINERID=container_1377141553101_0004_01_000002
2013-08-22 03:31:53,821 INFO org.apache.hadoop.yarn.server.resourcemanager.scheduler.common.fica.FiCaSchedulerNode: Released container container_1377141553101_0004_01_000002 of capacity <memory:1024, vCores:1> on host hadoop-998-6:58634, which currently has 0 containers, <memory:0, vCores:0> used and <memory:8192, vCores:16> available, release resources=true
2013-08-22 03:31:53,821 INFO org.apache.hadoop.yarn.server.resourcemanager.scheduler.capacity.LeafQueue: default used=<memory:2048, vCores:1> numContainers=1 user=ubuntu user-resources=<memory:2048, vCores:1>
2013-08-22 03:31:53,823 INFO org.apache.hadoop.yarn.server.resourcemanager.scheduler.capacity.LeafQueue: completedContainer container=Container: [ContainerId: container_1377141553101_0004_01_000002, NodeId: hadoop-998-6:58634, NodeHttpAddress: hadoop-998-6:8042, Resource: <memory:1024, vCores:1>, Priority: 20, State: NEW, Token: null, Status: container_id {, app_attempt_id {, application_id {, id: 4, cluster_timestamp: 1377141553101, }, attemptId: 1, }, id: 2, }, state: C_COMPLETE, diagnostics: "Container killed by the ApplicationMaster.\n", exit_status: 0, ] resource=<memory:1024, vCores:1> queue=default: capacity=1.0, absoluteCapacity=1.0, usedResources=<memory:2048, vCores:1>usedCapacity=0.041666668, absoluteUsedCapacity=0.041666668, numApps=1, numContainers=1 usedCapacity=0.041666668 absoluteUsedCapacity=0.041666668 used=<memory:2048, vCores:1> cluster=<memory:49152, vCores:96>
2013-08-22 03:31:53,823 INFO org.apache.hadoop.yarn.server.resourcemanager.scheduler.capacity.ParentQueue: completedContainer queue=root usedCapacity=0.041666668 absoluteUsedCapacity=0.041666668 used=<memory:2048, vCores:1> cluster=<memory:49152, vCores:96>
2013-08-22 03:31:53,823 INFO org.apache.hadoop.yarn.server.resourcemanager.scheduler.capacity.CapacityScheduler: Application appattempt_1377141553101_0004_000001 released container container_1377141553101_0004_01_000002 on node: host: hadoop-998-6:58634 #containers=0 available=8192 used=0 with event: FINISHED
2013-08-22 03:31:59,674 INFO org.apache.hadoop.yarn.server.resourcemanager.rmapp.attempt.RMAppAttemptImpl: appattempt_1377141553101_0004_000001 State change from RUNNING to FINISHING
2013-08-22 03:31:59,675 INFO org.apache.hadoop.yarn.server.resourcemanager.rmapp.RMAppImpl: application_1377141553101_0004 State change from RUNNING to FINISHING
2013-08-22 03:32:00,233 INFO org.apache.hadoop.yarn.server.resourcemanager.rmcontainer.RMContainerImpl: container_1377141553101_0004_01_000001 Container Transitioned from RUNNING to COMPLETED
2013-08-22 03:32:00,233 INFO org.apache.hadoop.yarn.server.resourcemanager.scheduler.common.fica.FiCaSchedulerApp: Completed container: container_1377141553101_0004_01_000001 in state: COMPLETED event:FINISHED
2013-08-22 03:32:00,233 INFO org.apache.hadoop.yarn.server.resourcemanager.RMAuditLogger: USER=ubuntu	OPERATION=AM Released Container	TARGET=SchedulerApp	RESULT=SUCCESS	APPID=application_1377141553101_0004	CONTAINERID=container_1377141553101_0004_01_000001
2013-08-22 03:32:00,233 INFO org.apache.hadoop.yarn.server.resourcemanager.scheduler.common.fica.FiCaSchedulerNode: Released container container_1377141553101_0004_01_000001 of capacity <memory:2048, vCores:1> on host hadoop-998-2:35081, which currently has 0 containers, <memory:0, vCores:0> used and <memory:8192, vCores:16> available, release resources=true
2013-08-22 03:32:00,233 INFO org.apache.hadoop.yarn.server.resourcemanager.scheduler.capacity.LeafQueue: default used=<memory:0, vCores:0> numContainers=0 user=ubuntu user-resources=<memory:0, vCores:0>
2013-08-22 03:32:00,235 INFO org.apache.hadoop.yarn.server.resourcemanager.scheduler.capacity.LeafQueue: completedContainer container=Container: [ContainerId: container_1377141553101_0004_01_000001, NodeId: hadoop-998-2:35081, NodeHttpAddress: hadoop-998-2:8042, Resource: <memory:2048, vCores:1>, Priority: 0, State: NEW, Token: null, Status: container_id {, app_attempt_id {, application_id {, id: 4, cluster_timestamp: 1377141553101, }, attemptId: 1, }, id: 1, }, state: C_COMPLETE, diagnostics: "", exit_status: 0, ] resource=<memory:2048, vCores:1> queue=default: capacity=1.0, absoluteCapacity=1.0, usedResources=<memory:0, vCores:0>usedCapacity=0.0, absoluteUsedCapacity=0.0, numApps=1, numContainers=0 usedCapacity=0.0 absoluteUsedCapacity=0.0 used=<memory:0, vCores:0> cluster=<memory:49152, vCores:96>
2013-08-22 03:32:00,235 INFO org.apache.hadoop.yarn.server.resourcemanager.scheduler.capacity.ParentQueue: completedContainer queue=root usedCapacity=0.0 absoluteUsedCapacity=0.0 used=<memory:0, vCores:0> cluster=<memory:49152, vCores:96>
2013-08-22 03:32:00,235 INFO org.apache.hadoop.yarn.server.resourcemanager.scheduler.capacity.CapacityScheduler: Application appattempt_1377141553101_0004_000001 released container container_1377141553101_0004_01_000001 on node: host: hadoop-998-2:35081 #containers=0 available=8192 used=0 with event: FINISHED
2013-08-22 03:32:00,235 INFO org.apache.hadoop.yarn.server.resourcemanager.rmapp.attempt.RMAppAttemptImpl: appattempt_1377141553101_0004_000001 State change from FINISHING to FINISHED
2013-08-22 03:32:00,236 INFO org.apache.hadoop.yarn.server.resourcemanager.rmapp.RMAppImpl: application_1377141553101_0004 State change from FINISHING to FINISHED
2013-08-22 03:32:00,236 INFO org.apache.hadoop.yarn.server.resourcemanager.scheduler.capacity.CapacityScheduler: Application appattempt_1377141553101_0004_000001 is done. finalState=FINISHED
2013-08-22 03:32:00,236 INFO org.apache.hadoop.yarn.server.resourcemanager.scheduler.AppSchedulingInfo: Application application_1377141553101_0004 requests cleared
2013-08-22 03:32:00,237 INFO org.apache.hadoop.yarn.server.resourcemanager.scheduler.capacity.LeafQueue: Application removed - appId: application_1377141553101_0004 user: ubuntu queue: default #user-pending-applications: 0 #user-active-applications: 0 #queue-pending-applications: 0 #queue-active-applications: 0
2013-08-22 03:32:00,237 INFO org.apache.hadoop.yarn.server.resourcemanager.scheduler.capacity.ParentQueue: Application removed - appId: application_1377141553101_0004 user: ubuntu leaf-queue of parent: root #applications: 0
2013-08-22 03:32:00,237 INFO org.apache.hadoop.yarn.server.resourcemanager.RMAuditLogger: USER=ubuntu	OPERATION=Application Finished - Succeeded	TARGET=RMAppManager	RESULT=SUCCESS	APPID=application_1377141553101_0004
2013-08-22 03:32:00,238 INFO org.apache.hadoop.yarn.server.resourcemanager.amlauncher.AMLauncher: Cleaning master appattempt_1377141553101_0004_000001
2013-08-22 03:32:00,238 INFO org.apache.hadoop.yarn.server.resourcemanager.recovery.RMStateStore: Removing info for app: application_1377141553101_0004
2013-08-22 03:32:00,238 INFO org.apache.hadoop.yarn.server.resourcemanager.RMAppManager$ApplicationSummary: appId=application_1377141553101_0004,name=TeraGen,user=ubuntu,queue=default,state=FINISHED,trackingUrl=hadoop-998-1.novalocal:8088/proxy/application_1377141553101_0004/jobhistory/job/job_1377141553101_0004,appMasterHost=hadoop-998-2,startTime=1377142140094,finishTime=1377142319675
2013-08-22 03:32:00,782 INFO org.apache.hadoop.yarn.server.resourcemanager.ClientRMService: Allocated new applicationId: 5
2013-08-22 03:32:02,763 INFO org.apache.hadoop.yarn.server.resourcemanager.ClientRMService: Storing Application with id application_1377141553101_0005
2013-08-22 03:32:02,763 INFO org.apache.hadoop.yarn.server.resourcemanager.recovery.RMStateStore: Storing info for app: application_1377141553101_0005
2013-08-22 03:32:02,763 INFO org.apache.hadoop.yarn.server.resourcemanager.ClientRMService: Application with id 5 submitted by user ubuntu
2013-08-22 03:32:02,764 INFO org.apache.hadoop.yarn.server.resourcemanager.RMAuditLogger: USER=ubuntu	IP=192.168.100.9	OPERATION=Submit Application Request	TARGET=ClientRMService	RESULT=SUCCESS	APPID=application_1377141553101_0005
2013-08-22 03:32:02,765 INFO org.apache.hadoop.yarn.server.resourcemanager.rmapp.RMAppImpl: application_1377141553101_0005 State change from NEW to SUBMITTED
2013-08-22 03:32:02,765 INFO org.apache.hadoop.yarn.server.resourcemanager.ApplicationMasterService: Registering appattempt_1377141553101_0005_000001
2013-08-22 03:32:02,765 INFO org.apache.hadoop.yarn.server.resourcemanager.rmapp.attempt.RMAppAttemptImpl: appattempt_1377141553101_0005_000001 State change from NEW to SUBMITTED
2013-08-22 03:32:02,766 INFO org.apache.hadoop.yarn.server.resourcemanager.scheduler.capacity.LeafQueue: Application application_1377141553101_0005 from user: ubuntu activated in queue: default
2013-08-22 03:32:02,766 INFO org.apache.hadoop.yarn.server.resourcemanager.scheduler.capacity.LeafQueue: Application added - appId: application_1377141553101_0005 user: org.apache.hadoop.yarn.server.resourcemanager.scheduler.capacity.LeafQueue$User@608b854d, leaf-queue: default #user-pending-applications: 0 #user-active-applications: 1 #queue-pending-applications: 0 #queue-active-applications: 1
2013-08-22 03:32:02,766 INFO org.apache.hadoop.yarn.server.resourcemanager.scheduler.capacity.ParentQueue: Application added - appId: application_1377141553101_0005 user: ubuntu leaf-queue of parent: root #applications: 1
2013-08-22 03:32:02,767 INFO org.apache.hadoop.yarn.server.resourcemanager.scheduler.capacity.CapacityScheduler: Application Submission: appattempt_1377141553101_0005_000001, user: ubuntu queue: default: capacity=1.0, absoluteCapacity=1.0, usedResources=<memory:0, vCores:0>usedCapacity=0.0, absoluteUsedCapacity=0.0, numApps=1, numContainers=0, currently active: 1
2013-08-22 03:32:02,767 INFO org.apache.hadoop.yarn.server.resourcemanager.rmapp.attempt.RMAppAttemptImpl: appattempt_1377141553101_0005_000001 State change from SUBMITTED to SCHEDULED
2013-08-22 03:32:02,767 INFO org.apache.hadoop.yarn.server.resourcemanager.rmapp.RMAppImpl: application_1377141553101_0005 State change from SUBMITTED to ACCEPTED
2013-08-22 03:32:02,847 INFO org.apache.hadoop.yarn.server.resourcemanager.rmcontainer.RMContainerImpl: container_1377141553101_0005_01_000001 Container Transitioned from NEW to ALLOCATED
2013-08-22 03:32:02,847 INFO org.apache.hadoop.yarn.server.resourcemanager.RMAuditLogger: USER=ubuntu	OPERATION=AM Allocated Container	TARGET=SchedulerApp	RESULT=SUCCESS	APPID=application_1377141553101_0005	CONTAINERID=container_1377141553101_0005_01_000001
2013-08-22 03:32:02,847 INFO org.apache.hadoop.yarn.server.resourcemanager.scheduler.common.fica.FiCaSchedulerNode: Assigned container container_1377141553101_0005_01_000001 of capacity <memory:2048, vCores:1> on host hadoop-998-6:58634, which currently has 1 containers, <memory:2048, vCores:1> used and <memory:6144, vCores:15> available
2013-08-22 03:32:02,848 INFO org.apache.hadoop.yarn.server.resourcemanager.scheduler.capacity.LeafQueue: assignedContainer application=application_1377141553101_0005 container=Container: [ContainerId: container_1377141553101_0005_01_000001, NodeId: hadoop-998-6:58634, NodeHttpAddress: hadoop-998-6:8042, Resource: <memory:2048, vCores:1>, Priority: 0, State: NEW, Token: null, Status: container_id {, app_attempt_id {, application_id {, id: 5, cluster_timestamp: 1377141553101, }, attemptId: 1, }, id: 1, }, state: C_NEW, ] containerId=container_1377141553101_0005_01_000001 queue=default: capacity=1.0, absoluteCapacity=1.0, usedResources=<memory:0, vCores:0>usedCapacity=0.0, absoluteUsedCapacity=0.0, numApps=1, numContainers=0 usedCapacity=0.0 absoluteUsedCapacity=0.0 used=<memory:0, vCores:0> cluster=<memory:49152, vCores:96>
2013-08-22 03:32:02,849 INFO org.apache.hadoop.yarn.server.resourcemanager.scheduler.capacity.ParentQueue: Re-sorting queues since queue: root.default stats: default: capacity=1.0, absoluteCapacity=1.0, usedResources=<memory:2048, vCores:1>usedCapacity=0.041666668, absoluteUsedCapacity=0.041666668, numApps=1, numContainers=1
2013-08-22 03:32:02,849 INFO org.apache.hadoop.yarn.server.resourcemanager.scheduler.capacity.ParentQueue: assignedContainer queue=root usedCapacity=0.041666668 absoluteUsedCapacity=0.041666668 used=<memory:2048, vCores:1> cluster=<memory:49152, vCores:96>
2013-08-22 03:32:02,850 INFO org.apache.hadoop.yarn.server.resourcemanager.rmcontainer.RMContainerImpl: container_1377141553101_0005_01_000001 Container Transitioned from ALLOCATED to ACQUIRED
2013-08-22 03:32:02,852 INFO org.apache.hadoop.yarn.server.resourcemanager.rmapp.attempt.RMAppAttemptImpl: Storing attempt: AppId: application_1377141553101_0005 AttemptId: appattempt_1377141553101_0005_000001 MasterContainer: Container: [ContainerId: container_1377141553101_0005_01_000001, NodeId: hadoop-998-6:58634, NodeHttpAddress: hadoop-998-6:8042, Resource: <memory:2048, vCores:1>, Priority: 0, State: NEW, Token: null, Status: container_id {, app_attempt_id {, application_id {, id: 5, cluster_timestamp: 1377141553101, }, attemptId: 1, }, id: 1, }, state: C_NEW, ]
2013-08-22 03:32:02,853 INFO org.apache.hadoop.yarn.server.resourcemanager.recovery.RMStateStore: Storing info for attempt: appattempt_1377141553101_0005_000001
2013-08-22 03:32:02,853 INFO org.apache.hadoop.yarn.server.resourcemanager.rmapp.attempt.RMAppAttemptImpl: appattempt_1377141553101_0005_000001 State change from SCHEDULED to ALLOCATED_SAVING
2013-08-22 03:32:02,854 INFO org.apache.hadoop.yarn.server.resourcemanager.rmapp.attempt.RMAppAttemptImpl: appattempt_1377141553101_0005_000001 State change from ALLOCATED_SAVING to ALLOCATED
2013-08-22 03:32:02,855 INFO org.apache.hadoop.yarn.server.resourcemanager.amlauncher.AMLauncher: Launching masterappattempt_1377141553101_0005_000001
2013-08-22 03:32:02,858 INFO org.apache.hadoop.yarn.server.resourcemanager.amlauncher.AMLauncher: Setting up container Container: [ContainerId: container_1377141553101_0005_01_000001, NodeId: hadoop-998-6:58634, NodeHttpAddress: hadoop-998-6:8042, Resource: <memory:2048, vCores:1>, Priority: 0, State: NEW, Token: null, Status: container_id {, app_attempt_id {, application_id {, id: 5, cluster_timestamp: 1377141553101, }, attemptId: 1, }, id: 1, }, state: C_NEW, ] for AM appattempt_1377141553101_0005_000001
2013-08-22 03:32:02,858 INFO org.apache.hadoop.yarn.server.resourcemanager.amlauncher.AMLauncher: Command to launch container container_1377141553101_0005_01_000001 : $JAVA_HOME/bin/java -Dlog4j.configuration=container-log4j.properties -Dyarn.app.mapreduce.container.log.dir=<LOG_DIR> -Dyarn.app.mapreduce.container.log.filesize=0 -Dhadoop.root.logger=INFO,CLA  -Xmx1024m org.apache.hadoop.mapreduce.v2.app.MRAppMaster 1><LOG_DIR>/stdout 2><LOG_DIR>/stderr 
2013-08-22 03:32:02,867 INFO org.apache.hadoop.yarn.server.resourcemanager.amlauncher.AMLauncher: Done launching container Container: [ContainerId: container_1377141553101_0005_01_000001, NodeId: hadoop-998-6:58634, NodeHttpAddress: hadoop-998-6:8042, Resource: <memory:2048, vCores:1>, Priority: 0, State: NEW, Token: null, Status: container_id {, app_attempt_id {, application_id {, id: 5, cluster_timestamp: 1377141553101, }, attemptId: 1, }, id: 1, }, state: C_NEW, ] for AM appattempt_1377141553101_0005_000001
2013-08-22 03:32:02,868 INFO org.apache.hadoop.yarn.server.resourcemanager.rmapp.attempt.RMAppAttemptImpl: appattempt_1377141553101_0005_000001 State change from ALLOCATED to LAUNCHED
2013-08-22 03:32:03,854 INFO org.apache.hadoop.yarn.server.resourcemanager.rmcontainer.RMContainerImpl: container_1377141553101_0005_01_000001 Container Transitioned from ACQUIRED to RUNNING
2013-08-22 03:32:09,161 INFO org.apache.hadoop.yarn.server.resourcemanager.ApplicationMasterService: AM registration appattempt_1377141553101_0005_000001
2013-08-22 03:32:09,162 INFO org.apache.hadoop.yarn.server.resourcemanager.RMAuditLogger: USER=ubuntu	IP=192.168.100.10	OPERATION=Register App Master	TARGET=ApplicationMasterService	RESULT=SUCCESS	APPID=application_1377141553101_0005	APPATTEMPTID=appattempt_1377141553101_0005_000001
2013-08-22 03:32:09,162 INFO org.apache.hadoop.yarn.server.resourcemanager.rmapp.attempt.RMAppAttemptImpl: appattempt_1377141553101_0005_000001 State change from LAUNCHED to RUNNING
2013-08-22 03:32:09,163 INFO org.apache.hadoop.yarn.server.resourcemanager.rmapp.RMAppImpl: application_1377141553101_0005 State change from ACCEPTED to RUNNING
2013-08-22 03:32:10,266 INFO org.apache.hadoop.yarn.server.resourcemanager.rmcontainer.RMContainerImpl: container_1377141553101_0005_01_000002 Container Transitioned from NEW to ALLOCATED
2013-08-22 03:32:10,266 INFO org.apache.hadoop.yarn.server.resourcemanager.RMAuditLogger: USER=ubuntu	OPERATION=AM Allocated Container	TARGET=SchedulerApp	RESULT=SUCCESS	APPID=application_1377141553101_0005	CONTAINERID=container_1377141553101_0005_01_000002
2013-08-22 03:32:10,267 INFO org.apache.hadoop.yarn.server.resourcemanager.scheduler.common.fica.FiCaSchedulerNode: Assigned container container_1377141553101_0005_01_000002 of capacity <memory:1024, vCores:1> on host hadoop-998-2:35081, which currently has 1 containers, <memory:1024, vCores:1> used and <memory:7168, vCores:15> available
2013-08-22 03:32:10,268 INFO org.apache.hadoop.yarn.server.resourcemanager.scheduler.capacity.LeafQueue: assignedContainer application=application_1377141553101_0005 container=Container: [ContainerId: container_1377141553101_0005_01_000002, NodeId: hadoop-998-2:35081, NodeHttpAddress: hadoop-998-2:8042, Resource: <memory:1024, vCores:1>, Priority: 20, State: NEW, Token: null, Status: container_id {, app_attempt_id {, application_id {, id: 5, cluster_timestamp: 1377141553101, }, attemptId: 1, }, id: 2, }, state: C_NEW, ] containerId=container_1377141553101_0005_01_000002 queue=default: capacity=1.0, absoluteCapacity=1.0, usedResources=<memory:2048, vCores:1>usedCapacity=0.041666668, absoluteUsedCapacity=0.041666668, numApps=1, numContainers=1 usedCapacity=0.041666668 absoluteUsedCapacity=0.041666668 used=<memory:2048, vCores:1> cluster=<memory:49152, vCores:96>
2013-08-22 03:32:10,268 INFO org.apache.hadoop.yarn.server.resourcemanager.scheduler.capacity.ParentQueue: Re-sorting queues since queue: root.default stats: default: capacity=1.0, absoluteCapacity=1.0, usedResources=<memory:3072, vCores:2>usedCapacity=0.0625, absoluteUsedCapacity=0.0625, numApps=1, numContainers=2
2013-08-22 03:32:10,268 INFO org.apache.hadoop.yarn.server.resourcemanager.scheduler.capacity.ParentQueue: assignedContainer queue=root usedCapacity=0.0625 absoluteUsedCapacity=0.0625 used=<memory:3072, vCores:2> cluster=<memory:49152, vCores:96>
2013-08-22 03:32:10,384 INFO org.apache.hadoop.yarn.server.resourcemanager.rmcontainer.RMContainerImpl: container_1377141553101_0005_01_000003 Container Transitioned from NEW to ALLOCATED
2013-08-22 03:32:10,385 INFO org.apache.hadoop.yarn.server.resourcemanager.RMAuditLogger: USER=ubuntu	OPERATION=AM Allocated Container	TARGET=SchedulerApp	RESULT=SUCCESS	APPID=application_1377141553101_0005	CONTAINERID=container_1377141553101_0005_01_000003
2013-08-22 03:32:10,385 INFO org.apache.hadoop.yarn.server.resourcemanager.scheduler.common.fica.FiCaSchedulerNode: Assigned container container_1377141553101_0005_01_000003 of capacity <memory:1024, vCores:1> on host hadoop-998-5:56087, which currently has 1 containers, <memory:1024, vCores:1> used and <memory:7168, vCores:15> available
2013-08-22 03:32:10,386 INFO org.apache.hadoop.yarn.server.resourcemanager.scheduler.capacity.LeafQueue: assignedContainer application=application_1377141553101_0005 container=Container: [ContainerId: container_1377141553101_0005_01_000003, NodeId: hadoop-998-5:56087, NodeHttpAddress: hadoop-998-5:8042, Resource: <memory:1024, vCores:1>, Priority: 20, State: NEW, Token: null, Status: container_id {, app_attempt_id {, application_id {, id: 5, cluster_timestamp: 1377141553101, }, attemptId: 1, }, id: 3, }, state: C_NEW, ] containerId=container_1377141553101_0005_01_000003 queue=default: capacity=1.0, absoluteCapacity=1.0, usedResources=<memory:3072, vCores:2>usedCapacity=0.0625, absoluteUsedCapacity=0.0625, numApps=1, numContainers=2 usedCapacity=0.0625 absoluteUsedCapacity=0.0625 used=<memory:3072, vCores:2> cluster=<memory:49152, vCores:96>
2013-08-22 03:32:10,386 INFO org.apache.hadoop.yarn.server.resourcemanager.scheduler.capacity.ParentQueue: Re-sorting queues since queue: root.default stats: default: capacity=1.0, absoluteCapacity=1.0, usedResources=<memory:4096, vCores:3>usedCapacity=0.083333336, absoluteUsedCapacity=0.083333336, numApps=1, numContainers=3
2013-08-22 03:32:10,386 INFO org.apache.hadoop.yarn.server.resourcemanager.scheduler.capacity.ParentQueue: assignedContainer queue=root usedCapacity=0.083333336 absoluteUsedCapacity=0.083333336 used=<memory:4096, vCores:3> cluster=<memory:49152, vCores:96>
2013-08-22 03:32:11,223 INFO org.apache.hadoop.yarn.server.resourcemanager.rmcontainer.RMContainerImpl: container_1377141553101_0005_01_000002 Container Transitioned from ALLOCATED to ACQUIRED
2013-08-22 03:32:11,226 INFO org.apache.hadoop.yarn.server.resourcemanager.rmcontainer.RMContainerImpl: container_1377141553101_0005_01_000003 Container Transitioned from ALLOCATED to ACQUIRED
2013-08-22 03:32:12,258 INFO org.apache.hadoop.yarn.server.resourcemanager.scheduler.AppSchedulingInfo: checking for deactivate... 
2013-08-22 03:32:12,275 INFO org.apache.hadoop.yarn.server.resourcemanager.rmcontainer.RMContainerImpl: container_1377141553101_0005_01_000002 Container Transitioned from ACQUIRED to RUNNING
2013-08-22 03:32:14,495 INFO org.apache.hadoop.yarn.server.resourcemanager.rmcontainer.RMContainerImpl: container_1377141553101_0005_01_000003 Container Transitioned from ACQUIRED to RUNNING
2013-08-22 03:34:43,914 INFO org.apache.hadoop.yarn.server.resourcemanager.rmcontainer.RMContainerImpl: container_1377141553101_0005_01_000002 Container Transitioned from RUNNING to COMPLETED
2013-08-22 03:34:43,915 INFO org.apache.hadoop.yarn.server.resourcemanager.scheduler.common.fica.FiCaSchedulerApp: Completed container: container_1377141553101_0005_01_000002 in state: COMPLETED event:FINISHED
2013-08-22 03:34:43,915 INFO org.apache.hadoop.yarn.server.resourcemanager.RMAuditLogger: USER=ubuntu	OPERATION=AM Released Container	TARGET=SchedulerApp	RESULT=SUCCESS	APPID=application_1377141553101_0005	CONTAINERID=container_1377141553101_0005_01_000002
2013-08-22 03:34:43,915 INFO org.apache.hadoop.yarn.server.resourcemanager.scheduler.common.fica.FiCaSchedulerNode: Released container container_1377141553101_0005_01_000002 of capacity <memory:1024, vCores:1> on host hadoop-998-2:35081, which currently has 0 containers, <memory:0, vCores:0> used and <memory:8192, vCores:16> available, release resources=true
2013-08-22 03:34:43,915 INFO org.apache.hadoop.yarn.server.resourcemanager.scheduler.capacity.LeafQueue: default used=<memory:3072, vCores:2> numContainers=2 user=ubuntu user-resources=<memory:3072, vCores:2>
2013-08-22 03:34:43,917 INFO org.apache.hadoop.yarn.server.resourcemanager.scheduler.capacity.LeafQueue: completedContainer container=Container: [ContainerId: container_1377141553101_0005_01_000002, NodeId: hadoop-998-2:35081, NodeHttpAddress: hadoop-998-2:8042, Resource: <memory:1024, vCores:1>, Priority: 20, State: NEW, Token: null, Status: container_id {, app_attempt_id {, application_id {, id: 5, cluster_timestamp: 1377141553101, }, attemptId: 1, }, id: 2, }, state: C_COMPLETE, diagnostics: "Container killed by the ApplicationMaster.\n", exit_status: 0, ] resource=<memory:1024, vCores:1> queue=default: capacity=1.0, absoluteCapacity=1.0, usedResources=<memory:3072, vCores:2>usedCapacity=0.0625, absoluteUsedCapacity=0.0625, numApps=1, numContainers=2 usedCapacity=0.0625 absoluteUsedCapacity=0.0625 used=<memory:3072, vCores:2> cluster=<memory:49152, vCores:96>
2013-08-22 03:34:43,917 INFO org.apache.hadoop.yarn.server.resourcemanager.scheduler.capacity.ParentQueue: completedContainer queue=root usedCapacity=0.0625 absoluteUsedCapacity=0.0625 used=<memory:3072, vCores:2> cluster=<memory:49152, vCores:96>
2013-08-22 03:34:43,917 INFO org.apache.hadoop.yarn.server.resourcemanager.scheduler.capacity.CapacityScheduler: Application appattempt_1377141553101_0005_000001 released container container_1377141553101_0005_01_000002 on node: host: hadoop-998-2:35081 #containers=0 available=8192 used=0 with event: FINISHED
2013-08-22 03:34:55,884 INFO org.apache.hadoop.yarn.server.resourcemanager.rmcontainer.RMContainerImpl: container_1377141553101_0005_01_000003 Container Transitioned from RUNNING to COMPLETED
2013-08-22 03:34:55,884 INFO org.apache.hadoop.yarn.server.resourcemanager.scheduler.common.fica.FiCaSchedulerApp: Completed container: container_1377141553101_0005_01_000003 in state: COMPLETED event:FINISHED
2013-08-22 03:34:55,885 INFO org.apache.hadoop.yarn.server.resourcemanager.RMAuditLogger: USER=ubuntu	OPERATION=AM Released Container	TARGET=SchedulerApp	RESULT=SUCCESS	APPID=application_1377141553101_0005	CONTAINERID=container_1377141553101_0005_01_000003
2013-08-22 03:34:55,885 INFO org.apache.hadoop.yarn.server.resourcemanager.scheduler.common.fica.FiCaSchedulerNode: Released container container_1377141553101_0005_01_000003 of capacity <memory:1024, vCores:1> on host hadoop-998-5:56087, which currently has 0 containers, <memory:0, vCores:0> used and <memory:8192, vCores:16> available, release resources=true
2013-08-22 03:34:55,885 INFO org.apache.hadoop.yarn.server.resourcemanager.scheduler.capacity.LeafQueue: default used=<memory:2048, vCores:1> numContainers=1 user=ubuntu user-resources=<memory:2048, vCores:1>
2013-08-22 03:34:55,887 INFO org.apache.hadoop.yarn.server.resourcemanager.scheduler.capacity.LeafQueue: completedContainer container=Container: [ContainerId: container_1377141553101_0005_01_000003, NodeId: hadoop-998-5:56087, NodeHttpAddress: hadoop-998-5:8042, Resource: <memory:1024, vCores:1>, Priority: 20, State: NEW, Token: null, Status: container_id {, app_attempt_id {, application_id {, id: 5, cluster_timestamp: 1377141553101, }, attemptId: 1, }, id: 3, }, state: C_COMPLETE, diagnostics: "Container killed by the ApplicationMaster.\n\n", exit_status: 143, ] resource=<memory:1024, vCores:1> queue=default: capacity=1.0, absoluteCapacity=1.0, usedResources=<memory:2048, vCores:1>usedCapacity=0.041666668, absoluteUsedCapacity=0.041666668, numApps=1, numContainers=1 usedCapacity=0.041666668 absoluteUsedCapacity=0.041666668 used=<memory:2048, vCores:1> cluster=<memory:49152, vCores:96>
2013-08-22 03:34:55,887 INFO org.apache.hadoop.yarn.server.resourcemanager.scheduler.capacity.ParentQueue: completedContainer queue=root usedCapacity=0.041666668 absoluteUsedCapacity=0.041666668 used=<memory:2048, vCores:1> cluster=<memory:49152, vCores:96>
2013-08-22 03:34:55,887 INFO org.apache.hadoop.yarn.server.resourcemanager.scheduler.capacity.CapacityScheduler: Application appattempt_1377141553101_0005_000001 released container container_1377141553101_0005_01_000003 on node: host: hadoop-998-5:56087 #containers=0 available=8192 used=0 with event: FINISHED
2013-08-22 03:35:00,009 INFO org.apache.hadoop.yarn.server.resourcemanager.rmapp.attempt.RMAppAttemptImpl: appattempt_1377141553101_0005_000001 State change from RUNNING to FINISHING
2013-08-22 03:35:00,010 INFO org.apache.hadoop.yarn.server.resourcemanager.rmapp.RMAppImpl: application_1377141553101_0005 State change from RUNNING to FINISHING
2013-08-22 03:35:00,756 INFO org.apache.hadoop.yarn.server.resourcemanager.rmcontainer.RMContainerImpl: container_1377141553101_0005_01_000001 Container Transitioned from RUNNING to COMPLETED
2013-08-22 03:35:00,756 INFO org.apache.hadoop.yarn.server.resourcemanager.scheduler.common.fica.FiCaSchedulerApp: Completed container: container_1377141553101_0005_01_000001 in state: COMPLETED event:FINISHED
2013-08-22 03:35:00,756 INFO org.apache.hadoop.yarn.server.resourcemanager.rmapp.attempt.RMAppAttemptImpl: appattempt_1377141553101_0005_000001 State change from FINISHING to FINISHED
2013-08-22 03:35:00,756 INFO org.apache.hadoop.yarn.server.resourcemanager.RMAuditLogger: USER=ubuntu	OPERATION=AM Released Container	TARGET=SchedulerApp	RESULT=SUCCESS	APPID=application_1377141553101_0005	CONTAINERID=container_1377141553101_0005_01_000001
2013-08-22 03:35:00,757 INFO org.apache.hadoop.yarn.server.resourcemanager.rmapp.RMAppImpl: application_1377141553101_0005 State change from FINISHING to FINISHED
2013-08-22 03:35:00,757 INFO org.apache.hadoop.yarn.server.resourcemanager.scheduler.common.fica.FiCaSchedulerNode: Released container container_1377141553101_0005_01_000001 of capacity <memory:2048, vCores:1> on host hadoop-998-6:58634, which currently has 0 containers, <memory:0, vCores:0> used and <memory:8192, vCores:16> available, release resources=true
2013-08-22 03:35:00,757 INFO org.apache.hadoop.yarn.server.resourcemanager.scheduler.capacity.LeafQueue: default used=<memory:0, vCores:0> numContainers=0 user=ubuntu user-resources=<memory:0, vCores:0>
2013-08-22 03:35:00,757 INFO org.apache.hadoop.yarn.server.resourcemanager.RMAuditLogger: USER=ubuntu	OPERATION=Application Finished - Succeeded	TARGET=RMAppManager	RESULT=SUCCESS	APPID=application_1377141553101_0005
2013-08-22 03:35:00,758 INFO org.apache.hadoop.yarn.server.resourcemanager.RMAppManager$ApplicationSummary: appId=application_1377141553101_0005,name=TeraGen,user=ubuntu,queue=default,state=FINISHED,trackingUrl=hadoop-998-1.novalocal:8088/proxy/application_1377141553101_0005/jobhistory/job/job_1377141553101_0005,appMasterHost=hadoop-998-6,startTime=1377142322763,finishTime=1377142500010
2013-08-22 03:35:00,758 INFO org.apache.hadoop.yarn.server.resourcemanager.recovery.RMStateStore: Removing info for app: application_1377141553101_0005
2013-08-22 03:35:00,759 INFO org.apache.hadoop.yarn.server.resourcemanager.scheduler.capacity.LeafQueue: completedContainer container=Container: [ContainerId: container_1377141553101_0005_01_000001, NodeId: hadoop-998-6:58634, NodeHttpAddress: hadoop-998-6:8042, Resource: <memory:2048, vCores:1>, Priority: 0, State: NEW, Token: null, Status: container_id {, app_attempt_id {, application_id {, id: 5, cluster_timestamp: 1377141553101, }, attemptId: 1, }, id: 1, }, state: C_COMPLETE, diagnostics: "", exit_status: 0, ] resource=<memory:2048, vCores:1> queue=default: capacity=1.0, absoluteCapacity=1.0, usedResources=<memory:0, vCores:0>usedCapacity=0.0, absoluteUsedCapacity=0.0, numApps=1, numContainers=0 usedCapacity=0.0 absoluteUsedCapacity=0.0 used=<memory:0, vCores:0> cluster=<memory:49152, vCores:96>
2013-08-22 03:35:00,759 INFO org.apache.hadoop.yarn.server.resourcemanager.amlauncher.AMLauncher: Cleaning master appattempt_1377141553101_0005_000001
2013-08-22 03:35:00,759 INFO org.apache.hadoop.yarn.server.resourcemanager.scheduler.capacity.ParentQueue: completedContainer queue=root usedCapacity=0.0 absoluteUsedCapacity=0.0 used=<memory:0, vCores:0> cluster=<memory:49152, vCores:96>
2013-08-22 03:35:00,763 INFO org.apache.hadoop.yarn.server.resourcemanager.scheduler.capacity.CapacityScheduler: Application appattempt_1377141553101_0005_000001 released container container_1377141553101_0005_01_000001 on node: host: hadoop-998-6:58634 #containers=0 available=8192 used=0 with event: FINISHED
2013-08-22 03:35:00,763 INFO org.apache.hadoop.yarn.server.resourcemanager.scheduler.capacity.CapacityScheduler: Application appattempt_1377141553101_0005_000001 is done. finalState=FINISHED
2013-08-22 03:35:00,763 INFO org.apache.hadoop.yarn.server.resourcemanager.scheduler.AppSchedulingInfo: Application application_1377141553101_0005 requests cleared
2013-08-22 03:35:00,764 INFO org.apache.hadoop.yarn.server.resourcemanager.scheduler.capacity.LeafQueue: Application removed - appId: application_1377141553101_0005 user: ubuntu queue: default #user-pending-applications: 0 #user-active-applications: 0 #queue-pending-applications: 0 #queue-active-applications: 0
2013-08-22 03:35:00,764 INFO org.apache.hadoop.yarn.server.resourcemanager.scheduler.capacity.ParentQueue: Application removed - appId: application_1377141553101_0005 user: ubuntu leaf-queue of parent: root #applications: 0
2013-08-22 03:35:25,119 INFO org.apache.hadoop.yarn.server.resourcemanager.ClientRMService: Allocated new applicationId: 6
2013-08-22 03:35:25,144 INFO org.apache.hadoop.yarn.server.resourcemanager.ClientRMService: Allocated new applicationId: 7
2013-08-22 03:35:25,293 INFO org.apache.hadoop.yarn.server.resourcemanager.ClientRMService: Allocated new applicationId: 8
2013-08-22 03:35:25,439 INFO org.apache.hadoop.yarn.server.resourcemanager.ClientRMService: Allocated new applicationId: 9
2013-08-22 03:35:26,030 INFO org.apache.hadoop.yarn.server.resourcemanager.ClientRMService: Allocated new applicationId: 10
2013-08-22 03:35:26,927 INFO org.apache.hadoop.yarn.server.resourcemanager.ClientRMService: Storing Application with id application_1377141553101_0006
2013-08-22 03:35:26,927 INFO org.apache.hadoop.yarn.server.resourcemanager.recovery.RMStateStore: Storing info for app: application_1377141553101_0006
2013-08-22 03:35:26,927 INFO org.apache.hadoop.yarn.server.resourcemanager.ClientRMService: Application with id 6 submitted by user ubuntu
2013-08-22 03:35:26,927 INFO org.apache.hadoop.yarn.server.resourcemanager.RMAuditLogger: USER=ubuntu	IP=192.168.100.9	OPERATION=Submit Application Request	TARGET=ClientRMService	RESULT=SUCCESS	APPID=application_1377141553101_0006
2013-08-22 03:35:26,927 INFO org.apache.hadoop.yarn.server.resourcemanager.rmapp.RMAppImpl: application_1377141553101_0006 State change from NEW to SUBMITTED
2013-08-22 03:35:26,928 INFO org.apache.hadoop.yarn.server.resourcemanager.ApplicationMasterService: Registering appattempt_1377141553101_0006_000001
2013-08-22 03:35:26,928 INFO org.apache.hadoop.yarn.server.resourcemanager.rmapp.attempt.RMAppAttemptImpl: appattempt_1377141553101_0006_000001 State change from NEW to SUBMITTED
2013-08-22 03:35:26,928 INFO org.apache.hadoop.yarn.server.resourcemanager.scheduler.capacity.LeafQueue: Application application_1377141553101_0006 from user: ubuntu activated in queue: default
2013-08-22 03:35:26,928 INFO org.apache.hadoop.yarn.server.resourcemanager.scheduler.capacity.LeafQueue: Application added - appId: application_1377141553101_0006 user: org.apache.hadoop.yarn.server.resourcemanager.scheduler.capacity.LeafQueue$User@295420d2, leaf-queue: default #user-pending-applications: 0 #user-active-applications: 1 #queue-pending-applications: 0 #queue-active-applications: 1
2013-08-22 03:35:26,928 INFO org.apache.hadoop.yarn.server.resourcemanager.scheduler.capacity.ParentQueue: Application added - appId: application_1377141553101_0006 user: ubuntu leaf-queue of parent: root #applications: 1
2013-08-22 03:35:26,928 INFO org.apache.hadoop.yarn.server.resourcemanager.scheduler.capacity.CapacityScheduler: Application Submission: appattempt_1377141553101_0006_000001, user: ubuntu queue: default: capacity=1.0, absoluteCapacity=1.0, usedResources=<memory:0, vCores:0>usedCapacity=0.0, absoluteUsedCapacity=0.0, numApps=1, numContainers=0, currently active: 1
2013-08-22 03:35:26,928 INFO org.apache.hadoop.yarn.server.resourcemanager.rmapp.attempt.RMAppAttemptImpl: appattempt_1377141553101_0006_000001 State change from SUBMITTED to SCHEDULED
2013-08-22 03:35:26,929 INFO org.apache.hadoop.yarn.server.resourcemanager.rmapp.RMAppImpl: application_1377141553101_0006 State change from SUBMITTED to ACCEPTED
2013-08-22 03:35:26,951 INFO org.apache.hadoop.yarn.server.resourcemanager.ClientRMService: Storing Application with id application_1377141553101_0008
2013-08-22 03:35:26,951 INFO org.apache.hadoop.yarn.server.resourcemanager.recovery.RMStateStore: Storing info for app: application_1377141553101_0008
2013-08-22 03:35:26,951 INFO org.apache.hadoop.yarn.server.resourcemanager.ClientRMService: Application with id 8 submitted by user ubuntu
2013-08-22 03:35:26,951 INFO org.apache.hadoop.yarn.server.resourcemanager.RMAuditLogger: USER=ubuntu	IP=192.168.100.9	OPERATION=Submit Application Request	TARGET=ClientRMService	RESULT=SUCCESS	APPID=application_1377141553101_0008
2013-08-22 03:35:26,952 INFO org.apache.hadoop.yarn.server.resourcemanager.rmapp.RMAppImpl: application_1377141553101_0008 State change from NEW to SUBMITTED
2013-08-22 03:35:26,952 INFO org.apache.hadoop.yarn.server.resourcemanager.ApplicationMasterService: Registering appattempt_1377141553101_0008_000001
2013-08-22 03:35:26,952 INFO org.apache.hadoop.yarn.server.resourcemanager.rmapp.attempt.RMAppAttemptImpl: appattempt_1377141553101_0008_000001 State change from NEW to SUBMITTED
2013-08-22 03:35:26,953 INFO org.apache.hadoop.yarn.server.resourcemanager.scheduler.capacity.LeafQueue: Application application_1377141553101_0008 from user: ubuntu activated in queue: default
2013-08-22 03:35:26,954 INFO org.apache.hadoop.yarn.server.resourcemanager.scheduler.capacity.LeafQueue: Application added - appId: application_1377141553101_0008 user: org.apache.hadoop.yarn.server.resourcemanager.scheduler.capacity.LeafQueue$User@295420d2, leaf-queue: default #user-pending-applications: 0 #user-active-applications: 2 #queue-pending-applications: 0 #queue-active-applications: 2
2013-08-22 03:35:26,954 INFO org.apache.hadoop.yarn.server.resourcemanager.scheduler.capacity.ParentQueue: Application added - appId: application_1377141553101_0008 user: ubuntu leaf-queue of parent: root #applications: 2
2013-08-22 03:35:26,954 INFO org.apache.hadoop.yarn.server.resourcemanager.scheduler.capacity.CapacityScheduler: Application Submission: appattempt_1377141553101_0008_000001, user: ubuntu queue: default: capacity=1.0, absoluteCapacity=1.0, usedResources=<memory:0, vCores:0>usedCapacity=0.0, absoluteUsedCapacity=0.0, numApps=2, numContainers=0, currently active: 2
2013-08-22 03:35:26,954 INFO org.apache.hadoop.yarn.server.resourcemanager.rmapp.attempt.RMAppAttemptImpl: appattempt_1377141553101_0008_000001 State change from SUBMITTED to SCHEDULED
2013-08-22 03:35:26,954 INFO org.apache.hadoop.yarn.server.resourcemanager.rmapp.RMAppImpl: application_1377141553101_0008 State change from SUBMITTED to ACCEPTED
2013-08-22 03:35:26,995 INFO org.apache.hadoop.yarn.server.resourcemanager.ClientRMService: Storing Application with id application_1377141553101_0007
2013-08-22 03:35:26,995 INFO org.apache.hadoop.yarn.server.resourcemanager.recovery.RMStateStore: Storing info for app: application_1377141553101_0007
2013-08-22 03:35:26,995 INFO org.apache.hadoop.yarn.server.resourcemanager.ClientRMService: Application with id 7 submitted by user ubuntu
2013-08-22 03:35:26,995 INFO org.apache.hadoop.yarn.server.resourcemanager.RMAuditLogger: USER=ubuntu	IP=192.168.100.9	OPERATION=Submit Application Request	TARGET=ClientRMService	RESULT=SUCCESS	APPID=application_1377141553101_0007
2013-08-22 03:35:26,995 INFO org.apache.hadoop.yarn.server.resourcemanager.rmapp.RMAppImpl: application_1377141553101_0007 State change from NEW to SUBMITTED
2013-08-22 03:35:26,995 INFO org.apache.hadoop.yarn.server.resourcemanager.ApplicationMasterService: Registering appattempt_1377141553101_0007_000001
2013-08-22 03:35:26,995 INFO org.apache.hadoop.yarn.server.resourcemanager.rmapp.attempt.RMAppAttemptImpl: appattempt_1377141553101_0007_000001 State change from NEW to SUBMITTED
2013-08-22 03:35:26,996 INFO org.apache.hadoop.yarn.server.resourcemanager.scheduler.capacity.LeafQueue: Application application_1377141553101_0007 from user: ubuntu activated in queue: default
2013-08-22 03:35:26,996 INFO org.apache.hadoop.yarn.server.resourcemanager.scheduler.capacity.LeafQueue: Application added - appId: application_1377141553101_0007 user: org.apache.hadoop.yarn.server.resourcemanager.scheduler.capacity.LeafQueue$User@295420d2, leaf-queue: default #user-pending-applications: 0 #user-active-applications: 3 #queue-pending-applications: 0 #queue-active-applications: 3
2013-08-22 03:35:26,996 INFO org.apache.hadoop.yarn.server.resourcemanager.scheduler.capacity.ParentQueue: Application added - appId: application_1377141553101_0007 user: ubuntu leaf-queue of parent: root #applications: 3
2013-08-22 03:35:26,996 INFO org.apache.hadoop.yarn.server.resourcemanager.scheduler.capacity.CapacityScheduler: Application Submission: appattempt_1377141553101_0007_000001, user: ubuntu queue: default: capacity=1.0, absoluteCapacity=1.0, usedResources=<memory:0, vCores:0>usedCapacity=0.0, absoluteUsedCapacity=0.0, numApps=3, numContainers=0, currently active: 3
2013-08-22 03:35:26,996 INFO org.apache.hadoop.yarn.server.resourcemanager.rmapp.attempt.RMAppAttemptImpl: appattempt_1377141553101_0007_000001 State change from SUBMITTED to SCHEDULED
2013-08-22 03:35:26,997 INFO org.apache.hadoop.yarn.server.resourcemanager.rmapp.RMAppImpl: application_1377141553101_0007 State change from SUBMITTED to ACCEPTED
2013-08-22 03:35:27,009 INFO org.apache.hadoop.yarn.server.resourcemanager.rmcontainer.RMContainerImpl: container_1377141553101_0006_01_000001 Container Transitioned from NEW to ALLOCATED
2013-08-22 03:35:27,009 INFO org.apache.hadoop.yarn.server.resourcemanager.RMAuditLogger: USER=ubuntu	OPERATION=AM Allocated Container	TARGET=SchedulerApp	RESULT=SUCCESS	APPID=application_1377141553101_0006	CONTAINERID=container_1377141553101_0006_01_000001
2013-08-22 03:35:27,009 INFO org.apache.hadoop.yarn.server.resourcemanager.scheduler.common.fica.FiCaSchedulerNode: Assigned container container_1377141553101_0006_01_000001 of capacity <memory:2048, vCores:1> on host hadoop-998-5:56087, which currently has 1 containers, <memory:2048, vCores:1> used and <memory:6144, vCores:15> available
2013-08-22 03:35:27,011 INFO org.apache.hadoop.yarn.server.resourcemanager.scheduler.capacity.LeafQueue: assignedContainer application=application_1377141553101_0006 container=Container: [ContainerId: container_1377141553101_0006_01_000001, NodeId: hadoop-998-5:56087, NodeHttpAddress: hadoop-998-5:8042, Resource: <memory:2048, vCores:1>, Priority: 0, State: NEW, Token: null, Status: container_id {, app_attempt_id {, application_id {, id: 6, cluster_timestamp: 1377141553101, }, attemptId: 1, }, id: 1, }, state: C_NEW, ] containerId=container_1377141553101_0006_01_000001 queue=default: capacity=1.0, absoluteCapacity=1.0, usedResources=<memory:0, vCores:0>usedCapacity=0.0, absoluteUsedCapacity=0.0, numApps=3, numContainers=0 usedCapacity=0.0 absoluteUsedCapacity=0.0 used=<memory:0, vCores:0> cluster=<memory:49152, vCores:96>
2013-08-22 03:35:27,027 INFO org.apache.hadoop.yarn.server.resourcemanager.scheduler.capacity.ParentQueue: Re-sorting queues since queue: root.default stats: default: capacity=1.0, absoluteCapacity=1.0, usedResources=<memory:2048, vCores:1>usedCapacity=0.041666668, absoluteUsedCapacity=0.041666668, numApps=3, numContainers=1
2013-08-22 03:35:27,031 INFO org.apache.hadoop.yarn.server.resourcemanager.scheduler.capacity.ParentQueue: assignedContainer queue=root usedCapacity=0.041666668 absoluteUsedCapacity=0.041666668 used=<memory:2048, vCores:1> cluster=<memory:49152, vCores:96>
2013-08-22 03:35:27,032 INFO org.apache.hadoop.yarn.server.resourcemanager.rmcontainer.RMContainerImpl: container_1377141553101_0006_01_000001 Container Transitioned from ALLOCATED to ACQUIRED
2013-08-22 03:35:27,033 INFO org.apache.hadoop.yarn.server.resourcemanager.rmapp.attempt.RMAppAttemptImpl: Storing attempt: AppId: application_1377141553101_0006 AttemptId: appattempt_1377141553101_0006_000001 MasterContainer: Container: [ContainerId: container_1377141553101_0006_01_000001, NodeId: hadoop-998-5:56087, NodeHttpAddress: hadoop-998-5:8042, Resource: <memory:2048, vCores:1>, Priority: 0, State: NEW, Token: null, Status: container_id {, app_attempt_id {, application_id {, id: 6, cluster_timestamp: 1377141553101, }, attemptId: 1, }, id: 1, }, state: C_NEW, ]
2013-08-22 03:35:27,033 INFO org.apache.hadoop.yarn.server.resourcemanager.rmapp.attempt.RMAppAttemptImpl: appattempt_1377141553101_0006_000001 State change from SCHEDULED to ALLOCATED_SAVING
2013-08-22 03:35:27,033 INFO org.apache.hadoop.yarn.server.resourcemanager.recovery.RMStateStore: Storing info for attempt: appattempt_1377141553101_0006_000001
2013-08-22 03:35:27,034 INFO org.apache.hadoop.yarn.server.resourcemanager.rmapp.attempt.RMAppAttemptImpl: appattempt_1377141553101_0006_000001 State change from ALLOCATED_SAVING to ALLOCATED
2013-08-22 03:35:27,034 INFO org.apache.hadoop.yarn.server.resourcemanager.amlauncher.AMLauncher: Launching masterappattempt_1377141553101_0006_000001
2013-08-22 03:35:27,035 INFO org.apache.hadoop.yarn.server.resourcemanager.amlauncher.AMLauncher: Setting up container Container: [ContainerId: container_1377141553101_0006_01_000001, NodeId: hadoop-998-5:56087, NodeHttpAddress: hadoop-998-5:8042, Resource: <memory:2048, vCores:1>, Priority: 0, State: NEW, Token: null, Status: container_id {, app_attempt_id {, application_id {, id: 6, cluster_timestamp: 1377141553101, }, attemptId: 1, }, id: 1, }, state: C_NEW, ] for AM appattempt_1377141553101_0006_000001
2013-08-22 03:35:27,036 INFO org.apache.hadoop.yarn.server.resourcemanager.amlauncher.AMLauncher: Command to launch container container_1377141553101_0006_01_000001 : $JAVA_HOME/bin/java -Dlog4j.configuration=container-log4j.properties -Dyarn.app.mapreduce.container.log.dir=<LOG_DIR> -Dyarn.app.mapreduce.container.log.filesize=0 -Dhadoop.root.logger=INFO,CLA  -Xmx1024m org.apache.hadoop.mapreduce.v2.app.MRAppMaster 1><LOG_DIR>/stdout 2><LOG_DIR>/stderr 
2013-08-22 03:35:27,051 INFO org.apache.hadoop.yarn.server.resourcemanager.amlauncher.AMLauncher: Done launching container Container: [ContainerId: container_1377141553101_0006_01_000001, NodeId: hadoop-998-5:56087, NodeHttpAddress: hadoop-998-5:8042, Resource: <memory:2048, vCores:1>, Priority: 0, State: NEW, Token: null, Status: container_id {, app_attempt_id {, application_id {, id: 6, cluster_timestamp: 1377141553101, }, attemptId: 1, }, id: 1, }, state: C_NEW, ] for AM appattempt_1377141553101_0006_000001
2013-08-22 03:35:27,052 INFO org.apache.hadoop.yarn.server.resourcemanager.rmapp.attempt.RMAppAttemptImpl: appattempt_1377141553101_0006_000001 State change from ALLOCATED to LAUNCHED
2013-08-22 03:35:27,067 INFO org.apache.hadoop.yarn.server.resourcemanager.rmcontainer.RMContainerImpl: container_1377141553101_0007_01_000001 Container Transitioned from NEW to ALLOCATED
2013-08-22 03:35:27,067 INFO org.apache.hadoop.yarn.server.resourcemanager.RMAuditLogger: USER=ubuntu	OPERATION=AM Allocated Container	TARGET=SchedulerApp	RESULT=SUCCESS	APPID=application_1377141553101_0007	CONTAINERID=container_1377141553101_0007_01_000001
2013-08-22 03:35:27,068 INFO org.apache.hadoop.yarn.server.resourcemanager.scheduler.common.fica.FiCaSchedulerNode: Assigned container container_1377141553101_0007_01_000001 of capacity <memory:2048, vCores:1> on host hadoop-998-2:35081, which currently has 1 containers, <memory:2048, vCores:1> used and <memory:6144, vCores:15> available
2013-08-22 03:35:27,068 INFO org.apache.hadoop.yarn.server.resourcemanager.scheduler.capacity.LeafQueue: assignedContainer application=application_1377141553101_0007 container=Container: [ContainerId: container_1377141553101_0007_01_000001, NodeId: hadoop-998-2:35081, NodeHttpAddress: hadoop-998-2:8042, Resource: <memory:2048, vCores:1>, Priority: 0, State: NEW, Token: null, Status: container_id {, app_attempt_id {, application_id {, id: 7, cluster_timestamp: 1377141553101, }, attemptId: 1, }, id: 1, }, state: C_NEW, ] containerId=container_1377141553101_0007_01_000001 queue=default: capacity=1.0, absoluteCapacity=1.0, usedResources=<memory:2048, vCores:1>usedCapacity=0.041666668, absoluteUsedCapacity=0.041666668, numApps=3, numContainers=1 usedCapacity=0.041666668 absoluteUsedCapacity=0.041666668 used=<memory:2048, vCores:1> cluster=<memory:49152, vCores:96>
2013-08-22 03:35:27,069 INFO org.apache.hadoop.yarn.server.resourcemanager.scheduler.capacity.ParentQueue: Re-sorting queues since queue: root.default stats: default: capacity=1.0, absoluteCapacity=1.0, usedResources=<memory:4096, vCores:2>usedCapacity=0.083333336, absoluteUsedCapacity=0.083333336, numApps=3, numContainers=2
2013-08-22 03:35:27,069 INFO org.apache.hadoop.yarn.server.resourcemanager.scheduler.capacity.ParentQueue: assignedContainer queue=root usedCapacity=0.083333336 absoluteUsedCapacity=0.083333336 used=<memory:4096, vCores:2> cluster=<memory:49152, vCores:96>
2013-08-22 03:35:27,069 INFO org.apache.hadoop.yarn.server.resourcemanager.rmcontainer.RMContainerImpl: container_1377141553101_0007_01_000001 Container Transitioned from ALLOCATED to ACQUIRED
2013-08-22 03:35:27,070 INFO org.apache.hadoop.yarn.server.resourcemanager.rmapp.attempt.RMAppAttemptImpl: Storing attempt: AppId: application_1377141553101_0007 AttemptId: appattempt_1377141553101_0007_000001 MasterContainer: Container: [ContainerId: container_1377141553101_0007_01_000001, NodeId: hadoop-998-2:35081, NodeHttpAddress: hadoop-998-2:8042, Resource: <memory:2048, vCores:1>, Priority: 0, State: NEW, Token: null, Status: container_id {, app_attempt_id {, application_id {, id: 7, cluster_timestamp: 1377141553101, }, attemptId: 1, }, id: 1, }, state: C_NEW, ]
2013-08-22 03:35:27,070 INFO org.apache.hadoop.yarn.server.resourcemanager.rmapp.attempt.RMAppAttemptImpl: appattempt_1377141553101_0007_000001 State change from SCHEDULED to ALLOCATED_SAVING
2013-08-22 03:35:27,070 INFO org.apache.hadoop.yarn.server.resourcemanager.recovery.RMStateStore: Storing info for attempt: appattempt_1377141553101_0007_000001
2013-08-22 03:35:27,070 INFO org.apache.hadoop.yarn.server.resourcemanager.rmapp.attempt.RMAppAttemptImpl: appattempt_1377141553101_0007_000001 State change from ALLOCATED_SAVING to ALLOCATED
2013-08-22 03:35:27,071 INFO org.apache.hadoop.yarn.server.resourcemanager.amlauncher.AMLauncher: Launching masterappattempt_1377141553101_0007_000001
2013-08-22 03:35:27,072 INFO org.apache.hadoop.yarn.server.resourcemanager.amlauncher.AMLauncher: Setting up container Container: [ContainerId: container_1377141553101_0007_01_000001, NodeId: hadoop-998-2:35081, NodeHttpAddress: hadoop-998-2:8042, Resource: <memory:2048, vCores:1>, Priority: 0, State: NEW, Token: null, Status: container_id {, app_attempt_id {, application_id {, id: 7, cluster_timestamp: 1377141553101, }, attemptId: 1, }, id: 1, }, state: C_NEW, ] for AM appattempt_1377141553101_0007_000001
2013-08-22 03:35:27,073 INFO org.apache.hadoop.yarn.server.resourcemanager.amlauncher.AMLauncher: Command to launch container container_1377141553101_0007_01_000001 : $JAVA_HOME/bin/java -Dlog4j.configuration=container-log4j.properties -Dyarn.app.mapreduce.container.log.dir=<LOG_DIR> -Dyarn.app.mapreduce.container.log.filesize=0 -Dhadoop.root.logger=INFO,CLA  -Xmx1024m org.apache.hadoop.mapreduce.v2.app.MRAppMaster 1><LOG_DIR>/stdout 2><LOG_DIR>/stderr 
2013-08-22 03:35:27,084 INFO org.apache.hadoop.yarn.server.resourcemanager.ClientRMService: Storing Application with id application_1377141553101_0009
2013-08-22 03:35:27,084 INFO org.apache.hadoop.yarn.server.resourcemanager.recovery.RMStateStore: Storing info for app: application_1377141553101_0009
2013-08-22 03:35:27,084 INFO org.apache.hadoop.yarn.server.resourcemanager.ClientRMService: Application with id 9 submitted by user ubuntu
2013-08-22 03:35:27,084 INFO org.apache.hadoop.yarn.server.resourcemanager.RMAuditLogger: USER=ubuntu	IP=192.168.100.9	OPERATION=Submit Application Request	TARGET=ClientRMService	RESULT=SUCCESS	APPID=application_1377141553101_0009
2013-08-22 03:35:27,085 INFO org.apache.hadoop.yarn.server.resourcemanager.rmapp.RMAppImpl: application_1377141553101_0009 State change from NEW to SUBMITTED
2013-08-22 03:35:27,085 INFO org.apache.hadoop.yarn.server.resourcemanager.ApplicationMasterService: Registering appattempt_1377141553101_0009_000001
2013-08-22 03:35:27,086 INFO org.apache.hadoop.yarn.server.resourcemanager.rmapp.attempt.RMAppAttemptImpl: appattempt_1377141553101_0009_000001 State change from NEW to SUBMITTED
2013-08-22 03:35:27,086 INFO org.apache.hadoop.yarn.server.resourcemanager.scheduler.capacity.LeafQueue: Application application_1377141553101_0009 from user: ubuntu activated in queue: default
2013-08-22 03:35:27,086 INFO org.apache.hadoop.yarn.server.resourcemanager.scheduler.capacity.LeafQueue: Application added - appId: application_1377141553101_0009 user: org.apache.hadoop.yarn.server.resourcemanager.scheduler.capacity.LeafQueue$User@295420d2, leaf-queue: default #user-pending-applications: 0 #user-active-applications: 4 #queue-pending-applications: 0 #queue-active-applications: 4
2013-08-22 03:35:27,086 INFO org.apache.hadoop.yarn.server.resourcemanager.scheduler.capacity.ParentQueue: Application added - appId: application_1377141553101_0009 user: ubuntu leaf-queue of parent: root #applications: 4
2013-08-22 03:35:27,086 INFO org.apache.hadoop.yarn.server.resourcemanager.scheduler.capacity.CapacityScheduler: Application Submission: appattempt_1377141553101_0009_000001, user: ubuntu queue: default: capacity=1.0, absoluteCapacity=1.0, usedResources=<memory:4096, vCores:2>usedCapacity=0.083333336, absoluteUsedCapacity=0.083333336, numApps=4, numContainers=2, currently active: 4
2013-08-22 03:35:27,086 INFO org.apache.hadoop.yarn.server.resourcemanager.rmapp.attempt.RMAppAttemptImpl: appattempt_1377141553101_0009_000001 State change from SUBMITTED to SCHEDULED
2013-08-22 03:35:27,086 INFO org.apache.hadoop.yarn.server.resourcemanager.rmapp.RMAppImpl: application_1377141553101_0009 State change from SUBMITTED to ACCEPTED
2013-08-22 03:35:27,089 INFO org.apache.hadoop.yarn.server.resourcemanager.amlauncher.AMLauncher: Done launching container Container: [ContainerId: container_1377141553101_0007_01_000001, NodeId: hadoop-998-2:35081, NodeHttpAddress: hadoop-998-2:8042, Resource: <memory:2048, vCores:1>, Priority: 0, State: NEW, Token: null, Status: container_id {, app_attempt_id {, application_id {, id: 7, cluster_timestamp: 1377141553101, }, attemptId: 1, }, id: 1, }, state: C_NEW, ] for AM appattempt_1377141553101_0007_000001
2013-08-22 03:35:27,089 INFO org.apache.hadoop.yarn.server.resourcemanager.rmapp.attempt.RMAppAttemptImpl: appattempt_1377141553101_0007_000001 State change from ALLOCATED to LAUNCHED
2013-08-22 03:35:27,345 INFO org.apache.hadoop.yarn.server.resourcemanager.rmcontainer.RMContainerImpl: container_1377141553101_0008_01_000001 Container Transitioned from NEW to ALLOCATED
2013-08-22 03:35:27,347 INFO org.apache.hadoop.yarn.server.resourcemanager.RMAuditLogger: USER=ubuntu	OPERATION=AM Allocated Container	TARGET=SchedulerApp	RESULT=SUCCESS	APPID=application_1377141553101_0008	CONTAINERID=container_1377141553101_0008_01_000001
2013-08-22 03:35:27,347 INFO org.apache.hadoop.yarn.server.resourcemanager.scheduler.common.fica.FiCaSchedulerNode: Assigned container container_1377141553101_0008_01_000001 of capacity <memory:2048, vCores:1> on host hadoop-998-3:53776, which currently has 1 containers, <memory:2048, vCores:1> used and <memory:6144, vCores:15> available
2013-08-22 03:35:27,348 INFO org.apache.hadoop.yarn.server.resourcemanager.scheduler.capacity.LeafQueue: assignedContainer application=application_1377141553101_0008 container=Container: [ContainerId: container_1377141553101_0008_01_000001, NodeId: hadoop-998-3:53776, NodeHttpAddress: hadoop-998-3:8042, Resource: <memory:2048, vCores:1>, Priority: 0, State: NEW, Token: null, Status: container_id {, app_attempt_id {, application_id {, id: 8, cluster_timestamp: 1377141553101, }, attemptId: 1, }, id: 1, }, state: C_NEW, ] containerId=container_1377141553101_0008_01_000001 queue=default: capacity=1.0, absoluteCapacity=1.0, usedResources=<memory:4096, vCores:2>usedCapacity=0.083333336, absoluteUsedCapacity=0.083333336, numApps=4, numContainers=2 usedCapacity=0.083333336 absoluteUsedCapacity=0.083333336 used=<memory:4096, vCores:2> cluster=<memory:49152, vCores:96>
2013-08-22 03:35:27,349 INFO org.apache.hadoop.yarn.server.resourcemanager.scheduler.capacity.ParentQueue: Re-sorting queues since queue: root.default stats: default: capacity=1.0, absoluteCapacity=1.0, usedResources=<memory:6144, vCores:3>usedCapacity=0.125, absoluteUsedCapacity=0.125, numApps=4, numContainers=3
2013-08-22 03:35:27,350 INFO org.apache.hadoop.yarn.server.resourcemanager.rmcontainer.RMContainerImpl: container_1377141553101_0008_01_000001 Container Transitioned from ALLOCATED to ACQUIRED
2013-08-22 03:35:27,352 INFO org.apache.hadoop.yarn.server.resourcemanager.rmapp.attempt.RMAppAttemptImpl: Storing attempt: AppId: application_1377141553101_0008 AttemptId: appattempt_1377141553101_0008_000001 MasterContainer: Container: [ContainerId: container_1377141553101_0008_01_000001, NodeId: hadoop-998-3:53776, NodeHttpAddress: hadoop-998-3:8042, Resource: <memory:2048, vCores:1>, Priority: 0, State: NEW, Token: null, Status: container_id {, app_attempt_id {, application_id {, id: 8, cluster_timestamp: 1377141553101, }, attemptId: 1, }, id: 1, }, state: C_NEW, ]
2013-08-22 03:35:27,352 INFO org.apache.hadoop.yarn.server.resourcemanager.rmapp.attempt.RMAppAttemptImpl: appattempt_1377141553101_0008_000001 State change from SCHEDULED to ALLOCATED_SAVING
2013-08-22 03:35:27,353 INFO org.apache.hadoop.yarn.server.resourcemanager.recovery.RMStateStore: Storing info for attempt: appattempt_1377141553101_0008_000001
2013-08-22 03:35:27,353 INFO org.apache.hadoop.yarn.server.resourcemanager.scheduler.capacity.ParentQueue: assignedContainer queue=root usedCapacity=0.125 absoluteUsedCapacity=0.125 used=<memory:6144, vCores:3> cluster=<memory:49152, vCores:96>
2013-08-22 03:35:27,354 INFO org.apache.hadoop.yarn.server.resourcemanager.rmapp.attempt.RMAppAttemptImpl: appattempt_1377141553101_0008_000001 State change from ALLOCATED_SAVING to ALLOCATED
2013-08-22 03:35:27,354 INFO org.apache.hadoop.yarn.server.resourcemanager.amlauncher.AMLauncher: Launching masterappattempt_1377141553101_0008_000001
2013-08-22 03:35:27,357 INFO org.apache.hadoop.yarn.server.resourcemanager.amlauncher.AMLauncher: Setting up container Container: [ContainerId: container_1377141553101_0008_01_000001, NodeId: hadoop-998-3:53776, NodeHttpAddress: hadoop-998-3:8042, Resource: <memory:2048, vCores:1>, Priority: 0, State: NEW, Token: null, Status: container_id {, app_attempt_id {, application_id {, id: 8, cluster_timestamp: 1377141553101, }, attemptId: 1, }, id: 1, }, state: C_NEW, ] for AM appattempt_1377141553101_0008_000001
2013-08-22 03:35:27,357 INFO org.apache.hadoop.yarn.server.resourcemanager.amlauncher.AMLauncher: Command to launch container container_1377141553101_0008_01_000001 : $JAVA_HOME/bin/java -Dlog4j.configuration=container-log4j.properties -Dyarn.app.mapreduce.container.log.dir=<LOG_DIR> -Dyarn.app.mapreduce.container.log.filesize=0 -Dhadoop.root.logger=INFO,CLA  -Xmx1024m org.apache.hadoop.mapreduce.v2.app.MRAppMaster 1><LOG_DIR>/stdout 2><LOG_DIR>/stderr 
2013-08-22 03:35:27,402 INFO org.apache.hadoop.yarn.server.resourcemanager.rmcontainer.RMContainerImpl: container_1377141553101_0009_01_000001 Container Transitioned from NEW to ALLOCATED
2013-08-22 03:35:27,402 INFO org.apache.hadoop.yarn.server.resourcemanager.RMAuditLogger: USER=ubuntu	OPERATION=AM Allocated Container	TARGET=SchedulerApp	RESULT=SUCCESS	APPID=application_1377141553101_0009	CONTAINERID=container_1377141553101_0009_01_000001
2013-08-22 03:35:27,402 INFO org.apache.hadoop.yarn.server.resourcemanager.scheduler.common.fica.FiCaSchedulerNode: Assigned container container_1377141553101_0009_01_000001 of capacity <memory:2048, vCores:1> on host hadoop-998-4:35553, which currently has 1 containers, <memory:2048, vCores:1> used and <memory:6144, vCores:15> available
2013-08-22 03:35:27,403 INFO org.apache.hadoop.yarn.server.resourcemanager.scheduler.capacity.LeafQueue: assignedContainer application=application_1377141553101_0009 container=Container: [ContainerId: container_1377141553101_0009_01_000001, NodeId: hadoop-998-4:35553, NodeHttpAddress: hadoop-998-4:8042, Resource: <memory:2048, vCores:1>, Priority: 0, State: NEW, Token: null, Status: container_id {, app_attempt_id {, application_id {, id: 9, cluster_timestamp: 1377141553101, }, attemptId: 1, }, id: 1, }, state: C_NEW, ] containerId=container_1377141553101_0009_01_000001 queue=default: capacity=1.0, absoluteCapacity=1.0, usedResources=<memory:6144, vCores:3>usedCapacity=0.125, absoluteUsedCapacity=0.125, numApps=4, numContainers=3 usedCapacity=0.125 absoluteUsedCapacity=0.125 used=<memory:6144, vCores:3> cluster=<memory:49152, vCores:96>
2013-08-22 03:35:27,404 INFO org.apache.hadoop.yarn.server.resourcemanager.scheduler.capacity.ParentQueue: Re-sorting queues since queue: root.default stats: default: capacity=1.0, absoluteCapacity=1.0, usedResources=<memory:8192, vCores:4>usedCapacity=0.16666667, absoluteUsedCapacity=0.16666667, numApps=4, numContainers=4
2013-08-22 03:35:27,405 INFO org.apache.hadoop.yarn.server.resourcemanager.rmcontainer.RMContainerImpl: container_1377141553101_0009_01_000001 Container Transitioned from ALLOCATED to ACQUIRED
2013-08-22 03:35:27,407 INFO org.apache.hadoop.yarn.server.resourcemanager.scheduler.capacity.ParentQueue: assignedContainer queue=root usedCapacity=0.16666667 absoluteUsedCapacity=0.16666667 used=<memory:8192, vCores:4> cluster=<memory:49152, vCores:96>
2013-08-22 03:35:27,407 INFO org.apache.hadoop.yarn.server.resourcemanager.rmapp.attempt.RMAppAttemptImpl: Storing attempt: AppId: application_1377141553101_0009 AttemptId: appattempt_1377141553101_0009_000001 MasterContainer: Container: [ContainerId: container_1377141553101_0009_01_000001, NodeId: hadoop-998-4:35553, NodeHttpAddress: hadoop-998-4:8042, Resource: <memory:2048, vCores:1>, Priority: 0, State: NEW, Token: null, Status: container_id {, app_attempt_id {, application_id {, id: 9, cluster_timestamp: 1377141553101, }, attemptId: 1, }, id: 1, }, state: C_NEW, ]
2013-08-22 03:35:27,408 INFO org.apache.hadoop.yarn.server.resourcemanager.recovery.RMStateStore: Storing info for attempt: appattempt_1377141553101_0009_000001
2013-08-22 03:35:27,408 INFO org.apache.hadoop.yarn.server.resourcemanager.rmapp.attempt.RMAppAttemptImpl: appattempt_1377141553101_0009_000001 State change from SCHEDULED to ALLOCATED_SAVING
2013-08-22 03:35:27,408 INFO org.apache.hadoop.yarn.server.resourcemanager.rmapp.attempt.RMAppAttemptImpl: appattempt_1377141553101_0009_000001 State change from ALLOCATED_SAVING to ALLOCATED
2013-08-22 03:35:27,409 INFO org.apache.hadoop.yarn.server.resourcemanager.amlauncher.AMLauncher: Launching masterappattempt_1377141553101_0009_000001
2013-08-22 03:35:27,411 INFO org.apache.hadoop.yarn.server.resourcemanager.amlauncher.AMLauncher: Setting up container Container: [ContainerId: container_1377141553101_0009_01_000001, NodeId: hadoop-998-4:35553, NodeHttpAddress: hadoop-998-4:8042, Resource: <memory:2048, vCores:1>, Priority: 0, State: NEW, Token: null, Status: container_id {, app_attempt_id {, application_id {, id: 9, cluster_timestamp: 1377141553101, }, attemptId: 1, }, id: 1, }, state: C_NEW, ] for AM appattempt_1377141553101_0009_000001
2013-08-22 03:35:27,412 INFO org.apache.hadoop.yarn.server.resourcemanager.amlauncher.AMLauncher: Command to launch container container_1377141553101_0009_01_000001 : $JAVA_HOME/bin/java -Dlog4j.configuration=container-log4j.properties -Dyarn.app.mapreduce.container.log.dir=<LOG_DIR> -Dyarn.app.mapreduce.container.log.filesize=0 -Dhadoop.root.logger=INFO,CLA  -Xmx1024m org.apache.hadoop.mapreduce.v2.app.MRAppMaster 1><LOG_DIR>/stdout 2><LOG_DIR>/stderr 
2013-08-22 03:35:27,709 INFO org.apache.hadoop.yarn.server.resourcemanager.ClientRMService: Storing Application with id application_1377141553101_0010
2013-08-22 03:35:27,709 INFO org.apache.hadoop.yarn.server.resourcemanager.recovery.RMStateStore: Storing info for app: application_1377141553101_0010
2013-08-22 03:35:27,709 INFO org.apache.hadoop.yarn.server.resourcemanager.ClientRMService: Application with id 10 submitted by user ubuntu
2013-08-22 03:35:27,709 INFO org.apache.hadoop.yarn.server.resourcemanager.RMAuditLogger: USER=ubuntu	IP=192.168.100.9	OPERATION=Submit Application Request	TARGET=ClientRMService	RESULT=SUCCESS	APPID=application_1377141553101_0010
2013-08-22 03:35:27,710 INFO org.apache.hadoop.yarn.server.resourcemanager.rmapp.RMAppImpl: application_1377141553101_0010 State change from NEW to SUBMITTED
2013-08-22 03:35:27,711 INFO org.apache.hadoop.yarn.server.resourcemanager.ApplicationMasterService: Registering appattempt_1377141553101_0010_000001
2013-08-22 03:35:27,711 INFO org.apache.hadoop.yarn.server.resourcemanager.rmapp.attempt.RMAppAttemptImpl: appattempt_1377141553101_0010_000001 State change from NEW to SUBMITTED
2013-08-22 03:35:27,712 INFO org.apache.hadoop.yarn.server.resourcemanager.scheduler.capacity.LeafQueue: Application application_1377141553101_0010 from user: ubuntu activated in queue: default
2013-08-22 03:35:27,712 INFO org.apache.hadoop.yarn.server.resourcemanager.scheduler.capacity.LeafQueue: Application added - appId: application_1377141553101_0010 user: org.apache.hadoop.yarn.server.resourcemanager.scheduler.capacity.LeafQueue$User@295420d2, leaf-queue: default #user-pending-applications: 0 #user-active-applications: 5 #queue-pending-applications: 0 #queue-active-applications: 5
2013-08-22 03:35:27,712 INFO org.apache.hadoop.yarn.server.resourcemanager.scheduler.capacity.ParentQueue: Application added - appId: application_1377141553101_0010 user: ubuntu leaf-queue of parent: root #applications: 5
2013-08-22 03:35:27,712 INFO org.apache.hadoop.yarn.server.resourcemanager.scheduler.capacity.CapacityScheduler: Application Submission: appattempt_1377141553101_0010_000001, user: ubuntu queue: default: capacity=1.0, absoluteCapacity=1.0, usedResources=<memory:8192, vCores:4>usedCapacity=0.16666667, absoluteUsedCapacity=0.16666667, numApps=5, numContainers=4, currently active: 5
2013-08-22 03:35:27,713 INFO org.apache.hadoop.yarn.server.resourcemanager.rmapp.attempt.RMAppAttemptImpl: appattempt_1377141553101_0010_000001 State change from SUBMITTED to SCHEDULED
2013-08-22 03:35:27,713 INFO org.apache.hadoop.yarn.server.resourcemanager.rmapp.RMAppImpl: application_1377141553101_0010 State change from SUBMITTED to ACCEPTED
2013-08-22 03:35:27,801 INFO org.apache.hadoop.yarn.server.resourcemanager.rmcontainer.RMContainerImpl: container_1377141553101_0010_01_000001 Container Transitioned from NEW to ALLOCATED
2013-08-22 03:35:27,802 INFO org.apache.hadoop.yarn.server.resourcemanager.RMAuditLogger: USER=ubuntu	OPERATION=AM Allocated Container	TARGET=SchedulerApp	RESULT=SUCCESS	APPID=application_1377141553101_0010	CONTAINERID=container_1377141553101_0010_01_000001
2013-08-22 03:35:27,802 INFO org.apache.hadoop.yarn.server.resourcemanager.scheduler.common.fica.FiCaSchedulerNode: Assigned container container_1377141553101_0010_01_000001 of capacity <memory:2048, vCores:1> on host hadoop-998-7:60905, which currently has 1 containers, <memory:2048, vCores:1> used and <memory:6144, vCores:15> available
2013-08-22 03:35:27,803 INFO org.apache.hadoop.yarn.server.resourcemanager.scheduler.capacity.LeafQueue: assignedContainer application=application_1377141553101_0010 container=Container: [ContainerId: container_1377141553101_0010_01_000001, NodeId: hadoop-998-7:60905, NodeHttpAddress: hadoop-998-7:8042, Resource: <memory:2048, vCores:1>, Priority: 0, State: NEW, Token: null, Status: container_id {, app_attempt_id {, application_id {, id: 10, cluster_timestamp: 1377141553101, }, attemptId: 1, }, id: 1, }, state: C_NEW, ] containerId=container_1377141553101_0010_01_000001 queue=default: capacity=1.0, absoluteCapacity=1.0, usedResources=<memory:8192, vCores:4>usedCapacity=0.16666667, absoluteUsedCapacity=0.16666667, numApps=5, numContainers=4 usedCapacity=0.16666667 absoluteUsedCapacity=0.16666667 used=<memory:8192, vCores:4> cluster=<memory:49152, vCores:96>
2013-08-22 03:35:27,804 INFO org.apache.hadoop.yarn.server.resourcemanager.scheduler.capacity.ParentQueue: Re-sorting queues since queue: root.default stats: default: capacity=1.0, absoluteCapacity=1.0, usedResources=<memory:10240, vCores:5>usedCapacity=0.20833333, absoluteUsedCapacity=0.20833333, numApps=5, numContainers=5
2013-08-22 03:35:27,805 INFO org.apache.hadoop.yarn.server.resourcemanager.scheduler.capacity.ParentQueue: assignedContainer queue=root usedCapacity=0.20833333 absoluteUsedCapacity=0.20833333 used=<memory:10240, vCores:5> cluster=<memory:49152, vCores:96>
2013-08-22 03:35:27,805 INFO org.apache.hadoop.yarn.server.resourcemanager.rmcontainer.RMContainerImpl: container_1377141553101_0010_01_000001 Container Transitioned from ALLOCATED to ACQUIRED
2013-08-22 03:35:27,806 INFO org.apache.hadoop.yarn.server.resourcemanager.rmapp.attempt.RMAppAttemptImpl: Storing attempt: AppId: application_1377141553101_0010 AttemptId: appattempt_1377141553101_0010_000001 MasterContainer: Container: [ContainerId: container_1377141553101_0010_01_000001, NodeId: hadoop-998-7:60905, NodeHttpAddress: hadoop-998-7:8042, Resource: <memory:2048, vCores:1>, Priority: 0, State: NEW, Token: null, Status: container_id {, app_attempt_id {, application_id {, id: 10, cluster_timestamp: 1377141553101, }, attemptId: 1, }, id: 1, }, state: C_NEW, ]
2013-08-22 03:35:27,807 INFO org.apache.hadoop.yarn.server.resourcemanager.recovery.RMStateStore: Storing info for attempt: appattempt_1377141553101_0010_000001
2013-08-22 03:35:27,807 INFO org.apache.hadoop.yarn.server.resourcemanager.rmapp.attempt.RMAppAttemptImpl: appattempt_1377141553101_0010_000001 State change from SCHEDULED to ALLOCATED_SAVING
2013-08-22 03:35:27,809 INFO org.apache.hadoop.yarn.server.resourcemanager.rmapp.attempt.RMAppAttemptImpl: appattempt_1377141553101_0010_000001 State change from ALLOCATED_SAVING to ALLOCATED
2013-08-22 03:35:27,809 INFO org.apache.hadoop.yarn.server.resourcemanager.amlauncher.AMLauncher: Launching masterappattempt_1377141553101_0010_000001
2013-08-22 03:35:27,812 INFO org.apache.hadoop.yarn.server.resourcemanager.amlauncher.AMLauncher: Setting up container Container: [ContainerId: container_1377141553101_0010_01_000001, NodeId: hadoop-998-7:60905, NodeHttpAddress: hadoop-998-7:8042, Resource: <memory:2048, vCores:1>, Priority: 0, State: NEW, Token: null, Status: container_id {, app_attempt_id {, application_id {, id: 10, cluster_timestamp: 1377141553101, }, attemptId: 1, }, id: 1, }, state: C_NEW, ] for AM appattempt_1377141553101_0010_000001
2013-08-22 03:35:27,812 INFO org.apache.hadoop.yarn.server.resourcemanager.amlauncher.AMLauncher: Command to launch container container_1377141553101_0010_01_000001 : $JAVA_HOME/bin/java -Dlog4j.configuration=container-log4j.properties -Dyarn.app.mapreduce.container.log.dir=<LOG_DIR> -Dyarn.app.mapreduce.container.log.filesize=0 -Dhadoop.root.logger=INFO,CLA  -Xmx1024m org.apache.hadoop.mapreduce.v2.app.MRAppMaster 1><LOG_DIR>/stdout 2><LOG_DIR>/stderr 
2013-08-22 03:35:27,825 INFO org.apache.hadoop.yarn.server.resourcemanager.amlauncher.AMLauncher: Done launching container Container: [ContainerId: container_1377141553101_0010_01_000001, NodeId: hadoop-998-7:60905, NodeHttpAddress: hadoop-998-7:8042, Resource: <memory:2048, vCores:1>, Priority: 0, State: NEW, Token: null, Status: container_id {, app_attempt_id {, application_id {, id: 10, cluster_timestamp: 1377141553101, }, attemptId: 1, }, id: 1, }, state: C_NEW, ] for AM appattempt_1377141553101_0010_000001
2013-08-22 03:35:27,825 INFO org.apache.hadoop.yarn.server.resourcemanager.rmapp.attempt.RMAppAttemptImpl: appattempt_1377141553101_0010_000001 State change from ALLOCATED to LAUNCHED
2013-08-22 03:35:28,013 INFO org.apache.hadoop.yarn.server.resourcemanager.rmcontainer.RMContainerImpl: container_1377141553101_0006_01_000001 Container Transitioned from ACQUIRED to RUNNING
2013-08-22 03:35:28,073 INFO org.apache.hadoop.yarn.server.resourcemanager.rmcontainer.RMContainerImpl: container_1377141553101_0007_01_000001 Container Transitioned from ACQUIRED to RUNNING
2013-08-22 03:35:28,277 INFO org.apache.hadoop.yarn.server.resourcemanager.amlauncher.AMLauncher: Done launching container Container: [ContainerId: container_1377141553101_0009_01_000001, NodeId: hadoop-998-4:35553, NodeHttpAddress: hadoop-998-4:8042, Resource: <memory:2048, vCores:1>, Priority: 0, State: NEW, Token: null, Status: container_id {, app_attempt_id {, application_id {, id: 9, cluster_timestamp: 1377141553101, }, attemptId: 1, }, id: 1, }, state: C_NEW, ] for AM appattempt_1377141553101_0009_000001
2013-08-22 03:35:28,278 INFO org.apache.hadoop.yarn.server.resourcemanager.rmapp.attempt.RMAppAttemptImpl: appattempt_1377141553101_0009_000001 State change from ALLOCATED to LAUNCHED
2013-08-22 03:35:28,359 INFO org.apache.hadoop.yarn.server.resourcemanager.amlauncher.AMLauncher: Done launching container Container: [ContainerId: container_1377141553101_0008_01_000001, NodeId: hadoop-998-3:53776, NodeHttpAddress: hadoop-998-3:8042, Resource: <memory:2048, vCores:1>, Priority: 0, State: NEW, Token: null, Status: container_id {, app_attempt_id {, application_id {, id: 8, cluster_timestamp: 1377141553101, }, attemptId: 1, }, id: 1, }, state: C_NEW, ] for AM appattempt_1377141553101_0008_000001
2013-08-22 03:35:28,360 INFO org.apache.hadoop.yarn.server.resourcemanager.rmapp.attempt.RMAppAttemptImpl: appattempt_1377141553101_0008_000001 State change from ALLOCATED to LAUNCHED
2013-08-22 03:35:28,373 INFO org.apache.hadoop.yarn.server.resourcemanager.rmcontainer.RMContainerImpl: container_1377141553101_0008_01_000001 Container Transitioned from ACQUIRED to RUNNING
2013-08-22 03:35:28,496 INFO org.apache.hadoop.yarn.server.resourcemanager.rmcontainer.RMContainerImpl: container_1377141553101_0009_01_000001 Container Transitioned from ACQUIRED to RUNNING
2013-08-22 03:35:28,810 INFO org.apache.hadoop.yarn.server.resourcemanager.rmcontainer.RMContainerImpl: container_1377141553101_0010_01_000001 Container Transitioned from ACQUIRED to RUNNING
2013-08-22 03:35:34,510 INFO org.apache.hadoop.yarn.server.resourcemanager.ApplicationMasterService: AM registration appattempt_1377141553101_0006_000001
2013-08-22 03:35:34,510 INFO org.apache.hadoop.yarn.server.resourcemanager.RMAuditLogger: USER=ubuntu	IP=192.168.100.15	OPERATION=Register App Master	TARGET=ApplicationMasterService	RESULT=SUCCESS	APPID=application_1377141553101_0006	APPATTEMPTID=appattempt_1377141553101_0006_000001
2013-08-22 03:35:34,513 INFO org.apache.hadoop.yarn.server.resourcemanager.rmapp.attempt.RMAppAttemptImpl: appattempt_1377141553101_0006_000001 State change from LAUNCHED to RUNNING
2013-08-22 03:35:34,514 INFO org.apache.hadoop.yarn.server.resourcemanager.rmapp.RMAppImpl: application_1377141553101_0006 State change from ACCEPTED to RUNNING
2013-08-22 03:35:35,104 INFO org.apache.hadoop.yarn.server.resourcemanager.ApplicationMasterService: AM registration appattempt_1377141553101_0010_000001
2013-08-22 03:35:35,104 INFO org.apache.hadoop.yarn.server.resourcemanager.RMAuditLogger: USER=ubuntu	IP=192.168.100.13	OPERATION=Register App Master	TARGET=ApplicationMasterService	RESULT=SUCCESS	APPID=application_1377141553101_0010	APPATTEMPTID=appattempt_1377141553101_0010_000001
2013-08-22 03:35:35,105 INFO org.apache.hadoop.yarn.server.resourcemanager.rmapp.attempt.RMAppAttemptImpl: appattempt_1377141553101_0010_000001 State change from LAUNCHED to RUNNING
2013-08-22 03:35:35,105 INFO org.apache.hadoop.yarn.server.resourcemanager.rmapp.RMAppImpl: application_1377141553101_0010 State change from ACCEPTED to RUNNING
2013-08-22 03:35:35,751 INFO org.apache.hadoop.yarn.server.resourcemanager.rmcontainer.RMContainerImpl: container_1377141553101_0006_01_000002 Container Transitioned from NEW to ALLOCATED
2013-08-22 03:35:35,751 INFO org.apache.hadoop.yarn.server.resourcemanager.RMAuditLogger: USER=ubuntu	OPERATION=AM Allocated Container	TARGET=SchedulerApp	RESULT=SUCCESS	APPID=application_1377141553101_0006	CONTAINERID=container_1377141553101_0006_01_000002
2013-08-22 03:35:35,751 INFO org.apache.hadoop.yarn.server.resourcemanager.scheduler.common.fica.FiCaSchedulerNode: Assigned container container_1377141553101_0006_01_000002 of capacity <memory:1024, vCores:1> on host hadoop-998-2:35081, which currently has 2 containers, <memory:3072, vCores:2> used and <memory:5120, vCores:14> available
2013-08-22 03:35:35,753 INFO org.apache.hadoop.yarn.server.resourcemanager.scheduler.capacity.LeafQueue: assignedContainer application=application_1377141553101_0006 container=Container: [ContainerId: container_1377141553101_0006_01_000002, NodeId: hadoop-998-2:35081, NodeHttpAddress: hadoop-998-2:8042, Resource: <memory:1024, vCores:1>, Priority: 20, State: NEW, Token: null, Status: container_id {, app_attempt_id {, application_id {, id: 6, cluster_timestamp: 1377141553101, }, attemptId: 1, }, id: 2, }, state: C_NEW, ] containerId=container_1377141553101_0006_01_000002 queue=default: capacity=1.0, absoluteCapacity=1.0, usedResources=<memory:10240, vCores:5>usedCapacity=0.20833333, absoluteUsedCapacity=0.20833333, numApps=5, numContainers=5 usedCapacity=0.20833333 absoluteUsedCapacity=0.20833333 used=<memory:10240, vCores:5> cluster=<memory:49152, vCores:96>
2013-08-22 03:35:35,753 INFO org.apache.hadoop.yarn.server.resourcemanager.scheduler.capacity.ParentQueue: Re-sorting queues since queue: root.default stats: default: capacity=1.0, absoluteCapacity=1.0, usedResources=<memory:11264, vCores:6>usedCapacity=0.22916667, absoluteUsedCapacity=0.22916667, numApps=5, numContainers=6
2013-08-22 03:35:35,753 INFO org.apache.hadoop.yarn.server.resourcemanager.scheduler.capacity.ParentQueue: assignedContainer queue=root usedCapacity=0.22916667 absoluteUsedCapacity=0.22916667 used=<memory:11264, vCores:6> cluster=<memory:49152, vCores:96>
2013-08-22 03:35:35,754 INFO org.apache.hadoop.yarn.server.resourcemanager.rmcontainer.RMContainerImpl: container_1377141553101_0006_01_000003 Container Transitioned from NEW to ALLOCATED
2013-08-22 03:35:35,754 INFO org.apache.hadoop.yarn.server.resourcemanager.RMAuditLogger: USER=ubuntu	OPERATION=AM Allocated Container	TARGET=SchedulerApp	RESULT=SUCCESS	APPID=application_1377141553101_0006	CONTAINERID=container_1377141553101_0006_01_000003
2013-08-22 03:35:35,754 INFO org.apache.hadoop.yarn.server.resourcemanager.scheduler.common.fica.FiCaSchedulerNode: Assigned container container_1377141553101_0006_01_000003 of capacity <memory:1024, vCores:1> on host hadoop-998-2:35081, which currently has 3 containers, <memory:4096, vCores:3> used and <memory:4096, vCores:13> available
2013-08-22 03:35:35,755 INFO org.apache.hadoop.yarn.server.resourcemanager.scheduler.capacity.LeafQueue: assignedContainer application=application_1377141553101_0006 container=Container: [ContainerId: container_1377141553101_0006_01_000003, NodeId: hadoop-998-2:35081, NodeHttpAddress: hadoop-998-2:8042, Resource: <memory:1024, vCores:1>, Priority: 20, State: NEW, Token: null, Status: container_id {, app_attempt_id {, application_id {, id: 6, cluster_timestamp: 1377141553101, }, attemptId: 1, }, id: 3, }, state: C_NEW, ] containerId=container_1377141553101_0006_01_000003 queue=default: capacity=1.0, absoluteCapacity=1.0, usedResources=<memory:11264, vCores:6>usedCapacity=0.22916667, absoluteUsedCapacity=0.22916667, numApps=5, numContainers=6 usedCapacity=0.22916667 absoluteUsedCapacity=0.22916667 used=<memory:11264, vCores:6> cluster=<memory:49152, vCores:96>
2013-08-22 03:35:35,755 INFO org.apache.hadoop.yarn.server.resourcemanager.scheduler.capacity.ParentQueue: Re-sorting queues since queue: root.default stats: default: capacity=1.0, absoluteCapacity=1.0, usedResources=<memory:12288, vCores:7>usedCapacity=0.25, absoluteUsedCapacity=0.25, numApps=5, numContainers=7
2013-08-22 03:35:35,756 INFO org.apache.hadoop.yarn.server.resourcemanager.scheduler.capacity.ParentQueue: assignedContainer queue=root usedCapacity=0.25 absoluteUsedCapacity=0.25 used=<memory:12288, vCores:7> cluster=<memory:49152, vCores:96>
2013-08-22 03:35:35,756 INFO org.apache.hadoop.yarn.server.resourcemanager.rmcontainer.RMContainerImpl: container_1377141553101_0006_01_000004 Container Transitioned from NEW to ALLOCATED
2013-08-22 03:35:35,756 INFO org.apache.hadoop.yarn.server.resourcemanager.RMAuditLogger: USER=ubuntu	OPERATION=AM Allocated Container	TARGET=SchedulerApp	RESULT=SUCCESS	APPID=application_1377141553101_0006	CONTAINERID=container_1377141553101_0006_01_000004
2013-08-22 03:35:35,756 INFO org.apache.hadoop.yarn.server.resourcemanager.scheduler.common.fica.FiCaSchedulerNode: Assigned container container_1377141553101_0006_01_000004 of capacity <memory:1024, vCores:1> on host hadoop-998-2:35081, which currently has 4 containers, <memory:5120, vCores:4> used and <memory:3072, vCores:12> available
2013-08-22 03:35:35,757 INFO org.apache.hadoop.yarn.server.resourcemanager.scheduler.capacity.LeafQueue: assignedContainer application=application_1377141553101_0006 container=Container: [ContainerId: container_1377141553101_0006_01_000004, NodeId: hadoop-998-2:35081, NodeHttpAddress: hadoop-998-2:8042, Resource: <memory:1024, vCores:1>, Priority: 20, State: NEW, Token: null, Status: container_id {, app_attempt_id {, application_id {, id: 6, cluster_timestamp: 1377141553101, }, attemptId: 1, }, id: 4, }, state: C_NEW, ] containerId=container_1377141553101_0006_01_000004 queue=default: capacity=1.0, absoluteCapacity=1.0, usedResources=<memory:12288, vCores:7>usedCapacity=0.25, absoluteUsedCapacity=0.25, numApps=5, numContainers=7 usedCapacity=0.25 absoluteUsedCapacity=0.25 used=<memory:12288, vCores:7> cluster=<memory:49152, vCores:96>
2013-08-22 03:35:35,758 INFO org.apache.hadoop.yarn.server.resourcemanager.scheduler.capacity.ParentQueue: Re-sorting queues since queue: root.default stats: default: capacity=1.0, absoluteCapacity=1.0, usedResources=<memory:13312, vCores:8>usedCapacity=0.27083334, absoluteUsedCapacity=0.27083334, numApps=5, numContainers=8
2013-08-22 03:35:35,758 INFO org.apache.hadoop.yarn.server.resourcemanager.scheduler.capacity.ParentQueue: assignedContainer queue=root usedCapacity=0.27083334 absoluteUsedCapacity=0.27083334 used=<memory:13312, vCores:8> cluster=<memory:49152, vCores:96>
2013-08-22 03:35:35,758 INFO org.apache.hadoop.yarn.server.resourcemanager.rmcontainer.RMContainerImpl: container_1377141553101_0006_01_000005 Container Transitioned from NEW to ALLOCATED
2013-08-22 03:35:35,759 INFO org.apache.hadoop.yarn.server.resourcemanager.RMAuditLogger: USER=ubuntu	OPERATION=AM Allocated Container	TARGET=SchedulerApp	RESULT=SUCCESS	APPID=application_1377141553101_0006	CONTAINERID=container_1377141553101_0006_01_000005
2013-08-22 03:35:35,759 INFO org.apache.hadoop.yarn.server.resourcemanager.scheduler.common.fica.FiCaSchedulerNode: Assigned container container_1377141553101_0006_01_000005 of capacity <memory:1024, vCores:1> on host hadoop-998-2:35081, which currently has 5 containers, <memory:6144, vCores:5> used and <memory:2048, vCores:11> available
2013-08-22 03:35:35,760 INFO org.apache.hadoop.yarn.server.resourcemanager.scheduler.capacity.LeafQueue: assignedContainer application=application_1377141553101_0006 container=Container: [ContainerId: container_1377141553101_0006_01_000005, NodeId: hadoop-998-2:35081, NodeHttpAddress: hadoop-998-2:8042, Resource: <memory:1024, vCores:1>, Priority: 20, State: NEW, Token: null, Status: container_id {, app_attempt_id {, application_id {, id: 6, cluster_timestamp: 1377141553101, }, attemptId: 1, }, id: 5, }, state: C_NEW, ] containerId=container_1377141553101_0006_01_000005 queue=default: capacity=1.0, absoluteCapacity=1.0, usedResources=<memory:13312, vCores:8>usedCapacity=0.27083334, absoluteUsedCapacity=0.27083334, numApps=5, numContainers=8 usedCapacity=0.27083334 absoluteUsedCapacity=0.27083334 used=<memory:13312, vCores:8> cluster=<memory:49152, vCores:96>
2013-08-22 03:35:35,760 INFO org.apache.hadoop.yarn.server.resourcemanager.scheduler.capacity.ParentQueue: Re-sorting queues since queue: root.default stats: default: capacity=1.0, absoluteCapacity=1.0, usedResources=<memory:14336, vCores:9>usedCapacity=0.29166666, absoluteUsedCapacity=0.29166666, numApps=5, numContainers=9
2013-08-22 03:35:35,760 INFO org.apache.hadoop.yarn.server.resourcemanager.scheduler.capacity.ParentQueue: assignedContainer queue=root usedCapacity=0.29166666 absoluteUsedCapacity=0.29166666 used=<memory:14336, vCores:9> cluster=<memory:49152, vCores:96>
2013-08-22 03:35:35,762 INFO org.apache.hadoop.yarn.server.resourcemanager.rmcontainer.RMContainerImpl: container_1377141553101_0006_01_000006 Container Transitioned from NEW to ALLOCATED
2013-08-22 03:35:35,762 INFO org.apache.hadoop.yarn.server.resourcemanager.RMAuditLogger: USER=ubuntu	OPERATION=AM Allocated Container	TARGET=SchedulerApp	RESULT=SUCCESS	APPID=application_1377141553101_0006	CONTAINERID=container_1377141553101_0006_01_000006
2013-08-22 03:35:35,762 INFO org.apache.hadoop.yarn.server.resourcemanager.scheduler.common.fica.FiCaSchedulerNode: Assigned container container_1377141553101_0006_01_000006 of capacity <memory:1024, vCores:1> on host hadoop-998-2:35081, which currently has 6 containers, <memory:7168, vCores:6> used and <memory:1024, vCores:10> available
2013-08-22 03:35:35,763 INFO org.apache.hadoop.yarn.server.resourcemanager.scheduler.capacity.LeafQueue: assignedContainer application=application_1377141553101_0006 container=Container: [ContainerId: container_1377141553101_0006_01_000006, NodeId: hadoop-998-2:35081, NodeHttpAddress: hadoop-998-2:8042, Resource: <memory:1024, vCores:1>, Priority: 20, State: NEW, Token: null, Status: container_id {, app_attempt_id {, application_id {, id: 6, cluster_timestamp: 1377141553101, }, attemptId: 1, }, id: 6, }, state: C_NEW, ] containerId=container_1377141553101_0006_01_000006 queue=default: capacity=1.0, absoluteCapacity=1.0, usedResources=<memory:14336, vCores:9>usedCapacity=0.29166666, absoluteUsedCapacity=0.29166666, numApps=5, numContainers=9 usedCapacity=0.29166666 absoluteUsedCapacity=0.29166666 used=<memory:14336, vCores:9> cluster=<memory:49152, vCores:96>
2013-08-22 03:35:35,763 INFO org.apache.hadoop.yarn.server.resourcemanager.scheduler.capacity.ParentQueue: Re-sorting queues since queue: root.default stats: default: capacity=1.0, absoluteCapacity=1.0, usedResources=<memory:15360, vCores:10>usedCapacity=0.3125, absoluteUsedCapacity=0.3125, numApps=5, numContainers=10
2013-08-22 03:35:35,764 INFO org.apache.hadoop.yarn.server.resourcemanager.scheduler.capacity.ParentQueue: assignedContainer queue=root usedCapacity=0.3125 absoluteUsedCapacity=0.3125 used=<memory:15360, vCores:10> cluster=<memory:49152, vCores:96>
2013-08-22 03:35:35,764 INFO org.apache.hadoop.yarn.server.resourcemanager.rmcontainer.RMContainerImpl: container_1377141553101_0006_01_000007 Container Transitioned from NEW to ALLOCATED
2013-08-22 03:35:35,764 INFO org.apache.hadoop.yarn.server.resourcemanager.RMAuditLogger: USER=ubuntu	OPERATION=AM Allocated Container	TARGET=SchedulerApp	RESULT=SUCCESS	APPID=application_1377141553101_0006	CONTAINERID=container_1377141553101_0006_01_000007
2013-08-22 03:35:35,764 INFO org.apache.hadoop.yarn.server.resourcemanager.scheduler.common.fica.FiCaSchedulerNode: Assigned container container_1377141553101_0006_01_000007 of capacity <memory:1024, vCores:1> on host hadoop-998-2:35081, which currently has 7 containers, <memory:8192, vCores:7> used and <memory:0, vCores:9> available
2013-08-22 03:35:35,765 INFO org.apache.hadoop.yarn.server.resourcemanager.scheduler.capacity.LeafQueue: assignedContainer application=application_1377141553101_0006 container=Container: [ContainerId: container_1377141553101_0006_01_000007, NodeId: hadoop-998-2:35081, NodeHttpAddress: hadoop-998-2:8042, Resource: <memory:1024, vCores:1>, Priority: 20, State: NEW, Token: null, Status: container_id {, app_attempt_id {, application_id {, id: 6, cluster_timestamp: 1377141553101, }, attemptId: 1, }, id: 7, }, state: C_NEW, ] containerId=container_1377141553101_0006_01_000007 queue=default: capacity=1.0, absoluteCapacity=1.0, usedResources=<memory:15360, vCores:10>usedCapacity=0.3125, absoluteUsedCapacity=0.3125, numApps=5, numContainers=10 usedCapacity=0.3125 absoluteUsedCapacity=0.3125 used=<memory:15360, vCores:10> cluster=<memory:49152, vCores:96>
2013-08-22 03:35:35,766 INFO org.apache.hadoop.yarn.server.resourcemanager.scheduler.capacity.ParentQueue: Re-sorting queues since queue: root.default stats: default: capacity=1.0, absoluteCapacity=1.0, usedResources=<memory:16384, vCores:11>usedCapacity=0.33333334, absoluteUsedCapacity=0.33333334, numApps=5, numContainers=11
2013-08-22 03:35:35,766 INFO org.apache.hadoop.yarn.server.resourcemanager.scheduler.capacity.ParentQueue: assignedContainer queue=root usedCapacity=0.33333334 absoluteUsedCapacity=0.33333334 used=<memory:16384, vCores:11> cluster=<memory:49152, vCores:96>
2013-08-22 03:35:35,844 INFO org.apache.hadoop.yarn.server.resourcemanager.rmcontainer.RMContainerImpl: container_1377141553101_0006_01_000008 Container Transitioned from NEW to ALLOCATED
2013-08-22 03:35:35,844 INFO org.apache.hadoop.yarn.server.resourcemanager.RMAuditLogger: USER=ubuntu	OPERATION=AM Allocated Container	TARGET=SchedulerApp	RESULT=SUCCESS	APPID=application_1377141553101_0006	CONTAINERID=container_1377141553101_0006_01_000008
2013-08-22 03:35:35,845 INFO org.apache.hadoop.yarn.server.resourcemanager.scheduler.common.fica.FiCaSchedulerNode: Assigned container container_1377141553101_0006_01_000008 of capacity <memory:1024, vCores:1> on host hadoop-998-7:60905, which currently has 2 containers, <memory:3072, vCores:2> used and <memory:5120, vCores:14> available
2013-08-22 03:35:35,846 INFO org.apache.hadoop.yarn.server.resourcemanager.scheduler.capacity.LeafQueue: assignedContainer application=application_1377141553101_0006 container=Container: [ContainerId: container_1377141553101_0006_01_000008, NodeId: hadoop-998-7:60905, NodeHttpAddress: hadoop-998-7:8042, Resource: <memory:1024, vCores:1>, Priority: 20, State: NEW, Token: null, Status: container_id {, app_attempt_id {, application_id {, id: 6, cluster_timestamp: 1377141553101, }, attemptId: 1, }, id: 8, }, state: C_NEW, ] containerId=container_1377141553101_0006_01_000008 queue=default: capacity=1.0, absoluteCapacity=1.0, usedResources=<memory:16384, vCores:11>usedCapacity=0.33333334, absoluteUsedCapacity=0.33333334, numApps=5, numContainers=11 usedCapacity=0.33333334 absoluteUsedCapacity=0.33333334 used=<memory:16384, vCores:11> cluster=<memory:49152, vCores:96>
2013-08-22 03:35:35,846 INFO org.apache.hadoop.yarn.server.resourcemanager.scheduler.capacity.ParentQueue: Re-sorting queues since queue: root.default stats: default: capacity=1.0, absoluteCapacity=1.0, usedResources=<memory:17408, vCores:12>usedCapacity=0.35416666, absoluteUsedCapacity=0.35416666, numApps=5, numContainers=12
2013-08-22 03:35:35,846 INFO org.apache.hadoop.yarn.server.resourcemanager.scheduler.capacity.ParentQueue: assignedContainer queue=root usedCapacity=0.35416666 absoluteUsedCapacity=0.35416666 used=<memory:17408, vCores:12> cluster=<memory:49152, vCores:96>
2013-08-22 03:35:35,847 INFO org.apache.hadoop.yarn.server.resourcemanager.rmcontainer.RMContainerImpl: container_1377141553101_0006_01_000009 Container Transitioned from NEW to ALLOCATED
2013-08-22 03:35:35,847 INFO org.apache.hadoop.yarn.server.resourcemanager.RMAuditLogger: USER=ubuntu	OPERATION=AM Allocated Container	TARGET=SchedulerApp	RESULT=SUCCESS	APPID=application_1377141553101_0006	CONTAINERID=container_1377141553101_0006_01_000009
2013-08-22 03:35:35,847 INFO org.apache.hadoop.yarn.server.resourcemanager.scheduler.common.fica.FiCaSchedulerNode: Assigned container container_1377141553101_0006_01_000009 of capacity <memory:1024, vCores:1> on host hadoop-998-7:60905, which currently has 3 containers, <memory:4096, vCores:3> used and <memory:4096, vCores:13> available
2013-08-22 03:35:35,848 INFO org.apache.hadoop.yarn.server.resourcemanager.scheduler.capacity.LeafQueue: assignedContainer application=application_1377141553101_0006 container=Container: [ContainerId: container_1377141553101_0006_01_000009, NodeId: hadoop-998-7:60905, NodeHttpAddress: hadoop-998-7:8042, Resource: <memory:1024, vCores:1>, Priority: 20, State: NEW, Token: null, Status: container_id {, app_attempt_id {, application_id {, id: 6, cluster_timestamp: 1377141553101, }, attemptId: 1, }, id: 9, }, state: C_NEW, ] containerId=container_1377141553101_0006_01_000009 queue=default: capacity=1.0, absoluteCapacity=1.0, usedResources=<memory:17408, vCores:12>usedCapacity=0.35416666, absoluteUsedCapacity=0.35416666, numApps=5, numContainers=12 usedCapacity=0.35416666 absoluteUsedCapacity=0.35416666 used=<memory:17408, vCores:12> cluster=<memory:49152, vCores:96>
2013-08-22 03:35:35,848 INFO org.apache.hadoop.yarn.server.resourcemanager.scheduler.capacity.ParentQueue: Re-sorting queues since queue: root.default stats: default: capacity=1.0, absoluteCapacity=1.0, usedResources=<memory:18432, vCores:13>usedCapacity=0.375, absoluteUsedCapacity=0.375, numApps=5, numContainers=13
2013-08-22 03:35:35,849 INFO org.apache.hadoop.yarn.server.resourcemanager.scheduler.capacity.ParentQueue: assignedContainer queue=root usedCapacity=0.375 absoluteUsedCapacity=0.375 used=<memory:18432, vCores:13> cluster=<memory:49152, vCores:96>
2013-08-22 03:35:35,849 INFO org.apache.hadoop.yarn.server.resourcemanager.rmcontainer.RMContainerImpl: container_1377141553101_0006_01_000010 Container Transitioned from NEW to ALLOCATED
2013-08-22 03:35:35,849 INFO org.apache.hadoop.yarn.server.resourcemanager.RMAuditLogger: USER=ubuntu	OPERATION=AM Allocated Container	TARGET=SchedulerApp	RESULT=SUCCESS	APPID=application_1377141553101_0006	CONTAINERID=container_1377141553101_0006_01_000010
2013-08-22 03:35:35,849 INFO org.apache.hadoop.yarn.server.resourcemanager.scheduler.common.fica.FiCaSchedulerNode: Assigned container container_1377141553101_0006_01_000010 of capacity <memory:1024, vCores:1> on host hadoop-998-7:60905, which currently has 4 containers, <memory:5120, vCores:4> used and <memory:3072, vCores:12> available
2013-08-22 03:35:35,850 INFO org.apache.hadoop.yarn.server.resourcemanager.scheduler.capacity.LeafQueue: assignedContainer application=application_1377141553101_0006 container=Container: [ContainerId: container_1377141553101_0006_01_000010, NodeId: hadoop-998-7:60905, NodeHttpAddress: hadoop-998-7:8042, Resource: <memory:1024, vCores:1>, Priority: 20, State: NEW, Token: null, Status: container_id {, app_attempt_id {, application_id {, id: 6, cluster_timestamp: 1377141553101, }, attemptId: 1, }, id: 10, }, state: C_NEW, ] containerId=container_1377141553101_0006_01_000010 queue=default: capacity=1.0, absoluteCapacity=1.0, usedResources=<memory:18432, vCores:13>usedCapacity=0.375, absoluteUsedCapacity=0.375, numApps=5, numContainers=13 usedCapacity=0.375 absoluteUsedCapacity=0.375 used=<memory:18432, vCores:13> cluster=<memory:49152, vCores:96>
2013-08-22 03:35:35,851 INFO org.apache.hadoop.yarn.server.resourcemanager.scheduler.capacity.ParentQueue: Re-sorting queues since queue: root.default stats: default: capacity=1.0, absoluteCapacity=1.0, usedResources=<memory:19456, vCores:14>usedCapacity=0.39583334, absoluteUsedCapacity=0.39583334, numApps=5, numContainers=14
2013-08-22 03:35:35,851 INFO org.apache.hadoop.yarn.server.resourcemanager.scheduler.capacity.ParentQueue: assignedContainer queue=root usedCapacity=0.39583334 absoluteUsedCapacity=0.39583334 used=<memory:19456, vCores:14> cluster=<memory:49152, vCores:96>
2013-08-22 03:35:35,851 INFO org.apache.hadoop.yarn.server.resourcemanager.rmcontainer.RMContainerImpl: container_1377141553101_0006_01_000011 Container Transitioned from NEW to ALLOCATED
2013-08-22 03:35:35,851 INFO org.apache.hadoop.yarn.server.resourcemanager.RMAuditLogger: USER=ubuntu	OPERATION=AM Allocated Container	TARGET=SchedulerApp	RESULT=SUCCESS	APPID=application_1377141553101_0006	CONTAINERID=container_1377141553101_0006_01_000011
2013-08-22 03:35:35,851 INFO org.apache.hadoop.yarn.server.resourcemanager.scheduler.common.fica.FiCaSchedulerNode: Assigned container container_1377141553101_0006_01_000011 of capacity <memory:1024, vCores:1> on host hadoop-998-7:60905, which currently has 5 containers, <memory:6144, vCores:5> used and <memory:2048, vCores:11> available
2013-08-22 03:35:35,852 INFO org.apache.hadoop.yarn.server.resourcemanager.scheduler.capacity.LeafQueue: assignedContainer application=application_1377141553101_0006 container=Container: [ContainerId: container_1377141553101_0006_01_000011, NodeId: hadoop-998-7:60905, NodeHttpAddress: hadoop-998-7:8042, Resource: <memory:1024, vCores:1>, Priority: 20, State: NEW, Token: null, Status: container_id {, app_attempt_id {, application_id {, id: 6, cluster_timestamp: 1377141553101, }, attemptId: 1, }, id: 11, }, state: C_NEW, ] containerId=container_1377141553101_0006_01_000011 queue=default: capacity=1.0, absoluteCapacity=1.0, usedResources=<memory:19456, vCores:14>usedCapacity=0.39583334, absoluteUsedCapacity=0.39583334, numApps=5, numContainers=14 usedCapacity=0.39583334 absoluteUsedCapacity=0.39583334 used=<memory:19456, vCores:14> cluster=<memory:49152, vCores:96>
2013-08-22 03:35:35,853 INFO org.apache.hadoop.yarn.server.resourcemanager.scheduler.capacity.ParentQueue: Re-sorting queues since queue: root.default stats: default: capacity=1.0, absoluteCapacity=1.0, usedResources=<memory:20480, vCores:15>usedCapacity=0.41666666, absoluteUsedCapacity=0.41666666, numApps=5, numContainers=15
2013-08-22 03:35:35,853 INFO org.apache.hadoop.yarn.server.resourcemanager.scheduler.capacity.ParentQueue: assignedContainer queue=root usedCapacity=0.41666666 absoluteUsedCapacity=0.41666666 used=<memory:20480, vCores:15> cluster=<memory:49152, vCores:96>
2013-08-22 03:35:35,853 INFO org.apache.hadoop.yarn.server.resourcemanager.rmcontainer.RMContainerImpl: container_1377141553101_0006_01_000012 Container Transitioned from NEW to ALLOCATED
2013-08-22 03:35:35,853 INFO org.apache.hadoop.yarn.server.resourcemanager.RMAuditLogger: USER=ubuntu	OPERATION=AM Allocated Container	TARGET=SchedulerApp	RESULT=SUCCESS	APPID=application_1377141553101_0006	CONTAINERID=container_1377141553101_0006_01_000012
2013-08-22 03:35:35,854 INFO org.apache.hadoop.yarn.server.resourcemanager.scheduler.common.fica.FiCaSchedulerNode: Assigned container container_1377141553101_0006_01_000012 of capacity <memory:1024, vCores:1> on host hadoop-998-7:60905, which currently has 6 containers, <memory:7168, vCores:6> used and <memory:1024, vCores:10> available
2013-08-22 03:35:35,855 INFO org.apache.hadoop.yarn.server.resourcemanager.scheduler.capacity.LeafQueue: assignedContainer application=application_1377141553101_0006 container=Container: [ContainerId: container_1377141553101_0006_01_000012, NodeId: hadoop-998-7:60905, NodeHttpAddress: hadoop-998-7:8042, Resource: <memory:1024, vCores:1>, Priority: 20, State: NEW, Token: null, Status: container_id {, app_attempt_id {, application_id {, id: 6, cluster_timestamp: 1377141553101, }, attemptId: 1, }, id: 12, }, state: C_NEW, ] containerId=container_1377141553101_0006_01_000012 queue=default: capacity=1.0, absoluteCapacity=1.0, usedResources=<memory:20480, vCores:15>usedCapacity=0.41666666, absoluteUsedCapacity=0.41666666, numApps=5, numContainers=15 usedCapacity=0.41666666 absoluteUsedCapacity=0.41666666 used=<memory:20480, vCores:15> cluster=<memory:49152, vCores:96>
2013-08-22 03:35:35,855 INFO org.apache.hadoop.yarn.server.resourcemanager.scheduler.capacity.ParentQueue: Re-sorting queues since queue: root.default stats: default: capacity=1.0, absoluteCapacity=1.0, usedResources=<memory:21504, vCores:16>usedCapacity=0.4375, absoluteUsedCapacity=0.4375, numApps=5, numContainers=16
2013-08-22 03:35:35,855 INFO org.apache.hadoop.yarn.server.resourcemanager.scheduler.capacity.ParentQueue: assignedContainer queue=root usedCapacity=0.4375 absoluteUsedCapacity=0.4375 used=<memory:21504, vCores:16> cluster=<memory:49152, vCores:96>
2013-08-22 03:35:35,856 INFO org.apache.hadoop.yarn.server.resourcemanager.rmcontainer.RMContainerImpl: container_1377141553101_0006_01_000013 Container Transitioned from NEW to ALLOCATED
2013-08-22 03:35:35,856 INFO org.apache.hadoop.yarn.server.resourcemanager.RMAuditLogger: USER=ubuntu	OPERATION=AM Allocated Container	TARGET=SchedulerApp	RESULT=SUCCESS	APPID=application_1377141553101_0006	CONTAINERID=container_1377141553101_0006_01_000013
2013-08-22 03:35:35,856 INFO org.apache.hadoop.yarn.server.resourcemanager.scheduler.common.fica.FiCaSchedulerNode: Assigned container container_1377141553101_0006_01_000013 of capacity <memory:1024, vCores:1> on host hadoop-998-7:60905, which currently has 7 containers, <memory:8192, vCores:7> used and <memory:0, vCores:9> available
2013-08-22 03:35:35,857 INFO org.apache.hadoop.yarn.server.resourcemanager.scheduler.capacity.LeafQueue: assignedContainer application=application_1377141553101_0006 container=Container: [ContainerId: container_1377141553101_0006_01_000013, NodeId: hadoop-998-7:60905, NodeHttpAddress: hadoop-998-7:8042, Resource: <memory:1024, vCores:1>, Priority: 20, State: NEW, Token: null, Status: container_id {, app_attempt_id {, application_id {, id: 6, cluster_timestamp: 1377141553101, }, attemptId: 1, }, id: 13, }, state: C_NEW, ] containerId=container_1377141553101_0006_01_000013 queue=default: capacity=1.0, absoluteCapacity=1.0, usedResources=<memory:21504, vCores:16>usedCapacity=0.4375, absoluteUsedCapacity=0.4375, numApps=5, numContainers=16 usedCapacity=0.4375 absoluteUsedCapacity=0.4375 used=<memory:21504, vCores:16> cluster=<memory:49152, vCores:96>
2013-08-22 03:35:35,857 INFO org.apache.hadoop.yarn.server.resourcemanager.scheduler.capacity.ParentQueue: Re-sorting queues since queue: root.default stats: default: capacity=1.0, absoluteCapacity=1.0, usedResources=<memory:22528, vCores:17>usedCapacity=0.45833334, absoluteUsedCapacity=0.45833334, numApps=5, numContainers=17
2013-08-22 03:35:35,857 INFO org.apache.hadoop.yarn.server.resourcemanager.scheduler.capacity.ParentQueue: assignedContainer queue=root usedCapacity=0.45833334 absoluteUsedCapacity=0.45833334 used=<memory:22528, vCores:17> cluster=<memory:49152, vCores:96>
2013-08-22 03:35:35,865 INFO org.apache.hadoop.yarn.server.resourcemanager.rmcontainer.RMContainerImpl: container_1377141553101_0006_01_000014 Container Transitioned from NEW to ALLOCATED
2013-08-22 03:35:35,865 INFO org.apache.hadoop.yarn.server.resourcemanager.RMAuditLogger: USER=ubuntu	OPERATION=AM Allocated Container	TARGET=SchedulerApp	RESULT=SUCCESS	APPID=application_1377141553101_0006	CONTAINERID=container_1377141553101_0006_01_000014
2013-08-22 03:35:35,866 INFO org.apache.hadoop.yarn.server.resourcemanager.scheduler.common.fica.FiCaSchedulerNode: Assigned container container_1377141553101_0006_01_000014 of capacity <memory:1024, vCores:1> on host hadoop-998-6:58634, which currently has 1 containers, <memory:1024, vCores:1> used and <memory:7168, vCores:15> available
2013-08-22 03:35:35,867 INFO org.apache.hadoop.yarn.server.resourcemanager.scheduler.capacity.LeafQueue: assignedContainer application=application_1377141553101_0006 container=Container: [ContainerId: container_1377141553101_0006_01_000014, NodeId: hadoop-998-6:58634, NodeHttpAddress: hadoop-998-6:8042, Resource: <memory:1024, vCores:1>, Priority: 20, State: NEW, Token: null, Status: container_id {, app_attempt_id {, application_id {, id: 6, cluster_timestamp: 1377141553101, }, attemptId: 1, }, id: 14, }, state: C_NEW, ] containerId=container_1377141553101_0006_01_000014 queue=default: capacity=1.0, absoluteCapacity=1.0, usedResources=<memory:22528, vCores:17>usedCapacity=0.45833334, absoluteUsedCapacity=0.45833334, numApps=5, numContainers=17 usedCapacity=0.45833334 absoluteUsedCapacity=0.45833334 used=<memory:22528, vCores:17> cluster=<memory:49152, vCores:96>
2013-08-22 03:35:35,867 INFO org.apache.hadoop.yarn.server.resourcemanager.scheduler.capacity.ParentQueue: Re-sorting queues since queue: root.default stats: default: capacity=1.0, absoluteCapacity=1.0, usedResources=<memory:23552, vCores:18>usedCapacity=0.47916666, absoluteUsedCapacity=0.47916666, numApps=5, numContainers=18
2013-08-22 03:35:35,867 INFO org.apache.hadoop.yarn.server.resourcemanager.scheduler.capacity.ParentQueue: assignedContainer queue=root usedCapacity=0.47916666 absoluteUsedCapacity=0.47916666 used=<memory:23552, vCores:18> cluster=<memory:49152, vCores:96>
2013-08-22 03:35:35,867 INFO org.apache.hadoop.yarn.server.resourcemanager.rmcontainer.RMContainerImpl: container_1377141553101_0006_01_000015 Container Transitioned from NEW to ALLOCATED
2013-08-22 03:35:35,868 INFO org.apache.hadoop.yarn.server.resourcemanager.RMAuditLogger: USER=ubuntu	OPERATION=AM Allocated Container	TARGET=SchedulerApp	RESULT=SUCCESS	APPID=application_1377141553101_0006	CONTAINERID=container_1377141553101_0006_01_000015
2013-08-22 03:35:35,868 INFO org.apache.hadoop.yarn.server.resourcemanager.scheduler.common.fica.FiCaSchedulerNode: Assigned container container_1377141553101_0006_01_000015 of capacity <memory:1024, vCores:1> on host hadoop-998-6:58634, which currently has 2 containers, <memory:2048, vCores:2> used and <memory:6144, vCores:14> available
2013-08-22 03:35:35,869 INFO org.apache.hadoop.yarn.server.resourcemanager.scheduler.capacity.LeafQueue: assignedContainer application=application_1377141553101_0006 container=Container: [ContainerId: container_1377141553101_0006_01_000015, NodeId: hadoop-998-6:58634, NodeHttpAddress: hadoop-998-6:8042, Resource: <memory:1024, vCores:1>, Priority: 20, State: NEW, Token: null, Status: container_id {, app_attempt_id {, application_id {, id: 6, cluster_timestamp: 1377141553101, }, attemptId: 1, }, id: 15, }, state: C_NEW, ] containerId=container_1377141553101_0006_01_000015 queue=default: capacity=1.0, absoluteCapacity=1.0, usedResources=<memory:23552, vCores:18>usedCapacity=0.47916666, absoluteUsedCapacity=0.47916666, numApps=5, numContainers=18 usedCapacity=0.47916666 absoluteUsedCapacity=0.47916666 used=<memory:23552, vCores:18> cluster=<memory:49152, vCores:96>
2013-08-22 03:35:35,869 INFO org.apache.hadoop.yarn.server.resourcemanager.scheduler.capacity.ParentQueue: Re-sorting queues since queue: root.default stats: default: capacity=1.0, absoluteCapacity=1.0, usedResources=<memory:24576, vCores:19>usedCapacity=0.5, absoluteUsedCapacity=0.5, numApps=5, numContainers=19
2013-08-22 03:35:35,869 INFO org.apache.hadoop.yarn.server.resourcemanager.scheduler.capacity.ParentQueue: assignedContainer queue=root usedCapacity=0.5 absoluteUsedCapacity=0.5 used=<memory:24576, vCores:19> cluster=<memory:49152, vCores:96>
2013-08-22 03:35:35,870 INFO org.apache.hadoop.yarn.server.resourcemanager.rmcontainer.RMContainerImpl: container_1377141553101_0006_01_000016 Container Transitioned from NEW to ALLOCATED
2013-08-22 03:35:35,870 INFO org.apache.hadoop.yarn.server.resourcemanager.RMAuditLogger: USER=ubuntu	OPERATION=AM Allocated Container	TARGET=SchedulerApp	RESULT=SUCCESS	APPID=application_1377141553101_0006	CONTAINERID=container_1377141553101_0006_01_000016
2013-08-22 03:35:35,870 INFO org.apache.hadoop.yarn.server.resourcemanager.scheduler.common.fica.FiCaSchedulerNode: Assigned container container_1377141553101_0006_01_000016 of capacity <memory:1024, vCores:1> on host hadoop-998-6:58634, which currently has 3 containers, <memory:3072, vCores:3> used and <memory:5120, vCores:13> available
2013-08-22 03:35:35,871 INFO org.apache.hadoop.yarn.server.resourcemanager.scheduler.capacity.LeafQueue: assignedContainer application=application_1377141553101_0006 container=Container: [ContainerId: container_1377141553101_0006_01_000016, NodeId: hadoop-998-6:58634, NodeHttpAddress: hadoop-998-6:8042, Resource: <memory:1024, vCores:1>, Priority: 20, State: NEW, Token: null, Status: container_id {, app_attempt_id {, application_id {, id: 6, cluster_timestamp: 1377141553101, }, attemptId: 1, }, id: 16, }, state: C_NEW, ] containerId=container_1377141553101_0006_01_000016 queue=default: capacity=1.0, absoluteCapacity=1.0, usedResources=<memory:24576, vCores:19>usedCapacity=0.5, absoluteUsedCapacity=0.5, numApps=5, numContainers=19 usedCapacity=0.5 absoluteUsedCapacity=0.5 used=<memory:24576, vCores:19> cluster=<memory:49152, vCores:96>
2013-08-22 03:35:35,871 INFO org.apache.hadoop.yarn.server.resourcemanager.scheduler.capacity.ParentQueue: Re-sorting queues since queue: root.default stats: default: capacity=1.0, absoluteCapacity=1.0, usedResources=<memory:25600, vCores:20>usedCapacity=0.5208333, absoluteUsedCapacity=0.5208333, numApps=5, numContainers=20
2013-08-22 03:35:35,871 INFO org.apache.hadoop.yarn.server.resourcemanager.scheduler.capacity.ParentQueue: assignedContainer queue=root usedCapacity=0.5208333 absoluteUsedCapacity=0.5208333 used=<memory:25600, vCores:20> cluster=<memory:49152, vCores:96>
2013-08-22 03:35:35,872 INFO org.apache.hadoop.yarn.server.resourcemanager.rmcontainer.RMContainerImpl: container_1377141553101_0006_01_000017 Container Transitioned from NEW to ALLOCATED
2013-08-22 03:35:35,872 INFO org.apache.hadoop.yarn.server.resourcemanager.RMAuditLogger: USER=ubuntu	OPERATION=AM Allocated Container	TARGET=SchedulerApp	RESULT=SUCCESS	APPID=application_1377141553101_0006	CONTAINERID=container_1377141553101_0006_01_000017
2013-08-22 03:35:35,872 INFO org.apache.hadoop.yarn.server.resourcemanager.scheduler.common.fica.FiCaSchedulerNode: Assigned container container_1377141553101_0006_01_000017 of capacity <memory:1024, vCores:1> on host hadoop-998-6:58634, which currently has 4 containers, <memory:4096, vCores:4> used and <memory:4096, vCores:12> available
2013-08-22 03:35:35,873 INFO org.apache.hadoop.yarn.server.resourcemanager.scheduler.capacity.LeafQueue: assignedContainer application=application_1377141553101_0006 container=Container: [ContainerId: container_1377141553101_0006_01_000017, NodeId: hadoop-998-6:58634, NodeHttpAddress: hadoop-998-6:8042, Resource: <memory:1024, vCores:1>, Priority: 20, State: NEW, Token: null, Status: container_id {, app_attempt_id {, application_id {, id: 6, cluster_timestamp: 1377141553101, }, attemptId: 1, }, id: 17, }, state: C_NEW, ] containerId=container_1377141553101_0006_01_000017 queue=default: capacity=1.0, absoluteCapacity=1.0, usedResources=<memory:25600, vCores:20>usedCapacity=0.5208333, absoluteUsedCapacity=0.5208333, numApps=5, numContainers=20 usedCapacity=0.5208333 absoluteUsedCapacity=0.5208333 used=<memory:25600, vCores:20> cluster=<memory:49152, vCores:96>
2013-08-22 03:35:35,873 INFO org.apache.hadoop.yarn.server.resourcemanager.scheduler.capacity.ParentQueue: Re-sorting queues since queue: root.default stats: default: capacity=1.0, absoluteCapacity=1.0, usedResources=<memory:26624, vCores:21>usedCapacity=0.5416667, absoluteUsedCapacity=0.5416667, numApps=5, numContainers=21
2013-08-22 03:35:35,873 INFO org.apache.hadoop.yarn.server.resourcemanager.scheduler.capacity.ParentQueue: assignedContainer queue=root usedCapacity=0.5416667 absoluteUsedCapacity=0.5416667 used=<memory:26624, vCores:21> cluster=<memory:49152, vCores:96>
2013-08-22 03:35:35,874 INFO org.apache.hadoop.yarn.server.resourcemanager.rmcontainer.RMContainerImpl: container_1377141553101_0006_01_000018 Container Transitioned from NEW to ALLOCATED
2013-08-22 03:35:35,874 INFO org.apache.hadoop.yarn.server.resourcemanager.RMAuditLogger: USER=ubuntu	OPERATION=AM Allocated Container	TARGET=SchedulerApp	RESULT=SUCCESS	APPID=application_1377141553101_0006	CONTAINERID=container_1377141553101_0006_01_000018
2013-08-22 03:35:35,874 INFO org.apache.hadoop.yarn.server.resourcemanager.scheduler.common.fica.FiCaSchedulerNode: Assigned container container_1377141553101_0006_01_000018 of capacity <memory:1024, vCores:1> on host hadoop-998-6:58634, which currently has 5 containers, <memory:5120, vCores:5> used and <memory:3072, vCores:11> available
2013-08-22 03:35:35,875 INFO org.apache.hadoop.yarn.server.resourcemanager.scheduler.capacity.LeafQueue: assignedContainer application=application_1377141553101_0006 container=Container: [ContainerId: container_1377141553101_0006_01_000018, NodeId: hadoop-998-6:58634, NodeHttpAddress: hadoop-998-6:8042, Resource: <memory:1024, vCores:1>, Priority: 20, State: NEW, Token: null, Status: container_id {, app_attempt_id {, application_id {, id: 6, cluster_timestamp: 1377141553101, }, attemptId: 1, }, id: 18, }, state: C_NEW, ] containerId=container_1377141553101_0006_01_000018 queue=default: capacity=1.0, absoluteCapacity=1.0, usedResources=<memory:26624, vCores:21>usedCapacity=0.5416667, absoluteUsedCapacity=0.5416667, numApps=5, numContainers=21 usedCapacity=0.5416667 absoluteUsedCapacity=0.5416667 used=<memory:26624, vCores:21> cluster=<memory:49152, vCores:96>
2013-08-22 03:35:35,875 INFO org.apache.hadoop.yarn.server.resourcemanager.scheduler.capacity.ParentQueue: Re-sorting queues since queue: root.default stats: default: capacity=1.0, absoluteCapacity=1.0, usedResources=<memory:27648, vCores:22>usedCapacity=0.5625, absoluteUsedCapacity=0.5625, numApps=5, numContainers=22
2013-08-22 03:35:35,876 INFO org.apache.hadoop.yarn.server.resourcemanager.scheduler.capacity.ParentQueue: assignedContainer queue=root usedCapacity=0.5625 absoluteUsedCapacity=0.5625 used=<memory:27648, vCores:22> cluster=<memory:49152, vCores:96>
2013-08-22 03:35:35,876 INFO org.apache.hadoop.yarn.server.resourcemanager.rmcontainer.RMContainerImpl: container_1377141553101_0006_01_000019 Container Transitioned from NEW to ALLOCATED
2013-08-22 03:35:35,876 INFO org.apache.hadoop.yarn.server.resourcemanager.RMAuditLogger: USER=ubuntu	OPERATION=AM Allocated Container	TARGET=SchedulerApp	RESULT=SUCCESS	APPID=application_1377141553101_0006	CONTAINERID=container_1377141553101_0006_01_000019
2013-08-22 03:35:35,876 INFO org.apache.hadoop.yarn.server.resourcemanager.scheduler.common.fica.FiCaSchedulerNode: Assigned container container_1377141553101_0006_01_000019 of capacity <memory:1024, vCores:1> on host hadoop-998-6:58634, which currently has 6 containers, <memory:6144, vCores:6> used and <memory:2048, vCores:10> available
2013-08-22 03:35:35,877 INFO org.apache.hadoop.yarn.server.resourcemanager.scheduler.capacity.LeafQueue: assignedContainer application=application_1377141553101_0006 container=Container: [ContainerId: container_1377141553101_0006_01_000019, NodeId: hadoop-998-6:58634, NodeHttpAddress: hadoop-998-6:8042, Resource: <memory:1024, vCores:1>, Priority: 20, State: NEW, Token: null, Status: container_id {, app_attempt_id {, application_id {, id: 6, cluster_timestamp: 1377141553101, }, attemptId: 1, }, id: 19, }, state: C_NEW, ] containerId=container_1377141553101_0006_01_000019 queue=default: capacity=1.0, absoluteCapacity=1.0, usedResources=<memory:27648, vCores:22>usedCapacity=0.5625, absoluteUsedCapacity=0.5625, numApps=5, numContainers=22 usedCapacity=0.5625 absoluteUsedCapacity=0.5625 used=<memory:27648, vCores:22> cluster=<memory:49152, vCores:96>
2013-08-22 03:35:35,878 INFO org.apache.hadoop.yarn.server.resourcemanager.scheduler.capacity.ParentQueue: Re-sorting queues since queue: root.default stats: default: capacity=1.0, absoluteCapacity=1.0, usedResources=<memory:28672, vCores:23>usedCapacity=0.5833333, absoluteUsedCapacity=0.5833333, numApps=5, numContainers=23
2013-08-22 03:35:35,878 INFO org.apache.hadoop.yarn.server.resourcemanager.scheduler.capacity.ParentQueue: assignedContainer queue=root usedCapacity=0.5833333 absoluteUsedCapacity=0.5833333 used=<memory:28672, vCores:23> cluster=<memory:49152, vCores:96>
2013-08-22 03:35:35,878 INFO org.apache.hadoop.yarn.server.resourcemanager.rmcontainer.RMContainerImpl: container_1377141553101_0006_01_000020 Container Transitioned from NEW to ALLOCATED
2013-08-22 03:35:35,878 INFO org.apache.hadoop.yarn.server.resourcemanager.RMAuditLogger: USER=ubuntu	OPERATION=AM Allocated Container	TARGET=SchedulerApp	RESULT=SUCCESS	APPID=application_1377141553101_0006	CONTAINERID=container_1377141553101_0006_01_000020
2013-08-22 03:35:35,879 INFO org.apache.hadoop.yarn.server.resourcemanager.scheduler.common.fica.FiCaSchedulerNode: Assigned container container_1377141553101_0006_01_000020 of capacity <memory:1024, vCores:1> on host hadoop-998-6:58634, which currently has 7 containers, <memory:7168, vCores:7> used and <memory:1024, vCores:9> available
2013-08-22 03:35:35,880 INFO org.apache.hadoop.yarn.server.resourcemanager.scheduler.capacity.LeafQueue: assignedContainer application=application_1377141553101_0006 container=Container: [ContainerId: container_1377141553101_0006_01_000020, NodeId: hadoop-998-6:58634, NodeHttpAddress: hadoop-998-6:8042, Resource: <memory:1024, vCores:1>, Priority: 20, State: NEW, Token: null, Status: container_id {, app_attempt_id {, application_id {, id: 6, cluster_timestamp: 1377141553101, }, attemptId: 1, }, id: 20, }, state: C_NEW, ] containerId=container_1377141553101_0006_01_000020 queue=default: capacity=1.0, absoluteCapacity=1.0, usedResources=<memory:28672, vCores:23>usedCapacity=0.5833333, absoluteUsedCapacity=0.5833333, numApps=5, numContainers=23 usedCapacity=0.5833333 absoluteUsedCapacity=0.5833333 used=<memory:28672, vCores:23> cluster=<memory:49152, vCores:96>
2013-08-22 03:35:35,880 INFO org.apache.hadoop.yarn.server.resourcemanager.scheduler.capacity.ParentQueue: Re-sorting queues since queue: root.default stats: default: capacity=1.0, absoluteCapacity=1.0, usedResources=<memory:29696, vCores:24>usedCapacity=0.6041667, absoluteUsedCapacity=0.6041667, numApps=5, numContainers=24
2013-08-22 03:35:35,880 INFO org.apache.hadoop.yarn.server.resourcemanager.scheduler.capacity.ParentQueue: assignedContainer queue=root usedCapacity=0.6041667 absoluteUsedCapacity=0.6041667 used=<memory:29696, vCores:24> cluster=<memory:49152, vCores:96>
2013-08-22 03:35:35,880 INFO org.apache.hadoop.yarn.server.resourcemanager.rmcontainer.RMContainerImpl: container_1377141553101_0006_01_000021 Container Transitioned from NEW to ALLOCATED
2013-08-22 03:35:35,881 INFO org.apache.hadoop.yarn.server.resourcemanager.RMAuditLogger: USER=ubuntu	OPERATION=AM Allocated Container	TARGET=SchedulerApp	RESULT=SUCCESS	APPID=application_1377141553101_0006	CONTAINERID=container_1377141553101_0006_01_000021
2013-08-22 03:35:35,881 INFO org.apache.hadoop.yarn.server.resourcemanager.scheduler.common.fica.FiCaSchedulerNode: Assigned container container_1377141553101_0006_01_000021 of capacity <memory:1024, vCores:1> on host hadoop-998-6:58634, which currently has 8 containers, <memory:8192, vCores:8> used and <memory:0, vCores:8> available
2013-08-22 03:35:35,882 INFO org.apache.hadoop.yarn.server.resourcemanager.scheduler.capacity.LeafQueue: assignedContainer application=application_1377141553101_0006 container=Container: [ContainerId: container_1377141553101_0006_01_000021, NodeId: hadoop-998-6:58634, NodeHttpAddress: hadoop-998-6:8042, Resource: <memory:1024, vCores:1>, Priority: 20, State: NEW, Token: null, Status: container_id {, app_attempt_id {, application_id {, id: 6, cluster_timestamp: 1377141553101, }, attemptId: 1, }, id: 21, }, state: C_NEW, ] containerId=container_1377141553101_0006_01_000021 queue=default: capacity=1.0, absoluteCapacity=1.0, usedResources=<memory:29696, vCores:24>usedCapacity=0.6041667, absoluteUsedCapacity=0.6041667, numApps=5, numContainers=24 usedCapacity=0.6041667 absoluteUsedCapacity=0.6041667 used=<memory:29696, vCores:24> cluster=<memory:49152, vCores:96>
2013-08-22 03:35:35,882 INFO org.apache.hadoop.yarn.server.resourcemanager.scheduler.capacity.ParentQueue: Re-sorting queues since queue: root.default stats: default: capacity=1.0, absoluteCapacity=1.0, usedResources=<memory:30720, vCores:25>usedCapacity=0.625, absoluteUsedCapacity=0.625, numApps=5, numContainers=25
2013-08-22 03:35:35,882 INFO org.apache.hadoop.yarn.server.resourcemanager.scheduler.capacity.ParentQueue: assignedContainer queue=root usedCapacity=0.625 absoluteUsedCapacity=0.625 used=<memory:30720, vCores:25> cluster=<memory:49152, vCores:96>
2013-08-22 03:35:36,055 INFO org.apache.hadoop.yarn.server.resourcemanager.rmcontainer.RMContainerImpl: container_1377141553101_0006_01_000022 Container Transitioned from NEW to ALLOCATED
2013-08-22 03:35:36,055 INFO org.apache.hadoop.yarn.server.resourcemanager.RMAuditLogger: USER=ubuntu	OPERATION=AM Allocated Container	TARGET=SchedulerApp	RESULT=SUCCESS	APPID=application_1377141553101_0006	CONTAINERID=container_1377141553101_0006_01_000022
2013-08-22 03:35:36,055 INFO org.apache.hadoop.yarn.server.resourcemanager.scheduler.common.fica.FiCaSchedulerNode: Assigned container container_1377141553101_0006_01_000022 of capacity <memory:1024, vCores:1> on host hadoop-998-5:56087, which currently has 2 containers, <memory:3072, vCores:2> used and <memory:5120, vCores:14> available
2013-08-22 03:35:36,056 INFO org.apache.hadoop.yarn.server.resourcemanager.scheduler.capacity.LeafQueue: assignedContainer application=application_1377141553101_0006 container=Container: [ContainerId: container_1377141553101_0006_01_000022, NodeId: hadoop-998-5:56087, NodeHttpAddress: hadoop-998-5:8042, Resource: <memory:1024, vCores:1>, Priority: 20, State: NEW, Token: null, Status: container_id {, app_attempt_id {, application_id {, id: 6, cluster_timestamp: 1377141553101, }, attemptId: 1, }, id: 22, }, state: C_NEW, ] containerId=container_1377141553101_0006_01_000022 queue=default: capacity=1.0, absoluteCapacity=1.0, usedResources=<memory:30720, vCores:25>usedCapacity=0.625, absoluteUsedCapacity=0.625, numApps=5, numContainers=25 usedCapacity=0.625 absoluteUsedCapacity=0.625 used=<memory:30720, vCores:25> cluster=<memory:49152, vCores:96>
2013-08-22 03:35:36,057 INFO org.apache.hadoop.yarn.server.resourcemanager.scheduler.capacity.ParentQueue: Re-sorting queues since queue: root.default stats: default: capacity=1.0, absoluteCapacity=1.0, usedResources=<memory:31744, vCores:26>usedCapacity=0.6458333, absoluteUsedCapacity=0.6458333, numApps=5, numContainers=26
2013-08-22 03:35:36,057 INFO org.apache.hadoop.yarn.server.resourcemanager.scheduler.capacity.ParentQueue: assignedContainer queue=root usedCapacity=0.6458333 absoluteUsedCapacity=0.6458333 used=<memory:31744, vCores:26> cluster=<memory:49152, vCores:96>
2013-08-22 03:35:36,057 INFO org.apache.hadoop.yarn.server.resourcemanager.rmcontainer.RMContainerImpl: container_1377141553101_0006_01_000023 Container Transitioned from NEW to ALLOCATED
2013-08-22 03:35:36,058 INFO org.apache.hadoop.yarn.server.resourcemanager.RMAuditLogger: USER=ubuntu	OPERATION=AM Allocated Container	TARGET=SchedulerApp	RESULT=SUCCESS	APPID=application_1377141553101_0006	CONTAINERID=container_1377141553101_0006_01_000023
2013-08-22 03:35:36,058 INFO org.apache.hadoop.yarn.server.resourcemanager.scheduler.common.fica.FiCaSchedulerNode: Assigned container container_1377141553101_0006_01_000023 of capacity <memory:1024, vCores:1> on host hadoop-998-5:56087, which currently has 3 containers, <memory:4096, vCores:3> used and <memory:4096, vCores:13> available
2013-08-22 03:35:36,059 INFO org.apache.hadoop.yarn.server.resourcemanager.scheduler.capacity.LeafQueue: assignedContainer application=application_1377141553101_0006 container=Container: [ContainerId: container_1377141553101_0006_01_000023, NodeId: hadoop-998-5:56087, NodeHttpAddress: hadoop-998-5:8042, Resource: <memory:1024, vCores:1>, Priority: 20, State: NEW, Token: null, Status: container_id {, app_attempt_id {, application_id {, id: 6, cluster_timestamp: 1377141553101, }, attemptId: 1, }, id: 23, }, state: C_NEW, ] containerId=container_1377141553101_0006_01_000023 queue=default: capacity=1.0, absoluteCapacity=1.0, usedResources=<memory:31744, vCores:26>usedCapacity=0.6458333, absoluteUsedCapacity=0.6458333, numApps=5, numContainers=26 usedCapacity=0.6458333 absoluteUsedCapacity=0.6458333 used=<memory:31744, vCores:26> cluster=<memory:49152, vCores:96>
2013-08-22 03:35:36,059 INFO org.apache.hadoop.yarn.server.resourcemanager.scheduler.capacity.ParentQueue: Re-sorting queues since queue: root.default stats: default: capacity=1.0, absoluteCapacity=1.0, usedResources=<memory:32768, vCores:27>usedCapacity=0.6666667, absoluteUsedCapacity=0.6666667, numApps=5, numContainers=27
2013-08-22 03:35:36,059 INFO org.apache.hadoop.yarn.server.resourcemanager.scheduler.capacity.ParentQueue: assignedContainer queue=root usedCapacity=0.6666667 absoluteUsedCapacity=0.6666667 used=<memory:32768, vCores:27> cluster=<memory:49152, vCores:96>
2013-08-22 03:35:36,060 INFO org.apache.hadoop.yarn.server.resourcemanager.rmcontainer.RMContainerImpl: container_1377141553101_0006_01_000024 Container Transitioned from NEW to ALLOCATED
2013-08-22 03:35:36,060 INFO org.apache.hadoop.yarn.server.resourcemanager.RMAuditLogger: USER=ubuntu	OPERATION=AM Allocated Container	TARGET=SchedulerApp	RESULT=SUCCESS	APPID=application_1377141553101_0006	CONTAINERID=container_1377141553101_0006_01_000024
2013-08-22 03:35:36,060 INFO org.apache.hadoop.yarn.server.resourcemanager.scheduler.common.fica.FiCaSchedulerNode: Assigned container container_1377141553101_0006_01_000024 of capacity <memory:1024, vCores:1> on host hadoop-998-5:56087, which currently has 4 containers, <memory:5120, vCores:4> used and <memory:3072, vCores:12> available
2013-08-22 03:35:36,061 INFO org.apache.hadoop.yarn.server.resourcemanager.scheduler.capacity.LeafQueue: assignedContainer application=application_1377141553101_0006 container=Container: [ContainerId: container_1377141553101_0006_01_000024, NodeId: hadoop-998-5:56087, NodeHttpAddress: hadoop-998-5:8042, Resource: <memory:1024, vCores:1>, Priority: 20, State: NEW, Token: null, Status: container_id {, app_attempt_id {, application_id {, id: 6, cluster_timestamp: 1377141553101, }, attemptId: 1, }, id: 24, }, state: C_NEW, ] containerId=container_1377141553101_0006_01_000024 queue=default: capacity=1.0, absoluteCapacity=1.0, usedResources=<memory:32768, vCores:27>usedCapacity=0.6666667, absoluteUsedCapacity=0.6666667, numApps=5, numContainers=27 usedCapacity=0.6666667 absoluteUsedCapacity=0.6666667 used=<memory:32768, vCores:27> cluster=<memory:49152, vCores:96>
2013-08-22 03:35:36,061 INFO org.apache.hadoop.yarn.server.resourcemanager.scheduler.capacity.ParentQueue: Re-sorting queues since queue: root.default stats: default: capacity=1.0, absoluteCapacity=1.0, usedResources=<memory:33792, vCores:28>usedCapacity=0.6875, absoluteUsedCapacity=0.6875, numApps=5, numContainers=28
2013-08-22 03:35:36,061 INFO org.apache.hadoop.yarn.server.resourcemanager.scheduler.capacity.ParentQueue: assignedContainer queue=root usedCapacity=0.6875 absoluteUsedCapacity=0.6875 used=<memory:33792, vCores:28> cluster=<memory:49152, vCores:96>
2013-08-22 03:35:36,062 INFO org.apache.hadoop.yarn.server.resourcemanager.rmcontainer.RMContainerImpl: container_1377141553101_0006_01_000025 Container Transitioned from NEW to ALLOCATED
2013-08-22 03:35:36,062 INFO org.apache.hadoop.yarn.server.resourcemanager.RMAuditLogger: USER=ubuntu	OPERATION=AM Allocated Container	TARGET=SchedulerApp	RESULT=SUCCESS	APPID=application_1377141553101_0006	CONTAINERID=container_1377141553101_0006_01_000025
2013-08-22 03:35:36,062 INFO org.apache.hadoop.yarn.server.resourcemanager.scheduler.common.fica.FiCaSchedulerNode: Assigned container container_1377141553101_0006_01_000025 of capacity <memory:1024, vCores:1> on host hadoop-998-5:56087, which currently has 5 containers, <memory:6144, vCores:5> used and <memory:2048, vCores:11> available
2013-08-22 03:35:36,063 INFO org.apache.hadoop.yarn.server.resourcemanager.scheduler.capacity.LeafQueue: assignedContainer application=application_1377141553101_0006 container=Container: [ContainerId: container_1377141553101_0006_01_000025, NodeId: hadoop-998-5:56087, NodeHttpAddress: hadoop-998-5:8042, Resource: <memory:1024, vCores:1>, Priority: 20, State: NEW, Token: null, Status: container_id {, app_attempt_id {, application_id {, id: 6, cluster_timestamp: 1377141553101, }, attemptId: 1, }, id: 25, }, state: C_NEW, ] containerId=container_1377141553101_0006_01_000025 queue=default: capacity=1.0, absoluteCapacity=1.0, usedResources=<memory:33792, vCores:28>usedCapacity=0.6875, absoluteUsedCapacity=0.6875, numApps=5, numContainers=28 usedCapacity=0.6875 absoluteUsedCapacity=0.6875 used=<memory:33792, vCores:28> cluster=<memory:49152, vCores:96>
2013-08-22 03:35:36,063 INFO org.apache.hadoop.yarn.server.resourcemanager.scheduler.capacity.ParentQueue: Re-sorting queues since queue: root.default stats: default: capacity=1.0, absoluteCapacity=1.0, usedResources=<memory:34816, vCores:29>usedCapacity=0.7083333, absoluteUsedCapacity=0.7083333, numApps=5, numContainers=29
2013-08-22 03:35:36,063 INFO org.apache.hadoop.yarn.server.resourcemanager.scheduler.capacity.ParentQueue: assignedContainer queue=root usedCapacity=0.7083333 absoluteUsedCapacity=0.7083333 used=<memory:34816, vCores:29> cluster=<memory:49152, vCores:96>
2013-08-22 03:35:36,064 INFO org.apache.hadoop.yarn.server.resourcemanager.rmcontainer.RMContainerImpl: container_1377141553101_0006_01_000026 Container Transitioned from NEW to ALLOCATED
2013-08-22 03:35:36,064 INFO org.apache.hadoop.yarn.server.resourcemanager.RMAuditLogger: USER=ubuntu	OPERATION=AM Allocated Container	TARGET=SchedulerApp	RESULT=SUCCESS	APPID=application_1377141553101_0006	CONTAINERID=container_1377141553101_0006_01_000026
2013-08-22 03:35:36,064 INFO org.apache.hadoop.yarn.server.resourcemanager.scheduler.common.fica.FiCaSchedulerNode: Assigned container container_1377141553101_0006_01_000026 of capacity <memory:1024, vCores:1> on host hadoop-998-5:56087, which currently has 6 containers, <memory:7168, vCores:6> used and <memory:1024, vCores:10> available
2013-08-22 03:35:36,065 INFO org.apache.hadoop.yarn.server.resourcemanager.scheduler.capacity.LeafQueue: assignedContainer application=application_1377141553101_0006 container=Container: [ContainerId: container_1377141553101_0006_01_000026, NodeId: hadoop-998-5:56087, NodeHttpAddress: hadoop-998-5:8042, Resource: <memory:1024, vCores:1>, Priority: 20, State: NEW, Token: null, Status: container_id {, app_attempt_id {, application_id {, id: 6, cluster_timestamp: 1377141553101, }, attemptId: 1, }, id: 26, }, state: C_NEW, ] containerId=container_1377141553101_0006_01_000026 queue=default: capacity=1.0, absoluteCapacity=1.0, usedResources=<memory:34816, vCores:29>usedCapacity=0.7083333, absoluteUsedCapacity=0.7083333, numApps=5, numContainers=29 usedCapacity=0.7083333 absoluteUsedCapacity=0.7083333 used=<memory:34816, vCores:29> cluster=<memory:49152, vCores:96>
2013-08-22 03:35:36,065 INFO org.apache.hadoop.yarn.server.resourcemanager.scheduler.capacity.ParentQueue: Re-sorting queues since queue: root.default stats: default: capacity=1.0, absoluteCapacity=1.0, usedResources=<memory:35840, vCores:30>usedCapacity=0.7291667, absoluteUsedCapacity=0.7291667, numApps=5, numContainers=30
2013-08-22 03:35:36,066 INFO org.apache.hadoop.yarn.server.resourcemanager.scheduler.capacity.ParentQueue: assignedContainer queue=root usedCapacity=0.7291667 absoluteUsedCapacity=0.7291667 used=<memory:35840, vCores:30> cluster=<memory:49152, vCores:96>
2013-08-22 03:35:36,066 INFO org.apache.hadoop.yarn.server.resourcemanager.rmcontainer.RMContainerImpl: container_1377141553101_0006_01_000027 Container Transitioned from NEW to ALLOCATED
2013-08-22 03:35:36,066 INFO org.apache.hadoop.yarn.server.resourcemanager.RMAuditLogger: USER=ubuntu	OPERATION=AM Allocated Container	TARGET=SchedulerApp	RESULT=SUCCESS	APPID=application_1377141553101_0006	CONTAINERID=container_1377141553101_0006_01_000027
2013-08-22 03:35:36,066 INFO org.apache.hadoop.yarn.server.resourcemanager.scheduler.common.fica.FiCaSchedulerNode: Assigned container container_1377141553101_0006_01_000027 of capacity <memory:1024, vCores:1> on host hadoop-998-5:56087, which currently has 7 containers, <memory:8192, vCores:7> used and <memory:0, vCores:9> available
2013-08-22 03:35:36,067 INFO org.apache.hadoop.yarn.server.resourcemanager.scheduler.capacity.LeafQueue: assignedContainer application=application_1377141553101_0006 container=Container: [ContainerId: container_1377141553101_0006_01_000027, NodeId: hadoop-998-5:56087, NodeHttpAddress: hadoop-998-5:8042, Resource: <memory:1024, vCores:1>, Priority: 20, State: NEW, Token: null, Status: container_id {, app_attempt_id {, application_id {, id: 6, cluster_timestamp: 1377141553101, }, attemptId: 1, }, id: 27, }, state: C_NEW, ] containerId=container_1377141553101_0006_01_000027 queue=default: capacity=1.0, absoluteCapacity=1.0, usedResources=<memory:35840, vCores:30>usedCapacity=0.7291667, absoluteUsedCapacity=0.7291667, numApps=5, numContainers=30 usedCapacity=0.7291667 absoluteUsedCapacity=0.7291667 used=<memory:35840, vCores:30> cluster=<memory:49152, vCores:96>
2013-08-22 03:35:36,068 INFO org.apache.hadoop.yarn.server.resourcemanager.scheduler.capacity.ParentQueue: Re-sorting queues since queue: root.default stats: default: capacity=1.0, absoluteCapacity=1.0, usedResources=<memory:36864, vCores:31>usedCapacity=0.75, absoluteUsedCapacity=0.75, numApps=5, numContainers=31
2013-08-22 03:35:36,068 INFO org.apache.hadoop.yarn.server.resourcemanager.scheduler.capacity.ParentQueue: assignedContainer queue=root usedCapacity=0.75 absoluteUsedCapacity=0.75 used=<memory:36864, vCores:31> cluster=<memory:49152, vCores:96>
2013-08-22 03:35:36,305 INFO org.apache.hadoop.yarn.server.resourcemanager.ApplicationMasterService: AM registration appattempt_1377141553101_0007_000001
2013-08-22 03:35:36,306 INFO org.apache.hadoop.yarn.server.resourcemanager.RMAuditLogger: USER=ubuntu	IP=192.168.100.6	OPERATION=Register App Master	TARGET=ApplicationMasterService	RESULT=SUCCESS	APPID=application_1377141553101_0007	APPATTEMPTID=appattempt_1377141553101_0007_000001
2013-08-22 03:35:36,307 INFO org.apache.hadoop.yarn.server.resourcemanager.rmapp.attempt.RMAppAttemptImpl: appattempt_1377141553101_0007_000001 State change from LAUNCHED to RUNNING
2013-08-22 03:35:36,307 INFO org.apache.hadoop.yarn.server.resourcemanager.rmapp.RMAppImpl: application_1377141553101_0007 State change from ACCEPTED to RUNNING
2013-08-22 03:35:36,420 INFO org.apache.hadoop.yarn.server.resourcemanager.rmcontainer.RMContainerImpl: container_1377141553101_0006_01_000028 Container Transitioned from NEW to ALLOCATED
2013-08-22 03:35:36,421 INFO org.apache.hadoop.yarn.server.resourcemanager.RMAuditLogger: USER=ubuntu	OPERATION=AM Allocated Container	TARGET=SchedulerApp	RESULT=SUCCESS	APPID=application_1377141553101_0006	CONTAINERID=container_1377141553101_0006_01_000028
2013-08-22 03:35:36,421 INFO org.apache.hadoop.yarn.server.resourcemanager.scheduler.common.fica.FiCaSchedulerNode: Assigned container container_1377141553101_0006_01_000028 of capacity <memory:1024, vCores:1> on host hadoop-998-3:53776, which currently has 2 containers, <memory:3072, vCores:2> used and <memory:5120, vCores:14> available
2013-08-22 03:35:36,422 INFO org.apache.hadoop.yarn.server.resourcemanager.scheduler.capacity.LeafQueue: assignedContainer application=application_1377141553101_0006 container=Container: [ContainerId: container_1377141553101_0006_01_000028, NodeId: hadoop-998-3:53776, NodeHttpAddress: hadoop-998-3:8042, Resource: <memory:1024, vCores:1>, Priority: 20, State: NEW, Token: null, Status: container_id {, app_attempt_id {, application_id {, id: 6, cluster_timestamp: 1377141553101, }, attemptId: 1, }, id: 28, }, state: C_NEW, ] containerId=container_1377141553101_0006_01_000028 queue=default: capacity=1.0, absoluteCapacity=1.0, usedResources=<memory:36864, vCores:31>usedCapacity=0.75, absoluteUsedCapacity=0.75, numApps=5, numContainers=31 usedCapacity=0.75 absoluteUsedCapacity=0.75 used=<memory:36864, vCores:31> cluster=<memory:49152, vCores:96>
2013-08-22 03:35:36,422 INFO org.apache.hadoop.yarn.server.resourcemanager.scheduler.capacity.ParentQueue: Re-sorting queues since queue: root.default stats: default: capacity=1.0, absoluteCapacity=1.0, usedResources=<memory:37888, vCores:32>usedCapacity=0.7708333, absoluteUsedCapacity=0.7708333, numApps=5, numContainers=32
2013-08-22 03:35:36,422 INFO org.apache.hadoop.yarn.server.resourcemanager.scheduler.capacity.ParentQueue: assignedContainer queue=root usedCapacity=0.7708333 absoluteUsedCapacity=0.7708333 used=<memory:37888, vCores:32> cluster=<memory:49152, vCores:96>
2013-08-22 03:35:36,423 INFO org.apache.hadoop.yarn.server.resourcemanager.rmcontainer.RMContainerImpl: container_1377141553101_0006_01_000029 Container Transitioned from NEW to ALLOCATED
2013-08-22 03:35:36,423 INFO org.apache.hadoop.yarn.server.resourcemanager.RMAuditLogger: USER=ubuntu	OPERATION=AM Allocated Container	TARGET=SchedulerApp	RESULT=SUCCESS	APPID=application_1377141553101_0006	CONTAINERID=container_1377141553101_0006_01_000029
2013-08-22 03:35:36,423 INFO org.apache.hadoop.yarn.server.resourcemanager.scheduler.common.fica.FiCaSchedulerNode: Assigned container container_1377141553101_0006_01_000029 of capacity <memory:1024, vCores:1> on host hadoop-998-3:53776, which currently has 3 containers, <memory:4096, vCores:3> used and <memory:4096, vCores:13> available
2013-08-22 03:35:36,424 INFO org.apache.hadoop.yarn.server.resourcemanager.scheduler.capacity.LeafQueue: assignedContainer application=application_1377141553101_0006 container=Container: [ContainerId: container_1377141553101_0006_01_000029, NodeId: hadoop-998-3:53776, NodeHttpAddress: hadoop-998-3:8042, Resource: <memory:1024, vCores:1>, Priority: 20, State: NEW, Token: null, Status: container_id {, app_attempt_id {, application_id {, id: 6, cluster_timestamp: 1377141553101, }, attemptId: 1, }, id: 29, }, state: C_NEW, ] containerId=container_1377141553101_0006_01_000029 queue=default: capacity=1.0, absoluteCapacity=1.0, usedResources=<memory:37888, vCores:32>usedCapacity=0.7708333, absoluteUsedCapacity=0.7708333, numApps=5, numContainers=32 usedCapacity=0.7708333 absoluteUsedCapacity=0.7708333 used=<memory:37888, vCores:32> cluster=<memory:49152, vCores:96>
2013-08-22 03:35:36,424 INFO org.apache.hadoop.yarn.server.resourcemanager.scheduler.capacity.ParentQueue: Re-sorting queues since queue: root.default stats: default: capacity=1.0, absoluteCapacity=1.0, usedResources=<memory:38912, vCores:33>usedCapacity=0.7916667, absoluteUsedCapacity=0.7916667, numApps=5, numContainers=33
2013-08-22 03:35:36,425 INFO org.apache.hadoop.yarn.server.resourcemanager.scheduler.capacity.ParentQueue: assignedContainer queue=root usedCapacity=0.7916667 absoluteUsedCapacity=0.7916667 used=<memory:38912, vCores:33> cluster=<memory:49152, vCores:96>
2013-08-22 03:35:36,425 INFO org.apache.hadoop.yarn.server.resourcemanager.rmcontainer.RMContainerImpl: container_1377141553101_0006_01_000030 Container Transitioned from NEW to ALLOCATED
2013-08-22 03:35:36,425 INFO org.apache.hadoop.yarn.server.resourcemanager.RMAuditLogger: USER=ubuntu	OPERATION=AM Allocated Container	TARGET=SchedulerApp	RESULT=SUCCESS	APPID=application_1377141553101_0006	CONTAINERID=container_1377141553101_0006_01_000030
2013-08-22 03:35:36,425 INFO org.apache.hadoop.yarn.server.resourcemanager.scheduler.common.fica.FiCaSchedulerNode: Assigned container container_1377141553101_0006_01_000030 of capacity <memory:1024, vCores:1> on host hadoop-998-3:53776, which currently has 4 containers, <memory:5120, vCores:4> used and <memory:3072, vCores:12> available
2013-08-22 03:35:36,426 INFO org.apache.hadoop.yarn.server.resourcemanager.scheduler.capacity.LeafQueue: assignedContainer application=application_1377141553101_0006 container=Container: [ContainerId: container_1377141553101_0006_01_000030, NodeId: hadoop-998-3:53776, NodeHttpAddress: hadoop-998-3:8042, Resource: <memory:1024, vCores:1>, Priority: 20, State: NEW, Token: null, Status: container_id {, app_attempt_id {, application_id {, id: 6, cluster_timestamp: 1377141553101, }, attemptId: 1, }, id: 30, }, state: C_NEW, ] containerId=container_1377141553101_0006_01_000030 queue=default: capacity=1.0, absoluteCapacity=1.0, usedResources=<memory:38912, vCores:33>usedCapacity=0.7916667, absoluteUsedCapacity=0.7916667, numApps=5, numContainers=33 usedCapacity=0.7916667 absoluteUsedCapacity=0.7916667 used=<memory:38912, vCores:33> cluster=<memory:49152, vCores:96>
2013-08-22 03:35:36,427 INFO org.apache.hadoop.yarn.server.resourcemanager.scheduler.capacity.ParentQueue: Re-sorting queues since queue: root.default stats: default: capacity=1.0, absoluteCapacity=1.0, usedResources=<memory:39936, vCores:34>usedCapacity=0.8125, absoluteUsedCapacity=0.8125, numApps=5, numContainers=34
2013-08-22 03:35:36,427 INFO org.apache.hadoop.yarn.server.resourcemanager.scheduler.capacity.ParentQueue: assignedContainer queue=root usedCapacity=0.8125 absoluteUsedCapacity=0.8125 used=<memory:39936, vCores:34> cluster=<memory:49152, vCores:96>
2013-08-22 03:35:36,427 INFO org.apache.hadoop.yarn.server.resourcemanager.rmcontainer.RMContainerImpl: container_1377141553101_0006_01_000031 Container Transitioned from NEW to ALLOCATED
2013-08-22 03:35:36,427 INFO org.apache.hadoop.yarn.server.resourcemanager.RMAuditLogger: USER=ubuntu	OPERATION=AM Allocated Container	TARGET=SchedulerApp	RESULT=SUCCESS	APPID=application_1377141553101_0006	CONTAINERID=container_1377141553101_0006_01_000031
2013-08-22 03:35:36,427 INFO org.apache.hadoop.yarn.server.resourcemanager.scheduler.common.fica.FiCaSchedulerNode: Assigned container container_1377141553101_0006_01_000031 of capacity <memory:1024, vCores:1> on host hadoop-998-3:53776, which currently has 5 containers, <memory:6144, vCores:5> used and <memory:2048, vCores:11> available
2013-08-22 03:35:36,428 INFO org.apache.hadoop.yarn.server.resourcemanager.scheduler.capacity.LeafQueue: assignedContainer application=application_1377141553101_0006 container=Container: [ContainerId: container_1377141553101_0006_01_000031, NodeId: hadoop-998-3:53776, NodeHttpAddress: hadoop-998-3:8042, Resource: <memory:1024, vCores:1>, Priority: 20, State: NEW, Token: null, Status: container_id {, app_attempt_id {, application_id {, id: 6, cluster_timestamp: 1377141553101, }, attemptId: 1, }, id: 31, }, state: C_NEW, ] containerId=container_1377141553101_0006_01_000031 queue=default: capacity=1.0, absoluteCapacity=1.0, usedResources=<memory:39936, vCores:34>usedCapacity=0.8125, absoluteUsedCapacity=0.8125, numApps=5, numContainers=34 usedCapacity=0.8125 absoluteUsedCapacity=0.8125 used=<memory:39936, vCores:34> cluster=<memory:49152, vCores:96>
2013-08-22 03:35:36,429 INFO org.apache.hadoop.yarn.server.resourcemanager.scheduler.capacity.ParentQueue: Re-sorting queues since queue: root.default stats: default: capacity=1.0, absoluteCapacity=1.0, usedResources=<memory:40960, vCores:35>usedCapacity=0.8333333, absoluteUsedCapacity=0.8333333, numApps=5, numContainers=35
2013-08-22 03:35:36,429 INFO org.apache.hadoop.yarn.server.resourcemanager.scheduler.capacity.ParentQueue: assignedContainer queue=root usedCapacity=0.8333333 absoluteUsedCapacity=0.8333333 used=<memory:40960, vCores:35> cluster=<memory:49152, vCores:96>
2013-08-22 03:35:36,429 INFO org.apache.hadoop.yarn.server.resourcemanager.rmcontainer.RMContainerImpl: container_1377141553101_0006_01_000032 Container Transitioned from NEW to ALLOCATED
2013-08-22 03:35:36,429 INFO org.apache.hadoop.yarn.server.resourcemanager.RMAuditLogger: USER=ubuntu	OPERATION=AM Allocated Container	TARGET=SchedulerApp	RESULT=SUCCESS	APPID=application_1377141553101_0006	CONTAINERID=container_1377141553101_0006_01_000032
2013-08-22 03:35:36,430 INFO org.apache.hadoop.yarn.server.resourcemanager.scheduler.common.fica.FiCaSchedulerNode: Assigned container container_1377141553101_0006_01_000032 of capacity <memory:1024, vCores:1> on host hadoop-998-3:53776, which currently has 6 containers, <memory:7168, vCores:6> used and <memory:1024, vCores:10> available
2013-08-22 03:35:36,431 INFO org.apache.hadoop.yarn.server.resourcemanager.scheduler.capacity.LeafQueue: assignedContainer application=application_1377141553101_0006 container=Container: [ContainerId: container_1377141553101_0006_01_000032, NodeId: hadoop-998-3:53776, NodeHttpAddress: hadoop-998-3:8042, Resource: <memory:1024, vCores:1>, Priority: 20, State: NEW, Token: null, Status: container_id {, app_attempt_id {, application_id {, id: 6, cluster_timestamp: 1377141553101, }, attemptId: 1, }, id: 32, }, state: C_NEW, ] containerId=container_1377141553101_0006_01_000032 queue=default: capacity=1.0, absoluteCapacity=1.0, usedResources=<memory:40960, vCores:35>usedCapacity=0.8333333, absoluteUsedCapacity=0.8333333, numApps=5, numContainers=35 usedCapacity=0.8333333 absoluteUsedCapacity=0.8333333 used=<memory:40960, vCores:35> cluster=<memory:49152, vCores:96>
2013-08-22 03:35:36,431 INFO org.apache.hadoop.yarn.server.resourcemanager.scheduler.capacity.ParentQueue: Re-sorting queues since queue: root.default stats: default: capacity=1.0, absoluteCapacity=1.0, usedResources=<memory:41984, vCores:36>usedCapacity=0.8541667, absoluteUsedCapacity=0.8541667, numApps=5, numContainers=36
2013-08-22 03:35:36,431 INFO org.apache.hadoop.yarn.server.resourcemanager.scheduler.capacity.ParentQueue: assignedContainer queue=root usedCapacity=0.8541667 absoluteUsedCapacity=0.8541667 used=<memory:41984, vCores:36> cluster=<memory:49152, vCores:96>
2013-08-22 03:35:36,431 INFO org.apache.hadoop.yarn.server.resourcemanager.rmcontainer.RMContainerImpl: container_1377141553101_0006_01_000033 Container Transitioned from NEW to ALLOCATED
2013-08-22 03:35:36,432 INFO org.apache.hadoop.yarn.server.resourcemanager.RMAuditLogger: USER=ubuntu	OPERATION=AM Allocated Container	TARGET=SchedulerApp	RESULT=SUCCESS	APPID=application_1377141553101_0006	CONTAINERID=container_1377141553101_0006_01_000033
2013-08-22 03:35:36,432 INFO org.apache.hadoop.yarn.server.resourcemanager.scheduler.common.fica.FiCaSchedulerNode: Assigned container container_1377141553101_0006_01_000033 of capacity <memory:1024, vCores:1> on host hadoop-998-3:53776, which currently has 7 containers, <memory:8192, vCores:7> used and <memory:0, vCores:9> available
2013-08-22 03:35:36,433 INFO org.apache.hadoop.yarn.server.resourcemanager.scheduler.capacity.LeafQueue: assignedContainer application=application_1377141553101_0006 container=Container: [ContainerId: container_1377141553101_0006_01_000033, NodeId: hadoop-998-3:53776, NodeHttpAddress: hadoop-998-3:8042, Resource: <memory:1024, vCores:1>, Priority: 20, State: NEW, Token: null, Status: container_id {, app_attempt_id {, application_id {, id: 6, cluster_timestamp: 1377141553101, }, attemptId: 1, }, id: 33, }, state: C_NEW, ] containerId=container_1377141553101_0006_01_000033 queue=default: capacity=1.0, absoluteCapacity=1.0, usedResources=<memory:41984, vCores:36>usedCapacity=0.8541667, absoluteUsedCapacity=0.8541667, numApps=5, numContainers=36 usedCapacity=0.8541667 absoluteUsedCapacity=0.8541667 used=<memory:41984, vCores:36> cluster=<memory:49152, vCores:96>
2013-08-22 03:35:36,433 INFO org.apache.hadoop.yarn.server.resourcemanager.scheduler.capacity.ParentQueue: Re-sorting queues since queue: root.default stats: default: capacity=1.0, absoluteCapacity=1.0, usedResources=<memory:43008, vCores:37>usedCapacity=0.875, absoluteUsedCapacity=0.875, numApps=5, numContainers=37
2013-08-22 03:35:36,433 INFO org.apache.hadoop.yarn.server.resourcemanager.scheduler.capacity.ParentQueue: assignedContainer queue=root usedCapacity=0.875 absoluteUsedCapacity=0.875 used=<memory:43008, vCores:37> cluster=<memory:49152, vCores:96>
2013-08-22 03:35:36,543 INFO org.apache.hadoop.yarn.server.resourcemanager.rmcontainer.RMContainerImpl: container_1377141553101_0006_01_000034 Container Transitioned from NEW to ALLOCATED
2013-08-22 03:35:36,543 INFO org.apache.hadoop.yarn.server.resourcemanager.RMAuditLogger: USER=ubuntu	OPERATION=AM Allocated Container	TARGET=SchedulerApp	RESULT=SUCCESS	APPID=application_1377141553101_0006	CONTAINERID=container_1377141553101_0006_01_000034
2013-08-22 03:35:36,543 INFO org.apache.hadoop.yarn.server.resourcemanager.scheduler.common.fica.FiCaSchedulerNode: Assigned container container_1377141553101_0006_01_000034 of capacity <memory:1024, vCores:1> on host hadoop-998-4:35553, which currently has 2 containers, <memory:3072, vCores:2> used and <memory:5120, vCores:14> available
2013-08-22 03:35:36,544 INFO org.apache.hadoop.yarn.server.resourcemanager.scheduler.capacity.LeafQueue: assignedContainer application=application_1377141553101_0006 container=Container: [ContainerId: container_1377141553101_0006_01_000034, NodeId: hadoop-998-4:35553, NodeHttpAddress: hadoop-998-4:8042, Resource: <memory:1024, vCores:1>, Priority: 20, State: NEW, Token: null, Status: container_id {, app_attempt_id {, application_id {, id: 6, cluster_timestamp: 1377141553101, }, attemptId: 1, }, id: 34, }, state: C_NEW, ] containerId=container_1377141553101_0006_01_000034 queue=default: capacity=1.0, absoluteCapacity=1.0, usedResources=<memory:43008, vCores:37>usedCapacity=0.875, absoluteUsedCapacity=0.875, numApps=5, numContainers=37 usedCapacity=0.875 absoluteUsedCapacity=0.875 used=<memory:43008, vCores:37> cluster=<memory:49152, vCores:96>
2013-08-22 03:35:36,544 INFO org.apache.hadoop.yarn.server.resourcemanager.scheduler.capacity.ParentQueue: Re-sorting queues since queue: root.default stats: default: capacity=1.0, absoluteCapacity=1.0, usedResources=<memory:44032, vCores:38>usedCapacity=0.8958333, absoluteUsedCapacity=0.8958333, numApps=5, numContainers=38
2013-08-22 03:35:36,545 INFO org.apache.hadoop.yarn.server.resourcemanager.scheduler.capacity.ParentQueue: assignedContainer queue=root usedCapacity=0.8958333 absoluteUsedCapacity=0.8958333 used=<memory:44032, vCores:38> cluster=<memory:49152, vCores:96>
2013-08-22 03:35:36,545 INFO org.apache.hadoop.yarn.server.resourcemanager.rmcontainer.RMContainerImpl: container_1377141553101_0006_01_000035 Container Transitioned from NEW to ALLOCATED
2013-08-22 03:35:36,545 INFO org.apache.hadoop.yarn.server.resourcemanager.RMAuditLogger: USER=ubuntu	OPERATION=AM Allocated Container	TARGET=SchedulerApp	RESULT=SUCCESS	APPID=application_1377141553101_0006	CONTAINERID=container_1377141553101_0006_01_000035
2013-08-22 03:35:36,545 INFO org.apache.hadoop.yarn.server.resourcemanager.scheduler.common.fica.FiCaSchedulerNode: Assigned container container_1377141553101_0006_01_000035 of capacity <memory:1024, vCores:1> on host hadoop-998-4:35553, which currently has 3 containers, <memory:4096, vCores:3> used and <memory:4096, vCores:13> available
2013-08-22 03:35:36,546 INFO org.apache.hadoop.yarn.server.resourcemanager.scheduler.capacity.LeafQueue: assignedContainer application=application_1377141553101_0006 container=Container: [ContainerId: container_1377141553101_0006_01_000035, NodeId: hadoop-998-4:35553, NodeHttpAddress: hadoop-998-4:8042, Resource: <memory:1024, vCores:1>, Priority: 20, State: NEW, Token: null, Status: container_id {, app_attempt_id {, application_id {, id: 6, cluster_timestamp: 1377141553101, }, attemptId: 1, }, id: 35, }, state: C_NEW, ] containerId=container_1377141553101_0006_01_000035 queue=default: capacity=1.0, absoluteCapacity=1.0, usedResources=<memory:44032, vCores:38>usedCapacity=0.8958333, absoluteUsedCapacity=0.8958333, numApps=5, numContainers=38 usedCapacity=0.8958333 absoluteUsedCapacity=0.8958333 used=<memory:44032, vCores:38> cluster=<memory:49152, vCores:96>
2013-08-22 03:35:36,547 INFO org.apache.hadoop.yarn.server.resourcemanager.scheduler.capacity.ParentQueue: Re-sorting queues since queue: root.default stats: default: capacity=1.0, absoluteCapacity=1.0, usedResources=<memory:45056, vCores:39>usedCapacity=0.9166667, absoluteUsedCapacity=0.9166667, numApps=5, numContainers=39
2013-08-22 03:35:36,547 INFO org.apache.hadoop.yarn.server.resourcemanager.scheduler.capacity.ParentQueue: assignedContainer queue=root usedCapacity=0.9166667 absoluteUsedCapacity=0.9166667 used=<memory:45056, vCores:39> cluster=<memory:49152, vCores:96>
2013-08-22 03:35:36,547 INFO org.apache.hadoop.yarn.server.resourcemanager.rmcontainer.RMContainerImpl: container_1377141553101_0006_01_000036 Container Transitioned from NEW to ALLOCATED
2013-08-22 03:35:36,547 INFO org.apache.hadoop.yarn.server.resourcemanager.RMAuditLogger: USER=ubuntu	OPERATION=AM Allocated Container	TARGET=SchedulerApp	RESULT=SUCCESS	APPID=application_1377141553101_0006	CONTAINERID=container_1377141553101_0006_01_000036
2013-08-22 03:35:36,548 INFO org.apache.hadoop.yarn.server.resourcemanager.scheduler.common.fica.FiCaSchedulerNode: Assigned container container_1377141553101_0006_01_000036 of capacity <memory:1024, vCores:1> on host hadoop-998-4:35553, which currently has 4 containers, <memory:5120, vCores:4> used and <memory:3072, vCores:12> available
2013-08-22 03:35:36,549 INFO org.apache.hadoop.yarn.server.resourcemanager.scheduler.capacity.LeafQueue: assignedContainer application=application_1377141553101_0006 container=Container: [ContainerId: container_1377141553101_0006_01_000036, NodeId: hadoop-998-4:35553, NodeHttpAddress: hadoop-998-4:8042, Resource: <memory:1024, vCores:1>, Priority: 20, State: NEW, Token: null, Status: container_id {, app_attempt_id {, application_id {, id: 6, cluster_timestamp: 1377141553101, }, attemptId: 1, }, id: 36, }, state: C_NEW, ] containerId=container_1377141553101_0006_01_000036 queue=default: capacity=1.0, absoluteCapacity=1.0, usedResources=<memory:45056, vCores:39>usedCapacity=0.9166667, absoluteUsedCapacity=0.9166667, numApps=5, numContainers=39 usedCapacity=0.9166667 absoluteUsedCapacity=0.9166667 used=<memory:45056, vCores:39> cluster=<memory:49152, vCores:96>
2013-08-22 03:35:36,549 INFO org.apache.hadoop.yarn.server.resourcemanager.scheduler.capacity.ParentQueue: Re-sorting queues since queue: root.default stats: default: capacity=1.0, absoluteCapacity=1.0, usedResources=<memory:46080, vCores:40>usedCapacity=0.9375, absoluteUsedCapacity=0.9375, numApps=5, numContainers=40
2013-08-22 03:35:36,549 INFO org.apache.hadoop.yarn.server.resourcemanager.scheduler.capacity.ParentQueue: assignedContainer queue=root usedCapacity=0.9375 absoluteUsedCapacity=0.9375 used=<memory:46080, vCores:40> cluster=<memory:49152, vCores:96>
2013-08-22 03:35:36,549 INFO org.apache.hadoop.yarn.server.resourcemanager.rmcontainer.RMContainerImpl: container_1377141553101_0006_01_000037 Container Transitioned from NEW to ALLOCATED
2013-08-22 03:35:36,550 INFO org.apache.hadoop.yarn.server.resourcemanager.RMAuditLogger: USER=ubuntu	OPERATION=AM Allocated Container	TARGET=SchedulerApp	RESULT=SUCCESS	APPID=application_1377141553101_0006	CONTAINERID=container_1377141553101_0006_01_000037
2013-08-22 03:35:36,550 INFO org.apache.hadoop.yarn.server.resourcemanager.scheduler.common.fica.FiCaSchedulerNode: Assigned container container_1377141553101_0006_01_000037 of capacity <memory:1024, vCores:1> on host hadoop-998-4:35553, which currently has 5 containers, <memory:6144, vCores:5> used and <memory:2048, vCores:11> available
2013-08-22 03:35:36,551 INFO org.apache.hadoop.yarn.server.resourcemanager.scheduler.capacity.LeafQueue: assignedContainer application=application_1377141553101_0006 container=Container: [ContainerId: container_1377141553101_0006_01_000037, NodeId: hadoop-998-4:35553, NodeHttpAddress: hadoop-998-4:8042, Resource: <memory:1024, vCores:1>, Priority: 20, State: NEW, Token: null, Status: container_id {, app_attempt_id {, application_id {, id: 6, cluster_timestamp: 1377141553101, }, attemptId: 1, }, id: 37, }, state: C_NEW, ] containerId=container_1377141553101_0006_01_000037 queue=default: capacity=1.0, absoluteCapacity=1.0, usedResources=<memory:46080, vCores:40>usedCapacity=0.9375, absoluteUsedCapacity=0.9375, numApps=5, numContainers=40 usedCapacity=0.9375 absoluteUsedCapacity=0.9375 used=<memory:46080, vCores:40> cluster=<memory:49152, vCores:96>
2013-08-22 03:35:36,551 INFO org.apache.hadoop.yarn.server.resourcemanager.scheduler.capacity.ParentQueue: Re-sorting queues since queue: root.default stats: default: capacity=1.0, absoluteCapacity=1.0, usedResources=<memory:47104, vCores:41>usedCapacity=0.9583333, absoluteUsedCapacity=0.9583333, numApps=5, numContainers=41
2013-08-22 03:35:36,551 INFO org.apache.hadoop.yarn.server.resourcemanager.scheduler.capacity.ParentQueue: assignedContainer queue=root usedCapacity=0.9583333 absoluteUsedCapacity=0.9583333 used=<memory:47104, vCores:41> cluster=<memory:49152, vCores:96>
2013-08-22 03:35:36,552 INFO org.apache.hadoop.yarn.server.resourcemanager.rmcontainer.RMContainerImpl: container_1377141553101_0006_01_000038 Container Transitioned from NEW to ALLOCATED
2013-08-22 03:35:36,552 INFO org.apache.hadoop.yarn.server.resourcemanager.RMAuditLogger: USER=ubuntu	OPERATION=AM Allocated Container	TARGET=SchedulerApp	RESULT=SUCCESS	APPID=application_1377141553101_0006	CONTAINERID=container_1377141553101_0006_01_000038
2013-08-22 03:35:36,552 INFO org.apache.hadoop.yarn.server.resourcemanager.scheduler.common.fica.FiCaSchedulerNode: Assigned container container_1377141553101_0006_01_000038 of capacity <memory:1024, vCores:1> on host hadoop-998-4:35553, which currently has 6 containers, <memory:7168, vCores:6> used and <memory:1024, vCores:10> available
2013-08-22 03:35:36,553 INFO org.apache.hadoop.yarn.server.resourcemanager.scheduler.capacity.LeafQueue: assignedContainer application=application_1377141553101_0006 container=Container: [ContainerId: container_1377141553101_0006_01_000038, NodeId: hadoop-998-4:35553, NodeHttpAddress: hadoop-998-4:8042, Resource: <memory:1024, vCores:1>, Priority: 20, State: NEW, Token: null, Status: container_id {, app_attempt_id {, application_id {, id: 6, cluster_timestamp: 1377141553101, }, attemptId: 1, }, id: 38, }, state: C_NEW, ] containerId=container_1377141553101_0006_01_000038 queue=default: capacity=1.0, absoluteCapacity=1.0, usedResources=<memory:47104, vCores:41>usedCapacity=0.9583333, absoluteUsedCapacity=0.9583333, numApps=5, numContainers=41 usedCapacity=0.9583333 absoluteUsedCapacity=0.9583333 used=<memory:47104, vCores:41> cluster=<memory:49152, vCores:96>
2013-08-22 03:35:36,553 INFO org.apache.hadoop.yarn.server.resourcemanager.scheduler.capacity.ParentQueue: Re-sorting queues since queue: root.default stats: default: capacity=1.0, absoluteCapacity=1.0, usedResources=<memory:48128, vCores:42>usedCapacity=0.9791667, absoluteUsedCapacity=0.9791667, numApps=5, numContainers=42
2013-08-22 03:35:36,553 INFO org.apache.hadoop.yarn.server.resourcemanager.scheduler.capacity.ParentQueue: assignedContainer queue=root usedCapacity=0.9791667 absoluteUsedCapacity=0.9791667 used=<memory:48128, vCores:42> cluster=<memory:49152, vCores:96>
2013-08-22 03:35:36,554 INFO org.apache.hadoop.yarn.server.resourcemanager.rmcontainer.RMContainerImpl: container_1377141553101_0006_01_000039 Container Transitioned from NEW to ALLOCATED
2013-08-22 03:35:36,554 INFO org.apache.hadoop.yarn.server.resourcemanager.RMAuditLogger: USER=ubuntu	OPERATION=AM Allocated Container	TARGET=SchedulerApp	RESULT=SUCCESS	APPID=application_1377141553101_0006	CONTAINERID=container_1377141553101_0006_01_000039
2013-08-22 03:35:36,554 INFO org.apache.hadoop.yarn.server.resourcemanager.scheduler.common.fica.FiCaSchedulerNode: Assigned container container_1377141553101_0006_01_000039 of capacity <memory:1024, vCores:1> on host hadoop-998-4:35553, which currently has 7 containers, <memory:8192, vCores:7> used and <memory:0, vCores:9> available
2013-08-22 03:35:36,555 INFO org.apache.hadoop.yarn.server.resourcemanager.scheduler.capacity.LeafQueue: assignedContainer application=application_1377141553101_0006 container=Container: [ContainerId: container_1377141553101_0006_01_000039, NodeId: hadoop-998-4:35553, NodeHttpAddress: hadoop-998-4:8042, Resource: <memory:1024, vCores:1>, Priority: 20, State: NEW, Token: null, Status: container_id {, app_attempt_id {, application_id {, id: 6, cluster_timestamp: 1377141553101, }, attemptId: 1, }, id: 39, }, state: C_NEW, ] containerId=container_1377141553101_0006_01_000039 queue=default: capacity=1.0, absoluteCapacity=1.0, usedResources=<memory:48128, vCores:42>usedCapacity=0.9791667, absoluteUsedCapacity=0.9791667, numApps=5, numContainers=42 usedCapacity=0.9791667 absoluteUsedCapacity=0.9791667 used=<memory:48128, vCores:42> cluster=<memory:49152, vCores:96>
2013-08-22 03:35:36,555 INFO org.apache.hadoop.yarn.server.resourcemanager.scheduler.capacity.ParentQueue: Re-sorting queues since queue: root.default stats: default: capacity=1.0, absoluteCapacity=1.0, usedResources=<memory:49152, vCores:43>usedCapacity=1.0, absoluteUsedCapacity=1.0, numApps=5, numContainers=43
2013-08-22 03:35:36,555 INFO org.apache.hadoop.yarn.server.resourcemanager.scheduler.capacity.ParentQueue: assignedContainer queue=root usedCapacity=1.0 absoluteUsedCapacity=1.0 used=<memory:49152, vCores:43> cluster=<memory:49152, vCores:96>
2013-08-22 03:35:36,577 INFO org.apache.hadoop.yarn.server.resourcemanager.rmcontainer.RMContainerImpl: container_1377141553101_0006_01_000002 Container Transitioned from ALLOCATED to ACQUIRED
2013-08-22 03:35:36,579 INFO org.apache.hadoop.yarn.server.resourcemanager.rmcontainer.RMContainerImpl: container_1377141553101_0006_01_000003 Container Transitioned from ALLOCATED to ACQUIRED
2013-08-22 03:35:36,580 INFO org.apache.hadoop.yarn.server.resourcemanager.rmcontainer.RMContainerImpl: container_1377141553101_0006_01_000004 Container Transitioned from ALLOCATED to ACQUIRED
2013-08-22 03:35:36,582 INFO org.apache.hadoop.yarn.server.resourcemanager.rmcontainer.RMContainerImpl: container_1377141553101_0006_01_000005 Container Transitioned from ALLOCATED to ACQUIRED
2013-08-22 03:35:36,583 INFO org.apache.hadoop.yarn.server.resourcemanager.rmcontainer.RMContainerImpl: container_1377141553101_0006_01_000006 Container Transitioned from ALLOCATED to ACQUIRED
2013-08-22 03:35:36,584 INFO org.apache.hadoop.yarn.server.resourcemanager.rmcontainer.RMContainerImpl: container_1377141553101_0006_01_000007 Container Transitioned from ALLOCATED to ACQUIRED
2013-08-22 03:35:36,585 INFO org.apache.hadoop.yarn.server.resourcemanager.rmcontainer.RMContainerImpl: container_1377141553101_0006_01_000008 Container Transitioned from ALLOCATED to ACQUIRED
2013-08-22 03:35:36,586 INFO org.apache.hadoop.yarn.server.resourcemanager.rmcontainer.RMContainerImpl: container_1377141553101_0006_01_000009 Container Transitioned from ALLOCATED to ACQUIRED
2013-08-22 03:35:36,587 INFO org.apache.hadoop.yarn.server.resourcemanager.rmcontainer.RMContainerImpl: container_1377141553101_0006_01_000010 Container Transitioned from ALLOCATED to ACQUIRED
2013-08-22 03:35:36,590 INFO org.apache.hadoop.yarn.server.resourcemanager.rmcontainer.RMContainerImpl: container_1377141553101_0006_01_000011 Container Transitioned from ALLOCATED to ACQUIRED
2013-08-22 03:35:36,590 INFO org.apache.hadoop.yarn.server.resourcemanager.rmcontainer.RMContainerImpl: container_1377141553101_0006_01_000012 Container Transitioned from ALLOCATED to ACQUIRED
2013-08-22 03:35:36,590 INFO org.apache.hadoop.yarn.server.resourcemanager.rmcontainer.RMContainerImpl: container_1377141553101_0006_01_000013 Container Transitioned from ALLOCATED to ACQUIRED
2013-08-22 03:35:36,591 INFO org.apache.hadoop.yarn.server.resourcemanager.rmcontainer.RMContainerImpl: container_1377141553101_0006_01_000014 Container Transitioned from ALLOCATED to ACQUIRED
2013-08-22 03:35:36,591 INFO org.apache.hadoop.yarn.server.resourcemanager.rmcontainer.RMContainerImpl: container_1377141553101_0006_01_000015 Container Transitioned from ALLOCATED to ACQUIRED
2013-08-22 03:35:36,591 INFO org.apache.hadoop.yarn.server.resourcemanager.rmcontainer.RMContainerImpl: container_1377141553101_0006_01_000016 Container Transitioned from ALLOCATED to ACQUIRED
2013-08-22 03:35:36,591 INFO org.apache.hadoop.yarn.server.resourcemanager.rmcontainer.RMContainerImpl: container_1377141553101_0006_01_000017 Container Transitioned from ALLOCATED to ACQUIRED
2013-08-22 03:35:36,591 INFO org.apache.hadoop.yarn.server.resourcemanager.rmcontainer.RMContainerImpl: container_1377141553101_0006_01_000018 Container Transitioned from ALLOCATED to ACQUIRED
2013-08-22 03:35:36,591 INFO org.apache.hadoop.yarn.server.resourcemanager.rmcontainer.RMContainerImpl: container_1377141553101_0006_01_000019 Container Transitioned from ALLOCATED to ACQUIRED
2013-08-22 03:35:36,592 INFO org.apache.hadoop.yarn.server.resourcemanager.rmcontainer.RMContainerImpl: container_1377141553101_0006_01_000020 Container Transitioned from ALLOCATED to ACQUIRED
2013-08-22 03:35:36,592 INFO org.apache.hadoop.yarn.server.resourcemanager.rmcontainer.RMContainerImpl: container_1377141553101_0006_01_000021 Container Transitioned from ALLOCATED to ACQUIRED
2013-08-22 03:35:36,592 INFO org.apache.hadoop.yarn.server.resourcemanager.rmcontainer.RMContainerImpl: container_1377141553101_0006_01_000022 Container Transitioned from ALLOCATED to ACQUIRED
2013-08-22 03:35:36,592 INFO org.apache.hadoop.yarn.server.resourcemanager.rmcontainer.RMContainerImpl: container_1377141553101_0006_01_000023 Container Transitioned from ALLOCATED to ACQUIRED
2013-08-22 03:35:36,592 INFO org.apache.hadoop.yarn.server.resourcemanager.rmcontainer.RMContainerImpl: container_1377141553101_0006_01_000024 Container Transitioned from ALLOCATED to ACQUIRED
2013-08-22 03:35:36,592 INFO org.apache.hadoop.yarn.server.resourcemanager.rmcontainer.RMContainerImpl: container_1377141553101_0006_01_000025 Container Transitioned from ALLOCATED to ACQUIRED
2013-08-22 03:35:36,593 INFO org.apache.hadoop.yarn.server.resourcemanager.rmcontainer.RMContainerImpl: container_1377141553101_0006_01_000026 Container Transitioned from ALLOCATED to ACQUIRED
2013-08-22 03:35:36,593 INFO org.apache.hadoop.yarn.server.resourcemanager.rmcontainer.RMContainerImpl: container_1377141553101_0006_01_000027 Container Transitioned from ALLOCATED to ACQUIRED
2013-08-22 03:35:36,593 INFO org.apache.hadoop.yarn.server.resourcemanager.rmcontainer.RMContainerImpl: container_1377141553101_0006_01_000028 Container Transitioned from ALLOCATED to ACQUIRED
2013-08-22 03:35:36,593 INFO org.apache.hadoop.yarn.server.resourcemanager.rmcontainer.RMContainerImpl: container_1377141553101_0006_01_000029 Container Transitioned from ALLOCATED to ACQUIRED
2013-08-22 03:35:36,593 INFO org.apache.hadoop.yarn.server.resourcemanager.rmcontainer.RMContainerImpl: container_1377141553101_0006_01_000030 Container Transitioned from ALLOCATED to ACQUIRED
2013-08-22 03:35:36,593 INFO org.apache.hadoop.yarn.server.resourcemanager.rmcontainer.RMContainerImpl: container_1377141553101_0006_01_000031 Container Transitioned from ALLOCATED to ACQUIRED
2013-08-22 03:35:36,594 INFO org.apache.hadoop.yarn.server.resourcemanager.rmcontainer.RMContainerImpl: container_1377141553101_0006_01_000032 Container Transitioned from ALLOCATED to ACQUIRED
2013-08-22 03:35:36,594 INFO org.apache.hadoop.yarn.server.resourcemanager.rmcontainer.RMContainerImpl: container_1377141553101_0006_01_000033 Container Transitioned from ALLOCATED to ACQUIRED
2013-08-22 03:35:36,594 INFO org.apache.hadoop.yarn.server.resourcemanager.rmcontainer.RMContainerImpl: container_1377141553101_0006_01_000034 Container Transitioned from ALLOCATED to ACQUIRED
2013-08-22 03:35:36,594 INFO org.apache.hadoop.yarn.server.resourcemanager.rmcontainer.RMContainerImpl: container_1377141553101_0006_01_000035 Container Transitioned from ALLOCATED to ACQUIRED
2013-08-22 03:35:36,594 INFO org.apache.hadoop.yarn.server.resourcemanager.rmcontainer.RMContainerImpl: container_1377141553101_0006_01_000036 Container Transitioned from ALLOCATED to ACQUIRED
2013-08-22 03:35:36,594 INFO org.apache.hadoop.yarn.server.resourcemanager.rmcontainer.RMContainerImpl: container_1377141553101_0006_01_000037 Container Transitioned from ALLOCATED to ACQUIRED
2013-08-22 03:35:36,595 INFO org.apache.hadoop.yarn.server.resourcemanager.rmcontainer.RMContainerImpl: container_1377141553101_0006_01_000038 Container Transitioned from ALLOCATED to ACQUIRED
2013-08-22 03:35:36,595 INFO org.apache.hadoop.yarn.server.resourcemanager.rmcontainer.RMContainerImpl: container_1377141553101_0006_01_000039 Container Transitioned from ALLOCATED to ACQUIRED
2013-08-22 03:35:36,961 INFO org.apache.hadoop.yarn.server.resourcemanager.ApplicationMasterService: AM registration appattempt_1377141553101_0008_000001
2013-08-22 03:35:36,962 INFO org.apache.hadoop.yarn.server.resourcemanager.RMAuditLogger: USER=ubuntu	IP=192.168.100.8	OPERATION=Register App Master	TARGET=ApplicationMasterService	RESULT=SUCCESS	APPID=application_1377141553101_0008	APPATTEMPTID=appattempt_1377141553101_0008_000001
2013-08-22 03:35:36,963 INFO org.apache.hadoop.yarn.server.resourcemanager.rmapp.attempt.RMAppAttemptImpl: appattempt_1377141553101_0008_000001 State change from LAUNCHED to RUNNING
2013-08-22 03:35:36,963 INFO org.apache.hadoop.yarn.server.resourcemanager.rmapp.RMAppImpl: application_1377141553101_0008 State change from ACCEPTED to RUNNING
2013-08-22 03:35:37,171 INFO org.apache.hadoop.yarn.server.resourcemanager.ApplicationMasterService: AM registration appattempt_1377141553101_0009_000001
2013-08-22 03:35:37,171 INFO org.apache.hadoop.yarn.server.resourcemanager.RMAuditLogger: USER=ubuntu	IP=192.168.100.11	OPERATION=Register App Master	TARGET=ApplicationMasterService	RESULT=SUCCESS	APPID=application_1377141553101_0009	APPATTEMPTID=appattempt_1377141553101_0009_000001
2013-08-22 03:35:37,173 INFO org.apache.hadoop.yarn.server.resourcemanager.rmapp.attempt.RMAppAttemptImpl: appattempt_1377141553101_0009_000001 State change from LAUNCHED to RUNNING
2013-08-22 03:35:37,173 INFO org.apache.hadoop.yarn.server.resourcemanager.rmapp.RMAppImpl: application_1377141553101_0009 State change from ACCEPTED to RUNNING
2013-08-22 03:35:37,439 INFO org.apache.hadoop.yarn.server.resourcemanager.rmcontainer.RMContainerImpl: container_1377141553101_0006_01_000028 Container Transitioned from ACQUIRED to RUNNING
2013-08-22 03:35:37,440 INFO org.apache.hadoop.yarn.server.resourcemanager.rmcontainer.RMContainerImpl: container_1377141553101_0006_01_000029 Container Transitioned from ACQUIRED to RUNNING
2013-08-22 03:35:37,441 INFO org.apache.hadoop.yarn.server.resourcemanager.rmcontainer.RMContainerImpl: container_1377141553101_0006_01_000030 Container Transitioned from ACQUIRED to RUNNING
2013-08-22 03:35:37,442 INFO org.apache.hadoop.yarn.server.resourcemanager.rmcontainer.RMContainerImpl: container_1377141553101_0006_01_000031 Container Transitioned from ACQUIRED to RUNNING
2013-08-22 03:35:37,443 INFO org.apache.hadoop.yarn.server.resourcemanager.rmcontainer.RMContainerImpl: container_1377141553101_0006_01_000032 Container Transitioned from ACQUIRED to RUNNING
2013-08-22 03:35:37,443 INFO org.apache.hadoop.yarn.server.resourcemanager.rmcontainer.RMContainerImpl: container_1377141553101_0006_01_000033 Container Transitioned from ACQUIRED to RUNNING
2013-08-22 03:35:37,640 INFO org.apache.hadoop.yarn.server.resourcemanager.rmcontainer.RMContainerImpl: container_1377141553101_0006_01_000034 Container Transitioned from ACQUIRED to RUNNING
2013-08-22 03:35:37,641 INFO org.apache.hadoop.yarn.server.resourcemanager.rmcontainer.RMContainerImpl: container_1377141553101_0006_01_000035 Container Transitioned from ACQUIRED to RUNNING
2013-08-22 03:35:37,642 INFO org.apache.hadoop.yarn.server.resourcemanager.rmcontainer.RMContainerImpl: container_1377141553101_0006_01_000036 Container Transitioned from ACQUIRED to RUNNING
2013-08-22 03:35:37,644 INFO org.apache.hadoop.yarn.server.resourcemanager.rmcontainer.RMContainerImpl: container_1377141553101_0006_01_000037 Container Transitioned from ACQUIRED to RUNNING
2013-08-22 03:35:37,644 INFO org.apache.hadoop.yarn.server.resourcemanager.rmcontainer.RMContainerImpl: container_1377141553101_0006_01_000038 Container Transitioned from ACQUIRED to RUNNING
2013-08-22 03:35:37,644 INFO org.apache.hadoop.yarn.server.resourcemanager.rmcontainer.RMContainerImpl: container_1377141553101_0006_01_000039 Container Transitioned from ACQUIRED to RUNNING
2013-08-22 03:35:37,761 INFO org.apache.hadoop.yarn.server.resourcemanager.rmcontainer.RMContainerImpl: container_1377141553101_0006_01_000002 Container Transitioned from ACQUIRED to RUNNING
2013-08-22 03:35:37,762 INFO org.apache.hadoop.yarn.server.resourcemanager.rmcontainer.RMContainerImpl: container_1377141553101_0006_01_000003 Container Transitioned from ACQUIRED to RUNNING
2013-08-22 03:35:37,762 INFO org.apache.hadoop.yarn.server.resourcemanager.rmcontainer.RMContainerImpl: container_1377141553101_0006_01_000004 Container Transitioned from ACQUIRED to RUNNING
2013-08-22 03:35:37,762 INFO org.apache.hadoop.yarn.server.resourcemanager.rmcontainer.RMContainerImpl: container_1377141553101_0006_01_000005 Container Transitioned from ACQUIRED to RUNNING
2013-08-22 03:35:37,762 INFO org.apache.hadoop.yarn.server.resourcemanager.rmcontainer.RMContainerImpl: container_1377141553101_0006_01_000006 Container Transitioned from ACQUIRED to RUNNING
2013-08-22 03:35:37,762 INFO org.apache.hadoop.yarn.server.resourcemanager.rmcontainer.RMContainerImpl: container_1377141553101_0006_01_000007 Container Transitioned from ACQUIRED to RUNNING
2013-08-22 03:35:37,856 INFO org.apache.hadoop.yarn.server.resourcemanager.rmcontainer.RMContainerImpl: container_1377141553101_0006_01_000008 Container Transitioned from ACQUIRED to RUNNING
2013-08-22 03:35:37,856 INFO org.apache.hadoop.yarn.server.resourcemanager.rmcontainer.RMContainerImpl: container_1377141553101_0006_01_000009 Container Transitioned from ACQUIRED to RUNNING
2013-08-22 03:35:37,857 INFO org.apache.hadoop.yarn.server.resourcemanager.rmcontainer.RMContainerImpl: container_1377141553101_0006_01_000010 Container Transitioned from ACQUIRED to RUNNING
2013-08-22 03:35:37,858 INFO org.apache.hadoop.yarn.server.resourcemanager.rmcontainer.RMContainerImpl: container_1377141553101_0006_01_000011 Container Transitioned from ACQUIRED to RUNNING
2013-08-22 03:35:37,860 INFO org.apache.hadoop.yarn.server.resourcemanager.rmcontainer.RMContainerImpl: container_1377141553101_0006_01_000012 Container Transitioned from ACQUIRED to RUNNING
2013-08-22 03:35:37,860 INFO org.apache.hadoop.yarn.server.resourcemanager.rmcontainer.RMContainerImpl: container_1377141553101_0006_01_000013 Container Transitioned from ACQUIRED to RUNNING
2013-08-22 03:35:38,066 INFO org.apache.hadoop.yarn.server.resourcemanager.rmcontainer.RMContainerImpl: container_1377141553101_0006_01_000014 Container Transitioned from ACQUIRED to RUNNING
2013-08-22 03:35:38,067 INFO org.apache.hadoop.yarn.server.resourcemanager.rmcontainer.RMContainerImpl: container_1377141553101_0006_01_000015 Container Transitioned from ACQUIRED to RUNNING
2013-08-22 03:35:38,067 INFO org.apache.hadoop.yarn.server.resourcemanager.rmcontainer.RMContainerImpl: container_1377141553101_0006_01_000016 Container Transitioned from ACQUIRED to RUNNING
2013-08-22 03:35:38,068 INFO org.apache.hadoop.yarn.server.resourcemanager.rmcontainer.RMContainerImpl: container_1377141553101_0006_01_000017 Container Transitioned from ACQUIRED to RUNNING
2013-08-22 03:35:38,069 INFO org.apache.hadoop.yarn.server.resourcemanager.rmcontainer.RMContainerImpl: container_1377141553101_0006_01_000018 Container Transitioned from ACQUIRED to RUNNING
2013-08-22 03:35:38,070 INFO org.apache.hadoop.yarn.server.resourcemanager.rmcontainer.RMContainerImpl: container_1377141553101_0006_01_000019 Container Transitioned from ACQUIRED to RUNNING
2013-08-22 03:35:38,070 INFO org.apache.hadoop.yarn.server.resourcemanager.rmcontainer.RMContainerImpl: container_1377141553101_0006_01_000020 Container Transitioned from ACQUIRED to RUNNING
2013-08-22 03:35:38,070 INFO org.apache.hadoop.yarn.server.resourcemanager.rmcontainer.RMContainerImpl: container_1377141553101_0006_01_000021 Container Transitioned from ACQUIRED to RUNNING
2013-08-22 03:35:38,070 INFO org.apache.hadoop.yarn.server.resourcemanager.rmcontainer.RMContainerImpl: container_1377141553101_0006_01_000022 Container Transitioned from ACQUIRED to RUNNING
2013-08-22 03:35:38,070 INFO org.apache.hadoop.yarn.server.resourcemanager.rmcontainer.RMContainerImpl: container_1377141553101_0006_01_000023 Container Transitioned from ACQUIRED to RUNNING
2013-08-22 03:35:38,071 INFO org.apache.hadoop.yarn.server.resourcemanager.rmcontainer.RMContainerImpl: container_1377141553101_0006_01_000024 Container Transitioned from ACQUIRED to RUNNING
2013-08-22 03:35:38,071 INFO org.apache.hadoop.yarn.server.resourcemanager.rmcontainer.RMContainerImpl: container_1377141553101_0006_01_000025 Container Transitioned from ACQUIRED to RUNNING
2013-08-22 03:35:38,071 INFO org.apache.hadoop.yarn.server.resourcemanager.rmcontainer.RMContainerImpl: container_1377141553101_0006_01_000026 Container Transitioned from ACQUIRED to RUNNING
2013-08-22 03:35:38,071 INFO org.apache.hadoop.yarn.server.resourcemanager.rmcontainer.RMContainerImpl: container_1377141553101_0006_01_000027 Container Transitioned from ACQUIRED to RUNNING
2013-08-22 03:36:01,425 INFO org.apache.hadoop.yarn.server.resourcemanager.rmcontainer.RMContainerImpl: container_1377141553101_0006_01_000028 Container Transitioned from RUNNING to COMPLETED
2013-08-22 03:36:01,425 INFO org.apache.hadoop.yarn.server.resourcemanager.scheduler.common.fica.FiCaSchedulerApp: Completed container: container_1377141553101_0006_01_000028 in state: COMPLETED event:FINISHED
2013-08-22 03:36:01,425 INFO org.apache.hadoop.yarn.server.resourcemanager.RMAuditLogger: USER=ubuntu	OPERATION=AM Released Container	TARGET=SchedulerApp	RESULT=SUCCESS	APPID=application_1377141553101_0006	CONTAINERID=container_1377141553101_0006_01_000028
2013-08-22 03:36:01,425 INFO org.apache.hadoop.yarn.server.resourcemanager.scheduler.common.fica.FiCaSchedulerNode: Released container container_1377141553101_0006_01_000028 of capacity <memory:1024, vCores:1> on host hadoop-998-3:53776, which currently has 6 containers, <memory:7168, vCores:6> used and <memory:1024, vCores:10> available, release resources=true
2013-08-22 03:36:01,426 INFO org.apache.hadoop.yarn.server.resourcemanager.scheduler.capacity.LeafQueue: default used=<memory:48128, vCores:42> numContainers=42 user=ubuntu user-resources=<memory:48128, vCores:42>
2013-08-22 03:36:01,428 INFO org.apache.hadoop.yarn.server.resourcemanager.scheduler.capacity.LeafQueue: completedContainer container=Container: [ContainerId: container_1377141553101_0006_01_000028, NodeId: hadoop-998-3:53776, NodeHttpAddress: hadoop-998-3:8042, Resource: <memory:1024, vCores:1>, Priority: 20, State: NEW, Token: null, Status: container_id {, app_attempt_id {, application_id {, id: 6, cluster_timestamp: 1377141553101, }, attemptId: 1, }, id: 28, }, state: C_COMPLETE, diagnostics: "Container killed by the ApplicationMaster.\n\n", exit_status: 143, ] resource=<memory:1024, vCores:1> queue=default: capacity=1.0, absoluteCapacity=1.0, usedResources=<memory:48128, vCores:42>usedCapacity=0.9791667, absoluteUsedCapacity=0.9791667, numApps=5, numContainers=42 usedCapacity=0.9791667 absoluteUsedCapacity=0.9791667 used=<memory:48128, vCores:42> cluster=<memory:49152, vCores:96>
2013-08-22 03:36:01,429 INFO org.apache.hadoop.yarn.server.resourcemanager.scheduler.capacity.ParentQueue: completedContainer queue=root usedCapacity=0.9791667 absoluteUsedCapacity=0.9791667 used=<memory:48128, vCores:42> cluster=<memory:49152, vCores:96>
2013-08-22 03:36:01,429 INFO org.apache.hadoop.yarn.server.resourcemanager.scheduler.capacity.CapacityScheduler: Application appattempt_1377141553101_0006_000001 released container container_1377141553101_0006_01_000028 on node: host: hadoop-998-3:53776 #containers=6 available=1024 used=7168 with event: FINISHED
2013-08-22 03:36:01,430 INFO org.apache.hadoop.yarn.server.resourcemanager.rmcontainer.RMContainerImpl: container_1377141553101_0006_01_000040 Container Transitioned from NEW to ALLOCATED
2013-08-22 03:36:01,430 INFO org.apache.hadoop.yarn.server.resourcemanager.RMAuditLogger: USER=ubuntu	OPERATION=AM Allocated Container	TARGET=SchedulerApp	RESULT=SUCCESS	APPID=application_1377141553101_0006	CONTAINERID=container_1377141553101_0006_01_000040
2013-08-22 03:36:01,430 INFO org.apache.hadoop.yarn.server.resourcemanager.scheduler.common.fica.FiCaSchedulerNode: Assigned container container_1377141553101_0006_01_000040 of capacity <memory:1024, vCores:1> on host hadoop-998-3:53776, which currently has 7 containers, <memory:8192, vCores:7> used and <memory:0, vCores:9> available
2013-08-22 03:36:01,431 INFO org.apache.hadoop.yarn.server.resourcemanager.scheduler.capacity.LeafQueue: assignedContainer application=application_1377141553101_0006 container=Container: [ContainerId: container_1377141553101_0006_01_000040, NodeId: hadoop-998-3:53776, NodeHttpAddress: hadoop-998-3:8042, Resource: <memory:1024, vCores:1>, Priority: 20, State: NEW, Token: null, Status: container_id {, app_attempt_id {, application_id {, id: 6, cluster_timestamp: 1377141553101, }, attemptId: 1, }, id: 40, }, state: C_NEW, ] containerId=container_1377141553101_0006_01_000040 queue=default: capacity=1.0, absoluteCapacity=1.0, usedResources=<memory:48128, vCores:42>usedCapacity=0.9791667, absoluteUsedCapacity=0.9791667, numApps=5, numContainers=42 usedCapacity=0.9791667 absoluteUsedCapacity=0.9791667 used=<memory:48128, vCores:42> cluster=<memory:49152, vCores:96>
2013-08-22 03:36:01,431 INFO org.apache.hadoop.yarn.server.resourcemanager.scheduler.capacity.ParentQueue: Re-sorting queues since queue: root.default stats: default: capacity=1.0, absoluteCapacity=1.0, usedResources=<memory:49152, vCores:43>usedCapacity=1.0, absoluteUsedCapacity=1.0, numApps=5, numContainers=43
2013-08-22 03:36:01,431 INFO org.apache.hadoop.yarn.server.resourcemanager.scheduler.capacity.ParentQueue: assignedContainer queue=root usedCapacity=1.0 absoluteUsedCapacity=1.0 used=<memory:49152, vCores:43> cluster=<memory:49152, vCores:96>
2013-08-22 03:36:01,864 INFO org.apache.hadoop.yarn.server.resourcemanager.rmcontainer.RMContainerImpl: container_1377141553101_0006_01_000040 Container Transitioned from ALLOCATED to ACQUIRED
2013-08-22 03:36:02,435 INFO org.apache.hadoop.yarn.server.resourcemanager.rmcontainer.RMContainerImpl: container_1377141553101_0006_01_000040 Container Transitioned from ACQUIRED to RUNNING
2013-08-22 03:36:02,979 INFO org.apache.hadoop.yarn.server.resourcemanager.rmcontainer.RMContainerImpl: container_1377141553101_0006_01_000023 Container Transitioned from RUNNING to COMPLETED
2013-08-22 03:36:02,979 INFO org.apache.hadoop.yarn.server.resourcemanager.scheduler.common.fica.FiCaSchedulerApp: Completed container: container_1377141553101_0006_01_000023 in state: COMPLETED event:FINISHED
2013-08-22 03:36:02,979 INFO org.apache.hadoop.yarn.server.resourcemanager.RMAuditLogger: USER=ubuntu	OPERATION=AM Released Container	TARGET=SchedulerApp	RESULT=SUCCESS	APPID=application_1377141553101_0006	CONTAINERID=container_1377141553101_0006_01_000023
2013-08-22 03:36:02,979 INFO org.apache.hadoop.yarn.server.resourcemanager.scheduler.common.fica.FiCaSchedulerNode: Released container container_1377141553101_0006_01_000023 of capacity <memory:1024, vCores:1> on host hadoop-998-5:56087, which currently has 6 containers, <memory:7168, vCores:6> used and <memory:1024, vCores:10> available, release resources=true
2013-08-22 03:36:02,980 INFO org.apache.hadoop.yarn.server.resourcemanager.scheduler.capacity.LeafQueue: default used=<memory:48128, vCores:42> numContainers=42 user=ubuntu user-resources=<memory:48128, vCores:42>
2013-08-22 03:36:02,981 INFO org.apache.hadoop.yarn.server.resourcemanager.scheduler.capacity.LeafQueue: completedContainer container=Container: [ContainerId: container_1377141553101_0006_01_000023, NodeId: hadoop-998-5:56087, NodeHttpAddress: hadoop-998-5:8042, Resource: <memory:1024, vCores:1>, Priority: 20, State: NEW, Token: null, Status: container_id {, app_attempt_id {, application_id {, id: 6, cluster_timestamp: 1377141553101, }, attemptId: 1, }, id: 23, }, state: C_COMPLETE, diagnostics: "Container killed by the ApplicationMaster.\n\n", exit_status: 143, ] resource=<memory:1024, vCores:1> queue=default: capacity=1.0, absoluteCapacity=1.0, usedResources=<memory:48128, vCores:42>usedCapacity=0.9791667, absoluteUsedCapacity=0.9791667, numApps=5, numContainers=42 usedCapacity=0.9791667 absoluteUsedCapacity=0.9791667 used=<memory:48128, vCores:42> cluster=<memory:49152, vCores:96>
2013-08-22 03:36:02,981 INFO org.apache.hadoop.yarn.server.resourcemanager.scheduler.capacity.ParentQueue: completedContainer queue=root usedCapacity=0.9791667 absoluteUsedCapacity=0.9791667 used=<memory:48128, vCores:42> cluster=<memory:49152, vCores:96>
2013-08-22 03:36:02,982 INFO org.apache.hadoop.yarn.server.resourcemanager.scheduler.capacity.CapacityScheduler: Application appattempt_1377141553101_0006_000001 released container container_1377141553101_0006_01_000023 on node: host: hadoop-998-5:56087 #containers=6 available=1024 used=7168 with event: FINISHED
2013-08-22 03:36:02,982 INFO org.apache.hadoop.yarn.server.resourcemanager.rmcontainer.RMContainerImpl: container_1377141553101_0006_01_000041 Container Transitioned from NEW to ALLOCATED
2013-08-22 03:36:02,982 INFO org.apache.hadoop.yarn.server.resourcemanager.RMAuditLogger: USER=ubuntu	OPERATION=AM Allocated Container	TARGET=SchedulerApp	RESULT=SUCCESS	APPID=application_1377141553101_0006	CONTAINERID=container_1377141553101_0006_01_000041
2013-08-22 03:36:02,983 INFO org.apache.hadoop.yarn.server.resourcemanager.scheduler.common.fica.FiCaSchedulerNode: Assigned container container_1377141553101_0006_01_000041 of capacity <memory:1024, vCores:1> on host hadoop-998-5:56087, which currently has 7 containers, <memory:8192, vCores:7> used and <memory:0, vCores:9> available
2013-08-22 03:36:02,984 INFO org.apache.hadoop.yarn.server.resourcemanager.scheduler.capacity.LeafQueue: assignedContainer application=application_1377141553101_0006 container=Container: [ContainerId: container_1377141553101_0006_01_000041, NodeId: hadoop-998-5:56087, NodeHttpAddress: hadoop-998-5:8042, Resource: <memory:1024, vCores:1>, Priority: 20, State: NEW, Token: null, Status: container_id {, app_attempt_id {, application_id {, id: 6, cluster_timestamp: 1377141553101, }, attemptId: 1, }, id: 41, }, state: C_NEW, ] containerId=container_1377141553101_0006_01_000041 queue=default: capacity=1.0, absoluteCapacity=1.0, usedResources=<memory:48128, vCores:42>usedCapacity=0.9791667, absoluteUsedCapacity=0.9791667, numApps=5, numContainers=42 usedCapacity=0.9791667 absoluteUsedCapacity=0.9791667 used=<memory:48128, vCores:42> cluster=<memory:49152, vCores:96>
2013-08-22 03:36:02,984 INFO org.apache.hadoop.yarn.server.resourcemanager.scheduler.capacity.ParentQueue: Re-sorting queues since queue: root.default stats: default: capacity=1.0, absoluteCapacity=1.0, usedResources=<memory:49152, vCores:43>usedCapacity=1.0, absoluteUsedCapacity=1.0, numApps=5, numContainers=43
2013-08-22 03:36:02,984 INFO org.apache.hadoop.yarn.server.resourcemanager.scheduler.capacity.ParentQueue: assignedContainer queue=root usedCapacity=1.0 absoluteUsedCapacity=1.0 used=<memory:49152, vCores:43> cluster=<memory:49152, vCores:96>
2013-08-22 03:36:03,034 INFO org.apache.hadoop.yarn.server.resourcemanager.rmcontainer.RMContainerImpl: container_1377141553101_0006_01_000026 Container Transitioned from RUNNING to COMPLETED
2013-08-22 03:36:03,035 INFO org.apache.hadoop.yarn.server.resourcemanager.scheduler.common.fica.FiCaSchedulerApp: Completed container: container_1377141553101_0006_01_000026 in state: COMPLETED event:FINISHED
2013-08-22 03:36:03,035 INFO org.apache.hadoop.yarn.server.resourcemanager.RMAuditLogger: USER=ubuntu	OPERATION=AM Released Container	TARGET=SchedulerApp	RESULT=SUCCESS	APPID=application_1377141553101_0006	CONTAINERID=container_1377141553101_0006_01_000026
2013-08-22 03:36:03,035 INFO org.apache.hadoop.yarn.server.resourcemanager.scheduler.common.fica.FiCaSchedulerNode: Released container container_1377141553101_0006_01_000026 of capacity <memory:1024, vCores:1> on host hadoop-998-5:56087, which currently has 6 containers, <memory:7168, vCores:6> used and <memory:1024, vCores:10> available, release resources=true
2013-08-22 03:36:03,035 INFO org.apache.hadoop.yarn.server.resourcemanager.scheduler.capacity.LeafQueue: default used=<memory:48128, vCores:42> numContainers=42 user=ubuntu user-resources=<memory:48128, vCores:42>
2013-08-22 03:36:03,036 INFO org.apache.hadoop.yarn.server.resourcemanager.scheduler.capacity.LeafQueue: completedContainer container=Container: [ContainerId: container_1377141553101_0006_01_000026, NodeId: hadoop-998-5:56087, NodeHttpAddress: hadoop-998-5:8042, Resource: <memory:1024, vCores:1>, Priority: 20, State: NEW, Token: null, Status: container_id {, app_attempt_id {, application_id {, id: 6, cluster_timestamp: 1377141553101, }, attemptId: 1, }, id: 26, }, state: C_COMPLETE, diagnostics: "Container killed by the ApplicationMaster.\n\n", exit_status: 143, ] resource=<memory:1024, vCores:1> queue=default: capacity=1.0, absoluteCapacity=1.0, usedResources=<memory:48128, vCores:42>usedCapacity=0.9791667, absoluteUsedCapacity=0.9791667, numApps=5, numContainers=42 usedCapacity=0.9791667 absoluteUsedCapacity=0.9791667 used=<memory:48128, vCores:42> cluster=<memory:49152, vCores:96>
2013-08-22 03:36:03,036 INFO org.apache.hadoop.yarn.server.resourcemanager.scheduler.capacity.ParentQueue: completedContainer queue=root usedCapacity=0.9791667 absoluteUsedCapacity=0.9791667 used=<memory:48128, vCores:42> cluster=<memory:49152, vCores:96>
2013-08-22 03:36:03,037 INFO org.apache.hadoop.yarn.server.resourcemanager.scheduler.capacity.CapacityScheduler: Application appattempt_1377141553101_0006_000001 released container container_1377141553101_0006_01_000026 on node: host: hadoop-998-5:56087 #containers=6 available=1024 used=7168 with event: FINISHED
2013-08-22 03:36:03,037 INFO org.apache.hadoop.yarn.server.resourcemanager.rmcontainer.RMContainerImpl: container_1377141553101_0007_01_000002 Container Transitioned from NEW to ALLOCATED
2013-08-22 03:36:03,037 INFO org.apache.hadoop.yarn.server.resourcemanager.RMAuditLogger: USER=ubuntu	OPERATION=AM Allocated Container	TARGET=SchedulerApp	RESULT=SUCCESS	APPID=application_1377141553101_0007	CONTAINERID=container_1377141553101_0007_01_000002
2013-08-22 03:36:03,038 INFO org.apache.hadoop.yarn.server.resourcemanager.scheduler.common.fica.FiCaSchedulerNode: Assigned container container_1377141553101_0007_01_000002 of capacity <memory:1024, vCores:1> on host hadoop-998-5:56087, which currently has 7 containers, <memory:8192, vCores:7> used and <memory:0, vCores:9> available
2013-08-22 03:36:03,039 INFO org.apache.hadoop.yarn.server.resourcemanager.scheduler.capacity.LeafQueue: assignedContainer application=application_1377141553101_0007 container=Container: [ContainerId: container_1377141553101_0007_01_000002, NodeId: hadoop-998-5:56087, NodeHttpAddress: hadoop-998-5:8042, Resource: <memory:1024, vCores:1>, Priority: 20, State: NEW, Token: null, Status: container_id {, app_attempt_id {, application_id {, id: 7, cluster_timestamp: 1377141553101, }, attemptId: 1, }, id: 2, }, state: C_NEW, ] containerId=container_1377141553101_0007_01_000002 queue=default: capacity=1.0, absoluteCapacity=1.0, usedResources=<memory:48128, vCores:42>usedCapacity=0.9791667, absoluteUsedCapacity=0.9791667, numApps=5, numContainers=42 usedCapacity=0.9791667 absoluteUsedCapacity=0.9791667 used=<memory:48128, vCores:42> cluster=<memory:49152, vCores:96>
2013-08-22 03:36:03,039 INFO org.apache.hadoop.yarn.server.resourcemanager.scheduler.capacity.ParentQueue: Re-sorting queues since queue: root.default stats: default: capacity=1.0, absoluteCapacity=1.0, usedResources=<memory:49152, vCores:43>usedCapacity=1.0, absoluteUsedCapacity=1.0, numApps=5, numContainers=43
2013-08-22 03:36:03,039 INFO org.apache.hadoop.yarn.server.resourcemanager.scheduler.capacity.ParentQueue: assignedContainer queue=root usedCapacity=1.0 absoluteUsedCapacity=1.0 used=<memory:49152, vCores:43> cluster=<memory:49152, vCores:96>
2013-08-22 03:36:03,530 INFO org.apache.hadoop.yarn.server.resourcemanager.rmcontainer.RMContainerImpl: container_1377141553101_0007_01_000002 Container Transitioned from ALLOCATED to ACQUIRED
2013-08-22 03:36:03,889 INFO org.apache.hadoop.yarn.server.resourcemanager.rmcontainer.RMContainerImpl: container_1377141553101_0006_01_000041 Container Transitioned from ALLOCATED to ACQUIRED
2013-08-22 03:36:04,050 INFO org.apache.hadoop.yarn.server.resourcemanager.rmcontainer.RMContainerImpl: container_1377141553101_0006_01_000041 Container Transitioned from ACQUIRED to RUNNING
2013-08-22 03:36:04,050 INFO org.apache.hadoop.yarn.server.resourcemanager.rmcontainer.RMContainerImpl: container_1377141553101_0006_01_000022 Container Transitioned from RUNNING to COMPLETED
2013-08-22 03:36:04,050 INFO org.apache.hadoop.yarn.server.resourcemanager.scheduler.common.fica.FiCaSchedulerApp: Completed container: container_1377141553101_0006_01_000022 in state: COMPLETED event:FINISHED
2013-08-22 03:36:04,050 INFO org.apache.hadoop.yarn.server.resourcemanager.RMAuditLogger: USER=ubuntu	OPERATION=AM Released Container	TARGET=SchedulerApp	RESULT=SUCCESS	APPID=application_1377141553101_0006	CONTAINERID=container_1377141553101_0006_01_000022
2013-08-22 03:36:04,051 INFO org.apache.hadoop.yarn.server.resourcemanager.scheduler.common.fica.FiCaSchedulerNode: Released container container_1377141553101_0006_01_000022 of capacity <memory:1024, vCores:1> on host hadoop-998-5:56087, which currently has 6 containers, <memory:7168, vCores:6> used and <memory:1024, vCores:10> available, release resources=true
2013-08-22 03:36:04,051 INFO org.apache.hadoop.yarn.server.resourcemanager.scheduler.capacity.LeafQueue: default used=<memory:48128, vCores:42> numContainers=42 user=ubuntu user-resources=<memory:48128, vCores:42>
2013-08-22 03:36:04,052 INFO org.apache.hadoop.yarn.server.resourcemanager.scheduler.capacity.LeafQueue: completedContainer container=Container: [ContainerId: container_1377141553101_0006_01_000022, NodeId: hadoop-998-5:56087, NodeHttpAddress: hadoop-998-5:8042, Resource: <memory:1024, vCores:1>, Priority: 20, State: NEW, Token: null, Status: container_id {, app_attempt_id {, application_id {, id: 6, cluster_timestamp: 1377141553101, }, attemptId: 1, }, id: 22, }, state: C_COMPLETE, diagnostics: "Container killed by the ApplicationMaster.\n\n", exit_status: 143, ] resource=<memory:1024, vCores:1> queue=default: capacity=1.0, absoluteCapacity=1.0, usedResources=<memory:48128, vCores:42>usedCapacity=0.9791667, absoluteUsedCapacity=0.9791667, numApps=5, numContainers=42 usedCapacity=0.9791667 absoluteUsedCapacity=0.9791667 used=<memory:48128, vCores:42> cluster=<memory:49152, vCores:96>
2013-08-22 03:36:04,052 INFO org.apache.hadoop.yarn.server.resourcemanager.scheduler.capacity.ParentQueue: completedContainer queue=root usedCapacity=0.9791667 absoluteUsedCapacity=0.9791667 used=<memory:48128, vCores:42> cluster=<memory:49152, vCores:96>
2013-08-22 03:36:04,052 INFO org.apache.hadoop.yarn.server.resourcemanager.scheduler.capacity.CapacityScheduler: Application appattempt_1377141553101_0006_000001 released container container_1377141553101_0006_01_000022 on node: host: hadoop-998-5:56087 #containers=6 available=1024 used=7168 with event: FINISHED
2013-08-22 03:36:04,053 INFO org.apache.hadoop.yarn.server.resourcemanager.rmcontainer.RMContainerImpl: container_1377141553101_0006_01_000042 Container Transitioned from NEW to ALLOCATED
2013-08-22 03:36:04,053 INFO org.apache.hadoop.yarn.server.resourcemanager.RMAuditLogger: USER=ubuntu	OPERATION=AM Allocated Container	TARGET=SchedulerApp	RESULT=SUCCESS	APPID=application_1377141553101_0006	CONTAINERID=container_1377141553101_0006_01_000042
2013-08-22 03:36:04,053 INFO org.apache.hadoop.yarn.server.resourcemanager.scheduler.common.fica.FiCaSchedulerNode: Assigned container container_1377141553101_0006_01_000042 of capacity <memory:1024, vCores:1> on host hadoop-998-5:56087, which currently has 7 containers, <memory:8192, vCores:7> used and <memory:0, vCores:9> available
2013-08-22 03:36:04,054 INFO org.apache.hadoop.yarn.server.resourcemanager.scheduler.capacity.LeafQueue: assignedContainer application=application_1377141553101_0006 container=Container: [ContainerId: container_1377141553101_0006_01_000042, NodeId: hadoop-998-5:56087, NodeHttpAddress: hadoop-998-5:8042, Resource: <memory:1024, vCores:1>, Priority: 10, State: NEW, Token: null, Status: container_id {, app_attempt_id {, application_id {, id: 6, cluster_timestamp: 1377141553101, }, attemptId: 1, }, id: 42, }, state: C_NEW, ] containerId=container_1377141553101_0006_01_000042 queue=default: capacity=1.0, absoluteCapacity=1.0, usedResources=<memory:48128, vCores:42>usedCapacity=0.9791667, absoluteUsedCapacity=0.9791667, numApps=5, numContainers=42 usedCapacity=0.9791667 absoluteUsedCapacity=0.9791667 used=<memory:48128, vCores:42> cluster=<memory:49152, vCores:96>
2013-08-22 03:36:04,055 INFO org.apache.hadoop.yarn.server.resourcemanager.scheduler.capacity.ParentQueue: Re-sorting queues since queue: root.default stats: default: capacity=1.0, absoluteCapacity=1.0, usedResources=<memory:49152, vCores:43>usedCapacity=1.0, absoluteUsedCapacity=1.0, numApps=5, numContainers=43
2013-08-22 03:36:04,055 INFO org.apache.hadoop.yarn.server.resourcemanager.scheduler.capacity.ParentQueue: assignedContainer queue=root usedCapacity=1.0 absoluteUsedCapacity=1.0 used=<memory:49152, vCores:43> cluster=<memory:49152, vCores:96>
2013-08-22 03:36:04,372 INFO org.apache.hadoop.yarn.server.resourcemanager.rmcontainer.RMContainerImpl: container_1377141553101_0006_01_000034 Container Transitioned from RUNNING to COMPLETED
2013-08-22 03:36:04,373 INFO org.apache.hadoop.yarn.server.resourcemanager.scheduler.common.fica.FiCaSchedulerApp: Completed container: container_1377141553101_0006_01_000034 in state: COMPLETED event:FINISHED
2013-08-22 03:36:04,373 INFO org.apache.hadoop.yarn.server.resourcemanager.RMAuditLogger: USER=ubuntu	OPERATION=AM Released Container	TARGET=SchedulerApp	RESULT=SUCCESS	APPID=application_1377141553101_0006	CONTAINERID=container_1377141553101_0006_01_000034
2013-08-22 03:36:04,373 INFO org.apache.hadoop.yarn.server.resourcemanager.scheduler.common.fica.FiCaSchedulerNode: Released container container_1377141553101_0006_01_000034 of capacity <memory:1024, vCores:1> on host hadoop-998-4:35553, which currently has 6 containers, <memory:7168, vCores:6> used and <memory:1024, vCores:10> available, release resources=true
2013-08-22 03:36:04,373 INFO org.apache.hadoop.yarn.server.resourcemanager.scheduler.capacity.LeafQueue: default used=<memory:48128, vCores:42> numContainers=42 user=ubuntu user-resources=<memory:48128, vCores:42>
2013-08-22 03:36:04,374 INFO org.apache.hadoop.yarn.server.resourcemanager.scheduler.capacity.LeafQueue: completedContainer container=Container: [ContainerId: container_1377141553101_0006_01_000034, NodeId: hadoop-998-4:35553, NodeHttpAddress: hadoop-998-4:8042, Resource: <memory:1024, vCores:1>, Priority: 20, State: NEW, Token: null, Status: container_id {, app_attempt_id {, application_id {, id: 6, cluster_timestamp: 1377141553101, }, attemptId: 1, }, id: 34, }, state: C_COMPLETE, diagnostics: "Container killed by the ApplicationMaster.\n", exit_status: 0, ] resource=<memory:1024, vCores:1> queue=default: capacity=1.0, absoluteCapacity=1.0, usedResources=<memory:48128, vCores:42>usedCapacity=0.9791667, absoluteUsedCapacity=0.9791667, numApps=5, numContainers=42 usedCapacity=0.9791667 absoluteUsedCapacity=0.9791667 used=<memory:48128, vCores:42> cluster=<memory:49152, vCores:96>
2013-08-22 03:36:04,375 INFO org.apache.hadoop.yarn.server.resourcemanager.scheduler.capacity.ParentQueue: completedContainer queue=root usedCapacity=0.9791667 absoluteUsedCapacity=0.9791667 used=<memory:48128, vCores:42> cluster=<memory:49152, vCores:96>
2013-08-22 03:36:04,375 INFO org.apache.hadoop.yarn.server.resourcemanager.scheduler.capacity.CapacityScheduler: Application appattempt_1377141553101_0006_000001 released container container_1377141553101_0006_01_000034 on node: host: hadoop-998-4:35553 #containers=6 available=1024 used=7168 with event: FINISHED
2013-08-22 03:36:04,375 INFO org.apache.hadoop.yarn.server.resourcemanager.rmcontainer.RMContainerImpl: container_1377141553101_0006_01_000035 Container Transitioned from RUNNING to COMPLETED
2013-08-22 03:36:04,375 INFO org.apache.hadoop.yarn.server.resourcemanager.scheduler.common.fica.FiCaSchedulerApp: Completed container: container_1377141553101_0006_01_000035 in state: COMPLETED event:FINISHED
2013-08-22 03:36:04,375 INFO org.apache.hadoop.yarn.server.resourcemanager.RMAuditLogger: USER=ubuntu	OPERATION=AM Released Container	TARGET=SchedulerApp	RESULT=SUCCESS	APPID=application_1377141553101_0006	CONTAINERID=container_1377141553101_0006_01_000035
2013-08-22 03:36:04,376 INFO org.apache.hadoop.yarn.server.resourcemanager.scheduler.common.fica.FiCaSchedulerNode: Released container container_1377141553101_0006_01_000035 of capacity <memory:1024, vCores:1> on host hadoop-998-4:35553, which currently has 5 containers, <memory:6144, vCores:5> used and <memory:2048, vCores:11> available, release resources=true
2013-08-22 03:36:04,376 INFO org.apache.hadoop.yarn.server.resourcemanager.scheduler.capacity.LeafQueue: default used=<memory:47104, vCores:41> numContainers=41 user=ubuntu user-resources=<memory:47104, vCores:41>
2013-08-22 03:36:04,378 INFO org.apache.hadoop.yarn.server.resourcemanager.scheduler.capacity.LeafQueue: completedContainer container=Container: [ContainerId: container_1377141553101_0006_01_000035, NodeId: hadoop-998-4:35553, NodeHttpAddress: hadoop-998-4:8042, Resource: <memory:1024, vCores:1>, Priority: 20, State: NEW, Token: null, Status: container_id {, app_attempt_id {, application_id {, id: 6, cluster_timestamp: 1377141553101, }, attemptId: 1, }, id: 35, }, state: C_COMPLETE, diagnostics: "Container killed by the ApplicationMaster.\n", exit_status: 0, ] resource=<memory:1024, vCores:1> queue=default: capacity=1.0, absoluteCapacity=1.0, usedResources=<memory:47104, vCores:41>usedCapacity=0.9583333, absoluteUsedCapacity=0.9583333, numApps=5, numContainers=41 usedCapacity=0.9583333 absoluteUsedCapacity=0.9583333 used=<memory:47104, vCores:41> cluster=<memory:49152, vCores:96>
2013-08-22 03:36:04,378 INFO org.apache.hadoop.yarn.server.resourcemanager.scheduler.capacity.ParentQueue: completedContainer queue=root usedCapacity=0.9583333 absoluteUsedCapacity=0.9583333 used=<memory:47104, vCores:41> cluster=<memory:49152, vCores:96>
2013-08-22 03:36:04,378 INFO org.apache.hadoop.yarn.server.resourcemanager.scheduler.capacity.CapacityScheduler: Application appattempt_1377141553101_0006_000001 released container container_1377141553101_0006_01_000035 on node: host: hadoop-998-4:35553 #containers=5 available=2048 used=6144 with event: FINISHED
2013-08-22 03:36:04,379 INFO org.apache.hadoop.yarn.server.resourcemanager.rmcontainer.RMContainerImpl: container_1377141553101_0007_01_000003 Container Transitioned from NEW to ALLOCATED
2013-08-22 03:36:04,379 INFO org.apache.hadoop.yarn.server.resourcemanager.RMAuditLogger: USER=ubuntu	OPERATION=AM Allocated Container	TARGET=SchedulerApp	RESULT=SUCCESS	APPID=application_1377141553101_0007	CONTAINERID=container_1377141553101_0007_01_000003
2013-08-22 03:36:04,379 INFO org.apache.hadoop.yarn.server.resourcemanager.scheduler.common.fica.FiCaSchedulerNode: Assigned container container_1377141553101_0007_01_000003 of capacity <memory:1024, vCores:1> on host hadoop-998-4:35553, which currently has 6 containers, <memory:7168, vCores:6> used and <memory:1024, vCores:10> available
2013-08-22 03:36:04,380 INFO org.apache.hadoop.yarn.server.resourcemanager.scheduler.capacity.LeafQueue: assignedContainer application=application_1377141553101_0007 container=Container: [ContainerId: container_1377141553101_0007_01_000003, NodeId: hadoop-998-4:35553, NodeHttpAddress: hadoop-998-4:8042, Resource: <memory:1024, vCores:1>, Priority: 20, State: NEW, Token: null, Status: container_id {, app_attempt_id {, application_id {, id: 7, cluster_timestamp: 1377141553101, }, attemptId: 1, }, id: 3, }, state: C_NEW, ] containerId=container_1377141553101_0007_01_000003 queue=default: capacity=1.0, absoluteCapacity=1.0, usedResources=<memory:47104, vCores:41>usedCapacity=0.9583333, absoluteUsedCapacity=0.9583333, numApps=5, numContainers=41 usedCapacity=0.9583333 absoluteUsedCapacity=0.9583333 used=<memory:47104, vCores:41> cluster=<memory:49152, vCores:96>
2013-08-22 03:36:04,380 INFO org.apache.hadoop.yarn.server.resourcemanager.scheduler.capacity.ParentQueue: Re-sorting queues since queue: root.default stats: default: capacity=1.0, absoluteCapacity=1.0, usedResources=<memory:48128, vCores:42>usedCapacity=0.9791667, absoluteUsedCapacity=0.9791667, numApps=5, numContainers=42
2013-08-22 03:36:04,381 INFO org.apache.hadoop.yarn.server.resourcemanager.scheduler.capacity.ParentQueue: assignedContainer queue=root usedCapacity=0.9791667 absoluteUsedCapacity=0.9791667 used=<memory:48128, vCores:42> cluster=<memory:49152, vCores:96>
2013-08-22 03:36:04,381 INFO org.apache.hadoop.yarn.server.resourcemanager.rmcontainer.RMContainerImpl: container_1377141553101_0007_01_000004 Container Transitioned from NEW to ALLOCATED
2013-08-22 03:36:04,381 INFO org.apache.hadoop.yarn.server.resourcemanager.RMAuditLogger: USER=ubuntu	OPERATION=AM Allocated Container	TARGET=SchedulerApp	RESULT=SUCCESS	APPID=application_1377141553101_0007	CONTAINERID=container_1377141553101_0007_01_000004
2013-08-22 03:36:04,382 INFO org.apache.hadoop.yarn.server.resourcemanager.scheduler.common.fica.FiCaSchedulerNode: Assigned container container_1377141553101_0007_01_000004 of capacity <memory:1024, vCores:1> on host hadoop-998-4:35553, which currently has 7 containers, <memory:8192, vCores:7> used and <memory:0, vCores:9> available
2013-08-22 03:36:04,383 INFO org.apache.hadoop.yarn.server.resourcemanager.scheduler.capacity.LeafQueue: assignedContainer application=application_1377141553101_0007 container=Container: [ContainerId: container_1377141553101_0007_01_000004, NodeId: hadoop-998-4:35553, NodeHttpAddress: hadoop-998-4:8042, Resource: <memory:1024, vCores:1>, Priority: 20, State: NEW, Token: null, Status: container_id {, app_attempt_id {, application_id {, id: 7, cluster_timestamp: 1377141553101, }, attemptId: 1, }, id: 4, }, state: C_NEW, ] containerId=container_1377141553101_0007_01_000004 queue=default: capacity=1.0, absoluteCapacity=1.0, usedResources=<memory:48128, vCores:42>usedCapacity=0.9791667, absoluteUsedCapacity=0.9791667, numApps=5, numContainers=42 usedCapacity=0.9791667 absoluteUsedCapacity=0.9791667 used=<memory:48128, vCores:42> cluster=<memory:49152, vCores:96>
2013-08-22 03:36:04,383 INFO org.apache.hadoop.yarn.server.resourcemanager.scheduler.capacity.ParentQueue: Re-sorting queues since queue: root.default stats: default: capacity=1.0, absoluteCapacity=1.0, usedResources=<memory:49152, vCores:43>usedCapacity=1.0, absoluteUsedCapacity=1.0, numApps=5, numContainers=43
2013-08-22 03:36:04,383 INFO org.apache.hadoop.yarn.server.resourcemanager.scheduler.capacity.ParentQueue: assignedContainer queue=root usedCapacity=1.0 absoluteUsedCapacity=1.0 used=<memory:49152, vCores:43> cluster=<memory:49152, vCores:96>
2013-08-22 03:36:04,559 INFO org.apache.hadoop.yarn.server.resourcemanager.rmcontainer.RMContainerImpl: container_1377141553101_0007_01_000003 Container Transitioned from ALLOCATED to ACQUIRED
2013-08-22 03:36:04,560 INFO org.apache.hadoop.yarn.server.resourcemanager.rmcontainer.RMContainerImpl: container_1377141553101_0007_01_000004 Container Transitioned from ALLOCATED to ACQUIRED
2013-08-22 03:36:04,993 INFO org.apache.hadoop.yarn.server.resourcemanager.rmcontainer.RMContainerImpl: container_1377141553101_0006_01_000042 Container Transitioned from ALLOCATED to ACQUIRED
2013-08-22 03:36:05,087 INFO org.apache.hadoop.yarn.server.resourcemanager.rmcontainer.RMContainerImpl: container_1377141553101_0007_01_000002 Container Transitioned from ACQUIRED to RUNNING
2013-08-22 03:36:05,400 INFO org.apache.hadoop.yarn.server.resourcemanager.rmcontainer.RMContainerImpl: container_1377141553101_0007_01_000003 Container Transitioned from ACQUIRED to RUNNING
2013-08-22 03:36:05,401 INFO org.apache.hadoop.yarn.server.resourcemanager.rmcontainer.RMContainerImpl: container_1377141553101_0007_01_000004 Container Transitioned from ACQUIRED to RUNNING
2013-08-22 03:36:06,005 INFO org.apache.hadoop.yarn.server.resourcemanager.scheduler.AppSchedulingInfo: checking for deactivate... 
2013-08-22 03:36:06,102 INFO org.apache.hadoop.yarn.server.resourcemanager.rmcontainer.RMContainerImpl: container_1377141553101_0006_01_000042 Container Transitioned from ACQUIRED to RUNNING
2013-08-22 03:36:07,630 INFO org.apache.hadoop.yarn.server.resourcemanager.rmcontainer.RMContainerImpl: container_1377141553101_0006_01_000003 Container Transitioned from RUNNING to COMPLETED
2013-08-22 03:36:07,630 INFO org.apache.hadoop.yarn.server.resourcemanager.scheduler.common.fica.FiCaSchedulerApp: Completed container: container_1377141553101_0006_01_000003 in state: COMPLETED event:FINISHED
2013-08-22 03:36:07,630 INFO org.apache.hadoop.yarn.server.resourcemanager.RMAuditLogger: USER=ubuntu	OPERATION=AM Released Container	TARGET=SchedulerApp	RESULT=SUCCESS	APPID=application_1377141553101_0006	CONTAINERID=container_1377141553101_0006_01_000003
2013-08-22 03:36:07,630 INFO org.apache.hadoop.yarn.server.resourcemanager.scheduler.common.fica.FiCaSchedulerNode: Released container container_1377141553101_0006_01_000003 of capacity <memory:1024, vCores:1> on host hadoop-998-2:35081, which currently has 6 containers, <memory:7168, vCores:6> used and <memory:1024, vCores:10> available, release resources=true
2013-08-22 03:36:07,630 INFO org.apache.hadoop.yarn.server.resourcemanager.scheduler.capacity.LeafQueue: default used=<memory:48128, vCores:42> numContainers=42 user=ubuntu user-resources=<memory:48128, vCores:42>
2013-08-22 03:36:07,632 INFO org.apache.hadoop.yarn.server.resourcemanager.scheduler.capacity.LeafQueue: completedContainer container=Container: [ContainerId: container_1377141553101_0006_01_000003, NodeId: hadoop-998-2:35081, NodeHttpAddress: hadoop-998-2:8042, Resource: <memory:1024, vCores:1>, Priority: 20, State: NEW, Token: null, Status: container_id {, app_attempt_id {, application_id {, id: 6, cluster_timestamp: 1377141553101, }, attemptId: 1, }, id: 3, }, state: C_COMPLETE, diagnostics: "Container killed by the ApplicationMaster.\n", exit_status: 0, ] resource=<memory:1024, vCores:1> queue=default: capacity=1.0, absoluteCapacity=1.0, usedResources=<memory:48128, vCores:42>usedCapacity=0.9791667, absoluteUsedCapacity=0.9791667, numApps=5, numContainers=42 usedCapacity=0.9791667 absoluteUsedCapacity=0.9791667 used=<memory:48128, vCores:42> cluster=<memory:49152, vCores:96>
2013-08-22 03:36:07,632 INFO org.apache.hadoop.yarn.server.resourcemanager.scheduler.capacity.ParentQueue: completedContainer queue=root usedCapacity=0.9791667 absoluteUsedCapacity=0.9791667 used=<memory:48128, vCores:42> cluster=<memory:49152, vCores:96>
2013-08-22 03:36:07,632 INFO org.apache.hadoop.yarn.server.resourcemanager.scheduler.capacity.CapacityScheduler: Application appattempt_1377141553101_0006_000001 released container container_1377141553101_0006_01_000003 on node: host: hadoop-998-2:35081 #containers=6 available=1024 used=7168 with event: FINISHED
2013-08-22 03:36:07,633 INFO org.apache.hadoop.yarn.server.resourcemanager.rmcontainer.RMContainerImpl: container_1377141553101_0006_01_000043 Container Transitioned from NEW to ALLOCATED
2013-08-22 03:36:07,633 INFO org.apache.hadoop.yarn.server.resourcemanager.RMAuditLogger: USER=ubuntu	OPERATION=AM Allocated Container	TARGET=SchedulerApp	RESULT=SUCCESS	APPID=application_1377141553101_0006	CONTAINERID=container_1377141553101_0006_01_000043
2013-08-22 03:36:07,633 INFO org.apache.hadoop.yarn.server.resourcemanager.scheduler.common.fica.FiCaSchedulerNode: Assigned container container_1377141553101_0006_01_000043 of capacity <memory:1024, vCores:1> on host hadoop-998-2:35081, which currently has 7 containers, <memory:8192, vCores:7> used and <memory:0, vCores:9> available
2013-08-22 03:36:07,634 INFO org.apache.hadoop.yarn.server.resourcemanager.scheduler.capacity.LeafQueue: assignedContainer application=application_1377141553101_0006 container=Container: [ContainerId: container_1377141553101_0006_01_000043, NodeId: hadoop-998-2:35081, NodeHttpAddress: hadoop-998-2:8042, Resource: <memory:1024, vCores:1>, Priority: 20, State: NEW, Token: null, Status: container_id {, app_attempt_id {, application_id {, id: 6, cluster_timestamp: 1377141553101, }, attemptId: 1, }, id: 43, }, state: C_NEW, ] containerId=container_1377141553101_0006_01_000043 queue=default: capacity=1.0, absoluteCapacity=1.0, usedResources=<memory:48128, vCores:42>usedCapacity=0.9791667, absoluteUsedCapacity=0.9791667, numApps=5, numContainers=42 usedCapacity=0.9791667 absoluteUsedCapacity=0.9791667 used=<memory:48128, vCores:42> cluster=<memory:49152, vCores:96>
2013-08-22 03:36:07,634 INFO org.apache.hadoop.yarn.server.resourcemanager.scheduler.capacity.ParentQueue: Re-sorting queues since queue: root.default stats: default: capacity=1.0, absoluteCapacity=1.0, usedResources=<memory:49152, vCores:43>usedCapacity=1.0, absoluteUsedCapacity=1.0, numApps=5, numContainers=43
2013-08-22 03:36:07,635 INFO org.apache.hadoop.yarn.server.resourcemanager.scheduler.capacity.ParentQueue: assignedContainer queue=root usedCapacity=1.0 absoluteUsedCapacity=1.0 used=<memory:49152, vCores:43> cluster=<memory:49152, vCores:96>
2013-08-22 03:36:08,017 INFO org.apache.hadoop.yarn.server.resourcemanager.rmcontainer.RMContainerImpl: container_1377141553101_0006_01_000043 Container Transitioned from ALLOCATED to ACQUIRED
2013-08-22 03:36:08,637 INFO org.apache.hadoop.yarn.server.resourcemanager.rmcontainer.RMContainerImpl: container_1377141553101_0006_01_000043 Container Transitioned from ACQUIRED to RUNNING
2013-08-22 03:36:08,660 INFO org.apache.hadoop.yarn.server.resourcemanager.rmcontainer.RMContainerImpl: container_1377141553101_0006_01_000017 Container Transitioned from RUNNING to COMPLETED
2013-08-22 03:36:08,661 INFO org.apache.hadoop.yarn.server.resourcemanager.scheduler.common.fica.FiCaSchedulerApp: Completed container: container_1377141553101_0006_01_000017 in state: COMPLETED event:FINISHED
2013-08-22 03:36:08,661 INFO org.apache.hadoop.yarn.server.resourcemanager.RMAuditLogger: USER=ubuntu	OPERATION=AM Released Container	TARGET=SchedulerApp	RESULT=SUCCESS	APPID=application_1377141553101_0006	CONTAINERID=container_1377141553101_0006_01_000017
2013-08-22 03:36:08,661 INFO org.apache.hadoop.yarn.server.resourcemanager.scheduler.common.fica.FiCaSchedulerNode: Released container container_1377141553101_0006_01_000017 of capacity <memory:1024, vCores:1> on host hadoop-998-6:58634, which currently has 7 containers, <memory:7168, vCores:7> used and <memory:1024, vCores:9> available, release resources=true
2013-08-22 03:36:08,661 INFO org.apache.hadoop.yarn.server.resourcemanager.scheduler.capacity.LeafQueue: default used=<memory:48128, vCores:42> numContainers=42 user=ubuntu user-resources=<memory:48128, vCores:42>
2013-08-22 03:36:08,662 INFO org.apache.hadoop.yarn.server.resourcemanager.scheduler.capacity.LeafQueue: completedContainer container=Container: [ContainerId: container_1377141553101_0006_01_000017, NodeId: hadoop-998-6:58634, NodeHttpAddress: hadoop-998-6:8042, Resource: <memory:1024, vCores:1>, Priority: 20, State: NEW, Token: null, Status: container_id {, app_attempt_id {, application_id {, id: 6, cluster_timestamp: 1377141553101, }, attemptId: 1, }, id: 17, }, state: C_COMPLETE, diagnostics: "Container killed by the ApplicationMaster.\n", exit_status: 0, ] resource=<memory:1024, vCores:1> queue=default: capacity=1.0, absoluteCapacity=1.0, usedResources=<memory:48128, vCores:42>usedCapacity=0.9791667, absoluteUsedCapacity=0.9791667, numApps=5, numContainers=42 usedCapacity=0.9791667 absoluteUsedCapacity=0.9791667 used=<memory:48128, vCores:42> cluster=<memory:49152, vCores:96>
2013-08-22 03:36:08,663 INFO org.apache.hadoop.yarn.server.resourcemanager.scheduler.capacity.ParentQueue: completedContainer queue=root usedCapacity=0.9791667 absoluteUsedCapacity=0.9791667 used=<memory:48128, vCores:42> cluster=<memory:49152, vCores:96>
2013-08-22 03:36:08,663 INFO org.apache.hadoop.yarn.server.resourcemanager.scheduler.capacity.CapacityScheduler: Application appattempt_1377141553101_0006_000001 released container container_1377141553101_0006_01_000017 on node: host: hadoop-998-6:58634 #containers=7 available=1024 used=7168 with event: FINISHED
2013-08-22 03:36:08,663 INFO org.apache.hadoop.yarn.server.resourcemanager.rmcontainer.RMContainerImpl: container_1377141553101_0007_01_000005 Container Transitioned from NEW to ALLOCATED
2013-08-22 03:36:08,664 INFO org.apache.hadoop.yarn.server.resourcemanager.RMAuditLogger: USER=ubuntu	OPERATION=AM Allocated Container	TARGET=SchedulerApp	RESULT=SUCCESS	APPID=application_1377141553101_0007	CONTAINERID=container_1377141553101_0007_01_000005
2013-08-22 03:36:08,664 INFO org.apache.hadoop.yarn.server.resourcemanager.scheduler.common.fica.FiCaSchedulerNode: Assigned container container_1377141553101_0007_01_000005 of capacity <memory:1024, vCores:1> on host hadoop-998-6:58634, which currently has 8 containers, <memory:8192, vCores:8> used and <memory:0, vCores:8> available
2013-08-22 03:36:08,665 INFO org.apache.hadoop.yarn.server.resourcemanager.scheduler.capacity.LeafQueue: assignedContainer application=application_1377141553101_0007 container=Container: [ContainerId: container_1377141553101_0007_01_000005, NodeId: hadoop-998-6:58634, NodeHttpAddress: hadoop-998-6:8042, Resource: <memory:1024, vCores:1>, Priority: 20, State: NEW, Token: null, Status: container_id {, app_attempt_id {, application_id {, id: 7, cluster_timestamp: 1377141553101, }, attemptId: 1, }, id: 5, }, state: C_NEW, ] containerId=container_1377141553101_0007_01_000005 queue=default: capacity=1.0, absoluteCapacity=1.0, usedResources=<memory:48128, vCores:42>usedCapacity=0.9791667, absoluteUsedCapacity=0.9791667, numApps=5, numContainers=42 usedCapacity=0.9791667 absoluteUsedCapacity=0.9791667 used=<memory:48128, vCores:42> cluster=<memory:49152, vCores:96>
2013-08-22 03:36:08,665 INFO org.apache.hadoop.yarn.server.resourcemanager.scheduler.capacity.ParentQueue: Re-sorting queues since queue: root.default stats: default: capacity=1.0, absoluteCapacity=1.0, usedResources=<memory:49152, vCores:43>usedCapacity=1.0, absoluteUsedCapacity=1.0, numApps=5, numContainers=43
2013-08-22 03:36:08,665 INFO org.apache.hadoop.yarn.server.resourcemanager.scheduler.capacity.ParentQueue: assignedContainer queue=root usedCapacity=1.0 absoluteUsedCapacity=1.0 used=<memory:49152, vCores:43> cluster=<memory:49152, vCores:96>
2013-08-22 03:36:09,025 INFO org.apache.hadoop.yarn.server.resourcemanager.scheduler.AppSchedulingInfo: checking for deactivate... 
2013-08-22 03:36:09,593 INFO org.apache.hadoop.yarn.server.resourcemanager.rmcontainer.RMContainerImpl: container_1377141553101_0007_01_000005 Container Transitioned from ALLOCATED to ACQUIRED
2013-08-22 03:36:09,776 INFO org.apache.hadoop.yarn.server.resourcemanager.rmcontainer.RMContainerImpl: container_1377141553101_0007_01_000005 Container Transitioned from ACQUIRED to RUNNING
2013-08-22 03:36:09,777 INFO org.apache.hadoop.yarn.server.resourcemanager.rmcontainer.RMContainerImpl: container_1377141553101_0006_01_000014 Container Transitioned from RUNNING to COMPLETED
2013-08-22 03:36:09,777 INFO org.apache.hadoop.yarn.server.resourcemanager.scheduler.common.fica.FiCaSchedulerApp: Completed container: container_1377141553101_0006_01_000014 in state: COMPLETED event:FINISHED
2013-08-22 03:36:09,777 INFO org.apache.hadoop.yarn.server.resourcemanager.RMAuditLogger: USER=ubuntu	OPERATION=AM Released Container	TARGET=SchedulerApp	RESULT=SUCCESS	APPID=application_1377141553101_0006	CONTAINERID=container_1377141553101_0006_01_000014
2013-08-22 03:36:09,777 INFO org.apache.hadoop.yarn.server.resourcemanager.scheduler.common.fica.FiCaSchedulerNode: Released container container_1377141553101_0006_01_000014 of capacity <memory:1024, vCores:1> on host hadoop-998-6:58634, which currently has 7 containers, <memory:7168, vCores:7> used and <memory:1024, vCores:9> available, release resources=true
2013-08-22 03:36:09,777 INFO org.apache.hadoop.yarn.server.resourcemanager.scheduler.capacity.LeafQueue: default used=<memory:48128, vCores:42> numContainers=42 user=ubuntu user-resources=<memory:48128, vCores:42>
2013-08-22 03:36:09,779 INFO org.apache.hadoop.yarn.server.resourcemanager.scheduler.capacity.LeafQueue: completedContainer container=Container: [ContainerId: container_1377141553101_0006_01_000014, NodeId: hadoop-998-6:58634, NodeHttpAddress: hadoop-998-6:8042, Resource: <memory:1024, vCores:1>, Priority: 20, State: NEW, Token: null, Status: container_id {, app_attempt_id {, application_id {, id: 6, cluster_timestamp: 1377141553101, }, attemptId: 1, }, id: 14, }, state: C_COMPLETE, diagnostics: "Container killed by the ApplicationMaster.\n\n", exit_status: 143, ] resource=<memory:1024, vCores:1> queue=default: capacity=1.0, absoluteCapacity=1.0, usedResources=<memory:48128, vCores:42>usedCapacity=0.9791667, absoluteUsedCapacity=0.9791667, numApps=5, numContainers=42 usedCapacity=0.9791667 absoluteUsedCapacity=0.9791667 used=<memory:48128, vCores:42> cluster=<memory:49152, vCores:96>
2013-08-22 03:36:09,779 INFO org.apache.hadoop.yarn.server.resourcemanager.scheduler.capacity.ParentQueue: completedContainer queue=root usedCapacity=0.9791667 absoluteUsedCapacity=0.9791667 used=<memory:48128, vCores:42> cluster=<memory:49152, vCores:96>
2013-08-22 03:36:09,780 INFO org.apache.hadoop.yarn.server.resourcemanager.scheduler.capacity.CapacityScheduler: Application appattempt_1377141553101_0006_000001 released container container_1377141553101_0006_01_000014 on node: host: hadoop-998-6:58634 #containers=7 available=1024 used=7168 with event: FINISHED
2013-08-22 03:36:09,780 INFO org.apache.hadoop.yarn.server.resourcemanager.rmcontainer.RMContainerImpl: container_1377141553101_0007_01_000006 Container Transitioned from NEW to ALLOCATED
2013-08-22 03:36:09,780 INFO org.apache.hadoop.yarn.server.resourcemanager.RMAuditLogger: USER=ubuntu	OPERATION=AM Allocated Container	TARGET=SchedulerApp	RESULT=SUCCESS	APPID=application_1377141553101_0007	CONTAINERID=container_1377141553101_0007_01_000006
2013-08-22 03:36:09,780 INFO org.apache.hadoop.yarn.server.resourcemanager.scheduler.common.fica.FiCaSchedulerNode: Assigned container container_1377141553101_0007_01_000006 of capacity <memory:1024, vCores:1> on host hadoop-998-6:58634, which currently has 8 containers, <memory:8192, vCores:8> used and <memory:0, vCores:8> available
2013-08-22 03:36:09,782 INFO org.apache.hadoop.yarn.server.resourcemanager.scheduler.capacity.LeafQueue: assignedContainer application=application_1377141553101_0007 container=Container: [ContainerId: container_1377141553101_0007_01_000006, NodeId: hadoop-998-6:58634, NodeHttpAddress: hadoop-998-6:8042, Resource: <memory:1024, vCores:1>, Priority: 20, State: NEW, Token: null, Status: container_id {, app_attempt_id {, application_id {, id: 7, cluster_timestamp: 1377141553101, }, attemptId: 1, }, id: 6, }, state: C_NEW, ] containerId=container_1377141553101_0007_01_000006 queue=default: capacity=1.0, absoluteCapacity=1.0, usedResources=<memory:48128, vCores:42>usedCapacity=0.9791667, absoluteUsedCapacity=0.9791667, numApps=5, numContainers=42 usedCapacity=0.9791667 absoluteUsedCapacity=0.9791667 used=<memory:48128, vCores:42> cluster=<memory:49152, vCores:96>
2013-08-22 03:36:09,782 INFO org.apache.hadoop.yarn.server.resourcemanager.scheduler.capacity.ParentQueue: Re-sorting queues since queue: root.default stats: default: capacity=1.0, absoluteCapacity=1.0, usedResources=<memory:49152, vCores:43>usedCapacity=1.0, absoluteUsedCapacity=1.0, numApps=5, numContainers=43
2013-08-22 03:36:09,782 INFO org.apache.hadoop.yarn.server.resourcemanager.scheduler.capacity.ParentQueue: assignedContainer queue=root usedCapacity=1.0 absoluteUsedCapacity=1.0 used=<memory:49152, vCores:43> cluster=<memory:49152, vCores:96>
2013-08-22 03:36:10,609 INFO org.apache.hadoop.yarn.server.resourcemanager.rmcontainer.RMContainerImpl: container_1377141553101_0007_01_000006 Container Transitioned from ALLOCATED to ACQUIRED
2013-08-22 03:36:11,067 INFO org.apache.hadoop.yarn.server.resourcemanager.rmcontainer.RMContainerImpl: container_1377141553101_0006_01_000009 Container Transitioned from RUNNING to COMPLETED
2013-08-22 03:36:11,068 INFO org.apache.hadoop.yarn.server.resourcemanager.scheduler.common.fica.FiCaSchedulerApp: Completed container: container_1377141553101_0006_01_000009 in state: COMPLETED event:FINISHED
2013-08-22 03:36:11,068 INFO org.apache.hadoop.yarn.server.resourcemanager.RMAuditLogger: USER=ubuntu	OPERATION=AM Released Container	TARGET=SchedulerApp	RESULT=SUCCESS	APPID=application_1377141553101_0006	CONTAINERID=container_1377141553101_0006_01_000009
2013-08-22 03:36:11,068 INFO org.apache.hadoop.yarn.server.resourcemanager.scheduler.common.fica.FiCaSchedulerNode: Released container container_1377141553101_0006_01_000009 of capacity <memory:1024, vCores:1> on host hadoop-998-7:60905, which currently has 6 containers, <memory:7168, vCores:6> used and <memory:1024, vCores:10> available, release resources=true
2013-08-22 03:36:11,068 INFO org.apache.hadoop.yarn.server.resourcemanager.scheduler.capacity.LeafQueue: default used=<memory:48128, vCores:42> numContainers=42 user=ubuntu user-resources=<memory:48128, vCores:42>
2013-08-22 03:36:11,070 INFO org.apache.hadoop.yarn.server.resourcemanager.scheduler.capacity.LeafQueue: completedContainer container=Container: [ContainerId: container_1377141553101_0006_01_000009, NodeId: hadoop-998-7:60905, NodeHttpAddress: hadoop-998-7:8042, Resource: <memory:1024, vCores:1>, Priority: 20, State: NEW, Token: null, Status: container_id {, app_attempt_id {, application_id {, id: 6, cluster_timestamp: 1377141553101, }, attemptId: 1, }, id: 9, }, state: C_COMPLETE, diagnostics: "Container killed by the ApplicationMaster.\n\n", exit_status: 143, ] resource=<memory:1024, vCores:1> queue=default: capacity=1.0, absoluteCapacity=1.0, usedResources=<memory:48128, vCores:42>usedCapacity=0.9791667, absoluteUsedCapacity=0.9791667, numApps=5, numContainers=42 usedCapacity=0.9791667 absoluteUsedCapacity=0.9791667 used=<memory:48128, vCores:42> cluster=<memory:49152, vCores:96>
2013-08-22 03:36:11,070 INFO org.apache.hadoop.yarn.server.resourcemanager.scheduler.capacity.ParentQueue: completedContainer queue=root usedCapacity=0.9791667 absoluteUsedCapacity=0.9791667 used=<memory:48128, vCores:42> cluster=<memory:49152, vCores:96>
2013-08-22 03:36:11,070 INFO org.apache.hadoop.yarn.server.resourcemanager.scheduler.capacity.CapacityScheduler: Application appattempt_1377141553101_0006_000001 released container container_1377141553101_0006_01_000009 on node: host: hadoop-998-7:60905 #containers=6 available=1024 used=7168 with event: FINISHED
2013-08-22 03:36:11,071 INFO org.apache.hadoop.yarn.server.resourcemanager.rmcontainer.RMContainerImpl: container_1377141553101_0007_01_000007 Container Transitioned from NEW to ALLOCATED
2013-08-22 03:36:11,071 INFO org.apache.hadoop.yarn.server.resourcemanager.RMAuditLogger: USER=ubuntu	OPERATION=AM Allocated Container	TARGET=SchedulerApp	RESULT=SUCCESS	APPID=application_1377141553101_0007	CONTAINERID=container_1377141553101_0007_01_000007
2013-08-22 03:36:11,071 INFO org.apache.hadoop.yarn.server.resourcemanager.scheduler.common.fica.FiCaSchedulerNode: Assigned container container_1377141553101_0007_01_000007 of capacity <memory:1024, vCores:1> on host hadoop-998-7:60905, which currently has 7 containers, <memory:8192, vCores:7> used and <memory:0, vCores:9> available
2013-08-22 03:36:11,072 INFO org.apache.hadoop.yarn.server.resourcemanager.scheduler.capacity.LeafQueue: assignedContainer application=application_1377141553101_0007 container=Container: [ContainerId: container_1377141553101_0007_01_000007, NodeId: hadoop-998-7:60905, NodeHttpAddress: hadoop-998-7:8042, Resource: <memory:1024, vCores:1>, Priority: 20, State: NEW, Token: null, Status: container_id {, app_attempt_id {, application_id {, id: 7, cluster_timestamp: 1377141553101, }, attemptId: 1, }, id: 7, }, state: C_NEW, ] containerId=container_1377141553101_0007_01_000007 queue=default: capacity=1.0, absoluteCapacity=1.0, usedResources=<memory:48128, vCores:42>usedCapacity=0.9791667, absoluteUsedCapacity=0.9791667, numApps=5, numContainers=42 usedCapacity=0.9791667 absoluteUsedCapacity=0.9791667 used=<memory:48128, vCores:42> cluster=<memory:49152, vCores:96>
2013-08-22 03:36:11,072 INFO org.apache.hadoop.yarn.server.resourcemanager.scheduler.capacity.ParentQueue: Re-sorting queues since queue: root.default stats: default: capacity=1.0, absoluteCapacity=1.0, usedResources=<memory:49152, vCores:43>usedCapacity=1.0, absoluteUsedCapacity=1.0, numApps=5, numContainers=43
2013-08-22 03:36:11,072 INFO org.apache.hadoop.yarn.server.resourcemanager.scheduler.capacity.ParentQueue: assignedContainer queue=root usedCapacity=1.0 absoluteUsedCapacity=1.0 used=<memory:49152, vCores:43> cluster=<memory:49152, vCores:96>
2013-08-22 03:36:11,356 INFO org.apache.hadoop.yarn.server.resourcemanager.rmcontainer.RMContainerImpl: container_1377141553101_0007_01_000006 Container Transitioned from ACQUIRED to RUNNING
2013-08-22 03:36:11,622 INFO org.apache.hadoop.yarn.server.resourcemanager.rmcontainer.RMContainerImpl: container_1377141553101_0007_01_000007 Container Transitioned from ALLOCATED to ACQUIRED
2013-08-22 03:36:12,079 INFO org.apache.hadoop.yarn.server.resourcemanager.rmcontainer.RMContainerImpl: container_1377141553101_0007_01_000007 Container Transitioned from ACQUIRED to RUNNING
2013-08-22 03:36:12,080 INFO org.apache.hadoop.yarn.server.resourcemanager.rmcontainer.RMContainerImpl: container_1377141553101_0006_01_000010 Container Transitioned from RUNNING to COMPLETED
2013-08-22 03:36:12,080 INFO org.apache.hadoop.yarn.server.resourcemanager.scheduler.common.fica.FiCaSchedulerApp: Completed container: container_1377141553101_0006_01_000010 in state: COMPLETED event:FINISHED
2013-08-22 03:36:12,080 INFO org.apache.hadoop.yarn.server.resourcemanager.RMAuditLogger: USER=ubuntu	OPERATION=AM Released Container	TARGET=SchedulerApp	RESULT=SUCCESS	APPID=application_1377141553101_0006	CONTAINERID=container_1377141553101_0006_01_000010
2013-08-22 03:36:12,080 INFO org.apache.hadoop.yarn.server.resourcemanager.scheduler.common.fica.FiCaSchedulerNode: Released container container_1377141553101_0006_01_000010 of capacity <memory:1024, vCores:1> on host hadoop-998-7:60905, which currently has 6 containers, <memory:7168, vCores:6> used and <memory:1024, vCores:10> available, release resources=true
2013-08-22 03:36:12,080 INFO org.apache.hadoop.yarn.server.resourcemanager.scheduler.capacity.LeafQueue: default used=<memory:48128, vCores:42> numContainers=42 user=ubuntu user-resources=<memory:48128, vCores:42>
2013-08-22 03:36:12,082 INFO org.apache.hadoop.yarn.server.resourcemanager.scheduler.capacity.LeafQueue: completedContainer container=Container: [ContainerId: container_1377141553101_0006_01_000010, NodeId: hadoop-998-7:60905, NodeHttpAddress: hadoop-998-7:8042, Resource: <memory:1024, vCores:1>, Priority: 20, State: NEW, Token: null, Status: container_id {, app_attempt_id {, application_id {, id: 6, cluster_timestamp: 1377141553101, }, attemptId: 1, }, id: 10, }, state: C_COMPLETE, diagnostics: "Container killed by the ApplicationMaster.\n\n", exit_status: 143, ] resource=<memory:1024, vCores:1> queue=default: capacity=1.0, absoluteCapacity=1.0, usedResources=<memory:48128, vCores:42>usedCapacity=0.9791667, absoluteUsedCapacity=0.9791667, numApps=5, numContainers=42 usedCapacity=0.9791667 absoluteUsedCapacity=0.9791667 used=<memory:48128, vCores:42> cluster=<memory:49152, vCores:96>
2013-08-22 03:36:12,082 INFO org.apache.hadoop.yarn.server.resourcemanager.scheduler.capacity.ParentQueue: completedContainer queue=root usedCapacity=0.9791667 absoluteUsedCapacity=0.9791667 used=<memory:48128, vCores:42> cluster=<memory:49152, vCores:96>
2013-08-22 03:36:12,082 INFO org.apache.hadoop.yarn.server.resourcemanager.scheduler.capacity.CapacityScheduler: Application appattempt_1377141553101_0006_000001 released container container_1377141553101_0006_01_000010 on node: host: hadoop-998-7:60905 #containers=6 available=1024 used=7168 with event: FINISHED
2013-08-22 03:36:12,083 INFO org.apache.hadoop.yarn.server.resourcemanager.rmcontainer.RMContainerImpl: container_1377141553101_0007_01_000008 Container Transitioned from NEW to ALLOCATED
2013-08-22 03:36:12,083 INFO org.apache.hadoop.yarn.server.resourcemanager.RMAuditLogger: USER=ubuntu	OPERATION=AM Allocated Container	TARGET=SchedulerApp	RESULT=SUCCESS	APPID=application_1377141553101_0007	CONTAINERID=container_1377141553101_0007_01_000008
2013-08-22 03:36:12,083 INFO org.apache.hadoop.yarn.server.resourcemanager.scheduler.common.fica.FiCaSchedulerNode: Assigned container container_1377141553101_0007_01_000008 of capacity <memory:1024, vCores:1> on host hadoop-998-7:60905, which currently has 7 containers, <memory:8192, vCores:7> used and <memory:0, vCores:9> available
2013-08-22 03:36:12,084 INFO org.apache.hadoop.yarn.server.resourcemanager.scheduler.capacity.LeafQueue: assignedContainer application=application_1377141553101_0007 container=Container: [ContainerId: container_1377141553101_0007_01_000008, NodeId: hadoop-998-7:60905, NodeHttpAddress: hadoop-998-7:8042, Resource: <memory:1024, vCores:1>, Priority: 20, State: NEW, Token: null, Status: container_id {, app_attempt_id {, application_id {, id: 7, cluster_timestamp: 1377141553101, }, attemptId: 1, }, id: 8, }, state: C_NEW, ] containerId=container_1377141553101_0007_01_000008 queue=default: capacity=1.0, absoluteCapacity=1.0, usedResources=<memory:48128, vCores:42>usedCapacity=0.9791667, absoluteUsedCapacity=0.9791667, numApps=5, numContainers=42 usedCapacity=0.9791667 absoluteUsedCapacity=0.9791667 used=<memory:48128, vCores:42> cluster=<memory:49152, vCores:96>
2013-08-22 03:36:12,084 INFO org.apache.hadoop.yarn.server.resourcemanager.scheduler.capacity.ParentQueue: Re-sorting queues since queue: root.default stats: default: capacity=1.0, absoluteCapacity=1.0, usedResources=<memory:49152, vCores:43>usedCapacity=1.0, absoluteUsedCapacity=1.0, numApps=5, numContainers=43
2013-08-22 03:36:12,084 INFO org.apache.hadoop.yarn.server.resourcemanager.scheduler.capacity.ParentQueue: assignedContainer queue=root usedCapacity=1.0 absoluteUsedCapacity=1.0 used=<memory:49152, vCores:43> cluster=<memory:49152, vCores:96>
2013-08-22 03:36:12,638 INFO org.apache.hadoop.yarn.server.resourcemanager.rmcontainer.RMContainerImpl: container_1377141553101_0007_01_000008 Container Transitioned from ALLOCATED to ACQUIRED
2013-08-22 03:36:13,101 INFO org.apache.hadoop.yarn.server.resourcemanager.rmcontainer.RMContainerImpl: container_1377141553101_0007_01_000008 Container Transitioned from ACQUIRED to RUNNING
2013-08-22 03:36:14,999 INFO org.apache.hadoop.yarn.server.resourcemanager.rmcontainer.RMContainerImpl: container_1377141553101_0006_01_000029 Container Transitioned from RUNNING to COMPLETED
2013-08-22 03:36:14,999 INFO org.apache.hadoop.yarn.server.resourcemanager.scheduler.common.fica.FiCaSchedulerApp: Completed container: container_1377141553101_0006_01_000029 in state: COMPLETED event:FINISHED
2013-08-22 03:36:14,999 INFO org.apache.hadoop.yarn.server.resourcemanager.RMAuditLogger: USER=ubuntu	OPERATION=AM Released Container	TARGET=SchedulerApp	RESULT=SUCCESS	APPID=application_1377141553101_0006	CONTAINERID=container_1377141553101_0006_01_000029
2013-08-22 03:36:14,999 INFO org.apache.hadoop.yarn.server.resourcemanager.scheduler.common.fica.FiCaSchedulerNode: Released container container_1377141553101_0006_01_000029 of capacity <memory:1024, vCores:1> on host hadoop-998-3:53776, which currently has 6 containers, <memory:7168, vCores:6> used and <memory:1024, vCores:10> available, release resources=true
2013-08-22 03:36:14,999 INFO org.apache.hadoop.yarn.server.resourcemanager.scheduler.capacity.LeafQueue: default used=<memory:48128, vCores:42> numContainers=42 user=ubuntu user-resources=<memory:48128, vCores:42>
2013-08-22 03:36:15,001 INFO org.apache.hadoop.yarn.server.resourcemanager.scheduler.capacity.LeafQueue: completedContainer container=Container: [ContainerId: container_1377141553101_0006_01_000029, NodeId: hadoop-998-3:53776, NodeHttpAddress: hadoop-998-3:8042, Resource: <memory:1024, vCores:1>, Priority: 20, State: NEW, Token: null, Status: container_id {, app_attempt_id {, application_id {, id: 6, cluster_timestamp: 1377141553101, }, attemptId: 1, }, id: 29, }, state: C_COMPLETE, diagnostics: "Container killed by the ApplicationMaster.\n\n", exit_status: 143, ] resource=<memory:1024, vCores:1> queue=default: capacity=1.0, absoluteCapacity=1.0, usedResources=<memory:48128, vCores:42>usedCapacity=0.9791667, absoluteUsedCapacity=0.9791667, numApps=5, numContainers=42 usedCapacity=0.9791667 absoluteUsedCapacity=0.9791667 used=<memory:48128, vCores:42> cluster=<memory:49152, vCores:96>
2013-08-22 03:36:15,001 INFO org.apache.hadoop.yarn.server.resourcemanager.scheduler.capacity.ParentQueue: completedContainer queue=root usedCapacity=0.9791667 absoluteUsedCapacity=0.9791667 used=<memory:48128, vCores:42> cluster=<memory:49152, vCores:96>
2013-08-22 03:36:15,001 INFO org.apache.hadoop.yarn.server.resourcemanager.scheduler.capacity.CapacityScheduler: Application appattempt_1377141553101_0006_000001 released container container_1377141553101_0006_01_000029 on node: host: hadoop-998-3:53776 #containers=6 available=1024 used=7168 with event: FINISHED
2013-08-22 03:36:15,002 INFO org.apache.hadoop.yarn.server.resourcemanager.rmcontainer.RMContainerImpl: container_1377141553101_0007_01_000009 Container Transitioned from NEW to ALLOCATED
2013-08-22 03:36:15,002 INFO org.apache.hadoop.yarn.server.resourcemanager.RMAuditLogger: USER=ubuntu	OPERATION=AM Allocated Container	TARGET=SchedulerApp	RESULT=SUCCESS	APPID=application_1377141553101_0007	CONTAINERID=container_1377141553101_0007_01_000009
2013-08-22 03:36:15,002 INFO org.apache.hadoop.yarn.server.resourcemanager.scheduler.common.fica.FiCaSchedulerNode: Assigned container container_1377141553101_0007_01_000009 of capacity <memory:1024, vCores:1> on host hadoop-998-3:53776, which currently has 7 containers, <memory:8192, vCores:7> used and <memory:0, vCores:9> available
2013-08-22 03:36:15,003 INFO org.apache.hadoop.yarn.server.resourcemanager.scheduler.capacity.LeafQueue: assignedContainer application=application_1377141553101_0007 container=Container: [ContainerId: container_1377141553101_0007_01_000009, NodeId: hadoop-998-3:53776, NodeHttpAddress: hadoop-998-3:8042, Resource: <memory:1024, vCores:1>, Priority: 20, State: NEW, Token: null, Status: container_id {, app_attempt_id {, application_id {, id: 7, cluster_timestamp: 1377141553101, }, attemptId: 1, }, id: 9, }, state: C_NEW, ] containerId=container_1377141553101_0007_01_000009 queue=default: capacity=1.0, absoluteCapacity=1.0, usedResources=<memory:48128, vCores:42>usedCapacity=0.9791667, absoluteUsedCapacity=0.9791667, numApps=5, numContainers=42 usedCapacity=0.9791667 absoluteUsedCapacity=0.9791667 used=<memory:48128, vCores:42> cluster=<memory:49152, vCores:96>
2013-08-22 03:36:15,003 INFO org.apache.hadoop.yarn.server.resourcemanager.scheduler.capacity.ParentQueue: Re-sorting queues since queue: root.default stats: default: capacity=1.0, absoluteCapacity=1.0, usedResources=<memory:49152, vCores:43>usedCapacity=1.0, absoluteUsedCapacity=1.0, numApps=5, numContainers=43
2013-08-22 03:36:15,003 INFO org.apache.hadoop.yarn.server.resourcemanager.scheduler.capacity.ParentQueue: assignedContainer queue=root usedCapacity=1.0 absoluteUsedCapacity=1.0 used=<memory:49152, vCores:43> cluster=<memory:49152, vCores:96>
2013-08-22 03:36:15,667 INFO org.apache.hadoop.yarn.server.resourcemanager.rmcontainer.RMContainerImpl: container_1377141553101_0007_01_000009 Container Transitioned from ALLOCATED to ACQUIRED
2013-08-22 03:36:16,034 INFO org.apache.hadoop.yarn.server.resourcemanager.rmcontainer.RMContainerImpl: container_1377141553101_0007_01_000009 Container Transitioned from ACQUIRED to RUNNING
2013-08-22 03:36:17,921 INFO org.apache.hadoop.yarn.server.resourcemanager.rmcontainer.RMContainerImpl: container_1377141553101_0006_01_000038 Container Transitioned from RUNNING to COMPLETED
2013-08-22 03:36:17,921 INFO org.apache.hadoop.yarn.server.resourcemanager.scheduler.common.fica.FiCaSchedulerApp: Completed container: container_1377141553101_0006_01_000038 in state: COMPLETED event:FINISHED
2013-08-22 03:36:17,922 INFO org.apache.hadoop.yarn.server.resourcemanager.RMAuditLogger: USER=ubuntu	OPERATION=AM Released Container	TARGET=SchedulerApp	RESULT=SUCCESS	APPID=application_1377141553101_0006	CONTAINERID=container_1377141553101_0006_01_000038
2013-08-22 03:36:17,922 INFO org.apache.hadoop.yarn.server.resourcemanager.scheduler.common.fica.FiCaSchedulerNode: Released container container_1377141553101_0006_01_000038 of capacity <memory:1024, vCores:1> on host hadoop-998-4:35553, which currently has 6 containers, <memory:7168, vCores:6> used and <memory:1024, vCores:10> available, release resources=true
2013-08-22 03:36:17,922 INFO org.apache.hadoop.yarn.server.resourcemanager.scheduler.capacity.LeafQueue: default used=<memory:48128, vCores:42> numContainers=42 user=ubuntu user-resources=<memory:48128, vCores:42>
2013-08-22 03:36:17,923 INFO org.apache.hadoop.yarn.server.resourcemanager.scheduler.capacity.LeafQueue: completedContainer container=Container: [ContainerId: container_1377141553101_0006_01_000038, NodeId: hadoop-998-4:35553, NodeHttpAddress: hadoop-998-4:8042, Resource: <memory:1024, vCores:1>, Priority: 20, State: NEW, Token: null, Status: container_id {, app_attempt_id {, application_id {, id: 6, cluster_timestamp: 1377141553101, }, attemptId: 1, }, id: 38, }, state: C_COMPLETE, diagnostics: "Container killed by the ApplicationMaster.\n\n", exit_status: 143, ] resource=<memory:1024, vCores:1> queue=default: capacity=1.0, absoluteCapacity=1.0, usedResources=<memory:48128, vCores:42>usedCapacity=0.9791667, absoluteUsedCapacity=0.9791667, numApps=5, numContainers=42 usedCapacity=0.9791667 absoluteUsedCapacity=0.9791667 used=<memory:48128, vCores:42> cluster=<memory:49152, vCores:96>
2013-08-22 03:36:17,924 INFO org.apache.hadoop.yarn.server.resourcemanager.scheduler.capacity.ParentQueue: completedContainer queue=root usedCapacity=0.9791667 absoluteUsedCapacity=0.9791667 used=<memory:48128, vCores:42> cluster=<memory:49152, vCores:96>
2013-08-22 03:36:17,924 INFO org.apache.hadoop.yarn.server.resourcemanager.scheduler.capacity.CapacityScheduler: Application appattempt_1377141553101_0006_000001 released container container_1377141553101_0006_01_000038 on node: host: hadoop-998-4:35553 #containers=6 available=1024 used=7168 with event: FINISHED
2013-08-22 03:36:17,924 INFO org.apache.hadoop.yarn.server.resourcemanager.rmcontainer.RMContainerImpl: container_1377141553101_0007_01_000010 Container Transitioned from NEW to ALLOCATED
2013-08-22 03:36:17,924 INFO org.apache.hadoop.yarn.server.resourcemanager.RMAuditLogger: USER=ubuntu	OPERATION=AM Allocated Container	TARGET=SchedulerApp	RESULT=SUCCESS	APPID=application_1377141553101_0007	CONTAINERID=container_1377141553101_0007_01_000010
2013-08-22 03:36:17,925 INFO org.apache.hadoop.yarn.server.resourcemanager.scheduler.common.fica.FiCaSchedulerNode: Assigned container container_1377141553101_0007_01_000010 of capacity <memory:1024, vCores:1> on host hadoop-998-4:35553, which currently has 7 containers, <memory:8192, vCores:7> used and <memory:0, vCores:9> available
2013-08-22 03:36:17,926 INFO org.apache.hadoop.yarn.server.resourcemanager.scheduler.capacity.LeafQueue: assignedContainer application=application_1377141553101_0007 container=Container: [ContainerId: container_1377141553101_0007_01_000010, NodeId: hadoop-998-4:35553, NodeHttpAddress: hadoop-998-4:8042, Resource: <memory:1024, vCores:1>, Priority: 20, State: NEW, Token: null, Status: container_id {, app_attempt_id {, application_id {, id: 7, cluster_timestamp: 1377141553101, }, attemptId: 1, }, id: 10, }, state: C_NEW, ] containerId=container_1377141553101_0007_01_000010 queue=default: capacity=1.0, absoluteCapacity=1.0, usedResources=<memory:48128, vCores:42>usedCapacity=0.9791667, absoluteUsedCapacity=0.9791667, numApps=5, numContainers=42 usedCapacity=0.9791667 absoluteUsedCapacity=0.9791667 used=<memory:48128, vCores:42> cluster=<memory:49152, vCores:96>
2013-08-22 03:36:17,926 INFO org.apache.hadoop.yarn.server.resourcemanager.scheduler.capacity.ParentQueue: Re-sorting queues since queue: root.default stats: default: capacity=1.0, absoluteCapacity=1.0, usedResources=<memory:49152, vCores:43>usedCapacity=1.0, absoluteUsedCapacity=1.0, numApps=5, numContainers=43
2013-08-22 03:36:17,926 INFO org.apache.hadoop.yarn.server.resourcemanager.scheduler.capacity.ParentQueue: assignedContainer queue=root usedCapacity=1.0 absoluteUsedCapacity=1.0 used=<memory:49152, vCores:43> cluster=<memory:49152, vCores:96>
2013-08-22 03:36:18,715 INFO org.apache.hadoop.yarn.server.resourcemanager.rmcontainer.RMContainerImpl: container_1377141553101_0007_01_000010 Container Transitioned from ALLOCATED to ACQUIRED
2013-08-22 03:36:19,167 INFO org.apache.hadoop.yarn.server.resourcemanager.rmcontainer.RMContainerImpl: container_1377141553101_0007_01_000010 Container Transitioned from ACQUIRED to RUNNING
2013-08-22 03:36:19,167 INFO org.apache.hadoop.yarn.server.resourcemanager.rmcontainer.RMContainerImpl: container_1377141553101_0006_01_000039 Container Transitioned from RUNNING to COMPLETED
2013-08-22 03:36:19,167 INFO org.apache.hadoop.yarn.server.resourcemanager.scheduler.common.fica.FiCaSchedulerApp: Completed container: container_1377141553101_0006_01_000039 in state: COMPLETED event:FINISHED
2013-08-22 03:36:19,167 INFO org.apache.hadoop.yarn.server.resourcemanager.RMAuditLogger: USER=ubuntu	OPERATION=AM Released Container	TARGET=SchedulerApp	RESULT=SUCCESS	APPID=application_1377141553101_0006	CONTAINERID=container_1377141553101_0006_01_000039
2013-08-22 03:36:19,168 INFO org.apache.hadoop.yarn.server.resourcemanager.scheduler.common.fica.FiCaSchedulerNode: Released container container_1377141553101_0006_01_000039 of capacity <memory:1024, vCores:1> on host hadoop-998-4:35553, which currently has 6 containers, <memory:7168, vCores:6> used and <memory:1024, vCores:10> available, release resources=true
2013-08-22 03:36:19,168 INFO org.apache.hadoop.yarn.server.resourcemanager.scheduler.capacity.LeafQueue: default used=<memory:48128, vCores:42> numContainers=42 user=ubuntu user-resources=<memory:48128, vCores:42>
2013-08-22 03:36:19,169 INFO org.apache.hadoop.yarn.server.resourcemanager.scheduler.capacity.LeafQueue: completedContainer container=Container: [ContainerId: container_1377141553101_0006_01_000039, NodeId: hadoop-998-4:35553, NodeHttpAddress: hadoop-998-4:8042, Resource: <memory:1024, vCores:1>, Priority: 20, State: NEW, Token: null, Status: container_id {, app_attempt_id {, application_id {, id: 6, cluster_timestamp: 1377141553101, }, attemptId: 1, }, id: 39, }, state: C_COMPLETE, diagnostics: "Container killed by the ApplicationMaster.\n\n", exit_status: 143, ] resource=<memory:1024, vCores:1> queue=default: capacity=1.0, absoluteCapacity=1.0, usedResources=<memory:48128, vCores:42>usedCapacity=0.9791667, absoluteUsedCapacity=0.9791667, numApps=5, numContainers=42 usedCapacity=0.9791667 absoluteUsedCapacity=0.9791667 used=<memory:48128, vCores:42> cluster=<memory:49152, vCores:96>
2013-08-22 03:36:19,169 INFO org.apache.hadoop.yarn.server.resourcemanager.scheduler.capacity.ParentQueue: completedContainer queue=root usedCapacity=0.9791667 absoluteUsedCapacity=0.9791667 used=<memory:48128, vCores:42> cluster=<memory:49152, vCores:96>
2013-08-22 03:36:19,169 INFO org.apache.hadoop.yarn.server.resourcemanager.scheduler.capacity.CapacityScheduler: Application appattempt_1377141553101_0006_000001 released container container_1377141553101_0006_01_000039 on node: host: hadoop-998-4:35553 #containers=6 available=1024 used=7168 with event: FINISHED
2013-08-22 03:36:19,170 INFO org.apache.hadoop.yarn.server.resourcemanager.rmcontainer.RMContainerImpl: container_1377141553101_0007_01_000011 Container Transitioned from NEW to ALLOCATED
2013-08-22 03:36:19,170 INFO org.apache.hadoop.yarn.server.resourcemanager.RMAuditLogger: USER=ubuntu	OPERATION=AM Allocated Container	TARGET=SchedulerApp	RESULT=SUCCESS	APPID=application_1377141553101_0007	CONTAINERID=container_1377141553101_0007_01_000011
2013-08-22 03:36:19,170 INFO org.apache.hadoop.yarn.server.resourcemanager.scheduler.common.fica.FiCaSchedulerNode: Assigned container container_1377141553101_0007_01_000011 of capacity <memory:1024, vCores:1> on host hadoop-998-4:35553, which currently has 7 containers, <memory:8192, vCores:7> used and <memory:0, vCores:9> available
2013-08-22 03:36:19,171 INFO org.apache.hadoop.yarn.server.resourcemanager.scheduler.capacity.LeafQueue: assignedContainer application=application_1377141553101_0007 container=Container: [ContainerId: container_1377141553101_0007_01_000011, NodeId: hadoop-998-4:35553, NodeHttpAddress: hadoop-998-4:8042, Resource: <memory:1024, vCores:1>, Priority: 20, State: NEW, Token: null, Status: container_id {, app_attempt_id {, application_id {, id: 7, cluster_timestamp: 1377141553101, }, attemptId: 1, }, id: 11, }, state: C_NEW, ] containerId=container_1377141553101_0007_01_000011 queue=default: capacity=1.0, absoluteCapacity=1.0, usedResources=<memory:48128, vCores:42>usedCapacity=0.9791667, absoluteUsedCapacity=0.9791667, numApps=5, numContainers=42 usedCapacity=0.9791667 absoluteUsedCapacity=0.9791667 used=<memory:48128, vCores:42> cluster=<memory:49152, vCores:96>
2013-08-22 03:36:19,172 INFO org.apache.hadoop.yarn.server.resourcemanager.scheduler.capacity.ParentQueue: Re-sorting queues since queue: root.default stats: default: capacity=1.0, absoluteCapacity=1.0, usedResources=<memory:49152, vCores:43>usedCapacity=1.0, absoluteUsedCapacity=1.0, numApps=5, numContainers=43
2013-08-22 03:36:19,172 INFO org.apache.hadoop.yarn.server.resourcemanager.scheduler.capacity.ParentQueue: assignedContainer queue=root usedCapacity=1.0 absoluteUsedCapacity=1.0 used=<memory:49152, vCores:43> cluster=<memory:49152, vCores:96>
2013-08-22 03:36:19,725 INFO org.apache.hadoop.yarn.server.resourcemanager.rmcontainer.RMContainerImpl: container_1377141553101_0007_01_000011 Container Transitioned from ALLOCATED to ACQUIRED
2013-08-22 03:36:20,178 INFO org.apache.hadoop.yarn.server.resourcemanager.rmcontainer.RMContainerImpl: container_1377141553101_0007_01_000011 Container Transitioned from ACQUIRED to RUNNING
2013-08-22 03:36:21,630 INFO org.apache.hadoop.yarn.server.resourcemanager.rmcontainer.RMContainerImpl: container_1377141553101_0006_01_000005 Container Transitioned from RUNNING to COMPLETED
2013-08-22 03:36:21,630 INFO org.apache.hadoop.yarn.server.resourcemanager.scheduler.common.fica.FiCaSchedulerApp: Completed container: container_1377141553101_0006_01_000005 in state: COMPLETED event:FINISHED
2013-08-22 03:36:21,630 INFO org.apache.hadoop.yarn.server.resourcemanager.RMAuditLogger: USER=ubuntu	OPERATION=AM Released Container	TARGET=SchedulerApp	RESULT=SUCCESS	APPID=application_1377141553101_0006	CONTAINERID=container_1377141553101_0006_01_000005
2013-08-22 03:36:21,630 INFO org.apache.hadoop.yarn.server.resourcemanager.scheduler.common.fica.FiCaSchedulerNode: Released container container_1377141553101_0006_01_000005 of capacity <memory:1024, vCores:1> on host hadoop-998-2:35081, which currently has 6 containers, <memory:7168, vCores:6> used and <memory:1024, vCores:10> available, release resources=true
2013-08-22 03:36:21,631 INFO org.apache.hadoop.yarn.server.resourcemanager.scheduler.capacity.LeafQueue: default used=<memory:48128, vCores:42> numContainers=42 user=ubuntu user-resources=<memory:48128, vCores:42>
2013-08-22 03:36:21,632 INFO org.apache.hadoop.yarn.server.resourcemanager.scheduler.capacity.LeafQueue: completedContainer container=Container: [ContainerId: container_1377141553101_0006_01_000005, NodeId: hadoop-998-2:35081, NodeHttpAddress: hadoop-998-2:8042, Resource: <memory:1024, vCores:1>, Priority: 20, State: NEW, Token: null, Status: container_id {, app_attempt_id {, application_id {, id: 6, cluster_timestamp: 1377141553101, }, attemptId: 1, }, id: 5, }, state: C_COMPLETE, diagnostics: "Container killed by the ApplicationMaster.\n\n", exit_status: 143, ] resource=<memory:1024, vCores:1> queue=default: capacity=1.0, absoluteCapacity=1.0, usedResources=<memory:48128, vCores:42>usedCapacity=0.9791667, absoluteUsedCapacity=0.9791667, numApps=5, numContainers=42 usedCapacity=0.9791667 absoluteUsedCapacity=0.9791667 used=<memory:48128, vCores:42> cluster=<memory:49152, vCores:96>
2013-08-22 03:36:21,632 INFO org.apache.hadoop.yarn.server.resourcemanager.scheduler.capacity.ParentQueue: completedContainer queue=root usedCapacity=0.9791667 absoluteUsedCapacity=0.9791667 used=<memory:48128, vCores:42> cluster=<memory:49152, vCores:96>
2013-08-22 03:36:21,632 INFO org.apache.hadoop.yarn.server.resourcemanager.scheduler.capacity.CapacityScheduler: Application appattempt_1377141553101_0006_000001 released container container_1377141553101_0006_01_000005 on node: host: hadoop-998-2:35081 #containers=6 available=1024 used=7168 with event: FINISHED
2013-08-22 03:36:21,633 INFO org.apache.hadoop.yarn.server.resourcemanager.rmcontainer.RMContainerImpl: container_1377141553101_0006_01_000044 Container Transitioned from NEW to ALLOCATED
2013-08-22 03:36:21,633 INFO org.apache.hadoop.yarn.server.resourcemanager.RMAuditLogger: USER=ubuntu	OPERATION=AM Allocated Container	TARGET=SchedulerApp	RESULT=SUCCESS	APPID=application_1377141553101_0006	CONTAINERID=container_1377141553101_0006_01_000044
2013-08-22 03:36:21,633 INFO org.apache.hadoop.yarn.server.resourcemanager.scheduler.common.fica.FiCaSchedulerNode: Assigned container container_1377141553101_0006_01_000044 of capacity <memory:1024, vCores:1> on host hadoop-998-2:35081, which currently has 7 containers, <memory:8192, vCores:7> used and <memory:0, vCores:9> available
2013-08-22 03:36:21,634 INFO org.apache.hadoop.yarn.server.resourcemanager.scheduler.capacity.LeafQueue: assignedContainer application=application_1377141553101_0006 container=Container: [ContainerId: container_1377141553101_0006_01_000044, NodeId: hadoop-998-2:35081, NodeHttpAddress: hadoop-998-2:8042, Resource: <memory:1024, vCores:1>, Priority: 20, State: NEW, Token: null, Status: container_id {, app_attempt_id {, application_id {, id: 6, cluster_timestamp: 1377141553101, }, attemptId: 1, }, id: 44, }, state: C_NEW, ] containerId=container_1377141553101_0006_01_000044 queue=default: capacity=1.0, absoluteCapacity=1.0, usedResources=<memory:48128, vCores:42>usedCapacity=0.9791667, absoluteUsedCapacity=0.9791667, numApps=5, numContainers=42 usedCapacity=0.9791667 absoluteUsedCapacity=0.9791667 used=<memory:48128, vCores:42> cluster=<memory:49152, vCores:96>
2013-08-22 03:36:21,634 INFO org.apache.hadoop.yarn.server.resourcemanager.scheduler.capacity.ParentQueue: Re-sorting queues since queue: root.default stats: default: capacity=1.0, absoluteCapacity=1.0, usedResources=<memory:49152, vCores:43>usedCapacity=1.0, absoluteUsedCapacity=1.0, numApps=5, numContainers=43
2013-08-22 03:36:21,635 INFO org.apache.hadoop.yarn.server.resourcemanager.scheduler.capacity.ParentQueue: assignedContainer queue=root usedCapacity=1.0 absoluteUsedCapacity=1.0 used=<memory:49152, vCores:43> cluster=<memory:49152, vCores:96>
2013-08-22 03:36:21,963 INFO org.apache.hadoop.yarn.server.resourcemanager.rmcontainer.RMContainerImpl: container_1377141553101_0006_01_000033 Container Transitioned from RUNNING to COMPLETED
2013-08-22 03:36:21,963 INFO org.apache.hadoop.yarn.server.resourcemanager.scheduler.common.fica.FiCaSchedulerApp: Completed container: container_1377141553101_0006_01_000033 in state: COMPLETED event:FINISHED
2013-08-22 03:36:21,963 INFO org.apache.hadoop.yarn.server.resourcemanager.RMAuditLogger: USER=ubuntu	OPERATION=AM Released Container	TARGET=SchedulerApp	RESULT=SUCCESS	APPID=application_1377141553101_0006	CONTAINERID=container_1377141553101_0006_01_000033
2013-08-22 03:36:21,963 INFO org.apache.hadoop.yarn.server.resourcemanager.scheduler.common.fica.FiCaSchedulerNode: Released container container_1377141553101_0006_01_000033 of capacity <memory:1024, vCores:1> on host hadoop-998-3:53776, which currently has 6 containers, <memory:7168, vCores:6> used and <memory:1024, vCores:10> available, release resources=true
2013-08-22 03:36:21,963 INFO org.apache.hadoop.yarn.server.resourcemanager.scheduler.capacity.LeafQueue: default used=<memory:48128, vCores:42> numContainers=42 user=ubuntu user-resources=<memory:48128, vCores:42>
2013-08-22 03:36:21,965 INFO org.apache.hadoop.yarn.server.resourcemanager.scheduler.capacity.LeafQueue: completedContainer container=Container: [ContainerId: container_1377141553101_0006_01_000033, NodeId: hadoop-998-3:53776, NodeHttpAddress: hadoop-998-3:8042, Resource: <memory:1024, vCores:1>, Priority: 20, State: NEW, Token: null, Status: container_id {, app_attempt_id {, application_id {, id: 6, cluster_timestamp: 1377141553101, }, attemptId: 1, }, id: 33, }, state: C_COMPLETE, diagnostics: "Container killed by the ApplicationMaster.\n\n", exit_status: 143, ] resource=<memory:1024, vCores:1> queue=default: capacity=1.0, absoluteCapacity=1.0, usedResources=<memory:48128, vCores:42>usedCapacity=0.9791667, absoluteUsedCapacity=0.9791667, numApps=5, numContainers=42 usedCapacity=0.9791667 absoluteUsedCapacity=0.9791667 used=<memory:48128, vCores:42> cluster=<memory:49152, vCores:96>
2013-08-22 03:36:21,965 INFO org.apache.hadoop.yarn.server.resourcemanager.scheduler.capacity.ParentQueue: completedContainer queue=root usedCapacity=0.9791667 absoluteUsedCapacity=0.9791667 used=<memory:48128, vCores:42> cluster=<memory:49152, vCores:96>
2013-08-22 03:36:21,965 INFO org.apache.hadoop.yarn.server.resourcemanager.scheduler.capacity.CapacityScheduler: Application appattempt_1377141553101_0006_000001 released container container_1377141553101_0006_01_000033 on node: host: hadoop-998-3:53776 #containers=6 available=1024 used=7168 with event: FINISHED
2013-08-22 03:36:21,966 INFO org.apache.hadoop.yarn.server.resourcemanager.rmcontainer.RMContainerImpl: container_1377141553101_0007_01_000012 Container Transitioned from NEW to ALLOCATED
2013-08-22 03:36:21,966 INFO org.apache.hadoop.yarn.server.resourcemanager.RMAuditLogger: USER=ubuntu	OPERATION=AM Allocated Container	TARGET=SchedulerApp	RESULT=SUCCESS	APPID=application_1377141553101_0007	CONTAINERID=container_1377141553101_0007_01_000012
2013-08-22 03:36:21,966 INFO org.apache.hadoop.yarn.server.resourcemanager.scheduler.common.fica.FiCaSchedulerNode: Assigned container container_1377141553101_0007_01_000012 of capacity <memory:1024, vCores:1> on host hadoop-998-3:53776, which currently has 7 containers, <memory:8192, vCores:7> used and <memory:0, vCores:9> available
2013-08-22 03:36:21,967 INFO org.apache.hadoop.yarn.server.resourcemanager.scheduler.capacity.LeafQueue: assignedContainer application=application_1377141553101_0007 container=Container: [ContainerId: container_1377141553101_0007_01_000012, NodeId: hadoop-998-3:53776, NodeHttpAddress: hadoop-998-3:8042, Resource: <memory:1024, vCores:1>, Priority: 20, State: NEW, Token: null, Status: container_id {, app_attempt_id {, application_id {, id: 7, cluster_timestamp: 1377141553101, }, attemptId: 1, }, id: 12, }, state: C_NEW, ] containerId=container_1377141553101_0007_01_000012 queue=default: capacity=1.0, absoluteCapacity=1.0, usedResources=<memory:48128, vCores:42>usedCapacity=0.9791667, absoluteUsedCapacity=0.9791667, numApps=5, numContainers=42 usedCapacity=0.9791667 absoluteUsedCapacity=0.9791667 used=<memory:48128, vCores:42> cluster=<memory:49152, vCores:96>
2013-08-22 03:36:21,967 INFO org.apache.hadoop.yarn.server.resourcemanager.scheduler.capacity.ParentQueue: Re-sorting queues since queue: root.default stats: default: capacity=1.0, absoluteCapacity=1.0, usedResources=<memory:49152, vCores:43>usedCapacity=1.0, absoluteUsedCapacity=1.0, numApps=5, numContainers=43
2013-08-22 03:36:21,967 INFO org.apache.hadoop.yarn.server.resourcemanager.scheduler.capacity.ParentQueue: assignedContainer queue=root usedCapacity=1.0 absoluteUsedCapacity=1.0 used=<memory:49152, vCores:43> cluster=<memory:49152, vCores:96>
2013-08-22 03:36:22,148 INFO org.apache.hadoop.yarn.server.resourcemanager.rmcontainer.RMContainerImpl: container_1377141553101_0006_01_000044 Container Transitioned from ALLOCATED to ACQUIRED
2013-08-22 03:36:22,157 INFO org.apache.hadoop.yarn.server.resourcemanager.rmcontainer.RMContainerImpl: container_1377141553101_0006_01_000007 Container Transitioned from RUNNING to COMPLETED
2013-08-22 03:36:22,157 INFO org.apache.hadoop.yarn.server.resourcemanager.scheduler.common.fica.FiCaSchedulerApp: Completed container: container_1377141553101_0006_01_000007 in state: COMPLETED event:FINISHED
2013-08-22 03:36:22,157 INFO org.apache.hadoop.yarn.server.resourcemanager.RMAuditLogger: USER=ubuntu	OPERATION=AM Released Container	TARGET=SchedulerApp	RESULT=SUCCESS	APPID=application_1377141553101_0006	CONTAINERID=container_1377141553101_0006_01_000007
2013-08-22 03:36:22,157 INFO org.apache.hadoop.yarn.server.resourcemanager.scheduler.common.fica.FiCaSchedulerNode: Released container container_1377141553101_0006_01_000007 of capacity <memory:1024, vCores:1> on host hadoop-998-2:35081, which currently has 6 containers, <memory:7168, vCores:6> used and <memory:1024, vCores:10> available, release resources=true
2013-08-22 03:36:22,157 INFO org.apache.hadoop.yarn.server.resourcemanager.scheduler.capacity.LeafQueue: default used=<memory:48128, vCores:42> numContainers=42 user=ubuntu user-resources=<memory:48128, vCores:42>
2013-08-22 03:36:22,158 INFO org.apache.hadoop.yarn.server.resourcemanager.scheduler.capacity.LeafQueue: completedContainer container=Container: [ContainerId: container_1377141553101_0006_01_000007, NodeId: hadoop-998-2:35081, NodeHttpAddress: hadoop-998-2:8042, Resource: <memory:1024, vCores:1>, Priority: 20, State: NEW, Token: null, Status: container_id {, app_attempt_id {, application_id {, id: 6, cluster_timestamp: 1377141553101, }, attemptId: 1, }, id: 7, }, state: C_COMPLETE, diagnostics: "Container killed by the ApplicationMaster.\n\n", exit_status: 143, ] resource=<memory:1024, vCores:1> queue=default: capacity=1.0, absoluteCapacity=1.0, usedResources=<memory:48128, vCores:42>usedCapacity=0.9791667, absoluteUsedCapacity=0.9791667, numApps=5, numContainers=42 usedCapacity=0.9791667 absoluteUsedCapacity=0.9791667 used=<memory:48128, vCores:42> cluster=<memory:49152, vCores:96>
2013-08-22 03:36:22,159 INFO org.apache.hadoop.yarn.server.resourcemanager.scheduler.capacity.ParentQueue: completedContainer queue=root usedCapacity=0.9791667 absoluteUsedCapacity=0.9791667 used=<memory:48128, vCores:42> cluster=<memory:49152, vCores:96>
2013-08-22 03:36:22,159 INFO org.apache.hadoop.yarn.server.resourcemanager.scheduler.capacity.CapacityScheduler: Application appattempt_1377141553101_0006_000001 released container container_1377141553101_0006_01_000007 on node: host: hadoop-998-2:35081 #containers=6 available=1024 used=7168 with event: FINISHED
2013-08-22 03:36:22,159 INFO org.apache.hadoop.yarn.server.resourcemanager.rmcontainer.RMContainerImpl: container_1377141553101_0007_01_000013 Container Transitioned from NEW to ALLOCATED
2013-08-22 03:36:22,159 INFO org.apache.hadoop.yarn.server.resourcemanager.RMAuditLogger: USER=ubuntu	OPERATION=AM Allocated Container	TARGET=SchedulerApp	RESULT=SUCCESS	APPID=application_1377141553101_0007	CONTAINERID=container_1377141553101_0007_01_000013
2013-08-22 03:36:22,160 INFO org.apache.hadoop.yarn.server.resourcemanager.scheduler.common.fica.FiCaSchedulerNode: Assigned container container_1377141553101_0007_01_000013 of capacity <memory:1024, vCores:1> on host hadoop-998-2:35081, which currently has 7 containers, <memory:8192, vCores:7> used and <memory:0, vCores:9> available
2013-08-22 03:36:22,161 INFO org.apache.hadoop.yarn.server.resourcemanager.scheduler.capacity.LeafQueue: assignedContainer application=application_1377141553101_0007 container=Container: [ContainerId: container_1377141553101_0007_01_000013, NodeId: hadoop-998-2:35081, NodeHttpAddress: hadoop-998-2:8042, Resource: <memory:1024, vCores:1>, Priority: 20, State: NEW, Token: null, Status: container_id {, app_attempt_id {, application_id {, id: 7, cluster_timestamp: 1377141553101, }, attemptId: 1, }, id: 13, }, state: C_NEW, ] containerId=container_1377141553101_0007_01_000013 queue=default: capacity=1.0, absoluteCapacity=1.0, usedResources=<memory:48128, vCores:42>usedCapacity=0.9791667, absoluteUsedCapacity=0.9791667, numApps=5, numContainers=42 usedCapacity=0.9791667 absoluteUsedCapacity=0.9791667 used=<memory:48128, vCores:42> cluster=<memory:49152, vCores:96>
2013-08-22 03:36:22,161 INFO org.apache.hadoop.yarn.server.resourcemanager.scheduler.capacity.ParentQueue: Re-sorting queues since queue: root.default stats: default: capacity=1.0, absoluteCapacity=1.0, usedResources=<memory:49152, vCores:43>usedCapacity=1.0, absoluteUsedCapacity=1.0, numApps=5, numContainers=43
2013-08-22 03:36:22,161 INFO org.apache.hadoop.yarn.server.resourcemanager.scheduler.capacity.ParentQueue: assignedContainer queue=root usedCapacity=1.0 absoluteUsedCapacity=1.0 used=<memory:49152, vCores:43> cluster=<memory:49152, vCores:96>
2013-08-22 03:36:22,745 INFO org.apache.hadoop.yarn.server.resourcemanager.rmcontainer.RMContainerImpl: container_1377141553101_0007_01_000012 Container Transitioned from ALLOCATED to ACQUIRED
2013-08-22 03:36:22,746 INFO org.apache.hadoop.yarn.server.resourcemanager.rmcontainer.RMContainerImpl: container_1377141553101_0007_01_000013 Container Transitioned from ALLOCATED to ACQUIRED
2013-08-22 03:36:23,011 INFO org.apache.hadoop.yarn.server.resourcemanager.rmcontainer.RMContainerImpl: container_1377141553101_0007_01_000012 Container Transitioned from ACQUIRED to RUNNING
2013-08-22 03:36:23,160 INFO org.apache.hadoop.yarn.server.resourcemanager.scheduler.AppSchedulingInfo: checking for deactivate... 
2013-08-22 03:36:23,162 INFO org.apache.hadoop.yarn.server.resourcemanager.rmcontainer.RMContainerImpl: container_1377141553101_0006_01_000044 Container Transitioned from ACQUIRED to RUNNING
2013-08-22 03:36:23,163 INFO org.apache.hadoop.yarn.server.resourcemanager.rmcontainer.RMContainerImpl: container_1377141553101_0007_01_000013 Container Transitioned from ACQUIRED to RUNNING
2013-08-22 03:36:23,163 INFO org.apache.hadoop.yarn.server.resourcemanager.rmcontainer.RMContainerImpl: container_1377141553101_0006_01_000002 Container Transitioned from RUNNING to COMPLETED
2013-08-22 03:36:23,163 INFO org.apache.hadoop.yarn.server.resourcemanager.scheduler.common.fica.FiCaSchedulerApp: Completed container: container_1377141553101_0006_01_000002 in state: COMPLETED event:FINISHED
2013-08-22 03:36:23,163 INFO org.apache.hadoop.yarn.server.resourcemanager.RMAuditLogger: USER=ubuntu	OPERATION=AM Released Container	TARGET=SchedulerApp	RESULT=SUCCESS	APPID=application_1377141553101_0006	CONTAINERID=container_1377141553101_0006_01_000002
2013-08-22 03:36:23,163 INFO org.apache.hadoop.yarn.server.resourcemanager.scheduler.common.fica.FiCaSchedulerNode: Released container container_1377141553101_0006_01_000002 of capacity <memory:1024, vCores:1> on host hadoop-998-2:35081, which currently has 6 containers, <memory:7168, vCores:6> used and <memory:1024, vCores:10> available, release resources=true
2013-08-22 03:36:23,164 INFO org.apache.hadoop.yarn.server.resourcemanager.scheduler.capacity.LeafQueue: default used=<memory:48128, vCores:42> numContainers=42 user=ubuntu user-resources=<memory:48128, vCores:42>
2013-08-22 03:36:23,165 INFO org.apache.hadoop.yarn.server.resourcemanager.scheduler.capacity.LeafQueue: completedContainer container=Container: [ContainerId: container_1377141553101_0006_01_000002, NodeId: hadoop-998-2:35081, NodeHttpAddress: hadoop-998-2:8042, Resource: <memory:1024, vCores:1>, Priority: 20, State: NEW, Token: null, Status: container_id {, app_attempt_id {, application_id {, id: 6, cluster_timestamp: 1377141553101, }, attemptId: 1, }, id: 2, }, state: C_COMPLETE, diagnostics: "Container killed by the ApplicationMaster.\n\n", exit_status: 143, ] resource=<memory:1024, vCores:1> queue=default: capacity=1.0, absoluteCapacity=1.0, usedResources=<memory:48128, vCores:42>usedCapacity=0.9791667, absoluteUsedCapacity=0.9791667, numApps=5, numContainers=42 usedCapacity=0.9791667 absoluteUsedCapacity=0.9791667 used=<memory:48128, vCores:42> cluster=<memory:49152, vCores:96>
2013-08-22 03:36:23,165 INFO org.apache.hadoop.yarn.server.resourcemanager.scheduler.capacity.ParentQueue: completedContainer queue=root usedCapacity=0.9791667 absoluteUsedCapacity=0.9791667 used=<memory:48128, vCores:42> cluster=<memory:49152, vCores:96>
2013-08-22 03:36:23,165 INFO org.apache.hadoop.yarn.server.resourcemanager.scheduler.capacity.CapacityScheduler: Application appattempt_1377141553101_0006_000001 released container container_1377141553101_0006_01_000002 on node: host: hadoop-998-2:35081 #containers=6 available=1024 used=7168 with event: FINISHED
2013-08-22 03:36:23,166 INFO org.apache.hadoop.yarn.server.resourcemanager.rmcontainer.RMContainerImpl: container_1377141553101_0007_01_000014 Container Transitioned from NEW to ALLOCATED
2013-08-22 03:36:23,166 INFO org.apache.hadoop.yarn.server.resourcemanager.RMAuditLogger: USER=ubuntu	OPERATION=AM Allocated Container	TARGET=SchedulerApp	RESULT=SUCCESS	APPID=application_1377141553101_0007	CONTAINERID=container_1377141553101_0007_01_000014
2013-08-22 03:36:23,166 INFO org.apache.hadoop.yarn.server.resourcemanager.scheduler.common.fica.FiCaSchedulerNode: Assigned container container_1377141553101_0007_01_000014 of capacity <memory:1024, vCores:1> on host hadoop-998-2:35081, which currently has 7 containers, <memory:8192, vCores:7> used and <memory:0, vCores:9> available
2013-08-22 03:36:23,167 INFO org.apache.hadoop.yarn.server.resourcemanager.scheduler.capacity.LeafQueue: assignedContainer application=application_1377141553101_0007 container=Container: [ContainerId: container_1377141553101_0007_01_000014, NodeId: hadoop-998-2:35081, NodeHttpAddress: hadoop-998-2:8042, Resource: <memory:1024, vCores:1>, Priority: 20, State: NEW, Token: null, Status: container_id {, app_attempt_id {, application_id {, id: 7, cluster_timestamp: 1377141553101, }, attemptId: 1, }, id: 14, }, state: C_NEW, ] containerId=container_1377141553101_0007_01_000014 queue=default: capacity=1.0, absoluteCapacity=1.0, usedResources=<memory:48128, vCores:42>usedCapacity=0.9791667, absoluteUsedCapacity=0.9791667, numApps=5, numContainers=42 usedCapacity=0.9791667 absoluteUsedCapacity=0.9791667 used=<memory:48128, vCores:42> cluster=<memory:49152, vCores:96>
2013-08-22 03:36:23,167 INFO org.apache.hadoop.yarn.server.resourcemanager.scheduler.capacity.ParentQueue: Re-sorting queues since queue: root.default stats: default: capacity=1.0, absoluteCapacity=1.0, usedResources=<memory:49152, vCores:43>usedCapacity=1.0, absoluteUsedCapacity=1.0, numApps=5, numContainers=43
2013-08-22 03:36:23,168 INFO org.apache.hadoop.yarn.server.resourcemanager.scheduler.capacity.ParentQueue: assignedContainer queue=root usedCapacity=1.0 absoluteUsedCapacity=1.0 used=<memory:49152, vCores:43> cluster=<memory:49152, vCores:96>
2013-08-22 03:36:23,761 INFO org.apache.hadoop.yarn.server.resourcemanager.rmcontainer.RMContainerImpl: container_1377141553101_0007_01_000014 Container Transitioned from ALLOCATED to ACQUIRED
2013-08-22 03:36:24,142 INFO org.apache.hadoop.yarn.server.resourcemanager.rmcontainer.RMContainerImpl: container_1377141553101_0006_01_000030 Container Transitioned from RUNNING to COMPLETED
2013-08-22 03:36:24,142 INFO org.apache.hadoop.yarn.server.resourcemanager.scheduler.common.fica.FiCaSchedulerApp: Completed container: container_1377141553101_0006_01_000030 in state: COMPLETED event:FINISHED
2013-08-22 03:36:24,142 INFO org.apache.hadoop.yarn.server.resourcemanager.RMAuditLogger: USER=ubuntu	OPERATION=AM Released Container	TARGET=SchedulerApp	RESULT=SUCCESS	APPID=application_1377141553101_0006	CONTAINERID=container_1377141553101_0006_01_000030
2013-08-22 03:36:24,143 INFO org.apache.hadoop.yarn.server.resourcemanager.scheduler.common.fica.FiCaSchedulerNode: Released container container_1377141553101_0006_01_000030 of capacity <memory:1024, vCores:1> on host hadoop-998-3:53776, which currently has 6 containers, <memory:7168, vCores:6> used and <memory:1024, vCores:10> available, release resources=true
2013-08-22 03:36:24,143 INFO org.apache.hadoop.yarn.server.resourcemanager.scheduler.capacity.LeafQueue: default used=<memory:48128, vCores:42> numContainers=42 user=ubuntu user-resources=<memory:48128, vCores:42>
2013-08-22 03:36:24,144 INFO org.apache.hadoop.yarn.server.resourcemanager.scheduler.capacity.LeafQueue: completedContainer container=Container: [ContainerId: container_1377141553101_0006_01_000030, NodeId: hadoop-998-3:53776, NodeHttpAddress: hadoop-998-3:8042, Resource: <memory:1024, vCores:1>, Priority: 20, State: NEW, Token: null, Status: container_id {, app_attempt_id {, application_id {, id: 6, cluster_timestamp: 1377141553101, }, attemptId: 1, }, id: 30, }, state: C_COMPLETE, diagnostics: "Container killed by the ApplicationMaster.\n\n", exit_status: 143, ] resource=<memory:1024, vCores:1> queue=default: capacity=1.0, absoluteCapacity=1.0, usedResources=<memory:48128, vCores:42>usedCapacity=0.9791667, absoluteUsedCapacity=0.9791667, numApps=5, numContainers=42 usedCapacity=0.9791667 absoluteUsedCapacity=0.9791667 used=<memory:48128, vCores:42> cluster=<memory:49152, vCores:96>
2013-08-22 03:36:24,144 INFO org.apache.hadoop.yarn.server.resourcemanager.scheduler.capacity.ParentQueue: completedContainer queue=root usedCapacity=0.9791667 absoluteUsedCapacity=0.9791667 used=<memory:48128, vCores:42> cluster=<memory:49152, vCores:96>
2013-08-22 03:36:24,145 INFO org.apache.hadoop.yarn.server.resourcemanager.scheduler.capacity.CapacityScheduler: Application appattempt_1377141553101_0006_000001 released container container_1377141553101_0006_01_000030 on node: host: hadoop-998-3:53776 #containers=6 available=1024 used=7168 with event: FINISHED
2013-08-22 03:36:24,145 INFO org.apache.hadoop.yarn.server.resourcemanager.rmcontainer.RMContainerImpl: container_1377141553101_0007_01_000015 Container Transitioned from NEW to ALLOCATED
2013-08-22 03:36:24,145 INFO org.apache.hadoop.yarn.server.resourcemanager.RMAuditLogger: USER=ubuntu	OPERATION=AM Allocated Container	TARGET=SchedulerApp	RESULT=SUCCESS	APPID=application_1377141553101_0007	CONTAINERID=container_1377141553101_0007_01_000015
2013-08-22 03:36:24,145 INFO org.apache.hadoop.yarn.server.resourcemanager.scheduler.common.fica.FiCaSchedulerNode: Assigned container container_1377141553101_0007_01_000015 of capacity <memory:1024, vCores:1> on host hadoop-998-3:53776, which currently has 7 containers, <memory:8192, vCores:7> used and <memory:0, vCores:9> available
2013-08-22 03:36:24,146 INFO org.apache.hadoop.yarn.server.resourcemanager.scheduler.capacity.LeafQueue: assignedContainer application=application_1377141553101_0007 container=Container: [ContainerId: container_1377141553101_0007_01_000015, NodeId: hadoop-998-3:53776, NodeHttpAddress: hadoop-998-3:8042, Resource: <memory:1024, vCores:1>, Priority: 20, State: NEW, Token: null, Status: container_id {, app_attempt_id {, application_id {, id: 7, cluster_timestamp: 1377141553101, }, attemptId: 1, }, id: 15, }, state: C_NEW, ] containerId=container_1377141553101_0007_01_000015 queue=default: capacity=1.0, absoluteCapacity=1.0, usedResources=<memory:48128, vCores:42>usedCapacity=0.9791667, absoluteUsedCapacity=0.9791667, numApps=5, numContainers=42 usedCapacity=0.9791667 absoluteUsedCapacity=0.9791667 used=<memory:48128, vCores:42> cluster=<memory:49152, vCores:96>
2013-08-22 03:36:24,147 INFO org.apache.hadoop.yarn.server.resourcemanager.scheduler.capacity.ParentQueue: Re-sorting queues since queue: root.default stats: default: capacity=1.0, absoluteCapacity=1.0, usedResources=<memory:49152, vCores:43>usedCapacity=1.0, absoluteUsedCapacity=1.0, numApps=5, numContainers=43
2013-08-22 03:36:24,147 INFO org.apache.hadoop.yarn.server.resourcemanager.scheduler.capacity.ParentQueue: assignedContainer queue=root usedCapacity=1.0 absoluteUsedCapacity=1.0 used=<memory:49152, vCores:43> cluster=<memory:49152, vCores:96>
2013-08-22 03:36:25,247 INFO org.apache.hadoop.yarn.server.resourcemanager.rmcontainer.RMContainerImpl: container_1377141553101_0007_01_000015 Container Transitioned from ALLOCATED to ACQUIRED
2013-08-22 03:36:25,251 INFO org.apache.hadoop.yarn.server.resourcemanager.rmcontainer.RMContainerImpl: container_1377141553101_0007_01_000014 Container Transitioned from ACQUIRED to RUNNING
2013-08-22 03:36:26,157 INFO org.apache.hadoop.yarn.server.resourcemanager.rmcontainer.RMContainerImpl: container_1377141553101_0007_01_000015 Container Transitioned from ACQUIRED to RUNNING
2013-08-22 03:36:29,562 INFO org.apache.hadoop.yarn.server.resourcemanager.rmcontainer.RMContainerImpl: container_1377141553101_0006_01_000040 Container Transitioned from RUNNING to COMPLETED
2013-08-22 03:36:29,562 INFO org.apache.hadoop.yarn.server.resourcemanager.scheduler.common.fica.FiCaSchedulerApp: Completed container: container_1377141553101_0006_01_000040 in state: COMPLETED event:FINISHED
2013-08-22 03:36:29,563 INFO org.apache.hadoop.yarn.server.resourcemanager.RMAuditLogger: USER=ubuntu	OPERATION=AM Released Container	TARGET=SchedulerApp	RESULT=SUCCESS	APPID=application_1377141553101_0006	CONTAINERID=container_1377141553101_0006_01_000040
2013-08-22 03:36:29,563 INFO org.apache.hadoop.yarn.server.resourcemanager.scheduler.common.fica.FiCaSchedulerNode: Released container container_1377141553101_0006_01_000040 of capacity <memory:1024, vCores:1> on host hadoop-998-3:53776, which currently has 6 containers, <memory:7168, vCores:6> used and <memory:1024, vCores:10> available, release resources=true
2013-08-22 03:36:29,563 INFO org.apache.hadoop.yarn.server.resourcemanager.scheduler.capacity.LeafQueue: default used=<memory:48128, vCores:42> numContainers=42 user=ubuntu user-resources=<memory:48128, vCores:42>
2013-08-22 03:36:29,564 INFO org.apache.hadoop.yarn.server.resourcemanager.scheduler.capacity.LeafQueue: completedContainer container=Container: [ContainerId: container_1377141553101_0006_01_000040, NodeId: hadoop-998-3:53776, NodeHttpAddress: hadoop-998-3:8042, Resource: <memory:1024, vCores:1>, Priority: 20, State: NEW, Token: null, Status: container_id {, app_attempt_id {, application_id {, id: 6, cluster_timestamp: 1377141553101, }, attemptId: 1, }, id: 40, }, state: C_COMPLETE, diagnostics: "Container killed by the ApplicationMaster.\n\n", exit_status: 143, ] resource=<memory:1024, vCores:1> queue=default: capacity=1.0, absoluteCapacity=1.0, usedResources=<memory:48128, vCores:42>usedCapacity=0.9791667, absoluteUsedCapacity=0.9791667, numApps=5, numContainers=42 usedCapacity=0.9791667 absoluteUsedCapacity=0.9791667 used=<memory:48128, vCores:42> cluster=<memory:49152, vCores:96>
2013-08-22 03:36:29,564 INFO org.apache.hadoop.yarn.server.resourcemanager.scheduler.capacity.ParentQueue: completedContainer queue=root usedCapacity=0.9791667 absoluteUsedCapacity=0.9791667 used=<memory:48128, vCores:42> cluster=<memory:49152, vCores:96>
2013-08-22 03:36:29,564 INFO org.apache.hadoop.yarn.server.resourcemanager.scheduler.capacity.CapacityScheduler: Application appattempt_1377141553101_0006_000001 released container container_1377141553101_0006_01_000040 on node: host: hadoop-998-3:53776 #containers=6 available=1024 used=7168 with event: FINISHED
2013-08-22 03:36:29,565 INFO org.apache.hadoop.yarn.server.resourcemanager.rmcontainer.RMContainerImpl: container_1377141553101_0007_01_000016 Container Transitioned from NEW to ALLOCATED
2013-08-22 03:36:29,565 INFO org.apache.hadoop.yarn.server.resourcemanager.RMAuditLogger: USER=ubuntu	OPERATION=AM Allocated Container	TARGET=SchedulerApp	RESULT=SUCCESS	APPID=application_1377141553101_0007	CONTAINERID=container_1377141553101_0007_01_000016
2013-08-22 03:36:29,565 INFO org.apache.hadoop.yarn.server.resourcemanager.scheduler.common.fica.FiCaSchedulerNode: Assigned container container_1377141553101_0007_01_000016 of capacity <memory:1024, vCores:1> on host hadoop-998-3:53776, which currently has 7 containers, <memory:8192, vCores:7> used and <memory:0, vCores:9> available
2013-08-22 03:36:29,566 INFO org.apache.hadoop.yarn.server.resourcemanager.scheduler.capacity.LeafQueue: assignedContainer application=application_1377141553101_0007 container=Container: [ContainerId: container_1377141553101_0007_01_000016, NodeId: hadoop-998-3:53776, NodeHttpAddress: hadoop-998-3:8042, Resource: <memory:1024, vCores:1>, Priority: 20, State: NEW, Token: null, Status: container_id {, app_attempt_id {, application_id {, id: 7, cluster_timestamp: 1377141553101, }, attemptId: 1, }, id: 16, }, state: C_NEW, ] containerId=container_1377141553101_0007_01_000016 queue=default: capacity=1.0, absoluteCapacity=1.0, usedResources=<memory:48128, vCores:42>usedCapacity=0.9791667, absoluteUsedCapacity=0.9791667, numApps=5, numContainers=42 usedCapacity=0.9791667 absoluteUsedCapacity=0.9791667 used=<memory:48128, vCores:42> cluster=<memory:49152, vCores:96>
2013-08-22 03:36:29,566 INFO org.apache.hadoop.yarn.server.resourcemanager.scheduler.capacity.ParentQueue: Re-sorting queues since queue: root.default stats: default: capacity=1.0, absoluteCapacity=1.0, usedResources=<memory:49152, vCores:43>usedCapacity=1.0, absoluteUsedCapacity=1.0, numApps=5, numContainers=43
2013-08-22 03:36:29,567 INFO org.apache.hadoop.yarn.server.resourcemanager.scheduler.capacity.ParentQueue: assignedContainer queue=root usedCapacity=1.0 absoluteUsedCapacity=1.0 used=<memory:49152, vCores:43> cluster=<memory:49152, vCores:96>
2013-08-22 03:36:30,269 INFO org.apache.hadoop.yarn.server.resourcemanager.rmcontainer.RMContainerImpl: container_1377141553101_0007_01_000016 Container Transitioned from ALLOCATED to ACQUIRED
2013-08-22 03:36:30,754 INFO org.apache.hadoop.yarn.server.resourcemanager.rmcontainer.RMContainerImpl: container_1377141553101_0007_01_000016 Container Transitioned from ACQUIRED to RUNNING
2013-08-22 03:36:30,755 INFO org.apache.hadoop.yarn.server.resourcemanager.rmcontainer.RMContainerImpl: container_1377141553101_0006_01_000032 Container Transitioned from RUNNING to COMPLETED
2013-08-22 03:36:30,755 INFO org.apache.hadoop.yarn.server.resourcemanager.scheduler.common.fica.FiCaSchedulerApp: Completed container: container_1377141553101_0006_01_000032 in state: COMPLETED event:FINISHED
2013-08-22 03:36:30,755 INFO org.apache.hadoop.yarn.server.resourcemanager.RMAuditLogger: USER=ubuntu	OPERATION=AM Released Container	TARGET=SchedulerApp	RESULT=SUCCESS	APPID=application_1377141553101_0006	CONTAINERID=container_1377141553101_0006_01_000032
2013-08-22 03:36:30,755 INFO org.apache.hadoop.yarn.server.resourcemanager.scheduler.common.fica.FiCaSchedulerNode: Released container container_1377141553101_0006_01_000032 of capacity <memory:1024, vCores:1> on host hadoop-998-3:53776, which currently has 6 containers, <memory:7168, vCores:6> used and <memory:1024, vCores:10> available, release resources=true
2013-08-22 03:36:30,755 INFO org.apache.hadoop.yarn.server.resourcemanager.scheduler.capacity.LeafQueue: default used=<memory:48128, vCores:42> numContainers=42 user=ubuntu user-resources=<memory:48128, vCores:42>
2013-08-22 03:36:30,757 INFO org.apache.hadoop.yarn.server.resourcemanager.scheduler.capacity.LeafQueue: completedContainer container=Container: [ContainerId: container_1377141553101_0006_01_000032, NodeId: hadoop-998-3:53776, NodeHttpAddress: hadoop-998-3:8042, Resource: <memory:1024, vCores:1>, Priority: 20, State: NEW, Token: null, Status: container_id {, app_attempt_id {, application_id {, id: 6, cluster_timestamp: 1377141553101, }, attemptId: 1, }, id: 32, }, state: C_COMPLETE, diagnostics: "Container killed by the ApplicationMaster.\n\n", exit_status: 143, ] resource=<memory:1024, vCores:1> queue=default: capacity=1.0, absoluteCapacity=1.0, usedResources=<memory:48128, vCores:42>usedCapacity=0.9791667, absoluteUsedCapacity=0.9791667, numApps=5, numContainers=42 usedCapacity=0.9791667 absoluteUsedCapacity=0.9791667 used=<memory:48128, vCores:42> cluster=<memory:49152, vCores:96>
2013-08-22 03:36:30,757 INFO org.apache.hadoop.yarn.server.resourcemanager.scheduler.capacity.ParentQueue: completedContainer queue=root usedCapacity=0.9791667 absoluteUsedCapacity=0.9791667 used=<memory:48128, vCores:42> cluster=<memory:49152, vCores:96>
2013-08-22 03:36:30,757 INFO org.apache.hadoop.yarn.server.resourcemanager.scheduler.capacity.CapacityScheduler: Application appattempt_1377141553101_0006_000001 released container container_1377141553101_0006_01_000032 on node: host: hadoop-998-3:53776 #containers=6 available=1024 used=7168 with event: FINISHED
2013-08-22 03:36:30,758 INFO org.apache.hadoop.yarn.server.resourcemanager.rmcontainer.RMContainerImpl: container_1377141553101_0007_01_000017 Container Transitioned from NEW to ALLOCATED
2013-08-22 03:36:30,758 INFO org.apache.hadoop.yarn.server.resourcemanager.RMAuditLogger: USER=ubuntu	OPERATION=AM Allocated Container	TARGET=SchedulerApp	RESULT=SUCCESS	APPID=application_1377141553101_0007	CONTAINERID=container_1377141553101_0007_01_000017
