2013-08-10 05:13:21,675 INFO org.apache.hadoop.yarn.server.resourcemanager.ResourceManager: STARTUP_MSG: 
/************************************************************
STARTUP_MSG: Starting ResourceManager
STARTUP_MSG:   host = hadoop-221-1/192.168.100.36
STARTUP_MSG:   args = []
STARTUP_MSG:   version = 3.0.0-SNAPSHOT
STARTUP_MSG:   build = https://github.com/lalithsuresh/hadoop-common -r 0cb423bd4868928bb06cd93f882bb0913172fd17; compiled by 'lsuresh' on 2013-04-08T15:47Z
STARTUP_MSG:   java = 1.7.0_17
************************************************************/
2013-08-10 05:13:21,689 INFO org.apache.hadoop.yarn.server.resourcemanager.ResourceManager: registered UNIX signal handlers for [TERM, HUP, INT]
2013-08-10 05:13:22,174 INFO org.apache.hadoop.yarn.server.resourcemanager.security.ApplicationTokenSecretManager: Rolling master-key for application-tokens
2013-08-10 05:13:22,202 INFO org.apache.hadoop.yarn.server.resourcemanager.security.RMContainerTokenSecretManager: ContainerTokenKeyRollingInterval: 86400000ms and ContainerTokenKeyActivationDelay: 900000ms
2013-08-10 05:13:22,204 INFO org.apache.hadoop.yarn.service.AbstractService: Service:Dispatcher is inited.
2013-08-10 05:13:22,206 INFO org.apache.hadoop.yarn.event.AsyncDispatcher: Registering class org.apache.hadoop.yarn.server.resourcemanager.recovery.RMStateStoreEventType for class org.apache.hadoop.yarn.server.resourcemanager.recovery.RMStateStore$ForwardingEventHandler
2013-08-10 05:13:22,206 INFO org.apache.hadoop.yarn.service.AbstractService: Service:Dispatcher is started.
2013-08-10 05:13:22,212 INFO org.apache.hadoop.yarn.event.AsyncDispatcher: Registering class org.apache.hadoop.yarn.server.resourcemanager.NodesListManagerEventType for class org.apache.hadoop.yarn.server.resourcemanager.NodesListManager
2013-08-10 05:13:22,212 INFO org.apache.hadoop.yarn.server.resourcemanager.ResourceManager: Using Scheduler: org.apache.hadoop.yarn.server.resourcemanager.scheduler.capacity.CapacityScheduler
2013-08-10 05:13:22,362 INFO org.apache.hadoop.yarn.event.AsyncDispatcher: Registering class org.apache.hadoop.yarn.server.resourcemanager.scheduler.event.SchedulerEventType for class org.apache.hadoop.yarn.server.resourcemanager.ResourceManager$SchedulerEventDispatcher
2013-08-10 05:13:22,363 INFO org.apache.hadoop.yarn.event.AsyncDispatcher: Registering class org.apache.hadoop.yarn.server.resourcemanager.rmapp.RMAppEventType for class org.apache.hadoop.yarn.server.resourcemanager.ResourceManager$ApplicationEventDispatcher
2013-08-10 05:13:22,368 INFO org.apache.hadoop.yarn.event.AsyncDispatcher: Registering class org.apache.hadoop.yarn.server.resourcemanager.rmapp.attempt.RMAppAttemptEventType for class org.apache.hadoop.yarn.server.resourcemanager.ResourceManager$ApplicationAttemptEventDispatcher
2013-08-10 05:13:22,370 INFO org.apache.hadoop.yarn.event.AsyncDispatcher: Registering class org.apache.hadoop.yarn.server.resourcemanager.rmnode.RMNodeEventType for class org.apache.hadoop.yarn.server.resourcemanager.ResourceManager$NodeEventDispatcher
2013-08-10 05:13:22,786 WARN org.apache.hadoop.util.NativeCodeLoader: Unable to load native-hadoop library for your platform... using builtin-java classes where applicable
2013-08-10 05:13:22,803 INFO org.apache.hadoop.yarn.server.resourcemanager.scheduler.capacity.ParentQueue: root, capacity=1.0, asboluteCapacity=1.0, maxCapacity=1.0, asboluteMaxCapacity=1.0, state=RUNNING, acls=SUBMIT_APPLICATIONS:*ADMINISTER_QUEUE:*
2013-08-10 05:13:22,803 INFO org.apache.hadoop.yarn.server.resourcemanager.scheduler.capacity.ParentQueue: Initialized parent-queue root name=root, fullname=root
2013-08-10 05:13:22,815 INFO org.apache.hadoop.yarn.server.resourcemanager.scheduler.capacity.LeafQueue: Initializing default
capacity = 1.0 [= (float) configuredCapacity / 100 ]
asboluteCapacity = 1.0 [= parentAbsoluteCapacity * capacity ]
maxCapacity = 1.0 [= configuredMaxCapacity ]
absoluteMaxCapacity = 1.0 [= 1.0 maximumCapacity undefined, (parentAbsoluteMaxCapacity * maximumCapacity) / 100 otherwise ]
userLimit = 100 [= configuredUserLimit ]
userLimitFactor = 1.0 [= configuredUserLimitFactor ]
maxApplications = 10000 [= configuredMaximumSystemApplicationsPerQueue or (int)(configuredMaximumSystemApplications * absoluteCapacity)]
maxApplicationsPerUser = 10000 [= (int)(maxApplications * (userLimit / 100.0f) * userLimitFactor) ]
maxActiveApplications = 1 [= max((int)ceil((clusterResourceMemory / minimumAllocation) * maxAMResourcePerQueuePercent * absoluteMaxCapacity),1) ]
maxActiveAppsUsingAbsCap = 1 [= max((int)ceil((clusterResourceMemory / minimumAllocation) *maxAMResourcePercent * absoluteCapacity),1) ]
maxActiveApplicationsPerUser = 1 [= max((int)(maxActiveApplications * (userLimit / 100.0f) * userLimitFactor),1) ]
usedCapacity = 0.0 [= usedResourcesMemory / (clusterResourceMemory * absoluteCapacity)]
absoluteUsedCapacity = 0.0 [= usedResourcesMemory / clusterResourceMemory]
maxAMResourcePerQueuePercent = 0.1 [= configuredMaximumAMResourcePercent ]
minimumAllocationFactor = 0.875 [= (float)(maximumAllocationMemory - minimumAllocationMemory) / maximumAllocationMemory ]
numContainers = 0 [= currentNumContainers ]
state = RUNNING [= configuredState ]
acls = SUBMIT_APPLICATIONS:*ADMINISTER_QUEUE:* [= configuredAcls ]

2013-08-10 05:13:22,816 INFO org.apache.hadoop.yarn.server.resourcemanager.scheduler.capacity.CapacityScheduler: Initialized queue: default: capacity=1.0, absoluteCapacity=1.0, usedResources=<memory:0, vCores:0>usedCapacity=0.0, absoluteUsedCapacity=0.0, numApps=0, numContainers=0
2013-08-10 05:13:22,816 INFO org.apache.hadoop.yarn.server.resourcemanager.scheduler.capacity.CapacityScheduler: Initialized queue: root: numChildQueue= 1, capacity=1.0, absoluteCapacity=1.0, usedResources=<memory:0, vCores:0>usedCapacity=0.0, numApps=0, numContainers=0
2013-08-10 05:13:22,816 INFO org.apache.hadoop.yarn.server.resourcemanager.scheduler.capacity.CapacityScheduler: Initialized root queue root: numChildQueue= 1, capacity=1.0, absoluteCapacity=1.0, usedResources=<memory:0, vCores:0>usedCapacity=0.0, numApps=0, numContainers=0
2013-08-10 05:13:22,816 INFO org.apache.hadoop.yarn.server.resourcemanager.scheduler.capacity.CapacityScheduler: Initialized CapacityScheduler with calculator=class org.apache.hadoop.yarn.server.resourcemanager.resource.DefaultResourceCalculator, minimumAllocation=<<memory:1024, vCores:1>>, maximumAllocation=<<memory:8192, vCores:32>>
2013-08-10 05:13:23,038 INFO org.apache.hadoop.yarn.event.AsyncDispatcher: Registering class org.apache.hadoop.yarn.server.resourcemanager.RMAppManagerEventType for class org.apache.hadoop.yarn.server.resourcemanager.RMAppManager
2013-08-10 05:13:23,050 INFO org.apache.hadoop.yarn.event.AsyncDispatcher: Registering class org.apache.hadoop.yarn.server.resourcemanager.amlauncher.AMLauncherEventType for class org.apache.hadoop.yarn.server.resourcemanager.amlauncher.ApplicationMasterLauncher
2013-08-10 05:13:23,105 INFO org.apache.hadoop.yarn.server.resourcemanager.RMNMInfo: Registered RMNMInfo MBean
2013-08-10 05:13:23,106 INFO org.apache.hadoop.yarn.service.AbstractService: Service:Dispatcher is inited.
2013-08-10 05:13:23,106 INFO org.apache.hadoop.yarn.service.AbstractService: Service:org.apache.hadoop.yarn.server.resourcemanager.rmcontainer.ContainerAllocationExpirer is inited.
2013-08-10 05:13:23,106 INFO org.apache.hadoop.yarn.service.AbstractService: Service:AMLivelinessMonitor is inited.
2013-08-10 05:13:23,106 INFO org.apache.hadoop.yarn.service.AbstractService: Service:AMLivelinessMonitor is inited.
2013-08-10 05:13:23,106 INFO org.apache.hadoop.yarn.service.AbstractService: Service:org.apache.hadoop.yarn.server.resourcemanager.security.DelegationTokenRenewer is inited.
2013-08-10 05:13:23,107 INFO org.apache.hadoop.util.HostsFileReader: Refreshing hosts (include/exclude) list
2013-08-10 05:13:23,107 INFO org.apache.hadoop.yarn.service.AbstractService: Service:org.apache.hadoop.yarn.server.resourcemanager.NodesListManager is inited.
2013-08-10 05:13:23,107 INFO org.apache.hadoop.yarn.service.AbstractService: Service:org.apache.hadoop.yarn.server.resourcemanager.ResourceManager$SchedulerEventDispatcher is inited.
2013-08-10 05:13:23,107 INFO org.apache.hadoop.yarn.service.AbstractService: Service:NMLivelinessMonitor is inited.
2013-08-10 05:13:23,112 INFO org.apache.hadoop.yarn.service.AbstractService: Service:org.apache.hadoop.yarn.server.resourcemanager.ResourceTrackerService is inited.
2013-08-10 05:13:23,112 INFO org.apache.hadoop.yarn.service.AbstractService: Service:org.apache.hadoop.yarn.server.resourcemanager.ApplicationMasterService is inited.
2013-08-10 05:13:23,112 INFO org.apache.hadoop.yarn.service.AbstractService: Service:org.apache.hadoop.yarn.server.resourcemanager.ClientRMService is inited.
2013-08-10 05:13:23,112 INFO org.apache.hadoop.yarn.service.AbstractService: Service:org.apache.hadoop.yarn.server.resourcemanager.AdminService is inited.
2013-08-10 05:13:23,112 INFO org.apache.hadoop.yarn.service.AbstractService: Service:org.apache.hadoop.yarn.server.resourcemanager.amlauncher.ApplicationMasterLauncher is inited.
2013-08-10 05:13:23,112 INFO org.apache.hadoop.yarn.service.AbstractService: Service:ResourceManager is inited.
2013-08-10 05:13:23,113 INFO org.apache.hadoop.yarn.server.resourcemanager.security.ApplicationTokenSecretManager: Rolling master-key for application-tokens
2013-08-10 05:13:23,113 INFO org.apache.hadoop.yarn.server.resourcemanager.security.RMContainerTokenSecretManager: Rolling master-key for container-tokens
2013-08-10 05:13:23,200 INFO org.mortbay.log: Logging to org.slf4j.impl.Log4jLoggerAdapter(org.mortbay.log) via org.mortbay.log.Slf4jLog
2013-08-10 05:13:23,255 INFO org.apache.hadoop.http.HttpServer: Added global filter 'safety' (class=org.apache.hadoop.http.HttpServer$QuotingInputFilter)
2013-08-10 05:13:23,258 INFO org.apache.hadoop.http.HttpServer: Added filter static_user_filter (class=org.apache.hadoop.http.lib.StaticUserWebFilter$StaticUserFilter) to context cluster
2013-08-10 05:13:23,258 INFO org.apache.hadoop.http.HttpServer: Added filter static_user_filter (class=org.apache.hadoop.http.lib.StaticUserWebFilter$StaticUserFilter) to context static
2013-08-10 05:13:23,258 INFO org.apache.hadoop.http.HttpServer: Added filter static_user_filter (class=org.apache.hadoop.http.lib.StaticUserWebFilter$StaticUserFilter) to context logs
2013-08-10 05:13:23,262 INFO org.apache.hadoop.http.HttpServer: adding path spec: /cluster
2013-08-10 05:13:23,262 INFO org.apache.hadoop.http.HttpServer: adding path spec: /cluster/*
2013-08-10 05:13:23,263 INFO org.apache.hadoop.http.HttpServer: adding path spec: /ws
2013-08-10 05:13:23,263 INFO org.apache.hadoop.http.HttpServer: adding path spec: /ws/*
2013-08-10 05:13:23,264 INFO org.apache.hadoop.http.HttpServer: Added global filter 'guice' (class=com.google.inject.servlet.GuiceFilter)
2013-08-10 05:13:23,270 INFO org.apache.hadoop.http.HttpServer: Jetty bound to port 8088
2013-08-10 05:13:23,270 INFO org.mortbay.log: jetty-6.1.26
2013-08-10 05:13:23,298 INFO org.mortbay.log: Extract jar:file:/home/ubuntu/hadoop-3.0.0-SNAPSHOT/share/hadoop/yarn/hadoop-yarn-common-3.0.0-SNAPSHOT.jar!/webapps/cluster to /tmp/Jetty_0_0_0_0_8088_cluster____u0rgz3/webapp
2013-08-10 05:13:23,572 INFO org.mortbay.log: Started SelectChannelConnector@0.0.0.0:8088
2013-08-10 05:13:23,572 INFO org.apache.hadoop.yarn.webapp.WebApps: Web app /cluster started at 8088
2013-08-10 05:13:24,034 INFO org.apache.hadoop.yarn.webapp.WebApps: Registered webapp guice modules
2013-08-10 05:13:24,087 INFO org.apache.hadoop.metrics2.impl.MetricsConfig: loaded properties from hadoop-metrics2.properties
2013-08-10 05:13:24,103 INFO org.apache.hadoop.metrics2.impl.MetricsSystemImpl: Scheduled snapshot period at 10 second(s).
2013-08-10 05:13:24,103 INFO org.apache.hadoop.metrics2.impl.MetricsSystemImpl: ResourceManager metrics system started
2013-08-10 05:13:24,110 INFO org.apache.hadoop.security.token.delegation.AbstractDelegationTokenSecretManager: Updating the current master key for generating delegation tokens
2013-08-10 05:13:24,112 INFO org.apache.hadoop.yarn.service.AbstractService: Service:Dispatcher is started.
2013-08-10 05:13:24,112 INFO org.apache.hadoop.security.token.delegation.AbstractDelegationTokenSecretManager: Starting expired delegation token remover thread, tokenRemoverScanInterval=60 min(s)
2013-08-10 05:13:24,112 INFO org.apache.hadoop.security.token.delegation.AbstractDelegationTokenSecretManager: Updating the current master key for generating delegation tokens
2013-08-10 05:13:24,113 INFO org.apache.hadoop.yarn.service.AbstractService: Service:org.apache.hadoop.yarn.server.resourcemanager.rmcontainer.ContainerAllocationExpirer is started.
2013-08-10 05:13:24,113 INFO org.apache.hadoop.yarn.service.AbstractService: Service:AMLivelinessMonitor is started.
2013-08-10 05:13:24,114 INFO org.apache.hadoop.yarn.service.AbstractService: Service:AMLivelinessMonitor is started.
2013-08-10 05:13:24,114 INFO org.apache.hadoop.yarn.service.AbstractService: Service:org.apache.hadoop.yarn.server.resourcemanager.security.DelegationTokenRenewer is started.
2013-08-10 05:13:24,114 INFO org.apache.hadoop.yarn.service.AbstractService: Service:org.apache.hadoop.yarn.server.resourcemanager.NodesListManager is started.
2013-08-10 05:13:24,115 INFO org.apache.hadoop.yarn.service.AbstractService: Service:org.apache.hadoop.yarn.server.resourcemanager.ResourceManager$SchedulerEventDispatcher is started.
2013-08-10 05:13:24,115 INFO org.apache.hadoop.yarn.service.AbstractService: Service:NMLivelinessMonitor is started.
2013-08-10 05:13:24,115 INFO org.apache.hadoop.yarn.service.AbstractService: Service:org.apache.hadoop.yarn.server.resourcemanager.ResourceTrackerService is started.
2013-08-10 05:13:24,150 INFO org.apache.hadoop.ipc.Server: Starting Socket Reader #1 for port 54110
2013-08-10 05:13:24,169 INFO org.apache.hadoop.yarn.factories.impl.pb.RpcServerFactoryPBImpl: Adding protocol org.apache.hadoop.yarn.server.api.ResourceTrackerPB to the server
2013-08-10 05:13:24,170 INFO org.apache.hadoop.ipc.Server: IPC Server Responder: starting
2013-08-10 05:13:24,170 INFO org.apache.hadoop.ipc.Server: IPC Server listener on 54110: starting
2013-08-10 05:13:24,246 INFO org.apache.hadoop.ipc.Server: Starting Socket Reader #1 for port 54112
2013-08-10 05:13:24,253 INFO org.apache.hadoop.yarn.factories.impl.pb.RpcServerFactoryPBImpl: Adding protocol org.apache.hadoop.yarn.api.AMRMProtocolPB to the server
2013-08-10 05:13:24,254 INFO org.apache.hadoop.ipc.Server: IPC Server Responder: starting
2013-08-10 05:13:24,254 INFO org.apache.hadoop.ipc.Server: IPC Server listener on 54112: starting
2013-08-10 05:13:24,270 INFO org.apache.hadoop.yarn.service.AbstractService: Service:org.apache.hadoop.yarn.server.resourcemanager.ApplicationMasterService is started.
2013-08-10 05:13:24,298 INFO org.apache.hadoop.ipc.Server: Starting Socket Reader #1 for port 54111
2013-08-10 05:13:24,301 INFO org.apache.hadoop.yarn.factories.impl.pb.RpcServerFactoryPBImpl: Adding protocol org.apache.hadoop.yarn.api.ClientRMProtocolPB to the server
2013-08-10 05:13:24,301 INFO org.apache.hadoop.ipc.Server: IPC Server Responder: starting
2013-08-10 05:13:24,302 INFO org.apache.hadoop.ipc.Server: IPC Server listener on 54111: starting
2013-08-10 05:13:24,319 INFO org.apache.hadoop.yarn.service.AbstractService: Service:org.apache.hadoop.yarn.server.resourcemanager.ClientRMService is started.
2013-08-10 05:13:24,337 INFO org.apache.hadoop.ipc.Server: Starting Socket Reader #1 for port 8033
2013-08-10 05:13:24,340 INFO org.apache.hadoop.yarn.factories.impl.pb.RpcServerFactoryPBImpl: Adding protocol org.apache.hadoop.yarn.api.RMAdminProtocolPB to the server
2013-08-10 05:13:24,341 INFO org.apache.hadoop.ipc.Server: IPC Server Responder: starting
2013-08-10 05:13:24,341 INFO org.apache.hadoop.yarn.service.AbstractService: Service:org.apache.hadoop.yarn.server.resourcemanager.AdminService is started.
2013-08-10 05:13:24,342 INFO org.apache.hadoop.ipc.Server: IPC Server listener on 8033: starting
2013-08-10 05:13:24,342 INFO org.apache.hadoop.yarn.service.AbstractService: Service:org.apache.hadoop.yarn.server.resourcemanager.amlauncher.ApplicationMasterLauncher is started.
2013-08-10 05:13:24,342 INFO org.apache.hadoop.yarn.service.AbstractService: Service:ResourceManager is started.
2013-08-10 05:13:36,352 INFO org.apache.hadoop.yarn.util.RackResolver: Resolved hadoop-221-7 to /default-rack
2013-08-10 05:13:36,355 INFO org.apache.hadoop.yarn.util.RackResolver: Resolved hadoop-221-6 to /default-rack
2013-08-10 05:13:36,362 INFO org.apache.hadoop.yarn.util.RackResolver: Resolved hadoop-221-5 to /default-rack
2013-08-10 05:13:36,366 INFO org.apache.hadoop.yarn.server.resourcemanager.ResourceTrackerService: NodeManager from node hadoop-221-5(cmPort: 42694 httpPort: 8042) registered with capability: <memory:8192, vCores:16>, assigned nodeId hadoop-221-5:42694
2013-08-10 05:13:36,368 INFO org.apache.hadoop.yarn.server.resourcemanager.ResourceTrackerService: NodeManager from node hadoop-221-7(cmPort: 34609 httpPort: 8042) registered with capability: <memory:8192, vCores:16>, assigned nodeId hadoop-221-7:34609
2013-08-10 05:13:36,369 INFO org.apache.hadoop.yarn.server.resourcemanager.ResourceTrackerService: NodeManager from node hadoop-221-6(cmPort: 57712 httpPort: 8042) registered with capability: <memory:8192, vCores:16>, assigned nodeId hadoop-221-6:57712
2013-08-10 05:13:36,369 INFO org.apache.hadoop.yarn.util.RackResolver: Resolved hadoop-221-4 to /default-rack
2013-08-10 05:13:36,369 INFO org.apache.hadoop.yarn.server.resourcemanager.ResourceTrackerService: NodeManager from node hadoop-221-4(cmPort: 41177 httpPort: 8042) registered with capability: <memory:8192, vCores:16>, assigned nodeId hadoop-221-4:41177
2013-08-10 05:13:36,372 INFO org.apache.hadoop.yarn.util.RackResolver: Resolved hadoop-221-3 to /default-rack
2013-08-10 05:13:36,372 INFO org.apache.hadoop.yarn.server.resourcemanager.ResourceTrackerService: NodeManager from node hadoop-221-3(cmPort: 43958 httpPort: 8042) registered with capability: <memory:8192, vCores:16>, assigned nodeId hadoop-221-3:43958
2013-08-10 05:13:36,384 INFO org.apache.hadoop.yarn.server.resourcemanager.rmnode.RMNodeImpl: hadoop-221-5:42694 Node Transitioned from NEW to RUNNING
2013-08-10 05:13:36,384 INFO org.apache.hadoop.yarn.server.resourcemanager.rmnode.RMNodeImpl: hadoop-221-7:34609 Node Transitioned from NEW to RUNNING
2013-08-10 05:13:36,384 INFO org.apache.hadoop.yarn.server.resourcemanager.rmnode.RMNodeImpl: hadoop-221-6:57712 Node Transitioned from NEW to RUNNING
2013-08-10 05:13:36,384 INFO org.apache.hadoop.yarn.server.resourcemanager.rmnode.RMNodeImpl: hadoop-221-4:41177 Node Transitioned from NEW to RUNNING
2013-08-10 05:13:36,385 INFO org.apache.hadoop.yarn.server.resourcemanager.rmnode.RMNodeImpl: hadoop-221-3:43958 Node Transitioned from NEW to RUNNING
2013-08-10 05:13:36,387 INFO org.apache.hadoop.yarn.server.resourcemanager.scheduler.capacity.CapacityScheduler: Added node hadoop-221-5:42694 clusterResource: <memory:8192, vCores:16>
2013-08-10 05:13:36,388 INFO org.apache.hadoop.yarn.server.resourcemanager.scheduler.capacity.CapacityScheduler: Added node hadoop-221-7:34609 clusterResource: <memory:16384, vCores:32>
2013-08-10 05:13:36,388 INFO org.apache.hadoop.yarn.server.resourcemanager.scheduler.capacity.CapacityScheduler: Added node hadoop-221-6:57712 clusterResource: <memory:24576, vCores:48>
2013-08-10 05:13:36,388 INFO org.apache.hadoop.yarn.server.resourcemanager.scheduler.capacity.CapacityScheduler: Added node hadoop-221-4:41177 clusterResource: <memory:32768, vCores:64>
2013-08-10 05:13:36,388 INFO org.apache.hadoop.yarn.server.resourcemanager.scheduler.capacity.CapacityScheduler: Added node hadoop-221-3:43958 clusterResource: <memory:40960, vCores:80>
2013-08-10 05:13:36,423 INFO org.apache.hadoop.yarn.util.RackResolver: Resolved hadoop-221-2 to /default-rack
2013-08-10 05:13:36,423 INFO org.apache.hadoop.yarn.server.resourcemanager.ResourceTrackerService: NodeManager from node hadoop-221-2(cmPort: 55267 httpPort: 8042) registered with capability: <memory:8192, vCores:16>, assigned nodeId hadoop-221-2:55267
2013-08-10 05:13:36,424 INFO org.apache.hadoop.yarn.server.resourcemanager.rmnode.RMNodeImpl: hadoop-221-2:55267 Node Transitioned from NEW to RUNNING
2013-08-10 05:13:36,427 INFO org.apache.hadoop.yarn.server.resourcemanager.scheduler.capacity.CapacityScheduler: Added node hadoop-221-2:55267 clusterResource: <memory:49152, vCores:96>
2013-08-10 05:13:43,578 INFO org.apache.hadoop.yarn.server.resourcemanager.ClientRMService: Allocated new applicationId: 1
2013-08-10 05:13:47,110 INFO org.apache.hadoop.yarn.server.resourcemanager.ClientRMService: Storing Application with id application_1376111601621_0001
2013-08-10 05:13:47,115 INFO org.apache.hadoop.yarn.server.resourcemanager.recovery.RMStateStore: Storing info for app: application_1376111601621_0001
2013-08-10 05:13:47,115 INFO org.apache.hadoop.yarn.server.resourcemanager.ClientRMService: Application with id 1 submitted by user ubuntu
2013-08-10 05:13:47,119 INFO org.apache.hadoop.yarn.server.resourcemanager.RMAuditLogger: USER=ubuntu	IP=192.168.100.36	OPERATION=Submit Application Request	TARGET=ClientRMService	RESULT=SUCCESS	APPID=application_1376111601621_0001
2013-08-10 05:13:47,169 INFO org.apache.hadoop.yarn.server.resourcemanager.rmapp.RMAppImpl: application_1376111601621_0001 State change from NEW to SUBMITTED
2013-08-10 05:13:47,170 INFO org.apache.hadoop.yarn.server.resourcemanager.ApplicationMasterService: Registering appattempt_1376111601621_0001_000001
2013-08-10 05:13:47,172 INFO org.apache.hadoop.yarn.server.resourcemanager.rmapp.attempt.RMAppAttemptImpl: appattempt_1376111601621_0001_000001 State change from NEW to SUBMITTED
2013-08-10 05:13:47,207 INFO org.apache.hadoop.yarn.server.resourcemanager.scheduler.capacity.LeafQueue: Application application_1376111601621_0001 from user: ubuntu activated in queue: default
2013-08-10 05:13:47,207 INFO org.apache.hadoop.yarn.server.resourcemanager.scheduler.capacity.LeafQueue: Application added - appId: application_1376111601621_0001 user: org.apache.hadoop.yarn.server.resourcemanager.scheduler.capacity.LeafQueue$User@4febd0d, leaf-queue: default #user-pending-applications: 0 #user-active-applications: 1 #queue-pending-applications: 0 #queue-active-applications: 1
2013-08-10 05:13:47,208 INFO org.apache.hadoop.yarn.server.resourcemanager.scheduler.capacity.ParentQueue: Application added - appId: application_1376111601621_0001 user: ubuntu leaf-queue of parent: root #applications: 1
2013-08-10 05:13:47,208 INFO org.apache.hadoop.yarn.server.resourcemanager.scheduler.capacity.CapacityScheduler: Application Submission: appattempt_1376111601621_0001_000001, user: ubuntu queue: default: capacity=1.0, absoluteCapacity=1.0, usedResources=<memory:0, vCores:0>usedCapacity=0.0, absoluteUsedCapacity=0.0, numApps=1, numContainers=0, currently active: 1
2013-08-10 05:13:47,214 INFO org.apache.hadoop.yarn.server.resourcemanager.rmapp.attempt.RMAppAttemptImpl: appattempt_1376111601621_0001_000001 State change from SUBMITTED to SCHEDULED
2013-08-10 05:13:47,215 INFO org.apache.hadoop.yarn.server.resourcemanager.rmapp.RMAppImpl: application_1376111601621_0001 State change from SUBMITTED to ACCEPTED
2013-08-10 05:13:47,582 INFO org.apache.hadoop.yarn.server.resourcemanager.rmcontainer.RMContainerImpl: container_1376111601621_0001_01_000001 Container Transitioned from NEW to ALLOCATED
2013-08-10 05:13:47,582 INFO org.apache.hadoop.yarn.server.resourcemanager.RMAuditLogger: USER=ubuntu	OPERATION=AM Allocated Container	TARGET=SchedulerApp	RESULT=SUCCESS	APPID=application_1376111601621_0001	CONTAINERID=container_1376111601621_0001_01_000001
2013-08-10 05:13:47,583 INFO org.apache.hadoop.yarn.server.resourcemanager.scheduler.common.fica.FiCaSchedulerNode: Assigned container container_1376111601621_0001_01_000001 of capacity <memory:2048, vCores:1> on host hadoop-221-6:57712, which currently has 1 containers, <memory:2048, vCores:1> used and <memory:6144, vCores:15> available
2013-08-10 05:13:47,590 INFO org.apache.hadoop.yarn.server.resourcemanager.scheduler.capacity.LeafQueue: assignedContainer application=application_1376111601621_0001 container=Container: [ContainerId: container_1376111601621_0001_01_000001, NodeId: hadoop-221-6:57712, NodeHttpAddress: hadoop-221-6:8042, Resource: <memory:2048, vCores:1>, Priority: 0, State: NEW, Token: null, Status: container_id {, app_attempt_id {, application_id {, id: 1, cluster_timestamp: 1376111601621, }, attemptId: 1, }, id: 1, }, state: C_NEW, ] containerId=container_1376111601621_0001_01_000001 queue=default: capacity=1.0, absoluteCapacity=1.0, usedResources=<memory:0, vCores:0>usedCapacity=0.0, absoluteUsedCapacity=0.0, numApps=1, numContainers=0 usedCapacity=0.0 absoluteUsedCapacity=0.0 used=<memory:0, vCores:0> cluster=<memory:49152, vCores:96>
2013-08-10 05:13:47,596 INFO org.apache.hadoop.yarn.server.resourcemanager.scheduler.capacity.ParentQueue: Re-sorting queues since queue: root.default stats: default: capacity=1.0, absoluteCapacity=1.0, usedResources=<memory:2048, vCores:1>usedCapacity=0.041666668, absoluteUsedCapacity=0.041666668, numApps=1, numContainers=1
2013-08-10 05:13:47,599 INFO org.apache.hadoop.yarn.server.resourcemanager.scheduler.capacity.ParentQueue: assignedContainer queue=root usedCapacity=0.041666668 absoluteUsedCapacity=0.041666668 used=<memory:2048, vCores:1> cluster=<memory:49152, vCores:96>
2013-08-10 05:13:47,598 INFO org.apache.hadoop.yarn.server.resourcemanager.rmcontainer.RMContainerImpl: container_1376111601621_0001_01_000001 Container Transitioned from ALLOCATED to ACQUIRED
2013-08-10 05:13:47,601 INFO org.apache.hadoop.yarn.server.resourcemanager.rmapp.attempt.RMAppAttemptImpl: Storing attempt: AppId: application_1376111601621_0001 AttemptId: appattempt_1376111601621_0001_000001 MasterContainer: Container: [ContainerId: container_1376111601621_0001_01_000001, NodeId: hadoop-221-6:57712, NodeHttpAddress: hadoop-221-6:8042, Resource: <memory:2048, vCores:1>, Priority: 0, State: NEW, Token: null, Status: container_id {, app_attempt_id {, application_id {, id: 1, cluster_timestamp: 1376111601621, }, attemptId: 1, }, id: 1, }, state: C_NEW, ]
2013-08-10 05:13:47,605 INFO org.apache.hadoop.yarn.server.resourcemanager.rmapp.attempt.RMAppAttemptImpl: appattempt_1376111601621_0001_000001 State change from SCHEDULED to ALLOCATED_SAVING
2013-08-10 05:13:47,609 INFO org.apache.hadoop.yarn.server.resourcemanager.recovery.RMStateStore: Storing info for attempt: appattempt_1376111601621_0001_000001
2013-08-10 05:13:47,612 INFO org.apache.hadoop.yarn.server.resourcemanager.rmapp.attempt.RMAppAttemptImpl: appattempt_1376111601621_0001_000001 State change from ALLOCATED_SAVING to ALLOCATED
2013-08-10 05:13:47,620 INFO org.apache.hadoop.yarn.server.resourcemanager.amlauncher.AMLauncher: Launching masterappattempt_1376111601621_0001_000001
2013-08-10 05:13:47,660 INFO org.apache.hadoop.yarn.server.resourcemanager.amlauncher.AMLauncher: Setting up container Container: [ContainerId: container_1376111601621_0001_01_000001, NodeId: hadoop-221-6:57712, NodeHttpAddress: hadoop-221-6:8042, Resource: <memory:2048, vCores:1>, Priority: 0, State: NEW, Token: null, Status: container_id {, app_attempt_id {, application_id {, id: 1, cluster_timestamp: 1376111601621, }, attemptId: 1, }, id: 1, }, state: C_NEW, ] for AM appattempt_1376111601621_0001_000001
2013-08-10 05:13:47,660 INFO org.apache.hadoop.yarn.server.resourcemanager.amlauncher.AMLauncher: Command to launch container container_1376111601621_0001_01_000001 : $JAVA_HOME/bin/java -Dlog4j.configuration=container-log4j.properties -Dyarn.app.mapreduce.container.log.dir=<LOG_DIR> -Dyarn.app.mapreduce.container.log.filesize=0 -Dhadoop.root.logger=INFO,CLA  -Xmx1024m org.apache.hadoop.mapreduce.v2.app.MRAppMaster 1><LOG_DIR>/stdout 2><LOG_DIR>/stderr 
2013-08-10 05:13:48,572 INFO org.apache.hadoop.yarn.server.resourcemanager.amlauncher.AMLauncher: Done launching container Container: [ContainerId: container_1376111601621_0001_01_000001, NodeId: hadoop-221-6:57712, NodeHttpAddress: hadoop-221-6:8042, Resource: <memory:2048, vCores:1>, Priority: 0, State: NEW, Token: null, Status: container_id {, app_attempt_id {, application_id {, id: 1, cluster_timestamp: 1376111601621, }, attemptId: 1, }, id: 1, }, state: C_NEW, ] for AM appattempt_1376111601621_0001_000001
2013-08-10 05:13:48,573 INFO org.apache.hadoop.yarn.server.resourcemanager.rmapp.attempt.RMAppAttemptImpl: appattempt_1376111601621_0001_000001 State change from ALLOCATED to LAUNCHED
2013-08-10 05:13:48,581 INFO org.apache.hadoop.yarn.server.resourcemanager.rmcontainer.RMContainerImpl: container_1376111601621_0001_01_000001 Container Transitioned from ACQUIRED to RUNNING
2013-08-10 05:13:57,107 INFO org.apache.hadoop.yarn.server.resourcemanager.ApplicationMasterService: AM registration appattempt_1376111601621_0001_000001
2013-08-10 05:13:57,108 INFO org.apache.hadoop.yarn.server.resourcemanager.RMAuditLogger: USER=ubuntu	IP=192.168.100.40	OPERATION=Register App Master	TARGET=ApplicationMasterService	RESULT=SUCCESS	APPID=application_1376111601621_0001	APPATTEMPTID=appattempt_1376111601621_0001_000001
2013-08-10 05:13:57,113 INFO org.apache.hadoop.yarn.server.resourcemanager.rmapp.attempt.RMAppAttemptImpl: appattempt_1376111601621_0001_000001 State change from LAUNCHED to RUNNING
2013-08-10 05:13:57,113 INFO org.apache.hadoop.yarn.server.resourcemanager.rmapp.RMAppImpl: application_1376111601621_0001 State change from ACCEPTED to RUNNING
2013-08-10 05:13:58,594 INFO org.apache.hadoop.yarn.server.resourcemanager.rmcontainer.RMContainerImpl: container_1376111601621_0001_01_000002 Container Transitioned from NEW to ALLOCATED
2013-08-10 05:13:58,594 INFO org.apache.hadoop.yarn.server.resourcemanager.RMAuditLogger: USER=ubuntu	OPERATION=AM Allocated Container	TARGET=SchedulerApp	RESULT=SUCCESS	APPID=application_1376111601621_0001	CONTAINERID=container_1376111601621_0001_01_000002
2013-08-10 05:13:58,594 INFO org.apache.hadoop.yarn.server.resourcemanager.scheduler.common.fica.FiCaSchedulerNode: Assigned container container_1376111601621_0001_01_000002 of capacity <memory:1024, vCores:1> on host hadoop-221-7:34609, which currently has 1 containers, <memory:1024, vCores:1> used and <memory:7168, vCores:15> available
2013-08-10 05:13:58,596 INFO org.apache.hadoop.yarn.server.resourcemanager.scheduler.capacity.LeafQueue: assignedContainer application=application_1376111601621_0001 container=Container: [ContainerId: container_1376111601621_0001_01_000002, NodeId: hadoop-221-7:34609, NodeHttpAddress: hadoop-221-7:8042, Resource: <memory:1024, vCores:1>, Priority: 20, State: NEW, Token: null, Status: container_id {, app_attempt_id {, application_id {, id: 1, cluster_timestamp: 1376111601621, }, attemptId: 1, }, id: 2, }, state: C_NEW, ] containerId=container_1376111601621_0001_01_000002 queue=default: capacity=1.0, absoluteCapacity=1.0, usedResources=<memory:2048, vCores:1>usedCapacity=0.041666668, absoluteUsedCapacity=0.041666668, numApps=1, numContainers=1 usedCapacity=0.041666668 absoluteUsedCapacity=0.041666668 used=<memory:2048, vCores:1> cluster=<memory:49152, vCores:96>
2013-08-10 05:13:58,597 INFO org.apache.hadoop.yarn.server.resourcemanager.scheduler.capacity.ParentQueue: Re-sorting queues since queue: root.default stats: default: capacity=1.0, absoluteCapacity=1.0, usedResources=<memory:3072, vCores:2>usedCapacity=0.0625, absoluteUsedCapacity=0.0625, numApps=1, numContainers=2
2013-08-10 05:13:58,597 INFO org.apache.hadoop.yarn.server.resourcemanager.scheduler.capacity.ParentQueue: assignedContainer queue=root usedCapacity=0.0625 absoluteUsedCapacity=0.0625 used=<memory:3072, vCores:2> cluster=<memory:49152, vCores:96>
2013-08-10 05:13:58,598 INFO org.apache.hadoop.yarn.server.resourcemanager.rmcontainer.RMContainerImpl: container_1376111601621_0001_01_000003 Container Transitioned from NEW to ALLOCATED
2013-08-10 05:13:58,598 INFO org.apache.hadoop.yarn.server.resourcemanager.RMAuditLogger: USER=ubuntu	OPERATION=AM Allocated Container	TARGET=SchedulerApp	RESULT=SUCCESS	APPID=application_1376111601621_0001	CONTAINERID=container_1376111601621_0001_01_000003
2013-08-10 05:13:58,598 INFO org.apache.hadoop.yarn.server.resourcemanager.scheduler.common.fica.FiCaSchedulerNode: Assigned container container_1376111601621_0001_01_000003 of capacity <memory:1024, vCores:1> on host hadoop-221-4:41177, which currently has 1 containers, <memory:1024, vCores:1> used and <memory:7168, vCores:15> available
2013-08-10 05:13:58,600 INFO org.apache.hadoop.yarn.server.resourcemanager.scheduler.capacity.LeafQueue: assignedContainer application=application_1376111601621_0001 container=Container: [ContainerId: container_1376111601621_0001_01_000003, NodeId: hadoop-221-4:41177, NodeHttpAddress: hadoop-221-4:8042, Resource: <memory:1024, vCores:1>, Priority: 20, State: NEW, Token: null, Status: container_id {, app_attempt_id {, application_id {, id: 1, cluster_timestamp: 1376111601621, }, attemptId: 1, }, id: 3, }, state: C_NEW, ] containerId=container_1376111601621_0001_01_000003 queue=default: capacity=1.0, absoluteCapacity=1.0, usedResources=<memory:3072, vCores:2>usedCapacity=0.0625, absoluteUsedCapacity=0.0625, numApps=1, numContainers=2 usedCapacity=0.0625 absoluteUsedCapacity=0.0625 used=<memory:3072, vCores:2> cluster=<memory:49152, vCores:96>
2013-08-10 05:13:58,600 INFO org.apache.hadoop.yarn.server.resourcemanager.scheduler.capacity.ParentQueue: Re-sorting queues since queue: root.default stats: default: capacity=1.0, absoluteCapacity=1.0, usedResources=<memory:4096, vCores:3>usedCapacity=0.083333336, absoluteUsedCapacity=0.083333336, numApps=1, numContainers=3
2013-08-10 05:13:58,600 INFO org.apache.hadoop.yarn.server.resourcemanager.scheduler.capacity.ParentQueue: assignedContainer queue=root usedCapacity=0.083333336 absoluteUsedCapacity=0.083333336 used=<memory:4096, vCores:3> cluster=<memory:49152, vCores:96>
2013-08-10 05:13:59,183 INFO org.apache.hadoop.yarn.server.resourcemanager.rmcontainer.RMContainerImpl: container_1376111601621_0001_01_000002 Container Transitioned from ALLOCATED to ACQUIRED
2013-08-10 05:13:59,185 INFO org.apache.hadoop.yarn.server.resourcemanager.rmcontainer.RMContainerImpl: container_1376111601621_0001_01_000003 Container Transitioned from ALLOCATED to ACQUIRED
2013-08-10 05:14:00,215 INFO org.apache.hadoop.yarn.server.resourcemanager.scheduler.AppSchedulingInfo: checking for deactivate... 
2013-08-10 05:14:00,678 INFO org.apache.hadoop.yarn.server.resourcemanager.rmcontainer.RMContainerImpl: container_1376111601621_0001_01_000002 Container Transitioned from ACQUIRED to RUNNING
2013-08-10 05:14:00,708 INFO org.apache.hadoop.yarn.server.resourcemanager.rmcontainer.RMContainerImpl: container_1376111601621_0001_01_000003 Container Transitioned from ACQUIRED to RUNNING
2013-08-10 05:16:56,467 INFO org.apache.hadoop.yarn.server.resourcemanager.rmcontainer.RMContainerImpl: container_1376111601621_0001_01_000003 Container Transitioned from RUNNING to COMPLETED
2013-08-10 05:16:56,467 INFO org.apache.hadoop.yarn.server.resourcemanager.scheduler.common.fica.FiCaSchedulerApp: Completed container: container_1376111601621_0001_01_000003 in state: COMPLETED event:FINISHED
2013-08-10 05:16:56,468 INFO org.apache.hadoop.yarn.server.resourcemanager.RMAuditLogger: USER=ubuntu	OPERATION=AM Released Container	TARGET=SchedulerApp	RESULT=SUCCESS	APPID=application_1376111601621_0001	CONTAINERID=container_1376111601621_0001_01_000003
2013-08-10 05:16:56,468 INFO org.apache.hadoop.yarn.server.resourcemanager.scheduler.common.fica.FiCaSchedulerNode: Released container container_1376111601621_0001_01_000003 of capacity <memory:1024, vCores:1> on host hadoop-221-4:41177, which currently has 0 containers, <memory:0, vCores:0> used and <memory:8192, vCores:16> available, release resources=true
2013-08-10 05:16:56,468 INFO org.apache.hadoop.yarn.server.resourcemanager.scheduler.capacity.LeafQueue: default used=<memory:3072, vCores:2> numContainers=2 user=ubuntu user-resources=<memory:3072, vCores:2>
2013-08-10 05:16:56,471 INFO org.apache.hadoop.yarn.server.resourcemanager.scheduler.capacity.LeafQueue: completedContainer container=Container: [ContainerId: container_1376111601621_0001_01_000003, NodeId: hadoop-221-4:41177, NodeHttpAddress: hadoop-221-4:8042, Resource: <memory:1024, vCores:1>, Priority: 20, State: NEW, Token: null, Status: container_id {, app_attempt_id {, application_id {, id: 1, cluster_timestamp: 1376111601621, }, attemptId: 1, }, id: 3, }, state: C_COMPLETE, diagnostics: "Container killed by the ApplicationMaster.\n\n", exit_status: 143, ] resource=<memory:1024, vCores:1> queue=default: capacity=1.0, absoluteCapacity=1.0, usedResources=<memory:3072, vCores:2>usedCapacity=0.0625, absoluteUsedCapacity=0.0625, numApps=1, numContainers=2 usedCapacity=0.0625 absoluteUsedCapacity=0.0625 used=<memory:3072, vCores:2> cluster=<memory:49152, vCores:96>
2013-08-10 05:16:56,471 INFO org.apache.hadoop.yarn.server.resourcemanager.scheduler.capacity.ParentQueue: completedContainer queue=root usedCapacity=0.0625 absoluteUsedCapacity=0.0625 used=<memory:3072, vCores:2> cluster=<memory:49152, vCores:96>
2013-08-10 05:16:56,471 INFO org.apache.hadoop.yarn.server.resourcemanager.scheduler.capacity.CapacityScheduler: Application appattempt_1376111601621_0001_000001 released container container_1376111601621_0001_01_000003 on node: host: hadoop-221-4:41177 #containers=0 available=8192 used=0 with event: FINISHED
2013-08-10 05:17:00,161 INFO org.apache.hadoop.yarn.server.resourcemanager.rmcontainer.RMContainerImpl: container_1376111601621_0001_01_000002 Container Transitioned from RUNNING to COMPLETED
2013-08-10 05:17:00,161 INFO org.apache.hadoop.yarn.server.resourcemanager.scheduler.common.fica.FiCaSchedulerApp: Completed container: container_1376111601621_0001_01_000002 in state: COMPLETED event:FINISHED
2013-08-10 05:17:00,161 INFO org.apache.hadoop.yarn.server.resourcemanager.RMAuditLogger: USER=ubuntu	OPERATION=AM Released Container	TARGET=SchedulerApp	RESULT=SUCCESS	APPID=application_1376111601621_0001	CONTAINERID=container_1376111601621_0001_01_000002
2013-08-10 05:17:00,161 INFO org.apache.hadoop.yarn.server.resourcemanager.scheduler.common.fica.FiCaSchedulerNode: Released container container_1376111601621_0001_01_000002 of capacity <memory:1024, vCores:1> on host hadoop-221-7:34609, which currently has 0 containers, <memory:0, vCores:0> used and <memory:8192, vCores:16> available, release resources=true
2013-08-10 05:17:00,161 INFO org.apache.hadoop.yarn.server.resourcemanager.scheduler.capacity.LeafQueue: default used=<memory:2048, vCores:1> numContainers=1 user=ubuntu user-resources=<memory:2048, vCores:1>
2013-08-10 05:17:00,163 INFO org.apache.hadoop.yarn.server.resourcemanager.scheduler.capacity.LeafQueue: completedContainer container=Container: [ContainerId: container_1376111601621_0001_01_000002, NodeId: hadoop-221-7:34609, NodeHttpAddress: hadoop-221-7:8042, Resource: <memory:1024, vCores:1>, Priority: 20, State: NEW, Token: null, Status: container_id {, app_attempt_id {, application_id {, id: 1, cluster_timestamp: 1376111601621, }, attemptId: 1, }, id: 2, }, state: C_COMPLETE, diagnostics: "Container killed by the ApplicationMaster.\n\n", exit_status: 143, ] resource=<memory:1024, vCores:1> queue=default: capacity=1.0, absoluteCapacity=1.0, usedResources=<memory:2048, vCores:1>usedCapacity=0.041666668, absoluteUsedCapacity=0.041666668, numApps=1, numContainers=1 usedCapacity=0.041666668 absoluteUsedCapacity=0.041666668 used=<memory:2048, vCores:1> cluster=<memory:49152, vCores:96>
2013-08-10 05:17:00,164 INFO org.apache.hadoop.yarn.server.resourcemanager.scheduler.capacity.ParentQueue: completedContainer queue=root usedCapacity=0.041666668 absoluteUsedCapacity=0.041666668 used=<memory:2048, vCores:1> cluster=<memory:49152, vCores:96>
2013-08-10 05:17:00,164 INFO org.apache.hadoop.yarn.server.resourcemanager.scheduler.capacity.CapacityScheduler: Application appattempt_1376111601621_0001_000001 released container container_1376111601621_0001_01_000002 on node: host: hadoop-221-7:34609 #containers=0 available=8192 used=0 with event: FINISHED
2013-08-10 05:17:04,354 INFO org.apache.hadoop.yarn.server.resourcemanager.rmapp.attempt.RMAppAttemptImpl: appattempt_1376111601621_0001_000001 State change from RUNNING to FINISHING
2013-08-10 05:17:04,355 INFO org.apache.hadoop.yarn.server.resourcemanager.rmapp.RMAppImpl: application_1376111601621_0001 State change from RUNNING to FINISHING
2013-08-10 05:17:04,858 INFO org.apache.hadoop.yarn.server.resourcemanager.rmcontainer.RMContainerImpl: container_1376111601621_0001_01_000001 Container Transitioned from RUNNING to COMPLETED
2013-08-10 05:17:04,858 INFO org.apache.hadoop.yarn.server.resourcemanager.scheduler.common.fica.FiCaSchedulerApp: Completed container: container_1376111601621_0001_01_000001 in state: COMPLETED event:FINISHED
2013-08-10 05:17:04,858 INFO org.apache.hadoop.yarn.server.resourcemanager.RMAuditLogger: USER=ubuntu	OPERATION=AM Released Container	TARGET=SchedulerApp	RESULT=SUCCESS	APPID=application_1376111601621_0001	CONTAINERID=container_1376111601621_0001_01_000001
2013-08-10 05:17:04,858 INFO org.apache.hadoop.yarn.server.resourcemanager.scheduler.common.fica.FiCaSchedulerNode: Released container container_1376111601621_0001_01_000001 of capacity <memory:2048, vCores:1> on host hadoop-221-6:57712, which currently has 0 containers, <memory:0, vCores:0> used and <memory:8192, vCores:16> available, release resources=true
2013-08-10 05:17:04,859 INFO org.apache.hadoop.yarn.server.resourcemanager.scheduler.capacity.LeafQueue: default used=<memory:0, vCores:0> numContainers=0 user=ubuntu user-resources=<memory:0, vCores:0>
2013-08-10 05:17:04,860 INFO org.apache.hadoop.yarn.server.resourcemanager.scheduler.capacity.LeafQueue: completedContainer container=Container: [ContainerId: container_1376111601621_0001_01_000001, NodeId: hadoop-221-6:57712, NodeHttpAddress: hadoop-221-6:8042, Resource: <memory:2048, vCores:1>, Priority: 0, State: NEW, Token: null, Status: container_id {, app_attempt_id {, application_id {, id: 1, cluster_timestamp: 1376111601621, }, attemptId: 1, }, id: 1, }, state: C_COMPLETE, diagnostics: "", exit_status: 0, ] resource=<memory:2048, vCores:1> queue=default: capacity=1.0, absoluteCapacity=1.0, usedResources=<memory:0, vCores:0>usedCapacity=0.0, absoluteUsedCapacity=0.0, numApps=1, numContainers=0 usedCapacity=0.0 absoluteUsedCapacity=0.0 used=<memory:0, vCores:0> cluster=<memory:49152, vCores:96>
2013-08-10 05:17:04,860 INFO org.apache.hadoop.yarn.server.resourcemanager.scheduler.capacity.ParentQueue: completedContainer queue=root usedCapacity=0.0 absoluteUsedCapacity=0.0 used=<memory:0, vCores:0> cluster=<memory:49152, vCores:96>
2013-08-10 05:17:04,860 INFO org.apache.hadoop.yarn.server.resourcemanager.scheduler.capacity.CapacityScheduler: Application appattempt_1376111601621_0001_000001 released container container_1376111601621_0001_01_000001 on node: host: hadoop-221-6:57712 #containers=0 available=8192 used=0 with event: FINISHED
2013-08-10 05:17:04,861 INFO org.apache.hadoop.yarn.server.resourcemanager.rmapp.attempt.RMAppAttemptImpl: appattempt_1376111601621_0001_000001 State change from FINISHING to FINISHED
2013-08-10 05:17:04,863 INFO org.apache.hadoop.yarn.server.resourcemanager.rmapp.RMAppImpl: application_1376111601621_0001 State change from FINISHING to FINISHED
2013-08-10 05:17:04,864 INFO org.apache.hadoop.yarn.server.resourcemanager.scheduler.capacity.CapacityScheduler: Application appattempt_1376111601621_0001_000001 is done. finalState=FINISHED
2013-08-10 05:17:04,864 INFO org.apache.hadoop.yarn.server.resourcemanager.RMAuditLogger: USER=ubuntu	OPERATION=Application Finished - Succeeded	TARGET=RMAppManager	RESULT=SUCCESS	APPID=application_1376111601621_0001
2013-08-10 05:17:04,865 INFO org.apache.hadoop.yarn.server.resourcemanager.amlauncher.AMLauncher: Cleaning master appattempt_1376111601621_0001_000001
2013-08-10 05:17:04,866 INFO org.apache.hadoop.yarn.server.resourcemanager.scheduler.AppSchedulingInfo: Application application_1376111601621_0001 requests cleared
2013-08-10 05:17:04,876 INFO org.apache.hadoop.yarn.server.resourcemanager.scheduler.capacity.LeafQueue: Application removed - appId: application_1376111601621_0001 user: ubuntu queue: default #user-pending-applications: 0 #user-active-applications: 0 #queue-pending-applications: 0 #queue-active-applications: 0
2013-08-10 05:17:04,876 INFO org.apache.hadoop.yarn.server.resourcemanager.scheduler.capacity.ParentQueue: Application removed - appId: application_1376111601621_0001 user: ubuntu leaf-queue of parent: root #applications: 0
2013-08-10 05:17:04,878 INFO org.apache.hadoop.yarn.server.resourcemanager.recovery.RMStateStore: Removing info for app: application_1376111601621_0001
2013-08-10 05:17:04,881 INFO org.apache.hadoop.yarn.server.resourcemanager.RMAppManager$ApplicationSummary: appId=application_1376111601621_0001,name=TeraGen,user=ubuntu,queue=default,state=FINISHED,trackingUrl=hadoop-221-1.novalocal:8088/proxy/application_1376111601621_0001/jobhistory/job/job_1376111601621_0001,appMasterHost=hadoop-221-6,startTime=1376111627103,finishTime=1376111824355
2013-08-10 05:17:05,783 INFO org.apache.hadoop.yarn.server.resourcemanager.ClientRMService: Allocated new applicationId: 2
2013-08-10 05:17:07,712 INFO org.apache.hadoop.yarn.server.resourcemanager.ClientRMService: Storing Application with id application_1376111601621_0002
2013-08-10 05:17:07,712 INFO org.apache.hadoop.yarn.server.resourcemanager.recovery.RMStateStore: Storing info for app: application_1376111601621_0002
2013-08-10 05:17:07,712 INFO org.apache.hadoop.yarn.server.resourcemanager.ClientRMService: Application with id 2 submitted by user ubuntu
2013-08-10 05:17:07,712 INFO org.apache.hadoop.yarn.server.resourcemanager.RMAuditLogger: USER=ubuntu	IP=192.168.100.36	OPERATION=Submit Application Request	TARGET=ClientRMService	RESULT=SUCCESS	APPID=application_1376111601621_0002
2013-08-10 05:17:07,715 INFO org.apache.hadoop.yarn.server.resourcemanager.rmapp.RMAppImpl: application_1376111601621_0002 State change from NEW to SUBMITTED
2013-08-10 05:17:07,715 INFO org.apache.hadoop.yarn.server.resourcemanager.ApplicationMasterService: Registering appattempt_1376111601621_0002_000001
2013-08-10 05:17:07,715 INFO org.apache.hadoop.yarn.server.resourcemanager.rmapp.attempt.RMAppAttemptImpl: appattempt_1376111601621_0002_000001 State change from NEW to SUBMITTED
2013-08-10 05:17:07,716 INFO org.apache.hadoop.yarn.server.resourcemanager.scheduler.capacity.LeafQueue: Application application_1376111601621_0002 from user: ubuntu activated in queue: default
2013-08-10 05:17:07,716 INFO org.apache.hadoop.yarn.server.resourcemanager.scheduler.capacity.LeafQueue: Application added - appId: application_1376111601621_0002 user: org.apache.hadoop.yarn.server.resourcemanager.scheduler.capacity.LeafQueue$User@21c49e79, leaf-queue: default #user-pending-applications: 0 #user-active-applications: 1 #queue-pending-applications: 0 #queue-active-applications: 1
2013-08-10 05:17:07,716 INFO org.apache.hadoop.yarn.server.resourcemanager.scheduler.capacity.ParentQueue: Application added - appId: application_1376111601621_0002 user: ubuntu leaf-queue of parent: root #applications: 1
2013-08-10 05:17:07,716 INFO org.apache.hadoop.yarn.server.resourcemanager.scheduler.capacity.CapacityScheduler: Application Submission: appattempt_1376111601621_0002_000001, user: ubuntu queue: default: capacity=1.0, absoluteCapacity=1.0, usedResources=<memory:0, vCores:0>usedCapacity=0.0, absoluteUsedCapacity=0.0, numApps=1, numContainers=0, currently active: 1
2013-08-10 05:17:07,717 INFO org.apache.hadoop.yarn.server.resourcemanager.rmapp.attempt.RMAppAttemptImpl: appattempt_1376111601621_0002_000001 State change from SUBMITTED to SCHEDULED
2013-08-10 05:17:07,717 INFO org.apache.hadoop.yarn.server.resourcemanager.rmapp.RMAppImpl: application_1376111601621_0002 State change from SUBMITTED to ACCEPTED
2013-08-10 05:17:07,873 INFO org.apache.hadoop.yarn.server.resourcemanager.rmcontainer.RMContainerImpl: container_1376111601621_0002_01_000001 Container Transitioned from NEW to ALLOCATED
2013-08-10 05:17:07,874 INFO org.apache.hadoop.yarn.server.resourcemanager.RMAuditLogger: USER=ubuntu	OPERATION=AM Allocated Container	TARGET=SchedulerApp	RESULT=SUCCESS	APPID=application_1376111601621_0002	CONTAINERID=container_1376111601621_0002_01_000001
2013-08-10 05:17:07,874 INFO org.apache.hadoop.yarn.server.resourcemanager.scheduler.common.fica.FiCaSchedulerNode: Assigned container container_1376111601621_0002_01_000001 of capacity <memory:2048, vCores:1> on host hadoop-221-5:42694, which currently has 1 containers, <memory:2048, vCores:1> used and <memory:6144, vCores:15> available
2013-08-10 05:17:07,875 INFO org.apache.hadoop.yarn.server.resourcemanager.scheduler.capacity.LeafQueue: assignedContainer application=application_1376111601621_0002 container=Container: [ContainerId: container_1376111601621_0002_01_000001, NodeId: hadoop-221-5:42694, NodeHttpAddress: hadoop-221-5:8042, Resource: <memory:2048, vCores:1>, Priority: 0, State: NEW, Token: null, Status: container_id {, app_attempt_id {, application_id {, id: 2, cluster_timestamp: 1376111601621, }, attemptId: 1, }, id: 1, }, state: C_NEW, ] containerId=container_1376111601621_0002_01_000001 queue=default: capacity=1.0, absoluteCapacity=1.0, usedResources=<memory:0, vCores:0>usedCapacity=0.0, absoluteUsedCapacity=0.0, numApps=1, numContainers=0 usedCapacity=0.0 absoluteUsedCapacity=0.0 used=<memory:0, vCores:0> cluster=<memory:49152, vCores:96>
2013-08-10 05:17:07,876 INFO org.apache.hadoop.yarn.server.resourcemanager.scheduler.capacity.ParentQueue: Re-sorting queues since queue: root.default stats: default: capacity=1.0, absoluteCapacity=1.0, usedResources=<memory:2048, vCores:1>usedCapacity=0.041666668, absoluteUsedCapacity=0.041666668, numApps=1, numContainers=1
2013-08-10 05:17:07,877 INFO org.apache.hadoop.yarn.server.resourcemanager.scheduler.capacity.ParentQueue: assignedContainer queue=root usedCapacity=0.041666668 absoluteUsedCapacity=0.041666668 used=<memory:2048, vCores:1> cluster=<memory:49152, vCores:96>
2013-08-10 05:17:07,877 INFO org.apache.hadoop.yarn.server.resourcemanager.rmcontainer.RMContainerImpl: container_1376111601621_0002_01_000001 Container Transitioned from ALLOCATED to ACQUIRED
2013-08-10 05:17:07,879 INFO org.apache.hadoop.yarn.server.resourcemanager.rmapp.attempt.RMAppAttemptImpl: Storing attempt: AppId: application_1376111601621_0002 AttemptId: appattempt_1376111601621_0002_000001 MasterContainer: Container: [ContainerId: container_1376111601621_0002_01_000001, NodeId: hadoop-221-5:42694, NodeHttpAddress: hadoop-221-5:8042, Resource: <memory:2048, vCores:1>, Priority: 0, State: NEW, Token: null, Status: container_id {, app_attempt_id {, application_id {, id: 2, cluster_timestamp: 1376111601621, }, attemptId: 1, }, id: 1, }, state: C_NEW, ]
2013-08-10 05:17:07,879 INFO org.apache.hadoop.yarn.server.resourcemanager.rmapp.attempt.RMAppAttemptImpl: appattempt_1376111601621_0002_000001 State change from SCHEDULED to ALLOCATED_SAVING
2013-08-10 05:17:07,880 INFO org.apache.hadoop.yarn.server.resourcemanager.recovery.RMStateStore: Storing info for attempt: appattempt_1376111601621_0002_000001
2013-08-10 05:17:07,881 INFO org.apache.hadoop.yarn.server.resourcemanager.rmapp.attempt.RMAppAttemptImpl: appattempt_1376111601621_0002_000001 State change from ALLOCATED_SAVING to ALLOCATED
2013-08-10 05:17:07,882 INFO org.apache.hadoop.yarn.server.resourcemanager.amlauncher.AMLauncher: Launching masterappattempt_1376111601621_0002_000001
2013-08-10 05:17:07,885 INFO org.apache.hadoop.yarn.server.resourcemanager.amlauncher.AMLauncher: Setting up container Container: [ContainerId: container_1376111601621_0002_01_000001, NodeId: hadoop-221-5:42694, NodeHttpAddress: hadoop-221-5:8042, Resource: <memory:2048, vCores:1>, Priority: 0, State: NEW, Token: null, Status: container_id {, app_attempt_id {, application_id {, id: 2, cluster_timestamp: 1376111601621, }, attemptId: 1, }, id: 1, }, state: C_NEW, ] for AM appattempt_1376111601621_0002_000001
2013-08-10 05:17:07,885 INFO org.apache.hadoop.yarn.server.resourcemanager.amlauncher.AMLauncher: Command to launch container container_1376111601621_0002_01_000001 : $JAVA_HOME/bin/java -Dlog4j.configuration=container-log4j.properties -Dyarn.app.mapreduce.container.log.dir=<LOG_DIR> -Dyarn.app.mapreduce.container.log.filesize=0 -Dhadoop.root.logger=INFO,CLA  -Xmx1024m org.apache.hadoop.mapreduce.v2.app.MRAppMaster 1><LOG_DIR>/stdout 2><LOG_DIR>/stderr 
2013-08-10 05:17:08,720 INFO org.apache.hadoop.yarn.server.resourcemanager.amlauncher.AMLauncher: Done launching container Container: [ContainerId: container_1376111601621_0002_01_000001, NodeId: hadoop-221-5:42694, NodeHttpAddress: hadoop-221-5:8042, Resource: <memory:2048, vCores:1>, Priority: 0, State: NEW, Token: null, Status: container_id {, app_attempt_id {, application_id {, id: 2, cluster_timestamp: 1376111601621, }, attemptId: 1, }, id: 1, }, state: C_NEW, ] for AM appattempt_1376111601621_0002_000001
2013-08-10 05:17:08,720 INFO org.apache.hadoop.yarn.server.resourcemanager.rmapp.attempt.RMAppAttemptImpl: appattempt_1376111601621_0002_000001 State change from ALLOCATED to LAUNCHED
2013-08-10 05:17:09,021 INFO org.apache.hadoop.yarn.server.resourcemanager.rmcontainer.RMContainerImpl: container_1376111601621_0002_01_000001 Container Transitioned from ACQUIRED to RUNNING
2013-08-10 05:17:18,132 INFO org.apache.hadoop.yarn.server.resourcemanager.ApplicationMasterService: AM registration appattempt_1376111601621_0002_000001
2013-08-10 05:17:18,132 INFO org.apache.hadoop.yarn.server.resourcemanager.RMAuditLogger: USER=ubuntu	IP=192.168.100.39	OPERATION=Register App Master	TARGET=ApplicationMasterService	RESULT=SUCCESS	APPID=application_1376111601621_0002	APPATTEMPTID=appattempt_1376111601621_0002_000001
2013-08-10 05:17:18,135 INFO org.apache.hadoop.yarn.server.resourcemanager.rmapp.attempt.RMAppAttemptImpl: appattempt_1376111601621_0002_000001 State change from LAUNCHED to RUNNING
2013-08-10 05:17:18,135 INFO org.apache.hadoop.yarn.server.resourcemanager.rmapp.RMAppImpl: application_1376111601621_0002 State change from ACCEPTED to RUNNING
2013-08-10 05:17:19,247 INFO org.apache.hadoop.yarn.server.resourcemanager.rmcontainer.RMContainerImpl: container_1376111601621_0002_01_000002 Container Transitioned from NEW to ALLOCATED
2013-08-10 05:17:19,247 INFO org.apache.hadoop.yarn.server.resourcemanager.RMAuditLogger: USER=ubuntu	OPERATION=AM Allocated Container	TARGET=SchedulerApp	RESULT=SUCCESS	APPID=application_1376111601621_0002	CONTAINERID=container_1376111601621_0002_01_000002
2013-08-10 05:17:19,247 INFO org.apache.hadoop.yarn.server.resourcemanager.scheduler.common.fica.FiCaSchedulerNode: Assigned container container_1376111601621_0002_01_000002 of capacity <memory:1024, vCores:1> on host hadoop-221-7:34609, which currently has 1 containers, <memory:1024, vCores:1> used and <memory:7168, vCores:15> available
2013-08-10 05:17:19,249 INFO org.apache.hadoop.yarn.server.resourcemanager.scheduler.capacity.LeafQueue: assignedContainer application=application_1376111601621_0002 container=Container: [ContainerId: container_1376111601621_0002_01_000002, NodeId: hadoop-221-7:34609, NodeHttpAddress: hadoop-221-7:8042, Resource: <memory:1024, vCores:1>, Priority: 20, State: NEW, Token: null, Status: container_id {, app_attempt_id {, application_id {, id: 2, cluster_timestamp: 1376111601621, }, attemptId: 1, }, id: 2, }, state: C_NEW, ] containerId=container_1376111601621_0002_01_000002 queue=default: capacity=1.0, absoluteCapacity=1.0, usedResources=<memory:2048, vCores:1>usedCapacity=0.041666668, absoluteUsedCapacity=0.041666668, numApps=1, numContainers=1 usedCapacity=0.041666668 absoluteUsedCapacity=0.041666668 used=<memory:2048, vCores:1> cluster=<memory:49152, vCores:96>
2013-08-10 05:17:19,249 INFO org.apache.hadoop.yarn.server.resourcemanager.scheduler.capacity.ParentQueue: Re-sorting queues since queue: root.default stats: default: capacity=1.0, absoluteCapacity=1.0, usedResources=<memory:3072, vCores:2>usedCapacity=0.0625, absoluteUsedCapacity=0.0625, numApps=1, numContainers=2
2013-08-10 05:17:19,250 INFO org.apache.hadoop.yarn.server.resourcemanager.scheduler.capacity.ParentQueue: assignedContainer queue=root usedCapacity=0.0625 absoluteUsedCapacity=0.0625 used=<memory:3072, vCores:2> cluster=<memory:49152, vCores:96>
2013-08-10 05:17:19,559 INFO org.apache.hadoop.yarn.server.resourcemanager.rmcontainer.RMContainerImpl: container_1376111601621_0002_01_000003 Container Transitioned from NEW to ALLOCATED
2013-08-10 05:17:19,559 INFO org.apache.hadoop.yarn.server.resourcemanager.RMAuditLogger: USER=ubuntu	OPERATION=AM Allocated Container	TARGET=SchedulerApp	RESULT=SUCCESS	APPID=application_1376111601621_0002	CONTAINERID=container_1376111601621_0002_01_000003
2013-08-10 05:17:19,559 INFO org.apache.hadoop.yarn.server.resourcemanager.scheduler.common.fica.FiCaSchedulerNode: Assigned container container_1376111601621_0002_01_000003 of capacity <memory:1024, vCores:1> on host hadoop-221-4:41177, which currently has 1 containers, <memory:1024, vCores:1> used and <memory:7168, vCores:15> available
2013-08-10 05:17:19,561 INFO org.apache.hadoop.yarn.server.resourcemanager.scheduler.capacity.LeafQueue: assignedContainer application=application_1376111601621_0002 container=Container: [ContainerId: container_1376111601621_0002_01_000003, NodeId: hadoop-221-4:41177, NodeHttpAddress: hadoop-221-4:8042, Resource: <memory:1024, vCores:1>, Priority: 20, State: NEW, Token: null, Status: container_id {, app_attempt_id {, application_id {, id: 2, cluster_timestamp: 1376111601621, }, attemptId: 1, }, id: 3, }, state: C_NEW, ] containerId=container_1376111601621_0002_01_000003 queue=default: capacity=1.0, absoluteCapacity=1.0, usedResources=<memory:3072, vCores:2>usedCapacity=0.0625, absoluteUsedCapacity=0.0625, numApps=1, numContainers=2 usedCapacity=0.0625 absoluteUsedCapacity=0.0625 used=<memory:3072, vCores:2> cluster=<memory:49152, vCores:96>
2013-08-10 05:17:19,561 INFO org.apache.hadoop.yarn.server.resourcemanager.scheduler.capacity.ParentQueue: Re-sorting queues since queue: root.default stats: default: capacity=1.0, absoluteCapacity=1.0, usedResources=<memory:4096, vCores:3>usedCapacity=0.083333336, absoluteUsedCapacity=0.083333336, numApps=1, numContainers=3
2013-08-10 05:17:19,561 INFO org.apache.hadoop.yarn.server.resourcemanager.scheduler.capacity.ParentQueue: assignedContainer queue=root usedCapacity=0.083333336 absoluteUsedCapacity=0.083333336 used=<memory:4096, vCores:3> cluster=<memory:49152, vCores:96>
2013-08-10 05:17:20,203 INFO org.apache.hadoop.yarn.server.resourcemanager.rmcontainer.RMContainerImpl: container_1376111601621_0002_01_000002 Container Transitioned from ALLOCATED to ACQUIRED
2013-08-10 05:17:20,207 INFO org.apache.hadoop.yarn.server.resourcemanager.rmcontainer.RMContainerImpl: container_1376111601621_0002_01_000003 Container Transitioned from ALLOCATED to ACQUIRED
2013-08-10 05:17:20,566 INFO org.apache.hadoop.yarn.server.resourcemanager.rmcontainer.RMContainerImpl: container_1376111601621_0002_01_000003 Container Transitioned from ACQUIRED to RUNNING
2013-08-10 05:17:21,237 INFO org.apache.hadoop.yarn.server.resourcemanager.scheduler.AppSchedulingInfo: checking for deactivate... 
2013-08-10 05:17:21,256 INFO org.apache.hadoop.yarn.server.resourcemanager.rmcontainer.RMContainerImpl: container_1376111601621_0002_01_000002 Container Transitioned from ACQUIRED to RUNNING
2013-08-10 05:20:08,324 INFO org.apache.hadoop.yarn.server.resourcemanager.rmcontainer.RMContainerImpl: container_1376111601621_0002_01_000002 Container Transitioned from RUNNING to COMPLETED
2013-08-10 05:20:08,325 INFO org.apache.hadoop.yarn.server.resourcemanager.scheduler.common.fica.FiCaSchedulerApp: Completed container: container_1376111601621_0002_01_000002 in state: COMPLETED event:FINISHED
2013-08-10 05:20:08,325 INFO org.apache.hadoop.yarn.server.resourcemanager.RMAuditLogger: USER=ubuntu	OPERATION=AM Released Container	TARGET=SchedulerApp	RESULT=SUCCESS	APPID=application_1376111601621_0002	CONTAINERID=container_1376111601621_0002_01_000002
2013-08-10 05:20:08,325 INFO org.apache.hadoop.yarn.server.resourcemanager.scheduler.common.fica.FiCaSchedulerNode: Released container container_1376111601621_0002_01_000002 of capacity <memory:1024, vCores:1> on host hadoop-221-7:34609, which currently has 0 containers, <memory:0, vCores:0> used and <memory:8192, vCores:16> available, release resources=true
2013-08-10 05:20:08,325 INFO org.apache.hadoop.yarn.server.resourcemanager.scheduler.capacity.LeafQueue: default used=<memory:3072, vCores:2> numContainers=2 user=ubuntu user-resources=<memory:3072, vCores:2>
2013-08-10 05:20:08,339 INFO org.apache.hadoop.yarn.server.resourcemanager.scheduler.capacity.LeafQueue: completedContainer container=Container: [ContainerId: container_1376111601621_0002_01_000002, NodeId: hadoop-221-7:34609, NodeHttpAddress: hadoop-221-7:8042, Resource: <memory:1024, vCores:1>, Priority: 20, State: NEW, Token: null, Status: container_id {, app_attempt_id {, application_id {, id: 2, cluster_timestamp: 1376111601621, }, attemptId: 1, }, id: 2, }, state: C_COMPLETE, diagnostics: "Container killed by the ApplicationMaster.\n\n", exit_status: 143, ] resource=<memory:1024, vCores:1> queue=default: capacity=1.0, absoluteCapacity=1.0, usedResources=<memory:3072, vCores:2>usedCapacity=0.0625, absoluteUsedCapacity=0.0625, numApps=1, numContainers=2 usedCapacity=0.0625 absoluteUsedCapacity=0.0625 used=<memory:3072, vCores:2> cluster=<memory:49152, vCores:96>
2013-08-10 05:20:08,339 INFO org.apache.hadoop.yarn.server.resourcemanager.scheduler.capacity.ParentQueue: completedContainer queue=root usedCapacity=0.0625 absoluteUsedCapacity=0.0625 used=<memory:3072, vCores:2> cluster=<memory:49152, vCores:96>
2013-08-10 05:20:08,339 INFO org.apache.hadoop.yarn.server.resourcemanager.scheduler.capacity.CapacityScheduler: Application appattempt_1376111601621_0002_000001 released container container_1376111601621_0002_01_000002 on node: host: hadoop-221-7:34609 #containers=0 available=8192 used=0 with event: FINISHED
2013-08-10 05:20:09,289 INFO org.apache.hadoop.yarn.server.resourcemanager.rmcontainer.RMContainerImpl: container_1376111601621_0002_01_000003 Container Transitioned from RUNNING to COMPLETED
2013-08-10 05:20:09,290 INFO org.apache.hadoop.yarn.server.resourcemanager.scheduler.common.fica.FiCaSchedulerApp: Completed container: container_1376111601621_0002_01_000003 in state: COMPLETED event:FINISHED
2013-08-10 05:20:09,290 INFO org.apache.hadoop.yarn.server.resourcemanager.RMAuditLogger: USER=ubuntu	OPERATION=AM Released Container	TARGET=SchedulerApp	RESULT=SUCCESS	APPID=application_1376111601621_0002	CONTAINERID=container_1376111601621_0002_01_000003
2013-08-10 05:20:09,290 INFO org.apache.hadoop.yarn.server.resourcemanager.scheduler.common.fica.FiCaSchedulerNode: Released container container_1376111601621_0002_01_000003 of capacity <memory:1024, vCores:1> on host hadoop-221-4:41177, which currently has 0 containers, <memory:0, vCores:0> used and <memory:8192, vCores:16> available, release resources=true
2013-08-10 05:20:09,290 INFO org.apache.hadoop.yarn.server.resourcemanager.scheduler.capacity.LeafQueue: default used=<memory:2048, vCores:1> numContainers=1 user=ubuntu user-resources=<memory:2048, vCores:1>
2013-08-10 05:20:09,292 INFO org.apache.hadoop.yarn.server.resourcemanager.scheduler.capacity.LeafQueue: completedContainer container=Container: [ContainerId: container_1376111601621_0002_01_000003, NodeId: hadoop-221-4:41177, NodeHttpAddress: hadoop-221-4:8042, Resource: <memory:1024, vCores:1>, Priority: 20, State: NEW, Token: null, Status: container_id {, app_attempt_id {, application_id {, id: 2, cluster_timestamp: 1376111601621, }, attemptId: 1, }, id: 3, }, state: C_COMPLETE, diagnostics: "Container killed by the ApplicationMaster.\n\n", exit_status: 143, ] resource=<memory:1024, vCores:1> queue=default: capacity=1.0, absoluteCapacity=1.0, usedResources=<memory:2048, vCores:1>usedCapacity=0.041666668, absoluteUsedCapacity=0.041666668, numApps=1, numContainers=1 usedCapacity=0.041666668 absoluteUsedCapacity=0.041666668 used=<memory:2048, vCores:1> cluster=<memory:49152, vCores:96>
2013-08-10 05:20:09,292 INFO org.apache.hadoop.yarn.server.resourcemanager.scheduler.capacity.ParentQueue: completedContainer queue=root usedCapacity=0.041666668 absoluteUsedCapacity=0.041666668 used=<memory:2048, vCores:1> cluster=<memory:49152, vCores:96>
2013-08-10 05:20:09,293 INFO org.apache.hadoop.yarn.server.resourcemanager.scheduler.capacity.CapacityScheduler: Application appattempt_1376111601621_0002_000001 released container container_1376111601621_0002_01_000003 on node: host: hadoop-221-4:41177 #containers=0 available=8192 used=0 with event: FINISHED
2013-08-10 05:20:13,453 INFO org.apache.hadoop.yarn.server.resourcemanager.rmapp.attempt.RMAppAttemptImpl: appattempt_1376111601621_0002_000001 State change from RUNNING to FINISHING
2013-08-10 05:20:13,456 INFO org.apache.hadoop.yarn.server.resourcemanager.rmapp.RMAppImpl: application_1376111601621_0002 State change from RUNNING to FINISHING
2013-08-10 05:20:14,299 INFO org.apache.hadoop.yarn.server.resourcemanager.rmcontainer.RMContainerImpl: container_1376111601621_0002_01_000001 Container Transitioned from RUNNING to COMPLETED
2013-08-10 05:20:14,300 INFO org.apache.hadoop.yarn.server.resourcemanager.rmapp.attempt.RMAppAttemptImpl: appattempt_1376111601621_0002_000001 State change from FINISHING to FINISHED
2013-08-10 05:20:14,300 INFO org.apache.hadoop.yarn.server.resourcemanager.scheduler.common.fica.FiCaSchedulerApp: Completed container: container_1376111601621_0002_01_000001 in state: COMPLETED event:FINISHED
2013-08-10 05:20:14,300 INFO org.apache.hadoop.yarn.server.resourcemanager.rmapp.RMAppImpl: application_1376111601621_0002 State change from FINISHING to FINISHED
2013-08-10 05:20:14,300 INFO org.apache.hadoop.yarn.server.resourcemanager.RMAuditLogger: USER=ubuntu	OPERATION=AM Released Container	TARGET=SchedulerApp	RESULT=SUCCESS	APPID=application_1376111601621_0002	CONTAINERID=container_1376111601621_0002_01_000001
2013-08-10 05:20:14,300 INFO org.apache.hadoop.yarn.server.resourcemanager.scheduler.common.fica.FiCaSchedulerNode: Released container container_1376111601621_0002_01_000001 of capacity <memory:2048, vCores:1> on host hadoop-221-5:42694, which currently has 0 containers, <memory:0, vCores:0> used and <memory:8192, vCores:16> available, release resources=true
2013-08-10 05:20:14,300 INFO org.apache.hadoop.yarn.server.resourcemanager.RMAuditLogger: USER=ubuntu	OPERATION=Application Finished - Succeeded	TARGET=RMAppManager	RESULT=SUCCESS	APPID=application_1376111601621_0002
2013-08-10 05:20:14,300 INFO org.apache.hadoop.yarn.server.resourcemanager.scheduler.capacity.LeafQueue: default used=<memory:0, vCores:0> numContainers=0 user=ubuntu user-resources=<memory:0, vCores:0>
2013-08-10 05:20:14,300 INFO org.apache.hadoop.yarn.server.resourcemanager.amlauncher.AMLauncher: Cleaning master appattempt_1376111601621_0002_000001
2013-08-10 05:20:14,301 INFO org.apache.hadoop.yarn.server.resourcemanager.recovery.RMStateStore: Removing info for app: application_1376111601621_0002
2013-08-10 05:20:14,301 INFO org.apache.hadoop.yarn.server.resourcemanager.RMAppManager$ApplicationSummary: appId=application_1376111601621_0002,name=TeraGen,user=ubuntu,queue=default,state=FINISHED,trackingUrl=hadoop-221-1.novalocal:8088/proxy/application_1376111601621_0002/jobhistory/job/job_1376111601621_0002,appMasterHost=hadoop-221-5,startTime=1376111827711,finishTime=1376112013456
2013-08-10 05:20:14,302 INFO org.apache.hadoop.yarn.server.resourcemanager.scheduler.capacity.LeafQueue: completedContainer container=Container: [ContainerId: container_1376111601621_0002_01_000001, NodeId: hadoop-221-5:42694, NodeHttpAddress: hadoop-221-5:8042, Resource: <memory:2048, vCores:1>, Priority: 0, State: NEW, Token: null, Status: container_id {, app_attempt_id {, application_id {, id: 2, cluster_timestamp: 1376111601621, }, attemptId: 1, }, id: 1, }, state: C_COMPLETE, diagnostics: "", exit_status: 0, ] resource=<memory:2048, vCores:1> queue=default: capacity=1.0, absoluteCapacity=1.0, usedResources=<memory:0, vCores:0>usedCapacity=0.0, absoluteUsedCapacity=0.0, numApps=1, numContainers=0 usedCapacity=0.0 absoluteUsedCapacity=0.0 used=<memory:0, vCores:0> cluster=<memory:49152, vCores:96>
2013-08-10 05:20:14,302 INFO org.apache.hadoop.yarn.server.resourcemanager.scheduler.capacity.ParentQueue: completedContainer queue=root usedCapacity=0.0 absoluteUsedCapacity=0.0 used=<memory:0, vCores:0> cluster=<memory:49152, vCores:96>
2013-08-10 05:20:14,303 INFO org.apache.hadoop.yarn.server.resourcemanager.scheduler.capacity.CapacityScheduler: Application appattempt_1376111601621_0002_000001 released container container_1376111601621_0002_01_000001 on node: host: hadoop-221-5:42694 #containers=0 available=8192 used=0 with event: FINISHED
2013-08-10 05:20:14,303 INFO org.apache.hadoop.yarn.server.resourcemanager.scheduler.capacity.CapacityScheduler: Application appattempt_1376111601621_0002_000001 is done. finalState=FINISHED
2013-08-10 05:20:14,303 INFO org.apache.hadoop.yarn.server.resourcemanager.scheduler.AppSchedulingInfo: Application application_1376111601621_0002 requests cleared
2013-08-10 05:20:14,303 INFO org.apache.hadoop.yarn.server.resourcemanager.scheduler.capacity.LeafQueue: Application removed - appId: application_1376111601621_0002 user: ubuntu queue: default #user-pending-applications: 0 #user-active-applications: 0 #queue-pending-applications: 0 #queue-active-applications: 0
2013-08-10 05:20:14,303 INFO org.apache.hadoop.yarn.server.resourcemanager.scheduler.capacity.ParentQueue: Application removed - appId: application_1376111601621_0002 user: ubuntu leaf-queue of parent: root #applications: 0
2013-08-10 05:20:14,456 INFO org.apache.hadoop.yarn.server.resourcemanager.ClientRMService: Allocated new applicationId: 3
2013-08-10 05:20:16,347 INFO org.apache.hadoop.yarn.server.resourcemanager.ClientRMService: Storing Application with id application_1376111601621_0003
2013-08-10 05:20:16,348 INFO org.apache.hadoop.yarn.server.resourcemanager.recovery.RMStateStore: Storing info for app: application_1376111601621_0003
2013-08-10 05:20:16,348 INFO org.apache.hadoop.yarn.server.resourcemanager.ClientRMService: Application with id 3 submitted by user ubuntu
2013-08-10 05:20:16,348 INFO org.apache.hadoop.yarn.server.resourcemanager.RMAuditLogger: USER=ubuntu	IP=192.168.100.36	OPERATION=Submit Application Request	TARGET=ClientRMService	RESULT=SUCCESS	APPID=application_1376111601621_0003
2013-08-10 05:20:16,349 INFO org.apache.hadoop.yarn.server.resourcemanager.rmapp.RMAppImpl: application_1376111601621_0003 State change from NEW to SUBMITTED
2013-08-10 05:20:16,350 INFO org.apache.hadoop.yarn.server.resourcemanager.ApplicationMasterService: Registering appattempt_1376111601621_0003_000001
2013-08-10 05:20:16,350 INFO org.apache.hadoop.yarn.server.resourcemanager.rmapp.attempt.RMAppAttemptImpl: appattempt_1376111601621_0003_000001 State change from NEW to SUBMITTED
2013-08-10 05:20:16,351 INFO org.apache.hadoop.yarn.server.resourcemanager.scheduler.capacity.LeafQueue: Application application_1376111601621_0003 from user: ubuntu activated in queue: default
2013-08-10 05:20:16,351 INFO org.apache.hadoop.yarn.server.resourcemanager.scheduler.capacity.LeafQueue: Application added - appId: application_1376111601621_0003 user: org.apache.hadoop.yarn.server.resourcemanager.scheduler.capacity.LeafQueue$User@3bdb200a, leaf-queue: default #user-pending-applications: 0 #user-active-applications: 1 #queue-pending-applications: 0 #queue-active-applications: 1
2013-08-10 05:20:16,351 INFO org.apache.hadoop.yarn.server.resourcemanager.scheduler.capacity.ParentQueue: Application added - appId: application_1376111601621_0003 user: ubuntu leaf-queue of parent: root #applications: 1
2013-08-10 05:20:16,351 INFO org.apache.hadoop.yarn.server.resourcemanager.scheduler.capacity.CapacityScheduler: Application Submission: appattempt_1376111601621_0003_000001, user: ubuntu queue: default: capacity=1.0, absoluteCapacity=1.0, usedResources=<memory:0, vCores:0>usedCapacity=0.0, absoluteUsedCapacity=0.0, numApps=1, numContainers=0, currently active: 1
2013-08-10 05:20:16,352 INFO org.apache.hadoop.yarn.server.resourcemanager.rmapp.attempt.RMAppAttemptImpl: appattempt_1376111601621_0003_000001 State change from SUBMITTED to SCHEDULED
2013-08-10 05:20:16,352 INFO org.apache.hadoop.yarn.server.resourcemanager.rmapp.RMAppImpl: application_1376111601621_0003 State change from SUBMITTED to ACCEPTED
2013-08-10 05:20:16,354 INFO org.apache.hadoop.yarn.server.resourcemanager.rmcontainer.RMContainerImpl: container_1376111601621_0003_01_000001 Container Transitioned from NEW to ALLOCATED
2013-08-10 05:20:16,354 INFO org.apache.hadoop.yarn.server.resourcemanager.RMAuditLogger: USER=ubuntu	OPERATION=AM Allocated Container	TARGET=SchedulerApp	RESULT=SUCCESS	APPID=application_1376111601621_0003	CONTAINERID=container_1376111601621_0003_01_000001
2013-08-10 05:20:16,354 INFO org.apache.hadoop.yarn.server.resourcemanager.scheduler.common.fica.FiCaSchedulerNode: Assigned container container_1376111601621_0003_01_000001 of capacity <memory:2048, vCores:1> on host hadoop-221-7:34609, which currently has 1 containers, <memory:2048, vCores:1> used and <memory:6144, vCores:15> available
2013-08-10 05:20:16,356 INFO org.apache.hadoop.yarn.server.resourcemanager.scheduler.capacity.LeafQueue: assignedContainer application=application_1376111601621_0003 container=Container: [ContainerId: container_1376111601621_0003_01_000001, NodeId: hadoop-221-7:34609, NodeHttpAddress: hadoop-221-7:8042, Resource: <memory:2048, vCores:1>, Priority: 0, State: NEW, Token: null, Status: container_id {, app_attempt_id {, application_id {, id: 3, cluster_timestamp: 1376111601621, }, attemptId: 1, }, id: 1, }, state: C_NEW, ] containerId=container_1376111601621_0003_01_000001 queue=default: capacity=1.0, absoluteCapacity=1.0, usedResources=<memory:0, vCores:0>usedCapacity=0.0, absoluteUsedCapacity=0.0, numApps=1, numContainers=0 usedCapacity=0.0 absoluteUsedCapacity=0.0 used=<memory:0, vCores:0> cluster=<memory:49152, vCores:96>
2013-08-10 05:20:16,356 INFO org.apache.hadoop.yarn.server.resourcemanager.scheduler.capacity.ParentQueue: Re-sorting queues since queue: root.default stats: default: capacity=1.0, absoluteCapacity=1.0, usedResources=<memory:2048, vCores:1>usedCapacity=0.041666668, absoluteUsedCapacity=0.041666668, numApps=1, numContainers=1
2013-08-10 05:20:16,356 INFO org.apache.hadoop.yarn.server.resourcemanager.scheduler.capacity.ParentQueue: assignedContainer queue=root usedCapacity=0.041666668 absoluteUsedCapacity=0.041666668 used=<memory:2048, vCores:1> cluster=<memory:49152, vCores:96>
2013-08-10 05:20:16,357 INFO org.apache.hadoop.yarn.server.resourcemanager.rmcontainer.RMContainerImpl: container_1376111601621_0003_01_000001 Container Transitioned from ALLOCATED to ACQUIRED
2013-08-10 05:20:16,358 INFO org.apache.hadoop.yarn.server.resourcemanager.rmapp.attempt.RMAppAttemptImpl: Storing attempt: AppId: application_1376111601621_0003 AttemptId: appattempt_1376111601621_0003_000001 MasterContainer: Container: [ContainerId: container_1376111601621_0003_01_000001, NodeId: hadoop-221-7:34609, NodeHttpAddress: hadoop-221-7:8042, Resource: <memory:2048, vCores:1>, Priority: 0, State: NEW, Token: null, Status: container_id {, app_attempt_id {, application_id {, id: 3, cluster_timestamp: 1376111601621, }, attemptId: 1, }, id: 1, }, state: C_NEW, ]
2013-08-10 05:20:16,359 INFO org.apache.hadoop.yarn.server.resourcemanager.rmapp.attempt.RMAppAttemptImpl: appattempt_1376111601621_0003_000001 State change from SCHEDULED to ALLOCATED_SAVING
2013-08-10 05:20:16,359 INFO org.apache.hadoop.yarn.server.resourcemanager.recovery.RMStateStore: Storing info for attempt: appattempt_1376111601621_0003_000001
2013-08-10 05:20:16,360 INFO org.apache.hadoop.yarn.server.resourcemanager.rmapp.attempt.RMAppAttemptImpl: appattempt_1376111601621_0003_000001 State change from ALLOCATED_SAVING to ALLOCATED
2013-08-10 05:20:16,362 INFO org.apache.hadoop.yarn.server.resourcemanager.amlauncher.AMLauncher: Launching masterappattempt_1376111601621_0003_000001
2013-08-10 05:20:16,365 INFO org.apache.hadoop.yarn.server.resourcemanager.amlauncher.AMLauncher: Setting up container Container: [ContainerId: container_1376111601621_0003_01_000001, NodeId: hadoop-221-7:34609, NodeHttpAddress: hadoop-221-7:8042, Resource: <memory:2048, vCores:1>, Priority: 0, State: NEW, Token: null, Status: container_id {, app_attempt_id {, application_id {, id: 3, cluster_timestamp: 1376111601621, }, attemptId: 1, }, id: 1, }, state: C_NEW, ] for AM appattempt_1376111601621_0003_000001
2013-08-10 05:20:16,365 INFO org.apache.hadoop.yarn.server.resourcemanager.amlauncher.AMLauncher: Command to launch container container_1376111601621_0003_01_000001 : $JAVA_HOME/bin/java -Dlog4j.configuration=container-log4j.properties -Dyarn.app.mapreduce.container.log.dir=<LOG_DIR> -Dyarn.app.mapreduce.container.log.filesize=0 -Dhadoop.root.logger=INFO,CLA  -Xmx1024m org.apache.hadoop.mapreduce.v2.app.MRAppMaster 1><LOG_DIR>/stdout 2><LOG_DIR>/stderr 
2013-08-10 05:20:16,381 INFO org.apache.hadoop.yarn.server.resourcemanager.amlauncher.AMLauncher: Done launching container Container: [ContainerId: container_1376111601621_0003_01_000001, NodeId: hadoop-221-7:34609, NodeHttpAddress: hadoop-221-7:8042, Resource: <memory:2048, vCores:1>, Priority: 0, State: NEW, Token: null, Status: container_id {, app_attempt_id {, application_id {, id: 3, cluster_timestamp: 1376111601621, }, attemptId: 1, }, id: 1, }, state: C_NEW, ] for AM appattempt_1376111601621_0003_000001
2013-08-10 05:20:16,381 INFO org.apache.hadoop.yarn.server.resourcemanager.rmapp.attempt.RMAppAttemptImpl: appattempt_1376111601621_0003_000001 State change from ALLOCATED to LAUNCHED
2013-08-10 05:20:17,360 INFO org.apache.hadoop.yarn.server.resourcemanager.rmcontainer.RMContainerImpl: container_1376111601621_0003_01_000001 Container Transitioned from ACQUIRED to RUNNING
2013-08-10 05:20:23,731 INFO org.apache.hadoop.yarn.server.resourcemanager.ApplicationMasterService: AM registration appattempt_1376111601621_0003_000001
2013-08-10 05:20:23,732 INFO org.apache.hadoop.yarn.server.resourcemanager.RMAuditLogger: USER=ubuntu	IP=192.168.100.42	OPERATION=Register App Master	TARGET=ApplicationMasterService	RESULT=SUCCESS	APPID=application_1376111601621_0003	APPATTEMPTID=appattempt_1376111601621_0003_000001
2013-08-10 05:20:23,733 INFO org.apache.hadoop.yarn.server.resourcemanager.rmapp.attempt.RMAppAttemptImpl: appattempt_1376111601621_0003_000001 State change from LAUNCHED to RUNNING
2013-08-10 05:20:23,733 INFO org.apache.hadoop.yarn.server.resourcemanager.rmapp.RMAppImpl: application_1376111601621_0003 State change from ACCEPTED to RUNNING
2013-08-10 05:20:24,796 INFO org.apache.hadoop.yarn.server.resourcemanager.rmcontainer.RMContainerImpl: container_1376111601621_0003_01_000002 Container Transitioned from NEW to ALLOCATED
2013-08-10 05:20:24,797 INFO org.apache.hadoop.yarn.server.resourcemanager.RMAuditLogger: USER=ubuntu	OPERATION=AM Allocated Container	TARGET=SchedulerApp	RESULT=SUCCESS	APPID=application_1376111601621_0003	CONTAINERID=container_1376111601621_0003_01_000002
2013-08-10 05:20:24,797 INFO org.apache.hadoop.yarn.server.resourcemanager.scheduler.common.fica.FiCaSchedulerNode: Assigned container container_1376111601621_0003_01_000002 of capacity <memory:1024, vCores:1> on host hadoop-221-6:57712, which currently has 1 containers, <memory:1024, vCores:1> used and <memory:7168, vCores:15> available
2013-08-10 05:20:24,798 INFO org.apache.hadoop.yarn.server.resourcemanager.scheduler.capacity.LeafQueue: assignedContainer application=application_1376111601621_0003 container=Container: [ContainerId: container_1376111601621_0003_01_000002, NodeId: hadoop-221-6:57712, NodeHttpAddress: hadoop-221-6:8042, Resource: <memory:1024, vCores:1>, Priority: 20, State: NEW, Token: null, Status: container_id {, app_attempt_id {, application_id {, id: 3, cluster_timestamp: 1376111601621, }, attemptId: 1, }, id: 2, }, state: C_NEW, ] containerId=container_1376111601621_0003_01_000002 queue=default: capacity=1.0, absoluteCapacity=1.0, usedResources=<memory:2048, vCores:1>usedCapacity=0.041666668, absoluteUsedCapacity=0.041666668, numApps=1, numContainers=1 usedCapacity=0.041666668 absoluteUsedCapacity=0.041666668 used=<memory:2048, vCores:1> cluster=<memory:49152, vCores:96>
2013-08-10 05:20:24,799 INFO org.apache.hadoop.yarn.server.resourcemanager.scheduler.capacity.ParentQueue: Re-sorting queues since queue: root.default stats: default: capacity=1.0, absoluteCapacity=1.0, usedResources=<memory:3072, vCores:2>usedCapacity=0.0625, absoluteUsedCapacity=0.0625, numApps=1, numContainers=2
2013-08-10 05:20:24,799 INFO org.apache.hadoop.yarn.server.resourcemanager.scheduler.capacity.ParentQueue: assignedContainer queue=root usedCapacity=0.0625 absoluteUsedCapacity=0.0625 used=<memory:3072, vCores:2> cluster=<memory:49152, vCores:96>
2013-08-10 05:20:25,264 INFO org.apache.hadoop.yarn.server.resourcemanager.rmcontainer.RMContainerImpl: container_1376111601621_0003_01_000003 Container Transitioned from NEW to ALLOCATED
2013-08-10 05:20:25,265 INFO org.apache.hadoop.yarn.server.resourcemanager.RMAuditLogger: USER=ubuntu	OPERATION=AM Allocated Container	TARGET=SchedulerApp	RESULT=SUCCESS	APPID=application_1376111601621_0003	CONTAINERID=container_1376111601621_0003_01_000003
2013-08-10 05:20:25,265 INFO org.apache.hadoop.yarn.server.resourcemanager.scheduler.common.fica.FiCaSchedulerNode: Assigned container container_1376111601621_0003_01_000003 of capacity <memory:1024, vCores:1> on host hadoop-221-2:55267, which currently has 1 containers, <memory:1024, vCores:1> used and <memory:7168, vCores:15> available
2013-08-10 05:20:25,266 INFO org.apache.hadoop.yarn.server.resourcemanager.scheduler.capacity.LeafQueue: assignedContainer application=application_1376111601621_0003 container=Container: [ContainerId: container_1376111601621_0003_01_000003, NodeId: hadoop-221-2:55267, NodeHttpAddress: hadoop-221-2:8042, Resource: <memory:1024, vCores:1>, Priority: 20, State: NEW, Token: null, Status: container_id {, app_attempt_id {, application_id {, id: 3, cluster_timestamp: 1376111601621, }, attemptId: 1, }, id: 3, }, state: C_NEW, ] containerId=container_1376111601621_0003_01_000003 queue=default: capacity=1.0, absoluteCapacity=1.0, usedResources=<memory:3072, vCores:2>usedCapacity=0.0625, absoluteUsedCapacity=0.0625, numApps=1, numContainers=2 usedCapacity=0.0625 absoluteUsedCapacity=0.0625 used=<memory:3072, vCores:2> cluster=<memory:49152, vCores:96>
2013-08-10 05:20:25,267 INFO org.apache.hadoop.yarn.server.resourcemanager.scheduler.capacity.ParentQueue: Re-sorting queues since queue: root.default stats: default: capacity=1.0, absoluteCapacity=1.0, usedResources=<memory:4096, vCores:3>usedCapacity=0.083333336, absoluteUsedCapacity=0.083333336, numApps=1, numContainers=3
2013-08-10 05:20:25,267 INFO org.apache.hadoop.yarn.server.resourcemanager.scheduler.capacity.ParentQueue: assignedContainer queue=root usedCapacity=0.083333336 absoluteUsedCapacity=0.083333336 used=<memory:4096, vCores:3> cluster=<memory:49152, vCores:96>
2013-08-10 05:20:25,805 INFO org.apache.hadoop.yarn.server.resourcemanager.rmcontainer.RMContainerImpl: container_1376111601621_0003_01_000002 Container Transitioned from ALLOCATED to ACQUIRED
2013-08-10 05:20:25,807 INFO org.apache.hadoop.yarn.server.resourcemanager.rmcontainer.RMContainerImpl: container_1376111601621_0003_01_000003 Container Transitioned from ALLOCATED to ACQUIRED
2013-08-10 05:20:26,809 INFO org.apache.hadoop.yarn.server.resourcemanager.rmcontainer.RMContainerImpl: container_1376111601621_0003_01_000002 Container Transitioned from ACQUIRED to RUNNING
2013-08-10 05:20:26,836 INFO org.apache.hadoop.yarn.server.resourcemanager.scheduler.AppSchedulingInfo: checking for deactivate... 
2013-08-10 05:20:27,360 INFO org.apache.hadoop.yarn.server.resourcemanager.rmcontainer.RMContainerImpl: container_1376111601621_0003_01_000003 Container Transitioned from ACQUIRED to RUNNING
2013-08-10 05:23:19,966 INFO org.apache.hadoop.yarn.server.resourcemanager.rmcontainer.RMContainerImpl: container_1376111601621_0003_01_000002 Container Transitioned from RUNNING to COMPLETED
2013-08-10 05:23:19,966 INFO org.apache.hadoop.yarn.server.resourcemanager.scheduler.common.fica.FiCaSchedulerApp: Completed container: container_1376111601621_0003_01_000002 in state: COMPLETED event:FINISHED
2013-08-10 05:23:19,966 INFO org.apache.hadoop.yarn.server.resourcemanager.RMAuditLogger: USER=ubuntu	OPERATION=AM Released Container	TARGET=SchedulerApp	RESULT=SUCCESS	APPID=application_1376111601621_0003	CONTAINERID=container_1376111601621_0003_01_000002
2013-08-10 05:23:19,966 INFO org.apache.hadoop.yarn.server.resourcemanager.scheduler.common.fica.FiCaSchedulerNode: Released container container_1376111601621_0003_01_000002 of capacity <memory:1024, vCores:1> on host hadoop-221-6:57712, which currently has 0 containers, <memory:0, vCores:0> used and <memory:8192, vCores:16> available, release resources=true
2013-08-10 05:23:19,967 INFO org.apache.hadoop.yarn.server.resourcemanager.scheduler.capacity.LeafQueue: default used=<memory:3072, vCores:2> numContainers=2 user=ubuntu user-resources=<memory:3072, vCores:2>
2013-08-10 05:23:19,968 INFO org.apache.hadoop.yarn.server.resourcemanager.scheduler.capacity.LeafQueue: completedContainer container=Container: [ContainerId: container_1376111601621_0003_01_000002, NodeId: hadoop-221-6:57712, NodeHttpAddress: hadoop-221-6:8042, Resource: <memory:1024, vCores:1>, Priority: 20, State: NEW, Token: null, Status: container_id {, app_attempt_id {, application_id {, id: 3, cluster_timestamp: 1376111601621, }, attemptId: 1, }, id: 2, }, state: C_COMPLETE, diagnostics: "Container killed by the ApplicationMaster.\n\n", exit_status: 143, ] resource=<memory:1024, vCores:1> queue=default: capacity=1.0, absoluteCapacity=1.0, usedResources=<memory:3072, vCores:2>usedCapacity=0.0625, absoluteUsedCapacity=0.0625, numApps=1, numContainers=2 usedCapacity=0.0625 absoluteUsedCapacity=0.0625 used=<memory:3072, vCores:2> cluster=<memory:49152, vCores:96>
2013-08-10 05:23:19,969 INFO org.apache.hadoop.yarn.server.resourcemanager.scheduler.capacity.ParentQueue: completedContainer queue=root usedCapacity=0.0625 absoluteUsedCapacity=0.0625 used=<memory:3072, vCores:2> cluster=<memory:49152, vCores:96>
2013-08-10 05:23:19,969 INFO org.apache.hadoop.yarn.server.resourcemanager.scheduler.capacity.CapacityScheduler: Application appattempt_1376111601621_0003_000001 released container container_1376111601621_0003_01_000002 on node: host: hadoop-221-6:57712 #containers=0 available=8192 used=0 with event: FINISHED
2013-08-10 05:23:25,496 INFO org.apache.hadoop.yarn.server.resourcemanager.rmcontainer.RMContainerImpl: container_1376111601621_0003_01_000003 Container Transitioned from RUNNING to COMPLETED
2013-08-10 05:23:25,496 INFO org.apache.hadoop.yarn.server.resourcemanager.scheduler.common.fica.FiCaSchedulerApp: Completed container: container_1376111601621_0003_01_000003 in state: COMPLETED event:FINISHED
2013-08-10 05:23:25,496 INFO org.apache.hadoop.yarn.server.resourcemanager.RMAuditLogger: USER=ubuntu	OPERATION=AM Released Container	TARGET=SchedulerApp	RESULT=SUCCESS	APPID=application_1376111601621_0003	CONTAINERID=container_1376111601621_0003_01_000003
2013-08-10 05:23:25,497 INFO org.apache.hadoop.yarn.server.resourcemanager.scheduler.common.fica.FiCaSchedulerNode: Released container container_1376111601621_0003_01_000003 of capacity <memory:1024, vCores:1> on host hadoop-221-2:55267, which currently has 0 containers, <memory:0, vCores:0> used and <memory:8192, vCores:16> available, release resources=true
2013-08-10 05:23:25,497 INFO org.apache.hadoop.yarn.server.resourcemanager.scheduler.capacity.LeafQueue: default used=<memory:2048, vCores:1> numContainers=1 user=ubuntu user-resources=<memory:2048, vCores:1>
2013-08-10 05:23:25,499 INFO org.apache.hadoop.yarn.server.resourcemanager.scheduler.capacity.LeafQueue: completedContainer container=Container: [ContainerId: container_1376111601621_0003_01_000003, NodeId: hadoop-221-2:55267, NodeHttpAddress: hadoop-221-2:8042, Resource: <memory:1024, vCores:1>, Priority: 20, State: NEW, Token: null, Status: container_id {, app_attempt_id {, application_id {, id: 3, cluster_timestamp: 1376111601621, }, attemptId: 1, }, id: 3, }, state: C_COMPLETE, diagnostics: "Container killed by the ApplicationMaster.\n\n", exit_status: 143, ] resource=<memory:1024, vCores:1> queue=default: capacity=1.0, absoluteCapacity=1.0, usedResources=<memory:2048, vCores:1>usedCapacity=0.041666668, absoluteUsedCapacity=0.041666668, numApps=1, numContainers=1 usedCapacity=0.041666668 absoluteUsedCapacity=0.041666668 used=<memory:2048, vCores:1> cluster=<memory:49152, vCores:96>
2013-08-10 05:23:25,499 INFO org.apache.hadoop.yarn.server.resourcemanager.scheduler.capacity.ParentQueue: completedContainer queue=root usedCapacity=0.041666668 absoluteUsedCapacity=0.041666668 used=<memory:2048, vCores:1> cluster=<memory:49152, vCores:96>
2013-08-10 05:23:25,499 INFO org.apache.hadoop.yarn.server.resourcemanager.scheduler.capacity.CapacityScheduler: Application appattempt_1376111601621_0003_000001 released container container_1376111601621_0003_01_000003 on node: host: hadoop-221-2:55267 #containers=0 available=8192 used=0 with event: FINISHED
2013-08-10 05:23:30,513 INFO org.apache.hadoop.yarn.server.resourcemanager.rmapp.attempt.RMAppAttemptImpl: appattempt_1376111601621_0003_000001 State change from RUNNING to FINISHING
2013-08-10 05:23:30,515 INFO org.apache.hadoop.yarn.server.resourcemanager.rmapp.RMAppImpl: application_1376111601621_0003 State change from RUNNING to FINISHING
2013-08-10 05:23:30,551 INFO org.apache.hadoop.yarn.server.resourcemanager.ClientRMService: Allocated new applicationId: 4
2013-08-10 05:23:30,905 INFO org.apache.hadoop.yarn.server.resourcemanager.rmcontainer.RMContainerImpl: container_1376111601621_0003_01_000001 Container Transitioned from RUNNING to COMPLETED
2013-08-10 05:23:30,905 INFO org.apache.hadoop.yarn.server.resourcemanager.scheduler.common.fica.FiCaSchedulerApp: Completed container: container_1376111601621_0003_01_000001 in state: COMPLETED event:FINISHED
2013-08-10 05:23:30,906 INFO org.apache.hadoop.yarn.server.resourcemanager.rmapp.attempt.RMAppAttemptImpl: appattempt_1376111601621_0003_000001 State change from FINISHING to FINISHED
2013-08-10 05:23:30,906 INFO org.apache.hadoop.yarn.server.resourcemanager.RMAuditLogger: USER=ubuntu	OPERATION=AM Released Container	TARGET=SchedulerApp	RESULT=SUCCESS	APPID=application_1376111601621_0003	CONTAINERID=container_1376111601621_0003_01_000001
2013-08-10 05:23:30,906 INFO org.apache.hadoop.yarn.server.resourcemanager.rmapp.RMAppImpl: application_1376111601621_0003 State change from FINISHING to FINISHED
2013-08-10 05:23:30,906 INFO org.apache.hadoop.yarn.server.resourcemanager.scheduler.common.fica.FiCaSchedulerNode: Released container container_1376111601621_0003_01_000001 of capacity <memory:2048, vCores:1> on host hadoop-221-7:34609, which currently has 0 containers, <memory:0, vCores:0> used and <memory:8192, vCores:16> available, release resources=true
2013-08-10 05:23:30,906 INFO org.apache.hadoop.yarn.server.resourcemanager.scheduler.capacity.LeafQueue: default used=<memory:0, vCores:0> numContainers=0 user=ubuntu user-resources=<memory:0, vCores:0>
2013-08-10 05:23:30,908 INFO org.apache.hadoop.yarn.server.resourcemanager.scheduler.capacity.LeafQueue: completedContainer container=Container: [ContainerId: container_1376111601621_0003_01_000001, NodeId: hadoop-221-7:34609, NodeHttpAddress: hadoop-221-7:8042, Resource: <memory:2048, vCores:1>, Priority: 0, State: NEW, Token: null, Status: container_id {, app_attempt_id {, application_id {, id: 3, cluster_timestamp: 1376111601621, }, attemptId: 1, }, id: 1, }, state: C_COMPLETE, diagnostics: "", exit_status: 0, ] resource=<memory:2048, vCores:1> queue=default: capacity=1.0, absoluteCapacity=1.0, usedResources=<memory:0, vCores:0>usedCapacity=0.0, absoluteUsedCapacity=0.0, numApps=1, numContainers=0 usedCapacity=0.0 absoluteUsedCapacity=0.0 used=<memory:0, vCores:0> cluster=<memory:49152, vCores:96>
2013-08-10 05:23:30,908 INFO org.apache.hadoop.yarn.server.resourcemanager.scheduler.capacity.ParentQueue: completedContainer queue=root usedCapacity=0.0 absoluteUsedCapacity=0.0 used=<memory:0, vCores:0> cluster=<memory:49152, vCores:96>
2013-08-10 05:23:30,908 INFO org.apache.hadoop.yarn.server.resourcemanager.scheduler.capacity.CapacityScheduler: Application appattempt_1376111601621_0003_000001 released container container_1376111601621_0003_01_000001 on node: host: hadoop-221-7:34609 #containers=0 available=8192 used=0 with event: FINISHED
2013-08-10 05:23:30,908 INFO org.apache.hadoop.yarn.server.resourcemanager.scheduler.capacity.CapacityScheduler: Application appattempt_1376111601621_0003_000001 is done. finalState=FINISHED
2013-08-10 05:23:30,909 INFO org.apache.hadoop.yarn.server.resourcemanager.scheduler.AppSchedulingInfo: Application application_1376111601621_0003 requests cleared
2013-08-10 05:23:30,909 INFO org.apache.hadoop.yarn.server.resourcemanager.scheduler.capacity.LeafQueue: Application removed - appId: application_1376111601621_0003 user: ubuntu queue: default #user-pending-applications: 0 #user-active-applications: 0 #queue-pending-applications: 0 #queue-active-applications: 0
2013-08-10 05:23:30,909 INFO org.apache.hadoop.yarn.server.resourcemanager.scheduler.capacity.ParentQueue: Application removed - appId: application_1376111601621_0003 user: ubuntu leaf-queue of parent: root #applications: 0
2013-08-10 05:23:30,909 INFO org.apache.hadoop.yarn.server.resourcemanager.RMAuditLogger: USER=ubuntu	OPERATION=Application Finished - Succeeded	TARGET=RMAppManager	RESULT=SUCCESS	APPID=application_1376111601621_0003
2013-08-10 05:23:30,910 INFO org.apache.hadoop.yarn.server.resourcemanager.RMAppManager$ApplicationSummary: appId=application_1376111601621_0003,name=TeraGen,user=ubuntu,queue=default,state=FINISHED,trackingUrl=hadoop-221-1.novalocal:8088/proxy/application_1376111601621_0003/jobhistory/job/job_1376111601621_0003,appMasterHost=hadoop-221-7,startTime=1376112016347,finishTime=1376112210515
2013-08-10 05:23:30,910 INFO org.apache.hadoop.yarn.server.resourcemanager.amlauncher.AMLauncher: Cleaning master appattempt_1376111601621_0003_000001
2013-08-10 05:23:30,910 INFO org.apache.hadoop.yarn.server.resourcemanager.recovery.RMStateStore: Removing info for app: application_1376111601621_0003
2013-08-10 05:23:32,461 INFO org.apache.hadoop.yarn.server.resourcemanager.ClientRMService: Storing Application with id application_1376111601621_0004
2013-08-10 05:23:32,461 INFO org.apache.hadoop.yarn.server.resourcemanager.recovery.RMStateStore: Storing info for app: application_1376111601621_0004
2013-08-10 05:23:32,461 INFO org.apache.hadoop.yarn.server.resourcemanager.ClientRMService: Application with id 4 submitted by user ubuntu
2013-08-10 05:23:32,461 INFO org.apache.hadoop.yarn.server.resourcemanager.RMAuditLogger: USER=ubuntu	IP=192.168.100.36	OPERATION=Submit Application Request	TARGET=ClientRMService	RESULT=SUCCESS	APPID=application_1376111601621_0004
2013-08-10 05:23:32,463 INFO org.apache.hadoop.yarn.server.resourcemanager.rmapp.RMAppImpl: application_1376111601621_0004 State change from NEW to SUBMITTED
2013-08-10 05:23:32,463 INFO org.apache.hadoop.yarn.server.resourcemanager.ApplicationMasterService: Registering appattempt_1376111601621_0004_000001
2013-08-10 05:23:32,464 INFO org.apache.hadoop.yarn.server.resourcemanager.rmapp.attempt.RMAppAttemptImpl: appattempt_1376111601621_0004_000001 State change from NEW to SUBMITTED
2013-08-10 05:23:32,464 INFO org.apache.hadoop.yarn.server.resourcemanager.scheduler.capacity.LeafQueue: Application application_1376111601621_0004 from user: ubuntu activated in queue: default
2013-08-10 05:23:32,464 INFO org.apache.hadoop.yarn.server.resourcemanager.scheduler.capacity.LeafQueue: Application added - appId: application_1376111601621_0004 user: org.apache.hadoop.yarn.server.resourcemanager.scheduler.capacity.LeafQueue$User@2aec4bcb, leaf-queue: default #user-pending-applications: 0 #user-active-applications: 1 #queue-pending-applications: 0 #queue-active-applications: 1
2013-08-10 05:23:32,464 INFO org.apache.hadoop.yarn.server.resourcemanager.scheduler.capacity.ParentQueue: Application added - appId: application_1376111601621_0004 user: ubuntu leaf-queue of parent: root #applications: 1
2013-08-10 05:23:32,465 INFO org.apache.hadoop.yarn.server.resourcemanager.scheduler.capacity.CapacityScheduler: Application Submission: appattempt_1376111601621_0004_000001, user: ubuntu queue: default: capacity=1.0, absoluteCapacity=1.0, usedResources=<memory:0, vCores:0>usedCapacity=0.0, absoluteUsedCapacity=0.0, numApps=1, numContainers=0, currently active: 1
2013-08-10 05:23:32,465 INFO org.apache.hadoop.yarn.server.resourcemanager.rmapp.attempt.RMAppAttemptImpl: appattempt_1376111601621_0004_000001 State change from SUBMITTED to SCHEDULED
2013-08-10 05:23:32,465 INFO org.apache.hadoop.yarn.server.resourcemanager.rmapp.RMAppImpl: application_1376111601621_0004 State change from SUBMITTED to ACCEPTED
2013-08-10 05:23:32,481 INFO org.apache.hadoop.yarn.server.resourcemanager.rmcontainer.RMContainerImpl: container_1376111601621_0004_01_000001 Container Transitioned from NEW to ALLOCATED
2013-08-10 05:23:32,482 INFO org.apache.hadoop.yarn.server.resourcemanager.RMAuditLogger: USER=ubuntu	OPERATION=AM Allocated Container	TARGET=SchedulerApp	RESULT=SUCCESS	APPID=application_1376111601621_0004	CONTAINERID=container_1376111601621_0004_01_000001
2013-08-10 05:23:32,482 INFO org.apache.hadoop.yarn.server.resourcemanager.scheduler.common.fica.FiCaSchedulerNode: Assigned container container_1376111601621_0004_01_000001 of capacity <memory:2048, vCores:1> on host hadoop-221-4:41177, which currently has 1 containers, <memory:2048, vCores:1> used and <memory:6144, vCores:15> available
2013-08-10 05:23:32,483 INFO org.apache.hadoop.yarn.server.resourcemanager.scheduler.capacity.LeafQueue: assignedContainer application=application_1376111601621_0004 container=Container: [ContainerId: container_1376111601621_0004_01_000001, NodeId: hadoop-221-4:41177, NodeHttpAddress: hadoop-221-4:8042, Resource: <memory:2048, vCores:1>, Priority: 0, State: NEW, Token: null, Status: container_id {, app_attempt_id {, application_id {, id: 4, cluster_timestamp: 1376111601621, }, attemptId: 1, }, id: 1, }, state: C_NEW, ] containerId=container_1376111601621_0004_01_000001 queue=default: capacity=1.0, absoluteCapacity=1.0, usedResources=<memory:0, vCores:0>usedCapacity=0.0, absoluteUsedCapacity=0.0, numApps=1, numContainers=0 usedCapacity=0.0 absoluteUsedCapacity=0.0 used=<memory:0, vCores:0> cluster=<memory:49152, vCores:96>
2013-08-10 05:23:32,483 INFO org.apache.hadoop.yarn.server.resourcemanager.scheduler.capacity.ParentQueue: Re-sorting queues since queue: root.default stats: default: capacity=1.0, absoluteCapacity=1.0, usedResources=<memory:2048, vCores:1>usedCapacity=0.041666668, absoluteUsedCapacity=0.041666668, numApps=1, numContainers=1
2013-08-10 05:23:32,484 INFO org.apache.hadoop.yarn.server.resourcemanager.scheduler.capacity.ParentQueue: assignedContainer queue=root usedCapacity=0.041666668 absoluteUsedCapacity=0.041666668 used=<memory:2048, vCores:1> cluster=<memory:49152, vCores:96>
2013-08-10 05:23:32,485 INFO org.apache.hadoop.yarn.server.resourcemanager.rmcontainer.RMContainerImpl: container_1376111601621_0004_01_000001 Container Transitioned from ALLOCATED to ACQUIRED
2013-08-10 05:23:32,486 INFO org.apache.hadoop.yarn.server.resourcemanager.rmapp.attempt.RMAppAttemptImpl: Storing attempt: AppId: application_1376111601621_0004 AttemptId: appattempt_1376111601621_0004_000001 MasterContainer: Container: [ContainerId: container_1376111601621_0004_01_000001, NodeId: hadoop-221-4:41177, NodeHttpAddress: hadoop-221-4:8042, Resource: <memory:2048, vCores:1>, Priority: 0, State: NEW, Token: null, Status: container_id {, app_attempt_id {, application_id {, id: 4, cluster_timestamp: 1376111601621, }, attemptId: 1, }, id: 1, }, state: C_NEW, ]
2013-08-10 05:23:32,487 INFO org.apache.hadoop.yarn.server.resourcemanager.recovery.RMStateStore: Storing info for attempt: appattempt_1376111601621_0004_000001
2013-08-10 05:23:32,487 INFO org.apache.hadoop.yarn.server.resourcemanager.rmapp.attempt.RMAppAttemptImpl: appattempt_1376111601621_0004_000001 State change from SCHEDULED to ALLOCATED_SAVING
2013-08-10 05:23:32,489 INFO org.apache.hadoop.yarn.server.resourcemanager.rmapp.attempt.RMAppAttemptImpl: appattempt_1376111601621_0004_000001 State change from ALLOCATED_SAVING to ALLOCATED
2013-08-10 05:23:32,490 INFO org.apache.hadoop.yarn.server.resourcemanager.amlauncher.AMLauncher: Launching masterappattempt_1376111601621_0004_000001
2013-08-10 05:23:32,493 INFO org.apache.hadoop.yarn.server.resourcemanager.amlauncher.AMLauncher: Setting up container Container: [ContainerId: container_1376111601621_0004_01_000001, NodeId: hadoop-221-4:41177, NodeHttpAddress: hadoop-221-4:8042, Resource: <memory:2048, vCores:1>, Priority: 0, State: NEW, Token: null, Status: container_id {, app_attempt_id {, application_id {, id: 4, cluster_timestamp: 1376111601621, }, attemptId: 1, }, id: 1, }, state: C_NEW, ] for AM appattempt_1376111601621_0004_000001
2013-08-10 05:23:32,493 INFO org.apache.hadoop.yarn.server.resourcemanager.amlauncher.AMLauncher: Command to launch container container_1376111601621_0004_01_000001 : $JAVA_HOME/bin/java -Dlog4j.configuration=container-log4j.properties -Dyarn.app.mapreduce.container.log.dir=<LOG_DIR> -Dyarn.app.mapreduce.container.log.filesize=0 -Dhadoop.root.logger=INFO,CLA  -Xmx1024m org.apache.hadoop.mapreduce.v2.app.MRAppMaster 1><LOG_DIR>/stdout 2><LOG_DIR>/stderr 
2013-08-10 05:23:32,509 INFO org.apache.hadoop.yarn.server.resourcemanager.amlauncher.AMLauncher: Done launching container Container: [ContainerId: container_1376111601621_0004_01_000001, NodeId: hadoop-221-4:41177, NodeHttpAddress: hadoop-221-4:8042, Resource: <memory:2048, vCores:1>, Priority: 0, State: NEW, Token: null, Status: container_id {, app_attempt_id {, application_id {, id: 4, cluster_timestamp: 1376111601621, }, attemptId: 1, }, id: 1, }, state: C_NEW, ] for AM appattempt_1376111601621_0004_000001
2013-08-10 05:23:32,509 INFO org.apache.hadoop.yarn.server.resourcemanager.rmapp.attempt.RMAppAttemptImpl: appattempt_1376111601621_0004_000001 State change from ALLOCATED to LAUNCHED
2013-08-10 05:23:33,488 INFO org.apache.hadoop.yarn.server.resourcemanager.rmcontainer.RMContainerImpl: container_1376111601621_0004_01_000001 Container Transitioned from ACQUIRED to RUNNING
2013-08-10 05:23:40,640 INFO org.apache.hadoop.yarn.server.resourcemanager.ApplicationMasterService: AM registration appattempt_1376111601621_0004_000001
2013-08-10 05:23:40,641 INFO org.apache.hadoop.yarn.server.resourcemanager.RMAuditLogger: USER=ubuntu	IP=192.168.100.38	OPERATION=Register App Master	TARGET=ApplicationMasterService	RESULT=SUCCESS	APPID=application_1376111601621_0004	APPATTEMPTID=appattempt_1376111601621_0004_000001
2013-08-10 05:23:40,641 INFO org.apache.hadoop.yarn.server.resourcemanager.rmapp.attempt.RMAppAttemptImpl: appattempt_1376111601621_0004_000001 State change from LAUNCHED to RUNNING
2013-08-10 05:23:40,641 INFO org.apache.hadoop.yarn.server.resourcemanager.rmapp.RMAppImpl: application_1376111601621_0004 State change from ACCEPTED to RUNNING
2013-08-10 05:23:41,946 INFO org.apache.hadoop.yarn.server.resourcemanager.rmcontainer.RMContainerImpl: container_1376111601621_0004_01_000002 Container Transitioned from NEW to ALLOCATED
2013-08-10 05:23:41,947 INFO org.apache.hadoop.yarn.server.resourcemanager.RMAuditLogger: USER=ubuntu	OPERATION=AM Allocated Container	TARGET=SchedulerApp	RESULT=SUCCESS	APPID=application_1376111601621_0004	CONTAINERID=container_1376111601621_0004_01_000002
2013-08-10 05:23:41,947 INFO org.apache.hadoop.yarn.server.resourcemanager.scheduler.common.fica.FiCaSchedulerNode: Assigned container container_1376111601621_0004_01_000002 of capacity <memory:1024, vCores:1> on host hadoop-221-7:34609, which currently has 1 containers, <memory:1024, vCores:1> used and <memory:7168, vCores:15> available
2013-08-10 05:23:41,948 INFO org.apache.hadoop.yarn.server.resourcemanager.scheduler.capacity.LeafQueue: assignedContainer application=application_1376111601621_0004 container=Container: [ContainerId: container_1376111601621_0004_01_000002, NodeId: hadoop-221-7:34609, NodeHttpAddress: hadoop-221-7:8042, Resource: <memory:1024, vCores:1>, Priority: 20, State: NEW, Token: null, Status: container_id {, app_attempt_id {, application_id {, id: 4, cluster_timestamp: 1376111601621, }, attemptId: 1, }, id: 2, }, state: C_NEW, ] containerId=container_1376111601621_0004_01_000002 queue=default: capacity=1.0, absoluteCapacity=1.0, usedResources=<memory:2048, vCores:1>usedCapacity=0.041666668, absoluteUsedCapacity=0.041666668, numApps=1, numContainers=1 usedCapacity=0.041666668 absoluteUsedCapacity=0.041666668 used=<memory:2048, vCores:1> cluster=<memory:49152, vCores:96>
2013-08-10 05:23:41,948 INFO org.apache.hadoop.yarn.server.resourcemanager.scheduler.capacity.ParentQueue: Re-sorting queues since queue: root.default stats: default: capacity=1.0, absoluteCapacity=1.0, usedResources=<memory:3072, vCores:2>usedCapacity=0.0625, absoluteUsedCapacity=0.0625, numApps=1, numContainers=2
2013-08-10 05:23:41,949 INFO org.apache.hadoop.yarn.server.resourcemanager.scheduler.capacity.ParentQueue: assignedContainer queue=root usedCapacity=0.0625 absoluteUsedCapacity=0.0625 used=<memory:3072, vCores:2> cluster=<memory:49152, vCores:96>
2013-08-10 05:23:42,034 INFO org.apache.hadoop.yarn.server.resourcemanager.rmcontainer.RMContainerImpl: container_1376111601621_0004_01_000003 Container Transitioned from NEW to ALLOCATED
2013-08-10 05:23:42,034 INFO org.apache.hadoop.yarn.server.resourcemanager.RMAuditLogger: USER=ubuntu	OPERATION=AM Allocated Container	TARGET=SchedulerApp	RESULT=SUCCESS	APPID=application_1376111601621_0004	CONTAINERID=container_1376111601621_0004_01_000003
2013-08-10 05:23:42,034 INFO org.apache.hadoop.yarn.server.resourcemanager.scheduler.common.fica.FiCaSchedulerNode: Assigned container container_1376111601621_0004_01_000003 of capacity <memory:1024, vCores:1> on host hadoop-221-6:57712, which currently has 1 containers, <memory:1024, vCores:1> used and <memory:7168, vCores:15> available
2013-08-10 05:23:42,035 INFO org.apache.hadoop.yarn.server.resourcemanager.scheduler.capacity.LeafQueue: assignedContainer application=application_1376111601621_0004 container=Container: [ContainerId: container_1376111601621_0004_01_000003, NodeId: hadoop-221-6:57712, NodeHttpAddress: hadoop-221-6:8042, Resource: <memory:1024, vCores:1>, Priority: 20, State: NEW, Token: null, Status: container_id {, app_attempt_id {, application_id {, id: 4, cluster_timestamp: 1376111601621, }, attemptId: 1, }, id: 3, }, state: C_NEW, ] containerId=container_1376111601621_0004_01_000003 queue=default: capacity=1.0, absoluteCapacity=1.0, usedResources=<memory:3072, vCores:2>usedCapacity=0.0625, absoluteUsedCapacity=0.0625, numApps=1, numContainers=2 usedCapacity=0.0625 absoluteUsedCapacity=0.0625 used=<memory:3072, vCores:2> cluster=<memory:49152, vCores:96>
2013-08-10 05:23:42,036 INFO org.apache.hadoop.yarn.server.resourcemanager.scheduler.capacity.ParentQueue: Re-sorting queues since queue: root.default stats: default: capacity=1.0, absoluteCapacity=1.0, usedResources=<memory:4096, vCores:3>usedCapacity=0.083333336, absoluteUsedCapacity=0.083333336, numApps=1, numContainers=3
2013-08-10 05:23:42,036 INFO org.apache.hadoop.yarn.server.resourcemanager.scheduler.capacity.ParentQueue: assignedContainer queue=root usedCapacity=0.083333336 absoluteUsedCapacity=0.083333336 used=<memory:4096, vCores:3> cluster=<memory:49152, vCores:96>
2013-08-10 05:23:42,714 INFO org.apache.hadoop.yarn.server.resourcemanager.rmcontainer.RMContainerImpl: container_1376111601621_0004_01_000002 Container Transitioned from ALLOCATED to ACQUIRED
2013-08-10 05:23:42,716 INFO org.apache.hadoop.yarn.server.resourcemanager.rmcontainer.RMContainerImpl: container_1376111601621_0004_01_000003 Container Transitioned from ALLOCATED to ACQUIRED
2013-08-10 05:23:43,039 INFO org.apache.hadoop.yarn.server.resourcemanager.rmcontainer.RMContainerImpl: container_1376111601621_0004_01_000003 Container Transitioned from ACQUIRED to RUNNING
2013-08-10 05:23:43,746 INFO org.apache.hadoop.yarn.server.resourcemanager.scheduler.AppSchedulingInfo: checking for deactivate... 
2013-08-10 05:23:43,956 INFO org.apache.hadoop.yarn.server.resourcemanager.rmcontainer.RMContainerImpl: container_1376111601621_0004_01_000002 Container Transitioned from ACQUIRED to RUNNING
2013-08-10 05:26:37,930 INFO org.apache.hadoop.yarn.server.resourcemanager.rmcontainer.RMContainerImpl: container_1376111601621_0004_01_000002 Container Transitioned from RUNNING to COMPLETED
2013-08-10 05:26:37,930 INFO org.apache.hadoop.yarn.server.resourcemanager.scheduler.common.fica.FiCaSchedulerApp: Completed container: container_1376111601621_0004_01_000002 in state: COMPLETED event:FINISHED
2013-08-10 05:26:37,930 INFO org.apache.hadoop.yarn.server.resourcemanager.RMAuditLogger: USER=ubuntu	OPERATION=AM Released Container	TARGET=SchedulerApp	RESULT=SUCCESS	APPID=application_1376111601621_0004	CONTAINERID=container_1376111601621_0004_01_000002
2013-08-10 05:26:37,931 INFO org.apache.hadoop.yarn.server.resourcemanager.scheduler.common.fica.FiCaSchedulerNode: Released container container_1376111601621_0004_01_000002 of capacity <memory:1024, vCores:1> on host hadoop-221-7:34609, which currently has 0 containers, <memory:0, vCores:0> used and <memory:8192, vCores:16> available, release resources=true
2013-08-10 05:26:37,931 INFO org.apache.hadoop.yarn.server.resourcemanager.scheduler.capacity.LeafQueue: default used=<memory:3072, vCores:2> numContainers=2 user=ubuntu user-resources=<memory:3072, vCores:2>
2013-08-10 05:26:37,932 INFO org.apache.hadoop.yarn.server.resourcemanager.scheduler.capacity.LeafQueue: completedContainer container=Container: [ContainerId: container_1376111601621_0004_01_000002, NodeId: hadoop-221-7:34609, NodeHttpAddress: hadoop-221-7:8042, Resource: <memory:1024, vCores:1>, Priority: 20, State: NEW, Token: null, Status: container_id {, app_attempt_id {, application_id {, id: 4, cluster_timestamp: 1376111601621, }, attemptId: 1, }, id: 2, }, state: C_COMPLETE, diagnostics: "Container killed by the ApplicationMaster.\n\n", exit_status: 143, ] resource=<memory:1024, vCores:1> queue=default: capacity=1.0, absoluteCapacity=1.0, usedResources=<memory:3072, vCores:2>usedCapacity=0.0625, absoluteUsedCapacity=0.0625, numApps=1, numContainers=2 usedCapacity=0.0625 absoluteUsedCapacity=0.0625 used=<memory:3072, vCores:2> cluster=<memory:49152, vCores:96>
2013-08-10 05:26:37,933 INFO org.apache.hadoop.yarn.server.resourcemanager.scheduler.capacity.ParentQueue: completedContainer queue=root usedCapacity=0.0625 absoluteUsedCapacity=0.0625 used=<memory:3072, vCores:2> cluster=<memory:49152, vCores:96>
2013-08-10 05:26:37,933 INFO org.apache.hadoop.yarn.server.resourcemanager.scheduler.capacity.CapacityScheduler: Application appattempt_1376111601621_0004_000001 released container container_1376111601621_0004_01_000002 on node: host: hadoop-221-7:34609 #containers=0 available=8192 used=0 with event: FINISHED
2013-08-10 05:26:38,746 INFO org.apache.hadoop.yarn.server.resourcemanager.rmcontainer.RMContainerImpl: container_1376111601621_0004_01_000003 Container Transitioned from RUNNING to COMPLETED
2013-08-10 05:26:38,746 INFO org.apache.hadoop.yarn.server.resourcemanager.scheduler.common.fica.FiCaSchedulerApp: Completed container: container_1376111601621_0004_01_000003 in state: COMPLETED event:FINISHED
2013-08-10 05:26:38,746 INFO org.apache.hadoop.yarn.server.resourcemanager.RMAuditLogger: USER=ubuntu	OPERATION=AM Released Container	TARGET=SchedulerApp	RESULT=SUCCESS	APPID=application_1376111601621_0004	CONTAINERID=container_1376111601621_0004_01_000003
2013-08-10 05:26:38,747 INFO org.apache.hadoop.yarn.server.resourcemanager.scheduler.common.fica.FiCaSchedulerNode: Released container container_1376111601621_0004_01_000003 of capacity <memory:1024, vCores:1> on host hadoop-221-6:57712, which currently has 0 containers, <memory:0, vCores:0> used and <memory:8192, vCores:16> available, release resources=true
2013-08-10 05:26:38,747 INFO org.apache.hadoop.yarn.server.resourcemanager.scheduler.capacity.LeafQueue: default used=<memory:2048, vCores:1> numContainers=1 user=ubuntu user-resources=<memory:2048, vCores:1>
2013-08-10 05:26:38,748 INFO org.apache.hadoop.yarn.server.resourcemanager.scheduler.capacity.LeafQueue: completedContainer container=Container: [ContainerId: container_1376111601621_0004_01_000003, NodeId: hadoop-221-6:57712, NodeHttpAddress: hadoop-221-6:8042, Resource: <memory:1024, vCores:1>, Priority: 20, State: NEW, Token: null, Status: container_id {, app_attempt_id {, application_id {, id: 4, cluster_timestamp: 1376111601621, }, attemptId: 1, }, id: 3, }, state: C_COMPLETE, diagnostics: "Container killed by the ApplicationMaster.\n\n", exit_status: 143, ] resource=<memory:1024, vCores:1> queue=default: capacity=1.0, absoluteCapacity=1.0, usedResources=<memory:2048, vCores:1>usedCapacity=0.041666668, absoluteUsedCapacity=0.041666668, numApps=1, numContainers=1 usedCapacity=0.041666668 absoluteUsedCapacity=0.041666668 used=<memory:2048, vCores:1> cluster=<memory:49152, vCores:96>
2013-08-10 05:26:38,749 INFO org.apache.hadoop.yarn.server.resourcemanager.scheduler.capacity.ParentQueue: completedContainer queue=root usedCapacity=0.041666668 absoluteUsedCapacity=0.041666668 used=<memory:2048, vCores:1> cluster=<memory:49152, vCores:96>
2013-08-10 05:26:38,749 INFO org.apache.hadoop.yarn.server.resourcemanager.scheduler.capacity.CapacityScheduler: Application appattempt_1376111601621_0004_000001 released container container_1376111601621_0004_01_000003 on node: host: hadoop-221-6:57712 #containers=0 available=8192 used=0 with event: FINISHED
2013-08-10 05:26:42,900 INFO org.apache.hadoop.yarn.server.resourcemanager.rmapp.attempt.RMAppAttemptImpl: appattempt_1376111601621_0004_000001 State change from RUNNING to FINISHING
2013-08-10 05:26:42,901 INFO org.apache.hadoop.yarn.server.resourcemanager.rmapp.RMAppImpl: application_1376111601621_0004 State change from RUNNING to FINISHING
2013-08-10 05:26:43,680 INFO org.apache.hadoop.yarn.server.resourcemanager.rmcontainer.RMContainerImpl: container_1376111601621_0004_01_000001 Container Transitioned from RUNNING to COMPLETED
2013-08-10 05:26:43,680 INFO org.apache.hadoop.yarn.server.resourcemanager.scheduler.common.fica.FiCaSchedulerApp: Completed container: container_1376111601621_0004_01_000001 in state: COMPLETED event:FINISHED
2013-08-10 05:26:43,680 INFO org.apache.hadoop.yarn.server.resourcemanager.RMAuditLogger: USER=ubuntu	OPERATION=AM Released Container	TARGET=SchedulerApp	RESULT=SUCCESS	APPID=application_1376111601621_0004	CONTAINERID=container_1376111601621_0004_01_000001
2013-08-10 05:26:43,680 INFO org.apache.hadoop.yarn.server.resourcemanager.scheduler.common.fica.FiCaSchedulerNode: Released container container_1376111601621_0004_01_000001 of capacity <memory:2048, vCores:1> on host hadoop-221-4:41177, which currently has 0 containers, <memory:0, vCores:0> used and <memory:8192, vCores:16> available, release resources=true
2013-08-10 05:26:43,680 INFO org.apache.hadoop.yarn.server.resourcemanager.scheduler.capacity.LeafQueue: default used=<memory:0, vCores:0> numContainers=0 user=ubuntu user-resources=<memory:0, vCores:0>
2013-08-10 05:26:43,681 INFO org.apache.hadoop.yarn.server.resourcemanager.scheduler.capacity.LeafQueue: completedContainer container=Container: [ContainerId: container_1376111601621_0004_01_000001, NodeId: hadoop-221-4:41177, NodeHttpAddress: hadoop-221-4:8042, Resource: <memory:2048, vCores:1>, Priority: 0, State: NEW, Token: null, Status: container_id {, app_attempt_id {, application_id {, id: 4, cluster_timestamp: 1376111601621, }, attemptId: 1, }, id: 1, }, state: C_COMPLETE, diagnostics: "", exit_status: 0, ] resource=<memory:2048, vCores:1> queue=default: capacity=1.0, absoluteCapacity=1.0, usedResources=<memory:0, vCores:0>usedCapacity=0.0, absoluteUsedCapacity=0.0, numApps=1, numContainers=0 usedCapacity=0.0 absoluteUsedCapacity=0.0 used=<memory:0, vCores:0> cluster=<memory:49152, vCores:96>
2013-08-10 05:26:43,681 INFO org.apache.hadoop.yarn.server.resourcemanager.scheduler.capacity.ParentQueue: completedContainer queue=root usedCapacity=0.0 absoluteUsedCapacity=0.0 used=<memory:0, vCores:0> cluster=<memory:49152, vCores:96>
2013-08-10 05:26:43,681 INFO org.apache.hadoop.yarn.server.resourcemanager.scheduler.capacity.CapacityScheduler: Application appattempt_1376111601621_0004_000001 released container container_1376111601621_0004_01_000001 on node: host: hadoop-221-4:41177 #containers=0 available=8192 used=0 with event: FINISHED
2013-08-10 05:26:43,682 INFO org.apache.hadoop.yarn.server.resourcemanager.rmapp.attempt.RMAppAttemptImpl: appattempt_1376111601621_0004_000001 State change from FINISHING to FINISHED
2013-08-10 05:26:43,682 INFO org.apache.hadoop.yarn.server.resourcemanager.rmapp.RMAppImpl: application_1376111601621_0004 State change from FINISHING to FINISHED
2013-08-10 05:26:43,682 INFO org.apache.hadoop.yarn.server.resourcemanager.scheduler.capacity.CapacityScheduler: Application appattempt_1376111601621_0004_000001 is done. finalState=FINISHED
2013-08-10 05:26:43,682 INFO org.apache.hadoop.yarn.server.resourcemanager.scheduler.AppSchedulingInfo: Application application_1376111601621_0004 requests cleared
2013-08-10 05:26:43,682 INFO org.apache.hadoop.yarn.server.resourcemanager.scheduler.capacity.LeafQueue: Application removed - appId: application_1376111601621_0004 user: ubuntu queue: default #user-pending-applications: 0 #user-active-applications: 0 #queue-pending-applications: 0 #queue-active-applications: 0
2013-08-10 05:26:43,682 INFO org.apache.hadoop.yarn.server.resourcemanager.scheduler.capacity.ParentQueue: Application removed - appId: application_1376111601621_0004 user: ubuntu leaf-queue of parent: root #applications: 0
2013-08-10 05:26:43,683 INFO org.apache.hadoop.yarn.server.resourcemanager.RMAuditLogger: USER=ubuntu	OPERATION=Application Finished - Succeeded	TARGET=RMAppManager	RESULT=SUCCESS	APPID=application_1376111601621_0004
2013-08-10 05:26:43,683 INFO org.apache.hadoop.yarn.server.resourcemanager.recovery.RMStateStore: Removing info for app: application_1376111601621_0004
2013-08-10 05:26:43,683 INFO org.apache.hadoop.yarn.server.resourcemanager.RMAppManager$ApplicationSummary: appId=application_1376111601621_0004,name=TeraGen,user=ubuntu,queue=default,state=FINISHED,trackingUrl=hadoop-221-1.novalocal:8088/proxy/application_1376111601621_0004/jobhistory/job/job_1376111601621_0004,appMasterHost=hadoop-221-4,startTime=1376112212460,finishTime=1376112402901
2013-08-10 05:26:43,683 INFO org.apache.hadoop.yarn.server.resourcemanager.amlauncher.AMLauncher: Cleaning master appattempt_1376111601621_0004_000001
2013-08-10 05:26:44,215 INFO org.apache.hadoop.yarn.server.resourcemanager.ClientRMService: Allocated new applicationId: 5
2013-08-10 05:26:46,103 INFO org.apache.hadoop.yarn.server.resourcemanager.ClientRMService: Storing Application with id application_1376111601621_0005
2013-08-10 05:26:46,104 INFO org.apache.hadoop.yarn.server.resourcemanager.recovery.RMStateStore: Storing info for app: application_1376111601621_0005
2013-08-10 05:26:46,104 INFO org.apache.hadoop.yarn.server.resourcemanager.ClientRMService: Application with id 5 submitted by user ubuntu
2013-08-10 05:26:46,104 INFO org.apache.hadoop.yarn.server.resourcemanager.RMAuditLogger: USER=ubuntu	IP=192.168.100.36	OPERATION=Submit Application Request	TARGET=ClientRMService	RESULT=SUCCESS	APPID=application_1376111601621_0005
2013-08-10 05:26:46,104 INFO org.apache.hadoop.yarn.server.resourcemanager.rmapp.RMAppImpl: application_1376111601621_0005 State change from NEW to SUBMITTED
2013-08-10 05:26:46,105 INFO org.apache.hadoop.yarn.server.resourcemanager.ApplicationMasterService: Registering appattempt_1376111601621_0005_000001
2013-08-10 05:26:46,105 INFO org.apache.hadoop.yarn.server.resourcemanager.rmapp.attempt.RMAppAttemptImpl: appattempt_1376111601621_0005_000001 State change from NEW to SUBMITTED
2013-08-10 05:26:46,105 INFO org.apache.hadoop.yarn.server.resourcemanager.scheduler.capacity.LeafQueue: Application application_1376111601621_0005 from user: ubuntu activated in queue: default
2013-08-10 05:26:46,105 INFO org.apache.hadoop.yarn.server.resourcemanager.scheduler.capacity.LeafQueue: Application added - appId: application_1376111601621_0005 user: org.apache.hadoop.yarn.server.resourcemanager.scheduler.capacity.LeafQueue$User@5b5b6746, leaf-queue: default #user-pending-applications: 0 #user-active-applications: 1 #queue-pending-applications: 0 #queue-active-applications: 1
2013-08-10 05:26:46,105 INFO org.apache.hadoop.yarn.server.resourcemanager.scheduler.capacity.ParentQueue: Application added - appId: application_1376111601621_0005 user: ubuntu leaf-queue of parent: root #applications: 1
2013-08-10 05:26:46,106 INFO org.apache.hadoop.yarn.server.resourcemanager.scheduler.capacity.CapacityScheduler: Application Submission: appattempt_1376111601621_0005_000001, user: ubuntu queue: default: capacity=1.0, absoluteCapacity=1.0, usedResources=<memory:0, vCores:0>usedCapacity=0.0, absoluteUsedCapacity=0.0, numApps=1, numContainers=0, currently active: 1
2013-08-10 05:26:46,106 INFO org.apache.hadoop.yarn.server.resourcemanager.rmapp.attempt.RMAppAttemptImpl: appattempt_1376111601621_0005_000001 State change from SUBMITTED to SCHEDULED
2013-08-10 05:26:46,106 INFO org.apache.hadoop.yarn.server.resourcemanager.rmapp.RMAppImpl: application_1376111601621_0005 State change from SUBMITTED to ACCEPTED
2013-08-10 05:26:46,170 INFO org.apache.hadoop.yarn.server.resourcemanager.rmcontainer.RMContainerImpl: container_1376111601621_0005_01_000001 Container Transitioned from NEW to ALLOCATED
2013-08-10 05:26:46,171 INFO org.apache.hadoop.yarn.server.resourcemanager.RMAuditLogger: USER=ubuntu	OPERATION=AM Allocated Container	TARGET=SchedulerApp	RESULT=SUCCESS	APPID=application_1376111601621_0005	CONTAINERID=container_1376111601621_0005_01_000001
2013-08-10 05:26:46,171 INFO org.apache.hadoop.yarn.server.resourcemanager.scheduler.common.fica.FiCaSchedulerNode: Assigned container container_1376111601621_0005_01_000001 of capacity <memory:2048, vCores:1> on host hadoop-221-2:55267, which currently has 1 containers, <memory:2048, vCores:1> used and <memory:6144, vCores:15> available
2013-08-10 05:26:46,172 INFO org.apache.hadoop.yarn.server.resourcemanager.scheduler.capacity.LeafQueue: assignedContainer application=application_1376111601621_0005 container=Container: [ContainerId: container_1376111601621_0005_01_000001, NodeId: hadoop-221-2:55267, NodeHttpAddress: hadoop-221-2:8042, Resource: <memory:2048, vCores:1>, Priority: 0, State: NEW, Token: null, Status: container_id {, app_attempt_id {, application_id {, id: 5, cluster_timestamp: 1376111601621, }, attemptId: 1, }, id: 1, }, state: C_NEW, ] containerId=container_1376111601621_0005_01_000001 queue=default: capacity=1.0, absoluteCapacity=1.0, usedResources=<memory:0, vCores:0>usedCapacity=0.0, absoluteUsedCapacity=0.0, numApps=1, numContainers=0 usedCapacity=0.0 absoluteUsedCapacity=0.0 used=<memory:0, vCores:0> cluster=<memory:49152, vCores:96>
2013-08-10 05:26:46,172 INFO org.apache.hadoop.yarn.server.resourcemanager.scheduler.capacity.ParentQueue: Re-sorting queues since queue: root.default stats: default: capacity=1.0, absoluteCapacity=1.0, usedResources=<memory:2048, vCores:1>usedCapacity=0.041666668, absoluteUsedCapacity=0.041666668, numApps=1, numContainers=1
2013-08-10 05:26:46,173 INFO org.apache.hadoop.yarn.server.resourcemanager.scheduler.capacity.ParentQueue: assignedContainer queue=root usedCapacity=0.041666668 absoluteUsedCapacity=0.041666668 used=<memory:2048, vCores:1> cluster=<memory:49152, vCores:96>
2013-08-10 05:26:46,174 INFO org.apache.hadoop.yarn.server.resourcemanager.rmcontainer.RMContainerImpl: container_1376111601621_0005_01_000001 Container Transitioned from ALLOCATED to ACQUIRED
2013-08-10 05:26:46,176 INFO org.apache.hadoop.yarn.server.resourcemanager.rmapp.attempt.RMAppAttemptImpl: Storing attempt: AppId: application_1376111601621_0005 AttemptId: appattempt_1376111601621_0005_000001 MasterContainer: Container: [ContainerId: container_1376111601621_0005_01_000001, NodeId: hadoop-221-2:55267, NodeHttpAddress: hadoop-221-2:8042, Resource: <memory:2048, vCores:1>, Priority: 0, State: NEW, Token: null, Status: container_id {, app_attempt_id {, application_id {, id: 5, cluster_timestamp: 1376111601621, }, attemptId: 1, }, id: 1, }, state: C_NEW, ]
2013-08-10 05:26:46,176 INFO org.apache.hadoop.yarn.server.resourcemanager.rmapp.attempt.RMAppAttemptImpl: appattempt_1376111601621_0005_000001 State change from SCHEDULED to ALLOCATED_SAVING
2013-08-10 05:26:46,176 INFO org.apache.hadoop.yarn.server.resourcemanager.recovery.RMStateStore: Storing info for attempt: appattempt_1376111601621_0005_000001
2013-08-10 05:26:46,177 INFO org.apache.hadoop.yarn.server.resourcemanager.rmapp.attempt.RMAppAttemptImpl: appattempt_1376111601621_0005_000001 State change from ALLOCATED_SAVING to ALLOCATED
2013-08-10 05:26:46,179 INFO org.apache.hadoop.yarn.server.resourcemanager.amlauncher.AMLauncher: Launching masterappattempt_1376111601621_0005_000001
2013-08-10 05:26:46,181 INFO org.apache.hadoop.yarn.server.resourcemanager.amlauncher.AMLauncher: Setting up container Container: [ContainerId: container_1376111601621_0005_01_000001, NodeId: hadoop-221-2:55267, NodeHttpAddress: hadoop-221-2:8042, Resource: <memory:2048, vCores:1>, Priority: 0, State: NEW, Token: null, Status: container_id {, app_attempt_id {, application_id {, id: 5, cluster_timestamp: 1376111601621, }, attemptId: 1, }, id: 1, }, state: C_NEW, ] for AM appattempt_1376111601621_0005_000001
2013-08-10 05:26:46,181 INFO org.apache.hadoop.yarn.server.resourcemanager.amlauncher.AMLauncher: Command to launch container container_1376111601621_0005_01_000001 : $JAVA_HOME/bin/java -Dlog4j.configuration=container-log4j.properties -Dyarn.app.mapreduce.container.log.dir=<LOG_DIR> -Dyarn.app.mapreduce.container.log.filesize=0 -Dhadoop.root.logger=INFO,CLA  -Xmx1024m org.apache.hadoop.mapreduce.v2.app.MRAppMaster 1><LOG_DIR>/stdout 2><LOG_DIR>/stderr 
2013-08-10 05:26:46,205 INFO org.apache.hadoop.yarn.server.resourcemanager.amlauncher.AMLauncher: Done launching container Container: [ContainerId: container_1376111601621_0005_01_000001, NodeId: hadoop-221-2:55267, NodeHttpAddress: hadoop-221-2:8042, Resource: <memory:2048, vCores:1>, Priority: 0, State: NEW, Token: null, Status: container_id {, app_attempt_id {, application_id {, id: 5, cluster_timestamp: 1376111601621, }, attemptId: 1, }, id: 1, }, state: C_NEW, ] for AM appattempt_1376111601621_0005_000001
2013-08-10 05:26:46,206 INFO org.apache.hadoop.yarn.server.resourcemanager.rmapp.attempt.RMAppAttemptImpl: appattempt_1376111601621_0005_000001 State change from ALLOCATED to LAUNCHED
2013-08-10 05:26:47,177 INFO org.apache.hadoop.yarn.server.resourcemanager.rmcontainer.RMContainerImpl: container_1376111601621_0005_01_000001 Container Transitioned from ACQUIRED to RUNNING
2013-08-10 05:26:53,448 INFO org.apache.hadoop.yarn.server.resourcemanager.ApplicationMasterService: AM registration appattempt_1376111601621_0005_000001
2013-08-10 05:26:53,449 INFO org.apache.hadoop.yarn.server.resourcemanager.RMAuditLogger: USER=ubuntu	IP=192.168.100.41	OPERATION=Register App Master	TARGET=ApplicationMasterService	RESULT=SUCCESS	APPID=application_1376111601621_0005	APPATTEMPTID=appattempt_1376111601621_0005_000001
2013-08-10 05:26:53,450 INFO org.apache.hadoop.yarn.server.resourcemanager.rmapp.attempt.RMAppAttemptImpl: appattempt_1376111601621_0005_000001 State change from LAUNCHED to RUNNING
2013-08-10 05:26:53,450 INFO org.apache.hadoop.yarn.server.resourcemanager.rmapp.RMAppImpl: application_1376111601621_0005 State change from ACCEPTED to RUNNING
2013-08-10 05:26:54,718 INFO org.apache.hadoop.yarn.server.resourcemanager.rmcontainer.RMContainerImpl: container_1376111601621_0005_01_000002 Container Transitioned from NEW to ALLOCATED
2013-08-10 05:26:54,719 INFO org.apache.hadoop.yarn.server.resourcemanager.RMAuditLogger: USER=ubuntu	OPERATION=AM Allocated Container	TARGET=SchedulerApp	RESULT=SUCCESS	APPID=application_1376111601621_0005	CONTAINERID=container_1376111601621_0005_01_000002
2013-08-10 05:26:54,719 INFO org.apache.hadoop.yarn.server.resourcemanager.scheduler.common.fica.FiCaSchedulerNode: Assigned container container_1376111601621_0005_01_000002 of capacity <memory:1024, vCores:1> on host hadoop-221-4:41177, which currently has 1 containers, <memory:1024, vCores:1> used and <memory:7168, vCores:15> available
2013-08-10 05:26:54,720 INFO org.apache.hadoop.yarn.server.resourcemanager.scheduler.capacity.LeafQueue: assignedContainer application=application_1376111601621_0005 container=Container: [ContainerId: container_1376111601621_0005_01_000002, NodeId: hadoop-221-4:41177, NodeHttpAddress: hadoop-221-4:8042, Resource: <memory:1024, vCores:1>, Priority: 20, State: NEW, Token: null, Status: container_id {, app_attempt_id {, application_id {, id: 5, cluster_timestamp: 1376111601621, }, attemptId: 1, }, id: 2, }, state: C_NEW, ] containerId=container_1376111601621_0005_01_000002 queue=default: capacity=1.0, absoluteCapacity=1.0, usedResources=<memory:2048, vCores:1>usedCapacity=0.041666668, absoluteUsedCapacity=0.041666668, numApps=1, numContainers=1 usedCapacity=0.041666668 absoluteUsedCapacity=0.041666668 used=<memory:2048, vCores:1> cluster=<memory:49152, vCores:96>
2013-08-10 05:26:54,721 INFO org.apache.hadoop.yarn.server.resourcemanager.scheduler.capacity.ParentQueue: Re-sorting queues since queue: root.default stats: default: capacity=1.0, absoluteCapacity=1.0, usedResources=<memory:3072, vCores:2>usedCapacity=0.0625, absoluteUsedCapacity=0.0625, numApps=1, numContainers=2
2013-08-10 05:26:54,721 INFO org.apache.hadoop.yarn.server.resourcemanager.scheduler.capacity.ParentQueue: assignedContainer queue=root usedCapacity=0.0625 absoluteUsedCapacity=0.0625 used=<memory:3072, vCores:2> cluster=<memory:49152, vCores:96>
2013-08-10 05:26:54,801 INFO org.apache.hadoop.yarn.server.resourcemanager.rmcontainer.RMContainerImpl: container_1376111601621_0005_01_000003 Container Transitioned from NEW to ALLOCATED
2013-08-10 05:26:54,801 INFO org.apache.hadoop.yarn.server.resourcemanager.RMAuditLogger: USER=ubuntu	OPERATION=AM Allocated Container	TARGET=SchedulerApp	RESULT=SUCCESS	APPID=application_1376111601621_0005	CONTAINERID=container_1376111601621_0005_01_000003
2013-08-10 05:26:54,802 INFO org.apache.hadoop.yarn.server.resourcemanager.scheduler.common.fica.FiCaSchedulerNode: Assigned container container_1376111601621_0005_01_000003 of capacity <memory:1024, vCores:1> on host hadoop-221-6:57712, which currently has 1 containers, <memory:1024, vCores:1> used and <memory:7168, vCores:15> available
2013-08-10 05:26:54,803 INFO org.apache.hadoop.yarn.server.resourcemanager.scheduler.capacity.LeafQueue: assignedContainer application=application_1376111601621_0005 container=Container: [ContainerId: container_1376111601621_0005_01_000003, NodeId: hadoop-221-6:57712, NodeHttpAddress: hadoop-221-6:8042, Resource: <memory:1024, vCores:1>, Priority: 20, State: NEW, Token: null, Status: container_id {, app_attempt_id {, application_id {, id: 5, cluster_timestamp: 1376111601621, }, attemptId: 1, }, id: 3, }, state: C_NEW, ] containerId=container_1376111601621_0005_01_000003 queue=default: capacity=1.0, absoluteCapacity=1.0, usedResources=<memory:3072, vCores:2>usedCapacity=0.0625, absoluteUsedCapacity=0.0625, numApps=1, numContainers=2 usedCapacity=0.0625 absoluteUsedCapacity=0.0625 used=<memory:3072, vCores:2> cluster=<memory:49152, vCores:96>
2013-08-10 05:26:54,803 INFO org.apache.hadoop.yarn.server.resourcemanager.scheduler.capacity.ParentQueue: Re-sorting queues since queue: root.default stats: default: capacity=1.0, absoluteCapacity=1.0, usedResources=<memory:4096, vCores:3>usedCapacity=0.083333336, absoluteUsedCapacity=0.083333336, numApps=1, numContainers=3
2013-08-10 05:26:54,803 INFO org.apache.hadoop.yarn.server.resourcemanager.scheduler.capacity.ParentQueue: assignedContainer queue=root usedCapacity=0.083333336 absoluteUsedCapacity=0.083333336 used=<memory:4096, vCores:3> cluster=<memory:49152, vCores:96>
2013-08-10 05:26:55,517 INFO org.apache.hadoop.yarn.server.resourcemanager.rmcontainer.RMContainerImpl: container_1376111601621_0005_01_000002 Container Transitioned from ALLOCATED to ACQUIRED
2013-08-10 05:26:55,520 INFO org.apache.hadoop.yarn.server.resourcemanager.rmcontainer.RMContainerImpl: container_1376111601621_0005_01_000003 Container Transitioned from ALLOCATED to ACQUIRED
2013-08-10 05:26:57,679 INFO org.apache.hadoop.yarn.server.resourcemanager.scheduler.AppSchedulingInfo: checking for deactivate... 
2013-08-10 05:26:57,730 INFO org.apache.hadoop.yarn.server.resourcemanager.rmcontainer.RMContainerImpl: container_1376111601621_0005_01_000002 Container Transitioned from ACQUIRED to RUNNING
2013-08-10 05:26:57,817 INFO org.apache.hadoop.yarn.server.resourcemanager.rmcontainer.RMContainerImpl: container_1376111601621_0005_01_000003 Container Transitioned from ACQUIRED to RUNNING
2013-08-10 05:29:32,176 INFO org.apache.hadoop.yarn.server.resourcemanager.rmcontainer.RMContainerImpl: container_1376111601621_0005_01_000003 Container Transitioned from RUNNING to COMPLETED
2013-08-10 05:29:32,176 INFO org.apache.hadoop.yarn.server.resourcemanager.scheduler.common.fica.FiCaSchedulerApp: Completed container: container_1376111601621_0005_01_000003 in state: COMPLETED event:FINISHED
2013-08-10 05:29:32,176 INFO org.apache.hadoop.yarn.server.resourcemanager.RMAuditLogger: USER=ubuntu	OPERATION=AM Released Container	TARGET=SchedulerApp	RESULT=SUCCESS	APPID=application_1376111601621_0005	CONTAINERID=container_1376111601621_0005_01_000003
2013-08-10 05:29:32,176 INFO org.apache.hadoop.yarn.server.resourcemanager.scheduler.common.fica.FiCaSchedulerNode: Released container container_1376111601621_0005_01_000003 of capacity <memory:1024, vCores:1> on host hadoop-221-6:57712, which currently has 0 containers, <memory:0, vCores:0> used and <memory:8192, vCores:16> available, release resources=true
2013-08-10 05:29:32,177 INFO org.apache.hadoop.yarn.server.resourcemanager.scheduler.capacity.LeafQueue: default used=<memory:3072, vCores:2> numContainers=2 user=ubuntu user-resources=<memory:3072, vCores:2>
2013-08-10 05:29:32,178 INFO org.apache.hadoop.yarn.server.resourcemanager.scheduler.capacity.LeafQueue: completedContainer container=Container: [ContainerId: container_1376111601621_0005_01_000003, NodeId: hadoop-221-6:57712, NodeHttpAddress: hadoop-221-6:8042, Resource: <memory:1024, vCores:1>, Priority: 20, State: NEW, Token: null, Status: container_id {, app_attempt_id {, application_id {, id: 5, cluster_timestamp: 1376111601621, }, attemptId: 1, }, id: 3, }, state: C_COMPLETE, diagnostics: "Container killed by the ApplicationMaster.\n\n", exit_status: 143, ] resource=<memory:1024, vCores:1> queue=default: capacity=1.0, absoluteCapacity=1.0, usedResources=<memory:3072, vCores:2>usedCapacity=0.0625, absoluteUsedCapacity=0.0625, numApps=1, numContainers=2 usedCapacity=0.0625 absoluteUsedCapacity=0.0625 used=<memory:3072, vCores:2> cluster=<memory:49152, vCores:96>
2013-08-10 05:29:32,178 INFO org.apache.hadoop.yarn.server.resourcemanager.scheduler.capacity.ParentQueue: completedContainer queue=root usedCapacity=0.0625 absoluteUsedCapacity=0.0625 used=<memory:3072, vCores:2> cluster=<memory:49152, vCores:96>
2013-08-10 05:29:32,179 INFO org.apache.hadoop.yarn.server.resourcemanager.scheduler.capacity.CapacityScheduler: Application appattempt_1376111601621_0005_000001 released container container_1376111601621_0005_01_000003 on node: host: hadoop-221-6:57712 #containers=0 available=8192 used=0 with event: FINISHED
2013-08-10 05:29:38,432 INFO org.apache.hadoop.yarn.server.resourcemanager.rmcontainer.RMContainerImpl: container_1376111601621_0005_01_000002 Container Transitioned from RUNNING to COMPLETED
2013-08-10 05:29:38,433 INFO org.apache.hadoop.yarn.server.resourcemanager.scheduler.common.fica.FiCaSchedulerApp: Completed container: container_1376111601621_0005_01_000002 in state: COMPLETED event:FINISHED
2013-08-10 05:29:38,433 INFO org.apache.hadoop.yarn.server.resourcemanager.RMAuditLogger: USER=ubuntu	OPERATION=AM Released Container	TARGET=SchedulerApp	RESULT=SUCCESS	APPID=application_1376111601621_0005	CONTAINERID=container_1376111601621_0005_01_000002
2013-08-10 05:29:38,433 INFO org.apache.hadoop.yarn.server.resourcemanager.scheduler.common.fica.FiCaSchedulerNode: Released container container_1376111601621_0005_01_000002 of capacity <memory:1024, vCores:1> on host hadoop-221-4:41177, which currently has 0 containers, <memory:0, vCores:0> used and <memory:8192, vCores:16> available, release resources=true
2013-08-10 05:29:38,434 INFO org.apache.hadoop.yarn.server.resourcemanager.scheduler.capacity.LeafQueue: default used=<memory:2048, vCores:1> numContainers=1 user=ubuntu user-resources=<memory:2048, vCores:1>
2013-08-10 05:29:38,435 INFO org.apache.hadoop.yarn.server.resourcemanager.scheduler.capacity.LeafQueue: completedContainer container=Container: [ContainerId: container_1376111601621_0005_01_000002, NodeId: hadoop-221-4:41177, NodeHttpAddress: hadoop-221-4:8042, Resource: <memory:1024, vCores:1>, Priority: 20, State: NEW, Token: null, Status: container_id {, app_attempt_id {, application_id {, id: 5, cluster_timestamp: 1376111601621, }, attemptId: 1, }, id: 2, }, state: C_COMPLETE, diagnostics: "Container killed by the ApplicationMaster.\n\n", exit_status: 143, ] resource=<memory:1024, vCores:1> queue=default: capacity=1.0, absoluteCapacity=1.0, usedResources=<memory:2048, vCores:1>usedCapacity=0.041666668, absoluteUsedCapacity=0.041666668, numApps=1, numContainers=1 usedCapacity=0.041666668 absoluteUsedCapacity=0.041666668 used=<memory:2048, vCores:1> cluster=<memory:49152, vCores:96>
2013-08-10 05:29:38,435 INFO org.apache.hadoop.yarn.server.resourcemanager.scheduler.capacity.ParentQueue: completedContainer queue=root usedCapacity=0.041666668 absoluteUsedCapacity=0.041666668 used=<memory:2048, vCores:1> cluster=<memory:49152, vCores:96>
2013-08-10 05:29:38,436 INFO org.apache.hadoop.yarn.server.resourcemanager.scheduler.capacity.CapacityScheduler: Application appattempt_1376111601621_0005_000001 released container container_1376111601621_0005_01_000002 on node: host: hadoop-221-4:41177 #containers=0 available=8192 used=0 with event: FINISHED
2013-08-10 05:29:42,598 INFO org.apache.hadoop.yarn.server.resourcemanager.rmapp.attempt.RMAppAttemptImpl: appattempt_1376111601621_0005_000001 State change from RUNNING to FINISHING
2013-08-10 05:29:42,599 INFO org.apache.hadoop.yarn.server.resourcemanager.rmapp.RMAppImpl: application_1376111601621_0005 State change from RUNNING to FINISHING
2013-08-10 05:29:43,556 INFO org.apache.hadoop.yarn.server.resourcemanager.rmcontainer.RMContainerImpl: container_1376111601621_0005_01_000001 Container Transitioned from RUNNING to COMPLETED
2013-08-10 05:29:43,556 INFO org.apache.hadoop.yarn.server.resourcemanager.scheduler.common.fica.FiCaSchedulerApp: Completed container: container_1376111601621_0005_01_000001 in state: COMPLETED event:FINISHED
2013-08-10 05:29:43,556 INFO org.apache.hadoop.yarn.server.resourcemanager.rmapp.attempt.RMAppAttemptImpl: appattempt_1376111601621_0005_000001 State change from FINISHING to FINISHED
2013-08-10 05:29:43,556 INFO org.apache.hadoop.yarn.server.resourcemanager.RMAuditLogger: USER=ubuntu	OPERATION=AM Released Container	TARGET=SchedulerApp	RESULT=SUCCESS	APPID=application_1376111601621_0005	CONTAINERID=container_1376111601621_0005_01_000001
2013-08-10 05:29:43,557 INFO org.apache.hadoop.yarn.server.resourcemanager.rmapp.RMAppImpl: application_1376111601621_0005 State change from FINISHING to FINISHED
2013-08-10 05:29:43,557 INFO org.apache.hadoop.yarn.server.resourcemanager.scheduler.common.fica.FiCaSchedulerNode: Released container container_1376111601621_0005_01_000001 of capacity <memory:2048, vCores:1> on host hadoop-221-2:55267, which currently has 0 containers, <memory:0, vCores:0> used and <memory:8192, vCores:16> available, release resources=true
2013-08-10 05:29:43,557 INFO org.apache.hadoop.yarn.server.resourcemanager.scheduler.capacity.LeafQueue: default used=<memory:0, vCores:0> numContainers=0 user=ubuntu user-resources=<memory:0, vCores:0>
2013-08-10 05:29:43,557 INFO org.apache.hadoop.yarn.server.resourcemanager.RMAuditLogger: USER=ubuntu	OPERATION=Application Finished - Succeeded	TARGET=RMAppManager	RESULT=SUCCESS	APPID=application_1376111601621_0005
2013-08-10 05:29:43,558 INFO org.apache.hadoop.yarn.server.resourcemanager.amlauncher.AMLauncher: Cleaning master appattempt_1376111601621_0005_000001
2013-08-10 05:29:43,558 INFO org.apache.hadoop.yarn.server.resourcemanager.recovery.RMStateStore: Removing info for app: application_1376111601621_0005
2013-08-10 05:29:43,558 INFO org.apache.hadoop.yarn.server.resourcemanager.RMAppManager$ApplicationSummary: appId=application_1376111601621_0005,name=TeraGen,user=ubuntu,queue=default,state=FINISHED,trackingUrl=hadoop-221-1.novalocal:8088/proxy/application_1376111601621_0005/jobhistory/job/job_1376111601621_0005,appMasterHost=hadoop-221-2,startTime=1376112406103,finishTime=1376112582599
2013-08-10 05:29:43,559 INFO org.apache.hadoop.yarn.server.resourcemanager.scheduler.capacity.LeafQueue: completedContainer container=Container: [ContainerId: container_1376111601621_0005_01_000001, NodeId: hadoop-221-2:55267, NodeHttpAddress: hadoop-221-2:8042, Resource: <memory:2048, vCores:1>, Priority: 0, State: NEW, Token: null, Status: container_id {, app_attempt_id {, application_id {, id: 5, cluster_timestamp: 1376111601621, }, attemptId: 1, }, id: 1, }, state: C_COMPLETE, diagnostics: "", exit_status: 0, ] resource=<memory:2048, vCores:1> queue=default: capacity=1.0, absoluteCapacity=1.0, usedResources=<memory:0, vCores:0>usedCapacity=0.0, absoluteUsedCapacity=0.0, numApps=1, numContainers=0 usedCapacity=0.0 absoluteUsedCapacity=0.0 used=<memory:0, vCores:0> cluster=<memory:49152, vCores:96>
2013-08-10 05:29:43,559 INFO org.apache.hadoop.yarn.server.resourcemanager.scheduler.capacity.ParentQueue: completedContainer queue=root usedCapacity=0.0 absoluteUsedCapacity=0.0 used=<memory:0, vCores:0> cluster=<memory:49152, vCores:96>
2013-08-10 05:29:43,559 INFO org.apache.hadoop.yarn.server.resourcemanager.scheduler.capacity.CapacityScheduler: Application appattempt_1376111601621_0005_000001 released container container_1376111601621_0005_01_000001 on node: host: hadoop-221-2:55267 #containers=0 available=8192 used=0 with event: FINISHED
2013-08-10 05:29:43,559 INFO org.apache.hadoop.yarn.server.resourcemanager.scheduler.capacity.CapacityScheduler: Application appattempt_1376111601621_0005_000001 is done. finalState=FINISHED
2013-08-10 05:29:43,559 INFO org.apache.hadoop.yarn.server.resourcemanager.scheduler.AppSchedulingInfo: Application application_1376111601621_0005 requests cleared
2013-08-10 05:29:43,559 INFO org.apache.hadoop.yarn.server.resourcemanager.scheduler.capacity.LeafQueue: Application removed - appId: application_1376111601621_0005 user: ubuntu queue: default #user-pending-applications: 0 #user-active-applications: 0 #queue-pending-applications: 0 #queue-active-applications: 0
2013-08-10 05:29:43,560 INFO org.apache.hadoop.yarn.server.resourcemanager.scheduler.capacity.ParentQueue: Application removed - appId: application_1376111601621_0005 user: ubuntu leaf-queue of parent: root #applications: 0
2013-08-10 05:29:57,277 INFO org.apache.hadoop.yarn.server.resourcemanager.ClientRMService: Allocated new applicationId: 6
2013-08-10 05:29:57,620 INFO org.apache.hadoop.yarn.server.resourcemanager.ClientRMService: Allocated new applicationId: 7
2013-08-10 05:29:58,101 INFO org.apache.hadoop.yarn.server.resourcemanager.ClientRMService: Allocated new applicationId: 8
2013-08-10 05:29:58,258 INFO org.apache.hadoop.yarn.server.resourcemanager.ClientRMService: Allocated new applicationId: 9
2013-08-10 05:29:58,406 INFO org.apache.hadoop.yarn.server.resourcemanager.ClientRMService: Allocated new applicationId: 10
2013-08-10 05:29:59,266 INFO org.apache.hadoop.yarn.server.resourcemanager.ClientRMService: Storing Application with id application_1376111601621_0006
2013-08-10 05:29:59,266 INFO org.apache.hadoop.yarn.server.resourcemanager.recovery.RMStateStore: Storing info for app: application_1376111601621_0006
2013-08-10 05:29:59,266 INFO org.apache.hadoop.yarn.server.resourcemanager.ClientRMService: Application with id 6 submitted by user ubuntu
2013-08-10 05:29:59,266 INFO org.apache.hadoop.yarn.server.resourcemanager.RMAuditLogger: USER=ubuntu	IP=192.168.100.36	OPERATION=Submit Application Request	TARGET=ClientRMService	RESULT=SUCCESS	APPID=application_1376111601621_0006
2013-08-10 05:29:59,267 INFO org.apache.hadoop.yarn.server.resourcemanager.rmapp.RMAppImpl: application_1376111601621_0006 State change from NEW to SUBMITTED
2013-08-10 05:29:59,267 INFO org.apache.hadoop.yarn.server.resourcemanager.ApplicationMasterService: Registering appattempt_1376111601621_0006_000001
2013-08-10 05:29:59,267 INFO org.apache.hadoop.yarn.server.resourcemanager.rmapp.attempt.RMAppAttemptImpl: appattempt_1376111601621_0006_000001 State change from NEW to SUBMITTED
2013-08-10 05:29:59,268 INFO org.apache.hadoop.yarn.server.resourcemanager.scheduler.capacity.LeafQueue: Application application_1376111601621_0006 from user: ubuntu activated in queue: default
2013-08-10 05:29:59,268 INFO org.apache.hadoop.yarn.server.resourcemanager.scheduler.capacity.LeafQueue: Application added - appId: application_1376111601621_0006 user: org.apache.hadoop.yarn.server.resourcemanager.scheduler.capacity.LeafQueue$User@79f936cc, leaf-queue: default #user-pending-applications: 0 #user-active-applications: 1 #queue-pending-applications: 0 #queue-active-applications: 1
2013-08-10 05:29:59,268 INFO org.apache.hadoop.yarn.server.resourcemanager.scheduler.capacity.ParentQueue: Application added - appId: application_1376111601621_0006 user: ubuntu leaf-queue of parent: root #applications: 1
2013-08-10 05:29:59,268 INFO org.apache.hadoop.yarn.server.resourcemanager.scheduler.capacity.CapacityScheduler: Application Submission: appattempt_1376111601621_0006_000001, user: ubuntu queue: default: capacity=1.0, absoluteCapacity=1.0, usedResources=<memory:0, vCores:0>usedCapacity=0.0, absoluteUsedCapacity=0.0, numApps=1, numContainers=0, currently active: 1
2013-08-10 05:29:59,268 INFO org.apache.hadoop.yarn.server.resourcemanager.rmapp.attempt.RMAppAttemptImpl: appattempt_1376111601621_0006_000001 State change from SUBMITTED to SCHEDULED
2013-08-10 05:29:59,268 INFO org.apache.hadoop.yarn.server.resourcemanager.rmapp.RMAppImpl: application_1376111601621_0006 State change from SUBMITTED to ACCEPTED
2013-08-10 05:29:59,283 INFO org.apache.hadoop.yarn.server.resourcemanager.rmcontainer.RMContainerImpl: container_1376111601621_0006_01_000001 Container Transitioned from NEW to ALLOCATED
2013-08-10 05:29:59,283 INFO org.apache.hadoop.yarn.server.resourcemanager.RMAuditLogger: USER=ubuntu	OPERATION=AM Allocated Container	TARGET=SchedulerApp	RESULT=SUCCESS	APPID=application_1376111601621_0006	CONTAINERID=container_1376111601621_0006_01_000001
2013-08-10 05:29:59,283 INFO org.apache.hadoop.yarn.server.resourcemanager.scheduler.common.fica.FiCaSchedulerNode: Assigned container container_1376111601621_0006_01_000001 of capacity <memory:2048, vCores:1> on host hadoop-221-6:57712, which currently has 1 containers, <memory:2048, vCores:1> used and <memory:6144, vCores:15> available
2013-08-10 05:29:59,284 INFO org.apache.hadoop.yarn.server.resourcemanager.scheduler.capacity.LeafQueue: assignedContainer application=application_1376111601621_0006 container=Container: [ContainerId: container_1376111601621_0006_01_000001, NodeId: hadoop-221-6:57712, NodeHttpAddress: hadoop-221-6:8042, Resource: <memory:2048, vCores:1>, Priority: 0, State: NEW, Token: null, Status: container_id {, app_attempt_id {, application_id {, id: 6, cluster_timestamp: 1376111601621, }, attemptId: 1, }, id: 1, }, state: C_NEW, ] containerId=container_1376111601621_0006_01_000001 queue=default: capacity=1.0, absoluteCapacity=1.0, usedResources=<memory:0, vCores:0>usedCapacity=0.0, absoluteUsedCapacity=0.0, numApps=1, numContainers=0 usedCapacity=0.0 absoluteUsedCapacity=0.0 used=<memory:0, vCores:0> cluster=<memory:49152, vCores:96>
2013-08-10 05:29:59,284 INFO org.apache.hadoop.yarn.server.resourcemanager.scheduler.capacity.ParentQueue: Re-sorting queues since queue: root.default stats: default: capacity=1.0, absoluteCapacity=1.0, usedResources=<memory:2048, vCores:1>usedCapacity=0.041666668, absoluteUsedCapacity=0.041666668, numApps=1, numContainers=1
2013-08-10 05:29:59,284 INFO org.apache.hadoop.yarn.server.resourcemanager.scheduler.capacity.ParentQueue: assignedContainer queue=root usedCapacity=0.041666668 absoluteUsedCapacity=0.041666668 used=<memory:2048, vCores:1> cluster=<memory:49152, vCores:96>
2013-08-10 05:29:59,288 INFO org.apache.hadoop.yarn.server.resourcemanager.rmcontainer.RMContainerImpl: container_1376111601621_0006_01_000001 Container Transitioned from ALLOCATED to ACQUIRED
2013-08-10 05:29:59,289 INFO org.apache.hadoop.yarn.server.resourcemanager.rmapp.attempt.RMAppAttemptImpl: Storing attempt: AppId: application_1376111601621_0006 AttemptId: appattempt_1376111601621_0006_000001 MasterContainer: Container: [ContainerId: container_1376111601621_0006_01_000001, NodeId: hadoop-221-6:57712, NodeHttpAddress: hadoop-221-6:8042, Resource: <memory:2048, vCores:1>, Priority: 0, State: NEW, Token: null, Status: container_id {, app_attempt_id {, application_id {, id: 6, cluster_timestamp: 1376111601621, }, attemptId: 1, }, id: 1, }, state: C_NEW, ]
2013-08-10 05:29:59,290 INFO org.apache.hadoop.yarn.server.resourcemanager.recovery.RMStateStore: Storing info for attempt: appattempt_1376111601621_0006_000001
2013-08-10 05:29:59,290 INFO org.apache.hadoop.yarn.server.resourcemanager.rmapp.attempt.RMAppAttemptImpl: appattempt_1376111601621_0006_000001 State change from SCHEDULED to ALLOCATED_SAVING
2013-08-10 05:29:59,291 INFO org.apache.hadoop.yarn.server.resourcemanager.rmapp.attempt.RMAppAttemptImpl: appattempt_1376111601621_0006_000001 State change from ALLOCATED_SAVING to ALLOCATED
2013-08-10 05:29:59,291 INFO org.apache.hadoop.yarn.server.resourcemanager.amlauncher.AMLauncher: Launching masterappattempt_1376111601621_0006_000001
2013-08-10 05:29:59,292 INFO org.apache.hadoop.yarn.server.resourcemanager.amlauncher.AMLauncher: Setting up container Container: [ContainerId: container_1376111601621_0006_01_000001, NodeId: hadoop-221-6:57712, NodeHttpAddress: hadoop-221-6:8042, Resource: <memory:2048, vCores:1>, Priority: 0, State: NEW, Token: null, Status: container_id {, app_attempt_id {, application_id {, id: 6, cluster_timestamp: 1376111601621, }, attemptId: 1, }, id: 1, }, state: C_NEW, ] for AM appattempt_1376111601621_0006_000001
2013-08-10 05:29:59,292 INFO org.apache.hadoop.yarn.server.resourcemanager.amlauncher.AMLauncher: Command to launch container container_1376111601621_0006_01_000001 : $JAVA_HOME/bin/java -Dlog4j.configuration=container-log4j.properties -Dyarn.app.mapreduce.container.log.dir=<LOG_DIR> -Dyarn.app.mapreduce.container.log.filesize=0 -Dhadoop.root.logger=INFO,CLA  -Xmx1024m org.apache.hadoop.mapreduce.v2.app.MRAppMaster 1><LOG_DIR>/stdout 2><LOG_DIR>/stderr 
2013-08-10 05:29:59,336 INFO org.apache.hadoop.yarn.server.resourcemanager.amlauncher.AMLauncher: Done launching container Container: [ContainerId: container_1376111601621_0006_01_000001, NodeId: hadoop-221-6:57712, NodeHttpAddress: hadoop-221-6:8042, Resource: <memory:2048, vCores:1>, Priority: 0, State: NEW, Token: null, Status: container_id {, app_attempt_id {, application_id {, id: 6, cluster_timestamp: 1376111601621, }, attemptId: 1, }, id: 1, }, state: C_NEW, ] for AM appattempt_1376111601621_0006_000001
2013-08-10 05:29:59,337 INFO org.apache.hadoop.yarn.server.resourcemanager.rmapp.attempt.RMAppAttemptImpl: appattempt_1376111601621_0006_000001 State change from ALLOCATED to LAUNCHED
2013-08-10 05:29:59,404 INFO org.apache.hadoop.yarn.server.resourcemanager.ClientRMService: Storing Application with id application_1376111601621_0007
2013-08-10 05:29:59,405 INFO org.apache.hadoop.yarn.server.resourcemanager.recovery.RMStateStore: Storing info for app: application_1376111601621_0007
2013-08-10 05:29:59,405 INFO org.apache.hadoop.yarn.server.resourcemanager.ClientRMService: Application with id 7 submitted by user ubuntu
2013-08-10 05:29:59,405 INFO org.apache.hadoop.yarn.server.resourcemanager.RMAuditLogger: USER=ubuntu	IP=192.168.100.36	OPERATION=Submit Application Request	TARGET=ClientRMService	RESULT=SUCCESS	APPID=application_1376111601621_0007
2013-08-10 05:29:59,405 INFO org.apache.hadoop.yarn.server.resourcemanager.rmapp.RMAppImpl: application_1376111601621_0007 State change from NEW to SUBMITTED
2013-08-10 05:29:59,406 INFO org.apache.hadoop.yarn.server.resourcemanager.ApplicationMasterService: Registering appattempt_1376111601621_0007_000001
2013-08-10 05:29:59,406 INFO org.apache.hadoop.yarn.server.resourcemanager.rmapp.attempt.RMAppAttemptImpl: appattempt_1376111601621_0007_000001 State change from NEW to SUBMITTED
2013-08-10 05:29:59,406 INFO org.apache.hadoop.yarn.server.resourcemanager.scheduler.capacity.LeafQueue: Application application_1376111601621_0007 from user: ubuntu activated in queue: default
2013-08-10 05:29:59,407 INFO org.apache.hadoop.yarn.server.resourcemanager.scheduler.capacity.LeafQueue: Application added - appId: application_1376111601621_0007 user: org.apache.hadoop.yarn.server.resourcemanager.scheduler.capacity.LeafQueue$User@79f936cc, leaf-queue: default #user-pending-applications: 0 #user-active-applications: 2 #queue-pending-applications: 0 #queue-active-applications: 2
2013-08-10 05:29:59,407 INFO org.apache.hadoop.yarn.server.resourcemanager.scheduler.capacity.ParentQueue: Application added - appId: application_1376111601621_0007 user: ubuntu leaf-queue of parent: root #applications: 2
2013-08-10 05:29:59,407 INFO org.apache.hadoop.yarn.server.resourcemanager.scheduler.capacity.CapacityScheduler: Application Submission: appattempt_1376111601621_0007_000001, user: ubuntu queue: default: capacity=1.0, absoluteCapacity=1.0, usedResources=<memory:2048, vCores:1>usedCapacity=0.041666668, absoluteUsedCapacity=0.041666668, numApps=2, numContainers=1, currently active: 2
2013-08-10 05:29:59,407 INFO org.apache.hadoop.yarn.server.resourcemanager.rmapp.attempt.RMAppAttemptImpl: appattempt_1376111601621_0007_000001 State change from SUBMITTED to SCHEDULED
2013-08-10 05:29:59,407 INFO org.apache.hadoop.yarn.server.resourcemanager.rmapp.RMAppImpl: application_1376111601621_0007 State change from SUBMITTED to ACCEPTED
2013-08-10 05:29:59,518 INFO org.apache.hadoop.yarn.server.resourcemanager.rmcontainer.RMContainerImpl: container_1376111601621_0007_01_000001 Container Transitioned from NEW to ALLOCATED
2013-08-10 05:29:59,518 INFO org.apache.hadoop.yarn.server.resourcemanager.RMAuditLogger: USER=ubuntu	OPERATION=AM Allocated Container	TARGET=SchedulerApp	RESULT=SUCCESS	APPID=application_1376111601621_0007	CONTAINERID=container_1376111601621_0007_01_000001
2013-08-10 05:29:59,519 INFO org.apache.hadoop.yarn.server.resourcemanager.scheduler.common.fica.FiCaSchedulerNode: Assigned container container_1376111601621_0007_01_000001 of capacity <memory:2048, vCores:1> on host hadoop-221-4:41177, which currently has 1 containers, <memory:2048, vCores:1> used and <memory:6144, vCores:15> available
2013-08-10 05:29:59,519 INFO org.apache.hadoop.yarn.server.resourcemanager.scheduler.capacity.LeafQueue: assignedContainer application=application_1376111601621_0007 container=Container: [ContainerId: container_1376111601621_0007_01_000001, NodeId: hadoop-221-4:41177, NodeHttpAddress: hadoop-221-4:8042, Resource: <memory:2048, vCores:1>, Priority: 0, State: NEW, Token: null, Status: container_id {, app_attempt_id {, application_id {, id: 7, cluster_timestamp: 1376111601621, }, attemptId: 1, }, id: 1, }, state: C_NEW, ] containerId=container_1376111601621_0007_01_000001 queue=default: capacity=1.0, absoluteCapacity=1.0, usedResources=<memory:2048, vCores:1>usedCapacity=0.041666668, absoluteUsedCapacity=0.041666668, numApps=2, numContainers=1 usedCapacity=0.041666668 absoluteUsedCapacity=0.041666668 used=<memory:2048, vCores:1> cluster=<memory:49152, vCores:96>
2013-08-10 05:29:59,520 INFO org.apache.hadoop.yarn.server.resourcemanager.scheduler.capacity.ParentQueue: Re-sorting queues since queue: root.default stats: default: capacity=1.0, absoluteCapacity=1.0, usedResources=<memory:4096, vCores:2>usedCapacity=0.083333336, absoluteUsedCapacity=0.083333336, numApps=2, numContainers=2
2013-08-10 05:29:59,520 INFO org.apache.hadoop.yarn.server.resourcemanager.rmcontainer.RMContainerImpl: container_1376111601621_0007_01_000001 Container Transitioned from ALLOCATED to ACQUIRED
2013-08-10 05:29:59,520 INFO org.apache.hadoop.yarn.server.resourcemanager.scheduler.capacity.ParentQueue: assignedContainer queue=root usedCapacity=0.083333336 absoluteUsedCapacity=0.083333336 used=<memory:4096, vCores:2> cluster=<memory:49152, vCores:96>
2013-08-10 05:29:59,521 INFO org.apache.hadoop.yarn.server.resourcemanager.rmapp.attempt.RMAppAttemptImpl: Storing attempt: AppId: application_1376111601621_0007 AttemptId: appattempt_1376111601621_0007_000001 MasterContainer: Container: [ContainerId: container_1376111601621_0007_01_000001, NodeId: hadoop-221-4:41177, NodeHttpAddress: hadoop-221-4:8042, Resource: <memory:2048, vCores:1>, Priority: 0, State: NEW, Token: null, Status: container_id {, app_attempt_id {, application_id {, id: 7, cluster_timestamp: 1376111601621, }, attemptId: 1, }, id: 1, }, state: C_NEW, ]
2013-08-10 05:29:59,522 INFO org.apache.hadoop.yarn.server.resourcemanager.recovery.RMStateStore: Storing info for attempt: appattempt_1376111601621_0007_000001
2013-08-10 05:29:59,522 INFO org.apache.hadoop.yarn.server.resourcemanager.rmapp.attempt.RMAppAttemptImpl: appattempt_1376111601621_0007_000001 State change from SCHEDULED to ALLOCATED_SAVING
2013-08-10 05:29:59,522 INFO org.apache.hadoop.yarn.server.resourcemanager.rmapp.attempt.RMAppAttemptImpl: appattempt_1376111601621_0007_000001 State change from ALLOCATED_SAVING to ALLOCATED
2013-08-10 05:29:59,522 INFO org.apache.hadoop.yarn.server.resourcemanager.amlauncher.AMLauncher: Launching masterappattempt_1376111601621_0007_000001
2013-08-10 05:29:59,524 INFO org.apache.hadoop.yarn.server.resourcemanager.amlauncher.AMLauncher: Setting up container Container: [ContainerId: container_1376111601621_0007_01_000001, NodeId: hadoop-221-4:41177, NodeHttpAddress: hadoop-221-4:8042, Resource: <memory:2048, vCores:1>, Priority: 0, State: NEW, Token: null, Status: container_id {, app_attempt_id {, application_id {, id: 7, cluster_timestamp: 1376111601621, }, attemptId: 1, }, id: 1, }, state: C_NEW, ] for AM appattempt_1376111601621_0007_000001
2013-08-10 05:29:59,525 INFO org.apache.hadoop.yarn.server.resourcemanager.amlauncher.AMLauncher: Command to launch container container_1376111601621_0007_01_000001 : $JAVA_HOME/bin/java -Dlog4j.configuration=container-log4j.properties -Dyarn.app.mapreduce.container.log.dir=<LOG_DIR> -Dyarn.app.mapreduce.container.log.filesize=0 -Dhadoop.root.logger=INFO,CLA  -Xmx1024m org.apache.hadoop.mapreduce.v2.app.MRAppMaster 1><LOG_DIR>/stdout 2><LOG_DIR>/stderr 
2013-08-10 05:29:59,537 INFO org.apache.hadoop.yarn.server.resourcemanager.amlauncher.AMLauncher: Done launching container Container: [ContainerId: container_1376111601621_0007_01_000001, NodeId: hadoop-221-4:41177, NodeHttpAddress: hadoop-221-4:8042, Resource: <memory:2048, vCores:1>, Priority: 0, State: NEW, Token: null, Status: container_id {, app_attempt_id {, application_id {, id: 7, cluster_timestamp: 1376111601621, }, attemptId: 1, }, id: 1, }, state: C_NEW, ] for AM appattempt_1376111601621_0007_000001
2013-08-10 05:29:59,538 INFO org.apache.hadoop.yarn.server.resourcemanager.rmapp.attempt.RMAppAttemptImpl: appattempt_1376111601621_0007_000001 State change from ALLOCATED to LAUNCHED
2013-08-10 05:29:59,636 INFO org.apache.hadoop.yarn.server.resourcemanager.ClientRMService: Storing Application with id application_1376111601621_0008
2013-08-10 05:29:59,637 INFO org.apache.hadoop.yarn.server.resourcemanager.recovery.RMStateStore: Storing info for app: application_1376111601621_0008
2013-08-10 05:29:59,637 INFO org.apache.hadoop.yarn.server.resourcemanager.ClientRMService: Application with id 8 submitted by user ubuntu
2013-08-10 05:29:59,637 INFO org.apache.hadoop.yarn.server.resourcemanager.RMAuditLogger: USER=ubuntu	IP=192.168.100.36	OPERATION=Submit Application Request	TARGET=ClientRMService	RESULT=SUCCESS	APPID=application_1376111601621_0008
2013-08-10 05:29:59,637 INFO org.apache.hadoop.yarn.server.resourcemanager.rmapp.RMAppImpl: application_1376111601621_0008 State change from NEW to SUBMITTED
2013-08-10 05:29:59,638 INFO org.apache.hadoop.yarn.server.resourcemanager.ApplicationMasterService: Registering appattempt_1376111601621_0008_000001
2013-08-10 05:29:59,638 INFO org.apache.hadoop.yarn.server.resourcemanager.rmapp.attempt.RMAppAttemptImpl: appattempt_1376111601621_0008_000001 State change from NEW to SUBMITTED
2013-08-10 05:29:59,638 INFO org.apache.hadoop.yarn.server.resourcemanager.scheduler.capacity.LeafQueue: Application application_1376111601621_0008 from user: ubuntu activated in queue: default
2013-08-10 05:29:59,638 INFO org.apache.hadoop.yarn.server.resourcemanager.scheduler.capacity.LeafQueue: Application added - appId: application_1376111601621_0008 user: org.apache.hadoop.yarn.server.resourcemanager.scheduler.capacity.LeafQueue$User@79f936cc, leaf-queue: default #user-pending-applications: 0 #user-active-applications: 3 #queue-pending-applications: 0 #queue-active-applications: 3
2013-08-10 05:29:59,638 INFO org.apache.hadoop.yarn.server.resourcemanager.scheduler.capacity.ParentQueue: Application added - appId: application_1376111601621_0008 user: ubuntu leaf-queue of parent: root #applications: 3
2013-08-10 05:29:59,638 INFO org.apache.hadoop.yarn.server.resourcemanager.scheduler.capacity.CapacityScheduler: Application Submission: appattempt_1376111601621_0008_000001, user: ubuntu queue: default: capacity=1.0, absoluteCapacity=1.0, usedResources=<memory:4096, vCores:2>usedCapacity=0.083333336, absoluteUsedCapacity=0.083333336, numApps=3, numContainers=2, currently active: 3
2013-08-10 05:29:59,639 INFO org.apache.hadoop.yarn.server.resourcemanager.rmapp.attempt.RMAppAttemptImpl: appattempt_1376111601621_0008_000001 State change from SUBMITTED to SCHEDULED
2013-08-10 05:29:59,639 INFO org.apache.hadoop.yarn.server.resourcemanager.rmapp.RMAppImpl: application_1376111601621_0008 State change from SUBMITTED to ACCEPTED
2013-08-10 05:29:59,810 INFO org.apache.hadoop.yarn.server.resourcemanager.ClientRMService: Storing Application with id application_1376111601621_0009
2013-08-10 05:29:59,810 INFO org.apache.hadoop.yarn.server.resourcemanager.recovery.RMStateStore: Storing info for app: application_1376111601621_0009
2013-08-10 05:29:59,810 INFO org.apache.hadoop.yarn.server.resourcemanager.ClientRMService: Application with id 9 submitted by user ubuntu
2013-08-10 05:29:59,811 INFO org.apache.hadoop.yarn.server.resourcemanager.RMAuditLogger: USER=ubuntu	IP=192.168.100.36	OPERATION=Submit Application Request	TARGET=ClientRMService	RESULT=SUCCESS	APPID=application_1376111601621_0009
2013-08-10 05:29:59,811 INFO org.apache.hadoop.yarn.server.resourcemanager.rmapp.RMAppImpl: application_1376111601621_0009 State change from NEW to SUBMITTED
2013-08-10 05:29:59,811 INFO org.apache.hadoop.yarn.server.resourcemanager.ApplicationMasterService: Registering appattempt_1376111601621_0009_000001
2013-08-10 05:29:59,811 INFO org.apache.hadoop.yarn.server.resourcemanager.rmapp.attempt.RMAppAttemptImpl: appattempt_1376111601621_0009_000001 State change from NEW to SUBMITTED
2013-08-10 05:29:59,812 INFO org.apache.hadoop.yarn.server.resourcemanager.scheduler.capacity.LeafQueue: Application application_1376111601621_0009 from user: ubuntu activated in queue: default
2013-08-10 05:29:59,812 INFO org.apache.hadoop.yarn.server.resourcemanager.scheduler.capacity.LeafQueue: Application added - appId: application_1376111601621_0009 user: org.apache.hadoop.yarn.server.resourcemanager.scheduler.capacity.LeafQueue$User@79f936cc, leaf-queue: default #user-pending-applications: 0 #user-active-applications: 4 #queue-pending-applications: 0 #queue-active-applications: 4
2013-08-10 05:29:59,812 INFO org.apache.hadoop.yarn.server.resourcemanager.scheduler.capacity.ParentQueue: Application added - appId: application_1376111601621_0009 user: ubuntu leaf-queue of parent: root #applications: 4
2013-08-10 05:29:59,812 INFO org.apache.hadoop.yarn.server.resourcemanager.scheduler.capacity.CapacityScheduler: Application Submission: appattempt_1376111601621_0009_000001, user: ubuntu queue: default: capacity=1.0, absoluteCapacity=1.0, usedResources=<memory:4096, vCores:2>usedCapacity=0.083333336, absoluteUsedCapacity=0.083333336, numApps=4, numContainers=2, currently active: 4
2013-08-10 05:29:59,812 INFO org.apache.hadoop.yarn.server.resourcemanager.rmapp.attempt.RMAppAttemptImpl: appattempt_1376111601621_0009_000001 State change from SUBMITTED to SCHEDULED
2013-08-10 05:29:59,812 INFO org.apache.hadoop.yarn.server.resourcemanager.rmapp.RMAppImpl: application_1376111601621_0009 State change from SUBMITTED to ACCEPTED
2013-08-10 05:29:59,830 INFO org.apache.hadoop.yarn.server.resourcemanager.rmcontainer.RMContainerImpl: container_1376111601621_0008_01_000001 Container Transitioned from NEW to ALLOCATED
2013-08-10 05:29:59,830 INFO org.apache.hadoop.yarn.server.resourcemanager.RMAuditLogger: USER=ubuntu	OPERATION=AM Allocated Container	TARGET=SchedulerApp	RESULT=SUCCESS	APPID=application_1376111601621_0008	CONTAINERID=container_1376111601621_0008_01_000001
2013-08-10 05:29:59,830 INFO org.apache.hadoop.yarn.server.resourcemanager.scheduler.common.fica.FiCaSchedulerNode: Assigned container container_1376111601621_0008_01_000001 of capacity <memory:2048, vCores:1> on host hadoop-221-7:34609, which currently has 1 containers, <memory:2048, vCores:1> used and <memory:6144, vCores:15> available
2013-08-10 05:29:59,831 INFO org.apache.hadoop.yarn.server.resourcemanager.scheduler.capacity.LeafQueue: assignedContainer application=application_1376111601621_0008 container=Container: [ContainerId: container_1376111601621_0008_01_000001, NodeId: hadoop-221-7:34609, NodeHttpAddress: hadoop-221-7:8042, Resource: <memory:2048, vCores:1>, Priority: 0, State: NEW, Token: null, Status: container_id {, app_attempt_id {, application_id {, id: 8, cluster_timestamp: 1376111601621, }, attemptId: 1, }, id: 1, }, state: C_NEW, ] containerId=container_1376111601621_0008_01_000001 queue=default: capacity=1.0, absoluteCapacity=1.0, usedResources=<memory:4096, vCores:2>usedCapacity=0.083333336, absoluteUsedCapacity=0.083333336, numApps=4, numContainers=2 usedCapacity=0.083333336 absoluteUsedCapacity=0.083333336 used=<memory:4096, vCores:2> cluster=<memory:49152, vCores:96>
2013-08-10 05:29:59,831 INFO org.apache.hadoop.yarn.server.resourcemanager.scheduler.capacity.ParentQueue: Re-sorting queues since queue: root.default stats: default: capacity=1.0, absoluteCapacity=1.0, usedResources=<memory:6144, vCores:3>usedCapacity=0.125, absoluteUsedCapacity=0.125, numApps=4, numContainers=3
2013-08-10 05:29:59,831 INFO org.apache.hadoop.yarn.server.resourcemanager.scheduler.capacity.ParentQueue: assignedContainer queue=root usedCapacity=0.125 absoluteUsedCapacity=0.125 used=<memory:6144, vCores:3> cluster=<memory:49152, vCores:96>
2013-08-10 05:29:59,831 INFO org.apache.hadoop.yarn.server.resourcemanager.rmcontainer.RMContainerImpl: container_1376111601621_0008_01_000001 Container Transitioned from ALLOCATED to ACQUIRED
2013-08-10 05:29:59,832 INFO org.apache.hadoop.yarn.server.resourcemanager.rmapp.attempt.RMAppAttemptImpl: Storing attempt: AppId: application_1376111601621_0008 AttemptId: appattempt_1376111601621_0008_000001 MasterContainer: Container: [ContainerId: container_1376111601621_0008_01_000001, NodeId: hadoop-221-7:34609, NodeHttpAddress: hadoop-221-7:8042, Resource: <memory:2048, vCores:1>, Priority: 0, State: NEW, Token: null, Status: container_id {, app_attempt_id {, application_id {, id: 8, cluster_timestamp: 1376111601621, }, attemptId: 1, }, id: 1, }, state: C_NEW, ]
2013-08-10 05:29:59,832 INFO org.apache.hadoop.yarn.server.resourcemanager.recovery.RMStateStore: Storing info for attempt: appattempt_1376111601621_0008_000001
2013-08-10 05:29:59,833 INFO org.apache.hadoop.yarn.server.resourcemanager.rmapp.attempt.RMAppAttemptImpl: appattempt_1376111601621_0008_000001 State change from SCHEDULED to ALLOCATED_SAVING
2013-08-10 05:29:59,833 INFO org.apache.hadoop.yarn.server.resourcemanager.rmapp.attempt.RMAppAttemptImpl: appattempt_1376111601621_0008_000001 State change from ALLOCATED_SAVING to ALLOCATED
2013-08-10 05:29:59,833 INFO org.apache.hadoop.yarn.server.resourcemanager.amlauncher.AMLauncher: Launching masterappattempt_1376111601621_0008_000001
2013-08-10 05:29:59,835 INFO org.apache.hadoop.yarn.server.resourcemanager.ClientRMService: Storing Application with id application_1376111601621_0010
2013-08-10 05:29:59,835 INFO org.apache.hadoop.yarn.server.resourcemanager.recovery.RMStateStore: Storing info for app: application_1376111601621_0010
2013-08-10 05:29:59,835 INFO org.apache.hadoop.yarn.server.resourcemanager.ClientRMService: Application with id 10 submitted by user ubuntu
2013-08-10 05:29:59,835 INFO org.apache.hadoop.yarn.server.resourcemanager.RMAuditLogger: USER=ubuntu	IP=192.168.100.36	OPERATION=Submit Application Request	TARGET=ClientRMService	RESULT=SUCCESS	APPID=application_1376111601621_0010
2013-08-10 05:29:59,835 INFO org.apache.hadoop.yarn.server.resourcemanager.rmapp.RMAppImpl: application_1376111601621_0010 State change from NEW to SUBMITTED
2013-08-10 05:29:59,836 INFO org.apache.hadoop.yarn.server.resourcemanager.amlauncher.AMLauncher: Setting up container Container: [ContainerId: container_1376111601621_0008_01_000001, NodeId: hadoop-221-7:34609, NodeHttpAddress: hadoop-221-7:8042, Resource: <memory:2048, vCores:1>, Priority: 0, State: NEW, Token: null, Status: container_id {, app_attempt_id {, application_id {, id: 8, cluster_timestamp: 1376111601621, }, attemptId: 1, }, id: 1, }, state: C_NEW, ] for AM appattempt_1376111601621_0008_000001
2013-08-10 05:29:59,836 INFO org.apache.hadoop.yarn.server.resourcemanager.ApplicationMasterService: Registering appattempt_1376111601621_0010_000001
2013-08-10 05:29:59,836 INFO org.apache.hadoop.yarn.server.resourcemanager.amlauncher.AMLauncher: Command to launch container container_1376111601621_0008_01_000001 : $JAVA_HOME/bin/java -Dlog4j.configuration=container-log4j.properties -Dyarn.app.mapreduce.container.log.dir=<LOG_DIR> -Dyarn.app.mapreduce.container.log.filesize=0 -Dhadoop.root.logger=INFO,CLA  -Xmx1024m org.apache.hadoop.mapreduce.v2.app.MRAppMaster 1><LOG_DIR>/stdout 2><LOG_DIR>/stderr 
2013-08-10 05:29:59,836 INFO org.apache.hadoop.yarn.server.resourcemanager.rmapp.attempt.RMAppAttemptImpl: appattempt_1376111601621_0010_000001 State change from NEW to SUBMITTED
2013-08-10 05:29:59,836 INFO org.apache.hadoop.yarn.server.resourcemanager.scheduler.capacity.LeafQueue: Application application_1376111601621_0010 from user: ubuntu activated in queue: default
2013-08-10 05:29:59,836 INFO org.apache.hadoop.yarn.server.resourcemanager.scheduler.capacity.LeafQueue: Application added - appId: application_1376111601621_0010 user: org.apache.hadoop.yarn.server.resourcemanager.scheduler.capacity.LeafQueue$User@79f936cc, leaf-queue: default #user-pending-applications: 0 #user-active-applications: 5 #queue-pending-applications: 0 #queue-active-applications: 5
2013-08-10 05:29:59,836 INFO org.apache.hadoop.yarn.server.resourcemanager.scheduler.capacity.ParentQueue: Application added - appId: application_1376111601621_0010 user: ubuntu leaf-queue of parent: root #applications: 5
2013-08-10 05:29:59,837 INFO org.apache.hadoop.yarn.server.resourcemanager.scheduler.capacity.CapacityScheduler: Application Submission: appattempt_1376111601621_0010_000001, user: ubuntu queue: default: capacity=1.0, absoluteCapacity=1.0, usedResources=<memory:6144, vCores:3>usedCapacity=0.125, absoluteUsedCapacity=0.125, numApps=5, numContainers=3, currently active: 5
2013-08-10 05:29:59,837 INFO org.apache.hadoop.yarn.server.resourcemanager.rmapp.attempt.RMAppAttemptImpl: appattempt_1376111601621_0010_000001 State change from SUBMITTED to SCHEDULED
2013-08-10 05:29:59,837 INFO org.apache.hadoop.yarn.server.resourcemanager.rmapp.RMAppImpl: application_1376111601621_0010 State change from SUBMITTED to ACCEPTED
2013-08-10 05:29:59,848 INFO org.apache.hadoop.yarn.server.resourcemanager.amlauncher.AMLauncher: Done launching container Container: [ContainerId: container_1376111601621_0008_01_000001, NodeId: hadoop-221-7:34609, NodeHttpAddress: hadoop-221-7:8042, Resource: <memory:2048, vCores:1>, Priority: 0, State: NEW, Token: null, Status: container_id {, app_attempt_id {, application_id {, id: 8, cluster_timestamp: 1376111601621, }, attemptId: 1, }, id: 1, }, state: C_NEW, ] for AM appattempt_1376111601621_0008_000001
2013-08-10 05:29:59,848 INFO org.apache.hadoop.yarn.server.resourcemanager.rmapp.attempt.RMAppAttemptImpl: appattempt_1376111601621_0008_000001 State change from ALLOCATED to LAUNCHED
2013-08-10 05:30:00,062 INFO org.apache.hadoop.yarn.server.resourcemanager.rmcontainer.RMContainerImpl: container_1376111601621_0009_01_000001 Container Transitioned from NEW to ALLOCATED
2013-08-10 05:30:00,062 INFO org.apache.hadoop.yarn.server.resourcemanager.RMAuditLogger: USER=ubuntu	OPERATION=AM Allocated Container	TARGET=SchedulerApp	RESULT=SUCCESS	APPID=application_1376111601621_0009	CONTAINERID=container_1376111601621_0009_01_000001
2013-08-10 05:30:00,062 INFO org.apache.hadoop.yarn.server.resourcemanager.scheduler.common.fica.FiCaSchedulerNode: Assigned container container_1376111601621_0009_01_000001 of capacity <memory:2048, vCores:1> on host hadoop-221-5:42694, which currently has 1 containers, <memory:2048, vCores:1> used and <memory:6144, vCores:15> available
2013-08-10 05:30:00,063 INFO org.apache.hadoop.yarn.server.resourcemanager.scheduler.capacity.LeafQueue: assignedContainer application=application_1376111601621_0009 container=Container: [ContainerId: container_1376111601621_0009_01_000001, NodeId: hadoop-221-5:42694, NodeHttpAddress: hadoop-221-5:8042, Resource: <memory:2048, vCores:1>, Priority: 0, State: NEW, Token: null, Status: container_id {, app_attempt_id {, application_id {, id: 9, cluster_timestamp: 1376111601621, }, attemptId: 1, }, id: 1, }, state: C_NEW, ] containerId=container_1376111601621_0009_01_000001 queue=default: capacity=1.0, absoluteCapacity=1.0, usedResources=<memory:6144, vCores:3>usedCapacity=0.125, absoluteUsedCapacity=0.125, numApps=5, numContainers=3 usedCapacity=0.125 absoluteUsedCapacity=0.125 used=<memory:6144, vCores:3> cluster=<memory:49152, vCores:96>
2013-08-10 05:30:00,063 INFO org.apache.hadoop.yarn.server.resourcemanager.scheduler.capacity.ParentQueue: Re-sorting queues since queue: root.default stats: default: capacity=1.0, absoluteCapacity=1.0, usedResources=<memory:8192, vCores:4>usedCapacity=0.16666667, absoluteUsedCapacity=0.16666667, numApps=5, numContainers=4
2013-08-10 05:30:00,063 INFO org.apache.hadoop.yarn.server.resourcemanager.scheduler.capacity.ParentQueue: assignedContainer queue=root usedCapacity=0.16666667 absoluteUsedCapacity=0.16666667 used=<memory:8192, vCores:4> cluster=<memory:49152, vCores:96>
2013-08-10 05:30:00,064 INFO org.apache.hadoop.yarn.server.resourcemanager.rmcontainer.RMContainerImpl: container_1376111601621_0009_01_000001 Container Transitioned from ALLOCATED to ACQUIRED
2013-08-10 05:30:00,065 INFO org.apache.hadoop.yarn.server.resourcemanager.rmapp.attempt.RMAppAttemptImpl: Storing attempt: AppId: application_1376111601621_0009 AttemptId: appattempt_1376111601621_0009_000001 MasterContainer: Container: [ContainerId: container_1376111601621_0009_01_000001, NodeId: hadoop-221-5:42694, NodeHttpAddress: hadoop-221-5:8042, Resource: <memory:2048, vCores:1>, Priority: 0, State: NEW, Token: null, Status: container_id {, app_attempt_id {, application_id {, id: 9, cluster_timestamp: 1376111601621, }, attemptId: 1, }, id: 1, }, state: C_NEW, ]
2013-08-10 05:30:00,065 INFO org.apache.hadoop.yarn.server.resourcemanager.rmapp.attempt.RMAppAttemptImpl: appattempt_1376111601621_0009_000001 State change from SCHEDULED to ALLOCATED_SAVING
2013-08-10 05:30:00,065 INFO org.apache.hadoop.yarn.server.resourcemanager.recovery.RMStateStore: Storing info for attempt: appattempt_1376111601621_0009_000001
2013-08-10 05:30:00,065 INFO org.apache.hadoop.yarn.server.resourcemanager.rmapp.attempt.RMAppAttemptImpl: appattempt_1376111601621_0009_000001 State change from ALLOCATED_SAVING to ALLOCATED
2013-08-10 05:30:00,066 INFO org.apache.hadoop.yarn.server.resourcemanager.amlauncher.AMLauncher: Launching masterappattempt_1376111601621_0009_000001
2013-08-10 05:30:00,067 INFO org.apache.hadoop.yarn.server.resourcemanager.amlauncher.AMLauncher: Setting up container Container: [ContainerId: container_1376111601621_0009_01_000001, NodeId: hadoop-221-5:42694, NodeHttpAddress: hadoop-221-5:8042, Resource: <memory:2048, vCores:1>, Priority: 0, State: NEW, Token: null, Status: container_id {, app_attempt_id {, application_id {, id: 9, cluster_timestamp: 1376111601621, }, attemptId: 1, }, id: 1, }, state: C_NEW, ] for AM appattempt_1376111601621_0009_000001
2013-08-10 05:30:00,067 INFO org.apache.hadoop.yarn.server.resourcemanager.amlauncher.AMLauncher: Command to launch container container_1376111601621_0009_01_000001 : $JAVA_HOME/bin/java -Dlog4j.configuration=container-log4j.properties -Dyarn.app.mapreduce.container.log.dir=<LOG_DIR> -Dyarn.app.mapreduce.container.log.filesize=0 -Dhadoop.root.logger=INFO,CLA  -Xmx1024m org.apache.hadoop.mapreduce.v2.app.MRAppMaster 1><LOG_DIR>/stdout 2><LOG_DIR>/stderr 
2013-08-10 05:30:00,084 INFO org.apache.hadoop.yarn.server.resourcemanager.amlauncher.AMLauncher: Done launching container Container: [ContainerId: container_1376111601621_0009_01_000001, NodeId: hadoop-221-5:42694, NodeHttpAddress: hadoop-221-5:8042, Resource: <memory:2048, vCores:1>, Priority: 0, State: NEW, Token: null, Status: container_id {, app_attempt_id {, application_id {, id: 9, cluster_timestamp: 1376111601621, }, attemptId: 1, }, id: 1, }, state: C_NEW, ] for AM appattempt_1376111601621_0009_000001
2013-08-10 05:30:00,084 INFO org.apache.hadoop.yarn.server.resourcemanager.rmapp.attempt.RMAppAttemptImpl: appattempt_1376111601621_0009_000001 State change from ALLOCATED to LAUNCHED
2013-08-10 05:30:00,089 INFO org.apache.hadoop.yarn.server.resourcemanager.rmcontainer.RMContainerImpl: container_1376111601621_0010_01_000001 Container Transitioned from NEW to ALLOCATED
2013-08-10 05:30:00,091 INFO org.apache.hadoop.yarn.server.resourcemanager.RMAuditLogger: USER=ubuntu	OPERATION=AM Allocated Container	TARGET=SchedulerApp	RESULT=SUCCESS	APPID=application_1376111601621_0010	CONTAINERID=container_1376111601621_0010_01_000001
2013-08-10 05:30:00,091 INFO org.apache.hadoop.yarn.server.resourcemanager.scheduler.common.fica.FiCaSchedulerNode: Assigned container container_1376111601621_0010_01_000001 of capacity <memory:2048, vCores:1> on host hadoop-221-3:43958, which currently has 1 containers, <memory:2048, vCores:1> used and <memory:6144, vCores:15> available
2013-08-10 05:30:00,092 INFO org.apache.hadoop.yarn.server.resourcemanager.scheduler.capacity.LeafQueue: assignedContainer application=application_1376111601621_0010 container=Container: [ContainerId: container_1376111601621_0010_01_000001, NodeId: hadoop-221-3:43958, NodeHttpAddress: hadoop-221-3:8042, Resource: <memory:2048, vCores:1>, Priority: 0, State: NEW, Token: null, Status: container_id {, app_attempt_id {, application_id {, id: 10, cluster_timestamp: 1376111601621, }, attemptId: 1, }, id: 1, }, state: C_NEW, ] containerId=container_1376111601621_0010_01_000001 queue=default: capacity=1.0, absoluteCapacity=1.0, usedResources=<memory:8192, vCores:4>usedCapacity=0.16666667, absoluteUsedCapacity=0.16666667, numApps=5, numContainers=4 usedCapacity=0.16666667 absoluteUsedCapacity=0.16666667 used=<memory:8192, vCores:4> cluster=<memory:49152, vCores:96>
2013-08-10 05:30:00,092 INFO org.apache.hadoop.yarn.server.resourcemanager.scheduler.capacity.ParentQueue: Re-sorting queues since queue: root.default stats: default: capacity=1.0, absoluteCapacity=1.0, usedResources=<memory:10240, vCores:5>usedCapacity=0.20833333, absoluteUsedCapacity=0.20833333, numApps=5, numContainers=5
2013-08-10 05:30:00,093 INFO org.apache.hadoop.yarn.server.resourcemanager.scheduler.capacity.ParentQueue: assignedContainer queue=root usedCapacity=0.20833333 absoluteUsedCapacity=0.20833333 used=<memory:10240, vCores:5> cluster=<memory:49152, vCores:96>
2013-08-10 05:30:00,093 INFO org.apache.hadoop.yarn.server.resourcemanager.rmcontainer.RMContainerImpl: container_1376111601621_0010_01_000001 Container Transitioned from ALLOCATED to ACQUIRED
2013-08-10 05:30:00,094 INFO org.apache.hadoop.yarn.server.resourcemanager.rmapp.attempt.RMAppAttemptImpl: Storing attempt: AppId: application_1376111601621_0010 AttemptId: appattempt_1376111601621_0010_000001 MasterContainer: Container: [ContainerId: container_1376111601621_0010_01_000001, NodeId: hadoop-221-3:43958, NodeHttpAddress: hadoop-221-3:8042, Resource: <memory:2048, vCores:1>, Priority: 0, State: NEW, Token: null, Status: container_id {, app_attempt_id {, application_id {, id: 10, cluster_timestamp: 1376111601621, }, attemptId: 1, }, id: 1, }, state: C_NEW, ]
2013-08-10 05:30:00,095 INFO org.apache.hadoop.yarn.server.resourcemanager.rmapp.attempt.RMAppAttemptImpl: appattempt_1376111601621_0010_000001 State change from SCHEDULED to ALLOCATED_SAVING
2013-08-10 05:30:00,095 INFO org.apache.hadoop.yarn.server.resourcemanager.recovery.RMStateStore: Storing info for attempt: appattempt_1376111601621_0010_000001
2013-08-10 05:30:00,095 INFO org.apache.hadoop.yarn.server.resourcemanager.rmapp.attempt.RMAppAttemptImpl: appattempt_1376111601621_0010_000001 State change from ALLOCATED_SAVING to ALLOCATED
2013-08-10 05:30:00,096 INFO org.apache.hadoop.yarn.server.resourcemanager.amlauncher.AMLauncher: Launching masterappattempt_1376111601621_0010_000001
2013-08-10 05:30:00,098 INFO org.apache.hadoop.yarn.server.resourcemanager.amlauncher.AMLauncher: Setting up container Container: [ContainerId: container_1376111601621_0010_01_000001, NodeId: hadoop-221-3:43958, NodeHttpAddress: hadoop-221-3:8042, Resource: <memory:2048, vCores:1>, Priority: 0, State: NEW, Token: null, Status: container_id {, app_attempt_id {, application_id {, id: 10, cluster_timestamp: 1376111601621, }, attemptId: 1, }, id: 1, }, state: C_NEW, ] for AM appattempt_1376111601621_0010_000001
2013-08-10 05:30:00,098 INFO org.apache.hadoop.yarn.server.resourcemanager.amlauncher.AMLauncher: Command to launch container container_1376111601621_0010_01_000001 : $JAVA_HOME/bin/java -Dlog4j.configuration=container-log4j.properties -Dyarn.app.mapreduce.container.log.dir=<LOG_DIR> -Dyarn.app.mapreduce.container.log.filesize=0 -Dhadoop.root.logger=INFO,CLA  -Xmx1024m org.apache.hadoop.mapreduce.v2.app.MRAppMaster 1><LOG_DIR>/stdout 2><LOG_DIR>/stderr 
2013-08-10 05:30:00,289 INFO org.apache.hadoop.yarn.server.resourcemanager.rmcontainer.RMContainerImpl: container_1376111601621_0006_01_000001 Container Transitioned from ACQUIRED to RUNNING
2013-08-10 05:30:00,524 INFO org.apache.hadoop.yarn.server.resourcemanager.rmcontainer.RMContainerImpl: container_1376111601621_0007_01_000001 Container Transitioned from ACQUIRED to RUNNING
2013-08-10 05:30:00,836 INFO org.apache.hadoop.yarn.server.resourcemanager.rmcontainer.RMContainerImpl: container_1376111601621_0008_01_000001 Container Transitioned from ACQUIRED to RUNNING
2013-08-10 05:30:01,040 INFO org.apache.hadoop.yarn.server.resourcemanager.amlauncher.AMLauncher: Done launching container Container: [ContainerId: container_1376111601621_0010_01_000001, NodeId: hadoop-221-3:43958, NodeHttpAddress: hadoop-221-3:8042, Resource: <memory:2048, vCores:1>, Priority: 0, State: NEW, Token: null, Status: container_id {, app_attempt_id {, application_id {, id: 10, cluster_timestamp: 1376111601621, }, attemptId: 1, }, id: 1, }, state: C_NEW, ] for AM appattempt_1376111601621_0010_000001
2013-08-10 05:30:01,040 INFO org.apache.hadoop.yarn.server.resourcemanager.rmapp.attempt.RMAppAttemptImpl: appattempt_1376111601621_0010_000001 State change from ALLOCATED to LAUNCHED
2013-08-10 05:30:01,068 INFO org.apache.hadoop.yarn.server.resourcemanager.rmcontainer.RMContainerImpl: container_1376111601621_0009_01_000001 Container Transitioned from ACQUIRED to RUNNING
2013-08-10 05:30:01,123 INFO org.apache.hadoop.yarn.server.resourcemanager.rmcontainer.RMContainerImpl: container_1376111601621_0010_01_000001 Container Transitioned from ACQUIRED to RUNNING
2013-08-10 05:30:05,580 INFO org.apache.hadoop.yarn.server.resourcemanager.ApplicationMasterService: AM registration appattempt_1376111601621_0006_000001
2013-08-10 05:30:05,581 INFO org.apache.hadoop.yarn.server.resourcemanager.RMAuditLogger: USER=ubuntu	IP=192.168.100.40	OPERATION=Register App Master	TARGET=ApplicationMasterService	RESULT=SUCCESS	APPID=application_1376111601621_0006	APPATTEMPTID=appattempt_1376111601621_0006_000001
2013-08-10 05:30:05,581 INFO org.apache.hadoop.yarn.server.resourcemanager.rmapp.attempt.RMAppAttemptImpl: appattempt_1376111601621_0006_000001 State change from LAUNCHED to RUNNING
2013-08-10 05:30:05,582 INFO org.apache.hadoop.yarn.server.resourcemanager.rmapp.RMAppImpl: application_1376111601621_0006 State change from ACCEPTED to RUNNING
2013-08-10 05:30:05,592 INFO org.apache.hadoop.yarn.server.resourcemanager.ApplicationMasterService: AM registration appattempt_1376111601621_0007_000001
2013-08-10 05:30:05,592 INFO org.apache.hadoop.yarn.server.resourcemanager.RMAuditLogger: USER=ubuntu	IP=192.168.100.38	OPERATION=Register App Master	TARGET=ApplicationMasterService	RESULT=SUCCESS	APPID=application_1376111601621_0007	APPATTEMPTID=appattempt_1376111601621_0007_000001
2013-08-10 05:30:05,593 INFO org.apache.hadoop.yarn.server.resourcemanager.rmapp.attempt.RMAppAttemptImpl: appattempt_1376111601621_0007_000001 State change from LAUNCHED to RUNNING
2013-08-10 05:30:05,593 INFO org.apache.hadoop.yarn.server.resourcemanager.rmapp.RMAppImpl: application_1376111601621_0007 State change from ACCEPTED to RUNNING
2013-08-10 05:30:06,618 INFO org.apache.hadoop.yarn.server.resourcemanager.ApplicationMasterService: AM registration appattempt_1376111601621_0008_000001
2013-08-10 05:30:06,618 INFO org.apache.hadoop.yarn.server.resourcemanager.RMAuditLogger: USER=ubuntu	IP=192.168.100.42	OPERATION=Register App Master	TARGET=ApplicationMasterService	RESULT=SUCCESS	APPID=application_1376111601621_0008	APPATTEMPTID=appattempt_1376111601621_0008_000001
2013-08-10 05:30:06,620 INFO org.apache.hadoop.yarn.server.resourcemanager.rmapp.attempt.RMAppAttemptImpl: appattempt_1376111601621_0008_000001 State change from LAUNCHED to RUNNING
2013-08-10 05:30:06,620 INFO org.apache.hadoop.yarn.server.resourcemanager.rmapp.RMAppImpl: application_1376111601621_0008 State change from ACCEPTED to RUNNING
2013-08-10 05:30:06,649 INFO org.apache.hadoop.yarn.server.resourcemanager.rmcontainer.RMContainerImpl: container_1376111601621_0006_01_000002 Container Transitioned from NEW to ALLOCATED
2013-08-10 05:30:06,649 INFO org.apache.hadoop.yarn.server.resourcemanager.RMAuditLogger: USER=ubuntu	OPERATION=AM Allocated Container	TARGET=SchedulerApp	RESULT=SUCCESS	APPID=application_1376111601621_0006	CONTAINERID=container_1376111601621_0006_01_000002
2013-08-10 05:30:06,649 INFO org.apache.hadoop.yarn.server.resourcemanager.scheduler.common.fica.FiCaSchedulerNode: Assigned container container_1376111601621_0006_01_000002 of capacity <memory:1024, vCores:1> on host hadoop-221-2:55267, which currently has 1 containers, <memory:1024, vCores:1> used and <memory:7168, vCores:15> available
2013-08-10 05:30:06,650 INFO org.apache.hadoop.yarn.server.resourcemanager.scheduler.capacity.LeafQueue: assignedContainer application=application_1376111601621_0006 container=Container: [ContainerId: container_1376111601621_0006_01_000002, NodeId: hadoop-221-2:55267, NodeHttpAddress: hadoop-221-2:8042, Resource: <memory:1024, vCores:1>, Priority: 20, State: NEW, Token: null, Status: container_id {, app_attempt_id {, application_id {, id: 6, cluster_timestamp: 1376111601621, }, attemptId: 1, }, id: 2, }, state: C_NEW, ] containerId=container_1376111601621_0006_01_000002 queue=default: capacity=1.0, absoluteCapacity=1.0, usedResources=<memory:10240, vCores:5>usedCapacity=0.20833333, absoluteUsedCapacity=0.20833333, numApps=5, numContainers=5 usedCapacity=0.20833333 absoluteUsedCapacity=0.20833333 used=<memory:10240, vCores:5> cluster=<memory:49152, vCores:96>
2013-08-10 05:30:06,650 INFO org.apache.hadoop.yarn.server.resourcemanager.scheduler.capacity.ParentQueue: Re-sorting queues since queue: root.default stats: default: capacity=1.0, absoluteCapacity=1.0, usedResources=<memory:11264, vCores:6>usedCapacity=0.22916667, absoluteUsedCapacity=0.22916667, numApps=5, numContainers=6
2013-08-10 05:30:06,651 INFO org.apache.hadoop.yarn.server.resourcemanager.scheduler.capacity.ParentQueue: assignedContainer queue=root usedCapacity=0.22916667 absoluteUsedCapacity=0.22916667 used=<memory:11264, vCores:6> cluster=<memory:49152, vCores:96>
2013-08-10 05:30:06,651 INFO org.apache.hadoop.yarn.server.resourcemanager.rmcontainer.RMContainerImpl: container_1376111601621_0006_01_000003 Container Transitioned from NEW to ALLOCATED
2013-08-10 05:30:06,651 INFO org.apache.hadoop.yarn.server.resourcemanager.RMAuditLogger: USER=ubuntu	OPERATION=AM Allocated Container	TARGET=SchedulerApp	RESULT=SUCCESS	APPID=application_1376111601621_0006	CONTAINERID=container_1376111601621_0006_01_000003
2013-08-10 05:30:06,651 INFO org.apache.hadoop.yarn.server.resourcemanager.scheduler.common.fica.FiCaSchedulerNode: Assigned container container_1376111601621_0006_01_000003 of capacity <memory:1024, vCores:1> on host hadoop-221-2:55267, which currently has 2 containers, <memory:2048, vCores:2> used and <memory:6144, vCores:14> available
2013-08-10 05:30:06,653 INFO org.apache.hadoop.yarn.server.resourcemanager.scheduler.capacity.LeafQueue: assignedContainer application=application_1376111601621_0006 container=Container: [ContainerId: container_1376111601621_0006_01_000003, NodeId: hadoop-221-2:55267, NodeHttpAddress: hadoop-221-2:8042, Resource: <memory:1024, vCores:1>, Priority: 20, State: NEW, Token: null, Status: container_id {, app_attempt_id {, application_id {, id: 6, cluster_timestamp: 1376111601621, }, attemptId: 1, }, id: 3, }, state: C_NEW, ] containerId=container_1376111601621_0006_01_000003 queue=default: capacity=1.0, absoluteCapacity=1.0, usedResources=<memory:11264, vCores:6>usedCapacity=0.22916667, absoluteUsedCapacity=0.22916667, numApps=5, numContainers=6 usedCapacity=0.22916667 absoluteUsedCapacity=0.22916667 used=<memory:11264, vCores:6> cluster=<memory:49152, vCores:96>
2013-08-10 05:30:06,653 INFO org.apache.hadoop.yarn.server.resourcemanager.scheduler.capacity.ParentQueue: Re-sorting queues since queue: root.default stats: default: capacity=1.0, absoluteCapacity=1.0, usedResources=<memory:12288, vCores:7>usedCapacity=0.25, absoluteUsedCapacity=0.25, numApps=5, numContainers=7
2013-08-10 05:30:06,653 INFO org.apache.hadoop.yarn.server.resourcemanager.scheduler.capacity.ParentQueue: assignedContainer queue=root usedCapacity=0.25 absoluteUsedCapacity=0.25 used=<memory:12288, vCores:7> cluster=<memory:49152, vCores:96>
2013-08-10 05:30:06,653 INFO org.apache.hadoop.yarn.server.resourcemanager.rmcontainer.RMContainerImpl: container_1376111601621_0006_01_000004 Container Transitioned from NEW to ALLOCATED
2013-08-10 05:30:06,654 INFO org.apache.hadoop.yarn.server.resourcemanager.RMAuditLogger: USER=ubuntu	OPERATION=AM Allocated Container	TARGET=SchedulerApp	RESULT=SUCCESS	APPID=application_1376111601621_0006	CONTAINERID=container_1376111601621_0006_01_000004
2013-08-10 05:30:06,654 INFO org.apache.hadoop.yarn.server.resourcemanager.scheduler.common.fica.FiCaSchedulerNode: Assigned container container_1376111601621_0006_01_000004 of capacity <memory:1024, vCores:1> on host hadoop-221-2:55267, which currently has 3 containers, <memory:3072, vCores:3> used and <memory:5120, vCores:13> available
2013-08-10 05:30:06,655 INFO org.apache.hadoop.yarn.server.resourcemanager.scheduler.capacity.LeafQueue: assignedContainer application=application_1376111601621_0006 container=Container: [ContainerId: container_1376111601621_0006_01_000004, NodeId: hadoop-221-2:55267, NodeHttpAddress: hadoop-221-2:8042, Resource: <memory:1024, vCores:1>, Priority: 20, State: NEW, Token: null, Status: container_id {, app_attempt_id {, application_id {, id: 6, cluster_timestamp: 1376111601621, }, attemptId: 1, }, id: 4, }, state: C_NEW, ] containerId=container_1376111601621_0006_01_000004 queue=default: capacity=1.0, absoluteCapacity=1.0, usedResources=<memory:12288, vCores:7>usedCapacity=0.25, absoluteUsedCapacity=0.25, numApps=5, numContainers=7 usedCapacity=0.25 absoluteUsedCapacity=0.25 used=<memory:12288, vCores:7> cluster=<memory:49152, vCores:96>
2013-08-10 05:30:06,655 INFO org.apache.hadoop.yarn.server.resourcemanager.scheduler.capacity.ParentQueue: Re-sorting queues since queue: root.default stats: default: capacity=1.0, absoluteCapacity=1.0, usedResources=<memory:13312, vCores:8>usedCapacity=0.27083334, absoluteUsedCapacity=0.27083334, numApps=5, numContainers=8
2013-08-10 05:30:06,655 INFO org.apache.hadoop.yarn.server.resourcemanager.scheduler.capacity.ParentQueue: assignedContainer queue=root usedCapacity=0.27083334 absoluteUsedCapacity=0.27083334 used=<memory:13312, vCores:8> cluster=<memory:49152, vCores:96>
2013-08-10 05:30:06,656 INFO org.apache.hadoop.yarn.server.resourcemanager.rmcontainer.RMContainerImpl: container_1376111601621_0006_01_000005 Container Transitioned from NEW to ALLOCATED
2013-08-10 05:30:06,656 INFO org.apache.hadoop.yarn.server.resourcemanager.RMAuditLogger: USER=ubuntu	OPERATION=AM Allocated Container	TARGET=SchedulerApp	RESULT=SUCCESS	APPID=application_1376111601621_0006	CONTAINERID=container_1376111601621_0006_01_000005
2013-08-10 05:30:06,656 INFO org.apache.hadoop.yarn.server.resourcemanager.scheduler.common.fica.FiCaSchedulerNode: Assigned container container_1376111601621_0006_01_000005 of capacity <memory:1024, vCores:1> on host hadoop-221-2:55267, which currently has 4 containers, <memory:4096, vCores:4> used and <memory:4096, vCores:12> available
2013-08-10 05:30:06,657 INFO org.apache.hadoop.yarn.server.resourcemanager.scheduler.capacity.LeafQueue: assignedContainer application=application_1376111601621_0006 container=Container: [ContainerId: container_1376111601621_0006_01_000005, NodeId: hadoop-221-2:55267, NodeHttpAddress: hadoop-221-2:8042, Resource: <memory:1024, vCores:1>, Priority: 20, State: NEW, Token: null, Status: container_id {, app_attempt_id {, application_id {, id: 6, cluster_timestamp: 1376111601621, }, attemptId: 1, }, id: 5, }, state: C_NEW, ] containerId=container_1376111601621_0006_01_000005 queue=default: capacity=1.0, absoluteCapacity=1.0, usedResources=<memory:13312, vCores:8>usedCapacity=0.27083334, absoluteUsedCapacity=0.27083334, numApps=5, numContainers=8 usedCapacity=0.27083334 absoluteUsedCapacity=0.27083334 used=<memory:13312, vCores:8> cluster=<memory:49152, vCores:96>
2013-08-10 05:30:06,657 INFO org.apache.hadoop.yarn.server.resourcemanager.scheduler.capacity.ParentQueue: Re-sorting queues since queue: root.default stats: default: capacity=1.0, absoluteCapacity=1.0, usedResources=<memory:14336, vCores:9>usedCapacity=0.29166666, absoluteUsedCapacity=0.29166666, numApps=5, numContainers=9
2013-08-10 05:30:06,658 INFO org.apache.hadoop.yarn.server.resourcemanager.scheduler.capacity.ParentQueue: assignedContainer queue=root usedCapacity=0.29166666 absoluteUsedCapacity=0.29166666 used=<memory:14336, vCores:9> cluster=<memory:49152, vCores:96>
2013-08-10 05:30:06,658 INFO org.apache.hadoop.yarn.server.resourcemanager.rmcontainer.RMContainerImpl: container_1376111601621_0006_01_000006 Container Transitioned from NEW to ALLOCATED
2013-08-10 05:30:06,658 INFO org.apache.hadoop.yarn.server.resourcemanager.RMAuditLogger: USER=ubuntu	OPERATION=AM Allocated Container	TARGET=SchedulerApp	RESULT=SUCCESS	APPID=application_1376111601621_0006	CONTAINERID=container_1376111601621_0006_01_000006
2013-08-10 05:30:06,658 INFO org.apache.hadoop.yarn.server.resourcemanager.scheduler.common.fica.FiCaSchedulerNode: Assigned container container_1376111601621_0006_01_000006 of capacity <memory:1024, vCores:1> on host hadoop-221-2:55267, which currently has 5 containers, <memory:5120, vCores:5> used and <memory:3072, vCores:11> available
2013-08-10 05:30:06,659 INFO org.apache.hadoop.yarn.server.resourcemanager.scheduler.capacity.LeafQueue: assignedContainer application=application_1376111601621_0006 container=Container: [ContainerId: container_1376111601621_0006_01_000006, NodeId: hadoop-221-2:55267, NodeHttpAddress: hadoop-221-2:8042, Resource: <memory:1024, vCores:1>, Priority: 20, State: NEW, Token: null, Status: container_id {, app_attempt_id {, application_id {, id: 6, cluster_timestamp: 1376111601621, }, attemptId: 1, }, id: 6, }, state: C_NEW, ] containerId=container_1376111601621_0006_01_000006 queue=default: capacity=1.0, absoluteCapacity=1.0, usedResources=<memory:14336, vCores:9>usedCapacity=0.29166666, absoluteUsedCapacity=0.29166666, numApps=5, numContainers=9 usedCapacity=0.29166666 absoluteUsedCapacity=0.29166666 used=<memory:14336, vCores:9> cluster=<memory:49152, vCores:96>
2013-08-10 05:30:06,660 INFO org.apache.hadoop.yarn.server.resourcemanager.scheduler.capacity.ParentQueue: Re-sorting queues since queue: root.default stats: default: capacity=1.0, absoluteCapacity=1.0, usedResources=<memory:15360, vCores:10>usedCapacity=0.3125, absoluteUsedCapacity=0.3125, numApps=5, numContainers=10
2013-08-10 05:30:06,660 INFO org.apache.hadoop.yarn.server.resourcemanager.scheduler.capacity.ParentQueue: assignedContainer queue=root usedCapacity=0.3125 absoluteUsedCapacity=0.3125 used=<memory:15360, vCores:10> cluster=<memory:49152, vCores:96>
2013-08-10 05:30:06,660 INFO org.apache.hadoop.yarn.server.resourcemanager.rmcontainer.RMContainerImpl: container_1376111601621_0006_01_000007 Container Transitioned from NEW to ALLOCATED
2013-08-10 05:30:06,660 INFO org.apache.hadoop.yarn.server.resourcemanager.RMAuditLogger: USER=ubuntu	OPERATION=AM Allocated Container	TARGET=SchedulerApp	RESULT=SUCCESS	APPID=application_1376111601621_0006	CONTAINERID=container_1376111601621_0006_01_000007
2013-08-10 05:30:06,661 INFO org.apache.hadoop.yarn.server.resourcemanager.scheduler.common.fica.FiCaSchedulerNode: Assigned container container_1376111601621_0006_01_000007 of capacity <memory:1024, vCores:1> on host hadoop-221-2:55267, which currently has 6 containers, <memory:6144, vCores:6> used and <memory:2048, vCores:10> available
2013-08-10 05:30:06,662 INFO org.apache.hadoop.yarn.server.resourcemanager.scheduler.capacity.LeafQueue: assignedContainer application=application_1376111601621_0006 container=Container: [ContainerId: container_1376111601621_0006_01_000007, NodeId: hadoop-221-2:55267, NodeHttpAddress: hadoop-221-2:8042, Resource: <memory:1024, vCores:1>, Priority: 20, State: NEW, Token: null, Status: container_id {, app_attempt_id {, application_id {, id: 6, cluster_timestamp: 1376111601621, }, attemptId: 1, }, id: 7, }, state: C_NEW, ] containerId=container_1376111601621_0006_01_000007 queue=default: capacity=1.0, absoluteCapacity=1.0, usedResources=<memory:15360, vCores:10>usedCapacity=0.3125, absoluteUsedCapacity=0.3125, numApps=5, numContainers=10 usedCapacity=0.3125 absoluteUsedCapacity=0.3125 used=<memory:15360, vCores:10> cluster=<memory:49152, vCores:96>
2013-08-10 05:30:06,662 INFO org.apache.hadoop.yarn.server.resourcemanager.scheduler.capacity.ParentQueue: Re-sorting queues since queue: root.default stats: default: capacity=1.0, absoluteCapacity=1.0, usedResources=<memory:16384, vCores:11>usedCapacity=0.33333334, absoluteUsedCapacity=0.33333334, numApps=5, numContainers=11
2013-08-10 05:30:06,662 INFO org.apache.hadoop.yarn.server.resourcemanager.scheduler.capacity.ParentQueue: assignedContainer queue=root usedCapacity=0.33333334 absoluteUsedCapacity=0.33333334 used=<memory:16384, vCores:11> cluster=<memory:49152, vCores:96>
2013-08-10 05:30:06,662 INFO org.apache.hadoop.yarn.server.resourcemanager.rmcontainer.RMContainerImpl: container_1376111601621_0006_01_000008 Container Transitioned from NEW to ALLOCATED
2013-08-10 05:30:06,663 INFO org.apache.hadoop.yarn.server.resourcemanager.RMAuditLogger: USER=ubuntu	OPERATION=AM Allocated Container	TARGET=SchedulerApp	RESULT=SUCCESS	APPID=application_1376111601621_0006	CONTAINERID=container_1376111601621_0006_01_000008
2013-08-10 05:30:06,663 INFO org.apache.hadoop.yarn.server.resourcemanager.scheduler.common.fica.FiCaSchedulerNode: Assigned container container_1376111601621_0006_01_000008 of capacity <memory:1024, vCores:1> on host hadoop-221-2:55267, which currently has 7 containers, <memory:7168, vCores:7> used and <memory:1024, vCores:9> available
2013-08-10 05:30:06,664 INFO org.apache.hadoop.yarn.server.resourcemanager.scheduler.capacity.LeafQueue: assignedContainer application=application_1376111601621_0006 container=Container: [ContainerId: container_1376111601621_0006_01_000008, NodeId: hadoop-221-2:55267, NodeHttpAddress: hadoop-221-2:8042, Resource: <memory:1024, vCores:1>, Priority: 20, State: NEW, Token: null, Status: container_id {, app_attempt_id {, application_id {, id: 6, cluster_timestamp: 1376111601621, }, attemptId: 1, }, id: 8, }, state: C_NEW, ] containerId=container_1376111601621_0006_01_000008 queue=default: capacity=1.0, absoluteCapacity=1.0, usedResources=<memory:16384, vCores:11>usedCapacity=0.33333334, absoluteUsedCapacity=0.33333334, numApps=5, numContainers=11 usedCapacity=0.33333334 absoluteUsedCapacity=0.33333334 used=<memory:16384, vCores:11> cluster=<memory:49152, vCores:96>
2013-08-10 05:30:06,664 INFO org.apache.hadoop.yarn.server.resourcemanager.scheduler.capacity.ParentQueue: Re-sorting queues since queue: root.default stats: default: capacity=1.0, absoluteCapacity=1.0, usedResources=<memory:17408, vCores:12>usedCapacity=0.35416666, absoluteUsedCapacity=0.35416666, numApps=5, numContainers=12
2013-08-10 05:30:06,664 INFO org.apache.hadoop.yarn.server.resourcemanager.scheduler.capacity.ParentQueue: assignedContainer queue=root usedCapacity=0.35416666 absoluteUsedCapacity=0.35416666 used=<memory:17408, vCores:12> cluster=<memory:49152, vCores:96>
2013-08-10 05:30:06,665 INFO org.apache.hadoop.yarn.server.resourcemanager.rmcontainer.RMContainerImpl: container_1376111601621_0006_01_000009 Container Transitioned from NEW to ALLOCATED
2013-08-10 05:30:06,665 INFO org.apache.hadoop.yarn.server.resourcemanager.RMAuditLogger: USER=ubuntu	OPERATION=AM Allocated Container	TARGET=SchedulerApp	RESULT=SUCCESS	APPID=application_1376111601621_0006	CONTAINERID=container_1376111601621_0006_01_000009
2013-08-10 05:30:06,665 INFO org.apache.hadoop.yarn.server.resourcemanager.scheduler.common.fica.FiCaSchedulerNode: Assigned container container_1376111601621_0006_01_000009 of capacity <memory:1024, vCores:1> on host hadoop-221-2:55267, which currently has 8 containers, <memory:8192, vCores:8> used and <memory:0, vCores:8> available
2013-08-10 05:30:06,666 INFO org.apache.hadoop.yarn.server.resourcemanager.scheduler.capacity.LeafQueue: assignedContainer application=application_1376111601621_0006 container=Container: [ContainerId: container_1376111601621_0006_01_000009, NodeId: hadoop-221-2:55267, NodeHttpAddress: hadoop-221-2:8042, Resource: <memory:1024, vCores:1>, Priority: 20, State: NEW, Token: null, Status: container_id {, app_attempt_id {, application_id {, id: 6, cluster_timestamp: 1376111601621, }, attemptId: 1, }, id: 9, }, state: C_NEW, ] containerId=container_1376111601621_0006_01_000009 queue=default: capacity=1.0, absoluteCapacity=1.0, usedResources=<memory:17408, vCores:12>usedCapacity=0.35416666, absoluteUsedCapacity=0.35416666, numApps=5, numContainers=12 usedCapacity=0.35416666 absoluteUsedCapacity=0.35416666 used=<memory:17408, vCores:12> cluster=<memory:49152, vCores:96>
2013-08-10 05:30:06,666 INFO org.apache.hadoop.yarn.server.resourcemanager.scheduler.capacity.ParentQueue: Re-sorting queues since queue: root.default stats: default: capacity=1.0, absoluteCapacity=1.0, usedResources=<memory:18432, vCores:13>usedCapacity=0.375, absoluteUsedCapacity=0.375, numApps=5, numContainers=13
2013-08-10 05:30:06,666 INFO org.apache.hadoop.yarn.server.resourcemanager.scheduler.capacity.ParentQueue: assignedContainer queue=root usedCapacity=0.375 absoluteUsedCapacity=0.375 used=<memory:18432, vCores:13> cluster=<memory:49152, vCores:96>
2013-08-10 05:30:06,862 INFO org.apache.hadoop.yarn.server.resourcemanager.rmcontainer.RMContainerImpl: container_1376111601621_0006_01_000010 Container Transitioned from NEW to ALLOCATED
2013-08-10 05:30:06,862 INFO org.apache.hadoop.yarn.server.resourcemanager.RMAuditLogger: USER=ubuntu	OPERATION=AM Allocated Container	TARGET=SchedulerApp	RESULT=SUCCESS	APPID=application_1376111601621_0006	CONTAINERID=container_1376111601621_0006_01_000010
2013-08-10 05:30:06,862 INFO org.apache.hadoop.yarn.server.resourcemanager.scheduler.common.fica.FiCaSchedulerNode: Assigned container container_1376111601621_0006_01_000010 of capacity <memory:1024, vCores:1> on host hadoop-221-7:34609, which currently has 2 containers, <memory:3072, vCores:2> used and <memory:5120, vCores:14> available
2013-08-10 05:30:06,863 INFO org.apache.hadoop.yarn.server.resourcemanager.scheduler.capacity.LeafQueue: assignedContainer application=application_1376111601621_0006 container=Container: [ContainerId: container_1376111601621_0006_01_000010, NodeId: hadoop-221-7:34609, NodeHttpAddress: hadoop-221-7:8042, Resource: <memory:1024, vCores:1>, Priority: 20, State: NEW, Token: null, Status: container_id {, app_attempt_id {, application_id {, id: 6, cluster_timestamp: 1376111601621, }, attemptId: 1, }, id: 10, }, state: C_NEW, ] containerId=container_1376111601621_0006_01_000010 queue=default: capacity=1.0, absoluteCapacity=1.0, usedResources=<memory:18432, vCores:13>usedCapacity=0.375, absoluteUsedCapacity=0.375, numApps=5, numContainers=13 usedCapacity=0.375 absoluteUsedCapacity=0.375 used=<memory:18432, vCores:13> cluster=<memory:49152, vCores:96>
2013-08-10 05:30:06,864 INFO org.apache.hadoop.yarn.server.resourcemanager.scheduler.capacity.ParentQueue: Re-sorting queues since queue: root.default stats: default: capacity=1.0, absoluteCapacity=1.0, usedResources=<memory:19456, vCores:14>usedCapacity=0.39583334, absoluteUsedCapacity=0.39583334, numApps=5, numContainers=14
2013-08-10 05:30:06,864 INFO org.apache.hadoop.yarn.server.resourcemanager.scheduler.capacity.ParentQueue: assignedContainer queue=root usedCapacity=0.39583334 absoluteUsedCapacity=0.39583334 used=<memory:19456, vCores:14> cluster=<memory:49152, vCores:96>
2013-08-10 05:30:06,864 INFO org.apache.hadoop.yarn.server.resourcemanager.rmcontainer.RMContainerImpl: container_1376111601621_0006_01_000011 Container Transitioned from NEW to ALLOCATED
2013-08-10 05:30:06,864 INFO org.apache.hadoop.yarn.server.resourcemanager.RMAuditLogger: USER=ubuntu	OPERATION=AM Allocated Container	TARGET=SchedulerApp	RESULT=SUCCESS	APPID=application_1376111601621_0006	CONTAINERID=container_1376111601621_0006_01_000011
2013-08-10 05:30:06,865 INFO org.apache.hadoop.yarn.server.resourcemanager.scheduler.common.fica.FiCaSchedulerNode: Assigned container container_1376111601621_0006_01_000011 of capacity <memory:1024, vCores:1> on host hadoop-221-7:34609, which currently has 3 containers, <memory:4096, vCores:3> used and <memory:4096, vCores:13> available
2013-08-10 05:30:06,866 INFO org.apache.hadoop.yarn.server.resourcemanager.scheduler.capacity.LeafQueue: assignedContainer application=application_1376111601621_0006 container=Container: [ContainerId: container_1376111601621_0006_01_000011, NodeId: hadoop-221-7:34609, NodeHttpAddress: hadoop-221-7:8042, Resource: <memory:1024, vCores:1>, Priority: 20, State: NEW, Token: null, Status: container_id {, app_attempt_id {, application_id {, id: 6, cluster_timestamp: 1376111601621, }, attemptId: 1, }, id: 11, }, state: C_NEW, ] containerId=container_1376111601621_0006_01_000011 queue=default: capacity=1.0, absoluteCapacity=1.0, usedResources=<memory:19456, vCores:14>usedCapacity=0.39583334, absoluteUsedCapacity=0.39583334, numApps=5, numContainers=14 usedCapacity=0.39583334 absoluteUsedCapacity=0.39583334 used=<memory:19456, vCores:14> cluster=<memory:49152, vCores:96>
2013-08-10 05:30:06,866 INFO org.apache.hadoop.yarn.server.resourcemanager.scheduler.capacity.ParentQueue: Re-sorting queues since queue: root.default stats: default: capacity=1.0, absoluteCapacity=1.0, usedResources=<memory:20480, vCores:15>usedCapacity=0.41666666, absoluteUsedCapacity=0.41666666, numApps=5, numContainers=15
2013-08-10 05:30:06,866 INFO org.apache.hadoop.yarn.server.resourcemanager.scheduler.capacity.ParentQueue: assignedContainer queue=root usedCapacity=0.41666666 absoluteUsedCapacity=0.41666666 used=<memory:20480, vCores:15> cluster=<memory:49152, vCores:96>
2013-08-10 05:30:06,867 INFO org.apache.hadoop.yarn.server.resourcemanager.rmcontainer.RMContainerImpl: container_1376111601621_0006_01_000012 Container Transitioned from NEW to ALLOCATED
2013-08-10 05:30:06,867 INFO org.apache.hadoop.yarn.server.resourcemanager.RMAuditLogger: USER=ubuntu	OPERATION=AM Allocated Container	TARGET=SchedulerApp	RESULT=SUCCESS	APPID=application_1376111601621_0006	CONTAINERID=container_1376111601621_0006_01_000012
2013-08-10 05:30:06,867 INFO org.apache.hadoop.yarn.server.resourcemanager.scheduler.common.fica.FiCaSchedulerNode: Assigned container container_1376111601621_0006_01_000012 of capacity <memory:1024, vCores:1> on host hadoop-221-7:34609, which currently has 4 containers, <memory:5120, vCores:4> used and <memory:3072, vCores:12> available
2013-08-10 05:30:06,868 INFO org.apache.hadoop.yarn.server.resourcemanager.scheduler.capacity.LeafQueue: assignedContainer application=application_1376111601621_0006 container=Container: [ContainerId: container_1376111601621_0006_01_000012, NodeId: hadoop-221-7:34609, NodeHttpAddress: hadoop-221-7:8042, Resource: <memory:1024, vCores:1>, Priority: 20, State: NEW, Token: null, Status: container_id {, app_attempt_id {, application_id {, id: 6, cluster_timestamp: 1376111601621, }, attemptId: 1, }, id: 12, }, state: C_NEW, ] containerId=container_1376111601621_0006_01_000012 queue=default: capacity=1.0, absoluteCapacity=1.0, usedResources=<memory:20480, vCores:15>usedCapacity=0.41666666, absoluteUsedCapacity=0.41666666, numApps=5, numContainers=15 usedCapacity=0.41666666 absoluteUsedCapacity=0.41666666 used=<memory:20480, vCores:15> cluster=<memory:49152, vCores:96>
2013-08-10 05:30:06,868 INFO org.apache.hadoop.yarn.server.resourcemanager.scheduler.capacity.ParentQueue: Re-sorting queues since queue: root.default stats: default: capacity=1.0, absoluteCapacity=1.0, usedResources=<memory:21504, vCores:16>usedCapacity=0.4375, absoluteUsedCapacity=0.4375, numApps=5, numContainers=16
2013-08-10 05:30:06,869 INFO org.apache.hadoop.yarn.server.resourcemanager.scheduler.capacity.ParentQueue: assignedContainer queue=root usedCapacity=0.4375 absoluteUsedCapacity=0.4375 used=<memory:21504, vCores:16> cluster=<memory:49152, vCores:96>
2013-08-10 05:30:06,869 INFO org.apache.hadoop.yarn.server.resourcemanager.rmcontainer.RMContainerImpl: container_1376111601621_0006_01_000013 Container Transitioned from NEW to ALLOCATED
2013-08-10 05:30:06,869 INFO org.apache.hadoop.yarn.server.resourcemanager.RMAuditLogger: USER=ubuntu	OPERATION=AM Allocated Container	TARGET=SchedulerApp	RESULT=SUCCESS	APPID=application_1376111601621_0006	CONTAINERID=container_1376111601621_0006_01_000013
2013-08-10 05:30:06,869 INFO org.apache.hadoop.yarn.server.resourcemanager.scheduler.common.fica.FiCaSchedulerNode: Assigned container container_1376111601621_0006_01_000013 of capacity <memory:1024, vCores:1> on host hadoop-221-7:34609, which currently has 5 containers, <memory:6144, vCores:5> used and <memory:2048, vCores:11> available
2013-08-10 05:30:06,870 INFO org.apache.hadoop.yarn.server.resourcemanager.scheduler.capacity.LeafQueue: assignedContainer application=application_1376111601621_0006 container=Container: [ContainerId: container_1376111601621_0006_01_000013, NodeId: hadoop-221-7:34609, NodeHttpAddress: hadoop-221-7:8042, Resource: <memory:1024, vCores:1>, Priority: 20, State: NEW, Token: null, Status: container_id {, app_attempt_id {, application_id {, id: 6, cluster_timestamp: 1376111601621, }, attemptId: 1, }, id: 13, }, state: C_NEW, ] containerId=container_1376111601621_0006_01_000013 queue=default: capacity=1.0, absoluteCapacity=1.0, usedResources=<memory:21504, vCores:16>usedCapacity=0.4375, absoluteUsedCapacity=0.4375, numApps=5, numContainers=16 usedCapacity=0.4375 absoluteUsedCapacity=0.4375 used=<memory:21504, vCores:16> cluster=<memory:49152, vCores:96>
2013-08-10 05:30:06,871 INFO org.apache.hadoop.yarn.server.resourcemanager.scheduler.capacity.ParentQueue: Re-sorting queues since queue: root.default stats: default: capacity=1.0, absoluteCapacity=1.0, usedResources=<memory:22528, vCores:17>usedCapacity=0.45833334, absoluteUsedCapacity=0.45833334, numApps=5, numContainers=17
2013-08-10 05:30:06,871 INFO org.apache.hadoop.yarn.server.resourcemanager.scheduler.capacity.ParentQueue: assignedContainer queue=root usedCapacity=0.45833334 absoluteUsedCapacity=0.45833334 used=<memory:22528, vCores:17> cluster=<memory:49152, vCores:96>
2013-08-10 05:30:06,871 INFO org.apache.hadoop.yarn.server.resourcemanager.rmcontainer.RMContainerImpl: container_1376111601621_0006_01_000014 Container Transitioned from NEW to ALLOCATED
2013-08-10 05:30:06,871 INFO org.apache.hadoop.yarn.server.resourcemanager.RMAuditLogger: USER=ubuntu	OPERATION=AM Allocated Container	TARGET=SchedulerApp	RESULT=SUCCESS	APPID=application_1376111601621_0006	CONTAINERID=container_1376111601621_0006_01_000014
2013-08-10 05:30:06,872 INFO org.apache.hadoop.yarn.server.resourcemanager.scheduler.common.fica.FiCaSchedulerNode: Assigned container container_1376111601621_0006_01_000014 of capacity <memory:1024, vCores:1> on host hadoop-221-7:34609, which currently has 6 containers, <memory:7168, vCores:6> used and <memory:1024, vCores:10> available
2013-08-10 05:30:06,873 INFO org.apache.hadoop.yarn.server.resourcemanager.scheduler.capacity.LeafQueue: assignedContainer application=application_1376111601621_0006 container=Container: [ContainerId: container_1376111601621_0006_01_000014, NodeId: hadoop-221-7:34609, NodeHttpAddress: hadoop-221-7:8042, Resource: <memory:1024, vCores:1>, Priority: 20, State: NEW, Token: null, Status: container_id {, app_attempt_id {, application_id {, id: 6, cluster_timestamp: 1376111601621, }, attemptId: 1, }, id: 14, }, state: C_NEW, ] containerId=container_1376111601621_0006_01_000014 queue=default: capacity=1.0, absoluteCapacity=1.0, usedResources=<memory:22528, vCores:17>usedCapacity=0.45833334, absoluteUsedCapacity=0.45833334, numApps=5, numContainers=17 usedCapacity=0.45833334 absoluteUsedCapacity=0.45833334 used=<memory:22528, vCores:17> cluster=<memory:49152, vCores:96>
2013-08-10 05:30:06,873 INFO org.apache.hadoop.yarn.server.resourcemanager.scheduler.capacity.ParentQueue: Re-sorting queues since queue: root.default stats: default: capacity=1.0, absoluteCapacity=1.0, usedResources=<memory:23552, vCores:18>usedCapacity=0.47916666, absoluteUsedCapacity=0.47916666, numApps=5, numContainers=18
2013-08-10 05:30:06,873 INFO org.apache.hadoop.yarn.server.resourcemanager.scheduler.capacity.ParentQueue: assignedContainer queue=root usedCapacity=0.47916666 absoluteUsedCapacity=0.47916666 used=<memory:23552, vCores:18> cluster=<memory:49152, vCores:96>
2013-08-10 05:30:06,873 INFO org.apache.hadoop.yarn.server.resourcemanager.rmcontainer.RMContainerImpl: container_1376111601621_0006_01_000015 Container Transitioned from NEW to ALLOCATED
2013-08-10 05:30:06,874 INFO org.apache.hadoop.yarn.server.resourcemanager.RMAuditLogger: USER=ubuntu	OPERATION=AM Allocated Container	TARGET=SchedulerApp	RESULT=SUCCESS	APPID=application_1376111601621_0006	CONTAINERID=container_1376111601621_0006_01_000015
2013-08-10 05:30:06,874 INFO org.apache.hadoop.yarn.server.resourcemanager.scheduler.common.fica.FiCaSchedulerNode: Assigned container container_1376111601621_0006_01_000015 of capacity <memory:1024, vCores:1> on host hadoop-221-7:34609, which currently has 7 containers, <memory:8192, vCores:7> used and <memory:0, vCores:9> available
2013-08-10 05:30:06,875 INFO org.apache.hadoop.yarn.server.resourcemanager.scheduler.capacity.LeafQueue: assignedContainer application=application_1376111601621_0006 container=Container: [ContainerId: container_1376111601621_0006_01_000015, NodeId: hadoop-221-7:34609, NodeHttpAddress: hadoop-221-7:8042, Resource: <memory:1024, vCores:1>, Priority: 20, State: NEW, Token: null, Status: container_id {, app_attempt_id {, application_id {, id: 6, cluster_timestamp: 1376111601621, }, attemptId: 1, }, id: 15, }, state: C_NEW, ] containerId=container_1376111601621_0006_01_000015 queue=default: capacity=1.0, absoluteCapacity=1.0, usedResources=<memory:23552, vCores:18>usedCapacity=0.47916666, absoluteUsedCapacity=0.47916666, numApps=5, numContainers=18 usedCapacity=0.47916666 absoluteUsedCapacity=0.47916666 used=<memory:23552, vCores:18> cluster=<memory:49152, vCores:96>
2013-08-10 05:30:06,875 INFO org.apache.hadoop.yarn.server.resourcemanager.scheduler.capacity.ParentQueue: Re-sorting queues since queue: root.default stats: default: capacity=1.0, absoluteCapacity=1.0, usedResources=<memory:24576, vCores:19>usedCapacity=0.5, absoluteUsedCapacity=0.5, numApps=5, numContainers=19
2013-08-10 05:30:06,875 INFO org.apache.hadoop.yarn.server.resourcemanager.scheduler.capacity.ParentQueue: assignedContainer queue=root usedCapacity=0.5 absoluteUsedCapacity=0.5 used=<memory:24576, vCores:19> cluster=<memory:49152, vCores:96>
2013-08-10 05:30:06,944 INFO org.apache.hadoop.yarn.server.resourcemanager.ApplicationMasterService: AM registration appattempt_1376111601621_0009_000001
2013-08-10 05:30:06,944 INFO org.apache.hadoop.yarn.server.resourcemanager.RMAuditLogger: USER=ubuntu	IP=192.168.100.39	OPERATION=Register App Master	TARGET=ApplicationMasterService	RESULT=SUCCESS	APPID=application_1376111601621_0009	APPATTEMPTID=appattempt_1376111601621_0009_000001
2013-08-10 05:30:06,946 INFO org.apache.hadoop.yarn.server.resourcemanager.rmapp.attempt.RMAppAttemptImpl: appattempt_1376111601621_0009_000001 State change from LAUNCHED to RUNNING
2013-08-10 05:30:06,946 INFO org.apache.hadoop.yarn.server.resourcemanager.rmapp.RMAppImpl: application_1376111601621_0009 State change from ACCEPTED to RUNNING
2013-08-10 05:30:07,096 INFO org.apache.hadoop.yarn.server.resourcemanager.rmcontainer.RMContainerImpl: container_1376111601621_0006_01_000016 Container Transitioned from NEW to ALLOCATED
2013-08-10 05:30:07,096 INFO org.apache.hadoop.yarn.server.resourcemanager.RMAuditLogger: USER=ubuntu	OPERATION=AM Allocated Container	TARGET=SchedulerApp	RESULT=SUCCESS	APPID=application_1376111601621_0006	CONTAINERID=container_1376111601621_0006_01_000016
2013-08-10 05:30:07,097 INFO org.apache.hadoop.yarn.server.resourcemanager.scheduler.common.fica.FiCaSchedulerNode: Assigned container container_1376111601621_0006_01_000016 of capacity <memory:1024, vCores:1> on host hadoop-221-5:42694, which currently has 2 containers, <memory:3072, vCores:2> used and <memory:5120, vCores:14> available
2013-08-10 05:30:07,098 INFO org.apache.hadoop.yarn.server.resourcemanager.scheduler.capacity.LeafQueue: assignedContainer application=application_1376111601621_0006 container=Container: [ContainerId: container_1376111601621_0006_01_000016, NodeId: hadoop-221-5:42694, NodeHttpAddress: hadoop-221-5:8042, Resource: <memory:1024, vCores:1>, Priority: 20, State: NEW, Token: null, Status: container_id {, app_attempt_id {, application_id {, id: 6, cluster_timestamp: 1376111601621, }, attemptId: 1, }, id: 16, }, state: C_NEW, ] containerId=container_1376111601621_0006_01_000016 queue=default: capacity=1.0, absoluteCapacity=1.0, usedResources=<memory:24576, vCores:19>usedCapacity=0.5, absoluteUsedCapacity=0.5, numApps=5, numContainers=19 usedCapacity=0.5 absoluteUsedCapacity=0.5 used=<memory:24576, vCores:19> cluster=<memory:49152, vCores:96>
2013-08-10 05:30:07,098 INFO org.apache.hadoop.yarn.server.resourcemanager.scheduler.capacity.ParentQueue: Re-sorting queues since queue: root.default stats: default: capacity=1.0, absoluteCapacity=1.0, usedResources=<memory:25600, vCores:20>usedCapacity=0.5208333, absoluteUsedCapacity=0.5208333, numApps=5, numContainers=20
2013-08-10 05:30:07,098 INFO org.apache.hadoop.yarn.server.resourcemanager.scheduler.capacity.ParentQueue: assignedContainer queue=root usedCapacity=0.5208333 absoluteUsedCapacity=0.5208333 used=<memory:25600, vCores:20> cluster=<memory:49152, vCores:96>
2013-08-10 05:30:07,099 INFO org.apache.hadoop.yarn.server.resourcemanager.rmcontainer.RMContainerImpl: container_1376111601621_0006_01_000017 Container Transitioned from NEW to ALLOCATED
2013-08-10 05:30:07,099 INFO org.apache.hadoop.yarn.server.resourcemanager.RMAuditLogger: USER=ubuntu	OPERATION=AM Allocated Container	TARGET=SchedulerApp	RESULT=SUCCESS	APPID=application_1376111601621_0006	CONTAINERID=container_1376111601621_0006_01_000017
2013-08-10 05:30:07,099 INFO org.apache.hadoop.yarn.server.resourcemanager.scheduler.common.fica.FiCaSchedulerNode: Assigned container container_1376111601621_0006_01_000017 of capacity <memory:1024, vCores:1> on host hadoop-221-5:42694, which currently has 3 containers, <memory:4096, vCores:3> used and <memory:4096, vCores:13> available
2013-08-10 05:30:07,100 INFO org.apache.hadoop.yarn.server.resourcemanager.scheduler.capacity.LeafQueue: assignedContainer application=application_1376111601621_0006 container=Container: [ContainerId: container_1376111601621_0006_01_000017, NodeId: hadoop-221-5:42694, NodeHttpAddress: hadoop-221-5:8042, Resource: <memory:1024, vCores:1>, Priority: 20, State: NEW, Token: null, Status: container_id {, app_attempt_id {, application_id {, id: 6, cluster_timestamp: 1376111601621, }, attemptId: 1, }, id: 17, }, state: C_NEW, ] containerId=container_1376111601621_0006_01_000017 queue=default: capacity=1.0, absoluteCapacity=1.0, usedResources=<memory:25600, vCores:20>usedCapacity=0.5208333, absoluteUsedCapacity=0.5208333, numApps=5, numContainers=20 usedCapacity=0.5208333 absoluteUsedCapacity=0.5208333 used=<memory:25600, vCores:20> cluster=<memory:49152, vCores:96>
2013-08-10 05:30:07,100 INFO org.apache.hadoop.yarn.server.resourcemanager.scheduler.capacity.ParentQueue: Re-sorting queues since queue: root.default stats: default: capacity=1.0, absoluteCapacity=1.0, usedResources=<memory:26624, vCores:21>usedCapacity=0.5416667, absoluteUsedCapacity=0.5416667, numApps=5, numContainers=21
2013-08-10 05:30:07,100 INFO org.apache.hadoop.yarn.server.resourcemanager.scheduler.capacity.ParentQueue: assignedContainer queue=root usedCapacity=0.5416667 absoluteUsedCapacity=0.5416667 used=<memory:26624, vCores:21> cluster=<memory:49152, vCores:96>
2013-08-10 05:30:07,101 INFO org.apache.hadoop.yarn.server.resourcemanager.rmcontainer.RMContainerImpl: container_1376111601621_0006_01_000018 Container Transitioned from NEW to ALLOCATED
2013-08-10 05:30:07,101 INFO org.apache.hadoop.yarn.server.resourcemanager.RMAuditLogger: USER=ubuntu	OPERATION=AM Allocated Container	TARGET=SchedulerApp	RESULT=SUCCESS	APPID=application_1376111601621_0006	CONTAINERID=container_1376111601621_0006_01_000018
2013-08-10 05:30:07,101 INFO org.apache.hadoop.yarn.server.resourcemanager.scheduler.common.fica.FiCaSchedulerNode: Assigned container container_1376111601621_0006_01_000018 of capacity <memory:1024, vCores:1> on host hadoop-221-5:42694, which currently has 4 containers, <memory:5120, vCores:4> used and <memory:3072, vCores:12> available
2013-08-10 05:30:07,102 INFO org.apache.hadoop.yarn.server.resourcemanager.scheduler.capacity.LeafQueue: assignedContainer application=application_1376111601621_0006 container=Container: [ContainerId: container_1376111601621_0006_01_000018, NodeId: hadoop-221-5:42694, NodeHttpAddress: hadoop-221-5:8042, Resource: <memory:1024, vCores:1>, Priority: 20, State: NEW, Token: null, Status: container_id {, app_attempt_id {, application_id {, id: 6, cluster_timestamp: 1376111601621, }, attemptId: 1, }, id: 18, }, state: C_NEW, ] containerId=container_1376111601621_0006_01_000018 queue=default: capacity=1.0, absoluteCapacity=1.0, usedResources=<memory:26624, vCores:21>usedCapacity=0.5416667, absoluteUsedCapacity=0.5416667, numApps=5, numContainers=21 usedCapacity=0.5416667 absoluteUsedCapacity=0.5416667 used=<memory:26624, vCores:21> cluster=<memory:49152, vCores:96>
2013-08-10 05:30:07,102 INFO org.apache.hadoop.yarn.server.resourcemanager.scheduler.capacity.ParentQueue: Re-sorting queues since queue: root.default stats: default: capacity=1.0, absoluteCapacity=1.0, usedResources=<memory:27648, vCores:22>usedCapacity=0.5625, absoluteUsedCapacity=0.5625, numApps=5, numContainers=22
2013-08-10 05:30:07,102 INFO org.apache.hadoop.yarn.server.resourcemanager.scheduler.capacity.ParentQueue: assignedContainer queue=root usedCapacity=0.5625 absoluteUsedCapacity=0.5625 used=<memory:27648, vCores:22> cluster=<memory:49152, vCores:96>
2013-08-10 05:30:07,103 INFO org.apache.hadoop.yarn.server.resourcemanager.rmcontainer.RMContainerImpl: container_1376111601621_0006_01_000019 Container Transitioned from NEW to ALLOCATED
2013-08-10 05:30:07,103 INFO org.apache.hadoop.yarn.server.resourcemanager.RMAuditLogger: USER=ubuntu	OPERATION=AM Allocated Container	TARGET=SchedulerApp	RESULT=SUCCESS	APPID=application_1376111601621_0006	CONTAINERID=container_1376111601621_0006_01_000019
2013-08-10 05:30:07,103 INFO org.apache.hadoop.yarn.server.resourcemanager.scheduler.common.fica.FiCaSchedulerNode: Assigned container container_1376111601621_0006_01_000019 of capacity <memory:1024, vCores:1> on host hadoop-221-5:42694, which currently has 5 containers, <memory:6144, vCores:5> used and <memory:2048, vCores:11> available
2013-08-10 05:30:07,104 INFO org.apache.hadoop.yarn.server.resourcemanager.scheduler.capacity.LeafQueue: assignedContainer application=application_1376111601621_0006 container=Container: [ContainerId: container_1376111601621_0006_01_000019, NodeId: hadoop-221-5:42694, NodeHttpAddress: hadoop-221-5:8042, Resource: <memory:1024, vCores:1>, Priority: 20, State: NEW, Token: null, Status: container_id {, app_attempt_id {, application_id {, id: 6, cluster_timestamp: 1376111601621, }, attemptId: 1, }, id: 19, }, state: C_NEW, ] containerId=container_1376111601621_0006_01_000019 queue=default: capacity=1.0, absoluteCapacity=1.0, usedResources=<memory:27648, vCores:22>usedCapacity=0.5625, absoluteUsedCapacity=0.5625, numApps=5, numContainers=22 usedCapacity=0.5625 absoluteUsedCapacity=0.5625 used=<memory:27648, vCores:22> cluster=<memory:49152, vCores:96>
2013-08-10 05:30:07,104 INFO org.apache.hadoop.yarn.server.resourcemanager.scheduler.capacity.ParentQueue: Re-sorting queues since queue: root.default stats: default: capacity=1.0, absoluteCapacity=1.0, usedResources=<memory:28672, vCores:23>usedCapacity=0.5833333, absoluteUsedCapacity=0.5833333, numApps=5, numContainers=23
2013-08-10 05:30:07,105 INFO org.apache.hadoop.yarn.server.resourcemanager.scheduler.capacity.ParentQueue: assignedContainer queue=root usedCapacity=0.5833333 absoluteUsedCapacity=0.5833333 used=<memory:28672, vCores:23> cluster=<memory:49152, vCores:96>
2013-08-10 05:30:07,105 INFO org.apache.hadoop.yarn.server.resourcemanager.rmcontainer.RMContainerImpl: container_1376111601621_0006_01_000020 Container Transitioned from NEW to ALLOCATED
2013-08-10 05:30:07,105 INFO org.apache.hadoop.yarn.server.resourcemanager.RMAuditLogger: USER=ubuntu	OPERATION=AM Allocated Container	TARGET=SchedulerApp	RESULT=SUCCESS	APPID=application_1376111601621_0006	CONTAINERID=container_1376111601621_0006_01_000020
2013-08-10 05:30:07,105 INFO org.apache.hadoop.yarn.server.resourcemanager.scheduler.common.fica.FiCaSchedulerNode: Assigned container container_1376111601621_0006_01_000020 of capacity <memory:1024, vCores:1> on host hadoop-221-5:42694, which currently has 6 containers, <memory:7168, vCores:6> used and <memory:1024, vCores:10> available
2013-08-10 05:30:07,106 INFO org.apache.hadoop.yarn.server.resourcemanager.scheduler.capacity.LeafQueue: assignedContainer application=application_1376111601621_0006 container=Container: [ContainerId: container_1376111601621_0006_01_000020, NodeId: hadoop-221-5:42694, NodeHttpAddress: hadoop-221-5:8042, Resource: <memory:1024, vCores:1>, Priority: 20, State: NEW, Token: null, Status: container_id {, app_attempt_id {, application_id {, id: 6, cluster_timestamp: 1376111601621, }, attemptId: 1, }, id: 20, }, state: C_NEW, ] containerId=container_1376111601621_0006_01_000020 queue=default: capacity=1.0, absoluteCapacity=1.0, usedResources=<memory:28672, vCores:23>usedCapacity=0.5833333, absoluteUsedCapacity=0.5833333, numApps=5, numContainers=23 usedCapacity=0.5833333 absoluteUsedCapacity=0.5833333 used=<memory:28672, vCores:23> cluster=<memory:49152, vCores:96>
2013-08-10 05:30:07,107 INFO org.apache.hadoop.yarn.server.resourcemanager.scheduler.capacity.ParentQueue: Re-sorting queues since queue: root.default stats: default: capacity=1.0, absoluteCapacity=1.0, usedResources=<memory:29696, vCores:24>usedCapacity=0.6041667, absoluteUsedCapacity=0.6041667, numApps=5, numContainers=24
2013-08-10 05:30:07,107 INFO org.apache.hadoop.yarn.server.resourcemanager.scheduler.capacity.ParentQueue: assignedContainer queue=root usedCapacity=0.6041667 absoluteUsedCapacity=0.6041667 used=<memory:29696, vCores:24> cluster=<memory:49152, vCores:96>
2013-08-10 05:30:07,107 INFO org.apache.hadoop.yarn.server.resourcemanager.rmcontainer.RMContainerImpl: container_1376111601621_0006_01_000021 Container Transitioned from NEW to ALLOCATED
2013-08-10 05:30:07,108 INFO org.apache.hadoop.yarn.server.resourcemanager.RMAuditLogger: USER=ubuntu	OPERATION=AM Allocated Container	TARGET=SchedulerApp	RESULT=SUCCESS	APPID=application_1376111601621_0006	CONTAINERID=container_1376111601621_0006_01_000021
2013-08-10 05:30:07,108 INFO org.apache.hadoop.yarn.server.resourcemanager.scheduler.common.fica.FiCaSchedulerNode: Assigned container container_1376111601621_0006_01_000021 of capacity <memory:1024, vCores:1> on host hadoop-221-5:42694, which currently has 7 containers, <memory:8192, vCores:7> used and <memory:0, vCores:9> available
2013-08-10 05:30:07,109 INFO org.apache.hadoop.yarn.server.resourcemanager.scheduler.capacity.LeafQueue: assignedContainer application=application_1376111601621_0006 container=Container: [ContainerId: container_1376111601621_0006_01_000021, NodeId: hadoop-221-5:42694, NodeHttpAddress: hadoop-221-5:8042, Resource: <memory:1024, vCores:1>, Priority: 20, State: NEW, Token: null, Status: container_id {, app_attempt_id {, application_id {, id: 6, cluster_timestamp: 1376111601621, }, attemptId: 1, }, id: 21, }, state: C_NEW, ] containerId=container_1376111601621_0006_01_000021 queue=default: capacity=1.0, absoluteCapacity=1.0, usedResources=<memory:29696, vCores:24>usedCapacity=0.6041667, absoluteUsedCapacity=0.6041667, numApps=5, numContainers=24 usedCapacity=0.6041667 absoluteUsedCapacity=0.6041667 used=<memory:29696, vCores:24> cluster=<memory:49152, vCores:96>
2013-08-10 05:30:07,109 INFO org.apache.hadoop.yarn.server.resourcemanager.scheduler.capacity.ParentQueue: Re-sorting queues since queue: root.default stats: default: capacity=1.0, absoluteCapacity=1.0, usedResources=<memory:30720, vCores:25>usedCapacity=0.625, absoluteUsedCapacity=0.625, numApps=5, numContainers=25
2013-08-10 05:30:07,109 INFO org.apache.hadoop.yarn.server.resourcemanager.scheduler.capacity.ParentQueue: assignedContainer queue=root usedCapacity=0.625 absoluteUsedCapacity=0.625 used=<memory:30720, vCores:25> cluster=<memory:49152, vCores:96>
2013-08-10 05:30:07,159 INFO org.apache.hadoop.yarn.server.resourcemanager.rmcontainer.RMContainerImpl: container_1376111601621_0006_01_000022 Container Transitioned from NEW to ALLOCATED
2013-08-10 05:30:07,159 INFO org.apache.hadoop.yarn.server.resourcemanager.RMAuditLogger: USER=ubuntu	OPERATION=AM Allocated Container	TARGET=SchedulerApp	RESULT=SUCCESS	APPID=application_1376111601621_0006	CONTAINERID=container_1376111601621_0006_01_000022
2013-08-10 05:30:07,159 INFO org.apache.hadoop.yarn.server.resourcemanager.scheduler.common.fica.FiCaSchedulerNode: Assigned container container_1376111601621_0006_01_000022 of capacity <memory:1024, vCores:1> on host hadoop-221-3:43958, which currently has 2 containers, <memory:3072, vCores:2> used and <memory:5120, vCores:14> available
2013-08-10 05:30:07,160 INFO org.apache.hadoop.yarn.server.resourcemanager.scheduler.capacity.LeafQueue: assignedContainer application=application_1376111601621_0006 container=Container: [ContainerId: container_1376111601621_0006_01_000022, NodeId: hadoop-221-3:43958, NodeHttpAddress: hadoop-221-3:8042, Resource: <memory:1024, vCores:1>, Priority: 20, State: NEW, Token: null, Status: container_id {, app_attempt_id {, application_id {, id: 6, cluster_timestamp: 1376111601621, }, attemptId: 1, }, id: 22, }, state: C_NEW, ] containerId=container_1376111601621_0006_01_000022 queue=default: capacity=1.0, absoluteCapacity=1.0, usedResources=<memory:30720, vCores:25>usedCapacity=0.625, absoluteUsedCapacity=0.625, numApps=5, numContainers=25 usedCapacity=0.625 absoluteUsedCapacity=0.625 used=<memory:30720, vCores:25> cluster=<memory:49152, vCores:96>
2013-08-10 05:30:07,160 INFO org.apache.hadoop.yarn.server.resourcemanager.scheduler.capacity.ParentQueue: Re-sorting queues since queue: root.default stats: default: capacity=1.0, absoluteCapacity=1.0, usedResources=<memory:31744, vCores:26>usedCapacity=0.6458333, absoluteUsedCapacity=0.6458333, numApps=5, numContainers=26
2013-08-10 05:30:07,160 INFO org.apache.hadoop.yarn.server.resourcemanager.scheduler.capacity.ParentQueue: assignedContainer queue=root usedCapacity=0.6458333 absoluteUsedCapacity=0.6458333 used=<memory:31744, vCores:26> cluster=<memory:49152, vCores:96>
2013-08-10 05:30:07,161 INFO org.apache.hadoop.yarn.server.resourcemanager.rmcontainer.RMContainerImpl: container_1376111601621_0006_01_000023 Container Transitioned from NEW to ALLOCATED
2013-08-10 05:30:07,161 INFO org.apache.hadoop.yarn.server.resourcemanager.RMAuditLogger: USER=ubuntu	OPERATION=AM Allocated Container	TARGET=SchedulerApp	RESULT=SUCCESS	APPID=application_1376111601621_0006	CONTAINERID=container_1376111601621_0006_01_000023
2013-08-10 05:30:07,161 INFO org.apache.hadoop.yarn.server.resourcemanager.scheduler.common.fica.FiCaSchedulerNode: Assigned container container_1376111601621_0006_01_000023 of capacity <memory:1024, vCores:1> on host hadoop-221-3:43958, which currently has 3 containers, <memory:4096, vCores:3> used and <memory:4096, vCores:13> available
2013-08-10 05:30:07,162 INFO org.apache.hadoop.yarn.server.resourcemanager.scheduler.capacity.LeafQueue: assignedContainer application=application_1376111601621_0006 container=Container: [ContainerId: container_1376111601621_0006_01_000023, NodeId: hadoop-221-3:43958, NodeHttpAddress: hadoop-221-3:8042, Resource: <memory:1024, vCores:1>, Priority: 20, State: NEW, Token: null, Status: container_id {, app_attempt_id {, application_id {, id: 6, cluster_timestamp: 1376111601621, }, attemptId: 1, }, id: 23, }, state: C_NEW, ] containerId=container_1376111601621_0006_01_000023 queue=default: capacity=1.0, absoluteCapacity=1.0, usedResources=<memory:31744, vCores:26>usedCapacity=0.6458333, absoluteUsedCapacity=0.6458333, numApps=5, numContainers=26 usedCapacity=0.6458333 absoluteUsedCapacity=0.6458333 used=<memory:31744, vCores:26> cluster=<memory:49152, vCores:96>
2013-08-10 05:30:07,162 INFO org.apache.hadoop.yarn.server.resourcemanager.scheduler.capacity.ParentQueue: Re-sorting queues since queue: root.default stats: default: capacity=1.0, absoluteCapacity=1.0, usedResources=<memory:32768, vCores:27>usedCapacity=0.6666667, absoluteUsedCapacity=0.6666667, numApps=5, numContainers=27
2013-08-10 05:30:07,162 INFO org.apache.hadoop.yarn.server.resourcemanager.scheduler.capacity.ParentQueue: assignedContainer queue=root usedCapacity=0.6666667 absoluteUsedCapacity=0.6666667 used=<memory:32768, vCores:27> cluster=<memory:49152, vCores:96>
2013-08-10 05:30:07,163 INFO org.apache.hadoop.yarn.server.resourcemanager.rmcontainer.RMContainerImpl: container_1376111601621_0006_01_000024 Container Transitioned from NEW to ALLOCATED
2013-08-10 05:30:07,163 INFO org.apache.hadoop.yarn.server.resourcemanager.RMAuditLogger: USER=ubuntu	OPERATION=AM Allocated Container	TARGET=SchedulerApp	RESULT=SUCCESS	APPID=application_1376111601621_0006	CONTAINERID=container_1376111601621_0006_01_000024
2013-08-10 05:30:07,163 INFO org.apache.hadoop.yarn.server.resourcemanager.scheduler.common.fica.FiCaSchedulerNode: Assigned container container_1376111601621_0006_01_000024 of capacity <memory:1024, vCores:1> on host hadoop-221-3:43958, which currently has 4 containers, <memory:5120, vCores:4> used and <memory:3072, vCores:12> available
2013-08-10 05:30:07,164 INFO org.apache.hadoop.yarn.server.resourcemanager.scheduler.capacity.LeafQueue: assignedContainer application=application_1376111601621_0006 container=Container: [ContainerId: container_1376111601621_0006_01_000024, NodeId: hadoop-221-3:43958, NodeHttpAddress: hadoop-221-3:8042, Resource: <memory:1024, vCores:1>, Priority: 20, State: NEW, Token: null, Status: container_id {, app_attempt_id {, application_id {, id: 6, cluster_timestamp: 1376111601621, }, attemptId: 1, }, id: 24, }, state: C_NEW, ] containerId=container_1376111601621_0006_01_000024 queue=default: capacity=1.0, absoluteCapacity=1.0, usedResources=<memory:32768, vCores:27>usedCapacity=0.6666667, absoluteUsedCapacity=0.6666667, numApps=5, numContainers=27 usedCapacity=0.6666667 absoluteUsedCapacity=0.6666667 used=<memory:32768, vCores:27> cluster=<memory:49152, vCores:96>
2013-08-10 05:30:07,164 INFO org.apache.hadoop.yarn.server.resourcemanager.scheduler.capacity.ParentQueue: Re-sorting queues since queue: root.default stats: default: capacity=1.0, absoluteCapacity=1.0, usedResources=<memory:33792, vCores:28>usedCapacity=0.6875, absoluteUsedCapacity=0.6875, numApps=5, numContainers=28
2013-08-10 05:30:07,165 INFO org.apache.hadoop.yarn.server.resourcemanager.scheduler.capacity.ParentQueue: assignedContainer queue=root usedCapacity=0.6875 absoluteUsedCapacity=0.6875 used=<memory:33792, vCores:28> cluster=<memory:49152, vCores:96>
2013-08-10 05:30:07,165 INFO org.apache.hadoop.yarn.server.resourcemanager.rmcontainer.RMContainerImpl: container_1376111601621_0006_01_000025 Container Transitioned from NEW to ALLOCATED
2013-08-10 05:30:07,165 INFO org.apache.hadoop.yarn.server.resourcemanager.RMAuditLogger: USER=ubuntu	OPERATION=AM Allocated Container	TARGET=SchedulerApp	RESULT=SUCCESS	APPID=application_1376111601621_0006	CONTAINERID=container_1376111601621_0006_01_000025
2013-08-10 05:30:07,165 INFO org.apache.hadoop.yarn.server.resourcemanager.scheduler.common.fica.FiCaSchedulerNode: Assigned container container_1376111601621_0006_01_000025 of capacity <memory:1024, vCores:1> on host hadoop-221-3:43958, which currently has 5 containers, <memory:6144, vCores:5> used and <memory:2048, vCores:11> available
2013-08-10 05:30:07,166 INFO org.apache.hadoop.yarn.server.resourcemanager.scheduler.capacity.LeafQueue: assignedContainer application=application_1376111601621_0006 container=Container: [ContainerId: container_1376111601621_0006_01_000025, NodeId: hadoop-221-3:43958, NodeHttpAddress: hadoop-221-3:8042, Resource: <memory:1024, vCores:1>, Priority: 20, State: NEW, Token: null, Status: container_id {, app_attempt_id {, application_id {, id: 6, cluster_timestamp: 1376111601621, }, attemptId: 1, }, id: 25, }, state: C_NEW, ] containerId=container_1376111601621_0006_01_000025 queue=default: capacity=1.0, absoluteCapacity=1.0, usedResources=<memory:33792, vCores:28>usedCapacity=0.6875, absoluteUsedCapacity=0.6875, numApps=5, numContainers=28 usedCapacity=0.6875 absoluteUsedCapacity=0.6875 used=<memory:33792, vCores:28> cluster=<memory:49152, vCores:96>
2013-08-10 05:30:07,167 INFO org.apache.hadoop.yarn.server.resourcemanager.scheduler.capacity.ParentQueue: Re-sorting queues since queue: root.default stats: default: capacity=1.0, absoluteCapacity=1.0, usedResources=<memory:34816, vCores:29>usedCapacity=0.7083333, absoluteUsedCapacity=0.7083333, numApps=5, numContainers=29
2013-08-10 05:30:07,167 INFO org.apache.hadoop.yarn.server.resourcemanager.scheduler.capacity.ParentQueue: assignedContainer queue=root usedCapacity=0.7083333 absoluteUsedCapacity=0.7083333 used=<memory:34816, vCores:29> cluster=<memory:49152, vCores:96>
2013-08-10 05:30:07,167 INFO org.apache.hadoop.yarn.server.resourcemanager.rmcontainer.RMContainerImpl: container_1376111601621_0006_01_000026 Container Transitioned from NEW to ALLOCATED
2013-08-10 05:30:07,167 INFO org.apache.hadoop.yarn.server.resourcemanager.RMAuditLogger: USER=ubuntu	OPERATION=AM Allocated Container	TARGET=SchedulerApp	RESULT=SUCCESS	APPID=application_1376111601621_0006	CONTAINERID=container_1376111601621_0006_01_000026
2013-08-10 05:30:07,167 INFO org.apache.hadoop.yarn.server.resourcemanager.scheduler.common.fica.FiCaSchedulerNode: Assigned container container_1376111601621_0006_01_000026 of capacity <memory:1024, vCores:1> on host hadoop-221-3:43958, which currently has 6 containers, <memory:7168, vCores:6> used and <memory:1024, vCores:10> available
2013-08-10 05:30:07,168 INFO org.apache.hadoop.yarn.server.resourcemanager.scheduler.capacity.LeafQueue: assignedContainer application=application_1376111601621_0006 container=Container: [ContainerId: container_1376111601621_0006_01_000026, NodeId: hadoop-221-3:43958, NodeHttpAddress: hadoop-221-3:8042, Resource: <memory:1024, vCores:1>, Priority: 20, State: NEW, Token: null, Status: container_id {, app_attempt_id {, application_id {, id: 6, cluster_timestamp: 1376111601621, }, attemptId: 1, }, id: 26, }, state: C_NEW, ] containerId=container_1376111601621_0006_01_000026 queue=default: capacity=1.0, absoluteCapacity=1.0, usedResources=<memory:34816, vCores:29>usedCapacity=0.7083333, absoluteUsedCapacity=0.7083333, numApps=5, numContainers=29 usedCapacity=0.7083333 absoluteUsedCapacity=0.7083333 used=<memory:34816, vCores:29> cluster=<memory:49152, vCores:96>
2013-08-10 05:30:07,169 INFO org.apache.hadoop.yarn.server.resourcemanager.scheduler.capacity.ParentQueue: Re-sorting queues since queue: root.default stats: default: capacity=1.0, absoluteCapacity=1.0, usedResources=<memory:35840, vCores:30>usedCapacity=0.7291667, absoluteUsedCapacity=0.7291667, numApps=5, numContainers=30
2013-08-10 05:30:07,169 INFO org.apache.hadoop.yarn.server.resourcemanager.scheduler.capacity.ParentQueue: assignedContainer queue=root usedCapacity=0.7291667 absoluteUsedCapacity=0.7291667 used=<memory:35840, vCores:30> cluster=<memory:49152, vCores:96>
2013-08-10 05:30:07,169 INFO org.apache.hadoop.yarn.server.resourcemanager.rmcontainer.RMContainerImpl: container_1376111601621_0006_01_000027 Container Transitioned from NEW to ALLOCATED
2013-08-10 05:30:07,170 INFO org.apache.hadoop.yarn.server.resourcemanager.RMAuditLogger: USER=ubuntu	OPERATION=AM Allocated Container	TARGET=SchedulerApp	RESULT=SUCCESS	APPID=application_1376111601621_0006	CONTAINERID=container_1376111601621_0006_01_000027
2013-08-10 05:30:07,170 INFO org.apache.hadoop.yarn.server.resourcemanager.scheduler.common.fica.FiCaSchedulerNode: Assigned container container_1376111601621_0006_01_000027 of capacity <memory:1024, vCores:1> on host hadoop-221-3:43958, which currently has 7 containers, <memory:8192, vCores:7> used and <memory:0, vCores:9> available
2013-08-10 05:30:07,171 INFO org.apache.hadoop.yarn.server.resourcemanager.scheduler.capacity.LeafQueue: assignedContainer application=application_1376111601621_0006 container=Container: [ContainerId: container_1376111601621_0006_01_000027, NodeId: hadoop-221-3:43958, NodeHttpAddress: hadoop-221-3:8042, Resource: <memory:1024, vCores:1>, Priority: 20, State: NEW, Token: null, Status: container_id {, app_attempt_id {, application_id {, id: 6, cluster_timestamp: 1376111601621, }, attemptId: 1, }, id: 27, }, state: C_NEW, ] containerId=container_1376111601621_0006_01_000027 queue=default: capacity=1.0, absoluteCapacity=1.0, usedResources=<memory:35840, vCores:30>usedCapacity=0.7291667, absoluteUsedCapacity=0.7291667, numApps=5, numContainers=30 usedCapacity=0.7291667 absoluteUsedCapacity=0.7291667 used=<memory:35840, vCores:30> cluster=<memory:49152, vCores:96>
2013-08-10 05:30:07,171 INFO org.apache.hadoop.yarn.server.resourcemanager.scheduler.capacity.ParentQueue: Re-sorting queues since queue: root.default stats: default: capacity=1.0, absoluteCapacity=1.0, usedResources=<memory:36864, vCores:31>usedCapacity=0.75, absoluteUsedCapacity=0.75, numApps=5, numContainers=31
2013-08-10 05:30:07,171 INFO org.apache.hadoop.yarn.server.resourcemanager.scheduler.capacity.ParentQueue: assignedContainer queue=root usedCapacity=0.75 absoluteUsedCapacity=0.75 used=<memory:36864, vCores:31> cluster=<memory:49152, vCores:96>
2013-08-10 05:30:07,316 INFO org.apache.hadoop.yarn.server.resourcemanager.rmcontainer.RMContainerImpl: container_1376111601621_0006_01_000028 Container Transitioned from NEW to ALLOCATED
2013-08-10 05:30:07,316 INFO org.apache.hadoop.yarn.server.resourcemanager.RMAuditLogger: USER=ubuntu	OPERATION=AM Allocated Container	TARGET=SchedulerApp	RESULT=SUCCESS	APPID=application_1376111601621_0006	CONTAINERID=container_1376111601621_0006_01_000028
2013-08-10 05:30:07,317 INFO org.apache.hadoop.yarn.server.resourcemanager.scheduler.common.fica.FiCaSchedulerNode: Assigned container container_1376111601621_0006_01_000028 of capacity <memory:1024, vCores:1> on host hadoop-221-6:57712, which currently has 2 containers, <memory:3072, vCores:2> used and <memory:5120, vCores:14> available
2013-08-10 05:30:07,318 INFO org.apache.hadoop.yarn.server.resourcemanager.scheduler.capacity.LeafQueue: assignedContainer application=application_1376111601621_0006 container=Container: [ContainerId: container_1376111601621_0006_01_000028, NodeId: hadoop-221-6:57712, NodeHttpAddress: hadoop-221-6:8042, Resource: <memory:1024, vCores:1>, Priority: 20, State: NEW, Token: null, Status: container_id {, app_attempt_id {, application_id {, id: 6, cluster_timestamp: 1376111601621, }, attemptId: 1, }, id: 28, }, state: C_NEW, ] containerId=container_1376111601621_0006_01_000028 queue=default: capacity=1.0, absoluteCapacity=1.0, usedResources=<memory:36864, vCores:31>usedCapacity=0.75, absoluteUsedCapacity=0.75, numApps=5, numContainers=31 usedCapacity=0.75 absoluteUsedCapacity=0.75 used=<memory:36864, vCores:31> cluster=<memory:49152, vCores:96>
2013-08-10 05:30:07,318 INFO org.apache.hadoop.yarn.server.resourcemanager.scheduler.capacity.ParentQueue: Re-sorting queues since queue: root.default stats: default: capacity=1.0, absoluteCapacity=1.0, usedResources=<memory:37888, vCores:32>usedCapacity=0.7708333, absoluteUsedCapacity=0.7708333, numApps=5, numContainers=32
2013-08-10 05:30:07,318 INFO org.apache.hadoop.yarn.server.resourcemanager.scheduler.capacity.ParentQueue: assignedContainer queue=root usedCapacity=0.7708333 absoluteUsedCapacity=0.7708333 used=<memory:37888, vCores:32> cluster=<memory:49152, vCores:96>
2013-08-10 05:30:07,318 INFO org.apache.hadoop.yarn.server.resourcemanager.rmcontainer.RMContainerImpl: container_1376111601621_0006_01_000029 Container Transitioned from NEW to ALLOCATED
2013-08-10 05:30:07,319 INFO org.apache.hadoop.yarn.server.resourcemanager.RMAuditLogger: USER=ubuntu	OPERATION=AM Allocated Container	TARGET=SchedulerApp	RESULT=SUCCESS	APPID=application_1376111601621_0006	CONTAINERID=container_1376111601621_0006_01_000029
2013-08-10 05:30:07,319 INFO org.apache.hadoop.yarn.server.resourcemanager.scheduler.common.fica.FiCaSchedulerNode: Assigned container container_1376111601621_0006_01_000029 of capacity <memory:1024, vCores:1> on host hadoop-221-6:57712, which currently has 3 containers, <memory:4096, vCores:3> used and <memory:4096, vCores:13> available
2013-08-10 05:30:07,320 INFO org.apache.hadoop.yarn.server.resourcemanager.scheduler.capacity.LeafQueue: assignedContainer application=application_1376111601621_0006 container=Container: [ContainerId: container_1376111601621_0006_01_000029, NodeId: hadoop-221-6:57712, NodeHttpAddress: hadoop-221-6:8042, Resource: <memory:1024, vCores:1>, Priority: 20, State: NEW, Token: null, Status: container_id {, app_attempt_id {, application_id {, id: 6, cluster_timestamp: 1376111601621, }, attemptId: 1, }, id: 29, }, state: C_NEW, ] containerId=container_1376111601621_0006_01_000029 queue=default: capacity=1.0, absoluteCapacity=1.0, usedResources=<memory:37888, vCores:32>usedCapacity=0.7708333, absoluteUsedCapacity=0.7708333, numApps=5, numContainers=32 usedCapacity=0.7708333 absoluteUsedCapacity=0.7708333 used=<memory:37888, vCores:32> cluster=<memory:49152, vCores:96>
2013-08-10 05:30:07,320 INFO org.apache.hadoop.yarn.server.resourcemanager.scheduler.capacity.ParentQueue: Re-sorting queues since queue: root.default stats: default: capacity=1.0, absoluteCapacity=1.0, usedResources=<memory:38912, vCores:33>usedCapacity=0.7916667, absoluteUsedCapacity=0.7916667, numApps=5, numContainers=33
2013-08-10 05:30:07,320 INFO org.apache.hadoop.yarn.server.resourcemanager.scheduler.capacity.ParentQueue: assignedContainer queue=root usedCapacity=0.7916667 absoluteUsedCapacity=0.7916667 used=<memory:38912, vCores:33> cluster=<memory:49152, vCores:96>
2013-08-10 05:30:07,321 INFO org.apache.hadoop.yarn.server.resourcemanager.rmcontainer.RMContainerImpl: container_1376111601621_0006_01_000030 Container Transitioned from NEW to ALLOCATED
2013-08-10 05:30:07,321 INFO org.apache.hadoop.yarn.server.resourcemanager.RMAuditLogger: USER=ubuntu	OPERATION=AM Allocated Container	TARGET=SchedulerApp	RESULT=SUCCESS	APPID=application_1376111601621_0006	CONTAINERID=container_1376111601621_0006_01_000030
2013-08-10 05:30:07,321 INFO org.apache.hadoop.yarn.server.resourcemanager.scheduler.common.fica.FiCaSchedulerNode: Assigned container container_1376111601621_0006_01_000030 of capacity <memory:1024, vCores:1> on host hadoop-221-6:57712, which currently has 4 containers, <memory:5120, vCores:4> used and <memory:3072, vCores:12> available
2013-08-10 05:30:07,322 INFO org.apache.hadoop.yarn.server.resourcemanager.scheduler.capacity.LeafQueue: assignedContainer application=application_1376111601621_0006 container=Container: [ContainerId: container_1376111601621_0006_01_000030, NodeId: hadoop-221-6:57712, NodeHttpAddress: hadoop-221-6:8042, Resource: <memory:1024, vCores:1>, Priority: 20, State: NEW, Token: null, Status: container_id {, app_attempt_id {, application_id {, id: 6, cluster_timestamp: 1376111601621, }, attemptId: 1, }, id: 30, }, state: C_NEW, ] containerId=container_1376111601621_0006_01_000030 queue=default: capacity=1.0, absoluteCapacity=1.0, usedResources=<memory:38912, vCores:33>usedCapacity=0.7916667, absoluteUsedCapacity=0.7916667, numApps=5, numContainers=33 usedCapacity=0.7916667 absoluteUsedCapacity=0.7916667 used=<memory:38912, vCores:33> cluster=<memory:49152, vCores:96>
2013-08-10 05:30:07,322 INFO org.apache.hadoop.yarn.server.resourcemanager.scheduler.capacity.ParentQueue: Re-sorting queues since queue: root.default stats: default: capacity=1.0, absoluteCapacity=1.0, usedResources=<memory:39936, vCores:34>usedCapacity=0.8125, absoluteUsedCapacity=0.8125, numApps=5, numContainers=34
2013-08-10 05:30:07,322 INFO org.apache.hadoop.yarn.server.resourcemanager.scheduler.capacity.ParentQueue: assignedContainer queue=root usedCapacity=0.8125 absoluteUsedCapacity=0.8125 used=<memory:39936, vCores:34> cluster=<memory:49152, vCores:96>
2013-08-10 05:30:07,323 INFO org.apache.hadoop.yarn.server.resourcemanager.rmcontainer.RMContainerImpl: container_1376111601621_0006_01_000031 Container Transitioned from NEW to ALLOCATED
2013-08-10 05:30:07,323 INFO org.apache.hadoop.yarn.server.resourcemanager.RMAuditLogger: USER=ubuntu	OPERATION=AM Allocated Container	TARGET=SchedulerApp	RESULT=SUCCESS	APPID=application_1376111601621_0006	CONTAINERID=container_1376111601621_0006_01_000031
2013-08-10 05:30:07,323 INFO org.apache.hadoop.yarn.server.resourcemanager.scheduler.common.fica.FiCaSchedulerNode: Assigned container container_1376111601621_0006_01_000031 of capacity <memory:1024, vCores:1> on host hadoop-221-6:57712, which currently has 5 containers, <memory:6144, vCores:5> used and <memory:2048, vCores:11> available
2013-08-10 05:30:07,324 INFO org.apache.hadoop.yarn.server.resourcemanager.scheduler.capacity.LeafQueue: assignedContainer application=application_1376111601621_0006 container=Container: [ContainerId: container_1376111601621_0006_01_000031, NodeId: hadoop-221-6:57712, NodeHttpAddress: hadoop-221-6:8042, Resource: <memory:1024, vCores:1>, Priority: 20, State: NEW, Token: null, Status: container_id {, app_attempt_id {, application_id {, id: 6, cluster_timestamp: 1376111601621, }, attemptId: 1, }, id: 31, }, state: C_NEW, ] containerId=container_1376111601621_0006_01_000031 queue=default: capacity=1.0, absoluteCapacity=1.0, usedResources=<memory:39936, vCores:34>usedCapacity=0.8125, absoluteUsedCapacity=0.8125, numApps=5, numContainers=34 usedCapacity=0.8125 absoluteUsedCapacity=0.8125 used=<memory:39936, vCores:34> cluster=<memory:49152, vCores:96>
2013-08-10 05:30:07,324 INFO org.apache.hadoop.yarn.server.resourcemanager.scheduler.capacity.ParentQueue: Re-sorting queues since queue: root.default stats: default: capacity=1.0, absoluteCapacity=1.0, usedResources=<memory:40960, vCores:35>usedCapacity=0.8333333, absoluteUsedCapacity=0.8333333, numApps=5, numContainers=35
2013-08-10 05:30:07,325 INFO org.apache.hadoop.yarn.server.resourcemanager.scheduler.capacity.ParentQueue: assignedContainer queue=root usedCapacity=0.8333333 absoluteUsedCapacity=0.8333333 used=<memory:40960, vCores:35> cluster=<memory:49152, vCores:96>
2013-08-10 05:30:07,325 INFO org.apache.hadoop.yarn.server.resourcemanager.rmcontainer.RMContainerImpl: container_1376111601621_0006_01_000032 Container Transitioned from NEW to ALLOCATED
2013-08-10 05:30:07,325 INFO org.apache.hadoop.yarn.server.resourcemanager.RMAuditLogger: USER=ubuntu	OPERATION=AM Allocated Container	TARGET=SchedulerApp	RESULT=SUCCESS	APPID=application_1376111601621_0006	CONTAINERID=container_1376111601621_0006_01_000032
2013-08-10 05:30:07,325 INFO org.apache.hadoop.yarn.server.resourcemanager.scheduler.common.fica.FiCaSchedulerNode: Assigned container container_1376111601621_0006_01_000032 of capacity <memory:1024, vCores:1> on host hadoop-221-6:57712, which currently has 6 containers, <memory:7168, vCores:6> used and <memory:1024, vCores:10> available
2013-08-10 05:30:07,326 INFO org.apache.hadoop.yarn.server.resourcemanager.scheduler.capacity.LeafQueue: assignedContainer application=application_1376111601621_0006 container=Container: [ContainerId: container_1376111601621_0006_01_000032, NodeId: hadoop-221-6:57712, NodeHttpAddress: hadoop-221-6:8042, Resource: <memory:1024, vCores:1>, Priority: 20, State: NEW, Token: null, Status: container_id {, app_attempt_id {, application_id {, id: 6, cluster_timestamp: 1376111601621, }, attemptId: 1, }, id: 32, }, state: C_NEW, ] containerId=container_1376111601621_0006_01_000032 queue=default: capacity=1.0, absoluteCapacity=1.0, usedResources=<memory:40960, vCores:35>usedCapacity=0.8333333, absoluteUsedCapacity=0.8333333, numApps=5, numContainers=35 usedCapacity=0.8333333 absoluteUsedCapacity=0.8333333 used=<memory:40960, vCores:35> cluster=<memory:49152, vCores:96>
2013-08-10 05:30:07,327 INFO org.apache.hadoop.yarn.server.resourcemanager.scheduler.capacity.ParentQueue: Re-sorting queues since queue: root.default stats: default: capacity=1.0, absoluteCapacity=1.0, usedResources=<memory:41984, vCores:36>usedCapacity=0.8541667, absoluteUsedCapacity=0.8541667, numApps=5, numContainers=36
2013-08-10 05:30:07,327 INFO org.apache.hadoop.yarn.server.resourcemanager.scheduler.capacity.ParentQueue: assignedContainer queue=root usedCapacity=0.8541667 absoluteUsedCapacity=0.8541667 used=<memory:41984, vCores:36> cluster=<memory:49152, vCores:96>
2013-08-10 05:30:07,327 INFO org.apache.hadoop.yarn.server.resourcemanager.rmcontainer.RMContainerImpl: container_1376111601621_0006_01_000033 Container Transitioned from NEW to ALLOCATED
2013-08-10 05:30:07,327 INFO org.apache.hadoop.yarn.server.resourcemanager.RMAuditLogger: USER=ubuntu	OPERATION=AM Allocated Container	TARGET=SchedulerApp	RESULT=SUCCESS	APPID=application_1376111601621_0006	CONTAINERID=container_1376111601621_0006_01_000033
2013-08-10 05:30:07,328 INFO org.apache.hadoop.yarn.server.resourcemanager.scheduler.common.fica.FiCaSchedulerNode: Assigned container container_1376111601621_0006_01_000033 of capacity <memory:1024, vCores:1> on host hadoop-221-6:57712, which currently has 7 containers, <memory:8192, vCores:7> used and <memory:0, vCores:9> available
2013-08-10 05:30:07,329 INFO org.apache.hadoop.yarn.server.resourcemanager.scheduler.capacity.LeafQueue: assignedContainer application=application_1376111601621_0006 container=Container: [ContainerId: container_1376111601621_0006_01_000033, NodeId: hadoop-221-6:57712, NodeHttpAddress: hadoop-221-6:8042, Resource: <memory:1024, vCores:1>, Priority: 20, State: NEW, Token: null, Status: container_id {, app_attempt_id {, application_id {, id: 6, cluster_timestamp: 1376111601621, }, attemptId: 1, }, id: 33, }, state: C_NEW, ] containerId=container_1376111601621_0006_01_000033 queue=default: capacity=1.0, absoluteCapacity=1.0, usedResources=<memory:41984, vCores:36>usedCapacity=0.8541667, absoluteUsedCapacity=0.8541667, numApps=5, numContainers=36 usedCapacity=0.8541667 absoluteUsedCapacity=0.8541667 used=<memory:41984, vCores:36> cluster=<memory:49152, vCores:96>
2013-08-10 05:30:07,329 INFO org.apache.hadoop.yarn.server.resourcemanager.scheduler.capacity.ParentQueue: Re-sorting queues since queue: root.default stats: default: capacity=1.0, absoluteCapacity=1.0, usedResources=<memory:43008, vCores:37>usedCapacity=0.875, absoluteUsedCapacity=0.875, numApps=5, numContainers=37
2013-08-10 05:30:07,329 INFO org.apache.hadoop.yarn.server.resourcemanager.scheduler.capacity.ParentQueue: assignedContainer queue=root usedCapacity=0.875 absoluteUsedCapacity=0.875 used=<memory:43008, vCores:37> cluster=<memory:49152, vCores:96>
2013-08-10 05:30:07,557 INFO org.apache.hadoop.yarn.server.resourcemanager.rmcontainer.RMContainerImpl: container_1376111601621_0006_01_000034 Container Transitioned from NEW to ALLOCATED
2013-08-10 05:30:07,557 INFO org.apache.hadoop.yarn.server.resourcemanager.RMAuditLogger: USER=ubuntu	OPERATION=AM Allocated Container	TARGET=SchedulerApp	RESULT=SUCCESS	APPID=application_1376111601621_0006	CONTAINERID=container_1376111601621_0006_01_000034
2013-08-10 05:30:07,557 INFO org.apache.hadoop.yarn.server.resourcemanager.scheduler.common.fica.FiCaSchedulerNode: Assigned container container_1376111601621_0006_01_000034 of capacity <memory:1024, vCores:1> on host hadoop-221-4:41177, which currently has 2 containers, <memory:3072, vCores:2> used and <memory:5120, vCores:14> available
2013-08-10 05:30:07,558 INFO org.apache.hadoop.yarn.server.resourcemanager.scheduler.capacity.LeafQueue: assignedContainer application=application_1376111601621_0006 container=Container: [ContainerId: container_1376111601621_0006_01_000034, NodeId: hadoop-221-4:41177, NodeHttpAddress: hadoop-221-4:8042, Resource: <memory:1024, vCores:1>, Priority: 20, State: NEW, Token: null, Status: container_id {, app_attempt_id {, application_id {, id: 6, cluster_timestamp: 1376111601621, }, attemptId: 1, }, id: 34, }, state: C_NEW, ] containerId=container_1376111601621_0006_01_000034 queue=default: capacity=1.0, absoluteCapacity=1.0, usedResources=<memory:43008, vCores:37>usedCapacity=0.875, absoluteUsedCapacity=0.875, numApps=5, numContainers=37 usedCapacity=0.875 absoluteUsedCapacity=0.875 used=<memory:43008, vCores:37> cluster=<memory:49152, vCores:96>
2013-08-10 05:30:07,559 INFO org.apache.hadoop.yarn.server.resourcemanager.scheduler.capacity.ParentQueue: Re-sorting queues since queue: root.default stats: default: capacity=1.0, absoluteCapacity=1.0, usedResources=<memory:44032, vCores:38>usedCapacity=0.8958333, absoluteUsedCapacity=0.8958333, numApps=5, numContainers=38
2013-08-10 05:30:07,559 INFO org.apache.hadoop.yarn.server.resourcemanager.scheduler.capacity.ParentQueue: assignedContainer queue=root usedCapacity=0.8958333 absoluteUsedCapacity=0.8958333 used=<memory:44032, vCores:38> cluster=<memory:49152, vCores:96>
2013-08-10 05:30:07,559 INFO org.apache.hadoop.yarn.server.resourcemanager.rmcontainer.RMContainerImpl: container_1376111601621_0006_01_000035 Container Transitioned from NEW to ALLOCATED
2013-08-10 05:30:07,560 INFO org.apache.hadoop.yarn.server.resourcemanager.RMAuditLogger: USER=ubuntu	OPERATION=AM Allocated Container	TARGET=SchedulerApp	RESULT=SUCCESS	APPID=application_1376111601621_0006	CONTAINERID=container_1376111601621_0006_01_000035
2013-08-10 05:30:07,560 INFO org.apache.hadoop.yarn.server.resourcemanager.scheduler.common.fica.FiCaSchedulerNode: Assigned container container_1376111601621_0006_01_000035 of capacity <memory:1024, vCores:1> on host hadoop-221-4:41177, which currently has 3 containers, <memory:4096, vCores:3> used and <memory:4096, vCores:13> available
2013-08-10 05:30:07,561 INFO org.apache.hadoop.yarn.server.resourcemanager.scheduler.capacity.LeafQueue: assignedContainer application=application_1376111601621_0006 container=Container: [ContainerId: container_1376111601621_0006_01_000035, NodeId: hadoop-221-4:41177, NodeHttpAddress: hadoop-221-4:8042, Resource: <memory:1024, vCores:1>, Priority: 20, State: NEW, Token: null, Status: container_id {, app_attempt_id {, application_id {, id: 6, cluster_timestamp: 1376111601621, }, attemptId: 1, }, id: 35, }, state: C_NEW, ] containerId=container_1376111601621_0006_01_000035 queue=default: capacity=1.0, absoluteCapacity=1.0, usedResources=<memory:44032, vCores:38>usedCapacity=0.8958333, absoluteUsedCapacity=0.8958333, numApps=5, numContainers=38 usedCapacity=0.8958333 absoluteUsedCapacity=0.8958333 used=<memory:44032, vCores:38> cluster=<memory:49152, vCores:96>
2013-08-10 05:30:07,561 INFO org.apache.hadoop.yarn.server.resourcemanager.scheduler.capacity.ParentQueue: Re-sorting queues since queue: root.default stats: default: capacity=1.0, absoluteCapacity=1.0, usedResources=<memory:45056, vCores:39>usedCapacity=0.9166667, absoluteUsedCapacity=0.9166667, numApps=5, numContainers=39
2013-08-10 05:30:07,561 INFO org.apache.hadoop.yarn.server.resourcemanager.scheduler.capacity.ParentQueue: assignedContainer queue=root usedCapacity=0.9166667 absoluteUsedCapacity=0.9166667 used=<memory:45056, vCores:39> cluster=<memory:49152, vCores:96>
2013-08-10 05:30:07,562 INFO org.apache.hadoop.yarn.server.resourcemanager.rmcontainer.RMContainerImpl: container_1376111601621_0006_01_000036 Container Transitioned from NEW to ALLOCATED
2013-08-10 05:30:07,562 INFO org.apache.hadoop.yarn.server.resourcemanager.RMAuditLogger: USER=ubuntu	OPERATION=AM Allocated Container	TARGET=SchedulerApp	RESULT=SUCCESS	APPID=application_1376111601621_0006	CONTAINERID=container_1376111601621_0006_01_000036
2013-08-10 05:30:07,562 INFO org.apache.hadoop.yarn.server.resourcemanager.scheduler.common.fica.FiCaSchedulerNode: Assigned container container_1376111601621_0006_01_000036 of capacity <memory:1024, vCores:1> on host hadoop-221-4:41177, which currently has 4 containers, <memory:5120, vCores:4> used and <memory:3072, vCores:12> available
2013-08-10 05:30:07,563 INFO org.apache.hadoop.yarn.server.resourcemanager.scheduler.capacity.LeafQueue: assignedContainer application=application_1376111601621_0006 container=Container: [ContainerId: container_1376111601621_0006_01_000036, NodeId: hadoop-221-4:41177, NodeHttpAddress: hadoop-221-4:8042, Resource: <memory:1024, vCores:1>, Priority: 20, State: NEW, Token: null, Status: container_id {, app_attempt_id {, application_id {, id: 6, cluster_timestamp: 1376111601621, }, attemptId: 1, }, id: 36, }, state: C_NEW, ] containerId=container_1376111601621_0006_01_000036 queue=default: capacity=1.0, absoluteCapacity=1.0, usedResources=<memory:45056, vCores:39>usedCapacity=0.9166667, absoluteUsedCapacity=0.9166667, numApps=5, numContainers=39 usedCapacity=0.9166667 absoluteUsedCapacity=0.9166667 used=<memory:45056, vCores:39> cluster=<memory:49152, vCores:96>
2013-08-10 05:30:07,563 INFO org.apache.hadoop.yarn.server.resourcemanager.scheduler.capacity.ParentQueue: Re-sorting queues since queue: root.default stats: default: capacity=1.0, absoluteCapacity=1.0, usedResources=<memory:46080, vCores:40>usedCapacity=0.9375, absoluteUsedCapacity=0.9375, numApps=5, numContainers=40
2013-08-10 05:30:07,564 INFO org.apache.hadoop.yarn.server.resourcemanager.scheduler.capacity.ParentQueue: assignedContainer queue=root usedCapacity=0.9375 absoluteUsedCapacity=0.9375 used=<memory:46080, vCores:40> cluster=<memory:49152, vCores:96>
2013-08-10 05:30:07,564 INFO org.apache.hadoop.yarn.server.resourcemanager.rmcontainer.RMContainerImpl: container_1376111601621_0006_01_000037 Container Transitioned from NEW to ALLOCATED
2013-08-10 05:30:07,564 INFO org.apache.hadoop.yarn.server.resourcemanager.RMAuditLogger: USER=ubuntu	OPERATION=AM Allocated Container	TARGET=SchedulerApp	RESULT=SUCCESS	APPID=application_1376111601621_0006	CONTAINERID=container_1376111601621_0006_01_000037
2013-08-10 05:30:07,564 INFO org.apache.hadoop.yarn.server.resourcemanager.scheduler.common.fica.FiCaSchedulerNode: Assigned container container_1376111601621_0006_01_000037 of capacity <memory:1024, vCores:1> on host hadoop-221-4:41177, which currently has 5 containers, <memory:6144, vCores:5> used and <memory:2048, vCores:11> available
2013-08-10 05:30:07,565 INFO org.apache.hadoop.yarn.server.resourcemanager.scheduler.capacity.LeafQueue: assignedContainer application=application_1376111601621_0006 container=Container: [ContainerId: container_1376111601621_0006_01_000037, NodeId: hadoop-221-4:41177, NodeHttpAddress: hadoop-221-4:8042, Resource: <memory:1024, vCores:1>, Priority: 20, State: NEW, Token: null, Status: container_id {, app_attempt_id {, application_id {, id: 6, cluster_timestamp: 1376111601621, }, attemptId: 1, }, id: 37, }, state: C_NEW, ] containerId=container_1376111601621_0006_01_000037 queue=default: capacity=1.0, absoluteCapacity=1.0, usedResources=<memory:46080, vCores:40>usedCapacity=0.9375, absoluteUsedCapacity=0.9375, numApps=5, numContainers=40 usedCapacity=0.9375 absoluteUsedCapacity=0.9375 used=<memory:46080, vCores:40> cluster=<memory:49152, vCores:96>
2013-08-10 05:30:07,566 INFO org.apache.hadoop.yarn.server.resourcemanager.scheduler.capacity.ParentQueue: Re-sorting queues since queue: root.default stats: default: capacity=1.0, absoluteCapacity=1.0, usedResources=<memory:47104, vCores:41>usedCapacity=0.9583333, absoluteUsedCapacity=0.9583333, numApps=5, numContainers=41
2013-08-10 05:30:07,566 INFO org.apache.hadoop.yarn.server.resourcemanager.scheduler.capacity.ParentQueue: assignedContainer queue=root usedCapacity=0.9583333 absoluteUsedCapacity=0.9583333 used=<memory:47104, vCores:41> cluster=<memory:49152, vCores:96>
2013-08-10 05:30:07,566 INFO org.apache.hadoop.yarn.server.resourcemanager.rmcontainer.RMContainerImpl: container_1376111601621_0006_01_000038 Container Transitioned from NEW to ALLOCATED
2013-08-10 05:30:07,566 INFO org.apache.hadoop.yarn.server.resourcemanager.RMAuditLogger: USER=ubuntu	OPERATION=AM Allocated Container	TARGET=SchedulerApp	RESULT=SUCCESS	APPID=application_1376111601621_0006	CONTAINERID=container_1376111601621_0006_01_000038
2013-08-10 05:30:07,566 INFO org.apache.hadoop.yarn.server.resourcemanager.scheduler.common.fica.FiCaSchedulerNode: Assigned container container_1376111601621_0006_01_000038 of capacity <memory:1024, vCores:1> on host hadoop-221-4:41177, which currently has 6 containers, <memory:7168, vCores:6> used and <memory:1024, vCores:10> available
2013-08-10 05:30:07,568 INFO org.apache.hadoop.yarn.server.resourcemanager.scheduler.capacity.LeafQueue: assignedContainer application=application_1376111601621_0006 container=Container: [ContainerId: container_1376111601621_0006_01_000038, NodeId: hadoop-221-4:41177, NodeHttpAddress: hadoop-221-4:8042, Resource: <memory:1024, vCores:1>, Priority: 20, State: NEW, Token: null, Status: container_id {, app_attempt_id {, application_id {, id: 6, cluster_timestamp: 1376111601621, }, attemptId: 1, }, id: 38, }, state: C_NEW, ] containerId=container_1376111601621_0006_01_000038 queue=default: capacity=1.0, absoluteCapacity=1.0, usedResources=<memory:47104, vCores:41>usedCapacity=0.9583333, absoluteUsedCapacity=0.9583333, numApps=5, numContainers=41 usedCapacity=0.9583333 absoluteUsedCapacity=0.9583333 used=<memory:47104, vCores:41> cluster=<memory:49152, vCores:96>
2013-08-10 05:30:07,568 INFO org.apache.hadoop.yarn.server.resourcemanager.scheduler.capacity.ParentQueue: Re-sorting queues since queue: root.default stats: default: capacity=1.0, absoluteCapacity=1.0, usedResources=<memory:48128, vCores:42>usedCapacity=0.9791667, absoluteUsedCapacity=0.9791667, numApps=5, numContainers=42
2013-08-10 05:30:07,568 INFO org.apache.hadoop.yarn.server.resourcemanager.scheduler.capacity.ParentQueue: assignedContainer queue=root usedCapacity=0.9791667 absoluteUsedCapacity=0.9791667 used=<memory:48128, vCores:42> cluster=<memory:49152, vCores:96>
2013-08-10 05:30:07,568 INFO org.apache.hadoop.yarn.server.resourcemanager.rmcontainer.RMContainerImpl: container_1376111601621_0006_01_000039 Container Transitioned from NEW to ALLOCATED
2013-08-10 05:30:07,569 INFO org.apache.hadoop.yarn.server.resourcemanager.RMAuditLogger: USER=ubuntu	OPERATION=AM Allocated Container	TARGET=SchedulerApp	RESULT=SUCCESS	APPID=application_1376111601621_0006	CONTAINERID=container_1376111601621_0006_01_000039
2013-08-10 05:30:07,569 INFO org.apache.hadoop.yarn.server.resourcemanager.scheduler.common.fica.FiCaSchedulerNode: Assigned container container_1376111601621_0006_01_000039 of capacity <memory:1024, vCores:1> on host hadoop-221-4:41177, which currently has 7 containers, <memory:8192, vCores:7> used and <memory:0, vCores:9> available
2013-08-10 05:30:07,570 INFO org.apache.hadoop.yarn.server.resourcemanager.scheduler.capacity.LeafQueue: assignedContainer application=application_1376111601621_0006 container=Container: [ContainerId: container_1376111601621_0006_01_000039, NodeId: hadoop-221-4:41177, NodeHttpAddress: hadoop-221-4:8042, Resource: <memory:1024, vCores:1>, Priority: 20, State: NEW, Token: null, Status: container_id {, app_attempt_id {, application_id {, id: 6, cluster_timestamp: 1376111601621, }, attemptId: 1, }, id: 39, }, state: C_NEW, ] containerId=container_1376111601621_0006_01_000039 queue=default: capacity=1.0, absoluteCapacity=1.0, usedResources=<memory:48128, vCores:42>usedCapacity=0.9791667, absoluteUsedCapacity=0.9791667, numApps=5, numContainers=42 usedCapacity=0.9791667 absoluteUsedCapacity=0.9791667 used=<memory:48128, vCores:42> cluster=<memory:49152, vCores:96>
2013-08-10 05:30:07,570 INFO org.apache.hadoop.yarn.server.resourcemanager.scheduler.capacity.ParentQueue: Re-sorting queues since queue: root.default stats: default: capacity=1.0, absoluteCapacity=1.0, usedResources=<memory:49152, vCores:43>usedCapacity=1.0, absoluteUsedCapacity=1.0, numApps=5, numContainers=43
2013-08-10 05:30:07,570 INFO org.apache.hadoop.yarn.server.resourcemanager.scheduler.capacity.ParentQueue: assignedContainer queue=root usedCapacity=1.0 absoluteUsedCapacity=1.0 used=<memory:49152, vCores:43> cluster=<memory:49152, vCores:96>
2013-08-10 05:30:07,669 INFO org.apache.hadoop.yarn.server.resourcemanager.rmcontainer.RMContainerImpl: container_1376111601621_0006_01_000002 Container Transitioned from ALLOCATED to ACQUIRED
2013-08-10 05:30:07,670 INFO org.apache.hadoop.yarn.server.resourcemanager.rmcontainer.RMContainerImpl: container_1376111601621_0006_01_000003 Container Transitioned from ALLOCATED to ACQUIRED
2013-08-10 05:30:07,671 INFO org.apache.hadoop.yarn.server.resourcemanager.rmcontainer.RMContainerImpl: container_1376111601621_0006_01_000004 Container Transitioned from ALLOCATED to ACQUIRED
2013-08-10 05:30:07,672 INFO org.apache.hadoop.yarn.server.resourcemanager.rmcontainer.RMContainerImpl: container_1376111601621_0006_01_000005 Container Transitioned from ALLOCATED to ACQUIRED
2013-08-10 05:30:07,672 INFO org.apache.hadoop.yarn.server.resourcemanager.rmcontainer.RMContainerImpl: container_1376111601621_0006_01_000006 Container Transitioned from ALLOCATED to ACQUIRED
2013-08-10 05:30:07,673 INFO org.apache.hadoop.yarn.server.resourcemanager.rmcontainer.RMContainerImpl: container_1376111601621_0006_01_000007 Container Transitioned from ALLOCATED to ACQUIRED
2013-08-10 05:30:07,674 INFO org.apache.hadoop.yarn.server.resourcemanager.rmcontainer.RMContainerImpl: container_1376111601621_0006_01_000008 Container Transitioned from ALLOCATED to ACQUIRED
2013-08-10 05:30:07,674 INFO org.apache.hadoop.yarn.server.resourcemanager.rmcontainer.RMContainerImpl: container_1376111601621_0006_01_000009 Container Transitioned from ALLOCATED to ACQUIRED
2013-08-10 05:30:07,675 INFO org.apache.hadoop.yarn.server.resourcemanager.rmcontainer.RMContainerImpl: container_1376111601621_0006_01_000010 Container Transitioned from ALLOCATED to ACQUIRED
2013-08-10 05:30:07,677 INFO org.apache.hadoop.yarn.server.resourcemanager.rmcontainer.RMContainerImpl: container_1376111601621_0006_01_000011 Container Transitioned from ALLOCATED to ACQUIRED
2013-08-10 05:30:07,677 INFO org.apache.hadoop.yarn.server.resourcemanager.rmcontainer.RMContainerImpl: container_1376111601621_0006_01_000012 Container Transitioned from ALLOCATED to ACQUIRED
2013-08-10 05:30:07,678 INFO org.apache.hadoop.yarn.server.resourcemanager.rmcontainer.RMContainerImpl: container_1376111601621_0006_01_000013 Container Transitioned from ALLOCATED to ACQUIRED
2013-08-10 05:30:07,678 INFO org.apache.hadoop.yarn.server.resourcemanager.rmcontainer.RMContainerImpl: container_1376111601621_0006_01_000014 Container Transitioned from ALLOCATED to ACQUIRED
2013-08-10 05:30:07,679 INFO org.apache.hadoop.yarn.server.resourcemanager.rmcontainer.RMContainerImpl: container_1376111601621_0006_01_000015 Container Transitioned from ALLOCATED to ACQUIRED
2013-08-10 05:30:07,679 INFO org.apache.hadoop.yarn.server.resourcemanager.rmcontainer.RMContainerImpl: container_1376111601621_0006_01_000016 Container Transitioned from ALLOCATED to ACQUIRED
2013-08-10 05:30:07,680 INFO org.apache.hadoop.yarn.server.resourcemanager.rmcontainer.RMContainerImpl: container_1376111601621_0006_01_000017 Container Transitioned from ALLOCATED to ACQUIRED
2013-08-10 05:30:07,680 INFO org.apache.hadoop.yarn.server.resourcemanager.rmcontainer.RMContainerImpl: container_1376111601621_0006_01_000018 Container Transitioned from ALLOCATED to ACQUIRED
2013-08-10 05:30:07,681 INFO org.apache.hadoop.yarn.server.resourcemanager.rmcontainer.RMContainerImpl: container_1376111601621_0006_01_000019 Container Transitioned from ALLOCATED to ACQUIRED
2013-08-10 05:30:07,681 INFO org.apache.hadoop.yarn.server.resourcemanager.rmcontainer.RMContainerImpl: container_1376111601621_0006_01_000020 Container Transitioned from ALLOCATED to ACQUIRED
2013-08-10 05:30:07,682 INFO org.apache.hadoop.yarn.server.resourcemanager.rmcontainer.RMContainerImpl: container_1376111601621_0006_01_000021 Container Transitioned from ALLOCATED to ACQUIRED
2013-08-10 05:30:07,683 INFO org.apache.hadoop.yarn.server.resourcemanager.rmcontainer.RMContainerImpl: container_1376111601621_0006_01_000022 Container Transitioned from ALLOCATED to ACQUIRED
2013-08-10 05:30:07,683 INFO org.apache.hadoop.yarn.server.resourcemanager.rmcontainer.RMContainerImpl: container_1376111601621_0006_01_000023 Container Transitioned from ALLOCATED to ACQUIRED
2013-08-10 05:30:07,683 INFO org.apache.hadoop.yarn.server.resourcemanager.rmcontainer.RMContainerImpl: container_1376111601621_0006_01_000024 Container Transitioned from ALLOCATED to ACQUIRED
2013-08-10 05:30:07,683 INFO org.apache.hadoop.yarn.server.resourcemanager.rmcontainer.RMContainerImpl: container_1376111601621_0006_01_000025 Container Transitioned from ALLOCATED to ACQUIRED
2013-08-10 05:30:07,684 INFO org.apache.hadoop.yarn.server.resourcemanager.rmcontainer.RMContainerImpl: container_1376111601621_0006_01_000026 Container Transitioned from ALLOCATED to ACQUIRED
2013-08-10 05:30:07,684 INFO org.apache.hadoop.yarn.server.resourcemanager.rmcontainer.RMContainerImpl: container_1376111601621_0006_01_000027 Container Transitioned from ALLOCATED to ACQUIRED
2013-08-10 05:30:07,684 INFO org.apache.hadoop.yarn.server.resourcemanager.rmcontainer.RMContainerImpl: container_1376111601621_0006_01_000028 Container Transitioned from ALLOCATED to ACQUIRED
2013-08-10 05:30:07,684 INFO org.apache.hadoop.yarn.server.resourcemanager.rmcontainer.RMContainerImpl: container_1376111601621_0006_01_000029 Container Transitioned from ALLOCATED to ACQUIRED
2013-08-10 05:30:07,685 INFO org.apache.hadoop.yarn.server.resourcemanager.rmcontainer.RMContainerImpl: container_1376111601621_0006_01_000030 Container Transitioned from ALLOCATED to ACQUIRED
2013-08-10 05:30:07,685 INFO org.apache.hadoop.yarn.server.resourcemanager.rmcontainer.RMContainerImpl: container_1376111601621_0006_01_000031 Container Transitioned from ALLOCATED to ACQUIRED
2013-08-10 05:30:07,685 INFO org.apache.hadoop.yarn.server.resourcemanager.rmcontainer.RMContainerImpl: container_1376111601621_0006_01_000032 Container Transitioned from ALLOCATED to ACQUIRED
2013-08-10 05:30:07,685 INFO org.apache.hadoop.yarn.server.resourcemanager.rmcontainer.RMContainerImpl: container_1376111601621_0006_01_000033 Container Transitioned from ALLOCATED to ACQUIRED
2013-08-10 05:30:07,686 INFO org.apache.hadoop.yarn.server.resourcemanager.rmcontainer.RMContainerImpl: container_1376111601621_0006_01_000034 Container Transitioned from ALLOCATED to ACQUIRED
2013-08-10 05:30:07,686 INFO org.apache.hadoop.yarn.server.resourcemanager.rmcontainer.RMContainerImpl: container_1376111601621_0006_01_000035 Container Transitioned from ALLOCATED to ACQUIRED
2013-08-10 05:30:07,686 INFO org.apache.hadoop.yarn.server.resourcemanager.rmcontainer.RMContainerImpl: container_1376111601621_0006_01_000036 Container Transitioned from ALLOCATED to ACQUIRED
2013-08-10 05:30:07,686 INFO org.apache.hadoop.yarn.server.resourcemanager.rmcontainer.RMContainerImpl: container_1376111601621_0006_01_000037 Container Transitioned from ALLOCATED to ACQUIRED
2013-08-10 05:30:07,686 INFO org.apache.hadoop.yarn.server.resourcemanager.rmcontainer.RMContainerImpl: container_1376111601621_0006_01_000038 Container Transitioned from ALLOCATED to ACQUIRED
2013-08-10 05:30:07,687 INFO org.apache.hadoop.yarn.server.resourcemanager.rmcontainer.RMContainerImpl: container_1376111601621_0006_01_000039 Container Transitioned from ALLOCATED to ACQUIRED
2013-08-10 05:30:08,336 INFO org.apache.hadoop.yarn.server.resourcemanager.rmcontainer.RMContainerImpl: container_1376111601621_0006_01_000028 Container Transitioned from ACQUIRED to RUNNING
2013-08-10 05:30:08,337 INFO org.apache.hadoop.yarn.server.resourcemanager.rmcontainer.RMContainerImpl: container_1376111601621_0006_01_000029 Container Transitioned from ACQUIRED to RUNNING
2013-08-10 05:30:08,338 INFO org.apache.hadoop.yarn.server.resourcemanager.rmcontainer.RMContainerImpl: container_1376111601621_0006_01_000030 Container Transitioned from ACQUIRED to RUNNING
2013-08-10 05:30:08,339 INFO org.apache.hadoop.yarn.server.resourcemanager.rmcontainer.RMContainerImpl: container_1376111601621_0006_01_000031 Container Transitioned from ACQUIRED to RUNNING
2013-08-10 05:30:08,340 INFO org.apache.hadoop.yarn.server.resourcemanager.rmcontainer.RMContainerImpl: container_1376111601621_0006_01_000032 Container Transitioned from ACQUIRED to RUNNING
2013-08-10 05:30:08,341 INFO org.apache.hadoop.yarn.server.resourcemanager.rmcontainer.RMContainerImpl: container_1376111601621_0006_01_000033 Container Transitioned from ACQUIRED to RUNNING
2013-08-10 05:30:08,569 INFO org.apache.hadoop.yarn.server.resourcemanager.rmcontainer.RMContainerImpl: container_1376111601621_0006_01_000034 Container Transitioned from ACQUIRED to RUNNING
2013-08-10 05:30:08,570 INFO org.apache.hadoop.yarn.server.resourcemanager.rmcontainer.RMContainerImpl: container_1376111601621_0006_01_000035 Container Transitioned from ACQUIRED to RUNNING
2013-08-10 05:30:08,571 INFO org.apache.hadoop.yarn.server.resourcemanager.rmcontainer.RMContainerImpl: container_1376111601621_0006_01_000036 Container Transitioned from ACQUIRED to RUNNING
2013-08-10 05:30:08,573 INFO org.apache.hadoop.yarn.server.resourcemanager.rmcontainer.RMContainerImpl: container_1376111601621_0006_01_000037 Container Transitioned from ACQUIRED to RUNNING
2013-08-10 05:30:08,573 INFO org.apache.hadoop.yarn.server.resourcemanager.rmcontainer.RMContainerImpl: container_1376111601621_0006_01_000038 Container Transitioned from ACQUIRED to RUNNING
2013-08-10 05:30:08,574 INFO org.apache.hadoop.yarn.server.resourcemanager.rmcontainer.RMContainerImpl: container_1376111601621_0006_01_000039 Container Transitioned from ACQUIRED to RUNNING
2013-08-10 05:30:08,718 INFO org.apache.hadoop.yarn.server.resourcemanager.rmcontainer.RMContainerImpl: container_1376111601621_0006_01_000002 Container Transitioned from ACQUIRED to RUNNING
2013-08-10 05:30:08,718 INFO org.apache.hadoop.yarn.server.resourcemanager.rmcontainer.RMContainerImpl: container_1376111601621_0006_01_000003 Container Transitioned from ACQUIRED to RUNNING
2013-08-10 05:30:08,719 INFO org.apache.hadoop.yarn.server.resourcemanager.rmcontainer.RMContainerImpl: container_1376111601621_0006_01_000004 Container Transitioned from ACQUIRED to RUNNING
2013-08-10 05:30:08,719 INFO org.apache.hadoop.yarn.server.resourcemanager.rmcontainer.RMContainerImpl: container_1376111601621_0006_01_000005 Container Transitioned from ACQUIRED to RUNNING
2013-08-10 05:30:08,719 INFO org.apache.hadoop.yarn.server.resourcemanager.rmcontainer.RMContainerImpl: container_1376111601621_0006_01_000006 Container Transitioned from ACQUIRED to RUNNING
2013-08-10 05:30:08,719 INFO org.apache.hadoop.yarn.server.resourcemanager.rmcontainer.RMContainerImpl: container_1376111601621_0006_01_000007 Container Transitioned from ACQUIRED to RUNNING
2013-08-10 05:30:08,719 INFO org.apache.hadoop.yarn.server.resourcemanager.rmcontainer.RMContainerImpl: container_1376111601621_0006_01_000008 Container Transitioned from ACQUIRED to RUNNING
2013-08-10 05:30:08,720 INFO org.apache.hadoop.yarn.server.resourcemanager.rmcontainer.RMContainerImpl: container_1376111601621_0006_01_000009 Container Transitioned from ACQUIRED to RUNNING
2013-08-10 05:30:08,888 INFO org.apache.hadoop.yarn.server.resourcemanager.rmcontainer.RMContainerImpl: container_1376111601621_0006_01_000010 Container Transitioned from ACQUIRED to RUNNING
2013-08-10 05:30:08,889 INFO org.apache.hadoop.yarn.server.resourcemanager.rmcontainer.RMContainerImpl: container_1376111601621_0006_01_000011 Container Transitioned from ACQUIRED to RUNNING
2013-08-10 05:30:08,890 INFO org.apache.hadoop.yarn.server.resourcemanager.rmcontainer.RMContainerImpl: container_1376111601621_0006_01_000012 Container Transitioned from ACQUIRED to RUNNING
2013-08-10 05:30:08,891 INFO org.apache.hadoop.yarn.server.resourcemanager.rmcontainer.RMContainerImpl: container_1376111601621_0006_01_000013 Container Transitioned from ACQUIRED to RUNNING
2013-08-10 05:30:08,892 INFO org.apache.hadoop.yarn.server.resourcemanager.rmcontainer.RMContainerImpl: container_1376111601621_0006_01_000014 Container Transitioned from ACQUIRED to RUNNING
2013-08-10 05:30:08,893 INFO org.apache.hadoop.yarn.server.resourcemanager.rmcontainer.RMContainerImpl: container_1376111601621_0006_01_000015 Container Transitioned from ACQUIRED to RUNNING
2013-08-10 05:30:09,128 INFO org.apache.hadoop.yarn.server.resourcemanager.rmcontainer.RMContainerImpl: container_1376111601621_0006_01_000016 Container Transitioned from ACQUIRED to RUNNING
2013-08-10 05:30:09,129 INFO org.apache.hadoop.yarn.server.resourcemanager.rmcontainer.RMContainerImpl: container_1376111601621_0006_01_000017 Container Transitioned from ACQUIRED to RUNNING
2013-08-10 05:30:09,130 INFO org.apache.hadoop.yarn.server.resourcemanager.rmcontainer.RMContainerImpl: container_1376111601621_0006_01_000018 Container Transitioned from ACQUIRED to RUNNING
2013-08-10 05:30:09,131 INFO org.apache.hadoop.yarn.server.resourcemanager.rmcontainer.RMContainerImpl: container_1376111601621_0006_01_000019 Container Transitioned from ACQUIRED to RUNNING
2013-08-10 05:30:09,131 INFO org.apache.hadoop.yarn.server.resourcemanager.rmcontainer.RMContainerImpl: container_1376111601621_0006_01_000020 Container Transitioned from ACQUIRED to RUNNING
2013-08-10 05:30:09,131 INFO org.apache.hadoop.yarn.server.resourcemanager.rmcontainer.RMContainerImpl: container_1376111601621_0006_01_000021 Container Transitioned from ACQUIRED to RUNNING
2013-08-10 05:30:09,181 INFO org.apache.hadoop.yarn.server.resourcemanager.rmcontainer.RMContainerImpl: container_1376111601621_0006_01_000022 Container Transitioned from ACQUIRED to RUNNING
2013-08-10 05:30:09,181 INFO org.apache.hadoop.yarn.server.resourcemanager.rmcontainer.RMContainerImpl: container_1376111601621_0006_01_000023 Container Transitioned from ACQUIRED to RUNNING
2013-08-10 05:30:09,181 INFO org.apache.hadoop.yarn.server.resourcemanager.rmcontainer.RMContainerImpl: container_1376111601621_0006_01_000024 Container Transitioned from ACQUIRED to RUNNING
2013-08-10 05:30:09,181 INFO org.apache.hadoop.yarn.server.resourcemanager.rmcontainer.RMContainerImpl: container_1376111601621_0006_01_000025 Container Transitioned from ACQUIRED to RUNNING
2013-08-10 05:30:09,182 INFO org.apache.hadoop.yarn.server.resourcemanager.rmcontainer.RMContainerImpl: container_1376111601621_0006_01_000026 Container Transitioned from ACQUIRED to RUNNING
2013-08-10 05:30:09,182 INFO org.apache.hadoop.yarn.server.resourcemanager.rmcontainer.RMContainerImpl: container_1376111601621_0006_01_000027 Container Transitioned from ACQUIRED to RUNNING
2013-08-10 05:30:14,823 INFO org.apache.hadoop.yarn.server.resourcemanager.ApplicationMasterService: AM registration appattempt_1376111601621_0010_000001
2013-08-10 05:30:14,823 INFO org.apache.hadoop.yarn.server.resourcemanager.RMAuditLogger: USER=ubuntu	IP=192.168.100.37	OPERATION=Register App Master	TARGET=ApplicationMasterService	RESULT=SUCCESS	APPID=application_1376111601621_0010	APPATTEMPTID=appattempt_1376111601621_0010_000001
2013-08-10 05:30:14,826 INFO org.apache.hadoop.yarn.server.resourcemanager.rmapp.attempt.RMAppAttemptImpl: appattempt_1376111601621_0010_000001 State change from LAUNCHED to RUNNING
2013-08-10 05:30:14,826 INFO org.apache.hadoop.yarn.server.resourcemanager.rmapp.RMAppImpl: application_1376111601621_0010 State change from ACCEPTED to RUNNING
2013-08-10 05:30:34,461 INFO org.apache.hadoop.yarn.server.resourcemanager.rmcontainer.RMContainerImpl: container_1376111601621_0006_01_000029 Container Transitioned from RUNNING to COMPLETED
2013-08-10 05:30:34,461 INFO org.apache.hadoop.yarn.server.resourcemanager.scheduler.common.fica.FiCaSchedulerApp: Completed container: container_1376111601621_0006_01_000029 in state: COMPLETED event:FINISHED
2013-08-10 05:30:34,461 INFO org.apache.hadoop.yarn.server.resourcemanager.RMAuditLogger: USER=ubuntu	OPERATION=AM Released Container	TARGET=SchedulerApp	RESULT=SUCCESS	APPID=application_1376111601621_0006	CONTAINERID=container_1376111601621_0006_01_000029
2013-08-10 05:30:34,462 INFO org.apache.hadoop.yarn.server.resourcemanager.scheduler.common.fica.FiCaSchedulerNode: Released container container_1376111601621_0006_01_000029 of capacity <memory:1024, vCores:1> on host hadoop-221-6:57712, which currently has 6 containers, <memory:7168, vCores:6> used and <memory:1024, vCores:10> available, release resources=true
2013-08-10 05:30:34,462 INFO org.apache.hadoop.yarn.server.resourcemanager.scheduler.capacity.LeafQueue: default used=<memory:48128, vCores:42> numContainers=42 user=ubuntu user-resources=<memory:48128, vCores:42>
2013-08-10 05:30:34,465 INFO org.apache.hadoop.yarn.server.resourcemanager.scheduler.capacity.LeafQueue: completedContainer container=Container: [ContainerId: container_1376111601621_0006_01_000029, NodeId: hadoop-221-6:57712, NodeHttpAddress: hadoop-221-6:8042, Resource: <memory:1024, vCores:1>, Priority: 20, State: NEW, Token: null, Status: container_id {, app_attempt_id {, application_id {, id: 6, cluster_timestamp: 1376111601621, }, attemptId: 1, }, id: 29, }, state: C_COMPLETE, diagnostics: "Container killed by the ApplicationMaster.\n\n", exit_status: 143, ] resource=<memory:1024, vCores:1> queue=default: capacity=1.0, absoluteCapacity=1.0, usedResources=<memory:48128, vCores:42>usedCapacity=0.9791667, absoluteUsedCapacity=0.9791667, numApps=5, numContainers=42 usedCapacity=0.9791667 absoluteUsedCapacity=0.9791667 used=<memory:48128, vCores:42> cluster=<memory:49152, vCores:96>
2013-08-10 05:30:34,465 INFO org.apache.hadoop.yarn.server.resourcemanager.scheduler.capacity.ParentQueue: completedContainer queue=root usedCapacity=0.9791667 absoluteUsedCapacity=0.9791667 used=<memory:48128, vCores:42> cluster=<memory:49152, vCores:96>
2013-08-10 05:30:34,465 INFO org.apache.hadoop.yarn.server.resourcemanager.scheduler.capacity.CapacityScheduler: Application appattempt_1376111601621_0006_000001 released container container_1376111601621_0006_01_000029 on node: host: hadoop-221-6:57712 #containers=6 available=1024 used=7168 with event: FINISHED
2013-08-10 05:30:34,466 INFO org.apache.hadoop.yarn.server.resourcemanager.rmcontainer.RMContainerImpl: container_1376111601621_0006_01_000040 Container Transitioned from NEW to ALLOCATED
2013-08-10 05:30:34,466 INFO org.apache.hadoop.yarn.server.resourcemanager.RMAuditLogger: USER=ubuntu	OPERATION=AM Allocated Container	TARGET=SchedulerApp	RESULT=SUCCESS	APPID=application_1376111601621_0006	CONTAINERID=container_1376111601621_0006_01_000040
2013-08-10 05:30:34,466 INFO org.apache.hadoop.yarn.server.resourcemanager.scheduler.common.fica.FiCaSchedulerNode: Assigned container container_1376111601621_0006_01_000040 of capacity <memory:1024, vCores:1> on host hadoop-221-6:57712, which currently has 7 containers, <memory:8192, vCores:7> used and <memory:0, vCores:9> available
2013-08-10 05:30:34,467 INFO org.apache.hadoop.yarn.server.resourcemanager.scheduler.capacity.LeafQueue: assignedContainer application=application_1376111601621_0006 container=Container: [ContainerId: container_1376111601621_0006_01_000040, NodeId: hadoop-221-6:57712, NodeHttpAddress: hadoop-221-6:8042, Resource: <memory:1024, vCores:1>, Priority: 20, State: NEW, Token: null, Status: container_id {, app_attempt_id {, application_id {, id: 6, cluster_timestamp: 1376111601621, }, attemptId: 1, }, id: 40, }, state: C_NEW, ] containerId=container_1376111601621_0006_01_000040 queue=default: capacity=1.0, absoluteCapacity=1.0, usedResources=<memory:48128, vCores:42>usedCapacity=0.9791667, absoluteUsedCapacity=0.9791667, numApps=5, numContainers=42 usedCapacity=0.9791667 absoluteUsedCapacity=0.9791667 used=<memory:48128, vCores:42> cluster=<memory:49152, vCores:96>
2013-08-10 05:30:34,468 INFO org.apache.hadoop.yarn.server.resourcemanager.scheduler.capacity.ParentQueue: Re-sorting queues since queue: root.default stats: default: capacity=1.0, absoluteCapacity=1.0, usedResources=<memory:49152, vCores:43>usedCapacity=1.0, absoluteUsedCapacity=1.0, numApps=5, numContainers=43
2013-08-10 05:30:34,468 INFO org.apache.hadoop.yarn.server.resourcemanager.scheduler.capacity.ParentQueue: assignedContainer queue=root usedCapacity=1.0 absoluteUsedCapacity=1.0 used=<memory:49152, vCores:43> cluster=<memory:49152, vCores:96>
2013-08-10 05:30:34,933 INFO org.apache.hadoop.yarn.server.resourcemanager.rmcontainer.RMContainerImpl: container_1376111601621_0006_01_000040 Container Transitioned from ALLOCATED to ACQUIRED
2013-08-10 05:30:35,468 INFO org.apache.hadoop.yarn.server.resourcemanager.rmcontainer.RMContainerImpl: container_1376111601621_0006_01_000040 Container Transitioned from ACQUIRED to RUNNING
2013-08-10 05:30:35,681 INFO org.apache.hadoop.yarn.server.resourcemanager.rmcontainer.RMContainerImpl: container_1376111601621_0006_01_000039 Container Transitioned from RUNNING to COMPLETED
2013-08-10 05:30:35,681 INFO org.apache.hadoop.yarn.server.resourcemanager.scheduler.common.fica.FiCaSchedulerApp: Completed container: container_1376111601621_0006_01_000039 in state: COMPLETED event:FINISHED
2013-08-10 05:30:35,681 INFO org.apache.hadoop.yarn.server.resourcemanager.RMAuditLogger: USER=ubuntu	OPERATION=AM Released Container	TARGET=SchedulerApp	RESULT=SUCCESS	APPID=application_1376111601621_0006	CONTAINERID=container_1376111601621_0006_01_000039
2013-08-10 05:30:35,681 INFO org.apache.hadoop.yarn.server.resourcemanager.scheduler.common.fica.FiCaSchedulerNode: Released container container_1376111601621_0006_01_000039 of capacity <memory:1024, vCores:1> on host hadoop-221-4:41177, which currently has 6 containers, <memory:7168, vCores:6> used and <memory:1024, vCores:10> available, release resources=true
2013-08-10 05:30:35,681 INFO org.apache.hadoop.yarn.server.resourcemanager.scheduler.capacity.LeafQueue: default used=<memory:48128, vCores:42> numContainers=42 user=ubuntu user-resources=<memory:48128, vCores:42>
2013-08-10 05:30:35,683 INFO org.apache.hadoop.yarn.server.resourcemanager.scheduler.capacity.LeafQueue: completedContainer container=Container: [ContainerId: container_1376111601621_0006_01_000039, NodeId: hadoop-221-4:41177, NodeHttpAddress: hadoop-221-4:8042, Resource: <memory:1024, vCores:1>, Priority: 20, State: NEW, Token: null, Status: container_id {, app_attempt_id {, application_id {, id: 6, cluster_timestamp: 1376111601621, }, attemptId: 1, }, id: 39, }, state: C_COMPLETE, diagnostics: "Container killed by the ApplicationMaster.\n\n", exit_status: 143, ] resource=<memory:1024, vCores:1> queue=default: capacity=1.0, absoluteCapacity=1.0, usedResources=<memory:48128, vCores:42>usedCapacity=0.9791667, absoluteUsedCapacity=0.9791667, numApps=5, numContainers=42 usedCapacity=0.9791667 absoluteUsedCapacity=0.9791667 used=<memory:48128, vCores:42> cluster=<memory:49152, vCores:96>
2013-08-10 05:30:35,683 INFO org.apache.hadoop.yarn.server.resourcemanager.scheduler.capacity.ParentQueue: completedContainer queue=root usedCapacity=0.9791667 absoluteUsedCapacity=0.9791667 used=<memory:48128, vCores:42> cluster=<memory:49152, vCores:96>
2013-08-10 05:30:35,683 INFO org.apache.hadoop.yarn.server.resourcemanager.scheduler.capacity.CapacityScheduler: Application appattempt_1376111601621_0006_000001 released container container_1376111601621_0006_01_000039 on node: host: hadoop-221-4:41177 #containers=6 available=1024 used=7168 with event: FINISHED
2013-08-10 05:30:35,684 INFO org.apache.hadoop.yarn.server.resourcemanager.rmcontainer.RMContainerImpl: container_1376111601621_0006_01_000041 Container Transitioned from NEW to ALLOCATED
2013-08-10 05:30:35,684 INFO org.apache.hadoop.yarn.server.resourcemanager.RMAuditLogger: USER=ubuntu	OPERATION=AM Allocated Container	TARGET=SchedulerApp	RESULT=SUCCESS	APPID=application_1376111601621_0006	CONTAINERID=container_1376111601621_0006_01_000041
2013-08-10 05:30:35,684 INFO org.apache.hadoop.yarn.server.resourcemanager.scheduler.common.fica.FiCaSchedulerNode: Assigned container container_1376111601621_0006_01_000041 of capacity <memory:1024, vCores:1> on host hadoop-221-4:41177, which currently has 7 containers, <memory:8192, vCores:7> used and <memory:0, vCores:9> available
2013-08-10 05:30:35,685 INFO org.apache.hadoop.yarn.server.resourcemanager.scheduler.capacity.LeafQueue: assignedContainer application=application_1376111601621_0006 container=Container: [ContainerId: container_1376111601621_0006_01_000041, NodeId: hadoop-221-4:41177, NodeHttpAddress: hadoop-221-4:8042, Resource: <memory:1024, vCores:1>, Priority: 20, State: NEW, Token: null, Status: container_id {, app_attempt_id {, application_id {, id: 6, cluster_timestamp: 1376111601621, }, attemptId: 1, }, id: 41, }, state: C_NEW, ] containerId=container_1376111601621_0006_01_000041 queue=default: capacity=1.0, absoluteCapacity=1.0, usedResources=<memory:48128, vCores:42>usedCapacity=0.9791667, absoluteUsedCapacity=0.9791667, numApps=5, numContainers=42 usedCapacity=0.9791667 absoluteUsedCapacity=0.9791667 used=<memory:48128, vCores:42> cluster=<memory:49152, vCores:96>
2013-08-10 05:30:35,686 INFO org.apache.hadoop.yarn.server.resourcemanager.scheduler.capacity.ParentQueue: Re-sorting queues since queue: root.default stats: default: capacity=1.0, absoluteCapacity=1.0, usedResources=<memory:49152, vCores:43>usedCapacity=1.0, absoluteUsedCapacity=1.0, numApps=5, numContainers=43
2013-08-10 05:30:35,686 INFO org.apache.hadoop.yarn.server.resourcemanager.scheduler.capacity.ParentQueue: assignedContainer queue=root usedCapacity=1.0 absoluteUsedCapacity=1.0 used=<memory:49152, vCores:43> cluster=<memory:49152, vCores:96>
2013-08-10 05:30:35,945 INFO org.apache.hadoop.yarn.server.resourcemanager.rmcontainer.RMContainerImpl: container_1376111601621_0006_01_000041 Container Transitioned from ALLOCATED to ACQUIRED
2013-08-10 05:30:36,408 INFO org.apache.hadoop.yarn.server.resourcemanager.rmcontainer.RMContainerImpl: container_1376111601621_0006_01_000026 Container Transitioned from RUNNING to COMPLETED
2013-08-10 05:30:36,408 INFO org.apache.hadoop.yarn.server.resourcemanager.scheduler.common.fica.FiCaSchedulerApp: Completed container: container_1376111601621_0006_01_000026 in state: COMPLETED event:FINISHED
2013-08-10 05:30:36,408 INFO org.apache.hadoop.yarn.server.resourcemanager.RMAuditLogger: USER=ubuntu	OPERATION=AM Released Container	TARGET=SchedulerApp	RESULT=SUCCESS	APPID=application_1376111601621_0006	CONTAINERID=container_1376111601621_0006_01_000026
2013-08-10 05:30:36,409 INFO org.apache.hadoop.yarn.server.resourcemanager.scheduler.common.fica.FiCaSchedulerNode: Released container container_1376111601621_0006_01_000026 of capacity <memory:1024, vCores:1> on host hadoop-221-3:43958, which currently has 6 containers, <memory:7168, vCores:6> used and <memory:1024, vCores:10> available, release resources=true
2013-08-10 05:30:36,409 INFO org.apache.hadoop.yarn.server.resourcemanager.scheduler.capacity.LeafQueue: default used=<memory:48128, vCores:42> numContainers=42 user=ubuntu user-resources=<memory:48128, vCores:42>
2013-08-10 05:30:36,410 INFO org.apache.hadoop.yarn.server.resourcemanager.scheduler.capacity.LeafQueue: completedContainer container=Container: [ContainerId: container_1376111601621_0006_01_000026, NodeId: hadoop-221-3:43958, NodeHttpAddress: hadoop-221-3:8042, Resource: <memory:1024, vCores:1>, Priority: 20, State: NEW, Token: null, Status: container_id {, app_attempt_id {, application_id {, id: 6, cluster_timestamp: 1376111601621, }, attemptId: 1, }, id: 26, }, state: C_COMPLETE, diagnostics: "Container killed by the ApplicationMaster.\n\n", exit_status: 143, ] resource=<memory:1024, vCores:1> queue=default: capacity=1.0, absoluteCapacity=1.0, usedResources=<memory:48128, vCores:42>usedCapacity=0.9791667, absoluteUsedCapacity=0.9791667, numApps=5, numContainers=42 usedCapacity=0.9791667 absoluteUsedCapacity=0.9791667 used=<memory:48128, vCores:42> cluster=<memory:49152, vCores:96>
2013-08-10 05:30:36,410 INFO org.apache.hadoop.yarn.server.resourcemanager.scheduler.capacity.ParentQueue: completedContainer queue=root usedCapacity=0.9791667 absoluteUsedCapacity=0.9791667 used=<memory:48128, vCores:42> cluster=<memory:49152, vCores:96>
2013-08-10 05:30:36,410 INFO org.apache.hadoop.yarn.server.resourcemanager.scheduler.capacity.CapacityScheduler: Application appattempt_1376111601621_0006_000001 released container container_1376111601621_0006_01_000026 on node: host: hadoop-221-3:43958 #containers=6 available=1024 used=7168 with event: FINISHED
2013-08-10 05:30:36,411 INFO org.apache.hadoop.yarn.server.resourcemanager.rmcontainer.RMContainerImpl: container_1376111601621_0006_01_000027 Container Transitioned from RUNNING to COMPLETED
2013-08-10 05:30:36,411 INFO org.apache.hadoop.yarn.server.resourcemanager.scheduler.common.fica.FiCaSchedulerApp: Completed container: container_1376111601621_0006_01_000027 in state: COMPLETED event:FINISHED
2013-08-10 05:30:36,411 INFO org.apache.hadoop.yarn.server.resourcemanager.RMAuditLogger: USER=ubuntu	OPERATION=AM Released Container	TARGET=SchedulerApp	RESULT=SUCCESS	APPID=application_1376111601621_0006	CONTAINERID=container_1376111601621_0006_01_000027
2013-08-10 05:30:36,411 INFO org.apache.hadoop.yarn.server.resourcemanager.scheduler.common.fica.FiCaSchedulerNode: Released container container_1376111601621_0006_01_000027 of capacity <memory:1024, vCores:1> on host hadoop-221-3:43958, which currently has 5 containers, <memory:6144, vCores:5> used and <memory:2048, vCores:11> available, release resources=true
2013-08-10 05:30:36,411 INFO org.apache.hadoop.yarn.server.resourcemanager.scheduler.capacity.LeafQueue: default used=<memory:47104, vCores:41> numContainers=41 user=ubuntu user-resources=<memory:47104, vCores:41>
2013-08-10 05:30:36,413 INFO org.apache.hadoop.yarn.server.resourcemanager.scheduler.capacity.LeafQueue: completedContainer container=Container: [ContainerId: container_1376111601621_0006_01_000027, NodeId: hadoop-221-3:43958, NodeHttpAddress: hadoop-221-3:8042, Resource: <memory:1024, vCores:1>, Priority: 20, State: NEW, Token: null, Status: container_id {, app_attempt_id {, application_id {, id: 6, cluster_timestamp: 1376111601621, }, attemptId: 1, }, id: 27, }, state: C_COMPLETE, diagnostics: "Container killed by the ApplicationMaster.\n\n", exit_status: 143, ] resource=<memory:1024, vCores:1> queue=default: capacity=1.0, absoluteCapacity=1.0, usedResources=<memory:47104, vCores:41>usedCapacity=0.9583333, absoluteUsedCapacity=0.9583333, numApps=5, numContainers=41 usedCapacity=0.9583333 absoluteUsedCapacity=0.9583333 used=<memory:47104, vCores:41> cluster=<memory:49152, vCores:96>
2013-08-10 05:30:36,413 INFO org.apache.hadoop.yarn.server.resourcemanager.scheduler.capacity.ParentQueue: completedContainer queue=root usedCapacity=0.9583333 absoluteUsedCapacity=0.9583333 used=<memory:47104, vCores:41> cluster=<memory:49152, vCores:96>
2013-08-10 05:30:36,413 INFO org.apache.hadoop.yarn.server.resourcemanager.scheduler.capacity.CapacityScheduler: Application appattempt_1376111601621_0006_000001 released container container_1376111601621_0006_01_000027 on node: host: hadoop-221-3:43958 #containers=5 available=2048 used=6144 with event: FINISHED
2013-08-10 05:30:36,414 INFO org.apache.hadoop.yarn.server.resourcemanager.rmcontainer.RMContainerImpl: container_1376111601621_0006_01_000042 Container Transitioned from NEW to ALLOCATED
2013-08-10 05:30:36,414 INFO org.apache.hadoop.yarn.server.resourcemanager.RMAuditLogger: USER=ubuntu	OPERATION=AM Allocated Container	TARGET=SchedulerApp	RESULT=SUCCESS	APPID=application_1376111601621_0006	CONTAINERID=container_1376111601621_0006_01_000042
2013-08-10 05:30:36,414 INFO org.apache.hadoop.yarn.server.resourcemanager.scheduler.common.fica.FiCaSchedulerNode: Assigned container container_1376111601621_0006_01_000042 of capacity <memory:1024, vCores:1> on host hadoop-221-3:43958, which currently has 6 containers, <memory:7168, vCores:6> used and <memory:1024, vCores:10> available
2013-08-10 05:30:36,415 INFO org.apache.hadoop.yarn.server.resourcemanager.scheduler.capacity.LeafQueue: assignedContainer application=application_1376111601621_0006 container=Container: [ContainerId: container_1376111601621_0006_01_000042, NodeId: hadoop-221-3:43958, NodeHttpAddress: hadoop-221-3:8042, Resource: <memory:1024, vCores:1>, Priority: 10, State: NEW, Token: null, Status: container_id {, app_attempt_id {, application_id {, id: 6, cluster_timestamp: 1376111601621, }, attemptId: 1, }, id: 42, }, state: C_NEW, ] containerId=container_1376111601621_0006_01_000042 queue=default: capacity=1.0, absoluteCapacity=1.0, usedResources=<memory:47104, vCores:41>usedCapacity=0.9583333, absoluteUsedCapacity=0.9583333, numApps=5, numContainers=41 usedCapacity=0.9583333 absoluteUsedCapacity=0.9583333 used=<memory:47104, vCores:41> cluster=<memory:49152, vCores:96>
2013-08-10 05:30:36,415 INFO org.apache.hadoop.yarn.server.resourcemanager.scheduler.capacity.ParentQueue: Re-sorting queues since queue: root.default stats: default: capacity=1.0, absoluteCapacity=1.0, usedResources=<memory:48128, vCores:42>usedCapacity=0.9791667, absoluteUsedCapacity=0.9791667, numApps=5, numContainers=42
2013-08-10 05:30:36,415 INFO org.apache.hadoop.yarn.server.resourcemanager.scheduler.capacity.ParentQueue: assignedContainer queue=root usedCapacity=0.9791667 absoluteUsedCapacity=0.9791667 used=<memory:48128, vCores:42> cluster=<memory:49152, vCores:96>
2013-08-10 05:30:36,456 INFO org.apache.hadoop.yarn.server.resourcemanager.rmcontainer.RMContainerImpl: container_1376111601621_0006_01_000012 Container Transitioned from RUNNING to COMPLETED
2013-08-10 05:30:36,456 INFO org.apache.hadoop.yarn.server.resourcemanager.scheduler.common.fica.FiCaSchedulerApp: Completed container: container_1376111601621_0006_01_000012 in state: COMPLETED event:FINISHED
2013-08-10 05:30:36,456 INFO org.apache.hadoop.yarn.server.resourcemanager.RMAuditLogger: USER=ubuntu	OPERATION=AM Released Container	TARGET=SchedulerApp	RESULT=SUCCESS	APPID=application_1376111601621_0006	CONTAINERID=container_1376111601621_0006_01_000012
2013-08-10 05:30:36,456 INFO org.apache.hadoop.yarn.server.resourcemanager.scheduler.common.fica.FiCaSchedulerNode: Released container container_1376111601621_0006_01_000012 of capacity <memory:1024, vCores:1> on host hadoop-221-7:34609, which currently has 6 containers, <memory:7168, vCores:6> used and <memory:1024, vCores:10> available, release resources=true
2013-08-10 05:30:36,456 INFO org.apache.hadoop.yarn.server.resourcemanager.scheduler.capacity.LeafQueue: default used=<memory:47104, vCores:41> numContainers=41 user=ubuntu user-resources=<memory:47104, vCores:41>
2013-08-10 05:30:36,458 INFO org.apache.hadoop.yarn.server.resourcemanager.scheduler.capacity.LeafQueue: completedContainer container=Container: [ContainerId: container_1376111601621_0006_01_000012, NodeId: hadoop-221-7:34609, NodeHttpAddress: hadoop-221-7:8042, Resource: <memory:1024, vCores:1>, Priority: 20, State: NEW, Token: null, Status: container_id {, app_attempt_id {, application_id {, id: 6, cluster_timestamp: 1376111601621, }, attemptId: 1, }, id: 12, }, state: C_COMPLETE, diagnostics: "Container killed by the ApplicationMaster.\n\n", exit_status: 143, ] resource=<memory:1024, vCores:1> queue=default: capacity=1.0, absoluteCapacity=1.0, usedResources=<memory:47104, vCores:41>usedCapacity=0.9583333, absoluteUsedCapacity=0.9583333, numApps=5, numContainers=41 usedCapacity=0.9583333 absoluteUsedCapacity=0.9583333 used=<memory:47104, vCores:41> cluster=<memory:49152, vCores:96>
2013-08-10 05:30:36,458 INFO org.apache.hadoop.yarn.server.resourcemanager.scheduler.capacity.ParentQueue: completedContainer queue=root usedCapacity=0.9583333 absoluteUsedCapacity=0.9583333 used=<memory:47104, vCores:41> cluster=<memory:49152, vCores:96>
2013-08-10 05:30:36,458 INFO org.apache.hadoop.yarn.server.resourcemanager.scheduler.capacity.CapacityScheduler: Application appattempt_1376111601621_0006_000001 released container container_1376111601621_0006_01_000012 on node: host: hadoop-221-7:34609 #containers=6 available=1024 used=7168 with event: FINISHED
2013-08-10 05:30:36,459 INFO org.apache.hadoop.yarn.server.resourcemanager.rmcontainer.RMContainerImpl: container_1376111601621_0006_01_000043 Container Transitioned from NEW to ALLOCATED
2013-08-10 05:30:36,459 INFO org.apache.hadoop.yarn.server.resourcemanager.RMAuditLogger: USER=ubuntu	OPERATION=AM Allocated Container	TARGET=SchedulerApp	RESULT=SUCCESS	APPID=application_1376111601621_0006	CONTAINERID=container_1376111601621_0006_01_000043
2013-08-10 05:30:36,459 INFO org.apache.hadoop.yarn.server.resourcemanager.scheduler.common.fica.FiCaSchedulerNode: Assigned container container_1376111601621_0006_01_000043 of capacity <memory:1024, vCores:1> on host hadoop-221-7:34609, which currently has 7 containers, <memory:8192, vCores:7> used and <memory:0, vCores:9> available
2013-08-10 05:30:36,461 INFO org.apache.hadoop.yarn.server.resourcemanager.scheduler.capacity.LeafQueue: assignedContainer application=application_1376111601621_0006 container=Container: [ContainerId: container_1376111601621_0006_01_000043, NodeId: hadoop-221-7:34609, NodeHttpAddress: hadoop-221-7:8042, Resource: <memory:1024, vCores:1>, Priority: 20, State: NEW, Token: null, Status: container_id {, app_attempt_id {, application_id {, id: 6, cluster_timestamp: 1376111601621, }, attemptId: 1, }, id: 43, }, state: C_NEW, ] containerId=container_1376111601621_0006_01_000043 queue=default: capacity=1.0, absoluteCapacity=1.0, usedResources=<memory:47104, vCores:41>usedCapacity=0.9583333, absoluteUsedCapacity=0.9583333, numApps=5, numContainers=41 usedCapacity=0.9583333 absoluteUsedCapacity=0.9583333 used=<memory:47104, vCores:41> cluster=<memory:49152, vCores:96>
2013-08-10 05:30:36,461 INFO org.apache.hadoop.yarn.server.resourcemanager.scheduler.capacity.ParentQueue: Re-sorting queues since queue: root.default stats: default: capacity=1.0, absoluteCapacity=1.0, usedResources=<memory:48128, vCores:42>usedCapacity=0.9791667, absoluteUsedCapacity=0.9791667, numApps=5, numContainers=42
2013-08-10 05:30:36,461 INFO org.apache.hadoop.yarn.server.resourcemanager.scheduler.capacity.ParentQueue: assignedContainer queue=root usedCapacity=0.9791667 absoluteUsedCapacity=0.9791667 used=<memory:48128, vCores:42> cluster=<memory:49152, vCores:96>
2013-08-10 05:30:36,688 INFO org.apache.hadoop.yarn.server.resourcemanager.rmcontainer.RMContainerImpl: container_1376111601621_0006_01_000041 Container Transitioned from ACQUIRED to RUNNING
2013-08-10 05:30:36,954 INFO org.apache.hadoop.yarn.server.resourcemanager.rmcontainer.RMContainerImpl: container_1376111601621_0006_01_000042 Container Transitioned from ALLOCATED to ACQUIRED
2013-08-10 05:30:36,956 INFO org.apache.hadoop.yarn.server.resourcemanager.rmcontainer.RMContainerImpl: container_1376111601621_0006_01_000043 Container Transitioned from ALLOCATED to ACQUIRED
2013-08-10 05:30:37,420 INFO org.apache.hadoop.yarn.server.resourcemanager.rmcontainer.RMContainerImpl: container_1376111601621_0006_01_000042 Container Transitioned from ACQUIRED to RUNNING
2013-08-10 05:30:37,421 INFO org.apache.hadoop.yarn.server.resourcemanager.rmcontainer.RMContainerImpl: container_1376111601621_0006_01_000044 Container Transitioned from NEW to ALLOCATED
2013-08-10 05:30:37,421 INFO org.apache.hadoop.yarn.server.resourcemanager.RMAuditLogger: USER=ubuntu	OPERATION=AM Allocated Container	TARGET=SchedulerApp	RESULT=SUCCESS	APPID=application_1376111601621_0006	CONTAINERID=container_1376111601621_0006_01_000044
2013-08-10 05:30:37,421 INFO org.apache.hadoop.yarn.server.resourcemanager.scheduler.common.fica.FiCaSchedulerNode: Assigned container container_1376111601621_0006_01_000044 of capacity <memory:1024, vCores:1> on host hadoop-221-3:43958, which currently has 7 containers, <memory:8192, vCores:7> used and <memory:0, vCores:9> available
2013-08-10 05:30:37,422 INFO org.apache.hadoop.yarn.server.resourcemanager.scheduler.capacity.LeafQueue: assignedContainer application=application_1376111601621_0006 container=Container: [ContainerId: container_1376111601621_0006_01_000044, NodeId: hadoop-221-3:43958, NodeHttpAddress: hadoop-221-3:8042, Resource: <memory:1024, vCores:1>, Priority: 20, State: NEW, Token: null, Status: container_id {, app_attempt_id {, application_id {, id: 6, cluster_timestamp: 1376111601621, }, attemptId: 1, }, id: 44, }, state: C_NEW, ] containerId=container_1376111601621_0006_01_000044 queue=default: capacity=1.0, absoluteCapacity=1.0, usedResources=<memory:48128, vCores:42>usedCapacity=0.9791667, absoluteUsedCapacity=0.9791667, numApps=5, numContainers=42 usedCapacity=0.9791667 absoluteUsedCapacity=0.9791667 used=<memory:48128, vCores:42> cluster=<memory:49152, vCores:96>
2013-08-10 05:30:37,423 INFO org.apache.hadoop.yarn.server.resourcemanager.scheduler.capacity.ParentQueue: Re-sorting queues since queue: root.default stats: default: capacity=1.0, absoluteCapacity=1.0, usedResources=<memory:49152, vCores:43>usedCapacity=1.0, absoluteUsedCapacity=1.0, numApps=5, numContainers=43
2013-08-10 05:30:37,423 INFO org.apache.hadoop.yarn.server.resourcemanager.scheduler.capacity.ParentQueue: assignedContainer queue=root usedCapacity=1.0 absoluteUsedCapacity=1.0 used=<memory:49152, vCores:43> cluster=<memory:49152, vCores:96>
2013-08-10 05:30:37,462 INFO org.apache.hadoop.yarn.server.resourcemanager.rmcontainer.RMContainerImpl: container_1376111601621_0006_01_000043 Container Transitioned from ACQUIRED to RUNNING
2013-08-10 05:30:37,966 INFO org.apache.hadoop.yarn.server.resourcemanager.scheduler.AppSchedulingInfo: checking for deactivate... 
2013-08-10 05:30:37,967 INFO org.apache.hadoop.yarn.server.resourcemanager.scheduler.AppSchedulingInfo: checking for deactivate... 
2013-08-10 05:30:37,968 INFO org.apache.hadoop.yarn.server.resourcemanager.rmcontainer.RMContainerImpl: container_1376111601621_0006_01_000044 Container Transitioned from ALLOCATED to ACQUIRED
2013-08-10 05:30:38,993 INFO org.apache.hadoop.yarn.server.resourcemanager.rmcontainer.RMContainerImpl: container_1376111601621_0006_01_000044 Container Transitioned from ACQUIRED to RELEASED
2013-08-10 05:30:38,993 INFO org.apache.hadoop.yarn.server.resourcemanager.scheduler.common.fica.FiCaSchedulerApp: Completed container: container_1376111601621_0006_01_000044 in state: RELEASED event:RELEASED
2013-08-10 05:30:38,994 INFO org.apache.hadoop.yarn.server.resourcemanager.RMAuditLogger: USER=ubuntu	IP=192.168.100.40	OPERATION=AM Released Container	TARGET=SchedulerApp	RESULT=SUCCESS	APPID=application_1376111601621_0006	CONTAINERID=container_1376111601621_0006_01_000044
2013-08-10 05:30:38,995 INFO org.apache.hadoop.yarn.server.resourcemanager.scheduler.common.fica.FiCaSchedulerNode: Released container container_1376111601621_0006_01_000044 of capacity <memory:1024, vCores:1> on host hadoop-221-3:43958, which currently has 6 containers, <memory:7168, vCores:6> used and <memory:1024, vCores:10> available, release resources=true
2013-08-10 05:30:38,996 INFO org.apache.hadoop.yarn.server.resourcemanager.scheduler.capacity.LeafQueue: default used=<memory:48128, vCores:42> numContainers=42 user=ubuntu user-resources=<memory:48128, vCores:42>
2013-08-10 05:30:38,998 INFO org.apache.hadoop.yarn.server.resourcemanager.scheduler.capacity.LeafQueue: completedContainer container=Container: [ContainerId: container_1376111601621_0006_01_000044, NodeId: hadoop-221-3:43958, NodeHttpAddress: hadoop-221-3:8042, Resource: <memory:1024, vCores:1>, Priority: 20, State: NEW, Token: null, Status: container_id {, app_attempt_id {, application_id {, id: 6, cluster_timestamp: 1376111601621, }, attemptId: 1, }, id: 44, }, state: C_COMPLETE, diagnostics: "Container released by application", exit_status: -100, ] resource=<memory:1024, vCores:1> queue=default: capacity=1.0, absoluteCapacity=1.0, usedResources=<memory:48128, vCores:42>usedCapacity=0.9791667, absoluteUsedCapacity=0.9791667, numApps=5, numContainers=42 usedCapacity=0.9791667 absoluteUsedCapacity=0.9791667 used=<memory:48128, vCores:42> cluster=<memory:49152, vCores:96>
2013-08-10 05:30:38,998 INFO org.apache.hadoop.yarn.server.resourcemanager.scheduler.capacity.ParentQueue: completedContainer queue=root usedCapacity=0.9791667 absoluteUsedCapacity=0.9791667 used=<memory:48128, vCores:42> cluster=<memory:49152, vCores:96>
2013-08-10 05:30:38,998 INFO org.apache.hadoop.yarn.server.resourcemanager.scheduler.capacity.CapacityScheduler: Application appattempt_1376111601621_0006_000001 released container container_1376111601621_0006_01_000044 on node: host: hadoop-221-3:43958 #containers=6 available=1024 used=7168 with event: RELEASED
2013-08-10 05:30:39,929 INFO org.apache.hadoop.yarn.server.resourcemanager.rmcontainer.RMContainerImpl: container_1376111601621_0006_01_000016 Container Transitioned from RUNNING to COMPLETED
2013-08-10 05:30:39,930 INFO org.apache.hadoop.yarn.server.resourcemanager.scheduler.common.fica.FiCaSchedulerApp: Completed container: container_1376111601621_0006_01_000016 in state: COMPLETED event:FINISHED
2013-08-10 05:30:39,930 INFO org.apache.hadoop.yarn.server.resourcemanager.RMAuditLogger: USER=ubuntu	OPERATION=AM Released Container	TARGET=SchedulerApp	RESULT=SUCCESS	APPID=application_1376111601621_0006	CONTAINERID=container_1376111601621_0006_01_000016
2013-08-10 05:30:39,930 INFO org.apache.hadoop.yarn.server.resourcemanager.scheduler.common.fica.FiCaSchedulerNode: Released container container_1376111601621_0006_01_000016 of capacity <memory:1024, vCores:1> on host hadoop-221-5:42694, which currently has 6 containers, <memory:7168, vCores:6> used and <memory:1024, vCores:10> available, release resources=true
2013-08-10 05:30:39,930 INFO org.apache.hadoop.yarn.server.resourcemanager.scheduler.capacity.LeafQueue: default used=<memory:47104, vCores:41> numContainers=41 user=ubuntu user-resources=<memory:47104, vCores:41>
2013-08-10 05:30:39,931 INFO org.apache.hadoop.yarn.server.resourcemanager.scheduler.capacity.LeafQueue: completedContainer container=Container: [ContainerId: container_1376111601621_0006_01_000016, NodeId: hadoop-221-5:42694, NodeHttpAddress: hadoop-221-5:8042, Resource: <memory:1024, vCores:1>, Priority: 20, State: NEW, Token: null, Status: container_id {, app_attempt_id {, application_id {, id: 6, cluster_timestamp: 1376111601621, }, attemptId: 1, }, id: 16, }, state: C_COMPLETE, diagnostics: "Container killed by the ApplicationMaster.\n\n", exit_status: 143, ] resource=<memory:1024, vCores:1> queue=default: capacity=1.0, absoluteCapacity=1.0, usedResources=<memory:47104, vCores:41>usedCapacity=0.9583333, absoluteUsedCapacity=0.9583333, numApps=5, numContainers=41 usedCapacity=0.9583333 absoluteUsedCapacity=0.9583333 used=<memory:47104, vCores:41> cluster=<memory:49152, vCores:96>
2013-08-10 05:30:39,932 INFO org.apache.hadoop.yarn.server.resourcemanager.scheduler.capacity.ParentQueue: completedContainer queue=root usedCapacity=0.9583333 absoluteUsedCapacity=0.9583333 used=<memory:47104, vCores:41> cluster=<memory:49152, vCores:96>
2013-08-10 05:30:39,932 INFO org.apache.hadoop.yarn.server.resourcemanager.scheduler.capacity.CapacityScheduler: Application appattempt_1376111601621_0006_000001 released container container_1376111601621_0006_01_000016 on node: host: hadoop-221-5:42694 #containers=6 available=1024 used=7168 with event: FINISHED
2013-08-10 05:30:39,932 INFO org.apache.hadoop.yarn.server.resourcemanager.rmcontainer.RMContainerImpl: container_1376111601621_0007_01_000002 Container Transitioned from NEW to ALLOCATED
2013-08-10 05:30:39,933 INFO org.apache.hadoop.yarn.server.resourcemanager.RMAuditLogger: USER=ubuntu	OPERATION=AM Allocated Container	TARGET=SchedulerApp	RESULT=SUCCESS	APPID=application_1376111601621_0007	CONTAINERID=container_1376111601621_0007_01_000002
2013-08-10 05:30:39,933 INFO org.apache.hadoop.yarn.server.resourcemanager.scheduler.common.fica.FiCaSchedulerNode: Assigned container container_1376111601621_0007_01_000002 of capacity <memory:1024, vCores:1> on host hadoop-221-5:42694, which currently has 7 containers, <memory:8192, vCores:7> used and <memory:0, vCores:9> available
2013-08-10 05:30:39,934 INFO org.apache.hadoop.yarn.server.resourcemanager.scheduler.capacity.LeafQueue: assignedContainer application=application_1376111601621_0007 container=Container: [ContainerId: container_1376111601621_0007_01_000002, NodeId: hadoop-221-5:42694, NodeHttpAddress: hadoop-221-5:8042, Resource: <memory:1024, vCores:1>, Priority: 20, State: NEW, Token: null, Status: container_id {, app_attempt_id {, application_id {, id: 7, cluster_timestamp: 1376111601621, }, attemptId: 1, }, id: 2, }, state: C_NEW, ] containerId=container_1376111601621_0007_01_000002 queue=default: capacity=1.0, absoluteCapacity=1.0, usedResources=<memory:47104, vCores:41>usedCapacity=0.9583333, absoluteUsedCapacity=0.9583333, numApps=5, numContainers=41 usedCapacity=0.9583333 absoluteUsedCapacity=0.9583333 used=<memory:47104, vCores:41> cluster=<memory:49152, vCores:96>
2013-08-10 05:30:39,934 INFO org.apache.hadoop.yarn.server.resourcemanager.scheduler.capacity.ParentQueue: Re-sorting queues since queue: root.default stats: default: capacity=1.0, absoluteCapacity=1.0, usedResources=<memory:48128, vCores:42>usedCapacity=0.9791667, absoluteUsedCapacity=0.9791667, numApps=5, numContainers=42
2013-08-10 05:30:39,934 INFO org.apache.hadoop.yarn.server.resourcemanager.scheduler.capacity.ParentQueue: assignedContainer queue=root usedCapacity=0.9791667 absoluteUsedCapacity=0.9791667 used=<memory:48128, vCores:42> cluster=<memory:49152, vCores:96>
2013-08-10 05:30:39,963 INFO org.apache.hadoop.yarn.server.resourcemanager.rmcontainer.RMContainerImpl: container_1376111601621_0007_01_000002 Container Transitioned from ALLOCATED to ACQUIRED
2013-08-10 05:30:39,985 INFO org.apache.hadoop.yarn.server.resourcemanager.rmcontainer.RMContainerImpl: container_1376111601621_0007_01_000003 Container Transitioned from NEW to ALLOCATED
2013-08-10 05:30:39,985 INFO org.apache.hadoop.yarn.server.resourcemanager.RMAuditLogger: USER=ubuntu	OPERATION=AM Allocated Container	TARGET=SchedulerApp	RESULT=SUCCESS	APPID=application_1376111601621_0007	CONTAINERID=container_1376111601621_0007_01_000003
2013-08-10 05:30:39,986 INFO org.apache.hadoop.yarn.server.resourcemanager.scheduler.common.fica.FiCaSchedulerNode: Assigned container container_1376111601621_0007_01_000003 of capacity <memory:1024, vCores:1> on host hadoop-221-3:43958, which currently has 7 containers, <memory:8192, vCores:7> used and <memory:0, vCores:9> available
2013-08-10 05:30:39,987 INFO org.apache.hadoop.yarn.server.resourcemanager.scheduler.capacity.LeafQueue: assignedContainer application=application_1376111601621_0007 container=Container: [ContainerId: container_1376111601621_0007_01_000003, NodeId: hadoop-221-3:43958, NodeHttpAddress: hadoop-221-3:8042, Resource: <memory:1024, vCores:1>, Priority: 20, State: NEW, Token: null, Status: container_id {, app_attempt_id {, application_id {, id: 7, cluster_timestamp: 1376111601621, }, attemptId: 1, }, id: 3, }, state: C_NEW, ] containerId=container_1376111601621_0007_01_000003 queue=default: capacity=1.0, absoluteCapacity=1.0, usedResources=<memory:48128, vCores:42>usedCapacity=0.9791667, absoluteUsedCapacity=0.9791667, numApps=5, numContainers=42 usedCapacity=0.9791667 absoluteUsedCapacity=0.9791667 used=<memory:48128, vCores:42> cluster=<memory:49152, vCores:96>
2013-08-10 05:30:39,987 INFO org.apache.hadoop.yarn.server.resourcemanager.scheduler.capacity.ParentQueue: Re-sorting queues since queue: root.default stats: default: capacity=1.0, absoluteCapacity=1.0, usedResources=<memory:49152, vCores:43>usedCapacity=1.0, absoluteUsedCapacity=1.0, numApps=5, numContainers=43
2013-08-10 05:30:39,987 INFO org.apache.hadoop.yarn.server.resourcemanager.scheduler.capacity.ParentQueue: assignedContainer queue=root usedCapacity=1.0 absoluteUsedCapacity=1.0 used=<memory:49152, vCores:43> cluster=<memory:49152, vCores:96>
2013-08-10 05:30:40,367 INFO org.apache.hadoop.yarn.server.resourcemanager.rmcontainer.RMContainerImpl: container_1376111601621_0006_01_000003 Container Transitioned from RUNNING to COMPLETED
2013-08-10 05:30:40,368 INFO org.apache.hadoop.yarn.server.resourcemanager.scheduler.common.fica.FiCaSchedulerApp: Completed container: container_1376111601621_0006_01_000003 in state: COMPLETED event:FINISHED
2013-08-10 05:30:40,368 INFO org.apache.hadoop.yarn.server.resourcemanager.RMAuditLogger: USER=ubuntu	OPERATION=AM Released Container	TARGET=SchedulerApp	RESULT=SUCCESS	APPID=application_1376111601621_0006	CONTAINERID=container_1376111601621_0006_01_000003
2013-08-10 05:30:40,368 INFO org.apache.hadoop.yarn.server.resourcemanager.scheduler.common.fica.FiCaSchedulerNode: Released container container_1376111601621_0006_01_000003 of capacity <memory:1024, vCores:1> on host hadoop-221-2:55267, which currently has 7 containers, <memory:7168, vCores:7> used and <memory:1024, vCores:9> available, release resources=true
2013-08-10 05:30:40,368 INFO org.apache.hadoop.yarn.server.resourcemanager.scheduler.capacity.LeafQueue: default used=<memory:48128, vCores:42> numContainers=42 user=ubuntu user-resources=<memory:48128, vCores:42>
2013-08-10 05:30:40,369 INFO org.apache.hadoop.yarn.server.resourcemanager.scheduler.capacity.LeafQueue: completedContainer container=Container: [ContainerId: container_1376111601621_0006_01_000003, NodeId: hadoop-221-2:55267, NodeHttpAddress: hadoop-221-2:8042, Resource: <memory:1024, vCores:1>, Priority: 20, State: NEW, Token: null, Status: container_id {, app_attempt_id {, application_id {, id: 6, cluster_timestamp: 1376111601621, }, attemptId: 1, }, id: 3, }, state: C_COMPLETE, diagnostics: "Container killed by the ApplicationMaster.\n\n", exit_status: 143, ] resource=<memory:1024, vCores:1> queue=default: capacity=1.0, absoluteCapacity=1.0, usedResources=<memory:48128, vCores:42>usedCapacity=0.9791667, absoluteUsedCapacity=0.9791667, numApps=5, numContainers=42 usedCapacity=0.9791667 absoluteUsedCapacity=0.9791667 used=<memory:48128, vCores:42> cluster=<memory:49152, vCores:96>
2013-08-10 05:30:40,370 INFO org.apache.hadoop.yarn.server.resourcemanager.scheduler.capacity.ParentQueue: completedContainer queue=root usedCapacity=0.9791667 absoluteUsedCapacity=0.9791667 used=<memory:48128, vCores:42> cluster=<memory:49152, vCores:96>
2013-08-10 05:30:40,370 INFO org.apache.hadoop.yarn.server.resourcemanager.scheduler.capacity.CapacityScheduler: Application appattempt_1376111601621_0006_000001 released container container_1376111601621_0006_01_000003 on node: host: hadoop-221-2:55267 #containers=7 available=1024 used=7168 with event: FINISHED
2013-08-10 05:30:40,370 INFO org.apache.hadoop.yarn.server.resourcemanager.rmcontainer.RMContainerImpl: container_1376111601621_0007_01_000004 Container Transitioned from NEW to ALLOCATED
2013-08-10 05:30:40,370 INFO org.apache.hadoop.yarn.server.resourcemanager.RMAuditLogger: USER=ubuntu	OPERATION=AM Allocated Container	TARGET=SchedulerApp	RESULT=SUCCESS	APPID=application_1376111601621_0007	CONTAINERID=container_1376111601621_0007_01_000004
2013-08-10 05:30:40,371 INFO org.apache.hadoop.yarn.server.resourcemanager.scheduler.common.fica.FiCaSchedulerNode: Assigned container container_1376111601621_0007_01_000004 of capacity <memory:1024, vCores:1> on host hadoop-221-2:55267, which currently has 8 containers, <memory:8192, vCores:8> used and <memory:0, vCores:8> available
2013-08-10 05:30:40,372 INFO org.apache.hadoop.yarn.server.resourcemanager.scheduler.capacity.LeafQueue: assignedContainer application=application_1376111601621_0007 container=Container: [ContainerId: container_1376111601621_0007_01_000004, NodeId: hadoop-221-2:55267, NodeHttpAddress: hadoop-221-2:8042, Resource: <memory:1024, vCores:1>, Priority: 20, State: NEW, Token: null, Status: container_id {, app_attempt_id {, application_id {, id: 7, cluster_timestamp: 1376111601621, }, attemptId: 1, }, id: 4, }, state: C_NEW, ] containerId=container_1376111601621_0007_01_000004 queue=default: capacity=1.0, absoluteCapacity=1.0, usedResources=<memory:48128, vCores:42>usedCapacity=0.9791667, absoluteUsedCapacity=0.9791667, numApps=5, numContainers=42 usedCapacity=0.9791667 absoluteUsedCapacity=0.9791667 used=<memory:48128, vCores:42> cluster=<memory:49152, vCores:96>
2013-08-10 05:30:40,372 INFO org.apache.hadoop.yarn.server.resourcemanager.scheduler.capacity.ParentQueue: Re-sorting queues since queue: root.default stats: default: capacity=1.0, absoluteCapacity=1.0, usedResources=<memory:49152, vCores:43>usedCapacity=1.0, absoluteUsedCapacity=1.0, numApps=5, numContainers=43
2013-08-10 05:30:40,372 INFO org.apache.hadoop.yarn.server.resourcemanager.scheduler.capacity.ParentQueue: assignedContainer queue=root usedCapacity=1.0 absoluteUsedCapacity=1.0 used=<memory:49152, vCores:43> cluster=<memory:49152, vCores:96>
2013-08-10 05:30:41,015 INFO org.apache.hadoop.yarn.server.resourcemanager.rmcontainer.RMContainerImpl: container_1376111601621_0007_01_000003 Container Transitioned from ALLOCATED to ACQUIRED
2013-08-10 05:30:41,016 INFO org.apache.hadoop.yarn.server.resourcemanager.rmcontainer.RMContainerImpl: container_1376111601621_0007_01_000004 Container Transitioned from ALLOCATED to ACQUIRED
2013-08-10 05:30:41,158 INFO org.apache.hadoop.yarn.server.resourcemanager.rmcontainer.RMContainerImpl: container_1376111601621_0007_01_000003 Container Transitioned from ACQUIRED to RUNNING
2013-08-10 05:30:41,159 INFO org.apache.hadoop.yarn.server.resourcemanager.rmcontainer.RMContainerImpl: container_1376111601621_0006_01_000022 Container Transitioned from RUNNING to COMPLETED
2013-08-10 05:30:41,159 INFO org.apache.hadoop.yarn.server.resourcemanager.scheduler.common.fica.FiCaSchedulerApp: Completed container: container_1376111601621_0006_01_000022 in state: COMPLETED event:FINISHED
2013-08-10 05:30:41,159 INFO org.apache.hadoop.yarn.server.resourcemanager.RMAuditLogger: USER=ubuntu	OPERATION=AM Released Container	TARGET=SchedulerApp	RESULT=SUCCESS	APPID=application_1376111601621_0006	CONTAINERID=container_1376111601621_0006_01_000022
2013-08-10 05:30:41,159 INFO org.apache.hadoop.yarn.server.resourcemanager.scheduler.common.fica.FiCaSchedulerNode: Released container container_1376111601621_0006_01_000022 of capacity <memory:1024, vCores:1> on host hadoop-221-3:43958, which currently has 6 containers, <memory:7168, vCores:6> used and <memory:1024, vCores:10> available, release resources=true
2013-08-10 05:30:41,159 INFO org.apache.hadoop.yarn.server.resourcemanager.scheduler.capacity.LeafQueue: default used=<memory:48128, vCores:42> numContainers=42 user=ubuntu user-resources=<memory:48128, vCores:42>
2013-08-10 05:30:41,161 INFO org.apache.hadoop.yarn.server.resourcemanager.scheduler.capacity.LeafQueue: completedContainer container=Container: [ContainerId: container_1376111601621_0006_01_000022, NodeId: hadoop-221-3:43958, NodeHttpAddress: hadoop-221-3:8042, Resource: <memory:1024, vCores:1>, Priority: 20, State: NEW, Token: null, Status: container_id {, app_attempt_id {, application_id {, id: 6, cluster_timestamp: 1376111601621, }, attemptId: 1, }, id: 22, }, state: C_COMPLETE, diagnostics: "Container killed by the ApplicationMaster.\n\n", exit_status: 143, ] resource=<memory:1024, vCores:1> queue=default: capacity=1.0, absoluteCapacity=1.0, usedResources=<memory:48128, vCores:42>usedCapacity=0.9791667, absoluteUsedCapacity=0.9791667, numApps=5, numContainers=42 usedCapacity=0.9791667 absoluteUsedCapacity=0.9791667 used=<memory:48128, vCores:42> cluster=<memory:49152, vCores:96>
2013-08-10 05:30:41,161 INFO org.apache.hadoop.yarn.server.resourcemanager.scheduler.capacity.ParentQueue: completedContainer queue=root usedCapacity=0.9791667 absoluteUsedCapacity=0.9791667 used=<memory:48128, vCores:42> cluster=<memory:49152, vCores:96>
2013-08-10 05:30:41,161 INFO org.apache.hadoop.yarn.server.resourcemanager.scheduler.capacity.CapacityScheduler: Application appattempt_1376111601621_0006_000001 released container container_1376111601621_0006_01_000022 on node: host: hadoop-221-3:43958 #containers=6 available=1024 used=7168 with event: FINISHED
2013-08-10 05:30:41,162 INFO org.apache.hadoop.yarn.server.resourcemanager.rmcontainer.RMContainerImpl: container_1376111601621_0007_01_000005 Container Transitioned from NEW to ALLOCATED
2013-08-10 05:30:41,162 INFO org.apache.hadoop.yarn.server.resourcemanager.RMAuditLogger: USER=ubuntu	OPERATION=AM Allocated Container	TARGET=SchedulerApp	RESULT=SUCCESS	APPID=application_1376111601621_0007	CONTAINERID=container_1376111601621_0007_01_000005
2013-08-10 05:30:41,162 INFO org.apache.hadoop.yarn.server.resourcemanager.scheduler.common.fica.FiCaSchedulerNode: Assigned container container_1376111601621_0007_01_000005 of capacity <memory:1024, vCores:1> on host hadoop-221-3:43958, which currently has 7 containers, <memory:8192, vCores:7> used and <memory:0, vCores:9> available
2013-08-10 05:30:41,163 INFO org.apache.hadoop.yarn.server.resourcemanager.scheduler.capacity.LeafQueue: assignedContainer application=application_1376111601621_0007 container=Container: [ContainerId: container_1376111601621_0007_01_000005, NodeId: hadoop-221-3:43958, NodeHttpAddress: hadoop-221-3:8042, Resource: <memory:1024, vCores:1>, Priority: 20, State: NEW, Token: null, Status: container_id {, app_attempt_id {, application_id {, id: 7, cluster_timestamp: 1376111601621, }, attemptId: 1, }, id: 5, }, state: C_NEW, ] containerId=container_1376111601621_0007_01_000005 queue=default: capacity=1.0, absoluteCapacity=1.0, usedResources=<memory:48128, vCores:42>usedCapacity=0.9791667, absoluteUsedCapacity=0.9791667, numApps=5, numContainers=42 usedCapacity=0.9791667 absoluteUsedCapacity=0.9791667 used=<memory:48128, vCores:42> cluster=<memory:49152, vCores:96>
2013-08-10 05:30:41,163 INFO org.apache.hadoop.yarn.server.resourcemanager.scheduler.capacity.ParentQueue: Re-sorting queues since queue: root.default stats: default: capacity=1.0, absoluteCapacity=1.0, usedResources=<memory:49152, vCores:43>usedCapacity=1.0, absoluteUsedCapacity=1.0, numApps=5, numContainers=43
2013-08-10 05:30:41,163 INFO org.apache.hadoop.yarn.server.resourcemanager.scheduler.capacity.ParentQueue: assignedContainer queue=root usedCapacity=1.0 absoluteUsedCapacity=1.0 used=<memory:49152, vCores:43> cluster=<memory:49152, vCores:96>
2013-08-10 05:30:41,229 INFO org.apache.hadoop.yarn.server.resourcemanager.rmcontainer.RMContainerImpl: container_1376111601621_0007_01_000002 Container Transitioned from ACQUIRED to RUNNING
2013-08-10 05:30:41,230 INFO org.apache.hadoop.yarn.server.resourcemanager.rmcontainer.RMContainerImpl: container_1376111601621_0006_01_000017 Container Transitioned from RUNNING to COMPLETED
2013-08-10 05:30:41,230 INFO org.apache.hadoop.yarn.server.resourcemanager.scheduler.common.fica.FiCaSchedulerApp: Completed container: container_1376111601621_0006_01_000017 in state: COMPLETED event:FINISHED
2013-08-10 05:30:41,230 INFO org.apache.hadoop.yarn.server.resourcemanager.RMAuditLogger: USER=ubuntu	OPERATION=AM Released Container	TARGET=SchedulerApp	RESULT=SUCCESS	APPID=application_1376111601621_0006	CONTAINERID=container_1376111601621_0006_01_000017
2013-08-10 05:30:41,230 INFO org.apache.hadoop.yarn.server.resourcemanager.scheduler.common.fica.FiCaSchedulerNode: Released container container_1376111601621_0006_01_000017 of capacity <memory:1024, vCores:1> on host hadoop-221-5:42694, which currently has 6 containers, <memory:7168, vCores:6> used and <memory:1024, vCores:10> available, release resources=true
2013-08-10 05:30:41,230 INFO org.apache.hadoop.yarn.server.resourcemanager.scheduler.capacity.LeafQueue: default used=<memory:48128, vCores:42> numContainers=42 user=ubuntu user-resources=<memory:48128, vCores:42>
2013-08-10 05:30:41,232 INFO org.apache.hadoop.yarn.server.resourcemanager.scheduler.capacity.LeafQueue: completedContainer container=Container: [ContainerId: container_1376111601621_0006_01_000017, NodeId: hadoop-221-5:42694, NodeHttpAddress: hadoop-221-5:8042, Resource: <memory:1024, vCores:1>, Priority: 20, State: NEW, Token: null, Status: container_id {, app_attempt_id {, application_id {, id: 6, cluster_timestamp: 1376111601621, }, attemptId: 1, }, id: 17, }, state: C_COMPLETE, diagnostics: "", exit_status: 0, ] resource=<memory:1024, vCores:1> queue=default: capacity=1.0, absoluteCapacity=1.0, usedResources=<memory:48128, vCores:42>usedCapacity=0.9791667, absoluteUsedCapacity=0.9791667, numApps=5, numContainers=42 usedCapacity=0.9791667 absoluteUsedCapacity=0.9791667 used=<memory:48128, vCores:42> cluster=<memory:49152, vCores:96>
2013-08-10 05:30:41,232 INFO org.apache.hadoop.yarn.server.resourcemanager.scheduler.capacity.ParentQueue: completedContainer queue=root usedCapacity=0.9791667 absoluteUsedCapacity=0.9791667 used=<memory:48128, vCores:42> cluster=<memory:49152, vCores:96>
2013-08-10 05:30:41,232 INFO org.apache.hadoop.yarn.server.resourcemanager.scheduler.capacity.CapacityScheduler: Application appattempt_1376111601621_0006_000001 released container container_1376111601621_0006_01_000017 on node: host: hadoop-221-5:42694 #containers=6 available=1024 used=7168 with event: FINISHED
2013-08-10 05:30:41,233 INFO org.apache.hadoop.yarn.server.resourcemanager.rmcontainer.RMContainerImpl: container_1376111601621_0007_01_000006 Container Transitioned from NEW to ALLOCATED
2013-08-10 05:30:41,233 INFO org.apache.hadoop.yarn.server.resourcemanager.RMAuditLogger: USER=ubuntu	OPERATION=AM Allocated Container	TARGET=SchedulerApp	RESULT=SUCCESS	APPID=application_1376111601621_0007	CONTAINERID=container_1376111601621_0007_01_000006
2013-08-10 05:30:41,233 INFO org.apache.hadoop.yarn.server.resourcemanager.scheduler.common.fica.FiCaSchedulerNode: Assigned container container_1376111601621_0007_01_000006 of capacity <memory:1024, vCores:1> on host hadoop-221-5:42694, which currently has 7 containers, <memory:8192, vCores:7> used and <memory:0, vCores:9> available
2013-08-10 05:30:41,234 INFO org.apache.hadoop.yarn.server.resourcemanager.scheduler.capacity.LeafQueue: assignedContainer application=application_1376111601621_0007 container=Container: [ContainerId: container_1376111601621_0007_01_000006, NodeId: hadoop-221-5:42694, NodeHttpAddress: hadoop-221-5:8042, Resource: <memory:1024, vCores:1>, Priority: 20, State: NEW, Token: null, Status: container_id {, app_attempt_id {, application_id {, id: 7, cluster_timestamp: 1376111601621, }, attemptId: 1, }, id: 6, }, state: C_NEW, ] containerId=container_1376111601621_0007_01_000006 queue=default: capacity=1.0, absoluteCapacity=1.0, usedResources=<memory:48128, vCores:42>usedCapacity=0.9791667, absoluteUsedCapacity=0.9791667, numApps=5, numContainers=42 usedCapacity=0.9791667 absoluteUsedCapacity=0.9791667 used=<memory:48128, vCores:42> cluster=<memory:49152, vCores:96>
2013-08-10 05:30:41,234 INFO org.apache.hadoop.yarn.server.resourcemanager.scheduler.capacity.ParentQueue: Re-sorting queues since queue: root.default stats: default: capacity=1.0, absoluteCapacity=1.0, usedResources=<memory:49152, vCores:43>usedCapacity=1.0, absoluteUsedCapacity=1.0, numApps=5, numContainers=43
2013-08-10 05:30:41,235 INFO org.apache.hadoop.yarn.server.resourcemanager.scheduler.capacity.ParentQueue: assignedContainer queue=root usedCapacity=1.0 absoluteUsedCapacity=1.0 used=<memory:49152, vCores:43> cluster=<memory:49152, vCores:96>
2013-08-10 05:30:41,377 INFO org.apache.hadoop.yarn.server.resourcemanager.rmcontainer.RMContainerImpl: container_1376111601621_0007_01_000004 Container Transitioned from ACQUIRED to RUNNING
2013-08-10 05:30:42,069 INFO org.apache.hadoop.yarn.server.resourcemanager.rmcontainer.RMContainerImpl: container_1376111601621_0007_01_000005 Container Transitioned from ALLOCATED to ACQUIRED
2013-08-10 05:30:42,070 INFO org.apache.hadoop.yarn.server.resourcemanager.rmcontainer.RMContainerImpl: container_1376111601621_0007_01_000006 Container Transitioned from ALLOCATED to ACQUIRED
2013-08-10 05:30:42,167 INFO org.apache.hadoop.yarn.server.resourcemanager.rmcontainer.RMContainerImpl: container_1376111601621_0007_01_000005 Container Transitioned from ACQUIRED to RUNNING
2013-08-10 05:30:42,189 INFO org.apache.hadoop.yarn.server.resourcemanager.rmcontainer.RMContainerImpl: container_1376111601621_0007_01_000006 Container Transitioned from ACQUIRED to RUNNING
2013-08-10 05:30:43,200 INFO org.apache.hadoop.yarn.server.resourcemanager.rmcontainer.RMContainerImpl: container_1376111601621_0006_01_000018 Container Transitioned from RUNNING to COMPLETED
2013-08-10 05:30:43,201 INFO org.apache.hadoop.yarn.server.resourcemanager.scheduler.common.fica.FiCaSchedulerApp: Completed container: container_1376111601621_0006_01_000018 in state: COMPLETED event:FINISHED
2013-08-10 05:30:43,201 INFO org.apache.hadoop.yarn.server.resourcemanager.RMAuditLogger: USER=ubuntu	OPERATION=AM Released Container	TARGET=SchedulerApp	RESULT=SUCCESS	APPID=application_1376111601621_0006	CONTAINERID=container_1376111601621_0006_01_000018
2013-08-10 05:30:43,201 INFO org.apache.hadoop.yarn.server.resourcemanager.scheduler.common.fica.FiCaSchedulerNode: Released container container_1376111601621_0006_01_000018 of capacity <memory:1024, vCores:1> on host hadoop-221-5:42694, which currently has 6 containers, <memory:7168, vCores:6> used and <memory:1024, vCores:10> available, release resources=true
2013-08-10 05:30:43,201 INFO org.apache.hadoop.yarn.server.resourcemanager.scheduler.capacity.LeafQueue: default used=<memory:48128, vCores:42> numContainers=42 user=ubuntu user-resources=<memory:48128, vCores:42>
2013-08-10 05:30:43,203 INFO org.apache.hadoop.yarn.server.resourcemanager.scheduler.capacity.LeafQueue: completedContainer container=Container: [ContainerId: container_1376111601621_0006_01_000018, NodeId: hadoop-221-5:42694, NodeHttpAddress: hadoop-221-5:8042, Resource: <memory:1024, vCores:1>, Priority: 20, State: NEW, Token: null, Status: container_id {, app_attempt_id {, application_id {, id: 6, cluster_timestamp: 1376111601621, }, attemptId: 1, }, id: 18, }, state: C_COMPLETE, diagnostics: "Container killed by the ApplicationMaster.\n", exit_status: 0, ] resource=<memory:1024, vCores:1> queue=default: capacity=1.0, absoluteCapacity=1.0, usedResources=<memory:48128, vCores:42>usedCapacity=0.9791667, absoluteUsedCapacity=0.9791667, numApps=5, numContainers=42 usedCapacity=0.9791667 absoluteUsedCapacity=0.9791667 used=<memory:48128, vCores:42> cluster=<memory:49152, vCores:96>
2013-08-10 05:30:43,203 INFO org.apache.hadoop.yarn.server.resourcemanager.scheduler.capacity.ParentQueue: completedContainer queue=root usedCapacity=0.9791667 absoluteUsedCapacity=0.9791667 used=<memory:48128, vCores:42> cluster=<memory:49152, vCores:96>
2013-08-10 05:30:43,203 INFO org.apache.hadoop.yarn.server.resourcemanager.scheduler.capacity.CapacityScheduler: Application appattempt_1376111601621_0006_000001 released container container_1376111601621_0006_01_000018 on node: host: hadoop-221-5:42694 #containers=6 available=1024 used=7168 with event: FINISHED
2013-08-10 05:30:43,204 INFO org.apache.hadoop.yarn.server.resourcemanager.rmcontainer.RMContainerImpl: container_1376111601621_0007_01_000007 Container Transitioned from NEW to ALLOCATED
2013-08-10 05:30:43,204 INFO org.apache.hadoop.yarn.server.resourcemanager.RMAuditLogger: USER=ubuntu	OPERATION=AM Allocated Container	TARGET=SchedulerApp	RESULT=SUCCESS	APPID=application_1376111601621_0007	CONTAINERID=container_1376111601621_0007_01_000007
2013-08-10 05:30:43,204 INFO org.apache.hadoop.yarn.server.resourcemanager.scheduler.common.fica.FiCaSchedulerNode: Assigned container container_1376111601621_0007_01_000007 of capacity <memory:1024, vCores:1> on host hadoop-221-5:42694, which currently has 7 containers, <memory:8192, vCores:7> used and <memory:0, vCores:9> available
2013-08-10 05:30:43,205 INFO org.apache.hadoop.yarn.server.resourcemanager.scheduler.capacity.LeafQueue: assignedContainer application=application_1376111601621_0007 container=Container: [ContainerId: container_1376111601621_0007_01_000007, NodeId: hadoop-221-5:42694, NodeHttpAddress: hadoop-221-5:8042, Resource: <memory:1024, vCores:1>, Priority: 20, State: NEW, Token: null, Status: container_id {, app_attempt_id {, application_id {, id: 7, cluster_timestamp: 1376111601621, }, attemptId: 1, }, id: 7, }, state: C_NEW, ] containerId=container_1376111601621_0007_01_000007 queue=default: capacity=1.0, absoluteCapacity=1.0, usedResources=<memory:48128, vCores:42>usedCapacity=0.9791667, absoluteUsedCapacity=0.9791667, numApps=5, numContainers=42 usedCapacity=0.9791667 absoluteUsedCapacity=0.9791667 used=<memory:48128, vCores:42> cluster=<memory:49152, vCores:96>
2013-08-10 05:30:43,205 INFO org.apache.hadoop.yarn.server.resourcemanager.scheduler.capacity.ParentQueue: Re-sorting queues since queue: root.default stats: default: capacity=1.0, absoluteCapacity=1.0, usedResources=<memory:49152, vCores:43>usedCapacity=1.0, absoluteUsedCapacity=1.0, numApps=5, numContainers=43
2013-08-10 05:30:43,205 INFO org.apache.hadoop.yarn.server.resourcemanager.scheduler.capacity.ParentQueue: assignedContainer queue=root usedCapacity=1.0 absoluteUsedCapacity=1.0 used=<memory:49152, vCores:43> cluster=<memory:49152, vCores:96>
2013-08-10 05:30:44,202 INFO org.apache.hadoop.yarn.server.resourcemanager.rmcontainer.RMContainerImpl: container_1376111601621_0007_01_000007 Container Transitioned from ALLOCATED to ACQUIRED
2013-08-10 05:30:45,238 INFO org.apache.hadoop.yarn.server.resourcemanager.rmcontainer.RMContainerImpl: container_1376111601621_0007_01_000007 Container Transitioned from ACQUIRED to RUNNING
2013-08-10 05:30:47,377 INFO org.apache.hadoop.yarn.server.resourcemanager.rmcontainer.RMContainerImpl: container_1376111601621_0006_01_000007 Container Transitioned from RUNNING to COMPLETED
2013-08-10 05:30:47,378 INFO org.apache.hadoop.yarn.server.resourcemanager.scheduler.common.fica.FiCaSchedulerApp: Completed container: container_1376111601621_0006_01_000007 in state: COMPLETED event:FINISHED
2013-08-10 05:30:47,378 INFO org.apache.hadoop.yarn.server.resourcemanager.RMAuditLogger: USER=ubuntu	OPERATION=AM Released Container	TARGET=SchedulerApp	RESULT=SUCCESS	APPID=application_1376111601621_0006	CONTAINERID=container_1376111601621_0006_01_000007
2013-08-10 05:30:47,378 INFO org.apache.hadoop.yarn.server.resourcemanager.scheduler.common.fica.FiCaSchedulerNode: Released container container_1376111601621_0006_01_000007 of capacity <memory:1024, vCores:1> on host hadoop-221-2:55267, which currently has 7 containers, <memory:7168, vCores:7> used and <memory:1024, vCores:9> available, release resources=true
2013-08-10 05:30:47,378 INFO org.apache.hadoop.yarn.server.resourcemanager.scheduler.capacity.LeafQueue: default used=<memory:48128, vCores:42> numContainers=42 user=ubuntu user-resources=<memory:48128, vCores:42>
2013-08-10 05:30:47,379 INFO org.apache.hadoop.yarn.server.resourcemanager.scheduler.capacity.LeafQueue: completedContainer container=Container: [ContainerId: container_1376111601621_0006_01_000007, NodeId: hadoop-221-2:55267, NodeHttpAddress: hadoop-221-2:8042, Resource: <memory:1024, vCores:1>, Priority: 20, State: NEW, Token: null, Status: container_id {, app_attempt_id {, application_id {, id: 6, cluster_timestamp: 1376111601621, }, attemptId: 1, }, id: 7, }, state: C_COMPLETE, diagnostics: "Container killed by the ApplicationMaster.\n\n", exit_status: 143, ] resource=<memory:1024, vCores:1> queue=default: capacity=1.0, absoluteCapacity=1.0, usedResources=<memory:48128, vCores:42>usedCapacity=0.9791667, absoluteUsedCapacity=0.9791667, numApps=5, numContainers=42 usedCapacity=0.9791667 absoluteUsedCapacity=0.9791667 used=<memory:48128, vCores:42> cluster=<memory:49152, vCores:96>
2013-08-10 05:30:47,380 INFO org.apache.hadoop.yarn.server.resourcemanager.scheduler.capacity.ParentQueue: completedContainer queue=root usedCapacity=0.9791667 absoluteUsedCapacity=0.9791667 used=<memory:48128, vCores:42> cluster=<memory:49152, vCores:96>
2013-08-10 05:30:47,380 INFO org.apache.hadoop.yarn.server.resourcemanager.scheduler.capacity.CapacityScheduler: Application appattempt_1376111601621_0006_000001 released container container_1376111601621_0006_01_000007 on node: host: hadoop-221-2:55267 #containers=7 available=1024 used=7168 with event: FINISHED
2013-08-10 05:30:47,380 INFO org.apache.hadoop.yarn.server.resourcemanager.rmcontainer.RMContainerImpl: container_1376111601621_0007_01_000008 Container Transitioned from NEW to ALLOCATED
2013-08-10 05:30:47,380 INFO org.apache.hadoop.yarn.server.resourcemanager.RMAuditLogger: USER=ubuntu	OPERATION=AM Allocated Container	TARGET=SchedulerApp	RESULT=SUCCESS	APPID=application_1376111601621_0007	CONTAINERID=container_1376111601621_0007_01_000008
2013-08-10 05:30:47,381 INFO org.apache.hadoop.yarn.server.resourcemanager.scheduler.common.fica.FiCaSchedulerNode: Assigned container container_1376111601621_0007_01_000008 of capacity <memory:1024, vCores:1> on host hadoop-221-2:55267, which currently has 8 containers, <memory:8192, vCores:8> used and <memory:0, vCores:8> available
2013-08-10 05:30:47,381 INFO org.apache.hadoop.yarn.server.resourcemanager.scheduler.capacity.LeafQueue: assignedContainer application=application_1376111601621_0007 container=Container: [ContainerId: container_1376111601621_0007_01_000008, NodeId: hadoop-221-2:55267, NodeHttpAddress: hadoop-221-2:8042, Resource: <memory:1024, vCores:1>, Priority: 20, State: NEW, Token: null, Status: container_id {, app_attempt_id {, application_id {, id: 7, cluster_timestamp: 1376111601621, }, attemptId: 1, }, id: 8, }, state: C_NEW, ] containerId=container_1376111601621_0007_01_000008 queue=default: capacity=1.0, absoluteCapacity=1.0, usedResources=<memory:48128, vCores:42>usedCapacity=0.9791667, absoluteUsedCapacity=0.9791667, numApps=5, numContainers=42 usedCapacity=0.9791667 absoluteUsedCapacity=0.9791667 used=<memory:48128, vCores:42> cluster=<memory:49152, vCores:96>
2013-08-10 05:30:47,382 INFO org.apache.hadoop.yarn.server.resourcemanager.scheduler.capacity.ParentQueue: Re-sorting queues since queue: root.default stats: default: capacity=1.0, absoluteCapacity=1.0, usedResources=<memory:49152, vCores:43>usedCapacity=1.0, absoluteUsedCapacity=1.0, numApps=5, numContainers=43
2013-08-10 05:30:47,382 INFO org.apache.hadoop.yarn.server.resourcemanager.scheduler.capacity.ParentQueue: assignedContainer queue=root usedCapacity=1.0 absoluteUsedCapacity=1.0 used=<memory:49152, vCores:43> cluster=<memory:49152, vCores:96>
2013-08-10 05:30:48,358 INFO org.apache.hadoop.yarn.server.resourcemanager.rmcontainer.RMContainerImpl: container_1376111601621_0007_01_000008 Container Transitioned from ALLOCATED to ACQUIRED
2013-08-10 05:30:48,363 INFO org.apache.hadoop.yarn.server.resourcemanager.rmcontainer.RMContainerImpl: container_1376111601621_0006_01_000020 Container Transitioned from RUNNING to COMPLETED
2013-08-10 05:30:48,363 INFO org.apache.hadoop.yarn.server.resourcemanager.scheduler.common.fica.FiCaSchedulerApp: Completed container: container_1376111601621_0006_01_000020 in state: COMPLETED event:FINISHED
2013-08-10 05:30:48,363 INFO org.apache.hadoop.yarn.server.resourcemanager.RMAuditLogger: USER=ubuntu	OPERATION=AM Released Container	TARGET=SchedulerApp	RESULT=SUCCESS	APPID=application_1376111601621_0006	CONTAINERID=container_1376111601621_0006_01_000020
2013-08-10 05:30:48,363 INFO org.apache.hadoop.yarn.server.resourcemanager.scheduler.common.fica.FiCaSchedulerNode: Released container container_1376111601621_0006_01_000020 of capacity <memory:1024, vCores:1> on host hadoop-221-5:42694, which currently has 6 containers, <memory:7168, vCores:6> used and <memory:1024, vCores:10> available, release resources=true
2013-08-10 05:30:48,363 INFO org.apache.hadoop.yarn.server.resourcemanager.scheduler.capacity.LeafQueue: default used=<memory:48128, vCores:42> numContainers=42 user=ubuntu user-resources=<memory:48128, vCores:42>
2013-08-10 05:30:48,365 INFO org.apache.hadoop.yarn.server.resourcemanager.scheduler.capacity.LeafQueue: completedContainer container=Container: [ContainerId: container_1376111601621_0006_01_000020, NodeId: hadoop-221-5:42694, NodeHttpAddress: hadoop-221-5:8042, Resource: <memory:1024, vCores:1>, Priority: 20, State: NEW, Token: null, Status: container_id {, app_attempt_id {, application_id {, id: 6, cluster_timestamp: 1376111601621, }, attemptId: 1, }, id: 20, }, state: C_COMPLETE, diagnostics: "Container killed by the ApplicationMaster.\n\n", exit_status: 143, ] resource=<memory:1024, vCores:1> queue=default: capacity=1.0, absoluteCapacity=1.0, usedResources=<memory:48128, vCores:42>usedCapacity=0.9791667, absoluteUsedCapacity=0.9791667, numApps=5, numContainers=42 usedCapacity=0.9791667 absoluteUsedCapacity=0.9791667 used=<memory:48128, vCores:42> cluster=<memory:49152, vCores:96>
2013-08-10 05:30:48,365 INFO org.apache.hadoop.yarn.server.resourcemanager.scheduler.capacity.ParentQueue: completedContainer queue=root usedCapacity=0.9791667 absoluteUsedCapacity=0.9791667 used=<memory:48128, vCores:42> cluster=<memory:49152, vCores:96>
2013-08-10 05:30:48,365 INFO org.apache.hadoop.yarn.server.resourcemanager.scheduler.capacity.CapacityScheduler: Application appattempt_1376111601621_0006_000001 released container container_1376111601621_0006_01_000020 on node: host: hadoop-221-5:42694 #containers=6 available=1024 used=7168 with event: FINISHED
2013-08-10 05:30:48,365 INFO org.apache.hadoop.yarn.server.resourcemanager.rmcontainer.RMContainerImpl: container_1376111601621_0007_01_000009 Container Transitioned from NEW to ALLOCATED
2013-08-10 05:30:48,366 INFO org.apache.hadoop.yarn.server.resourcemanager.RMAuditLogger: USER=ubuntu	OPERATION=AM Allocated Container	TARGET=SchedulerApp	RESULT=SUCCESS	APPID=application_1376111601621_0007	CONTAINERID=container_1376111601621_0007_01_000009
2013-08-10 05:30:48,366 INFO org.apache.hadoop.yarn.server.resourcemanager.scheduler.common.fica.FiCaSchedulerNode: Assigned container container_1376111601621_0007_01_000009 of capacity <memory:1024, vCores:1> on host hadoop-221-5:42694, which currently has 7 containers, <memory:8192, vCores:7> used and <memory:0, vCores:9> available
2013-08-10 05:30:48,367 INFO org.apache.hadoop.yarn.server.resourcemanager.scheduler.capacity.LeafQueue: assignedContainer application=application_1376111601621_0007 container=Container: [ContainerId: container_1376111601621_0007_01_000009, NodeId: hadoop-221-5:42694, NodeHttpAddress: hadoop-221-5:8042, Resource: <memory:1024, vCores:1>, Priority: 20, State: NEW, Token: null, Status: container_id {, app_attempt_id {, application_id {, id: 7, cluster_timestamp: 1376111601621, }, attemptId: 1, }, id: 9, }, state: C_NEW, ] containerId=container_1376111601621_0007_01_000009 queue=default: capacity=1.0, absoluteCapacity=1.0, usedResources=<memory:48128, vCores:42>usedCapacity=0.9791667, absoluteUsedCapacity=0.9791667, numApps=5, numContainers=42 usedCapacity=0.9791667 absoluteUsedCapacity=0.9791667 used=<memory:48128, vCores:42> cluster=<memory:49152, vCores:96>
2013-08-10 05:30:48,367 INFO org.apache.hadoop.yarn.server.resourcemanager.scheduler.capacity.ParentQueue: Re-sorting queues since queue: root.default stats: default: capacity=1.0, absoluteCapacity=1.0, usedResources=<memory:49152, vCores:43>usedCapacity=1.0, absoluteUsedCapacity=1.0, numApps=5, numContainers=43
2013-08-10 05:30:48,367 INFO org.apache.hadoop.yarn.server.resourcemanager.scheduler.capacity.ParentQueue: assignedContainer queue=root usedCapacity=1.0 absoluteUsedCapacity=1.0 used=<memory:49152, vCores:43> cluster=<memory:49152, vCores:96>
2013-08-10 05:30:49,082 INFO org.apache.hadoop.yarn.server.resourcemanager.rmcontainer.RMContainerImpl: container_1376111601621_0007_01_000008 Container Transitioned from ACQUIRED to RUNNING
2013-08-10 05:30:49,082 INFO org.apache.hadoop.yarn.server.resourcemanager.rmcontainer.RMContainerImpl: container_1376111601621_0006_01_000004 Container Transitioned from RUNNING to COMPLETED
2013-08-10 05:30:49,082 INFO org.apache.hadoop.yarn.server.resourcemanager.scheduler.common.fica.FiCaSchedulerApp: Completed container: container_1376111601621_0006_01_000004 in state: COMPLETED event:FINISHED
2013-08-10 05:30:49,082 INFO org.apache.hadoop.yarn.server.resourcemanager.RMAuditLogger: USER=ubuntu	OPERATION=AM Released Container	TARGET=SchedulerApp	RESULT=SUCCESS	APPID=application_1376111601621_0006	CONTAINERID=container_1376111601621_0006_01_000004
2013-08-10 05:30:49,083 INFO org.apache.hadoop.yarn.server.resourcemanager.scheduler.common.fica.FiCaSchedulerNode: Released container container_1376111601621_0006_01_000004 of capacity <memory:1024, vCores:1> on host hadoop-221-2:55267, which currently has 7 containers, <memory:7168, vCores:7> used and <memory:1024, vCores:9> available, release resources=true
2013-08-10 05:30:49,083 INFO org.apache.hadoop.yarn.server.resourcemanager.scheduler.capacity.LeafQueue: default used=<memory:48128, vCores:42> numContainers=42 user=ubuntu user-resources=<memory:48128, vCores:42>
2013-08-10 05:30:49,084 INFO org.apache.hadoop.yarn.server.resourcemanager.scheduler.capacity.LeafQueue: completedContainer container=Container: [ContainerId: container_1376111601621_0006_01_000004, NodeId: hadoop-221-2:55267, NodeHttpAddress: hadoop-221-2:8042, Resource: <memory:1024, vCores:1>, Priority: 20, State: NEW, Token: null, Status: container_id {, app_attempt_id {, application_id {, id: 6, cluster_timestamp: 1376111601621, }, attemptId: 1, }, id: 4, }, state: C_COMPLETE, diagnostics: "Container killed by the ApplicationMaster.\n\n", exit_status: 143, ] resource=<memory:1024, vCores:1> queue=default: capacity=1.0, absoluteCapacity=1.0, usedResources=<memory:48128, vCores:42>usedCapacity=0.9791667, absoluteUsedCapacity=0.9791667, numApps=5, numContainers=42 usedCapacity=0.9791667 absoluteUsedCapacity=0.9791667 used=<memory:48128, vCores:42> cluster=<memory:49152, vCores:96>
2013-08-10 05:30:49,084 INFO org.apache.hadoop.yarn.server.resourcemanager.scheduler.capacity.ParentQueue: completedContainer queue=root usedCapacity=0.9791667 absoluteUsedCapacity=0.9791667 used=<memory:48128, vCores:42> cluster=<memory:49152, vCores:96>
2013-08-10 05:30:49,084 INFO org.apache.hadoop.yarn.server.resourcemanager.scheduler.capacity.CapacityScheduler: Application appattempt_1376111601621_0006_000001 released container container_1376111601621_0006_01_000004 on node: host: hadoop-221-2:55267 #containers=7 available=1024 used=7168 with event: FINISHED
2013-08-10 05:30:49,085 INFO org.apache.hadoop.yarn.server.resourcemanager.rmcontainer.RMContainerImpl: container_1376111601621_0007_01_000010 Container Transitioned from NEW to ALLOCATED
2013-08-10 05:30:49,085 INFO org.apache.hadoop.yarn.server.resourcemanager.RMAuditLogger: USER=ubuntu	OPERATION=AM Allocated Container	TARGET=SchedulerApp	RESULT=SUCCESS	APPID=application_1376111601621_0007	CONTAINERID=container_1376111601621_0007_01_000010
2013-08-10 05:30:49,085 INFO org.apache.hadoop.yarn.server.resourcemanager.scheduler.common.fica.FiCaSchedulerNode: Assigned container container_1376111601621_0007_01_000010 of capacity <memory:1024, vCores:1> on host hadoop-221-2:55267, which currently has 8 containers, <memory:8192, vCores:8> used and <memory:0, vCores:8> available
2013-08-10 05:30:49,086 INFO org.apache.hadoop.yarn.server.resourcemanager.scheduler.capacity.LeafQueue: assignedContainer application=application_1376111601621_0007 container=Container: [ContainerId: container_1376111601621_0007_01_000010, NodeId: hadoop-221-2:55267, NodeHttpAddress: hadoop-221-2:8042, Resource: <memory:1024, vCores:1>, Priority: 20, State: NEW, Token: null, Status: container_id {, app_attempt_id {, application_id {, id: 7, cluster_timestamp: 1376111601621, }, attemptId: 1, }, id: 10, }, state: C_NEW, ] containerId=container_1376111601621_0007_01_000010 queue=default: capacity=1.0, absoluteCapacity=1.0, usedResources=<memory:48128, vCores:42>usedCapacity=0.9791667, absoluteUsedCapacity=0.9791667, numApps=5, numContainers=42 usedCapacity=0.9791667 absoluteUsedCapacity=0.9791667 used=<memory:48128, vCores:42> cluster=<memory:49152, vCores:96>
2013-08-10 05:30:49,086 INFO org.apache.hadoop.yarn.server.resourcemanager.scheduler.capacity.ParentQueue: Re-sorting queues since queue: root.default stats: default: capacity=1.0, absoluteCapacity=1.0, usedResources=<memory:49152, vCores:43>usedCapacity=1.0, absoluteUsedCapacity=1.0, numApps=5, numContainers=43
2013-08-10 05:30:49,087 INFO org.apache.hadoop.yarn.server.resourcemanager.scheduler.capacity.ParentQueue: assignedContainer queue=root usedCapacity=1.0 absoluteUsedCapacity=1.0 used=<memory:49152, vCores:43> cluster=<memory:49152, vCores:96>
2013-08-10 05:30:49,392 INFO org.apache.hadoop.yarn.server.resourcemanager.rmcontainer.RMContainerImpl: container_1376111601621_0007_01_000009 Container Transitioned from ALLOCATED to ACQUIRED
2013-08-10 05:30:49,394 INFO org.apache.hadoop.yarn.server.resourcemanager.rmcontainer.RMContainerImpl: container_1376111601621_0007_01_000010 Container Transitioned from ALLOCATED to ACQUIRED
2013-08-10 05:30:49,423 INFO org.apache.hadoop.yarn.server.resourcemanager.rmcontainer.RMContainerImpl: container_1376111601621_0006_01_000021 Container Transitioned from RUNNING to COMPLETED
2013-08-10 05:30:49,423 INFO org.apache.hadoop.yarn.server.resourcemanager.scheduler.common.fica.FiCaSchedulerApp: Completed container: container_1376111601621_0006_01_000021 in state: COMPLETED event:FINISHED
2013-08-10 05:30:49,423 INFO org.apache.hadoop.yarn.server.resourcemanager.RMAuditLogger: USER=ubuntu	OPERATION=AM Released Container	TARGET=SchedulerApp	RESULT=SUCCESS	APPID=application_1376111601621_0006	CONTAINERID=container_1376111601621_0006_01_000021
2013-08-10 05:30:49,424 INFO org.apache.hadoop.yarn.server.resourcemanager.scheduler.common.fica.FiCaSchedulerNode: Released container container_1376111601621_0006_01_000021 of capacity <memory:1024, vCores:1> on host hadoop-221-5:42694, which currently has 6 containers, <memory:7168, vCores:6> used and <memory:1024, vCores:10> available, release resources=true
2013-08-10 05:30:49,424 INFO org.apache.hadoop.yarn.server.resourcemanager.scheduler.capacity.LeafQueue: default used=<memory:48128, vCores:42> numContainers=42 user=ubuntu user-resources=<memory:48128, vCores:42>
2013-08-10 05:30:49,425 INFO org.apache.hadoop.yarn.server.resourcemanager.scheduler.capacity.LeafQueue: completedContainer container=Container: [ContainerId: container_1376111601621_0006_01_000021, NodeId: hadoop-221-5:42694, NodeHttpAddress: hadoop-221-5:8042, Resource: <memory:1024, vCores:1>, Priority: 20, State: NEW, Token: null, Status: container_id {, app_attempt_id {, application_id {, id: 6, cluster_timestamp: 1376111601621, }, attemptId: 1, }, id: 21, }, state: C_COMPLETE, diagnostics: "Container killed by the ApplicationMaster.\n", exit_status: 0, ] resource=<memory:1024, vCores:1> queue=default: capacity=1.0, absoluteCapacity=1.0, usedResources=<memory:48128, vCores:42>usedCapacity=0.9791667, absoluteUsedCapacity=0.9791667, numApps=5, numContainers=42 usedCapacity=0.9791667 absoluteUsedCapacity=0.9791667 used=<memory:48128, vCores:42> cluster=<memory:49152, vCores:96>
2013-08-10 05:30:49,425 INFO org.apache.hadoop.yarn.server.resourcemanager.scheduler.capacity.ParentQueue: completedContainer queue=root usedCapacity=0.9791667 absoluteUsedCapacity=0.9791667 used=<memory:48128, vCores:42> cluster=<memory:49152, vCores:96>
2013-08-10 05:30:49,425 INFO org.apache.hadoop.yarn.server.resourcemanager.scheduler.capacity.CapacityScheduler: Application appattempt_1376111601621_0006_000001 released container container_1376111601621_0006_01_000021 on node: host: hadoop-221-5:42694 #containers=6 available=1024 used=7168 with event: FINISHED
2013-08-10 05:30:49,426 INFO org.apache.hadoop.yarn.server.resourcemanager.rmcontainer.RMContainerImpl: container_1376111601621_0007_01_000011 Container Transitioned from NEW to ALLOCATED
2013-08-10 05:30:49,426 INFO org.apache.hadoop.yarn.server.resourcemanager.RMAuditLogger: USER=ubuntu	OPERATION=AM Allocated Container	TARGET=SchedulerApp	RESULT=SUCCESS	APPID=application_1376111601621_0007	CONTAINERID=container_1376111601621_0007_01_000011
2013-08-10 05:30:49,426 INFO org.apache.hadoop.yarn.server.resourcemanager.scheduler.common.fica.FiCaSchedulerNode: Assigned container container_1376111601621_0007_01_000011 of capacity <memory:1024, vCores:1> on host hadoop-221-5:42694, which currently has 7 containers, <memory:8192, vCores:7> used and <memory:0, vCores:9> available
2013-08-10 05:30:49,427 INFO org.apache.hadoop.yarn.server.resourcemanager.scheduler.capacity.LeafQueue: assignedContainer application=application_1376111601621_0007 container=Container: [ContainerId: container_1376111601621_0007_01_000011, NodeId: hadoop-221-5:42694, NodeHttpAddress: hadoop-221-5:8042, Resource: <memory:1024, vCores:1>, Priority: 20, State: NEW, Token: null, Status: container_id {, app_attempt_id {, application_id {, id: 7, cluster_timestamp: 1376111601621, }, attemptId: 1, }, id: 11, }, state: C_NEW, ] containerId=container_1376111601621_0007_01_000011 queue=default: capacity=1.0, absoluteCapacity=1.0, usedResources=<memory:48128, vCores:42>usedCapacity=0.9791667, absoluteUsedCapacity=0.9791667, numApps=5, numContainers=42 usedCapacity=0.9791667 absoluteUsedCapacity=0.9791667 used=<memory:48128, vCores:42> cluster=<memory:49152, vCores:96>
2013-08-10 05:30:49,428 INFO org.apache.hadoop.yarn.server.resourcemanager.scheduler.capacity.ParentQueue: Re-sorting queues since queue: root.default stats: default: capacity=1.0, absoluteCapacity=1.0, usedResources=<memory:49152, vCores:43>usedCapacity=1.0, absoluteUsedCapacity=1.0, numApps=5, numContainers=43
2013-08-10 05:30:49,428 INFO org.apache.hadoop.yarn.server.resourcemanager.scheduler.capacity.ParentQueue: assignedContainer queue=root usedCapacity=1.0 absoluteUsedCapacity=1.0 used=<memory:49152, vCores:43> cluster=<memory:49152, vCores:96>
2013-08-10 05:30:50,092 INFO org.apache.hadoop.yarn.server.resourcemanager.rmcontainer.RMContainerImpl: container_1376111601621_0007_01_000010 Container Transitioned from ACQUIRED to RUNNING
2013-08-10 05:30:50,414 INFO org.apache.hadoop.yarn.server.resourcemanager.rmcontainer.RMContainerImpl: container_1376111601621_0007_01_000011 Container Transitioned from ALLOCATED to ACQUIRED
2013-08-10 05:30:50,433 INFO org.apache.hadoop.yarn.server.resourcemanager.rmcontainer.RMContainerImpl: container_1376111601621_0007_01_000009 Container Transitioned from ACQUIRED to RUNNING
2013-08-10 05:30:51,465 INFO org.apache.hadoop.yarn.server.resourcemanager.rmcontainer.RMContainerImpl: container_1376111601621_0007_01_000011 Container Transitioned from ACQUIRED to RUNNING
2013-08-10 05:30:52,395 INFO org.apache.hadoop.yarn.server.resourcemanager.rmcontainer.RMContainerImpl: container_1376111601621_0006_01_000035 Container Transitioned from RUNNING to COMPLETED
2013-08-10 05:30:52,395 INFO org.apache.hadoop.yarn.server.resourcemanager.scheduler.common.fica.FiCaSchedulerApp: Completed container: container_1376111601621_0006_01_000035 in state: COMPLETED event:FINISHED
2013-08-10 05:30:52,395 INFO org.apache.hadoop.yarn.server.resourcemanager.RMAuditLogger: USER=ubuntu	OPERATION=AM Released Container	TARGET=SchedulerApp	RESULT=SUCCESS	APPID=application_1376111601621_0006	CONTAINERID=container_1376111601621_0006_01_000035
2013-08-10 05:30:52,395 INFO org.apache.hadoop.yarn.server.resourcemanager.scheduler.common.fica.FiCaSchedulerNode: Released container container_1376111601621_0006_01_000035 of capacity <memory:1024, vCores:1> on host hadoop-221-4:41177, which currently has 6 containers, <memory:7168, vCores:6> used and <memory:1024, vCores:10> available, release resources=true
2013-08-10 05:30:52,395 INFO org.apache.hadoop.yarn.server.resourcemanager.scheduler.capacity.LeafQueue: default used=<memory:48128, vCores:42> numContainers=42 user=ubuntu user-resources=<memory:48128, vCores:42>
2013-08-10 05:30:52,397 INFO org.apache.hadoop.yarn.server.resourcemanager.scheduler.capacity.LeafQueue: completedContainer container=Container: [ContainerId: container_1376111601621_0006_01_000035, NodeId: hadoop-221-4:41177, NodeHttpAddress: hadoop-221-4:8042, Resource: <memory:1024, vCores:1>, Priority: 20, State: NEW, Token: null, Status: container_id {, app_attempt_id {, application_id {, id: 6, cluster_timestamp: 1376111601621, }, attemptId: 1, }, id: 35, }, state: C_COMPLETE, diagnostics: "Container killed by the ApplicationMaster.\n\n", exit_status: 143, ] resource=<memory:1024, vCores:1> queue=default: capacity=1.0, absoluteCapacity=1.0, usedResources=<memory:48128, vCores:42>usedCapacity=0.9791667, absoluteUsedCapacity=0.9791667, numApps=5, numContainers=42 usedCapacity=0.9791667 absoluteUsedCapacity=0.9791667 used=<memory:48128, vCores:42> cluster=<memory:49152, vCores:96>
2013-08-10 05:30:52,397 INFO org.apache.hadoop.yarn.server.resourcemanager.scheduler.capacity.ParentQueue: completedContainer queue=root usedCapacity=0.9791667 absoluteUsedCapacity=0.9791667 used=<memory:48128, vCores:42> cluster=<memory:49152, vCores:96>
2013-08-10 05:30:52,397 INFO org.apache.hadoop.yarn.server.resourcemanager.scheduler.capacity.CapacityScheduler: Application appattempt_1376111601621_0006_000001 released container container_1376111601621_0006_01_000035 on node: host: hadoop-221-4:41177 #containers=6 available=1024 used=7168 with event: FINISHED
2013-08-10 05:30:52,398 INFO org.apache.hadoop.yarn.server.resourcemanager.rmcontainer.RMContainerImpl: container_1376111601621_0006_01_000045 Container Transitioned from NEW to ALLOCATED
2013-08-10 05:30:52,398 INFO org.apache.hadoop.yarn.server.resourcemanager.RMAuditLogger: USER=ubuntu	OPERATION=AM Allocated Container	TARGET=SchedulerApp	RESULT=SUCCESS	APPID=application_1376111601621_0006	CONTAINERID=container_1376111601621_0006_01_000045
2013-08-10 05:30:52,398 INFO org.apache.hadoop.yarn.server.resourcemanager.scheduler.common.fica.FiCaSchedulerNode: Assigned container container_1376111601621_0006_01_000045 of capacity <memory:1024, vCores:1> on host hadoop-221-4:41177, which currently has 7 containers, <memory:8192, vCores:7> used and <memory:0, vCores:9> available
2013-08-10 05:30:52,399 INFO org.apache.hadoop.yarn.server.resourcemanager.scheduler.capacity.LeafQueue: assignedContainer application=application_1376111601621_0006 container=Container: [ContainerId: container_1376111601621_0006_01_000045, NodeId: hadoop-221-4:41177, NodeHttpAddress: hadoop-221-4:8042, Resource: <memory:1024, vCores:1>, Priority: 20, State: NEW, Token: null, Status: container_id {, app_attempt_id {, application_id {, id: 6, cluster_timestamp: 1376111601621, }, attemptId: 1, }, id: 45, }, state: C_NEW, ] containerId=container_1376111601621_0006_01_000045 queue=default: capacity=1.0, absoluteCapacity=1.0, usedResources=<memory:48128, vCores:42>usedCapacity=0.9791667, absoluteUsedCapacity=0.9791667, numApps=5, numContainers=42 usedCapacity=0.9791667 absoluteUsedCapacity=0.9791667 used=<memory:48128, vCores:42> cluster=<memory:49152, vCores:96>
2013-08-10 05:30:52,399 INFO org.apache.hadoop.yarn.server.resourcemanager.scheduler.capacity.ParentQueue: Re-sorting queues since queue: root.default stats: default: capacity=1.0, absoluteCapacity=1.0, usedResources=<memory:49152, vCores:43>usedCapacity=1.0, absoluteUsedCapacity=1.0, numApps=5, numContainers=43
2013-08-10 05:30:52,399 INFO org.apache.hadoop.yarn.server.resourcemanager.scheduler.capacity.ParentQueue: assignedContainer queue=root usedCapacity=1.0 absoluteUsedCapacity=1.0 used=<memory:49152, vCores:43> cluster=<memory:49152, vCores:96>
2013-08-10 05:30:53,235 INFO org.apache.hadoop.yarn.server.resourcemanager.rmcontainer.RMContainerImpl: container_1376111601621_0006_01_000045 Container Transitioned from ALLOCATED to ACQUIRED
2013-08-10 05:30:53,418 INFO org.apache.hadoop.yarn.server.resourcemanager.rmcontainer.RMContainerImpl: container_1376111601621_0006_01_000045 Container Transitioned from ACQUIRED to RUNNING
2013-08-10 05:30:54,243 INFO org.apache.hadoop.yarn.server.resourcemanager.scheduler.AppSchedulingInfo: checking for deactivate... 
2013-08-10 05:30:56,487 INFO org.apache.hadoop.yarn.server.resourcemanager.rmcontainer.RMContainerImpl: container_1376111601621_0006_01_000005 Container Transitioned from RUNNING to COMPLETED
2013-08-10 05:30:56,487 INFO org.apache.hadoop.yarn.server.resourcemanager.scheduler.common.fica.FiCaSchedulerApp: Completed container: container_1376111601621_0006_01_000005 in state: COMPLETED event:FINISHED
2013-08-10 05:30:56,487 INFO org.apache.hadoop.yarn.server.resourcemanager.RMAuditLogger: USER=ubuntu	OPERATION=AM Released Container	TARGET=SchedulerApp	RESULT=SUCCESS	APPID=application_1376111601621_0006	CONTAINERID=container_1376111601621_0006_01_000005
2013-08-10 05:30:56,488 INFO org.apache.hadoop.yarn.server.resourcemanager.scheduler.common.fica.FiCaSchedulerNode: Released container container_1376111601621_0006_01_000005 of capacity <memory:1024, vCores:1> on host hadoop-221-2:55267, which currently has 7 containers, <memory:7168, vCores:7> used and <memory:1024, vCores:9> available, release resources=true
2013-08-10 05:30:56,488 INFO org.apache.hadoop.yarn.server.resourcemanager.scheduler.capacity.LeafQueue: default used=<memory:48128, vCores:42> numContainers=42 user=ubuntu user-resources=<memory:48128, vCores:42>
2013-08-10 05:30:56,489 INFO org.apache.hadoop.yarn.server.resourcemanager.scheduler.capacity.LeafQueue: completedContainer container=Container: [ContainerId: container_1376111601621_0006_01_000005, NodeId: hadoop-221-2:55267, NodeHttpAddress: hadoop-221-2:8042, Resource: <memory:1024, vCores:1>, Priority: 20, State: NEW, Token: null, Status: container_id {, app_attempt_id {, application_id {, id: 6, cluster_timestamp: 1376111601621, }, attemptId: 1, }, id: 5, }, state: C_COMPLETE, diagnostics: "Container killed by the ApplicationMaster.\n\n", exit_status: 143, ] resource=<memory:1024, vCores:1> queue=default: capacity=1.0, absoluteCapacity=1.0, usedResources=<memory:48128, vCores:42>usedCapacity=0.9791667, absoluteUsedCapacity=0.9791667, numApps=5, numContainers=42 usedCapacity=0.9791667 absoluteUsedCapacity=0.9791667 used=<memory:48128, vCores:42> cluster=<memory:49152, vCores:96>
2013-08-10 05:30:56,489 INFO org.apache.hadoop.yarn.server.resourcemanager.scheduler.capacity.ParentQueue: completedContainer queue=root usedCapacity=0.9791667 absoluteUsedCapacity=0.9791667 used=<memory:48128, vCores:42> cluster=<memory:49152, vCores:96>
2013-08-10 05:30:56,489 INFO org.apache.hadoop.yarn.server.resourcemanager.scheduler.capacity.CapacityScheduler: Application appattempt_1376111601621_0006_000001 released container container_1376111601621_0006_01_000005 on node: host: hadoop-221-2:55267 #containers=7 available=1024 used=7168 with event: FINISHED
2013-08-10 05:30:56,490 INFO org.apache.hadoop.yarn.server.resourcemanager.rmcontainer.RMContainerImpl: container_1376111601621_0007_01_000012 Container Transitioned from NEW to ALLOCATED
2013-08-10 05:30:56,490 INFO org.apache.hadoop.yarn.server.resourcemanager.RMAuditLogger: USER=ubuntu	OPERATION=AM Allocated Container	TARGET=SchedulerApp	RESULT=SUCCESS	APPID=application_1376111601621_0007	CONTAINERID=container_1376111601621_0007_01_000012
2013-08-10 05:30:56,490 INFO org.apache.hadoop.yarn.server.resourcemanager.scheduler.common.fica.FiCaSchedulerNode: Assigned container container_1376111601621_0007_01_000012 of capacity <memory:1024, vCores:1> on host hadoop-221-2:55267, which currently has 8 containers, <memory:8192, vCores:8> used and <memory:0, vCores:8> available
2013-08-10 05:30:56,491 INFO org.apache.hadoop.yarn.server.resourcemanager.scheduler.capacity.LeafQueue: assignedContainer application=application_1376111601621_0007 container=Container: [ContainerId: container_1376111601621_0007_01_000012, NodeId: hadoop-221-2:55267, NodeHttpAddress: hadoop-221-2:8042, Resource: <memory:1024, vCores:1>, Priority: 20, State: NEW, Token: null, Status: container_id {, app_attempt_id {, application_id {, id: 7, cluster_timestamp: 1376111601621, }, attemptId: 1, }, id: 12, }, state: C_NEW, ] containerId=container_1376111601621_0007_01_000012 queue=default: capacity=1.0, absoluteCapacity=1.0, usedResources=<memory:48128, vCores:42>usedCapacity=0.9791667, absoluteUsedCapacity=0.9791667, numApps=5, numContainers=42 usedCapacity=0.9791667 absoluteUsedCapacity=0.9791667 used=<memory:48128, vCores:42> cluster=<memory:49152, vCores:96>
2013-08-10 05:30:56,492 INFO org.apache.hadoop.yarn.server.resourcemanager.scheduler.capacity.ParentQueue: Re-sorting queues since queue: root.default stats: default: capacity=1.0, absoluteCapacity=1.0, usedResources=<memory:49152, vCores:43>usedCapacity=1.0, absoluteUsedCapacity=1.0, numApps=5, numContainers=43
2013-08-10 05:30:56,492 INFO org.apache.hadoop.yarn.server.resourcemanager.scheduler.capacity.ParentQueue: assignedContainer queue=root usedCapacity=1.0 absoluteUsedCapacity=1.0 used=<memory:49152, vCores:43> cluster=<memory:49152, vCores:96>
2013-08-10 05:30:57,475 INFO org.apache.hadoop.yarn.server.resourcemanager.rmcontainer.RMContainerImpl: container_1376111601621_0007_01_000012 Container Transitioned from ALLOCATED to ACQUIRED
2013-08-10 05:30:57,596 INFO org.apache.hadoop.yarn.server.resourcemanager.rmcontainer.RMContainerImpl: container_1376111601621_0006_01_000010 Container Transitioned from RUNNING to COMPLETED
2013-08-10 05:30:57,597 INFO org.apache.hadoop.yarn.server.resourcemanager.scheduler.common.fica.FiCaSchedulerApp: Completed container: container_1376111601621_0006_01_000010 in state: COMPLETED event:FINISHED
2013-08-10 05:30:57,597 INFO org.apache.hadoop.yarn.server.resourcemanager.RMAuditLogger: USER=ubuntu	OPERATION=AM Released Container	TARGET=SchedulerApp	RESULT=SUCCESS	APPID=application_1376111601621_0006	CONTAINERID=container_1376111601621_0006_01_000010
2013-08-10 05:30:57,597 INFO org.apache.hadoop.yarn.server.resourcemanager.scheduler.common.fica.FiCaSchedulerNode: Released container container_1376111601621_0006_01_000010 of capacity <memory:1024, vCores:1> on host hadoop-221-7:34609, which currently has 6 containers, <memory:7168, vCores:6> used and <memory:1024, vCores:10> available, release resources=true
2013-08-10 05:30:57,597 INFO org.apache.hadoop.yarn.server.resourcemanager.scheduler.capacity.LeafQueue: default used=<memory:48128, vCores:42> numContainers=42 user=ubuntu user-resources=<memory:48128, vCores:42>
2013-08-10 05:30:57,598 INFO org.apache.hadoop.yarn.server.resourcemanager.scheduler.capacity.LeafQueue: completedContainer container=Container: [ContainerId: container_1376111601621_0006_01_000010, NodeId: hadoop-221-7:34609, NodeHttpAddress: hadoop-221-7:8042, Resource: <memory:1024, vCores:1>, Priority: 20, State: NEW, Token: null, Status: container_id {, app_attempt_id {, application_id {, id: 6, cluster_timestamp: 1376111601621, }, attemptId: 1, }, id: 10, }, state: C_COMPLETE, diagnostics: "Container killed by the ApplicationMaster.\n", exit_status: 0, ] resource=<memory:1024, vCores:1> queue=default: capacity=1.0, absoluteCapacity=1.0, usedResources=<memory:48128, vCores:42>usedCapacity=0.9791667, absoluteUsedCapacity=0.9791667, numApps=5, numContainers=42 usedCapacity=0.9791667 absoluteUsedCapacity=0.9791667 used=<memory:48128, vCores:42> cluster=<memory:49152, vCores:96>
2013-08-10 05:30:57,599 INFO org.apache.hadoop.yarn.server.resourcemanager.scheduler.capacity.ParentQueue: completedContainer queue=root usedCapacity=0.9791667 absoluteUsedCapacity=0.9791667 used=<memory:48128, vCores:42> cluster=<memory:49152, vCores:96>
2013-08-10 05:30:57,599 INFO org.apache.hadoop.yarn.server.resourcemanager.scheduler.capacity.CapacityScheduler: Application appattempt_1376111601621_0006_000001 released container container_1376111601621_0006_01_000010 on node: host: hadoop-221-7:34609 #containers=6 available=1024 used=7168 with event: FINISHED
2013-08-10 05:30:57,599 INFO org.apache.hadoop.yarn.server.resourcemanager.rmcontainer.RMContainerImpl: container_1376111601621_0007_01_000013 Container Transitioned from NEW to ALLOCATED
2013-08-10 05:30:57,600 INFO org.apache.hadoop.yarn.server.resourcemanager.RMAuditLogger: USER=ubuntu	OPERATION=AM Allocated Container	TARGET=SchedulerApp	RESULT=SUCCESS	APPID=application_1376111601621_0007	CONTAINERID=container_1376111601621_0007_01_000013
2013-08-10 05:30:57,600 INFO org.apache.hadoop.yarn.server.resourcemanager.scheduler.common.fica.FiCaSchedulerNode: Assigned container container_1376111601621_0007_01_000013 of capacity <memory:1024, vCores:1> on host hadoop-221-7:34609, which currently has 7 containers, <memory:8192, vCores:7> used and <memory:0, vCores:9> available
2013-08-10 05:30:57,601 INFO org.apache.hadoop.yarn.server.resourcemanager.scheduler.capacity.LeafQueue: assignedContainer application=application_1376111601621_0007 container=Container: [ContainerId: container_1376111601621_0007_01_000013, NodeId: hadoop-221-7:34609, NodeHttpAddress: hadoop-221-7:8042, Resource: <memory:1024, vCores:1>, Priority: 20, State: NEW, Token: null, Status: container_id {, app_attempt_id {, application_id {, id: 7, cluster_timestamp: 1376111601621, }, attemptId: 1, }, id: 13, }, state: C_NEW, ] containerId=container_1376111601621_0007_01_000013 queue=default: capacity=1.0, absoluteCapacity=1.0, usedResources=<memory:48128, vCores:42>usedCapacity=0.9791667, absoluteUsedCapacity=0.9791667, numApps=5, numContainers=42 usedCapacity=0.9791667 absoluteUsedCapacity=0.9791667 used=<memory:48128, vCores:42> cluster=<memory:49152, vCores:96>
2013-08-10 05:30:57,601 INFO org.apache.hadoop.yarn.server.resourcemanager.scheduler.capacity.ParentQueue: Re-sorting queues since queue: root.default stats: default: capacity=1.0, absoluteCapacity=1.0, usedResources=<memory:49152, vCores:43>usedCapacity=1.0, absoluteUsedCapacity=1.0, numApps=5, numContainers=43
2013-08-10 05:30:57,601 INFO org.apache.hadoop.yarn.server.resourcemanager.scheduler.capacity.ParentQueue: assignedContainer queue=root usedCapacity=1.0 absoluteUsedCapacity=1.0 used=<memory:49152, vCores:43> cluster=<memory:49152, vCores:96>
2013-08-10 05:30:58,489 INFO org.apache.hadoop.yarn.server.resourcemanager.rmcontainer.RMContainerImpl: container_1376111601621_0007_01_000013 Container Transitioned from ALLOCATED to ACQUIRED
2013-08-10 05:30:58,502 INFO org.apache.hadoop.yarn.server.resourcemanager.rmcontainer.RMContainerImpl: container_1376111601621_0007_01_000012 Container Transitioned from ACQUIRED to RUNNING
2013-08-10 05:30:58,603 INFO org.apache.hadoop.yarn.server.resourcemanager.rmcontainer.RMContainerImpl: container_1376111601621_0007_01_000013 Container Transitioned from ACQUIRED to RUNNING
2013-08-10 05:31:00,182 INFO org.apache.hadoop.yarn.server.resourcemanager.rmcontainer.RMContainerImpl: container_1376111601621_0006_01_000040 Container Transitioned from RUNNING to COMPLETED
2013-08-10 05:31:00,182 INFO org.apache.hadoop.yarn.server.resourcemanager.scheduler.common.fica.FiCaSchedulerApp: Completed container: container_1376111601621_0006_01_000040 in state: COMPLETED event:FINISHED
2013-08-10 05:31:00,182 INFO org.apache.hadoop.yarn.server.resourcemanager.RMAuditLogger: USER=ubuntu	OPERATION=AM Released Container	TARGET=SchedulerApp	RESULT=SUCCESS	APPID=application_1376111601621_0006	CONTAINERID=container_1376111601621_0006_01_000040
2013-08-10 05:31:00,183 INFO org.apache.hadoop.yarn.server.resourcemanager.scheduler.common.fica.FiCaSchedulerNode: Released container container_1376111601621_0006_01_000040 of capacity <memory:1024, vCores:1> on host hadoop-221-6:57712, which currently has 6 containers, <memory:7168, vCores:6> used and <memory:1024, vCores:10> available, release resources=true
2013-08-10 05:31:00,183 INFO org.apache.hadoop.yarn.server.resourcemanager.scheduler.capacity.LeafQueue: default used=<memory:48128, vCores:42> numContainers=42 user=ubuntu user-resources=<memory:48128, vCores:42>
2013-08-10 05:31:00,184 INFO org.apache.hadoop.yarn.server.resourcemanager.scheduler.capacity.LeafQueue: completedContainer container=Container: [ContainerId: container_1376111601621_0006_01_000040, NodeId: hadoop-221-6:57712, NodeHttpAddress: hadoop-221-6:8042, Resource: <memory:1024, vCores:1>, Priority: 20, State: NEW, Token: null, Status: container_id {, app_attempt_id {, application_id {, id: 6, cluster_timestamp: 1376111601621, }, attemptId: 1, }, id: 40, }, state: C_COMPLETE, diagnostics: "Container killed by the ApplicationMaster.\n\n", exit_status: 143, ] resource=<memory:1024, vCores:1> queue=default: capacity=1.0, absoluteCapacity=1.0, usedResources=<memory:48128, vCores:42>usedCapacity=0.9791667, absoluteUsedCapacity=0.9791667, numApps=5, numContainers=42 usedCapacity=0.9791667 absoluteUsedCapacity=0.9791667 used=<memory:48128, vCores:42> cluster=<memory:49152, vCores:96>
2013-08-10 05:31:00,184 INFO org.apache.hadoop.yarn.server.resourcemanager.scheduler.capacity.ParentQueue: completedContainer queue=root usedCapacity=0.9791667 absoluteUsedCapacity=0.9791667 used=<memory:48128, vCores:42> cluster=<memory:49152, vCores:96>
2013-08-10 05:31:00,184 INFO org.apache.hadoop.yarn.server.resourcemanager.scheduler.capacity.CapacityScheduler: Application appattempt_1376111601621_0006_000001 released container container_1376111601621_0006_01_000040 on node: host: hadoop-221-6:57712 #containers=6 available=1024 used=7168 with event: FINISHED
2013-08-10 05:31:00,185 INFO org.apache.hadoop.yarn.server.resourcemanager.rmcontainer.RMContainerImpl: container_1376111601621_0007_01_000014 Container Transitioned from NEW to ALLOCATED
2013-08-10 05:31:00,185 INFO org.apache.hadoop.yarn.server.resourcemanager.RMAuditLogger: USER=ubuntu	OPERATION=AM Allocated Container	TARGET=SchedulerApp	RESULT=SUCCESS	APPID=application_1376111601621_0007	CONTAINERID=container_1376111601621_0007_01_000014
2013-08-10 05:31:00,185 INFO org.apache.hadoop.yarn.server.resourcemanager.scheduler.common.fica.FiCaSchedulerNode: Assigned container container_1376111601621_0007_01_000014 of capacity <memory:1024, vCores:1> on host hadoop-221-6:57712, which currently has 7 containers, <memory:8192, vCores:7> used and <memory:0, vCores:9> available
2013-08-10 05:31:00,186 INFO org.apache.hadoop.yarn.server.resourcemanager.scheduler.capacity.LeafQueue: assignedContainer application=application_1376111601621_0007 container=Container: [ContainerId: container_1376111601621_0007_01_000014, NodeId: hadoop-221-6:57712, NodeHttpAddress: hadoop-221-6:8042, Resource: <memory:1024, vCores:1>, Priority: 20, State: NEW, Token: null, Status: container_id {, app_attempt_id {, application_id {, id: 7, cluster_timestamp: 1376111601621, }, attemptId: 1, }, id: 14, }, state: C_NEW, ] containerId=container_1376111601621_0007_01_000014 queue=default: capacity=1.0, absoluteCapacity=1.0, usedResources=<memory:48128, vCores:42>usedCapacity=0.9791667, absoluteUsedCapacity=0.9791667, numApps=5, numContainers=42 usedCapacity=0.9791667 absoluteUsedCapacity=0.9791667 used=<memory:48128, vCores:42> cluster=<memory:49152, vCores:96>
2013-08-10 05:31:00,186 INFO org.apache.hadoop.yarn.server.resourcemanager.scheduler.capacity.ParentQueue: Re-sorting queues since queue: root.default stats: default: capacity=1.0, absoluteCapacity=1.0, usedResources=<memory:49152, vCores:43>usedCapacity=1.0, absoluteUsedCapacity=1.0, numApps=5, numContainers=43
2013-08-10 05:31:00,187 INFO org.apache.hadoop.yarn.server.resourcemanager.scheduler.capacity.ParentQueue: assignedContainer queue=root usedCapacity=1.0 absoluteUsedCapacity=1.0 used=<memory:49152, vCores:43> cluster=<memory:49152, vCores:96>
2013-08-10 05:31:00,536 INFO org.apache.hadoop.yarn.server.resourcemanager.rmcontainer.RMContainerImpl: container_1376111601621_0007_01_000014 Container Transitioned from ALLOCATED to ACQUIRED
2013-08-10 05:31:01,234 INFO org.apache.hadoop.yarn.server.resourcemanager.rmcontainer.RMContainerImpl: container_1376111601621_0007_01_000014 Container Transitioned from ACQUIRED to RUNNING
2013-08-10 05:31:05,891 INFO org.apache.hadoop.yarn.server.resourcemanager.rmcontainer.RMContainerImpl: container_1376111601621_0006_01_000038 Container Transitioned from RUNNING to COMPLETED
2013-08-10 05:31:05,891 INFO org.apache.hadoop.yarn.server.resourcemanager.scheduler.common.fica.FiCaSchedulerApp: Completed container: container_1376111601621_0006_01_000038 in state: COMPLETED event:FINISHED
2013-08-10 05:31:05,891 INFO org.apache.hadoop.yarn.server.resourcemanager.RMAuditLogger: USER=ubuntu	OPERATION=AM Released Container	TARGET=SchedulerApp	RESULT=SUCCESS	APPID=application_1376111601621_0006	CONTAINERID=container_1376111601621_0006_01_000038
2013-08-10 05:31:05,892 INFO org.apache.hadoop.yarn.server.resourcemanager.scheduler.common.fica.FiCaSchedulerNode: Released container container_1376111601621_0006_01_000038 of capacity <memory:1024, vCores:1> on host hadoop-221-4:41177, which currently has 6 containers, <memory:7168, vCores:6> used and <memory:1024, vCores:10> available, release resources=true
2013-08-10 05:31:05,892 INFO org.apache.hadoop.yarn.server.resourcemanager.scheduler.capacity.LeafQueue: default used=<memory:48128, vCores:42> numContainers=42 user=ubuntu user-resources=<memory:48128, vCores:42>
2013-08-10 05:31:05,893 INFO org.apache.hadoop.yarn.server.resourcemanager.scheduler.capacity.LeafQueue: completedContainer container=Container: [ContainerId: container_1376111601621_0006_01_000038, NodeId: hadoop-221-4:41177, NodeHttpAddress: hadoop-221-4:8042, Resource: <memory:1024, vCores:1>, Priority: 20, State: NEW, Token: null, Status: container_id {, app_attempt_id {, application_id {, id: 6, cluster_timestamp: 1376111601621, }, attemptId: 1, }, id: 38, }, state: C_COMPLETE, diagnostics: "Container killed by the ApplicationMaster.\n\n", exit_status: 143, ] resource=<memory:1024, vCores:1> queue=default: capacity=1.0, absoluteCapacity=1.0, usedResources=<memory:48128, vCores:42>usedCapacity=0.9791667, absoluteUsedCapacity=0.9791667, numApps=5, numContainers=42 usedCapacity=0.9791667 absoluteUsedCapacity=0.9791667 used=<memory:48128, vCores:42> cluster=<memory:49152, vCores:96>
2013-08-10 05:31:05,893 INFO org.apache.hadoop.yarn.server.resourcemanager.scheduler.capacity.ParentQueue: completedContainer queue=root usedCapacity=0.9791667 absoluteUsedCapacity=0.9791667 used=<memory:48128, vCores:42> cluster=<memory:49152, vCores:96>
2013-08-10 05:31:05,893 INFO org.apache.hadoop.yarn.server.resourcemanager.scheduler.capacity.CapacityScheduler: Application appattempt_1376111601621_0006_000001 released container container_1376111601621_0006_01_000038 on node: host: hadoop-221-4:41177 #containers=6 available=1024 used=7168 with event: FINISHED
2013-08-10 05:31:05,894 INFO org.apache.hadoop.yarn.server.resourcemanager.rmcontainer.RMContainerImpl: container_1376111601621_0007_01_000015 Container Transitioned from NEW to ALLOCATED
2013-08-10 05:31:05,894 INFO org.apache.hadoop.yarn.server.resourcemanager.RMAuditLogger: USER=ubuntu	OPERATION=AM Allocated Container	TARGET=SchedulerApp	RESULT=SUCCESS	APPID=application_1376111601621_0007	CONTAINERID=container_1376111601621_0007_01_000015
2013-08-10 05:31:05,894 INFO org.apache.hadoop.yarn.server.resourcemanager.scheduler.common.fica.FiCaSchedulerNode: Assigned container container_1376111601621_0007_01_000015 of capacity <memory:1024, vCores:1> on host hadoop-221-4:41177, which currently has 7 containers, <memory:8192, vCores:7> used and <memory:0, vCores:9> available
2013-08-10 05:31:05,895 INFO org.apache.hadoop.yarn.server.resourcemanager.scheduler.capacity.LeafQueue: assignedContainer application=application_1376111601621_0007 container=Container: [ContainerId: container_1376111601621_0007_01_000015, NodeId: hadoop-221-4:41177, NodeHttpAddress: hadoop-221-4:8042, Resource: <memory:1024, vCores:1>, Priority: 20, State: NEW, Token: null, Status: container_id {, app_attempt_id {, application_id {, id: 7, cluster_timestamp: 1376111601621, }, attemptId: 1, }, id: 15, }, state: C_NEW, ] containerId=container_1376111601621_0007_01_000015 queue=default: capacity=1.0, absoluteCapacity=1.0, usedResources=<memory:48128, vCores:42>usedCapacity=0.9791667, absoluteUsedCapacity=0.9791667, numApps=5, numContainers=42 usedCapacity=0.9791667 absoluteUsedCapacity=0.9791667 used=<memory:48128, vCores:42> cluster=<memory:49152, vCores:96>
2013-08-10 05:31:05,896 INFO org.apache.hadoop.yarn.server.resourcemanager.scheduler.capacity.ParentQueue: Re-sorting queues since queue: root.default stats: default: capacity=1.0, absoluteCapacity=1.0, usedResources=<memory:49152, vCores:43>usedCapacity=1.0, absoluteUsedCapacity=1.0, numApps=5, numContainers=43
2013-08-10 05:31:05,896 INFO org.apache.hadoop.yarn.server.resourcemanager.scheduler.capacity.ParentQueue: assignedContainer queue=root usedCapacity=1.0 absoluteUsedCapacity=1.0 used=<memory:49152, vCores:43> cluster=<memory:49152, vCores:96>
2013-08-10 05:31:06,062 INFO org.apache.hadoop.yarn.server.resourcemanager.rmcontainer.RMContainerImpl: container_1376111601621_0006_01_000032 Container Transitioned from RUNNING to COMPLETED
2013-08-10 05:31:06,063 INFO org.apache.hadoop.yarn.server.resourcemanager.scheduler.common.fica.FiCaSchedulerApp: Completed container: container_1376111601621_0006_01_000032 in state: COMPLETED event:FINISHED
2013-08-10 05:31:06,063 INFO org.apache.hadoop.yarn.server.resourcemanager.RMAuditLogger: USER=ubuntu	OPERATION=AM Released Container	TARGET=SchedulerApp	RESULT=SUCCESS	APPID=application_1376111601621_0006	CONTAINERID=container_1376111601621_0006_01_000032
2013-08-10 05:31:06,063 INFO org.apache.hadoop.yarn.server.resourcemanager.scheduler.common.fica.FiCaSchedulerNode: Released container container_1376111601621_0006_01_000032 of capacity <memory:1024, vCores:1> on host hadoop-221-6:57712, which currently has 6 containers, <memory:7168, vCores:6> used and <memory:1024, vCores:10> available, release resources=true
2013-08-10 05:31:06,063 INFO org.apache.hadoop.yarn.server.resourcemanager.scheduler.capacity.LeafQueue: default used=<memory:48128, vCores:42> numContainers=42 user=ubuntu user-resources=<memory:48128, vCores:42>
2013-08-10 05:31:06,064 INFO org.apache.hadoop.yarn.server.resourcemanager.scheduler.capacity.LeafQueue: completedContainer container=Container: [ContainerId: container_1376111601621_0006_01_000032, NodeId: hadoop-221-6:57712, NodeHttpAddress: hadoop-221-6:8042, Resource: <memory:1024, vCores:1>, Priority: 20, State: NEW, Token: null, Status: container_id {, app_attempt_id {, application_id {, id: 6, cluster_timestamp: 1376111601621, }, attemptId: 1, }, id: 32, }, state: C_COMPLETE, diagnostics: "Container killed by the ApplicationMaster.\n\n", exit_status: 143, ] resource=<memory:1024, vCores:1> queue=default: capacity=1.0, absoluteCapacity=1.0, usedResources=<memory:48128, vCores:42>usedCapacity=0.9791667, absoluteUsedCapacity=0.9791667, numApps=5, numContainers=42 usedCapacity=0.9791667 absoluteUsedCapacity=0.9791667 used=<memory:48128, vCores:42> cluster=<memory:49152, vCores:96>
2013-08-10 05:31:06,065 INFO org.apache.hadoop.yarn.server.resourcemanager.scheduler.capacity.ParentQueue: completedContainer queue=root usedCapacity=0.9791667 absoluteUsedCapacity=0.9791667 used=<memory:48128, vCores:42> cluster=<memory:49152, vCores:96>
2013-08-10 05:31:06,065 INFO org.apache.hadoop.yarn.server.resourcemanager.scheduler.capacity.CapacityScheduler: Application appattempt_1376111601621_0006_000001 released container container_1376111601621_0006_01_000032 on node: host: hadoop-221-6:57712 #containers=6 available=1024 used=7168 with event: FINISHED
2013-08-10 05:31:06,065 INFO org.apache.hadoop.yarn.server.resourcemanager.rmcontainer.RMContainerImpl: container_1376111601621_0007_01_000016 Container Transitioned from NEW to ALLOCATED
2013-08-10 05:31:06,066 INFO org.apache.hadoop.yarn.server.resourcemanager.RMAuditLogger: USER=ubuntu	OPERATION=AM Allocated Container	TARGET=SchedulerApp	RESULT=SUCCESS	APPID=application_1376111601621_0007	CONTAINERID=container_1376111601621_0007_01_000016
2013-08-10 05:31:06,066 INFO org.apache.hadoop.yarn.server.resourcemanager.scheduler.common.fica.FiCaSchedulerNode: Assigned container container_1376111601621_0007_01_000016 of capacity <memory:1024, vCores:1> on host hadoop-221-6:57712, which currently has 7 containers, <memory:8192, vCores:7> used and <memory:0, vCores:9> available
